
#######################################################################
# +-----------------------------------------------------------------+ #
# |                            BO4 object                           | #
# +-----------------------------------------------------------------+ #
#######################################################################

Author: Unknown

Description: No description given

SettingsMode: WriteWithoutComments


#######################################################################
# +-----------------------------------------------------------------+ #
# |                          Main settings                          | #
# +-----------------------------------------------------------------+ #
#######################################################################

FixedRotation: 

Frequency: 0

SpawnHeight: highestBlock

UseCenterForHighestBlock: true

##############################
# Height Limits for the BO4. #
##############################

MinHeight: 0

MaxHeight: 255

InheritBO3: 

InheritBO3Rotation: NORTH

OverrideChildSettings: true

OverrideParentHeight: false

CanOverride: false

BranchFrequency: 0

BranchFrequencyGroup: 

MustBeBelowOther: false

MustBeInside: 

CannotBeInside: 

ReplacesBO3: 

MustBeInsideWorldBorders: false

CanSpawnOnWater: true

SpawnOnWaterOnly: false

SpawnUnderWater: false

SpawnAtWaterLevel: false

HeightOffset: 0

RemoveAir: true

ReplaceAbove: 

ReplaceBelow: 

ReplaceWithBiomeBlocks: true

ReplaceWithSurfaceBlock: GRASS

ReplaceWithGroundBlock: DIRT

ReplaceWithStoneBlock: STONE

SmoothRadius: 0

SmoothHeightOffset: 0

SmoothStartTop: false

SmoothStartWood: false

SmoothingSurfaceBlock: 

SmoothingGroundBlock: 

BO3Group: 

IsSpawnPoint: false

DoReplaceBlocks: true


#######################################################################
# +-----------------------------------------------------------------+ #
# |                              Blocks                             | #
# +-----------------------------------------------------------------+ #
#######################################################################

B(-2,55,-5,minecraft:netherrack)
B(-2,55,-4,minecraft:netherrack)
B(-2,55,-3,minecraft:netherrack)
B(-2,55,-2,minecraft:netherrack)
B(-2,55,-1,minecraft:netherrack)
B(-2,54,0,minecraft:netherrack)
B(-2,55,0,minecraft:netherrack)
B(-2,54,1,minecraft:netherrack)
B(-2,55,1,minecraft:netherrack)
B(-2,55,2,minecraft:netherrack)
B(-2,55,3,minecraft:netherrack)
B(-2,55,4,minecraft:netherrack)
B(-1,55,-4,minecraft:netherrack)
B(-1,55,-3,minecraft:netherrack)
B(-1,55,-2,minecraft:netherrack)
B(-1,55,-1,minecraft:netherrack)
B(-1,55,0,minecraft:netherrack)
B(-1,55,1,minecraft:netherrack)
B(-1,55,2,minecraft:netherrack)
B(-1,55,3,minecraft:netherrack)
B(-1,55,4,minecraft:netherrack)
B(0,55,-3,minecraft:netherrack)
B(0,55,-2,minecraft:netherrack)
B(0,55,-1,minecraft:netherrack)
B(0,55,0,minecraft:netherrack)
B(0,55,1,minecraft:netherrack)
B(0,55,2,minecraft:netherrack)
B(0,55,3,minecraft:netherrack)
B(0,55,4,minecraft:netherrack)
B(0,55,5,minecraft:netherrack)
B(1,53,-5,minecraft:netherrack)
B(1,54,-5,minecraft:netherrack)
B(1,55,-5,minecraft:netherrack)
B(1,49,-4,minecraft:netherrack)
B(1,50,-4,minecraft:netherrack)
B(1,51,-4,minecraft:netherrack)
B(1,52,-4,minecraft:netherrack)
B(1,53,-4,minecraft:netherrack)
B(1,54,-4,minecraft:netherrack)
B(1,55,-4,minecraft:netherrack)
B(1,48,-3,minecraft:netherrack)
B(1,49,-3,minecraft:netherrack)
B(1,50,-3,minecraft:netherrack)
B(1,51,-3,minecraft:netherrack)
B(1,52,-3,minecraft:netherrack)
B(1,53,-3,minecraft:netherrack)
B(1,54,-3,minecraft:netherrack)
B(1,55,-3,minecraft:netherrack)
B(1,48,-2,minecraft:netherrack)
B(1,49,-2,minecraft:netherrack)
B(1,50,-2,minecraft:netherrack)
B(1,51,-2,minecraft:netherrack)
B(1,52,-2,minecraft:netherrack)
B(1,53,-2,minecraft:netherrack)
B(1,54,-2,minecraft:netherrack)
B(1,55,-2,minecraft:netherrack)
B(1,52,-1,minecraft:netherrack)
B(1,53,-1,minecraft:netherrack)
B(1,54,-1,minecraft:netherrack)
B(1,55,-1,minecraft:netherrack)
B(1,55,0,minecraft:netherrack)
B(1,55,1,minecraft:netherrack)
B(1,55,2,minecraft:netherrack)
B(1,55,3,minecraft:netherrack)
B(1,55,4,minecraft:netherrack)
B(1,55,5,minecraft:netherrack)
B(1,55,6,minecraft:netherrack)
B(2,52,-6,minecraft:netherrack)
B(2,53,-6,minecraft:netherrack)
B(2,54,-6,minecraft:netherrack)
B(2,55,-6,minecraft:netherrack)
B(2,48,-5,minecraft:netherrack)
B(2,49,-5,minecraft:netherrack)
B(2,50,-5,minecraft:netherrack)
B(2,51,-5,minecraft:netherrack)
B(2,52,-5,minecraft:netherrack)
B(2,53,-5,minecraft:netherrack)
B(2,54,-5,minecraft:netherrack)
B(2,55,-5,minecraft:netherrack)
B(2,47,-4,minecraft:netherrack)
B(2,48,-4,minecraft:netherrack)
B(2,49,-4,minecraft:netherrack)
B(2,50,-4,minecraft:netherrack)
B(2,51,-4,minecraft:netherrack)
B(2,52,-4,minecraft:netherrack)
B(2,53,-4,minecraft:netherrack)
B(2,54,-4,minecraft:netherrack)
B(2,55,-4,minecraft:netherrack)
B(2,46,-3,minecraft:netherrack)
B(2,47,-3,minecraft:netherrack)
B(2,48,-3,minecraft:netherrack)
B(2,49,-3,minecraft:netherrack)
B(2,50,-3,minecraft:netherrack)
B(2,51,-3,minecraft:netherrack)
B(2,52,-3,minecraft:netherrack)
B(2,53,-3,minecraft:netherrack)
B(2,54,-3,minecraft:netherrack)
B(2,55,-3,minecraft:netherrack)
B(2,45,-2,minecraft:netherrack)
B(2,46,-2,minecraft:netherrack)
B(2,47,-2,minecraft:netherrack)
B(2,48,-2,minecraft:netherrack)
B(2,49,-2,minecraft:netherrack)
B(2,50,-2,minecraft:netherrack)
B(2,51,-2,minecraft:netherrack)
B(2,52,-2,minecraft:netherrack)
B(2,53,-2,minecraft:netherrack)
B(2,54,-2,minecraft:netherrack)
B(2,55,-2,minecraft:netherrack)
B(2,45,-1,minecraft:netherrack)
B(2,46,-1,minecraft:netherrack)
B(2,47,-1,minecraft:netherrack)
B(2,48,-1,minecraft:netherrack)
B(2,49,-1,minecraft:netherrack)
B(2,50,-1,minecraft:netherrack)
B(2,51,-1,minecraft:netherrack)
B(2,52,-1,minecraft:netherrack)
B(2,53,-1,minecraft:netherrack)
B(2,54,-1,minecraft:netherrack)
B(2,55,-1,minecraft:netherrack)
B(2,45,0,minecraft:netherrack)
B(2,46,0,minecraft:netherrack)
B(2,47,0,minecraft:netherrack)
B(2,48,0,minecraft:netherrack)
B(2,49,0,minecraft:netherrack)
B(2,50,0,minecraft:netherrack)
B(2,51,0,minecraft:netherrack)
B(2,52,0,minecraft:netherrack)
B(2,53,0,minecraft:netherrack)
B(2,54,0,minecraft:netherrack)
B(2,55,0,minecraft:netherrack)
B(2,55,1,minecraft:netherrack)
B(2,55,2,minecraft:netherrack)
B(2,55,3,minecraft:netherrack)
B(2,55,4,minecraft:netherrack)
B(2,55,5,minecraft:netherrack)
B(2,55,6,minecraft:netherrack)
B(3,52,-7,minecraft:netherrack)
B(3,53,-7,minecraft:netherrack)
B(3,54,-7,minecraft:netherrack)
B(3,55,-7,minecraft:netherrack)
B(3,47,-6,minecraft:netherrack)
B(3,48,-6,minecraft:netherrack)
B(3,49,-6,minecraft:netherrack)
B(3,50,-6,minecraft:netherrack)
B(3,51,-6,minecraft:netherrack)
B(3,52,-6,minecraft:netherrack)
B(3,53,-6,minecraft:netherrack)
B(3,54,-6,minecraft:netherrack)
B(3,55,-6,minecraft:netherrack)
B(3,46,-5,minecraft:netherrack)
B(3,47,-5,minecraft:netherrack)
B(3,48,-5,minecraft:netherrack)
B(3,49,-5,minecraft:netherrack)
B(3,50,-5,minecraft:netherrack)
B(3,51,-5,minecraft:netherrack)
B(3,52,-5,minecraft:netherrack)
B(3,53,-5,minecraft:netherrack)
B(3,54,-5,minecraft:netherrack)
B(3,55,-5,minecraft:netherrack)
B(3,44,-4,minecraft:netherrack)
B(3,45,-4,minecraft:netherrack)
B(3,46,-4,minecraft:netherrack)
B(3,47,-4,minecraft:netherrack)
B(3,48,-4,minecraft:netherrack)
B(3,49,-4,minecraft:netherrack)
B(3,50,-4,minecraft:netherrack)
B(3,51,-4,minecraft:netherrack)
B(3,52,-4,minecraft:netherrack)
B(3,53,-4,minecraft:netherrack)
B(3,54,-4,minecraft:netherrack)
B(3,55,-4,minecraft:netherrack)
B(3,43,-3,minecraft:netherrack)
B(3,44,-3,minecraft:netherrack)
B(3,45,-3,minecraft:netherrack)
B(3,46,-3,minecraft:netherrack)
B(3,47,-3,minecraft:netherrack)
B(3,48,-3,minecraft:netherrack)
B(3,49,-3,minecraft:netherrack)
B(3,50,-3,minecraft:netherrack)
B(3,51,-3,minecraft:netherrack)
B(3,52,-3,minecraft:netherrack)
B(3,53,-3,minecraft:netherrack)
B(3,54,-3,minecraft:netherrack)
B(3,55,-3,minecraft:netherrack)
B(3,42,-2,minecraft:netherrack)
B(3,43,-2,minecraft:netherrack)
B(3,44,-2,minecraft:netherrack)
B(3,45,-2,minecraft:netherrack)
B(3,46,-2,minecraft:netherrack)
B(3,47,-2,minecraft:netherrack)
B(3,48,-2,minecraft:netherrack)
B(3,49,-2,minecraft:netherrack)
B(3,50,-2,minecraft:netherrack)
B(3,51,-2,minecraft:netherrack)
B(3,52,-2,minecraft:netherrack)
B(3,53,-2,minecraft:netherrack)
B(3,54,-2,minecraft:netherrack)
B(3,55,-2,minecraft:netherrack)
B(3,42,-1,minecraft:netherrack)
B(3,43,-1,minecraft:netherrack)
B(3,44,-1,minecraft:netherrack)
B(3,45,-1,minecraft:netherrack)
B(3,46,-1,minecraft:netherrack)
B(3,47,-1,minecraft:netherrack)
B(3,48,-1,minecraft:netherrack)
B(3,49,-1,minecraft:netherrack)
B(3,50,-1,minecraft:netherrack)
B(3,51,-1,minecraft:netherrack)
B(3,52,-1,minecraft:netherrack)
B(3,53,-1,minecraft:netherrack)
B(3,54,-1,minecraft:netherrack)
B(3,55,-1,minecraft:netherrack)
B(3,42,0,minecraft:netherrack)
B(3,43,0,minecraft:netherrack)
B(3,44,0,minecraft:netherrack)
B(3,45,0,minecraft:netherrack)
B(3,46,0,minecraft:netherrack)
B(3,47,0,minecraft:netherrack)
B(3,48,0,minecraft:netherrack)
B(3,49,0,minecraft:netherrack)
B(3,50,0,minecraft:netherrack)
B(3,51,0,minecraft:netherrack)
B(3,52,0,minecraft:netherrack)
B(3,53,0,minecraft:netherrack)
B(3,54,0,minecraft:netherrack)
B(3,55,0,minecraft:netherrack)
B(3,42,1,minecraft:netherrack)
B(3,43,1,minecraft:netherrack)
B(3,44,1,minecraft:netherrack)
B(3,45,1,minecraft:netherrack)
B(3,46,1,minecraft:netherrack)
B(3,47,1,minecraft:netherrack)
B(3,48,1,minecraft:netherrack)
B(3,49,1,minecraft:netherrack)
B(3,50,1,minecraft:netherrack)
B(3,51,1,minecraft:netherrack)
B(3,52,1,minecraft:netherrack)
B(3,53,1,minecraft:netherrack)
B(3,54,1,minecraft:netherrack)
B(3,55,1,minecraft:netherrack)
B(3,53,2,minecraft:netherrack)
B(3,54,2,minecraft:netherrack)
B(3,55,2,minecraft:netherrack)
B(3,55,3,minecraft:netherrack)
B(3,55,4,minecraft:netherrack)
B(3,55,5,minecraft:netherrack)
B(4,48,-7,minecraft:netherrack)
B(4,49,-7,minecraft:netherrack)
B(4,50,-7,minecraft:netherrack)
B(4,51,-7,minecraft:netherrack)
B(4,52,-7,minecraft:netherrack)
B(4,53,-7,minecraft:netherrack)
B(4,54,-7,minecraft:netherrack)
B(4,55,-7,minecraft:netherrack)
B(4,46,-6,minecraft:netherrack)
B(4,47,-6,minecraft:netherrack)
B(4,48,-6,minecraft:netherrack)
B(4,49,-6,minecraft:netherrack)
B(4,50,-6,minecraft:netherrack)
B(4,51,-6,minecraft:netherrack)
B(4,52,-6,minecraft:netherrack)
B(4,53,-6,minecraft:netherrack)
B(4,54,-6,minecraft:netherrack)
B(4,55,-6,minecraft:netherrack)
B(4,44,-5,minecraft:netherrack)
B(4,45,-5,minecraft:netherrack)
B(4,46,-5,minecraft:netherrack)
B(4,47,-5,minecraft:netherrack)
B(4,48,-5,minecraft:netherrack)
B(4,49,-5,minecraft:netherrack)
B(4,50,-5,minecraft:netherrack)
B(4,51,-5,minecraft:netherrack)
B(4,52,-5,minecraft:netherrack)
B(4,53,-5,minecraft:netherrack)
B(4,54,-5,minecraft:netherrack)
B(4,55,-5,minecraft:netherrack)
B(4,42,-4,minecraft:netherrack)
B(4,43,-4,minecraft:netherrack)
B(4,44,-4,minecraft:netherrack)
B(4,45,-4,minecraft:netherrack)
B(4,46,-4,minecraft:netherrack)
B(4,47,-4,minecraft:netherrack)
B(4,48,-4,minecraft:netherrack)
B(4,49,-4,minecraft:netherrack)
B(4,50,-4,minecraft:netherrack)
B(4,51,-4,minecraft:netherrack)
B(4,52,-4,minecraft:netherrack)
B(4,53,-4,minecraft:netherrack)
B(4,54,-4,minecraft:netherrack)
B(4,55,-4,minecraft:netherrack)
B(4,41,-3,minecraft:netherrack)
B(4,42,-3,minecraft:netherrack)
B(4,43,-3,minecraft:netherrack)
B(4,44,-3,minecraft:netherrack)
B(4,45,-3,minecraft:netherrack)
B(4,46,-3,minecraft:netherrack)
B(4,47,-3,minecraft:netherrack)
B(4,48,-3,minecraft:netherrack)
B(4,49,-3,minecraft:netherrack)
B(4,50,-3,minecraft:netherrack)
B(4,51,-3,minecraft:netherrack)
B(4,52,-3,minecraft:netherrack)
B(4,53,-3,minecraft:netherrack)
B(4,54,-3,minecraft:netherrack)
B(4,55,-3,minecraft:netherrack)
B(4,40,-2,minecraft:netherrack)
B(4,41,-2,minecraft:netherrack)
B(4,42,-2,minecraft:netherrack)
B(4,43,-2,minecraft:netherrack)
B(4,44,-2,minecraft:netherrack)
B(4,45,-2,minecraft:netherrack)
B(4,46,-2,minecraft:netherrack)
B(4,47,-2,minecraft:netherrack)
B(4,48,-2,minecraft:netherrack)
B(4,49,-2,minecraft:netherrack)
B(4,50,-2,minecraft:netherrack)
B(4,51,-2,minecraft:netherrack)
B(4,52,-2,minecraft:netherrack)
B(4,53,-2,minecraft:netherrack)
B(4,54,-2,minecraft:netherrack)
B(4,55,-2,minecraft:netherrack)
B(4,39,-1,minecraft:netherrack)
B(4,40,-1,minecraft:netherrack)
B(4,41,-1,minecraft:netherrack)
B(4,42,-1,minecraft:netherrack)
B(4,43,-1,minecraft:netherrack)
B(4,44,-1,minecraft:netherrack)
B(4,45,-1,minecraft:netherrack)
B(4,46,-1,minecraft:netherrack)
B(4,47,-1,minecraft:netherrack)
B(4,48,-1,minecraft:netherrack)
B(4,49,-1,minecraft:netherrack)
B(4,50,-1,minecraft:netherrack)
B(4,51,-1,minecraft:netherrack)
B(4,52,-1,minecraft:netherrack)
B(4,53,-1,minecraft:netherrack)
B(4,54,-1,minecraft:netherrack)
B(4,55,-1,minecraft:netherrack)
B(4,38,0,minecraft:netherrack)
B(4,39,0,minecraft:netherrack)
B(4,40,0,minecraft:netherrack)
B(4,41,0,minecraft:netherrack)
B(4,42,0,minecraft:netherrack)
B(4,43,0,minecraft:netherrack)
B(4,44,0,minecraft:netherrack)
B(4,45,0,minecraft:netherrack)
B(4,46,0,minecraft:netherrack)
B(4,47,0,minecraft:netherrack)
B(4,48,0,minecraft:netherrack)
B(4,49,0,minecraft:netherrack)
B(4,50,0,minecraft:netherrack)
B(4,51,0,minecraft:netherrack)
B(4,52,0,minecraft:netherrack)
B(4,53,0,minecraft:netherrack)
B(4,54,0,minecraft:netherrack)
B(4,55,0,minecraft:netherrack)
B(4,39,1,minecraft:netherrack)
B(4,40,1,minecraft:netherrack)
B(4,41,1,minecraft:netherrack)
B(4,42,1,minecraft:netherrack)
B(4,43,1,minecraft:netherrack)
B(4,44,1,minecraft:netherrack)
B(4,45,1,minecraft:netherrack)
B(4,46,1,minecraft:netherrack)
B(4,47,1,minecraft:netherrack)
B(4,48,1,minecraft:netherrack)
B(4,49,1,minecraft:netherrack)
B(4,50,1,minecraft:netherrack)
B(4,51,1,minecraft:netherrack)
B(4,52,1,minecraft:netherrack)
B(4,53,1,minecraft:netherrack)
B(4,54,1,minecraft:netherrack)
B(4,55,1,minecraft:netherrack)
B(4,39,2,minecraft:netherrack)
B(4,40,2,minecraft:netherrack)
B(4,41,2,minecraft:netherrack)
B(4,42,2,minecraft:netherrack)
B(4,43,2,minecraft:netherrack)
B(4,44,2,minecraft:netherrack)
B(4,45,2,minecraft:netherrack)
B(4,46,2,minecraft:netherrack)
B(4,47,2,minecraft:netherrack)
B(4,48,2,minecraft:netherrack)
B(4,49,2,minecraft:netherrack)
B(4,50,2,minecraft:netherrack)
B(4,51,2,minecraft:netherrack)
B(4,52,2,minecraft:netherrack)
B(4,53,2,minecraft:netherrack)
B(4,54,2,minecraft:netherrack)
B(4,55,2,minecraft:netherrack)
B(4,48,3,minecraft:netherrack)
B(4,49,3,minecraft:netherrack)
B(4,50,3,minecraft:netherrack)
B(4,51,3,minecraft:netherrack)
B(4,52,3,minecraft:netherrack)
B(4,53,3,minecraft:netherrack)
B(4,54,3,minecraft:netherrack)
B(4,55,3,minecraft:netherrack)
B(4,55,5,minecraft:netherrack)
B(4,55,7,minecraft:netherrack)
B(4,55,8,minecraft:netherrack)
B(5,47,-7,minecraft:netherrack)
B(5,48,-7,minecraft:netherrack)
B(5,49,-7,minecraft:netherrack)
B(5,50,-7,minecraft:netherrack)
B(5,51,-7,minecraft:netherrack)
B(5,52,-7,minecraft:netherrack)
B(5,53,-7,minecraft:netherrack)
B(5,54,-7,minecraft:netherrack)
B(5,55,-7,minecraft:netherrack)
B(5,45,-6,minecraft:netherrack)
B(5,46,-6,minecraft:netherrack)
B(5,47,-6,minecraft:netherrack)
B(5,48,-6,minecraft:netherrack)
B(5,49,-6,minecraft:netherrack)
B(5,50,-6,minecraft:netherrack)
B(5,51,-6,minecraft:netherrack)
B(5,52,-6,minecraft:netherrack)
B(5,53,-6,minecraft:netherrack)
B(5,54,-6,minecraft:netherrack)
B(5,55,-6,minecraft:netherrack)
B(5,43,-5,minecraft:netherrack)
B(5,44,-5,minecraft:netherrack)
B(5,45,-5,minecraft:netherrack)
B(5,46,-5,minecraft:netherrack)
B(5,47,-5,minecraft:netherrack)
B(5,48,-5,minecraft:netherrack)
B(5,49,-5,minecraft:netherrack)
B(5,50,-5,minecraft:netherrack)
B(5,51,-5,minecraft:netherrack)
B(5,52,-5,minecraft:netherrack)
B(5,53,-5,minecraft:netherrack)
B(5,54,-5,minecraft:netherrack)
B(5,55,-5,minecraft:netherrack)
B(5,41,-4,minecraft:netherrack)
B(5,42,-4,minecraft:netherrack)
B(5,43,-4,minecraft:netherrack)
B(5,44,-4,minecraft:netherrack)
B(5,45,-4,minecraft:netherrack)
B(5,46,-4,minecraft:netherrack)
B(5,47,-4,minecraft:netherrack)
B(5,48,-4,minecraft:netherrack)
B(5,49,-4,minecraft:netherrack)
B(5,50,-4,minecraft:netherrack)
B(5,51,-4,minecraft:netherrack)
B(5,52,-4,minecraft:netherrack)
B(5,53,-4,minecraft:netherrack)
B(5,54,-4,minecraft:netherrack)
B(5,55,-4,minecraft:netherrack)
B(5,39,-3,minecraft:netherrack)
B(5,40,-3,minecraft:netherrack)
B(5,41,-3,minecraft:netherrack)
B(5,42,-3,minecraft:netherrack)
B(5,43,-3,minecraft:netherrack)
B(5,44,-3,minecraft:netherrack)
B(5,45,-3,minecraft:netherrack)
B(5,46,-3,minecraft:netherrack)
B(5,47,-3,minecraft:netherrack)
B(5,48,-3,minecraft:netherrack)
B(5,49,-3,minecraft:netherrack)
B(5,50,-3,minecraft:netherrack)
B(5,51,-3,minecraft:netherrack)
B(5,52,-3,minecraft:netherrack)
B(5,53,-3,minecraft:netherrack)
B(5,54,-3,minecraft:netherrack)
B(5,55,-3,minecraft:netherrack)
B(5,37,-2,minecraft:netherrack)
B(5,38,-2,minecraft:netherrack)
B(5,39,-2,minecraft:netherrack)
B(5,40,-2,minecraft:netherrack)
B(5,41,-2,minecraft:netherrack)
B(5,42,-2,minecraft:netherrack)
B(5,43,-2,minecraft:netherrack)
B(5,44,-2,minecraft:netherrack)
B(5,45,-2,minecraft:netherrack)
B(5,46,-2,minecraft:netherrack)
B(5,47,-2,minecraft:netherrack)
B(5,48,-2,minecraft:netherrack)
B(5,49,-2,minecraft:netherrack)
B(5,50,-2,minecraft:netherrack)
B(5,51,-2,minecraft:netherrack)
B(5,52,-2,minecraft:netherrack)
B(5,53,-2,minecraft:netherrack)
B(5,54,-2,minecraft:netherrack)
B(5,55,-2,minecraft:netherrack)
B(5,36,-1,minecraft:netherrack)
B(5,37,-1,minecraft:netherrack)
B(5,38,-1,minecraft:netherrack)
B(5,39,-1,minecraft:netherrack)
B(5,40,-1,minecraft:netherrack)
B(5,41,-1,minecraft:netherrack)
B(5,42,-1,minecraft:netherrack)
B(5,43,-1,minecraft:netherrack)
B(5,44,-1,minecraft:netherrack)
B(5,45,-1,minecraft:netherrack)
B(5,46,-1,minecraft:netherrack)
B(5,47,-1,minecraft:netherrack)
B(5,48,-1,minecraft:netherrack)
B(5,49,-1,minecraft:netherrack)
B(5,50,-1,minecraft:netherrack)
B(5,51,-1,minecraft:netherrack)
B(5,52,-1,minecraft:netherrack)
B(5,53,-1,minecraft:netherrack)
B(5,54,-1,minecraft:netherrack)
B(5,55,-1,minecraft:netherrack)
B(5,36,0,minecraft:netherrack)
B(5,37,0,minecraft:netherrack)
B(5,38,0,minecraft:netherrack)
B(5,39,0,minecraft:netherrack)
B(5,40,0,minecraft:netherrack)
B(5,41,0,minecraft:netherrack)
B(5,42,0,minecraft:netherrack)
B(5,43,0,minecraft:netherrack)
B(5,44,0,minecraft:netherrack)
B(5,45,0,minecraft:netherrack)
B(5,46,0,minecraft:netherrack)
B(5,47,0,minecraft:netherrack)
B(5,48,0,minecraft:netherrack)
B(5,49,0,minecraft:netherrack)
B(5,50,0,minecraft:netherrack)
B(5,51,0,minecraft:netherrack)
B(5,52,0,minecraft:netherrack)
B(5,53,0,minecraft:netherrack)
B(5,54,0,minecraft:netherrack)
B(5,55,0,minecraft:netherrack)
B(5,36,1,minecraft:netherrack)
B(5,37,1,minecraft:netherrack)
B(5,38,1,minecraft:netherrack)
B(5,39,1,minecraft:netherrack)
B(5,40,1,minecraft:netherrack)
B(5,41,1,minecraft:netherrack)
B(5,42,1,minecraft:netherrack)
B(5,43,1,minecraft:netherrack)
B(5,44,1,minecraft:netherrack)
B(5,45,1,minecraft:netherrack)
B(5,46,1,minecraft:netherrack)
B(5,47,1,minecraft:netherrack)
B(5,48,1,minecraft:netherrack)
B(5,49,1,minecraft:netherrack)
B(5,50,1,minecraft:netherrack)
B(5,51,1,minecraft:netherrack)
B(5,52,1,minecraft:netherrack)
B(5,53,1,minecraft:netherrack)
B(5,54,1,minecraft:netherrack)
B(5,55,1,minecraft:netherrack)
B(5,36,2,minecraft:netherrack)
B(5,37,2,minecraft:netherrack)
B(5,38,2,minecraft:netherrack)
B(5,39,2,minecraft:netherrack)
B(5,40,2,minecraft:netherrack)
B(5,41,2,minecraft:netherrack)
B(5,42,2,minecraft:netherrack)
B(5,43,2,minecraft:netherrack)
B(5,44,2,minecraft:netherrack)
B(5,45,2,minecraft:netherrack)
B(5,46,2,minecraft:netherrack)
B(5,47,2,minecraft:netherrack)
B(5,48,2,minecraft:netherrack)
B(5,49,2,minecraft:netherrack)
B(5,50,2,minecraft:netherrack)
B(5,51,2,minecraft:netherrack)
B(5,52,2,minecraft:netherrack)
B(5,53,2,minecraft:netherrack)
B(5,54,2,minecraft:netherrack)
B(5,55,2,minecraft:netherrack)
B(5,35,3,minecraft:netherrack)
B(5,36,3,minecraft:netherrack)
B(5,37,3,minecraft:netherrack)
B(5,38,3,minecraft:netherrack)
B(5,39,3,minecraft:netherrack)
B(5,40,3,minecraft:netherrack)
B(5,41,3,minecraft:netherrack)
B(5,42,3,minecraft:netherrack)
B(5,43,3,minecraft:netherrack)
B(5,44,3,minecraft:netherrack)
B(5,45,3,minecraft:netherrack)
B(5,46,3,minecraft:netherrack)
B(5,47,3,minecraft:netherrack)
B(5,48,3,minecraft:netherrack)
B(5,49,3,minecraft:netherrack)
B(5,50,3,minecraft:netherrack)
B(5,51,3,minecraft:netherrack)
B(5,52,3,minecraft:netherrack)
B(5,53,3,minecraft:netherrack)
B(5,54,3,minecraft:netherrack)
B(5,55,3,minecraft:netherrack)
B(5,43,4,minecraft:netherrack)
B(5,44,4,minecraft:netherrack)
B(5,45,4,minecraft:netherrack)
B(5,46,4,minecraft:netherrack)
B(5,47,4,minecraft:netherrack)
B(5,48,4,minecraft:netherrack)
B(5,49,4,minecraft:netherrack)
B(5,50,4,minecraft:netherrack)
B(5,51,4,minecraft:netherrack)
B(5,52,4,minecraft:netherrack)
B(5,53,4,minecraft:netherrack)
B(5,54,4,minecraft:netherrack)
B(5,55,4,minecraft:netherrack)
B(5,53,7,minecraft:netherrack)
B(5,54,7,minecraft:netherrack)
B(5,55,7,minecraft:netherrack)
B(5,53,8,minecraft:netherrack)
B(5,54,8,minecraft:netherrack)
B(5,55,8,minecraft:netherrack)
B(6,46,-7,minecraft:netherrack)
B(6,47,-7,minecraft:netherrack)
B(6,48,-7,minecraft:netherrack)
B(6,49,-7,minecraft:netherrack)
B(6,50,-7,minecraft:netherrack)
B(6,51,-7,minecraft:netherrack)
B(6,52,-7,minecraft:netherrack)
B(6,53,-7,minecraft:netherrack)
B(6,54,-7,minecraft:netherrack)
B(6,55,-7,minecraft:netherrack)
B(6,44,-6,minecraft:netherrack)
B(6,45,-6,minecraft:netherrack)
B(6,46,-6,minecraft:netherrack)
B(6,47,-6,minecraft:netherrack)
B(6,48,-6,minecraft:netherrack)
B(6,49,-6,minecraft:netherrack)
B(6,50,-6,minecraft:netherrack)
B(6,51,-6,minecraft:netherrack)
B(6,52,-6,minecraft:netherrack)
B(6,53,-6,minecraft:netherrack)
B(6,54,-6,minecraft:netherrack)
B(6,55,-6,minecraft:netherrack)
B(6,42,-5,minecraft:netherrack)
B(6,43,-5,minecraft:netherrack)
B(6,44,-5,minecraft:netherrack)
B(6,45,-5,minecraft:netherrack)
B(6,46,-5,minecraft:netherrack)
B(6,47,-5,minecraft:netherrack)
B(6,48,-5,minecraft:netherrack)
B(6,49,-5,minecraft:netherrack)
B(6,50,-5,minecraft:netherrack)
B(6,51,-5,minecraft:netherrack)
B(6,52,-5,minecraft:netherrack)
B(6,53,-5,minecraft:netherrack)
B(6,54,-5,minecraft:netherrack)
B(6,55,-5,minecraft:netherrack)
B(6,40,-4,minecraft:netherrack)
B(6,41,-4,minecraft:netherrack)
B(6,42,-4,minecraft:netherrack)
B(6,43,-4,minecraft:netherrack)
B(6,44,-4,minecraft:netherrack)
B(6,45,-4,minecraft:netherrack)
B(6,46,-4,minecraft:netherrack)
B(6,47,-4,minecraft:netherrack)
B(6,48,-4,minecraft:netherrack)
B(6,49,-4,minecraft:netherrack)
B(6,50,-4,minecraft:netherrack)
B(6,51,-4,minecraft:netherrack)
B(6,52,-4,minecraft:netherrack)
B(6,53,-4,minecraft:netherrack)
B(6,54,-4,minecraft:netherrack)
B(6,55,-4,minecraft:netherrack)
B(6,37,-3,minecraft:netherrack)
B(6,38,-3,minecraft:netherrack)
B(6,39,-3,minecraft:netherrack)
B(6,40,-3,minecraft:netherrack)
B(6,41,-3,minecraft:netherrack)
B(6,42,-3,minecraft:netherrack)
B(6,43,-3,minecraft:netherrack)
B(6,44,-3,minecraft:netherrack)
B(6,45,-3,minecraft:netherrack)
B(6,46,-3,minecraft:netherrack)
B(6,47,-3,minecraft:netherrack)
B(6,48,-3,minecraft:netherrack)
B(6,49,-3,minecraft:netherrack)
B(6,50,-3,minecraft:netherrack)
B(6,51,-3,minecraft:netherrack)
B(6,52,-3,minecraft:netherrack)
B(6,53,-3,minecraft:netherrack)
B(6,54,-3,minecraft:netherrack)
B(6,55,-3,minecraft:netherrack)
B(6,36,-2,minecraft:netherrack)
B(6,37,-2,minecraft:netherrack)
B(6,38,-2,minecraft:netherrack)
B(6,39,-2,minecraft:netherrack)
B(6,40,-2,minecraft:netherrack)
B(6,41,-2,minecraft:netherrack)
B(6,42,-2,minecraft:netherrack)
B(6,43,-2,minecraft:netherrack)
B(6,44,-2,minecraft:netherrack)
B(6,45,-2,minecraft:netherrack)
B(6,46,-2,minecraft:netherrack)
B(6,47,-2,minecraft:netherrack)
B(6,48,-2,minecraft:netherrack)
B(6,49,-2,minecraft:netherrack)
B(6,50,-2,minecraft:netherrack)
B(6,51,-2,minecraft:netherrack)
B(6,52,-2,minecraft:netherrack)
B(6,53,-2,minecraft:netherrack)
B(6,54,-2,minecraft:netherrack)
B(6,55,-2,minecraft:netherrack)
B(6,35,-1,minecraft:netherrack)
B(6,36,-1,minecraft:netherrack)
B(6,37,-1,minecraft:netherrack)
B(6,38,-1,minecraft:netherrack)
B(6,39,-1,minecraft:netherrack)
B(6,40,-1,minecraft:netherrack)
B(6,41,-1,minecraft:netherrack)
B(6,42,-1,minecraft:netherrack)
B(6,43,-1,minecraft:netherrack)
B(6,44,-1,minecraft:netherrack)
B(6,45,-1,minecraft:netherrack)
B(6,46,-1,minecraft:netherrack)
B(6,47,-1,minecraft:netherrack)
B(6,48,-1,minecraft:netherrack)
B(6,49,-1,minecraft:netherrack)
B(6,50,-1,minecraft:netherrack)
B(6,51,-1,minecraft:netherrack)
B(6,52,-1,minecraft:netherrack)
B(6,53,-1,minecraft:netherrack)
B(6,54,-1,minecraft:netherrack)
B(6,55,-1,minecraft:netherrack)
B(6,34,0,minecraft:netherrack)
B(6,35,0,minecraft:netherrack)
B(6,36,0,minecraft:netherrack)
B(6,37,0,minecraft:netherrack)
B(6,38,0,minecraft:netherrack)
B(6,39,0,minecraft:netherrack)
B(6,40,0,minecraft:netherrack)
B(6,41,0,minecraft:netherrack)
B(6,42,0,minecraft:netherrack)
B(6,43,0,minecraft:netherrack)
B(6,44,0,minecraft:netherrack)
B(6,45,0,minecraft:netherrack)
B(6,46,0,minecraft:netherrack)
B(6,47,0,minecraft:netherrack)
B(6,48,0,minecraft:netherrack)
B(6,49,0,minecraft:netherrack)
B(6,50,0,minecraft:netherrack)
B(6,51,0,minecraft:netherrack)
B(6,52,0,minecraft:netherrack)
B(6,53,0,minecraft:netherrack)
B(6,54,0,minecraft:netherrack)
B(6,55,0,minecraft:netherrack)
B(6,34,1,minecraft:netherrack)
B(6,35,1,minecraft:netherrack)
B(6,36,1,minecraft:netherrack)
B(6,37,1,minecraft:netherrack)
B(6,38,1,minecraft:netherrack)
B(6,39,1,minecraft:netherrack)
B(6,40,1,minecraft:netherrack)
B(6,41,1,minecraft:netherrack)
B(6,42,1,minecraft:netherrack)
B(6,43,1,minecraft:netherrack)
B(6,44,1,minecraft:netherrack)
B(6,45,1,minecraft:netherrack)
B(6,46,1,minecraft:netherrack)
B(6,47,1,minecraft:netherrack)
B(6,48,1,minecraft:netherrack)
B(6,49,1,minecraft:netherrack)
B(6,50,1,minecraft:netherrack)
B(6,51,1,minecraft:netherrack)
B(6,52,1,minecraft:netherrack)
B(6,53,1,minecraft:netherrack)
B(6,54,1,minecraft:netherrack)
B(6,55,1,minecraft:netherrack)
B(6,34,2,minecraft:netherrack)
B(6,35,2,minecraft:netherrack)
B(6,36,2,minecraft:netherrack)
B(6,37,2,minecraft:netherrack)
B(6,38,2,minecraft:netherrack)
B(6,39,2,minecraft:netherrack)
B(6,40,2,minecraft:netherrack)
B(6,41,2,minecraft:netherrack)
B(6,42,2,minecraft:netherrack)
B(6,43,2,minecraft:netherrack)
B(6,44,2,minecraft:netherrack)
B(6,45,2,minecraft:netherrack)
B(6,46,2,minecraft:netherrack)
B(6,47,2,minecraft:netherrack)
B(6,48,2,minecraft:netherrack)
B(6,49,2,minecraft:netherrack)
B(6,50,2,minecraft:netherrack)
B(6,51,2,minecraft:netherrack)
B(6,52,2,minecraft:netherrack)
B(6,53,2,minecraft:netherrack)
B(6,54,2,minecraft:netherrack)
B(6,55,2,minecraft:netherrack)
B(6,33,3,minecraft:netherrack)
B(6,34,3,minecraft:netherrack)
B(6,35,3,minecraft:netherrack)
B(6,36,3,minecraft:netherrack)
B(6,37,3,minecraft:netherrack)
B(6,38,3,minecraft:netherrack)
B(6,39,3,minecraft:netherrack)
B(6,40,3,minecraft:netherrack)
B(6,41,3,minecraft:netherrack)
B(6,42,3,minecraft:netherrack)
B(6,43,3,minecraft:netherrack)
B(6,44,3,minecraft:netherrack)
B(6,45,3,minecraft:netherrack)
B(6,46,3,minecraft:netherrack)
B(6,47,3,minecraft:netherrack)
B(6,48,3,minecraft:netherrack)
B(6,49,3,minecraft:netherrack)
B(6,50,3,minecraft:netherrack)
B(6,51,3,minecraft:netherrack)
B(6,52,3,minecraft:netherrack)
B(6,53,3,minecraft:netherrack)
B(6,54,3,minecraft:netherrack)
B(6,55,3,minecraft:netherrack)
B(6,39,4,minecraft:netherrack)
B(6,40,4,minecraft:netherrack)
B(6,41,4,minecraft:netherrack)
B(6,42,4,minecraft:netherrack)
B(6,43,4,minecraft:netherrack)
B(6,44,4,minecraft:netherrack)
B(6,45,4,minecraft:netherrack)
B(6,46,4,minecraft:netherrack)
B(6,47,4,minecraft:netherrack)
B(6,48,4,minecraft:netherrack)
B(6,49,4,minecraft:netherrack)
B(6,50,4,minecraft:netherrack)
B(6,51,4,minecraft:netherrack)
B(6,52,4,minecraft:netherrack)
B(6,53,4,minecraft:netherrack)
B(6,54,4,minecraft:netherrack)
B(6,55,4,minecraft:netherrack)
B(6,43,5,minecraft:netherrack)
B(6,44,5,minecraft:netherrack)
B(6,45,5,minecraft:netherrack)
B(6,46,5,minecraft:netherrack)
B(6,47,5,minecraft:netherrack)
B(6,48,5,minecraft:netherrack)
B(6,49,5,minecraft:netherrack)
B(6,50,5,minecraft:netherrack)
B(6,51,5,minecraft:netherrack)
B(6,52,5,minecraft:netherrack)
B(6,53,5,minecraft:netherrack)
B(6,54,5,minecraft:netherrack)
B(6,55,5,minecraft:netherrack)
B(6,50,7,minecraft:netherrack)
B(6,51,7,minecraft:netherrack)
B(6,52,7,minecraft:netherrack)
B(6,53,7,minecraft:netherrack)
B(6,54,7,minecraft:netherrack)
B(6,55,7,minecraft:netherrack)
B(6,50,8,minecraft:netherrack)
B(6,51,8,minecraft:netherrack)
B(6,52,8,minecraft:netherrack)
B(6,53,8,minecraft:netherrack)
B(6,54,8,minecraft:netherrack)
B(6,55,8,minecraft:netherrack)
B(7,46,-7,minecraft:netherrack)
B(7,47,-7,minecraft:netherrack)
B(7,48,-7,minecraft:netherrack)
B(7,49,-7,minecraft:netherrack)
B(7,50,-7,minecraft:netherrack)
B(7,51,-7,minecraft:netherrack)
B(7,52,-7,minecraft:netherrack)
B(7,53,-7,minecraft:netherrack)
B(7,54,-7,minecraft:netherrack)
B(7,55,-7,minecraft:netherrack)
B(7,44,-6,minecraft:netherrack)
B(7,45,-6,minecraft:netherrack)
B(7,46,-6,minecraft:netherrack)
B(7,47,-6,minecraft:netherrack)
B(7,48,-6,minecraft:netherrack)
B(7,49,-6,minecraft:netherrack)
B(7,50,-6,minecraft:netherrack)
B(7,51,-6,minecraft:netherrack)
B(7,52,-6,minecraft:netherrack)
B(7,53,-6,minecraft:netherrack)
B(7,54,-6,minecraft:netherrack)
B(7,55,-6,minecraft:netherrack)
B(7,41,-5,minecraft:netherrack)
B(7,42,-5,minecraft:netherrack)
B(7,43,-5,minecraft:netherrack)
B(7,44,-5,minecraft:netherrack)
B(7,45,-5,minecraft:netherrack)
B(7,46,-5,minecraft:netherrack)
B(7,47,-5,minecraft:netherrack)
B(7,48,-5,minecraft:netherrack)
B(7,49,-5,minecraft:netherrack)
B(7,50,-5,minecraft:netherrack)
B(7,51,-5,minecraft:netherrack)
B(7,52,-5,minecraft:netherrack)
B(7,53,-5,minecraft:netherrack)
B(7,54,-5,minecraft:netherrack)
B(7,55,-5,minecraft:netherrack)
B(7,39,-4,minecraft:netherrack)
B(7,40,-4,minecraft:netherrack)
B(7,41,-4,minecraft:netherrack)
B(7,42,-4,minecraft:netherrack)
B(7,43,-4,minecraft:netherrack)
B(7,44,-4,minecraft:netherrack)
B(7,45,-4,minecraft:netherrack)
B(7,46,-4,minecraft:netherrack)
B(7,47,-4,minecraft:netherrack)
B(7,48,-4,minecraft:netherrack)
B(7,49,-4,minecraft:netherrack)
B(7,50,-4,minecraft:netherrack)
B(7,51,-4,minecraft:netherrack)
B(7,52,-4,minecraft:netherrack)
B(7,53,-4,minecraft:netherrack)
B(7,54,-4,minecraft:netherrack)
B(7,55,-4,minecraft:netherrack)
B(7,37,-3,minecraft:netherrack)
B(7,38,-3,minecraft:netherrack)
B(7,39,-3,minecraft:netherrack)
B(7,40,-3,minecraft:netherrack)
B(7,41,-3,minecraft:netherrack)
B(7,42,-3,minecraft:netherrack)
B(7,43,-3,minecraft:netherrack)
B(7,44,-3,minecraft:netherrack)
B(7,45,-3,minecraft:netherrack)
B(7,46,-3,minecraft:netherrack)
B(7,47,-3,minecraft:netherrack)
B(7,48,-3,minecraft:netherrack)
B(7,49,-3,minecraft:netherrack)
B(7,50,-3,minecraft:netherrack)
B(7,51,-3,minecraft:netherrack)
B(7,52,-3,minecraft:netherrack)
B(7,53,-3,minecraft:netherrack)
B(7,54,-3,minecraft:netherrack)
B(7,55,-3,minecraft:netherrack)
B(7,35,-2,minecraft:netherrack)
B(7,36,-2,minecraft:netherrack)
B(7,37,-2,minecraft:netherrack)
B(7,38,-2,minecraft:netherrack)
B(7,39,-2,minecraft:netherrack)
B(7,40,-2,minecraft:netherrack)
B(7,41,-2,minecraft:netherrack)
B(7,42,-2,minecraft:netherrack)
B(7,43,-2,minecraft:netherrack)
B(7,44,-2,minecraft:netherrack)
B(7,45,-2,minecraft:netherrack)
B(7,46,-2,minecraft:netherrack)
B(7,47,-2,minecraft:netherrack)
B(7,48,-2,minecraft:netherrack)
B(7,49,-2,minecraft:netherrack)
B(7,50,-2,minecraft:netherrack)
B(7,51,-2,minecraft:netherrack)
B(7,52,-2,minecraft:netherrack)
B(7,53,-2,minecraft:netherrack)
B(7,54,-2,minecraft:netherrack)
B(7,55,-2,minecraft:netherrack)
B(7,34,-1,minecraft:netherrack)
B(7,35,-1,minecraft:netherrack)
B(7,36,-1,minecraft:netherrack)
B(7,37,-1,minecraft:netherrack)
B(7,38,-1,minecraft:netherrack)
B(7,39,-1,minecraft:netherrack)
B(7,40,-1,minecraft:netherrack)
B(7,41,-1,minecraft:netherrack)
B(7,42,-1,minecraft:netherrack)
B(7,43,-1,minecraft:netherrack)
B(7,44,-1,minecraft:netherrack)
B(7,45,-1,minecraft:netherrack)
B(7,46,-1,minecraft:netherrack)
B(7,47,-1,minecraft:netherrack)
B(7,48,-1,minecraft:netherrack)
B(7,49,-1,minecraft:netherrack)
B(7,50,-1,minecraft:netherrack)
B(7,51,-1,minecraft:netherrack)
B(7,52,-1,minecraft:netherrack)
B(7,53,-1,minecraft:netherrack)
B(7,54,-1,minecraft:netherrack)
B(7,55,-1,minecraft:netherrack)
B(7,33,0,minecraft:netherrack)
B(7,34,0,minecraft:netherrack)
B(7,35,0,minecraft:netherrack)
B(7,36,0,minecraft:netherrack)
B(7,37,0,minecraft:netherrack)
B(7,38,0,minecraft:netherrack)
B(7,39,0,minecraft:netherrack)
B(7,40,0,minecraft:netherrack)
B(7,41,0,minecraft:netherrack)
B(7,42,0,minecraft:netherrack)
B(7,43,0,minecraft:netherrack)
B(7,44,0,minecraft:netherrack)
B(7,45,0,minecraft:netherrack)
B(7,46,0,minecraft:netherrack)
B(7,47,0,minecraft:netherrack)
B(7,48,0,minecraft:netherrack)
B(7,49,0,minecraft:netherrack)
B(7,50,0,minecraft:netherrack)
B(7,51,0,minecraft:netherrack)
B(7,52,0,minecraft:netherrack)
B(7,53,0,minecraft:netherrack)
B(7,54,0,minecraft:netherrack)
B(7,55,0,minecraft:netherrack)
B(7,33,1,minecraft:netherrack)
B(7,34,1,minecraft:netherrack)
B(7,35,1,minecraft:netherrack)
B(7,36,1,minecraft:netherrack)
B(7,37,1,minecraft:netherrack)
B(7,38,1,minecraft:netherrack)
B(7,39,1,minecraft:netherrack)
B(7,40,1,minecraft:netherrack)
B(7,41,1,minecraft:netherrack)
B(7,42,1,minecraft:netherrack)
B(7,43,1,minecraft:netherrack)
B(7,44,1,minecraft:netherrack)
B(7,45,1,minecraft:netherrack)
B(7,46,1,minecraft:netherrack)
B(7,47,1,minecraft:netherrack)
B(7,48,1,minecraft:netherrack)
B(7,49,1,minecraft:netherrack)
B(7,50,1,minecraft:netherrack)
B(7,51,1,minecraft:netherrack)
B(7,52,1,minecraft:netherrack)
B(7,53,1,minecraft:netherrack)
B(7,54,1,minecraft:netherrack)
B(7,55,1,minecraft:netherrack)
B(7,33,2,minecraft:netherrack)
B(7,34,2,minecraft:netherrack)
B(7,35,2,minecraft:netherrack)
B(7,36,2,minecraft:netherrack)
B(7,37,2,minecraft:netherrack)
B(7,38,2,minecraft:netherrack)
B(7,39,2,minecraft:netherrack)
B(7,40,2,minecraft:netherrack)
B(7,41,2,minecraft:netherrack)
B(7,42,2,minecraft:netherrack)
B(7,43,2,minecraft:netherrack)
B(7,44,2,minecraft:netherrack)
B(7,45,2,minecraft:netherrack)
B(7,46,2,minecraft:netherrack)
B(7,47,2,minecraft:netherrack)
B(7,48,2,minecraft:netherrack)
B(7,49,2,minecraft:netherrack)
B(7,50,2,minecraft:netherrack)
B(7,51,2,minecraft:netherrack)
B(7,52,2,minecraft:netherrack)
B(7,53,2,minecraft:netherrack)
B(7,54,2,minecraft:netherrack)
B(7,55,2,minecraft:netherrack)
B(7,31,3,minecraft:netherrack)
B(7,32,3,minecraft:netherrack)
B(7,33,3,minecraft:netherrack)
B(7,34,3,minecraft:netherrack)
B(7,35,3,minecraft:netherrack)
B(7,36,3,minecraft:netherrack)
B(7,37,3,minecraft:netherrack)
B(7,38,3,minecraft:netherrack)
B(7,39,3,minecraft:netherrack)
B(7,40,3,minecraft:netherrack)
B(7,41,3,minecraft:netherrack)
B(7,42,3,minecraft:netherrack)
B(7,43,3,minecraft:netherrack)
B(7,44,3,minecraft:netherrack)
B(7,45,3,minecraft:netherrack)
B(7,46,3,minecraft:netherrack)
B(7,47,3,minecraft:netherrack)
B(7,48,3,minecraft:netherrack)
B(7,49,3,minecraft:netherrack)
B(7,50,3,minecraft:netherrack)
B(7,51,3,minecraft:netherrack)
B(7,52,3,minecraft:netherrack)
B(7,53,3,minecraft:netherrack)
B(7,54,3,minecraft:netherrack)
B(7,55,3,minecraft:netherrack)
B(7,32,4,minecraft:netherrack)
B(7,33,4,minecraft:netherrack)
B(7,34,4,minecraft:netherrack)
B(7,35,4,minecraft:netherrack)
B(7,36,4,minecraft:netherrack)
B(7,37,4,minecraft:netherrack)
B(7,38,4,minecraft:netherrack)
B(7,39,4,minecraft:netherrack)
B(7,40,4,minecraft:netherrack)
B(7,41,4,minecraft:netherrack)
B(7,42,4,minecraft:netherrack)
B(7,43,4,minecraft:netherrack)
B(7,44,4,minecraft:netherrack)
B(7,45,4,minecraft:netherrack)
B(7,46,4,minecraft:netherrack)
B(7,47,4,minecraft:netherrack)
B(7,48,4,minecraft:netherrack)
B(7,49,4,minecraft:netherrack)
B(7,50,4,minecraft:netherrack)
B(7,51,4,minecraft:netherrack)
B(7,52,4,minecraft:netherrack)
B(7,53,4,minecraft:netherrack)
B(7,54,4,minecraft:netherrack)
B(7,55,4,minecraft:netherrack)
B(7,37,5,minecraft:netherrack)
B(7,38,5,minecraft:netherrack)
B(7,39,5,minecraft:netherrack)
B(7,40,5,minecraft:netherrack)
B(7,41,5,minecraft:netherrack)
B(7,42,5,minecraft:netherrack)
B(7,43,5,minecraft:netherrack)
B(7,44,5,minecraft:netherrack)
B(7,45,5,minecraft:netherrack)
B(7,46,5,minecraft:netherrack)
B(7,47,5,minecraft:netherrack)
B(7,48,5,minecraft:netherrack)
B(7,49,5,minecraft:netherrack)
B(7,50,5,minecraft:netherrack)
B(7,51,5,minecraft:netherrack)
B(7,52,5,minecraft:netherrack)
B(7,53,5,minecraft:netherrack)
B(7,54,5,minecraft:netherrack)
B(7,55,5,minecraft:netherrack)
B(7,47,6,minecraft:netherrack)
B(7,48,6,minecraft:netherrack)
B(7,49,6,minecraft:netherrack)
B(7,50,6,minecraft:netherrack)
B(7,51,6,minecraft:netherrack)
B(7,52,6,minecraft:netherrack)
B(7,53,6,minecraft:netherrack)
B(7,54,6,minecraft:netherrack)
B(7,55,6,minecraft:netherrack)
B(7,47,7,minecraft:netherrack)
B(7,48,7,minecraft:netherrack)
B(7,49,7,minecraft:netherrack)
B(7,50,7,minecraft:netherrack)
B(7,51,7,minecraft:netherrack)
B(7,52,7,minecraft:netherrack)
B(7,53,7,minecraft:netherrack)
B(7,54,7,minecraft:netherrack)
B(7,55,7,minecraft:netherrack)
B(7,47,8,minecraft:netherrack)
B(7,48,8,minecraft:netherrack)
B(7,49,8,minecraft:netherrack)
B(7,50,8,minecraft:netherrack)
B(7,51,8,minecraft:netherrack)
B(7,52,8,minecraft:netherrack)
B(7,53,8,minecraft:netherrack)
B(7,54,8,minecraft:netherrack)
B(7,55,8,minecraft:netherrack)

#######################################################################
# +-----------------------------------------------------------------+ #
# |                             Branches                            | #
# +-----------------------------------------------------------------+ #
#######################################################################

Branch(16,0,0,true,GiantNetherrackStalactite3_C1_R1,NORTH,100.0,0)
Branch(0,0,16,true,GiantNetherrackStalactite3_C0_R2,NORTH,100.0,0)

#######################################################################
# +-----------------------------------------------------------------+ #
# |                             Entities                            | #
# +-----------------------------------------------------------------+ #
#######################################################################

