
#######################################################################
# +-----------------------------------------------------------------+ #
# |                            BO4 object                           | #
# +-----------------------------------------------------------------+ #
#######################################################################

Author: Unknown

Description: No description given

SettingsMode: WriteWithoutComments


#######################################################################
# +-----------------------------------------------------------------+ #
# |                          Main settings                          | #
# +-----------------------------------------------------------------+ #
#######################################################################

FixedRotation: 

Frequency: 0

SpawnHeight: highestBlock

UseCenterForHighestBlock: true

##############################
# Height Limits for the BO4. #
##############################

MinHeight: 0

MaxHeight: 255

InheritBO3: 

InheritBO3Rotation: NORTH

OverrideChildSettings: true

OverrideParentHeight: false

CanOverride: false

BranchFrequency: 0

BranchFrequencyGroup: 

MustBeBelowOther: false

MustBeInside: 

CannotBeInside: 

ReplacesBO3: 

MustBeInsideWorldBorders: false

CanSpawnOnWater: true

SpawnOnWaterOnly: false

SpawnUnderWater: false

SpawnAtWaterLevel: false

HeightOffset: 0

RemoveAir: true

ReplaceAbove: 

ReplaceBelow: 

ReplaceWithBiomeBlocks: true

ReplaceWithSurfaceBlock: GRASS

ReplaceWithGroundBlock: DIRT

ReplaceWithStoneBlock: STONE

SmoothRadius: 0

SmoothHeightOffset: 0

SmoothStartTop: false

SmoothStartWood: false

SmoothingSurfaceBlock: 

SmoothingGroundBlock: 

BO3Group: 

IsSpawnPoint: false

DoReplaceBlocks: true


#######################################################################
# +-----------------------------------------------------------------+ #
# |                              Blocks                             | #
# +-----------------------------------------------------------------+ #
#######################################################################

B(-8,0,-7,minecraft:lava)
B(-8,1,-7,minecraft:lava)
B(-8,2,-7,minecraft:lava)
B(-8,3,-7,minecraft:lava)
B(-8,4,-7,minecraft:lava[level=2])
B(-8,0,-6,minecraft:lava)
B(-8,1,-6,minecraft:lava)
B(-8,2,-6,minecraft:lava)
B(-8,3,-6,minecraft:lava)
B(-8,4,-6,minecraft:lava[level=2])
B(-8,0,-5,minecraft:lava)
B(-8,1,-5,minecraft:lava)
B(-8,2,-5,minecraft:lava)
B(-8,3,-5,minecraft:lava)
B(-8,0,-4,minecraft:lava)
B(-8,1,-4,minecraft:lava)
B(-8,2,-4,minecraft:lava)
B(-8,3,-4,minecraft:lava)
B(-8,0,-3,minecraft:lava)
B(-8,1,-3,minecraft:lava)
B(-8,2,-3,minecraft:lava[level=8])
B(-8,3,-3,minecraft:lava[level=2])
B(-8,0,-2,minecraft:lava)
B(-8,1,-2,minecraft:lava)
B(-8,0,-1,minecraft:lava)
B(-8,1,-1,minecraft:lava[level=2])
B(-8,0,0,minecraft:lava)
B(-8,0,1,minecraft:lava)
B(-8,0,2,minecraft:lava)
B(-8,0,3,minecraft:lava)
B(-8,0,4,minecraft:lava[level=2])
B(-8,0,5,minecraft:lava[level=4])
B(-8,0,6,minecraft:lava[level=6])
B(-7,0,-7,minecraft:lava)
B(-7,1,-7,minecraft:lava)
B(-7,2,-7,minecraft:lava)
B(-7,3,-7,minecraft:lava)
B(-7,4,-7,minecraft:lava)
B(-7,0,-6,minecraft:lava)
B(-7,1,-6,minecraft:lava)
B(-7,2,-6,minecraft:lava)
B(-7,3,-6,minecraft:lava)
B(-7,4,-6,minecraft:lava)
B(-7,0,-5,minecraft:lava)
B(-7,1,-5,minecraft:lava)
B(-7,2,-5,minecraft:lava)
B(-7,3,-5,minecraft:lava)
B(-7,4,-5,minecraft:lava[level=2])
B(-7,0,-4,minecraft:lava)
B(-7,1,-4,minecraft:lava)
B(-7,2,-4,minecraft:lava)
B(-7,3,-4,minecraft:lava)
B(-7,0,-3,minecraft:lava)
B(-7,1,-3,minecraft:lava)
B(-7,2,-3,minecraft:lava[level=8])
B(-7,3,-3,minecraft:lava[level=2])
B(-7,0,-2,minecraft:lava)
B(-7,1,-2,minecraft:lava)
B(-7,2,-2,minecraft:lava[level=2])
B(-7,0,-1,minecraft:lava)
B(-7,1,-1,minecraft:lava[level=2])
B(-7,0,0,minecraft:lava)
B(-7,0,1,minecraft:lava)
B(-7,0,2,minecraft:lava)
B(-7,0,3,minecraft:lava)
B(-7,0,4,minecraft:lava)
B(-7,0,5,minecraft:lava[level=2])
B(-7,0,6,minecraft:lava[level=4])
B(-7,0,7,minecraft:lava[level=6])
B(-6,0,-7,minecraft:lava)
B(-6,1,-7,minecraft:lava)
B(-6,2,-7,minecraft:lava)
B(-6,3,-7,minecraft:lava)
B(-6,4,-7,minecraft:lava)
B(-6,5,-7,minecraft:lava[level=2])
B(-6,0,-6,minecraft:lava)
B(-6,1,-6,minecraft:lava)
B(-6,2,-6,minecraft:lava)
B(-6,3,-6,minecraft:lava)
B(-6,4,-6,minecraft:lava)
B(-6,5,-6,minecraft:lava[level=2])
B(-6,0,-5,minecraft:lava)
B(-6,1,-5,minecraft:lava)
B(-6,2,-5,minecraft:lava)
B(-6,3,-5,minecraft:lava)
B(-6,4,-5,minecraft:lava)
B(-6,0,-4,minecraft:lava)
B(-6,1,-4,minecraft:lava)
B(-6,2,-4,minecraft:lava)
B(-6,3,-4,minecraft:lava)
B(-6,4,-4,minecraft:lava[level=2])
B(-6,0,-3,minecraft:lava)
B(-6,1,-3,minecraft:lava)
B(-6,2,-3,minecraft:lava)
B(-6,3,-3,minecraft:lava)
B(-6,0,-2,minecraft:lava)
B(-6,1,-2,minecraft:lava)
B(-6,2,-2,minecraft:lava)
B(-6,3,-2,minecraft:lava[level=2])
B(-6,0,-1,minecraft:lava)
B(-6,1,-1,minecraft:lava)
B(-6,2,-1,minecraft:lava[level=2])
B(-6,0,0,minecraft:lava)
B(-6,1,0,minecraft:lava[level=2])
B(-6,0,1,minecraft:lava)
B(-6,0,2,minecraft:lava)
B(-6,0,3,minecraft:lava)
B(-6,0,4,minecraft:lava)
B(-6,0,5,minecraft:lava[level=2])
B(-6,0,6,minecraft:lava[level=4])
B(-6,0,7,minecraft:lava[level=6])
B(-5,0,-7,minecraft:lava)
B(-5,1,-7,minecraft:lava)
B(-5,2,-7,minecraft:lava)
B(-5,3,-7,minecraft:lava)
B(-5,4,-7,minecraft:lava)
B(-5,5,-7,minecraft:lava)
B(-5,6,-7,minecraft:lava[level=2])
B(-5,0,-6,minecraft:lava)
B(-5,1,-6,minecraft:lava)
B(-5,2,-6,minecraft:lava)
B(-5,3,-6,minecraft:lava)
B(-5,4,-6,minecraft:lava)
B(-5,5,-6,minecraft:lava)
B(-5,0,-5,minecraft:lava)
B(-5,1,-5,minecraft:lava)
B(-5,2,-5,minecraft:lava)
B(-5,3,-5,minecraft:lava)
B(-5,4,-5,minecraft:lava)
B(-5,5,-5,minecraft:lava[level=2])
B(-5,0,-4,minecraft:lava)
B(-5,1,-4,minecraft:lava)
B(-5,2,-4,minecraft:lava)
B(-5,3,-4,minecraft:lava)
B(-5,4,-4,minecraft:lava)
B(-5,0,-3,minecraft:lava)
B(-5,1,-3,minecraft:lava)
B(-5,2,-3,minecraft:lava)
B(-5,3,-3,minecraft:lava)
B(-5,4,-3,minecraft:lava[level=2])
B(-5,0,-2,minecraft:lava)
B(-5,1,-2,minecraft:lava)
B(-5,2,-2,minecraft:lava)
B(-5,3,-2,minecraft:lava[level=2])
B(-5,0,-1,minecraft:lava)
B(-5,1,-1,minecraft:lava)
B(-5,2,-1,minecraft:lava[level=2])
B(-5,0,0,minecraft:lava)
B(-5,1,0,minecraft:lava[level=2])
B(-5,0,1,minecraft:lava)
B(-5,0,2,minecraft:lava)
B(-5,0,3,minecraft:lava)
B(-5,0,4,minecraft:lava[level=2])
B(-5,0,5,minecraft:lava[level=4])
B(-5,0,6,minecraft:lava[level=6])
B(-4,0,-7,minecraft:lava)
B(-4,1,-7,minecraft:lava)
B(-4,2,-7,minecraft:lava)
B(-4,3,-7,minecraft:lava)
B(-4,4,-7,minecraft:lava)
B(-4,5,-7,minecraft:lava)
B(-4,6,-7,minecraft:lava)
B(-4,7,-7,minecraft:lava[level=2])
B(-4,0,-6,minecraft:lava)
B(-4,1,-6,minecraft:lava)
B(-4,2,-6,minecraft:lava)
B(-4,3,-6,minecraft:lava)
B(-4,4,-6,minecraft:lava)
B(-4,5,-6,minecraft:lava)
B(-4,6,-6,minecraft:lava[level=2])
B(-4,0,-5,minecraft:lava)
B(-4,1,-5,minecraft:lava)
B(-4,2,-5,minecraft:lava)
B(-4,3,-5,minecraft:lava)
B(-4,4,-5,minecraft:lava)
B(-4,5,-5,minecraft:lava)
B(-4,0,-4,minecraft:lava)
B(-4,1,-4,minecraft:lava)
B(-4,2,-4,minecraft:lava)
B(-4,3,-4,minecraft:lava)
B(-4,4,-4,minecraft:lava)
B(-4,5,-4,minecraft:lava[level=2])
B(-4,0,-3,minecraft:lava)
B(-4,1,-3,minecraft:lava)
B(-4,2,-3,minecraft:lava)
B(-4,3,-3,minecraft:lava)
B(-4,4,-3,minecraft:lava[level=2])
B(-4,0,-2,minecraft:lava)
B(-4,1,-2,minecraft:lava)
B(-4,2,-2,minecraft:lava)
B(-4,3,-2,minecraft:lava[level=2])
B(-4,0,-1,minecraft:lava)
B(-4,1,-1,minecraft:lava)
B(-4,2,-1,minecraft:lava[level=2])
B(-4,0,0,minecraft:lava)
B(-4,1,0,minecraft:lava[level=2])
B(-4,0,1,minecraft:lava)
B(-4,0,2,minecraft:lava)
B(-4,0,3,minecraft:lava[level=2])
B(-4,0,4,minecraft:lava[level=4])
B(-4,0,5,minecraft:lava[level=6])
B(-3,0,-7,minecraft:lava)
B(-3,1,-7,minecraft:lava)
B(-3,2,-7,minecraft:lava)
B(-3,3,-7,minecraft:lava)
B(-3,4,-7,minecraft:lava)
B(-3,5,-7,minecraft:lava)
B(-3,6,-7,minecraft:lava)
B(-3,7,-7,minecraft:lava)
B(-3,8,-7,minecraft:lava[level=2])
B(-3,0,-6,minecraft:lava)
B(-3,1,-6,minecraft:lava)
B(-3,2,-6,minecraft:lava)
B(-3,3,-6,minecraft:lava)
B(-3,4,-6,minecraft:lava)
B(-3,5,-6,minecraft:lava)
B(-3,6,-6,minecraft:lava)
B(-3,7,-6,minecraft:lava[level=2])
B(-3,0,-5,minecraft:lava)
B(-3,1,-5,minecraft:lava)
B(-3,2,-5,minecraft:lava)
B(-3,3,-5,minecraft:lava)
B(-3,4,-5,minecraft:lava)
B(-3,5,-5,minecraft:lava)
B(-3,6,-5,minecraft:lava[level=2])
B(-3,0,-4,minecraft:lava)
B(-3,1,-4,minecraft:lava)
B(-3,2,-4,minecraft:lava)
B(-3,3,-4,minecraft:lava)
B(-3,4,-4,minecraft:lava)
B(-3,5,-4,minecraft:lava[level=2])
B(-3,0,-3,minecraft:lava)
B(-3,1,-3,minecraft:lava)
B(-3,2,-3,minecraft:lava)
B(-3,3,-3,minecraft:lava)
B(-3,4,-3,minecraft:lava[level=2])
B(-3,0,-2,minecraft:lava)
B(-3,1,-2,minecraft:lava)
B(-3,2,-2,minecraft:lava)
B(-3,3,-2,minecraft:lava[level=2])
B(-3,0,-1,minecraft:lava)
B(-3,1,-1,minecraft:lava)
B(-3,2,-1,minecraft:lava[level=2])
B(-3,0,0,minecraft:lava[level=8])
B(-3,1,0,minecraft:lava[level=2])
B(-3,0,1,minecraft:lava)
B(-3,0,2,minecraft:lava[level=2])
B(-3,0,3,minecraft:lava[level=4])
B(-2,0,-7,minecraft:lava)
B(-2,1,-7,minecraft:lava)
B(-2,2,-7,minecraft:lava)
B(-2,3,-7,minecraft:lava)
B(-2,4,-7,minecraft:lava)
B(-2,5,-7,minecraft:lava)
B(-2,6,-7,minecraft:lava)
B(-2,7,-7,minecraft:lava)
B(-2,8,-7,minecraft:lava)
B(-2,9,-7,minecraft:lava[level=2])
B(-2,0,-6,minecraft:lava)
B(-2,1,-6,minecraft:lava)
B(-2,2,-6,minecraft:lava)
B(-2,3,-6,minecraft:lava)
B(-2,4,-6,minecraft:lava)
B(-2,5,-6,minecraft:lava)
B(-2,6,-6,minecraft:lava)
B(-2,7,-6,minecraft:lava)
B(-2,8,-6,minecraft:lava[level=2])
B(-2,0,-5,minecraft:lava)
B(-2,1,-5,minecraft:lava)
B(-2,2,-5,minecraft:lava)
B(-2,3,-5,minecraft:lava)
B(-2,4,-5,minecraft:lava)
B(-2,5,-5,minecraft:lava)
B(-2,6,-5,minecraft:lava)
B(-2,7,-5,minecraft:lava[level=2])
B(-2,0,-4,minecraft:lava)
B(-2,1,-4,minecraft:lava)
B(-2,2,-4,minecraft:lava)
B(-2,3,-4,minecraft:lava)
B(-2,4,-4,minecraft:lava)
B(-2,5,-4,minecraft:lava)
B(-2,6,-4,minecraft:lava[level=2])
B(-2,0,-3,minecraft:lava)
B(-2,1,-3,minecraft:lava)
B(-2,2,-3,minecraft:lava)
B(-2,3,-3,minecraft:lava)
B(-2,4,-3,minecraft:lava)
B(-2,5,-3,minecraft:lava[level=2])
B(-2,0,-2,minecraft:lava)
B(-2,1,-2,minecraft:lava)
B(-2,2,-2,minecraft:lava)
B(-2,3,-2,minecraft:lava[level=8])
B(-2,4,-2,minecraft:lava[level=2])
B(-2,0,-1,minecraft:lava)
B(-2,1,-1,minecraft:lava)
B(-2,2,-1,minecraft:lava[level=2])
B(-2,0,0,minecraft:lava[level=8])
B(-2,1,0,minecraft:lava[level=2])
B(-2,0,1,minecraft:lava[level=2])
B(-2,0,2,minecraft:lava[level=4])
B(-2,0,3,minecraft:lava[level=6])
B(-1,0,-7,minecraft:lava)
B(-1,1,-7,minecraft:lava)
B(-1,2,-7,minecraft:lava)
B(-1,3,-7,minecraft:lava)
B(-1,4,-7,minecraft:lava)
B(-1,5,-7,minecraft:lava)
B(-1,6,-7,minecraft:lava)
B(-1,7,-7,minecraft:lava)
B(-1,8,-7,minecraft:lava)
B(-1,9,-7,minecraft:lava)
B(-1,10,-7,minecraft:lava[level=8])
B(-1,11,-7,minecraft:lava[level=2])
B(-1,0,-6,minecraft:lava)
B(-1,1,-6,minecraft:lava)
B(-1,2,-6,minecraft:lava)
B(-1,3,-6,minecraft:lava)
B(-1,4,-6,minecraft:lava)
B(-1,5,-6,minecraft:lava)
B(-1,6,-6,minecraft:lava)
B(-1,7,-6,minecraft:lava)
B(-1,8,-6,minecraft:lava)
B(-1,9,-6,minecraft:lava[level=8])
B(-1,10,-6,minecraft:lava[level=2])
B(-1,0,-5,minecraft:lava)
B(-1,1,-5,minecraft:lava)
B(-1,2,-5,minecraft:lava)
B(-1,3,-5,minecraft:lava)
B(-1,4,-5,minecraft:lava)
B(-1,5,-5,minecraft:lava)
B(-1,6,-5,minecraft:lava)
B(-1,7,-5,minecraft:lava)
B(-1,8,-5,minecraft:lava[level=2])
B(-1,0,-4,minecraft:lava)
B(-1,1,-4,minecraft:lava)
B(-1,2,-4,minecraft:lava)
B(-1,3,-4,minecraft:lava)
B(-1,4,-4,minecraft:lava)
B(-1,5,-4,minecraft:lava)
B(-1,6,-4,minecraft:lava)
B(-1,7,-4,minecraft:lava[level=2])
B(-1,0,-3,minecraft:lava)
B(-1,1,-3,minecraft:lava)
B(-1,2,-3,minecraft:lava)
B(-1,3,-3,minecraft:lava)
B(-1,4,-3,minecraft:lava)
B(-1,5,-3,minecraft:lava[level=8])
B(-1,6,-3,minecraft:lava[level=2])
B(-1,0,-2,minecraft:lava)
B(-1,1,-2,minecraft:lava)
B(-1,2,-2,minecraft:lava)
B(-1,3,-2,minecraft:lava)
B(-1,4,-2,minecraft:lava[level=2])
B(-1,0,-1,minecraft:lava[level=8])
B(-1,1,-1,minecraft:lava[level=8])
B(-1,2,-1,minecraft:lava[level=8])
B(-1,3,-1,minecraft:lava[level=2])
B(-1,0,0,minecraft:lava[level=8])
B(-1,1,0,minecraft:lava[level=2])
B(-1,0,1,minecraft:lava[level=2])
B(-1,0,2,minecraft:lava[level=4])
B(-1,0,3,minecraft:lava[level=6])
B(-1,0,4,minecraft:lava[level=6])
B(0,0,-7,minecraft:lava)
B(0,1,-7,minecraft:lava)
B(0,2,-7,minecraft:lava)
B(0,3,-7,minecraft:lava)
B(0,4,-7,minecraft:lava)
B(0,5,-7,minecraft:lava)
B(0,6,-7,minecraft:lava)
B(0,7,-7,minecraft:lava)
B(0,8,-7,minecraft:lava)
B(0,9,-7,minecraft:lava)
B(0,10,-7,minecraft:lava)
B(0,11,-7,minecraft:lava)
B(0,0,-6,minecraft:lava)
B(0,1,-6,minecraft:lava)
B(0,2,-6,minecraft:lava)
B(0,3,-6,minecraft:lava)
B(0,4,-6,minecraft:lava)
B(0,5,-6,minecraft:lava)
B(0,6,-6,minecraft:lava)
B(0,7,-6,minecraft:lava)
B(0,8,-6,minecraft:lava)
B(0,9,-6,minecraft:lava)
B(0,10,-6,minecraft:lava)
B(0,11,-6,minecraft:lava[level=2])
B(0,0,-5,minecraft:lava)
B(0,1,-5,minecraft:lava)
B(0,2,-5,minecraft:lava)
B(0,3,-5,minecraft:lava)
B(0,4,-5,minecraft:lava)
B(0,5,-5,minecraft:lava)
B(0,6,-5,minecraft:lava)
B(0,7,-5,minecraft:lava)
B(0,8,-5,minecraft:lava)
B(0,9,-5,minecraft:lava[level=8])
B(0,10,-5,minecraft:lava[level=2])
B(0,0,-4,minecraft:lava)
B(0,1,-4,minecraft:lava)
B(0,2,-4,minecraft:lava)
B(0,3,-4,minecraft:lava)
B(0,4,-4,minecraft:lava)
B(0,5,-4,minecraft:lava)
B(0,6,-4,minecraft:lava)
B(0,7,-4,minecraft:lava)
B(0,8,-4,minecraft:lava[level=2])
B(0,0,-3,minecraft:lava)
B(0,1,-3,minecraft:lava)
B(0,2,-3,minecraft:lava)
B(0,3,-3,minecraft:lava)
B(0,4,-3,minecraft:lava)
B(0,5,-3,minecraft:lava)
B(0,6,-3,minecraft:lava[level=8])
B(0,7,-3,minecraft:lava[level=2])
B(0,0,-2,minecraft:lava)
B(0,1,-2,minecraft:lava)
B(0,2,-2,minecraft:lava)
B(0,3,-2,minecraft:lava)
B(0,4,-2,minecraft:lava)
B(0,5,-2,minecraft:lava[level=2])
B(0,0,-1,minecraft:lava[level=8])
B(0,1,-1,minecraft:lava[level=8])
B(0,2,-1,minecraft:lava[level=8])
B(0,3,-1,minecraft:lava[level=8])
B(0,4,-1,minecraft:lava[level=2])
B(0,0,0,minecraft:lava)
B(0,1,0,minecraft:lava)
B(0,0,1,minecraft:lava)
B(0,1,1,minecraft:lava[level=2])
B(0,0,2,minecraft:lava[level=2])
B(0,0,3,minecraft:lava[level=4])
B(0,0,4,minecraft:lava[level=4])
B(0,0,5,minecraft:lava[level=2])
B(0,0,6,minecraft:lava[level=2])
B(0,0,7,minecraft:lava[level=4])
B(0,0,8,minecraft:lava[level=6])
B(1,0,-7,minecraft:lava)
B(1,1,-7,minecraft:lava)
B(1,2,-7,minecraft:lava)
B(1,3,-7,minecraft:lava)
B(1,4,-7,minecraft:lava)
B(1,5,-7,minecraft:lava)
B(1,6,-7,minecraft:lava)
B(1,7,-7,minecraft:lava)
B(1,8,-7,minecraft:lava)
B(1,9,-7,minecraft:lava)
B(1,10,-7,minecraft:lava)
B(1,11,-7,minecraft:lava)
B(1,12,-7,minecraft:lava[level=8])
B(1,13,-7,minecraft:lava[level=8])
B(1,14,-7,minecraft:lava[level=8])
B(1,15,-7,minecraft:lava[level=8])
B(1,16,-7,minecraft:lava[level=8])
B(1,17,-7,minecraft:lava[level=2])
B(1,0,-6,minecraft:lava)
B(1,1,-6,minecraft:lava)
B(1,2,-6,minecraft:lava)
B(1,3,-6,minecraft:lava)
B(1,4,-6,minecraft:lava)
B(1,5,-6,minecraft:lava)
B(1,6,-6,minecraft:lava)
B(1,7,-6,minecraft:lava)
B(1,8,-6,minecraft:lava)
B(1,9,-6,minecraft:lava)
B(1,10,-6,minecraft:lava)
B(1,11,-6,minecraft:lava)
B(1,12,-6,minecraft:lava[level=8])
B(1,13,-6,minecraft:lava[level=8])
B(1,14,-6,minecraft:lava[level=8])
B(1,15,-6,minecraft:lava[level=8])
B(1,16,-6,minecraft:lava[level=2])
B(1,0,-5,minecraft:lava)
B(1,1,-5,minecraft:lava)
B(1,2,-5,minecraft:lava)
B(1,3,-5,minecraft:lava)
B(1,4,-5,minecraft:lava)
B(1,5,-5,minecraft:lava)
B(1,6,-5,minecraft:lava)
B(1,7,-5,minecraft:lava)
B(1,8,-5,minecraft:lava)
B(1,9,-5,minecraft:lava)
B(1,10,-5,minecraft:lava[level=8])
B(1,11,-5,minecraft:lava[level=8])
B(1,12,-5,minecraft:lava[level=8])
B(1,13,-5,minecraft:lava[level=8])
B(1,14,-5,minecraft:lava[level=8])
B(1,15,-5,minecraft:lava[level=2])
B(1,0,-4,minecraft:lava)
B(1,1,-4,minecraft:lava)
B(1,2,-4,minecraft:lava)
B(1,3,-4,minecraft:lava)
B(1,4,-4,minecraft:lava)
B(1,5,-4,minecraft:lava)
B(1,6,-4,minecraft:lava)
B(1,7,-4,minecraft:lava)
B(1,8,-4,minecraft:lava)
B(1,9,-4,minecraft:lava[level=8])
B(1,10,-4,minecraft:lava[level=8])
B(1,11,-4,minecraft:lava[level=8])
B(1,12,-4,minecraft:lava[level=8])
B(1,13,-4,minecraft:lava[level=2])
B(1,0,-3,minecraft:lava)
B(1,1,-3,minecraft:lava)
B(1,2,-3,minecraft:lava)
B(1,3,-3,minecraft:lava)
B(1,4,-3,minecraft:lava)
B(1,5,-3,minecraft:lava)
B(1,6,-3,minecraft:lava)
B(1,7,-3,minecraft:lava[level=8])
B(1,8,-3,minecraft:lava[level=8])
B(1,9,-3,minecraft:lava[level=8])
B(1,10,-3,minecraft:lava[level=8])
B(1,11,-3,minecraft:lava[level=8])
B(1,12,-3,minecraft:lava[level=2])
B(1,0,-2,minecraft:lava)
B(1,1,-2,minecraft:lava)
B(1,2,-2,minecraft:lava)
B(1,3,-2,minecraft:lava)
B(1,4,-2,minecraft:lava)
B(1,5,-2,minecraft:lava[level=8])
B(1,6,-2,minecraft:lava[level=8])
B(1,7,-2,minecraft:lava[level=8])
B(1,8,-2,minecraft:lava[level=8])
B(1,9,-2,minecraft:lava[level=8])
B(1,10,-2,minecraft:lava[level=2])
B(1,0,-1,minecraft:lava)
B(1,1,-1,minecraft:lava)
B(1,2,-1,minecraft:lava)
B(1,3,-1,minecraft:lava)
B(1,4,-1,minecraft:lava[level=8])
B(1,5,-1,minecraft:lava[level=8])
B(1,6,-1,minecraft:lava[level=8])
B(1,7,-1,minecraft:lava[level=8])
B(1,8,-1,minecraft:lava[level=8])
B(1,9,-1,minecraft:lava[level=2])
B(1,0,0,minecraft:lava)
B(1,1,0,minecraft:lava)
B(1,2,0,minecraft:lava[level=8])
B(1,3,0,minecraft:lava[level=2])
B(1,0,1,minecraft:lava)
B(1,1,1,minecraft:lava[level=2])
B(1,0,2,minecraft:lava[level=2])
B(1,0,3,minecraft:lava[level=2])
B(1,0,4,minecraft:lava[level=2])
B(1,0,5,minecraft:lava)
B(1,0,6,minecraft:lava)
B(1,0,7,minecraft:lava[level=2])
B(1,0,8,minecraft:lava[level=4])
B(2,0,-7,minecraft:lava)
B(2,1,-7,minecraft:lava)
B(2,2,-7,minecraft:lava)
B(2,3,-7,minecraft:lava)
B(2,4,-7,minecraft:lava)
B(2,5,-7,minecraft:lava)
B(2,6,-7,minecraft:lava)
B(2,7,-7,minecraft:lava)
B(2,8,-7,minecraft:lava)
B(2,9,-7,minecraft:lava)
B(2,10,-7,minecraft:lava)
B(2,11,-7,minecraft:lava)
B(2,12,-7,minecraft:lava)
B(2,13,-7,minecraft:lava)
B(2,14,-7,minecraft:lava)
B(2,15,-7,minecraft:lava)
B(2,16,-7,minecraft:lava)
B(2,17,-7,minecraft:lava)
B(2,18,-7,minecraft:lava[level=2])
B(2,0,-6,minecraft:lava)
B(2,1,-6,minecraft:lava)
B(2,2,-6,minecraft:lava)
B(2,3,-6,minecraft:lava)
B(2,4,-6,minecraft:lava)
B(2,5,-6,minecraft:lava)
B(2,6,-6,minecraft:lava)
B(2,7,-6,minecraft:lava)
B(2,8,-6,minecraft:lava)
B(2,9,-6,minecraft:lava)
B(2,10,-6,minecraft:lava)
B(2,11,-6,minecraft:lava)
B(2,12,-6,minecraft:lava)
B(2,13,-6,minecraft:lava)
B(2,14,-6,minecraft:lava)
B(2,15,-6,minecraft:lava)
B(2,16,-6,minecraft:lava)
B(2,17,-6,minecraft:lava[level=2])
B(2,0,-5,minecraft:lava)
B(2,1,-5,minecraft:lava)
B(2,2,-5,minecraft:lava)
B(2,3,-5,minecraft:lava)
B(2,4,-5,minecraft:lava)
B(2,5,-5,minecraft:lava)
B(2,6,-5,minecraft:lava)
B(2,7,-5,minecraft:lava)
B(2,8,-5,minecraft:lava)
B(2,9,-5,minecraft:lava)
B(2,10,-5,minecraft:lava)
B(2,11,-5,minecraft:lava)
B(2,12,-5,minecraft:lava)
B(2,13,-5,minecraft:lava)
B(2,14,-5,minecraft:lava)
B(2,15,-5,minecraft:lava)
B(2,16,-5,minecraft:lava[level=2])
B(2,0,-4,minecraft:lava)
B(2,1,-4,minecraft:lava)
B(2,2,-4,minecraft:lava)
B(2,3,-4,minecraft:lava)
B(2,4,-4,minecraft:lava)
B(2,5,-4,minecraft:lava)
B(2,6,-4,minecraft:lava)
B(2,7,-4,minecraft:lava)
B(2,8,-4,minecraft:lava)
B(2,9,-4,minecraft:lava)
B(2,10,-4,minecraft:lava)
B(2,11,-4,minecraft:lava)
B(2,12,-4,minecraft:lava)
B(2,13,-4,minecraft:lava)
B(2,14,-4,minecraft:lava[level=8])
B(2,15,-4,minecraft:lava[level=2])
B(2,0,-3,minecraft:lava)
B(2,1,-3,minecraft:lava)
B(2,2,-3,minecraft:lava)
B(2,3,-3,minecraft:lava)
B(2,4,-3,minecraft:lava)
B(2,5,-3,minecraft:lava)
B(2,6,-3,minecraft:lava)
B(2,7,-3,minecraft:lava)
B(2,8,-3,minecraft:lava)
B(2,9,-3,minecraft:lava)
B(2,10,-3,minecraft:lava)
B(2,11,-3,minecraft:lava)
B(2,12,-3,minecraft:lava)
B(2,13,-3,minecraft:lava[level=2])
B(2,0,-2,minecraft:lava)
B(2,1,-2,minecraft:lava)
B(2,2,-2,minecraft:lava)
B(2,3,-2,minecraft:lava)
B(2,4,-2,minecraft:lava)
B(2,5,-2,minecraft:lava)
B(2,6,-2,minecraft:lava)
B(2,7,-2,minecraft:lava)
B(2,8,-2,minecraft:lava)
B(2,9,-2,minecraft:lava)
B(2,10,-2,minecraft:lava)
B(2,11,-2,minecraft:lava[level=8])
B(2,12,-2,minecraft:lava[level=2])
B(2,0,-1,minecraft:lava)
B(2,1,-1,minecraft:lava)
B(2,2,-1,minecraft:lava)
B(2,3,-1,minecraft:lava)
B(2,4,-1,minecraft:lava)
B(2,5,-1,minecraft:lava)
B(2,6,-1,minecraft:lava)
B(2,7,-1,minecraft:lava)
B(2,8,-1,minecraft:lava)
B(2,9,-1,minecraft:lava)
B(2,10,-1,minecraft:lava[level=2])
B(2,0,0,minecraft:lava)
B(2,1,0,minecraft:lava)
B(2,2,0,minecraft:lava[level=8])
B(2,3,0,minecraft:lava[level=8])
B(2,4,0,minecraft:lava[level=8])
B(2,5,0,minecraft:lava[level=8])
B(2,6,0,minecraft:lava[level=8])
B(2,7,0,minecraft:lava[level=8])
B(2,8,0,minecraft:lava[level=8])
B(2,9,0,minecraft:lava[level=2])
B(2,0,1,minecraft:lava)
B(2,1,1,minecraft:lava[level=8])
B(2,2,1,minecraft:lava[level=8])
B(2,3,1,minecraft:lava[level=8])
B(2,4,1,minecraft:lava[level=8])
B(2,5,1,minecraft:lava[level=8])
B(2,6,1,minecraft:lava[level=8])
B(2,7,1,minecraft:lava[level=2])
B(2,0,2,minecraft:lava)
B(2,1,2,minecraft:lava[level=8])
B(2,2,2,minecraft:lava[level=8])
B(2,3,2,minecraft:lava[level=8])
B(2,4,2,minecraft:lava[level=8])
B(2,5,2,minecraft:lava[level=2])
B(2,0,3,minecraft:lava)
B(2,0,4,minecraft:lava)
B(2,0,5,minecraft:lava)
B(2,0,6,minecraft:lava)
B(2,0,7,minecraft:lava)
B(2,0,8,minecraft:lava[level=2])
B(3,0,-7,minecraft:lava)
B(3,1,-7,minecraft:lava)
B(3,2,-7,minecraft:lava)
B(3,3,-7,minecraft:lava)
B(3,4,-7,minecraft:lava)
B(3,5,-7,minecraft:lava)
B(3,6,-7,minecraft:lava)
B(3,7,-7,minecraft:lava)
B(3,8,-7,minecraft:lava)
B(3,9,-7,minecraft:lava)
B(3,10,-7,minecraft:lava)
B(3,11,-7,minecraft:lava)
B(3,12,-7,minecraft:lava)
B(3,13,-7,minecraft:lava)
B(3,14,-7,minecraft:lava)
B(3,15,-7,minecraft:lava)
B(3,16,-7,minecraft:lava)
B(3,17,-7,minecraft:lava)
B(3,18,-7,minecraft:lava)
B(3,19,-7,minecraft:lava[level=2])
B(3,0,-6,minecraft:lava)
B(3,1,-6,minecraft:lava)
B(3,2,-6,minecraft:lava)
B(3,3,-6,minecraft:lava)
B(3,4,-6,minecraft:lava)
B(3,5,-6,minecraft:lava)
B(3,6,-6,minecraft:lava)
B(3,7,-6,minecraft:lava)
B(3,8,-6,minecraft:lava)
B(3,9,-6,minecraft:lava)
B(3,10,-6,minecraft:lava)
B(3,11,-6,minecraft:lava)
B(3,12,-6,minecraft:lava)
B(3,13,-6,minecraft:lava)
B(3,14,-6,minecraft:lava)
B(3,15,-6,minecraft:lava)
B(3,16,-6,minecraft:lava)
B(3,17,-6,minecraft:lava)
B(3,18,-6,minecraft:lava[level=2])
B(3,0,-5,minecraft:lava)
B(3,1,-5,minecraft:lava)
B(3,2,-5,minecraft:lava)
B(3,3,-5,minecraft:lava)
B(3,4,-5,minecraft:lava)
B(3,5,-5,minecraft:lava)
B(3,6,-5,minecraft:lava)
B(3,7,-5,minecraft:lava)
B(3,8,-5,minecraft:lava)
B(3,9,-5,minecraft:lava)
B(3,10,-5,minecraft:lava)
B(3,11,-5,minecraft:lava)
B(3,12,-5,minecraft:lava)
B(3,13,-5,minecraft:lava)
B(3,14,-5,minecraft:lava)
B(3,15,-5,minecraft:lava)
B(3,16,-5,minecraft:lava)
B(3,17,-5,minecraft:lava[level=2])
B(3,0,-4,minecraft:lava)
B(3,1,-4,minecraft:lava)
B(3,2,-4,minecraft:lava)
B(3,3,-4,minecraft:lava)
B(3,4,-4,minecraft:lava)
B(3,5,-4,minecraft:lava)
B(3,6,-4,minecraft:lava)
B(3,7,-4,minecraft:lava)
B(3,8,-4,minecraft:lava)
B(3,9,-4,minecraft:lava)
B(3,10,-4,minecraft:lava)
B(3,11,-4,minecraft:lava)
B(3,12,-4,minecraft:lava)
B(3,13,-4,minecraft:lava)
B(3,14,-4,minecraft:lava)
B(3,15,-4,minecraft:lava)
B(3,16,-4,minecraft:lava[level=2])
B(3,0,-3,minecraft:lava)
B(3,1,-3,minecraft:lava)
B(3,2,-3,minecraft:lava)
B(3,3,-3,minecraft:lava)
B(3,4,-3,minecraft:lava)
B(3,5,-3,minecraft:lava)
B(3,6,-3,minecraft:lava)
B(3,7,-3,minecraft:lava)
B(3,8,-3,minecraft:lava)
B(3,9,-3,minecraft:lava)
B(3,10,-3,minecraft:lava)
B(3,11,-3,minecraft:lava)
B(3,12,-3,minecraft:lava)
B(3,13,-3,minecraft:lava)
B(3,14,-3,minecraft:lava[level=8])
B(3,15,-3,minecraft:lava[level=2])
B(3,0,-2,minecraft:lava)
B(3,1,-2,minecraft:lava)
B(3,2,-2,minecraft:lava)
B(3,3,-2,minecraft:lava)
B(3,4,-2,minecraft:lava)
B(3,5,-2,minecraft:lava)
B(3,6,-2,minecraft:lava)
B(3,7,-2,minecraft:lava)
B(3,8,-2,minecraft:lava)
B(3,9,-2,minecraft:lava)
B(3,10,-2,minecraft:lava)
B(3,11,-2,minecraft:lava[level=8])
B(3,12,-2,minecraft:lava[level=8])
B(3,13,-2,minecraft:lava[level=2])
B(3,0,-1,minecraft:lava)
B(3,1,-1,minecraft:lava)
B(3,2,-1,minecraft:lava)
B(3,3,-1,minecraft:lava)
B(3,4,-1,minecraft:lava)
B(3,5,-1,minecraft:lava)
B(3,6,-1,minecraft:lava)
B(3,7,-1,minecraft:lava)
B(3,8,-1,minecraft:lava)
B(3,9,-1,minecraft:lava)
B(3,10,-1,minecraft:lava[level=2])
B(3,0,0,minecraft:lava)
B(3,1,0,minecraft:lava)
B(3,2,0,minecraft:lava)
B(3,3,0,minecraft:lava)
B(3,4,0,minecraft:lava)
B(3,5,0,minecraft:lava)
B(3,6,0,minecraft:lava)
B(3,7,0,minecraft:lava)
B(3,8,0,minecraft:lava)
B(3,9,0,minecraft:lava[level=2])
B(3,0,1,minecraft:lava)
B(3,1,1,minecraft:lava)
B(3,2,1,minecraft:lava)
B(3,3,1,minecraft:lava)
B(3,4,1,minecraft:lava)
B(3,5,1,minecraft:lava)
B(3,6,1,minecraft:lava)
B(3,7,1,minecraft:lava)
B(3,8,1,minecraft:lava[level=2])
B(3,0,2,minecraft:lava)
B(3,1,2,minecraft:lava)
B(3,2,2,minecraft:lava)
B(3,3,2,minecraft:lava)
B(3,4,2,minecraft:lava)
B(3,5,2,minecraft:lava)
B(3,6,2,minecraft:lava[level=8])
B(3,7,2,minecraft:lava[level=2])
B(3,0,3,minecraft:lava[level=8])
B(3,1,3,minecraft:lava[level=8])
B(3,2,3,minecraft:lava[level=8])
B(3,3,3,minecraft:lava[level=8])
B(3,4,3,minecraft:lava[level=8])
B(3,5,3,minecraft:lava[level=2])
B(3,0,4,minecraft:lava)
B(3,0,5,minecraft:lava)
B(3,0,6,minecraft:lava)
B(3,0,7,minecraft:lava)
B(3,0,8,minecraft:lava[level=2])
B(4,0,-7,minecraft:lava)
B(4,1,-7,minecraft:lava)
B(4,2,-7,minecraft:lava)
B(4,3,-7,minecraft:lava)
B(4,4,-7,minecraft:lava)
B(4,5,-7,minecraft:lava)
B(4,6,-7,minecraft:lava)
B(4,7,-7,minecraft:lava)
B(4,8,-7,minecraft:lava)
B(4,9,-7,minecraft:lava)
B(4,10,-7,minecraft:lava)
B(4,11,-7,minecraft:lava)
B(4,12,-7,minecraft:lava)
B(4,13,-7,minecraft:lava)
B(4,14,-7,minecraft:lava)
B(4,15,-7,minecraft:lava)
B(4,16,-7,minecraft:lava)
B(4,17,-7,minecraft:lava)
B(4,18,-7,minecraft:lava)
B(4,19,-7,minecraft:lava)
B(4,0,-6,minecraft:lava)
B(4,1,-6,minecraft:lava)
B(4,2,-6,minecraft:lava)
B(4,3,-6,minecraft:lava)
B(4,4,-6,minecraft:lava)
B(4,5,-6,minecraft:lava)
B(4,6,-6,minecraft:lava)
B(4,7,-6,minecraft:lava)
B(4,8,-6,minecraft:lava)
B(4,9,-6,minecraft:lava)
B(4,10,-6,minecraft:lava)
B(4,11,-6,minecraft:lava)
B(4,12,-6,minecraft:lava)
B(4,13,-6,minecraft:lava)
B(4,14,-6,minecraft:lava)
B(4,15,-6,minecraft:lava)
B(4,16,-6,minecraft:lava)
B(4,17,-6,minecraft:lava)
B(4,18,-6,minecraft:lava)
B(4,19,-6,minecraft:lava[level=2])
B(4,0,-5,minecraft:lava)
B(4,1,-5,minecraft:lava)
B(4,2,-5,minecraft:lava)
B(4,3,-5,minecraft:lava)
B(4,4,-5,minecraft:lava)
B(4,5,-5,minecraft:lava)
B(4,6,-5,minecraft:lava)
B(4,7,-5,minecraft:lava)
B(4,8,-5,minecraft:lava)
B(4,9,-5,minecraft:lava)
B(4,10,-5,minecraft:lava)
B(4,11,-5,minecraft:lava)
B(4,12,-5,minecraft:lava)
B(4,13,-5,minecraft:lava)
B(4,14,-5,minecraft:lava)
B(4,15,-5,minecraft:lava)
B(4,16,-5,minecraft:lava)
B(4,17,-5,minecraft:lava)
B(4,18,-5,minecraft:lava[level=2])
B(4,0,-4,minecraft:lava)
B(4,1,-4,minecraft:lava)
B(4,2,-4,minecraft:lava)
B(4,3,-4,minecraft:lava)
B(4,4,-4,minecraft:lava)
B(4,5,-4,minecraft:lava)
B(4,6,-4,minecraft:lava)
B(4,7,-4,minecraft:lava)
B(4,8,-4,minecraft:lava)
B(4,9,-4,minecraft:lava)
B(4,10,-4,minecraft:lava)
B(4,11,-4,minecraft:lava)
B(4,12,-4,minecraft:lava)
B(4,13,-4,minecraft:lava)
B(4,14,-4,minecraft:lava)
B(4,15,-4,minecraft:lava)
B(4,16,-4,minecraft:lava[level=8])
B(4,17,-4,minecraft:lava[level=2])
B(4,0,-3,minecraft:lava)
B(4,1,-3,minecraft:lava)
B(4,2,-3,minecraft:lava)
B(4,3,-3,minecraft:lava)
B(4,4,-3,minecraft:lava)
B(4,5,-3,minecraft:lava)
B(4,6,-3,minecraft:lava)
B(4,7,-3,minecraft:lava)
B(4,8,-3,minecraft:lava)
B(4,9,-3,minecraft:lava)
B(4,10,-3,minecraft:lava)
B(4,11,-3,minecraft:lava)
B(4,12,-3,minecraft:lava)
B(4,13,-3,minecraft:lava)
B(4,14,-3,minecraft:lava)
B(4,15,-3,minecraft:lava[level=2])
B(4,0,-2,minecraft:lava)
B(4,1,-2,minecraft:lava)
B(4,2,-2,minecraft:lava)
B(4,3,-2,minecraft:lava)
B(4,4,-2,minecraft:lava)
B(4,5,-2,minecraft:lava)
B(4,6,-2,minecraft:lava)
B(4,7,-2,minecraft:lava)
B(4,8,-2,minecraft:lava)
B(4,9,-2,minecraft:lava)
B(4,10,-2,minecraft:lava)
B(4,11,-2,minecraft:lava)
B(4,12,-2,minecraft:lava[level=8])
B(4,13,-2,minecraft:lava[level=8])
B(4,14,-2,minecraft:lava[level=2])
B(4,0,-1,minecraft:lava)
B(4,1,-1,minecraft:lava)
B(4,2,-1,minecraft:lava)
B(4,3,-1,minecraft:lava)
B(4,4,-1,minecraft:lava)
B(4,5,-1,minecraft:lava)
B(4,6,-1,minecraft:lava)
B(4,7,-1,minecraft:lava)
B(4,8,-1,minecraft:lava)
B(4,9,-1,minecraft:lava)
B(4,10,-1,minecraft:lava)
B(4,11,-1,minecraft:lava[level=2])
B(4,0,0,minecraft:lava)
B(4,1,0,minecraft:lava)
B(4,2,0,minecraft:lava)
B(4,3,0,minecraft:lava)
B(4,4,0,minecraft:lava)
B(4,5,0,minecraft:lava)
B(4,6,0,minecraft:lava)
B(4,7,0,minecraft:lava)
B(4,8,0,minecraft:lava)
B(4,9,0,minecraft:lava)
B(4,10,0,minecraft:lava[level=2])
B(4,0,1,minecraft:lava)
B(4,1,1,minecraft:lava)
B(4,2,1,minecraft:lava)
B(4,3,1,minecraft:lava)
B(4,4,1,minecraft:lava)
B(4,5,1,minecraft:lava)
B(4,6,1,minecraft:lava)
B(4,7,1,minecraft:lava)
B(4,8,1,minecraft:lava[level=8])
B(4,9,1,minecraft:lava[level=2])
B(4,0,2,minecraft:lava)
B(4,1,2,minecraft:lava)
B(4,2,2,minecraft:lava)
B(4,3,2,minecraft:lava)
B(4,4,2,minecraft:lava)
B(4,5,2,minecraft:lava)
B(4,6,2,minecraft:lava)
B(4,7,2,minecraft:lava[level=2])
B(4,0,3,minecraft:lava)
B(4,1,3,minecraft:lava)
B(4,2,3,minecraft:lava)
B(4,3,3,minecraft:lava)
B(4,4,3,minecraft:lava)
B(4,5,3,minecraft:lava[level=8])
B(4,6,3,minecraft:lava[level=2])
B(4,0,4,minecraft:lava[level=8])
B(4,1,4,minecraft:lava[level=8])
B(4,2,4,minecraft:lava[level=8])
B(4,3,4,minecraft:lava[level=8])
B(4,4,4,minecraft:lava[level=2])
B(4,0,5,minecraft:lava)
B(4,0,6,minecraft:lava)
B(4,0,7,minecraft:lava)
B(4,0,8,minecraft:lava[level=2])
B(5,0,-7,minecraft:lava)
B(5,1,-7,minecraft:lava)
B(5,2,-7,minecraft:lava)
B(5,3,-7,minecraft:lava)
B(5,4,-7,minecraft:lava)
B(5,5,-7,minecraft:lava)
B(5,6,-7,minecraft:lava)
B(5,7,-7,minecraft:lava)
B(5,8,-7,minecraft:lava)
B(5,9,-7,minecraft:lava)
B(5,10,-7,minecraft:lava)
B(5,11,-7,minecraft:lava)
B(5,12,-7,minecraft:lava)
B(5,13,-7,minecraft:lava)
B(5,14,-7,minecraft:lava)
B(5,15,-7,minecraft:lava)
B(5,16,-7,minecraft:lava)
B(5,17,-7,minecraft:lava)
B(5,18,-7,minecraft:lava)
B(5,19,-7,minecraft:lava)
B(5,20,-7,minecraft:lava[level=2])
B(5,0,-6,minecraft:lava)
B(5,1,-6,minecraft:lava)
B(5,2,-6,minecraft:lava)
B(5,3,-6,minecraft:lava)
B(5,4,-6,minecraft:lava)
B(5,5,-6,minecraft:lava)
B(5,6,-6,minecraft:lava)
B(5,7,-6,minecraft:lava)
B(5,8,-6,minecraft:lava)
B(5,9,-6,minecraft:lava)
B(5,10,-6,minecraft:lava)
B(5,11,-6,minecraft:lava)
B(5,12,-6,minecraft:lava)
B(5,13,-6,minecraft:lava)
B(5,14,-6,minecraft:lava)
B(5,15,-6,minecraft:lava)
B(5,16,-6,minecraft:lava)
B(5,17,-6,minecraft:lava)
B(5,18,-6,minecraft:lava)
B(5,19,-6,minecraft:lava[level=2])
B(5,0,-5,minecraft:lava)
B(5,1,-5,minecraft:lava)
B(5,2,-5,minecraft:lava)
B(5,3,-5,minecraft:lava)
B(5,4,-5,minecraft:lava)
B(5,5,-5,minecraft:lava)
B(5,6,-5,minecraft:lava)
B(5,7,-5,minecraft:lava)
B(5,8,-5,minecraft:lava)
B(5,9,-5,minecraft:lava)
B(5,10,-5,minecraft:lava)
B(5,11,-5,minecraft:lava)
B(5,12,-5,minecraft:lava)
B(5,13,-5,minecraft:lava)
B(5,14,-5,minecraft:lava)
B(5,15,-5,minecraft:lava)
B(5,16,-5,minecraft:lava)
B(5,17,-5,minecraft:lava)
B(5,18,-5,minecraft:lava[level=2])
B(5,0,-4,minecraft:lava)
B(5,1,-4,minecraft:lava)
B(5,2,-4,minecraft:lava)
B(5,3,-4,minecraft:lava)
B(5,4,-4,minecraft:lava)
B(5,5,-4,minecraft:lava)
B(5,6,-4,minecraft:lava)
B(5,7,-4,minecraft:lava)
B(5,8,-4,minecraft:lava)
B(5,9,-4,minecraft:lava)
B(5,10,-4,minecraft:lava)
B(5,11,-4,minecraft:lava)
B(5,12,-4,minecraft:lava)
B(5,13,-4,minecraft:lava)
B(5,14,-4,minecraft:lava)
B(5,15,-4,minecraft:lava)
B(5,16,-4,minecraft:lava)
B(5,17,-4,minecraft:lava[level=2])
B(5,0,-3,minecraft:lava)
B(5,1,-3,minecraft:lava)
B(5,2,-3,minecraft:lava)
B(5,3,-3,minecraft:lava)
B(5,4,-3,minecraft:lava)
B(5,5,-3,minecraft:lava)
B(5,6,-3,minecraft:lava)
B(5,7,-3,minecraft:lava)
B(5,8,-3,minecraft:lava)
B(5,9,-3,minecraft:lava)
B(5,10,-3,minecraft:lava)
B(5,11,-3,minecraft:lava)
B(5,12,-3,minecraft:lava)
B(5,13,-3,minecraft:lava)
B(5,14,-3,minecraft:lava)
B(5,15,-3,minecraft:lava[level=8])
B(5,16,-3,minecraft:lava[level=2])
B(5,0,-2,minecraft:lava)
B(5,1,-2,minecraft:lava)
B(5,2,-2,minecraft:lava)
B(5,3,-2,minecraft:lava)
B(5,4,-2,minecraft:lava)
B(5,5,-2,minecraft:lava)
B(5,6,-2,minecraft:lava)
B(5,7,-2,minecraft:lava)
B(5,8,-2,minecraft:lava)
B(5,9,-2,minecraft:lava)
B(5,10,-2,minecraft:lava)
B(5,11,-2,minecraft:lava)
B(5,12,-2,minecraft:lava[level=8])
B(5,13,-2,minecraft:lava[level=8])
B(5,14,-2,minecraft:lava[level=2])
B(5,0,-1,minecraft:lava)
B(5,1,-1,minecraft:lava)
B(5,2,-1,minecraft:lava)
B(5,3,-1,minecraft:lava)
B(5,4,-1,minecraft:lava)
B(5,5,-1,minecraft:lava)
B(5,6,-1,minecraft:lava)
B(5,7,-1,minecraft:lava)
B(5,8,-1,minecraft:lava)
B(5,9,-1,minecraft:lava)
B(5,10,-1,minecraft:lava)
B(5,11,-1,minecraft:lava[level=2])
B(5,0,0,minecraft:lava)
B(5,1,0,minecraft:lava)
B(5,2,0,minecraft:lava)
B(5,3,0,minecraft:lava)
B(5,4,0,minecraft:lava)
B(5,5,0,minecraft:lava)
B(5,6,0,minecraft:lava)
B(5,7,0,minecraft:lava)
B(5,8,0,minecraft:lava)
B(5,9,0,minecraft:lava)
B(5,10,0,minecraft:lava[level=2])
B(5,0,1,minecraft:lava)
B(5,1,1,minecraft:lava)
B(5,2,1,minecraft:lava)
B(5,3,1,minecraft:lava)
B(5,4,1,minecraft:lava)
B(5,5,1,minecraft:lava)
B(5,6,1,minecraft:lava)
B(5,7,1,minecraft:lava)
B(5,8,1,minecraft:lava)
B(5,9,1,minecraft:lava[level=2])
B(5,0,2,minecraft:lava)
B(5,1,2,minecraft:lava)
B(5,2,2,minecraft:lava)
B(5,3,2,minecraft:lava)
B(5,4,2,minecraft:lava)
B(5,5,2,minecraft:lava)
B(5,6,2,minecraft:lava)
B(5,7,2,minecraft:lava[level=8])
B(5,8,2,minecraft:lava[level=2])
B(5,0,3,minecraft:lava)
B(5,1,3,minecraft:lava)
B(5,2,3,minecraft:lava)
B(5,3,3,minecraft:lava)
B(5,4,3,minecraft:lava)
B(5,5,3,minecraft:lava)
B(5,6,3,minecraft:lava[level=2])
B(5,0,4,minecraft:lava)
B(5,1,4,minecraft:lava[level=8])
B(5,2,4,minecraft:lava[level=8])
B(5,3,4,minecraft:lava[level=8])
B(5,4,4,minecraft:lava[level=8])
B(5,5,4,minecraft:lava[level=2])
B(5,0,5,minecraft:lava[level=2])
B(5,0,6,minecraft:lava[level=2])
B(6,0,-7,minecraft:lava)
B(6,1,-7,minecraft:lava)
B(6,2,-7,minecraft:lava)
B(6,3,-7,minecraft:lava)
B(6,4,-7,minecraft:lava)
B(6,5,-7,minecraft:lava)
B(6,6,-7,minecraft:lava)
B(6,7,-7,minecraft:lava)
B(6,8,-7,minecraft:lava)
B(6,9,-7,minecraft:lava)
B(6,10,-7,minecraft:lava)
B(6,11,-7,minecraft:lava)
B(6,12,-7,minecraft:lava)
B(6,13,-7,minecraft:lava)
B(6,14,-7,minecraft:lava)
B(6,15,-7,minecraft:lava)
B(6,16,-7,minecraft:lava)
B(6,17,-7,minecraft:lava)
B(6,18,-7,minecraft:lava)
B(6,19,-7,minecraft:lava)
B(6,20,-7,minecraft:lava)
B(6,21,-7,minecraft:lava[level=2])
B(6,0,-6,minecraft:lava)
B(6,1,-6,minecraft:lava)
B(6,2,-6,minecraft:lava)
B(6,3,-6,minecraft:lava)
B(6,4,-6,minecraft:lava)
B(6,5,-6,minecraft:lava)
B(6,6,-6,minecraft:lava)
B(6,7,-6,minecraft:lava)
B(6,8,-6,minecraft:lava)
B(6,9,-6,minecraft:lava)
B(6,10,-6,minecraft:lava)
B(6,11,-6,minecraft:lava)
B(6,12,-6,minecraft:lava)
B(6,13,-6,minecraft:lava)
B(6,14,-6,minecraft:lava)
B(6,15,-6,minecraft:lava)
B(6,16,-6,minecraft:lava)
B(6,17,-6,minecraft:lava)
B(6,18,-6,minecraft:lava)
B(6,19,-6,minecraft:lava)
B(6,20,-6,minecraft:lava[level=2])
B(6,0,-5,minecraft:lava)
B(6,1,-5,minecraft:lava)
B(6,2,-5,minecraft:lava)
B(6,3,-5,minecraft:lava)
B(6,4,-5,minecraft:lava)
B(6,5,-5,minecraft:lava)
B(6,6,-5,minecraft:lava)
B(6,7,-5,minecraft:lava)
B(6,8,-5,minecraft:lava)
B(6,9,-5,minecraft:lava)
B(6,10,-5,minecraft:lava)
B(6,11,-5,minecraft:lava)
B(6,12,-5,minecraft:lava)
B(6,13,-5,minecraft:lava)
B(6,14,-5,minecraft:lava)
B(6,15,-5,minecraft:lava)
B(6,16,-5,minecraft:lava)
B(6,17,-5,minecraft:lava)
B(6,18,-5,minecraft:lava)
B(6,19,-5,minecraft:lava[level=2])
B(6,0,-4,minecraft:lava)
B(6,1,-4,minecraft:lava)
B(6,2,-4,minecraft:lava)
B(6,3,-4,minecraft:lava)
B(6,4,-4,minecraft:lava)
B(6,5,-4,minecraft:lava)
B(6,6,-4,minecraft:lava)
B(6,7,-4,minecraft:lava)
B(6,8,-4,minecraft:lava)
B(6,9,-4,minecraft:lava)
B(6,10,-4,minecraft:lava)
B(6,11,-4,minecraft:lava)
B(6,12,-4,minecraft:lava)
B(6,13,-4,minecraft:lava)
B(6,14,-4,minecraft:lava)
B(6,15,-4,minecraft:lava)
B(6,16,-4,minecraft:lava)
B(6,17,-4,minecraft:lava[level=8])
B(6,18,-4,minecraft:lava[level=2])
B(6,0,-3,minecraft:lava)
B(6,1,-3,minecraft:lava)
B(6,2,-3,minecraft:lava)
B(6,3,-3,minecraft:lava)
B(6,4,-3,minecraft:lava)
B(6,5,-3,minecraft:lava)
B(6,6,-3,minecraft:lava)
B(6,7,-3,minecraft:lava)
B(6,8,-3,minecraft:lava)
B(6,9,-3,minecraft:lava)
B(6,10,-3,minecraft:lava)
B(6,11,-3,minecraft:lava)
B(6,12,-3,minecraft:lava)
B(6,13,-3,minecraft:lava)
B(6,14,-3,minecraft:lava)
B(6,15,-3,minecraft:lava)
B(6,16,-3,minecraft:lava[level=2])
B(6,0,-2,minecraft:lava)
B(6,1,-2,minecraft:lava)
B(6,2,-2,minecraft:lava)
B(6,3,-2,minecraft:lava)
B(6,4,-2,minecraft:lava)
B(6,5,-2,minecraft:lava)
B(6,6,-2,minecraft:lava)
B(6,7,-2,minecraft:lava)
B(6,8,-2,minecraft:lava)
B(6,9,-2,minecraft:lava)
B(6,10,-2,minecraft:lava)
B(6,11,-2,minecraft:lava)
B(6,12,-2,minecraft:lava[level=8])
B(6,13,-2,minecraft:lava[level=8])
B(6,14,-2,minecraft:lava[level=8])
B(6,15,-2,minecraft:lava[level=2])
B(6,0,-1,minecraft:lava)
B(6,1,-1,minecraft:lava)
B(6,2,-1,minecraft:lava)
B(6,3,-1,minecraft:lava)
B(6,4,-1,minecraft:lava)
B(6,5,-1,minecraft:lava)
B(6,6,-1,minecraft:lava)
B(6,7,-1,minecraft:lava)
B(6,8,-1,minecraft:lava)
B(6,9,-1,minecraft:lava)
B(6,10,-1,minecraft:lava)
B(6,11,-1,minecraft:lava)
B(6,0,0,minecraft:lava)
B(6,1,0,minecraft:lava)
B(6,2,0,minecraft:lava)
B(6,3,0,minecraft:lava)
B(6,4,0,minecraft:lava)
B(6,5,0,minecraft:lava)
B(6,6,0,minecraft:lava)
B(6,7,0,minecraft:lava)
B(6,8,0,minecraft:lava)
B(6,9,0,minecraft:lava)
B(6,10,0,minecraft:lava)
B(6,11,0,minecraft:lava[level=2])
B(6,0,1,minecraft:lava)
B(6,1,1,minecraft:lava)
B(6,2,1,minecraft:lava)
B(6,3,1,minecraft:lava)
B(6,4,1,minecraft:lava)
B(6,5,1,minecraft:lava)
B(6,6,1,minecraft:lava)
B(6,7,1,minecraft:lava)
B(6,8,1,minecraft:lava)
B(6,9,1,minecraft:lava)
B(6,10,1,minecraft:lava[level=2])
B(6,0,2,minecraft:lava)
B(6,1,2,minecraft:lava)
B(6,2,2,minecraft:lava)
B(6,3,2,minecraft:lava)
B(6,4,2,minecraft:lava)
B(6,5,2,minecraft:lava)
B(6,6,2,minecraft:lava)
B(6,7,2,minecraft:lava)
B(6,8,2,minecraft:lava[level=8])
B(6,9,2,minecraft:lava[level=2])
B(6,0,3,minecraft:lava)
B(6,1,3,minecraft:lava)
B(6,2,3,minecraft:lava)
B(6,3,3,minecraft:lava)
B(6,4,3,minecraft:lava)
B(6,5,3,minecraft:lava)
B(6,6,3,minecraft:lava[level=8])
B(6,7,3,minecraft:lava[level=2])
B(6,0,4,minecraft:lava)
B(6,1,4,minecraft:lava[level=8])
B(6,2,4,minecraft:lava[level=8])
B(6,3,4,minecraft:lava[level=8])
B(6,4,4,minecraft:lava[level=8])
B(6,5,4,minecraft:lava[level=2])
B(6,0,5,minecraft:lava[level=2])
B(6,0,6,minecraft:lava[level=4])
B(7,0,-7,minecraft:lava)
B(7,1,-7,minecraft:lava)
B(7,2,-7,minecraft:lava)
B(7,3,-7,minecraft:lava)
B(7,4,-7,minecraft:lava)
B(7,5,-7,minecraft:lava)
B(7,6,-7,minecraft:lava)
B(7,7,-7,minecraft:lava)
B(7,8,-7,minecraft:lava)
B(7,9,-7,minecraft:lava)
B(7,10,-7,minecraft:lava)
B(7,11,-7,minecraft:lava)
B(7,12,-7,minecraft:lava)
B(7,13,-7,minecraft:lava)
B(7,14,-7,minecraft:lava)
B(7,15,-7,minecraft:lava)
B(7,16,-7,minecraft:lava)
B(7,17,-7,minecraft:lava)
B(7,18,-7,minecraft:lava)
B(7,19,-7,minecraft:lava)
B(7,20,-7,minecraft:lava)
B(7,21,-7,minecraft:lava[level=2])
B(7,0,-6,minecraft:lava)
B(7,1,-6,minecraft:lava)
B(7,2,-6,minecraft:lava)
B(7,3,-6,minecraft:lava)
B(7,4,-6,minecraft:lava)
B(7,5,-6,minecraft:lava)
B(7,6,-6,minecraft:lava)
B(7,7,-6,minecraft:lava)
B(7,8,-6,minecraft:lava)
B(7,9,-6,minecraft:lava)
B(7,10,-6,minecraft:lava)
B(7,11,-6,minecraft:lava)
B(7,12,-6,minecraft:lava)
B(7,13,-6,minecraft:lava)
B(7,14,-6,minecraft:lava)
B(7,15,-6,minecraft:lava)
B(7,16,-6,minecraft:lava)
B(7,17,-6,minecraft:lava)
B(7,18,-6,minecraft:lava)
B(7,19,-6,minecraft:lava)
B(7,20,-6,minecraft:lava[level=2])
B(7,0,-5,minecraft:lava)
B(7,1,-5,minecraft:lava)
B(7,2,-5,minecraft:lava)
B(7,3,-5,minecraft:lava)
B(7,4,-5,minecraft:lava)
B(7,5,-5,minecraft:lava)
B(7,6,-5,minecraft:lava)
B(7,7,-5,minecraft:lava)
B(7,8,-5,minecraft:lava)
B(7,9,-5,minecraft:lava)
B(7,10,-5,minecraft:lava)
B(7,11,-5,minecraft:lava)
B(7,12,-5,minecraft:lava)
B(7,13,-5,minecraft:lava)
B(7,14,-5,minecraft:lava)
B(7,15,-5,minecraft:lava)
B(7,16,-5,minecraft:lava)
B(7,17,-5,minecraft:lava)
B(7,18,-5,minecraft:lava)
B(7,19,-5,minecraft:lava[level=2])
B(7,0,-4,minecraft:lava)
B(7,1,-4,minecraft:lava)
B(7,2,-4,minecraft:lava)
B(7,3,-4,minecraft:lava)
B(7,4,-4,minecraft:lava)
B(7,5,-4,minecraft:lava)
B(7,6,-4,minecraft:lava)
B(7,7,-4,minecraft:lava)
B(7,8,-4,minecraft:lava)
B(7,9,-4,minecraft:lava)
B(7,10,-4,minecraft:lava)
B(7,11,-4,minecraft:lava)
B(7,12,-4,minecraft:lava)
B(7,13,-4,minecraft:lava)
B(7,14,-4,minecraft:lava)
B(7,15,-4,minecraft:lava)
B(7,16,-4,minecraft:lava)
B(7,17,-4,minecraft:lava[level=8])
B(7,18,-4,minecraft:lava[level=2])
B(7,0,-3,minecraft:lava)
B(7,1,-3,minecraft:lava)
B(7,2,-3,minecraft:lava)
B(7,3,-3,minecraft:lava)
B(7,4,-3,minecraft:lava)
B(7,5,-3,minecraft:lava)
B(7,6,-3,minecraft:lava)
B(7,7,-3,minecraft:lava)
B(7,8,-3,minecraft:lava)
B(7,9,-3,minecraft:lava)
B(7,10,-3,minecraft:lava)
B(7,11,-3,minecraft:lava)
B(7,12,-3,minecraft:lava)
B(7,13,-3,minecraft:lava)
B(7,14,-3,minecraft:lava)
B(7,15,-3,minecraft:lava)
B(7,16,-3,minecraft:lava[level=2])
B(7,0,-2,minecraft:lava)
B(7,1,-2,minecraft:lava)
B(7,2,-2,minecraft:lava)
B(7,3,-2,minecraft:lava)
B(7,4,-2,minecraft:lava)
B(7,5,-2,minecraft:lava)
B(7,6,-2,minecraft:lava)
B(7,7,-2,minecraft:lava)
B(7,8,-2,minecraft:lava)
B(7,9,-2,minecraft:lava)
B(7,10,-2,minecraft:lava)
B(7,11,-2,minecraft:lava)
B(7,12,-2,minecraft:lava)
B(7,13,-2,minecraft:lava[level=8])
B(7,14,-2,minecraft:lava[level=8])
B(7,15,-2,minecraft:lava[level=2])
B(7,0,-1,minecraft:lava)
B(7,1,-1,minecraft:lava)
B(7,2,-1,minecraft:lava)
B(7,3,-1,minecraft:lava)
B(7,4,-1,minecraft:lava)
B(7,5,-1,minecraft:lava)
B(7,6,-1,minecraft:lava)
B(7,7,-1,minecraft:lava)
B(7,8,-1,minecraft:lava)
B(7,9,-1,minecraft:lava)
B(7,10,-1,minecraft:lava)
B(7,11,-1,minecraft:lava)
B(7,12,-1,minecraft:lava[level=2])
B(7,0,0,minecraft:lava)
B(7,1,0,minecraft:lava)
B(7,2,0,minecraft:lava)
B(7,3,0,minecraft:lava)
B(7,4,0,minecraft:lava)
B(7,5,0,minecraft:lava)
B(7,6,0,minecraft:lava)
B(7,7,0,minecraft:lava)
B(7,8,0,minecraft:lava)
B(7,9,0,minecraft:lava)
B(7,10,0,minecraft:lava)
B(7,11,0,minecraft:lava[level=2])
B(7,0,1,minecraft:lava)
B(7,1,1,minecraft:lava)
B(7,2,1,minecraft:lava)
B(7,3,1,minecraft:lava)
B(7,4,1,minecraft:lava)
B(7,5,1,minecraft:lava)
B(7,6,1,minecraft:lava)
B(7,7,1,minecraft:lava)
B(7,8,1,minecraft:lava)
B(7,9,1,minecraft:lava)
B(7,10,1,minecraft:lava[level=2])
B(7,0,2,minecraft:lava)
B(7,1,2,minecraft:lava)
B(7,2,2,minecraft:lava)
B(7,3,2,minecraft:lava)
B(7,4,2,minecraft:lava)
B(7,5,2,minecraft:lava)
B(7,6,2,minecraft:lava)
B(7,7,2,minecraft:lava)
B(7,8,2,minecraft:lava[level=8])
B(7,9,2,minecraft:lava[level=2])
B(7,0,3,minecraft:lava)
B(7,1,3,minecraft:lava)
B(7,2,3,minecraft:lava)
B(7,3,3,minecraft:lava)
B(7,4,3,minecraft:lava)
B(7,5,3,minecraft:lava)
B(7,6,3,minecraft:lava[level=8])
B(7,7,3,minecraft:lava[level=2])
B(7,0,4,minecraft:lava)
B(7,1,4,minecraft:lava[level=8])
B(7,2,4,minecraft:lava[level=8])
B(7,3,4,minecraft:lava[level=8])
B(7,4,4,minecraft:lava[level=8])
B(7,5,4,minecraft:lava[level=2])
B(7,0,5,minecraft:lava[level=2])
B(7,0,6,minecraft:lava[level=4])

#######################################################################
# +-----------------------------------------------------------------+ #
# |                             Branches                            | #
# +-----------------------------------------------------------------+ #
#######################################################################

Branch(16,0,0,true,GiantLavaStalacmite1_C2_R2,NORTH,100.0,0)

#######################################################################
# +-----------------------------------------------------------------+ #
# |                             Entities                            | #
# +-----------------------------------------------------------------+ #
#######################################################################

