
#######################################################################
# +-----------------------------------------------------------------+ #
# |                            BO4 object                           | #
# +-----------------------------------------------------------------+ #
#######################################################################

Author: Unknown

Description: No description given

SettingsMode: WriteWithoutComments


#######################################################################
# +-----------------------------------------------------------------+ #
# |                          Main settings                          | #
# +-----------------------------------------------------------------+ #
#######################################################################

FixedRotation: 

Frequency: 0

SpawnHeight: highestBlock

UseCenterForHighestBlock: true

##############################
# Height Limits for the BO4. #
##############################

MinHeight: 0

MaxHeight: 255

InheritBO3: 

InheritBO3Rotation: NORTH

OverrideChildSettings: true

OverrideParentHeight: false

CanOverride: false

BranchFrequency: 0

BranchFrequencyGroup: 

MustBeBelowOther: false

MustBeInside: 

CannotBeInside: 

ReplacesBO3: 

MustBeInsideWorldBorders: false

CanSpawnOnWater: true

SpawnOnWaterOnly: false

SpawnUnderWater: false

SpawnAtWaterLevel: false

HeightOffset: 0

RemoveAir: true

ReplaceAbove: 

ReplaceBelow: 

ReplaceWithBiomeBlocks: true

ReplaceWithSurfaceBlock: GRASS

ReplaceWithGroundBlock: DIRT

ReplaceWithStoneBlock: STONE

SmoothRadius: 0

SmoothHeightOffset: 0

SmoothStartTop: false

SmoothStartWood: false

SmoothingSurfaceBlock: 

SmoothingGroundBlock: 

BO3Group: 

IsSpawnPoint: false

DoReplaceBlocks: true


#######################################################################
# +-----------------------------------------------------------------+ #
# |                              Blocks                             | #
# +-----------------------------------------------------------------+ #
#######################################################################

B(-8,0,-7,minecraft:lava)
B(-8,1,-7,minecraft:lava)
B(-8,2,-7,minecraft:lava)
B(-8,3,-7,minecraft:lava)
B(-8,4,-7,minecraft:lava)
B(-8,0,-6,minecraft:lava)
B(-8,1,-6,minecraft:lava)
B(-8,2,-6,minecraft:lava)
B(-8,3,-6,minecraft:lava)
B(-8,4,-6,minecraft:lava)
B(-8,5,-6,minecraft:lava[level=2])
B(-8,0,-5,minecraft:lava)
B(-8,1,-5,minecraft:lava)
B(-8,2,-5,minecraft:lava)
B(-8,3,-5,minecraft:lava)
B(-8,4,-5,minecraft:lava)
B(-8,5,-5,minecraft:lava)
B(-8,0,-4,minecraft:lava)
B(-8,1,-4,minecraft:lava)
B(-8,2,-4,minecraft:lava)
B(-8,3,-4,minecraft:lava)
B(-8,4,-4,minecraft:lava)
B(-8,5,-4,minecraft:lava)
B(-8,0,-3,minecraft:lava)
B(-8,1,-3,minecraft:lava)
B(-8,2,-3,minecraft:lava)
B(-8,3,-3,minecraft:lava)
B(-8,4,-3,minecraft:lava)
B(-8,5,-3,minecraft:lava)
B(-8,0,-2,minecraft:lava)
B(-8,1,-2,minecraft:lava)
B(-8,2,-2,minecraft:lava)
B(-8,3,-2,minecraft:lava)
B(-8,4,-2,minecraft:lava)
B(-8,5,-2,minecraft:lava[level=2])
B(-8,0,-1,minecraft:lava)
B(-8,1,-1,minecraft:lava)
B(-8,2,-1,minecraft:lava)
B(-8,3,-1,minecraft:lava)
B(-8,4,-1,minecraft:lava[level=2])
B(-8,0,0,minecraft:lava)
B(-8,1,0,minecraft:lava)
B(-8,2,0,minecraft:lava)
B(-8,3,0,minecraft:lava)
B(-8,0,1,minecraft:lava)
B(-8,1,1,minecraft:lava)
B(-8,2,1,minecraft:lava)
B(-8,3,1,minecraft:lava[level=2])
B(-8,0,2,minecraft:lava)
B(-8,1,2,minecraft:lava)
B(-8,2,2,minecraft:lava)
B(-8,3,2,minecraft:lava[level=2])
B(-8,0,3,minecraft:lava)
B(-8,1,3,minecraft:lava)
B(-8,2,3,minecraft:lava)
B(-8,3,3,minecraft:lava[level=2])
B(-8,0,4,minecraft:lava)
B(-8,1,4,minecraft:lava)
B(-8,2,4,minecraft:lava)
B(-8,3,4,minecraft:lava[level=2])
B(-8,0,5,minecraft:lava)
B(-8,1,5,minecraft:lava)
B(-8,2,5,minecraft:lava)
B(-8,3,5,minecraft:lava[level=2])
B(-8,0,6,minecraft:lava)
B(-8,1,6,minecraft:lava)
B(-8,2,6,minecraft:lava)
B(-8,3,6,minecraft:lava[level=2])
B(-8,0,7,minecraft:lava)
B(-8,1,7,minecraft:lava)
B(-8,2,7,minecraft:lava)
B(-8,3,7,minecraft:lava[level=2])
B(-8,0,8,minecraft:lava)
B(-8,1,8,minecraft:lava)
B(-8,2,8,minecraft:lava)
B(-8,3,8,minecraft:lava)
B(-8,4,8,minecraft:lava[level=2])
B(-7,0,-7,minecraft:lava)
B(-7,1,-7,minecraft:lava)
B(-7,2,-7,minecraft:lava)
B(-7,3,-7,minecraft:lava)
B(-7,4,-7,minecraft:lava[level=2])
B(-7,0,-6,minecraft:lava)
B(-7,1,-6,minecraft:lava)
B(-7,2,-6,minecraft:lava)
B(-7,3,-6,minecraft:lava)
B(-7,4,-6,minecraft:lava)
B(-7,0,-5,minecraft:lava)
B(-7,1,-5,minecraft:lava)
B(-7,2,-5,minecraft:lava)
B(-7,3,-5,minecraft:lava)
B(-7,4,-5,minecraft:lava)
B(-7,5,-5,minecraft:lava[level=2])
B(-7,0,-4,minecraft:lava)
B(-7,1,-4,minecraft:lava)
B(-7,2,-4,minecraft:lava)
B(-7,3,-4,minecraft:lava)
B(-7,4,-4,minecraft:lava)
B(-7,5,-4,minecraft:lava)
B(-7,6,-4,minecraft:lava[level=2])
B(-7,0,-3,minecraft:lava)
B(-7,1,-3,minecraft:lava)
B(-7,2,-3,minecraft:lava)
B(-7,3,-3,minecraft:lava)
B(-7,4,-3,minecraft:lava)
B(-7,5,-3,minecraft:lava)
B(-7,6,-3,minecraft:lava[level=2])
B(-7,0,-2,minecraft:lava)
B(-7,1,-2,minecraft:lava)
B(-7,2,-2,minecraft:lava)
B(-7,3,-2,minecraft:lava)
B(-7,4,-2,minecraft:lava)
B(-7,5,-2,minecraft:lava[level=2])
B(-7,0,-1,minecraft:lava)
B(-7,1,-1,minecraft:lava)
B(-7,2,-1,minecraft:lava)
B(-7,3,-1,minecraft:lava)
B(-7,4,-1,minecraft:lava)
B(-7,5,-1,minecraft:lava[level=2])
B(-7,0,0,minecraft:lava)
B(-7,1,0,minecraft:lava)
B(-7,2,0,minecraft:lava)
B(-7,3,0,minecraft:lava)
B(-7,4,0,minecraft:lava[level=2])
B(-7,0,1,minecraft:lava)
B(-7,1,1,minecraft:lava)
B(-7,2,1,minecraft:lava)
B(-7,3,1,minecraft:lava)
B(-7,4,1,minecraft:lava[level=2])
B(-7,0,2,minecraft:lava)
B(-7,1,2,minecraft:lava)
B(-7,2,2,minecraft:lava)
B(-7,3,2,minecraft:lava)
B(-7,4,2,minecraft:lava[level=2])
B(-7,0,3,minecraft:lava)
B(-7,1,3,minecraft:lava)
B(-7,2,3,minecraft:lava)
B(-7,3,3,minecraft:lava)
B(-7,4,3,minecraft:lava[level=2])
B(-7,0,4,minecraft:lava)
B(-7,1,4,minecraft:lava)
B(-7,2,4,minecraft:lava)
B(-7,3,4,minecraft:lava)
B(-7,4,4,minecraft:lava[level=2])
B(-7,0,5,minecraft:lava)
B(-7,1,5,minecraft:lava)
B(-7,2,5,minecraft:lava)
B(-7,3,5,minecraft:lava)
B(-7,4,5,minecraft:lava[level=2])
B(-7,0,6,minecraft:lava)
B(-7,1,6,minecraft:lava)
B(-7,2,6,minecraft:lava)
B(-7,3,6,minecraft:lava)
B(-7,4,6,minecraft:lava[level=2])
B(-7,0,7,minecraft:lava)
B(-7,1,7,minecraft:lava)
B(-7,2,7,minecraft:lava)
B(-7,3,7,minecraft:lava)
B(-7,4,7,minecraft:lava[level=2])
B(-7,0,8,minecraft:lava)
B(-7,1,8,minecraft:lava)
B(-7,2,8,minecraft:lava)
B(-7,3,8,minecraft:lava)
B(-7,4,8,minecraft:lava)
B(-6,0,-7,minecraft:lava)
B(-6,1,-7,minecraft:lava)
B(-6,2,-7,minecraft:lava)
B(-6,3,-7,minecraft:lava)
B(-6,4,-7,minecraft:lava)
B(-6,5,-7,minecraft:lava[level=2])
B(-6,0,-6,minecraft:lava)
B(-6,1,-6,minecraft:lava)
B(-6,2,-6,minecraft:lava)
B(-6,3,-6,minecraft:lava)
B(-6,4,-6,minecraft:lava)
B(-6,0,-5,minecraft:lava)
B(-6,1,-5,minecraft:lava)
B(-6,2,-5,minecraft:lava)
B(-6,3,-5,minecraft:lava)
B(-6,4,-5,minecraft:lava[level=8])
B(-6,5,-5,minecraft:lava[level=8])
B(-6,6,-5,minecraft:lava[level=8])
B(-6,7,-5,minecraft:lava[level=2])
B(-6,0,-4,minecraft:lava)
B(-6,1,-4,minecraft:lava)
B(-6,2,-4,minecraft:lava)
B(-6,3,-4,minecraft:lava)
B(-6,4,-4,minecraft:lava)
B(-6,5,-4,minecraft:lava)
B(-6,6,-4,minecraft:lava)
B(-6,7,-4,minecraft:lava[level=2])
B(-6,0,-3,minecraft:lava)
B(-6,1,-3,minecraft:lava)
B(-6,2,-3,minecraft:lava)
B(-6,3,-3,minecraft:lava)
B(-6,4,-3,minecraft:lava)
B(-6,5,-3,minecraft:lava)
B(-6,6,-3,minecraft:lava)
B(-6,7,-3,minecraft:lava[level=2])
B(-6,0,-2,minecraft:lava)
B(-6,1,-2,minecraft:lava)
B(-6,2,-2,minecraft:lava)
B(-6,3,-2,minecraft:lava)
B(-6,4,-2,minecraft:lava)
B(-6,5,-2,minecraft:lava)
B(-6,6,-2,minecraft:lava[level=8])
B(-6,7,-2,minecraft:lava[level=2])
B(-6,0,-1,minecraft:lava)
B(-6,1,-1,minecraft:lava)
B(-6,2,-1,minecraft:lava)
B(-6,3,-1,minecraft:lava)
B(-6,4,-1,minecraft:lava)
B(-6,5,-1,minecraft:lava)
B(-6,6,-1,minecraft:lava[level=2])
B(-6,0,0,minecraft:lava)
B(-6,1,0,minecraft:lava)
B(-6,2,0,minecraft:lava)
B(-6,3,0,minecraft:lava)
B(-6,4,0,minecraft:lava)
B(-6,5,0,minecraft:lava[level=8])
B(-6,6,0,minecraft:lava[level=2])
B(-6,0,1,minecraft:lava)
B(-6,1,1,minecraft:lava)
B(-6,2,1,minecraft:lava)
B(-6,3,1,minecraft:lava)
B(-6,4,1,minecraft:lava)
B(-6,5,1,minecraft:lava[level=8])
B(-6,6,1,minecraft:lava[level=2])
B(-6,0,2,minecraft:lava)
B(-6,1,2,minecraft:lava)
B(-6,2,2,minecraft:lava)
B(-6,3,2,minecraft:lava)
B(-6,4,2,minecraft:lava)
B(-6,5,2,minecraft:lava[level=8])
B(-6,6,2,minecraft:lava[level=2])
B(-6,0,3,minecraft:lava)
B(-6,1,3,minecraft:lava)
B(-6,2,3,minecraft:lava)
B(-6,3,3,minecraft:lava)
B(-6,4,3,minecraft:lava)
B(-6,5,3,minecraft:lava[level=8])
B(-6,6,3,minecraft:lava[level=2])
B(-6,0,4,minecraft:lava)
B(-6,1,4,minecraft:lava)
B(-6,2,4,minecraft:lava)
B(-6,3,4,minecraft:lava)
B(-6,4,4,minecraft:lava)
B(-6,5,4,minecraft:lava[level=8])
B(-6,6,4,minecraft:lava[level=2])
B(-6,0,5,minecraft:lava)
B(-6,1,5,minecraft:lava)
B(-6,2,5,minecraft:lava)
B(-6,3,5,minecraft:lava)
B(-6,4,5,minecraft:lava)
B(-6,5,5,minecraft:lava[level=8])
B(-6,6,5,minecraft:lava[level=2])
B(-6,0,6,minecraft:lava)
B(-6,1,6,minecraft:lava)
B(-6,2,6,minecraft:lava)
B(-6,3,6,minecraft:lava)
B(-6,4,6,minecraft:lava)
B(-6,5,6,minecraft:lava[level=8])
B(-6,6,6,minecraft:lava[level=2])
B(-6,0,7,minecraft:lava)
B(-6,1,7,minecraft:lava)
B(-6,2,7,minecraft:lava)
B(-6,3,7,minecraft:lava)
B(-6,4,7,minecraft:lava)
B(-6,0,8,minecraft:lava)
B(-6,1,8,minecraft:lava)
B(-6,2,8,minecraft:lava)
B(-6,3,8,minecraft:lava)
B(-6,4,8,minecraft:lava)
B(-6,5,8,minecraft:lava[level=2])
B(-5,0,-7,minecraft:lava)
B(-5,1,-7,minecraft:lava)
B(-5,2,-7,minecraft:lava)
B(-5,3,-7,minecraft:lava)
B(-5,4,-7,minecraft:lava)
B(-5,5,-7,minecraft:lava)
B(-5,0,-6,minecraft:lava)
B(-5,1,-6,minecraft:lava)
B(-5,2,-6,minecraft:lava)
B(-5,3,-6,minecraft:lava)
B(-5,4,-6,minecraft:lava)
B(-5,5,-6,minecraft:lava[level=8])
B(-5,6,-6,minecraft:lava[level=8])
B(-5,7,-6,minecraft:lava[level=8])
B(-5,8,-6,minecraft:lava[level=2])
B(-5,0,-5,minecraft:lava)
B(-5,1,-5,minecraft:lava)
B(-5,2,-5,minecraft:lava)
B(-5,3,-5,minecraft:lava)
B(-5,4,-5,minecraft:lava)
B(-5,5,-5,minecraft:lava)
B(-5,6,-5,minecraft:lava)
B(-5,7,-5,minecraft:lava)
B(-5,8,-5,minecraft:lava[level=8])
B(-5,9,-5,minecraft:lava[level=2])
B(-5,0,-4,minecraft:lava)
B(-5,1,-4,minecraft:lava)
B(-5,2,-4,minecraft:lava)
B(-5,3,-4,minecraft:lava)
B(-5,4,-4,minecraft:lava)
B(-5,5,-4,minecraft:lava)
B(-5,6,-4,minecraft:lava)
B(-5,7,-4,minecraft:lava)
B(-5,8,-4,minecraft:lava[level=8])
B(-5,9,-4,minecraft:lava[level=2])
B(-5,0,-3,minecraft:lava)
B(-5,1,-3,minecraft:lava)
B(-5,2,-3,minecraft:lava)
B(-5,3,-3,minecraft:lava)
B(-5,4,-3,minecraft:lava)
B(-5,5,-3,minecraft:lava)
B(-5,6,-3,minecraft:lava)
B(-5,7,-3,minecraft:lava)
B(-5,8,-3,minecraft:lava[level=8])
B(-5,9,-3,minecraft:lava[level=2])
B(-5,0,-2,minecraft:lava)
B(-5,1,-2,minecraft:lava)
B(-5,2,-2,minecraft:lava)
B(-5,3,-2,minecraft:lava)
B(-5,4,-2,minecraft:lava)
B(-5,5,-2,minecraft:lava)
B(-5,6,-2,minecraft:lava)
B(-5,7,-2,minecraft:lava)
B(-5,8,-2,minecraft:lava[level=8])
B(-5,9,-2,minecraft:lava[level=2])
B(-5,0,-1,minecraft:lava)
B(-5,1,-1,minecraft:lava)
B(-5,2,-1,minecraft:lava)
B(-5,3,-1,minecraft:lava)
B(-5,4,-1,minecraft:lava)
B(-5,5,-1,minecraft:lava)
B(-5,6,-1,minecraft:lava)
B(-5,7,-1,minecraft:lava[level=8])
B(-5,8,-1,minecraft:lava[level=8])
B(-5,9,-1,minecraft:lava[level=2])
B(-5,0,0,minecraft:lava)
B(-5,1,0,minecraft:lava)
B(-5,2,0,minecraft:lava)
B(-5,3,0,minecraft:lava)
B(-5,4,0,minecraft:lava)
B(-5,5,0,minecraft:lava)
B(-5,6,0,minecraft:lava)
B(-5,7,0,minecraft:lava[level=8])
B(-5,8,0,minecraft:lava[level=2])
B(-5,0,1,minecraft:lava)
B(-5,1,1,minecraft:lava)
B(-5,2,1,minecraft:lava)
B(-5,3,1,minecraft:lava)
B(-5,4,1,minecraft:lava)
B(-5,5,1,minecraft:lava)
B(-5,6,1,minecraft:lava)
B(-5,7,1,minecraft:lava[level=8])
B(-5,8,1,minecraft:lava[level=2])
B(-5,0,2,minecraft:lava)
B(-5,1,2,minecraft:lava)
B(-5,2,2,minecraft:lava)
B(-5,3,2,minecraft:lava)
B(-5,4,2,minecraft:lava)
B(-5,5,2,minecraft:lava)
B(-5,6,2,minecraft:lava)
B(-5,7,2,minecraft:lava[level=8])
B(-5,8,2,minecraft:lava[level=2])
B(-5,0,3,minecraft:lava)
B(-5,1,3,minecraft:lava)
B(-5,2,3,minecraft:lava)
B(-5,3,3,minecraft:lava)
B(-5,4,3,minecraft:lava)
B(-5,5,3,minecraft:lava)
B(-5,6,3,minecraft:lava)
B(-5,7,3,minecraft:lava[level=8])
B(-5,8,3,minecraft:lava[level=2])
B(-5,0,4,minecraft:lava)
B(-5,1,4,minecraft:lava)
B(-5,2,4,minecraft:lava)
B(-5,3,4,minecraft:lava)
B(-5,4,4,minecraft:lava)
B(-5,5,4,minecraft:lava)
B(-5,6,4,minecraft:lava)
B(-5,7,4,minecraft:lava[level=8])
B(-5,8,4,minecraft:lava[level=2])
B(-5,0,5,minecraft:lava)
B(-5,1,5,minecraft:lava)
B(-5,2,5,minecraft:lava)
B(-5,3,5,minecraft:lava)
B(-5,4,5,minecraft:lava)
B(-5,5,5,minecraft:lava)
B(-5,6,5,minecraft:lava)
B(-5,7,5,minecraft:lava[level=8])
B(-5,8,5,minecraft:lava[level=2])
B(-5,0,6,minecraft:lava)
B(-5,1,6,minecraft:lava)
B(-5,2,6,minecraft:lava)
B(-5,3,6,minecraft:lava)
B(-5,4,6,minecraft:lava)
B(-5,5,6,minecraft:lava)
B(-5,6,6,minecraft:lava)
B(-5,7,6,minecraft:lava[level=8])
B(-5,8,6,minecraft:lava[level=2])
B(-5,0,7,minecraft:lava)
B(-5,1,7,minecraft:lava)
B(-5,2,7,minecraft:lava)
B(-5,3,7,minecraft:lava)
B(-5,4,7,minecraft:lava)
B(-5,5,7,minecraft:lava[level=8])
B(-5,6,7,minecraft:lava[level=8])
B(-5,7,7,minecraft:lava[level=8])
B(-5,8,7,minecraft:lava[level=8])
B(-5,9,7,minecraft:lava[level=2])
B(-5,0,8,minecraft:lava)
B(-5,1,8,minecraft:lava)
B(-5,2,8,minecraft:lava)
B(-5,3,8,minecraft:lava)
B(-5,4,8,minecraft:lava)
B(-5,5,8,minecraft:lava)
B(-5,6,8,minecraft:lava[level=2])
B(-4,0,-7,minecraft:lava)
B(-4,1,-7,minecraft:lava)
B(-4,2,-7,minecraft:lava)
B(-4,3,-7,minecraft:lava)
B(-4,4,-7,minecraft:lava)
B(-4,5,-7,minecraft:lava)
B(-4,6,-7,minecraft:lava[level=8])
B(-4,7,-7,minecraft:lava[level=8])
B(-4,8,-7,minecraft:lava[level=2])
B(-4,0,-6,minecraft:lava)
B(-4,1,-6,minecraft:lava)
B(-4,2,-6,minecraft:lava)
B(-4,3,-6,minecraft:lava)
B(-4,4,-6,minecraft:lava)
B(-4,5,-6,minecraft:lava)
B(-4,6,-6,minecraft:lava)
B(-4,7,-6,minecraft:lava)
B(-4,8,-6,minecraft:lava)
B(-4,9,-6,minecraft:lava[level=2])
B(-4,0,-5,minecraft:lava)
B(-4,1,-5,minecraft:lava)
B(-4,2,-5,minecraft:lava)
B(-4,3,-5,minecraft:lava)
B(-4,4,-5,minecraft:lava)
B(-4,5,-5,minecraft:lava)
B(-4,6,-5,minecraft:lava)
B(-4,7,-5,minecraft:lava)
B(-4,8,-5,minecraft:lava)
B(-4,9,-5,minecraft:lava)
B(-4,10,-5,minecraft:lava[level=2])
B(-4,0,-4,minecraft:lava)
B(-4,1,-4,minecraft:lava)
B(-4,2,-4,minecraft:lava)
B(-4,3,-4,minecraft:lava)
B(-4,4,-4,minecraft:lava)
B(-4,5,-4,minecraft:lava)
B(-4,6,-4,minecraft:lava)
B(-4,7,-4,minecraft:lava)
B(-4,8,-4,minecraft:lava)
B(-4,9,-4,minecraft:lava)
B(-4,10,-4,minecraft:lava[level=8])
B(-4,11,-4,minecraft:lava[level=2])
B(-4,0,-3,minecraft:lava)
B(-4,1,-3,minecraft:lava)
B(-4,2,-3,minecraft:lava)
B(-4,3,-3,minecraft:lava)
B(-4,4,-3,minecraft:lava)
B(-4,5,-3,minecraft:lava)
B(-4,6,-3,minecraft:lava)
B(-4,7,-3,minecraft:lava)
B(-4,8,-3,minecraft:lava)
B(-4,9,-3,minecraft:lava)
B(-4,10,-3,minecraft:lava[level=8])
B(-4,11,-3,minecraft:lava[level=2])
B(-4,0,-2,minecraft:lava)
B(-4,1,-2,minecraft:lava)
B(-4,2,-2,minecraft:lava)
B(-4,3,-2,minecraft:lava)
B(-4,4,-2,minecraft:lava)
B(-4,5,-2,minecraft:lava)
B(-4,6,-2,minecraft:lava)
B(-4,7,-2,minecraft:lava)
B(-4,8,-2,minecraft:lava)
B(-4,9,-2,minecraft:lava)
B(-4,10,-2,minecraft:lava[level=8])
B(-4,11,-2,minecraft:lava[level=2])
B(-4,0,-1,minecraft:lava)
B(-4,1,-1,minecraft:lava)
B(-4,2,-1,minecraft:lava)
B(-4,3,-1,minecraft:lava)
B(-4,4,-1,minecraft:lava)
B(-4,5,-1,minecraft:lava)
B(-4,6,-1,minecraft:lava)
B(-4,7,-1,minecraft:lava)
B(-4,8,-1,minecraft:lava)
B(-4,9,-1,minecraft:lava)
B(-4,10,-1,minecraft:lava[level=8])
B(-4,11,-1,minecraft:lava[level=2])
B(-4,0,0,minecraft:lava)
B(-4,1,0,minecraft:lava)
B(-4,2,0,minecraft:lava)
B(-4,3,0,minecraft:lava)
B(-4,4,0,minecraft:lava)
B(-4,5,0,minecraft:lava)
B(-4,6,0,minecraft:lava)
B(-4,7,0,minecraft:lava)
B(-4,8,0,minecraft:lava)
B(-4,9,0,minecraft:lava[level=8])
B(-4,10,0,minecraft:lava[level=2])
B(-4,0,1,minecraft:lava)
B(-4,1,1,minecraft:lava)
B(-4,2,1,minecraft:lava)
B(-4,3,1,minecraft:lava)
B(-4,4,1,minecraft:lava)
B(-4,5,1,minecraft:lava)
B(-4,6,1,minecraft:lava)
B(-4,7,1,minecraft:lava)
B(-4,8,1,minecraft:lava)
B(-4,9,1,minecraft:lava[level=8])
B(-4,10,1,minecraft:lava[level=2])
B(-4,0,2,minecraft:lava)
B(-4,1,2,minecraft:lava)
B(-4,2,2,minecraft:lava)
B(-4,3,2,minecraft:lava)
B(-4,4,2,minecraft:lava)
B(-4,5,2,minecraft:lava)
B(-4,6,2,minecraft:lava)
B(-4,7,2,minecraft:lava)
B(-4,8,2,minecraft:lava)
B(-4,9,2,minecraft:lava[level=8])
B(-4,10,2,minecraft:lava[level=2])
B(-4,0,3,minecraft:lava)
B(-4,1,3,minecraft:lava)
B(-4,2,3,minecraft:lava)
B(-4,3,3,minecraft:lava)
B(-4,4,3,minecraft:lava)
B(-4,5,3,minecraft:lava)
B(-4,6,3,minecraft:lava)
B(-4,7,3,minecraft:lava)
B(-4,8,3,minecraft:lava)
B(-4,9,3,minecraft:lava[level=8])
B(-4,10,3,minecraft:lava[level=2])
B(-4,0,4,minecraft:lava)
B(-4,1,4,minecraft:lava)
B(-4,2,4,minecraft:lava)
B(-4,3,4,minecraft:lava)
B(-4,4,4,minecraft:lava)
B(-4,5,4,minecraft:lava)
B(-4,6,4,minecraft:lava)
B(-4,7,4,minecraft:lava)
B(-4,8,4,minecraft:lava)
B(-4,9,4,minecraft:lava[level=8])
B(-4,10,4,minecraft:lava[level=2])
B(-4,0,5,minecraft:lava)
B(-4,1,5,minecraft:lava)
B(-4,2,5,minecraft:lava)
B(-4,3,5,minecraft:lava)
B(-4,4,5,minecraft:lava)
B(-4,5,5,minecraft:lava)
B(-4,6,5,minecraft:lava)
B(-4,7,5,minecraft:lava)
B(-4,8,5,minecraft:lava)
B(-4,9,5,minecraft:lava[level=8])
B(-4,10,5,minecraft:lava[level=2])
B(-4,0,6,minecraft:lava)
B(-4,1,6,minecraft:lava)
B(-4,2,6,minecraft:lava)
B(-4,3,6,minecraft:lava)
B(-4,4,6,minecraft:lava)
B(-4,5,6,minecraft:lava)
B(-4,6,6,minecraft:lava)
B(-4,7,6,minecraft:lava)
B(-4,8,6,minecraft:lava)
B(-4,9,6,minecraft:lava[level=8])
B(-4,10,6,minecraft:lava[level=2])
B(-4,0,7,minecraft:lava)
B(-4,1,7,minecraft:lava)
B(-4,2,7,minecraft:lava)
B(-4,3,7,minecraft:lava)
B(-4,4,7,minecraft:lava)
B(-4,5,7,minecraft:lava)
B(-4,6,7,minecraft:lava)
B(-4,7,7,minecraft:lava)
B(-4,8,7,minecraft:lava)
B(-4,9,7,minecraft:lava)
B(-4,10,7,minecraft:lava[level=2])
B(-4,0,8,minecraft:lava)
B(-4,1,8,minecraft:lava)
B(-4,2,8,minecraft:lava)
B(-4,3,8,minecraft:lava)
B(-4,4,8,minecraft:lava)
B(-4,5,8,minecraft:lava)
B(-4,6,8,minecraft:lava)
B(-4,7,8,minecraft:lava[level=8])
B(-4,8,8,minecraft:lava[level=8])
B(-4,9,8,minecraft:lava[level=2])
B(-3,0,-7,minecraft:lava)
B(-3,1,-7,minecraft:lava)
B(-3,2,-7,minecraft:lava)
B(-3,3,-7,minecraft:lava)
B(-3,4,-7,minecraft:lava)
B(-3,5,-7,minecraft:lava)
B(-3,6,-7,minecraft:lava)
B(-3,7,-7,minecraft:lava)
B(-3,8,-7,minecraft:lava)
B(-3,9,-7,minecraft:lava[level=8])
B(-3,10,-7,minecraft:lava[level=2])
B(-3,0,-6,minecraft:lava)
B(-3,1,-6,minecraft:lava)
B(-3,2,-6,minecraft:lava)
B(-3,3,-6,minecraft:lava)
B(-3,4,-6,minecraft:lava)
B(-3,5,-6,minecraft:lava)
B(-3,6,-6,minecraft:lava)
B(-3,7,-6,minecraft:lava)
B(-3,8,-6,minecraft:lava)
B(-3,9,-6,minecraft:lava)
B(-3,10,-6,minecraft:lava[level=2])
B(-3,0,-5,minecraft:lava)
B(-3,1,-5,minecraft:lava)
B(-3,2,-5,minecraft:lava)
B(-3,3,-5,minecraft:lava)
B(-3,4,-5,minecraft:lava)
B(-3,5,-5,minecraft:lava)
B(-3,6,-5,minecraft:lava)
B(-3,7,-5,minecraft:lava)
B(-3,8,-5,minecraft:lava)
B(-3,9,-5,minecraft:lava)
B(-3,10,-5,minecraft:lava)
B(-3,11,-5,minecraft:lava[level=8])
B(-3,12,-5,minecraft:lava[level=8])
B(-3,13,-5,minecraft:lava[level=2])
B(-3,0,-4,minecraft:lava)
B(-3,1,-4,minecraft:lava)
B(-3,2,-4,minecraft:lava)
B(-3,3,-4,minecraft:lava)
B(-3,4,-4,minecraft:lava)
B(-3,5,-4,minecraft:lava)
B(-3,6,-4,minecraft:lava)
B(-3,7,-4,minecraft:lava)
B(-3,8,-4,minecraft:lava)
B(-3,9,-4,minecraft:lava)
B(-3,10,-4,minecraft:lava)
B(-3,11,-4,minecraft:lava)
B(-3,12,-4,minecraft:lava[level=8])
B(-3,13,-4,minecraft:lava[level=2])
B(-3,0,-3,minecraft:lava)
B(-3,1,-3,minecraft:lava)
B(-3,2,-3,minecraft:lava)
B(-3,3,-3,minecraft:lava)
B(-3,4,-3,minecraft:lava)
B(-3,5,-3,minecraft:lava)
B(-3,6,-3,minecraft:lava)
B(-3,7,-3,minecraft:lava)
B(-3,8,-3,minecraft:lava)
B(-3,9,-3,minecraft:lava)
B(-3,10,-3,minecraft:lava)
B(-3,11,-3,minecraft:lava)
B(-3,12,-3,minecraft:lava[level=8])
B(-3,13,-3,minecraft:lava[level=2])
B(-3,0,-2,minecraft:lava)
B(-3,1,-2,minecraft:lava)
B(-3,2,-2,minecraft:lava)
B(-3,3,-2,minecraft:lava)
B(-3,4,-2,minecraft:lava)
B(-3,5,-2,minecraft:lava)
B(-3,6,-2,minecraft:lava)
B(-3,7,-2,minecraft:lava)
B(-3,8,-2,minecraft:lava)
B(-3,9,-2,minecraft:lava)
B(-3,10,-2,minecraft:lava)
B(-3,11,-2,minecraft:lava)
B(-3,12,-2,minecraft:lava[level=2])
B(-3,0,-1,minecraft:lava)
B(-3,1,-1,minecraft:lava)
B(-3,2,-1,minecraft:lava)
B(-3,3,-1,minecraft:lava)
B(-3,4,-1,minecraft:lava)
B(-3,5,-1,minecraft:lava)
B(-3,6,-1,minecraft:lava)
B(-3,7,-1,minecraft:lava)
B(-3,8,-1,minecraft:lava)
B(-3,9,-1,minecraft:lava)
B(-3,10,-1,minecraft:lava)
B(-3,11,-1,minecraft:lava)
B(-3,12,-1,minecraft:lava[level=2])
B(-3,0,0,minecraft:lava)
B(-3,1,0,minecraft:lava)
B(-3,2,0,minecraft:lava)
B(-3,3,0,minecraft:lava)
B(-3,4,0,minecraft:lava)
B(-3,5,0,minecraft:lava)
B(-3,6,0,minecraft:lava)
B(-3,7,0,minecraft:lava)
B(-3,8,0,minecraft:lava)
B(-3,9,0,minecraft:lava)
B(-3,10,0,minecraft:lava)
B(-3,11,0,minecraft:lava[level=8])
B(-3,12,0,minecraft:lava[level=2])
B(-3,0,1,minecraft:lava)
B(-3,1,1,minecraft:lava)
B(-3,2,1,minecraft:lava)
B(-3,3,1,minecraft:lava)
B(-3,4,1,minecraft:lava)
B(-3,5,1,minecraft:lava)
B(-3,6,1,minecraft:lava)
B(-3,7,1,minecraft:lava)
B(-3,8,1,minecraft:lava)
B(-3,9,1,minecraft:lava)
B(-3,10,1,minecraft:lava)
B(-3,11,1,minecraft:lava[level=2])
B(-3,0,2,minecraft:lava)
B(-3,1,2,minecraft:lava)
B(-3,2,2,minecraft:lava)
B(-3,3,2,minecraft:lava)
B(-3,4,2,minecraft:lava)
B(-3,5,2,minecraft:lava)
B(-3,6,2,minecraft:lava)
B(-3,7,2,minecraft:lava)
B(-3,8,2,minecraft:lava)
B(-3,9,2,minecraft:lava)
B(-3,10,2,minecraft:lava)
B(-3,11,2,minecraft:lava[level=2])
B(-3,0,3,minecraft:lava)
B(-3,1,3,minecraft:lava)
B(-3,2,3,minecraft:lava)
B(-3,3,3,minecraft:lava)
B(-3,4,3,minecraft:lava)
B(-3,5,3,minecraft:lava)
B(-3,6,3,minecraft:lava)
B(-3,7,3,minecraft:lava)
B(-3,8,3,minecraft:lava)
B(-3,9,3,minecraft:lava)
B(-3,10,3,minecraft:lava)
B(-3,11,3,minecraft:lava[level=2])
B(-3,0,4,minecraft:lava)
B(-3,1,4,minecraft:lava)
B(-3,2,4,minecraft:lava)
B(-3,3,4,minecraft:lava)
B(-3,4,4,minecraft:lava)
B(-3,5,4,minecraft:lava)
B(-3,6,4,minecraft:lava)
B(-3,7,4,minecraft:lava)
B(-3,8,4,minecraft:lava)
B(-3,9,4,minecraft:lava)
B(-3,10,4,minecraft:lava)
B(-3,11,4,minecraft:lava[level=2])
B(-3,0,5,minecraft:lava)
B(-3,1,5,minecraft:lava)
B(-3,2,5,minecraft:lava)
B(-3,3,5,minecraft:lava)
B(-3,4,5,minecraft:lava)
B(-3,5,5,minecraft:lava)
B(-3,6,5,minecraft:lava)
B(-3,7,5,minecraft:lava)
B(-3,8,5,minecraft:lava)
B(-3,9,5,minecraft:lava)
B(-3,10,5,minecraft:lava)
B(-3,11,5,minecraft:lava[level=2])
B(-3,0,6,minecraft:lava)
B(-3,1,6,minecraft:lava)
B(-3,2,6,minecraft:lava)
B(-3,3,6,minecraft:lava)
B(-3,4,6,minecraft:lava)
B(-3,5,6,minecraft:lava)
B(-3,6,6,minecraft:lava)
B(-3,7,6,minecraft:lava)
B(-3,8,6,minecraft:lava)
B(-3,9,6,minecraft:lava)
B(-3,10,6,minecraft:lava)
B(-3,11,6,minecraft:lava[level=2])
B(-3,0,7,minecraft:lava)
B(-3,1,7,minecraft:lava)
B(-3,2,7,minecraft:lava)
B(-3,3,7,minecraft:lava)
B(-3,4,7,minecraft:lava)
B(-3,5,7,minecraft:lava)
B(-3,6,7,minecraft:lava)
B(-3,7,7,minecraft:lava)
B(-3,8,7,minecraft:lava)
B(-3,9,7,minecraft:lava)
B(-3,10,7,minecraft:lava)
B(-3,11,7,minecraft:lava[level=2])
B(-3,0,8,minecraft:lava)
B(-3,1,8,minecraft:lava)
B(-3,2,8,minecraft:lava)
B(-3,3,8,minecraft:lava)
B(-3,4,8,minecraft:lava)
B(-3,5,8,minecraft:lava)
B(-3,6,8,minecraft:lava)
B(-3,7,8,minecraft:lava)
B(-3,8,8,minecraft:lava[level=8])
B(-3,9,8,minecraft:lava[level=8])
B(-3,10,8,minecraft:lava[level=2])
B(-2,0,-7,minecraft:lava)
B(-2,1,-7,minecraft:lava)
B(-2,2,-7,minecraft:lava)
B(-2,3,-7,minecraft:lava)
B(-2,4,-7,minecraft:lava)
B(-2,5,-7,minecraft:lava)
B(-2,6,-7,minecraft:lava)
B(-2,7,-7,minecraft:lava)
B(-2,8,-7,minecraft:lava)
B(-2,9,-7,minecraft:lava)
B(-2,10,-7,minecraft:lava)
B(-2,11,-7,minecraft:lava[level=2])
B(-2,0,-6,minecraft:lava)
B(-2,1,-6,minecraft:lava)
B(-2,2,-6,minecraft:lava)
B(-2,3,-6,minecraft:lava)
B(-2,4,-6,minecraft:lava)
B(-2,5,-6,minecraft:lava)
B(-2,6,-6,minecraft:lava)
B(-2,7,-6,minecraft:lava)
B(-2,8,-6,minecraft:lava)
B(-2,9,-6,minecraft:lava)
B(-2,10,-6,minecraft:lava)
B(-2,11,-6,minecraft:lava[level=8])
B(-2,12,-6,minecraft:lava[level=8])
B(-2,13,-6,minecraft:lava[level=2])
B(-2,0,-5,minecraft:lava)
B(-2,1,-5,minecraft:lava)
B(-2,2,-5,minecraft:lava)
B(-2,3,-5,minecraft:lava)
B(-2,4,-5,minecraft:lava)
B(-2,5,-5,minecraft:lava)
B(-2,6,-5,minecraft:lava)
B(-2,7,-5,minecraft:lava)
B(-2,8,-5,minecraft:lava)
B(-2,9,-5,minecraft:lava)
B(-2,10,-5,minecraft:lava)
B(-2,11,-5,minecraft:lava)
B(-2,12,-5,minecraft:lava)
B(-2,13,-5,minecraft:lava)
B(-2,14,-5,minecraft:lava[level=2])
B(-2,0,-4,minecraft:lava)
B(-2,1,-4,minecraft:lava)
B(-2,2,-4,minecraft:lava)
B(-2,3,-4,minecraft:lava)
B(-2,4,-4,minecraft:lava)
B(-2,5,-4,minecraft:lava)
B(-2,6,-4,minecraft:lava)
B(-2,7,-4,minecraft:lava)
B(-2,8,-4,minecraft:lava)
B(-2,9,-4,minecraft:lava)
B(-2,10,-4,minecraft:lava)
B(-2,11,-4,minecraft:lava)
B(-2,12,-4,minecraft:lava)
B(-2,13,-4,minecraft:lava)
B(-2,14,-4,minecraft:lava[level=2])
B(-2,0,-3,minecraft:lava)
B(-2,1,-3,minecraft:lava)
B(-2,2,-3,minecraft:lava)
B(-2,3,-3,minecraft:lava)
B(-2,4,-3,minecraft:lava)
B(-2,5,-3,minecraft:lava)
B(-2,6,-3,minecraft:lava)
B(-2,7,-3,minecraft:lava)
B(-2,8,-3,minecraft:lava)
B(-2,9,-3,minecraft:lava)
B(-2,10,-3,minecraft:lava)
B(-2,11,-3,minecraft:lava)
B(-2,12,-3,minecraft:lava)
B(-2,13,-3,minecraft:lava)
B(-2,14,-3,minecraft:lava[level=2])
B(-2,0,-2,minecraft:lava)
B(-2,1,-2,minecraft:lava)
B(-2,2,-2,minecraft:lava)
B(-2,3,-2,minecraft:lava)
B(-2,4,-2,minecraft:lava)
B(-2,5,-2,minecraft:lava)
B(-2,6,-2,minecraft:lava)
B(-2,7,-2,minecraft:lava)
B(-2,8,-2,minecraft:lava)
B(-2,9,-2,minecraft:lava)
B(-2,10,-2,minecraft:lava)
B(-2,11,-2,minecraft:lava)
B(-2,12,-2,minecraft:lava)
B(-2,13,-2,minecraft:lava[level=8])
B(-2,14,-2,minecraft:lava[level=2])
B(-2,0,-1,minecraft:lava)
B(-2,1,-1,minecraft:lava)
B(-2,2,-1,minecraft:lava)
B(-2,3,-1,minecraft:lava)
B(-2,4,-1,minecraft:lava)
B(-2,5,-1,minecraft:lava)
B(-2,6,-1,minecraft:lava)
B(-2,7,-1,minecraft:lava)
B(-2,8,-1,minecraft:lava)
B(-2,9,-1,minecraft:lava)
B(-2,10,-1,minecraft:lava)
B(-2,11,-1,minecraft:lava)
B(-2,12,-1,minecraft:lava)
B(-2,13,-1,minecraft:lava[level=2])
B(-2,0,0,minecraft:lava)
B(-2,1,0,minecraft:lava)
B(-2,2,0,minecraft:lava)
B(-2,3,0,minecraft:lava)
B(-2,4,0,minecraft:lava)
B(-2,5,0,minecraft:lava)
B(-2,6,0,minecraft:lava)
B(-2,7,0,minecraft:lava)
B(-2,8,0,minecraft:lava)
B(-2,9,0,minecraft:lava)
B(-2,10,0,minecraft:lava)
B(-2,11,0,minecraft:lava)
B(-2,12,0,minecraft:lava)
B(-2,13,0,minecraft:lava[level=2])
B(-2,0,1,minecraft:lava)
B(-2,1,1,minecraft:lava)
B(-2,2,1,minecraft:lava)
B(-2,3,1,minecraft:lava)
B(-2,4,1,minecraft:lava)
B(-2,5,1,minecraft:lava)
B(-2,6,1,minecraft:lava)
B(-2,7,1,minecraft:lava)
B(-2,8,1,minecraft:lava)
B(-2,9,1,minecraft:lava)
B(-2,10,1,minecraft:lava)
B(-2,11,1,minecraft:lava)
B(-2,12,1,minecraft:lava[level=2])
B(-2,0,2,minecraft:lava)
B(-2,1,2,minecraft:lava)
B(-2,2,2,minecraft:lava)
B(-2,3,2,minecraft:lava)
B(-2,4,2,minecraft:lava)
B(-2,5,2,minecraft:lava)
B(-2,6,2,minecraft:lava)
B(-2,7,2,minecraft:lava)
B(-2,8,2,minecraft:lava)
B(-2,9,2,minecraft:lava)
B(-2,10,2,minecraft:lava)
B(-2,11,2,minecraft:lava)
B(-2,12,2,minecraft:lava[level=2])
B(-2,0,3,minecraft:lava)
B(-2,1,3,minecraft:lava)
B(-2,2,3,minecraft:lava)
B(-2,3,3,minecraft:lava)
B(-2,4,3,minecraft:lava)
B(-2,5,3,minecraft:lava)
B(-2,6,3,minecraft:lava)
B(-2,7,3,minecraft:lava)
B(-2,8,3,minecraft:lava)
B(-2,9,3,minecraft:lava)
B(-2,10,3,minecraft:lava)
B(-2,11,3,minecraft:lava)
B(-2,12,3,minecraft:lava[level=2])
B(-2,0,4,minecraft:lava)
B(-2,1,4,minecraft:lava)
B(-2,2,4,minecraft:lava)
B(-2,3,4,minecraft:lava)
B(-2,4,4,minecraft:lava)
B(-2,5,4,minecraft:lava)
B(-2,6,4,minecraft:lava)
B(-2,7,4,minecraft:lava)
B(-2,8,4,minecraft:lava)
B(-2,9,4,minecraft:lava)
B(-2,10,4,minecraft:lava)
B(-2,11,4,minecraft:lava)
B(-2,12,4,minecraft:lava[level=2])
B(-2,0,5,minecraft:lava)
B(-2,1,5,minecraft:lava)
B(-2,2,5,minecraft:lava)
B(-2,3,5,minecraft:lava)
B(-2,4,5,minecraft:lava)
B(-2,5,5,minecraft:lava)
B(-2,6,5,minecraft:lava)
B(-2,7,5,minecraft:lava)
B(-2,8,5,minecraft:lava)
B(-2,9,5,minecraft:lava)
B(-2,10,5,minecraft:lava)
B(-2,11,5,minecraft:lava)
B(-2,12,5,minecraft:lava[level=2])
B(-2,0,6,minecraft:lava)
B(-2,1,6,minecraft:lava)
B(-2,2,6,minecraft:lava)
B(-2,3,6,minecraft:lava)
B(-2,4,6,minecraft:lava)
B(-2,5,6,minecraft:lava)
B(-2,6,6,minecraft:lava)
B(-2,7,6,minecraft:lava)
B(-2,8,6,minecraft:lava)
B(-2,9,6,minecraft:lava)
B(-2,10,6,minecraft:lava)
B(-2,11,6,minecraft:lava)
B(-2,12,6,minecraft:lava[level=2])
B(-2,0,7,minecraft:lava)
B(-2,1,7,minecraft:lava)
B(-2,2,7,minecraft:lava)
B(-2,3,7,minecraft:lava)
B(-2,4,7,minecraft:lava)
B(-2,5,7,minecraft:lava)
B(-2,6,7,minecraft:lava)
B(-2,7,7,minecraft:lava)
B(-2,8,7,minecraft:lava)
B(-2,9,7,minecraft:lava)
B(-2,10,7,minecraft:lava)
B(-2,11,7,minecraft:lava)
B(-2,12,7,minecraft:lava[level=8])
B(-2,13,7,minecraft:lava[level=2])
B(-2,0,8,minecraft:lava)
B(-2,1,8,minecraft:lava)
B(-2,2,8,minecraft:lava)
B(-2,3,8,minecraft:lava)
B(-2,4,8,minecraft:lava)
B(-2,5,8,minecraft:lava)
B(-2,6,8,minecraft:lava)
B(-2,7,8,minecraft:lava)
B(-2,8,8,minecraft:lava)
B(-2,9,8,minecraft:lava)
B(-2,10,8,minecraft:lava[level=8])
B(-2,11,8,minecraft:lava[level=2])
B(-1,0,-7,minecraft:lava)
B(-1,1,-7,minecraft:lava)
B(-1,2,-7,minecraft:lava)
B(-1,3,-7,minecraft:lava)
B(-1,4,-7,minecraft:lava)
B(-1,5,-7,minecraft:lava)
B(-1,6,-7,minecraft:lava)
B(-1,7,-7,minecraft:lava)
B(-1,8,-7,minecraft:lava)
B(-1,9,-7,minecraft:lava)
B(-1,10,-7,minecraft:lava)
B(-1,11,-7,minecraft:lava)
B(-1,12,-7,minecraft:lava[level=8])
B(-1,13,-7,minecraft:lava[level=8])
B(-1,14,-7,minecraft:lava[level=2])
B(-1,0,-6,minecraft:lava)
B(-1,1,-6,minecraft:lava)
B(-1,2,-6,minecraft:lava)
B(-1,3,-6,minecraft:lava)
B(-1,4,-6,minecraft:lava)
B(-1,5,-6,minecraft:lava)
B(-1,6,-6,minecraft:lava)
B(-1,7,-6,minecraft:lava)
B(-1,8,-6,minecraft:lava)
B(-1,9,-6,minecraft:lava)
B(-1,10,-6,minecraft:lava)
B(-1,11,-6,minecraft:lava)
B(-1,12,-6,minecraft:lava)
B(-1,13,-6,minecraft:lava)
B(-1,14,-6,minecraft:lava[level=2])
B(-1,0,-5,minecraft:lava)
B(-1,1,-5,minecraft:lava)
B(-1,2,-5,minecraft:lava)
B(-1,3,-5,minecraft:lava)
B(-1,4,-5,minecraft:lava)
B(-1,5,-5,minecraft:lava)
B(-1,6,-5,minecraft:lava)
B(-1,7,-5,minecraft:lava)
B(-1,8,-5,minecraft:lava)
B(-1,9,-5,minecraft:lava)
B(-1,10,-5,minecraft:lava)
B(-1,11,-5,minecraft:lava)
B(-1,12,-5,minecraft:lava)
B(-1,13,-5,minecraft:lava)
B(-1,14,-5,minecraft:lava)
B(-1,15,-5,minecraft:lava[level=2])
B(-1,0,-4,minecraft:lava)
B(-1,1,-4,minecraft:lava)
B(-1,2,-4,minecraft:lava)
B(-1,3,-4,minecraft:lava)
B(-1,4,-4,minecraft:lava)
B(-1,5,-4,minecraft:lava)
B(-1,6,-4,minecraft:lava)
B(-1,7,-4,minecraft:lava)
B(-1,8,-4,minecraft:lava)
B(-1,9,-4,minecraft:lava)
B(-1,10,-4,minecraft:lava)
B(-1,11,-4,minecraft:lava)
B(-1,12,-4,minecraft:lava)
B(-1,13,-4,minecraft:lava)
B(-1,14,-4,minecraft:lava)
B(-1,15,-4,minecraft:lava[level=2])
B(-1,0,-3,minecraft:lava)
B(-1,1,-3,minecraft:lava)
B(-1,2,-3,minecraft:lava)
B(-1,3,-3,minecraft:lava)
B(-1,4,-3,minecraft:lava)
B(-1,5,-3,minecraft:lava)
B(-1,6,-3,minecraft:lava)
B(-1,7,-3,minecraft:lava)
B(-1,8,-3,minecraft:lava)
B(-1,9,-3,minecraft:lava)
B(-1,10,-3,minecraft:lava)
B(-1,11,-3,minecraft:lava)
B(-1,12,-3,minecraft:lava)
B(-1,13,-3,minecraft:lava)
B(-1,14,-3,minecraft:lava)
B(-1,15,-3,minecraft:lava[level=8])
B(-1,16,-3,minecraft:lava[level=2])
B(-1,0,-2,minecraft:lava)
B(-1,1,-2,minecraft:lava)
B(-1,2,-2,minecraft:lava)
B(-1,3,-2,minecraft:lava)
B(-1,4,-2,minecraft:lava)
B(-1,5,-2,minecraft:lava)
B(-1,6,-2,minecraft:lava)
B(-1,7,-2,minecraft:lava)
B(-1,8,-2,minecraft:lava)
B(-1,9,-2,minecraft:lava)
B(-1,10,-2,minecraft:lava)
B(-1,11,-2,minecraft:lava)
B(-1,12,-2,minecraft:lava)
B(-1,13,-2,minecraft:lava)
B(-1,14,-2,minecraft:lava)
B(-1,15,-2,minecraft:lava[level=8])
B(-1,16,-2,minecraft:lava[level=8])
B(-1,17,-2,minecraft:lava[level=8])
B(-1,18,-2,minecraft:lava[level=8])
B(-1,19,-2,minecraft:lava[level=2])
B(-1,0,-1,minecraft:lava)
B(-1,1,-1,minecraft:lava)
B(-1,2,-1,minecraft:lava)
B(-1,3,-1,minecraft:lava)
B(-1,4,-1,minecraft:lava)
B(-1,5,-1,minecraft:lava)
B(-1,6,-1,minecraft:lava)
B(-1,7,-1,minecraft:lava)
B(-1,8,-1,minecraft:lava)
B(-1,9,-1,minecraft:lava)
B(-1,10,-1,minecraft:lava)
B(-1,11,-1,minecraft:lava)
B(-1,12,-1,minecraft:lava)
B(-1,13,-1,minecraft:lava)
B(-1,14,-1,minecraft:lava[level=8])
B(-1,15,-1,minecraft:lava[level=8])
B(-1,16,-1,minecraft:lava[level=8])
B(-1,17,-1,minecraft:lava[level=8])
B(-1,18,-1,minecraft:lava[level=8])
B(-1,19,-1,minecraft:lava[level=8])
B(-1,20,-1,minecraft:lava[level=8])
B(-1,21,-1,minecraft:lava[level=8])
B(-1,22,-1,minecraft:lava[level=8])
B(-1,23,-1,minecraft:lava[level=8])
B(-1,24,-1,minecraft:lava[level=2])
B(-1,0,0,minecraft:lava)
B(-1,1,0,minecraft:lava)
B(-1,2,0,minecraft:lava)
B(-1,3,0,minecraft:lava)
B(-1,4,0,minecraft:lava)
B(-1,5,0,minecraft:lava)
B(-1,6,0,minecraft:lava)
B(-1,7,0,minecraft:lava)
B(-1,8,0,minecraft:lava)
B(-1,9,0,minecraft:lava)
B(-1,10,0,minecraft:lava)
B(-1,11,0,minecraft:lava)
B(-1,12,0,minecraft:lava)
B(-1,13,0,minecraft:lava)
B(-1,14,0,minecraft:lava[level=8])
B(-1,15,0,minecraft:lava[level=8])
B(-1,16,0,minecraft:lava[level=8])
B(-1,17,0,minecraft:lava[level=8])
B(-1,18,0,minecraft:lava[level=8])
B(-1,19,0,minecraft:lava[level=8])
B(-1,20,0,minecraft:lava[level=8])
B(-1,21,0,minecraft:lava[level=8])
B(-1,22,0,minecraft:lava[level=8])
B(-1,23,0,minecraft:lava[level=8])
B(-1,24,0,minecraft:lava[level=8])
B(-1,25,0,minecraft:lava[level=8])
B(-1,26,0,minecraft:lava[level=2])
B(-1,0,1,minecraft:lava)
B(-1,1,1,minecraft:lava)
B(-1,2,1,minecraft:lava)
B(-1,3,1,minecraft:lava)
B(-1,4,1,minecraft:lava)
B(-1,5,1,minecraft:lava)
B(-1,6,1,minecraft:lava)
B(-1,7,1,minecraft:lava)
B(-1,8,1,minecraft:lava)
B(-1,9,1,minecraft:lava)
B(-1,10,1,minecraft:lava)
B(-1,11,1,minecraft:lava)
B(-1,12,1,minecraft:lava)
B(-1,13,1,minecraft:lava[level=8])
B(-1,14,1,minecraft:lava[level=8])
B(-1,15,1,minecraft:lava[level=8])
B(-1,16,1,minecraft:lava[level=8])
B(-1,17,1,minecraft:lava[level=8])
B(-1,18,1,minecraft:lava[level=8])
B(-1,19,1,minecraft:lava[level=8])
B(-1,20,1,minecraft:lava[level=8])
B(-1,21,1,minecraft:lava[level=8])
B(-1,22,1,minecraft:lava[level=8])
B(-1,23,1,minecraft:lava[level=8])
B(-1,24,1,minecraft:lava[level=8])
B(-1,25,1,minecraft:lava[level=8])
B(-1,26,1,minecraft:lava[level=2])
B(-1,0,2,minecraft:lava)
B(-1,1,2,minecraft:lava)
B(-1,2,2,minecraft:lava)
B(-1,3,2,minecraft:lava)
B(-1,4,2,minecraft:lava)
B(-1,5,2,minecraft:lava)
B(-1,6,2,minecraft:lava)
B(-1,7,2,minecraft:lava)
B(-1,8,2,minecraft:lava)
B(-1,9,2,minecraft:lava)
B(-1,10,2,minecraft:lava)
B(-1,11,2,minecraft:lava)
B(-1,12,2,minecraft:lava)
B(-1,13,2,minecraft:lava[level=8])
B(-1,14,2,minecraft:lava[level=8])
B(-1,15,2,minecraft:lava[level=8])
B(-1,16,2,minecraft:lava[level=8])
B(-1,17,2,minecraft:lava[level=8])
B(-1,18,2,minecraft:lava[level=8])
B(-1,19,2,minecraft:lava[level=8])
B(-1,20,2,minecraft:lava[level=8])
B(-1,21,2,minecraft:lava[level=8])
B(-1,22,2,minecraft:lava[level=8])
B(-1,23,2,minecraft:lava[level=8])
B(-1,24,2,minecraft:lava[level=2])
B(-1,0,3,minecraft:lava)
B(-1,1,3,minecraft:lava)
B(-1,2,3,minecraft:lava)
B(-1,3,3,minecraft:lava)
B(-1,4,3,minecraft:lava)
B(-1,5,3,minecraft:lava)
B(-1,6,3,minecraft:lava)
B(-1,7,3,minecraft:lava)
B(-1,8,3,minecraft:lava)
B(-1,9,3,minecraft:lava)
B(-1,10,3,minecraft:lava)
B(-1,11,3,minecraft:lava)
B(-1,12,3,minecraft:lava)
B(-1,13,3,minecraft:lava[level=8])
B(-1,14,3,minecraft:lava[level=8])
B(-1,15,3,minecraft:lava[level=8])
B(-1,16,3,minecraft:lava[level=8])
B(-1,17,3,minecraft:lava[level=8])
B(-1,18,3,minecraft:lava[level=2])
B(-1,0,4,minecraft:lava)
B(-1,1,4,minecraft:lava)
B(-1,2,4,minecraft:lava)
B(-1,3,4,minecraft:lava)
B(-1,4,4,minecraft:lava)
B(-1,5,4,minecraft:lava)
B(-1,6,4,minecraft:lava)
B(-1,7,4,minecraft:lava)
B(-1,8,4,minecraft:lava)
B(-1,9,4,minecraft:lava)
B(-1,10,4,minecraft:lava)
B(-1,11,4,minecraft:lava)
B(-1,12,4,minecraft:lava)
B(-1,0,5,minecraft:lava)
B(-1,1,5,minecraft:lava)
B(-1,2,5,minecraft:lava)
B(-1,3,5,minecraft:lava)
B(-1,4,5,minecraft:lava)
B(-1,5,5,minecraft:lava)
B(-1,6,5,minecraft:lava)
B(-1,7,5,minecraft:lava)
B(-1,8,5,minecraft:lava)
B(-1,9,5,minecraft:lava)
B(-1,10,5,minecraft:lava)
B(-1,11,5,minecraft:lava)
B(-1,12,5,minecraft:lava)
B(-1,0,6,minecraft:lava)
B(-1,1,6,minecraft:lava)
B(-1,2,6,minecraft:lava)
B(-1,3,6,minecraft:lava)
B(-1,4,6,minecraft:lava)
B(-1,5,6,minecraft:lava)
B(-1,6,6,minecraft:lava)
B(-1,7,6,minecraft:lava)
B(-1,8,6,minecraft:lava)
B(-1,9,6,minecraft:lava)
B(-1,10,6,minecraft:lava)
B(-1,11,6,minecraft:lava)
B(-1,12,6,minecraft:lava)
B(-1,13,6,minecraft:lava[level=2])
B(-1,0,7,minecraft:lava)
B(-1,1,7,minecraft:lava)
B(-1,2,7,minecraft:lava)
B(-1,3,7,minecraft:lava)
B(-1,4,7,minecraft:lava)
B(-1,5,7,minecraft:lava)
B(-1,6,7,minecraft:lava)
B(-1,7,7,minecraft:lava)
B(-1,8,7,minecraft:lava)
B(-1,9,7,minecraft:lava)
B(-1,10,7,minecraft:lava)
B(-1,11,7,minecraft:lava)
B(-1,12,7,minecraft:lava)
B(-1,13,7,minecraft:lava)
B(-1,14,7,minecraft:lava[level=2])
B(-1,0,8,minecraft:lava)
B(-1,1,8,minecraft:lava)
B(-1,2,8,minecraft:lava)
B(-1,3,8,minecraft:lava)
B(-1,4,8,minecraft:lava)
B(-1,5,8,minecraft:lava)
B(-1,6,8,minecraft:lava)
B(-1,7,8,minecraft:lava)
B(-1,8,8,minecraft:lava)
B(-1,9,8,minecraft:lava)
B(-1,10,8,minecraft:lava)
B(-1,11,8,minecraft:lava[level=8])
B(-1,12,8,minecraft:lava[level=8])
B(-1,13,8,minecraft:lava[level=2])
B(0,0,-7,minecraft:lava)
B(0,1,-7,minecraft:lava)
B(0,2,-7,minecraft:lava)
B(0,3,-7,minecraft:lava)
B(0,4,-7,minecraft:lava)
B(0,5,-7,minecraft:lava)
B(0,6,-7,minecraft:lava)
B(0,7,-7,minecraft:lava)
B(0,8,-7,minecraft:lava)
B(0,9,-7,minecraft:lava)
B(0,10,-7,minecraft:lava)
B(0,11,-7,minecraft:lava)
B(0,12,-7,minecraft:lava)
B(0,13,-7,minecraft:lava)
B(0,14,-7,minecraft:lava)
B(0,15,-7,minecraft:lava[level=2])
B(0,0,-6,minecraft:lava)
B(0,1,-6,minecraft:lava)
B(0,2,-6,minecraft:lava)
B(0,3,-6,minecraft:lava)
B(0,4,-6,minecraft:lava)
B(0,5,-6,minecraft:lava)
B(0,6,-6,minecraft:lava)
B(0,7,-6,minecraft:lava)
B(0,8,-6,minecraft:lava)
B(0,9,-6,minecraft:lava)
B(0,10,-6,minecraft:lava)
B(0,11,-6,minecraft:lava)
B(0,12,-6,minecraft:lava)
B(0,13,-6,minecraft:lava)
B(0,14,-6,minecraft:lava)
B(0,15,-6,minecraft:lava[level=8])
B(0,16,-6,minecraft:lava[level=8])
B(0,17,-6,minecraft:lava[level=8])
B(0,18,-6,minecraft:lava[level=8])
B(0,19,-6,minecraft:lava[level=2])
B(0,0,-5,minecraft:lava)
B(0,1,-5,minecraft:lava)
B(0,2,-5,minecraft:lava)
B(0,3,-5,minecraft:lava)
B(0,4,-5,minecraft:lava)
B(0,5,-5,minecraft:lava)
B(0,6,-5,minecraft:lava)
B(0,7,-5,minecraft:lava)
B(0,8,-5,minecraft:lava)
B(0,9,-5,minecraft:lava)
B(0,10,-5,minecraft:lava)
B(0,11,-5,minecraft:lava)
B(0,12,-5,minecraft:lava)
B(0,13,-5,minecraft:lava)
B(0,14,-5,minecraft:lava)
B(0,15,-5,minecraft:lava)
B(0,16,-5,minecraft:lava[level=8])
B(0,17,-5,minecraft:lava[level=8])
B(0,18,-5,minecraft:lava[level=8])
B(0,19,-5,minecraft:lava[level=8])
B(0,20,-5,minecraft:lava[level=2])
B(0,0,-4,minecraft:lava)
B(0,1,-4,minecraft:lava)
B(0,2,-4,minecraft:lava)
B(0,3,-4,minecraft:lava)
B(0,4,-4,minecraft:lava)
B(0,5,-4,minecraft:lava)
B(0,6,-4,minecraft:lava)
B(0,7,-4,minecraft:lava)
B(0,8,-4,minecraft:lava)
B(0,9,-4,minecraft:lava)
B(0,10,-4,minecraft:lava)
B(0,11,-4,minecraft:lava)
B(0,12,-4,minecraft:lava)
B(0,13,-4,minecraft:lava)
B(0,14,-4,minecraft:lava)
B(0,15,-4,minecraft:lava)
B(0,16,-4,minecraft:lava[level=8])
B(0,17,-4,minecraft:lava[level=8])
B(0,18,-4,minecraft:lava[level=8])
B(0,19,-4,minecraft:lava[level=8])
B(0,20,-4,minecraft:lava[level=8])
B(0,21,-4,minecraft:lava[level=2])
B(0,0,-3,minecraft:lava)
B(0,1,-3,minecraft:lava)
B(0,2,-3,minecraft:lava)
B(0,3,-3,minecraft:lava)
B(0,4,-3,minecraft:lava)
B(0,5,-3,minecraft:lava)
B(0,6,-3,minecraft:lava)
B(0,7,-3,minecraft:lava)
B(0,8,-3,minecraft:lava)
B(0,9,-3,minecraft:lava)
B(0,10,-3,minecraft:lava)
B(0,11,-3,minecraft:lava)
B(0,12,-3,minecraft:lava)
B(0,13,-3,minecraft:lava)
B(0,14,-3,minecraft:lava)
B(0,15,-3,minecraft:lava)
B(0,16,-3,minecraft:lava)
B(0,17,-3,minecraft:lava[level=8])
B(0,18,-3,minecraft:lava[level=8])
B(0,19,-3,minecraft:lava[level=8])
B(0,20,-3,minecraft:lava[level=8])
B(0,21,-3,minecraft:lava[level=8])
B(0,22,-3,minecraft:lava[level=8])
B(0,23,-3,minecraft:lava[level=8])
B(0,24,-3,minecraft:lava[level=2])
B(0,0,-2,minecraft:lava)
B(0,1,-2,minecraft:lava)
B(0,2,-2,minecraft:lava)
B(0,3,-2,minecraft:lava)
B(0,4,-2,minecraft:lava)
B(0,5,-2,minecraft:lava)
B(0,6,-2,minecraft:lava)
B(0,7,-2,minecraft:lava)
B(0,8,-2,minecraft:lava)
B(0,9,-2,minecraft:lava)
B(0,10,-2,minecraft:lava)
B(0,11,-2,minecraft:lava)
B(0,12,-2,minecraft:lava)
B(0,13,-2,minecraft:lava)
B(0,14,-2,minecraft:lava)
B(0,15,-2,minecraft:lava)
B(0,16,-2,minecraft:lava)
B(0,17,-2,minecraft:lava)
B(0,18,-2,minecraft:lava)
B(0,19,-2,minecraft:lava)
B(0,20,-2,minecraft:lava[level=8])
B(0,21,-2,minecraft:lava[level=8])
B(0,22,-2,minecraft:lava[level=8])
B(0,23,-2,minecraft:lava[level=8])
B(0,24,-2,minecraft:lava[level=8])
B(0,25,-2,minecraft:lava[level=8])
B(0,26,-2,minecraft:lava[level=8])
B(0,27,-2,minecraft:lava[level=8])
B(0,28,-2,minecraft:lava[level=2])
B(0,0,-1,minecraft:lava)
B(0,1,-1,minecraft:lava)
B(0,2,-1,minecraft:lava)
B(0,3,-1,minecraft:lava)
B(0,4,-1,minecraft:lava)
B(0,5,-1,minecraft:lava)
B(0,6,-1,minecraft:lava)
B(0,7,-1,minecraft:lava)
B(0,8,-1,minecraft:lava)
B(0,9,-1,minecraft:lava)
B(0,10,-1,minecraft:lava)
B(0,11,-1,minecraft:lava)
B(0,12,-1,minecraft:lava)
B(0,13,-1,minecraft:lava)
B(0,14,-1,minecraft:lava)
B(0,15,-1,minecraft:lava)
B(0,16,-1,minecraft:lava)
B(0,17,-1,minecraft:lava)
B(0,18,-1,minecraft:lava)
B(0,19,-1,minecraft:lava)
B(0,20,-1,minecraft:lava)
B(0,21,-1,minecraft:lava)
B(0,22,-1,minecraft:lava)
B(0,23,-1,minecraft:lava)
B(0,24,-1,minecraft:lava)
B(0,25,-1,minecraft:lava[level=8])
B(0,26,-1,minecraft:lava[level=8])
B(0,27,-1,minecraft:lava[level=8])
B(0,28,-1,minecraft:lava[level=8])
B(0,29,-1,minecraft:lava[level=8])
B(0,30,-1,minecraft:lava[level=8])
B(0,31,-1,minecraft:lava[level=8])
B(0,32,-1,minecraft:lava[level=2])
B(0,0,0,minecraft:lava)
B(0,1,0,minecraft:lava)
B(0,2,0,minecraft:lava)
B(0,3,0,minecraft:lava)
B(0,4,0,minecraft:lava)
B(0,5,0,minecraft:lava)
B(0,6,0,minecraft:lava)
B(0,7,0,minecraft:lava)
B(0,8,0,minecraft:lava)
B(0,9,0,minecraft:lava)
B(0,10,0,minecraft:lava)
B(0,11,0,minecraft:lava)
B(0,12,0,minecraft:lava)
B(0,13,0,minecraft:lava)
B(0,14,0,minecraft:lava)
B(0,15,0,minecraft:lava)
B(0,16,0,minecraft:lava)
B(0,17,0,minecraft:lava)
B(0,18,0,minecraft:lava)
B(0,19,0,minecraft:lava)
B(0,20,0,minecraft:lava)
B(0,21,0,minecraft:lava)
B(0,22,0,minecraft:lava)
B(0,23,0,minecraft:lava)
B(0,24,0,minecraft:lava)
B(0,25,0,minecraft:lava)
B(0,26,0,minecraft:lava)
B(0,27,0,minecraft:lava[level=8])
B(0,28,0,minecraft:lava[level=8])
B(0,29,0,minecraft:lava[level=8])
B(0,30,0,minecraft:lava[level=8])
B(0,31,0,minecraft:lava[level=8])
B(0,32,0,minecraft:lava[level=8])
B(0,33,0,minecraft:lava[level=8])
B(0,34,0,minecraft:lava[level=8])
B(0,35,0,minecraft:lava[level=8])
B(0,36,0,minecraft:lava[level=8])
B(0,37,0,minecraft:lava[level=8])
B(0,38,0,minecraft:lava[level=8])
B(0,39,0,minecraft:lava[level=2])
B(0,0,1,minecraft:lava)
B(0,1,1,minecraft:lava)
B(0,2,1,minecraft:lava)
B(0,3,1,minecraft:lava)
B(0,4,1,minecraft:lava)
B(0,5,1,minecraft:lava)
B(0,6,1,minecraft:lava)
B(0,7,1,minecraft:lava)
B(0,8,1,minecraft:lava)
B(0,9,1,minecraft:lava)
B(0,10,1,minecraft:lava)
B(0,11,1,minecraft:lava)
B(0,12,1,minecraft:lava)
B(0,13,1,minecraft:lava)
B(0,14,1,minecraft:lava)
B(0,15,1,minecraft:lava)
B(0,16,1,minecraft:lava)
B(0,17,1,minecraft:lava)
B(0,18,1,minecraft:lava)
B(0,19,1,minecraft:lava)
B(0,20,1,minecraft:lava)
B(0,21,1,minecraft:lava)
B(0,22,1,minecraft:lava)
B(0,23,1,minecraft:lava)
B(0,24,1,minecraft:lava)
B(0,25,1,minecraft:lava)
B(0,26,1,minecraft:lava)
B(0,27,1,minecraft:lava[level=8])
B(0,28,1,minecraft:lava[level=8])
B(0,29,1,minecraft:lava[level=8])
B(0,30,1,minecraft:lava[level=8])
B(0,31,1,minecraft:lava[level=8])
B(0,32,1,minecraft:lava[level=8])
B(0,33,1,minecraft:lava[level=8])
B(0,34,1,minecraft:lava[level=8])
B(0,35,1,minecraft:lava[level=8])
B(0,36,1,minecraft:lava[level=8])
B(0,37,1,minecraft:lava[level=8])
B(0,38,1,minecraft:lava[level=8])
B(0,39,1,minecraft:lava[level=2])
B(0,0,2,minecraft:lava)
B(0,1,2,minecraft:lava)
B(0,2,2,minecraft:lava)
B(0,3,2,minecraft:lava)
B(0,4,2,minecraft:lava)
B(0,5,2,minecraft:lava)
B(0,6,2,minecraft:lava)
B(0,7,2,minecraft:lava)
B(0,8,2,minecraft:lava)
B(0,9,2,minecraft:lava)
B(0,10,2,minecraft:lava)
B(0,11,2,minecraft:lava)
B(0,12,2,minecraft:lava)
B(0,13,2,minecraft:lava)
B(0,14,2,minecraft:lava)
B(0,15,2,minecraft:lava)
B(0,16,2,minecraft:lava)
B(0,17,2,minecraft:lava)
B(0,18,2,minecraft:lava)
B(0,19,2,minecraft:lava)
B(0,20,2,minecraft:lava)
B(0,21,2,minecraft:lava)
B(0,22,2,minecraft:lava)
B(0,23,2,minecraft:lava)
B(0,24,2,minecraft:lava)
B(0,25,2,minecraft:lava[level=8])
B(0,26,2,minecraft:lava[level=8])
B(0,27,2,minecraft:lava[level=8])
B(0,28,2,minecraft:lava[level=8])
B(0,29,2,minecraft:lava[level=8])
B(0,30,2,minecraft:lava[level=8])
B(0,31,2,minecraft:lava[level=8])
B(0,32,2,minecraft:lava[level=8])
B(0,33,2,minecraft:lava[level=8])
B(0,34,2,minecraft:lava[level=8])
B(0,35,2,minecraft:lava[level=8])
B(0,36,2,minecraft:lava[level=8])
B(0,37,2,minecraft:lava[level=8])
B(0,38,2,minecraft:lava[level=2])
B(0,0,3,minecraft:lava)
B(0,1,3,minecraft:lava)
B(0,2,3,minecraft:lava)
B(0,3,3,minecraft:lava)
B(0,4,3,minecraft:lava)
B(0,5,3,minecraft:lava)
B(0,6,3,minecraft:lava)
B(0,7,3,minecraft:lava)
B(0,8,3,minecraft:lava)
B(0,9,3,minecraft:lava)
B(0,10,3,minecraft:lava)
B(0,11,3,minecraft:lava)
B(0,12,3,minecraft:lava)
B(0,13,3,minecraft:lava)
B(0,14,3,minecraft:lava)
B(0,15,3,minecraft:lava)
B(0,16,3,minecraft:lava)
B(0,17,3,minecraft:lava)
B(0,18,3,minecraft:lava)
B(0,19,3,minecraft:lava[level=8])
B(0,20,3,minecraft:lava[level=8])
B(0,21,3,minecraft:lava[level=8])
B(0,22,3,minecraft:lava[level=8])
B(0,23,3,minecraft:lava[level=8])
B(0,24,3,minecraft:lava[level=8])
B(0,25,3,minecraft:lava[level=8])
B(0,26,3,minecraft:lava[level=8])
B(0,27,3,minecraft:lava[level=8])
B(0,28,3,minecraft:lava[level=8])
B(0,29,3,minecraft:lava[level=8])
B(0,30,3,minecraft:lava[level=8])
B(0,31,3,minecraft:lava[level=8])
B(0,32,3,minecraft:lava[level=8])
B(0,33,3,minecraft:lava[level=8])
B(0,34,3,minecraft:lava[level=8])
B(0,35,3,minecraft:lava[level=8])
B(0,36,3,minecraft:lava[level=8])
B(0,37,3,minecraft:lava[level=2])
B(0,0,4,minecraft:lava)
B(0,1,4,minecraft:lava)
B(0,2,4,minecraft:lava)
B(0,3,4,minecraft:lava)
B(0,4,4,minecraft:lava)
B(0,5,4,minecraft:lava)
B(0,6,4,minecraft:lava)
B(0,7,4,minecraft:lava)
B(0,8,4,minecraft:lava)
B(0,9,4,minecraft:lava)
B(0,10,4,minecraft:lava)
B(0,11,4,minecraft:lava)
B(0,12,4,minecraft:lava)
B(0,13,4,minecraft:lava[level=8])
B(0,14,4,minecraft:lava[level=8])
B(0,15,4,minecraft:lava[level=8])
B(0,16,4,minecraft:lava[level=8])
B(0,17,4,minecraft:lava[level=8])
B(0,18,4,minecraft:lava[level=8])
B(0,19,4,minecraft:lava[level=8])
B(0,20,4,minecraft:lava[level=8])
B(0,21,4,minecraft:lava[level=8])
B(0,22,4,minecraft:lava[level=8])
B(0,23,4,minecraft:lava[level=8])
B(0,24,4,minecraft:lava[level=8])
B(0,25,4,minecraft:lava[level=8])
B(0,26,4,minecraft:lava[level=8])
B(0,27,4,minecraft:lava[level=2])
B(0,0,5,minecraft:lava)
B(0,1,5,minecraft:lava)
B(0,2,5,minecraft:lava)
B(0,3,5,minecraft:lava)
B(0,4,5,minecraft:lava)
B(0,5,5,minecraft:lava)
B(0,6,5,minecraft:lava)
B(0,7,5,minecraft:lava)
B(0,8,5,minecraft:lava)
B(0,9,5,minecraft:lava)
B(0,10,5,minecraft:lava)
B(0,11,5,minecraft:lava)
B(0,12,5,minecraft:lava)
B(0,13,5,minecraft:lava[level=2])
B(0,0,6,minecraft:lava)
B(0,1,6,minecraft:lava)
B(0,2,6,minecraft:lava)
B(0,3,6,minecraft:lava)
B(0,4,6,minecraft:lava)
B(0,5,6,minecraft:lava)
B(0,6,6,minecraft:lava)
B(0,7,6,minecraft:lava)
B(0,8,6,minecraft:lava)
B(0,9,6,minecraft:lava)
B(0,10,6,minecraft:lava)
B(0,11,6,minecraft:lava)
B(0,12,6,minecraft:lava)
B(0,13,6,minecraft:lava[level=8])
B(0,14,6,minecraft:lava[level=8])
B(0,15,6,minecraft:lava[level=8])
B(0,16,6,minecraft:lava[level=2])
B(0,0,7,minecraft:lava)
B(0,1,7,minecraft:lava)
B(0,2,7,minecraft:lava)
B(0,3,7,minecraft:lava)
B(0,4,7,minecraft:lava)
B(0,5,7,minecraft:lava)
B(0,6,7,minecraft:lava)
B(0,7,7,minecraft:lava)
B(0,8,7,minecraft:lava)
B(0,9,7,minecraft:lava)
B(0,10,7,minecraft:lava)
B(0,11,7,minecraft:lava)
B(0,12,7,minecraft:lava)
B(0,13,7,minecraft:lava)
B(0,14,7,minecraft:lava)
B(0,15,7,minecraft:lava[level=8])
B(0,16,7,minecraft:lava[level=2])
B(0,0,8,minecraft:lava)
B(0,1,8,minecraft:lava)
B(0,2,8,minecraft:lava)
B(0,3,8,minecraft:lava)
B(0,4,8,minecraft:lava)
B(0,5,8,minecraft:lava)
B(0,6,8,minecraft:lava)
B(0,7,8,minecraft:lava)
B(0,8,8,minecraft:lava)
B(0,9,8,minecraft:lava)
B(0,10,8,minecraft:lava)
B(0,11,8,minecraft:lava)
B(0,12,8,minecraft:lava[level=8])
B(0,13,8,minecraft:lava[level=8])
B(0,14,8,minecraft:lava[level=2])
B(1,0,-7,minecraft:lava)
B(1,1,-7,minecraft:lava)
B(1,2,-7,minecraft:lava)
B(1,3,-7,minecraft:lava)
B(1,4,-7,minecraft:lava)
B(1,5,-7,minecraft:lava)
B(1,6,-7,minecraft:lava)
B(1,7,-7,minecraft:lava)
B(1,8,-7,minecraft:lava)
B(1,9,-7,minecraft:lava)
B(1,10,-7,minecraft:lava)
B(1,11,-7,minecraft:lava)
B(1,12,-7,minecraft:lava)
B(1,13,-7,minecraft:lava)
B(1,14,-7,minecraft:lava)
B(1,15,-7,minecraft:lava)
B(1,16,-7,minecraft:lava[level=8])
B(1,17,-7,minecraft:lava[level=8])
B(1,18,-7,minecraft:lava[level=8])
B(1,19,-7,minecraft:lava[level=2])
B(1,0,-6,minecraft:lava)
B(1,1,-6,minecraft:lava)
B(1,2,-6,minecraft:lava)
B(1,3,-6,minecraft:lava)
B(1,4,-6,minecraft:lava)
B(1,5,-6,minecraft:lava)
B(1,6,-6,minecraft:lava)
B(1,7,-6,minecraft:lava)
B(1,8,-6,minecraft:lava)
B(1,9,-6,minecraft:lava)
B(1,10,-6,minecraft:lava)
B(1,11,-6,minecraft:lava)
B(1,12,-6,minecraft:lava)
B(1,13,-6,minecraft:lava)
B(1,14,-6,minecraft:lava)
B(1,15,-6,minecraft:lava)
B(1,16,-6,minecraft:lava)
B(1,17,-6,minecraft:lava)
B(1,18,-6,minecraft:lava)
B(1,19,-6,minecraft:lava)
B(1,20,-6,minecraft:lava[level=8])
B(1,21,-6,minecraft:lava[level=2])
B(1,0,-5,minecraft:lava)
B(1,1,-5,minecraft:lava)
B(1,2,-5,minecraft:lava)
B(1,3,-5,minecraft:lava)
B(1,4,-5,minecraft:lava)
B(1,5,-5,minecraft:lava)
B(1,6,-5,minecraft:lava)
B(1,7,-5,minecraft:lava)
B(1,8,-5,minecraft:lava)
B(1,9,-5,minecraft:lava)
B(1,10,-5,minecraft:lava)
B(1,11,-5,minecraft:lava)
B(1,12,-5,minecraft:lava)
B(1,13,-5,minecraft:lava)
B(1,14,-5,minecraft:lava)
B(1,15,-5,minecraft:lava)
B(1,16,-5,minecraft:lava)
B(1,17,-5,minecraft:lava)
B(1,18,-5,minecraft:lava)
B(1,19,-5,minecraft:lava)
B(1,20,-5,minecraft:lava)
B(1,21,-5,minecraft:lava[level=8])
B(1,22,-5,minecraft:lava[level=2])
B(1,0,-4,minecraft:lava)
B(1,1,-4,minecraft:lava)
B(1,2,-4,minecraft:lava)
B(1,3,-4,minecraft:lava)
B(1,4,-4,minecraft:lava)
B(1,5,-4,minecraft:lava)
B(1,6,-4,minecraft:lava)
B(1,7,-4,minecraft:lava)
B(1,8,-4,minecraft:lava)
B(1,9,-4,minecraft:lava)
B(1,10,-4,minecraft:lava)
B(1,11,-4,minecraft:lava)
B(1,12,-4,minecraft:lava)
B(1,13,-4,minecraft:lava)
B(1,14,-4,minecraft:lava)
B(1,15,-4,minecraft:lava)
B(1,16,-4,minecraft:lava)
B(1,17,-4,minecraft:lava)
B(1,18,-4,minecraft:lava)
B(1,19,-4,minecraft:lava)
B(1,20,-4,minecraft:lava)
B(1,21,-4,minecraft:lava)
B(1,22,-4,minecraft:lava[level=8])
B(1,23,-4,minecraft:lava[level=8])
B(1,24,-4,minecraft:lava[level=8])
B(1,25,-4,minecraft:lava[level=8])
B(1,26,-4,minecraft:lava[level=8])
B(1,27,-4,minecraft:lava[level=2])
B(1,0,-3,minecraft:lava)
B(1,1,-3,minecraft:lava)
B(1,2,-3,minecraft:lava)
B(1,3,-3,minecraft:lava)
B(1,4,-3,minecraft:lava)
B(1,5,-3,minecraft:lava)
B(1,6,-3,minecraft:lava)
B(1,7,-3,minecraft:lava)
B(1,8,-3,minecraft:lava)
B(1,9,-3,minecraft:lava)
B(1,10,-3,minecraft:lava)
B(1,11,-3,minecraft:lava)
B(1,12,-3,minecraft:lava)
B(1,13,-3,minecraft:lava)
B(1,14,-3,minecraft:lava)
B(1,15,-3,minecraft:lava)
B(1,16,-3,minecraft:lava)
B(1,17,-3,minecraft:lava)
B(1,18,-3,minecraft:lava)
B(1,19,-3,minecraft:lava)
B(1,20,-3,minecraft:lava)
B(1,21,-3,minecraft:lava)
B(1,22,-3,minecraft:lava)
B(1,23,-3,minecraft:lava)
B(1,24,-3,minecraft:lava)
B(1,25,-3,minecraft:lava[level=8])
B(1,26,-3,minecraft:lava[level=8])
B(1,27,-3,minecraft:lava[level=8])
B(1,28,-3,minecraft:lava[level=2])
B(1,0,-2,minecraft:lava)
B(1,1,-2,minecraft:lava)
B(1,2,-2,minecraft:lava)
B(1,3,-2,minecraft:lava)
B(1,4,-2,minecraft:lava)
B(1,5,-2,minecraft:lava)
B(1,6,-2,minecraft:lava)
B(1,7,-2,minecraft:lava)
B(1,8,-2,minecraft:lava)
B(1,9,-2,minecraft:lava)
B(1,10,-2,minecraft:lava)
B(1,11,-2,minecraft:lava)
B(1,12,-2,minecraft:lava)
B(1,13,-2,minecraft:lava)
B(1,14,-2,minecraft:lava)
B(1,15,-2,minecraft:lava)
B(1,16,-2,minecraft:lava)
B(1,17,-2,minecraft:lava)
B(1,18,-2,minecraft:lava)
B(1,19,-2,minecraft:lava)
B(1,20,-2,minecraft:lava)
B(1,21,-2,minecraft:lava)
B(1,22,-2,minecraft:lava)
B(1,23,-2,minecraft:lava)
B(1,24,-2,minecraft:lava)
B(1,25,-2,minecraft:lava)
B(1,26,-2,minecraft:lava)
B(1,27,-2,minecraft:lava)
B(1,28,-2,minecraft:lava)
B(1,29,-2,minecraft:lava[level=8])
B(1,30,-2,minecraft:lava[level=8])
B(1,31,-2,minecraft:lava[level=8])
B(1,32,-2,minecraft:lava[level=8])
B(1,33,-2,minecraft:lava[level=8])
B(1,34,-2,minecraft:lava[level=8])
B(1,35,-2,minecraft:lava[level=2])
B(1,0,-1,minecraft:lava)
B(1,1,-1,minecraft:lava)
B(1,2,-1,minecraft:lava)
B(1,3,-1,minecraft:lava)
B(1,4,-1,minecraft:lava)
B(1,5,-1,minecraft:lava)
B(1,6,-1,minecraft:lava)
B(1,7,-1,minecraft:lava)
B(1,8,-1,minecraft:lava)
B(1,9,-1,minecraft:lava)
B(1,10,-1,minecraft:lava)
B(1,11,-1,minecraft:lava)
B(1,12,-1,minecraft:lava)
B(1,13,-1,minecraft:lava)
B(1,14,-1,minecraft:lava)
B(1,15,-1,minecraft:lava)
B(1,16,-1,minecraft:lava)
B(1,17,-1,minecraft:lava)
B(1,18,-1,minecraft:lava)
B(1,19,-1,minecraft:lava)
B(1,20,-1,minecraft:lava)
B(1,21,-1,minecraft:lava)
B(1,22,-1,minecraft:lava)
B(1,23,-1,minecraft:lava)
B(1,24,-1,minecraft:lava)
B(1,25,-1,minecraft:lava)
B(1,26,-1,minecraft:lava)
B(1,27,-1,minecraft:lava)
B(1,28,-1,minecraft:lava)
B(1,29,-1,minecraft:lava)
B(1,30,-1,minecraft:lava)
B(1,31,-1,minecraft:lava)
B(1,32,-1,minecraft:lava)
B(1,33,-1,minecraft:lava[level=8])
B(1,34,-1,minecraft:lava[level=8])
B(1,35,-1,minecraft:lava[level=8])
B(1,36,-1,minecraft:lava[level=8])
B(1,37,-1,minecraft:lava[level=8])
B(1,38,-1,minecraft:lava[level=8])
B(1,39,-1,minecraft:lava[level=8])
B(1,40,-1,minecraft:lava[level=8])
B(1,41,-1,minecraft:lava[level=8])
B(1,42,-1,minecraft:lava[level=8])
B(1,43,-1,minecraft:lava[level=2])
B(1,0,0,minecraft:lava)
B(1,1,0,minecraft:lava)
B(1,2,0,minecraft:lava)
B(1,3,0,minecraft:lava)
B(1,4,0,minecraft:lava)
B(1,5,0,minecraft:lava)
B(1,6,0,minecraft:lava)
B(1,7,0,minecraft:lava)
B(1,8,0,minecraft:lava)
B(1,9,0,minecraft:lava)
B(1,10,0,minecraft:lava)
B(1,11,0,minecraft:lava)
B(1,12,0,minecraft:lava)
B(1,13,0,minecraft:lava)
B(1,14,0,minecraft:lava)
B(1,15,0,minecraft:lava)
B(1,16,0,minecraft:lava)
B(1,17,0,minecraft:lava)
B(1,18,0,minecraft:lava)
B(1,19,0,minecraft:lava)
B(1,20,0,minecraft:lava)
B(1,21,0,minecraft:lava)
B(1,22,0,minecraft:lava)
B(1,23,0,minecraft:lava)
B(1,24,0,minecraft:lava)
B(1,25,0,minecraft:lava)
B(1,26,0,minecraft:lava)
B(1,27,0,minecraft:lava)
B(1,28,0,minecraft:lava)
B(1,29,0,minecraft:lava)
B(1,30,0,minecraft:lava)
B(1,31,0,minecraft:lava)
B(1,32,0,minecraft:lava)
B(1,33,0,minecraft:lava)
B(1,34,0,minecraft:lava)
B(1,35,0,minecraft:lava)
B(1,36,0,minecraft:lava)
B(1,37,0,minecraft:lava)
B(1,38,0,minecraft:lava)
B(1,39,0,minecraft:lava)
B(1,40,0,minecraft:lava[level=8])
B(1,41,0,minecraft:lava[level=8])
B(1,42,0,minecraft:lava[level=8])
B(1,43,0,minecraft:lava[level=2])
B(1,0,1,minecraft:lava)
B(1,1,1,minecraft:lava)
B(1,2,1,minecraft:lava)
B(1,3,1,minecraft:lava)
B(1,4,1,minecraft:lava)
B(1,5,1,minecraft:lava)
B(1,6,1,minecraft:lava)
B(1,7,1,minecraft:lava)
B(1,8,1,minecraft:lava)
B(1,9,1,minecraft:lava)
B(1,10,1,minecraft:lava)
B(1,11,1,minecraft:lava)
B(1,12,1,minecraft:lava)
B(1,13,1,minecraft:lava)
B(1,14,1,minecraft:lava)
B(1,15,1,minecraft:lava)
B(1,16,1,minecraft:lava)
B(1,17,1,minecraft:lava)
B(1,18,1,minecraft:lava)
B(1,19,1,minecraft:lava)
B(1,20,1,minecraft:lava)
B(1,21,1,minecraft:lava)
B(1,22,1,minecraft:lava)
B(1,23,1,minecraft:lava)
B(1,24,1,minecraft:lava)
B(1,25,1,minecraft:lava)
B(1,26,1,minecraft:lava)
B(1,27,1,minecraft:lava)
B(1,28,1,minecraft:lava)
B(1,29,1,minecraft:lava)
B(1,30,1,minecraft:lava)
B(1,31,1,minecraft:lava)
B(1,32,1,minecraft:lava)
B(1,33,1,minecraft:lava)
B(1,34,1,minecraft:lava)
B(1,35,1,minecraft:lava)
B(1,36,1,minecraft:lava)
B(1,37,1,minecraft:lava)
B(1,38,1,minecraft:lava)
B(1,39,1,minecraft:lava)
B(1,40,1,minecraft:lava[level=8])
B(1,41,1,minecraft:lava[level=2])
B(1,0,2,minecraft:lava)
B(1,1,2,minecraft:lava)
B(1,2,2,minecraft:lava)
B(1,3,2,minecraft:lava)
B(1,4,2,minecraft:lava)
B(1,5,2,minecraft:lava)
B(1,6,2,minecraft:lava)
B(1,7,2,minecraft:lava)
B(1,8,2,minecraft:lava)
B(1,9,2,minecraft:lava)
B(1,10,2,minecraft:lava)
B(1,11,2,minecraft:lava)
B(1,12,2,minecraft:lava)
B(1,13,2,minecraft:lava)
B(1,14,2,minecraft:lava)
B(1,15,2,minecraft:lava)
B(1,16,2,minecraft:lava)
B(1,17,2,minecraft:lava)
B(1,18,2,minecraft:lava)
B(1,19,2,minecraft:lava)
B(1,20,2,minecraft:lava)
B(1,21,2,minecraft:lava)
B(1,22,2,minecraft:lava)
B(1,23,2,minecraft:lava)
B(1,24,2,minecraft:lava)
B(1,25,2,minecraft:lava)
B(1,26,2,minecraft:lava)
B(1,27,2,minecraft:lava)
B(1,28,2,minecraft:lava)
B(1,29,2,minecraft:lava)
B(1,30,2,minecraft:lava)
B(1,31,2,minecraft:lava)
B(1,32,2,minecraft:lava)
B(1,33,2,minecraft:lava)
B(1,34,2,minecraft:lava)
B(1,35,2,minecraft:lava)
B(1,36,2,minecraft:lava)
B(1,37,2,minecraft:lava)
B(1,38,2,minecraft:lava)
B(1,39,2,minecraft:lava[level=8])
B(1,40,2,minecraft:lava[level=2])
B(1,0,3,minecraft:lava)
B(1,1,3,minecraft:lava)
B(1,2,3,minecraft:lava)
B(1,3,3,minecraft:lava)
B(1,4,3,minecraft:lava)
B(1,5,3,minecraft:lava)
B(1,6,3,minecraft:lava)
B(1,7,3,minecraft:lava)
B(1,8,3,minecraft:lava)
B(1,9,3,minecraft:lava)
B(1,10,3,minecraft:lava)
B(1,11,3,minecraft:lava)
B(1,12,3,minecraft:lava)
B(1,13,3,minecraft:lava)
B(1,14,3,minecraft:lava)
B(1,15,3,minecraft:lava)
B(1,16,3,minecraft:lava)
B(1,17,3,minecraft:lava)
B(1,18,3,minecraft:lava)
B(1,19,3,minecraft:lava)
B(1,20,3,minecraft:lava)
B(1,21,3,minecraft:lava)
B(1,22,3,minecraft:lava)
B(1,23,3,minecraft:lava)
B(1,24,3,minecraft:lava)
B(1,25,3,minecraft:lava)
B(1,26,3,minecraft:lava)
B(1,27,3,minecraft:lava)
B(1,28,3,minecraft:lava)
B(1,29,3,minecraft:lava)
B(1,30,3,minecraft:lava)
B(1,31,3,minecraft:lava)
B(1,32,3,minecraft:lava)
B(1,33,3,minecraft:lava)
B(1,34,3,minecraft:lava)
B(1,35,3,minecraft:lava)
B(1,36,3,minecraft:lava)
B(1,37,3,minecraft:lava)
B(1,38,3,minecraft:lava[level=8])
B(1,39,3,minecraft:lava[level=2])
B(1,0,4,minecraft:lava)
B(1,1,4,minecraft:lava)
B(1,2,4,minecraft:lava)
B(1,3,4,minecraft:lava)
B(1,4,4,minecraft:lava)
B(1,5,4,minecraft:lava)
B(1,6,4,minecraft:lava)
B(1,7,4,minecraft:lava)
B(1,8,4,minecraft:lava)
B(1,9,4,minecraft:lava)
B(1,10,4,minecraft:lava)
B(1,11,4,minecraft:lava)
B(1,12,4,minecraft:lava)
B(1,13,4,minecraft:lava)
B(1,14,4,minecraft:lava)
B(1,15,4,minecraft:lava)
B(1,16,4,minecraft:lava)
B(1,17,4,minecraft:lava)
B(1,18,4,minecraft:lava)
B(1,19,4,minecraft:lava)
B(1,20,4,minecraft:lava)
B(1,21,4,minecraft:lava)
B(1,22,4,minecraft:lava)
B(1,23,4,minecraft:lava)
B(1,24,4,minecraft:lava)
B(1,25,4,minecraft:lava)
B(1,26,4,minecraft:lava)
B(1,27,4,minecraft:lava)
B(1,28,4,minecraft:lava[level=8])
B(1,29,4,minecraft:lava[level=8])
B(1,30,4,minecraft:lava[level=8])
B(1,31,4,minecraft:lava[level=8])
B(1,32,4,minecraft:lava[level=8])
B(1,33,4,minecraft:lava[level=8])
B(1,34,4,minecraft:lava[level=8])
B(1,35,4,minecraft:lava[level=8])
B(1,36,4,minecraft:lava[level=8])
B(1,37,4,minecraft:lava[level=8])
B(1,38,4,minecraft:lava[level=2])
B(1,0,5,minecraft:lava)
B(1,1,5,minecraft:lava)
B(1,2,5,minecraft:lava)
B(1,3,5,minecraft:lava)
B(1,4,5,minecraft:lava)
B(1,5,5,minecraft:lava)
B(1,6,5,minecraft:lava)
B(1,7,5,minecraft:lava)
B(1,8,5,minecraft:lava)
B(1,9,5,minecraft:lava)
B(1,10,5,minecraft:lava)
B(1,11,5,minecraft:lava)
B(1,12,5,minecraft:lava)
B(1,13,5,minecraft:lava)
B(1,14,5,minecraft:lava[level=8])
B(1,15,5,minecraft:lava[level=8])
B(1,16,5,minecraft:lava[level=8])
B(1,17,5,minecraft:lava[level=8])
B(1,18,5,minecraft:lava[level=8])
B(1,19,5,minecraft:lava[level=8])
B(1,20,5,minecraft:lava[level=8])
B(1,21,5,minecraft:lava[level=8])
B(1,22,5,minecraft:lava[level=8])
B(1,23,5,minecraft:lava[level=8])
B(1,24,5,minecraft:lava[level=8])
B(1,25,5,minecraft:lava[level=8])
B(1,26,5,minecraft:lava[level=8])
B(1,27,5,minecraft:lava[level=8])
B(1,28,5,minecraft:lava[level=8])
B(1,29,5,minecraft:lava[level=8])
B(1,30,5,minecraft:lava[level=8])
B(1,31,5,minecraft:lava[level=8])
B(1,32,5,minecraft:lava[level=8])
B(1,33,5,minecraft:lava[level=8])
B(1,34,5,minecraft:lava[level=8])
B(1,35,5,minecraft:lava[level=8])
B(1,36,5,minecraft:lava[level=2])
B(1,0,6,minecraft:lava)
B(1,1,6,minecraft:lava)
B(1,2,6,minecraft:lava)
B(1,3,6,minecraft:lava)
B(1,4,6,minecraft:lava)
B(1,5,6,minecraft:lava)
B(1,6,6,minecraft:lava)
B(1,7,6,minecraft:lava)
B(1,8,6,minecraft:lava)
B(1,9,6,minecraft:lava)
B(1,10,6,minecraft:lava)
B(1,11,6,minecraft:lava)
B(1,12,6,minecraft:lava)
B(1,13,6,minecraft:lava)
B(1,14,6,minecraft:lava)
B(1,15,6,minecraft:lava)
B(1,16,6,minecraft:lava)
B(1,17,6,minecraft:lava[level=2])
B(1,0,7,minecraft:lava)
B(1,1,7,minecraft:lava)
B(1,2,7,minecraft:lava)
B(1,3,7,minecraft:lava)
B(1,4,7,minecraft:lava)
B(1,5,7,minecraft:lava)
B(1,6,7,minecraft:lava)
B(1,7,7,minecraft:lava)
B(1,8,7,minecraft:lava)
B(1,9,7,minecraft:lava)
B(1,10,7,minecraft:lava)
B(1,11,7,minecraft:lava)
B(1,12,7,minecraft:lava)
B(1,13,7,minecraft:lava)
B(1,14,7,minecraft:lava)
B(1,15,7,minecraft:lava)
B(1,16,7,minecraft:lava)
B(1,17,7,minecraft:lava[level=8])
B(1,18,7,minecraft:lava[level=2])
B(1,0,8,minecraft:lava)
B(1,1,8,minecraft:lava)
B(1,2,8,minecraft:lava)
B(1,3,8,minecraft:lava)
B(1,4,8,minecraft:lava)
B(1,5,8,minecraft:lava)
B(1,6,8,minecraft:lava)
B(1,7,8,minecraft:lava)
B(1,8,8,minecraft:lava)
B(1,9,8,minecraft:lava)
B(1,10,8,minecraft:lava)
B(1,11,8,minecraft:lava)
B(1,12,8,minecraft:lava)
B(1,13,8,minecraft:lava[level=8])
B(1,14,8,minecraft:lava[level=8])
B(1,15,8,minecraft:lava[level=8])
B(1,16,8,minecraft:lava[level=8])
B(1,17,8,minecraft:lava[level=2])
B(2,0,-7,minecraft:lava)
B(2,1,-7,minecraft:lava)
B(2,2,-7,minecraft:lava)
B(2,3,-7,minecraft:lava)
B(2,4,-7,minecraft:lava)
B(2,5,-7,minecraft:lava)
B(2,6,-7,minecraft:lava)
B(2,7,-7,minecraft:lava)
B(2,8,-7,minecraft:lava)
B(2,9,-7,minecraft:lava)
B(2,10,-7,minecraft:lava)
B(2,11,-7,minecraft:lava)
B(2,12,-7,minecraft:lava)
B(2,13,-7,minecraft:lava)
B(2,14,-7,minecraft:lava)
B(2,15,-7,minecraft:lava)
B(2,16,-7,minecraft:lava)
B(2,17,-7,minecraft:lava)
B(2,18,-7,minecraft:lava[level=8])
B(2,19,-7,minecraft:lava[level=8])
B(2,20,-7,minecraft:lava[level=8])
B(2,21,-7,minecraft:lava[level=2])
B(2,0,-6,minecraft:lava)
B(2,1,-6,minecraft:lava)
B(2,2,-6,minecraft:lava)
B(2,3,-6,minecraft:lava)
B(2,4,-6,minecraft:lava)
B(2,5,-6,minecraft:lava)
B(2,6,-6,minecraft:lava)
B(2,7,-6,minecraft:lava)
B(2,8,-6,minecraft:lava)
B(2,9,-6,minecraft:lava)
B(2,10,-6,minecraft:lava)
B(2,11,-6,minecraft:lava)
B(2,12,-6,minecraft:lava)
B(2,13,-6,minecraft:lava)
B(2,14,-6,minecraft:lava)
B(2,15,-6,minecraft:lava)
B(2,16,-6,minecraft:lava)
B(2,17,-6,minecraft:lava)
B(2,18,-6,minecraft:lava)
B(2,19,-6,minecraft:lava)
B(2,20,-6,minecraft:lava)
B(2,21,-6,minecraft:lava)
B(2,22,-6,minecraft:lava[level=8])
B(2,23,-6,minecraft:lava[level=2])
B(2,0,-5,minecraft:lava)
B(2,1,-5,minecraft:lava)
B(2,2,-5,minecraft:lava)
B(2,3,-5,minecraft:lava)
B(2,4,-5,minecraft:lava)
B(2,5,-5,minecraft:lava)
B(2,6,-5,minecraft:lava)
B(2,7,-5,minecraft:lava)
B(2,8,-5,minecraft:lava)
B(2,9,-5,minecraft:lava)
B(2,10,-5,minecraft:lava)
B(2,11,-5,minecraft:lava)
B(2,12,-5,minecraft:lava)
B(2,13,-5,minecraft:lava)
B(2,14,-5,minecraft:lava)
B(2,15,-5,minecraft:lava)
B(2,16,-5,minecraft:lava)
B(2,17,-5,minecraft:lava)
B(2,18,-5,minecraft:lava)
B(2,19,-5,minecraft:lava)
B(2,20,-5,minecraft:lava)
B(2,21,-5,minecraft:lava)
B(2,22,-5,minecraft:lava)
B(2,23,-5,minecraft:lava[level=8])
B(2,24,-5,minecraft:lava[level=8])
B(2,25,-5,minecraft:lava[level=8])
B(2,26,-5,minecraft:lava[level=8])
B(2,27,-5,minecraft:lava[level=2])
B(2,0,-4,minecraft:lava)
B(2,1,-4,minecraft:lava)
B(2,2,-4,minecraft:lava)
B(2,3,-4,minecraft:lava)
B(2,4,-4,minecraft:lava)
B(2,5,-4,minecraft:lava)
B(2,6,-4,minecraft:lava)
B(2,7,-4,minecraft:lava)
B(2,8,-4,minecraft:lava)
B(2,9,-4,minecraft:lava)
B(2,10,-4,minecraft:lava)
B(2,11,-4,minecraft:lava)
B(2,12,-4,minecraft:lava)
B(2,13,-4,minecraft:lava)
B(2,14,-4,minecraft:lava)
B(2,15,-4,minecraft:lava)
B(2,16,-4,minecraft:lava)
B(2,17,-4,minecraft:lava)
B(2,18,-4,minecraft:lava)
B(2,19,-4,minecraft:lava)
B(2,20,-4,minecraft:lava)
B(2,21,-4,minecraft:lava)
B(2,22,-4,minecraft:lava)
B(2,23,-4,minecraft:lava)
B(2,24,-4,minecraft:lava)
B(2,25,-4,minecraft:lava)
B(2,26,-4,minecraft:lava)
B(2,27,-4,minecraft:lava)
B(2,28,-4,minecraft:lava[level=2])
B(2,0,-3,minecraft:lava)
B(2,1,-3,minecraft:lava)
B(2,2,-3,minecraft:lava)
B(2,3,-3,minecraft:lava)
B(2,4,-3,minecraft:lava)
B(2,5,-3,minecraft:lava)
B(2,6,-3,minecraft:lava)
B(2,7,-3,minecraft:lava)
B(2,8,-3,minecraft:lava)
B(2,9,-3,minecraft:lava)
B(2,10,-3,minecraft:lava)
B(2,11,-3,minecraft:lava)
B(2,12,-3,minecraft:lava)
B(2,13,-3,minecraft:lava)
B(2,14,-3,minecraft:lava)
B(2,15,-3,minecraft:lava)
B(2,16,-3,minecraft:lava)
B(2,17,-3,minecraft:lava)
B(2,18,-3,minecraft:lava)
B(2,19,-3,minecraft:lava)
B(2,20,-3,minecraft:lava)
B(2,21,-3,minecraft:lava)
B(2,22,-3,minecraft:lava)
B(2,23,-3,minecraft:lava)
B(2,24,-3,minecraft:lava)
B(2,25,-3,minecraft:lava)
B(2,26,-3,minecraft:lava)
B(2,27,-3,minecraft:lava)
B(2,28,-3,minecraft:lava)
B(2,29,-3,minecraft:lava[level=8])
B(2,30,-3,minecraft:lava[level=8])
B(2,31,-3,minecraft:lava[level=8])
B(2,32,-3,minecraft:lava[level=8])
B(2,33,-3,minecraft:lava[level=8])
B(2,34,-3,minecraft:lava[level=8])
B(2,35,-3,minecraft:lava[level=2])
B(2,0,-2,minecraft:lava)
B(2,1,-2,minecraft:lava)
B(2,2,-2,minecraft:lava)
B(2,3,-2,minecraft:lava)
B(2,4,-2,minecraft:lava)
B(2,5,-2,minecraft:lava)
B(2,6,-2,minecraft:lava)
B(2,7,-2,minecraft:lava)
B(2,8,-2,minecraft:lava)
B(2,9,-2,minecraft:lava)
B(2,10,-2,minecraft:lava)
B(2,11,-2,minecraft:lava)
B(2,12,-2,minecraft:lava)
B(2,13,-2,minecraft:lava)
B(2,14,-2,minecraft:lava)
B(2,15,-2,minecraft:lava)
B(2,16,-2,minecraft:lava)
B(2,17,-2,minecraft:lava)
B(2,18,-2,minecraft:lava)
B(2,19,-2,minecraft:lava)
B(2,20,-2,minecraft:lava)
B(2,21,-2,minecraft:lava)
B(2,22,-2,minecraft:lava)
B(2,23,-2,minecraft:lava)
B(2,24,-2,minecraft:lava)
B(2,25,-2,minecraft:lava)
B(2,26,-2,minecraft:lava)
B(2,27,-2,minecraft:lava)
B(2,28,-2,minecraft:lava)
B(2,29,-2,minecraft:lava)
B(2,30,-2,minecraft:lava)
B(2,31,-2,minecraft:lava)
B(2,32,-2,minecraft:lava)
B(2,33,-2,minecraft:lava)
B(2,34,-2,minecraft:lava)
B(2,35,-2,minecraft:lava)
B(2,36,-2,minecraft:lava[level=8])
B(2,37,-2,minecraft:lava[level=8])
B(2,38,-2,minecraft:lava[level=8])
B(2,39,-2,minecraft:lava[level=8])
B(2,40,-2,minecraft:lava[level=8])
B(2,41,-2,minecraft:lava[level=8])
B(2,42,-2,minecraft:lava[level=8])
B(2,43,-2,minecraft:lava[level=2])
B(2,0,-1,minecraft:lava)
B(2,1,-1,minecraft:lava)
B(2,2,-1,minecraft:lava)
B(2,3,-1,minecraft:lava)
B(2,4,-1,minecraft:lava)
B(2,5,-1,minecraft:lava)
B(2,6,-1,minecraft:lava)
B(2,7,-1,minecraft:lava)
B(2,8,-1,minecraft:lava)
B(2,9,-1,minecraft:lava)
B(2,10,-1,minecraft:lava)
B(2,11,-1,minecraft:lava)
B(2,12,-1,minecraft:lava)
B(2,13,-1,minecraft:lava)
B(2,14,-1,minecraft:lava)
B(2,15,-1,minecraft:lava)
B(2,16,-1,minecraft:lava)
B(2,17,-1,minecraft:lava)
B(2,18,-1,minecraft:lava)
B(2,19,-1,minecraft:lava)
B(2,20,-1,minecraft:lava)
B(2,21,-1,minecraft:lava)
B(2,22,-1,minecraft:lava)
B(2,23,-1,minecraft:lava)
B(2,24,-1,minecraft:lava)
B(2,25,-1,minecraft:lava)
B(2,26,-1,minecraft:lava)
B(2,27,-1,minecraft:lava)
B(2,28,-1,minecraft:lava)
B(2,29,-1,minecraft:lava)
B(2,30,-1,minecraft:lava)
B(2,31,-1,minecraft:lava)
B(2,32,-1,minecraft:lava)
B(2,33,-1,minecraft:lava)
B(2,34,-1,minecraft:lava)
B(2,35,-1,minecraft:lava)
B(2,36,-1,minecraft:lava)
B(2,37,-1,minecraft:lava)
B(2,38,-1,minecraft:lava)
B(2,39,-1,minecraft:lava)
B(2,40,-1,minecraft:lava)
B(2,41,-1,minecraft:lava)
B(2,42,-1,minecraft:lava)
B(2,43,-1,minecraft:lava)
B(2,44,-1,minecraft:lava[level=2])
B(2,0,0,minecraft:lava)
B(2,1,0,minecraft:lava)
B(2,2,0,minecraft:lava)
B(2,3,0,minecraft:lava)
B(2,4,0,minecraft:lava)
B(2,5,0,minecraft:lava)
B(2,6,0,minecraft:lava)
B(2,7,0,minecraft:lava)
B(2,8,0,minecraft:lava)
B(2,9,0,minecraft:lava)
B(2,10,0,minecraft:lava)
B(2,11,0,minecraft:lava)
B(2,12,0,minecraft:lava)
B(2,13,0,minecraft:lava)
B(2,14,0,minecraft:lava)
B(2,15,0,minecraft:lava)
B(2,16,0,minecraft:lava)
B(2,17,0,minecraft:lava)
B(2,18,0,minecraft:lava)
B(2,19,0,minecraft:lava)
B(2,20,0,minecraft:lava)
B(2,21,0,minecraft:lava)
B(2,22,0,minecraft:lava)
B(2,23,0,minecraft:lava)
B(2,24,0,minecraft:lava)
B(2,25,0,minecraft:lava)
B(2,26,0,minecraft:lava)
B(2,27,0,minecraft:lava)
B(2,28,0,minecraft:lava)
B(2,29,0,minecraft:lava)
B(2,30,0,minecraft:lava)
B(2,31,0,minecraft:lava)
B(2,32,0,minecraft:lava)
B(2,33,0,minecraft:lava)
B(2,34,0,minecraft:lava)
B(2,35,0,minecraft:lava)
B(2,36,0,minecraft:lava)
B(2,37,0,minecraft:lava)
B(2,38,0,minecraft:lava)
B(2,39,0,minecraft:lava)
B(2,40,0,minecraft:lava)
B(2,41,0,minecraft:lava)
B(2,42,0,minecraft:lava)
B(2,43,0,minecraft:lava)
B(2,44,0,minecraft:lava[level=2])
B(2,0,1,minecraft:lava)
B(2,1,1,minecraft:lava)
B(2,2,1,minecraft:lava)
B(2,3,1,minecraft:lava)
B(2,4,1,minecraft:lava)
B(2,5,1,minecraft:lava)
B(2,6,1,minecraft:lava)
B(2,7,1,minecraft:lava)
B(2,8,1,minecraft:lava)
B(2,9,1,minecraft:lava)
B(2,10,1,minecraft:lava)
B(2,11,1,minecraft:lava)
B(2,12,1,minecraft:lava)
B(2,13,1,minecraft:lava)
B(2,14,1,minecraft:lava)
B(2,15,1,minecraft:lava)
B(2,16,1,minecraft:lava)
B(2,17,1,minecraft:lava)
B(2,18,1,minecraft:lava)
B(2,19,1,minecraft:lava)
B(2,20,1,minecraft:lava)
B(2,21,1,minecraft:lava)
B(2,22,1,minecraft:lava)
B(2,23,1,minecraft:lava)
B(2,24,1,minecraft:lava)
B(2,25,1,minecraft:lava)
B(2,26,1,minecraft:lava)
B(2,27,1,minecraft:lava)
B(2,28,1,minecraft:lava)
B(2,29,1,minecraft:lava)
B(2,30,1,minecraft:lava)
B(2,31,1,minecraft:lava)
B(2,32,1,minecraft:lava)
B(2,33,1,minecraft:lava)
B(2,34,1,minecraft:lava)
B(2,35,1,minecraft:lava)
B(2,36,1,minecraft:lava)
B(2,37,1,minecraft:lava)
B(2,38,1,minecraft:lava)
B(2,39,1,minecraft:lava)
B(2,40,1,minecraft:lava)
B(2,41,1,minecraft:lava)
B(2,42,1,minecraft:lava[level=8])
B(2,43,1,minecraft:lava[level=2])
B(2,0,2,minecraft:lava)
B(2,1,2,minecraft:lava)
B(2,2,2,minecraft:lava)
B(2,3,2,minecraft:lava)
B(2,4,2,minecraft:lava)
B(2,5,2,minecraft:lava)
B(2,6,2,minecraft:lava)
B(2,7,2,minecraft:lava)
B(2,8,2,minecraft:lava)
B(2,9,2,minecraft:lava)
B(2,10,2,minecraft:lava)
B(2,11,2,minecraft:lava)
B(2,12,2,minecraft:lava)
B(2,13,2,minecraft:lava)
B(2,14,2,minecraft:lava)
B(2,15,2,minecraft:lava)
B(2,16,2,minecraft:lava)
B(2,17,2,minecraft:lava)
B(2,18,2,minecraft:lava)
B(2,19,2,minecraft:lava)
B(2,20,2,minecraft:lava)
B(2,21,2,minecraft:lava)
B(2,22,2,minecraft:lava)
B(2,23,2,minecraft:lava)
B(2,24,2,minecraft:lava)
B(2,25,2,minecraft:lava)
B(2,26,2,minecraft:lava)
B(2,27,2,minecraft:lava)
B(2,28,2,minecraft:lava)
B(2,29,2,minecraft:lava)
B(2,30,2,minecraft:lava)
B(2,31,2,minecraft:lava)
B(2,32,2,minecraft:lava)
B(2,33,2,minecraft:lava)
B(2,34,2,minecraft:lava)
B(2,35,2,minecraft:lava)
B(2,36,2,minecraft:lava)
B(2,37,2,minecraft:lava)
B(2,38,2,minecraft:lava)
B(2,39,2,minecraft:lava)
B(2,40,2,minecraft:lava)
B(2,41,2,minecraft:lava[level=8])
B(2,42,2,minecraft:lava[level=2])
B(2,0,3,minecraft:lava)
B(2,1,3,minecraft:lava)
B(2,2,3,minecraft:lava)
B(2,3,3,minecraft:lava)
B(2,4,3,minecraft:lava)
B(2,5,3,minecraft:lava)
B(2,6,3,minecraft:lava)
B(2,7,3,minecraft:lava)
B(2,8,3,minecraft:lava)
B(2,9,3,minecraft:lava)
B(2,10,3,minecraft:lava)
B(2,11,3,minecraft:lava)
B(2,12,3,minecraft:lava)
B(2,13,3,minecraft:lava)
B(2,14,3,minecraft:lava)
B(2,15,3,minecraft:lava)
B(2,16,3,minecraft:lava)
B(2,17,3,minecraft:lava)
B(2,18,3,minecraft:lava)
B(2,19,3,minecraft:lava)
B(2,20,3,minecraft:lava)
B(2,21,3,minecraft:lava)
B(2,22,3,minecraft:lava)
B(2,23,3,minecraft:lava)
B(2,24,3,minecraft:lava)
B(2,25,3,minecraft:lava)
B(2,26,3,minecraft:lava)
B(2,27,3,minecraft:lava)
B(2,28,3,minecraft:lava)
B(2,29,3,minecraft:lava)
B(2,30,3,minecraft:lava)
B(2,31,3,minecraft:lava)
B(2,32,3,minecraft:lava)
B(2,33,3,minecraft:lava)
B(2,34,3,minecraft:lava)
B(2,35,3,minecraft:lava)
B(2,36,3,minecraft:lava)
B(2,37,3,minecraft:lava)
B(2,38,3,minecraft:lava)
B(2,39,3,minecraft:lava)
B(2,40,3,minecraft:lava[level=8])
B(2,41,3,minecraft:lava[level=2])
B(2,0,4,minecraft:lava)
B(2,1,4,minecraft:lava)
B(2,2,4,minecraft:lava)
B(2,3,4,minecraft:lava)
B(2,4,4,minecraft:lava)
B(2,5,4,minecraft:lava)
B(2,6,4,minecraft:lava)
B(2,7,4,minecraft:lava)
B(2,8,4,minecraft:lava)
B(2,9,4,minecraft:lava)
B(2,10,4,minecraft:lava)
B(2,11,4,minecraft:lava)
B(2,12,4,minecraft:lava)
B(2,13,4,minecraft:lava)
B(2,14,4,minecraft:lava)
B(2,15,4,minecraft:lava)
B(2,16,4,minecraft:lava)
B(2,17,4,minecraft:lava)
B(2,18,4,minecraft:lava)
B(2,19,4,minecraft:lava)
B(2,20,4,minecraft:lava)
B(2,21,4,minecraft:lava)
B(2,22,4,minecraft:lava)
B(2,23,4,minecraft:lava)
B(2,24,4,minecraft:lava)
B(2,25,4,minecraft:lava)
B(2,26,4,minecraft:lava)
B(2,27,4,minecraft:lava)
B(2,28,4,minecraft:lava)
B(2,29,4,minecraft:lava)
B(2,30,4,minecraft:lava)
B(2,31,4,minecraft:lava)
B(2,32,4,minecraft:lava)
B(2,33,4,minecraft:lava)
B(2,34,4,minecraft:lava)
B(2,35,4,minecraft:lava)
B(2,36,4,minecraft:lava)
B(2,37,4,minecraft:lava)
B(2,38,4,minecraft:lava)
B(2,39,4,minecraft:lava[level=2])
B(2,0,5,minecraft:lava)
B(2,1,5,minecraft:lava)
B(2,2,5,minecraft:lava)
B(2,3,5,minecraft:lava)
B(2,4,5,minecraft:lava)
B(2,5,5,minecraft:lava)
B(2,6,5,minecraft:lava)
B(2,7,5,minecraft:lava)
B(2,8,5,minecraft:lava)
B(2,9,5,minecraft:lava)
B(2,10,5,minecraft:lava)
B(2,11,5,minecraft:lava)
B(2,12,5,minecraft:lava)
B(2,13,5,minecraft:lava)
B(2,14,5,minecraft:lava)
B(2,15,5,minecraft:lava)
B(2,16,5,minecraft:lava)
B(2,17,5,minecraft:lava)
B(2,18,5,minecraft:lava)
B(2,19,5,minecraft:lava)
B(2,20,5,minecraft:lava)
B(2,21,5,minecraft:lava)
B(2,22,5,minecraft:lava)
B(2,23,5,minecraft:lava)
B(2,24,5,minecraft:lava)
B(2,25,5,minecraft:lava)
B(2,26,5,minecraft:lava)
B(2,27,5,minecraft:lava)
B(2,28,5,minecraft:lava)
B(2,29,5,minecraft:lava)
B(2,30,5,minecraft:lava)
B(2,31,5,minecraft:lava)
B(2,32,5,minecraft:lava)
B(2,33,5,minecraft:lava)
B(2,34,5,minecraft:lava)
B(2,35,5,minecraft:lava)
B(2,36,5,minecraft:lava)
B(2,37,5,minecraft:lava[level=8])
B(2,38,5,minecraft:lava[level=2])
B(2,0,6,minecraft:lava)
B(2,1,6,minecraft:lava)
B(2,2,6,minecraft:lava)
B(2,3,6,minecraft:lava)
B(2,4,6,minecraft:lava)
B(2,5,6,minecraft:lava)
B(2,6,6,minecraft:lava)
B(2,7,6,minecraft:lava)
B(2,8,6,minecraft:lava)
B(2,9,6,minecraft:lava)
B(2,10,6,minecraft:lava)
B(2,11,6,minecraft:lava)
B(2,12,6,minecraft:lava)
B(2,13,6,minecraft:lava)
B(2,14,6,minecraft:lava)
B(2,15,6,minecraft:lava)
B(2,16,6,minecraft:lava)
B(2,17,6,minecraft:lava)
B(2,18,6,minecraft:lava[level=8])
B(2,19,6,minecraft:lava[level=8])
B(2,20,6,minecraft:lava[level=8])
B(2,21,6,minecraft:lava[level=8])
B(2,22,6,minecraft:lava[level=8])
B(2,23,6,minecraft:lava[level=8])
B(2,24,6,minecraft:lava[level=8])
B(2,25,6,minecraft:lava[level=8])
B(2,26,6,minecraft:lava[level=8])
B(2,27,6,minecraft:lava[level=8])
B(2,28,6,minecraft:lava[level=8])
B(2,29,6,minecraft:lava[level=8])
B(2,30,6,minecraft:lava[level=8])
B(2,31,6,minecraft:lava[level=8])
B(2,32,6,minecraft:lava[level=8])
B(2,33,6,minecraft:lava[level=8])
B(2,34,6,minecraft:lava[level=8])
B(2,35,6,minecraft:lava[level=8])
B(2,36,6,minecraft:lava[level=2])
B(2,0,7,minecraft:lava)
B(2,1,7,minecraft:lava)
B(2,2,7,minecraft:lava)
B(2,3,7,minecraft:lava)
B(2,4,7,minecraft:lava)
B(2,5,7,minecraft:lava)
B(2,6,7,minecraft:lava)
B(2,7,7,minecraft:lava)
B(2,8,7,minecraft:lava)
B(2,9,7,minecraft:lava)
B(2,10,7,minecraft:lava)
B(2,11,7,minecraft:lava)
B(2,12,7,minecraft:lava)
B(2,13,7,minecraft:lava)
B(2,14,7,minecraft:lava)
B(2,15,7,minecraft:lava)
B(2,16,7,minecraft:lava)
B(2,17,7,minecraft:lava)
B(2,18,7,minecraft:lava)
B(2,19,7,minecraft:lava[level=2])
B(2,0,8,minecraft:lava)
B(2,1,8,minecraft:lava)
B(2,2,8,minecraft:lava)
B(2,3,8,minecraft:lava)
B(2,4,8,minecraft:lava)
B(2,5,8,minecraft:lava)
B(2,6,8,minecraft:lava)
B(2,7,8,minecraft:lava)
B(2,8,8,minecraft:lava)
B(2,9,8,minecraft:lava)
B(2,10,8,minecraft:lava)
B(2,11,8,minecraft:lava)
B(2,12,8,minecraft:lava)
B(2,13,8,minecraft:lava)
B(2,14,8,minecraft:lava)
B(2,15,8,minecraft:lava)
B(2,16,8,minecraft:lava)
B(2,17,8,minecraft:lava)
B(2,18,8,minecraft:lava[level=8])
B(2,19,8,minecraft:lava[level=2])
B(3,0,-7,minecraft:lava)
B(3,1,-7,minecraft:lava)
B(3,2,-7,minecraft:lava)
B(3,3,-7,minecraft:lava)
B(3,4,-7,minecraft:lava)
B(3,5,-7,minecraft:lava)
B(3,6,-7,minecraft:lava)
B(3,7,-7,minecraft:lava)
B(3,8,-7,minecraft:lava)
B(3,9,-7,minecraft:lava)
B(3,10,-7,minecraft:lava)
B(3,11,-7,minecraft:lava)
B(3,12,-7,minecraft:lava)
B(3,13,-7,minecraft:lava)
B(3,14,-7,minecraft:lava)
B(3,15,-7,minecraft:lava)
B(3,16,-7,minecraft:lava)
B(3,17,-7,minecraft:lava)
B(3,18,-7,minecraft:lava)
B(3,19,-7,minecraft:lava)
B(3,20,-7,minecraft:lava)
B(3,21,-7,minecraft:lava[level=8])
B(3,22,-7,minecraft:lava[level=8])
B(3,23,-7,minecraft:lava[level=2])
B(3,0,-6,minecraft:lava)
B(3,1,-6,minecraft:lava)
B(3,2,-6,minecraft:lava)
B(3,3,-6,minecraft:lava)
B(3,4,-6,minecraft:lava)
B(3,5,-6,minecraft:lava)
B(3,6,-6,minecraft:lava)
B(3,7,-6,minecraft:lava)
B(3,8,-6,minecraft:lava)
B(3,9,-6,minecraft:lava)
B(3,10,-6,minecraft:lava)
B(3,11,-6,minecraft:lava)
B(3,12,-6,minecraft:lava)
B(3,13,-6,minecraft:lava)
B(3,14,-6,minecraft:lava)
B(3,15,-6,minecraft:lava)
B(3,16,-6,minecraft:lava)
B(3,17,-6,minecraft:lava)
B(3,18,-6,minecraft:lava)
B(3,19,-6,minecraft:lava)
B(3,20,-6,minecraft:lava)
B(3,21,-6,minecraft:lava)
B(3,22,-6,minecraft:lava)
B(3,23,-6,minecraft:lava)
B(3,24,-6,minecraft:lava[level=8])
B(3,25,-6,minecraft:lava[level=8])
B(3,26,-6,minecraft:lava[level=8])
B(3,27,-6,minecraft:lava[level=2])
B(3,0,-5,minecraft:lava)
B(3,1,-5,minecraft:lava)
B(3,2,-5,minecraft:lava)
B(3,3,-5,minecraft:lava)
B(3,4,-5,minecraft:lava)
B(3,5,-5,minecraft:lava)
B(3,6,-5,minecraft:lava)
B(3,7,-5,minecraft:lava)
B(3,8,-5,minecraft:lava)
B(3,9,-5,minecraft:lava)
B(3,10,-5,minecraft:lava)
B(3,11,-5,minecraft:lava)
B(3,12,-5,minecraft:lava)
B(3,13,-5,minecraft:lava)
B(3,14,-5,minecraft:lava)
B(3,15,-5,minecraft:lava)
B(3,16,-5,minecraft:lava)
B(3,17,-5,minecraft:lava)
B(3,18,-5,minecraft:lava)
B(3,19,-5,minecraft:lava)
B(3,20,-5,minecraft:lava)
B(3,21,-5,minecraft:lava)
B(3,22,-5,minecraft:lava)
B(3,23,-5,minecraft:lava)
B(3,24,-5,minecraft:lava)
B(3,25,-5,minecraft:lava)
B(3,26,-5,minecraft:lava)
B(3,27,-5,minecraft:lava)
B(3,28,-5,minecraft:lava[level=8])
B(3,29,-5,minecraft:lava[level=2])
B(3,0,-4,minecraft:lava)
B(3,1,-4,minecraft:lava)
B(3,2,-4,minecraft:lava)
B(3,3,-4,minecraft:lava)
B(3,4,-4,minecraft:lava)
B(3,5,-4,minecraft:lava)
B(3,6,-4,minecraft:lava)
B(3,7,-4,minecraft:lava)
B(3,8,-4,minecraft:lava)
B(3,9,-4,minecraft:lava)
B(3,10,-4,minecraft:lava)
B(3,11,-4,minecraft:lava)
B(3,12,-4,minecraft:lava)
B(3,13,-4,minecraft:lava)
B(3,14,-4,minecraft:lava)
B(3,15,-4,minecraft:lava)
B(3,16,-4,minecraft:lava)
B(3,17,-4,minecraft:lava)
B(3,18,-4,minecraft:lava)
B(3,19,-4,minecraft:lava)
B(3,20,-4,minecraft:lava)
B(3,21,-4,minecraft:lava)
B(3,22,-4,minecraft:lava)
B(3,23,-4,minecraft:lava)
B(3,24,-4,minecraft:lava)
B(3,25,-4,minecraft:lava)
B(3,26,-4,minecraft:lava)
B(3,27,-4,minecraft:lava)
B(3,28,-4,minecraft:lava)
B(3,29,-4,minecraft:lava[level=8])
B(3,30,-4,minecraft:lava[level=8])
B(3,31,-4,minecraft:lava[level=8])
B(3,32,-4,minecraft:lava[level=8])
B(3,33,-4,minecraft:lava[level=8])
B(3,34,-4,minecraft:lava[level=8])
B(3,35,-4,minecraft:lava[level=2])
B(3,0,-3,minecraft:lava)
B(3,1,-3,minecraft:lava)
B(3,2,-3,minecraft:lava)
B(3,3,-3,minecraft:lava)
B(3,4,-3,minecraft:lava)
B(3,5,-3,minecraft:lava)
B(3,6,-3,minecraft:lava)
B(3,7,-3,minecraft:lava)
B(3,8,-3,minecraft:lava)
B(3,9,-3,minecraft:lava)
B(3,10,-3,minecraft:lava)
B(3,11,-3,minecraft:lava)
B(3,12,-3,minecraft:lava)
B(3,13,-3,minecraft:lava)
B(3,14,-3,minecraft:lava)
B(3,15,-3,minecraft:lava)
B(3,16,-3,minecraft:lava)
B(3,17,-3,minecraft:lava)
B(3,18,-3,minecraft:lava)
B(3,19,-3,minecraft:lava)
B(3,20,-3,minecraft:lava)
B(3,21,-3,minecraft:lava)
B(3,22,-3,minecraft:lava)
B(3,23,-3,minecraft:lava)
B(3,24,-3,minecraft:lava)
B(3,25,-3,minecraft:lava)
B(3,26,-3,minecraft:lava)
B(3,27,-3,minecraft:lava)
B(3,28,-3,minecraft:lava)
B(3,29,-3,minecraft:lava)
B(3,30,-3,minecraft:lava)
B(3,31,-3,minecraft:lava)
B(3,32,-3,minecraft:lava)
B(3,33,-3,minecraft:lava)
B(3,34,-3,minecraft:lava)
B(3,35,-3,minecraft:lava)
B(3,36,-3,minecraft:lava[level=8])
B(3,37,-3,minecraft:lava[level=8])
B(3,38,-3,minecraft:lava[level=8])
B(3,39,-3,minecraft:lava[level=8])
B(3,40,-3,minecraft:lava[level=8])
B(3,41,-3,minecraft:lava[level=8])
B(3,42,-3,minecraft:lava[level=8])
B(3,43,-3,minecraft:lava[level=2])
B(3,0,-2,minecraft:lava)
B(3,1,-2,minecraft:lava)
B(3,2,-2,minecraft:lava)
B(3,3,-2,minecraft:lava)
B(3,4,-2,minecraft:lava)
B(3,5,-2,minecraft:lava)
B(3,6,-2,minecraft:lava)
B(3,7,-2,minecraft:lava)
B(3,8,-2,minecraft:lava)
B(3,9,-2,minecraft:lava)
B(3,10,-2,minecraft:lava)
B(3,11,-2,minecraft:lava)
B(3,12,-2,minecraft:lava)
B(3,13,-2,minecraft:lava)
B(3,14,-2,minecraft:lava)
B(3,15,-2,minecraft:lava)
B(3,16,-2,minecraft:lava)
B(3,17,-2,minecraft:lava)
B(3,18,-2,minecraft:lava)
B(3,19,-2,minecraft:lava)
B(3,20,-2,minecraft:lava)
B(3,21,-2,minecraft:lava)
B(3,22,-2,minecraft:lava)
B(3,23,-2,minecraft:lava)
B(3,24,-2,minecraft:lava)
B(3,25,-2,minecraft:lava)
B(3,26,-2,minecraft:lava)
B(3,27,-2,minecraft:lava)
B(3,28,-2,minecraft:lava)
B(3,29,-2,minecraft:lava)
B(3,30,-2,minecraft:lava)
B(3,31,-2,minecraft:lava)
B(3,32,-2,minecraft:lava)
B(3,33,-2,minecraft:lava)
B(3,34,-2,minecraft:lava)
B(3,35,-2,minecraft:lava)
B(3,36,-2,minecraft:lava)
B(3,37,-2,minecraft:lava)
B(3,38,-2,minecraft:lava)
B(3,39,-2,minecraft:lava)
B(3,40,-2,minecraft:lava)
B(3,41,-2,minecraft:lava)
B(3,42,-2,minecraft:lava)
B(3,43,-2,minecraft:lava)
B(3,44,-2,minecraft:lava[level=2])
B(3,0,-1,minecraft:lava)
B(3,1,-1,minecraft:lava)
B(3,2,-1,minecraft:lava)
B(3,3,-1,minecraft:lava)
B(3,4,-1,minecraft:lava)
B(3,5,-1,minecraft:lava)
B(3,6,-1,minecraft:lava)
B(3,7,-1,minecraft:lava)
B(3,8,-1,minecraft:lava)
B(3,9,-1,minecraft:lava)
B(3,10,-1,minecraft:lava)
B(3,11,-1,minecraft:lava)
B(3,12,-1,minecraft:lava)
B(3,13,-1,minecraft:lava)
B(3,14,-1,minecraft:lava)
B(3,15,-1,minecraft:lava)
B(3,16,-1,minecraft:lava)
B(3,17,-1,minecraft:lava)
B(3,18,-1,minecraft:lava)
B(3,19,-1,minecraft:lava)
B(3,20,-1,minecraft:lava)
B(3,21,-1,minecraft:lava)
B(3,22,-1,minecraft:lava)
B(3,23,-1,minecraft:lava)
B(3,24,-1,minecraft:lava)
B(3,25,-1,minecraft:lava)
B(3,26,-1,minecraft:lava)
B(3,27,-1,minecraft:lava)
B(3,28,-1,minecraft:lava)
B(3,29,-1,minecraft:lava)
B(3,30,-1,minecraft:lava)
B(3,31,-1,minecraft:lava)
B(3,32,-1,minecraft:lava)
B(3,33,-1,minecraft:lava)
B(3,34,-1,minecraft:lava)
B(3,35,-1,minecraft:lava)
B(3,36,-1,minecraft:lava)
B(3,37,-1,minecraft:lava)
B(3,38,-1,minecraft:lava)
B(3,39,-1,minecraft:lava)
B(3,40,-1,minecraft:lava)
B(3,41,-1,minecraft:lava)
B(3,42,-1,minecraft:lava)
B(3,43,-1,minecraft:lava)
B(3,44,-1,minecraft:lava)
B(3,0,0,minecraft:lava)
B(3,1,0,minecraft:lava)
B(3,2,0,minecraft:lava)
B(3,3,0,minecraft:lava)
B(3,4,0,minecraft:lava)
B(3,5,0,minecraft:lava)
B(3,6,0,minecraft:lava)
B(3,7,0,minecraft:lava)
B(3,8,0,minecraft:lava)
B(3,9,0,minecraft:lava)
B(3,10,0,minecraft:lava)
B(3,11,0,minecraft:lava)
B(3,12,0,minecraft:lava)
B(3,13,0,minecraft:lava)
B(3,14,0,minecraft:lava)
B(3,15,0,minecraft:lava)
B(3,16,0,minecraft:lava)
B(3,17,0,minecraft:lava)
B(3,18,0,minecraft:lava)
B(3,19,0,minecraft:lava)
B(3,20,0,minecraft:lava)
B(3,21,0,minecraft:lava)
B(3,22,0,minecraft:lava)
B(3,23,0,minecraft:lava)
B(3,24,0,minecraft:lava)
B(3,25,0,minecraft:lava)
B(3,26,0,minecraft:lava)
B(3,27,0,minecraft:lava)
B(3,28,0,minecraft:lava)
B(3,29,0,minecraft:lava)
B(3,30,0,minecraft:lava)
B(3,31,0,minecraft:lava)
B(3,32,0,minecraft:lava)
B(3,33,0,minecraft:lava)
B(3,34,0,minecraft:lava)
B(3,35,0,minecraft:lava)
B(3,36,0,minecraft:lava)
B(3,37,0,minecraft:lava)
B(3,38,0,minecraft:lava)
B(3,39,0,minecraft:lava)
B(3,40,0,minecraft:lava)
B(3,41,0,minecraft:lava)
B(3,42,0,minecraft:lava)
B(3,43,0,minecraft:lava)
B(3,44,0,minecraft:lava)
B(3,0,1,minecraft:lava)
B(3,1,1,minecraft:lava)
B(3,2,1,minecraft:lava)
B(3,3,1,minecraft:lava)
B(3,4,1,minecraft:lava)
B(3,5,1,minecraft:lava)
B(3,6,1,minecraft:lava)
B(3,7,1,minecraft:lava)
B(3,8,1,minecraft:lava)
B(3,9,1,minecraft:lava)
B(3,10,1,minecraft:lava)
B(3,11,1,minecraft:lava)
B(3,12,1,minecraft:lava)
B(3,13,1,minecraft:lava)
B(3,14,1,minecraft:lava)
B(3,15,1,minecraft:lava)
B(3,16,1,minecraft:lava)
B(3,17,1,minecraft:lava)
B(3,18,1,minecraft:lava)
B(3,19,1,minecraft:lava)
B(3,20,1,minecraft:lava)
B(3,21,1,minecraft:lava)
B(3,22,1,minecraft:lava)
B(3,23,1,minecraft:lava)
B(3,24,1,minecraft:lava)
B(3,25,1,minecraft:lava)
B(3,26,1,minecraft:lava)
B(3,27,1,minecraft:lava)
B(3,28,1,minecraft:lava)
B(3,29,1,minecraft:lava)
B(3,30,1,minecraft:lava)
B(3,31,1,minecraft:lava)
B(3,32,1,minecraft:lava)
B(3,33,1,minecraft:lava)
B(3,34,1,minecraft:lava)
B(3,35,1,minecraft:lava)
B(3,36,1,minecraft:lava)
B(3,37,1,minecraft:lava)
B(3,38,1,minecraft:lava)
B(3,39,1,minecraft:lava)
B(3,40,1,minecraft:lava)
B(3,41,1,minecraft:lava)
B(3,42,1,minecraft:lava)
B(3,43,1,minecraft:lava)
B(3,44,1,minecraft:lava[level=2])
B(3,0,2,minecraft:lava)
B(3,1,2,minecraft:lava)
B(3,2,2,minecraft:lava)
B(3,3,2,minecraft:lava)
B(3,4,2,minecraft:lava)
B(3,5,2,minecraft:lava)
B(3,6,2,minecraft:lava)
B(3,7,2,minecraft:lava)
B(3,8,2,minecraft:lava)
B(3,9,2,minecraft:lava)
B(3,10,2,minecraft:lava)
B(3,11,2,minecraft:lava)
B(3,12,2,minecraft:lava)
B(3,13,2,minecraft:lava)
B(3,14,2,minecraft:lava)
B(3,15,2,minecraft:lava)
B(3,16,2,minecraft:lava)
B(3,17,2,minecraft:lava)
B(3,18,2,minecraft:lava)
B(3,19,2,minecraft:lava)
B(3,20,2,minecraft:lava)
B(3,21,2,minecraft:lava)
B(3,22,2,minecraft:lava)
B(3,23,2,minecraft:lava)
B(3,24,2,minecraft:lava)
B(3,25,2,minecraft:lava)
B(3,26,2,minecraft:lava)
B(3,27,2,minecraft:lava)
B(3,28,2,minecraft:lava)
B(3,29,2,minecraft:lava)
B(3,30,2,minecraft:lava)
B(3,31,2,minecraft:lava)
B(3,32,2,minecraft:lava)
B(3,33,2,minecraft:lava)
B(3,34,2,minecraft:lava)
B(3,35,2,minecraft:lava)
B(3,36,2,minecraft:lava)
B(3,37,2,minecraft:lava)
B(3,38,2,minecraft:lava)
B(3,39,2,minecraft:lava)
B(3,40,2,minecraft:lava)
B(3,41,2,minecraft:lava)
B(3,42,2,minecraft:lava)
B(3,43,2,minecraft:lava[level=8])
B(3,44,2,minecraft:lava[level=2])
B(3,0,3,minecraft:lava)
B(3,1,3,minecraft:lava)
B(3,2,3,minecraft:lava)
B(3,3,3,minecraft:lava)
B(3,4,3,minecraft:lava)
B(3,5,3,minecraft:lava)
B(3,6,3,minecraft:lava)
B(3,7,3,minecraft:lava)
B(3,8,3,minecraft:lava)
B(3,9,3,minecraft:lava)
B(3,10,3,minecraft:lava)
B(3,11,3,minecraft:lava)
B(3,12,3,minecraft:lava)
B(3,13,3,minecraft:lava)
B(3,14,3,minecraft:lava)
B(3,15,3,minecraft:lava)
B(3,16,3,minecraft:lava)
B(3,17,3,minecraft:lava)
B(3,18,3,minecraft:lava)
B(3,19,3,minecraft:lava)
B(3,20,3,minecraft:lava)
B(3,21,3,minecraft:lava)
B(3,22,3,minecraft:lava)
B(3,23,3,minecraft:lava)
B(3,24,3,minecraft:lava)
B(3,25,3,minecraft:lava)
B(3,26,3,minecraft:lava)
B(3,27,3,minecraft:lava)
B(3,28,3,minecraft:lava)
B(3,29,3,minecraft:lava)
B(3,30,3,minecraft:lava)
B(3,31,3,minecraft:lava)
B(3,32,3,minecraft:lava)
B(3,33,3,minecraft:lava)
B(3,34,3,minecraft:lava)
B(3,35,3,minecraft:lava)
B(3,36,3,minecraft:lava)
B(3,37,3,minecraft:lava)
B(3,38,3,minecraft:lava)
B(3,39,3,minecraft:lava)
B(3,40,3,minecraft:lava)
B(3,41,3,minecraft:lava)
B(3,42,3,minecraft:lava[level=2])
B(3,0,4,minecraft:lava)
B(3,1,4,minecraft:lava)
B(3,2,4,minecraft:lava)
B(3,3,4,minecraft:lava)
B(3,4,4,minecraft:lava)
B(3,5,4,minecraft:lava)
B(3,6,4,minecraft:lava)
B(3,7,4,minecraft:lava)
B(3,8,4,minecraft:lava)
B(3,9,4,minecraft:lava)
B(3,10,4,minecraft:lava)
B(3,11,4,minecraft:lava)
B(3,12,4,minecraft:lava)
B(3,13,4,minecraft:lava)
B(3,14,4,minecraft:lava)
B(3,15,4,minecraft:lava)
B(3,16,4,minecraft:lava)
B(3,17,4,minecraft:lava)
B(3,18,4,minecraft:lava)
B(3,19,4,minecraft:lava)
B(3,20,4,minecraft:lava)
B(3,21,4,minecraft:lava)
B(3,22,4,minecraft:lava)
B(3,23,4,minecraft:lava)
B(3,24,4,minecraft:lava)
B(3,25,4,minecraft:lava)
B(3,26,4,minecraft:lava)
B(3,27,4,minecraft:lava)
B(3,28,4,minecraft:lava)
B(3,29,4,minecraft:lava)
B(3,30,4,minecraft:lava)
B(3,31,4,minecraft:lava)
B(3,32,4,minecraft:lava)
B(3,33,4,minecraft:lava)
B(3,34,4,minecraft:lava)
B(3,35,4,minecraft:lava)
B(3,36,4,minecraft:lava)
B(3,37,4,minecraft:lava)
B(3,38,4,minecraft:lava)
B(3,39,4,minecraft:lava)
B(3,40,4,minecraft:lava[level=8])
B(3,41,4,minecraft:lava[level=2])
B(3,0,5,minecraft:lava)
B(3,1,5,minecraft:lava)
B(3,2,5,minecraft:lava)
B(3,3,5,minecraft:lava)
B(3,4,5,minecraft:lava)
B(3,5,5,minecraft:lava)
B(3,6,5,minecraft:lava)
B(3,7,5,minecraft:lava)
B(3,8,5,minecraft:lava)
B(3,9,5,minecraft:lava)
B(3,10,5,minecraft:lava)
B(3,11,5,minecraft:lava)
B(3,12,5,minecraft:lava)
B(3,13,5,minecraft:lava)
B(3,14,5,minecraft:lava)
B(3,15,5,minecraft:lava)
B(3,16,5,minecraft:lava)
B(3,17,5,minecraft:lava)
B(3,18,5,minecraft:lava)
B(3,19,5,minecraft:lava)
B(3,20,5,minecraft:lava)
B(3,21,5,minecraft:lava)
B(3,22,5,minecraft:lava)
B(3,23,5,minecraft:lava)
B(3,24,5,minecraft:lava)
B(3,25,5,minecraft:lava)
B(3,26,5,minecraft:lava)
B(3,27,5,minecraft:lava)
B(3,28,5,minecraft:lava)
B(3,29,5,minecraft:lava)
B(3,30,5,minecraft:lava)
B(3,31,5,minecraft:lava)
B(3,32,5,minecraft:lava)
B(3,33,5,minecraft:lava)
B(3,34,5,minecraft:lava)
B(3,35,5,minecraft:lava)
B(3,36,5,minecraft:lava)
B(3,37,5,minecraft:lava)
B(3,38,5,minecraft:lava[level=8])
B(3,39,5,minecraft:lava[level=2])
B(3,0,6,minecraft:lava)
B(3,1,6,minecraft:lava)
B(3,2,6,minecraft:lava)
B(3,3,6,minecraft:lava)
B(3,4,6,minecraft:lava)
B(3,5,6,minecraft:lava)
B(3,6,6,minecraft:lava)
B(3,7,6,minecraft:lava)
B(3,8,6,minecraft:lava)
B(3,9,6,minecraft:lava)
B(3,10,6,minecraft:lava)
B(3,11,6,minecraft:lava)
B(3,12,6,minecraft:lava)
B(3,13,6,minecraft:lava)
B(3,14,6,minecraft:lava)
B(3,15,6,minecraft:lava)
B(3,16,6,minecraft:lava)
B(3,17,6,minecraft:lava)
B(3,18,6,minecraft:lava)
B(3,19,6,minecraft:lava)
B(3,20,6,minecraft:lava)
B(3,21,6,minecraft:lava)
B(3,22,6,minecraft:lava)
B(3,23,6,minecraft:lava)
B(3,24,6,minecraft:lava)
B(3,25,6,minecraft:lava)
B(3,26,6,minecraft:lava)
B(3,27,6,minecraft:lava)
B(3,28,6,minecraft:lava)
B(3,29,6,minecraft:lava[level=8])
B(3,30,6,minecraft:lava[level=8])
B(3,31,6,minecraft:lava[level=8])
B(3,32,6,minecraft:lava[level=8])
B(3,33,6,minecraft:lava[level=8])
B(3,34,6,minecraft:lava[level=8])
B(3,35,6,minecraft:lava[level=8])
B(3,36,6,minecraft:lava[level=8])
B(3,37,6,minecraft:lava[level=2])
B(3,0,7,minecraft:lava)
B(3,1,7,minecraft:lava)
B(3,2,7,minecraft:lava)
B(3,3,7,minecraft:lava)
B(3,4,7,minecraft:lava)
B(3,5,7,minecraft:lava)
B(3,6,7,minecraft:lava)
B(3,7,7,minecraft:lava)
B(3,8,7,minecraft:lava)
B(3,9,7,minecraft:lava)
B(3,10,7,minecraft:lava)
B(3,11,7,minecraft:lava)
B(3,12,7,minecraft:lava)
B(3,13,7,minecraft:lava)
B(3,14,7,minecraft:lava)
B(3,15,7,minecraft:lava)
B(3,16,7,minecraft:lava)
B(3,17,7,minecraft:lava)
B(3,18,7,minecraft:lava)
B(3,19,7,minecraft:lava)
B(3,20,7,minecraft:lava[level=8])
B(3,21,7,minecraft:lava[level=8])
B(3,22,7,minecraft:lava[level=8])
B(3,23,7,minecraft:lava[level=8])
B(3,24,7,minecraft:lava[level=8])
B(3,25,7,minecraft:lava[level=8])
B(3,26,7,minecraft:lava[level=8])
B(3,27,7,minecraft:lava[level=8])
B(3,28,7,minecraft:lava[level=2])
B(3,0,8,minecraft:lava)
B(3,1,8,minecraft:lava)
B(3,2,8,minecraft:lava)
B(3,3,8,minecraft:lava)
B(3,4,8,minecraft:lava)
B(3,5,8,minecraft:lava)
B(3,6,8,minecraft:lava)
B(3,7,8,minecraft:lava)
B(3,8,8,minecraft:lava)
B(3,9,8,minecraft:lava)
B(3,10,8,minecraft:lava)
B(3,11,8,minecraft:lava)
B(3,12,8,minecraft:lava)
B(3,13,8,minecraft:lava)
B(3,14,8,minecraft:lava)
B(3,15,8,minecraft:lava)
B(3,16,8,minecraft:lava)
B(3,17,8,minecraft:lava)
B(3,18,8,minecraft:lava)
B(3,19,8,minecraft:lava)
B(4,0,-7,minecraft:lava)
B(4,1,-7,minecraft:lava)
B(4,2,-7,minecraft:lava)
B(4,3,-7,minecraft:lava)
B(4,4,-7,minecraft:lava)
B(4,5,-7,minecraft:lava)
B(4,6,-7,minecraft:lava)
B(4,7,-7,minecraft:lava)
B(4,8,-7,minecraft:lava)
B(4,9,-7,minecraft:lava)
B(4,10,-7,minecraft:lava)
B(4,11,-7,minecraft:lava)
B(4,12,-7,minecraft:lava)
B(4,13,-7,minecraft:lava)
B(4,14,-7,minecraft:lava)
B(4,15,-7,minecraft:lava)
B(4,16,-7,minecraft:lava)
B(4,17,-7,minecraft:lava)
B(4,18,-7,minecraft:lava)
B(4,19,-7,minecraft:lava)
B(4,20,-7,minecraft:lava)
B(4,21,-7,minecraft:lava)
B(4,22,-7,minecraft:lava)
B(4,23,-7,minecraft:lava)
B(4,24,-7,minecraft:lava[level=8])
B(4,25,-7,minecraft:lava[level=8])
B(4,26,-7,minecraft:lava[level=8])
B(4,27,-7,minecraft:lava[level=2])
B(4,0,-6,minecraft:lava)
B(4,1,-6,minecraft:lava)
B(4,2,-6,minecraft:lava)
B(4,3,-6,minecraft:lava)
B(4,4,-6,minecraft:lava)
B(4,5,-6,minecraft:lava)
B(4,6,-6,minecraft:lava)
B(4,7,-6,minecraft:lava)
B(4,8,-6,minecraft:lava)
B(4,9,-6,minecraft:lava)
B(4,10,-6,minecraft:lava)
B(4,11,-6,minecraft:lava)
B(4,12,-6,minecraft:lava)
B(4,13,-6,minecraft:lava)
B(4,14,-6,minecraft:lava)
B(4,15,-6,minecraft:lava)
B(4,16,-6,minecraft:lava)
B(4,17,-6,minecraft:lava)
B(4,18,-6,minecraft:lava)
B(4,19,-6,minecraft:lava)
B(4,20,-6,minecraft:lava)
B(4,21,-6,minecraft:lava)
B(4,22,-6,minecraft:lava)
B(4,23,-6,minecraft:lava)
B(4,24,-6,minecraft:lava)
B(4,25,-6,minecraft:lava)
B(4,26,-6,minecraft:lava)
B(4,27,-6,minecraft:lava)
B(4,28,-6,minecraft:lava[level=8])
B(4,29,-6,minecraft:lava[level=2])
B(4,0,-5,minecraft:lava)
B(4,1,-5,minecraft:lava)
B(4,2,-5,minecraft:lava)
B(4,3,-5,minecraft:lava)
B(4,4,-5,minecraft:lava)
B(4,5,-5,minecraft:lava)
B(4,6,-5,minecraft:lava)
B(4,7,-5,minecraft:lava)
B(4,8,-5,minecraft:lava)
B(4,9,-5,minecraft:lava)
B(4,10,-5,minecraft:lava)
B(4,11,-5,minecraft:lava)
B(4,12,-5,minecraft:lava)
B(4,13,-5,minecraft:lava)
B(4,14,-5,minecraft:lava)
B(4,15,-5,minecraft:lava)
B(4,16,-5,minecraft:lava)
B(4,17,-5,minecraft:lava)
B(4,18,-5,minecraft:lava)
B(4,19,-5,minecraft:lava)
B(4,20,-5,minecraft:lava)
B(4,21,-5,minecraft:lava)
B(4,22,-5,minecraft:lava)
B(4,23,-5,minecraft:lava)
B(4,24,-5,minecraft:lava)
B(4,25,-5,minecraft:lava)
B(4,26,-5,minecraft:lava)
B(4,27,-5,minecraft:lava)
B(4,28,-5,minecraft:lava)
B(4,29,-5,minecraft:lava)
B(4,30,-5,minecraft:lava[level=8])
B(4,31,-5,minecraft:lava[level=2])
B(4,0,-4,minecraft:lava)
B(4,1,-4,minecraft:lava)
B(4,2,-4,minecraft:lava)
B(4,3,-4,minecraft:lava)
B(4,4,-4,minecraft:lava)
B(4,5,-4,minecraft:lava)
B(4,6,-4,minecraft:lava)
B(4,7,-4,minecraft:lava)
B(4,8,-4,minecraft:lava)
B(4,9,-4,minecraft:lava)
B(4,10,-4,minecraft:lava)
B(4,11,-4,minecraft:lava)
B(4,12,-4,minecraft:lava)
B(4,13,-4,minecraft:lava)
B(4,14,-4,minecraft:lava)
B(4,15,-4,minecraft:lava)
B(4,16,-4,minecraft:lava)
B(4,17,-4,minecraft:lava)
B(4,18,-4,minecraft:lava)
B(4,19,-4,minecraft:lava)
B(4,20,-4,minecraft:lava)
B(4,21,-4,minecraft:lava)
B(4,22,-4,minecraft:lava)
B(4,23,-4,minecraft:lava)
B(4,24,-4,minecraft:lava)
B(4,25,-4,minecraft:lava)
B(4,26,-4,minecraft:lava)
B(4,27,-4,minecraft:lava)
B(4,28,-4,minecraft:lava)
B(4,29,-4,minecraft:lava)
B(4,30,-4,minecraft:lava)
B(4,31,-4,minecraft:lava)
B(4,32,-4,minecraft:lava[level=8])
B(4,33,-4,minecraft:lava[level=8])
B(4,34,-4,minecraft:lava[level=8])
B(4,35,-4,minecraft:lava[level=8])
B(4,36,-4,minecraft:lava[level=8])
B(4,37,-4,minecraft:lava[level=8])
B(4,38,-4,minecraft:lava[level=8])
B(4,39,-4,minecraft:lava[level=2])
B(4,0,-3,minecraft:lava)
B(4,1,-3,minecraft:lava)
B(4,2,-3,minecraft:lava)
B(4,3,-3,minecraft:lava)
B(4,4,-3,minecraft:lava)
B(4,5,-3,minecraft:lava)
B(4,6,-3,minecraft:lava)
B(4,7,-3,minecraft:lava)
B(4,8,-3,minecraft:lava)
B(4,9,-3,minecraft:lava)
B(4,10,-3,minecraft:lava)
B(4,11,-3,minecraft:lava)
B(4,12,-3,minecraft:lava)
B(4,13,-3,minecraft:lava)
B(4,14,-3,minecraft:lava)
B(4,15,-3,minecraft:lava)
B(4,16,-3,minecraft:lava)
B(4,17,-3,minecraft:lava)
B(4,18,-3,minecraft:lava)
B(4,19,-3,minecraft:lava)
B(4,20,-3,minecraft:lava)
B(4,21,-3,minecraft:lava)
B(4,22,-3,minecraft:lava)
B(4,23,-3,minecraft:lava)
B(4,24,-3,minecraft:lava)
B(4,25,-3,minecraft:lava)
B(4,26,-3,minecraft:lava)
B(4,27,-3,minecraft:lava)
B(4,28,-3,minecraft:lava)
B(4,29,-3,minecraft:lava)
B(4,30,-3,minecraft:lava)
B(4,31,-3,minecraft:lava)
B(4,32,-3,minecraft:lava)
B(4,33,-3,minecraft:lava)
B(4,34,-3,minecraft:lava)
B(4,35,-3,minecraft:lava)
B(4,36,-3,minecraft:lava)
B(4,37,-3,minecraft:lava)
B(4,38,-3,minecraft:lava)
B(4,39,-3,minecraft:lava)
B(4,40,-3,minecraft:lava[level=8])
B(4,41,-3,minecraft:lava[level=8])
B(4,42,-3,minecraft:lava[level=8])
B(4,43,-3,minecraft:lava[level=8])
B(4,44,-3,minecraft:lava[level=2])
B(4,0,-2,minecraft:lava)
B(4,1,-2,minecraft:lava)
B(4,2,-2,minecraft:lava)
B(4,3,-2,minecraft:lava)
B(4,4,-2,minecraft:lava)
B(4,5,-2,minecraft:lava)
B(4,6,-2,minecraft:lava)
B(4,7,-2,minecraft:lava)
B(4,8,-2,minecraft:lava)
B(4,9,-2,minecraft:lava)
B(4,10,-2,minecraft:lava)
B(4,11,-2,minecraft:lava)
B(4,12,-2,minecraft:lava)
B(4,13,-2,minecraft:lava)
B(4,14,-2,minecraft:lava)
B(4,15,-2,minecraft:lava)
B(4,16,-2,minecraft:lava)
B(4,17,-2,minecraft:lava)
B(4,18,-2,minecraft:lava)
B(4,19,-2,minecraft:lava)
B(4,20,-2,minecraft:lava)
B(4,21,-2,minecraft:lava)
B(4,22,-2,minecraft:lava)
B(4,23,-2,minecraft:lava)
B(4,24,-2,minecraft:lava)
B(4,25,-2,minecraft:lava)
B(4,26,-2,minecraft:lava)
B(4,27,-2,minecraft:lava)
B(4,28,-2,minecraft:lava)
B(4,29,-2,minecraft:lava)
B(4,30,-2,minecraft:lava)
B(4,31,-2,minecraft:lava)
B(4,32,-2,minecraft:lava)
B(4,33,-2,minecraft:lava)
B(4,34,-2,minecraft:lava)
B(4,35,-2,minecraft:lava)
B(4,36,-2,minecraft:lava)
B(4,37,-2,minecraft:lava)
B(4,38,-2,minecraft:lava)
B(4,39,-2,minecraft:lava)
B(4,40,-2,minecraft:lava)
B(4,41,-2,minecraft:lava)
B(4,42,-2,minecraft:lava)
B(4,43,-2,minecraft:lava)
B(4,44,-2,minecraft:lava)
B(4,0,-1,minecraft:lava)
B(4,1,-1,minecraft:lava)
B(4,2,-1,minecraft:lava)
B(4,3,-1,minecraft:lava)
B(4,4,-1,minecraft:lava)
B(4,5,-1,minecraft:lava)
B(4,6,-1,minecraft:lava)
B(4,7,-1,minecraft:lava)
B(4,8,-1,minecraft:lava)
B(4,9,-1,minecraft:lava)
B(4,10,-1,minecraft:lava)
B(4,11,-1,minecraft:lava)
B(4,12,-1,minecraft:lava)
B(4,13,-1,minecraft:lava)
B(4,14,-1,minecraft:lava)
B(4,15,-1,minecraft:lava)
B(4,16,-1,minecraft:lava)
B(4,17,-1,minecraft:lava)
B(4,18,-1,minecraft:lava)
B(4,19,-1,minecraft:lava)
B(4,20,-1,minecraft:lava)
B(4,21,-1,minecraft:lava)
B(4,22,-1,minecraft:lava)
B(4,23,-1,minecraft:lava)
B(4,24,-1,minecraft:lava)
B(4,25,-1,minecraft:lava)
B(4,26,-1,minecraft:lava)
B(4,27,-1,minecraft:lava)
B(4,28,-1,minecraft:lava)
B(4,29,-1,minecraft:lava)
B(4,30,-1,minecraft:lava)
B(4,31,-1,minecraft:lava)
B(4,32,-1,minecraft:lava)
B(4,33,-1,minecraft:lava)
B(4,34,-1,minecraft:lava)
B(4,35,-1,minecraft:lava)
B(4,36,-1,minecraft:lava)
B(4,37,-1,minecraft:lava)
B(4,38,-1,minecraft:lava)
B(4,39,-1,minecraft:lava)
B(4,40,-1,minecraft:lava)
B(4,41,-1,minecraft:lava)
B(4,42,-1,minecraft:lava)
B(4,43,-1,minecraft:lava)
B(4,44,-1,minecraft:lava)
B(4,0,0,minecraft:lava)
B(4,1,0,minecraft:lava)
B(4,2,0,minecraft:lava)
B(4,3,0,minecraft:lava)
B(4,4,0,minecraft:lava)
B(4,5,0,minecraft:lava)
B(4,6,0,minecraft:lava)
B(4,7,0,minecraft:lava)
B(4,8,0,minecraft:lava)
B(4,9,0,minecraft:lava)
B(4,10,0,minecraft:lava)
B(4,11,0,minecraft:lava)
B(4,12,0,minecraft:lava)
B(4,13,0,minecraft:lava)
B(4,14,0,minecraft:lava)
B(4,15,0,minecraft:lava)
B(4,16,0,minecraft:lava)
B(4,17,0,minecraft:lava)
