
#######################################################################
# +-----------------------------------------------------------------+ #
# |                            BO4 object                           | #
# +-----------------------------------------------------------------+ #
#######################################################################

Author: Unknown

Description: No description given

SettingsMode: WriteWithoutComments


#######################################################################
# +-----------------------------------------------------------------+ #
# |                          Main settings                          | #
# +-----------------------------------------------------------------+ #
#######################################################################

FixedRotation: 

Frequency: 0

SpawnHeight: highestBlock

UseCenterForHighestBlock: true

##############################
# Height Limits for the BO4. #
##############################

MinHeight: 0

MaxHeight: 255

InheritBO3: 

InheritBO3Rotation: NORTH

OverrideChildSettings: true

OverrideParentHeight: false

CanOverride: false

BranchFrequency: 0

BranchFrequencyGroup: 

MustBeBelowOther: false

MustBeInside: 

CannotBeInside: 

ReplacesBO3: 

MustBeInsideWorldBorders: false

CanSpawnOnWater: true

SpawnOnWaterOnly: false

SpawnUnderWater: false

SpawnAtWaterLevel: false

HeightOffset: 0

RemoveAir: true

ReplaceAbove: 

ReplaceBelow: 

ReplaceWithBiomeBlocks: true

ReplaceWithSurfaceBlock: GRASS

ReplaceWithGroundBlock: DIRT

ReplaceWithStoneBlock: STONE

SmoothRadius: 0

SmoothHeightOffset: 0

SmoothStartTop: false

SmoothStartWood: false

SmoothingSurfaceBlock: 

SmoothingGroundBlock: 

BO3Group: 

IsSpawnPoint: false

DoReplaceBlocks: true


#######################################################################
# +-----------------------------------------------------------------+ #
# |                              Blocks                             | #
# +-----------------------------------------------------------------+ #
#######################################################################

B(-8,112,-7,minecraft:basalt)
B(-8,113,-7,minecraft:basalt)
B(-8,114,-7,minecraft:basalt)
B(-8,115,-7,minecraft:basalt)
B(-8,116,-7,minecraft:basalt)
B(-8,112,-6,minecraft:basalt)
B(-8,113,-6,minecraft:basalt)
B(-8,114,-6,minecraft:basalt)
B(-8,115,-6,minecraft:basalt)
B(-8,116,-6,minecraft:basalt)
B(-8,112,-5,minecraft:basalt)
B(-8,113,-5,minecraft:basalt)
B(-8,114,-5,minecraft:basalt)
B(-8,115,-5,minecraft:basalt)
B(-8,116,-5,minecraft:basalt)
B(-8,112,-4,minecraft:basalt)
B(-8,113,-4,minecraft:basalt)
B(-8,114,-4,minecraft:basalt)
B(-8,115,-4,minecraft:basalt)
B(-8,116,-4,minecraft:basalt)
B(-8,111,-3,minecraft:basalt)
B(-8,112,-3,minecraft:basalt)
B(-8,113,-3,minecraft:basalt)
B(-8,114,-3,minecraft:basalt)
B(-8,115,-3,minecraft:basalt)
B(-8,116,-3,minecraft:basalt)
B(-8,111,-2,minecraft:basalt)
B(-8,112,-2,minecraft:basalt)
B(-8,113,-2,minecraft:basalt)
B(-8,114,-2,minecraft:basalt)
B(-8,115,-2,minecraft:basalt)
B(-8,116,-2,minecraft:basalt)
B(-8,111,-1,minecraft:basalt)
B(-8,112,-1,minecraft:basalt)
B(-8,113,-1,minecraft:basalt)
B(-8,114,-1,minecraft:basalt)
B(-8,115,-1,minecraft:basalt)
B(-8,116,-1,minecraft:basalt)
B(-8,111,0,minecraft:basalt)
B(-8,112,0,minecraft:basalt)
B(-8,113,0,minecraft:basalt)
B(-8,114,0,minecraft:basalt)
B(-8,115,0,minecraft:basalt)
B(-8,116,0,minecraft:basalt)
B(-8,111,1,minecraft:basalt)
B(-8,112,1,minecraft:basalt)
B(-8,113,1,minecraft:basalt)
B(-8,114,1,minecraft:basalt)
B(-8,115,1,minecraft:basalt)
B(-8,116,1,minecraft:basalt)
B(-8,111,2,minecraft:basalt)
B(-8,112,2,minecraft:basalt)
B(-8,113,2,minecraft:basalt)
B(-8,114,2,minecraft:basalt)
B(-8,115,2,minecraft:basalt)
B(-8,116,2,minecraft:basalt)
B(-8,111,3,minecraft:basalt)
B(-8,112,3,minecraft:basalt)
B(-8,113,3,minecraft:basalt)
B(-8,114,3,minecraft:basalt)
B(-8,115,3,minecraft:basalt)
B(-8,116,3,minecraft:basalt)
B(-8,111,4,minecraft:basalt)
B(-8,112,4,minecraft:basalt)
B(-8,113,4,minecraft:basalt)
B(-8,114,4,minecraft:basalt)
B(-8,115,4,minecraft:basalt)
B(-8,116,4,minecraft:basalt)
B(-8,112,5,minecraft:basalt)
B(-8,113,5,minecraft:basalt)
B(-8,114,5,minecraft:basalt)
B(-8,115,5,minecraft:basalt)
B(-8,116,5,minecraft:basalt)
B(-8,113,6,minecraft:basalt)
B(-8,114,6,minecraft:basalt)
B(-8,115,6,minecraft:basalt)
B(-8,116,6,minecraft:basalt)
B(-8,114,7,minecraft:basalt)
B(-8,115,7,minecraft:basalt)
B(-8,116,7,minecraft:basalt)
B(-8,115,8,minecraft:basalt)
B(-8,116,8,minecraft:basalt)
B(-7,112,-7,minecraft:basalt)
B(-7,113,-7,minecraft:basalt)
B(-7,114,-7,minecraft:basalt)
B(-7,115,-7,minecraft:basalt)
B(-7,116,-7,minecraft:basalt)
B(-7,112,-6,minecraft:basalt)
B(-7,113,-6,minecraft:basalt)
B(-7,114,-6,minecraft:basalt)
B(-7,115,-6,minecraft:basalt)
B(-7,116,-6,minecraft:basalt)
B(-7,112,-5,minecraft:basalt)
B(-7,113,-5,minecraft:basalt)
B(-7,114,-5,minecraft:basalt)
B(-7,115,-5,minecraft:basalt)
B(-7,116,-5,minecraft:basalt)
B(-7,112,-4,minecraft:basalt)
B(-7,113,-4,minecraft:basalt)
B(-7,114,-4,minecraft:basalt)
B(-7,115,-4,minecraft:basalt)
B(-7,116,-4,minecraft:basalt)
B(-7,112,-3,minecraft:basalt)
B(-7,113,-3,minecraft:basalt)
B(-7,114,-3,minecraft:basalt)
B(-7,115,-3,minecraft:basalt)
B(-7,116,-3,minecraft:basalt)
B(-7,111,-2,minecraft:basalt)
B(-7,112,-2,minecraft:basalt)
B(-7,113,-2,minecraft:basalt)
B(-7,114,-2,minecraft:basalt)
B(-7,115,-2,minecraft:basalt)
B(-7,116,-2,minecraft:basalt)
B(-7,111,-1,minecraft:basalt)
B(-7,112,-1,minecraft:basalt)
B(-7,113,-1,minecraft:basalt)
B(-7,114,-1,minecraft:basalt)
B(-7,115,-1,minecraft:basalt)
B(-7,116,-1,minecraft:basalt)
B(-7,111,0,minecraft:basalt)
B(-7,112,0,minecraft:basalt)
B(-7,113,0,minecraft:basalt)
B(-7,114,0,minecraft:basalt)
B(-7,115,0,minecraft:basalt)
B(-7,116,0,minecraft:basalt)
B(-7,110,1,minecraft:basalt)
B(-7,111,1,minecraft:basalt)
B(-7,112,1,minecraft:basalt)
B(-7,113,1,minecraft:basalt)
B(-7,114,1,minecraft:basalt)
B(-7,115,1,minecraft:basalt)
B(-7,116,1,minecraft:basalt)
B(-7,110,2,minecraft:basalt)
B(-7,111,2,minecraft:basalt)
B(-7,112,2,minecraft:basalt)
B(-7,113,2,minecraft:basalt)
B(-7,114,2,minecraft:basalt)
B(-7,115,2,minecraft:basalt)
B(-7,116,2,minecraft:basalt)
B(-7,110,3,minecraft:basalt)
B(-7,111,3,minecraft:basalt)
B(-7,112,3,minecraft:basalt)
B(-7,113,3,minecraft:basalt)
B(-7,114,3,minecraft:basalt)
B(-7,115,3,minecraft:basalt)
B(-7,116,3,minecraft:basalt)
B(-7,110,4,minecraft:basalt)
B(-7,111,4,minecraft:basalt)
B(-7,112,4,minecraft:basalt)
B(-7,113,4,minecraft:basalt)
B(-7,114,4,minecraft:basalt)
B(-7,115,4,minecraft:basalt)
B(-7,116,4,minecraft:basalt)
B(-7,111,5,minecraft:basalt)
B(-7,112,5,minecraft:basalt)
B(-7,113,5,minecraft:basalt)
B(-7,114,5,minecraft:basalt)
B(-7,115,5,minecraft:basalt)
B(-7,116,5,minecraft:basalt)
B(-7,112,6,minecraft:basalt)
B(-7,113,6,minecraft:basalt)
B(-7,114,6,minecraft:basalt)
B(-7,115,6,minecraft:basalt)
B(-7,116,6,minecraft:basalt)
B(-7,113,7,minecraft:basalt)
B(-7,114,7,minecraft:basalt)
B(-7,115,7,minecraft:basalt)
B(-7,116,7,minecraft:basalt)
B(-7,114,8,minecraft:basalt)
B(-7,115,8,minecraft:basalt)
B(-7,116,8,minecraft:basalt)
B(-6,112,-7,minecraft:basalt)
B(-6,113,-7,minecraft:basalt)
B(-6,114,-7,minecraft:basalt)
B(-6,115,-7,minecraft:basalt)
B(-6,116,-7,minecraft:basalt)
B(-6,112,-6,minecraft:basalt)
B(-6,113,-6,minecraft:basalt)
B(-6,114,-6,minecraft:basalt)
B(-6,115,-6,minecraft:basalt)
B(-6,116,-6,minecraft:basalt)
B(-6,112,-5,minecraft:basalt)
B(-6,113,-5,minecraft:basalt)
B(-6,114,-5,minecraft:basalt)
B(-6,115,-5,minecraft:basalt)
B(-6,116,-5,minecraft:basalt)
B(-6,112,-4,minecraft:basalt)
B(-6,113,-4,minecraft:basalt)
B(-6,114,-4,minecraft:basalt)
B(-6,115,-4,minecraft:basalt)
B(-6,116,-4,minecraft:basalt)
B(-6,112,-3,minecraft:basalt)
B(-6,113,-3,minecraft:basalt)
B(-6,114,-3,minecraft:basalt)
B(-6,115,-3,minecraft:basalt)
B(-6,116,-3,minecraft:basalt)
B(-6,111,-2,minecraft:basalt)
B(-6,112,-2,minecraft:basalt)
B(-6,113,-2,minecraft:basalt)
B(-6,114,-2,minecraft:basalt)
B(-6,115,-2,minecraft:basalt)
B(-6,116,-2,minecraft:basalt)
B(-6,111,-1,minecraft:basalt)
B(-6,112,-1,minecraft:basalt)
B(-6,113,-1,minecraft:basalt)
B(-6,114,-1,minecraft:basalt)
B(-6,115,-1,minecraft:basalt)
B(-6,116,-1,minecraft:basalt)
B(-6,110,0,minecraft:basalt)
B(-6,111,0,minecraft:basalt)
B(-6,112,0,minecraft:basalt)
B(-6,113,0,minecraft:basalt)
B(-6,114,0,minecraft:basalt)
B(-6,115,0,minecraft:basalt)
B(-6,116,0,minecraft:basalt)
B(-6,110,1,minecraft:basalt)
B(-6,111,1,minecraft:basalt)
B(-6,112,1,minecraft:basalt)
B(-6,113,1,minecraft:basalt)
B(-6,114,1,minecraft:basalt)
B(-6,115,1,minecraft:basalt)
B(-6,116,1,minecraft:basalt)
B(-6,110,2,minecraft:basalt)
B(-6,111,2,minecraft:basalt)
B(-6,112,2,minecraft:basalt)
B(-6,113,2,minecraft:basalt)
B(-6,114,2,minecraft:basalt)
B(-6,115,2,minecraft:basalt)
B(-6,116,2,minecraft:basalt)
B(-6,109,3,minecraft:basalt)
B(-6,110,3,minecraft:basalt)
B(-6,111,3,minecraft:basalt)
B(-6,112,3,minecraft:basalt)
B(-6,113,3,minecraft:basalt)
B(-6,114,3,minecraft:basalt)
B(-6,115,3,minecraft:basalt)
B(-6,116,3,minecraft:basalt)
B(-6,109,4,minecraft:basalt)
B(-6,110,4,minecraft:basalt)
B(-6,111,4,minecraft:basalt)
B(-6,112,4,minecraft:basalt)
B(-6,113,4,minecraft:basalt)
B(-6,114,4,minecraft:basalt)
B(-6,115,4,minecraft:basalt)
B(-6,116,4,minecraft:basalt)
B(-6,110,5,minecraft:basalt)
B(-6,111,5,minecraft:basalt)
B(-6,112,5,minecraft:basalt)
B(-6,113,5,minecraft:basalt)
B(-6,114,5,minecraft:basalt)
B(-6,115,5,minecraft:basalt)
B(-6,116,5,minecraft:basalt)
B(-6,111,6,minecraft:basalt)
B(-6,112,6,minecraft:basalt)
B(-6,113,6,minecraft:basalt)
B(-6,114,6,minecraft:basalt)
B(-6,115,6,minecraft:basalt)
B(-6,116,6,minecraft:basalt)
B(-6,111,7,minecraft:basalt)
B(-6,112,7,minecraft:basalt)
B(-6,113,7,minecraft:basalt)
B(-6,114,7,minecraft:basalt)
B(-6,115,7,minecraft:basalt)
B(-6,116,7,minecraft:basalt)
B(-6,112,8,minecraft:basalt)
B(-6,113,8,minecraft:basalt)
B(-6,114,8,minecraft:basalt)
B(-6,115,8,minecraft:basalt)
B(-6,116,8,minecraft:basalt)
B(-5,112,-7,minecraft:basalt)
B(-5,113,-7,minecraft:basalt)
B(-5,114,-7,minecraft:basalt)
B(-5,115,-7,minecraft:basalt)
B(-5,116,-7,minecraft:basalt)
B(-5,112,-6,minecraft:basalt)
B(-5,113,-6,minecraft:basalt)
B(-5,114,-6,minecraft:basalt)
B(-5,115,-6,minecraft:basalt)
B(-5,116,-6,minecraft:basalt)
B(-5,112,-5,minecraft:basalt)
B(-5,113,-5,minecraft:basalt)
B(-5,114,-5,minecraft:basalt)
B(-5,115,-5,minecraft:basalt)
B(-5,116,-5,minecraft:basalt)
B(-5,112,-4,minecraft:basalt)
B(-5,113,-4,minecraft:basalt)
B(-5,114,-4,minecraft:basalt)
B(-5,115,-4,minecraft:basalt)
B(-5,116,-4,minecraft:basalt)
B(-5,112,-3,minecraft:basalt)
B(-5,113,-3,minecraft:basalt)
B(-5,114,-3,minecraft:basalt)
B(-5,115,-3,minecraft:basalt)
B(-5,116,-3,minecraft:basalt)
B(-5,111,-2,minecraft:basalt)
B(-5,112,-2,minecraft:basalt)
B(-5,113,-2,minecraft:basalt)
B(-5,114,-2,minecraft:basalt)
B(-5,115,-2,minecraft:basalt)
B(-5,116,-2,minecraft:basalt)
B(-5,111,-1,minecraft:basalt)
B(-5,112,-1,minecraft:basalt)
B(-5,113,-1,minecraft:basalt)
B(-5,114,-1,minecraft:basalt)
B(-5,115,-1,minecraft:basalt)
B(-5,116,-1,minecraft:basalt)
B(-5,110,0,minecraft:basalt)
B(-5,111,0,minecraft:basalt)
B(-5,112,0,minecraft:basalt)
B(-5,113,0,minecraft:basalt)
B(-5,114,0,minecraft:basalt)
B(-5,115,0,minecraft:basalt)
B(-5,116,0,minecraft:basalt)
B(-5,110,1,minecraft:basalt)
B(-5,111,1,minecraft:basalt)
B(-5,112,1,minecraft:basalt)
B(-5,113,1,minecraft:basalt)
B(-5,114,1,minecraft:basalt)
B(-5,115,1,minecraft:basalt)
B(-5,116,1,minecraft:basalt)
B(-5,109,2,minecraft:basalt)
B(-5,110,2,minecraft:basalt)
B(-5,111,2,minecraft:basalt)
B(-5,112,2,minecraft:basalt)
B(-5,113,2,minecraft:basalt)
B(-5,114,2,minecraft:basalt)
B(-5,115,2,minecraft:basalt)
B(-5,116,2,minecraft:basalt)
B(-5,109,3,minecraft:basalt)
B(-5,110,3,minecraft:basalt)
B(-5,111,3,minecraft:basalt)
B(-5,112,3,minecraft:basalt)
B(-5,113,3,minecraft:basalt)
B(-5,114,3,minecraft:basalt)
B(-5,115,3,minecraft:basalt)
B(-5,116,3,minecraft:basalt)
B(-5,108,4,minecraft:basalt)
B(-5,109,4,minecraft:basalt)
B(-5,110,4,minecraft:basalt)
B(-5,111,4,minecraft:basalt)
B(-5,112,4,minecraft:basalt)
B(-5,113,4,minecraft:basalt)
B(-5,114,4,minecraft:basalt)
B(-5,115,4,minecraft:basalt)
B(-5,116,4,minecraft:basalt)
B(-5,109,5,minecraft:basalt)
B(-5,110,5,minecraft:basalt)
B(-5,111,5,minecraft:basalt)
B(-5,112,5,minecraft:basalt)
B(-5,113,5,minecraft:basalt)
B(-5,114,5,minecraft:basalt)
B(-5,115,5,minecraft:basalt)
B(-5,116,5,minecraft:basalt)
B(-5,109,6,minecraft:basalt)
B(-5,110,6,minecraft:basalt)
B(-5,111,6,minecraft:basalt)
B(-5,112,6,minecraft:basalt)
B(-5,113,6,minecraft:basalt)
B(-5,114,6,minecraft:basalt)
B(-5,115,6,minecraft:basalt)
B(-5,116,6,minecraft:basalt)
B(-5,110,7,minecraft:basalt)
B(-5,111,7,minecraft:basalt)
B(-5,112,7,minecraft:basalt)
B(-5,113,7,minecraft:basalt)
B(-5,114,7,minecraft:basalt)
B(-5,115,7,minecraft:basalt)
B(-5,116,7,minecraft:basalt)
B(-5,110,8,minecraft:basalt)
B(-5,111,8,minecraft:basalt)
B(-5,112,8,minecraft:basalt)
B(-5,113,8,minecraft:basalt)
B(-5,114,8,minecraft:basalt)
B(-5,115,8,minecraft:basalt)
B(-5,116,8,minecraft:basalt)
B(-4,112,-7,minecraft:basalt)
B(-4,113,-7,minecraft:basalt)
B(-4,114,-7,minecraft:basalt)
B(-4,115,-7,minecraft:basalt)
B(-4,116,-7,minecraft:basalt)
B(-4,112,-6,minecraft:basalt)
B(-4,113,-6,minecraft:basalt)
B(-4,114,-6,minecraft:basalt)
B(-4,115,-6,minecraft:basalt)
B(-4,116,-6,minecraft:basalt)
B(-4,112,-5,minecraft:basalt)
B(-4,113,-5,minecraft:basalt)
B(-4,114,-5,minecraft:basalt)
B(-4,115,-5,minecraft:basalt)
B(-4,116,-5,minecraft:basalt)
B(-4,112,-4,minecraft:basalt)
B(-4,113,-4,minecraft:basalt)
B(-4,114,-4,minecraft:basalt)
B(-4,115,-4,minecraft:basalt)
B(-4,116,-4,minecraft:basalt)
B(-4,112,-3,minecraft:basalt)
B(-4,113,-3,minecraft:basalt)
B(-4,114,-3,minecraft:basalt)
B(-4,115,-3,minecraft:basalt)
B(-4,116,-3,minecraft:basalt)
B(-4,111,-2,minecraft:basalt)
B(-4,112,-2,minecraft:basalt)
B(-4,113,-2,minecraft:basalt)
B(-4,114,-2,minecraft:basalt)
B(-4,115,-2,minecraft:basalt)
B(-4,116,-2,minecraft:basalt)
B(-4,111,-1,minecraft:basalt)
B(-4,112,-1,minecraft:basalt)
B(-4,113,-1,minecraft:basalt)
B(-4,114,-1,minecraft:basalt)
B(-4,115,-1,minecraft:basalt)
B(-4,116,-1,minecraft:basalt)
B(-4,110,0,minecraft:basalt)
B(-4,111,0,minecraft:basalt)
B(-4,112,0,minecraft:basalt)
B(-4,113,0,minecraft:basalt)
B(-4,114,0,minecraft:basalt)
B(-4,115,0,minecraft:basalt)
B(-4,116,0,minecraft:basalt)
B(-4,110,1,minecraft:basalt)
B(-4,111,1,minecraft:basalt)
B(-4,112,1,minecraft:basalt)
B(-4,113,1,minecraft:basalt)
B(-4,114,1,minecraft:basalt)
B(-4,115,1,minecraft:basalt)
B(-4,116,1,minecraft:basalt)
B(-4,109,2,minecraft:basalt)
B(-4,110,2,minecraft:basalt)
B(-4,111,2,minecraft:basalt)
B(-4,112,2,minecraft:basalt)
B(-4,113,2,minecraft:basalt)
B(-4,114,2,minecraft:basalt)
B(-4,115,2,minecraft:basalt)
B(-4,116,2,minecraft:basalt)
B(-4,108,3,minecraft:basalt)
B(-4,109,3,minecraft:basalt)
B(-4,110,3,minecraft:basalt)
B(-4,111,3,minecraft:basalt)
B(-4,112,3,minecraft:basalt)
B(-4,113,3,minecraft:basalt)
B(-4,114,3,minecraft:basalt)
B(-4,115,3,minecraft:basalt)
B(-4,116,3,minecraft:basalt)
B(-4,108,4,minecraft:basalt)
B(-4,109,4,minecraft:basalt)
B(-4,110,4,minecraft:basalt)
B(-4,111,4,minecraft:basalt)
B(-4,112,4,minecraft:basalt)
B(-4,113,4,minecraft:basalt)
B(-4,114,4,minecraft:basalt)
B(-4,115,4,minecraft:basalt)
B(-4,116,4,minecraft:basalt)
B(-4,108,5,minecraft:basalt)
B(-4,109,5,minecraft:basalt)
B(-4,110,5,minecraft:basalt)
B(-4,111,5,minecraft:basalt)
B(-4,112,5,minecraft:basalt)
B(-4,113,5,minecraft:basalt)
B(-4,114,5,minecraft:basalt)
B(-4,115,5,minecraft:basalt)
B(-4,116,5,minecraft:basalt)
B(-4,108,6,minecraft:basalt)
B(-4,109,6,minecraft:basalt)
B(-4,110,6,minecraft:basalt)
B(-4,111,6,minecraft:basalt)
B(-4,112,6,minecraft:basalt)
B(-4,113,6,minecraft:basalt)
B(-4,114,6,minecraft:basalt)
B(-4,115,6,minecraft:basalt)
B(-4,116,6,minecraft:basalt)
B(-4,108,7,minecraft:basalt)
B(-4,109,7,minecraft:basalt)
B(-4,110,7,minecraft:basalt)
B(-4,111,7,minecraft:basalt)
B(-4,112,7,minecraft:basalt)
B(-4,113,7,minecraft:basalt)
B(-4,114,7,minecraft:basalt)
B(-4,115,7,minecraft:basalt)
B(-4,116,7,minecraft:basalt)
B(-4,108,8,minecraft:basalt)
B(-4,109,8,minecraft:basalt)
B(-4,110,8,minecraft:basalt)
B(-4,111,8,minecraft:basalt)
B(-4,112,8,minecraft:basalt)
B(-4,113,8,minecraft:basalt)
B(-4,114,8,minecraft:basalt)
B(-4,115,8,minecraft:basalt)
B(-4,116,8,minecraft:basalt)
B(-3,112,-7,minecraft:basalt)
B(-3,113,-7,minecraft:basalt)
B(-3,114,-7,minecraft:basalt)
B(-3,115,-7,minecraft:basalt)
B(-3,116,-7,minecraft:basalt)
B(-3,112,-6,minecraft:basalt)
B(-3,113,-6,minecraft:basalt)
B(-3,114,-6,minecraft:basalt)
B(-3,115,-6,minecraft:basalt)
B(-3,116,-6,minecraft:basalt)
B(-3,112,-5,minecraft:basalt)
B(-3,113,-5,minecraft:basalt)
B(-3,114,-5,minecraft:basalt)
B(-3,115,-5,minecraft:basalt)
B(-3,116,-5,minecraft:basalt)
B(-3,112,-4,minecraft:basalt)
B(-3,113,-4,minecraft:basalt)
B(-3,114,-4,minecraft:basalt)
B(-3,115,-4,minecraft:basalt)
B(-3,116,-4,minecraft:basalt)
B(-3,112,-3,minecraft:basalt)
B(-3,113,-3,minecraft:basalt)
B(-3,114,-3,minecraft:basalt)
B(-3,115,-3,minecraft:basalt)
B(-3,116,-3,minecraft:basalt)
B(-3,111,-2,minecraft:basalt)
B(-3,112,-2,minecraft:basalt)
B(-3,113,-2,minecraft:basalt)
B(-3,114,-2,minecraft:basalt)
B(-3,115,-2,minecraft:basalt)
B(-3,116,-2,minecraft:basalt)
B(-3,111,-1,minecraft:basalt)
B(-3,112,-1,minecraft:basalt)
B(-3,113,-1,minecraft:basalt)
B(-3,114,-1,minecraft:basalt)
B(-3,115,-1,minecraft:basalt)
B(-3,116,-1,minecraft:basalt)
B(-3,110,0,minecraft:basalt)
B(-3,111,0,minecraft:basalt)
B(-3,112,0,minecraft:basalt)
B(-3,113,0,minecraft:basalt)
B(-3,114,0,minecraft:basalt)
B(-3,115,0,minecraft:basalt)
B(-3,116,0,minecraft:basalt)
B(-3,109,1,minecraft:basalt)
B(-3,110,1,minecraft:basalt)
B(-3,111,1,minecraft:basalt)
B(-3,112,1,minecraft:basalt)
B(-3,113,1,minecraft:basalt)
B(-3,114,1,minecraft:basalt)
B(-3,115,1,minecraft:basalt)
B(-3,116,1,minecraft:basalt)
B(-3,108,2,minecraft:basalt)
B(-3,109,2,minecraft:basalt)
B(-3,110,2,minecraft:basalt)
B(-3,111,2,minecraft:basalt)
B(-3,112,2,minecraft:basalt)
B(-3,113,2,minecraft:basalt)
B(-3,114,2,minecraft:basalt)
B(-3,115,2,minecraft:basalt)
B(-3,116,2,minecraft:basalt)
B(-3,108,3,minecraft:basalt)
B(-3,109,3,minecraft:basalt)
B(-3,110,3,minecraft:basalt)
B(-3,111,3,minecraft:basalt)
B(-3,112,3,minecraft:basalt)
B(-3,113,3,minecraft:basalt)
B(-3,114,3,minecraft:basalt)
B(-3,115,3,minecraft:basalt)
B(-3,116,3,minecraft:basalt)
B(-3,107,4,minecraft:basalt)
B(-3,108,4,minecraft:basalt)
B(-3,109,4,minecraft:basalt)
B(-3,110,4,minecraft:basalt)
B(-3,111,4,minecraft:basalt)
B(-3,112,4,minecraft:basalt)
B(-3,113,4,minecraft:basalt)
B(-3,114,4,minecraft:basalt)
B(-3,115,4,minecraft:basalt)
B(-3,116,4,minecraft:basalt)
B(-3,107,5,minecraft:basalt)
B(-3,108,5,minecraft:basalt)
B(-3,109,5,minecraft:basalt)
B(-3,110,5,minecraft:basalt)
B(-3,111,5,minecraft:basalt)
B(-3,112,5,minecraft:basalt)
B(-3,113,5,minecraft:basalt)
B(-3,114,5,minecraft:basalt)
B(-3,115,5,minecraft:basalt)
B(-3,116,5,minecraft:basalt)
B(-3,107,6,minecraft:basalt)
B(-3,108,6,minecraft:basalt)
B(-3,109,6,minecraft:basalt)
B(-3,110,6,minecraft:basalt)
B(-3,111,6,minecraft:basalt)
B(-3,112,6,minecraft:basalt)
B(-3,113,6,minecraft:basalt)
B(-3,114,6,minecraft:basalt)
B(-3,115,6,minecraft:basalt)
B(-3,116,6,minecraft:basalt)
B(-3,106,7,minecraft:basalt)
B(-3,107,7,minecraft:basalt)
B(-3,108,7,minecraft:basalt)
B(-3,109,7,minecraft:basalt)
B(-3,110,7,minecraft:basalt)
B(-3,111,7,minecraft:basalt)
B(-3,112,7,minecraft:basalt)
B(-3,113,7,minecraft:basalt)
B(-3,114,7,minecraft:basalt)
B(-3,115,7,minecraft:basalt)
B(-3,116,7,minecraft:basalt)
B(-3,106,8,minecraft:basalt)
B(-3,107,8,minecraft:basalt)
B(-3,108,8,minecraft:basalt)
B(-3,109,8,minecraft:basalt)
B(-3,110,8,minecraft:basalt)
B(-3,111,8,minecraft:basalt)
B(-3,112,8,minecraft:basalt)
B(-3,113,8,minecraft:basalt)
B(-3,114,8,minecraft:basalt)
B(-3,115,8,minecraft:basalt)
B(-3,116,8,minecraft:basalt)
B(-2,112,-7,minecraft:basalt)
B(-2,113,-7,minecraft:basalt)
B(-2,114,-7,minecraft:basalt)
B(-2,115,-7,minecraft:basalt)
B(-2,116,-7,minecraft:basalt)
B(-2,112,-6,minecraft:basalt)
B(-2,113,-6,minecraft:basalt)
B(-2,114,-6,minecraft:basalt)
B(-2,115,-6,minecraft:basalt)
B(-2,116,-6,minecraft:basalt)
B(-2,112,-5,minecraft:basalt)
B(-2,113,-5,minecraft:basalt)
B(-2,114,-5,minecraft:basalt)
B(-2,115,-5,minecraft:basalt)
B(-2,116,-5,minecraft:basalt)
B(-2,112,-4,minecraft:basalt)
B(-2,113,-4,minecraft:basalt)
B(-2,114,-4,minecraft:basalt)
B(-2,115,-4,minecraft:basalt)
B(-2,116,-4,minecraft:basalt)
B(-2,111,-3,minecraft:basalt)
B(-2,112,-3,minecraft:basalt)
B(-2,113,-3,minecraft:basalt)
B(-2,114,-3,minecraft:basalt)
B(-2,115,-3,minecraft:basalt)
B(-2,116,-3,minecraft:basalt)
B(-2,111,-2,minecraft:basalt)
B(-2,112,-2,minecraft:basalt)
B(-2,113,-2,minecraft:basalt)
B(-2,114,-2,minecraft:basalt)
B(-2,115,-2,minecraft:basalt)
B(-2,116,-2,minecraft:basalt)
B(-2,110,-1,minecraft:basalt)
B(-2,111,-1,minecraft:basalt)
B(-2,112,-1,minecraft:basalt)
B(-2,113,-1,minecraft:basalt)
B(-2,114,-1,minecraft:basalt)
B(-2,115,-1,minecraft:basalt)
B(-2,116,-1,minecraft:basalt)
B(-2,110,0,minecraft:basalt)
B(-2,111,0,minecraft:basalt)
B(-2,112,0,minecraft:basalt)
B(-2,113,0,minecraft:basalt)
B(-2,114,0,minecraft:basalt)
B(-2,115,0,minecraft:basalt)
B(-2,116,0,minecraft:basalt)
B(-2,109,1,minecraft:basalt)
B(-2,110,1,minecraft:basalt)
B(-2,111,1,minecraft:basalt)
B(-2,112,1,minecraft:basalt)
B(-2,113,1,minecraft:basalt)
B(-2,114,1,minecraft:basalt)
B(-2,115,1,minecraft:basalt)
B(-2,116,1,minecraft:basalt)
B(-2,108,2,minecraft:basalt)
B(-2,109,2,minecraft:basalt)
B(-2,110,2,minecraft:basalt)
B(-2,111,2,minecraft:basalt)
B(-2,112,2,minecraft:basalt)
B(-2,113,2,minecraft:basalt)
B(-2,114,2,minecraft:basalt)
B(-2,115,2,minecraft:basalt)
B(-2,116,2,minecraft:basalt)
B(-2,108,3,minecraft:basalt)
B(-2,109,3,minecraft:basalt)
B(-2,110,3,minecraft:basalt)
B(-2,111,3,minecraft:basalt)
B(-2,112,3,minecraft:basalt)
B(-2,113,3,minecraft:basalt)
B(-2,114,3,minecraft:basalt)
B(-2,115,3,minecraft:basalt)
B(-2,116,3,minecraft:basalt)
B(-2,107,4,minecraft:basalt)
B(-2,108,4,minecraft:basalt)
B(-2,109,4,minecraft:basalt)
B(-2,110,4,minecraft:basalt)
B(-2,111,4,minecraft:basalt)
B(-2,112,4,minecraft:basalt)
B(-2,113,4,minecraft:basalt)
B(-2,114,4,minecraft:basalt)
B(-2,115,4,minecraft:basalt)
B(-2,116,4,minecraft:basalt)
B(-2,107,5,minecraft:basalt)
B(-2,108,5,minecraft:basalt)
B(-2,109,5,minecraft:basalt)
B(-2,110,5,minecraft:basalt)
B(-2,111,5,minecraft:basalt)
B(-2,112,5,minecraft:basalt)
B(-2,113,5,minecraft:basalt)
B(-2,114,5,minecraft:basalt)
B(-2,115,5,minecraft:basalt)
B(-2,116,5,minecraft:basalt)
B(-2,107,6,minecraft:basalt)
B(-2,108,6,minecraft:basalt)
B(-2,109,6,minecraft:basalt)
B(-2,110,6,minecraft:basalt)
B(-2,111,6,minecraft:basalt)
B(-2,112,6,minecraft:basalt)
B(-2,113,6,minecraft:basalt)
B(-2,114,6,minecraft:basalt)
B(-2,115,6,minecraft:basalt)
B(-2,116,6,minecraft:basalt)
B(-2,106,7,minecraft:basalt)
B(-2,107,7,minecraft:basalt)
B(-2,108,7,minecraft:basalt)
B(-2,109,7,minecraft:basalt)
B(-2,110,7,minecraft:basalt)
B(-2,111,7,minecraft:basalt)
B(-2,112,7,minecraft:basalt)
B(-2,113,7,minecraft:basalt)
B(-2,114,7,minecraft:basalt)
B(-2,115,7,minecraft:basalt)
B(-2,116,7,minecraft:basalt)
B(-2,106,8,minecraft:basalt)
B(-2,107,8,minecraft:basalt)
B(-2,108,8,minecraft:basalt)
B(-2,109,8,minecraft:basalt)
B(-2,110,8,minecraft:basalt)
B(-2,111,8,minecraft:basalt)
B(-2,112,8,minecraft:basalt)
B(-2,113,8,minecraft:basalt)
B(-2,114,8,minecraft:basalt)
B(-2,115,8,minecraft:basalt)
B(-2,116,8,minecraft:basalt)
B(-1,112,-7,minecraft:basalt)
B(-1,113,-7,minecraft:basalt)
B(-1,114,-7,minecraft:basalt)
B(-1,115,-7,minecraft:basalt)
B(-1,116,-7,minecraft:basalt)
B(-1,112,-6,minecraft:basalt)
B(-1,113,-6,minecraft:basalt)
B(-1,114,-6,minecraft:basalt)
B(-1,115,-6,minecraft:basalt)
B(-1,116,-6,minecraft:basalt)
B(-1,111,-5,minecraft:basalt)
B(-1,112,-5,minecraft:basalt)
B(-1,113,-5,minecraft:basalt)
B(-1,114,-5,minecraft:basalt)
B(-1,115,-5,minecraft:basalt)
B(-1,116,-5,minecraft:basalt)
B(-1,111,-4,minecraft:basalt)
B(-1,112,-4,minecraft:basalt)
B(-1,113,-4,minecraft:basalt)
B(-1,114,-4,minecraft:basalt)
B(-1,115,-4,minecraft:basalt)
B(-1,116,-4,minecraft:basalt)
B(-1,111,-3,minecraft:basalt)
B(-1,112,-3,minecraft:basalt)
B(-1,113,-3,minecraft:basalt)
B(-1,114,-3,minecraft:basalt)
B(-1,115,-3,minecraft:basalt)
B(-1,116,-3,minecraft:basalt)
B(-1,110,-2,minecraft:basalt)
B(-1,111,-2,minecraft:basalt)
B(-1,112,-2,minecraft:basalt)
B(-1,113,-2,minecraft:basalt)
B(-1,114,-2,minecraft:basalt)
B(-1,115,-2,minecraft:basalt)
B(-1,116,-2,minecraft:basalt)
B(-1,110,-1,minecraft:basalt)
B(-1,111,-1,minecraft:basalt)
B(-1,112,-1,minecraft:basalt)
B(-1,113,-1,minecraft:basalt)
B(-1,114,-1,minecraft:basalt)
B(-1,115,-1,minecraft:basalt)
B(-1,116,-1,minecraft:basalt)
B(-1,109,0,minecraft:basalt)
B(-1,110,0,minecraft:basalt)
B(-1,111,0,minecraft:basalt)
B(-1,112,0,minecraft:basalt)
B(-1,113,0,minecraft:basalt)
B(-1,114,0,minecraft:basalt)
B(-1,115,0,minecraft:basalt)
B(-1,116,0,minecraft:basalt)
B(-1,109,1,minecraft:basalt)
B(-1,110,1,minecraft:basalt)
B(-1,111,1,minecraft:basalt)
B(-1,112,1,minecraft:basalt)
B(-1,113,1,minecraft:basalt)
B(-1,114,1,minecraft:basalt)
B(-1,115,1,minecraft:basalt)
B(-1,116,1,minecraft:basalt)
B(-1,108,2,minecraft:basalt)
B(-1,109,2,minecraft:basalt)
B(-1,110,2,minecraft:basalt)
B(-1,111,2,minecraft:basalt)
B(-1,112,2,minecraft:basalt)
B(-1,113,2,minecraft:basalt)
B(-1,114,2,minecraft:basalt)
B(-1,115,2,minecraft:basalt)
B(-1,116,2,minecraft:basalt)
B(-1,107,3,minecraft:basalt)
B(-1,108,3,minecraft:basalt)
B(-1,109,3,minecraft:basalt)
B(-1,110,3,minecraft:basalt)
B(-1,111,3,minecraft:basalt)
B(-1,112,3,minecraft:basalt)
B(-1,113,3,minecraft:basalt)
B(-1,114,3,minecraft:basalt)
B(-1,115,3,minecraft:basalt)
B(-1,116,3,minecraft:basalt)
B(-1,107,4,minecraft:basalt)
B(-1,108,4,minecraft:basalt)
B(-1,109,4,minecraft:basalt)
B(-1,110,4,minecraft:basalt)
B(-1,111,4,minecraft:basalt)
B(-1,112,4,minecraft:basalt)
B(-1,113,4,minecraft:basalt)
B(-1,114,4,minecraft:basalt)
B(-1,115,4,minecraft:basalt)
B(-1,116,4,minecraft:basalt)
B(-1,107,5,minecraft:basalt)
B(-1,108,5,minecraft:basalt)
B(-1,109,5,minecraft:basalt)
B(-1,110,5,minecraft:basalt)
B(-1,111,5,minecraft:basalt)
B(-1,112,5,minecraft:basalt)
B(-1,113,5,minecraft:basalt)
B(-1,114,5,minecraft:basalt)
B(-1,115,5,minecraft:basalt)
B(-1,116,5,minecraft:basalt)
B(-1,107,6,minecraft:basalt)
B(-1,108,6,minecraft:basalt)
B(-1,109,6,minecraft:basalt)
B(-1,110,6,minecraft:basalt)
B(-1,111,6,minecraft:basalt)
B(-1,112,6,minecraft:basalt)
B(-1,113,6,minecraft:basalt)
B(-1,114,6,minecraft:basalt)
B(-1,115,6,minecraft:basalt)
B(-1,116,6,minecraft:basalt)
B(-1,106,7,minecraft:basalt)
B(-1,107,7,minecraft:basalt)
B(-1,108,7,minecraft:basalt)
B(-1,109,7,minecraft:basalt)
B(-1,110,7,minecraft:basalt)
B(-1,111,7,minecraft:basalt)
B(-1,112,7,minecraft:basalt)
B(-1,113,7,minecraft:basalt)
B(-1,114,7,minecraft:basalt)
B(-1,115,7,minecraft:basalt)
B(-1,116,7,minecraft:basalt)
B(-1,106,8,minecraft:basalt)
B(-1,107,8,minecraft:basalt)
B(-1,108,8,minecraft:basalt)
B(-1,109,8,minecraft:basalt)
B(-1,110,8,minecraft:basalt)
B(-1,111,8,minecraft:basalt)
B(-1,112,8,minecraft:basalt)
B(-1,113,8,minecraft:basalt)
B(-1,114,8,minecraft:basalt)
B(-1,115,8,minecraft:basalt)
B(-1,116,8,minecraft:basalt)
B(0,112,-7,minecraft:basalt)
B(0,113,-7,minecraft:basalt)
B(0,114,-7,minecraft:basalt)
B(0,115,-7,minecraft:basalt)
B(0,116,-7,minecraft:basalt)
B(0,111,-6,minecraft:basalt)
B(0,112,-6,minecraft:basalt)
B(0,113,-6,minecraft:basalt)
B(0,114,-6,minecraft:basalt)
B(0,115,-6,minecraft:basalt)
B(0,116,-6,minecraft:basalt)
B(0,111,-5,minecraft:basalt)
B(0,112,-5,minecraft:basalt)
B(0,113,-5,minecraft:basalt)
B(0,114,-5,minecraft:basalt)
B(0,115,-5,minecraft:basalt)
B(0,116,-5,minecraft:basalt)
B(0,111,-4,minecraft:basalt)
B(0,112,-4,minecraft:basalt)
B(0,113,-4,minecraft:basalt)
B(0,114,-4,minecraft:basalt)
B(0,115,-4,minecraft:basalt)
B(0,116,-4,minecraft:basalt)
B(0,110,-3,minecraft:basalt)
B(0,111,-3,minecraft:basalt)
B(0,112,-3,minecraft:basalt)
B(0,113,-3,minecraft:basalt)
B(0,114,-3,minecraft:basalt)
B(0,115,-3,minecraft:basalt)
B(0,116,-3,minecraft:basalt)
B(0,110,-2,minecraft:basalt)
B(0,111,-2,minecraft:basalt)
B(0,112,-2,minecraft:basalt)
B(0,113,-2,minecraft:basalt)
B(0,114,-2,minecraft:basalt)
B(0,115,-2,minecraft:basalt)
B(0,116,-2,minecraft:basalt)
B(0,109,-1,minecraft:basalt)
B(0,110,-1,minecraft:basalt)
B(0,111,-1,minecraft:basalt)
B(0,112,-1,minecraft:basalt)
B(0,113,-1,minecraft:basalt)
B(0,114,-1,minecraft:basalt)
B(0,115,-1,minecraft:basalt)
B(0,116,-1,minecraft:basalt)
B(0,109,0,minecraft:basalt)
B(0,110,0,minecraft:basalt)
B(0,111,0,minecraft:basalt)
B(0,112,0,minecraft:basalt)
B(0,113,0,minecraft:basalt)
B(0,114,0,minecraft:basalt)
B(0,115,0,minecraft:basalt)
B(0,116,0,minecraft:basalt)
B(0,108,1,minecraft:basalt)
B(0,109,1,minecraft:basalt)
B(0,110,1,minecraft:basalt)
B(0,111,1,minecraft:basalt)
B(0,112,1,minecraft:basalt)
B(0,113,1,minecraft:basalt)
B(0,114,1,minecraft:basalt)
B(0,115,1,minecraft:basalt)
B(0,116,1,minecraft:basalt)
B(0,108,2,minecraft:basalt)
B(0,109,2,minecraft:basalt)
B(0,110,2,minecraft:basalt)
B(0,111,2,minecraft:basalt)
B(0,112,2,minecraft:basalt)
B(0,113,2,minecraft:basalt)
B(0,114,2,minecraft:basalt)
B(0,115,2,minecraft:basalt)
B(0,116,2,minecraft:basalt)
B(0,107,3,minecraft:basalt)
B(0,108,3,minecraft:basalt)
B(0,109,3,minecraft:basalt)
B(0,110,3,minecraft:basalt)
B(0,111,3,minecraft:basalt)
B(0,112,3,minecraft:basalt)
B(0,113,3,minecraft:basalt)
B(0,114,3,minecraft:basalt)
B(0,115,3,minecraft:basalt)
B(0,116,3,minecraft:basalt)
B(0,107,4,minecraft:basalt)
B(0,108,4,minecraft:basalt)
B(0,109,4,minecraft:basalt)
B(0,110,4,minecraft:basalt)
B(0,111,4,minecraft:basalt)
B(0,112,4,minecraft:basalt)
B(0,113,4,minecraft:basalt)
B(0,114,4,minecraft:basalt)
B(0,115,4,minecraft:basalt)
B(0,116,4,minecraft:basalt)
B(0,107,5,minecraft:basalt)
B(0,108,5,minecraft:basalt)
B(0,109,5,minecraft:basalt)
B(0,110,5,minecraft:basalt)
B(0,111,5,minecraft:basalt)
B(0,112,5,minecraft:basalt)
B(0,113,5,minecraft:basalt)
B(0,114,5,minecraft:basalt)
B(0,115,5,minecraft:basalt)
B(0,116,5,minecraft:basalt)
B(0,107,6,minecraft:basalt)
B(0,108,6,minecraft:basalt)
B(0,109,6,minecraft:basalt)
B(0,110,6,minecraft:basalt)
B(0,111,6,minecraft:basalt)
B(0,112,6,minecraft:basalt)
B(0,113,6,minecraft:basalt)
B(0,114,6,minecraft:basalt)
B(0,115,6,minecraft:basalt)
B(0,116,6,minecraft:basalt)
B(0,106,7,minecraft:basalt)
B(0,107,7,minecraft:basalt)
B(0,108,7,minecraft:basalt)
B(0,109,7,minecraft:basalt)
B(0,110,7,minecraft:basalt)
B(0,111,7,minecraft:basalt)
B(0,112,7,minecraft:basalt)
B(0,113,7,minecraft:basalt)
B(0,114,7,minecraft:basalt)
B(0,115,7,minecraft:basalt)
B(0,116,7,minecraft:basalt)
B(0,106,8,minecraft:basalt)
B(0,107,8,minecraft:basalt)
B(0,108,8,minecraft:basalt)
B(0,109,8,minecraft:basalt)
B(0,110,8,minecraft:basalt)
B(0,111,8,minecraft:basalt)
B(0,112,8,minecraft:basalt)
B(0,113,8,minecraft:basalt)
B(0,114,8,minecraft:basalt)
B(0,115,8,minecraft:basalt)
B(0,116,8,minecraft:basalt)
B(1,112,-7,minecraft:basalt)
B(1,113,-7,minecraft:basalt)
B(1,114,-7,minecraft:basalt)
B(1,115,-7,minecraft:basalt)
B(1,116,-7,minecraft:basalt)
B(1,111,-6,minecraft:basalt)
B(1,112,-6,minecraft:basalt)
B(1,113,-6,minecraft:basalt)
B(1,114,-6,minecraft:basalt)
B(1,115,-6,minecraft:basalt)
B(1,116,-6,minecraft:basalt)
B(1,111,-5,minecraft:basalt)
B(1,112,-5,minecraft:basalt)
B(1,113,-5,minecraft:basalt)
B(1,114,-5,minecraft:basalt)
B(1,115,-5,minecraft:basalt)
B(1,116,-5,minecraft:basalt)
B(1,110,-4,minecraft:basalt)
B(1,111,-4,minecraft:basalt)
B(1,112,-4,minecraft:basalt)
B(1,113,-4,minecraft:basalt)
B(1,114,-4,minecraft:basalt)
B(1,115,-4,minecraft:basalt)
B(1,116,-4,minecraft:basalt)
B(1,110,-3,minecraft:basalt)
B(1,111,-3,minecraft:basalt)
B(1,112,-3,minecraft:basalt)
B(1,113,-3,minecraft:basalt)
B(1,114,-3,minecraft:basalt)
B(1,115,-3,minecraft:basalt)
B(1,116,-3,minecraft:basalt)
B(1,109,-2,minecraft:basalt)
B(1,110,-2,minecraft:basalt)
B(1,111,-2,minecraft:basalt)
B(1,112,-2,minecraft:basalt)
B(1,113,-2,minecraft:basalt)
B(1,114,-2,minecraft:basalt)
B(1,115,-2,minecraft:basalt)
B(1,116,-2,minecraft:basalt)
B(1,109,-1,minecraft:basalt)
B(1,110,-1,minecraft:basalt)
B(1,111,-1,minecraft:basalt)
B(1,112,-1,minecraft:basalt)
B(1,113,-1,minecraft:basalt)
B(1,114,-1,minecraft:basalt)
B(1,115,-1,minecraft:basalt)
B(1,116,-1,minecraft:basalt)
B(1,108,0,minecraft:basalt)
B(1,109,0,minecraft:basalt)
B(1,110,0,minecraft:basalt)
B(1,111,0,minecraft:basalt)
B(1,112,0,minecraft:basalt)
B(1,113,0,minecraft:basalt)
B(1,114,0,minecraft:basalt)
B(1,115,0,minecraft:basalt)
B(1,116,0,minecraft:basalt)
B(1,108,1,minecraft:basalt)
B(1,109,1,minecraft:basalt)
B(1,110,1,minecraft:basalt)
B(1,111,1,minecraft:basalt)
B(1,112,1,minecraft:basalt)
B(1,113,1,minecraft:basalt)
B(1,114,1,minecraft:basalt)
B(1,115,1,minecraft:basalt)
B(1,116,1,minecraft:basalt)
B(1,108,2,minecraft:basalt)
B(1,109,2,minecraft:basalt)
B(1,110,2,minecraft:basalt)
B(1,111,2,minecraft:basalt)
B(1,112,2,minecraft:basalt)
B(1,113,2,minecraft:basalt)
B(1,114,2,minecraft:basalt)
B(1,115,2,minecraft:basalt)
B(1,116,2,minecraft:basalt)
B(1,107,3,minecraft:basalt)
B(1,108,3,minecraft:basalt)
B(1,109,3,minecraft:basalt)
B(1,110,3,minecraft:basalt)
B(1,111,3,minecraft:basalt)
B(1,112,3,minecraft:basalt)
B(1,113,3,minecraft:basalt)
B(1,114,3,minecraft:basalt)
B(1,115,3,minecraft:basalt)
B(1,116,3,minecraft:basalt)
B(1,107,4,minecraft:basalt)
B(1,108,4,minecraft:basalt)
B(1,109,4,minecraft:basalt)
B(1,110,4,minecraft:basalt)
B(1,111,4,minecraft:basalt)
B(1,112,4,minecraft:basalt)
B(1,113,4,minecraft:basalt)
B(1,114,4,minecraft:basalt)
B(1,115,4,minecraft:basalt)
B(1,116,4,minecraft:basalt)
B(1,107,5,minecraft:basalt)
B(1,108,5,minecraft:basalt)
B(1,109,5,minecraft:basalt)
B(1,110,5,minecraft:basalt)
B(1,111,5,minecraft:basalt)
B(1,112,5,minecraft:basalt)
B(1,113,5,minecraft:basalt)
B(1,114,5,minecraft:basalt)
B(1,115,5,minecraft:basalt)
B(1,116,5,minecraft:basalt)
B(1,107,6,minecraft:basalt)
B(1,108,6,minecraft:basalt)
B(1,109,6,minecraft:basalt)
B(1,110,6,minecraft:basalt)
B(1,111,6,minecraft:basalt)
B(1,112,6,minecraft:basalt)
B(1,113,6,minecraft:basalt)
B(1,114,6,minecraft:basalt)
B(1,115,6,minecraft:basalt)
B(1,116,6,minecraft:basalt)
B(1,106,7,minecraft:basalt)
B(1,107,7,minecraft:basalt)
B(1,108,7,minecraft:basalt)
B(1,109,7,minecraft:basalt)
B(1,110,7,minecraft:basalt)
B(1,111,7,minecraft:basalt)
B(1,112,7,minecraft:basalt)
B(1,113,7,minecraft:basalt)
B(1,114,7,minecraft:basalt)
B(1,115,7,minecraft:basalt)
B(1,116,7,minecraft:basalt)
B(1,106,8,minecraft:basalt)
B(1,107,8,minecraft:basalt)
B(1,108,8,minecraft:basalt)
B(1,109,8,minecraft:basalt)
B(1,110,8,minecraft:basalt)
B(1,111,8,minecraft:basalt)
B(1,112,8,minecraft:basalt)
B(1,113,8,minecraft:basalt)
B(1,114,8,minecraft:basalt)
B(1,115,8,minecraft:basalt)
B(1,116,8,minecraft:basalt)
B(2,0,-7,minecraft:basalt)
B(2,109,-7,minecraft:basalt)
B(2,110,-7,minecraft:basalt)
B(2,111,-7,minecraft:basalt)
B(2,112,-7,minecraft:basalt)
B(2,113,-7,minecraft:basalt)
B(2,114,-7,minecraft:basalt)
B(2,115,-7,minecraft:basalt)
B(2,116,-7,minecraft:basalt)
B(2,0,-6,minecraft:basalt)
B(2,109,-6,minecraft:basalt)
B(2,110,-6,minecraft:basalt)
B(2,111,-6,minecraft:basalt)
B(2,112,-6,minecraft:basalt)
B(2,113,-6,minecraft:basalt)
B(2,114,-6,minecraft:basalt)
B(2,115,-6,minecraft:basalt)
B(2,116,-6,minecraft:basalt)
B(2,0,-5,minecraft:basalt)
B(2,109,-5,minecraft:basalt)
B(2,110,-5,minecraft:basalt)
B(2,111,-5,minecraft:basalt)
B(2,112,-5,minecraft:basalt)
B(2,113,-5,minecraft:basalt)
B(2,114,-5,minecraft:basalt)
B(2,115,-5,minecraft:basalt)
B(2,116,-5,minecraft:basalt)
B(2,0,-4,minecraft:basalt)
B(2,108,-4,minecraft:basalt)
B(2,109,-4,minecraft:basalt)
B(2,110,-4,minecraft:basalt)
B(2,111,-4,minecraft:basalt)
B(2,112,-4,minecraft:basalt)
B(2,113,-4,minecraft:basalt)
B(2,114,-4,minecraft:basalt)
B(2,115,-4,minecraft:basalt)
B(2,116,-4,minecraft:basalt)
B(2,108,-3,minecraft:basalt)
B(2,109,-3,minecraft:basalt)
B(2,110,-3,minecraft:basalt)
B(2,111,-3,minecraft:basalt)
B(2,112,-3,minecraft:basalt)
B(2,113,-3,minecraft:basalt)
B(2,114,-3,minecraft:basalt)
B(2,115,-3,minecraft:basalt)
B(2,116,-3,minecraft:basalt)
B(2,108,-2,minecraft:basalt)
B(2,109,-2,minecraft:basalt)
B(2,110,-2,minecraft:basalt)
B(2,111,-2,minecraft:basalt)
B(2,112,-2,minecraft:basalt)
B(2,113,-2,minecraft:basalt)
B(2,114,-2,minecraft:basalt)
B(2,115,-2,minecraft:basalt)
B(2,116,-2,minecraft:basalt)
B(2,108,-1,minecraft:basalt)
B(2,109,-1,minecraft:basalt)
B(2,110,-1,minecraft:basalt)
B(2,111,-1,minecraft:basalt)
B(2,112,-1,minecraft:basalt)
B(2,113,-1,minecraft:basalt)
B(2,114,-1,minecraft:basalt)
B(2,115,-1,minecraft:basalt)
B(2,116,-1,minecraft:basalt)
B(2,108,0,minecraft:basalt)
B(2,109,0,minecraft:basalt)
B(2,110,0,minecraft:basalt)
B(2,111,0,minecraft:basalt)
B(2,112,0,minecraft:basalt)
B(2,113,0,minecraft:basalt)
B(2,114,0,minecraft:basalt)
B(2,115,0,minecraft:basalt)
B(2,116,0,minecraft:basalt)
B(2,108,1,minecraft:basalt)
B(2,109,1,minecraft:basalt)
B(2,110,1,minecraft:basalt)
B(2,111,1,minecraft:basalt)
B(2,112,1,minecraft:basalt)
B(2,113,1,minecraft:basalt)
B(2,114,1,minecraft:basalt)
B(2,115,1,minecraft:basalt)
B(2,116,1,minecraft:basalt)
B(2,108,2,minecraft:basalt)
B(2,109,2,minecraft:basalt)
B(2,110,2,minecraft:basalt)
B(2,111,2,minecraft:basalt)
B(2,112,2,minecraft:basalt)
B(2,113,2,minecraft:basalt)
B(2,114,2,minecraft:basalt)
B(2,115,2,minecraft:basalt)
B(2,116,2,minecraft:basalt)
B(2,107,3,minecraft:basalt)
B(2,108,3,minecraft:basalt)
B(2,109,3,minecraft:basalt)
B(2,110,3,minecraft:basalt)
B(2,111,3,minecraft:basalt)
B(2,112,3,minecraft:basalt)
B(2,113,3,minecraft:basalt)
B(2,114,3,minecraft:basalt)
B(2,115,3,minecraft:basalt)
B(2,116,3,minecraft:basalt)
B(2,107,4,minecraft:basalt)
B(2,108,4,minecraft:basalt)
B(2,109,4,minecraft:basalt)
B(2,110,4,minecraft:basalt)
B(2,111,4,minecraft:basalt)
B(2,112,4,minecraft:basalt)
B(2,113,4,minecraft:basalt)
B(2,114,4,minecraft:basalt)
B(2,115,4,minecraft:basalt)
B(2,116,4,minecraft:basalt)
B(2,107,5,minecraft:basalt)
B(2,108,5,minecraft:basalt)
B(2,109,5,minecraft:basalt)
B(2,110,5,minecraft:basalt)
B(2,111,5,minecraft:basalt)
B(2,112,5,minecraft:basalt)
B(2,113,5,minecraft:basalt)
B(2,114,5,minecraft:basalt)
B(2,115,5,minecraft:basalt)
B(2,116,5,minecraft:basalt)
B(2,107,6,minecraft:basalt)
B(2,108,6,minecraft:basalt)
B(2,109,6,minecraft:basalt)
B(2,110,6,minecraft:basalt)
B(2,111,6,minecraft:basalt)
B(2,112,6,minecraft:basalt)
B(2,113,6,minecraft:basalt)
B(2,114,6,minecraft:basalt)
B(2,115,6,minecraft:basalt)
B(2,116,6,minecraft:basalt)
B(2,106,7,minecraft:basalt)
B(2,107,7,minecraft:basalt)
B(2,108,7,minecraft:basalt)
B(2,109,7,minecraft:basalt)
B(2,110,7,minecraft:basalt)
B(2,111,7,minecraft:basalt)
B(2,112,7,minecraft:basalt)
B(2,113,7,minecraft:basalt)
B(2,114,7,minecraft:basalt)
B(2,115,7,minecraft:basalt)
B(2,116,7,minecraft:basalt)
B(2,106,8,minecraft:basalt)
B(2,107,8,minecraft:basalt)
B(2,108,8,minecraft:basalt)
B(2,109,8,minecraft:basalt)
B(2,110,8,minecraft:basalt)
B(2,111,8,minecraft:basalt)
B(2,112,8,minecraft:basalt)
B(2,113,8,minecraft:basalt)
B(2,114,8,minecraft:basalt)
B(2,115,8,minecraft:basalt)
B(2,116,8,minecraft:basalt)
B(3,0,-7,minecraft:basalt)
B(3,1,-7,minecraft:basalt)
B(3,107,-7,minecraft:basalt)
B(3,108,-7,minecraft:basalt)
B(3,109,-7,minecraft:basalt)
B(3,110,-7,minecraft:basalt)
B(3,111,-7,minecraft:basalt)
B(3,112,-7,minecraft:basalt)
B(3,113,-7,minecraft:basalt)
B(3,114,-7,minecraft:basalt)
B(3,115,-7,minecraft:basalt)
B(3,116,-7,minecraft:basalt)
B(3,0,-6,minecraft:basalt)
B(3,1,-6,minecraft:basalt)
B(3,107,-6,minecraft:basalt)
B(3,108,-6,minecraft:basalt)
B(3,109,-6,minecraft:basalt)
B(3,110,-6,minecraft:basalt)
B(3,111,-6,minecraft:basalt)
B(3,112,-6,minecraft:basalt)
B(3,113,-6,minecraft:basalt)
B(3,114,-6,minecraft:basalt)
B(3,115,-6,minecraft:basalt)
B(3,116,-6,minecraft:basalt)
B(3,0,-5,minecraft:basalt)
B(3,1,-5,minecraft:basalt)
B(3,107,-5,minecraft:basalt)
B(3,108,-5,minecraft:basalt)
B(3,109,-5,minecraft:basalt)
B(3,110,-5,minecraft:basalt)
B(3,111,-5,minecraft:basalt)
B(3,112,-5,minecraft:basalt)
B(3,113,-5,minecraft:basalt)
B(3,114,-5,minecraft:basalt)
B(3,115,-5,minecraft:basalt)
B(3,116,-5,minecraft:basalt)
B(3,0,-4,minecraft:basalt)
B(3,107,-4,minecraft:basalt)
B(3,108,-4,minecraft:basalt)
B(3,109,-4,minecraft:basalt)
B(3,110,-4,minecraft:basalt)
B(3,111,-4,minecraft:basalt)
B(3,112,-4,minecraft:basalt)
B(3,113,-4,minecraft:basalt)
B(3,114,-4,minecraft:basalt)
B(3,115,-4,minecraft:basalt)
B(3,116,-4,minecraft:basalt)
B(3,0,-3,minecraft:basalt)
B(3,107,-3,minecraft:basalt)
B(3,108,-3,minecraft:basalt)
B(3,109,-3,minecraft:basalt)
B(3,110,-3,minecraft:basalt)
B(3,111,-3,minecraft:basalt)
B(3,112,-3,minecraft:basalt)
B(3,113,-3,minecraft:basalt)
B(3,114,-3,minecraft:basalt)
B(3,115,-3,minecraft:basalt)
B(3,116,-3,minecraft:basalt)
B(3,0,-2,minecraft:basalt)
B(3,107,-2,minecraft:basalt)
B(3,108,-2,minecraft:basalt)
B(3,109,-2,minecraft:basalt)
B(3,110,-2,minecraft:basalt)
B(3,111,-2,minecraft:basalt)
B(3,112,-2,minecraft:basalt)
B(3,113,-2,minecraft:basalt)
B(3,114,-2,minecraft:basalt)
B(3,115,-2,minecraft:basalt)
B(3,116,-2,minecraft:basalt)
B(3,108,-1,minecraft:basalt)
B(3,109,-1,minecraft:basalt)
B(3,110,-1,minecraft:basalt)
B(3,111,-1,minecraft:basalt)
B(3,112,-1,minecraft:basalt)
B(3,113,-1,minecraft:basalt)
B(3,114,-1,minecraft:basalt)
B(3,115,-1,minecraft:basalt)
B(3,116,-1,minecraft:basalt)
B(3,108,0,minecraft:basalt)
B(3,109,0,minecraft:basalt)
B(3,110,0,minecraft:basalt)
B(3,111,0,minecraft:basalt)
B(3,112,0,minecraft:basalt)
B(3,113,0,minecraft:basalt)
B(3,114,0,minecraft:basalt)
B(3,115,0,minecraft:basalt)
B(3,116,0,minecraft:basalt)
B(3,108,1,minecraft:basalt)
B(3,109,1,minecraft:basalt)
B(3,110,1,minecraft:basalt)
B(3,111,1,minecraft:basalt)
B(3,112,1,minecraft:basalt)
B(3,113,1,minecraft:basalt)
B(3,114,1,minecraft:basalt)
B(3,115,1,minecraft:basalt)
B(3,116,1,minecraft:basalt)
B(3,107,2,minecraft:basalt)
B(3,108,2,minecraft:basalt)
B(3,109,2,minecraft:basalt)
B(3,110,2,minecraft:basalt)
B(3,111,2,minecraft:basalt)
B(3,112,2,minecraft:basalt)
B(3,113,2,minecraft:basalt)
B(3,114,2,minecraft:basalt)
B(3,115,2,minecraft:basalt)
B(3,116,2,minecraft:basalt)
B(3,107,3,minecraft:basalt)
B(3,108,3,minecraft:basalt)
B(3,109,3,minecraft:basalt)
B(3,110,3,minecraft:basalt)
B(3,111,3,minecraft:basalt)
B(3,112,3,minecraft:basalt)
B(3,113,3,minecraft:basalt)
B(3,114,3,minecraft:basalt)
B(3,115,3,minecraft:basalt)
B(3,116,3,minecraft:basalt)
B(3,107,4,minecraft:basalt)
B(3,108,4,minecraft:basalt)
B(3,109,4,minecraft:basalt)
B(3,110,4,minecraft:basalt)
B(3,111,4,minecraft:basalt)
B(3,112,4,minecraft:basalt)
B(3,113,4,minecraft:basalt)
B(3,114,4,minecraft:basalt)
B(3,115,4,minecraft:basalt)
B(3,116,4,minecraft:basalt)
B(3,107,5,minecraft:basalt)
B(3,108,5,minecraft:basalt)
B(3,109,5,minecraft:basalt)
B(3,110,5,minecraft:basalt)
B(3,111,5,minecraft:basalt)
B(3,112,5,minecraft:basalt)
B(3,113,5,minecraft:basalt)
B(3,114,5,minecraft:basalt)
B(3,115,5,minecraft:basalt)
B(3,116,5,minecraft:basalt)
B(3,107,6,minecraft:basalt)
B(3,108,6,minecraft:basalt)
B(3,109,6,minecraft:basalt)
B(3,110,6,minecraft:basalt)
B(3,111,6,minecraft:basalt)
B(3,112,6,minecraft:basalt)
B(3,113,6,minecraft:basalt)
B(3,114,6,minecraft:basalt)
B(3,115,6,minecraft:basalt)
B(3,116,6,minecraft:basalt)
B(3,107,7,minecraft:basalt)
B(3,108,7,minecraft:basalt)
B(3,109,7,minecraft:basalt)
B(3,110,7,minecraft:basalt)
B(3,111,7,minecraft:basalt)
B(3,112,7,minecraft:basalt)
B(3,113,7,minecraft:basalt)
B(3,114,7,minecraft:basalt)
B(3,115,7,minecraft:basalt)
B(3,116,7,minecraft:basalt)
B(3,107,8,minecraft:basalt)
B(3,108,8,minecraft:basalt)
B(3,109,8,minecraft:basalt)
B(3,110,8,minecraft:basalt)
B(3,111,8,minecraft:basalt)
B(3,112,8,minecraft:basalt)
B(3,113,8,minecraft:basalt)
B(3,114,8,minecraft:basalt)
B(3,115,8,minecraft:basalt)
B(3,116,8,minecraft:basalt)
B(4,0,-7,minecraft:basalt)
B(4,1,-7,minecraft:basalt)
B(4,2,-7,minecraft:basalt)
B(4,105,-7,minecraft:basalt)
B(4,106,-7,minecraft:basalt)
B(4,107,-7,minecraft:basalt)
B(4,108,-7,minecraft:basalt)
B(4,109,-7,minecraft:basalt)
B(4,110,-7,minecraft:basalt)
B(4,111,-7,minecraft:basalt)
B(4,112,-7,minecraft:basalt)
B(4,113,-7,minecraft:basalt)
B(4,114,-7,minecraft:basalt)
B(4,115,-7,minecraft:basalt)
B(4,116,-7,minecraft:basalt)
B(4,0,-6,minecraft:basalt)
B(4,1,-6,minecraft:basalt)
B(4,2,-6,minecraft:basalt)
B(4,105,-6,minecraft:basalt)
B(4,106,-6,minecraft:basalt)
B(4,107,-6,minecraft:basalt)
B(4,108,-6,minecraft:basalt)
B(4,109,-6,minecraft:basalt)
B(4,110,-6,minecraft:basalt)
B(4,111,-6,minecraft:basalt)
B(4,112,-6,minecraft:basalt)
B(4,113,-6,minecraft:basalt)
B(4,114,-6,minecraft:basalt)
B(4,115,-6,minecraft:basalt)
B(4,116,-6,minecraft:basalt)
B(4,0,-5,minecraft:basalt)
B(4,1,-5,minecraft:basalt)
B(4,105,-5,minecraft:basalt)
B(4,106,-5,minecraft:basalt)
B(4,107,-5,minecraft:basalt)
B(4,108,-5,minecraft:basalt)
B(4,109,-5,minecraft:basalt)
B(4,110,-5,minecraft:basalt)
B(4,111,-5,minecraft:basalt)
B(4,112,-5,minecraft:basalt)
B(4,113,-5,minecraft:basalt)
B(4,114,-5,minecraft:basalt)
B(4,115,-5,minecraft:basalt)
B(4,116,-5,minecraft:basalt)
B(4,0,-4,minecraft:basalt)
B(4,1,-4,minecraft:basalt)
B(4,105,-4,minecraft:basalt)
B(4,106,-4,minecraft:basalt)
B(4,107,-4,minecraft:basalt)
B(4,108,-4,minecraft:basalt)
B(4,109,-4,minecraft:basalt)
B(4,110,-4,minecraft:basalt)
B(4,111,-4,minecraft:basalt)
B(4,112,-4,minecraft:basalt)
B(4,113,-4,minecraft:basalt)
B(4,114,-4,minecraft:basalt)
B(4,115,-4,minecraft:basalt)
B(4,116,-4,minecraft:basalt)
B(4,0,-3,minecraft:basalt)
B(4,1,-3,minecraft:basalt)
B(4,106,-3,minecraft:basalt)
B(4,107,-3,minecraft:basalt)
B(4,108,-3,minecraft:basalt)
B(4,109,-3,minecraft:basalt)
B(4,110,-3,minecraft:basalt)
B(4,111,-3,minecraft:basalt)
B(4,112,-3,minecraft:basalt)
B(4,113,-3,minecraft:basalt)
B(4,114,-3,minecraft:basalt)
B(4,115,-3,minecraft:basalt)
B(4,116,-3,minecraft:basalt)
B(4,0,-2,minecraft:basalt)
B(4,107,-2,minecraft:basalt)
B(4,108,-2,minecraft:basalt)
B(4,109,-2,minecraft:basalt)
B(4,110,-2,minecraft:basalt)
B(4,111,-2,minecraft:basalt)
B(4,112,-2,minecraft:basalt)
B(4,113,-2,minecraft:basalt)
B(4,114,-2,minecraft:basalt)
B(4,115,-2,minecraft:basalt)
B(4,116,-2,minecraft:basalt)
B(4,0,-1,minecraft:basalt)
B(4,108,-1,minecraft:basalt)
B(4,109,-1,minecraft:basalt)
B(4,110,-1,minecraft:basalt)
B(4,111,-1,minecraft:basalt)
B(4,112,-1,minecraft:basalt)
B(4,113,-1,minecraft:basalt)
B(4,114,-1,minecraft:basalt)
B(4,115,-1,minecraft:basalt)
B(4,116,-1,minecraft:basalt)
B(4,108,0,minecraft:basalt)
B(4,109,0,minecraft:basalt)
B(4,110,0,minecraft:basalt)
B(4,111,0,minecraft:basalt)
B(4,112,0,minecraft:basalt)
B(4,113,0,minecraft:basalt)
B(4,114,0,minecraft:basalt)
B(4,115,0,minecraft:basalt)
B(4,116,0,minecraft:basalt)
B(4,108,1,minecraft:basalt)
B(4,109,1,minecraft:basalt)
B(4,110,1,minecraft:basalt)
B(4,111,1,minecraft:basalt)
B(4,112,1,minecraft:basalt)
B(4,113,1,minecraft:basalt)
B(4,114,1,minecraft:basalt)
B(4,115,1,minecraft:basalt)
B(4,116,1,minecraft:basalt)
B(4,107,2,minecraft:basalt)
B(4,108,2,minecraft:basalt)
B(4,109,2,minecraft:basalt)
B(4,110,2,minecraft:basalt)
B(4,111,2,minecraft:basalt)
B(4,112,2,minecraft:basalt)
B(4,113,2,minecraft:basalt)
B(4,114,2,minecraft:basalt)
B(4,115,2,minecraft:basalt)
B(4,116,2,minecraft:basalt)
B(4,107,3,minecraft:basalt)
B(4,108,3,minecraft:basalt)
B(4,109,3,minecraft:basalt)
B(4,110,3,minecraft:basalt)
B(4,111,3,minecraft:basalt)
B(4,112,3,minecraft:basalt)
B(4,113,3,minecraft:basalt)
B(4,114,3,minecraft:basalt)
B(4,115,3,minecraft:basalt)
B(4,116,3,minecraft:basalt)
B(4,106,4,minecraft:basalt)
B(4,107,4,minecraft:basalt)
B(4,108,4,minecraft:basalt)
B(4,109,4,minecraft:basalt)
B(4,110,4,minecraft:basalt)
B(4,111,4,minecraft:basalt)
B(4,112,4,minecraft:basalt)
B(4,113,4,minecraft:basalt)
B(4,114,4,minecraft:basalt)
B(4,115,4,minecraft:basalt)
B(4,116,4,minecraft:basalt)
B(4,106,5,minecraft:basalt)
B(4,107,5,minecraft:basalt)
B(4,108,5,minecraft:basalt)
B(4,109,5,minecraft:basalt)
B(4,110,5,minecraft:basalt)
B(4,111,5,minecraft:basalt)
B(4,112,5,minecraft:basalt)
B(4,113,5,minecraft:basalt)
B(4,114,5,minecraft:basalt)
B(4,115,5,minecraft:basalt)
B(4,116,5,minecraft:basalt)
B(4,107,6,minecraft:basalt)
B(4,108,6,minecraft:basalt)
B(4,109,6,minecraft:basalt)
B(4,110,6,minecraft:basalt)
B(4,111,6,minecraft:basalt)
B(4,112,6,minecraft:basalt)
B(4,113,6,minecraft:basalt)
B(4,114,6,minecraft:basalt)
B(4,115,6,minecraft:basalt)
B(4,116,6,minecraft:basalt)
B(4,107,7,minecraft:basalt)
B(4,108,7,minecraft:basalt)
B(4,109,7,minecraft:basalt)
B(4,110,7,minecraft:basalt)
B(4,111,7,minecraft:basalt)
B(4,112,7,minecraft:basalt)
B(4,113,7,minecraft:basalt)
B(4,114,7,minecraft:basalt)
B(4,115,7,minecraft:basalt)
B(4,116,7,minecraft:basalt)
B(4,107,8,minecraft:basalt)
B(4,108,8,minecraft:basalt)
B(4,109,8,minecraft:basalt)
B(4,110,8,minecraft:basalt)
B(4,111,8,minecraft:basalt)
B(4,112,8,minecraft:basalt)
B(4,113,8,minecraft:basalt)
B(4,114,8,minecraft:basalt)
B(4,115,8,minecraft:basalt)
B(4,116,8,minecraft:basalt)
B(5,0,-7,minecraft:basalt)
B(5,1,-7,minecraft:basalt)
B(5,2,-7,minecraft:basalt)
B(5,102,-7,minecraft:basalt)
B(5,103,-7,minecraft:basalt)
B(5,104,-7,minecraft:basalt)
B(5,105,-7,minecraft:basalt)
B(5,106,-7,minecraft:basalt)
B(5,107,-7,minecraft:basalt)
B(5,108,-7,minecraft:basalt)
B(5,109,-7,minecraft:basalt)
B(5,110,-7,minecraft:basalt)
B(5,111,-7,minecraft:basalt)
B(5,112,-7,minecraft:basalt)
B(5,113,-7,minecraft:basalt)
B(5,114,-7,minecraft:basalt)
B(5,115,-7,minecraft:basalt)
B(5,116,-7,minecraft:basalt)
B(5,0,-6,minecraft:basalt)
B(5,1,-6,minecraft:basalt)
B(5,2,-6,minecraft:basalt)
B(5,102,-6,minecraft:basalt)
B(5,103,-6,minecraft:basalt)
B(5,104,-6,minecraft:basalt)
B(5,105,-6,minecraft:basalt)
B(5,106,-6,minecraft:basalt)
B(5,107,-6,minecraft:basalt)
B(5,108,-6,minecraft:basalt)
B(5,109,-6,minecraft:basalt)
B(5,110,-6,minecraft:basalt)
B(5,111,-6,minecraft:basalt)
B(5,112,-6,minecraft:basalt)
B(5,113,-6,minecraft:basalt)
B(5,114,-6,minecraft:basalt)
B(5,115,-6,minecraft:basalt)
B(5,116,-6,minecraft:basalt)
B(5,0,-5,minecraft:basalt)
B(5,1,-5,minecraft:basalt)
B(5,2,-5,minecraft:basalt)
B(5,103,-5,minecraft:basalt)
B(5,104,-5,minecraft:basalt)
B(5,105,-5,minecraft:basalt)
B(5,106,-5,minecraft:basalt)
B(5,107,-5,minecraft:basalt)
B(5,108,-5,minecraft:basalt)
B(5,109,-5,minecraft:basalt)
B(5,110,-5,minecraft:basalt)
B(5,111,-5,minecraft:basalt)
B(5,112,-5,minecraft:basalt)
B(5,113,-5,minecraft:basalt)
B(5,114,-5,minecraft:basalt)
B(5,115,-5,minecraft:basalt)
B(5,116,-5,minecraft:basalt)
B(5,0,-4,minecraft:basalt)
B(5,1,-4,minecraft:basalt)
B(5,2,-4,minecraft:basalt)
B(5,103,-4,minecraft:basalt)
B(5,104,-4,minecraft:basalt)
B(5,105,-4,minecraft:basalt)
B(5,106,-4,minecraft:basalt)
B(5,107,-4,minecraft:basalt)
B(5,108,-4,minecraft:basalt)
B(5,109,-4,minecraft:basalt)
B(5,110,-4,minecraft:basalt)
B(5,111,-4,minecraft:basalt)
B(5,112,-4,minecraft:basalt)
B(5,113,-4,minecraft:basalt)
B(5,114,-4,minecraft:basalt)
B(5,115,-4,minecraft:basalt)
B(5,116,-4,minecraft:basalt)
B(5,0,-3,minecraft:basalt)
B(5,1,-3,minecraft:basalt)
B(5,104,-3,minecraft:basalt)
B(5,105,-3,minecraft:basalt)
B(5,106,-3,minecraft:basalt)
B(5,107,-3,minecraft:basalt)
B(5,108,-3,minecraft:basalt)
B(5,109,-3,minecraft:basalt)
B(5,110,-3,minecraft:basalt)
B(5,111,-3,minecraft:basalt)
B(5,112,-3,minecraft:basalt)
B(5,113,-3,minecraft:basalt)
B(5,114,-3,minecraft:basalt)
B(5,115,-3,minecraft:basalt)
B(5,116,-3,minecraft:basalt)
B(5,0,-2,minecraft:basalt)
B(5,1,-2,minecraft:basalt)
B(5,106,-2,minecraft:basalt)
B(5,107,-2,minecraft:basalt)
B(5,108,-2,minecraft:basalt)
B(5,109,-2,minecraft:basalt)
B(5,110,-2,minecraft:basalt)
B(5,111,-2,minecraft:basalt)
B(5,112,-2,minecraft:basalt)
B(5,113,-2,minecraft:basalt)
B(5,114,-2,minecraft:basalt)
B(5,115,-2,minecraft:basalt)
B(5,116,-2,minecraft:basalt)
B(5,0,-1,minecraft:basalt)
B(5,1,-1,minecraft:basalt)
B(5,107,-1,minecraft:basalt)
B(5,108,-1,minecraft:basalt)
B(5,109,-1,minecraft:basalt)
B(5,110,-1,minecraft:basalt)
B(5,111,-1,minecraft:basalt)
B(5,112,-1,minecraft:basalt)
B(5,113,-1,minecraft:basalt)
B(5,114,-1,minecraft:basalt)
B(5,115,-1,minecraft:basalt)
B(5,116,-1,minecraft:basalt)
B(5,0,0,minecraft:basalt)
B(5,109,0,minecraft:basalt)
B(5,110,0,minecraft:basalt)
B(5,111,0,minecraft:basalt)
B(5,112,0,minecraft:basalt)
B(5,113,0,minecraft:basalt)
B(5,114,0,minecraft:basalt)
B(5,115,0,minecraft:basalt)
B(5,116,0,minecraft:basalt)
B(5,108,1,minecraft:basalt)
B(5,109,1,minecraft:basalt)
B(5,110,1,minecraft:basalt)
B(5,111,1,minecraft:basalt)
B(5,112,1,minecraft:basalt)
B(5,113,1,minecraft:basalt)
B(5,114,1,minecraft:basalt)
B(5,115,1,minecraft:basalt)
B(5,116,1,minecraft:basalt)
B(5,107,2,minecraft:basalt)
B(5,108,2,minecraft:basalt)
B(5,109,2,minecraft:basalt)
B(5,110,2,minecraft:basalt)
B(5,111,2,minecraft:basalt)
B(5,112,2,minecraft:basalt)
B(5,113,2,minecraft:basalt)
B(5,114,2,minecraft:basalt)
B(5,115,2,minecraft:basalt)
B(5,116,2,minecraft:basalt)
B(5,107,3,minecraft:basalt)
B(5,108,3,minecraft:basalt)
B(5,109,3,minecraft:basalt)
B(5,110,3,minecraft:basalt)
B(5,111,3,minecraft:basalt)
B(5,112,3,minecraft:basalt)
B(5,113,3,minecraft:basalt)
B(5,114,3,minecraft:basalt)
B(5,115,3,minecraft:basalt)
B(5,116,3,minecraft:basalt)
B(5,106,4,minecraft:basalt)
B(5,107,4,minecraft:basalt)
B(5,108,4,minecraft:basalt)
B(5,109,4,minecraft:basalt)
B(5,110,4,minecraft:basalt)
B(5,111,4,minecraft:basalt)
B(5,112,4,minecraft:basalt)
B(5,113,4,minecraft:basalt)
B(5,114,4,minecraft:basalt)
B(5,115,4,minecraft:basalt)
B(5,116,4,minecraft:basalt)
B(5,106,5,minecraft:basalt)
B(5,107,5,minecraft:basalt)
B(5,108,5,minecraft:basalt)
B(5,109,5,minecraft:basalt)
B(5,110,5,minecraft:basalt)
B(5,111,5,minecraft:basalt)
B(5,112,5,minecraft:basalt)
B(5,113,5,minecraft:basalt)
B(5,114,5,minecraft:basalt)
B(5,115,5,minecraft:basalt)
B(5,116,5,minecraft:basalt)
B(5,107,6,minecraft:basalt)
B(5,108,6,minecraft:basalt)
B(5,109,6,minecraft:basalt)
B(5,110,6,minecraft:basalt)
B(5,111,6,minecraft:basalt)
B(5,112,6,minecraft:basalt)
B(5,113,6,minecraft:basalt)
B(5,114,6,minecraft:basalt)
B(5,115,6,minecraft:basalt)
B(5,116,6,minecraft:basalt)
B(5,107,7,minecraft:basalt)
B(5,108,7,minecraft:basalt)
B(5,109,7,minecraft:basalt)
B(5,110,7,minecraft:basalt)
B(5,111,7,minecraft:basalt)
B(5,112,7,minecraft:basalt)
B(5,113,7,minecraft:basalt)
B(5,114,7,minecraft:basalt)
B(5,115,7,minecraft:basalt)
B(5,116,7,minecraft:basalt)
B(5,107,8,minecraft:basalt)
B(5,108,8,minecraft:basalt)
B(5,109,8,minecraft:basalt)
B(5,110,8,minecraft:basalt)
B(5,111,8,minecraft:basalt)
B(5,112,8,minecraft:basalt)
B(5,113,8,minecraft:basalt)
B(5,114,8,minecraft:basalt)
B(5,115,8,minecraft:basalt)
B(5,116,8,minecraft:basalt)
B(6,0,-7,minecraft:basalt)
B(6,1,-7,minecraft:basalt)
B(6,2,-7,minecraft:basalt)
B(6,102,-7,minecraft:basalt)
B(6,103,-7,minecraft:basalt)
B(6,104,-7,minecraft:basalt)
B(6,105,-7,minecraft:basalt)
B(6,106,-7,minecraft:basalt)
B(6,107,-7,minecraft:basalt)
B(6,108,-7,minecraft:basalt)
B(6,109,-7,minecraft:basalt)
B(6,110,-7,minecraft:basalt)
B(6,111,-7,minecraft:basalt)
B(6,112,-7,minecraft:basalt)
B(6,113,-7,minecraft:basalt)
B(6,114,-7,minecraft:basalt)
B(6,115,-7,minecraft:basalt)
B(6,116,-7,minecraft:basalt)
B(6,0,-6,minecraft:basalt)
B(6,1,-6,minecraft:basalt)
B(6,2,-6,minecraft:basalt)
B(6,102,-6,minecraft:basalt)
B(6,103,-6,minecraft:basalt)
B(6,104,-6,minecraft:basalt)
B(6,105,-6,minecraft:basalt)
B(6,106,-6,minecraft:basalt)
B(6,107,-6,minecraft:basalt)
B(6,108,-6,minecraft:basalt)
B(6,109,-6,minecraft:basalt)
B(6,110,-6,minecraft:basalt)
B(6,111,-6,minecraft:basalt)
B(6,112,-6,minecraft:basalt)
B(6,113,-6,minecraft:basalt)
B(6,114,-6,minecraft:basalt)
B(6,115,-6,minecraft:basalt)
B(6,116,-6,minecraft:basalt)
B(6,0,-5,minecraft:basalt)
B(6,1,-5,minecraft:basalt)
B(6,2,-5,minecraft:basalt)
B(6,102,-5,minecraft:basalt)
B(6,103,-5,minecraft:basalt)
B(6,104,-5,minecraft:basalt)
B(6,105,-5,minecraft:basalt)
B(6,106,-5,minecraft:basalt)
B(6,107,-5,minecraft:basalt)
B(6,108,-5,minecraft:basalt)
B(6,109,-5,minecraft:basalt)
B(6,110,-5,minecraft:basalt)
B(6,111,-5,minecraft:basalt)
B(6,112,-5,minecraft:basalt)
B(6,113,-5,minecraft:basalt)
B(6,114,-5,minecraft:basalt)
B(6,115,-5,minecraft:basalt)
B(6,116,-5,minecraft:basalt)
B(6,0,-4,minecraft:basalt)
B(6,1,-4,minecraft:basalt)
B(6,2,-4,minecraft:basalt)
B(6,103,-4,minecraft:basalt)
B(6,104,-4,minecraft:basalt)
B(6,105,-4,minecraft:basalt)
B(6,106,-4,minecraft:basalt)
B(6,107,-4,minecraft:basalt)
B(6,108,-4,minecraft:basalt)
B(6,109,-4,minecraft:basalt)
B(6,110,-4,minecraft:basalt)
B(6,111,-4,minecraft:basalt)
B(6,112,-4,minecraft:basalt)
B(6,113,-4,minecraft:basalt)
B(6,114,-4,minecraft:basalt)
B(6,115,-4,minecraft:basalt)
B(6,116,-4,minecraft:basalt)
B(6,0,-3,minecraft:basalt)
B(6,1,-3,minecraft:basalt)
B(6,2,-3,minecraft:basalt)
B(6,104,-3,minecraft:basalt)
B(6,105,-3,minecraft:basalt)
B(6,106,-3,minecraft:basalt)
B(6,107,-3,minecraft:basalt)
B(6,108,-3,minecraft:basalt)
B(6,109,-3,minecraft:basalt)
B(6,110,-3,minecraft:basalt)
B(6,111,-3,minecraft:basalt)
B(6,112,-3,minecraft:basalt)
B(6,113,-3,minecraft:basalt)
B(6,114,-3,minecraft:basalt)
B(6,115,-3,minecraft:basalt)
B(6,116,-3,minecraft:basalt)
B(6,0,-2,minecraft:basalt)
B(6,1,-2,minecraft:basalt)
B(6,105,-2,minecraft:basalt)
B(6,106,-2,minecraft:basalt)
B(6,107,-2,minecraft:basalt)
B(6,108,-2,minecraft:basalt)
B(6,109,-2,minecraft:basalt)
B(6,110,-2,minecraft:basalt)
B(6,111,-2,minecraft:basalt)
B(6,112,-2,minecraft:basalt)
B(6,113,-2,minecraft:basalt)
B(6,114,-2,minecraft:basalt)
B(6,115,-2,minecraft:basalt)
B(6,116,-2,minecraft:basalt)
B(6,0,-1,minecraft:basalt)
B(6,1,-1,minecraft:basalt)
B(6,106,-1,minecraft:basalt)
B(6,107,-1,minecraft:basalt)
B(6,108,-1,minecraft:basalt)
B(6,109,-1,minecraft:basalt)
B(6,110,-1,minecraft:basalt)
B(6,111,-1,minecraft:basalt)
B(6,112,-1,minecraft:basalt)
B(6,113,-1,minecraft:basalt)
B(6,114,-1,minecraft:basalt)
B(6,115,-1,minecraft:basalt)
B(6,116,-1,minecraft:basalt)
B(6,0,0,minecraft:basalt)
B(6,1,0,minecraft:basalt)
B(6,107,0,minecraft:basalt)
B(6,108,0,minecraft:basalt)
B(6,109,0,minecraft:basalt)
B(6,110,0,minecraft:basalt)
B(6,111,0,minecraft:basalt)
B(6,112,0,minecraft:basalt)
B(6,113,0,minecraft:basalt)
B(6,114,0,minecraft:basalt)
B(6,115,0,minecraft:basalt)
B(6,116,0,minecraft:basalt)
B(6,0,1,minecraft:basalt)
B(6,107,1,minecraft:basalt)
B(6,108,1,minecraft:basalt)
B(6,109,1,minecraft:basalt)
B(6,110,1,minecraft:basalt)
B(6,111,1,minecraft:basalt)
B(6,112,1,minecraft:basalt)
B(6,113,1,minecraft:basalt)
B(6,114,1,minecraft:basalt)
B(6,115,1,minecraft:basalt)
B(6,116,1,minecraft:basalt)
B(6,106,2,minecraft:basalt)
B(6,107,2,minecraft:basalt)
B(6,108,2,minecraft:basalt)
B(6,109,2,minecraft:basalt)
B(6,110,2,minecraft:basalt)
B(6,111,2,minecraft:basalt)
B(6,112,2,minecraft:basalt)
B(6,113,2,minecraft:basalt)
B(6,114,2,minecraft:basalt)
B(6,115,2,minecraft:basalt)
B(6,116,2,minecraft:basalt)
B(6,106,3,minecraft:basalt)
B(6,107,3,minecraft:basalt)
B(6,108,3,minecraft:basalt)
B(6,109,3,minecraft:basalt)
B(6,110,3,minecraft:basalt)
B(6,111,3,minecraft:basalt)
B(6,112,3,minecraft:basalt)
B(6,113,3,minecraft:basalt)
B(6,114,3,minecraft:basalt)
B(6,115,3,minecraft:basalt)
B(6,116,3,minecraft:basalt)
B(6,105,4,minecraft:basalt)
B(6,106,4,minecraft:basalt)
B(6,107,4,minecraft:basalt)
B(6,108,4,minecraft:basalt)
B(6,109,4,minecraft:basalt)
B(6,110,4,minecraft:basalt)
B(6,111,4,minecraft:basalt)
B(6,112,4,minecraft:basalt)
B(6,113,4,minecraft:basalt)
B(6,114,4,minecraft:basalt)
B(6,115,4,minecraft:basalt)
B(6,116,4,minecraft:basalt)
B(6,106,5,minecraft:basalt)
B(6,107,5,minecraft:basalt)
B(6,108,5,minecraft:basalt)
B(6,109,5,minecraft:basalt)
B(6,110,5,minecraft:basalt)
B(6,111,5,minecraft:basalt)
B(6,112,5,minecraft:basalt)
B(6,113,5,minecraft:basalt)
B(6,114,5,minecraft:basalt)
B(6,115,5,minecraft:basalt)
B(6,116,5,minecraft:basalt)
B(6,106,6,minecraft:basalt)
B(6,107,6,minecraft:basalt)
B(6,108,6,minecraft:basalt)
B(6,109,6,minecraft:basalt)
B(6,110,6,minecraft:basalt)
B(6,111,6,minecraft:basalt)
B(6,112,6,minecraft:basalt)
B(6,113,6,minecraft:basalt)
B(6,114,6,minecraft:basalt)
B(6,115,6,minecraft:basalt)
B(6,116,6,minecraft:basalt)
B(6,106,7,minecraft:basalt)
B(6,107,7,minecraft:basalt)
B(6,108,7,minecraft:basalt)
B(6,109,7,minecraft:basalt)
B(6,110,7,minecraft:basalt)
B(6,111,7,minecraft:basalt)
B(6,112,7,minecraft:basalt)
B(6,113,7,minecraft:basalt)
B(6,114,7,minecraft:basalt)
B(6,115,7,minecraft:basalt)
B(6,116,7,minecraft:basalt)
B(6,106,8,minecraft:basalt)
B(6,107,8,minecraft:basalt)
B(6,108,8,minecraft:basalt)
B(6,109,8,minecraft:basalt)
B(6,110,8,minecraft:basalt)
B(6,111,8,minecraft:basalt)
B(6,112,8,minecraft:basalt)
B(6,113,8,minecraft:basalt)
B(6,114,8,minecraft:basalt)
B(6,115,8,minecraft:basalt)
B(6,116,8,minecraft:basalt)
B(7,0,-7,minecraft:basalt)
B(7,1,-7,minecraft:basalt)
B(7,2,-7,minecraft:basalt)
B(7,99,-7,minecraft:basalt)
B(7,100,-7,minecraft:basalt)
B(7,101,-7,minecraft:basalt)
B(7,102,-7,minecraft:basalt)
B(7,103,-7,minecraft:basalt)
B(7,104,-7,minecraft:basalt)
B(7,105,-7,minecraft:basalt)
B(7,106,-7,minecraft:basalt)
B(7,107,-7,minecraft:basalt)
B(7,108,-7,minecraft:basalt)
B(7,109,-7,minecraft:basalt)
B(7,110,-7,minecraft:basalt)
B(7,111,-7,minecraft:basalt)
B(7,112,-7,minecraft:basalt)
B(7,113,-7,minecraft:basalt)
B(7,114,-7,minecraft:basalt)
B(7,115,-7,minecraft:basalt)
B(7,116,-7,minecraft:basalt)
B(7,0,-6,minecraft:basalt)
B(7,1,-6,minecraft:basalt)
B(7,2,-6,minecraft:basalt)
B(7,100,-6,minecraft:basalt)
B(7,101,-6,minecraft:basalt)
B(7,102,-6,minecraft:basalt)
B(7,103,-6,minecraft:basalt)
B(7,104,-6,minecraft:basalt)
B(7,105,-6,minecraft:basalt)
B(7,106,-6,minecraft:basalt)
B(7,107,-6,minecraft:basalt)
B(7,108,-6,minecraft:basalt)
B(7,109,-6,minecraft:basalt)
B(7,110,-6,minecraft:basalt)
B(7,111,-6,minecraft:basalt)
B(7,112,-6,minecraft:basalt)
B(7,113,-6,minecraft:basalt)
B(7,114,-6,minecraft:basalt)
B(7,115,-6,minecraft:basalt)
B(7,116,-6,minecraft:basalt)
B(7,0,-5,minecraft:basalt)
B(7,1,-5,minecraft:basalt)
B(7,2,-5,minecraft:basalt)
B(7,102,-5,minecraft:basalt)
B(7,103,-5,minecraft:basalt)
B(7,104,-5,minecraft:basalt)
B(7,105,-5,minecraft:basalt)
B(7,106,-5,minecraft:basalt)
B(7,107,-5,minecraft:basalt)
B(7,108,-5,minecraft:basalt)
B(7,109,-5,minecraft:basalt)
B(7,110,-5,minecraft:basalt)
B(7,111,-5,minecraft:basalt)
B(7,112,-5,minecraft:basalt)
B(7,113,-5,minecraft:basalt)
B(7,114,-5,minecraft:basalt)
B(7,115,-5,minecraft:basalt)
B(7,116,-5,minecraft:basalt)
B(7,0,-4,minecraft:basalt)
B(7,1,-4,minecraft:basalt)
B(7,2,-4,minecraft:basalt)
B(7,103,-4,minecraft:basalt)
B(7,104,-4,minecraft:basalt)
B(7,105,-4,minecraft:basalt)
B(7,106,-4,minecraft:basalt)
B(7,107,-4,minecraft:basalt)
B(7,108,-4,minecraft:basalt)
B(7,109,-4,minecraft:basalt)
B(7,110,-4,minecraft:basalt)
B(7,111,-4,minecraft:basalt)
B(7,112,-4,minecraft:basalt)
B(7,113,-4,minecraft:basalt)
B(7,114,-4,minecraft:basalt)
B(7,115,-4,minecraft:basalt)
B(7,116,-4,minecraft:basalt)
B(7,0,-3,minecraft:basalt)
B(7,1,-3,minecraft:basalt)
B(7,2,-3,minecraft:basalt)
B(7,103,-3,minecraft:basalt)
B(7,104,-3,minecraft:basalt)
B(7,105,-3,minecraft:basalt)
B(7,106,-3,minecraft:basalt)
B(7,107,-3,minecraft:basalt)
B(7,108,-3,minecraft:basalt)
B(7,109,-3,minecraft:basalt)
B(7,110,-3,minecraft:basalt)
B(7,111,-3,minecraft:basalt)
B(7,112,-3,minecraft:basalt)
B(7,113,-3,minecraft:basalt)
B(7,114,-3,minecraft:basalt)
B(7,115,-3,minecraft:basalt)
B(7,116,-3,minecraft:basalt)
B(7,0,-2,minecraft:basalt)
B(7,1,-2,minecraft:basalt)
B(7,104,-2,minecraft:basalt)
B(7,105,-2,minecraft:basalt)
B(7,106,-2,minecraft:basalt)
B(7,107,-2,minecraft:basalt)
B(7,108,-2,minecraft:basalt)
B(7,109,-2,minecraft:basalt)
B(7,110,-2,minecraft:basalt)
B(7,111,-2,minecraft:basalt)
B(7,112,-2,minecraft:basalt)
B(7,113,-2,minecraft:basalt)
B(7,114,-2,minecraft:basalt)
B(7,115,-2,minecraft:basalt)
B(7,116,-2,minecraft:basalt)
B(7,0,-1,minecraft:basalt)
B(7,1,-1,minecraft:basalt)
B(7,105,-1,minecraft:basalt)
B(7,106,-1,minecraft:basalt)
B(7,107,-1,minecraft:basalt)
B(7,108,-1,minecraft:basalt)
B(7,109,-1,minecraft:basalt)
B(7,110,-1,minecraft:basalt)
B(7,111,-1,minecraft:basalt)
B(7,112,-1,minecraft:basalt)
B(7,113,-1,minecraft:basalt)
B(7,114,-1,minecraft:basalt)
B(7,115,-1,minecraft:basalt)
B(7,116,-1,minecraft:basalt)
B(7,0,0,minecraft:basalt)
B(7,1,0,minecraft:basalt)
B(7,106,0,minecraft:basalt)
B(7,107,0,minecraft:basalt)
B(7,108,0,minecraft:basalt)
B(7,109,0,minecraft:basalt)
B(7,110,0,minecraft:basalt)
B(7,111,0,minecraft:basalt)
B(7,112,0,minecraft:basalt)
B(7,113,0,minecraft:basalt)
B(7,114,0,minecraft:basalt)
B(7,115,0,minecraft:basalt)
B(7,116,0,minecraft:basalt)
B(7,0,1,minecraft:basalt)
B(7,1,1,minecraft:basalt)
B(7,105,1,minecraft:basalt)
B(7,106,1,minecraft:basalt)
B(7,107,1,minecraft:basalt)
B(7,108,1,minecraft:basalt)
B(7,109,1,minecraft:basalt)
B(7,110,1,minecraft:basalt)
B(7,111,1,minecraft:basalt)
B(7,112,1,minecraft:basalt)
B(7,113,1,minecraft:basalt)
B(7,114,1,minecraft:basalt)
B(7,115,1,minecraft:basalt)
B(7,116,1,minecraft:basalt)
B(7,0,2,minecraft:basalt)
B(7,1,2,minecraft:basalt)
B(7,105,2,minecraft:basalt)
B(7,106,2,minecraft:basalt)
B(7,107,2,minecraft:basalt)
B(7,108,2,minecraft:basalt)
B(7,109,2,minecraft:basalt)
B(7,110,2,minecraft:basalt)
B(7,111,2,minecraft:basalt)
B(7,112,2,minecraft:basalt)
B(7,113,2,minecraft:basalt)
B(7,114,2,minecraft:basalt)
B(7,115,2,minecraft:basalt)
B(7,116,2,minecraft:basalt)
B(7,0,3,minecraft:basalt)
B(7,105,3,minecraft:basalt)
B(7,106,3,minecraft:basalt)
B(7,107,3,minecraft:basalt)
B(7,108,3,minecraft:basalt)
B(7,109,3,minecraft:basalt)
B(7,110,3,minecraft:basalt)
B(7,111,3,minecraft:basalt)
B(7,112,3,minecraft:basalt)
B(7,113,3,minecraft:basalt)
B(7,114,3,minecraft:basalt)
B(7,115,3,minecraft:basalt)
B(7,116,3,minecraft:basalt)
B(7,0,4,minecraft:basalt)
B(7,105,4,minecraft:basalt)
B(7,106,4,minecraft:basalt)
B(7,107,4,minecraft:basalt)
B(7,108,4,minecraft:basalt)
B(7,109,4,minecraft:basalt)
B(7,110,4,minecraft:basalt)
B(7,111,4,minecraft:basalt)
B(7,112,4,minecraft:basalt)
B(7,113,4,minecraft:basalt)
B(7,114,4,minecraft:basalt)
B(7,115,4,minecraft:basalt)
B(7,116,4,minecraft:basalt)
B(7,105,5,minecraft:basalt)
B(7,106,5,minecraft:basalt)
B(7,107,5,minecraft:basalt)
B(7,108,5,minecraft:basalt)
B(7,109,5,minecraft:basalt)
B(7,110,5,minecraft:basalt)
B(7,111,5,minecraft:basalt)
B(7,112,5,minecraft:basalt)
B(7,113,5,minecraft:basalt)
B(7,114,5,minecraft:basalt)
B(7,115,5,minecraft:basalt)
B(7,116,5,minecraft:basalt)
B(7,105,6,minecraft:basalt)
B(7,106,6,minecraft:basalt)
B(7,107,6,minecraft:basalt)
B(7,108,6,minecraft:basalt)
B(7,109,6,minecraft:basalt)
B(7,110,6,minecraft:basalt)
B(7,111,6,minecraft:basalt)
B(7,112,6,minecraft:basalt)
B(7,113,6,minecraft:basalt)
B(7,114,6,minecraft:basalt)
B(7,115,6,minecraft:basalt)
B(7,116,6,minecraft:basalt)
B(7,105,7,minecraft:basalt)
B(7,106,7,minecraft:basalt)
B(7,107,7,minecraft:basalt)
B(7,108,7,minecraft:basalt)
B(7,109,7,minecraft:basalt)
B(7,110,7,minecraft:basalt)
B(7,111,7,minecraft:basalt)
B(7,112,7,minecraft:basalt)
B(7,113,7,minecraft:basalt)
B(7,114,7,minecraft:basalt)
B(7,115,7,minecraft:basalt)
B(7,116,7,minecraft:basalt)
B(7,104,8,minecraft:basalt)
B(7,105,8,minecraft:basalt)
B(7,106,8,minecraft:basalt)
B(7,107,8,minecraft:basalt)
B(7,108,8,minecraft:basalt)
B(7,109,8,minecraft:basalt)
B(7,110,8,minecraft:basalt)
B(7,111,8,minecraft:basalt)
B(7,112,8,minecraft:basalt)
B(7,113,8,minecraft:basalt)
B(7,114,8,minecraft:basalt)
B(7,115,8,minecraft:basalt)
B(7,116,8,minecraft:basalt)

#######################################################################
# +-----------------------------------------------------------------+ #
# |                             Branches                            | #
# +-----------------------------------------------------------------+ #
#######################################################################

Branch(16,0,0,true,GiantBasaltConnectedStalactite1_C1_R3,NORTH,100.0,0)
Branch(0,0,16,true,GiantBasaltConnectedStalactite1_C0_R4,NORTH,100.0,0)

#######################################################################
# +-----------------------------------------------------------------+ #
# |                             Entities                            | #
# +-----------------------------------------------------------------+ #
#######################################################################

