Author: Bo3 BulkEdit

Description: Converted Schematic - Modified by Bo3BulkEdit

Version: 3

SettingsMode: WriteDisable

IsOTGPlus: true
Tree: false
Frequency: 10
Rarity: 100
RotateRandomly: true
SpawnHeight: randomY
SpawnHeightOffset: 0
SpawnHeightVariance: 0
MaxBranchDepth: 10
ExcludedBiomes: All

MinHeight: 50
MaxHeight: 65

SourceBlocks: AIR
MaxPercentageOutsideSourceBlock: 100
OutsideSourceBlock: placeAnyway

ReplaceBelow: NETHER_WART_BLOCK
ReplaceWithBiomeBlocks: false
ReplaceWithGroundBlock: NETHER_WART_BLOCK
ReplaceWithSurfaceBlock: NETHER_WART_BLOCK
ReplaceWithStoneBlock: NETHER_WART_BLOCK
SmoothRadius: 30
SmoothHeightOffset: 0
SmoothStartTop: false
SmoothStartWood: false
SmoothingSurfaceBlock: NETHER_WART_BLOCK
SmoothingGroundBlock: NETHER_WART_BLOCK

B(0,750,0,AIR)
B(15,750,15,AIR)
B(0,0,0,minecraft:nether_wart_block)
B(1,0,0,minecraft:nether_wart_block)
B(2,0,0,minecraft:nether_wart_block)
B(0,0,1,minecraft:nether_wart_block)
B(1,0,1,minecraft:nether_wart_block)
B(2,0,1,minecraft:nether_wart_block)
B(0,0,2,minecraft:nether_wart_block)
B(1,0,2,minecraft:nether_wart_block)
B(2,0,2,minecraft:nether_wart_block)
B(3,0,2,minecraft:nether_wart_block)
B(0,0,3,minecraft:nether_wart_block)
B(1,0,3,minecraft:nether_wart_block)
B(2,0,3,minecraft:nether_wart_block)
B(3,0,3,minecraft:nether_wart_block)
B(0,0,4,minecraft:nether_wart_block)
B(1,0,4,minecraft:nether_wart_block)
B(2,0,4,minecraft:nether_wart_block)
B(3,0,4,minecraft:nether_wart_block)
B(0,0,5,minecraft:nether_wart_block)
B(1,0,5,minecraft:nether_wart_block)
B(2,0,5,minecraft:nether_wart_block)
B(3,0,5,minecraft:nether_wart_block)
B(4,0,5,minecraft:nether_wart_block)
B(0,0,6,minecraft:nether_wart_block)
B(1,0,6,minecraft:nether_wart_block)
B(2,0,6,minecraft:nether_wart_block)
B(0,0,7,minecraft:nether_wart_block)
B(1,0,7,minecraft:nether_wart_block)
B(2,0,7,minecraft:nether_wart_block)
B(3,0,7,minecraft:nether_wart_block)
B(4,0,7,minecraft:nether_wart_block)
B(5,0,7,minecraft:nether_wart_block)
B(6,0,7,minecraft:nether_wart_block)
B(0,0,8,minecraft:nether_wart_block)
B(1,0,8,minecraft:nether_wart_block)
B(2,0,8,minecraft:nether_wart_block)
B(3,0,8,minecraft:nether_wart_block)
B(4,0,8,minecraft:nether_wart_block)
B(5,0,8,minecraft:nether_wart_block)
B(6,0,8,minecraft:nether_wart_block)
B(7,0,8,minecraft:nether_wart_block)
B(0,0,9,minecraft:nether_wart_block)
B(1,0,9,minecraft:nether_wart_block)
B(2,0,9,minecraft:nether_wart_block)
B(3,0,9,minecraft:nether_wart_block)
B(4,0,9,minecraft:nether_wart_block)
B(5,0,9,minecraft:nether_wart_block)
B(6,0,9,minecraft:nether_wart_block)
B(7,0,9,minecraft:nether_wart_block)
B(8,0,9,minecraft:nether_wart_block)
B(0,0,10,minecraft:nether_wart_block)
B(1,0,10,minecraft:nether_wart_block)
B(2,0,10,minecraft:nether_wart_block)
B(3,0,10,minecraft:nether_wart_block)
B(4,0,10,minecraft:nether_wart_block)
B(5,0,10,minecraft:nether_wart_block)
B(6,0,10,minecraft:nether_wart_block)
B(7,0,10,minecraft:nether_wart_block)
B(8,0,10,minecraft:nether_wart_block)
B(9,0,10,minecraft:nether_wart_block)
B(10,0,10,minecraft:nether_wart_block)
B(0,0,11,minecraft:nether_wart_block)
B(1,0,11,minecraft:nether_wart_block)
B(2,0,11,minecraft:nether_wart_block)
B(3,0,11,minecraft:nether_wart_block)
B(4,0,11,minecraft:nether_wart_block)
B(5,0,11,minecraft:nether_wart_block)
B(6,0,11,minecraft:nether_wart_block)
B(7,0,11,minecraft:nether_wart_block)
B(8,0,11,minecraft:nether_wart_block)
B(9,0,11,minecraft:nether_wart_block)
B(10,0,11,minecraft:nether_wart_block)
B(0,0,12,minecraft:nether_wart_block)
B(1,0,12,minecraft:nether_wart_block)
B(2,0,12,minecraft:nether_wart_block)
B(3,0,12,minecraft:nether_wart_block)
B(4,0,12,minecraft:nether_wart_block)
B(5,0,12,minecraft:nether_wart_block)
B(6,0,12,minecraft:nether_wart_block)
B(7,0,12,minecraft:nether_wart_block)
B(8,0,12,minecraft:nether_wart_block)
B(9,0,12,minecraft:nether_wart_block)
B(10,0,12,minecraft:nether_wart_block)
B(0,0,13,minecraft:nether_wart_block)
B(1,0,13,minecraft:nether_wart_block)
B(2,0,13,minecraft:nether_wart_block)
B(3,0,13,minecraft:nether_wart_block)
B(4,0,13,minecraft:nether_wart_block)
B(5,0,13,minecraft:nether_wart_block)
B(6,0,13,minecraft:nether_wart_block)
B(0,0,14,minecraft:nether_wart_block)
B(1,0,14,minecraft:nether_wart_block)
B(2,0,14,minecraft:nether_wart_block)
B(3,0,14,minecraft:nether_wart_block)
B(4,0,14,minecraft:nether_wart_block)
B(5,0,14,minecraft:nether_wart_block)
B(6,0,14,minecraft:nether_wart_block)
B(0,0,15,minecraft:nether_wart_block)
B(1,0,15,minecraft:nether_wart_block)
B(2,0,15,minecraft:nether_wart_block)
B(3,0,15,minecraft:nether_wart_block)
B(4,0,15,minecraft:nether_wart_block)
B(5,0,15,minecraft:nether_wart_block)
B(6,0,15,minecraft:nether_wart_block)
B(0,1,0,minecraft:nether_wart_block)
B(1,1,0,minecraft:nether_wart_block)
B(0,1,1,minecraft:nether_wart_block)
B(1,1,1,minecraft:nether_wart_block)
B(0,1,2,minecraft:nether_wart_block)
B(1,1,2,minecraft:nether_wart_block)
B(2,1,2,minecraft:nether_wart_block)
B(0,1,3,minecraft:nether_wart_block)
B(1,1,3,minecraft:nether_wart_block)
B(2,1,3,minecraft:nether_wart_block)
B(0,1,4,minecraft:nether_wart_block)
B(1,1,4,minecraft:nether_wart_block)
B(2,1,4,minecraft:nether_wart_block)
B(0,1,5,minecraft:nether_wart_block)
B(1,1,5,minecraft:nether_wart_block)
B(2,1,5,minecraft:nether_wart_block)
B(3,1,5,minecraft:nether_wart_block)
B(0,1,6,minecraft:nether_wart_block)
B(1,1,6,minecraft:nether_wart_block)
B(2,1,6,minecraft:nether_wart_block)
B(0,1,7,minecraft:nether_wart_block)
B(1,1,7,minecraft:nether_wart_block)
B(2,1,7,minecraft:nether_wart_block)
B(3,1,7,minecraft:nether_wart_block)
B(4,1,7,minecraft:nether_wart_block)
B(5,1,7,minecraft:nether_wart_block)
B(0,1,8,minecraft:nether_wart_block)
B(1,1,8,minecraft:nether_wart_block)
B(2,1,8,minecraft:nether_wart_block)
B(3,1,8,minecraft:nether_wart_block)
B(4,1,8,minecraft:nether_wart_block)
B(5,1,8,minecraft:nether_wart_block)
B(6,1,8,minecraft:nether_wart_block)
B(0,1,9,minecraft:nether_wart_block)
B(1,1,9,minecraft:nether_wart_block)
B(2,1,9,minecraft:nether_wart_block)
B(3,1,9,minecraft:nether_wart_block)
B(4,1,9,minecraft:nether_wart_block)
B(5,1,9,minecraft:nether_wart_block)
B(6,1,9,minecraft:nether_wart_block)
B(7,1,9,minecraft:nether_wart_block)
B(0,1,10,minecraft:nether_wart_block)
B(1,1,10,minecraft:nether_wart_block)
B(2,1,10,minecraft:nether_wart_block)
B(3,1,10,minecraft:nether_wart_block)
B(4,1,10,minecraft:nether_wart_block)
B(5,1,10,minecraft:nether_wart_block)
B(6,1,10,minecraft:nether_wart_block)
B(7,1,10,minecraft:nether_wart_block)
B(0,1,11,minecraft:nether_wart_block)
B(1,1,11,minecraft:nether_wart_block)
B(2,1,11,minecraft:nether_wart_block)
B(3,1,11,minecraft:nether_wart_block)
B(4,1,11,minecraft:nether_wart_block)
B(5,1,11,minecraft:nether_wart_block)
B(6,1,11,minecraft:nether_wart_block)
B(7,1,11,minecraft:nether_wart_block)
B(0,1,12,minecraft:nether_wart_block)
B(1,1,12,minecraft:nether_wart_block)
B(2,1,12,minecraft:nether_wart_block)
B(3,1,12,minecraft:nether_wart_block)
B(4,1,12,minecraft:nether_wart_block)
B(5,1,12,minecraft:nether_wart_block)
B(6,1,12,minecraft:nether_wart_block)
B(7,1,12,minecraft:nether_wart_block)
B(0,1,13,minecraft:nether_wart_block)
B(1,1,13,minecraft:nether_wart_block)
B(2,1,13,minecraft:nether_wart_block)
B(3,1,13,minecraft:nether_wart_block)
B(4,1,13,minecraft:nether_wart_block)
B(5,1,13,minecraft:nether_wart_block)
B(6,1,13,minecraft:nether_wart_block)
B(0,1,14,minecraft:nether_wart_block)
B(1,1,14,minecraft:nether_wart_block)
B(2,1,14,minecraft:nether_wart_block)
B(3,1,14,minecraft:nether_wart_block)
B(4,1,14,minecraft:nether_wart_block)
B(5,1,14,minecraft:nether_wart_block)
B(0,1,15,minecraft:nether_wart_block)
B(1,1,15,minecraft:nether_wart_block)
B(2,1,15,minecraft:nether_wart_block)
B(3,1,15,minecraft:nether_wart_block)
B(4,1,15,minecraft:nether_wart_block)
B(5,1,15,minecraft:nether_wart_block)
B(0,2,1,minecraft:nether_wart_block)
B(0,2,2,minecraft:nether_wart_block)
B(1,2,2,minecraft:nether_wart_block)
B(0,2,3,minecraft:nether_wart_block)
B(1,2,3,minecraft:nether_wart_block)
B(0,2,4,minecraft:nether_wart_block)
B(1,2,4,minecraft:nether_wart_block)
B(0,2,5,minecraft:nether_wart_block)
B(1,2,5,minecraft:nether_wart_block)
B(2,2,5,minecraft:nether_wart_block)
B(0,2,6,minecraft:nether_wart_block)
B(1,2,6,minecraft:nether_wart_block)
B(2,2,6,minecraft:nether_wart_block)
B(0,2,7,minecraft:nether_wart_block)
B(1,2,7,minecraft:nether_wart_block)
B(2,2,7,minecraft:nether_wart_block)
B(3,2,7,minecraft:nether_wart_block)
B(4,2,7,minecraft:nether_wart_block)
B(0,2,8,minecraft:nether_wart_block)
B(1,2,8,minecraft:nether_wart_block)
B(2,2,8,minecraft:nether_wart_block)
B(3,2,8,minecraft:nether_wart_block)
B(4,2,8,minecraft:nether_wart_block)
B(5,2,8,minecraft:nether_wart_block)
B(0,2,9,minecraft:nether_wart_block)
B(1,2,9,minecraft:nether_wart_block)
B(2,2,9,minecraft:nether_wart_block)
B(3,2,9,minecraft:nether_wart_block)
B(4,2,9,minecraft:nether_wart_block)
B(5,2,9,minecraft:nether_wart_block)
B(6,2,9,minecraft:nether_wart_block)
B(0,2,10,minecraft:nether_wart_block)
B(1,2,10,minecraft:nether_wart_block)
B(2,2,10,minecraft:nether_wart_block)
B(3,2,10,minecraft:nether_wart_block)
B(4,2,10,minecraft:nether_wart_block)
B(5,2,10,minecraft:nether_wart_block)
B(6,2,10,minecraft:nether_wart_block)
B(0,2,11,minecraft:nether_wart_block)
B(1,2,11,minecraft:nether_wart_block)
B(2,2,11,minecraft:nether_wart_block)
B(3,2,11,minecraft:nether_wart_block)
B(4,2,11,minecraft:nether_wart_block)
B(5,2,11,minecraft:nether_wart_block)
B(6,2,11,minecraft:nether_wart_block)
B(0,2,12,minecraft:nether_wart_block)
B(1,2,12,minecraft:nether_wart_block)
B(2,2,12,minecraft:nether_wart_block)
B(3,2,12,minecraft:nether_wart_block)
B(4,2,12,minecraft:nether_wart_block)
B(5,2,12,minecraft:nether_wart_block)
B(6,2,12,minecraft:nether_wart_block)
B(0,2,13,minecraft:nether_wart_block)
B(1,2,13,minecraft:nether_wart_block)
B(2,2,13,minecraft:nether_wart_block)
B(3,2,13,minecraft:nether_wart_block)
B(4,2,13,minecraft:nether_wart_block)
B(5,2,13,minecraft:nether_wart_block)
B(6,2,13,minecraft:nether_wart_block)
B(0,2,14,minecraft:nether_wart_block)
B(1,2,14,minecraft:nether_wart_block)
B(2,2,14,minecraft:nether_wart_block)
B(3,2,14,minecraft:nether_wart_block)
B(4,2,14,minecraft:nether_wart_block)
B(5,2,14,minecraft:nether_wart_block)
B(0,2,15,minecraft:nether_wart_block)
B(1,2,15,minecraft:nether_wart_block)
B(2,2,15,minecraft:nether_wart_block)
B(3,2,15,minecraft:nether_wart_block)
B(4,2,15,minecraft:nether_wart_block)
B(0,3,4,minecraft:nether_wart_block)
B(0,3,5,minecraft:nether_wart_block)
B(1,3,5,minecraft:nether_wart_block)
B(2,3,5,minecraft:nether_wart_block)
B(0,3,6,minecraft:nether_wart_block)
B(1,3,6,minecraft:nether_wart_block)
B(2,3,6,minecraft:nether_wart_block)
B(0,3,7,minecraft:nether_wart_block)
B(1,3,7,minecraft:nether_wart_block)
B(2,3,7,minecraft:nether_wart_block)
B(3,3,7,minecraft:nether_wart_block)
B(0,3,8,minecraft:nether_wart_block)
B(1,3,8,minecraft:nether_wart_block)
B(2,3,8,minecraft:nether_wart_block)
B(3,3,8,minecraft:nether_wart_block)
B(4,3,8,minecraft:nether_wart_block)
B(0,3,9,minecraft:nether_wart_block)
B(1,3,9,minecraft:nether_wart_block)
B(2,3,9,minecraft:nether_wart_block)
B(3,3,9,minecraft:nether_wart_block)
B(4,3,9,minecraft:nether_wart_block)
B(5,3,9,minecraft:nether_wart_block)
B(0,3,10,minecraft:nether_wart_block)
B(1,3,10,minecraft:nether_wart_block)
B(2,3,10,minecraft:nether_wart_block)
B(3,3,10,minecraft:nether_wart_block)
B(4,3,10,minecraft:nether_wart_block)
B(5,3,10,minecraft:nether_wart_block)
B(0,3,11,minecraft:nether_wart_block)
B(1,3,11,minecraft:nether_wart_block)
B(2,3,11,minecraft:nether_wart_block)
B(3,3,11,minecraft:nether_wart_block)
B(4,3,11,minecraft:nether_wart_block)
B(5,3,11,minecraft:nether_wart_block)
B(0,3,12,minecraft:nether_wart_block)
B(1,3,12,minecraft:nether_wart_block)
B(2,3,12,minecraft:nether_wart_block)
B(3,3,12,minecraft:nether_wart_block)
B(4,3,12,minecraft:nether_wart_block)
B(5,3,12,minecraft:nether_wart_block)
B(6,3,12,minecraft:nether_wart_block)
B(0,3,13,minecraft:nether_wart_block)
B(1,3,13,minecraft:nether_wart_block)
B(2,3,13,minecraft:nether_wart_block)
B(3,3,13,minecraft:nether_wart_block)
B(4,3,13,minecraft:nether_wart_block)
B(5,3,13,minecraft:nether_wart_block)
B(0,3,14,minecraft:nether_wart_block)
B(1,3,14,minecraft:nether_wart_block)
B(2,3,14,minecraft:nether_wart_block)
B(3,3,14,minecraft:nether_wart_block)
B(4,3,14,minecraft:nether_wart_block)
B(0,3,15,minecraft:nether_wart_block)
B(1,3,15,minecraft:nether_wart_block)
B(2,3,15,minecraft:nether_wart_block)
B(3,3,15,minecraft:nether_wart_block)
B(4,3,15,minecraft:nether_wart_block)
B(0,4,5,minecraft:nether_wart_block)
B(1,4,5,minecraft:nether_wart_block)
B(0,4,6,minecraft:nether_wart_block)
B(1,4,6,minecraft:nether_wart_block)
B(2,4,6,minecraft:nether_wart_block)
B(0,4,7,minecraft:nether_wart_block)
B(1,4,7,minecraft:nether_wart_block)
B(2,4,7,minecraft:nether_wart_block)
B(0,4,8,minecraft:nether_wart_block)
B(1,4,8,minecraft:nether_wart_block)
B(2,4,8,minecraft:nether_wart_block)
B(3,4,8,minecraft:nether_wart_block)
B(0,4,9,minecraft:nether_wart_block)
B(1,4,9,minecraft:nether_wart_block)
B(2,4,9,minecraft:nether_wart_block)
B(3,4,9,minecraft:nether_wart_block)
B(4,4,9,minecraft:nether_wart_block)
B(0,4,10,minecraft:nether_wart_block)
B(1,4,10,minecraft:nether_wart_block)
B(2,4,10,minecraft:nether_wart_block)
B(3,4,10,minecraft:nether_wart_block)
B(4,4,10,minecraft:nether_wart_block)
B(0,4,11,minecraft:nether_wart_block)
B(1,4,11,minecraft:nether_wart_block)
B(2,4,11,minecraft:nether_wart_block)
B(3,4,11,minecraft:nether_wart_block)
B(4,4,11,minecraft:nether_wart_block)
B(0,4,12,minecraft:nether_wart_block)
B(1,4,12,minecraft:nether_wart_block)
B(2,4,12,minecraft:nether_wart_block)
B(3,4,12,minecraft:nether_wart_block)
B(4,4,12,minecraft:nether_wart_block)
B(5,4,12,minecraft:nether_wart_block)
B(0,4,13,minecraft:nether_wart_block)
B(1,4,13,minecraft:nether_wart_block)
B(2,4,13,minecraft:nether_wart_block)
B(3,4,13,minecraft:nether_wart_block)
B(4,4,13,minecraft:nether_wart_block)
B(0,4,14,minecraft:nether_wart_block)
B(1,4,14,minecraft:nether_wart_block)
B(2,4,14,minecraft:nether_wart_block)
B(3,4,14,minecraft:nether_wart_block)
B(4,4,14,minecraft:nether_wart_block)
B(0,4,15,minecraft:nether_wart_block)
B(1,4,15,minecraft:nether_wart_block)
B(2,4,15,minecraft:nether_wart_block)
B(3,4,15,minecraft:nether_wart_block)
B(4,4,15,minecraft:nether_wart_block)
B(0,5,5,minecraft:nether_wart_block)
B(1,5,5,minecraft:nether_wart_block)
B(0,5,6,minecraft:nether_wart_block)
B(1,5,6,minecraft:nether_wart_block)
B(0,5,7,minecraft:nether_wart_block)
B(1,5,7,minecraft:nether_wart_block)
B(2,5,7,minecraft:nether_wart_block)
B(0,5,8,minecraft:nether_wart_block)
B(1,5,8,minecraft:nether_wart_block)
B(2,5,8,minecraft:nether_wart_block)
B(0,5,9,minecraft:nether_wart_block)
B(1,5,9,minecraft:nether_wart_block)
B(2,5,9,minecraft:nether_wart_block)
B(3,5,9,minecraft:nether_wart_block)
B(0,5,10,minecraft:nether_wart_block)
B(1,5,10,minecraft:nether_wart_block)
B(2,5,10,minecraft:nether_wart_block)
B(3,5,10,minecraft:nether_wart_block)
B(0,5,11,minecraft:nether_wart_block)
B(1,5,11,minecraft:nether_wart_block)
B(2,5,11,minecraft:nether_wart_block)
B(3,5,11,minecraft:nether_wart_block)
B(0,5,12,minecraft:nether_wart_block)
B(1,5,12,minecraft:nether_wart_block)
B(2,5,12,minecraft:nether_wart_block)
B(3,5,12,minecraft:nether_wart_block)
B(4,5,12,minecraft:nether_wart_block)
B(0,5,13,minecraft:nether_wart_block)
B(1,5,13,minecraft:nether_wart_block)
B(2,5,13,minecraft:nether_wart_block)
B(3,5,13,minecraft:nether_wart_block)
B(0,5,14,minecraft:nether_wart_block)
B(1,5,14,minecraft:nether_wart_block)
B(2,5,14,minecraft:nether_wart_block)
B(3,5,14,minecraft:nether_wart_block)
B(4,5,14,minecraft:nether_wart_block)
B(0,5,15,minecraft:nether_wart_block)
B(1,5,15,minecraft:nether_wart_block)
B(2,5,15,minecraft:nether_wart_block)
B(3,5,15,minecraft:nether_wart_block)
B(4,5,15,minecraft:nether_wart_block)
B(0,6,5,minecraft:nether_wart_block)
B(0,6,6,minecraft:nether_wart_block)
B(1,6,6,minecraft:nether_wart_block)
B(0,6,7,minecraft:nether_wart_block)
B(1,6,7,minecraft:nether_wart_block)
B(0,6,8,minecraft:nether_wart_block)
B(1,6,8,minecraft:nether_wart_block)
B(2,6,8,minecraft:nether_wart_block)
B(0,6,9,minecraft:nether_wart_block)
B(1,6,9,minecraft:nether_wart_block)
B(2,6,9,minecraft:nether_wart_block)
B(0,6,10,minecraft:nether_wart_block)
B(1,6,10,minecraft:nether_wart_block)
B(2,6,10,minecraft:nether_wart_block)
B(0,6,11,minecraft:nether_wart_block)
B(1,6,11,minecraft:nether_wart_block)
B(2,6,11,minecraft:nether_wart_block)
B(3,6,11,minecraft:nether_wart_block)
B(0,6,12,minecraft:nether_wart_block)
B(1,6,12,minecraft:nether_wart_block)
B(2,6,12,minecraft:nether_wart_block)
B(3,6,12,minecraft:nether_wart_block)
B(0,6,13,minecraft:nether_wart_block)
B(1,6,13,minecraft:nether_wart_block)
B(2,6,13,minecraft:nether_wart_block)
B(3,6,13,minecraft:nether_wart_block)
B(0,6,14,minecraft:nether_wart_block)
B(1,6,14,minecraft:nether_wart_block)
B(2,6,14,minecraft:nether_wart_block)
B(3,6,14,minecraft:nether_wart_block)
B(0,6,15,minecraft:nether_wart_block)
B(1,6,15,minecraft:nether_wart_block)
B(2,6,15,minecraft:nether_wart_block)
B(3,6,15,minecraft:nether_wart_block)
B(0,7,6,minecraft:nether_wart_block)
B(0,7,7,minecraft:nether_wart_block)
B(1,7,7,minecraft:nether_wart_block)
B(0,7,8,minecraft:nether_wart_block)
B(1,7,8,minecraft:nether_wart_block)
B(0,7,9,minecraft:nether_wart_block)
B(1,7,9,minecraft:nether_wart_block)
B(2,7,9,minecraft:nether_wart_block)
B(0,7,10,minecraft:nether_wart_block)
B(1,7,10,minecraft:nether_wart_block)
B(2,7,10,minecraft:nether_wart_block)
B(0,7,11,minecraft:nether_wart_block)
B(1,7,11,minecraft:nether_wart_block)
B(2,7,11,minecraft:nether_wart_block)
B(0,7,12,minecraft:nether_wart_block)
B(1,7,12,minecraft:nether_wart_block)
B(2,7,12,minecraft:nether_wart_block)
B(0,7,13,minecraft:nether_wart_block)
B(1,7,13,minecraft:nether_wart_block)
B(2,7,13,minecraft:nether_wart_block)
B(0,7,14,minecraft:nether_wart_block)
B(1,7,14,minecraft:nether_wart_block)
B(2,7,14,minecraft:nether_wart_block)
B(0,7,15,minecraft:nether_wart_block)
B(1,7,15,minecraft:nether_wart_block)
B(2,7,15,minecraft:nether_wart_block)
B(0,8,7,minecraft:nether_wart_block)
B(0,8,8,minecraft:nether_wart_block)
B(1,8,8,minecraft:nether_wart_block)
B(0,8,9,minecraft:nether_wart_block)
B(1,8,9,minecraft:nether_wart_block)
B(0,8,10,minecraft:nether_wart_block)
B(1,8,10,minecraft:nether_wart_block)
B(0,8,11,minecraft:nether_wart_block)
B(1,8,11,minecraft:nether_wart_block)
B(0,8,12,minecraft:nether_wart_block)
B(1,8,12,minecraft:nether_wart_block)
B(0,8,13,minecraft:nether_wart_block)
B(1,8,13,minecraft:nether_wart_block)
B(0,8,14,minecraft:nether_wart_block)
B(1,8,14,minecraft:nether_wart_block)
B(0,8,15,minecraft:nether_wart_block)
B(1,8,15,minecraft:nether_wart_block)
B(2,8,15,minecraft:nether_wart_block)
B(0,9,8,minecraft:nether_wart_block)
B(0,9,9,minecraft:nether_wart_block)
B(0,9,10,minecraft:nether_wart_block)
B(1,9,10,minecraft:nether_wart_block)
B(0,9,11,minecraft:nether_wart_block)
B(1,9,11,minecraft:nether_wart_block)
B(0,9,12,minecraft:nether_wart_block)
B(1,9,12,minecraft:nether_wart_block)
B(0,9,13,minecraft:nether_wart_block)
B(1,9,13,minecraft:nether_wart_block)
B(0,9,14,minecraft:nether_wart_block)
B(1,9,14,minecraft:nether_wart_block)
B(0,9,15,minecraft:nether_wart_block)
B(1,9,15,minecraft:nether_wart_block)
B(2,9,15,minecraft:nether_wart_block)
B(0,10,8,minecraft:nether_wart_block)
B(0,10,9,minecraft:nether_wart_block)
B(0,10,10,minecraft:nether_wart_block)
B(0,10,11,minecraft:nether_wart_block)
B(0,10,12,minecraft:nether_wart_block)
B(0,10,13,minecraft:nether_wart_block)
B(1,10,13,minecraft:nether_wart_block)
B(0,10,14,minecraft:nether_wart_block)
B(1,10,14,minecraft:nether_wart_block)
B(0,10,15,minecraft:nether_wart_block)
B(1,10,15,minecraft:nether_wart_block)
B(2,10,15,minecraft:nether_wart_block)
B(0,11,8,minecraft:nether_wart_block)
B(0,11,9,minecraft:nether_wart_block)
B(0,11,13,minecraft:nether_wart_block)
B(0,11,14,minecraft:nether_wart_block)
B(1,11,14,minecraft:nether_wart_block)
B(0,11,15,minecraft:nether_wart_block)
B(1,11,15,minecraft:nether_wart_block)
B(0,12,8,minecraft:nether_wart_block)
B(0,12,9,minecraft:nether_wart_block)
B(0,12,13,minecraft:nether_wart_block)
B(0,12,14,minecraft:nether_wart_block)
B(1,12,14,minecraft:nether_wart_block)
B(0,12,15,minecraft:nether_wart_block)
B(1,12,15,minecraft:nether_wart_block)
B(0,13,13,minecraft:nether_wart_block)
B(0,13,14,minecraft:nether_wart_block)
B(1,13,14,minecraft:nether_wart_block)
B(0,13,15,minecraft:nether_wart_block)
B(1,13,15,minecraft:nether_wart_block)
B(0,14,13,minecraft:nether_wart_block)
B(0,14,14,minecraft:nether_wart_block)
B(0,14,15,minecraft:nether_wart_block)
B(1,14,15,minecraft:nether_wart_block)
B(0,15,13,minecraft:nether_wart_block)
B(0,15,14,minecraft:nether_wart_block)
B(0,15,15,minecraft:nether_wart_block)
B(1,15,15,minecraft:nether_wart_block)
B(0,16,13,minecraft:nether_wart_block)
B(0,16,14,minecraft:nether_wart_block)
B(0,16,15,minecraft:nether_wart_block)
B(1,16,15,minecraft:nether_wart_block)
B(0,17,13,minecraft:nether_wart_block)
B(0,17,14,minecraft:nether_wart_block)
B(0,17,15,minecraft:nether_wart_block)
B(1,17,15,minecraft:nether_wart_block)
B(0,18,13,minecraft:nether_wart_block)
B(0,18,14,minecraft:nether_wart_block)
B(0,18,15,minecraft:nether_wart_block)
B(1,18,15,minecraft:nether_wart_block)
B(0,19,13,minecraft:nether_wart_block)
B(0,19,14,minecraft:nether_wart_block)
B(0,19,15,minecraft:nether_wart_block)
B(0,20,13,minecraft:nether_wart_block)
B(0,20,14,minecraft:nether_wart_block)
B(0,20,15,minecraft:nether_wart_block)
B(0,21,14,minecraft:nether_wart_block)
B(0,21,15,minecraft:nether_wart_block)
B(0,22,14,minecraft:nether_wart_block)
B(0,22,15,minecraft:nether_wart_block)
B(0,23,14,minecraft:nether_wart_block)
B(0,23,15,minecraft:nether_wart_block)
B(0,24,14,minecraft:nether_wart_block)
B(0,24,15,minecraft:nether_wart_block)
B(0,25,14,minecraft:nether_wart_block)

