Author: Bo3 BulkEdit

Description: Converted Schematic - Modified by Bo3BulkEdit

Version: 3

SettingsMode: WriteDisable

IsOTGPlus: true
Tree: false
Frequency: 10
Rarity: 100
RotateRandomly: true
SpawnHeight: randomY
SpawnHeightOffset: 0
SpawnHeightVariance: 0
MaxBranchDepth: 10
ExcludedBiomes: All

MinHeight: 50
MaxHeight: 65

SourceBlocks: AIR
MaxPercentageOutsideSourceBlock: 100
OutsideSourceBlock: placeAnyway

ReplaceBelow: NETHER_WART_BLOCK
ReplaceWithBiomeBlocks: false
ReplaceWithGroundBlock: NETHER_WART_BLOCK
ReplaceWithSurfaceBlock: NETHER_WART_BLOCK
ReplaceWithStoneBlock: NETHER_WART_BLOCK
SmoothRadius: 30
SmoothHeightOffset: 0
SmoothStartTop: false
SmoothStartWood: false
SmoothingSurfaceBlock: NETHER_WART_BLOCK
SmoothingGroundBlock: NETHER_WART_BLOCK

B(0,750,0,AIR)
B(15,750,15,AIR)
B(0,0,2,minecraft:nether_wart_block)
B(2,0,2,minecraft:nether_wart_block)
B(0,0,3,minecraft:nether_wart_block)
B(1,0,3,minecraft:nether_wart_block)
B(2,0,3,minecraft:nether_wart_block)
B(4,0,3,minecraft:nether_wart_block)
B(0,0,4,minecraft:nether_wart_block)
B(1,0,4,minecraft:nether_wart_block)
B(4,0,4,minecraft:nether_wart_block)
B(0,0,5,minecraft:nether_wart_block)
B(1,0,5,minecraft:nether_wart_block)
B(2,0,5,minecraft:lava[level=6])
B(3,0,5,minecraft:nether_wart_block)
B(4,0,5,minecraft:nether_wart_block)
B(5,0,5,minecraft:nether_wart_block)
B(0,0,6,minecraft:nether_wart_block)
B(1,0,6,minecraft:nether_wart_block)
B(2,0,6,minecraft:lava[level=4])
B(3,0,6,minecraft:nether_wart_block)
B(4,0,6,minecraft:nether_wart_block)
B(5,0,6,minecraft:nether_wart_block)
B(6,0,6,minecraft:nether_wart_block)
B(7,0,6,minecraft:nether_wart_block)
B(8,0,6,minecraft:nether_wart_block)
B(9,0,6,minecraft:nether_wart_block)
B(0,0,7,minecraft:nether_wart_block)
B(1,0,7,minecraft:nether_wart_block)
B(2,0,7,minecraft:lava[level=2])
B(3,0,7,minecraft:nether_wart_block)
B(4,0,7,minecraft:nether_wart_block)
B(5,0,7,minecraft:nether_wart_block)
B(6,0,7,minecraft:nether_wart_block)
B(7,0,7,minecraft:nether_wart_block)
B(8,0,7,minecraft:nether_wart_block)
B(9,0,7,minecraft:nether_wart_block)
B(10,0,7,minecraft:nether_wart_block)
B(0,0,8,minecraft:nether_wart_block)
B(1,0,8,minecraft:nether_wart_block)
B(2,0,8,minecraft:lava[level=8])
B(3,0,8,minecraft:nether_wart_block)
B(4,0,8,minecraft:nether_wart_block)
B(5,0,8,minecraft:nether_wart_block)
B(6,0,8,minecraft:nether_wart_block)
B(7,0,8,minecraft:nether_wart_block)
B(8,0,8,minecraft:nether_wart_block)
B(9,0,8,minecraft:nether_wart_block)
B(10,0,8,minecraft:nether_wart_block)
B(11,0,8,minecraft:nether_wart_block)
B(0,0,9,minecraft:nether_wart_block)
B(1,0,9,minecraft:nether_wart_block)
B(2,0,9,minecraft:nether_wart_block)
B(3,0,9,minecraft:nether_wart_block)
B(4,0,9,minecraft:nether_wart_block)
B(5,0,9,minecraft:nether_wart_block)
B(6,0,9,minecraft:nether_wart_block)
B(7,0,9,minecraft:nether_wart_block)
B(8,0,9,minecraft:nether_wart_block)
B(9,0,9,minecraft:nether_wart_block)
B(10,0,9,minecraft:nether_wart_block)
B(11,0,9,minecraft:nether_wart_block)
B(12,0,9,minecraft:nether_wart_block)
B(13,0,9,minecraft:nether_wart_block)
B(0,0,10,minecraft:nether_wart_block)
B(1,0,10,minecraft:nether_wart_block)
B(2,0,10,minecraft:nether_wart_block)
B(3,0,10,minecraft:nether_wart_block)
B(4,0,10,minecraft:nether_wart_block)
B(5,0,10,minecraft:nether_wart_block)
B(6,0,10,minecraft:nether_wart_block)
B(7,0,10,minecraft:nether_wart_block)
B(8,0,10,minecraft:nether_wart_block)
B(9,0,10,minecraft:nether_wart_block)
B(10,0,10,minecraft:nether_wart_block)
B(11,0,10,minecraft:nether_wart_block)
B(12,0,10,minecraft:nether_wart_block)
B(13,0,10,minecraft:nether_wart_block)
B(14,0,10,minecraft:nether_wart_block)
B(15,0,10,minecraft:nether_wart_block)
B(0,0,11,minecraft:nether_wart_block)
B(1,0,11,minecraft:nether_wart_block)
B(2,0,11,minecraft:nether_wart_block)
B(3,0,11,minecraft:nether_wart_block)
B(4,0,11,minecraft:nether_wart_block)
B(5,0,11,minecraft:nether_wart_block)
B(6,0,11,minecraft:nether_wart_block)
B(7,0,11,minecraft:nether_wart_block)
B(8,0,11,minecraft:nether_wart_block)
B(9,0,11,minecraft:nether_wart_block)
B(10,0,11,minecraft:nether_wart_block)
B(11,0,11,minecraft:nether_wart_block)
B(12,0,11,minecraft:nether_wart_block)
B(13,0,11,minecraft:nether_wart_block)
B(14,0,11,minecraft:nether_wart_block)
B(15,0,11,minecraft:nether_wart_block)
B(0,0,12,minecraft:nether_wart_block)
B(1,0,12,minecraft:nether_wart_block)
B(2,0,12,minecraft:nether_wart_block)
B(3,0,12,minecraft:nether_wart_block)
B(4,0,12,minecraft:nether_wart_block)
B(5,0,12,minecraft:nether_wart_block)
B(6,0,12,minecraft:nether_wart_block)
B(7,0,12,minecraft:nether_wart_block)
B(8,0,12,minecraft:nether_wart_block)
B(9,0,12,minecraft:nether_wart_block)
B(10,0,12,minecraft:nether_wart_block)
B(11,0,12,minecraft:nether_wart_block)
B(12,0,12,minecraft:nether_wart_block)
B(13,0,12,minecraft:nether_wart_block)
B(14,0,12,minecraft:nether_wart_block)
B(15,0,12,minecraft:nether_wart_block)
B(0,0,13,minecraft:nether_wart_block)
B(1,0,13,minecraft:nether_wart_block)
B(2,0,13,minecraft:nether_wart_block)
B(3,0,13,minecraft:nether_wart_block)
B(4,0,13,minecraft:nether_wart_block)
B(5,0,13,minecraft:nether_wart_block)
B(6,0,13,minecraft:nether_wart_block)
B(7,0,13,minecraft:nether_wart_block)
B(8,0,13,minecraft:nether_wart_block)
B(9,0,13,minecraft:nether_wart_block)
B(10,0,13,minecraft:nether_wart_block)
B(11,0,13,minecraft:nether_wart_block)
B(12,0,13,minecraft:nether_wart_block)
B(13,0,13,minecraft:nether_wart_block)
B(14,0,13,minecraft:nether_wart_block)
B(15,0,13,minecraft:nether_wart_block)
B(0,0,14,minecraft:nether_wart_block)
B(1,0,14,minecraft:nether_wart_block)
B(2,0,14,minecraft:nether_wart_block)
B(3,0,14,minecraft:nether_wart_block)
B(4,0,14,minecraft:nether_wart_block)
B(5,0,14,minecraft:nether_wart_block)
B(6,0,14,minecraft:nether_wart_block)
B(7,0,14,minecraft:nether_wart_block)
B(8,0,14,minecraft:nether_wart_block)
B(9,0,14,minecraft:nether_wart_block)
B(10,0,14,minecraft:nether_wart_block)
B(11,0,14,minecraft:nether_wart_block)
B(12,0,14,minecraft:nether_wart_block)
B(13,0,14,minecraft:nether_wart_block)
B(14,0,14,minecraft:nether_wart_block)
B(15,0,14,minecraft:nether_wart_block)
B(0,0,15,minecraft:nether_wart_block)
B(1,0,15,minecraft:nether_wart_block)
B(2,0,15,minecraft:nether_wart_block)
B(3,0,15,minecraft:nether_wart_block)
B(4,0,15,minecraft:nether_wart_block)
B(5,0,15,minecraft:nether_wart_block)
B(6,0,15,minecraft:nether_wart_block)
B(7,0,15,minecraft:nether_wart_block)
B(8,0,15,minecraft:nether_wart_block)
B(9,0,15,minecraft:nether_wart_block)
B(10,0,15,minecraft:nether_wart_block)
B(11,0,15,minecraft:nether_wart_block)
B(12,0,15,minecraft:nether_wart_block)
B(13,0,15,minecraft:nether_wart_block)
B(14,0,15,minecraft:nether_wart_block)
B(15,0,15,minecraft:nether_wart_block)
B(2,1,3,minecraft:nether_wart_block)
B(0,1,4,minecraft:nether_wart_block)
B(1,1,4,minecraft:nether_wart_block)
B(4,1,4,minecraft:nether_wart_block)
B(0,1,5,minecraft:nether_wart_block)
B(1,1,5,minecraft:nether_wart_block)
B(3,1,5,minecraft:nether_wart_block)
B(0,1,6,minecraft:nether_wart_block)
B(1,1,6,minecraft:nether_wart_block)
B(3,1,6,minecraft:nether_wart_block)
B(4,1,6,minecraft:nether_wart_block)
B(5,1,6,minecraft:nether_wart_block)
B(6,1,6,minecraft:nether_wart_block)
B(0,1,7,minecraft:nether_wart_block)
B(1,1,7,minecraft:nether_wart_block)
B(3,1,7,minecraft:nether_wart_block)
B(4,1,7,minecraft:nether_wart_block)
B(5,1,7,minecraft:nether_wart_block)
B(6,1,7,minecraft:nether_wart_block)
B(7,1,7,minecraft:nether_wart_block)
B(8,1,7,minecraft:nether_wart_block)
B(9,1,7,minecraft:nether_wart_block)
B(0,1,8,minecraft:nether_wart_block)
B(1,1,8,minecraft:nether_wart_block)
B(2,1,8,minecraft:lava[level=8])
B(3,1,8,minecraft:nether_wart_block)
B(4,1,8,minecraft:nether_wart_block)
B(5,1,8,minecraft:nether_wart_block)
B(6,1,8,minecraft:nether_wart_block)
B(7,1,8,minecraft:nether_wart_block)
B(8,1,8,minecraft:nether_wart_block)
B(9,1,8,minecraft:nether_wart_block)
B(10,1,8,minecraft:nether_wart_block)
B(0,1,9,minecraft:nether_wart_block)
B(1,1,9,minecraft:nether_wart_block)
B(2,1,9,minecraft:nether_wart_block)
B(3,1,9,minecraft:nether_wart_block)
B(4,1,9,minecraft:nether_wart_block)
B(5,1,9,minecraft:nether_wart_block)
B(6,1,9,minecraft:nether_wart_block)
B(7,1,9,minecraft:nether_wart_block)
B(8,1,9,minecraft:nether_wart_block)
B(9,1,9,minecraft:nether_wart_block)
B(10,1,9,minecraft:nether_wart_block)
B(11,1,9,minecraft:nether_wart_block)
B(0,1,10,minecraft:nether_wart_block)
B(1,1,10,minecraft:nether_wart_block)
B(2,1,10,minecraft:nether_wart_block)
B(3,1,10,minecraft:nether_wart_block)
B(4,1,10,minecraft:nether_wart_block)
B(5,1,10,minecraft:nether_wart_block)
B(6,1,10,minecraft:nether_wart_block)
B(7,1,10,minecraft:nether_wart_block)
B(8,1,10,minecraft:nether_wart_block)
B(9,1,10,minecraft:nether_wart_block)
B(10,1,10,minecraft:nether_wart_block)
B(11,1,10,minecraft:nether_wart_block)
B(12,1,10,minecraft:nether_wart_block)
B(0,1,11,minecraft:nether_wart_block)
B(1,1,11,minecraft:nether_wart_block)
B(2,1,11,minecraft:nether_wart_block)
B(3,1,11,minecraft:nether_wart_block)
B(4,1,11,minecraft:nether_wart_block)
B(5,1,11,minecraft:nether_wart_block)
B(6,1,11,minecraft:nether_wart_block)
B(7,1,11,minecraft:nether_wart_block)
B(8,1,11,minecraft:nether_wart_block)
B(9,1,11,minecraft:nether_wart_block)
B(10,1,11,minecraft:nether_wart_block)
B(11,1,11,minecraft:nether_wart_block)
B(12,1,11,minecraft:nether_wart_block)
B(13,1,11,minecraft:nether_wart_block)
B(14,1,11,minecraft:nether_wart_block)
B(15,1,11,minecraft:nether_wart_block)
B(0,1,12,minecraft:nether_wart_block)
B(1,1,12,minecraft:nether_wart_block)
B(2,1,12,minecraft:nether_wart_block)
B(3,1,12,minecraft:nether_wart_block)
B(4,1,12,minecraft:nether_wart_block)
B(5,1,12,minecraft:nether_wart_block)
B(6,1,12,minecraft:nether_wart_block)
B(7,1,12,minecraft:nether_wart_block)
B(8,1,12,minecraft:nether_wart_block)
B(9,1,12,minecraft:nether_wart_block)
B(10,1,12,minecraft:nether_wart_block)
B(11,1,12,minecraft:nether_wart_block)
B(12,1,12,minecraft:nether_wart_block)
B(13,1,12,minecraft:nether_wart_block)
B(14,1,12,minecraft:nether_wart_block)
B(15,1,12,minecraft:nether_wart_block)
B(0,1,13,minecraft:nether_wart_block)
B(1,1,13,minecraft:nether_wart_block)
B(2,1,13,minecraft:nether_wart_block)
B(3,1,13,minecraft:nether_wart_block)
B(4,1,13,minecraft:nether_wart_block)
B(5,1,13,minecraft:nether_wart_block)
B(6,1,13,minecraft:nether_wart_block)
B(7,1,13,minecraft:nether_wart_block)
B(8,1,13,minecraft:nether_wart_block)
B(9,1,13,minecraft:nether_wart_block)
B(10,1,13,minecraft:nether_wart_block)
B(11,1,13,minecraft:nether_wart_block)
B(12,1,13,minecraft:nether_wart_block)
B(13,1,13,minecraft:nether_wart_block)
B(14,1,13,minecraft:nether_wart_block)
B(15,1,13,minecraft:nether_wart_block)
B(0,1,14,minecraft:nether_wart_block)
B(1,1,14,minecraft:nether_wart_block)
B(2,1,14,minecraft:nether_wart_block)
B(3,1,14,minecraft:nether_wart_block)
B(4,1,14,minecraft:nether_wart_block)
B(5,1,14,minecraft:nether_wart_block)
B(6,1,14,minecraft:nether_wart_block)
B(7,1,14,minecraft:nether_wart_block)
B(8,1,14,minecraft:nether_wart_block)
B(9,1,14,minecraft:nether_wart_block)
B(10,1,14,minecraft:nether_wart_block)
B(11,1,14,minecraft:nether_wart_block)
B(12,1,14,minecraft:nether_wart_block)
B(13,1,14,minecraft:nether_wart_block)
B(14,1,14,minecraft:nether_wart_block)
B(15,1,14,minecraft:nether_wart_block)
B(0,1,15,minecraft:nether_wart_block)
B(1,1,15,minecraft:nether_wart_block)
B(2,1,15,minecraft:nether_wart_block)
B(3,1,15,minecraft:nether_wart_block)
B(4,1,15,minecraft:nether_wart_block)
B(5,1,15,minecraft:nether_wart_block)
B(6,1,15,minecraft:nether_wart_block)
B(7,1,15,minecraft:nether_wart_block)
B(8,1,15,minecraft:nether_wart_block)
B(9,1,15,minecraft:nether_wart_block)
B(10,1,15,minecraft:nether_wart_block)
B(11,1,15,minecraft:nether_wart_block)
B(12,1,15,minecraft:nether_wart_block)
B(13,1,15,minecraft:nether_wart_block)
B(14,1,15,minecraft:nether_wart_block)
B(15,1,15,minecraft:nether_wart_block)
B(0,2,5,minecraft:nether_wart_block)
B(0,2,6,minecraft:nether_wart_block)
B(0,2,7,minecraft:nether_wart_block)
B(4,2,7,minecraft:nether_wart_block)
B(5,2,7,minecraft:nether_wart_block)
B(6,2,7,minecraft:nether_wart_block)
B(7,2,7,minecraft:nether_wart_block)
B(0,2,8,minecraft:nether_wart_block)
B(2,2,8,minecraft:lava[level=6])
B(4,2,8,minecraft:nether_wart_block)
B(5,2,8,minecraft:nether_wart_block)
B(6,2,8,minecraft:nether_wart_block)
B(7,2,8,minecraft:nether_wart_block)
B(8,2,8,minecraft:nether_wart_block)
B(9,2,8,minecraft:nether_wart_block)
B(0,2,9,minecraft:nether_wart_block)
B(1,2,9,minecraft:nether_wart_block)
B(2,2,9,minecraft:lava[level=4])
B(3,2,9,minecraft:nether_wart_block)
B(4,2,9,minecraft:nether_wart_block)
B(5,2,9,minecraft:nether_wart_block)
B(6,2,9,minecraft:nether_wart_block)
B(7,2,9,minecraft:nether_wart_block)
B(8,2,9,minecraft:nether_wart_block)
B(9,2,9,minecraft:nether_wart_block)
B(10,2,9,minecraft:nether_wart_block)
B(0,2,10,minecraft:nether_wart_block)
B(1,2,10,minecraft:lava[level=8])
B(2,2,10,minecraft:lava[level=2])
B(3,2,10,minecraft:nether_wart_block)
B(4,2,10,minecraft:nether_wart_block)
B(5,2,10,minecraft:nether_wart_block)
B(6,2,10,minecraft:nether_wart_block)
B(7,2,10,minecraft:nether_wart_block)
B(8,2,10,minecraft:nether_wart_block)
B(9,2,10,minecraft:nether_wart_block)
B(10,2,10,minecraft:nether_wart_block)
B(11,2,10,minecraft:nether_wart_block)
B(0,2,11,minecraft:nether_wart_block)
B(1,2,11,minecraft:nether_wart_block)
B(2,2,11,minecraft:lava[level=8])
B(3,2,11,minecraft:nether_wart_block)
B(4,2,11,minecraft:nether_wart_block)
B(5,2,11,minecraft:nether_wart_block)
B(6,2,11,minecraft:nether_wart_block)
B(7,2,11,minecraft:nether_wart_block)
B(8,2,11,minecraft:nether_wart_block)
B(9,2,11,minecraft:nether_wart_block)
B(10,2,11,minecraft:nether_wart_block)
B(11,2,11,minecraft:nether_wart_block)
B(12,2,11,minecraft:nether_wart_block)
B(0,2,12,minecraft:nether_wart_block)
B(1,2,12,minecraft:nether_wart_block)
B(2,2,12,minecraft:nether_wart_block)
B(3,2,12,minecraft:nether_wart_block)
B(4,2,12,minecraft:nether_wart_block)
B(5,2,12,minecraft:nether_wart_block)
B(6,2,12,minecraft:nether_wart_block)
B(7,2,12,minecraft:nether_wart_block)
B(8,2,12,minecraft:nether_wart_block)
B(9,2,12,minecraft:nether_wart_block)
B(10,2,12,minecraft:nether_wart_block)
B(11,2,12,minecraft:nether_wart_block)
B(12,2,12,minecraft:nether_wart_block)
B(13,2,12,minecraft:nether_wart_block)
B(14,2,12,minecraft:nether_wart_block)
B(0,2,13,minecraft:nether_wart_block)
B(1,2,13,minecraft:nether_wart_block)
B(2,2,13,minecraft:nether_wart_block)
B(3,2,13,minecraft:nether_wart_block)
B(4,2,13,minecraft:nether_wart_block)
B(5,2,13,minecraft:nether_wart_block)
B(6,2,13,minecraft:nether_wart_block)
B(7,2,13,minecraft:nether_wart_block)
B(8,2,13,minecraft:nether_wart_block)
B(9,2,13,minecraft:nether_wart_block)
B(10,2,13,minecraft:nether_wart_block)
B(11,2,13,minecraft:nether_wart_block)
B(12,2,13,minecraft:nether_wart_block)
B(13,2,13,minecraft:nether_wart_block)
B(14,2,13,minecraft:nether_wart_block)
B(15,2,13,minecraft:nether_wart_block)
B(0,2,14,minecraft:nether_wart_block)
B(1,2,14,minecraft:nether_wart_block)
B(2,2,14,minecraft:nether_wart_block)
B(3,2,14,minecraft:nether_wart_block)
B(4,2,14,minecraft:nether_wart_block)
B(5,2,14,minecraft:nether_wart_block)
B(6,2,14,minecraft:nether_wart_block)
B(7,2,14,minecraft:nether_wart_block)
B(8,2,14,minecraft:nether_wart_block)
B(9,2,14,minecraft:nether_wart_block)
B(10,2,14,minecraft:nether_wart_block)
B(11,2,14,minecraft:nether_wart_block)
B(12,2,14,minecraft:nether_wart_block)
B(13,2,14,minecraft:nether_wart_block)
B(14,2,14,minecraft:nether_wart_block)
B(15,2,14,minecraft:nether_wart_block)
B(0,2,15,minecraft:nether_wart_block)
B(1,2,15,minecraft:nether_wart_block)
B(2,2,15,minecraft:nether_wart_block)
B(3,2,15,minecraft:nether_wart_block)
B(4,2,15,minecraft:nether_wart_block)
B(5,2,15,minecraft:nether_wart_block)
B(6,2,15,minecraft:nether_wart_block)
B(7,2,15,minecraft:nether_wart_block)
B(8,2,15,minecraft:nether_wart_block)
B(9,2,15,minecraft:nether_wart_block)
B(10,2,15,minecraft:nether_wart_block)
B(11,2,15,minecraft:nether_wart_block)
B(12,2,15,minecraft:nether_wart_block)
B(13,2,15,minecraft:nether_wart_block)
B(14,2,15,minecraft:nether_wart_block)
B(15,2,15,minecraft:nether_wart_block)
B(6,3,8,minecraft:nether_wart_block)
B(1,3,9,minecraft:nether_wart_block)
B(3,3,9,minecraft:nether_wart_block)
B(4,3,9,minecraft:nether_wart_block)
B(5,3,9,minecraft:nether_wart_block)
B(6,3,9,minecraft:nether_wart_block)
B(7,3,9,minecraft:nether_wart_block)
B(8,3,9,minecraft:nether_wart_block)
B(9,3,9,minecraft:nether_wart_block)
B(0,3,10,minecraft:nether_wart_block)
B(1,3,10,minecraft:lava[level=8])
B(3,3,10,minecraft:nether_wart_block)
B(4,3,10,minecraft:nether_wart_block)
B(5,3,10,minecraft:nether_wart_block)
B(6,3,10,minecraft:nether_wart_block)
B(7,3,10,minecraft:nether_wart_block)
B(8,3,10,minecraft:nether_wart_block)
B(9,3,10,minecraft:nether_wart_block)
B(10,3,10,minecraft:nether_wart_block)
B(0,3,11,minecraft:nether_wart_block)
B(1,3,11,minecraft:nether_wart_block)
B(2,3,11,minecraft:lava[level=8])
B(3,3,11,minecraft:nether_wart_block)
B(4,3,11,minecraft:nether_wart_block)
B(5,3,11,minecraft:nether_wart_block)
B(6,3,11,minecraft:nether_wart_block)
B(7,3,11,minecraft:nether_wart_block)
B(8,3,11,minecraft:nether_wart_block)
B(9,3,11,minecraft:nether_wart_block)
B(10,3,11,minecraft:nether_wart_block)
B(11,3,11,minecraft:nether_wart_block)
B(0,3,12,minecraft:nether_wart_block)
B(1,3,12,minecraft:nether_wart_block)
B(2,3,12,minecraft:nether_wart_block)
B(3,3,12,minecraft:nether_wart_block)
B(4,3,12,minecraft:nether_wart_block)
B(5,3,12,minecraft:nether_wart_block)
B(6,3,12,minecraft:nether_wart_block)
B(7,3,12,minecraft:nether_wart_block)
B(8,3,12,minecraft:nether_wart_block)
B(9,3,12,minecraft:nether_wart_block)
B(10,3,12,minecraft:nether_wart_block)
B(11,3,12,minecraft:nether_wart_block)
B(0,3,13,minecraft:nether_wart_block)
B(1,3,13,minecraft:nether_wart_block)
B(2,3,13,minecraft:nether_wart_block)
B(3,3,13,minecraft:nether_wart_block)
B(4,3,13,minecraft:nether_wart_block)
B(5,3,13,minecraft:nether_wart_block)
B(6,3,13,minecraft:nether_wart_block)
B(7,3,13,minecraft:nether_wart_block)
B(8,3,13,minecraft:nether_wart_block)
B(9,3,13,minecraft:nether_wart_block)
B(10,3,13,minecraft:nether_wart_block)
B(11,3,13,minecraft:nether_wart_block)
B(12,3,13,minecraft:nether_wart_block)
B(0,3,14,minecraft:nether_wart_block)
B(1,3,14,minecraft:nether_wart_block)
B(2,3,14,minecraft:nether_wart_block)
B(3,3,14,minecraft:nether_wart_block)
B(4,3,14,minecraft:nether_wart_block)
B(5,3,14,minecraft:nether_wart_block)
B(6,3,14,minecraft:nether_wart_block)
B(7,3,14,minecraft:nether_wart_block)
B(8,3,14,minecraft:nether_wart_block)
B(9,3,14,minecraft:nether_wart_block)
B(10,3,14,minecraft:nether_wart_block)
B(11,3,14,minecraft:nether_wart_block)
B(12,3,14,minecraft:nether_wart_block)
B(13,3,14,minecraft:nether_wart_block)
B(0,3,15,minecraft:nether_wart_block)
B(1,3,15,minecraft:nether_wart_block)
B(2,3,15,minecraft:nether_wart_block)
B(3,3,15,minecraft:nether_wart_block)
B(4,3,15,minecraft:nether_wart_block)
B(5,3,15,minecraft:nether_wart_block)
B(6,3,15,minecraft:nether_wart_block)
B(7,3,15,minecraft:nether_wart_block)
B(8,3,15,minecraft:nether_wart_block)
B(9,3,15,minecraft:nether_wart_block)
B(10,3,15,minecraft:nether_wart_block)
B(11,3,15,minecraft:nether_wart_block)
B(12,3,15,minecraft:nether_wart_block)
B(13,3,15,minecraft:nether_wart_block)
B(14,3,15,minecraft:nether_wart_block)
B(0,4,10,minecraft:nether_wart_block)
B(1,4,10,minecraft:lava[level=8])
B(4,4,10,minecraft:nether_wart_block)
B(5,4,10,minecraft:nether_wart_block)
B(6,4,10,minecraft:nether_wart_block)
B(7,4,10,minecraft:nether_wart_block)
B(8,4,10,minecraft:nether_wart_block)
B(9,4,10,minecraft:nether_wart_block)
B(0,4,11,minecraft:nether_wart_block)
B(1,4,11,minecraft:nether_wart_block)
B(2,4,11,minecraft:lava[level=8])
B(4,4,11,minecraft:nether_wart_block)
B(5,4,11,minecraft:nether_wart_block)
B(6,4,11,minecraft:nether_wart_block)
B(7,4,11,minecraft:nether_wart_block)
B(8,4,11,minecraft:nether_wart_block)
B(9,4,11,minecraft:nether_wart_block)
B(10,4,11,minecraft:nether_wart_block)
B(0,4,12,minecraft:nether_wart_block)
B(1,4,12,minecraft:nether_wart_block)
B(2,4,12,minecraft:nether_wart_block)
B(3,4,12,minecraft:nether_wart_block)
B(4,4,12,minecraft:nether_wart_block)
B(5,4,12,minecraft:nether_wart_block)
B(6,4,12,minecraft:nether_wart_block)
B(7,4,12,minecraft:nether_wart_block)
B(8,4,12,minecraft:nether_wart_block)
B(9,4,12,minecraft:nether_wart_block)
B(10,4,12,minecraft:nether_wart_block)
B(0,4,13,minecraft:nether_wart_block)
B(1,4,13,minecraft:nether_wart_block)
B(2,4,13,minecraft:nether_wart_block)
B(3,4,13,minecraft:nether_wart_block)
B(4,4,13,minecraft:nether_wart_block)
B(5,4,13,minecraft:nether_wart_block)
B(6,4,13,minecraft:nether_wart_block)
B(7,4,13,minecraft:nether_wart_block)
B(8,4,13,minecraft:nether_wart_block)
B(9,4,13,minecraft:nether_wart_block)
B(10,4,13,minecraft:nether_wart_block)
B(0,4,14,minecraft:nether_wart_block)
B(1,4,14,minecraft:nether_wart_block)
B(2,4,14,minecraft:nether_wart_block)
B(3,4,14,minecraft:nether_wart_block)
B(4,4,14,minecraft:nether_wart_block)
B(5,4,14,minecraft:nether_wart_block)
B(6,4,14,minecraft:nether_wart_block)
B(7,4,14,minecraft:nether_wart_block)
B(8,4,14,minecraft:nether_wart_block)
B(9,4,14,minecraft:nether_wart_block)
B(10,4,14,minecraft:nether_wart_block)
B(11,4,14,minecraft:nether_wart_block)
B(0,4,15,minecraft:nether_wart_block)
B(1,4,15,minecraft:nether_wart_block)
B(2,4,15,minecraft:nether_wart_block)
B(3,4,15,minecraft:nether_wart_block)
B(4,4,15,minecraft:nether_wart_block)
B(5,4,15,minecraft:nether_wart_block)
B(6,4,15,minecraft:nether_wart_block)
B(7,4,15,minecraft:nether_wart_block)
B(8,4,15,minecraft:nether_wart_block)
B(9,4,15,minecraft:nether_wart_block)
B(10,4,15,minecraft:nether_wart_block)
B(11,4,15,minecraft:nether_wart_block)
B(0,5,10,minecraft:nether_wart_block)
B(1,5,10,minecraft:lava[level=8])
B(5,5,10,minecraft:nether_wart_block)
B(6,5,10,minecraft:nether_wart_block)
B(7,5,10,minecraft:nether_wart_block)
B(0,5,11,minecraft:nether_wart_block)
B(1,5,11,minecraft:nether_wart_block)
B(2,5,11,minecraft:lava[level=8])
B(5,5,11,minecraft:nether_wart_block)
B(6,5,11,minecraft:nether_wart_block)
B(7,5,11,minecraft:nether_wart_block)
B(8,5,11,minecraft:nether_wart_block)
B(9,5,11,minecraft:nether_wart_block)
B(0,5,12,minecraft:nether_wart_block)
B(1,5,12,minecraft:nether_wart_block)
B(2,5,12,minecraft:nether_wart_block)
B(3,5,12,minecraft:nether_wart_block)
B(4,5,12,minecraft:nether_wart_block)
B(5,5,12,minecraft:nether_wart_block)
B(6,5,12,minecraft:nether_wart_block)
B(7,5,12,minecraft:nether_wart_block)
B(8,5,12,minecraft:nether_wart_block)
B(9,5,12,minecraft:nether_wart_block)
B(0,5,13,minecraft:nether_wart_block)
B(1,5,13,minecraft:nether_wart_block)
B(2,5,13,minecraft:nether_wart_block)
B(3,5,13,minecraft:nether_wart_block)
B(4,5,13,minecraft:nether_wart_block)
B(5,5,13,minecraft:nether_wart_block)
B(6,5,13,minecraft:nether_wart_block)
B(7,5,13,minecraft:nether_wart_block)
B(8,5,13,minecraft:nether_wart_block)
B(9,5,13,minecraft:nether_wart_block)
B(0,5,14,minecraft:nether_wart_block)
B(1,5,14,minecraft:nether_wart_block)
B(2,5,14,minecraft:nether_wart_block)
B(3,5,14,minecraft:nether_wart_block)
B(4,5,14,minecraft:nether_wart_block)
B(5,5,14,minecraft:nether_wart_block)
B(6,5,14,minecraft:nether_wart_block)
B(7,5,14,minecraft:nether_wart_block)
B(8,5,14,minecraft:nether_wart_block)
B(9,5,14,minecraft:nether_wart_block)
B(10,5,14,minecraft:nether_wart_block)
B(0,5,15,minecraft:nether_wart_block)
B(1,5,15,minecraft:nether_wart_block)
B(2,5,15,minecraft:nether_wart_block)
B(3,5,15,minecraft:nether_wart_block)
B(4,5,15,minecraft:nether_wart_block)
B(5,5,15,minecraft:nether_wart_block)
B(6,5,15,minecraft:nether_wart_block)
B(7,5,15,minecraft:nether_wart_block)
B(8,5,15,minecraft:nether_wart_block)
B(9,5,15,minecraft:nether_wart_block)
B(10,5,15,minecraft:nether_wart_block)
B(0,6,10,minecraft:nether_wart_block)
B(1,6,10,minecraft:lava[level=8])
B(0,6,11,minecraft:nether_wart_block)
B(1,6,11,minecraft:nether_wart_block)
B(2,6,11,minecraft:lava[level=8])
B(0,6,12,minecraft:nether_wart_block)
B(1,6,12,minecraft:nether_wart_block)
B(2,6,12,minecraft:nether_wart_block)
B(3,6,12,minecraft:nether_wart_block)
B(4,6,12,minecraft:nether_wart_block)
B(5,6,12,minecraft:nether_wart_block)
B(6,6,12,minecraft:nether_wart_block)
B(7,6,12,minecraft:nether_wart_block)
B(8,6,12,minecraft:nether_wart_block)
B(0,6,13,minecraft:nether_wart_block)
B(1,6,13,minecraft:nether_wart_block)
B(2,6,13,minecraft:nether_wart_block)
B(3,6,13,minecraft:nether_wart_block)
B(4,6,13,minecraft:nether_wart_block)
B(5,6,13,minecraft:nether_wart_block)
B(6,6,13,minecraft:nether_wart_block)
B(7,6,13,minecraft:nether_wart_block)
B(8,6,13,minecraft:nether_wart_block)
B(9,6,13,minecraft:nether_wart_block)
B(0,6,14,minecraft:nether_wart_block)
B(1,6,14,minecraft:nether_wart_block)
B(2,6,14,minecraft:nether_wart_block)
B(3,6,14,minecraft:nether_wart_block)
B(4,6,14,minecraft:nether_wart_block)
B(5,6,14,minecraft:nether_wart_block)
B(6,6,14,minecraft:nether_wart_block)
B(7,6,14,minecraft:nether_wart_block)
B(8,6,14,minecraft:nether_wart_block)
B(9,6,14,minecraft:nether_wart_block)
B(0,6,15,minecraft:nether_wart_block)
B(1,6,15,minecraft:nether_wart_block)
B(2,6,15,minecraft:nether_wart_block)
B(3,6,15,minecraft:nether_wart_block)
B(4,6,15,minecraft:nether_wart_block)
B(5,6,15,minecraft:nether_wart_block)
B(6,6,15,minecraft:nether_wart_block)
B(7,6,15,minecraft:nether_wart_block)
B(8,6,15,minecraft:nether_wart_block)
B(9,6,15,minecraft:nether_wart_block)
B(0,7,10,minecraft:nether_wart_block)
B(1,7,10,minecraft:lava[level=8])
B(0,7,11,minecraft:nether_wart_block)
B(1,7,11,minecraft:nether_wart_block)
B(2,7,11,minecraft:lava[level=8])
B(0,7,12,minecraft:nether_wart_block)
B(1,7,12,minecraft:nether_wart_block)
B(2,7,12,minecraft:nether_wart_block)
B(3,7,12,minecraft:nether_wart_block)
B(4,7,12,minecraft:nether_wart_block)
B(5,7,12,minecraft:nether_wart_block)
B(6,7,12,minecraft:nether_wart_block)
B(0,7,13,minecraft:nether_wart_block)
B(1,7,13,minecraft:nether_wart_block)
B(2,7,13,minecraft:nether_wart_block)
B(3,7,13,minecraft:nether_wart_block)
B(4,7,13,minecraft:nether_wart_block)
B(5,7,13,minecraft:nether_wart_block)
B(6,7,13,minecraft:nether_wart_block)
B(7,7,13,minecraft:nether_wart_block)
B(8,7,13,minecraft:nether_wart_block)
B(0,7,14,minecraft:nether_wart_block)
B(1,7,14,minecraft:nether_wart_block)
B(2,7,14,minecraft:nether_wart_block)
B(3,7,14,minecraft:nether_wart_block)
B(4,7,14,minecraft:nether_wart_block)
B(5,7,14,minecraft:nether_wart_block)
B(6,7,14,minecraft:nether_wart_block)
B(7,7,14,minecraft:nether_wart_block)
B(8,7,14,minecraft:nether_wart_block)
B(0,7,15,minecraft:nether_wart_block)
B(1,7,15,minecraft:nether_wart_block)
B(2,7,15,minecraft:nether_wart_block)
B(3,7,15,minecraft:nether_wart_block)
B(4,7,15,minecraft:nether_wart_block)
B(5,7,15,minecraft:nether_wart_block)
B(6,7,15,minecraft:nether_wart_block)
B(7,7,15,minecraft:nether_wart_block)
B(8,7,15,minecraft:nether_wart_block)
B(9,7,15,minecraft:nether_wart_block)
B(0,8,10,minecraft:nether_wart_block)
B(1,8,10,minecraft:lava[level=8])
B(0,8,11,minecraft:nether_wart_block)
B(1,8,11,minecraft:nether_wart_block)
B(2,8,11,minecraft:lava[level=8])
B(0,8,12,minecraft:nether_wart_block)
B(1,8,12,minecraft:nether_wart_block)
B(2,8,12,minecraft:nether_wart_block)
B(3,8,12,minecraft:nether_wart_block)
B(4,8,12,minecraft:nether_wart_block)
B(5,8,12,minecraft:nether_wart_block)
B(6,8,12,minecraft:nether_wart_block)
B(0,8,13,minecraft:nether_wart_block)
B(1,8,13,minecraft:nether_wart_block)
B(2,8,13,minecraft:nether_wart_block)
B(3,8,13,minecraft:nether_wart_block)
B(4,8,13,minecraft:nether_wart_block)
B(5,8,13,minecraft:nether_wart_block)
B(6,8,13,minecraft:nether_wart_block)
B(0,8,14,minecraft:nether_wart_block)
B(1,8,14,minecraft:nether_wart_block)
B(2,8,14,minecraft:nether_wart_block)
B(3,8,14,minecraft:nether_wart_block)
B(4,8,14,minecraft:nether_wart_block)
B(5,8,14,minecraft:nether_wart_block)
B(6,8,14,minecraft:nether_wart_block)
B(7,8,14,minecraft:nether_wart_block)
B(8,8,14,minecraft:nether_wart_block)
B(0,8,15,minecraft:nether_wart_block)
B(1,8,15,minecraft:nether_wart_block)
B(2,8,15,minecraft:nether_wart_block)
B(3,8,15,minecraft:nether_wart_block)
B(4,8,15,minecraft:nether_wart_block)
B(5,8,15,minecraft:nether_wart_block)
B(6,8,15,minecraft:nether_wart_block)
B(7,8,15,minecraft:nether_wart_block)
B(8,8,15,minecraft:nether_wart_block)
B(0,9,10,minecraft:nether_wart_block)
B(1,9,10,minecraft:lava[level=8])
B(0,9,11,minecraft:nether_wart_block)
B(1,9,11,minecraft:nether_wart_block)
B(2,9,11,minecraft:lava[level=8])
B(0,9,12,minecraft:nether_wart_block)
B(1,9,12,minecraft:nether_wart_block)
B(2,9,12,minecraft:nether_wart_block)
B(3,9,12,minecraft:nether_wart_block)
B(4,9,12,minecraft:nether_wart_block)
B(5,9,12,minecraft:nether_wart_block)
B(0,9,13,minecraft:nether_wart_block)
B(1,9,13,minecraft:nether_wart_block)
B(2,9,13,minecraft:nether_wart_block)
B(3,9,13,minecraft:nether_wart_block)
B(4,9,13,minecraft:nether_wart_block)
B(5,9,13,minecraft:nether_wart_block)
B(6,9,13,minecraft:nether_wart_block)
B(0,9,14,minecraft:nether_wart_block)
B(1,9,14,minecraft:nether_wart_block)
B(2,9,14,minecraft:nether_wart_block)
B(3,9,14,minecraft:nether_wart_block)
B(4,9,14,minecraft:nether_wart_block)
B(5,9,14,minecraft:nether_wart_block)
B(6,9,14,minecraft:nether_wart_block)
B(7,9,14,minecraft:nether_wart_block)
B(0,9,15,minecraft:nether_wart_block)
B(1,9,15,minecraft:nether_wart_block)
B(2,9,15,minecraft:nether_wart_block)
B(3,9,15,minecraft:nether_wart_block)
B(4,9,15,minecraft:nether_wart_block)
B(5,9,15,minecraft:nether_wart_block)
B(6,9,15,minecraft:nether_wart_block)
B(7,9,15,minecraft:nether_wart_block)
B(0,10,10,minecraft:nether_wart_block)
B(1,10,10,minecraft:lava[level=8])
B(0,10,11,minecraft:nether_wart_block)
B(1,10,11,minecraft:nether_wart_block)
B(2,10,11,minecraft:lava[level=8])
B(0,10,12,minecraft:nether_wart_block)
B(1,10,12,minecraft:nether_wart_block)
B(2,10,12,minecraft:nether_wart_block)
B(3,10,12,minecraft:nether_wart_block)
B(4,10,12,minecraft:nether_wart_block)
B(5,10,12,minecraft:nether_wart_block)
B(0,10,13,minecraft:nether_wart_block)
B(1,10,13,minecraft:nether_wart_block)
B(2,10,13,minecraft:nether_wart_block)
B(3,10,13,minecraft:nether_wart_block)
B(4,10,13,minecraft:nether_wart_block)
B(5,10,13,minecraft:nether_wart_block)
B(6,10,13,minecraft:nether_wart_block)
B(0,10,14,minecraft:nether_wart_block)
B(1,10,14,minecraft:nether_wart_block)
B(2,10,14,minecraft:nether_wart_block)
B(3,10,14,minecraft:nether_wart_block)
B(4,10,14,minecraft:nether_wart_block)
B(5,10,14,minecraft:nether_wart_block)
B(6,10,14,minecraft:nether_wart_block)
B(0,10,15,minecraft:nether_wart_block)
B(1,10,15,minecraft:nether_wart_block)
B(2,10,15,minecraft:nether_wart_block)
B(3,10,15,minecraft:nether_wart_block)
B(4,10,15,minecraft:nether_wart_block)
B(5,10,15,minecraft:nether_wart_block)
B(6,10,15,minecraft:nether_wart_block)
B(7,10,15,minecraft:nether_wart_block)
B(0,11,10,minecraft:nether_wart_block)
B(1,11,10,minecraft:lava[level=2])
B(0,11,11,minecraft:nether_wart_block)
B(1,11,11,minecraft:lava[level=8])
B(2,11,11,minecraft:lava[level=2])
B(0,11,12,minecraft:nether_wart_block)
B(1,11,12,minecraft:nether_wart_block)
B(2,11,12,minecraft:nether_wart_block)
B(3,11,12,minecraft:nether_wart_block)
B(4,11,12,minecraft:nether_wart_block)
B(0,11,13,minecraft:nether_wart_block)
B(1,11,13,minecraft:nether_wart_block)
B(2,11,13,minecraft:nether_wart_block)
B(3,11,13,minecraft:nether_wart_block)
B(4,11,13,minecraft:nether_wart_block)
B(5,11,13,minecraft:nether_wart_block)
B(6,11,13,minecraft:nether_wart_block)
B(0,11,14,minecraft:nether_wart_block)
B(1,11,14,minecraft:nether_wart_block)
B(2,11,14,minecraft:nether_wart_block)
B(3,11,14,minecraft:nether_wart_block)
B(4,11,14,minecraft:nether_wart_block)
B(5,11,14,minecraft:nether_wart_block)
B(6,11,14,minecraft:nether_wart_block)
B(0,11,15,minecraft:nether_wart_block)
B(1,11,15,minecraft:nether_wart_block)
B(2,11,15,minecraft:nether_wart_block)
B(3,11,15,minecraft:nether_wart_block)
B(4,11,15,minecraft:nether_wart_block)
B(5,11,15,minecraft:nether_wart_block)
B(6,11,15,minecraft:nether_wart_block)
B(7,11,15,minecraft:nether_wart_block)
B(0,12,10,minecraft:nether_wart_block)
B(0,12,11,minecraft:lava[level=8])
B(1,12,11,minecraft:lava[level=2])
B(0,12,12,minecraft:nether_wart_block)
B(1,12,12,minecraft:nether_wart_block)
B(2,12,12,minecraft:nether_wart_block)
B(3,12,12,minecraft:nether_wart_block)
B(4,12,12,minecraft:nether_wart_block)
B(0,12,13,minecraft:nether_wart_block)
B(1,12,13,minecraft:nether_wart_block)
B(2,12,13,minecraft:nether_wart_block)
B(3,12,13,minecraft:nether_wart_block)
B(4,12,13,minecraft:nether_wart_block)
B(5,12,13,minecraft:nether_wart_block)
B(6,12,13,minecraft:nether_wart_block)
B(0,12,14,minecraft:nether_wart_block)
B(1,12,14,minecraft:nether_wart_block)
B(2,12,14,minecraft:nether_wart_block)
B(3,12,14,minecraft:nether_wart_block)
B(4,12,14,minecraft:nether_wart_block)
B(5,12,14,minecraft:nether_wart_block)
B(6,12,14,minecraft:nether_wart_block)
B(0,12,15,minecraft:nether_wart_block)
B(1,12,15,minecraft:nether_wart_block)
B(2,12,15,minecraft:nether_wart_block)
B(3,12,15,minecraft:nether_wart_block)
B(4,12,15,minecraft:nether_wart_block)
B(5,12,15,minecraft:nether_wart_block)
B(6,12,15,minecraft:nether_wart_block)
B(0,13,10,minecraft:nether_wart_block)
B(0,13,11,minecraft:lava[level=8])
B(0,13,12,minecraft:nether_wart_block)
B(1,13,12,minecraft:nether_wart_block)
B(2,13,12,minecraft:nether_wart_block)
B(0,13,13,minecraft:nether_wart_block)
B(1,13,13,minecraft:nether_wart_block)
B(2,13,13,minecraft:nether_wart_block)
B(3,13,13,minecraft:nether_wart_block)
B(4,13,13,minecraft:nether_wart_block)
B(5,13,13,minecraft:nether_wart_block)
B(6,13,13,minecraft:nether_wart_block)
B(0,13,14,minecraft:nether_wart_block)
B(1,13,14,minecraft:nether_wart_block)
B(2,13,14,minecraft:nether_wart_block)
B(3,13,14,minecraft:nether_wart_block)
B(4,13,14,minecraft:nether_wart_block)
B(5,13,14,minecraft:nether_wart_block)
B(6,13,14,minecraft:nether_wart_block)
B(0,13,15,minecraft:nether_wart_block)
B(1,13,15,minecraft:nether_wart_block)
B(2,13,15,minecraft:nether_wart_block)
B(3,13,15,minecraft:nether_wart_block)
B(4,13,15,minecraft:nether_wart_block)
B(5,13,15,minecraft:nether_wart_block)
B(6,13,15,minecraft:nether_wart_block)
B(0,14,11,minecraft:lava[level=8])
B(0,14,12,minecraft:nether_wart_block)
B(0,14,13,minecraft:nether_wart_block)
B(1,14,13,minecraft:nether_wart_block)
B(2,14,13,minecraft:nether_wart_block)
B(3,14,13,minecraft:nether_wart_block)
B(4,14,13,minecraft:nether_wart_block)
B(5,14,13,minecraft:nether_wart_block)
B(0,14,14,minecraft:nether_wart_block)
B(1,14,14,minecraft:nether_wart_block)
B(2,14,14,minecraft:nether_wart_block)
B(3,14,14,minecraft:nether_wart_block)
B(4,14,14,minecraft:nether_wart_block)
B(5,14,14,minecraft:nether_wart_block)
B(6,14,14,minecraft:nether_wart_block)
B(0,14,15,minecraft:nether_wart_block)
B(1,14,15,minecraft:nether_wart_block)
B(2,14,15,minecraft:nether_wart_block)
B(3,14,15,minecraft:nether_wart_block)
B(4,14,15,minecraft:nether_wart_block)
B(5,14,15,minecraft:nether_wart_block)
B(6,14,15,minecraft:nether_wart_block)
B(0,15,11,minecraft:lava[level=2])
B(0,15,12,minecraft:nether_wart_block)
B(0,15,13,minecraft:nether_wart_block)
B(1,15,13,minecraft:nether_wart_block)
B(2,15,13,minecraft:nether_wart_block)
B(3,15,13,minecraft:nether_wart_block)
B(4,15,13,minecraft:nether_wart_block)
B(0,15,14,minecraft:nether_wart_block)
B(1,15,14,minecraft:nether_wart_block)
B(2,15,14,minecraft:nether_wart_block)
B(3,15,14,minecraft:nether_wart_block)
B(4,15,14,minecraft:nether_wart_block)
B(5,15,14,minecraft:nether_wart_block)
B(6,15,14,minecraft:nether_wart_block)
B(0,15,15,minecraft:nether_wart_block)
B(1,15,15,minecraft:nether_wart_block)
B(2,15,15,minecraft:nether_wart_block)
B(3,15,15,minecraft:nether_wart_block)
B(4,15,15,minecraft:nether_wart_block)
B(5,15,15,minecraft:nether_wart_block)
B(6,15,15,minecraft:nether_wart_block)
B(0,16,12,minecraft:nether_wart_block)
B(0,16,13,minecraft:nether_wart_block)
B(1,16,13,minecraft:nether_wart_block)
B(2,16,13,minecraft:nether_wart_block)
B(3,16,13,minecraft:nether_wart_block)
B(4,16,13,minecraft:nether_wart_block)
B(0,16,14,minecraft:nether_wart_block)
B(1,16,14,minecraft:nether_wart_block)
B(2,16,14,minecraft:nether_wart_block)
B(3,16,14,minecraft:nether_wart_block)
B(4,16,14,minecraft:nether_wart_block)
B(5,16,14,minecraft:nether_wart_block)
B(6,16,14,minecraft:nether_wart_block)
B(0,16,15,minecraft:nether_wart_block)
B(1,16,15,minecraft:nether_wart_block)
B(2,16,15,minecraft:nether_wart_block)
B(3,16,15,minecraft:nether_wart_block)
B(4,16,15,minecraft:nether_wart_block)
B(5,16,15,minecraft:nether_wart_block)
B(6,16,15,minecraft:nether_wart_block)
B(0,17,14,minecraft:nether_wart_block)
B(1,17,14,minecraft:nether_wart_block)
B(2,17,14,minecraft:nether_wart_block)
B(3,17,14,minecraft:nether_wart_block)
B(4,17,14,minecraft:nether_wart_block)
B(5,17,14,minecraft:nether_wart_block)
B(6,17,14,minecraft:nether_wart_block)
B(0,17,15,minecraft:nether_wart_block)
B(1,17,15,minecraft:nether_wart_block)
B(2,17,15,minecraft:nether_wart_block)
B(3,17,15,minecraft:nether_wart_block)
B(4,17,15,minecraft:nether_wart_block)
B(5,17,15,minecraft:nether_wart_block)
B(6,17,15,minecraft:nether_wart_block)
B(0,18,14,minecraft:nether_wart_block)
B(1,18,14,minecraft:nether_wart_block)
B(2,18,14,minecraft:nether_wart_block)
B(3,18,14,minecraft:nether_wart_block)
B(4,18,14,minecraft:nether_wart_block)
B(5,18,14,minecraft:nether_wart_block)
B(0,18,15,minecraft:nether_wart_block)
B(1,18,15,minecraft:nether_wart_block)
B(2,18,15,minecraft:nether_wart_block)
B(3,18,15,minecraft:nether_wart_block)
B(4,18,15,minecraft:nether_wart_block)
B(5,18,15,minecraft:nether_wart_block)
B(6,18,15,minecraft:nether_wart_block)
B(0,19,14,minecraft:nether_wart_block)
B(1,19,14,minecraft:nether_wart_block)
B(2,19,14,minecraft:nether_wart_block)
B(3,19,14,minecraft:nether_wart_block)
B(4,19,14,minecraft:nether_wart_block)
B(5,19,14,minecraft:nether_wart_block)
B(0,19,15,minecraft:nether_wart_block)
B(1,19,15,minecraft:nether_wart_block)
B(2,19,15,minecraft:nether_wart_block)
B(3,19,15,minecraft:nether_wart_block)
B(4,19,15,minecraft:nether_wart_block)
B(5,19,15,minecraft:nether_wart_block)
B(6,19,15,minecraft:nether_wart_block)
B(5,20,14,minecraft:nether_wart_block)
B(0,20,15,minecraft:nether_wart_block)
B(1,20,15,minecraft:nether_wart_block)
B(2,20,15,minecraft:nether_wart_block)
B(3,20,15,minecraft:nether_wart_block)
B(4,20,15,minecraft:nether_wart_block)
B(5,20,15,minecraft:nether_wart_block)
B(0,21,15,minecraft:nether_wart_block)
B(1,21,15,minecraft:nether_wart_block)
B(2,21,15,minecraft:nether_wart_block)
B(3,21,15,minecraft:nether_wart_block)
B(4,21,15,minecraft:nether_wart_block)
B(5,21,15,minecraft:nether_wart_block)
B(4,22,15,minecraft:nether_wart_block)
B(5,22,15,minecraft:nether_wart_block)
B(5,23,15,minecraft:nether_wart_block)

BR(16,0,0,true,FleshVolcano1_4x0,NORTH,100,0)
