
#######################################################################
# +-----------------------------------------------------------------+ #
# |                            BO4 object                           | #
# +-----------------------------------------------------------------+ #
#######################################################################

Author: Unknown

Description: No description given

SettingsMode: WriteWithoutComments


#######################################################################
# +-----------------------------------------------------------------+ #
# |                          Main settings                          | #
# +-----------------------------------------------------------------+ #
#######################################################################

FixedRotation: 

Frequency: 0

SpawnHeight: highestBlock

UseCenterForHighestBlock: true

##############################
# Height Limits for the BO4. #
##############################

MinHeight: 0

MaxHeight: 255

InheritBO3: 

InheritBO3Rotation: NORTH

OverrideChildSettings: true

OverrideParentHeight: false

CanOverride: false

BranchFrequency: 0

BranchFrequencyGroup: 

MustBeBelowOther: false

MustBeInside: 

CannotBeInside: 

ReplacesBO3: 

MustBeInsideWorldBorders: false

CanSpawnOnWater: true

SpawnOnWaterOnly: false

SpawnUnderWater: false

SpawnAtWaterLevel: false

HeightOffset: 0

RemoveAir: true

ReplaceAbove: 

ReplaceBelow: 

ReplaceWithBiomeBlocks: true

ReplaceWithSurfaceBlock: GRASS

ReplaceWithGroundBlock: DIRT

ReplaceWithStoneBlock: STONE

SmoothRadius: 0

SmoothHeightOffset: 0

SmoothStartTop: false

SmoothStartWood: false

SmoothingSurfaceBlock: 

SmoothingGroundBlock: 

BO3Group: 

IsSpawnPoint: false

DoReplaceBlocks: true


#######################################################################
# +-----------------------------------------------------------------+ #
# |                              Blocks                             | #
# +-----------------------------------------------------------------+ #
#######################################################################

B(1,0,-7,minecraft:soul_sand)
B(1,1,-7,minecraft:soul_sand)
B(1,2,-7,minecraft:soul_sand)
B(1,0,-6,minecraft:soul_sand)
B(2,0,-7,minecraft:soul_sand)
B(2,1,-7,minecraft:soul_sand)
B(2,2,-7,minecraft:soul_sand)
B(2,3,-7,minecraft:soul_sand)
B(2,4,-7,minecraft:soul_sand)
B(2,0,-6,minecraft:soul_sand)
B(2,1,-6,minecraft:soul_sand)
B(2,2,-6,minecraft:soul_sand)
B(2,0,-5,minecraft:soul_sand)
B(3,0,-7,minecraft:soul_sand)
B(3,1,-7,minecraft:soul_sand)
B(3,2,-7,minecraft:soul_sand)
B(3,3,-7,minecraft:soul_sand)
B(3,4,-7,minecraft:soul_sand)
B(3,5,-7,minecraft:soul_sand)
B(3,6,-7,minecraft:soul_sand)
B(3,0,-6,minecraft:soul_sand)
B(3,1,-6,minecraft:soul_sand)
B(3,2,-6,minecraft:soul_sand)
B(3,3,-6,minecraft:soul_sand)
B(3,4,-6,minecraft:soul_sand)
B(3,0,-5,minecraft:soul_sand)
B(3,1,-5,minecraft:soul_sand)
B(3,2,-5,minecraft:soul_sand)
B(3,0,-4,minecraft:nether_quartz_ore)
B(4,0,-7,minecraft:soul_sand)
B(4,1,-7,minecraft:soul_sand)
B(4,2,-7,minecraft:soul_sand)
B(4,3,-7,minecraft:soul_sand)
B(4,4,-7,minecraft:soul_sand)
B(4,5,-7,minecraft:soul_sand)
B(4,6,-7,minecraft:soul_sand)
B(4,7,-7,minecraft:soul_sand)
B(4,0,-6,minecraft:soul_sand)
B(4,1,-6,minecraft:soul_sand)
B(4,2,-6,minecraft:soul_sand)
B(4,3,-6,minecraft:soul_sand)
B(4,4,-6,minecraft:soul_sand)
B(4,5,-6,minecraft:soul_sand)
B(4,0,-5,minecraft:soul_sand)
B(4,1,-5,minecraft:soul_sand)
B(4,2,-5,minecraft:soul_sand)
B(4,3,-5,minecraft:soul_sand)
B(4,0,-4,minecraft:soul_sand)
B(4,1,-4,minecraft:soul_sand)
B(5,0,-7,minecraft:soul_sand)
B(5,1,-7,minecraft:soul_sand)
B(5,2,-7,minecraft:soul_sand)
B(5,3,-7,minecraft:soul_sand)
B(5,4,-7,minecraft:soul_sand)
B(5,5,-7,minecraft:soul_sand)
B(5,6,-7,minecraft:soul_sand)
B(5,7,-7,minecraft:soul_sand)
B(5,8,-7,minecraft:soul_sand)
B(5,0,-6,minecraft:soul_sand)
B(5,1,-6,minecraft:soul_sand)
B(5,2,-6,minecraft:soul_sand)
B(5,3,-6,minecraft:soul_sand)
B(5,4,-6,minecraft:soul_sand)
B(5,5,-6,minecraft:soul_sand)
B(5,6,-6,minecraft:soul_sand)
B(5,0,-5,minecraft:soul_sand)
B(5,1,-5,minecraft:soul_sand)
B(5,2,-5,minecraft:soul_sand)
B(5,3,-5,minecraft:soul_sand)
B(5,4,-5,minecraft:soul_sand)
B(5,0,-4,minecraft:soul_sand)
B(5,1,-4,minecraft:soul_sand)
B(5,2,-4,minecraft:soul_sand)
B(6,0,-7,minecraft:soul_sand)
B(6,1,-7,minecraft:soul_sand)
B(6,2,-7,minecraft:soul_sand)
B(6,3,-7,minecraft:soul_sand)
B(6,4,-7,minecraft:soul_sand)
B(6,5,-7,minecraft:soul_sand)
B(6,6,-7,minecraft:soul_sand)
B(6,7,-7,minecraft:soul_sand)
B(6,8,-7,minecraft:soul_sand)
B(6,9,-7,minecraft:soul_sand)
B(6,10,-7,minecraft:soul_sand)
B(6,11,-7,minecraft:soul_sand)
B(6,12,-7,minecraft:soul_sand)
B(6,13,-7,minecraft:soul_sand)
B(6,0,-6,minecraft:soul_sand)
B(6,1,-6,minecraft:soul_sand)
B(6,2,-6,minecraft:soul_sand)
B(6,3,-6,minecraft:soul_sand)
B(6,4,-6,minecraft:soul_sand)
B(6,5,-6,minecraft:soul_sand)
B(6,6,-6,minecraft:soul_sand)
B(6,7,-6,minecraft:soul_sand)
B(6,8,-6,minecraft:soul_sand)
B(6,9,-6,minecraft:soul_sand)
B(6,10,-6,minecraft:soul_sand)
B(6,0,-5,minecraft:soul_sand)
B(7,0,-7,minecraft:soul_sand)
B(7,1,-7,minecraft:soul_sand)
B(7,2,-7,minecraft:soul_sand)
B(7,3,-7,minecraft:soul_sand)
B(7,4,-7,minecraft:soul_sand)
B(7,5,-7,minecraft:soul_sand)
B(7,6,-7,minecraft:soul_sand)
B(7,7,-7,minecraft:soul_sand)
B(7,8,-7,minecraft:soul_sand)
B(7,9,-7,minecraft:soul_sand)
B(7,10,-7,minecraft:soul_sand)
B(7,11,-7,minecraft:soul_sand)
B(7,12,-7,minecraft:soul_sand)
B(7,13,-7,minecraft:soul_sand)
B(7,14,-7,minecraft:soul_sand)
B(7,15,-7,minecraft:soul_sand)
B(7,16,-7,minecraft:soul_sand)
B(7,17,-7,minecraft:soul_sand)
B(7,0,-6,minecraft:soul_sand)
B(7,1,-6,minecraft:soul_sand)
B(7,2,-6,minecraft:soul_sand)
B(7,3,-6,minecraft:soul_sand)
B(7,4,-6,minecraft:soul_sand)
B(7,5,-6,minecraft:soul_sand)
B(7,6,-6,minecraft:soul_sand)
B(7,7,-6,minecraft:soul_sand)
B(7,8,-6,minecraft:soul_sand)
B(7,9,-6,minecraft:soul_sand)
B(7,10,-6,minecraft:soul_sand)
B(7,11,-6,minecraft:soul_sand)
B(7,12,-6,minecraft:soul_sand)
B(7,0,-5,minecraft:soul_sand)

#######################################################################
# +-----------------------------------------------------------------+ #
# |                             Branches                            | #
# +-----------------------------------------------------------------+ #
#######################################################################

Branch(16,0,0,true,GiantSoulSandStalacmite3_C1_R2,NORTH,100.0,0)

#######################################################################
# +-----------------------------------------------------------------+ #
# |                             Entities                            | #
# +-----------------------------------------------------------------+ #
#######################################################################

