Author: Bo3 BulkEdit

Description: Converted Schematic - Modified by Bo3BulkEdit

Version: 3

SettingsMode: WriteDisable

IsOTGPlus: true
Tree: false
Frequency: 10
Rarity: 100
RotateRandomly: true
SpawnHeight: randomY
SpawnHeightOffset: 0
SpawnHeightVariance: 0
MaxBranchDepth: 10
ExcludedBiomes: All

MinHeight: 50
MaxHeight: 65

SourceBlocks: AIR
MaxPercentageOutsideSourceBlock: 100
OutsideSourceBlock: placeAnyway

ReplaceBelow: BLACKSTONE
ReplaceWithBiomeBlocks: false
ReplaceWithGroundBlock: BLACKSTONE
ReplaceWithSurfaceBlock: BLACKSTONE
ReplaceWithStoneBlock: BLACKSTONE
SmoothRadius: 30
SmoothingSurfaceBlock: BLACKSTONE
SmoothingGroundBlock: BLACKSTONE

B(0,750,0,AIR)
B(15,750,15,AIR)
B(10,0,6,minecraft:lava[level=8])
B(11,0,6,minecraft:lava[level=8])
B(12,0,6,minecraft:lava[level=8])
B(13,0,6,minecraft:lava[level=8])
B(14,0,6,minecraft:lava[level=8])
B(5,0,7,minecraft:blackstone)
B(6,0,7,minecraft:blackstone)
B(7,0,7,minecraft:blackstone)
B(8,0,7,minecraft:blackstone)
B(9,0,7,minecraft:blackstone)
B(10,0,7,minecraft:blackstone)
B(11,0,7,minecraft:blackstone)
B(12,0,7,minecraft:blackstone)
B(13,0,7,minecraft:blackstone)
B(14,0,7,minecraft:blackstone)
B(15,0,7,minecraft:blackstone)
B(3,0,8,minecraft:lava[level=4])
B(4,0,8,minecraft:lava[level=2])
B(5,0,8,minecraft:blackstone)
B(6,0,8,minecraft:blackstone)
B(7,0,8,minecraft:blackstone)
B(8,0,8,minecraft:blackstone)
B(9,0,8,minecraft:blackstone)
B(10,0,8,minecraft:blackstone)
B(11,0,8,minecraft:blackstone)
B(12,0,8,minecraft:blackstone)
B(13,0,8,minecraft:blackstone)
B(14,0,8,minecraft:blackstone)
B(15,0,8,minecraft:blackstone)
B(2,0,9,minecraft:lava[level=4])
B(3,0,9,minecraft:lava[level=2])
B(4,0,9,minecraft:lava[level=8])
B(5,0,9,minecraft:blackstone)
B(6,0,9,minecraft:blackstone)
B(7,0,9,minecraft:blackstone)
B(8,0,9,minecraft:blackstone)
B(9,0,9,minecraft:blackstone)
B(10,0,9,minecraft:blackstone)
B(11,0,9,minecraft:blackstone)
B(12,0,9,minecraft:blackstone)
B(13,0,9,minecraft:blackstone)
B(14,0,9,minecraft:blackstone)
B(15,0,9,minecraft:blackstone)
B(2,0,10,minecraft:lava[level=4])
B(3,0,10,minecraft:lava[level=2])
B(4,0,10,minecraft:lava[level=8])
B(5,0,10,minecraft:blackstone)
B(6,0,10,minecraft:blackstone)
B(7,0,10,minecraft:blackstone)
B(8,0,10,minecraft:blackstone)
B(9,0,10,minecraft:blackstone)
B(10,0,10,minecraft:blackstone)
B(11,0,10,minecraft:blackstone)
B(12,0,10,minecraft:blackstone)
B(13,0,10,minecraft:blackstone)
B(14,0,10,minecraft:blackstone)
B(15,0,10,minecraft:blackstone)
B(1,0,11,minecraft:lava[level=6])
B(2,0,11,minecraft:lava[level=4])
B(3,0,11,minecraft:lava[level=2])
B(4,0,11,minecraft:lava[level=8])
B(5,0,11,minecraft:blackstone)
B(6,0,11,minecraft:blackstone)
B(7,0,11,minecraft:blackstone)
B(8,0,11,minecraft:blackstone)
B(9,0,11,minecraft:blackstone)
B(10,0,11,minecraft:blackstone)
B(11,0,11,minecraft:blackstone)
B(12,0,11,minecraft:blackstone)
B(13,0,11,minecraft:blackstone)
B(14,0,11,minecraft:blackstone)
B(15,0,11,minecraft:blackstone)
B(1,0,12,minecraft:lava[level=4])
B(2,0,12,minecraft:lava[level=2])
B(3,0,12,minecraft:lava[level=8])
B(4,0,12,minecraft:blackstone)
B(5,0,12,minecraft:blackstone)
B(6,0,12,minecraft:blackstone)
B(7,0,12,minecraft:blackstone)
B(8,0,12,minecraft:blackstone)
B(9,0,12,minecraft:blackstone)
B(10,0,12,minecraft:blackstone)
B(11,0,12,minecraft:blackstone)
B(12,0,12,minecraft:blackstone)
B(13,0,12,minecraft:blackstone)
B(14,0,12,minecraft:blackstone)
B(15,0,12,minecraft:blackstone)
B(2,0,13,minecraft:blackstone)
B(4,0,13,minecraft:blackstone)
B(5,0,13,minecraft:blackstone)
B(6,0,13,minecraft:blackstone)
B(7,0,13,minecraft:blackstone)
B(8,0,13,minecraft:blackstone)
B(9,0,13,minecraft:blackstone)
B(10,0,13,minecraft:blackstone)
B(11,0,13,minecraft:blackstone)
B(12,0,13,minecraft:blackstone)
B(13,0,13,minecraft:blackstone)
B(14,0,13,minecraft:blackstone)
B(15,0,13,minecraft:blackstone)
B(2,0,14,minecraft:blackstone)
B(3,0,14,minecraft:blackstone)
B(4,0,14,minecraft:blackstone)
B(5,0,14,minecraft:blackstone)
B(6,0,14,minecraft:blackstone)
B(7,0,14,minecraft:blackstone)
B(8,0,14,minecraft:blackstone)
B(9,0,14,minecraft:blackstone)
B(10,0,14,minecraft:blackstone)
B(11,0,14,minecraft:blackstone)
B(12,0,14,minecraft:blackstone)
B(13,0,14,minecraft:blackstone)
B(14,0,14,minecraft:blackstone)
B(15,0,14,minecraft:blackstone)
B(1,0,15,minecraft:blackstone)
B(2,0,15,minecraft:blackstone)
B(3,0,15,minecraft:blackstone)
B(4,0,15,minecraft:blackstone)
B(5,0,15,minecraft:blackstone)
B(6,0,15,minecraft:blackstone)
B(7,0,15,minecraft:blackstone)
B(8,0,15,minecraft:blackstone)
B(9,0,15,minecraft:blackstone)
B(10,0,15,minecraft:blackstone)
B(11,0,15,minecraft:blackstone)
B(12,0,15,minecraft:blackstone)
B(13,0,15,minecraft:blackstone)
B(14,0,15,minecraft:blackstone)
B(15,0,15,minecraft:blackstone)
B(10,1,6,minecraft:lava[level=8])
B(11,1,6,minecraft:lava[level=8])
B(12,1,6,minecraft:lava[level=8])
B(13,1,6,minecraft:lava[level=8])
B(14,1,6,minecraft:lava[level=8])
B(6,1,7,minecraft:blackstone)
B(7,1,7,minecraft:blackstone)
B(8,1,7,minecraft:blackstone)
B(9,1,7,minecraft:blackstone)
B(10,1,7,minecraft:blackstone)
B(11,1,7,minecraft:blackstone)
B(12,1,7,minecraft:blackstone)
B(13,1,7,minecraft:blackstone)
B(14,1,7,minecraft:blackstone)
B(15,1,7,minecraft:blackstone)
B(6,1,8,minecraft:blackstone)
B(7,1,8,minecraft:blackstone)
B(8,1,8,minecraft:blackstone)
B(9,1,8,minecraft:blackstone)
B(10,1,8,minecraft:blackstone)
B(11,1,8,minecraft:blackstone)
B(12,1,8,minecraft:blackstone)
B(13,1,8,minecraft:blackstone)
B(14,1,8,minecraft:blackstone)
B(15,1,8,minecraft:blackstone)
B(4,1,9,minecraft:lava[level=2])
B(5,1,9,minecraft:lava[level=8])
B(6,1,9,minecraft:blackstone)
B(7,1,9,minecraft:blackstone)
B(8,1,9,minecraft:blackstone)
B(9,1,9,minecraft:blackstone)
B(10,1,9,minecraft:blackstone)
B(11,1,9,minecraft:blackstone)
B(12,1,9,minecraft:blackstone)
B(13,1,9,minecraft:blackstone)
B(14,1,9,minecraft:blackstone)
B(15,1,9,minecraft:blackstone)
B(4,1,10,minecraft:lava[level=2])
B(5,1,10,minecraft:lava[level=8])
B(6,1,10,minecraft:blackstone)
B(7,1,10,minecraft:blackstone)
B(8,1,10,minecraft:blackstone)
B(9,1,10,minecraft:blackstone)
B(10,1,10,minecraft:blackstone)
B(11,1,10,minecraft:blackstone)
B(12,1,10,minecraft:blackstone)
B(13,1,10,minecraft:blackstone)
B(14,1,10,minecraft:blackstone)
B(15,1,10,minecraft:blackstone)
B(4,1,11,minecraft:lava[level=2])
B(5,1,11,minecraft:lava[level=8])
B(6,1,11,minecraft:blackstone)
B(7,1,11,minecraft:blackstone)
B(8,1,11,minecraft:blackstone)
B(9,1,11,minecraft:blackstone)
B(10,1,11,minecraft:blackstone)
B(11,1,11,minecraft:blackstone)
B(12,1,11,minecraft:blackstone)
B(13,1,11,minecraft:blackstone)
B(14,1,11,minecraft:blackstone)
B(15,1,11,minecraft:blackstone)
B(3,1,12,minecraft:lava[level=6])
B(4,1,12,minecraft:lava[level=4])
B(5,1,12,minecraft:lava[level=2])
B(6,1,12,minecraft:lava[level=8])
B(7,1,12,minecraft:blackstone)
B(8,1,12,minecraft:blackstone)
B(9,1,12,minecraft:blackstone)
B(10,1,12,minecraft:blackstone)
B(11,1,12,minecraft:blackstone)
B(12,1,12,minecraft:blackstone)
B(13,1,12,minecraft:blackstone)
B(14,1,12,minecraft:blackstone)
B(15,1,12,minecraft:blackstone)
B(7,1,13,minecraft:blackstone)
B(8,1,13,minecraft:blackstone)
B(9,1,13,minecraft:blackstone)
B(10,1,13,minecraft:blackstone)
B(11,1,13,minecraft:blackstone)
B(12,1,13,minecraft:blackstone)
B(13,1,13,minecraft:blackstone)
B(14,1,13,minecraft:blackstone)
B(15,1,13,minecraft:blackstone)
B(0,1,14,minecraft:blackstone)
B(5,1,14,minecraft:blackstone)
B(6,1,14,minecraft:blackstone)
B(7,1,14,minecraft:blackstone)
B(8,1,14,minecraft:blackstone)
B(9,1,14,minecraft:blackstone)
B(10,1,14,minecraft:blackstone)
B(11,1,14,minecraft:blackstone)
B(12,1,14,minecraft:blackstone)
B(13,1,14,minecraft:blackstone)
B(14,1,14,minecraft:blackstone)
B(15,1,14,minecraft:blackstone)
B(0,1,15,minecraft:blackstone)
B(4,1,15,minecraft:blackstone)
B(5,1,15,minecraft:blackstone)
B(6,1,15,minecraft:blackstone)
B(7,1,15,minecraft:blackstone)
B(8,1,15,minecraft:blackstone)
B(9,1,15,minecraft:blackstone)
B(10,1,15,minecraft:blackstone)
B(11,1,15,minecraft:blackstone)
B(12,1,15,minecraft:blackstone)
B(13,1,15,minecraft:blackstone)
B(14,1,15,minecraft:blackstone)
B(15,1,15,minecraft:blackstone)
B(10,2,6,minecraft:lava[level=8])
B(11,2,6,minecraft:lava[level=8])
B(12,2,6,minecraft:lava[level=8])
B(13,2,6,minecraft:lava[level=8])
B(14,2,6,minecraft:lava[level=8])
B(8,2,7,minecraft:blackstone)
B(9,2,7,minecraft:blackstone)
B(10,2,7,minecraft:blackstone)
B(11,2,7,minecraft:blackstone)
B(12,2,7,minecraft:blackstone)
B(13,2,7,minecraft:blackstone)
B(14,2,7,minecraft:blackstone)
B(15,2,7,minecraft:blackstone)
B(8,2,8,minecraft:blackstone)
B(9,2,8,minecraft:blackstone)
B(10,2,8,minecraft:blackstone)
B(11,2,8,minecraft:blackstone)
B(12,2,8,minecraft:blackstone)
B(13,2,8,minecraft:blackstone)
B(14,2,8,minecraft:blackstone)
B(15,2,8,minecraft:blackstone)
B(5,2,9,minecraft:lava[level=4])
B(6,2,9,minecraft:lava[level=2])
B(7,2,9,minecraft:lava[level=8])
B(8,2,9,minecraft:blackstone)
B(9,2,9,minecraft:blackstone)
B(10,2,9,minecraft:blackstone)
B(11,2,9,minecraft:blackstone)
B(12,2,9,minecraft:blackstone)
B(13,2,9,minecraft:blackstone)
B(14,2,9,minecraft:blackstone)
B(15,2,9,minecraft:blackstone)
B(5,2,10,minecraft:lava[level=6])
B(6,2,10,minecraft:lava[level=4])
B(7,2,10,minecraft:lava[level=2])
B(8,2,10,minecraft:lava[level=8])
B(9,2,10,minecraft:blackstone)
B(10,2,10,minecraft:blackstone)
B(11,2,10,minecraft:blackstone)
B(12,2,10,minecraft:blackstone)
B(13,2,10,minecraft:blackstone)
B(14,2,10,minecraft:blackstone)
B(15,2,10,minecraft:blackstone)
B(5,2,11,minecraft:lava[level=6])
B(6,2,11,minecraft:lava[level=4])
B(7,2,11,minecraft:lava[level=2])
B(8,2,11,minecraft:lava[level=8])
B(9,2,11,minecraft:blackstone)
B(10,2,11,minecraft:blackstone)
B(11,2,11,minecraft:blackstone)
B(12,2,11,minecraft:blackstone)
B(13,2,11,minecraft:blackstone)
B(14,2,11,minecraft:blackstone)
B(15,2,11,minecraft:blackstone)
B(6,2,12,minecraft:lava[level=2])
B(7,2,12,minecraft:lava[level=8])
B(8,2,12,minecraft:blackstone)
B(9,2,12,minecraft:blackstone)
B(10,2,12,minecraft:blackstone)
B(11,2,12,minecraft:blackstone)
B(12,2,12,minecraft:blackstone)
B(13,2,12,minecraft:blackstone)
B(14,2,12,minecraft:blackstone)
B(15,2,12,minecraft:blackstone)
B(7,2,13,minecraft:blackstone)
B(8,2,13,minecraft:blackstone)
B(9,2,13,minecraft:blackstone)
B(10,2,13,minecraft:blackstone)
B(11,2,13,minecraft:blackstone)
B(12,2,13,minecraft:blackstone)
B(13,2,13,minecraft:blackstone)
B(14,2,13,minecraft:blackstone)
B(15,2,13,minecraft:blackstone)
B(5,2,14,minecraft:blackstone)
B(6,2,14,minecraft:blackstone)
B(7,2,14,minecraft:blackstone)
B(8,2,14,minecraft:blackstone)
B(9,2,14,minecraft:blackstone)
B(10,2,14,minecraft:blackstone)
B(11,2,14,minecraft:blackstone)
B(12,2,14,minecraft:blackstone)
B(13,2,14,minecraft:blackstone)
B(14,2,14,minecraft:blackstone)
B(15,2,14,minecraft:blackstone)
B(4,2,15,minecraft:blackstone)
B(5,2,15,minecraft:blackstone)
B(6,2,15,minecraft:blackstone)
B(7,2,15,minecraft:blackstone)
B(8,2,15,minecraft:blackstone)
B(9,2,15,minecraft:blackstone)
B(10,2,15,minecraft:blackstone)
B(11,2,15,minecraft:blackstone)
B(12,2,15,minecraft:blackstone)
B(13,2,15,minecraft:blackstone)
B(14,2,15,minecraft:blackstone)
B(15,2,15,minecraft:blackstone)
B(10,3,6,minecraft:lava[level=6])
B(11,3,6,minecraft:lava[level=4])
B(12,3,6,minecraft:lava[level=4])
B(13,3,6,minecraft:lava[level=4])
B(14,3,6,minecraft:lava[level=4])
B(10,3,7,minecraft:lava[level=4])
B(11,3,7,minecraft:lava[level=2])
B(12,3,7,minecraft:lava[level=2])
B(13,3,7,minecraft:lava[level=2])
B(14,3,7,minecraft:lava[level=2])
B(10,3,8,minecraft:lava[level=2])
B(11,3,8,minecraft:lava[level=8])
B(12,3,8,minecraft:lava[level=8])
B(13,3,8,minecraft:lava[level=8])
B(14,3,8,minecraft:lava[level=8])
B(15,3,8,minecraft:lava[level=8])
B(7,3,9,minecraft:lava[level=6])
B(8,3,9,minecraft:lava[level=4])
B(9,3,9,minecraft:lava[level=2])
B(10,3,9,minecraft:lava[level=8])
B(11,3,9,minecraft:blackstone)
B(12,3,9,minecraft:blackstone)
B(13,3,9,minecraft:blackstone)
B(14,3,9,minecraft:blackstone)
B(15,3,9,minecraft:blackstone)
B(8,3,10,minecraft:lava[level=2])
B(9,3,10,minecraft:lava[level=8])
B(10,3,10,minecraft:blackstone)
B(11,3,10,minecraft:blackstone)
B(12,3,10,minecraft:blackstone)
B(13,3,10,minecraft:blackstone)
B(14,3,10,minecraft:blackstone)
B(15,3,10,minecraft:blackstone)
B(8,3,11,minecraft:lava[level=8])
B(9,3,11,minecraft:blackstone)
B(10,3,11,minecraft:blackstone)
B(11,3,11,minecraft:blackstone)
B(12,3,11,minecraft:blackstone)
B(13,3,11,minecraft:blackstone)
B(14,3,11,minecraft:blackstone)
B(15,3,11,minecraft:blackstone)
B(7,3,12,minecraft:lava[level=8])
B(8,3,12,minecraft:blackstone)
B(9,3,12,minecraft:blackstone)
B(10,3,12,minecraft:blackstone)
B(11,3,12,minecraft:blackstone)
B(12,3,12,minecraft:blackstone)
B(13,3,12,minecraft:blackstone)
B(14,3,12,minecraft:blackstone)
B(15,3,12,minecraft:blackstone)
B(7,3,13,minecraft:blackstone)
B(8,3,13,minecraft:blackstone)
B(9,3,13,minecraft:blackstone)
B(10,3,13,minecraft:blackstone)
B(11,3,13,minecraft:blackstone)
B(12,3,13,minecraft:blackstone)
B(13,3,13,minecraft:blackstone)
B(14,3,13,minecraft:blackstone)
B(15,3,13,minecraft:blackstone)
B(5,3,14,minecraft:blackstone)
B(6,3,14,minecraft:blackstone)
B(7,3,14,minecraft:blackstone)
B(8,3,14,minecraft:blackstone)
B(9,3,14,minecraft:blackstone)
B(10,3,14,minecraft:blackstone)
B(11,3,14,minecraft:blackstone)
B(12,3,14,minecraft:blackstone)
B(13,3,14,minecraft:blackstone)
B(14,3,14,minecraft:blackstone)
B(15,3,14,minecraft:blackstone)
B(4,3,15,minecraft:blackstone)
B(5,3,15,minecraft:blackstone)
B(6,3,15,minecraft:blackstone)
B(7,3,15,minecraft:blackstone)
B(8,3,15,minecraft:blackstone)
B(9,3,15,minecraft:blackstone)
B(10,3,15,minecraft:blackstone)
B(11,3,15,minecraft:blackstone)
B(12,3,15,minecraft:blackstone)
B(13,3,15,minecraft:blackstone)
B(14,3,15,minecraft:blackstone)
B(15,3,15,minecraft:blackstone)
B(11,4,8,minecraft:lava[level=2])
B(12,4,8,minecraft:lava[level=8])
B(13,4,8,minecraft:lava[level=8])
B(14,4,8,minecraft:lava[level=8])
B(15,4,8,minecraft:lava[level=2])
B(10,4,9,minecraft:lava[level=8])
B(11,4,9,minecraft:lava[level=8])
B(12,4,9,minecraft:blackstone)
B(13,4,9,minecraft:blackstone)
B(14,4,9,minecraft:blackstone)
B(15,4,9,minecraft:lava[level=8])
B(9,4,10,minecraft:lava[level=8])
B(10,4,10,minecraft:blackstone)
B(11,4,10,minecraft:blackstone)
B(12,4,10,minecraft:blackstone)
B(13,4,10,minecraft:blackstone)
B(14,4,10,minecraft:blackstone)
B(15,4,10,minecraft:blackstone)
B(8,4,11,minecraft:lava[level=8])
B(9,4,11,minecraft:blackstone)
B(10,4,11,minecraft:blackstone)
B(11,4,11,minecraft:blackstone)
B(12,4,11,minecraft:blackstone)
B(13,4,11,minecraft:blackstone)
B(14,4,11,minecraft:blackstone)
B(15,4,11,minecraft:blackstone)
B(7,4,12,minecraft:lava[level=2])
B(8,4,12,minecraft:lava[level=8])
B(9,4,12,minecraft:blackstone)
B(10,4,12,minecraft:blackstone)
B(11,4,12,minecraft:blackstone)
B(12,4,12,minecraft:blackstone)
B(13,4,12,minecraft:blackstone)
B(14,4,12,minecraft:blackstone)
B(15,4,12,minecraft:blackstone)
B(7,4,13,minecraft:blackstone)
B(8,4,13,minecraft:blackstone)
B(9,4,13,minecraft:blackstone)
B(10,4,13,minecraft:blackstone)
B(11,4,13,minecraft:blackstone)
B(12,4,13,minecraft:blackstone)
B(13,4,13,minecraft:blackstone)
B(14,4,13,minecraft:blackstone)
B(15,4,13,minecraft:blackstone)
B(5,4,14,minecraft:blackstone)
B(6,4,14,minecraft:blackstone)
B(7,4,14,minecraft:blackstone)
B(8,4,14,minecraft:blackstone)
B(9,4,14,minecraft:blackstone)
B(10,4,14,minecraft:blackstone)
B(11,4,14,minecraft:blackstone)
B(12,4,14,minecraft:blackstone)
B(13,4,14,minecraft:blackstone)
B(14,4,14,minecraft:blackstone)
B(15,4,14,minecraft:blackstone)
B(4,4,15,minecraft:blackstone)
B(5,4,15,minecraft:blackstone)
B(6,4,15,minecraft:blackstone)
B(7,4,15,minecraft:blackstone)
B(8,4,15,minecraft:blackstone)
B(9,4,15,minecraft:blackstone)
B(10,4,15,minecraft:blackstone)
B(11,4,15,minecraft:blackstone)
B(12,4,15,minecraft:blackstone)
B(13,4,15,minecraft:blackstone)
B(14,4,15,minecraft:blackstone)
B(15,4,15,minecraft:blackstone)
B(12,5,8,minecraft:lava[level=2])
B(13,5,8,minecraft:lava[level=2])
B(14,5,8,minecraft:lava[level=2])
B(10,5,9,minecraft:lava[level=2])
B(11,5,9,minecraft:lava[level=8])
B(12,5,9,minecraft:lava[level=8])
B(13,5,9,minecraft:lava[level=8])
B(14,5,9,minecraft:lava[level=8])
B(15,5,9,minecraft:lava[level=2])
B(9,5,10,minecraft:lava[level=2])
B(10,5,10,minecraft:lava[level=8])
B(11,5,10,minecraft:blackstone)
B(12,5,10,minecraft:blackstone)
B(13,5,10,minecraft:blackstone)
B(14,5,10,minecraft:blackstone)
B(15,5,10,minecraft:blackstone)
B(8,5,11,minecraft:lava[level=2])
B(9,5,11,minecraft:lava[level=8])
B(10,5,11,minecraft:blackstone)
B(11,5,11,minecraft:blackstone)
B(12,5,11,minecraft:blackstone)
B(13,5,11,minecraft:blackstone)
B(14,5,11,minecraft:blackstone)
B(15,5,11,minecraft:blackstone)
B(8,5,12,minecraft:lava[level=8])
B(9,5,12,minecraft:blackstone)
B(10,5,12,minecraft:blackstone)
B(11,5,12,minecraft:blackstone)
B(12,5,12,minecraft:blackstone)
B(13,5,12,minecraft:blackstone)
B(14,5,12,minecraft:blackstone)
B(15,5,12,minecraft:blackstone)
B(7,5,13,minecraft:blackstone)
B(8,5,13,minecraft:blackstone)
B(9,5,13,minecraft:blackstone)
B(10,5,13,minecraft:blackstone)
B(11,5,13,minecraft:blackstone)
B(12,5,13,minecraft:blackstone)
B(13,5,13,minecraft:blackstone)
B(14,5,13,minecraft:blackstone)
B(15,5,13,minecraft:blackstone)
B(5,5,14,minecraft:blackstone)
B(6,5,14,minecraft:blackstone)
B(7,5,14,minecraft:blackstone)
B(8,5,14,minecraft:blackstone)
B(9,5,14,minecraft:blackstone)
B(10,5,14,minecraft:blackstone)
B(11,5,14,minecraft:blackstone)
B(12,5,14,minecraft:blackstone)
B(13,5,14,minecraft:blackstone)
B(14,5,14,minecraft:blackstone)
B(15,5,14,minecraft:blackstone)
B(4,5,15,minecraft:blackstone)
B(5,5,15,minecraft:blackstone)
B(6,5,15,minecraft:blackstone)
B(7,5,15,minecraft:blackstone)
B(8,5,15,minecraft:blackstone)
B(9,5,15,minecraft:blackstone)
B(10,5,15,minecraft:blackstone)
B(11,5,15,minecraft:blackstone)
B(12,5,15,minecraft:blackstone)
B(13,5,15,minecraft:blackstone)
B(14,5,15,minecraft:blackstone)
B(15,5,15,minecraft:blackstone)
B(11,6,9,minecraft:lava[level=2])
B(12,6,9,minecraft:lava[level=2])
B(13,6,9,minecraft:lava[level=2])
B(14,6,9,minecraft:lava[level=2])
B(10,6,10,minecraft:lava[level=2])
B(11,6,10,minecraft:lava[level=8])
B(12,6,10,minecraft:lava[level=8])
B(13,6,10,minecraft:lava[level=8])
B(14,6,10,minecraft:lava[level=8])
B(9,6,11,minecraft:lava[level=2])
B(10,6,11,minecraft:lava[level=8])
B(11,6,11,minecraft:blackstone)
B(12,6,11,minecraft:blackstone)
B(13,6,11,minecraft:blackstone)
B(14,6,11,minecraft:blackstone)
B(15,6,11,minecraft:blackstone)
B(8,6,12,minecraft:lava[level=2])
B(9,6,12,minecraft:lava[level=8])
B(10,6,12,minecraft:blackstone)
B(11,6,12,minecraft:blackstone)
B(12,6,12,minecraft:blackstone)
B(13,6,12,minecraft:blackstone)
B(14,6,12,minecraft:blackstone)
B(15,6,12,minecraft:blackstone)
B(7,6,13,minecraft:blackstone)
B(8,6,13,minecraft:blackstone)
B(9,6,13,minecraft:blackstone)
B(10,6,13,minecraft:blackstone)
B(11,6,13,minecraft:blackstone)
B(12,6,13,minecraft:blackstone)
B(13,6,13,minecraft:blackstone)
B(14,6,13,minecraft:blackstone)
B(15,6,13,minecraft:blackstone)
B(5,6,14,minecraft:blackstone)
B(6,6,14,minecraft:blackstone)
B(7,6,14,minecraft:blackstone)
B(8,6,14,minecraft:blackstone)
B(9,6,14,minecraft:blackstone)
B(10,6,14,minecraft:blackstone)
B(11,6,14,minecraft:blackstone)
B(12,6,14,minecraft:blackstone)
B(13,6,14,minecraft:blackstone)
B(14,6,14,minecraft:blackstone)
B(15,6,14,minecraft:blackstone)
B(4,6,15,minecraft:blackstone)
B(5,6,15,minecraft:blackstone)
B(6,6,15,minecraft:blackstone)
B(7,6,15,minecraft:blackstone)
B(8,6,15,minecraft:blackstone)
B(9,6,15,minecraft:blackstone)
B(10,6,15,minecraft:blackstone)
B(11,6,15,minecraft:blackstone)
B(12,6,15,minecraft:blackstone)
B(13,6,15,minecraft:blackstone)
B(14,6,15,minecraft:blackstone)
B(15,6,15,minecraft:blackstone)
B(11,7,10,minecraft:lava[level=4])
B(12,7,10,minecraft:lava[level=2])
B(13,7,10,minecraft:lava[level=2])
B(14,7,10,minecraft:lava[level=2])
B(10,7,11,minecraft:lava[level=4])
B(11,7,11,minecraft:lava[level=2])
B(12,7,11,minecraft:lava[level=8])
B(13,7,11,minecraft:lava[level=8])
B(14,7,11,minecraft:lava[level=8])
B(15,7,11,minecraft:blackstone)
B(9,7,12,minecraft:lava[level=4])
B(10,7,12,minecraft:lava[level=2])
B(11,7,12,minecraft:lava[level=8])
B(12,7,12,minecraft:blackstone)
B(13,7,12,minecraft:blackstone)
B(14,7,12,minecraft:blackstone)
B(15,7,12,minecraft:blackstone)
B(7,7,13,minecraft:blackstone)
B(8,7,13,minecraft:blackstone)
B(9,7,13,minecraft:blackstone)
B(10,7,13,minecraft:blackstone)
B(11,7,13,minecraft:blackstone)
B(12,7,13,minecraft:blackstone)
B(13,7,13,minecraft:blackstone)
B(14,7,13,minecraft:blackstone)
B(15,7,13,minecraft:blackstone)
B(5,7,14,minecraft:blackstone)
B(6,7,14,minecraft:blackstone)
B(7,7,14,minecraft:blackstone)
B(8,7,14,minecraft:blackstone)
B(9,7,14,minecraft:blackstone)
B(10,7,14,minecraft:blackstone)
B(11,7,14,minecraft:blackstone)
B(12,7,14,minecraft:blackstone)
B(13,7,14,minecraft:blackstone)
B(14,7,14,minecraft:blackstone)
B(15,7,14,minecraft:blackstone)
B(4,7,15,minecraft:blackstone)
B(5,7,15,minecraft:blackstone)
B(6,7,15,minecraft:blackstone)
B(7,7,15,minecraft:blackstone)
B(8,7,15,minecraft:blackstone)
B(9,7,15,minecraft:blackstone)
B(10,7,15,minecraft:blackstone)
B(11,7,15,minecraft:blackstone)
B(12,7,15,minecraft:blackstone)
B(13,7,15,minecraft:blackstone)
B(14,7,15,minecraft:blackstone)
B(15,7,15,minecraft:blackstone)
B(12,8,11,minecraft:lava[level=4])
B(13,8,11,minecraft:lava[level=2])
B(14,8,11,minecraft:lava[level=8])
B(15,8,11,minecraft:blackstone)
B(11,8,12,minecraft:lava[level=4])
B(12,8,12,minecraft:lava[level=2])
B(13,8,12,minecraft:lava[level=8])
B(14,8,12,minecraft:blackstone)
B(15,8,12,minecraft:blackstone)
B(7,8,13,minecraft:blackstone)
B(8,8,13,minecraft:blackstone)
B(9,8,13,minecraft:blackstone)
B(10,8,13,minecraft:blackstone)
B(11,8,13,minecraft:blackstone)
B(12,8,13,minecraft:lava[level=8])
B(13,8,13,minecraft:lava[level=8])
B(14,8,13,minecraft:blackstone)
B(15,8,13,minecraft:blackstone)
B(6,8,14,minecraft:blackstone)
B(7,8,14,minecraft:blackstone)
B(8,8,14,minecraft:blackstone)
B(9,8,14,minecraft:blackstone)
B(10,8,14,minecraft:blackstone)
B(11,8,14,minecraft:blackstone)
B(12,8,14,minecraft:blackstone)
B(13,8,14,minecraft:blackstone)
B(14,8,14,minecraft:blackstone)
B(15,8,14,minecraft:blackstone)
B(5,8,15,minecraft:blackstone)
B(6,8,15,minecraft:blackstone)
B(7,8,15,minecraft:blackstone)
B(8,8,15,minecraft:blackstone)
B(9,8,15,minecraft:blackstone)
B(10,8,15,minecraft:blackstone)
B(11,8,15,minecraft:blackstone)
B(12,8,15,minecraft:blackstone)
B(13,8,15,minecraft:blackstone)
B(14,8,15,minecraft:blackstone)
B(15,8,15,minecraft:blackstone)
B(14,9,11,minecraft:lava[level=8])
B(15,9,11,minecraft:blackstone)
B(13,9,12,minecraft:lava[level=8])
B(14,9,12,minecraft:blackstone)
B(15,9,12,minecraft:blackstone)
B(7,9,13,minecraft:blackstone)
B(8,9,13,minecraft:blackstone)
B(9,9,13,minecraft:blackstone)
B(10,9,13,minecraft:blackstone)
B(11,9,13,minecraft:blackstone)
B(12,9,13,minecraft:lava[level=8])
B(13,9,13,minecraft:lava[level=8])
B(14,9,13,minecraft:blackstone)
B(15,9,13,minecraft:blackstone)
B(6,9,14,minecraft:blackstone)
B(7,9,14,minecraft:blackstone)
B(8,9,14,minecraft:blackstone)
B(9,9,14,minecraft:blackstone)
B(10,9,14,minecraft:blackstone)
B(11,9,14,minecraft:blackstone)
B(12,9,14,minecraft:blackstone)
B(13,9,14,minecraft:lava[level=8])
B(14,9,14,minecraft:blackstone)
B(15,9,14,minecraft:blackstone)
B(5,9,15,minecraft:blackstone)
B(6,9,15,minecraft:blackstone)
B(7,9,15,minecraft:blackstone)
B(8,9,15,minecraft:blackstone)
B(9,9,15,minecraft:blackstone)
B(10,9,15,minecraft:blackstone)
B(11,9,15,minecraft:blackstone)
B(12,9,15,minecraft:blackstone)
B(13,9,15,minecraft:blackstone)
B(14,9,15,minecraft:blackstone)
B(15,9,15,minecraft:blackstone)
B(14,10,11,minecraft:lava[level=8])
B(15,10,11,minecraft:blackstone)
B(13,10,12,minecraft:lava[level=8])
B(14,10,12,minecraft:blackstone)
B(15,10,12,minecraft:blackstone)
B(8,10,13,minecraft:blackstone)
B(9,10,13,minecraft:blackstone)
B(10,10,13,minecraft:blackstone)
B(11,10,13,minecraft:blackstone)
B(12,10,13,minecraft:lava[level=8])
B(13,10,13,minecraft:lava[level=8])
B(14,10,13,minecraft:blackstone)
B(15,10,13,minecraft:blackstone)
B(6,10,14,minecraft:blackstone)
B(7,10,14,minecraft:blackstone)
B(8,10,14,minecraft:blackstone)
B(9,10,14,minecraft:blackstone)
B(10,10,14,minecraft:blackstone)
B(11,10,14,minecraft:blackstone)
B(12,10,14,minecraft:blackstone)
B(13,10,14,minecraft:lava[level=8])
B(14,10,14,minecraft:blackstone)
B(15,10,14,minecraft:blackstone)
B(5,10,15,minecraft:blackstone)
B(6,10,15,minecraft:blackstone)
B(7,10,15,minecraft:blackstone)
B(8,10,15,minecraft:blackstone)
B(9,10,15,minecraft:blackstone)
B(10,10,15,minecraft:blackstone)
B(11,10,15,minecraft:blackstone)
B(12,10,15,minecraft:blackstone)
B(13,10,15,minecraft:blackstone)
B(14,10,15,minecraft:blackstone)
B(15,10,15,minecraft:blackstone)
B(14,11,11,minecraft:lava[level=2])
B(15,11,11,minecraft:blackstone)
B(13,11,12,minecraft:lava[level=2])
B(14,11,12,minecraft:lava[level=8])
B(15,11,12,minecraft:blackstone)
B(8,11,13,minecraft:blackstone)
B(10,11,13,minecraft:blackstone)
B(12,11,13,minecraft:lava[level=8])
B(13,11,13,minecraft:lava[level=8])
B(14,11,13,minecraft:blackstone)
B(15,11,13,minecraft:blackstone)
B(6,11,14,minecraft:blackstone)
B(7,11,14,minecraft:blackstone)
B(8,11,14,minecraft:blackstone)
B(9,11,14,minecraft:blackstone)
B(10,11,14,minecraft:blackstone)
B(11,11,14,minecraft:blackstone)
B(12,11,14,minecraft:blackstone)
B(13,11,14,minecraft:lava[level=8])
B(14,11,14,minecraft:blackstone)
B(15,11,14,minecraft:blackstone)
B(5,11,15,minecraft:blackstone)
B(6,11,15,minecraft:blackstone)
B(7,11,15,minecraft:blackstone)
B(8,11,15,minecraft:blackstone)
B(9,11,15,minecraft:blackstone)
B(10,11,15,minecraft:blackstone)
B(11,11,15,minecraft:blackstone)
B(12,11,15,minecraft:blackstone)
B(13,11,15,minecraft:blackstone)
B(14,11,15,minecraft:blackstone)
B(15,11,15,minecraft:blackstone)
B(14,12,12,minecraft:lava[level=2])
B(15,12,12,minecraft:blackstone)
B(12,12,13,minecraft:lava[level=8])
B(13,12,13,minecraft:lava[level=2])
B(14,12,13,minecraft:lava[level=8])
B(15,12,13,minecraft:blackstone)
B(6,12,14,minecraft:blackstone)
B(7,12,14,minecraft:blackstone)
B(8,12,14,minecraft:blackstone)
B(9,12,14,minecraft:blackstone)
B(10,12,14,minecraft:blackstone)
B(11,12,14,minecraft:blackstone)
B(12,12,14,minecraft:blackstone)
B(13,12,14,minecraft:lava[level=8])
B(14,12,14,minecraft:blackstone)
B(15,12,14,minecraft:blackstone)
B(5,12,15,minecraft:blackstone)
B(6,12,15,minecraft:blackstone)
B(7,12,15,minecraft:blackstone)
B(8,12,15,minecraft:blackstone)
B(9,12,15,minecraft:blackstone)
B(10,12,15,minecraft:blackstone)
B(11,12,15,minecraft:blackstone)
B(12,12,15,minecraft:blackstone)
B(13,12,15,minecraft:blackstone)
B(14,12,15,minecraft:blackstone)
B(15,12,15,minecraft:blackstone)
B(12,13,13,minecraft:lava[level=2])
B(14,13,13,minecraft:lava[level=8])
B(7,13,14,minecraft:blackstone)
B(8,13,14,minecraft:blackstone)
B(9,13,14,minecraft:blackstone)
B(10,13,14,minecraft:blackstone)
B(11,13,14,minecraft:blackstone)
B(12,13,14,minecraft:lava[level=8])
B(13,13,14,minecraft:lava[level=8])
B(14,13,14,minecraft:blackstone)
B(15,13,14,minecraft:blackstone)
B(6,13,15,minecraft:blackstone)
B(7,13,15,minecraft:blackstone)
B(8,13,15,minecraft:blackstone)
B(9,13,15,minecraft:blackstone)
B(10,13,15,minecraft:blackstone)
B(11,13,15,minecraft:blackstone)
B(12,13,15,minecraft:blackstone)
B(13,13,15,minecraft:blackstone)
B(14,13,15,minecraft:blackstone)
B(15,13,15,minecraft:blackstone)
B(14,14,13,minecraft:lava[level=8])
B(12,14,14,minecraft:lava[level=2])
B(13,14,14,minecraft:lava[level=8])
B(14,14,14,minecraft:blackstone)
B(15,14,14,minecraft:blackstone)
B(7,14,15,minecraft:blackstone)
B(8,14,15,minecraft:blackstone)
B(9,14,15,minecraft:blackstone)
B(10,14,15,minecraft:blackstone)
B(11,14,15,minecraft:blackstone)
B(12,14,15,minecraft:lava[level=8])
B(13,14,15,minecraft:blackstone)
B(14,14,15,minecraft:blackstone)
B(15,14,15,minecraft:blackstone)
B(14,15,13,minecraft:lava[level=2])
B(13,15,14,minecraft:lava[level=8])
B(14,15,14,minecraft:lava[level=8])
B(15,15,14,minecraft:blackstone)
B(7,15,15,minecraft:blackstone)
B(8,15,15,minecraft:blackstone)
B(9,15,15,minecraft:blackstone)
B(10,15,15,minecraft:blackstone)
B(11,15,15,minecraft:blackstone)
B(12,15,15,minecraft:lava[level=8])
B(13,15,15,minecraft:blackstone)
B(14,15,15,minecraft:blackstone)
B(15,15,15,minecraft:blackstone)
B(13,16,14,minecraft:lava[level=8])
B(14,16,14,minecraft:lava[level=8])
B(15,16,14,minecraft:blackstone)
B(7,16,15,minecraft:blackstone)
B(8,16,15,minecraft:blackstone)
B(9,16,15,minecraft:blackstone)
B(10,16,15,minecraft:blackstone)
B(11,16,15,minecraft:blackstone)
B(12,16,15,minecraft:lava[level=8])
B(13,16,15,minecraft:blackstone)
B(14,16,15,minecraft:blackstone)
B(15,16,15,minecraft:blackstone)
B(13,17,14,minecraft:lava[level=8])
B(14,17,14,minecraft:lava[level=8])
B(15,17,14,minecraft:blackstone)
B(7,17,15,minecraft:blackstone)
B(8,17,15,minecraft:blackstone)
B(9,17,15,minecraft:blackstone)
B(10,17,15,minecraft:blackstone)
B(11,17,15,minecraft:blackstone)
B(12,17,15,minecraft:lava[level=8])
B(13,17,15,minecraft:blackstone)
B(14,17,15,minecraft:blackstone)
B(15,17,15,minecraft:blackstone)
B(13,18,14,minecraft:lava[level=2])
B(14,18,14,minecraft:lava[level=8])
B(8,18,15,minecraft:blackstone)
B(9,18,15,minecraft:blackstone)
B(10,18,15,minecraft:blackstone)
B(12,18,15,minecraft:lava[level=8])
B(13,18,15,minecraft:lava[level=8])
B(14,18,15,minecraft:blackstone)
B(15,18,15,minecraft:blackstone)
B(14,19,14,minecraft:lava[level=2])
B(12,19,15,minecraft:lava[level=8])
B(13,19,15,minecraft:lava[level=8])
B(14,19,15,minecraft:lava[level=8])
B(15,19,15,minecraft:blackstone)
B(12,20,15,minecraft:lava[level=2])
B(13,20,15,minecraft:lava[level=8])
B(14,20,15,minecraft:lava[level=8])
B(15,20,15,minecraft:blackstone)
B(13,21,15,minecraft:lava[level=2])
B(14,21,15,minecraft:lava[level=8])
B(15,21,15,minecraft:blackstone)
B(14,22,15,minecraft:lava[level=2])
B(15,22,15,minecraft:blackstone)
B(15,23,15,minecraft:blackstone)
B(15,24,15,minecraft:blackstone)

BR(-16,0,0,true,BlackstoneVolcano2_0x0,NORTH,100,0)
