
#######################################################################
# +-----------------------------------------------------------------+ #
# |                            BO4 object                           | #
# +-----------------------------------------------------------------+ #
#######################################################################

Author: Unknown

Description: No description given

SettingsMode: WriteWithoutComments


#######################################################################
# +-----------------------------------------------------------------+ #
# |                          Main settings                          | #
# +-----------------------------------------------------------------+ #
#######################################################################

FixedRotation: 

Frequency: 0

SpawnHeight: highestBlock

UseCenterForHighestBlock: true

##############################
# Height Limits for the BO4. #
##############################

MinHeight: 0

MaxHeight: 255

InheritBO3: 

InheritBO3Rotation: NORTH

OverrideChildSettings: true

OverrideParentHeight: false

CanOverride: false

BranchFrequency: 0

BranchFrequencyGroup: 

MustBeBelowOther: false

MustBeInside: 

CannotBeInside: 

ReplacesBO3: 

MustBeInsideWorldBorders: false

CanSpawnOnWater: true

SpawnOnWaterOnly: false

SpawnUnderWater: false

SpawnAtWaterLevel: false

HeightOffset: 0

RemoveAir: true

ReplaceAbove: 

ReplaceBelow: 

ReplaceWithBiomeBlocks: true

ReplaceWithSurfaceBlock: GRASS

ReplaceWithGroundBlock: DIRT

ReplaceWithStoneBlock: STONE

SmoothRadius: 0

SmoothHeightOffset: 0

SmoothStartTop: false

SmoothStartWood: false

SmoothingSurfaceBlock: 

SmoothingGroundBlock: 

BO3Group: 

IsSpawnPoint: false

DoReplaceBlocks: true


#######################################################################
# +-----------------------------------------------------------------+ #
# |                              Blocks                             | #
# +-----------------------------------------------------------------+ #
#######################################################################

B(-8,0,-7,minecraft:netherrack)
B(-8,1,-7,minecraft:netherrack)
B(-8,2,-7,minecraft:netherrack)
B(-8,3,-7,minecraft:soul_soil)
B(-8,4,-7,minecraft:soul_soil)
B(-8,5,-7,minecraft:soul_sand)
B(-8,0,-6,minecraft:netherrack)
B(-8,1,-6,minecraft:netherrack)
B(-8,2,-6,minecraft:netherrack)
B(-8,3,-6,minecraft:soul_soil)
B(-8,4,-6,minecraft:soul_soil)
B(-8,5,-6,minecraft:soul_sand)
B(-8,0,-5,minecraft:netherrack)
B(-8,1,-5,minecraft:netherrack)
B(-8,2,-5,minecraft:netherrack)
B(-8,3,-5,minecraft:soul_soil)
B(-8,4,-5,minecraft:soul_soil)
B(-8,5,-5,minecraft:soul_sand)
B(-8,0,-4,minecraft:netherrack)
B(-8,1,-4,minecraft:netherrack)
B(-8,2,-4,minecraft:netherrack)
B(-8,3,-4,minecraft:soul_soil)
B(-8,4,-4,minecraft:soul_soil)
B(-8,5,-4,minecraft:soul_sand)
B(-8,0,-3,minecraft:netherrack)
B(-8,1,-3,minecraft:netherrack)
B(-8,2,-3,minecraft:netherrack)
B(-8,3,-3,minecraft:soul_soil)
B(-8,4,-3,minecraft:soul_soil)
B(-8,5,-3,minecraft:soul_sand)
B(-8,0,-2,minecraft:netherrack)
B(-8,1,-2,minecraft:netherrack)
B(-8,2,-2,minecraft:soul_soil)
B(-8,3,-2,minecraft:soul_soil)
B(-8,4,-2,minecraft:soul_sand)
B(-8,0,-1,minecraft:netherrack)
B(-8,1,-1,minecraft:netherrack)
B(-8,2,-1,minecraft:soul_soil)
B(-8,3,-1,minecraft:soul_soil)
B(-8,4,-1,minecraft:soul_sand)
B(-8,0,0,minecraft:netherrack)
B(-8,1,0,minecraft:soul_soil)
B(-8,2,0,minecraft:soul_soil)
B(-8,3,0,minecraft:soul_sand)
B(-8,0,1,minecraft:netherrack)
B(-8,1,1,minecraft:soul_soil)
B(-8,2,1,minecraft:soul_soil)
B(-8,3,1,minecraft:soul_sand)
B(-8,0,2,minecraft:netherrack)
B(-8,1,2,minecraft:soul_soil)
B(-8,2,2,minecraft:soul_soil)
B(-8,3,2,minecraft:soul_sand)
B(-8,0,3,minecraft:soul_soil)
B(-8,1,3,minecraft:soul_soil)
B(-8,2,3,minecraft:soul_sand)
B(-8,0,4,minecraft:soul_soil)
B(-8,1,4,minecraft:soul_soil)
B(-8,2,4,minecraft:soul_sand)
B(-8,0,5,minecraft:soul_soil)
B(-8,1,5,minecraft:soul_soil)
B(-8,2,5,minecraft:soul_sand)
B(-8,0,6,minecraft:soul_soil)
B(-8,1,6,minecraft:soul_soil)
B(-8,2,6,minecraft:soul_sand)
B(-8,0,7,minecraft:soul_soil)
B(-8,1,7,minecraft:soul_soil)
B(-8,2,7,minecraft:soul_sand)
B(-8,0,8,minecraft:soul_soil)
B(-8,1,8,minecraft:soul_soil)
B(-8,2,8,minecraft:soul_sand)
B(-7,0,-7,minecraft:netherrack)
B(-7,1,-7,minecraft:netherrack)
B(-7,2,-7,minecraft:netherrack)
B(-7,3,-7,minecraft:soul_soil)
B(-7,4,-7,minecraft:soul_soil)
B(-7,5,-7,minecraft:soul_sand)
B(-7,0,-6,minecraft:netherrack)
B(-7,1,-6,minecraft:netherrack)
B(-7,2,-6,minecraft:netherrack)
B(-7,3,-6,minecraft:soul_soil)
B(-7,4,-6,minecraft:soul_soil)
B(-7,5,-6,minecraft:soul_sand)
B(-7,0,-5,minecraft:netherrack)
B(-7,1,-5,minecraft:netherrack)
B(-7,2,-5,minecraft:netherrack)
B(-7,3,-5,minecraft:soul_soil)
B(-7,4,-5,minecraft:soul_soil)
B(-7,5,-5,minecraft:soul_sand)
B(-7,0,-4,minecraft:netherrack)
B(-7,1,-4,minecraft:netherrack)
B(-7,2,-4,minecraft:soul_soil)
B(-7,3,-4,minecraft:soul_soil)
B(-7,4,-4,minecraft:soul_sand)
B(-7,0,-3,minecraft:netherrack)
B(-7,1,-3,minecraft:netherrack)
B(-7,2,-3,minecraft:soul_soil)
B(-7,3,-3,minecraft:soul_soil)
B(-7,4,-3,minecraft:soul_sand)
B(-7,0,-2,minecraft:netherrack)
B(-7,1,-2,minecraft:netherrack)
B(-7,2,-2,minecraft:soul_soil)
B(-7,3,-2,minecraft:soul_soil)
B(-7,4,-2,minecraft:soul_sand)
B(-7,0,-1,minecraft:netherrack)
B(-7,1,-1,minecraft:netherrack)
B(-7,2,-1,minecraft:soul_soil)
B(-7,3,-1,minecraft:soul_soil)
B(-7,4,-1,minecraft:soul_sand)
B(-7,0,0,minecraft:netherrack)
B(-7,1,0,minecraft:soul_soil)
B(-7,2,0,minecraft:soul_soil)
B(-7,3,0,minecraft:soul_sand)
B(-7,0,1,minecraft:netherrack)
B(-7,1,1,minecraft:soul_soil)
B(-7,2,1,minecraft:soul_soil)
B(-7,3,1,minecraft:soul_sand)
B(-7,0,2,minecraft:soul_soil)
B(-7,1,2,minecraft:soul_soil)
B(-7,2,2,minecraft:soul_sand)
B(-7,0,3,minecraft:soul_soil)
B(-7,1,3,minecraft:soul_soil)
B(-7,2,3,minecraft:soul_sand)
B(-7,0,4,minecraft:soul_soil)
B(-7,1,4,minecraft:soul_soil)
B(-7,2,4,minecraft:soul_sand)
B(-7,0,5,minecraft:soul_soil)
B(-7,1,5,minecraft:soul_soil)
B(-7,2,5,minecraft:soul_sand)
B(-7,0,6,minecraft:soul_soil)
B(-7,1,6,minecraft:soul_soil)
B(-7,2,6,minecraft:soul_sand)
B(-7,0,7,minecraft:soul_soil)
B(-7,1,7,minecraft:soul_soil)
B(-7,2,7,minecraft:soul_sand)
B(-7,0,8,minecraft:netherrack)
B(-7,1,8,minecraft:soul_soil)
B(-7,2,8,minecraft:soul_sand)
B(-6,0,-7,minecraft:netherrack)
B(-6,1,-7,minecraft:netherrack)
B(-6,2,-7,minecraft:netherrack)
B(-6,3,-7,minecraft:soul_soil)
B(-6,4,-7,minecraft:soul_soil)
B(-6,5,-7,minecraft:soul_sand)
B(-6,0,-6,minecraft:netherrack)
B(-6,1,-6,minecraft:netherrack)
B(-6,2,-6,minecraft:netherrack)
B(-6,3,-6,minecraft:soul_soil)
B(-6,4,-6,minecraft:soul_soil)
B(-6,5,-6,minecraft:soul_sand)
B(-6,0,-5,minecraft:netherrack)
B(-6,1,-5,minecraft:netherrack)
B(-6,2,-5,minecraft:netherrack)
B(-6,3,-5,minecraft:soul_soil)
B(-6,4,-5,minecraft:soul_soil)
B(-6,5,-5,minecraft:soul_sand)
B(-6,0,-4,minecraft:netherrack)
B(-6,1,-4,minecraft:netherrack)
B(-6,2,-4,minecraft:soul_soil)
B(-6,3,-4,minecraft:soul_soil)
B(-6,4,-4,minecraft:soul_sand)
B(-6,0,-3,minecraft:netherrack)
B(-6,1,-3,minecraft:netherrack)
B(-6,2,-3,minecraft:soul_soil)
B(-6,3,-3,minecraft:soul_soil)
B(-6,4,-3,minecraft:soul_sand)
B(-6,0,-2,minecraft:netherrack)
B(-6,1,-2,minecraft:netherrack)
B(-6,2,-2,minecraft:soul_soil)
B(-6,3,-2,minecraft:soul_soil)
B(-6,4,-2,minecraft:soul_sand)
B(-6,0,-1,minecraft:netherrack)
B(-6,1,-1,minecraft:soul_soil)
B(-6,2,-1,minecraft:soul_soil)
B(-6,3,-1,minecraft:soul_sand)
B(-6,0,0,minecraft:netherrack)
B(-6,1,0,minecraft:soul_soil)
B(-6,2,0,minecraft:soul_soil)
B(-6,3,0,minecraft:soul_sand)
B(-6,0,1,minecraft:netherrack)
B(-6,1,1,minecraft:soul_soil)
B(-6,2,1,minecraft:soul_soil)
B(-6,3,1,minecraft:soul_sand)
B(-6,0,2,minecraft:soul_soil)
B(-6,1,2,minecraft:soul_soil)
B(-6,2,2,minecraft:soul_sand)
B(-6,0,3,minecraft:soul_soil)
B(-6,1,3,minecraft:soul_soil)
B(-6,2,3,minecraft:soul_sand)
B(-6,0,4,minecraft:soul_soil)
B(-6,1,4,minecraft:soul_soil)
B(-6,2,4,minecraft:soul_sand)
B(-6,0,5,minecraft:soul_soil)
B(-6,1,5,minecraft:soul_soil)
B(-6,2,5,minecraft:soul_sand)
B(-6,0,6,minecraft:netherrack)
B(-6,1,6,minecraft:soul_soil)
B(-6,2,6,minecraft:soul_sand)
B(-6,0,7,minecraft:soul_soil)
B(-6,1,7,minecraft:soul_soil)
B(-6,2,7,minecraft:soul_sand)
B(-6,0,8,minecraft:soul_soil)
B(-6,1,8,minecraft:soul_soil)
B(-6,2,8,minecraft:soul_sand)
B(-5,0,-7,minecraft:netherrack)
B(-5,1,-7,minecraft:netherrack)
B(-5,2,-7,minecraft:netherrack)
B(-5,3,-7,minecraft:soul_soil)
B(-5,4,-7,minecraft:soul_soil)
B(-5,5,-7,minecraft:soul_sand)
B(-5,0,-6,minecraft:netherrack)
B(-5,1,-6,minecraft:netherrack)
B(-5,2,-6,minecraft:netherrack)
B(-5,3,-6,minecraft:soul_soil)
B(-5,4,-6,minecraft:soul_soil)
B(-5,5,-6,minecraft:soul_sand)
B(-5,0,-5,minecraft:netherrack)
B(-5,1,-5,minecraft:netherrack)
B(-5,2,-5,minecraft:netherrack)
B(-5,3,-5,minecraft:soul_soil)
B(-5,4,-5,minecraft:soul_soil)
B(-5,5,-5,minecraft:soul_sand)
B(-5,0,-4,minecraft:netherrack)
B(-5,1,-4,minecraft:netherrack)
B(-5,2,-4,minecraft:soul_soil)
B(-5,3,-4,minecraft:soul_soil)
B(-5,4,-4,minecraft:soul_sand)
B(-5,0,-3,minecraft:netherrack)
B(-5,1,-3,minecraft:netherrack)
B(-5,2,-3,minecraft:soul_soil)
B(-5,3,-3,minecraft:soul_soil)
B(-5,4,-3,minecraft:soul_sand)
B(-5,0,-2,minecraft:netherrack)
B(-5,1,-2,minecraft:netherrack)
B(-5,2,-2,minecraft:soul_soil)
B(-5,3,-2,minecraft:soul_soil)
B(-5,4,-2,minecraft:soul_sand)
B(-5,0,-1,minecraft:netherrack)
B(-5,1,-1,minecraft:soul_soil)
B(-5,2,-1,minecraft:soul_soil)
B(-5,3,-1,minecraft:soul_sand)
B(-5,0,0,minecraft:netherrack)
B(-5,1,0,minecraft:soul_soil)
B(-5,2,0,minecraft:soul_soil)
B(-5,3,0,minecraft:soul_sand)
B(-5,0,1,minecraft:netherrack)
B(-5,1,1,minecraft:soul_soil)
B(-5,2,1,minecraft:soul_soil)
B(-5,3,1,minecraft:soul_sand)
B(-5,0,2,minecraft:soul_soil)
B(-5,1,2,minecraft:soul_soil)
B(-5,2,2,minecraft:soul_sand)
B(-5,0,3,minecraft:soul_soil)
B(-5,1,3,minecraft:soul_soil)
B(-5,2,3,minecraft:soul_sand)
B(-5,0,4,minecraft:soul_soil)
B(-5,1,4,minecraft:soul_soil)
B(-5,2,4,minecraft:soul_sand)
B(-5,0,5,minecraft:soul_soil)
B(-5,1,5,minecraft:soul_soil)
B(-5,2,5,minecraft:soul_sand)
B(-5,0,6,minecraft:soul_soil)
B(-5,1,6,minecraft:soul_soil)
B(-5,2,6,minecraft:soul_sand)
B(-5,0,7,minecraft:soul_soil)
B(-5,1,7,minecraft:soul_soil)
B(-5,2,7,minecraft:soul_sand)
B(-5,0,8,minecraft:netherrack)
B(-5,1,8,minecraft:soul_soil)
B(-5,2,8,minecraft:soul_sand)
B(-4,0,-7,minecraft:netherrack)
B(-4,1,-7,minecraft:netherrack)
B(-4,2,-7,minecraft:netherrack)
B(-4,3,-7,minecraft:soul_soil)
B(-4,4,-7,minecraft:soul_soil)
B(-4,5,-7,minecraft:soul_sand)
B(-4,0,-6,minecraft:netherrack)
B(-4,1,-6,minecraft:netherrack)
B(-4,2,-6,minecraft:netherrack)
B(-4,3,-6,minecraft:soul_soil)
B(-4,4,-6,minecraft:soul_soil)
B(-4,5,-6,minecraft:soul_sand)
B(-4,0,-5,minecraft:netherrack)
B(-4,1,-5,minecraft:netherrack)
B(-4,2,-5,minecraft:netherrack)
B(-4,3,-5,minecraft:soul_soil)
B(-4,4,-5,minecraft:soul_soil)
B(-4,5,-5,minecraft:soul_sand)
B(-4,0,-4,minecraft:netherrack)
B(-4,1,-4,minecraft:netherrack)
B(-4,2,-4,minecraft:soul_soil)
B(-4,3,-4,minecraft:soul_soil)
B(-4,4,-4,minecraft:soul_sand)
B(-4,0,-3,minecraft:netherrack)
B(-4,1,-3,minecraft:netherrack)
B(-4,2,-3,minecraft:soul_soil)
B(-4,3,-3,minecraft:soul_soil)
B(-4,4,-3,minecraft:soul_sand)
B(-4,0,-2,minecraft:netherrack)
B(-4,1,-2,minecraft:netherrack)
B(-4,2,-2,minecraft:soul_soil)
B(-4,3,-2,minecraft:soul_soil)
B(-4,4,-2,minecraft:soul_sand)
B(-4,0,-1,minecraft:netherrack)
B(-4,1,-1,minecraft:soul_soil)
B(-4,2,-1,minecraft:soul_soil)
B(-4,3,-1,minecraft:soul_sand)
B(-4,0,0,minecraft:netherrack)
B(-4,1,0,minecraft:soul_soil)
B(-4,2,0,minecraft:soul_soil)
B(-4,3,0,minecraft:soul_sand)
B(-4,0,1,minecraft:netherrack)
B(-4,1,1,minecraft:soul_soil)
B(-4,2,1,minecraft:soul_soil)
B(-4,3,1,minecraft:soul_sand)
B(-4,0,2,minecraft:soul_soil)
B(-4,1,2,minecraft:soul_soil)
B(-4,2,2,minecraft:soul_sand)
B(-4,0,3,minecraft:soul_soil)
B(-4,1,3,minecraft:soul_soil)
B(-4,2,3,minecraft:soul_sand)
B(-4,0,4,minecraft:soul_soil)
B(-4,1,4,minecraft:soul_soil)
B(-4,2,4,minecraft:soul_sand)
B(-4,0,5,minecraft:soul_soil)
B(-4,1,5,minecraft:soul_soil)
B(-4,2,5,minecraft:soul_sand)
B(-4,0,6,minecraft:soul_soil)
B(-4,1,6,minecraft:soul_soil)
B(-4,2,6,minecraft:soul_sand)
B(-4,0,7,minecraft:netherrack)
B(-4,1,7,minecraft:soul_soil)
B(-4,2,7,minecraft:soul_sand)
B(-4,0,8,minecraft:netherrack)
B(-4,1,8,minecraft:soul_soil)
B(-4,2,8,minecraft:soul_sand)
B(-3,0,-7,minecraft:netherrack)
B(-3,1,-7,minecraft:netherrack)
B(-3,2,-7,minecraft:netherrack)
B(-3,3,-7,minecraft:soul_soil)
B(-3,4,-7,minecraft:soul_soil)
B(-3,5,-7,minecraft:soul_sand)
B(-3,0,-6,minecraft:netherrack)
B(-3,1,-6,minecraft:netherrack)
B(-3,2,-6,minecraft:netherrack)
B(-3,3,-6,minecraft:soul_soil)
B(-3,4,-6,minecraft:soul_soil)
B(-3,5,-6,minecraft:soul_sand)
B(-3,0,-5,minecraft:netherrack)
B(-3,1,-5,minecraft:netherrack)
B(-3,2,-5,minecraft:netherrack)
B(-3,3,-5,minecraft:soul_soil)
B(-3,4,-5,minecraft:soul_soil)
B(-3,5,-5,minecraft:soul_sand)
B(-3,0,-4,minecraft:netherrack)
B(-3,1,-4,minecraft:netherrack)
B(-3,2,-4,minecraft:soul_soil)
B(-3,3,-4,minecraft:soul_soil)
B(-3,4,-4,minecraft:soul_sand)
B(-3,0,-3,minecraft:netherrack)
B(-3,1,-3,minecraft:netherrack)
B(-3,2,-3,minecraft:soul_soil)
B(-3,3,-3,minecraft:soul_soil)
B(-3,4,-3,minecraft:soul_sand)
B(-3,0,-2,minecraft:netherrack)
B(-3,1,-2,minecraft:soul_soil)
B(-3,2,-2,minecraft:soul_soil)
B(-3,3,-2,minecraft:soul_sand)
B(-3,0,-1,minecraft:netherrack)
B(-3,1,-1,minecraft:soul_soil)
B(-3,2,-1,minecraft:soul_soil)
B(-3,3,-1,minecraft:soul_sand)
B(-3,0,0,minecraft:netherrack)
B(-3,1,0,minecraft:soul_soil)
B(-3,2,0,minecraft:soul_soil)
B(-3,3,0,minecraft:soul_sand)
B(-3,0,1,minecraft:netherrack)
B(-3,1,1,minecraft:soul_soil)
B(-3,2,1,minecraft:soul_soil)
B(-3,3,1,minecraft:soul_sand)
B(-3,0,2,minecraft:soul_soil)
B(-3,1,2,minecraft:soul_soil)
B(-3,2,2,minecraft:soul_sand)
B(-3,0,3,minecraft:soul_soil)
B(-3,1,3,minecraft:soul_soil)
B(-3,2,3,minecraft:soul_sand)
B(-3,0,4,minecraft:soul_soil)
B(-3,1,4,minecraft:soul_soil)
B(-3,2,4,minecraft:soul_sand)
B(-3,0,5,minecraft:soul_soil)
B(-3,1,5,minecraft:soul_soil)
B(-3,2,5,minecraft:soul_sand)
B(-3,0,6,minecraft:soul_soil)
B(-3,1,6,minecraft:soul_soil)
B(-3,2,6,minecraft:soul_sand)
B(-3,0,7,minecraft:soul_soil)
B(-3,1,7,minecraft:soul_soil)
B(-3,2,7,minecraft:soul_sand)
B(-3,0,8,minecraft:netherrack)
B(-3,1,8,minecraft:soul_soil)
B(-3,2,8,minecraft:soul_sand)
B(-2,0,-7,minecraft:netherrack)
B(-2,1,-7,minecraft:netherrack)
B(-2,2,-7,minecraft:netherrack)
B(-2,3,-7,minecraft:soul_soil)
B(-2,4,-7,minecraft:soul_soil)
B(-2,5,-7,minecraft:soul_sand)
B(-2,0,-6,minecraft:netherrack)
B(-2,1,-6,minecraft:netherrack)
B(-2,2,-6,minecraft:netherrack)
B(-2,3,-6,minecraft:soul_soil)
B(-2,4,-6,minecraft:soul_soil)
B(-2,5,-6,minecraft:soul_sand)
B(-2,0,-5,minecraft:netherrack)
B(-2,1,-5,minecraft:netherrack)
B(-2,2,-5,minecraft:netherrack)
B(-2,3,-5,minecraft:soul_soil)
B(-2,4,-5,minecraft:soul_soil)
B(-2,5,-5,minecraft:soul_sand)
B(-2,0,-4,minecraft:netherrack)
B(-2,1,-4,minecraft:netherrack)
B(-2,2,-4,minecraft:netherrack)
B(-2,3,-4,minecraft:soul_soil)
B(-2,4,-4,minecraft:soul_soil)
B(-2,5,-4,minecraft:soul_sand)
B(-2,0,-3,minecraft:netherrack)
B(-2,1,-3,minecraft:netherrack)
B(-2,2,-3,minecraft:soul_soil)
B(-2,3,-3,minecraft:soul_soil)
B(-2,4,-3,minecraft:soul_sand)
B(-2,0,-2,minecraft:netherrack)
B(-2,1,-2,minecraft:soul_soil)
B(-2,2,-2,minecraft:soul_soil)
B(-2,3,-2,minecraft:soul_sand)
B(-2,0,-1,minecraft:netherrack)
B(-2,1,-1,minecraft:soul_soil)
B(-2,2,-1,minecraft:soul_soil)
B(-2,3,-1,minecraft:soul_sand)
B(-2,0,0,minecraft:netherrack)
B(-2,1,0,minecraft:soul_soil)
B(-2,2,0,minecraft:soul_soil)
B(-2,3,0,minecraft:soul_sand)
B(-2,0,1,minecraft:soul_soil)
B(-2,1,1,minecraft:soul_soil)
B(-2,2,1,minecraft:soul_sand)
B(-2,0,2,minecraft:soul_soil)
B(-2,1,2,minecraft:soul_soil)
B(-2,2,2,minecraft:soul_sand)
B(-2,0,3,minecraft:soul_soil)
B(-2,1,3,minecraft:soul_soil)
B(-2,2,3,minecraft:soul_sand)
B(-2,0,4,minecraft:soul_soil)
B(-2,1,4,minecraft:soul_soil)
B(-2,2,4,minecraft:soul_sand)
B(-2,0,5,minecraft:soul_soil)
B(-2,1,5,minecraft:soul_soil)
B(-2,2,5,minecraft:soul_sand)
B(-2,0,6,minecraft:soul_soil)
B(-2,1,6,minecraft:soul_soil)
B(-2,2,6,minecraft:soul_sand)
B(-2,0,7,minecraft:soul_soil)
B(-2,1,7,minecraft:soul_soil)
B(-2,2,7,minecraft:soul_sand)
B(-2,0,8,minecraft:netherrack)
B(-2,1,8,minecraft:soul_soil)
B(-2,2,8,minecraft:soul_soil)
B(-2,3,8,minecraft:soul_sand)
B(-1,0,-7,minecraft:netherrack)
B(-1,1,-7,minecraft:netherrack)
B(-1,2,-7,minecraft:netherrack)
B(-1,3,-7,minecraft:soul_soil)
B(-1,4,-7,minecraft:soul_soil)
B(-1,5,-7,minecraft:soul_sand)
B(-1,0,-6,minecraft:netherrack)
B(-1,1,-6,minecraft:netherrack)
B(-1,2,-6,minecraft:netherrack)
B(-1,3,-6,minecraft:soul_soil)
B(-1,4,-6,minecraft:soul_soil)
B(-1,5,-6,minecraft:soul_sand)
B(-1,0,-5,minecraft:netherrack)
B(-1,1,-5,minecraft:netherrack)
B(-1,2,-5,minecraft:netherrack)
B(-1,3,-5,minecraft:soul_soil)
B(-1,4,-5,minecraft:soul_soil)
B(-1,5,-5,minecraft:soul_sand)
B(-1,0,-4,minecraft:netherrack)
B(-1,1,-4,minecraft:netherrack)
B(-1,2,-4,minecraft:netherrack)
B(-1,3,-4,minecraft:soul_soil)
B(-1,4,-4,minecraft:soul_soil)
B(-1,5,-4,minecraft:soul_sand)
B(-1,0,-3,minecraft:netherrack)
B(-1,1,-3,minecraft:netherrack)
B(-1,2,-3,minecraft:soul_soil)
B(-1,3,-3,minecraft:soul_soil)
B(-1,4,-3,minecraft:soul_sand)
B(-1,0,-2,minecraft:netherrack)
B(-1,1,-2,minecraft:netherrack)
B(-1,2,-2,minecraft:soul_soil)
B(-1,3,-2,minecraft:soul_soil)
B(-1,4,-2,minecraft:soul_sand)
B(-1,0,-1,minecraft:netherrack)
B(-1,1,-1,minecraft:soul_soil)
B(-1,2,-1,minecraft:soul_soil)
B(-1,3,-1,minecraft:soul_sand)
B(-1,0,0,minecraft:netherrack)
B(-1,1,0,minecraft:soul_soil)
B(-1,2,0,minecraft:soul_soil)
B(-1,3,0,minecraft:soul_sand)
B(-1,0,1,minecraft:netherrack)
B(-1,1,1,minecraft:soul_soil)
B(-1,2,1,minecraft:soul_soil)
B(-1,3,1,minecraft:soul_sand)
B(-1,0,2,minecraft:netherrack)
B(-1,1,2,minecraft:soul_soil)
B(-1,2,2,minecraft:soul_soil)
B(-1,3,2,minecraft:soul_sand)
B(-1,0,3,minecraft:netherrack)
B(-1,1,3,minecraft:soul_soil)
B(-1,2,3,minecraft:soul_soil)
B(-1,3,3,minecraft:soul_sand)
B(-1,0,4,minecraft:netherrack)
B(-1,1,4,minecraft:soul_soil)
B(-1,2,4,minecraft:soul_soil)
B(-1,3,4,minecraft:soul_sand)
B(-1,0,5,minecraft:netherrack)
B(-1,1,5,minecraft:soul_soil)
B(-1,2,5,minecraft:soul_soil)
B(-1,3,5,minecraft:soul_sand)
B(-1,0,6,minecraft:netherrack)
B(-1,1,6,minecraft:soul_soil)
B(-1,2,6,minecraft:soul_soil)
B(-1,3,6,minecraft:soul_sand)
B(-1,0,7,minecraft:netherrack)
B(-1,1,7,minecraft:soul_soil)
B(-1,2,7,minecraft:soul_soil)
B(-1,3,7,minecraft:soul_sand)
B(-1,0,8,minecraft:netherrack)
B(-1,1,8,minecraft:soul_soil)
B(-1,2,8,minecraft:soul_soil)
B(-1,3,8,minecraft:soul_sand)
B(0,0,-7,minecraft:netherrack)
B(0,1,-7,minecraft:netherrack)
B(0,2,-7,minecraft:netherrack)
B(0,3,-7,minecraft:soul_soil)
B(0,4,-7,minecraft:soul_soil)
B(0,5,-7,minecraft:soul_sand)
B(0,0,-6,minecraft:netherrack)
B(0,1,-6,minecraft:netherrack)
B(0,2,-6,minecraft:netherrack)
B(0,3,-6,minecraft:soul_soil)
B(0,4,-6,minecraft:soul_soil)
B(0,5,-6,minecraft:soul_sand)
B(0,0,-5,minecraft:netherrack)
B(0,1,-5,minecraft:netherrack)
B(0,2,-5,minecraft:netherrack)
B(0,3,-5,minecraft:soul_soil)
B(0,4,-5,minecraft:soul_soil)
B(0,5,-5,minecraft:soul_sand)
B(0,0,-4,minecraft:netherrack)
B(0,1,-4,minecraft:netherrack)
B(0,2,-4,minecraft:netherrack)
B(0,3,-4,minecraft:soul_soil)
B(0,4,-4,minecraft:soul_soil)
B(0,5,-4,minecraft:soul_sand)
B(0,0,-3,minecraft:netherrack)
B(0,1,-3,minecraft:netherrack)
B(0,2,-3,minecraft:soul_soil)
B(0,3,-3,minecraft:soul_soil)
B(0,4,-3,minecraft:soul_sand)
B(0,0,-2,minecraft:netherrack)
B(0,1,-2,minecraft:netherrack)
B(0,2,-2,minecraft:soul_soil)
B(0,3,-2,minecraft:soul_soil)
B(0,4,-2,minecraft:soul_sand)
B(0,0,-1,minecraft:netherrack)
B(0,1,-1,minecraft:netherrack)
B(0,2,-1,minecraft:soul_soil)
B(0,3,-1,minecraft:soul_soil)
B(0,4,-1,minecraft:soul_sand)
B(0,0,0,minecraft:netherrack)
B(0,1,0,minecraft:soul_soil)
B(0,2,0,minecraft:soul_soil)
B(0,3,0,minecraft:soul_sand)
B(0,0,1,minecraft:netherrack)
B(0,1,1,minecraft:soul_soil)
B(0,2,1,minecraft:soul_soil)
B(0,3,1,minecraft:soul_sand)
B(0,0,2,minecraft:netherrack)
B(0,1,2,minecraft:soul_soil)
B(0,2,2,minecraft:soul_soil)
B(0,3,2,minecraft:soul_sand)
B(0,0,3,minecraft:netherrack)
B(0,1,3,minecraft:soul_soil)
B(0,2,3,minecraft:soul_soil)
B(0,3,3,minecraft:soul_sand)
B(0,0,4,minecraft:netherrack)
B(0,1,4,minecraft:soul_soil)
B(0,2,4,minecraft:soul_soil)
B(0,3,4,minecraft:soul_sand)
B(0,0,5,minecraft:netherrack)
B(0,1,5,minecraft:netherrack)
B(0,2,5,minecraft:soul_soil)
B(0,3,5,minecraft:soul_soil)
B(0,4,5,minecraft:soul_sand)
B(0,0,6,minecraft:netherrack)
B(0,1,6,minecraft:netherrack)
B(0,2,6,minecraft:soul_soil)
B(0,3,6,minecraft:soul_soil)
B(0,4,6,minecraft:soul_sand)
B(0,0,7,minecraft:netherrack)
B(0,1,7,minecraft:soul_soil)
B(0,2,7,minecraft:soul_soil)
B(0,3,7,minecraft:soul_sand)
B(0,0,8,minecraft:netherrack)
B(0,1,8,minecraft:soul_soil)
B(0,2,8,minecraft:soul_soil)
B(0,3,8,minecraft:soul_sand)
B(1,0,-7,minecraft:netherrack)
B(1,1,-7,minecraft:netherrack)
B(1,2,-7,minecraft:netherrack)
B(1,3,-7,minecraft:soul_soil)
B(1,4,-7,minecraft:soul_soil)
B(1,5,-7,minecraft:soul_sand)
B(1,0,-6,minecraft:netherrack)
B(1,1,-6,minecraft:netherrack)
B(1,2,-6,minecraft:netherrack)
B(1,3,-6,minecraft:soul_soil)
B(1,4,-6,minecraft:soul_soil)
B(1,5,-6,minecraft:soul_sand)
B(1,0,-5,minecraft:netherrack)
B(1,1,-5,minecraft:netherrack)
B(1,2,-5,minecraft:netherrack)
B(1,3,-5,minecraft:soul_soil)
B(1,4,-5,minecraft:soul_soil)
B(1,5,-5,minecraft:soul_sand)
B(1,0,-4,minecraft:netherrack)
B(1,1,-4,minecraft:netherrack)
B(1,2,-4,minecraft:netherrack)
B(1,3,-4,minecraft:soul_soil)
B(1,4,-4,minecraft:soul_soil)
B(1,5,-4,minecraft:soul_sand)
B(1,0,-3,minecraft:netherrack)
B(1,1,-3,minecraft:netherrack)
B(1,2,-3,minecraft:netherrack)
B(1,3,-3,minecraft:soul_soil)
B(1,4,-3,minecraft:soul_soil)
B(1,5,-3,minecraft:soul_sand)
B(1,0,-2,minecraft:netherrack)
B(1,1,-2,minecraft:netherrack)
B(1,2,-2,minecraft:soul_soil)
B(1,3,-2,minecraft:soul_soil)
B(1,4,-2,minecraft:soul_sand)
B(1,0,-1,minecraft:netherrack)
B(1,1,-1,minecraft:netherrack)
B(1,2,-1,minecraft:soul_soil)
B(1,3,-1,minecraft:soul_soil)
B(1,4,-1,minecraft:soul_sand)
B(1,0,0,minecraft:netherrack)
B(1,1,0,minecraft:netherrack)
B(1,2,0,minecraft:soul_soil)
B(1,3,0,minecraft:soul_soil)
B(1,4,0,minecraft:soul_sand)
B(1,0,1,minecraft:netherrack)
B(1,1,1,minecraft:soul_soil)
B(1,2,1,minecraft:soul_soil)
B(1,3,1,minecraft:soul_sand)
B(1,0,2,minecraft:netherrack)
B(1,1,2,minecraft:soul_soil)
B(1,2,2,minecraft:soul_soil)
B(1,3,2,minecraft:soul_sand)
B(1,0,3,minecraft:netherrack)
B(1,1,3,minecraft:netherrack)
B(1,2,3,minecraft:soul_soil)
B(1,3,3,minecraft:soul_soil)
B(1,4,3,minecraft:soul_sand)
B(1,0,4,minecraft:netherrack)
B(1,1,4,minecraft:netherrack)
B(1,2,4,minecraft:soul_soil)
B(1,3,4,minecraft:soul_soil)
B(1,4,4,minecraft:soul_sand)
B(1,0,5,minecraft:netherrack)
B(1,1,5,minecraft:netherrack)
B(1,2,5,minecraft:soul_soil)
B(1,3,5,minecraft:soul_soil)
B(1,4,5,minecraft:soul_sand)
B(1,0,6,minecraft:netherrack)
B(1,1,6,minecraft:netherrack)
B(1,2,6,minecraft:soul_soil)
B(1,3,6,minecraft:soul_soil)
B(1,4,6,minecraft:soul_sand)
B(1,0,7,minecraft:netherrack)
B(1,1,7,minecraft:netherrack)
B(1,2,7,minecraft:soul_soil)
B(1,3,7,minecraft:soul_soil)
B(1,4,7,minecraft:soul_sand)
B(1,0,8,minecraft:netherrack)
B(1,1,8,minecraft:soul_soil)
B(1,2,8,minecraft:soul_soil)
B(1,3,8,minecraft:soul_sand)
B(2,0,-7,minecraft:netherrack)
B(2,1,-7,minecraft:netherrack)
B(2,2,-7,minecraft:netherrack)
B(2,3,-7,minecraft:soul_soil)
B(2,4,-7,minecraft:soul_soil)
B(2,5,-7,minecraft:soul_sand)
B(2,0,-6,minecraft:netherrack)
B(2,1,-6,minecraft:netherrack)
B(2,2,-6,minecraft:netherrack)
B(2,3,-6,minecraft:soul_soil)
B(2,4,-6,minecraft:soul_soil)
B(2,5,-6,minecraft:soul_sand)
B(2,0,-5,minecraft:netherrack)
B(2,1,-5,minecraft:netherrack)
B(2,2,-5,minecraft:netherrack)
B(2,3,-5,minecraft:soul_soil)
B(2,4,-5,minecraft:soul_soil)
B(2,5,-5,minecraft:soul_sand)
B(2,0,-4,minecraft:netherrack)
B(2,1,-4,minecraft:netherrack)
B(2,2,-4,minecraft:netherrack)
B(2,3,-4,minecraft:soul_soil)
B(2,4,-4,minecraft:soul_soil)
B(2,5,-4,minecraft:soul_sand)
B(2,0,-3,minecraft:netherrack)
B(2,1,-3,minecraft:netherrack)
B(2,2,-3,minecraft:netherrack)
B(2,3,-3,minecraft:soul_soil)
B(2,4,-3,minecraft:soul_soil)
B(2,5,-3,minecraft:soul_sand)
B(2,0,-2,minecraft:netherrack)
B(2,1,-2,minecraft:netherrack)
B(2,2,-2,minecraft:netherrack)
B(2,3,-2,minecraft:soul_soil)
B(2,4,-2,minecraft:soul_soil)
B(2,5,-2,minecraft:soul_sand)
B(2,0,-1,minecraft:netherrack)
B(2,1,-1,minecraft:netherrack)
B(2,2,-1,minecraft:soul_soil)
B(2,3,-1,minecraft:soul_soil)
B(2,4,-1,minecraft:soul_sand)
B(2,0,0,minecraft:netherrack)
B(2,1,0,minecraft:netherrack)
B(2,2,0,minecraft:soul_soil)
B(2,3,0,minecraft:soul_soil)
B(2,4,0,minecraft:soul_sand)
B(2,0,1,minecraft:netherrack)
B(2,1,1,minecraft:netherrack)
B(2,2,1,minecraft:soul_soil)
B(2,3,1,minecraft:soul_soil)
B(2,4,1,minecraft:soul_sand)
B(2,0,2,minecraft:netherrack)
B(2,1,2,minecraft:netherrack)
B(2,2,2,minecraft:soul_soil)
B(2,3,2,minecraft:soul_soil)
B(2,4,2,minecraft:soul_sand)
B(2,0,3,minecraft:netherrack)
B(2,1,3,minecraft:netherrack)
B(2,2,3,minecraft:soul_soil)
B(2,3,3,minecraft:soul_soil)
B(2,4,3,minecraft:soul_sand)
B(2,0,4,minecraft:netherrack)
B(2,1,4,minecraft:netherrack)
B(2,2,4,minecraft:soul_soil)
B(2,3,4,minecraft:soul_soil)
B(2,4,4,minecraft:soul_sand)
B(2,0,5,minecraft:netherrack)
B(2,1,5,minecraft:netherrack)
B(2,2,5,minecraft:netherrack)
B(2,3,5,minecraft:soul_soil)
B(2,4,5,minecraft:soul_soil)
B(2,5,5,minecraft:soul_sand)
B(2,0,6,minecraft:netherrack)
B(2,1,6,minecraft:netherrack)
B(2,2,6,minecraft:netherrack)
B(2,3,6,minecraft:soul_soil)
B(2,4,6,minecraft:soul_soil)
B(2,5,6,minecraft:soul_sand)
B(2,0,7,minecraft:netherrack)
B(2,1,7,minecraft:netherrack)
B(2,2,7,minecraft:soul_soil)
B(2,3,7,minecraft:soul_soil)
B(2,4,7,minecraft:soul_sand)
B(2,0,8,minecraft:netherrack)
B(2,1,8,minecraft:netherrack)
B(2,2,8,minecraft:soul_soil)
B(2,3,8,minecraft:soul_soil)
B(2,4,8,minecraft:soul_sand)
B(3,0,-7,minecraft:netherrack)
B(3,1,-7,minecraft:netherrack)
B(3,2,-7,minecraft:netherrack)
B(3,3,-7,minecraft:soul_soil)
B(3,4,-7,minecraft:soul_soil)
B(3,5,-7,minecraft:soul_sand)
B(3,0,-6,minecraft:netherrack)
B(3,1,-6,minecraft:netherrack)
B(3,2,-6,minecraft:netherrack)
B(3,3,-6,minecraft:soul_soil)
B(3,4,-6,minecraft:soul_soil)
B(3,5,-6,minecraft:soul_sand)
B(3,0,-5,minecraft:netherrack)
B(3,1,-5,minecraft:netherrack)
B(3,2,-5,minecraft:netherrack)
B(3,3,-5,minecraft:soul_soil)
B(3,4,-5,minecraft:soul_soil)
B(3,5,-5,minecraft:soul_sand)
B(3,0,-4,minecraft:netherrack)
B(3,1,-4,minecraft:netherrack)
B(3,2,-4,minecraft:netherrack)
B(3,3,-4,minecraft:soul_soil)
B(3,4,-4,minecraft:soul_soil)
B(3,5,-4,minecraft:soul_sand)
B(3,0,-3,minecraft:netherrack)
B(3,1,-3,minecraft:netherrack)
B(3,2,-3,minecraft:netherrack)
B(3,3,-3,minecraft:soul_soil)
B(3,4,-3,minecraft:soul_soil)
B(3,5,-3,minecraft:soul_sand)
B(3,0,-2,minecraft:netherrack)
B(3,1,-2,minecraft:netherrack)
B(3,2,-2,minecraft:netherrack)
B(3,3,-2,minecraft:soul_soil)
B(3,4,-2,minecraft:soul_soil)
B(3,5,-2,minecraft:soul_sand)
B(3,0,-1,minecraft:netherrack)
B(3,1,-1,minecraft:netherrack)
B(3,2,-1,minecraft:netherrack)
B(3,3,-1,minecraft:soul_soil)
B(3,4,-1,minecraft:soul_soil)
B(3,5,-1,minecraft:soul_sand)
B(3,0,0,minecraft:netherrack)
B(3,1,0,minecraft:netherrack)
B(3,2,0,minecraft:netherrack)
B(3,3,0,minecraft:soul_soil)
B(3,4,0,minecraft:soul_soil)
B(3,5,0,minecraft:soul_sand)
B(3,0,1,minecraft:netherrack)
B(3,1,1,minecraft:netherrack)
B(3,2,1,minecraft:soul_soil)
B(3,3,1,minecraft:soul_soil)
B(3,4,1,minecraft:soul_sand)
B(3,0,2,minecraft:netherrack)
B(3,1,2,minecraft:netherrack)
B(3,2,2,minecraft:soul_soil)
B(3,3,2,minecraft:soul_soil)
B(3,4,2,minecraft:soul_sand)
B(3,0,3,minecraft:netherrack)
B(3,1,3,minecraft:netherrack)
B(3,2,3,minecraft:netherrack)
B(3,3,3,minecraft:soul_soil)
B(3,4,3,minecraft:soul_soil)
B(3,5,3,minecraft:soul_sand)
B(3,0,4,minecraft:netherrack)
B(3,1,4,minecraft:netherrack)
B(3,2,4,minecraft:netherrack)
B(3,3,4,minecraft:soul_soil)
B(3,4,4,minecraft:soul_soil)
B(3,5,4,minecraft:soul_sand)
B(3,0,5,minecraft:netherrack)
B(3,1,5,minecraft:netherrack)
B(3,2,5,minecraft:netherrack)
B(3,3,5,minecraft:soul_soil)
B(3,4,5,minecraft:soul_soil)
B(3,5,5,minecraft:soul_sand)
B(3,0,6,minecraft:netherrack)
B(3,1,6,minecraft:netherrack)
B(3,2,6,minecraft:netherrack)
B(3,3,6,minecraft:soul_soil)
B(3,4,6,minecraft:soul_soil)
B(3,5,6,minecraft:soul_sand)
B(3,0,7,minecraft:netherrack)
B(3,1,7,minecraft:netherrack)
B(3,2,7,minecraft:soul_soil)
B(3,3,7,minecraft:soul_soil)
B(3,4,7,minecraft:soul_sand)
B(3,0,8,minecraft:netherrack)
B(3,1,8,minecraft:soul_soil)
B(3,2,8,minecraft:soul_soil)
B(3,3,8,minecraft:soul_sand)
B(4,0,-7,minecraft:netherrack)
B(4,1,-7,minecraft:netherrack)
B(4,2,-7,minecraft:soul_soil)
B(4,3,-7,minecraft:soul_soil)
B(4,4,-7,minecraft:soul_sand)
B(4,0,-6,minecraft:netherrack)
B(4,1,-6,minecraft:netherrack)
B(4,2,-6,minecraft:soul_soil)
B(4,3,-6,minecraft:soul_soil)
B(4,4,-6,minecraft:soul_sand)
B(4,0,-5,minecraft:netherrack)
B(4,1,-5,minecraft:netherrack)
B(4,2,-5,minecraft:soul_soil)
B(4,3,-5,minecraft:soul_soil)
B(4,4,-5,minecraft:soul_sand)
B(4,0,-4,minecraft:netherrack)
B(4,1,-4,minecraft:netherrack)
B(4,2,-4,minecraft:soul_soil)
B(4,3,-4,minecraft:soul_soil)
B(4,4,-4,minecraft:soul_sand)
B(4,0,-3,minecraft:netherrack)
B(4,1,-3,minecraft:netherrack)
B(4,2,-3,minecraft:nether_quartz_ore)
B(4,3,-3,minecraft:soul_soil)
B(4,4,-3,minecraft:soul_soil)
B(4,5,-3,minecraft:soul_sand)
B(4,0,-2,minecraft:netherrack)
B(4,1,-2,minecraft:netherrack)
B(4,2,-2,minecraft:netherrack)
B(4,3,-2,minecraft:soul_soil)
B(4,4,-2,minecraft:soul_soil)
B(4,5,-2,minecraft:soul_sand)
B(4,0,-1,minecraft:netherrack)
B(4,1,-1,minecraft:netherrack)
B(4,2,-1,minecraft:netherrack)
B(4,3,-1,minecraft:soul_soil)
B(4,4,-1,minecraft:soul_soil)
B(4,5,-1,minecraft:soul_sand)
B(4,0,0,minecraft:netherrack)
B(4,1,0,minecraft:netherrack)
B(4,2,0,minecraft:netherrack)
B(4,3,0,minecraft:soul_soil)
B(4,4,0,minecraft:soul_soil)
B(4,5,0,minecraft:soul_sand)
B(4,0,1,minecraft:netherrack)
B(4,1,1,minecraft:netherrack)
B(4,2,1,minecraft:netherrack)
B(4,3,1,minecraft:soul_soil)
B(4,4,1,minecraft:soul_soil)
B(4,5,1,minecraft:soul_sand)
B(4,0,2,minecraft:netherrack)
B(4,1,2,minecraft:netherrack)
B(4,2,2,minecraft:netherrack)
B(4,3,2,minecraft:soul_soil)
B(4,4,2,minecraft:soul_soil)
B(4,5,2,minecraft:soul_sand)
B(4,0,3,minecraft:netherrack)
B(4,1,3,minecraft:netherrack)
B(4,2,3,minecraft:netherrack)
B(4,3,3,minecraft:soul_soil)
B(4,4,3,minecraft:soul_soil)
B(4,5,3,minecraft:soul_sand)
B(4,0,4,minecraft:netherrack)
B(4,1,4,minecraft:netherrack)
B(4,2,4,minecraft:netherrack)
B(4,3,4,minecraft:soul_soil)
B(4,4,4,minecraft:soul_soil)
B(4,5,4,minecraft:soul_sand)
B(4,0,5,minecraft:netherrack)
B(4,1,5,minecraft:netherrack)
B(4,2,5,minecraft:netherrack)
B(4,3,5,minecraft:soul_soil)
B(4,4,5,minecraft:soul_soil)
B(4,5,5,minecraft:soul_sand)
B(4,0,6,minecraft:netherrack)
B(4,1,6,minecraft:netherrack)
B(4,2,6,minecraft:netherrack)
B(4,3,6,minecraft:soul_soil)
B(4,4,6,minecraft:soul_soil)
B(4,5,6,minecraft:soul_sand)
B(4,0,7,minecraft:netherrack)
B(4,1,7,minecraft:netherrack)
B(4,2,7,minecraft:soul_soil)
B(4,3,7,minecraft:soul_soil)
B(4,4,7,minecraft:soul_sand)
B(4,0,8,minecraft:netherrack)
B(4,1,8,minecraft:soul_soil)
B(4,2,8,minecraft:soul_soil)
B(4,3,8,minecraft:soul_sand)
B(5,0,-7,minecraft:netherrack)
B(5,1,-7,minecraft:soul_soil)
B(5,2,-7,minecraft:soul_soil)
B(5,3,-7,minecraft:soul_sand)
B(5,0,-6,minecraft:netherrack)
B(5,1,-6,minecraft:soul_soil)
B(5,2,-6,minecraft:soul_soil)
B(5,3,-6,minecraft:soul_sand)
B(5,0,-5,minecraft:netherrack)
B(5,1,-5,minecraft:netherrack)
B(5,2,-5,minecraft:soul_soil)
B(5,3,-5,minecraft:soul_soil)
B(5,4,-5,minecraft:soul_sand)
B(5,0,-4,minecraft:netherrack)
B(5,1,-4,minecraft:netherrack)
B(5,2,-4,minecraft:soul_soil)
B(5,3,-4,minecraft:soul_soil)
B(5,4,-4,minecraft:soul_sand)
B(5,0,-3,minecraft:netherrack)
B(5,1,-3,minecraft:netherrack)
B(5,2,-3,minecraft:soul_soil)
B(5,3,-3,minecraft:soul_soil)
B(5,4,-3,minecraft:soul_sand)
B(5,0,-2,minecraft:netherrack)
B(5,1,-2,minecraft:netherrack)
B(5,2,-2,minecraft:netherrack)
B(5,3,-2,minecraft:soul_soil)
B(5,4,-2,minecraft:soul_soil)
B(5,5,-2,minecraft:soul_sand)
B(5,0,-1,minecraft:netherrack)
B(5,1,-1,minecraft:netherrack)
B(5,2,-1,minecraft:netherrack)
B(5,3,-1,minecraft:soul_soil)
B(5,4,-1,minecraft:soul_soil)
B(5,5,-1,minecraft:soul_sand)
B(5,0,0,minecraft:netherrack)
B(5,1,0,minecraft:netherrack)
B(5,2,0,minecraft:netherrack)
B(5,3,0,minecraft:soul_soil)
B(5,4,0,minecraft:soul_soil)
B(5,5,0,minecraft:soul_sand)
B(5,0,1,minecraft:netherrack)
B(5,1,1,minecraft:netherrack)
B(5,2,1,minecraft:netherrack)
B(5,3,1,minecraft:soul_soil)
B(5,4,1,minecraft:soul_soil)
B(5,5,1,minecraft:soul_sand)
B(5,0,2,minecraft:netherrack)
B(5,1,2,minecraft:netherrack)
B(5,2,2,minecraft:netherrack)
B(5,3,2,minecraft:soul_soil)
B(5,4,2,minecraft:soul_soil)
B(5,5,2,minecraft:soul_sand)
B(5,0,3,minecraft:netherrack)
B(5,1,3,minecraft:netherrack)
B(5,2,3,minecraft:netherrack)
B(5,3,3,minecraft:soul_soil)
B(5,4,3,minecraft:soul_soil)
B(5,5,3,minecraft:soul_sand)
B(5,0,4,minecraft:netherrack)
B(5,1,4,minecraft:netherrack)
B(5,2,4,minecraft:netherrack)
B(5,3,4,minecraft:soul_soil)
B(5,4,4,minecraft:soul_soil)
B(5,5,4,minecraft:soul_sand)
B(5,0,5,minecraft:netherrack)
B(5,1,5,minecraft:netherrack)
B(5,2,5,minecraft:netherrack)
B(5,3,5,minecraft:soul_soil)
B(5,4,5,minecraft:soul_soil)
B(5,5,5,minecraft:soul_sand)
B(5,0,6,minecraft:netherrack)
B(5,1,6,minecraft:netherrack)
B(5,2,6,minecraft:netherrack)
B(5,3,6,minecraft:soul_soil)
B(5,4,6,minecraft:soul_soil)
B(5,5,6,minecraft:soul_sand)
B(5,0,7,minecraft:netherrack)
B(5,1,7,minecraft:netherrack)
B(5,2,7,minecraft:soul_soil)
B(5,3,7,minecraft:soul_soil)
B(5,4,7,minecraft:soul_sand)
B(5,0,8,minecraft:netherrack)
B(5,1,8,minecraft:soul_soil)
B(5,2,8,minecraft:soul_soil)
B(5,3,8,minecraft:soul_sand)
B(6,0,-7,minecraft:soul_sand)
B(6,1,-7,minecraft:soul_sand)
B(6,2,-7,minecraft:soul_sand)
B(6,3,-7,minecraft:soul_sand)
B(6,4,-7,minecraft:soul_sand)
B(6,5,-7,minecraft:soul_sand)
B(6,6,-7,minecraft:soul_sand)
B(6,7,-7,minecraft:soul_sand)
B(6,8,-7,minecraft:soul_sand)
B(6,9,-7,minecraft:soul_sand)
B(6,10,-7,minecraft:soul_sand)
B(6,11,-7,minecraft:soul_sand)
B(6,12,-7,minecraft:soul_sand)
B(6,13,-7,minecraft:soul_sand)
B(6,14,-7,minecraft:soul_sand)
B(6,15,-7,minecraft:soul_sand)
B(6,16,-7,minecraft:soul_sand)
B(6,17,-7,minecraft:soul_sand)
B(6,18,-7,minecraft:soul_sand)
B(6,19,-7,minecraft:soul_sand)
B(6,20,-7,minecraft:soul_sand)
B(6,21,-7,minecraft:soul_sand)
B(6,22,-7,minecraft:soul_sand)
B(6,23,-7,minecraft:soul_sand)
B(6,24,-7,minecraft:soul_sand)
B(6,25,-7,minecraft:soul_sand)
B(6,26,-7,minecraft:soul_sand)
B(6,27,-7,minecraft:soul_sand)
B(6,28,-7,minecraft:soul_sand)
B(6,29,-7,minecraft:soul_sand)
B(6,30,-7,minecraft:soul_sand)
B(6,31,-7,minecraft:soul_sand)
B(6,32,-7,minecraft:soul_sand)
B(6,33,-7,minecraft:soul_sand)
B(6,34,-7,minecraft:soul_sand)
B(6,35,-7,minecraft:soul_sand)
B(6,36,-7,minecraft:soul_sand)
B(6,37,-7,minecraft:soul_sand)
B(6,38,-7,minecraft:soul_sand)
B(6,39,-7,minecraft:soul_sand)
B(6,40,-7,minecraft:soul_sand)
B(6,0,-6,minecraft:soul_soil)
B(6,1,-6,minecraft:soul_soil)
B(6,2,-6,minecraft:soul_sand)
B(6,0,-5,minecraft:netherrack)
B(6,1,-5,minecraft:soul_soil)
B(6,2,-5,minecraft:soul_soil)
B(6,3,-5,minecraft:soul_sand)
B(6,0,-4,minecraft:netherrack)
B(6,1,-4,minecraft:netherrack)
B(6,2,-4,minecraft:soul_soil)
B(6,3,-4,minecraft:soul_soil)
B(6,4,-4,minecraft:soul_sand)
B(6,0,-3,minecraft:netherrack)
B(6,1,-3,minecraft:netherrack)
B(6,2,-3,minecraft:soul_soil)
B(6,3,-3,minecraft:soul_soil)
B(6,4,-3,minecraft:soul_sand)
B(6,0,-2,minecraft:netherrack)
B(6,1,-2,minecraft:netherrack)
B(6,2,-2,minecraft:netherrack)
B(6,3,-2,minecraft:soul_soil)
B(6,4,-2,minecraft:soul_soil)
B(6,5,-2,minecraft:soul_sand)
B(6,0,-1,minecraft:netherrack)
B(6,1,-1,minecraft:netherrack)
B(6,2,-1,minecraft:netherrack)
B(6,3,-1,minecraft:soul_soil)
B(6,4,-1,minecraft:soul_soil)
B(6,5,-1,minecraft:soul_sand)
B(6,0,0,minecraft:netherrack)
B(6,1,0,minecraft:netherrack)
B(6,2,0,minecraft:netherrack)
B(6,3,0,minecraft:soul_soil)
B(6,4,0,minecraft:soul_soil)
B(6,5,0,minecraft:soul_sand)
B(6,0,1,minecraft:netherrack)
B(6,1,1,minecraft:netherrack)
B(6,2,1,minecraft:netherrack)
B(6,3,1,minecraft:soul_soil)
B(6,4,1,minecraft:soul_soil)
B(6,5,1,minecraft:soul_sand)
B(6,0,2,minecraft:netherrack)
B(6,1,2,minecraft:netherrack)
B(6,2,2,minecraft:netherrack)
B(6,3,2,minecraft:soul_soil)
B(6,4,2,minecraft:soul_soil)
B(6,5,2,minecraft:soul_sand)
B(6,0,3,minecraft:netherrack)
B(6,1,3,minecraft:netherrack)
B(6,2,3,minecraft:netherrack)
B(6,3,3,minecraft:soul_soil)
B(6,4,3,minecraft:soul_soil)
B(6,5,3,minecraft:soul_sand)
B(6,0,4,minecraft:netherrack)
B(6,1,4,minecraft:netherrack)
B(6,2,4,minecraft:nether_quartz_ore)
B(6,3,4,minecraft:soul_soil)
B(6,4,4,minecraft:soul_soil)
B(6,5,4,minecraft:soul_sand)
B(6,0,5,minecraft:netherrack)
B(6,1,5,minecraft:netherrack)
B(6,2,5,minecraft:nether_quartz_ore)
B(6,3,5,minecraft:soul_soil)
B(6,4,5,minecraft:soul_soil)
B(6,5,5,minecraft:soul_sand)
B(6,0,6,minecraft:netherrack)
B(6,1,6,minecraft:netherrack)
B(6,2,6,minecraft:soul_soil)
B(6,3,6,minecraft:soul_soil)
B(6,4,6,minecraft:soul_sand)
B(6,0,7,minecraft:netherrack)
B(6,1,7,minecraft:netherrack)
B(6,2,7,minecraft:soul_soil)
B(6,3,7,minecraft:soul_soil)
B(6,4,7,minecraft:soul_sand)
B(6,0,8,minecraft:netherrack)
B(6,1,8,minecraft:soul_soil)
B(6,2,8,minecraft:soul_soil)
B(6,3,8,minecraft:soul_sand)
B(7,0,-7,minecraft:soul_sand)
B(7,1,-7,minecraft:soul_sand)
B(7,2,-7,minecraft:soul_sand)
B(7,3,-7,minecraft:soul_sand)
B(7,4,-7,minecraft:soul_sand)
B(7,5,-7,minecraft:soul_sand)
B(7,6,-7,minecraft:soul_sand)
B(7,7,-7,minecraft:soul_sand)
B(7,8,-7,minecraft:soul_sand)
B(7,9,-7,minecraft:soul_sand)
B(7,10,-7,minecraft:soul_sand)
B(7,11,-7,minecraft:soul_sand)
B(7,12,-7,minecraft:soul_sand)
B(7,13,-7,minecraft:soul_sand)
B(7,14,-7,minecraft:soul_sand)
B(7,15,-7,minecraft:soul_sand)
B(7,16,-7,minecraft:soul_sand)
B(7,17,-7,minecraft:soul_sand)
B(7,18,-7,minecraft:soul_sand)
B(7,19,-7,minecraft:soul_sand)
B(7,20,-7,minecraft:soul_sand)
B(7,21,-7,minecraft:soul_sand)
B(7,22,-7,minecraft:soul_sand)
B(7,23,-7,minecraft:soul_sand)
B(7,24,-7,minecraft:soul_sand)
B(7,25,-7,minecraft:soul_sand)
B(7,26,-7,minecraft:soul_sand)
B(7,27,-7,minecraft:soul_sand)
B(7,28,-7,minecraft:soul_sand)
B(7,29,-7,minecraft:soul_sand)
B(7,30,-7,minecraft:soul_sand)
B(7,31,-7,minecraft:soul_sand)
B(7,32,-7,minecraft:soul_sand)
B(7,33,-7,minecraft:soul_sand)
B(7,34,-7,minecraft:soul_sand)
B(7,35,-7,minecraft:soul_sand)
B(7,36,-7,minecraft:soul_sand)
B(7,37,-7,minecraft:soul_sand)
B(7,38,-7,minecraft:soul_sand)
B(7,39,-7,minecraft:soul_sand)
B(7,40,-7,minecraft:soul_sand)
B(7,41,-7,minecraft:soul_sand)
B(7,42,-7,minecraft:soul_sand)
B(7,43,-7,minecraft:soul_sand)
B(7,44,-7,minecraft:soul_sand)
B(7,45,-7,minecraft:soul_sand)
B(7,46,-7,minecraft:soul_sand)
B(7,47,-7,minecraft:soul_sand)
B(7,48,-7,minecraft:soul_sand)
B(7,49,-7,minecraft:soul_sand)
B(7,0,-6,minecraft:soul_sand)
B(7,1,-6,minecraft:soul_sand)
B(7,2,-6,minecraft:soul_sand)
B(7,3,-6,minecraft:soul_sand)
B(7,4,-6,minecraft:soul_sand)
B(7,5,-6,minecraft:soul_sand)
B(7,6,-6,minecraft:soul_sand)
B(7,7,-6,minecraft:soul_sand)
B(7,8,-6,minecraft:soul_sand)
B(7,9,-6,minecraft:soul_sand)
B(7,10,-6,minecraft:soul_sand)
B(7,11,-6,minecraft:soul_sand)
B(7,12,-6,minecraft:soul_sand)
B(7,13,-6,minecraft:soul_sand)
B(7,14,-6,minecraft:soul_sand)
B(7,15,-6,minecraft:soul_sand)
B(7,16,-6,minecraft:soul_sand)
B(7,17,-6,minecraft:soul_sand)
B(7,18,-6,minecraft:soul_sand)
B(7,19,-6,minecraft:soul_sand)
B(7,20,-6,minecraft:soul_sand)
B(7,21,-6,minecraft:soul_sand)
B(7,22,-6,minecraft:soul_sand)
B(7,23,-6,minecraft:soul_sand)
B(7,24,-6,minecraft:soul_sand)
B(7,25,-6,minecraft:soul_sand)
B(7,26,-6,minecraft:soul_sand)
B(7,27,-6,minecraft:soul_sand)
B(7,28,-6,minecraft:soul_sand)
B(7,29,-6,minecraft:soul_sand)
B(7,30,-6,minecraft:soul_sand)
B(7,31,-6,minecraft:soul_sand)
B(7,32,-6,minecraft:soul_sand)
B(7,33,-6,minecraft:soul_sand)
B(7,34,-6,minecraft:soul_sand)
B(7,35,-6,minecraft:soul_sand)
B(7,36,-6,minecraft:soul_sand)
B(7,37,-6,minecraft:soul_sand)
B(7,0,-5,minecraft:netherrack)
B(7,1,-5,minecraft:soul_soil)
B(7,2,-5,minecraft:soul_soil)
B(7,3,-5,minecraft:soul_sand)
B(7,0,-4,minecraft:netherrack)
B(7,1,-4,minecraft:netherrack)
B(7,2,-4,minecraft:soul_soil)
B(7,3,-4,minecraft:soul_soil)
B(7,4,-4,minecraft:soul_sand)
B(7,0,-3,minecraft:netherrack)
B(7,1,-3,minecraft:netherrack)
B(7,2,-3,minecraft:soul_soil)
B(7,3,-3,minecraft:soul_soil)
B(7,4,-3,minecraft:soul_sand)
B(7,0,-2,minecraft:netherrack)
B(7,1,-2,minecraft:netherrack)
B(7,2,-2,minecraft:netherrack)
B(7,3,-2,minecraft:soul_soil)
B(7,4,-2,minecraft:soul_soil)
B(7,5,-2,minecraft:soul_sand)
B(7,0,-1,minecraft:netherrack)
B(7,1,-1,minecraft:netherrack)
B(7,2,-1,minecraft:netherrack)
B(7,3,-1,minecraft:soul_soil)
B(7,4,-1,minecraft:soul_soil)
B(7,5,-1,minecraft:soul_sand)
B(7,0,0,minecraft:netherrack)
B(7,1,0,minecraft:netherrack)
B(7,2,0,minecraft:netherrack)
B(7,3,0,minecraft:soul_soil)
B(7,4,0,minecraft:soul_soil)
B(7,5,0,minecraft:soul_sand)
B(7,0,1,minecraft:netherrack)
B(7,1,1,minecraft:netherrack)
B(7,2,1,minecraft:netherrack)
B(7,3,1,minecraft:soul_soil)
B(7,4,1,minecraft:soul_soil)
B(7,5,1,minecraft:soul_sand)
B(7,0,2,minecraft:netherrack)
B(7,1,2,minecraft:netherrack)
B(7,2,2,minecraft:netherrack)
B(7,3,2,minecraft:soul_soil)
B(7,4,2,minecraft:soul_soil)
B(7,5,2,minecraft:soul_sand)
B(7,0,3,minecraft:netherrack)
B(7,1,3,minecraft:netherrack)
B(7,2,3,minecraft:netherrack)
B(7,3,3,minecraft:soul_soil)
B(7,4,3,minecraft:soul_soil)
B(7,5,3,minecraft:soul_sand)
B(7,0,4,minecraft:netherrack)
B(7,1,4,minecraft:nether_quartz_ore)
B(7,2,4,minecraft:nether_quartz_ore)
B(7,3,4,minecraft:soul_soil)
B(7,4,4,minecraft:soul_soil)
B(7,5,4,minecraft:soul_sand)
B(7,0,5,minecraft:netherrack)
B(7,1,5,minecraft:nether_quartz_ore)
B(7,2,5,minecraft:nether_quartz_ore)
B(7,3,5,minecraft:soul_soil)
B(7,4,5,minecraft:soul_soil)
B(7,5,5,minecraft:soul_sand)
B(7,0,6,minecraft:netherrack)
B(7,1,6,minecraft:nether_quartz_ore)
B(7,2,6,minecraft:nether_quartz_ore)
B(7,3,6,minecraft:soul_soil)
B(7,4,6,minecraft:soul_sand)
B(7,0,7,minecraft:netherrack)
B(7,1,7,minecraft:netherrack)
B(7,2,7,minecraft:soul_soil)
B(7,3,7,minecraft:soul_sand)
B(7,0,8,minecraft:netherrack)
B(7,1,8,minecraft:netherrack)
B(7,2,8,minecraft:soul_soil)
B(7,3,8,minecraft:soul_sand)

#######################################################################
# +-----------------------------------------------------------------+ #
# |                             Branches                            | #
# +-----------------------------------------------------------------+ #
#######################################################################

Branch(16,0,0,true,SoulSandWall2_C2_R4,NORTH,100.0,0)

#######################################################################
# +-----------------------------------------------------------------+ #
# |                             Entities                            | #
# +-----------------------------------------------------------------+ #
#######################################################################

