
#######################################################################
# +-----------------------------------------------------------------+ #
# |                            BO4 object                           | #
# +-----------------------------------------------------------------+ #
#######################################################################

Author: Unknown

Description: No description given

SettingsMode: WriteWithoutComments


#######################################################################
# +-----------------------------------------------------------------+ #
# |                          Main settings                          | #
# +-----------------------------------------------------------------+ #
#######################################################################

FixedRotation: 

Frequency: 0

SpawnHeight: highestBlock

UseCenterForHighestBlock: true

##############################
# Height Limits for the BO4. #
##############################

MinHeight: 0

MaxHeight: 255

InheritBO3: 

InheritBO3Rotation: NORTH

OverrideChildSettings: true

OverrideParentHeight: false

CanOverride: false

BranchFrequency: 0

BranchFrequencyGroup: 

MustBeBelowOther: false

MustBeInside: 

CannotBeInside: 

ReplacesBO3: 

MustBeInsideWorldBorders: false

CanSpawnOnWater: true

SpawnOnWaterOnly: false

SpawnUnderWater: false

SpawnAtWaterLevel: false

HeightOffset: 0

RemoveAir: true

ReplaceAbove: 

ReplaceBelow: 

ReplaceWithBiomeBlocks: true

ReplaceWithSurfaceBlock: GRASS

ReplaceWithGroundBlock: DIRT

ReplaceWithStoneBlock: STONE

SmoothRadius: 0

SmoothHeightOffset: 0

SmoothStartTop: false

SmoothStartWood: false

SmoothingSurfaceBlock: 

SmoothingGroundBlock: 

BO3Group: 

IsSpawnPoint: false

DoReplaceBlocks: true


#######################################################################
# +-----------------------------------------------------------------+ #
# |                              Blocks                             | #
# +-----------------------------------------------------------------+ #
#######################################################################

B(-8,114,-3,minecraft:netherrack)
B(-8,114,-2,minecraft:netherrack)
B(-8,114,-1,minecraft:netherrack)
B(-8,114,0,minecraft:netherrack)
B(-8,114,1,minecraft:netherrack)
B(-7,114,-1,minecraft:netherrack)
B(-7,114,0,minecraft:netherrack)
B(-7,114,1,minecraft:netherrack)
B(-6,114,0,minecraft:netherrack)
B(-6,114,1,minecraft:netherrack)
B(-5,114,1,minecraft:netherrack)
B(-4,114,1,minecraft:netherrack)
B(-3,114,-2,minecraft:netherrack)
B(-3,114,-1,minecraft:netherrack)
B(-3,114,0,minecraft:netherrack)
B(-3,114,1,minecraft:netherrack)
B(-2,114,-3,minecraft:netherrack)
B(-2,114,-2,minecraft:netherrack)
B(-2,114,-1,minecraft:netherrack)
B(-2,114,0,minecraft:netherrack)
B(-2,114,1,minecraft:netherrack)
B(-1,114,-5,minecraft:netherrack)
B(-1,114,-4,minecraft:netherrack)
B(-1,114,-3,minecraft:netherrack)
B(-1,114,-2,minecraft:netherrack)
B(-1,114,-1,minecraft:netherrack)
B(-1,114,0,minecraft:netherrack)
B(-1,114,1,minecraft:netherrack)
B(-1,114,2,minecraft:netherrack)
B(0,114,-5,minecraft:netherrack)
B(0,114,-4,minecraft:netherrack)
B(0,114,-3,minecraft:netherrack)
B(0,114,-2,minecraft:netherrack)
B(0,114,-1,minecraft:netherrack)
B(0,114,0,minecraft:netherrack)
B(0,114,1,minecraft:netherrack)
B(0,114,2,minecraft:netherrack)
B(0,114,3,minecraft:netherrack)
B(1,114,-4,minecraft:netherrack)
B(1,114,-3,minecraft:netherrack)
B(1,114,-2,minecraft:netherrack)
B(1,114,-1,minecraft:netherrack)
B(1,114,0,minecraft:netherrack)
B(1,114,1,minecraft:netherrack)
B(1,114,2,minecraft:netherrack)
B(1,114,3,minecraft:netherrack)
B(1,114,4,minecraft:netherrack)
B(1,114,5,minecraft:netherrack)
B(2,114,-2,minecraft:netherrack)
B(2,114,-1,minecraft:netherrack)
B(2,114,0,minecraft:netherrack)
B(2,114,1,minecraft:netherrack)
B(2,114,2,minecraft:netherrack)
B(2,114,3,minecraft:netherrack)
B(2,114,4,minecraft:netherrack)
B(2,114,5,minecraft:netherrack)
B(3,114,-1,minecraft:netherrack)
B(3,114,0,minecraft:netherrack)
B(3,114,1,minecraft:netherrack)
B(3,113,2,minecraft:netherrack)
B(3,114,2,minecraft:netherrack)
B(3,113,3,minecraft:netherrack)
B(3,114,3,minecraft:netherrack)
B(3,113,4,minecraft:netherrack)
B(3,114,4,minecraft:netherrack)
B(3,113,5,minecraft:netherrack)
B(3,114,5,minecraft:netherrack)
B(3,114,6,minecraft:netherrack)
B(4,114,-1,minecraft:netherrack)
B(4,114,0,minecraft:netherrack)
B(4,113,1,minecraft:netherrack)
B(4,114,1,minecraft:netherrack)
B(4,113,2,minecraft:netherrack)
B(4,114,2,minecraft:netherrack)
B(4,113,3,minecraft:netherrack)
B(4,114,3,minecraft:netherrack)
B(4,112,4,minecraft:netherrack)
B(4,113,4,minecraft:netherrack)
B(4,114,4,minecraft:netherrack)
B(4,112,5,minecraft:netherrack)
B(4,113,5,minecraft:netherrack)
B(4,114,5,minecraft:netherrack)
B(4,113,6,minecraft:netherrack)
B(4,114,6,minecraft:netherrack)
B(4,114,7,minecraft:netherrack)
B(4,114,8,minecraft:netherrack)
B(5,114,-1,minecraft:netherrack)
B(5,114,0,minecraft:netherrack)
B(5,113,1,minecraft:netherrack)
B(5,114,1,minecraft:netherrack)
B(5,113,2,minecraft:netherrack)
B(5,114,2,minecraft:netherrack)
B(5,112,3,minecraft:netherrack)
B(5,113,3,minecraft:netherrack)
B(5,114,3,minecraft:netherrack)
B(5,112,4,minecraft:netherrack)
B(5,113,4,minecraft:netherrack)
B(5,114,4,minecraft:netherrack)
B(5,111,5,minecraft:netherrack)
B(5,112,5,minecraft:netherrack)
B(5,113,5,minecraft:netherrack)
B(5,114,5,minecraft:netherrack)
B(5,112,6,minecraft:netherrack)
B(5,113,6,minecraft:netherrack)
B(5,114,6,minecraft:netherrack)
B(5,112,7,minecraft:netherrack)
B(5,113,7,minecraft:netherrack)
B(5,114,7,minecraft:netherrack)
B(5,113,8,minecraft:netherrack)
B(5,114,8,minecraft:netherrack)
B(6,114,-1,minecraft:netherrack)
B(6,114,0,minecraft:netherrack)
B(6,113,1,minecraft:netherrack)
B(6,114,1,minecraft:netherrack)
B(6,113,2,minecraft:netherrack)
B(6,114,2,minecraft:netherrack)
B(6,112,3,minecraft:netherrack)
B(6,113,3,minecraft:netherrack)
B(6,114,3,minecraft:netherrack)
B(6,111,4,minecraft:netherrack)
B(6,112,4,minecraft:netherrack)
B(6,113,4,minecraft:netherrack)
B(6,114,4,minecraft:netherrack)
B(6,111,5,minecraft:netherrack)
B(6,112,5,minecraft:netherrack)
B(6,113,5,minecraft:netherrack)
B(6,114,5,minecraft:netherrack)
B(6,111,6,minecraft:netherrack)
B(6,112,6,minecraft:netherrack)
B(6,113,6,minecraft:netherrack)
B(6,114,6,minecraft:netherrack)
B(6,111,7,minecraft:netherrack)
B(6,112,7,minecraft:netherrack)
B(6,113,7,minecraft:netherrack)
B(6,114,7,minecraft:netherrack)
B(6,111,8,minecraft:netherrack)
B(6,112,8,minecraft:netherrack)
B(6,113,8,minecraft:netherrack)
B(6,114,8,minecraft:netherrack)
B(7,114,-1,minecraft:netherrack)
B(7,114,0,minecraft:netherrack)
B(7,113,1,minecraft:netherrack)
B(7,114,1,minecraft:netherrack)
B(7,112,2,minecraft:netherrack)
B(7,113,2,minecraft:netherrack)
B(7,114,2,minecraft:netherrack)
B(7,111,3,minecraft:netherrack)
B(7,112,3,minecraft:netherrack)
B(7,113,3,minecraft:netherrack)
B(7,114,3,minecraft:netherrack)
B(7,111,4,minecraft:netherrack)
B(7,112,4,minecraft:netherrack)
B(7,113,4,minecraft:netherrack)
B(7,114,4,minecraft:netherrack)
B(7,110,5,minecraft:netherrack)
B(7,111,5,minecraft:netherrack)
B(7,112,5,minecraft:netherrack)
B(7,113,5,minecraft:netherrack)
B(7,114,5,minecraft:netherrack)
B(7,110,6,minecraft:netherrack)
B(7,111,6,minecraft:netherrack)
B(7,112,6,minecraft:netherrack)
B(7,113,6,minecraft:netherrack)
B(7,114,6,minecraft:netherrack)
B(7,110,7,minecraft:netherrack)
B(7,111,7,minecraft:netherrack)
B(7,112,7,minecraft:netherrack)
B(7,113,7,minecraft:netherrack)
B(7,114,7,minecraft:netherrack)
B(7,109,8,minecraft:netherrack)
B(7,110,8,minecraft:netherrack)
B(7,111,8,minecraft:netherrack)
B(7,112,8,minecraft:netherrack)
B(7,113,8,minecraft:netherrack)
B(7,114,8,minecraft:netherrack)

#######################################################################
# +-----------------------------------------------------------------+ #
# |                             Branches                            | #
# +-----------------------------------------------------------------+ #
#######################################################################

Branch(16,0,0,true,LargeNetherrackConnectedStalactite1_C1_R3,NORTH,100.0,0)
Branch(0,0,16,true,LargeNetherrackConnectedStalactite1_C0_R4,NORTH,100.0,0)

#######################################################################
# +-----------------------------------------------------------------+ #
# |                             Entities                            | #
# +-----------------------------------------------------------------+ #
#######################################################################

