
#######################################################################
# +-----------------------------------------------------------------+ #
# |                            BO4 object                           | #
# +-----------------------------------------------------------------+ #
#######################################################################

Author: Unknown

Description: No description given

SettingsMode: WriteWithoutComments


#######################################################################
# +-----------------------------------------------------------------+ #
# |                          Main settings                          | #
# +-----------------------------------------------------------------+ #
#######################################################################

FixedRotation: 

Frequency: 0

SpawnHeight: highestBlock

UseCenterForHighestBlock: true

##############################
# Height Limits for the BO4. #
##############################

MinHeight: 0

MaxHeight: 255

InheritBO3: 

InheritBO3Rotation: NORTH

OverrideChildSettings: true

OverrideParentHeight: false

CanOverride: false

BranchFrequency: 0

BranchFrequencyGroup: 

MustBeBelowOther: false

MustBeInside: 

CannotBeInside: 

ReplacesBO3: 

MustBeInsideWorldBorders: false

CanSpawnOnWater: true

SpawnOnWaterOnly: false

SpawnUnderWater: false

SpawnAtWaterLevel: false

HeightOffset: 0

RemoveAir: true

ReplaceAbove: 

ReplaceBelow: 

ReplaceWithBiomeBlocks: true

ReplaceWithSurfaceBlock: GRASS

ReplaceWithGroundBlock: DIRT

ReplaceWithStoneBlock: STONE

SmoothRadius: 0

SmoothHeightOffset: 0

SmoothStartTop: false

SmoothStartWood: false

SmoothingSurfaceBlock: 

SmoothingGroundBlock: 

BO3Group: 

IsSpawnPoint: false

DoReplaceBlocks: true


#######################################################################
# +-----------------------------------------------------------------+ #
# |                              Blocks                             | #
# +-----------------------------------------------------------------+ #
#######################################################################

B(-8,0,-7,minecraft:nether_wart_block)
B(-8,1,-7,minecraft:nether_wart_block)
B(-8,2,-7,minecraft:nether_wart_block)
B(-8,3,-7,minecraft:nether_wart_block)
B(-8,4,-7,minecraft:nether_wart_block)
B(-8,5,-7,minecraft:nether_wart_block)
B(-8,6,-7,minecraft:nether_wart_block)
B(-8,7,-7,minecraft:nether_wart_block)
B(-8,8,-7,minecraft:nether_wart_block)
B(-8,9,-7,minecraft:nether_wart_block)
B(-8,10,-7,minecraft:nether_wart_block)
B(-8,11,-7,minecraft:nether_wart_block)
B(-8,12,-7,minecraft:nether_wart_block)
B(-8,13,-7,minecraft:nether_wart_block)
B(-8,14,-7,minecraft:nether_wart_block)
B(-8,15,-7,minecraft:nether_wart_block)
B(-8,16,-7,minecraft:nether_wart_block)
B(-8,17,-7,minecraft:nether_wart_block)
B(-8,18,-7,minecraft:nether_wart_block)
B(-8,19,-7,minecraft:nether_wart_block)
B(-8,20,-7,minecraft:nether_wart_block)
B(-8,21,-7,minecraft:nether_wart_block)
B(-8,22,-7,minecraft:nether_wart_block)
B(-8,23,-7,minecraft:nether_wart_block)
B(-8,24,-7,minecraft:nether_wart_block)
B(-8,25,-7,minecraft:nether_wart_block)
B(-8,26,-7,minecraft:nether_wart_block)
B(-8,27,-7,minecraft:nether_wart_block)
B(-8,28,-7,minecraft:nether_wart_block)
B(-8,29,-7,minecraft:nether_wart_block)
B(-8,30,-7,minecraft:nether_wart_block)
B(-8,31,-7,minecraft:nether_wart_block)
B(-8,32,-7,minecraft:nether_wart_block)
B(-8,33,-7,minecraft:nether_wart_block)
B(-8,34,-7,minecraft:nether_wart_block)
B(-8,35,-7,minecraft:nether_wart_block)
B(-8,36,-7,minecraft:nether_wart_block)
B(-8,37,-7,minecraft:nether_wart_block)
B(-8,38,-7,minecraft:nether_wart_block)
B(-8,65,-7,minecraft:nether_wart_block)
B(-8,66,-7,minecraft:nether_wart_block)
B(-8,67,-7,minecraft:nether_wart_block)
B(-8,68,-7,minecraft:nether_wart_block)
B(-8,69,-7,minecraft:nether_wart_block)
B(-8,70,-7,minecraft:nether_wart_block)
B(-8,71,-7,minecraft:nether_wart_block)
B(-8,72,-7,minecraft:nether_wart_block)
B(-8,73,-7,minecraft:nether_wart_block)
B(-8,74,-7,minecraft:nether_wart_block)
B(-8,75,-7,minecraft:nether_wart_block)
B(-8,0,-6,minecraft:nether_wart_block)
B(-8,1,-6,minecraft:nether_wart_block)
B(-8,2,-6,minecraft:nether_wart_block)
B(-8,3,-6,minecraft:nether_wart_block)
B(-8,4,-6,minecraft:nether_wart_block)
B(-8,5,-6,minecraft:nether_wart_block)
B(-8,6,-6,minecraft:nether_wart_block)
B(-8,7,-6,minecraft:nether_wart_block)
B(-8,8,-6,minecraft:nether_wart_block)
B(-8,9,-6,minecraft:nether_wart_block)
B(-8,10,-6,minecraft:nether_wart_block)
B(-8,11,-6,minecraft:nether_wart_block)
B(-8,12,-6,minecraft:nether_wart_block)
B(-8,13,-6,minecraft:nether_wart_block)
B(-8,14,-6,minecraft:nether_wart_block)
B(-8,15,-6,minecraft:nether_wart_block)
B(-8,16,-6,minecraft:nether_wart_block)
B(-8,17,-6,minecraft:nether_wart_block)
B(-8,18,-6,minecraft:nether_wart_block)
B(-8,19,-6,minecraft:nether_wart_block)
B(-8,20,-6,minecraft:nether_wart_block)
B(-8,21,-6,minecraft:nether_wart_block)
B(-8,22,-6,minecraft:nether_wart_block)
B(-8,23,-6,minecraft:nether_wart_block)
B(-8,24,-6,minecraft:nether_wart_block)
B(-8,25,-6,minecraft:nether_wart_block)
B(-8,26,-6,minecraft:nether_wart_block)
B(-8,27,-6,minecraft:nether_wart_block)
B(-8,28,-6,minecraft:nether_wart_block)
B(-8,29,-6,minecraft:nether_wart_block)
B(-8,30,-6,minecraft:nether_wart_block)
B(-8,31,-6,minecraft:nether_wart_block)
B(-8,32,-6,minecraft:nether_wart_block)
B(-8,33,-6,minecraft:nether_wart_block)
B(-8,40,-6,minecraft:nether_wart_block)
B(-8,41,-6,minecraft:nether_wart_block)
B(-8,42,-6,minecraft:nether_wart_block)
B(-8,43,-6,minecraft:nether_wart_block)
B(-8,44,-6,minecraft:nether_wart_block)
B(-8,65,-6,minecraft:nether_wart_block)
B(-8,66,-6,minecraft:nether_wart_block)
B(-8,67,-6,minecraft:nether_wart_block)
B(-8,68,-6,minecraft:nether_wart_block)
B(-8,69,-6,minecraft:nether_wart_block)
B(-8,70,-6,minecraft:nether_wart_block)
B(-8,71,-6,minecraft:nether_wart_block)
B(-8,72,-6,minecraft:nether_wart_block)
B(-8,73,-6,minecraft:nether_wart_block)
B(-8,74,-6,minecraft:nether_wart_block)
B(-8,75,-6,minecraft:nether_wart_block)
B(-8,0,-5,minecraft:nether_wart_block)
B(-8,1,-5,minecraft:nether_wart_block)
B(-8,2,-5,minecraft:nether_wart_block)
B(-8,3,-5,minecraft:nether_wart_block)
B(-8,4,-5,minecraft:nether_wart_block)
B(-8,5,-5,minecraft:nether_wart_block)
B(-8,6,-5,minecraft:nether_wart_block)
B(-8,7,-5,minecraft:nether_wart_block)
B(-8,8,-5,minecraft:nether_wart_block)
B(-8,9,-5,minecraft:nether_wart_block)
B(-8,10,-5,minecraft:nether_wart_block)
B(-8,11,-5,minecraft:nether_wart_block)
B(-8,12,-5,minecraft:nether_wart_block)
B(-8,13,-5,minecraft:nether_wart_block)
B(-8,14,-5,minecraft:nether_wart_block)
B(-8,15,-5,minecraft:nether_wart_block)
B(-8,16,-5,minecraft:nether_wart_block)
B(-8,17,-5,minecraft:nether_wart_block)
B(-8,18,-5,minecraft:nether_wart_block)
B(-8,19,-5,minecraft:nether_wart_block)
B(-8,20,-5,minecraft:nether_wart_block)
B(-8,21,-5,minecraft:nether_wart_block)
B(-8,22,-5,minecraft:nether_wart_block)
B(-8,23,-5,minecraft:nether_wart_block)
B(-8,24,-5,minecraft:nether_wart_block)
B(-8,25,-5,minecraft:nether_wart_block)
B(-8,26,-5,minecraft:nether_wart_block)
B(-8,27,-5,minecraft:nether_wart_block)
B(-8,28,-5,minecraft:nether_wart_block)
B(-8,29,-5,minecraft:nether_wart_block)
B(-8,30,-5,minecraft:nether_wart_block)
B(-8,31,-5,minecraft:nether_wart_block)
B(-8,32,-5,minecraft:nether_wart_block)
B(-8,39,-5,minecraft:nether_wart_block)
B(-8,40,-5,minecraft:nether_wart_block)
B(-8,41,-5,minecraft:nether_wart_block)
B(-8,42,-5,minecraft:nether_wart_block)
B(-8,43,-5,minecraft:nether_wart_block)
B(-8,44,-5,minecraft:nether_wart_block)
B(-8,45,-5,minecraft:nether_wart_block)
B(-8,66,-5,minecraft:nether_wart_block)
B(-8,67,-5,minecraft:nether_wart_block)
B(-8,68,-5,minecraft:nether_wart_block)
B(-8,69,-5,minecraft:nether_wart_block)
B(-8,70,-5,minecraft:nether_wart_block)
B(-8,71,-5,minecraft:nether_wart_block)
B(-8,72,-5,minecraft:nether_wart_block)
B(-8,73,-5,minecraft:nether_wart_block)
B(-8,74,-5,minecraft:nether_wart_block)
B(-8,0,-4,minecraft:nether_wart_block)
B(-8,1,-4,minecraft:nether_wart_block)
B(-8,2,-4,minecraft:nether_wart_block)
B(-8,3,-4,minecraft:nether_wart_block)
B(-8,4,-4,minecraft:nether_wart_block)
B(-8,5,-4,minecraft:nether_wart_block)
B(-8,6,-4,minecraft:nether_wart_block)
B(-8,7,-4,minecraft:nether_wart_block)
B(-8,8,-4,minecraft:nether_wart_block)
B(-8,9,-4,minecraft:nether_wart_block)
B(-8,10,-4,minecraft:nether_wart_block)
B(-8,11,-4,minecraft:nether_wart_block)
B(-8,12,-4,minecraft:nether_wart_block)
B(-8,13,-4,minecraft:nether_wart_block)
B(-8,14,-4,minecraft:nether_wart_block)
B(-8,15,-4,minecraft:nether_wart_block)
B(-8,16,-4,minecraft:nether_wart_block)
B(-8,17,-4,minecraft:nether_wart_block)
B(-8,18,-4,minecraft:nether_wart_block)
B(-8,19,-4,minecraft:nether_wart_block)
B(-8,20,-4,minecraft:nether_wart_block)
B(-8,21,-4,minecraft:nether_wart_block)
B(-8,22,-4,minecraft:nether_wart_block)
B(-8,23,-4,minecraft:nether_wart_block)
B(-8,24,-4,minecraft:nether_wart_block)
B(-8,25,-4,minecraft:nether_wart_block)
B(-8,26,-4,minecraft:nether_wart_block)
B(-8,27,-4,minecraft:nether_wart_block)
B(-8,28,-4,minecraft:nether_wart_block)
B(-8,29,-4,minecraft:nether_wart_block)
B(-8,30,-4,minecraft:nether_wart_block)
B(-8,39,-4,minecraft:nether_wart_block)
B(-8,40,-4,minecraft:nether_wart_block)
B(-8,41,-4,minecraft:nether_wart_block)
B(-8,42,-4,minecraft:nether_wart_block)
B(-8,43,-4,minecraft:nether_wart_block)
B(-8,44,-4,minecraft:nether_wart_block)
B(-8,45,-4,minecraft:nether_wart_block)
B(-8,66,-4,minecraft:nether_wart_block)
B(-8,67,-4,minecraft:nether_wart_block)
B(-8,68,-4,minecraft:nether_wart_block)
B(-8,69,-4,minecraft:nether_wart_block)
B(-8,70,-4,minecraft:nether_wart_block)
B(-8,71,-4,minecraft:nether_wart_block)
B(-8,72,-4,minecraft:nether_wart_block)
B(-8,73,-4,minecraft:nether_wart_block)
B(-8,74,-4,minecraft:nether_wart_block)
B(-8,0,-3,minecraft:nether_wart_block)
B(-8,1,-3,minecraft:nether_wart_block)
B(-8,2,-3,minecraft:nether_wart_block)
B(-8,3,-3,minecraft:nether_wart_block)
B(-8,4,-3,minecraft:nether_wart_block)
B(-8,5,-3,minecraft:nether_wart_block)
B(-8,6,-3,minecraft:nether_wart_block)
B(-8,7,-3,minecraft:nether_wart_block)
B(-8,8,-3,minecraft:nether_wart_block)
B(-8,9,-3,minecraft:nether_wart_block)
B(-8,10,-3,minecraft:nether_wart_block)
B(-8,11,-3,minecraft:nether_wart_block)
B(-8,12,-3,minecraft:nether_wart_block)
B(-8,13,-3,minecraft:nether_wart_block)
B(-8,14,-3,minecraft:nether_wart_block)
B(-8,15,-3,minecraft:nether_wart_block)
B(-8,16,-3,minecraft:nether_wart_block)
B(-8,17,-3,minecraft:nether_wart_block)
B(-8,18,-3,minecraft:nether_wart_block)
B(-8,19,-3,minecraft:nether_wart_block)
B(-8,20,-3,minecraft:nether_wart_block)
B(-8,21,-3,minecraft:nether_wart_block)
B(-8,22,-3,minecraft:nether_wart_block)
B(-8,23,-3,minecraft:nether_wart_block)
B(-8,24,-3,minecraft:nether_wart_block)
B(-8,25,-3,minecraft:nether_wart_block)
B(-8,26,-3,minecraft:nether_wart_block)
B(-8,27,-3,minecraft:nether_wart_block)
B(-8,28,-3,minecraft:nether_wart_block)
B(-8,29,-3,minecraft:nether_wart_block)
B(-8,39,-3,minecraft:nether_wart_block)
B(-8,40,-3,minecraft:nether_wart_block)
B(-8,41,-3,minecraft:nether_wart_block)
B(-8,42,-3,minecraft:nether_wart_block)
B(-8,43,-3,minecraft:nether_wart_block)
B(-8,44,-3,minecraft:nether_wart_block)
B(-8,45,-3,minecraft:nether_wart_block)
B(-8,67,-3,minecraft:nether_wart_block)
B(-8,68,-3,minecraft:nether_wart_block)
B(-8,69,-3,minecraft:nether_wart_block)
B(-8,70,-3,minecraft:nether_wart_block)
B(-8,71,-3,minecraft:nether_wart_block)
B(-8,72,-3,minecraft:nether_wart_block)
B(-8,73,-3,minecraft:nether_wart_block)
B(-8,0,-2,minecraft:nether_wart_block)
B(-8,1,-2,minecraft:nether_wart_block)
B(-8,2,-2,minecraft:nether_wart_block)
B(-8,3,-2,minecraft:nether_wart_block)
B(-8,4,-2,minecraft:nether_wart_block)
B(-8,5,-2,minecraft:nether_wart_block)
B(-8,6,-2,minecraft:nether_wart_block)
B(-8,7,-2,minecraft:nether_wart_block)
B(-8,8,-2,minecraft:nether_wart_block)
B(-8,9,-2,minecraft:nether_wart_block)
B(-8,10,-2,minecraft:nether_wart_block)
B(-8,11,-2,minecraft:nether_wart_block)
B(-8,12,-2,minecraft:nether_wart_block)
B(-8,13,-2,minecraft:nether_wart_block)
B(-8,14,-2,minecraft:nether_wart_block)
B(-8,15,-2,minecraft:nether_wart_block)
B(-8,16,-2,minecraft:nether_wart_block)
B(-8,17,-2,minecraft:nether_wart_block)
B(-8,18,-2,minecraft:nether_wart_block)
B(-8,19,-2,minecraft:nether_wart_block)
B(-8,20,-2,minecraft:nether_wart_block)
B(-8,21,-2,minecraft:nether_wart_block)
B(-8,22,-2,minecraft:nether_wart_block)
B(-8,23,-2,minecraft:nether_wart_block)
B(-8,24,-2,minecraft:nether_wart_block)
B(-8,25,-2,minecraft:nether_wart_block)
B(-8,26,-2,minecraft:nether_wart_block)
B(-8,27,-2,minecraft:nether_wart_block)
B(-8,28,-2,minecraft:nether_wart_block)
B(-8,39,-2,minecraft:nether_wart_block)
B(-8,40,-2,minecraft:nether_wart_block)
B(-8,41,-2,minecraft:nether_wart_block)
B(-8,42,-2,minecraft:nether_wart_block)
B(-8,43,-2,minecraft:nether_wart_block)
B(-8,44,-2,minecraft:nether_wart_block)
B(-8,45,-2,minecraft:nether_wart_block)
B(-8,68,-2,minecraft:nether_wart_block)
B(-8,69,-2,minecraft:nether_wart_block)
B(-8,70,-2,minecraft:nether_wart_block)
B(-8,71,-2,minecraft:nether_wart_block)
B(-8,72,-2,minecraft:nether_wart_block)
B(-8,9,-1,minecraft:nether_wart_block)
B(-8,10,-1,minecraft:nether_wart_block)
B(-8,11,-1,minecraft:nether_wart_block)
B(-8,12,-1,minecraft:nether_wart_block)
B(-8,13,-1,minecraft:nether_wart_block)
B(-8,14,-1,minecraft:nether_wart_block)
B(-8,15,-1,minecraft:nether_wart_block)
B(-8,16,-1,minecraft:nether_wart_block)
B(-8,17,-1,minecraft:nether_wart_block)
B(-8,18,-1,minecraft:nether_wart_block)
B(-8,19,-1,minecraft:nether_wart_block)
B(-8,20,-1,minecraft:nether_wart_block)
B(-8,21,-1,minecraft:nether_wart_block)
B(-8,22,-1,minecraft:nether_wart_block)
B(-8,23,-1,minecraft:nether_wart_block)
B(-8,24,-1,minecraft:nether_wart_block)
B(-8,38,-1,minecraft:nether_wart_block)
B(-8,39,-1,minecraft:nether_wart_block)
B(-8,40,-1,minecraft:nether_wart_block)
B(-8,41,-1,minecraft:nether_wart_block)
B(-8,42,-1,minecraft:nether_wart_block)
B(-8,43,-1,minecraft:nether_wart_block)
B(-8,44,-1,minecraft:nether_wart_block)
B(-8,45,-1,minecraft:nether_wart_block)
B(-8,14,0,minecraft:nether_wart_block)
B(-8,15,0,minecraft:nether_wart_block)
B(-8,16,0,minecraft:nether_wart_block)
B(-8,17,0,minecraft:nether_wart_block)
B(-8,18,0,minecraft:nether_wart_block)
B(-8,20,0,minecraft:nether_wart_block)
B(-8,21,0,minecraft:nether_wart_block)
B(-8,22,0,minecraft:nether_wart_block)
B(-8,37,0,minecraft:nether_wart_block)
B(-8,38,0,minecraft:nether_wart_block)
B(-8,39,0,minecraft:nether_wart_block)
B(-8,40,0,minecraft:nether_wart_block)
B(-8,41,0,minecraft:nether_wart_block)
B(-8,42,0,minecraft:nether_wart_block)
B(-8,43,0,minecraft:nether_wart_block)
B(-8,44,0,minecraft:nether_wart_block)
B(-8,37,1,minecraft:nether_wart_block)
B(-8,38,1,minecraft:nether_wart_block)
B(-8,39,1,minecraft:nether_wart_block)
B(-8,40,1,minecraft:nether_wart_block)
B(-8,41,1,minecraft:nether_wart_block)
B(-8,37,2,minecraft:nether_wart_block)
B(-8,38,2,minecraft:nether_wart_block)
B(-8,39,2,minecraft:nether_wart_block)
B(-8,40,2,minecraft:nether_wart_block)
B(-8,41,2,minecraft:nether_wart_block)
B(-8,38,3,minecraft:nether_wart_block)
B(-8,39,3,minecraft:nether_wart_block)
B(-8,40,3,minecraft:nether_wart_block)
B(-7,0,-7,minecraft:nether_wart_block)
B(-7,1,-7,minecraft:nether_wart_block)
B(-7,2,-7,minecraft:nether_wart_block)
B(-7,3,-7,minecraft:nether_wart_block)
B(-7,4,-7,minecraft:nether_wart_block)
B(-7,5,-7,minecraft:nether_wart_block)
B(-7,6,-7,minecraft:nether_wart_block)
B(-7,7,-7,minecraft:nether_wart_block)
B(-7,8,-7,minecraft:nether_wart_block)
B(-7,9,-7,minecraft:nether_wart_block)
B(-7,10,-7,minecraft:nether_wart_block)
B(-7,11,-7,minecraft:nether_wart_block)
B(-7,12,-7,minecraft:nether_wart_block)
B(-7,13,-7,minecraft:nether_wart_block)
B(-7,14,-7,minecraft:nether_wart_block)
B(-7,15,-7,minecraft:nether_wart_block)
B(-7,16,-7,minecraft:nether_wart_block)
B(-7,17,-7,minecraft:nether_wart_block)
B(-7,18,-7,minecraft:nether_wart_block)
B(-7,19,-7,minecraft:nether_wart_block)
B(-7,20,-7,minecraft:nether_wart_block)
B(-7,21,-7,minecraft:nether_wart_block)
B(-7,22,-7,minecraft:nether_wart_block)
B(-7,23,-7,minecraft:nether_wart_block)
B(-7,24,-7,minecraft:nether_wart_block)
B(-7,25,-7,minecraft:nether_wart_block)
B(-7,26,-7,minecraft:nether_wart_block)
B(-7,27,-7,minecraft:nether_wart_block)
B(-7,28,-7,minecraft:nether_wart_block)
B(-7,29,-7,minecraft:nether_wart_block)
B(-7,34,-7,minecraft:nether_wart_block)
B(-7,35,-7,minecraft:nether_wart_block)
B(-7,36,-7,minecraft:nether_wart_block)
B(-7,37,-7,minecraft:nether_wart_block)
B(-7,38,-7,minecraft:nether_wart_block)
B(-7,40,-7,minecraft:nether_wart_block)
B(-7,41,-7,minecraft:nether_wart_block)
B(-7,42,-7,minecraft:nether_wart_block)
B(-7,43,-7,minecraft:nether_wart_block)
B(-7,44,-7,minecraft:nether_wart_block)
B(-7,45,-7,minecraft:nether_wart_block)
B(-7,46,-7,minecraft:nether_wart_block)
B(-7,47,-7,minecraft:nether_wart_block)
B(-7,48,-7,minecraft:nether_wart_block)
B(-7,65,-7,minecraft:nether_wart_block)
B(-7,66,-7,minecraft:nether_wart_block)
B(-7,67,-7,minecraft:nether_wart_block)
B(-7,68,-7,minecraft:nether_wart_block)
B(-7,69,-7,minecraft:nether_wart_block)
B(-7,70,-7,minecraft:nether_wart_block)
B(-7,71,-7,minecraft:nether_wart_block)
B(-7,72,-7,minecraft:nether_wart_block)
B(-7,73,-7,minecraft:nether_wart_block)
B(-7,74,-7,minecraft:nether_wart_block)
B(-7,75,-7,minecraft:nether_wart_block)
B(-7,0,-6,minecraft:nether_wart_block)
B(-7,1,-6,minecraft:nether_wart_block)
B(-7,2,-6,minecraft:nether_wart_block)
B(-7,3,-6,minecraft:nether_wart_block)
B(-7,4,-6,minecraft:nether_wart_block)
B(-7,5,-6,minecraft:nether_wart_block)
B(-7,6,-6,minecraft:nether_wart_block)
B(-7,7,-6,minecraft:nether_wart_block)
B(-7,8,-6,minecraft:nether_wart_block)
B(-7,9,-6,minecraft:nether_wart_block)
B(-7,10,-6,minecraft:nether_wart_block)
B(-7,11,-6,minecraft:nether_wart_block)
B(-7,12,-6,minecraft:nether_wart_block)
B(-7,13,-6,minecraft:nether_wart_block)
B(-7,14,-6,minecraft:nether_wart_block)
B(-7,15,-6,minecraft:nether_wart_block)
B(-7,16,-6,minecraft:nether_wart_block)
B(-7,17,-6,minecraft:nether_wart_block)
B(-7,18,-6,minecraft:nether_wart_block)
B(-7,19,-6,minecraft:nether_wart_block)
B(-7,20,-6,minecraft:nether_wart_block)
B(-7,21,-6,minecraft:nether_wart_block)
B(-7,22,-6,minecraft:nether_wart_block)
B(-7,23,-6,minecraft:nether_wart_block)
B(-7,24,-6,minecraft:nether_wart_block)
B(-7,25,-6,minecraft:nether_wart_block)
B(-7,26,-6,minecraft:nether_wart_block)
B(-7,27,-6,minecraft:nether_wart_block)
B(-7,28,-6,minecraft:nether_wart_block)
B(-7,29,-6,minecraft:nether_wart_block)
B(-7,39,-6,minecraft:nether_wart_block)
B(-7,40,-6,minecraft:nether_wart_block)
B(-7,41,-6,minecraft:nether_wart_block)
B(-7,42,-6,minecraft:nether_wart_block)
B(-7,43,-6,minecraft:nether_wart_block)
B(-7,44,-6,minecraft:nether_wart_block)
B(-7,45,-6,minecraft:nether_wart_block)
B(-7,46,-6,minecraft:nether_wart_block)
B(-7,47,-6,minecraft:nether_wart_block)
B(-7,48,-6,minecraft:nether_wart_block)
B(-7,65,-6,minecraft:nether_wart_block)
B(-7,66,-6,minecraft:nether_wart_block)
B(-7,67,-6,minecraft:nether_wart_block)
B(-7,68,-6,minecraft:nether_wart_block)
B(-7,69,-6,minecraft:nether_wart_block)
B(-7,70,-6,minecraft:nether_wart_block)
B(-7,71,-6,minecraft:nether_wart_block)
B(-7,72,-6,minecraft:nether_wart_block)
B(-7,73,-6,minecraft:nether_wart_block)
B(-7,74,-6,minecraft:nether_wart_block)
B(-7,75,-6,minecraft:nether_wart_block)
B(-7,0,-5,minecraft:nether_wart_block)
B(-7,1,-5,minecraft:nether_wart_block)
B(-7,2,-5,minecraft:nether_wart_block)
B(-7,3,-5,minecraft:nether_wart_block)
B(-7,4,-5,minecraft:nether_wart_block)
B(-7,5,-5,minecraft:nether_wart_block)
B(-7,6,-5,minecraft:nether_wart_block)
B(-7,7,-5,minecraft:nether_wart_block)
B(-7,8,-5,minecraft:nether_wart_block)
B(-7,9,-5,minecraft:nether_wart_block)
B(-7,10,-5,minecraft:nether_wart_block)
B(-7,11,-5,minecraft:nether_wart_block)
B(-7,12,-5,minecraft:nether_wart_block)
B(-7,13,-5,minecraft:nether_wart_block)
B(-7,14,-5,minecraft:nether_wart_block)
B(-7,15,-5,minecraft:nether_wart_block)
B(-7,16,-5,minecraft:nether_wart_block)
B(-7,17,-5,minecraft:nether_wart_block)
B(-7,18,-5,minecraft:nether_wart_block)
B(-7,19,-5,minecraft:nether_wart_block)
B(-7,20,-5,minecraft:nether_wart_block)
B(-7,21,-5,minecraft:nether_wart_block)
B(-7,22,-5,minecraft:nether_wart_block)
B(-7,23,-5,minecraft:nether_wart_block)
B(-7,24,-5,minecraft:nether_wart_block)
B(-7,25,-5,minecraft:nether_wart_block)
B(-7,26,-5,minecraft:nether_wart_block)
B(-7,27,-5,minecraft:nether_wart_block)
B(-7,28,-5,minecraft:nether_wart_block)
B(-7,29,-5,minecraft:nether_wart_block)
B(-7,38,-5,minecraft:nether_wart_block)
B(-7,39,-5,minecraft:nether_wart_block)
B(-7,40,-5,minecraft:nether_wart_block)
B(-7,41,-5,minecraft:nether_wart_block)
B(-7,42,-5,minecraft:nether_wart_block)
B(-7,43,-5,minecraft:nether_wart_block)
B(-7,44,-5,minecraft:nether_wart_block)
B(-7,45,-5,minecraft:nether_wart_block)
B(-7,46,-5,minecraft:nether_wart_block)
B(-7,47,-5,minecraft:nether_wart_block)
B(-7,48,-5,minecraft:nether_wart_block)
B(-7,65,-5,minecraft:nether_wart_block)
B(-7,66,-5,minecraft:nether_wart_block)
B(-7,67,-5,minecraft:nether_wart_block)
B(-7,68,-5,minecraft:nether_wart_block)
B(-7,69,-5,minecraft:nether_wart_block)
B(-7,70,-5,minecraft:nether_wart_block)
B(-7,71,-5,minecraft:nether_wart_block)
B(-7,72,-5,minecraft:nether_wart_block)
B(-7,73,-5,minecraft:nether_wart_block)
B(-7,74,-5,minecraft:nether_wart_block)
B(-7,75,-5,minecraft:nether_wart_block)
B(-7,0,-4,minecraft:nether_wart_block)
B(-7,1,-4,minecraft:nether_wart_block)
B(-7,2,-4,minecraft:nether_wart_block)
B(-7,3,-4,minecraft:nether_wart_block)
B(-7,4,-4,minecraft:nether_wart_block)
B(-7,5,-4,minecraft:nether_wart_block)
B(-7,6,-4,minecraft:nether_wart_block)
B(-7,7,-4,minecraft:nether_wart_block)
B(-7,8,-4,minecraft:nether_wart_block)
B(-7,9,-4,minecraft:nether_wart_block)
B(-7,10,-4,minecraft:nether_wart_block)
B(-7,11,-4,minecraft:nether_wart_block)
B(-7,12,-4,minecraft:nether_wart_block)
B(-7,13,-4,minecraft:nether_wart_block)
B(-7,14,-4,minecraft:nether_wart_block)
B(-7,15,-4,minecraft:nether_wart_block)
B(-7,16,-4,minecraft:nether_wart_block)
B(-7,17,-4,minecraft:nether_wart_block)
B(-7,18,-4,minecraft:nether_wart_block)
B(-7,19,-4,minecraft:nether_wart_block)
B(-7,20,-4,minecraft:nether_wart_block)
B(-7,21,-4,minecraft:nether_wart_block)
B(-7,22,-4,minecraft:nether_wart_block)
B(-7,23,-4,minecraft:nether_wart_block)
B(-7,24,-4,minecraft:nether_wart_block)
B(-7,25,-4,minecraft:nether_wart_block)
B(-7,26,-4,minecraft:nether_wart_block)
B(-7,27,-4,minecraft:nether_wart_block)
B(-7,28,-4,minecraft:nether_wart_block)
B(-7,29,-4,minecraft:nether_wart_block)
B(-7,38,-4,minecraft:nether_wart_block)
B(-7,39,-4,minecraft:nether_wart_block)
B(-7,40,-4,minecraft:nether_wart_block)
B(-7,41,-4,minecraft:nether_wart_block)
B(-7,42,-4,minecraft:nether_wart_block)
B(-7,43,-4,minecraft:nether_wart_block)
B(-7,44,-4,minecraft:nether_wart_block)
B(-7,45,-4,minecraft:nether_wart_block)
B(-7,46,-4,minecraft:nether_wart_block)
B(-7,47,-4,minecraft:nether_wart_block)
B(-7,66,-4,minecraft:nether_wart_block)
B(-7,67,-4,minecraft:nether_wart_block)
B(-7,68,-4,minecraft:nether_wart_block)
B(-7,69,-4,minecraft:nether_wart_block)
B(-7,70,-4,minecraft:nether_wart_block)
B(-7,71,-4,minecraft:nether_wart_block)
B(-7,72,-4,minecraft:nether_wart_block)
B(-7,73,-4,minecraft:nether_wart_block)
B(-7,74,-4,minecraft:nether_wart_block)
B(-7,0,-3,minecraft:nether_wart_block)
B(-7,1,-3,minecraft:nether_wart_block)
B(-7,2,-3,minecraft:nether_wart_block)
B(-7,3,-3,minecraft:nether_wart_block)
B(-7,4,-3,minecraft:nether_wart_block)
B(-7,5,-3,minecraft:nether_wart_block)
B(-7,6,-3,minecraft:nether_wart_block)
B(-7,7,-3,minecraft:nether_wart_block)
B(-7,8,-3,minecraft:nether_wart_block)
B(-7,9,-3,minecraft:nether_wart_block)
B(-7,10,-3,minecraft:nether_wart_block)
B(-7,11,-3,minecraft:nether_wart_block)
B(-7,12,-3,minecraft:nether_wart_block)
B(-7,13,-3,minecraft:nether_wart_block)
B(-7,14,-3,minecraft:nether_wart_block)
B(-7,15,-3,minecraft:nether_wart_block)
B(-7,16,-3,minecraft:nether_wart_block)
B(-7,17,-3,minecraft:nether_wart_block)
B(-7,18,-3,minecraft:nether_wart_block)
B(-7,19,-3,minecraft:nether_wart_block)
B(-7,20,-3,minecraft:nether_wart_block)
B(-7,21,-3,minecraft:nether_wart_block)
B(-7,22,-3,minecraft:nether_wart_block)
B(-7,23,-3,minecraft:nether_wart_block)
B(-7,24,-3,minecraft:nether_wart_block)
B(-7,25,-3,minecraft:nether_wart_block)
B(-7,26,-3,minecraft:nether_wart_block)
B(-7,27,-3,minecraft:nether_wart_block)
B(-7,28,-3,minecraft:nether_wart_block)
B(-7,38,-3,minecraft:nether_wart_block)
B(-7,39,-3,minecraft:nether_wart_block)
B(-7,40,-3,minecraft:nether_wart_block)
B(-7,41,-3,minecraft:nether_wart_block)
B(-7,42,-3,minecraft:nether_wart_block)
B(-7,43,-3,minecraft:nether_wart_block)
B(-7,44,-3,minecraft:nether_wart_block)
B(-7,45,-3,minecraft:nether_wart_block)
B(-7,46,-3,minecraft:nether_wart_block)
B(-7,66,-3,minecraft:nether_wart_block)
B(-7,67,-3,minecraft:nether_wart_block)
B(-7,68,-3,minecraft:nether_wart_block)
B(-7,69,-3,minecraft:nether_wart_block)
B(-7,70,-3,minecraft:nether_wart_block)
B(-7,71,-3,minecraft:nether_wart_block)
B(-7,72,-3,minecraft:nether_wart_block)
B(-7,73,-3,minecraft:nether_wart_block)
B(-7,74,-3,minecraft:nether_wart_block)
B(-7,0,-2,minecraft:nether_wart_block)
B(-7,1,-2,minecraft:nether_wart_block)
B(-7,2,-2,minecraft:nether_wart_block)
B(-7,3,-2,minecraft:nether_wart_block)
B(-7,4,-2,minecraft:nether_wart_block)
B(-7,5,-2,minecraft:nether_wart_block)
B(-7,6,-2,minecraft:nether_wart_block)
B(-7,7,-2,minecraft:nether_wart_block)
B(-7,8,-2,minecraft:nether_wart_block)
B(-7,9,-2,minecraft:nether_wart_block)
B(-7,10,-2,minecraft:nether_wart_block)
B(-7,11,-2,minecraft:nether_wart_block)
B(-7,12,-2,minecraft:nether_wart_block)
B(-7,13,-2,minecraft:nether_wart_block)
B(-7,14,-2,minecraft:nether_wart_block)
B(-7,15,-2,minecraft:nether_wart_block)
B(-7,16,-2,minecraft:nether_wart_block)
B(-7,17,-2,minecraft:nether_wart_block)
B(-7,18,-2,minecraft:nether_wart_block)
B(-7,19,-2,minecraft:nether_wart_block)
B(-7,20,-2,minecraft:nether_wart_block)
B(-7,21,-2,minecraft:nether_wart_block)
B(-7,22,-2,minecraft:nether_wart_block)
B(-7,23,-2,minecraft:nether_wart_block)
B(-7,24,-2,minecraft:nether_wart_block)
B(-7,37,-2,minecraft:nether_wart_block)
B(-7,38,-2,minecraft:nether_wart_block)
B(-7,39,-2,minecraft:nether_wart_block)
B(-7,40,-2,minecraft:nether_wart_block)
B(-7,41,-2,minecraft:nether_wart_block)
B(-7,42,-2,minecraft:nether_wart_block)
B(-7,43,-2,minecraft:nether_wart_block)
B(-7,44,-2,minecraft:nether_wart_block)
B(-7,45,-2,minecraft:nether_wart_block)
B(-7,46,-2,minecraft:nether_wart_block)
B(-7,67,-2,minecraft:nether_wart_block)
B(-7,68,-2,minecraft:nether_wart_block)
B(-7,69,-2,minecraft:nether_wart_block)
B(-7,70,-2,minecraft:nether_wart_block)
B(-7,71,-2,minecraft:nether_wart_block)
B(-7,72,-2,minecraft:nether_wart_block)
B(-7,73,-2,minecraft:nether_wart_block)
B(-7,9,-1,minecraft:nether_wart_block)
B(-7,10,-1,minecraft:nether_wart_block)
B(-7,11,-1,minecraft:nether_wart_block)
B(-7,12,-1,minecraft:nether_wart_block)
B(-7,13,-1,minecraft:nether_wart_block)
B(-7,14,-1,minecraft:nether_wart_block)
B(-7,15,-1,minecraft:nether_wart_block)
B(-7,16,-1,minecraft:nether_wart_block)
B(-7,17,-1,minecraft:nether_wart_block)
B(-7,18,-1,minecraft:nether_wart_block)
B(-7,19,-1,minecraft:nether_wart_block)
B(-7,20,-1,minecraft:nether_wart_block)
B(-7,21,-1,minecraft:nether_wart_block)
B(-7,22,-1,minecraft:nether_wart_block)
B(-7,23,-1,minecraft:nether_wart_block)
B(-7,36,-1,minecraft:nether_wart_block)
B(-7,37,-1,minecraft:nether_wart_block)
B(-7,38,-1,minecraft:nether_wart_block)
B(-7,39,-1,minecraft:nether_wart_block)
B(-7,40,-1,minecraft:nether_wart_block)
B(-7,41,-1,minecraft:nether_wart_block)
B(-7,42,-1,minecraft:nether_wart_block)
B(-7,43,-1,minecraft:nether_wart_block)
B(-7,44,-1,minecraft:nether_wart_block)
B(-7,45,-1,minecraft:nether_wart_block)
B(-7,46,-1,minecraft:nether_wart_block)
B(-7,69,-1,minecraft:nether_wart_block)
B(-7,70,-1,minecraft:nether_wart_block)
B(-7,71,-1,minecraft:nether_wart_block)
B(-7,15,0,minecraft:nether_wart_block)
B(-7,16,0,minecraft:nether_wart_block)
B(-7,17,0,minecraft:nether_wart_block)
B(-7,36,0,minecraft:nether_wart_block)
B(-7,37,0,minecraft:nether_wart_block)
B(-7,38,0,minecraft:nether_wart_block)
B(-7,39,0,minecraft:nether_wart_block)
B(-7,40,0,minecraft:nether_wart_block)
B(-7,41,0,minecraft:nether_wart_block)
B(-7,42,0,minecraft:nether_wart_block)
B(-7,43,0,minecraft:nether_wart_block)
B(-7,44,0,minecraft:nether_wart_block)
B(-7,45,0,minecraft:nether_wart_block)
B(-7,36,1,minecraft:nether_wart_block)
B(-7,37,1,minecraft:nether_wart_block)
B(-7,38,1,minecraft:nether_wart_block)
B(-7,39,1,minecraft:nether_wart_block)
B(-7,40,1,minecraft:nether_wart_block)
B(-7,41,1,minecraft:nether_wart_block)
B(-7,42,1,minecraft:nether_wart_block)
B(-7,43,1,minecraft:nether_wart_block)
B(-7,44,1,minecraft:nether_wart_block)
B(-7,36,2,minecraft:nether_wart_block)
B(-7,37,2,minecraft:nether_wart_block)
B(-7,38,2,minecraft:nether_wart_block)
B(-7,39,2,minecraft:nether_wart_block)
B(-7,40,2,minecraft:nether_wart_block)
B(-7,41,2,minecraft:nether_wart_block)
B(-7,42,2,minecraft:nether_wart_block)
B(-7,36,3,minecraft:nether_wart_block)
B(-7,37,3,minecraft:nether_wart_block)
B(-7,38,3,minecraft:nether_wart_block)
B(-7,39,3,minecraft:nether_wart_block)
B(-7,40,3,minecraft:nether_wart_block)
B(-7,41,3,minecraft:nether_wart_block)
B(-7,42,3,minecraft:nether_wart_block)
B(-7,37,4,minecraft:nether_wart_block)
B(-7,38,4,minecraft:nether_wart_block)
B(-7,39,4,minecraft:nether_wart_block)
B(-7,40,4,minecraft:nether_wart_block)
B(-7,41,4,minecraft:nether_wart_block)
B(-6,0,-7,minecraft:nether_wart_block)
B(-6,1,-7,minecraft:nether_wart_block)
B(-6,2,-7,minecraft:nether_wart_block)
B(-6,3,-7,minecraft:nether_wart_block)
B(-6,4,-7,minecraft:nether_wart_block)
B(-6,5,-7,minecraft:nether_wart_block)
B(-6,6,-7,minecraft:nether_wart_block)
B(-6,7,-7,minecraft:nether_wart_block)
B(-6,8,-7,minecraft:nether_wart_block)
B(-6,9,-7,minecraft:nether_wart_block)
B(-6,10,-7,minecraft:nether_wart_block)
B(-6,11,-7,minecraft:nether_wart_block)
B(-6,12,-7,minecraft:nether_wart_block)
B(-6,13,-7,minecraft:nether_wart_block)
B(-6,14,-7,minecraft:nether_wart_block)
B(-6,15,-7,minecraft:nether_wart_block)
B(-6,16,-7,minecraft:nether_wart_block)
B(-6,17,-7,minecraft:nether_wart_block)
B(-6,18,-7,minecraft:nether_wart_block)
B(-6,19,-7,minecraft:nether_wart_block)
B(-6,20,-7,minecraft:nether_wart_block)
B(-6,21,-7,minecraft:nether_wart_block)
B(-6,22,-7,minecraft:nether_wart_block)
B(-6,23,-7,minecraft:nether_wart_block)
B(-6,24,-7,minecraft:nether_wart_block)
B(-6,25,-7,minecraft:nether_wart_block)
B(-6,26,-7,minecraft:nether_wart_block)
B(-6,27,-7,minecraft:nether_wart_block)
B(-6,28,-7,minecraft:nether_wart_block)
B(-6,35,-7,minecraft:nether_wart_block)
B(-6,36,-7,minecraft:nether_wart_block)
B(-6,37,-7,minecraft:nether_wart_block)
B(-6,39,-7,minecraft:nether_wart_block)
B(-6,40,-7,minecraft:nether_wart_block)
B(-6,41,-7,minecraft:nether_wart_block)
B(-6,42,-7,minecraft:nether_wart_block)
B(-6,43,-7,minecraft:nether_wart_block)
B(-6,44,-7,minecraft:nether_wart_block)
B(-6,45,-7,minecraft:nether_wart_block)
B(-6,46,-7,minecraft:nether_wart_block)
B(-6,47,-7,minecraft:nether_wart_block)
B(-6,48,-7,minecraft:nether_wart_block)
B(-6,49,-7,minecraft:nether_wart_block)
B(-6,65,-7,minecraft:nether_wart_block)
B(-6,66,-7,minecraft:nether_wart_block)
B(-6,67,-7,minecraft:nether_wart_block)
B(-6,68,-7,minecraft:nether_wart_block)
B(-6,69,-7,minecraft:nether_wart_block)
B(-6,70,-7,minecraft:nether_wart_block)
B(-6,71,-7,minecraft:nether_wart_block)
B(-6,72,-7,minecraft:nether_wart_block)
B(-6,73,-7,minecraft:nether_wart_block)
B(-6,74,-7,minecraft:nether_wart_block)
B(-6,75,-7,minecraft:nether_wart_block)
B(-6,0,-6,minecraft:nether_wart_block)
B(-6,1,-6,minecraft:nether_wart_block)
B(-6,2,-6,minecraft:nether_wart_block)
B(-6,3,-6,minecraft:nether_wart_block)
B(-6,4,-6,minecraft:nether_wart_block)
B(-6,5,-6,minecraft:nether_wart_block)
B(-6,6,-6,minecraft:nether_wart_block)
B(-6,7,-6,minecraft:nether_wart_block)
B(-6,8,-6,minecraft:nether_wart_block)
B(-6,9,-6,minecraft:nether_wart_block)
B(-6,10,-6,minecraft:nether_wart_block)
B(-6,11,-6,minecraft:nether_wart_block)
B(-6,12,-6,minecraft:nether_wart_block)
B(-6,13,-6,minecraft:nether_wart_block)
B(-6,14,-6,minecraft:nether_wart_block)
B(-6,15,-6,minecraft:nether_wart_block)
B(-6,16,-6,minecraft:nether_wart_block)
B(-6,17,-6,minecraft:nether_wart_block)
B(-6,18,-6,minecraft:nether_wart_block)
B(-6,19,-6,minecraft:nether_wart_block)
B(-6,20,-6,minecraft:nether_wart_block)
B(-6,21,-6,minecraft:nether_wart_block)
B(-6,22,-6,minecraft:nether_wart_block)
B(-6,23,-6,minecraft:nether_wart_block)
B(-6,24,-6,minecraft:nether_wart_block)
B(-6,25,-6,minecraft:nether_wart_block)
B(-6,26,-6,minecraft:nether_wart_block)
B(-6,27,-6,minecraft:nether_wart_block)
B(-6,28,-6,minecraft:nether_wart_block)
B(-6,38,-6,minecraft:nether_wart_block)
B(-6,39,-6,minecraft:nether_wart_block)
B(-6,40,-6,minecraft:nether_wart_block)
B(-6,41,-6,minecraft:nether_wart_block)
B(-6,42,-6,minecraft:nether_wart_block)
B(-6,43,-6,minecraft:nether_wart_block)
B(-6,44,-6,minecraft:nether_wart_block)
B(-6,45,-6,minecraft:nether_wart_block)
B(-6,46,-6,minecraft:nether_wart_block)
B(-6,47,-6,minecraft:nether_wart_block)
B(-6,48,-6,minecraft:nether_wart_block)
B(-6,49,-6,minecraft:nether_wart_block)
B(-6,65,-6,minecraft:nether_wart_block)
B(-6,66,-6,minecraft:nether_wart_block)
B(-6,67,-6,minecraft:nether_wart_block)
B(-6,68,-6,minecraft:nether_wart_block)
B(-6,69,-6,minecraft:nether_wart_block)
B(-6,70,-6,minecraft:nether_wart_block)
B(-6,71,-6,minecraft:nether_wart_block)
B(-6,72,-6,minecraft:nether_wart_block)
B(-6,73,-6,minecraft:nether_wart_block)
B(-6,74,-6,minecraft:nether_wart_block)
B(-6,75,-6,minecraft:nether_wart_block)
B(-6,0,-5,minecraft:nether_wart_block)
B(-6,1,-5,minecraft:nether_wart_block)
B(-6,2,-5,minecraft:nether_wart_block)
B(-6,3,-5,minecraft:nether_wart_block)
B(-6,4,-5,minecraft:nether_wart_block)
B(-6,5,-5,minecraft:nether_wart_block)
B(-6,6,-5,minecraft:nether_wart_block)
B(-6,7,-5,minecraft:nether_wart_block)
B(-6,8,-5,minecraft:nether_wart_block)
B(-6,9,-5,minecraft:nether_wart_block)
B(-6,10,-5,minecraft:nether_wart_block)
B(-6,11,-5,minecraft:nether_wart_block)
B(-6,12,-5,minecraft:nether_wart_block)
B(-6,13,-5,minecraft:nether_wart_block)
B(-6,14,-5,minecraft:nether_wart_block)
B(-6,15,-5,minecraft:nether_wart_block)
B(-6,16,-5,minecraft:nether_wart_block)
B(-6,17,-5,minecraft:nether_wart_block)
B(-6,18,-5,minecraft:nether_wart_block)
B(-6,19,-5,minecraft:nether_wart_block)
B(-6,20,-5,minecraft:nether_wart_block)
B(-6,21,-5,minecraft:nether_wart_block)
B(-6,22,-5,minecraft:nether_wart_block)
B(-6,23,-5,minecraft:nether_wart_block)
B(-6,24,-5,minecraft:nether_wart_block)
B(-6,25,-5,minecraft:nether_wart_block)
B(-6,26,-5,minecraft:nether_wart_block)
B(-6,27,-5,minecraft:nether_wart_block)
B(-6,28,-5,minecraft:nether_wart_block)
B(-6,38,-5,minecraft:nether_wart_block)
B(-6,39,-5,minecraft:nether_wart_block)
B(-6,40,-5,minecraft:nether_wart_block)
B(-6,41,-5,minecraft:nether_wart_block)
B(-6,42,-5,minecraft:nether_wart_block)
B(-6,43,-5,minecraft:nether_wart_block)
B(-6,44,-5,minecraft:nether_wart_block)
B(-6,45,-5,minecraft:nether_wart_block)
B(-6,46,-5,minecraft:nether_wart_block)
B(-6,47,-5,minecraft:nether_wart_block)
B(-6,48,-5,minecraft:nether_wart_block)
B(-6,49,-5,minecraft:nether_wart_block)
B(-6,65,-5,minecraft:nether_wart_block)
B(-6,66,-5,minecraft:nether_wart_block)
B(-6,67,-5,minecraft:nether_wart_block)
B(-6,68,-5,minecraft:nether_wart_block)
B(-6,69,-5,minecraft:nether_wart_block)
B(-6,70,-5,minecraft:nether_wart_block)
B(-6,71,-5,minecraft:nether_wart_block)
B(-6,72,-5,minecraft:nether_wart_block)
B(-6,73,-5,minecraft:nether_wart_block)
B(-6,74,-5,minecraft:nether_wart_block)
B(-6,75,-5,minecraft:nether_wart_block)
B(-6,0,-4,minecraft:nether_wart_block)
B(-6,1,-4,minecraft:nether_wart_block)
B(-6,2,-4,minecraft:nether_wart_block)
B(-6,3,-4,minecraft:nether_wart_block)
B(-6,4,-4,minecraft:nether_wart_block)
B(-6,5,-4,minecraft:nether_wart_block)
B(-6,6,-4,minecraft:nether_wart_block)
B(-6,7,-4,minecraft:nether_wart_block)
B(-6,8,-4,minecraft:nether_wart_block)
B(-6,9,-4,minecraft:nether_wart_block)
B(-6,10,-4,minecraft:nether_wart_block)
B(-6,11,-4,minecraft:nether_wart_block)
B(-6,12,-4,minecraft:nether_wart_block)
B(-6,13,-4,minecraft:nether_wart_block)
B(-6,14,-4,minecraft:nether_wart_block)
B(-6,15,-4,minecraft:nether_wart_block)
B(-6,16,-4,minecraft:nether_wart_block)
B(-6,17,-4,minecraft:nether_wart_block)
B(-6,18,-4,minecraft:nether_wart_block)
B(-6,19,-4,minecraft:nether_wart_block)
B(-6,20,-4,minecraft:nether_wart_block)
B(-6,21,-4,minecraft:nether_wart_block)
B(-6,22,-4,minecraft:nether_wart_block)
B(-6,23,-4,minecraft:nether_wart_block)
B(-6,24,-4,minecraft:nether_wart_block)
B(-6,25,-4,minecraft:nether_wart_block)
B(-6,26,-4,minecraft:nether_wart_block)
B(-6,27,-4,minecraft:nether_wart_block)
B(-6,37,-4,minecraft:nether_wart_block)
B(-6,38,-4,minecraft:nether_wart_block)
B(-6,39,-4,minecraft:nether_wart_block)
B(-6,40,-4,minecraft:nether_wart_block)
B(-6,41,-4,minecraft:nether_wart_block)
B(-6,42,-4,minecraft:nether_wart_block)
B(-6,43,-4,minecraft:nether_wart_block)
B(-6,44,-4,minecraft:nether_wart_block)
B(-6,45,-4,minecraft:nether_wart_block)
B(-6,46,-4,minecraft:nether_wart_block)
B(-6,47,-4,minecraft:nether_wart_block)
B(-6,48,-4,minecraft:nether_wart_block)
B(-6,49,-4,minecraft:nether_wart_block)
B(-6,65,-4,minecraft:nether_wart_block)
B(-6,66,-4,minecraft:nether_wart_block)
B(-6,67,-4,minecraft:nether_wart_block)
B(-6,68,-4,minecraft:nether_wart_block)
B(-6,69,-4,minecraft:nether_wart_block)
B(-6,70,-4,minecraft:nether_wart_block)
B(-6,71,-4,minecraft:nether_wart_block)
B(-6,72,-4,minecraft:nether_wart_block)
B(-6,73,-4,minecraft:nether_wart_block)
B(-6,74,-4,minecraft:nether_wart_block)
B(-6,75,-4,minecraft:nether_wart_block)
B(-6,0,-3,minecraft:nether_wart_block)
B(-6,1,-3,minecraft:nether_wart_block)
B(-6,2,-3,minecraft:nether_wart_block)
B(-6,3,-3,minecraft:nether_wart_block)
B(-6,4,-3,minecraft:nether_wart_block)
B(-6,5,-3,minecraft:nether_wart_block)
B(-6,6,-3,minecraft:nether_wart_block)
B(-6,7,-3,minecraft:nether_wart_block)
B(-6,8,-3,minecraft:nether_wart_block)
B(-6,9,-3,minecraft:nether_wart_block)
B(-6,10,-3,minecraft:nether_wart_block)
B(-6,11,-3,minecraft:nether_wart_block)
B(-6,12,-3,minecraft:nether_wart_block)
B(-6,13,-3,minecraft:nether_wart_block)
B(-6,14,-3,minecraft:nether_wart_block)
B(-6,15,-3,minecraft:nether_wart_block)
B(-6,16,-3,minecraft:nether_wart_block)
B(-6,17,-3,minecraft:nether_wart_block)
B(-6,18,-3,minecraft:nether_wart_block)
B(-6,19,-3,minecraft:nether_wart_block)
B(-6,20,-3,minecraft:nether_wart_block)
B(-6,21,-3,minecraft:nether_wart_block)
B(-6,22,-3,minecraft:nether_wart_block)
B(-6,23,-3,minecraft:nether_wart_block)
B(-6,24,-3,minecraft:nether_wart_block)
B(-6,37,-3,minecraft:nether_wart_block)
B(-6,38,-3,minecraft:nether_wart_block)
B(-6,39,-3,minecraft:nether_wart_block)
B(-6,40,-3,minecraft:nether_wart_block)
B(-6,41,-3,minecraft:nether_wart_block)
B(-6,42,-3,minecraft:nether_wart_block)
B(-6,43,-3,minecraft:nether_wart_block)
B(-6,44,-3,minecraft:nether_wart_block)
B(-6,45,-3,minecraft:nether_wart_block)
B(-6,46,-3,minecraft:nether_wart_block)
B(-6,47,-3,minecraft:nether_wart_block)
B(-6,48,-3,minecraft:nether_wart_block)
B(-6,66,-3,minecraft:nether_wart_block)
B(-6,67,-3,minecraft:nether_wart_block)
B(-6,68,-3,minecraft:nether_wart_block)
B(-6,69,-3,minecraft:nether_wart_block)
B(-6,70,-3,minecraft:nether_wart_block)
B(-6,71,-3,minecraft:nether_wart_block)
B(-6,72,-3,minecraft:nether_wart_block)
B(-6,73,-3,minecraft:nether_wart_block)
B(-6,74,-3,minecraft:nether_wart_block)
B(-6,0,-2,minecraft:nether_wart_block)
B(-6,1,-2,minecraft:nether_wart_block)
B(-6,2,-2,minecraft:nether_wart_block)
B(-6,5,-2,minecraft:nether_wart_block)
B(-6,6,-2,minecraft:nether_wart_block)
B(-6,7,-2,minecraft:nether_wart_block)
B(-6,8,-2,minecraft:nether_wart_block)
B(-6,9,-2,minecraft:nether_wart_block)
B(-6,10,-2,minecraft:nether_wart_block)
B(-6,11,-2,minecraft:nether_wart_block)
B(-6,12,-2,minecraft:nether_wart_block)
B(-6,13,-2,minecraft:nether_wart_block)
B(-6,14,-2,minecraft:nether_wart_block)
B(-6,15,-2,minecraft:nether_wart_block)
B(-6,16,-2,minecraft:nether_wart_block)
B(-6,17,-2,minecraft:nether_wart_block)
B(-6,18,-2,minecraft:nether_wart_block)
B(-6,19,-2,minecraft:nether_wart_block)
B(-6,20,-2,minecraft:nether_wart_block)
B(-6,21,-2,minecraft:nether_wart_block)
B(-6,22,-2,minecraft:nether_wart_block)
B(-6,23,-2,minecraft:nether_wart_block)
B(-6,36,-2,minecraft:nether_wart_block)
B(-6,37,-2,minecraft:nether_wart_block)
B(-6,38,-2,minecraft:nether_wart_block)
B(-6,39,-2,minecraft:nether_wart_block)
B(-6,40,-2,minecraft:nether_wart_block)
B(-6,41,-2,minecraft:nether_wart_block)
B(-6,42,-2,minecraft:nether_wart_block)
B(-6,43,-2,minecraft:nether_wart_block)
B(-6,44,-2,minecraft:nether_wart_block)
B(-6,45,-2,minecraft:nether_wart_block)
B(-6,46,-2,minecraft:nether_wart_block)
B(-6,47,-2,minecraft:nether_wart_block)
B(-6,67,-2,minecraft:nether_wart_block)
B(-6,68,-2,minecraft:nether_wart_block)
B(-6,69,-2,minecraft:nether_wart_block)
B(-6,70,-2,minecraft:nether_wart_block)
B(-6,71,-2,minecraft:nether_wart_block)
B(-6,72,-2,minecraft:nether_wart_block)
B(-6,73,-2,minecraft:nether_wart_block)
B(-6,10,-1,minecraft:nether_wart_block)
B(-6,11,-1,minecraft:nether_wart_block)
B(-6,12,-1,minecraft:nether_wart_block)
B(-6,14,-1,minecraft:nether_wart_block)
B(-6,15,-1,minecraft:nether_wart_block)
B(-6,16,-1,minecraft:nether_wart_block)
B(-6,17,-1,minecraft:nether_wart_block)
B(-6,18,-1,minecraft:nether_wart_block)
B(-6,35,-1,minecraft:nether_wart_block)
B(-6,36,-1,minecraft:nether_wart_block)
B(-6,37,-1,minecraft:nether_wart_block)
B(-6,38,-1,minecraft:nether_wart_block)
B(-6,39,-1,minecraft:nether_wart_block)
B(-6,40,-1,minecraft:nether_wart_block)
B(-6,41,-1,minecraft:nether_wart_block)
B(-6,42,-1,minecraft:nether_wart_block)
B(-6,43,-1,minecraft:nether_wart_block)
B(-6,44,-1,minecraft:nether_wart_block)
B(-6,45,-1,minecraft:nether_wart_block)
B(-6,46,-1,minecraft:nether_wart_block)
B(-6,68,-1,minecraft:nether_wart_block)
B(-6,69,-1,minecraft:nether_wart_block)
B(-6,70,-1,minecraft:nether_wart_block)
B(-6,71,-1,minecraft:nether_wart_block)
B(-6,72,-1,minecraft:nether_wart_block)
B(-6,35,0,minecraft:nether_wart_block)
B(-6,36,0,minecraft:nether_wart_block)
B(-6,37,0,minecraft:nether_wart_block)
B(-6,38,0,minecraft:nether_wart_block)
B(-6,39,0,minecraft:nether_wart_block)
B(-6,40,0,minecraft:nether_wart_block)
B(-6,41,0,minecraft:nether_wart_block)
B(-6,42,0,minecraft:nether_wart_block)
B(-6,43,0,minecraft:nether_wart_block)
B(-6,44,0,minecraft:nether_wart_block)
B(-6,45,0,minecraft:nether_wart_block)
B(-6,46,0,minecraft:nether_wart_block)
B(-6,35,1,minecraft:nether_wart_block)
B(-6,36,1,minecraft:nether_wart_block)
B(-6,37,1,minecraft:nether_wart_block)
B(-6,38,1,minecraft:nether_wart_block)
B(-6,39,1,minecraft:nether_wart_block)
B(-6,40,1,minecraft:nether_wart_block)
B(-6,41,1,minecraft:nether_wart_block)
B(-6,42,1,minecraft:nether_wart_block)
B(-6,43,1,minecraft:nether_wart_block)
B(-6,44,1,minecraft:nether_wart_block)
B(-6,45,1,minecraft:nether_wart_block)
B(-6,35,2,minecraft:nether_wart_block)
B(-6,36,2,minecraft:nether_wart_block)
B(-6,37,2,minecraft:nether_wart_block)
B(-6,38,2,minecraft:nether_wart_block)
B(-6,39,2,minecraft:nether_wart_block)
B(-6,40,2,minecraft:nether_wart_block)
B(-6,41,2,minecraft:nether_wart_block)
B(-6,42,2,minecraft:nether_wart_block)
B(-6,43,2,minecraft:nether_wart_block)
B(-6,35,3,minecraft:nether_wart_block)
B(-6,36,3,minecraft:nether_wart_block)
B(-6,37,3,minecraft:nether_wart_block)
B(-6,38,3,minecraft:nether_wart_block)
B(-6,39,3,minecraft:nether_wart_block)
B(-6,40,3,minecraft:nether_wart_block)
B(-6,41,3,minecraft:nether_wart_block)
B(-6,42,3,minecraft:nether_wart_block)
B(-6,43,3,minecraft:nether_wart_block)
B(-6,36,4,minecraft:nether_wart_block)
B(-6,37,4,minecraft:nether_wart_block)
B(-6,38,4,minecraft:nether_wart_block)
B(-6,39,4,minecraft:nether_wart_block)
B(-6,40,4,minecraft:nether_wart_block)
B(-6,41,4,minecraft:nether_wart_block)
B(-6,42,4,minecraft:nether_wart_block)
B(-6,37,5,minecraft:nether_wart_block)
B(-6,38,5,minecraft:nether_wart_block)
B(-6,39,5,minecraft:nether_wart_block)
B(-6,40,5,minecraft:nether_wart_block)
B(-6,41,5,minecraft:nether_wart_block)
B(-5,0,-7,minecraft:nether_wart_block)
B(-5,1,-7,minecraft:nether_wart_block)
B(-5,2,-7,minecraft:nether_wart_block)
B(-5,3,-7,minecraft:nether_wart_block)
B(-5,4,-7,minecraft:nether_wart_block)
B(-5,5,-7,minecraft:nether_wart_block)
B(-5,6,-7,minecraft:nether_wart_block)
B(-5,7,-7,minecraft:nether_wart_block)
B(-5,8,-7,minecraft:nether_wart_block)
B(-5,9,-7,minecraft:nether_wart_block)
B(-5,10,-7,minecraft:nether_wart_block)
B(-5,11,-7,minecraft:nether_wart_block)
B(-5,12,-7,minecraft:nether_wart_block)
B(-5,13,-7,minecraft:nether_wart_block)
B(-5,14,-7,minecraft:nether_wart_block)
B(-5,15,-7,minecraft:nether_wart_block)
B(-5,16,-7,minecraft:nether_wart_block)
B(-5,17,-7,minecraft:nether_wart_block)
B(-5,18,-7,minecraft:nether_wart_block)
B(-5,19,-7,minecraft:nether_wart_block)
B(-5,20,-7,minecraft:nether_wart_block)
B(-5,21,-7,minecraft:nether_wart_block)
B(-5,22,-7,minecraft:nether_wart_block)
B(-5,39,-7,minecraft:nether_wart_block)
B(-5,40,-7,minecraft:nether_wart_block)
B(-5,41,-7,minecraft:nether_wart_block)
B(-5,42,-7,minecraft:nether_wart_block)
B(-5,43,-7,minecraft:nether_wart_block)
B(-5,44,-7,minecraft:nether_wart_block)
B(-5,45,-7,minecraft:nether_wart_block)
B(-5,46,-7,minecraft:nether_wart_block)
B(-5,47,-7,minecraft:nether_wart_block)
B(-5,48,-7,minecraft:nether_wart_block)
B(-5,49,-7,minecraft:nether_wart_block)
B(-5,50,-7,minecraft:nether_wart_block)
B(-5,65,-7,minecraft:nether_wart_block)
B(-5,66,-7,minecraft:nether_wart_block)
B(-5,67,-7,minecraft:nether_wart_block)
B(-5,68,-7,minecraft:nether_wart_block)
B(-5,69,-7,minecraft:nether_wart_block)
B(-5,70,-7,minecraft:nether_wart_block)
B(-5,71,-7,minecraft:nether_wart_block)
B(-5,72,-7,minecraft:nether_wart_block)
B(-5,73,-7,minecraft:nether_wart_block)
B(-5,74,-7,minecraft:nether_wart_block)
B(-5,75,-7,minecraft:nether_wart_block)
B(-5,0,-6,minecraft:nether_wart_block)
B(-5,1,-6,minecraft:nether_wart_block)
B(-5,2,-6,minecraft:nether_wart_block)
B(-5,3,-6,minecraft:nether_wart_block)
B(-5,4,-6,minecraft:nether_wart_block)
B(-5,5,-6,minecraft:nether_wart_block)
B(-5,6,-6,minecraft:nether_wart_block)
B(-5,7,-6,minecraft:nether_wart_block)
B(-5,8,-6,minecraft:nether_wart_block)
B(-5,9,-6,minecraft:nether_wart_block)
B(-5,10,-6,minecraft:nether_wart_block)
B(-5,11,-6,minecraft:nether_wart_block)
B(-5,12,-6,minecraft:nether_wart_block)
B(-5,13,-6,minecraft:nether_wart_block)
B(-5,14,-6,minecraft:nether_wart_block)
B(-5,15,-6,minecraft:nether_wart_block)
B(-5,16,-6,minecraft:nether_wart_block)
B(-5,17,-6,minecraft:nether_wart_block)
B(-5,18,-6,minecraft:nether_wart_block)
B(-5,19,-6,minecraft:nether_wart_block)
B(-5,20,-6,minecraft:nether_wart_block)
B(-5,21,-6,minecraft:nether_wart_block)
B(-5,22,-6,minecraft:nether_wart_block)
B(-5,23,-6,minecraft:nether_wart_block)
B(-5,38,-6,minecraft:nether_wart_block)
B(-5,39,-6,minecraft:nether_wart_block)
B(-5,40,-6,minecraft:nether_wart_block)
B(-5,41,-6,minecraft:nether_wart_block)
B(-5,42,-6,minecraft:nether_wart_block)
B(-5,43,-6,minecraft:nether_wart_block)
B(-5,44,-6,minecraft:nether_wart_block)
B(-5,45,-6,minecraft:nether_wart_block)
B(-5,46,-6,minecraft:nether_wart_block)
B(-5,47,-6,minecraft:nether_wart_block)
B(-5,48,-6,minecraft:nether_wart_block)
B(-5,49,-6,minecraft:nether_wart_block)
B(-5,50,-6,minecraft:nether_wart_block)
B(-5,65,-6,minecraft:nether_wart_block)
B(-5,66,-6,minecraft:nether_wart_block)
B(-5,67,-6,minecraft:nether_wart_block)
B(-5,68,-6,minecraft:nether_wart_block)
B(-5,69,-6,minecraft:nether_wart_block)
B(-5,70,-6,minecraft:nether_wart_block)
B(-5,71,-6,minecraft:nether_wart_block)
B(-5,72,-6,minecraft:nether_wart_block)
B(-5,73,-6,minecraft:nether_wart_block)
B(-5,74,-6,minecraft:nether_wart_block)
B(-5,75,-6,minecraft:nether_wart_block)
B(-5,0,-5,minecraft:nether_wart_block)
B(-5,1,-5,minecraft:nether_wart_block)
B(-5,2,-5,minecraft:nether_wart_block)
B(-5,3,-5,minecraft:nether_wart_block)
B(-5,4,-5,minecraft:nether_wart_block)
B(-5,5,-5,minecraft:nether_wart_block)
B(-5,6,-5,minecraft:nether_wart_block)
B(-5,7,-5,minecraft:nether_wart_block)
B(-5,8,-5,minecraft:nether_wart_block)
B(-5,9,-5,minecraft:nether_wart_block)
B(-5,10,-5,minecraft:nether_wart_block)
B(-5,11,-5,minecraft:nether_wart_block)
B(-5,12,-5,minecraft:nether_wart_block)
B(-5,13,-5,minecraft:nether_wart_block)
B(-5,14,-5,minecraft:nether_wart_block)
B(-5,15,-5,minecraft:nether_wart_block)
B(-5,16,-5,minecraft:nether_wart_block)
B(-5,17,-5,minecraft:nether_wart_block)
B(-5,18,-5,minecraft:nether_wart_block)
B(-5,19,-5,minecraft:nether_wart_block)
B(-5,20,-5,minecraft:nether_wart_block)
B(-5,21,-5,minecraft:nether_wart_block)
B(-5,22,-5,minecraft:nether_wart_block)
B(-5,23,-5,minecraft:nether_wart_block)
B(-5,37,-5,minecraft:nether_wart_block)
B(-5,38,-5,minecraft:nether_wart_block)
B(-5,39,-5,minecraft:nether_wart_block)
B(-5,40,-5,minecraft:nether_wart_block)
B(-5,41,-5,minecraft:nether_wart_block)
B(-5,42,-5,minecraft:nether_wart_block)
B(-5,43,-5,minecraft:nether_wart_block)
B(-5,44,-5,minecraft:nether_wart_block)
B(-5,45,-5,minecraft:nether_wart_block)
B(-5,46,-5,minecraft:nether_wart_block)
B(-5,47,-5,minecraft:nether_wart_block)
B(-5,48,-5,minecraft:nether_wart_block)
B(-5,49,-5,minecraft:nether_wart_block)
B(-5,50,-5,minecraft:nether_wart_block)
B(-5,65,-5,minecraft:nether_wart_block)
B(-5,66,-5,minecraft:nether_wart_block)
B(-5,67,-5,minecraft:nether_wart_block)
B(-5,68,-5,minecraft:nether_wart_block)
B(-5,69,-5,minecraft:nether_wart_block)
B(-5,70,-5,minecraft:nether_wart_block)
B(-5,71,-5,minecraft:nether_wart_block)
B(-5,72,-5,minecraft:nether_wart_block)
B(-5,73,-5,minecraft:nether_wart_block)
B(-5,74,-5,minecraft:nether_wart_block)
B(-5,75,-5,minecraft:nether_wart_block)
B(-5,0,-4,minecraft:nether_wart_block)
B(-5,1,-4,minecraft:nether_wart_block)
B(-5,2,-4,minecraft:nether_wart_block)
B(-5,3,-4,minecraft:nether_wart_block)
B(-5,4,-4,minecraft:nether_wart_block)
B(-5,5,-4,minecraft:nether_wart_block)
B(-5,6,-4,minecraft:nether_wart_block)
B(-5,7,-4,minecraft:nether_wart_block)
B(-5,8,-4,minecraft:nether_wart_block)
B(-5,9,-4,minecraft:nether_wart_block)
B(-5,10,-4,minecraft:nether_wart_block)
B(-5,11,-4,minecraft:nether_wart_block)
B(-5,12,-4,minecraft:nether_wart_block)
B(-5,13,-4,minecraft:nether_wart_block)
B(-5,14,-4,minecraft:nether_wart_block)
B(-5,15,-4,minecraft:nether_wart_block)
B(-5,16,-4,minecraft:nether_wart_block)
B(-5,17,-4,minecraft:nether_wart_block)
B(-5,18,-4,minecraft:nether_wart_block)
B(-5,19,-4,minecraft:nether_wart_block)
B(-5,20,-4,minecraft:nether_wart_block)
B(-5,21,-4,minecraft:nether_wart_block)
B(-5,22,-4,minecraft:nether_wart_block)
B(-5,23,-4,minecraft:nether_wart_block)
B(-5,37,-4,minecraft:nether_wart_block)
B(-5,38,-4,minecraft:nether_wart_block)
B(-5,39,-4,minecraft:nether_wart_block)
B(-5,40,-4,minecraft:nether_wart_block)
B(-5,41,-4,minecraft:nether_wart_block)
B(-5,42,-4,minecraft:nether_wart_block)
B(-5,43,-4,minecraft:nether_wart_block)
B(-5,44,-4,minecraft:nether_wart_block)
B(-5,45,-4,minecraft:nether_wart_block)
B(-5,46,-4,minecraft:nether_wart_block)
B(-5,47,-4,minecraft:nether_wart_block)
B(-5,48,-4,minecraft:nether_wart_block)
B(-5,49,-4,minecraft:nether_wart_block)
B(-5,50,-4,minecraft:nether_wart_block)
B(-5,65,-4,minecraft:nether_wart_block)
B(-5,66,-4,minecraft:nether_wart_block)
B(-5,67,-4,minecraft:nether_wart_block)
B(-5,68,-4,minecraft:nether_wart_block)
B(-5,69,-4,minecraft:nether_wart_block)
B(-5,70,-4,minecraft:nether_wart_block)
B(-5,71,-4,minecraft:nether_wart_block)
B(-5,72,-4,minecraft:nether_wart_block)
B(-5,73,-4,minecraft:nether_wart_block)
B(-5,74,-4,minecraft:nether_wart_block)
B(-5,75,-4,minecraft:nether_wart_block)
B(-5,0,-3,minecraft:nether_wart_block)
B(-5,1,-3,minecraft:nether_wart_block)
B(-5,2,-3,minecraft:nether_wart_block)
B(-5,3,-3,minecraft:nether_wart_block)
B(-5,4,-3,minecraft:nether_wart_block)
B(-5,5,-3,minecraft:nether_wart_block)
B(-5,6,-3,minecraft:nether_wart_block)
B(-5,7,-3,minecraft:nether_wart_block)
B(-5,8,-3,minecraft:nether_wart_block)
B(-5,9,-3,minecraft:nether_wart_block)
B(-5,10,-3,minecraft:nether_wart_block)
B(-5,11,-3,minecraft:nether_wart_block)
B(-5,12,-3,minecraft:nether_wart_block)
B(-5,13,-3,minecraft:nether_wart_block)
B(-5,14,-3,minecraft:nether_wart_block)
B(-5,15,-3,minecraft:nether_wart_block)
B(-5,16,-3,minecraft:nether_wart_block)
B(-5,17,-3,minecraft:nether_wart_block)
B(-5,18,-3,minecraft:nether_wart_block)
B(-5,19,-3,minecraft:nether_wart_block)
B(-5,20,-3,minecraft:nether_wart_block)
B(-5,21,-3,minecraft:nether_wart_block)
B(-5,22,-3,minecraft:nether_wart_block)
B(-5,36,-3,minecraft:nether_wart_block)
B(-5,37,-3,minecraft:nether_wart_block)
B(-5,38,-3,minecraft:nether_wart_block)
B(-5,39,-3,minecraft:nether_wart_block)
B(-5,40,-3,minecraft:nether_wart_block)
B(-5,41,-3,minecraft:nether_wart_block)
B(-5,42,-3,minecraft:nether_wart_block)
B(-5,43,-3,minecraft:nether_wart_block)
B(-5,44,-3,minecraft:nether_wart_block)
B(-5,45,-3,minecraft:nether_wart_block)
B(-5,46,-3,minecraft:nether_wart_block)
B(-5,47,-3,minecraft:nether_wart_block)
B(-5,48,-3,minecraft:nether_wart_block)
B(-5,49,-3,minecraft:nether_wart_block)
B(-5,66,-3,minecraft:nether_wart_block)
B(-5,67,-3,minecraft:nether_wart_block)
B(-5,68,-3,minecraft:nether_wart_block)
B(-5,69,-3,minecraft:nether_wart_block)
B(-5,70,-3,minecraft:nether_wart_block)
B(-5,71,-3,minecraft:nether_wart_block)
B(-5,72,-3,minecraft:nether_wart_block)
B(-5,73,-3,minecraft:nether_wart_block)
B(-5,74,-3,minecraft:nether_wart_block)
B(-5,9,-2,minecraft:nether_wart_block)
B(-5,10,-2,minecraft:nether_wart_block)
B(-5,11,-2,minecraft:nether_wart_block)
B(-5,12,-2,minecraft:nether_wart_block)
B(-5,13,-2,minecraft:nether_wart_block)
B(-5,14,-2,minecraft:nether_wart_block)
B(-5,15,-2,minecraft:nether_wart_block)
B(-5,16,-2,minecraft:nether_wart_block)
B(-5,17,-2,minecraft:nether_wart_block)
B(-5,18,-2,minecraft:nether_wart_block)
B(-5,35,-2,minecraft:nether_wart_block)
B(-5,36,-2,minecraft:nether_wart_block)
B(-5,37,-2,minecraft:nether_wart_block)
B(-5,38,-2,minecraft:nether_wart_block)
B(-5,39,-2,minecraft:nether_wart_block)
B(-5,40,-2,minecraft:nether_wart_block)
B(-5,41,-2,minecraft:nether_wart_block)
B(-5,42,-2,minecraft:nether_wart_block)
B(-5,43,-2,minecraft:nether_wart_block)
B(-5,44,-2,minecraft:nether_wart_block)
B(-5,45,-2,minecraft:nether_wart_block)
B(-5,46,-2,minecraft:nether_wart_block)
B(-5,47,-2,minecraft:nether_wart_block)
B(-5,48,-2,minecraft:nether_wart_block)
B(-5,67,-2,minecraft:nether_wart_block)
B(-5,68,-2,minecraft:nether_wart_block)
B(-5,69,-2,minecraft:nether_wart_block)
B(-5,70,-2,minecraft:nether_wart_block)
B(-5,71,-2,minecraft:nether_wart_block)
B(-5,72,-2,minecraft:nether_wart_block)
B(-5,73,-2,minecraft:nether_wart_block)
B(-5,35,-1,minecraft:nether_wart_block)
B(-5,36,-1,minecraft:nether_wart_block)
B(-5,37,-1,minecraft:nether_wart_block)
B(-5,38,-1,minecraft:nether_wart_block)
B(-5,39,-1,minecraft:nether_wart_block)
B(-5,40,-1,minecraft:nether_wart_block)
B(-5,41,-1,minecraft:nether_wart_block)
B(-5,42,-1,minecraft:nether_wart_block)
B(-5,43,-1,minecraft:nether_wart_block)
B(-5,44,-1,minecraft:nether_wart_block)
B(-5,45,-1,minecraft:nether_wart_block)
B(-5,46,-1,minecraft:nether_wart_block)
B(-5,47,-1,minecraft:nether_wart_block)
B(-5,68,-1,minecraft:nether_wart_block)
B(-5,69,-1,minecraft:nether_wart_block)
B(-5,70,-1,minecraft:nether_wart_block)
B(-5,71,-1,minecraft:nether_wart_block)
B(-5,72,-1,minecraft:nether_wart_block)
B(-5,34,0,minecraft:nether_wart_block)
B(-5,35,0,minecraft:nether_wart_block)
B(-5,36,0,minecraft:nether_wart_block)
B(-5,37,0,minecraft:nether_wart_block)
B(-5,38,0,minecraft:nether_wart_block)
B(-5,39,0,minecraft:nether_wart_block)
B(-5,40,0,minecraft:nether_wart_block)
B(-5,41,0,minecraft:nether_wart_block)
B(-5,42,0,minecraft:nether_wart_block)
B(-5,43,0,minecraft:nether_wart_block)
B(-5,44,0,minecraft:nether_wart_block)
B(-5,45,0,minecraft:nether_wart_block)
B(-5,46,0,minecraft:nether_wart_block)
B(-5,34,1,minecraft:nether_wart_block)
B(-5,35,1,minecraft:nether_wart_block)
B(-5,36,1,minecraft:nether_wart_block)
B(-5,37,1,minecraft:nether_wart_block)
B(-5,38,1,minecraft:nether_wart_block)
B(-5,39,1,minecraft:nether_wart_block)
B(-5,40,1,minecraft:nether_wart_block)
B(-5,41,1,minecraft:nether_wart_block)
B(-5,42,1,minecraft:nether_wart_block)
B(-5,43,1,minecraft:nether_wart_block)
B(-5,44,1,minecraft:nether_wart_block)
B(-5,45,1,minecraft:nether_wart_block)
B(-5,34,2,minecraft:nether_wart_block)
B(-5,35,2,minecraft:nether_wart_block)
B(-5,36,2,minecraft:nether_wart_block)
B(-5,37,2,minecraft:nether_wart_block)
B(-5,38,2,minecraft:nether_wart_block)
B(-5,39,2,minecraft:nether_wart_block)
B(-5,40,2,minecraft:nether_wart_block)
B(-5,41,2,minecraft:nether_wart_block)
B(-5,42,2,minecraft:nether_wart_block)
B(-5,43,2,minecraft:nether_wart_block)
B(-5,44,2,minecraft:nether_wart_block)
B(-5,35,3,minecraft:nether_wart_block)
B(-5,36,3,minecraft:nether_wart_block)
B(-5,37,3,minecraft:nether_wart_block)
B(-5,38,3,minecraft:nether_wart_block)
B(-5,39,3,minecraft:nether_wart_block)
B(-5,40,3,minecraft:nether_wart_block)
B(-5,41,3,minecraft:nether_wart_block)
B(-5,42,3,minecraft:nether_wart_block)
B(-5,43,3,minecraft:nether_wart_block)
B(-5,35,4,minecraft:nether_wart_block)
B(-5,36,4,minecraft:nether_wart_block)
B(-5,37,4,minecraft:nether_wart_block)
B(-5,38,4,minecraft:nether_wart_block)
B(-5,39,4,minecraft:nether_wart_block)
B(-5,40,4,minecraft:nether_wart_block)
B(-5,41,4,minecraft:nether_wart_block)
B(-5,42,4,minecraft:nether_wart_block)
B(-5,43,4,minecraft:nether_wart_block)
B(-5,36,5,minecraft:nether_wart_block)
B(-5,37,5,minecraft:nether_wart_block)
B(-5,38,5,minecraft:nether_wart_block)
B(-5,39,5,minecraft:nether_wart_block)
B(-5,40,5,minecraft:nether_wart_block)
B(-5,41,5,minecraft:nether_wart_block)
B(-5,42,5,minecraft:nether_wart_block)
B(-5,38,6,minecraft:nether_wart_block)
B(-5,39,6,minecraft:nether_wart_block)
B(-5,40,6,minecraft:nether_wart_block)
B(-4,0,-7,minecraft:nether_wart_block)
B(-4,1,-7,minecraft:nether_wart_block)
B(-4,2,-7,minecraft:nether_wart_block)
B(-4,3,-7,minecraft:nether_wart_block)
B(-4,4,-7,minecraft:nether_wart_block)
B(-4,5,-7,minecraft:nether_wart_block)
B(-4,6,-7,minecraft:nether_wart_block)
B(-4,7,-7,minecraft:nether_wart_block)
B(-4,8,-7,minecraft:nether_wart_block)
B(-4,9,-7,minecraft:nether_wart_block)
B(-4,10,-7,minecraft:nether_wart_block)
B(-4,11,-7,minecraft:nether_wart_block)
B(-4,12,-7,minecraft:nether_wart_block)
B(-4,13,-7,minecraft:nether_wart_block)
B(-4,14,-7,minecraft:nether_wart_block)
B(-4,15,-7,minecraft:nether_wart_block)
B(-4,16,-7,minecraft:nether_wart_block)
B(-4,17,-7,minecraft:nether_wart_block)
B(-4,39,-7,minecraft:nether_wart_block)
B(-4,40,-7,minecraft:nether_wart_block)
B(-4,41,-7,minecraft:nether_wart_block)
B(-4,42,-7,minecraft:nether_wart_block)
B(-4,43,-7,minecraft:nether_wart_block)
B(-4,44,-7,minecraft:nether_wart_block)
B(-4,45,-7,minecraft:nether_wart_block)
B(-4,46,-7,minecraft:nether_wart_block)
B(-4,47,-7,minecraft:nether_wart_block)
B(-4,48,-7,minecraft:nether_wart_block)
B(-4,49,-7,minecraft:nether_wart_block)
B(-4,50,-7,minecraft:nether_wart_block)
B(-4,51,-7,minecraft:nether_wart_block)
B(-4,65,-7,minecraft:nether_wart_block)
B(-4,66,-7,minecraft:nether_wart_block)
B(-4,67,-7,minecraft:nether_wart_block)
B(-4,68,-7,minecraft:nether_wart_block)
B(-4,69,-7,minecraft:nether_wart_block)
B(-4,70,-7,minecraft:nether_wart_block)
B(-4,71,-7,minecraft:nether_wart_block)
B(-4,72,-7,minecraft:nether_wart_block)
B(-4,73,-7,minecraft:nether_wart_block)
B(-4,74,-7,minecraft:nether_wart_block)
B(-4,75,-7,minecraft:nether_wart_block)
B(-4,0,-6,minecraft:nether_wart_block)
B(-4,1,-6,minecraft:nether_wart_block)
B(-4,2,-6,minecraft:nether_wart_block)
B(-4,3,-6,minecraft:nether_wart_block)
B(-4,4,-6,minecraft:nether_wart_block)
B(-4,5,-6,minecraft:nether_wart_block)
B(-4,6,-6,minecraft:nether_wart_block)
B(-4,7,-6,minecraft:nether_wart_block)
B(-4,8,-6,minecraft:nether_wart_block)
B(-4,9,-6,minecraft:nether_wart_block)
B(-4,10,-6,minecraft:nether_wart_block)
B(-4,11,-6,minecraft:nether_wart_block)
B(-4,12,-6,minecraft:nether_wart_block)
B(-4,13,-6,minecraft:nether_wart_block)
B(-4,14,-6,minecraft:nether_wart_block)
B(-4,15,-6,minecraft:nether_wart_block)
B(-4,16,-6,minecraft:nether_wart_block)
B(-4,17,-6,minecraft:nether_wart_block)
B(-4,18,-6,minecraft:nether_wart_block)
B(-4,38,-6,minecraft:nether_wart_block)
B(-4,39,-6,minecraft:nether_wart_block)
B(-4,40,-6,minecraft:nether_wart_block)
B(-4,41,-6,minecraft:nether_wart_block)
B(-4,42,-6,minecraft:nether_wart_block)
B(-4,43,-6,minecraft:nether_wart_block)
B(-4,44,-6,minecraft:nether_wart_block)
B(-4,45,-6,minecraft:nether_wart_block)
B(-4,46,-6,minecraft:nether_wart_block)
B(-4,47,-6,minecraft:nether_wart_block)
B(-4,48,-6,minecraft:nether_wart_block)
B(-4,49,-6,minecraft:nether_wart_block)
B(-4,50,-6,minecraft:nether_wart_block)
B(-4,51,-6,minecraft:nether_wart_block)
B(-4,65,-6,minecraft:nether_wart_block)
B(-4,66,-6,minecraft:nether_wart_block)
B(-4,67,-6,minecraft:nether_wart_block)
B(-4,68,-6,minecraft:nether_wart_block)
B(-4,69,-6,minecraft:nether_wart_block)
B(-4,70,-6,minecraft:nether_wart_block)
B(-4,71,-6,minecraft:nether_wart_block)
B(-4,72,-6,minecraft:nether_wart_block)
B(-4,73,-6,minecraft:nether_wart_block)
B(-4,74,-6,minecraft:nether_wart_block)
B(-4,75,-6,minecraft:nether_wart_block)
B(-4,0,-5,minecraft:nether_wart_block)
B(-4,1,-5,minecraft:nether_wart_block)
B(-4,2,-5,minecraft:nether_wart_block)
B(-4,3,-5,minecraft:nether_wart_block)
B(-4,4,-5,minecraft:nether_wart_block)
B(-4,5,-5,minecraft:nether_wart_block)
B(-4,6,-5,minecraft:nether_wart_block)
B(-4,7,-5,minecraft:nether_wart_block)
B(-4,8,-5,minecraft:nether_wart_block)
B(-4,9,-5,minecraft:nether_wart_block)
B(-4,10,-5,minecraft:nether_wart_block)
B(-4,11,-5,minecraft:nether_wart_block)
B(-4,12,-5,minecraft:nether_wart_block)
B(-4,13,-5,minecraft:nether_wart_block)
B(-4,14,-5,minecraft:nether_wart_block)
B(-4,15,-5,minecraft:nether_wart_block)
B(-4,16,-5,minecraft:nether_wart_block)
B(-4,17,-5,minecraft:nether_wart_block)
B(-4,18,-5,minecraft:nether_wart_block)
B(-4,37,-5,minecraft:nether_wart_block)
B(-4,38,-5,minecraft:nether_wart_block)
B(-4,39,-5,minecraft:nether_wart_block)
B(-4,40,-5,minecraft:nether_wart_block)
B(-4,41,-5,minecraft:nether_wart_block)
B(-4,42,-5,minecraft:nether_wart_block)
B(-4,43,-5,minecraft:nether_wart_block)
B(-4,44,-5,minecraft:nether_wart_block)
B(-4,45,-5,minecraft:nether_wart_block)
B(-4,46,-5,minecraft:nether_wart_block)
B(-4,47,-5,minecraft:nether_wart_block)
B(-4,48,-5,minecraft:nether_wart_block)
B(-4,49,-5,minecraft:nether_wart_block)
B(-4,50,-5,minecraft:nether_wart_block)
B(-4,51,-5,minecraft:nether_wart_block)
B(-4,65,-5,minecraft:nether_wart_block)
B(-4,66,-5,minecraft:nether_wart_block)
B(-4,67,-5,minecraft:nether_wart_block)
B(-4,68,-5,minecraft:nether_wart_block)
B(-4,69,-5,minecraft:nether_wart_block)
B(-4,70,-5,minecraft:nether_wart_block)
B(-4,71,-5,minecraft:nether_wart_block)
B(-4,72,-5,minecraft:nether_wart_block)
B(-4,73,-5,minecraft:nether_wart_block)
B(-4,74,-5,minecraft:nether_wart_block)
B(-4,75,-5,minecraft:nether_wart_block)
B(-4,0,-4,minecraft:nether_wart_block)
B(-4,1,-4,minecraft:nether_wart_block)
B(-4,2,-4,minecraft:nether_wart_block)
B(-4,3,-4,minecraft:nether_wart_block)
B(-4,4,-4,minecraft:nether_wart_block)
B(-4,5,-4,minecraft:nether_wart_block)
B(-4,6,-4,minecraft:nether_wart_block)
B(-4,7,-4,minecraft:nether_wart_block)
B(-4,8,-4,minecraft:nether_wart_block)
B(-4,9,-4,minecraft:nether_wart_block)
B(-4,10,-4,minecraft:nether_wart_block)
B(-4,11,-4,minecraft:nether_wart_block)
B(-4,12,-4,minecraft:nether_wart_block)
B(-4,13,-4,minecraft:nether_wart_block)
B(-4,14,-4,minecraft:nether_wart_block)
B(-4,15,-4,minecraft:nether_wart_block)
B(-4,16,-4,minecraft:nether_wart_block)
B(-4,17,-4,minecraft:nether_wart_block)
B(-4,18,-4,minecraft:nether_wart_block)
B(-4,37,-4,minecraft:nether_wart_block)
B(-4,38,-4,minecraft:nether_wart_block)
B(-4,39,-4,minecraft:nether_wart_block)
B(-4,40,-4,minecraft:nether_wart_block)
B(-4,41,-4,minecraft:nether_wart_block)
B(-4,42,-4,minecraft:nether_wart_block)
B(-4,43,-4,minecraft:nether_wart_block)
B(-4,44,-4,minecraft:nether_wart_block)
B(-4,45,-4,minecraft:nether_wart_block)
B(-4,46,-4,minecraft:nether_wart_block)
B(-4,47,-4,minecraft:nether_wart_block)
B(-4,48,-4,minecraft:nether_wart_block)
B(-4,49,-4,minecraft:nether_wart_block)
B(-4,50,-4,minecraft:nether_wart_block)
B(-4,65,-4,minecraft:nether_wart_block)
B(-4,66,-4,minecraft:nether_wart_block)
B(-4,67,-4,minecraft:nether_wart_block)
B(-4,68,-4,minecraft:nether_wart_block)
B(-4,69,-4,minecraft:nether_wart_block)
B(-4,70,-4,minecraft:nether_wart_block)
B(-4,71,-4,minecraft:nether_wart_block)
B(-4,72,-4,minecraft:nether_wart_block)
B(-4,73,-4,minecraft:nether_wart_block)
B(-4,74,-4,minecraft:nether_wart_block)
B(-4,75,-4,minecraft:nether_wart_block)
B(-4,9,-3,minecraft:nether_wart_block)
B(-4,10,-3,minecraft:nether_wart_block)
B(-4,11,-3,minecraft:nether_wart_block)
B(-4,12,-3,minecraft:nether_wart_block)
B(-4,13,-3,minecraft:nether_wart_block)
B(-4,15,-3,minecraft:nether_wart_block)
B(-4,16,-3,minecraft:nether_wart_block)
B(-4,17,-3,minecraft:nether_wart_block)
B(-4,36,-3,minecraft:nether_wart_block)
B(-4,37,-3,minecraft:nether_wart_block)
B(-4,38,-3,minecraft:nether_wart_block)
B(-4,39,-3,minecraft:nether_wart_block)
B(-4,40,-3,minecraft:nether_wart_block)
B(-4,41,-3,minecraft:nether_wart_block)
B(-4,42,-3,minecraft:nether_wart_block)
B(-4,43,-3,minecraft:nether_wart_block)
B(-4,44,-3,minecraft:nether_wart_block)
B(-4,45,-3,minecraft:nether_wart_block)
B(-4,46,-3,minecraft:nether_wart_block)
B(-4,47,-3,minecraft:nether_wart_block)
B(-4,48,-3,minecraft:nether_wart_block)
B(-4,49,-3,minecraft:nether_wart_block)
B(-4,50,-3,minecraft:nether_wart_block)
B(-4,66,-3,minecraft:nether_wart_block)
B(-4,67,-3,minecraft:nether_wart_block)
B(-4,68,-3,minecraft:nether_wart_block)
B(-4,69,-3,minecraft:nether_wart_block)
B(-4,70,-3,minecraft:nether_wart_block)
B(-4,71,-3,minecraft:nether_wart_block)
B(-4,72,-3,minecraft:nether_wart_block)
B(-4,73,-3,minecraft:nether_wart_block)
B(-4,74,-3,minecraft:nether_wart_block)
B(-4,35,-2,minecraft:nether_wart_block)
B(-4,36,-2,minecraft:nether_wart_block)
B(-4,37,-2,minecraft:nether_wart_block)
B(-4,38,-2,minecraft:nether_wart_block)
B(-4,39,-2,minecraft:nether_wart_block)
B(-4,40,-2,minecraft:nether_wart_block)
B(-4,41,-2,minecraft:nether_wart_block)
B(-4,42,-2,minecraft:nether_wart_block)
B(-4,43,-2,minecraft:nether_wart_block)
B(-4,44,-2,minecraft:nether_wart_block)
B(-4,45,-2,minecraft:nether_wart_block)
B(-4,46,-2,minecraft:nether_wart_block)
B(-4,47,-2,minecraft:nether_wart_block)
B(-4,48,-2,minecraft:nether_wart_block)
B(-4,49,-2,minecraft:nether_wart_block)
B(-4,66,-2,minecraft:nether_wart_block)
B(-4,67,-2,minecraft:nether_wart_block)
B(-4,68,-2,minecraft:nether_wart_block)
B(-4,69,-2,minecraft:nether_wart_block)
B(-4,70,-2,minecraft:nether_wart_block)
B(-4,71,-2,minecraft:nether_wart_block)
B(-4,72,-2,minecraft:nether_wart_block)
B(-4,73,-2,minecraft:nether_wart_block)
B(-4,74,-2,minecraft:nether_wart_block)
B(-4,34,-1,minecraft:nether_wart_block)
B(-4,35,-1,minecraft:nether_wart_block)
B(-4,36,-1,minecraft:nether_wart_block)
B(-4,37,-1,minecraft:nether_wart_block)
B(-4,38,-1,minecraft:nether_wart_block)
B(-4,39,-1,minecraft:nether_wart_block)
B(-4,40,-1,minecraft:nether_wart_block)
B(-4,41,-1,minecraft:nether_wart_block)
B(-4,42,-1,minecraft:nether_wart_block)
B(-4,43,-1,minecraft:nether_wart_block)
B(-4,44,-1,minecraft:nether_wart_block)
B(-4,45,-1,minecraft:nether_wart_block)
B(-4,46,-1,minecraft:nether_wart_block)
B(-4,47,-1,minecraft:nether_wart_block)
B(-4,67,-1,minecraft:nether_wart_block)
B(-4,68,-1,minecraft:nether_wart_block)
B(-4,69,-1,minecraft:nether_wart_block)
B(-4,70,-1,minecraft:nether_wart_block)
B(-4,71,-1,minecraft:nether_wart_block)
B(-4,72,-1,minecraft:nether_wart_block)
B(-4,73,-1,minecraft:nether_wart_block)
B(-4,34,0,minecraft:nether_wart_block)
B(-4,35,0,minecraft:nether_wart_block)
B(-4,36,0,minecraft:nether_wart_block)
B(-4,37,0,minecraft:nether_wart_block)
B(-4,38,0,minecraft:nether_wart_block)
B(-4,39,0,minecraft:nether_wart_block)
B(-4,40,0,minecraft:nether_wart_block)
B(-4,41,0,minecraft:nether_wart_block)
B(-4,42,0,minecraft:nether_wart_block)
B(-4,43,0,minecraft:nether_wart_block)
B(-4,44,0,minecraft:nether_wart_block)
B(-4,45,0,minecraft:nether_wart_block)
B(-4,46,0,minecraft:nether_wart_block)
B(-4,68,0,minecraft:nether_wart_block)
B(-4,69,0,minecraft:nether_wart_block)
B(-4,70,0,minecraft:nether_wart_block)
B(-4,71,0,minecraft:nether_wart_block)
B(-4,72,0,minecraft:nether_wart_block)
B(-4,34,1,minecraft:nether_wart_block)
B(-4,35,1,minecraft:nether_wart_block)
B(-4,36,1,minecraft:nether_wart_block)
B(-4,37,1,minecraft:nether_wart_block)
B(-4,38,1,minecraft:nether_wart_block)
B(-4,39,1,minecraft:nether_wart_block)
B(-4,40,1,minecraft:nether_wart_block)
B(-4,41,1,minecraft:nether_wart_block)
B(-4,42,1,minecraft:nether_wart_block)
B(-4,43,1,minecraft:nether_wart_block)
B(-4,44,1,minecraft:nether_wart_block)
B(-4,45,1,minecraft:nether_wart_block)
B(-4,34,2,minecraft:nether_wart_block)
B(-4,35,2,minecraft:nether_wart_block)
B(-4,36,2,minecraft:nether_wart_block)
B(-4,37,2,minecraft:nether_wart_block)
B(-4,38,2,minecraft:nether_wart_block)
B(-4,39,2,minecraft:nether_wart_block)
B(-4,40,2,minecraft:nether_wart_block)
B(-4,41,2,minecraft:nether_wart_block)
B(-4,42,2,minecraft:nether_wart_block)
B(-4,43,2,minecraft:nether_wart_block)
B(-4,44,2,minecraft:nether_wart_block)
B(-4,34,3,minecraft:nether_wart_block)
B(-4,35,3,minecraft:nether_wart_block)
B(-4,36,3,minecraft:nether_wart_block)
B(-4,37,3,minecraft:nether_wart_block)
B(-4,38,3,minecraft:nether_wart_block)
B(-4,39,3,minecraft:nether_wart_block)
B(-4,40,3,minecraft:nether_wart_block)
B(-4,41,3,minecraft:nether_wart_block)
B(-4,42,3,minecraft:nether_wart_block)
B(-4,43,3,minecraft:nether_wart_block)
B(-4,44,3,minecraft:nether_wart_block)
B(-4,35,4,minecraft:nether_wart_block)
B(-4,36,4,minecraft:nether_wart_block)
B(-4,37,4,minecraft:nether_wart_block)
B(-4,38,4,minecraft:nether_wart_block)
B(-4,39,4,minecraft:nether_wart_block)
B(-4,40,4,minecraft:nether_wart_block)
B(-4,41,4,minecraft:nether_wart_block)
B(-4,42,4,minecraft:nether_wart_block)
B(-4,43,4,minecraft:nether_wart_block)
B(-4,36,5,minecraft:nether_wart_block)
B(-4,37,5,minecraft:nether_wart_block)
B(-4,38,5,minecraft:nether_wart_block)
B(-4,39,5,minecraft:nether_wart_block)
B(-4,40,5,minecraft:nether_wart_block)
B(-4,41,5,minecraft:nether_wart_block)
B(-4,42,5,minecraft:nether_wart_block)
B(-4,37,6,minecraft:nether_wart_block)
B(-4,38,6,minecraft:nether_wart_block)
B(-4,39,6,minecraft:nether_wart_block)
B(-4,40,6,minecraft:nether_wart_block)
B(-4,41,6,minecraft:nether_wart_block)
B(-3,0,-7,minecraft:nether_wart_block)
B(-3,1,-7,minecraft:nether_wart_block)
B(-3,2,-7,minecraft:nether_wart_block)
B(-3,3,-7,minecraft:nether_wart_block)
B(-3,4,-7,minecraft:nether_wart_block)
B(-3,5,-7,minecraft:nether_wart_block)
B(-3,6,-7,minecraft:nether_wart_block)
B(-3,7,-7,minecraft:nether_wart_block)
B(-3,8,-7,minecraft:nether_wart_block)
B(-3,9,-7,minecraft:nether_wart_block)
B(-3,10,-7,minecraft:nether_wart_block)
B(-3,11,-7,minecraft:nether_wart_block)
B(-3,12,-7,minecraft:nether_wart_block)
B(-3,13,-7,minecraft:nether_wart_block)
B(-3,39,-7,minecraft:nether_wart_block)
B(-3,40,-7,minecraft:nether_wart_block)
B(-3,41,-7,minecraft:nether_wart_block)
B(-3,42,-7,minecraft:nether_wart_block)
B(-3,43,-7,minecraft:nether_wart_block)
B(-3,44,-7,minecraft:nether_wart_block)
B(-3,45,-7,minecraft:nether_wart_block)
B(-3,46,-7,minecraft:nether_wart_block)
B(-3,47,-7,minecraft:nether_wart_block)
B(-3,48,-7,minecraft:nether_wart_block)
B(-3,49,-7,minecraft:nether_wart_block)
B(-3,50,-7,minecraft:nether_wart_block)
B(-3,51,-7,minecraft:nether_wart_block)
B(-3,52,-7,minecraft:nether_wart_block)
B(-3,53,-7,minecraft:nether_wart_block)
B(-3,54,-7,minecraft:nether_wart_block)
B(-3,65,-7,minecraft:nether_wart_block)
B(-3,66,-7,minecraft:nether_wart_block)
B(-3,67,-7,minecraft:nether_wart_block)
B(-3,68,-7,minecraft:nether_wart_block)
B(-3,69,-7,minecraft:nether_wart_block)
B(-3,70,-7,minecraft:nether_wart_block)
B(-3,71,-7,minecraft:nether_wart_block)
B(-3,72,-7,minecraft:nether_wart_block)
B(-3,73,-7,minecraft:nether_wart_block)
B(-3,74,-7,minecraft:nether_wart_block)
B(-3,75,-7,minecraft:nether_wart_block)
B(-3,0,-6,minecraft:nether_wart_block)
B(-3,1,-6,minecraft:nether_wart_block)
B(-3,2,-6,minecraft:nether_wart_block)
B(-3,3,-6,minecraft:nether_wart_block)
B(-3,4,-6,minecraft:nether_wart_block)
B(-3,5,-6,minecraft:nether_wart_block)
B(-3,6,-6,minecraft:nether_wart_block)
B(-3,7,-6,minecraft:nether_wart_block)
B(-3,8,-6,minecraft:nether_wart_block)
B(-3,9,-6,minecraft:nether_wart_block)
B(-3,10,-6,minecraft:nether_wart_block)
B(-3,11,-6,minecraft:nether_wart_block)
B(-3,12,-6,minecraft:nether_wart_block)
B(-3,13,-6,minecraft:nether_wart_block)
B(-3,38,-6,minecraft:nether_wart_block)
B(-3,39,-6,minecraft:nether_wart_block)
B(-3,40,-6,minecraft:nether_wart_block)
B(-3,41,-6,minecraft:nether_wart_block)
B(-3,42,-6,minecraft:nether_wart_block)
B(-3,43,-6,minecraft:nether_wart_block)
B(-3,44,-6,minecraft:nether_wart_block)
B(-3,45,-6,minecraft:nether_wart_block)
B(-3,46,-6,minecraft:nether_wart_block)
B(-3,47,-6,minecraft:nether_wart_block)
B(-3,48,-6,minecraft:nether_wart_block)
B(-3,49,-6,minecraft:nether_wart_block)
B(-3,50,-6,minecraft:nether_wart_block)
B(-3,51,-6,minecraft:nether_wart_block)
B(-3,52,-6,minecraft:nether_wart_block)
B(-3,53,-6,minecraft:nether_wart_block)
B(-3,54,-6,minecraft:nether_wart_block)
B(-3,65,-6,minecraft:nether_wart_block)
B(-3,66,-6,minecraft:nether_wart_block)
B(-3,67,-6,minecraft:nether_wart_block)
B(-3,68,-6,minecraft:nether_wart_block)
B(-3,69,-6,minecraft:nether_wart_block)
B(-3,70,-6,minecraft:nether_wart_block)
B(-3,71,-6,minecraft:nether_wart_block)
B(-3,72,-6,minecraft:nether_wart_block)
B(-3,73,-6,minecraft:nether_wart_block)
B(-3,74,-6,minecraft:nether_wart_block)
B(-3,75,-6,minecraft:nether_wart_block)
B(-3,0,-5,minecraft:nether_wart_block)
B(-3,1,-5,minecraft:nether_wart_block)
B(-3,2,-5,minecraft:nether_wart_block)
B(-3,5,-5,minecraft:nether_wart_block)
B(-3,6,-5,minecraft:nether_wart_block)
B(-3,7,-5,minecraft:nether_wart_block)
B(-3,9,-5,minecraft:nether_wart_block)
B(-3,10,-5,minecraft:nether_wart_block)
B(-3,11,-5,minecraft:nether_wart_block)
B(-3,12,-5,minecraft:nether_wart_block)
B(-3,13,-5,minecraft:nether_wart_block)
B(-3,37,-5,minecraft:nether_wart_block)
B(-3,38,-5,minecraft:nether_wart_block)
B(-3,39,-5,minecraft:nether_wart_block)
B(-3,40,-5,minecraft:nether_wart_block)
B(-3,41,-5,minecraft:nether_wart_block)
B(-3,42,-5,minecraft:nether_wart_block)
B(-3,43,-5,minecraft:nether_wart_block)
B(-3,44,-5,minecraft:nether_wart_block)
B(-3,45,-5,minecraft:nether_wart_block)
B(-3,46,-5,minecraft:nether_wart_block)
B(-3,47,-5,minecraft:nether_wart_block)
B(-3,48,-5,minecraft:nether_wart_block)
B(-3,49,-5,minecraft:nether_wart_block)
B(-3,50,-5,minecraft:nether_wart_block)
B(-3,51,-5,minecraft:nether_wart_block)
B(-3,52,-5,minecraft:nether_wart_block)
B(-3,53,-5,minecraft:nether_wart_block)
B(-3,54,-5,minecraft:nether_wart_block)
B(-3,65,-5,minecraft:nether_wart_block)
B(-3,66,-5,minecraft:nether_wart_block)
B(-3,67,-5,minecraft:nether_wart_block)
B(-3,68,-5,minecraft:nether_wart_block)
B(-3,69,-5,minecraft:nether_wart_block)
B(-3,70,-5,minecraft:nether_wart_block)
B(-3,71,-5,minecraft:nether_wart_block)
B(-3,72,-5,minecraft:nether_wart_block)
B(-3,73,-5,minecraft:nether_wart_block)
B(-3,74,-5,minecraft:nether_wart_block)
B(-3,75,-5,minecraft:nether_wart_block)
B(-3,10,-4,minecraft:nether_wart_block)
B(-3,11,-4,minecraft:nether_wart_block)
B(-3,12,-4,minecraft:nether_wart_block)
B(-3,37,-4,minecraft:nether_wart_block)
B(-3,38,-4,minecraft:nether_wart_block)
B(-3,39,-4,minecraft:nether_wart_block)
B(-3,40,-4,minecraft:nether_wart_block)
B(-3,41,-4,minecraft:nether_wart_block)
B(-3,42,-4,minecraft:nether_wart_block)
B(-3,43,-4,minecraft:nether_wart_block)
B(-3,44,-4,minecraft:nether_wart_block)
B(-3,45,-4,minecraft:nether_wart_block)
B(-3,46,-4,minecraft:nether_wart_block)
B(-3,47,-4,minecraft:nether_wart_block)
B(-3,48,-4,minecraft:nether_wart_block)
B(-3,49,-4,minecraft:nether_wart_block)
B(-3,50,-4,minecraft:nether_wart_block)
B(-3,51,-4,minecraft:nether_wart_block)
B(-3,52,-4,minecraft:nether_wart_block)
B(-3,53,-4,minecraft:nether_wart_block)
B(-3,65,-4,minecraft:nether_wart_block)
B(-3,66,-4,minecraft:nether_wart_block)
B(-3,67,-4,minecraft:nether_wart_block)
B(-3,68,-4,minecraft:nether_wart_block)
B(-3,69,-4,minecraft:nether_wart_block)
B(-3,70,-4,minecraft:nether_wart_block)
B(-3,71,-4,minecraft:nether_wart_block)
B(-3,72,-4,minecraft:nether_wart_block)
B(-3,73,-4,minecraft:nether_wart_block)
B(-3,74,-4,minecraft:nether_wart_block)
B(-3,75,-4,minecraft:nether_wart_block)
B(-3,36,-3,minecraft:nether_wart_block)
B(-3,37,-3,minecraft:nether_wart_block)
B(-3,38,-3,minecraft:nether_wart_block)
B(-3,39,-3,minecraft:nether_wart_block)
B(-3,40,-3,minecraft:nether_wart_block)
B(-3,41,-3,minecraft:nether_wart_block)
B(-3,42,-3,minecraft:nether_wart_block)
B(-3,43,-3,minecraft:nether_wart_block)
B(-3,44,-3,minecraft:nether_wart_block)
B(-3,45,-3,minecraft:nether_wart_block)
B(-3,46,-3,minecraft:nether_wart_block)
B(-3,47,-3,minecraft:nether_wart_block)
B(-3,48,-3,minecraft:nether_wart_block)
B(-3,49,-3,minecraft:nether_wart_block)
B(-3,50,-3,minecraft:nether_wart_block)
B(-3,65,-3,minecraft:nether_wart_block)
B(-3,66,-3,minecraft:nether_wart_block)
B(-3,67,-3,minecraft:nether_wart_block)
B(-3,68,-3,minecraft:nether_wart_block)
B(-3,69,-3,minecraft:nether_wart_block)
B(-3,70,-3,minecraft:nether_wart_block)
B(-3,71,-3,minecraft:nether_wart_block)
B(-3,72,-3,minecraft:nether_wart_block)
B(-3,73,-3,minecraft:nether_wart_block)
B(-3,74,-3,minecraft:nether_wart_block)
B(-3,75,-3,minecraft:nether_wart_block)
B(-3,35,-2,minecraft:nether_wart_block)
B(-3,36,-2,minecraft:nether_wart_block)
B(-3,37,-2,minecraft:nether_wart_block)
B(-3,38,-2,minecraft:nether_wart_block)
B(-3,39,-2,minecraft:nether_wart_block)
B(-3,40,-2,minecraft:nether_wart_block)
B(-3,41,-2,minecraft:nether_wart_block)
B(-3,42,-2,minecraft:nether_wart_block)
B(-3,43,-2,minecraft:nether_wart_block)
B(-3,44,-2,minecraft:nether_wart_block)
B(-3,45,-2,minecraft:nether_wart_block)
B(-3,46,-2,minecraft:nether_wart_block)
B(-3,47,-2,minecraft:nether_wart_block)
B(-3,48,-2,minecraft:nether_wart_block)
B(-3,49,-2,minecraft:nether_wart_block)
B(-3,65,-2,minecraft:nether_wart_block)
B(-3,66,-2,minecraft:nether_wart_block)
B(-3,67,-2,minecraft:nether_wart_block)
B(-3,68,-2,minecraft:nether_wart_block)
B(-3,69,-2,minecraft:nether_wart_block)
B(-3,70,-2,minecraft:nether_wart_block)
B(-3,71,-2,minecraft:nether_wart_block)
B(-3,72,-2,minecraft:nether_wart_block)
B(-3,73,-2,minecraft:nether_wart_block)
B(-3,74,-2,minecraft:nether_wart_block)
B(-3,34,-1,minecraft:nether_wart_block)
B(-3,35,-1,minecraft:nether_wart_block)
B(-3,36,-1,minecraft:nether_wart_block)
B(-3,37,-1,minecraft:nether_wart_block)
B(-3,38,-1,minecraft:nether_wart_block)
B(-3,39,-1,minecraft:nether_wart_block)
B(-3,40,-1,minecraft:nether_wart_block)
B(-3,41,-1,minecraft:nether_wart_block)
B(-3,42,-1,minecraft:nether_wart_block)
B(-3,43,-1,minecraft:nether_wart_block)
B(-3,44,-1,minecraft:nether_wart_block)
B(-3,45,-1,minecraft:nether_wart_block)
B(-3,46,-1,minecraft:nether_wart_block)
B(-3,47,-1,minecraft:nether_wart_block)
B(-3,48,-1,minecraft:nether_wart_block)
B(-3,65,-1,minecraft:nether_wart_block)
B(-3,66,-1,minecraft:nether_wart_block)
B(-3,67,-1,minecraft:nether_wart_block)
B(-3,68,-1,minecraft:nether_wart_block)
B(-3,69,-1,minecraft:nether_wart_block)
B(-3,70,-1,minecraft:nether_wart_block)
B(-3,71,-1,minecraft:nether_wart_block)
B(-3,72,-1,minecraft:nether_wart_block)
B(-3,73,-1,minecraft:nether_wart_block)
B(-3,74,-1,minecraft:nether_wart_block)
B(-3,34,0,minecraft:nether_wart_block)
B(-3,35,0,minecraft:nether_wart_block)
B(-3,36,0,minecraft:nether_wart_block)
B(-3,37,0,minecraft:nether_wart_block)
B(-3,38,0,minecraft:nether_wart_block)
B(-3,39,0,minecraft:nether_wart_block)
B(-3,40,0,minecraft:nether_wart_block)
B(-3,41,0,minecraft:nether_wart_block)
B(-3,42,0,minecraft:nether_wart_block)
B(-3,43,0,minecraft:nether_wart_block)
B(-3,44,0,minecraft:nether_wart_block)
B(-3,45,0,minecraft:nether_wart_block)
B(-3,46,0,minecraft:nether_wart_block)
B(-3,65,0,minecraft:nether_wart_block)
B(-3,66,0,minecraft:nether_wart_block)
B(-3,67,0,minecraft:nether_wart_block)
B(-3,68,0,minecraft:nether_wart_block)
B(-3,69,0,minecraft:nether_wart_block)
B(-3,70,0,minecraft:nether_wart_block)
B(-3,71,0,minecraft:nether_wart_block)
B(-3,72,0,minecraft:nether_wart_block)
B(-3,73,0,minecraft:nether_wart_block)
B(-3,34,1,minecraft:nether_wart_block)
B(-3,35,1,minecraft:nether_wart_block)
B(-3,36,1,minecraft:nether_wart_block)
B(-3,37,1,minecraft:nether_wart_block)
B(-3,38,1,minecraft:nether_wart_block)
B(-3,39,1,minecraft:nether_wart_block)
B(-3,40,1,minecraft:nether_wart_block)
B(-3,41,1,minecraft:nether_wart_block)
B(-3,42,1,minecraft:nether_wart_block)
B(-3,43,1,minecraft:nether_wart_block)
B(-3,44,1,minecraft:nether_wart_block)
B(-3,45,1,minecraft:nether_wart_block)
B(-3,66,1,minecraft:nether_wart_block)
B(-3,67,1,minecraft:nether_wart_block)
B(-3,68,1,minecraft:nether_wart_block)
B(-3,69,1,minecraft:nether_wart_block)
B(-3,70,1,minecraft:nether_wart_block)
B(-3,71,1,minecraft:nether_wart_block)
B(-3,34,2,minecraft:nether_wart_block)
B(-3,35,2,minecraft:nether_wart_block)
B(-3,36,2,minecraft:nether_wart_block)
B(-3,37,2,minecraft:nether_wart_block)
B(-3,38,2,minecraft:nether_wart_block)
B(-3,39,2,minecraft:nether_wart_block)
B(-3,40,2,minecraft:nether_wart_block)
B(-3,41,2,minecraft:nether_wart_block)
B(-3,42,2,minecraft:nether_wart_block)
B(-3,43,2,minecraft:nether_wart_block)
B(-3,44,2,minecraft:nether_wart_block)
B(-3,34,3,minecraft:nether_wart_block)
B(-3,35,3,minecraft:nether_wart_block)
B(-3,36,3,minecraft:nether_wart_block)
B(-3,37,3,minecraft:nether_wart_block)
B(-3,38,3,minecraft:nether_wart_block)
B(-3,39,3,minecraft:nether_wart_block)
B(-3,40,3,minecraft:nether_wart_block)
B(-3,41,3,minecraft:nether_wart_block)
B(-3,42,3,minecraft:nether_wart_block)
B(-3,43,3,minecraft:nether_wart_block)
B(-3,44,3,minecraft:nether_wart_block)
B(-3,35,4,minecraft:nether_wart_block)
B(-3,36,4,minecraft:nether_wart_block)
B(-3,37,4,minecraft:nether_wart_block)
B(-3,38,4,minecraft:nether_wart_block)
B(-3,39,4,minecraft:nether_wart_block)
B(-3,40,4,minecraft:nether_wart_block)
B(-3,41,4,minecraft:nether_wart_block)
B(-3,42,4,minecraft:nether_wart_block)
B(-3,43,4,minecraft:nether_wart_block)
B(-3,36,5,minecraft:nether_wart_block)
B(-3,37,5,minecraft:nether_wart_block)
B(-3,38,5,minecraft:nether_wart_block)
B(-3,39,5,minecraft:nether_wart_block)
B(-3,40,5,minecraft:nether_wart_block)
B(-3,41,5,minecraft:nether_wart_block)
B(-3,42,5,minecraft:nether_wart_block)
B(-3,37,6,minecraft:nether_wart_block)
B(-3,38,6,minecraft:nether_wart_block)
B(-3,39,6,minecraft:nether_wart_block)
B(-3,40,6,minecraft:nether_wart_block)
B(-3,41,6,minecraft:nether_wart_block)
B(-2,39,-7,minecraft:nether_wart_block)
B(-2,40,-7,minecraft:nether_wart_block)
B(-2,41,-7,minecraft:nether_wart_block)
B(-2,42,-7,minecraft:nether_wart_block)
B(-2,43,-7,minecraft:nether_wart_block)
B(-2,44,-7,minecraft:nether_wart_block)
B(-2,45,-7,minecraft:nether_wart_block)
B(-2,46,-7,minecraft:nether_wart_block)
B(-2,47,-7,minecraft:nether_wart_block)
B(-2,48,-7,minecraft:nether_wart_block)
B(-2,49,-7,minecraft:nether_wart_block)
B(-2,50,-7,minecraft:nether_wart_block)
B(-2,51,-7,minecraft:nether_wart_block)
B(-2,52,-7,minecraft:nether_wart_block)
B(-2,53,-7,minecraft:nether_wart_block)
B(-2,54,-7,minecraft:nether_wart_block)
B(-2,55,-7,minecraft:nether_wart_block)
B(-2,66,-7,minecraft:nether_wart_block)
B(-2,67,-7,minecraft:nether_wart_block)
B(-2,68,-7,minecraft:nether_wart_block)
B(-2,69,-7,minecraft:nether_wart_block)
B(-2,70,-7,minecraft:nether_wart_block)
B(-2,71,-7,minecraft:nether_wart_block)
B(-2,72,-7,minecraft:nether_wart_block)
B(-2,73,-7,minecraft:nether_wart_block)
B(-2,74,-7,minecraft:nether_wart_block)
B(-2,38,-6,minecraft:nether_wart_block)
B(-2,39,-6,minecraft:nether_wart_block)
B(-2,40,-6,minecraft:nether_wart_block)
B(-2,41,-6,minecraft:nether_wart_block)
B(-2,42,-6,minecraft:nether_wart_block)
B(-2,43,-6,minecraft:nether_wart_block)
B(-2,44,-6,minecraft:nether_wart_block)
B(-2,45,-6,minecraft:nether_wart_block)
B(-2,46,-6,minecraft:nether_wart_block)
B(-2,47,-6,minecraft:nether_wart_block)
B(-2,48,-6,minecraft:nether_wart_block)
B(-2,49,-6,minecraft:nether_wart_block)
B(-2,50,-6,minecraft:nether_wart_block)
B(-2,51,-6,minecraft:nether_wart_block)
B(-2,52,-6,minecraft:nether_wart_block)
B(-2,53,-6,minecraft:nether_wart_block)
B(-2,54,-6,minecraft:nether_wart_block)
B(-2,55,-6,minecraft:nether_wart_block)
B(-2,65,-6,minecraft:nether_wart_block)
B(-2,66,-6,minecraft:nether_wart_block)
B(-2,67,-6,minecraft:nether_wart_block)
B(-2,68,-6,minecraft:nether_wart_block)
B(-2,69,-6,minecraft:nether_wart_block)
B(-2,70,-6,minecraft:nether_wart_block)
B(-2,71,-6,minecraft:nether_wart_block)
B(-2,72,-6,minecraft:nether_wart_block)
B(-2,73,-6,minecraft:nether_wart_block)
B(-2,74,-6,minecraft:nether_wart_block)
B(-2,75,-6,minecraft:nether_wart_block)
B(-2,38,-5,minecraft:nether_wart_block)
B(-2,39,-5,minecraft:nether_wart_block)
B(-2,40,-5,minecraft:nether_wart_block)
B(-2,41,-5,minecraft:nether_wart_block)
B(-2,42,-5,minecraft:nether_wart_block)
B(-2,43,-5,minecraft:nether_wart_block)
B(-2,44,-5,minecraft:nether_wart_block)
B(-2,45,-5,minecraft:nether_wart_block)
B(-2,46,-5,minecraft:nether_wart_block)
B(-2,47,-5,minecraft:nether_wart_block)
B(-2,48,-5,minecraft:nether_wart_block)
B(-2,49,-5,minecraft:nether_wart_block)
B(-2,50,-5,minecraft:nether_wart_block)
B(-2,51,-5,minecraft:nether_wart_block)
B(-2,52,-5,minecraft:nether_wart_block)
B(-2,53,-5,minecraft:nether_wart_block)
B(-2,54,-5,minecraft:nether_wart_block)
B(-2,55,-5,minecraft:nether_wart_block)
B(-2,56,-5,minecraft:nether_wart_block)
B(-2,57,-5,minecraft:nether_wart_block)
B(-2,65,-5,minecraft:nether_wart_block)
B(-2,66,-5,minecraft:nether_wart_block)
B(-2,67,-5,minecraft:nether_wart_block)
B(-2,68,-5,minecraft:nether_wart_block)
B(-2,69,-5,minecraft:nether_wart_block)
B(-2,70,-5,minecraft:nether_wart_block)
B(-2,71,-5,minecraft:nether_wart_block)
B(-2,72,-5,minecraft:nether_wart_block)
B(-2,73,-5,minecraft:nether_wart_block)
B(-2,74,-5,minecraft:nether_wart_block)
B(-2,75,-5,minecraft:nether_wart_block)
B(-2,37,-4,minecraft:nether_wart_block)
B(-2,38,-4,minecraft:nether_wart_block)
B(-2,39,-4,minecraft:nether_wart_block)
B(-2,40,-4,minecraft:nether_wart_block)
B(-2,41,-4,minecraft:nether_wart_block)
B(-2,42,-4,minecraft:nether_wart_block)
B(-2,43,-4,minecraft:nether_wart_block)
B(-2,44,-4,minecraft:nether_wart_block)
B(-2,45,-4,minecraft:nether_wart_block)
B(-2,46,-4,minecraft:nether_wart_block)
B(-2,47,-4,minecraft:nether_wart_block)
B(-2,48,-4,minecraft:nether_wart_block)
B(-2,49,-4,minecraft:nether_wart_block)
B(-2,50,-4,minecraft:nether_wart_block)
B(-2,51,-4,minecraft:nether_wart_block)
B(-2,52,-4,minecraft:nether_wart_block)
B(-2,53,-4,minecraft:nether_wart_block)
B(-2,54,-4,minecraft:nether_wart_block)
B(-2,55,-4,minecraft:nether_wart_block)
B(-2,56,-4,minecraft:nether_wart_block)
B(-2,57,-4,minecraft:nether_wart_block)
B(-2,58,-4,minecraft:nether_wart_block)
B(-2,65,-4,minecraft:nether_wart_block)
B(-2,66,-4,minecraft:nether_wart_block)
B(-2,67,-4,minecraft:nether_wart_block)
B(-2,68,-4,minecraft:nether_wart_block)
B(-2,69,-4,minecraft:nether_wart_block)
B(-2,70,-4,minecraft:nether_wart_block)
B(-2,71,-4,minecraft:nether_wart_block)
B(-2,72,-4,minecraft:nether_wart_block)
B(-2,73,-4,minecraft:nether_wart_block)
B(-2,74,-4,minecraft:nether_wart_block)
B(-2,75,-4,minecraft:nether_wart_block)
B(-2,36,-3,minecraft:nether_wart_block)
B(-2,37,-3,minecraft:nether_wart_block)
B(-2,38,-3,minecraft:nether_wart_block)
B(-2,39,-3,minecraft:nether_wart_block)
B(-2,40,-3,minecraft:nether_wart_block)
B(-2,41,-3,minecraft:nether_wart_block)
B(-2,42,-3,minecraft:nether_wart_block)
B(-2,43,-3,minecraft:nether_wart_block)
B(-2,44,-3,minecraft:nether_wart_block)
B(-2,45,-3,minecraft:nether_wart_block)
B(-2,46,-3,minecraft:nether_wart_block)
B(-2,47,-3,minecraft:nether_wart_block)
B(-2,48,-3,minecraft:nether_wart_block)
B(-2,49,-3,minecraft:nether_wart_block)
B(-2,50,-3,minecraft:nether_wart_block)
B(-2,51,-3,minecraft:nether_wart_block)
B(-2,52,-3,minecraft:nether_wart_block)
B(-2,53,-3,minecraft:nether_wart_block)
B(-2,54,-3,minecraft:nether_wart_block)
B(-2,55,-3,minecraft:nether_wart_block)
B(-2,56,-3,minecraft:nether_wart_block)
B(-2,57,-3,minecraft:nether_wart_block)
B(-2,58,-3,minecraft:nether_wart_block)
B(-2,64,-3,minecraft:nether_wart_block)
B(-2,65,-3,minecraft:nether_wart_block)
B(-2,66,-3,minecraft:nether_wart_block)
B(-2,67,-3,minecraft:nether_wart_block)
B(-2,68,-3,minecraft:nether_wart_block)
B(-2,69,-3,minecraft:nether_wart_block)
B(-2,70,-3,minecraft:nether_wart_block)
B(-2,71,-3,minecraft:nether_wart_block)
B(-2,72,-3,minecraft:nether_wart_block)
B(-2,73,-3,minecraft:nether_wart_block)
B(-2,74,-3,minecraft:nether_wart_block)
B(-2,75,-3,minecraft:nether_wart_block)
B(-2,35,-2,minecraft:nether_wart_block)
B(-2,36,-2,minecraft:nether_wart_block)
B(-2,37,-2,minecraft:nether_wart_block)
B(-2,38,-2,minecraft:nether_wart_block)
B(-2,39,-2,minecraft:nether_wart_block)
B(-2,40,-2,minecraft:nether_wart_block)
B(-2,41,-2,minecraft:nether_wart_block)
B(-2,42,-2,minecraft:nether_wart_block)
B(-2,43,-2,minecraft:nether_wart_block)
B(-2,44,-2,minecraft:nether_wart_block)
B(-2,45,-2,minecraft:nether_wart_block)
B(-2,46,-2,minecraft:nether_wart_block)
B(-2,47,-2,minecraft:nether_wart_block)
B(-2,48,-2,minecraft:nether_wart_block)
B(-2,49,-2,minecraft:nether_wart_block)
B(-2,54,-2,minecraft:nether_wart_block)
B(-2,55,-2,minecraft:nether_wart_block)
B(-2,56,-2,minecraft:nether_wart_block)
B(-2,57,-2,minecraft:nether_wart_block)
B(-2,58,-2,minecraft:nether_wart_block)
B(-2,64,-2,minecraft:nether_wart_block)
B(-2,65,-2,minecraft:nether_wart_block)
B(-2,66,-2,minecraft:nether_wart_block)
B(-2,67,-2,minecraft:nether_wart_block)
B(-2,68,-2,minecraft:nether_wart_block)
B(-2,69,-2,minecraft:nether_wart_block)
B(-2,70,-2,minecraft:nether_wart_block)
B(-2,71,-2,minecraft:nether_wart_block)
B(-2,72,-2,minecraft:nether_wart_block)
B(-2,73,-2,minecraft:nether_wart_block)
B(-2,74,-2,minecraft:nether_wart_block)
B(-2,75,-2,minecraft:nether_wart_block)
B(-2,34,-1,minecraft:nether_wart_block)
B(-2,35,-1,minecraft:nether_wart_block)
B(-2,36,-1,minecraft:nether_wart_block)
B(-2,37,-1,minecraft:nether_wart_block)
B(-2,38,-1,minecraft:nether_wart_block)
B(-2,39,-1,minecraft:nether_wart_block)
B(-2,40,-1,minecraft:nether_wart_block)
B(-2,41,-1,minecraft:nether_wart_block)
B(-2,42,-1,minecraft:nether_wart_block)
B(-2,43,-1,minecraft:nether_wart_block)
B(-2,44,-1,minecraft:nether_wart_block)
B(-2,45,-1,minecraft:nether_wart_block)
B(-2,46,-1,minecraft:nether_wart_block)
B(-2,47,-1,minecraft:nether_wart_block)
B(-2,48,-1,minecraft:nether_wart_block)
B(-2,55,-1,minecraft:nether_wart_block)
B(-2,56,-1,minecraft:nether_wart_block)
B(-2,57,-1,minecraft:nether_wart_block)
B(-2,64,-1,minecraft:nether_wart_block)
B(-2,65,-1,minecraft:nether_wart_block)
B(-2,66,-1,minecraft:nether_wart_block)
B(-2,67,-1,minecraft:nether_wart_block)
B(-2,68,-1,minecraft:nether_wart_block)
B(-2,69,-1,minecraft:nether_wart_block)
B(-2,70,-1,minecraft:nether_wart_block)
B(-2,71,-1,minecraft:nether_wart_block)
B(-2,72,-1,minecraft:nether_wart_block)
B(-2,73,-1,minecraft:nether_wart_block)
B(-2,74,-1,minecraft:nether_wart_block)
B(-2,34,0,minecraft:nether_wart_block)
B(-2,35,0,minecraft:nether_wart_block)
B(-2,36,0,minecraft:nether_wart_block)
B(-2,37,0,minecraft:nether_wart_block)
B(-2,38,0,minecraft:nether_wart_block)
B(-2,39,0,minecraft:nether_wart_block)
B(-2,40,0,minecraft:nether_wart_block)
B(-2,41,0,minecraft:nether_wart_block)
B(-2,42,0,minecraft:nether_wart_block)
B(-2,43,0,minecraft:nether_wart_block)
B(-2,44,0,minecraft:nether_wart_block)
B(-2,45,0,minecraft:nether_wart_block)
B(-2,46,0,minecraft:nether_wart_block)
B(-2,64,0,minecraft:nether_wart_block)
B(-2,65,0,minecraft:nether_wart_block)
B(-2,66,0,minecraft:nether_wart_block)
B(-2,67,0,minecraft:nether_wart_block)
B(-2,68,0,minecraft:nether_wart_block)
B(-2,69,0,minecraft:nether_wart_block)
B(-2,70,0,minecraft:nether_wart_block)
B(-2,71,0,minecraft:nether_wart_block)
B(-2,72,0,minecraft:nether_wart_block)
B(-2,73,0,minecraft:nether_wart_block)
B(-2,34,1,minecraft:nether_wart_block)
B(-2,35,1,minecraft:nether_wart_block)
B(-2,36,1,minecraft:nether_wart_block)
B(-2,37,1,minecraft:nether_wart_block)
B(-2,38,1,minecraft:nether_wart_block)
B(-2,39,1,minecraft:nether_wart_block)
B(-2,40,1,minecraft:nether_wart_block)
B(-2,41,1,minecraft:nether_wart_block)
B(-2,42,1,minecraft:nether_wart_block)
B(-2,43,1,minecraft:nether_wart_block)
B(-2,44,1,minecraft:nether_wart_block)
B(-2,45,1,minecraft:nether_wart_block)
B(-2,64,1,minecraft:nether_wart_block)
B(-2,65,1,minecraft:nether_wart_block)
B(-2,66,1,minecraft:nether_wart_block)
B(-2,67,1,minecraft:nether_wart_block)
B(-2,68,1,minecraft:nether_wart_block)
B(-2,69,1,minecraft:nether_wart_block)
B(-2,70,1,minecraft:nether_wart_block)
B(-2,71,1,minecraft:nether_wart_block)
B(-2,72,1,minecraft:nether_wart_block)
B(-2,34,2,minecraft:nether_wart_block)
B(-2,35,2,minecraft:nether_wart_block)
B(-2,36,2,minecraft:nether_wart_block)
B(-2,37,2,minecraft:nether_wart_block)
B(-2,38,2,minecraft:nether_wart_block)
B(-2,39,2,minecraft:nether_wart_block)
B(-2,40,2,minecraft:nether_wart_block)
B(-2,41,2,minecraft:nether_wart_block)
B(-2,42,2,minecraft:nether_wart_block)
B(-2,43,2,minecraft:nether_wart_block)
B(-2,44,2,minecraft:nether_wart_block)
B(-2,65,2,minecraft:nether_wart_block)
B(-2,66,2,minecraft:nether_wart_block)
B(-2,67,2,minecraft:nether_wart_block)
B(-2,68,2,minecraft:nether_wart_block)
B(-2,69,2,minecraft:nether_wart_block)
B(-2,34,3,minecraft:nether_wart_block)
B(-2,35,3,minecraft:nether_wart_block)
B(-2,36,3,minecraft:nether_wart_block)
B(-2,37,3,minecraft:nether_wart_block)
B(-2,38,3,minecraft:nether_wart_block)
B(-2,39,3,minecraft:nether_wart_block)
B(-2,40,3,minecraft:nether_wart_block)
B(-2,41,3,minecraft:nether_wart_block)
B(-2,42,3,minecraft:nether_wart_block)
B(-2,43,3,minecraft:nether_wart_block)
B(-2,44,3,minecraft:nether_wart_block)
B(-2,34,4,minecraft:nether_wart_block)
B(-2,35,4,minecraft:nether_wart_block)
B(-2,36,4,minecraft:nether_wart_block)
B(-2,37,4,minecraft:nether_wart_block)
B(-2,38,4,minecraft:nether_wart_block)
B(-2,39,4,minecraft:nether_wart_block)
B(-2,40,4,minecraft:nether_wart_block)
B(-2,41,4,minecraft:nether_wart_block)
B(-2,42,4,minecraft:nether_wart_block)
B(-2,43,4,minecraft:nether_wart_block)
B(-2,35,5,minecraft:nether_wart_block)
B(-2,36,5,minecraft:nether_wart_block)
B(-2,37,5,minecraft:nether_wart_block)
B(-2,38,5,minecraft:nether_wart_block)
B(-2,39,5,minecraft:nether_wart_block)
B(-2,40,5,minecraft:nether_wart_block)
B(-2,41,5,minecraft:nether_wart_block)
B(-2,42,5,minecraft:nether_wart_block)
B(-2,37,6,minecraft:nether_wart_block)
B(-2,38,6,minecraft:nether_wart_block)
B(-2,39,6,minecraft:nether_wart_block)
B(-2,40,6,minecraft:nether_wart_block)
B(-2,41,6,minecraft:nether_wart_block)
B(-1,40,-7,minecraft:nether_wart_block)
B(-1,41,-7,minecraft:nether_wart_block)
B(-1,42,-7,minecraft:nether_wart_block)
B(-1,43,-7,minecraft:nether_wart_block)
B(-1,44,-7,minecraft:nether_wart_block)
B(-1,45,-7,minecraft:nether_wart_block)
B(-1,46,-7,minecraft:nether_wart_block)
B(-1,47,-7,minecraft:nether_wart_block)
B(-1,48,-7,minecraft:nether_wart_block)
B(-1,49,-7,minecraft:nether_wart_block)
B(-1,50,-7,minecraft:nether_wart_block)
B(-1,51,-7,minecraft:nether_wart_block)
B(-1,52,-7,minecraft:nether_wart_block)
B(-1,53,-7,minecraft:nether_wart_block)
B(-1,54,-7,minecraft:nether_wart_block)
B(-1,55,-7,minecraft:nether_wart_block)
B(-1,56,-7,minecraft:nether_wart_block)
B(-1,66,-7,minecraft:nether_wart_block)
B(-1,67,-7,minecraft:nether_wart_block)
B(-1,68,-7,minecraft:nether_wart_block)
B(-1,69,-7,minecraft:nether_wart_block)
B(-1,70,-7,minecraft:nether_wart_block)
B(-1,71,-7,minecraft:nether_wart_block)
B(-1,72,-7,minecraft:nether_wart_block)
B(-1,73,-7,minecraft:nether_wart_block)
B(-1,74,-7,minecraft:nether_wart_block)
B(-1,39,-6,minecraft:nether_wart_block)
B(-1,40,-6,minecraft:nether_wart_block)
B(-1,41,-6,minecraft:nether_wart_block)
B(-1,42,-6,minecraft:nether_wart_block)
B(-1,43,-6,minecraft:nether_wart_block)
B(-1,44,-6,minecraft:nether_wart_block)
B(-1,45,-6,minecraft:nether_wart_block)
B(-1,46,-6,minecraft:nether_wart_block)
B(-1,47,-6,minecraft:nether_wart_block)
B(-1,48,-6,minecraft:nether_wart_block)
B(-1,49,-6,minecraft:nether_wart_block)
B(-1,50,-6,minecraft:nether_wart_block)
B(-1,51,-6,minecraft:nether_wart_block)
B(-1,52,-6,minecraft:nether_wart_block)
B(-1,53,-6,minecraft:nether_wart_block)
B(-1,54,-6,minecraft:nether_wart_block)
B(-1,55,-6,minecraft:nether_wart_block)
B(-1,56,-6,minecraft:nether_wart_block)
B(-1,57,-6,minecraft:nether_wart_block)
B(-1,58,-6,minecraft:nether_wart_block)
B(-1,65,-6,minecraft:nether_wart_block)
B(-1,66,-6,minecraft:nether_wart_block)
B(-1,67,-6,minecraft:nether_wart_block)
B(-1,68,-6,minecraft:nether_wart_block)
B(-1,69,-6,minecraft:nether_wart_block)
B(-1,70,-6,minecraft:nether_wart_block)
B(-1,71,-6,minecraft:nether_wart_block)
B(-1,72,-6,minecraft:nether_wart_block)
B(-1,73,-6,minecraft:nether_wart_block)
B(-1,74,-6,minecraft:nether_wart_block)
B(-1,75,-6,minecraft:nether_wart_block)
B(-1,38,-5,minecraft:nether_wart_block)
B(-1,39,-5,minecraft:nether_wart_block)
B(-1,40,-5,minecraft:nether_wart_block)
B(-1,41,-5,minecraft:nether_wart_block)
B(-1,42,-5,minecraft:nether_wart_block)
B(-1,43,-5,minecraft:nether_wart_block)
B(-1,44,-5,minecraft:nether_wart_block)
B(-1,45,-5,minecraft:nether_wart_block)
B(-1,46,-5,minecraft:nether_wart_block)
B(-1,47,-5,minecraft:nether_wart_block)
B(-1,48,-5,minecraft:nether_wart_block)
B(-1,49,-5,minecraft:nether_wart_block)
B(-1,50,-5,minecraft:nether_wart_block)
B(-1,51,-5,minecraft:nether_wart_block)
B(-1,52,-5,minecraft:nether_wart_block)
B(-1,53,-5,minecraft:nether_wart_block)
B(-1,54,-5,minecraft:nether_wart_block)
B(-1,55,-5,minecraft:nether_wart_block)
B(-1,56,-5,minecraft:nether_wart_block)
B(-1,57,-5,minecraft:nether_wart_block)
B(-1,58,-5,minecraft:nether_wart_block)
B(-1,59,-5,minecraft:nether_wart_block)
B(-1,65,-5,minecraft:nether_wart_block)
B(-1,66,-5,minecraft:nether_wart_block)
B(-1,67,-5,minecraft:nether_wart_block)
B(-1,68,-5,minecraft:nether_wart_block)
B(-1,69,-5,minecraft:nether_wart_block)
B(-1,70,-5,minecraft:nether_wart_block)
B(-1,71,-5,minecraft:nether_wart_block)
B(-1,72,-5,minecraft:nether_wart_block)
B(-1,73,-5,minecraft:nether_wart_block)
B(-1,74,-5,minecraft:nether_wart_block)
B(-1,75,-5,minecraft:nether_wart_block)
B(-1,38,-4,minecraft:nether_wart_block)
B(-1,39,-4,minecraft:nether_wart_block)
