
#######################################################################
# +-----------------------------------------------------------------+ #
# |                            BO4 object                           | #
# +-----------------------------------------------------------------+ #
#######################################################################

Author: Unknown

Description: No description given

SettingsMode: WriteWithoutComments


#######################################################################
# +-----------------------------------------------------------------+ #
# |                          Main settings                          | #
# +-----------------------------------------------------------------+ #
#######################################################################

FixedRotation: 

Frequency: 0

SpawnHeight: highestBlock

UseCenterForHighestBlock: true

##############################
# Height Limits for the BO4. #
##############################

MinHeight: 0

MaxHeight: 255

InheritBO3: 

InheritBO3Rotation: NORTH

OverrideChildSettings: true

OverrideParentHeight: false

CanOverride: false

BranchFrequency: 0

BranchFrequencyGroup: 

MustBeBelowOther: false

MustBeInside: 

CannotBeInside: 

ReplacesBO3: 

MustBeInsideWorldBorders: false

CanSpawnOnWater: true

SpawnOnWaterOnly: false

SpawnUnderWater: false

SpawnAtWaterLevel: false

HeightOffset: 0

RemoveAir: true

ReplaceAbove: 

ReplaceBelow: 

ReplaceWithBiomeBlocks: true

ReplaceWithSurfaceBlock: GRASS

ReplaceWithGroundBlock: DIRT

ReplaceWithStoneBlock: STONE

SmoothRadius: 0

SmoothHeightOffset: 0

SmoothStartTop: false

SmoothStartWood: false

SmoothingSurfaceBlock: 

SmoothingGroundBlock: 

BO3Group: 

IsSpawnPoint: false

DoReplaceBlocks: true


#######################################################################
# +-----------------------------------------------------------------+ #
# |                              Blocks                             | #
# +-----------------------------------------------------------------+ #
#######################################################################

B(-7,74,8,minecraft:nether_wart_block)
B(-7,75,8,minecraft:nether_wart_block)
B(-7,76,8,minecraft:nether_wart_block)
B(-6,73,7,minecraft:nether_wart_block)
B(-6,74,7,minecraft:nether_wart_block)
B(-6,75,7,minecraft:nether_wart_block)
B(-6,76,7,minecraft:nether_wart_block)
B(-6,77,7,minecraft:nether_wart_block)
B(-6,72,8,minecraft:nether_wart_block)
B(-6,73,8,minecraft:nether_wart_block)
B(-6,74,8,minecraft:nether_wart_block)
B(-6,75,8,minecraft:nether_wart_block)
B(-6,76,8,minecraft:nether_wart_block)
B(-6,77,8,minecraft:nether_wart_block)
B(-6,78,8,minecraft:nether_wart_block)
B(-5,73,6,minecraft:nether_wart_block)
B(-5,74,6,minecraft:nether_wart_block)
B(-5,75,6,minecraft:nether_wart_block)
B(-5,76,6,minecraft:nether_wart_block)
B(-5,77,6,minecraft:nether_wart_block)
B(-5,72,7,minecraft:nether_wart_block)
B(-5,73,7,minecraft:nether_wart_block)
B(-5,74,7,minecraft:nether_wart_block)
B(-5,75,7,minecraft:nether_wart_block)
B(-5,76,7,minecraft:nether_wart_block)
B(-5,77,7,minecraft:nether_wart_block)
B(-5,78,7,minecraft:nether_wart_block)
B(-5,71,8,minecraft:nether_wart_block)
B(-5,72,8,minecraft:nether_wart_block)
B(-5,73,8,minecraft:nether_wart_block)
B(-5,74,8,minecraft:nether_wart_block)
B(-5,75,8,minecraft:nether_wart_block)
B(-5,76,8,minecraft:nether_wart_block)
B(-5,77,8,minecraft:nether_wart_block)
B(-5,78,8,minecraft:nether_wart_block)
B(-5,79,8,minecraft:nether_wart_block)
B(-4,74,5,minecraft:nether_wart_block)
B(-4,75,5,minecraft:nether_wart_block)
B(-4,76,5,minecraft:nether_wart_block)
B(-4,72,6,minecraft:nether_wart_block)
B(-4,73,6,minecraft:nether_wart_block)
B(-4,74,6,minecraft:nether_wart_block)
B(-4,75,6,minecraft:nether_wart_block)
B(-4,76,6,minecraft:nether_wart_block)
B(-4,77,6,minecraft:nether_wart_block)
B(-4,78,6,minecraft:nether_wart_block)
B(-4,71,7,minecraft:nether_wart_block)
B(-4,72,7,minecraft:nether_wart_block)
B(-4,73,7,minecraft:nether_wart_block)
B(-4,74,7,minecraft:nether_wart_block)
B(-4,75,7,minecraft:nether_wart_block)
B(-4,76,7,minecraft:nether_wart_block)
B(-4,77,7,minecraft:nether_wart_block)
B(-4,78,7,minecraft:nether_wart_block)
B(-4,79,7,minecraft:nether_wart_block)
B(-4,70,8,minecraft:nether_wart_block)
B(-4,71,8,minecraft:nether_wart_block)
B(-4,72,8,minecraft:nether_wart_block)
B(-4,73,8,minecraft:nether_wart_block)
B(-4,74,8,minecraft:nether_wart_block)
B(-4,75,8,minecraft:nether_wart_block)
B(-4,76,8,minecraft:nether_wart_block)
B(-4,77,8,minecraft:nether_wart_block)
B(-4,78,8,minecraft:nether_wart_block)
B(-4,79,8,minecraft:nether_wart_block)
B(-3,73,5,minecraft:nether_wart_block)
B(-3,74,5,minecraft:nether_wart_block)
B(-3,75,5,minecraft:nether_wart_block)
B(-3,76,5,minecraft:nether_wart_block)
B(-3,77,5,minecraft:nether_wart_block)
B(-3,72,6,minecraft:nether_wart_block)
B(-3,73,6,minecraft:nether_wart_block)
B(-3,74,6,minecraft:nether_wart_block)
B(-3,75,6,minecraft:nether_wart_block)
B(-3,76,6,minecraft:nether_wart_block)
B(-3,77,6,minecraft:nether_wart_block)
B(-3,78,6,minecraft:nether_wart_block)
B(-3,69,7,minecraft:nether_wart_block)
B(-3,70,7,minecraft:nether_wart_block)
B(-3,71,7,minecraft:nether_wart_block)
B(-3,72,7,minecraft:nether_wart_block)
B(-3,73,7,minecraft:nether_wart_block)
B(-3,74,7,minecraft:nether_wart_block)
B(-3,75,7,minecraft:nether_wart_block)
B(-3,76,7,minecraft:nether_wart_block)
B(-3,77,7,minecraft:nether_wart_block)
B(-3,78,7,minecraft:nether_wart_block)
B(-3,79,7,minecraft:nether_wart_block)
B(-3,68,8,minecraft:nether_wart_block)
B(-3,69,8,minecraft:nether_wart_block)
B(-3,70,8,minecraft:nether_wart_block)
B(-3,71,8,minecraft:nether_wart_block)
B(-3,72,8,minecraft:nether_wart_block)
B(-3,73,8,minecraft:nether_wart_block)
B(-3,74,8,minecraft:nether_wart_block)
B(-3,75,8,minecraft:nether_wart_block)
B(-3,76,8,minecraft:nether_wart_block)
B(-3,77,8,minecraft:nether_wart_block)
B(-3,78,8,minecraft:nether_wart_block)
B(-3,79,8,minecraft:nether_wart_block)
B(-3,80,8,minecraft:nether_wart_block)
B(-2,34,4,minecraft:nether_wart_block)
B(-2,35,4,minecraft:nether_wart_block)
B(-2,36,4,minecraft:nether_wart_block)
B(-2,33,5,minecraft:nether_wart_block)
B(-2,34,5,minecraft:nether_wart_block)
B(-2,35,5,minecraft:nether_wart_block)
B(-2,36,5,minecraft:nether_wart_block)
B(-2,37,5,minecraft:nether_wart_block)
B(-2,73,5,minecraft:nether_wart_block)
B(-2,74,5,minecraft:nether_wart_block)
B(-2,75,5,minecraft:nether_wart_block)
B(-2,76,5,minecraft:nether_wart_block)
B(-2,77,5,minecraft:nether_wart_block)
B(-2,33,6,minecraft:nether_wart_block)
B(-2,34,6,minecraft:nether_wart_block)
B(-2,35,6,minecraft:nether_wart_block)
B(-2,36,6,minecraft:nether_wart_block)
B(-2,37,6,minecraft:nether_wart_block)
B(-2,69,6,minecraft:nether_wart_block)
B(-2,70,6,minecraft:nether_wart_block)
B(-2,71,6,minecraft:nether_wart_block)
B(-2,72,6,minecraft:nether_wart_block)
B(-2,73,6,minecraft:nether_wart_block)
B(-2,74,6,minecraft:nether_wart_block)
B(-2,75,6,minecraft:nether_wart_block)
B(-2,76,6,minecraft:nether_wart_block)
B(-2,77,6,minecraft:nether_wart_block)
B(-2,78,6,minecraft:nether_wart_block)
B(-2,30,7,minecraft:nether_wart_block)
B(-2,31,7,minecraft:nether_wart_block)
B(-2,32,7,minecraft:nether_wart_block)
B(-2,33,7,minecraft:nether_wart_block)
B(-2,34,7,minecraft:nether_wart_block)
B(-2,35,7,minecraft:nether_wart_block)
B(-2,36,7,minecraft:nether_wart_block)
B(-2,37,7,minecraft:nether_wart_block)
B(-2,68,7,minecraft:nether_wart_block)
B(-2,69,7,minecraft:nether_wart_block)
B(-2,70,7,minecraft:nether_wart_block)
B(-2,71,7,minecraft:nether_wart_block)
B(-2,72,7,minecraft:nether_wart_block)
B(-2,73,7,minecraft:nether_wart_block)
B(-2,74,7,minecraft:nether_wart_block)
B(-2,75,7,minecraft:nether_wart_block)
B(-2,76,7,minecraft:nether_wart_block)
B(-2,77,7,minecraft:nether_wart_block)
B(-2,78,7,minecraft:nether_wart_block)
B(-2,79,7,minecraft:nether_wart_block)
B(-2,29,8,minecraft:nether_wart_block)
B(-2,30,8,minecraft:nether_wart_block)
B(-2,31,8,minecraft:nether_wart_block)
B(-2,32,8,minecraft:nether_wart_block)
B(-2,33,8,minecraft:nether_wart_block)
B(-2,34,8,minecraft:nether_wart_block)
B(-2,35,8,minecraft:nether_wart_block)
B(-2,36,8,minecraft:nether_wart_block)
B(-2,67,8,minecraft:nether_wart_block)
B(-2,68,8,minecraft:nether_wart_block)
B(-2,69,8,minecraft:nether_wart_block)
B(-2,70,8,minecraft:nether_wart_block)
B(-2,71,8,minecraft:nether_wart_block)
B(-2,72,8,minecraft:nether_wart_block)
B(-2,73,8,minecraft:nether_wart_block)
B(-2,74,8,minecraft:nether_wart_block)
B(-2,75,8,minecraft:nether_wart_block)
B(-2,76,8,minecraft:nether_wart_block)
B(-2,77,8,minecraft:nether_wart_block)
B(-2,78,8,minecraft:nether_wart_block)
B(-2,79,8,minecraft:nether_wart_block)
B(-2,80,8,minecraft:nether_wart_block)
B(-1,33,3,minecraft:nether_wart_block)
B(-1,34,3,minecraft:nether_wart_block)
B(-1,35,3,minecraft:nether_wart_block)
B(-1,36,3,minecraft:nether_wart_block)
B(-1,37,3,minecraft:nether_wart_block)
B(-1,32,4,minecraft:nether_wart_block)
B(-1,33,4,minecraft:nether_wart_block)
B(-1,34,4,minecraft:nether_wart_block)
B(-1,35,4,minecraft:nether_wart_block)
B(-1,36,4,minecraft:nether_wart_block)
B(-1,37,4,minecraft:nether_wart_block)
B(-1,38,4,minecraft:nether_wart_block)
B(-1,32,5,minecraft:nether_wart_block)
B(-1,33,5,minecraft:nether_wart_block)
B(-1,34,5,minecraft:nether_wart_block)
B(-1,35,5,minecraft:nether_wart_block)
B(-1,36,5,minecraft:nether_wart_block)
B(-1,37,5,minecraft:nether_wart_block)
B(-1,38,5,minecraft:nether_wart_block)
B(-1,70,5,minecraft:nether_wart_block)
B(-1,71,5,minecraft:nether_wart_block)
B(-1,72,5,minecraft:nether_wart_block)
B(-1,73,5,minecraft:nether_wart_block)
B(-1,74,5,minecraft:nether_wart_block)
B(-1,75,5,minecraft:nether_wart_block)
B(-1,76,5,minecraft:nether_wart_block)
B(-1,77,5,minecraft:nether_wart_block)
B(-1,29,6,minecraft:nether_wart_block)
B(-1,30,6,minecraft:nether_wart_block)
B(-1,31,6,minecraft:nether_wart_block)
B(-1,32,6,minecraft:nether_wart_block)
B(-1,33,6,minecraft:nether_wart_block)
B(-1,34,6,minecraft:nether_wart_block)
B(-1,35,6,minecraft:nether_wart_block)
B(-1,36,6,minecraft:nether_wart_block)
B(-1,37,6,minecraft:nether_wart_block)
B(-1,38,6,minecraft:nether_wart_block)
B(-1,68,6,minecraft:nether_wart_block)
B(-1,69,6,minecraft:nether_wart_block)
B(-1,70,6,minecraft:nether_wart_block)
B(-1,71,6,minecraft:nether_wart_block)
B(-1,72,6,minecraft:nether_wart_block)
B(-1,73,6,minecraft:nether_wart_block)
B(-1,74,6,minecraft:nether_wart_block)
B(-1,75,6,minecraft:nether_wart_block)
B(-1,76,6,minecraft:nether_wart_block)
B(-1,77,6,minecraft:nether_wart_block)
B(-1,78,6,minecraft:nether_wart_block)
B(-1,28,7,minecraft:nether_wart_block)
B(-1,29,7,minecraft:nether_wart_block)
B(-1,30,7,minecraft:nether_wart_block)
B(-1,31,7,minecraft:nether_wart_block)
B(-1,32,7,minecraft:nether_wart_block)
B(-1,33,7,minecraft:nether_wart_block)
B(-1,34,7,minecraft:nether_wart_block)
B(-1,35,7,minecraft:nether_wart_block)
B(-1,36,7,minecraft:nether_wart_block)
B(-1,37,7,minecraft:nether_wart_block)
B(-1,38,7,minecraft:nether_wart_block)
B(-1,67,7,minecraft:nether_wart_block)
B(-1,68,7,minecraft:nether_wart_block)
B(-1,69,7,minecraft:nether_wart_block)
B(-1,70,7,minecraft:nether_wart_block)
B(-1,71,7,minecraft:nether_wart_block)
B(-1,72,7,minecraft:nether_wart_block)
B(-1,73,7,minecraft:nether_wart_block)
B(-1,74,7,minecraft:nether_wart_block)
B(-1,75,7,minecraft:nether_wart_block)
B(-1,76,7,minecraft:nether_wart_block)
B(-1,77,7,minecraft:nether_wart_block)
B(-1,78,7,minecraft:nether_wart_block)
B(-1,79,7,minecraft:nether_wart_block)
B(-1,26,8,minecraft:nether_wart_block)
B(-1,27,8,minecraft:nether_wart_block)
B(-1,28,8,minecraft:nether_wart_block)
B(-1,29,8,minecraft:nether_wart_block)
B(-1,30,8,minecraft:nether_wart_block)
B(-1,31,8,minecraft:nether_wart_block)
B(-1,32,8,minecraft:nether_wart_block)
B(-1,33,8,minecraft:nether_wart_block)
B(-1,34,8,minecraft:nether_wart_block)
B(-1,35,8,minecraft:nether_wart_block)
B(-1,36,8,minecraft:nether_wart_block)
B(-1,37,8,minecraft:nether_wart_block)
B(-1,38,8,minecraft:nether_wart_block)
B(-1,67,8,minecraft:nether_wart_block)
B(-1,68,8,minecraft:nether_wart_block)
B(-1,69,8,minecraft:nether_wart_block)
B(-1,70,8,minecraft:nether_wart_block)
B(-1,71,8,minecraft:nether_wart_block)
B(-1,72,8,minecraft:nether_wart_block)
B(-1,73,8,minecraft:nether_wart_block)
B(-1,74,8,minecraft:nether_wart_block)
B(-1,75,8,minecraft:nether_wart_block)
B(-1,76,8,minecraft:nether_wart_block)
B(-1,77,8,minecraft:nether_wart_block)
B(-1,78,8,minecraft:nether_wart_block)
B(-1,79,8,minecraft:nether_wart_block)
B(-1,80,8,minecraft:nether_wart_block)
B(0,33,2,minecraft:nether_wart_block)
B(0,34,2,minecraft:nether_wart_block)
B(0,35,2,minecraft:nether_wart_block)
B(0,36,2,minecraft:nether_wart_block)
B(0,37,2,minecraft:nether_wart_block)
B(0,32,3,minecraft:nether_wart_block)
B(0,33,3,minecraft:nether_wart_block)
B(0,34,3,minecraft:nether_wart_block)
B(0,35,3,minecraft:nether_wart_block)
B(0,36,3,minecraft:nether_wart_block)
B(0,37,3,minecraft:nether_wart_block)
B(0,38,3,minecraft:nether_wart_block)
B(0,31,4,minecraft:nether_wart_block)
B(0,32,4,minecraft:nether_wart_block)
B(0,33,4,minecraft:nether_wart_block)
B(0,34,4,minecraft:nether_wart_block)
B(0,35,4,minecraft:nether_wart_block)
B(0,36,4,minecraft:nether_wart_block)
B(0,37,4,minecraft:nether_wart_block)
B(0,38,4,minecraft:nether_wart_block)
B(0,39,4,minecraft:nether_wart_block)
B(0,29,5,minecraft:nether_wart_block)
B(0,30,5,minecraft:nether_wart_block)
B(0,31,5,minecraft:nether_wart_block)
B(0,32,5,minecraft:nether_wart_block)
B(0,33,5,minecraft:nether_wart_block)
B(0,34,5,minecraft:nether_wart_block)
B(0,35,5,minecraft:nether_wart_block)
B(0,36,5,minecraft:nether_wart_block)
B(0,37,5,minecraft:nether_wart_block)
B(0,38,5,minecraft:nether_wart_block)
B(0,39,5,minecraft:nether_wart_block)
B(0,69,5,minecraft:nether_wart_block)
B(0,70,5,minecraft:nether_wart_block)
B(0,71,5,minecraft:nether_wart_block)
B(0,72,5,minecraft:nether_wart_block)
B(0,73,5,minecraft:nether_wart_block)
B(0,74,5,minecraft:nether_wart_block)
B(0,75,5,minecraft:nether_wart_block)
B(0,76,5,minecraft:nether_wart_block)
B(0,28,6,minecraft:nether_wart_block)
B(0,29,6,minecraft:nether_wart_block)
B(0,30,6,minecraft:nether_wart_block)
B(0,31,6,minecraft:nether_wart_block)
B(0,32,6,minecraft:nether_wart_block)
B(0,33,6,minecraft:nether_wart_block)
B(0,34,6,minecraft:nether_wart_block)
B(0,35,6,minecraft:nether_wart_block)
B(0,36,6,minecraft:nether_wart_block)
B(0,37,6,minecraft:nether_wart_block)
B(0,38,6,minecraft:nether_wart_block)
B(0,39,6,minecraft:nether_wart_block)
B(0,68,6,minecraft:nether_wart_block)
B(0,69,6,minecraft:nether_wart_block)
B(0,70,6,minecraft:nether_wart_block)
B(0,71,6,minecraft:nether_wart_block)
B(0,72,6,minecraft:nether_wart_block)
B(0,73,6,minecraft:nether_wart_block)
B(0,74,6,minecraft:nether_wart_block)
B(0,75,6,minecraft:nether_wart_block)
B(0,76,6,minecraft:nether_wart_block)
B(0,77,6,minecraft:nether_wart_block)
B(0,78,6,minecraft:nether_wart_block)
B(0,27,7,minecraft:nether_wart_block)
B(0,28,7,minecraft:nether_wart_block)
B(0,29,7,minecraft:nether_wart_block)
B(0,30,7,minecraft:nether_wart_block)
B(0,31,7,minecraft:nether_wart_block)
B(0,32,7,minecraft:nether_wart_block)
B(0,33,7,minecraft:nether_wart_block)
B(0,34,7,minecraft:nether_wart_block)
B(0,35,7,minecraft:nether_wart_block)
B(0,36,7,minecraft:nether_wart_block)
B(0,37,7,minecraft:nether_wart_block)
B(0,38,7,minecraft:nether_wart_block)
B(0,39,7,minecraft:nether_wart_block)
B(0,67,7,minecraft:nether_wart_block)
B(0,68,7,minecraft:nether_wart_block)
B(0,69,7,minecraft:nether_wart_block)
B(0,70,7,minecraft:nether_wart_block)
B(0,71,7,minecraft:nether_wart_block)
B(0,72,7,minecraft:nether_wart_block)
B(0,73,7,minecraft:nether_wart_block)
B(0,74,7,minecraft:nether_wart_block)
B(0,75,7,minecraft:nether_wart_block)
B(0,76,7,minecraft:nether_wart_block)
B(0,77,7,minecraft:nether_wart_block)
B(0,78,7,minecraft:nether_wart_block)
B(0,79,7,minecraft:nether_wart_block)
B(0,25,8,minecraft:nether_wart_block)
B(0,26,8,minecraft:nether_wart_block)
B(0,27,8,minecraft:nether_wart_block)
B(0,28,8,minecraft:nether_wart_block)
B(0,29,8,minecraft:nether_wart_block)
B(0,30,8,minecraft:nether_wart_block)
B(0,31,8,minecraft:nether_wart_block)
B(0,32,8,minecraft:nether_wart_block)
B(0,33,8,minecraft:nether_wart_block)
B(0,34,8,minecraft:nether_wart_block)
B(0,35,8,minecraft:nether_wart_block)
B(0,36,8,minecraft:nether_wart_block)
B(0,37,8,minecraft:nether_wart_block)
B(0,38,8,minecraft:nether_wart_block)
B(0,39,8,minecraft:nether_wart_block)
B(0,66,8,minecraft:nether_wart_block)
B(0,67,8,minecraft:nether_wart_block)
B(0,68,8,minecraft:nether_wart_block)
B(0,69,8,minecraft:nether_wart_block)
B(0,70,8,minecraft:nether_wart_block)
B(0,71,8,minecraft:nether_wart_block)
B(0,72,8,minecraft:nether_wart_block)
B(0,73,8,minecraft:nether_wart_block)
B(0,74,8,minecraft:nether_wart_block)
B(0,75,8,minecraft:nether_wart_block)
B(0,76,8,minecraft:nether_wart_block)
B(0,77,8,minecraft:nether_wart_block)
B(0,78,8,minecraft:nether_wart_block)
B(0,79,8,minecraft:nether_wart_block)
B(1,34,1,minecraft:nether_wart_block)
B(1,35,1,minecraft:nether_wart_block)
B(1,36,1,minecraft:nether_wart_block)
B(1,32,2,minecraft:nether_wart_block)
B(1,33,2,minecraft:nether_wart_block)
B(1,34,2,minecraft:nether_wart_block)
B(1,35,2,minecraft:nether_wart_block)
B(1,36,2,minecraft:nether_wart_block)
B(1,37,2,minecraft:nether_wart_block)
B(1,38,2,minecraft:nether_wart_block)
B(1,31,3,minecraft:nether_wart_block)
B(1,32,3,minecraft:nether_wart_block)
B(1,33,3,minecraft:nether_wart_block)
B(1,34,3,minecraft:nether_wart_block)
B(1,35,3,minecraft:nether_wart_block)
B(1,36,3,minecraft:nether_wart_block)
B(1,37,3,minecraft:nether_wart_block)
B(1,38,3,minecraft:nether_wart_block)
B(1,39,3,minecraft:nether_wart_block)
B(1,14,4,minecraft:nether_wart_block)
B(1,15,4,minecraft:nether_wart_block)
B(1,16,4,minecraft:nether_wart_block)
B(1,30,4,minecraft:nether_wart_block)
B(1,31,4,minecraft:nether_wart_block)
B(1,32,4,minecraft:nether_wart_block)
B(1,33,4,minecraft:nether_wart_block)
B(1,34,4,minecraft:nether_wart_block)
B(1,35,4,minecraft:nether_wart_block)
B(1,36,4,minecraft:nether_wart_block)
B(1,37,4,minecraft:nether_wart_block)
B(1,38,4,minecraft:nether_wart_block)
B(1,39,4,minecraft:nether_wart_block)
B(1,13,5,minecraft:nether_wart_block)
B(1,14,5,minecraft:nether_wart_block)
B(1,15,5,minecraft:nether_wart_block)
B(1,16,5,minecraft:nether_wart_block)
B(1,17,5,minecraft:nether_wart_block)
B(1,28,5,minecraft:nether_wart_block)
B(1,29,5,minecraft:nether_wart_block)
B(1,30,5,minecraft:nether_wart_block)
B(1,31,5,minecraft:nether_wart_block)
B(1,32,5,minecraft:nether_wart_block)
B(1,33,5,minecraft:nether_wart_block)
B(1,34,5,minecraft:nether_wart_block)
B(1,35,5,minecraft:nether_wart_block)
B(1,36,5,minecraft:nether_wart_block)
B(1,37,5,minecraft:nether_wart_block)
B(1,38,5,minecraft:nether_wart_block)
B(1,39,5,minecraft:nether_wart_block)
B(1,40,5,minecraft:nether_wart_block)
B(1,69,5,minecraft:nether_wart_block)
B(1,70,5,minecraft:nether_wart_block)
B(1,71,5,minecraft:nether_wart_block)
B(1,72,5,minecraft:nether_wart_block)
B(1,73,5,minecraft:nether_wart_block)
B(1,13,6,minecraft:nether_wart_block)
B(1,14,6,minecraft:nether_wart_block)
B(1,15,6,minecraft:nether_wart_block)
B(1,16,6,minecraft:nether_wart_block)
B(1,17,6,minecraft:nether_wart_block)
B(1,27,6,minecraft:nether_wart_block)
B(1,28,6,minecraft:nether_wart_block)
B(1,29,6,minecraft:nether_wart_block)
B(1,30,6,minecraft:nether_wart_block)
B(1,31,6,minecraft:nether_wart_block)
B(1,32,6,minecraft:nether_wart_block)
B(1,33,6,minecraft:nether_wart_block)
B(1,34,6,minecraft:nether_wart_block)
B(1,35,6,minecraft:nether_wart_block)
B(1,36,6,minecraft:nether_wart_block)
B(1,37,6,minecraft:nether_wart_block)
B(1,38,6,minecraft:nether_wart_block)
B(1,39,6,minecraft:nether_wart_block)
B(1,40,6,minecraft:nether_wart_block)
B(1,68,6,minecraft:nether_wart_block)
B(1,69,6,minecraft:nether_wart_block)
B(1,70,6,minecraft:nether_wart_block)
B(1,71,6,minecraft:nether_wart_block)
B(1,72,6,minecraft:nether_wart_block)
B(1,73,6,minecraft:nether_wart_block)
B(1,74,6,minecraft:nether_wart_block)
B(1,75,6,minecraft:nether_wart_block)
B(1,76,6,minecraft:nether_wart_block)
B(1,77,6,minecraft:nether_wart_block)
B(1,13,7,minecraft:nether_wart_block)
B(1,14,7,minecraft:nether_wart_block)
B(1,15,7,minecraft:nether_wart_block)
B(1,16,7,minecraft:nether_wart_block)
B(1,17,7,minecraft:nether_wart_block)
B(1,24,7,minecraft:nether_wart_block)
B(1,25,7,minecraft:nether_wart_block)
B(1,26,7,minecraft:nether_wart_block)
B(1,27,7,minecraft:nether_wart_block)
B(1,28,7,minecraft:nether_wart_block)
B(1,29,7,minecraft:nether_wart_block)
B(1,30,7,minecraft:nether_wart_block)
B(1,31,7,minecraft:nether_wart_block)
B(1,32,7,minecraft:nether_wart_block)
B(1,33,7,minecraft:nether_wart_block)
B(1,34,7,minecraft:nether_wart_block)
B(1,35,7,minecraft:nether_wart_block)
B(1,36,7,minecraft:nether_wart_block)
B(1,37,7,minecraft:nether_wart_block)
B(1,38,7,minecraft:nether_wart_block)
B(1,39,7,minecraft:nether_wart_block)
B(1,40,7,minecraft:nether_wart_block)
B(1,67,7,minecraft:nether_wart_block)
B(1,68,7,minecraft:nether_wart_block)
B(1,69,7,minecraft:nether_wart_block)
B(1,70,7,minecraft:nether_wart_block)
B(1,71,7,minecraft:nether_wart_block)
B(1,72,7,minecraft:nether_wart_block)
B(1,73,7,minecraft:nether_wart_block)
B(1,74,7,minecraft:nether_wart_block)
B(1,75,7,minecraft:nether_wart_block)
B(1,76,7,minecraft:nether_wart_block)
B(1,77,7,minecraft:nether_wart_block)
B(1,78,7,minecraft:nether_wart_block)
B(1,14,8,minecraft:nether_wart_block)
B(1,15,8,minecraft:nether_wart_block)
B(1,16,8,minecraft:nether_wart_block)
B(1,23,8,minecraft:nether_wart_block)
B(1,24,8,minecraft:nether_wart_block)
B(1,25,8,minecraft:nether_wart_block)
B(1,26,8,minecraft:nether_wart_block)
B(1,27,8,minecraft:nether_wart_block)
B(1,28,8,minecraft:nether_wart_block)
B(1,29,8,minecraft:nether_wart_block)
B(1,30,8,minecraft:nether_wart_block)
B(1,31,8,minecraft:nether_wart_block)
B(1,32,8,minecraft:nether_wart_block)
B(1,33,8,minecraft:nether_wart_block)
B(1,34,8,minecraft:nether_wart_block)
B(1,35,8,minecraft:nether_wart_block)
B(1,36,8,minecraft:nether_wart_block)
B(1,37,8,minecraft:nether_wart_block)
B(1,38,8,minecraft:nether_wart_block)
B(1,39,8,minecraft:nether_wart_block)
B(1,66,8,minecraft:nether_wart_block)
B(1,67,8,minecraft:nether_wart_block)
B(1,68,8,minecraft:nether_wart_block)
B(1,69,8,minecraft:nether_wart_block)
B(1,70,8,minecraft:nether_wart_block)
B(1,71,8,minecraft:nether_wart_block)
B(1,72,8,minecraft:nether_wart_block)
B(1,73,8,minecraft:nether_wart_block)
B(1,74,8,minecraft:nether_wart_block)
B(1,75,8,minecraft:nether_wart_block)
B(1,76,8,minecraft:nether_wart_block)
B(1,77,8,minecraft:nether_wart_block)
B(1,78,8,minecraft:nether_wart_block)
B(1,79,8,minecraft:nether_wart_block)
B(2,16,-1,minecraft:nether_wart_block)
B(2,17,-1,minecraft:nether_wart_block)
B(2,18,-1,minecraft:nether_wart_block)
B(2,15,0,minecraft:nether_wart_block)
B(2,16,0,minecraft:nether_wart_block)
B(2,17,0,minecraft:nether_wart_block)
B(2,18,0,minecraft:nether_wart_block)
B(2,19,0,minecraft:nether_wart_block)
B(2,15,1,minecraft:nether_wart_block)
B(2,16,1,minecraft:nether_wart_block)
B(2,17,1,minecraft:nether_wart_block)
B(2,18,1,minecraft:nether_wart_block)
B(2,19,1,minecraft:nether_wart_block)
B(2,33,1,minecraft:nether_wart_block)
B(2,34,1,minecraft:nether_wart_block)
B(2,35,1,minecraft:nether_wart_block)
B(2,36,1,minecraft:nether_wart_block)
B(2,37,1,minecraft:nether_wart_block)
B(2,15,2,minecraft:nether_wart_block)
B(2,16,2,minecraft:nether_wart_block)
B(2,17,2,minecraft:nether_wart_block)
B(2,18,2,minecraft:nether_wart_block)
B(2,19,2,minecraft:nether_wart_block)
B(2,32,2,minecraft:nether_wart_block)
B(2,33,2,minecraft:nether_wart_block)
B(2,34,2,minecraft:nether_wart_block)
B(2,35,2,minecraft:nether_wart_block)
B(2,36,2,minecraft:nether_wart_block)
B(2,37,2,minecraft:nether_wart_block)
B(2,38,2,minecraft:nether_wart_block)
B(2,13,3,minecraft:nether_wart_block)
B(2,14,3,minecraft:nether_wart_block)
B(2,15,3,minecraft:nether_wart_block)
B(2,16,3,minecraft:nether_wart_block)
B(2,17,3,minecraft:nether_wart_block)
B(2,18,3,minecraft:nether_wart_block)
B(2,31,3,minecraft:nether_wart_block)
B(2,32,3,minecraft:nether_wart_block)
B(2,33,3,minecraft:nether_wart_block)
B(2,34,3,minecraft:nether_wart_block)
B(2,35,3,minecraft:nether_wart_block)
B(2,36,3,minecraft:nether_wart_block)
B(2,37,3,minecraft:nether_wart_block)
B(2,38,3,minecraft:nether_wart_block)
B(2,39,3,minecraft:nether_wart_block)
B(2,12,4,minecraft:nether_wart_block)
B(2,13,4,minecraft:nether_wart_block)
B(2,14,4,minecraft:nether_wart_block)
B(2,15,4,minecraft:nether_wart_block)
B(2,16,4,minecraft:nether_wart_block)
B(2,17,4,minecraft:nether_wart_block)
B(2,18,4,minecraft:nether_wart_block)
B(2,29,4,minecraft:nether_wart_block)
B(2,30,4,minecraft:nether_wart_block)
B(2,31,4,minecraft:nether_wart_block)
B(2,32,4,minecraft:nether_wart_block)
B(2,33,4,minecraft:nether_wart_block)
B(2,34,4,minecraft:nether_wart_block)
B(2,35,4,minecraft:nether_wart_block)
B(2,36,4,minecraft:nether_wart_block)
B(2,37,4,minecraft:nether_wart_block)
B(2,38,4,minecraft:nether_wart_block)
B(2,39,4,minecraft:nether_wart_block)
B(2,40,4,minecraft:nether_wart_block)
B(2,12,5,minecraft:nether_wart_block)
B(2,13,5,minecraft:nether_wart_block)
B(2,14,5,minecraft:nether_wart_block)
B(2,15,5,minecraft:nether_wart_block)
B(2,16,5,minecraft:nether_wart_block)
B(2,17,5,minecraft:nether_wart_block)
B(2,18,5,minecraft:nether_wart_block)
B(2,28,5,minecraft:nether_wart_block)
B(2,29,5,minecraft:nether_wart_block)
B(2,30,5,minecraft:nether_wart_block)
B(2,31,5,minecraft:nether_wart_block)
B(2,32,5,minecraft:nether_wart_block)
B(2,33,5,minecraft:nether_wart_block)
B(2,34,5,minecraft:nether_wart_block)
B(2,35,5,minecraft:nether_wart_block)
B(2,36,5,minecraft:nether_wart_block)
B(2,37,5,minecraft:nether_wart_block)
B(2,38,5,minecraft:nether_wart_block)
B(2,39,5,minecraft:nether_wart_block)
B(2,40,5,minecraft:nether_wart_block)
B(2,69,5,minecraft:nether_wart_block)
B(2,70,5,minecraft:nether_wart_block)
B(2,71,5,minecraft:nether_wart_block)
B(2,72,5,minecraft:nether_wart_block)
B(2,73,5,minecraft:nether_wart_block)
B(2,12,6,minecraft:nether_wart_block)
B(2,13,6,minecraft:nether_wart_block)
B(2,14,6,minecraft:nether_wart_block)
B(2,15,6,minecraft:nether_wart_block)
B(2,16,6,minecraft:nether_wart_block)
B(2,17,6,minecraft:nether_wart_block)
B(2,18,6,minecraft:nether_wart_block)
B(2,24,6,minecraft:nether_wart_block)
B(2,25,6,minecraft:nether_wart_block)
B(2,26,6,minecraft:nether_wart_block)
B(2,27,6,minecraft:nether_wart_block)
B(2,28,6,minecraft:nether_wart_block)
B(2,29,6,minecraft:nether_wart_block)
B(2,30,6,minecraft:nether_wart_block)
B(2,31,6,minecraft:nether_wart_block)
B(2,32,6,minecraft:nether_wart_block)
B(2,33,6,minecraft:nether_wart_block)
B(2,34,6,minecraft:nether_wart_block)
B(2,35,6,minecraft:nether_wart_block)
B(2,36,6,minecraft:nether_wart_block)
B(2,37,6,minecraft:nether_wart_block)
B(2,38,6,minecraft:nether_wart_block)
B(2,39,6,minecraft:nether_wart_block)
B(2,40,6,minecraft:nether_wart_block)
B(2,68,6,minecraft:nether_wart_block)
B(2,69,6,minecraft:nether_wart_block)
B(2,70,6,minecraft:nether_wart_block)
B(2,71,6,minecraft:nether_wart_block)
B(2,72,6,minecraft:nether_wart_block)
B(2,73,6,minecraft:nether_wart_block)
B(2,74,6,minecraft:nether_wart_block)
B(2,12,7,minecraft:nether_wart_block)
B(2,13,7,minecraft:nether_wart_block)
B(2,14,7,minecraft:nether_wart_block)
B(2,15,7,minecraft:nether_wart_block)
B(2,16,7,minecraft:nether_wart_block)
B(2,17,7,minecraft:nether_wart_block)
B(2,18,7,minecraft:nether_wart_block)
B(2,23,7,minecraft:nether_wart_block)
B(2,24,7,minecraft:nether_wart_block)
B(2,25,7,minecraft:nether_wart_block)
B(2,26,7,minecraft:nether_wart_block)
B(2,27,7,minecraft:nether_wart_block)
B(2,28,7,minecraft:nether_wart_block)
B(2,29,7,minecraft:nether_wart_block)
B(2,30,7,minecraft:nether_wart_block)
B(2,31,7,minecraft:nether_wart_block)
B(2,32,7,minecraft:nether_wart_block)
B(2,33,7,minecraft:nether_wart_block)
B(2,34,7,minecraft:nether_wart_block)
B(2,35,7,minecraft:nether_wart_block)
B(2,36,7,minecraft:nether_wart_block)
B(2,37,7,minecraft:nether_wart_block)
B(2,38,7,minecraft:nether_wart_block)
B(2,39,7,minecraft:nether_wart_block)
B(2,40,7,minecraft:nether_wart_block)
B(2,67,7,minecraft:nether_wart_block)
B(2,68,7,minecraft:nether_wart_block)
B(2,69,7,minecraft:nether_wart_block)
B(2,70,7,minecraft:nether_wart_block)
B(2,71,7,minecraft:nether_wart_block)
B(2,72,7,minecraft:nether_wart_block)
B(2,73,7,minecraft:nether_wart_block)
B(2,74,7,minecraft:nether_wart_block)
B(2,75,7,minecraft:nether_wart_block)
B(2,76,7,minecraft:nether_wart_block)
B(2,77,7,minecraft:nether_wart_block)
B(2,12,8,minecraft:nether_wart_block)
B(2,13,8,minecraft:nether_wart_block)
B(2,14,8,minecraft:nether_wart_block)
B(2,15,8,minecraft:nether_wart_block)
B(2,16,8,minecraft:nether_wart_block)
B(2,17,8,minecraft:nether_wart_block)
B(2,18,8,minecraft:nether_wart_block)
B(2,19,8,minecraft:nether_wart_block)
B(2,20,8,minecraft:nether_wart_block)
B(2,21,8,minecraft:nether_wart_block)
B(2,22,8,minecraft:nether_wart_block)
B(2,23,8,minecraft:nether_wart_block)
B(2,24,8,minecraft:nether_wart_block)
B(2,25,8,minecraft:nether_wart_block)
B(2,26,8,minecraft:nether_wart_block)
B(2,27,8,minecraft:nether_wart_block)
B(2,28,8,minecraft:nether_wart_block)
B(2,29,8,minecraft:nether_wart_block)
B(2,30,8,minecraft:nether_wart_block)
B(2,31,8,minecraft:nether_wart_block)
B(2,32,8,minecraft:nether_wart_block)
B(2,33,8,minecraft:nether_wart_block)
B(2,34,8,minecraft:nether_wart_block)
B(2,35,8,minecraft:nether_wart_block)
B(2,36,8,minecraft:nether_wart_block)
B(2,37,8,minecraft:nether_wart_block)
B(2,38,8,minecraft:nether_wart_block)
B(2,39,8,minecraft:nether_wart_block)
B(2,40,8,minecraft:nether_wart_block)
B(2,66,8,minecraft:nether_wart_block)
B(2,67,8,minecraft:nether_wart_block)
B(2,68,8,minecraft:nether_wart_block)
B(2,69,8,minecraft:nether_wart_block)
B(2,70,8,minecraft:nether_wart_block)
B(2,71,8,minecraft:nether_wart_block)
B(2,72,8,minecraft:nether_wart_block)
B(2,73,8,minecraft:nether_wart_block)
B(2,74,8,minecraft:nether_wart_block)
B(2,75,8,minecraft:nether_wart_block)
B(2,76,8,minecraft:nether_wart_block)
B(2,77,8,minecraft:nether_wart_block)
B(2,78,8,minecraft:nether_wart_block)
B(3,18,-6,minecraft:nether_wart_block)
B(3,19,-6,minecraft:nether_wart_block)
B(3,20,-6,minecraft:nether_wart_block)
B(3,17,-5,minecraft:nether_wart_block)
B(3,18,-5,minecraft:nether_wart_block)
B(3,19,-5,minecraft:nether_wart_block)
B(3,20,-5,minecraft:nether_wart_block)
B(3,21,-5,minecraft:nether_wart_block)
B(3,17,-4,minecraft:nether_wart_block)
B(3,18,-4,minecraft:nether_wart_block)
B(3,19,-4,minecraft:nether_wart_block)
B(3,20,-4,minecraft:nether_wart_block)
B(3,21,-4,minecraft:nether_wart_block)
B(3,17,-3,minecraft:nether_wart_block)
B(3,18,-3,minecraft:nether_wart_block)
B(3,19,-3,minecraft:nether_wart_block)
B(3,20,-3,minecraft:nether_wart_block)
B(3,21,-3,minecraft:nether_wart_block)
B(3,15,-2,minecraft:nether_wart_block)
B(3,16,-2,minecraft:nether_wart_block)
B(3,17,-2,minecraft:nether_wart_block)
B(3,18,-2,minecraft:nether_wart_block)
B(3,19,-2,minecraft:nether_wart_block)
B(3,20,-2,minecraft:nether_wart_block)
B(3,14,-1,minecraft:nether_wart_block)
B(3,15,-1,minecraft:nether_wart_block)
B(3,16,-1,minecraft:nether_wart_block)
B(3,17,-1,minecraft:nether_wart_block)
B(3,18,-1,minecraft:nether_wart_block)
B(3,19,-1,minecraft:nether_wart_block)
B(3,20,-1,minecraft:nether_wart_block)
B(3,14,0,minecraft:nether_wart_block)
B(3,15,0,minecraft:nether_wart_block)
B(3,16,0,minecraft:nether_wart_block)
B(3,17,0,minecraft:nether_wart_block)
B(3,18,0,minecraft:nether_wart_block)
B(3,19,0,minecraft:nether_wart_block)
B(3,20,0,minecraft:nether_wart_block)
B(3,14,1,minecraft:nether_wart_block)
B(3,15,1,minecraft:nether_wart_block)
B(3,16,1,minecraft:nether_wart_block)
B(3,17,1,minecraft:nether_wart_block)
B(3,18,1,minecraft:nether_wart_block)
B(3,19,1,minecraft:nether_wart_block)
B(3,20,1,minecraft:nether_wart_block)
B(3,33,1,minecraft:nether_wart_block)
B(3,34,1,minecraft:nether_wart_block)
B(3,35,1,minecraft:nether_wart_block)
B(3,36,1,minecraft:nether_wart_block)
B(3,37,1,minecraft:nether_wart_block)
B(3,13,2,minecraft:nether_wart_block)
B(3,14,2,minecraft:nether_wart_block)
B(3,15,2,minecraft:nether_wart_block)
B(3,16,2,minecraft:nether_wart_block)
B(3,17,2,minecraft:nether_wart_block)
B(3,18,2,minecraft:nether_wart_block)
B(3,19,2,minecraft:nether_wart_block)
B(3,20,2,minecraft:nether_wart_block)
B(3,32,2,minecraft:nether_wart_block)
B(3,33,2,minecraft:nether_wart_block)
B(3,34,2,minecraft:nether_wart_block)
B(3,35,2,minecraft:nether_wart_block)
B(3,36,2,minecraft:nether_wart_block)
B(3,37,2,minecraft:nether_wart_block)
B(3,38,2,minecraft:nether_wart_block)
B(3,12,3,minecraft:nether_wart_block)
B(3,13,3,minecraft:nether_wart_block)
B(3,14,3,minecraft:nether_wart_block)
B(3,15,3,minecraft:nether_wart_block)
B(3,16,3,minecraft:nether_wart_block)
B(3,17,3,minecraft:nether_wart_block)
B(3,18,3,minecraft:nether_wart_block)
B(3,19,3,minecraft:nether_wart_block)
B(3,20,3,minecraft:nether_wart_block)
B(3,31,3,minecraft:nether_wart_block)
B(3,32,3,minecraft:nether_wart_block)
B(3,33,3,minecraft:nether_wart_block)
B(3,34,3,minecraft:nether_wart_block)
B(3,35,3,minecraft:nether_wart_block)
B(3,36,3,minecraft:nether_wart_block)
B(3,37,3,minecraft:nether_wart_block)
B(3,38,3,minecraft:nether_wart_block)
B(3,39,3,minecraft:nether_wart_block)
B(3,11,4,minecraft:nether_wart_block)
B(3,12,4,minecraft:nether_wart_block)
B(3,13,4,minecraft:nether_wart_block)
B(3,14,4,minecraft:nether_wart_block)
B(3,15,4,minecraft:nether_wart_block)
B(3,16,4,minecraft:nether_wart_block)
B(3,17,4,minecraft:nether_wart_block)
B(3,18,4,minecraft:nether_wart_block)
B(3,19,4,minecraft:nether_wart_block)
B(3,29,4,minecraft:nether_wart_block)
B(3,30,4,minecraft:nether_wart_block)
B(3,31,4,minecraft:nether_wart_block)
B(3,32,4,minecraft:nether_wart_block)
B(3,33,4,minecraft:nether_wart_block)
B(3,34,4,minecraft:nether_wart_block)
B(3,35,4,minecraft:nether_wart_block)
B(3,36,4,minecraft:nether_wart_block)
B(3,37,4,minecraft:nether_wart_block)
B(3,38,4,minecraft:nether_wart_block)
B(3,39,4,minecraft:nether_wart_block)
B(3,40,4,minecraft:nether_wart_block)
B(3,11,5,minecraft:nether_wart_block)
B(3,12,5,minecraft:nether_wart_block)
B(3,13,5,minecraft:nether_wart_block)
B(3,14,5,minecraft:nether_wart_block)
B(3,15,5,minecraft:nether_wart_block)
B(3,16,5,minecraft:nether_wart_block)
B(3,17,5,minecraft:nether_wart_block)
B(3,18,5,minecraft:nether_wart_block)
B(3,19,5,minecraft:nether_wart_block)
B(3,25,5,minecraft:nether_wart_block)
B(3,26,5,minecraft:nether_wart_block)
B(3,27,5,minecraft:nether_wart_block)
B(3,28,5,minecraft:nether_wart_block)
B(3,29,5,minecraft:nether_wart_block)
B(3,30,5,minecraft:nether_wart_block)
B(3,31,5,minecraft:nether_wart_block)
B(3,32,5,minecraft:nether_wart_block)
B(3,33,5,minecraft:nether_wart_block)
B(3,34,5,minecraft:nether_wart_block)
B(3,35,5,minecraft:nether_wart_block)
B(3,36,5,minecraft:nether_wart_block)
B(3,37,5,minecraft:nether_wart_block)
B(3,38,5,minecraft:nether_wart_block)
B(3,39,5,minecraft:nether_wart_block)
B(3,40,5,minecraft:nether_wart_block)
B(3,68,5,minecraft:nether_wart_block)
B(3,69,5,minecraft:nether_wart_block)
B(3,70,5,minecraft:nether_wart_block)
B(3,71,5,minecraft:nether_wart_block)
B(3,72,5,minecraft:nether_wart_block)
B(3,11,6,minecraft:nether_wart_block)
B(3,12,6,minecraft:nether_wart_block)
B(3,13,6,minecraft:nether_wart_block)
B(3,14,6,minecraft:nether_wart_block)
B(3,15,6,minecraft:nether_wart_block)
B(3,16,6,minecraft:nether_wart_block)
B(3,17,6,minecraft:nether_wart_block)
B(3,18,6,minecraft:nether_wart_block)
B(3,19,6,minecraft:nether_wart_block)
B(3,23,6,minecraft:nether_wart_block)
B(3,24,6,minecraft:nether_wart_block)
B(3,25,6,minecraft:nether_wart_block)
B(3,26,6,minecraft:nether_wart_block)
B(3,27,6,minecraft:nether_wart_block)
B(3,28,6,minecraft:nether_wart_block)
B(3,29,6,minecraft:nether_wart_block)
B(3,30,6,minecraft:nether_wart_block)
B(3,31,6,minecraft:nether_wart_block)
B(3,32,6,minecraft:nether_wart_block)
B(3,33,6,minecraft:nether_wart_block)
B(3,34,6,minecraft:nether_wart_block)
B(3,35,6,minecraft:nether_wart_block)
B(3,36,6,minecraft:nether_wart_block)
B(3,37,6,minecraft:nether_wart_block)
B(3,38,6,minecraft:nether_wart_block)
B(3,39,6,minecraft:nether_wart_block)
B(3,40,6,minecraft:nether_wart_block)
B(3,67,6,minecraft:nether_wart_block)
B(3,68,6,minecraft:nether_wart_block)
B(3,69,6,minecraft:nether_wart_block)
B(3,70,6,minecraft:nether_wart_block)
B(3,71,6,minecraft:nether_wart_block)
B(3,72,6,minecraft:nether_wart_block)
B(3,73,6,minecraft:nether_wart_block)
B(3,74,6,minecraft:nether_wart_block)
B(3,0,7,minecraft:nether_wart_block)
B(3,1,7,minecraft:nether_wart_block)
B(3,2,7,minecraft:nether_wart_block)
B(3,5,7,minecraft:nether_wart_block)
B(3,6,7,minecraft:nether_wart_block)
B(3,7,7,minecraft:nether_wart_block)
B(3,11,7,minecraft:nether_wart_block)
B(3,12,7,minecraft:nether_wart_block)
B(3,13,7,minecraft:nether_wart_block)
B(3,14,7,minecraft:nether_wart_block)
B(3,15,7,minecraft:nether_wart_block)
B(3,16,7,minecraft:nether_wart_block)
B(3,17,7,minecraft:nether_wart_block)
B(3,18,7,minecraft:nether_wart_block)
B(3,19,7,minecraft:nether_wart_block)
B(3,20,7,minecraft:nether_wart_block)
B(3,21,7,minecraft:nether_wart_block)
B(3,22,7,minecraft:nether_wart_block)
B(3,23,7,minecraft:nether_wart_block)
B(3,24,7,minecraft:nether_wart_block)
B(3,25,7,minecraft:nether_wart_block)
B(3,26,7,minecraft:nether_wart_block)
B(3,27,7,minecraft:nether_wart_block)
B(3,28,7,minecraft:nether_wart_block)
B(3,29,7,minecraft:nether_wart_block)
B(3,30,7,minecraft:nether_wart_block)
B(3,31,7,minecraft:nether_wart_block)
B(3,32,7,minecraft:nether_wart_block)
B(3,33,7,minecraft:nether_wart_block)
B(3,34,7,minecraft:nether_wart_block)
B(3,35,7,minecraft:nether_wart_block)
B(3,36,7,minecraft:nether_wart_block)
B(3,37,7,minecraft:nether_wart_block)
B(3,38,7,minecraft:nether_wart_block)
B(3,39,7,minecraft:nether_wart_block)
B(3,40,7,minecraft:nether_wart_block)
B(3,66,7,minecraft:nether_wart_block)
B(3,67,7,minecraft:nether_wart_block)
B(3,68,7,minecraft:nether_wart_block)
B(3,69,7,minecraft:nether_wart_block)
B(3,70,7,minecraft:nether_wart_block)
B(3,71,7,minecraft:nether_wart_block)
B(3,72,7,minecraft:nether_wart_block)
B(3,73,7,minecraft:nether_wart_block)
B(3,74,7,minecraft:nether_wart_block)
B(3,75,7,minecraft:nether_wart_block)
B(3,0,8,minecraft:nether_wart_block)
B(3,1,8,minecraft:nether_wart_block)
B(3,2,8,minecraft:nether_wart_block)
B(3,3,8,minecraft:nether_wart_block)
B(3,4,8,minecraft:nether_wart_block)
B(3,5,8,minecraft:nether_wart_block)
B(3,6,8,minecraft:nether_wart_block)
B(3,7,8,minecraft:nether_wart_block)
B(3,8,8,minecraft:nether_wart_block)
B(3,10,8,minecraft:nether_wart_block)
B(3,11,8,minecraft:nether_wart_block)
B(3,12,8,minecraft:nether_wart_block)
B(3,13,8,minecraft:nether_wart_block)
B(3,14,8,minecraft:nether_wart_block)
B(3,15,8,minecraft:nether_wart_block)
B(3,16,8,minecraft:nether_wart_block)
B(3,17,8,minecraft:nether_wart_block)
B(3,18,8,minecraft:nether_wart_block)
B(3,19,8,minecraft:nether_wart_block)
B(3,20,8,minecraft:nether_wart_block)
B(3,21,8,minecraft:nether_wart_block)
B(3,22,8,minecraft:nether_wart_block)
B(3,23,8,minecraft:nether_wart_block)
B(3,24,8,minecraft:nether_wart_block)
B(3,25,8,minecraft:nether_wart_block)
B(3,26,8,minecraft:nether_wart_block)
B(3,27,8,minecraft:nether_wart_block)
B(3,28,8,minecraft:nether_wart_block)
B(3,29,8,minecraft:nether_wart_block)
B(3,30,8,minecraft:nether_wart_block)
B(3,31,8,minecraft:nether_wart_block)
B(3,32,8,minecraft:nether_wart_block)
B(3,33,8,minecraft:nether_wart_block)
B(3,34,8,minecraft:nether_wart_block)
B(3,35,8,minecraft:nether_wart_block)
B(3,36,8,minecraft:nether_wart_block)
B(3,37,8,minecraft:nether_wart_block)
B(3,38,8,minecraft:nether_wart_block)
B(3,39,8,minecraft:nether_wart_block)
B(3,40,8,minecraft:nether_wart_block)
B(3,66,8,minecraft:nether_wart_block)
B(3,67,8,minecraft:nether_wart_block)
B(3,68,8,minecraft:nether_wart_block)
B(3,69,8,minecraft:nether_wart_block)
B(3,70,8,minecraft:nether_wart_block)
B(3,71,8,minecraft:nether_wart_block)
B(3,72,8,minecraft:nether_wart_block)
B(3,73,8,minecraft:nether_wart_block)
B(3,74,8,minecraft:nether_wart_block)
B(3,75,8,minecraft:nether_wart_block)
B(3,76,8,minecraft:nether_wart_block)
B(4,17,-7,minecraft:nether_wart_block)
B(4,18,-7,minecraft:nether_wart_block)
B(4,19,-7,minecraft:nether_wart_block)
B(4,20,-7,minecraft:nether_wart_block)
B(4,21,-7,minecraft:nether_wart_block)
B(4,16,-6,minecraft:nether_wart_block)
B(4,17,-6,minecraft:nether_wart_block)
B(4,18,-6,minecraft:nether_wart_block)
B(4,19,-6,minecraft:nether_wart_block)
B(4,20,-6,minecraft:nether_wart_block)
B(4,21,-6,minecraft:nether_wart_block)
B(4,22,-6,minecraft:nether_wart_block)
B(4,16,-5,minecraft:nether_wart_block)
B(4,17,-5,minecraft:nether_wart_block)
B(4,18,-5,minecraft:nether_wart_block)
B(4,19,-5,minecraft:nether_wart_block)
B(4,20,-5,minecraft:nether_wart_block)
B(4,21,-5,minecraft:nether_wart_block)
B(4,22,-5,minecraft:nether_wart_block)
B(4,16,-4,minecraft:nether_wart_block)
B(4,17,-4,minecraft:nether_wart_block)
B(4,18,-4,minecraft:nether_wart_block)
B(4,19,-4,minecraft:nether_wart_block)
B(4,20,-4,minecraft:nether_wart_block)
B(4,21,-4,minecraft:nether_wart_block)
B(4,22,-4,minecraft:nether_wart_block)
B(4,15,-3,minecraft:nether_wart_block)
B(4,16,-3,minecraft:nether_wart_block)
B(4,17,-3,minecraft:nether_wart_block)
B(4,18,-3,minecraft:nether_wart_block)
B(4,19,-3,minecraft:nether_wart_block)
B(4,20,-3,minecraft:nether_wart_block)
B(4,21,-3,minecraft:nether_wart_block)
B(4,22,-3,minecraft:nether_wart_block)
B(4,14,-2,minecraft:nether_wart_block)
B(4,15,-2,minecraft:nether_wart_block)
B(4,16,-2,minecraft:nether_wart_block)
B(4,17,-2,minecraft:nether_wart_block)
B(4,18,-2,minecraft:nether_wart_block)
B(4,19,-2,minecraft:nether_wart_block)
B(4,20,-2,minecraft:nether_wart_block)
B(4,21,-2,minecraft:nether_wart_block)
B(4,22,-2,minecraft:nether_wart_block)
B(4,13,-1,minecraft:nether_wart_block)
B(4,14,-1,minecraft:nether_wart_block)
B(4,15,-1,minecraft:nether_wart_block)
B(4,16,-1,minecraft:nether_wart_block)
B(4,17,-1,minecraft:nether_wart_block)
B(4,18,-1,minecraft:nether_wart_block)
B(4,19,-1,minecraft:nether_wart_block)
B(4,20,-1,minecraft:nether_wart_block)
B(4,21,-1,minecraft:nether_wart_block)
B(4,13,0,minecraft:nether_wart_block)
B(4,14,0,minecraft:nether_wart_block)
B(4,15,0,minecraft:nether_wart_block)
B(4,16,0,minecraft:nether_wart_block)
B(4,17,0,minecraft:nether_wart_block)
B(4,18,0,minecraft:nether_wart_block)
B(4,19,0,minecraft:nether_wart_block)
B(4,20,0,minecraft:nether_wart_block)
B(4,21,0,minecraft:nether_wart_block)
B(4,13,1,minecraft:nether_wart_block)
B(4,14,1,minecraft:nether_wart_block)
B(4,15,1,minecraft:nether_wart_block)
B(4,16,1,minecraft:nether_wart_block)
B(4,17,1,minecraft:nether_wart_block)
B(4,18,1,minecraft:nether_wart_block)
B(4,19,1,minecraft:nether_wart_block)
B(4,20,1,minecraft:nether_wart_block)
B(4,21,1,minecraft:nether_wart_block)
B(4,33,1,minecraft:nether_wart_block)
B(4,34,1,minecraft:nether_wart_block)
B(4,35,1,minecraft:nether_wart_block)
B(4,36,1,minecraft:nether_wart_block)
B(4,37,1,minecraft:nether_wart_block)
B(4,38,1,minecraft:nether_wart_block)
B(4,12,2,minecraft:nether_wart_block)
B(4,13,2,minecraft:nether_wart_block)
B(4,14,2,minecraft:nether_wart_block)
B(4,15,2,minecraft:nether_wart_block)
B(4,16,2,minecraft:nether_wart_block)
B(4,17,2,minecraft:nether_wart_block)
B(4,18,2,minecraft:nether_wart_block)
B(4,19,2,minecraft:nether_wart_block)
B(4,20,2,minecraft:nether_wart_block)
B(4,21,2,minecraft:nether_wart_block)
B(4,32,2,minecraft:nether_wart_block)
B(4,33,2,minecraft:nether_wart_block)
B(4,34,2,minecraft:nether_wart_block)
B(4,35,2,minecraft:nether_wart_block)
B(4,36,2,minecraft:nether_wart_block)
B(4,37,2,minecraft:nether_wart_block)
B(4,38,2,minecraft:nether_wart_block)
B(4,39,2,minecraft:nether_wart_block)
B(4,11,3,minecraft:nether_wart_block)
B(4,12,3,minecraft:nether_wart_block)
B(4,13,3,minecraft:nether_wart_block)
B(4,14,3,minecraft:nether_wart_block)
B(4,15,3,minecraft:nether_wart_block)
B(4,16,3,minecraft:nether_wart_block)
B(4,17,3,minecraft:nether_wart_block)
B(4,18,3,minecraft:nether_wart_block)
B(4,19,3,minecraft:nether_wart_block)
B(4,20,3,minecraft:nether_wart_block)
B(4,21,3,minecraft:nether_wart_block)
B(4,31,3,minecraft:nether_wart_block)
B(4,32,3,minecraft:nether_wart_block)
B(4,33,3,minecraft:nether_wart_block)
B(4,34,3,minecraft:nether_wart_block)
B(4,35,3,minecraft:nether_wart_block)
B(4,36,3,minecraft:nether_wart_block)
B(4,37,3,minecraft:nether_wart_block)
B(4,38,3,minecraft:nether_wart_block)
B(4,39,3,minecraft:nether_wart_block)
B(4,11,4,minecraft:nether_wart_block)
B(4,12,4,minecraft:nether_wart_block)
B(4,13,4,minecraft:nether_wart_block)
B(4,14,4,minecraft:nether_wart_block)
B(4,15,4,minecraft:nether_wart_block)
B(4,16,4,minecraft:nether_wart_block)
B(4,17,4,minecraft:nether_wart_block)
B(4,18,4,minecraft:nether_wart_block)
B(4,19,4,minecraft:nether_wart_block)
B(4,20,4,minecraft:nether_wart_block)
B(4,29,4,minecraft:nether_wart_block)
B(4,30,4,minecraft:nether_wart_block)
B(4,31,4,minecraft:nether_wart_block)
B(4,32,4,minecraft:nether_wart_block)
B(4,33,4,minecraft:nether_wart_block)
B(4,34,4,minecraft:nether_wart_block)
B(4,35,4,minecraft:nether_wart_block)
B(4,36,4,minecraft:nether_wart_block)
B(4,37,4,minecraft:nether_wart_block)
B(4,38,4,minecraft:nether_wart_block)
B(4,39,4,minecraft:nether_wart_block)
B(4,40,4,minecraft:nether_wart_block)
B(4,69,4,minecraft:nether_wart_block)
B(4,70,4,minecraft:nether_wart_block)
B(4,71,4,minecraft:nether_wart_block)
B(4,10,5,minecraft:nether_wart_block)
B(4,11,5,minecraft:nether_wart_block)
B(4,12,5,minecraft:nether_wart_block)
B(4,13,5,minecraft:nether_wart_block)
B(4,14,5,minecraft:nether_wart_block)
B(4,15,5,minecraft:nether_wart_block)
B(4,16,5,minecraft:nether_wart_block)
B(4,17,5,minecraft:nether_wart_block)
B(4,18,5,minecraft:nether_wart_block)
B(4,19,5,minecraft:nether_wart_block)
B(4,20,5,minecraft:nether_wart_block)
B(4,24,5,minecraft:nether_wart_block)
B(4,25,5,minecraft:nether_wart_block)
B(4,26,5,minecraft:nether_wart_block)
B(4,27,5,minecraft:nether_wart_block)
B(4,28,5,minecraft:nether_wart_block)
B(4,29,5,minecraft:nether_wart_block)
B(4,30,5,minecraft:nether_wart_block)
B(4,31,5,minecraft:nether_wart_block)
B(4,32,5,minecraft:nether_wart_block)
B(4,33,5,minecraft:nether_wart_block)
B(4,34,5,minecraft:nether_wart_block)
B(4,35,5,minecraft:nether_wart_block)
B(4,36,5,minecraft:nether_wart_block)
B(4,37,5,minecraft:nether_wart_block)
B(4,38,5,minecraft:nether_wart_block)
B(4,39,5,minecraft:nether_wart_block)
B(4,40,5,minecraft:nether_wart_block)
B(4,67,5,minecraft:nether_wart_block)
B(4,68,5,minecraft:nether_wart_block)
B(4,69,5,minecraft:nether_wart_block)
B(4,70,5,minecraft:nether_wart_block)
B(4,71,5,minecraft:nether_wart_block)
B(4,72,5,minecraft:nether_wart_block)
B(4,73,5,minecraft:nether_wart_block)
B(4,0,6,minecraft:nether_wart_block)
B(4,1,6,minecraft:nether_wart_block)
B(4,2,6,minecraft:nether_wart_block)
B(4,3,6,minecraft:nether_wart_block)
B(4,4,6,minecraft:nether_wart_block)
B(4,5,6,minecraft:nether_wart_block)
B(4,6,6,minecraft:nether_wart_block)
B(4,7,6,minecraft:nether_wart_block)
B(4,8,6,minecraft:nether_wart_block)
B(4,10,6,minecraft:nether_wart_block)
B(4,11,6,minecraft:nether_wart_block)
B(4,12,6,minecraft:nether_wart_block)
B(4,13,6,minecraft:nether_wart_block)
B(4,14,6,minecraft:nether_wart_block)
B(4,15,6,minecraft:nether_wart_block)
B(4,16,6,minecraft:nether_wart_block)
B(4,17,6,minecraft:nether_wart_block)
B(4,18,6,minecraft:nether_wart_block)
B(4,19,6,minecraft:nether_wart_block)
B(4,20,6,minecraft:nether_wart_block)
B(4,21,6,minecraft:nether_wart_block)
B(4,22,6,minecraft:nether_wart_block)
B(4,23,6,minecraft:nether_wart_block)
B(4,24,6,minecraft:nether_wart_block)
B(4,25,6,minecraft:nether_wart_block)
B(4,26,6,minecraft:nether_wart_block)
B(4,27,6,minecraft:nether_wart_block)
B(4,28,6,minecraft:nether_wart_block)
B(4,29,6,minecraft:nether_wart_block)
B(4,30,6,minecraft:nether_wart_block)
B(4,31,6,minecraft:nether_wart_block)
B(4,32,6,minecraft:nether_wart_block)
B(4,33,6,minecraft:nether_wart_block)
B(4,34,6,minecraft:nether_wart_block)
B(4,35,6,minecraft:nether_wart_block)
B(4,36,6,minecraft:nether_wart_block)
B(4,37,6,minecraft:nether_wart_block)
B(4,38,6,minecraft:nether_wart_block)
B(4,39,6,minecraft:nether_wart_block)
B(4,40,6,minecraft:nether_wart_block)
B(4,66,6,minecraft:nether_wart_block)
B(4,67,6,minecraft:nether_wart_block)
B(4,68,6,minecraft:nether_wart_block)
B(4,69,6,minecraft:nether_wart_block)
B(4,70,6,minecraft:nether_wart_block)
B(4,71,6,minecraft:nether_wart_block)
B(4,72,6,minecraft:nether_wart_block)
B(4,73,6,minecraft:nether_wart_block)
B(4,74,6,minecraft:nether_wart_block)
B(4,0,7,minecraft:nether_wart_block)
B(4,1,7,minecraft:nether_wart_block)
B(4,2,7,minecraft:nether_wart_block)
B(4,3,7,minecraft:nether_wart_block)
B(4,4,7,minecraft:nether_wart_block)
B(4,5,7,minecraft:nether_wart_block)
B(4,6,7,minecraft:nether_wart_block)
B(4,7,7,minecraft:nether_wart_block)
B(4,8,7,minecraft:nether_wart_block)
B(4,9,7,minecraft:nether_wart_block)
B(4,10,7,minecraft:nether_wart_block)
B(4,11,7,minecraft:nether_wart_block)
B(4,12,7,minecraft:nether_wart_block)
B(4,13,7,minecraft:nether_wart_block)
B(4,14,7,minecraft:nether_wart_block)
B(4,15,7,minecraft:nether_wart_block)
B(4,16,7,minecraft:nether_wart_block)
B(4,17,7,minecraft:nether_wart_block)
B(4,18,7,minecraft:nether_wart_block)
B(4,19,7,minecraft:nether_wart_block)
B(4,20,7,minecraft:nether_wart_block)
B(4,21,7,minecraft:nether_wart_block)
B(4,22,7,minecraft:nether_wart_block)
B(4,23,7,minecraft:nether_wart_block)
B(4,24,7,minecraft:nether_wart_block)
B(4,25,7,minecraft:nether_wart_block)
B(4,26,7,minecraft:nether_wart_block)
B(4,27,7,minecraft:nether_wart_block)
B(4,28,7,minecraft:nether_wart_block)
B(4,29,7,minecraft:nether_wart_block)
B(4,30,7,minecraft:nether_wart_block)
B(4,31,7,minecraft:nether_wart_block)
B(4,32,7,minecraft:nether_wart_block)
B(4,33,7,minecraft:nether_wart_block)
B(4,34,7,minecraft:nether_wart_block)
B(4,35,7,minecraft:nether_wart_block)
B(4,36,7,minecraft:nether_wart_block)
B(4,37,7,minecraft:nether_wart_block)
B(4,38,7,minecraft:nether_wart_block)
B(4,39,7,minecraft:nether_wart_block)
B(4,40,7,minecraft:nether_wart_block)
B(4,66,7,minecraft:nether_wart_block)
B(4,67,7,minecraft:nether_wart_block)
B(4,68,7,minecraft:nether_wart_block)
B(4,69,7,minecraft:nether_wart_block)
B(4,70,7,minecraft:nether_wart_block)
B(4,71,7,minecraft:nether_wart_block)
B(4,72,7,minecraft:nether_wart_block)
B(4,73,7,minecraft:nether_wart_block)
B(4,74,7,minecraft:nether_wart_block)
B(4,0,8,minecraft:nether_wart_block)
B(4,1,8,minecraft:nether_wart_block)
B(4,2,8,minecraft:nether_wart_block)
B(4,3,8,minecraft:nether_wart_block)
B(4,4,8,minecraft:nether_wart_block)
B(4,5,8,minecraft:nether_wart_block)
B(4,6,8,minecraft:nether_wart_block)
B(4,7,8,minecraft:nether_wart_block)
B(4,8,8,minecraft:nether_wart_block)
B(4,9,8,minecraft:nether_wart_block)
B(4,10,8,minecraft:nether_wart_block)
B(4,11,8,minecraft:nether_wart_block)
B(4,12,8,minecraft:nether_wart_block)
B(4,13,8,minecraft:nether_wart_block)
B(4,14,8,minecraft:nether_wart_block)
B(4,15,8,minecraft:nether_wart_block)
B(4,16,8,minecraft:nether_wart_block)
B(4,17,8,minecraft:nether_wart_block)
B(4,18,8,minecraft:nether_wart_block)
B(4,19,8,minecraft:nether_wart_block)
B(4,20,8,minecraft:nether_wart_block)
B(4,21,8,minecraft:nether_wart_block)
B(4,22,8,minecraft:nether_wart_block)
B(4,23,8,minecraft:nether_wart_block)
B(4,24,8,minecraft:nether_wart_block)
B(4,25,8,minecraft:nether_wart_block)
B(4,26,8,minecraft:nether_wart_block)
B(4,27,8,minecraft:nether_wart_block)
B(4,28,8,minecraft:nether_wart_block)
B(4,29,8,minecraft:nether_wart_block)
B(4,30,8,minecraft:nether_wart_block)
B(4,31,8,minecraft:nether_wart_block)
B(4,32,8,minecraft:nether_wart_block)
B(4,33,8,minecraft:nether_wart_block)
B(4,34,8,minecraft:nether_wart_block)
B(4,35,8,minecraft:nether_wart_block)
B(4,36,8,minecraft:nether_wart_block)
B(4,37,8,minecraft:nether_wart_block)
B(4,38,8,minecraft:nether_wart_block)
B(4,39,8,minecraft:nether_wart_block)
B(4,40,8,minecraft:nether_wart_block)
B(4,65,8,minecraft:nether_wart_block)
B(4,66,8,minecraft:nether_wart_block)
B(4,67,8,minecraft:nether_wart_block)
B(4,68,8,minecraft:nether_wart_block)
B(4,69,8,minecraft:nether_wart_block)
B(4,70,8,minecraft:nether_wart_block)
B(4,71,8,minecraft:nether_wart_block)
B(4,72,8,minecraft:nether_wart_block)
B(4,73,8,minecraft:nether_wart_block)
B(4,74,8,minecraft:nether_wart_block)
B(4,75,8,minecraft:nether_wart_block)
B(5,16,-7,minecraft:nether_wart_block)
B(5,17,-7,minecraft:nether_wart_block)
B(5,18,-7,minecraft:nether_wart_block)
B(5,19,-7,minecraft:nether_wart_block)
B(5,20,-7,minecraft:nether_wart_block)
B(5,21,-7,minecraft:nether_wart_block)
B(5,22,-7,minecraft:nether_wart_block)
B(5,15,-6,minecraft:nether_wart_block)
B(5,16,-6,minecraft:nether_wart_block)
B(5,17,-6,minecraft:nether_wart_block)
B(5,18,-6,minecraft:nether_wart_block)
B(5,19,-6,minecraft:nether_wart_block)
B(5,20,-6,minecraft:nether_wart_block)
B(5,21,-6,minecraft:nether_wart_block)
B(5,22,-6,minecraft:nether_wart_block)
B(5,23,-6,minecraft:nether_wart_block)
B(5,15,-5,minecraft:nether_wart_block)
B(5,16,-5,minecraft:nether_wart_block)
B(5,17,-5,minecraft:nether_wart_block)
B(5,18,-5,minecraft:nether_wart_block)
B(5,19,-5,minecraft:nether_wart_block)
B(5,20,-5,minecraft:nether_wart_block)
B(5,21,-5,minecraft:nether_wart_block)
B(5,22,-5,minecraft:nether_wart_block)
B(5,23,-5,minecraft:nether_wart_block)
B(5,15,-4,minecraft:nether_wart_block)
B(5,16,-4,minecraft:nether_wart_block)
B(5,17,-4,minecraft:nether_wart_block)
B(5,18,-4,minecraft:nether_wart_block)
B(5,19,-4,minecraft:nether_wart_block)
B(5,20,-4,minecraft:nether_wart_block)
B(5,21,-4,minecraft:nether_wart_block)
B(5,22,-4,minecraft:nether_wart_block)
B(5,23,-4,minecraft:nether_wart_block)
B(5,14,-3,minecraft:nether_wart_block)
B(5,15,-3,minecraft:nether_wart_block)
B(5,16,-3,minecraft:nether_wart_block)
B(5,17,-3,minecraft:nether_wart_block)
B(5,18,-3,minecraft:nether_wart_block)
B(5,19,-3,minecraft:nether_wart_block)
B(5,20,-3,minecraft:nether_wart_block)
B(5,21,-3,minecraft:nether_wart_block)
B(5,22,-3,minecraft:nether_wart_block)
B(5,23,-3,minecraft:nether_wart_block)
B(5,13,-2,minecraft:nether_wart_block)
B(5,14,-2,minecraft:nether_wart_block)
B(5,15,-2,minecraft:nether_wart_block)
B(5,16,-2,minecraft:nether_wart_block)
B(5,17,-2,minecraft:nether_wart_block)
B(5,18,-2,minecraft:nether_wart_block)
B(5,19,-2,minecraft:nether_wart_block)
B(5,20,-2,minecraft:nether_wart_block)
B(5,21,-2,minecraft:nether_wart_block)
B(5,22,-2,minecraft:nether_wart_block)
B(5,23,-2,minecraft:nether_wart_block)
B(5,13,-1,minecraft:nether_wart_block)
B(5,14,-1,minecraft:nether_wart_block)
B(5,15,-1,minecraft:nether_wart_block)
B(5,16,-1,minecraft:nether_wart_block)
B(5,17,-1,minecraft:nether_wart_block)
B(5,18,-1,minecraft:nether_wart_block)
B(5,19,-1,minecraft:nether_wart_block)
B(5,20,-1,minecraft:nether_wart_block)
B(5,21,-1,minecraft:nether_wart_block)
B(5,22,-1,minecraft:nether_wart_block)
B(5,12,0,minecraft:nether_wart_block)
B(5,13,0,minecraft:nether_wart_block)
B(5,14,0,minecraft:nether_wart_block)
B(5,15,0,minecraft:nether_wart_block)
B(5,16,0,minecraft:nether_wart_block)
B(5,17,0,minecraft:nether_wart_block)
B(5,18,0,minecraft:nether_wart_block)
B(5,19,0,minecraft:nether_wart_block)
B(5,20,0,minecraft:nether_wart_block)
B(5,21,0,minecraft:nether_wart_block)
B(5,22,0,minecraft:nether_wart_block)
B(5,34,0,minecraft:nether_wart_block)
B(5,35,0,minecraft:nether_wart_block)
B(5,36,0,minecraft:nether_wart_block)
B(5,37,0,minecraft:nether_wart_block)
B(5,38,0,minecraft:nether_wart_block)
B(5,12,1,minecraft:nether_wart_block)
B(5,13,1,minecraft:nether_wart_block)
B(5,14,1,minecraft:nether_wart_block)
B(5,15,1,minecraft:nether_wart_block)
B(5,16,1,minecraft:nether_wart_block)
B(5,17,1,minecraft:nether_wart_block)
B(5,18,1,minecraft:nether_wart_block)
B(5,19,1,minecraft:nether_wart_block)
B(5,20,1,minecraft:nether_wart_block)
B(5,21,1,minecraft:nether_wart_block)
B(5,22,1,minecraft:nether_wart_block)
B(5,33,1,minecraft:nether_wart_block)
B(5,34,1,minecraft:nether_wart_block)
B(5,35,1,minecraft:nether_wart_block)
B(5,36,1,minecraft:nether_wart_block)
B(5,37,1,minecraft:nether_wart_block)
B(5,38,1,minecraft:nether_wart_block)
B(5,39,1,minecraft:nether_wart_block)
B(5,12,2,minecraft:nether_wart_block)
B(5,13,2,minecraft:nether_wart_block)
B(5,14,2,minecraft:nether_wart_block)
B(5,15,2,minecraft:nether_wart_block)
B(5,16,2,minecraft:nether_wart_block)
B(5,17,2,minecraft:nether_wart_block)
B(5,18,2,minecraft:nether_wart_block)
B(5,19,2,minecraft:nether_wart_block)
B(5,20,2,minecraft:nether_wart_block)
B(5,21,2,minecraft:nether_wart_block)
B(5,22,2,minecraft:nether_wart_block)
B(5,32,2,minecraft:nether_wart_block)
B(5,33,2,minecraft:nether_wart_block)
B(5,34,2,minecraft:nether_wart_block)
B(5,35,2,minecraft:nether_wart_block)
B(5,36,2,minecraft:nether_wart_block)
B(5,37,2,minecraft:nether_wart_block)
B(5,38,2,minecraft:nether_wart_block)
B(5,39,2,minecraft:nether_wart_block)
B(5,40,2,minecraft:nether_wart_block)
B(5,11,3,minecraft:nether_wart_block)
B(5,12,3,minecraft:nether_wart_block)
B(5,13,3,minecraft:nether_wart_block)
B(5,14,3,minecraft:nether_wart_block)
B(5,15,3,minecraft:nether_wart_block)
B(5,16,3,minecraft:nether_wart_block)
B(5,17,3,minecraft:nether_wart_block)
B(5,18,3,minecraft:nether_wart_block)
B(5,19,3,minecraft:nether_wart_block)
B(5,20,3,minecraft:nether_wart_block)
B(5,21,3,minecraft:nether_wart_block)
B(5,31,3,minecraft:nether_wart_block)
B(5,32,3,minecraft:nether_wart_block)
B(5,33,3,minecraft:nether_wart_block)
B(5,34,3,minecraft:nether_wart_block)
B(5,35,3,minecraft:nether_wart_block)
B(5,36,3,minecraft:nether_wart_block)
B(5,37,3,minecraft:nether_wart_block)
B(5,38,3,minecraft:nether_wart_block)
B(5,39,3,minecraft:nether_wart_block)
B(5,40,3,minecraft:nether_wart_block)
B(5,10,4,minecraft:nether_wart_block)
B(5,11,4,minecraft:nether_wart_block)
B(5,12,4,minecraft:nether_wart_block)
B(5,13,4,minecraft:nether_wart_block)
B(5,14,4,minecraft:nether_wart_block)
B(5,15,4,minecraft:nether_wart_block)
B(5,16,4,minecraft:nether_wart_block)
B(5,17,4,minecraft:nether_wart_block)
B(5,18,4,minecraft:nether_wart_block)
B(5,19,4,minecraft:nether_wart_block)
B(5,20,4,minecraft:nether_wart_block)
B(5,21,4,minecraft:nether_wart_block)
B(5,30,4,minecraft:nether_wart_block)
B(5,31,4,minecraft:nether_wart_block)
B(5,32,4,minecraft:nether_wart_block)
B(5,33,4,minecraft:nether_wart_block)
B(5,34,4,minecraft:nether_wart_block)
B(5,35,4,minecraft:nether_wart_block)
B(5,36,4,minecraft:nether_wart_block)
B(5,37,4,minecraft:nether_wart_block)
B(5,38,4,minecraft:nether_wart_block)
B(5,39,4,minecraft:nether_wart_block)
B(5,40,4,minecraft:nether_wart_block)
B(5,68,4,minecraft:nether_wart_block)
B(5,69,4,minecraft:nether_wart_block)
B(5,70,4,minecraft:nether_wart_block)
B(5,71,4,minecraft:nether_wart_block)
B(5,72,4,minecraft:nether_wart_block)
B(5,0,5,minecraft:nether_wart_block)
B(5,1,5,minecraft:nether_wart_block)
B(5,2,5,minecraft:nether_wart_block)
B(5,3,5,minecraft:nether_wart_block)
B(5,4,5,minecraft:nether_wart_block)
B(5,5,5,minecraft:nether_wart_block)
B(5,6,5,minecraft:nether_wart_block)
B(5,7,5,minecraft:nether_wart_block)
B(5,8,5,minecraft:nether_wart_block)
B(5,10,5,minecraft:nether_wart_block)
B(5,11,5,minecraft:nether_wart_block)
B(5,12,5,minecraft:nether_wart_block)
B(5,13,5,minecraft:nether_wart_block)
B(5,14,5,minecraft:nether_wart_block)
B(5,15,5,minecraft:nether_wart_block)
B(5,16,5,minecraft:nether_wart_block)
B(5,17,5,minecraft:nether_wart_block)
B(5,18,5,minecraft:nether_wart_block)
B(5,19,5,minecraft:nether_wart_block)
B(5,20,5,minecraft:nether_wart_block)
B(5,24,5,minecraft:nether_wart_block)
B(5,25,5,minecraft:nether_wart_block)
B(5,26,5,minecraft:nether_wart_block)
B(5,27,5,minecraft:nether_wart_block)
B(5,28,5,minecraft:nether_wart_block)
B(5,29,5,minecraft:nether_wart_block)
B(5,30,5,minecraft:nether_wart_block)
B(5,31,5,minecraft:nether_wart_block)
B(5,32,5,minecraft:nether_wart_block)
B(5,33,5,minecraft:nether_wart_block)
B(5,34,5,minecraft:nether_wart_block)
B(5,35,5,minecraft:nether_wart_block)
B(5,36,5,minecraft:nether_wart_block)
B(5,37,5,minecraft:nether_wart_block)
B(5,38,5,minecraft:nether_wart_block)
B(5,39,5,minecraft:nether_wart_block)
B(5,40,5,minecraft:nether_wart_block)
B(5,67,5,minecraft:nether_wart_block)
B(5,68,5,minecraft:nether_wart_block)
B(5,69,5,minecraft:nether_wart_block)
B(5,70,5,minecraft:nether_wart_block)
B(5,71,5,minecraft:nether_wart_block)
B(5,72,5,minecraft:nether_wart_block)
B(5,73,5,minecraft:nether_wart_block)
B(5,0,6,minecraft:nether_wart_block)
B(5,1,6,minecraft:nether_wart_block)
B(5,2,6,minecraft:nether_wart_block)
B(5,3,6,minecraft:nether_wart_block)
B(5,4,6,minecraft:nether_wart_block)
B(5,5,6,minecraft:nether_wart_block)
B(5,6,6,minecraft:nether_wart_block)
B(5,7,6,minecraft:nether_wart_block)
B(5,8,6,minecraft:nether_wart_block)
B(5,9,6,minecraft:nether_wart_block)
B(5,10,6,minecraft:nether_wart_block)
B(5,11,6,minecraft:nether_wart_block)
B(5,12,6,minecraft:nether_wart_block)
B(5,13,6,minecraft:nether_wart_block)
B(5,14,6,minecraft:nether_wart_block)
B(5,15,6,minecraft:nether_wart_block)
B(5,16,6,minecraft:nether_wart_block)
B(5,17,6,minecraft:nether_wart_block)
B(5,18,6,minecraft:nether_wart_block)
B(5,19,6,minecraft:nether_wart_block)
B(5,20,6,minecraft:nether_wart_block)
B(5,21,6,minecraft:nether_wart_block)
B(5,22,6,minecraft:nether_wart_block)
B(5,23,6,minecraft:nether_wart_block)
B(5,24,6,minecraft:nether_wart_block)
B(5,25,6,minecraft:nether_wart_block)
B(5,26,6,minecraft:nether_wart_block)
B(5,27,6,minecraft:nether_wart_block)
B(5,28,6,minecraft:nether_wart_block)
B(5,29,6,minecraft:nether_wart_block)
B(5,30,6,minecraft:nether_wart_block)
B(5,31,6,minecraft:nether_wart_block)
B(5,32,6,minecraft:nether_wart_block)
B(5,33,6,minecraft:nether_wart_block)
B(5,34,6,minecraft:nether_wart_block)
B(5,35,6,minecraft:nether_wart_block)
B(5,36,6,minecraft:nether_wart_block)
B(5,37,6,minecraft:nether_wart_block)
B(5,38,6,minecraft:nether_wart_block)
B(5,39,6,minecraft:nether_wart_block)
B(5,40,6,minecraft:nether_wart_block)
B(5,66,6,minecraft:nether_wart_block)
B(5,67,6,minecraft:nether_wart_block)
B(5,68,6,minecraft:nether_wart_block)
B(5,69,6,minecraft:nether_wart_block)
B(5,70,6,minecraft:nether_wart_block)
B(5,71,6,minecraft:nether_wart_block)
B(5,72,6,minecraft:nether_wart_block)
B(5,73,6,minecraft:nether_wart_block)
B(5,74,6,minecraft:nether_wart_block)
B(5,0,7,minecraft:nether_wart_block)
B(5,1,7,minecraft:nether_wart_block)
B(5,2,7,minecraft:nether_wart_block)
B(5,3,7,minecraft:nether_wart_block)
B(5,4,7,minecraft:nether_wart_block)
B(5,5,7,minecraft:nether_wart_block)
B(5,6,7,minecraft:nether_wart_block)
B(5,7,7,minecraft:nether_wart_block)
B(5,8,7,minecraft:nether_wart_block)
B(5,9,7,minecraft:nether_wart_block)
B(5,10,7,minecraft:nether_wart_block)
B(5,11,7,minecraft:nether_wart_block)
B(5,12,7,minecraft:nether_wart_block)
B(5,13,7,minecraft:nether_wart_block)
B(5,14,7,minecraft:nether_wart_block)
B(5,15,7,minecraft:nether_wart_block)
B(5,16,7,minecraft:nether_wart_block)
B(5,17,7,minecraft:nether_wart_block)
B(5,18,7,minecraft:nether_wart_block)
B(5,19,7,minecraft:nether_wart_block)
B(5,20,7,minecraft:nether_wart_block)
B(5,21,7,minecraft:nether_wart_block)
B(5,22,7,minecraft:nether_wart_block)
B(5,23,7,minecraft:nether_wart_block)
B(5,24,7,minecraft:nether_wart_block)
B(5,25,7,minecraft:nether_wart_block)
B(5,26,7,minecraft:nether_wart_block)
B(5,27,7,minecraft:nether_wart_block)
B(5,28,7,minecraft:nether_wart_block)
B(5,29,7,minecraft:nether_wart_block)
B(5,30,7,minecraft:nether_wart_block)
B(5,31,7,minecraft:nether_wart_block)
B(5,32,7,minecraft:nether_wart_block)
B(5,33,7,minecraft:nether_wart_block)
B(5,34,7,minecraft:nether_wart_block)
B(5,35,7,minecraft:nether_wart_block)
B(5,36,7,minecraft:nether_wart_block)
B(5,37,7,minecraft:nether_wart_block)
B(5,38,7,minecraft:nether_wart_block)
B(5,39,7,minecraft:nether_wart_block)
B(5,40,7,minecraft:nether_wart_block)
B(5,65,7,minecraft:nether_wart_block)
B(5,66,7,minecraft:nether_wart_block)
B(5,67,7,minecraft:nether_wart_block)
B(5,68,7,minecraft:nether_wart_block)
B(5,69,7,minecraft:nether_wart_block)
B(5,70,7,minecraft:nether_wart_block)
B(5,71,7,minecraft:nether_wart_block)
B(5,72,7,minecraft:nether_wart_block)
B(5,73,7,minecraft:nether_wart_block)
B(5,74,7,minecraft:nether_wart_block)
B(5,75,7,minecraft:nether_wart_block)
B(5,0,8,minecraft:nether_wart_block)
B(5,1,8,minecraft:nether_wart_block)
B(5,2,8,minecraft:nether_wart_block)
B(5,3,8,minecraft:nether_wart_block)
B(5,4,8,minecraft:nether_wart_block)
B(5,5,8,minecraft:nether_wart_block)
B(5,6,8,minecraft:nether_wart_block)
B(5,7,8,minecraft:nether_wart_block)
B(5,8,8,minecraft:nether_wart_block)
B(5,9,8,minecraft:nether_wart_block)
B(5,10,8,minecraft:nether_wart_block)
B(5,11,8,minecraft:nether_wart_block)
B(5,12,8,minecraft:nether_wart_block)
B(5,13,8,minecraft:nether_wart_block)
B(5,14,8,minecraft:nether_wart_block)
B(5,15,8,minecraft:nether_wart_block)
B(5,16,8,minecraft:nether_wart_block)
B(5,17,8,minecraft:nether_wart_block)
B(5,18,8,minecraft:nether_wart_block)
B(5,19,8,minecraft:nether_wart_block)
B(5,20,8,minecraft:nether_wart_block)
B(5,21,8,minecraft:nether_wart_block)
B(5,22,8,minecraft:nether_wart_block)
B(5,23,8,minecraft:nether_wart_block)
B(5,24,8,minecraft:nether_wart_block)
B(5,25,8,minecraft:nether_wart_block)
B(5,26,8,minecraft:nether_wart_block)
B(5,27,8,minecraft:nether_wart_block)
B(5,28,8,minecraft:nether_wart_block)
B(5,29,8,minecraft:nether_wart_block)
B(5,30,8,minecraft:nether_wart_block)
B(5,31,8,minecraft:nether_wart_block)
B(5,32,8,minecraft:nether_wart_block)
B(5,33,8,minecraft:nether_wart_block)
B(5,34,8,minecraft:nether_wart_block)
B(5,35,8,minecraft:nether_wart_block)
B(5,36,8,minecraft:nether_wart_block)
B(5,37,8,minecraft:nether_wart_block)
B(5,38,8,minecraft:nether_wart_block)
B(5,39,8,minecraft:nether_wart_block)
B(5,65,8,minecraft:nether_wart_block)
B(5,66,8,minecraft:nether_wart_block)
B(5,67,8,minecraft:nether_wart_block)
B(5,68,8,minecraft:nether_wart_block)
B(5,69,8,minecraft:nether_wart_block)
B(5,70,8,minecraft:nether_wart_block)
B(5,71,8,minecraft:nether_wart_block)
B(5,72,8,minecraft:nether_wart_block)
B(5,73,8,minecraft:nether_wart_block)
B(5,74,8,minecraft:nether_wart_block)
B(5,75,8,minecraft:nether_wart_block)
B(6,15,-7,minecraft:nether_wart_block)
B(6,16,-7,minecraft:nether_wart_block)
B(6,17,-7,minecraft:nether_wart_block)
B(6,18,-7,minecraft:nether_wart_block)
B(6,19,-7,minecraft:nether_wart_block)
B(6,20,-7,minecraft:nether_wart_block)
B(6,21,-7,minecraft:nether_wart_block)
B(6,22,-7,minecraft:nether_wart_block)
B(6,23,-7,minecraft:nether_wart_block)
B(6,15,-6,minecraft:nether_wart_block)
B(6,16,-6,minecraft:nether_wart_block)
B(6,17,-6,minecraft:nether_wart_block)
B(6,18,-6,minecraft:nether_wart_block)
B(6,19,-6,minecraft:nether_wart_block)
B(6,20,-6,minecraft:nether_wart_block)
B(6,21,-6,minecraft:nether_wart_block)
B(6,22,-6,minecraft:nether_wart_block)
B(6,23,-6,minecraft:nether_wart_block)
B(6,14,-5,minecraft:nether_wart_block)
B(6,15,-5,minecraft:nether_wart_block)
B(6,16,-5,minecraft:nether_wart_block)
B(6,17,-5,minecraft:nether_wart_block)
B(6,18,-5,minecraft:nether_wart_block)
B(6,19,-5,minecraft:nether_wart_block)
B(6,20,-5,minecraft:nether_wart_block)
B(6,21,-5,minecraft:nether_wart_block)
B(6,22,-5,minecraft:nether_wart_block)
B(6,23,-5,minecraft:nether_wart_block)
B(6,24,-5,minecraft:nether_wart_block)
B(6,14,-4,minecraft:nether_wart_block)
B(6,15,-4,minecraft:nether_wart_block)
B(6,16,-4,minecraft:nether_wart_block)
B(6,17,-4,minecraft:nether_wart_block)
B(6,18,-4,minecraft:nether_wart_block)
B(6,19,-4,minecraft:nether_wart_block)
B(6,20,-4,minecraft:nether_wart_block)
B(6,21,-4,minecraft:nether_wart_block)
B(6,22,-4,minecraft:nether_wart_block)
B(6,23,-4,minecraft:nether_wart_block)
B(6,24,-4,minecraft:nether_wart_block)
B(6,14,-3,minecraft:nether_wart_block)
B(6,15,-3,minecraft:nether_wart_block)
B(6,16,-3,minecraft:nether_wart_block)
B(6,17,-3,minecraft:nether_wart_block)
B(6,18,-3,minecraft:nether_wart_block)
B(6,19,-3,minecraft:nether_wart_block)
B(6,20,-3,minecraft:nether_wart_block)
B(6,21,-3,minecraft:nether_wart_block)
B(6,22,-3,minecraft:nether_wart_block)
B(6,23,-3,minecraft:nether_wart_block)
B(6,24,-3,minecraft:nether_wart_block)
B(6,13,-2,minecraft:nether_wart_block)
B(6,14,-2,minecraft:nether_wart_block)
B(6,15,-2,minecraft:nether_wart_block)
B(6,16,-2,minecraft:nether_wart_block)
B(6,17,-2,minecraft:nether_wart_block)
B(6,18,-2,minecraft:nether_wart_block)
B(6,19,-2,minecraft:nether_wart_block)
B(6,20,-2,minecraft:nether_wart_block)
B(6,21,-2,minecraft:nether_wart_block)
B(6,22,-2,minecraft:nether_wart_block)
B(6,23,-2,minecraft:nether_wart_block)
B(6,12,-1,minecraft:nether_wart_block)
B(6,13,-1,minecraft:nether_wart_block)
B(6,14,-1,minecraft:nether_wart_block)
B(6,15,-1,minecraft:nether_wart_block)
B(6,16,-1,minecraft:nether_wart_block)
B(6,17,-1,minecraft:nether_wart_block)
B(6,18,-1,minecraft:nether_wart_block)
B(6,19,-1,minecraft:nether_wart_block)
B(6,20,-1,minecraft:nether_wart_block)
B(6,21,-1,minecraft:nether_wart_block)
B(6,22,-1,minecraft:nether_wart_block)
B(6,23,-1,minecraft:nether_wart_block)
B(6,35,-1,minecraft:nether_wart_block)
B(6,36,-1,minecraft:nether_wart_block)
B(6,37,-1,minecraft:nether_wart_block)
B(6,12,0,minecraft:nether_wart_block)
B(6,13,0,minecraft:nether_wart_block)
B(6,14,0,minecraft:nether_wart_block)
B(6,15,0,minecraft:nether_wart_block)
B(6,16,0,minecraft:nether_wart_block)
B(6,17,0,minecraft:nether_wart_block)
B(6,18,0,minecraft:nether_wart_block)
B(6,19,0,minecraft:nether_wart_block)
B(6,20,0,minecraft:nether_wart_block)
B(6,21,0,minecraft:nether_wart_block)
B(6,22,0,minecraft:nether_wart_block)
B(6,33,0,minecraft:nether_wart_block)
B(6,34,0,minecraft:nether_wart_block)
B(6,35,0,minecraft:nether_wart_block)
B(6,36,0,minecraft:nether_wart_block)
B(6,37,0,minecraft:nether_wart_block)
B(6,38,0,minecraft:nether_wart_block)
B(6,39,0,minecraft:nether_wart_block)
B(6,12,1,minecraft:nether_wart_block)
B(6,13,1,minecraft:nether_wart_block)
B(6,14,1,minecraft:nether_wart_block)
B(6,15,1,minecraft:nether_wart_block)
B(6,16,1,minecraft:nether_wart_block)
B(6,17,1,minecraft:nether_wart_block)
B(6,18,1,minecraft:nether_wart_block)
B(6,19,1,minecraft:nether_wart_block)
B(6,20,1,minecraft:nether_wart_block)
B(6,21,1,minecraft:nether_wart_block)
B(6,22,1,minecraft:nether_wart_block)
B(6,32,1,minecraft:nether_wart_block)
B(6,33,1,minecraft:nether_wart_block)
B(6,34,1,minecraft:nether_wart_block)
B(6,35,1,minecraft:nether_wart_block)
B(6,36,1,minecraft:nether_wart_block)
B(6,37,1,minecraft:nether_wart_block)
B(6,38,1,minecraft:nether_wart_block)
B(6,39,1,minecraft:nether_wart_block)
B(6,40,1,minecraft:nether_wart_block)
B(6,41,1,minecraft:nether_wart_block)
B(6,12,2,minecraft:nether_wart_block)
B(6,13,2,minecraft:nether_wart_block)
B(6,14,2,minecraft:nether_wart_block)
B(6,15,2,minecraft:nether_wart_block)
B(6,16,2,minecraft:nether_wart_block)
B(6,17,2,minecraft:nether_wart_block)
B(6,18,2,minecraft:nether_wart_block)
B(6,19,2,minecraft:nether_wart_block)
B(6,20,2,minecraft:nether_wart_block)
B(6,21,2,minecraft:nether_wart_block)
B(6,22,2,minecraft:nether_wart_block)
B(6,32,2,minecraft:nether_wart_block)
B(6,33,2,minecraft:nether_wart_block)
B(6,34,2,minecraft:nether_wart_block)
B(6,35,2,minecraft:nether_wart_block)
B(6,36,2,minecraft:nether_wart_block)
B(6,37,2,minecraft:nether_wart_block)
B(6,38,2,minecraft:nether_wart_block)
B(6,39,2,minecraft:nether_wart_block)
B(6,40,2,minecraft:nether_wart_block)
B(6,41,2,minecraft:nether_wart_block)
B(6,42,2,minecraft:nether_wart_block)
B(6,11,3,minecraft:nether_wart_block)
B(6,12,3,minecraft:nether_wart_block)
B(6,13,3,minecraft:nether_wart_block)
B(6,14,3,minecraft:nether_wart_block)
B(6,15,3,minecraft:nether_wart_block)
B(6,16,3,minecraft:nether_wart_block)
B(6,17,3,minecraft:nether_wart_block)
B(6,18,3,minecraft:nether_wart_block)
B(6,19,3,minecraft:nether_wart_block)
B(6,20,3,minecraft:nether_wart_block)
B(6,21,3,minecraft:nether_wart_block)
B(6,22,3,minecraft:nether_wart_block)
B(6,31,3,minecraft:nether_wart_block)
B(6,32,3,minecraft:nether_wart_block)
B(6,33,3,minecraft:nether_wart_block)
B(6,34,3,minecraft:nether_wart_block)
B(6,35,3,minecraft:nether_wart_block)
B(6,36,3,minecraft:nether_wart_block)
B(6,37,3,minecraft:nether_wart_block)
B(6,38,3,minecraft:nether_wart_block)
B(6,39,3,minecraft:nether_wart_block)
B(6,40,3,minecraft:nether_wart_block)
B(6,41,3,minecraft:nether_wart_block)
B(6,42,3,minecraft:nether_wart_block)
B(6,0,4,minecraft:nether_wart_block)
B(6,1,4,minecraft:nether_wart_block)
B(6,2,4,minecraft:nether_wart_block)
B(6,5,4,minecraft:nether_wart_block)
B(6,6,4,minecraft:nether_wart_block)
B(6,7,4,minecraft:nether_wart_block)
B(6,10,4,minecraft:nether_wart_block)
B(6,11,4,minecraft:nether_wart_block)
B(6,12,4,minecraft:nether_wart_block)
B(6,13,4,minecraft:nether_wart_block)
B(6,14,4,minecraft:nether_wart_block)
B(6,15,4,minecraft:nether_wart_block)
B(6,16,4,minecraft:nether_wart_block)
B(6,17,4,minecraft:nether_wart_block)
B(6,18,4,minecraft:nether_wart_block)
B(6,19,4,minecraft:nether_wart_block)
B(6,20,4,minecraft:nether_wart_block)
B(6,21,4,minecraft:nether_wart_block)
B(6,31,4,minecraft:nether_wart_block)
B(6,32,4,minecraft:nether_wart_block)
B(6,33,4,minecraft:nether_wart_block)
B(6,34,4,minecraft:nether_wart_block)
B(6,35,4,minecraft:nether_wart_block)
B(6,36,4,minecraft:nether_wart_block)
B(6,37,4,minecraft:nether_wart_block)
B(6,38,4,minecraft:nether_wart_block)
B(6,39,4,minecraft:nether_wart_block)
B(6,40,4,minecraft:nether_wart_block)
B(6,41,4,minecraft:nether_wart_block)
B(6,42,4,minecraft:nether_wart_block)
B(6,68,4,minecraft:nether_wart_block)
B(6,69,4,minecraft:nether_wart_block)
B(6,70,4,minecraft:nether_wart_block)
B(6,71,4,minecraft:nether_wart_block)
B(6,72,4,minecraft:nether_wart_block)
B(6,0,5,minecraft:nether_wart_block)
B(6,1,5,minecraft:nether_wart_block)
B(6,2,5,minecraft:nether_wart_block)
B(6,3,5,minecraft:nether_wart_block)
B(6,4,5,minecraft:nether_wart_block)
B(6,5,5,minecraft:nether_wart_block)
B(6,6,5,minecraft:nether_wart_block)
B(6,7,5,minecraft:nether_wart_block)
B(6,8,5,minecraft:nether_wart_block)
B(6,9,5,minecraft:nether_wart_block)
B(6,10,5,minecraft:nether_wart_block)
B(6,11,5,minecraft:nether_wart_block)
B(6,12,5,minecraft:nether_wart_block)
B(6,13,5,minecraft:nether_wart_block)
B(6,14,5,minecraft:nether_wart_block)
B(6,15,5,minecraft:nether_wart_block)
B(6,16,5,minecraft:nether_wart_block)
B(6,17,5,minecraft:nether_wart_block)
B(6,18,5,minecraft:nether_wart_block)
B(6,19,5,minecraft:nether_wart_block)
B(6,20,5,minecraft:nether_wart_block)
B(6,24,5,minecraft:nether_wart_block)
B(6,25,5,minecraft:nether_wart_block)
B(6,26,5,minecraft:nether_wart_block)
B(6,27,5,minecraft:nether_wart_block)
B(6,28,5,minecraft:nether_wart_block)
B(6,29,5,minecraft:nether_wart_block)
B(6,30,5,minecraft:nether_wart_block)
B(6,31,5,minecraft:nether_wart_block)
B(6,32,5,minecraft:nether_wart_block)
B(6,33,5,minecraft:nether_wart_block)
B(6,34,5,minecraft:nether_wart_block)
B(6,35,5,minecraft:nether_wart_block)
B(6,36,5,minecraft:nether_wart_block)
B(6,37,5,minecraft:nether_wart_block)
B(6,38,5,minecraft:nether_wart_block)
B(6,39,5,minecraft:nether_wart_block)
B(6,40,5,minecraft:nether_wart_block)
B(6,41,5,minecraft:nether_wart_block)
B(6,67,5,minecraft:nether_wart_block)
B(6,68,5,minecraft:nether_wart_block)
B(6,69,5,minecraft:nether_wart_block)
B(6,70,5,minecraft:nether_wart_block)
B(6,71,5,minecraft:nether_wart_block)
B(6,72,5,minecraft:nether_wart_block)
B(6,73,5,minecraft:nether_wart_block)
B(6,0,6,minecraft:nether_wart_block)
B(6,1,6,minecraft:nether_wart_block)
B(6,2,6,minecraft:nether_wart_block)
B(6,3,6,minecraft:nether_wart_block)
B(6,4,6,minecraft:nether_wart_block)
B(6,5,6,minecraft:nether_wart_block)
B(6,6,6,minecraft:nether_wart_block)
B(6,7,6,minecraft:nether_wart_block)
B(6,8,6,minecraft:nether_wart_block)
B(6,9,6,minecraft:nether_wart_block)
B(6,10,6,minecraft:nether_wart_block)
B(6,11,6,minecraft:nether_wart_block)
B(6,12,6,minecraft:nether_wart_block)
B(6,13,6,minecraft:nether_wart_block)
B(6,14,6,minecraft:nether_wart_block)
B(6,15,6,minecraft:nether_wart_block)
B(6,16,6,minecraft:nether_wart_block)
B(6,17,6,minecraft:nether_wart_block)
B(6,18,6,minecraft:nether_wart_block)
B(6,19,6,minecraft:nether_wart_block)
B(6,20,6,minecraft:nether_wart_block)
B(6,21,6,minecraft:nether_wart_block)
B(6,22,6,minecraft:nether_wart_block)
B(6,23,6,minecraft:nether_wart_block)
B(6,24,6,minecraft:nether_wart_block)
B(6,25,6,minecraft:nether_wart_block)
B(6,26,6,minecraft:nether_wart_block)
B(6,27,6,minecraft:nether_wart_block)
B(6,28,6,minecraft:nether_wart_block)
B(6,29,6,minecraft:nether_wart_block)
B(6,30,6,minecraft:nether_wart_block)
B(6,31,6,minecraft:nether_wart_block)
B(6,32,6,minecraft:nether_wart_block)
B(6,33,6,minecraft:nether_wart_block)
B(6,34,6,minecraft:nether_wart_block)
B(6,35,6,minecraft:nether_wart_block)
B(6,36,6,minecraft:nether_wart_block)
B(6,37,6,minecraft:nether_wart_block)
B(6,38,6,minecraft:nether_wart_block)
B(6,39,6,minecraft:nether_wart_block)
B(6,40,6,minecraft:nether_wart_block)
B(6,66,6,minecraft:nether_wart_block)
B(6,67,6,minecraft:nether_wart_block)
B(6,68,6,minecraft:nether_wart_block)
B(6,69,6,minecraft:nether_wart_block)
B(6,70,6,minecraft:nether_wart_block)
B(6,71,6,minecraft:nether_wart_block)
B(6,72,6,minecraft:nether_wart_block)
B(6,73,6,minecraft:nether_wart_block)
B(6,74,6,minecraft:nether_wart_block)
B(6,0,7,minecraft:nether_wart_block)
B(6,1,7,minecraft:nether_wart_block)
B(6,2,7,minecraft:nether_wart_block)
B(6,3,7,minecraft:nether_wart_block)
B(6,4,7,minecraft:nether_wart_block)
B(6,5,7,minecraft:nether_wart_block)
B(6,6,7,minecraft:nether_wart_block)
B(6,7,7,minecraft:nether_wart_block)
B(6,8,7,minecraft:nether_wart_block)
B(6,9,7,minecraft:nether_wart_block)
B(6,10,7,minecraft:nether_wart_block)
B(6,11,7,minecraft:nether_wart_block)
B(6,12,7,minecraft:nether_wart_block)
B(6,13,7,minecraft:nether_wart_block)
B(6,14,7,minecraft:nether_wart_block)
B(6,15,7,minecraft:nether_wart_block)
B(6,16,7,minecraft:nether_wart_block)
B(6,17,7,minecraft:nether_wart_block)
B(6,18,7,minecraft:nether_wart_block)
B(6,19,7,minecraft:nether_wart_block)
B(6,20,7,minecraft:nether_wart_block)
B(6,21,7,minecraft:nether_wart_block)
B(6,22,7,minecraft:nether_wart_block)
B(6,23,7,minecraft:nether_wart_block)
B(6,24,7,minecraft:nether_wart_block)
B(6,25,7,minecraft:nether_wart_block)
B(6,26,7,minecraft:nether_wart_block)
B(6,27,7,minecraft:nether_wart_block)
B(6,28,7,minecraft:nether_wart_block)
B(6,29,7,minecraft:nether_wart_block)
B(6,30,7,minecraft:nether_wart_block)
B(6,31,7,minecraft:nether_wart_block)
B(6,32,7,minecraft:nether_wart_block)
B(6,33,7,minecraft:nether_wart_block)
B(6,34,7,minecraft:nether_wart_block)
B(6,35,7,minecraft:nether_wart_block)
B(6,36,7,minecraft:nether_wart_block)
B(6,37,7,minecraft:nether_wart_block)
B(6,38,7,minecraft:nether_wart_block)
B(6,39,7,minecraft:nether_wart_block)
B(6,40,7,minecraft:nether_wart_block)
B(6,65,7,minecraft:nether_wart_block)
B(6,66,7,minecraft:nether_wart_block)
B(6,67,7,minecraft:nether_wart_block)
B(6,68,7,minecraft:nether_wart_block)
B(6,69,7,minecraft:nether_wart_block)
B(6,70,7,minecraft:nether_wart_block)
B(6,71,7,minecraft:nether_wart_block)
B(6,72,7,minecraft:nether_wart_block)
B(6,73,7,minecraft:nether_wart_block)
B(6,74,7,minecraft:nether_wart_block)
B(6,75,7,minecraft:nether_wart_block)
B(6,0,8,minecraft:nether_wart_block)
B(6,1,8,minecraft:nether_wart_block)
B(6,2,8,minecraft:nether_wart_block)
B(6,3,8,minecraft:nether_wart_block)
B(6,4,8,minecraft:nether_wart_block)
B(6,5,8,minecraft:nether_wart_block)
B(6,6,8,minecraft:nether_wart_block)
B(6,7,8,minecraft:nether_wart_block)
B(6,8,8,minecraft:nether_wart_block)
B(6,9,8,minecraft:nether_wart_block)
B(6,10,8,minecraft:nether_wart_block)
B(6,11,8,minecraft:nether_wart_block)
B(6,12,8,minecraft:nether_wart_block)
B(6,13,8,minecraft:nether_wart_block)
B(6,14,8,minecraft:nether_wart_block)
B(6,15,8,minecraft:nether_wart_block)
B(6,16,8,minecraft:nether_wart_block)
B(6,17,8,minecraft:nether_wart_block)
B(6,18,8,minecraft:nether_wart_block)
B(6,19,8,minecraft:nether_wart_block)
B(6,20,8,minecraft:nether_wart_block)
B(6,21,8,minecraft:nether_wart_block)
B(6,22,8,minecraft:nether_wart_block)
B(6,23,8,minecraft:nether_wart_block)
B(6,24,8,minecraft:nether_wart_block)
B(6,25,8,minecraft:nether_wart_block)
B(6,26,8,minecraft:nether_wart_block)
B(6,27,8,minecraft:nether_wart_block)
B(6,28,8,minecraft:nether_wart_block)
B(6,29,8,minecraft:nether_wart_block)
B(6,30,8,minecraft:nether_wart_block)
B(6,31,8,minecraft:nether_wart_block)
B(6,32,8,minecraft:nether_wart_block)
B(6,33,8,minecraft:nether_wart_block)
B(6,34,8,minecraft:nether_wart_block)
B(6,35,8,minecraft:nether_wart_block)
B(6,36,8,minecraft:nether_wart_block)
B(6,37,8,minecraft:nether_wart_block)
B(6,38,8,minecraft:nether_wart_block)
B(6,39,8,minecraft:nether_wart_block)
B(6,65,8,minecraft:nether_wart_block)
B(6,66,8,minecraft:nether_wart_block)
B(6,67,8,minecraft:nether_wart_block)
B(6,68,8,minecraft:nether_wart_block)
B(6,69,8,minecraft:nether_wart_block)
B(6,70,8,minecraft:nether_wart_block)
B(6,71,8,minecraft:nether_wart_block)
B(6,72,8,minecraft:nether_wart_block)
B(6,73,8,minecraft:nether_wart_block)
B(6,74,8,minecraft:nether_wart_block)
B(6,75,8,minecraft:nether_wart_block)
B(7,15,-7,minecraft:nether_wart_block)
B(7,16,-7,minecraft:nether_wart_block)
B(7,17,-7,minecraft:nether_wart_block)
B(7,18,-7,minecraft:nether_wart_block)
B(7,19,-7,minecraft:nether_wart_block)
B(7,20,-7,minecraft:nether_wart_block)
B(7,21,-7,minecraft:nether_wart_block)
B(7,22,-7,minecraft:nether_wart_block)
B(7,23,-7,minecraft:nether_wart_block)
B(7,14,-6,minecraft:nether_wart_block)
B(7,15,-6,minecraft:nether_wart_block)
B(7,16,-6,minecraft:nether_wart_block)
B(7,17,-6,minecraft:nether_wart_block)
B(7,18,-6,minecraft:nether_wart_block)
B(7,19,-6,minecraft:nether_wart_block)
B(7,20,-6,minecraft:nether_wart_block)
B(7,21,-6,minecraft:nether_wart_block)
B(7,22,-6,minecraft:nether_wart_block)
B(7,23,-6,minecraft:nether_wart_block)
B(7,24,-6,minecraft:nether_wart_block)
B(7,14,-5,minecraft:nether_wart_block)
B(7,15,-5,minecraft:nether_wart_block)
B(7,16,-5,minecraft:nether_wart_block)
B(7,17,-5,minecraft:nether_wart_block)
B(7,18,-5,minecraft:nether_wart_block)
B(7,19,-5,minecraft:nether_wart_block)
B(7,20,-5,minecraft:nether_wart_block)
B(7,21,-5,minecraft:nether_wart_block)
B(7,22,-5,minecraft:nether_wart_block)
B(7,23,-5,minecraft:nether_wart_block)
B(7,24,-5,minecraft:nether_wart_block)
B(7,14,-4,minecraft:nether_wart_block)
B(7,15,-4,minecraft:nether_wart_block)
B(7,16,-4,minecraft:nether_wart_block)
B(7,17,-4,minecraft:nether_wart_block)
B(7,18,-4,minecraft:nether_wart_block)
B(7,19,-4,minecraft:nether_wart_block)
B(7,20,-4,minecraft:nether_wart_block)
B(7,21,-4,minecraft:nether_wart_block)
B(7,22,-4,minecraft:nether_wart_block)
B(7,23,-4,minecraft:nether_wart_block)
B(7,24,-4,minecraft:nether_wart_block)
B(7,14,-3,minecraft:nether_wart_block)
B(7,15,-3,minecraft:nether_wart_block)
B(7,16,-3,minecraft:nether_wart_block)
B(7,17,-3,minecraft:nether_wart_block)
B(7,18,-3,minecraft:nether_wart_block)
B(7,19,-3,minecraft:nether_wart_block)
B(7,20,-3,minecraft:nether_wart_block)
B(7,21,-3,minecraft:nether_wart_block)
B(7,22,-3,minecraft:nether_wart_block)
B(7,23,-3,minecraft:nether_wart_block)
B(7,24,-3,minecraft:nether_wart_block)
B(7,13,-2,minecraft:nether_wart_block)
B(7,14,-2,minecraft:nether_wart_block)
B(7,15,-2,minecraft:nether_wart_block)
B(7,16,-2,minecraft:nether_wart_block)
B(7,17,-2,minecraft:nether_wart_block)
B(7,18,-2,minecraft:nether_wart_block)
B(7,19,-2,minecraft:nether_wart_block)
B(7,20,-2,minecraft:nether_wart_block)
B(7,21,-2,minecraft:nether_wart_block)
B(7,22,-2,minecraft:nether_wart_block)
B(7,23,-2,minecraft:nether_wart_block)
B(7,24,-2,minecraft:nether_wart_block)
B(7,12,-1,minecraft:nether_wart_block)
B(7,13,-1,minecraft:nether_wart_block)
B(7,14,-1,minecraft:nether_wart_block)
B(7,15,-1,minecraft:nether_wart_block)
B(7,16,-1,minecraft:nether_wart_block)
B(7,17,-1,minecraft:nether_wart_block)
B(7,18,-1,minecraft:nether_wart_block)
B(7,19,-1,minecraft:nether_wart_block)
B(7,20,-1,minecraft:nether_wart_block)
B(7,21,-1,minecraft:nether_wart_block)
B(7,22,-1,minecraft:nether_wart_block)
B(7,23,-1,minecraft:nether_wart_block)
B(7,34,-1,minecraft:nether_wart_block)
B(7,35,-1,minecraft:nether_wart_block)
B(7,36,-1,minecraft:nether_wart_block)
B(7,37,-1,minecraft:nether_wart_block)
B(7,38,-1,minecraft:nether_wart_block)
B(7,12,0,minecraft:nether_wart_block)
B(7,13,0,minecraft:nether_wart_block)
B(7,14,0,minecraft:nether_wart_block)
B(7,15,0,minecraft:nether_wart_block)
B(7,16,0,minecraft:nether_wart_block)
B(7,17,0,minecraft:nether_wart_block)
B(7,18,0,minecraft:nether_wart_block)
B(7,19,0,minecraft:nether_wart_block)
B(7,20,0,minecraft:nether_wart_block)
B(7,21,0,minecraft:nether_wart_block)
B(7,22,0,minecraft:nether_wart_block)
B(7,33,0,minecraft:nether_wart_block)
B(7,34,0,minecraft:nether_wart_block)
B(7,35,0,minecraft:nether_wart_block)
B(7,36,0,minecraft:nether_wart_block)
B(7,37,0,minecraft:nether_wart_block)
B(7,38,0,minecraft:nether_wart_block)
B(7,39,0,minecraft:nether_wart_block)
B(7,40,0,minecraft:nether_wart_block)
B(7,41,0,minecraft:nether_wart_block)
B(7,42,0,minecraft:nether_wart_block)
B(7,12,1,minecraft:nether_wart_block)
B(7,13,1,minecraft:nether_wart_block)
B(7,14,1,minecraft:nether_wart_block)
B(7,15,1,minecraft:nether_wart_block)
B(7,16,1,minecraft:nether_wart_block)
B(7,17,1,minecraft:nether_wart_block)
B(7,18,1,minecraft:nether_wart_block)
B(7,19,1,minecraft:nether_wart_block)
B(7,20,1,minecraft:nether_wart_block)
B(7,21,1,minecraft:nether_wart_block)
B(7,22,1,minecraft:nether_wart_block)
B(7,32,1,minecraft:nether_wart_block)
B(7,33,1,minecraft:nether_wart_block)
B(7,34,1,minecraft:nether_wart_block)
B(7,35,1,minecraft:nether_wart_block)
B(7,36,1,minecraft:nether_wart_block)
B(7,37,1,minecraft:nether_wart_block)
B(7,38,1,minecraft:nether_wart_block)
B(7,39,1,minecraft:nether_wart_block)
B(7,40,1,minecraft:nether_wart_block)
B(7,41,1,minecraft:nether_wart_block)
B(7,42,1,minecraft:nether_wart_block)
B(7,43,1,minecraft:nether_wart_block)
B(7,12,2,minecraft:nether_wart_block)
B(7,13,2,minecraft:nether_wart_block)
B(7,14,2,minecraft:nether_wart_block)
B(7,15,2,minecraft:nether_wart_block)
B(7,16,2,minecraft:nether_wart_block)
B(7,17,2,minecraft:nether_wart_block)
B(7,18,2,minecraft:nether_wart_block)
B(7,19,2,minecraft:nether_wart_block)
B(7,20,2,minecraft:nether_wart_block)
B(7,21,2,minecraft:nether_wart_block)
B(7,22,2,minecraft:nether_wart_block)
B(7,31,2,minecraft:nether_wart_block)
B(7,32,2,minecraft:nether_wart_block)
B(7,33,2,minecraft:nether_wart_block)
B(7,34,2,minecraft:nether_wart_block)
B(7,35,2,minecraft:nether_wart_block)
B(7,36,2,minecraft:nether_wart_block)
B(7,37,2,minecraft:nether_wart_block)
B(7,38,2,minecraft:nether_wart_block)
B(7,39,2,minecraft:nether_wart_block)
B(7,40,2,minecraft:nether_wart_block)
B(7,41,2,minecraft:nether_wart_block)
B(7,42,2,minecraft:nether_wart_block)
B(7,43,2,minecraft:nether_wart_block)
B(7,11,3,minecraft:nether_wart_block)
B(7,12,3,minecraft:nether_wart_block)
B(7,13,3,minecraft:nether_wart_block)
B(7,14,3,minecraft:nether_wart_block)
B(7,15,3,minecraft:nether_wart_block)
B(7,16,3,minecraft:nether_wart_block)
B(7,17,3,minecraft:nether_wart_block)
B(7,18,3,minecraft:nether_wart_block)
B(7,19,3,minecraft:nether_wart_block)
B(7,20,3,minecraft:nether_wart_block)
B(7,21,3,minecraft:nether_wart_block)
B(7,22,3,minecraft:nether_wart_block)
B(7,31,3,minecraft:nether_wart_block)
B(7,32,3,minecraft:nether_wart_block)
B(7,33,3,minecraft:nether_wart_block)
B(7,34,3,minecraft:nether_wart_block)
B(7,35,3,minecraft:nether_wart_block)
B(7,36,3,minecraft:nether_wart_block)
B(7,37,3,minecraft:nether_wart_block)
B(7,38,3,minecraft:nether_wart_block)
B(7,39,3,minecraft:nether_wart_block)
B(7,40,3,minecraft:nether_wart_block)
B(7,41,3,minecraft:nether_wart_block)
B(7,42,3,minecraft:nether_wart_block)
B(7,43,3,minecraft:nether_wart_block)
B(7,0,4,minecraft:nether_wart_block)
B(7,1,4,minecraft:nether_wart_block)
B(7,2,4,minecraft:nether_wart_block)
B(7,3,4,minecraft:nether_wart_block)
B(7,4,4,minecraft:nether_wart_block)
B(7,5,4,minecraft:nether_wart_block)
B(7,6,4,minecraft:nether_wart_block)
B(7,7,4,minecraft:nether_wart_block)
B(7,8,4,minecraft:nether_wart_block)
B(7,10,4,minecraft:nether_wart_block)
B(7,11,4,minecraft:nether_wart_block)
B(7,12,4,minecraft:nether_wart_block)
B(7,13,4,minecraft:nether_wart_block)
B(7,14,4,minecraft:nether_wart_block)
B(7,15,4,minecraft:nether_wart_block)
B(7,16,4,minecraft:nether_wart_block)
B(7,17,4,minecraft:nether_wart_block)
B(7,18,4,minecraft:nether_wart_block)
B(7,19,4,minecraft:nether_wart_block)
B(7,20,4,minecraft:nether_wart_block)
B(7,21,4,minecraft:nether_wart_block)
B(7,31,4,minecraft:nether_wart_block)
B(7,32,4,minecraft:nether_wart_block)
B(7,33,4,minecraft:nether_wart_block)
B(7,34,4,minecraft:nether_wart_block)
B(7,35,4,minecraft:nether_wart_block)
B(7,36,4,minecraft:nether_wart_block)
B(7,37,4,minecraft:nether_wart_block)
B(7,38,4,minecraft:nether_wart_block)
B(7,39,4,minecraft:nether_wart_block)
B(7,40,4,minecraft:nether_wart_block)
B(7,41,4,minecraft:nether_wart_block)
B(7,42,4,minecraft:nether_wart_block)
B(7,43,4,minecraft:nether_wart_block)
B(7,68,4,minecraft:nether_wart_block)
B(7,69,4,minecraft:nether_wart_block)
B(7,70,4,minecraft:nether_wart_block)
B(7,71,4,minecraft:nether_wart_block)
B(7,72,4,minecraft:nether_wart_block)
B(7,0,5,minecraft:nether_wart_block)
B(7,1,5,minecraft:nether_wart_block)
B(7,2,5,minecraft:nether_wart_block)
B(7,3,5,minecraft:nether_wart_block)
B(7,4,5,minecraft:nether_wart_block)
B(7,5,5,minecraft:nether_wart_block)
B(7,6,5,minecraft:nether_wart_block)
B(7,7,5,minecraft:nether_wart_block)
B(7,8,5,minecraft:nether_wart_block)
B(7,9,5,minecraft:nether_wart_block)
B(7,10,5,minecraft:nether_wart_block)
B(7,11,5,minecraft:nether_wart_block)
B(7,12,5,minecraft:nether_wart_block)
B(7,13,5,minecraft:nether_wart_block)
B(7,14,5,minecraft:nether_wart_block)
B(7,15,5,minecraft:nether_wart_block)
B(7,16,5,minecraft:nether_wart_block)
B(7,17,5,minecraft:nether_wart_block)
B(7,18,5,minecraft:nether_wart_block)
B(7,19,5,minecraft:nether_wart_block)
B(7,20,5,minecraft:nether_wart_block)
B(7,25,5,minecraft:nether_wart_block)
B(7,26,5,minecraft:nether_wart_block)
B(7,27,5,minecraft:nether_wart_block)
B(7,31,5,minecraft:nether_wart_block)
B(7,32,5,minecraft:nether_wart_block)
B(7,33,5,minecraft:nether_wart_block)
B(7,34,5,minecraft:nether_wart_block)
B(7,35,5,minecraft:nether_wart_block)
B(7,36,5,minecraft:nether_wart_block)
B(7,37,5,minecraft:nether_wart_block)
B(7,38,5,minecraft:nether_wart_block)
B(7,39,5,minecraft:nether_wart_block)
B(7,40,5,minecraft:nether_wart_block)
B(7,41,5,minecraft:nether_wart_block)
B(7,42,5,minecraft:nether_wart_block)
B(7,43,5,minecraft:nether_wart_block)
B(7,67,5,minecraft:nether_wart_block)
B(7,68,5,minecraft:nether_wart_block)
B(7,69,5,minecraft:nether_wart_block)
B(7,70,5,minecraft:nether_wart_block)
B(7,71,5,minecraft:nether_wart_block)
B(7,72,5,minecraft:nether_wart_block)
B(7,73,5,minecraft:nether_wart_block)
B(7,0,6,minecraft:nether_wart_block)
B(7,1,6,minecraft:nether_wart_block)
B(7,2,6,minecraft:nether_wart_block)
B(7,3,6,minecraft:nether_wart_block)
B(7,4,6,minecraft:nether_wart_block)
B(7,5,6,minecraft:nether_wart_block)
B(7,6,6,minecraft:nether_wart_block)
B(7,7,6,minecraft:nether_wart_block)
B(7,8,6,minecraft:nether_wart_block)
B(7,9,6,minecraft:nether_wart_block)
B(7,10,6,minecraft:nether_wart_block)
B(7,11,6,minecraft:nether_wart_block)
B(7,12,6,minecraft:nether_wart_block)
B(7,13,6,minecraft:nether_wart_block)
B(7,14,6,minecraft:nether_wart_block)
B(7,15,6,minecraft:nether_wart_block)
B(7,16,6,minecraft:nether_wart_block)
B(7,17,6,minecraft:nether_wart_block)
B(7,18,6,minecraft:nether_wart_block)
B(7,19,6,minecraft:nether_wart_block)
B(7,20,6,minecraft:nether_wart_block)
B(7,21,6,minecraft:nether_wart_block)
B(7,22,6,minecraft:nether_wart_block)
B(7,23,6,minecraft:nether_wart_block)
B(7,24,6,minecraft:nether_wart_block)
B(7,25,6,minecraft:nether_wart_block)
B(7,26,6,minecraft:nether_wart_block)
B(7,27,6,minecraft:nether_wart_block)
B(7,28,6,minecraft:nether_wart_block)
B(7,29,6,minecraft:nether_wart_block)
B(7,30,6,minecraft:nether_wart_block)
B(7,31,6,minecraft:nether_wart_block)
B(7,32,6,minecraft:nether_wart_block)
B(7,33,6,minecraft:nether_wart_block)
B(7,34,6,minecraft:nether_wart_block)
B(7,35,6,minecraft:nether_wart_block)
B(7,36,6,minecraft:nether_wart_block)
B(7,37,6,minecraft:nether_wart_block)
B(7,38,6,minecraft:nether_wart_block)
B(7,39,6,minecraft:nether_wart_block)
B(7,40,6,minecraft:nether_wart_block)
B(7,41,6,minecraft:nether_wart_block)
B(7,42,6,minecraft:nether_wart_block)
B(7,66,6,minecraft:nether_wart_block)
B(7,67,6,minecraft:nether_wart_block)
B(7,68,6,minecraft:nether_wart_block)
B(7,69,6,minecraft:nether_wart_block)
B(7,70,6,minecraft:nether_wart_block)
B(7,71,6,minecraft:nether_wart_block)
B(7,72,6,minecraft:nether_wart_block)
B(7,73,6,minecraft:nether_wart_block)
B(7,74,6,minecraft:nether_wart_block)
B(7,0,7,minecraft:nether_wart_block)
B(7,1,7,minecraft:nether_wart_block)
B(7,2,7,minecraft:nether_wart_block)
B(7,3,7,minecraft:nether_wart_block)
B(7,4,7,minecraft:nether_wart_block)
B(7,5,7,minecraft:nether_wart_block)
B(7,6,7,minecraft:nether_wart_block)
B(7,7,7,minecraft:nether_wart_block)
B(7,8,7,minecraft:nether_wart_block)
B(7,9,7,minecraft:nether_wart_block)
B(7,10,7,minecraft:nether_wart_block)
B(7,11,7,minecraft:nether_wart_block)
B(7,12,7,minecraft:nether_wart_block)
B(7,13,7,minecraft:nether_wart_block)
B(7,14,7,minecraft:nether_wart_block)
B(7,15,7,minecraft:nether_wart_block)
B(7,16,7,minecraft:nether_wart_block)
B(7,17,7,minecraft:nether_wart_block)
B(7,18,7,minecraft:nether_wart_block)
B(7,19,7,minecraft:nether_wart_block)
B(7,20,7,minecraft:nether_wart_block)
B(7,21,7,minecraft:nether_wart_block)
B(7,22,7,minecraft:nether_wart_block)
B(7,23,7,minecraft:nether_wart_block)
B(7,24,7,minecraft:nether_wart_block)
B(7,25,7,minecraft:nether_wart_block)
B(7,26,7,minecraft:nether_wart_block)
B(7,27,7,minecraft:nether_wart_block)
B(7,28,7,minecraft:nether_wart_block)
B(7,29,7,minecraft:nether_wart_block)
B(7,30,7,minecraft:nether_wart_block)
B(7,31,7,minecraft:nether_wart_block)
B(7,32,7,minecraft:nether_wart_block)
B(7,33,7,minecraft:nether_wart_block)
B(7,34,7,minecraft:nether_wart_block)
B(7,35,7,minecraft:nether_wart_block)
B(7,36,7,minecraft:nether_wart_block)
B(7,37,7,minecraft:nether_wart_block)
B(7,38,7,minecraft:nether_wart_block)
B(7,39,7,minecraft:nether_wart_block)
B(7,40,7,minecraft:nether_wart_block)
B(7,65,7,minecraft:nether_wart_block)
B(7,66,7,minecraft:nether_wart_block)
B(7,67,7,minecraft:nether_wart_block)
B(7,68,7,minecraft:nether_wart_block)
B(7,69,7,minecraft:nether_wart_block)
B(7,70,7,minecraft:nether_wart_block)
B(7,71,7,minecraft:nether_wart_block)
B(7,72,7,minecraft:nether_wart_block)
B(7,73,7,minecraft:nether_wart_block)
B(7,74,7,minecraft:nether_wart_block)
B(7,75,7,minecraft:nether_wart_block)
B(7,0,8,minecraft:nether_wart_block)
B(7,1,8,minecraft:nether_wart_block)
B(7,2,8,minecraft:nether_wart_block)
B(7,3,8,minecraft:nether_wart_block)
B(7,4,8,minecraft:nether_wart_block)
B(7,5,8,minecraft:nether_wart_block)
B(7,6,8,minecraft:nether_wart_block)
B(7,7,8,minecraft:nether_wart_block)
B(7,8,8,minecraft:nether_wart_block)
B(7,9,8,minecraft:nether_wart_block)
B(7,10,8,minecraft:nether_wart_block)
B(7,11,8,minecraft:nether_wart_block)
B(7,12,8,minecraft:nether_wart_block)
B(7,13,8,minecraft:nether_wart_block)
B(7,14,8,minecraft:nether_wart_block)
B(7,15,8,minecraft:nether_wart_block)
B(7,16,8,minecraft:nether_wart_block)
B(7,17,8,minecraft:nether_wart_block)
B(7,18,8,minecraft:nether_wart_block)
B(7,19,8,minecraft:nether_wart_block)
B(7,20,8,minecraft:nether_wart_block)
B(7,21,8,minecraft:nether_wart_block)
B(7,22,8,minecraft:nether_wart_block)
B(7,23,8,minecraft:nether_wart_block)
B(7,24,8,minecraft:nether_wart_block)
B(7,25,8,minecraft:nether_wart_block)
B(7,26,8,minecraft:nether_wart_block)
B(7,27,8,minecraft:nether_wart_block)
B(7,28,8,minecraft:nether_wart_block)
B(7,29,8,minecraft:nether_wart_block)
B(7,30,8,minecraft:nether_wart_block)
B(7,31,8,minecraft:nether_wart_block)
B(7,32,8,minecraft:nether_wart_block)
B(7,33,8,minecraft:nether_wart_block)
B(7,34,8,minecraft:nether_wart_block)
B(7,35,8,minecraft:nether_wart_block)
B(7,36,8,minecraft:nether_wart_block)
B(7,37,8,minecraft:nether_wart_block)
B(7,38,8,minecraft:nether_wart_block)
B(7,39,8,minecraft:nether_wart_block)
B(7,65,8,minecraft:nether_wart_block)
B(7,66,8,minecraft:nether_wart_block)
B(7,67,8,minecraft:nether_wart_block)
B(7,68,8,minecraft:nether_wart_block)
B(7,69,8,minecraft:nether_wart_block)
B(7,70,8,minecraft:nether_wart_block)
B(7,71,8,minecraft:nether_wart_block)
B(7,72,8,minecraft:nether_wart_block)
B(7,73,8,minecraft:nether_wart_block)
B(7,74,8,minecraft:nether_wart_block)
B(7,75,8,minecraft:nether_wart_block)

#######################################################################
# +-----------------------------------------------------------------+ #
# |                             Branches                            | #
# +-----------------------------------------------------------------+ #
#######################################################################

Branch(16,0,0,true,CrimsonBeanstalk3_C2_R1,NORTH,100.0,0)

#######################################################################
# +-----------------------------------------------------------------+ #
# |                             Entities                            | #
# +-----------------------------------------------------------------+ #
#######################################################################

