
#######################################################################
# +-----------------------------------------------------------------+ #
# |                            BO4 object                           | #
# +-----------------------------------------------------------------+ #
#######################################################################

Author: Unknown

Description: No description given

SettingsMode: WriteWithoutComments


#######################################################################
# +-----------------------------------------------------------------+ #
# |                          Main settings                          | #
# +-----------------------------------------------------------------+ #
#######################################################################

FixedRotation: 

Frequency: 0

SpawnHeight: highestBlock

UseCenterForHighestBlock: true

##############################
# Height Limits for the BO4. #
##############################

MinHeight: 0

MaxHeight: 255

InheritBO3: 

InheritBO3Rotation: NORTH

OverrideChildSettings: true

OverrideParentHeight: false

CanOverride: false

BranchFrequency: 0

BranchFrequencyGroup: 

MustBeBelowOther: false

MustBeInside: 

CannotBeInside: 

ReplacesBO3: 

MustBeInsideWorldBorders: false

CanSpawnOnWater: true

SpawnOnWaterOnly: false

SpawnUnderWater: false

SpawnAtWaterLevel: false

HeightOffset: 0

RemoveAir: true

ReplaceAbove: 

ReplaceBelow: 

ReplaceWithBiomeBlocks: true

ReplaceWithSurfaceBlock: GRASS

ReplaceWithGroundBlock: DIRT

ReplaceWithStoneBlock: STONE

SmoothRadius: 0

SmoothHeightOffset: 0

SmoothStartTop: false

SmoothStartWood: false

SmoothingSurfaceBlock: 

SmoothingGroundBlock: 

BO3Group: 

IsSpawnPoint: false

DoReplaceBlocks: true


#######################################################################
# +-----------------------------------------------------------------+ #
# |                              Blocks                             | #
# +-----------------------------------------------------------------+ #
#######################################################################

B(-8,32,-7,minecraft:nether_wart_block)
B(-8,33,-7,minecraft:nether_wart_block)
B(-8,34,-7,minecraft:nether_wart_block)
B(-8,35,-7,minecraft:nether_wart_block)
B(-8,36,-7,minecraft:nether_wart_block)
B(-8,37,-7,minecraft:nether_wart_block)
B(-8,38,-7,minecraft:nether_wart_block)
B(-8,39,-7,minecraft:nether_wart_block)
B(-8,40,-7,minecraft:nether_wart_block)
B(-8,41,-7,minecraft:nether_wart_block)
B(-8,33,-6,minecraft:nether_wart_block)
B(-8,34,-6,minecraft:nether_wart_block)
B(-8,35,-6,minecraft:nether_wart_block)
B(-8,36,-6,minecraft:nether_wart_block)
B(-8,37,-6,minecraft:nether_wart_block)
B(-8,38,-6,minecraft:nether_wart_block)
B(-8,39,-6,minecraft:nether_wart_block)
B(-8,40,-6,minecraft:nether_wart_block)
B(-8,41,-6,minecraft:nether_wart_block)
B(-8,34,-5,minecraft:nether_wart_block)
B(-8,35,-5,minecraft:nether_wart_block)
B(-8,36,-5,minecraft:nether_wart_block)
B(-8,37,-5,minecraft:nether_wart_block)
B(-8,38,-5,minecraft:nether_wart_block)
B(-8,39,-5,minecraft:nether_wart_block)
B(-8,40,-5,minecraft:nether_wart_block)
B(-8,36,-4,minecraft:nether_wart_block)
B(-8,37,-4,minecraft:nether_wart_block)
B(-8,38,-4,minecraft:nether_wart_block)
B(-7,32,-7,minecraft:nether_wart_block)
B(-7,33,-7,minecraft:nether_wart_block)
B(-7,34,-7,minecraft:nether_wart_block)
B(-7,35,-7,minecraft:nether_wart_block)
B(-7,36,-7,minecraft:nether_wart_block)
B(-7,37,-7,minecraft:nether_wart_block)
B(-7,38,-7,minecraft:nether_wart_block)
B(-7,39,-7,minecraft:nether_wart_block)
B(-7,40,-7,minecraft:nether_wart_block)
B(-7,41,-7,minecraft:nether_wart_block)
B(-7,42,-7,minecraft:nether_wart_block)
B(-7,33,-6,minecraft:nether_wart_block)
B(-7,34,-6,minecraft:nether_wart_block)
B(-7,35,-6,minecraft:nether_wart_block)
B(-7,36,-6,minecraft:nether_wart_block)
B(-7,37,-6,minecraft:nether_wart_block)
B(-7,38,-6,minecraft:nether_wart_block)
B(-7,39,-6,minecraft:nether_wart_block)
B(-7,40,-6,minecraft:nether_wart_block)
B(-7,41,-6,minecraft:nether_wart_block)
B(-7,42,-6,minecraft:nether_wart_block)
B(-7,34,-5,minecraft:nether_wart_block)
B(-7,35,-5,minecraft:nether_wart_block)
B(-7,36,-5,minecraft:nether_wart_block)
B(-7,37,-5,minecraft:nether_wart_block)
B(-7,38,-5,minecraft:nether_wart_block)
B(-7,39,-5,minecraft:nether_wart_block)
B(-7,40,-5,minecraft:nether_wart_block)
B(-7,41,-5,minecraft:nether_wart_block)
B(-7,35,-4,minecraft:nether_wart_block)
B(-7,36,-4,minecraft:nether_wart_block)
B(-7,37,-4,minecraft:nether_wart_block)
B(-7,38,-4,minecraft:nether_wart_block)
B(-7,39,-4,minecraft:nether_wart_block)
B(-6,32,-7,minecraft:nether_wart_block)
B(-6,33,-7,minecraft:nether_wart_block)
B(-6,34,-7,minecraft:nether_wart_block)
B(-6,35,-7,minecraft:nether_wart_block)
B(-6,36,-7,minecraft:nether_wart_block)
B(-6,37,-7,minecraft:nether_wart_block)
B(-6,38,-7,minecraft:nether_wart_block)
B(-6,39,-7,minecraft:nether_wart_block)
B(-6,40,-7,minecraft:nether_wart_block)
B(-6,41,-7,minecraft:nether_wart_block)
B(-6,42,-7,minecraft:nether_wart_block)
B(-6,43,-7,minecraft:nether_wart_block)
B(-6,33,-6,minecraft:nether_wart_block)
B(-6,34,-6,minecraft:nether_wart_block)
B(-6,35,-6,minecraft:nether_wart_block)
B(-6,36,-6,minecraft:nether_wart_block)
B(-6,37,-6,minecraft:nether_wart_block)
B(-6,38,-6,minecraft:nether_wart_block)
B(-6,39,-6,minecraft:nether_wart_block)
B(-6,40,-6,minecraft:nether_wart_block)
B(-6,41,-6,minecraft:nether_wart_block)
B(-6,42,-6,minecraft:nether_wart_block)
B(-6,43,-6,minecraft:nether_wart_block)
B(-6,34,-5,minecraft:nether_wart_block)
B(-6,35,-5,minecraft:nether_wart_block)
B(-6,36,-5,minecraft:nether_wart_block)
B(-6,37,-5,minecraft:nether_wart_block)
B(-6,38,-5,minecraft:nether_wart_block)
B(-6,39,-5,minecraft:nether_wart_block)
B(-6,40,-5,minecraft:nether_wart_block)
B(-6,41,-5,minecraft:nether_wart_block)
B(-6,42,-5,minecraft:nether_wart_block)
B(-6,43,-5,minecraft:nether_wart_block)
B(-6,35,-4,minecraft:nether_wart_block)
B(-6,36,-4,minecraft:nether_wart_block)
B(-6,37,-4,minecraft:nether_wart_block)
B(-6,38,-4,minecraft:nether_wart_block)
B(-6,39,-4,minecraft:nether_wart_block)
B(-6,40,-4,minecraft:nether_wart_block)
B(-6,41,-4,minecraft:nether_wart_block)
B(-6,42,-4,minecraft:nether_wart_block)
B(-5,32,-7,minecraft:nether_wart_block)
B(-5,33,-7,minecraft:nether_wart_block)
B(-5,34,-7,minecraft:nether_wart_block)
B(-5,35,-7,minecraft:nether_wart_block)
B(-5,36,-7,minecraft:nether_wart_block)
B(-5,37,-7,minecraft:nether_wart_block)
B(-5,38,-7,minecraft:nether_wart_block)
B(-5,39,-7,minecraft:nether_wart_block)
B(-5,40,-7,minecraft:nether_wart_block)
B(-5,41,-7,minecraft:nether_wart_block)
B(-5,42,-7,minecraft:nether_wart_block)
B(-5,43,-7,minecraft:nether_wart_block)
B(-5,44,-7,minecraft:nether_wart_block)
B(-5,33,-6,minecraft:nether_wart_block)
B(-5,34,-6,minecraft:nether_wart_block)
B(-5,35,-6,minecraft:nether_wart_block)
B(-5,36,-6,minecraft:nether_wart_block)
B(-5,37,-6,minecraft:nether_wart_block)
B(-5,38,-6,minecraft:nether_wart_block)
B(-5,39,-6,minecraft:nether_wart_block)
B(-5,40,-6,minecraft:nether_wart_block)
B(-5,41,-6,minecraft:nether_wart_block)
B(-5,42,-6,minecraft:nether_wart_block)
B(-5,43,-6,minecraft:nether_wart_block)
B(-5,44,-6,minecraft:nether_wart_block)
B(-5,34,-5,minecraft:nether_wart_block)
B(-5,35,-5,minecraft:nether_wart_block)
B(-5,36,-5,minecraft:nether_wart_block)
B(-5,37,-5,minecraft:nether_wart_block)
B(-5,38,-5,minecraft:nether_wart_block)
B(-5,39,-5,minecraft:nether_wart_block)
B(-5,40,-5,minecraft:nether_wart_block)
B(-5,41,-5,minecraft:nether_wart_block)
B(-5,42,-5,minecraft:nether_wart_block)
B(-5,43,-5,minecraft:nether_wart_block)
B(-5,44,-5,minecraft:nether_wart_block)
B(-5,35,-4,minecraft:nether_wart_block)
B(-5,36,-4,minecraft:nether_wart_block)
B(-5,37,-4,minecraft:nether_wart_block)
B(-5,38,-4,minecraft:nether_wart_block)
B(-5,39,-4,minecraft:nether_wart_block)
B(-5,40,-4,minecraft:nether_wart_block)
B(-5,41,-4,minecraft:nether_wart_block)
B(-5,42,-4,minecraft:nether_wart_block)
B(-5,43,-4,minecraft:nether_wart_block)
B(-5,38,-3,minecraft:nether_wart_block)
B(-5,39,-3,minecraft:nether_wart_block)
B(-5,40,-3,minecraft:nether_wart_block)
B(-5,41,-3,minecraft:nether_wart_block)
B(-5,42,-3,minecraft:nether_wart_block)
B(-4,33,-7,minecraft:nether_wart_block)
B(-4,34,-7,minecraft:nether_wart_block)
B(-4,35,-7,minecraft:nether_wart_block)
B(-4,36,-7,minecraft:nether_wart_block)
B(-4,37,-7,minecraft:nether_wart_block)
B(-4,38,-7,minecraft:nether_wart_block)
B(-4,39,-7,minecraft:nether_wart_block)
B(-4,40,-7,minecraft:nether_wart_block)
B(-4,41,-7,minecraft:nether_wart_block)
B(-4,42,-7,minecraft:nether_wart_block)
B(-4,43,-7,minecraft:nether_wart_block)
B(-4,44,-7,minecraft:nether_wart_block)
B(-4,45,-7,minecraft:nether_wart_block)
B(-4,33,-6,minecraft:nether_wart_block)
B(-4,34,-6,minecraft:nether_wart_block)
B(-4,35,-6,minecraft:nether_wart_block)
B(-4,36,-6,minecraft:nether_wart_block)
B(-4,37,-6,minecraft:nether_wart_block)
B(-4,38,-6,minecraft:nether_wart_block)
B(-4,39,-6,minecraft:nether_wart_block)
B(-4,40,-6,minecraft:nether_wart_block)
B(-4,41,-6,minecraft:nether_wart_block)
B(-4,42,-6,minecraft:nether_wart_block)
B(-4,43,-6,minecraft:nether_wart_block)
B(-4,44,-6,minecraft:nether_wart_block)
B(-4,45,-6,minecraft:nether_wart_block)
B(-4,34,-5,minecraft:nether_wart_block)
B(-4,35,-5,minecraft:nether_wart_block)
B(-4,36,-5,minecraft:nether_wart_block)
B(-4,37,-5,minecraft:nether_wart_block)
B(-4,38,-5,minecraft:nether_wart_block)
B(-4,39,-5,minecraft:nether_wart_block)
B(-4,40,-5,minecraft:nether_wart_block)
B(-4,41,-5,minecraft:nether_wart_block)
B(-4,42,-5,minecraft:nether_wart_block)
B(-4,43,-5,minecraft:nether_wart_block)
B(-4,44,-5,minecraft:nether_wart_block)
B(-4,36,-4,minecraft:nether_wart_block)
B(-4,37,-4,minecraft:nether_wart_block)
B(-4,38,-4,minecraft:nether_wart_block)
B(-4,39,-4,minecraft:nether_wart_block)
B(-4,40,-4,minecraft:nether_wart_block)
B(-4,41,-4,minecraft:nether_wart_block)
B(-4,42,-4,minecraft:nether_wart_block)
B(-4,43,-4,minecraft:nether_wart_block)
B(-4,44,-4,minecraft:nether_wart_block)
B(-4,37,-3,minecraft:nether_wart_block)
B(-4,38,-3,minecraft:nether_wart_block)
B(-4,39,-3,minecraft:nether_wart_block)
B(-4,40,-3,minecraft:nether_wart_block)
B(-4,41,-3,minecraft:nether_wart_block)
B(-4,42,-3,minecraft:nether_wart_block)
B(-4,43,-3,minecraft:nether_wart_block)
B(-4,39,-2,minecraft:nether_wart_block)
B(-4,40,-2,minecraft:nether_wart_block)
B(-4,41,-2,minecraft:nether_wart_block)
B(-3,33,-7,minecraft:nether_wart_block)
B(-3,34,-7,minecraft:nether_wart_block)
B(-3,35,-7,minecraft:nether_wart_block)
B(-3,36,-7,minecraft:nether_wart_block)
B(-3,37,-7,minecraft:nether_wart_block)
B(-3,38,-7,minecraft:nether_wart_block)
B(-3,39,-7,minecraft:nether_wart_block)
B(-3,40,-7,minecraft:nether_wart_block)
B(-3,41,-7,minecraft:nether_wart_block)
B(-3,42,-7,minecraft:nether_wart_block)
B(-3,43,-7,minecraft:nether_wart_block)
B(-3,44,-7,minecraft:nether_wart_block)
B(-3,45,-7,minecraft:nether_wart_block)
B(-3,34,-6,minecraft:nether_wart_block)
B(-3,35,-6,minecraft:nether_wart_block)
B(-3,36,-6,minecraft:nether_wart_block)
B(-3,37,-6,minecraft:nether_wart_block)
B(-3,38,-6,minecraft:nether_wart_block)
B(-3,39,-6,minecraft:nether_wart_block)
B(-3,40,-6,minecraft:nether_wart_block)
B(-3,41,-6,minecraft:nether_wart_block)
B(-3,42,-6,minecraft:nether_wart_block)
B(-3,43,-6,minecraft:nether_wart_block)
B(-3,44,-6,minecraft:nether_wart_block)
B(-3,45,-6,minecraft:nether_wart_block)
B(-3,35,-5,minecraft:nether_wart_block)
B(-3,36,-5,minecraft:nether_wart_block)
B(-3,37,-5,minecraft:nether_wart_block)
B(-3,38,-5,minecraft:nether_wart_block)
B(-3,39,-5,minecraft:nether_wart_block)
B(-3,40,-5,minecraft:nether_wart_block)
B(-3,41,-5,minecraft:nether_wart_block)
B(-3,42,-5,minecraft:nether_wart_block)
B(-3,43,-5,minecraft:nether_wart_block)
B(-3,44,-5,minecraft:nether_wart_block)
B(-3,45,-5,minecraft:nether_wart_block)
B(-3,36,-4,minecraft:nether_wart_block)
B(-3,37,-4,minecraft:nether_wart_block)
B(-3,38,-4,minecraft:nether_wart_block)
B(-3,39,-4,minecraft:nether_wart_block)
B(-3,40,-4,minecraft:nether_wart_block)
B(-3,41,-4,minecraft:nether_wart_block)
B(-3,42,-4,minecraft:nether_wart_block)
B(-3,43,-4,minecraft:nether_wart_block)
B(-3,44,-4,minecraft:nether_wart_block)
B(-3,37,-3,minecraft:nether_wart_block)
B(-3,38,-3,minecraft:nether_wart_block)
B(-3,39,-3,minecraft:nether_wart_block)
B(-3,40,-3,minecraft:nether_wart_block)
B(-3,41,-3,minecraft:nether_wart_block)
B(-3,42,-3,minecraft:nether_wart_block)
B(-3,43,-3,minecraft:nether_wart_block)
B(-3,38,-2,minecraft:nether_wart_block)
B(-3,39,-2,minecraft:nether_wart_block)
B(-3,40,-2,minecraft:nether_wart_block)
B(-3,41,-2,minecraft:nether_wart_block)
B(-3,42,-2,minecraft:nether_wart_block)
B(-2,34,-7,minecraft:nether_wart_block)
B(-2,35,-7,minecraft:nether_wart_block)
B(-2,36,-7,minecraft:nether_wart_block)
B(-2,37,-7,minecraft:nether_wart_block)
B(-2,38,-7,minecraft:nether_wart_block)
B(-2,39,-7,minecraft:nether_wart_block)
B(-2,40,-7,minecraft:nether_wart_block)
B(-2,41,-7,minecraft:nether_wart_block)
B(-2,42,-7,minecraft:nether_wart_block)
B(-2,43,-7,minecraft:nether_wart_block)
B(-2,44,-7,minecraft:nether_wart_block)
B(-2,45,-7,minecraft:nether_wart_block)
B(-2,35,-6,minecraft:nether_wart_block)
B(-2,36,-6,minecraft:nether_wart_block)
B(-2,37,-6,minecraft:nether_wart_block)
B(-2,38,-6,minecraft:nether_wart_block)
B(-2,39,-6,minecraft:nether_wart_block)
B(-2,40,-6,minecraft:nether_wart_block)
B(-2,41,-6,minecraft:nether_wart_block)
B(-2,42,-6,minecraft:nether_wart_block)
B(-2,43,-6,minecraft:nether_wart_block)
B(-2,44,-6,minecraft:nether_wart_block)
B(-2,45,-6,minecraft:nether_wart_block)
B(-2,35,-5,minecraft:nether_wart_block)
B(-2,36,-5,minecraft:nether_wart_block)
B(-2,37,-5,minecraft:nether_wart_block)
B(-2,38,-5,minecraft:nether_wart_block)
B(-2,39,-5,minecraft:nether_wart_block)
B(-2,40,-5,minecraft:nether_wart_block)
B(-2,41,-5,minecraft:nether_wart_block)
B(-2,42,-5,minecraft:nether_wart_block)
B(-2,43,-5,minecraft:nether_wart_block)
B(-2,44,-5,minecraft:nether_wart_block)
B(-2,45,-5,minecraft:nether_wart_block)
B(-2,36,-4,minecraft:nether_wart_block)
B(-2,37,-4,minecraft:nether_wart_block)
B(-2,38,-4,minecraft:nether_wart_block)
B(-2,39,-4,minecraft:nether_wart_block)
B(-2,40,-4,minecraft:nether_wart_block)
B(-2,41,-4,minecraft:nether_wart_block)
B(-2,42,-4,minecraft:nether_wart_block)
B(-2,43,-4,minecraft:nether_wart_block)
B(-2,44,-4,minecraft:nether_wart_block)
B(-2,37,-3,minecraft:nether_wart_block)
B(-2,38,-3,minecraft:nether_wart_block)
B(-2,39,-3,minecraft:nether_wart_block)
B(-2,40,-3,minecraft:nether_wart_block)
B(-2,41,-3,minecraft:nether_wart_block)
B(-2,42,-3,minecraft:nether_wart_block)
B(-2,43,-3,minecraft:nether_wart_block)
B(-2,38,-2,minecraft:nether_wart_block)
B(-2,39,-2,minecraft:nether_wart_block)
B(-2,40,-2,minecraft:nether_wart_block)
B(-2,41,-2,minecraft:nether_wart_block)
B(-2,42,-2,minecraft:nether_wart_block)
B(-1,35,-7,minecraft:nether_wart_block)
B(-1,36,-7,minecraft:nether_wart_block)
B(-1,37,-7,minecraft:nether_wart_block)
B(-1,38,-7,minecraft:nether_wart_block)
B(-1,39,-7,minecraft:nether_wart_block)
B(-1,40,-7,minecraft:nether_wart_block)
B(-1,41,-7,minecraft:nether_wart_block)
B(-1,42,-7,minecraft:nether_wart_block)
B(-1,43,-7,minecraft:nether_wart_block)
B(-1,44,-7,minecraft:nether_wart_block)
B(-1,45,-7,minecraft:nether_wart_block)
B(-1,35,-6,minecraft:nether_wart_block)
B(-1,36,-6,minecraft:nether_wart_block)
B(-1,37,-6,minecraft:nether_wart_block)
B(-1,38,-6,minecraft:nether_wart_block)
B(-1,39,-6,minecraft:nether_wart_block)
B(-1,40,-6,minecraft:nether_wart_block)
B(-1,41,-6,minecraft:nether_wart_block)
B(-1,42,-6,minecraft:nether_wart_block)
B(-1,43,-6,minecraft:nether_wart_block)
B(-1,44,-6,minecraft:nether_wart_block)
B(-1,45,-6,minecraft:nether_wart_block)
B(-1,35,-5,minecraft:nether_wart_block)
B(-1,36,-5,minecraft:nether_wart_block)
B(-1,37,-5,minecraft:nether_wart_block)
B(-1,38,-5,minecraft:nether_wart_block)
B(-1,39,-5,minecraft:nether_wart_block)
B(-1,40,-5,minecraft:nether_wart_block)
B(-1,41,-5,minecraft:nether_wart_block)
B(-1,42,-5,minecraft:nether_wart_block)
B(-1,43,-5,minecraft:nether_wart_block)
B(-1,44,-5,minecraft:nether_wart_block)
B(-1,45,-5,minecraft:nether_wart_block)
B(-1,36,-4,minecraft:nether_wart_block)
B(-1,37,-4,minecraft:nether_wart_block)
B(-1,38,-4,minecraft:nether_wart_block)
B(-1,39,-4,minecraft:nether_wart_block)
B(-1,40,-4,minecraft:nether_wart_block)
B(-1,41,-4,minecraft:nether_wart_block)
B(-1,42,-4,minecraft:nether_wart_block)
B(-1,43,-4,minecraft:nether_wart_block)
B(-1,44,-4,minecraft:nether_wart_block)
B(-1,37,-3,minecraft:nether_wart_block)
B(-1,38,-3,minecraft:nether_wart_block)
B(-1,39,-3,minecraft:nether_wart_block)
B(-1,40,-3,minecraft:nether_wart_block)
B(-1,41,-3,minecraft:nether_wart_block)
B(-1,42,-3,minecraft:nether_wart_block)
B(-1,43,-3,minecraft:nether_wart_block)
B(-1,38,-2,minecraft:nether_wart_block)
B(-1,39,-2,minecraft:nether_wart_block)
B(-1,40,-2,minecraft:nether_wart_block)
B(-1,41,-2,minecraft:nether_wart_block)
B(-1,42,-2,minecraft:nether_wart_block)
B(0,35,-7,minecraft:nether_wart_block)
B(0,36,-7,minecraft:nether_wart_block)
B(0,37,-7,minecraft:nether_wart_block)
B(0,38,-7,minecraft:nether_wart_block)
B(0,39,-7,minecraft:nether_wart_block)
B(0,40,-7,minecraft:nether_wart_block)
B(0,41,-7,minecraft:nether_wart_block)
B(0,42,-7,minecraft:nether_wart_block)
B(0,43,-7,minecraft:nether_wart_block)
B(0,44,-7,minecraft:nether_wart_block)
B(0,45,-7,minecraft:nether_wart_block)
B(0,35,-6,minecraft:nether_wart_block)
B(0,36,-6,minecraft:nether_wart_block)
B(0,37,-6,minecraft:nether_wart_block)
B(0,38,-6,minecraft:nether_wart_block)
B(0,39,-6,minecraft:nether_wart_block)
B(0,40,-6,minecraft:nether_wart_block)
B(0,41,-6,minecraft:nether_wart_block)
B(0,42,-6,minecraft:nether_wart_block)
B(0,43,-6,minecraft:nether_wart_block)
B(0,44,-6,minecraft:nether_wart_block)
B(0,45,-6,minecraft:nether_wart_block)
B(0,36,-5,minecraft:nether_wart_block)
B(0,37,-5,minecraft:nether_wart_block)
B(0,38,-5,minecraft:nether_wart_block)
B(0,39,-5,minecraft:nether_wart_block)
B(0,40,-5,minecraft:nether_wart_block)
B(0,41,-5,minecraft:nether_wart_block)
B(0,42,-5,minecraft:nether_wart_block)
B(0,43,-5,minecraft:nether_wart_block)
B(0,44,-5,minecraft:nether_wart_block)
B(0,36,-4,minecraft:nether_wart_block)
B(0,37,-4,minecraft:nether_wart_block)
B(0,38,-4,minecraft:nether_wart_block)
B(0,39,-4,minecraft:nether_wart_block)
B(0,40,-4,minecraft:nether_wart_block)
B(0,41,-4,minecraft:nether_wart_block)
B(0,42,-4,minecraft:nether_wart_block)
B(0,43,-4,minecraft:nether_wart_block)
B(0,44,-4,minecraft:nether_wart_block)
B(0,37,-3,minecraft:nether_wart_block)
B(0,38,-3,minecraft:nether_wart_block)
B(0,39,-3,minecraft:nether_wart_block)
B(0,40,-3,minecraft:nether_wart_block)
B(0,41,-3,minecraft:nether_wart_block)
B(0,42,-3,minecraft:nether_wart_block)
B(0,43,-3,minecraft:nether_wart_block)
B(0,39,-2,minecraft:nether_wart_block)
B(0,40,-2,minecraft:nether_wart_block)
B(0,41,-2,minecraft:nether_wart_block)
B(1,36,-7,minecraft:nether_wart_block)
B(1,37,-7,minecraft:nether_wart_block)
B(1,38,-7,minecraft:nether_wart_block)
B(1,39,-7,minecraft:nether_wart_block)
B(1,40,-7,minecraft:nether_wart_block)
B(1,41,-7,minecraft:nether_wart_block)
B(1,42,-7,minecraft:nether_wart_block)
B(1,43,-7,minecraft:nether_wart_block)
B(1,44,-7,minecraft:nether_wart_block)
B(1,45,-7,minecraft:nether_wart_block)
B(1,36,-6,minecraft:nether_wart_block)
B(1,37,-6,minecraft:nether_wart_block)
B(1,38,-6,minecraft:nether_wart_block)
B(1,39,-6,minecraft:nether_wart_block)
B(1,40,-6,minecraft:nether_wart_block)
B(1,41,-6,minecraft:nether_wart_block)
B(1,42,-6,minecraft:nether_wart_block)
B(1,43,-6,minecraft:nether_wart_block)
B(1,44,-6,minecraft:nether_wart_block)
B(1,36,-5,minecraft:nether_wart_block)
B(1,37,-5,minecraft:nether_wart_block)
B(1,38,-5,minecraft:nether_wart_block)
B(1,39,-5,minecraft:nether_wart_block)
B(1,40,-5,minecraft:nether_wart_block)
B(1,41,-5,minecraft:nether_wart_block)
B(1,42,-5,minecraft:nether_wart_block)
B(1,43,-5,minecraft:nether_wart_block)
B(1,44,-5,minecraft:nether_wart_block)
B(1,37,-4,minecraft:nether_wart_block)
B(1,38,-4,minecraft:nether_wart_block)
B(1,39,-4,minecraft:nether_wart_block)
B(1,40,-4,minecraft:nether_wart_block)
B(1,41,-4,minecraft:nether_wart_block)
B(1,42,-4,minecraft:nether_wart_block)
B(1,43,-4,minecraft:nether_wart_block)
B(1,38,-3,minecraft:nether_wart_block)
B(1,39,-3,minecraft:nether_wart_block)
B(1,40,-3,minecraft:nether_wart_block)
B(1,41,-3,minecraft:nether_wart_block)
B(1,42,-3,minecraft:nether_wart_block)
B(2,37,-7,minecraft:nether_wart_block)
B(2,38,-7,minecraft:nether_wart_block)
B(2,39,-7,minecraft:nether_wart_block)
B(2,40,-7,minecraft:nether_wart_block)
B(2,41,-7,minecraft:nether_wart_block)
B(2,42,-7,minecraft:nether_wart_block)
B(2,43,-7,minecraft:nether_wart_block)
B(2,44,-7,minecraft:nether_wart_block)
B(2,45,-7,minecraft:nether_wart_block)
B(2,37,-6,minecraft:nether_wart_block)
B(2,38,-6,minecraft:nether_wart_block)
B(2,39,-6,minecraft:nether_wart_block)
B(2,40,-6,minecraft:nether_wart_block)
B(2,41,-6,minecraft:nether_wart_block)
B(2,42,-6,minecraft:nether_wart_block)
B(2,43,-6,minecraft:nether_wart_block)
B(2,37,-5,minecraft:nether_wart_block)
B(2,38,-5,minecraft:nether_wart_block)
B(2,39,-5,minecraft:nether_wart_block)
B(2,40,-5,minecraft:nether_wart_block)
B(2,41,-5,minecraft:nether_wart_block)
B(2,42,-5,minecraft:nether_wart_block)
B(2,43,-5,minecraft:nether_wart_block)
B(2,38,-4,minecraft:nether_wart_block)
B(2,39,-4,minecraft:nether_wart_block)
B(2,40,-4,minecraft:nether_wart_block)
B(2,41,-4,minecraft:nether_wart_block)
B(2,42,-4,minecraft:nether_wart_block)
B(3,38,-7,minecraft:nether_wart_block)
B(3,39,-7,minecraft:nether_wart_block)
B(3,40,-7,minecraft:nether_wart_block)
B(3,41,-7,minecraft:nether_wart_block)
B(3,42,-7,minecraft:nether_wart_block)
B(3,43,-7,minecraft:nether_wart_block)
B(3,44,-7,minecraft:nether_wart_block)
B(3,38,-6,minecraft:nether_wart_block)
B(3,39,-6,minecraft:nether_wart_block)
B(3,40,-6,minecraft:nether_wart_block)
B(3,41,-6,minecraft:nether_wart_block)
B(3,42,-6,minecraft:nether_wart_block)
B(3,39,-5,minecraft:nether_wart_block)
B(3,40,-5,minecraft:nether_wart_block)
B(3,41,-5,minecraft:nether_wart_block)

#######################################################################
# +-----------------------------------------------------------------+ #
# |                             Branches                            | #
# +-----------------------------------------------------------------+ #
#######################################################################


#######################################################################
# +-----------------------------------------------------------------+ #
# |                             Entities                            | #
# +-----------------------------------------------------------------+ #
#######################################################################

