
#######################################################################
# +-----------------------------------------------------------------+ #
# |                            BO4 object                           | #
# +-----------------------------------------------------------------+ #
#######################################################################

Author: Unknown

Description: No description given

SettingsMode: WriteWithoutComments


#######################################################################
# +-----------------------------------------------------------------+ #
# |                          Main settings                          | #
# +-----------------------------------------------------------------+ #
#######################################################################

FixedRotation: 

Frequency: 0

SpawnHeight: highestBlock

UseCenterForHighestBlock: true

##############################
# Height Limits for the BO4. #
##############################

MinHeight: 0

MaxHeight: 255

InheritBO3: 

InheritBO3Rotation: NORTH

OverrideChildSettings: true

OverrideParentHeight: false

CanOverride: false

BranchFrequency: 0

BranchFrequencyGroup: 

MustBeBelowOther: false

MustBeInside: 

CannotBeInside: 

ReplacesBO3: 

MustBeInsideWorldBorders: false

CanSpawnOnWater: true

SpawnOnWaterOnly: false

SpawnUnderWater: false

SpawnAtWaterLevel: false

HeightOffset: 0

RemoveAir: true

ReplaceAbove: 

ReplaceBelow: 

ReplaceWithBiomeBlocks: true

ReplaceWithSurfaceBlock: GRASS

ReplaceWithGroundBlock: DIRT

ReplaceWithStoneBlock: STONE

SmoothRadius: 0

SmoothHeightOffset: 0

SmoothStartTop: false

SmoothStartWood: false

SmoothingSurfaceBlock: 

SmoothingGroundBlock: 

BO3Group: 

IsSpawnPoint: false

DoReplaceBlocks: true


#######################################################################
# +-----------------------------------------------------------------+ #
# |                              Blocks                             | #
# +-----------------------------------------------------------------+ #
#######################################################################

B(-8,0,-7,minecraft:soul_soil)
B(-8,1,-7,minecraft:soul_soil)
B(-8,2,-7,minecraft:basalt)
B(-8,0,-6,minecraft:basalt)
B(-8,1,-6,minecraft:basalt)
B(-8,2,-6,minecraft:basalt)
B(-8,3,-6,minecraft:basalt)
B(-8,0,-5,minecraft:basalt)
B(-8,1,-5,minecraft:basalt)
B(-8,2,-5,minecraft:basalt)
B(-8,3,-5,minecraft:basalt)
B(-8,4,-5,minecraft:basalt)
B(-8,5,-5,minecraft:basalt)
B(-8,6,-5,minecraft:basalt)
B(-8,7,-5,minecraft:basalt)
B(-8,8,-5,minecraft:basalt)
B(-8,9,-5,minecraft:basalt)
B(-8,10,-5,minecraft:basalt)
B(-8,11,-5,minecraft:basalt)
B(-8,12,-5,minecraft:basalt)
B(-8,13,-5,minecraft:basalt)
B(-8,14,-5,minecraft:basalt)
B(-8,15,-5,minecraft:basalt)
B(-8,16,-5,minecraft:basalt)
B(-8,17,-5,minecraft:basalt)
B(-8,18,-5,minecraft:basalt)
B(-8,19,-5,minecraft:basalt)
B(-8,20,-5,minecraft:basalt)
B(-8,21,-5,minecraft:basalt)
B(-8,22,-5,minecraft:basalt)
B(-8,23,-5,minecraft:basalt)
B(-8,24,-5,minecraft:basalt)
B(-8,25,-5,minecraft:basalt)
B(-8,26,-5,minecraft:basalt)
B(-8,27,-5,minecraft:basalt)
B(-8,28,-5,minecraft:basalt)
B(-8,29,-5,minecraft:basalt)
B(-8,30,-5,minecraft:basalt)
B(-8,31,-5,minecraft:basalt)
B(-8,32,-5,minecraft:basalt)
B(-8,33,-5,minecraft:basalt)
B(-8,34,-5,minecraft:basalt)
B(-8,35,-5,minecraft:basalt)
B(-8,36,-5,minecraft:basalt)
B(-8,37,-5,minecraft:basalt)
B(-8,38,-5,minecraft:basalt)
B(-8,39,-5,minecraft:basalt)
B(-8,40,-5,minecraft:basalt)
B(-8,0,-4,minecraft:basalt)
B(-8,1,-4,minecraft:basalt)
B(-8,2,-4,minecraft:basalt)
B(-8,3,-4,minecraft:basalt)
B(-8,4,-4,minecraft:basalt)
B(-8,5,-4,minecraft:basalt)
B(-8,6,-4,minecraft:basalt)
B(-8,7,-4,minecraft:basalt)
B(-8,8,-4,minecraft:basalt)
B(-8,9,-4,minecraft:basalt)
B(-8,10,-4,minecraft:basalt)
B(-8,11,-4,minecraft:basalt)
B(-8,12,-4,minecraft:basalt)
B(-8,13,-4,minecraft:basalt)
B(-8,14,-4,minecraft:basalt)
B(-8,15,-4,minecraft:basalt)
B(-8,16,-4,minecraft:basalt)
B(-8,17,-4,minecraft:basalt)
B(-8,18,-4,minecraft:basalt)
B(-8,19,-4,minecraft:basalt)
B(-8,20,-4,minecraft:basalt)
B(-8,21,-4,minecraft:basalt)
B(-8,22,-4,minecraft:basalt)
B(-8,23,-4,minecraft:basalt)
B(-8,24,-4,minecraft:basalt)
B(-8,25,-4,minecraft:basalt)
B(-8,26,-4,minecraft:basalt)
B(-8,27,-4,minecraft:basalt)
B(-8,28,-4,minecraft:basalt)
B(-8,29,-4,minecraft:basalt)
B(-8,30,-4,minecraft:basalt)
B(-8,31,-4,minecraft:basalt)
B(-8,32,-4,minecraft:basalt)
B(-8,33,-4,minecraft:basalt)
B(-8,34,-4,minecraft:basalt)
B(-8,35,-4,minecraft:basalt)
B(-8,36,-4,minecraft:basalt)
B(-8,37,-4,minecraft:basalt)
B(-8,38,-4,minecraft:basalt)
B(-8,39,-4,minecraft:basalt)
B(-8,40,-4,minecraft:basalt)
B(-8,41,-4,minecraft:basalt)
B(-8,42,-4,minecraft:basalt)
B(-8,43,-4,minecraft:basalt)
B(-8,44,-4,minecraft:basalt)
B(-8,45,-4,minecraft:basalt)
B(-8,46,-4,minecraft:basalt)
B(-8,47,-4,minecraft:basalt)
B(-8,48,-4,minecraft:basalt)
B(-8,49,-4,minecraft:basalt)
B(-8,50,-4,minecraft:basalt)
B(-8,51,-4,minecraft:basalt)
B(-8,52,-4,minecraft:basalt)
B(-8,53,-4,minecraft:basalt)
B(-8,54,-4,minecraft:basalt)
B(-8,55,-4,minecraft:basalt)
B(-8,0,-3,minecraft:basalt)
B(-8,1,-3,minecraft:basalt)
B(-8,2,-3,minecraft:basalt)
B(-8,3,-3,minecraft:basalt)
B(-8,4,-3,minecraft:basalt)
B(-8,5,-3,minecraft:basalt)
B(-8,6,-3,minecraft:basalt)
B(-8,7,-3,minecraft:basalt)
B(-8,8,-3,minecraft:basalt)
B(-8,9,-3,minecraft:basalt)
B(-8,10,-3,minecraft:basalt)
B(-8,11,-3,minecraft:basalt)
B(-8,12,-3,minecraft:basalt)
B(-8,13,-3,minecraft:basalt)
B(-8,14,-3,minecraft:basalt)
B(-8,15,-3,minecraft:basalt)
B(-8,16,-3,minecraft:basalt)
B(-8,17,-3,minecraft:basalt)
B(-8,18,-3,minecraft:basalt)
B(-8,19,-3,minecraft:basalt)
B(-8,20,-3,minecraft:basalt)
B(-8,21,-3,minecraft:basalt)
B(-8,22,-3,minecraft:basalt)
B(-8,23,-3,minecraft:basalt)
B(-8,24,-3,minecraft:basalt)
B(-8,25,-3,minecraft:basalt)
B(-8,26,-3,minecraft:basalt)
B(-8,27,-3,minecraft:basalt)
B(-8,28,-3,minecraft:basalt)
B(-8,29,-3,minecraft:basalt)
B(-8,30,-3,minecraft:basalt)
B(-8,31,-3,minecraft:basalt)
B(-8,32,-3,minecraft:basalt)
B(-8,33,-3,minecraft:basalt)
B(-8,34,-3,minecraft:basalt)
B(-8,35,-3,minecraft:basalt)
B(-8,36,-3,minecraft:basalt)
B(-8,37,-3,minecraft:basalt)
B(-8,38,-3,minecraft:basalt)
B(-8,39,-3,minecraft:basalt)
B(-8,40,-3,minecraft:basalt)
B(-8,41,-3,minecraft:basalt)
B(-8,42,-3,minecraft:basalt)
B(-8,43,-3,minecraft:basalt)
B(-8,44,-3,minecraft:basalt)
B(-8,45,-3,minecraft:basalt)
B(-8,46,-3,minecraft:basalt)
B(-8,47,-3,minecraft:basalt)
B(-8,48,-3,minecraft:basalt)
B(-8,49,-3,minecraft:basalt)
B(-8,50,-3,minecraft:basalt)
B(-8,51,-3,minecraft:basalt)
B(-8,52,-3,minecraft:basalt)
B(-8,53,-3,minecraft:basalt)
B(-8,54,-3,minecraft:basalt)
B(-8,55,-3,minecraft:basalt)
B(-8,56,-3,minecraft:basalt)
B(-8,57,-3,minecraft:basalt)
B(-8,58,-3,minecraft:basalt)
B(-8,59,-3,minecraft:basalt)
B(-8,60,-3,minecraft:basalt)
B(-8,61,-3,minecraft:basalt)
B(-8,62,-3,minecraft:basalt)
B(-8,63,-3,minecraft:basalt)
B(-8,64,-3,minecraft:basalt)
B(-8,0,-2,minecraft:basalt)
B(-8,1,-2,minecraft:basalt)
B(-8,2,-2,minecraft:basalt)
B(-8,3,-2,minecraft:basalt)
B(-8,4,-2,minecraft:basalt)
B(-8,5,-2,minecraft:basalt)
B(-8,6,-2,minecraft:basalt)
B(-8,7,-2,minecraft:basalt)
B(-8,8,-2,minecraft:basalt)
B(-8,9,-2,minecraft:basalt)
B(-8,10,-2,minecraft:basalt)
B(-8,11,-2,minecraft:basalt)
B(-8,12,-2,minecraft:basalt)
B(-8,13,-2,minecraft:basalt)
B(-8,14,-2,minecraft:basalt)
B(-8,15,-2,minecraft:basalt)
B(-8,16,-2,minecraft:basalt)
B(-8,17,-2,minecraft:basalt)
B(-8,18,-2,minecraft:basalt)
B(-8,19,-2,minecraft:basalt)
B(-8,20,-2,minecraft:basalt)
B(-8,21,-2,minecraft:basalt)
B(-8,22,-2,minecraft:basalt)
B(-8,23,-2,minecraft:basalt)
B(-8,24,-2,minecraft:basalt)
B(-8,25,-2,minecraft:basalt)
B(-8,26,-2,minecraft:basalt)
B(-8,27,-2,minecraft:basalt)
B(-8,28,-2,minecraft:basalt)
B(-8,29,-2,minecraft:basalt)
B(-8,30,-2,minecraft:basalt)
B(-8,31,-2,minecraft:basalt)
B(-8,32,-2,minecraft:basalt)
B(-8,33,-2,minecraft:basalt)
B(-8,34,-2,minecraft:basalt)
B(-8,35,-2,minecraft:basalt)
B(-8,36,-2,minecraft:basalt)
B(-8,37,-2,minecraft:basalt)
B(-8,38,-2,minecraft:basalt)
B(-8,39,-2,minecraft:basalt)
B(-8,40,-2,minecraft:basalt)
B(-8,41,-2,minecraft:basalt)
B(-8,42,-2,minecraft:basalt)
B(-8,43,-2,minecraft:basalt)
B(-8,44,-2,minecraft:basalt)
B(-8,45,-2,minecraft:basalt)
B(-8,46,-2,minecraft:basalt)
B(-8,47,-2,minecraft:basalt)
B(-8,48,-2,minecraft:basalt)
B(-8,49,-2,minecraft:basalt)
B(-8,50,-2,minecraft:basalt)
B(-8,51,-2,minecraft:basalt)
B(-8,52,-2,minecraft:basalt)
B(-8,53,-2,minecraft:basalt)
B(-8,54,-2,minecraft:basalt)
B(-8,55,-2,minecraft:basalt)
B(-8,56,-2,minecraft:basalt)
B(-8,57,-2,minecraft:basalt)
B(-8,58,-2,minecraft:basalt)
B(-8,59,-2,minecraft:basalt)
B(-8,60,-2,minecraft:basalt)
B(-8,61,-2,minecraft:basalt)
B(-8,62,-2,minecraft:basalt)
B(-8,63,-2,minecraft:basalt)
B(-8,64,-2,minecraft:basalt)
B(-8,0,-1,minecraft:basalt)
B(-8,1,-1,minecraft:basalt)
B(-8,2,-1,minecraft:basalt)
B(-8,3,-1,minecraft:basalt)
B(-8,4,-1,minecraft:basalt)
B(-8,5,-1,minecraft:basalt)
B(-8,6,-1,minecraft:basalt)
B(-8,7,-1,minecraft:basalt)
B(-8,8,-1,minecraft:basalt)
B(-8,9,-1,minecraft:basalt)
B(-8,10,-1,minecraft:basalt)
B(-8,11,-1,minecraft:basalt)
B(-8,12,-1,minecraft:basalt)
B(-8,13,-1,minecraft:basalt)
B(-8,14,-1,minecraft:basalt)
B(-8,15,-1,minecraft:basalt)
B(-8,16,-1,minecraft:basalt)
B(-8,17,-1,minecraft:basalt)
B(-8,18,-1,minecraft:basalt)
B(-8,19,-1,minecraft:basalt)
B(-8,20,-1,minecraft:basalt)
B(-8,21,-1,minecraft:basalt)
B(-8,22,-1,minecraft:basalt)
B(-8,23,-1,minecraft:basalt)
B(-8,24,-1,minecraft:basalt)
B(-8,25,-1,minecraft:basalt)
B(-8,26,-1,minecraft:basalt)
B(-8,27,-1,minecraft:basalt)
B(-8,28,-1,minecraft:basalt)
B(-8,29,-1,minecraft:basalt)
B(-8,30,-1,minecraft:basalt)
B(-8,31,-1,minecraft:basalt)
B(-8,32,-1,minecraft:basalt)
B(-8,33,-1,minecraft:basalt)
B(-8,34,-1,minecraft:basalt)
B(-8,35,-1,minecraft:basalt)
B(-8,36,-1,minecraft:basalt)
B(-8,37,-1,minecraft:basalt)
B(-8,38,-1,minecraft:basalt)
B(-8,39,-1,minecraft:basalt)
B(-8,40,-1,minecraft:basalt)
B(-8,41,-1,minecraft:basalt)
B(-8,42,-1,minecraft:basalt)
B(-8,43,-1,minecraft:basalt)
B(-8,44,-1,minecraft:basalt)
B(-8,45,-1,minecraft:basalt)
B(-8,46,-1,minecraft:basalt)
B(-8,47,-1,minecraft:basalt)
B(-8,48,-1,minecraft:basalt)
B(-8,49,-1,minecraft:basalt)
B(-8,50,-1,minecraft:basalt)
B(-8,51,-1,minecraft:basalt)
B(-8,52,-1,minecraft:basalt)
B(-8,53,-1,minecraft:basalt)
B(-8,54,-1,minecraft:basalt)
B(-8,55,-1,minecraft:basalt)
B(-8,56,-1,minecraft:basalt)
B(-8,57,-1,minecraft:basalt)
B(-8,58,-1,minecraft:basalt)
B(-8,59,-1,minecraft:basalt)
B(-8,60,-1,minecraft:basalt)
B(-8,61,-1,minecraft:basalt)
B(-8,62,-1,minecraft:basalt)
B(-8,63,-1,minecraft:basalt)
B(-8,64,-1,minecraft:basalt)
B(-8,0,0,minecraft:basalt)
B(-8,1,0,minecraft:basalt)
B(-8,2,0,minecraft:basalt)
B(-8,3,0,minecraft:basalt)
B(-8,4,0,minecraft:basalt)
B(-8,5,0,minecraft:basalt)
B(-8,6,0,minecraft:basalt)
B(-8,7,0,minecraft:basalt)
B(-8,8,0,minecraft:basalt)
B(-8,9,0,minecraft:basalt)
B(-8,10,0,minecraft:basalt)
B(-8,11,0,minecraft:basalt)
B(-8,12,0,minecraft:basalt)
B(-8,13,0,minecraft:basalt)
B(-8,14,0,minecraft:basalt)
B(-8,15,0,minecraft:basalt)
B(-8,16,0,minecraft:basalt)
B(-8,17,0,minecraft:basalt)
B(-8,18,0,minecraft:basalt)
B(-8,19,0,minecraft:basalt)
B(-8,20,0,minecraft:basalt)
B(-8,21,0,minecraft:basalt)
B(-8,22,0,minecraft:basalt)
B(-8,23,0,minecraft:basalt)
B(-8,24,0,minecraft:basalt)
B(-8,25,0,minecraft:basalt)
B(-8,26,0,minecraft:basalt)
B(-8,27,0,minecraft:basalt)
B(-8,28,0,minecraft:basalt)
B(-8,29,0,minecraft:basalt)
B(-8,30,0,minecraft:basalt)
B(-8,31,0,minecraft:basalt)
B(-8,32,0,minecraft:basalt)
B(-8,33,0,minecraft:basalt)
B(-8,34,0,minecraft:basalt)
B(-8,35,0,minecraft:basalt)
B(-8,36,0,minecraft:basalt)
B(-8,37,0,minecraft:basalt)
B(-8,38,0,minecraft:basalt)
B(-8,39,0,minecraft:basalt)
B(-8,40,0,minecraft:basalt)
B(-8,41,0,minecraft:basalt)
B(-8,42,0,minecraft:basalt)
B(-8,43,0,minecraft:basalt)
B(-8,44,0,minecraft:basalt)
B(-8,45,0,minecraft:basalt)
B(-8,46,0,minecraft:basalt)
B(-8,47,0,minecraft:basalt)
B(-8,48,0,minecraft:basalt)
B(-8,49,0,minecraft:basalt)
B(-8,50,0,minecraft:basalt)
B(-8,51,0,minecraft:basalt)
B(-8,52,0,minecraft:basalt)
B(-8,53,0,minecraft:basalt)
B(-8,54,0,minecraft:basalt)
B(-8,55,0,minecraft:basalt)
B(-8,56,0,minecraft:basalt)
B(-8,57,0,minecraft:basalt)
B(-8,58,0,minecraft:basalt)
B(-8,59,0,minecraft:basalt)
B(-8,60,0,minecraft:basalt)
B(-8,61,0,minecraft:basalt)
B(-8,62,0,minecraft:basalt)
B(-8,63,0,minecraft:basalt)
B(-8,64,0,minecraft:basalt)
B(-8,0,1,minecraft:basalt)
B(-8,1,1,minecraft:basalt)
B(-8,2,1,minecraft:basalt)
B(-8,3,1,minecraft:basalt)
B(-8,4,1,minecraft:basalt)
B(-8,5,1,minecraft:basalt)
B(-8,6,1,minecraft:basalt)
B(-8,7,1,minecraft:basalt)
B(-8,8,1,minecraft:basalt)
B(-8,9,1,minecraft:basalt)
B(-8,10,1,minecraft:basalt)
B(-8,11,1,minecraft:basalt)
B(-8,12,1,minecraft:basalt)
B(-8,13,1,minecraft:basalt)
B(-8,14,1,minecraft:basalt)
B(-8,15,1,minecraft:basalt)
B(-8,16,1,minecraft:basalt)
B(-8,17,1,minecraft:basalt)
B(-8,18,1,minecraft:basalt)
B(-8,19,1,minecraft:basalt)
B(-8,20,1,minecraft:basalt)
B(-8,21,1,minecraft:basalt)
B(-8,22,1,minecraft:basalt)
B(-8,23,1,minecraft:basalt)
B(-8,24,1,minecraft:basalt)
B(-8,25,1,minecraft:basalt)
B(-8,26,1,minecraft:basalt)
B(-8,27,1,minecraft:basalt)
B(-8,28,1,minecraft:basalt)
B(-8,29,1,minecraft:basalt)
B(-8,30,1,minecraft:basalt)
B(-8,31,1,minecraft:basalt)
B(-8,32,1,minecraft:basalt)
B(-8,33,1,minecraft:basalt)
B(-8,34,1,minecraft:basalt)
B(-8,35,1,minecraft:basalt)
B(-8,36,1,minecraft:basalt)
B(-8,37,1,minecraft:basalt)
B(-8,38,1,minecraft:basalt)
B(-8,39,1,minecraft:basalt)
B(-8,40,1,minecraft:basalt)
B(-8,41,1,minecraft:basalt)
B(-8,42,1,minecraft:basalt)
B(-8,43,1,minecraft:basalt)
B(-8,44,1,minecraft:basalt)
B(-8,45,1,minecraft:basalt)
B(-8,46,1,minecraft:basalt)
B(-8,47,1,minecraft:basalt)
B(-8,48,1,minecraft:basalt)
B(-8,49,1,minecraft:basalt)
B(-8,50,1,minecraft:basalt)
B(-8,51,1,minecraft:basalt)
B(-8,52,1,minecraft:basalt)
B(-8,53,1,minecraft:basalt)
B(-8,54,1,minecraft:basalt)
B(-8,55,1,minecraft:basalt)
B(-8,56,1,minecraft:basalt)
B(-8,57,1,minecraft:basalt)
B(-8,58,1,minecraft:basalt)
B(-8,59,1,minecraft:basalt)
B(-8,60,1,minecraft:basalt)
B(-8,61,1,minecraft:basalt)
B(-8,62,1,minecraft:basalt)
B(-8,63,1,minecraft:basalt)
B(-8,64,1,minecraft:basalt)
B(-8,65,1,minecraft:basalt)
B(-8,0,2,minecraft:basalt)
B(-8,1,2,minecraft:basalt)
B(-8,2,2,minecraft:basalt)
B(-8,3,2,minecraft:basalt)
B(-8,4,2,minecraft:basalt)
B(-8,5,2,minecraft:basalt)
B(-8,6,2,minecraft:basalt)
B(-8,7,2,minecraft:basalt)
B(-8,8,2,minecraft:basalt)
B(-8,9,2,minecraft:basalt)
B(-8,10,2,minecraft:basalt)
B(-8,11,2,minecraft:basalt)
B(-8,12,2,minecraft:basalt)
B(-8,13,2,minecraft:basalt)
B(-8,14,2,minecraft:basalt)
B(-8,15,2,minecraft:basalt)
B(-8,16,2,minecraft:basalt)
B(-8,17,2,minecraft:basalt)
B(-8,18,2,minecraft:basalt)
B(-8,19,2,minecraft:basalt)
B(-8,20,2,minecraft:basalt)
B(-8,21,2,minecraft:basalt)
B(-8,22,2,minecraft:basalt)
B(-8,23,2,minecraft:basalt)
B(-8,24,2,minecraft:basalt)
B(-8,25,2,minecraft:basalt)
B(-8,26,2,minecraft:basalt)
B(-8,27,2,minecraft:basalt)
B(-8,28,2,minecraft:basalt)
B(-8,29,2,minecraft:basalt)
B(-8,30,2,minecraft:basalt)
B(-8,31,2,minecraft:basalt)
B(-8,32,2,minecraft:basalt)
B(-8,33,2,minecraft:basalt)
B(-8,34,2,minecraft:basalt)
B(-8,35,2,minecraft:basalt)
B(-8,36,2,minecraft:basalt)
B(-8,37,2,minecraft:basalt)
B(-8,38,2,minecraft:basalt)
B(-8,39,2,minecraft:basalt)
B(-8,40,2,minecraft:basalt)
B(-8,41,2,minecraft:basalt)
B(-8,42,2,minecraft:basalt)
B(-8,43,2,minecraft:basalt)
B(-8,44,2,minecraft:basalt)
B(-8,45,2,minecraft:basalt)
B(-8,46,2,minecraft:basalt)
B(-8,47,2,minecraft:basalt)
B(-8,48,2,minecraft:basalt)
B(-8,49,2,minecraft:basalt)
B(-8,50,2,minecraft:basalt)
B(-8,51,2,minecraft:basalt)
B(-8,52,2,minecraft:basalt)
B(-8,53,2,minecraft:basalt)
B(-8,54,2,minecraft:basalt)
B(-8,55,2,minecraft:basalt)
B(-8,56,2,minecraft:basalt)
B(-8,57,2,minecraft:basalt)
B(-8,58,2,minecraft:basalt)
B(-8,59,2,minecraft:basalt)
B(-8,60,2,minecraft:basalt)
B(-8,61,2,minecraft:basalt)
B(-8,62,2,minecraft:basalt)
B(-8,63,2,minecraft:basalt)
B(-8,64,2,minecraft:basalt)
B(-8,65,2,minecraft:basalt)
B(-8,0,3,minecraft:basalt)
B(-8,1,3,minecraft:basalt)
B(-8,2,3,minecraft:basalt)
B(-8,3,3,minecraft:basalt)
B(-8,4,3,minecraft:basalt)
B(-8,5,3,minecraft:basalt)
B(-8,6,3,minecraft:basalt)
B(-8,7,3,minecraft:basalt)
B(-8,8,3,minecraft:basalt)
B(-8,9,3,minecraft:basalt)
B(-8,10,3,minecraft:basalt)
B(-8,11,3,minecraft:basalt)
B(-8,12,3,minecraft:basalt)
B(-8,13,3,minecraft:basalt)
B(-8,14,3,minecraft:basalt)
B(-8,15,3,minecraft:basalt)
B(-8,16,3,minecraft:basalt)
B(-8,17,3,minecraft:basalt)
B(-8,18,3,minecraft:basalt)
B(-8,19,3,minecraft:basalt)
B(-8,20,3,minecraft:basalt)
B(-8,21,3,minecraft:basalt)
B(-8,22,3,minecraft:basalt)
B(-8,23,3,minecraft:basalt)
B(-8,24,3,minecraft:basalt)
B(-8,25,3,minecraft:basalt)
B(-8,26,3,minecraft:basalt)
B(-8,27,3,minecraft:basalt)
B(-8,28,3,minecraft:basalt)
B(-8,29,3,minecraft:basalt)
B(-8,30,3,minecraft:basalt)
B(-8,31,3,minecraft:basalt)
B(-8,32,3,minecraft:basalt)
B(-8,33,3,minecraft:basalt)
B(-8,34,3,minecraft:basalt)
B(-8,35,3,minecraft:basalt)
B(-8,36,3,minecraft:basalt)
B(-8,37,3,minecraft:basalt)
B(-8,38,3,minecraft:basalt)
B(-8,39,3,minecraft:basalt)
B(-8,40,3,minecraft:basalt)
B(-8,41,3,minecraft:basalt)
B(-8,42,3,minecraft:basalt)
B(-8,43,3,minecraft:basalt)
B(-8,44,3,minecraft:basalt)
B(-8,45,3,minecraft:basalt)
B(-8,46,3,minecraft:basalt)
B(-8,47,3,minecraft:basalt)
B(-8,48,3,minecraft:basalt)
B(-8,49,3,minecraft:basalt)
B(-8,50,3,minecraft:basalt)
B(-8,51,3,minecraft:basalt)
B(-8,52,3,minecraft:basalt)
B(-8,53,3,minecraft:basalt)
B(-8,54,3,minecraft:basalt)
B(-8,55,3,minecraft:basalt)
B(-8,56,3,minecraft:basalt)
B(-8,57,3,minecraft:basalt)
B(-8,58,3,minecraft:basalt)
B(-8,59,3,minecraft:basalt)
B(-8,60,3,minecraft:basalt)
B(-8,61,3,minecraft:basalt)
B(-8,62,3,minecraft:basalt)
B(-8,63,3,minecraft:basalt)
B(-8,64,3,minecraft:basalt)
B(-8,65,3,minecraft:basalt)
B(-8,0,4,minecraft:basalt)
B(-8,1,4,minecraft:basalt)
B(-8,2,4,minecraft:basalt)
B(-8,3,4,minecraft:basalt)
B(-8,4,4,minecraft:basalt)
B(-8,5,4,minecraft:basalt)
B(-8,6,4,minecraft:basalt)
B(-8,7,4,minecraft:basalt)
B(-8,8,4,minecraft:basalt)
B(-8,9,4,minecraft:basalt)
B(-8,10,4,minecraft:basalt)
B(-8,11,4,minecraft:basalt)
B(-8,12,4,minecraft:basalt)
B(-8,13,4,minecraft:basalt)
B(-8,14,4,minecraft:basalt)
B(-8,15,4,minecraft:basalt)
B(-8,16,4,minecraft:basalt)
B(-8,17,4,minecraft:basalt)
B(-8,18,4,minecraft:basalt)
B(-8,19,4,minecraft:basalt)
B(-8,20,4,minecraft:basalt)
B(-8,21,4,minecraft:basalt)
B(-8,22,4,minecraft:basalt)
B(-8,23,4,minecraft:basalt)
B(-8,24,4,minecraft:basalt)
B(-8,25,4,minecraft:basalt)
B(-8,26,4,minecraft:basalt)
B(-8,27,4,minecraft:basalt)
B(-8,28,4,minecraft:basalt)
B(-8,29,4,minecraft:basalt)
B(-8,30,4,minecraft:basalt)
B(-8,31,4,minecraft:basalt)
B(-8,32,4,minecraft:basalt)
B(-8,33,4,minecraft:basalt)
B(-8,34,4,minecraft:basalt)
B(-8,35,4,minecraft:basalt)
B(-8,36,4,minecraft:basalt)
B(-8,37,4,minecraft:basalt)
B(-8,38,4,minecraft:basalt)
B(-8,39,4,minecraft:basalt)
B(-8,40,4,minecraft:basalt)
B(-8,41,4,minecraft:basalt)
B(-8,42,4,minecraft:basalt)
B(-8,43,4,minecraft:basalt)
B(-8,44,4,minecraft:basalt)
B(-8,45,4,minecraft:basalt)
B(-8,46,4,minecraft:basalt)
B(-8,47,4,minecraft:basalt)
B(-8,48,4,minecraft:basalt)
B(-8,49,4,minecraft:basalt)
B(-8,50,4,minecraft:basalt)
B(-8,51,4,minecraft:basalt)
B(-8,52,4,minecraft:basalt)
B(-8,53,4,minecraft:basalt)
B(-8,54,4,minecraft:basalt)
B(-8,55,4,minecraft:basalt)
B(-8,56,4,minecraft:basalt)
B(-8,57,4,minecraft:basalt)
B(-8,58,4,minecraft:basalt)
B(-8,59,4,minecraft:basalt)
B(-8,60,4,minecraft:basalt)
B(-8,61,4,minecraft:basalt)
B(-8,62,4,minecraft:basalt)
B(-8,63,4,minecraft:basalt)
B(-8,64,4,minecraft:basalt)
B(-8,65,4,minecraft:basalt)
B(-7,0,-7,minecraft:basalt)
B(-7,1,-7,minecraft:soul_soil)
B(-7,2,-7,minecraft:soul_soil)
B(-7,3,-7,minecraft:basalt)
B(-7,0,-6,minecraft:basalt)
B(-7,1,-6,minecraft:basalt)
B(-7,2,-6,minecraft:soul_soil)
B(-7,3,-6,minecraft:soul_soil)
B(-7,4,-6,minecraft:basalt)
B(-7,0,-5,minecraft:basalt)
B(-7,1,-5,minecraft:basalt)
B(-7,2,-5,minecraft:basalt)
B(-7,3,-5,minecraft:basalt)
B(-7,4,-5,minecraft:basalt)
B(-7,0,-4,minecraft:basalt)
B(-7,1,-4,minecraft:basalt)
B(-7,2,-4,minecraft:basalt)
B(-7,3,-4,minecraft:basalt)
B(-7,4,-4,minecraft:basalt)
B(-7,5,-4,minecraft:basalt)
B(-7,6,-4,minecraft:basalt)
B(-7,7,-4,minecraft:basalt)
B(-7,8,-4,minecraft:basalt)
B(-7,9,-4,minecraft:basalt)
B(-7,10,-4,minecraft:basalt)
B(-7,11,-4,minecraft:basalt)
B(-7,12,-4,minecraft:basalt)
B(-7,13,-4,minecraft:basalt)
B(-7,14,-4,minecraft:basalt)
B(-7,15,-4,minecraft:basalt)
B(-7,16,-4,minecraft:basalt)
B(-7,17,-4,minecraft:basalt)
B(-7,18,-4,minecraft:basalt)
B(-7,19,-4,minecraft:basalt)
B(-7,20,-4,minecraft:basalt)
B(-7,21,-4,minecraft:basalt)
B(-7,22,-4,minecraft:basalt)
B(-7,23,-4,minecraft:basalt)
B(-7,24,-4,minecraft:basalt)
B(-7,25,-4,minecraft:basalt)
B(-7,26,-4,minecraft:basalt)
B(-7,27,-4,minecraft:basalt)
B(-7,28,-4,minecraft:basalt)
B(-7,29,-4,minecraft:basalt)
B(-7,30,-4,minecraft:basalt)
B(-7,31,-4,minecraft:basalt)
B(-7,32,-4,minecraft:basalt)
B(-7,33,-4,minecraft:basalt)
B(-7,34,-4,minecraft:basalt)
B(-7,35,-4,minecraft:basalt)
B(-7,36,-4,minecraft:basalt)
B(-7,37,-4,minecraft:basalt)
B(-7,38,-4,minecraft:basalt)
B(-7,39,-4,minecraft:basalt)
B(-7,40,-4,minecraft:basalt)
B(-7,41,-4,minecraft:basalt)
B(-7,42,-4,minecraft:basalt)
B(-7,43,-4,minecraft:basalt)
B(-7,0,-3,minecraft:basalt)
B(-7,1,-3,minecraft:basalt)
B(-7,2,-3,minecraft:basalt)
B(-7,3,-3,minecraft:basalt)
B(-7,4,-3,minecraft:basalt)
B(-7,5,-3,minecraft:basalt)
B(-7,6,-3,minecraft:basalt)
B(-7,7,-3,minecraft:basalt)
B(-7,8,-3,minecraft:basalt)
B(-7,9,-3,minecraft:basalt)
B(-7,10,-3,minecraft:basalt)
B(-7,11,-3,minecraft:basalt)
B(-7,12,-3,minecraft:basalt)
B(-7,13,-3,minecraft:basalt)
B(-7,14,-3,minecraft:basalt)
B(-7,15,-3,minecraft:basalt)
B(-7,16,-3,minecraft:basalt)
B(-7,17,-3,minecraft:basalt)
B(-7,18,-3,minecraft:basalt)
B(-7,19,-3,minecraft:basalt)
B(-7,20,-3,minecraft:basalt)
B(-7,21,-3,minecraft:basalt)
B(-7,22,-3,minecraft:basalt)
B(-7,23,-3,minecraft:basalt)
B(-7,24,-3,minecraft:basalt)
B(-7,25,-3,minecraft:basalt)
B(-7,26,-3,minecraft:basalt)
B(-7,27,-3,minecraft:basalt)
B(-7,28,-3,minecraft:basalt)
B(-7,29,-3,minecraft:basalt)
B(-7,30,-3,minecraft:basalt)
B(-7,31,-3,minecraft:basalt)
B(-7,32,-3,minecraft:basalt)
B(-7,33,-3,minecraft:basalt)
B(-7,34,-3,minecraft:basalt)
B(-7,35,-3,minecraft:basalt)
B(-7,36,-3,minecraft:basalt)
B(-7,37,-3,minecraft:basalt)
B(-7,38,-3,minecraft:basalt)
B(-7,39,-3,minecraft:basalt)
B(-7,40,-3,minecraft:basalt)
B(-7,41,-3,minecraft:basalt)
B(-7,42,-3,minecraft:basalt)
B(-7,43,-3,minecraft:basalt)
B(-7,44,-3,minecraft:basalt)
B(-7,45,-3,minecraft:basalt)
B(-7,46,-3,minecraft:basalt)
B(-7,47,-3,minecraft:basalt)
B(-7,48,-3,minecraft:basalt)
B(-7,49,-3,minecraft:basalt)
B(-7,50,-3,minecraft:basalt)
B(-7,51,-3,minecraft:basalt)
B(-7,52,-3,minecraft:basalt)
B(-7,53,-3,minecraft:basalt)
B(-7,54,-3,minecraft:basalt)
B(-7,55,-3,minecraft:basalt)
B(-7,56,-3,minecraft:basalt)
B(-7,57,-3,minecraft:basalt)
B(-7,58,-3,minecraft:basalt)
B(-7,59,-3,minecraft:basalt)
B(-7,60,-3,minecraft:basalt)
B(-7,61,-3,minecraft:basalt)
B(-7,0,-2,minecraft:basalt)
B(-7,1,-2,minecraft:basalt)
B(-7,2,-2,minecraft:basalt)
B(-7,3,-2,minecraft:basalt)
B(-7,4,-2,minecraft:basalt)
B(-7,5,-2,minecraft:basalt)
B(-7,6,-2,minecraft:basalt)
B(-7,7,-2,minecraft:basalt)
B(-7,8,-2,minecraft:basalt)
B(-7,9,-2,minecraft:basalt)
B(-7,10,-2,minecraft:basalt)
B(-7,11,-2,minecraft:basalt)
B(-7,12,-2,minecraft:basalt)
B(-7,13,-2,minecraft:basalt)
B(-7,14,-2,minecraft:basalt)
B(-7,15,-2,minecraft:basalt)
B(-7,16,-2,minecraft:basalt)
B(-7,17,-2,minecraft:basalt)
B(-7,18,-2,minecraft:basalt)
B(-7,19,-2,minecraft:basalt)
B(-7,20,-2,minecraft:basalt)
B(-7,21,-2,minecraft:basalt)
B(-7,22,-2,minecraft:basalt)
B(-7,23,-2,minecraft:basalt)
B(-7,24,-2,minecraft:basalt)
B(-7,25,-2,minecraft:basalt)
B(-7,26,-2,minecraft:basalt)
B(-7,27,-2,minecraft:basalt)
B(-7,28,-2,minecraft:basalt)
B(-7,29,-2,minecraft:basalt)
B(-7,30,-2,minecraft:basalt)
B(-7,31,-2,minecraft:basalt)
B(-7,32,-2,minecraft:basalt)
B(-7,33,-2,minecraft:basalt)
B(-7,34,-2,minecraft:basalt)
B(-7,35,-2,minecraft:basalt)
B(-7,36,-2,minecraft:basalt)
B(-7,37,-2,minecraft:basalt)
B(-7,38,-2,minecraft:basalt)
B(-7,39,-2,minecraft:basalt)
B(-7,40,-2,minecraft:basalt)
B(-7,41,-2,minecraft:basalt)
B(-7,42,-2,minecraft:basalt)
B(-7,43,-2,minecraft:basalt)
B(-7,44,-2,minecraft:basalt)
B(-7,45,-2,minecraft:basalt)
B(-7,46,-2,minecraft:basalt)
B(-7,47,-2,minecraft:basalt)
B(-7,48,-2,minecraft:basalt)
B(-7,49,-2,minecraft:basalt)
B(-7,50,-2,minecraft:basalt)
B(-7,51,-2,minecraft:basalt)
B(-7,52,-2,minecraft:basalt)
B(-7,53,-2,minecraft:basalt)
B(-7,54,-2,minecraft:basalt)
B(-7,55,-2,minecraft:basalt)
B(-7,56,-2,minecraft:basalt)
B(-7,57,-2,minecraft:basalt)
B(-7,58,-2,minecraft:basalt)
B(-7,59,-2,minecraft:basalt)
B(-7,60,-2,minecraft:basalt)
B(-7,61,-2,minecraft:basalt)
B(-7,62,-2,minecraft:basalt)
B(-7,63,-2,minecraft:basalt)
B(-7,0,-1,minecraft:basalt)
B(-7,1,-1,minecraft:basalt)
B(-7,2,-1,minecraft:basalt)
B(-7,3,-1,minecraft:basalt)
B(-7,4,-1,minecraft:basalt)
B(-7,5,-1,minecraft:basalt)
B(-7,6,-1,minecraft:basalt)
B(-7,7,-1,minecraft:basalt)
B(-7,8,-1,minecraft:basalt)
B(-7,9,-1,minecraft:basalt)
B(-7,10,-1,minecraft:basalt)
B(-7,11,-1,minecraft:basalt)
B(-7,12,-1,minecraft:basalt)
B(-7,13,-1,minecraft:basalt)
B(-7,14,-1,minecraft:basalt)
B(-7,15,-1,minecraft:basalt)
B(-7,16,-1,minecraft:basalt)
B(-7,17,-1,minecraft:basalt)
B(-7,18,-1,minecraft:basalt)
B(-7,19,-1,minecraft:basalt)
B(-7,20,-1,minecraft:basalt)
B(-7,21,-1,minecraft:basalt)
B(-7,22,-1,minecraft:basalt)
B(-7,23,-1,minecraft:basalt)
B(-7,24,-1,minecraft:basalt)
B(-7,25,-1,minecraft:basalt)
B(-7,26,-1,minecraft:basalt)
B(-7,27,-1,minecraft:basalt)
B(-7,28,-1,minecraft:basalt)
B(-7,29,-1,minecraft:basalt)
B(-7,30,-1,minecraft:basalt)
B(-7,31,-1,minecraft:basalt)
B(-7,32,-1,minecraft:basalt)
B(-7,33,-1,minecraft:basalt)
B(-7,34,-1,minecraft:basalt)
B(-7,35,-1,minecraft:basalt)
B(-7,36,-1,minecraft:basalt)
B(-7,37,-1,minecraft:basalt)
B(-7,38,-1,minecraft:basalt)
B(-7,39,-1,minecraft:basalt)
B(-7,40,-1,minecraft:basalt)
B(-7,41,-1,minecraft:basalt)
B(-7,42,-1,minecraft:basalt)
B(-7,43,-1,minecraft:basalt)
B(-7,44,-1,minecraft:basalt)
B(-7,45,-1,minecraft:basalt)
B(-7,46,-1,minecraft:basalt)
B(-7,47,-1,minecraft:basalt)
B(-7,48,-1,minecraft:basalt)
B(-7,49,-1,minecraft:basalt)
B(-7,50,-1,minecraft:basalt)
B(-7,51,-1,minecraft:basalt)
B(-7,52,-1,minecraft:basalt)
B(-7,53,-1,minecraft:basalt)
B(-7,54,-1,minecraft:basalt)
B(-7,55,-1,minecraft:basalt)
B(-7,56,-1,minecraft:basalt)
B(-7,57,-1,minecraft:basalt)
B(-7,58,-1,minecraft:basalt)
B(-7,59,-1,minecraft:basalt)
B(-7,60,-1,minecraft:basalt)
B(-7,61,-1,minecraft:basalt)
B(-7,62,-1,minecraft:basalt)
B(-7,63,-1,minecraft:basalt)
B(-7,64,-1,minecraft:basalt)
B(-7,0,0,minecraft:basalt)
B(-7,1,0,minecraft:basalt)
B(-7,2,0,minecraft:basalt)
B(-7,3,0,minecraft:basalt)
B(-7,4,0,minecraft:basalt)
B(-7,5,0,minecraft:basalt)
B(-7,6,0,minecraft:basalt)
B(-7,7,0,minecraft:basalt)
B(-7,8,0,minecraft:basalt)
B(-7,9,0,minecraft:basalt)
B(-7,10,0,minecraft:basalt)
B(-7,11,0,minecraft:basalt)
B(-7,12,0,minecraft:basalt)
B(-7,13,0,minecraft:basalt)
B(-7,14,0,minecraft:basalt)
B(-7,15,0,minecraft:basalt)
B(-7,16,0,minecraft:basalt)
B(-7,17,0,minecraft:basalt)
B(-7,18,0,minecraft:basalt)
B(-7,19,0,minecraft:basalt)
B(-7,20,0,minecraft:basalt)
B(-7,21,0,minecraft:basalt)
B(-7,22,0,minecraft:basalt)
B(-7,23,0,minecraft:basalt)
B(-7,24,0,minecraft:basalt)
B(-7,25,0,minecraft:basalt)
B(-7,26,0,minecraft:basalt)
B(-7,27,0,minecraft:basalt)
B(-7,28,0,minecraft:basalt)
B(-7,29,0,minecraft:basalt)
B(-7,30,0,minecraft:basalt)
B(-7,31,0,minecraft:basalt)
B(-7,32,0,minecraft:basalt)
B(-7,33,0,minecraft:basalt)
B(-7,34,0,minecraft:basalt)
B(-7,35,0,minecraft:basalt)
B(-7,36,0,minecraft:basalt)
B(-7,37,0,minecraft:basalt)
B(-7,38,0,minecraft:basalt)
B(-7,39,0,minecraft:basalt)
B(-7,40,0,minecraft:basalt)
B(-7,41,0,minecraft:basalt)
B(-7,42,0,minecraft:basalt)
B(-7,43,0,minecraft:basalt)
B(-7,44,0,minecraft:basalt)
B(-7,45,0,minecraft:basalt)
B(-7,46,0,minecraft:basalt)
B(-7,47,0,minecraft:basalt)
B(-7,48,0,minecraft:basalt)
B(-7,49,0,minecraft:basalt)
B(-7,50,0,minecraft:basalt)
B(-7,51,0,minecraft:basalt)
B(-7,52,0,minecraft:basalt)
B(-7,53,0,minecraft:basalt)
B(-7,54,0,minecraft:basalt)
B(-7,55,0,minecraft:basalt)
B(-7,56,0,minecraft:basalt)
B(-7,57,0,minecraft:basalt)
B(-7,58,0,minecraft:basalt)
B(-7,59,0,minecraft:basalt)
B(-7,60,0,minecraft:basalt)
B(-7,61,0,minecraft:basalt)
B(-7,62,0,minecraft:basalt)
B(-7,63,0,minecraft:basalt)
B(-7,64,0,minecraft:basalt)
B(-7,65,0,minecraft:basalt)
B(-7,0,1,minecraft:basalt)
B(-7,1,1,minecraft:basalt)
B(-7,2,1,minecraft:basalt)
B(-7,3,1,minecraft:basalt)
B(-7,4,1,minecraft:basalt)
B(-7,5,1,minecraft:basalt)
B(-7,6,1,minecraft:basalt)
B(-7,7,1,minecraft:basalt)
B(-7,8,1,minecraft:basalt)
B(-7,9,1,minecraft:basalt)
B(-7,10,1,minecraft:basalt)
B(-7,11,1,minecraft:basalt)
B(-7,12,1,minecraft:basalt)
B(-7,13,1,minecraft:basalt)
B(-7,14,1,minecraft:basalt)
B(-7,15,1,minecraft:basalt)
B(-7,16,1,minecraft:basalt)
B(-7,17,1,minecraft:basalt)
B(-7,18,1,minecraft:basalt)
B(-7,19,1,minecraft:basalt)
B(-7,20,1,minecraft:basalt)
B(-7,21,1,minecraft:basalt)
B(-7,22,1,minecraft:basalt)
B(-7,23,1,minecraft:basalt)
B(-7,24,1,minecraft:basalt)
B(-7,25,1,minecraft:basalt)
B(-7,26,1,minecraft:basalt)
B(-7,27,1,minecraft:basalt)
B(-7,28,1,minecraft:basalt)
B(-7,29,1,minecraft:basalt)
B(-7,30,1,minecraft:basalt)
B(-7,31,1,minecraft:basalt)
B(-7,32,1,minecraft:basalt)
B(-7,33,1,minecraft:basalt)
B(-7,34,1,minecraft:basalt)
B(-7,35,1,minecraft:basalt)
B(-7,36,1,minecraft:basalt)
B(-7,37,1,minecraft:basalt)
B(-7,38,1,minecraft:basalt)
B(-7,39,1,minecraft:basalt)
B(-7,40,1,minecraft:basalt)
B(-7,41,1,minecraft:basalt)
B(-7,42,1,minecraft:basalt)
B(-7,43,1,minecraft:basalt)
B(-7,44,1,minecraft:basalt)
B(-7,45,1,minecraft:basalt)
B(-7,46,1,minecraft:basalt)
B(-7,47,1,minecraft:basalt)
B(-7,48,1,minecraft:basalt)
B(-7,49,1,minecraft:basalt)
B(-7,50,1,minecraft:basalt)
B(-7,51,1,minecraft:basalt)
B(-7,52,1,minecraft:basalt)
B(-7,53,1,minecraft:basalt)
B(-7,54,1,minecraft:basalt)
B(-7,55,1,minecraft:basalt)
B(-7,56,1,minecraft:basalt)
B(-7,57,1,minecraft:basalt)
B(-7,58,1,minecraft:basalt)
B(-7,59,1,minecraft:basalt)
B(-7,60,1,minecraft:basalt)
B(-7,61,1,minecraft:basalt)
B(-7,62,1,minecraft:basalt)
B(-7,63,1,minecraft:basalt)
B(-7,64,1,minecraft:basalt)
B(-7,65,1,minecraft:basalt)
B(-7,66,1,minecraft:basalt)
B(-7,67,1,minecraft:basalt)
B(-7,0,2,minecraft:basalt)
B(-7,1,2,minecraft:basalt)
B(-7,2,2,minecraft:basalt)
B(-7,3,2,minecraft:basalt)
B(-7,4,2,minecraft:basalt)
B(-7,5,2,minecraft:basalt)
B(-7,6,2,minecraft:basalt)
B(-7,7,2,minecraft:basalt)
B(-7,8,2,minecraft:basalt)
B(-7,9,2,minecraft:basalt)
B(-7,10,2,minecraft:basalt)
B(-7,11,2,minecraft:basalt)
B(-7,12,2,minecraft:basalt)
B(-7,13,2,minecraft:basalt)
B(-7,14,2,minecraft:basalt)
B(-7,15,2,minecraft:basalt)
B(-7,16,2,minecraft:basalt)
B(-7,17,2,minecraft:basalt)
B(-7,18,2,minecraft:basalt)
B(-7,19,2,minecraft:basalt)
B(-7,20,2,minecraft:basalt)
B(-7,21,2,minecraft:basalt)
B(-7,22,2,minecraft:basalt)
B(-7,23,2,minecraft:basalt)
B(-7,24,2,minecraft:basalt)
B(-7,25,2,minecraft:basalt)
B(-7,26,2,minecraft:basalt)
B(-7,27,2,minecraft:basalt)
B(-7,28,2,minecraft:basalt)
B(-7,29,2,minecraft:basalt)
B(-7,30,2,minecraft:basalt)
B(-7,31,2,minecraft:basalt)
B(-7,32,2,minecraft:basalt)
B(-7,33,2,minecraft:basalt)
B(-7,34,2,minecraft:basalt)
B(-7,35,2,minecraft:basalt)
B(-7,36,2,minecraft:basalt)
B(-7,37,2,minecraft:basalt)
B(-7,38,2,minecraft:basalt)
B(-7,39,2,minecraft:basalt)
B(-7,40,2,minecraft:basalt)
B(-7,41,2,minecraft:basalt)
B(-7,42,2,minecraft:basalt)
B(-7,43,2,minecraft:basalt)
B(-7,44,2,minecraft:basalt)
B(-7,45,2,minecraft:basalt)
B(-7,46,2,minecraft:basalt)
B(-7,47,2,minecraft:basalt)
B(-7,48,2,minecraft:basalt)
B(-7,49,2,minecraft:basalt)
B(-7,50,2,minecraft:basalt)
B(-7,51,2,minecraft:basalt)
B(-7,52,2,minecraft:basalt)
B(-7,53,2,minecraft:basalt)
B(-7,54,2,minecraft:basalt)
B(-7,55,2,minecraft:basalt)
B(-7,56,2,minecraft:basalt)
B(-7,57,2,minecraft:basalt)
B(-7,58,2,minecraft:basalt)
B(-7,59,2,minecraft:basalt)
B(-7,60,2,minecraft:basalt)
B(-7,61,2,minecraft:basalt)
B(-7,62,2,minecraft:basalt)
B(-7,63,2,minecraft:basalt)
B(-7,64,2,minecraft:basalt)
B(-7,65,2,minecraft:basalt)
B(-7,66,2,minecraft:basalt)
B(-7,67,2,minecraft:basalt)
B(-7,0,3,minecraft:basalt)
B(-7,1,3,minecraft:basalt)
B(-7,2,3,minecraft:basalt)
B(-7,3,3,minecraft:basalt)
B(-7,4,3,minecraft:basalt)
B(-7,5,3,minecraft:basalt)
B(-7,6,3,minecraft:basalt)
B(-7,7,3,minecraft:basalt)
B(-7,8,3,minecraft:basalt)
B(-7,9,3,minecraft:basalt)
B(-7,10,3,minecraft:basalt)
B(-7,11,3,minecraft:basalt)
B(-7,12,3,minecraft:basalt)
B(-7,13,3,minecraft:basalt)
B(-7,14,3,minecraft:basalt)
B(-7,15,3,minecraft:basalt)
B(-7,16,3,minecraft:basalt)
B(-7,17,3,minecraft:basalt)
B(-7,18,3,minecraft:basalt)
B(-7,19,3,minecraft:basalt)
B(-7,20,3,minecraft:basalt)
B(-7,21,3,minecraft:basalt)
B(-7,22,3,minecraft:basalt)
B(-7,23,3,minecraft:basalt)
B(-7,24,3,minecraft:basalt)
B(-7,25,3,minecraft:basalt)
B(-7,26,3,minecraft:basalt)
B(-7,27,3,minecraft:basalt)
B(-7,28,3,minecraft:basalt)
B(-7,29,3,minecraft:basalt)
B(-7,30,3,minecraft:basalt)
B(-7,31,3,minecraft:basalt)
B(-7,32,3,minecraft:basalt)
B(-7,33,3,minecraft:basalt)
B(-7,34,3,minecraft:basalt)
B(-7,35,3,minecraft:basalt)
B(-7,36,3,minecraft:basalt)
B(-7,37,3,minecraft:basalt)
B(-7,38,3,minecraft:basalt)
B(-7,39,3,minecraft:basalt)
B(-7,40,3,minecraft:basalt)
B(-7,41,3,minecraft:basalt)
B(-7,42,3,minecraft:basalt)
B(-7,43,3,minecraft:basalt)
B(-7,44,3,minecraft:basalt)
B(-7,45,3,minecraft:basalt)
B(-7,46,3,minecraft:basalt)
B(-7,47,3,minecraft:basalt)
B(-7,48,3,minecraft:basalt)
B(-7,49,3,minecraft:basalt)
B(-7,50,3,minecraft:basalt)
B(-7,51,3,minecraft:basalt)
B(-7,52,3,minecraft:basalt)
B(-7,53,3,minecraft:basalt)
B(-7,54,3,minecraft:basalt)
B(-7,55,3,minecraft:basalt)
B(-7,56,3,minecraft:basalt)
B(-7,57,3,minecraft:basalt)
B(-7,58,3,minecraft:basalt)
B(-7,59,3,minecraft:basalt)
B(-7,60,3,minecraft:basalt)
B(-7,61,3,minecraft:basalt)
B(-7,62,3,minecraft:basalt)
B(-7,63,3,minecraft:basalt)
B(-7,64,3,minecraft:basalt)
B(-7,65,3,minecraft:basalt)
B(-7,66,3,minecraft:basalt)
B(-7,67,3,minecraft:basalt)
B(-7,0,6,minecraft:basalt)
B(-7,1,6,minecraft:basalt)
B(-7,2,6,minecraft:basalt)
B(-7,3,6,minecraft:basalt)
B(-7,4,6,minecraft:basalt)
B(-7,5,6,minecraft:basalt)
B(-7,6,6,minecraft:basalt)
B(-7,7,6,minecraft:basalt)
B(-7,8,6,minecraft:basalt)
B(-7,9,6,minecraft:basalt)
B(-7,10,6,minecraft:basalt)
B(-7,11,6,minecraft:basalt)
B(-7,12,6,minecraft:basalt)
B(-7,13,6,minecraft:basalt)
B(-7,14,6,minecraft:basalt)
B(-7,15,6,minecraft:basalt)
B(-7,16,6,minecraft:basalt)
B(-7,17,6,minecraft:basalt)
B(-7,18,6,minecraft:basalt)
B(-7,19,6,minecraft:basalt)
B(-7,20,6,minecraft:basalt)
B(-7,21,6,minecraft:basalt)
B(-7,22,6,minecraft:basalt)
B(-7,23,6,minecraft:basalt)
B(-7,24,6,minecraft:basalt)
B(-7,25,6,minecraft:basalt)
B(-7,26,6,minecraft:basalt)
B(-7,27,6,minecraft:basalt)
B(-7,28,6,minecraft:basalt)
B(-7,29,6,minecraft:basalt)
B(-7,30,6,minecraft:basalt)
B(-7,31,6,minecraft:basalt)
B(-6,0,-7,minecraft:basalt)
B(-6,1,-7,minecraft:basalt)
B(-6,2,-7,minecraft:soul_soil)
B(-6,3,-7,minecraft:soul_soil)
B(-6,4,-7,minecraft:basalt)
B(-6,0,-6,minecraft:basalt)
B(-6,1,-6,minecraft:basalt)
B(-6,2,-6,minecraft:basalt)
B(-6,3,-6,minecraft:soul_soil)
B(-6,4,-6,minecraft:soul_soil)
B(-6,5,-6,minecraft:basalt)
B(-6,0,-5,minecraft:basalt)
B(-6,1,-5,minecraft:basalt)
B(-6,2,-5,minecraft:basalt)
B(-6,3,-5,minecraft:soul_soil)
B(-6,4,-5,minecraft:soul_soil)
B(-6,5,-5,minecraft:basalt)
B(-6,0,-4,minecraft:basalt)
B(-6,1,-4,minecraft:basalt)
B(-6,2,-4,minecraft:basalt)
B(-6,3,-4,minecraft:basalt)
B(-6,4,-4,minecraft:basalt)
B(-6,0,-3,minecraft:basalt)
B(-6,1,-3,minecraft:basalt)
B(-6,2,-3,minecraft:basalt)
B(-6,3,-3,minecraft:basalt)
B(-6,4,-3,minecraft:basalt)
B(-6,5,-3,minecraft:basalt)
B(-6,6,-3,minecraft:basalt)
B(-6,7,-3,minecraft:basalt)
B(-6,8,-3,minecraft:basalt)
B(-6,9,-3,minecraft:basalt)
B(-6,10,-3,minecraft:basalt)
B(-6,11,-3,minecraft:basalt)
B(-6,12,-3,minecraft:basalt)
B(-6,13,-3,minecraft:basalt)
B(-6,14,-3,minecraft:basalt)
B(-6,15,-3,minecraft:basalt)
B(-6,16,-3,minecraft:basalt)
B(-6,17,-3,minecraft:basalt)
B(-6,18,-3,minecraft:basalt)
B(-6,19,-3,minecraft:basalt)
B(-6,20,-3,minecraft:basalt)
B(-6,21,-3,minecraft:basalt)
B(-6,22,-3,minecraft:basalt)
B(-6,23,-3,minecraft:basalt)
B(-6,24,-3,minecraft:basalt)
B(-6,25,-3,minecraft:basalt)
B(-6,26,-3,minecraft:basalt)
B(-6,27,-3,minecraft:basalt)
B(-6,28,-3,minecraft:basalt)
B(-6,29,-3,minecraft:basalt)
B(-6,30,-3,minecraft:basalt)
B(-6,31,-3,minecraft:basalt)
B(-6,32,-3,minecraft:basalt)
B(-6,33,-3,minecraft:basalt)
B(-6,34,-3,minecraft:basalt)
B(-6,35,-3,minecraft:basalt)
B(-6,36,-3,minecraft:basalt)
B(-6,37,-3,minecraft:basalt)
B(-6,38,-3,minecraft:basalt)
B(-6,39,-3,minecraft:basalt)
B(-6,40,-3,minecraft:basalt)
B(-6,41,-3,minecraft:basalt)
B(-6,42,-3,minecraft:basalt)
B(-6,43,-3,minecraft:basalt)
B(-6,44,-3,minecraft:basalt)
B(-6,45,-3,minecraft:basalt)
B(-6,0,-2,minecraft:basalt)
B(-6,1,-2,minecraft:basalt)
B(-6,2,-2,minecraft:basalt)
B(-6,3,-2,minecraft:basalt)
B(-6,4,-2,minecraft:basalt)
B(-6,5,-2,minecraft:basalt)
B(-6,6,-2,minecraft:basalt)
B(-6,7,-2,minecraft:basalt)
B(-6,8,-2,minecraft:basalt)
B(-6,9,-2,minecraft:basalt)
B(-6,10,-2,minecraft:basalt)
B(-6,11,-2,minecraft:basalt)
B(-6,12,-2,minecraft:basalt)
B(-6,13,-2,minecraft:basalt)
B(-6,14,-2,minecraft:basalt)
B(-6,15,-2,minecraft:basalt)
B(-6,16,-2,minecraft:basalt)
B(-6,17,-2,minecraft:basalt)
B(-6,18,-2,minecraft:basalt)
B(-6,19,-2,minecraft:basalt)
B(-6,20,-2,minecraft:basalt)
B(-6,21,-2,minecraft:basalt)
B(-6,22,-2,minecraft:basalt)
B(-6,23,-2,minecraft:basalt)
B(-6,24,-2,minecraft:basalt)
B(-6,25,-2,minecraft:basalt)
B(-6,26,-2,minecraft:basalt)
B(-6,27,-2,minecraft:basalt)
B(-6,28,-2,minecraft:basalt)
B(-6,29,-2,minecraft:basalt)
B(-6,30,-2,minecraft:basalt)
B(-6,31,-2,minecraft:basalt)
B(-6,32,-2,minecraft:basalt)
B(-6,33,-2,minecraft:basalt)
B(-6,34,-2,minecraft:basalt)
B(-6,35,-2,minecraft:basalt)
B(-6,36,-2,minecraft:basalt)
B(-6,37,-2,minecraft:basalt)
B(-6,38,-2,minecraft:basalt)
B(-6,39,-2,minecraft:basalt)
B(-6,40,-2,minecraft:basalt)
B(-6,41,-2,minecraft:basalt)
B(-6,42,-2,minecraft:basalt)
B(-6,43,-2,minecraft:basalt)
B(-6,44,-2,minecraft:basalt)
B(-6,45,-2,minecraft:basalt)
B(-6,46,-2,minecraft:basalt)
B(-6,47,-2,minecraft:basalt)
B(-6,48,-2,minecraft:basalt)
B(-6,49,-2,minecraft:basalt)
B(-6,50,-2,minecraft:basalt)
B(-6,51,-2,minecraft:basalt)
B(-6,52,-2,minecraft:basalt)
B(-6,53,-2,minecraft:basalt)
B(-6,54,-2,minecraft:basalt)
B(-6,55,-2,minecraft:basalt)
B(-6,56,-2,minecraft:basalt)
B(-6,57,-2,minecraft:basalt)
B(-6,58,-2,minecraft:basalt)
B(-6,59,-2,minecraft:basalt)
B(-6,60,-2,minecraft:basalt)
B(-6,61,-2,minecraft:basalt)
B(-6,62,-2,minecraft:basalt)
B(-6,63,-2,minecraft:basalt)
B(-6,0,-1,minecraft:basalt)
B(-6,1,-1,minecraft:basalt)
B(-6,2,-1,minecraft:basalt)
B(-6,3,-1,minecraft:basalt)
B(-6,4,-1,minecraft:basalt)
B(-6,5,-1,minecraft:basalt)
B(-6,6,-1,minecraft:basalt)
B(-6,7,-1,minecraft:basalt)
B(-6,8,-1,minecraft:basalt)
B(-6,9,-1,minecraft:basalt)
B(-6,10,-1,minecraft:basalt)
B(-6,11,-1,minecraft:basalt)
B(-6,12,-1,minecraft:basalt)
B(-6,13,-1,minecraft:basalt)
B(-6,14,-1,minecraft:basalt)
B(-6,15,-1,minecraft:basalt)
B(-6,16,-1,minecraft:basalt)
B(-6,17,-1,minecraft:basalt)
B(-6,18,-1,minecraft:basalt)
B(-6,19,-1,minecraft:basalt)
B(-6,20,-1,minecraft:basalt)
B(-6,21,-1,minecraft:basalt)
B(-6,22,-1,minecraft:basalt)
B(-6,23,-1,minecraft:basalt)
B(-6,24,-1,minecraft:basalt)
B(-6,25,-1,minecraft:basalt)
B(-6,26,-1,minecraft:basalt)
B(-6,27,-1,minecraft:basalt)
B(-6,28,-1,minecraft:basalt)
B(-6,29,-1,minecraft:basalt)
B(-6,30,-1,minecraft:basalt)
B(-6,31,-1,minecraft:basalt)
B(-6,32,-1,minecraft:basalt)
B(-6,33,-1,minecraft:basalt)
B(-6,34,-1,minecraft:basalt)
B(-6,35,-1,minecraft:basalt)
B(-6,36,-1,minecraft:basalt)
B(-6,37,-1,minecraft:basalt)
B(-6,38,-1,minecraft:basalt)
B(-6,39,-1,minecraft:basalt)
B(-6,40,-1,minecraft:basalt)
B(-6,41,-1,minecraft:basalt)
B(-6,42,-1,minecraft:basalt)
B(-6,43,-1,minecraft:basalt)
B(-6,44,-1,minecraft:basalt)
B(-6,45,-1,minecraft:basalt)
B(-6,46,-1,minecraft:basalt)
B(-6,47,-1,minecraft:basalt)
B(-6,48,-1,minecraft:basalt)
B(-6,49,-1,minecraft:basalt)
B(-6,50,-1,minecraft:basalt)
B(-6,51,-1,minecraft:basalt)
B(-6,52,-1,minecraft:basalt)
B(-6,53,-1,minecraft:basalt)
B(-6,54,-1,minecraft:basalt)
B(-6,55,-1,minecraft:basalt)
B(-6,56,-1,minecraft:basalt)
B(-6,57,-1,minecraft:basalt)
B(-6,58,-1,minecraft:basalt)
B(-6,59,-1,minecraft:basalt)
B(-6,60,-1,minecraft:basalt)
B(-6,61,-1,minecraft:basalt)
B(-6,62,-1,minecraft:basalt)
B(-6,63,-1,minecraft:basalt)
B(-6,64,-1,minecraft:basalt)
B(-6,65,-1,minecraft:basalt)
B(-6,0,0,minecraft:basalt)
B(-6,1,0,minecraft:basalt)
B(-6,2,0,minecraft:basalt)
B(-6,3,0,minecraft:basalt)
B(-6,4,0,minecraft:basalt)
B(-6,5,0,minecraft:basalt)
B(-6,6,0,minecraft:basalt)
B(-6,7,0,minecraft:basalt)
B(-6,8,0,minecraft:basalt)
B(-6,9,0,minecraft:basalt)
B(-6,10,0,minecraft:basalt)
B(-6,11,0,minecraft:basalt)
B(-6,12,0,minecraft:basalt)
B(-6,13,0,minecraft:basalt)
B(-6,14,0,minecraft:basalt)
B(-6,15,0,minecraft:basalt)
B(-6,16,0,minecraft:basalt)
B(-6,17,0,minecraft:basalt)
B(-6,18,0,minecraft:basalt)
B(-6,19,0,minecraft:basalt)
B(-6,20,0,minecraft:basalt)
B(-6,21,0,minecraft:basalt)
B(-6,22,0,minecraft:basalt)
B(-6,23,0,minecraft:basalt)
B(-6,24,0,minecraft:basalt)
B(-6,25,0,minecraft:basalt)
B(-6,26,0,minecraft:basalt)
B(-6,27,0,minecraft:basalt)
B(-6,28,0,minecraft:basalt)
B(-6,29,0,minecraft:basalt)
B(-6,30,0,minecraft:basalt)
B(-6,31,0,minecraft:basalt)
B(-6,32,0,minecraft:basalt)
B(-6,33,0,minecraft:basalt)
B(-6,34,0,minecraft:basalt)
B(-6,35,0,minecraft:basalt)
B(-6,36,0,minecraft:basalt)
B(-6,37,0,minecraft:basalt)
B(-6,38,0,minecraft:basalt)
B(-6,39,0,minecraft:basalt)
B(-6,40,0,minecraft:basalt)
B(-6,41,0,minecraft:basalt)
B(-6,42,0,minecraft:basalt)
B(-6,43,0,minecraft:basalt)
B(-6,44,0,minecraft:basalt)
B(-6,45,0,minecraft:basalt)
B(-6,46,0,minecraft:basalt)
B(-6,47,0,minecraft:basalt)
B(-6,48,0,minecraft:basalt)
B(-6,49,0,minecraft:basalt)
B(-6,50,0,minecraft:basalt)
B(-6,51,0,minecraft:basalt)
B(-6,52,0,minecraft:basalt)
B(-6,53,0,minecraft:basalt)
B(-6,54,0,minecraft:basalt)
B(-6,55,0,minecraft:basalt)
B(-6,56,0,minecraft:basalt)
B(-6,57,0,minecraft:basalt)
B(-6,58,0,minecraft:basalt)
B(-6,59,0,minecraft:basalt)
B(-6,60,0,minecraft:basalt)
B(-6,61,0,minecraft:basalt)
B(-6,62,0,minecraft:basalt)
B(-6,63,0,minecraft:basalt)
B(-6,64,0,minecraft:basalt)
B(-6,65,0,minecraft:basalt)
B(-6,66,0,minecraft:basalt)
B(-6,67,0,minecraft:basalt)
B(-6,0,1,minecraft:basalt)
B(-6,1,1,minecraft:basalt)
B(-6,2,1,minecraft:basalt)
B(-6,3,1,minecraft:basalt)
B(-6,4,1,minecraft:basalt)
B(-6,5,1,minecraft:basalt)
B(-6,6,1,minecraft:basalt)
B(-6,7,1,minecraft:basalt)
B(-6,8,1,minecraft:basalt)
B(-6,9,1,minecraft:basalt)
B(-6,10,1,minecraft:basalt)
B(-6,11,1,minecraft:basalt)
B(-6,12,1,minecraft:basalt)
B(-6,13,1,minecraft:basalt)
B(-6,14,1,minecraft:basalt)
B(-6,15,1,minecraft:basalt)
B(-6,16,1,minecraft:basalt)
B(-6,17,1,minecraft:basalt)
B(-6,18,1,minecraft:basalt)
B(-6,19,1,minecraft:basalt)
B(-6,20,1,minecraft:basalt)
B(-6,21,1,minecraft:basalt)
B(-6,22,1,minecraft:basalt)
B(-6,23,1,minecraft:basalt)
B(-6,24,1,minecraft:basalt)
B(-6,25,1,minecraft:basalt)
B(-6,26,1,minecraft:basalt)
B(-6,27,1,minecraft:basalt)
B(-6,28,1,minecraft:basalt)
B(-6,29,1,minecraft:basalt)
B(-6,30,1,minecraft:basalt)
B(-6,31,1,minecraft:basalt)
B(-6,32,1,minecraft:basalt)
B(-6,33,1,minecraft:basalt)
B(-6,34,1,minecraft:basalt)
B(-6,35,1,minecraft:basalt)
B(-6,36,1,minecraft:basalt)
B(-6,37,1,minecraft:basalt)
B(-6,38,1,minecraft:basalt)
B(-6,39,1,minecraft:basalt)
B(-6,40,1,minecraft:basalt)
B(-6,41,1,minecraft:basalt)
B(-6,42,1,minecraft:basalt)
B(-6,43,1,minecraft:basalt)
B(-6,44,1,minecraft:basalt)
B(-6,45,1,minecraft:basalt)
B(-6,46,1,minecraft:basalt)
B(-6,47,1,minecraft:basalt)
B(-6,48,1,minecraft:basalt)
B(-6,49,1,minecraft:basalt)
B(-6,50,1,minecraft:basalt)
B(-6,51,1,minecraft:basalt)
B(-6,52,1,minecraft:basalt)
B(-6,53,1,minecraft:basalt)
B(-6,54,1,minecraft:basalt)
B(-6,55,1,minecraft:basalt)
B(-6,56,1,minecraft:basalt)
B(-6,57,1,minecraft:basalt)
B(-6,58,1,minecraft:basalt)
B(-6,59,1,minecraft:basalt)
B(-6,60,1,minecraft:basalt)
B(-6,61,1,minecraft:basalt)
B(-6,62,1,minecraft:basalt)
B(-6,63,1,minecraft:basalt)
B(-6,64,1,minecraft:basalt)
B(-6,65,1,minecraft:basalt)
B(-6,66,1,minecraft:basalt)
B(-6,67,1,minecraft:basalt)
B(-6,0,2,minecraft:basalt)
B(-6,1,2,minecraft:basalt)
B(-6,2,2,minecraft:basalt)
B(-6,3,2,minecraft:basalt)
B(-6,4,2,minecraft:basalt)
B(-6,5,2,minecraft:basalt)
B(-6,6,2,minecraft:basalt)
B(-6,7,2,minecraft:basalt)
B(-6,8,2,minecraft:basalt)
B(-6,9,2,minecraft:basalt)
B(-6,10,2,minecraft:basalt)
B(-6,11,2,minecraft:basalt)
B(-6,12,2,minecraft:basalt)
B(-6,13,2,minecraft:basalt)
B(-6,14,2,minecraft:basalt)
B(-6,15,2,minecraft:basalt)
B(-6,16,2,minecraft:basalt)
B(-6,17,2,minecraft:basalt)
B(-6,18,2,minecraft:basalt)
B(-6,19,2,minecraft:basalt)
B(-6,20,2,minecraft:basalt)
B(-6,21,2,minecraft:basalt)
B(-6,22,2,minecraft:basalt)
B(-6,23,2,minecraft:basalt)
B(-6,24,2,minecraft:basalt)
B(-6,25,2,minecraft:basalt)
B(-6,26,2,minecraft:basalt)
B(-6,27,2,minecraft:basalt)
B(-6,28,2,minecraft:basalt)
B(-6,29,2,minecraft:basalt)
B(-6,30,2,minecraft:basalt)
B(-6,31,2,minecraft:basalt)
B(-6,32,2,minecraft:basalt)
B(-6,33,2,minecraft:basalt)
B(-6,34,2,minecraft:basalt)
B(-6,35,2,minecraft:basalt)
B(-6,36,2,minecraft:basalt)
B(-6,37,2,minecraft:basalt)
B(-6,38,2,minecraft:basalt)
B(-6,39,2,minecraft:basalt)
B(-6,40,2,minecraft:basalt)
B(-6,41,2,minecraft:basalt)
B(-6,42,2,minecraft:basalt)
B(-6,43,2,minecraft:basalt)
B(-6,44,2,minecraft:basalt)
B(-6,45,2,minecraft:basalt)
B(-6,46,2,minecraft:basalt)
B(-6,47,2,minecraft:basalt)
B(-6,48,2,minecraft:basalt)
B(-6,49,2,minecraft:basalt)
B(-6,50,2,minecraft:basalt)
B(-6,51,2,minecraft:basalt)
B(-6,52,2,minecraft:basalt)
B(-6,53,2,minecraft:basalt)
B(-6,54,2,minecraft:basalt)
B(-6,55,2,minecraft:basalt)
B(-6,56,2,minecraft:basalt)
B(-6,57,2,minecraft:basalt)
B(-6,58,2,minecraft:basalt)
B(-6,59,2,minecraft:basalt)
B(-6,60,2,minecraft:basalt)
B(-6,61,2,minecraft:basalt)
B(-6,62,2,minecraft:basalt)
B(-6,63,2,minecraft:basalt)
B(-6,64,2,minecraft:basalt)
B(-6,65,2,minecraft:basalt)
B(-6,66,2,minecraft:basalt)
B(-6,67,2,minecraft:basalt)
B(-6,68,2,minecraft:basalt)
B(-6,0,3,minecraft:basalt)
B(-6,1,3,minecraft:basalt)
B(-6,2,3,minecraft:basalt)
B(-6,3,3,minecraft:basalt)
B(-6,4,3,minecraft:basalt)
B(-6,5,3,minecraft:basalt)
B(-6,6,3,minecraft:basalt)
B(-6,7,3,minecraft:basalt)
B(-6,8,3,minecraft:basalt)
B(-6,9,3,minecraft:basalt)
B(-6,10,3,minecraft:basalt)
B(-6,11,3,minecraft:basalt)
B(-6,12,3,minecraft:basalt)
B(-6,13,3,minecraft:basalt)
B(-6,14,3,minecraft:basalt)
B(-6,15,3,minecraft:basalt)
B(-6,16,3,minecraft:basalt)
B(-6,17,3,minecraft:basalt)
B(-6,18,3,minecraft:basalt)
B(-6,19,3,minecraft:basalt)
B(-6,20,3,minecraft:basalt)
B(-6,21,3,minecraft:basalt)
B(-6,22,3,minecraft:basalt)
B(-6,23,3,minecraft:basalt)
B(-6,24,3,minecraft:basalt)
B(-6,25,3,minecraft:basalt)
B(-6,26,3,minecraft:basalt)
B(-6,27,3,minecraft:basalt)
B(-6,28,3,minecraft:basalt)
B(-6,29,3,minecraft:basalt)
B(-6,30,3,minecraft:basalt)
B(-6,31,3,minecraft:basalt)
B(-6,32,3,minecraft:basalt)
B(-6,33,3,minecraft:basalt)
B(-6,34,3,minecraft:basalt)
B(-6,35,3,minecraft:basalt)
B(-6,36,3,minecraft:basalt)
B(-6,37,3,minecraft:basalt)
B(-6,38,3,minecraft:basalt)
B(-6,39,3,minecraft:basalt)
B(-6,40,3,minecraft:basalt)
B(-6,41,3,minecraft:basalt)
B(-6,42,3,minecraft:basalt)
B(-6,43,3,minecraft:basalt)
B(-6,44,3,minecraft:basalt)
B(-6,45,3,minecraft:basalt)
B(-6,46,3,minecraft:basalt)
B(-6,47,3,minecraft:basalt)
B(-6,48,3,minecraft:basalt)
B(-6,49,3,minecraft:basalt)
B(-6,50,3,minecraft:basalt)
B(-6,51,3,minecraft:basalt)
B(-6,52,3,minecraft:basalt)
B(-6,53,3,minecraft:basalt)
B(-6,54,3,minecraft:basalt)
B(-6,55,3,minecraft:basalt)
B(-6,56,3,minecraft:basalt)
B(-6,57,3,minecraft:basalt)
B(-6,58,3,minecraft:basalt)
B(-6,59,3,minecraft:basalt)
B(-6,60,3,minecraft:basalt)
B(-6,61,3,minecraft:basalt)
B(-6,62,3,minecraft:basalt)
B(-6,63,3,minecraft:basalt)
B(-6,64,3,minecraft:basalt)
B(-6,65,3,minecraft:basalt)
B(-6,66,3,minecraft:basalt)
B(-6,67,3,minecraft:basalt)
B(-6,68,3,minecraft:basalt)
B(-6,0,6,minecraft:basalt)
B(-6,1,6,minecraft:basalt)
B(-6,2,6,minecraft:basalt)
B(-6,3,6,minecraft:basalt)
B(-6,4,6,minecraft:basalt)
B(-6,5,6,minecraft:basalt)
B(-6,6,6,minecraft:basalt)
B(-6,7,6,minecraft:basalt)
B(-6,8,6,minecraft:basalt)
B(-6,9,6,minecraft:basalt)
B(-6,10,6,minecraft:basalt)
B(-6,11,6,minecraft:basalt)
B(-6,12,6,minecraft:basalt)
B(-6,13,6,minecraft:basalt)
B(-6,14,6,minecraft:basalt)
B(-6,15,6,minecraft:basalt)
B(-6,16,6,minecraft:basalt)
B(-6,17,6,minecraft:basalt)
B(-6,18,6,minecraft:basalt)
B(-6,19,6,minecraft:basalt)
B(-6,20,6,minecraft:basalt)
B(-6,21,6,minecraft:basalt)
B(-6,22,6,minecraft:basalt)
B(-6,23,6,minecraft:basalt)
B(-6,24,6,minecraft:basalt)
B(-6,25,6,minecraft:basalt)
B(-6,26,6,minecraft:basalt)
B(-6,27,6,minecraft:basalt)
B(-6,28,6,minecraft:basalt)
B(-6,29,6,minecraft:basalt)
B(-6,30,6,minecraft:basalt)
B(-6,31,6,minecraft:basalt)
B(-6,32,6,minecraft:basalt)
B(-6,33,6,minecraft:basalt)
B(-6,34,6,minecraft:basalt)
B(-6,35,6,minecraft:basalt)
B(-6,36,6,minecraft:basalt)
B(-6,37,6,minecraft:basalt)
B(-6,38,6,minecraft:basalt)
B(-6,39,6,minecraft:basalt)
B(-6,40,6,minecraft:basalt)
B(-6,41,6,minecraft:basalt)
B(-6,42,6,minecraft:basalt)
B(-6,43,6,minecraft:basalt)
B(-6,0,7,minecraft:basalt)
B(-6,1,7,minecraft:basalt)
B(-6,2,7,minecraft:basalt)
B(-6,3,7,minecraft:basalt)
B(-6,4,7,minecraft:basalt)
B(-6,5,7,minecraft:basalt)
B(-6,6,7,minecraft:basalt)
B(-6,7,7,minecraft:basalt)
B(-6,8,7,minecraft:basalt)
B(-6,9,7,minecraft:basalt)
B(-6,10,7,minecraft:basalt)
B(-6,11,7,minecraft:basalt)
B(-5,0,-7,minecraft:basalt)
B(-5,1,-7,minecraft:basalt)
B(-5,2,-7,minecraft:soul_soil)
B(-5,3,-7,minecraft:soul_soil)
B(-5,4,-7,minecraft:basalt)
B(-5,0,-6,minecraft:basalt)
B(-5,1,-6,minecraft:basalt)
B(-5,2,-6,minecraft:nether_quartz_ore)
B(-5,3,-6,minecraft:soul_soil)
B(-5,4,-6,minecraft:soul_soil)
B(-5,5,-6,minecraft:basalt)
B(-5,0,-5,minecraft:basalt)
B(-5,1,-5,minecraft:nether_quartz_ore)
B(-5,2,-5,minecraft:nether_quartz_ore)
B(-5,3,-5,minecraft:soul_soil)
B(-5,4,-5,minecraft:soul_soil)
B(-5,5,-5,minecraft:basalt)
B(-5,0,-4,minecraft:basalt)
B(-5,1,-4,minecraft:basalt)
B(-5,2,-4,minecraft:basalt)
B(-5,3,-4,minecraft:soul_soil)
B(-5,4,-4,minecraft:basalt)
B(-5,0,-3,minecraft:basalt)
B(-5,1,-3,minecraft:basalt)
B(-5,2,-3,minecraft:basalt)
B(-5,3,-3,minecraft:basalt)
B(-5,4,-3,minecraft:basalt)
B(-5,0,-2,minecraft:basalt)
B(-5,1,-2,minecraft:basalt)
B(-5,2,-2,minecraft:basalt)
B(-5,3,-2,minecraft:basalt)
B(-5,4,-2,minecraft:basalt)
B(-5,5,-2,minecraft:basalt)
B(-5,6,-2,minecraft:basalt)
B(-5,7,-2,minecraft:basalt)
B(-5,8,-2,minecraft:basalt)
B(-5,9,-2,minecraft:basalt)
B(-5,10,-2,minecraft:basalt)
B(-5,11,-2,minecraft:basalt)
B(-5,12,-2,minecraft:basalt)
B(-5,13,-2,minecraft:basalt)
B(-5,14,-2,minecraft:basalt)
B(-5,15,-2,minecraft:basalt)
B(-5,16,-2,minecraft:basalt)
B(-5,17,-2,minecraft:basalt)
B(-5,18,-2,minecraft:basalt)
B(-5,19,-2,minecraft:basalt)
B(-5,20,-2,minecraft:basalt)
B(-5,21,-2,minecraft:basalt)
B(-5,22,-2,minecraft:basalt)
B(-5,23,-2,minecraft:basalt)
B(-5,24,-2,minecraft:basalt)
B(-5,25,-2,minecraft:basalt)
B(-5,26,-2,minecraft:basalt)
B(-5,27,-2,minecraft:basalt)
B(-5,28,-2,minecraft:basalt)
B(-5,29,-2,minecraft:basalt)
B(-5,30,-2,minecraft:basalt)
B(-5,31,-2,minecraft:basalt)
B(-5,32,-2,minecraft:basalt)
B(-5,33,-2,minecraft:basalt)
B(-5,34,-2,minecraft:basalt)
B(-5,35,-2,minecraft:basalt)
B(-5,36,-2,minecraft:basalt)
B(-5,37,-2,minecraft:basalt)
B(-5,38,-2,minecraft:basalt)
B(-5,39,-2,minecraft:basalt)
B(-5,40,-2,minecraft:basalt)
B(-5,41,-2,minecraft:basalt)
B(-5,42,-2,minecraft:basalt)
B(-5,43,-2,minecraft:basalt)
B(-5,44,-2,minecraft:basalt)
B(-5,45,-2,minecraft:basalt)
B(-5,46,-2,minecraft:basalt)
B(-5,47,-2,minecraft:basalt)
B(-5,48,-2,minecraft:basalt)
B(-5,49,-2,minecraft:basalt)
B(-5,50,-2,minecraft:basalt)
B(-5,51,-2,minecraft:basalt)
B(-5,52,-2,minecraft:basalt)
B(-5,53,-2,minecraft:basalt)
B(-5,54,-2,minecraft:basalt)
B(-5,55,-2,minecraft:basalt)
B(-5,56,-2,minecraft:basalt)
B(-5,57,-2,minecraft:basalt)
B(-5,58,-2,minecraft:basalt)
B(-5,59,-2,minecraft:basalt)
B(-5,0,-1,minecraft:basalt)
B(-5,1,-1,minecraft:basalt)
B(-5,2,-1,minecraft:basalt)
B(-5,3,-1,minecraft:basalt)
B(-5,4,-1,minecraft:basalt)
B(-5,5,-1,minecraft:basalt)
B(-5,6,-1,minecraft:basalt)
B(-5,7,-1,minecraft:basalt)
B(-5,8,-1,minecraft:basalt)
B(-5,9,-1,minecraft:basalt)
B(-5,10,-1,minecraft:basalt)
B(-5,11,-1,minecraft:basalt)
B(-5,12,-1,minecraft:basalt)
B(-5,13,-1,minecraft:basalt)
B(-5,14,-1,minecraft:basalt)
B(-5,15,-1,minecraft:basalt)
B(-5,16,-1,minecraft:basalt)
B(-5,17,-1,minecraft:basalt)
B(-5,18,-1,minecraft:basalt)
B(-5,19,-1,minecraft:basalt)
B(-5,20,-1,minecraft:basalt)
B(-5,21,-1,minecraft:basalt)
B(-5,22,-1,minecraft:basalt)
B(-5,23,-1,minecraft:basalt)
B(-5,24,-1,minecraft:basalt)
B(-5,25,-1,minecraft:basalt)
B(-5,26,-1,minecraft:basalt)
B(-5,27,-1,minecraft:basalt)
B(-5,28,-1,minecraft:basalt)
B(-5,29,-1,minecraft:basalt)
B(-5,30,-1,minecraft:basalt)
B(-5,31,-1,minecraft:basalt)
B(-5,32,-1,minecraft:basalt)
B(-5,33,-1,minecraft:basalt)
B(-5,34,-1,minecraft:basalt)
B(-5,35,-1,minecraft:basalt)
B(-5,36,-1,minecraft:basalt)
B(-5,37,-1,minecraft:basalt)
B(-5,38,-1,minecraft:basalt)
B(-5,39,-1,minecraft:basalt)
B(-5,40,-1,minecraft:basalt)
B(-5,41,-1,minecraft:basalt)
B(-5,42,-1,minecraft:basalt)
B(-5,43,-1,minecraft:basalt)
B(-5,44,-1,minecraft:basalt)
B(-5,45,-1,minecraft:basalt)
B(-5,46,-1,minecraft:basalt)
B(-5,47,-1,minecraft:basalt)
B(-5,48,-1,minecraft:basalt)
B(-5,49,-1,minecraft:basalt)
B(-5,50,-1,minecraft:basalt)
B(-5,51,-1,minecraft:basalt)
B(-5,52,-1,minecraft:basalt)
B(-5,53,-1,minecraft:basalt)
B(-5,54,-1,minecraft:basalt)
B(-5,55,-1,minecraft:basalt)
B(-5,56,-1,minecraft:basalt)
B(-5,57,-1,minecraft:basalt)
B(-5,58,-1,minecraft:basalt)
B(-5,59,-1,minecraft:basalt)
B(-5,60,-1,minecraft:basalt)
B(-5,61,-1,minecraft:basalt)
B(-5,62,-1,minecraft:basalt)
B(-5,63,-1,minecraft:basalt)
B(-5,64,-1,minecraft:basalt)
B(-5,65,-1,minecraft:basalt)
B(-5,66,-1,minecraft:basalt)
B(-5,0,0,minecraft:basalt)
B(-5,1,0,minecraft:basalt)
B(-5,2,0,minecraft:basalt)
B(-5,3,0,minecraft:basalt)
B(-5,4,0,minecraft:basalt)
B(-5,5,0,minecraft:basalt)
B(-5,6,0,minecraft:basalt)
B(-5,7,0,minecraft:basalt)
B(-5,8,0,minecraft:basalt)
B(-5,9,0,minecraft:basalt)
B(-5,10,0,minecraft:basalt)
B(-5,11,0,minecraft:basalt)
B(-5,12,0,minecraft:basalt)
B(-5,13,0,minecraft:basalt)
B(-5,14,0,minecraft:basalt)
B(-5,15,0,minecraft:basalt)
B(-5,16,0,minecraft:basalt)
B(-5,17,0,minecraft:basalt)
B(-5,18,0,minecraft:basalt)
B(-5,19,0,minecraft:basalt)
B(-5,20,0,minecraft:basalt)
B(-5,21,0,minecraft:basalt)
B(-5,22,0,minecraft:basalt)
B(-5,23,0,minecraft:basalt)
B(-5,24,0,minecraft:basalt)
B(-5,25,0,minecraft:basalt)
B(-5,26,0,minecraft:basalt)
B(-5,27,0,minecraft:basalt)
B(-5,28,0,minecraft:basalt)
B(-5,29,0,minecraft:basalt)
B(-5,30,0,minecraft:basalt)
B(-5,31,0,minecraft:basalt)
B(-5,32,0,minecraft:basalt)
B(-5,33,0,minecraft:basalt)
B(-5,34,0,minecraft:basalt)
B(-5,35,0,minecraft:basalt)
B(-5,36,0,minecraft:basalt)
B(-5,37,0,minecraft:basalt)
B(-5,38,0,minecraft:basalt)
B(-5,39,0,minecraft:basalt)
B(-5,40,0,minecraft:basalt)
B(-5,41,0,minecraft:basalt)
B(-5,42,0,minecraft:basalt)
B(-5,43,0,minecraft:basalt)
B(-5,44,0,minecraft:basalt)
B(-5,45,0,minecraft:basalt)
B(-5,46,0,minecraft:basalt)
B(-5,47,0,minecraft:basalt)
B(-5,48,0,minecraft:basalt)
B(-5,49,0,minecraft:basalt)
B(-5,50,0,minecraft:basalt)
B(-5,51,0,minecraft:basalt)
B(-5,52,0,minecraft:basalt)
B(-5,53,0,minecraft:basalt)
B(-5,54,0,minecraft:basalt)
B(-5,55,0,minecraft:basalt)
B(-5,56,0,minecraft:basalt)
B(-5,57,0,minecraft:basalt)
B(-5,58,0,minecraft:basalt)
B(-5,59,0,minecraft:basalt)
B(-5,60,0,minecraft:basalt)
B(-5,61,0,minecraft:basalt)
B(-5,62,0,minecraft:basalt)
B(-5,63,0,minecraft:basalt)
B(-5,64,0,minecraft:basalt)
B(-5,65,0,minecraft:basalt)
B(-5,66,0,minecraft:basalt)
B(-5,67,0,minecraft:basalt)
B(-5,0,1,minecraft:basalt)
B(-5,1,1,minecraft:basalt)
B(-5,2,1,minecraft:basalt)
B(-5,3,1,minecraft:basalt)
B(-5,4,1,minecraft:basalt)
B(-5,5,1,minecraft:basalt)
B(-5,6,1,minecraft:basalt)
B(-5,7,1,minecraft:basalt)
B(-5,8,1,minecraft:basalt)
B(-5,9,1,minecraft:basalt)
B(-5,10,1,minecraft:basalt)
B(-5,11,1,minecraft:basalt)
B(-5,12,1,minecraft:basalt)
B(-5,13,1,minecraft:basalt)
B(-5,14,1,minecraft:basalt)
B(-5,15,1,minecraft:basalt)
B(-5,16,1,minecraft:basalt)
B(-5,17,1,minecraft:basalt)
B(-5,18,1,minecraft:basalt)
B(-5,19,1,minecraft:basalt)
B(-5,20,1,minecraft:basalt)
B(-5,21,1,minecraft:basalt)
B(-5,22,1,minecraft:basalt)
B(-5,23,1,minecraft:basalt)
B(-5,24,1,minecraft:basalt)
B(-5,25,1,minecraft:basalt)
B(-5,26,1,minecraft:basalt)
B(-5,27,1,minecraft:basalt)
B(-5,28,1,minecraft:basalt)
B(-5,29,1,minecraft:basalt)
B(-5,30,1,minecraft:basalt)
B(-5,31,1,minecraft:basalt)
B(-5,32,1,minecraft:basalt)
B(-5,33,1,minecraft:basalt)
B(-5,34,1,minecraft:basalt)
B(-5,35,1,minecraft:basalt)
B(-5,36,1,minecraft:basalt)
B(-5,37,1,minecraft:basalt)
B(-5,38,1,minecraft:basalt)
B(-5,39,1,minecraft:basalt)
B(-5,40,1,minecraft:basalt)
B(-5,41,1,minecraft:basalt)
B(-5,42,1,minecraft:basalt)
B(-5,43,1,minecraft:basalt)
B(-5,44,1,minecraft:basalt)
B(-5,45,1,minecraft:basalt)
B(-5,46,1,minecraft:basalt)
B(-5,47,1,minecraft:basalt)
B(-5,48,1,minecraft:basalt)
B(-5,49,1,minecraft:basalt)
B(-5,50,1,minecraft:basalt)
B(-5,51,1,minecraft:basalt)
B(-5,52,1,minecraft:basalt)
B(-5,53,1,minecraft:basalt)
B(-5,54,1,minecraft:basalt)
B(-5,55,1,minecraft:basalt)
B(-5,56,1,minecraft:basalt)
B(-5,57,1,minecraft:basalt)
B(-5,58,1,minecraft:basalt)
B(-5,59,1,minecraft:basalt)
B(-5,60,1,minecraft:basalt)
B(-5,61,1,minecraft:basalt)
B(-5,62,1,minecraft:basalt)
B(-5,63,1,minecraft:basalt)
B(-5,64,1,minecraft:basalt)
B(-5,65,1,minecraft:basalt)
B(-5,66,1,minecraft:basalt)
B(-5,67,1,minecraft:basalt)
B(-5,68,1,minecraft:basalt)
B(-5,0,2,minecraft:basalt)
B(-5,1,2,minecraft:basalt)
B(-5,2,2,minecraft:basalt)
B(-5,3,2,minecraft:basalt)
B(-5,4,2,minecraft:basalt)
B(-5,5,2,minecraft:basalt)
B(-5,6,2,minecraft:basalt)
B(-5,7,2,minecraft:basalt)
B(-5,8,2,minecraft:basalt)
B(-5,9,2,minecraft:basalt)
B(-5,10,2,minecraft:basalt)
B(-5,11,2,minecraft:basalt)
B(-5,12,2,minecraft:basalt)
B(-5,13,2,minecraft:basalt)
B(-5,14,2,minecraft:basalt)
B(-5,15,2,minecraft:basalt)
B(-5,16,2,minecraft:basalt)
B(-5,17,2,minecraft:basalt)
B(-5,18,2,minecraft:basalt)
B(-5,19,2,minecraft:basalt)
B(-5,20,2,minecraft:basalt)
B(-5,21,2,minecraft:basalt)
B(-5,22,2,minecraft:basalt)
B(-5,23,2,minecraft:basalt)
B(-5,24,2,minecraft:basalt)
B(-5,25,2,minecraft:basalt)
B(-5,26,2,minecraft:basalt)
B(-5,27,2,minecraft:basalt)
B(-5,28,2,minecraft:basalt)
B(-5,29,2,minecraft:basalt)
B(-5,30,2,minecraft:basalt)
B(-5,31,2,minecraft:basalt)
B(-5,32,2,minecraft:basalt)
B(-5,33,2,minecraft:basalt)
B(-5,34,2,minecraft:basalt)
B(-5,35,2,minecraft:basalt)
B(-5,36,2,minecraft:basalt)
B(-5,37,2,minecraft:basalt)
B(-5,38,2,minecraft:basalt)
B(-5,39,2,minecraft:basalt)
B(-5,40,2,minecraft:basalt)
B(-5,41,2,minecraft:basalt)
B(-5,42,2,minecraft:basalt)
B(-5,43,2,minecraft:basalt)
B(-5,44,2,minecraft:basalt)
B(-5,45,2,minecraft:basalt)
B(-5,46,2,minecraft:basalt)
B(-5,47,2,minecraft:basalt)
B(-5,48,2,minecraft:basalt)
B(-5,49,2,minecraft:basalt)
B(-5,50,2,minecraft:basalt)
B(-5,51,2,minecraft:basalt)
B(-5,52,2,minecraft:basalt)
B(-5,53,2,minecraft:basalt)
B(-5,54,2,minecraft:basalt)
B(-5,55,2,minecraft:basalt)
B(-5,56,2,minecraft:basalt)
B(-5,57,2,minecraft:basalt)
B(-5,58,2,minecraft:basalt)
B(-5,59,2,minecraft:basalt)
B(-5,60,2,minecraft:basalt)
B(-5,61,2,minecraft:basalt)
B(-5,62,2,minecraft:basalt)
B(-5,63,2,minecraft:basalt)
B(-5,64,2,minecraft:basalt)
B(-5,65,2,minecraft:basalt)
B(-5,66,2,minecraft:basalt)
B(-5,67,2,minecraft:basalt)
B(-5,68,2,minecraft:basalt)
B(-5,0,3,minecraft:basalt)
B(-5,1,3,minecraft:basalt)
B(-5,2,3,minecraft:basalt)
B(-5,3,3,minecraft:basalt)
B(-5,4,3,minecraft:basalt)
B(-5,5,3,minecraft:basalt)
B(-5,6,3,minecraft:basalt)
B(-5,7,3,minecraft:basalt)
B(-5,8,3,minecraft:basalt)
B(-5,9,3,minecraft:basalt)
B(-5,10,3,minecraft:basalt)
B(-5,11,3,minecraft:basalt)
B(-5,12,3,minecraft:basalt)
B(-5,13,3,minecraft:basalt)
B(-5,14,3,minecraft:basalt)
B(-5,15,3,minecraft:basalt)
B(-5,16,3,minecraft:basalt)
B(-5,17,3,minecraft:basalt)
B(-5,18,3,minecraft:basalt)
B(-5,19,3,minecraft:basalt)
B(-5,20,3,minecraft:basalt)
B(-5,21,3,minecraft:basalt)
B(-5,22,3,minecraft:basalt)
B(-5,23,3,minecraft:basalt)
B(-5,24,3,minecraft:basalt)
B(-5,25,3,minecraft:basalt)
B(-5,26,3,minecraft:basalt)
B(-5,27,3,minecraft:basalt)
B(-5,28,3,minecraft:basalt)
B(-5,29,3,minecraft:basalt)
B(-5,30,3,minecraft:basalt)
B(-5,31,3,minecraft:basalt)
B(-5,32,3,minecraft:basalt)
B(-5,33,3,minecraft:basalt)
B(-5,34,3,minecraft:basalt)
B(-5,35,3,minecraft:basalt)
B(-5,36,3,minecraft:basalt)
B(-5,37,3,minecraft:basalt)
B(-5,38,3,minecraft:basalt)
B(-5,39,3,minecraft:basalt)
B(-5,40,3,minecraft:basalt)
B(-5,41,3,minecraft:basalt)
B(-5,42,3,minecraft:basalt)
B(-5,43,3,minecraft:basalt)
B(-5,44,3,minecraft:basalt)
B(-5,45,3,minecraft:basalt)
B(-5,46,3,minecraft:basalt)
B(-5,47,3,minecraft:basalt)
B(-5,48,3,minecraft:basalt)
B(-5,49,3,minecraft:basalt)
B(-5,50,3,minecraft:basalt)
B(-5,51,3,minecraft:basalt)
B(-5,52,3,minecraft:basalt)
B(-5,53,3,minecraft:basalt)
B(-5,54,3,minecraft:basalt)
B(-5,55,3,minecraft:basalt)
B(-5,56,3,minecraft:basalt)
B(-5,57,3,minecraft:basalt)
B(-5,58,3,minecraft:basalt)
B(-5,59,3,minecraft:basalt)
B(-5,60,3,minecraft:basalt)
B(-5,61,3,minecraft:basalt)
B(-5,62,3,minecraft:basalt)
B(-5,63,3,minecraft:basalt)
B(-5,64,3,minecraft:basalt)
B(-5,65,3,minecraft:basalt)
B(-5,66,3,minecraft:basalt)
B(-5,67,3,minecraft:basalt)
B(-5,68,3,minecraft:basalt)
B(-5,0,4,minecraft:basalt)
B(-5,1,4,minecraft:basalt)
B(-5,2,4,minecraft:basalt)
B(-5,3,4,minecraft:basalt)
B(-5,4,4,minecraft:basalt)
B(-5,5,4,minecraft:basalt)
B(-5,6,4,minecraft:basalt)
B(-5,7,4,minecraft:basalt)
B(-5,8,4,minecraft:basalt)
B(-5,9,4,minecraft:basalt)
B(-5,10,4,minecraft:basalt)
B(-5,11,4,minecraft:basalt)
B(-5,12,4,minecraft:basalt)
B(-5,13,4,minecraft:basalt)
B(-5,14,4,minecraft:basalt)
B(-5,15,4,minecraft:basalt)
B(-5,16,4,minecraft:basalt)
B(-5,17,4,minecraft:basalt)
B(-5,18,4,minecraft:basalt)
B(-5,19,4,minecraft:basalt)
B(-5,20,4,minecraft:basalt)
B(-5,21,4,minecraft:basalt)
B(-5,22,4,minecraft:basalt)
B(-5,23,4,minecraft:basalt)
B(-5,24,4,minecraft:basalt)
B(-5,25,4,minecraft:basalt)
B(-5,26,4,minecraft:basalt)
B(-5,27,4,minecraft:basalt)
B(-5,28,4,minecraft:basalt)
B(-5,29,4,minecraft:basalt)
B(-5,30,4,minecraft:basalt)
B(-5,31,4,minecraft:basalt)
B(-5,32,4,minecraft:basalt)
B(-5,33,4,minecraft:basalt)
B(-5,34,4,minecraft:basalt)
B(-5,35,4,minecraft:basalt)
B(-5,36,4,minecraft:basalt)
B(-5,37,4,minecraft:basalt)
B(-5,38,4,minecraft:basalt)
B(-5,39,4,minecraft:basalt)
B(-5,40,4,minecraft:basalt)
B(-5,41,4,minecraft:basalt)
B(-5,42,4,minecraft:basalt)
B(-5,43,4,minecraft:basalt)
B(-5,44,4,minecraft:basalt)
B(-5,45,4,minecraft:basalt)
B(-5,46,4,minecraft:basalt)
B(-5,47,4,minecraft:basalt)
B(-5,48,4,minecraft:basalt)
B(-5,49,4,minecraft:basalt)
B(-5,50,4,minecraft:basalt)
B(-5,51,4,minecraft:basalt)
B(-5,52,4,minecraft:basalt)
B(-5,53,4,minecraft:basalt)
B(-5,54,4,minecraft:basalt)
B(-5,55,4,minecraft:basalt)
B(-5,56,4,minecraft:basalt)
B(-5,57,4,minecraft:basalt)
B(-5,58,4,minecraft:basalt)
B(-5,59,4,minecraft:basalt)
B(-5,60,4,minecraft:basalt)
B(-5,61,4,minecraft:basalt)
B(-5,62,4,minecraft:basalt)
B(-5,63,4,minecraft:basalt)
B(-5,64,4,minecraft:basalt)
B(-5,65,4,minecraft:basalt)
B(-5,66,4,minecraft:basalt)
B(-5,67,4,minecraft:basalt)
B(-5,68,4,minecraft:basalt)
B(-5,0,5,minecraft:basalt)
B(-5,1,5,minecraft:basalt)
B(-5,2,5,minecraft:basalt)
B(-5,3,5,minecraft:basalt)
B(-5,4,5,minecraft:basalt)
B(-5,5,5,minecraft:basalt)
B(-5,6,5,minecraft:basalt)
B(-5,7,5,minecraft:basalt)
B(-5,8,5,minecraft:basalt)
B(-5,9,5,minecraft:basalt)
B(-5,10,5,minecraft:basalt)
B(-5,11,5,minecraft:basalt)
B(-5,12,5,minecraft:basalt)
B(-5,13,5,minecraft:basalt)
B(-5,14,5,minecraft:basalt)
B(-5,15,5,minecraft:basalt)
B(-5,16,5,minecraft:basalt)
B(-5,17,5,minecraft:basalt)
B(-5,18,5,minecraft:basalt)
B(-5,19,5,minecraft:basalt)
B(-5,20,5,minecraft:basalt)
B(-5,21,5,minecraft:basalt)
B(-5,22,5,minecraft:basalt)
B(-5,23,5,minecraft:basalt)
B(-5,24,5,minecraft:basalt)
B(-5,25,5,minecraft:basalt)
B(-5,26,5,minecraft:basalt)
B(-5,27,5,minecraft:basalt)
B(-5,28,5,minecraft:basalt)
B(-5,29,5,minecraft:basalt)
B(-5,30,5,minecraft:basalt)
B(-5,31,5,minecraft:basalt)
B(-5,32,5,minecraft:basalt)
B(-5,33,5,minecraft:basalt)
B(-5,34,5,minecraft:basalt)
B(-5,35,5,minecraft:basalt)
B(-5,36,5,minecraft:basalt)
B(-5,37,5,minecraft:basalt)
B(-5,38,5,minecraft:basalt)
B(-5,39,5,minecraft:basalt)
B(-5,40,5,minecraft:basalt)
B(-5,41,5,minecraft:basalt)
B(-5,42,5,minecraft:basalt)
B(-5,43,5,minecraft:basalt)
B(-5,44,5,minecraft:basalt)
B(-5,45,5,minecraft:basalt)
B(-5,46,5,minecraft:basalt)
B(-5,47,5,minecraft:basalt)
B(-5,48,5,minecraft:basalt)
B(-5,49,5,minecraft:basalt)
B(-5,50,5,minecraft:basalt)
B(-5,51,5,minecraft:basalt)
B(-5,52,5,minecraft:basalt)
B(-5,53,5,minecraft:basalt)
B(-5,54,5,minecraft:basalt)
B(-5,55,5,minecraft:basalt)
B(-5,56,5,minecraft:basalt)
B(-5,57,5,minecraft:basalt)
B(-5,58,5,minecraft:basalt)
B(-5,59,5,minecraft:basalt)
B(-5,60,5,minecraft:basalt)
B(-5,61,5,minecraft:basalt)
B(-5,62,5,minecraft:basalt)
B(-5,63,5,minecraft:basalt)
B(-5,64,5,minecraft:basalt)
B(-5,65,5,minecraft:basalt)
B(-5,66,5,minecraft:basalt)
B(-5,67,5,minecraft:basalt)
B(-5,68,5,minecraft:basalt)
B(-5,0,6,minecraft:basalt)
B(-5,1,6,minecraft:basalt)
B(-5,2,6,minecraft:basalt)
B(-5,3,6,minecraft:basalt)
B(-5,4,6,minecraft:basalt)
B(-5,5,6,minecraft:basalt)
B(-5,6,6,minecraft:basalt)
B(-5,7,6,minecraft:basalt)
B(-5,8,6,minecraft:basalt)
B(-5,9,6,minecraft:basalt)
B(-5,10,6,minecraft:basalt)
B(-5,11,6,minecraft:basalt)
B(-5,12,6,minecraft:basalt)
B(-5,13,6,minecraft:basalt)
B(-5,14,6,minecraft:basalt)
B(-5,15,6,minecraft:basalt)
B(-5,16,6,minecraft:basalt)
B(-5,17,6,minecraft:basalt)
B(-5,18,6,minecraft:basalt)
B(-5,19,6,minecraft:basalt)
B(-5,20,6,minecraft:basalt)
B(-5,21,6,minecraft:basalt)
B(-5,22,6,minecraft:basalt)
B(-5,23,6,minecraft:basalt)
B(-5,24,6,minecraft:basalt)
B(-5,25,6,minecraft:basalt)
B(-5,26,6,minecraft:basalt)
B(-5,27,6,minecraft:basalt)
B(-5,28,6,minecraft:basalt)
B(-5,29,6,minecraft:basalt)
B(-5,30,6,minecraft:basalt)
B(-5,31,6,minecraft:basalt)
B(-5,32,6,minecraft:basalt)
B(-5,33,6,minecraft:basalt)
B(-5,34,6,minecraft:basalt)
B(-5,35,6,minecraft:basalt)
B(-5,36,6,minecraft:basalt)
B(-5,37,6,minecraft:basalt)
B(-5,38,6,minecraft:basalt)
B(-5,39,6,minecraft:basalt)
B(-5,40,6,minecraft:basalt)
B(-5,41,6,minecraft:basalt)
B(-5,42,6,minecraft:basalt)
B(-5,43,6,minecraft:basalt)
B(-5,44,6,minecraft:basalt)
B(-5,45,6,minecraft:basalt)
B(-5,46,6,minecraft:basalt)
B(-5,47,6,minecraft:basalt)
B(-5,48,6,minecraft:basalt)
B(-5,49,6,minecraft:basalt)
B(-5,50,6,minecraft:basalt)
B(-5,51,6,minecraft:basalt)
B(-5,52,6,minecraft:basalt)
B(-5,53,6,minecraft:basalt)
B(-5,54,6,minecraft:basalt)
B(-5,55,6,minecraft:basalt)
B(-5,56,6,minecraft:basalt)
B(-5,57,6,minecraft:basalt)
B(-5,58,6,minecraft:basalt)
B(-5,59,6,minecraft:basalt)
B(-5,60,6,minecraft:basalt)
B(-5,61,6,minecraft:basalt)
B(-5,62,6,minecraft:basalt)
B(-5,63,6,minecraft:basalt)
B(-5,64,6,minecraft:basalt)
B(-5,65,6,minecraft:basalt)
B(-5,66,6,minecraft:basalt)
B(-5,67,6,minecraft:basalt)
B(-4,0,-7,minecraft:basalt)
B(-4,1,-7,minecraft:basalt)
B(-4,2,-7,minecraft:basalt)
B(-4,3,-7,minecraft:soul_soil)
B(-4,4,-7,minecraft:soul_soil)
B(-4,5,-7,minecraft:basalt)
B(-4,0,-6,minecraft:basalt)
B(-4,1,-6,minecraft:basalt)
B(-4,2,-6,minecraft:basalt)
B(-4,3,-6,minecraft:soul_soil)
B(-4,4,-6,minecraft:soul_soil)
B(-4,5,-6,minecraft:basalt)
B(-4,0,-5,minecraft:basalt)
B(-4,1,-5,minecraft:nether_quartz_ore)
B(-4,2,-5,minecraft:soul_soil)
B(-4,3,-5,minecraft:soul_soil)
B(-4,4,-5,minecraft:soul_soil)
B(-4,5,-5,minecraft:basalt)
B(-4,0,-4,minecraft:basalt)
B(-4,1,-4,minecraft:nether_quartz_ore)
B(-4,2,-4,minecraft:soul_soil)
B(-4,3,-4,minecraft:soul_soil)
B(-4,4,-4,minecraft:basalt)
B(-4,0,-3,minecraft:basalt)
B(-4,1,-3,minecraft:basalt)
B(-4,2,-3,minecraft:soul_soil)
B(-4,3,-3,minecraft:soul_soil)
B(-4,4,-3,minecraft:basalt)
B(-4,0,-2,minecraft:basalt)
B(-4,1,-2,minecraft:basalt)
B(-4,2,-2,minecraft:basalt)
B(-4,3,-2,minecraft:basalt)
B(-4,4,-2,minecraft:basalt)
B(-4,5,-2,minecraft:basalt)
B(-4,6,-2,minecraft:basalt)
B(-4,7,-2,minecraft:basalt)
B(-4,8,-2,minecraft:basalt)
B(-4,9,-2,minecraft:basalt)
B(-4,10,-2,minecraft:basalt)
B(-4,11,-2,minecraft:basalt)
B(-4,12,-2,minecraft:basalt)
B(-4,13,-2,minecraft:basalt)
B(-4,14,-2,minecraft:basalt)
B(-4,15,-2,minecraft:basalt)
B(-4,16,-2,minecraft:basalt)
B(-4,17,-2,minecraft:basalt)
B(-4,18,-2,minecraft:basalt)
B(-4,19,-2,minecraft:basalt)
B(-4,20,-2,minecraft:basalt)
B(-4,21,-2,minecraft:basalt)
B(-4,22,-2,minecraft:basalt)
B(-4,23,-2,minecraft:basalt)
B(-4,24,-2,minecraft:basalt)
B(-4,25,-2,minecraft:basalt)
B(-4,26,-2,minecraft:basalt)
B(-4,27,-2,minecraft:basalt)
B(-4,28,-2,minecraft:basalt)
B(-4,29,-2,minecraft:basalt)
B(-4,30,-2,minecraft:basalt)
B(-4,31,-2,minecraft:basalt)
B(-4,32,-2,minecraft:basalt)
B(-4,33,-2,minecraft:basalt)
B(-4,34,-2,minecraft:basalt)
B(-4,35,-2,minecraft:basalt)
B(-4,36,-2,minecraft:basalt)
B(-4,37,-2,minecraft:basalt)
B(-4,38,-2,minecraft:basalt)
B(-4,39,-2,minecraft:basalt)
B(-4,40,-2,minecraft:basalt)
B(-4,41,-2,minecraft:basalt)
B(-4,42,-2,minecraft:basalt)
B(-4,43,-2,minecraft:basalt)
B(-4,44,-2,minecraft:basalt)
B(-4,45,-2,minecraft:basalt)
B(-4,46,-2,minecraft:basalt)
B(-4,47,-2,minecraft:basalt)
B(-4,48,-2,minecraft:basalt)
B(-4,49,-2,minecraft:basalt)
B(-4,50,-2,minecraft:basalt)
B(-4,51,-2,minecraft:basalt)
B(-4,52,-2,minecraft:basalt)
B(-4,53,-2,minecraft:basalt)
B(-4,54,-2,minecraft:basalt)
B(-4,55,-2,minecraft:basalt)
B(-4,56,-2,minecraft:basalt)
B(-4,57,-2,minecraft:basalt)
B(-4,58,-2,minecraft:basalt)
B(-4,59,-2,minecraft:basalt)
B(-4,0,-1,minecraft:basalt)
B(-4,1,-1,minecraft:basalt)
B(-4,2,-1,minecraft:basalt)
B(-4,3,-1,minecraft:basalt)
B(-4,4,-1,minecraft:basalt)
B(-4,5,-1,minecraft:basalt)
B(-4,6,-1,minecraft:basalt)
B(-4,7,-1,minecraft:basalt)
B(-4,8,-1,minecraft:basalt)
B(-4,9,-1,minecraft:basalt)
B(-4,10,-1,minecraft:basalt)
B(-4,11,-1,minecraft:basalt)
B(-4,12,-1,minecraft:basalt)
B(-4,13,-1,minecraft:basalt)
B(-4,14,-1,minecraft:basalt)
B(-4,15,-1,minecraft:basalt)
B(-4,16,-1,minecraft:basalt)
B(-4,17,-1,minecraft:basalt)
B(-4,18,-1,minecraft:basalt)
B(-4,19,-1,minecraft:basalt)
B(-4,20,-1,minecraft:basalt)
B(-4,21,-1,minecraft:basalt)
B(-4,22,-1,minecraft:basalt)
B(-4,23,-1,minecraft:basalt)
B(-4,24,-1,minecraft:basalt)
B(-4,25,-1,minecraft:basalt)
B(-4,26,-1,minecraft:basalt)
B(-4,27,-1,minecraft:basalt)
B(-4,28,-1,minecraft:basalt)
B(-4,29,-1,minecraft:basalt)
B(-4,30,-1,minecraft:basalt)
B(-4,31,-1,minecraft:basalt)
B(-4,32,-1,minecraft:basalt)
B(-4,33,-1,minecraft:basalt)
B(-4,34,-1,minecraft:basalt)
B(-4,35,-1,minecraft:basalt)
B(-4,36,-1,minecraft:basalt)
B(-4,37,-1,minecraft:basalt)
B(-4,38,-1,minecraft:basalt)
B(-4,39,-1,minecraft:basalt)
B(-4,40,-1,minecraft:basalt)
B(-4,41,-1,minecraft:basalt)
B(-4,42,-1,minecraft:basalt)
B(-4,43,-1,minecraft:basalt)
B(-4,44,-1,minecraft:basalt)
B(-4,45,-1,minecraft:basalt)
B(-4,46,-1,minecraft:basalt)
B(-4,47,-1,minecraft:basalt)
B(-4,48,-1,minecraft:basalt)
B(-4,49,-1,minecraft:basalt)
B(-4,50,-1,minecraft:basalt)
B(-4,51,-1,minecraft:basalt)
B(-4,52,-1,minecraft:basalt)
B(-4,53,-1,minecraft:basalt)
B(-4,54,-1,minecraft:basalt)
B(-4,55,-1,minecraft:basalt)
B(-4,56,-1,minecraft:basalt)
B(-4,57,-1,minecraft:basalt)
B(-4,58,-1,minecraft:basalt)
B(-4,59,-1,minecraft:basalt)
B(-4,60,-1,minecraft:basalt)
B(-4,61,-1,minecraft:basalt)
B(-4,62,-1,minecraft:basalt)
B(-4,63,-1,minecraft:basalt)
B(-4,64,-1,minecraft:basalt)
B(-4,65,-1,minecraft:basalt)
B(-4,66,-1,minecraft:basalt)
B(-4,0,0,minecraft:basalt)
B(-4,1,0,minecraft:basalt)
B(-4,2,0,minecraft:basalt)
B(-4,3,0,minecraft:basalt)
B(-4,4,0,minecraft:basalt)
B(-4,5,0,minecraft:basalt)
B(-4,6,0,minecraft:basalt)
B(-4,7,0,minecraft:basalt)
B(-4,8,0,minecraft:basalt)
B(-4,9,0,minecraft:basalt)
B(-4,10,0,minecraft:basalt)
B(-4,11,0,minecraft:basalt)
B(-4,12,0,minecraft:basalt)
B(-4,13,0,minecraft:basalt)
B(-4,14,0,minecraft:basalt)
B(-4,15,0,minecraft:basalt)
B(-4,16,0,minecraft:basalt)
B(-4,17,0,minecraft:basalt)
B(-4,18,0,minecraft:basalt)
B(-4,19,0,minecraft:basalt)
B(-4,20,0,minecraft:basalt)
B(-4,21,0,minecraft:basalt)
B(-4,22,0,minecraft:basalt)
B(-4,23,0,minecraft:basalt)
B(-4,24,0,minecraft:basalt)
B(-4,25,0,minecraft:basalt)
B(-4,26,0,minecraft:basalt)
B(-4,27,0,minecraft:basalt)
B(-4,28,0,minecraft:basalt)
B(-4,29,0,minecraft:basalt)
B(-4,30,0,minecraft:basalt)
B(-4,31,0,minecraft:basalt)
B(-4,32,0,minecraft:basalt)
B(-4,33,0,minecraft:basalt)
B(-4,34,0,minecraft:basalt)
B(-4,35,0,minecraft:basalt)
B(-4,36,0,minecraft:basalt)
B(-4,37,0,minecraft:basalt)
B(-4,38,0,minecraft:basalt)
B(-4,39,0,minecraft:basalt)
B(-4,40,0,minecraft:basalt)
B(-4,41,0,minecraft:basalt)
B(-4,42,0,minecraft:basalt)
B(-4,43,0,minecraft:basalt)
B(-4,44,0,minecraft:basalt)
B(-4,45,0,minecraft:basalt)
B(-4,46,0,minecraft:basalt)
B(-4,47,0,minecraft:basalt)
B(-4,48,0,minecraft:basalt)
B(-4,49,0,minecraft:basalt)
B(-4,50,0,minecraft:basalt)
B(-4,51,0,minecraft:basalt)
B(-4,52,0,minecraft:basalt)
B(-4,53,0,minecraft:basalt)
B(-4,54,0,minecraft:basalt)
B(-4,55,0,minecraft:basalt)
B(-4,56,0,minecraft:basalt)
B(-4,57,0,minecraft:basalt)
B(-4,58,0,minecraft:basalt)
B(-4,59,0,minecraft:basalt)
B(-4,60,0,minecraft:basalt)
B(-4,61,0,minecraft:basalt)
B(-4,62,0,minecraft:basalt)
B(-4,63,0,minecraft:basalt)
B(-4,64,0,minecraft:basalt)
B(-4,65,0,minecraft:basalt)
B(-4,66,0,minecraft:basalt)
B(-4,67,0,minecraft:basalt)
B(-4,0,1,minecraft:basalt)
B(-4,1,1,minecraft:basalt)
B(-4,2,1,minecraft:basalt)
B(-4,3,1,minecraft:basalt)
B(-4,4,1,minecraft:basalt)
B(-4,5,1,minecraft:basalt)
B(-4,6,1,minecraft:basalt)
B(-4,7,1,minecraft:basalt)
B(-4,8,1,minecraft:basalt)
B(-4,9,1,minecraft:basalt)
B(-4,10,1,minecraft:basalt)
B(-4,11,1,minecraft:basalt)
B(-4,12,1,minecraft:basalt)
B(-4,13,1,minecraft:basalt)
B(-4,14,1,minecraft:basalt)
B(-4,15,1,minecraft:basalt)
B(-4,16,1,minecraft:basalt)
B(-4,17,1,minecraft:basalt)
B(-4,18,1,minecraft:basalt)
B(-4,19,1,minecraft:basalt)
B(-4,20,1,minecraft:basalt)
B(-4,21,1,minecraft:basalt)
B(-4,22,1,minecraft:basalt)
B(-4,23,1,minecraft:basalt)
B(-4,24,1,minecraft:basalt)
B(-4,25,1,minecraft:basalt)
B(-4,26,1,minecraft:basalt)
B(-4,27,1,minecraft:basalt)
B(-4,28,1,minecraft:basalt)
B(-4,29,1,minecraft:basalt)
B(-4,30,1,minecraft:basalt)
B(-4,31,1,minecraft:basalt)
B(-4,32,1,minecraft:basalt)
B(-4,33,1,minecraft:basalt)
B(-4,34,1,minecraft:basalt)
B(-4,35,1,minecraft:basalt)
B(-4,36,1,minecraft:basalt)
B(-4,37,1,minecraft:basalt)
B(-4,38,1,minecraft:basalt)
B(-4,39,1,minecraft:basalt)
B(-4,40,1,minecraft:basalt)
B(-4,41,1,minecraft:basalt)
B(-4,42,1,minecraft:basalt)
B(-4,43,1,minecraft:basalt)
B(-4,44,1,minecraft:basalt)
B(-4,45,1,minecraft:basalt)
B(-4,46,1,minecraft:basalt)
B(-4,47,1,minecraft:basalt)
B(-4,48,1,minecraft:basalt)
B(-4,49,1,minecraft:basalt)
B(-4,50,1,minecraft:basalt)
B(-4,51,1,minecraft:basalt)
B(-4,52,1,minecraft:basalt)
B(-4,53,1,minecraft:basalt)
B(-4,54,1,minecraft:basalt)
B(-4,55,1,minecraft:basalt)
B(-4,56,1,minecraft:basalt)
B(-4,57,1,minecraft:basalt)
B(-4,58,1,minecraft:basalt)
B(-4,59,1,minecraft:basalt)
B(-4,60,1,minecraft:basalt)
B(-4,61,1,minecraft:basalt)
B(-4,62,1,minecraft:basalt)
B(-4,63,1,minecraft:basalt)
B(-4,64,1,minecraft:basalt)
B(-4,65,1,minecraft:basalt)
B(-4,66,1,minecraft:basalt)
B(-4,67,1,minecraft:basalt)
B(-4,68,1,minecraft:basalt)
B(-4,0,2,minecraft:basalt)
B(-4,1,2,minecraft:basalt)
B(-4,2,2,minecraft:basalt)
B(-4,3,2,minecraft:basalt)
B(-4,4,2,minecraft:basalt)
B(-4,5,2,minecraft:basalt)
B(-4,6,2,minecraft:basalt)
B(-4,7,2,minecraft:basalt)
B(-4,8,2,minecraft:basalt)
B(-4,9,2,minecraft:basalt)
B(-4,10,2,minecraft:basalt)
B(-4,11,2,minecraft:basalt)
B(-4,12,2,minecraft:basalt)
B(-4,13,2,minecraft:basalt)
B(-4,14,2,minecraft:basalt)
B(-4,15,2,minecraft:basalt)
B(-4,16,2,minecraft:basalt)
B(-4,17,2,minecraft:basalt)
B(-4,18,2,minecraft:basalt)
B(-4,19,2,minecraft:basalt)
B(-4,20,2,minecraft:basalt)
B(-4,21,2,minecraft:basalt)
B(-4,22,2,minecraft:basalt)
B(-4,23,2,minecraft:basalt)
B(-4,24,2,minecraft:basalt)
B(-4,25,2,minecraft:basalt)
B(-4,26,2,minecraft:basalt)
B(-4,27,2,minecraft:basalt)
B(-4,28,2,minecraft:basalt)
B(-4,29,2,minecraft:basalt)
B(-4,30,2,minecraft:basalt)
B(-4,31,2,minecraft:basalt)
B(-4,32,2,minecraft:basalt)
B(-4,33,2,minecraft:basalt)
B(-4,34,2,minecraft:basalt)
B(-4,35,2,minecraft:basalt)
B(-4,36,2,minecraft:basalt)
B(-4,37,2,minecraft:basalt)
B(-4,38,2,minecraft:basalt)
B(-4,39,2,minecraft:basalt)
B(-4,40,2,minecraft:basalt)
B(-4,41,2,minecraft:basalt)
B(-4,42,2,minecraft:basalt)
B(-4,43,2,minecraft:basalt)
B(-4,44,2,minecraft:basalt)
B(-4,45,2,minecraft:basalt)
B(-4,46,2,minecraft:basalt)
B(-4,47,2,minecraft:basalt)
B(-4,48,2,minecraft:basalt)
B(-4,49,2,minecraft:basalt)
B(-4,50,2,minecraft:basalt)
B(-4,51,2,minecraft:basalt)
B(-4,52,2,minecraft:basalt)
B(-4,53,2,minecraft:basalt)
B(-4,54,2,minecraft:basalt)
B(-4,55,2,minecraft:basalt)
B(-4,56,2,minecraft:basalt)
B(-4,57,2,minecraft:basalt)
B(-4,58,2,minecraft:basalt)
B(-4,59,2,minecraft:basalt)
B(-4,60,2,minecraft:basalt)
B(-4,61,2,minecraft:basalt)
B(-4,62,2,minecraft:basalt)
B(-4,63,2,minecraft:basalt)
B(-4,64,2,minecraft:basalt)
B(-4,65,2,minecraft:basalt)
B(-4,66,2,minecraft:basalt)
B(-4,67,2,minecraft:basalt)
B(-4,68,2,minecraft:basalt)
B(-4,0,3,minecraft:basalt)
B(-4,1,3,minecraft:basalt)
B(-4,2,3,minecraft:basalt)
B(-4,3,3,minecraft:basalt)
B(-4,4,3,minecraft:basalt)
B(-4,5,3,minecraft:basalt)
B(-4,6,3,minecraft:basalt)
B(-4,7,3,minecraft:basalt)
B(-4,8,3,minecraft:basalt)
B(-4,9,3,minecraft:basalt)
B(-4,10,3,minecraft:basalt)
B(-4,11,3,minecraft:basalt)
B(-4,12,3,minecraft:basalt)
B(-4,13,3,minecraft:basalt)
B(-4,14,3,minecraft:basalt)
B(-4,15,3,minecraft:basalt)
B(-4,16,3,minecraft:basalt)
B(-4,17,3,minecraft:basalt)
B(-4,18,3,minecraft:basalt)
B(-4,19,3,minecraft:basalt)
B(-4,20,3,minecraft:basalt)
B(-4,21,3,minecraft:basalt)
B(-4,22,3,minecraft:basalt)
B(-4,23,3,minecraft:basalt)
B(-4,24,3,minecraft:basalt)
B(-4,25,3,minecraft:basalt)
B(-4,26,3,minecraft:basalt)
B(-4,27,3,minecraft:basalt)
B(-4,28,3,minecraft:basalt)
B(-4,29,3,minecraft:basalt)
B(-4,30,3,minecraft:basalt)
B(-4,31,3,minecraft:basalt)
B(-4,32,3,minecraft:basalt)
B(-4,33,3,minecraft:basalt)
B(-4,34,3,minecraft:basalt)
B(-4,35,3,minecraft:basalt)
B(-4,36,3,minecraft:basalt)
B(-4,37,3,minecraft:basalt)
B(-4,38,3,minecraft:basalt)
B(-4,39,3,minecraft:basalt)
B(-4,40,3,minecraft:basalt)
B(-4,41,3,minecraft:basalt)
B(-4,42,3,minecraft:basalt)
B(-4,43,3,minecraft:basalt)
B(-4,44,3,minecraft:basalt)
B(-4,45,3,minecraft:basalt)
B(-4,46,3,minecraft:basalt)
B(-4,47,3,minecraft:basalt)
B(-4,48,3,minecraft:basalt)
B(-4,49,3,minecraft:basalt)
B(-4,50,3,minecraft:basalt)
B(-4,51,3,minecraft:basalt)
B(-4,52,3,minecraft:basalt)
B(-4,53,3,minecraft:basalt)
B(-4,54,3,minecraft:basalt)
B(-4,55,3,minecraft:basalt)
B(-4,56,3,minecraft:basalt)
B(-4,57,3,minecraft:basalt)
B(-4,58,3,minecraft:basalt)
B(-4,59,3,minecraft:basalt)
B(-4,60,3,minecraft:basalt)
B(-4,61,3,minecraft:basalt)
B(-4,62,3,minecraft:basalt)
B(-4,63,3,minecraft:basalt)
B(-4,64,3,minecraft:basalt)
B(-4,65,3,minecraft:basalt)
B(-4,66,3,minecraft:basalt)
B(-4,67,3,minecraft:basalt)
B(-4,68,3,minecraft:basalt)
B(-4,0,4,minecraft:basalt)
B(-4,1,4,minecraft:basalt)
B(-4,2,4,minecraft:basalt)
B(-4,3,4,minecraft:basalt)
B(-4,4,4,minecraft:basalt)
B(-4,5,4,minecraft:basalt)
B(-4,6,4,minecraft:basalt)
B(-4,7,4,minecraft:basalt)
B(-4,8,4,minecraft:basalt)
B(-4,9,4,minecraft:basalt)
B(-4,10,4,minecraft:basalt)
B(-4,11,4,minecraft:basalt)
B(-4,12,4,minecraft:basalt)
B(-4,13,4,minecraft:basalt)
B(-4,14,4,minecraft:basalt)
B(-4,15,4,minecraft:basalt)
B(-4,16,4,minecraft:basalt)
B(-4,17,4,minecraft:basalt)
B(-4,18,4,minecraft:basalt)
B(-4,19,4,minecraft:basalt)
B(-4,20,4,minecraft:basalt)
B(-4,21,4,minecraft:basalt)
B(-4,22,4,minecraft:basalt)
B(-4,23,4,minecraft:basalt)
B(-4,24,4,minecraft:basalt)
B(-4,25,4,minecraft:basalt)
B(-4,26,4,minecraft:basalt)
B(-4,27,4,minecraft:basalt)
B(-4,28,4,minecraft:basalt)
B(-4,29,4,minecraft:basalt)
B(-4,30,4,minecraft:basalt)
B(-4,31,4,minecraft:basalt)
B(-4,32,4,minecraft:basalt)
B(-4,33,4,minecraft:basalt)
B(-4,34,4,minecraft:basalt)
B(-4,35,4,minecraft:basalt)
B(-4,36,4,minecraft:basalt)
B(-4,37,4,minecraft:basalt)
B(-4,38,4,minecraft:basalt)
B(-4,39,4,minecraft:basalt)
B(-4,40,4,minecraft:basalt)
B(-4,41,4,minecraft:basalt)
B(-4,42,4,minecraft:basalt)
B(-4,43,4,minecraft:basalt)
B(-4,44,4,minecraft:basalt)
B(-4,45,4,minecraft:basalt)
B(-4,46,4,minecraft:basalt)
B(-4,47,4,minecraft:basalt)
B(-4,48,4,minecraft:basalt)
B(-4,49,4,minecraft:basalt)
B(-4,50,4,minecraft:basalt)
B(-4,51,4,minecraft:basalt)
B(-4,52,4,minecraft:basalt)
B(-4,53,4,minecraft:basalt)
B(-4,54,4,minecraft:basalt)
B(-4,55,4,minecraft:basalt)
B(-4,56,4,minecraft:basalt)
B(-4,57,4,minecraft:basalt)
B(-4,58,4,minecraft:basalt)
B(-4,59,4,minecraft:basalt)
B(-4,60,4,minecraft:basalt)
B(-4,61,4,minecraft:basalt)
B(-4,62,4,minecraft:basalt)
B(-4,63,4,minecraft:basalt)
B(-4,64,4,minecraft:basalt)
B(-4,65,4,minecraft:basalt)
B(-4,66,4,minecraft:basalt)
B(-4,67,4,minecraft:basalt)
B(-4,68,4,minecraft:basalt)
B(-4,0,5,minecraft:basalt)
B(-4,1,5,minecraft:basalt)
B(-4,2,5,minecraft:basalt)
B(-4,3,5,minecraft:basalt)
B(-4,4,5,minecraft:basalt)
B(-4,5,5,minecraft:basalt)
B(-4,6,5,minecraft:basalt)
B(-4,7,5,minecraft:basalt)
B(-4,8,5,minecraft:basalt)
B(-4,9,5,minecraft:basalt)
B(-4,10,5,minecraft:basalt)
B(-4,11,5,minecraft:basalt)
B(-4,12,5,minecraft:basalt)
B(-4,13,5,minecraft:basalt)
B(-4,14,5,minecraft:basalt)
B(-4,15,5,minecraft:basalt)
B(-4,16,5,minecraft:basalt)
B(-4,17,5,minecraft:basalt)
B(-4,18,5,minecraft:basalt)
B(-4,19,5,minecraft:basalt)
B(-4,20,5,minecraft:basalt)
B(-4,21,5,minecraft:basalt)
B(-4,22,5,minecraft:basalt)
B(-4,23,5,minecraft:basalt)
B(-4,24,5,minecraft:basalt)
B(-4,25,5,minecraft:basalt)
B(-4,26,5,minecraft:basalt)
B(-4,27,5,minecraft:basalt)
B(-4,28,5,minecraft:basalt)
B(-4,29,5,minecraft:basalt)
B(-4,30,5,minecraft:basalt)
B(-4,31,5,minecraft:basalt)
B(-4,32,5,minecraft:basalt)
B(-4,33,5,minecraft:basalt)
B(-4,34,5,minecraft:basalt)
B(-4,35,5,minecraft:basalt)
B(-4,36,5,minecraft:basalt)
B(-4,37,5,minecraft:basalt)
B(-4,38,5,minecraft:basalt)
B(-4,39,5,minecraft:basalt)
B(-4,40,5,minecraft:basalt)
B(-4,41,5,minecraft:basalt)
B(-4,42,5,minecraft:basalt)
B(-4,43,5,minecraft:basalt)
B(-4,44,5,minecraft:basalt)
B(-4,45,5,minecraft:basalt)
B(-4,46,5,minecraft:basalt)
B(-4,47,5,minecraft:basalt)
B(-4,48,5,minecraft:basalt)
B(-4,49,5,minecraft:basalt)
B(-4,50,5,minecraft:basalt)
B(-4,51,5,minecraft:basalt)
B(-4,52,5,minecraft:basalt)
B(-4,53,5,minecraft:basalt)
B(-4,54,5,minecraft:basalt)
B(-4,55,5,minecraft:basalt)
B(-4,56,5,minecraft:basalt)
B(-4,57,5,minecraft:basalt)
B(-4,58,5,minecraft:basalt)
B(-4,59,5,minecraft:basalt)
B(-4,60,5,minecraft:basalt)
B(-4,61,5,minecraft:basalt)
B(-4,62,5,minecraft:basalt)
B(-4,63,5,minecraft:basalt)
B(-4,64,5,minecraft:basalt)
B(-4,65,5,minecraft:basalt)
B(-4,66,5,minecraft:basalt)
B(-4,67,5,minecraft:basalt)
B(-4,68,5,minecraft:basalt)
B(-4,0,6,minecraft:basalt)
B(-4,1,6,minecraft:basalt)
B(-4,2,6,minecraft:basalt)
B(-4,3,6,minecraft:basalt)
B(-4,4,6,minecraft:basalt)
B(-4,5,6,minecraft:basalt)
B(-4,6,6,minecraft:basalt)
B(-4,7,6,minecraft:basalt)
B(-4,8,6,minecraft:basalt)
B(-4,9,6,minecraft:basalt)
B(-4,10,6,minecraft:basalt)
B(-4,11,6,minecraft:basalt)
B(-4,12,6,minecraft:basalt)
B(-4,13,6,minecraft:basalt)
B(-4,14,6,minecraft:basalt)
B(-4,15,6,minecraft:basalt)
B(-4,16,6,minecraft:basalt)
B(-4,17,6,minecraft:basalt)
B(-4,18,6,minecraft:basalt)
B(-4,19,6,minecraft:basalt)
B(-4,20,6,minecraft:basalt)
B(-4,21,6,minecraft:basalt)
B(-4,22,6,minecraft:basalt)
B(-4,23,6,minecraft:basalt)
B(-4,24,6,minecraft:basalt)
B(-4,25,6,minecraft:basalt)
B(-4,26,6,minecraft:basalt)
B(-4,27,6,minecraft:basalt)
B(-4,28,6,minecraft:basalt)
B(-4,29,6,minecraft:basalt)
B(-4,30,6,minecraft:basalt)
B(-4,31,6,minecraft:basalt)
B(-4,32,6,minecraft:basalt)
B(-4,33,6,minecraft:basalt)
B(-4,34,6,minecraft:basalt)
B(-4,35,6,minecraft:basalt)
B(-4,36,6,minecraft:basalt)
B(-4,37,6,minecraft:basalt)
B(-4,38,6,minecraft:basalt)
B(-4,39,6,minecraft:basalt)
B(-4,40,6,minecraft:basalt)
B(-4,41,6,minecraft:basalt)
B(-4,42,6,minecraft:basalt)
B(-4,43,6,minecraft:basalt)
B(-4,44,6,minecraft:basalt)
B(-4,45,6,minecraft:basalt)
B(-4,46,6,minecraft:basalt)
B(-4,47,6,minecraft:basalt)
B(-4,48,6,minecraft:basalt)
B(-4,49,6,minecraft:basalt)
B(-4,50,6,minecraft:basalt)
B(-4,51,6,minecraft:basalt)
B(-4,52,6,minecraft:basalt)
B(-4,53,6,minecraft:basalt)
B(-4,54,6,minecraft:basalt)
B(-4,55,6,minecraft:basalt)
B(-4,56,6,minecraft:basalt)
B(-4,57,6,minecraft:basalt)
B(-4,58,6,minecraft:basalt)
B(-4,59,6,minecraft:basalt)
B(-4,60,6,minecraft:basalt)
B(-4,61,6,minecraft:basalt)
B(-4,62,6,minecraft:basalt)
B(-4,63,6,minecraft:basalt)
B(-4,64,6,minecraft:basalt)
B(-4,65,6,minecraft:basalt)
B(-4,66,6,minecraft:basalt)
B(-4,67,6,minecraft:basalt)
B(-4,0,7,minecraft:basalt)
B(-4,1,7,minecraft:basalt)
B(-4,2,7,minecraft:basalt)
B(-4,3,7,minecraft:basalt)
B(-4,4,7,minecraft:basalt)
B(-4,5,7,minecraft:basalt)
B(-4,6,7,minecraft:basalt)
B(-4,7,7,minecraft:basalt)
B(-4,8,7,minecraft:basalt)
B(-4,9,7,minecraft:basalt)
B(-4,10,7,minecraft:basalt)
B(-4,11,7,minecraft:basalt)
B(-4,12,7,minecraft:basalt)
B(-4,13,7,minecraft:basalt)
B(-4,14,7,minecraft:basalt)
B(-4,15,7,minecraft:basalt)
B(-4,16,7,minecraft:basalt)
B(-4,17,7,minecraft:basalt)
B(-4,18,7,minecraft:basalt)
B(-4,19,7,minecraft:basalt)
B(-4,20,7,minecraft:basalt)
B(-4,21,7,minecraft:basalt)
B(-4,22,7,minecraft:basalt)
B(-4,23,7,minecraft:basalt)
B(-4,24,7,minecraft:basalt)
B(-4,25,7,minecraft:basalt)
B(-4,26,7,minecraft:basalt)
B(-4,27,7,minecraft:basalt)
B(-4,28,7,minecraft:basalt)
B(-4,29,7,minecraft:basalt)
B(-4,30,7,minecraft:basalt)
B(-4,31,7,minecraft:basalt)
B(-4,32,7,minecraft:basalt)
B(-4,33,7,minecraft:basalt)
B(-4,34,7,minecraft:basalt)
B(-4,35,7,minecraft:basalt)
B(-4,36,7,minecraft:basalt)
B(-4,37,7,minecraft:basalt)
B(-4,38,7,minecraft:basalt)
B(-4,39,7,minecraft:basalt)
B(-4,40,7,minecraft:basalt)
B(-4,41,7,minecraft:basalt)
B(-4,42,7,minecraft:basalt)
B(-4,43,7,minecraft:basalt)
B(-4,44,7,minecraft:basalt)
B(-4,45,7,minecraft:basalt)
B(-4,46,7,minecraft:basalt)
B(-4,47,7,minecraft:basalt)
B(-4,48,7,minecraft:basalt)
B(-4,49,7,minecraft:basalt)
B(-4,50,7,minecraft:basalt)
B(-4,51,7,minecraft:basalt)
B(-4,52,7,minecraft:basalt)
B(-4,53,7,minecraft:basalt)
B(-4,54,7,minecraft:basalt)
B(-4,55,7,minecraft:basalt)
B(-4,56,7,minecraft:basalt)
B(-4,57,7,minecraft:basalt)
B(-4,58,7,minecraft:basalt)
B(-4,59,7,minecraft:basalt)
B(-4,60,7,minecraft:basalt)
B(-4,61,7,minecraft:basalt)
B(-4,62,7,minecraft:basalt)
B(-4,63,7,minecraft:basalt)
B(-4,64,7,minecraft:basalt)
B(-4,65,7,minecraft:basalt)
B(-4,0,8,minecraft:basalt)
B(-4,1,8,minecraft:basalt)
B(-4,2,8,minecraft:basalt)
B(-4,3,8,minecraft:basalt)
B(-4,4,8,minecraft:basalt)
B(-4,5,8,minecraft:basalt)
B(-4,6,8,minecraft:basalt)
B(-4,7,8,minecraft:basalt)
B(-4,8,8,minecraft:basalt)
B(-4,9,8,minecraft:basalt)
B(-4,10,8,minecraft:basalt)
B(-4,11,8,minecraft:basalt)
B(-4,12,8,minecraft:basalt)
B(-4,13,8,minecraft:basalt)
B(-4,14,8,minecraft:basalt)
B(-4,15,8,minecraft:basalt)
B(-4,16,8,minecraft:basalt)
B(-4,17,8,minecraft:basalt)
B(-4,18,8,minecraft:basalt)
B(-4,19,8,minecraft:basalt)
B(-4,20,8,minecraft:basalt)
B(-4,21,8,minecraft:basalt)
B(-4,22,8,minecraft:basalt)
B(-4,23,8,minecraft:basalt)
B(-4,24,8,minecraft:basalt)
B(-4,25,8,minecraft:basalt)
B(-4,26,8,minecraft:basalt)
B(-4,27,8,minecraft:basalt)
B(-4,28,8,minecraft:basalt)
B(-4,29,8,minecraft:basalt)
B(-4,30,8,minecraft:basalt)
B(-4,31,8,minecraft:basalt)
B(-4,32,8,minecraft:basalt)
B(-4,33,8,minecraft:basalt)
B(-4,34,8,minecraft:basalt)
B(-4,35,8,minecraft:basalt)
B(-4,36,8,minecraft:basalt)
B(-4,37,8,minecraft:basalt)
B(-4,38,8,minecraft:basalt)
B(-4,39,8,minecraft:basalt)
B(-3,0,-7,minecraft:basalt)
B(-3,1,-7,minecraft:basalt)
B(-3,2,-7,minecraft:soul_soil)
B(-3,3,-7,minecraft:soul_soil)
B(-3,4,-7,minecraft:soul_soil)
B(-3,5,-7,minecraft:basalt)
B(-3,0,-6,minecraft:basalt)
B(-3,1,-6,minecraft:basalt)
B(-3,2,-6,minecraft:soul_soil)
B(-3,3,-6,minecraft:soul_soil)
B(-3,4,-6,minecraft:soul_soil)
B(-3,5,-6,minecraft:basalt)
B(-3,0,-5,minecraft:basalt)
B(-3,1,-5,minecraft:basalt)
B(-3,2,-5,minecraft:soul_soil)
B(-3,3,-5,minecraft:soul_soil)
B(-3,4,-5,minecraft:soul_soil)
B(-3,5,-5,minecraft:basalt)
B(-3,0,-4,minecraft:basalt)
B(-3,1,-4,minecraft:basalt)
B(-3,2,-4,minecraft:soul_soil)
B(-3,3,-4,minecraft:soul_soil)
B(-3,4,-4,minecraft:soul_soil)
B(-3,5,-4,minecraft:basalt)
B(-3,0,-3,minecraft:basalt)
B(-3,1,-3,minecraft:soul_soil)
B(-3,2,-3,minecraft:soul_soil)
B(-3,3,-3,minecraft:soul_soil)
B(-3,4,-3,minecraft:basalt)
B(-3,0,-2,minecraft:basalt)
B(-3,1,-2,minecraft:basalt)
B(-3,2,-2,minecraft:basalt)
B(-3,3,-2,minecraft:basalt)
B(-3,4,-2,minecraft:basalt)
B(-3,5,-2,minecraft:basalt)
B(-3,6,-2,minecraft:basalt)
B(-3,7,-2,minecraft:basalt)
B(-3,8,-2,minecraft:basalt)
B(-3,9,-2,minecraft:basalt)
B(-3,10,-2,minecraft:basalt)
B(-3,11,-2,minecraft:basalt)
B(-3,12,-2,minecraft:basalt)
B(-3,13,-2,minecraft:basalt)
B(-3,14,-2,minecraft:basalt)
B(-3,15,-2,minecraft:basalt)
B(-3,16,-2,minecraft:basalt)
B(-3,17,-2,minecraft:basalt)
B(-3,18,-2,minecraft:basalt)
B(-3,19,-2,minecraft:basalt)
B(-3,20,-2,minecraft:basalt)
B(-3,21,-2,minecraft:basalt)
B(-3,22,-2,minecraft:basalt)
B(-3,23,-2,minecraft:basalt)
B(-3,24,-2,minecraft:basalt)
B(-3,25,-2,minecraft:basalt)
B(-3,26,-2,minecraft:basalt)
B(-3,27,-2,minecraft:basalt)
B(-3,28,-2,minecraft:basalt)
B(-3,29,-2,minecraft:basalt)
B(-3,30,-2,minecraft:basalt)
B(-3,31,-2,minecraft:basalt)
B(-3,32,-2,minecraft:basalt)
B(-3,33,-2,minecraft:basalt)
B(-3,34,-2,minecraft:basalt)
B(-3,35,-2,minecraft:basalt)
B(-3,36,-2,minecraft:basalt)
B(-3,37,-2,minecraft:basalt)
B(-3,38,-2,minecraft:basalt)
B(-3,39,-2,minecraft:basalt)
B(-3,40,-2,minecraft:basalt)
B(-3,41,-2,minecraft:basalt)
B(-3,42,-2,minecraft:basalt)
B(-3,43,-2,minecraft:basalt)
B(-3,44,-2,minecraft:basalt)
B(-3,45,-2,minecraft:basalt)
B(-3,46,-2,minecraft:basalt)
B(-3,47,-2,minecraft:basalt)
B(-3,48,-2,minecraft:basalt)
B(-3,49,-2,minecraft:basalt)
B(-3,50,-2,minecraft:basalt)
B(-3,51,-2,minecraft:basalt)
B(-3,52,-2,minecraft:basalt)
B(-3,53,-2,minecraft:basalt)
B(-3,54,-2,minecraft:basalt)
B(-3,0,-1,minecraft:basalt)
B(-3,1,-1,minecraft:basalt)
B(-3,2,-1,minecraft:basalt)
B(-3,3,-1,minecraft:basalt)
B(-3,4,-1,minecraft:basalt)
B(-3,5,-1,minecraft:basalt)
B(-3,6,-1,minecraft:basalt)
B(-3,7,-1,minecraft:basalt)
B(-3,8,-1,minecraft:basalt)
B(-3,9,-1,minecraft:basalt)
B(-3,10,-1,minecraft:basalt)
B(-3,11,-1,minecraft:basalt)
B(-3,12,-1,minecraft:basalt)
B(-3,13,-1,minecraft:basalt)
B(-3,14,-1,minecraft:basalt)
B(-3,15,-1,minecraft:basalt)
B(-3,16,-1,minecraft:basalt)
B(-3,17,-1,minecraft:basalt)
B(-3,18,-1,minecraft:basalt)
B(-3,19,-1,minecraft:basalt)
B(-3,20,-1,minecraft:basalt)
B(-3,21,-1,minecraft:basalt)
B(-3,22,-1,minecraft:basalt)
B(-3,23,-1,minecraft:basalt)
B(-3,24,-1,minecraft:basalt)
B(-3,25,-1,minecraft:basalt)
B(-3,26,-1,minecraft:basalt)
B(-3,27,-1,minecraft:basalt)
B(-3,28,-1,minecraft:basalt)
B(-3,29,-1,minecraft:basalt)
B(-3,30,-1,minecraft:basalt)
B(-3,31,-1,minecraft:basalt)
B(-3,32,-1,minecraft:basalt)
B(-3,33,-1,minecraft:basalt)
B(-3,34,-1,minecraft:basalt)
B(-3,35,-1,minecraft:basalt)
B(-3,36,-1,minecraft:basalt)
B(-3,37,-1,minecraft:basalt)
B(-3,38,-1,minecraft:basalt)
B(-3,39,-1,minecraft:basalt)
B(-3,40,-1,minecraft:basalt)
B(-3,41,-1,minecraft:basalt)
B(-3,42,-1,minecraft:basalt)
B(-3,43,-1,minecraft:basalt)
B(-3,44,-1,minecraft:basalt)
B(-3,45,-1,minecraft:basalt)
B(-3,46,-1,minecraft:basalt)
B(-3,47,-1,minecraft:basalt)
B(-3,48,-1,minecraft:basalt)
B(-3,49,-1,minecraft:basalt)
B(-3,50,-1,minecraft:basalt)
B(-3,51,-1,minecraft:basalt)
B(-3,52,-1,minecraft:basalt)
B(-3,53,-1,minecraft:basalt)
B(-3,54,-1,minecraft:basalt)
B(-3,55,-1,minecraft:basalt)
B(-3,56,-1,minecraft:basalt)
B(-3,57,-1,minecraft:basalt)
B(-3,58,-1,minecraft:basalt)
B(-3,59,-1,minecraft:basalt)
B(-3,60,-1,minecraft:basalt)
B(-3,61,-1,minecraft:basalt)
B(-3,62,-1,minecraft:basalt)
B(-3,63,-1,minecraft:basalt)
B(-3,64,-1,minecraft:basalt)
B(-3,65,-1,minecraft:basalt)
B(-3,66,-1,minecraft:basalt)
B(-3,0,0,minecraft:basalt)
B(-3,1,0,minecraft:basalt)
B(-3,2,0,minecraft:basalt)
B(-3,3,0,minecraft:basalt)
B(-3,4,0,minecraft:basalt)
B(-3,5,0,minecraft:basalt)
B(-3,6,0,minecraft:basalt)
B(-3,7,0,minecraft:basalt)
B(-3,8,0,minecraft:basalt)
B(-3,9,0,minecraft:basalt)
B(-3,10,0,minecraft:basalt)
B(-3,11,0,minecraft:basalt)
B(-3,12,0,minecraft:basalt)
B(-3,13,0,minecraft:basalt)
B(-3,14,0,minecraft:basalt)
B(-3,15,0,minecraft:basalt)
B(-3,16,0,minecraft:basalt)
B(-3,17,0,minecraft:basalt)
B(-3,18,0,minecraft:basalt)
B(-3,19,0,minecraft:basalt)
B(-3,20,0,minecraft:basalt)
B(-3,21,0,minecraft:basalt)
B(-3,22,0,minecraft:basalt)
B(-3,23,0,minecraft:basalt)
B(-3,24,0,minecraft:basalt)
B(-3,25,0,minecraft:basalt)
B(-3,26,0,minecraft:basalt)
B(-3,27,0,minecraft:basalt)
B(-3,28,0,minecraft:basalt)
B(-3,29,0,minecraft:basalt)
B(-3,30,0,minecraft:basalt)
B(-3,31,0,minecraft:basalt)
B(-3,32,0,minecraft:basalt)
B(-3,33,0,minecraft:basalt)
B(-3,34,0,minecraft:basalt)
B(-3,35,0,minecraft:basalt)
B(-3,36,0,minecraft:basalt)
B(-3,37,0,minecraft:basalt)
B(-3,38,0,minecraft:basalt)
B(-3,39,0,minecraft:basalt)
B(-3,40,0,minecraft:basalt)
B(-3,41,0,minecraft:basalt)
B(-3,42,0,minecraft:basalt)
B(-3,43,0,minecraft:basalt)
B(-3,44,0,minecraft:basalt)
B(-3,45,0,minecraft:basalt)
B(-3,46,0,minecraft:basalt)
B(-3,47,0,minecraft:basalt)
B(-3,48,0,minecraft:basalt)
B(-3,49,0,minecraft:basalt)
B(-3,50,0,minecraft:basalt)
B(-3,51,0,minecraft:basalt)
B(-3,52,0,minecraft:basalt)
B(-3,53,0,minecraft:basalt)
B(-3,54,0,minecraft:basalt)
B(-3,55,0,minecraft:basalt)
B(-3,56,0,minecraft:basalt)
B(-3,57,0,minecraft:basalt)
B(-3,58,0,minecraft:basalt)
B(-3,59,0,minecraft:basalt)
B(-3,60,0,minecraft:basalt)
B(-3,61,0,minecraft:basalt)
B(-3,62,0,minecraft:basalt)
B(-3,63,0,minecraft:basalt)
B(-3,64,0,minecraft:basalt)
B(-3,65,0,minecraft:basalt)
B(-3,66,0,minecraft:basalt)
B(-3,67,0,minecraft:basalt)
B(-3,0,1,minecraft:basalt)
B(-3,1,1,minecraft:basalt)
B(-3,2,1,minecraft:basalt)
B(-3,3,1,minecraft:basalt)
B(-3,4,1,minecraft:basalt)
B(-3,5,1,minecraft:basalt)
B(-3,6,1,minecraft:basalt)
B(-3,7,1,minecraft:basalt)
B(-3,8,1,minecraft:basalt)
B(-3,9,1,minecraft:basalt)
B(-3,10,1,minecraft:basalt)
B(-3,11,1,minecraft:basalt)
B(-3,12,1,minecraft:basalt)
B(-3,13,1,minecraft:basalt)
B(-3,14,1,minecraft:basalt)
B(-3,15,1,minecraft:basalt)
B(-3,16,1,minecraft:basalt)
B(-3,17,1,minecraft:basalt)
B(-3,18,1,minecraft:basalt)
B(-3,19,1,minecraft:basalt)
B(-3,20,1,minecraft:basalt)
B(-3,21,1,minecraft:basalt)
B(-3,22,1,minecraft:basalt)
B(-3,23,1,minecraft:basalt)
B(-3,24,1,minecraft:basalt)
B(-3,25,1,minecraft:basalt)
B(-3,26,1,minecraft:basalt)
B(-3,27,1,minecraft:basalt)
B(-3,28,1,minecraft:basalt)
B(-3,29,1,minecraft:basalt)
B(-3,30,1,minecraft:basalt)
B(-3,31,1,minecraft:basalt)
B(-3,32,1,minecraft:basalt)
B(-3,33,1,minecraft:basalt)
B(-3,34,1,minecraft:basalt)
B(-3,35,1,minecraft:basalt)
B(-3,36,1,minecraft:basalt)
B(-3,37,1,minecraft:basalt)
B(-3,38,1,minecraft:basalt)
B(-3,39,1,minecraft:basalt)
B(-3,40,1,minecraft:basalt)
B(-3,41,1,minecraft:basalt)
B(-3,42,1,minecraft:basalt)
B(-3,43,1,minecraft:basalt)
B(-3,44,1,minecraft:basalt)
B(-3,45,1,minecraft:basalt)
B(-3,46,1,minecraft:basalt)
B(-3,47,1,minecraft:basalt)
B(-3,48,1,minecraft:basalt)
B(-3,49,1,minecraft:basalt)
B(-3,50,1,minecraft:basalt)
B(-3,51,1,minecraft:basalt)
B(-3,52,1,minecraft:basalt)
B(-3,53,1,minecraft:basalt)
B(-3,54,1,minecraft:basalt)
B(-3,55,1,minecraft:basalt)
B(-3,56,1,minecraft:basalt)
B(-3,57,1,minecraft:basalt)
B(-3,58,1,minecraft:basalt)
B(-3,59,1,minecraft:basalt)
B(-3,60,1,minecraft:basalt)
B(-3,61,1,minecraft:basalt)
B(-3,62,1,minecraft:basalt)
B(-3,63,1,minecraft:basalt)
B(-3,64,1,minecraft:basalt)
B(-3,65,1,minecraft:basalt)
B(-3,66,1,minecraft:basalt)
B(-3,67,1,minecraft:basalt)
B(-3,68,1,minecraft:basalt)
B(-3,0,2,minecraft:basalt)
B(-3,1,2,minecraft:basalt)
B(-3,2,2,minecraft:basalt)
B(-3,3,2,minecraft:basalt)
B(-3,4,2,minecraft:basalt)
B(-3,5,2,minecraft:basalt)
B(-3,6,2,minecraft:basalt)
B(-3,7,2,minecraft:basalt)
B(-3,8,2,minecraft:basalt)
B(-3,9,2,minecraft:basalt)
B(-3,10,2,minecraft:basalt)
B(-3,11,2,minecraft:basalt)
B(-3,12,2,minecraft:basalt)
B(-3,13,2,minecraft:basalt)
B(-3,14,2,minecraft:basalt)
B(-3,15,2,minecraft:basalt)
B(-3,16,2,minecraft:basalt)
B(-3,17,2,minecraft:basalt)
B(-3,18,2,minecraft:basalt)
B(-3,19,2,minecraft:basalt)
B(-3,20,2,minecraft:basalt)
B(-3,21,2,minecraft:basalt)
B(-3,22,2,minecraft:basalt)
B(-3,23,2,minecraft:basalt)
B(-3,24,2,minecraft:basalt)
B(-3,25,2,minecraft:basalt)
B(-3,26,2,minecraft:basalt)
B(-3,27,2,minecraft:basalt)
B(-3,28,2,minecraft:basalt)
B(-3,29,2,minecraft:basalt)
B(-3,30,2,minecraft:basalt)
B(-3,31,2,minecraft:basalt)
B(-3,32,2,minecraft:basalt)
B(-3,33,2,minecraft:basalt)
B(-3,34,2,minecraft:basalt)
B(-3,35,2,minecraft:basalt)
B(-3,36,2,minecraft:basalt)
B(-3,37,2,minecraft:basalt)
B(-3,38,2,minecraft:basalt)
B(-3,39,2,minecraft:basalt)
B(-3,40,2,minecraft:basalt)
B(-3,41,2,minecraft:basalt)
B(-3,42,2,minecraft:basalt)
B(-3,43,2,minecraft:basalt)
B(-3,44,2,minecraft:basalt)
B(-3,45,2,minecraft:basalt)
B(-3,46,2,minecraft:basalt)
B(-3,47,2,minecraft:basalt)
B(-3,48,2,minecraft:basalt)
B(-3,49,2,minecraft:basalt)
B(-3,50,2,minecraft:basalt)
B(-3,51,2,minecraft:basalt)
B(-3,52,2,minecraft:basalt)
B(-3,53,2,minecraft:basalt)
B(-3,54,2,minecraft:basalt)
B(-3,55,2,minecraft:basalt)
B(-3,56,2,minecraft:basalt)
B(-3,57,2,minecraft:basalt)
B(-3,58,2,minecraft:basalt)
B(-3,59,2,minecraft:basalt)
B(-3,60,2,minecraft:basalt)
B(-3,61,2,minecraft:basalt)
B(-3,62,2,minecraft:basalt)
B(-3,63,2,minecraft:basalt)
B(-3,64,2,minecraft:basalt)
B(-3,65,2,minecraft:basalt)
B(-3,66,2,minecraft:basalt)
B(-3,67,2,minecraft:basalt)
B(-3,68,2,minecraft:basalt)
B(-3,0,3,minecraft:basalt)
B(-3,1,3,minecraft:basalt)
B(-3,2,3,minecraft:basalt)
B(-3,3,3,minecraft:basalt)
B(-3,4,3,minecraft:basalt)
B(-3,5,3,minecraft:basalt)
B(-3,6,3,minecraft:basalt)
B(-3,7,3,minecraft:basalt)
B(-3,8,3,minecraft:basalt)
B(-3,9,3,minecraft:basalt)
B(-3,10,3,minecraft:basalt)
B(-3,11,3,minecraft:basalt)
B(-3,12,3,minecraft:basalt)
B(-3,13,3,minecraft:basalt)
B(-3,14,3,minecraft:basalt)
B(-3,15,3,minecraft:basalt)
B(-3,16,3,minecraft:basalt)
B(-3,17,3,minecraft:basalt)
B(-3,18,3,minecraft:basalt)
B(-3,19,3,minecraft:basalt)
B(-3,20,3,minecraft:basalt)
B(-3,21,3,minecraft:basalt)
B(-3,22,3,minecraft:basalt)
B(-3,23,3,minecraft:basalt)
B(-3,24,3,minecraft:basalt)
B(-3,25,3,minecraft:basalt)
B(-3,26,3,minecraft:basalt)
B(-3,27,3,minecraft:basalt)
