
#######################################################################
# +-----------------------------------------------------------------+ #
# |                            BO4 object                           | #
# +-----------------------------------------------------------------+ #
#######################################################################

Author: Unknown

Description: No description given

SettingsMode: WriteWithoutComments


#######################################################################
# +-----------------------------------------------------------------+ #
# |                          Main settings                          | #
# +-----------------------------------------------------------------+ #
#######################################################################

FixedRotation: 

Frequency: 0

SpawnHeight: highestBlock

UseCenterForHighestBlock: true

##############################
# Height Limits for the BO4. #
##############################

MinHeight: 0

MaxHeight: 255

InheritBO3: 

InheritBO3Rotation: NORTH

OverrideChildSettings: true

OverrideParentHeight: false

CanOverride: false

BranchFrequency: 0

BranchFrequencyGroup: 

MustBeBelowOther: false

MustBeInside: 

CannotBeInside: 

ReplacesBO3: 

MustBeInsideWorldBorders: false

CanSpawnOnWater: true

SpawnOnWaterOnly: false

SpawnUnderWater: false

SpawnAtWaterLevel: false

HeightOffset: 0

RemoveAir: true

ReplaceAbove: 

ReplaceBelow: 

ReplaceWithBiomeBlocks: true

ReplaceWithSurfaceBlock: GRASS

ReplaceWithGroundBlock: DIRT

ReplaceWithStoneBlock: STONE

SmoothRadius: 0

SmoothHeightOffset: 0

SmoothStartTop: false

SmoothStartWood: false

SmoothingSurfaceBlock: 

SmoothingGroundBlock: 

BO3Group: 

IsSpawnPoint: false

DoReplaceBlocks: true


#######################################################################
# +-----------------------------------------------------------------+ #
# |                              Blocks                             | #
# +-----------------------------------------------------------------+ #
#######################################################################

B(-8,0,-7,minecraft:soul_soil)
B(-8,1,-7,minecraft:soul_soil)
B(-8,2,-7,minecraft:basalt)
B(-8,0,-6,minecraft:basalt)
B(-8,1,-6,minecraft:soul_soil)
B(-8,2,-6,minecraft:basalt)
B(-8,0,-5,minecraft:basalt)
B(-8,1,-5,minecraft:soul_soil)
B(-8,2,-5,minecraft:basalt)
B(-8,0,-4,minecraft:basalt)
B(-8,1,-4,minecraft:soul_soil)
B(-8,2,-4,minecraft:basalt)
B(-8,0,-3,minecraft:soul_soil)
B(-8,1,-3,minecraft:soul_soil)
B(-8,2,-3,minecraft:basalt)
B(-8,0,-2,minecraft:soul_soil)
B(-8,1,-2,minecraft:soul_soil)
B(-8,2,-2,minecraft:basalt)
B(-8,0,-1,minecraft:basalt)
B(-8,1,-1,minecraft:basalt)
B(-8,2,-1,minecraft:soul_soil)
B(-8,3,-1,minecraft:basalt)
B(-8,0,0,minecraft:basalt)
B(-8,1,0,minecraft:soul_soil)
B(-8,2,0,minecraft:soul_soil)
B(-8,3,0,minecraft:basalt)
B(-8,0,1,minecraft:basalt)
B(-8,1,1,minecraft:basalt)
B(-8,2,1,minecraft:soul_soil)
B(-8,3,1,minecraft:soul_soil)
B(-8,4,1,minecraft:basalt)
B(-8,0,2,minecraft:basalt)
B(-8,1,2,minecraft:basalt)
B(-8,2,2,minecraft:basalt)
B(-8,3,2,minecraft:soul_soil)
B(-8,4,2,minecraft:soul_soil)
B(-8,5,2,minecraft:basalt)
B(-8,0,3,minecraft:basalt)
B(-8,1,3,minecraft:basalt)
B(-8,2,3,minecraft:basalt)
B(-8,3,3,minecraft:soul_soil)
B(-8,4,3,minecraft:soul_soil)
B(-8,5,3,minecraft:basalt)
B(-8,0,4,minecraft:basalt)
B(-8,1,4,minecraft:basalt)
B(-8,2,4,minecraft:basalt)
B(-8,3,4,minecraft:soul_soil)
B(-8,4,4,minecraft:soul_soil)
B(-8,5,4,minecraft:basalt)
B(-8,0,5,minecraft:basalt)
B(-8,1,5,minecraft:basalt)
B(-8,2,5,minecraft:basalt)
B(-8,3,5,minecraft:soul_soil)
B(-8,4,5,minecraft:soul_soil)
B(-8,5,5,minecraft:basalt)
B(-8,0,6,minecraft:basalt)
B(-8,1,6,minecraft:basalt)
B(-8,2,6,minecraft:basalt)
B(-8,3,6,minecraft:soul_soil)
B(-8,4,6,minecraft:soul_soil)
B(-8,5,6,minecraft:basalt)
B(-8,0,7,minecraft:basalt)
B(-8,1,7,minecraft:basalt)
B(-8,2,7,minecraft:soul_soil)
B(-8,3,7,minecraft:soul_soil)
B(-8,4,7,minecraft:basalt)
B(-8,0,8,minecraft:soul_soil)
B(-8,1,8,minecraft:basalt)
B(-7,0,-7,minecraft:basalt)
B(-7,1,-7,minecraft:basalt)
B(-7,2,-7,minecraft:soul_soil)
B(-7,3,-7,minecraft:basalt)
B(-7,0,-6,minecraft:soul_soil)
B(-7,1,-6,minecraft:soul_soil)
B(-7,2,-6,minecraft:basalt)
B(-7,0,-5,minecraft:soul_soil)
B(-7,1,-5,minecraft:soul_soil)
B(-7,2,-5,minecraft:basalt)
B(-7,0,-4,minecraft:basalt)
B(-7,1,-4,minecraft:basalt)
B(-7,2,-4,minecraft:soul_soil)
B(-7,3,-4,minecraft:basalt)
B(-7,0,-3,minecraft:basalt)
B(-7,1,-3,minecraft:soul_soil)
B(-7,2,-3,minecraft:soul_soil)
B(-7,3,-3,minecraft:basalt)
B(-7,0,-2,minecraft:basalt)
B(-7,1,-2,minecraft:soul_soil)
B(-7,2,-2,minecraft:soul_soil)
B(-7,3,-2,minecraft:basalt)
B(-7,0,-1,minecraft:basalt)
B(-7,1,-1,minecraft:soul_soil)
B(-7,2,-1,minecraft:soul_soil)
B(-7,3,-1,minecraft:basalt)
B(-7,0,0,minecraft:basalt)
B(-7,1,0,minecraft:soul_soil)
B(-7,2,0,minecraft:soul_soil)
B(-7,3,0,minecraft:basalt)
B(-7,0,1,minecraft:basalt)
B(-7,1,1,minecraft:soul_soil)
B(-7,2,1,minecraft:soul_soil)
B(-7,3,1,minecraft:basalt)
B(-7,0,2,minecraft:basalt)
B(-7,1,2,minecraft:soul_soil)
B(-7,2,2,minecraft:soul_soil)
B(-7,3,2,minecraft:basalt)
B(-7,0,3,minecraft:basalt)
B(-7,1,3,minecraft:basalt)
B(-7,2,3,minecraft:soul_soil)
B(-7,3,3,minecraft:soul_soil)
B(-7,4,3,minecraft:basalt)
B(-7,0,4,minecraft:basalt)
B(-7,1,4,minecraft:basalt)
B(-7,2,4,minecraft:basalt)
B(-7,3,4,minecraft:soul_soil)
B(-7,4,4,minecraft:soul_soil)
B(-7,5,4,minecraft:basalt)
B(-7,0,5,minecraft:basalt)
B(-7,1,5,minecraft:basalt)
B(-7,2,5,minecraft:basalt)
B(-7,3,5,minecraft:soul_soil)
B(-7,4,5,minecraft:soul_soil)
B(-7,5,5,minecraft:basalt)
B(-7,0,6,minecraft:basalt)
B(-7,1,6,minecraft:basalt)
B(-7,2,6,minecraft:basalt)
B(-7,3,6,minecraft:soul_soil)
B(-7,4,6,minecraft:soul_soil)
B(-7,5,6,minecraft:basalt)
B(-7,0,7,minecraft:basalt)
B(-7,1,7,minecraft:basalt)
B(-7,2,7,minecraft:soul_soil)
B(-7,3,7,minecraft:soul_soil)
B(-7,4,7,minecraft:basalt)
B(-7,0,8,minecraft:soul_soil)
B(-7,1,8,minecraft:basalt)
B(-6,0,-7,minecraft:basalt)
B(-6,1,-7,minecraft:basalt)
B(-6,2,-7,minecraft:soul_soil)
B(-6,3,-7,minecraft:basalt)
B(-6,0,-6,minecraft:basalt)
B(-6,1,-6,minecraft:basalt)
B(-6,2,-6,minecraft:soul_soil)
B(-6,3,-6,minecraft:basalt)
B(-6,0,-5,minecraft:basalt)
B(-6,1,-5,minecraft:soul_soil)
B(-6,2,-5,minecraft:soul_soil)
B(-6,3,-5,minecraft:basalt)
B(-6,0,-4,minecraft:basalt)
B(-6,1,-4,minecraft:basalt)
B(-6,2,-4,minecraft:soul_soil)
B(-6,3,-4,minecraft:basalt)
B(-6,0,-3,minecraft:basalt)
B(-6,1,-3,minecraft:basalt)
B(-6,2,-3,minecraft:soul_soil)
B(-6,3,-3,minecraft:basalt)
B(-6,0,-2,minecraft:basalt)
B(-6,1,-2,minecraft:basalt)
B(-6,2,-2,minecraft:basalt)
B(-6,3,-2,minecraft:soul_soil)
B(-6,4,-2,minecraft:basalt)
B(-6,0,-1,minecraft:basalt)
B(-6,1,-1,minecraft:soul_soil)
B(-6,2,-1,minecraft:soul_soil)
B(-6,3,-1,minecraft:basalt)
B(-6,0,0,minecraft:basalt)
B(-6,1,0,minecraft:basalt)
B(-6,2,0,minecraft:soul_soil)
B(-6,3,0,minecraft:basalt)
B(-6,0,1,minecraft:soul_soil)
B(-6,1,1,minecraft:soul_soil)
B(-6,2,1,minecraft:basalt)
B(-6,0,2,minecraft:soul_soil)
B(-6,1,2,minecraft:soul_soil)
B(-6,2,2,minecraft:basalt)
B(-6,0,3,minecraft:basalt)
B(-6,1,3,minecraft:soul_soil)
B(-6,2,3,minecraft:soul_soil)
B(-6,3,3,minecraft:basalt)
B(-6,0,4,minecraft:basalt)
B(-6,1,4,minecraft:basalt)
B(-6,2,4,minecraft:basalt)
B(-6,3,4,minecraft:soul_soil)
B(-6,4,4,minecraft:basalt)
B(-6,0,5,minecraft:basalt)
B(-6,1,5,minecraft:basalt)
B(-6,2,5,minecraft:basalt)
B(-6,3,5,minecraft:soul_soil)
B(-6,4,5,minecraft:soul_soil)
B(-6,5,5,minecraft:basalt)
B(-6,0,6,minecraft:basalt)
B(-6,1,6,minecraft:basalt)
B(-6,2,6,minecraft:basalt)
B(-6,3,6,minecraft:soul_soil)
B(-6,4,6,minecraft:soul_soil)
B(-6,5,6,minecraft:basalt)
B(-6,0,7,minecraft:basalt)
B(-6,1,7,minecraft:basalt)
B(-6,2,7,minecraft:soul_soil)
B(-6,3,7,minecraft:soul_soil)
B(-6,4,7,minecraft:basalt)
B(-6,0,8,minecraft:soul_soil)
B(-6,1,8,minecraft:basalt)
B(-5,0,-7,minecraft:soul_soil)
B(-5,1,-7,minecraft:soul_soil)
B(-5,2,-7,minecraft:basalt)
B(-5,0,-6,minecraft:soul_soil)
B(-5,1,-6,minecraft:soul_soil)
B(-5,2,-6,minecraft:basalt)
B(-5,0,-5,minecraft:basalt)
B(-5,1,-5,minecraft:basalt)
B(-5,2,-5,minecraft:soul_soil)
B(-5,3,-5,minecraft:basalt)
B(-5,0,-4,minecraft:basalt)
B(-5,1,-4,minecraft:soul_soil)
B(-5,2,-4,minecraft:soul_soil)
B(-5,3,-4,minecraft:basalt)
B(-5,0,-3,minecraft:basalt)
B(-5,1,-3,minecraft:basalt)
B(-5,2,-3,minecraft:soul_soil)
B(-5,3,-3,minecraft:soul_soil)
B(-5,4,-3,minecraft:basalt)
B(-5,0,-2,minecraft:basalt)
B(-5,1,-2,minecraft:basalt)
B(-5,2,-2,minecraft:basalt)
B(-5,3,-2,minecraft:basalt)
B(-5,4,-2,minecraft:soul_soil)
B(-5,5,-2,minecraft:basalt)
B(-5,0,-1,minecraft:basalt)
B(-5,1,-1,minecraft:basalt)
B(-5,2,-1,minecraft:soul_soil)
B(-5,3,-1,minecraft:soul_soil)
B(-5,4,-1,minecraft:basalt)
B(-5,0,0,minecraft:basalt)
B(-5,1,0,minecraft:soul_soil)
B(-5,2,0,minecraft:soul_soil)
B(-5,3,0,minecraft:basalt)
B(-5,0,1,minecraft:soul_soil)
B(-5,1,1,minecraft:soul_soil)
B(-5,2,1,minecraft:basalt)
B(-5,0,2,minecraft:soul_soil)
B(-5,1,2,minecraft:basalt)
B(-5,0,3,minecraft:soul_soil)
B(-5,1,3,minecraft:soul_soil)
B(-5,2,3,minecraft:basalt)
B(-5,0,4,minecraft:soul_soil)
B(-5,1,4,minecraft:soul_soil)
B(-5,2,4,minecraft:basalt)
B(-5,0,5,minecraft:basalt)
B(-5,1,5,minecraft:soul_soil)
B(-5,2,5,minecraft:soul_soil)
B(-5,3,5,minecraft:basalt)
B(-5,0,6,minecraft:basalt)
B(-5,1,6,minecraft:basalt)
B(-5,2,6,minecraft:soul_soil)
B(-5,3,6,minecraft:soul_soil)
B(-5,4,6,minecraft:basalt)
B(-5,0,7,minecraft:soul_soil)
B(-5,1,7,minecraft:soul_soil)
B(-5,2,7,minecraft:basalt)
B(-5,0,8,minecraft:basalt)
B(-4,0,-7,minecraft:basalt)
B(-4,1,-7,minecraft:soul_soil)
B(-4,2,-7,minecraft:basalt)
B(-4,0,-6,minecraft:soul_soil)
B(-4,1,-6,minecraft:soul_soil)
B(-4,2,-6,minecraft:basalt)
B(-4,0,-5,minecraft:basalt)
B(-4,1,-5,minecraft:soul_soil)
B(-4,2,-5,minecraft:soul_soil)
B(-4,3,-5,minecraft:basalt)
B(-4,0,-4,minecraft:basalt)
B(-4,1,-4,minecraft:basalt)
B(-4,2,-4,minecraft:basalt)
B(-4,3,-4,minecraft:soul_soil)
B(-4,4,-4,minecraft:basalt)
B(-4,0,-3,minecraft:basalt)
B(-4,1,-3,minecraft:basalt)
B(-4,2,-3,minecraft:basalt)
B(-4,3,-3,minecraft:basalt)
B(-4,4,-3,minecraft:soul_soil)
B(-4,5,-3,minecraft:basalt)
B(-4,0,-2,minecraft:basalt)
B(-4,1,-2,minecraft:basalt)
B(-4,2,-2,minecraft:basalt)
B(-4,3,-2,minecraft:basalt)
B(-4,4,-2,minecraft:soul_soil)
B(-4,5,-2,minecraft:basalt)
B(-4,0,-1,minecraft:basalt)
B(-4,1,-1,minecraft:basalt)
B(-4,2,-1,minecraft:basalt)
B(-4,3,-1,minecraft:basalt)
B(-4,4,-1,minecraft:soul_soil)
B(-4,5,-1,minecraft:basalt)
B(-4,0,0,minecraft:basalt)
B(-4,1,0,minecraft:basalt)
B(-4,2,0,minecraft:soul_soil)
B(-4,3,0,minecraft:basalt)
B(-4,0,1,minecraft:basalt)
B(-4,1,1,minecraft:soul_soil)
B(-4,2,1,minecraft:basalt)
B(-4,0,2,minecraft:basalt)
B(-4,0,3,minecraft:soul_soil)
B(-4,1,3,minecraft:basalt)
B(-4,0,4,minecraft:soul_soil)
B(-4,1,4,minecraft:basalt)
B(-4,0,5,minecraft:soul_soil)
B(-4,1,5,minecraft:basalt)
B(-4,0,6,minecraft:soul_soil)
B(-4,1,6,minecraft:basalt)
B(-4,0,7,minecraft:basalt)
B(-3,0,-7,minecraft:soul_soil)
B(-3,1,-7,minecraft:basalt)
B(-3,0,-6,minecraft:soul_soil)
B(-3,1,-6,minecraft:basalt)
B(-3,0,-5,minecraft:basalt)
B(-3,1,-5,minecraft:basalt)
B(-3,2,-5,minecraft:soul_soil)
B(-3,3,-5,minecraft:basalt)
B(-3,0,-4,minecraft:basalt)
B(-3,1,-4,minecraft:basalt)
B(-3,2,-4,minecraft:basalt)
B(-3,3,-4,minecraft:soul_soil)
B(-3,4,-4,minecraft:basalt)
B(-3,0,-3,minecraft:basalt)
B(-3,1,-3,minecraft:basalt)
B(-3,2,-3,minecraft:basalt)
B(-3,3,-3,minecraft:basalt)
B(-3,4,-3,minecraft:soul_soil)
B(-3,5,-3,minecraft:basalt)
B(-3,0,-2,minecraft:basalt)
B(-3,1,-2,minecraft:basalt)
B(-3,2,-2,minecraft:basalt)
B(-3,3,-2,minecraft:soul_soil)
B(-3,4,-2,minecraft:soul_soil)
B(-3,5,-2,minecraft:basalt)
B(-3,0,-1,minecraft:basalt)
B(-3,1,-1,minecraft:basalt)
B(-3,2,-1,minecraft:basalt)
B(-3,3,-1,minecraft:soul_soil)
B(-3,4,-1,minecraft:soul_soil)
B(-3,5,-1,minecraft:basalt)
B(-3,0,0,minecraft:basalt)
B(-3,1,0,minecraft:soul_soil)
B(-3,2,0,minecraft:soul_soil)
B(-3,3,0,minecraft:basalt)
B(-3,0,1,minecraft:soul_soil)
B(-3,1,1,minecraft:basalt)
B(-3,0,2,minecraft:basalt)
B(-2,0,-7,minecraft:soul_soil)
B(-2,1,-7,minecraft:basalt)
B(-2,0,-6,minecraft:soul_soil)
B(-2,1,-6,minecraft:basalt)
B(-2,0,-5,minecraft:basalt)
B(-2,1,-5,minecraft:soul_soil)
B(-2,2,-5,minecraft:soul_soil)
B(-2,3,-5,minecraft:basalt)
B(-2,0,-4,minecraft:basalt)
B(-2,1,-4,minecraft:basalt)
B(-2,2,-4,minecraft:basalt)
B(-2,3,-4,minecraft:basalt)
B(-2,4,-4,minecraft:soul_soil)
B(-2,5,-4,minecraft:basalt)
B(-2,0,-3,minecraft:basalt)
B(-2,1,-3,minecraft:basalt)
B(-2,2,-3,minecraft:basalt)
B(-2,3,-3,minecraft:soul_soil)
B(-2,4,-3,minecraft:soul_soil)
B(-2,5,-3,minecraft:basalt)
B(-2,0,-2,minecraft:basalt)
B(-2,1,-2,minecraft:basalt)
B(-2,2,-2,minecraft:basalt)
B(-2,3,-2,minecraft:basalt)
B(-2,4,-2,minecraft:soul_soil)
B(-2,5,-2,minecraft:basalt)
B(-2,0,-1,minecraft:basalt)
B(-2,1,-1,minecraft:basalt)
B(-2,2,-1,minecraft:basalt)
B(-2,3,-1,minecraft:soul_soil)
B(-2,4,-1,minecraft:soul_soil)
B(-2,5,-1,minecraft:basalt)
B(-2,0,0,minecraft:basalt)
B(-2,1,0,minecraft:basalt)
B(-2,2,0,minecraft:basalt)
B(-2,3,0,minecraft:soul_soil)
B(-2,4,0,minecraft:basalt)
B(-2,0,1,minecraft:soul_soil)
B(-2,1,1,minecraft:basalt)
B(-1,0,-7,minecraft:soul_soil)
B(-1,1,-7,minecraft:basalt)
B(-1,0,-6,minecraft:soul_soil)
B(-1,1,-6,minecraft:basalt)
B(-1,0,-5,minecraft:soul_soil)
B(-1,1,-5,minecraft:soul_soil)
B(-1,2,-5,minecraft:basalt)
B(-1,0,-4,minecraft:basalt)
B(-1,1,-4,minecraft:soul_soil)
B(-1,2,-4,minecraft:soul_soil)
B(-1,3,-4,minecraft:basalt)
B(-1,0,-3,minecraft:basalt)
B(-1,1,-3,minecraft:basalt)
B(-1,2,-3,minecraft:soul_soil)
B(-1,3,-3,minecraft:soul_soil)
B(-1,4,-3,minecraft:basalt)
B(-1,0,-2,minecraft:basalt)
B(-1,1,-2,minecraft:basalt)
B(-1,2,-2,minecraft:basalt)
B(-1,3,-2,minecraft:soul_soil)
B(-1,4,-2,minecraft:soul_soil)
B(-1,5,-2,minecraft:basalt)
B(-1,0,-1,minecraft:basalt)
B(-1,1,-1,minecraft:basalt)
B(-1,2,-1,minecraft:soul_soil)
B(-1,3,-1,minecraft:soul_soil)
B(-1,4,-1,minecraft:basalt)
B(-1,0,0,minecraft:basalt)
B(-1,1,0,minecraft:soul_soil)
B(-1,2,0,minecraft:basalt)
B(-1,0,1,minecraft:basalt)
B(0,0,-7,minecraft:basalt)
B(0,0,-6,minecraft:basalt)
B(0,0,-5,minecraft:soul_soil)
B(0,1,-5,minecraft:basalt)
B(0,0,-4,minecraft:soul_soil)
B(0,1,-4,minecraft:soul_soil)
B(0,2,-4,minecraft:basalt)
B(0,0,-3,minecraft:soul_soil)
B(0,1,-3,minecraft:soul_soil)
B(0,2,-3,minecraft:basalt)
B(0,0,-2,minecraft:basalt)
B(0,1,-2,minecraft:soul_soil)
B(0,2,-2,minecraft:soul_soil)
B(0,3,-2,minecraft:basalt)
B(0,0,-1,minecraft:basalt)
B(0,1,-1,minecraft:soul_soil)
B(0,2,-1,minecraft:basalt)
B(0,0,0,minecraft:soul_soil)
B(0,1,0,minecraft:basalt)
B(1,0,-7,minecraft:basalt)
B(1,0,-6,minecraft:basalt)
B(1,0,-5,minecraft:basalt)
B(1,0,-4,minecraft:basalt)
B(1,0,-3,minecraft:basalt)
B(1,0,-2,minecraft:basalt)
B(1,0,-1,minecraft:basalt)
B(2,0,-7,minecraft:basalt)
B(2,0,-6,minecraft:basalt)
B(3,0,-6,minecraft:basalt)
B(7,0,1,minecraft:basalt)
B(7,0,2,minecraft:soul_soil)
B(7,1,2,minecraft:basalt)
B(7,0,3,minecraft:basalt)

#######################################################################
# +-----------------------------------------------------------------+ #
# |                             Branches                            | #
# +-----------------------------------------------------------------+ #
#######################################################################

Branch(16,0,0,true,BasaltWall2_C3_R5,NORTH,100.0,0)

#######################################################################
# +-----------------------------------------------------------------+ #
# |                             Entities                            | #
# +-----------------------------------------------------------------+ #
#######################################################################

