Author: Bo3 BulkEdit

Description: Converted Schematic - Modified by Bo3BulkEdit

Version: 3

SettingsMode: WriteDisable

IsOTGPlus: true
Tree: false
Frequency: 10
Rarity: 100
RotateRandomly: true
SpawnHeight: randomY
SpawnHeightOffset: 0
SpawnHeightVariance: 0
MaxBranchDepth: 10
ExcludedBiomes: All

MinHeight: 50
MaxHeight: 65

SourceBlocks: AIR
MaxPercentageOutsideSourceBlock: 100
OutsideSourceBlock: placeAnyway

ReplaceBelow: NETHER_WART_BLOCK
ReplaceWithBiomeBlocks: false
ReplaceWithGroundBlock: NETHER_WART_BLOCK
ReplaceWithSurfaceBlock: NETHER_WART_BLOCK
ReplaceWithStoneBlock: NETHER_WART_BLOCK
SmoothRadius: 30
SmoothHeightOffset: 0
SmoothStartTop: false
SmoothStartWood: false
SmoothingSurfaceBlock: NETHER_WART_BLOCK
SmoothingGroundBlock: NETHER_WART_BLOCK

B(0,750,0,AIR)
B(15,750,15,AIR)
B(11,0,0,minecraft:nether_wart_block)
B(12,0,0,minecraft:nether_wart_block)
B(13,0,0,minecraft:nether_wart_block)
B(14,0,0,minecraft:nether_wart_block)
B(15,0,0,minecraft:nether_wart_block)
B(10,0,1,minecraft:nether_wart_block)
B(11,0,1,minecraft:nether_wart_block)
B(12,0,1,minecraft:nether_wart_block)
B(13,0,1,minecraft:nether_wart_block)
B(14,0,1,minecraft:nether_wart_block)
B(15,0,1,minecraft:nether_wart_block)
B(9,0,2,minecraft:nether_wart_block)
B(10,0,2,minecraft:nether_wart_block)
B(11,0,2,minecraft:nether_wart_block)
B(12,0,2,minecraft:nether_wart_block)
B(13,0,2,minecraft:nether_wart_block)
B(14,0,2,minecraft:nether_wart_block)
B(15,0,2,minecraft:nether_wart_block)
B(9,0,3,minecraft:nether_wart_block)
B(10,0,3,minecraft:nether_wart_block)
B(11,0,3,minecraft:nether_wart_block)
B(12,0,3,minecraft:nether_wart_block)
B(13,0,3,minecraft:nether_wart_block)
B(14,0,3,minecraft:nether_wart_block)
B(15,0,3,minecraft:nether_wart_block)
B(9,0,4,minecraft:nether_wart_block)
B(10,0,4,minecraft:nether_wart_block)
B(11,0,4,minecraft:nether_wart_block)
B(12,0,4,minecraft:nether_wart_block)
B(13,0,4,minecraft:nether_wart_block)
B(14,0,4,minecraft:nether_wart_block)
B(15,0,4,minecraft:nether_wart_block)
B(10,0,5,minecraft:nether_wart_block)
B(11,0,5,minecraft:nether_wart_block)
B(12,0,5,minecraft:nether_wart_block)
B(13,0,5,minecraft:nether_wart_block)
B(14,0,5,minecraft:nether_wart_block)
B(15,0,5,minecraft:nether_wart_block)
B(11,0,6,minecraft:nether_wart_block)
B(12,0,6,minecraft:nether_wart_block)
B(13,0,6,minecraft:nether_wart_block)
B(14,0,6,minecraft:nether_wart_block)
B(15,0,6,minecraft:nether_wart_block)
B(12,0,7,minecraft:nether_wart_block)
B(13,0,7,minecraft:nether_wart_block)
B(14,0,7,minecraft:nether_wart_block)
B(15,0,7,minecraft:nether_wart_block)
B(13,0,8,minecraft:nether_wart_block)
B(14,0,8,minecraft:nether_wart_block)
B(15,0,8,minecraft:nether_wart_block)
B(13,0,9,minecraft:nether_wart_block)
B(14,0,9,minecraft:nether_wart_block)
B(15,0,9,minecraft:nether_wart_block)
B(12,0,10,minecraft:nether_wart_block)
B(13,0,10,minecraft:nether_wart_block)
B(14,0,10,minecraft:nether_wart_block)
B(15,0,10,minecraft:nether_wart_block)
B(11,0,11,minecraft:nether_wart_block)
B(12,0,11,minecraft:nether_wart_block)
B(13,0,11,minecraft:nether_wart_block)
B(14,0,11,minecraft:nether_wart_block)
B(15,0,11,minecraft:nether_wart_block)
B(11,0,12,minecraft:nether_wart_block)
B(12,0,12,minecraft:nether_wart_block)
B(13,0,12,minecraft:nether_wart_block)
B(14,0,12,minecraft:nether_wart_block)
B(15,0,12,minecraft:nether_wart_block)
B(11,0,13,minecraft:nether_wart_block)
B(12,0,13,minecraft:nether_wart_block)
B(13,0,13,minecraft:nether_wart_block)
B(14,0,13,minecraft:nether_wart_block)
B(15,0,13,minecraft:nether_wart_block)
B(11,0,14,minecraft:nether_wart_block)
B(12,0,14,minecraft:nether_wart_block)
B(13,0,14,minecraft:nether_wart_block)
B(14,0,14,minecraft:nether_wart_block)
B(15,0,14,minecraft:nether_wart_block)
B(11,0,15,minecraft:nether_wart_block)
B(12,0,15,minecraft:nether_wart_block)
B(13,0,15,minecraft:nether_wart_block)
B(14,0,15,minecraft:nether_wart_block)
B(15,0,15,minecraft:nether_wart_block)
B(14,1,0,minecraft:nether_wart_block)
B(15,1,0,minecraft:nether_wart_block)
B(12,1,1,minecraft:nether_wart_block)
B(13,1,1,minecraft:nether_wart_block)
B(14,1,1,minecraft:nether_wart_block)
B(15,1,1,minecraft:nether_wart_block)
B(12,1,2,minecraft:nether_wart_block)
B(13,1,2,minecraft:nether_wart_block)
B(14,1,2,minecraft:nether_wart_block)
B(15,1,2,minecraft:nether_wart_block)
B(11,1,3,minecraft:nether_wart_block)
B(12,1,3,minecraft:nether_wart_block)
B(13,1,3,minecraft:nether_wart_block)
B(14,1,3,minecraft:nether_wart_block)
B(15,1,3,minecraft:nether_wart_block)
B(12,1,4,minecraft:nether_wart_block)
B(13,1,4,minecraft:nether_wart_block)
B(14,1,4,minecraft:nether_wart_block)
B(15,1,4,minecraft:nether_wart_block)
B(14,1,5,minecraft:nether_wart_block)
B(15,1,5,minecraft:nether_wart_block)
B(14,1,6,minecraft:nether_wart_block)
B(15,1,6,minecraft:nether_wart_block)
B(13,1,7,minecraft:nether_wart_block)
B(14,1,7,minecraft:nether_wart_block)
B(15,1,7,minecraft:nether_wart_block)
B(13,1,8,minecraft:nether_wart_block)
B(14,1,8,minecraft:nether_wart_block)
B(15,1,8,minecraft:nether_wart_block)
B(13,1,9,minecraft:nether_wart_block)
B(14,1,9,minecraft:nether_wart_block)
B(15,1,9,minecraft:nether_wart_block)
B(12,1,10,minecraft:nether_wart_block)
B(13,1,10,minecraft:nether_wart_block)
B(14,1,10,minecraft:nether_wart_block)
B(15,1,10,minecraft:nether_wart_block)
B(12,1,11,minecraft:nether_wart_block)
B(13,1,11,minecraft:nether_wart_block)
B(14,1,11,minecraft:nether_wart_block)
B(15,1,11,minecraft:nether_wart_block)
B(12,1,12,minecraft:nether_wart_block)
B(13,1,12,minecraft:nether_wart_block)
B(14,1,12,minecraft:nether_wart_block)
B(15,1,12,minecraft:nether_wart_block)
B(11,1,13,minecraft:nether_wart_block)
B(12,1,13,minecraft:nether_wart_block)
B(13,1,13,minecraft:nether_wart_block)
B(14,1,13,minecraft:nether_wart_block)
B(15,1,13,minecraft:nether_wart_block)
B(11,1,14,minecraft:nether_wart_block)
B(12,1,14,minecraft:nether_wart_block)
B(13,1,14,minecraft:nether_wart_block)
B(14,1,14,minecraft:nether_wart_block)
B(15,1,14,minecraft:nether_wart_block)
B(11,1,15,minecraft:nether_wart_block)
B(12,1,15,minecraft:nether_wart_block)
B(13,1,15,minecraft:nether_wart_block)
B(14,1,15,minecraft:nether_wart_block)
B(15,1,15,minecraft:nether_wart_block)
B(15,2,5,minecraft:nether_wart_block)
B(14,2,6,minecraft:nether_wart_block)
B(15,2,6,minecraft:nether_wart_block)
B(13,2,7,minecraft:nether_wart_block)
B(14,2,7,minecraft:nether_wart_block)
B(15,2,7,minecraft:nether_wart_block)
B(13,2,8,minecraft:nether_wart_block)
B(14,2,8,minecraft:nether_wart_block)
B(15,2,8,minecraft:nether_wart_block)
B(13,2,9,minecraft:nether_wart_block)
B(14,2,9,minecraft:nether_wart_block)
B(15,2,9,minecraft:nether_wart_block)
B(12,2,10,minecraft:nether_wart_block)
B(13,2,10,minecraft:nether_wart_block)
B(14,2,10,minecraft:nether_wart_block)
B(15,2,10,minecraft:nether_wart_block)
B(13,2,11,minecraft:nether_wart_block)
B(14,2,11,minecraft:nether_wart_block)
B(15,2,11,minecraft:nether_wart_block)
B(13,2,12,minecraft:nether_wart_block)
B(14,2,12,minecraft:nether_wart_block)
B(15,2,12,minecraft:nether_wart_block)
B(12,2,13,minecraft:nether_wart_block)
B(13,2,13,minecraft:nether_wart_block)
B(14,2,13,minecraft:nether_wart_block)
B(15,2,13,minecraft:nether_wart_block)
B(12,2,14,minecraft:nether_wart_block)
B(13,2,14,minecraft:nether_wart_block)
B(14,2,14,minecraft:nether_wart_block)
B(15,2,14,minecraft:nether_wart_block)
B(12,2,15,minecraft:nether_wart_block)
B(13,2,15,minecraft:nether_wart_block)
B(14,2,15,minecraft:nether_wart_block)
B(15,2,15,minecraft:nether_wart_block)
B(14,3,7,minecraft:nether_wart_block)
B(15,3,7,minecraft:nether_wart_block)
B(13,3,8,minecraft:nether_wart_block)
B(14,3,8,minecraft:nether_wart_block)
B(15,3,8,minecraft:nether_wart_block)
B(13,3,9,minecraft:nether_wart_block)
B(14,3,9,minecraft:nether_wart_block)
B(15,3,9,minecraft:nether_wart_block)
B(13,3,10,minecraft:nether_wart_block)
B(14,3,10,minecraft:nether_wart_block)
B(15,3,10,minecraft:nether_wart_block)
B(13,3,11,minecraft:nether_wart_block)
B(14,3,11,minecraft:nether_wart_block)
B(15,3,11,minecraft:nether_wart_block)
B(13,3,12,minecraft:nether_wart_block)
B(14,3,12,minecraft:nether_wart_block)
B(15,3,12,minecraft:nether_wart_block)
B(13,3,13,minecraft:nether_wart_block)
B(14,3,13,minecraft:nether_wart_block)
B(15,3,13,minecraft:nether_wart_block)
B(13,3,14,minecraft:nether_wart_block)
B(14,3,14,minecraft:nether_wart_block)
B(15,3,14,minecraft:nether_wart_block)
B(13,3,15,minecraft:nether_wart_block)
B(14,3,15,minecraft:nether_wart_block)
B(15,3,15,minecraft:nether_wart_block)
B(15,4,7,minecraft:nether_wart_block)
B(15,4,8,minecraft:nether_wart_block)
B(15,4,9,minecraft:nether_wart_block)
B(14,4,10,minecraft:nether_wart_block)
B(15,4,10,minecraft:nether_wart_block)
B(14,4,11,minecraft:nether_wart_block)
B(15,4,11,minecraft:nether_wart_block)
B(14,4,12,minecraft:nether_wart_block)
B(15,4,12,minecraft:nether_wart_block)
B(14,4,13,minecraft:nether_wart_block)
B(15,4,13,minecraft:nether_wart_block)
B(14,4,14,minecraft:nether_wart_block)
B(15,4,14,minecraft:nether_wart_block)
B(14,4,15,minecraft:nether_wart_block)
B(15,4,15,minecraft:nether_wart_block)

