Author: Bo3 BulkEdit

Description: Converted Schematic - Modified by Bo3BulkEdit

Version: 3

SettingsMode: WriteDisable

IsOTGPlus: true
Tree: false
Frequency: 1
Rarity: 100
RotateRandomly: false
SpawnHeight: randomY
SpawnHeightOffset: 0
SpawnHeightVariance: 0
MaxBranchDepth: 10
ExcludedBiomes: All

MinHeight: 25
MaxHeight: 30

SourceBlocks: AIR
MaxPercentageOutsideSourceBlock: 100
OutsideSourceBlock: placeAnyway

RB(15,104,4,minecraft:crying_obsidian,10,minecraft:obsidian,100)
RB(14,105,3,minecraft:crying_obsidian,10,minecraft:obsidian,100)
RB(14,106,3,minecraft:crying_obsidian,10,minecraft:obsidian,100)
RB(14,107,3,minecraft:crying_obsidian,10,minecraft:obsidian,100)
RB(14,108,4,minecraft:crying_obsidian,10,minecraft:obsidian,100)
RB(15,108,6,minecraft:crying_obsidian,10,minecraft:obsidian,100)
B(14,109,5,minecraft:glowstone)
B(14,110,5,minecraft:chain[axis=y,waterlogged=false])
B(14,111,5,minecraft:glowstone)
RB(13,112,4,minecraft:crying_obsidian,10,minecraft:obsidian,100)
RB(14,112,6,minecraft:crying_obsidian,10,minecraft:obsidian,100)
RB(12,113,3,minecraft:crying_obsidian,10,minecraft:obsidian,100)
RB(14,113,7,minecraft:crying_obsidian,10,minecraft:obsidian,100)
RB(12,114,3,minecraft:crying_obsidian,10,minecraft:obsidian,100)
RB(14,114,7,minecraft:crying_obsidian,10,minecraft:obsidian,100)
RB(12,115,3,minecraft:crying_obsidian,10,minecraft:obsidian,100)
RB(14,115,7,minecraft:crying_obsidian,10,minecraft:obsidian,100)
RB(12,116,4,minecraft:crying_obsidian,10,minecraft:obsidian,100)
RB(13,116,6,minecraft:crying_obsidian,10,minecraft:obsidian,100)
B(12,117,5,minecraft:glowstone)
B(12,118,5,minecraft:chain[axis=y,waterlogged=false])
B(12,119,5,minecraft:glowstone)
RB(11,120,4,minecraft:crying_obsidian,10,minecraft:obsidian,100)
RB(12,120,6,minecraft:crying_obsidian,10,minecraft:obsidian,100)
RB(10,121,3,minecraft:crying_obsidian,10,minecraft:obsidian,100)
RB(12,121,7,minecraft:crying_obsidian,10,minecraft:obsidian,100)
RB(10,122,3,minecraft:crying_obsidian,10,minecraft:obsidian,100)
RB(12,122,7,minecraft:crying_obsidian,10,minecraft:obsidian,100)
RB(10,123,3,minecraft:crying_obsidian,10,minecraft:obsidian,100)
RB(12,123,7,minecraft:crying_obsidian,10,minecraft:obsidian,100)
RB(10,124,4,minecraft:crying_obsidian,10,minecraft:obsidian,100)
RB(11,124,6,minecraft:crying_obsidian,10,minecraft:obsidian,100)
B(10,125,5,minecraft:glowstone)
B(10,126,5,minecraft:chain[axis=y,waterlogged=false])
B(10,127,5,minecraft:glowstone)
RB(9,128,4,minecraft:crying_obsidian,10,minecraft:obsidian,100)
RB(10,128,6,minecraft:crying_obsidian,10,minecraft:obsidian,100)
RB(8,129,3,minecraft:crying_obsidian,10,minecraft:obsidian,100)
RB(10,129,7,minecraft:crying_obsidian,10,minecraft:obsidian,100)
RB(8,130,3,minecraft:crying_obsidian,10,minecraft:obsidian,100)
RB(10,130,7,minecraft:crying_obsidian,10,minecraft:obsidian,100)
RB(8,131,3,minecraft:crying_obsidian,10,minecraft:obsidian,100)
RB(10,131,7,minecraft:crying_obsidian,10,minecraft:obsidian,100)
RB(8,132,4,minecraft:crying_obsidian,10,minecraft:obsidian,100)
RB(9,132,6,minecraft:crying_obsidian,10,minecraft:obsidian,100)
B(8,133,5,minecraft:glowstone)
B(8,134,5,minecraft:chain[axis=y,waterlogged=false])
B(8,135,5,minecraft:glowstone)
RB(7,136,4,minecraft:crying_obsidian,10,minecraft:obsidian,100)
RB(8,136,6,minecraft:crying_obsidian,10,minecraft:obsidian,100)
RB(6,137,3,minecraft:crying_obsidian,10,minecraft:obsidian,100)
RB(8,137,7,minecraft:crying_obsidian,10,minecraft:obsidian,100)
RB(6,138,3,minecraft:crying_obsidian,10,minecraft:obsidian,100)
RB(8,138,7,minecraft:crying_obsidian,10,minecraft:obsidian,100)
RB(6,139,3,minecraft:crying_obsidian,10,minecraft:obsidian,100)
RB(8,139,7,minecraft:crying_obsidian,10,minecraft:obsidian,100)
RB(6,140,4,minecraft:crying_obsidian,10,minecraft:obsidian,100)
RB(7,140,6,minecraft:crying_obsidian,10,minecraft:obsidian,100)

