
#######################################################################
# +-----------------------------------------------------------------+ #
# |                            BO4 object                           | #
# +-----------------------------------------------------------------+ #
#######################################################################

Author: Unknown

Description: No description given

SettingsMode: WriteWithoutComments


#######################################################################
# +-----------------------------------------------------------------+ #
# |                          Main settings                          | #
# +-----------------------------------------------------------------+ #
#######################################################################

FixedRotation: 

Frequency: 0

SpawnHeight: highestBlock

UseCenterForHighestBlock: true

##############################
# Height Limits for the BO4. #
##############################

MinHeight: 0

MaxHeight: 255

InheritBO3: 

InheritBO3Rotation: NORTH

OverrideChildSettings: true

OverrideParentHeight: false

CanOverride: false

BranchFrequency: 0

BranchFrequencyGroup: 

MustBeBelowOther: false

MustBeInside: 

CannotBeInside: 

ReplacesBO3: 

MustBeInsideWorldBorders: false

CanSpawnOnWater: true

SpawnOnWaterOnly: false

SpawnUnderWater: false

SpawnAtWaterLevel: false

HeightOffset: 0

RemoveAir: true

ReplaceAbove: 

ReplaceBelow: 

ReplaceWithBiomeBlocks: true

ReplaceWithSurfaceBlock: GRASS

ReplaceWithGroundBlock: DIRT

ReplaceWithStoneBlock: STONE

SmoothRadius: 0

SmoothHeightOffset: 0

SmoothStartTop: false

SmoothStartWood: false

SmoothingSurfaceBlock: 

SmoothingGroundBlock: 

BO3Group: 

IsSpawnPoint: false

DoReplaceBlocks: true


#######################################################################
# +-----------------------------------------------------------------+ #
# |                              Blocks                             | #
# +-----------------------------------------------------------------+ #
#######################################################################

B(-8,42,-7,minecraft:soul_sand)
B(-8,43,-7,minecraft:soul_sand)
B(-8,44,-7,minecraft:soul_sand)
B(-8,45,-7,minecraft:soul_sand)
B(-8,46,-7,minecraft:soul_sand)
B(-8,47,-7,minecraft:soul_sand)
B(-8,48,-7,minecraft:soul_sand)
B(-8,49,-7,minecraft:soul_sand)
B(-8,50,-7,minecraft:soul_sand)
B(-8,42,-6,minecraft:soul_sand)
B(-8,43,-6,minecraft:soul_sand)
B(-8,44,-6,minecraft:soul_sand)
B(-8,45,-6,minecraft:soul_sand)
B(-8,46,-6,minecraft:soul_sand)
B(-8,47,-6,minecraft:soul_sand)
B(-8,48,-6,minecraft:soul_sand)
B(-8,49,-6,minecraft:soul_sand)
B(-8,50,-6,minecraft:soul_sand)
B(-8,39,-5,minecraft:soul_sand)
B(-8,40,-5,minecraft:soul_sand)
B(-8,41,-5,minecraft:soul_sand)
B(-8,42,-5,minecraft:soul_sand)
B(-8,43,-5,minecraft:soul_sand)
B(-8,44,-5,minecraft:soul_sand)
B(-8,45,-5,minecraft:soul_sand)
B(-8,46,-5,minecraft:soul_sand)
B(-8,47,-5,minecraft:soul_sand)
B(-8,48,-5,minecraft:soul_sand)
B(-8,49,-5,minecraft:soul_sand)
B(-8,50,-5,minecraft:soul_sand)
B(-8,39,-4,minecraft:soul_sand)
B(-8,40,-4,minecraft:soul_sand)
B(-8,41,-4,minecraft:soul_sand)
B(-8,42,-4,minecraft:soul_sand)
B(-8,43,-4,minecraft:soul_sand)
B(-8,44,-4,minecraft:soul_sand)
B(-8,45,-4,minecraft:soul_sand)
B(-8,46,-4,minecraft:soul_sand)
B(-8,47,-4,minecraft:soul_sand)
B(-8,48,-4,minecraft:soul_sand)
B(-8,49,-4,minecraft:soul_sand)
B(-8,50,-4,minecraft:soul_sand)
B(-8,39,-3,minecraft:soul_sand)
B(-8,40,-3,minecraft:soul_sand)
B(-8,41,-3,minecraft:soul_sand)
B(-8,42,-3,minecraft:soul_sand)
B(-8,43,-3,minecraft:soul_sand)
B(-8,44,-3,minecraft:soul_sand)
B(-8,45,-3,minecraft:soul_sand)
B(-8,46,-3,minecraft:soul_sand)
B(-8,47,-3,minecraft:soul_sand)
B(-8,48,-3,minecraft:soul_sand)
B(-8,49,-3,minecraft:soul_sand)
B(-8,50,-3,minecraft:soul_sand)
B(-8,38,-2,minecraft:soul_sand)
B(-8,39,-2,minecraft:soul_sand)
B(-8,40,-2,minecraft:soul_sand)
B(-8,41,-2,minecraft:soul_sand)
B(-8,42,-2,minecraft:soul_sand)
B(-8,43,-2,minecraft:soul_sand)
B(-8,44,-2,minecraft:soul_sand)
B(-8,45,-2,minecraft:soul_sand)
B(-8,46,-2,minecraft:soul_sand)
B(-8,47,-2,minecraft:soul_sand)
B(-8,48,-2,minecraft:soul_sand)
B(-8,49,-2,minecraft:soul_sand)
B(-8,50,-2,minecraft:soul_sand)
B(-8,37,-1,minecraft:soul_sand)
B(-8,38,-1,minecraft:soul_sand)
B(-8,39,-1,minecraft:soul_sand)
B(-8,40,-1,minecraft:soul_sand)
B(-8,41,-1,minecraft:soul_sand)
B(-8,42,-1,minecraft:soul_sand)
B(-8,43,-1,minecraft:soul_sand)
B(-8,44,-1,minecraft:soul_sand)
B(-8,45,-1,minecraft:soul_sand)
B(-8,46,-1,minecraft:soul_sand)
B(-8,47,-1,minecraft:soul_sand)
B(-8,48,-1,minecraft:soul_sand)
B(-8,49,-1,minecraft:soul_sand)
B(-8,50,-1,minecraft:soul_sand)
B(-8,36,0,minecraft:soul_sand)
B(-8,37,0,minecraft:soul_sand)
B(-8,38,0,minecraft:soul_sand)
B(-8,39,0,minecraft:soul_sand)
B(-8,40,0,minecraft:soul_sand)
B(-8,41,0,minecraft:soul_sand)
B(-8,42,0,minecraft:soul_sand)
B(-8,43,0,minecraft:soul_sand)
B(-8,44,0,minecraft:soul_sand)
B(-8,45,0,minecraft:soul_sand)
B(-8,46,0,minecraft:soul_sand)
B(-8,47,0,minecraft:soul_sand)
B(-8,48,0,minecraft:soul_sand)
B(-8,49,0,minecraft:soul_sand)
B(-8,50,0,minecraft:soul_sand)
B(-8,35,1,minecraft:soul_sand)
B(-8,36,1,minecraft:soul_sand)
B(-8,37,1,minecraft:soul_sand)
B(-8,38,1,minecraft:soul_sand)
B(-8,39,1,minecraft:soul_sand)
B(-8,40,1,minecraft:soul_sand)
B(-8,41,1,minecraft:soul_sand)
B(-8,42,1,minecraft:soul_sand)
B(-8,43,1,minecraft:soul_sand)
B(-8,44,1,minecraft:soul_sand)
B(-8,45,1,minecraft:soul_sand)
B(-8,46,1,minecraft:soul_sand)
B(-8,47,1,minecraft:soul_sand)
B(-8,48,1,minecraft:soul_sand)
B(-8,49,1,minecraft:soul_sand)
B(-8,50,1,minecraft:soul_sand)
B(-8,34,2,minecraft:soul_sand)
B(-8,35,2,minecraft:soul_sand)
B(-8,36,2,minecraft:soul_sand)
B(-8,37,2,minecraft:soul_sand)
B(-8,38,2,minecraft:soul_sand)
B(-8,39,2,minecraft:soul_sand)
B(-8,40,2,minecraft:soul_sand)
B(-8,41,2,minecraft:soul_sand)
B(-8,42,2,minecraft:soul_sand)
B(-8,43,2,minecraft:soul_sand)
B(-8,44,2,minecraft:soul_sand)
B(-8,45,2,minecraft:soul_sand)
B(-8,46,2,minecraft:soul_sand)
B(-8,47,2,minecraft:soul_sand)
B(-8,48,2,minecraft:soul_sand)
B(-8,49,2,minecraft:soul_sand)
B(-8,50,2,minecraft:soul_sand)
B(-8,33,3,minecraft:soul_sand)
B(-8,34,3,minecraft:soul_sand)
B(-8,35,3,minecraft:soul_sand)
B(-8,36,3,minecraft:soul_sand)
B(-8,37,3,minecraft:soul_sand)
B(-8,38,3,minecraft:soul_sand)
B(-8,39,3,minecraft:soul_sand)
B(-8,40,3,minecraft:soul_sand)
B(-8,41,3,minecraft:soul_sand)
B(-8,42,3,minecraft:soul_sand)
B(-8,43,3,minecraft:soul_sand)
B(-8,44,3,minecraft:soul_sand)
B(-8,45,3,minecraft:soul_sand)
B(-8,46,3,minecraft:soul_sand)
B(-8,47,3,minecraft:soul_sand)
B(-8,48,3,minecraft:soul_sand)
B(-8,49,3,minecraft:soul_sand)
B(-8,50,3,minecraft:soul_sand)
B(-8,33,4,minecraft:soul_sand)
B(-8,34,4,minecraft:soul_sand)
B(-8,35,4,minecraft:soul_sand)
B(-8,36,4,minecraft:soul_sand)
B(-8,37,4,minecraft:soul_sand)
B(-8,38,4,minecraft:soul_sand)
B(-8,39,4,minecraft:soul_sand)
B(-8,40,4,minecraft:soul_sand)
B(-8,41,4,minecraft:soul_sand)
B(-8,42,4,minecraft:soul_sand)
B(-8,43,4,minecraft:soul_sand)
B(-8,44,4,minecraft:soul_sand)
B(-8,45,4,minecraft:soul_sand)
B(-8,46,4,minecraft:soul_sand)
B(-8,47,4,minecraft:soul_sand)
B(-8,48,4,minecraft:soul_sand)
B(-8,49,4,minecraft:soul_sand)
B(-8,50,4,minecraft:soul_sand)
B(-8,33,5,minecraft:soul_sand)
B(-8,34,5,minecraft:soul_sand)
B(-8,35,5,minecraft:soul_sand)
B(-8,36,5,minecraft:soul_sand)
B(-8,37,5,minecraft:soul_sand)
B(-8,38,5,minecraft:soul_sand)
B(-8,39,5,minecraft:soul_sand)
B(-8,40,5,minecraft:soul_sand)
B(-8,41,5,minecraft:soul_sand)
B(-8,42,5,minecraft:soul_sand)
B(-8,43,5,minecraft:soul_sand)
B(-8,44,5,minecraft:soul_sand)
B(-8,45,5,minecraft:soul_sand)
B(-8,46,5,minecraft:soul_sand)
B(-8,47,5,minecraft:soul_sand)
B(-8,48,5,minecraft:soul_sand)
B(-8,49,5,minecraft:soul_sand)
B(-8,50,5,minecraft:soul_sand)
B(-8,34,6,minecraft:soul_sand)
B(-8,35,6,minecraft:soul_sand)
B(-8,36,6,minecraft:soul_sand)
B(-8,37,6,minecraft:soul_sand)
B(-8,38,6,minecraft:soul_sand)
B(-8,39,6,minecraft:soul_sand)
B(-8,40,6,minecraft:soul_sand)
B(-8,41,6,minecraft:soul_sand)
B(-8,42,6,minecraft:soul_sand)
B(-8,43,6,minecraft:soul_sand)
B(-8,44,6,minecraft:soul_sand)
B(-8,45,6,minecraft:soul_sand)
B(-8,46,6,minecraft:soul_sand)
B(-8,47,6,minecraft:soul_sand)
B(-8,48,6,minecraft:soul_sand)
B(-8,49,6,minecraft:soul_sand)
B(-8,50,6,minecraft:soul_sand)
B(-8,35,7,minecraft:soul_sand)
B(-8,36,7,minecraft:soul_sand)
B(-8,37,7,minecraft:soul_sand)
B(-8,38,7,minecraft:soul_sand)
B(-8,39,7,minecraft:soul_sand)
B(-8,40,7,minecraft:soul_sand)
B(-8,41,7,minecraft:soul_sand)
B(-8,42,7,minecraft:soul_sand)
B(-8,43,7,minecraft:soul_sand)
B(-8,44,7,minecraft:soul_sand)
B(-8,45,7,minecraft:soul_sand)
B(-8,46,7,minecraft:soul_sand)
B(-8,47,7,minecraft:soul_sand)
B(-8,48,7,minecraft:soul_sand)
B(-8,49,7,minecraft:soul_sand)
B(-8,50,7,minecraft:soul_sand)
B(-8,36,8,minecraft:soul_sand)
B(-8,37,8,minecraft:soul_sand)
B(-8,38,8,minecraft:soul_sand)
B(-8,39,8,minecraft:soul_sand)
B(-8,40,8,minecraft:soul_sand)
B(-8,41,8,minecraft:soul_sand)
B(-8,42,8,minecraft:soul_sand)
B(-8,43,8,minecraft:soul_sand)
B(-8,44,8,minecraft:soul_sand)
B(-8,45,8,minecraft:soul_sand)
B(-8,46,8,minecraft:soul_sand)
B(-8,47,8,minecraft:soul_sand)
B(-8,48,8,minecraft:soul_sand)
B(-8,49,8,minecraft:soul_sand)
B(-8,50,8,minecraft:soul_sand)
B(-7,43,-7,minecraft:soul_sand)
B(-7,44,-7,minecraft:soul_sand)
B(-7,45,-7,minecraft:soul_sand)
B(-7,46,-7,minecraft:soul_sand)
B(-7,47,-7,minecraft:soul_sand)
B(-7,48,-7,minecraft:soul_sand)
B(-7,49,-7,minecraft:soul_sand)
B(-7,50,-7,minecraft:soul_sand)
B(-7,43,-6,minecraft:soul_sand)
B(-7,44,-6,minecraft:soul_sand)
B(-7,45,-6,minecraft:soul_sand)
B(-7,46,-6,minecraft:soul_sand)
B(-7,47,-6,minecraft:soul_sand)
B(-7,48,-6,minecraft:soul_sand)
B(-7,49,-6,minecraft:soul_sand)
B(-7,50,-6,minecraft:soul_sand)
B(-7,42,-5,minecraft:soul_sand)
B(-7,43,-5,minecraft:soul_sand)
B(-7,44,-5,minecraft:soul_sand)
B(-7,45,-5,minecraft:soul_sand)
B(-7,46,-5,minecraft:soul_sand)
B(-7,47,-5,minecraft:soul_sand)
B(-7,48,-5,minecraft:soul_sand)
B(-7,49,-5,minecraft:soul_sand)
B(-7,50,-5,minecraft:soul_sand)
B(-7,40,-4,minecraft:soul_sand)
B(-7,41,-4,minecraft:soul_sand)
B(-7,42,-4,minecraft:soul_sand)
B(-7,43,-4,minecraft:soul_sand)
B(-7,44,-4,minecraft:soul_sand)
B(-7,45,-4,minecraft:soul_sand)
B(-7,46,-4,minecraft:soul_sand)
B(-7,47,-4,minecraft:soul_sand)
B(-7,48,-4,minecraft:soul_sand)
B(-7,49,-4,minecraft:soul_sand)
B(-7,50,-4,minecraft:soul_sand)
B(-7,39,-3,minecraft:soul_sand)
B(-7,40,-3,minecraft:soul_sand)
B(-7,41,-3,minecraft:soul_sand)
B(-7,42,-3,minecraft:soul_sand)
B(-7,43,-3,minecraft:soul_sand)
B(-7,44,-3,minecraft:soul_sand)
B(-7,45,-3,minecraft:soul_sand)
B(-7,46,-3,minecraft:soul_sand)
B(-7,47,-3,minecraft:soul_sand)
B(-7,48,-3,minecraft:soul_sand)
B(-7,49,-3,minecraft:soul_sand)
B(-7,50,-3,minecraft:soul_sand)
B(-7,39,-2,minecraft:soul_sand)
B(-7,40,-2,minecraft:soul_sand)
B(-7,41,-2,minecraft:soul_sand)
B(-7,42,-2,minecraft:soul_sand)
B(-7,43,-2,minecraft:soul_sand)
B(-7,44,-2,minecraft:soul_sand)
B(-7,45,-2,minecraft:soul_sand)
B(-7,46,-2,minecraft:soul_sand)
B(-7,47,-2,minecraft:soul_sand)
B(-7,48,-2,minecraft:soul_sand)
B(-7,49,-2,minecraft:soul_sand)
B(-7,50,-2,minecraft:soul_sand)
B(-7,38,-1,minecraft:soul_sand)
B(-7,39,-1,minecraft:soul_sand)
B(-7,40,-1,minecraft:soul_sand)
B(-7,41,-1,minecraft:soul_sand)
B(-7,42,-1,minecraft:soul_sand)
B(-7,43,-1,minecraft:soul_sand)
B(-7,44,-1,minecraft:soul_sand)
B(-7,45,-1,minecraft:soul_sand)
B(-7,46,-1,minecraft:soul_sand)
B(-7,47,-1,minecraft:soul_sand)
B(-7,48,-1,minecraft:soul_sand)
B(-7,49,-1,minecraft:soul_sand)
B(-7,50,-1,minecraft:soul_sand)
B(-7,37,0,minecraft:soul_sand)
B(-7,38,0,minecraft:soul_sand)
B(-7,39,0,minecraft:soul_sand)
B(-7,40,0,minecraft:soul_sand)
B(-7,41,0,minecraft:soul_sand)
B(-7,42,0,minecraft:soul_sand)
B(-7,43,0,minecraft:soul_sand)
B(-7,44,0,minecraft:soul_sand)
B(-7,45,0,minecraft:soul_sand)
B(-7,46,0,minecraft:soul_sand)
B(-7,47,0,minecraft:soul_sand)
B(-7,48,0,minecraft:soul_sand)
B(-7,49,0,minecraft:soul_sand)
B(-7,50,0,minecraft:soul_sand)
B(-7,36,1,minecraft:soul_sand)
B(-7,37,1,minecraft:soul_sand)
B(-7,38,1,minecraft:soul_sand)
B(-7,39,1,minecraft:soul_sand)
B(-7,40,1,minecraft:soul_sand)
B(-7,41,1,minecraft:soul_sand)
B(-7,42,1,minecraft:soul_sand)
B(-7,43,1,minecraft:soul_sand)
B(-7,44,1,minecraft:soul_sand)
B(-7,45,1,minecraft:soul_sand)
B(-7,46,1,minecraft:soul_sand)
B(-7,47,1,minecraft:soul_sand)
B(-7,48,1,minecraft:soul_sand)
B(-7,49,1,minecraft:soul_sand)
B(-7,50,1,minecraft:soul_sand)
B(-7,35,2,minecraft:soul_sand)
B(-7,36,2,minecraft:soul_sand)
B(-7,37,2,minecraft:soul_sand)
B(-7,38,2,minecraft:soul_sand)
B(-7,39,2,minecraft:soul_sand)
B(-7,40,2,minecraft:soul_sand)
B(-7,41,2,minecraft:soul_sand)
B(-7,42,2,minecraft:soul_sand)
B(-7,43,2,minecraft:soul_sand)
B(-7,44,2,minecraft:soul_sand)
B(-7,45,2,minecraft:soul_sand)
B(-7,46,2,minecraft:soul_sand)
B(-7,47,2,minecraft:soul_sand)
B(-7,48,2,minecraft:soul_sand)
B(-7,49,2,minecraft:soul_sand)
B(-7,50,2,minecraft:soul_sand)
B(-7,35,3,minecraft:soul_sand)
B(-7,36,3,minecraft:soul_sand)
B(-7,37,3,minecraft:soul_sand)
B(-7,38,3,minecraft:soul_sand)
B(-7,39,3,minecraft:soul_sand)
B(-7,40,3,minecraft:soul_sand)
B(-7,41,3,minecraft:soul_sand)
B(-7,42,3,minecraft:soul_sand)
B(-7,43,3,minecraft:soul_sand)
B(-7,44,3,minecraft:soul_sand)
B(-7,45,3,minecraft:soul_sand)
B(-7,46,3,minecraft:soul_sand)
B(-7,47,3,minecraft:soul_sand)
B(-7,48,3,minecraft:soul_sand)
B(-7,49,3,minecraft:soul_sand)
B(-7,50,3,minecraft:soul_sand)
B(-7,35,4,minecraft:soul_sand)
B(-7,36,4,minecraft:soul_sand)
B(-7,37,4,minecraft:soul_sand)
B(-7,38,4,minecraft:soul_sand)
B(-7,39,4,minecraft:soul_sand)
B(-7,40,4,minecraft:soul_sand)
B(-7,41,4,minecraft:soul_sand)
B(-7,42,4,minecraft:soul_sand)
B(-7,43,4,minecraft:soul_sand)
B(-7,44,4,minecraft:soul_sand)
B(-7,45,4,minecraft:soul_sand)
B(-7,46,4,minecraft:soul_sand)
B(-7,47,4,minecraft:soul_sand)
B(-7,48,4,minecraft:soul_sand)
B(-7,49,4,minecraft:soul_sand)
B(-7,50,4,minecraft:soul_sand)
B(-7,35,5,minecraft:soul_sand)
B(-7,36,5,minecraft:soul_sand)
B(-7,37,5,minecraft:soul_sand)
B(-7,38,5,minecraft:soul_sand)
B(-7,39,5,minecraft:soul_sand)
B(-7,40,5,minecraft:soul_sand)
B(-7,41,5,minecraft:soul_sand)
B(-7,42,5,minecraft:soul_sand)
B(-7,43,5,minecraft:soul_sand)
B(-7,44,5,minecraft:soul_sand)
B(-7,45,5,minecraft:soul_sand)
B(-7,46,5,minecraft:soul_sand)
B(-7,47,5,minecraft:soul_sand)
B(-7,48,5,minecraft:soul_sand)
B(-7,49,5,minecraft:soul_sand)
B(-7,50,5,minecraft:soul_sand)
B(-7,35,6,minecraft:soul_sand)
B(-7,36,6,minecraft:soul_sand)
B(-7,37,6,minecraft:soul_sand)
B(-7,38,6,minecraft:soul_sand)
B(-7,39,6,minecraft:soul_sand)
B(-7,40,6,minecraft:soul_sand)
B(-7,41,6,minecraft:soul_sand)
B(-7,42,6,minecraft:soul_sand)
B(-7,43,6,minecraft:soul_sand)
B(-7,44,6,minecraft:soul_sand)
B(-7,45,6,minecraft:soul_sand)
B(-7,46,6,minecraft:soul_sand)
B(-7,47,6,minecraft:soul_sand)
B(-7,48,6,minecraft:soul_sand)
B(-7,49,6,minecraft:soul_sand)
B(-7,50,6,minecraft:soul_sand)
B(-7,35,7,minecraft:soul_sand)
B(-7,36,7,minecraft:soul_sand)
B(-7,37,7,minecraft:soul_sand)
B(-7,38,7,minecraft:soul_sand)
B(-7,39,7,minecraft:soul_sand)
B(-7,40,7,minecraft:soul_sand)
B(-7,41,7,minecraft:soul_sand)
B(-7,42,7,minecraft:soul_sand)
B(-7,43,7,minecraft:soul_sand)
B(-7,44,7,minecraft:soul_sand)
B(-7,45,7,minecraft:soul_sand)
B(-7,46,7,minecraft:soul_sand)
B(-7,47,7,minecraft:soul_sand)
B(-7,48,7,minecraft:soul_sand)
B(-7,49,7,minecraft:soul_sand)
B(-7,50,7,minecraft:soul_sand)
B(-7,36,8,minecraft:soul_sand)
B(-7,37,8,minecraft:soul_sand)
B(-7,38,8,minecraft:soul_sand)
B(-7,39,8,minecraft:soul_sand)
B(-7,40,8,minecraft:soul_sand)
B(-7,41,8,minecraft:soul_sand)
B(-7,42,8,minecraft:soul_sand)
B(-7,43,8,minecraft:soul_sand)
B(-7,44,8,minecraft:soul_sand)
B(-7,45,8,minecraft:soul_sand)
B(-7,46,8,minecraft:soul_sand)
B(-7,47,8,minecraft:soul_sand)
B(-7,48,8,minecraft:soul_sand)
B(-7,49,8,minecraft:soul_sand)
B(-7,50,8,minecraft:soul_sand)
B(-6,44,-7,minecraft:soul_sand)
B(-6,45,-7,minecraft:soul_sand)
B(-6,46,-7,minecraft:soul_sand)
B(-6,47,-7,minecraft:soul_sand)
B(-6,48,-7,minecraft:soul_sand)
B(-6,49,-7,minecraft:soul_sand)
B(-6,50,-7,minecraft:soul_sand)
B(-6,43,-6,minecraft:soul_sand)
B(-6,44,-6,minecraft:soul_sand)
B(-6,45,-6,minecraft:soul_sand)
B(-6,46,-6,minecraft:soul_sand)
B(-6,47,-6,minecraft:soul_sand)
B(-6,48,-6,minecraft:soul_sand)
B(-6,49,-6,minecraft:soul_sand)
B(-6,50,-6,minecraft:soul_sand)
B(-6,43,-5,minecraft:soul_sand)
B(-6,44,-5,minecraft:soul_sand)
B(-6,45,-5,minecraft:soul_sand)
B(-6,46,-5,minecraft:soul_sand)
B(-6,47,-5,minecraft:soul_sand)
B(-6,48,-5,minecraft:soul_sand)
B(-6,49,-5,minecraft:soul_sand)
B(-6,50,-5,minecraft:soul_sand)
B(-6,43,-4,minecraft:soul_sand)
B(-6,44,-4,minecraft:soul_sand)
B(-6,45,-4,minecraft:soul_sand)
B(-6,46,-4,minecraft:soul_sand)
B(-6,47,-4,minecraft:soul_sand)
B(-6,48,-4,minecraft:soul_sand)
B(-6,49,-4,minecraft:soul_sand)
B(-6,50,-4,minecraft:soul_sand)
B(-6,42,-3,minecraft:soul_sand)
B(-6,43,-3,minecraft:soul_sand)
B(-6,44,-3,minecraft:soul_sand)
B(-6,45,-3,minecraft:soul_sand)
B(-6,46,-3,minecraft:soul_sand)
B(-6,47,-3,minecraft:soul_sand)
B(-6,48,-3,minecraft:soul_sand)
B(-6,49,-3,minecraft:soul_sand)
B(-6,50,-3,minecraft:soul_sand)
B(-6,40,-2,minecraft:soul_sand)
B(-6,41,-2,minecraft:soul_sand)
B(-6,42,-2,minecraft:soul_sand)
B(-6,43,-2,minecraft:soul_sand)
B(-6,44,-2,minecraft:soul_sand)
B(-6,45,-2,minecraft:soul_sand)
B(-6,46,-2,minecraft:soul_sand)
B(-6,47,-2,minecraft:soul_sand)
B(-6,48,-2,minecraft:soul_sand)
B(-6,49,-2,minecraft:soul_sand)
B(-6,50,-2,minecraft:soul_sand)
B(-6,39,-1,minecraft:soul_sand)
B(-6,40,-1,minecraft:soul_sand)
B(-6,41,-1,minecraft:soul_sand)
B(-6,42,-1,minecraft:soul_sand)
B(-6,43,-1,minecraft:soul_sand)
B(-6,44,-1,minecraft:soul_sand)
B(-6,45,-1,minecraft:soul_sand)
B(-6,46,-1,minecraft:soul_sand)
B(-6,47,-1,minecraft:soul_sand)
B(-6,48,-1,minecraft:soul_sand)
B(-6,49,-1,minecraft:soul_sand)
B(-6,50,-1,minecraft:soul_sand)
B(-6,38,0,minecraft:soul_sand)
B(-6,39,0,minecraft:soul_sand)
B(-6,40,0,minecraft:soul_sand)
B(-6,41,0,minecraft:soul_sand)
B(-6,42,0,minecraft:soul_sand)
B(-6,43,0,minecraft:soul_sand)
B(-6,44,0,minecraft:soul_sand)
B(-6,45,0,minecraft:soul_sand)
B(-6,46,0,minecraft:soul_sand)
B(-6,47,0,minecraft:soul_sand)
B(-6,48,0,minecraft:soul_sand)
B(-6,49,0,minecraft:soul_sand)
B(-6,50,0,minecraft:soul_sand)
B(-6,37,1,minecraft:soul_sand)
B(-6,38,1,minecraft:soul_sand)
B(-6,39,1,minecraft:soul_sand)
B(-6,40,1,minecraft:soul_sand)
B(-6,41,1,minecraft:soul_sand)
B(-6,42,1,minecraft:soul_sand)
B(-6,43,1,minecraft:soul_sand)
B(-6,44,1,minecraft:soul_sand)
B(-6,45,1,minecraft:soul_sand)
B(-6,46,1,minecraft:soul_sand)
B(-6,47,1,minecraft:soul_sand)
B(-6,48,1,minecraft:soul_sand)
B(-6,49,1,minecraft:soul_sand)
B(-6,50,1,minecraft:soul_sand)
B(-6,36,2,minecraft:soul_sand)
B(-6,37,2,minecraft:soul_sand)
B(-6,38,2,minecraft:soul_sand)
B(-6,39,2,minecraft:soul_sand)
B(-6,40,2,minecraft:soul_sand)
B(-6,41,2,minecraft:soul_sand)
B(-6,42,2,minecraft:soul_sand)
B(-6,43,2,minecraft:soul_sand)
B(-6,44,2,minecraft:soul_sand)
B(-6,45,2,minecraft:soul_sand)
B(-6,46,2,minecraft:soul_sand)
B(-6,47,2,minecraft:soul_sand)
B(-6,48,2,minecraft:soul_sand)
B(-6,49,2,minecraft:soul_sand)
B(-6,50,2,minecraft:soul_sand)
B(-6,36,3,minecraft:soul_sand)
B(-6,37,3,minecraft:soul_sand)
B(-6,38,3,minecraft:soul_sand)
B(-6,39,3,minecraft:soul_sand)
B(-6,40,3,minecraft:soul_sand)
B(-6,41,3,minecraft:soul_sand)
B(-6,42,3,minecraft:soul_sand)
B(-6,43,3,minecraft:soul_sand)
B(-6,44,3,minecraft:soul_sand)
B(-6,45,3,minecraft:soul_sand)
B(-6,46,3,minecraft:soul_sand)
B(-6,47,3,minecraft:soul_sand)
B(-6,48,3,minecraft:soul_sand)
B(-6,49,3,minecraft:soul_sand)
B(-6,50,3,minecraft:soul_sand)
B(-6,36,4,minecraft:soul_sand)
B(-6,37,4,minecraft:soul_sand)
B(-6,38,4,minecraft:soul_sand)
B(-6,39,4,minecraft:soul_sand)
B(-6,40,4,minecraft:soul_sand)
B(-6,41,4,minecraft:soul_sand)
B(-6,42,4,minecraft:soul_sand)
B(-6,43,4,minecraft:soul_sand)
B(-6,44,4,minecraft:soul_sand)
B(-6,45,4,minecraft:soul_sand)
B(-6,46,4,minecraft:soul_sand)
B(-6,47,4,minecraft:soul_sand)
B(-6,48,4,minecraft:soul_sand)
B(-6,49,4,minecraft:soul_sand)
B(-6,50,4,minecraft:soul_sand)
B(-6,36,5,minecraft:soul_sand)
B(-6,37,5,minecraft:soul_sand)
B(-6,38,5,minecraft:soul_sand)
B(-6,39,5,minecraft:soul_sand)
B(-6,40,5,minecraft:soul_sand)
B(-6,41,5,minecraft:soul_sand)
B(-6,42,5,minecraft:soul_sand)
B(-6,43,5,minecraft:soul_sand)
B(-6,44,5,minecraft:soul_sand)
B(-6,45,5,minecraft:soul_sand)
B(-6,46,5,minecraft:soul_sand)
B(-6,47,5,minecraft:soul_sand)
B(-6,48,5,minecraft:soul_sand)
B(-6,49,5,minecraft:soul_sand)
B(-6,50,5,minecraft:soul_sand)
B(-6,38,6,minecraft:soul_sand)
B(-6,39,6,minecraft:soul_sand)
B(-6,40,6,minecraft:soul_sand)
B(-6,41,6,minecraft:soul_sand)
B(-6,42,6,minecraft:soul_sand)
B(-6,43,6,minecraft:soul_sand)
B(-6,44,6,minecraft:soul_sand)
B(-6,45,6,minecraft:soul_sand)
B(-6,46,6,minecraft:soul_sand)
B(-6,47,6,minecraft:soul_sand)
B(-6,48,6,minecraft:soul_sand)
B(-6,49,6,minecraft:soul_sand)
B(-6,50,6,minecraft:soul_sand)
B(-6,38,7,minecraft:soul_sand)
B(-6,39,7,minecraft:soul_sand)
B(-6,40,7,minecraft:soul_sand)
B(-6,41,7,minecraft:soul_sand)
B(-6,42,7,minecraft:soul_sand)
B(-6,43,7,minecraft:soul_sand)
B(-6,44,7,minecraft:soul_sand)
B(-6,45,7,minecraft:soul_sand)
B(-6,46,7,minecraft:soul_sand)
B(-6,47,7,minecraft:soul_sand)
B(-6,48,7,minecraft:soul_sand)
B(-6,49,7,minecraft:soul_sand)
B(-6,50,7,minecraft:soul_sand)
B(-6,39,8,minecraft:soul_sand)
B(-6,40,8,minecraft:soul_sand)
B(-6,41,8,minecraft:soul_sand)
B(-6,42,8,minecraft:soul_sand)
B(-6,43,8,minecraft:soul_sand)
B(-6,44,8,minecraft:soul_sand)
B(-6,45,8,minecraft:soul_sand)
B(-6,46,8,minecraft:soul_sand)
B(-6,47,8,minecraft:soul_sand)
B(-6,48,8,minecraft:soul_sand)
B(-6,49,8,minecraft:soul_sand)
B(-6,50,8,minecraft:soul_sand)
B(-5,44,-7,minecraft:soul_sand)
B(-5,45,-7,minecraft:soul_sand)
B(-5,46,-7,minecraft:soul_sand)
B(-5,47,-7,minecraft:soul_sand)
B(-5,48,-7,minecraft:soul_sand)
B(-5,49,-7,minecraft:soul_sand)
B(-5,50,-7,minecraft:soul_sand)
B(-5,44,-6,minecraft:soul_sand)
B(-5,45,-6,minecraft:soul_sand)
B(-5,46,-6,minecraft:soul_sand)
B(-5,47,-6,minecraft:soul_sand)
B(-5,48,-6,minecraft:soul_sand)
B(-5,49,-6,minecraft:soul_sand)
B(-5,50,-6,minecraft:soul_sand)
B(-5,44,-5,minecraft:soul_sand)
B(-5,45,-5,minecraft:soul_sand)
B(-5,46,-5,minecraft:soul_sand)
B(-5,47,-5,minecraft:soul_sand)
B(-5,48,-5,minecraft:soul_sand)
B(-5,49,-5,minecraft:soul_sand)
B(-5,50,-5,minecraft:soul_sand)
B(-5,44,-4,minecraft:soul_sand)
B(-5,45,-4,minecraft:soul_sand)
B(-5,46,-4,minecraft:soul_sand)
B(-5,47,-4,minecraft:soul_sand)
B(-5,48,-4,minecraft:soul_sand)
B(-5,49,-4,minecraft:soul_sand)
B(-5,50,-4,minecraft:soul_sand)
B(-5,43,-3,minecraft:soul_sand)
B(-5,44,-3,minecraft:soul_sand)
B(-5,45,-3,minecraft:soul_sand)
B(-5,46,-3,minecraft:soul_sand)
B(-5,47,-3,minecraft:soul_sand)
B(-5,48,-3,minecraft:soul_sand)
B(-5,49,-3,minecraft:soul_sand)
B(-5,50,-3,minecraft:soul_sand)
B(-5,42,-2,minecraft:soul_sand)
B(-5,43,-2,minecraft:soul_sand)
B(-5,44,-2,minecraft:soul_sand)
B(-5,45,-2,minecraft:soul_sand)
B(-5,46,-2,minecraft:soul_sand)
B(-5,47,-2,minecraft:soul_sand)
B(-5,48,-2,minecraft:soul_sand)
B(-5,49,-2,minecraft:soul_sand)
B(-5,50,-2,minecraft:soul_sand)
B(-5,40,-1,minecraft:soul_sand)
B(-5,41,-1,minecraft:soul_sand)
B(-5,42,-1,minecraft:soul_sand)
B(-5,43,-1,minecraft:soul_sand)
B(-5,44,-1,minecraft:soul_sand)
B(-5,45,-1,minecraft:soul_sand)
B(-5,46,-1,minecraft:soul_sand)
B(-5,47,-1,minecraft:soul_sand)
B(-5,48,-1,minecraft:soul_sand)
B(-5,49,-1,minecraft:soul_sand)
B(-5,50,-1,minecraft:soul_sand)
B(-5,39,0,minecraft:soul_sand)
B(-5,40,0,minecraft:soul_sand)
B(-5,41,0,minecraft:soul_sand)
B(-5,42,0,minecraft:soul_sand)
B(-5,43,0,minecraft:soul_sand)
B(-5,44,0,minecraft:soul_sand)
B(-5,45,0,minecraft:soul_sand)
B(-5,46,0,minecraft:soul_sand)
B(-5,47,0,minecraft:soul_sand)
B(-5,48,0,minecraft:soul_sand)
B(-5,49,0,minecraft:soul_sand)
B(-5,50,0,minecraft:soul_sand)
B(-5,38,1,minecraft:soul_sand)
B(-5,39,1,minecraft:soul_sand)
B(-5,40,1,minecraft:soul_sand)
B(-5,41,1,minecraft:soul_sand)
B(-5,42,1,minecraft:soul_sand)
B(-5,43,1,minecraft:soul_sand)
B(-5,44,1,minecraft:soul_sand)
B(-5,45,1,minecraft:soul_sand)
B(-5,46,1,minecraft:soul_sand)
B(-5,47,1,minecraft:soul_sand)
B(-5,48,1,minecraft:soul_sand)
B(-5,49,1,minecraft:soul_sand)
B(-5,50,1,minecraft:soul_sand)
B(-5,37,2,minecraft:soul_sand)
B(-5,38,2,minecraft:soul_sand)
B(-5,39,2,minecraft:soul_sand)
B(-5,40,2,minecraft:soul_sand)
B(-5,41,2,minecraft:soul_sand)
B(-5,42,2,minecraft:soul_sand)
B(-5,43,2,minecraft:soul_sand)
B(-5,44,2,minecraft:soul_sand)
B(-5,45,2,minecraft:soul_sand)
B(-5,46,2,minecraft:soul_sand)
B(-5,47,2,minecraft:soul_sand)
B(-5,48,2,minecraft:soul_sand)
B(-5,49,2,minecraft:soul_sand)
B(-5,50,2,minecraft:soul_sand)
B(-5,37,3,minecraft:soul_sand)
B(-5,38,3,minecraft:soul_sand)
B(-5,39,3,minecraft:soul_sand)
B(-5,40,3,minecraft:soul_sand)
B(-5,41,3,minecraft:soul_sand)
B(-5,42,3,minecraft:soul_sand)
B(-5,43,3,minecraft:soul_sand)
B(-5,44,3,minecraft:soul_sand)
B(-5,45,3,minecraft:soul_sand)
B(-5,46,3,minecraft:soul_sand)
B(-5,47,3,minecraft:soul_sand)
B(-5,48,3,minecraft:soul_sand)
B(-5,49,3,minecraft:soul_sand)
B(-5,50,3,minecraft:soul_sand)
B(-5,37,4,minecraft:soul_sand)
B(-5,38,4,minecraft:soul_sand)
B(-5,39,4,minecraft:soul_sand)
B(-5,40,4,minecraft:soul_sand)
B(-5,41,4,minecraft:soul_sand)
B(-5,42,4,minecraft:soul_sand)
B(-5,43,4,minecraft:soul_sand)
B(-5,44,4,minecraft:soul_sand)
B(-5,45,4,minecraft:soul_sand)
B(-5,46,4,minecraft:soul_sand)
B(-5,47,4,minecraft:soul_sand)
B(-5,48,4,minecraft:soul_sand)
B(-5,49,4,minecraft:soul_sand)
B(-5,50,4,minecraft:soul_sand)
B(-5,37,5,minecraft:soul_sand)
B(-5,38,5,minecraft:soul_sand)
B(-5,39,5,minecraft:soul_sand)
B(-5,40,5,minecraft:soul_sand)
B(-5,41,5,minecraft:soul_sand)
B(-5,42,5,minecraft:soul_sand)
B(-5,43,5,minecraft:soul_sand)
B(-5,44,5,minecraft:soul_sand)
B(-5,45,5,minecraft:soul_sand)
B(-5,46,5,minecraft:soul_sand)
B(-5,47,5,minecraft:soul_sand)
B(-5,48,5,minecraft:soul_sand)
B(-5,49,5,minecraft:soul_sand)
B(-5,50,5,minecraft:soul_sand)
B(-5,38,6,minecraft:soul_sand)
B(-5,39,6,minecraft:soul_sand)
B(-5,40,6,minecraft:soul_sand)
B(-5,41,6,minecraft:soul_sand)
B(-5,42,6,minecraft:soul_sand)
B(-5,43,6,minecraft:soul_sand)
B(-5,44,6,minecraft:soul_sand)
B(-5,45,6,minecraft:soul_sand)
B(-5,46,6,minecraft:soul_sand)
B(-5,47,6,minecraft:soul_sand)
B(-5,48,6,minecraft:soul_sand)
B(-5,49,6,minecraft:soul_sand)
B(-5,50,6,minecraft:soul_sand)
B(-5,39,7,minecraft:soul_sand)
B(-5,40,7,minecraft:soul_sand)
B(-5,41,7,minecraft:soul_sand)
B(-5,42,7,minecraft:soul_sand)
B(-5,43,7,minecraft:soul_sand)
B(-5,44,7,minecraft:soul_sand)
B(-5,45,7,minecraft:soul_sand)
B(-5,46,7,minecraft:soul_sand)
B(-5,47,7,minecraft:soul_sand)
B(-5,48,7,minecraft:soul_sand)
B(-5,49,7,minecraft:soul_sand)
B(-5,50,7,minecraft:soul_sand)
B(-5,40,8,minecraft:soul_sand)
B(-5,41,8,minecraft:soul_sand)
B(-5,42,8,minecraft:soul_sand)
B(-5,43,8,minecraft:soul_sand)
B(-5,44,8,minecraft:soul_sand)
B(-5,45,8,minecraft:soul_sand)
B(-5,46,8,minecraft:soul_sand)
B(-5,47,8,minecraft:soul_sand)
B(-5,48,8,minecraft:soul_sand)
B(-5,49,8,minecraft:soul_sand)
B(-5,50,8,minecraft:soul_sand)
B(-4,44,-7,minecraft:soul_sand)
B(-4,45,-7,minecraft:soul_sand)
B(-4,46,-7,minecraft:soul_sand)
B(-4,47,-7,minecraft:soul_sand)
B(-4,48,-7,minecraft:soul_sand)
B(-4,49,-7,minecraft:soul_sand)
B(-4,50,-7,minecraft:soul_sand)
B(-4,45,-6,minecraft:soul_sand)
B(-4,46,-6,minecraft:soul_sand)
B(-4,47,-6,minecraft:soul_sand)
B(-4,48,-6,minecraft:soul_sand)
B(-4,49,-6,minecraft:soul_sand)
B(-4,50,-6,minecraft:soul_sand)
B(-4,45,-5,minecraft:soul_sand)
B(-4,46,-5,minecraft:soul_sand)
B(-4,47,-5,minecraft:soul_sand)
B(-4,48,-5,minecraft:soul_sand)
B(-4,49,-5,minecraft:soul_sand)
B(-4,50,-5,minecraft:soul_sand)
B(-4,44,-4,minecraft:soul_sand)
B(-4,45,-4,minecraft:soul_sand)
B(-4,46,-4,minecraft:soul_sand)
B(-4,47,-4,minecraft:soul_sand)
B(-4,48,-4,minecraft:soul_sand)
B(-4,49,-4,minecraft:soul_sand)
B(-4,50,-4,minecraft:soul_sand)
B(-4,44,-3,minecraft:soul_sand)
B(-4,45,-3,minecraft:soul_sand)
B(-4,46,-3,minecraft:soul_sand)
B(-4,47,-3,minecraft:soul_sand)
B(-4,48,-3,minecraft:soul_sand)
B(-4,49,-3,minecraft:soul_sand)
B(-4,50,-3,minecraft:soul_sand)
B(-4,43,-2,minecraft:soul_sand)
B(-4,44,-2,minecraft:soul_sand)
B(-4,45,-2,minecraft:soul_sand)
B(-4,46,-2,minecraft:soul_sand)
B(-4,47,-2,minecraft:soul_sand)
B(-4,48,-2,minecraft:soul_sand)
B(-4,49,-2,minecraft:soul_sand)
B(-4,50,-2,minecraft:soul_sand)
B(-4,42,-1,minecraft:soul_sand)
B(-4,43,-1,minecraft:soul_sand)
B(-4,44,-1,minecraft:soul_sand)
B(-4,45,-1,minecraft:soul_sand)
B(-4,46,-1,minecraft:soul_sand)
B(-4,47,-1,minecraft:soul_sand)
B(-4,48,-1,minecraft:soul_sand)
B(-4,49,-1,minecraft:soul_sand)
B(-4,50,-1,minecraft:soul_sand)
B(-4,39,0,minecraft:soul_sand)
B(-4,40,0,minecraft:soul_sand)
B(-4,41,0,minecraft:soul_sand)
B(-4,42,0,minecraft:soul_sand)
B(-4,43,0,minecraft:soul_sand)
B(-4,44,0,minecraft:soul_sand)
B(-4,45,0,minecraft:soul_sand)
B(-4,46,0,minecraft:soul_sand)
B(-4,47,0,minecraft:soul_sand)
B(-4,48,0,minecraft:soul_sand)
B(-4,49,0,minecraft:soul_sand)
B(-4,50,0,minecraft:soul_sand)
B(-4,39,1,minecraft:soul_sand)
B(-4,40,1,minecraft:soul_sand)
B(-4,41,1,minecraft:soul_sand)
B(-4,42,1,minecraft:soul_sand)
B(-4,43,1,minecraft:soul_sand)
B(-4,44,1,minecraft:soul_sand)
B(-4,45,1,minecraft:soul_sand)
B(-4,46,1,minecraft:soul_sand)
B(-4,47,1,minecraft:soul_sand)
B(-4,48,1,minecraft:soul_sand)
B(-4,49,1,minecraft:soul_sand)
B(-4,50,1,minecraft:soul_sand)
B(-4,38,2,minecraft:soul_sand)
B(-4,39,2,minecraft:soul_sand)
B(-4,40,2,minecraft:soul_sand)
B(-4,41,2,minecraft:soul_sand)
B(-4,42,2,minecraft:soul_sand)
B(-4,43,2,minecraft:soul_sand)
B(-4,44,2,minecraft:soul_sand)
B(-4,45,2,minecraft:soul_sand)
B(-4,46,2,minecraft:soul_sand)
B(-4,47,2,minecraft:soul_sand)
B(-4,48,2,minecraft:soul_sand)
B(-4,49,2,minecraft:soul_sand)
B(-4,50,2,minecraft:soul_sand)
B(-4,38,3,minecraft:soul_sand)
B(-4,39,3,minecraft:soul_sand)
B(-4,40,3,minecraft:soul_sand)
B(-4,41,3,minecraft:soul_sand)
B(-4,42,3,minecraft:soul_sand)
B(-4,43,3,minecraft:soul_sand)
B(-4,44,3,minecraft:soul_sand)
B(-4,45,3,minecraft:soul_sand)
B(-4,46,3,minecraft:soul_sand)
B(-4,47,3,minecraft:soul_sand)
B(-4,48,3,minecraft:soul_sand)
B(-4,49,3,minecraft:soul_sand)
B(-4,50,3,minecraft:soul_sand)
B(-4,38,4,minecraft:soul_sand)
B(-4,39,4,minecraft:soul_sand)
B(-4,40,4,minecraft:soul_sand)
B(-4,41,4,minecraft:soul_sand)
B(-4,42,4,minecraft:soul_sand)
B(-4,43,4,minecraft:soul_sand)
B(-4,44,4,minecraft:soul_sand)
B(-4,45,4,minecraft:soul_sand)
B(-4,46,4,minecraft:soul_sand)
B(-4,47,4,minecraft:soul_sand)
B(-4,48,4,minecraft:soul_sand)
B(-4,49,4,minecraft:soul_sand)
B(-4,50,4,minecraft:soul_sand)
B(-4,38,5,minecraft:soul_sand)
B(-4,39,5,minecraft:soul_sand)
B(-4,40,5,minecraft:soul_sand)
B(-4,41,5,minecraft:soul_sand)
B(-4,42,5,minecraft:soul_sand)
B(-4,43,5,minecraft:soul_sand)
B(-4,44,5,minecraft:soul_sand)
B(-4,45,5,minecraft:soul_sand)
B(-4,46,5,minecraft:soul_sand)
B(-4,47,5,minecraft:soul_sand)
B(-4,48,5,minecraft:soul_sand)
B(-4,49,5,minecraft:soul_sand)
B(-4,50,5,minecraft:soul_sand)
B(-4,39,6,minecraft:soul_sand)
B(-4,40,6,minecraft:soul_sand)
B(-4,41,6,minecraft:soul_sand)
B(-4,42,6,minecraft:soul_sand)
B(-4,43,6,minecraft:soul_sand)
B(-4,44,6,minecraft:soul_sand)
B(-4,45,6,minecraft:soul_sand)
B(-4,46,6,minecraft:soul_sand)
B(-4,47,6,minecraft:soul_sand)
B(-4,48,6,minecraft:soul_sand)
B(-4,49,6,minecraft:soul_sand)
B(-4,50,6,minecraft:soul_sand)
B(-4,40,7,minecraft:soul_sand)
B(-4,41,7,minecraft:soul_sand)
B(-4,42,7,minecraft:soul_sand)
B(-4,43,7,minecraft:soul_sand)
B(-4,44,7,minecraft:soul_sand)
B(-4,45,7,minecraft:soul_sand)
B(-4,46,7,minecraft:soul_sand)
B(-4,47,7,minecraft:soul_sand)
B(-4,48,7,minecraft:soul_sand)
B(-4,49,7,minecraft:soul_sand)
B(-4,50,7,minecraft:soul_sand)
B(-4,41,8,minecraft:soul_sand)
B(-4,42,8,minecraft:soul_sand)
B(-4,43,8,minecraft:soul_sand)
B(-4,44,8,minecraft:soul_sand)
B(-4,45,8,minecraft:soul_sand)
B(-4,46,8,minecraft:soul_sand)
B(-4,47,8,minecraft:soul_sand)
B(-4,48,8,minecraft:soul_sand)
B(-4,49,8,minecraft:soul_sand)
B(-4,50,8,minecraft:soul_sand)
B(-3,45,-7,minecraft:soul_sand)
B(-3,46,-7,minecraft:soul_sand)
B(-3,47,-7,minecraft:soul_sand)
B(-3,48,-7,minecraft:soul_sand)
B(-3,49,-7,minecraft:soul_sand)
B(-3,50,-7,minecraft:soul_sand)
B(-3,45,-6,minecraft:soul_sand)
B(-3,46,-6,minecraft:soul_sand)
B(-3,47,-6,minecraft:soul_sand)
B(-3,48,-6,minecraft:soul_sand)
B(-3,49,-6,minecraft:soul_sand)
B(-3,50,-6,minecraft:soul_sand)
B(-3,45,-5,minecraft:soul_sand)
B(-3,46,-5,minecraft:soul_sand)
B(-3,47,-5,minecraft:soul_sand)
B(-3,48,-5,minecraft:soul_sand)
B(-3,49,-5,minecraft:soul_sand)
B(-3,50,-5,minecraft:soul_sand)
B(-3,45,-4,minecraft:soul_sand)
B(-3,46,-4,minecraft:soul_sand)
B(-3,47,-4,minecraft:soul_sand)
B(-3,48,-4,minecraft:soul_sand)
B(-3,49,-4,minecraft:soul_sand)
B(-3,50,-4,minecraft:soul_sand)
B(-3,44,-3,minecraft:soul_sand)
B(-3,45,-3,minecraft:soul_sand)
B(-3,46,-3,minecraft:soul_sand)
B(-3,47,-3,minecraft:soul_sand)
B(-3,48,-3,minecraft:soul_sand)
B(-3,49,-3,minecraft:soul_sand)
B(-3,50,-3,minecraft:soul_sand)
B(-3,43,-2,minecraft:soul_sand)
B(-3,44,-2,minecraft:soul_sand)
B(-3,45,-2,minecraft:soul_sand)
B(-3,46,-2,minecraft:soul_sand)
B(-3,47,-2,minecraft:soul_sand)
B(-3,48,-2,minecraft:soul_sand)
B(-3,49,-2,minecraft:soul_sand)
B(-3,50,-2,minecraft:soul_sand)
B(-3,42,-1,minecraft:soul_sand)
B(-3,43,-1,minecraft:soul_sand)
B(-3,44,-1,minecraft:soul_sand)
B(-3,45,-1,minecraft:soul_sand)
B(-3,46,-1,minecraft:soul_sand)
B(-3,47,-1,minecraft:soul_sand)
B(-3,48,-1,minecraft:soul_sand)
B(-3,49,-1,minecraft:soul_sand)
B(-3,50,-1,minecraft:soul_sand)
B(-3,40,0,minecraft:soul_sand)
B(-3,41,0,minecraft:soul_sand)
B(-3,42,0,minecraft:soul_sand)
B(-3,43,0,minecraft:soul_sand)
B(-3,44,0,minecraft:soul_sand)
B(-3,45,0,minecraft:soul_sand)
B(-3,46,0,minecraft:soul_sand)
B(-3,47,0,minecraft:soul_sand)
B(-3,48,0,minecraft:soul_sand)
B(-3,49,0,minecraft:soul_sand)
B(-3,50,0,minecraft:soul_sand)
B(-3,39,1,minecraft:soul_sand)
B(-3,40,1,minecraft:soul_sand)
B(-3,41,1,minecraft:soul_sand)
B(-3,42,1,minecraft:soul_sand)
B(-3,43,1,minecraft:soul_sand)
B(-3,44,1,minecraft:soul_sand)
B(-3,45,1,minecraft:soul_sand)
B(-3,46,1,minecraft:soul_sand)
B(-3,47,1,minecraft:soul_sand)
B(-3,48,1,minecraft:soul_sand)
B(-3,49,1,minecraft:soul_sand)
B(-3,50,1,minecraft:soul_sand)
B(-3,39,2,minecraft:soul_sand)
B(-3,40,2,minecraft:soul_sand)
B(-3,41,2,minecraft:soul_sand)
B(-3,42,2,minecraft:soul_sand)
B(-3,43,2,minecraft:soul_sand)
B(-3,44,2,minecraft:soul_sand)
B(-3,45,2,minecraft:soul_sand)
B(-3,46,2,minecraft:soul_sand)
B(-3,47,2,minecraft:soul_sand)
B(-3,48,2,minecraft:soul_sand)
B(-3,49,2,minecraft:soul_sand)
B(-3,50,2,minecraft:soul_sand)
B(-3,39,3,minecraft:soul_sand)
B(-3,40,3,minecraft:soul_sand)
B(-3,41,3,minecraft:soul_sand)
B(-3,42,3,minecraft:soul_sand)
B(-3,43,3,minecraft:soul_sand)
B(-3,44,3,minecraft:soul_sand)
B(-3,45,3,minecraft:soul_sand)
B(-3,46,3,minecraft:soul_sand)
B(-3,47,3,minecraft:soul_sand)
B(-3,48,3,minecraft:soul_sand)
B(-3,49,3,minecraft:soul_sand)
B(-3,50,3,minecraft:soul_sand)
B(-3,39,4,minecraft:soul_sand)
B(-3,40,4,minecraft:soul_sand)
B(-3,41,4,minecraft:soul_sand)
B(-3,42,4,minecraft:soul_sand)
B(-3,43,4,minecraft:soul_sand)
B(-3,44,4,minecraft:soul_sand)
B(-3,45,4,minecraft:soul_sand)
B(-3,46,4,minecraft:soul_sand)
B(-3,47,4,minecraft:soul_sand)
B(-3,48,4,minecraft:soul_sand)
B(-3,49,4,minecraft:soul_sand)
B(-3,50,4,minecraft:soul_sand)
B(-3,39,5,minecraft:soul_sand)
B(-3,40,5,minecraft:soul_sand)
B(-3,41,5,minecraft:soul_sand)
B(-3,42,5,minecraft:soul_sand)
B(-3,43,5,minecraft:soul_sand)
B(-3,44,5,minecraft:soul_sand)
B(-3,45,5,minecraft:soul_sand)
B(-3,46,5,minecraft:soul_sand)
B(-3,47,5,minecraft:soul_sand)
B(-3,48,5,minecraft:soul_sand)
B(-3,49,5,minecraft:soul_sand)
B(-3,50,5,minecraft:soul_sand)
B(-3,40,6,minecraft:soul_sand)
B(-3,41,6,minecraft:soul_sand)
B(-3,42,6,minecraft:soul_sand)
B(-3,43,6,minecraft:soul_sand)
B(-3,44,6,minecraft:soul_sand)
B(-3,45,6,minecraft:soul_sand)
B(-3,46,6,minecraft:soul_sand)
B(-3,47,6,minecraft:soul_sand)
B(-3,48,6,minecraft:soul_sand)
B(-3,49,6,minecraft:soul_sand)
B(-3,50,6,minecraft:soul_sand)
B(-3,41,7,minecraft:soul_sand)
B(-3,42,7,minecraft:soul_sand)
B(-3,43,7,minecraft:soul_sand)
B(-3,44,7,minecraft:soul_sand)
B(-3,45,7,minecraft:soul_sand)
B(-3,46,7,minecraft:soul_sand)
B(-3,47,7,minecraft:soul_sand)
B(-3,48,7,minecraft:soul_sand)
B(-3,49,7,minecraft:soul_sand)
B(-3,50,7,minecraft:soul_sand)
B(-3,42,8,minecraft:soul_sand)
B(-3,43,8,minecraft:soul_sand)
B(-3,44,8,minecraft:soul_sand)
B(-3,45,8,minecraft:soul_sand)
B(-3,46,8,minecraft:soul_sand)
B(-3,47,8,minecraft:soul_sand)
B(-3,48,8,minecraft:soul_sand)
B(-3,49,8,minecraft:soul_sand)
B(-3,50,8,minecraft:soul_sand)
B(-2,46,-7,minecraft:soul_sand)
B(-2,47,-7,minecraft:soul_sand)
B(-2,48,-7,minecraft:soul_sand)
B(-2,49,-7,minecraft:soul_sand)
B(-2,50,-7,minecraft:soul_sand)
B(-2,46,-6,minecraft:soul_sand)
B(-2,47,-6,minecraft:soul_sand)
B(-2,48,-6,minecraft:soul_sand)
B(-2,49,-6,minecraft:soul_sand)
B(-2,50,-6,minecraft:soul_sand)
B(-2,46,-5,minecraft:soul_sand)
B(-2,47,-5,minecraft:soul_sand)
B(-2,48,-5,minecraft:soul_sand)
B(-2,49,-5,minecraft:soul_sand)
B(-2,50,-5,minecraft:soul_sand)
B(-2,46,-4,minecraft:soul_sand)
B(-2,47,-4,minecraft:soul_sand)
B(-2,48,-4,minecraft:soul_sand)
B(-2,49,-4,minecraft:soul_sand)
B(-2,50,-4,minecraft:soul_sand)
B(-2,49,-3,minecraft:soul_sand)
B(-2,50,-3,minecraft:soul_sand)
B(-2,44,-2,minecraft:soul_sand)
B(-2,45,-2,minecraft:soul_sand)
B(-2,46,-2,minecraft:soul_sand)
B(-2,47,-2,minecraft:soul_sand)
B(-2,48,-2,minecraft:soul_sand)
B(-2,49,-2,minecraft:soul_sand)
B(-2,50,-2,minecraft:soul_sand)
B(-2,43,-1,minecraft:soul_sand)
B(-2,44,-1,minecraft:soul_sand)
B(-2,45,-1,minecraft:soul_sand)
B(-2,46,-1,minecraft:soul_sand)
B(-2,47,-1,minecraft:soul_sand)
B(-2,48,-1,minecraft:soul_sand)
B(-2,49,-1,minecraft:soul_sand)
B(-2,50,-1,minecraft:soul_sand)
B(-2,41,0,minecraft:soul_sand)
B(-2,42,0,minecraft:soul_sand)
B(-2,43,0,minecraft:soul_sand)
B(-2,44,0,minecraft:soul_sand)
B(-2,45,0,minecraft:soul_sand)
B(-2,46,0,minecraft:soul_sand)
B(-2,47,0,minecraft:soul_sand)
B(-2,48,0,minecraft:soul_sand)
B(-2,49,0,minecraft:soul_sand)
B(-2,50,0,minecraft:soul_sand)
B(-2,40,1,minecraft:soul_sand)
B(-2,41,1,minecraft:soul_sand)
B(-2,42,1,minecraft:soul_sand)
B(-2,43,1,minecraft:soul_sand)
B(-2,44,1,minecraft:soul_sand)
B(-2,45,1,minecraft:soul_sand)
B(-2,46,1,minecraft:soul_sand)
B(-2,47,1,minecraft:soul_sand)
B(-2,48,1,minecraft:soul_sand)
B(-2,49,1,minecraft:soul_sand)
B(-2,50,1,minecraft:soul_sand)
B(-2,40,2,minecraft:soul_sand)
B(-2,41,2,minecraft:soul_sand)
B(-2,42,2,minecraft:soul_sand)
B(-2,43,2,minecraft:soul_sand)
B(-2,44,2,minecraft:soul_sand)
B(-2,45,2,minecraft:soul_sand)
B(-2,46,2,minecraft:soul_sand)
B(-2,47,2,minecraft:soul_sand)
B(-2,48,2,minecraft:soul_sand)
B(-2,49,2,minecraft:soul_sand)
B(-2,50,2,minecraft:soul_sand)
B(-2,40,3,minecraft:soul_sand)
B(-2,41,3,minecraft:soul_sand)
B(-2,42,3,minecraft:soul_sand)
B(-2,43,3,minecraft:soul_sand)
B(-2,44,3,minecraft:soul_sand)
B(-2,45,3,minecraft:soul_sand)
B(-2,46,3,minecraft:soul_sand)
B(-2,47,3,minecraft:soul_sand)
B(-2,48,3,minecraft:soul_sand)
B(-2,49,3,minecraft:soul_sand)
B(-2,50,3,minecraft:soul_sand)
B(-2,40,4,minecraft:soul_sand)
B(-2,41,4,minecraft:soul_sand)
B(-2,42,4,minecraft:soul_sand)
B(-2,43,4,minecraft:soul_sand)
B(-2,44,4,minecraft:soul_sand)
B(-2,45,4,minecraft:soul_sand)
B(-2,46,4,minecraft:soul_sand)
B(-2,47,4,minecraft:soul_sand)
B(-2,48,4,minecraft:soul_sand)
B(-2,49,4,minecraft:soul_sand)
B(-2,50,4,minecraft:soul_sand)
B(-2,40,5,minecraft:soul_sand)
B(-2,41,5,minecraft:soul_sand)
B(-2,42,5,minecraft:soul_sand)
B(-2,43,5,minecraft:soul_sand)
B(-2,44,5,minecraft:soul_sand)
B(-2,45,5,minecraft:soul_sand)
B(-2,46,5,minecraft:soul_sand)
B(-2,47,5,minecraft:soul_sand)
B(-2,48,5,minecraft:soul_sand)
B(-2,49,5,minecraft:soul_sand)
B(-2,50,5,minecraft:soul_sand)
B(-2,41,6,minecraft:soul_sand)
B(-2,42,6,minecraft:soul_sand)
B(-2,43,6,minecraft:soul_sand)
B(-2,44,6,minecraft:soul_sand)
B(-2,45,6,minecraft:soul_sand)
B(-2,46,6,minecraft:soul_sand)
B(-2,47,6,minecraft:soul_sand)
B(-2,48,6,minecraft:soul_sand)
B(-2,49,6,minecraft:soul_sand)
B(-2,50,6,minecraft:soul_sand)
B(-2,42,7,minecraft:soul_sand)
B(-2,43,7,minecraft:soul_sand)
B(-2,44,7,minecraft:soul_sand)
B(-2,45,7,minecraft:soul_sand)
B(-2,46,7,minecraft:soul_sand)
B(-2,47,7,minecraft:soul_sand)
B(-2,48,7,minecraft:soul_sand)
B(-2,49,7,minecraft:soul_sand)
B(-2,50,7,minecraft:soul_sand)
B(-2,42,8,minecraft:soul_sand)
B(-2,43,8,minecraft:soul_sand)
B(-2,44,8,minecraft:soul_sand)
B(-2,45,8,minecraft:soul_sand)
B(-2,46,8,minecraft:soul_sand)
B(-2,47,8,minecraft:soul_sand)
B(-2,48,8,minecraft:soul_sand)
B(-2,49,8,minecraft:soul_sand)
B(-2,50,8,minecraft:soul_sand)
B(-1,47,-7,minecraft:soul_sand)
B(-1,48,-7,minecraft:soul_sand)
B(-1,49,-7,minecraft:soul_sand)
B(-1,50,-7,minecraft:soul_sand)
B(-1,47,-6,minecraft:soul_sand)
B(-1,48,-6,minecraft:soul_sand)
B(-1,49,-6,minecraft:soul_sand)
B(-1,50,-6,minecraft:soul_sand)
B(-1,47,-5,minecraft:soul_sand)
B(-1,48,-5,minecraft:soul_sand)
B(-1,49,-5,minecraft:soul_sand)
B(-1,50,-5,minecraft:soul_sand)
B(-1,47,-4,minecraft:soul_sand)
B(-1,48,-4,minecraft:soul_sand)
B(-1,49,-4,minecraft:soul_sand)
B(-1,50,-4,minecraft:soul_sand)
B(-1,47,-3,minecraft:soul_sand)
B(-1,48,-3,minecraft:soul_sand)
B(-1,49,-3,minecraft:soul_sand)
B(-1,50,-3,minecraft:soul_sand)
B(-1,46,-2,minecraft:soul_sand)
B(-1,47,-2,minecraft:soul_sand)
B(-1,48,-2,minecraft:soul_sand)
B(-1,49,-2,minecraft:soul_sand)
B(-1,50,-2,minecraft:soul_sand)
B(-1,45,-1,minecraft:soul_sand)
B(-1,46,-1,minecraft:soul_sand)
B(-1,47,-1,minecraft:soul_sand)
B(-1,48,-1,minecraft:soul_sand)
B(-1,49,-1,minecraft:soul_sand)
B(-1,50,-1,minecraft:soul_sand)
B(-1,45,0,minecraft:soul_sand)
B(-1,46,0,minecraft:soul_sand)
B(-1,47,0,minecraft:soul_sand)
B(-1,48,0,minecraft:soul_sand)
B(-1,49,0,minecraft:soul_sand)
B(-1,50,0,minecraft:soul_sand)
B(-1,41,1,minecraft:soul_sand)
B(-1,42,1,minecraft:soul_sand)
B(-1,43,1,minecraft:soul_sand)
B(-1,44,1,minecraft:soul_sand)
B(-1,45,1,minecraft:soul_sand)
B(-1,46,1,minecraft:soul_sand)
B(-1,47,1,minecraft:soul_sand)
B(-1,48,1,minecraft:soul_sand)
B(-1,49,1,minecraft:soul_sand)
B(-1,50,1,minecraft:soul_sand)
B(-1,40,2,minecraft:soul_sand)
B(-1,41,2,minecraft:soul_sand)
B(-1,42,2,minecraft:soul_sand)
B(-1,43,2,minecraft:soul_sand)
B(-1,44,2,minecraft:soul_sand)
B(-1,45,2,minecraft:soul_sand)
B(-1,46,2,minecraft:soul_sand)
B(-1,47,2,minecraft:soul_sand)
B(-1,48,2,minecraft:soul_sand)
B(-1,49,2,minecraft:soul_sand)
B(-1,50,2,minecraft:soul_sand)
B(-1,40,3,minecraft:soul_sand)
B(-1,41,3,minecraft:soul_sand)
B(-1,42,3,minecraft:soul_sand)
B(-1,43,3,minecraft:soul_sand)
B(-1,44,3,minecraft:soul_sand)
B(-1,45,3,minecraft:soul_sand)
B(-1,46,3,minecraft:soul_sand)
B(-1,47,3,minecraft:soul_sand)
B(-1,48,3,minecraft:soul_sand)
B(-1,49,3,minecraft:soul_sand)
B(-1,50,3,minecraft:soul_sand)
B(-1,41,4,minecraft:soul_sand)
B(-1,42,4,minecraft:soul_sand)
B(-1,43,4,minecraft:soul_sand)
B(-1,44,4,minecraft:soul_sand)
B(-1,45,4,minecraft:soul_sand)
B(-1,46,4,minecraft:soul_sand)
B(-1,47,4,minecraft:soul_sand)
B(-1,48,4,minecraft:soul_sand)
B(-1,49,4,minecraft:soul_sand)
B(-1,50,4,minecraft:soul_sand)
B(-1,41,5,minecraft:soul_sand)
B(-1,42,5,minecraft:soul_sand)
B(-1,43,5,minecraft:soul_sand)
B(-1,44,5,minecraft:soul_sand)
B(-1,45,5,minecraft:soul_sand)
B(-1,46,5,minecraft:soul_sand)
B(-1,47,5,minecraft:soul_sand)
B(-1,48,5,minecraft:soul_sand)
B(-1,49,5,minecraft:soul_sand)
B(-1,50,5,minecraft:soul_sand)
B(-1,42,6,minecraft:soul_sand)
B(-1,43,6,minecraft:soul_sand)
B(-1,44,6,minecraft:soul_sand)
B(-1,45,6,minecraft:soul_sand)
B(-1,46,6,minecraft:soul_sand)
B(-1,47,6,minecraft:soul_sand)
B(-1,48,6,minecraft:soul_sand)
B(-1,49,6,minecraft:soul_sand)
B(-1,50,6,minecraft:soul_sand)
B(-1,42,7,minecraft:soul_sand)
B(-1,43,7,minecraft:soul_sand)
B(-1,44,7,minecraft:soul_sand)
B(-1,45,7,minecraft:soul_sand)
B(-1,46,7,minecraft:soul_sand)
B(-1,47,7,minecraft:soul_sand)
B(-1,48,7,minecraft:soul_sand)
B(-1,49,7,minecraft:soul_sand)
B(-1,50,7,minecraft:soul_sand)
B(-1,43,8,minecraft:soul_sand)
B(-1,44,8,minecraft:soul_sand)
B(-1,45,8,minecraft:soul_sand)
B(-1,46,8,minecraft:soul_sand)
B(-1,47,8,minecraft:soul_sand)
B(-1,48,8,minecraft:soul_sand)
B(-1,49,8,minecraft:soul_sand)
B(-1,50,8,minecraft:soul_sand)
B(0,47,-7,minecraft:soul_sand)
B(0,48,-7,minecraft:soul_sand)
B(0,49,-7,minecraft:soul_sand)
B(0,50,-7,minecraft:soul_sand)
B(0,47,-6,minecraft:soul_sand)
B(0,48,-6,minecraft:soul_sand)
B(0,49,-6,minecraft:soul_sand)
B(0,50,-6,minecraft:soul_sand)
B(0,47,-5,minecraft:soul_sand)
B(0,48,-5,minecraft:soul_sand)
B(0,49,-5,minecraft:soul_sand)
B(0,50,-5,minecraft:soul_sand)
B(0,48,-4,minecraft:soul_sand)
B(0,49,-4,minecraft:soul_sand)
B(0,50,-4,minecraft:soul_sand)
B(0,47,-3,minecraft:soul_sand)
B(0,48,-3,minecraft:soul_sand)
B(0,49,-3,minecraft:soul_sand)
B(0,50,-3,minecraft:soul_sand)
B(0,46,-2,minecraft:soul_sand)
B(0,47,-2,minecraft:soul_sand)
B(0,48,-2,minecraft:soul_sand)
B(0,49,-2,minecraft:soul_sand)
B(0,50,-2,minecraft:soul_sand)
B(0,46,-1,minecraft:soul_sand)
B(0,47,-1,minecraft:soul_sand)
B(0,48,-1,minecraft:soul_sand)
B(0,49,-1,minecraft:soul_sand)
B(0,50,-1,minecraft:soul_sand)
B(0,45,0,minecraft:soul_sand)
B(0,46,0,minecraft:soul_sand)
B(0,47,0,minecraft:soul_sand)
B(0,48,0,minecraft:soul_sand)
B(0,49,0,minecraft:soul_sand)
B(0,50,0,minecraft:soul_sand)
B(0,41,1,minecraft:soul_sand)
B(0,42,1,minecraft:soul_sand)
B(0,43,1,minecraft:soul_sand)
B(0,44,1,minecraft:soul_sand)
B(0,45,1,minecraft:soul_sand)
B(0,46,1,minecraft:soul_sand)
B(0,47,1,minecraft:soul_sand)
B(0,48,1,minecraft:soul_sand)
B(0,49,1,minecraft:soul_sand)
B(0,50,1,minecraft:soul_sand)
B(0,40,2,minecraft:soul_sand)
B(0,41,2,minecraft:soul_sand)
B(0,42,2,minecraft:soul_sand)
B(0,43,2,minecraft:soul_sand)
B(0,44,2,minecraft:soul_sand)
B(0,45,2,minecraft:soul_sand)
B(0,46,2,minecraft:soul_sand)
B(0,47,2,minecraft:soul_sand)
B(0,48,2,minecraft:soul_sand)
B(0,49,2,minecraft:soul_sand)
B(0,50,2,minecraft:soul_sand)
B(0,41,3,minecraft:soul_sand)
B(0,42,3,minecraft:soul_sand)
B(0,43,3,minecraft:soul_sand)
B(0,44,3,minecraft:soul_sand)
B(0,45,3,minecraft:soul_sand)
B(0,46,3,minecraft:soul_sand)
B(0,47,3,minecraft:soul_sand)
B(0,48,3,minecraft:soul_sand)
B(0,49,3,minecraft:soul_sand)
B(0,50,3,minecraft:soul_sand)
B(0,41,4,minecraft:soul_sand)
B(0,42,4,minecraft:soul_sand)
B(0,43,4,minecraft:soul_sand)
B(0,44,4,minecraft:soul_sand)
B(0,45,4,minecraft:soul_sand)
B(0,46,4,minecraft:soul_sand)
B(0,47,4,minecraft:soul_sand)
B(0,48,4,minecraft:soul_sand)
B(0,49,4,minecraft:soul_sand)
B(0,50,4,minecraft:soul_sand)
B(0,42,5,minecraft:soul_sand)
B(0,43,5,minecraft:soul_sand)
B(0,44,5,minecraft:soul_sand)
B(0,45,5,minecraft:soul_sand)
B(0,46,5,minecraft:soul_sand)
B(0,47,5,minecraft:soul_sand)
B(0,48,5,minecraft:soul_sand)
B(0,49,5,minecraft:soul_sand)
B(0,50,5,minecraft:soul_sand)
B(0,42,6,minecraft:soul_sand)
B(0,43,6,minecraft:soul_sand)
B(0,44,6,minecraft:soul_sand)
B(0,45,6,minecraft:soul_sand)
B(0,46,6,minecraft:soul_sand)
B(0,47,6,minecraft:soul_sand)
B(0,48,6,minecraft:soul_sand)
B(0,49,6,minecraft:soul_sand)
B(0,50,6,minecraft:soul_sand)
B(0,43,7,minecraft:soul_sand)
B(0,44,7,minecraft:soul_sand)
B(0,45,7,minecraft:soul_sand)
B(0,46,7,minecraft:soul_sand)
B(0,47,7,minecraft:soul_sand)
B(0,48,7,minecraft:soul_sand)
B(0,49,7,minecraft:soul_sand)
B(0,50,7,minecraft:soul_sand)
B(0,44,8,minecraft:soul_sand)
B(0,45,8,minecraft:soul_sand)
B(0,46,8,minecraft:soul_sand)
B(0,47,8,minecraft:soul_sand)
B(0,48,8,minecraft:soul_sand)
B(0,49,8,minecraft:soul_sand)
B(0,50,8,minecraft:soul_sand)
B(1,47,-7,minecraft:soul_sand)
B(1,48,-7,minecraft:soul_sand)
B(1,49,-7,minecraft:soul_sand)
B(1,50,-7,minecraft:soul_sand)
B(1,47,-6,minecraft:soul_sand)
B(1,48,-6,minecraft:soul_sand)
B(1,49,-6,minecraft:soul_sand)
B(1,50,-6,minecraft:soul_sand)
B(1,48,-5,minecraft:soul_sand)
B(1,49,-5,minecraft:soul_sand)
B(1,50,-5,minecraft:soul_sand)
B(1,48,-4,minecraft:soul_sand)
B(1,49,-4,minecraft:soul_sand)
B(1,50,-4,minecraft:soul_sand)
B(1,48,-3,minecraft:soul_sand)
B(1,49,-3,minecraft:soul_sand)
B(1,50,-3,minecraft:soul_sand)
B(1,47,-2,minecraft:soul_sand)
B(1,48,-2,minecraft:soul_sand)
B(1,49,-2,minecraft:soul_sand)
B(1,50,-2,minecraft:soul_sand)
B(1,47,-1,minecraft:soul_sand)
B(1,48,-1,minecraft:soul_sand)
B(1,49,-1,minecraft:soul_sand)
B(1,50,-1,minecraft:soul_sand)
B(1,46,0,minecraft:soul_sand)
B(1,47,0,minecraft:soul_sand)
B(1,48,0,minecraft:soul_sand)
B(1,49,0,minecraft:soul_sand)
B(1,50,0,minecraft:soul_sand)
B(1,41,1,minecraft:soul_sand)
B(1,42,1,minecraft:soul_sand)
B(1,43,1,minecraft:soul_sand)
B(1,44,1,minecraft:soul_sand)
B(1,45,1,minecraft:soul_sand)
B(1,46,1,minecraft:soul_sand)
B(1,47,1,minecraft:soul_sand)
B(1,48,1,minecraft:soul_sand)
B(1,49,1,minecraft:soul_sand)
B(1,50,1,minecraft:soul_sand)
B(1,41,2,minecraft:soul_sand)
B(1,42,2,minecraft:soul_sand)
B(1,43,2,minecraft:soul_sand)
B(1,44,2,minecraft:soul_sand)
B(1,45,2,minecraft:soul_sand)
B(1,46,2,minecraft:soul_sand)
B(1,47,2,minecraft:soul_sand)
B(1,48,2,minecraft:soul_sand)
B(1,49,2,minecraft:soul_sand)
B(1,50,2,minecraft:soul_sand)
B(1,42,3,minecraft:soul_sand)
B(1,43,3,minecraft:soul_sand)
B(1,44,3,minecraft:soul_sand)
B(1,45,3,minecraft:soul_sand)
B(1,46,3,minecraft:soul_sand)
B(1,47,3,minecraft:soul_sand)
B(1,48,3,minecraft:soul_sand)
B(1,49,3,minecraft:soul_sand)
B(1,50,3,minecraft:soul_sand)
B(1,42,4,minecraft:soul_sand)
B(1,43,4,minecraft:soul_sand)
B(1,44,4,minecraft:soul_sand)
B(1,45,4,minecraft:soul_sand)
B(1,46,4,minecraft:soul_sand)
B(1,47,4,minecraft:soul_sand)
B(1,48,4,minecraft:soul_sand)
B(1,49,4,minecraft:soul_sand)
B(1,50,4,minecraft:soul_sand)
B(1,43,5,minecraft:soul_sand)
B(1,44,5,minecraft:soul_sand)
B(1,45,5,minecraft:soul_sand)
B(1,46,5,minecraft:soul_sand)
B(1,47,5,minecraft:soul_sand)
B(1,48,5,minecraft:soul_sand)
B(1,49,5,minecraft:soul_sand)
B(1,50,5,minecraft:soul_sand)
B(1,43,6,minecraft:soul_sand)
B(1,44,6,minecraft:soul_sand)
B(1,45,6,minecraft:soul_sand)
B(1,46,6,minecraft:soul_sand)
B(1,47,6,minecraft:soul_sand)
B(1,48,6,minecraft:soul_sand)
B(1,49,6,minecraft:soul_sand)
B(1,50,6,minecraft:soul_sand)
B(1,44,7,minecraft:soul_sand)
B(1,45,7,minecraft:soul_sand)
B(1,46,7,minecraft:soul_sand)
B(1,47,7,minecraft:soul_sand)
B(1,48,7,minecraft:soul_sand)
B(1,49,7,minecraft:soul_sand)
B(1,50,7,minecraft:soul_sand)
B(1,44,8,minecraft:soul_sand)
B(1,45,8,minecraft:soul_sand)
B(1,46,8,minecraft:soul_sand)
B(1,47,8,minecraft:soul_sand)
B(1,48,8,minecraft:soul_sand)
B(1,49,8,minecraft:soul_sand)
B(1,50,8,minecraft:soul_sand)
B(2,47,-7,minecraft:soul_sand)
B(2,48,-7,minecraft:soul_sand)
B(2,49,-7,minecraft:soul_sand)
B(2,50,-7,minecraft:soul_sand)
B(2,47,-6,minecraft:soul_sand)
B(2,48,-6,minecraft:soul_sand)
B(2,49,-6,minecraft:soul_sand)
B(2,50,-6,minecraft:soul_sand)
B(2,48,-5,minecraft:soul_sand)
B(2,49,-5,minecraft:soul_sand)
B(2,50,-5,minecraft:soul_sand)
B(2,48,-4,minecraft:soul_sand)
B(2,49,-4,minecraft:soul_sand)
B(2,50,-4,minecraft:soul_sand)
B(2,48,-3,minecraft:soul_sand)
B(2,49,-3,minecraft:soul_sand)
B(2,50,-3,minecraft:soul_sand)
B(2,48,-2,minecraft:soul_sand)
B(2,49,-2,minecraft:soul_sand)
B(2,50,-2,minecraft:soul_sand)
B(2,47,-1,minecraft:soul_sand)
B(2,48,-1,minecraft:soul_sand)
B(2,49,-1,minecraft:soul_sand)
B(2,50,-1,minecraft:soul_sand)
B(2,46,0,minecraft:soul_sand)
B(2,47,0,minecraft:soul_sand)
B(2,48,0,minecraft:soul_sand)
B(2,49,0,minecraft:soul_sand)
B(2,50,0,minecraft:soul_sand)
B(2,46,1,minecraft:soul_sand)
B(2,47,1,minecraft:soul_sand)
B(2,48,1,minecraft:soul_sand)
B(2,49,1,minecraft:soul_sand)
B(2,50,1,minecraft:soul_sand)
B(2,45,2,minecraft:soul_sand)
B(2,46,2,minecraft:soul_sand)
B(2,47,2,minecraft:soul_sand)
B(2,48,2,minecraft:soul_sand)
B(2,49,2,minecraft:soul_sand)
B(2,50,2,minecraft:soul_sand)
B(2,43,3,minecraft:soul_sand)
B(2,44,3,minecraft:soul_sand)
B(2,45,3,minecraft:soul_sand)
B(2,46,3,minecraft:soul_sand)
B(2,47,3,minecraft:soul_sand)
B(2,48,3,minecraft:soul_sand)
B(2,49,3,minecraft:soul_sand)
B(2,50,3,minecraft:soul_sand)
B(2,43,4,minecraft:soul_sand)
B(2,44,4,minecraft:soul_sand)
B(2,45,4,minecraft:soul_sand)
B(2,46,4,minecraft:soul_sand)
B(2,47,4,minecraft:soul_sand)
B(2,48,4,minecraft:soul_sand)
B(2,49,4,minecraft:soul_sand)
B(2,50,4,minecraft:soul_sand)
B(2,43,5,minecraft:soul_sand)
B(2,44,5,minecraft:soul_sand)
B(2,45,5,minecraft:soul_sand)
B(2,46,5,minecraft:soul_sand)
B(2,47,5,minecraft:soul_sand)
B(2,48,5,minecraft:soul_sand)
B(2,49,5,minecraft:soul_sand)
B(2,50,5,minecraft:soul_sand)
B(2,44,6,minecraft:soul_sand)
B(2,45,6,minecraft:soul_sand)
B(2,46,6,minecraft:soul_sand)
B(2,47,6,minecraft:soul_sand)
B(2,48,6,minecraft:soul_sand)
B(2,49,6,minecraft:soul_sand)
B(2,50,6,minecraft:soul_sand)
B(2,45,7,minecraft:soul_sand)
B(2,46,7,minecraft:soul_sand)
B(2,47,7,minecraft:soul_sand)
B(2,48,7,minecraft:soul_sand)
B(2,49,7,minecraft:soul_sand)
B(2,50,7,minecraft:soul_sand)
B(2,45,8,minecraft:soul_sand)
B(2,46,8,minecraft:soul_sand)
B(2,47,8,minecraft:soul_sand)
B(2,48,8,minecraft:soul_sand)
B(2,49,8,minecraft:soul_sand)
B(2,50,8,minecraft:soul_sand)
B(3,47,-7,minecraft:soul_sand)
B(3,48,-7,minecraft:soul_sand)
B(3,49,-7,minecraft:soul_sand)
B(3,50,-7,minecraft:soul_sand)
B(3,48,-6,minecraft:soul_sand)
B(3,49,-6,minecraft:soul_sand)
B(3,50,-6,minecraft:soul_sand)
B(3,48,-5,minecraft:soul_sand)
B(3,49,-5,minecraft:soul_sand)
B(3,50,-5,minecraft:soul_sand)
B(3,49,-4,minecraft:soul_sand)
B(3,50,-4,minecraft:soul_sand)
B(3,49,-3,minecraft:soul_sand)
B(3,50,-3,minecraft:soul_sand)
B(3,49,-2,minecraft:soul_sand)
B(3,50,-2,minecraft:soul_sand)
B(3,48,-1,minecraft:soul_sand)
B(3,49,-1,minecraft:soul_sand)
B(3,50,-1,minecraft:soul_sand)
B(3,47,0,minecraft:soul_sand)
B(3,48,0,minecraft:soul_sand)
B(3,49,0,minecraft:soul_sand)
B(3,50,0,minecraft:soul_sand)
B(3,46,1,minecraft:soul_sand)
B(3,47,1,minecraft:soul_sand)
B(3,48,1,minecraft:soul_sand)
B(3,49,1,minecraft:soul_sand)
B(3,50,1,minecraft:soul_sand)
B(3,45,2,minecraft:soul_sand)
B(3,46,2,minecraft:soul_sand)
B(3,47,2,minecraft:soul_sand)
B(3,48,2,minecraft:soul_sand)
B(3,49,2,minecraft:soul_sand)
B(3,50,2,minecraft:soul_sand)
B(3,44,3,minecraft:soul_sand)
B(3,45,3,minecraft:soul_sand)
B(3,46,3,minecraft:soul_sand)
B(3,47,3,minecraft:soul_sand)
B(3,48,3,minecraft:soul_sand)
B(3,49,3,minecraft:soul_sand)
B(3,50,3,minecraft:soul_sand)
B(3,44,4,minecraft:soul_sand)
B(3,45,4,minecraft:soul_sand)
B(3,46,4,minecraft:soul_sand)
B(3,47,4,minecraft:soul_sand)
B(3,48,4,minecraft:soul_sand)
B(3,49,4,minecraft:soul_sand)
B(3,50,4,minecraft:soul_sand)
B(3,44,5,minecraft:soul_sand)
B(3,45,5,minecraft:soul_sand)
B(3,46,5,minecraft:soul_sand)
B(3,47,5,minecraft:soul_sand)
B(3,48,5,minecraft:soul_sand)
B(3,49,5,minecraft:soul_sand)
B(3,50,5,minecraft:soul_sand)
B(3,45,6,minecraft:soul_sand)
B(3,46,6,minecraft:soul_sand)
B(3,47,6,minecraft:soul_sand)
B(3,48,6,minecraft:soul_sand)
B(3,49,6,minecraft:soul_sand)
B(3,50,6,minecraft:soul_sand)
B(3,45,7,minecraft:soul_sand)
B(3,46,7,minecraft:soul_sand)
B(3,47,7,minecraft:soul_sand)
B(3,48,7,minecraft:soul_sand)
B(3,49,7,minecraft:soul_sand)
B(3,50,7,minecraft:soul_sand)
B(3,45,8,minecraft:soul_sand)
B(3,46,8,minecraft:soul_sand)
B(3,47,8,minecraft:soul_sand)
B(3,48,8,minecraft:soul_sand)
B(3,49,8,minecraft:soul_sand)
B(3,50,8,minecraft:soul_sand)
B(4,48,-7,minecraft:soul_sand)
B(4,49,-7,minecraft:soul_sand)
B(4,50,-7,minecraft:soul_sand)
B(4,48,-6,minecraft:soul_sand)
B(4,49,-6,minecraft:soul_sand)
B(4,50,-6,minecraft:soul_sand)
B(4,49,-5,minecraft:soul_sand)
B(4,50,-5,minecraft:soul_sand)
B(4,49,-4,minecraft:soul_sand)
B(4,50,-4,minecraft:soul_sand)
B(4,49,-3,minecraft:soul_sand)
B(4,50,-3,minecraft:soul_sand)
B(4,49,-2,minecraft:soul_sand)
B(4,50,-2,minecraft:soul_sand)
B(4,48,-1,minecraft:soul_sand)
B(4,49,-1,minecraft:soul_sand)
B(4,50,-1,minecraft:soul_sand)
B(4,48,0,minecraft:soul_sand)
B(4,49,0,minecraft:soul_sand)
B(4,50,0,minecraft:soul_sand)
B(4,47,1,minecraft:soul_sand)
B(4,48,1,minecraft:soul_sand)
B(4,49,1,minecraft:soul_sand)
B(4,50,1,minecraft:soul_sand)
B(4,46,2,minecraft:soul_sand)
B(4,47,2,minecraft:soul_sand)
B(4,48,2,minecraft:soul_sand)
B(4,49,2,minecraft:soul_sand)
B(4,50,2,minecraft:soul_sand)
B(4,45,3,minecraft:soul_sand)
B(4,46,3,minecraft:soul_sand)
B(4,47,3,minecraft:soul_sand)
B(4,48,3,minecraft:soul_sand)
B(4,49,3,minecraft:soul_sand)
B(4,50,3,minecraft:soul_sand)
B(4,45,4,minecraft:soul_sand)
B(4,46,4,minecraft:soul_sand)
B(4,47,4,minecraft:soul_sand)
B(4,48,4,minecraft:soul_sand)
B(4,49,4,minecraft:soul_sand)
B(4,50,4,minecraft:soul_sand)
B(4,45,5,minecraft:soul_sand)
B(4,46,5,minecraft:soul_sand)
B(4,47,5,minecraft:soul_sand)
B(4,48,5,minecraft:soul_sand)
B(4,49,5,minecraft:soul_sand)
B(4,50,5,minecraft:soul_sand)
B(4,45,6,minecraft:soul_sand)
B(4,46,6,minecraft:soul_sand)
B(4,47,6,minecraft:soul_sand)
B(4,48,6,minecraft:soul_sand)
B(4,49,6,minecraft:soul_sand)
B(4,50,6,minecraft:soul_sand)
B(4,45,7,minecraft:soul_sand)
B(4,46,7,minecraft:soul_sand)
B(4,47,7,minecraft:soul_sand)
B(4,48,7,minecraft:soul_sand)
B(4,49,7,minecraft:soul_sand)
B(4,50,7,minecraft:soul_sand)
B(4,45,8,minecraft:soul_sand)
B(4,46,8,minecraft:soul_sand)
B(4,47,8,minecraft:soul_sand)
B(4,48,8,minecraft:soul_sand)
B(4,49,8,minecraft:soul_sand)
B(4,50,8,minecraft:soul_sand)
B(5,49,-7,minecraft:soul_sand)
B(5,50,-7,minecraft:soul_sand)
B(5,49,-6,minecraft:soul_sand)
B(5,50,-6,minecraft:soul_sand)
B(5,49,-5,minecraft:soul_sand)
B(5,50,-5,minecraft:soul_sand)
B(5,49,-4,minecraft:soul_sand)
B(5,50,-4,minecraft:soul_sand)
B(5,49,-3,minecraft:soul_sand)
B(5,50,-3,minecraft:soul_sand)
B(5,50,-2,minecraft:soul_sand)
B(5,49,-1,minecraft:soul_sand)
B(5,50,-1,minecraft:soul_sand)
B(5,48,0,minecraft:soul_sand)
B(5,49,0,minecraft:soul_sand)
B(5,50,0,minecraft:soul_sand)
B(5,48,1,minecraft:soul_sand)
B(5,49,1,minecraft:soul_sand)
B(5,50,1,minecraft:soul_sand)
B(5,47,2,minecraft:soul_sand)
B(5,48,2,minecraft:soul_sand)
B(5,49,2,minecraft:soul_sand)
B(5,50,2,minecraft:soul_sand)
B(5,46,3,minecraft:soul_sand)
B(5,47,3,minecraft:soul_sand)
B(5,48,3,minecraft:soul_sand)
B(5,49,3,minecraft:soul_sand)
B(5,50,3,minecraft:soul_sand)
B(5,45,4,minecraft:soul_sand)
B(5,46,4,minecraft:soul_sand)
B(5,47,4,minecraft:soul_sand)
B(5,48,4,minecraft:soul_sand)
B(5,49,4,minecraft:soul_sand)
B(5,50,4,minecraft:soul_sand)
B(5,45,5,minecraft:soul_sand)
B(5,46,5,minecraft:soul_sand)
B(5,47,5,minecraft:soul_sand)
B(5,48,5,minecraft:soul_sand)
B(5,49,5,minecraft:soul_sand)
B(5,50,5,minecraft:soul_sand)
B(5,45,6,minecraft:soul_sand)
B(5,46,6,minecraft:soul_sand)
B(5,47,6,minecraft:soul_sand)
B(5,48,6,minecraft:soul_sand)
B(5,49,6,minecraft:soul_sand)
B(5,50,6,minecraft:soul_sand)
B(5,45,7,minecraft:soul_sand)
B(5,46,7,minecraft:soul_sand)
B(5,47,7,minecraft:soul_sand)
B(5,48,7,minecraft:soul_sand)
B(5,49,7,minecraft:soul_sand)
B(5,50,7,minecraft:soul_sand)
B(5,45,8,minecraft:soul_sand)
B(5,46,8,minecraft:soul_sand)
B(5,47,8,minecraft:soul_sand)
B(5,48,8,minecraft:soul_sand)
B(5,49,8,minecraft:soul_sand)
B(5,50,8,minecraft:soul_sand)
B(6,50,-7,minecraft:soul_sand)
B(6,50,-6,minecraft:soul_sand)
B(6,50,-5,minecraft:soul_sand)
B(6,50,-4,minecraft:soul_sand)
B(6,50,-3,minecraft:soul_sand)
B(6,50,-2,minecraft:soul_sand)
B(6,50,-1,minecraft:soul_sand)
B(6,49,0,minecraft:soul_sand)
B(6,50,0,minecraft:soul_sand)
B(6,48,1,minecraft:soul_sand)
B(6,49,1,minecraft:soul_sand)
B(6,50,1,minecraft:soul_sand)
B(6,47,2,minecraft:soul_sand)
B(6,48,2,minecraft:soul_sand)
B(6,49,2,minecraft:soul_sand)
B(6,50,2,minecraft:soul_sand)
B(6,47,3,minecraft:soul_sand)
B(6,48,3,minecraft:soul_sand)
B(6,49,3,minecraft:soul_sand)
B(6,50,3,minecraft:soul_sand)
B(6,46,4,minecraft:soul_sand)
B(6,47,4,minecraft:soul_sand)
B(6,48,4,minecraft:soul_sand)
B(6,49,4,minecraft:soul_sand)
B(6,50,4,minecraft:soul_sand)
B(6,46,5,minecraft:soul_sand)
B(6,47,5,minecraft:soul_sand)
B(6,48,5,minecraft:soul_sand)
B(6,49,5,minecraft:soul_sand)
B(6,50,5,minecraft:soul_sand)
B(6,45,6,minecraft:soul_sand)
B(6,46,6,minecraft:soul_sand)
B(6,47,6,minecraft:soul_sand)
B(6,48,6,minecraft:soul_sand)
B(6,49,6,minecraft:soul_sand)
B(6,50,6,minecraft:soul_sand)
B(6,45,7,minecraft:soul_sand)
B(6,46,7,minecraft:soul_sand)
B(6,47,7,minecraft:soul_sand)
B(6,48,7,minecraft:soul_sand)
B(6,49,7,minecraft:soul_sand)
B(6,50,7,minecraft:soul_sand)
B(6,46,8,minecraft:soul_sand)
B(6,47,8,minecraft:soul_sand)
B(6,48,8,minecraft:soul_sand)
B(6,49,8,minecraft:soul_sand)
B(6,50,8,minecraft:soul_sand)
B(7,50,-6,minecraft:soul_sand)
B(7,50,-5,minecraft:soul_sand)
B(7,50,-4,minecraft:soul_sand)
B(7,50,-3,minecraft:soul_sand)
B(7,50,-1,minecraft:soul_sand)
B(7,50,0,minecraft:soul_sand)
B(7,49,1,minecraft:soul_sand)
B(7,50,1,minecraft:soul_sand)
B(7,48,2,minecraft:soul_sand)
B(7,49,2,minecraft:soul_sand)
B(7,50,2,minecraft:soul_sand)
B(7,47,3,minecraft:soul_sand)
B(7,48,3,minecraft:soul_sand)
B(7,49,3,minecraft:soul_sand)
B(7,50,3,minecraft:soul_sand)
B(7,47,4,minecraft:soul_sand)
B(7,48,4,minecraft:soul_sand)
B(7,49,4,minecraft:soul_sand)
B(7,50,4,minecraft:soul_sand)
B(7,46,5,minecraft:soul_sand)
B(7,47,5,minecraft:soul_sand)
B(7,48,5,minecraft:soul_sand)
B(7,49,5,minecraft:soul_sand)
B(7,50,5,minecraft:soul_sand)
B(7,46,6,minecraft:soul_sand)
B(7,47,6,minecraft:soul_sand)
B(7,48,6,minecraft:soul_sand)
B(7,49,6,minecraft:soul_sand)
B(7,50,6,minecraft:soul_sand)
B(7,46,7,minecraft:soul_sand)
B(7,47,7,minecraft:soul_sand)
B(7,48,7,minecraft:soul_sand)
B(7,49,7,minecraft:soul_sand)
B(7,50,7,minecraft:soul_sand)
B(7,46,8,minecraft:soul_sand)
B(7,47,8,minecraft:soul_sand)
B(7,48,8,minecraft:soul_sand)
B(7,49,8,minecraft:soul_sand)
B(7,50,8,minecraft:soul_sand)

#######################################################################
# +-----------------------------------------------------------------+ #
# |                             Branches                            | #
# +-----------------------------------------------------------------+ #
#######################################################################

Branch(16,0,0,true,GiantSoulSandStalactite1_C3_R1,NORTH,100.0,0)

#######################################################################
# +-----------------------------------------------------------------+ #
# |                             Entities                            | #
# +-----------------------------------------------------------------+ #
#######################################################################

