
#######################################################################
# +-----------------------------------------------------------------+ #
# |                            BO4 object                           | #
# +-----------------------------------------------------------------+ #
#######################################################################

Author: Unknown

Description: No description given

SettingsMode: WriteWithoutComments


#######################################################################
# +-----------------------------------------------------------------+ #
# |                          Main settings                          | #
# +-----------------------------------------------------------------+ #
#######################################################################

FixedRotation: 

Frequency: 0

SpawnHeight: highestBlock

UseCenterForHighestBlock: true

##############################
# Height Limits for the BO4. #
##############################

MinHeight: 0

MaxHeight: 255

InheritBO3: 

InheritBO3Rotation: NORTH

OverrideChildSettings: true

OverrideParentHeight: false

CanOverride: false

BranchFrequency: 0

BranchFrequencyGroup: 

MustBeBelowOther: false

MustBeInside: 

CannotBeInside: 

ReplacesBO3: 

MustBeInsideWorldBorders: false

CanSpawnOnWater: true

SpawnOnWaterOnly: false

SpawnUnderWater: false

SpawnAtWaterLevel: false

HeightOffset: 0

RemoveAir: true

ReplaceAbove: 

ReplaceBelow: 

ReplaceWithBiomeBlocks: true

ReplaceWithSurfaceBlock: GRASS

ReplaceWithGroundBlock: DIRT

ReplaceWithStoneBlock: STONE

SmoothRadius: 0

SmoothHeightOffset: 0

SmoothStartTop: false

SmoothStartWood: false

SmoothingSurfaceBlock: 

SmoothingGroundBlock: 

BO3Group: 

IsSpawnPoint: false

DoReplaceBlocks: true


#######################################################################
# +-----------------------------------------------------------------+ #
# |                              Blocks                             | #
# +-----------------------------------------------------------------+ #
#######################################################################

B(-8,44,-7,minecraft:soul_sand)
B(-8,45,-7,minecraft:soul_sand)
B(-8,46,-7,minecraft:soul_sand)
B(-8,47,-7,minecraft:soul_sand)
B(-8,48,-7,minecraft:soul_sand)
B(-8,49,-7,minecraft:soul_sand)
B(-8,50,-7,minecraft:soul_sand)
B(-8,43,-6,minecraft:soul_sand)
B(-8,44,-6,minecraft:soul_sand)
B(-8,45,-6,minecraft:soul_sand)
B(-8,46,-6,minecraft:soul_sand)
B(-8,47,-6,minecraft:soul_sand)
B(-8,48,-6,minecraft:soul_sand)
B(-8,49,-6,minecraft:soul_sand)
B(-8,50,-6,minecraft:soul_sand)
B(-8,38,-5,minecraft:soul_sand)
B(-8,39,-5,minecraft:soul_sand)
B(-8,40,-5,minecraft:soul_sand)
B(-8,41,-5,minecraft:soul_sand)
B(-8,42,-5,minecraft:soul_sand)
B(-8,43,-5,minecraft:soul_sand)
B(-8,44,-5,minecraft:soul_sand)
B(-8,45,-5,minecraft:soul_sand)
B(-8,46,-5,minecraft:soul_sand)
B(-8,47,-5,minecraft:soul_sand)
B(-8,48,-5,minecraft:soul_sand)
B(-8,49,-5,minecraft:soul_sand)
B(-8,50,-5,minecraft:soul_sand)
B(-8,36,-4,minecraft:soul_sand)
B(-8,37,-4,minecraft:soul_sand)
B(-8,38,-4,minecraft:soul_sand)
B(-8,39,-4,minecraft:soul_sand)
B(-8,40,-4,minecraft:soul_sand)
B(-8,41,-4,minecraft:soul_sand)
B(-8,42,-4,minecraft:soul_sand)
B(-8,43,-4,minecraft:soul_sand)
B(-8,44,-4,minecraft:soul_sand)
B(-8,45,-4,minecraft:soul_sand)
B(-8,46,-4,minecraft:soul_sand)
B(-8,47,-4,minecraft:soul_sand)
B(-8,48,-4,minecraft:soul_sand)
B(-8,49,-4,minecraft:soul_sand)
B(-8,50,-4,minecraft:soul_sand)
B(-8,36,-3,minecraft:soul_sand)
B(-8,37,-3,minecraft:soul_sand)
B(-8,38,-3,minecraft:soul_sand)
B(-8,39,-3,minecraft:soul_sand)
B(-8,40,-3,minecraft:soul_sand)
B(-8,41,-3,minecraft:soul_sand)
B(-8,42,-3,minecraft:soul_sand)
B(-8,43,-3,minecraft:soul_sand)
B(-8,44,-3,minecraft:soul_sand)
B(-8,45,-3,minecraft:soul_sand)
B(-8,46,-3,minecraft:soul_sand)
B(-8,47,-3,minecraft:soul_sand)
B(-8,48,-3,minecraft:soul_sand)
B(-8,49,-3,minecraft:soul_sand)
B(-8,50,-3,minecraft:soul_sand)
B(-8,36,-2,minecraft:soul_sand)
B(-8,37,-2,minecraft:soul_sand)
B(-8,38,-2,minecraft:soul_sand)
B(-8,39,-2,minecraft:soul_sand)
B(-8,40,-2,minecraft:soul_sand)
B(-8,41,-2,minecraft:soul_sand)
B(-8,42,-2,minecraft:soul_sand)
B(-8,43,-2,minecraft:soul_sand)
B(-8,44,-2,minecraft:soul_sand)
B(-8,45,-2,minecraft:soul_sand)
B(-8,46,-2,minecraft:soul_sand)
B(-8,47,-2,minecraft:soul_sand)
B(-8,48,-2,minecraft:soul_sand)
B(-8,49,-2,minecraft:soul_sand)
B(-8,50,-2,minecraft:soul_sand)
B(-8,34,-1,minecraft:soul_sand)
B(-8,35,-1,minecraft:soul_sand)
B(-8,36,-1,minecraft:soul_sand)
B(-8,37,-1,minecraft:soul_sand)
B(-8,38,-1,minecraft:soul_sand)
B(-8,39,-1,minecraft:soul_sand)
B(-8,40,-1,minecraft:soul_sand)
B(-8,41,-1,minecraft:soul_sand)
B(-8,42,-1,minecraft:soul_sand)
B(-8,43,-1,minecraft:soul_sand)
B(-8,44,-1,minecraft:soul_sand)
B(-8,45,-1,minecraft:soul_sand)
B(-8,46,-1,minecraft:soul_sand)
B(-8,47,-1,minecraft:soul_sand)
B(-8,48,-1,minecraft:soul_sand)
B(-8,49,-1,minecraft:soul_sand)
B(-8,50,-1,minecraft:soul_sand)
B(-8,33,0,minecraft:soul_sand)
B(-8,34,0,minecraft:soul_sand)
B(-8,35,0,minecraft:soul_sand)
B(-8,36,0,minecraft:soul_sand)
B(-8,37,0,minecraft:soul_sand)
B(-8,38,0,minecraft:soul_sand)
B(-8,39,0,minecraft:soul_sand)
B(-8,40,0,minecraft:soul_sand)
B(-8,41,0,minecraft:soul_sand)
B(-8,42,0,minecraft:soul_sand)
B(-8,43,0,minecraft:soul_sand)
B(-8,44,0,minecraft:soul_sand)
B(-8,45,0,minecraft:soul_sand)
B(-8,46,0,minecraft:soul_sand)
B(-8,47,0,minecraft:soul_sand)
B(-8,48,0,minecraft:soul_sand)
B(-8,49,0,minecraft:soul_sand)
B(-8,50,0,minecraft:soul_sand)
B(-8,33,1,minecraft:soul_sand)
B(-8,34,1,minecraft:soul_sand)
B(-8,35,1,minecraft:soul_sand)
B(-8,36,1,minecraft:soul_sand)
B(-8,37,1,minecraft:soul_sand)
B(-8,38,1,minecraft:soul_sand)
B(-8,39,1,minecraft:soul_sand)
B(-8,40,1,minecraft:soul_sand)
B(-8,41,1,minecraft:soul_sand)
B(-8,42,1,minecraft:soul_sand)
B(-8,43,1,minecraft:soul_sand)
B(-8,44,1,minecraft:soul_sand)
B(-8,45,1,minecraft:soul_sand)
B(-8,46,1,minecraft:soul_sand)
B(-8,47,1,minecraft:soul_sand)
B(-8,48,1,minecraft:soul_sand)
B(-8,49,1,minecraft:soul_sand)
B(-8,50,1,minecraft:soul_sand)
B(-8,33,2,minecraft:soul_sand)
B(-8,34,2,minecraft:soul_sand)
B(-8,35,2,minecraft:soul_sand)
B(-8,36,2,minecraft:soul_sand)
B(-8,37,2,minecraft:soul_sand)
B(-8,38,2,minecraft:soul_sand)
B(-8,39,2,minecraft:soul_sand)
B(-8,40,2,minecraft:soul_sand)
B(-8,41,2,minecraft:soul_sand)
B(-8,42,2,minecraft:soul_sand)
B(-8,43,2,minecraft:soul_sand)
B(-8,44,2,minecraft:soul_sand)
B(-8,45,2,minecraft:soul_sand)
B(-8,46,2,minecraft:soul_sand)
B(-8,47,2,minecraft:soul_sand)
B(-8,48,2,minecraft:soul_sand)
B(-8,49,2,minecraft:soul_sand)
B(-8,50,2,minecraft:soul_sand)
B(-8,33,3,minecraft:soul_sand)
B(-8,34,3,minecraft:soul_sand)
B(-8,35,3,minecraft:soul_sand)
B(-8,36,3,minecraft:soul_sand)
B(-8,37,3,minecraft:soul_sand)
B(-8,38,3,minecraft:soul_sand)
B(-8,39,3,minecraft:soul_sand)
B(-8,40,3,minecraft:soul_sand)
B(-8,41,3,minecraft:soul_sand)
B(-8,42,3,minecraft:soul_sand)
B(-8,43,3,minecraft:soul_sand)
B(-8,44,3,minecraft:soul_sand)
B(-8,45,3,minecraft:soul_sand)
B(-8,46,3,minecraft:soul_sand)
B(-8,47,3,minecraft:soul_sand)
B(-8,48,3,minecraft:soul_sand)
B(-8,49,3,minecraft:soul_sand)
B(-8,50,3,minecraft:soul_sand)
B(-8,34,4,minecraft:soul_sand)
B(-8,35,4,minecraft:soul_sand)
B(-8,36,4,minecraft:soul_sand)
B(-8,37,4,minecraft:soul_sand)
B(-8,38,4,minecraft:soul_sand)
B(-8,39,4,minecraft:soul_sand)
B(-8,40,4,minecraft:soul_sand)
B(-8,41,4,minecraft:soul_sand)
B(-8,42,4,minecraft:soul_sand)
B(-8,43,4,minecraft:soul_sand)
B(-8,44,4,minecraft:soul_sand)
B(-8,45,4,minecraft:soul_sand)
B(-8,46,4,minecraft:soul_sand)
B(-8,47,4,minecraft:soul_sand)
B(-8,48,4,minecraft:soul_sand)
B(-8,49,4,minecraft:soul_sand)
B(-8,50,4,minecraft:soul_sand)
B(-8,34,5,minecraft:soul_sand)
B(-8,35,5,minecraft:soul_sand)
B(-8,36,5,minecraft:soul_sand)
B(-8,37,5,minecraft:soul_sand)
B(-8,38,5,minecraft:soul_sand)
B(-8,39,5,minecraft:soul_sand)
B(-8,40,5,minecraft:soul_sand)
B(-8,41,5,minecraft:soul_sand)
B(-8,42,5,minecraft:soul_sand)
B(-8,43,5,minecraft:soul_sand)
B(-8,44,5,minecraft:soul_sand)
B(-8,45,5,minecraft:soul_sand)
B(-8,46,5,minecraft:soul_sand)
B(-8,47,5,minecraft:soul_sand)
B(-8,48,5,minecraft:soul_sand)
B(-8,49,5,minecraft:soul_sand)
B(-8,50,5,minecraft:soul_sand)
B(-8,35,6,minecraft:soul_sand)
B(-8,36,6,minecraft:soul_sand)
B(-8,37,6,minecraft:soul_sand)
B(-8,38,6,minecraft:soul_sand)
B(-8,39,6,minecraft:soul_sand)
B(-8,40,6,minecraft:soul_sand)
B(-8,41,6,minecraft:soul_sand)
B(-8,42,6,minecraft:soul_sand)
B(-8,43,6,minecraft:soul_sand)
B(-8,44,6,minecraft:soul_sand)
B(-8,45,6,minecraft:soul_sand)
B(-8,46,6,minecraft:soul_sand)
B(-8,47,6,minecraft:soul_sand)
B(-8,48,6,minecraft:soul_sand)
B(-8,49,6,minecraft:soul_sand)
B(-8,50,6,minecraft:soul_sand)
B(-8,35,7,minecraft:soul_sand)
B(-8,36,7,minecraft:soul_sand)
B(-8,37,7,minecraft:soul_sand)
B(-8,38,7,minecraft:soul_sand)
B(-8,39,7,minecraft:soul_sand)
B(-8,40,7,minecraft:soul_sand)
B(-8,41,7,minecraft:soul_sand)
B(-8,42,7,minecraft:soul_sand)
B(-8,43,7,minecraft:soul_sand)
B(-8,44,7,minecraft:soul_sand)
B(-8,45,7,minecraft:soul_sand)
B(-8,46,7,minecraft:soul_sand)
B(-8,47,7,minecraft:soul_sand)
B(-8,48,7,minecraft:soul_sand)
B(-8,49,7,minecraft:soul_sand)
B(-8,50,7,minecraft:soul_sand)
B(-8,35,8,minecraft:soul_sand)
B(-8,36,8,minecraft:soul_sand)
B(-8,37,8,minecraft:soul_sand)
B(-8,38,8,minecraft:soul_sand)
B(-8,39,8,minecraft:soul_sand)
B(-8,40,8,minecraft:soul_sand)
B(-8,41,8,minecraft:soul_sand)
B(-8,42,8,minecraft:soul_sand)
B(-8,43,8,minecraft:soul_sand)
B(-8,44,8,minecraft:soul_sand)
B(-8,45,8,minecraft:soul_sand)
B(-8,46,8,minecraft:soul_sand)
B(-8,47,8,minecraft:soul_sand)
B(-8,48,8,minecraft:soul_sand)
B(-8,49,8,minecraft:soul_sand)
B(-8,50,8,minecraft:soul_sand)
B(-7,42,-7,minecraft:soul_sand)
B(-7,43,-7,minecraft:soul_sand)
B(-7,44,-7,minecraft:soul_sand)
B(-7,45,-7,minecraft:soul_sand)
B(-7,46,-7,minecraft:soul_sand)
B(-7,47,-7,minecraft:soul_sand)
B(-7,48,-7,minecraft:soul_sand)
B(-7,49,-7,minecraft:soul_sand)
B(-7,50,-7,minecraft:soul_sand)
B(-7,39,-6,minecraft:soul_sand)
B(-7,40,-6,minecraft:soul_sand)
B(-7,41,-6,minecraft:soul_sand)
B(-7,42,-6,minecraft:soul_sand)
B(-7,43,-6,minecraft:soul_sand)
B(-7,44,-6,minecraft:soul_sand)
B(-7,45,-6,minecraft:soul_sand)
B(-7,46,-6,minecraft:soul_sand)
B(-7,47,-6,minecraft:soul_sand)
B(-7,48,-6,minecraft:soul_sand)
B(-7,49,-6,minecraft:soul_sand)
B(-7,50,-6,minecraft:soul_sand)
B(-7,37,-5,minecraft:soul_sand)
B(-7,38,-5,minecraft:soul_sand)
B(-7,39,-5,minecraft:soul_sand)
B(-7,40,-5,minecraft:soul_sand)
B(-7,41,-5,minecraft:soul_sand)
B(-7,42,-5,minecraft:soul_sand)
B(-7,43,-5,minecraft:soul_sand)
B(-7,44,-5,minecraft:soul_sand)
B(-7,45,-5,minecraft:soul_sand)
B(-7,46,-5,minecraft:soul_sand)
B(-7,47,-5,minecraft:soul_sand)
B(-7,48,-5,minecraft:soul_sand)
B(-7,49,-5,minecraft:soul_sand)
B(-7,50,-5,minecraft:soul_sand)
B(-7,35,-4,minecraft:soul_sand)
B(-7,36,-4,minecraft:soul_sand)
B(-7,37,-4,minecraft:soul_sand)
B(-7,38,-4,minecraft:soul_sand)
B(-7,39,-4,minecraft:soul_sand)
B(-7,40,-4,minecraft:soul_sand)
B(-7,41,-4,minecraft:soul_sand)
B(-7,42,-4,minecraft:soul_sand)
B(-7,43,-4,minecraft:soul_sand)
B(-7,44,-4,minecraft:soul_sand)
B(-7,45,-4,minecraft:soul_sand)
B(-7,46,-4,minecraft:soul_sand)
B(-7,47,-4,minecraft:soul_sand)
B(-7,48,-4,minecraft:soul_sand)
B(-7,49,-4,minecraft:soul_sand)
B(-7,50,-4,minecraft:soul_sand)
B(-7,34,-3,minecraft:soul_sand)
B(-7,35,-3,minecraft:soul_sand)
B(-7,36,-3,minecraft:soul_sand)
B(-7,37,-3,minecraft:soul_sand)
B(-7,38,-3,minecraft:soul_sand)
B(-7,39,-3,minecraft:soul_sand)
B(-7,40,-3,minecraft:soul_sand)
B(-7,41,-3,minecraft:soul_sand)
B(-7,42,-3,minecraft:soul_sand)
B(-7,43,-3,minecraft:soul_sand)
B(-7,44,-3,minecraft:soul_sand)
B(-7,45,-3,minecraft:soul_sand)
B(-7,46,-3,minecraft:soul_sand)
B(-7,47,-3,minecraft:soul_sand)
B(-7,48,-3,minecraft:soul_sand)
B(-7,49,-3,minecraft:soul_sand)
B(-7,50,-3,minecraft:soul_sand)
B(-7,33,-2,minecraft:soul_sand)
B(-7,34,-2,minecraft:soul_sand)
B(-7,35,-2,minecraft:soul_sand)
B(-7,36,-2,minecraft:soul_sand)
B(-7,37,-2,minecraft:soul_sand)
B(-7,38,-2,minecraft:soul_sand)
B(-7,39,-2,minecraft:soul_sand)
B(-7,40,-2,minecraft:soul_sand)
B(-7,41,-2,minecraft:soul_sand)
B(-7,42,-2,minecraft:soul_sand)
B(-7,43,-2,minecraft:soul_sand)
B(-7,44,-2,minecraft:soul_sand)
B(-7,45,-2,minecraft:soul_sand)
B(-7,46,-2,minecraft:soul_sand)
B(-7,47,-2,minecraft:soul_sand)
B(-7,48,-2,minecraft:soul_sand)
B(-7,49,-2,minecraft:soul_sand)
B(-7,50,-2,minecraft:soul_sand)
B(-7,33,-1,minecraft:soul_sand)
B(-7,34,-1,minecraft:soul_sand)
B(-7,35,-1,minecraft:soul_sand)
B(-7,36,-1,minecraft:soul_sand)
B(-7,37,-1,minecraft:soul_sand)
B(-7,38,-1,minecraft:soul_sand)
B(-7,39,-1,minecraft:soul_sand)
B(-7,40,-1,minecraft:soul_sand)
B(-7,41,-1,minecraft:soul_sand)
B(-7,42,-1,minecraft:soul_sand)
B(-7,43,-1,minecraft:soul_sand)
B(-7,44,-1,minecraft:soul_sand)
B(-7,45,-1,minecraft:soul_sand)
B(-7,46,-1,minecraft:soul_sand)
B(-7,47,-1,minecraft:soul_sand)
B(-7,48,-1,minecraft:soul_sand)
B(-7,49,-1,minecraft:soul_sand)
B(-7,50,-1,minecraft:soul_sand)
B(-7,32,0,minecraft:soul_sand)
B(-7,33,0,minecraft:soul_sand)
B(-7,34,0,minecraft:soul_sand)
B(-7,35,0,minecraft:soul_sand)
B(-7,36,0,minecraft:soul_sand)
B(-7,37,0,minecraft:soul_sand)
B(-7,38,0,minecraft:soul_sand)
B(-7,39,0,minecraft:soul_sand)
B(-7,40,0,minecraft:soul_sand)
B(-7,41,0,minecraft:soul_sand)
B(-7,42,0,minecraft:soul_sand)
B(-7,43,0,minecraft:soul_sand)
B(-7,44,0,minecraft:soul_sand)
B(-7,45,0,minecraft:soul_sand)
B(-7,46,0,minecraft:soul_sand)
B(-7,47,0,minecraft:soul_sand)
B(-7,48,0,minecraft:soul_sand)
B(-7,49,0,minecraft:soul_sand)
B(-7,50,0,minecraft:soul_sand)
B(-7,32,1,minecraft:soul_sand)
B(-7,33,1,minecraft:soul_sand)
B(-7,34,1,minecraft:soul_sand)
B(-7,35,1,minecraft:soul_sand)
B(-7,36,1,minecraft:soul_sand)
B(-7,37,1,minecraft:soul_sand)
B(-7,38,1,minecraft:soul_sand)
B(-7,39,1,minecraft:soul_sand)
B(-7,40,1,minecraft:soul_sand)
B(-7,41,1,minecraft:soul_sand)
B(-7,42,1,minecraft:soul_sand)
B(-7,43,1,minecraft:soul_sand)
B(-7,44,1,minecraft:soul_sand)
B(-7,45,1,minecraft:soul_sand)
B(-7,46,1,minecraft:soul_sand)
B(-7,47,1,minecraft:soul_sand)
B(-7,48,1,minecraft:soul_sand)
B(-7,49,1,minecraft:soul_sand)
B(-7,50,1,minecraft:soul_sand)
B(-7,31,2,minecraft:soul_sand)
B(-7,32,2,minecraft:soul_sand)
B(-7,33,2,minecraft:soul_sand)
B(-7,34,2,minecraft:soul_sand)
B(-7,35,2,minecraft:soul_sand)
B(-7,36,2,minecraft:soul_sand)
B(-7,37,2,minecraft:soul_sand)
B(-7,38,2,minecraft:soul_sand)
B(-7,39,2,minecraft:soul_sand)
B(-7,40,2,minecraft:soul_sand)
B(-7,41,2,minecraft:soul_sand)
B(-7,42,2,minecraft:soul_sand)
B(-7,43,2,minecraft:soul_sand)
B(-7,44,2,minecraft:soul_sand)
B(-7,45,2,minecraft:soul_sand)
B(-7,46,2,minecraft:soul_sand)
B(-7,47,2,minecraft:soul_sand)
B(-7,48,2,minecraft:soul_sand)
B(-7,49,2,minecraft:soul_sand)
B(-7,50,2,minecraft:soul_sand)
B(-7,28,3,minecraft:soul_sand)
B(-7,29,3,minecraft:soul_sand)
B(-7,30,3,minecraft:soul_sand)
B(-7,31,3,minecraft:soul_sand)
B(-7,32,3,minecraft:soul_sand)
B(-7,33,3,minecraft:soul_sand)
B(-7,34,3,minecraft:soul_sand)
B(-7,35,3,minecraft:soul_sand)
B(-7,36,3,minecraft:soul_sand)
B(-7,37,3,minecraft:soul_sand)
B(-7,38,3,minecraft:soul_sand)
B(-7,39,3,minecraft:soul_sand)
B(-7,40,3,minecraft:soul_sand)
B(-7,41,3,minecraft:soul_sand)
B(-7,42,3,minecraft:soul_sand)
B(-7,43,3,minecraft:soul_sand)
B(-7,44,3,minecraft:soul_sand)
B(-7,45,3,minecraft:soul_sand)
B(-7,46,3,minecraft:soul_sand)
B(-7,47,3,minecraft:soul_sand)
B(-7,48,3,minecraft:soul_sand)
B(-7,49,3,minecraft:soul_sand)
B(-7,50,3,minecraft:soul_sand)
B(-7,23,4,minecraft:soul_sand)
B(-7,24,4,minecraft:soul_sand)
B(-7,25,4,minecraft:soul_sand)
B(-7,26,4,minecraft:soul_sand)
B(-7,27,4,minecraft:soul_sand)
B(-7,28,4,minecraft:soul_sand)
B(-7,29,4,minecraft:soul_sand)
B(-7,30,4,minecraft:soul_sand)
B(-7,31,4,minecraft:soul_sand)
B(-7,32,4,minecraft:soul_sand)
B(-7,33,4,minecraft:soul_sand)
B(-7,34,4,minecraft:soul_sand)
B(-7,35,4,minecraft:soul_sand)
B(-7,36,4,minecraft:soul_sand)
B(-7,37,4,minecraft:soul_sand)
B(-7,38,4,minecraft:soul_sand)
B(-7,39,4,minecraft:soul_sand)
B(-7,40,4,minecraft:soul_sand)
B(-7,41,4,minecraft:soul_sand)
B(-7,42,4,minecraft:soul_sand)
B(-7,43,4,minecraft:soul_sand)
B(-7,44,4,minecraft:soul_sand)
B(-7,45,4,minecraft:soul_sand)
B(-7,46,4,minecraft:soul_sand)
B(-7,47,4,minecraft:soul_sand)
B(-7,48,4,minecraft:soul_sand)
B(-7,49,4,minecraft:soul_sand)
B(-7,50,4,minecraft:soul_sand)
B(-7,21,5,minecraft:soul_sand)
B(-7,22,5,minecraft:soul_sand)
B(-7,23,5,minecraft:soul_sand)
B(-7,24,5,minecraft:soul_sand)
B(-7,25,5,minecraft:soul_sand)
B(-7,26,5,minecraft:soul_sand)
B(-7,27,5,minecraft:soul_sand)
B(-7,28,5,minecraft:soul_sand)
B(-7,29,5,minecraft:soul_sand)
B(-7,30,5,minecraft:soul_sand)
B(-7,31,5,minecraft:soul_sand)
B(-7,32,5,minecraft:soul_sand)
B(-7,33,5,minecraft:soul_sand)
B(-7,34,5,minecraft:soul_sand)
B(-7,35,5,minecraft:soul_sand)
B(-7,36,5,minecraft:soul_sand)
B(-7,37,5,minecraft:soul_sand)
B(-7,38,5,minecraft:soul_sand)
B(-7,39,5,minecraft:soul_sand)
B(-7,40,5,minecraft:soul_sand)
B(-7,41,5,minecraft:soul_sand)
B(-7,42,5,minecraft:soul_sand)
B(-7,43,5,minecraft:soul_sand)
B(-7,44,5,minecraft:soul_sand)
B(-7,45,5,minecraft:soul_sand)
B(-7,46,5,minecraft:soul_sand)
B(-7,47,5,minecraft:soul_sand)
B(-7,48,5,minecraft:soul_sand)
B(-7,49,5,minecraft:soul_sand)
B(-7,50,5,minecraft:soul_sand)
B(-7,21,6,minecraft:soul_sand)
B(-7,22,6,minecraft:soul_sand)
B(-7,23,6,minecraft:soul_sand)
B(-7,24,6,minecraft:soul_sand)
B(-7,25,6,minecraft:soul_sand)
B(-7,26,6,minecraft:soul_sand)
B(-7,27,6,minecraft:soul_sand)
B(-7,28,6,minecraft:soul_sand)
B(-7,29,6,minecraft:soul_sand)
B(-7,30,6,minecraft:soul_sand)
B(-7,31,6,minecraft:soul_sand)
B(-7,32,6,minecraft:soul_sand)
B(-7,33,6,minecraft:soul_sand)
B(-7,34,6,minecraft:soul_sand)
B(-7,35,6,minecraft:soul_sand)
B(-7,36,6,minecraft:soul_sand)
B(-7,37,6,minecraft:soul_sand)
B(-7,38,6,minecraft:soul_sand)
B(-7,39,6,minecraft:soul_sand)
B(-7,40,6,minecraft:soul_sand)
B(-7,41,6,minecraft:soul_sand)
B(-7,42,6,minecraft:soul_sand)
B(-7,43,6,minecraft:soul_sand)
B(-7,44,6,minecraft:soul_sand)
B(-7,45,6,minecraft:soul_sand)
B(-7,46,6,minecraft:soul_sand)
B(-7,47,6,minecraft:soul_sand)
B(-7,48,6,minecraft:soul_sand)
B(-7,49,6,minecraft:soul_sand)
B(-7,50,6,minecraft:soul_sand)
B(-7,23,7,minecraft:soul_sand)
B(-7,24,7,minecraft:soul_sand)
B(-7,25,7,minecraft:soul_sand)
B(-7,26,7,minecraft:soul_sand)
B(-7,27,7,minecraft:soul_sand)
B(-7,28,7,minecraft:soul_sand)
B(-7,29,7,minecraft:soul_sand)
B(-7,30,7,minecraft:soul_sand)
B(-7,31,7,minecraft:soul_sand)
B(-7,32,7,minecraft:soul_sand)
B(-7,33,7,minecraft:soul_sand)
B(-7,34,7,minecraft:soul_sand)
B(-7,35,7,minecraft:soul_sand)
B(-7,36,7,minecraft:soul_sand)
B(-7,37,7,minecraft:soul_sand)
B(-7,38,7,minecraft:soul_sand)
B(-7,39,7,minecraft:soul_sand)
B(-7,40,7,minecraft:soul_sand)
B(-7,41,7,minecraft:soul_sand)
B(-7,42,7,minecraft:soul_sand)
B(-7,43,7,minecraft:soul_sand)
B(-7,44,7,minecraft:soul_sand)
B(-7,45,7,minecraft:soul_sand)
B(-7,46,7,minecraft:soul_sand)
B(-7,47,7,minecraft:soul_sand)
B(-7,48,7,minecraft:soul_sand)
B(-7,49,7,minecraft:soul_sand)
B(-7,50,7,minecraft:soul_sand)
B(-7,29,8,minecraft:soul_sand)
B(-7,30,8,minecraft:soul_sand)
B(-7,31,8,minecraft:soul_sand)
B(-7,32,8,minecraft:soul_sand)
B(-7,33,8,minecraft:soul_sand)
B(-7,34,8,minecraft:soul_sand)
B(-7,35,8,minecraft:soul_sand)
B(-7,36,8,minecraft:soul_sand)
B(-7,37,8,minecraft:soul_sand)
B(-7,38,8,minecraft:soul_sand)
B(-7,39,8,minecraft:soul_sand)
B(-7,40,8,minecraft:soul_sand)
B(-7,41,8,minecraft:soul_sand)
B(-7,42,8,minecraft:soul_sand)
B(-7,43,8,minecraft:soul_sand)
B(-7,44,8,minecraft:soul_sand)
B(-7,45,8,minecraft:soul_sand)
B(-7,46,8,minecraft:soul_sand)
B(-7,47,8,minecraft:soul_sand)
B(-7,48,8,minecraft:soul_sand)
B(-7,49,8,minecraft:soul_sand)
B(-7,50,8,minecraft:soul_sand)
B(-6,41,-7,minecraft:soul_sand)
B(-6,42,-7,minecraft:soul_sand)
B(-6,43,-7,minecraft:soul_sand)
B(-6,44,-7,minecraft:soul_sand)
B(-6,45,-7,minecraft:soul_sand)
B(-6,46,-7,minecraft:soul_sand)
B(-6,47,-7,minecraft:soul_sand)
B(-6,48,-7,minecraft:soul_sand)
B(-6,49,-7,minecraft:soul_sand)
B(-6,50,-7,minecraft:soul_sand)
B(-6,39,-6,minecraft:soul_sand)
B(-6,40,-6,minecraft:soul_sand)
B(-6,41,-6,minecraft:soul_sand)
B(-6,42,-6,minecraft:soul_sand)
B(-6,43,-6,minecraft:soul_sand)
B(-6,44,-6,minecraft:soul_sand)
B(-6,45,-6,minecraft:soul_sand)
B(-6,46,-6,minecraft:soul_sand)
B(-6,47,-6,minecraft:soul_sand)
B(-6,48,-6,minecraft:soul_sand)
B(-6,49,-6,minecraft:soul_sand)
B(-6,50,-6,minecraft:soul_sand)
B(-6,36,-5,minecraft:soul_sand)
B(-6,37,-5,minecraft:soul_sand)
B(-6,38,-5,minecraft:soul_sand)
B(-6,39,-5,minecraft:soul_sand)
B(-6,40,-5,minecraft:soul_sand)
B(-6,41,-5,minecraft:soul_sand)
B(-6,42,-5,minecraft:soul_sand)
B(-6,43,-5,minecraft:soul_sand)
B(-6,44,-5,minecraft:soul_sand)
B(-6,45,-5,minecraft:soul_sand)
B(-6,46,-5,minecraft:soul_sand)
B(-6,47,-5,minecraft:soul_sand)
B(-6,48,-5,minecraft:soul_sand)
B(-6,49,-5,minecraft:soul_sand)
B(-6,50,-5,minecraft:soul_sand)
B(-6,34,-4,minecraft:soul_sand)
B(-6,35,-4,minecraft:soul_sand)
B(-6,36,-4,minecraft:soul_sand)
B(-6,37,-4,minecraft:soul_sand)
B(-6,38,-4,minecraft:soul_sand)
B(-6,39,-4,minecraft:soul_sand)
B(-6,40,-4,minecraft:soul_sand)
B(-6,41,-4,minecraft:soul_sand)
B(-6,42,-4,minecraft:soul_sand)
B(-6,43,-4,minecraft:soul_sand)
B(-6,44,-4,minecraft:soul_sand)
B(-6,45,-4,minecraft:soul_sand)
B(-6,46,-4,minecraft:soul_sand)
B(-6,47,-4,minecraft:soul_sand)
B(-6,48,-4,minecraft:soul_sand)
B(-6,49,-4,minecraft:soul_sand)
B(-6,50,-4,minecraft:soul_sand)
B(-6,33,-3,minecraft:soul_sand)
B(-6,34,-3,minecraft:soul_sand)
B(-6,35,-3,minecraft:soul_sand)
B(-6,36,-3,minecraft:soul_sand)
B(-6,37,-3,minecraft:soul_sand)
B(-6,38,-3,minecraft:soul_sand)
B(-6,39,-3,minecraft:soul_sand)
B(-6,40,-3,minecraft:soul_sand)
B(-6,41,-3,minecraft:soul_sand)
B(-6,42,-3,minecraft:soul_sand)
B(-6,43,-3,minecraft:soul_sand)
B(-6,44,-3,minecraft:soul_sand)
B(-6,45,-3,minecraft:soul_sand)
B(-6,46,-3,minecraft:soul_sand)
B(-6,47,-3,minecraft:soul_sand)
B(-6,48,-3,minecraft:soul_sand)
B(-6,49,-3,minecraft:soul_sand)
B(-6,50,-3,minecraft:soul_sand)
B(-6,32,-2,minecraft:soul_sand)
B(-6,33,-2,minecraft:soul_sand)
B(-6,34,-2,minecraft:soul_sand)
B(-6,35,-2,minecraft:soul_sand)
B(-6,36,-2,minecraft:soul_sand)
B(-6,37,-2,minecraft:soul_sand)
B(-6,38,-2,minecraft:soul_sand)
B(-6,39,-2,minecraft:soul_sand)
B(-6,40,-2,minecraft:soul_sand)
B(-6,41,-2,minecraft:soul_sand)
B(-6,42,-2,minecraft:soul_sand)
B(-6,43,-2,minecraft:soul_sand)
B(-6,44,-2,minecraft:soul_sand)
B(-6,45,-2,minecraft:soul_sand)
B(-6,46,-2,minecraft:soul_sand)
B(-6,47,-2,minecraft:soul_sand)
B(-6,48,-2,minecraft:soul_sand)
B(-6,49,-2,minecraft:soul_sand)
B(-6,50,-2,minecraft:soul_sand)
B(-6,28,-1,minecraft:soul_sand)
B(-6,29,-1,minecraft:soul_sand)
B(-6,30,-1,minecraft:soul_sand)
B(-6,31,-1,minecraft:soul_sand)
B(-6,32,-1,minecraft:soul_sand)
B(-6,33,-1,minecraft:soul_sand)
B(-6,34,-1,minecraft:soul_sand)
B(-6,35,-1,minecraft:soul_sand)
B(-6,36,-1,minecraft:soul_sand)
B(-6,37,-1,minecraft:soul_sand)
B(-6,38,-1,minecraft:soul_sand)
B(-6,39,-1,minecraft:soul_sand)
B(-6,40,-1,minecraft:soul_sand)
B(-6,41,-1,minecraft:soul_sand)
B(-6,42,-1,minecraft:soul_sand)
B(-6,43,-1,minecraft:soul_sand)
B(-6,44,-1,minecraft:soul_sand)
B(-6,45,-1,minecraft:soul_sand)
B(-6,46,-1,minecraft:soul_sand)
B(-6,47,-1,minecraft:soul_sand)
B(-6,48,-1,minecraft:soul_sand)
B(-6,49,-1,minecraft:soul_sand)
B(-6,50,-1,minecraft:soul_sand)
B(-6,27,0,minecraft:soul_sand)
B(-6,28,0,minecraft:soul_sand)
B(-6,29,0,minecraft:soul_sand)
B(-6,30,0,minecraft:soul_sand)
B(-6,31,0,minecraft:soul_sand)
B(-6,32,0,minecraft:soul_sand)
B(-6,33,0,minecraft:soul_sand)
B(-6,34,0,minecraft:soul_sand)
B(-6,35,0,minecraft:soul_sand)
B(-6,36,0,minecraft:soul_sand)
B(-6,37,0,minecraft:soul_sand)
B(-6,38,0,minecraft:soul_sand)
B(-6,39,0,minecraft:soul_sand)
B(-6,40,0,minecraft:soul_sand)
B(-6,41,0,minecraft:soul_sand)
B(-6,42,0,minecraft:soul_sand)
B(-6,43,0,minecraft:soul_sand)
B(-6,44,0,minecraft:soul_sand)
B(-6,45,0,minecraft:soul_sand)
B(-6,46,0,minecraft:soul_sand)
B(-6,47,0,minecraft:soul_sand)
B(-6,48,0,minecraft:soul_sand)
B(-6,49,0,minecraft:soul_sand)
B(-6,50,0,minecraft:soul_sand)
B(-6,26,1,minecraft:soul_sand)
B(-6,27,1,minecraft:soul_sand)
B(-6,28,1,minecraft:soul_sand)
B(-6,29,1,minecraft:soul_sand)
B(-6,30,1,minecraft:soul_sand)
B(-6,31,1,minecraft:soul_sand)
B(-6,32,1,minecraft:soul_sand)
B(-6,33,1,minecraft:soul_sand)
B(-6,34,1,minecraft:soul_sand)
B(-6,35,1,minecraft:soul_sand)
B(-6,36,1,minecraft:soul_sand)
B(-6,37,1,minecraft:soul_sand)
B(-6,38,1,minecraft:soul_sand)
B(-6,39,1,minecraft:soul_sand)
B(-6,40,1,minecraft:soul_sand)
B(-6,41,1,minecraft:soul_sand)
B(-6,42,1,minecraft:soul_sand)
B(-6,43,1,minecraft:soul_sand)
B(-6,44,1,minecraft:soul_sand)
B(-6,45,1,minecraft:soul_sand)
B(-6,46,1,minecraft:soul_sand)
B(-6,47,1,minecraft:soul_sand)
B(-6,48,1,minecraft:soul_sand)
B(-6,49,1,minecraft:soul_sand)
B(-6,50,1,minecraft:soul_sand)
B(-6,23,2,minecraft:soul_sand)
B(-6,24,2,minecraft:soul_sand)
B(-6,25,2,minecraft:soul_sand)
B(-6,26,2,minecraft:soul_sand)
B(-6,27,2,minecraft:soul_sand)
B(-6,28,2,minecraft:soul_sand)
B(-6,29,2,minecraft:soul_sand)
B(-6,30,2,minecraft:soul_sand)
B(-6,31,2,minecraft:soul_sand)
B(-6,32,2,minecraft:soul_sand)
B(-6,33,2,minecraft:soul_sand)
B(-6,34,2,minecraft:soul_sand)
B(-6,35,2,minecraft:soul_sand)
B(-6,36,2,minecraft:soul_sand)
B(-6,37,2,minecraft:soul_sand)
B(-6,38,2,minecraft:soul_sand)
B(-6,39,2,minecraft:soul_sand)
B(-6,40,2,minecraft:soul_sand)
B(-6,41,2,minecraft:soul_sand)
B(-6,42,2,minecraft:soul_sand)
B(-6,43,2,minecraft:soul_sand)
B(-6,44,2,minecraft:soul_sand)
B(-6,45,2,minecraft:soul_sand)
B(-6,46,2,minecraft:soul_sand)
B(-6,47,2,minecraft:soul_sand)
B(-6,48,2,minecraft:soul_sand)
B(-6,49,2,minecraft:soul_sand)
B(-6,50,2,minecraft:soul_sand)
B(-6,19,3,minecraft:soul_sand)
B(-6,20,3,minecraft:soul_sand)
B(-6,21,3,minecraft:soul_sand)
B(-6,22,3,minecraft:soul_sand)
B(-6,23,3,minecraft:soul_sand)
B(-6,24,3,minecraft:soul_sand)
B(-6,25,3,minecraft:soul_sand)
B(-6,26,3,minecraft:soul_sand)
B(-6,27,3,minecraft:soul_sand)
B(-6,28,3,minecraft:soul_sand)
B(-6,29,3,minecraft:soul_sand)
B(-6,30,3,minecraft:soul_sand)
B(-6,31,3,minecraft:soul_sand)
B(-6,32,3,minecraft:soul_sand)
B(-6,33,3,minecraft:soul_sand)
B(-6,34,3,minecraft:soul_sand)
B(-6,35,3,minecraft:soul_sand)
B(-6,36,3,minecraft:soul_sand)
B(-6,37,3,minecraft:soul_sand)
B(-6,38,3,minecraft:soul_sand)
B(-6,39,3,minecraft:soul_sand)
B(-6,40,3,minecraft:soul_sand)
B(-6,41,3,minecraft:soul_sand)
B(-6,42,3,minecraft:soul_sand)
B(-6,43,3,minecraft:soul_sand)
B(-6,44,3,minecraft:soul_sand)
B(-6,45,3,minecraft:soul_sand)
B(-6,46,3,minecraft:soul_sand)
B(-6,47,3,minecraft:soul_sand)
B(-6,48,3,minecraft:soul_sand)
B(-6,49,3,minecraft:soul_sand)
B(-6,50,3,minecraft:soul_sand)
B(-6,15,4,minecraft:soul_sand)
B(-6,16,4,minecraft:soul_sand)
B(-6,17,4,minecraft:soul_sand)
B(-6,18,4,minecraft:soul_sand)
B(-6,19,4,minecraft:soul_sand)
B(-6,20,4,minecraft:soul_sand)
B(-6,21,4,minecraft:soul_sand)
B(-6,22,4,minecraft:soul_sand)
B(-6,23,4,minecraft:soul_sand)
B(-6,24,4,minecraft:soul_sand)
B(-6,25,4,minecraft:soul_sand)
B(-6,26,4,minecraft:soul_sand)
B(-6,27,4,minecraft:soul_sand)
B(-6,28,4,minecraft:soul_sand)
B(-6,29,4,minecraft:soul_sand)
B(-6,30,4,minecraft:soul_sand)
B(-6,31,4,minecraft:soul_sand)
B(-6,32,4,minecraft:soul_sand)
B(-6,33,4,minecraft:soul_sand)
B(-6,34,4,minecraft:soul_sand)
B(-6,35,4,minecraft:soul_sand)
B(-6,36,4,minecraft:soul_sand)
B(-6,37,4,minecraft:soul_sand)
B(-6,38,4,minecraft:soul_sand)
B(-6,39,4,minecraft:soul_sand)
B(-6,40,4,minecraft:soul_sand)
B(-6,41,4,minecraft:soul_sand)
B(-6,42,4,minecraft:soul_sand)
B(-6,43,4,minecraft:soul_sand)
B(-6,44,4,minecraft:soul_sand)
B(-6,45,4,minecraft:soul_sand)
B(-6,46,4,minecraft:soul_sand)
B(-6,47,4,minecraft:soul_sand)
B(-6,48,4,minecraft:soul_sand)
B(-6,49,4,minecraft:soul_sand)
B(-6,50,4,minecraft:soul_sand)
B(-6,8,5,minecraft:soul_sand)
B(-6,9,5,minecraft:soul_sand)
B(-6,10,5,minecraft:soul_sand)
B(-6,11,5,minecraft:soul_sand)
B(-6,12,5,minecraft:soul_sand)
B(-6,13,5,minecraft:soul_sand)
B(-6,14,5,minecraft:soul_sand)
B(-6,15,5,minecraft:soul_sand)
B(-6,16,5,minecraft:soul_sand)
B(-6,17,5,minecraft:soul_sand)
B(-6,18,5,minecraft:soul_sand)
B(-6,19,5,minecraft:soul_sand)
B(-6,20,5,minecraft:soul_sand)
B(-6,21,5,minecraft:soul_sand)
B(-6,22,5,minecraft:soul_sand)
B(-6,23,5,minecraft:soul_sand)
B(-6,24,5,minecraft:soul_sand)
B(-6,25,5,minecraft:soul_sand)
B(-6,26,5,minecraft:soul_sand)
B(-6,27,5,minecraft:soul_sand)
B(-6,28,5,minecraft:soul_sand)
B(-6,29,5,minecraft:soul_sand)
B(-6,30,5,minecraft:soul_sand)
B(-6,31,5,minecraft:soul_sand)
B(-6,32,5,minecraft:soul_sand)
B(-6,33,5,minecraft:soul_sand)
B(-6,34,5,minecraft:soul_sand)
B(-6,35,5,minecraft:soul_sand)
B(-6,36,5,minecraft:soul_sand)
B(-6,37,5,minecraft:soul_sand)
B(-6,38,5,minecraft:soul_sand)
B(-6,39,5,minecraft:soul_sand)
B(-6,40,5,minecraft:soul_sand)
B(-6,41,5,minecraft:soul_sand)
B(-6,42,5,minecraft:soul_sand)
B(-6,43,5,minecraft:soul_sand)
B(-6,44,5,minecraft:soul_sand)
B(-6,45,5,minecraft:soul_sand)
B(-6,46,5,minecraft:soul_sand)
B(-6,47,5,minecraft:soul_sand)
B(-6,48,5,minecraft:soul_sand)
B(-6,49,5,minecraft:soul_sand)
B(-6,50,5,minecraft:soul_sand)
B(-6,8,6,minecraft:soul_sand)
B(-6,9,6,minecraft:soul_sand)
B(-6,10,6,minecraft:soul_sand)
B(-6,11,6,minecraft:soul_sand)
B(-6,12,6,minecraft:soul_sand)
B(-6,13,6,minecraft:soul_sand)
B(-6,14,6,minecraft:soul_sand)
B(-6,15,6,minecraft:soul_sand)
B(-6,16,6,minecraft:soul_sand)
B(-6,17,6,minecraft:soul_sand)
B(-6,18,6,minecraft:soul_sand)
B(-6,19,6,minecraft:soul_sand)
B(-6,20,6,minecraft:soul_sand)
B(-6,21,6,minecraft:soul_sand)
B(-6,22,6,minecraft:soul_sand)
B(-6,23,6,minecraft:soul_sand)
B(-6,24,6,minecraft:soul_sand)
B(-6,25,6,minecraft:soul_sand)
B(-6,26,6,minecraft:soul_sand)
B(-6,27,6,minecraft:soul_sand)
B(-6,28,6,minecraft:soul_sand)
B(-6,29,6,minecraft:soul_sand)
B(-6,30,6,minecraft:soul_sand)
B(-6,31,6,minecraft:soul_sand)
B(-6,32,6,minecraft:soul_sand)
B(-6,33,6,minecraft:soul_sand)
B(-6,34,6,minecraft:soul_sand)
B(-6,35,6,minecraft:soul_sand)
B(-6,36,6,minecraft:soul_sand)
B(-6,37,6,minecraft:soul_sand)
B(-6,38,6,minecraft:soul_sand)
B(-6,39,6,minecraft:soul_sand)
B(-6,40,6,minecraft:soul_sand)
B(-6,41,6,minecraft:soul_sand)
B(-6,42,6,minecraft:soul_sand)
B(-6,43,6,minecraft:soul_sand)
B(-6,44,6,minecraft:soul_sand)
B(-6,45,6,minecraft:soul_sand)
B(-6,46,6,minecraft:soul_sand)
B(-6,47,6,minecraft:soul_sand)
B(-6,48,6,minecraft:soul_sand)
B(-6,49,6,minecraft:soul_sand)
B(-6,50,6,minecraft:soul_sand)
B(-6,9,7,minecraft:soul_sand)
B(-6,10,7,minecraft:soul_sand)
B(-6,11,7,minecraft:soul_sand)
B(-6,12,7,minecraft:soul_sand)
B(-6,13,7,minecraft:soul_sand)
B(-6,14,7,minecraft:soul_sand)
B(-6,15,7,minecraft:soul_sand)
B(-6,16,7,minecraft:soul_sand)
B(-6,17,7,minecraft:soul_sand)
B(-6,18,7,minecraft:soul_sand)
B(-6,19,7,minecraft:soul_sand)
B(-6,20,7,minecraft:soul_sand)
B(-6,21,7,minecraft:soul_sand)
B(-6,22,7,minecraft:soul_sand)
B(-6,23,7,minecraft:soul_sand)
B(-6,24,7,minecraft:soul_sand)
B(-6,25,7,minecraft:soul_sand)
B(-6,26,7,minecraft:soul_sand)
B(-6,27,7,minecraft:soul_sand)
B(-6,28,7,minecraft:soul_sand)
B(-6,29,7,minecraft:soul_sand)
B(-6,30,7,minecraft:soul_sand)
B(-6,31,7,minecraft:soul_sand)
B(-6,32,7,minecraft:soul_sand)
B(-6,33,7,minecraft:soul_sand)
B(-6,34,7,minecraft:soul_sand)
B(-6,35,7,minecraft:soul_sand)
B(-6,36,7,minecraft:soul_sand)
B(-6,37,7,minecraft:soul_sand)
B(-6,38,7,minecraft:soul_sand)
B(-6,39,7,minecraft:soul_sand)
B(-6,40,7,minecraft:soul_sand)
B(-6,41,7,minecraft:soul_sand)
B(-6,42,7,minecraft:soul_sand)
B(-6,43,7,minecraft:soul_sand)
B(-6,44,7,minecraft:soul_sand)
B(-6,45,7,minecraft:soul_sand)
B(-6,46,7,minecraft:soul_sand)
B(-6,47,7,minecraft:soul_sand)
B(-6,48,7,minecraft:soul_sand)
B(-6,49,7,minecraft:soul_sand)
B(-6,50,7,minecraft:soul_sand)
B(-6,10,8,minecraft:soul_sand)
B(-6,11,8,minecraft:soul_sand)
B(-6,12,8,minecraft:soul_sand)
B(-6,13,8,minecraft:soul_sand)
B(-6,14,8,minecraft:soul_sand)
B(-6,15,8,minecraft:soul_sand)
B(-6,16,8,minecraft:soul_sand)
B(-6,17,8,minecraft:soul_sand)
B(-6,18,8,minecraft:soul_sand)
B(-6,19,8,minecraft:soul_sand)
B(-6,20,8,minecraft:soul_sand)
B(-6,21,8,minecraft:soul_sand)
B(-6,22,8,minecraft:soul_sand)
B(-6,23,8,minecraft:soul_sand)
B(-6,24,8,minecraft:soul_sand)
B(-6,25,8,minecraft:soul_sand)
B(-6,26,8,minecraft:soul_sand)
B(-6,27,8,minecraft:soul_sand)
B(-6,28,8,minecraft:soul_sand)
B(-6,29,8,minecraft:soul_sand)
B(-6,30,8,minecraft:soul_sand)
B(-6,31,8,minecraft:soul_sand)
B(-6,32,8,minecraft:soul_sand)
B(-6,33,8,minecraft:soul_sand)
B(-6,34,8,minecraft:soul_sand)
B(-6,35,8,minecraft:soul_sand)
B(-6,36,8,minecraft:soul_sand)
B(-6,37,8,minecraft:soul_sand)
B(-6,38,8,minecraft:soul_sand)
B(-6,39,8,minecraft:soul_sand)
B(-6,40,8,minecraft:soul_sand)
B(-6,41,8,minecraft:soul_sand)
B(-6,42,8,minecraft:soul_sand)
B(-6,43,8,minecraft:soul_sand)
B(-6,44,8,minecraft:soul_sand)
B(-6,45,8,minecraft:soul_sand)
B(-6,46,8,minecraft:soul_sand)
B(-6,47,8,minecraft:soul_sand)
B(-6,48,8,minecraft:soul_sand)
B(-6,49,8,minecraft:soul_sand)
B(-6,50,8,minecraft:soul_sand)
B(-5,41,-7,minecraft:soul_sand)
B(-5,42,-7,minecraft:soul_sand)
B(-5,43,-7,minecraft:soul_sand)
B(-5,44,-7,minecraft:soul_sand)
B(-5,45,-7,minecraft:soul_sand)
B(-5,46,-7,minecraft:soul_sand)
B(-5,47,-7,minecraft:soul_sand)
B(-5,48,-7,minecraft:soul_sand)
B(-5,49,-7,minecraft:soul_sand)
B(-5,50,-7,minecraft:soul_sand)
B(-5,38,-6,minecraft:soul_sand)
B(-5,39,-6,minecraft:soul_sand)
B(-5,40,-6,minecraft:soul_sand)
B(-5,41,-6,minecraft:soul_sand)
B(-5,42,-6,minecraft:soul_sand)
B(-5,43,-6,minecraft:soul_sand)
B(-5,44,-6,minecraft:soul_sand)
B(-5,45,-6,minecraft:soul_sand)
B(-5,46,-6,minecraft:soul_sand)
B(-5,47,-6,minecraft:soul_sand)
B(-5,48,-6,minecraft:soul_sand)
B(-5,49,-6,minecraft:soul_sand)
B(-5,50,-6,minecraft:soul_sand)
B(-5,36,-5,minecraft:soul_sand)
B(-5,37,-5,minecraft:soul_sand)
B(-5,38,-5,minecraft:soul_sand)
B(-5,39,-5,minecraft:soul_sand)
B(-5,40,-5,minecraft:soul_sand)
B(-5,41,-5,minecraft:soul_sand)
B(-5,42,-5,minecraft:soul_sand)
B(-5,43,-5,minecraft:soul_sand)
B(-5,44,-5,minecraft:soul_sand)
B(-5,45,-5,minecraft:soul_sand)
B(-5,46,-5,minecraft:soul_sand)
B(-5,47,-5,minecraft:soul_sand)
B(-5,48,-5,minecraft:soul_sand)
B(-5,49,-5,minecraft:soul_sand)
B(-5,50,-5,minecraft:soul_sand)
B(-5,34,-4,minecraft:soul_sand)
B(-5,35,-4,minecraft:soul_sand)
B(-5,36,-4,minecraft:soul_sand)
B(-5,37,-4,minecraft:soul_sand)
B(-5,38,-4,minecraft:soul_sand)
B(-5,39,-4,minecraft:soul_sand)
B(-5,40,-4,minecraft:soul_sand)
B(-5,41,-4,minecraft:soul_sand)
B(-5,42,-4,minecraft:soul_sand)
B(-5,43,-4,minecraft:soul_sand)
B(-5,44,-4,minecraft:soul_sand)
B(-5,45,-4,minecraft:soul_sand)
B(-5,46,-4,minecraft:soul_sand)
B(-5,47,-4,minecraft:soul_sand)
B(-5,48,-4,minecraft:soul_sand)
B(-5,49,-4,minecraft:soul_sand)
B(-5,50,-4,minecraft:soul_sand)
B(-5,32,-3,minecraft:soul_sand)
B(-5,33,-3,minecraft:soul_sand)
B(-5,34,-3,minecraft:soul_sand)
B(-5,35,-3,minecraft:soul_sand)
B(-5,36,-3,minecraft:soul_sand)
B(-5,37,-3,minecraft:soul_sand)
B(-5,38,-3,minecraft:soul_sand)
B(-5,39,-3,minecraft:soul_sand)
B(-5,40,-3,minecraft:soul_sand)
B(-5,41,-3,minecraft:soul_sand)
B(-5,42,-3,minecraft:soul_sand)
B(-5,43,-3,minecraft:soul_sand)
B(-5,44,-3,minecraft:soul_sand)
B(-5,45,-3,minecraft:soul_sand)
B(-5,46,-3,minecraft:soul_sand)
B(-5,47,-3,minecraft:soul_sand)
B(-5,48,-3,minecraft:soul_sand)
B(-5,49,-3,minecraft:soul_sand)
B(-5,50,-3,minecraft:soul_sand)
B(-5,30,-2,minecraft:soul_sand)
B(-5,31,-2,minecraft:soul_sand)
B(-5,32,-2,minecraft:soul_sand)
B(-5,33,-2,minecraft:soul_sand)
B(-5,34,-2,minecraft:soul_sand)
B(-5,35,-2,minecraft:soul_sand)
B(-5,36,-2,minecraft:soul_sand)
B(-5,37,-2,minecraft:soul_sand)
B(-5,38,-2,minecraft:soul_sand)
B(-5,39,-2,minecraft:soul_sand)
B(-5,40,-2,minecraft:soul_sand)
B(-5,41,-2,minecraft:soul_sand)
B(-5,42,-2,minecraft:soul_sand)
B(-5,43,-2,minecraft:soul_sand)
B(-5,44,-2,minecraft:soul_sand)
B(-5,45,-2,minecraft:soul_sand)
B(-5,46,-2,minecraft:soul_sand)
B(-5,47,-2,minecraft:soul_sand)
B(-5,48,-2,minecraft:soul_sand)
B(-5,49,-2,minecraft:soul_sand)
B(-5,50,-2,minecraft:soul_sand)
B(-5,26,-1,minecraft:soul_sand)
B(-5,27,-1,minecraft:soul_sand)
B(-5,28,-1,minecraft:soul_sand)
B(-5,29,-1,minecraft:soul_sand)
B(-5,30,-1,minecraft:soul_sand)
B(-5,31,-1,minecraft:soul_sand)
B(-5,32,-1,minecraft:soul_sand)
B(-5,33,-1,minecraft:soul_sand)
B(-5,34,-1,minecraft:soul_sand)
B(-5,35,-1,minecraft:soul_sand)
B(-5,36,-1,minecraft:soul_sand)
B(-5,37,-1,minecraft:soul_sand)
B(-5,38,-1,minecraft:soul_sand)
B(-5,39,-1,minecraft:soul_sand)
B(-5,40,-1,minecraft:soul_sand)
B(-5,41,-1,minecraft:soul_sand)
B(-5,42,-1,minecraft:soul_sand)
B(-5,43,-1,minecraft:soul_sand)
B(-5,44,-1,minecraft:soul_sand)
B(-5,45,-1,minecraft:soul_sand)
B(-5,46,-1,minecraft:soul_sand)
B(-5,47,-1,minecraft:soul_sand)
B(-5,48,-1,minecraft:soul_sand)
B(-5,49,-1,minecraft:soul_sand)
B(-5,50,-1,minecraft:soul_sand)
B(-5,25,0,minecraft:soul_sand)
B(-5,26,0,minecraft:soul_sand)
B(-5,27,0,minecraft:soul_sand)
B(-5,28,0,minecraft:soul_sand)
B(-5,29,0,minecraft:soul_sand)
B(-5,30,0,minecraft:soul_sand)
B(-5,31,0,minecraft:soul_sand)
B(-5,32,0,minecraft:soul_sand)
B(-5,33,0,minecraft:soul_sand)
B(-5,34,0,minecraft:soul_sand)
B(-5,35,0,minecraft:soul_sand)
B(-5,36,0,minecraft:soul_sand)
B(-5,37,0,minecraft:soul_sand)
B(-5,38,0,minecraft:soul_sand)
B(-5,39,0,minecraft:soul_sand)
B(-5,40,0,minecraft:soul_sand)
B(-5,41,0,minecraft:soul_sand)
B(-5,42,0,minecraft:soul_sand)
B(-5,43,0,minecraft:soul_sand)
B(-5,44,0,minecraft:soul_sand)
B(-5,45,0,minecraft:soul_sand)
B(-5,46,0,minecraft:soul_sand)
B(-5,47,0,minecraft:soul_sand)
B(-5,48,0,minecraft:soul_sand)
B(-5,49,0,minecraft:soul_sand)
B(-5,50,0,minecraft:soul_sand)
B(-5,20,1,minecraft:soul_sand)
B(-5,21,1,minecraft:soul_sand)
B(-5,22,1,minecraft:soul_sand)
B(-5,23,1,minecraft:soul_sand)
B(-5,24,1,minecraft:soul_sand)
B(-5,25,1,minecraft:soul_sand)
B(-5,26,1,minecraft:soul_sand)
B(-5,27,1,minecraft:soul_sand)
B(-5,28,1,minecraft:soul_sand)
B(-5,29,1,minecraft:soul_sand)
B(-5,30,1,minecraft:soul_sand)
B(-5,31,1,minecraft:soul_sand)
B(-5,32,1,minecraft:soul_sand)
B(-5,33,1,minecraft:soul_sand)
B(-5,34,1,minecraft:soul_sand)
B(-5,35,1,minecraft:soul_sand)
B(-5,36,1,minecraft:soul_sand)
B(-5,37,1,minecraft:soul_sand)
B(-5,38,1,minecraft:soul_sand)
B(-5,39,1,minecraft:soul_sand)
B(-5,40,1,minecraft:soul_sand)
B(-5,41,1,minecraft:soul_sand)
B(-5,42,1,minecraft:soul_sand)
B(-5,43,1,minecraft:soul_sand)
B(-5,44,1,minecraft:soul_sand)
B(-5,45,1,minecraft:soul_sand)
B(-5,46,1,minecraft:soul_sand)
B(-5,47,1,minecraft:soul_sand)
B(-5,48,1,minecraft:soul_sand)
B(-5,49,1,minecraft:soul_sand)
B(-5,50,1,minecraft:soul_sand)
B(-5,19,2,minecraft:soul_sand)
B(-5,20,2,minecraft:soul_sand)
B(-5,21,2,minecraft:soul_sand)
B(-5,22,2,minecraft:soul_sand)
B(-5,23,2,minecraft:soul_sand)
B(-5,24,2,minecraft:soul_sand)
B(-5,25,2,minecraft:soul_sand)
B(-5,26,2,minecraft:soul_sand)
B(-5,27,2,minecraft:soul_sand)
B(-5,28,2,minecraft:soul_sand)
B(-5,29,2,minecraft:soul_sand)
B(-5,30,2,minecraft:soul_sand)
B(-5,31,2,minecraft:soul_sand)
B(-5,32,2,minecraft:soul_sand)
B(-5,33,2,minecraft:soul_sand)
B(-5,34,2,minecraft:soul_sand)
B(-5,35,2,minecraft:soul_sand)
B(-5,36,2,minecraft:soul_sand)
B(-5,37,2,minecraft:soul_sand)
B(-5,38,2,minecraft:soul_sand)
B(-5,39,2,minecraft:soul_sand)
B(-5,40,2,minecraft:soul_sand)
B(-5,41,2,minecraft:soul_sand)
B(-5,42,2,minecraft:soul_sand)
B(-5,43,2,minecraft:soul_sand)
B(-5,44,2,minecraft:soul_sand)
B(-5,45,2,minecraft:soul_sand)
B(-5,46,2,minecraft:soul_sand)
B(-5,47,2,minecraft:soul_sand)
B(-5,48,2,minecraft:soul_sand)
B(-5,49,2,minecraft:soul_sand)
B(-5,50,2,minecraft:soul_sand)
B(-5,12,3,minecraft:soul_sand)
B(-5,13,3,minecraft:soul_sand)
B(-5,14,3,minecraft:soul_sand)
B(-5,15,3,minecraft:soul_sand)
B(-5,16,3,minecraft:soul_sand)
B(-5,17,3,minecraft:soul_sand)
B(-5,18,3,minecraft:soul_sand)
B(-5,19,3,minecraft:soul_sand)
B(-5,20,3,minecraft:soul_sand)
B(-5,21,3,minecraft:soul_sand)
B(-5,22,3,minecraft:soul_sand)
B(-5,23,3,minecraft:soul_sand)
B(-5,24,3,minecraft:soul_sand)
B(-5,25,3,minecraft:soul_sand)
B(-5,26,3,minecraft:soul_sand)
B(-5,27,3,minecraft:soul_sand)
B(-5,28,3,minecraft:soul_sand)
B(-5,29,3,minecraft:soul_sand)
B(-5,30,3,minecraft:soul_sand)
B(-5,31,3,minecraft:soul_sand)
B(-5,32,3,minecraft:soul_sand)
B(-5,33,3,minecraft:soul_sand)
B(-5,34,3,minecraft:soul_sand)
B(-5,35,3,minecraft:soul_sand)
B(-5,36,3,minecraft:soul_sand)
B(-5,37,3,minecraft:soul_sand)
B(-5,38,3,minecraft:soul_sand)
B(-5,39,3,minecraft:soul_sand)
B(-5,40,3,minecraft:soul_sand)
B(-5,41,3,minecraft:soul_sand)
B(-5,42,3,minecraft:soul_sand)
B(-5,43,3,minecraft:soul_sand)
B(-5,44,3,minecraft:soul_sand)
B(-5,45,3,minecraft:soul_sand)
B(-5,46,3,minecraft:soul_sand)
B(-5,47,3,minecraft:soul_sand)
B(-5,48,3,minecraft:soul_sand)
B(-5,49,3,minecraft:soul_sand)
B(-5,50,3,minecraft:soul_sand)
B(-5,4,4,minecraft:soul_sand)
B(-5,5,4,minecraft:soul_sand)
B(-5,6,4,minecraft:soul_sand)
B(-5,7,4,minecraft:soul_sand)
B(-5,8,4,minecraft:soul_sand)
B(-5,9,4,minecraft:soul_sand)
B(-5,10,4,minecraft:soul_sand)
B(-5,11,4,minecraft:soul_sand)
B(-5,12,4,minecraft:soul_sand)
B(-5,13,4,minecraft:soul_sand)
B(-5,14,4,minecraft:soul_sand)
B(-5,15,4,minecraft:soul_sand)
B(-5,16,4,minecraft:soul_sand)
B(-5,17,4,minecraft:soul_sand)
B(-5,18,4,minecraft:soul_sand)
B(-5,19,4,minecraft:soul_sand)
B(-5,20,4,minecraft:soul_sand)
B(-5,21,4,minecraft:soul_sand)
B(-5,22,4,minecraft:soul_sand)
B(-5,23,4,minecraft:soul_sand)
B(-5,24,4,minecraft:soul_sand)
B(-5,25,4,minecraft:soul_sand)
B(-5,26,4,minecraft:soul_sand)
B(-5,27,4,minecraft:soul_sand)
B(-5,28,4,minecraft:soul_sand)
B(-5,29,4,minecraft:soul_sand)
B(-5,30,4,minecraft:soul_sand)
B(-5,31,4,minecraft:soul_sand)
B(-5,32,4,minecraft:soul_sand)
B(-5,33,4,minecraft:soul_sand)
B(-5,34,4,minecraft:soul_sand)
B(-5,35,4,minecraft:soul_sand)
B(-5,36,4,minecraft:soul_sand)
B(-5,37,4,minecraft:soul_sand)
B(-5,38,4,minecraft:soul_sand)
B(-5,39,4,minecraft:soul_sand)
B(-5,40,4,minecraft:soul_sand)
B(-5,41,4,minecraft:soul_sand)
B(-5,42,4,minecraft:soul_sand)
B(-5,43,4,minecraft:soul_sand)
B(-5,44,4,minecraft:soul_sand)
B(-5,45,4,minecraft:soul_sand)
B(-5,46,4,minecraft:soul_sand)
B(-5,47,4,minecraft:soul_sand)
B(-5,48,4,minecraft:soul_sand)
B(-5,49,4,minecraft:soul_sand)
B(-5,50,4,minecraft:soul_sand)
B(-5,4,5,minecraft:soul_sand)
B(-5,5,5,minecraft:soul_sand)
B(-5,6,5,minecraft:soul_sand)
B(-5,7,5,minecraft:soul_sand)
B(-5,8,5,minecraft:soul_sand)
B(-5,9,5,minecraft:soul_sand)
B(-5,10,5,minecraft:soul_sand)
B(-5,11,5,minecraft:soul_sand)
B(-5,12,5,minecraft:soul_sand)
B(-5,13,5,minecraft:soul_sand)
B(-5,14,5,minecraft:soul_sand)
B(-5,15,5,minecraft:soul_sand)
B(-5,16,5,minecraft:soul_sand)
B(-5,17,5,minecraft:soul_sand)
B(-5,18,5,minecraft:soul_sand)
B(-5,19,5,minecraft:soul_sand)
B(-5,20,5,minecraft:soul_sand)
B(-5,21,5,minecraft:soul_sand)
B(-5,22,5,minecraft:soul_sand)
B(-5,23,5,minecraft:soul_sand)
B(-5,24,5,minecraft:soul_sand)
B(-5,25,5,minecraft:soul_sand)
B(-5,26,5,minecraft:soul_sand)
B(-5,27,5,minecraft:soul_sand)
B(-5,28,5,minecraft:soul_sand)
B(-5,29,5,minecraft:soul_sand)
B(-5,30,5,minecraft:soul_sand)
B(-5,31,5,minecraft:soul_sand)
B(-5,32,5,minecraft:soul_sand)
B(-5,33,5,minecraft:soul_sand)
B(-5,34,5,minecraft:soul_sand)
B(-5,35,5,minecraft:soul_sand)
B(-5,36,5,minecraft:soul_sand)
B(-5,37,5,minecraft:soul_sand)
B(-5,38,5,minecraft:soul_sand)
B(-5,39,5,minecraft:soul_sand)
B(-5,40,5,minecraft:soul_sand)
B(-5,41,5,minecraft:soul_sand)
B(-5,42,5,minecraft:soul_sand)
B(-5,43,5,minecraft:soul_sand)
B(-5,44,5,minecraft:soul_sand)
B(-5,45,5,minecraft:soul_sand)
B(-5,46,5,minecraft:soul_sand)
B(-5,47,5,minecraft:soul_sand)
B(-5,48,5,minecraft:soul_sand)
B(-5,49,5,minecraft:soul_sand)
B(-5,50,5,minecraft:soul_sand)
B(-5,6,6,minecraft:soul_sand)
B(-5,7,6,minecraft:soul_sand)
B(-5,8,6,minecraft:soul_sand)
B(-5,9,6,minecraft:soul_sand)
B(-5,10,6,minecraft:soul_sand)
B(-5,11,6,minecraft:soul_sand)
B(-5,12,6,minecraft:soul_sand)
B(-5,13,6,minecraft:soul_sand)
B(-5,14,6,minecraft:soul_sand)
B(-5,15,6,minecraft:soul_sand)
B(-5,16,6,minecraft:soul_sand)
B(-5,17,6,minecraft:soul_sand)
B(-5,18,6,minecraft:soul_sand)
B(-5,19,6,minecraft:soul_sand)
B(-5,20,6,minecraft:soul_sand)
B(-5,21,6,minecraft:soul_sand)
B(-5,22,6,minecraft:soul_sand)
B(-5,23,6,minecraft:soul_sand)
B(-5,24,6,minecraft:soul_sand)
B(-5,25,6,minecraft:soul_sand)
B(-5,26,6,minecraft:soul_sand)
B(-5,27,6,minecraft:soul_sand)
B(-5,28,6,minecraft:soul_sand)
B(-5,29,6,minecraft:soul_sand)
B(-5,30,6,minecraft:soul_sand)
B(-5,31,6,minecraft:soul_sand)
B(-5,32,6,minecraft:soul_sand)
B(-5,33,6,minecraft:soul_sand)
B(-5,34,6,minecraft:soul_sand)
B(-5,35,6,minecraft:soul_sand)
B(-5,36,6,minecraft:soul_sand)
B(-5,37,6,minecraft:soul_sand)
B(-5,38,6,minecraft:soul_sand)
B(-5,39,6,minecraft:soul_sand)
B(-5,40,6,minecraft:soul_sand)
B(-5,41,6,minecraft:soul_sand)
B(-5,42,6,minecraft:soul_sand)
B(-5,43,6,minecraft:soul_sand)
B(-5,44,6,minecraft:soul_sand)
B(-5,45,6,minecraft:soul_sand)
B(-5,46,6,minecraft:soul_sand)
B(-5,47,6,minecraft:soul_sand)
B(-5,48,6,minecraft:soul_sand)
B(-5,49,6,minecraft:soul_sand)
B(-5,50,6,minecraft:soul_sand)
B(-5,7,7,minecraft:soul_sand)
B(-5,8,7,minecraft:soul_sand)
B(-5,9,7,minecraft:soul_sand)
B(-5,10,7,minecraft:soul_sand)
B(-5,11,7,minecraft:soul_sand)
B(-5,12,7,minecraft:soul_sand)
B(-5,13,7,minecraft:soul_sand)
B(-5,14,7,minecraft:soul_sand)
B(-5,15,7,minecraft:soul_sand)
B(-5,16,7,minecraft:soul_sand)
B(-5,17,7,minecraft:soul_sand)
B(-5,18,7,minecraft:soul_sand)
B(-5,19,7,minecraft:soul_sand)
B(-5,20,7,minecraft:soul_sand)
B(-5,21,7,minecraft:soul_sand)
B(-5,22,7,minecraft:soul_sand)
B(-5,23,7,minecraft:soul_sand)
B(-5,24,7,minecraft:soul_sand)
B(-5,25,7,minecraft:soul_sand)
B(-5,26,7,minecraft:soul_sand)
B(-5,27,7,minecraft:soul_sand)
B(-5,28,7,minecraft:soul_sand)
B(-5,29,7,minecraft:soul_sand)
B(-5,30,7,minecraft:soul_sand)
B(-5,31,7,minecraft:soul_sand)
B(-5,32,7,minecraft:soul_sand)
B(-5,33,7,minecraft:soul_sand)
B(-5,34,7,minecraft:soul_sand)
B(-5,35,7,minecraft:soul_sand)
B(-5,36,7,minecraft:soul_sand)
B(-5,37,7,minecraft:soul_sand)
B(-5,38,7,minecraft:soul_sand)
B(-5,39,7,minecraft:soul_sand)
B(-5,40,7,minecraft:soul_sand)
B(-5,41,7,minecraft:soul_sand)
B(-5,42,7,minecraft:soul_sand)
B(-5,43,7,minecraft:soul_sand)
B(-5,44,7,minecraft:soul_sand)
B(-5,45,7,minecraft:soul_sand)
B(-5,46,7,minecraft:soul_sand)
B(-5,47,7,minecraft:soul_sand)
B(-5,48,7,minecraft:soul_sand)
B(-5,49,7,minecraft:soul_sand)
B(-5,50,7,minecraft:soul_sand)
B(-5,8,8,minecraft:soul_sand)
B(-5,9,8,minecraft:soul_sand)
B(-5,10,8,minecraft:soul_sand)
B(-5,11,8,minecraft:soul_sand)
B(-5,12,8,minecraft:soul_sand)
B(-5,13,8,minecraft:soul_sand)
B(-5,14,8,minecraft:soul_sand)
B(-5,15,8,minecraft:soul_sand)
B(-5,16,8,minecraft:soul_sand)
B(-5,17,8,minecraft:soul_sand)
B(-5,18,8,minecraft:soul_sand)
B(-5,19,8,minecraft:soul_sand)
B(-5,20,8,minecraft:soul_sand)
B(-5,21,8,minecraft:soul_sand)
B(-5,22,8,minecraft:soul_sand)
B(-5,23,8,minecraft:soul_sand)
B(-5,24,8,minecraft:soul_sand)
B(-5,25,8,minecraft:soul_sand)
B(-5,26,8,minecraft:soul_sand)
B(-5,27,8,minecraft:soul_sand)
B(-5,28,8,minecraft:soul_sand)
B(-5,29,8,minecraft:soul_sand)
B(-5,30,8,minecraft:soul_sand)
B(-5,31,8,minecraft:soul_sand)
B(-5,32,8,minecraft:soul_sand)
B(-5,33,8,minecraft:soul_sand)
B(-5,34,8,minecraft:soul_sand)
B(-5,35,8,minecraft:soul_sand)
B(-5,36,8,minecraft:soul_sand)
B(-5,37,8,minecraft:soul_sand)
B(-5,38,8,minecraft:soul_sand)
B(-5,39,8,minecraft:soul_sand)
B(-5,40,8,minecraft:soul_sand)
B(-5,41,8,minecraft:soul_sand)
B(-5,42,8,minecraft:soul_sand)
B(-5,43,8,minecraft:soul_sand)
B(-5,44,8,minecraft:soul_sand)
B(-5,45,8,minecraft:soul_sand)
B(-5,46,8,minecraft:soul_sand)
B(-5,47,8,minecraft:soul_sand)
B(-5,48,8,minecraft:soul_sand)
B(-5,49,8,minecraft:soul_sand)
B(-5,50,8,minecraft:soul_sand)
B(-4,40,-7,minecraft:soul_sand)
B(-4,41,-7,minecraft:soul_sand)
B(-4,42,-7,minecraft:soul_sand)
B(-4,43,-7,minecraft:soul_sand)
B(-4,44,-7,minecraft:soul_sand)
B(-4,45,-7,minecraft:soul_sand)
B(-4,46,-7,minecraft:soul_sand)
B(-4,47,-7,minecraft:soul_sand)
B(-4,48,-7,minecraft:soul_sand)
B(-4,49,-7,minecraft:soul_sand)
B(-4,50,-7,minecraft:soul_sand)
B(-4,37,-6,minecraft:soul_sand)
B(-4,38,-6,minecraft:soul_sand)
B(-4,39,-6,minecraft:soul_sand)
B(-4,40,-6,minecraft:soul_sand)
B(-4,41,-6,minecraft:soul_sand)
B(-4,42,-6,minecraft:soul_sand)
B(-4,43,-6,minecraft:soul_sand)
B(-4,44,-6,minecraft:soul_sand)
B(-4,45,-6,minecraft:soul_sand)
B(-4,46,-6,minecraft:soul_sand)
B(-4,47,-6,minecraft:soul_sand)
B(-4,48,-6,minecraft:soul_sand)
B(-4,49,-6,minecraft:soul_sand)
B(-4,50,-6,minecraft:soul_sand)
B(-4,35,-5,minecraft:soul_sand)
B(-4,36,-5,minecraft:soul_sand)
B(-4,37,-5,minecraft:soul_sand)
B(-4,38,-5,minecraft:soul_sand)
B(-4,39,-5,minecraft:soul_sand)
B(-4,40,-5,minecraft:soul_sand)
B(-4,41,-5,minecraft:soul_sand)
B(-4,42,-5,minecraft:soul_sand)
B(-4,43,-5,minecraft:soul_sand)
B(-4,44,-5,minecraft:soul_sand)
B(-4,45,-5,minecraft:soul_sand)
B(-4,46,-5,minecraft:soul_sand)
B(-4,47,-5,minecraft:soul_sand)
B(-4,48,-5,minecraft:soul_sand)
B(-4,49,-5,minecraft:soul_sand)
B(-4,50,-5,minecraft:soul_sand)
B(-4,33,-4,minecraft:soul_sand)
B(-4,34,-4,minecraft:soul_sand)
B(-4,35,-4,minecraft:soul_sand)
B(-4,36,-4,minecraft:soul_sand)
B(-4,37,-4,minecraft:soul_sand)
B(-4,38,-4,minecraft:soul_sand)
B(-4,39,-4,minecraft:soul_sand)
B(-4,40,-4,minecraft:soul_sand)
B(-4,41,-4,minecraft:soul_sand)
B(-4,42,-4,minecraft:soul_sand)
B(-4,43,-4,minecraft:soul_sand)
B(-4,44,-4,minecraft:soul_sand)
B(-4,45,-4,minecraft:soul_sand)
B(-4,46,-4,minecraft:soul_sand)
B(-4,47,-4,minecraft:soul_sand)
B(-4,48,-4,minecraft:soul_sand)
B(-4,49,-4,minecraft:soul_sand)
B(-4,50,-4,minecraft:soul_sand)
B(-4,30,-3,minecraft:soul_sand)
B(-4,31,-3,minecraft:soul_sand)
B(-4,32,-3,minecraft:soul_sand)
B(-4,33,-3,minecraft:soul_sand)
B(-4,34,-3,minecraft:soul_sand)
B(-4,35,-3,minecraft:soul_sand)
B(-4,36,-3,minecraft:soul_sand)
B(-4,37,-3,minecraft:soul_sand)
B(-4,38,-3,minecraft:soul_sand)
B(-4,39,-3,minecraft:soul_sand)
B(-4,40,-3,minecraft:soul_sand)
B(-4,41,-3,minecraft:soul_sand)
B(-4,42,-3,minecraft:soul_sand)
B(-4,43,-3,minecraft:soul_sand)
B(-4,44,-3,minecraft:soul_sand)
B(-4,45,-3,minecraft:soul_sand)
B(-4,46,-3,minecraft:soul_sand)
B(-4,47,-3,minecraft:soul_sand)
B(-4,48,-3,minecraft:soul_sand)
B(-4,49,-3,minecraft:soul_sand)
B(-4,50,-3,minecraft:soul_sand)
B(-4,27,-2,minecraft:soul_sand)
B(-4,28,-2,minecraft:soul_sand)
B(-4,29,-2,minecraft:soul_sand)
B(-4,30,-2,minecraft:soul_sand)
B(-4,31,-2,minecraft:soul_sand)
B(-4,32,-2,minecraft:soul_sand)
B(-4,33,-2,minecraft:soul_sand)
B(-4,34,-2,minecraft:soul_sand)
B(-4,35,-2,minecraft:soul_sand)
B(-4,36,-2,minecraft:soul_sand)
B(-4,37,-2,minecraft:soul_sand)
B(-4,38,-2,minecraft:soul_sand)
B(-4,39,-2,minecraft:soul_sand)
B(-4,40,-2,minecraft:soul_sand)
B(-4,41,-2,minecraft:soul_sand)
B(-4,42,-2,minecraft:soul_sand)
B(-4,43,-2,minecraft:soul_sand)
B(-4,44,-2,minecraft:soul_sand)
B(-4,45,-2,minecraft:soul_sand)
B(-4,46,-2,minecraft:soul_sand)
B(-4,47,-2,minecraft:soul_sand)
B(-4,48,-2,minecraft:soul_sand)
B(-4,49,-2,minecraft:soul_sand)
B(-4,50,-2,minecraft:soul_sand)
B(-4,24,-1,minecraft:soul_sand)
B(-4,25,-1,minecraft:soul_sand)
B(-4,26,-1,minecraft:soul_sand)
B(-4,27,-1,minecraft:soul_sand)
B(-4,28,-1,minecraft:soul_sand)
B(-4,29,-1,minecraft:soul_sand)
B(-4,30,-1,minecraft:soul_sand)
B(-4,31,-1,minecraft:soul_sand)
B(-4,32,-1,minecraft:soul_sand)
B(-4,33,-1,minecraft:soul_sand)
B(-4,34,-1,minecraft:soul_sand)
B(-4,35,-1,minecraft:soul_sand)
B(-4,36,-1,minecraft:soul_sand)
B(-4,37,-1,minecraft:soul_sand)
B(-4,38,-1,minecraft:soul_sand)
B(-4,39,-1,minecraft:soul_sand)
B(-4,40,-1,minecraft:soul_sand)
B(-4,41,-1,minecraft:soul_sand)
B(-4,42,-1,minecraft:soul_sand)
B(-4,43,-1,minecraft:soul_sand)
B(-4,44,-1,minecraft:soul_sand)
B(-4,45,-1,minecraft:soul_sand)
B(-4,46,-1,minecraft:soul_sand)
B(-4,47,-1,minecraft:soul_sand)
B(-4,48,-1,minecraft:soul_sand)
B(-4,49,-1,minecraft:soul_sand)
B(-4,50,-1,minecraft:soul_sand)
B(-4,20,0,minecraft:soul_sand)
B(-4,21,0,minecraft:soul_sand)
B(-4,22,0,minecraft:soul_sand)
B(-4,23,0,minecraft:soul_sand)
B(-4,24,0,minecraft:soul_sand)
B(-4,25,0,minecraft:soul_sand)
B(-4,26,0,minecraft:soul_sand)
B(-4,27,0,minecraft:soul_sand)
B(-4,28,0,minecraft:soul_sand)
B(-4,29,0,minecraft:soul_sand)
B(-4,30,0,minecraft:soul_sand)
B(-4,31,0,minecraft:soul_sand)
B(-4,32,0,minecraft:soul_sand)
B(-4,33,0,minecraft:soul_sand)
B(-4,34,0,minecraft:soul_sand)
B(-4,35,0,minecraft:soul_sand)
B(-4,36,0,minecraft:soul_sand)
B(-4,37,0,minecraft:soul_sand)
B(-4,38,0,minecraft:soul_sand)
B(-4,39,0,minecraft:soul_sand)
B(-4,40,0,minecraft:soul_sand)
B(-4,41,0,minecraft:soul_sand)
B(-4,42,0,minecraft:soul_sand)
B(-4,43,0,minecraft:soul_sand)
B(-4,44,0,minecraft:soul_sand)
B(-4,45,0,minecraft:soul_sand)
B(-4,46,0,minecraft:soul_sand)
B(-4,47,0,minecraft:soul_sand)
B(-4,48,0,minecraft:soul_sand)
B(-4,49,0,minecraft:soul_sand)
B(-4,50,0,minecraft:soul_sand)
B(-4,19,1,minecraft:soul_sand)
B(-4,20,1,minecraft:soul_sand)
B(-4,21,1,minecraft:soul_sand)
B(-4,22,1,minecraft:soul_sand)
B(-4,23,1,minecraft:soul_sand)
B(-4,24,1,minecraft:soul_sand)
B(-4,25,1,minecraft:soul_sand)
B(-4,26,1,minecraft:soul_sand)
B(-4,27,1,minecraft:soul_sand)
B(-4,28,1,minecraft:soul_sand)
B(-4,29,1,minecraft:soul_sand)
B(-4,30,1,minecraft:soul_sand)
B(-4,31,1,minecraft:soul_sand)
B(-4,32,1,minecraft:soul_sand)
B(-4,33,1,minecraft:soul_sand)
B(-4,34,1,minecraft:soul_sand)
B(-4,35,1,minecraft:soul_sand)
B(-4,36,1,minecraft:soul_sand)
B(-4,37,1,minecraft:soul_sand)
B(-4,38,1,minecraft:soul_sand)
B(-4,39,1,minecraft:soul_sand)
B(-4,40,1,minecraft:soul_sand)
B(-4,41,1,minecraft:soul_sand)
B(-4,42,1,minecraft:soul_sand)
B(-4,43,1,minecraft:soul_sand)
B(-4,44,1,minecraft:soul_sand)
B(-4,45,1,minecraft:soul_sand)
B(-4,46,1,minecraft:soul_sand)
B(-4,47,1,minecraft:soul_sand)
B(-4,48,1,minecraft:soul_sand)
B(-4,49,1,minecraft:soul_sand)
B(-4,50,1,minecraft:soul_sand)
B(-4,12,2,minecraft:soul_sand)
B(-4,13,2,minecraft:soul_sand)
B(-4,14,2,minecraft:soul_sand)
B(-4,15,2,minecraft:soul_sand)
B(-4,16,2,minecraft:soul_sand)
B(-4,17,2,minecraft:soul_sand)
B(-4,18,2,minecraft:soul_sand)
B(-4,19,2,minecraft:soul_sand)
B(-4,20,2,minecraft:soul_sand)
B(-4,21,2,minecraft:soul_sand)
B(-4,22,2,minecraft:soul_sand)
B(-4,23,2,minecraft:soul_sand)
B(-4,24,2,minecraft:soul_sand)
B(-4,25,2,minecraft:soul_sand)
B(-4,26,2,minecraft:soul_sand)
B(-4,27,2,minecraft:soul_sand)
B(-4,28,2,minecraft:soul_sand)
B(-4,29,2,minecraft:soul_sand)
B(-4,30,2,minecraft:soul_sand)
B(-4,31,2,minecraft:soul_sand)
B(-4,32,2,minecraft:soul_sand)
B(-4,33,2,minecraft:soul_sand)
B(-4,34,2,minecraft:soul_sand)
B(-4,35,2,minecraft:soul_sand)
B(-4,36,2,minecraft:soul_sand)
B(-4,37,2,minecraft:soul_sand)
B(-4,38,2,minecraft:soul_sand)
B(-4,39,2,minecraft:soul_sand)
B(-4,40,2,minecraft:soul_sand)
B(-4,41,2,minecraft:soul_sand)
B(-4,42,2,minecraft:soul_sand)
B(-4,43,2,minecraft:soul_sand)
B(-4,44,2,minecraft:soul_sand)
B(-4,45,2,minecraft:soul_sand)
B(-4,46,2,minecraft:soul_sand)
B(-4,47,2,minecraft:soul_sand)
B(-4,48,2,minecraft:soul_sand)
B(-4,49,2,minecraft:soul_sand)
B(-4,50,2,minecraft:soul_sand)
B(-4,4,3,minecraft:soul_sand)
B(-4,5,3,minecraft:soul_sand)
B(-4,6,3,minecraft:soul_sand)
B(-4,7,3,minecraft:soul_sand)
B(-4,8,3,minecraft:soul_sand)
B(-4,9,3,minecraft:soul_sand)
B(-4,10,3,minecraft:soul_sand)
B(-4,11,3,minecraft:soul_sand)
B(-4,12,3,minecraft:soul_sand)
B(-4,13,3,minecraft:soul_sand)
B(-4,14,3,minecraft:soul_sand)
B(-4,15,3,minecraft:soul_sand)
B(-4,16,3,minecraft:soul_sand)
B(-4,17,3,minecraft:soul_sand)
B(-4,18,3,minecraft:soul_sand)
B(-4,19,3,minecraft:soul_sand)
B(-4,20,3,minecraft:soul_sand)
B(-4,21,3,minecraft:soul_sand)
B(-4,22,3,minecraft:soul_sand)
B(-4,23,3,minecraft:soul_sand)
B(-4,24,3,minecraft:soul_sand)
B(-4,25,3,minecraft:soul_sand)
B(-4,26,3,minecraft:soul_sand)
B(-4,27,3,minecraft:soul_sand)
B(-4,28,3,minecraft:soul_sand)
B(-4,29,3,minecraft:soul_sand)
B(-4,30,3,minecraft:soul_sand)
B(-4,31,3,minecraft:soul_sand)
B(-4,32,3,minecraft:soul_sand)
B(-4,33,3,minecraft:soul_sand)
B(-4,34,3,minecraft:soul_sand)
B(-4,35,3,minecraft:soul_sand)
B(-4,36,3,minecraft:soul_sand)
B(-4,37,3,minecraft:soul_sand)
B(-4,38,3,minecraft:soul_sand)
B(-4,39,3,minecraft:soul_sand)
B(-4,40,3,minecraft:soul_sand)
B(-4,41,3,minecraft:soul_sand)
B(-4,42,3,minecraft:soul_sand)
B(-4,43,3,minecraft:soul_sand)
B(-4,44,3,minecraft:soul_sand)
B(-4,45,3,minecraft:soul_sand)
B(-4,46,3,minecraft:soul_sand)
B(-4,47,3,minecraft:soul_sand)
B(-4,48,3,minecraft:soul_sand)
B(-4,49,3,minecraft:soul_sand)
B(-4,50,3,minecraft:soul_sand)
B(-4,3,4,minecraft:soul_sand)
B(-4,4,4,minecraft:soul_sand)
B(-4,5,4,minecraft:soul_sand)
B(-4,6,4,minecraft:soul_sand)
B(-4,7,4,minecraft:soul_sand)
B(-4,8,4,minecraft:soul_sand)
B(-4,9,4,minecraft:soul_sand)
B(-4,10,4,minecraft:soul_sand)
B(-4,11,4,minecraft:soul_sand)
B(-4,12,4,minecraft:soul_sand)
B(-4,13,4,minecraft:soul_sand)
B(-4,14,4,minecraft:soul_sand)
B(-4,15,4,minecraft:soul_sand)
B(-4,16,4,minecraft:soul_sand)
B(-4,17,4,minecraft:soul_sand)
B(-4,18,4,minecraft:soul_sand)
B(-4,19,4,minecraft:soul_sand)
B(-4,20,4,minecraft:soul_sand)
B(-4,21,4,minecraft:soul_sand)
B(-4,22,4,minecraft:soul_sand)
B(-4,23,4,minecraft:soul_sand)
B(-4,24,4,minecraft:soul_sand)
B(-4,25,4,minecraft:soul_sand)
B(-4,26,4,minecraft:soul_sand)
B(-4,27,4,minecraft:soul_sand)
B(-4,28,4,minecraft:soul_sand)
B(-4,29,4,minecraft:soul_sand)
B(-4,30,4,minecraft:soul_sand)
B(-4,31,4,minecraft:soul_sand)
B(-4,32,4,minecraft:soul_sand)
B(-4,33,4,minecraft:soul_sand)
B(-4,34,4,minecraft:soul_sand)
B(-4,35,4,minecraft:soul_sand)
B(-4,36,4,minecraft:soul_sand)
B(-4,37,4,minecraft:soul_sand)
B(-4,38,4,minecraft:soul_sand)
B(-4,39,4,minecraft:soul_sand)
B(-4,40,4,minecraft:soul_sand)
B(-4,41,4,minecraft:soul_sand)
B(-4,42,4,minecraft:soul_sand)
B(-4,43,4,minecraft:soul_sand)
B(-4,44,4,minecraft:soul_sand)
B(-4,45,4,minecraft:soul_sand)
B(-4,46,4,minecraft:soul_sand)
B(-4,47,4,minecraft:soul_sand)
B(-4,48,4,minecraft:soul_sand)
B(-4,49,4,minecraft:soul_sand)
B(-4,50,4,minecraft:soul_sand)
B(-4,3,5,minecraft:soul_sand)
B(-4,4,5,minecraft:soul_sand)
B(-4,5,5,minecraft:soul_sand)
B(-4,6,5,minecraft:soul_sand)
B(-4,7,5,minecraft:soul_sand)
B(-4,8,5,minecraft:soul_sand)
B(-4,9,5,minecraft:soul_sand)
B(-4,10,5,minecraft:soul_sand)
B(-4,11,5,minecraft:soul_sand)
B(-4,12,5,minecraft:soul_sand)
B(-4,13,5,minecraft:soul_sand)
B(-4,14,5,minecraft:soul_sand)
B(-4,15,5,minecraft:soul_sand)
B(-4,16,5,minecraft:soul_sand)
B(-4,17,5,minecraft:soul_sand)
B(-4,18,5,minecraft:soul_sand)
B(-4,19,5,minecraft:soul_sand)
B(-4,20,5,minecraft:soul_sand)
B(-4,21,5,minecraft:soul_sand)
B(-4,22,5,minecraft:soul_sand)
B(-4,23,5,minecraft:soul_sand)
B(-4,24,5,minecraft:soul_sand)
B(-4,25,5,minecraft:soul_sand)
B(-4,26,5,minecraft:soul_sand)
B(-4,27,5,minecraft:soul_sand)
B(-4,28,5,minecraft:soul_sand)
B(-4,29,5,minecraft:soul_sand)
B(-4,30,5,minecraft:soul_sand)
B(-4,31,5,minecraft:soul_sand)
B(-4,32,5,minecraft:soul_sand)
B(-4,33,5,minecraft:soul_sand)
B(-4,34,5,minecraft:soul_sand)
B(-4,35,5,minecraft:soul_sand)
B(-4,36,5,minecraft:soul_sand)
B(-4,37,5,minecraft:soul_sand)
B(-4,38,5,minecraft:soul_sand)
B(-4,39,5,minecraft:soul_sand)
B(-4,40,5,minecraft:soul_sand)
B(-4,41,5,minecraft:soul_sand)
B(-4,42,5,minecraft:soul_sand)
B(-4,43,5,minecraft:soul_sand)
B(-4,44,5,minecraft:soul_sand)
B(-4,45,5,minecraft:soul_sand)
B(-4,46,5,minecraft:soul_sand)
B(-4,47,5,minecraft:soul_sand)
B(-4,48,5,minecraft:soul_sand)
B(-4,49,5,minecraft:soul_sand)
B(-4,50,5,minecraft:soul_sand)
B(-4,4,6,minecraft:soul_sand)
B(-4,5,6,minecraft:soul_sand)
B(-4,6,6,minecraft:soul_sand)
B(-4,7,6,minecraft:soul_sand)
B(-4,8,6,minecraft:soul_sand)
B(-4,9,6,minecraft:soul_sand)
B(-4,10,6,minecraft:soul_sand)
B(-4,11,6,minecraft:soul_sand)
B(-4,12,6,minecraft:soul_sand)
B(-4,13,6,minecraft:soul_sand)
B(-4,14,6,minecraft:soul_sand)
B(-4,15,6,minecraft:soul_sand)
B(-4,16,6,minecraft:soul_sand)
B(-4,17,6,minecraft:soul_sand)
B(-4,18,6,minecraft:soul_sand)
B(-4,19,6,minecraft:soul_sand)
B(-4,20,6,minecraft:soul_sand)
B(-4,21,6,minecraft:soul_sand)
B(-4,22,6,minecraft:soul_sand)
B(-4,23,6,minecraft:soul_sand)
B(-4,24,6,minecraft:soul_sand)
B(-4,25,6,minecraft:soul_sand)
B(-4,26,6,minecraft:soul_sand)
B(-4,27,6,minecraft:soul_sand)
B(-4,28,6,minecraft:soul_sand)
B(-4,29,6,minecraft:soul_sand)
B(-4,30,6,minecraft:soul_sand)
B(-4,31,6,minecraft:soul_sand)
B(-4,32,6,minecraft:soul_sand)
B(-4,33,6,minecraft:soul_sand)
B(-4,34,6,minecraft:soul_sand)
B(-4,35,6,minecraft:soul_sand)
B(-4,36,6,minecraft:soul_sand)
B(-4,37,6,minecraft:soul_sand)
B(-4,38,6,minecraft:soul_sand)
B(-4,39,6,minecraft:soul_sand)
B(-4,40,6,minecraft:soul_sand)
B(-4,41,6,minecraft:soul_sand)
B(-4,42,6,minecraft:soul_sand)
B(-4,43,6,minecraft:soul_sand)
B(-4,44,6,minecraft:soul_sand)
B(-4,45,6,minecraft:soul_sand)
B(-4,46,6,minecraft:soul_sand)
B(-4,47,6,minecraft:soul_sand)
B(-4,48,6,minecraft:soul_sand)
B(-4,49,6,minecraft:soul_sand)
B(-4,50,6,minecraft:soul_sand)
B(-4,5,7,minecraft:soul_sand)
B(-4,6,7,minecraft:soul_sand)
B(-4,7,7,minecraft:soul_sand)
B(-4,8,7,minecraft:soul_sand)
B(-4,9,7,minecraft:soul_sand)
B(-4,10,7,minecraft:soul_sand)
B(-4,11,7,minecraft:soul_sand)
B(-4,12,7,minecraft:soul_sand)
B(-4,13,7,minecraft:soul_sand)
B(-4,14,7,minecraft:soul_sand)
B(-4,15,7,minecraft:soul_sand)
B(-4,16,7,minecraft:soul_sand)
B(-4,17,7,minecraft:soul_sand)
B(-4,18,7,minecraft:soul_sand)
B(-4,19,7,minecraft:soul_sand)
B(-4,20,7,minecraft:soul_sand)
B(-4,21,7,minecraft:soul_sand)
B(-4,22,7,minecraft:soul_sand)
B(-4,23,7,minecraft:soul_sand)
B(-4,24,7,minecraft:soul_sand)
B(-4,25,7,minecraft:soul_sand)
B(-4,26,7,minecraft:soul_sand)
B(-4,27,7,minecraft:soul_sand)
B(-4,28,7,minecraft:soul_sand)
B(-4,29,7,minecraft:soul_sand)
B(-4,30,7,minecraft:soul_sand)
B(-4,31,7,minecraft:soul_sand)
B(-4,32,7,minecraft:soul_sand)
B(-4,33,7,minecraft:soul_sand)
B(-4,34,7,minecraft:soul_sand)
B(-4,35,7,minecraft:soul_sand)
B(-4,36,7,minecraft:soul_sand)
B(-4,37,7,minecraft:soul_sand)
B(-4,38,7,minecraft:soul_sand)
B(-4,39,7,minecraft:soul_sand)
B(-4,40,7,minecraft:soul_sand)
B(-4,41,7,minecraft:soul_sand)
B(-4,42,7,minecraft:soul_sand)
B(-4,43,7,minecraft:soul_sand)
B(-4,44,7,minecraft:soul_sand)
B(-4,45,7,minecraft:soul_sand)
B(-4,46,7,minecraft:soul_sand)
B(-4,47,7,minecraft:soul_sand)
B(-4,48,7,minecraft:soul_sand)
B(-4,49,7,minecraft:soul_sand)
B(-4,50,7,minecraft:soul_sand)
B(-4,6,8,minecraft:soul_sand)
B(-4,7,8,minecraft:soul_sand)
B(-4,8,8,minecraft:soul_sand)
B(-4,9,8,minecraft:soul_sand)
B(-4,10,8,minecraft:soul_sand)
B(-4,11,8,minecraft:soul_sand)
B(-4,12,8,minecraft:soul_sand)
B(-4,13,8,minecraft:soul_sand)
B(-4,14,8,minecraft:soul_sand)
B(-4,15,8,minecraft:soul_sand)
B(-4,16,8,minecraft:soul_sand)
B(-4,17,8,minecraft:soul_sand)
B(-4,18,8,minecraft:soul_sand)
B(-4,19,8,minecraft:soul_sand)
B(-4,20,8,minecraft:soul_sand)
B(-4,21,8,minecraft:soul_sand)
B(-4,22,8,minecraft:soul_sand)
B(-4,23,8,minecraft:soul_sand)
B(-4,24,8,minecraft:soul_sand)
B(-4,25,8,minecraft:soul_sand)
B(-4,26,8,minecraft:soul_sand)
B(-4,27,8,minecraft:soul_sand)
B(-4,28,8,minecraft:soul_sand)
B(-4,29,8,minecraft:soul_sand)
B(-4,30,8,minecraft:soul_sand)
B(-4,31,8,minecraft:soul_sand)
B(-4,32,8,minecraft:soul_sand)
B(-4,33,8,minecraft:soul_sand)
B(-4,34,8,minecraft:soul_sand)
B(-4,35,8,minecraft:soul_sand)
B(-4,36,8,minecraft:soul_sand)
B(-4,37,8,minecraft:soul_sand)
B(-4,38,8,minecraft:soul_sand)
B(-4,39,8,minecraft:soul_sand)
B(-4,40,8,minecraft:soul_sand)
B(-4,41,8,minecraft:soul_sand)
B(-4,42,8,minecraft:soul_sand)
B(-4,43,8,minecraft:soul_sand)
B(-4,44,8,minecraft:soul_sand)
B(-4,45,8,minecraft:soul_sand)
B(-4,46,8,minecraft:soul_sand)
B(-4,47,8,minecraft:soul_sand)
B(-4,48,8,minecraft:soul_sand)
B(-4,49,8,minecraft:soul_sand)
B(-4,50,8,minecraft:soul_sand)
B(-3,40,-7,minecraft:soul_sand)
B(-3,41,-7,minecraft:soul_sand)
B(-3,42,-7,minecraft:soul_sand)
B(-3,43,-7,minecraft:soul_sand)
B(-3,44,-7,minecraft:soul_sand)
B(-3,45,-7,minecraft:soul_sand)
B(-3,46,-7,minecraft:soul_sand)
B(-3,47,-7,minecraft:soul_sand)
B(-3,48,-7,minecraft:soul_sand)
B(-3,49,-7,minecraft:soul_sand)
B(-3,50,-7,minecraft:soul_sand)
B(-3,37,-6,minecraft:soul_sand)
B(-3,38,-6,minecraft:soul_sand)
B(-3,39,-6,minecraft:soul_sand)
B(-3,40,-6,minecraft:soul_sand)
B(-3,41,-6,minecraft:soul_sand)
B(-3,42,-6,minecraft:soul_sand)
B(-3,43,-6,minecraft:soul_sand)
B(-3,44,-6,minecraft:soul_sand)
B(-3,45,-6,minecraft:soul_sand)
B(-3,46,-6,minecraft:soul_sand)
B(-3,47,-6,minecraft:soul_sand)
B(-3,48,-6,minecraft:soul_sand)
B(-3,49,-6,minecraft:soul_sand)
B(-3,50,-6,minecraft:soul_sand)
B(-3,34,-5,minecraft:soul_sand)
B(-3,35,-5,minecraft:soul_sand)
B(-3,36,-5,minecraft:soul_sand)
B(-3,37,-5,minecraft:soul_sand)
B(-3,38,-5,minecraft:soul_sand)
B(-3,39,-5,minecraft:soul_sand)
B(-3,40,-5,minecraft:soul_sand)
B(-3,41,-5,minecraft:soul_sand)
B(-3,42,-5,minecraft:soul_sand)
B(-3,43,-5,minecraft:soul_sand)
B(-3,44,-5,minecraft:soul_sand)
B(-3,45,-5,minecraft:soul_sand)
B(-3,46,-5,minecraft:soul_sand)
B(-3,47,-5,minecraft:soul_sand)
B(-3,48,-5,minecraft:soul_sand)
B(-3,49,-5,minecraft:soul_sand)
B(-3,50,-5,minecraft:soul_sand)
B(-3,32,-4,minecraft:soul_sand)
B(-3,33,-4,minecraft:soul_sand)
B(-3,34,-4,minecraft:soul_sand)
B(-3,35,-4,minecraft:soul_sand)
B(-3,36,-4,minecraft:soul_sand)
B(-3,37,-4,minecraft:soul_sand)
B(-3,38,-4,minecraft:soul_sand)
B(-3,39,-4,minecraft:soul_sand)
B(-3,40,-4,minecraft:soul_sand)
B(-3,41,-4,minecraft:soul_sand)
B(-3,42,-4,minecraft:soul_sand)
B(-3,43,-4,minecraft:soul_sand)
B(-3,44,-4,minecraft:soul_sand)
B(-3,45,-4,minecraft:soul_sand)
B(-3,46,-4,minecraft:soul_sand)
B(-3,47,-4,minecraft:soul_sand)
B(-3,48,-4,minecraft:soul_sand)
B(-3,49,-4,minecraft:soul_sand)
B(-3,50,-4,minecraft:soul_sand)
B(-3,27,-3,minecraft:soul_sand)
B(-3,28,-3,minecraft:soul_sand)
B(-3,29,-3,minecraft:soul_sand)
B(-3,30,-3,minecraft:soul_sand)
B(-3,31,-3,minecraft:soul_sand)
B(-3,32,-3,minecraft:soul_sand)
B(-3,33,-3,minecraft:soul_sand)
B(-3,34,-3,minecraft:soul_sand)
B(-3,35,-3,minecraft:soul_sand)
B(-3,36,-3,minecraft:soul_sand)
B(-3,37,-3,minecraft:soul_sand)
B(-3,38,-3,minecraft:soul_sand)
B(-3,39,-3,minecraft:soul_sand)
B(-3,40,-3,minecraft:soul_sand)
B(-3,41,-3,minecraft:soul_sand)
B(-3,42,-3,minecraft:soul_sand)
B(-3,43,-3,minecraft:soul_sand)
B(-3,44,-3,minecraft:soul_sand)
B(-3,45,-3,minecraft:soul_sand)
B(-3,46,-3,minecraft:soul_sand)
B(-3,47,-3,minecraft:soul_sand)
B(-3,48,-3,minecraft:soul_sand)
B(-3,49,-3,minecraft:soul_sand)
B(-3,50,-3,minecraft:soul_sand)
B(-3,24,-2,minecraft:soul_sand)
B(-3,25,-2,minecraft:soul_sand)
B(-3,26,-2,minecraft:soul_sand)
B(-3,27,-2,minecraft:soul_sand)
B(-3,28,-2,minecraft:soul_sand)
B(-3,29,-2,minecraft:soul_sand)
B(-3,30,-2,minecraft:soul_sand)
B(-3,31,-2,minecraft:soul_sand)
B(-3,32,-2,minecraft:soul_sand)
B(-3,33,-2,minecraft:soul_sand)
B(-3,34,-2,minecraft:soul_sand)
B(-3,35,-2,minecraft:soul_sand)
B(-3,36,-2,minecraft:soul_sand)
B(-3,37,-2,minecraft:soul_sand)
B(-3,38,-2,minecraft:soul_sand)
B(-3,39,-2,minecraft:soul_sand)
B(-3,40,-2,minecraft:soul_sand)
B(-3,41,-2,minecraft:soul_sand)
B(-3,42,-2,minecraft:soul_sand)
B(-3,43,-2,minecraft:soul_sand)
B(-3,44,-2,minecraft:soul_sand)
B(-3,45,-2,minecraft:soul_sand)
B(-3,46,-2,minecraft:soul_sand)
B(-3,47,-2,minecraft:soul_sand)
B(-3,48,-2,minecraft:soul_sand)
B(-3,49,-2,minecraft:soul_sand)
B(-3,50,-2,minecraft:soul_sand)
B(-3,20,-1,minecraft:soul_sand)
B(-3,21,-1,minecraft:soul_sand)
B(-3,22,-1,minecraft:soul_sand)
B(-3,23,-1,minecraft:soul_sand)
B(-3,24,-1,minecraft:soul_sand)
B(-3,25,-1,minecraft:soul_sand)
B(-3,26,-1,minecraft:soul_sand)
B(-3,27,-1,minecraft:soul_sand)
B(-3,28,-1,minecraft:soul_sand)
B(-3,29,-1,minecraft:soul_sand)
B(-3,30,-1,minecraft:soul_sand)
B(-3,31,-1,minecraft:soul_sand)
B(-3,32,-1,minecraft:soul_sand)
B(-3,33,-1,minecraft:soul_sand)
B(-3,34,-1,minecraft:soul_sand)
B(-3,35,-1,minecraft:soul_sand)
B(-3,36,-1,minecraft:soul_sand)
B(-3,37,-1,minecraft:soul_sand)
B(-3,38,-1,minecraft:soul_sand)
B(-3,39,-1,minecraft:soul_sand)
B(-3,40,-1,minecraft:soul_sand)
B(-3,41,-1,minecraft:soul_sand)
B(-3,42,-1,minecraft:soul_sand)
B(-3,43,-1,minecraft:soul_sand)
B(-3,44,-1,minecraft:soul_sand)
B(-3,45,-1,minecraft:soul_sand)
B(-3,46,-1,minecraft:soul_sand)
B(-3,47,-1,minecraft:soul_sand)
B(-3,48,-1,minecraft:soul_sand)
B(-3,49,-1,minecraft:soul_sand)
B(-3,50,-1,minecraft:soul_sand)
B(-3,18,0,minecraft:soul_sand)
B(-3,19,0,minecraft:soul_sand)
B(-3,20,0,minecraft:soul_sand)
B(-3,21,0,minecraft:soul_sand)
B(-3,22,0,minecraft:soul_sand)
B(-3,23,0,minecraft:soul_sand)
B(-3,24,0,minecraft:soul_sand)
B(-3,25,0,minecraft:soul_sand)
B(-3,26,0,minecraft:soul_sand)
B(-3,27,0,minecraft:soul_sand)
B(-3,28,0,minecraft:soul_sand)
B(-3,29,0,minecraft:soul_sand)
B(-3,30,0,minecraft:soul_sand)
B(-3,31,0,minecraft:soul_sand)
B(-3,32,0,minecraft:soul_sand)
B(-3,33,0,minecraft:soul_sand)
B(-3,34,0,minecraft:soul_sand)
B(-3,35,0,minecraft:soul_sand)
B(-3,36,0,minecraft:soul_sand)
B(-3,37,0,minecraft:soul_sand)
B(-3,38,0,minecraft:soul_sand)
B(-3,39,0,minecraft:soul_sand)
B(-3,40,0,minecraft:soul_sand)
B(-3,41,0,minecraft:soul_sand)
B(-3,42,0,minecraft:soul_sand)
B(-3,43,0,minecraft:soul_sand)
B(-3,44,0,minecraft:soul_sand)
B(-3,45,0,minecraft:soul_sand)
B(-3,46,0,minecraft:soul_sand)
B(-3,47,0,minecraft:soul_sand)
B(-3,48,0,minecraft:soul_sand)
B(-3,49,0,minecraft:soul_sand)
B(-3,50,0,minecraft:soul_sand)
B(-3,16,1,minecraft:soul_sand)
B(-3,17,1,minecraft:soul_sand)
B(-3,18,1,minecraft:soul_sand)
B(-3,19,1,minecraft:soul_sand)
B(-3,20,1,minecraft:soul_sand)
B(-3,21,1,minecraft:soul_sand)
B(-3,22,1,minecraft:soul_sand)
B(-3,23,1,minecraft:soul_sand)
B(-3,24,1,minecraft:soul_sand)
B(-3,25,1,minecraft:soul_sand)
B(-3,26,1,minecraft:soul_sand)
B(-3,27,1,minecraft:soul_sand)
B(-3,28,1,minecraft:soul_sand)
B(-3,29,1,minecraft:soul_sand)
B(-3,30,1,minecraft:soul_sand)
B(-3,31,1,minecraft:soul_sand)
B(-3,32,1,minecraft:soul_sand)
B(-3,33,1,minecraft:soul_sand)
B(-3,34,1,minecraft:soul_sand)
B(-3,35,1,minecraft:soul_sand)
B(-3,36,1,minecraft:soul_sand)
B(-3,37,1,minecraft:soul_sand)
B(-3,38,1,minecraft:soul_sand)
B(-3,39,1,minecraft:soul_sand)
B(-3,40,1,minecraft:soul_sand)
B(-3,41,1,minecraft:soul_sand)
B(-3,42,1,minecraft:soul_sand)
B(-3,43,1,minecraft:soul_sand)
B(-3,44,1,minecraft:soul_sand)
B(-3,45,1,minecraft:soul_sand)
B(-3,46,1,minecraft:soul_sand)
B(-3,47,1,minecraft:soul_sand)
B(-3,48,1,minecraft:soul_sand)
B(-3,49,1,minecraft:soul_sand)
B(-3,50,1,minecraft:soul_sand)
B(-3,8,2,minecraft:soul_sand)
B(-3,9,2,minecraft:soul_sand)
B(-3,10,2,minecraft:soul_sand)
B(-3,11,2,minecraft:soul_sand)
B(-3,12,2,minecraft:soul_sand)
B(-3,13,2,minecraft:soul_sand)
B(-3,14,2,minecraft:soul_sand)
B(-3,15,2,minecraft:soul_sand)
B(-3,16,2,minecraft:soul_sand)
B(-3,17,2,minecraft:soul_sand)
B(-3,18,2,minecraft:soul_sand)
B(-3,19,2,minecraft:soul_sand)
B(-3,20,2,minecraft:soul_sand)
B(-3,21,2,minecraft:soul_sand)
B(-3,22,2,minecraft:soul_sand)
B(-3,23,2,minecraft:soul_sand)
B(-3,24,2,minecraft:soul_sand)
B(-3,25,2,minecraft:soul_sand)
B(-3,26,2,minecraft:soul_sand)
B(-3,27,2,minecraft:soul_sand)
B(-3,28,2,minecraft:soul_sand)
B(-3,29,2,minecraft:soul_sand)
B(-3,30,2,minecraft:soul_sand)
B(-3,31,2,minecraft:soul_sand)
B(-3,32,2,minecraft:soul_sand)
B(-3,33,2,minecraft:soul_sand)
B(-3,34,2,minecraft:soul_sand)
B(-3,35,2,minecraft:soul_sand)
B(-3,36,2,minecraft:soul_sand)
B(-3,37,2,minecraft:soul_sand)
B(-3,38,2,minecraft:soul_sand)
B(-3,39,2,minecraft:soul_sand)
B(-3,40,2,minecraft:soul_sand)
B(-3,41,2,minecraft:soul_sand)
B(-3,42,2,minecraft:soul_sand)
B(-3,43,2,minecraft:soul_sand)
B(-3,44,2,minecraft:soul_sand)
B(-3,45,2,minecraft:soul_sand)
B(-3,46,2,minecraft:soul_sand)
B(-3,47,2,minecraft:soul_sand)
B(-3,48,2,minecraft:soul_sand)
B(-3,49,2,minecraft:soul_sand)
B(-3,50,2,minecraft:soul_sand)
B(-3,3,3,minecraft:soul_sand)
B(-3,4,3,minecraft:soul_sand)
B(-3,5,3,minecraft:soul_sand)
B(-3,6,3,minecraft:soul_sand)
B(-3,7,3,minecraft:soul_sand)
B(-3,8,3,minecraft:soul_sand)
B(-3,9,3,minecraft:soul_sand)
B(-3,10,3,minecraft:soul_sand)
B(-3,11,3,minecraft:soul_sand)
B(-3,12,3,minecraft:soul_sand)
B(-3,13,3,minecraft:soul_sand)
B(-3,14,3,minecraft:soul_sand)
B(-3,15,3,minecraft:soul_sand)
B(-3,16,3,minecraft:soul_sand)
B(-3,17,3,minecraft:soul_sand)
B(-3,18,3,minecraft:soul_sand)
B(-3,19,3,minecraft:soul_sand)
B(-3,20,3,minecraft:soul_sand)
B(-3,21,3,minecraft:soul_sand)
B(-3,22,3,minecraft:soul_sand)
B(-3,23,3,minecraft:soul_sand)
B(-3,24,3,minecraft:soul_sand)
B(-3,25,3,minecraft:soul_sand)
B(-3,26,3,minecraft:soul_sand)
B(-3,27,3,minecraft:soul_sand)
B(-3,28,3,minecraft:soul_sand)
B(-3,29,3,minecraft:soul_sand)
B(-3,30,3,minecraft:soul_sand)
B(-3,31,3,minecraft:soul_sand)
B(-3,32,3,minecraft:soul_sand)
B(-3,33,3,minecraft:soul_sand)
B(-3,34,3,minecraft:soul_sand)
B(-3,35,3,minecraft:soul_sand)
B(-3,36,3,minecraft:soul_sand)
B(-3,37,3,minecraft:soul_sand)
B(-3,38,3,minecraft:soul_sand)
B(-3,39,3,minecraft:soul_sand)
B(-3,40,3,minecraft:soul_sand)
B(-3,41,3,minecraft:soul_sand)
B(-3,42,3,minecraft:soul_sand)
B(-3,43,3,minecraft:soul_sand)
B(-3,44,3,minecraft:soul_sand)
B(-3,45,3,minecraft:soul_sand)
B(-3,46,3,minecraft:soul_sand)
B(-3,47,3,minecraft:soul_sand)
B(-3,48,3,minecraft:soul_sand)
B(-3,49,3,minecraft:soul_sand)
B(-3,50,3,minecraft:soul_sand)
B(-3,3,4,minecraft:soul_sand)
B(-3,4,4,minecraft:soul_sand)
B(-3,5,4,minecraft:soul_sand)
B(-3,6,4,minecraft:soul_sand)
B(-3,7,4,minecraft:soul_sand)
B(-3,8,4,minecraft:soul_sand)
B(-3,9,4,minecraft:soul_sand)
B(-3,10,4,minecraft:soul_sand)
B(-3,11,4,minecraft:soul_sand)
B(-3,12,4,minecraft:soul_sand)
B(-3,13,4,minecraft:soul_sand)
B(-3,14,4,minecraft:soul_sand)
B(-3,15,4,minecraft:soul_sand)
B(-3,16,4,minecraft:soul_sand)
B(-3,17,4,minecraft:soul_sand)
B(-3,18,4,minecraft:soul_sand)
B(-3,19,4,minecraft:soul_sand)
B(-3,20,4,minecraft:soul_sand)
B(-3,21,4,minecraft:soul_sand)
B(-3,22,4,minecraft:soul_sand)
B(-3,23,4,minecraft:soul_sand)
B(-3,24,4,minecraft:soul_sand)
B(-3,25,4,minecraft:soul_sand)
B(-3,26,4,minecraft:soul_sand)
B(-3,27,4,minecraft:soul_sand)
B(-3,28,4,minecraft:soul_sand)
B(-3,29,4,minecraft:soul_sand)
B(-3,30,4,minecraft:soul_sand)
B(-3,31,4,minecraft:soul_sand)
B(-3,32,4,minecraft:soul_sand)
B(-3,33,4,minecraft:soul_sand)
B(-3,34,4,minecraft:soul_sand)
B(-3,35,4,minecraft:soul_sand)
B(-3,36,4,minecraft:soul_sand)
B(-3,37,4,minecraft:soul_sand)
B(-3,38,4,minecraft:soul_sand)
B(-3,39,4,minecraft:soul_sand)
B(-3,40,4,minecraft:soul_sand)
B(-3,41,4,minecraft:soul_sand)
B(-3,42,4,minecraft:soul_sand)
B(-3,43,4,minecraft:soul_sand)
B(-3,44,4,minecraft:soul_sand)
B(-3,45,4,minecraft:soul_sand)
B(-3,46,4,minecraft:soul_sand)
B(-3,47,4,minecraft:soul_sand)
B(-3,48,4,minecraft:soul_sand)
B(-3,49,4,minecraft:soul_sand)
B(-3,50,4,minecraft:soul_sand)
B(-3,3,5,minecraft:soul_sand)
B(-3,4,5,minecraft:soul_sand)
B(-3,5,5,minecraft:soul_sand)
B(-3,6,5,minecraft:soul_sand)
B(-3,7,5,minecraft:soul_sand)
B(-3,8,5,minecraft:soul_sand)
B(-3,9,5,minecraft:soul_sand)
B(-3,10,5,minecraft:soul_sand)
B(-3,11,5,minecraft:soul_sand)
B(-3,12,5,minecraft:soul_sand)
B(-3,13,5,minecraft:soul_sand)
B(-3,14,5,minecraft:soul_sand)
B(-3,15,5,minecraft:soul_sand)
B(-3,16,5,minecraft:soul_sand)
B(-3,17,5,minecraft:soul_sand)
B(-3,18,5,minecraft:soul_sand)
B(-3,19,5,minecraft:soul_sand)
B(-3,20,5,minecraft:soul_sand)
B(-3,21,5,minecraft:soul_sand)
B(-3,22,5,minecraft:soul_sand)
B(-3,23,5,minecraft:soul_sand)
B(-3,24,5,minecraft:soul_sand)
B(-3,25,5,minecraft:soul_sand)
B(-3,26,5,minecraft:soul_sand)
B(-3,27,5,minecraft:soul_sand)
B(-3,28,5,minecraft:soul_sand)
B(-3,29,5,minecraft:soul_sand)
B(-3,30,5,minecraft:soul_sand)
B(-3,31,5,minecraft:soul_sand)
B(-3,32,5,minecraft:soul_sand)
B(-3,33,5,minecraft:soul_sand)
B(-3,34,5,minecraft:soul_sand)
B(-3,35,5,minecraft:soul_sand)
B(-3,36,5,minecraft:soul_sand)
B(-3,37,5,minecraft:soul_sand)
B(-3,38,5,minecraft:soul_sand)
B(-3,39,5,minecraft:soul_sand)
B(-3,40,5,minecraft:soul_sand)
B(-3,41,5,minecraft:soul_sand)
B(-3,42,5,minecraft:soul_sand)
B(-3,43,5,minecraft:soul_sand)
B(-3,44,5,minecraft:soul_sand)
B(-3,45,5,minecraft:soul_sand)
B(-3,46,5,minecraft:soul_sand)
B(-3,47,5,minecraft:soul_sand)
B(-3,48,5,minecraft:soul_sand)
B(-3,49,5,minecraft:soul_sand)
B(-3,50,5,minecraft:soul_sand)
B(-3,3,6,minecraft:soul_sand)
B(-3,4,6,minecraft:soul_sand)
B(-3,5,6,minecraft:soul_sand)
B(-3,6,6,minecraft:soul_sand)
B(-3,7,6,minecraft:soul_sand)
B(-3,8,6,minecraft:soul_sand)
B(-3,9,6,minecraft:soul_sand)
B(-3,10,6,minecraft:soul_sand)
B(-3,11,6,minecraft:soul_sand)
B(-3,12,6,minecraft:soul_sand)
B(-3,13,6,minecraft:soul_sand)
B(-3,14,6,minecraft:soul_sand)
B(-3,15,6,minecraft:soul_sand)
B(-3,16,6,minecraft:soul_sand)
B(-3,17,6,minecraft:soul_sand)
B(-3,18,6,minecraft:soul_sand)
B(-3,19,6,minecraft:soul_sand)
B(-3,20,6,minecraft:soul_sand)
B(-3,21,6,minecraft:soul_sand)
B(-3,22,6,minecraft:soul_sand)
B(-3,23,6,minecraft:soul_sand)
B(-3,24,6,minecraft:soul_sand)
B(-3,25,6,minecraft:soul_sand)
B(-3,26,6,minecraft:soul_sand)
B(-3,27,6,minecraft:soul_sand)
B(-3,28,6,minecraft:soul_sand)
B(-3,29,6,minecraft:soul_sand)
B(-3,30,6,minecraft:soul_sand)
B(-3,31,6,minecraft:soul_sand)
B(-3,32,6,minecraft:soul_sand)
B(-3,33,6,minecraft:soul_sand)
B(-3,34,6,minecraft:soul_sand)
B(-3,35,6,minecraft:soul_sand)
B(-3,36,6,minecraft:soul_sand)
B(-3,37,6,minecraft:soul_sand)
B(-3,38,6,minecraft:soul_sand)
B(-3,39,6,minecraft:soul_sand)
B(-3,40,6,minecraft:soul_sand)
B(-3,41,6,minecraft:soul_sand)
B(-3,42,6,minecraft:soul_sand)
B(-3,43,6,minecraft:soul_sand)
B(-3,44,6,minecraft:soul_sand)
B(-3,45,6,minecraft:soul_sand)
B(-3,46,6,minecraft:soul_sand)
B(-3,47,6,minecraft:soul_sand)
B(-3,48,6,minecraft:soul_sand)
B(-3,49,6,minecraft:soul_sand)
B(-3,50,6,minecraft:soul_sand)
B(-3,3,7,minecraft:soul_sand)
B(-3,4,7,minecraft:soul_sand)
B(-3,5,7,minecraft:soul_sand)
B(-3,6,7,minecraft:soul_sand)
B(-3,7,7,minecraft:soul_sand)
B(-3,8,7,minecraft:soul_sand)
B(-3,9,7,minecraft:soul_sand)
B(-3,10,7,minecraft:soul_sand)
B(-3,11,7,minecraft:soul_sand)
B(-3,12,7,minecraft:soul_sand)
B(-3,13,7,minecraft:soul_sand)
B(-3,14,7,minecraft:soul_sand)
B(-3,15,7,minecraft:soul_sand)
B(-3,16,7,minecraft:soul_sand)
B(-3,17,7,minecraft:soul_sand)
B(-3,18,7,minecraft:soul_sand)
B(-3,19,7,minecraft:soul_sand)
B(-3,20,7,minecraft:soul_sand)
B(-3,21,7,minecraft:soul_sand)
B(-3,22,7,minecraft:soul_sand)
B(-3,23,7,minecraft:soul_sand)
B(-3,24,7,minecraft:soul_sand)
B(-3,25,7,minecraft:soul_sand)
B(-3,26,7,minecraft:soul_sand)
B(-3,27,7,minecraft:soul_sand)
B(-3,28,7,minecraft:soul_sand)
B(-3,29,7,minecraft:soul_sand)
B(-3,30,7,minecraft:soul_sand)
B(-3,31,7,minecraft:soul_sand)
B(-3,32,7,minecraft:soul_sand)
B(-3,33,7,minecraft:soul_sand)
B(-3,34,7,minecraft:soul_sand)
B(-3,35,7,minecraft:soul_sand)
B(-3,36,7,minecraft:soul_sand)
B(-3,37,7,minecraft:soul_sand)
B(-3,38,7,minecraft:soul_sand)
B(-3,39,7,minecraft:soul_sand)
B(-3,40,7,minecraft:soul_sand)
B(-3,41,7,minecraft:soul_sand)
B(-3,42,7,minecraft:soul_sand)
B(-3,43,7,minecraft:soul_sand)
B(-3,44,7,minecraft:soul_sand)
B(-3,45,7,minecraft:soul_sand)
B(-3,46,7,minecraft:soul_sand)
B(-3,47,7,minecraft:soul_sand)
B(-3,48,7,minecraft:soul_sand)
B(-3,49,7,minecraft:soul_sand)
B(-3,50,7,minecraft:soul_sand)
B(-3,5,8,minecraft:soul_sand)
B(-3,6,8,minecraft:soul_sand)
B(-3,7,8,minecraft:soul_sand)
B(-3,8,8,minecraft:soul_sand)
B(-3,9,8,minecraft:soul_sand)
B(-3,10,8,minecraft:soul_sand)
B(-3,11,8,minecraft:soul_sand)
B(-3,12,8,minecraft:soul_sand)
B(-3,13,8,minecraft:soul_sand)
B(-3,14,8,minecraft:soul_sand)
B(-3,15,8,minecraft:soul_sand)
B(-3,16,8,minecraft:soul_sand)
B(-3,17,8,minecraft:soul_sand)
B(-3,18,8,minecraft:soul_sand)
B(-3,19,8,minecraft:soul_sand)
B(-3,20,8,minecraft:soul_sand)
B(-3,21,8,minecraft:soul_sand)
B(-3,22,8,minecraft:soul_sand)
B(-3,23,8,minecraft:soul_sand)
B(-3,24,8,minecraft:soul_sand)
B(-3,25,8,minecraft:soul_sand)
B(-3,26,8,minecraft:soul_sand)
B(-3,27,8,minecraft:soul_sand)
B(-3,28,8,minecraft:soul_sand)
B(-3,29,8,minecraft:soul_sand)
B(-3,30,8,minecraft:soul_sand)
B(-3,31,8,minecraft:soul_sand)
B(-3,32,8,minecraft:soul_sand)
B(-3,33,8,minecraft:soul_sand)
B(-3,34,8,minecraft:soul_sand)
B(-3,35,8,minecraft:soul_sand)
B(-3,36,8,minecraft:soul_sand)
B(-3,37,8,minecraft:soul_sand)
B(-3,38,8,minecraft:soul_sand)
B(-3,39,8,minecraft:soul_sand)
B(-3,40,8,minecraft:soul_sand)
B(-3,41,8,minecraft:soul_sand)
B(-3,42,8,minecraft:soul_sand)
B(-3,43,8,minecraft:soul_sand)
B(-3,44,8,minecraft:soul_sand)
B(-3,45,8,minecraft:soul_sand)
B(-3,46,8,minecraft:soul_sand)
B(-3,47,8,minecraft:soul_sand)
B(-3,48,8,minecraft:soul_sand)
B(-3,49,8,minecraft:soul_sand)
B(-3,50,8,minecraft:soul_sand)
B(-2,40,-7,minecraft:soul_sand)
B(-2,41,-7,minecraft:soul_sand)
B(-2,42,-7,minecraft:soul_sand)
B(-2,43,-7,minecraft:soul_sand)
B(-2,44,-7,minecraft:soul_sand)
B(-2,45,-7,minecraft:soul_sand)
B(-2,46,-7,minecraft:soul_sand)
B(-2,47,-7,minecraft:soul_sand)
B(-2,48,-7,minecraft:soul_sand)
B(-2,49,-7,minecraft:soul_sand)
B(-2,50,-7,minecraft:soul_sand)
B(-2,37,-6,minecraft:soul_sand)
B(-2,38,-6,minecraft:soul_sand)
B(-2,39,-6,minecraft:soul_sand)
B(-2,40,-6,minecraft:soul_sand)
B(-2,41,-6,minecraft:soul_sand)
B(-2,42,-6,minecraft:soul_sand)
B(-2,43,-6,minecraft:soul_sand)
B(-2,44,-6,minecraft:soul_sand)
B(-2,45,-6,minecraft:soul_sand)
B(-2,46,-6,minecraft:soul_sand)
B(-2,47,-6,minecraft:soul_sand)
B(-2,48,-6,minecraft:soul_sand)
B(-2,49,-6,minecraft:soul_sand)
B(-2,50,-6,minecraft:soul_sand)
B(-2,34,-5,minecraft:soul_sand)
B(-2,35,-5,minecraft:soul_sand)
B(-2,36,-5,minecraft:soul_sand)
B(-2,37,-5,minecraft:soul_sand)
B(-2,38,-5,minecraft:soul_sand)
B(-2,39,-5,minecraft:soul_sand)
B(-2,40,-5,minecraft:soul_sand)
B(-2,41,-5,minecraft:soul_sand)
B(-2,42,-5,minecraft:soul_sand)
B(-2,43,-5,minecraft:soul_sand)
B(-2,44,-5,minecraft:soul_sand)
B(-2,45,-5,minecraft:soul_sand)
B(-2,46,-5,minecraft:soul_sand)
B(-2,47,-5,minecraft:soul_sand)
B(-2,48,-5,minecraft:soul_sand)
B(-2,49,-5,minecraft:soul_sand)
B(-2,50,-5,minecraft:soul_sand)
B(-2,32,-4,minecraft:soul_sand)
B(-2,33,-4,minecraft:soul_sand)
B(-2,34,-4,minecraft:soul_sand)
B(-2,35,-4,minecraft:soul_sand)
B(-2,36,-4,minecraft:soul_sand)
B(-2,37,-4,minecraft:soul_sand)
B(-2,38,-4,minecraft:soul_sand)
B(-2,39,-4,minecraft:soul_sand)
B(-2,40,-4,minecraft:soul_sand)
B(-2,41,-4,minecraft:soul_sand)
B(-2,42,-4,minecraft:soul_sand)
B(-2,43,-4,minecraft:soul_sand)
B(-2,44,-4,minecraft:soul_sand)
B(-2,45,-4,minecraft:soul_sand)
B(-2,46,-4,minecraft:soul_sand)
B(-2,47,-4,minecraft:soul_sand)
B(-2,48,-4,minecraft:soul_sand)
B(-2,49,-4,minecraft:soul_sand)
B(-2,50,-4,minecraft:soul_sand)
B(-2,27,-3,minecraft:soul_sand)
B(-2,28,-3,minecraft:soul_sand)
B(-2,29,-3,minecraft:soul_sand)
B(-2,30,-3,minecraft:soul_sand)
B(-2,31,-3,minecraft:soul_sand)
B(-2,32,-3,minecraft:soul_sand)
B(-2,33,-3,minecraft:soul_sand)
B(-2,34,-3,minecraft:soul_sand)
B(-2,35,-3,minecraft:soul_sand)
B(-2,36,-3,minecraft:soul_sand)
B(-2,37,-3,minecraft:soul_sand)
B(-2,38,-3,minecraft:soul_sand)
B(-2,39,-3,minecraft:soul_sand)
B(-2,40,-3,minecraft:soul_sand)
B(-2,41,-3,minecraft:soul_sand)
B(-2,42,-3,minecraft:soul_sand)
B(-2,43,-3,minecraft:soul_sand)
B(-2,44,-3,minecraft:soul_sand)
B(-2,45,-3,minecraft:soul_sand)
B(-2,46,-3,minecraft:soul_sand)
B(-2,47,-3,minecraft:soul_sand)
B(-2,48,-3,minecraft:soul_sand)
B(-2,49,-3,minecraft:soul_sand)
B(-2,50,-3,minecraft:soul_sand)
B(-2,23,-2,minecraft:soul_sand)
B(-2,24,-2,minecraft:soul_sand)
B(-2,25,-2,minecraft:soul_sand)
B(-2,26,-2,minecraft:soul_sand)
B(-2,27,-2,minecraft:soul_sand)
B(-2,28,-2,minecraft:soul_sand)
B(-2,29,-2,minecraft:soul_sand)
B(-2,30,-2,minecraft:soul_sand)
B(-2,31,-2,minecraft:soul_sand)
B(-2,32,-2,minecraft:soul_sand)
B(-2,33,-2,minecraft:soul_sand)
B(-2,34,-2,minecraft:soul_sand)
B(-2,35,-2,minecraft:soul_sand)
B(-2,36,-2,minecraft:soul_sand)
B(-2,37,-2,minecraft:soul_sand)
B(-2,38,-2,minecraft:soul_sand)
B(-2,39,-2,minecraft:soul_sand)
B(-2,40,-2,minecraft:soul_sand)
B(-2,41,-2,minecraft:soul_sand)
B(-2,42,-2,minecraft:soul_sand)
B(-2,43,-2,minecraft:soul_sand)
B(-2,44,-2,minecraft:soul_sand)
B(-2,45,-2,minecraft:soul_sand)
B(-2,46,-2,minecraft:soul_sand)
B(-2,47,-2,minecraft:soul_sand)
B(-2,48,-2,minecraft:soul_sand)
B(-2,49,-2,minecraft:soul_sand)
B(-2,50,-2,minecraft:soul_sand)
B(-2,20,-1,minecraft:soul_sand)
B(-2,21,-1,minecraft:soul_sand)
B(-2,22,-1,minecraft:soul_sand)
B(-2,23,-1,minecraft:soul_sand)
B(-2,24,-1,minecraft:soul_sand)
B(-2,25,-1,minecraft:soul_sand)
B(-2,26,-1,minecraft:soul_sand)
B(-2,27,-1,minecraft:soul_sand)
B(-2,28,-1,minecraft:soul_sand)
B(-2,29,-1,minecraft:soul_sand)
B(-2,30,-1,minecraft:soul_sand)
B(-2,31,-1,minecraft:soul_sand)
B(-2,32,-1,minecraft:soul_sand)
B(-2,33,-1,minecraft:soul_sand)
B(-2,34,-1,minecraft:soul_sand)
B(-2,35,-1,minecraft:soul_sand)
B(-2,36,-1,minecraft:soul_sand)
B(-2,37,-1,minecraft:soul_sand)
B(-2,38,-1,minecraft:soul_sand)
B(-2,39,-1,minecraft:soul_sand)
B(-2,40,-1,minecraft:soul_sand)
B(-2,41,-1,minecraft:soul_sand)
B(-2,42,-1,minecraft:soul_sand)
B(-2,43,-1,minecraft:soul_sand)
B(-2,44,-1,minecraft:soul_sand)
B(-2,45,-1,minecraft:soul_sand)
B(-2,46,-1,minecraft:soul_sand)
B(-2,47,-1,minecraft:soul_sand)
B(-2,48,-1,minecraft:soul_sand)
B(-2,49,-1,minecraft:soul_sand)
B(-2,50,-1,minecraft:soul_sand)
B(-2,18,0,minecraft:soul_sand)
B(-2,19,0,minecraft:soul_sand)
B(-2,20,0,minecraft:soul_sand)
B(-2,21,0,minecraft:soul_sand)
B(-2,22,0,minecraft:soul_sand)
B(-2,23,0,minecraft:soul_sand)
B(-2,24,0,minecraft:soul_sand)
B(-2,25,0,minecraft:soul_sand)
B(-2,26,0,minecraft:soul_sand)
B(-2,27,0,minecraft:soul_sand)
B(-2,28,0,minecraft:soul_sand)
B(-2,29,0,minecraft:soul_sand)
B(-2,30,0,minecraft:soul_sand)
B(-2,31,0,minecraft:soul_sand)
B(-2,32,0,minecraft:soul_sand)
B(-2,33,0,minecraft:soul_sand)
B(-2,34,0,minecraft:soul_sand)
B(-2,35,0,minecraft:soul_sand)
B(-2,36,0,minecraft:soul_sand)
B(-2,37,0,minecraft:soul_sand)
B(-2,38,0,minecraft:soul_sand)
B(-2,39,0,minecraft:soul_sand)
B(-2,40,0,minecraft:soul_sand)
B(-2,41,0,minecraft:soul_sand)
B(-2,42,0,minecraft:soul_sand)
B(-2,43,0,minecraft:soul_sand)
B(-2,44,0,minecraft:soul_sand)
B(-2,45,0,minecraft:soul_sand)
B(-2,46,0,minecraft:soul_sand)
B(-2,47,0,minecraft:soul_sand)
B(-2,48,0,minecraft:soul_sand)
B(-2,49,0,minecraft:soul_sand)
B(-2,50,0,minecraft:soul_sand)
B(-2,17,1,minecraft:soul_sand)
B(-2,18,1,minecraft:soul_sand)
B(-2,19,1,minecraft:soul_sand)
B(-2,20,1,minecraft:soul_sand)
B(-2,21,1,minecraft:soul_sand)
B(-2,22,1,minecraft:soul_sand)
B(-2,23,1,minecraft:soul_sand)
B(-2,24,1,minecraft:soul_sand)
B(-2,25,1,minecraft:soul_sand)
B(-2,26,1,minecraft:soul_sand)
B(-2,27,1,minecraft:soul_sand)
B(-2,28,1,minecraft:soul_sand)
B(-2,29,1,minecraft:soul_sand)
B(-2,30,1,minecraft:soul_sand)
B(-2,31,1,minecraft:soul_sand)
B(-2,32,1,minecraft:soul_sand)
B(-2,33,1,minecraft:soul_sand)
B(-2,34,1,minecraft:soul_sand)
B(-2,35,1,minecraft:soul_sand)
B(-2,36,1,minecraft:soul_sand)
B(-2,37,1,minecraft:soul_sand)
B(-2,38,1,minecraft:soul_sand)
B(-2,39,1,minecraft:soul_sand)
B(-2,40,1,minecraft:soul_sand)
B(-2,41,1,minecraft:soul_sand)
B(-2,42,1,minecraft:soul_sand)
B(-2,43,1,minecraft:soul_sand)
B(-2,44,1,minecraft:soul_sand)
B(-2,45,1,minecraft:soul_sand)
B(-2,46,1,minecraft:soul_sand)
B(-2,47,1,minecraft:soul_sand)
B(-2,48,1,minecraft:soul_sand)
B(-2,49,1,minecraft:soul_sand)
B(-2,50,1,minecraft:soul_sand)
B(-2,7,2,minecraft:soul_sand)
B(-2,8,2,minecraft:soul_sand)
B(-2,9,2,minecraft:soul_sand)
B(-2,10,2,minecraft:soul_sand)
B(-2,11,2,minecraft:soul_sand)
B(-2,12,2,minecraft:soul_sand)
B(-2,13,2,minecraft:soul_sand)
B(-2,14,2,minecraft:soul_sand)
B(-2,15,2,minecraft:soul_sand)
B(-2,16,2,minecraft:soul_sand)
B(-2,17,2,minecraft:soul_sand)
B(-2,18,2,minecraft:soul_sand)
B(-2,19,2,minecraft:soul_sand)
B(-2,20,2,minecraft:soul_sand)
B(-2,21,2,minecraft:soul_sand)
B(-2,22,2,minecraft:soul_sand)
B(-2,23,2,minecraft:soul_sand)
B(-2,24,2,minecraft:soul_sand)
B(-2,25,2,minecraft:soul_sand)
B(-2,26,2,minecraft:soul_sand)
B(-2,27,2,minecraft:soul_sand)
B(-2,28,2,minecraft:soul_sand)
B(-2,29,2,minecraft:soul_sand)
B(-2,30,2,minecraft:soul_sand)
B(-2,31,2,minecraft:soul_sand)
B(-2,32,2,minecraft:soul_sand)
B(-2,33,2,minecraft:soul_sand)
B(-2,34,2,minecraft:soul_sand)
B(-2,35,2,minecraft:soul_sand)
B(-2,36,2,minecraft:soul_sand)
B(-2,37,2,minecraft:soul_sand)
B(-2,38,2,minecraft:soul_sand)
B(-2,39,2,minecraft:soul_sand)
B(-2,40,2,minecraft:soul_sand)
B(-2,41,2,minecraft:soul_sand)
B(-2,42,2,minecraft:soul_sand)
B(-2,43,2,minecraft:soul_sand)
B(-2,44,2,minecraft:soul_sand)
B(-2,45,2,minecraft:soul_sand)
B(-2,46,2,minecraft:soul_sand)
B(-2,47,2,minecraft:soul_sand)
B(-2,48,2,minecraft:soul_sand)
B(-2,49,2,minecraft:soul_sand)
B(-2,50,2,minecraft:soul_sand)
B(-2,3,3,minecraft:soul_sand)
B(-2,4,3,minecraft:soul_sand)
B(-2,5,3,minecraft:soul_sand)
B(-2,6,3,minecraft:soul_sand)
B(-2,7,3,minecraft:soul_sand)
B(-2,8,3,minecraft:soul_sand)
B(-2,9,3,minecraft:soul_sand)
B(-2,10,3,minecraft:soul_sand)
B(-2,11,3,minecraft:soul_sand)
B(-2,12,3,minecraft:soul_sand)
B(-2,13,3,minecraft:soul_sand)
B(-2,14,3,minecraft:soul_sand)
B(-2,15,3,minecraft:soul_sand)
B(-2,16,3,minecraft:soul_sand)
B(-2,17,3,minecraft:soul_sand)
B(-2,18,3,minecraft:soul_sand)
B(-2,19,3,minecraft:soul_sand)
B(-2,20,3,minecraft:soul_sand)
B(-2,21,3,minecraft:soul_sand)
B(-2,22,3,minecraft:soul_sand)
B(-2,23,3,minecraft:soul_sand)
B(-2,24,3,minecraft:soul_sand)
B(-2,25,3,minecraft:soul_sand)
B(-2,26,3,minecraft:soul_sand)
B(-2,27,3,minecraft:soul_sand)
B(-2,28,3,minecraft:soul_sand)
B(-2,29,3,minecraft:soul_sand)
B(-2,30,3,minecraft:soul_sand)
B(-2,31,3,minecraft:soul_sand)
B(-2,32,3,minecraft:soul_sand)
B(-2,33,3,minecraft:soul_sand)
B(-2,34,3,minecraft:soul_sand)
B(-2,35,3,minecraft:soul_sand)
B(-2,36,3,minecraft:soul_sand)
B(-2,37,3,minecraft:soul_sand)
B(-2,38,3,minecraft:soul_sand)
B(-2,39,3,minecraft:soul_sand)
B(-2,40,3,minecraft:soul_sand)
B(-2,41,3,minecraft:soul_sand)
B(-2,42,3,minecraft:soul_sand)
B(-2,43,3,minecraft:soul_sand)
B(-2,44,3,minecraft:soul_sand)
B(-2,45,3,minecraft:soul_sand)
B(-2,46,3,minecraft:soul_sand)
B(-2,47,3,minecraft:soul_sand)
B(-2,48,3,minecraft:soul_sand)
B(-2,49,3,minecraft:soul_sand)
B(-2,50,3,minecraft:soul_sand)
B(-2,3,4,minecraft:soul_sand)
B(-2,4,4,minecraft:soul_sand)
B(-2,5,4,minecraft:soul_sand)
B(-2,6,4,minecraft:soul_sand)
B(-2,7,4,minecraft:soul_sand)
B(-2,8,4,minecraft:soul_sand)
B(-2,9,4,minecraft:soul_sand)
B(-2,10,4,minecraft:soul_sand)
B(-2,11,4,minecraft:soul_sand)
B(-2,12,4,minecraft:soul_sand)
B(-2,13,4,minecraft:soul_sand)
B(-2,14,4,minecraft:soul_sand)
B(-2,15,4,minecraft:soul_sand)
B(-2,16,4,minecraft:soul_sand)
B(-2,17,4,minecraft:soul_sand)
B(-2,18,4,minecraft:soul_sand)
B(-2,19,4,minecraft:soul_sand)
B(-2,20,4,minecraft:soul_sand)
B(-2,21,4,minecraft:soul_sand)
B(-2,22,4,minecraft:soul_sand)
B(-2,23,4,minecraft:soul_sand)
B(-2,24,4,minecraft:soul_sand)
B(-2,25,4,minecraft:soul_sand)
B(-2,26,4,minecraft:soul_sand)
B(-2,27,4,minecraft:soul_sand)
B(-2,28,4,minecraft:soul_sand)
B(-2,29,4,minecraft:soul_sand)
B(-2,30,4,minecraft:soul_sand)
B(-2,31,4,minecraft:soul_sand)
B(-2,32,4,minecraft:soul_sand)
B(-2,33,4,minecraft:soul_sand)
B(-2,34,4,minecraft:soul_sand)
B(-2,35,4,minecraft:soul_sand)
B(-2,36,4,minecraft:soul_sand)
B(-2,37,4,minecraft:soul_sand)
B(-2,38,4,minecraft:soul_sand)
B(-2,39,4,minecraft:soul_sand)
B(-2,40,4,minecraft:soul_sand)
B(-2,41,4,minecraft:soul_sand)
B(-2,42,4,minecraft:soul_sand)
B(-2,43,4,minecraft:soul_sand)
B(-2,44,4,minecraft:soul_sand)
B(-2,45,4,minecraft:soul_sand)
B(-2,46,4,minecraft:soul_sand)
B(-2,47,4,minecraft:soul_sand)
B(-2,48,4,minecraft:soul_sand)
B(-2,49,4,minecraft:soul_sand)
B(-2,50,4,minecraft:soul_sand)
B(-2,2,5,minecraft:soul_sand)
B(-2,3,5,minecraft:soul_sand)
B(-2,4,5,minecraft:soul_sand)
B(-2,5,5,minecraft:soul_sand)
B(-2,6,5,minecraft:soul_sand)
B(-2,7,5,minecraft:soul_sand)
B(-2,8,5,minecraft:soul_sand)
B(-2,9,5,minecraft:soul_sand)
B(-2,10,5,minecraft:soul_sand)
B(-2,11,5,minecraft:soul_sand)
B(-2,12,5,minecraft:soul_sand)
B(-2,13,5,minecraft:soul_sand)
B(-2,14,5,minecraft:soul_sand)
B(-2,15,5,minecraft:soul_sand)
B(-2,16,5,minecraft:soul_sand)
B(-2,17,5,minecraft:soul_sand)
B(-2,18,5,minecraft:soul_sand)
B(-2,19,5,minecraft:soul_sand)
B(-2,20,5,minecraft:soul_sand)
B(-2,21,5,minecraft:soul_sand)
B(-2,22,5,minecraft:soul_sand)
B(-2,23,5,minecraft:soul_sand)
B(-2,24,5,minecraft:soul_sand)
B(-2,25,5,minecraft:soul_sand)
B(-2,26,5,minecraft:soul_sand)
B(-2,27,5,minecraft:soul_sand)
B(-2,28,5,minecraft:soul_sand)
B(-2,29,5,minecraft:soul_sand)
B(-2,30,5,minecraft:soul_sand)
B(-2,31,5,minecraft:soul_sand)
B(-2,32,5,minecraft:soul_sand)
B(-2,33,5,minecraft:soul_sand)
B(-2,34,5,minecraft:soul_sand)
B(-2,35,5,minecraft:soul_sand)
B(-2,36,5,minecraft:soul_sand)
B(-2,37,5,minecraft:soul_sand)
B(-2,38,5,minecraft:soul_sand)
B(-2,39,5,minecraft:soul_sand)
B(-2,40,5,minecraft:soul_sand)
B(-2,41,5,minecraft:soul_sand)
B(-2,42,5,minecraft:soul_sand)
B(-2,43,5,minecraft:soul_sand)
B(-2,44,5,minecraft:soul_sand)
B(-2,45,5,minecraft:soul_sand)
B(-2,46,5,minecraft:soul_sand)
B(-2,47,5,minecraft:soul_sand)
B(-2,48,5,minecraft:soul_sand)
B(-2,49,5,minecraft:soul_sand)
B(-2,50,5,minecraft:soul_sand)
B(-2,2,6,minecraft:soul_sand)
B(-2,3,6,minecraft:soul_sand)
B(-2,4,6,minecraft:soul_sand)
B(-2,5,6,minecraft:soul_sand)
B(-2,6,6,minecraft:soul_sand)
B(-2,7,6,minecraft:soul_sand)
B(-2,8,6,minecraft:soul_sand)
B(-2,9,6,minecraft:soul_sand)
B(-2,10,6,minecraft:soul_sand)
B(-2,11,6,minecraft:soul_sand)
B(-2,12,6,minecraft:soul_sand)
B(-2,13,6,minecraft:soul_sand)
B(-2,14,6,minecraft:soul_sand)
B(-2,15,6,minecraft:soul_sand)
B(-2,16,6,minecraft:soul_sand)
B(-2,17,6,minecraft:soul_sand)
B(-2,18,6,minecraft:soul_sand)
B(-2,19,6,minecraft:soul_sand)
B(-2,20,6,minecraft:soul_sand)
B(-2,21,6,minecraft:soul_sand)
B(-2,22,6,minecraft:soul_sand)
B(-2,23,6,minecraft:soul_sand)
B(-2,24,6,minecraft:soul_sand)
B(-2,25,6,minecraft:soul_sand)
B(-2,26,6,minecraft:soul_sand)
B(-2,27,6,minecraft:soul_sand)
B(-2,28,6,minecraft:soul_sand)
B(-2,29,6,minecraft:soul_sand)
B(-2,30,6,minecraft:soul_sand)
B(-2,31,6,minecraft:soul_sand)
B(-2,32,6,minecraft:soul_sand)
B(-2,33,6,minecraft:soul_sand)
B(-2,34,6,minecraft:soul_sand)
B(-2,35,6,minecraft:soul_sand)
B(-2,36,6,minecraft:soul_sand)
B(-2,37,6,minecraft:soul_sand)
B(-2,38,6,minecraft:soul_sand)
B(-2,39,6,minecraft:soul_sand)
B(-2,40,6,minecraft:soul_sand)
B(-2,41,6,minecraft:soul_sand)
B(-2,42,6,minecraft:soul_sand)
B(-2,43,6,minecraft:soul_sand)
B(-2,44,6,minecraft:soul_sand)
B(-2,45,6,minecraft:soul_sand)
B(-2,46,6,minecraft:soul_sand)
B(-2,47,6,minecraft:soul_sand)
B(-2,48,6,minecraft:soul_sand)
B(-2,49,6,minecraft:soul_sand)
B(-2,50,6,minecraft:soul_sand)
B(-2,3,7,minecraft:soul_sand)
B(-2,4,7,minecraft:soul_sand)
B(-2,5,7,minecraft:soul_sand)
B(-2,6,7,minecraft:soul_sand)
B(-2,7,7,minecraft:soul_sand)
B(-2,8,7,minecraft:soul_sand)
B(-2,9,7,minecraft:soul_sand)
B(-2,10,7,minecraft:soul_sand)
B(-2,11,7,minecraft:soul_sand)
B(-2,12,7,minecraft:soul_sand)
B(-2,13,7,minecraft:soul_sand)
B(-2,14,7,minecraft:soul_sand)
B(-2,15,7,minecraft:soul_sand)
B(-2,16,7,minecraft:soul_sand)
B(-2,17,7,minecraft:soul_sand)
B(-2,18,7,minecraft:soul_sand)
B(-2,19,7,minecraft:soul_sand)
B(-2,20,7,minecraft:soul_sand)
B(-2,21,7,minecraft:soul_sand)
B(-2,22,7,minecraft:soul_sand)
B(-2,23,7,minecraft:soul_sand)
B(-2,24,7,minecraft:soul_sand)
B(-2,25,7,minecraft:soul_sand)
B(-2,26,7,minecraft:soul_sand)
B(-2,27,7,minecraft:soul_sand)
B(-2,28,7,minecraft:soul_sand)
B(-2,29,7,minecraft:soul_sand)
B(-2,30,7,minecraft:soul_sand)
B(-2,31,7,minecraft:soul_sand)
B(-2,32,7,minecraft:soul_sand)
B(-2,33,7,minecraft:soul_sand)
B(-2,34,7,minecraft:soul_sand)
B(-2,35,7,minecraft:soul_sand)
B(-2,36,7,minecraft:soul_sand)
B(-2,37,7,minecraft:soul_sand)
B(-2,38,7,minecraft:soul_sand)
B(-2,39,7,minecraft:soul_sand)
B(-2,40,7,minecraft:soul_sand)
B(-2,41,7,minecraft:soul_sand)
B(-2,42,7,minecraft:soul_sand)
B(-2,43,7,minecraft:soul_sand)
B(-2,44,7,minecraft:soul_sand)
B(-2,45,7,minecraft:soul_sand)
B(-2,46,7,minecraft:soul_sand)
B(-2,47,7,minecraft:soul_sand)
B(-2,48,7,minecraft:soul_sand)
B(-2,49,7,minecraft:soul_sand)
B(-2,50,7,minecraft:soul_sand)
B(-2,4,8,minecraft:soul_sand)
B(-2,5,8,minecraft:soul_sand)
B(-2,6,8,minecraft:soul_sand)
B(-2,7,8,minecraft:soul_sand)
B(-2,8,8,minecraft:soul_sand)
B(-2,9,8,minecraft:soul_sand)
B(-2,10,8,minecraft:soul_sand)
B(-2,11,8,minecraft:soul_sand)
B(-2,12,8,minecraft:soul_sand)
B(-2,13,8,minecraft:soul_sand)
B(-2,14,8,minecraft:soul_sand)
B(-2,15,8,minecraft:soul_sand)
B(-2,16,8,minecraft:soul_sand)
B(-2,17,8,minecraft:soul_sand)
B(-2,18,8,minecraft:soul_sand)
B(-2,19,8,minecraft:soul_sand)
B(-2,20,8,minecraft:soul_sand)
B(-2,21,8,minecraft:soul_sand)
B(-2,22,8,minecraft:soul_sand)
B(-2,23,8,minecraft:soul_sand)
B(-2,24,8,minecraft:soul_sand)
B(-2,25,8,minecraft:soul_sand)
B(-2,26,8,minecraft:soul_sand)
B(-2,27,8,minecraft:soul_sand)
B(-2,28,8,minecraft:soul_sand)
B(-2,29,8,minecraft:soul_sand)
B(-2,30,8,minecraft:soul_sand)
B(-2,31,8,minecraft:soul_sand)
B(-2,32,8,minecraft:soul_sand)
B(-2,33,8,minecraft:soul_sand)
B(-2,34,8,minecraft:soul_sand)
B(-2,35,8,minecraft:soul_sand)
B(-2,36,8,minecraft:soul_sand)
B(-2,37,8,minecraft:soul_sand)
B(-2,38,8,minecraft:soul_sand)
B(-2,39,8,minecraft:soul_sand)
B(-2,40,8,minecraft:soul_sand)
B(-2,41,8,minecraft:soul_sand)
B(-2,42,8,minecraft:soul_sand)
B(-2,43,8,minecraft:soul_sand)
B(-2,44,8,minecraft:soul_sand)
B(-2,45,8,minecraft:soul_sand)
B(-2,46,8,minecraft:soul_sand)
B(-2,47,8,minecraft:soul_sand)
B(-2,48,8,minecraft:soul_sand)
B(-2,49,8,minecraft:soul_sand)
B(-2,50,8,minecraft:soul_sand)
B(-1,40,-7,minecraft:soul_sand)
B(-1,41,-7,minecraft:soul_sand)
B(-1,42,-7,minecraft:soul_sand)
B(-1,43,-7,minecraft:soul_sand)
B(-1,44,-7,minecraft:soul_sand)
B(-1,45,-7,minecraft:soul_sand)
B(-1,46,-7,minecraft:soul_sand)
B(-1,47,-7,minecraft:soul_sand)
B(-1,48,-7,minecraft:soul_sand)
B(-1,49,-7,minecraft:soul_sand)
B(-1,50,-7,minecraft:soul_sand)
B(-1,37,-6,minecraft:soul_sand)
B(-1,38,-6,minecraft:soul_sand)
B(-1,39,-6,minecraft:soul_sand)
B(-1,40,-6,minecraft:soul_sand)
B(-1,41,-6,minecraft:soul_sand)
B(-1,42,-6,minecraft:soul_sand)
B(-1,43,-6,minecraft:soul_sand)
B(-1,44,-6,minecraft:soul_sand)
B(-1,45,-6,minecraft:soul_sand)
B(-1,46,-6,minecraft:soul_sand)
B(-1,47,-6,minecraft:soul_sand)
B(-1,48,-6,minecraft:soul_sand)
B(-1,49,-6,minecraft:soul_sand)
B(-1,50,-6,minecraft:soul_sand)
B(-1,34,-5,minecraft:soul_sand)
B(-1,35,-5,minecraft:soul_sand)
B(-1,36,-5,minecraft:soul_sand)
B(-1,37,-5,minecraft:soul_sand)
B(-1,38,-5,minecraft:soul_sand)
B(-1,39,-5,minecraft:soul_sand)
B(-1,40,-5,minecraft:soul_sand)
B(-1,41,-5,minecraft:soul_sand)
B(-1,42,-5,minecraft:soul_sand)
B(-1,43,-5,minecraft:soul_sand)
B(-1,44,-5,minecraft:soul_sand)
B(-1,45,-5,minecraft:soul_sand)
B(-1,46,-5,minecraft:soul_sand)
B(-1,47,-5,minecraft:soul_sand)
B(-1,48,-5,minecraft:soul_sand)
B(-1,49,-5,minecraft:soul_sand)
B(-1,50,-5,minecraft:soul_sand)
B(-1,32,-4,minecraft:soul_sand)
B(-1,33,-4,minecraft:soul_sand)
B(-1,34,-4,minecraft:soul_sand)
B(-1,35,-4,minecraft:soul_sand)
B(-1,36,-4,minecraft:soul_sand)
B(-1,37,-4,minecraft:soul_sand)
B(-1,38,-4,minecraft:soul_sand)
B(-1,39,-4,minecraft:soul_sand)
B(-1,40,-4,minecraft:soul_sand)
B(-1,41,-4,minecraft:soul_sand)
B(-1,42,-4,minecraft:soul_sand)
B(-1,43,-4,minecraft:soul_sand)
B(-1,44,-4,minecraft:soul_sand)
B(-1,45,-4,minecraft:soul_sand)
B(-1,46,-4,minecraft:soul_sand)
B(-1,47,-4,minecraft:soul_sand)
B(-1,48,-4,minecraft:soul_sand)
B(-1,49,-4,minecraft:soul_sand)
B(-1,50,-4,minecraft:soul_sand)
B(-1,27,-3,minecraft:soul_sand)
B(-1,28,-3,minecraft:soul_sand)
B(-1,29,-3,minecraft:soul_sand)
B(-1,30,-3,minecraft:soul_sand)
