
#######################################################################
# +-----------------------------------------------------------------+ #
# |                            BO4 object                           | #
# +-----------------------------------------------------------------+ #
#######################################################################

Author: Unknown

Description: No description given

SettingsMode: WriteWithoutComments


#######################################################################
# +-----------------------------------------------------------------+ #
# |                          Main settings                          | #
# +-----------------------------------------------------------------+ #
#######################################################################

FixedRotation: 

Frequency: 0

SpawnHeight: highestBlock

UseCenterForHighestBlock: true

##############################
# Height Limits for the BO4. #
##############################

MinHeight: 0

MaxHeight: 255

InheritBO3: 

InheritBO3Rotation: NORTH

OverrideChildSettings: true

OverrideParentHeight: false

CanOverride: false

BranchFrequency: 0

BranchFrequencyGroup: 

MustBeBelowOther: false

MustBeInside: 

CannotBeInside: 

ReplacesBO3: 

MustBeInsideWorldBorders: false

CanSpawnOnWater: true

SpawnOnWaterOnly: false

SpawnUnderWater: false

SpawnAtWaterLevel: false

HeightOffset: 0

RemoveAir: true

ReplaceAbove: 

ReplaceBelow: 

ReplaceWithBiomeBlocks: true

ReplaceWithSurfaceBlock: GRASS

ReplaceWithGroundBlock: DIRT

ReplaceWithStoneBlock: STONE

SmoothRadius: 0

SmoothHeightOffset: 0

SmoothStartTop: false

SmoothStartWood: false

SmoothingSurfaceBlock: 

SmoothingGroundBlock: 

BO3Group: 

IsSpawnPoint: false

DoReplaceBlocks: true


#######################################################################
# +-----------------------------------------------------------------+ #
# |                              Blocks                             | #
# +-----------------------------------------------------------------+ #
#######################################################################

B(-8,0,-6,minecraft:soul_sand)
B(-8,1,-6,minecraft:soul_sand)
B(-8,2,-6,minecraft:soul_sand)
B(-8,0,-5,minecraft:soul_sand)
B(-8,1,-5,minecraft:soul_sand)
B(-8,2,-5,minecraft:soul_sand)
B(-8,3,-5,minecraft:soul_sand)
B(-8,4,-5,minecraft:soul_sand)
B(-8,5,-5,minecraft:soul_sand)
B(-8,6,-5,minecraft:soul_sand)
B(-8,7,-5,minecraft:soul_sand)
B(-8,0,-4,minecraft:soul_sand)
B(-8,1,-4,minecraft:soul_sand)
B(-8,2,-4,minecraft:soul_sand)
B(-8,3,-4,minecraft:soul_sand)
B(-8,4,-4,minecraft:soul_sand)
B(-8,5,-4,minecraft:soul_sand)
B(-8,6,-4,minecraft:soul_sand)
B(-8,7,-4,minecraft:soul_sand)
B(-8,8,-4,minecraft:soul_sand)
B(-8,0,-3,minecraft:soul_sand)
B(-8,1,-3,minecraft:soul_sand)
B(-8,2,-3,minecraft:soul_sand)
B(-8,3,-3,minecraft:soul_sand)
B(-8,4,-3,minecraft:soul_sand)
B(-8,5,-3,minecraft:soul_sand)
B(-8,6,-3,minecraft:soul_sand)
B(-8,7,-3,minecraft:soul_sand)
B(-8,8,-3,minecraft:soul_sand)
B(-8,0,-2,minecraft:soul_sand)
B(-8,1,-2,minecraft:soul_sand)
B(-8,2,-2,minecraft:soul_sand)
B(-8,3,-2,minecraft:soul_sand)
B(-8,4,-2,minecraft:soul_sand)
B(-8,5,-2,minecraft:soul_sand)
B(-8,6,-2,minecraft:soul_sand)
B(-8,7,-2,minecraft:soul_sand)
B(-8,8,-2,minecraft:soul_sand)
B(-8,9,-2,minecraft:soul_sand)
B(-8,0,-1,minecraft:soul_sand)
B(-8,1,-1,minecraft:soul_sand)
B(-8,2,-1,minecraft:soul_sand)
B(-8,3,-1,minecraft:soul_sand)
B(-8,4,-1,minecraft:soul_sand)
B(-8,5,-1,minecraft:soul_sand)
B(-8,6,-1,minecraft:soul_sand)
B(-8,7,-1,minecraft:soul_sand)
B(-8,8,-1,minecraft:soul_sand)
B(-8,9,-1,minecraft:soul_sand)
B(-8,0,0,minecraft:soul_sand)
B(-8,1,0,minecraft:soul_sand)
B(-8,2,0,minecraft:soul_sand)
B(-8,3,0,minecraft:soul_sand)
B(-8,4,0,minecraft:soul_sand)
B(-8,5,0,minecraft:soul_sand)
B(-8,6,0,minecraft:soul_sand)
B(-8,7,0,minecraft:soul_sand)
B(-8,8,0,minecraft:soul_sand)
B(-8,9,0,minecraft:soul_sand)
B(-8,0,1,minecraft:soul_sand)
B(-8,1,1,minecraft:soul_sand)
B(-8,2,1,minecraft:soul_sand)
B(-8,3,1,minecraft:soul_sand)
B(-8,4,1,minecraft:soul_sand)
B(-8,5,1,minecraft:soul_sand)
B(-8,6,1,minecraft:soul_sand)
B(-8,7,1,minecraft:soul_sand)
B(-8,8,1,minecraft:soul_sand)
B(-8,0,2,minecraft:soul_sand)
B(-8,1,2,minecraft:soul_sand)
B(-8,2,2,minecraft:soul_sand)
B(-8,3,2,minecraft:soul_sand)
B(-8,4,2,minecraft:soul_sand)
B(-8,5,2,minecraft:soul_sand)
B(-8,6,2,minecraft:soul_sand)
B(-8,7,2,minecraft:soul_sand)
B(-8,8,2,minecraft:soul_sand)
B(-8,9,2,minecraft:soul_sand)
B(-8,0,3,minecraft:soul_sand)
B(-8,1,3,minecraft:soul_sand)
B(-8,2,3,minecraft:soul_sand)
B(-8,3,3,minecraft:soul_sand)
B(-8,4,3,minecraft:soul_sand)
B(-8,5,3,minecraft:soul_sand)
B(-8,6,3,minecraft:soul_sand)
B(-8,7,3,minecraft:soul_sand)
B(-8,8,3,minecraft:soul_sand)
B(-8,9,3,minecraft:soul_sand)
B(-8,10,3,minecraft:soul_sand)
B(-8,0,4,minecraft:soul_sand)
B(-8,1,4,minecraft:soul_sand)
B(-8,2,4,minecraft:soul_sand)
B(-8,3,4,minecraft:soul_sand)
B(-8,4,4,minecraft:soul_sand)
B(-8,5,4,minecraft:soul_sand)
B(-8,6,4,minecraft:soul_sand)
B(-8,7,4,minecraft:soul_sand)
B(-8,8,4,minecraft:soul_sand)
B(-8,9,4,minecraft:soul_sand)
B(-8,10,4,minecraft:soul_sand)
B(-8,11,4,minecraft:soul_sand)
B(-8,0,5,minecraft:soul_sand)
B(-8,1,5,minecraft:soul_sand)
B(-8,2,5,minecraft:soul_sand)
B(-8,3,5,minecraft:soul_sand)
B(-8,4,5,minecraft:soul_sand)
B(-8,5,5,minecraft:soul_sand)
B(-8,6,5,minecraft:soul_sand)
B(-8,7,5,minecraft:soul_sand)
B(-8,8,5,minecraft:soul_sand)
B(-8,9,5,minecraft:soul_sand)
B(-8,10,5,minecraft:soul_sand)
B(-8,11,5,minecraft:soul_sand)
B(-8,0,6,minecraft:soul_sand)
B(-8,1,6,minecraft:soul_sand)
B(-8,2,6,minecraft:soul_sand)
B(-8,3,6,minecraft:soul_sand)
B(-8,4,6,minecraft:soul_sand)
B(-8,5,6,minecraft:soul_sand)
B(-8,6,6,minecraft:soul_sand)
B(-8,7,6,minecraft:soul_sand)
B(-8,8,6,minecraft:soul_sand)
B(-8,9,6,minecraft:soul_sand)
B(-8,10,6,minecraft:soul_sand)
B(-8,11,6,minecraft:soul_sand)
B(-8,0,7,minecraft:soul_sand)
B(-8,1,7,minecraft:soul_sand)
B(-8,2,7,minecraft:soul_sand)
B(-8,3,7,minecraft:soul_sand)
B(-8,4,7,minecraft:soul_sand)
B(-8,5,7,minecraft:soul_sand)
B(-8,6,7,minecraft:soul_sand)
B(-8,7,7,minecraft:soul_sand)
B(-8,8,7,minecraft:soul_sand)
B(-8,9,7,minecraft:soul_sand)
B(-8,10,7,minecraft:soul_sand)
B(-8,11,7,minecraft:soul_sand)
B(-8,0,8,minecraft:soul_sand)
B(-8,1,8,minecraft:soul_sand)
B(-8,2,8,minecraft:soul_sand)
B(-8,3,8,minecraft:soul_sand)
B(-8,4,8,minecraft:soul_sand)
B(-8,5,8,minecraft:soul_sand)
B(-8,6,8,minecraft:soul_sand)
B(-8,7,8,minecraft:soul_sand)
B(-8,8,8,minecraft:soul_sand)
B(-8,9,8,minecraft:soul_sand)
B(-8,10,8,minecraft:soul_sand)
B(-8,11,8,minecraft:soul_sand)
B(-7,0,-6,minecraft:soul_sand)
B(-7,1,-6,minecraft:soul_sand)
B(-7,2,-6,minecraft:soul_sand)
B(-7,3,-6,minecraft:soul_sand)
B(-7,4,-6,minecraft:soul_sand)
B(-7,0,-5,minecraft:soul_sand)
B(-7,1,-5,minecraft:soul_sand)
B(-7,2,-5,minecraft:soul_sand)
B(-7,3,-5,minecraft:soul_sand)
B(-7,4,-5,minecraft:soul_sand)
B(-7,5,-5,minecraft:soul_sand)
B(-7,6,-5,minecraft:soul_sand)
B(-7,0,-4,minecraft:soul_sand)
B(-7,1,-4,minecraft:soul_sand)
B(-7,2,-4,minecraft:soul_sand)
B(-7,3,-4,minecraft:soul_sand)
B(-7,4,-4,minecraft:soul_sand)
B(-7,5,-4,minecraft:soul_sand)
B(-7,6,-4,minecraft:soul_sand)
B(-7,7,-4,minecraft:soul_sand)
B(-7,8,-4,minecraft:soul_sand)
B(-7,0,-3,minecraft:soul_sand)
B(-7,1,-3,minecraft:soul_sand)
B(-7,2,-3,minecraft:soul_sand)
B(-7,3,-3,minecraft:soul_sand)
B(-7,4,-3,minecraft:soul_sand)
B(-7,5,-3,minecraft:soul_sand)
B(-7,6,-3,minecraft:soul_sand)
B(-7,7,-3,minecraft:soul_sand)
B(-7,8,-3,minecraft:soul_sand)
B(-7,9,-3,minecraft:soul_sand)
B(-7,0,-2,minecraft:soul_sand)
B(-7,1,-2,minecraft:soul_sand)
B(-7,2,-2,minecraft:soul_sand)
B(-7,3,-2,minecraft:soul_sand)
B(-7,4,-2,minecraft:soul_sand)
B(-7,5,-2,minecraft:soul_sand)
B(-7,6,-2,minecraft:soul_sand)
B(-7,7,-2,minecraft:soul_sand)
B(-7,8,-2,minecraft:soul_sand)
B(-7,9,-2,minecraft:soul_sand)
B(-7,0,-1,minecraft:soul_sand)
B(-7,1,-1,minecraft:soul_sand)
B(-7,2,-1,minecraft:soul_sand)
B(-7,3,-1,minecraft:soul_sand)
B(-7,4,-1,minecraft:soul_sand)
B(-7,5,-1,minecraft:soul_sand)
B(-7,6,-1,minecraft:soul_sand)
B(-7,7,-1,minecraft:soul_sand)
B(-7,8,-1,minecraft:soul_sand)
B(-7,9,-1,minecraft:soul_sand)
B(-7,0,0,minecraft:soul_sand)
B(-7,1,0,minecraft:soul_sand)
B(-7,2,0,minecraft:soul_sand)
B(-7,3,0,minecraft:soul_sand)
B(-7,4,0,minecraft:soul_sand)
B(-7,5,0,minecraft:soul_sand)
B(-7,6,0,minecraft:soul_sand)
B(-7,7,0,minecraft:soul_sand)
B(-7,8,0,minecraft:soul_sand)
B(-7,9,0,minecraft:soul_sand)
B(-7,0,1,minecraft:soul_sand)
B(-7,1,1,minecraft:soul_sand)
B(-7,2,1,minecraft:soul_sand)
B(-7,3,1,minecraft:soul_sand)
B(-7,4,1,minecraft:soul_sand)
B(-7,5,1,minecraft:soul_sand)
B(-7,6,1,minecraft:soul_sand)
B(-7,7,1,minecraft:soul_sand)
B(-7,8,1,minecraft:soul_sand)
B(-7,9,1,minecraft:soul_sand)
B(-7,0,2,minecraft:soul_sand)
B(-7,1,2,minecraft:soul_sand)
B(-7,2,2,minecraft:soul_sand)
B(-7,3,2,minecraft:soul_sand)
B(-7,4,2,minecraft:soul_sand)
B(-7,5,2,minecraft:soul_sand)
B(-7,6,2,minecraft:soul_sand)
B(-7,7,2,minecraft:soul_sand)
B(-7,8,2,minecraft:soul_sand)
B(-7,9,2,minecraft:soul_sand)
B(-7,0,3,minecraft:soul_sand)
B(-7,1,3,minecraft:soul_sand)
B(-7,2,3,minecraft:soul_sand)
B(-7,3,3,minecraft:soul_sand)
B(-7,4,3,minecraft:soul_sand)
B(-7,5,3,minecraft:soul_sand)
B(-7,6,3,minecraft:soul_sand)
B(-7,7,3,minecraft:soul_sand)
B(-7,8,3,minecraft:soul_sand)
B(-7,9,3,minecraft:soul_sand)
B(-7,10,3,minecraft:soul_sand)
B(-7,0,4,minecraft:soul_sand)
B(-7,1,4,minecraft:soul_sand)
B(-7,2,4,minecraft:soul_sand)
B(-7,3,4,minecraft:soul_sand)
B(-7,4,4,minecraft:soul_sand)
B(-7,5,4,minecraft:soul_sand)
B(-7,6,4,minecraft:soul_sand)
B(-7,7,4,minecraft:soul_sand)
B(-7,8,4,minecraft:soul_sand)
B(-7,9,4,minecraft:soul_sand)
B(-7,10,4,minecraft:soul_sand)
B(-7,0,5,minecraft:soul_sand)
B(-7,1,5,minecraft:soul_sand)
B(-7,2,5,minecraft:soul_sand)
B(-7,3,5,minecraft:soul_sand)
B(-7,4,5,minecraft:soul_sand)
B(-7,5,5,minecraft:soul_sand)
B(-7,6,5,minecraft:soul_sand)
B(-7,7,5,minecraft:soul_sand)
B(-7,8,5,minecraft:soul_sand)
B(-7,9,5,minecraft:soul_sand)
B(-7,10,5,minecraft:soul_sand)
B(-7,11,5,minecraft:soul_sand)
B(-7,0,6,minecraft:soul_sand)
B(-7,1,6,minecraft:soul_sand)
B(-7,2,6,minecraft:soul_sand)
B(-7,3,6,minecraft:soul_sand)
B(-7,4,6,minecraft:soul_sand)
B(-7,5,6,minecraft:soul_sand)
B(-7,6,6,minecraft:soul_sand)
B(-7,7,6,minecraft:soul_sand)
B(-7,8,6,minecraft:soul_sand)
B(-7,9,6,minecraft:soul_sand)
B(-7,10,6,minecraft:soul_sand)
B(-7,11,6,minecraft:soul_sand)
B(-7,0,7,minecraft:soul_sand)
B(-7,1,7,minecraft:soul_sand)
B(-7,2,7,minecraft:soul_sand)
B(-7,3,7,minecraft:soul_sand)
B(-7,4,7,minecraft:soul_sand)
B(-7,5,7,minecraft:soul_sand)
B(-7,6,7,minecraft:soul_sand)
B(-7,7,7,minecraft:soul_sand)
B(-7,8,7,minecraft:soul_sand)
B(-7,9,7,minecraft:soul_sand)
B(-7,10,7,minecraft:soul_sand)
B(-7,11,7,minecraft:soul_sand)
B(-7,0,8,minecraft:soul_sand)
B(-7,1,8,minecraft:soul_sand)
B(-7,2,8,minecraft:soul_sand)
B(-7,3,8,minecraft:soul_sand)
B(-7,4,8,minecraft:soul_sand)
B(-7,5,8,minecraft:soul_sand)
B(-7,6,8,minecraft:soul_sand)
B(-7,7,8,minecraft:soul_sand)
B(-7,8,8,minecraft:soul_sand)
B(-7,9,8,minecraft:soul_sand)
B(-7,10,8,minecraft:soul_sand)
B(-6,0,-6,minecraft:soul_sand)
B(-6,1,-6,minecraft:soul_sand)
B(-6,2,-6,minecraft:soul_sand)
B(-6,3,-6,minecraft:soul_sand)
B(-6,4,-6,minecraft:soul_sand)
B(-6,0,-5,minecraft:soul_sand)
B(-6,1,-5,minecraft:soul_sand)
B(-6,2,-5,minecraft:soul_sand)
B(-6,3,-5,minecraft:soul_sand)
B(-6,4,-5,minecraft:soul_sand)
B(-6,5,-5,minecraft:soul_sand)
B(-6,6,-5,minecraft:soul_sand)
B(-6,0,-4,minecraft:soul_sand)
B(-6,1,-4,minecraft:soul_sand)
B(-6,2,-4,minecraft:soul_sand)
B(-6,3,-4,minecraft:soul_sand)
B(-6,4,-4,minecraft:soul_sand)
B(-6,5,-4,minecraft:soul_sand)
B(-6,6,-4,minecraft:soul_sand)
B(-6,7,-4,minecraft:soul_sand)
B(-6,8,-4,minecraft:soul_sand)
B(-6,0,-3,minecraft:soul_sand)
B(-6,1,-3,minecraft:soul_sand)
B(-6,2,-3,minecraft:soul_sand)
B(-6,3,-3,minecraft:soul_sand)
B(-6,4,-3,minecraft:soul_sand)
B(-6,5,-3,minecraft:soul_sand)
B(-6,6,-3,minecraft:soul_sand)
B(-6,7,-3,minecraft:soul_sand)
B(-6,8,-3,minecraft:soul_sand)
B(-6,9,-3,minecraft:soul_sand)
B(-6,0,-2,minecraft:soul_sand)
B(-6,1,-2,minecraft:soul_sand)
B(-6,2,-2,minecraft:soul_sand)
B(-6,3,-2,minecraft:soul_sand)
B(-6,4,-2,minecraft:soul_sand)
B(-6,5,-2,minecraft:soul_sand)
B(-6,6,-2,minecraft:soul_sand)
B(-6,7,-2,minecraft:soul_sand)
B(-6,8,-2,minecraft:soul_sand)
B(-6,9,-2,minecraft:soul_sand)
B(-6,0,-1,minecraft:soul_sand)
B(-6,1,-1,minecraft:soul_sand)
B(-6,2,-1,minecraft:soul_sand)
B(-6,3,-1,minecraft:soul_sand)
B(-6,4,-1,minecraft:soul_sand)
B(-6,5,-1,minecraft:soul_sand)
B(-6,6,-1,minecraft:soul_sand)
B(-6,7,-1,minecraft:soul_sand)
B(-6,8,-1,minecraft:soul_sand)
B(-6,9,-1,minecraft:soul_sand)
B(-6,0,0,minecraft:soul_sand)
B(-6,1,0,minecraft:soul_sand)
B(-6,2,0,minecraft:soul_sand)
B(-6,3,0,minecraft:soul_sand)
B(-6,4,0,minecraft:soul_sand)
B(-6,5,0,minecraft:soul_sand)
B(-6,6,0,minecraft:soul_sand)
B(-6,7,0,minecraft:soul_sand)
B(-6,8,0,minecraft:soul_sand)
B(-6,9,0,minecraft:soul_sand)
B(-6,0,1,minecraft:soul_sand)
B(-6,1,1,minecraft:soul_sand)
B(-6,2,1,minecraft:soul_sand)
B(-6,3,1,minecraft:soul_sand)
B(-6,4,1,minecraft:soul_sand)
B(-6,5,1,minecraft:soul_sand)
B(-6,6,1,minecraft:soul_sand)
B(-6,7,1,minecraft:soul_sand)
B(-6,8,1,minecraft:soul_sand)
B(-6,9,1,minecraft:soul_sand)
B(-6,0,2,minecraft:soul_sand)
B(-6,1,2,minecraft:soul_sand)
B(-6,2,2,minecraft:soul_sand)
B(-6,3,2,minecraft:soul_sand)
B(-6,4,2,minecraft:soul_sand)
B(-6,5,2,minecraft:soul_sand)
B(-6,6,2,minecraft:soul_sand)
B(-6,7,2,minecraft:soul_sand)
B(-6,8,2,minecraft:soul_sand)
B(-6,0,3,minecraft:soul_sand)
B(-6,1,3,minecraft:soul_sand)
B(-6,2,3,minecraft:soul_sand)
B(-6,3,3,minecraft:soul_sand)
B(-6,4,3,minecraft:soul_sand)
B(-6,5,3,minecraft:soul_sand)
B(-6,6,3,minecraft:soul_sand)
B(-6,7,3,minecraft:soul_sand)
B(-6,8,3,minecraft:soul_sand)
B(-6,9,3,minecraft:soul_sand)
B(-6,0,4,minecraft:soul_sand)
B(-6,1,4,minecraft:soul_sand)
B(-6,2,4,minecraft:soul_sand)
B(-6,3,4,minecraft:soul_sand)
B(-6,4,4,minecraft:soul_sand)
B(-6,5,4,minecraft:soul_sand)
B(-6,6,4,minecraft:soul_sand)
B(-6,7,4,minecraft:soul_sand)
B(-6,8,4,minecraft:soul_sand)
B(-6,9,4,minecraft:soul_sand)
B(-6,10,4,minecraft:soul_sand)
B(-6,0,5,minecraft:soul_sand)
B(-6,1,5,minecraft:soul_sand)
B(-6,2,5,minecraft:soul_sand)
B(-6,3,5,minecraft:soul_sand)
B(-6,4,5,minecraft:soul_sand)
B(-6,5,5,minecraft:soul_sand)
B(-6,6,5,minecraft:soul_sand)
B(-6,7,5,minecraft:soul_sand)
B(-6,8,5,minecraft:soul_sand)
B(-6,9,5,minecraft:soul_sand)
B(-6,10,5,minecraft:soul_sand)
B(-6,0,6,minecraft:soul_sand)
B(-6,1,6,minecraft:soul_sand)
B(-6,2,6,minecraft:soul_sand)
B(-6,3,6,minecraft:soul_sand)
B(-6,4,6,minecraft:soul_sand)
B(-6,5,6,minecraft:soul_sand)
B(-6,6,6,minecraft:soul_sand)
B(-6,7,6,minecraft:soul_sand)
B(-6,8,6,minecraft:soul_sand)
B(-6,9,6,minecraft:soul_sand)
B(-6,10,6,minecraft:soul_sand)
B(-6,0,7,minecraft:soul_sand)
B(-6,1,7,minecraft:soul_sand)
B(-6,2,7,minecraft:soul_sand)
B(-6,3,7,minecraft:soul_sand)
B(-6,4,7,minecraft:soul_sand)
B(-6,5,7,minecraft:soul_sand)
B(-6,6,7,minecraft:soul_sand)
B(-6,7,7,minecraft:soul_sand)
B(-6,8,7,minecraft:soul_sand)
B(-6,9,7,minecraft:soul_sand)
B(-6,10,7,minecraft:soul_sand)
B(-6,0,8,minecraft:soul_sand)
B(-6,1,8,minecraft:soul_sand)
B(-6,2,8,minecraft:soul_sand)
B(-6,3,8,minecraft:soul_sand)
B(-6,4,8,minecraft:soul_sand)
B(-6,5,8,minecraft:soul_sand)
B(-6,6,8,minecraft:soul_sand)
B(-6,7,8,minecraft:soul_sand)
B(-6,8,8,minecraft:soul_sand)
B(-6,9,8,minecraft:soul_sand)
B(-6,10,8,minecraft:soul_sand)
B(-5,0,-6,minecraft:soul_sand)
B(-5,1,-6,minecraft:soul_sand)
B(-5,2,-6,minecraft:soul_sand)
B(-5,3,-6,minecraft:soul_sand)
B(-5,4,-6,minecraft:soul_sand)
B(-5,0,-5,minecraft:soul_sand)
B(-5,1,-5,minecraft:soul_sand)
B(-5,2,-5,minecraft:soul_sand)
B(-5,3,-5,minecraft:soul_sand)
B(-5,4,-5,minecraft:soul_sand)
B(-5,5,-5,minecraft:soul_sand)
B(-5,6,-5,minecraft:soul_sand)
B(-5,0,-4,minecraft:soul_sand)
B(-5,1,-4,minecraft:soul_sand)
B(-5,2,-4,minecraft:soul_sand)
B(-5,3,-4,minecraft:soul_sand)
B(-5,4,-4,minecraft:soul_sand)
B(-5,5,-4,minecraft:soul_sand)
B(-5,6,-4,minecraft:soul_sand)
B(-5,7,-4,minecraft:soul_sand)
B(-5,8,-4,minecraft:soul_sand)
B(-5,0,-3,minecraft:soul_sand)
B(-5,1,-3,minecraft:soul_sand)
B(-5,2,-3,minecraft:soul_sand)
B(-5,3,-3,minecraft:soul_sand)
B(-5,4,-3,minecraft:soul_sand)
B(-5,5,-3,minecraft:soul_sand)
B(-5,6,-3,minecraft:soul_sand)
B(-5,7,-3,minecraft:soul_sand)
B(-5,8,-3,minecraft:soul_sand)
B(-5,9,-3,minecraft:soul_sand)
B(-5,0,-2,minecraft:soul_sand)
B(-5,1,-2,minecraft:soul_sand)
B(-5,2,-2,minecraft:soul_sand)
B(-5,3,-2,minecraft:soul_sand)
B(-5,4,-2,minecraft:soul_sand)
B(-5,5,-2,minecraft:soul_sand)
B(-5,6,-2,minecraft:soul_sand)
B(-5,7,-2,minecraft:soul_sand)
B(-5,8,-2,minecraft:soul_sand)
B(-5,9,-2,minecraft:soul_sand)
B(-5,0,-1,minecraft:soul_sand)
B(-5,1,-1,minecraft:soul_sand)
B(-5,2,-1,minecraft:soul_sand)
B(-5,3,-1,minecraft:soul_sand)
B(-5,4,-1,minecraft:soul_sand)
B(-5,5,-1,minecraft:soul_sand)
B(-5,6,-1,minecraft:soul_sand)
B(-5,7,-1,minecraft:soul_sand)
B(-5,8,-1,minecraft:soul_sand)
B(-5,9,-1,minecraft:soul_sand)
B(-5,0,0,minecraft:soul_sand)
B(-5,1,0,minecraft:soul_sand)
B(-5,2,0,minecraft:soul_sand)
B(-5,3,0,minecraft:soul_sand)
B(-5,4,0,minecraft:soul_sand)
B(-5,5,0,minecraft:soul_sand)
B(-5,6,0,minecraft:soul_sand)
B(-5,7,0,minecraft:soul_sand)
B(-5,8,0,minecraft:soul_sand)
B(-5,9,0,minecraft:soul_sand)
B(-5,0,1,minecraft:soul_sand)
B(-5,1,1,minecraft:soul_sand)
B(-5,2,1,minecraft:soul_sand)
B(-5,3,1,minecraft:soul_sand)
B(-5,4,1,minecraft:soul_sand)
B(-5,5,1,minecraft:soul_sand)
B(-5,6,1,minecraft:soul_sand)
B(-5,7,1,minecraft:soul_sand)
B(-5,8,1,minecraft:soul_sand)
B(-5,9,1,minecraft:soul_sand)
B(-5,0,2,minecraft:soul_sand)
B(-5,1,2,minecraft:soul_sand)
B(-5,2,2,minecraft:soul_sand)
B(-5,3,2,minecraft:soul_sand)
B(-5,4,2,minecraft:soul_sand)
B(-5,5,2,minecraft:soul_sand)
B(-5,6,2,minecraft:soul_sand)
B(-5,7,2,minecraft:soul_sand)
B(-5,8,2,minecraft:soul_sand)
B(-5,9,2,minecraft:soul_sand)
B(-5,10,2,minecraft:soul_sand)
B(-5,11,2,minecraft:soul_sand)
B(-5,0,3,minecraft:soul_sand)
B(-5,1,3,minecraft:soul_sand)
B(-5,2,3,minecraft:soul_sand)
B(-5,3,3,minecraft:soul_sand)
B(-5,4,3,minecraft:soul_sand)
B(-5,5,3,minecraft:soul_sand)
B(-5,6,3,minecraft:soul_sand)
B(-5,7,3,minecraft:soul_sand)
B(-5,8,3,minecraft:soul_sand)
B(-5,9,3,minecraft:soul_sand)
B(-5,10,3,minecraft:soul_sand)
B(-5,11,3,minecraft:soul_sand)
B(-5,12,3,minecraft:soul_sand)
B(-5,13,3,minecraft:soul_sand)
B(-5,0,4,minecraft:soul_sand)
B(-5,1,4,minecraft:soul_sand)
B(-5,2,4,minecraft:soul_sand)
B(-5,3,4,minecraft:soul_sand)
B(-5,4,4,minecraft:soul_sand)
B(-5,5,4,minecraft:soul_sand)
B(-5,6,4,minecraft:soul_sand)
B(-5,7,4,minecraft:soul_sand)
B(-5,8,4,minecraft:soul_sand)
B(-5,9,4,minecraft:soul_sand)
B(-5,10,4,minecraft:soul_sand)
B(-5,11,4,minecraft:soul_sand)
B(-5,12,4,minecraft:soul_sand)
B(-5,13,4,minecraft:soul_sand)
B(-5,0,5,minecraft:soul_sand)
B(-5,1,5,minecraft:soul_sand)
B(-5,2,5,minecraft:soul_sand)
B(-5,3,5,minecraft:soul_sand)
B(-5,4,5,minecraft:soul_sand)
B(-5,5,5,minecraft:soul_sand)
B(-5,6,5,minecraft:soul_sand)
B(-5,7,5,minecraft:soul_sand)
B(-5,8,5,minecraft:soul_sand)
B(-5,9,5,minecraft:soul_sand)
B(-5,10,5,minecraft:soul_sand)
B(-5,11,5,minecraft:soul_sand)
B(-5,12,5,minecraft:soul_sand)
B(-5,13,5,minecraft:soul_sand)
B(-5,0,6,minecraft:soul_sand)
B(-5,1,6,minecraft:soul_sand)
B(-5,2,6,minecraft:soul_sand)
B(-5,3,6,minecraft:soul_sand)
B(-5,4,6,minecraft:soul_sand)
B(-5,5,6,minecraft:soul_sand)
B(-5,6,6,minecraft:soul_sand)
B(-5,7,6,minecraft:soul_sand)
B(-5,8,6,minecraft:soul_sand)
B(-5,9,6,minecraft:soul_sand)
B(-5,10,6,minecraft:soul_sand)
B(-5,11,6,minecraft:soul_sand)
B(-5,12,6,minecraft:soul_sand)
B(-5,0,7,minecraft:soul_sand)
B(-5,1,7,minecraft:soul_sand)
B(-5,2,7,minecraft:soul_sand)
B(-5,3,7,minecraft:soul_sand)
B(-5,4,7,minecraft:soul_sand)
B(-5,5,7,minecraft:soul_sand)
B(-5,6,7,minecraft:soul_sand)
B(-5,7,7,minecraft:soul_sand)
B(-5,8,7,minecraft:soul_sand)
B(-5,9,7,minecraft:soul_sand)
B(-5,0,8,minecraft:soul_sand)
B(-5,1,8,minecraft:soul_sand)
B(-5,2,8,minecraft:soul_sand)
B(-5,3,8,minecraft:soul_sand)
B(-5,4,8,minecraft:soul_sand)
B(-5,5,8,minecraft:soul_sand)
B(-5,6,8,minecraft:soul_sand)
B(-5,7,8,minecraft:soul_sand)
B(-5,8,8,minecraft:soul_sand)
B(-5,9,8,minecraft:soul_sand)
B(-5,10,8,minecraft:soul_sand)
B(-4,0,-6,minecraft:soul_sand)
B(-4,1,-6,minecraft:soul_sand)
B(-4,2,-6,minecraft:soul_sand)
B(-4,0,-5,minecraft:soul_sand)
B(-4,1,-5,minecraft:soul_sand)
B(-4,2,-5,minecraft:soul_sand)
B(-4,3,-5,minecraft:soul_sand)
B(-4,4,-5,minecraft:soul_sand)
B(-4,5,-5,minecraft:soul_sand)
B(-4,6,-5,minecraft:soul_sand)
B(-4,7,-5,minecraft:soul_sand)
B(-4,0,-4,minecraft:soul_sand)
B(-4,1,-4,minecraft:soul_sand)
B(-4,2,-4,minecraft:soul_sand)
B(-4,3,-4,minecraft:soul_sand)
B(-4,4,-4,minecraft:soul_sand)
B(-4,5,-4,minecraft:soul_sand)
B(-4,6,-4,minecraft:soul_sand)
B(-4,7,-4,minecraft:soul_sand)
B(-4,8,-4,minecraft:soul_sand)
B(-4,0,-3,minecraft:soul_sand)
B(-4,1,-3,minecraft:soul_sand)
B(-4,2,-3,minecraft:soul_sand)
B(-4,3,-3,minecraft:soul_sand)
B(-4,4,-3,minecraft:soul_sand)
B(-4,5,-3,minecraft:soul_sand)
B(-4,6,-3,minecraft:soul_sand)
B(-4,7,-3,minecraft:soul_sand)
B(-4,8,-3,minecraft:soul_sand)
B(-4,0,-2,minecraft:soul_sand)
B(-4,1,-2,minecraft:soul_sand)
B(-4,2,-2,minecraft:soul_sand)
B(-4,3,-2,minecraft:soul_sand)
B(-4,4,-2,minecraft:soul_sand)
B(-4,5,-2,minecraft:soul_sand)
B(-4,6,-2,minecraft:soul_sand)
B(-4,7,-2,minecraft:soul_sand)
B(-4,8,-2,minecraft:soul_sand)
B(-4,9,-2,minecraft:soul_sand)
B(-4,0,-1,minecraft:soul_sand)
B(-4,1,-1,minecraft:soul_sand)
B(-4,2,-1,minecraft:soul_sand)
B(-4,3,-1,minecraft:soul_sand)
B(-4,4,-1,minecraft:soul_sand)
B(-4,5,-1,minecraft:soul_sand)
B(-4,6,-1,minecraft:soul_sand)
B(-4,7,-1,minecraft:soul_sand)
B(-4,8,-1,minecraft:soul_sand)
B(-4,9,-1,minecraft:soul_sand)
B(-4,0,0,minecraft:soul_sand)
B(-4,1,0,minecraft:soul_sand)
B(-4,2,0,minecraft:soul_sand)
B(-4,3,0,minecraft:soul_sand)
B(-4,4,0,minecraft:soul_sand)
B(-4,5,0,minecraft:soul_sand)
B(-4,6,0,minecraft:soul_sand)
B(-4,7,0,minecraft:soul_sand)
B(-4,8,0,minecraft:soul_sand)
B(-4,9,0,minecraft:soul_sand)
B(-4,0,1,minecraft:soul_sand)
B(-4,1,1,minecraft:soul_sand)
B(-4,2,1,minecraft:soul_sand)
B(-4,3,1,minecraft:soul_sand)
B(-4,4,1,minecraft:soul_sand)
B(-4,5,1,minecraft:soul_sand)
B(-4,6,1,minecraft:soul_sand)
B(-4,7,1,minecraft:soul_sand)
B(-4,8,1,minecraft:soul_sand)
B(-4,9,1,minecraft:soul_sand)
B(-4,10,1,minecraft:soul_sand)
B(-4,11,1,minecraft:soul_sand)
B(-4,12,1,minecraft:soul_sand)
B(-4,13,1,minecraft:soul_sand)
B(-4,0,2,minecraft:soul_sand)
B(-4,1,2,minecraft:soul_sand)
B(-4,2,2,minecraft:soul_sand)
B(-4,3,2,minecraft:soul_sand)
B(-4,4,2,minecraft:soul_sand)
B(-4,5,2,minecraft:soul_sand)
B(-4,6,2,minecraft:soul_sand)
B(-4,7,2,minecraft:soul_sand)
B(-4,8,2,minecraft:soul_sand)
B(-4,9,2,minecraft:soul_sand)
B(-4,10,2,minecraft:soul_sand)
B(-4,11,2,minecraft:soul_sand)
B(-4,12,2,minecraft:soul_sand)
B(-4,13,2,minecraft:soul_sand)
B(-4,14,2,minecraft:soul_sand)
B(-4,0,3,minecraft:soul_sand)
B(-4,1,3,minecraft:soul_sand)
B(-4,2,3,minecraft:soul_sand)
B(-4,3,3,minecraft:soul_sand)
B(-4,4,3,minecraft:soul_sand)
B(-4,5,3,minecraft:soul_sand)
B(-4,6,3,minecraft:soul_sand)
B(-4,7,3,minecraft:soul_sand)
B(-4,8,3,minecraft:soul_sand)
B(-4,9,3,minecraft:soul_sand)
B(-4,10,3,minecraft:soul_sand)
B(-4,11,3,minecraft:soul_sand)
B(-4,12,3,minecraft:soul_sand)
B(-4,13,3,minecraft:soul_sand)
B(-4,14,3,minecraft:soul_sand)
B(-4,0,4,minecraft:soul_sand)
B(-4,1,4,minecraft:soul_sand)
B(-4,2,4,minecraft:soul_sand)
B(-4,3,4,minecraft:soul_sand)
B(-4,4,4,minecraft:soul_sand)
B(-4,5,4,minecraft:soul_sand)
B(-4,6,4,minecraft:soul_sand)
B(-4,7,4,minecraft:soul_sand)
B(-4,8,4,minecraft:soul_sand)
B(-4,9,4,minecraft:soul_sand)
B(-4,10,4,minecraft:soul_sand)
B(-4,11,4,minecraft:soul_sand)
B(-4,12,4,minecraft:soul_sand)
B(-4,13,4,minecraft:soul_sand)
B(-4,14,4,minecraft:soul_sand)
B(-4,0,5,minecraft:soul_sand)
B(-4,1,5,minecraft:soul_sand)
B(-4,2,5,minecraft:soul_sand)
B(-4,3,5,minecraft:soul_sand)
B(-4,4,5,minecraft:soul_sand)
B(-4,5,5,minecraft:soul_sand)
B(-4,6,5,minecraft:soul_sand)
B(-4,7,5,minecraft:soul_sand)
B(-4,8,5,minecraft:soul_sand)
B(-4,9,5,minecraft:soul_sand)
B(-4,10,5,minecraft:soul_sand)
B(-4,11,5,minecraft:soul_sand)
B(-4,12,5,minecraft:soul_sand)
B(-4,13,5,minecraft:soul_sand)
B(-4,14,5,minecraft:soul_sand)
B(-4,0,6,minecraft:soul_sand)
B(-4,1,6,minecraft:soul_sand)
B(-4,2,6,minecraft:soul_sand)
B(-4,3,6,minecraft:soul_sand)
B(-4,4,6,minecraft:soul_sand)
B(-4,5,6,minecraft:soul_sand)
B(-4,6,6,minecraft:soul_sand)
B(-4,7,6,minecraft:soul_sand)
B(-4,8,6,minecraft:soul_sand)
B(-4,9,6,minecraft:soul_sand)
B(-4,10,6,minecraft:soul_sand)
B(-4,11,6,minecraft:soul_sand)
B(-4,12,6,minecraft:soul_sand)
B(-4,13,6,minecraft:soul_sand)
B(-4,14,6,minecraft:soul_sand)
B(-4,0,7,minecraft:soul_sand)
B(-4,1,7,minecraft:soul_sand)
B(-4,2,7,minecraft:soul_sand)
B(-4,3,7,minecraft:soul_sand)
B(-4,4,7,minecraft:soul_sand)
B(-4,5,7,minecraft:soul_sand)
B(-4,6,7,minecraft:soul_sand)
B(-4,7,7,minecraft:soul_sand)
B(-4,8,7,minecraft:soul_sand)
B(-4,9,7,minecraft:soul_sand)
B(-4,10,7,minecraft:soul_sand)
B(-4,11,7,minecraft:soul_sand)
B(-4,12,7,minecraft:soul_sand)
B(-4,13,7,minecraft:soul_sand)
B(-4,0,8,minecraft:soul_sand)
B(-4,1,8,minecraft:soul_sand)
B(-4,2,8,minecraft:soul_sand)
B(-4,3,8,minecraft:soul_sand)
B(-4,4,8,minecraft:soul_sand)
B(-4,5,8,minecraft:soul_sand)
B(-4,6,8,minecraft:soul_sand)
B(-4,7,8,minecraft:soul_sand)
B(-4,8,8,minecraft:soul_sand)
B(-4,9,8,minecraft:soul_sand)
B(-4,10,8,minecraft:soul_sand)
B(-4,11,8,minecraft:soul_sand)
B(-4,12,8,minecraft:soul_sand)
B(-3,0,-5,minecraft:soul_sand)
B(-3,1,-5,minecraft:soul_sand)
B(-3,2,-5,minecraft:soul_sand)
B(-3,3,-5,minecraft:soul_sand)
B(-3,4,-5,minecraft:soul_sand)
B(-3,5,-5,minecraft:soul_sand)
B(-3,6,-5,minecraft:soul_sand)
B(-3,0,-4,minecraft:soul_sand)
B(-3,1,-4,minecraft:soul_sand)
B(-3,2,-4,minecraft:soul_sand)
B(-3,3,-4,minecraft:soul_sand)
B(-3,4,-4,minecraft:soul_sand)
B(-3,5,-4,minecraft:soul_sand)
B(-3,6,-4,minecraft:soul_sand)
B(-3,7,-4,minecraft:soul_sand)
B(-3,0,-3,minecraft:soul_sand)
B(-3,1,-3,minecraft:soul_sand)
B(-3,2,-3,minecraft:soul_sand)
B(-3,3,-3,minecraft:soul_sand)
B(-3,4,-3,minecraft:soul_sand)
B(-3,5,-3,minecraft:soul_sand)
B(-3,6,-3,minecraft:soul_sand)
B(-3,7,-3,minecraft:soul_sand)
B(-3,8,-3,minecraft:soul_sand)
B(-3,0,-2,minecraft:soul_sand)
B(-3,1,-2,minecraft:soul_sand)
B(-3,2,-2,minecraft:soul_sand)
B(-3,3,-2,minecraft:soul_sand)
B(-3,4,-2,minecraft:soul_sand)
B(-3,5,-2,minecraft:soul_sand)
B(-3,6,-2,minecraft:soul_sand)
B(-3,7,-2,minecraft:soul_sand)
B(-3,8,-2,minecraft:soul_sand)
B(-3,0,-1,minecraft:soul_sand)
B(-3,1,-1,minecraft:soul_sand)
B(-3,2,-1,minecraft:soul_sand)
B(-3,3,-1,minecraft:soul_sand)
B(-3,4,-1,minecraft:soul_sand)
B(-3,5,-1,minecraft:soul_sand)
B(-3,6,-1,minecraft:soul_sand)
B(-3,7,-1,minecraft:soul_sand)
B(-3,8,-1,minecraft:soul_sand)
B(-3,0,0,minecraft:soul_sand)
B(-3,1,0,minecraft:soul_sand)
B(-3,2,0,minecraft:soul_sand)
B(-3,3,0,minecraft:soul_sand)
B(-3,4,0,minecraft:soul_sand)
B(-3,5,0,minecraft:soul_sand)
B(-3,6,0,minecraft:soul_sand)
B(-3,7,0,minecraft:soul_sand)
B(-3,8,0,minecraft:soul_sand)
B(-3,9,0,minecraft:soul_sand)
B(-3,10,0,minecraft:soul_sand)
B(-3,11,0,minecraft:soul_sand)
B(-3,12,0,minecraft:soul_sand)
B(-3,13,0,minecraft:soul_sand)
B(-3,0,1,minecraft:soul_sand)
B(-3,1,1,minecraft:soul_sand)
B(-3,2,1,minecraft:soul_sand)
B(-3,3,1,minecraft:soul_sand)
B(-3,4,1,minecraft:soul_sand)
B(-3,5,1,minecraft:soul_sand)
B(-3,6,1,minecraft:soul_sand)
B(-3,7,1,minecraft:soul_sand)
B(-3,8,1,minecraft:soul_sand)
B(-3,9,1,minecraft:soul_sand)
B(-3,10,1,minecraft:soul_sand)
B(-3,11,1,minecraft:soul_sand)
B(-3,12,1,minecraft:soul_sand)
B(-3,13,1,minecraft:soul_sand)
B(-3,14,1,minecraft:soul_sand)
B(-3,0,2,minecraft:soul_sand)
B(-3,1,2,minecraft:soul_sand)
B(-3,2,2,minecraft:soul_sand)
B(-3,3,2,minecraft:soul_sand)
B(-3,4,2,minecraft:soul_sand)
B(-3,5,2,minecraft:soul_sand)
B(-3,6,2,minecraft:soul_sand)
B(-3,7,2,minecraft:soul_sand)
B(-3,8,2,minecraft:soul_sand)
B(-3,9,2,minecraft:soul_sand)
B(-3,10,2,minecraft:soul_sand)
B(-3,11,2,minecraft:soul_sand)
B(-3,12,2,minecraft:soul_sand)
B(-3,13,2,minecraft:soul_sand)
B(-3,14,2,minecraft:soul_sand)
B(-3,15,2,minecraft:soul_sand)
B(-3,0,3,minecraft:soul_sand)
B(-3,1,3,minecraft:soul_sand)
B(-3,2,3,minecraft:soul_sand)
B(-3,3,3,minecraft:soul_sand)
B(-3,4,3,minecraft:soul_sand)
B(-3,5,3,minecraft:soul_sand)
B(-3,6,3,minecraft:soul_sand)
B(-3,7,3,minecraft:soul_sand)
B(-3,8,3,minecraft:soul_sand)
B(-3,9,3,minecraft:soul_sand)
B(-3,10,3,minecraft:soul_sand)
B(-3,11,3,minecraft:soul_sand)
B(-3,12,3,minecraft:soul_sand)
B(-3,13,3,minecraft:soul_sand)
B(-3,14,3,minecraft:soul_sand)
B(-3,15,3,minecraft:soul_sand)
B(-3,0,4,minecraft:soul_sand)
B(-3,1,4,minecraft:soul_sand)
B(-3,2,4,minecraft:soul_sand)
B(-3,3,4,minecraft:soul_sand)
B(-3,4,4,minecraft:soul_sand)
B(-3,5,4,minecraft:soul_sand)
B(-3,6,4,minecraft:soul_sand)
B(-3,7,4,minecraft:soul_sand)
B(-3,8,4,minecraft:soul_sand)
B(-3,9,4,minecraft:soul_sand)
B(-3,10,4,minecraft:soul_sand)
B(-3,11,4,minecraft:soul_sand)
B(-3,12,4,minecraft:soul_sand)
B(-3,13,4,minecraft:soul_sand)
B(-3,14,4,minecraft:soul_sand)
B(-3,15,4,minecraft:soul_sand)
B(-3,0,5,minecraft:soul_sand)
B(-3,1,5,minecraft:soul_sand)
B(-3,2,5,minecraft:soul_sand)
B(-3,3,5,minecraft:soul_sand)
B(-3,4,5,minecraft:soul_sand)
B(-3,5,5,minecraft:soul_sand)
B(-3,6,5,minecraft:soul_sand)
B(-3,7,5,minecraft:soul_sand)
B(-3,8,5,minecraft:soul_sand)
B(-3,9,5,minecraft:soul_sand)
B(-3,10,5,minecraft:soul_sand)
B(-3,11,5,minecraft:soul_sand)
B(-3,12,5,minecraft:soul_sand)
B(-3,13,5,minecraft:soul_sand)
B(-3,14,5,minecraft:soul_sand)
B(-3,15,5,minecraft:soul_sand)
B(-3,16,5,minecraft:soul_sand)
B(-3,17,5,minecraft:soul_sand)
B(-3,18,5,minecraft:soul_sand)
B(-3,0,6,minecraft:soul_sand)
B(-3,1,6,minecraft:soul_sand)
B(-3,2,6,minecraft:soul_sand)
B(-3,3,6,minecraft:soul_sand)
B(-3,4,6,minecraft:soul_sand)
B(-3,5,6,minecraft:soul_sand)
B(-3,6,6,minecraft:soul_sand)
B(-3,7,6,minecraft:soul_sand)
B(-3,8,6,minecraft:soul_sand)
B(-3,9,6,minecraft:soul_sand)
B(-3,10,6,minecraft:soul_sand)
B(-3,11,6,minecraft:soul_sand)
B(-3,12,6,minecraft:soul_sand)
B(-3,13,6,minecraft:soul_sand)
B(-3,14,6,minecraft:soul_sand)
B(-3,15,6,minecraft:soul_sand)
B(-3,16,6,minecraft:soul_sand)
B(-3,17,6,minecraft:soul_sand)
B(-3,18,6,minecraft:soul_sand)
B(-3,0,7,minecraft:soul_sand)
B(-3,1,7,minecraft:soul_sand)
B(-3,2,7,minecraft:soul_sand)
B(-3,3,7,minecraft:soul_sand)
B(-3,4,7,minecraft:soul_sand)
B(-3,5,7,minecraft:soul_sand)
B(-3,6,7,minecraft:soul_sand)
B(-3,7,7,minecraft:soul_sand)
B(-3,8,7,minecraft:soul_sand)
B(-3,9,7,minecraft:soul_sand)
B(-3,10,7,minecraft:soul_sand)
B(-3,11,7,minecraft:soul_sand)
B(-3,12,7,minecraft:soul_sand)
B(-3,13,7,minecraft:soul_sand)
B(-3,14,7,minecraft:soul_sand)
B(-3,15,7,minecraft:soul_sand)
B(-3,16,7,minecraft:soul_sand)
B(-3,0,8,minecraft:soul_sand)
B(-3,1,8,minecraft:soul_sand)
B(-3,2,8,minecraft:soul_sand)
B(-3,3,8,minecraft:soul_sand)
B(-3,4,8,minecraft:soul_sand)
B(-3,5,8,minecraft:soul_sand)
B(-3,6,8,minecraft:soul_sand)
B(-3,7,8,minecraft:soul_sand)
B(-3,8,8,minecraft:soul_sand)
B(-3,9,8,minecraft:soul_sand)
B(-3,10,8,minecraft:soul_sand)
B(-3,11,8,minecraft:soul_sand)
B(-3,12,8,minecraft:soul_sand)
B(-3,13,8,minecraft:soul_sand)
B(-2,0,-5,minecraft:soul_sand)
B(-2,1,-5,minecraft:soul_sand)
B(-2,2,-5,minecraft:soul_sand)
B(-2,0,-4,minecraft:soul_sand)
B(-2,1,-4,minecraft:soul_sand)
B(-2,2,-4,minecraft:soul_sand)
B(-2,3,-4,minecraft:soul_sand)
B(-2,4,-4,minecraft:soul_sand)
B(-2,5,-4,minecraft:soul_sand)
B(-2,6,-4,minecraft:soul_sand)
B(-2,0,-3,minecraft:soul_sand)
B(-2,1,-3,minecraft:soul_sand)
B(-2,2,-3,minecraft:soul_sand)
B(-2,3,-3,minecraft:soul_sand)
B(-2,4,-3,minecraft:soul_sand)
B(-2,5,-3,minecraft:soul_sand)
B(-2,6,-3,minecraft:soul_sand)
B(-2,7,-3,minecraft:soul_sand)
B(-2,0,-2,minecraft:soul_sand)
B(-2,1,-2,minecraft:soul_sand)
B(-2,2,-2,minecraft:soul_sand)
B(-2,3,-2,minecraft:soul_sand)
B(-2,4,-2,minecraft:soul_sand)
B(-2,5,-2,minecraft:soul_sand)
B(-2,6,-2,minecraft:soul_sand)
B(-2,7,-2,minecraft:soul_sand)
B(-2,0,-1,minecraft:soul_sand)
B(-2,1,-1,minecraft:soul_sand)
B(-2,2,-1,minecraft:soul_sand)
B(-2,3,-1,minecraft:soul_sand)
B(-2,4,-1,minecraft:soul_sand)
B(-2,5,-1,minecraft:soul_sand)
B(-2,6,-1,minecraft:soul_sand)
B(-2,7,-1,minecraft:soul_sand)
B(-2,8,-1,minecraft:soul_sand)
B(-2,9,-1,minecraft:soul_sand)
B(-2,10,-1,minecraft:soul_sand)
B(-2,0,0,minecraft:soul_sand)
B(-2,1,0,minecraft:soul_sand)
B(-2,2,0,minecraft:soul_sand)
B(-2,3,0,minecraft:soul_sand)
B(-2,4,0,minecraft:soul_sand)
B(-2,5,0,minecraft:soul_sand)
B(-2,6,0,minecraft:soul_sand)
B(-2,7,0,minecraft:soul_sand)
B(-2,8,0,minecraft:soul_sand)
B(-2,9,0,minecraft:soul_sand)
B(-2,10,0,minecraft:soul_sand)
B(-2,11,0,minecraft:soul_sand)
B(-2,12,0,minecraft:soul_sand)
B(-2,13,0,minecraft:soul_sand)
B(-2,14,0,minecraft:soul_sand)
B(-2,0,1,minecraft:soul_sand)
B(-2,1,1,minecraft:soul_sand)
B(-2,2,1,minecraft:soul_sand)
B(-2,3,1,minecraft:soul_sand)
B(-2,4,1,minecraft:soul_sand)
B(-2,5,1,minecraft:soul_sand)
B(-2,6,1,minecraft:soul_sand)
B(-2,7,1,minecraft:soul_sand)
B(-2,8,1,minecraft:soul_sand)
B(-2,9,1,minecraft:soul_sand)
B(-2,10,1,minecraft:soul_sand)
B(-2,11,1,minecraft:soul_sand)
B(-2,12,1,minecraft:soul_sand)
B(-2,13,1,minecraft:soul_sand)
B(-2,14,1,minecraft:soul_sand)
B(-2,15,1,minecraft:soul_sand)
B(-2,0,2,minecraft:soul_sand)
B(-2,1,2,minecraft:soul_sand)
B(-2,2,2,minecraft:soul_sand)
B(-2,3,2,minecraft:soul_sand)
B(-2,4,2,minecraft:soul_sand)
B(-2,5,2,minecraft:soul_sand)
B(-2,6,2,minecraft:soul_sand)
B(-2,7,2,minecraft:soul_sand)
B(-2,8,2,minecraft:soul_sand)
B(-2,9,2,minecraft:soul_sand)
B(-2,10,2,minecraft:soul_sand)
B(-2,11,2,minecraft:soul_sand)
B(-2,12,2,minecraft:soul_sand)
B(-2,13,2,minecraft:soul_sand)
B(-2,14,2,minecraft:soul_sand)
B(-2,15,2,minecraft:soul_sand)
B(-2,0,3,minecraft:soul_sand)
B(-2,1,3,minecraft:soul_sand)
B(-2,2,3,minecraft:soul_sand)
B(-2,3,3,minecraft:soul_sand)
B(-2,4,3,minecraft:soul_sand)
B(-2,5,3,minecraft:soul_sand)
B(-2,6,3,minecraft:soul_sand)
B(-2,7,3,minecraft:soul_sand)
B(-2,8,3,minecraft:soul_sand)
B(-2,9,3,minecraft:soul_sand)
B(-2,10,3,minecraft:soul_sand)
B(-2,11,3,minecraft:soul_sand)
B(-2,12,3,minecraft:soul_sand)
B(-2,13,3,minecraft:soul_sand)
B(-2,14,3,minecraft:soul_sand)
B(-2,15,3,minecraft:soul_sand)
B(-2,16,3,minecraft:soul_sand)
B(-2,0,4,minecraft:soul_sand)
B(-2,1,4,minecraft:soul_sand)
B(-2,2,4,minecraft:soul_sand)
B(-2,3,4,minecraft:soul_sand)
B(-2,4,4,minecraft:soul_sand)
B(-2,5,4,minecraft:soul_sand)
B(-2,6,4,minecraft:soul_sand)
B(-2,7,4,minecraft:soul_sand)
B(-2,8,4,minecraft:soul_sand)
B(-2,9,4,minecraft:soul_sand)
B(-2,10,4,minecraft:soul_sand)
B(-2,11,4,minecraft:soul_sand)
B(-2,12,4,minecraft:soul_sand)
B(-2,13,4,minecraft:soul_sand)
B(-2,14,4,minecraft:soul_sand)
B(-2,15,4,minecraft:soul_sand)
B(-2,16,4,minecraft:soul_sand)
B(-2,17,4,minecraft:soul_sand)
B(-2,18,4,minecraft:soul_sand)
B(-2,19,4,minecraft:soul_sand)
B(-2,0,5,minecraft:soul_sand)
B(-2,1,5,minecraft:soul_sand)
B(-2,2,5,minecraft:soul_sand)
B(-2,3,5,minecraft:soul_sand)
B(-2,4,5,minecraft:soul_sand)
B(-2,5,5,minecraft:soul_sand)
B(-2,6,5,minecraft:soul_sand)
B(-2,7,5,minecraft:soul_sand)
B(-2,8,5,minecraft:soul_sand)
B(-2,9,5,minecraft:soul_sand)
B(-2,10,5,minecraft:soul_sand)
B(-2,11,5,minecraft:soul_sand)
B(-2,12,5,minecraft:soul_sand)
B(-2,13,5,minecraft:soul_sand)
B(-2,14,5,minecraft:soul_sand)
B(-2,15,5,minecraft:soul_sand)
B(-2,16,5,minecraft:soul_sand)
B(-2,17,5,minecraft:soul_sand)
B(-2,18,5,minecraft:soul_sand)
B(-2,19,5,minecraft:soul_sand)
B(-2,0,6,minecraft:soul_sand)
B(-2,1,6,minecraft:soul_sand)
B(-2,2,6,minecraft:soul_sand)
B(-2,3,6,minecraft:soul_sand)
B(-2,4,6,minecraft:soul_sand)
B(-2,5,6,minecraft:soul_sand)
B(-2,6,6,minecraft:soul_sand)
B(-2,7,6,minecraft:soul_sand)
B(-2,8,6,minecraft:soul_sand)
B(-2,9,6,minecraft:soul_sand)
B(-2,10,6,minecraft:soul_sand)
B(-2,11,6,minecraft:soul_sand)
B(-2,12,6,minecraft:soul_sand)
B(-2,13,6,minecraft:soul_sand)
B(-2,14,6,minecraft:soul_sand)
B(-2,15,6,minecraft:soul_sand)
B(-2,16,6,minecraft:soul_sand)
B(-2,17,6,minecraft:soul_sand)
B(-2,18,6,minecraft:soul_sand)
B(-2,19,6,minecraft:soul_sand)
B(-2,0,7,minecraft:soul_sand)
B(-2,1,7,minecraft:soul_sand)
B(-2,2,7,minecraft:soul_sand)
B(-2,3,7,minecraft:soul_sand)
B(-2,4,7,minecraft:soul_sand)
B(-2,5,7,minecraft:soul_sand)
B(-2,6,7,minecraft:soul_sand)
B(-2,7,7,minecraft:soul_sand)
B(-2,8,7,minecraft:soul_sand)
B(-2,9,7,minecraft:soul_sand)
B(-2,10,7,minecraft:soul_sand)
B(-2,11,7,minecraft:soul_sand)
B(-2,12,7,minecraft:soul_sand)
B(-2,13,7,minecraft:soul_sand)
B(-2,14,7,minecraft:soul_sand)
B(-2,15,7,minecraft:soul_sand)
B(-2,16,7,minecraft:soul_sand)
B(-2,17,7,minecraft:soul_sand)
B(-2,18,7,minecraft:soul_sand)
B(-2,19,7,minecraft:soul_sand)
B(-2,0,8,minecraft:soul_sand)
B(-2,1,8,minecraft:soul_sand)
B(-2,2,8,minecraft:soul_sand)
B(-2,3,8,minecraft:soul_sand)
B(-2,4,8,minecraft:soul_sand)
B(-2,5,8,minecraft:soul_sand)
B(-2,6,8,minecraft:soul_sand)
B(-2,7,8,minecraft:soul_sand)
B(-2,8,8,minecraft:soul_sand)
B(-2,9,8,minecraft:soul_sand)
B(-2,10,8,minecraft:soul_sand)
B(-2,11,8,minecraft:soul_sand)
B(-2,12,8,minecraft:soul_sand)
B(-2,13,8,minecraft:soul_sand)
B(-2,14,8,minecraft:soul_sand)
B(-2,15,8,minecraft:soul_sand)
B(-2,16,8,minecraft:soul_sand)
B(-2,17,8,minecraft:soul_sand)
B(-2,18,8,minecraft:soul_sand)
B(-2,19,8,minecraft:soul_sand)
B(-1,0,-6,minecraft:soul_sand)
B(-1,1,-6,minecraft:soul_sand)
B(-1,2,-6,minecraft:soul_sand)
B(-1,3,-6,minecraft:soul_sand)
B(-1,0,-5,minecraft:soul_sand)
B(-1,1,-5,minecraft:soul_sand)
B(-1,2,-5,minecraft:soul_sand)
B(-1,3,-5,minecraft:soul_sand)
B(-1,4,-5,minecraft:soul_sand)
B(-1,0,-4,minecraft:soul_sand)
B(-1,1,-4,minecraft:soul_sand)
B(-1,2,-4,minecraft:soul_sand)
B(-1,3,-4,minecraft:soul_sand)
B(-1,4,-4,minecraft:soul_sand)
B(-1,0,-3,minecraft:soul_sand)
B(-1,1,-3,minecraft:soul_sand)
B(-1,2,-3,minecraft:soul_sand)
B(-1,3,-3,minecraft:soul_sand)
B(-1,4,-3,minecraft:soul_sand)
B(-1,5,-3,minecraft:soul_sand)
B(-1,0,-2,minecraft:soul_sand)
B(-1,1,-2,minecraft:soul_sand)
B(-1,2,-2,minecraft:soul_sand)
B(-1,3,-2,minecraft:soul_sand)
B(-1,4,-2,minecraft:soul_sand)
B(-1,5,-2,minecraft:soul_sand)
B(-1,6,-2,minecraft:soul_sand)
B(-1,0,-1,minecraft:soul_sand)
B(-1,1,-1,minecraft:soul_sand)
B(-1,2,-1,minecraft:soul_sand)
B(-1,3,-1,minecraft:soul_sand)
B(-1,4,-1,minecraft:soul_sand)
B(-1,5,-1,minecraft:soul_sand)
B(-1,6,-1,minecraft:soul_sand)
B(-1,7,-1,minecraft:soul_sand)
B(-1,8,-1,minecraft:soul_sand)
B(-1,9,-1,minecraft:soul_sand)
B(-1,10,-1,minecraft:soul_sand)
B(-1,11,-1,minecraft:soul_sand)
B(-1,0,0,minecraft:soul_sand)
B(-1,1,0,minecraft:soul_sand)
B(-1,2,0,minecraft:soul_sand)
B(-1,3,0,minecraft:soul_sand)
B(-1,4,0,minecraft:soul_sand)
B(-1,5,0,minecraft:soul_sand)
B(-1,6,0,minecraft:soul_sand)
B(-1,7,0,minecraft:soul_sand)
B(-1,8,0,minecraft:soul_sand)
B(-1,9,0,minecraft:soul_sand)
B(-1,10,0,minecraft:soul_sand)
B(-1,11,0,minecraft:soul_sand)
B(-1,12,0,minecraft:soul_sand)
B(-1,13,0,minecraft:soul_sand)
B(-1,0,1,minecraft:soul_sand)
B(-1,1,1,minecraft:soul_sand)
B(-1,2,1,minecraft:soul_sand)
B(-1,3,1,minecraft:soul_sand)
B(-1,4,1,minecraft:soul_sand)
B(-1,5,1,minecraft:soul_sand)
B(-1,6,1,minecraft:soul_sand)
B(-1,7,1,minecraft:soul_sand)
B(-1,8,1,minecraft:soul_sand)
B(-1,9,1,minecraft:soul_sand)
B(-1,10,1,minecraft:soul_sand)
B(-1,11,1,minecraft:soul_sand)
B(-1,12,1,minecraft:soul_sand)
B(-1,13,1,minecraft:soul_sand)
B(-1,14,1,minecraft:soul_sand)
B(-1,15,1,minecraft:soul_sand)
B(-1,0,2,minecraft:soul_sand)
B(-1,1,2,minecraft:soul_sand)
B(-1,2,2,minecraft:soul_sand)
B(-1,3,2,minecraft:soul_sand)
B(-1,4,2,minecraft:soul_sand)
B(-1,5,2,minecraft:soul_sand)
B(-1,6,2,minecraft:soul_sand)
B(-1,7,2,minecraft:soul_sand)
B(-1,8,2,minecraft:soul_sand)
B(-1,9,2,minecraft:soul_sand)
B(-1,10,2,minecraft:soul_sand)
B(-1,11,2,minecraft:soul_sand)
B(-1,12,2,minecraft:soul_sand)
B(-1,13,2,minecraft:soul_sand)
B(-1,14,2,minecraft:soul_sand)
B(-1,15,2,minecraft:soul_sand)
B(-1,16,2,minecraft:soul_sand)
B(-1,17,2,minecraft:soul_sand)
B(-1,0,3,minecraft:soul_sand)
B(-1,1,3,minecraft:soul_sand)
B(-1,2,3,minecraft:soul_sand)
B(-1,3,3,minecraft:soul_sand)
B(-1,4,3,minecraft:soul_sand)
B(-1,5,3,minecraft:soul_sand)
B(-1,6,3,minecraft:soul_sand)
B(-1,7,3,minecraft:soul_sand)
B(-1,8,3,minecraft:soul_sand)
B(-1,9,3,minecraft:soul_sand)
B(-1,10,3,minecraft:soul_sand)
B(-1,11,3,minecraft:soul_sand)
B(-1,12,3,minecraft:soul_sand)
B(-1,13,3,minecraft:soul_sand)
B(-1,14,3,minecraft:soul_sand)
B(-1,15,3,minecraft:soul_sand)
B(-1,16,3,minecraft:soul_sand)
B(-1,17,3,minecraft:soul_sand)
B(-1,18,3,minecraft:soul_sand)
B(-1,0,4,minecraft:soul_sand)
B(-1,1,4,minecraft:soul_sand)
B(-1,2,4,minecraft:soul_sand)
B(-1,3,4,minecraft:soul_sand)
B(-1,4,4,minecraft:soul_sand)
B(-1,5,4,minecraft:soul_sand)
B(-1,6,4,minecraft:soul_sand)
B(-1,7,4,minecraft:soul_sand)
B(-1,8,4,minecraft:soul_sand)
B(-1,9,4,minecraft:soul_sand)
B(-1,10,4,minecraft:soul_sand)
B(-1,11,4,minecraft:soul_sand)
B(-1,12,4,minecraft:soul_sand)
B(-1,13,4,minecraft:soul_sand)
B(-1,14,4,minecraft:soul_sand)
B(-1,15,4,minecraft:soul_sand)
B(-1,16,4,minecraft:soul_sand)
B(-1,17,4,minecraft:soul_sand)
B(-1,18,4,minecraft:soul_sand)
B(-1,19,4,minecraft:soul_sand)
B(-1,0,5,minecraft:soul_sand)
B(-1,1,5,minecraft:soul_sand)
B(-1,2,5,minecraft:soul_sand)
B(-1,3,5,minecraft:soul_sand)
B(-1,4,5,minecraft:soul_sand)
B(-1,5,5,minecraft:soul_sand)
B(-1,6,5,minecraft:soul_sand)
B(-1,7,5,minecraft:soul_sand)
B(-1,8,5,minecraft:soul_sand)
B(-1,9,5,minecraft:soul_sand)
B(-1,10,5,minecraft:soul_sand)
B(-1,11,5,minecraft:soul_sand)
B(-1,12,5,minecraft:soul_sand)
B(-1,13,5,minecraft:soul_sand)
B(-1,14,5,minecraft:soul_sand)
B(-1,15,5,minecraft:soul_sand)
B(-1,16,5,minecraft:soul_sand)
B(-1,17,5,minecraft:soul_sand)
B(-1,18,5,minecraft:soul_sand)
B(-1,19,5,minecraft:soul_sand)
B(-1,0,6,minecraft:soul_sand)
B(-1,1,6,minecraft:soul_sand)
B(-1,2,6,minecraft:soul_sand)
B(-1,3,6,minecraft:soul_sand)
B(-1,4,6,minecraft:soul_sand)
B(-1,5,6,minecraft:soul_sand)
B(-1,6,6,minecraft:soul_sand)
B(-1,7,6,minecraft:soul_sand)
B(-1,8,6,minecraft:soul_sand)
B(-1,9,6,minecraft:soul_sand)
B(-1,10,6,minecraft:soul_sand)
B(-1,11,6,minecraft:soul_sand)
B(-1,12,6,minecraft:soul_sand)
B(-1,13,6,minecraft:soul_sand)
B(-1,14,6,minecraft:soul_sand)
B(-1,15,6,minecraft:soul_sand)
B(-1,16,6,minecraft:soul_sand)
B(-1,17,6,minecraft:soul_sand)
B(-1,18,6,minecraft:soul_sand)
B(-1,19,6,minecraft:soul_sand)
B(-1,20,6,minecraft:soul_sand)
B(-1,0,7,minecraft:soul_sand)
B(-1,1,7,minecraft:soul_sand)
B(-1,2,7,minecraft:soul_sand)
B(-1,3,7,minecraft:soul_sand)
B(-1,4,7,minecraft:soul_sand)
B(-1,5,7,minecraft:soul_sand)
B(-1,6,7,minecraft:soul_sand)
B(-1,7,7,minecraft:soul_sand)
B(-1,8,7,minecraft:soul_sand)
B(-1,9,7,minecraft:soul_sand)
B(-1,10,7,minecraft:soul_sand)
B(-1,11,7,minecraft:soul_sand)
B(-1,12,7,minecraft:soul_sand)
B(-1,13,7,minecraft:soul_sand)
B(-1,14,7,minecraft:soul_sand)
B(-1,15,7,minecraft:soul_sand)
B(-1,16,7,minecraft:soul_sand)
B(-1,17,7,minecraft:soul_sand)
B(-1,18,7,minecraft:soul_sand)
B(-1,19,7,minecraft:soul_sand)
B(-1,20,7,minecraft:soul_sand)
B(-1,0,8,minecraft:soul_sand)
B(-1,1,8,minecraft:soul_sand)
B(-1,2,8,minecraft:soul_sand)
B(-1,3,8,minecraft:soul_sand)
B(-1,4,8,minecraft:soul_sand)
B(-1,5,8,minecraft:soul_sand)
B(-1,6,8,minecraft:soul_sand)
B(-1,7,8,minecraft:soul_sand)
B(-1,8,8,minecraft:soul_sand)
B(-1,9,8,minecraft:soul_sand)
B(-1,10,8,minecraft:soul_sand)
B(-1,11,8,minecraft:soul_sand)
B(-1,12,8,minecraft:soul_sand)
B(-1,13,8,minecraft:soul_sand)
B(-1,14,8,minecraft:soul_sand)
B(-1,15,8,minecraft:soul_sand)
B(-1,16,8,minecraft:soul_sand)
B(-1,17,8,minecraft:soul_sand)
B(-1,18,8,minecraft:soul_sand)
B(-1,19,8,minecraft:soul_sand)
B(0,0,-7,minecraft:soul_sand)
B(0,1,-7,minecraft:soul_sand)
B(0,2,-7,minecraft:soul_sand)
B(0,3,-7,minecraft:soul_sand)
B(0,0,-6,minecraft:soul_sand)
B(0,1,-6,minecraft:soul_sand)
B(0,2,-6,minecraft:soul_sand)
B(0,3,-6,minecraft:soul_sand)
B(0,4,-6,minecraft:soul_sand)
B(0,0,-5,minecraft:soul_sand)
B(0,1,-5,minecraft:soul_sand)
B(0,2,-5,minecraft:soul_sand)
B(0,3,-5,minecraft:soul_sand)
B(0,4,-5,minecraft:soul_sand)
B(0,5,-5,minecraft:soul_sand)
B(0,0,-4,minecraft:soul_sand)
B(0,1,-4,minecraft:soul_sand)
B(0,2,-4,minecraft:soul_sand)
B(0,3,-4,minecraft:soul_sand)
B(0,4,-4,minecraft:soul_sand)
B(0,5,-4,minecraft:soul_sand)
B(0,0,-3,minecraft:soul_sand)
B(0,1,-3,minecraft:soul_sand)
B(0,2,-3,minecraft:soul_sand)
B(0,3,-3,minecraft:soul_sand)
B(0,4,-3,minecraft:soul_sand)
B(0,5,-3,minecraft:soul_sand)
B(0,0,-2,minecraft:soul_sand)
B(0,1,-2,minecraft:soul_sand)
B(0,2,-2,minecraft:soul_sand)
B(0,3,-2,minecraft:soul_sand)
B(0,4,-2,minecraft:soul_sand)
B(0,5,-2,minecraft:soul_sand)
B(0,0,-1,minecraft:soul_sand)
B(0,1,-1,minecraft:soul_sand)
B(0,2,-1,minecraft:soul_sand)
B(0,3,-1,minecraft:soul_sand)
B(0,4,-1,minecraft:soul_sand)
B(0,5,-1,minecraft:soul_sand)
B(0,6,-1,minecraft:soul_sand)
B(0,7,-1,minecraft:soul_sand)
B(0,8,-1,minecraft:soul_sand)
B(0,9,-1,minecraft:soul_sand)
B(0,10,-1,minecraft:soul_sand)
B(0,0,0,minecraft:soul_sand)
B(0,1,0,minecraft:soul_sand)
B(0,2,0,minecraft:soul_sand)
B(0,3,0,minecraft:soul_sand)
B(0,4,0,minecraft:soul_sand)
B(0,5,0,minecraft:soul_sand)
B(0,6,0,minecraft:soul_sand)
B(0,7,0,minecraft:soul_sand)
B(0,8,0,minecraft:soul_sand)
B(0,9,0,minecraft:soul_sand)
B(0,10,0,minecraft:soul_sand)
B(0,11,0,minecraft:soul_sand)
B(0,12,0,minecraft:soul_sand)
B(0,13,0,minecraft:soul_sand)
B(0,14,0,minecraft:soul_sand)
B(0,15,0,minecraft:soul_sand)
B(0,0,1,minecraft:soul_sand)
B(0,1,1,minecraft:soul_sand)
B(0,2,1,minecraft:soul_sand)
B(0,3,1,minecraft:soul_sand)
B(0,4,1,minecraft:soul_sand)
B(0,5,1,minecraft:soul_sand)
B(0,6,1,minecraft:soul_sand)
B(0,7,1,minecraft:soul_sand)
B(0,8,1,minecraft:soul_sand)
B(0,9,1,minecraft:soul_sand)
B(0,10,1,minecraft:soul_sand)
B(0,11,1,minecraft:soul_sand)
B(0,12,1,minecraft:soul_sand)
B(0,13,1,minecraft:soul_sand)
B(0,14,1,minecraft:soul_sand)
B(0,15,1,minecraft:soul_sand)
B(0,0,2,minecraft:soul_sand)
B(0,1,2,minecraft:soul_sand)
B(0,2,2,minecraft:soul_sand)
B(0,3,2,minecraft:soul_sand)
B(0,4,2,minecraft:soul_sand)
B(0,5,2,minecraft:soul_sand)
B(0,6,2,minecraft:soul_sand)
B(0,7,2,minecraft:soul_sand)
B(0,8,2,minecraft:soul_sand)
B(0,9,2,minecraft:soul_sand)
B(0,10,2,minecraft:soul_sand)
B(0,11,2,minecraft:soul_sand)
B(0,12,2,minecraft:soul_sand)
B(0,13,2,minecraft:soul_sand)
B(0,14,2,minecraft:soul_sand)
B(0,15,2,minecraft:soul_sand)
B(0,16,2,minecraft:soul_sand)
B(0,0,3,minecraft:soul_sand)
B(0,1,3,minecraft:soul_sand)
B(0,2,3,minecraft:soul_sand)
B(0,3,3,minecraft:soul_sand)
B(0,4,3,minecraft:soul_sand)
B(0,5,3,minecraft:soul_sand)
B(0,6,3,minecraft:soul_sand)
B(0,7,3,minecraft:soul_sand)
B(0,8,3,minecraft:soul_sand)
B(0,9,3,minecraft:soul_sand)
B(0,10,3,minecraft:soul_sand)
B(0,11,3,minecraft:soul_sand)
B(0,12,3,minecraft:soul_sand)
B(0,13,3,minecraft:soul_sand)
B(0,14,3,minecraft:soul_sand)
B(0,15,3,minecraft:soul_sand)
B(0,16,3,minecraft:soul_sand)
B(0,17,3,minecraft:soul_sand)
B(0,0,4,minecraft:soul_sand)
B(0,1,4,minecraft:soul_sand)
B(0,2,4,minecraft:soul_sand)
B(0,3,4,minecraft:soul_sand)
B(0,4,4,minecraft:soul_sand)
B(0,5,4,minecraft:soul_sand)
B(0,6,4,minecraft:soul_sand)
B(0,7,4,minecraft:soul_sand)
B(0,8,4,minecraft:soul_sand)
B(0,9,4,minecraft:soul_sand)
B(0,10,4,minecraft:soul_sand)
B(0,11,4,minecraft:soul_sand)
B(0,12,4,minecraft:soul_sand)
B(0,13,4,minecraft:soul_sand)
B(0,14,4,minecraft:soul_sand)
B(0,15,4,minecraft:soul_sand)
B(0,16,4,minecraft:soul_sand)
B(0,17,4,minecraft:soul_sand)
B(0,18,4,minecraft:soul_sand)
B(0,0,5,minecraft:soul_sand)
B(0,1,5,minecraft:soul_sand)
B(0,2,5,minecraft:soul_sand)
B(0,3,5,minecraft:soul_sand)
B(0,4,5,minecraft:soul_sand)
B(0,5,5,minecraft:soul_sand)
B(0,6,5,minecraft:soul_sand)
B(0,7,5,minecraft:soul_sand)
B(0,8,5,minecraft:soul_sand)
B(0,9,5,minecraft:soul_sand)
B(0,10,5,minecraft:soul_sand)
B(0,11,5,minecraft:soul_sand)
B(0,12,5,minecraft:soul_sand)
B(0,13,5,minecraft:soul_sand)
B(0,14,5,minecraft:soul_sand)
B(0,15,5,minecraft:soul_sand)
B(0,16,5,minecraft:soul_sand)
B(0,17,5,minecraft:soul_sand)
B(0,18,5,minecraft:soul_sand)
B(0,0,6,minecraft:soul_sand)
B(0,1,6,minecraft:soul_sand)
B(0,2,6,minecraft:soul_sand)
B(0,3,6,minecraft:soul_sand)
B(0,4,6,minecraft:soul_sand)
B(0,5,6,minecraft:soul_sand)
B(0,6,6,minecraft:soul_sand)
B(0,7,6,minecraft:soul_sand)
B(0,8,6,minecraft:soul_sand)
B(0,9,6,minecraft:soul_sand)
B(0,10,6,minecraft:soul_sand)
B(0,11,6,minecraft:soul_sand)
B(0,12,6,minecraft:soul_sand)
B(0,13,6,minecraft:soul_sand)
B(0,14,6,minecraft:soul_sand)
B(0,15,6,minecraft:soul_sand)
B(0,16,6,minecraft:soul_sand)
B(0,17,6,minecraft:soul_sand)
B(0,18,6,minecraft:soul_sand)
B(0,19,6,minecraft:soul_sand)
B(0,0,7,minecraft:soul_sand)
B(0,1,7,minecraft:soul_sand)
B(0,2,7,minecraft:soul_sand)
B(0,3,7,minecraft:soul_sand)
B(0,4,7,minecraft:soul_sand)
B(0,5,7,minecraft:soul_sand)
B(0,6,7,minecraft:soul_sand)
B(0,7,7,minecraft:soul_sand)
B(0,8,7,minecraft:soul_sand)
B(0,9,7,minecraft:soul_sand)
B(0,10,7,minecraft:soul_sand)
B(0,11,7,minecraft:soul_sand)
B(0,12,7,minecraft:soul_sand)
B(0,13,7,minecraft:soul_sand)
B(0,14,7,minecraft:soul_sand)
B(0,15,7,minecraft:soul_sand)
B(0,16,7,minecraft:soul_sand)
B(0,17,7,minecraft:soul_sand)
B(0,18,7,minecraft:soul_sand)
B(0,19,7,minecraft:soul_sand)
B(0,20,7,minecraft:soul_sand)
B(0,0,8,minecraft:soul_sand)
B(0,1,8,minecraft:soul_sand)
B(0,2,8,minecraft:soul_sand)
B(0,3,8,minecraft:soul_sand)
B(0,4,8,minecraft:soul_sand)
B(0,5,8,minecraft:soul_sand)
B(0,6,8,minecraft:soul_sand)
B(0,7,8,minecraft:soul_sand)
B(0,8,8,minecraft:soul_sand)
B(0,9,8,minecraft:soul_sand)
B(0,10,8,minecraft:soul_sand)
B(0,11,8,minecraft:soul_sand)
B(0,12,8,minecraft:soul_sand)
B(0,13,8,minecraft:soul_sand)
B(0,14,8,minecraft:soul_sand)
B(0,15,8,minecraft:soul_sand)
B(0,16,8,minecraft:soul_sand)
B(0,17,8,minecraft:soul_sand)
B(0,18,8,minecraft:soul_sand)
B(0,19,8,minecraft:soul_sand)
B(1,0,-7,minecraft:soul_sand)
B(1,1,-7,minecraft:soul_sand)
B(1,2,-7,minecraft:soul_sand)
B(1,3,-7,minecraft:soul_sand)
B(1,4,-7,minecraft:soul_sand)
B(1,0,-6,minecraft:soul_sand)
B(1,1,-6,minecraft:soul_sand)
B(1,2,-6,minecraft:soul_sand)
B(1,3,-6,minecraft:soul_sand)
B(1,4,-6,minecraft:soul_sand)
B(1,5,-6,minecraft:soul_sand)
B(1,0,-5,minecraft:soul_sand)
B(1,1,-5,minecraft:soul_sand)
B(1,2,-5,minecraft:soul_sand)
B(1,3,-5,minecraft:soul_sand)
B(1,4,-5,minecraft:soul_sand)
B(1,5,-5,minecraft:soul_sand)
B(1,0,-4,minecraft:soul_sand)
B(1,1,-4,minecraft:soul_sand)
B(1,2,-4,minecraft:soul_sand)
B(1,3,-4,minecraft:soul_sand)
B(1,4,-4,minecraft:soul_sand)
B(1,5,-4,minecraft:soul_sand)
B(1,6,-4,minecraft:soul_sand)
B(1,0,-3,minecraft:soul_sand)
B(1,1,-3,minecraft:soul_sand)
B(1,2,-3,minecraft:soul_sand)
B(1,3,-3,minecraft:soul_sand)
B(1,4,-3,minecraft:soul_sand)
B(1,5,-3,minecraft:soul_sand)
B(1,6,-3,minecraft:soul_sand)
B(1,0,-2,minecraft:soul_sand)
B(1,1,-2,minecraft:soul_sand)
B(1,2,-2,minecraft:soul_sand)
B(1,3,-2,minecraft:soul_sand)
B(1,4,-2,minecraft:soul_sand)
B(1,5,-2,minecraft:soul_sand)
B(1,6,-2,minecraft:soul_sand)
B(1,0,-1,minecraft:soul_sand)
B(1,1,-1,minecraft:soul_sand)
B(1,2,-1,minecraft:soul_sand)
B(1,3,-1,minecraft:soul_sand)
B(1,4,-1,minecraft:soul_sand)
B(1,5,-1,minecraft:soul_sand)
B(1,6,-1,minecraft:soul_sand)
B(1,7,-1,minecraft:soul_sand)
B(1,8,-1,minecraft:soul_sand)
B(1,9,-1,minecraft:soul_sand)
B(1,10,-1,minecraft:soul_sand)
B(1,0,0,minecraft:soul_sand)
B(1,1,0,minecraft:soul_sand)
B(1,2,0,minecraft:soul_sand)
B(1,3,0,minecraft:soul_sand)
B(1,4,0,minecraft:soul_sand)
B(1,5,0,minecraft:soul_sand)
B(1,6,0,minecraft:soul_sand)
B(1,7,0,minecraft:soul_sand)
B(1,8,0,minecraft:soul_sand)
B(1,9,0,minecraft:soul_sand)
B(1,10,0,minecraft:soul_sand)
B(1,11,0,minecraft:soul_sand)
B(1,12,0,minecraft:soul_sand)
B(1,13,0,minecraft:soul_sand)
B(1,14,0,minecraft:soul_sand)
B(1,15,0,minecraft:soul_sand)
B(1,0,1,minecraft:soul_sand)
B(1,1,1,minecraft:soul_sand)
B(1,2,1,minecraft:soul_sand)
B(1,3,1,minecraft:soul_sand)
B(1,4,1,minecraft:soul_sand)
B(1,5,1,minecraft:soul_sand)
B(1,6,1,minecraft:soul_sand)
B(1,7,1,minecraft:soul_sand)
B(1,8,1,minecraft:soul_sand)
B(1,9,1,minecraft:soul_sand)
B(1,10,1,minecraft:soul_sand)
B(1,11,1,minecraft:soul_sand)
B(1,12,1,minecraft:soul_sand)
B(1,13,1,minecraft:soul_sand)
B(1,14,1,minecraft:soul_sand)
B(1,15,1,minecraft:soul_sand)
B(1,0,2,minecraft:soul_sand)
B(1,1,2,minecraft:soul_sand)
B(1,2,2,minecraft:soul_sand)
B(1,3,2,minecraft:soul_sand)
B(1,4,2,minecraft:soul_sand)
B(1,5,2,minecraft:soul_sand)
B(1,6,2,minecraft:soul_sand)
B(1,7,2,minecraft:soul_sand)
B(1,8,2,minecraft:soul_sand)
B(1,9,2,minecraft:soul_sand)
B(1,10,2,minecraft:soul_sand)
B(1,11,2,minecraft:soul_sand)
B(1,12,2,minecraft:soul_sand)
B(1,13,2,minecraft:soul_sand)
B(1,14,2,minecraft:soul_sand)
B(1,15,2,minecraft:soul_sand)
B(1,16,2,minecraft:soul_sand)
B(1,0,3,minecraft:soul_sand)
B(1,1,3,minecraft:soul_sand)
B(1,2,3,minecraft:soul_sand)
B(1,3,3,minecraft:soul_sand)
B(1,4,3,minecraft:soul_sand)
B(1,5,3,minecraft:soul_sand)
B(1,6,3,minecraft:soul_sand)
B(1,7,3,minecraft:soul_sand)
B(1,8,3,minecraft:soul_sand)
B(1,9,3,minecraft:soul_sand)
B(1,10,3,minecraft:soul_sand)
B(1,11,3,minecraft:soul_sand)
B(1,12,3,minecraft:soul_sand)
B(1,13,3,minecraft:soul_sand)
B(1,14,3,minecraft:soul_sand)
B(1,15,3,minecraft:soul_sand)
B(1,16,3,minecraft:soul_sand)
B(1,17,3,minecraft:soul_sand)
B(1,0,4,minecraft:soul_sand)
B(1,1,4,minecraft:soul_sand)
B(1,2,4,minecraft:soul_sand)
B(1,3,4,minecraft:soul_sand)
B(1,4,4,minecraft:soul_sand)
B(1,5,4,minecraft:soul_sand)
B(1,6,4,minecraft:soul_sand)
B(1,7,4,minecraft:soul_sand)
B(1,8,4,minecraft:soul_sand)
B(1,9,4,minecraft:soul_sand)
B(1,10,4,minecraft:soul_sand)
B(1,11,4,minecraft:soul_sand)
B(1,12,4,minecraft:soul_sand)
B(1,13,4,minecraft:soul_sand)
B(1,14,4,minecraft:soul_sand)
B(1,15,4,minecraft:soul_sand)
B(1,16,4,minecraft:soul_sand)
B(1,17,4,minecraft:soul_sand)
B(1,18,4,minecraft:soul_sand)
B(1,0,5,minecraft:soul_sand)
B(1,1,5,minecraft:soul_sand)
B(1,2,5,minecraft:soul_sand)
B(1,3,5,minecraft:soul_sand)
B(1,4,5,minecraft:soul_sand)
B(1,5,5,minecraft:soul_sand)
B(1,6,5,minecraft:soul_sand)
B(1,7,5,minecraft:soul_sand)
B(1,8,5,minecraft:soul_sand)
B(1,9,5,minecraft:soul_sand)
B(1,10,5,minecraft:soul_sand)
B(1,11,5,minecraft:soul_sand)
B(1,12,5,minecraft:soul_sand)
B(1,13,5,minecraft:soul_sand)
B(1,14,5,minecraft:soul_sand)
B(1,15,5,minecraft:soul_sand)
B(1,16,5,minecraft:soul_sand)
B(1,17,5,minecraft:soul_sand)
B(1,18,5,minecraft:soul_sand)
B(1,0,6,minecraft:soul_sand)
B(1,1,6,minecraft:soul_sand)
B(1,2,6,minecraft:soul_sand)
B(1,3,6,minecraft:soul_sand)
B(1,4,6,minecraft:soul_sand)
B(1,5,6,minecraft:soul_sand)
B(1,6,6,minecraft:soul_sand)
B(1,7,6,minecraft:soul_sand)
B(1,8,6,minecraft:soul_sand)
B(1,9,6,minecraft:soul_sand)
B(1,10,6,minecraft:soul_sand)
B(1,11,6,minecraft:soul_sand)
B(1,12,6,minecraft:soul_sand)
B(1,13,6,minecraft:soul_sand)
B(1,14,6,minecraft:soul_sand)
B(1,15,6,minecraft:soul_sand)
B(1,16,6,minecraft:soul_sand)
B(1,17,6,minecraft:soul_sand)
B(1,18,6,minecraft:soul_sand)
B(1,0,7,minecraft:soul_sand)
B(1,1,7,minecraft:soul_sand)
B(1,2,7,minecraft:soul_sand)
B(1,3,7,minecraft:soul_sand)
B(1,4,7,minecraft:soul_sand)
B(1,5,7,minecraft:soul_sand)
B(1,6,7,minecraft:soul_sand)
B(1,7,7,minecraft:soul_sand)
B(1,8,7,minecraft:soul_sand)
B(1,9,7,minecraft:soul_sand)
B(1,10,7,minecraft:soul_sand)
B(1,11,7,minecraft:soul_sand)
B(1,12,7,minecraft:soul_sand)
B(1,13,7,minecraft:soul_sand)
B(1,14,7,minecraft:soul_sand)
B(1,15,7,minecraft:soul_sand)
B(1,16,7,minecraft:soul_sand)
B(1,17,7,minecraft:soul_sand)
B(1,18,7,minecraft:soul_sand)
B(1,19,7,minecraft:soul_sand)
B(1,0,8,minecraft:soul_sand)
B(1,1,8,minecraft:soul_sand)
B(1,2,8,minecraft:soul_sand)
B(1,3,8,minecraft:soul_sand)
B(1,4,8,minecraft:soul_sand)
B(1,5,8,minecraft:soul_sand)
B(1,6,8,minecraft:soul_sand)
B(1,7,8,minecraft:soul_sand)
B(1,8,8,minecraft:soul_sand)
B(1,9,8,minecraft:soul_sand)
B(1,10,8,minecraft:soul_sand)
B(1,11,8,minecraft:soul_sand)
B(1,12,8,minecraft:soul_sand)
B(1,13,8,minecraft:soul_sand)
B(1,14,8,minecraft:soul_sand)
B(1,15,8,minecraft:soul_sand)
B(1,16,8,minecraft:soul_sand)
B(1,17,8,minecraft:soul_sand)
B(1,18,8,minecraft:soul_sand)
B(1,19,8,minecraft:soul_sand)
B(2,0,-7,minecraft:lava[level=8])
B(2,1,-7,minecraft:lava[level=8])
B(2,2,-7,minecraft:lava[level=8])
B(2,3,-7,minecraft:lava[level=8])
B(2,4,-7,minecraft:lava[level=8])
B(2,5,-7,minecraft:lava[level=2])
B(2,0,-6,minecraft:soul_sand)
B(2,1,-6,minecraft:soul_sand)
B(2,2,-6,minecraft:soul_sand)
B(2,3,-6,minecraft:soul_sand)
B(2,4,-6,minecraft:soul_sand)
B(2,5,-6,minecraft:lava[level=1])
B(2,0,-5,minecraft:soul_sand)
B(2,1,-5,minecraft:soul_sand)
B(2,2,-5,minecraft:soul_sand)
B(2,3,-5,minecraft:soul_sand)
B(2,4,-5,minecraft:soul_sand)
B(2,5,-5,minecraft:lava[level=8])
B(2,6,-5,minecraft:lava[level=5])
B(2,0,-4,minecraft:soul_sand)
B(2,1,-4,minecraft:soul_sand)
B(2,2,-4,minecraft:soul_sand)
B(2,3,-4,minecraft:soul_sand)
B(2,4,-4,minecraft:soul_sand)
B(2,5,-4,minecraft:soul_sand)
B(2,6,-4,minecraft:lava[level=4])
B(2,0,-3,minecraft:soul_sand)
B(2,1,-3,minecraft:soul_sand)
B(2,2,-3,minecraft:soul_sand)
B(2,3,-3,minecraft:soul_sand)
B(2,4,-3,minecraft:soul_sand)
B(2,5,-3,minecraft:soul_sand)
B(2,6,-3,minecraft:soul_sand)
B(2,0,-2,minecraft:soul_sand)
B(2,1,-2,minecraft:soul_sand)
B(2,2,-2,minecraft:soul_sand)
B(2,3,-2,minecraft:soul_sand)
B(2,4,-2,minecraft:soul_sand)
B(2,5,-2,minecraft:soul_sand)
B(2,6,-2,minecraft:soul_sand)
B(2,0,-1,minecraft:soul_sand)
B(2,1,-1,minecraft:soul_sand)
B(2,2,-1,minecraft:soul_sand)
B(2,3,-1,minecraft:soul_sand)
B(2,4,-1,minecraft:soul_sand)
B(2,5,-1,minecraft:soul_sand)
B(2,6,-1,minecraft:soul_sand)
B(2,7,-1,minecraft:soul_sand)
B(2,8,-1,minecraft:soul_sand)
B(2,9,-1,minecraft:soul_sand)
B(2,10,-1,minecraft:soul_sand)
B(2,11,-1,minecraft:soul_sand)
B(2,12,-1,minecraft:soul_sand)
B(2,13,-1,minecraft:soul_sand)
B(2,14,-1,minecraft:soul_sand)
B(2,15,-1,minecraft:soul_sand)
B(2,0,0,minecraft:soul_sand)
B(2,1,0,minecraft:soul_sand)
B(2,2,0,minecraft:soul_sand)
B(2,3,0,minecraft:soul_sand)
B(2,4,0,minecraft:soul_sand)
B(2,5,0,minecraft:soul_sand)
B(2,6,0,minecraft:soul_sand)
B(2,7,0,minecraft:soul_sand)
B(2,8,0,minecraft:soul_sand)
B(2,9,0,minecraft:soul_sand)
B(2,10,0,minecraft:soul_sand)
B(2,11,0,minecraft:soul_sand)
B(2,12,0,minecraft:soul_sand)
B(2,13,0,minecraft:soul_sand)
B(2,14,0,minecraft:soul_sand)
B(2,15,0,minecraft:soul_sand)
B(2,0,1,minecraft:soul_sand)
B(2,1,1,minecraft:soul_sand)
B(2,2,1,minecraft:soul_sand)
B(2,3,1,minecraft:soul_sand)
B(2,4,1,minecraft:soul_sand)
B(2,5,1,minecraft:soul_sand)
B(2,6,1,minecraft:soul_sand)
B(2,7,1,minecraft:soul_sand)
B(2,8,1,minecraft:soul_sand)
B(2,9,1,minecraft:soul_sand)
B(2,10,1,minecraft:soul_sand)
B(2,11,1,minecraft:soul_sand)
B(2,12,1,minecraft:soul_sand)
B(2,13,1,minecraft:soul_sand)
B(2,14,1,minecraft:soul_sand)
B(2,15,1,minecraft:soul_sand)
B(2,16,1,minecraft:soul_sand)
B(2,0,2,minecraft:soul_sand)
B(2,1,2,minecraft:soul_sand)
B(2,2,2,minecraft:soul_sand)
B(2,3,2,minecraft:soul_sand)
B(2,4,2,minecraft:soul_sand)
B(2,5,2,minecraft:soul_sand)
B(2,6,2,minecraft:soul_sand)
B(2,7,2,minecraft:soul_sand)
B(2,8,2,minecraft:soul_sand)
B(2,9,2,minecraft:soul_sand)
B(2,10,2,minecraft:soul_sand)
B(2,11,2,minecraft:soul_sand)
B(2,12,2,minecraft:soul_sand)
B(2,13,2,minecraft:soul_sand)
B(2,14,2,minecraft:soul_sand)
B(2,15,2,minecraft:soul_sand)
B(2,16,2,minecraft:soul_sand)
B(2,0,3,minecraft:soul_sand)
B(2,1,3,minecraft:soul_sand)
B(2,2,3,minecraft:soul_sand)
B(2,3,3,minecraft:soul_sand)
B(2,4,3,minecraft:soul_sand)
B(2,5,3,minecraft:soul_sand)
B(2,6,3,minecraft:soul_sand)
B(2,7,3,minecraft:soul_sand)
B(2,8,3,minecraft:soul_sand)
B(2,9,3,minecraft:soul_sand)
B(2,10,3,minecraft:soul_sand)
B(2,11,3,minecraft:soul_sand)
B(2,12,3,minecraft:soul_sand)
B(2,13,3,minecraft:soul_sand)
B(2,14,3,minecraft:soul_sand)
B(2,15,3,minecraft:soul_sand)
B(2,16,3,minecraft:soul_sand)
B(2,17,3,minecraft:soul_sand)
B(2,0,4,minecraft:soul_sand)
B(2,1,4,minecraft:soul_sand)
B(2,2,4,minecraft:soul_sand)
B(2,3,4,minecraft:soul_sand)
B(2,4,4,minecraft:soul_sand)
B(2,5,4,minecraft:soul_sand)
B(2,6,4,minecraft:soul_sand)
B(2,7,4,minecraft:soul_sand)
B(2,8,4,minecraft:soul_sand)
B(2,9,4,minecraft:soul_sand)
B(2,10,4,minecraft:soul_sand)
B(2,11,4,minecraft:soul_sand)
B(2,12,4,minecraft:soul_sand)
B(2,13,4,minecraft:soul_sand)
B(2,14,4,minecraft:soul_sand)
B(2,15,4,minecraft:soul_sand)
B(2,16,4,minecraft:soul_sand)
B(2,17,4,minecraft:soul_sand)
B(2,0,5,minecraft:soul_sand)
B(2,1,5,minecraft:soul_sand)
B(2,2,5,minecraft:soul_sand)
B(2,3,5,minecraft:soul_sand)
B(2,4,5,minecraft:soul_sand)
B(2,5,5,minecraft:soul_sand)
B(2,6,5,minecraft:soul_sand)
B(2,7,5,minecraft:soul_sand)
B(2,8,5,minecraft:soul_sand)
B(2,9,5,minecraft:soul_sand)
B(2,10,5,minecraft:soul_sand)
B(2,11,5,minecraft:soul_sand)
B(2,12,5,minecraft:soul_sand)
B(2,13,5,minecraft:soul_sand)
B(2,14,5,minecraft:soul_sand)
B(2,15,5,minecraft:soul_sand)
B(2,16,5,minecraft:soul_sand)
B(2,17,5,minecraft:soul_sand)
B(2,18,5,minecraft:soul_sand)
B(2,0,6,minecraft:soul_sand)
B(2,1,6,minecraft:soul_sand)
B(2,2,6,minecraft:soul_sand)
B(2,3,6,minecraft:soul_sand)
B(2,4,6,minecraft:soul_sand)
B(2,5,6,minecraft:soul_sand)
B(2,6,6,minecraft:soul_sand)
B(2,7,6,minecraft:soul_sand)
B(2,8,6,minecraft:soul_sand)
B(2,9,6,minecraft:soul_sand)
B(2,10,6,minecraft:soul_sand)
B(2,11,6,minecraft:soul_sand)
B(2,12,6,minecraft:soul_sand)
B(2,13,6,minecraft:soul_sand)
B(2,14,6,minecraft:soul_sand)
B(2,15,6,minecraft:soul_sand)
B(2,16,6,minecraft:soul_sand)
B(2,17,6,minecraft:soul_sand)
B(2,18,6,minecraft:soul_sand)
B(2,0,7,minecraft:soul_sand)
B(2,1,7,minecraft:soul_sand)
B(2,2,7,minecraft:soul_sand)
B(2,3,7,minecraft:soul_sand)
B(2,4,7,minecraft:soul_sand)
B(2,5,7,minecraft:soul_sand)
B(2,6,7,minecraft:soul_sand)
B(2,7,7,minecraft:soul_sand)
B(2,8,7,minecraft:soul_sand)
B(2,9,7,minecraft:soul_sand)
B(2,10,7,minecraft:soul_sand)
B(2,11,7,minecraft:soul_sand)
B(2,12,7,minecraft:soul_sand)
B(2,13,7,minecraft:soul_sand)
B(2,14,7,minecraft:soul_sand)
B(2,15,7,minecraft:soul_sand)
B(2,16,7,minecraft:soul_sand)
B(2,17,7,minecraft:soul_sand)
B(2,18,7,minecraft:soul_sand)
B(2,19,7,minecraft:soul_sand)
B(2,0,8,minecraft:soul_sand)
B(2,1,8,minecraft:soul_sand)
B(2,2,8,minecraft:soul_sand)
B(2,3,8,minecraft:soul_sand)
B(2,4,8,minecraft:soul_sand)
B(2,5,8,minecraft:soul_sand)
B(2,6,8,minecraft:soul_sand)
B(2,7,8,minecraft:soul_sand)
B(2,8,8,minecraft:soul_sand)
B(2,9,8,minecraft:soul_sand)
B(2,10,8,minecraft:soul_sand)
B(2,11,8,minecraft:soul_sand)
B(2,12,8,minecraft:soul_sand)
B(2,13,8,minecraft:soul_sand)
B(2,14,8,minecraft:soul_sand)
B(2,15,8,minecraft:soul_sand)
B(2,16,8,minecraft:soul_sand)
B(2,17,8,minecraft:soul_sand)
B(2,18,8,minecraft:soul_sand)
B(2,19,8,minecraft:soul_sand)
B(2,20,8,minecraft:soul_sand)
B(2,21,8,minecraft:soul_sand)
B(3,0,-7,minecraft:soul_sand)
B(3,1,-7,minecraft:soul_sand)
B(3,2,-7,minecraft:soul_sand)
B(3,3,-7,minecraft:soul_sand)
B(3,4,-7,minecraft:soul_sand)
B(3,0,-6,minecraft:soul_sand)
B(3,1,-6,minecraft:soul_sand)
B(3,2,-6,minecraft:soul_sand)
B(3,3,-6,minecraft:soul_sand)
B(3,4,-6,minecraft:soul_sand)
B(3,5,-6,minecraft:soul_sand)
B(3,0,-5,minecraft:soul_sand)
B(3,1,-5,minecraft:soul_sand)
B(3,2,-5,minecraft:soul_sand)
B(3,3,-5,minecraft:soul_sand)
B(3,4,-5,minecraft:soul_sand)
B(3,5,-5,minecraft:soul_sand)
B(3,6,-5,minecraft:soul_sand)
B(3,0,-4,minecraft:soul_sand)
B(3,1,-4,minecraft:soul_sand)
B(3,2,-4,minecraft:soul_sand)
B(3,3,-4,minecraft:soul_sand)
B(3,4,-4,minecraft:soul_sand)
B(3,5,-4,minecraft:soul_sand)
B(3,6,-4,minecraft:lava[level=3])
B(3,0,-3,minecraft:soul_sand)
B(3,1,-3,minecraft:soul_sand)
B(3,2,-3,minecraft:soul_sand)
B(3,3,-3,minecraft:soul_sand)
B(3,4,-3,minecraft:soul_sand)
B(3,5,-3,minecraft:soul_sand)
B(3,6,-3,minecraft:soul_sand)
B(3,0,-2,minecraft:soul_sand)
B(3,1,-2,minecraft:soul_sand)
B(3,2,-2,minecraft:soul_sand)
B(3,3,-2,minecraft:soul_sand)
B(3,4,-2,minecraft:soul_sand)
B(3,5,-2,minecraft:soul_sand)
B(3,6,-2,minecraft:soul_sand)
B(3,7,-2,minecraft:soul_sand)
B(3,8,-2,minecraft:soul_sand)
B(3,9,-2,minecraft:soul_sand)
B(3,0,-1,minecraft:soul_sand)
B(3,1,-1,minecraft:soul_sand)
B(3,2,-1,minecraft:soul_sand)
B(3,3,-1,minecraft:soul_sand)
B(3,4,-1,minecraft:soul_sand)
B(3,5,-1,minecraft:soul_sand)
B(3,6,-1,minecraft:soul_sand)
B(3,7,-1,minecraft:soul_sand)
B(3,8,-1,minecraft:soul_sand)
B(3,9,-1,minecraft:soul_sand)
B(3,10,-1,minecraft:soul_sand)
B(3,11,-1,minecraft:soul_sand)
B(3,12,-1,minecraft:soul_sand)
B(3,13,-1,minecraft:soul_sand)
B(3,14,-1,minecraft:soul_sand)
B(3,15,-1,minecraft:soul_sand)
B(3,0,0,minecraft:soul_sand)
B(3,1,0,minecraft:soul_sand)
B(3,2,0,minecraft:soul_sand)
B(3,3,0,minecraft:soul_sand)
B(3,4,0,minecraft:soul_sand)
B(3,5,0,minecraft:soul_sand)
B(3,6,0,minecraft:soul_sand)
B(3,7,0,minecraft:soul_sand)
B(3,8,0,minecraft:soul_sand)
B(3,9,0,minecraft:soul_sand)
B(3,10,0,minecraft:soul_sand)
B(3,11,0,minecraft:soul_sand)
B(3,12,0,minecraft:soul_sand)
B(3,13,0,minecraft:soul_sand)
B(3,14,0,minecraft:soul_sand)
B(3,15,0,minecraft:soul_sand)
B(3,16,0,minecraft:soul_sand)
B(3,0,1,minecraft:soul_sand)
B(3,1,1,minecraft:soul_sand)
B(3,2,1,minecraft:soul_sand)
B(3,3,1,minecraft:soul_sand)
B(3,4,1,minecraft:soul_sand)
B(3,5,1,minecraft:soul_sand)
B(3,6,1,minecraft:soul_sand)
B(3,7,1,minecraft:soul_sand)
B(3,8,1,minecraft:soul_sand)
B(3,9,1,minecraft:soul_sand)
B(3,10,1,minecraft:soul_sand)
B(3,11,1,minecraft:soul_sand)
B(3,12,1,minecraft:soul_sand)
B(3,13,1,minecraft:soul_sand)
B(3,14,1,minecraft:soul_sand)
B(3,15,1,minecraft:soul_sand)
B(3,16,1,minecraft:lava[level=3])
B(3,0,2,minecraft:soul_sand)
B(3,1,2,minecraft:soul_sand)
B(3,2,2,minecraft:soul_sand)
B(3,3,2,minecraft:soul_sand)
B(3,4,2,minecraft:soul_sand)
B(3,5,2,minecraft:soul_sand)
B(3,6,2,minecraft:soul_sand)
B(3,7,2,minecraft:soul_sand)
B(3,8,2,minecraft:soul_sand)
B(3,9,2,minecraft:soul_sand)
B(3,10,2,minecraft:soul_sand)
B(3,11,2,minecraft:soul_sand)
B(3,12,2,minecraft:soul_sand)
B(3,13,2,minecraft:soul_sand)
B(3,14,2,minecraft:soul_sand)
B(3,15,2,minecraft:soul_sand)
B(3,16,2,minecraft:lava[level=2])
B(3,0,3,minecraft:soul_sand)
B(3,1,3,minecraft:soul_sand)
B(3,2,3,minecraft:soul_sand)
B(3,3,3,minecraft:soul_sand)
B(3,4,3,minecraft:soul_sand)
B(3,5,3,minecraft:soul_sand)
B(3,6,3,minecraft:soul_sand)
B(3,7,3,minecraft:soul_sand)
B(3,8,3,minecraft:soul_sand)
B(3,9,3,minecraft:soul_sand)
B(3,10,3,minecraft:soul_sand)
B(3,11,3,minecraft:soul_sand)
B(3,12,3,minecraft:soul_sand)
B(3,13,3,minecraft:soul_sand)
B(3,14,3,minecraft:soul_sand)
B(3,15,3,minecraft:soul_sand)
B(3,16,3,minecraft:lava[level=1])
B(3,0,4,minecraft:soul_sand)
B(3,1,4,minecraft:soul_sand)
B(3,2,4,minecraft:soul_sand)
B(3,3,4,minecraft:soul_sand)
B(3,4,4,minecraft:soul_sand)
B(3,5,4,minecraft:soul_sand)
B(3,6,4,minecraft:soul_sand)
B(3,7,4,minecraft:soul_sand)
B(3,8,4,minecraft:soul_sand)
B(3,9,4,minecraft:soul_sand)
B(3,10,4,minecraft:soul_sand)
B(3,11,4,minecraft:soul_sand)
B(3,12,4,minecraft:soul_sand)
B(3,13,4,minecraft:soul_sand)
B(3,14,4,minecraft:soul_sand)
B(3,15,4,minecraft:soul_sand)
B(3,16,4,minecraft:lava[level=8])
B(3,17,4,minecraft:lava[level=2])
B(3,0,5,minecraft:soul_sand)
B(3,1,5,minecraft:soul_sand)
B(3,2,5,minecraft:soul_sand)
B(3,3,5,minecraft:soul_sand)
B(3,4,5,minecraft:soul_sand)
B(3,5,5,minecraft:soul_sand)
B(3,6,5,minecraft:soul_sand)
B(3,7,5,minecraft:soul_sand)
B(3,8,5,minecraft:soul_sand)
B(3,9,5,minecraft:soul_sand)
B(3,10,5,minecraft:soul_sand)
B(3,11,5,minecraft:soul_sand)
B(3,12,5,minecraft:soul_sand)
B(3,13,5,minecraft:soul_sand)
B(3,14,5,minecraft:soul_sand)
B(3,15,5,minecraft:soul_sand)
B(3,16,5,minecraft:soul_sand)
B(3,17,5,minecraft:lava[level=1])
B(3,0,6,minecraft:soul_sand)
B(3,1,6,minecraft:soul_sand)
B(3,2,6,minecraft:soul_sand)
B(3,3,6,minecraft:soul_sand)
B(3,4,6,minecraft:soul_sand)
B(3,5,6,minecraft:soul_sand)
B(3,6,6,minecraft:soul_sand)
B(3,7,6,minecraft:soul_sand)
B(3,8,6,minecraft:soul_sand)
B(3,9,6,minecraft:soul_sand)
B(3,10,6,minecraft:soul_sand)
B(3,11,6,minecraft:soul_sand)
B(3,12,6,minecraft:soul_sand)
B(3,13,6,minecraft:soul_sand)
B(3,14,6,minecraft:soul_sand)
B(3,15,6,minecraft:soul_sand)
B(3,16,6,minecraft:soul_sand)
B(3,17,6,minecraft:lava[level=8])
B(3,18,6,minecraft:lava[level=3])
B(3,0,7,minecraft:soul_sand)
B(3,1,7,minecraft:soul_sand)
B(3,2,7,minecraft:soul_sand)
B(3,3,7,minecraft:soul_sand)
B(3,4,7,minecraft:soul_sand)
B(3,5,7,minecraft:soul_sand)
B(3,6,7,minecraft:soul_sand)
B(3,7,7,minecraft:soul_sand)
B(3,8,7,minecraft:soul_sand)
B(3,9,7,minecraft:soul_sand)
B(3,10,7,minecraft:soul_sand)
B(3,11,7,minecraft:soul_sand)
B(3,12,7,minecraft:soul_sand)
B(3,13,7,minecraft:soul_sand)
B(3,14,7,minecraft:soul_sand)
B(3,15,7,minecraft:soul_sand)
B(3,16,7,minecraft:soul_sand)
B(3,17,7,minecraft:soul_sand)
B(3,18,7,minecraft:lava[level=2])
B(3,0,8,minecraft:soul_sand)
B(3,1,8,minecraft:soul_sand)
B(3,2,8,minecraft:soul_sand)
B(3,3,8,minecraft:soul_sand)
B(3,4,8,minecraft:soul_sand)
B(3,5,8,minecraft:soul_sand)
B(3,6,8,minecraft:soul_sand)
B(3,7,8,minecraft:soul_sand)
B(3,8,8,minecraft:soul_sand)
B(3,9,8,minecraft:soul_sand)
B(3,10,8,minecraft:soul_sand)
B(3,11,8,minecraft:soul_sand)
B(3,12,8,minecraft:soul_sand)
B(3,13,8,minecraft:soul_sand)
B(3,14,8,minecraft:soul_sand)
B(3,15,8,minecraft:soul_sand)
B(3,16,8,minecraft:soul_sand)
B(3,17,8,minecraft:soul_sand)
B(3,18,8,minecraft:soul_sand)
B(3,19,8,minecraft:soul_sand)
B(3,20,8,minecraft:soul_sand)
B(3,21,8,minecraft:soul_sand)
B(3,22,8,minecraft:soul_sand)
B(4,0,-7,minecraft:soul_sand)
B(4,1,-7,minecraft:soul_sand)
B(4,2,-7,minecraft:soul_sand)
B(4,3,-7,minecraft:soul_sand)
B(4,4,-7,minecraft:soul_sand)
B(4,0,-6,minecraft:soul_sand)
B(4,1,-6,minecraft:soul_sand)
B(4,2,-6,minecraft:soul_sand)
B(4,3,-6,minecraft:soul_sand)
B(4,4,-6,minecraft:soul_sand)
B(4,5,-6,minecraft:soul_sand)
B(4,0,-5,minecraft:soul_sand)
B(4,1,-5,minecraft:soul_sand)
B(4,2,-5,minecraft:soul_sand)
B(4,3,-5,minecraft:soul_sand)
B(4,4,-5,minecraft:soul_sand)
B(4,5,-5,minecraft:soul_sand)
B(4,6,-5,minecraft:soul_sand)
B(4,0,-4,minecraft:soul_sand)
B(4,1,-4,minecraft:soul_sand)
B(4,2,-4,minecraft:soul_sand)
B(4,3,-4,minecraft:soul_sand)
B(4,4,-4,minecraft:soul_sand)
B(4,5,-4,minecraft:soul_sand)
B(4,6,-4,minecraft:lava[level=2])
B(4,0,-3,minecraft:soul_sand)
B(4,1,-3,minecraft:soul_sand)
B(4,2,-3,minecraft:soul_sand)
B(4,3,-3,minecraft:soul_sand)
B(4,4,-3,minecraft:soul_sand)
B(4,5,-3,minecraft:soul_sand)
B(4,6,-3,minecraft:lava[level=1])
B(4,0,-2,minecraft:soul_sand)
B(4,1,-2,minecraft:soul_sand)
B(4,2,-2,minecraft:soul_sand)
B(4,3,-2,minecraft:soul_sand)
B(4,4,-2,minecraft:soul_sand)
B(4,5,-2,minecraft:soul_sand)
B(4,6,-2,minecraft:lava[level=8])
B(4,7,-2,minecraft:lava[level=8])
B(4,8,-2,minecraft:lava[level=8])
B(4,9,-2,minecraft:lava[level=1])
B(4,0,-1,minecraft:soul_sand)
B(4,1,-1,minecraft:soul_sand)
B(4,2,-1,minecraft:soul_sand)
B(4,3,-1,minecraft:soul_sand)
B(4,4,-1,minecraft:soul_sand)
B(4,5,-1,minecraft:soul_sand)
B(4,6,-1,minecraft:soul_sand)
B(4,7,-1,minecraft:soul_sand)
B(4,8,-1,minecraft:soul_sand)
B(4,9,-1,minecraft:lava[level=8])
B(4,10,-1,minecraft:lava[level=8])
B(4,11,-1,minecraft:lava[level=8])
B(4,12,-1,minecraft:lava[level=8])
B(4,13,-1,minecraft:lava[level=1])
B(4,0,0,minecraft:soul_sand)
B(4,1,0,minecraft:soul_sand)
B(4,2,0,minecraft:soul_sand)
B(4,3,0,minecraft:soul_sand)
B(4,4,0,minecraft:soul_sand)
B(4,5,0,minecraft:soul_sand)
B(4,6,0,minecraft:soul_sand)
B(4,7,0,minecraft:soul_sand)
B(4,8,0,minecraft:soul_sand)
B(4,9,0,minecraft:soul_sand)
B(4,10,0,minecraft:soul_sand)
B(4,11,0,minecraft:soul_sand)
B(4,12,0,minecraft:soul_sand)
B(4,13,0,minecraft:lava[level=8])
B(4,14,0,minecraft:lava[level=8])
B(4,15,0,minecraft:lava[level=1])
B(4,0,1,minecraft:soul_sand)
B(4,1,1,minecraft:soul_sand)
B(4,2,1,minecraft:soul_sand)
B(4,3,1,minecraft:soul_sand)
B(4,4,1,minecraft:soul_sand)
B(4,5,1,minecraft:soul_sand)
B(4,6,1,minecraft:soul_sand)
B(4,7,1,minecraft:soul_sand)
B(4,8,1,minecraft:soul_sand)
B(4,9,1,minecraft:soul_sand)
B(4,10,1,minecraft:soul_sand)
B(4,11,1,minecraft:soul_sand)
B(4,12,1,minecraft:soul_sand)
B(4,13,1,minecraft:soul_sand)
B(4,14,1,minecraft:soul_sand)
B(4,15,1,minecraft:lava[level=8])
B(4,16,1,minecraft:lava[level=4])
B(4,0,2,minecraft:soul_sand)
B(4,1,2,minecraft:soul_sand)
B(4,2,2,minecraft:soul_sand)
B(4,3,2,minecraft:soul_sand)
B(4,4,2,minecraft:soul_sand)
B(4,5,2,minecraft:soul_sand)
B(4,6,2,minecraft:soul_sand)
B(4,7,2,minecraft:soul_sand)
B(4,8,2,minecraft:soul_sand)
B(4,9,2,minecraft:soul_sand)
B(4,10,2,minecraft:soul_sand)
B(4,11,2,minecraft:soul_sand)
B(4,12,2,minecraft:soul_sand)
B(4,13,2,minecraft:soul_sand)
B(4,14,2,minecraft:soul_sand)
B(4,15,2,minecraft:soul_sand)
B(4,16,2,minecraft:soul_sand)
B(4,0,3,minecraft:soul_sand)
B(4,1,3,minecraft:soul_sand)
B(4,2,3,minecraft:soul_sand)
B(4,3,3,minecraft:soul_sand)
B(4,4,3,minecraft:soul_sand)
B(4,5,3,minecraft:soul_sand)
B(4,6,3,minecraft:soul_sand)
B(4,7,3,minecraft:soul_sand)
B(4,8,3,minecraft:soul_sand)
B(4,9,3,minecraft:soul_sand)
B(4,10,3,minecraft:soul_sand)
B(4,11,3,minecraft:soul_sand)
B(4,12,3,minecraft:soul_sand)
B(4,13,3,minecraft:soul_sand)
B(4,14,3,minecraft:soul_sand)
B(4,15,3,minecraft:soul_sand)
B(4,16,3,minecraft:soul_sand)
B(4,0,4,minecraft:soul_sand)
B(4,1,4,minecraft:soul_sand)
B(4,2,4,minecraft:soul_sand)
B(4,3,4,minecraft:soul_sand)
B(4,4,4,minecraft:soul_sand)
B(4,5,4,minecraft:soul_sand)
B(4,6,4,minecraft:soul_sand)
B(4,7,4,minecraft:soul_sand)
B(4,8,4,minecraft:soul_sand)
B(4,9,4,minecraft:soul_sand)
B(4,10,4,minecraft:soul_sand)
B(4,11,4,minecraft:soul_sand)
B(4,12,4,minecraft:soul_sand)
B(4,13,4,minecraft:soul_sand)
B(4,14,4,minecraft:soul_sand)
B(4,15,4,minecraft:soul_sand)
B(4,16,4,minecraft:soul_sand)
B(4,17,4,minecraft:soul_sand)
B(4,0,5,minecraft:soul_sand)
B(4,1,5,minecraft:soul_sand)
B(4,2,5,minecraft:soul_sand)
B(4,3,5,minecraft:soul_sand)
B(4,4,5,minecraft:soul_sand)
B(4,5,5,minecraft:soul_sand)
B(4,6,5,minecraft:soul_sand)
B(4,7,5,minecraft:soul_sand)
B(4,8,5,minecraft:soul_sand)
B(4,9,5,minecraft:soul_sand)
B(4,10,5,minecraft:soul_sand)
B(4,11,5,minecraft:soul_sand)
B(4,12,5,minecraft:soul_sand)
B(4,13,5,minecraft:soul_sand)
B(4,14,5,minecraft:soul_sand)
B(4,15,5,minecraft:soul_sand)
B(4,16,5,minecraft:soul_sand)
B(4,17,5,minecraft:soul_sand)
B(4,0,6,minecraft:soul_sand)
B(4,1,6,minecraft:soul_sand)
B(4,2,6,minecraft:soul_sand)
B(4,3,6,minecraft:soul_sand)
B(4,4,6,minecraft:soul_sand)
B(4,5,6,minecraft:soul_sand)
B(4,6,6,minecraft:soul_sand)
B(4,7,6,minecraft:soul_sand)
B(4,8,6,minecraft:soul_sand)
B(4,9,6,minecraft:soul_sand)
B(4,10,6,minecraft:soul_sand)
B(4,11,6,minecraft:soul_sand)
B(4,12,6,minecraft:soul_sand)
B(4,13,6,minecraft:soul_sand)
B(4,14,6,minecraft:soul_sand)
B(4,15,6,minecraft:soul_sand)
B(4,16,6,minecraft:soul_sand)
B(4,17,6,minecraft:soul_sand)
B(4,18,6,minecraft:soul_sand)
B(4,0,7,minecraft:soul_sand)
B(4,1,7,minecraft:soul_sand)
B(4,2,7,minecraft:soul_sand)
B(4,3,7,minecraft:soul_sand)
B(4,4,7,minecraft:soul_sand)
B(4,5,7,minecraft:soul_sand)
B(4,6,7,minecraft:soul_sand)
B(4,7,7,minecraft:soul_sand)
B(4,8,7,minecraft:soul_sand)
B(4,9,7,minecraft:soul_sand)
B(4,10,7,minecraft:soul_sand)
B(4,11,7,minecraft:soul_sand)
B(4,12,7,minecraft:soul_sand)
B(4,13,7,minecraft:soul_sand)
B(4,14,7,minecraft:soul_sand)
B(4,15,7,minecraft:soul_sand)
B(4,16,7,minecraft:soul_sand)
B(4,17,7,minecraft:soul_sand)
B(4,18,7,minecraft:lava[level=1])
B(4,0,8,minecraft:soul_sand)
B(4,1,8,minecraft:soul_sand)
B(4,2,8,minecraft:soul_sand)
B(4,3,8,minecraft:soul_sand)
B(4,4,8,minecraft:soul_sand)
B(4,5,8,minecraft:soul_sand)
B(4,6,8,minecraft:soul_sand)
B(4,7,8,minecraft:soul_sand)
B(4,8,8,minecraft:soul_sand)
B(4,9,8,minecraft:soul_sand)
B(4,10,8,minecraft:soul_sand)
B(4,11,8,minecraft:soul_sand)
B(4,12,8,minecraft:soul_sand)
B(4,13,8,minecraft:soul_sand)
B(4,14,8,minecraft:soul_sand)
B(4,15,8,minecraft:soul_sand)
B(4,16,8,minecraft:soul_sand)
B(4,17,8,minecraft:soul_sand)
B(4,18,8,minecraft:soul_sand)
B(4,19,8,minecraft:soul_sand)
B(4,20,8,minecraft:soul_sand)
B(4,21,8,minecraft:soul_sand)
B(4,22,8,minecraft:soul_sand)
B(5,0,-7,minecraft:soul_sand)
B(5,1,-7,minecraft:soul_sand)
B(5,2,-7,minecraft:soul_sand)
B(5,3,-7,minecraft:soul_sand)
B(5,4,-7,minecraft:soul_sand)
B(5,0,-6,minecraft:soul_sand)
B(5,1,-6,minecraft:soul_sand)
B(5,2,-6,minecraft:soul_sand)
B(5,3,-6,minecraft:soul_sand)
B(5,4,-6,minecraft:soul_sand)
B(5,5,-6,minecraft:soul_sand)
B(5,0,-5,minecraft:soul_sand)
B(5,1,-5,minecraft:soul_sand)
B(5,2,-5,minecraft:soul_sand)
B(5,3,-5,minecraft:soul_sand)
B(5,4,-5,minecraft:soul_sand)
B(5,5,-5,minecraft:soul_sand)
B(5,0,-4,minecraft:soul_sand)
B(5,1,-4,minecraft:soul_sand)
B(5,2,-4,minecraft:soul_sand)
B(5,3,-4,minecraft:soul_sand)
B(5,4,-4,minecraft:soul_sand)
B(5,5,-4,minecraft:soul_sand)
B(5,6,-4,minecraft:soul_sand)
B(5,0,-3,minecraft:soul_sand)
B(5,1,-3,minecraft:soul_sand)
B(5,2,-3,minecraft:soul_sand)
B(5,3,-3,minecraft:soul_sand)
B(5,4,-3,minecraft:soul_sand)
B(5,5,-3,minecraft:soul_sand)
B(5,6,-3,minecraft:soul_sand)
B(5,0,-2,minecraft:soul_sand)
B(5,1,-2,minecraft:soul_sand)
B(5,2,-2,minecraft:soul_sand)
B(5,3,-2,minecraft:soul_sand)
B(5,4,-2,minecraft:soul_sand)
B(5,5,-2,minecraft:soul_sand)
B(5,6,-2,minecraft:soul_sand)
B(5,7,-2,minecraft:soul_sand)
B(5,8,-2,minecraft:soul_sand)
B(5,9,-2,minecraft:soul_sand)
B(5,0,-1,minecraft:soul_sand)
B(5,1,-1,minecraft:soul_sand)
B(5,2,-1,minecraft:soul_sand)
B(5,3,-1,minecraft:soul_sand)
B(5,4,-1,minecraft:soul_sand)
B(5,5,-1,minecraft:soul_sand)
B(5,6,-1,minecraft:soul_sand)
B(5,7,-1,minecraft:soul_sand)
B(5,8,-1,minecraft:soul_sand)
B(5,9,-1,minecraft:soul_sand)
B(5,10,-1,minecraft:soul_sand)
B(5,11,-1,minecraft:soul_sand)
B(5,12,-1,minecraft:soul_sand)
B(5,13,-1,minecraft:soul_sand)
B(5,0,0,minecraft:soul_sand)
B(5,1,0,minecraft:soul_sand)
B(5,2,0,minecraft:soul_sand)
B(5,3,0,minecraft:soul_sand)
B(5,4,0,minecraft:soul_sand)
B(5,5,0,minecraft:soul_sand)
B(5,6,0,minecraft:soul_sand)
B(5,7,0,minecraft:soul_sand)
B(5,8,0,minecraft:soul_sand)
B(5,9,0,minecraft:soul_sand)
B(5,10,0,minecraft:soul_sand)
B(5,11,0,minecraft:soul_sand)
B(5,12,0,minecraft:soul_sand)
B(5,13,0,minecraft:soul_sand)
B(5,14,0,minecraft:soul_sand)
B(5,0,1,minecraft:soul_sand)
B(5,1,1,minecraft:soul_sand)
B(5,2,1,minecraft:soul_sand)
B(5,3,1,minecraft:soul_sand)
B(5,4,1,minecraft:soul_sand)
B(5,5,1,minecraft:soul_sand)
B(5,6,1,minecraft:soul_sand)
B(5,7,1,minecraft:soul_sand)
B(5,8,1,minecraft:soul_sand)
B(5,9,1,minecraft:soul_sand)
B(5,10,1,minecraft:soul_sand)
B(5,11,1,minecraft:soul_sand)
B(5,12,1,minecraft:soul_sand)
B(5,13,1,minecraft:soul_sand)
B(5,14,1,minecraft:soul_sand)
B(5,15,1,minecraft:soul_sand)
B(5,16,1,minecraft:soul_sand)
B(5,0,2,minecraft:soul_sand)
B(5,1,2,minecraft:soul_sand)
B(5,2,2,minecraft:soul_sand)
B(5,3,2,minecraft:soul_sand)
B(5,4,2,minecraft:soul_sand)
B(5,5,2,minecraft:soul_sand)
B(5,6,2,minecraft:soul_sand)
B(5,7,2,minecraft:soul_sand)
B(5,8,2,minecraft:soul_sand)
B(5,9,2,minecraft:soul_sand)
B(5,10,2,minecraft:soul_sand)
B(5,11,2,minecraft:soul_sand)
B(5,12,2,minecraft:soul_sand)
B(5,13,2,minecraft:soul_sand)
B(5,14,2,minecraft:soul_sand)
B(5,15,2,minecraft:soul_sand)
B(5,16,2,minecraft:soul_sand)
B(5,0,3,minecraft:soul_sand)
B(5,1,3,minecraft:soul_sand)
B(5,2,3,minecraft:soul_sand)
B(5,3,3,minecraft:soul_sand)
B(5,4,3,minecraft:soul_sand)
B(5,5,3,minecraft:soul_sand)
B(5,6,3,minecraft:soul_sand)
B(5,7,3,minecraft:soul_sand)
B(5,8,3,minecraft:soul_sand)
B(5,9,3,minecraft:soul_sand)
B(5,10,3,minecraft:soul_sand)
B(5,11,3,minecraft:soul_sand)
B(5,12,3,minecraft:soul_sand)
B(5,13,3,minecraft:soul_sand)
B(5,14,3,minecraft:soul_sand)
B(5,15,3,minecraft:soul_sand)
B(5,16,3,minecraft:soul_sand)
B(5,0,4,minecraft:soul_sand)
B(5,1,4,minecraft:soul_sand)
B(5,2,4,minecraft:soul_sand)
B(5,3,4,minecraft:soul_sand)
B(5,4,4,minecraft:soul_sand)
B(5,5,4,minecraft:soul_sand)
B(5,6,4,minecraft:soul_sand)
B(5,7,4,minecraft:soul_sand)
B(5,8,4,minecraft:soul_sand)
B(5,9,4,minecraft:soul_sand)
B(5,10,4,minecraft:soul_sand)
B(5,11,4,minecraft:soul_sand)
B(5,12,4,minecraft:soul_sand)
B(5,13,4,minecraft:soul_sand)
B(5,14,4,minecraft:soul_sand)
B(5,15,4,minecraft:soul_sand)
B(5,16,4,minecraft:soul_sand)
B(5,17,4,minecraft:soul_sand)
B(5,0,5,minecraft:soul_sand)
B(5,1,5,minecraft:soul_sand)
B(5,2,5,minecraft:soul_sand)
B(5,3,5,minecraft:soul_sand)
B(5,4,5,minecraft:soul_sand)
B(5,5,5,minecraft:soul_sand)
B(5,6,5,minecraft:soul_sand)
B(5,7,5,minecraft:soul_sand)
B(5,8,5,minecraft:soul_sand)
B(5,9,5,minecraft:soul_sand)
B(5,10,5,minecraft:soul_sand)
B(5,11,5,minecraft:soul_sand)
B(5,12,5,minecraft:soul_sand)
B(5,13,5,minecraft:soul_sand)
B(5,14,5,minecraft:soul_sand)
B(5,15,5,minecraft:soul_sand)
B(5,16,5,minecraft:soul_sand)
B(5,17,5,minecraft:soul_sand)
B(5,0,6,minecraft:soul_sand)
B(5,1,6,minecraft:soul_sand)
B(5,2,6,minecraft:soul_sand)
B(5,3,6,minecraft:soul_sand)
B(5,4,6,minecraft:soul_sand)
B(5,5,6,minecraft:soul_sand)
B(5,6,6,minecraft:soul_sand)
B(5,7,6,minecraft:soul_sand)
B(5,8,6,minecraft:soul_sand)
B(5,9,6,minecraft:soul_sand)
B(5,10,6,minecraft:soul_sand)
B(5,11,6,minecraft:soul_sand)
B(5,12,6,minecraft:soul_sand)
B(5,13,6,minecraft:soul_sand)
B(5,14,6,minecraft:soul_sand)
B(5,15,6,minecraft:soul_sand)
B(5,16,6,minecraft:soul_sand)
B(5,17,6,minecraft:soul_sand)
B(5,18,6,minecraft:soul_sand)
B(5,19,6,minecraft:soul_sand)
B(5,20,6,minecraft:soul_sand)
B(5,21,6,minecraft:soul_sand)
B(5,22,6,minecraft:soul_sand)
B(5,0,7,minecraft:soul_sand)
B(5,1,7,minecraft:soul_sand)
B(5,2,7,minecraft:soul_sand)
B(5,3,7,minecraft:soul_sand)
B(5,4,7,minecraft:soul_sand)
B(5,5,7,minecraft:soul_sand)
B(5,6,7,minecraft:soul_sand)
B(5,7,7,minecraft:soul_sand)
B(5,8,7,minecraft:soul_sand)
B(5,9,7,minecraft:soul_sand)
B(5,10,7,minecraft:soul_sand)
B(5,11,7,minecraft:soul_sand)
B(5,12,7,minecraft:soul_sand)
B(5,13,7,minecraft:soul_sand)
B(5,14,7,minecraft:soul_sand)
B(5,15,7,minecraft:soul_sand)
B(5,16,7,minecraft:soul_sand)
B(5,17,7,minecraft:soul_sand)
B(5,18,7,minecraft:lava[level=8])
B(5,19,7,minecraft:lava[level=8])
B(5,20,7,minecraft:lava[level=8])
B(5,21,7,minecraft:lava[level=8])
B(5,22,7,minecraft:lava[level=2])
B(5,0,8,minecraft:soul_sand)
B(5,1,8,minecraft:soul_sand)
B(5,2,8,minecraft:soul_sand)
B(5,3,8,minecraft:soul_sand)
B(5,4,8,minecraft:soul_sand)
B(5,5,8,minecraft:soul_sand)
B(5,6,8,minecraft:soul_sand)
B(5,7,8,minecraft:soul_sand)
B(5,8,8,minecraft:soul_sand)
B(5,9,8,minecraft:soul_sand)
B(5,10,8,minecraft:soul_sand)
B(5,11,8,minecraft:soul_sand)
B(5,12,8,minecraft:soul_sand)
B(5,13,8,minecraft:soul_sand)
B(5,14,8,minecraft:soul_sand)
B(5,15,8,minecraft:soul_sand)
B(5,16,8,minecraft:soul_sand)
B(5,17,8,minecraft:soul_sand)
B(5,18,8,minecraft:soul_sand)
B(5,19,8,minecraft:soul_sand)
B(5,20,8,minecraft:soul_sand)
B(5,21,8,minecraft:soul_sand)
B(5,22,8,minecraft:soul_sand)
B(6,0,-7,minecraft:soul_sand)
B(6,1,-7,minecraft:soul_sand)
B(6,2,-7,minecraft:soul_sand)
B(6,3,-7,minecraft:soul_sand)
B(6,0,-6,minecraft:soul_sand)
B(6,1,-6,minecraft:soul_sand)
B(6,2,-6,minecraft:soul_sand)
B(6,3,-6,minecraft:soul_sand)
B(6,4,-6,minecraft:soul_sand)
B(6,0,-5,minecraft:soul_sand)
B(6,1,-5,minecraft:soul_sand)
B(6,2,-5,minecraft:soul_sand)
B(6,3,-5,minecraft:soul_sand)
B(6,4,-5,minecraft:soul_sand)
B(6,5,-5,minecraft:soul_sand)
B(6,6,-5,minecraft:soul_sand)
B(6,0,-4,minecraft:soul_sand)
B(6,1,-4,minecraft:soul_sand)
B(6,2,-4,minecraft:soul_sand)
B(6,3,-4,minecraft:soul_sand)
B(6,4,-4,minecraft:soul_sand)
B(6,5,-4,minecraft:soul_sand)
B(6,6,-4,minecraft:soul_sand)
B(6,7,-4,minecraft:soul_sand)
B(6,0,-3,minecraft:soul_sand)
B(6,1,-3,minecraft:soul_sand)
B(6,2,-3,minecraft:soul_sand)
B(6,3,-3,minecraft:soul_sand)
B(6,4,-3,minecraft:soul_sand)
B(6,5,-3,minecraft:soul_sand)
B(6,6,-3,minecraft:soul_sand)
B(6,7,-3,minecraft:soul_sand)
B(6,0,-2,minecraft:soul_sand)
B(6,1,-2,minecraft:soul_sand)
B(6,2,-2,minecraft:soul_sand)
B(6,3,-2,minecraft:soul_sand)
B(6,4,-2,minecraft:soul_sand)
B(6,5,-2,minecraft:soul_sand)
B(6,6,-2,minecraft:soul_sand)
B(6,7,-2,minecraft:soul_sand)
B(6,0,-1,minecraft:soul_sand)
B(6,1,-1,minecraft:soul_sand)
B(6,2,-1,minecraft:soul_sand)
B(6,3,-1,minecraft:soul_sand)
B(6,4,-1,minecraft:soul_sand)
B(6,5,-1,minecraft:soul_sand)
B(6,6,-1,minecraft:soul_sand)
B(6,7,-1,minecraft:soul_sand)
B(6,8,-1,minecraft:soul_sand)
B(6,9,-1,minecraft:soul_sand)
B(6,10,-1,minecraft:soul_sand)
B(6,11,-1,minecraft:soul_sand)
B(6,12,-1,minecraft:soul_sand)
B(6,0,0,minecraft:soul_sand)
B(6,1,0,minecraft:soul_sand)
B(6,2,0,minecraft:soul_sand)
B(6,3,0,minecraft:soul_sand)
B(6,4,0,minecraft:soul_sand)
B(6,5,0,minecraft:soul_sand)
B(6,6,0,minecraft:soul_sand)
B(6,7,0,minecraft:soul_sand)
B(6,8,0,minecraft:soul_sand)
B(6,9,0,minecraft:soul_sand)
B(6,10,0,minecraft:soul_sand)
B(6,11,0,minecraft:soul_sand)
B(6,12,0,minecraft:soul_sand)
B(6,13,0,minecraft:soul_sand)
B(6,14,0,minecraft:soul_sand)
B(6,0,1,minecraft:soul_sand)
B(6,1,1,minecraft:soul_sand)
B(6,2,1,minecraft:soul_sand)
B(6,3,1,minecraft:soul_sand)
B(6,4,1,minecraft:soul_sand)
B(6,5,1,minecraft:soul_sand)
B(6,6,1,minecraft:soul_sand)
B(6,7,1,minecraft:soul_sand)
B(6,8,1,minecraft:soul_sand)
B(6,9,1,minecraft:soul_sand)
B(6,10,1,minecraft:soul_sand)
B(6,11,1,minecraft:soul_sand)
B(6,12,1,minecraft:soul_sand)
B(6,13,1,minecraft:soul_sand)
B(6,14,1,minecraft:soul_sand)
B(6,15,1,minecraft:soul_sand)
B(6,0,2,minecraft:soul_sand)
B(6,1,2,minecraft:soul_sand)
B(6,2,2,minecraft:soul_sand)
B(6,3,2,minecraft:soul_sand)
B(6,4,2,minecraft:soul_sand)
B(6,5,2,minecraft:soul_sand)
B(6,6,2,minecraft:soul_sand)
B(6,7,2,minecraft:soul_sand)
B(6,8,2,minecraft:soul_sand)
B(6,9,2,minecraft:soul_sand)
B(6,10,2,minecraft:soul_sand)
B(6,11,2,minecraft:soul_sand)
B(6,12,2,minecraft:soul_sand)
B(6,13,2,minecraft:soul_sand)
B(6,14,2,minecraft:soul_sand)
B(6,15,2,minecraft:soul_sand)
B(6,16,2,minecraft:soul_sand)
B(6,0,3,minecraft:soul_sand)
B(6,1,3,minecraft:soul_sand)
B(6,2,3,minecraft:soul_sand)
B(6,3,3,minecraft:soul_sand)
B(6,4,3,minecraft:soul_sand)
B(6,5,3,minecraft:soul_sand)
B(6,6,3,minecraft:soul_sand)
B(6,7,3,minecraft:soul_sand)
B(6,8,3,minecraft:soul_sand)
B(6,9,3,minecraft:soul_sand)
B(6,10,3,minecraft:soul_sand)
B(6,11,3,minecraft:soul_sand)
B(6,12,3,minecraft:soul_sand)
B(6,13,3,minecraft:soul_sand)
B(6,14,3,minecraft:soul_sand)
B(6,15,3,minecraft:soul_sand)
B(6,16,3,minecraft:lava[level=1])
B(6,0,4,minecraft:soul_sand)
B(6,1,4,minecraft:soul_sand)
B(6,2,4,minecraft:soul_sand)
B(6,3,4,minecraft:soul_sand)
B(6,4,4,minecraft:soul_sand)
B(6,5,4,minecraft:soul_sand)
B(6,6,4,minecraft:soul_sand)
B(6,7,4,minecraft:soul_sand)
B(6,8,4,minecraft:soul_sand)
B(6,9,4,minecraft:soul_sand)
B(6,10,4,minecraft:soul_sand)
B(6,11,4,minecraft:soul_sand)
B(6,12,4,minecraft:soul_sand)
B(6,13,4,minecraft:soul_sand)
B(6,14,4,minecraft:soul_sand)
B(6,15,4,minecraft:soul_sand)
B(6,16,4,minecraft:lava[level=8])
B(6,17,4,minecraft:lava[level=2])
B(6,0,5,minecraft:soul_sand)
B(6,1,5,minecraft:soul_sand)
B(6,2,5,minecraft:soul_sand)
B(6,3,5,minecraft:soul_sand)
B(6,4,5,minecraft:soul_sand)
B(6,5,5,minecraft:soul_sand)
B(6,6,5,minecraft:soul_sand)
B(6,7,5,minecraft:soul_sand)
B(6,8,5,minecraft:soul_sand)
B(6,9,5,minecraft:soul_sand)
B(6,10,5,minecraft:soul_sand)
B(6,11,5,minecraft:soul_sand)
B(6,12,5,minecraft:soul_sand)
B(6,13,5,minecraft:soul_sand)
B(6,14,5,minecraft:soul_sand)
B(6,15,5,minecraft:soul_sand)
B(6,16,5,minecraft:soul_sand)
B(6,17,5,minecraft:lava[level=1])
B(6,0,6,minecraft:soul_sand)
B(6,1,6,minecraft:soul_sand)
B(6,2,6,minecraft:soul_sand)
B(6,3,6,minecraft:soul_sand)
B(6,4,6,minecraft:soul_sand)
B(6,5,6,minecraft:soul_sand)
B(6,6,6,minecraft:soul_sand)
B(6,7,6,minecraft:soul_sand)
B(6,8,6,minecraft:soul_sand)
B(6,9,6,minecraft:soul_sand)
B(6,10,6,minecraft:soul_sand)
B(6,11,6,minecraft:soul_sand)
B(6,12,6,minecraft:soul_sand)
B(6,13,6,minecraft:soul_sand)
B(6,14,6,minecraft:soul_sand)
B(6,15,6,minecraft:soul_sand)
B(6,16,6,minecraft:soul_sand)
B(6,17,6,minecraft:lava[level=8])
B(6,18,6,minecraft:lava[level=8])
B(6,19,6,minecraft:lava[level=8])
B(6,20,6,minecraft:lava[level=8])
B(6,21,6,minecraft:lava[level=8])
B(6,22,6,minecraft:lava[level=2])
B(6,0,7,minecraft:soul_sand)
B(6,1,7,minecraft:soul_sand)
B(6,2,7,minecraft:soul_sand)
B(6,3,7,minecraft:soul_sand)
B(6,4,7,minecraft:soul_sand)
B(6,5,7,minecraft:soul_sand)
B(6,6,7,minecraft:soul_sand)
B(6,7,7,minecraft:soul_sand)
B(6,8,7,minecraft:soul_sand)
B(6,9,7,minecraft:soul_sand)
B(6,10,7,minecraft:soul_sand)
B(6,11,7,minecraft:soul_sand)
B(6,12,7,minecraft:soul_sand)
B(6,13,7,minecraft:soul_sand)
B(6,14,7,minecraft:soul_sand)
B(6,15,7,minecraft:soul_sand)
B(6,16,7,minecraft:soul_sand)
B(6,17,7,minecraft:soul_sand)
B(6,18,7,minecraft:soul_sand)
B(6,19,7,minecraft:soul_sand)
B(6,20,7,minecraft:soul_sand)
B(6,21,7,minecraft:soul_sand)
B(6,22,7,minecraft:lava[level=1])
B(6,0,8,minecraft:soul_sand)
B(6,1,8,minecraft:soul_sand)
B(6,2,8,minecraft:soul_sand)
B(6,3,8,minecraft:soul_sand)
B(6,4,8,minecraft:soul_sand)
B(6,5,8,minecraft:soul_sand)
B(6,6,8,minecraft:soul_sand)
B(6,7,8,minecraft:soul_sand)
B(6,8,8,minecraft:soul_sand)
B(6,9,8,minecraft:soul_sand)
B(6,10,8,minecraft:soul_sand)
B(6,11,8,minecraft:soul_sand)
B(6,12,8,minecraft:soul_sand)
B(6,13,8,minecraft:soul_sand)
B(6,14,8,minecraft:soul_sand)
B(6,15,8,minecraft:soul_sand)
B(6,16,8,minecraft:soul_sand)
B(6,17,8,minecraft:soul_sand)
B(6,18,8,minecraft:soul_sand)
B(6,19,8,minecraft:soul_sand)
B(6,20,8,minecraft:soul_sand)
B(6,21,8,minecraft:soul_sand)
B(6,22,8,minecraft:lava[level=8])
B(6,23,8,minecraft:lava[level=2])
B(7,0,-7,minecraft:lava[level=8])
B(7,1,-7,minecraft:lava[level=8])
B(7,2,-7,minecraft:lava[level=8])
B(7,3,-7,minecraft:lava[level=1])
B(7,0,-6,minecraft:soul_sand)
B(7,1,-6,minecraft:soul_sand)
B(7,2,-6,minecraft:soul_sand)
B(7,3,-6,minecraft:lava[level=8])
B(7,4,-6,minecraft:lava[level=1])
B(7,0,-5,minecraft:soul_sand)
B(7,1,-5,minecraft:soul_sand)
B(7,2,-5,minecraft:soul_sand)
B(7,3,-5,minecraft:soul_sand)
B(7,4,-5,minecraft:lava[level=8])
B(7,5,-5,minecraft:lava[level=8])
B(7,6,-5,minecraft:lava[level=1])
B(7,0,-4,minecraft:soul_sand)
B(7,1,-4,minecraft:soul_sand)
B(7,2,-4,minecraft:soul_sand)
B(7,3,-4,minecraft:soul_sand)
B(7,4,-4,minecraft:soul_sand)
B(7,5,-4,minecraft:soul_sand)
B(7,6,-4,minecraft:lava[level=8])
B(7,7,-4,minecraft:lava[level=6])
B(7,0,-3,minecraft:soul_sand)
B(7,1,-3,minecraft:soul_sand)
B(7,2,-3,minecraft:soul_sand)
B(7,3,-3,minecraft:soul_sand)
B(7,4,-3,minecraft:soul_sand)
B(7,5,-3,minecraft:soul_sand)
B(7,6,-3,minecraft:soul_sand)
B(7,7,-3,minecraft:lava[level=5])
B(7,0,-2,minecraft:soul_sand)
B(7,1,-2,minecraft:soul_sand)
B(7,2,-2,minecraft:soul_sand)
B(7,3,-2,minecraft:soul_sand)
B(7,4,-2,minecraft:soul_sand)
B(7,5,-2,minecraft:soul_sand)
B(7,6,-2,minecraft:soul_sand)
B(7,7,-2,minecraft:lava[level=4])
B(7,0,-1,minecraft:soul_sand)
B(7,1,-1,minecraft:soul_sand)
B(7,2,-1,minecraft:soul_sand)
B(7,3,-1,minecraft:soul_sand)
B(7,4,-1,minecraft:soul_sand)
B(7,5,-1,minecraft:soul_sand)
B(7,6,-1,minecraft:soul_sand)
B(7,7,-1,minecraft:lava[level=3])
B(7,0,0,minecraft:soul_sand)
B(7,1,0,minecraft:soul_sand)
B(7,2,0,minecraft:soul_sand)
B(7,3,0,minecraft:soul_sand)
B(7,4,0,minecraft:soul_sand)
B(7,5,0,minecraft:soul_sand)
B(7,6,0,minecraft:soul_sand)
B(7,7,0,minecraft:soul_sand)
B(7,8,0,minecraft:soul_sand)
B(7,9,0,minecraft:soul_sand)
B(7,10,0,minecraft:soul_sand)
B(7,11,0,minecraft:soul_sand)
B(7,12,0,minecraft:soul_sand)
B(7,13,0,minecraft:soul_sand)
B(7,0,1,minecraft:soul_sand)
B(7,1,1,minecraft:soul_sand)
B(7,2,1,minecraft:soul_sand)
B(7,3,1,minecraft:soul_sand)
B(7,4,1,minecraft:soul_sand)
B(7,5,1,minecraft:soul_sand)
B(7,6,1,minecraft:soul_sand)
B(7,7,1,minecraft:soul_sand)
B(7,8,1,minecraft:soul_sand)
B(7,9,1,minecraft:soul_sand)
B(7,10,1,minecraft:soul_sand)
B(7,11,1,minecraft:soul_sand)
B(7,12,1,minecraft:soul_sand)
B(7,13,1,minecraft:soul_sand)
B(7,14,1,minecraft:soul_sand)
B(7,15,1,minecraft:soul_sand)
B(7,16,1,minecraft:soul_sand)
B(7,0,2,minecraft:soul_sand)
B(7,1,2,minecraft:soul_sand)
B(7,2,2,minecraft:soul_sand)
B(7,3,2,minecraft:soul_sand)
B(7,4,2,minecraft:soul_sand)
B(7,5,2,minecraft:soul_sand)
B(7,6,2,minecraft:soul_sand)
B(7,7,2,minecraft:soul_sand)
B(7,8,2,minecraft:soul_sand)
B(7,9,2,minecraft:soul_sand)
B(7,10,2,minecraft:soul_sand)
B(7,11,2,minecraft:soul_sand)
B(7,12,2,minecraft:soul_sand)
B(7,13,2,minecraft:soul_sand)
B(7,14,2,minecraft:soul_sand)
B(7,15,2,minecraft:soul_sand)
B(7,16,2,minecraft:lava[level=3])
B(7,0,3,minecraft:soul_sand)
B(7,1,3,minecraft:soul_sand)
B(7,2,3,minecraft:soul_sand)
B(7,3,3,minecraft:soul_sand)
B(7,4,3,minecraft:soul_sand)
B(7,5,3,minecraft:soul_sand)
B(7,6,3,minecraft:soul_sand)
B(7,7,3,minecraft:soul_sand)
B(7,8,3,minecraft:soul_sand)
B(7,9,3,minecraft:soul_sand)
B(7,10,3,minecraft:soul_sand)
B(7,11,3,minecraft:soul_sand)
B(7,12,3,minecraft:soul_sand)
B(7,13,3,minecraft:soul_sand)
B(7,14,3,minecraft:soul_sand)
B(7,15,3,minecraft:soul_sand)
B(7,16,3,minecraft:lava[level=2])
B(7,0,4,minecraft:soul_sand)
B(7,1,4,minecraft:soul_sand)
B(7,2,4,minecraft:soul_sand)
B(7,3,4,minecraft:soul_sand)
B(7,4,4,minecraft:soul_sand)
B(7,5,4,minecraft:soul_sand)
B(7,6,4,minecraft:soul_sand)
B(7,7,4,minecraft:soul_sand)
B(7,8,4,minecraft:soul_sand)
B(7,9,4,minecraft:soul_sand)
B(7,10,4,minecraft:soul_sand)
B(7,11,4,minecraft:soul_sand)
B(7,12,4,minecraft:soul_sand)
B(7,13,4,minecraft:soul_sand)
B(7,14,4,minecraft:soul_sand)
B(7,15,4,minecraft:soul_sand)
B(7,16,4,minecraft:soul_sand)
B(7,17,4,minecraft:soul_sand)
B(7,18,4,minecraft:soul_sand)
B(7,0,5,minecraft:soul_sand)
B(7,1,5,minecraft:soul_sand)
B(7,2,5,minecraft:soul_sand)
B(7,3,5,minecraft:soul_sand)
B(7,4,5,minecraft:soul_sand)
B(7,5,5,minecraft:soul_sand)
B(7,6,5,minecraft:soul_sand)
B(7,7,5,minecraft:soul_sand)
B(7,8,5,minecraft:soul_sand)
B(7,9,5,minecraft:soul_sand)
B(7,10,5,minecraft:soul_sand)
B(7,11,5,minecraft:soul_sand)
B(7,12,5,minecraft:soul_sand)
B(7,13,5,minecraft:soul_sand)
B(7,14,5,minecraft:soul_sand)
B(7,15,5,minecraft:soul_sand)
B(7,16,5,minecraft:soul_sand)
B(7,17,5,minecraft:soul_sand)
B(7,18,5,minecraft:soul_sand)
B(7,19,5,minecraft:soul_sand)
B(7,0,6,minecraft:soul_sand)
B(7,1,6,minecraft:soul_sand)
B(7,2,6,minecraft:soul_sand)
B(7,3,6,minecraft:soul_sand)
B(7,4,6,minecraft:soul_sand)
B(7,5,6,minecraft:soul_sand)
B(7,6,6,minecraft:soul_sand)
B(7,7,6,minecraft:soul_sand)
B(7,8,6,minecraft:soul_sand)
B(7,9,6,minecraft:soul_sand)
B(7,10,6,minecraft:soul_sand)
B(7,11,6,minecraft:soul_sand)
B(7,12,6,minecraft:soul_sand)
B(7,13,6,minecraft:soul_sand)
B(7,14,6,minecraft:soul_sand)
B(7,15,6,minecraft:soul_sand)
B(7,16,6,minecraft:soul_sand)
B(7,17,6,minecraft:soul_sand)
B(7,18,6,minecraft:soul_sand)
B(7,19,6,minecraft:soul_sand)
B(7,20,6,minecraft:soul_sand)
B(7,21,6,minecraft:soul_sand)
B(7,22,6,minecraft:soul_sand)
B(7,0,7,minecraft:soul_sand)
B(7,1,7,minecraft:soul_sand)
B(7,2,7,minecraft:soul_sand)
B(7,3,7,minecraft:soul_sand)
B(7,4,7,minecraft:soul_sand)
B(7,5,7,minecraft:soul_sand)
B(7,6,7,minecraft:soul_sand)
B(7,7,7,minecraft:soul_sand)
B(7,8,7,minecraft:soul_sand)
B(7,9,7,minecraft:soul_sand)
B(7,10,7,minecraft:soul_sand)
B(7,11,7,minecraft:soul_sand)
B(7,12,7,minecraft:soul_sand)
B(7,13,7,minecraft:soul_sand)
B(7,14,7,minecraft:soul_sand)
B(7,15,7,minecraft:soul_sand)
B(7,16,7,minecraft:soul_sand)
B(7,17,7,minecraft:soul_sand)
B(7,18,7,minecraft:soul_sand)
B(7,19,7,minecraft:soul_sand)
B(7,20,7,minecraft:soul_sand)
B(7,21,7,minecraft:soul_sand)
B(7,22,7,minecraft:soul_sand)
B(7,23,7,minecraft:soul_sand)
B(7,0,8,minecraft:soul_sand)
B(7,1,8,minecraft:soul_sand)
B(7,2,8,minecraft:soul_sand)
B(7,3,8,minecraft:soul_sand)
B(7,4,8,minecraft:soul_sand)
B(7,5,8,minecraft:soul_sand)
B(7,6,8,minecraft:soul_sand)
B(7,7,8,minecraft:soul_sand)
B(7,8,8,minecraft:soul_sand)
B(7,9,8,minecraft:soul_sand)
B(7,10,8,minecraft:soul_sand)
B(7,11,8,minecraft:soul_sand)
B(7,12,8,minecraft:soul_sand)
B(7,13,8,minecraft:soul_sand)
B(7,14,8,minecraft:soul_sand)
B(7,15,8,minecraft:soul_sand)
B(7,16,8,minecraft:soul_sand)
B(7,17,8,minecraft:soul_sand)
B(7,18,8,minecraft:soul_sand)
B(7,19,8,minecraft:soul_sand)
B(7,20,8,minecraft:soul_sand)
B(7,21,8,minecraft:soul_sand)
B(7,22,8,minecraft:soul_sand)
B(7,23,8,minecraft:soul_sand)

#######################################################################
# +-----------------------------------------------------------------+ #
# |                             Branches                            | #
# +-----------------------------------------------------------------+ #
#######################################################################

Branch(16,0,0,true,SoulSandOozingMountain2_C2_R0,NORTH,100.0,0)

#######################################################################
# +-----------------------------------------------------------------+ #
# |                             Entities                            | #
# +-----------------------------------------------------------------+ #
#######################################################################

