Author: Frank

Description: Floating bit of obsidian - Modified by Bo3BulkEdit

Version: 3

SettingsMode: WriteDisable

IsOTGPlus: false
Tree: true
Frequency: 2
Rarity: 10.0
RotateRandomly: true
SpawnHeight: randomY
SpawnHeightOffset: 0
SpawnHeightVariance: 0
MaxBranchDepth: 10

ExtrudeMode: None
ExtrudeThroughBlocks: minecraft:air

MinHeight: 90
MaxHeight: 120

SourceBlocks: AIR
MaxPercentageOutsideSourceBlock: 0
OutsideSourceBlock: placeAnyway

DoReplaceBlocks: true

RB(-15,13,2,minecraft:obsidian,80,minecraft:crying_obsidian,20)
RB(-15,14,2,minecraft:obsidian,80,minecraft:crying_obsidian,20)
RB(-15,15,2,minecraft:obsidian,80,minecraft:crying_obsidian,20)
RB(-15,12,3,minecraft:obsidian,80,minecraft:crying_obsidian,20)
RB(-15,13,3,minecraft:obsidian,80,minecraft:crying_obsidian,20)
RB(-15,14,3,minecraft:obsidian,80,minecraft:crying_obsidian,20)
RB(-15,15,3,minecraft:obsidian,80,minecraft:crying_obsidian,20)
RB(-15,16,3,minecraft:obsidian,80,minecraft:crying_obsidian,20)
RB(-15,17,3,minecraft:obsidian,80,minecraft:crying_obsidian,20)
RB(-15,18,3,minecraft:obsidian,80,minecraft:crying_obsidian,20)
RB(-15,12,4,minecraft:obsidian,80,minecraft:crying_obsidian,20)
RB(-15,13,4,minecraft:obsidian,80,minecraft:crying_obsidian,20)
RB(-15,14,4,minecraft:obsidian,80,minecraft:crying_obsidian,20)
RB(-15,15,4,minecraft:obsidian,80,minecraft:crying_obsidian,20)
RB(-15,16,4,minecraft:obsidian,80,minecraft:crying_obsidian,20)
RB(-15,17,4,minecraft:obsidian,80,minecraft:crying_obsidian,20)
RB(-15,18,4,minecraft:obsidian,80,minecraft:crying_obsidian,20)
RB(-15,19,4,minecraft:obsidian,80,minecraft:crying_obsidian,20)
RB(-15,20,4,minecraft:obsidian,80,minecraft:crying_obsidian,20)
RB(-15,12,5,minecraft:obsidian,80,minecraft:crying_obsidian,20)
RB(-15,13,5,minecraft:obsidian,80,minecraft:crying_obsidian,20)
RB(-15,14,5,minecraft:obsidian,80,minecraft:crying_obsidian,20)
RB(-15,15,5,minecraft:obsidian,80,minecraft:crying_obsidian,20)
RB(-15,16,5,minecraft:obsidian,80,minecraft:crying_obsidian,20)
RB(-15,17,5,minecraft:obsidian,80,minecraft:crying_obsidian,20)
RB(-15,18,5,minecraft:obsidian,80,minecraft:crying_obsidian,20)
RB(-15,19,5,minecraft:obsidian,80,minecraft:crying_obsidian,20)
RB(-15,20,5,minecraft:obsidian,80,minecraft:crying_obsidian,20)
RB(-15,21,5,minecraft:obsidian,80,minecraft:crying_obsidian,20)
RB(-15,16,6,minecraft:obsidian,80,minecraft:crying_obsidian,20)
RB(-15,17,6,minecraft:obsidian,80,minecraft:crying_obsidian,20)
RB(-15,18,6,minecraft:obsidian,80,minecraft:crying_obsidian,20)
RB(-15,19,6,minecraft:obsidian,80,minecraft:crying_obsidian,20)
RB(-15,20,6,minecraft:obsidian,80,minecraft:crying_obsidian,20)
RB(-14,11,-4,minecraft:obsidian,80,minecraft:crying_obsidian,20)
RB(-14,12,-4,minecraft:obsidian,80,minecraft:crying_obsidian,20)
RB(-14,13,-4,minecraft:obsidian,80,minecraft:crying_obsidian,20)
RB(-14,10,-3,minecraft:obsidian,80,minecraft:crying_obsidian,20)
RB(-14,11,-3,minecraft:obsidian,80,minecraft:crying_obsidian,20)
RB(-14,12,-3,minecraft:obsidian,80,minecraft:crying_obsidian,20)
RB(-14,13,-3,minecraft:obsidian,80,minecraft:crying_obsidian,20)
RB(-14,14,-3,minecraft:obsidian,80,minecraft:crying_obsidian,20)
RB(-14,15,-3,minecraft:obsidian,80,minecraft:crying_obsidian,20)
RB(-14,10,-2,minecraft:obsidian,80,minecraft:crying_obsidian,20)
RB(-14,11,-2,minecraft:obsidian,80,minecraft:crying_obsidian,20)
RB(-14,12,-2,minecraft:obsidian,80,minecraft:crying_obsidian,20)
RB(-14,13,-2,minecraft:obsidian,80,minecraft:crying_obsidian,20)
RB(-14,14,-2,minecraft:obsidian,80,minecraft:crying_obsidian,20)
RB(-14,15,-2,minecraft:obsidian,80,minecraft:crying_obsidian,20)
RB(-14,10,-1,minecraft:obsidian,80,minecraft:crying_obsidian,20)
RB(-14,11,-1,minecraft:obsidian,80,minecraft:crying_obsidian,20)
RB(-14,12,-1,minecraft:obsidian,80,minecraft:crying_obsidian,20)
RB(-14,13,-1,minecraft:obsidian,80,minecraft:crying_obsidian,20)
RB(-14,14,-1,minecraft:obsidian,80,minecraft:crying_obsidian,20)
RB(-14,15,-1,minecraft:obsidian,80,minecraft:crying_obsidian,20)
RB(-14,11,0,minecraft:obsidian,80,minecraft:crying_obsidian,20)
RB(-14,12,0,minecraft:obsidian,80,minecraft:crying_obsidian,20)
RB(-14,13,0,minecraft:obsidian,80,minecraft:crying_obsidian,20)
RB(-14,14,0,minecraft:obsidian,80,minecraft:crying_obsidian,20)
RB(-14,12,1,minecraft:obsidian,80,minecraft:crying_obsidian,20)
RB(-14,13,1,minecraft:obsidian,80,minecraft:crying_obsidian,20)
RB(-14,14,1,minecraft:obsidian,80,minecraft:crying_obsidian,20)
RB(-14,15,1,minecraft:obsidian,80,minecraft:crying_obsidian,20)
RB(-14,16,1,minecraft:obsidian,80,minecraft:crying_obsidian,20)
RB(-14,17,1,minecraft:obsidian,80,minecraft:crying_obsidian,20)
RB(-14,11,2,minecraft:obsidian,80,minecraft:crying_obsidian,20)
RB(-14,12,2,minecraft:obsidian,80,minecraft:crying_obsidian,20)
RB(-14,13,2,minecraft:obsidian,80,minecraft:crying_obsidian,20)
RB(-14,14,2,minecraft:obsidian,80,minecraft:crying_obsidian,20)
RB(-14,15,2,minecraft:obsidian,80,minecraft:crying_obsidian,20)
RB(-14,16,2,minecraft:obsidian,80,minecraft:crying_obsidian,20)
RB(-14,17,2,minecraft:obsidian,80,minecraft:crying_obsidian,20)
RB(-14,11,3,minecraft:obsidian,80,minecraft:crying_obsidian,20)
RB(-14,12,3,minecraft:obsidian,80,minecraft:crying_obsidian,20)
RB(-14,13,3,minecraft:obsidian,80,minecraft:crying_obsidian,20)
RB(-14,14,3,minecraft:obsidian,80,minecraft:crying_obsidian,20)
RB(-14,15,3,minecraft:obsidian,80,minecraft:crying_obsidian,20)
RB(-14,16,3,minecraft:obsidian,80,minecraft:crying_obsidian,20)
RB(-14,17,3,minecraft:obsidian,80,minecraft:crying_obsidian,20)
RB(-14,18,3,minecraft:obsidian,80,minecraft:crying_obsidian,20)
RB(-14,11,4,minecraft:obsidian,80,minecraft:crying_obsidian,20)
RB(-14,12,4,minecraft:obsidian,80,minecraft:crying_obsidian,20)
RB(-14,13,4,minecraft:obsidian,80,minecraft:crying_obsidian,20)
RB(-14,14,4,minecraft:obsidian,80,minecraft:crying_obsidian,20)
RB(-14,15,4,minecraft:obsidian,80,minecraft:crying_obsidian,20)
RB(-14,16,4,minecraft:obsidian,80,minecraft:crying_obsidian,20)
RB(-14,17,4,minecraft:obsidian,80,minecraft:crying_obsidian,20)
RB(-14,18,4,minecraft:obsidian,80,minecraft:crying_obsidian,20)
RB(-14,19,4,minecraft:obsidian,80,minecraft:crying_obsidian,20)
RB(-14,20,4,minecraft:obsidian,80,minecraft:crying_obsidian,20)
RB(-14,21,4,minecraft:obsidian,80,minecraft:crying_obsidian,20)
RB(-14,11,5,minecraft:obsidian,80,minecraft:crying_obsidian,20)
RB(-14,12,5,minecraft:obsidian,80,minecraft:crying_obsidian,20)
RB(-14,13,5,minecraft:obsidian,80,minecraft:crying_obsidian,20)
RB(-14,14,5,minecraft:obsidian,80,minecraft:crying_obsidian,20)
RB(-14,15,5,minecraft:obsidian,80,minecraft:crying_obsidian,20)
RB(-14,16,5,minecraft:obsidian,80,minecraft:crying_obsidian,20)
RB(-14,17,5,minecraft:obsidian,80,minecraft:crying_obsidian,20)
RB(-14,18,5,minecraft:obsidian,80,minecraft:crying_obsidian,20)
RB(-14,19,5,minecraft:obsidian,80,minecraft:crying_obsidian,20)
RB(-14,20,5,minecraft:obsidian,80,minecraft:crying_obsidian,20)
RB(-14,21,5,minecraft:obsidian,80,minecraft:crying_obsidian,20)
RB(-14,11,6,minecraft:obsidian,80,minecraft:crying_obsidian,20)
RB(-14,12,6,minecraft:obsidian,80,minecraft:crying_obsidian,20)
RB(-14,13,6,minecraft:obsidian,80,minecraft:crying_obsidian,20)
RB(-14,14,6,minecraft:obsidian,80,minecraft:crying_obsidian,20)
RB(-14,15,6,minecraft:obsidian,80,minecraft:crying_obsidian,20)
RB(-14,16,6,minecraft:obsidian,80,minecraft:crying_obsidian,20)
RB(-14,17,6,minecraft:obsidian,80,minecraft:crying_obsidian,20)
RB(-14,18,6,minecraft:obsidian,80,minecraft:crying_obsidian,20)
RB(-14,19,6,minecraft:obsidian,80,minecraft:crying_obsidian,20)
RB(-14,20,6,minecraft:obsidian,80,minecraft:crying_obsidian,20)
RB(-14,21,6,minecraft:obsidian,80,minecraft:crying_obsidian,20)
RB(-14,22,6,minecraft:obsidian,80,minecraft:crying_obsidian,20)
RB(-14,14,7,minecraft:obsidian,80,minecraft:crying_obsidian,20)
RB(-14,15,7,minecraft:obsidian,80,minecraft:crying_obsidian,20)
RB(-14,16,7,minecraft:obsidian,80,minecraft:crying_obsidian,20)
RB(-14,17,7,minecraft:obsidian,80,minecraft:crying_obsidian,20)
RB(-14,18,7,minecraft:obsidian,80,minecraft:crying_obsidian,20)
RB(-14,19,7,minecraft:obsidian,80,minecraft:crying_obsidian,20)
RB(-14,20,7,minecraft:obsidian,80,minecraft:crying_obsidian,20)
RB(-14,21,7,minecraft:obsidian,80,minecraft:crying_obsidian,20)
RB(-14,14,9,minecraft:obsidian,80,minecraft:crying_obsidian,20)
RB(-14,15,9,minecraft:obsidian,80,minecraft:crying_obsidian,20)
RB(-14,16,9,minecraft:obsidian,80,minecraft:crying_obsidian,20)
RB(-14,17,9,minecraft:obsidian,80,minecraft:crying_obsidian,20)
RB(-14,18,9,minecraft:obsidian,80,minecraft:crying_obsidian,20)
RB(-14,19,9,minecraft:obsidian,80,minecraft:crying_obsidian,20)
RB(-14,12,10,minecraft:obsidian,80,minecraft:crying_obsidian,20)
RB(-14,13,10,minecraft:obsidian,80,minecraft:crying_obsidian,20)
RB(-14,14,10,minecraft:obsidian,80,minecraft:crying_obsidian,20)
RB(-14,15,10,minecraft:obsidian,80,minecraft:crying_obsidian,20)
RB(-14,16,10,minecraft:obsidian,80,minecraft:crying_obsidian,20)
RB(-14,17,10,minecraft:obsidian,80,minecraft:crying_obsidian,20)
RB(-14,12,11,minecraft:obsidian,80,minecraft:crying_obsidian,20)
RB(-14,13,11,minecraft:obsidian,80,minecraft:crying_obsidian,20)
RB(-14,14,11,minecraft:obsidian,80,minecraft:crying_obsidian,20)
RB(-14,15,11,minecraft:obsidian,80,minecraft:crying_obsidian,20)
RB(-14,16,11,minecraft:obsidian,80,minecraft:crying_obsidian,20)
RB(-14,12,12,minecraft:obsidian,80,minecraft:crying_obsidian,20)
RB(-14,13,12,minecraft:obsidian,80,minecraft:crying_obsidian,20)
RB(-14,14,12,minecraft:obsidian,80,minecraft:crying_obsidian,20)
RB(-14,15,12,minecraft:obsidian,80,minecraft:crying_obsidian,20)
RB(-14,16,12,minecraft:obsidian,80,minecraft:crying_obsidian,20)
RB(-14,13,13,minecraft:obsidian,80,minecraft:crying_obsidian,20)
RB(-14,14,13,minecraft:obsidian,80,minecraft:crying_obsidian,20)
RB(-14,15,13,minecraft:obsidian,80,minecraft:crying_obsidian,20)
RB(-13,10,-5,minecraft:obsidian,80,minecraft:crying_obsidian,20)
RB(-13,11,-5,minecraft:obsidian,80,minecraft:crying_obsidian,20)
RB(-13,12,-5,minecraft:obsidian,80,minecraft:crying_obsidian,20)
RB(-13,13,-5,minecraft:obsidian,80,minecraft:crying_obsidian,20)
RB(-13,14,-5,minecraft:obsidian,80,minecraft:crying_obsidian,20)
RB(-13,9,-4,minecraft:obsidian,80,minecraft:crying_obsidian,20)
RB(-13,10,-4,minecraft:obsidian,80,minecraft:crying_obsidian,20)
RB(-13,11,-4,minecraft:obsidian,80,minecraft:crying_obsidian,20)
RB(-13,12,-4,minecraft:obsidian,80,minecraft:crying_obsidian,20)
RB(-13,13,-4,minecraft:obsidian,80,minecraft:crying_obsidian,20)
RB(-13,14,-4,minecraft:obsidian,80,minecraft:crying_obsidian,20)
RB(-13,15,-4,minecraft:obsidian,80,minecraft:crying_obsidian,20)
RB(-13,16,-4,minecraft:obsidian,80,minecraft:crying_obsidian,20)
RB(-13,9,-3,minecraft:obsidian,80,minecraft:crying_obsidian,20)
RB(-13,10,-3,minecraft:obsidian,80,minecraft:crying_obsidian,20)
RB(-13,11,-3,minecraft:obsidian,80,minecraft:crying_obsidian,20)
RB(-13,12,-3,minecraft:obsidian,80,minecraft:crying_obsidian,20)
RB(-13,13,-3,minecraft:obsidian,80,minecraft:crying_obsidian,20)
RB(-13,14,-3,minecraft:obsidian,80,minecraft:crying_obsidian,20)
RB(-13,15,-3,minecraft:obsidian,80,minecraft:crying_obsidian,20)
RB(-13,16,-3,minecraft:obsidian,80,minecraft:crying_obsidian,20)
RB(-13,9,-2,minecraft:obsidian,80,minecraft:crying_obsidian,20)
RB(-13,10,-2,minecraft:obsidian,80,minecraft:crying_obsidian,20)
RB(-13,11,-2,minecraft:obsidian,80,minecraft:crying_obsidian,20)
RB(-13,12,-2,minecraft:obsidian,80,minecraft:crying_obsidian,20)
RB(-13,13,-2,minecraft:obsidian,80,minecraft:crying_obsidian,20)
RB(-13,14,-2,minecraft:obsidian,80,minecraft:crying_obsidian,20)
RB(-13,15,-2,minecraft:obsidian,80,minecraft:crying_obsidian,20)
RB(-13,16,-2,minecraft:obsidian,80,minecraft:crying_obsidian,20)
RB(-13,9,-1,minecraft:obsidian,80,minecraft:crying_obsidian,20)
RB(-13,10,-1,minecraft:obsidian,80,minecraft:crying_obsidian,20)
RB(-13,11,-1,minecraft:obsidian,80,minecraft:crying_obsidian,20)
RB(-13,12,-1,minecraft:obsidian,80,minecraft:crying_obsidian,20)
RB(-13,13,-1,minecraft:obsidian,80,minecraft:crying_obsidian,20)
RB(-13,14,-1,minecraft:obsidian,80,minecraft:crying_obsidian,20)
RB(-13,15,-1,minecraft:obsidian,80,minecraft:crying_obsidian,20)
RB(-13,16,-1,minecraft:obsidian,80,minecraft:crying_obsidian,20)
RB(-13,9,0,minecraft:obsidian,80,minecraft:crying_obsidian,20)
RB(-13,10,0,minecraft:obsidian,80,minecraft:crying_obsidian,20)
RB(-13,11,0,minecraft:obsidian,80,minecraft:crying_obsidian,20)
RB(-13,12,0,minecraft:obsidian,80,minecraft:crying_obsidian,20)
RB(-13,13,0,minecraft:obsidian,80,minecraft:crying_obsidian,20)
RB(-13,14,0,minecraft:obsidian,80,minecraft:crying_obsidian,20)
RB(-13,15,0,minecraft:obsidian,80,minecraft:crying_obsidian,20)
RB(-13,16,0,minecraft:obsidian,80,minecraft:crying_obsidian,20)
RB(-13,17,0,minecraft:obsidian,80,minecraft:crying_obsidian,20)
RB(-13,10,1,minecraft:obsidian,80,minecraft:crying_obsidian,20)
RB(-13,11,1,minecraft:obsidian,80,minecraft:crying_obsidian,20)
RB(-13,12,1,minecraft:obsidian,80,minecraft:crying_obsidian,20)
RB(-13,13,1,minecraft:obsidian,80,minecraft:crying_obsidian,20)
RB(-13,14,1,minecraft:obsidian,80,minecraft:crying_obsidian,20)
RB(-13,15,1,minecraft:obsidian,80,minecraft:crying_obsidian,20)
RB(-13,16,1,minecraft:obsidian,80,minecraft:crying_obsidian,20)
RB(-13,17,1,minecraft:obsidian,80,minecraft:crying_obsidian,20)
RB(-13,18,1,minecraft:obsidian,80,minecraft:crying_obsidian,20)
RB(-13,10,2,minecraft:obsidian,80,minecraft:crying_obsidian,20)
RB(-13,11,2,minecraft:obsidian,80,minecraft:crying_obsidian,20)
RB(-13,12,2,minecraft:obsidian,80,minecraft:crying_obsidian,20)
RB(-13,13,2,minecraft:obsidian,80,minecraft:crying_obsidian,20)
RB(-13,14,2,minecraft:obsidian,80,minecraft:crying_obsidian,20)
RB(-13,15,2,minecraft:obsidian,80,minecraft:crying_obsidian,20)
RB(-13,16,2,minecraft:obsidian,80,minecraft:crying_obsidian,20)
RB(-13,17,2,minecraft:obsidian,80,minecraft:crying_obsidian,20)
RB(-13,18,2,minecraft:obsidian,80,minecraft:crying_obsidian,20)
RB(-13,10,3,minecraft:obsidian,80,minecraft:crying_obsidian,20)
RB(-13,11,3,minecraft:obsidian,80,minecraft:crying_obsidian,20)
RB(-13,12,3,minecraft:obsidian,80,minecraft:crying_obsidian,20)
RB(-13,13,3,minecraft:obsidian,80,minecraft:crying_obsidian,20)
RB(-13,14,3,minecraft:obsidian,80,minecraft:crying_obsidian,20)
RB(-13,15,3,minecraft:obsidian,80,minecraft:crying_obsidian,20)
RB(-13,16,3,minecraft:obsidian,80,minecraft:crying_obsidian,20)
RB(-13,17,3,minecraft:obsidian,80,minecraft:crying_obsidian,20)
RB(-13,18,3,minecraft:obsidian,80,minecraft:crying_obsidian,20)
RB(-13,19,3,minecraft:obsidian,80,minecraft:crying_obsidian,20)
RB(-13,20,3,minecraft:obsidian,80,minecraft:crying_obsidian,20)
RB(-13,10,4,minecraft:obsidian,80,minecraft:crying_obsidian,20)
RB(-13,11,4,minecraft:obsidian,80,minecraft:crying_obsidian,20)
RB(-13,12,4,minecraft:obsidian,80,minecraft:crying_obsidian,20)
RB(-13,13,4,minecraft:obsidian,80,minecraft:crying_obsidian,20)
RB(-13,14,4,minecraft:obsidian,80,minecraft:crying_obsidian,20)
RB(-13,15,4,minecraft:obsidian,80,minecraft:crying_obsidian,20)
RB(-13,16,4,minecraft:obsidian,80,minecraft:crying_obsidian,20)
RB(-13,17,4,minecraft:obsidian,80,minecraft:crying_obsidian,20)
RB(-13,18,4,minecraft:obsidian,80,minecraft:crying_obsidian,20)
RB(-13,19,4,minecraft:obsidian,80,minecraft:crying_obsidian,20)
RB(-13,20,4,minecraft:obsidian,80,minecraft:crying_obsidian,20)
RB(-13,21,4,minecraft:obsidian,80,minecraft:crying_obsidian,20)
RB(-13,10,5,minecraft:obsidian,80,minecraft:crying_obsidian,20)
RB(-13,11,5,minecraft:obsidian,80,minecraft:crying_obsidian,20)
RB(-13,12,5,minecraft:obsidian,80,minecraft:crying_obsidian,20)
RB(-13,13,5,minecraft:obsidian,80,minecraft:crying_obsidian,20)
RB(-13,14,5,minecraft:obsidian,80,minecraft:crying_obsidian,20)
RB(-13,15,5,minecraft:obsidian,80,minecraft:crying_obsidian,20)
RB(-13,16,5,minecraft:obsidian,80,minecraft:crying_obsidian,20)
RB(-13,17,5,minecraft:obsidian,80,minecraft:crying_obsidian,20)
RB(-13,18,5,minecraft:obsidian,80,minecraft:crying_obsidian,20)
RB(-13,19,5,minecraft:obsidian,80,minecraft:crying_obsidian,20)
RB(-13,20,5,minecraft:obsidian,80,minecraft:crying_obsidian,20)
RB(-13,21,5,minecraft:obsidian,80,minecraft:crying_obsidian,20)
RB(-13,10,6,minecraft:obsidian,80,minecraft:crying_obsidian,20)
RB(-13,11,6,minecraft:obsidian,80,minecraft:crying_obsidian,20)
RB(-13,12,6,minecraft:obsidian,80,minecraft:crying_obsidian,20)
RB(-13,13,6,minecraft:obsidian,80,minecraft:crying_obsidian,20)
RB(-13,14,6,minecraft:obsidian,80,minecraft:crying_obsidian,20)
RB(-13,15,6,minecraft:obsidian,80,minecraft:crying_obsidian,20)
RB(-13,16,6,minecraft:obsidian,80,minecraft:crying_obsidian,20)
RB(-13,17,6,minecraft:obsidian,80,minecraft:crying_obsidian,20)
RB(-13,18,6,minecraft:obsidian,80,minecraft:crying_obsidian,20)
RB(-13,19,6,minecraft:obsidian,80,minecraft:crying_obsidian,20)
RB(-13,20,6,minecraft:obsidian,80,minecraft:crying_obsidian,20)
RB(-13,21,6,minecraft:obsidian,80,minecraft:crying_obsidian,20)
RB(-13,11,7,minecraft:obsidian,80,minecraft:crying_obsidian,20)
RB(-13,12,7,minecraft:obsidian,80,minecraft:crying_obsidian,20)
RB(-13,13,7,minecraft:obsidian,80,minecraft:crying_obsidian,20)
RB(-13,14,7,minecraft:obsidian,80,minecraft:crying_obsidian,20)
RB(-13,15,7,minecraft:obsidian,80,minecraft:crying_obsidian,20)
RB(-13,16,7,minecraft:obsidian,80,minecraft:crying_obsidian,20)
RB(-13,17,7,minecraft:obsidian,80,minecraft:crying_obsidian,20)
RB(-13,18,7,minecraft:obsidian,80,minecraft:crying_obsidian,20)
RB(-13,19,7,minecraft:obsidian,80,minecraft:crying_obsidian,20)
RB(-13,20,7,minecraft:obsidian,80,minecraft:crying_obsidian,20)
RB(-13,21,7,minecraft:obsidian,80,minecraft:crying_obsidian,20)
RB(-13,13,8,minecraft:obsidian,80,minecraft:crying_obsidian,20)
RB(-13,14,8,minecraft:obsidian,80,minecraft:crying_obsidian,20)
RB(-13,15,8,minecraft:obsidian,80,minecraft:crying_obsidian,20)
RB(-13,16,8,minecraft:obsidian,80,minecraft:crying_obsidian,20)
RB(-13,17,8,minecraft:obsidian,80,minecraft:crying_obsidian,20)
RB(-13,18,8,minecraft:obsidian,80,minecraft:crying_obsidian,20)
RB(-13,19,8,minecraft:obsidian,80,minecraft:crying_obsidian,20)
RB(-13,20,8,minecraft:obsidian,80,minecraft:crying_obsidian,20)
RB(-13,11,9,minecraft:obsidian,80,minecraft:crying_obsidian,20)
RB(-13,12,9,minecraft:obsidian,80,minecraft:crying_obsidian,20)
RB(-13,13,9,minecraft:obsidian,80,minecraft:crying_obsidian,20)
RB(-13,14,9,minecraft:obsidian,80,minecraft:crying_obsidian,20)
RB(-13,15,9,minecraft:obsidian,80,minecraft:crying_obsidian,20)
RB(-13,16,9,minecraft:obsidian,80,minecraft:crying_obsidian,20)
RB(-13,17,9,minecraft:obsidian,80,minecraft:crying_obsidian,20)
RB(-13,18,9,minecraft:obsidian,80,minecraft:crying_obsidian,20)
RB(-13,19,9,minecraft:obsidian,80,minecraft:crying_obsidian,20)
RB(-13,11,10,minecraft:obsidian,80,minecraft:crying_obsidian,20)
RB(-13,12,10,minecraft:obsidian,80,minecraft:crying_obsidian,20)
RB(-13,13,10,minecraft:obsidian,80,minecraft:crying_obsidian,20)
RB(-13,14,10,minecraft:obsidian,80,minecraft:crying_obsidian,20)
RB(-13,15,10,minecraft:obsidian,80,minecraft:crying_obsidian,20)
RB(-13,16,10,minecraft:obsidian,80,minecraft:crying_obsidian,20)
RB(-13,17,10,minecraft:obsidian,80,minecraft:crying_obsidian,20)
RB(-13,18,10,minecraft:obsidian,80,minecraft:crying_obsidian,20)
RB(-13,11,11,minecraft:obsidian,80,minecraft:crying_obsidian,20)
RB(-13,12,11,minecraft:obsidian,80,minecraft:crying_obsidian,20)
RB(-13,13,11,minecraft:obsidian,80,minecraft:crying_obsidian,20)
RB(-13,14,11,minecraft:obsidian,80,minecraft:crying_obsidian,20)
RB(-13,15,11,minecraft:obsidian,80,minecraft:crying_obsidian,20)
RB(-13,16,11,minecraft:obsidian,80,minecraft:crying_obsidian,20)
RB(-13,17,11,minecraft:obsidian,80,minecraft:crying_obsidian,20)
RB(-13,11,12,minecraft:obsidian,80,minecraft:crying_obsidian,20)
RB(-13,12,12,minecraft:obsidian,80,minecraft:crying_obsidian,20)
RB(-13,13,12,minecraft:obsidian,80,minecraft:crying_obsidian,20)
RB(-13,14,12,minecraft:obsidian,80,minecraft:crying_obsidian,20)
RB(-13,15,12,minecraft:obsidian,80,minecraft:crying_obsidian,20)
RB(-13,16,12,minecraft:obsidian,80,minecraft:crying_obsidian,20)
RB(-13,17,12,minecraft:obsidian,80,minecraft:crying_obsidian,20)
RB(-13,11,13,minecraft:obsidian,80,minecraft:crying_obsidian,20)
RB(-13,12,13,minecraft:obsidian,80,minecraft:crying_obsidian,20)
RB(-13,13,13,minecraft:obsidian,80,minecraft:crying_obsidian,20)
RB(-13,14,13,minecraft:obsidian,80,minecraft:crying_obsidian,20)
RB(-13,15,13,minecraft:obsidian,80,minecraft:crying_obsidian,20)
RB(-13,16,13,minecraft:obsidian,80,minecraft:crying_obsidian,20)
RB(-13,17,13,minecraft:obsidian,80,minecraft:crying_obsidian,20)
RB(-13,12,14,minecraft:obsidian,80,minecraft:crying_obsidian,20)
RB(-13,13,14,minecraft:obsidian,80,minecraft:crying_obsidian,20)
RB(-13,14,14,minecraft:obsidian,80,minecraft:crying_obsidian,20)
RB(-13,15,14,minecraft:obsidian,80,minecraft:crying_obsidian,20)
RB(-13,16,14,minecraft:obsidian,80,minecraft:crying_obsidian,20)
RB(-12,10,-6,minecraft:obsidian,80,minecraft:crying_obsidian,20)
RB(-12,11,-6,minecraft:obsidian,80,minecraft:crying_obsidian,20)
RB(-12,12,-6,minecraft:obsidian,80,minecraft:crying_obsidian,20)
RB(-12,13,-6,minecraft:obsidian,80,minecraft:crying_obsidian,20)
RB(-12,14,-6,minecraft:obsidian,80,minecraft:crying_obsidian,20)
RB(-12,9,-5,minecraft:obsidian,80,minecraft:crying_obsidian,20)
RB(-12,10,-5,minecraft:obsidian,80,minecraft:crying_obsidian,20)
RB(-12,11,-5,minecraft:obsidian,80,minecraft:crying_obsidian,20)
RB(-12,12,-5,minecraft:obsidian,80,minecraft:crying_obsidian,20)
RB(-12,13,-5,minecraft:obsidian,80,minecraft:crying_obsidian,20)
RB(-12,14,-5,minecraft:obsidian,80,minecraft:crying_obsidian,20)
RB(-12,15,-5,minecraft:obsidian,80,minecraft:crying_obsidian,20)
RB(-12,8,-4,minecraft:obsidian,80,minecraft:crying_obsidian,20)
RB(-12,9,-4,minecraft:obsidian,80,minecraft:crying_obsidian,20)
RB(-12,10,-4,minecraft:obsidian,80,minecraft:crying_obsidian,20)
RB(-12,11,-4,minecraft:obsidian,80,minecraft:crying_obsidian,20)
RB(-12,12,-4,minecraft:obsidian,80,minecraft:crying_obsidian,20)
RB(-12,13,-4,minecraft:obsidian,80,minecraft:crying_obsidian,20)
RB(-12,14,-4,minecraft:obsidian,80,minecraft:crying_obsidian,20)
RB(-12,15,-4,minecraft:obsidian,80,minecraft:crying_obsidian,20)
RB(-12,16,-4,minecraft:obsidian,80,minecraft:crying_obsidian,20)
RB(-12,17,-4,minecraft:obsidian,80,minecraft:crying_obsidian,20)
RB(-12,8,-3,minecraft:obsidian,80,minecraft:crying_obsidian,20)
RB(-12,9,-3,minecraft:obsidian,80,minecraft:crying_obsidian,20)
RB(-12,10,-3,minecraft:obsidian,80,minecraft:crying_obsidian,20)
RB(-12,11,-3,minecraft:obsidian,80,minecraft:crying_obsidian,20)
RB(-12,12,-3,minecraft:obsidian,80,minecraft:crying_obsidian,20)
RB(-12,13,-3,minecraft:obsidian,80,minecraft:crying_obsidian,20)
RB(-12,14,-3,minecraft:obsidian,80,minecraft:crying_obsidian,20)
RB(-12,15,-3,minecraft:obsidian,80,minecraft:crying_obsidian,20)
RB(-12,16,-3,minecraft:obsidian,80,minecraft:crying_obsidian,20)
RB(-12,17,-3,minecraft:obsidian,80,minecraft:crying_obsidian,20)
RB(-12,8,-2,minecraft:obsidian,80,minecraft:crying_obsidian,20)
RB(-12,9,-2,minecraft:obsidian,80,minecraft:crying_obsidian,20)
RB(-12,10,-2,minecraft:obsidian,80,minecraft:crying_obsidian,20)
RB(-12,11,-2,minecraft:obsidian,80,minecraft:crying_obsidian,20)
RB(-12,12,-2,minecraft:obsidian,80,minecraft:crying_obsidian,20)
RB(-12,13,-2,minecraft:obsidian,80,minecraft:crying_obsidian,20)
RB(-12,14,-2,minecraft:obsidian,80,minecraft:crying_obsidian,20)
RB(-12,15,-2,minecraft:obsidian,80,minecraft:crying_obsidian,20)
RB(-12,16,-2,minecraft:obsidian,80,minecraft:crying_obsidian,20)
RB(-12,17,-2,minecraft:obsidian,80,minecraft:crying_obsidian,20)
RB(-12,8,-1,minecraft:obsidian,80,minecraft:crying_obsidian,20)
RB(-12,9,-1,minecraft:obsidian,80,minecraft:crying_obsidian,20)
RB(-12,10,-1,minecraft:obsidian,80,minecraft:crying_obsidian,20)
RB(-12,11,-1,minecraft:obsidian,80,minecraft:crying_obsidian,20)
RB(-12,12,-1,minecraft:obsidian,80,minecraft:crying_obsidian,20)
RB(-12,13,-1,minecraft:obsidian,80,minecraft:crying_obsidian,20)
RB(-12,14,-1,minecraft:obsidian,80,minecraft:crying_obsidian,20)
RB(-12,15,-1,minecraft:obsidian,80,minecraft:crying_obsidian,20)
RB(-12,16,-1,minecraft:obsidian,80,minecraft:crying_obsidian,20)
RB(-12,17,-1,minecraft:obsidian,80,minecraft:crying_obsidian,20)
RB(-12,8,0,minecraft:obsidian,80,minecraft:crying_obsidian,20)
RB(-12,9,0,minecraft:obsidian,80,minecraft:crying_obsidian,20)
RB(-12,10,0,minecraft:obsidian,80,minecraft:crying_obsidian,20)
RB(-12,11,0,minecraft:obsidian,80,minecraft:crying_obsidian,20)
RB(-12,12,0,minecraft:obsidian,80,minecraft:crying_obsidian,20)
RB(-12,13,0,minecraft:obsidian,80,minecraft:crying_obsidian,20)
RB(-12,14,0,minecraft:obsidian,80,minecraft:crying_obsidian,20)
RB(-12,15,0,minecraft:obsidian,80,minecraft:crying_obsidian,20)
RB(-12,16,0,minecraft:obsidian,80,minecraft:crying_obsidian,20)
RB(-12,17,0,minecraft:obsidian,80,minecraft:crying_obsidian,20)
RB(-12,18,0,minecraft:obsidian,80,minecraft:crying_obsidian,20)
RB(-12,9,1,minecraft:obsidian,80,minecraft:crying_obsidian,20)
RB(-12,10,1,minecraft:obsidian,80,minecraft:crying_obsidian,20)
RB(-12,11,1,minecraft:obsidian,80,minecraft:crying_obsidian,20)
RB(-12,12,1,minecraft:obsidian,80,minecraft:crying_obsidian,20)
RB(-12,13,1,minecraft:obsidian,80,minecraft:crying_obsidian,20)
RB(-12,14,1,minecraft:obsidian,80,minecraft:crying_obsidian,20)
RB(-12,15,1,minecraft:obsidian,80,minecraft:crying_obsidian,20)
RB(-12,16,1,minecraft:obsidian,80,minecraft:crying_obsidian,20)
RB(-12,17,1,minecraft:obsidian,80,minecraft:crying_obsidian,20)
RB(-12,18,1,minecraft:obsidian,80,minecraft:crying_obsidian,20)
RB(-12,10,2,minecraft:obsidian,80,minecraft:crying_obsidian,20)
RB(-12,11,2,minecraft:obsidian,80,minecraft:crying_obsidian,20)
RB(-12,12,2,minecraft:obsidian,80,minecraft:crying_obsidian,20)
RB(-12,13,2,minecraft:obsidian,80,minecraft:crying_obsidian,20)
RB(-12,14,2,minecraft:obsidian,80,minecraft:crying_obsidian,20)
RB(-12,15,2,minecraft:obsidian,80,minecraft:crying_obsidian,20)
RB(-12,16,2,minecraft:obsidian,80,minecraft:crying_obsidian,20)
RB(-12,17,2,minecraft:obsidian,80,minecraft:crying_obsidian,20)
RB(-12,18,2,minecraft:obsidian,80,minecraft:crying_obsidian,20)
RB(-12,9,3,minecraft:obsidian,80,minecraft:crying_obsidian,20)
RB(-12,10,3,minecraft:obsidian,80,minecraft:crying_obsidian,20)
RB(-12,11,3,minecraft:obsidian,80,minecraft:crying_obsidian,20)
RB(-12,12,3,minecraft:obsidian,80,minecraft:crying_obsidian,20)
RB(-12,13,3,minecraft:obsidian,80,minecraft:crying_obsidian,20)
RB(-12,14,3,minecraft:obsidian,80,minecraft:crying_obsidian,20)
RB(-12,15,3,minecraft:obsidian,80,minecraft:crying_obsidian,20)
RB(-12,16,3,minecraft:obsidian,80,minecraft:crying_obsidian,20)
RB(-12,17,3,minecraft:obsidian,80,minecraft:crying_obsidian,20)
RB(-12,18,3,minecraft:obsidian,80,minecraft:crying_obsidian,20)
RB(-12,19,3,minecraft:obsidian,80,minecraft:crying_obsidian,20)
RB(-12,9,4,minecraft:obsidian,80,minecraft:crying_obsidian,20)
RB(-12,10,4,minecraft:obsidian,80,minecraft:crying_obsidian,20)
RB(-12,11,4,minecraft:obsidian,80,minecraft:crying_obsidian,20)
RB(-12,12,4,minecraft:obsidian,80,minecraft:crying_obsidian,20)
RB(-12,13,4,minecraft:obsidian,80,minecraft:crying_obsidian,20)
RB(-12,14,4,minecraft:obsidian,80,minecraft:crying_obsidian,20)
RB(-12,15,4,minecraft:obsidian,80,minecraft:crying_obsidian,20)
RB(-12,16,4,minecraft:obsidian,80,minecraft:crying_obsidian,20)
RB(-12,17,4,minecraft:obsidian,80,minecraft:crying_obsidian,20)
RB(-12,18,4,minecraft:obsidian,80,minecraft:crying_obsidian,20)
RB(-12,19,4,minecraft:obsidian,80,minecraft:crying_obsidian,20)
RB(-12,20,4,minecraft:obsidian,80,minecraft:crying_obsidian,20)
RB(-12,21,4,minecraft:obsidian,80,minecraft:crying_obsidian,20)
RB(-12,9,5,minecraft:obsidian,80,minecraft:crying_obsidian,20)
RB(-12,10,5,minecraft:obsidian,80,minecraft:crying_obsidian,20)
RB(-12,11,5,minecraft:obsidian,80,minecraft:crying_obsidian,20)
RB(-12,12,5,minecraft:obsidian,80,minecraft:crying_obsidian,20)
RB(-12,13,5,minecraft:obsidian,80,minecraft:crying_obsidian,20)
RB(-12,14,5,minecraft:obsidian,80,minecraft:crying_obsidian,20)
RB(-12,15,5,minecraft:obsidian,80,minecraft:crying_obsidian,20)
RB(-12,16,5,minecraft:obsidian,80,minecraft:crying_obsidian,20)
RB(-12,17,5,minecraft:obsidian,80,minecraft:crying_obsidian,20)
RB(-12,18,5,minecraft:obsidian,80,minecraft:crying_obsidian,20)
RB(-12,19,5,minecraft:obsidian,80,minecraft:crying_obsidian,20)
RB(-12,20,5,minecraft:obsidian,80,minecraft:crying_obsidian,20)
RB(-12,21,5,minecraft:obsidian,80,minecraft:crying_obsidian,20)
RB(-12,10,6,minecraft:obsidian,80,minecraft:crying_obsidian,20)
RB(-12,11,6,minecraft:obsidian,80,minecraft:crying_obsidian,20)
RB(-12,12,6,minecraft:obsidian,80,minecraft:crying_obsidian,20)
RB(-12,13,6,minecraft:obsidian,80,minecraft:crying_obsidian,20)
RB(-12,14,6,minecraft:obsidian,80,minecraft:crying_obsidian,20)
RB(-12,15,6,minecraft:obsidian,80,minecraft:crying_obsidian,20)
RB(-12,16,6,minecraft:obsidian,80,minecraft:crying_obsidian,20)
RB(-12,17,6,minecraft:obsidian,80,minecraft:crying_obsidian,20)
RB(-12,18,6,minecraft:obsidian,80,minecraft:crying_obsidian,20)
RB(-12,19,6,minecraft:obsidian,80,minecraft:crying_obsidian,20)
RB(-12,20,6,minecraft:obsidian,80,minecraft:crying_obsidian,20)
RB(-12,21,6,minecraft:obsidian,80,minecraft:crying_obsidian,20)
RB(-12,10,7,minecraft:obsidian,80,minecraft:crying_obsidian,20)
RB(-12,11,7,minecraft:obsidian,80,minecraft:crying_obsidian,20)
RB(-12,12,7,minecraft:obsidian,80,minecraft:crying_obsidian,20)
RB(-12,13,7,minecraft:obsidian,80,minecraft:crying_obsidian,20)
RB(-12,14,7,minecraft:obsidian,80,minecraft:crying_obsidian,20)
RB(-12,15,7,minecraft:obsidian,80,minecraft:crying_obsidian,20)
RB(-12,16,7,minecraft:obsidian,80,minecraft:crying_obsidian,20)
RB(-12,17,7,minecraft:obsidian,80,minecraft:crying_obsidian,20)
RB(-12,18,7,minecraft:obsidian,80,minecraft:crying_obsidian,20)
RB(-12,19,7,minecraft:obsidian,80,minecraft:crying_obsidian,20)
RB(-12,20,7,minecraft:obsidian,80,minecraft:crying_obsidian,20)
RB(-12,11,8,minecraft:obsidian,80,minecraft:crying_obsidian,20)
RB(-12,12,8,minecraft:obsidian,80,minecraft:crying_obsidian,20)
RB(-12,13,8,minecraft:obsidian,80,minecraft:crying_obsidian,20)
RB(-12,14,8,minecraft:obsidian,80,minecraft:crying_obsidian,20)
RB(-12,15,8,minecraft:obsidian,80,minecraft:crying_obsidian,20)
RB(-12,16,8,minecraft:obsidian,80,minecraft:crying_obsidian,20)
RB(-12,17,8,minecraft:obsidian,80,minecraft:crying_obsidian,20)
RB(-12,18,8,minecraft:obsidian,80,minecraft:crying_obsidian,20)
RB(-12,19,8,minecraft:obsidian,80,minecraft:crying_obsidian,20)
RB(-12,10,9,minecraft:obsidian,80,minecraft:crying_obsidian,20)
RB(-12,11,9,minecraft:obsidian,80,minecraft:crying_obsidian,20)
RB(-12,12,9,minecraft:obsidian,80,minecraft:crying_obsidian,20)
RB(-12,13,9,minecraft:obsidian,80,minecraft:crying_obsidian,20)
RB(-12,14,9,minecraft:obsidian,80,minecraft:crying_obsidian,20)
RB(-12,15,9,minecraft:obsidian,80,minecraft:crying_obsidian,20)
RB(-12,16,9,minecraft:obsidian,80,minecraft:crying_obsidian,20)
RB(-12,17,9,minecraft:obsidian,80,minecraft:crying_obsidian,20)
RB(-12,18,9,minecraft:obsidian,80,minecraft:crying_obsidian,20)
RB(-12,19,9,minecraft:obsidian,80,minecraft:crying_obsidian,20)
RB(-12,10,10,minecraft:obsidian,80,minecraft:crying_obsidian,20)
RB(-12,11,10,minecraft:obsidian,80,minecraft:crying_obsidian,20)
RB(-12,12,10,minecraft:obsidian,80,minecraft:crying_obsidian,20)
RB(-12,13,10,minecraft:obsidian,80,minecraft:crying_obsidian,20)
RB(-12,14,10,minecraft:obsidian,80,minecraft:crying_obsidian,20)
RB(-12,15,10,minecraft:obsidian,80,minecraft:crying_obsidian,20)
RB(-12,16,10,minecraft:obsidian,80,minecraft:crying_obsidian,20)
RB(-12,17,10,minecraft:obsidian,80,minecraft:crying_obsidian,20)
RB(-12,18,10,minecraft:obsidian,80,minecraft:crying_obsidian,20)
RB(-12,10,11,minecraft:obsidian,80,minecraft:crying_obsidian,20)
RB(-12,11,11,minecraft:obsidian,80,minecraft:crying_obsidian,20)
RB(-12,12,11,minecraft:obsidian,80,minecraft:crying_obsidian,20)
RB(-12,13,11,minecraft:obsidian,80,minecraft:crying_obsidian,20)
RB(-12,14,11,minecraft:obsidian,80,minecraft:crying_obsidian,20)
RB(-12,15,11,minecraft:obsidian,80,minecraft:crying_obsidian,20)
RB(-12,16,11,minecraft:obsidian,80,minecraft:crying_obsidian,20)
RB(-12,17,11,minecraft:obsidian,80,minecraft:crying_obsidian,20)
RB(-12,18,11,minecraft:obsidian,80,minecraft:crying_obsidian,20)
RB(-12,10,12,minecraft:obsidian,80,minecraft:crying_obsidian,20)
RB(-12,11,12,minecraft:obsidian,80,minecraft:crying_obsidian,20)
RB(-12,12,12,minecraft:obsidian,80,minecraft:crying_obsidian,20)
RB(-12,13,12,minecraft:obsidian,80,minecraft:crying_obsidian,20)
RB(-12,14,12,minecraft:obsidian,80,minecraft:crying_obsidian,20)
RB(-12,15,12,minecraft:obsidian,80,minecraft:crying_obsidian,20)
RB(-12,16,12,minecraft:obsidian,80,minecraft:crying_obsidian,20)
RB(-12,17,12,minecraft:obsidian,80,minecraft:crying_obsidian,20)
RB(-12,18,12,minecraft:obsidian,80,minecraft:crying_obsidian,20)
RB(-12,10,13,minecraft:obsidian,80,minecraft:crying_obsidian,20)
RB(-12,11,13,minecraft:obsidian,80,minecraft:crying_obsidian,20)
RB(-12,12,13,minecraft:obsidian,80,minecraft:crying_obsidian,20)
RB(-12,13,13,minecraft:obsidian,80,minecraft:crying_obsidian,20)
RB(-12,14,13,minecraft:obsidian,80,minecraft:crying_obsidian,20)
RB(-12,15,13,minecraft:obsidian,80,minecraft:crying_obsidian,20)
RB(-12,16,13,minecraft:obsidian,80,minecraft:crying_obsidian,20)
RB(-12,17,13,minecraft:obsidian,80,minecraft:crying_obsidian,20)
RB(-12,18,13,minecraft:obsidian,80,minecraft:crying_obsidian,20)
RB(-12,19,13,minecraft:obsidian,80,minecraft:crying_obsidian,20)
RB(-12,20,13,minecraft:obsidian,80,minecraft:crying_obsidian,20)
RB(-12,11,14,minecraft:obsidian,80,minecraft:crying_obsidian,20)
RB(-12,12,14,minecraft:obsidian,80,minecraft:crying_obsidian,20)
RB(-12,13,14,minecraft:obsidian,80,minecraft:crying_obsidian,20)
RB(-12,14,14,minecraft:obsidian,80,minecraft:crying_obsidian,20)
RB(-12,15,14,minecraft:obsidian,80,minecraft:crying_obsidian,20)
RB(-12,16,14,minecraft:obsidian,80,minecraft:crying_obsidian,20)
RB(-12,17,14,minecraft:obsidian,80,minecraft:crying_obsidian,20)
RB(-12,18,14,minecraft:obsidian,80,minecraft:crying_obsidian,20)
RB(-12,19,14,minecraft:obsidian,80,minecraft:crying_obsidian,20)
RB(-12,12,15,minecraft:obsidian,80,minecraft:crying_obsidian,20)
RB(-12,13,15,minecraft:obsidian,80,minecraft:crying_obsidian,20)
RB(-12,14,15,minecraft:obsidian,80,minecraft:crying_obsidian,20)
RB(-12,15,15,minecraft:obsidian,80,minecraft:crying_obsidian,20)
RB(-12,16,15,minecraft:obsidian,80,minecraft:crying_obsidian,20)
RB(-12,17,15,minecraft:obsidian,80,minecraft:crying_obsidian,20)
RB(-12,18,15,minecraft:obsidian,80,minecraft:crying_obsidian,20)
RB(-12,19,15,minecraft:obsidian,80,minecraft:crying_obsidian,20)
RB(-11,10,-12,minecraft:obsidian,80,minecraft:crying_obsidian,20)
RB(-11,11,-12,minecraft:obsidian,80,minecraft:crying_obsidian,20)
RB(-11,12,-12,minecraft:obsidian,80,minecraft:crying_obsidian,20)
RB(-11,9,-11,minecraft:obsidian,80,minecraft:crying_obsidian,20)
RB(-11,10,-11,minecraft:obsidian,80,minecraft:crying_obsidian,20)
RB(-11,11,-11,minecraft:obsidian,80,minecraft:crying_obsidian,20)
RB(-11,12,-11,minecraft:obsidian,80,minecraft:crying_obsidian,20)
RB(-11,13,-11,minecraft:obsidian,80,minecraft:crying_obsidian,20)
RB(-11,9,-10,minecraft:obsidian,80,minecraft:crying_obsidian,20)
RB(-11,10,-10,minecraft:obsidian,80,minecraft:crying_obsidian,20)
RB(-11,11,-10,minecraft:obsidian,80,minecraft:crying_obsidian,20)
RB(-11,12,-10,minecraft:obsidian,80,minecraft:crying_obsidian,20)
RB(-11,13,-10,minecraft:obsidian,80,minecraft:crying_obsidian,20)
RB(-11,9,-9,minecraft:obsidian,80,minecraft:crying_obsidian,20)
RB(-11,10,-9,minecraft:obsidian,80,minecraft:crying_obsidian,20)
RB(-11,11,-9,minecraft:obsidian,80,minecraft:crying_obsidian,20)
RB(-11,12,-9,minecraft:obsidian,80,minecraft:crying_obsidian,20)
RB(-11,13,-9,minecraft:obsidian,80,minecraft:crying_obsidian,20)
RB(-11,16,-9,minecraft:obsidian,80,minecraft:crying_obsidian,20)
RB(-11,17,-9,minecraft:obsidian,80,minecraft:crying_obsidian,20)
RB(-11,18,-9,minecraft:obsidian,80,minecraft:crying_obsidian,20)
RB(-11,10,-8,minecraft:obsidian,80,minecraft:crying_obsidian,20)
RB(-11,11,-8,minecraft:obsidian,80,minecraft:crying_obsidian,20)
RB(-11,12,-8,minecraft:obsidian,80,minecraft:crying_obsidian,20)
RB(-11,15,-8,minecraft:obsidian,80,minecraft:crying_obsidian,20)
RB(-11,16,-8,minecraft:obsidian,80,minecraft:crying_obsidian,20)
RB(-11,17,-8,minecraft:obsidian,80,minecraft:crying_obsidian,20)
RB(-11,18,-8,minecraft:obsidian,80,minecraft:crying_obsidian,20)
RB(-11,19,-8,minecraft:obsidian,80,minecraft:crying_obsidian,20)
RB(-11,20,-8,minecraft:obsidian,80,minecraft:crying_obsidian,20)
RB(-11,21,-8,minecraft:obsidian,80,minecraft:crying_obsidian,20)
RB(-11,22,-8,minecraft:obsidian,80,minecraft:crying_obsidian,20)
RB(-11,11,-7,minecraft:obsidian,80,minecraft:crying_obsidian,20)
RB(-11,12,-7,minecraft:obsidian,80,minecraft:crying_obsidian,20)
RB(-11,13,-7,minecraft:obsidian,80,minecraft:crying_obsidian,20)
RB(-11,15,-7,minecraft:obsidian,80,minecraft:crying_obsidian,20)
RB(-11,16,-7,minecraft:obsidian,80,minecraft:crying_obsidian,20)
RB(-11,17,-7,minecraft:obsidian,80,minecraft:crying_obsidian,20)
RB(-11,18,-7,minecraft:obsidian,80,minecraft:crying_obsidian,20)
RB(-11,19,-7,minecraft:obsidian,80,minecraft:crying_obsidian,20)
RB(-11,20,-7,minecraft:obsidian,80,minecraft:crying_obsidian,20)
RB(-11,21,-7,minecraft:obsidian,80,minecraft:crying_obsidian,20)
RB(-11,22,-7,minecraft:obsidian,80,minecraft:crying_obsidian,20)
RB(-11,23,-7,minecraft:obsidian,80,minecraft:crying_obsidian,20)
RB(-11,24,-7,minecraft:obsidian,80,minecraft:crying_obsidian,20)
RB(-11,9,-6,minecraft:obsidian,80,minecraft:crying_obsidian,20)
RB(-11,10,-6,minecraft:obsidian,80,minecraft:crying_obsidian,20)
RB(-11,11,-6,minecraft:obsidian,80,minecraft:crying_obsidian,20)
RB(-11,12,-6,minecraft:obsidian,80,minecraft:crying_obsidian,20)
RB(-11,13,-6,minecraft:obsidian,80,minecraft:crying_obsidian,20)
RB(-11,14,-6,minecraft:obsidian,80,minecraft:crying_obsidian,20)
RB(-11,15,-6,minecraft:obsidian,80,minecraft:crying_obsidian,20)
RB(-11,16,-6,minecraft:obsidian,80,minecraft:crying_obsidian,20)
RB(-11,17,-6,minecraft:obsidian,80,minecraft:crying_obsidian,20)
RB(-11,18,-6,minecraft:obsidian,80,minecraft:crying_obsidian,20)
RB(-11,19,-6,minecraft:obsidian,80,minecraft:crying_obsidian,20)
RB(-11,20,-6,minecraft:obsidian,80,minecraft:crying_obsidian,20)
RB(-11,21,-6,minecraft:obsidian,80,minecraft:crying_obsidian,20)
RB(-11,22,-6,minecraft:obsidian,80,minecraft:crying_obsidian,20)
RB(-11,23,-6,minecraft:obsidian,80,minecraft:crying_obsidian,20)
RB(-11,8,-5,minecraft:obsidian,80,minecraft:crying_obsidian,20)
RB(-11,9,-5,minecraft:obsidian,80,minecraft:crying_obsidian,20)
RB(-11,10,-5,minecraft:obsidian,80,minecraft:crying_obsidian,20)
RB(-11,11,-5,minecraft:obsidian,80,minecraft:crying_obsidian,20)
RB(-11,12,-5,minecraft:obsidian,80,minecraft:crying_obsidian,20)
RB(-11,13,-5,minecraft:obsidian,80,minecraft:crying_obsidian,20)
RB(-11,14,-5,minecraft:obsidian,80,minecraft:crying_obsidian,20)
RB(-11,15,-5,minecraft:obsidian,80,minecraft:crying_obsidian,20)
RB(-11,16,-5,minecraft:obsidian,80,minecraft:crying_obsidian,20)
RB(-11,17,-5,minecraft:obsidian,80,minecraft:crying_obsidian,20)
RB(-11,18,-5,minecraft:obsidian,80,minecraft:crying_obsidian,20)
RB(-11,19,-5,minecraft:obsidian,80,minecraft:crying_obsidian,20)
RB(-11,20,-5,minecraft:obsidian,80,minecraft:crying_obsidian,20)
RB(-11,21,-5,minecraft:obsidian,80,minecraft:crying_obsidian,20)
RB(-11,8,-4,minecraft:obsidian,80,minecraft:crying_obsidian,20)
RB(-11,9,-4,minecraft:obsidian,80,minecraft:crying_obsidian,20)
RB(-11,10,-4,minecraft:obsidian,80,minecraft:crying_obsidian,20)
RB(-11,11,-4,minecraft:obsidian,80,minecraft:crying_obsidian,20)
RB(-11,12,-4,minecraft:obsidian,80,minecraft:crying_obsidian,20)
RB(-11,13,-4,minecraft:obsidian,80,minecraft:crying_obsidian,20)
RB(-11,14,-4,minecraft:obsidian,80,minecraft:crying_obsidian,20)
RB(-11,15,-4,minecraft:obsidian,80,minecraft:crying_obsidian,20)
RB(-11,16,-4,minecraft:obsidian,80,minecraft:crying_obsidian,20)
RB(-11,17,-4,minecraft:obsidian,80,minecraft:crying_obsidian,20)
RB(-11,18,-4,minecraft:obsidian,80,minecraft:crying_obsidian,20)
RB(-11,19,-4,minecraft:obsidian,80,minecraft:crying_obsidian,20)
RB(-11,7,-3,minecraft:obsidian,80,minecraft:crying_obsidian,20)
RB(-11,8,-3,minecraft:obsidian,80,minecraft:crying_obsidian,20)
RB(-11,9,-3,minecraft:obsidian,80,minecraft:crying_obsidian,20)
RB(-11,10,-3,minecraft:obsidian,80,minecraft:crying_obsidian,20)
RB(-11,11,-3,minecraft:obsidian,80,minecraft:crying_obsidian,20)
RB(-11,12,-3,minecraft:obsidian,80,minecraft:crying_obsidian,20)
RB(-11,13,-3,minecraft:obsidian,80,minecraft:crying_obsidian,20)
RB(-11,14,-3,minecraft:obsidian,80,minecraft:crying_obsidian,20)
RB(-11,15,-3,minecraft:obsidian,80,minecraft:crying_obsidian,20)
RB(-11,16,-3,minecraft:obsidian,80,minecraft:crying_obsidian,20)
RB(-11,17,-3,minecraft:obsidian,80,minecraft:crying_obsidian,20)
RB(-11,18,-3,minecraft:obsidian,80,minecraft:crying_obsidian,20)
RB(-11,19,-3,minecraft:obsidian,80,minecraft:crying_obsidian,20)
RB(-11,20,-3,minecraft:obsidian,80,minecraft:crying_obsidian,20)
RB(-11,9,-2,minecraft:obsidian,80,minecraft:crying_obsidian,20)
RB(-11,10,-2,minecraft:obsidian,80,minecraft:crying_obsidian,20)
RB(-11,11,-2,minecraft:obsidian,80,minecraft:crying_obsidian,20)
RB(-11,12,-2,minecraft:obsidian,80,minecraft:crying_obsidian,20)
RB(-11,13,-2,minecraft:obsidian,80,minecraft:crying_obsidian,20)
RB(-11,14,-2,minecraft:obsidian,80,minecraft:crying_obsidian,20)
RB(-11,15,-2,minecraft:obsidian,80,minecraft:crying_obsidian,20)
RB(-11,16,-2,minecraft:obsidian,80,minecraft:crying_obsidian,20)
RB(-11,17,-2,minecraft:obsidian,80,minecraft:crying_obsidian,20)
RB(-11,18,-2,minecraft:obsidian,80,minecraft:crying_obsidian,20)
RB(-11,9,-1,minecraft:obsidian,80,minecraft:crying_obsidian,20)
RB(-11,10,-1,minecraft:obsidian,80,minecraft:crying_obsidian,20)
RB(-11,11,-1,minecraft:obsidian,80,minecraft:crying_obsidian,20)
RB(-11,12,-1,minecraft:obsidian,80,minecraft:crying_obsidian,20)
RB(-11,13,-1,minecraft:obsidian,80,minecraft:crying_obsidian,20)
RB(-11,14,-1,minecraft:obsidian,80,minecraft:crying_obsidian,20)
RB(-11,15,-1,minecraft:obsidian,80,minecraft:crying_obsidian,20)
RB(-11,16,-1,minecraft:obsidian,80,minecraft:crying_obsidian,20)
RB(-11,17,-1,minecraft:obsidian,80,minecraft:crying_obsidian,20)
RB(-11,18,-1,minecraft:obsidian,80,minecraft:crying_obsidian,20)
RB(-11,9,0,minecraft:obsidian,80,minecraft:crying_obsidian,20)
RB(-11,10,0,minecraft:obsidian,80,minecraft:crying_obsidian,20)
RB(-11,11,0,minecraft:obsidian,80,minecraft:crying_obsidian,20)
RB(-11,12,0,minecraft:obsidian,80,minecraft:crying_obsidian,20)
RB(-11,13,0,minecraft:obsidian,80,minecraft:crying_obsidian,20)
RB(-11,14,0,minecraft:obsidian,80,minecraft:crying_obsidian,20)
RB(-11,15,0,minecraft:obsidian,80,minecraft:crying_obsidian,20)
RB(-11,16,0,minecraft:obsidian,80,minecraft:crying_obsidian,20)
RB(-11,17,0,minecraft:obsidian,80,minecraft:crying_obsidian,20)
RB(-11,18,0,minecraft:obsidian,80,minecraft:crying_obsidian,20)
RB(-11,8,1,minecraft:obsidian,80,minecraft:crying_obsidian,20)
RB(-11,9,1,minecraft:obsidian,80,minecraft:crying_obsidian,20)
RB(-11,10,1,minecraft:obsidian,80,minecraft:crying_obsidian,20)
RB(-11,11,1,minecraft:obsidian,80,minecraft:crying_obsidian,20)
RB(-11,12,1,minecraft:obsidian,80,minecraft:crying_obsidian,20)
RB(-11,13,1,minecraft:obsidian,80,minecraft:crying_obsidian,20)
RB(-11,14,1,minecraft:obsidian,80,minecraft:crying_obsidian,20)
RB(-11,15,1,minecraft:obsidian,80,minecraft:crying_obsidian,20)
RB(-11,16,1,minecraft:obsidian,80,minecraft:crying_obsidian,20)
RB(-11,17,1,minecraft:obsidian,80,minecraft:crying_obsidian,20)
RB(-11,18,1,minecraft:obsidian,80,minecraft:crying_obsidian,20)
RB(-11,10,2,minecraft:obsidian,80,minecraft:crying_obsidian,20)
RB(-11,11,2,minecraft:obsidian,80,minecraft:crying_obsidian,20)
RB(-11,12,2,minecraft:obsidian,80,minecraft:crying_obsidian,20)
RB(-11,13,2,minecraft:obsidian,80,minecraft:crying_obsidian,20)
RB(-11,14,2,minecraft:obsidian,80,minecraft:crying_obsidian,20)
RB(-11,15,2,minecraft:obsidian,80,minecraft:crying_obsidian,20)
RB(-11,16,2,minecraft:obsidian,80,minecraft:crying_obsidian,20)
RB(-11,17,2,minecraft:obsidian,80,minecraft:crying_obsidian,20)
RB(-11,18,2,minecraft:obsidian,80,minecraft:crying_obsidian,20)
RB(-11,19,2,minecraft:obsidian,80,minecraft:crying_obsidian,20)
RB(-11,10,3,minecraft:obsidian,80,minecraft:crying_obsidian,20)
RB(-11,11,3,minecraft:obsidian,80,minecraft:crying_obsidian,20)
RB(-11,12,3,minecraft:obsidian,80,minecraft:crying_obsidian,20)
RB(-11,13,3,minecraft:obsidian,80,minecraft:crying_obsidian,20)
RB(-11,14,3,minecraft:obsidian,80,minecraft:crying_obsidian,20)
RB(-11,15,3,minecraft:obsidian,80,minecraft:crying_obsidian,20)
RB(-11,16,3,minecraft:obsidian,80,minecraft:crying_obsidian,20)
RB(-11,17,3,minecraft:obsidian,80,minecraft:crying_obsidian,20)
RB(-11,18,3,minecraft:obsidian,80,minecraft:crying_obsidian,20)
RB(-11,19,3,minecraft:obsidian,80,minecraft:crying_obsidian,20)
RB(-11,10,4,minecraft:obsidian,80,minecraft:crying_obsidian,20)
RB(-11,11,4,minecraft:obsidian,80,minecraft:crying_obsidian,20)
RB(-11,12,4,minecraft:obsidian,80,minecraft:crying_obsidian,20)
RB(-11,13,4,minecraft:obsidian,80,minecraft:crying_obsidian,20)
RB(-11,14,4,minecraft:obsidian,80,minecraft:crying_obsidian,20)
RB(-11,15,4,minecraft:obsidian,80,minecraft:crying_obsidian,20)
RB(-11,16,4,minecraft:obsidian,80,minecraft:crying_obsidian,20)
RB(-11,17,4,minecraft:obsidian,80,minecraft:crying_obsidian,20)
RB(-11,18,4,minecraft:obsidian,80,minecraft:crying_obsidian,20)
RB(-11,19,4,minecraft:obsidian,80,minecraft:crying_obsidian,20)
RB(-11,9,5,minecraft:obsidian,80,minecraft:crying_obsidian,20)
RB(-11,10,5,minecraft:obsidian,80,minecraft:crying_obsidian,20)
RB(-11,11,5,minecraft:obsidian,80,minecraft:crying_obsidian,20)
RB(-11,12,5,minecraft:obsidian,80,minecraft:crying_obsidian,20)
RB(-11,13,5,minecraft:obsidian,80,minecraft:crying_obsidian,20)
RB(-11,14,5,minecraft:obsidian,80,minecraft:crying_obsidian,20)
RB(-11,15,5,minecraft:obsidian,80,minecraft:crying_obsidian,20)
RB(-11,16,5,minecraft:obsidian,80,minecraft:crying_obsidian,20)
RB(-11,17,5,minecraft:obsidian,80,minecraft:crying_obsidian,20)
RB(-11,18,5,minecraft:obsidian,80,minecraft:crying_obsidian,20)
RB(-11,19,5,minecraft:obsidian,80,minecraft:crying_obsidian,20)
RB(-11,20,5,minecraft:obsidian,80,minecraft:crying_obsidian,20)
RB(-11,9,6,minecraft:obsidian,80,minecraft:crying_obsidian,20)
RB(-11,10,6,minecraft:obsidian,80,minecraft:crying_obsidian,20)
RB(-11,11,6,minecraft:obsidian,80,minecraft:crying_obsidian,20)
RB(-11,12,6,minecraft:obsidian,80,minecraft:crying_obsidian,20)
RB(-11,13,6,minecraft:obsidian,80,minecraft:crying_obsidian,20)
RB(-11,14,6,minecraft:obsidian,80,minecraft:crying_obsidian,20)
RB(-11,15,6,minecraft:obsidian,80,minecraft:crying_obsidian,20)
RB(-11,16,6,minecraft:obsidian,80,minecraft:crying_obsidian,20)
RB(-11,17,6,minecraft:obsidian,80,minecraft:crying_obsidian,20)
RB(-11,18,6,minecraft:obsidian,80,minecraft:crying_obsidian,20)
RB(-11,19,6,minecraft:obsidian,80,minecraft:crying_obsidian,20)
RB(-11,20,6,minecraft:obsidian,80,minecraft:crying_obsidian,20)
RB(-11,10,7,minecraft:obsidian,80,minecraft:crying_obsidian,20)
RB(-11,11,7,minecraft:obsidian,80,minecraft:crying_obsidian,20)
RB(-11,12,7,minecraft:obsidian,80,minecraft:crying_obsidian,20)
RB(-11,13,7,minecraft:obsidian,80,minecraft:crying_obsidian,20)
RB(-11,14,7,minecraft:obsidian,80,minecraft:crying_obsidian,20)
RB(-11,15,7,minecraft:obsidian,80,minecraft:crying_obsidian,20)
RB(-11,16,7,minecraft:obsidian,80,minecraft:crying_obsidian,20)
RB(-11,17,7,minecraft:obsidian,80,minecraft:crying_obsidian,20)
RB(-11,18,7,minecraft:obsidian,80,minecraft:crying_obsidian,20)
RB(-11,19,7,minecraft:obsidian,80,minecraft:crying_obsidian,20)
RB(-11,20,7,minecraft:obsidian,80,minecraft:crying_obsidian,20)
RB(-11,10,8,minecraft:obsidian,80,minecraft:crying_obsidian,20)
RB(-11,11,8,minecraft:obsidian,80,minecraft:crying_obsidian,20)
RB(-11,12,8,minecraft:obsidian,80,minecraft:crying_obsidian,20)
RB(-11,13,8,minecraft:obsidian,80,minecraft:crying_obsidian,20)
RB(-11,14,8,minecraft:obsidian,80,minecraft:crying_obsidian,20)
RB(-11,15,8,minecraft:obsidian,80,minecraft:crying_obsidian,20)
RB(-11,16,8,minecraft:obsidian,80,minecraft:crying_obsidian,20)
RB(-11,17,8,minecraft:obsidian,80,minecraft:crying_obsidian,20)
RB(-11,18,8,minecraft:obsidian,80,minecraft:crying_obsidian,20)
RB(-11,19,8,minecraft:obsidian,80,minecraft:crying_obsidian,20)
RB(-11,10,9,minecraft:obsidian,80,minecraft:crying_obsidian,20)
RB(-11,11,9,minecraft:obsidian,80,minecraft:crying_obsidian,20)
RB(-11,12,9,minecraft:obsidian,80,minecraft:crying_obsidian,20)
RB(-11,13,9,minecraft:obsidian,80,minecraft:crying_obsidian,20)
RB(-11,14,9,minecraft:obsidian,80,minecraft:crying_obsidian,20)
RB(-11,15,9,minecraft:obsidian,80,minecraft:crying_obsidian,20)
RB(-11,16,9,minecraft:obsidian,80,minecraft:crying_obsidian,20)
RB(-11,17,9,minecraft:obsidian,80,minecraft:crying_obsidian,20)
RB(-11,18,9,minecraft:obsidian,80,minecraft:crying_obsidian,20)
RB(-11,9,10,minecraft:obsidian,80,minecraft:crying_obsidian,20)
RB(-11,10,10,minecraft:obsidian,80,minecraft:crying_obsidian,20)
RB(-11,11,10,minecraft:obsidian,80,minecraft:crying_obsidian,20)
RB(-11,12,10,minecraft:obsidian,80,minecraft:crying_obsidian,20)
RB(-11,13,10,minecraft:obsidian,80,minecraft:crying_obsidian,20)
RB(-11,14,10,minecraft:obsidian,80,minecraft:crying_obsidian,20)
RB(-11,15,10,minecraft:obsidian,80,minecraft:crying_obsidian,20)
RB(-11,16,10,minecraft:obsidian,80,minecraft:crying_obsidian,20)
RB(-11,17,10,minecraft:obsidian,80,minecraft:crying_obsidian,20)
RB(-11,18,10,minecraft:obsidian,80,minecraft:crying_obsidian,20)
RB(-11,19,10,minecraft:obsidian,80,minecraft:crying_obsidian,20)
RB(-11,9,11,minecraft:obsidian,80,minecraft:crying_obsidian,20)
RB(-11,10,11,minecraft:obsidian,80,minecraft:crying_obsidian,20)
RB(-11,11,11,minecraft:obsidian,80,minecraft:crying_obsidian,20)
RB(-11,12,11,minecraft:obsidian,80,minecraft:crying_obsidian,20)
RB(-11,13,11,minecraft:obsidian,80,minecraft:crying_obsidian,20)
RB(-11,14,11,minecraft:obsidian,80,minecraft:crying_obsidian,20)
RB(-11,15,11,minecraft:obsidian,80,minecraft:crying_obsidian,20)
RB(-11,16,11,minecraft:obsidian,80,minecraft:crying_obsidian,20)
RB(-11,17,11,minecraft:obsidian,80,minecraft:crying_obsidian,20)
RB(-11,18,11,minecraft:obsidian,80,minecraft:crying_obsidian,20)
RB(-11,19,11,minecraft:obsidian,80,minecraft:crying_obsidian,20)
RB(-11,9,12,minecraft:obsidian,80,minecraft:crying_obsidian,20)
RB(-11,10,12,minecraft:obsidian,80,minecraft:crying_obsidian,20)
RB(-11,11,12,minecraft:obsidian,80,minecraft:crying_obsidian,20)
RB(-11,12,12,minecraft:obsidian,80,minecraft:crying_obsidian,20)
RB(-11,13,12,minecraft:obsidian,80,minecraft:crying_obsidian,20)
RB(-11,14,12,minecraft:obsidian,80,minecraft:crying_obsidian,20)
RB(-11,15,12,minecraft:obsidian,80,minecraft:crying_obsidian,20)
RB(-11,16,12,minecraft:obsidian,80,minecraft:crying_obsidian,20)
RB(-11,17,12,minecraft:obsidian,80,minecraft:crying_obsidian,20)
RB(-11,18,12,minecraft:obsidian,80,minecraft:crying_obsidian,20)
RB(-11,19,12,minecraft:obsidian,80,minecraft:crying_obsidian,20)
RB(-11,20,12,minecraft:obsidian,80,minecraft:crying_obsidian,20)
RB(-11,21,12,minecraft:obsidian,80,minecraft:crying_obsidian,20)
RB(-11,10,13,minecraft:obsidian,80,minecraft:crying_obsidian,20)
RB(-11,11,13,minecraft:obsidian,80,minecraft:crying_obsidian,20)
RB(-11,12,13,minecraft:obsidian,80,minecraft:crying_obsidian,20)
RB(-11,13,13,minecraft:obsidian,80,minecraft:crying_obsidian,20)
RB(-11,14,13,minecraft:obsidian,80,minecraft:crying_obsidian,20)
RB(-11,15,13,minecraft:obsidian,80,minecraft:crying_obsidian,20)
RB(-11,16,13,minecraft:obsidian,80,minecraft:crying_obsidian,20)
RB(-11,17,13,minecraft:obsidian,80,minecraft:crying_obsidian,20)
RB(-11,18,13,minecraft:obsidian,80,minecraft:crying_obsidian,20)
RB(-11,19,13,minecraft:obsidian,80,minecraft:crying_obsidian,20)
RB(-11,20,13,minecraft:obsidian,80,minecraft:crying_obsidian,20)
RB(-11,10,14,minecraft:obsidian,80,minecraft:crying_obsidian,20)
RB(-11,11,14,minecraft:obsidian,80,minecraft:crying_obsidian,20)
RB(-11,12,14,minecraft:obsidian,80,minecraft:crying_obsidian,20)
RB(-11,13,14,minecraft:obsidian,80,minecraft:crying_obsidian,20)
RB(-11,14,14,minecraft:obsidian,80,minecraft:crying_obsidian,20)
RB(-11,15,14,minecraft:obsidian,80,minecraft:crying_obsidian,20)
RB(-11,16,14,minecraft:obsidian,80,minecraft:crying_obsidian,20)
RB(-11,17,14,minecraft:obsidian,80,minecraft:crying_obsidian,20)
RB(-11,18,14,minecraft:obsidian,80,minecraft:crying_obsidian,20)
RB(-11,19,14,minecraft:obsidian,80,minecraft:crying_obsidian,20)
RB(-11,20,14,minecraft:obsidian,80,minecraft:crying_obsidian,20)
RB(-11,21,14,minecraft:obsidian,80,minecraft:crying_obsidian,20)
RB(-11,11,15,minecraft:obsidian,80,minecraft:crying_obsidian,20)
RB(-11,12,15,minecraft:obsidian,80,minecraft:crying_obsidian,20)
RB(-11,13,15,minecraft:obsidian,80,minecraft:crying_obsidian,20)
RB(-11,14,15,minecraft:obsidian,80,minecraft:crying_obsidian,20)
RB(-11,15,15,minecraft:obsidian,80,minecraft:crying_obsidian,20)
RB(-11,16,15,minecraft:obsidian,80,minecraft:crying_obsidian,20)
RB(-11,17,15,minecraft:obsidian,80,minecraft:crying_obsidian,20)
RB(-11,18,15,minecraft:obsidian,80,minecraft:crying_obsidian,20)
RB(-11,19,15,minecraft:obsidian,80,minecraft:crying_obsidian,20)
RB(-11,20,15,minecraft:obsidian,80,minecraft:crying_obsidian,20)
RB(-11,21,15,minecraft:obsidian,80,minecraft:crying_obsidian,20)
RB(-11,13,16,minecraft:obsidian,80,minecraft:crying_obsidian,20)
RB(-11,14,16,minecraft:obsidian,80,minecraft:crying_obsidian,20)
RB(-11,15,16,minecraft:obsidian,80,minecraft:crying_obsidian,20)
RB(-11,16,16,minecraft:obsidian,80,minecraft:crying_obsidian,20)
RB(-11,17,16,minecraft:obsidian,80,minecraft:crying_obsidian,20)
RB(-11,18,16,minecraft:obsidian,80,minecraft:crying_obsidian,20)
RB(-11,19,16,minecraft:obsidian,80,minecraft:crying_obsidian,20)
RB(-11,20,16,minecraft:obsidian,80,minecraft:crying_obsidian,20)
RB(-10,9,-13,minecraft:obsidian,80,minecraft:crying_obsidian,20)
RB(-10,10,-13,minecraft:obsidian,80,minecraft:crying_obsidian,20)
RB(-10,11,-13,minecraft:obsidian,80,minecraft:crying_obsidian,20)
RB(-10,12,-13,minecraft:obsidian,80,minecraft:crying_obsidian,20)
RB(-10,13,-13,minecraft:obsidian,80,minecraft:crying_obsidian,20)
RB(-10,8,-12,minecraft:obsidian,80,minecraft:crying_obsidian,20)
RB(-10,9,-12,minecraft:obsidian,80,minecraft:crying_obsidian,20)
RB(-10,10,-12,minecraft:obsidian,80,minecraft:crying_obsidian,20)
RB(-10,11,-12,minecraft:obsidian,80,minecraft:crying_obsidian,20)
RB(-10,12,-12,minecraft:obsidian,80,minecraft:crying_obsidian,20)
RB(-10,13,-12,minecraft:obsidian,80,minecraft:crying_obsidian,20)
RB(-10,14,-12,minecraft:obsidian,80,minecraft:crying_obsidian,20)
RB(-10,8,-11,minecraft:obsidian,80,minecraft:crying_obsidian,20)
RB(-10,9,-11,minecraft:obsidian,80,minecraft:crying_obsidian,20)
RB(-10,10,-11,minecraft:obsidian,80,minecraft:crying_obsidian,20)
RB(-10,11,-11,minecraft:obsidian,80,minecraft:crying_obsidian,20)
RB(-10,12,-11,minecraft:obsidian,80,minecraft:crying_obsidian,20)
RB(-10,13,-11,minecraft:obsidian,80,minecraft:crying_obsidian,20)
RB(-10,14,-11,minecraft:obsidian,80,minecraft:crying_obsidian,20)
RB(-10,8,-10,minecraft:obsidian,80,minecraft:crying_obsidian,20)
RB(-10,9,-10,minecraft:obsidian,80,minecraft:crying_obsidian,20)
RB(-10,10,-10,minecraft:obsidian,80,minecraft:crying_obsidian,20)
RB(-10,11,-10,minecraft:obsidian,80,minecraft:crying_obsidian,20)
RB(-10,12,-10,minecraft:obsidian,80,minecraft:crying_obsidian,20)
RB(-10,13,-10,minecraft:obsidian,80,minecraft:crying_obsidian,20)
RB(-10,14,-10,minecraft:obsidian,80,minecraft:crying_obsidian,20)
RB(-10,15,-10,minecraft:obsidian,80,minecraft:crying_obsidian,20)
RB(-10,16,-10,minecraft:obsidian,80,minecraft:crying_obsidian,20)
RB(-10,17,-10,minecraft:obsidian,80,minecraft:crying_obsidian,20)
RB(-10,18,-10,minecraft:obsidian,80,minecraft:crying_obsidian,20)
RB(-10,19,-10,minecraft:obsidian,80,minecraft:crying_obsidian,20)
RB(-10,20,-10,minecraft:obsidian,80,minecraft:crying_obsidian,20)
RB(-10,21,-10,minecraft:obsidian,80,minecraft:crying_obsidian,20)
RB(-10,8,-9,minecraft:obsidian,80,minecraft:crying_obsidian,20)
RB(-10,9,-9,minecraft:obsidian,80,minecraft:crying_obsidian,20)
RB(-10,10,-9,minecraft:obsidian,80,minecraft:crying_obsidian,20)
RB(-10,11,-9,minecraft:obsidian,80,minecraft:crying_obsidian,20)
RB(-10,12,-9,minecraft:obsidian,80,minecraft:crying_obsidian,20)
RB(-10,13,-9,minecraft:obsidian,80,minecraft:crying_obsidian,20)
RB(-10,14,-9,minecraft:obsidian,80,minecraft:crying_obsidian,20)
RB(-10,15,-9,minecraft:obsidian,80,minecraft:crying_obsidian,20)
RB(-10,16,-9,minecraft:obsidian,80,minecraft:crying_obsidian,20)
RB(-10,17,-9,minecraft:obsidian,80,minecraft:crying_obsidian,20)
RB(-10,18,-9,minecraft:obsidian,80,minecraft:crying_obsidian,20)
RB(-10,19,-9,minecraft:obsidian,80,minecraft:crying_obsidian,20)
RB(-10,20,-9,minecraft:obsidian,80,minecraft:crying_obsidian,20)
RB(-10,21,-9,minecraft:obsidian,80,minecraft:crying_obsidian,20)
RB(-10,22,-9,minecraft:obsidian,80,minecraft:crying_obsidian,20)
RB(-10,23,-9,minecraft:obsidian,80,minecraft:crying_obsidian,20)
RB(-10,24,-9,minecraft:obsidian,80,minecraft:crying_obsidian,20)
RB(-10,8,-8,minecraft:obsidian,80,minecraft:crying_obsidian,20)
RB(-10,9,-8,minecraft:obsidian,80,minecraft:crying_obsidian,20)
RB(-10,10,-8,minecraft:obsidian,80,minecraft:crying_obsidian,20)
RB(-10,11,-8,minecraft:obsidian,80,minecraft:crying_obsidian,20)
RB(-10,12,-8,minecraft:obsidian,80,minecraft:crying_obsidian,20)
RB(-10,13,-8,minecraft:obsidian,80,minecraft:crying_obsidian,20)
RB(-10,14,-8,minecraft:obsidian,80,minecraft:crying_obsidian,20)
RB(-10,15,-8,minecraft:obsidian,80,minecraft:crying_obsidian,20)
RB(-10,16,-8,minecraft:obsidian,80,minecraft:crying_obsidian,20)
RB(-10,17,-8,minecraft:obsidian,80,minecraft:crying_obsidian,20)
RB(-10,18,-8,minecraft:obsidian,80,minecraft:crying_obsidian,20)
RB(-10,19,-8,minecraft:obsidian,80,minecraft:crying_obsidian,20)
RB(-10,20,-8,minecraft:obsidian,80,minecraft:crying_obsidian,20)
RB(-10,21,-8,minecraft:obsidian,80,minecraft:crying_obsidian,20)
RB(-10,22,-8,minecraft:obsidian,80,minecraft:crying_obsidian,20)
RB(-10,23,-8,minecraft:obsidian,80,minecraft:crying_obsidian,20)
RB(-10,24,-8,minecraft:obsidian,80,minecraft:crying_obsidian,20)
RB(-10,25,-8,minecraft:obsidian,80,minecraft:crying_obsidian,20)
RB(-10,9,-7,minecraft:obsidian,80,minecraft:crying_obsidian,20)
RB(-10,10,-7,minecraft:obsidian,80,minecraft:crying_obsidian,20)
RB(-10,11,-7,minecraft:obsidian,80,minecraft:crying_obsidian,20)
RB(-10,12,-7,minecraft:obsidian,80,minecraft:crying_obsidian,20)
RB(-10,13,-7,minecraft:obsidian,80,minecraft:crying_obsidian,20)
RB(-10,14,-7,minecraft:obsidian,80,minecraft:crying_obsidian,20)
RB(-10,15,-7,minecraft:obsidian,80,minecraft:crying_obsidian,20)
RB(-10,16,-7,minecraft:obsidian,80,minecraft:crying_obsidian,20)
RB(-10,17,-7,minecraft:obsidian,80,minecraft:crying_obsidian,20)
RB(-10,18,-7,minecraft:obsidian,80,minecraft:crying_obsidian,20)
RB(-10,19,-7,minecraft:obsidian,80,minecraft:crying_obsidian,20)
RB(-10,20,-7,minecraft:obsidian,80,minecraft:crying_obsidian,20)
RB(-10,21,-7,minecraft:obsidian,80,minecraft:crying_obsidian,20)
RB(-10,22,-7,minecraft:obsidian,80,minecraft:crying_obsidian,20)
RB(-10,23,-7,minecraft:obsidian,80,minecraft:crying_obsidian,20)
RB(-10,24,-7,minecraft:obsidian,80,minecraft:crying_obsidian,20)
RB(-10,25,-7,minecraft:obsidian,80,minecraft:crying_obsidian,20)
RB(-10,9,-6,minecraft:obsidian,80,minecraft:crying_obsidian,20)
RB(-10,10,-6,minecraft:obsidian,80,minecraft:crying_obsidian,20)
RB(-10,11,-6,minecraft:obsidian,80,minecraft:crying_obsidian,20)
RB(-10,12,-6,minecraft:obsidian,80,minecraft:crying_obsidian,20)
RB(-10,13,-6,minecraft:obsidian,80,minecraft:crying_obsidian,20)
RB(-10,14,-6,minecraft:obsidian,80,minecraft:crying_obsidian,20)
RB(-10,15,-6,minecraft:obsidian,80,minecraft:crying_obsidian,20)
RB(-10,16,-6,minecraft:obsidian,80,minecraft:crying_obsidian,20)
RB(-10,17,-6,minecraft:obsidian,80,minecraft:crying_obsidian,20)
RB(-10,18,-6,minecraft:obsidian,80,minecraft:crying_obsidian,20)
RB(-10,19,-6,minecraft:obsidian,80,minecraft:crying_obsidian,20)
RB(-10,20,-6,minecraft:obsidian,80,minecraft:crying_obsidian,20)
RB(-10,21,-6,minecraft:obsidian,80,minecraft:crying_obsidian,20)
RB(-10,22,-6,minecraft:obsidian,80,minecraft:crying_obsidian,20)
RB(-10,23,-6,minecraft:obsidian,80,minecraft:crying_obsidian,20)
RB(-10,24,-6,minecraft:obsidian,80,minecraft:crying_obsidian,20)
RB(-10,8,-5,minecraft:obsidian,80,minecraft:crying_obsidian,20)
RB(-10,9,-5,minecraft:obsidian,80,minecraft:crying_obsidian,20)
RB(-10,10,-5,minecraft:obsidian,80,minecraft:crying_obsidian,20)
RB(-10,11,-5,minecraft:obsidian,80,minecraft:crying_obsidian,20)
RB(-10,12,-5,minecraft:obsidian,80,minecraft:crying_obsidian,20)
RB(-10,13,-5,minecraft:obsidian,80,minecraft:crying_obsidian,20)
RB(-10,14,-5,minecraft:obsidian,80,minecraft:crying_obsidian,20)
RB(-10,15,-5,minecraft:obsidian,80,minecraft:crying_obsidian,20)
RB(-10,16,-5,minecraft:obsidian,80,minecraft:crying_obsidian,20)
RB(-10,17,-5,minecraft:obsidian,80,minecraft:crying_obsidian,20)
RB(-10,18,-5,minecraft:obsidian,80,minecraft:crying_obsidian,20)
RB(-10,19,-5,minecraft:obsidian,80,minecraft:crying_obsidian,20)
RB(-10,20,-5,minecraft:obsidian,80,minecraft:crying_obsidian,20)
RB(-10,21,-5,minecraft:obsidian,80,minecraft:crying_obsidian,20)
RB(-10,22,-5,minecraft:obsidian,80,minecraft:crying_obsidian,20)
RB(-10,23,-5,minecraft:obsidian,80,minecraft:crying_obsidian,20)
RB(-10,8,-4,minecraft:obsidian,80,minecraft:crying_obsidian,20)
RB(-10,9,-4,minecraft:obsidian,80,minecraft:crying_obsidian,20)
RB(-10,10,-4,minecraft:obsidian,80,minecraft:crying_obsidian,20)
RB(-10,11,-4,minecraft:obsidian,80,minecraft:crying_obsidian,20)
RB(-10,12,-4,minecraft:obsidian,80,minecraft:crying_obsidian,20)
RB(-10,13,-4,minecraft:obsidian,80,minecraft:crying_obsidian,20)
RB(-10,14,-4,minecraft:obsidian,80,minecraft:crying_obsidian,20)
RB(-10,15,-4,minecraft:obsidian,80,minecraft:crying_obsidian,20)
RB(-10,16,-4,minecraft:obsidian,80,minecraft:crying_obsidian,20)
RB(-10,17,-4,minecraft:obsidian,80,minecraft:crying_obsidian,20)
RB(-10,18,-4,minecraft:obsidian,80,minecraft:crying_obsidian,20)
RB(-10,19,-4,minecraft:obsidian,80,minecraft:crying_obsidian,20)
RB(-10,20,-4,minecraft:obsidian,80,minecraft:crying_obsidian,20)
RB(-10,21,-4,minecraft:obsidian,80,minecraft:crying_obsidian,20)
RB(-10,22,-4,minecraft:obsidian,80,minecraft:crying_obsidian,20)
RB(-10,9,-3,minecraft:obsidian,80,minecraft:crying_obsidian,20)
RB(-10,10,-3,minecraft:obsidian,80,minecraft:crying_obsidian,20)
RB(-10,11,-3,minecraft:obsidian,80,minecraft:crying_obsidian,20)
RB(-10,12,-3,minecraft:obsidian,80,minecraft:crying_obsidian,20)
RB(-10,13,-3,minecraft:obsidian,80,minecraft:crying_obsidian,20)
RB(-10,14,-3,minecraft:obsidian,80,minecraft:crying_obsidian,20)
RB(-10,15,-3,minecraft:obsidian,80,minecraft:crying_obsidian,20)
RB(-10,16,-3,minecraft:obsidian,80,minecraft:crying_obsidian,20)
RB(-10,17,-3,minecraft:obsidian,80,minecraft:crying_obsidian,20)
RB(-10,18,-3,minecraft:obsidian,80,minecraft:crying_obsidian,20)
RB(-10,19,-3,minecraft:obsidian,80,minecraft:crying_obsidian,20)
RB(-10,20,-3,minecraft:obsidian,80,minecraft:crying_obsidian,20)
RB(-10,9,-2,minecraft:obsidian,80,minecraft:crying_obsidian,20)
RB(-10,10,-2,minecraft:obsidian,80,minecraft:crying_obsidian,20)
RB(-10,11,-2,minecraft:obsidian,80,minecraft:crying_obsidian,20)
RB(-10,12,-2,minecraft:obsidian,80,minecraft:crying_obsidian,20)
RB(-10,13,-2,minecraft:obsidian,80,minecraft:crying_obsidian,20)
RB(-10,14,-2,minecraft:obsidian,80,minecraft:crying_obsidian,20)
RB(-10,15,-2,minecraft:obsidian,80,minecraft:crying_obsidian,20)
RB(-10,16,-2,minecraft:obsidian,80,minecraft:crying_obsidian,20)
RB(-10,17,-2,minecraft:obsidian,80,minecraft:crying_obsidian,20)
RB(-10,18,-2,minecraft:obsidian,80,minecraft:crying_obsidian,20)
RB(-10,19,-2,minecraft:obsidian,80,minecraft:crying_obsidian,20)
RB(-10,9,-1,minecraft:obsidian,80,minecraft:crying_obsidian,20)
RB(-10,10,-1,minecraft:obsidian,80,minecraft:crying_obsidian,20)
RB(-10,11,-1,minecraft:obsidian,80,minecraft:crying_obsidian,20)
RB(-10,12,-1,minecraft:obsidian,80,minecraft:crying_obsidian,20)
RB(-10,13,-1,minecraft:obsidian,80,minecraft:crying_obsidian,20)
RB(-10,14,-1,minecraft:obsidian,80,minecraft:crying_obsidian,20)
RB(-10,15,-1,minecraft:obsidian,80,minecraft:crying_obsidian,20)
RB(-10,16,-1,minecraft:obsidian,80,minecraft:crying_obsidian,20)
RB(-10,17,-1,minecraft:obsidian,80,minecraft:crying_obsidian,20)
RB(-10,18,-1,minecraft:obsidian,80,minecraft:crying_obsidian,20)
RB(-10,9,0,minecraft:obsidian,80,minecraft:crying_obsidian,20)
RB(-10,10,0,minecraft:obsidian,80,minecraft:crying_obsidian,20)
RB(-10,11,0,minecraft:obsidian,80,minecraft:crying_obsidian,20)
RB(-10,12,0,minecraft:obsidian,80,minecraft:crying_obsidian,20)
RB(-10,13,0,minecraft:obsidian,80,minecraft:crying_obsidian,20)
RB(-10,14,0,minecraft:obsidian,80,minecraft:crying_obsidian,20)
RB(-10,15,0,minecraft:obsidian,80,minecraft:crying_obsidian,20)
RB(-10,16,0,minecraft:obsidian,80,minecraft:crying_obsidian,20)
RB(-10,17,0,minecraft:obsidian,80,minecraft:crying_obsidian,20)
RB(-10,18,0,minecraft:obsidian,80,minecraft:crying_obsidian,20)
RB(-10,10,1,minecraft:obsidian,80,minecraft:crying_obsidian,20)
RB(-10,11,1,minecraft:obsidian,80,minecraft:crying_obsidian,20)
RB(-10,12,1,minecraft:obsidian,80,minecraft:crying_obsidian,20)
RB(-10,13,1,minecraft:obsidian,80,minecraft:crying_obsidian,20)
RB(-10,14,1,minecraft:obsidian,80,minecraft:crying_obsidian,20)
RB(-10,15,1,minecraft:obsidian,80,minecraft:crying_obsidian,20)
RB(-10,16,1,minecraft:obsidian,80,minecraft:crying_obsidian,20)
RB(-10,17,1,minecraft:obsidian,80,minecraft:crying_obsidian,20)
RB(-10,18,1,minecraft:obsidian,80,minecraft:crying_obsidian,20)
RB(-10,10,2,minecraft:obsidian,80,minecraft:crying_obsidian,20)
RB(-10,11,2,minecraft:obsidian,80,minecraft:crying_obsidian,20)
RB(-10,12,2,minecraft:obsidian,80,minecraft:crying_obsidian,20)
RB(-10,13,2,minecraft:obsidian,80,minecraft:crying_obsidian,20)
RB(-10,14,2,minecraft:obsidian,80,minecraft:crying_obsidian,20)
RB(-10,15,2,minecraft:obsidian,80,minecraft:crying_obsidian,20)
RB(-10,16,2,minecraft:obsidian,80,minecraft:crying_obsidian,20)
RB(-10,17,2,minecraft:obsidian,80,minecraft:crying_obsidian,20)
RB(-10,18,2,minecraft:obsidian,80,minecraft:crying_obsidian,20)
RB(-10,19,2,minecraft:obsidian,80,minecraft:crying_obsidian,20)
RB(-10,10,3,minecraft:obsidian,80,minecraft:crying_obsidian,20)
RB(-10,11,3,minecraft:obsidian,80,minecraft:crying_obsidian,20)
RB(-10,12,3,minecraft:obsidian,80,minecraft:crying_obsidian,20)
RB(-10,13,3,minecraft:obsidian,80,minecraft:crying_obsidian,20)
RB(-10,14,3,minecraft:obsidian,80,minecraft:crying_obsidian,20)
RB(-10,15,3,minecraft:obsidian,80,minecraft:crying_obsidian,20)
RB(-10,16,3,minecraft:obsidian,80,minecraft:crying_obsidian,20)
RB(-10,17,3,minecraft:obsidian,80,minecraft:crying_obsidian,20)
RB(-10,18,3,minecraft:obsidian,80,minecraft:crying_obsidian,20)
RB(-10,19,3,minecraft:obsidian,80,minecraft:crying_obsidian,20)
RB(-10,10,4,minecraft:obsidian,80,minecraft:crying_obsidian,20)
RB(-10,11,4,minecraft:obsidian,80,minecraft:crying_obsidian,20)
RB(-10,12,4,minecraft:obsidian,80,minecraft:crying_obsidian,20)
RB(-10,13,4,minecraft:obsidian,80,minecraft:crying_obsidian,20)
RB(-10,14,4,minecraft:obsidian,80,minecraft:crying_obsidian,20)
RB(-10,15,4,minecraft:obsidian,80,minecraft:crying_obsidian,20)
RB(-10,16,4,minecraft:obsidian,80,minecraft:crying_obsidian,20)
RB(-10,17,4,minecraft:obsidian,80,minecraft:crying_obsidian,20)
RB(-10,18,4,minecraft:obsidian,80,minecraft:crying_obsidian,20)
RB(-10,19,4,minecraft:obsidian,80,minecraft:crying_obsidian,20)
RB(-10,10,5,minecraft:obsidian,80,minecraft:crying_obsidian,20)
RB(-10,11,5,minecraft:obsidian,80,minecraft:crying_obsidian,20)
RB(-10,12,5,minecraft:obsidian,80,minecraft:crying_obsidian,20)
RB(-10,13,5,minecraft:obsidian,80,minecraft:crying_obsidian,20)
RB(-10,14,5,minecraft:obsidian,80,minecraft:crying_obsidian,20)
RB(-10,15,5,minecraft:obsidian,80,minecraft:crying_obsidian,20)
RB(-10,16,5,minecraft:obsidian,80,minecraft:crying_obsidian,20)
RB(-10,17,5,minecraft:obsidian,80,minecraft:crying_obsidian,20)
RB(-10,18,5,minecraft:obsidian,80,minecraft:crying_obsidian,20)
RB(-10,19,5,minecraft:obsidian,80,minecraft:crying_obsidian,20)
RB(-10,9,6,minecraft:obsidian,80,minecraft:crying_obsidian,20)
RB(-10,10,6,minecraft:obsidian,80,minecraft:crying_obsidian,20)
RB(-10,11,6,minecraft:obsidian,80,minecraft:crying_obsidian,20)
RB(-10,12,6,minecraft:obsidian,80,minecraft:crying_obsidian,20)
RB(-10,13,6,minecraft:obsidian,80,minecraft:crying_obsidian,20)
RB(-10,14,6,minecraft:obsidian,80,minecraft:crying_obsidian,20)
RB(-10,15,6,minecraft:obsidian,80,minecraft:crying_obsidian,20)
RB(-10,16,6,minecraft:obsidian,80,minecraft:crying_obsidian,20)
RB(-10,17,6,minecraft:obsidian,80,minecraft:crying_obsidian,20)
RB(-10,18,6,minecraft:obsidian,80,minecraft:crying_obsidian,20)
RB(-10,19,6,minecraft:obsidian,80,minecraft:crying_obsidian,20)
RB(-10,10,7,minecraft:obsidian,80,minecraft:crying_obsidian,20)
RB(-10,11,7,minecraft:obsidian,80,minecraft:crying_obsidian,20)
RB(-10,12,7,minecraft:obsidian,80,minecraft:crying_obsidian,20)
RB(-10,13,7,minecraft:obsidian,80,minecraft:crying_obsidian,20)
RB(-10,14,7,minecraft:obsidian,80,minecraft:crying_obsidian,20)
RB(-10,15,7,minecraft:obsidian,80,minecraft:crying_obsidian,20)
RB(-10,16,7,minecraft:obsidian,80,minecraft:crying_obsidian,20)
RB(-10,17,7,minecraft:obsidian,80,minecraft:crying_obsidian,20)
RB(-10,18,7,minecraft:obsidian,80,minecraft:crying_obsidian,20)
RB(-10,10,8,minecraft:obsidian,80,minecraft:crying_obsidian,20)
RB(-10,11,8,minecraft:obsidian,80,minecraft:crying_obsidian,20)
RB(-10,12,8,minecraft:obsidian,80,minecraft:crying_obsidian,20)
RB(-10,13,8,minecraft:obsidian,80,minecraft:crying_obsidian,20)
RB(-10,14,8,minecraft:obsidian,80,minecraft:crying_obsidian,20)
RB(-10,15,8,minecraft:obsidian,80,minecraft:crying_obsidian,20)
RB(-10,16,8,minecraft:obsidian,80,minecraft:crying_obsidian,20)
RB(-10,17,8,minecraft:obsidian,80,minecraft:crying_obsidian,20)
RB(-10,18,8,minecraft:obsidian,80,minecraft:crying_obsidian,20)
RB(-10,9,9,minecraft:obsidian,80,minecraft:crying_obsidian,20)
RB(-10,10,9,minecraft:obsidian,80,minecraft:crying_obsidian,20)
RB(-10,11,9,minecraft:obsidian,80,minecraft:crying_obsidian,20)
RB(-10,12,9,minecraft:obsidian,80,minecraft:crying_obsidian,20)
RB(-10,13,9,minecraft:obsidian,80,minecraft:crying_obsidian,20)
RB(-10,14,9,minecraft:obsidian,80,minecraft:crying_obsidian,20)
RB(-10,15,9,minecraft:obsidian,80,minecraft:crying_obsidian,20)
RB(-10,16,9,minecraft:obsidian,80,minecraft:crying_obsidian,20)
RB(-10,17,9,minecraft:obsidian,80,minecraft:crying_obsidian,20)
RB(-10,18,9,minecraft:obsidian,80,minecraft:crying_obsidian,20)
RB(-10,19,9,minecraft:obsidian,80,minecraft:crying_obsidian,20)
RB(-10,9,10,minecraft:obsidian,80,minecraft:crying_obsidian,20)
RB(-10,10,10,minecraft:obsidian,80,minecraft:crying_obsidian,20)
RB(-10,11,10,minecraft:obsidian,80,minecraft:crying_obsidian,20)
RB(-10,12,10,minecraft:obsidian,80,minecraft:crying_obsidian,20)
RB(-10,13,10,minecraft:obsidian,80,minecraft:crying_obsidian,20)
RB(-10,14,10,minecraft:obsidian,80,minecraft:crying_obsidian,20)
RB(-10,15,10,minecraft:obsidian,80,minecraft:crying_obsidian,20)
RB(-10,16,10,minecraft:obsidian,80,minecraft:crying_obsidian,20)
RB(-10,17,10,minecraft:obsidian,80,minecraft:crying_obsidian,20)
RB(-10,18,10,minecraft:obsidian,80,minecraft:crying_obsidian,20)
RB(-10,19,10,minecraft:obsidian,80,minecraft:crying_obsidian,20)
RB(-10,9,11,minecraft:obsidian,80,minecraft:crying_obsidian,20)
RB(-10,10,11,minecraft:obsidian,80,minecraft:crying_obsidian,20)
RB(-10,11,11,minecraft:obsidian,80,minecraft:crying_obsidian,20)
RB(-10,12,11,minecraft:obsidian,80,minecraft:crying_obsidian,20)
RB(-10,13,11,minecraft:obsidian,80,minecraft:crying_obsidian,20)
RB(-10,14,11,minecraft:obsidian,80,minecraft:crying_obsidian,20)
RB(-10,15,11,minecraft:obsidian,80,minecraft:crying_obsidian,20)
RB(-10,16,11,minecraft:obsidian,80,minecraft:crying_obsidian,20)
RB(-10,17,11,minecraft:obsidian,80,minecraft:crying_obsidian,20)
RB(-10,18,11,minecraft:obsidian,80,minecraft:crying_obsidian,20)
RB(-10,19,11,minecraft:obsidian,80,minecraft:crying_obsidian,20)
RB(-10,9,12,minecraft:obsidian,80,minecraft:crying_obsidian,20)
RB(-10,10,12,minecraft:obsidian,80,minecraft:crying_obsidian,20)
RB(-10,11,12,minecraft:obsidian,80,minecraft:crying_obsidian,20)
RB(-10,12,12,minecraft:obsidian,80,minecraft:crying_obsidian,20)
RB(-10,13,12,minecraft:obsidian,80,minecraft:crying_obsidian,20)
RB(-10,14,12,minecraft:obsidian,80,minecraft:crying_obsidian,20)
RB(-10,15,12,minecraft:obsidian,80,minecraft:crying_obsidian,20)
RB(-10,16,12,minecraft:obsidian,80,minecraft:crying_obsidian,20)
RB(-10,17,12,minecraft:obsidian,80,minecraft:crying_obsidian,20)
RB(-10,18,12,minecraft:obsidian,80,minecraft:crying_obsidian,20)
RB(-10,19,12,minecraft:obsidian,80,minecraft:crying_obsidian,20)
RB(-10,20,12,minecraft:obsidian,80,minecraft:crying_obsidian,20)
RB(-10,21,12,minecraft:obsidian,80,minecraft:crying_obsidian,20)
RB(-10,9,13,minecraft:obsidian,80,minecraft:crying_obsidian,20)
RB(-10,10,13,minecraft:obsidian,80,minecraft:crying_obsidian,20)
RB(-10,11,13,minecraft:obsidian,80,minecraft:crying_obsidian,20)
RB(-10,12,13,minecraft:obsidian,80,minecraft:crying_obsidian,20)
RB(-10,13,13,minecraft:obsidian,80,minecraft:crying_obsidian,20)
RB(-10,14,13,minecraft:obsidian,80,minecraft:crying_obsidian,20)
RB(-10,15,13,minecraft:obsidian,80,minecraft:crying_obsidian,20)
RB(-10,16,13,minecraft:obsidian,80,minecraft:crying_obsidian,20)
RB(-10,17,13,minecraft:obsidian,80,minecraft:crying_obsidian,20)
RB(-10,18,13,minecraft:obsidian,80,minecraft:crying_obsidian,20)
RB(-10,19,13,minecraft:obsidian,80,minecraft:crying_obsidian,20)
RB(-10,20,13,minecraft:obsidian,80,minecraft:crying_obsidian,20)
RB(-10,21,13,minecraft:obsidian,80,minecraft:crying_obsidian,20)
RB(-10,10,14,minecraft:obsidian,80,minecraft:crying_obsidian,20)
RB(-10,11,14,minecraft:obsidian,80,minecraft:crying_obsidian,20)
RB(-10,12,14,minecraft:obsidian,80,minecraft:crying_obsidian,20)
RB(-10,13,14,minecraft:obsidian,80,minecraft:crying_obsidian,20)
RB(-10,14,14,minecraft:obsidian,80,minecraft:crying_obsidian,20)
RB(-10,15,14,minecraft:obsidian,80,minecraft:crying_obsidian,20)
RB(-10,16,14,minecraft:obsidian,80,minecraft:crying_obsidian,20)
RB(-10,17,14,minecraft:obsidian,80,minecraft:crying_obsidian,20)
RB(-10,18,14,minecraft:obsidian,80,minecraft:crying_obsidian,20)
RB(-10,19,14,minecraft:obsidian,80,minecraft:crying_obsidian,20)
RB(-10,20,14,minecraft:obsidian,80,minecraft:crying_obsidian,20)
RB(-10,21,14,minecraft:obsidian,80,minecraft:crying_obsidian,20)
RB(-10,22,14,minecraft:obsidian,80,minecraft:crying_obsidian,20)
RB(-10,11,15,minecraft:obsidian,80,minecraft:crying_obsidian,20)
RB(-10,12,15,minecraft:obsidian,80,minecraft:crying_obsidian,20)
RB(-10,13,15,minecraft:obsidian,80,minecraft:crying_obsidian,20)
RB(-10,14,15,minecraft:obsidian,80,minecraft:crying_obsidian,20)
RB(-10,15,15,minecraft:obsidian,80,minecraft:crying_obsidian,20)
RB(-10,16,15,minecraft:obsidian,80,minecraft:crying_obsidian,20)
RB(-10,17,15,minecraft:obsidian,80,minecraft:crying_obsidian,20)
RB(-10,18,15,minecraft:obsidian,80,minecraft:crying_obsidian,20)
RB(-10,19,15,minecraft:obsidian,80,minecraft:crying_obsidian,20)
RB(-10,20,15,minecraft:obsidian,80,minecraft:crying_obsidian,20)
RB(-10,21,15,minecraft:obsidian,80,minecraft:crying_obsidian,20)
RB(-10,22,15,minecraft:obsidian,80,minecraft:crying_obsidian,20)
RB(-10,12,16,minecraft:obsidian,80,minecraft:crying_obsidian,20)
RB(-10,13,16,minecraft:obsidian,80,minecraft:crying_obsidian,20)
RB(-10,14,16,minecraft:obsidian,80,minecraft:crying_obsidian,20)
RB(-10,15,16,minecraft:obsidian,80,minecraft:crying_obsidian,20)
RB(-10,16,16,minecraft:obsidian,80,minecraft:crying_obsidian,20)
RB(-10,17,16,minecraft:obsidian,80,minecraft:crying_obsidian,20)
RB(-10,18,16,minecraft:obsidian,80,minecraft:crying_obsidian,20)
RB(-10,19,16,minecraft:obsidian,80,minecraft:crying_obsidian,20)
RB(-10,20,16,minecraft:obsidian,80,minecraft:crying_obsidian,20)
RB(-10,21,16,minecraft:obsidian,80,minecraft:crying_obsidian,20)
RB(-9,9,-14,minecraft:obsidian,80,minecraft:crying_obsidian,20)
RB(-9,10,-14,minecraft:obsidian,80,minecraft:crying_obsidian,20)
RB(-9,11,-14,minecraft:obsidian,80,minecraft:crying_obsidian,20)
RB(-9,12,-14,minecraft:obsidian,80,minecraft:crying_obsidian,20)
RB(-9,13,-14,minecraft:obsidian,80,minecraft:crying_obsidian,20)
RB(-9,8,-13,minecraft:obsidian,80,minecraft:crying_obsidian,20)
RB(-9,9,-13,minecraft:obsidian,80,minecraft:crying_obsidian,20)
RB(-9,10,-13,minecraft:obsidian,80,minecraft:crying_obsidian,20)
RB(-9,11,-13,minecraft:obsidian,80,minecraft:crying_obsidian,20)
RB(-9,12,-13,minecraft:obsidian,80,minecraft:crying_obsidian,20)
RB(-9,13,-13,minecraft:obsidian,80,minecraft:crying_obsidian,20)
RB(-9,14,-13,minecraft:obsidian,80,minecraft:crying_obsidian,20)
RB(-9,7,-12,minecraft:obsidian,80,minecraft:crying_obsidian,20)
RB(-9,8,-12,minecraft:obsidian,80,minecraft:crying_obsidian,20)
RB(-9,9,-12,minecraft:obsidian,80,minecraft:crying_obsidian,20)
RB(-9,10,-12,minecraft:obsidian,80,minecraft:crying_obsidian,20)
RB(-9,11,-12,minecraft:obsidian,80,minecraft:crying_obsidian,20)
RB(-9,12,-12,minecraft:obsidian,80,minecraft:crying_obsidian,20)
RB(-9,13,-12,minecraft:obsidian,80,minecraft:crying_obsidian,20)
RB(-9,14,-12,minecraft:obsidian,80,minecraft:crying_obsidian,20)
RB(-9,15,-12,minecraft:obsidian,80,minecraft:crying_obsidian,20)
RB(-9,7,-11,minecraft:obsidian,80,minecraft:crying_obsidian,20)
RB(-9,8,-11,minecraft:obsidian,80,minecraft:crying_obsidian,20)
RB(-9,9,-11,minecraft:obsidian,80,minecraft:crying_obsidian,20)
RB(-9,10,-11,minecraft:obsidian,80,minecraft:crying_obsidian,20)
RB(-9,11,-11,minecraft:obsidian,80,minecraft:crying_obsidian,20)
RB(-9,12,-11,minecraft:obsidian,80,minecraft:crying_obsidian,20)
RB(-9,13,-11,minecraft:obsidian,80,minecraft:crying_obsidian,20)
RB(-9,14,-11,minecraft:obsidian,80,minecraft:crying_obsidian,20)
RB(-9,15,-11,minecraft:obsidian,80,minecraft:crying_obsidian,20)
RB(-9,16,-11,minecraft:obsidian,80,minecraft:crying_obsidian,20)
RB(-9,17,-11,minecraft:obsidian,80,minecraft:crying_obsidian,20)
RB(-9,18,-11,minecraft:obsidian,80,minecraft:crying_obsidian,20)
RB(-9,19,-11,minecraft:obsidian,80,minecraft:crying_obsidian,20)
RB(-9,20,-11,minecraft:obsidian,80,minecraft:crying_obsidian,20)
RB(-9,21,-11,minecraft:obsidian,80,minecraft:crying_obsidian,20)
RB(-9,7,-10,minecraft:obsidian,80,minecraft:crying_obsidian,20)
RB(-9,8,-10,minecraft:obsidian,80,minecraft:crying_obsidian,20)
RB(-9,9,-10,minecraft:obsidian,80,minecraft:crying_obsidian,20)
RB(-9,10,-10,minecraft:obsidian,80,minecraft:crying_obsidian,20)
RB(-9,11,-10,minecraft:obsidian,80,minecraft:crying_obsidian,20)
RB(-9,12,-10,minecraft:obsidian,80,minecraft:crying_obsidian,20)
RB(-9,13,-10,minecraft:obsidian,80,minecraft:crying_obsidian,20)
RB(-9,14,-10,minecraft:obsidian,80,minecraft:crying_obsidian,20)
RB(-9,15,-10,minecraft:obsidian,80,minecraft:crying_obsidian,20)
RB(-9,16,-10,minecraft:obsidian,80,minecraft:crying_obsidian,20)
RB(-9,17,-10,minecraft:obsidian,80,minecraft:crying_obsidian,20)
RB(-9,18,-10,minecraft:obsidian,80,minecraft:crying_obsidian,20)
RB(-9,19,-10,minecraft:obsidian,80,minecraft:crying_obsidian,20)
RB(-9,20,-10,minecraft:obsidian,80,minecraft:crying_obsidian,20)
RB(-9,21,-10,minecraft:obsidian,80,minecraft:crying_obsidian,20)
RB(-9,22,-10,minecraft:obsidian,80,minecraft:crying_obsidian,20)
RB(-9,7,-9,minecraft:obsidian,80,minecraft:crying_obsidian,20)
RB(-9,8,-9,minecraft:obsidian,80,minecraft:crying_obsidian,20)
RB(-9,9,-9,minecraft:obsidian,80,minecraft:crying_obsidian,20)
RB(-9,10,-9,minecraft:obsidian,80,minecraft:crying_obsidian,20)
RB(-9,11,-9,minecraft:obsidian,80,minecraft:crying_obsidian,20)
RB(-9,12,-9,minecraft:obsidian,80,minecraft:crying_obsidian,20)
RB(-9,13,-9,minecraft:obsidian,80,minecraft:crying_obsidian,20)
RB(-9,14,-9,minecraft:obsidian,80,minecraft:crying_obsidian,20)
RB(-9,15,-9,minecraft:obsidian,80,minecraft:crying_obsidian,20)
RB(-9,16,-9,minecraft:obsidian,80,minecraft:crying_obsidian,20)
RB(-9,17,-9,minecraft:obsidian,80,minecraft:crying_obsidian,20)
RB(-9,18,-9,minecraft:obsidian,80,minecraft:crying_obsidian,20)
RB(-9,19,-9,minecraft:obsidian,80,minecraft:crying_obsidian,20)
RB(-9,20,-9,minecraft:obsidian,80,minecraft:crying_obsidian,20)
RB(-9,21,-9,minecraft:obsidian,80,minecraft:crying_obsidian,20)
RB(-9,22,-9,minecraft:obsidian,80,minecraft:crying_obsidian,20)
RB(-9,23,-9,minecraft:obsidian,80,minecraft:crying_obsidian,20)
RB(-9,24,-9,minecraft:obsidian,80,minecraft:crying_obsidian,20)
RB(-9,25,-9,minecraft:obsidian,80,minecraft:crying_obsidian,20)
RB(-9,6,-8,minecraft:obsidian,80,minecraft:crying_obsidian,20)
RB(-9,7,-8,minecraft:obsidian,80,minecraft:crying_obsidian,20)
RB(-9,8,-8,minecraft:obsidian,80,minecraft:crying_obsidian,20)
RB(-9,9,-8,minecraft:obsidian,80,minecraft:crying_obsidian,20)
RB(-9,10,-8,minecraft:obsidian,80,minecraft:crying_obsidian,20)
RB(-9,11,-8,minecraft:obsidian,80,minecraft:crying_obsidian,20)
RB(-9,12,-8,minecraft:obsidian,80,minecraft:crying_obsidian,20)
RB(-9,13,-8,minecraft:obsidian,80,minecraft:crying_obsidian,20)
RB(-9,14,-8,minecraft:obsidian,80,minecraft:crying_obsidian,20)
RB(-9,15,-8,minecraft:obsidian,80,minecraft:crying_obsidian,20)
RB(-9,16,-8,minecraft:obsidian,80,minecraft:crying_obsidian,20)
RB(-9,17,-8,minecraft:obsidian,80,minecraft:crying_obsidian,20)
RB(-9,18,-8,minecraft:obsidian,80,minecraft:crying_obsidian,20)
RB(-9,19,-8,minecraft:obsidian,80,minecraft:crying_obsidian,20)
RB(-9,20,-8,minecraft:obsidian,80,minecraft:crying_obsidian,20)
RB(-9,21,-8,minecraft:obsidian,80,minecraft:crying_obsidian,20)
RB(-9,22,-8,minecraft:obsidian,80,minecraft:crying_obsidian,20)
RB(-9,23,-8,minecraft:obsidian,80,minecraft:crying_obsidian,20)
RB(-9,24,-8,minecraft:obsidian,80,minecraft:crying_obsidian,20)
RB(-9,25,-8,minecraft:obsidian,80,minecraft:crying_obsidian,20)
RB(-9,6,-7,minecraft:obsidian,80,minecraft:crying_obsidian,20)
RB(-9,7,-7,minecraft:obsidian,80,minecraft:crying_obsidian,20)
RB(-9,8,-7,minecraft:obsidian,80,minecraft:crying_obsidian,20)
RB(-9,9,-7,minecraft:obsidian,80,minecraft:crying_obsidian,20)
RB(-9,10,-7,minecraft:obsidian,80,minecraft:crying_obsidian,20)
RB(-9,11,-7,minecraft:obsidian,80,minecraft:crying_obsidian,20)
RB(-9,12,-7,minecraft:obsidian,80,minecraft:crying_obsidian,20)
RB(-9,13,-7,minecraft:obsidian,80,minecraft:crying_obsidian,20)
RB(-9,14,-7,minecraft:obsidian,80,minecraft:crying_obsidian,20)
RB(-9,15,-7,minecraft:obsidian,80,minecraft:crying_obsidian,20)
RB(-9,16,-7,minecraft:obsidian,80,minecraft:crying_obsidian,20)
RB(-9,17,-7,minecraft:obsidian,80,minecraft:crying_obsidian,20)
RB(-9,18,-7,minecraft:obsidian,80,minecraft:crying_obsidian,20)
RB(-9,19,-7,minecraft:obsidian,80,minecraft:crying_obsidian,20)
RB(-9,20,-7,minecraft:obsidian,80,minecraft:crying_obsidian,20)
RB(-9,21,-7,minecraft:obsidian,80,minecraft:crying_obsidian,20)
RB(-9,22,-7,minecraft:obsidian,80,minecraft:crying_obsidian,20)
RB(-9,23,-7,minecraft:obsidian,80,minecraft:crying_obsidian,20)
RB(-9,24,-7,minecraft:obsidian,80,minecraft:crying_obsidian,20)
RB(-9,25,-7,minecraft:obsidian,80,minecraft:crying_obsidian,20)
RB(-9,6,-6,minecraft:obsidian,80,minecraft:crying_obsidian,20)
RB(-9,7,-6,minecraft:obsidian,80,minecraft:crying_obsidian,20)
RB(-9,8,-6,minecraft:obsidian,80,minecraft:crying_obsidian,20)
RB(-9,9,-6,minecraft:obsidian,80,minecraft:crying_obsidian,20)
RB(-9,10,-6,minecraft:obsidian,80,minecraft:crying_obsidian,20)
RB(-9,11,-6,minecraft:obsidian,80,minecraft:crying_obsidian,20)
RB(-9,12,-6,minecraft:obsidian,80,minecraft:crying_obsidian,20)
RB(-9,13,-6,minecraft:obsidian,80,minecraft:crying_obsidian,20)
RB(-9,14,-6,minecraft:obsidian,80,minecraft:crying_obsidian,20)
RB(-9,15,-6,minecraft:obsidian,80,minecraft:crying_obsidian,20)
RB(-9,16,-6,minecraft:obsidian,80,minecraft:crying_obsidian,20)
RB(-9,17,-6,minecraft:obsidian,80,minecraft:crying_obsidian,20)
RB(-9,18,-6,minecraft:obsidian,80,minecraft:crying_obsidian,20)
RB(-9,19,-6,minecraft:obsidian,80,minecraft:crying_obsidian,20)
RB(-9,20,-6,minecraft:obsidian,80,minecraft:crying_obsidian,20)
RB(-9,21,-6,minecraft:obsidian,80,minecraft:crying_obsidian,20)
RB(-9,22,-6,minecraft:obsidian,80,minecraft:crying_obsidian,20)
RB(-9,23,-6,minecraft:obsidian,80,minecraft:crying_obsidian,20)
RB(-9,24,-6,minecraft:obsidian,80,minecraft:crying_obsidian,20)
RB(-9,25,-6,minecraft:obsidian,80,minecraft:crying_obsidian,20)
RB(-9,7,-5,minecraft:obsidian,80,minecraft:crying_obsidian,20)
RB(-9,8,-5,minecraft:obsidian,80,minecraft:crying_obsidian,20)
RB(-9,9,-5,minecraft:obsidian,80,minecraft:crying_obsidian,20)
RB(-9,10,-5,minecraft:obsidian,80,minecraft:crying_obsidian,20)
RB(-9,11,-5,minecraft:obsidian,80,minecraft:crying_obsidian,20)
RB(-9,12,-5,minecraft:obsidian,80,minecraft:crying_obsidian,20)
RB(-9,13,-5,minecraft:obsidian,80,minecraft:crying_obsidian,20)
RB(-9,14,-5,minecraft:obsidian,80,minecraft:crying_obsidian,20)
RB(-9,15,-5,minecraft:obsidian,80,minecraft:crying_obsidian,20)
RB(-9,16,-5,minecraft:obsidian,80,minecraft:crying_obsidian,20)
RB(-9,17,-5,minecraft:obsidian,80,minecraft:crying_obsidian,20)
RB(-9,18,-5,minecraft:obsidian,80,minecraft:crying_obsidian,20)
RB(-9,19,-5,minecraft:obsidian,80,minecraft:crying_obsidian,20)
RB(-9,20,-5,minecraft:obsidian,80,minecraft:crying_obsidian,20)
RB(-9,21,-5,minecraft:obsidian,80,minecraft:crying_obsidian,20)
RB(-9,22,-5,minecraft:obsidian,80,minecraft:crying_obsidian,20)
RB(-9,23,-5,minecraft:obsidian,80,minecraft:crying_obsidian,20)
RB(-9,24,-5,minecraft:obsidian,80,minecraft:crying_obsidian,20)
RB(-9,25,-5,minecraft:obsidian,80,minecraft:crying_obsidian,20)
RB(-9,9,-4,minecraft:obsidian,80,minecraft:crying_obsidian,20)
RB(-9,10,-4,minecraft:obsidian,80,minecraft:crying_obsidian,20)
RB(-9,11,-4,minecraft:obsidian,80,minecraft:crying_obsidian,20)
RB(-9,12,-4,minecraft:obsidian,80,minecraft:crying_obsidian,20)
RB(-9,13,-4,minecraft:obsidian,80,minecraft:crying_obsidian,20)
RB(-9,14,-4,minecraft:obsidian,80,minecraft:crying_obsidian,20)
RB(-9,15,-4,minecraft:obsidian,80,minecraft:crying_obsidian,20)
RB(-9,16,-4,minecraft:obsidian,80,minecraft:crying_obsidian,20)
RB(-9,17,-4,minecraft:obsidian,80,minecraft:crying_obsidian,20)
RB(-9,18,-4,minecraft:obsidian,80,minecraft:crying_obsidian,20)
RB(-9,19,-4,minecraft:obsidian,80,minecraft:crying_obsidian,20)
RB(-9,20,-4,minecraft:obsidian,80,minecraft:crying_obsidian,20)
RB(-9,21,-4,minecraft:obsidian,80,minecraft:crying_obsidian,20)
RB(-9,22,-4,minecraft:obsidian,80,minecraft:crying_obsidian,20)
RB(-9,23,-4,minecraft:obsidian,80,minecraft:crying_obsidian,20)
RB(-9,9,-3,minecraft:obsidian,80,minecraft:crying_obsidian,20)
RB(-9,10,-3,minecraft:obsidian,80,minecraft:crying_obsidian,20)
RB(-9,11,-3,minecraft:obsidian,80,minecraft:crying_obsidian,20)
RB(-9,12,-3,minecraft:obsidian,80,minecraft:crying_obsidian,20)
RB(-9,13,-3,minecraft:obsidian,80,minecraft:crying_obsidian,20)
RB(-9,14,-3,minecraft:obsidian,80,minecraft:crying_obsidian,20)
RB(-9,15,-3,minecraft:obsidian,80,minecraft:crying_obsidian,20)
RB(-9,16,-3,minecraft:obsidian,80,minecraft:crying_obsidian,20)
RB(-9,17,-3,minecraft:obsidian,80,minecraft:crying_obsidian,20)
RB(-9,18,-3,minecraft:obsidian,80,minecraft:crying_obsidian,20)
RB(-9,19,-3,minecraft:obsidian,80,minecraft:crying_obsidian,20)
RB(-9,20,-3,minecraft:obsidian,80,minecraft:crying_obsidian,20)
RB(-9,21,-3,minecraft:obsidian,80,minecraft:crying_obsidian,20)
RB(-9,22,-3,minecraft:obsidian,80,minecraft:crying_obsidian,20)
RB(-9,9,-2,minecraft:obsidian,80,minecraft:crying_obsidian,20)
RB(-9,10,-2,minecraft:obsidian,80,minecraft:crying_obsidian,20)
RB(-9,11,-2,minecraft:obsidian,80,minecraft:crying_obsidian,20)
RB(-9,12,-2,minecraft:obsidian,80,minecraft:crying_obsidian,20)
RB(-9,13,-2,minecraft:obsidian,80,minecraft:crying_obsidian,20)
RB(-9,14,-2,minecraft:obsidian,80,minecraft:crying_obsidian,20)
RB(-9,15,-2,minecraft:obsidian,80,minecraft:crying_obsidian,20)
RB(-9,16,-2,minecraft:obsidian,80,minecraft:crying_obsidian,20)
RB(-9,17,-2,minecraft:obsidian,80,minecraft:crying_obsidian,20)
RB(-9,9,-1,minecraft:obsidian,80,minecraft:crying_obsidian,20)
RB(-9,10,-1,minecraft:obsidian,80,minecraft:crying_obsidian,20)
RB(-9,11,-1,minecraft:obsidian,80,minecraft:crying_obsidian,20)
RB(-9,12,-1,minecraft:obsidian,80,minecraft:crying_obsidian,20)
RB(-9,13,-1,minecraft:obsidian,80,minecraft:crying_obsidian,20)
RB(-9,14,-1,minecraft:obsidian,80,minecraft:crying_obsidian,20)
RB(-9,15,-1,minecraft:obsidian,80,minecraft:crying_obsidian,20)
RB(-9,16,-1,minecraft:obsidian,80,minecraft:crying_obsidian,20)
RB(-9,17,-1,minecraft:obsidian,80,minecraft:crying_obsidian,20)
RB(-9,10,0,minecraft:obsidian,80,minecraft:crying_obsidian,20)
RB(-9,11,0,minecraft:obsidian,80,minecraft:crying_obsidian,20)
RB(-9,12,0,minecraft:obsidian,80,minecraft:crying_obsidian,20)
RB(-9,13,0,minecraft:obsidian,80,minecraft:crying_obsidian,20)
RB(-9,14,0,minecraft:obsidian,80,minecraft:crying_obsidian,20)
RB(-9,15,0,minecraft:obsidian,80,minecraft:crying_obsidian,20)
RB(-9,16,0,minecraft:obsidian,80,minecraft:crying_obsidian,20)
RB(-9,17,0,minecraft:obsidian,80,minecraft:crying_obsidian,20)
RB(-9,11,1,minecraft:obsidian,80,minecraft:crying_obsidian,20)
RB(-9,12,1,minecraft:obsidian,80,minecraft:crying_obsidian,20)
RB(-9,13,1,minecraft:obsidian,80,minecraft:crying_obsidian,20)
RB(-9,14,1,minecraft:obsidian,80,minecraft:crying_obsidian,20)
RB(-9,15,1,minecraft:obsidian,80,minecraft:crying_obsidian,20)
RB(-9,16,1,minecraft:obsidian,80,minecraft:crying_obsidian,20)
RB(-9,17,1,minecraft:obsidian,80,minecraft:crying_obsidian,20)
RB(-9,18,1,minecraft:obsidian,80,minecraft:crying_obsidian,20)
RB(-9,11,2,minecraft:obsidian,80,minecraft:crying_obsidian,20)
RB(-9,12,2,minecraft:obsidian,80,minecraft:crying_obsidian,20)
RB(-9,13,2,minecraft:obsidian,80,minecraft:crying_obsidian,20)
RB(-9,14,2,minecraft:obsidian,80,minecraft:crying_obsidian,20)
RB(-9,15,2,minecraft:obsidian,80,minecraft:crying_obsidian,20)
RB(-9,16,2,minecraft:obsidian,80,minecraft:crying_obsidian,20)
RB(-9,17,2,minecraft:obsidian,80,minecraft:crying_obsidian,20)
RB(-9,18,2,minecraft:obsidian,80,minecraft:crying_obsidian,20)
RB(-9,19,2,minecraft:obsidian,80,minecraft:crying_obsidian,20)
RB(-9,10,3,minecraft:obsidian,80,minecraft:crying_obsidian,20)
RB(-9,11,3,minecraft:obsidian,80,minecraft:crying_obsidian,20)
RB(-9,12,3,minecraft:obsidian,80,minecraft:crying_obsidian,20)
RB(-9,13,3,minecraft:obsidian,80,minecraft:crying_obsidian,20)
RB(-9,14,3,minecraft:obsidian,80,minecraft:crying_obsidian,20)
RB(-9,15,3,minecraft:obsidian,80,minecraft:crying_obsidian,20)
RB(-9,16,3,minecraft:obsidian,80,minecraft:crying_obsidian,20)
RB(-9,17,3,minecraft:obsidian,80,minecraft:crying_obsidian,20)
RB(-9,18,3,minecraft:obsidian,80,minecraft:crying_obsidian,20)
RB(-9,19,3,minecraft:obsidian,80,minecraft:crying_obsidian,20)
RB(-9,10,4,minecraft:obsidian,80,minecraft:crying_obsidian,20)
RB(-9,11,4,minecraft:obsidian,80,minecraft:crying_obsidian,20)
RB(-9,12,4,minecraft:obsidian,80,minecraft:crying_obsidian,20)
RB(-9,13,4,minecraft:obsidian,80,minecraft:crying_obsidian,20)
RB(-9,14,4,minecraft:obsidian,80,minecraft:crying_obsidian,20)
RB(-9,15,4,minecraft:obsidian,80,minecraft:crying_obsidian,20)
RB(-9,16,4,minecraft:obsidian,80,minecraft:crying_obsidian,20)
RB(-9,17,4,minecraft:obsidian,80,minecraft:crying_obsidian,20)
RB(-9,18,4,minecraft:obsidian,80,minecraft:crying_obsidian,20)
RB(-9,19,4,minecraft:obsidian,80,minecraft:crying_obsidian,20)
RB(-9,10,5,minecraft:obsidian,80,minecraft:crying_obsidian,20)
RB(-9,11,5,minecraft:obsidian,80,minecraft:crying_obsidian,20)
RB(-9,12,5,minecraft:obsidian,80,minecraft:crying_obsidian,20)
RB(-9,13,5,minecraft:obsidian,80,minecraft:crying_obsidian,20)
RB(-9,14,5,minecraft:obsidian,80,minecraft:crying_obsidian,20)
RB(-9,15,5,minecraft:obsidian,80,minecraft:crying_obsidian,20)
RB(-9,16,5,minecraft:obsidian,80,minecraft:crying_obsidian,20)
RB(-9,17,5,minecraft:obsidian,80,minecraft:crying_obsidian,20)
RB(-9,18,5,minecraft:obsidian,80,minecraft:crying_obsidian,20)
RB(-9,19,5,minecraft:obsidian,80,minecraft:crying_obsidian,20)
RB(-9,10,6,minecraft:obsidian,80,minecraft:crying_obsidian,20)
RB(-9,11,6,minecraft:obsidian,80,minecraft:crying_obsidian,20)
RB(-9,12,6,minecraft:obsidian,80,minecraft:crying_obsidian,20)
RB(-9,13,6,minecraft:obsidian,80,minecraft:crying_obsidian,20)
RB(-9,14,6,minecraft:obsidian,80,minecraft:crying_obsidian,20)
RB(-9,15,6,minecraft:obsidian,80,minecraft:crying_obsidian,20)
RB(-9,16,6,minecraft:obsidian,80,minecraft:crying_obsidian,20)
RB(-9,17,6,minecraft:obsidian,80,minecraft:crying_obsidian,20)
RB(-9,18,6,minecraft:obsidian,80,minecraft:crying_obsidian,20)
RB(-9,19,6,minecraft:obsidian,80,minecraft:crying_obsidian,20)
RB(-9,10,7,minecraft:obsidian,80,minecraft:crying_obsidian,20)
RB(-9,11,7,minecraft:obsidian,80,minecraft:crying_obsidian,20)
RB(-9,12,7,minecraft:obsidian,80,minecraft:crying_obsidian,20)
RB(-9,13,7,minecraft:obsidian,80,minecraft:crying_obsidian,20)
RB(-9,14,7,minecraft:obsidian,80,minecraft:crying_obsidian,20)
RB(-9,15,7,minecraft:obsidian,80,minecraft:crying_obsidian,20)
RB(-9,16,7,minecraft:obsidian,80,minecraft:crying_obsidian,20)
RB(-9,17,7,minecraft:obsidian,80,minecraft:crying_obsidian,20)
RB(-9,18,7,minecraft:obsidian,80,minecraft:crying_obsidian,20)
RB(-9,10,8,minecraft:obsidian,80,minecraft:crying_obsidian,20)
RB(-9,11,8,minecraft:obsidian,80,minecraft:crying_obsidian,20)
RB(-9,12,8,minecraft:obsidian,80,minecraft:crying_obsidian,20)
RB(-9,13,8,minecraft:obsidian,80,minecraft:crying_obsidian,20)
RB(-9,14,8,minecraft:obsidian,80,minecraft:crying_obsidian,20)
RB(-9,15,8,minecraft:obsidian,80,minecraft:crying_obsidian,20)
RB(-9,16,8,minecraft:obsidian,80,minecraft:crying_obsidian,20)
RB(-9,17,8,minecraft:obsidian,80,minecraft:crying_obsidian,20)
RB(-9,18,8,minecraft:obsidian,80,minecraft:crying_obsidian,20)
RB(-9,9,9,minecraft:obsidian,80,minecraft:crying_obsidian,20)
RB(-9,10,9,minecraft:obsidian,80,minecraft:crying_obsidian,20)
RB(-9,11,9,minecraft:obsidian,80,minecraft:crying_obsidian,20)
RB(-9,12,9,minecraft:obsidian,80,minecraft:crying_obsidian,20)
RB(-9,13,9,minecraft:obsidian,80,minecraft:crying_obsidian,20)
RB(-9,14,9,minecraft:obsidian,80,minecraft:crying_obsidian,20)
RB(-9,15,9,minecraft:obsidian,80,minecraft:crying_obsidian,20)
RB(-9,16,9,minecraft:obsidian,80,minecraft:crying_obsidian,20)
RB(-9,17,9,minecraft:obsidian,80,minecraft:crying_obsidian,20)
RB(-9,18,9,minecraft:obsidian,80,minecraft:crying_obsidian,20)
RB(-9,19,9,minecraft:obsidian,80,minecraft:crying_obsidian,20)
RB(-9,9,10,minecraft:obsidian,80,minecraft:crying_obsidian,20)
RB(-9,10,10,minecraft:obsidian,80,minecraft:crying_obsidian,20)
RB(-9,11,10,minecraft:obsidian,80,minecraft:crying_obsidian,20)
RB(-9,12,10,minecraft:obsidian,80,minecraft:crying_obsidian,20)
RB(-9,13,10,minecraft:obsidian,80,minecraft:crying_obsidian,20)
RB(-9,14,10,minecraft:obsidian,80,minecraft:crying_obsidian,20)
RB(-9,15,10,minecraft:obsidian,80,minecraft:crying_obsidian,20)
RB(-9,16,10,minecraft:obsidian,80,minecraft:crying_obsidian,20)
RB(-9,17,10,minecraft:obsidian,80,minecraft:crying_obsidian,20)
RB(-9,18,10,minecraft:obsidian,80,minecraft:crying_obsidian,20)
RB(-9,19,10,minecraft:obsidian,80,minecraft:crying_obsidian,20)
RB(-9,9,11,minecraft:obsidian,80,minecraft:crying_obsidian,20)
RB(-9,10,11,minecraft:obsidian,80,minecraft:crying_obsidian,20)
RB(-9,11,11,minecraft:obsidian,80,minecraft:crying_obsidian,20)
RB(-9,12,11,minecraft:obsidian,80,minecraft:crying_obsidian,20)
RB(-9,13,11,minecraft:obsidian,80,minecraft:crying_obsidian,20)
RB(-9,14,11,minecraft:obsidian,80,minecraft:crying_obsidian,20)
RB(-9,15,11,minecraft:obsidian,80,minecraft:crying_obsidian,20)
RB(-9,16,11,minecraft:obsidian,80,minecraft:crying_obsidian,20)
RB(-9,17,11,minecraft:obsidian,80,minecraft:crying_obsidian,20)
RB(-9,18,11,minecraft:obsidian,80,minecraft:crying_obsidian,20)
RB(-9,19,11,minecraft:obsidian,80,minecraft:crying_obsidian,20)
RB(-9,9,12,minecraft:obsidian,80,minecraft:crying_obsidian,20)
RB(-9,10,12,minecraft:obsidian,80,minecraft:crying_obsidian,20)
RB(-9,11,12,minecraft:obsidian,80,minecraft:crying_obsidian,20)
RB(-9,12,12,minecraft:obsidian,80,minecraft:crying_obsidian,20)
RB(-9,13,12,minecraft:obsidian,80,minecraft:crying_obsidian,20)
RB(-9,14,12,minecraft:obsidian,80,minecraft:crying_obsidian,20)
RB(-9,15,12,minecraft:obsidian,80,minecraft:crying_obsidian,20)
RB(-9,16,12,minecraft:obsidian,80,minecraft:crying_obsidian,20)
RB(-9,17,12,minecraft:obsidian,80,minecraft:crying_obsidian,20)
RB(-9,18,12,minecraft:obsidian,80,minecraft:crying_obsidian,20)
RB(-9,19,12,minecraft:obsidian,80,minecraft:crying_obsidian,20)
RB(-9,20,12,minecraft:obsidian,80,minecraft:crying_obsidian,20)
RB(-9,21,12,minecraft:obsidian,80,minecraft:crying_obsidian,20)
RB(-9,9,13,minecraft:obsidian,80,minecraft:crying_obsidian,20)
RB(-9,10,13,minecraft:obsidian,80,minecraft:crying_obsidian,20)
RB(-9,11,13,minecraft:obsidian,80,minecraft:crying_obsidian,20)
RB(-9,12,13,minecraft:obsidian,80,minecraft:crying_obsidian,20)
RB(-9,13,13,minecraft:obsidian,80,minecraft:crying_obsidian,20)
RB(-9,14,13,minecraft:obsidian,80,minecraft:crying_obsidian,20)
RB(-9,15,13,minecraft:obsidian,80,minecraft:crying_obsidian,20)
RB(-9,16,13,minecraft:obsidian,80,minecraft:crying_obsidian,20)
RB(-9,17,13,minecraft:obsidian,80,minecraft:crying_obsidian,20)
RB(-9,18,13,minecraft:obsidian,80,minecraft:crying_obsidian,20)
RB(-9,19,13,minecraft:obsidian,80,minecraft:crying_obsidian,20)
RB(-9,20,13,minecraft:obsidian,80,minecraft:crying_obsidian,20)
RB(-9,21,13,minecraft:obsidian,80,minecraft:crying_obsidian,20)
RB(-9,10,14,minecraft:obsidian,80,minecraft:crying_obsidian,20)
RB(-9,11,14,minecraft:obsidian,80,minecraft:crying_obsidian,20)
RB(-9,12,14,minecraft:obsidian,80,minecraft:crying_obsidian,20)
RB(-9,13,14,minecraft:obsidian,80,minecraft:crying_obsidian,20)
RB(-9,14,14,minecraft:obsidian,80,minecraft:crying_obsidian,20)
RB(-9,15,14,minecraft:obsidian,80,minecraft:crying_obsidian,20)
RB(-9,16,14,minecraft:obsidian,80,minecraft:crying_obsidian,20)
RB(-9,17,14,minecraft:obsidian,80,minecraft:crying_obsidian,20)
RB(-9,18,14,minecraft:obsidian,80,minecraft:crying_obsidian,20)
RB(-9,19,14,minecraft:obsidian,80,minecraft:crying_obsidian,20)
RB(-9,20,14,minecraft:obsidian,80,minecraft:crying_obsidian,20)
RB(-9,21,14,minecraft:obsidian,80,minecraft:crying_obsidian,20)
RB(-9,22,14,minecraft:obsidian,80,minecraft:crying_obsidian,20)
RB(-9,11,15,minecraft:obsidian,80,minecraft:crying_obsidian,20)
RB(-9,12,15,minecraft:obsidian,80,minecraft:crying_obsidian,20)
RB(-9,13,15,minecraft:obsidian,80,minecraft:crying_obsidian,20)
RB(-9,14,15,minecraft:obsidian,80,minecraft:crying_obsidian,20)
RB(-9,15,15,minecraft:obsidian,80,minecraft:crying_obsidian,20)
RB(-9,16,15,minecraft:obsidian,80,minecraft:crying_obsidian,20)
RB(-9,17,15,minecraft:obsidian,80,minecraft:crying_obsidian,20)
RB(-9,18,15,minecraft:obsidian,80,minecraft:crying_obsidian,20)
RB(-9,19,15,minecraft:obsidian,80,minecraft:crying_obsidian,20)
