#######################################################################
# +-----------------------------------------------------------------+ #
# |                            BO3 object                           | #
# +-----------------------------------------------------------------+ #
#######################################################################

Author: Frank

Description: Floating bit of obsidian - Modified by Bo3BulkEdit

Version: 3

SettingsMode: WriteDisable

#######################################################################
# +-----------------------------------------------------------------+ #
# |                          Main settings                          | #
# +-----------------------------------------------------------------+ #
#######################################################################

IsOTGPlus: false
Tree: true
Frequency: 2
Rarity: 10.0
RotateRandomly: true
SpawnHeight: randomY
SpawnHeightOffset: 0
SpawnHeightVariance: 0
MaxBranchDepth: 10
ExcludedBiomes: All

ExtrudeMode: None
ExtrudeThroughBlocks: minecraft:air

##############################
# Height Limits for the BO3. #
##############################

MinHeight: 90
MaxHeight: 120

#######################################################################
# +-----------------------------------------------------------------+ #
# |                      Source block settings                      | #
# +-----------------------------------------------------------------+ #
#######################################################################

SourceBlocks: AIR
MaxPercentageOutsideSourceBlock: 0
OutsideSourceBlock: placeAnyway

RemoveAir: true
ReplaceBelow: OBSIDIAN
ReplaceWithBiomeBlocks: false
ReplaceWithGroundBlock: OBSIDIAN
ReplaceWithSurfaceBlock: OBSIDIAN
ReplaceWithStoneBlock: OBSIDIAN
SmoothRadius: 30
SmoothingSurfaceBlock: OBSIDIAN
SmoothingGroundBlock: OBSIDIAN
DoReplaceBlocks: true

#######################################################################
# +-----------------------------------------------------------------+ #
# |                              Blocks                             | #
# +-----------------------------------------------------------------+ #
#######################################################################

RB(-10,13,4,minecraft:crying_obsidian,20,minecraft:obsidian,100)
RB(-10,14,4,minecraft:crying_obsidian,20,minecraft:obsidian,100)
RB(-10,15,4,minecraft:crying_obsidian,20,minecraft:obsidian,100)
RB(-10,16,4,minecraft:crying_obsidian,20,minecraft:obsidian,100)
RB(-10,17,4,minecraft:crying_obsidian,20,minecraft:obsidian,100)
RB(-10,18,4,minecraft:crying_obsidian,20,minecraft:obsidian,100)
RB(-10,12,5,minecraft:crying_obsidian,20,minecraft:obsidian,100)
RB(-10,13,5,minecraft:crying_obsidian,20,minecraft:obsidian,100)
RB(-10,14,5,minecraft:crying_obsidian,20,minecraft:obsidian,100)
RB(-10,15,5,minecraft:crying_obsidian,20,minecraft:obsidian,100)
RB(-10,16,5,minecraft:crying_obsidian,20,minecraft:obsidian,100)
RB(-10,17,5,minecraft:crying_obsidian,20,minecraft:obsidian,100)
RB(-10,18,5,minecraft:crying_obsidian,20,minecraft:obsidian,100)
RB(-10,19,5,minecraft:crying_obsidian,20,minecraft:obsidian,100)
RB(-10,20,5,minecraft:crying_obsidian,20,minecraft:obsidian,100)
RB(-10,12,6,minecraft:crying_obsidian,20,minecraft:obsidian,100)
RB(-10,13,6,minecraft:crying_obsidian,20,minecraft:obsidian,100)
RB(-10,14,6,minecraft:crying_obsidian,20,minecraft:obsidian,100)
RB(-10,15,6,minecraft:crying_obsidian,20,minecraft:obsidian,100)
RB(-10,16,6,minecraft:crying_obsidian,20,minecraft:obsidian,100)
RB(-10,17,6,minecraft:crying_obsidian,20,minecraft:obsidian,100)
RB(-10,18,6,minecraft:crying_obsidian,20,minecraft:obsidian,100)
RB(-10,19,6,minecraft:crying_obsidian,20,minecraft:obsidian,100)
RB(-10,20,6,minecraft:crying_obsidian,20,minecraft:obsidian,100)
RB(-10,12,7,minecraft:crying_obsidian,20,minecraft:obsidian,100)
RB(-10,13,7,minecraft:crying_obsidian,20,minecraft:obsidian,100)
RB(-10,14,7,minecraft:crying_obsidian,20,minecraft:obsidian,100)
RB(-10,15,7,minecraft:crying_obsidian,20,minecraft:obsidian,100)
RB(-10,16,7,minecraft:crying_obsidian,20,minecraft:obsidian,100)
RB(-10,17,7,minecraft:crying_obsidian,20,minecraft:obsidian,100)
RB(-10,18,7,minecraft:crying_obsidian,20,minecraft:obsidian,100)
RB(-10,19,7,minecraft:crying_obsidian,20,minecraft:obsidian,100)
RB(-10,20,7,minecraft:crying_obsidian,20,minecraft:obsidian,100)
RB(-10,13,8,minecraft:crying_obsidian,20,minecraft:obsidian,100)
RB(-10,14,8,minecraft:crying_obsidian,20,minecraft:obsidian,100)
RB(-10,15,8,minecraft:crying_obsidian,20,minecraft:obsidian,100)
RB(-10,16,8,minecraft:crying_obsidian,20,minecraft:obsidian,100)
RB(-10,17,8,minecraft:crying_obsidian,20,minecraft:obsidian,100)
RB(-10,18,8,minecraft:crying_obsidian,20,minecraft:obsidian,100)
RB(-10,19,8,minecraft:crying_obsidian,20,minecraft:obsidian,100)
RB(-10,20,8,minecraft:crying_obsidian,20,minecraft:obsidian,100)
RB(-9,12,3,minecraft:crying_obsidian,20,minecraft:obsidian,100)
RB(-9,13,3,minecraft:crying_obsidian,20,minecraft:obsidian,100)
RB(-9,14,3,minecraft:crying_obsidian,20,minecraft:obsidian,100)
RB(-9,15,3,minecraft:crying_obsidian,20,minecraft:obsidian,100)
RB(-9,16,3,minecraft:crying_obsidian,20,minecraft:obsidian,100)
RB(-9,17,3,minecraft:crying_obsidian,20,minecraft:obsidian,100)
RB(-9,18,3,minecraft:crying_obsidian,20,minecraft:obsidian,100)
RB(-9,13,4,minecraft:crying_obsidian,20,minecraft:obsidian,100)
RB(-9,14,4,minecraft:crying_obsidian,20,minecraft:obsidian,100)
RB(-9,15,4,minecraft:crying_obsidian,20,minecraft:obsidian,100)
RB(-9,16,4,minecraft:crying_obsidian,20,minecraft:obsidian,100)
RB(-9,17,4,minecraft:crying_obsidian,20,minecraft:obsidian,100)
RB(-9,18,4,minecraft:crying_obsidian,20,minecraft:obsidian,100)
RB(-9,19,4,minecraft:crying_obsidian,20,minecraft:obsidian,100)
RB(-9,20,4,minecraft:crying_obsidian,20,minecraft:obsidian,100)
RB(-9,13,5,minecraft:crying_obsidian,20,minecraft:obsidian,100)
RB(-9,14,5,minecraft:crying_obsidian,20,minecraft:obsidian,100)
RB(-9,15,5,minecraft:crying_obsidian,20,minecraft:obsidian,100)
RB(-9,16,5,minecraft:crying_obsidian,20,minecraft:obsidian,100)
RB(-9,17,5,minecraft:crying_obsidian,20,minecraft:obsidian,100)
RB(-9,18,5,minecraft:crying_obsidian,20,minecraft:obsidian,100)
RB(-9,19,5,minecraft:crying_obsidian,20,minecraft:obsidian,100)
RB(-9,20,5,minecraft:crying_obsidian,20,minecraft:obsidian,100)
RB(-9,13,6,minecraft:crying_obsidian,20,minecraft:obsidian,100)
RB(-9,14,6,minecraft:crying_obsidian,20,minecraft:obsidian,100)
RB(-9,15,6,minecraft:crying_obsidian,20,minecraft:obsidian,100)
RB(-9,16,6,minecraft:crying_obsidian,20,minecraft:obsidian,100)
RB(-9,17,6,minecraft:crying_obsidian,20,minecraft:obsidian,100)
RB(-9,18,6,minecraft:crying_obsidian,20,minecraft:obsidian,100)
RB(-9,19,6,minecraft:crying_obsidian,20,minecraft:obsidian,100)
RB(-9,20,6,minecraft:crying_obsidian,20,minecraft:obsidian,100)
RB(-9,21,6,minecraft:crying_obsidian,20,minecraft:obsidian,100)
RB(-9,13,7,minecraft:crying_obsidian,20,minecraft:obsidian,100)
RB(-9,14,7,minecraft:crying_obsidian,20,minecraft:obsidian,100)
RB(-9,15,7,minecraft:crying_obsidian,20,minecraft:obsidian,100)
RB(-9,16,7,minecraft:crying_obsidian,20,minecraft:obsidian,100)
RB(-9,17,7,minecraft:crying_obsidian,20,minecraft:obsidian,100)
RB(-9,18,7,minecraft:crying_obsidian,20,minecraft:obsidian,100)
RB(-9,19,7,minecraft:crying_obsidian,20,minecraft:obsidian,100)
RB(-9,20,7,minecraft:crying_obsidian,20,minecraft:obsidian,100)
RB(-9,21,7,minecraft:crying_obsidian,20,minecraft:obsidian,100)
RB(-9,13,8,minecraft:crying_obsidian,20,minecraft:obsidian,100)
RB(-9,14,8,minecraft:crying_obsidian,20,minecraft:obsidian,100)
RB(-9,15,8,minecraft:crying_obsidian,20,minecraft:obsidian,100)
RB(-9,16,8,minecraft:crying_obsidian,20,minecraft:obsidian,100)
RB(-9,17,8,minecraft:crying_obsidian,20,minecraft:obsidian,100)
RB(-9,18,8,minecraft:crying_obsidian,20,minecraft:obsidian,100)
RB(-9,19,8,minecraft:crying_obsidian,20,minecraft:obsidian,100)
RB(-9,20,8,minecraft:crying_obsidian,20,minecraft:obsidian,100)
RB(-9,21,8,minecraft:crying_obsidian,20,minecraft:obsidian,100)
RB(-9,12,9,minecraft:crying_obsidian,20,minecraft:obsidian,100)
RB(-9,13,9,minecraft:crying_obsidian,20,minecraft:obsidian,100)
RB(-9,14,9,minecraft:crying_obsidian,20,minecraft:obsidian,100)
RB(-9,15,9,minecraft:crying_obsidian,20,minecraft:obsidian,100)
RB(-9,16,9,minecraft:crying_obsidian,20,minecraft:obsidian,100)
RB(-9,17,9,minecraft:crying_obsidian,20,minecraft:obsidian,100)
RB(-9,18,9,minecraft:crying_obsidian,20,minecraft:obsidian,100)
RB(-9,19,9,minecraft:crying_obsidian,20,minecraft:obsidian,100)
RB(-9,20,9,minecraft:crying_obsidian,20,minecraft:obsidian,100)
RB(-9,21,9,minecraft:crying_obsidian,20,minecraft:obsidian,100)
RB(-8,13,2,minecraft:crying_obsidian,20,minecraft:obsidian,100)
RB(-8,14,2,minecraft:crying_obsidian,20,minecraft:obsidian,100)
RB(-8,15,2,minecraft:crying_obsidian,20,minecraft:obsidian,100)
RB(-8,16,2,minecraft:crying_obsidian,20,minecraft:obsidian,100)
RB(-8,13,3,minecraft:crying_obsidian,20,minecraft:obsidian,100)
RB(-8,14,3,minecraft:crying_obsidian,20,minecraft:obsidian,100)
RB(-8,15,3,minecraft:crying_obsidian,20,minecraft:obsidian,100)
RB(-8,16,3,minecraft:crying_obsidian,20,minecraft:obsidian,100)
RB(-8,17,3,minecraft:crying_obsidian,20,minecraft:obsidian,100)
RB(-8,18,3,minecraft:crying_obsidian,20,minecraft:obsidian,100)
RB(-8,13,4,minecraft:crying_obsidian,20,minecraft:obsidian,100)
RB(-8,14,4,minecraft:crying_obsidian,20,minecraft:obsidian,100)
RB(-8,15,4,minecraft:crying_obsidian,20,minecraft:obsidian,100)
RB(-8,16,4,minecraft:crying_obsidian,20,minecraft:obsidian,100)
RB(-8,17,4,minecraft:crying_obsidian,20,minecraft:obsidian,100)
RB(-8,18,4,minecraft:crying_obsidian,20,minecraft:obsidian,100)
RB(-8,19,4,minecraft:crying_obsidian,20,minecraft:obsidian,100)
RB(-8,20,4,minecraft:crying_obsidian,20,minecraft:obsidian,100)
RB(-8,12,5,minecraft:crying_obsidian,20,minecraft:obsidian,100)
RB(-8,13,5,minecraft:crying_obsidian,20,minecraft:obsidian,100)
RB(-8,14,5,minecraft:crying_obsidian,20,minecraft:obsidian,100)
RB(-8,15,5,minecraft:crying_obsidian,20,minecraft:obsidian,100)
RB(-8,16,5,minecraft:crying_obsidian,20,minecraft:obsidian,100)
RB(-8,17,5,minecraft:crying_obsidian,20,minecraft:obsidian,100)
RB(-8,18,5,minecraft:crying_obsidian,20,minecraft:obsidian,100)
RB(-8,19,5,minecraft:crying_obsidian,20,minecraft:obsidian,100)
RB(-8,20,5,minecraft:crying_obsidian,20,minecraft:obsidian,100)
RB(-8,12,6,minecraft:crying_obsidian,20,minecraft:obsidian,100)
RB(-8,13,6,minecraft:crying_obsidian,20,minecraft:obsidian,100)
RB(-8,14,6,minecraft:crying_obsidian,20,minecraft:obsidian,100)
RB(-8,15,6,minecraft:crying_obsidian,20,minecraft:obsidian,100)
RB(-8,16,6,minecraft:crying_obsidian,20,minecraft:obsidian,100)
RB(-8,17,6,minecraft:crying_obsidian,20,minecraft:obsidian,100)
RB(-8,18,6,minecraft:crying_obsidian,20,minecraft:obsidian,100)
RB(-8,19,6,minecraft:crying_obsidian,20,minecraft:obsidian,100)
RB(-8,20,6,minecraft:crying_obsidian,20,minecraft:obsidian,100)
RB(-8,21,6,minecraft:crying_obsidian,20,minecraft:obsidian,100)
RB(-8,12,7,minecraft:crying_obsidian,20,minecraft:obsidian,100)
RB(-8,13,7,minecraft:crying_obsidian,20,minecraft:obsidian,100)
RB(-8,14,7,minecraft:crying_obsidian,20,minecraft:obsidian,100)
RB(-8,15,7,minecraft:crying_obsidian,20,minecraft:obsidian,100)
RB(-8,16,7,minecraft:crying_obsidian,20,minecraft:obsidian,100)
RB(-8,17,7,minecraft:crying_obsidian,20,minecraft:obsidian,100)
RB(-8,18,7,minecraft:crying_obsidian,20,minecraft:obsidian,100)
RB(-8,19,7,minecraft:crying_obsidian,20,minecraft:obsidian,100)
RB(-8,20,7,minecraft:crying_obsidian,20,minecraft:obsidian,100)
RB(-8,21,7,minecraft:crying_obsidian,20,minecraft:obsidian,100)
RB(-8,12,8,minecraft:crying_obsidian,20,minecraft:obsidian,100)
RB(-8,13,8,minecraft:crying_obsidian,20,minecraft:obsidian,100)
RB(-8,14,8,minecraft:crying_obsidian,20,minecraft:obsidian,100)
RB(-8,15,8,minecraft:crying_obsidian,20,minecraft:obsidian,100)
RB(-8,16,8,minecraft:crying_obsidian,20,minecraft:obsidian,100)
RB(-8,17,8,minecraft:crying_obsidian,20,minecraft:obsidian,100)
RB(-8,18,8,minecraft:crying_obsidian,20,minecraft:obsidian,100)
RB(-8,19,8,minecraft:crying_obsidian,20,minecraft:obsidian,100)
RB(-8,20,8,minecraft:crying_obsidian,20,minecraft:obsidian,100)
RB(-8,21,8,minecraft:crying_obsidian,20,minecraft:obsidian,100)
RB(-8,12,9,minecraft:crying_obsidian,20,minecraft:obsidian,100)
RB(-8,13,9,minecraft:crying_obsidian,20,minecraft:obsidian,100)
RB(-8,14,9,minecraft:crying_obsidian,20,minecraft:obsidian,100)
RB(-8,15,9,minecraft:crying_obsidian,20,minecraft:obsidian,100)
RB(-8,16,9,minecraft:crying_obsidian,20,minecraft:obsidian,100)
RB(-8,17,9,minecraft:crying_obsidian,20,minecraft:obsidian,100)
RB(-8,18,9,minecraft:crying_obsidian,20,minecraft:obsidian,100)
RB(-8,19,9,minecraft:crying_obsidian,20,minecraft:obsidian,100)
RB(-8,20,9,minecraft:crying_obsidian,20,minecraft:obsidian,100)
RB(-8,21,9,minecraft:crying_obsidian,20,minecraft:obsidian,100)
RB(-8,12,10,minecraft:crying_obsidian,20,minecraft:obsidian,100)
RB(-8,13,10,minecraft:crying_obsidian,20,minecraft:obsidian,100)
RB(-8,14,10,minecraft:crying_obsidian,20,minecraft:obsidian,100)
RB(-8,15,10,minecraft:crying_obsidian,20,minecraft:obsidian,100)
RB(-8,16,10,minecraft:crying_obsidian,20,minecraft:obsidian,100)
RB(-8,17,10,minecraft:crying_obsidian,20,minecraft:obsidian,100)
RB(-8,18,10,minecraft:crying_obsidian,20,minecraft:obsidian,100)
RB(-8,19,10,minecraft:crying_obsidian,20,minecraft:obsidian,100)
RB(-8,20,10,minecraft:crying_obsidian,20,minecraft:obsidian,100)
RB(-8,21,10,minecraft:crying_obsidian,20,minecraft:obsidian,100)
RB(-7,14,1,minecraft:crying_obsidian,20,minecraft:obsidian,100)
RB(-7,15,1,minecraft:crying_obsidian,20,minecraft:obsidian,100)
RB(-7,13,2,minecraft:crying_obsidian,20,minecraft:obsidian,100)
RB(-7,14,2,minecraft:crying_obsidian,20,minecraft:obsidian,100)
RB(-7,15,2,minecraft:crying_obsidian,20,minecraft:obsidian,100)
RB(-7,16,2,minecraft:crying_obsidian,20,minecraft:obsidian,100)
RB(-7,17,2,minecraft:crying_obsidian,20,minecraft:obsidian,100)
RB(-7,13,3,minecraft:crying_obsidian,20,minecraft:obsidian,100)
RB(-7,14,3,minecraft:crying_obsidian,20,minecraft:obsidian,100)
RB(-7,15,3,minecraft:crying_obsidian,20,minecraft:obsidian,100)
RB(-7,16,3,minecraft:crying_obsidian,20,minecraft:obsidian,100)
RB(-7,17,3,minecraft:crying_obsidian,20,minecraft:obsidian,100)
RB(-7,18,3,minecraft:crying_obsidian,20,minecraft:obsidian,100)
RB(-7,13,4,minecraft:crying_obsidian,20,minecraft:obsidian,100)
RB(-7,14,4,minecraft:crying_obsidian,20,minecraft:obsidian,100)
RB(-7,15,4,minecraft:crying_obsidian,20,minecraft:obsidian,100)
RB(-7,16,4,minecraft:crying_obsidian,20,minecraft:obsidian,100)
RB(-7,17,4,minecraft:crying_obsidian,20,minecraft:obsidian,100)
RB(-7,18,4,minecraft:crying_obsidian,20,minecraft:obsidian,100)
RB(-7,19,4,minecraft:crying_obsidian,20,minecraft:obsidian,100)
RB(-7,12,5,minecraft:crying_obsidian,20,minecraft:obsidian,100)
RB(-7,13,5,minecraft:crying_obsidian,20,minecraft:obsidian,100)
RB(-7,14,5,minecraft:crying_obsidian,20,minecraft:obsidian,100)
RB(-7,15,5,minecraft:crying_obsidian,20,minecraft:obsidian,100)
RB(-7,16,5,minecraft:crying_obsidian,20,minecraft:obsidian,100)
RB(-7,17,5,minecraft:crying_obsidian,20,minecraft:obsidian,100)
RB(-7,18,5,minecraft:crying_obsidian,20,minecraft:obsidian,100)
RB(-7,19,5,minecraft:crying_obsidian,20,minecraft:obsidian,100)
RB(-7,20,5,minecraft:crying_obsidian,20,minecraft:obsidian,100)
RB(-7,11,6,minecraft:crying_obsidian,20,minecraft:obsidian,100)
RB(-7,12,6,minecraft:crying_obsidian,20,minecraft:obsidian,100)
RB(-7,13,6,minecraft:crying_obsidian,20,minecraft:obsidian,100)
RB(-7,14,6,minecraft:crying_obsidian,20,minecraft:obsidian,100)
RB(-7,15,6,minecraft:crying_obsidian,20,minecraft:obsidian,100)
RB(-7,16,6,minecraft:crying_obsidian,20,minecraft:obsidian,100)
RB(-7,17,6,minecraft:crying_obsidian,20,minecraft:obsidian,100)
RB(-7,18,6,minecraft:crying_obsidian,20,minecraft:obsidian,100)
RB(-7,19,6,minecraft:crying_obsidian,20,minecraft:obsidian,100)
RB(-7,20,6,minecraft:crying_obsidian,20,minecraft:obsidian,100)
RB(-7,11,7,minecraft:crying_obsidian,20,minecraft:obsidian,100)
RB(-7,12,7,minecraft:crying_obsidian,20,minecraft:obsidian,100)
RB(-7,13,7,minecraft:crying_obsidian,20,minecraft:obsidian,100)
RB(-7,14,7,minecraft:crying_obsidian,20,minecraft:obsidian,100)
RB(-7,15,7,minecraft:crying_obsidian,20,minecraft:obsidian,100)
RB(-7,16,7,minecraft:crying_obsidian,20,minecraft:obsidian,100)
RB(-7,17,7,minecraft:crying_obsidian,20,minecraft:obsidian,100)
RB(-7,18,7,minecraft:crying_obsidian,20,minecraft:obsidian,100)
RB(-7,19,7,minecraft:crying_obsidian,20,minecraft:obsidian,100)
RB(-7,20,7,minecraft:crying_obsidian,20,minecraft:obsidian,100)
RB(-7,12,8,minecraft:crying_obsidian,20,minecraft:obsidian,100)
RB(-7,13,8,minecraft:crying_obsidian,20,minecraft:obsidian,100)
RB(-7,14,8,minecraft:crying_obsidian,20,minecraft:obsidian,100)
RB(-7,15,8,minecraft:crying_obsidian,20,minecraft:obsidian,100)
RB(-7,16,8,minecraft:crying_obsidian,20,minecraft:obsidian,100)
RB(-7,17,8,minecraft:crying_obsidian,20,minecraft:obsidian,100)
RB(-7,18,8,minecraft:crying_obsidian,20,minecraft:obsidian,100)
RB(-7,19,8,minecraft:crying_obsidian,20,minecraft:obsidian,100)
RB(-7,20,8,minecraft:crying_obsidian,20,minecraft:obsidian,100)
RB(-7,21,8,minecraft:crying_obsidian,20,minecraft:obsidian,100)
RB(-7,12,9,minecraft:crying_obsidian,20,minecraft:obsidian,100)
RB(-7,13,9,minecraft:crying_obsidian,20,minecraft:obsidian,100)
RB(-7,14,9,minecraft:crying_obsidian,20,minecraft:obsidian,100)
RB(-7,15,9,minecraft:crying_obsidian,20,minecraft:obsidian,100)
RB(-7,16,9,minecraft:crying_obsidian,20,minecraft:obsidian,100)
RB(-7,17,9,minecraft:crying_obsidian,20,minecraft:obsidian,100)
RB(-7,18,9,minecraft:crying_obsidian,20,minecraft:obsidian,100)
RB(-7,19,9,minecraft:crying_obsidian,20,minecraft:obsidian,100)
RB(-7,20,9,minecraft:crying_obsidian,20,minecraft:obsidian,100)
RB(-7,21,9,minecraft:crying_obsidian,20,minecraft:obsidian,100)
RB(-7,11,10,minecraft:crying_obsidian,20,minecraft:obsidian,100)
RB(-7,12,10,minecraft:crying_obsidian,20,minecraft:obsidian,100)
RB(-7,13,10,minecraft:crying_obsidian,20,minecraft:obsidian,100)
RB(-7,14,10,minecraft:crying_obsidian,20,minecraft:obsidian,100)
RB(-7,15,10,minecraft:crying_obsidian,20,minecraft:obsidian,100)
RB(-7,16,10,minecraft:crying_obsidian,20,minecraft:obsidian,100)
RB(-7,17,10,minecraft:crying_obsidian,20,minecraft:obsidian,100)
RB(-7,18,10,minecraft:crying_obsidian,20,minecraft:obsidian,100)
RB(-7,19,10,minecraft:crying_obsidian,20,minecraft:obsidian,100)
RB(-7,20,10,minecraft:crying_obsidian,20,minecraft:obsidian,100)
RB(-7,13,11,minecraft:crying_obsidian,20,minecraft:obsidian,100)
RB(-7,14,11,minecraft:crying_obsidian,20,minecraft:obsidian,100)
RB(-7,15,11,minecraft:crying_obsidian,20,minecraft:obsidian,100)
RB(-7,16,11,minecraft:crying_obsidian,20,minecraft:obsidian,100)
RB(-7,17,11,minecraft:crying_obsidian,20,minecraft:obsidian,100)
RB(-7,18,11,minecraft:crying_obsidian,20,minecraft:obsidian,100)
RB(-7,19,11,minecraft:crying_obsidian,20,minecraft:obsidian,100)
RB(-6,9,-8,minecraft:crying_obsidian,20,minecraft:obsidian,100)
RB(-6,10,-8,minecraft:crying_obsidian,20,minecraft:obsidian,100)
RB(-6,11,-8,minecraft:crying_obsidian,20,minecraft:obsidian,100)
RB(-6,8,-7,minecraft:crying_obsidian,20,minecraft:obsidian,100)
RB(-6,9,-7,minecraft:crying_obsidian,20,minecraft:obsidian,100)
RB(-6,10,-7,minecraft:crying_obsidian,20,minecraft:obsidian,100)
RB(-6,11,-7,minecraft:crying_obsidian,20,minecraft:obsidian,100)
RB(-6,12,-7,minecraft:crying_obsidian,20,minecraft:obsidian,100)
RB(-6,8,-6,minecraft:crying_obsidian,20,minecraft:obsidian,100)
RB(-6,9,-6,minecraft:crying_obsidian,20,minecraft:obsidian,100)
RB(-6,10,-6,minecraft:crying_obsidian,20,minecraft:obsidian,100)
RB(-6,11,-6,minecraft:crying_obsidian,20,minecraft:obsidian,100)
RB(-6,12,-6,minecraft:crying_obsidian,20,minecraft:obsidian,100)
RB(-6,8,-5,minecraft:crying_obsidian,20,minecraft:obsidian,100)
RB(-6,9,-5,minecraft:crying_obsidian,20,minecraft:obsidian,100)
RB(-6,10,-5,minecraft:crying_obsidian,20,minecraft:obsidian,100)
RB(-6,11,-5,minecraft:crying_obsidian,20,minecraft:obsidian,100)
RB(-6,12,-5,minecraft:crying_obsidian,20,minecraft:obsidian,100)
RB(-6,11,-4,minecraft:crying_obsidian,20,minecraft:obsidian,100)
RB(-6,14,1,minecraft:crying_obsidian,20,minecraft:obsidian,100)
RB(-6,15,1,minecraft:crying_obsidian,20,minecraft:obsidian,100)
RB(-6,16,1,minecraft:crying_obsidian,20,minecraft:obsidian,100)
RB(-6,13,2,minecraft:crying_obsidian,20,minecraft:obsidian,100)
RB(-6,14,2,minecraft:crying_obsidian,20,minecraft:obsidian,100)
RB(-6,15,2,minecraft:crying_obsidian,20,minecraft:obsidian,100)
RB(-6,16,2,minecraft:crying_obsidian,20,minecraft:obsidian,100)
RB(-6,17,2,minecraft:crying_obsidian,20,minecraft:obsidian,100)
RB(-6,13,3,minecraft:crying_obsidian,20,minecraft:obsidian,100)
RB(-6,14,3,minecraft:crying_obsidian,20,minecraft:obsidian,100)
RB(-6,15,3,minecraft:crying_obsidian,20,minecraft:obsidian,100)
RB(-6,16,3,minecraft:crying_obsidian,20,minecraft:obsidian,100)
RB(-6,17,3,minecraft:crying_obsidian,20,minecraft:obsidian,100)
RB(-6,18,3,minecraft:crying_obsidian,20,minecraft:obsidian,100)
RB(-6,12,4,minecraft:crying_obsidian,20,minecraft:obsidian,100)
RB(-6,13,4,minecraft:crying_obsidian,20,minecraft:obsidian,100)
RB(-6,14,4,minecraft:crying_obsidian,20,minecraft:obsidian,100)
RB(-6,15,4,minecraft:crying_obsidian,20,minecraft:obsidian,100)
RB(-6,16,4,minecraft:crying_obsidian,20,minecraft:obsidian,100)
RB(-6,17,4,minecraft:crying_obsidian,20,minecraft:obsidian,100)
RB(-6,18,4,minecraft:crying_obsidian,20,minecraft:obsidian,100)
RB(-6,19,4,minecraft:crying_obsidian,20,minecraft:obsidian,100)
RB(-6,12,5,minecraft:crying_obsidian,20,minecraft:obsidian,100)
RB(-6,13,5,minecraft:crying_obsidian,20,minecraft:obsidian,100)
RB(-6,14,5,minecraft:crying_obsidian,20,minecraft:obsidian,100)
RB(-6,15,5,minecraft:crying_obsidian,20,minecraft:obsidian,100)
RB(-6,16,5,minecraft:crying_obsidian,20,minecraft:obsidian,100)
RB(-6,17,5,minecraft:crying_obsidian,20,minecraft:obsidian,100)
RB(-6,18,5,minecraft:crying_obsidian,20,minecraft:obsidian,100)
RB(-6,19,5,minecraft:crying_obsidian,20,minecraft:obsidian,100)
RB(-6,12,6,minecraft:crying_obsidian,20,minecraft:obsidian,100)
RB(-6,13,6,minecraft:crying_obsidian,20,minecraft:obsidian,100)
RB(-6,14,6,minecraft:crying_obsidian,20,minecraft:obsidian,100)
RB(-6,15,6,minecraft:crying_obsidian,20,minecraft:obsidian,100)
RB(-6,16,6,minecraft:crying_obsidian,20,minecraft:obsidian,100)
RB(-6,17,6,minecraft:crying_obsidian,20,minecraft:obsidian,100)
RB(-6,18,6,minecraft:crying_obsidian,20,minecraft:obsidian,100)
RB(-6,19,6,minecraft:crying_obsidian,20,minecraft:obsidian,100)
RB(-6,11,7,minecraft:crying_obsidian,20,minecraft:obsidian,100)
RB(-6,12,7,minecraft:crying_obsidian,20,minecraft:obsidian,100)
RB(-6,13,7,minecraft:crying_obsidian,20,minecraft:obsidian,100)
RB(-6,14,7,minecraft:crying_obsidian,20,minecraft:obsidian,100)
RB(-6,15,7,minecraft:crying_obsidian,20,minecraft:obsidian,100)
RB(-6,16,7,minecraft:crying_obsidian,20,minecraft:obsidian,100)
RB(-6,17,7,minecraft:crying_obsidian,20,minecraft:obsidian,100)
RB(-6,18,7,minecraft:crying_obsidian,20,minecraft:obsidian,100)
RB(-6,19,7,minecraft:crying_obsidian,20,minecraft:obsidian,100)
RB(-6,20,7,minecraft:crying_obsidian,20,minecraft:obsidian,100)
RB(-6,11,8,minecraft:crying_obsidian,20,minecraft:obsidian,100)
RB(-6,12,8,minecraft:crying_obsidian,20,minecraft:obsidian,100)
RB(-6,13,8,minecraft:crying_obsidian,20,minecraft:obsidian,100)
RB(-6,14,8,minecraft:crying_obsidian,20,minecraft:obsidian,100)
RB(-6,15,8,minecraft:crying_obsidian,20,minecraft:obsidian,100)
RB(-6,16,8,minecraft:crying_obsidian,20,minecraft:obsidian,100)
RB(-6,17,8,minecraft:crying_obsidian,20,minecraft:obsidian,100)
RB(-6,18,8,minecraft:crying_obsidian,20,minecraft:obsidian,100)
RB(-6,19,8,minecraft:crying_obsidian,20,minecraft:obsidian,100)
RB(-6,20,8,minecraft:crying_obsidian,20,minecraft:obsidian,100)
RB(-6,21,8,minecraft:crying_obsidian,20,minecraft:obsidian,100)
RB(-6,12,9,minecraft:crying_obsidian,20,minecraft:obsidian,100)
RB(-6,13,9,minecraft:crying_obsidian,20,minecraft:obsidian,100)
RB(-6,14,9,minecraft:crying_obsidian,20,minecraft:obsidian,100)
RB(-6,15,9,minecraft:crying_obsidian,20,minecraft:obsidian,100)
RB(-6,16,9,minecraft:crying_obsidian,20,minecraft:obsidian,100)
RB(-6,17,9,minecraft:crying_obsidian,20,minecraft:obsidian,100)
RB(-6,18,9,minecraft:crying_obsidian,20,minecraft:obsidian,100)
RB(-6,19,9,minecraft:crying_obsidian,20,minecraft:obsidian,100)
RB(-6,20,9,minecraft:crying_obsidian,20,minecraft:obsidian,100)
RB(-6,21,9,minecraft:crying_obsidian,20,minecraft:obsidian,100)
RB(-6,11,10,minecraft:crying_obsidian,20,minecraft:obsidian,100)
RB(-6,12,10,minecraft:crying_obsidian,20,minecraft:obsidian,100)
RB(-6,13,10,minecraft:crying_obsidian,20,minecraft:obsidian,100)
RB(-6,14,10,minecraft:crying_obsidian,20,minecraft:obsidian,100)
RB(-6,15,10,minecraft:crying_obsidian,20,minecraft:obsidian,100)
RB(-6,16,10,minecraft:crying_obsidian,20,minecraft:obsidian,100)
RB(-6,17,10,minecraft:crying_obsidian,20,minecraft:obsidian,100)
RB(-6,18,10,minecraft:crying_obsidian,20,minecraft:obsidian,100)
RB(-6,19,10,minecraft:crying_obsidian,20,minecraft:obsidian,100)
RB(-6,20,10,minecraft:crying_obsidian,20,minecraft:obsidian,100)
RB(-6,12,11,minecraft:crying_obsidian,20,minecraft:obsidian,100)
RB(-6,13,11,minecraft:crying_obsidian,20,minecraft:obsidian,100)
RB(-6,14,11,minecraft:crying_obsidian,20,minecraft:obsidian,100)
RB(-6,15,11,minecraft:crying_obsidian,20,minecraft:obsidian,100)
RB(-6,16,11,minecraft:crying_obsidian,20,minecraft:obsidian,100)
RB(-6,17,11,minecraft:crying_obsidian,20,minecraft:obsidian,100)
RB(-6,18,11,minecraft:crying_obsidian,20,minecraft:obsidian,100)
RB(-6,19,11,minecraft:crying_obsidian,20,minecraft:obsidian,100)
RB(-6,20,11,minecraft:crying_obsidian,20,minecraft:obsidian,100)
RB(-5,8,-9,minecraft:crying_obsidian,20,minecraft:obsidian,100)
RB(-5,9,-9,minecraft:crying_obsidian,20,minecraft:obsidian,100)
RB(-5,10,-9,minecraft:crying_obsidian,20,minecraft:obsidian,100)
RB(-5,11,-9,minecraft:crying_obsidian,20,minecraft:obsidian,100)
RB(-5,12,-9,minecraft:crying_obsidian,20,minecraft:obsidian,100)
RB(-5,7,-8,minecraft:crying_obsidian,20,minecraft:obsidian,100)
RB(-5,8,-8,minecraft:crying_obsidian,20,minecraft:obsidian,100)
RB(-5,9,-8,minecraft:crying_obsidian,20,minecraft:obsidian,100)
RB(-5,10,-8,minecraft:crying_obsidian,20,minecraft:obsidian,100)
RB(-5,11,-8,minecraft:crying_obsidian,20,minecraft:obsidian,100)
RB(-5,12,-8,minecraft:crying_obsidian,20,minecraft:obsidian,100)
RB(-5,13,-8,minecraft:crying_obsidian,20,minecraft:obsidian,100)
RB(-5,7,-7,minecraft:crying_obsidian,20,minecraft:obsidian,100)
RB(-5,8,-7,minecraft:crying_obsidian,20,minecraft:obsidian,100)
RB(-5,9,-7,minecraft:crying_obsidian,20,minecraft:obsidian,100)
RB(-5,10,-7,minecraft:crying_obsidian,20,minecraft:obsidian,100)
RB(-5,11,-7,minecraft:crying_obsidian,20,minecraft:obsidian,100)
RB(-5,12,-7,minecraft:crying_obsidian,20,minecraft:obsidian,100)
RB(-5,13,-7,minecraft:crying_obsidian,20,minecraft:obsidian,100)
RB(-5,7,-6,minecraft:crying_obsidian,20,minecraft:obsidian,100)
RB(-5,8,-6,minecraft:crying_obsidian,20,minecraft:obsidian,100)
RB(-5,9,-6,minecraft:crying_obsidian,20,minecraft:obsidian,100)
RB(-5,10,-6,minecraft:crying_obsidian,20,minecraft:obsidian,100)
RB(-5,11,-6,minecraft:crying_obsidian,20,minecraft:obsidian,100)
RB(-5,12,-6,minecraft:crying_obsidian,20,minecraft:obsidian,100)
RB(-5,13,-6,minecraft:crying_obsidian,20,minecraft:obsidian,100)
RB(-5,10,-5,minecraft:crying_obsidian,20,minecraft:obsidian,100)
RB(-5,11,-5,minecraft:crying_obsidian,20,minecraft:obsidian,100)
RB(-5,12,-5,minecraft:crying_obsidian,20,minecraft:obsidian,100)
RB(-5,13,-5,minecraft:crying_obsidian,20,minecraft:obsidian,100)
RB(-5,10,-4,minecraft:crying_obsidian,20,minecraft:obsidian,100)
RB(-5,11,-4,minecraft:crying_obsidian,20,minecraft:obsidian,100)
RB(-5,12,-4,minecraft:crying_obsidian,20,minecraft:obsidian,100)
RB(-5,13,-4,minecraft:crying_obsidian,20,minecraft:obsidian,100)
RB(-5,12,-3,minecraft:crying_obsidian,20,minecraft:obsidian,100)
RB(-5,12,-1,minecraft:crying_obsidian,20,minecraft:obsidian,100)
RB(-5,13,-1,minecraft:crying_obsidian,20,minecraft:obsidian,100)
RB(-5,13,0,minecraft:crying_obsidian,20,minecraft:obsidian,100)
RB(-5,14,0,minecraft:crying_obsidian,20,minecraft:obsidian,100)
RB(-5,15,0,minecraft:crying_obsidian,20,minecraft:obsidian,100)
RB(-5,13,1,minecraft:crying_obsidian,20,minecraft:obsidian,100)
RB(-5,14,1,minecraft:crying_obsidian,20,minecraft:obsidian,100)
RB(-5,15,1,minecraft:crying_obsidian,20,minecraft:obsidian,100)
RB(-5,16,1,minecraft:crying_obsidian,20,minecraft:obsidian,100)
RB(-5,17,1,minecraft:crying_obsidian,20,minecraft:obsidian,100)
RB(-5,12,2,minecraft:crying_obsidian,20,minecraft:obsidian,100)
RB(-5,13,2,minecraft:crying_obsidian,20,minecraft:obsidian,100)
RB(-5,14,2,minecraft:crying_obsidian,20,minecraft:obsidian,100)
RB(-5,15,2,minecraft:crying_obsidian,20,minecraft:obsidian,100)
RB(-5,16,2,minecraft:crying_obsidian,20,minecraft:obsidian,100)
RB(-5,17,2,minecraft:crying_obsidian,20,minecraft:obsidian,100)
RB(-5,12,3,minecraft:crying_obsidian,20,minecraft:obsidian,100)
RB(-5,13,3,minecraft:crying_obsidian,20,minecraft:obsidian,100)
RB(-5,14,3,minecraft:crying_obsidian,20,minecraft:obsidian,100)
RB(-5,15,3,minecraft:crying_obsidian,20,minecraft:obsidian,100)
RB(-5,16,3,minecraft:crying_obsidian,20,minecraft:obsidian,100)
RB(-5,17,3,minecraft:crying_obsidian,20,minecraft:obsidian,100)
RB(-5,18,3,minecraft:crying_obsidian,20,minecraft:obsidian,100)
RB(-5,12,4,minecraft:crying_obsidian,20,minecraft:obsidian,100)
RB(-5,13,4,minecraft:crying_obsidian,20,minecraft:obsidian,100)
RB(-5,14,4,minecraft:crying_obsidian,20,minecraft:obsidian,100)
RB(-5,15,4,minecraft:crying_obsidian,20,minecraft:obsidian,100)
RB(-5,16,4,minecraft:crying_obsidian,20,minecraft:obsidian,100)
RB(-5,17,4,minecraft:crying_obsidian,20,minecraft:obsidian,100)
RB(-5,18,4,minecraft:crying_obsidian,20,minecraft:obsidian,100)
RB(-5,19,4,minecraft:crying_obsidian,20,minecraft:obsidian,100)
RB(-5,12,5,minecraft:crying_obsidian,20,minecraft:obsidian,100)
RB(-5,13,5,minecraft:crying_obsidian,20,minecraft:obsidian,100)
RB(-5,14,5,minecraft:crying_obsidian,20,minecraft:obsidian,100)
RB(-5,15,5,minecraft:crying_obsidian,20,minecraft:obsidian,100)
RB(-5,16,5,minecraft:crying_obsidian,20,minecraft:obsidian,100)
RB(-5,17,5,minecraft:crying_obsidian,20,minecraft:obsidian,100)
RB(-5,18,5,minecraft:crying_obsidian,20,minecraft:obsidian,100)
RB(-5,19,5,minecraft:crying_obsidian,20,minecraft:obsidian,100)
RB(-5,12,6,minecraft:crying_obsidian,20,minecraft:obsidian,100)
RB(-5,13,6,minecraft:crying_obsidian,20,minecraft:obsidian,100)
RB(-5,14,6,minecraft:crying_obsidian,20,minecraft:obsidian,100)
RB(-5,15,6,minecraft:crying_obsidian,20,minecraft:obsidian,100)
RB(-5,16,6,minecraft:crying_obsidian,20,minecraft:obsidian,100)
RB(-5,17,6,minecraft:crying_obsidian,20,minecraft:obsidian,100)
RB(-5,18,6,minecraft:crying_obsidian,20,minecraft:obsidian,100)
RB(-5,19,6,minecraft:crying_obsidian,20,minecraft:obsidian,100)
RB(-5,11,7,minecraft:crying_obsidian,20,minecraft:obsidian,100)
RB(-5,12,7,minecraft:crying_obsidian,20,minecraft:obsidian,100)
RB(-5,13,7,minecraft:crying_obsidian,20,minecraft:obsidian,100)
RB(-5,14,7,minecraft:crying_obsidian,20,minecraft:obsidian,100)
RB(-5,15,7,minecraft:crying_obsidian,20,minecraft:obsidian,100)
RB(-5,16,7,minecraft:crying_obsidian,20,minecraft:obsidian,100)
RB(-5,17,7,minecraft:crying_obsidian,20,minecraft:obsidian,100)
RB(-5,18,7,minecraft:crying_obsidian,20,minecraft:obsidian,100)
RB(-5,19,7,minecraft:crying_obsidian,20,minecraft:obsidian,100)
RB(-5,20,7,minecraft:crying_obsidian,20,minecraft:obsidian,100)
RB(-5,11,8,minecraft:crying_obsidian,20,minecraft:obsidian,100)
RB(-5,12,8,minecraft:crying_obsidian,20,minecraft:obsidian,100)
RB(-5,13,8,minecraft:crying_obsidian,20,minecraft:obsidian,100)
RB(-5,14,8,minecraft:crying_obsidian,20,minecraft:obsidian,100)
RB(-5,15,8,minecraft:crying_obsidian,20,minecraft:obsidian,100)
RB(-5,16,8,minecraft:crying_obsidian,20,minecraft:obsidian,100)
RB(-5,17,8,minecraft:crying_obsidian,20,minecraft:obsidian,100)
RB(-5,18,8,minecraft:crying_obsidian,20,minecraft:obsidian,100)
RB(-5,19,8,minecraft:crying_obsidian,20,minecraft:obsidian,100)
RB(-5,20,8,minecraft:crying_obsidian,20,minecraft:obsidian,100)
RB(-5,21,8,minecraft:crying_obsidian,20,minecraft:obsidian,100)
RB(-5,10,9,minecraft:crying_obsidian,20,minecraft:obsidian,100)
RB(-5,11,9,minecraft:crying_obsidian,20,minecraft:obsidian,100)
RB(-5,12,9,minecraft:crying_obsidian,20,minecraft:obsidian,100)
RB(-5,13,9,minecraft:crying_obsidian,20,minecraft:obsidian,100)
RB(-5,14,9,minecraft:crying_obsidian,20,minecraft:obsidian,100)
RB(-5,15,9,minecraft:crying_obsidian,20,minecraft:obsidian,100)
RB(-5,16,9,minecraft:crying_obsidian,20,minecraft:obsidian,100)
RB(-5,17,9,minecraft:crying_obsidian,20,minecraft:obsidian,100)
RB(-5,18,9,minecraft:crying_obsidian,20,minecraft:obsidian,100)
RB(-5,19,9,minecraft:crying_obsidian,20,minecraft:obsidian,100)
RB(-5,20,9,minecraft:crying_obsidian,20,minecraft:obsidian,100)
RB(-5,21,9,minecraft:crying_obsidian,20,minecraft:obsidian,100)
RB(-5,11,10,minecraft:crying_obsidian,20,minecraft:obsidian,100)
RB(-5,12,10,minecraft:crying_obsidian,20,minecraft:obsidian,100)
RB(-5,13,10,minecraft:crying_obsidian,20,minecraft:obsidian,100)
RB(-5,14,10,minecraft:crying_obsidian,20,minecraft:obsidian,100)
RB(-5,15,10,minecraft:crying_obsidian,20,minecraft:obsidian,100)
RB(-5,16,10,minecraft:crying_obsidian,20,minecraft:obsidian,100)
RB(-5,17,10,minecraft:crying_obsidian,20,minecraft:obsidian,100)
RB(-5,18,10,minecraft:crying_obsidian,20,minecraft:obsidian,100)
RB(-5,19,10,minecraft:crying_obsidian,20,minecraft:obsidian,100)
RB(-5,20,10,minecraft:crying_obsidian,20,minecraft:obsidian,100)
RB(-5,12,11,minecraft:crying_obsidian,20,minecraft:obsidian,100)
RB(-5,13,11,minecraft:crying_obsidian,20,minecraft:obsidian,100)
RB(-5,14,11,minecraft:crying_obsidian,20,minecraft:obsidian,100)
RB(-5,15,11,minecraft:crying_obsidian,20,minecraft:obsidian,100)
RB(-5,16,11,minecraft:crying_obsidian,20,minecraft:obsidian,100)
RB(-5,17,11,minecraft:crying_obsidian,20,minecraft:obsidian,100)
RB(-5,18,11,minecraft:crying_obsidian,20,minecraft:obsidian,100)
RB(-5,19,11,minecraft:crying_obsidian,20,minecraft:obsidian,100)
RB(-4,8,-10,minecraft:crying_obsidian,20,minecraft:obsidian,100)
RB(-4,9,-10,minecraft:crying_obsidian,20,minecraft:obsidian,100)
RB(-4,10,-10,minecraft:crying_obsidian,20,minecraft:obsidian,100)
RB(-4,11,-10,minecraft:crying_obsidian,20,minecraft:obsidian,100)
RB(-4,12,-10,minecraft:crying_obsidian,20,minecraft:obsidian,100)
RB(-4,7,-9,minecraft:crying_obsidian,20,minecraft:obsidian,100)
RB(-4,8,-9,minecraft:crying_obsidian,20,minecraft:obsidian,100)
RB(-4,9,-9,minecraft:crying_obsidian,20,minecraft:obsidian,100)
RB(-4,10,-9,minecraft:crying_obsidian,20,minecraft:obsidian,100)
RB(-4,11,-9,minecraft:crying_obsidian,20,minecraft:obsidian,100)
RB(-4,12,-9,minecraft:crying_obsidian,20,minecraft:obsidian,100)
RB(-4,13,-9,minecraft:crying_obsidian,20,minecraft:obsidian,100)
RB(-4,6,-8,minecraft:crying_obsidian,20,minecraft:obsidian,100)
RB(-4,7,-8,minecraft:crying_obsidian,20,minecraft:obsidian,100)
RB(-4,8,-8,minecraft:crying_obsidian,20,minecraft:obsidian,100)
RB(-4,9,-8,minecraft:crying_obsidian,20,minecraft:obsidian,100)
RB(-4,10,-8,minecraft:crying_obsidian,20,minecraft:obsidian,100)
RB(-4,11,-8,minecraft:crying_obsidian,20,minecraft:obsidian,100)
RB(-4,12,-8,minecraft:crying_obsidian,20,minecraft:obsidian,100)
RB(-4,13,-8,minecraft:crying_obsidian,20,minecraft:obsidian,100)
RB(-4,14,-8,minecraft:crying_obsidian,20,minecraft:obsidian,100)
RB(-4,6,-7,minecraft:crying_obsidian,20,minecraft:obsidian,100)
RB(-4,7,-7,minecraft:crying_obsidian,20,minecraft:obsidian,100)
RB(-4,8,-7,minecraft:crying_obsidian,20,minecraft:obsidian,100)
RB(-4,9,-7,minecraft:crying_obsidian,20,minecraft:obsidian,100)
RB(-4,10,-7,minecraft:crying_obsidian,20,minecraft:obsidian,100)
RB(-4,11,-7,minecraft:crying_obsidian,20,minecraft:obsidian,100)
RB(-4,12,-7,minecraft:crying_obsidian,20,minecraft:obsidian,100)
RB(-4,13,-7,minecraft:crying_obsidian,20,minecraft:obsidian,100)
RB(-4,14,-7,minecraft:crying_obsidian,20,minecraft:obsidian,100)
RB(-4,9,-6,minecraft:crying_obsidian,20,minecraft:obsidian,100)
RB(-4,10,-6,minecraft:crying_obsidian,20,minecraft:obsidian,100)
RB(-4,11,-6,minecraft:crying_obsidian,20,minecraft:obsidian,100)
RB(-4,12,-6,minecraft:crying_obsidian,20,minecraft:obsidian,100)
RB(-4,13,-6,minecraft:crying_obsidian,20,minecraft:obsidian,100)
RB(-4,14,-6,minecraft:crying_obsidian,20,minecraft:obsidian,100)
RB(-4,15,-6,minecraft:crying_obsidian,20,minecraft:obsidian,100)
RB(-4,9,-5,minecraft:crying_obsidian,20,minecraft:obsidian,100)
RB(-4,10,-5,minecraft:crying_obsidian,20,minecraft:obsidian,100)
RB(-4,11,-5,minecraft:crying_obsidian,20,minecraft:obsidian,100)
RB(-4,12,-5,minecraft:crying_obsidian,20,minecraft:obsidian,100)
RB(-4,13,-5,minecraft:crying_obsidian,20,minecraft:obsidian,100)
RB(-4,14,-5,minecraft:crying_obsidian,20,minecraft:obsidian,100)
RB(-4,15,-5,minecraft:crying_obsidian,20,minecraft:obsidian,100)
RB(-4,10,-4,minecraft:crying_obsidian,20,minecraft:obsidian,100)
RB(-4,11,-4,minecraft:crying_obsidian,20,minecraft:obsidian,100)
RB(-4,12,-4,minecraft:crying_obsidian,20,minecraft:obsidian,100)
RB(-4,13,-4,minecraft:crying_obsidian,20,minecraft:obsidian,100)
RB(-4,14,-4,minecraft:crying_obsidian,20,minecraft:obsidian,100)
RB(-4,15,-4,minecraft:crying_obsidian,20,minecraft:obsidian,100)
RB(-4,16,-4,minecraft:crying_obsidian,20,minecraft:obsidian,100)
RB(-4,11,-3,minecraft:crying_obsidian,20,minecraft:obsidian,100)
RB(-4,12,-3,minecraft:crying_obsidian,20,minecraft:obsidian,100)
RB(-4,13,-3,minecraft:crying_obsidian,20,minecraft:obsidian,100)
RB(-4,14,-3,minecraft:crying_obsidian,20,minecraft:obsidian,100)
RB(-4,15,-3,minecraft:crying_obsidian,20,minecraft:obsidian,100)
RB(-4,13,-2,minecraft:crying_obsidian,20,minecraft:obsidian,100)
RB(-4,14,-2,minecraft:crying_obsidian,20,minecraft:obsidian,100)
RB(-4,15,-2,minecraft:crying_obsidian,20,minecraft:obsidian,100)
RB(-4,16,-2,minecraft:crying_obsidian,20,minecraft:obsidian,100)
RB(-4,12,-1,minecraft:crying_obsidian,20,minecraft:obsidian,100)
RB(-4,13,-1,minecraft:crying_obsidian,20,minecraft:obsidian,100)
RB(-4,14,-1,minecraft:crying_obsidian,20,minecraft:obsidian,100)
RB(-4,15,-1,minecraft:crying_obsidian,20,minecraft:obsidian,100)
RB(-4,16,-1,minecraft:crying_obsidian,20,minecraft:obsidian,100)
RB(-4,12,0,minecraft:crying_obsidian,20,minecraft:obsidian,100)
RB(-4,13,0,minecraft:crying_obsidian,20,minecraft:obsidian,100)
RB(-4,14,0,minecraft:crying_obsidian,20,minecraft:obsidian,100)
RB(-4,15,0,minecraft:crying_obsidian,20,minecraft:obsidian,100)
RB(-4,16,0,minecraft:crying_obsidian,20,minecraft:obsidian,100)
RB(-4,12,1,minecraft:crying_obsidian,20,minecraft:obsidian,100)
RB(-4,13,1,minecraft:crying_obsidian,20,minecraft:obsidian,100)
RB(-4,14,1,minecraft:crying_obsidian,20,minecraft:obsidian,100)
RB(-4,15,1,minecraft:crying_obsidian,20,minecraft:obsidian,100)
RB(-4,16,1,minecraft:crying_obsidian,20,minecraft:obsidian,100)
RB(-4,17,1,minecraft:crying_obsidian,20,minecraft:obsidian,100)
RB(-4,12,2,minecraft:crying_obsidian,20,minecraft:obsidian,100)
RB(-4,13,2,minecraft:crying_obsidian,20,minecraft:obsidian,100)
RB(-4,14,2,minecraft:crying_obsidian,20,minecraft:obsidian,100)
RB(-4,15,2,minecraft:crying_obsidian,20,minecraft:obsidian,100)
RB(-4,16,2,minecraft:crying_obsidian,20,minecraft:obsidian,100)
RB(-4,17,2,minecraft:crying_obsidian,20,minecraft:obsidian,100)
RB(-4,18,2,minecraft:crying_obsidian,20,minecraft:obsidian,100)
RB(-4,11,3,minecraft:crying_obsidian,20,minecraft:obsidian,100)
RB(-4,12,3,minecraft:crying_obsidian,20,minecraft:obsidian,100)
RB(-4,13,3,minecraft:crying_obsidian,20,minecraft:obsidian,100)
RB(-4,14,3,minecraft:crying_obsidian,20,minecraft:obsidian,100)
RB(-4,15,3,minecraft:crying_obsidian,20,minecraft:obsidian,100)
RB(-4,16,3,minecraft:crying_obsidian,20,minecraft:obsidian,100)
RB(-4,17,3,minecraft:crying_obsidian,20,minecraft:obsidian,100)
RB(-4,18,3,minecraft:crying_obsidian,20,minecraft:obsidian,100)
RB(-4,11,4,minecraft:crying_obsidian,20,minecraft:obsidian,100)
RB(-4,12,4,minecraft:crying_obsidian,20,minecraft:obsidian,100)
RB(-4,13,4,minecraft:crying_obsidian,20,minecraft:obsidian,100)
RB(-4,14,4,minecraft:crying_obsidian,20,minecraft:obsidian,100)
RB(-4,15,4,minecraft:crying_obsidian,20,minecraft:obsidian,100)
RB(-4,16,4,minecraft:crying_obsidian,20,minecraft:obsidian,100)
RB(-4,17,4,minecraft:crying_obsidian,20,minecraft:obsidian,100)
RB(-4,18,4,minecraft:crying_obsidian,20,minecraft:obsidian,100)
RB(-4,19,4,minecraft:crying_obsidian,20,minecraft:obsidian,100)
RB(-4,12,5,minecraft:crying_obsidian,20,minecraft:obsidian,100)
RB(-4,13,5,minecraft:crying_obsidian,20,minecraft:obsidian,100)
RB(-4,14,5,minecraft:crying_obsidian,20,minecraft:obsidian,100)
RB(-4,15,5,minecraft:crying_obsidian,20,minecraft:obsidian,100)
RB(-4,16,5,minecraft:crying_obsidian,20,minecraft:obsidian,100)
RB(-4,17,5,minecraft:crying_obsidian,20,minecraft:obsidian,100)
RB(-4,18,5,minecraft:crying_obsidian,20,minecraft:obsidian,100)
RB(-4,19,5,minecraft:crying_obsidian,20,minecraft:obsidian,100)
RB(-4,12,6,minecraft:crying_obsidian,20,minecraft:obsidian,100)
RB(-4,13,6,minecraft:crying_obsidian,20,minecraft:obsidian,100)
RB(-4,14,6,minecraft:crying_obsidian,20,minecraft:obsidian,100)
RB(-4,15,6,minecraft:crying_obsidian,20,minecraft:obsidian,100)
RB(-4,16,6,minecraft:crying_obsidian,20,minecraft:obsidian,100)
RB(-4,17,6,minecraft:crying_obsidian,20,minecraft:obsidian,100)
RB(-4,18,6,minecraft:crying_obsidian,20,minecraft:obsidian,100)
RB(-4,19,6,minecraft:crying_obsidian,20,minecraft:obsidian,100)
RB(-4,11,7,minecraft:crying_obsidian,20,minecraft:obsidian,100)
RB(-4,12,7,minecraft:crying_obsidian,20,minecraft:obsidian,100)
RB(-4,13,7,minecraft:crying_obsidian,20,minecraft:obsidian,100)
RB(-4,14,7,minecraft:crying_obsidian,20,minecraft:obsidian,100)
RB(-4,15,7,minecraft:crying_obsidian,20,minecraft:obsidian,100)
RB(-4,16,7,minecraft:crying_obsidian,20,minecraft:obsidian,100)
RB(-4,17,7,minecraft:crying_obsidian,20,minecraft:obsidian,100)
RB(-4,18,7,minecraft:crying_obsidian,20,minecraft:obsidian,100)
RB(-4,19,7,minecraft:crying_obsidian,20,minecraft:obsidian,100)
RB(-4,20,7,minecraft:crying_obsidian,20,minecraft:obsidian,100)
RB(-4,9,8,minecraft:crying_obsidian,20,minecraft:obsidian,100)
RB(-4,10,8,minecraft:crying_obsidian,20,minecraft:obsidian,100)
RB(-4,11,8,minecraft:crying_obsidian,20,minecraft:obsidian,100)
RB(-4,12,8,minecraft:crying_obsidian,20,minecraft:obsidian,100)
RB(-4,13,8,minecraft:crying_obsidian,20,minecraft:obsidian,100)
RB(-4,14,8,minecraft:crying_obsidian,20,minecraft:obsidian,100)
RB(-4,15,8,minecraft:crying_obsidian,20,minecraft:obsidian,100)
RB(-4,16,8,minecraft:crying_obsidian,20,minecraft:obsidian,100)
RB(-4,17,8,minecraft:crying_obsidian,20,minecraft:obsidian,100)
RB(-4,18,8,minecraft:crying_obsidian,20,minecraft:obsidian,100)
RB(-4,19,8,minecraft:crying_obsidian,20,minecraft:obsidian,100)
RB(-4,20,8,minecraft:crying_obsidian,20,minecraft:obsidian,100)
RB(-4,21,8,minecraft:crying_obsidian,20,minecraft:obsidian,100)
RB(-4,10,9,minecraft:crying_obsidian,20,minecraft:obsidian,100)
RB(-4,11,9,minecraft:crying_obsidian,20,minecraft:obsidian,100)
RB(-4,12,9,minecraft:crying_obsidian,20,minecraft:obsidian,100)
RB(-4,13,9,minecraft:crying_obsidian,20,minecraft:obsidian,100)
RB(-4,14,9,minecraft:crying_obsidian,20,minecraft:obsidian,100)
RB(-4,15,9,minecraft:crying_obsidian,20,minecraft:obsidian,100)
RB(-4,16,9,minecraft:crying_obsidian,20,minecraft:obsidian,100)
RB(-4,17,9,minecraft:crying_obsidian,20,minecraft:obsidian,100)
RB(-4,18,9,minecraft:crying_obsidian,20,minecraft:obsidian,100)
RB(-4,19,9,minecraft:crying_obsidian,20,minecraft:obsidian,100)
RB(-4,20,9,minecraft:crying_obsidian,20,minecraft:obsidian,100)
RB(-4,21,9,minecraft:crying_obsidian,20,minecraft:obsidian,100)
RB(-4,11,10,minecraft:crying_obsidian,20,minecraft:obsidian,100)
RB(-4,12,10,minecraft:crying_obsidian,20,minecraft:obsidian,100)
RB(-4,13,10,minecraft:crying_obsidian,20,minecraft:obsidian,100)
RB(-4,14,10,minecraft:crying_obsidian,20,minecraft:obsidian,100)
RB(-4,15,10,minecraft:crying_obsidian,20,minecraft:obsidian,100)
RB(-4,16,10,minecraft:crying_obsidian,20,minecraft:obsidian,100)
RB(-4,17,10,minecraft:crying_obsidian,20,minecraft:obsidian,100)
RB(-4,18,10,minecraft:crying_obsidian,20,minecraft:obsidian,100)
RB(-4,19,10,minecraft:crying_obsidian,20,minecraft:obsidian,100)
RB(-4,20,10,minecraft:crying_obsidian,20,minecraft:obsidian,100)
RB(-4,12,11,minecraft:crying_obsidian,20,minecraft:obsidian,100)
RB(-4,13,11,minecraft:crying_obsidian,20,minecraft:obsidian,100)
RB(-4,14,11,minecraft:crying_obsidian,20,minecraft:obsidian,100)
RB(-4,15,11,minecraft:crying_obsidian,20,minecraft:obsidian,100)
RB(-4,16,11,minecraft:crying_obsidian,20,minecraft:obsidian,100)
RB(-4,17,11,minecraft:crying_obsidian,20,minecraft:obsidian,100)
RB(-4,18,11,minecraft:crying_obsidian,20,minecraft:obsidian,100)
RB(-4,19,11,minecraft:crying_obsidian,20,minecraft:obsidian,100)
RB(-3,9,-11,minecraft:crying_obsidian,20,minecraft:obsidian,100)
RB(-3,10,-11,minecraft:crying_obsidian,20,minecraft:obsidian,100)
RB(-3,11,-11,minecraft:crying_obsidian,20,minecraft:obsidian,100)
RB(-3,7,-10,minecraft:crying_obsidian,20,minecraft:obsidian,100)
RB(-3,8,-10,minecraft:crying_obsidian,20,minecraft:obsidian,100)
RB(-3,9,-10,minecraft:crying_obsidian,20,minecraft:obsidian,100)
RB(-3,10,-10,minecraft:crying_obsidian,20,minecraft:obsidian,100)
RB(-3,11,-10,minecraft:crying_obsidian,20,minecraft:obsidian,100)
RB(-3,12,-10,minecraft:crying_obsidian,20,minecraft:obsidian,100)
RB(-3,13,-10,minecraft:crying_obsidian,20,minecraft:obsidian,100)
RB(-3,6,-9,minecraft:crying_obsidian,20,minecraft:obsidian,100)
RB(-3,7,-9,minecraft:crying_obsidian,20,minecraft:obsidian,100)
RB(-3,8,-9,minecraft:crying_obsidian,20,minecraft:obsidian,100)
RB(-3,9,-9,minecraft:crying_obsidian,20,minecraft:obsidian,100)
RB(-3,10,-9,minecraft:crying_obsidian,20,minecraft:obsidian,100)
RB(-3,11,-9,minecraft:crying_obsidian,20,minecraft:obsidian,100)
RB(-3,12,-9,minecraft:crying_obsidian,20,minecraft:obsidian,100)
RB(-3,13,-9,minecraft:crying_obsidian,20,minecraft:obsidian,100)
RB(-3,14,-9,minecraft:crying_obsidian,20,minecraft:obsidian,100)
RB(-3,6,-8,minecraft:crying_obsidian,20,minecraft:obsidian,100)
RB(-3,7,-8,minecraft:crying_obsidian,20,minecraft:obsidian,100)
RB(-3,8,-8,minecraft:crying_obsidian,20,minecraft:obsidian,100)
RB(-3,9,-8,minecraft:crying_obsidian,20,minecraft:obsidian,100)
RB(-3,10,-8,minecraft:crying_obsidian,20,minecraft:obsidian,100)
RB(-3,11,-8,minecraft:crying_obsidian,20,minecraft:obsidian,100)
RB(-3,12,-8,minecraft:crying_obsidian,20,minecraft:obsidian,100)
RB(-3,13,-8,minecraft:crying_obsidian,20,minecraft:obsidian,100)
RB(-3,14,-8,minecraft:crying_obsidian,20,minecraft:obsidian,100)
RB(-3,6,-7,minecraft:crying_obsidian,20,minecraft:obsidian,100)
RB(-3,7,-7,minecraft:crying_obsidian,20,minecraft:obsidian,100)
RB(-3,8,-7,minecraft:crying_obsidian,20,minecraft:obsidian,100)
RB(-3,9,-7,minecraft:crying_obsidian,20,minecraft:obsidian,100)
RB(-3,10,-7,minecraft:crying_obsidian,20,minecraft:obsidian,100)
RB(-3,11,-7,minecraft:crying_obsidian,20,minecraft:obsidian,100)
RB(-3,12,-7,minecraft:crying_obsidian,20,minecraft:obsidian,100)
RB(-3,13,-7,minecraft:crying_obsidian,20,minecraft:obsidian,100)
RB(-3,14,-7,minecraft:crying_obsidian,20,minecraft:obsidian,100)
RB(-3,15,-7,minecraft:crying_obsidian,20,minecraft:obsidian,100)
RB(-3,16,-7,minecraft:crying_obsidian,20,minecraft:obsidian,100)
RB(-3,6,-6,minecraft:crying_obsidian,20,minecraft:obsidian,100)
RB(-3,7,-6,minecraft:crying_obsidian,20,minecraft:obsidian,100)
RB(-3,8,-6,minecraft:crying_obsidian,20,minecraft:obsidian,100)
RB(-3,9,-6,minecraft:crying_obsidian,20,minecraft:obsidian,100)
RB(-3,10,-6,minecraft:crying_obsidian,20,minecraft:obsidian,100)
RB(-3,11,-6,minecraft:crying_obsidian,20,minecraft:obsidian,100)
RB(-3,12,-6,minecraft:crying_obsidian,20,minecraft:obsidian,100)
RB(-3,13,-6,minecraft:crying_obsidian,20,minecraft:obsidian,100)
RB(-3,14,-6,minecraft:crying_obsidian,20,minecraft:obsidian,100)
RB(-3,15,-6,minecraft:crying_obsidian,20,minecraft:obsidian,100)
RB(-3,16,-6,minecraft:crying_obsidian,20,minecraft:obsidian,100)
RB(-3,17,-6,minecraft:crying_obsidian,20,minecraft:obsidian,100)
RB(-3,8,-5,minecraft:crying_obsidian,20,minecraft:obsidian,100)
RB(-3,9,-5,minecraft:crying_obsidian,20,minecraft:obsidian,100)
RB(-3,10,-5,minecraft:crying_obsidian,20,minecraft:obsidian,100)
RB(-3,11,-5,minecraft:crying_obsidian,20,minecraft:obsidian,100)
RB(-3,12,-5,minecraft:crying_obsidian,20,minecraft:obsidian,100)
RB(-3,13,-5,minecraft:crying_obsidian,20,minecraft:obsidian,100)
RB(-3,14,-5,minecraft:crying_obsidian,20,minecraft:obsidian,100)
RB(-3,15,-5,minecraft:crying_obsidian,20,minecraft:obsidian,100)
RB(-3,16,-5,minecraft:crying_obsidian,20,minecraft:obsidian,100)
RB(-3,17,-5,minecraft:crying_obsidian,20,minecraft:obsidian,100)
RB(-3,10,-4,minecraft:crying_obsidian,20,minecraft:obsidian,100)
RB(-3,11,-4,minecraft:crying_obsidian,20,minecraft:obsidian,100)
RB(-3,12,-4,minecraft:crying_obsidian,20,minecraft:obsidian,100)
RB(-3,13,-4,minecraft:crying_obsidian,20,minecraft:obsidian,100)
RB(-3,14,-4,minecraft:crying_obsidian,20,minecraft:obsidian,100)
RB(-3,15,-4,minecraft:crying_obsidian,20,minecraft:obsidian,100)
RB(-3,16,-4,minecraft:crying_obsidian,20,minecraft:obsidian,100)
RB(-3,17,-4,minecraft:crying_obsidian,20,minecraft:obsidian,100)
RB(-3,10,-3,minecraft:crying_obsidian,20,minecraft:obsidian,100)
RB(-3,11,-3,minecraft:crying_obsidian,20,minecraft:obsidian,100)
RB(-3,12,-3,minecraft:crying_obsidian,20,minecraft:obsidian,100)
RB(-3,13,-3,minecraft:crying_obsidian,20,minecraft:obsidian,100)
RB(-3,14,-3,minecraft:crying_obsidian,20,minecraft:obsidian,100)
RB(-3,15,-3,minecraft:crying_obsidian,20,minecraft:obsidian,100)
RB(-3,16,-3,minecraft:crying_obsidian,20,minecraft:obsidian,100)
RB(-3,11,-2,minecraft:crying_obsidian,20,minecraft:obsidian,100)
RB(-3,12,-2,minecraft:crying_obsidian,20,minecraft:obsidian,100)
RB(-3,13,-2,minecraft:crying_obsidian,20,minecraft:obsidian,100)
RB(-3,14,-2,minecraft:crying_obsidian,20,minecraft:obsidian,100)
RB(-3,15,-2,minecraft:crying_obsidian,20,minecraft:obsidian,100)
RB(-3,16,-2,minecraft:crying_obsidian,20,minecraft:obsidian,100)
RB(-3,17,-2,minecraft:crying_obsidian,20,minecraft:obsidian,100)
RB(-3,12,-1,minecraft:crying_obsidian,20,minecraft:obsidian,100)
RB(-3,13,-1,minecraft:crying_obsidian,20,minecraft:obsidian,100)
RB(-3,14,-1,minecraft:crying_obsidian,20,minecraft:obsidian,100)
RB(-3,15,-1,minecraft:crying_obsidian,20,minecraft:obsidian,100)
RB(-3,16,-1,minecraft:crying_obsidian,20,minecraft:obsidian,100)
RB(-3,17,-1,minecraft:crying_obsidian,20,minecraft:obsidian,100)
RB(-3,18,-1,minecraft:crying_obsidian,20,minecraft:obsidian,100)
RB(-3,11,0,minecraft:crying_obsidian,20,minecraft:obsidian,100)
RB(-3,12,0,minecraft:crying_obsidian,20,minecraft:obsidian,100)
RB(-3,13,0,minecraft:crying_obsidian,20,minecraft:obsidian,100)
RB(-3,14,0,minecraft:crying_obsidian,20,minecraft:obsidian,100)
RB(-3,15,0,minecraft:crying_obsidian,20,minecraft:obsidian,100)
RB(-3,16,0,minecraft:crying_obsidian,20,minecraft:obsidian,100)
RB(-3,17,0,minecraft:crying_obsidian,20,minecraft:obsidian,100)
RB(-3,12,1,minecraft:crying_obsidian,20,minecraft:obsidian,100)
RB(-3,13,1,minecraft:crying_obsidian,20,minecraft:obsidian,100)
RB(-3,14,1,minecraft:crying_obsidian,20,minecraft:obsidian,100)
RB(-3,15,1,minecraft:crying_obsidian,20,minecraft:obsidian,100)
RB(-3,16,1,minecraft:crying_obsidian,20,minecraft:obsidian,100)
RB(-3,17,1,minecraft:crying_obsidian,20,minecraft:obsidian,100)
RB(-3,12,2,minecraft:crying_obsidian,20,minecraft:obsidian,100)
RB(-3,13,2,minecraft:crying_obsidian,20,minecraft:obsidian,100)
RB(-3,14,2,minecraft:crying_obsidian,20,minecraft:obsidian,100)
RB(-3,15,2,minecraft:crying_obsidian,20,minecraft:obsidian,100)
RB(-3,16,2,minecraft:crying_obsidian,20,minecraft:obsidian,100)
RB(-3,17,2,minecraft:crying_obsidian,20,minecraft:obsidian,100)
RB(-3,18,2,minecraft:crying_obsidian,20,minecraft:obsidian,100)
RB(-3,10,3,minecraft:crying_obsidian,20,minecraft:obsidian,100)
RB(-3,11,3,minecraft:crying_obsidian,20,minecraft:obsidian,100)
RB(-3,12,3,minecraft:crying_obsidian,20,minecraft:obsidian,100)
RB(-3,13,3,minecraft:crying_obsidian,20,minecraft:obsidian,100)
RB(-3,14,3,minecraft:crying_obsidian,20,minecraft:obsidian,100)
RB(-3,15,3,minecraft:crying_obsidian,20,minecraft:obsidian,100)
RB(-3,16,3,minecraft:crying_obsidian,20,minecraft:obsidian,100)
RB(-3,17,3,minecraft:crying_obsidian,20,minecraft:obsidian,100)
RB(-3,18,3,minecraft:crying_obsidian,20,minecraft:obsidian,100)
RB(-3,11,4,minecraft:crying_obsidian,20,minecraft:obsidian,100)
RB(-3,12,4,minecraft:crying_obsidian,20,minecraft:obsidian,100)
RB(-3,13,4,minecraft:crying_obsidian,20,minecraft:obsidian,100)
RB(-3,14,4,minecraft:crying_obsidian,20,minecraft:obsidian,100)
RB(-3,15,4,minecraft:crying_obsidian,20,minecraft:obsidian,100)
RB(-3,16,4,minecraft:crying_obsidian,20,minecraft:obsidian,100)
RB(-3,17,4,minecraft:crying_obsidian,20,minecraft:obsidian,100)
RB(-3,18,4,minecraft:crying_obsidian,20,minecraft:obsidian,100)
RB(-3,10,5,minecraft:crying_obsidian,20,minecraft:obsidian,100)
RB(-3,11,5,minecraft:crying_obsidian,20,minecraft:obsidian,100)
RB(-3,12,5,minecraft:crying_obsidian,20,minecraft:obsidian,100)
RB(-3,13,5,minecraft:crying_obsidian,20,minecraft:obsidian,100)
RB(-3,14,5,minecraft:crying_obsidian,20,minecraft:obsidian,100)
RB(-3,15,5,minecraft:crying_obsidian,20,minecraft:obsidian,100)
RB(-3,16,5,minecraft:crying_obsidian,20,minecraft:obsidian,100)
RB(-3,17,5,minecraft:crying_obsidian,20,minecraft:obsidian,100)
RB(-3,18,5,minecraft:crying_obsidian,20,minecraft:obsidian,100)
RB(-3,19,5,minecraft:crying_obsidian,20,minecraft:obsidian,100)
RB(-3,9,6,minecraft:crying_obsidian,20,minecraft:obsidian,100)
RB(-3,10,6,minecraft:crying_obsidian,20,minecraft:obsidian,100)
RB(-3,11,6,minecraft:crying_obsidian,20,minecraft:obsidian,100)
RB(-3,12,6,minecraft:crying_obsidian,20,minecraft:obsidian,100)
RB(-3,13,6,minecraft:crying_obsidian,20,minecraft:obsidian,100)
RB(-3,14,6,minecraft:crying_obsidian,20,minecraft:obsidian,100)
RB(-3,15,6,minecraft:crying_obsidian,20,minecraft:obsidian,100)
RB(-3,16,6,minecraft:crying_obsidian,20,minecraft:obsidian,100)
RB(-3,17,6,minecraft:crying_obsidian,20,minecraft:obsidian,100)
RB(-3,18,6,minecraft:crying_obsidian,20,minecraft:obsidian,100)
RB(-3,19,6,minecraft:crying_obsidian,20,minecraft:obsidian,100)
RB(-3,9,7,minecraft:crying_obsidian,20,minecraft:obsidian,100)
RB(-3,10,7,minecraft:crying_obsidian,20,minecraft:obsidian,100)
RB(-3,11,7,minecraft:crying_obsidian,20,minecraft:obsidian,100)
RB(-3,12,7,minecraft:crying_obsidian,20,minecraft:obsidian,100)
RB(-3,13,7,minecraft:crying_obsidian,20,minecraft:obsidian,100)
RB(-3,14,7,minecraft:crying_obsidian,20,minecraft:obsidian,100)
RB(-3,15,7,minecraft:crying_obsidian,20,minecraft:obsidian,100)
RB(-3,16,7,minecraft:crying_obsidian,20,minecraft:obsidian,100)
RB(-3,17,7,minecraft:crying_obsidian,20,minecraft:obsidian,100)
RB(-3,18,7,minecraft:crying_obsidian,20,minecraft:obsidian,100)
RB(-3,19,7,minecraft:crying_obsidian,20,minecraft:obsidian,100)
RB(-3,20,7,minecraft:crying_obsidian,20,minecraft:obsidian,100)
RB(-3,10,8,minecraft:crying_obsidian,20,minecraft:obsidian,100)
RB(-3,11,8,minecraft:crying_obsidian,20,minecraft:obsidian,100)
RB(-3,12,8,minecraft:crying_obsidian,20,minecraft:obsidian,100)
RB(-3,13,8,minecraft:crying_obsidian,20,minecraft:obsidian,100)
RB(-3,14,8,minecraft:crying_obsidian,20,minecraft:obsidian,100)
RB(-3,15,8,minecraft:crying_obsidian,20,minecraft:obsidian,100)
RB(-3,16,8,minecraft:crying_obsidian,20,minecraft:obsidian,100)
RB(-3,17,8,minecraft:crying_obsidian,20,minecraft:obsidian,100)
RB(-3,18,8,minecraft:crying_obsidian,20,minecraft:obsidian,100)
RB(-3,19,8,minecraft:crying_obsidian,20,minecraft:obsidian,100)
RB(-3,20,8,minecraft:crying_obsidian,20,minecraft:obsidian,100)
RB(-3,10,9,minecraft:crying_obsidian,20,minecraft:obsidian,100)
RB(-3,11,9,minecraft:crying_obsidian,20,minecraft:obsidian,100)
RB(-3,12,9,minecraft:crying_obsidian,20,minecraft:obsidian,100)
RB(-3,13,9,minecraft:crying_obsidian,20,minecraft:obsidian,100)
RB(-3,14,9,minecraft:crying_obsidian,20,minecraft:obsidian,100)
RB(-3,15,9,minecraft:crying_obsidian,20,minecraft:obsidian,100)
RB(-3,16,9,minecraft:crying_obsidian,20,minecraft:obsidian,100)
RB(-3,17,9,minecraft:crying_obsidian,20,minecraft:obsidian,100)
RB(-3,18,9,minecraft:crying_obsidian,20,minecraft:obsidian,100)
RB(-3,19,9,minecraft:crying_obsidian,20,minecraft:obsidian,100)
RB(-3,20,9,minecraft:crying_obsidian,20,minecraft:obsidian,100)
RB(-3,11,10,minecraft:crying_obsidian,20,minecraft:obsidian,100)
RB(-3,12,10,minecraft:crying_obsidian,20,minecraft:obsidian,100)
RB(-3,13,10,minecraft:crying_obsidian,20,minecraft:obsidian,100)
RB(-3,14,10,minecraft:crying_obsidian,20,minecraft:obsidian,100)
RB(-3,15,10,minecraft:crying_obsidian,20,minecraft:obsidian,100)
RB(-3,16,10,minecraft:crying_obsidian,20,minecraft:obsidian,100)
RB(-3,17,10,minecraft:crying_obsidian,20,minecraft:obsidian,100)
RB(-3,18,10,minecraft:crying_obsidian,20,minecraft:obsidian,100)
RB(-3,19,10,minecraft:crying_obsidian,20,minecraft:obsidian,100)
RB(-3,20,10,minecraft:crying_obsidian,20,minecraft:obsidian,100)
RB(-3,13,11,minecraft:crying_obsidian,20,minecraft:obsidian,100)
RB(-3,14,11,minecraft:crying_obsidian,20,minecraft:obsidian,100)
RB(-3,15,11,minecraft:crying_obsidian,20,minecraft:obsidian,100)
RB(-3,16,11,minecraft:crying_obsidian,20,minecraft:obsidian,100)
RB(-3,17,11,minecraft:crying_obsidian,20,minecraft:obsidian,100)
RB(-3,18,11,minecraft:crying_obsidian,20,minecraft:obsidian,100)
RB(-2,8,-11,minecraft:crying_obsidian,20,minecraft:obsidian,100)
RB(-2,9,-11,minecraft:crying_obsidian,20,minecraft:obsidian,100)
RB(-2,10,-11,minecraft:crying_obsidian,20,minecraft:obsidian,100)
RB(-2,11,-11,minecraft:crying_obsidian,20,minecraft:obsidian,100)
RB(-2,12,-11,minecraft:crying_obsidian,20,minecraft:obsidian,100)
RB(-2,7,-10,minecraft:crying_obsidian,20,minecraft:obsidian,100)
RB(-2,8,-10,minecraft:crying_obsidian,20,minecraft:obsidian,100)
RB(-2,9,-10,minecraft:crying_obsidian,20,minecraft:obsidian,100)
RB(-2,10,-10,minecraft:crying_obsidian,20,minecraft:obsidian,100)
RB(-2,11,-10,minecraft:crying_obsidian,20,minecraft:obsidian,100)
RB(-2,12,-10,minecraft:crying_obsidian,20,minecraft:obsidian,100)
RB(-2,13,-10,minecraft:crying_obsidian,20,minecraft:obsidian,100)
RB(-2,6,-9,minecraft:crying_obsidian,20,minecraft:obsidian,100)
RB(-2,7,-9,minecraft:crying_obsidian,20,minecraft:obsidian,100)
RB(-2,8,-9,minecraft:crying_obsidian,20,minecraft:obsidian,100)
RB(-2,9,-9,minecraft:crying_obsidian,20,minecraft:obsidian,100)
RB(-2,10,-9,minecraft:crying_obsidian,20,minecraft:obsidian,100)
RB(-2,11,-9,minecraft:crying_obsidian,20,minecraft:obsidian,100)
RB(-2,12,-9,minecraft:crying_obsidian,20,minecraft:obsidian,100)
RB(-2,13,-9,minecraft:crying_obsidian,20,minecraft:obsidian,100)
RB(-2,14,-9,minecraft:crying_obsidian,20,minecraft:obsidian,100)
RB(-2,5,-8,minecraft:crying_obsidian,20,minecraft:obsidian,100)
RB(-2,6,-8,minecraft:crying_obsidian,20,minecraft:obsidian,100)
RB(-2,7,-8,minecraft:crying_obsidian,20,minecraft:obsidian,100)
RB(-2,8,-8,minecraft:crying_obsidian,20,minecraft:obsidian,100)
RB(-2,9,-8,minecraft:crying_obsidian,20,minecraft:obsidian,100)
RB(-2,10,-8,minecraft:crying_obsidian,20,minecraft:obsidian,100)
RB(-2,11,-8,minecraft:crying_obsidian,20,minecraft:obsidian,100)
RB(-2,12,-8,minecraft:crying_obsidian,20,minecraft:obsidian,100)
RB(-2,13,-8,minecraft:crying_obsidian,20,minecraft:obsidian,100)
RB(-2,14,-8,minecraft:crying_obsidian,20,minecraft:obsidian,100)
RB(-2,15,-8,minecraft:crying_obsidian,20,minecraft:obsidian,100)
RB(-2,6,-7,minecraft:crying_obsidian,20,minecraft:obsidian,100)
RB(-2,7,-7,minecraft:crying_obsidian,20,minecraft:obsidian,100)
RB(-2,8,-7,minecraft:crying_obsidian,20,minecraft:obsidian,100)
RB(-2,9,-7,minecraft:crying_obsidian,20,minecraft:obsidian,100)
RB(-2,10,-7,minecraft:crying_obsidian,20,minecraft:obsidian,100)
RB(-2,11,-7,minecraft:crying_obsidian,20,minecraft:obsidian,100)
RB(-2,12,-7,minecraft:crying_obsidian,20,minecraft:obsidian,100)
RB(-2,13,-7,minecraft:crying_obsidian,20,minecraft:obsidian,100)
RB(-2,14,-7,minecraft:crying_obsidian,20,minecraft:obsidian,100)
RB(-2,15,-7,minecraft:crying_obsidian,20,minecraft:obsidian,100)
RB(-2,16,-7,minecraft:crying_obsidian,20,minecraft:obsidian,100)
RB(-2,17,-7,minecraft:crying_obsidian,20,minecraft:obsidian,100)
RB(-2,6,-6,minecraft:crying_obsidian,20,minecraft:obsidian,100)
RB(-2,7,-6,minecraft:crying_obsidian,20,minecraft:obsidian,100)
RB(-2,8,-6,minecraft:crying_obsidian,20,minecraft:obsidian,100)
RB(-2,9,-6,minecraft:crying_obsidian,20,minecraft:obsidian,100)
RB(-2,10,-6,minecraft:crying_obsidian,20,minecraft:obsidian,100)
RB(-2,11,-6,minecraft:crying_obsidian,20,minecraft:obsidian,100)
RB(-2,12,-6,minecraft:crying_obsidian,20,minecraft:obsidian,100)
RB(-2,13,-6,minecraft:crying_obsidian,20,minecraft:obsidian,100)
RB(-2,14,-6,minecraft:crying_obsidian,20,minecraft:obsidian,100)
RB(-2,15,-6,minecraft:crying_obsidian,20,minecraft:obsidian,100)
RB(-2,16,-6,minecraft:crying_obsidian,20,minecraft:obsidian,100)
RB(-2,17,-6,minecraft:crying_obsidian,20,minecraft:obsidian,100)
RB(-2,8,-5,minecraft:crying_obsidian,20,minecraft:obsidian,100)
RB(-2,9,-5,minecraft:crying_obsidian,20,minecraft:obsidian,100)
RB(-2,10,-5,minecraft:crying_obsidian,20,minecraft:obsidian,100)
RB(-2,11,-5,minecraft:crying_obsidian,20,minecraft:obsidian,100)
RB(-2,12,-5,minecraft:crying_obsidian,20,minecraft:obsidian,100)
RB(-2,13,-5,minecraft:crying_obsidian,20,minecraft:obsidian,100)
RB(-2,14,-5,minecraft:crying_obsidian,20,minecraft:obsidian,100)
RB(-2,15,-5,minecraft:crying_obsidian,20,minecraft:obsidian,100)
RB(-2,16,-5,minecraft:crying_obsidian,20,minecraft:obsidian,100)
RB(-2,17,-5,minecraft:crying_obsidian,20,minecraft:obsidian,100)
RB(-2,8,-4,minecraft:crying_obsidian,20,minecraft:obsidian,100)
RB(-2,9,-4,minecraft:crying_obsidian,20,minecraft:obsidian,100)
RB(-2,10,-4,minecraft:crying_obsidian,20,minecraft:obsidian,100)
RB(-2,11,-4,minecraft:crying_obsidian,20,minecraft:obsidian,100)
RB(-2,12,-4,minecraft:crying_obsidian,20,minecraft:obsidian,100)
RB(-2,13,-4,minecraft:crying_obsidian,20,minecraft:obsidian,100)
RB(-2,14,-4,minecraft:crying_obsidian,20,minecraft:obsidian,100)
RB(-2,15,-4,minecraft:crying_obsidian,20,minecraft:obsidian,100)
RB(-2,16,-4,minecraft:crying_obsidian,20,minecraft:obsidian,100)
RB(-2,17,-4,minecraft:crying_obsidian,20,minecraft:obsidian,100)
RB(-2,18,-4,minecraft:crying_obsidian,20,minecraft:obsidian,100)
RB(-2,10,-3,minecraft:crying_obsidian,20,minecraft:obsidian,100)
RB(-2,11,-3,minecraft:crying_obsidian,20,minecraft:obsidian,100)
RB(-2,12,-3,minecraft:crying_obsidian,20,minecraft:obsidian,100)
RB(-2,13,-3,minecraft:crying_obsidian,20,minecraft:obsidian,100)
RB(-2,14,-3,minecraft:crying_obsidian,20,minecraft:obsidian,100)
RB(-2,15,-3,minecraft:crying_obsidian,20,minecraft:obsidian,100)
RB(-2,16,-3,minecraft:crying_obsidian,20,minecraft:obsidian,100)
RB(-2,17,-3,minecraft:crying_obsidian,20,minecraft:obsidian,100)
RB(-2,18,-3,minecraft:crying_obsidian,20,minecraft:obsidian,100)
RB(-2,11,-2,minecraft:crying_obsidian,20,minecraft:obsidian,100)
RB(-2,12,-2,minecraft:crying_obsidian,20,minecraft:obsidian,100)
RB(-2,13,-2,minecraft:crying_obsidian,20,minecraft:obsidian,100)
RB(-2,14,-2,minecraft:crying_obsidian,20,minecraft:obsidian,100)
RB(-2,15,-2,minecraft:crying_obsidian,20,minecraft:obsidian,100)
RB(-2,16,-2,minecraft:crying_obsidian,20,minecraft:obsidian,100)
RB(-2,17,-2,minecraft:crying_obsidian,20,minecraft:obsidian,100)
RB(-2,18,-2,minecraft:crying_obsidian,20,minecraft:obsidian,100)
RB(-2,12,-1,minecraft:crying_obsidian,20,minecraft:obsidian,100)
RB(-2,13,-1,minecraft:crying_obsidian,20,minecraft:obsidian,100)
RB(-2,14,-1,minecraft:crying_obsidian,20,minecraft:obsidian,100)
RB(-2,15,-1,minecraft:crying_obsidian,20,minecraft:obsidian,100)
RB(-2,16,-1,minecraft:crying_obsidian,20,minecraft:obsidian,100)
RB(-2,17,-1,minecraft:crying_obsidian,20,minecraft:obsidian,100)
RB(-2,18,-1,minecraft:crying_obsidian,20,minecraft:obsidian,100)
RB(-2,11,0,minecraft:crying_obsidian,20,minecraft:obsidian,100)
RB(-2,12,0,minecraft:crying_obsidian,20,minecraft:obsidian,100)
RB(-2,13,0,minecraft:crying_obsidian,20,minecraft:obsidian,100)
RB(-2,14,0,minecraft:crying_obsidian,20,minecraft:obsidian,100)
RB(-2,15,0,minecraft:crying_obsidian,20,minecraft:obsidian,100)
RB(-2,16,0,minecraft:crying_obsidian,20,minecraft:obsidian,100)
RB(-2,17,0,minecraft:crying_obsidian,20,minecraft:obsidian,100)
RB(-2,18,0,minecraft:crying_obsidian,20,minecraft:obsidian,100)
RB(-2,10,1,minecraft:crying_obsidian,20,minecraft:obsidian,100)
RB(-2,11,1,minecraft:crying_obsidian,20,minecraft:obsidian,100)
RB(-2,12,1,minecraft:crying_obsidian,20,minecraft:obsidian,100)
RB(-2,13,1,minecraft:crying_obsidian,20,minecraft:obsidian,100)
RB(-2,14,1,minecraft:crying_obsidian,20,minecraft:obsidian,100)
RB(-2,15,1,minecraft:crying_obsidian,20,minecraft:obsidian,100)
RB(-2,16,1,minecraft:crying_obsidian,20,minecraft:obsidian,100)
RB(-2,17,1,minecraft:crying_obsidian,20,minecraft:obsidian,100)
RB(-2,18,1,minecraft:crying_obsidian,20,minecraft:obsidian,100)
RB(-2,8,2,minecraft:crying_obsidian,20,minecraft:obsidian,100)
RB(-2,9,2,minecraft:crying_obsidian,20,minecraft:obsidian,100)
RB(-2,10,2,minecraft:crying_obsidian,20,minecraft:obsidian,100)
RB(-2,11,2,minecraft:crying_obsidian,20,minecraft:obsidian,100)
RB(-2,12,2,minecraft:crying_obsidian,20,minecraft:obsidian,100)
RB(-2,13,2,minecraft:crying_obsidian,20,minecraft:obsidian,100)
RB(-2,14,2,minecraft:crying_obsidian,20,minecraft:obsidian,100)
RB(-2,15,2,minecraft:crying_obsidian,20,minecraft:obsidian,100)
RB(-2,16,2,minecraft:crying_obsidian,20,minecraft:obsidian,100)
RB(-2,17,2,minecraft:crying_obsidian,20,minecraft:obsidian,100)
RB(-2,18,2,minecraft:crying_obsidian,20,minecraft:obsidian,100)
RB(-2,9,3,minecraft:crying_obsidian,20,minecraft:obsidian,100)
RB(-2,10,3,minecraft:crying_obsidian,20,minecraft:obsidian,100)
RB(-2,11,3,minecraft:crying_obsidian,20,minecraft:obsidian,100)
RB(-2,12,3,minecraft:crying_obsidian,20,minecraft:obsidian,100)
RB(-2,13,3,minecraft:crying_obsidian,20,minecraft:obsidian,100)
RB(-2,14,3,minecraft:crying_obsidian,20,minecraft:obsidian,100)
RB(-2,15,3,minecraft:crying_obsidian,20,minecraft:obsidian,100)
RB(-2,16,3,minecraft:crying_obsidian,20,minecraft:obsidian,100)
RB(-2,17,3,minecraft:crying_obsidian,20,minecraft:obsidian,100)
RB(-2,9,4,minecraft:crying_obsidian,20,minecraft:obsidian,100)
RB(-2,10,4,minecraft:crying_obsidian,20,minecraft:obsidian,100)
RB(-2,11,4,minecraft:crying_obsidian,20,minecraft:obsidian,100)
RB(-2,12,4,minecraft:crying_obsidian,20,minecraft:obsidian,100)
RB(-2,13,4,minecraft:crying_obsidian,20,minecraft:obsidian,100)
RB(-2,14,4,minecraft:crying_obsidian,20,minecraft:obsidian,100)
RB(-2,15,4,minecraft:crying_obsidian,20,minecraft:obsidian,100)
RB(-2,16,4,minecraft:crying_obsidian,20,minecraft:obsidian,100)
RB(-2,17,4,minecraft:crying_obsidian,20,minecraft:obsidian,100)
RB(-2,18,4,minecraft:crying_obsidian,20,minecraft:obsidian,100)
RB(-2,9,5,minecraft:crying_obsidian,20,minecraft:obsidian,100)
RB(-2,10,5,minecraft:crying_obsidian,20,minecraft:obsidian,100)
RB(-2,11,5,minecraft:crying_obsidian,20,minecraft:obsidian,100)
RB(-2,12,5,minecraft:crying_obsidian,20,minecraft:obsidian,100)
RB(-2,13,5,minecraft:crying_obsidian,20,minecraft:obsidian,100)
RB(-2,14,5,minecraft:crying_obsidian,20,minecraft:obsidian,100)
RB(-2,15,5,minecraft:crying_obsidian,20,minecraft:obsidian,100)
RB(-2,16,5,minecraft:crying_obsidian,20,minecraft:obsidian,100)
RB(-2,17,5,minecraft:crying_obsidian,20,minecraft:obsidian,100)
RB(-2,18,5,minecraft:crying_obsidian,20,minecraft:obsidian,100)
RB(-2,10,6,minecraft:crying_obsidian,20,minecraft:obsidian,100)
RB(-2,11,6,minecraft:crying_obsidian,20,minecraft:obsidian,100)
RB(-2,12,6,minecraft:crying_obsidian,20,minecraft:obsidian,100)
RB(-2,13,6,minecraft:crying_obsidian,20,minecraft:obsidian,100)
RB(-2,14,6,minecraft:crying_obsidian,20,minecraft:obsidian,100)
RB(-2,15,6,minecraft:crying_obsidian,20,minecraft:obsidian,100)
RB(-2,16,6,minecraft:crying_obsidian,20,minecraft:obsidian,100)
RB(-2,17,6,minecraft:crying_obsidian,20,minecraft:obsidian,100)
RB(-2,18,6,minecraft:crying_obsidian,20,minecraft:obsidian,100)
RB(-2,11,7,minecraft:crying_obsidian,20,minecraft:obsidian,100)
RB(-2,12,7,minecraft:crying_obsidian,20,minecraft:obsidian,100)
RB(-2,13,7,minecraft:crying_obsidian,20,minecraft:obsidian,100)
RB(-2,14,7,minecraft:crying_obsidian,20,minecraft:obsidian,100)
RB(-2,15,7,minecraft:crying_obsidian,20,minecraft:obsidian,100)
RB(-2,16,7,minecraft:crying_obsidian,20,minecraft:obsidian,100)
RB(-2,17,7,minecraft:crying_obsidian,20,minecraft:obsidian,100)
RB(-2,18,7,minecraft:crying_obsidian,20,minecraft:obsidian,100)
RB(-2,11,8,minecraft:crying_obsidian,20,minecraft:obsidian,100)
RB(-2,12,8,minecraft:crying_obsidian,20,minecraft:obsidian,100)
RB(-2,13,8,minecraft:crying_obsidian,20,minecraft:obsidian,100)
RB(-2,14,8,minecraft:crying_obsidian,20,minecraft:obsidian,100)
RB(-2,15,8,minecraft:crying_obsidian,20,minecraft:obsidian,100)
RB(-2,16,8,minecraft:crying_obsidian,20,minecraft:obsidian,100)
RB(-2,17,8,minecraft:crying_obsidian,20,minecraft:obsidian,100)
RB(-2,18,8,minecraft:crying_obsidian,20,minecraft:obsidian,100)
RB(-2,19,8,minecraft:crying_obsidian,20,minecraft:obsidian,100)
RB(-2,12,9,minecraft:crying_obsidian,20,minecraft:obsidian,100)
RB(-2,13,9,minecraft:crying_obsidian,20,minecraft:obsidian,100)
RB(-2,14,9,minecraft:crying_obsidian,20,minecraft:obsidian,100)
RB(-2,15,9,minecraft:crying_obsidian,20,minecraft:obsidian,100)
RB(-2,16,9,minecraft:crying_obsidian,20,minecraft:obsidian,100)
RB(-2,17,9,minecraft:crying_obsidian,20,minecraft:obsidian,100)
RB(-2,18,9,minecraft:crying_obsidian,20,minecraft:obsidian,100)
RB(-2,19,9,minecraft:crying_obsidian,20,minecraft:obsidian,100)
RB(-2,12,10,minecraft:crying_obsidian,20,minecraft:obsidian,100)
RB(-2,13,10,minecraft:crying_obsidian,20,minecraft:obsidian,100)
RB(-2,14,10,minecraft:crying_obsidian,20,minecraft:obsidian,100)
RB(-2,15,10,minecraft:crying_obsidian,20,minecraft:obsidian,100)
RB(-2,16,10,minecraft:crying_obsidian,20,minecraft:obsidian,100)
RB(-2,17,10,minecraft:crying_obsidian,20,minecraft:obsidian,100)
RB(-2,18,10,minecraft:crying_obsidian,20,minecraft:obsidian,100)
RB(-2,13,11,minecraft:crying_obsidian,20,minecraft:obsidian,100)
RB(-2,14,11,minecraft:crying_obsidian,20,minecraft:obsidian,100)
RB(-2,15,11,minecraft:crying_obsidian,20,minecraft:obsidian,100)
RB(-1,8,-11,minecraft:crying_obsidian,20,minecraft:obsidian,100)
RB(-1,9,-11,minecraft:crying_obsidian,20,minecraft:obsidian,100)
RB(-1,10,-11,minecraft:crying_obsidian,20,minecraft:obsidian,100)
RB(-1,11,-11,minecraft:crying_obsidian,20,minecraft:obsidian,100)
RB(-1,12,-11,minecraft:crying_obsidian,20,minecraft:obsidian,100)
RB(-1,7,-10,minecraft:crying_obsidian,20,minecraft:obsidian,100)
RB(-1,8,-10,minecraft:crying_obsidian,20,minecraft:obsidian,100)
RB(-1,9,-10,minecraft:crying_obsidian,20,minecraft:obsidian,100)
RB(-1,10,-10,minecraft:crying_obsidian,20,minecraft:obsidian,100)
RB(-1,11,-10,minecraft:crying_obsidian,20,minecraft:obsidian,100)
RB(-1,12,-10,minecraft:crying_obsidian,20,minecraft:obsidian,100)
RB(-1,13,-10,minecraft:crying_obsidian,20,minecraft:obsidian,100)
RB(-1,6,-9,minecraft:crying_obsidian,20,minecraft:obsidian,100)
RB(-1,7,-9,minecraft:crying_obsidian,20,minecraft:obsidian,100)
RB(-1,8,-9,minecraft:crying_obsidian,20,minecraft:obsidian,100)
RB(-1,9,-9,minecraft:crying_obsidian,20,minecraft:obsidian,100)
RB(-1,10,-9,minecraft:crying_obsidian,20,minecraft:obsidian,100)
RB(-1,11,-9,minecraft:crying_obsidian,20,minecraft:obsidian,100)
RB(-1,12,-9,minecraft:crying_obsidian,20,minecraft:obsidian,100)
RB(-1,13,-9,minecraft:crying_obsidian,20,minecraft:obsidian,100)
RB(-1,14,-9,minecraft:crying_obsidian,20,minecraft:obsidian,100)
RB(-1,5,-8,minecraft:crying_obsidian,20,minecraft:obsidian,100)
RB(-1,6,-8,minecraft:crying_obsidian,20,minecraft:obsidian,100)
RB(-1,7,-8,minecraft:crying_obsidian,20,minecraft:obsidian,100)
RB(-1,8,-8,minecraft:crying_obsidian,20,minecraft:obsidian,100)
RB(-1,9,-8,minecraft:crying_obsidian,20,minecraft:obsidian,100)
RB(-1,10,-8,minecraft:crying_obsidian,20,minecraft:obsidian,100)
RB(-1,11,-8,minecraft:crying_obsidian,20,minecraft:obsidian,100)
RB(-1,12,-8,minecraft:crying_obsidian,20,minecraft:obsidian,100)
RB(-1,13,-8,minecraft:crying_obsidian,20,minecraft:obsidian,100)
RB(-1,14,-8,minecraft:crying_obsidian,20,minecraft:obsidian,100)
RB(-1,15,-8,minecraft:crying_obsidian,20,minecraft:obsidian,100)
RB(-1,16,-8,minecraft:crying_obsidian,20,minecraft:obsidian,100)
RB(-1,6,-7,minecraft:crying_obsidian,20,minecraft:obsidian,100)
RB(-1,7,-7,minecraft:crying_obsidian,20,minecraft:obsidian,100)
RB(-1,8,-7,minecraft:crying_obsidian,20,minecraft:obsidian,100)
RB(-1,9,-7,minecraft:crying_obsidian,20,minecraft:obsidian,100)
RB(-1,10,-7,minecraft:crying_obsidian,20,minecraft:obsidian,100)
RB(-1,11,-7,minecraft:crying_obsidian,20,minecraft:obsidian,100)
RB(-1,12,-7,minecraft:crying_obsidian,20,minecraft:obsidian,100)
RB(-1,13,-7,minecraft:crying_obsidian,20,minecraft:obsidian,100)
RB(-1,14,-7,minecraft:crying_obsidian,20,minecraft:obsidian,100)
RB(-1,15,-7,minecraft:crying_obsidian,20,minecraft:obsidian,100)
RB(-1,16,-7,minecraft:crying_obsidian,20,minecraft:obsidian,100)
RB(-1,17,-7,minecraft:crying_obsidian,20,minecraft:obsidian,100)
RB(-1,6,-6,minecraft:crying_obsidian,20,minecraft:obsidian,100)
RB(-1,7,-6,minecraft:crying_obsidian,20,minecraft:obsidian,100)
RB(-1,8,-6,minecraft:crying_obsidian,20,minecraft:obsidian,100)
RB(-1,9,-6,minecraft:crying_obsidian,20,minecraft:obsidian,100)
RB(-1,10,-6,minecraft:crying_obsidian,20,minecraft:obsidian,100)
RB(-1,11,-6,minecraft:crying_obsidian,20,minecraft:obsidian,100)
RB(-1,12,-6,minecraft:crying_obsidian,20,minecraft:obsidian,100)
RB(-1,13,-6,minecraft:crying_obsidian,20,minecraft:obsidian,100)
RB(-1,14,-6,minecraft:crying_obsidian,20,minecraft:obsidian,100)
RB(-1,15,-6,minecraft:crying_obsidian,20,minecraft:obsidian,100)
RB(-1,16,-6,minecraft:crying_obsidian,20,minecraft:obsidian,100)
RB(-1,17,-6,minecraft:crying_obsidian,20,minecraft:obsidian,100)
RB(-1,8,-5,minecraft:crying_obsidian,20,minecraft:obsidian,100)
RB(-1,9,-5,minecraft:crying_obsidian,20,minecraft:obsidian,100)
RB(-1,10,-5,minecraft:crying_obsidian,20,minecraft:obsidian,100)
RB(-1,11,-5,minecraft:crying_obsidian,20,minecraft:obsidian,100)
RB(-1,12,-5,minecraft:crying_obsidian,20,minecraft:obsidian,100)
RB(-1,13,-5,minecraft:crying_obsidian,20,minecraft:obsidian,100)
RB(-1,14,-5,minecraft:crying_obsidian,20,minecraft:obsidian,100)
RB(-1,15,-5,minecraft:crying_obsidian,20,minecraft:obsidian,100)
RB(-1,16,-5,minecraft:crying_obsidian,20,minecraft:obsidian,100)
RB(-1,17,-5,minecraft:crying_obsidian,20,minecraft:obsidian,100)
RB(-1,8,-4,minecraft:crying_obsidian,20,minecraft:obsidian,100)
RB(-1,9,-4,minecraft:crying_obsidian,20,minecraft:obsidian,100)
RB(-1,10,-4,minecraft:crying_obsidian,20,minecraft:obsidian,100)
RB(-1,11,-4,minecraft:crying_obsidian,20,minecraft:obsidian,100)
RB(-1,12,-4,minecraft:crying_obsidian,20,minecraft:obsidian,100)
RB(-1,13,-4,minecraft:crying_obsidian,20,minecraft:obsidian,100)
RB(-1,14,-4,minecraft:crying_obsidian,20,minecraft:obsidian,100)
RB(-1,15,-4,minecraft:crying_obsidian,20,minecraft:obsidian,100)
RB(-1,16,-4,minecraft:crying_obsidian,20,minecraft:obsidian,100)
RB(-1,17,-4,minecraft:crying_obsidian,20,minecraft:obsidian,100)
RB(-1,10,-3,minecraft:crying_obsidian,20,minecraft:obsidian,100)
RB(-1,11,-3,minecraft:crying_obsidian,20,minecraft:obsidian,100)
RB(-1,12,-3,minecraft:crying_obsidian,20,minecraft:obsidian,100)
RB(-1,13,-3,minecraft:crying_obsidian,20,minecraft:obsidian,100)
RB(-1,14,-3,minecraft:crying_obsidian,20,minecraft:obsidian,100)
RB(-1,15,-3,minecraft:crying_obsidian,20,minecraft:obsidian,100)
RB(-1,16,-3,minecraft:crying_obsidian,20,minecraft:obsidian,100)
RB(-1,17,-3,minecraft:crying_obsidian,20,minecraft:obsidian,100)
RB(-1,18,-3,minecraft:crying_obsidian,20,minecraft:obsidian,100)
RB(-1,11,-2,minecraft:crying_obsidian,20,minecraft:obsidian,100)
RB(-1,12,-2,minecraft:crying_obsidian,20,minecraft:obsidian,100)
RB(-1,13,-2,minecraft:crying_obsidian,20,minecraft:obsidian,100)
RB(-1,14,-2,minecraft:crying_obsidian,20,minecraft:obsidian,100)
RB(-1,15,-2,minecraft:crying_obsidian,20,minecraft:obsidian,100)
RB(-1,16,-2,minecraft:crying_obsidian,20,minecraft:obsidian,100)
RB(-1,17,-2,minecraft:crying_obsidian,20,minecraft:obsidian,100)
RB(-1,18,-2,minecraft:crying_obsidian,20,minecraft:obsidian,100)
RB(-1,19,-2,minecraft:crying_obsidian,20,minecraft:obsidian,100)
RB(-1,12,-1,minecraft:crying_obsidian,20,minecraft:obsidian,100)
RB(-1,13,-1,minecraft:crying_obsidian,20,minecraft:obsidian,100)
RB(-1,14,-1,minecraft:crying_obsidian,20,minecraft:obsidian,100)
RB(-1,15,-1,minecraft:crying_obsidian,20,minecraft:obsidian,100)
RB(-1,16,-1,minecraft:crying_obsidian,20,minecraft:obsidian,100)
RB(-1,17,-1,minecraft:crying_obsidian,20,minecraft:obsidian,100)
RB(-1,18,-1,minecraft:crying_obsidian,20,minecraft:obsidian,100)
RB(-1,10,0,minecraft:crying_obsidian,20,minecraft:obsidian,100)
RB(-1,11,0,minecraft:crying_obsidian,20,minecraft:obsidian,100)
RB(-1,12,0,minecraft:crying_obsidian,20,minecraft:obsidian,100)
RB(-1,13,0,minecraft:crying_obsidian,20,minecraft:obsidian,100)
RB(-1,14,0,minecraft:crying_obsidian,20,minecraft:obsidian,100)
RB(-1,15,0,minecraft:crying_obsidian,20,minecraft:obsidian,100)
RB(-1,16,0,minecraft:crying_obsidian,20,minecraft:obsidian,100)
RB(-1,17,0,minecraft:crying_obsidian,20,minecraft:obsidian,100)
RB(-1,18,0,minecraft:crying_obsidian,20,minecraft:obsidian,100)
RB(-1,9,1,minecraft:crying_obsidian,20,minecraft:obsidian,100)
RB(-1,10,1,minecraft:crying_obsidian,20,minecraft:obsidian,100)
RB(-1,11,1,minecraft:crying_obsidian,20,minecraft:obsidian,100)
RB(-1,12,1,minecraft:crying_obsidian,20,minecraft:obsidian,100)
RB(-1,13,1,minecraft:crying_obsidian,20,minecraft:obsidian,100)
RB(-1,14,1,minecraft:crying_obsidian,20,minecraft:obsidian,100)
RB(-1,15,1,minecraft:crying_obsidian,20,minecraft:obsidian,100)
RB(-1,16,1,minecraft:crying_obsidian,20,minecraft:obsidian,100)
RB(-1,17,1,minecraft:crying_obsidian,20,minecraft:obsidian,100)
RB(-1,18,1,minecraft:crying_obsidian,20,minecraft:obsidian,100)
RB(-1,19,1,minecraft:crying_obsidian,20,minecraft:obsidian,100)
RB(-1,8,2,minecraft:crying_obsidian,20,minecraft:obsidian,100)
RB(-1,9,2,minecraft:crying_obsidian,20,minecraft:obsidian,100)
RB(-1,10,2,minecraft:crying_obsidian,20,minecraft:obsidian,100)
RB(-1,11,2,minecraft:crying_obsidian,20,minecraft:obsidian,100)
RB(-1,12,2,minecraft:crying_obsidian,20,minecraft:obsidian,100)
RB(-1,13,2,minecraft:crying_obsidian,20,minecraft:obsidian,100)
RB(-1,14,2,minecraft:crying_obsidian,20,minecraft:obsidian,100)
RB(-1,15,2,minecraft:crying_obsidian,20,minecraft:obsidian,100)
RB(-1,16,2,minecraft:crying_obsidian,20,minecraft:obsidian,100)
RB(-1,17,2,minecraft:crying_obsidian,20,minecraft:obsidian,100)
RB(-1,18,2,minecraft:crying_obsidian,20,minecraft:obsidian,100)
RB(-1,8,3,minecraft:crying_obsidian,20,minecraft:obsidian,100)
RB(-1,9,3,minecraft:crying_obsidian,20,minecraft:obsidian,100)
RB(-1,10,3,minecraft:crying_obsidian,20,minecraft:obsidian,100)
RB(-1,11,3,minecraft:crying_obsidian,20,minecraft:obsidian,100)
RB(-1,12,3,minecraft:crying_obsidian,20,minecraft:obsidian,100)
RB(-1,13,3,minecraft:crying_obsidian,20,minecraft:obsidian,100)
RB(-1,14,3,minecraft:crying_obsidian,20,minecraft:obsidian,100)
RB(-1,15,3,minecraft:crying_obsidian,20,minecraft:obsidian,100)
RB(-1,16,3,minecraft:crying_obsidian,20,minecraft:obsidian,100)
RB(-1,17,3,minecraft:crying_obsidian,20,minecraft:obsidian,100)
RB(-1,18,3,minecraft:crying_obsidian,20,minecraft:obsidian,100)
RB(-1,9,4,minecraft:crying_obsidian,20,minecraft:obsidian,100)
RB(-1,10,4,minecraft:crying_obsidian,20,minecraft:obsidian,100)
RB(-1,11,4,minecraft:crying_obsidian,20,minecraft:obsidian,100)
RB(-1,12,4,minecraft:crying_obsidian,20,minecraft:obsidian,100)
RB(-1,13,4,minecraft:crying_obsidian,20,minecraft:obsidian,100)
RB(-1,14,4,minecraft:crying_obsidian,20,minecraft:obsidian,100)
RB(-1,15,4,minecraft:crying_obsidian,20,minecraft:obsidian,100)
RB(-1,16,4,minecraft:crying_obsidian,20,minecraft:obsidian,100)
RB(-1,17,4,minecraft:crying_obsidian,20,minecraft:obsidian,100)
RB(-1,9,5,minecraft:crying_obsidian,20,minecraft:obsidian,100)
RB(-1,10,5,minecraft:crying_obsidian,20,minecraft:obsidian,100)
RB(-1,11,5,minecraft:crying_obsidian,20,minecraft:obsidian,100)
RB(-1,12,5,minecraft:crying_obsidian,20,minecraft:obsidian,100)
RB(-1,13,5,minecraft:crying_obsidian,20,minecraft:obsidian,100)
RB(-1,14,5,minecraft:crying_obsidian,20,minecraft:obsidian,100)
RB(-1,15,5,minecraft:crying_obsidian,20,minecraft:obsidian,100)
RB(-1,16,5,minecraft:crying_obsidian,20,minecraft:obsidian,100)
RB(-1,17,5,minecraft:crying_obsidian,20,minecraft:obsidian,100)
RB(-1,11,6,minecraft:crying_obsidian,20,minecraft:obsidian,100)
RB(-1,12,6,minecraft:crying_obsidian,20,minecraft:obsidian,100)
RB(-1,13,6,minecraft:crying_obsidian,20,minecraft:obsidian,100)
RB(-1,14,6,minecraft:crying_obsidian,20,minecraft:obsidian,100)
RB(-1,15,6,minecraft:crying_obsidian,20,minecraft:obsidian,100)
RB(-1,16,6,minecraft:crying_obsidian,20,minecraft:obsidian,100)
RB(-1,17,6,minecraft:crying_obsidian,20,minecraft:obsidian,100)
RB(-1,12,7,minecraft:crying_obsidian,20,minecraft:obsidian,100)
RB(-1,13,7,minecraft:crying_obsidian,20,minecraft:obsidian,100)
RB(-1,14,7,minecraft:crying_obsidian,20,minecraft:obsidian,100)
RB(-1,15,7,minecraft:crying_obsidian,20,minecraft:obsidian,100)
RB(-1,16,7,minecraft:crying_obsidian,20,minecraft:obsidian,100)
RB(-1,17,7,minecraft:crying_obsidian,20,minecraft:obsidian,100)
RB(-1,13,8,minecraft:crying_obsidian,20,minecraft:obsidian,100)
RB(-1,14,8,minecraft:crying_obsidian,20,minecraft:obsidian,100)
RB(-1,15,8,minecraft:crying_obsidian,20,minecraft:obsidian,100)
RB(-1,16,8,minecraft:crying_obsidian,20,minecraft:obsidian,100)
RB(-1,17,8,minecraft:crying_obsidian,20,minecraft:obsidian,100)
RB(-1,13,9,minecraft:crying_obsidian,20,minecraft:obsidian,100)
RB(-1,14,9,minecraft:crying_obsidian,20,minecraft:obsidian,100)
RB(-1,15,9,minecraft:crying_obsidian,20,minecraft:obsidian,100)
RB(-1,16,9,minecraft:crying_obsidian,20,minecraft:obsidian,100)
RB(-1,17,9,minecraft:crying_obsidian,20,minecraft:obsidian,100)
RB(-1,13,10,minecraft:crying_obsidian,20,minecraft:obsidian,100)
RB(-1,14,10,minecraft:crying_obsidian,20,minecraft:obsidian,100)
RB(-1,15,10,minecraft:crying_obsidian,20,minecraft:obsidian,100)
RB(-1,16,10,minecraft:crying_obsidian,20,minecraft:obsidian,100)
RB(-1,17,10,minecraft:crying_obsidian,20,minecraft:obsidian,100)
RB(-1,12,11,minecraft:crying_obsidian,20,minecraft:obsidian,100)
RB(-1,13,11,minecraft:crying_obsidian,20,minecraft:obsidian,100)
RB(-1,14,11,minecraft:crying_obsidian,20,minecraft:obsidian,100)
RB(-1,15,11,minecraft:crying_obsidian,20,minecraft:obsidian,100)
RB(-1,16,11,minecraft:crying_obsidian,20,minecraft:obsidian,100)
RB(-1,17,11,minecraft:crying_obsidian,20,minecraft:obsidian,100)
RB(-1,13,12,minecraft:crying_obsidian,20,minecraft:obsidian,100)
RB(-1,14,12,minecraft:crying_obsidian,20,minecraft:obsidian,100)
RB(-1,15,12,minecraft:crying_obsidian,20,minecraft:obsidian,100)
RB(-1,16,12,minecraft:crying_obsidian,20,minecraft:obsidian,100)
RB(0,8,-11,minecraft:crying_obsidian,20,minecraft:obsidian,100)
RB(0,9,-11,minecraft:crying_obsidian,20,minecraft:obsidian,100)
RB(0,10,-11,minecraft:crying_obsidian,20,minecraft:obsidian,100)
RB(0,11,-11,minecraft:crying_obsidian,20,minecraft:obsidian,100)
RB(0,12,-11,minecraft:crying_obsidian,20,minecraft:obsidian,100)
RB(0,7,-10,minecraft:crying_obsidian,20,minecraft:obsidian,100)
RB(0,8,-10,minecraft:crying_obsidian,20,minecraft:obsidian,100)
RB(0,9,-10,minecraft:crying_obsidian,20,minecraft:obsidian,100)
RB(0,10,-10,minecraft:crying_obsidian,20,minecraft:obsidian,100)
RB(0,11,-10,minecraft:crying_obsidian,20,minecraft:obsidian,100)
RB(0,12,-10,minecraft:crying_obsidian,20,minecraft:obsidian,100)
RB(0,13,-10,minecraft:crying_obsidian,20,minecraft:obsidian,100)
RB(0,6,-9,minecraft:crying_obsidian,20,minecraft:obsidian,100)
RB(0,7,-9,minecraft:crying_obsidian,20,minecraft:obsidian,100)
RB(0,8,-9,minecraft:crying_obsidian,20,minecraft:obsidian,100)
RB(0,9,-9,minecraft:crying_obsidian,20,minecraft:obsidian,100)
RB(0,10,-9,minecraft:crying_obsidian,20,minecraft:obsidian,100)
RB(0,11,-9,minecraft:crying_obsidian,20,minecraft:obsidian,100)
RB(0,12,-9,minecraft:crying_obsidian,20,minecraft:obsidian,100)
RB(0,13,-9,minecraft:crying_obsidian,20,minecraft:obsidian,100)
RB(0,14,-9,minecraft:crying_obsidian,20,minecraft:obsidian,100)
RB(0,5,-8,minecraft:crying_obsidian,20,minecraft:obsidian,100)
RB(0,6,-8,minecraft:crying_obsidian,20,minecraft:obsidian,100)
RB(0,7,-8,minecraft:crying_obsidian,20,minecraft:obsidian,100)
RB(0,8,-8,minecraft:crying_obsidian,20,minecraft:obsidian,100)
RB(0,9,-8,minecraft:crying_obsidian,20,minecraft:obsidian,100)
RB(0,10,-8,minecraft:crying_obsidian,20,minecraft:obsidian,100)
RB(0,11,-8,minecraft:crying_obsidian,20,minecraft:obsidian,100)
RB(0,12,-8,minecraft:crying_obsidian,20,minecraft:obsidian,100)
RB(0,13,-8,minecraft:crying_obsidian,20,minecraft:obsidian,100)
RB(0,14,-8,minecraft:crying_obsidian,20,minecraft:obsidian,100)
RB(0,15,-8,minecraft:crying_obsidian,20,minecraft:obsidian,100)
RB(0,16,-8,minecraft:crying_obsidian,20,minecraft:obsidian,100)
RB(0,5,-7,minecraft:crying_obsidian,20,minecraft:obsidian,100)
RB(0,6,-7,minecraft:crying_obsidian,20,minecraft:obsidian,100)
RB(0,7,-7,minecraft:crying_obsidian,20,minecraft:obsidian,100)
RB(0,8,-7,minecraft:crying_obsidian,20,minecraft:obsidian,100)
RB(0,9,-7,minecraft:crying_obsidian,20,minecraft:obsidian,100)
RB(0,10,-7,minecraft:crying_obsidian,20,minecraft:obsidian,100)
RB(0,11,-7,minecraft:crying_obsidian,20,minecraft:obsidian,100)
RB(0,12,-7,minecraft:crying_obsidian,20,minecraft:obsidian,100)
RB(0,13,-7,minecraft:crying_obsidian,20,minecraft:obsidian,100)
RB(0,14,-7,minecraft:crying_obsidian,20,minecraft:obsidian,100)
RB(0,15,-7,minecraft:crying_obsidian,20,minecraft:obsidian,100)
RB(0,16,-7,minecraft:crying_obsidian,20,minecraft:obsidian,100)
RB(0,17,-7,minecraft:crying_obsidian,20,minecraft:obsidian,100)
RB(0,6,-6,minecraft:crying_obsidian,20,minecraft:obsidian,100)
RB(0,7,-6,minecraft:crying_obsidian,20,minecraft:obsidian,100)
RB(0,8,-6,minecraft:crying_obsidian,20,minecraft:obsidian,100)
RB(0,9,-6,minecraft:crying_obsidian,20,minecraft:obsidian,100)
RB(0,10,-6,minecraft:crying_obsidian,20,minecraft:obsidian,100)
RB(0,11,-6,minecraft:crying_obsidian,20,minecraft:obsidian,100)
RB(0,12,-6,minecraft:crying_obsidian,20,minecraft:obsidian,100)
RB(0,13,-6,minecraft:crying_obsidian,20,minecraft:obsidian,100)
RB(0,14,-6,minecraft:crying_obsidian,20,minecraft:obsidian,100)
RB(0,15,-6,minecraft:crying_obsidian,20,minecraft:obsidian,100)
RB(0,16,-6,minecraft:crying_obsidian,20,minecraft:obsidian,100)
RB(0,17,-6,minecraft:crying_obsidian,20,minecraft:obsidian,100)
RB(0,18,-6,minecraft:crying_obsidian,20,minecraft:obsidian,100)
RB(0,7,-5,minecraft:crying_obsidian,20,minecraft:obsidian,100)
RB(0,8,-5,minecraft:crying_obsidian,20,minecraft:obsidian,100)
RB(0,9,-5,minecraft:crying_obsidian,20,minecraft:obsidian,100)
RB(0,10,-5,minecraft:crying_obsidian,20,minecraft:obsidian,100)
RB(0,11,-5,minecraft:crying_obsidian,20,minecraft:obsidian,100)
RB(0,12,-5,minecraft:crying_obsidian,20,minecraft:obsidian,100)
RB(0,13,-5,minecraft:crying_obsidian,20,minecraft:obsidian,100)
RB(0,14,-5,minecraft:crying_obsidian,20,minecraft:obsidian,100)
RB(0,15,-5,minecraft:crying_obsidian,20,minecraft:obsidian,100)
RB(0,16,-5,minecraft:crying_obsidian,20,minecraft:obsidian,100)
RB(0,17,-5,minecraft:crying_obsidian,20,minecraft:obsidian,100)
RB(0,18,-5,minecraft:crying_obsidian,20,minecraft:obsidian,100)
RB(0,9,-4,minecraft:crying_obsidian,20,minecraft:obsidian,100)
RB(0,10,-4,minecraft:crying_obsidian,20,minecraft:obsidian,100)
RB(0,11,-4,minecraft:crying_obsidian,20,minecraft:obsidian,100)
RB(0,12,-4,minecraft:crying_obsidian,20,minecraft:obsidian,100)
RB(0,13,-4,minecraft:crying_obsidian,20,minecraft:obsidian,100)
RB(0,14,-4,minecraft:crying_obsidian,20,minecraft:obsidian,100)
RB(0,15,-4,minecraft:crying_obsidian,20,minecraft:obsidian,100)
RB(0,16,-4,minecraft:crying_obsidian,20,minecraft:obsidian,100)
RB(0,17,-4,minecraft:crying_obsidian,20,minecraft:obsidian,100)
RB(0,18,-4,minecraft:crying_obsidian,20,minecraft:obsidian,100)
RB(0,9,-3,minecraft:crying_obsidian,20,minecraft:obsidian,100)
RB(0,10,-3,minecraft:crying_obsidian,20,minecraft:obsidian,100)
RB(0,11,-3,minecraft:crying_obsidian,20,minecraft:obsidian,100)
RB(0,12,-3,minecraft:crying_obsidian,20,minecraft:obsidian,100)
RB(0,13,-3,minecraft:crying_obsidian,20,minecraft:obsidian,100)
RB(0,14,-3,minecraft:crying_obsidian,20,minecraft:obsidian,100)
RB(0,15,-3,minecraft:crying_obsidian,20,minecraft:obsidian,100)
RB(0,16,-3,minecraft:crying_obsidian,20,minecraft:obsidian,100)
RB(0,17,-3,minecraft:crying_obsidian,20,minecraft:obsidian,100)
RB(0,18,-3,minecraft:crying_obsidian,20,minecraft:obsidian,100)
RB(0,11,-2,minecraft:crying_obsidian,20,minecraft:obsidian,100)
RB(0,12,-2,minecraft:crying_obsidian,20,minecraft:obsidian,100)
RB(0,13,-2,minecraft:crying_obsidian,20,minecraft:obsidian,100)
RB(0,14,-2,minecraft:crying_obsidian,20,minecraft:obsidian,100)
RB(0,15,-2,minecraft:crying_obsidian,20,minecraft:obsidian,100)
RB(0,16,-2,minecraft:crying_obsidian,20,minecraft:obsidian,100)
RB(0,17,-2,minecraft:crying_obsidian,20,minecraft:obsidian,100)
RB(0,18,-2,minecraft:crying_obsidian,20,minecraft:obsidian,100)
RB(0,8,-1,minecraft:crying_obsidian,20,minecraft:obsidian,100)
RB(0,9,-1,minecraft:crying_obsidian,20,minecraft:obsidian,100)
RB(0,10,-1,minecraft:crying_obsidian,20,minecraft:obsidian,100)
RB(0,11,-1,minecraft:crying_obsidian,20,minecraft:obsidian,100)
RB(0,12,-1,minecraft:crying_obsidian,20,minecraft:obsidian,100)
RB(0,13,-1,minecraft:crying_obsidian,20,minecraft:obsidian,100)
RB(0,14,-1,minecraft:crying_obsidian,20,minecraft:obsidian,100)
RB(0,15,-1,minecraft:crying_obsidian,20,minecraft:obsidian,100)
RB(0,16,-1,minecraft:crying_obsidian,20,minecraft:obsidian,100)
RB(0,17,-1,minecraft:crying_obsidian,20,minecraft:obsidian,100)
RB(0,18,-1,minecraft:crying_obsidian,20,minecraft:obsidian,100)
RB(0,8,0,minecraft:crying_obsidian,20,minecraft:obsidian,100)
RB(0,9,0,minecraft:crying_obsidian,20,minecraft:obsidian,100)
RB(0,10,0,minecraft:crying_obsidian,20,minecraft:obsidian,100)
RB(0,11,0,minecraft:crying_obsidian,20,minecraft:obsidian,100)
RB(0,12,0,minecraft:crying_obsidian,20,minecraft:obsidian,100)
RB(0,13,0,minecraft:crying_obsidian,20,minecraft:obsidian,100)
RB(0,14,0,minecraft:crying_obsidian,20,minecraft:obsidian,100)
RB(0,15,0,minecraft:crying_obsidian,20,minecraft:obsidian,100)
RB(0,16,0,minecraft:crying_obsidian,20,minecraft:obsidian,100)
RB(0,17,0,minecraft:crying_obsidian,20,minecraft:obsidian,100)
RB(0,18,0,minecraft:crying_obsidian,20,minecraft:obsidian,100)
RB(0,8,1,minecraft:crying_obsidian,20,minecraft:obsidian,100)
RB(0,9,1,minecraft:crying_obsidian,20,minecraft:obsidian,100)
RB(0,10,1,minecraft:crying_obsidian,20,minecraft:obsidian,100)
RB(0,11,1,minecraft:crying_obsidian,20,minecraft:obsidian,100)
RB(0,12,1,minecraft:crying_obsidian,20,minecraft:obsidian,100)
RB(0,13,1,minecraft:crying_obsidian,20,minecraft:obsidian,100)
RB(0,14,1,minecraft:crying_obsidian,20,minecraft:obsidian,100)
RB(0,15,1,minecraft:crying_obsidian,20,minecraft:obsidian,100)
RB(0,16,1,minecraft:crying_obsidian,20,minecraft:obsidian,100)
RB(0,17,1,minecraft:crying_obsidian,20,minecraft:obsidian,100)
RB(0,18,1,minecraft:crying_obsidian,20,minecraft:obsidian,100)
RB(0,8,2,minecraft:crying_obsidian,20,minecraft:obsidian,100)
RB(0,9,2,minecraft:crying_obsidian,20,minecraft:obsidian,100)
RB(0,10,2,minecraft:crying_obsidian,20,minecraft:obsidian,100)
RB(0,11,2,minecraft:crying_obsidian,20,minecraft:obsidian,100)
RB(0,12,2,minecraft:crying_obsidian,20,minecraft:obsidian,100)
RB(0,13,2,minecraft:crying_obsidian,20,minecraft:obsidian,100)
RB(0,14,2,minecraft:crying_obsidian,20,minecraft:obsidian,100)
RB(0,15,2,minecraft:crying_obsidian,20,minecraft:obsidian,100)
RB(0,16,2,minecraft:crying_obsidian,20,minecraft:obsidian,100)
RB(0,17,2,minecraft:crying_obsidian,20,minecraft:obsidian,100)
RB(0,18,2,minecraft:crying_obsidian,20,minecraft:obsidian,100)
RB(0,8,3,minecraft:crying_obsidian,20,minecraft:obsidian,100)
RB(0,9,3,minecraft:crying_obsidian,20,minecraft:obsidian,100)
RB(0,10,3,minecraft:crying_obsidian,20,minecraft:obsidian,100)
RB(0,11,3,minecraft:crying_obsidian,20,minecraft:obsidian,100)
RB(0,12,3,minecraft:crying_obsidian,20,minecraft:obsidian,100)
RB(0,13,3,minecraft:crying_obsidian,20,minecraft:obsidian,100)
RB(0,14,3,minecraft:crying_obsidian,20,minecraft:obsidian,100)
RB(0,15,3,minecraft:crying_obsidian,20,minecraft:obsidian,100)
RB(0,16,3,minecraft:crying_obsidian,20,minecraft:obsidian,100)
RB(0,17,3,minecraft:crying_obsidian,20,minecraft:obsidian,100)
RB(0,18,3,minecraft:crying_obsidian,20,minecraft:obsidian,100)
RB(0,9,4,minecraft:crying_obsidian,20,minecraft:obsidian,100)
RB(0,10,4,minecraft:crying_obsidian,20,minecraft:obsidian,100)
RB(0,11,4,minecraft:crying_obsidian,20,minecraft:obsidian,100)
RB(0,12,4,minecraft:crying_obsidian,20,minecraft:obsidian,100)
RB(0,13,4,minecraft:crying_obsidian,20,minecraft:obsidian,100)
RB(0,14,4,minecraft:crying_obsidian,20,minecraft:obsidian,100)
RB(0,15,4,minecraft:crying_obsidian,20,minecraft:obsidian,100)
RB(0,16,4,minecraft:crying_obsidian,20,minecraft:obsidian,100)
RB(0,17,4,minecraft:crying_obsidian,20,minecraft:obsidian,100)
RB(0,10,5,minecraft:crying_obsidian,20,minecraft:obsidian,100)
RB(0,11,5,minecraft:crying_obsidian,20,minecraft:obsidian,100)
RB(0,12,5,minecraft:crying_obsidian,20,minecraft:obsidian,100)
RB(0,13,5,minecraft:crying_obsidian,20,minecraft:obsidian,100)
RB(0,14,5,minecraft:crying_obsidian,20,minecraft:obsidian,100)
RB(0,15,5,minecraft:crying_obsidian,20,minecraft:obsidian,100)
RB(0,16,5,minecraft:crying_obsidian,20,minecraft:obsidian,100)
RB(0,11,6,minecraft:crying_obsidian,20,minecraft:obsidian,100)
RB(0,12,6,minecraft:crying_obsidian,20,minecraft:obsidian,100)
RB(0,13,6,minecraft:crying_obsidian,20,minecraft:obsidian,100)
RB(0,14,6,minecraft:crying_obsidian,20,minecraft:obsidian,100)
RB(0,15,6,minecraft:crying_obsidian,20,minecraft:obsidian,100)
RB(0,16,6,minecraft:crying_obsidian,20,minecraft:obsidian,100)
RB(0,17,6,minecraft:crying_obsidian,20,minecraft:obsidian,100)
RB(0,12,7,minecraft:crying_obsidian,20,minecraft:obsidian,100)
RB(0,13,7,minecraft:crying_obsidian,20,minecraft:obsidian,100)
RB(0,14,7,minecraft:crying_obsidian,20,minecraft:obsidian,100)
RB(0,15,7,minecraft:crying_obsidian,20,minecraft:obsidian,100)
RB(0,16,7,minecraft:crying_obsidian,20,minecraft:obsidian,100)
RB(0,17,7,minecraft:crying_obsidian,20,minecraft:obsidian,100)
RB(0,18,7,minecraft:crying_obsidian,20,minecraft:obsidian,100)
RB(0,12,8,minecraft:crying_obsidian,20,minecraft:obsidian,100)
RB(0,13,8,minecraft:crying_obsidian,20,minecraft:obsidian,100)
RB(0,14,8,minecraft:crying_obsidian,20,minecraft:obsidian,100)
RB(0,15,8,minecraft:crying_obsidian,20,minecraft:obsidian,100)
RB(0,16,8,minecraft:crying_obsidian,20,minecraft:obsidian,100)
RB(0,17,8,minecraft:crying_obsidian,20,minecraft:obsidian,100)
RB(0,18,8,minecraft:crying_obsidian,20,minecraft:obsidian,100)
RB(0,12,9,minecraft:crying_obsidian,20,minecraft:obsidian,100)
RB(0,13,9,minecraft:crying_obsidian,20,minecraft:obsidian,100)
RB(0,14,9,minecraft:crying_obsidian,20,minecraft:obsidian,100)
RB(0,15,9,minecraft:crying_obsidian,20,minecraft:obsidian,100)
RB(0,16,9,minecraft:crying_obsidian,20,minecraft:obsidian,100)
RB(0,17,9,minecraft:crying_obsidian,20,minecraft:obsidian,100)
RB(0,18,9,minecraft:crying_obsidian,20,minecraft:obsidian,100)
RB(0,12,10,minecraft:crying_obsidian,20,minecraft:obsidian,100)
RB(0,13,10,minecraft:crying_obsidian,20,minecraft:obsidian,100)
RB(0,14,10,minecraft:crying_obsidian,20,minecraft:obsidian,100)
RB(0,15,10,minecraft:crying_obsidian,20,minecraft:obsidian,100)
RB(0,16,10,minecraft:crying_obsidian,20,minecraft:obsidian,100)
RB(0,17,10,minecraft:crying_obsidian,20,minecraft:obsidian,100)
RB(0,18,10,minecraft:crying_obsidian,20,minecraft:obsidian,100)
RB(0,12,11,minecraft:crying_obsidian,20,minecraft:obsidian,100)
RB(0,13,11,minecraft:crying_obsidian,20,minecraft:obsidian,100)
RB(0,14,11,minecraft:crying_obsidian,20,minecraft:obsidian,100)
RB(0,15,11,minecraft:crying_obsidian,20,minecraft:obsidian,100)
RB(0,16,11,minecraft:crying_obsidian,20,minecraft:obsidian,100)
RB(0,17,11,minecraft:crying_obsidian,20,minecraft:obsidian,100)
RB(0,18,11,minecraft:crying_obsidian,20,minecraft:obsidian,100)
RB(0,13,12,minecraft:crying_obsidian,20,minecraft:obsidian,100)
RB(0,14,12,minecraft:crying_obsidian,20,minecraft:obsidian,100)
RB(0,15,12,minecraft:crying_obsidian,20,minecraft:obsidian,100)
RB(0,16,12,minecraft:crying_obsidian,20,minecraft:obsidian,100)
RB(0,17,12,minecraft:crying_obsidian,20,minecraft:obsidian,100)
RB(0,13,13,minecraft:crying_obsidian,20,minecraft:obsidian,100)
RB(0,14,13,minecraft:crying_obsidian,20,minecraft:obsidian,100)
RB(0,15,13,minecraft:crying_obsidian,20,minecraft:obsidian,100)
RB(0,16,13,minecraft:crying_obsidian,20,minecraft:obsidian,100)
RB(1,9,-11,minecraft:crying_obsidian,20,minecraft:obsidian,100)
RB(1,10,-11,minecraft:crying_obsidian,20,minecraft:obsidian,100)
RB(1,11,-11,minecraft:crying_obsidian,20,minecraft:obsidian,100)
RB(1,7,-10,minecraft:crying_obsidian,20,minecraft:obsidian,100)
RB(1,8,-10,minecraft:crying_obsidian,20,minecraft:obsidian,100)
RB(1,9,-10,minecraft:crying_obsidian,20,minecraft:obsidian,100)
RB(1,10,-10,minecraft:crying_obsidian,20,minecraft:obsidian,100)
RB(1,11,-10,minecraft:crying_obsidian,20,minecraft:obsidian,100)
RB(1,12,-10,minecraft:crying_obsidian,20,minecraft:obsidian,100)
RB(1,13,-10,minecraft:crying_obsidian,20,minecraft:obsidian,100)
RB(1,6,-9,minecraft:crying_obsidian,20,minecraft:obsidian,100)
RB(1,7,-9,minecraft:crying_obsidian,20,minecraft:obsidian,100)
RB(1,8,-9,minecraft:crying_obsidian,20,minecraft:obsidian,100)
RB(1,9,-9,minecraft:crying_obsidian,20,minecraft:obsidian,100)
RB(1,10,-9,minecraft:crying_obsidian,20,minecraft:obsidian,100)
RB(1,11,-9,minecraft:crying_obsidian,20,minecraft:obsidian,100)
RB(1,12,-9,minecraft:crying_obsidian,20,minecraft:obsidian,100)
RB(1,13,-9,minecraft:crying_obsidian,20,minecraft:obsidian,100)
RB(1,14,-9,minecraft:crying_obsidian,20,minecraft:obsidian,100)
RB(1,6,-8,minecraft:crying_obsidian,20,minecraft:obsidian,100)
RB(1,7,-8,minecraft:crying_obsidian,20,minecraft:obsidian,100)
RB(1,8,-8,minecraft:crying_obsidian,20,minecraft:obsidian,100)
RB(1,9,-8,minecraft:crying_obsidian,20,minecraft:obsidian,100)
RB(1,10,-8,minecraft:crying_obsidian,20,minecraft:obsidian,100)
RB(1,11,-8,minecraft:crying_obsidian,20,minecraft:obsidian,100)
RB(1,12,-8,minecraft:crying_obsidian,20,minecraft:obsidian,100)
