#######################################################################
# +-----------------------------------------------------------------+ #
# |                            BO3 object                           | #
# +-----------------------------------------------------------------+ #
#######################################################################

Author: Frank

Description: Floating bit of obsidian - Modified by Bo3BulkEdit

Version: 3

SettingsMode: WriteDisable

#######################################################################
# +-----------------------------------------------------------------+ #
# |                          Main settings                          | #
# +-----------------------------------------------------------------+ #
#######################################################################

IsOTGPlus: false
Tree: true
Frequency: 2
Rarity: 10.0
RotateRandomly: true
SpawnHeight: randomY
SpawnHeightOffset: 0
SpawnHeightVariance: 0
MaxBranchDepth: 10
ExcludedBiomes: All

ExtrudeMode: None
ExtrudeThroughBlocks: minecraft:air

##############################
# Height Limits for the BO3. #
##############################

MinHeight: 90
MaxHeight: 120

#######################################################################
# +-----------------------------------------------------------------+ #
# |                      Source block settings                      | #
# +-----------------------------------------------------------------+ #
#######################################################################

SourceBlocks: AIR
MaxPercentageOutsideSourceBlock: 0
OutsideSourceBlock: placeAnyway

RemoveAir: true
ReplaceBelow: OBSIDIAN
ReplaceWithBiomeBlocks: false
ReplaceWithGroundBlock: OBSIDIAN
ReplaceWithSurfaceBlock: OBSIDIAN
ReplaceWithStoneBlock: OBSIDIAN
SmoothRadius: 30
SmoothingSurfaceBlock: OBSIDIAN
SmoothingGroundBlock: OBSIDIAN
DoReplaceBlocks: true

#######################################################################
# +-----------------------------------------------------------------+ #
# |                              Blocks                             | #
# +-----------------------------------------------------------------+ #
#######################################################################

RB(-13,18,8,minecraft:crying_obsidian,20,minecraft:obsidian,100)
RB(-13,19,8,minecraft:crying_obsidian,20,minecraft:obsidian,100)
RB(-13,20,8,minecraft:crying_obsidian,20,minecraft:obsidian,100)
RB(-13,14,9,minecraft:crying_obsidian,20,minecraft:obsidian,100)
RB(-13,15,9,minecraft:crying_obsidian,20,minecraft:obsidian,100)
RB(-13,16,9,minecraft:crying_obsidian,20,minecraft:obsidian,100)
RB(-13,17,9,minecraft:crying_obsidian,20,minecraft:obsidian,100)
RB(-13,18,9,minecraft:crying_obsidian,20,minecraft:obsidian,100)
RB(-13,19,9,minecraft:crying_obsidian,20,minecraft:obsidian,100)
RB(-13,20,9,minecraft:crying_obsidian,20,minecraft:obsidian,100)
RB(-13,14,10,minecraft:crying_obsidian,20,minecraft:obsidian,100)
RB(-13,15,10,minecraft:crying_obsidian,20,minecraft:obsidian,100)
RB(-13,16,10,minecraft:crying_obsidian,20,minecraft:obsidian,100)
RB(-13,17,10,minecraft:crying_obsidian,20,minecraft:obsidian,100)
RB(-13,18,10,minecraft:crying_obsidian,20,minecraft:obsidian,100)
RB(-13,19,10,minecraft:crying_obsidian,20,minecraft:obsidian,100)
RB(-13,20,10,minecraft:crying_obsidian,20,minecraft:obsidian,100)
RB(-13,14,11,minecraft:crying_obsidian,20,minecraft:obsidian,100)
RB(-13,15,11,minecraft:crying_obsidian,20,minecraft:obsidian,100)
RB(-13,16,11,minecraft:crying_obsidian,20,minecraft:obsidian,100)
RB(-13,17,11,minecraft:crying_obsidian,20,minecraft:obsidian,100)
RB(-13,18,11,minecraft:crying_obsidian,20,minecraft:obsidian,100)
RB(-13,19,11,minecraft:crying_obsidian,20,minecraft:obsidian,100)
RB(-13,20,11,minecraft:crying_obsidian,20,minecraft:obsidian,100)
RB(-13,15,12,minecraft:crying_obsidian,20,minecraft:obsidian,100)
RB(-13,16,12,minecraft:crying_obsidian,20,minecraft:obsidian,100)
RB(-13,17,12,minecraft:crying_obsidian,20,minecraft:obsidian,100)
RB(-13,18,12,minecraft:crying_obsidian,20,minecraft:obsidian,100)
RB(-12,19,7,minecraft:crying_obsidian,20,minecraft:obsidian,100)
RB(-12,20,7,minecraft:crying_obsidian,20,minecraft:obsidian,100)
RB(-12,21,7,minecraft:crying_obsidian,20,minecraft:obsidian,100)
RB(-12,13,8,minecraft:crying_obsidian,20,minecraft:obsidian,100)
RB(-12,14,8,minecraft:crying_obsidian,20,minecraft:obsidian,100)
RB(-12,15,8,minecraft:crying_obsidian,20,minecraft:obsidian,100)
RB(-12,16,8,minecraft:crying_obsidian,20,minecraft:obsidian,100)
RB(-12,17,8,minecraft:crying_obsidian,20,minecraft:obsidian,100)
RB(-12,18,8,minecraft:crying_obsidian,20,minecraft:obsidian,100)
RB(-12,19,8,minecraft:crying_obsidian,20,minecraft:obsidian,100)
RB(-12,20,8,minecraft:crying_obsidian,20,minecraft:obsidian,100)
RB(-12,21,8,minecraft:crying_obsidian,20,minecraft:obsidian,100)
RB(-12,22,8,minecraft:crying_obsidian,20,minecraft:obsidian,100)
RB(-12,13,9,minecraft:crying_obsidian,20,minecraft:obsidian,100)
RB(-12,14,9,minecraft:crying_obsidian,20,minecraft:obsidian,100)
RB(-12,15,9,minecraft:crying_obsidian,20,minecraft:obsidian,100)
RB(-12,16,9,minecraft:crying_obsidian,20,minecraft:obsidian,100)
RB(-12,17,9,minecraft:crying_obsidian,20,minecraft:obsidian,100)
RB(-12,18,9,minecraft:crying_obsidian,20,minecraft:obsidian,100)
RB(-12,19,9,minecraft:crying_obsidian,20,minecraft:obsidian,100)
RB(-12,20,9,minecraft:crying_obsidian,20,minecraft:obsidian,100)
RB(-12,21,9,minecraft:crying_obsidian,20,minecraft:obsidian,100)
RB(-12,13,10,minecraft:crying_obsidian,20,minecraft:obsidian,100)
RB(-12,14,10,minecraft:crying_obsidian,20,minecraft:obsidian,100)
RB(-12,15,10,minecraft:crying_obsidian,20,minecraft:obsidian,100)
RB(-12,16,10,minecraft:crying_obsidian,20,minecraft:obsidian,100)
RB(-12,17,10,minecraft:crying_obsidian,20,minecraft:obsidian,100)
RB(-12,18,10,minecraft:crying_obsidian,20,minecraft:obsidian,100)
RB(-12,19,10,minecraft:crying_obsidian,20,minecraft:obsidian,100)
RB(-12,20,10,minecraft:crying_obsidian,20,minecraft:obsidian,100)
RB(-12,21,10,minecraft:crying_obsidian,20,minecraft:obsidian,100)
RB(-12,13,11,minecraft:crying_obsidian,20,minecraft:obsidian,100)
RB(-12,14,11,minecraft:crying_obsidian,20,minecraft:obsidian,100)
RB(-12,15,11,minecraft:crying_obsidian,20,minecraft:obsidian,100)
RB(-12,16,11,minecraft:crying_obsidian,20,minecraft:obsidian,100)
RB(-12,17,11,minecraft:crying_obsidian,20,minecraft:obsidian,100)
RB(-12,18,11,minecraft:crying_obsidian,20,minecraft:obsidian,100)
RB(-12,19,11,minecraft:crying_obsidian,20,minecraft:obsidian,100)
RB(-12,20,11,minecraft:crying_obsidian,20,minecraft:obsidian,100)
RB(-12,13,12,minecraft:crying_obsidian,20,minecraft:obsidian,100)
RB(-12,14,12,minecraft:crying_obsidian,20,minecraft:obsidian,100)
RB(-12,15,12,minecraft:crying_obsidian,20,minecraft:obsidian,100)
RB(-12,16,12,minecraft:crying_obsidian,20,minecraft:obsidian,100)
RB(-12,17,12,minecraft:crying_obsidian,20,minecraft:obsidian,100)
RB(-12,18,12,minecraft:crying_obsidian,20,minecraft:obsidian,100)
RB(-12,19,12,minecraft:crying_obsidian,20,minecraft:obsidian,100)
RB(-12,20,12,minecraft:crying_obsidian,20,minecraft:obsidian,100)
RB(-12,14,13,minecraft:crying_obsidian,20,minecraft:obsidian,100)
RB(-12,15,13,minecraft:crying_obsidian,20,minecraft:obsidian,100)
RB(-12,16,13,minecraft:crying_obsidian,20,minecraft:obsidian,100)
RB(-12,17,13,minecraft:crying_obsidian,20,minecraft:obsidian,100)
RB(-12,18,13,minecraft:crying_obsidian,20,minecraft:obsidian,100)
RB(-11,18,0,minecraft:crying_obsidian,20,minecraft:obsidian,100)
RB(-11,16,1,minecraft:crying_obsidian,20,minecraft:obsidian,100)
RB(-11,17,1,minecraft:crying_obsidian,20,minecraft:obsidian,100)
RB(-11,18,1,minecraft:crying_obsidian,20,minecraft:obsidian,100)
RB(-11,17,2,minecraft:crying_obsidian,20,minecraft:obsidian,100)
RB(-11,18,2,minecraft:crying_obsidian,20,minecraft:obsidian,100)
RB(-11,19,2,minecraft:crying_obsidian,20,minecraft:obsidian,100)
RB(-11,17,3,minecraft:crying_obsidian,20,minecraft:obsidian,100)
RB(-11,18,3,minecraft:crying_obsidian,20,minecraft:obsidian,100)
RB(-11,19,3,minecraft:crying_obsidian,20,minecraft:obsidian,100)
RB(-11,19,4,minecraft:crying_obsidian,20,minecraft:obsidian,100)
RB(-11,20,4,minecraft:crying_obsidian,20,minecraft:obsidian,100)
RB(-11,18,6,minecraft:crying_obsidian,20,minecraft:obsidian,100)
RB(-11,19,6,minecraft:crying_obsidian,20,minecraft:obsidian,100)
RB(-11,20,6,minecraft:crying_obsidian,20,minecraft:obsidian,100)
RB(-11,13,7,minecraft:crying_obsidian,20,minecraft:obsidian,100)
RB(-11,14,7,minecraft:crying_obsidian,20,minecraft:obsidian,100)
RB(-11,15,7,minecraft:crying_obsidian,20,minecraft:obsidian,100)
RB(-11,16,7,minecraft:crying_obsidian,20,minecraft:obsidian,100)
RB(-11,17,7,minecraft:crying_obsidian,20,minecraft:obsidian,100)
RB(-11,18,7,minecraft:crying_obsidian,20,minecraft:obsidian,100)
RB(-11,19,7,minecraft:crying_obsidian,20,minecraft:obsidian,100)
RB(-11,20,7,minecraft:crying_obsidian,20,minecraft:obsidian,100)
RB(-11,21,7,minecraft:crying_obsidian,20,minecraft:obsidian,100)
RB(-11,12,8,minecraft:crying_obsidian,20,minecraft:obsidian,100)
RB(-11,13,8,minecraft:crying_obsidian,20,minecraft:obsidian,100)
RB(-11,14,8,minecraft:crying_obsidian,20,minecraft:obsidian,100)
RB(-11,15,8,minecraft:crying_obsidian,20,minecraft:obsidian,100)
RB(-11,16,8,minecraft:crying_obsidian,20,minecraft:obsidian,100)
RB(-11,17,8,minecraft:crying_obsidian,20,minecraft:obsidian,100)
RB(-11,18,8,minecraft:crying_obsidian,20,minecraft:obsidian,100)
RB(-11,19,8,minecraft:crying_obsidian,20,minecraft:obsidian,100)
RB(-11,20,8,minecraft:crying_obsidian,20,minecraft:obsidian,100)
RB(-11,21,8,minecraft:crying_obsidian,20,minecraft:obsidian,100)
RB(-11,12,9,minecraft:crying_obsidian,20,minecraft:obsidian,100)
RB(-11,13,9,minecraft:crying_obsidian,20,minecraft:obsidian,100)
RB(-11,14,9,minecraft:crying_obsidian,20,minecraft:obsidian,100)
RB(-11,15,9,minecraft:crying_obsidian,20,minecraft:obsidian,100)
RB(-11,16,9,minecraft:crying_obsidian,20,minecraft:obsidian,100)
RB(-11,17,9,minecraft:crying_obsidian,20,minecraft:obsidian,100)
RB(-11,18,9,minecraft:crying_obsidian,20,minecraft:obsidian,100)
RB(-11,19,9,minecraft:crying_obsidian,20,minecraft:obsidian,100)
RB(-11,20,9,minecraft:crying_obsidian,20,minecraft:obsidian,100)
RB(-11,21,9,minecraft:crying_obsidian,20,minecraft:obsidian,100)
RB(-11,12,10,minecraft:crying_obsidian,20,minecraft:obsidian,100)
RB(-11,13,10,minecraft:crying_obsidian,20,minecraft:obsidian,100)
RB(-11,14,10,minecraft:crying_obsidian,20,minecraft:obsidian,100)
RB(-11,15,10,minecraft:crying_obsidian,20,minecraft:obsidian,100)
RB(-11,16,10,minecraft:crying_obsidian,20,minecraft:obsidian,100)
RB(-11,17,10,minecraft:crying_obsidian,20,minecraft:obsidian,100)
RB(-11,18,10,minecraft:crying_obsidian,20,minecraft:obsidian,100)
RB(-11,19,10,minecraft:crying_obsidian,20,minecraft:obsidian,100)
RB(-11,20,10,minecraft:crying_obsidian,20,minecraft:obsidian,100)
RB(-11,21,10,minecraft:crying_obsidian,20,minecraft:obsidian,100)
RB(-11,12,11,minecraft:crying_obsidian,20,minecraft:obsidian,100)
RB(-11,13,11,minecraft:crying_obsidian,20,minecraft:obsidian,100)
RB(-11,14,11,minecraft:crying_obsidian,20,minecraft:obsidian,100)
RB(-11,15,11,minecraft:crying_obsidian,20,minecraft:obsidian,100)
RB(-11,16,11,minecraft:crying_obsidian,20,minecraft:obsidian,100)
RB(-11,17,11,minecraft:crying_obsidian,20,minecraft:obsidian,100)
RB(-11,18,11,minecraft:crying_obsidian,20,minecraft:obsidian,100)
RB(-11,19,11,minecraft:crying_obsidian,20,minecraft:obsidian,100)
RB(-11,20,11,minecraft:crying_obsidian,20,minecraft:obsidian,100)
RB(-11,21,11,minecraft:crying_obsidian,20,minecraft:obsidian,100)
RB(-11,12,12,minecraft:crying_obsidian,20,minecraft:obsidian,100)
RB(-11,13,12,minecraft:crying_obsidian,20,minecraft:obsidian,100)
RB(-11,14,12,minecraft:crying_obsidian,20,minecraft:obsidian,100)
RB(-11,15,12,minecraft:crying_obsidian,20,minecraft:obsidian,100)
RB(-11,16,12,minecraft:crying_obsidian,20,minecraft:obsidian,100)
RB(-11,17,12,minecraft:crying_obsidian,20,minecraft:obsidian,100)
RB(-11,18,12,minecraft:crying_obsidian,20,minecraft:obsidian,100)
RB(-11,19,12,minecraft:crying_obsidian,20,minecraft:obsidian,100)
RB(-11,20,12,minecraft:crying_obsidian,20,minecraft:obsidian,100)
RB(-11,13,13,minecraft:crying_obsidian,20,minecraft:obsidian,100)
RB(-11,14,13,minecraft:crying_obsidian,20,minecraft:obsidian,100)
RB(-11,15,13,minecraft:crying_obsidian,20,minecraft:obsidian,100)
RB(-11,16,13,minecraft:crying_obsidian,20,minecraft:obsidian,100)
RB(-11,17,13,minecraft:crying_obsidian,20,minecraft:obsidian,100)
RB(-11,18,13,minecraft:crying_obsidian,20,minecraft:obsidian,100)
RB(-11,19,13,minecraft:crying_obsidian,20,minecraft:obsidian,100)
RB(-11,14,14,minecraft:crying_obsidian,20,minecraft:obsidian,100)
RB(-11,15,14,minecraft:crying_obsidian,20,minecraft:obsidian,100)
RB(-11,16,14,minecraft:crying_obsidian,20,minecraft:obsidian,100)
RB(-11,17,14,minecraft:crying_obsidian,20,minecraft:obsidian,100)
RB(-11,18,14,minecraft:crying_obsidian,20,minecraft:obsidian,100)
RB(-10,14,-1,minecraft:crying_obsidian,20,minecraft:obsidian,100)
RB(-10,15,-1,minecraft:crying_obsidian,20,minecraft:obsidian,100)
RB(-10,16,-1,minecraft:crying_obsidian,20,minecraft:obsidian,100)
RB(-10,17,-1,minecraft:crying_obsidian,20,minecraft:obsidian,100)
RB(-10,18,-1,minecraft:crying_obsidian,20,minecraft:obsidian,100)
RB(-10,19,-1,minecraft:crying_obsidian,20,minecraft:obsidian,100)
RB(-10,20,-1,minecraft:crying_obsidian,20,minecraft:obsidian,100)
RB(-10,12,0,minecraft:crying_obsidian,20,minecraft:obsidian,100)
RB(-10,13,0,minecraft:crying_obsidian,20,minecraft:obsidian,100)
RB(-10,14,0,minecraft:crying_obsidian,20,minecraft:obsidian,100)
RB(-10,15,0,minecraft:crying_obsidian,20,minecraft:obsidian,100)
RB(-10,16,0,minecraft:crying_obsidian,20,minecraft:obsidian,100)
RB(-10,17,0,minecraft:crying_obsidian,20,minecraft:obsidian,100)
RB(-10,18,0,minecraft:crying_obsidian,20,minecraft:obsidian,100)
RB(-10,19,0,minecraft:crying_obsidian,20,minecraft:obsidian,100)
RB(-10,20,0,minecraft:crying_obsidian,20,minecraft:obsidian,100)
RB(-10,16,1,minecraft:crying_obsidian,20,minecraft:obsidian,100)
RB(-10,17,1,minecraft:crying_obsidian,20,minecraft:obsidian,100)
RB(-10,18,1,minecraft:crying_obsidian,20,minecraft:obsidian,100)
RB(-10,19,1,minecraft:crying_obsidian,20,minecraft:obsidian,100)
RB(-10,15,2,minecraft:crying_obsidian,20,minecraft:obsidian,100)
RB(-10,16,2,minecraft:crying_obsidian,20,minecraft:obsidian,100)
RB(-10,17,2,minecraft:crying_obsidian,20,minecraft:obsidian,100)
RB(-10,18,2,minecraft:crying_obsidian,20,minecraft:obsidian,100)
RB(-10,19,2,minecraft:crying_obsidian,20,minecraft:obsidian,100)
RB(-10,20,2,minecraft:crying_obsidian,20,minecraft:obsidian,100)
RB(-10,17,3,minecraft:crying_obsidian,20,minecraft:obsidian,100)
RB(-10,18,3,minecraft:crying_obsidian,20,minecraft:obsidian,100)
RB(-10,19,3,minecraft:crying_obsidian,20,minecraft:obsidian,100)
RB(-10,16,4,minecraft:crying_obsidian,20,minecraft:obsidian,100)
RB(-10,17,4,minecraft:crying_obsidian,20,minecraft:obsidian,100)
RB(-10,18,4,minecraft:crying_obsidian,20,minecraft:obsidian,100)
RB(-10,19,4,minecraft:crying_obsidian,20,minecraft:obsidian,100)
RB(-10,20,4,minecraft:crying_obsidian,20,minecraft:obsidian,100)
RB(-10,17,5,minecraft:crying_obsidian,20,minecraft:obsidian,100)
RB(-10,18,5,minecraft:crying_obsidian,20,minecraft:obsidian,100)
RB(-10,19,5,minecraft:crying_obsidian,20,minecraft:obsidian,100)
RB(-10,20,5,minecraft:crying_obsidian,20,minecraft:obsidian,100)
RB(-10,17,6,minecraft:crying_obsidian,20,minecraft:obsidian,100)
RB(-10,18,6,minecraft:crying_obsidian,20,minecraft:obsidian,100)
RB(-10,19,6,minecraft:crying_obsidian,20,minecraft:obsidian,100)
RB(-10,20,6,minecraft:crying_obsidian,20,minecraft:obsidian,100)
RB(-10,21,6,minecraft:crying_obsidian,20,minecraft:obsidian,100)
RB(-10,13,7,minecraft:crying_obsidian,20,minecraft:obsidian,100)
RB(-10,14,7,minecraft:crying_obsidian,20,minecraft:obsidian,100)
RB(-10,15,7,minecraft:crying_obsidian,20,minecraft:obsidian,100)
RB(-10,16,7,minecraft:crying_obsidian,20,minecraft:obsidian,100)
RB(-10,17,7,minecraft:crying_obsidian,20,minecraft:obsidian,100)
RB(-10,18,7,minecraft:crying_obsidian,20,minecraft:obsidian,100)
RB(-10,19,7,minecraft:crying_obsidian,20,minecraft:obsidian,100)
RB(-10,20,7,minecraft:crying_obsidian,20,minecraft:obsidian,100)
RB(-10,21,7,minecraft:crying_obsidian,20,minecraft:obsidian,100)
RB(-10,12,8,minecraft:crying_obsidian,20,minecraft:obsidian,100)
RB(-10,13,8,minecraft:crying_obsidian,20,minecraft:obsidian,100)
RB(-10,14,8,minecraft:crying_obsidian,20,minecraft:obsidian,100)
RB(-10,15,8,minecraft:crying_obsidian,20,minecraft:obsidian,100)
RB(-10,16,8,minecraft:crying_obsidian,20,minecraft:obsidian,100)
RB(-10,17,8,minecraft:crying_obsidian,20,minecraft:obsidian,100)
RB(-10,18,8,minecraft:crying_obsidian,20,minecraft:obsidian,100)
RB(-10,19,8,minecraft:crying_obsidian,20,minecraft:obsidian,100)
RB(-10,20,8,minecraft:crying_obsidian,20,minecraft:obsidian,100)
RB(-10,21,8,minecraft:crying_obsidian,20,minecraft:obsidian,100)
RB(-10,11,9,minecraft:crying_obsidian,20,minecraft:obsidian,100)
RB(-10,12,9,minecraft:crying_obsidian,20,minecraft:obsidian,100)
RB(-10,13,9,minecraft:crying_obsidian,20,minecraft:obsidian,100)
RB(-10,14,9,minecraft:crying_obsidian,20,minecraft:obsidian,100)
RB(-10,15,9,minecraft:crying_obsidian,20,minecraft:obsidian,100)
RB(-10,16,9,minecraft:crying_obsidian,20,minecraft:obsidian,100)
RB(-10,17,9,minecraft:crying_obsidian,20,minecraft:obsidian,100)
RB(-10,18,9,minecraft:crying_obsidian,20,minecraft:obsidian,100)
RB(-10,19,9,minecraft:crying_obsidian,20,minecraft:obsidian,100)
RB(-10,20,9,minecraft:crying_obsidian,20,minecraft:obsidian,100)
RB(-10,21,9,minecraft:crying_obsidian,20,minecraft:obsidian,100)
RB(-10,22,9,minecraft:crying_obsidian,20,minecraft:obsidian,100)
RB(-10,11,10,minecraft:crying_obsidian,20,minecraft:obsidian,100)
RB(-10,12,10,minecraft:crying_obsidian,20,minecraft:obsidian,100)
RB(-10,13,10,minecraft:crying_obsidian,20,minecraft:obsidian,100)
RB(-10,14,10,minecraft:crying_obsidian,20,minecraft:obsidian,100)
RB(-10,15,10,minecraft:crying_obsidian,20,minecraft:obsidian,100)
RB(-10,16,10,minecraft:crying_obsidian,20,minecraft:obsidian,100)
RB(-10,17,10,minecraft:crying_obsidian,20,minecraft:obsidian,100)
RB(-10,18,10,minecraft:crying_obsidian,20,minecraft:obsidian,100)
RB(-10,19,10,minecraft:crying_obsidian,20,minecraft:obsidian,100)
RB(-10,20,10,minecraft:crying_obsidian,20,minecraft:obsidian,100)
RB(-10,21,10,minecraft:crying_obsidian,20,minecraft:obsidian,100)
RB(-10,11,11,minecraft:crying_obsidian,20,minecraft:obsidian,100)
RB(-10,12,11,minecraft:crying_obsidian,20,minecraft:obsidian,100)
RB(-10,13,11,minecraft:crying_obsidian,20,minecraft:obsidian,100)
RB(-10,14,11,minecraft:crying_obsidian,20,minecraft:obsidian,100)
RB(-10,15,11,minecraft:crying_obsidian,20,minecraft:obsidian,100)
RB(-10,16,11,minecraft:crying_obsidian,20,minecraft:obsidian,100)
RB(-10,17,11,minecraft:crying_obsidian,20,minecraft:obsidian,100)
RB(-10,18,11,minecraft:crying_obsidian,20,minecraft:obsidian,100)
RB(-10,19,11,minecraft:crying_obsidian,20,minecraft:obsidian,100)
RB(-10,20,11,minecraft:crying_obsidian,20,minecraft:obsidian,100)
RB(-10,21,11,minecraft:crying_obsidian,20,minecraft:obsidian,100)
RB(-10,12,12,minecraft:crying_obsidian,20,minecraft:obsidian,100)
RB(-10,13,12,minecraft:crying_obsidian,20,minecraft:obsidian,100)
RB(-10,14,12,minecraft:crying_obsidian,20,minecraft:obsidian,100)
RB(-10,15,12,minecraft:crying_obsidian,20,minecraft:obsidian,100)
RB(-10,16,12,minecraft:crying_obsidian,20,minecraft:obsidian,100)
RB(-10,17,12,minecraft:crying_obsidian,20,minecraft:obsidian,100)
RB(-10,18,12,minecraft:crying_obsidian,20,minecraft:obsidian,100)
RB(-10,19,12,minecraft:crying_obsidian,20,minecraft:obsidian,100)
RB(-10,20,12,minecraft:crying_obsidian,20,minecraft:obsidian,100)
RB(-10,12,13,minecraft:crying_obsidian,20,minecraft:obsidian,100)
RB(-10,13,13,minecraft:crying_obsidian,20,minecraft:obsidian,100)
RB(-10,14,13,minecraft:crying_obsidian,20,minecraft:obsidian,100)
RB(-10,15,13,minecraft:crying_obsidian,20,minecraft:obsidian,100)
RB(-10,16,13,minecraft:crying_obsidian,20,minecraft:obsidian,100)
RB(-10,17,13,minecraft:crying_obsidian,20,minecraft:obsidian,100)
RB(-10,18,13,minecraft:crying_obsidian,20,minecraft:obsidian,100)
RB(-10,19,13,minecraft:crying_obsidian,20,minecraft:obsidian,100)
RB(-10,20,13,minecraft:crying_obsidian,20,minecraft:obsidian,100)
RB(-10,13,14,minecraft:crying_obsidian,20,minecraft:obsidian,100)
RB(-10,14,14,minecraft:crying_obsidian,20,minecraft:obsidian,100)
RB(-10,15,14,minecraft:crying_obsidian,20,minecraft:obsidian,100)
RB(-10,16,14,minecraft:crying_obsidian,20,minecraft:obsidian,100)
RB(-10,17,14,minecraft:crying_obsidian,20,minecraft:obsidian,100)
RB(-10,18,14,minecraft:crying_obsidian,20,minecraft:obsidian,100)
RB(-10,19,14,minecraft:crying_obsidian,20,minecraft:obsidian,100)
RB(-10,15,15,minecraft:crying_obsidian,20,minecraft:obsidian,100)
RB(-10,16,15,minecraft:crying_obsidian,20,minecraft:obsidian,100)
RB(-10,17,15,minecraft:crying_obsidian,20,minecraft:obsidian,100)
RB(-9,14,-9,minecraft:crying_obsidian,20,minecraft:obsidian,100)
RB(-9,15,-9,minecraft:crying_obsidian,20,minecraft:obsidian,100)
RB(-9,16,-9,minecraft:crying_obsidian,20,minecraft:obsidian,100)
RB(-9,13,-8,minecraft:crying_obsidian,20,minecraft:obsidian,100)
RB(-9,14,-8,minecraft:crying_obsidian,20,minecraft:obsidian,100)
RB(-9,15,-8,minecraft:crying_obsidian,20,minecraft:obsidian,100)
RB(-9,16,-8,minecraft:crying_obsidian,20,minecraft:obsidian,100)
RB(-9,17,-8,minecraft:crying_obsidian,20,minecraft:obsidian,100)
RB(-9,18,-8,minecraft:crying_obsidian,20,minecraft:obsidian,100)
RB(-9,19,-8,minecraft:crying_obsidian,20,minecraft:obsidian,100)
RB(-9,13,-7,minecraft:crying_obsidian,20,minecraft:obsidian,100)
RB(-9,14,-7,minecraft:crying_obsidian,20,minecraft:obsidian,100)
RB(-9,15,-7,minecraft:crying_obsidian,20,minecraft:obsidian,100)
RB(-9,16,-7,minecraft:crying_obsidian,20,minecraft:obsidian,100)
RB(-9,17,-7,minecraft:crying_obsidian,20,minecraft:obsidian,100)
RB(-9,18,-7,minecraft:crying_obsidian,20,minecraft:obsidian,100)
RB(-9,19,-7,minecraft:crying_obsidian,20,minecraft:obsidian,100)
RB(-9,13,-6,minecraft:crying_obsidian,20,minecraft:obsidian,100)
RB(-9,14,-6,minecraft:crying_obsidian,20,minecraft:obsidian,100)
RB(-9,15,-6,minecraft:crying_obsidian,20,minecraft:obsidian,100)
RB(-9,16,-6,minecraft:crying_obsidian,20,minecraft:obsidian,100)
RB(-9,17,-6,minecraft:crying_obsidian,20,minecraft:obsidian,100)
RB(-9,18,-6,minecraft:crying_obsidian,20,minecraft:obsidian,100)
RB(-9,19,-6,minecraft:crying_obsidian,20,minecraft:obsidian,100)
RB(-9,14,-5,minecraft:crying_obsidian,20,minecraft:obsidian,100)
RB(-9,15,-5,minecraft:crying_obsidian,20,minecraft:obsidian,100)
RB(-9,16,-5,minecraft:crying_obsidian,20,minecraft:obsidian,100)
RB(-9,17,-5,minecraft:crying_obsidian,20,minecraft:obsidian,100)
RB(-9,18,-5,minecraft:crying_obsidian,20,minecraft:obsidian,100)
RB(-9,14,-2,minecraft:crying_obsidian,20,minecraft:obsidian,100)
RB(-9,15,-2,minecraft:crying_obsidian,20,minecraft:obsidian,100)
RB(-9,16,-2,minecraft:crying_obsidian,20,minecraft:obsidian,100)
RB(-9,17,-2,minecraft:crying_obsidian,20,minecraft:obsidian,100)
RB(-9,18,-2,minecraft:crying_obsidian,20,minecraft:obsidian,100)
RB(-9,19,-2,minecraft:crying_obsidian,20,minecraft:obsidian,100)
RB(-9,12,-1,minecraft:crying_obsidian,20,minecraft:obsidian,100)
RB(-9,13,-1,minecraft:crying_obsidian,20,minecraft:obsidian,100)
RB(-9,14,-1,minecraft:crying_obsidian,20,minecraft:obsidian,100)
RB(-9,15,-1,minecraft:crying_obsidian,20,minecraft:obsidian,100)
RB(-9,16,-1,minecraft:crying_obsidian,20,minecraft:obsidian,100)
RB(-9,17,-1,minecraft:crying_obsidian,20,minecraft:obsidian,100)
RB(-9,18,-1,minecraft:crying_obsidian,20,minecraft:obsidian,100)
RB(-9,19,-1,minecraft:crying_obsidian,20,minecraft:obsidian,100)
RB(-9,20,-1,minecraft:crying_obsidian,20,minecraft:obsidian,100)
RB(-9,11,0,minecraft:crying_obsidian,20,minecraft:obsidian,100)
RB(-9,12,0,minecraft:crying_obsidian,20,minecraft:obsidian,100)
RB(-9,13,0,minecraft:crying_obsidian,20,minecraft:obsidian,100)
RB(-9,14,0,minecraft:crying_obsidian,20,minecraft:obsidian,100)
RB(-9,15,0,minecraft:crying_obsidian,20,minecraft:obsidian,100)
RB(-9,16,0,minecraft:crying_obsidian,20,minecraft:obsidian,100)
RB(-9,17,0,minecraft:crying_obsidian,20,minecraft:obsidian,100)
RB(-9,18,0,minecraft:crying_obsidian,20,minecraft:obsidian,100)
RB(-9,19,0,minecraft:crying_obsidian,20,minecraft:obsidian,100)
RB(-9,20,0,minecraft:crying_obsidian,20,minecraft:obsidian,100)
RB(-9,12,1,minecraft:crying_obsidian,20,minecraft:obsidian,100)
RB(-9,13,1,minecraft:crying_obsidian,20,minecraft:obsidian,100)
RB(-9,14,1,minecraft:crying_obsidian,20,minecraft:obsidian,100)
RB(-9,15,1,minecraft:crying_obsidian,20,minecraft:obsidian,100)
RB(-9,16,1,minecraft:crying_obsidian,20,minecraft:obsidian,100)
RB(-9,17,1,minecraft:crying_obsidian,20,minecraft:obsidian,100)
RB(-9,18,1,minecraft:crying_obsidian,20,minecraft:obsidian,100)
RB(-9,19,1,minecraft:crying_obsidian,20,minecraft:obsidian,100)
RB(-9,20,1,minecraft:crying_obsidian,20,minecraft:obsidian,100)
RB(-9,12,2,minecraft:crying_obsidian,20,minecraft:obsidian,100)
RB(-9,13,2,minecraft:crying_obsidian,20,minecraft:obsidian,100)
RB(-9,14,2,minecraft:crying_obsidian,20,minecraft:obsidian,100)
RB(-9,15,2,minecraft:crying_obsidian,20,minecraft:obsidian,100)
RB(-9,16,2,minecraft:crying_obsidian,20,minecraft:obsidian,100)
RB(-9,17,2,minecraft:crying_obsidian,20,minecraft:obsidian,100)
RB(-9,18,2,minecraft:crying_obsidian,20,minecraft:obsidian,100)
RB(-9,19,2,minecraft:crying_obsidian,20,minecraft:obsidian,100)
RB(-9,20,2,minecraft:crying_obsidian,20,minecraft:obsidian,100)
RB(-9,21,2,minecraft:crying_obsidian,20,minecraft:obsidian,100)
RB(-9,12,3,minecraft:crying_obsidian,20,minecraft:obsidian,100)
RB(-9,13,3,minecraft:crying_obsidian,20,minecraft:obsidian,100)
RB(-9,14,3,minecraft:crying_obsidian,20,minecraft:obsidian,100)
RB(-9,15,3,minecraft:crying_obsidian,20,minecraft:obsidian,100)
RB(-9,16,3,minecraft:crying_obsidian,20,minecraft:obsidian,100)
RB(-9,17,3,minecraft:crying_obsidian,20,minecraft:obsidian,100)
RB(-9,18,3,minecraft:crying_obsidian,20,minecraft:obsidian,100)
RB(-9,19,3,minecraft:crying_obsidian,20,minecraft:obsidian,100)
RB(-9,20,3,minecraft:crying_obsidian,20,minecraft:obsidian,100)
RB(-9,21,3,minecraft:crying_obsidian,20,minecraft:obsidian,100)
RB(-9,12,4,minecraft:crying_obsidian,20,minecraft:obsidian,100)
RB(-9,13,4,minecraft:crying_obsidian,20,minecraft:obsidian,100)
RB(-9,14,4,minecraft:crying_obsidian,20,minecraft:obsidian,100)
RB(-9,15,4,minecraft:crying_obsidian,20,minecraft:obsidian,100)
RB(-9,16,4,minecraft:crying_obsidian,20,minecraft:obsidian,100)
RB(-9,17,4,minecraft:crying_obsidian,20,minecraft:obsidian,100)
RB(-9,18,4,minecraft:crying_obsidian,20,minecraft:obsidian,100)
RB(-9,19,4,minecraft:crying_obsidian,20,minecraft:obsidian,100)
RB(-9,20,4,minecraft:crying_obsidian,20,minecraft:obsidian,100)
RB(-9,21,4,minecraft:crying_obsidian,20,minecraft:obsidian,100)
RB(-9,16,5,minecraft:crying_obsidian,20,minecraft:obsidian,100)
RB(-9,17,5,minecraft:crying_obsidian,20,minecraft:obsidian,100)
RB(-9,18,5,minecraft:crying_obsidian,20,minecraft:obsidian,100)
RB(-9,19,5,minecraft:crying_obsidian,20,minecraft:obsidian,100)
RB(-9,20,5,minecraft:crying_obsidian,20,minecraft:obsidian,100)
RB(-9,15,6,minecraft:crying_obsidian,20,minecraft:obsidian,100)
RB(-9,16,6,minecraft:crying_obsidian,20,minecraft:obsidian,100)
RB(-9,17,6,minecraft:crying_obsidian,20,minecraft:obsidian,100)
RB(-9,18,6,minecraft:crying_obsidian,20,minecraft:obsidian,100)
RB(-9,19,6,minecraft:crying_obsidian,20,minecraft:obsidian,100)
RB(-9,20,6,minecraft:crying_obsidian,20,minecraft:obsidian,100)
RB(-9,21,6,minecraft:crying_obsidian,20,minecraft:obsidian,100)
RB(-9,13,7,minecraft:crying_obsidian,20,minecraft:obsidian,100)
RB(-9,14,7,minecraft:crying_obsidian,20,minecraft:obsidian,100)
RB(-9,15,7,minecraft:crying_obsidian,20,minecraft:obsidian,100)
RB(-9,16,7,minecraft:crying_obsidian,20,minecraft:obsidian,100)
RB(-9,17,7,minecraft:crying_obsidian,20,minecraft:obsidian,100)
RB(-9,18,7,minecraft:crying_obsidian,20,minecraft:obsidian,100)
RB(-9,19,7,minecraft:crying_obsidian,20,minecraft:obsidian,100)
RB(-9,20,7,minecraft:crying_obsidian,20,minecraft:obsidian,100)
RB(-9,21,7,minecraft:crying_obsidian,20,minecraft:obsidian,100)
RB(-9,11,8,minecraft:crying_obsidian,20,minecraft:obsidian,100)
RB(-9,12,8,minecraft:crying_obsidian,20,minecraft:obsidian,100)
RB(-9,13,8,minecraft:crying_obsidian,20,minecraft:obsidian,100)
RB(-9,14,8,minecraft:crying_obsidian,20,minecraft:obsidian,100)
RB(-9,15,8,minecraft:crying_obsidian,20,minecraft:obsidian,100)
RB(-9,16,8,minecraft:crying_obsidian,20,minecraft:obsidian,100)
RB(-9,17,8,minecraft:crying_obsidian,20,minecraft:obsidian,100)
RB(-9,18,8,minecraft:crying_obsidian,20,minecraft:obsidian,100)
RB(-9,19,8,minecraft:crying_obsidian,20,minecraft:obsidian,100)
RB(-9,20,8,minecraft:crying_obsidian,20,minecraft:obsidian,100)
RB(-9,21,8,minecraft:crying_obsidian,20,minecraft:obsidian,100)
RB(-9,22,8,minecraft:crying_obsidian,20,minecraft:obsidian,100)
RB(-9,11,9,minecraft:crying_obsidian,20,minecraft:obsidian,100)
RB(-9,12,9,minecraft:crying_obsidian,20,minecraft:obsidian,100)
RB(-9,13,9,minecraft:crying_obsidian,20,minecraft:obsidian,100)
RB(-9,14,9,minecraft:crying_obsidian,20,minecraft:obsidian,100)
RB(-9,15,9,minecraft:crying_obsidian,20,minecraft:obsidian,100)
RB(-9,16,9,minecraft:crying_obsidian,20,minecraft:obsidian,100)
RB(-9,17,9,minecraft:crying_obsidian,20,minecraft:obsidian,100)
RB(-9,18,9,minecraft:crying_obsidian,20,minecraft:obsidian,100)
RB(-9,19,9,minecraft:crying_obsidian,20,minecraft:obsidian,100)
RB(-9,20,9,minecraft:crying_obsidian,20,minecraft:obsidian,100)
RB(-9,21,9,minecraft:crying_obsidian,20,minecraft:obsidian,100)
RB(-9,22,9,minecraft:crying_obsidian,20,minecraft:obsidian,100)
RB(-9,11,10,minecraft:crying_obsidian,20,minecraft:obsidian,100)
RB(-9,12,10,minecraft:crying_obsidian,20,minecraft:obsidian,100)
RB(-9,13,10,minecraft:crying_obsidian,20,minecraft:obsidian,100)
RB(-9,14,10,minecraft:crying_obsidian,20,minecraft:obsidian,100)
RB(-9,15,10,minecraft:crying_obsidian,20,minecraft:obsidian,100)
RB(-9,16,10,minecraft:crying_obsidian,20,minecraft:obsidian,100)
RB(-9,17,10,minecraft:crying_obsidian,20,minecraft:obsidian,100)
RB(-9,18,10,minecraft:crying_obsidian,20,minecraft:obsidian,100)
RB(-9,19,10,minecraft:crying_obsidian,20,minecraft:obsidian,100)
RB(-9,20,10,minecraft:crying_obsidian,20,minecraft:obsidian,100)
RB(-9,21,10,minecraft:crying_obsidian,20,minecraft:obsidian,100)
RB(-9,11,11,minecraft:crying_obsidian,20,minecraft:obsidian,100)
RB(-9,12,11,minecraft:crying_obsidian,20,minecraft:obsidian,100)
RB(-9,13,11,minecraft:crying_obsidian,20,minecraft:obsidian,100)
RB(-9,14,11,minecraft:crying_obsidian,20,minecraft:obsidian,100)
RB(-9,15,11,minecraft:crying_obsidian,20,minecraft:obsidian,100)
RB(-9,16,11,minecraft:crying_obsidian,20,minecraft:obsidian,100)
RB(-9,17,11,minecraft:crying_obsidian,20,minecraft:obsidian,100)
RB(-9,18,11,minecraft:crying_obsidian,20,minecraft:obsidian,100)
RB(-9,19,11,minecraft:crying_obsidian,20,minecraft:obsidian,100)
RB(-9,20,11,minecraft:crying_obsidian,20,minecraft:obsidian,100)
RB(-9,21,11,minecraft:crying_obsidian,20,minecraft:obsidian,100)
RB(-9,11,12,minecraft:crying_obsidian,20,minecraft:obsidian,100)
RB(-9,12,12,minecraft:crying_obsidian,20,minecraft:obsidian,100)
RB(-9,13,12,minecraft:crying_obsidian,20,minecraft:obsidian,100)
RB(-9,14,12,minecraft:crying_obsidian,20,minecraft:obsidian,100)
RB(-9,15,12,minecraft:crying_obsidian,20,minecraft:obsidian,100)
RB(-9,16,12,minecraft:crying_obsidian,20,minecraft:obsidian,100)
RB(-9,17,12,minecraft:crying_obsidian,20,minecraft:obsidian,100)
RB(-9,18,12,minecraft:crying_obsidian,20,minecraft:obsidian,100)
RB(-9,19,12,minecraft:crying_obsidian,20,minecraft:obsidian,100)
RB(-9,20,12,minecraft:crying_obsidian,20,minecraft:obsidian,100)
RB(-9,21,12,minecraft:crying_obsidian,20,minecraft:obsidian,100)
RB(-9,12,13,minecraft:crying_obsidian,20,minecraft:obsidian,100)
RB(-9,13,13,minecraft:crying_obsidian,20,minecraft:obsidian,100)
RB(-9,14,13,minecraft:crying_obsidian,20,minecraft:obsidian,100)
RB(-9,15,13,minecraft:crying_obsidian,20,minecraft:obsidian,100)
RB(-9,16,13,minecraft:crying_obsidian,20,minecraft:obsidian,100)
RB(-9,17,13,minecraft:crying_obsidian,20,minecraft:obsidian,100)
RB(-9,18,13,minecraft:crying_obsidian,20,minecraft:obsidian,100)
RB(-9,19,13,minecraft:crying_obsidian,20,minecraft:obsidian,100)
RB(-9,20,13,minecraft:crying_obsidian,20,minecraft:obsidian,100)
RB(-9,13,14,minecraft:crying_obsidian,20,minecraft:obsidian,100)
RB(-9,14,14,minecraft:crying_obsidian,20,minecraft:obsidian,100)
RB(-9,15,14,minecraft:crying_obsidian,20,minecraft:obsidian,100)
RB(-9,16,14,minecraft:crying_obsidian,20,minecraft:obsidian,100)
RB(-9,17,14,minecraft:crying_obsidian,20,minecraft:obsidian,100)
RB(-9,18,14,minecraft:crying_obsidian,20,minecraft:obsidian,100)
RB(-9,19,14,minecraft:crying_obsidian,20,minecraft:obsidian,100)
RB(-9,14,15,minecraft:crying_obsidian,20,minecraft:obsidian,100)
RB(-9,15,15,minecraft:crying_obsidian,20,minecraft:obsidian,100)
RB(-9,16,15,minecraft:crying_obsidian,20,minecraft:obsidian,100)
RB(-9,17,15,minecraft:crying_obsidian,20,minecraft:obsidian,100)
RB(-9,18,15,minecraft:crying_obsidian,20,minecraft:obsidian,100)
RB(-8,13,-10,minecraft:crying_obsidian,20,minecraft:obsidian,100)
RB(-8,14,-10,minecraft:crying_obsidian,20,minecraft:obsidian,100)
RB(-8,15,-10,minecraft:crying_obsidian,20,minecraft:obsidian,100)
RB(-8,16,-10,minecraft:crying_obsidian,20,minecraft:obsidian,100)
RB(-8,17,-10,minecraft:crying_obsidian,20,minecraft:obsidian,100)
RB(-8,18,-10,minecraft:crying_obsidian,20,minecraft:obsidian,100)
RB(-8,12,-9,minecraft:crying_obsidian,20,minecraft:obsidian,100)
RB(-8,13,-9,minecraft:crying_obsidian,20,minecraft:obsidian,100)
RB(-8,14,-9,minecraft:crying_obsidian,20,minecraft:obsidian,100)
RB(-8,15,-9,minecraft:crying_obsidian,20,minecraft:obsidian,100)
RB(-8,16,-9,minecraft:crying_obsidian,20,minecraft:obsidian,100)
RB(-8,17,-9,minecraft:crying_obsidian,20,minecraft:obsidian,100)
RB(-8,18,-9,minecraft:crying_obsidian,20,minecraft:obsidian,100)
RB(-8,19,-9,minecraft:crying_obsidian,20,minecraft:obsidian,100)
RB(-8,20,-9,minecraft:crying_obsidian,20,minecraft:obsidian,100)
RB(-8,12,-8,minecraft:crying_obsidian,20,minecraft:obsidian,100)
RB(-8,13,-8,minecraft:crying_obsidian,20,minecraft:obsidian,100)
RB(-8,14,-8,minecraft:crying_obsidian,20,minecraft:obsidian,100)
RB(-8,15,-8,minecraft:crying_obsidian,20,minecraft:obsidian,100)
RB(-8,16,-8,minecraft:crying_obsidian,20,minecraft:obsidian,100)
RB(-8,17,-8,minecraft:crying_obsidian,20,minecraft:obsidian,100)
RB(-8,18,-8,minecraft:crying_obsidian,20,minecraft:obsidian,100)
RB(-8,19,-8,minecraft:crying_obsidian,20,minecraft:obsidian,100)
RB(-8,20,-8,minecraft:crying_obsidian,20,minecraft:obsidian,100)
RB(-8,12,-7,minecraft:crying_obsidian,20,minecraft:obsidian,100)
RB(-8,13,-7,minecraft:crying_obsidian,20,minecraft:obsidian,100)
RB(-8,14,-7,minecraft:crying_obsidian,20,minecraft:obsidian,100)
RB(-8,15,-7,minecraft:crying_obsidian,20,minecraft:obsidian,100)
RB(-8,16,-7,minecraft:crying_obsidian,20,minecraft:obsidian,100)
RB(-8,17,-7,minecraft:crying_obsidian,20,minecraft:obsidian,100)
RB(-8,18,-7,minecraft:crying_obsidian,20,minecraft:obsidian,100)
RB(-8,19,-7,minecraft:crying_obsidian,20,minecraft:obsidian,100)
RB(-8,20,-7,minecraft:crying_obsidian,20,minecraft:obsidian,100)
RB(-8,12,-6,minecraft:crying_obsidian,20,minecraft:obsidian,100)
RB(-8,13,-6,minecraft:crying_obsidian,20,minecraft:obsidian,100)
RB(-8,14,-6,minecraft:crying_obsidian,20,minecraft:obsidian,100)
RB(-8,15,-6,minecraft:crying_obsidian,20,minecraft:obsidian,100)
RB(-8,16,-6,minecraft:crying_obsidian,20,minecraft:obsidian,100)
RB(-8,17,-6,minecraft:crying_obsidian,20,minecraft:obsidian,100)
RB(-8,18,-6,minecraft:crying_obsidian,20,minecraft:obsidian,100)
RB(-8,19,-6,minecraft:crying_obsidian,20,minecraft:obsidian,100)
RB(-8,20,-6,minecraft:crying_obsidian,20,minecraft:obsidian,100)
RB(-8,12,-5,minecraft:crying_obsidian,20,minecraft:obsidian,100)
RB(-8,13,-5,minecraft:crying_obsidian,20,minecraft:obsidian,100)
RB(-8,14,-5,minecraft:crying_obsidian,20,minecraft:obsidian,100)
RB(-8,15,-5,minecraft:crying_obsidian,20,minecraft:obsidian,100)
RB(-8,16,-5,minecraft:crying_obsidian,20,minecraft:obsidian,100)
RB(-8,17,-5,minecraft:crying_obsidian,20,minecraft:obsidian,100)
RB(-8,18,-5,minecraft:crying_obsidian,20,minecraft:obsidian,100)
RB(-8,19,-5,minecraft:crying_obsidian,20,minecraft:obsidian,100)
RB(-8,20,-5,minecraft:crying_obsidian,20,minecraft:obsidian,100)
RB(-8,21,-5,minecraft:crying_obsidian,20,minecraft:obsidian,100)
RB(-8,13,-4,minecraft:crying_obsidian,20,minecraft:obsidian,100)
RB(-8,14,-4,minecraft:crying_obsidian,20,minecraft:obsidian,100)
RB(-8,15,-4,minecraft:crying_obsidian,20,minecraft:obsidian,100)
RB(-8,16,-4,minecraft:crying_obsidian,20,minecraft:obsidian,100)
RB(-8,17,-4,minecraft:crying_obsidian,20,minecraft:obsidian,100)
RB(-8,18,-4,minecraft:crying_obsidian,20,minecraft:obsidian,100)
RB(-8,19,-4,minecraft:crying_obsidian,20,minecraft:obsidian,100)
RB(-8,15,-3,minecraft:crying_obsidian,20,minecraft:obsidian,100)
RB(-8,16,-3,minecraft:crying_obsidian,20,minecraft:obsidian,100)
RB(-8,17,-3,minecraft:crying_obsidian,20,minecraft:obsidian,100)
RB(-8,18,-3,minecraft:crying_obsidian,20,minecraft:obsidian,100)
RB(-8,12,-2,minecraft:crying_obsidian,20,minecraft:obsidian,100)
RB(-8,13,-2,minecraft:crying_obsidian,20,minecraft:obsidian,100)
RB(-8,14,-2,minecraft:crying_obsidian,20,minecraft:obsidian,100)
RB(-8,15,-2,minecraft:crying_obsidian,20,minecraft:obsidian,100)
RB(-8,16,-2,minecraft:crying_obsidian,20,minecraft:obsidian,100)
RB(-8,17,-2,minecraft:crying_obsidian,20,minecraft:obsidian,100)
RB(-8,18,-2,minecraft:crying_obsidian,20,minecraft:obsidian,100)
RB(-8,19,-2,minecraft:crying_obsidian,20,minecraft:obsidian,100)
RB(-8,20,-2,minecraft:crying_obsidian,20,minecraft:obsidian,100)
RB(-8,11,-1,minecraft:crying_obsidian,20,minecraft:obsidian,100)
RB(-8,12,-1,minecraft:crying_obsidian,20,minecraft:obsidian,100)
RB(-8,13,-1,minecraft:crying_obsidian,20,minecraft:obsidian,100)
RB(-8,14,-1,minecraft:crying_obsidian,20,minecraft:obsidian,100)
RB(-8,15,-1,minecraft:crying_obsidian,20,minecraft:obsidian,100)
RB(-8,16,-1,minecraft:crying_obsidian,20,minecraft:obsidian,100)
RB(-8,17,-1,minecraft:crying_obsidian,20,minecraft:obsidian,100)
RB(-8,18,-1,minecraft:crying_obsidian,20,minecraft:obsidian,100)
RB(-8,19,-1,minecraft:crying_obsidian,20,minecraft:obsidian,100)
RB(-8,20,-1,minecraft:crying_obsidian,20,minecraft:obsidian,100)
RB(-8,11,0,minecraft:crying_obsidian,20,minecraft:obsidian,100)
RB(-8,12,0,minecraft:crying_obsidian,20,minecraft:obsidian,100)
RB(-8,13,0,minecraft:crying_obsidian,20,minecraft:obsidian,100)
RB(-8,14,0,minecraft:crying_obsidian,20,minecraft:obsidian,100)
RB(-8,15,0,minecraft:crying_obsidian,20,minecraft:obsidian,100)
RB(-8,16,0,minecraft:crying_obsidian,20,minecraft:obsidian,100)
RB(-8,17,0,minecraft:crying_obsidian,20,minecraft:obsidian,100)
RB(-8,18,0,minecraft:crying_obsidian,20,minecraft:obsidian,100)
RB(-8,19,0,minecraft:crying_obsidian,20,minecraft:obsidian,100)
RB(-8,20,0,minecraft:crying_obsidian,20,minecraft:obsidian,100)
RB(-8,11,1,minecraft:crying_obsidian,20,minecraft:obsidian,100)
RB(-8,12,1,minecraft:crying_obsidian,20,minecraft:obsidian,100)
RB(-8,13,1,minecraft:crying_obsidian,20,minecraft:obsidian,100)
RB(-8,14,1,minecraft:crying_obsidian,20,minecraft:obsidian,100)
RB(-8,15,1,minecraft:crying_obsidian,20,minecraft:obsidian,100)
RB(-8,16,1,minecraft:crying_obsidian,20,minecraft:obsidian,100)
RB(-8,17,1,minecraft:crying_obsidian,20,minecraft:obsidian,100)
RB(-8,18,1,minecraft:crying_obsidian,20,minecraft:obsidian,100)
RB(-8,19,1,minecraft:crying_obsidian,20,minecraft:obsidian,100)
RB(-8,20,1,minecraft:crying_obsidian,20,minecraft:obsidian,100)
RB(-8,21,1,minecraft:crying_obsidian,20,minecraft:obsidian,100)
RB(-8,22,1,minecraft:crying_obsidian,20,minecraft:obsidian,100)
RB(-8,11,2,minecraft:crying_obsidian,20,minecraft:obsidian,100)
RB(-8,12,2,minecraft:crying_obsidian,20,minecraft:obsidian,100)
RB(-8,13,2,minecraft:crying_obsidian,20,minecraft:obsidian,100)
RB(-8,14,2,minecraft:crying_obsidian,20,minecraft:obsidian,100)
RB(-8,15,2,minecraft:crying_obsidian,20,minecraft:obsidian,100)
RB(-8,16,2,minecraft:crying_obsidian,20,minecraft:obsidian,100)
RB(-8,17,2,minecraft:crying_obsidian,20,minecraft:obsidian,100)
RB(-8,18,2,minecraft:crying_obsidian,20,minecraft:obsidian,100)
RB(-8,19,2,minecraft:crying_obsidian,20,minecraft:obsidian,100)
RB(-8,20,2,minecraft:crying_obsidian,20,minecraft:obsidian,100)
RB(-8,21,2,minecraft:crying_obsidian,20,minecraft:obsidian,100)
RB(-8,22,2,minecraft:crying_obsidian,20,minecraft:obsidian,100)
RB(-8,11,3,minecraft:crying_obsidian,20,minecraft:obsidian,100)
RB(-8,12,3,minecraft:crying_obsidian,20,minecraft:obsidian,100)
RB(-8,13,3,minecraft:crying_obsidian,20,minecraft:obsidian,100)
RB(-8,14,3,minecraft:crying_obsidian,20,minecraft:obsidian,100)
RB(-8,15,3,minecraft:crying_obsidian,20,minecraft:obsidian,100)
RB(-8,16,3,minecraft:crying_obsidian,20,minecraft:obsidian,100)
RB(-8,17,3,minecraft:crying_obsidian,20,minecraft:obsidian,100)
RB(-8,18,3,minecraft:crying_obsidian,20,minecraft:obsidian,100)
RB(-8,19,3,minecraft:crying_obsidian,20,minecraft:obsidian,100)
RB(-8,20,3,minecraft:crying_obsidian,20,minecraft:obsidian,100)
RB(-8,21,3,minecraft:crying_obsidian,20,minecraft:obsidian,100)
RB(-8,22,3,minecraft:crying_obsidian,20,minecraft:obsidian,100)
RB(-8,12,4,minecraft:crying_obsidian,20,minecraft:obsidian,100)
RB(-8,13,4,minecraft:crying_obsidian,20,minecraft:obsidian,100)
RB(-8,14,4,minecraft:crying_obsidian,20,minecraft:obsidian,100)
RB(-8,15,4,minecraft:crying_obsidian,20,minecraft:obsidian,100)
RB(-8,16,4,minecraft:crying_obsidian,20,minecraft:obsidian,100)
RB(-8,17,4,minecraft:crying_obsidian,20,minecraft:obsidian,100)
RB(-8,18,4,minecraft:crying_obsidian,20,minecraft:obsidian,100)
RB(-8,19,4,minecraft:crying_obsidian,20,minecraft:obsidian,100)
RB(-8,20,4,minecraft:crying_obsidian,20,minecraft:obsidian,100)
RB(-8,21,4,minecraft:crying_obsidian,20,minecraft:obsidian,100)
RB(-8,12,5,minecraft:crying_obsidian,20,minecraft:obsidian,100)
RB(-8,13,5,minecraft:crying_obsidian,20,minecraft:obsidian,100)
RB(-8,14,5,minecraft:crying_obsidian,20,minecraft:obsidian,100)
RB(-8,15,5,minecraft:crying_obsidian,20,minecraft:obsidian,100)
RB(-8,16,5,minecraft:crying_obsidian,20,minecraft:obsidian,100)
RB(-8,17,5,minecraft:crying_obsidian,20,minecraft:obsidian,100)
RB(-8,18,5,minecraft:crying_obsidian,20,minecraft:obsidian,100)
RB(-8,19,5,minecraft:crying_obsidian,20,minecraft:obsidian,100)
RB(-8,20,5,minecraft:crying_obsidian,20,minecraft:obsidian,100)
RB(-8,21,5,minecraft:crying_obsidian,20,minecraft:obsidian,100)
RB(-8,22,5,minecraft:crying_obsidian,20,minecraft:obsidian,100)
RB(-8,13,6,minecraft:crying_obsidian,20,minecraft:obsidian,100)
RB(-8,14,6,minecraft:crying_obsidian,20,minecraft:obsidian,100)
RB(-8,15,6,minecraft:crying_obsidian,20,minecraft:obsidian,100)
RB(-8,16,6,minecraft:crying_obsidian,20,minecraft:obsidian,100)
RB(-8,17,6,minecraft:crying_obsidian,20,minecraft:obsidian,100)
RB(-8,18,6,minecraft:crying_obsidian,20,minecraft:obsidian,100)
RB(-8,19,6,minecraft:crying_obsidian,20,minecraft:obsidian,100)
RB(-8,20,6,minecraft:crying_obsidian,20,minecraft:obsidian,100)
RB(-8,21,6,minecraft:crying_obsidian,20,minecraft:obsidian,100)
RB(-8,13,7,minecraft:crying_obsidian,20,minecraft:obsidian,100)
RB(-8,14,7,minecraft:crying_obsidian,20,minecraft:obsidian,100)
RB(-8,15,7,minecraft:crying_obsidian,20,minecraft:obsidian,100)
RB(-8,16,7,minecraft:crying_obsidian,20,minecraft:obsidian,100)
RB(-8,17,7,minecraft:crying_obsidian,20,minecraft:obsidian,100)
RB(-8,18,7,minecraft:crying_obsidian,20,minecraft:obsidian,100)
RB(-8,19,7,minecraft:crying_obsidian,20,minecraft:obsidian,100)
RB(-8,20,7,minecraft:crying_obsidian,20,minecraft:obsidian,100)
RB(-8,21,7,minecraft:crying_obsidian,20,minecraft:obsidian,100)
RB(-8,11,8,minecraft:crying_obsidian,20,minecraft:obsidian,100)
RB(-8,12,8,minecraft:crying_obsidian,20,minecraft:obsidian,100)
RB(-8,13,8,minecraft:crying_obsidian,20,minecraft:obsidian,100)
RB(-8,14,8,minecraft:crying_obsidian,20,minecraft:obsidian,100)
RB(-8,15,8,minecraft:crying_obsidian,20,minecraft:obsidian,100)
RB(-8,16,8,minecraft:crying_obsidian,20,minecraft:obsidian,100)
RB(-8,17,8,minecraft:crying_obsidian,20,minecraft:obsidian,100)
RB(-8,18,8,minecraft:crying_obsidian,20,minecraft:obsidian,100)
RB(-8,19,8,minecraft:crying_obsidian,20,minecraft:obsidian,100)
RB(-8,20,8,minecraft:crying_obsidian,20,minecraft:obsidian,100)
RB(-8,21,8,minecraft:crying_obsidian,20,minecraft:obsidian,100)
RB(-8,22,8,minecraft:crying_obsidian,20,minecraft:obsidian,100)
RB(-8,11,9,minecraft:crying_obsidian,20,minecraft:obsidian,100)
RB(-8,12,9,minecraft:crying_obsidian,20,minecraft:obsidian,100)
RB(-8,13,9,minecraft:crying_obsidian,20,minecraft:obsidian,100)
RB(-8,14,9,minecraft:crying_obsidian,20,minecraft:obsidian,100)
RB(-8,15,9,minecraft:crying_obsidian,20,minecraft:obsidian,100)
RB(-8,16,9,minecraft:crying_obsidian,20,minecraft:obsidian,100)
RB(-8,17,9,minecraft:crying_obsidian,20,minecraft:obsidian,100)
RB(-8,18,9,minecraft:crying_obsidian,20,minecraft:obsidian,100)
RB(-8,19,9,minecraft:crying_obsidian,20,minecraft:obsidian,100)
RB(-8,20,9,minecraft:crying_obsidian,20,minecraft:obsidian,100)
RB(-8,21,9,minecraft:crying_obsidian,20,minecraft:obsidian,100)
RB(-8,22,9,minecraft:crying_obsidian,20,minecraft:obsidian,100)
RB(-8,11,10,minecraft:crying_obsidian,20,minecraft:obsidian,100)
RB(-8,12,10,minecraft:crying_obsidian,20,minecraft:obsidian,100)
RB(-8,13,10,minecraft:crying_obsidian,20,minecraft:obsidian,100)
RB(-8,14,10,minecraft:crying_obsidian,20,minecraft:obsidian,100)
RB(-8,15,10,minecraft:crying_obsidian,20,minecraft:obsidian,100)
RB(-8,16,10,minecraft:crying_obsidian,20,minecraft:obsidian,100)
RB(-8,17,10,minecraft:crying_obsidian,20,minecraft:obsidian,100)
RB(-8,18,10,minecraft:crying_obsidian,20,minecraft:obsidian,100)
RB(-8,19,10,minecraft:crying_obsidian,20,minecraft:obsidian,100)
RB(-8,20,10,minecraft:crying_obsidian,20,minecraft:obsidian,100)
RB(-8,21,10,minecraft:crying_obsidian,20,minecraft:obsidian,100)
RB(-8,11,11,minecraft:crying_obsidian,20,minecraft:obsidian,100)
RB(-8,12,11,minecraft:crying_obsidian,20,minecraft:obsidian,100)
RB(-8,13,11,minecraft:crying_obsidian,20,minecraft:obsidian,100)
RB(-8,14,11,minecraft:crying_obsidian,20,minecraft:obsidian,100)
RB(-8,15,11,minecraft:crying_obsidian,20,minecraft:obsidian,100)
RB(-8,16,11,minecraft:crying_obsidian,20,minecraft:obsidian,100)
RB(-8,17,11,minecraft:crying_obsidian,20,minecraft:obsidian,100)
RB(-8,18,11,minecraft:crying_obsidian,20,minecraft:obsidian,100)
RB(-8,19,11,minecraft:crying_obsidian,20,minecraft:obsidian,100)
RB(-8,20,11,minecraft:crying_obsidian,20,minecraft:obsidian,100)
RB(-8,21,11,minecraft:crying_obsidian,20,minecraft:obsidian,100)
RB(-8,11,12,minecraft:crying_obsidian,20,minecraft:obsidian,100)
RB(-8,12,12,minecraft:crying_obsidian,20,minecraft:obsidian,100)
RB(-8,13,12,minecraft:crying_obsidian,20,minecraft:obsidian,100)
RB(-8,14,12,minecraft:crying_obsidian,20,minecraft:obsidian,100)
RB(-8,15,12,minecraft:crying_obsidian,20,minecraft:obsidian,100)
RB(-8,16,12,minecraft:crying_obsidian,20,minecraft:obsidian,100)
RB(-8,17,12,minecraft:crying_obsidian,20,minecraft:obsidian,100)
RB(-8,18,12,minecraft:crying_obsidian,20,minecraft:obsidian,100)
RB(-8,19,12,minecraft:crying_obsidian,20,minecraft:obsidian,100)
RB(-8,20,12,minecraft:crying_obsidian,20,minecraft:obsidian,100)
RB(-8,21,12,minecraft:crying_obsidian,20,minecraft:obsidian,100)
RB(-8,12,13,minecraft:crying_obsidian,20,minecraft:obsidian,100)
RB(-8,13,13,minecraft:crying_obsidian,20,minecraft:obsidian,100)
RB(-8,14,13,minecraft:crying_obsidian,20,minecraft:obsidian,100)
RB(-8,15,13,minecraft:crying_obsidian,20,minecraft:obsidian,100)
RB(-8,16,13,minecraft:crying_obsidian,20,minecraft:obsidian,100)
RB(-8,17,13,minecraft:crying_obsidian,20,minecraft:obsidian,100)
RB(-8,18,13,minecraft:crying_obsidian,20,minecraft:obsidian,100)
RB(-8,19,13,minecraft:crying_obsidian,20,minecraft:obsidian,100)
RB(-8,20,13,minecraft:crying_obsidian,20,minecraft:obsidian,100)
RB(-8,13,14,minecraft:crying_obsidian,20,minecraft:obsidian,100)
RB(-8,14,14,minecraft:crying_obsidian,20,minecraft:obsidian,100)
RB(-8,15,14,minecraft:crying_obsidian,20,minecraft:obsidian,100)
RB(-8,16,14,minecraft:crying_obsidian,20,minecraft:obsidian,100)
RB(-8,17,14,minecraft:crying_obsidian,20,minecraft:obsidian,100)
RB(-8,18,14,minecraft:crying_obsidian,20,minecraft:obsidian,100)
RB(-8,19,14,minecraft:crying_obsidian,20,minecraft:obsidian,100)
RB(-8,14,15,minecraft:crying_obsidian,20,minecraft:obsidian,100)
RB(-8,15,15,minecraft:crying_obsidian,20,minecraft:obsidian,100)
RB(-8,16,15,minecraft:crying_obsidian,20,minecraft:obsidian,100)
RB(-8,17,15,minecraft:crying_obsidian,20,minecraft:obsidian,100)
RB(-8,18,15,minecraft:crying_obsidian,20,minecraft:obsidian,100)
RB(-7,13,-11,minecraft:crying_obsidian,20,minecraft:obsidian,100)
RB(-7,14,-11,minecraft:crying_obsidian,20,minecraft:obsidian,100)
RB(-7,15,-11,minecraft:crying_obsidian,20,minecraft:obsidian,100)
RB(-7,16,-11,minecraft:crying_obsidian,20,minecraft:obsidian,100)
RB(-7,17,-11,minecraft:crying_obsidian,20,minecraft:obsidian,100)
RB(-7,12,-10,minecraft:crying_obsidian,20,minecraft:obsidian,100)
RB(-7,13,-10,minecraft:crying_obsidian,20,minecraft:obsidian,100)
RB(-7,14,-10,minecraft:crying_obsidian,20,minecraft:obsidian,100)
RB(-7,15,-10,minecraft:crying_obsidian,20,minecraft:obsidian,100)
RB(-7,16,-10,minecraft:crying_obsidian,20,minecraft:obsidian,100)
RB(-7,17,-10,minecraft:crying_obsidian,20,minecraft:obsidian,100)
RB(-7,18,-10,minecraft:crying_obsidian,20,minecraft:obsidian,100)
RB(-7,19,-10,minecraft:crying_obsidian,20,minecraft:obsidian,100)
RB(-7,20,-10,minecraft:crying_obsidian,20,minecraft:obsidian,100)
RB(-7,11,-9,minecraft:crying_obsidian,20,minecraft:obsidian,100)
RB(-7,12,-9,minecraft:crying_obsidian,20,minecraft:obsidian,100)
RB(-7,13,-9,minecraft:crying_obsidian,20,minecraft:obsidian,100)
RB(-7,14,-9,minecraft:crying_obsidian,20,minecraft:obsidian,100)
RB(-7,15,-9,minecraft:crying_obsidian,20,minecraft:obsidian,100)
RB(-7,16,-9,minecraft:crying_obsidian,20,minecraft:obsidian,100)
RB(-7,17,-9,minecraft:crying_obsidian,20,minecraft:obsidian,100)
RB(-7,18,-9,minecraft:crying_obsidian,20,minecraft:obsidian,100)
RB(-7,19,-9,minecraft:crying_obsidian,20,minecraft:obsidian,100)
RB(-7,20,-9,minecraft:crying_obsidian,20,minecraft:obsidian,100)
RB(-7,21,-9,minecraft:crying_obsidian,20,minecraft:obsidian,100)
RB(-7,11,-8,minecraft:crying_obsidian,20,minecraft:obsidian,100)
RB(-7,12,-8,minecraft:crying_obsidian,20,minecraft:obsidian,100)
RB(-7,13,-8,minecraft:crying_obsidian,20,minecraft:obsidian,100)
RB(-7,14,-8,minecraft:crying_obsidian,20,minecraft:obsidian,100)
RB(-7,15,-8,minecraft:crying_obsidian,20,minecraft:obsidian,100)
RB(-7,16,-8,minecraft:crying_obsidian,20,minecraft:obsidian,100)
RB(-7,17,-8,minecraft:crying_obsidian,20,minecraft:obsidian,100)
RB(-7,18,-8,minecraft:crying_obsidian,20,minecraft:obsidian,100)
RB(-7,19,-8,minecraft:crying_obsidian,20,minecraft:obsidian,100)
RB(-7,20,-8,minecraft:crying_obsidian,20,minecraft:obsidian,100)
RB(-7,21,-8,minecraft:crying_obsidian,20,minecraft:obsidian,100)
RB(-7,11,-7,minecraft:crying_obsidian,20,minecraft:obsidian,100)
RB(-7,12,-7,minecraft:crying_obsidian,20,minecraft:obsidian,100)
RB(-7,13,-7,minecraft:crying_obsidian,20,minecraft:obsidian,100)
RB(-7,14,-7,minecraft:crying_obsidian,20,minecraft:obsidian,100)
RB(-7,15,-7,minecraft:crying_obsidian,20,minecraft:obsidian,100)
RB(-7,16,-7,minecraft:crying_obsidian,20,minecraft:obsidian,100)
RB(-7,17,-7,minecraft:crying_obsidian,20,minecraft:obsidian,100)
RB(-7,18,-7,minecraft:crying_obsidian,20,minecraft:obsidian,100)
RB(-7,19,-7,minecraft:crying_obsidian,20,minecraft:obsidian,100)
RB(-7,20,-7,minecraft:crying_obsidian,20,minecraft:obsidian,100)
RB(-7,21,-7,minecraft:crying_obsidian,20,minecraft:obsidian,100)
RB(-7,11,-6,minecraft:crying_obsidian,20,minecraft:obsidian,100)
RB(-7,12,-6,minecraft:crying_obsidian,20,minecraft:obsidian,100)
RB(-7,13,-6,minecraft:crying_obsidian,20,minecraft:obsidian,100)
RB(-7,14,-6,minecraft:crying_obsidian,20,minecraft:obsidian,100)
RB(-7,15,-6,minecraft:crying_obsidian,20,minecraft:obsidian,100)
RB(-7,16,-6,minecraft:crying_obsidian,20,minecraft:obsidian,100)
RB(-7,17,-6,minecraft:crying_obsidian,20,minecraft:obsidian,100)
RB(-7,18,-6,minecraft:crying_obsidian,20,minecraft:obsidian,100)
RB(-7,19,-6,minecraft:crying_obsidian,20,minecraft:obsidian,100)
RB(-7,20,-6,minecraft:crying_obsidian,20,minecraft:obsidian,100)
RB(-7,21,-6,minecraft:crying_obsidian,20,minecraft:obsidian,100)
RB(-7,11,-5,minecraft:crying_obsidian,20,minecraft:obsidian,100)
RB(-7,12,-5,minecraft:crying_obsidian,20,minecraft:obsidian,100)
RB(-7,13,-5,minecraft:crying_obsidian,20,minecraft:obsidian,100)
RB(-7,14,-5,minecraft:crying_obsidian,20,minecraft:obsidian,100)
RB(-7,15,-5,minecraft:crying_obsidian,20,minecraft:obsidian,100)
RB(-7,16,-5,minecraft:crying_obsidian,20,minecraft:obsidian,100)
RB(-7,17,-5,minecraft:crying_obsidian,20,minecraft:obsidian,100)
RB(-7,18,-5,minecraft:crying_obsidian,20,minecraft:obsidian,100)
RB(-7,19,-5,minecraft:crying_obsidian,20,minecraft:obsidian,100)
RB(-7,20,-5,minecraft:crying_obsidian,20,minecraft:obsidian,100)
RB(-7,21,-5,minecraft:crying_obsidian,20,minecraft:obsidian,100)
RB(-7,12,-4,minecraft:crying_obsidian,20,minecraft:obsidian,100)
RB(-7,13,-4,minecraft:crying_obsidian,20,minecraft:obsidian,100)
RB(-7,14,-4,minecraft:crying_obsidian,20,minecraft:obsidian,100)
RB(-7,15,-4,minecraft:crying_obsidian,20,minecraft:obsidian,100)
RB(-7,16,-4,minecraft:crying_obsidian,20,minecraft:obsidian,100)
RB(-7,17,-4,minecraft:crying_obsidian,20,minecraft:obsidian,100)
RB(-7,18,-4,minecraft:crying_obsidian,20,minecraft:obsidian,100)
RB(-7,19,-4,minecraft:crying_obsidian,20,minecraft:obsidian,100)
RB(-7,20,-4,minecraft:crying_obsidian,20,minecraft:obsidian,100)
RB(-7,13,-3,minecraft:crying_obsidian,20,minecraft:obsidian,100)
RB(-7,14,-3,minecraft:crying_obsidian,20,minecraft:obsidian,100)
RB(-7,15,-3,minecraft:crying_obsidian,20,minecraft:obsidian,100)
RB(-7,16,-3,minecraft:crying_obsidian,20,minecraft:obsidian,100)
RB(-7,17,-3,minecraft:crying_obsidian,20,minecraft:obsidian,100)
RB(-7,18,-3,minecraft:crying_obsidian,20,minecraft:obsidian,100)
RB(-7,19,-3,minecraft:crying_obsidian,20,minecraft:obsidian,100)
RB(-7,12,-2,minecraft:crying_obsidian,20,minecraft:obsidian,100)
RB(-7,13,-2,minecraft:crying_obsidian,20,minecraft:obsidian,100)
RB(-7,14,-2,minecraft:crying_obsidian,20,minecraft:obsidian,100)
RB(-7,15,-2,minecraft:crying_obsidian,20,minecraft:obsidian,100)
RB(-7,16,-2,minecraft:crying_obsidian,20,minecraft:obsidian,100)
RB(-7,17,-2,minecraft:crying_obsidian,20,minecraft:obsidian,100)
RB(-7,18,-2,minecraft:crying_obsidian,20,minecraft:obsidian,100)
RB(-7,19,-2,minecraft:crying_obsidian,20,minecraft:obsidian,100)
RB(-7,11,-1,minecraft:crying_obsidian,20,minecraft:obsidian,100)
RB(-7,12,-1,minecraft:crying_obsidian,20,minecraft:obsidian,100)
RB(-7,13,-1,minecraft:crying_obsidian,20,minecraft:obsidian,100)
RB(-7,14,-1,minecraft:crying_obsidian,20,minecraft:obsidian,100)
RB(-7,15,-1,minecraft:crying_obsidian,20,minecraft:obsidian,100)
RB(-7,16,-1,minecraft:crying_obsidian,20,minecraft:obsidian,100)
RB(-7,17,-1,minecraft:crying_obsidian,20,minecraft:obsidian,100)
RB(-7,18,-1,minecraft:crying_obsidian,20,minecraft:obsidian,100)
RB(-7,19,-1,minecraft:crying_obsidian,20,minecraft:obsidian,100)
RB(-7,20,-1,minecraft:crying_obsidian,20,minecraft:obsidian,100)
RB(-7,10,0,minecraft:crying_obsidian,20,minecraft:obsidian,100)
RB(-7,11,0,minecraft:crying_obsidian,20,minecraft:obsidian,100)
RB(-7,12,0,minecraft:crying_obsidian,20,minecraft:obsidian,100)
RB(-7,13,0,minecraft:crying_obsidian,20,minecraft:obsidian,100)
RB(-7,14,0,minecraft:crying_obsidian,20,minecraft:obsidian,100)
RB(-7,15,0,minecraft:crying_obsidian,20,minecraft:obsidian,100)
RB(-7,16,0,minecraft:crying_obsidian,20,minecraft:obsidian,100)
RB(-7,17,0,minecraft:crying_obsidian,20,minecraft:obsidian,100)
RB(-7,18,0,minecraft:crying_obsidian,20,minecraft:obsidian,100)
RB(-7,19,0,minecraft:crying_obsidian,20,minecraft:obsidian,100)
RB(-7,20,0,minecraft:crying_obsidian,20,minecraft:obsidian,100)
RB(-7,21,0,minecraft:crying_obsidian,20,minecraft:obsidian,100)
RB(-7,22,0,minecraft:crying_obsidian,20,minecraft:obsidian,100)
RB(-7,10,1,minecraft:crying_obsidian,20,minecraft:obsidian,100)
RB(-7,11,1,minecraft:crying_obsidian,20,minecraft:obsidian,100)
RB(-7,12,1,minecraft:crying_obsidian,20,minecraft:obsidian,100)
RB(-7,13,1,minecraft:crying_obsidian,20,minecraft:obsidian,100)
RB(-7,14,1,minecraft:crying_obsidian,20,minecraft:obsidian,100)
RB(-7,15,1,minecraft:crying_obsidian,20,minecraft:obsidian,100)
RB(-7,16,1,minecraft:crying_obsidian,20,minecraft:obsidian,100)
RB(-7,17,1,minecraft:crying_obsidian,20,minecraft:obsidian,100)
RB(-7,18,1,minecraft:crying_obsidian,20,minecraft:obsidian,100)
RB(-7,19,1,minecraft:crying_obsidian,20,minecraft:obsidian,100)
RB(-7,20,1,minecraft:crying_obsidian,20,minecraft:obsidian,100)
RB(-7,21,1,minecraft:crying_obsidian,20,minecraft:obsidian,100)
RB(-7,22,1,minecraft:crying_obsidian,20,minecraft:obsidian,100)
RB(-7,11,2,minecraft:crying_obsidian,20,minecraft:obsidian,100)
RB(-7,12,2,minecraft:crying_obsidian,20,minecraft:obsidian,100)
RB(-7,13,2,minecraft:crying_obsidian,20,minecraft:obsidian,100)
RB(-7,14,2,minecraft:crying_obsidian,20,minecraft:obsidian,100)
RB(-7,15,2,minecraft:crying_obsidian,20,minecraft:obsidian,100)
RB(-7,16,2,minecraft:crying_obsidian,20,minecraft:obsidian,100)
RB(-7,17,2,minecraft:crying_obsidian,20,minecraft:obsidian,100)
RB(-7,18,2,minecraft:crying_obsidian,20,minecraft:obsidian,100)
RB(-7,19,2,minecraft:crying_obsidian,20,minecraft:obsidian,100)
RB(-7,20,2,minecraft:crying_obsidian,20,minecraft:obsidian,100)
RB(-7,21,2,minecraft:crying_obsidian,20,minecraft:obsidian,100)
RB(-7,22,2,minecraft:crying_obsidian,20,minecraft:obsidian,100)
RB(-7,11,3,minecraft:crying_obsidian,20,minecraft:obsidian,100)
RB(-7,12,3,minecraft:crying_obsidian,20,minecraft:obsidian,100)
RB(-7,13,3,minecraft:crying_obsidian,20,minecraft:obsidian,100)
RB(-7,14,3,minecraft:crying_obsidian,20,minecraft:obsidian,100)
RB(-7,15,3,minecraft:crying_obsidian,20,minecraft:obsidian,100)
RB(-7,16,3,minecraft:crying_obsidian,20,minecraft:obsidian,100)
RB(-7,17,3,minecraft:crying_obsidian,20,minecraft:obsidian,100)
RB(-7,18,3,minecraft:crying_obsidian,20,minecraft:obsidian,100)
RB(-7,19,3,minecraft:crying_obsidian,20,minecraft:obsidian,100)
RB(-7,20,3,minecraft:crying_obsidian,20,minecraft:obsidian,100)
RB(-7,21,3,minecraft:crying_obsidian,20,minecraft:obsidian,100)
RB(-7,22,3,minecraft:crying_obsidian,20,minecraft:obsidian,100)
RB(-7,11,4,minecraft:crying_obsidian,20,minecraft:obsidian,100)
RB(-7,12,4,minecraft:crying_obsidian,20,minecraft:obsidian,100)
RB(-7,13,4,minecraft:crying_obsidian,20,minecraft:obsidian,100)
RB(-7,14,4,minecraft:crying_obsidian,20,minecraft:obsidian,100)
RB(-7,15,4,minecraft:crying_obsidian,20,minecraft:obsidian,100)
RB(-7,16,4,minecraft:crying_obsidian,20,minecraft:obsidian,100)
RB(-7,17,4,minecraft:crying_obsidian,20,minecraft:obsidian,100)
RB(-7,18,4,minecraft:crying_obsidian,20,minecraft:obsidian,100)
RB(-7,19,4,minecraft:crying_obsidian,20,minecraft:obsidian,100)
RB(-7,20,4,minecraft:crying_obsidian,20,minecraft:obsidian,100)
RB(-7,21,4,minecraft:crying_obsidian,20,minecraft:obsidian,100)
RB(-7,22,4,minecraft:crying_obsidian,20,minecraft:obsidian,100)
RB(-7,23,4,minecraft:crying_obsidian,20,minecraft:obsidian,100)
RB(-7,12,5,minecraft:crying_obsidian,20,minecraft:obsidian,100)
RB(-7,13,5,minecraft:crying_obsidian,20,minecraft:obsidian,100)
RB(-7,14,5,minecraft:crying_obsidian,20,minecraft:obsidian,100)
RB(-7,15,5,minecraft:crying_obsidian,20,minecraft:obsidian,100)
RB(-7,16,5,minecraft:crying_obsidian,20,minecraft:obsidian,100)
RB(-7,17,5,minecraft:crying_obsidian,20,minecraft:obsidian,100)
RB(-7,18,5,minecraft:crying_obsidian,20,minecraft:obsidian,100)
RB(-7,19,5,minecraft:crying_obsidian,20,minecraft:obsidian,100)
RB(-7,20,5,minecraft:crying_obsidian,20,minecraft:obsidian,100)
RB(-7,21,5,minecraft:crying_obsidian,20,minecraft:obsidian,100)
RB(-7,22,5,minecraft:crying_obsidian,20,minecraft:obsidian,100)
RB(-7,23,5,minecraft:crying_obsidian,20,minecraft:obsidian,100)
RB(-7,13,6,minecraft:crying_obsidian,20,minecraft:obsidian,100)
RB(-7,14,6,minecraft:crying_obsidian,20,minecraft:obsidian,100)
RB(-7,15,6,minecraft:crying_obsidian,20,minecraft:obsidian,100)
RB(-7,16,6,minecraft:crying_obsidian,20,minecraft:obsidian,100)
RB(-7,17,6,minecraft:crying_obsidian,20,minecraft:obsidian,100)
RB(-7,18,6,minecraft:crying_obsidian,20,minecraft:obsidian,100)
RB(-7,19,6,minecraft:crying_obsidian,20,minecraft:obsidian,100)
RB(-7,20,6,minecraft:crying_obsidian,20,minecraft:obsidian,100)
RB(-7,21,6,minecraft:crying_obsidian,20,minecraft:obsidian,100)
RB(-7,22,6,minecraft:crying_obsidian,20,minecraft:obsidian,100)
RB(-7,23,6,minecraft:crying_obsidian,20,minecraft:obsidian,100)
RB(-7,12,7,minecraft:crying_obsidian,20,minecraft:obsidian,100)
RB(-7,13,7,minecraft:crying_obsidian,20,minecraft:obsidian,100)
RB(-7,14,7,minecraft:crying_obsidian,20,minecraft:obsidian,100)
RB(-7,15,7,minecraft:crying_obsidian,20,minecraft:obsidian,100)
RB(-7,16,7,minecraft:crying_obsidian,20,minecraft:obsidian,100)
RB(-7,17,7,minecraft:crying_obsidian,20,minecraft:obsidian,100)
RB(-7,18,7,minecraft:crying_obsidian,20,minecraft:obsidian,100)
RB(-7,19,7,minecraft:crying_obsidian,20,minecraft:obsidian,100)
RB(-7,20,7,minecraft:crying_obsidian,20,minecraft:obsidian,100)
RB(-7,21,7,minecraft:crying_obsidian,20,minecraft:obsidian,100)
RB(-7,22,7,minecraft:crying_obsidian,20,minecraft:obsidian,100)
RB(-7,11,8,minecraft:crying_obsidian,20,minecraft:obsidian,100)
RB(-7,12,8,minecraft:crying_obsidian,20,minecraft:obsidian,100)
RB(-7,13,8,minecraft:crying_obsidian,20,minecraft:obsidian,100)
RB(-7,14,8,minecraft:crying_obsidian,20,minecraft:obsidian,100)
RB(-7,15,8,minecraft:crying_obsidian,20,minecraft:obsidian,100)
RB(-7,16,8,minecraft:crying_obsidian,20,minecraft:obsidian,100)
RB(-7,17,8,minecraft:crying_obsidian,20,minecraft:obsidian,100)
RB(-7,18,8,minecraft:crying_obsidian,20,minecraft:obsidian,100)
RB(-7,19,8,minecraft:crying_obsidian,20,minecraft:obsidian,100)
RB(-7,20,8,minecraft:crying_obsidian,20,minecraft:obsidian,100)
RB(-7,21,8,minecraft:crying_obsidian,20,minecraft:obsidian,100)
RB(-7,22,8,minecraft:crying_obsidian,20,minecraft:obsidian,100)
RB(-7,11,9,minecraft:crying_obsidian,20,minecraft:obsidian,100)
RB(-7,12,9,minecraft:crying_obsidian,20,minecraft:obsidian,100)
RB(-7,13,9,minecraft:crying_obsidian,20,minecraft:obsidian,100)
RB(-7,14,9,minecraft:crying_obsidian,20,minecraft:obsidian,100)
RB(-7,15,9,minecraft:crying_obsidian,20,minecraft:obsidian,100)
RB(-7,16,9,minecraft:crying_obsidian,20,minecraft:obsidian,100)
RB(-7,17,9,minecraft:crying_obsidian,20,minecraft:obsidian,100)
RB(-7,18,9,minecraft:crying_obsidian,20,minecraft:obsidian,100)
RB(-7,19,9,minecraft:crying_obsidian,20,minecraft:obsidian,100)
RB(-7,20,9,minecraft:crying_obsidian,20,minecraft:obsidian,100)
RB(-7,21,9,minecraft:crying_obsidian,20,minecraft:obsidian,100)
RB(-7,22,9,minecraft:crying_obsidian,20,minecraft:obsidian,100)
RB(-7,11,10,minecraft:crying_obsidian,20,minecraft:obsidian,100)
RB(-7,12,10,minecraft:crying_obsidian,20,minecraft:obsidian,100)
RB(-7,13,10,minecraft:crying_obsidian,20,minecraft:obsidian,100)
RB(-7,14,10,minecraft:crying_obsidian,20,minecraft:obsidian,100)
RB(-7,15,10,minecraft:crying_obsidian,20,minecraft:obsidian,100)
RB(-7,16,10,minecraft:crying_obsidian,20,minecraft:obsidian,100)
RB(-7,17,10,minecraft:crying_obsidian,20,minecraft:obsidian,100)
RB(-7,18,10,minecraft:crying_obsidian,20,minecraft:obsidian,100)
RB(-7,19,10,minecraft:crying_obsidian,20,minecraft:obsidian,100)
RB(-7,20,10,minecraft:crying_obsidian,20,minecraft:obsidian,100)
RB(-7,21,10,minecraft:crying_obsidian,20,minecraft:obsidian,100)
RB(-7,11,11,minecraft:crying_obsidian,20,minecraft:obsidian,100)
RB(-7,12,11,minecraft:crying_obsidian,20,minecraft:obsidian,100)
RB(-7,13,11,minecraft:crying_obsidian,20,minecraft:obsidian,100)
RB(-7,14,11,minecraft:crying_obsidian,20,minecraft:obsidian,100)
RB(-7,15,11,minecraft:crying_obsidian,20,minecraft:obsidian,100)
RB(-7,16,11,minecraft:crying_obsidian,20,minecraft:obsidian,100)
RB(-7,17,11,minecraft:crying_obsidian,20,minecraft:obsidian,100)
RB(-7,18,11,minecraft:crying_obsidian,20,minecraft:obsidian,100)
RB(-7,19,11,minecraft:crying_obsidian,20,minecraft:obsidian,100)
RB(-7,20,11,minecraft:crying_obsidian,20,minecraft:obsidian,100)
RB(-7,21,11,minecraft:crying_obsidian,20,minecraft:obsidian,100)
RB(-7,11,12,minecraft:crying_obsidian,20,minecraft:obsidian,100)
RB(-7,12,12,minecraft:crying_obsidian,20,minecraft:obsidian,100)
RB(-7,13,12,minecraft:crying_obsidian,20,minecraft:obsidian,100)
RB(-7,14,12,minecraft:crying_obsidian,20,minecraft:obsidian,100)
RB(-7,15,12,minecraft:crying_obsidian,20,minecraft:obsidian,100)
RB(-7,16,12,minecraft:crying_obsidian,20,minecraft:obsidian,100)
RB(-7,17,12,minecraft:crying_obsidian,20,minecraft:obsidian,100)
RB(-7,18,12,minecraft:crying_obsidian,20,minecraft:obsidian,100)
RB(-7,19,12,minecraft:crying_obsidian,20,minecraft:obsidian,100)
RB(-7,20,12,minecraft:crying_obsidian,20,minecraft:obsidian,100)
RB(-7,21,12,minecraft:crying_obsidian,20,minecraft:obsidian,100)
RB(-7,12,13,minecraft:crying_obsidian,20,minecraft:obsidian,100)
RB(-7,13,13,minecraft:crying_obsidian,20,minecraft:obsidian,100)
RB(-7,14,13,minecraft:crying_obsidian,20,minecraft:obsidian,100)
RB(-7,15,13,minecraft:crying_obsidian,20,minecraft:obsidian,100)
RB(-7,16,13,minecraft:crying_obsidian,20,minecraft:obsidian,100)
RB(-7,17,13,minecraft:crying_obsidian,20,minecraft:obsidian,100)
RB(-7,18,13,minecraft:crying_obsidian,20,minecraft:obsidian,100)
RB(-7,19,13,minecraft:crying_obsidian,20,minecraft:obsidian,100)
RB(-7,20,13,minecraft:crying_obsidian,20,minecraft:obsidian,100)
RB(-7,13,14,minecraft:crying_obsidian,20,minecraft:obsidian,100)
RB(-7,14,14,minecraft:crying_obsidian,20,minecraft:obsidian,100)
RB(-7,15,14,minecraft:crying_obsidian,20,minecraft:obsidian,100)
RB(-7,16,14,minecraft:crying_obsidian,20,minecraft:obsidian,100)
RB(-7,17,14,minecraft:crying_obsidian,20,minecraft:obsidian,100)
RB(-7,18,14,minecraft:crying_obsidian,20,minecraft:obsidian,100)
RB(-7,19,14,minecraft:crying_obsidian,20,minecraft:obsidian,100)
RB(-7,14,15,minecraft:crying_obsidian,20,minecraft:obsidian,100)
RB(-7,15,15,minecraft:crying_obsidian,20,minecraft:obsidian,100)
RB(-7,16,15,minecraft:crying_obsidian,20,minecraft:obsidian,100)
RB(-7,17,15,minecraft:crying_obsidian,20,minecraft:obsidian,100)
RB(-7,18,15,minecraft:crying_obsidian,20,minecraft:obsidian,100)
RB(-6,14,-12,minecraft:crying_obsidian,20,minecraft:obsidian,100)
RB(-6,15,-12,minecraft:crying_obsidian,20,minecraft:obsidian,100)
RB(-6,16,-12,minecraft:crying_obsidian,20,minecraft:obsidian,100)
RB(-6,12,-11,minecraft:crying_obsidian,20,minecraft:obsidian,100)
RB(-6,13,-11,minecraft:crying_obsidian,20,minecraft:obsidian,100)
RB(-6,14,-11,minecraft:crying_obsidian,20,minecraft:obsidian,100)
RB(-6,15,-11,minecraft:crying_obsidian,20,minecraft:obsidian,100)
RB(-6,16,-11,minecraft:crying_obsidian,20,minecraft:obsidian,100)
RB(-6,17,-11,minecraft:crying_obsidian,20,minecraft:obsidian,100)
RB(-6,18,-11,minecraft:crying_obsidian,20,minecraft:obsidian,100)
RB(-6,19,-11,minecraft:crying_obsidian,20,minecraft:obsidian,100)
RB(-6,11,-10,minecraft:crying_obsidian,20,minecraft:obsidian,100)
RB(-6,12,-10,minecraft:crying_obsidian,20,minecraft:obsidian,100)
RB(-6,13,-10,minecraft:crying_obsidian,20,minecraft:obsidian,100)
RB(-6,14,-10,minecraft:crying_obsidian,20,minecraft:obsidian,100)
RB(-6,15,-10,minecraft:crying_obsidian,20,minecraft:obsidian,100)
RB(-6,16,-10,minecraft:crying_obsidian,20,minecraft:obsidian,100)
RB(-6,17,-10,minecraft:crying_obsidian,20,minecraft:obsidian,100)
RB(-6,18,-10,minecraft:crying_obsidian,20,minecraft:obsidian,100)
RB(-6,19,-10,minecraft:crying_obsidian,20,minecraft:obsidian,100)
RB(-6,20,-10,minecraft:crying_obsidian,20,minecraft:obsidian,100)
RB(-6,21,-10,minecraft:crying_obsidian,20,minecraft:obsidian,100)
RB(-6,11,-9,minecraft:crying_obsidian,20,minecraft:obsidian,100)
RB(-6,12,-9,minecraft:crying_obsidian,20,minecraft:obsidian,100)
RB(-6,13,-9,minecraft:crying_obsidian,20,minecraft:obsidian,100)
RB(-6,14,-9,minecraft:crying_obsidian,20,minecraft:obsidian,100)
RB(-6,15,-9,minecraft:crying_obsidian,20,minecraft:obsidian,100)
RB(-6,16,-9,minecraft:crying_obsidian,20,minecraft:obsidian,100)
RB(-6,17,-9,minecraft:crying_obsidian,20,minecraft:obsidian,100)
RB(-6,18,-9,minecraft:crying_obsidian,20,minecraft:obsidian,100)
RB(-6,19,-9,minecraft:crying_obsidian,20,minecraft:obsidian,100)
RB(-6,20,-9,minecraft:crying_obsidian,20,minecraft:obsidian,100)
RB(-6,21,-9,minecraft:crying_obsidian,20,minecraft:obsidian,100)
RB(-6,10,-8,minecraft:crying_obsidian,20,minecraft:obsidian,100)
RB(-6,11,-8,minecraft:crying_obsidian,20,minecraft:obsidian,100)
RB(-6,12,-8,minecraft:crying_obsidian,20,minecraft:obsidian,100)
RB(-6,13,-8,minecraft:crying_obsidian,20,minecraft:obsidian,100)
RB(-6,14,-8,minecraft:crying_obsidian,20,minecraft:obsidian,100)
RB(-6,15,-8,minecraft:crying_obsidian,20,minecraft:obsidian,100)
RB(-6,16,-8,minecraft:crying_obsidian,20,minecraft:obsidian,100)
RB(-6,17,-8,minecraft:crying_obsidian,20,minecraft:obsidian,100)
RB(-6,18,-8,minecraft:crying_obsidian,20,minecraft:obsidian,100)
RB(-6,19,-8,minecraft:crying_obsidian,20,minecraft:obsidian,100)
RB(-6,20,-8,minecraft:crying_obsidian,20,minecraft:obsidian,100)
RB(-6,21,-8,minecraft:crying_obsidian,20,minecraft:obsidian,100)
RB(-6,22,-8,minecraft:crying_obsidian,20,minecraft:obsidian,100)
RB(-6,10,-7,minecraft:crying_obsidian,20,minecraft:obsidian,100)
RB(-6,11,-7,minecraft:crying_obsidian,20,minecraft:obsidian,100)
RB(-6,12,-7,minecraft:crying_obsidian,20,minecraft:obsidian,100)
RB(-6,13,-7,minecraft:crying_obsidian,20,minecraft:obsidian,100)
RB(-6,14,-7,minecraft:crying_obsidian,20,minecraft:obsidian,100)
RB(-6,15,-7,minecraft:crying_obsidian,20,minecraft:obsidian,100)
RB(-6,16,-7,minecraft:crying_obsidian,20,minecraft:obsidian,100)
RB(-6,17,-7,minecraft:crying_obsidian,20,minecraft:obsidian,100)
RB(-6,18,-7,minecraft:crying_obsidian,20,minecraft:obsidian,100)
RB(-6,19,-7,minecraft:crying_obsidian,20,minecraft:obsidian,100)
RB(-6,20,-7,minecraft:crying_obsidian,20,minecraft:obsidian,100)
RB(-6,21,-7,minecraft:crying_obsidian,20,minecraft:obsidian,100)
RB(-6,22,-7,minecraft:crying_obsidian,20,minecraft:obsidian,100)
RB(-6,10,-6,minecraft:crying_obsidian,20,minecraft:obsidian,100)
RB(-6,11,-6,minecraft:crying_obsidian,20,minecraft:obsidian,100)
RB(-6,12,-6,minecraft:crying_obsidian,20,minecraft:obsidian,100)
RB(-6,13,-6,minecraft:crying_obsidian,20,minecraft:obsidian,100)
RB(-6,14,-6,minecraft:crying_obsidian,20,minecraft:obsidian,100)
RB(-6,15,-6,minecraft:crying_obsidian,20,minecraft:obsidian,100)
RB(-6,16,-6,minecraft:crying_obsidian,20,minecraft:obsidian,100)
RB(-6,17,-6,minecraft:crying_obsidian,20,minecraft:obsidian,100)
RB(-6,18,-6,minecraft:crying_obsidian,20,minecraft:obsidian,100)
RB(-6,19,-6,minecraft:crying_obsidian,20,minecraft:obsidian,100)
RB(-6,20,-6,minecraft:crying_obsidian,20,minecraft:obsidian,100)
RB(-6,21,-6,minecraft:crying_obsidian,20,minecraft:obsidian,100)
RB(-6,22,-6,minecraft:crying_obsidian,20,minecraft:obsidian,100)
RB(-6,11,-5,minecraft:crying_obsidian,20,minecraft:obsidian,100)
RB(-6,12,-5,minecraft:crying_obsidian,20,minecraft:obsidian,100)
RB(-6,13,-5,minecraft:crying_obsidian,20,minecraft:obsidian,100)
RB(-6,14,-5,minecraft:crying_obsidian,20,minecraft:obsidian,100)
RB(-6,15,-5,minecraft:crying_obsidian,20,minecraft:obsidian,100)
RB(-6,16,-5,minecraft:crying_obsidian,20,minecraft:obsidian,100)
RB(-6,17,-5,minecraft:crying_obsidian,20,minecraft:obsidian,100)
RB(-6,18,-5,minecraft:crying_obsidian,20,minecraft:obsidian,100)
RB(-6,19,-5,minecraft:crying_obsidian,20,minecraft:obsidian,100)
RB(-6,20,-5,minecraft:crying_obsidian,20,minecraft:obsidian,100)
RB(-6,21,-5,minecraft:crying_obsidian,20,minecraft:obsidian,100)
RB(-6,11,-4,minecraft:crying_obsidian,20,minecraft:obsidian,100)
RB(-6,12,-4,minecraft:crying_obsidian,20,minecraft:obsidian,100)
RB(-6,13,-4,minecraft:crying_obsidian,20,minecraft:obsidian,100)
RB(-6,14,-4,minecraft:crying_obsidian,20,minecraft:obsidian,100)
RB(-6,15,-4,minecraft:crying_obsidian,20,minecraft:obsidian,100)
RB(-6,16,-4,minecraft:crying_obsidian,20,minecraft:obsidian,100)
RB(-6,17,-4,minecraft:crying_obsidian,20,minecraft:obsidian,100)
RB(-6,18,-4,minecraft:crying_obsidian,20,minecraft:obsidian,100)
RB(-6,19,-4,minecraft:crying_obsidian,20,minecraft:obsidian,100)
RB(-6,20,-4,minecraft:crying_obsidian,20,minecraft:obsidian,100)
RB(-6,12,-3,minecraft:crying_obsidian,20,minecraft:obsidian,100)
RB(-6,13,-3,minecraft:crying_obsidian,20,minecraft:obsidian,100)
RB(-6,14,-3,minecraft:crying_obsidian,20,minecraft:obsidian,100)
RB(-6,15,-3,minecraft:crying_obsidian,20,minecraft:obsidian,100)
RB(-6,16,-3,minecraft:crying_obsidian,20,minecraft:obsidian,100)
RB(-6,17,-3,minecraft:crying_obsidian,20,minecraft:obsidian,100)
RB(-6,18,-3,minecraft:crying_obsidian,20,minecraft:obsidian,100)
RB(-6,19,-3,minecraft:crying_obsidian,20,minecraft:obsidian,100)
RB(-6,12,-2,minecraft:crying_obsidian,20,minecraft:obsidian,100)
RB(-6,13,-2,minecraft:crying_obsidian,20,minecraft:obsidian,100)
RB(-6,14,-2,minecraft:crying_obsidian,20,minecraft:obsidian,100)
RB(-6,15,-2,minecraft:crying_obsidian,20,minecraft:obsidian,100)
RB(-6,16,-2,minecraft:crying_obsidian,20,minecraft:obsidian,100)
RB(-6,17,-2,minecraft:crying_obsidian,20,minecraft:obsidian,100)
RB(-6,18,-2,minecraft:crying_obsidian,20,minecraft:obsidian,100)
RB(-6,19,-2,minecraft:crying_obsidian,20,minecraft:obsidian,100)
RB(-6,11,-1,minecraft:crying_obsidian,20,minecraft:obsidian,100)
RB(-6,12,-1,minecraft:crying_obsidian,20,minecraft:obsidian,100)
RB(-6,13,-1,minecraft:crying_obsidian,20,minecraft:obsidian,100)
RB(-6,14,-1,minecraft:crying_obsidian,20,minecraft:obsidian,100)
RB(-6,15,-1,minecraft:crying_obsidian,20,minecraft:obsidian,100)
RB(-6,16,-1,minecraft:crying_obsidian,20,minecraft:obsidian,100)
RB(-6,17,-1,minecraft:crying_obsidian,20,minecraft:obsidian,100)
RB(-6,18,-1,minecraft:crying_obsidian,20,minecraft:obsidian,100)
RB(-6,19,-1,minecraft:crying_obsidian,20,minecraft:obsidian,100)
RB(-6,20,-1,minecraft:crying_obsidian,20,minecraft:obsidian,100)
RB(-6,11,0,minecraft:crying_obsidian,20,minecraft:obsidian,100)
RB(-6,12,0,minecraft:crying_obsidian,20,minecraft:obsidian,100)
RB(-6,13,0,minecraft:crying_obsidian,20,minecraft:obsidian,100)
RB(-6,14,0,minecraft:crying_obsidian,20,minecraft:obsidian,100)
RB(-6,15,0,minecraft:crying_obsidian,20,minecraft:obsidian,100)
RB(-6,16,0,minecraft:crying_obsidian,20,minecraft:obsidian,100)
RB(-6,17,0,minecraft:crying_obsidian,20,minecraft:obsidian,100)
RB(-6,18,0,minecraft:crying_obsidian,20,minecraft:obsidian,100)
RB(-6,19,0,minecraft:crying_obsidian,20,minecraft:obsidian,100)
RB(-6,20,0,minecraft:crying_obsidian,20,minecraft:obsidian,100)
RB(-6,21,0,minecraft:crying_obsidian,20,minecraft:obsidian,100)
RB(-6,22,0,minecraft:crying_obsidian,20,minecraft:obsidian,100)
RB(-6,11,1,minecraft:crying_obsidian,20,minecraft:obsidian,100)
RB(-6,12,1,minecraft:crying_obsidian,20,minecraft:obsidian,100)
RB(-6,13,1,minecraft:crying_obsidian,20,minecraft:obsidian,100)
RB(-6,14,1,minecraft:crying_obsidian,20,minecraft:obsidian,100)
RB(-6,15,1,minecraft:crying_obsidian,20,minecraft:obsidian,100)
RB(-6,16,1,minecraft:crying_obsidian,20,minecraft:obsidian,100)
RB(-6,17,1,minecraft:crying_obsidian,20,minecraft:obsidian,100)
RB(-6,18,1,minecraft:crying_obsidian,20,minecraft:obsidian,100)
RB(-6,19,1,minecraft:crying_obsidian,20,minecraft:obsidian,100)
RB(-6,20,1,minecraft:crying_obsidian,20,minecraft:obsidian,100)
RB(-6,21,1,minecraft:crying_obsidian,20,minecraft:obsidian,100)
RB(-6,22,1,minecraft:crying_obsidian,20,minecraft:obsidian,100)
RB(-6,10,2,minecraft:crying_obsidian,20,minecraft:obsidian,100)
RB(-6,11,2,minecraft:crying_obsidian,20,minecraft:obsidian,100)
RB(-6,12,2,minecraft:crying_obsidian,20,minecraft:obsidian,100)
RB(-6,13,2,minecraft:crying_obsidian,20,minecraft:obsidian,100)
RB(-6,14,2,minecraft:crying_obsidian,20,minecraft:obsidian,100)
RB(-6,15,2,minecraft:crying_obsidian,20,minecraft:obsidian,100)
RB(-6,16,2,minecraft:crying_obsidian,20,minecraft:obsidian,100)
RB(-6,17,2,minecraft:crying_obsidian,20,minecraft:obsidian,100)
RB(-6,18,2,minecraft:crying_obsidian,20,minecraft:obsidian,100)
RB(-6,19,2,minecraft:crying_obsidian,20,minecraft:obsidian,100)
RB(-6,20,2,minecraft:crying_obsidian,20,minecraft:obsidian,100)
RB(-6,21,2,minecraft:crying_obsidian,20,minecraft:obsidian,100)
RB(-6,22,2,minecraft:crying_obsidian,20,minecraft:obsidian,100)
RB(-6,11,3,minecraft:crying_obsidian,20,minecraft:obsidian,100)
RB(-6,12,3,minecraft:crying_obsidian,20,minecraft:obsidian,100)
RB(-6,13,3,minecraft:crying_obsidian,20,minecraft:obsidian,100)
RB(-6,14,3,minecraft:crying_obsidian,20,minecraft:obsidian,100)
RB(-6,15,3,minecraft:crying_obsidian,20,minecraft:obsidian,100)
RB(-6,16,3,minecraft:crying_obsidian,20,minecraft:obsidian,100)
RB(-6,17,3,minecraft:crying_obsidian,20,minecraft:obsidian,100)
RB(-6,18,3,minecraft:crying_obsidian,20,minecraft:obsidian,100)
RB(-6,19,3,minecraft:crying_obsidian,20,minecraft:obsidian,100)
RB(-6,20,3,minecraft:crying_obsidian,20,minecraft:obsidian,100)
RB(-6,21,3,minecraft:crying_obsidian,20,minecraft:obsidian,100)
RB(-6,22,3,minecraft:crying_obsidian,20,minecraft:obsidian,100)
RB(-6,23,3,minecraft:crying_obsidian,20,minecraft:obsidian,100)
RB(-6,11,4,minecraft:crying_obsidian,20,minecraft:obsidian,100)
RB(-6,12,4,minecraft:crying_obsidian,20,minecraft:obsidian,100)
RB(-6,13,4,minecraft:crying_obsidian,20,minecraft:obsidian,100)
RB(-6,14,4,minecraft:crying_obsidian,20,minecraft:obsidian,100)
RB(-6,15,4,minecraft:crying_obsidian,20,minecraft:obsidian,100)
RB(-6,16,4,minecraft:crying_obsidian,20,minecraft:obsidian,100)
RB(-6,17,4,minecraft:crying_obsidian,20,minecraft:obsidian,100)
RB(-6,18,4,minecraft:crying_obsidian,20,minecraft:obsidian,100)
RB(-6,19,4,minecraft:crying_obsidian,20,minecraft:obsidian,100)
RB(-6,20,4,minecraft:crying_obsidian,20,minecraft:obsidian,100)
RB(-6,21,4,minecraft:crying_obsidian,20,minecraft:obsidian,100)
RB(-6,22,4,minecraft:crying_obsidian,20,minecraft:obsidian,100)
RB(-6,23,4,minecraft:crying_obsidian,20,minecraft:obsidian,100)
RB(-6,12,5,minecraft:crying_obsidian,20,minecraft:obsidian,100)
RB(-6,13,5,minecraft:crying_obsidian,20,minecraft:obsidian,100)
RB(-6,14,5,minecraft:crying_obsidian,20,minecraft:obsidian,100)
RB(-6,15,5,minecraft:crying_obsidian,20,minecraft:obsidian,100)
RB(-6,16,5,minecraft:crying_obsidian,20,minecraft:obsidian,100)
RB(-6,17,5,minecraft:crying_obsidian,20,minecraft:obsidian,100)
RB(-6,18,5,minecraft:crying_obsidian,20,minecraft:obsidian,100)
RB(-6,19,5,minecraft:crying_obsidian,20,minecraft:obsidian,100)
RB(-6,20,5,minecraft:crying_obsidian,20,minecraft:obsidian,100)
RB(-6,21,5,minecraft:crying_obsidian,20,minecraft:obsidian,100)
RB(-6,22,5,minecraft:crying_obsidian,20,minecraft:obsidian,100)
RB(-6,23,5,minecraft:crying_obsidian,20,minecraft:obsidian,100)
RB(-6,12,6,minecraft:crying_obsidian,20,minecraft:obsidian,100)
RB(-6,13,6,minecraft:crying_obsidian,20,minecraft:obsidian,100)
RB(-6,14,6,minecraft:crying_obsidian,20,minecraft:obsidian,100)
RB(-6,15,6,minecraft:crying_obsidian,20,minecraft:obsidian,100)
RB(-6,16,6,minecraft:crying_obsidian,20,minecraft:obsidian,100)
RB(-6,17,6,minecraft:crying_obsidian,20,minecraft:obsidian,100)
RB(-6,18,6,minecraft:crying_obsidian,20,minecraft:obsidian,100)
RB(-6,19,6,minecraft:crying_obsidian,20,minecraft:obsidian,100)
RB(-6,20,6,minecraft:crying_obsidian,20,minecraft:obsidian,100)
RB(-6,21,6,minecraft:crying_obsidian,20,minecraft:obsidian,100)
RB(-6,22,6,minecraft:crying_obsidian,20,minecraft:obsidian,100)
RB(-6,23,6,minecraft:crying_obsidian,20,minecraft:obsidian,100)
RB(-6,12,7,minecraft:crying_obsidian,20,minecraft:obsidian,100)
RB(-6,13,7,minecraft:crying_obsidian,20,minecraft:obsidian,100)
RB(-6,14,7,minecraft:crying_obsidian,20,minecraft:obsidian,100)
RB(-6,15,7,minecraft:crying_obsidian,20,minecraft:obsidian,100)
RB(-6,16,7,minecraft:crying_obsidian,20,minecraft:obsidian,100)
RB(-6,17,7,minecraft:crying_obsidian,20,minecraft:obsidian,100)
RB(-6,18,7,minecraft:crying_obsidian,20,minecraft:obsidian,100)
RB(-6,19,7,minecraft:crying_obsidian,20,minecraft:obsidian,100)
RB(-6,20,7,minecraft:crying_obsidian,20,minecraft:obsidian,100)
RB(-6,21,7,minecraft:crying_obsidian,20,minecraft:obsidian,100)
RB(-6,22,7,minecraft:crying_obsidian,20,minecraft:obsidian,100)
RB(-6,12,8,minecraft:crying_obsidian,20,minecraft:obsidian,100)
RB(-6,13,8,minecraft:crying_obsidian,20,minecraft:obsidian,100)
RB(-6,14,8,minecraft:crying_obsidian,20,minecraft:obsidian,100)
RB(-6,15,8,minecraft:crying_obsidian,20,minecraft:obsidian,100)
RB(-6,16,8,minecraft:crying_obsidian,20,minecraft:obsidian,100)
RB(-6,17,8,minecraft:crying_obsidian,20,minecraft:obsidian,100)
RB(-6,18,8,minecraft:crying_obsidian,20,minecraft:obsidian,100)
RB(-6,19,8,minecraft:crying_obsidian,20,minecraft:obsidian,100)
RB(-6,20,8,minecraft:crying_obsidian,20,minecraft:obsidian,100)
RB(-6,21,8,minecraft:crying_obsidian,20,minecraft:obsidian,100)
RB(-6,11,9,minecraft:crying_obsidian,20,minecraft:obsidian,100)
RB(-6,12,9,minecraft:crying_obsidian,20,minecraft:obsidian,100)
RB(-6,13,9,minecraft:crying_obsidian,20,minecraft:obsidian,100)
RB(-6,14,9,minecraft:crying_obsidian,20,minecraft:obsidian,100)
RB(-6,15,9,minecraft:crying_obsidian,20,minecraft:obsidian,100)
RB(-6,16,9,minecraft:crying_obsidian,20,minecraft:obsidian,100)
RB(-6,17,9,minecraft:crying_obsidian,20,minecraft:obsidian,100)
RB(-6,18,9,minecraft:crying_obsidian,20,minecraft:obsidian,100)
RB(-6,19,9,minecraft:crying_obsidian,20,minecraft:obsidian,100)
RB(-6,20,9,minecraft:crying_obsidian,20,minecraft:obsidian,100)
RB(-6,21,9,minecraft:crying_obsidian,20,minecraft:obsidian,100)
RB(-6,11,10,minecraft:crying_obsidian,20,minecraft:obsidian,100)
RB(-6,12,10,minecraft:crying_obsidian,20,minecraft:obsidian,100)
RB(-6,13,10,minecraft:crying_obsidian,20,minecraft:obsidian,100)
RB(-6,14,10,minecraft:crying_obsidian,20,minecraft:obsidian,100)
RB(-6,15,10,minecraft:crying_obsidian,20,minecraft:obsidian,100)
RB(-6,16,10,minecraft:crying_obsidian,20,minecraft:obsidian,100)
RB(-6,17,10,minecraft:crying_obsidian,20,minecraft:obsidian,100)
RB(-6,18,10,minecraft:crying_obsidian,20,minecraft:obsidian,100)
RB(-6,19,10,minecraft:crying_obsidian,20,minecraft:obsidian,100)
RB(-6,20,10,minecraft:crying_obsidian,20,minecraft:obsidian,100)
RB(-6,21,10,minecraft:crying_obsidian,20,minecraft:obsidian,100)
RB(-6,11,11,minecraft:crying_obsidian,20,minecraft:obsidian,100)
RB(-6,12,11,minecraft:crying_obsidian,20,minecraft:obsidian,100)
RB(-6,13,11,minecraft:crying_obsidian,20,minecraft:obsidian,100)
RB(-6,14,11,minecraft:crying_obsidian,20,minecraft:obsidian,100)
RB(-6,15,11,minecraft:crying_obsidian,20,minecraft:obsidian,100)
RB(-6,16,11,minecraft:crying_obsidian,20,minecraft:obsidian,100)
RB(-6,17,11,minecraft:crying_obsidian,20,minecraft:obsidian,100)
RB(-6,18,11,minecraft:crying_obsidian,20,minecraft:obsidian,100)
RB(-6,19,11,minecraft:crying_obsidian,20,minecraft:obsidian,100)
RB(-6,20,11,minecraft:crying_obsidian,20,minecraft:obsidian,100)
RB(-6,21,11,minecraft:crying_obsidian,20,minecraft:obsidian,100)
RB(-6,12,12,minecraft:crying_obsidian,20,minecraft:obsidian,100)
RB(-6,13,12,minecraft:crying_obsidian,20,minecraft:obsidian,100)
RB(-6,14,12,minecraft:crying_obsidian,20,minecraft:obsidian,100)
RB(-6,15,12,minecraft:crying_obsidian,20,minecraft:obsidian,100)
RB(-6,16,12,minecraft:crying_obsidian,20,minecraft:obsidian,100)
RB(-6,17,12,minecraft:crying_obsidian,20,minecraft:obsidian,100)
RB(-6,18,12,minecraft:crying_obsidian,20,minecraft:obsidian,100)
RB(-6,19,12,minecraft:crying_obsidian,20,minecraft:obsidian,100)
RB(-6,20,12,minecraft:crying_obsidian,20,minecraft:obsidian,100)
RB(-6,12,13,minecraft:crying_obsidian,20,minecraft:obsidian,100)
RB(-6,13,13,minecraft:crying_obsidian,20,minecraft:obsidian,100)
RB(-6,14,13,minecraft:crying_obsidian,20,minecraft:obsidian,100)
RB(-6,15,13,minecraft:crying_obsidian,20,minecraft:obsidian,100)
RB(-6,16,13,minecraft:crying_obsidian,20,minecraft:obsidian,100)
RB(-6,17,13,minecraft:crying_obsidian,20,minecraft:obsidian,100)
RB(-6,18,13,minecraft:crying_obsidian,20,minecraft:obsidian,100)
RB(-6,19,13,minecraft:crying_obsidian,20,minecraft:obsidian,100)
RB(-6,20,13,minecraft:crying_obsidian,20,minecraft:obsidian,100)
RB(-6,13,14,minecraft:crying_obsidian,20,minecraft:obsidian,100)
RB(-6,14,14,minecraft:crying_obsidian,20,minecraft:obsidian,100)
RB(-6,15,14,minecraft:crying_obsidian,20,minecraft:obsidian,100)
RB(-6,16,14,minecraft:crying_obsidian,20,minecraft:obsidian,100)
RB(-6,17,14,minecraft:crying_obsidian,20,minecraft:obsidian,100)
RB(-6,18,14,minecraft:crying_obsidian,20,minecraft:obsidian,100)
RB(-6,19,14,minecraft:crying_obsidian,20,minecraft:obsidian,100)
RB(-6,15,15,minecraft:crying_obsidian,20,minecraft:obsidian,100)
RB(-6,16,15,minecraft:crying_obsidian,20,minecraft:obsidian,100)
RB(-6,17,15,minecraft:crying_obsidian,20,minecraft:obsidian,100)
RB(-5,13,-12,minecraft:crying_obsidian,20,minecraft:obsidian,100)
RB(-5,14,-12,minecraft:crying_obsidian,20,minecraft:obsidian,100)
RB(-5,15,-12,minecraft:crying_obsidian,20,minecraft:obsidian,100)
RB(-5,16,-12,minecraft:crying_obsidian,20,minecraft:obsidian,100)
RB(-5,17,-12,minecraft:crying_obsidian,20,minecraft:obsidian,100)
RB(-5,12,-11,minecraft:crying_obsidian,20,minecraft:obsidian,100)
RB(-5,13,-11,minecraft:crying_obsidian,20,minecraft:obsidian,100)
RB(-5,14,-11,minecraft:crying_obsidian,20,minecraft:obsidian,100)
RB(-5,15,-11,minecraft:crying_obsidian,20,minecraft:obsidian,100)
RB(-5,16,-11,minecraft:crying_obsidian,20,minecraft:obsidian,100)
RB(-5,17,-11,minecraft:crying_obsidian,20,minecraft:obsidian,100)
RB(-5,18,-11,minecraft:crying_obsidian,20,minecraft:obsidian,100)
RB(-5,11,-10,minecraft:crying_obsidian,20,minecraft:obsidian,100)
RB(-5,12,-10,minecraft:crying_obsidian,20,minecraft:obsidian,100)
RB(-5,13,-10,minecraft:crying_obsidian,20,minecraft:obsidian,100)
RB(-5,14,-10,minecraft:crying_obsidian,20,minecraft:obsidian,100)
RB(-5,15,-10,minecraft:crying_obsidian,20,minecraft:obsidian,100)
RB(-5,16,-10,minecraft:crying_obsidian,20,minecraft:obsidian,100)
RB(-5,17,-10,minecraft:crying_obsidian,20,minecraft:obsidian,100)
RB(-5,18,-10,minecraft:crying_obsidian,20,minecraft:obsidian,100)
RB(-5,19,-10,minecraft:crying_obsidian,20,minecraft:obsidian,100)
RB(-5,20,-10,minecraft:crying_obsidian,20,minecraft:obsidian,100)
RB(-5,21,-10,minecraft:crying_obsidian,20,minecraft:obsidian,100)
RB(-5,10,-9,minecraft:crying_obsidian,20,minecraft:obsidian,100)
RB(-5,11,-9,minecraft:crying_obsidian,20,minecraft:obsidian,100)
RB(-5,12,-9,minecraft:crying_obsidian,20,minecraft:obsidian,100)
RB(-5,13,-9,minecraft:crying_obsidian,20,minecraft:obsidian,100)
RB(-5,14,-9,minecraft:crying_obsidian,20,minecraft:obsidian,100)
RB(-5,15,-9,minecraft:crying_obsidian,20,minecraft:obsidian,100)
RB(-5,16,-9,minecraft:crying_obsidian,20,minecraft:obsidian,100)
RB(-5,17,-9,minecraft:crying_obsidian,20,minecraft:obsidian,100)
RB(-5,18,-9,minecraft:crying_obsidian,20,minecraft:obsidian,100)
RB(-5,19,-9,minecraft:crying_obsidian,20,minecraft:obsidian,100)
RB(-5,20,-9,minecraft:crying_obsidian,20,minecraft:obsidian,100)
RB(-5,21,-9,minecraft:crying_obsidian,20,minecraft:obsidian,100)
RB(-5,22,-9,minecraft:crying_obsidian,20,minecraft:obsidian,100)
RB(-5,10,-8,minecraft:crying_obsidian,20,minecraft:obsidian,100)
RB(-5,11,-8,minecraft:crying_obsidian,20,minecraft:obsidian,100)
RB(-5,12,-8,minecraft:crying_obsidian,20,minecraft:obsidian,100)
RB(-5,13,-8,minecraft:crying_obsidian,20,minecraft:obsidian,100)
RB(-5,14,-8,minecraft:crying_obsidian,20,minecraft:obsidian,100)
RB(-5,15,-8,minecraft:crying_obsidian,20,minecraft:obsidian,100)
RB(-5,16,-8,minecraft:crying_obsidian,20,minecraft:obsidian,100)
RB(-5,17,-8,minecraft:crying_obsidian,20,minecraft:obsidian,100)
RB(-5,18,-8,minecraft:crying_obsidian,20,minecraft:obsidian,100)
RB(-5,19,-8,minecraft:crying_obsidian,20,minecraft:obsidian,100)
RB(-5,20,-8,minecraft:crying_obsidian,20,minecraft:obsidian,100)
RB(-5,21,-8,minecraft:crying_obsidian,20,minecraft:obsidian,100)
RB(-5,22,-8,minecraft:crying_obsidian,20,minecraft:obsidian,100)
RB(-5,10,-7,minecraft:crying_obsidian,20,minecraft:obsidian,100)
RB(-5,11,-7,minecraft:crying_obsidian,20,minecraft:obsidian,100)
RB(-5,12,-7,minecraft:crying_obsidian,20,minecraft:obsidian,100)
RB(-5,13,-7,minecraft:crying_obsidian,20,minecraft:obsidian,100)
RB(-5,14,-7,minecraft:crying_obsidian,20,minecraft:obsidian,100)
RB(-5,15,-7,minecraft:crying_obsidian,20,minecraft:obsidian,100)
RB(-5,16,-7,minecraft:crying_obsidian,20,minecraft:obsidian,100)
RB(-5,17,-7,minecraft:crying_obsidian,20,minecraft:obsidian,100)
RB(-5,18,-7,minecraft:crying_obsidian,20,minecraft:obsidian,100)
RB(-5,19,-7,minecraft:crying_obsidian,20,minecraft:obsidian,100)
RB(-5,20,-7,minecraft:crying_obsidian,20,minecraft:obsidian,100)
RB(-5,21,-7,minecraft:crying_obsidian,20,minecraft:obsidian,100)
RB(-5,22,-7,minecraft:crying_obsidian,20,minecraft:obsidian,100)
RB(-5,10,-6,minecraft:crying_obsidian,20,minecraft:obsidian,100)
RB(-5,11,-6,minecraft:crying_obsidian,20,minecraft:obsidian,100)
RB(-5,12,-6,minecraft:crying_obsidian,20,minecraft:obsidian,100)
RB(-5,13,-6,minecraft:crying_obsidian,20,minecraft:obsidian,100)
RB(-5,14,-6,minecraft:crying_obsidian,20,minecraft:obsidian,100)
RB(-5,15,-6,minecraft:crying_obsidian,20,minecraft:obsidian,100)
RB(-5,16,-6,minecraft:crying_obsidian,20,minecraft:obsidian,100)
RB(-5,17,-6,minecraft:crying_obsidian,20,minecraft:obsidian,100)
RB(-5,18,-6,minecraft:crying_obsidian,20,minecraft:obsidian,100)
RB(-5,19,-6,minecraft:crying_obsidian,20,minecraft:obsidian,100)
RB(-5,20,-6,minecraft:crying_obsidian,20,minecraft:obsidian,100)
RB(-5,21,-6,minecraft:crying_obsidian,20,minecraft:obsidian,100)
RB(-5,22,-6,minecraft:crying_obsidian,20,minecraft:obsidian,100)
RB(-5,10,-5,minecraft:crying_obsidian,20,minecraft:obsidian,100)
RB(-5,11,-5,minecraft:crying_obsidian,20,minecraft:obsidian,100)
RB(-5,12,-5,minecraft:crying_obsidian,20,minecraft:obsidian,100)
RB(-5,13,-5,minecraft:crying_obsidian,20,minecraft:obsidian,100)
RB(-5,14,-5,minecraft:crying_obsidian,20,minecraft:obsidian,100)
RB(-5,15,-5,minecraft:crying_obsidian,20,minecraft:obsidian,100)
RB(-5,16,-5,minecraft:crying_obsidian,20,minecraft:obsidian,100)
RB(-5,17,-5,minecraft:crying_obsidian,20,minecraft:obsidian,100)
RB(-5,18,-5,minecraft:crying_obsidian,20,minecraft:obsidian,100)
RB(-5,19,-5,minecraft:crying_obsidian,20,minecraft:obsidian,100)
RB(-5,20,-5,minecraft:crying_obsidian,20,minecraft:obsidian,100)
RB(-5,21,-5,minecraft:crying_obsidian,20,minecraft:obsidian,100)
RB(-5,11,-4,minecraft:crying_obsidian,20,minecraft:obsidian,100)
RB(-5,12,-4,minecraft:crying_obsidian,20,minecraft:obsidian,100)
RB(-5,13,-4,minecraft:crying_obsidian,20,minecraft:obsidian,100)
RB(-5,14,-4,minecraft:crying_obsidian,20,minecraft:obsidian,100)
RB(-5,15,-4,minecraft:crying_obsidian,20,minecraft:obsidian,100)
RB(-5,16,-4,minecraft:crying_obsidian,20,minecraft:obsidian,100)
RB(-5,17,-4,minecraft:crying_obsidian,20,minecraft:obsidian,100)
RB(-5,18,-4,minecraft:crying_obsidian,20,minecraft:obsidian,100)
RB(-5,19,-4,minecraft:crying_obsidian,20,minecraft:obsidian,100)
RB(-5,20,-4,minecraft:crying_obsidian,20,minecraft:obsidian,100)
RB(-5,12,-3,minecraft:crying_obsidian,20,minecraft:obsidian,100)
RB(-5,13,-3,minecraft:crying_obsidian,20,minecraft:obsidian,100)
RB(-5,14,-3,minecraft:crying_obsidian,20,minecraft:obsidian,100)
RB(-5,15,-3,minecraft:crying_obsidian,20,minecraft:obsidian,100)
RB(-5,16,-3,minecraft:crying_obsidian,20,minecraft:obsidian,100)
RB(-5,17,-3,minecraft:crying_obsidian,20,minecraft:obsidian,100)
RB(-5,18,-3,minecraft:crying_obsidian,20,minecraft:obsidian,100)
RB(-5,19,-3,minecraft:crying_obsidian,20,minecraft:obsidian,100)
RB(-5,12,-2,minecraft:crying_obsidian,20,minecraft:obsidian,100)
RB(-5,13,-2,minecraft:crying_obsidian,20,minecraft:obsidian,100)
RB(-5,14,-2,minecraft:crying_obsidian,20,minecraft:obsidian,100)
RB(-5,15,-2,minecraft:crying_obsidian,20,minecraft:obsidian,100)
RB(-5,16,-2,minecraft:crying_obsidian,20,minecraft:obsidian,100)
RB(-5,17,-2,minecraft:crying_obsidian,20,minecraft:obsidian,100)
RB(-5,18,-2,minecraft:crying_obsidian,20,minecraft:obsidian,100)
RB(-5,19,-2,minecraft:crying_obsidian,20,minecraft:obsidian,100)
RB(-5,11,-1,minecraft:crying_obsidian,20,minecraft:obsidian,100)
RB(-5,12,-1,minecraft:crying_obsidian,20,minecraft:obsidian,100)
RB(-5,13,-1,minecraft:crying_obsidian,20,minecraft:obsidian,100)
RB(-5,14,-1,minecraft:crying_obsidian,20,minecraft:obsidian,100)
RB(-5,15,-1,minecraft:crying_obsidian,20,minecraft:obsidian,100)
RB(-5,16,-1,minecraft:crying_obsidian,20,minecraft:obsidian,100)
RB(-5,17,-1,minecraft:crying_obsidian,20,minecraft:obsidian,100)
RB(-5,18,-1,minecraft:crying_obsidian,20,minecraft:obsidian,100)
RB(-5,19,-1,minecraft:crying_obsidian,20,minecraft:obsidian,100)
RB(-5,20,-1,minecraft:crying_obsidian,20,minecraft:obsidian,100)
RB(-5,10,0,minecraft:crying_obsidian,20,minecraft:obsidian,100)
RB(-5,11,0,minecraft:crying_obsidian,20,minecraft:obsidian,100)
RB(-5,12,0,minecraft:crying_obsidian,20,minecraft:obsidian,100)
RB(-5,13,0,minecraft:crying_obsidian,20,minecraft:obsidian,100)
RB(-5,14,0,minecraft:crying_obsidian,20,minecraft:obsidian,100)
RB(-5,15,0,minecraft:crying_obsidian,20,minecraft:obsidian,100)
RB(-5,16,0,minecraft:crying_obsidian,20,minecraft:obsidian,100)
RB(-5,17,0,minecraft:crying_obsidian,20,minecraft:obsidian,100)
RB(-5,18,0,minecraft:crying_obsidian,20,minecraft:obsidian,100)
RB(-5,19,0,minecraft:crying_obsidian,20,minecraft:obsidian,100)
RB(-5,20,0,minecraft:crying_obsidian,20,minecraft:obsidian,100)
RB(-5,21,0,minecraft:crying_obsidian,20,minecraft:obsidian,100)
RB(-5,22,0,minecraft:crying_obsidian,20,minecraft:obsidian,100)
RB(-5,10,1,minecraft:crying_obsidian,20,minecraft:obsidian,100)
RB(-5,11,1,minecraft:crying_obsidian,20,minecraft:obsidian,100)
RB(-5,12,1,minecraft:crying_obsidian,20,minecraft:obsidian,100)
RB(-5,13,1,minecraft:crying_obsidian,20,minecraft:obsidian,100)
RB(-5,14,1,minecraft:crying_obsidian,20,minecraft:obsidian,100)
RB(-5,15,1,minecraft:crying_obsidian,20,minecraft:obsidian,100)
RB(-5,16,1,minecraft:crying_obsidian,20,minecraft:obsidian,100)
RB(-5,17,1,minecraft:crying_obsidian,20,minecraft:obsidian,100)
RB(-5,18,1,minecraft:crying_obsidian,20,minecraft:obsidian,100)
RB(-5,19,1,minecraft:crying_obsidian,20,minecraft:obsidian,100)
RB(-5,20,1,minecraft:crying_obsidian,20,minecraft:obsidian,100)
RB(-5,21,1,minecraft:crying_obsidian,20,minecraft:obsidian,100)
RB(-5,22,1,minecraft:crying_obsidian,20,minecraft:obsidian,100)
RB(-5,8,2,minecraft:crying_obsidian,20,minecraft:obsidian,100)
RB(-5,9,2,minecraft:crying_obsidian,20,minecraft:obsidian,100)
RB(-5,10,2,minecraft:crying_obsidian,20,minecraft:obsidian,100)
RB(-5,11,2,minecraft:crying_obsidian,20,minecraft:obsidian,100)
RB(-5,12,2,minecraft:crying_obsidian,20,minecraft:obsidian,100)
RB(-5,13,2,minecraft:crying_obsidian,20,minecraft:obsidian,100)
RB(-5,14,2,minecraft:crying_obsidian,20,minecraft:obsidian,100)
RB(-5,15,2,minecraft:crying_obsidian,20,minecraft:obsidian,100)
RB(-5,16,2,minecraft:crying_obsidian,20,minecraft:obsidian,100)
RB(-5,17,2,minecraft:crying_obsidian,20,minecraft:obsidian,100)
RB(-5,18,2,minecraft:crying_obsidian,20,minecraft:obsidian,100)
RB(-5,19,2,minecraft:crying_obsidian,20,minecraft:obsidian,100)
RB(-5,20,2,minecraft:crying_obsidian,20,minecraft:obsidian,100)
RB(-5,21,2,minecraft:crying_obsidian,20,minecraft:obsidian,100)
RB(-5,22,2,minecraft:crying_obsidian,20,minecraft:obsidian,100)
RB(-5,23,2,minecraft:crying_obsidian,20,minecraft:obsidian,100)
RB(-5,8,3,minecraft:crying_obsidian,20,minecraft:obsidian,100)
RB(-5,9,3,minecraft:crying_obsidian,20,minecraft:obsidian,100)
RB(-5,10,3,minecraft:crying_obsidian,20,minecraft:obsidian,100)
RB(-5,11,3,minecraft:crying_obsidian,20,minecraft:obsidian,100)
RB(-5,12,3,minecraft:crying_obsidian,20,minecraft:obsidian,100)
RB(-5,13,3,minecraft:crying_obsidian,20,minecraft:obsidian,100)
RB(-5,14,3,minecraft:crying_obsidian,20,minecraft:obsidian,100)
RB(-5,15,3,minecraft:crying_obsidian,20,minecraft:obsidian,100)
RB(-5,16,3,minecraft:crying_obsidian,20,minecraft:obsidian,100)
RB(-5,17,3,minecraft:crying_obsidian,20,minecraft:obsidian,100)
RB(-5,18,3,minecraft:crying_obsidian,20,minecraft:obsidian,100)
RB(-5,19,3,minecraft:crying_obsidian,20,minecraft:obsidian,100)
RB(-5,20,3,minecraft:crying_obsidian,20,minecraft:obsidian,100)
RB(-5,21,3,minecraft:crying_obsidian,20,minecraft:obsidian,100)
RB(-5,22,3,minecraft:crying_obsidian,20,minecraft:obsidian,100)
RB(-5,23,3,minecraft:crying_obsidian,20,minecraft:obsidian,100)
RB(-5,10,4,minecraft:crying_obsidian,20,minecraft:obsidian,100)
RB(-5,11,4,minecraft:crying_obsidian,20,minecraft:obsidian,100)
RB(-5,12,4,minecraft:crying_obsidian,20,minecraft:obsidian,100)
RB(-5,13,4,minecraft:crying_obsidian,20,minecraft:obsidian,100)
RB(-5,14,4,minecraft:crying_obsidian,20,minecraft:obsidian,100)
RB(-5,15,4,minecraft:crying_obsidian,20,minecraft:obsidian,100)
RB(-5,16,4,minecraft:crying_obsidian,20,minecraft:obsidian,100)
RB(-5,17,4,minecraft:crying_obsidian,20,minecraft:obsidian,100)
RB(-5,18,4,minecraft:crying_obsidian,20,minecraft:obsidian,100)
RB(-5,19,4,minecraft:crying_obsidian,20,minecraft:obsidian,100)
RB(-5,20,4,minecraft:crying_obsidian,20,minecraft:obsidian,100)
RB(-5,21,4,minecraft:crying_obsidian,20,minecraft:obsidian,100)
RB(-5,22,4,minecraft:crying_obsidian,20,minecraft:obsidian,100)
RB(-5,23,4,minecraft:crying_obsidian,20,minecraft:obsidian,100)
RB(-5,11,5,minecraft:crying_obsidian,20,minecraft:obsidian,100)
RB(-5,12,5,minecraft:crying_obsidian,20,minecraft:obsidian,100)
RB(-5,13,5,minecraft:crying_obsidian,20,minecraft:obsidian,100)
RB(-5,14,5,minecraft:crying_obsidian,20,minecraft:obsidian,100)
RB(-5,15,5,minecraft:crying_obsidian,20,minecraft:obsidian,100)
RB(-5,16,5,minecraft:crying_obsidian,20,minecraft:obsidian,100)
RB(-5,17,5,minecraft:crying_obsidian,20,minecraft:obsidian,100)
RB(-5,18,5,minecraft:crying_obsidian,20,minecraft:obsidian,100)
RB(-5,19,5,minecraft:crying_obsidian,20,minecraft:obsidian,100)
RB(-5,20,5,minecraft:crying_obsidian,20,minecraft:obsidian,100)
RB(-5,21,5,minecraft:crying_obsidian,20,minecraft:obsidian,100)
RB(-5,22,5,minecraft:crying_obsidian,20,minecraft:obsidian,100)
RB(-5,23,5,minecraft:crying_obsidian,20,minecraft:obsidian,100)
RB(-5,11,6,minecraft:crying_obsidian,20,minecraft:obsidian,100)
RB(-5,12,6,minecraft:crying_obsidian,20,minecraft:obsidian,100)
RB(-5,13,6,minecraft:crying_obsidian,20,minecraft:obsidian,100)
RB(-5,14,6,minecraft:crying_obsidian,20,minecraft:obsidian,100)
RB(-5,15,6,minecraft:crying_obsidian,20,minecraft:obsidian,100)
RB(-5,16,6,minecraft:crying_obsidian,20,minecraft:obsidian,100)
RB(-5,17,6,minecraft:crying_obsidian,20,minecraft:obsidian,100)
RB(-5,18,6,minecraft:crying_obsidian,20,minecraft:obsidian,100)
