# ------------------------------------------------------------------- #
# "THE I WOULD LICENSE THIS UNDER BEER-WARE BUT I DON'T DRINK SO I'LL HAVE A DOUGHNUT INSTEAD LICENSE"
# <frank@infotoast.org> wrote this file.  As long as you retain this notice you
# can do whatever you want with this stuff. If we meet some day, and you think
# this stuff is worth it, you can buy me a doughnut in return.
# ------------------------------------------------------------------- #

#######################################################################
# +-----------------------------------------------------------------+ #
# |                            BO3 object                           | #
# +-----------------------------------------------------------------+ #
#######################################################################

Author: Frank

Description: Medium glowstone spike

Version: 3

SettingsMode: WriteDisable


#######################################################################
# +-----------------------------------------------------------------+ #
# |                          Main settings                          | #
# +-----------------------------------------------------------------+ #
#######################################################################

Tree: true

Frequency: 10

Rarity: 100.0

MaxSpawn: 1

RotateRandomly: true

SpawnHeight: randomY

SpawnHeightOffset: 0

SpawnHeightVariance: 0

##############################
# Height Limits for the BO3. #
##############################

MinHeight: 50

MaxHeight: 65

######################
# Extrusion settings #
######################

ExtrudeMode: None

ExtrudeThroughBlocks: minecraft:air

MaxBranchDepth: 10


#######################################################################
# +-----------------------------------------------------------------+ #
# |                      Source block settings                      | #
# +-----------------------------------------------------------------+ #
#######################################################################

SourceBlocks: minecraft:air

MaxPercentageOutsideSourceBlock: 60

OutsideSourceBlock: placeAnyway

DoReplaceBlocks: true

IsOTGPlus: false


#######################################################################
# +-----------------------------------------------------------------+ #
# |                              Blocks                             | #
# +-----------------------------------------------------------------+ #
#######################################################################

B(-14,19,-14,minecraft:glowstone)
B(-13,16,-13,minecraft:glowstone)
B(-13,17,-13,minecraft:glowstone)
B(-13,18,-13,minecraft:glowstone)
B(-13,15,-12,minecraft:glowstone)
B(-13,16,-12,minecraft:glowstone)
B(-13,17,-12,minecraft:glowstone)
B(-13,15,-11,minecraft:glowstone)
B(-13,16,-11,minecraft:glowstone)
B(-13,15,-10,minecraft:glowstone)
B(-12,17,-13,minecraft:glowstone)
B(-12,13,-12,minecraft:glowstone)
B(-12,14,-12,minecraft:glowstone)
B(-12,15,-12,minecraft:glowstone)
B(-12,16,-12,minecraft:glowstone)
B(-12,17,-12,minecraft:glowstone)
B(-12,12,-11,minecraft:glowstone)
B(-12,13,-11,minecraft:glowstone)
B(-12,14,-11,minecraft:glowstone)
B(-12,15,-11,minecraft:glowstone)
B(-12,16,-11,minecraft:glowstone)
B(-12,11,-10,minecraft:glowstone)
B(-12,12,-10,minecraft:glowstone)
B(-12,13,-10,minecraft:glowstone)
B(-12,14,-10,minecraft:glowstone)
B(-12,15,-10,minecraft:glowstone)
B(-12,16,-10,minecraft:glowstone)
B(-12,11,-9,minecraft:glowstone)
B(-12,12,-9,minecraft:glowstone)
B(-12,13,-9,minecraft:glowstone)
B(-12,14,-9,minecraft:glowstone)
B(-12,15,-9,minecraft:glowstone)
B(-12,10,-8,minecraft:glowstone)
B(-12,11,-8,minecraft:glowstone)
B(-12,12,-8,minecraft:glowstone)
B(-12,13,-8,minecraft:glowstone)
B(-12,14,-8,minecraft:glowstone)
B(-12,11,-7,minecraft:glowstone)
B(-12,12,-7,minecraft:glowstone)
B(-12,13,-7,minecraft:glowstone)
B(-12,11,-6,minecraft:glowstone)
B(-12,12,-6,minecraft:glowstone)
B(-11,14,-12,minecraft:glowstone)
B(-11,15,-12,minecraft:glowstone)
B(-11,16,-12,minecraft:glowstone)
B(-11,10,-11,minecraft:glowstone)
B(-11,11,-11,minecraft:glowstone)
B(-11,12,-11,minecraft:glowstone)
B(-11,13,-11,minecraft:glowstone)
B(-11,14,-11,minecraft:glowstone)
B(-11,15,-11,minecraft:glowstone)
B(-11,16,-11,minecraft:glowstone)
B(-11,8,-10,minecraft:glowstone)
B(-11,9,-10,minecraft:glowstone)
B(-11,10,-10,minecraft:glowstone)
B(-11,11,-10,minecraft:glowstone)
B(-11,12,-10,minecraft:glowstone)
B(-11,13,-10,minecraft:glowstone)
B(-11,14,-10,minecraft:glowstone)
B(-11,15,-10,minecraft:glowstone)
B(-11,16,-10,minecraft:glowstone)
B(-11,7,-9,minecraft:glowstone)
B(-11,8,-9,minecraft:glowstone)
B(-11,9,-9,minecraft:glowstone)
B(-11,10,-9,minecraft:glowstone)
B(-11,11,-9,minecraft:glowstone)
B(-11,12,-9,minecraft:glowstone)
B(-11,13,-9,minecraft:glowstone)
B(-11,14,-9,minecraft:glowstone)
B(-11,15,-9,minecraft:glowstone)
B(-11,7,-8,minecraft:glowstone)
B(-11,8,-8,minecraft:glowstone)
B(-11,9,-8,minecraft:glowstone)
B(-11,10,-8,minecraft:glowstone)
B(-11,11,-8,minecraft:glowstone)
B(-11,12,-8,minecraft:glowstone)
B(-11,13,-8,minecraft:glowstone)
B(-11,14,-8,minecraft:glowstone)
B(-11,6,-7,minecraft:glowstone)
B(-11,7,-7,minecraft:glowstone)
B(-11,8,-7,minecraft:glowstone)
B(-11,9,-7,minecraft:glowstone)
B(-11,10,-7,minecraft:glowstone)
B(-11,11,-7,minecraft:glowstone)
B(-11,12,-7,minecraft:glowstone)
B(-11,13,-7,minecraft:glowstone)
B(-11,6,-6,minecraft:glowstone)
B(-11,7,-6,minecraft:glowstone)
B(-11,8,-6,minecraft:glowstone)
B(-11,9,-6,minecraft:glowstone)
B(-11,10,-6,minecraft:glowstone)
B(-11,11,-6,minecraft:glowstone)
B(-11,12,-6,minecraft:glowstone)
B(-11,5,-5,minecraft:glowstone)
B(-11,6,-5,minecraft:glowstone)
B(-11,7,-5,minecraft:glowstone)
B(-11,8,-5,minecraft:glowstone)
B(-11,9,-5,minecraft:glowstone)
B(-11,10,-5,minecraft:glowstone)
B(-11,11,-5,minecraft:glowstone)
B(-11,6,-4,minecraft:glowstone)
B(-11,7,-4,minecraft:glowstone)
B(-11,8,-4,minecraft:glowstone)
B(-11,9,-4,minecraft:glowstone)
B(-11,10,-4,minecraft:glowstone)
B(-11,7,-3,minecraft:glowstone)
B(-11,8,-3,minecraft:glowstone)
B(-11,9,-3,minecraft:glowstone)
B(-11,7,-2,minecraft:glowstone)
B(-11,8,-2,minecraft:glowstone)
B(-10,15,-12,minecraft:glowstone)
B(-10,16,-12,minecraft:glowstone)
B(-10,11,-11,minecraft:glowstone)
B(-10,12,-11,minecraft:glowstone)
B(-10,13,-11,minecraft:glowstone)
B(-10,14,-11,minecraft:glowstone)
B(-10,15,-11,minecraft:glowstone)
B(-10,16,-11,minecraft:glowstone)
B(-10,7,-10,minecraft:glowstone)
B(-10,8,-10,minecraft:glowstone)
B(-10,9,-10,minecraft:glowstone)
B(-10,10,-10,minecraft:glowstone)
B(-10,11,-10,minecraft:glowstone)
B(-10,12,-10,minecraft:glowstone)
B(-10,13,-10,minecraft:glowstone)
B(-10,14,-10,minecraft:glowstone)
B(-10,15,-10,minecraft:glowstone)
B(-10,4,-9,minecraft:glowstone)
B(-10,5,-9,minecraft:glowstone)
B(-10,6,-9,minecraft:glowstone)
B(-10,7,-9,minecraft:glowstone)
B(-10,8,-9,minecraft:glowstone)
B(-10,9,-9,minecraft:glowstone)
B(-10,10,-9,minecraft:glowstone)
B(-10,11,-9,minecraft:glowstone)
B(-10,12,-9,minecraft:glowstone)
B(-10,13,-9,minecraft:glowstone)
B(-10,14,-9,minecraft:glowstone)
B(-10,15,-9,minecraft:glowstone)
B(-10,4,-8,minecraft:glowstone)
B(-10,5,-8,minecraft:glowstone)
B(-10,6,-8,minecraft:glowstone)
B(-10,7,-8,minecraft:glowstone)
B(-10,8,-8,minecraft:glowstone)
B(-10,9,-8,minecraft:glowstone)
B(-10,10,-8,minecraft:glowstone)
B(-10,11,-8,minecraft:glowstone)
B(-10,12,-8,minecraft:glowstone)
B(-10,13,-8,minecraft:glowstone)
B(-10,14,-8,minecraft:glowstone)
B(-10,3,-7,minecraft:glowstone)
B(-10,4,-7,minecraft:glowstone)
B(-10,5,-7,minecraft:glowstone)
B(-10,6,-7,minecraft:glowstone)
B(-10,7,-7,minecraft:glowstone)
B(-10,8,-7,minecraft:glowstone)
B(-10,9,-7,minecraft:glowstone)
B(-10,10,-7,minecraft:glowstone)
B(-10,11,-7,minecraft:glowstone)
B(-10,12,-7,minecraft:glowstone)
B(-10,13,-7,minecraft:glowstone)
B(-10,14,-7,minecraft:glowstone)
B(-10,3,-6,minecraft:glowstone)
B(-10,4,-6,minecraft:glowstone)
B(-10,5,-6,minecraft:glowstone)
B(-10,6,-6,minecraft:glowstone)
B(-10,7,-6,minecraft:glowstone)
B(-10,8,-6,minecraft:glowstone)
B(-10,9,-6,minecraft:glowstone)
B(-10,10,-6,minecraft:glowstone)
B(-10,11,-6,minecraft:glowstone)
B(-10,12,-6,minecraft:glowstone)
B(-10,13,-6,minecraft:glowstone)
B(-10,2,-5,minecraft:glowstone)
B(-10,3,-5,minecraft:glowstone)
B(-10,4,-5,minecraft:glowstone)
B(-10,5,-5,minecraft:glowstone)
B(-10,6,-5,minecraft:glowstone)
B(-10,7,-5,minecraft:glowstone)
B(-10,8,-5,minecraft:glowstone)
B(-10,9,-5,minecraft:glowstone)
B(-10,10,-5,minecraft:glowstone)
B(-10,11,-5,minecraft:glowstone)
B(-10,12,-5,minecraft:glowstone)
B(-10,2,-4,minecraft:glowstone)
B(-10,3,-4,minecraft:glowstone)
B(-10,4,-4,minecraft:glowstone)
B(-10,5,-4,minecraft:glowstone)
B(-10,6,-4,minecraft:glowstone)
B(-10,7,-4,minecraft:glowstone)
B(-10,8,-4,minecraft:glowstone)
B(-10,9,-4,minecraft:glowstone)
B(-10,10,-4,minecraft:glowstone)
B(-10,11,-4,minecraft:glowstone)
B(-10,1,-3,minecraft:glowstone)
B(-10,2,-3,minecraft:glowstone)
B(-10,3,-3,minecraft:glowstone)
B(-10,4,-3,minecraft:glowstone)
B(-10,5,-3,minecraft:glowstone)
B(-10,6,-3,minecraft:glowstone)
B(-10,7,-3,minecraft:glowstone)
B(-10,8,-3,minecraft:glowstone)
B(-10,9,-3,minecraft:glowstone)
B(-10,10,-3,minecraft:glowstone)
B(-10,0,-2,minecraft:glowstone)
B(-10,1,-2,minecraft:glowstone)
B(-10,2,-2,minecraft:glowstone)
B(-10,3,-2,minecraft:glowstone)
B(-10,4,-2,minecraft:glowstone)
B(-10,5,-2,minecraft:glowstone)
B(-10,6,-2,minecraft:glowstone)
B(-10,7,-2,minecraft:glowstone)
B(-10,8,-2,minecraft:glowstone)
B(-10,9,-2,minecraft:glowstone)
B(-10,1,-1,minecraft:glowstone)
B(-10,2,-1,minecraft:glowstone)
B(-10,3,-1,minecraft:glowstone)
B(-10,4,-1,minecraft:glowstone)
B(-10,5,-1,minecraft:glowstone)
B(-10,6,-1,minecraft:glowstone)
B(-10,7,-1,minecraft:glowstone)
B(-10,8,-1,minecraft:glowstone)
B(-10,2,0,minecraft:glowstone)
B(-10,3,0,minecraft:glowstone)
B(-10,4,0,minecraft:glowstone)
B(-10,5,0,minecraft:glowstone)
B(-10,6,0,minecraft:glowstone)
B(-10,7,0,minecraft:glowstone)
B(-10,3,1,minecraft:glowstone)
B(-10,4,1,minecraft:glowstone)
B(-10,5,1,minecraft:glowstone)
B(-10,6,1,minecraft:glowstone)
B(-10,3,2,minecraft:glowstone)
B(-10,4,2,minecraft:glowstone)
B(-10,5,2,minecraft:glowstone)
B(-10,4,3,minecraft:glowstone)
B(-9,12,-11,minecraft:glowstone)
B(-9,13,-11,minecraft:glowstone)
B(-9,14,-11,minecraft:glowstone)
B(-9,15,-11,minecraft:glowstone)
B(-9,8,-10,minecraft:glowstone)
B(-9,9,-10,minecraft:glowstone)
B(-9,10,-10,minecraft:glowstone)
B(-9,11,-10,minecraft:glowstone)
B(-9,12,-10,minecraft:glowstone)
B(-9,13,-10,minecraft:glowstone)
B(-9,14,-10,minecraft:glowstone)
B(-9,15,-10,minecraft:glowstone)
B(-9,4,-9,minecraft:glowstone)
B(-9,5,-9,minecraft:glowstone)
B(-9,6,-9,minecraft:glowstone)
B(-9,7,-9,minecraft:glowstone)
B(-9,8,-9,minecraft:glowstone)
B(-9,9,-9,minecraft:glowstone)
B(-9,10,-9,minecraft:glowstone)
B(-9,11,-9,minecraft:glowstone)
B(-9,12,-9,minecraft:glowstone)
B(-9,13,-9,minecraft:glowstone)
B(-9,14,-9,minecraft:glowstone)
B(-9,15,-9,minecraft:glowstone)
B(-9,0,-8,minecraft:glowstone)
B(-9,1,-8,minecraft:glowstone)
B(-9,2,-8,minecraft:glowstone)
B(-9,3,-8,minecraft:glowstone)
B(-9,4,-8,minecraft:glowstone)
B(-9,5,-8,minecraft:glowstone)
B(-9,6,-8,minecraft:glowstone)
B(-9,7,-8,minecraft:glowstone)
B(-9,8,-8,minecraft:glowstone)
B(-9,9,-8,minecraft:glowstone)
B(-9,10,-8,minecraft:glowstone)
B(-9,11,-8,minecraft:glowstone)
B(-9,12,-8,minecraft:glowstone)
B(-9,13,-8,minecraft:glowstone)
B(-9,14,-8,minecraft:glowstone)
B(-9,0,-7,minecraft:glowstone)
B(-9,1,-7,minecraft:glowstone)
B(-9,2,-7,minecraft:glowstone)
B(-9,3,-7,minecraft:glowstone)
B(-9,4,-7,minecraft:glowstone)
B(-9,5,-7,minecraft:glowstone)
B(-9,6,-7,minecraft:glowstone)
B(-9,7,-7,minecraft:glowstone)
B(-9,8,-7,minecraft:glowstone)
B(-9,9,-7,minecraft:glowstone)
B(-9,10,-7,minecraft:glowstone)
B(-9,11,-7,minecraft:glowstone)
B(-9,12,-7,minecraft:glowstone)
B(-9,13,-7,minecraft:glowstone)
B(-9,14,-7,minecraft:glowstone)
B(-9,0,-6,minecraft:glowstone)
B(-9,1,-6,minecraft:glowstone)
B(-9,2,-6,minecraft:glowstone)
B(-9,3,-6,minecraft:glowstone)
B(-9,4,-6,minecraft:glowstone)
B(-9,5,-6,minecraft:glowstone)
B(-9,6,-6,minecraft:glowstone)
B(-9,7,-6,minecraft:glowstone)
B(-9,8,-6,minecraft:glowstone)
B(-9,9,-6,minecraft:glowstone)
B(-9,10,-6,minecraft:glowstone)
B(-9,11,-6,minecraft:glowstone)
B(-9,12,-6,minecraft:glowstone)
B(-9,13,-6,minecraft:glowstone)
B(-9,0,-5,minecraft:glowstone)
B(-9,1,-5,minecraft:glowstone)
B(-9,2,-5,minecraft:glowstone)
B(-9,3,-5,minecraft:glowstone)
B(-9,4,-5,minecraft:glowstone)
B(-9,5,-5,minecraft:glowstone)
B(-9,6,-5,minecraft:glowstone)
B(-9,7,-5,minecraft:glowstone)
B(-9,8,-5,minecraft:glowstone)
B(-9,9,-5,minecraft:glowstone)
B(-9,10,-5,minecraft:glowstone)
B(-9,11,-5,minecraft:glowstone)
B(-9,12,-5,minecraft:glowstone)
B(-9,0,-4,minecraft:glowstone)
B(-9,1,-4,minecraft:glowstone)
B(-9,2,-4,minecraft:glowstone)
B(-9,3,-4,minecraft:glowstone)
B(-9,4,-4,minecraft:glowstone)
B(-9,5,-4,minecraft:glowstone)
B(-9,6,-4,minecraft:glowstone)
B(-9,7,-4,minecraft:glowstone)
B(-9,8,-4,minecraft:glowstone)
B(-9,9,-4,minecraft:glowstone)
B(-9,10,-4,minecraft:glowstone)
B(-9,11,-4,minecraft:glowstone)
B(-9,12,-4,minecraft:glowstone)
B(-9,0,-3,minecraft:glowstone)
B(-9,1,-3,minecraft:glowstone)
B(-9,2,-3,minecraft:glowstone)
B(-9,3,-3,minecraft:glowstone)
B(-9,4,-3,minecraft:glowstone)
B(-9,5,-3,minecraft:glowstone)
B(-9,6,-3,minecraft:glowstone)
B(-9,7,-3,minecraft:glowstone)
B(-9,8,-3,minecraft:glowstone)
B(-9,9,-3,minecraft:glowstone)
B(-9,10,-3,minecraft:glowstone)
B(-9,11,-3,minecraft:glowstone)
B(-9,0,-2,minecraft:glowstone)
B(-9,1,-2,minecraft:glowstone)
B(-9,2,-2,minecraft:glowstone)
B(-9,3,-2,minecraft:glowstone)
B(-9,4,-2,minecraft:glowstone)
B(-9,5,-2,minecraft:glowstone)
B(-9,6,-2,minecraft:glowstone)
B(-9,7,-2,minecraft:glowstone)
B(-9,8,-2,minecraft:glowstone)
B(-9,9,-2,minecraft:glowstone)
B(-9,10,-2,minecraft:glowstone)
B(-9,0,-1,minecraft:glowstone)
B(-9,1,-1,minecraft:glowstone)
B(-9,2,-1,minecraft:glowstone)
B(-9,3,-1,minecraft:glowstone)
B(-9,4,-1,minecraft:glowstone)
B(-9,5,-1,minecraft:glowstone)
B(-9,6,-1,minecraft:glowstone)
B(-9,7,-1,minecraft:glowstone)
B(-9,8,-1,minecraft:glowstone)
B(-9,9,-1,minecraft:glowstone)
B(-9,0,0,minecraft:glowstone)
B(-9,1,0,minecraft:glowstone)
B(-9,2,0,minecraft:glowstone)
B(-9,3,0,minecraft:glowstone)
B(-9,4,0,minecraft:glowstone)
B(-9,5,0,minecraft:glowstone)
B(-9,6,0,minecraft:glowstone)
B(-9,7,0,minecraft:glowstone)
B(-9,8,0,minecraft:glowstone)
B(-9,0,1,minecraft:glowstone)
B(-9,1,1,minecraft:glowstone)
B(-9,2,1,minecraft:glowstone)
B(-9,3,1,minecraft:glowstone)
B(-9,4,1,minecraft:glowstone)
B(-9,5,1,minecraft:glowstone)
B(-9,6,1,minecraft:glowstone)
B(-9,7,1,minecraft:glowstone)
B(-9,0,2,minecraft:glowstone)
B(-9,1,2,minecraft:glowstone)
B(-9,2,2,minecraft:glowstone)
B(-9,3,2,minecraft:glowstone)
B(-9,4,2,minecraft:glowstone)
B(-9,5,2,minecraft:glowstone)
B(-9,6,2,minecraft:glowstone)
B(-9,0,3,minecraft:glowstone)
B(-9,1,3,minecraft:glowstone)
B(-9,2,3,minecraft:glowstone)
B(-9,3,3,minecraft:glowstone)
B(-9,4,3,minecraft:glowstone)
B(-9,5,3,minecraft:glowstone)
B(-9,0,4,minecraft:glowstone)
B(-9,1,4,minecraft:glowstone)
B(-9,2,4,minecraft:glowstone)
B(-9,3,4,minecraft:glowstone)
B(-9,4,4,minecraft:glowstone)
B(-9,0,5,minecraft:glowstone)
B(-9,1,5,minecraft:glowstone)
B(-9,2,5,minecraft:glowstone)
B(-9,3,5,minecraft:glowstone)
B(-9,0,6,minecraft:glowstone)
B(-9,1,6,minecraft:glowstone)
B(-9,2,6,minecraft:glowstone)
B(-9,0,7,minecraft:glowstone)
B(-9,1,7,minecraft:glowstone)
B(-9,0,8,minecraft:glowstone)
B(-8,12,-11,minecraft:glowstone)
B(-8,13,-11,minecraft:glowstone)
B(-8,14,-11,minecraft:glowstone)
B(-8,9,-10,minecraft:glowstone)
B(-8,10,-10,minecraft:glowstone)
B(-8,11,-10,minecraft:glowstone)
B(-8,12,-10,minecraft:glowstone)
B(-8,13,-10,minecraft:glowstone)
B(-8,14,-10,minecraft:glowstone)
B(-8,5,-9,minecraft:glowstone)
B(-8,6,-9,minecraft:glowstone)
B(-8,7,-9,minecraft:glowstone)
B(-8,8,-9,minecraft:glowstone)
B(-8,9,-9,minecraft:glowstone)
B(-8,10,-9,minecraft:glowstone)
B(-8,11,-9,minecraft:glowstone)
B(-8,12,-9,minecraft:glowstone)
B(-8,13,-9,minecraft:glowstone)
B(-8,14,-9,minecraft:glowstone)
B(-8,1,-8,minecraft:glowstone)
B(-8,2,-8,minecraft:glowstone)
B(-8,3,-8,minecraft:glowstone)
B(-8,4,-8,minecraft:glowstone)
B(-8,5,-8,minecraft:glowstone)
B(-8,6,-8,minecraft:glowstone)
B(-8,7,-8,minecraft:glowstone)
B(-8,8,-8,minecraft:glowstone)
B(-8,9,-8,minecraft:glowstone)
B(-8,10,-8,minecraft:glowstone)
B(-8,11,-8,minecraft:glowstone)
B(-8,12,-8,minecraft:glowstone)
B(-8,13,-8,minecraft:glowstone)
B(-8,14,-8,minecraft:glowstone)
B(-8,0,-7,minecraft:glowstone)
B(-8,1,-7,minecraft:glowstone)
B(-8,2,-7,minecraft:glowstone)
B(-8,3,-7,minecraft:glowstone)
B(-8,4,-7,minecraft:glowstone)
B(-8,5,-7,minecraft:glowstone)
B(-8,6,-7,minecraft:glowstone)
B(-8,7,-7,minecraft:glowstone)
B(-8,8,-7,minecraft:glowstone)
B(-8,9,-7,minecraft:glowstone)
B(-8,10,-7,minecraft:glowstone)
B(-8,11,-7,minecraft:glowstone)
B(-8,12,-7,minecraft:glowstone)
B(-8,13,-7,minecraft:glowstone)
B(-8,0,-6,minecraft:glowstone)
B(-8,1,-6,minecraft:glowstone)
B(-8,2,-6,minecraft:glowstone)
B(-8,3,-6,minecraft:glowstone)
B(-8,4,-6,minecraft:glowstone)
B(-8,5,-6,minecraft:glowstone)
B(-8,6,-6,minecraft:glowstone)
B(-8,7,-6,minecraft:glowstone)
B(-8,8,-6,minecraft:glowstone)
B(-8,9,-6,minecraft:glowstone)
B(-8,10,-6,minecraft:glowstone)
B(-8,11,-6,minecraft:glowstone)
B(-8,12,-6,minecraft:glowstone)
B(-8,13,-6,minecraft:glowstone)
B(-8,0,-5,minecraft:glowstone)
B(-8,1,-5,minecraft:glowstone)
B(-8,2,-5,minecraft:glowstone)
B(-8,3,-5,minecraft:glowstone)
B(-8,4,-5,minecraft:glowstone)
B(-8,5,-5,minecraft:glowstone)
B(-8,6,-5,minecraft:glowstone)
B(-8,7,-5,minecraft:glowstone)
B(-8,8,-5,minecraft:glowstone)
B(-8,9,-5,minecraft:glowstone)
B(-8,10,-5,minecraft:glowstone)
B(-8,11,-5,minecraft:glowstone)
B(-8,12,-5,minecraft:glowstone)
B(-8,0,-4,minecraft:glowstone)
B(-8,1,-4,minecraft:glowstone)
B(-8,2,-4,minecraft:glowstone)
B(-8,3,-4,minecraft:glowstone)
B(-8,4,-4,minecraft:glowstone)
B(-8,5,-4,minecraft:glowstone)
B(-8,6,-4,minecraft:glowstone)
B(-8,7,-4,minecraft:glowstone)
B(-8,8,-4,minecraft:glowstone)
B(-8,9,-4,minecraft:glowstone)
B(-8,10,-4,minecraft:glowstone)
B(-8,11,-4,minecraft:glowstone)
B(-8,12,-4,minecraft:glowstone)
B(-8,0,-3,minecraft:glowstone)
B(-8,1,-3,minecraft:glowstone)
B(-8,2,-3,minecraft:glowstone)
B(-8,3,-3,minecraft:glowstone)
B(-8,4,-3,minecraft:glowstone)
B(-8,5,-3,minecraft:glowstone)
B(-8,6,-3,minecraft:glowstone)
B(-8,7,-3,minecraft:glowstone)
B(-8,8,-3,minecraft:glowstone)
B(-8,9,-3,minecraft:glowstone)
B(-8,10,-3,minecraft:glowstone)
B(-8,11,-3,minecraft:glowstone)
B(-8,0,-2,minecraft:glowstone)
B(-8,1,-2,minecraft:glowstone)
B(-8,2,-2,minecraft:glowstone)
B(-8,3,-2,minecraft:glowstone)
B(-8,4,-2,minecraft:glowstone)
B(-8,5,-2,minecraft:glowstone)
B(-8,6,-2,minecraft:glowstone)
B(-8,7,-2,minecraft:glowstone)
B(-8,8,-2,minecraft:glowstone)
B(-8,9,-2,minecraft:glowstone)
B(-8,10,-2,minecraft:glowstone)
B(-8,0,-1,minecraft:glowstone)
B(-8,1,-1,minecraft:glowstone)
B(-8,2,-1,minecraft:glowstone)
B(-8,3,-1,minecraft:glowstone)
B(-8,4,-1,minecraft:glowstone)
B(-8,5,-1,minecraft:glowstone)
B(-8,6,-1,minecraft:glowstone)
B(-8,7,-1,minecraft:glowstone)
B(-8,8,-1,minecraft:glowstone)
B(-8,9,-1,minecraft:glowstone)
B(-8,0,0,minecraft:glowstone)
B(-8,1,0,minecraft:glowstone)
B(-8,2,0,minecraft:glowstone)
B(-8,3,0,minecraft:glowstone)
B(-8,4,0,minecraft:glowstone)
B(-8,5,0,minecraft:glowstone)
B(-8,6,0,minecraft:glowstone)
B(-8,7,0,minecraft:glowstone)
B(-8,8,0,minecraft:glowstone)
B(-8,0,1,minecraft:glowstone)
B(-8,1,1,minecraft:glowstone)
B(-8,2,1,minecraft:glowstone)
B(-8,3,1,minecraft:glowstone)
B(-8,4,1,minecraft:glowstone)
B(-8,5,1,minecraft:glowstone)
B(-8,6,1,minecraft:glowstone)
B(-8,7,1,minecraft:glowstone)
B(-8,0,2,minecraft:glowstone)
B(-8,1,2,minecraft:glowstone)
B(-8,2,2,minecraft:glowstone)
B(-8,3,2,minecraft:glowstone)
B(-8,4,2,minecraft:glowstone)
B(-8,5,2,minecraft:glowstone)
B(-8,6,2,minecraft:glowstone)
B(-8,0,3,minecraft:glowstone)
B(-8,1,3,minecraft:glowstone)
B(-8,2,3,minecraft:glowstone)
B(-8,3,3,minecraft:glowstone)
B(-8,4,3,minecraft:glowstone)
B(-8,5,3,minecraft:glowstone)
B(-8,0,4,minecraft:glowstone)
B(-8,1,4,minecraft:glowstone)
B(-8,2,4,minecraft:glowstone)
B(-8,3,4,minecraft:glowstone)
B(-8,4,4,minecraft:glowstone)
B(-8,0,5,minecraft:glowstone)
B(-8,1,5,minecraft:glowstone)
B(-8,2,5,minecraft:glowstone)
B(-8,3,5,minecraft:glowstone)
B(-8,0,6,minecraft:glowstone)
B(-8,1,6,minecraft:glowstone)
B(-8,2,6,minecraft:glowstone)
B(-8,0,7,minecraft:glowstone)
B(-8,1,7,minecraft:glowstone)
B(-8,0,8,minecraft:glowstone)
B(-7,13,-11,minecraft:glowstone)
B(-7,9,-10,minecraft:glowstone)
B(-7,10,-10,minecraft:glowstone)
B(-7,11,-10,minecraft:glowstone)
B(-7,12,-10,minecraft:glowstone)
B(-7,13,-10,minecraft:glowstone)
B(-7,14,-10,minecraft:glowstone)
B(-7,6,-9,minecraft:glowstone)
B(-7,7,-9,minecraft:glowstone)
B(-7,8,-9,minecraft:glowstone)
B(-7,9,-9,minecraft:glowstone)
B(-7,10,-9,minecraft:glowstone)
B(-7,11,-9,minecraft:glowstone)
B(-7,12,-9,minecraft:glowstone)
B(-7,13,-9,minecraft:glowstone)
B(-7,14,-9,minecraft:glowstone)
B(-7,2,-8,minecraft:glowstone)
B(-7,3,-8,minecraft:glowstone)
B(-7,4,-8,minecraft:glowstone)
B(-7,5,-8,minecraft:glowstone)
B(-7,6,-8,minecraft:glowstone)
B(-7,7,-8,minecraft:glowstone)
B(-7,8,-8,minecraft:glowstone)
B(-7,9,-8,minecraft:glowstone)
B(-7,10,-8,minecraft:glowstone)
B(-7,11,-8,minecraft:glowstone)
B(-7,12,-8,minecraft:glowstone)
B(-7,13,-8,minecraft:glowstone)
B(-7,0,-7,minecraft:glowstone)
B(-7,1,-7,minecraft:glowstone)
B(-7,2,-7,minecraft:glowstone)
B(-7,3,-7,minecraft:glowstone)
B(-7,4,-7,minecraft:glowstone)
B(-7,5,-7,minecraft:glowstone)
B(-7,6,-7,minecraft:glowstone)
B(-7,7,-7,minecraft:glowstone)
B(-7,8,-7,minecraft:glowstone)
B(-7,9,-7,minecraft:glowstone)
B(-7,10,-7,minecraft:glowstone)
B(-7,11,-7,minecraft:glowstone)
B(-7,12,-7,minecraft:glowstone)
B(-7,13,-7,minecraft:glowstone)
B(-7,0,-6,minecraft:glowstone)
B(-7,1,-6,minecraft:glowstone)
B(-7,2,-6,minecraft:glowstone)
B(-7,3,-6,minecraft:glowstone)
B(-7,4,-6,minecraft:glowstone)
B(-7,5,-6,minecraft:glowstone)
B(-7,6,-6,minecraft:glowstone)
B(-7,7,-6,minecraft:glowstone)
B(-7,8,-6,minecraft:glowstone)
B(-7,9,-6,minecraft:glowstone)
B(-7,10,-6,minecraft:glowstone)
B(-7,11,-6,minecraft:glowstone)
B(-7,12,-6,minecraft:glowstone)
B(-7,13,-6,minecraft:glowstone)
B(-7,0,-5,minecraft:glowstone)
B(-7,1,-5,minecraft:glowstone)
B(-7,2,-5,minecraft:glowstone)
B(-7,3,-5,minecraft:glowstone)
B(-7,4,-5,minecraft:glowstone)
B(-7,5,-5,minecraft:glowstone)
B(-7,6,-5,minecraft:glowstone)
B(-7,7,-5,minecraft:glowstone)
B(-7,8,-5,minecraft:glowstone)
B(-7,9,-5,minecraft:glowstone)
B(-7,10,-5,minecraft:glowstone)
B(-7,11,-5,minecraft:glowstone)
B(-7,12,-5,minecraft:glowstone)
B(-7,0,-4,minecraft:glowstone)
B(-7,1,-4,minecraft:glowstone)
B(-7,2,-4,minecraft:glowstone)
B(-7,3,-4,minecraft:glowstone)
B(-7,4,-4,minecraft:glowstone)
B(-7,5,-4,minecraft:glowstone)
B(-7,6,-4,minecraft:glowstone)
B(-7,7,-4,minecraft:glowstone)
B(-7,8,-4,minecraft:glowstone)
B(-7,9,-4,minecraft:glowstone)
B(-7,10,-4,minecraft:glowstone)
B(-7,11,-4,minecraft:glowstone)
B(-7,0,-3,minecraft:glowstone)
B(-7,1,-3,minecraft:glowstone)
B(-7,2,-3,minecraft:glowstone)
B(-7,3,-3,minecraft:glowstone)
B(-7,4,-3,minecraft:glowstone)
B(-7,5,-3,minecraft:glowstone)
B(-7,6,-3,minecraft:glowstone)
B(-7,7,-3,minecraft:glowstone)
B(-7,8,-3,minecraft:glowstone)
B(-7,9,-3,minecraft:glowstone)
B(-7,10,-3,minecraft:glowstone)
B(-7,11,-3,minecraft:glowstone)
B(-7,0,-2,minecraft:glowstone)
B(-7,1,-2,minecraft:glowstone)
B(-7,2,-2,minecraft:glowstone)
B(-7,3,-2,minecraft:glowstone)
B(-7,4,-2,minecraft:glowstone)
B(-7,5,-2,minecraft:glowstone)
B(-7,6,-2,minecraft:glowstone)
B(-7,7,-2,minecraft:glowstone)
B(-7,8,-2,minecraft:glowstone)
B(-7,9,-2,minecraft:glowstone)
B(-7,10,-2,minecraft:glowstone)
B(-7,0,-1,minecraft:glowstone)
B(-7,1,-1,minecraft:glowstone)
B(-7,2,-1,minecraft:glowstone)
B(-7,3,-1,minecraft:glowstone)
B(-7,4,-1,minecraft:glowstone)
B(-7,5,-1,minecraft:glowstone)
B(-7,6,-1,minecraft:glowstone)
B(-7,7,-1,minecraft:glowstone)
B(-7,8,-1,minecraft:glowstone)
B(-7,9,-1,minecraft:glowstone)
B(-7,10,-1,minecraft:glowstone)
B(-7,0,0,minecraft:glowstone)
B(-7,1,0,minecraft:glowstone)
B(-7,2,0,minecraft:glowstone)
B(-7,3,0,minecraft:glowstone)
B(-7,4,0,minecraft:glowstone)
B(-7,5,0,minecraft:glowstone)
B(-7,6,0,minecraft:glowstone)
B(-7,7,0,minecraft:glowstone)
B(-7,8,0,minecraft:glowstone)
B(-7,9,0,minecraft:glowstone)
B(-7,0,1,minecraft:glowstone)
B(-7,1,1,minecraft:glowstone)
B(-7,2,1,minecraft:glowstone)
B(-7,3,1,minecraft:glowstone)
B(-7,4,1,minecraft:glowstone)
B(-7,5,1,minecraft:glowstone)
B(-7,6,1,minecraft:glowstone)
B(-7,7,1,minecraft:glowstone)
B(-7,8,1,minecraft:glowstone)
B(-7,0,2,minecraft:glowstone)
B(-7,1,2,minecraft:glowstone)
B(-7,2,2,minecraft:glowstone)
B(-7,3,2,minecraft:glowstone)
B(-7,4,2,minecraft:glowstone)
B(-7,5,2,minecraft:glowstone)
B(-7,6,2,minecraft:glowstone)
B(-7,7,2,minecraft:glowstone)
B(-7,0,3,minecraft:glowstone)
B(-7,1,3,minecraft:glowstone)
B(-7,2,3,minecraft:glowstone)
B(-7,3,3,minecraft:glowstone)
B(-7,4,3,minecraft:glowstone)
B(-7,5,3,minecraft:glowstone)
B(-7,6,3,minecraft:glowstone)
B(-7,0,4,minecraft:glowstone)
B(-7,1,4,minecraft:glowstone)
B(-7,2,4,minecraft:glowstone)
B(-7,3,4,minecraft:glowstone)
B(-7,4,4,minecraft:glowstone)
B(-7,5,4,minecraft:glowstone)
B(-7,0,5,minecraft:glowstone)
B(-7,1,5,minecraft:glowstone)
B(-7,2,5,minecraft:glowstone)
B(-7,3,5,minecraft:glowstone)
B(-7,4,5,minecraft:glowstone)
B(-7,0,6,minecraft:glowstone)
B(-7,1,6,minecraft:glowstone)
B(-7,2,6,minecraft:glowstone)
B(-7,3,6,minecraft:glowstone)
B(-7,0,7,minecraft:glowstone)
B(-7,1,7,minecraft:glowstone)
B(-7,2,7,minecraft:glowstone)
B(-7,0,8,minecraft:glowstone)
B(-7,1,8,minecraft:glowstone)
B(-7,0,9,minecraft:glowstone)
B(-6,10,-10,minecraft:glowstone)
B(-6,11,-10,minecraft:glowstone)
B(-6,12,-10,minecraft:glowstone)
B(-6,13,-10,minecraft:glowstone)
B(-6,6,-9,minecraft:glowstone)
B(-6,7,-9,minecraft:glowstone)
B(-6,8,-9,minecraft:glowstone)
B(-6,9,-9,minecraft:glowstone)
B(-6,10,-9,minecraft:glowstone)
B(-6,11,-9,minecraft:glowstone)
B(-6,12,-9,minecraft:glowstone)
B(-6,13,-9,minecraft:glowstone)
B(-6,2,-8,minecraft:glowstone)
B(-6,3,-8,minecraft:glowstone)
B(-6,4,-8,minecraft:glowstone)
B(-6,5,-8,minecraft:glowstone)
B(-6,6,-8,minecraft:glowstone)
B(-6,7,-8,minecraft:glowstone)
B(-6,8,-8,minecraft:glowstone)
B(-6,9,-8,minecraft:glowstone)
B(-6,10,-8,minecraft:glowstone)
B(-6,11,-8,minecraft:glowstone)
B(-6,12,-8,minecraft:glowstone)
B(-6,13,-8,minecraft:glowstone)
B(-6,0,-7,minecraft:glowstone)
B(-6,1,-7,minecraft:glowstone)
B(-6,2,-7,minecraft:glowstone)
B(-6,3,-7,minecraft:glowstone)
B(-6,4,-7,minecraft:glowstone)
B(-6,5,-7,minecraft:glowstone)
B(-6,6,-7,minecraft:glowstone)
B(-6,7,-7,minecraft:glowstone)
B(-6,8,-7,minecraft:glowstone)
B(-6,9,-7,minecraft:glowstone)
B(-6,10,-7,minecraft:glowstone)
B(-6,11,-7,minecraft:glowstone)
B(-6,12,-7,minecraft:glowstone)
B(-6,13,-7,minecraft:glowstone)
B(-6,0,-6,minecraft:glowstone)
B(-6,1,-6,minecraft:glowstone)
B(-6,2,-6,minecraft:glowstone)
B(-6,3,-6,minecraft:glowstone)
B(-6,4,-6,minecraft:glowstone)
B(-6,5,-6,minecraft:glowstone)
B(-6,6,-6,minecraft:glowstone)
B(-6,7,-6,minecraft:glowstone)
B(-6,8,-6,minecraft:glowstone)
B(-6,9,-6,minecraft:glowstone)
B(-6,10,-6,minecraft:glowstone)
B(-6,11,-6,minecraft:glowstone)
B(-6,12,-6,minecraft:glowstone)
B(-6,0,-5,minecraft:glowstone)
B(-6,1,-5,minecraft:glowstone)
B(-6,2,-5,minecraft:glowstone)
B(-6,3,-5,minecraft:glowstone)
B(-6,4,-5,minecraft:glowstone)
B(-6,5,-5,minecraft:glowstone)
B(-6,6,-5,minecraft:glowstone)
B(-6,7,-5,minecraft:glowstone)
B(-6,8,-5,minecraft:glowstone)
B(-6,9,-5,minecraft:glowstone)
B(-6,10,-5,minecraft:glowstone)
B(-6,11,-5,minecraft:glowstone)
B(-6,12,-5,minecraft:glowstone)
B(-6,0,-4,minecraft:glowstone)
B(-6,1,-4,minecraft:glowstone)
B(-6,2,-4,minecraft:glowstone)
B(-6,3,-4,minecraft:glowstone)
B(-6,4,-4,minecraft:glowstone)
B(-6,5,-4,minecraft:glowstone)
B(-6,6,-4,minecraft:glowstone)
B(-6,7,-4,minecraft:glowstone)
B(-6,8,-4,minecraft:glowstone)
B(-6,9,-4,minecraft:glowstone)
B(-6,10,-4,minecraft:glowstone)
B(-6,11,-4,minecraft:glowstone)
B(-6,0,-3,minecraft:glowstone)
B(-6,1,-3,minecraft:glowstone)
B(-6,2,-3,minecraft:glowstone)
B(-6,3,-3,minecraft:glowstone)
B(-6,4,-3,minecraft:glowstone)
B(-6,5,-3,minecraft:glowstone)
B(-6,6,-3,minecraft:glowstone)
B(-6,7,-3,minecraft:glowstone)
B(-6,8,-3,minecraft:glowstone)
B(-6,9,-3,minecraft:glowstone)
B(-6,10,-3,minecraft:glowstone)
B(-6,11,-3,minecraft:glowstone)
B(-6,0,-2,minecraft:glowstone)
B(-6,1,-2,minecraft:glowstone)
B(-6,2,-2,minecraft:glowstone)
B(-6,3,-2,minecraft:glowstone)
B(-6,4,-2,minecraft:glowstone)
B(-6,5,-2,minecraft:glowstone)
B(-6,6,-2,minecraft:glowstone)
B(-6,7,-2,minecraft:glowstone)
B(-6,8,-2,minecraft:glowstone)
B(-6,9,-2,minecraft:glowstone)
B(-6,10,-2,minecraft:glowstone)
B(-6,0,-1,minecraft:glowstone)
B(-6,1,-1,minecraft:glowstone)
B(-6,2,-1,minecraft:glowstone)
B(-6,3,-1,minecraft:glowstone)
B(-6,4,-1,minecraft:glowstone)
B(-6,5,-1,minecraft:glowstone)
B(-6,6,-1,minecraft:glowstone)
B(-6,7,-1,minecraft:glowstone)
B(-6,8,-1,minecraft:glowstone)
B(-6,9,-1,minecraft:glowstone)
B(-6,0,0,minecraft:glowstone)
B(-6,1,0,minecraft:glowstone)
B(-6,2,0,minecraft:glowstone)
B(-6,3,0,minecraft:glowstone)
B(-6,4,0,minecraft:glowstone)
B(-6,5,0,minecraft:glowstone)
B(-6,6,0,minecraft:glowstone)
B(-6,7,0,minecraft:glowstone)
B(-6,8,0,minecraft:glowstone)
B(-6,9,0,minecraft:glowstone)
B(-6,0,1,minecraft:glowstone)
B(-6,1,1,minecraft:glowstone)
B(-6,2,1,minecraft:glowstone)
B(-6,3,1,minecraft:glowstone)
B(-6,4,1,minecraft:glowstone)
B(-6,5,1,minecraft:glowstone)
B(-6,6,1,minecraft:glowstone)
B(-6,7,1,minecraft:glowstone)
B(-6,8,1,minecraft:glowstone)
B(-6,0,2,minecraft:glowstone)
B(-6,1,2,minecraft:glowstone)
B(-6,2,2,minecraft:glowstone)
B(-6,3,2,minecraft:glowstone)
B(-6,4,2,minecraft:glowstone)
B(-6,5,2,minecraft:glowstone)
B(-6,6,2,minecraft:glowstone)
B(-6,7,2,minecraft:glowstone)
B(-6,8,2,minecraft:glowstone)
B(-6,0,3,minecraft:glowstone)
B(-6,1,3,minecraft:glowstone)
B(-6,2,3,minecraft:glowstone)
B(-6,3,3,minecraft:glowstone)
B(-6,4,3,minecraft:glowstone)
B(-6,5,3,minecraft:glowstone)
B(-6,6,3,minecraft:glowstone)
B(-6,7,3,minecraft:glowstone)
B(-6,0,4,minecraft:glowstone)
B(-6,1,4,minecraft:glowstone)
B(-6,2,4,minecraft:glowstone)
B(-6,3,4,minecraft:glowstone)
B(-6,4,4,minecraft:glowstone)
B(-6,5,4,minecraft:glowstone)
B(-6,6,4,minecraft:glowstone)
B(-6,0,5,minecraft:glowstone)
B(-6,1,5,minecraft:glowstone)
B(-6,2,5,minecraft:glowstone)
B(-6,3,5,minecraft:glowstone)
B(-6,4,5,minecraft:glowstone)
B(-6,5,5,minecraft:glowstone)
B(-6,0,6,minecraft:glowstone)
B(-6,1,6,minecraft:glowstone)
B(-6,2,6,minecraft:glowstone)
B(-6,3,6,minecraft:glowstone)
B(-6,4,6,minecraft:glowstone)
B(-6,0,7,minecraft:glowstone)
B(-6,1,7,minecraft:glowstone)
B(-6,2,7,minecraft:glowstone)
B(-6,3,7,minecraft:glowstone)
B(-6,0,8,minecraft:glowstone)
B(-6,1,8,minecraft:glowstone)
B(-6,2,8,minecraft:glowstone)
B(-6,0,9,minecraft:glowstone)
B(-6,1,9,minecraft:glowstone)
B(-6,0,10,minecraft:glowstone)
B(-5,11,-10,minecraft:glowstone)
B(-5,7,-9,minecraft:glowstone)
B(-5,8,-9,minecraft:glowstone)
B(-5,9,-9,minecraft:glowstone)
B(-5,10,-9,minecraft:glowstone)
B(-5,11,-9,minecraft:glowstone)
B(-5,12,-9,minecraft:glowstone)
B(-5,3,-8,minecraft:glowstone)
B(-5,4,-8,minecraft:glowstone)
B(-5,5,-8,minecraft:glowstone)
B(-5,6,-8,minecraft:glowstone)
B(-5,7,-8,minecraft:glowstone)
B(-5,8,-8,minecraft:glowstone)
B(-5,9,-8,minecraft:glowstone)
B(-5,10,-8,minecraft:glowstone)
B(-5,11,-8,minecraft:glowstone)
B(-5,12,-8,minecraft:glowstone)
B(-5,0,-7,minecraft:glowstone)
B(-5,1,-7,minecraft:glowstone)
B(-5,2,-7,minecraft:glowstone)
B(-5,3,-7,minecraft:glowstone)
B(-5,4,-7,minecraft:glowstone)
B(-5,5,-7,minecraft:glowstone)
B(-5,6,-7,minecraft:glowstone)
B(-5,7,-7,minecraft:glowstone)
B(-5,8,-7,minecraft:glowstone)
B(-5,9,-7,minecraft:glowstone)
B(-5,10,-7,minecraft:glowstone)
B(-5,11,-7,minecraft:glowstone)
B(-5,12,-7,minecraft:glowstone)
B(-5,0,-6,minecraft:glowstone)
B(-5,1,-6,minecraft:glowstone)
B(-5,2,-6,minecraft:glowstone)
B(-5,3,-6,minecraft:glowstone)
B(-5,4,-6,minecraft:glowstone)
B(-5,5,-6,minecraft:glowstone)
B(-5,6,-6,minecraft:glowstone)
B(-5,7,-6,minecraft:glowstone)
B(-5,8,-6,minecraft:glowstone)
B(-5,9,-6,minecraft:glowstone)
B(-5,10,-6,minecraft:glowstone)
B(-5,11,-6,minecraft:glowstone)
B(-5,12,-6,minecraft:glowstone)
B(-5,0,-5,minecraft:glowstone)
B(-5,1,-5,minecraft:glowstone)
B(-5,2,-5,minecraft:glowstone)
B(-5,3,-5,minecraft:glowstone)
B(-5,4,-5,minecraft:glowstone)
B(-5,5,-5,minecraft:glowstone)
B(-5,6,-5,minecraft:glowstone)
B(-5,7,-5,minecraft:glowstone)
B(-5,8,-5,minecraft:glowstone)
B(-5,9,-5,minecraft:glowstone)
B(-5,10,-5,minecraft:glowstone)
B(-5,11,-5,minecraft:glowstone)
B(-5,0,-4,minecraft:glowstone)
B(-5,1,-4,minecraft:glowstone)
B(-5,2,-4,minecraft:glowstone)
B(-5,3,-4,minecraft:glowstone)
B(-5,4,-4,minecraft:glowstone)
B(-5,5,-4,minecraft:glowstone)
B(-5,6,-4,minecraft:glowstone)
B(-5,7,-4,minecraft:glowstone)
B(-5,8,-4,minecraft:glowstone)
B(-5,9,-4,minecraft:glowstone)
B(-5,10,-4,minecraft:glowstone)
B(-5,11,-4,minecraft:glowstone)
B(-5,0,-3,minecraft:glowstone)
B(-5,1,-3,minecraft:glowstone)
B(-5,2,-3,minecraft:glowstone)
B(-5,3,-3,minecraft:glowstone)
B(-5,4,-3,minecraft:glowstone)
B(-5,5,-3,minecraft:glowstone)
B(-5,6,-3,minecraft:glowstone)
B(-5,7,-3,minecraft:glowstone)
B(-5,8,-3,minecraft:glowstone)
B(-5,9,-3,minecraft:glowstone)
B(-5,10,-3,minecraft:glowstone)
B(-5,11,-3,minecraft:glowstone)
B(-5,0,-2,minecraft:glowstone)
B(-5,1,-2,minecraft:glowstone)
B(-5,2,-2,minecraft:glowstone)
B(-5,3,-2,minecraft:glowstone)
B(-5,4,-2,minecraft:glowstone)
B(-5,5,-2,minecraft:glowstone)
B(-5,6,-2,minecraft:glowstone)
B(-5,7,-2,minecraft:glowstone)
B(-5,8,-2,minecraft:glowstone)
B(-5,9,-2,minecraft:glowstone)
B(-5,10,-2,minecraft:glowstone)
B(-5,0,-1,minecraft:glowstone)
B(-5,1,-1,minecraft:glowstone)
B(-5,2,-1,minecraft:glowstone)
B(-5,3,-1,minecraft:glowstone)
B(-5,4,-1,minecraft:glowstone)
B(-5,5,-1,minecraft:glowstone)
B(-5,6,-1,minecraft:glowstone)
B(-5,7,-1,minecraft:glowstone)
B(-5,8,-1,minecraft:glowstone)
B(-5,9,-1,minecraft:glowstone)
B(-5,0,0,minecraft:glowstone)
B(-5,1,0,minecraft:glowstone)
B(-5,2,0,minecraft:glowstone)
B(-5,3,0,minecraft:glowstone)
B(-5,4,0,minecraft:glowstone)
B(-5,5,0,minecraft:glowstone)
B(-5,6,0,minecraft:glowstone)
B(-5,7,0,minecraft:glowstone)
B(-5,8,0,minecraft:glowstone)
B(-5,9,0,minecraft:glowstone)
B(-5,0,1,minecraft:glowstone)
B(-5,1,1,minecraft:glowstone)
B(-5,2,1,minecraft:glowstone)
B(-5,3,1,minecraft:glowstone)
B(-5,4,1,minecraft:glowstone)
B(-5,5,1,minecraft:glowstone)
B(-5,6,1,minecraft:glowstone)
B(-5,7,1,minecraft:glowstone)
B(-5,8,1,minecraft:glowstone)
B(-5,0,2,minecraft:glowstone)
B(-5,1,2,minecraft:glowstone)
B(-5,2,2,minecraft:glowstone)
B(-5,3,2,minecraft:glowstone)
B(-5,4,2,minecraft:glowstone)
B(-5,5,2,minecraft:glowstone)
B(-5,6,2,minecraft:glowstone)
B(-5,7,2,minecraft:glowstone)
B(-5,0,3,minecraft:glowstone)
B(-5,1,3,minecraft:glowstone)
B(-5,2,3,minecraft:glowstone)
B(-5,3,3,minecraft:glowstone)
B(-5,4,3,minecraft:glowstone)
B(-5,5,3,minecraft:glowstone)
B(-5,6,3,minecraft:glowstone)
B(-5,7,3,minecraft:glowstone)
B(-5,0,4,minecraft:glowstone)
B(-5,1,4,minecraft:glowstone)
B(-5,2,4,minecraft:glowstone)
B(-5,3,4,minecraft:glowstone)
B(-5,4,4,minecraft:glowstone)
B(-5,5,4,minecraft:glowstone)
B(-5,6,4,minecraft:glowstone)
B(-5,0,5,minecraft:glowstone)
B(-5,1,5,minecraft:glowstone)
B(-5,2,5,minecraft:glowstone)
B(-5,3,5,minecraft:glowstone)
B(-5,4,5,minecraft:glowstone)
B(-5,5,5,minecraft:glowstone)
B(-5,0,6,minecraft:glowstone)
B(-5,1,6,minecraft:glowstone)
B(-5,2,6,minecraft:glowstone)
B(-5,3,6,minecraft:glowstone)
B(-5,4,6,minecraft:glowstone)
B(-5,0,7,minecraft:glowstone)
B(-5,1,7,minecraft:glowstone)
B(-5,2,7,minecraft:glowstone)
B(-5,3,7,minecraft:glowstone)
B(-5,0,8,minecraft:glowstone)
B(-5,1,8,minecraft:glowstone)
B(-5,2,8,minecraft:glowstone)
B(-5,0,9,minecraft:glowstone)
B(-5,1,9,minecraft:glowstone)
B(-5,0,10,minecraft:glowstone)
B(-4,7,-9,minecraft:glowstone)
B(-4,8,-9,minecraft:glowstone)
B(-4,9,-9,minecraft:glowstone)
B(-4,10,-9,minecraft:glowstone)
B(-4,11,-9,minecraft:glowstone)
B(-4,4,-8,minecraft:glowstone)
B(-4,5,-8,minecraft:glowstone)
B(-4,6,-8,minecraft:glowstone)
B(-4,7,-8,minecraft:glowstone)
B(-4,8,-8,minecraft:glowstone)
B(-4,9,-8,minecraft:glowstone)
B(-4,10,-8,minecraft:glowstone)
B(-4,11,-8,minecraft:glowstone)
B(-4,12,-8,minecraft:glowstone)
B(-4,0,-7,minecraft:glowstone)
B(-4,1,-7,minecraft:glowstone)
B(-4,2,-7,minecraft:glowstone)
B(-4,3,-7,minecraft:glowstone)
B(-4,4,-7,minecraft:glowstone)
B(-4,5,-7,minecraft:glowstone)
B(-4,6,-7,minecraft:glowstone)
B(-4,7,-7,minecraft:glowstone)
B(-4,8,-7,minecraft:glowstone)
B(-4,9,-7,minecraft:glowstone)
B(-4,10,-7,minecraft:glowstone)
B(-4,11,-7,minecraft:glowstone)
B(-4,12,-7,minecraft:glowstone)
B(-4,0,-6,minecraft:glowstone)
B(-4,1,-6,minecraft:glowstone)
B(-4,2,-6,minecraft:glowstone)
B(-4,3,-6,minecraft:glowstone)
B(-4,4,-6,minecraft:glowstone)
B(-4,5,-6,minecraft:glowstone)
B(-4,6,-6,minecraft:glowstone)
B(-4,7,-6,minecraft:glowstone)
B(-4,8,-6,minecraft:glowstone)
B(-4,9,-6,minecraft:glowstone)
B(-4,10,-6,minecraft:glowstone)
B(-4,11,-6,minecraft:glowstone)
B(-4,12,-6,minecraft:glowstone)
B(-4,0,-5,minecraft:glowstone)
B(-4,1,-5,minecraft:glowstone)
B(-4,2,-5,minecraft:glowstone)
B(-4,3,-5,minecraft:glowstone)
B(-4,4,-5,minecraft:glowstone)
B(-4,5,-5,minecraft:glowstone)
B(-4,6,-5,minecraft:glowstone)
B(-4,7,-5,minecraft:glowstone)
B(-4,8,-5,minecraft:glowstone)
B(-4,9,-5,minecraft:glowstone)
B(-4,10,-5,minecraft:glowstone)
B(-4,11,-5,minecraft:glowstone)
B(-4,0,-4,minecraft:glowstone)
B(-4,1,-4,minecraft:glowstone)
B(-4,2,-4,minecraft:glowstone)
B(-4,3,-4,minecraft:glowstone)
B(-4,4,-4,minecraft:glowstone)
B(-4,5,-4,minecraft:glowstone)
B(-4,6,-4,minecraft:glowstone)
B(-4,7,-4,minecraft:glowstone)
B(-4,8,-4,minecraft:glowstone)
B(-4,9,-4,minecraft:glowstone)
B(-4,10,-4,minecraft:glowstone)
B(-4,11,-4,minecraft:glowstone)
B(-4,0,-3,minecraft:glowstone)
B(-4,1,-3,minecraft:glowstone)
B(-4,2,-3,minecraft:glowstone)
B(-4,3,-3,minecraft:glowstone)
B(-4,4,-3,minecraft:glowstone)
B(-4,5,-3,minecraft:glowstone)
B(-4,6,-3,minecraft:glowstone)
B(-4,7,-3,minecraft:glowstone)
B(-4,8,-3,minecraft:glowstone)
B(-4,9,-3,minecraft:glowstone)
B(-4,10,-3,minecraft:glowstone)
B(-4,0,-2,minecraft:glowstone)
B(-4,1,-2,minecraft:glowstone)
B(-4,2,-2,minecraft:glowstone)
B(-4,3,-2,minecraft:glowstone)
B(-4,4,-2,minecraft:glowstone)
B(-4,5,-2,minecraft:glowstone)
B(-4,6,-2,minecraft:glowstone)
B(-4,7,-2,minecraft:glowstone)
B(-4,8,-2,minecraft:glowstone)
B(-4,9,-2,minecraft:glowstone)
B(-4,10,-2,minecraft:glowstone)
B(-4,0,-1,minecraft:glowstone)
B(-4,1,-1,minecraft:glowstone)
B(-4,2,-1,minecraft:glowstone)
B(-4,3,-1,minecraft:glowstone)
B(-4,4,-1,minecraft:glowstone)
B(-4,5,-1,minecraft:glowstone)
B(-4,6,-1,minecraft:glowstone)
B(-4,7,-1,minecraft:glowstone)
B(-4,8,-1,minecraft:glowstone)
B(-4,9,-1,minecraft:glowstone)
B(-4,0,0,minecraft:glowstone)
B(-4,1,0,minecraft:glowstone)
B(-4,2,0,minecraft:glowstone)
B(-4,3,0,minecraft:glowstone)
B(-4,4,0,minecraft:glowstone)
B(-4,5,0,minecraft:glowstone)
B(-4,6,0,minecraft:glowstone)
B(-4,7,0,minecraft:glowstone)
B(-4,8,0,minecraft:glowstone)
B(-4,9,0,minecraft:glowstone)
B(-4,0,1,minecraft:glowstone)
B(-4,1,1,minecraft:glowstone)
B(-4,2,1,minecraft:glowstone)
B(-4,3,1,minecraft:glowstone)
B(-4,4,1,minecraft:glowstone)
B(-4,5,1,minecraft:glowstone)
B(-4,6,1,minecraft:glowstone)
B(-4,7,1,minecraft:glowstone)
B(-4,8,1,minecraft:glowstone)
B(-4,0,2,minecraft:glowstone)
B(-4,1,2,minecraft:glowstone)
B(-4,2,2,minecraft:glowstone)
B(-4,3,2,minecraft:glowstone)
B(-4,4,2,minecraft:glowstone)
B(-4,5,2,minecraft:glowstone)
B(-4,6,2,minecraft:glowstone)
B(-4,7,2,minecraft:glowstone)
B(-4,0,3,minecraft:glowstone)
B(-4,1,3,minecraft:glowstone)
B(-4,2,3,minecraft:glowstone)
B(-4,3,3,minecraft:glowstone)
B(-4,4,3,minecraft:glowstone)
B(-4,5,3,minecraft:glowstone)
B(-4,6,3,minecraft:glowstone)
B(-4,7,3,minecraft:glowstone)
B(-4,0,4,minecraft:glowstone)
B(-4,1,4,minecraft:glowstone)
B(-4,2,4,minecraft:glowstone)
B(-4,3,4,minecraft:glowstone)
B(-4,4,4,minecraft:glowstone)
B(-4,5,4,minecraft:glowstone)
B(-4,6,4,minecraft:glowstone)
B(-4,0,5,minecraft:glowstone)
B(-4,1,5,minecraft:glowstone)
B(-4,2,5,minecraft:glowstone)
B(-4,3,5,minecraft:glowstone)
B(-4,4,5,minecraft:glowstone)
B(-4,5,5,minecraft:glowstone)
B(-4,6,5,minecraft:glowstone)
B(-4,0,6,minecraft:glowstone)
B(-4,1,6,minecraft:glowstone)
B(-4,2,6,minecraft:glowstone)
B(-4,3,6,minecraft:glowstone)
B(-4,4,6,minecraft:glowstone)
B(-4,5,6,minecraft:glowstone)
B(-4,0,7,minecraft:glowstone)
B(-4,1,7,minecraft:glowstone)
B(-4,2,7,minecraft:glowstone)
B(-4,3,7,minecraft:glowstone)
B(-4,4,7,minecraft:glowstone)
B(-4,0,8,minecraft:glowstone)
B(-4,1,8,minecraft:glowstone)
B(-4,2,8,minecraft:glowstone)
B(-4,3,8,minecraft:glowstone)
B(-4,0,9,minecraft:glowstone)
B(-4,1,9,minecraft:glowstone)
B(-4,2,9,minecraft:glowstone)
B(-4,0,10,minecraft:glowstone)
B(-4,1,10,minecraft:glowstone)
B(-4,0,11,minecraft:glowstone)
B(-3,8,-9,minecraft:glowstone)
B(-3,9,-9,minecraft:glowstone)
B(-3,10,-9,minecraft:glowstone)
B(-3,4,-8,minecraft:glowstone)
B(-3,5,-8,minecraft:glowstone)
B(-3,6,-8,minecraft:glowstone)
B(-3,7,-8,minecraft:glowstone)
B(-3,8,-8,minecraft:glowstone)
B(-3,9,-8,minecraft:glowstone)
B(-3,10,-8,minecraft:glowstone)
B(-3,11,-8,minecraft:glowstone)
B(-3,1,-7,minecraft:glowstone)
B(-3,2,-7,minecraft:glowstone)
B(-3,3,-7,minecraft:glowstone)
B(-3,4,-7,minecraft:glowstone)
B(-3,5,-7,minecraft:glowstone)
B(-3,6,-7,minecraft:glowstone)
B(-3,7,-7,minecraft:glowstone)
B(-3,8,-7,minecraft:glowstone)
B(-3,9,-7,minecraft:glowstone)
B(-3,10,-7,minecraft:glowstone)
B(-3,11,-7,minecraft:glowstone)
B(-3,0,-6,minecraft:glowstone)
B(-3,1,-6,minecraft:glowstone)
B(-3,2,-6,minecraft:glowstone)
B(-3,3,-6,minecraft:glowstone)
B(-3,4,-6,minecraft:glowstone)
B(-3,5,-6,minecraft:glowstone)
B(-3,6,-6,minecraft:glowstone)
B(-3,7,-6,minecraft:glowstone)
B(-3,8,-6,minecraft:glowstone)
B(-3,9,-6,minecraft:glowstone)
B(-3,10,-6,minecraft:glowstone)
B(-3,11,-6,minecraft:glowstone)
B(-3,0,-5,minecraft:glowstone)
B(-3,1,-5,minecraft:glowstone)
B(-3,2,-5,minecraft:glowstone)
B(-3,3,-5,minecraft:glowstone)
B(-3,4,-5,minecraft:glowstone)
B(-3,5,-5,minecraft:glowstone)
B(-3,6,-5,minecraft:glowstone)
B(-3,7,-5,minecraft:glowstone)
B(-3,8,-5,minecraft:glowstone)
B(-3,9,-5,minecraft:glowstone)
B(-3,10,-5,minecraft:glowstone)
B(-3,11,-5,minecraft:glowstone)
B(-3,0,-4,minecraft:glowstone)
B(-3,1,-4,minecraft:glowstone)
B(-3,2,-4,minecraft:glowstone)
B(-3,3,-4,minecraft:glowstone)
B(-3,4,-4,minecraft:glowstone)
B(-3,5,-4,minecraft:glowstone)
B(-3,6,-4,minecraft:glowstone)
B(-3,7,-4,minecraft:glowstone)
B(-3,8,-4,minecraft:glowstone)
B(-3,9,-4,minecraft:glowstone)
B(-3,10,-4,minecraft:glowstone)
B(-3,0,-3,minecraft:glowstone)
B(-3,1,-3,minecraft:glowstone)
B(-3,2,-3,minecraft:glowstone)
B(-3,3,-3,minecraft:glowstone)
B(-3,4,-3,minecraft:glowstone)
B(-3,5,-3,minecraft:glowstone)
B(-3,6,-3,minecraft:glowstone)
B(-3,7,-3,minecraft:glowstone)
B(-3,8,-3,minecraft:glowstone)
B(-3,9,-3,minecraft:glowstone)
B(-3,10,-3,minecraft:glowstone)
B(-3,0,-2,minecraft:glowstone)
B(-3,1,-2,minecraft:glowstone)
B(-3,2,-2,minecraft:glowstone)
B(-3,3,-2,minecraft:glowstone)
B(-3,4,-2,minecraft:glowstone)
B(-3,5,-2,minecraft:glowstone)
B(-3,6,-2,minecraft:glowstone)
B(-3,7,-2,minecraft:glowstone)
B(-3,8,-2,minecraft:glowstone)
B(-3,9,-2,minecraft:glowstone)
B(-3,0,-1,minecraft:glowstone)
B(-3,1,-1,minecraft:glowstone)
B(-3,2,-1,minecraft:glowstone)
B(-3,3,-1,minecraft:glowstone)
B(-3,4,-1,minecraft:glowstone)
B(-3,5,-1,minecraft:glowstone)
B(-3,6,-1,minecraft:glowstone)
B(-3,7,-1,minecraft:glowstone)
B(-3,8,-1,minecraft:glowstone)
B(-3,9,-1,minecraft:glowstone)
B(-3,0,0,minecraft:glowstone)
B(-3,1,0,minecraft:glowstone)
B(-3,2,0,minecraft:glowstone)
B(-3,3,0,minecraft:glowstone)
B(-3,4,0,minecraft:glowstone)
B(-3,5,0,minecraft:glowstone)
B(-3,6,0,minecraft:glowstone)
B(-3,7,0,minecraft:glowstone)
B(-3,8,0,minecraft:glowstone)
B(-3,0,1,minecraft:glowstone)
B(-3,1,1,minecraft:glowstone)
B(-3,2,1,minecraft:glowstone)
B(-3,3,1,minecraft:glowstone)
B(-3,4,1,minecraft:glowstone)
B(-3,5,1,minecraft:glowstone)
B(-3,6,1,minecraft:glowstone)
B(-3,7,1,minecraft:glowstone)
B(-3,8,1,minecraft:glowstone)
B(-3,0,2,minecraft:glowstone)
B(-3,1,2,minecraft:glowstone)
B(-3,2,2,minecraft:glowstone)
B(-3,3,2,minecraft:glowstone)
B(-3,4,2,minecraft:glowstone)
B(-3,5,2,minecraft:glowstone)
B(-3,6,2,minecraft:glowstone)
B(-3,7,2,minecraft:glowstone)
B(-3,0,3,minecraft:glowstone)
B(-3,1,3,minecraft:glowstone)
B(-3,2,3,minecraft:glowstone)
B(-3,3,3,minecraft:glowstone)
B(-3,4,3,minecraft:glowstone)
B(-3,5,3,minecraft:glowstone)
B(-3,6,3,minecraft:glowstone)
B(-3,7,3,minecraft:glowstone)
B(-3,0,4,minecraft:glowstone)
B(-3,1,4,minecraft:glowstone)
B(-3,2,4,minecraft:glowstone)
B(-3,3,4,minecraft:glowstone)
B(-3,4,4,minecraft:glowstone)
B(-3,5,4,minecraft:glowstone)
B(-3,6,4,minecraft:glowstone)
B(-3,0,5,minecraft:glowstone)
B(-3,1,5,minecraft:glowstone)
B(-3,2,5,minecraft:glowstone)
B(-3,3,5,minecraft:glowstone)
B(-3,4,5,minecraft:glowstone)
B(-3,5,5,minecraft:glowstone)
B(-3,0,6,minecraft:glowstone)
B(-3,1,6,minecraft:glowstone)
B(-3,2,6,minecraft:glowstone)
B(-3,3,6,minecraft:glowstone)
B(-3,4,6,minecraft:glowstone)
B(-3,5,6,minecraft:glowstone)
B(-3,0,7,minecraft:glowstone)
B(-3,1,7,minecraft:glowstone)
B(-3,2,7,minecraft:glowstone)
B(-3,3,7,minecraft:glowstone)
B(-3,4,7,minecraft:glowstone)
B(-3,0,8,minecraft:glowstone)
B(-3,1,8,minecraft:glowstone)
B(-3,2,8,minecraft:glowstone)
B(-3,3,8,minecraft:glowstone)
B(-3,4,8,minecraft:glowstone)
B(-3,0,9,minecraft:glowstone)
B(-3,1,9,minecraft:glowstone)
B(-3,2,9,minecraft:glowstone)
B(-3,3,9,minecraft:glowstone)
B(-3,0,10,minecraft:glowstone)
B(-3,1,10,minecraft:glowstone)
B(-3,2,10,minecraft:glowstone)
B(-3,0,11,minecraft:glowstone)
B(-3,1,11,minecraft:glowstone)
B(-3,0,12,minecraft:glowstone)
B(-2,5,-8,minecraft:glowstone)
B(-2,6,-8,minecraft:glowstone)
B(-2,7,-8,minecraft:glowstone)
B(-2,8,-8,minecraft:glowstone)
B(-2,9,-8,minecraft:glowstone)
B(-2,10,-8,minecraft:glowstone)
B(-2,1,-7,minecraft:glowstone)
B(-2,2,-7,minecraft:glowstone)
B(-2,3,-7,minecraft:glowstone)
B(-2,4,-7,minecraft:glowstone)
B(-2,5,-7,minecraft:glowstone)
B(-2,6,-7,minecraft:glowstone)
B(-2,7,-7,minecraft:glowstone)
B(-2,8,-7,minecraft:glowstone)
B(-2,9,-7,minecraft:glowstone)
B(-2,10,-7,minecraft:glowstone)
B(-2,0,-6,minecraft:glowstone)
B(-2,1,-6,minecraft:glowstone)
B(-2,2,-6,minecraft:glowstone)
B(-2,3,-6,minecraft:glowstone)
B(-2,4,-6,minecraft:glowstone)
B(-2,5,-6,minecraft:glowstone)
B(-2,6,-6,minecraft:glowstone)
B(-2,7,-6,minecraft:glowstone)
B(-2,8,-6,minecraft:glowstone)
B(-2,9,-6,minecraft:glowstone)
B(-2,10,-6,minecraft:glowstone)
B(-2,0,-5,minecraft:glowstone)
B(-2,1,-5,minecraft:glowstone)
B(-2,2,-5,minecraft:glowstone)
B(-2,3,-5,minecraft:glowstone)
B(-2,4,-5,minecraft:glowstone)
B(-2,5,-5,minecraft:glowstone)
B(-2,6,-5,minecraft:glowstone)
B(-2,7,-5,minecraft:glowstone)
B(-2,8,-5,minecraft:glowstone)
B(-2,9,-5,minecraft:glowstone)
B(-2,10,-5,minecraft:glowstone)
B(-2,0,-4,minecraft:glowstone)
B(-2,1,-4,minecraft:glowstone)
B(-2,2,-4,minecraft:glowstone)
B(-2,3,-4,minecraft:glowstone)
B(-2,4,-4,minecraft:glowstone)
B(-2,5,-4,minecraft:glowstone)
B(-2,6,-4,minecraft:glowstone)
B(-2,7,-4,minecraft:glowstone)
B(-2,8,-4,minecraft:glowstone)
B(-2,9,-4,minecraft:glowstone)
B(-2,10,-4,minecraft:glowstone)
B(-2,0,-3,minecraft:glowstone)
B(-2,1,-3,minecraft:glowstone)
B(-2,2,-3,minecraft:glowstone)
B(-2,3,-3,minecraft:glowstone)
B(-2,4,-3,minecraft:glowstone)
B(-2,5,-3,minecraft:glowstone)
B(-2,6,-3,minecraft:glowstone)
B(-2,7,-3,minecraft:glowstone)
B(-2,8,-3,minecraft:glowstone)
B(-2,9,-3,minecraft:glowstone)
B(-2,10,-3,minecraft:glowstone)
B(-2,0,-2,minecraft:glowstone)
B(-2,1,-2,minecraft:glowstone)
B(-2,2,-2,minecraft:glowstone)
B(-2,3,-2,minecraft:glowstone)
B(-2,4,-2,minecraft:glowstone)
B(-2,5,-2,minecraft:glowstone)
B(-2,6,-2,minecraft:glowstone)
B(-2,7,-2,minecraft:glowstone)
B(-2,8,-2,minecraft:glowstone)
B(-2,9,-2,minecraft:glowstone)
B(-2,0,-1,minecraft:glowstone)
B(-2,1,-1,minecraft:glowstone)
B(-2,2,-1,minecraft:glowstone)
B(-2,3,-1,minecraft:glowstone)
B(-2,4,-1,minecraft:glowstone)
B(-2,5,-1,minecraft:glowstone)
B(-2,6,-1,minecraft:glowstone)
B(-2,7,-1,minecraft:glowstone)
B(-2,8,-1,minecraft:glowstone)
B(-2,9,-1,minecraft:glowstone)
B(-2,0,0,minecraft:glowstone)
B(-2,1,0,minecraft:glowstone)
B(-2,2,0,minecraft:glowstone)
B(-2,3,0,minecraft:glowstone)
B(-2,4,0,minecraft:glowstone)
B(-2,5,0,minecraft:glowstone)
B(-2,6,0,minecraft:glowstone)
B(-2,7,0,minecraft:glowstone)
B(-2,8,0,minecraft:glowstone)
B(-2,0,1,minecraft:glowstone)
B(-2,1,1,minecraft:glowstone)
B(-2,2,1,minecraft:glowstone)
B(-2,3,1,minecraft:glowstone)
B(-2,4,1,minecraft:glowstone)
B(-2,5,1,minecraft:glowstone)
B(-2,6,1,minecraft:glowstone)
B(-2,7,1,minecraft:glowstone)
B(-2,8,1,minecraft:glowstone)
B(-2,0,2,minecraft:glowstone)
B(-2,1,2,minecraft:glowstone)
B(-2,2,2,minecraft:glowstone)
B(-2,3,2,minecraft:glowstone)
B(-2,4,2,minecraft:glowstone)
B(-2,5,2,minecraft:glowstone)
B(-2,6,2,minecraft:glowstone)
B(-2,7,2,minecraft:glowstone)
B(-2,0,3,minecraft:glowstone)
B(-2,1,3,minecraft:glowstone)
B(-2,2,3,minecraft:glowstone)
B(-2,3,3,minecraft:glowstone)
B(-2,4,3,minecraft:glowstone)
B(-2,5,3,minecraft:glowstone)
B(-2,6,3,minecraft:glowstone)
B(-2,0,4,minecraft:glowstone)
B(-2,1,4,minecraft:glowstone)
B(-2,2,4,minecraft:glowstone)
B(-2,3,4,minecraft:glowstone)
B(-2,4,4,minecraft:glowstone)
B(-2,5,4,minecraft:glowstone)
B(-2,6,4,minecraft:glowstone)
B(-2,0,5,minecraft:glowstone)
B(-2,1,5,minecraft:glowstone)
B(-2,2,5,minecraft:glowstone)
B(-2,3,5,minecraft:glowstone)
B(-2,4,5,minecraft:glowstone)
B(-2,5,5,minecraft:glowstone)
B(-2,0,6,minecraft:glowstone)
B(-2,1,6,minecraft:glowstone)
B(-2,2,6,minecraft:glowstone)
B(-2,3,6,minecraft:glowstone)
B(-2,4,6,minecraft:glowstone)
B(-2,5,6,minecraft:glowstone)
B(-2,0,7,minecraft:glowstone)
B(-2,1,7,minecraft:glowstone)
B(-2,2,7,minecraft:glowstone)
B(-2,3,7,minecraft:glowstone)
B(-2,4,7,minecraft:glowstone)
B(-2,0,8,minecraft:glowstone)
B(-2,1,8,minecraft:glowstone)
B(-2,2,8,minecraft:glowstone)
B(-2,3,8,minecraft:glowstone)
B(-2,0,9,minecraft:glowstone)
B(-2,1,9,minecraft:glowstone)
B(-2,2,9,minecraft:glowstone)
B(-2,3,9,minecraft:glowstone)
B(-2,0,10,minecraft:glowstone)
B(-2,1,10,minecraft:glowstone)
B(-2,2,10,minecraft:glowstone)
B(-2,0,11,minecraft:glowstone)
B(-2,1,11,minecraft:glowstone)
B(-2,0,12,minecraft:glowstone)
B(-1,6,-8,minecraft:glowstone)
B(-1,7,-8,minecraft:glowstone)
B(-1,8,-8,minecraft:glowstone)
B(-1,9,-8,minecraft:glowstone)
B(-1,2,-7,minecraft:glowstone)
B(-1,3,-7,minecraft:glowstone)
B(-1,4,-7,minecraft:glowstone)
B(-1,5,-7,minecraft:glowstone)
B(-1,6,-7,minecraft:glowstone)
B(-1,7,-7,minecraft:glowstone)
B(-1,8,-7,minecraft:glowstone)
B(-1,9,-7,minecraft:glowstone)
B(-1,0,-6,minecraft:glowstone)
B(-1,1,-6,minecraft:glowstone)
B(-1,2,-6,minecraft:glowstone)
B(-1,3,-6,minecraft:glowstone)
B(-1,4,-6,minecraft:glowstone)
B(-1,5,-6,minecraft:glowstone)
B(-1,6,-6,minecraft:glowstone)
B(-1,7,-6,minecraft:glowstone)
B(-1,8,-6,minecraft:glowstone)
B(-1,9,-6,minecraft:glowstone)
B(-1,10,-6,minecraft:glowstone)
B(-1,0,-5,minecraft:glowstone)
B(-1,1,-5,minecraft:glowstone)
B(-1,2,-5,minecraft:glowstone)
B(-1,3,-5,minecraft:glowstone)
B(-1,4,-5,minecraft:glowstone)
B(-1,5,-5,minecraft:glowstone)
B(-1,6,-5,minecraft:glowstone)
B(-1,7,-5,minecraft:glowstone)
B(-1,8,-5,minecraft:glowstone)
B(-1,9,-5,minecraft:glowstone)
B(-1,10,-5,minecraft:glowstone)
B(-1,0,-4,minecraft:glowstone)
B(-1,1,-4,minecraft:glowstone)
B(-1,2,-4,minecraft:glowstone)
B(-1,3,-4,minecraft:glowstone)
B(-1,4,-4,minecraft:glowstone)
B(-1,5,-4,minecraft:glowstone)
B(-1,6,-4,minecraft:glowstone)
B(-1,7,-4,minecraft:glowstone)
B(-1,8,-4,minecraft:glowstone)
B(-1,9,-4,minecraft:glowstone)
B(-1,10,-4,minecraft:glowstone)
B(-1,0,-3,minecraft:glowstone)
B(-1,1,-3,minecraft:glowstone)
B(-1,2,-3,minecraft:glowstone)
B(-1,3,-3,minecraft:glowstone)
B(-1,4,-3,minecraft:glowstone)
B(-1,5,-3,minecraft:glowstone)
B(-1,6,-3,minecraft:glowstone)
B(-1,7,-3,minecraft:glowstone)
B(-1,8,-3,minecraft:glowstone)
B(-1,9,-3,minecraft:glowstone)
B(-1,0,-2,minecraft:glowstone)
B(-1,1,-2,minecraft:glowstone)
B(-1,2,-2,minecraft:glowstone)
B(-1,3,-2,minecraft:glowstone)
B(-1,4,-2,minecraft:glowstone)
B(-1,5,-2,minecraft:glowstone)
B(-1,6,-2,minecraft:glowstone)
B(-1,7,-2,minecraft:glowstone)
B(-1,8,-2,minecraft:glowstone)
B(-1,9,-2,minecraft:glowstone)
B(-1,0,-1,minecraft:glowstone)
B(-1,1,-1,minecraft:glowstone)
B(-1,2,-1,minecraft:glowstone)
B(-1,3,-1,minecraft:glowstone)
B(-1,4,-1,minecraft:glowstone)
B(-1,5,-1,minecraft:glowstone)
B(-1,6,-1,minecraft:glowstone)
B(-1,7,-1,minecraft:glowstone)
B(-1,8,-1,minecraft:glowstone)
B(-1,0,0,minecraft:glowstone)
B(-1,1,0,minecraft:glowstone)
B(-1,2,0,minecraft:glowstone)
B(-1,3,0,minecraft:glowstone)
B(-1,4,0,minecraft:glowstone)
B(-1,5,0,minecraft:glowstone)
B(-1,6,0,minecraft:glowstone)
B(-1,7,0,minecraft:glowstone)
B(-1,8,0,minecraft:glowstone)
B(-1,0,1,minecraft:glowstone)
B(-1,1,1,minecraft:glowstone)
B(-1,2,1,minecraft:glowstone)
B(-1,3,1,minecraft:glowstone)
B(-1,4,1,minecraft:glowstone)
B(-1,5,1,minecraft:glowstone)
B(-1,6,1,minecraft:glowstone)
B(-1,7,1,minecraft:glowstone)
B(-1,0,2,minecraft:glowstone)
B(-1,1,2,minecraft:glowstone)
B(-1,2,2,minecraft:glowstone)
B(-1,3,2,minecraft:glowstone)
B(-1,4,2,minecraft:glowstone)
B(-1,5,2,minecraft:glowstone)
B(-1,6,2,minecraft:glowstone)
B(-1,7,2,minecraft:glowstone)
B(-1,0,3,minecraft:glowstone)
B(-1,1,3,minecraft:glowstone)
B(-1,2,3,minecraft:glowstone)
B(-1,3,3,minecraft:glowstone)
B(-1,4,3,minecraft:glowstone)
B(-1,5,3,minecraft:glowstone)
B(-1,6,3,minecraft:glowstone)
B(-1,0,4,minecraft:glowstone)
B(-1,1,4,minecraft:glowstone)
B(-1,2,4,minecraft:glowstone)
B(-1,3,4,minecraft:glowstone)
B(-1,4,4,minecraft:glowstone)
B(-1,5,4,minecraft:glowstone)
B(-1,6,4,minecraft:glowstone)
B(-1,0,5,minecraft:glowstone)
B(-1,1,5,minecraft:glowstone)
B(-1,2,5,minecraft:glowstone)
B(-1,3,5,minecraft:glowstone)
B(-1,4,5,minecraft:glowstone)
B(-1,5,5,minecraft:glowstone)
B(-1,0,6,minecraft:glowstone)
B(-1,1,6,minecraft:glowstone)
B(-1,2,6,minecraft:glowstone)
B(-1,3,6,minecraft:glowstone)
B(-1,4,6,minecraft:glowstone)
B(-1,0,7,minecraft:glowstone)
B(-1,1,7,minecraft:glowstone)
B(-1,2,7,minecraft:glowstone)
B(-1,3,7,minecraft:glowstone)
B(-1,4,7,minecraft:glowstone)
B(-1,0,8,minecraft:glowstone)
B(-1,1,8,minecraft:glowstone)
B(-1,2,8,minecraft:glowstone)
B(-1,3,8,minecraft:glowstone)
B(-1,0,9,minecraft:glowstone)
B(-1,1,9,minecraft:glowstone)
B(-1,2,9,minecraft:glowstone)
B(-1,3,9,minecraft:glowstone)
B(-1,0,10,minecraft:glowstone)
B(-1,1,10,minecraft:glowstone)
B(-1,2,10,minecraft:glowstone)
B(-1,0,11,minecraft:glowstone)
B(-1,1,11,minecraft:glowstone)
B(-1,0,12,minecraft:glowstone)
B(-1,1,12,minecraft:glowstone)
B(-1,0,13,minecraft:glowstone)
B(0,6,-8,minecraft:glowstone)
B(0,7,-8,minecraft:glowstone)
B(0,3,-7,minecraft:glowstone)
B(0,4,-7,minecraft:glowstone)
B(0,5,-7,minecraft:glowstone)
B(0,6,-7,minecraft:glowstone)
B(0,7,-7,minecraft:glowstone)
B(0,8,-7,minecraft:glowstone)
B(0,9,-7,minecraft:glowstone)
B(0,0,-6,minecraft:glowstone)
B(0,1,-6,minecraft:glowstone)
B(0,2,-6,minecraft:glowstone)
B(0,3,-6,minecraft:glowstone)
B(0,4,-6,minecraft:glowstone)
B(0,5,-6,minecraft:glowstone)
B(0,6,-6,minecraft:glowstone)
B(0,7,-6,minecraft:glowstone)
B(0,8,-6,minecraft:glowstone)
B(0,9,-6,minecraft:glowstone)
B(0,0,-5,minecraft:glowstone)
B(0,1,-5,minecraft:glowstone)
B(0,2,-5,minecraft:glowstone)
B(0,3,-5,minecraft:glowstone)
B(0,4,-5,minecraft:glowstone)
B(0,5,-5,minecraft:glowstone)
B(0,6,-5,minecraft:glowstone)
B(0,7,-5,minecraft:glowstone)
B(0,8,-5,minecraft:glowstone)
B(0,9,-5,minecraft:glowstone)
B(0,0,-4,minecraft:glowstone)
B(0,1,-4,minecraft:glowstone)
B(0,2,-4,minecraft:glowstone)
B(0,3,-4,minecraft:glowstone)
B(0,4,-4,minecraft:glowstone)
B(0,5,-4,minecraft:glowstone)
B(0,6,-4,minecraft:glowstone)
B(0,7,-4,minecraft:glowstone)
B(0,8,-4,minecraft:glowstone)
B(0,9,-4,minecraft:glowstone)
B(0,0,-3,minecraft:glowstone)
B(0,1,-3,minecraft:glowstone)
B(0,2,-3,minecraft:glowstone)
B(0,3,-3,minecraft:glowstone)
B(0,4,-3,minecraft:glowstone)
B(0,5,-3,minecraft:glowstone)
B(0,6,-3,minecraft:glowstone)
B(0,7,-3,minecraft:glowstone)
B(0,8,-3,minecraft:glowstone)
B(0,9,-3,minecraft:glowstone)
B(0,0,-2,minecraft:glowstone)
B(0,1,-2,minecraft:glowstone)
B(0,2,-2,minecraft:glowstone)
B(0,3,-2,minecraft:glowstone)
B(0,4,-2,minecraft:glowstone)
B(0,5,-2,minecraft:glowstone)
B(0,6,-2,minecraft:glowstone)
B(0,7,-2,minecraft:glowstone)
B(0,8,-2,minecraft:glowstone)
B(0,0,-1,minecraft:glowstone)
B(0,1,-1,minecraft:glowstone)
B(0,2,-1,minecraft:glowstone)
B(0,3,-1,minecraft:glowstone)
B(0,4,-1,minecraft:glowstone)
B(0,5,-1,minecraft:glowstone)
B(0,6,-1,minecraft:glowstone)
B(0,7,-1,minecraft:glowstone)
B(0,8,-1,minecraft:glowstone)
B(0,0,0,minecraft:glowstone)
B(0,1,0,minecraft:glowstone)
B(0,2,0,minecraft:glowstone)
B(0,3,0,minecraft:glowstone)
B(0,4,0,minecraft:glowstone)
B(0,5,0,minecraft:glowstone)
B(0,6,0,minecraft:glowstone)
B(0,7,0,minecraft:glowstone)
B(0,8,0,minecraft:glowstone)
B(0,0,1,minecraft:glowstone)
B(0,1,1,minecraft:glowstone)
B(0,2,1,minecraft:glowstone)
B(0,3,1,minecraft:glowstone)
B(0,4,1,minecraft:glowstone)
B(0,5,1,minecraft:glowstone)
B(0,6,1,minecraft:glowstone)
B(0,7,1,minecraft:glowstone)
B(0,0,2,minecraft:glowstone)
B(0,1,2,minecraft:glowstone)
B(0,2,2,minecraft:glowstone)
B(0,3,2,minecraft:glowstone)
B(0,4,2,minecraft:glowstone)
B(0,5,2,minecraft:glowstone)
B(0,6,2,minecraft:glowstone)
B(0,7,2,minecraft:glowstone)
B(0,0,3,minecraft:glowstone)
B(0,1,3,minecraft:glowstone)
B(0,2,3,minecraft:glowstone)
B(0,3,3,minecraft:glowstone)
B(0,4,3,minecraft:glowstone)
B(0,5,3,minecraft:glowstone)
B(0,6,3,minecraft:glowstone)
B(0,0,4,minecraft:glowstone)
B(0,1,4,minecraft:glowstone)
B(0,2,4,minecraft:glowstone)
B(0,3,4,minecraft:glowstone)
B(0,4,4,minecraft:glowstone)
B(0,5,4,minecraft:glowstone)
B(0,6,4,minecraft:glowstone)
B(0,0,5,minecraft:glowstone)
B(0,1,5,minecraft:glowstone)
B(0,2,5,minecraft:glowstone)
B(0,3,5,minecraft:glowstone)
B(0,4,5,minecraft:glowstone)
B(0,5,5,minecraft:glowstone)
B(0,0,6,minecraft:glowstone)
B(0,1,6,minecraft:glowstone)
B(0,2,6,minecraft:glowstone)
B(0,3,6,minecraft:glowstone)
B(0,4,6,minecraft:glowstone)
B(0,0,7,minecraft:glowstone)
B(0,1,7,minecraft:glowstone)
B(0,2,7,minecraft:glowstone)
B(0,3,7,minecraft:glowstone)
B(0,4,7,minecraft:glowstone)
B(0,0,8,minecraft:glowstone)
B(0,1,8,minecraft:glowstone)
B(0,2,8,minecraft:glowstone)
B(0,3,8,minecraft:glowstone)
B(0,0,9,minecraft:glowstone)
B(0,1,9,minecraft:glowstone)
B(0,2,9,minecraft:glowstone)
B(0,3,9,minecraft:glowstone)
B(0,0,10,minecraft:glowstone)
B(0,1,10,minecraft:glowstone)
B(0,2,10,minecraft:glowstone)
B(0,0,11,minecraft:glowstone)
B(0,1,11,minecraft:glowstone)
B(0,0,12,minecraft:glowstone)
B(0,1,12,minecraft:glowstone)
B(0,0,13,minecraft:glowstone)
B(0,0,14,minecraft:glowstone)
B(1,3,-7,minecraft:glowstone)
B(1,4,-7,minecraft:glowstone)
B(1,5,-7,minecraft:glowstone)
B(1,6,-7,minecraft:glowstone)
B(1,7,-7,minecraft:glowstone)
B(1,0,-6,minecraft:glowstone)
B(1,1,-6,minecraft:glowstone)
B(1,2,-6,minecraft:glowstone)
B(1,3,-6,minecraft:glowstone)
B(1,4,-6,minecraft:glowstone)
B(1,5,-6,minecraft:glowstone)
B(1,6,-6,minecraft:glowstone)
B(1,7,-6,minecraft:glowstone)
B(1,8,-6,minecraft:glowstone)
B(1,0,-5,minecraft:glowstone)
B(1,1,-5,minecraft:glowstone)
B(1,2,-5,minecraft:glowstone)
B(1,3,-5,minecraft:glowstone)
B(1,4,-5,minecraft:glowstone)
B(1,5,-5,minecraft:glowstone)
B(1,6,-5,minecraft:glowstone)
B(1,7,-5,minecraft:glowstone)
B(1,8,-5,minecraft:glowstone)
B(1,0,-4,minecraft:glowstone)
B(1,1,-4,minecraft:glowstone)
B(1,2,-4,minecraft:glowstone)
B(1,3,-4,minecraft:glowstone)
B(1,4,-4,minecraft:glowstone)
B(1,5,-4,minecraft:glowstone)
B(1,6,-4,minecraft:glowstone)
B(1,7,-4,minecraft:glowstone)
B(1,8,-4,minecraft:glowstone)
B(1,0,-3,minecraft:glowstone)
B(1,1,-3,minecraft:glowstone)
B(1,2,-3,minecraft:glowstone)
B(1,3,-3,minecraft:glowstone)
B(1,4,-3,minecraft:glowstone)
B(1,5,-3,minecraft:glowstone)
B(1,6,-3,minecraft:glowstone)
B(1,7,-3,minecraft:glowstone)
B(1,8,-3,minecraft:glowstone)
B(1,0,-2,minecraft:glowstone)
B(1,1,-2,minecraft:glowstone)
B(1,2,-2,minecraft:glowstone)
B(1,3,-2,minecraft:glowstone)
B(1,4,-2,minecraft:glowstone)
B(1,5,-2,minecraft:glowstone)
B(1,6,-2,minecraft:glowstone)
B(1,7,-2,minecraft:glowstone)
B(1,8,-2,minecraft:glowstone)
B(1,0,-1,minecraft:glowstone)
B(1,1,-1,minecraft:glowstone)
B(1,2,-1,minecraft:glowstone)
B(1,3,-1,minecraft:glowstone)
B(1,4,-1,minecraft:glowstone)
B(1,5,-1,minecraft:glowstone)
B(1,6,-1,minecraft:glowstone)
B(1,7,-1,minecraft:glowstone)
B(1,8,-1,minecraft:glowstone)
B(1,0,0,minecraft:glowstone)
B(1,1,0,minecraft:glowstone)
B(1,2,0,minecraft:glowstone)
B(1,3,0,minecraft:glowstone)
B(1,4,0,minecraft:glowstone)
B(1,5,0,minecraft:glowstone)
B(1,6,0,minecraft:glowstone)
B(1,7,0,minecraft:glowstone)
B(1,0,1,minecraft:glowstone)
B(1,1,1,minecraft:glowstone)
B(1,2,1,minecraft:glowstone)
B(1,3,1,minecraft:glowstone)
B(1,4,1,minecraft:glowstone)
B(1,5,1,minecraft:glowstone)
B(1,6,1,minecraft:glowstone)
B(1,7,1,minecraft:glowstone)
B(1,0,2,minecraft:glowstone)
B(1,1,2,minecraft:glowstone)
B(1,2,2,minecraft:glowstone)
B(1,3,2,minecraft:glowstone)
B(1,4,2,minecraft:glowstone)
B(1,5,2,minecraft:glowstone)
B(1,6,2,minecraft:glowstone)
B(1,0,3,minecraft:glowstone)
B(1,1,3,minecraft:glowstone)
B(1,2,3,minecraft:glowstone)
B(1,3,3,minecraft:glowstone)
B(1,4,3,minecraft:glowstone)
B(1,5,3,minecraft:glowstone)
B(1,6,3,minecraft:glowstone)
B(1,0,4,minecraft:glowstone)
B(1,1,4,minecraft:glowstone)
B(1,2,4,minecraft:glowstone)
B(1,3,4,minecraft:glowstone)
B(1,4,4,minecraft:glowstone)
B(1,5,4,minecraft:glowstone)
B(1,0,5,minecraft:glowstone)
B(1,1,5,minecraft:glowstone)
B(1,2,5,minecraft:glowstone)
B(1,3,5,minecraft:glowstone)
B(1,4,5,minecraft:glowstone)
B(1,5,5,minecraft:glowstone)
B(1,0,6,minecraft:glowstone)
B(1,1,6,minecraft:glowstone)
B(1,2,6,minecraft:glowstone)
B(1,3,6,minecraft:glowstone)
B(1,4,6,minecraft:glowstone)
B(1,0,7,minecraft:glowstone)
B(1,1,7,minecraft:glowstone)
B(1,2,7,minecraft:glowstone)
B(1,3,7,minecraft:glowstone)
B(1,4,7,minecraft:glowstone)
B(1,0,8,minecraft:glowstone)
B(1,1,8,minecraft:glowstone)
B(1,2,8,minecraft:glowstone)
B(1,3,8,minecraft:glowstone)
B(1,0,9,minecraft:glowstone)
B(1,1,9,minecraft:glowstone)
B(1,2,9,minecraft:glowstone)
B(1,0,10,minecraft:glowstone)
B(1,1,10,minecraft:glowstone)
B(1,2,10,minecraft:glowstone)
B(1,0,11,minecraft:glowstone)
B(1,1,11,minecraft:glowstone)
B(1,0,12,minecraft:glowstone)
B(1,1,12,minecraft:glowstone)
B(1,0,13,minecraft:glowstone)
B(2,4,-7,minecraft:glowstone)
B(2,5,-7,minecraft:glowstone)
B(2,6,-7,minecraft:glowstone)
B(2,0,-6,minecraft:glowstone)
B(2,1,-6,minecraft:glowstone)
B(2,2,-6,minecraft:glowstone)
B(2,3,-6,minecraft:glowstone)
B(2,4,-6,minecraft:glowstone)
B(2,5,-6,minecraft:glowstone)
B(2,6,-6,minecraft:glowstone)
B(2,7,-6,minecraft:glowstone)
B(2,0,-5,minecraft:glowstone)
B(2,1,-5,minecraft:glowstone)
B(2,2,-5,minecraft:glowstone)
B(2,3,-5,minecraft:glowstone)
B(2,4,-5,minecraft:glowstone)
B(2,5,-5,minecraft:glowstone)
B(2,6,-5,minecraft:glowstone)
B(2,7,-5,minecraft:glowstone)
B(2,0,-4,minecraft:glowstone)
B(2,1,-4,minecraft:glowstone)
B(2,2,-4,minecraft:glowstone)
B(2,3,-4,minecraft:glowstone)
B(2,4,-4,minecraft:glowstone)
B(2,5,-4,minecraft:glowstone)
B(2,6,-4,minecraft:glowstone)
B(2,7,-4,minecraft:glowstone)
B(2,0,-3,minecraft:glowstone)
B(2,1,-3,minecraft:glowstone)
B(2,2,-3,minecraft:glowstone)
B(2,3,-3,minecraft:glowstone)
B(2,4,-3,minecraft:glowstone)
B(2,5,-3,minecraft:glowstone)
B(2,6,-3,minecraft:glowstone)
B(2,7,-3,minecraft:glowstone)
B(2,8,-3,minecraft:glowstone)
B(2,0,-2,minecraft:glowstone)
B(2,1,-2,minecraft:glowstone)
B(2,2,-2,minecraft:glowstone)
B(2,3,-2,minecraft:glowstone)
B(2,4,-2,minecraft:glowstone)
B(2,5,-2,minecraft:glowstone)
B(2,6,-2,minecraft:glowstone)
B(2,7,-2,minecraft:glowstone)
B(2,8,-2,minecraft:glowstone)
B(2,0,-1,minecraft:glowstone)
B(2,1,-1,minecraft:glowstone)
B(2,2,-1,minecraft:glowstone)
B(2,3,-1,minecraft:glowstone)
B(2,4,-1,minecraft:glowstone)
B(2,5,-1,minecraft:glowstone)
B(2,6,-1,minecraft:glowstone)
B(2,7,-1,minecraft:glowstone)
B(2,0,0,minecraft:glowstone)
B(2,1,0,minecraft:glowstone)
B(2,2,0,minecraft:glowstone)
B(2,3,0,minecraft:glowstone)
B(2,4,0,minecraft:glowstone)
B(2,5,0,minecraft:glowstone)
B(2,6,0,minecraft:glowstone)
B(2,7,0,minecraft:glowstone)
B(2,0,1,minecraft:glowstone)
B(2,1,1,minecraft:glowstone)
B(2,2,1,minecraft:glowstone)
B(2,3,1,minecraft:glowstone)
B(2,4,1,minecraft:glowstone)
B(2,5,1,minecraft:glowstone)
B(2,6,1,minecraft:glowstone)
B(2,0,2,minecraft:glowstone)
B(2,1,2,minecraft:glowstone)
B(2,2,2,minecraft:glowstone)
B(2,3,2,minecraft:glowstone)
B(2,4,2,minecraft:glowstone)
B(2,5,2,minecraft:glowstone)
B(2,6,2,minecraft:glowstone)
B(2,0,3,minecraft:glowstone)
B(2,1,3,minecraft:glowstone)
B(2,2,3,minecraft:glowstone)
B(2,3,3,minecraft:glowstone)
B(2,4,3,minecraft:glowstone)
B(2,5,3,minecraft:glowstone)
B(2,6,3,minecraft:glowstone)
B(2,0,4,minecraft:glowstone)
B(2,1,4,minecraft:glowstone)
B(2,2,4,minecraft:glowstone)
B(2,3,4,minecraft:glowstone)
B(2,4,4,minecraft:glowstone)
B(2,5,4,minecraft:glowstone)
B(2,0,5,minecraft:glowstone)
B(2,1,5,minecraft:glowstone)
B(2,2,5,minecraft:glowstone)
B(2,3,5,minecraft:glowstone)
B(2,4,5,minecraft:glowstone)
B(2,5,5,minecraft:glowstone)
B(2,0,6,minecraft:glowstone)
B(2,1,6,minecraft:glowstone)
B(2,2,6,minecraft:glowstone)
B(2,3,6,minecraft:glowstone)
B(2,4,6,minecraft:glowstone)
B(2,0,7,minecraft:glowstone)
B(2,1,7,minecraft:glowstone)
B(2,2,7,minecraft:glowstone)
B(2,3,7,minecraft:glowstone)
B(2,0,8,minecraft:glowstone)
B(2,1,8,minecraft:glowstone)
B(2,2,8,minecraft:glowstone)
B(2,3,8,minecraft:glowstone)
B(2,0,9,minecraft:glowstone)
B(2,1,9,minecraft:glowstone)
B(2,2,9,minecraft:glowstone)
B(2,0,10,minecraft:glowstone)
B(2,1,10,minecraft:glowstone)
B(2,2,10,minecraft:glowstone)
B(2,0,11,minecraft:glowstone)
B(2,1,11,minecraft:glowstone)
B(2,0,12,minecraft:glowstone)
B(2,0,13,minecraft:glowstone)
B(3,1,-6,minecraft:glowstone)
B(3,2,-6,minecraft:glowstone)
B(3,3,-6,minecraft:glowstone)
B(3,4,-6,minecraft:glowstone)
B(3,5,-6,minecraft:glowstone)
B(3,6,-6,minecraft:glowstone)
B(3,0,-5,minecraft:glowstone)
B(3,1,-5,minecraft:glowstone)
B(3,2,-5,minecraft:glowstone)
B(3,3,-5,minecraft:glowstone)
B(3,4,-5,minecraft:glowstone)
B(3,5,-5,minecraft:glowstone)
B(3,6,-5,minecraft:glowstone)
B(3,7,-5,minecraft:glowstone)
B(3,0,-4,minecraft:glowstone)
B(3,1,-4,minecraft:glowstone)
B(3,2,-4,minecraft:glowstone)
B(3,3,-4,minecraft:glowstone)
B(3,4,-4,minecraft:glowstone)
B(3,5,-4,minecraft:glowstone)
B(3,6,-4,minecraft:glowstone)
B(3,7,-4,minecraft:glowstone)
B(3,0,-3,minecraft:glowstone)
B(3,1,-3,minecraft:glowstone)
B(3,2,-3,minecraft:glowstone)
B(3,3,-3,minecraft:glowstone)
B(3,4,-3,minecraft:glowstone)
B(3,5,-3,minecraft:glowstone)
B(3,6,-3,minecraft:glowstone)
B(3,7,-3,minecraft:glowstone)
B(3,0,-2,minecraft:glowstone)
B(3,1,-2,minecraft:glowstone)
B(3,2,-2,minecraft:glowstone)
B(3,3,-2,minecraft:glowstone)
B(3,4,-2,minecraft:glowstone)
B(3,5,-2,minecraft:glowstone)
B(3,6,-2,minecraft:glowstone)
B(3,7,-2,minecraft:glowstone)
B(3,0,-1,minecraft:glowstone)
B(3,1,-1,minecraft:glowstone)
B(3,2,-1,minecraft:glowstone)
B(3,3,-1,minecraft:glowstone)
B(3,4,-1,minecraft:glowstone)
B(3,5,-1,minecraft:glowstone)
B(3,6,-1,minecraft:glowstone)
B(3,7,-1,minecraft:glowstone)
B(3,0,0,minecraft:glowstone)
B(3,1,0,minecraft:glowstone)
B(3,2,0,minecraft:glowstone)
B(3,3,0,minecraft:glowstone)
B(3,4,0,minecraft:glowstone)
B(3,5,0,minecraft:glowstone)
B(3,6,0,minecraft:glowstone)
B(3,0,1,minecraft:glowstone)
B(3,1,1,minecraft:glowstone)
B(3,2,1,minecraft:glowstone)
B(3,3,1,minecraft:glowstone)
B(3,4,1,minecraft:glowstone)
B(3,5,1,minecraft:glowstone)
B(3,6,1,minecraft:glowstone)
B(3,0,2,minecraft:glowstone)
B(3,1,2,minecraft:glowstone)
B(3,2,2,minecraft:glowstone)
B(3,3,2,minecraft:glowstone)
B(3,4,2,minecraft:glowstone)
B(3,5,2,minecraft:glowstone)
B(3,6,2,minecraft:glowstone)
B(3,0,3,minecraft:glowstone)
B(3,1,3,minecraft:glowstone)
B(3,2,3,minecraft:glowstone)
B(3,3,3,minecraft:glowstone)
B(3,4,3,minecraft:glowstone)
B(3,5,3,minecraft:glowstone)
B(3,0,4,minecraft:glowstone)
B(3,1,4,minecraft:glowstone)
B(3,2,4,minecraft:glowstone)
B(3,3,4,minecraft:glowstone)
B(3,4,4,minecraft:glowstone)
B(3,5,4,minecraft:glowstone)
B(3,0,5,minecraft:glowstone)
B(3,1,5,minecraft:glowstone)
B(3,2,5,minecraft:glowstone)
B(3,3,5,minecraft:glowstone)
B(3,4,5,minecraft:glowstone)
B(3,0,6,minecraft:glowstone)
B(3,1,6,minecraft:glowstone)
B(3,2,6,minecraft:glowstone)
B(3,3,6,minecraft:glowstone)
B(3,4,6,minecraft:glowstone)
B(3,0,7,minecraft:glowstone)
B(3,1,7,minecraft:glowstone)
B(3,2,7,minecraft:glowstone)
B(3,3,7,minecraft:glowstone)
B(3,0,8,minecraft:glowstone)
B(3,1,8,minecraft:glowstone)
B(3,2,8,minecraft:glowstone)
B(3,3,8,minecraft:glowstone)
B(3,0,9,minecraft:glowstone)
B(3,1,9,minecraft:glowstone)
B(3,2,9,minecraft:glowstone)
B(3,0,10,minecraft:glowstone)
B(3,1,10,minecraft:glowstone)
B(3,0,11,minecraft:glowstone)
B(3,1,11,minecraft:glowstone)
B(3,0,12,minecraft:glowstone)
B(3,0,13,minecraft:glowstone)
B(4,2,-6,minecraft:glowstone)
B(4,3,-6,minecraft:glowstone)
B(4,4,-6,minecraft:glowstone)
B(4,0,-5,minecraft:glowstone)
B(4,1,-5,minecraft:glowstone)
B(4,2,-5,minecraft:glowstone)
B(4,3,-5,minecraft:glowstone)
B(4,4,-5,minecraft:glowstone)
B(4,5,-5,minecraft:glowstone)
B(4,6,-5,minecraft:glowstone)
B(4,0,-4,minecraft:glowstone)
B(4,1,-4,minecraft:glowstone)
B(4,2,-4,minecraft:glowstone)
B(4,3,-4,minecraft:glowstone)
B(4,4,-4,minecraft:glowstone)
B(4,5,-4,minecraft:glowstone)
B(4,6,-4,minecraft:glowstone)
B(4,0,-3,minecraft:glowstone)
B(4,1,-3,minecraft:glowstone)
B(4,2,-3,minecraft:glowstone)
B(4,3,-3,minecraft:glowstone)
B(4,4,-3,minecraft:glowstone)
B(4,5,-3,minecraft:glowstone)
B(4,6,-3,minecraft:glowstone)
B(4,0,-2,minecraft:glowstone)
B(4,1,-2,minecraft:glowstone)
B(4,2,-2,minecraft:glowstone)
B(4,3,-2,minecraft:glowstone)
B(4,4,-2,minecraft:glowstone)
B(4,5,-2,minecraft:glowstone)
B(4,6,-2,minecraft:glowstone)
B(4,0,-1,minecraft:glowstone)
B(4,1,-1,minecraft:glowstone)
B(4,2,-1,minecraft:glowstone)
B(4,3,-1,minecraft:glowstone)
B(4,4,-1,minecraft:glowstone)
B(4,5,-1,minecraft:glowstone)
B(4,6,-1,minecraft:glowstone)
B(4,0,0,minecraft:glowstone)
B(4,1,0,minecraft:glowstone)
B(4,2,0,minecraft:glowstone)
B(4,3,0,minecraft:glowstone)
B(4,4,0,minecraft:glowstone)
B(4,5,0,minecraft:glowstone)
B(4,6,0,minecraft:glowstone)
B(4,0,1,minecraft:glowstone)
B(4,1,1,minecraft:glowstone)
B(4,2,1,minecraft:glowstone)
B(4,3,1,minecraft:glowstone)
B(4,4,1,minecraft:glowstone)
B(4,5,1,minecraft:glowstone)
B(4,6,1,minecraft:glowstone)
B(4,0,2,minecraft:glowstone)
B(4,1,2,minecraft:glowstone)
B(4,2,2,minecraft:glowstone)
B(4,3,2,minecraft:glowstone)
B(4,4,2,minecraft:glowstone)
B(4,5,2,minecraft:glowstone)
B(4,0,3,minecraft:glowstone)
B(4,1,3,minecraft:glowstone)
B(4,2,3,minecraft:glowstone)
B(4,3,3,minecraft:glowstone)
B(4,4,3,minecraft:glowstone)
B(4,5,3,minecraft:glowstone)
B(4,0,4,minecraft:glowstone)
B(4,1,4,minecraft:glowstone)
B(4,2,4,minecraft:glowstone)
B(4,3,4,minecraft:glowstone)
B(4,4,4,minecraft:glowstone)
B(4,0,5,minecraft:glowstone)
B(4,1,5,minecraft:glowstone)
B(4,2,5,minecraft:glowstone)
B(4,3,5,minecraft:glowstone)
B(4,4,5,minecraft:glowstone)
B(4,0,6,minecraft:glowstone)
B(4,1,6,minecraft:glowstone)
B(4,2,6,minecraft:glowstone)
B(4,3,6,minecraft:glowstone)
B(4,4,6,minecraft:glowstone)
B(4,0,7,minecraft:glowstone)
B(4,1,7,minecraft:glowstone)
B(4,2,7,minecraft:glowstone)
B(4,3,7,minecraft:glowstone)
B(4,0,8,minecraft:glowstone)
B(4,1,8,minecraft:glowstone)
B(4,2,8,minecraft:glowstone)
B(4,3,8,minecraft:glowstone)
B(4,0,9,minecraft:glowstone)
B(4,1,9,minecraft:glowstone)
B(4,2,9,minecraft:glowstone)
B(4,0,10,minecraft:glowstone)
B(4,1,10,minecraft:glowstone)
B(4,0,11,minecraft:glowstone)
B(4,1,11,minecraft:glowstone)
B(4,0,12,minecraft:glowstone)
B(5,2,-6,minecraft:glowstone)
B(5,3,-6,minecraft:glowstone)
B(5,0,-5,minecraft:glowstone)
B(5,1,-5,minecraft:glowstone)
B(5,2,-5,minecraft:glowstone)
B(5,3,-5,minecraft:glowstone)
B(5,4,-5,minecraft:glowstone)
B(5,5,-5,minecraft:glowstone)
B(5,0,-4,minecraft:glowstone)
B(5,1,-4,minecraft:glowstone)
B(5,2,-4,minecraft:glowstone)
B(5,3,-4,minecraft:glowstone)
B(5,4,-4,minecraft:glowstone)
B(5,5,-4,minecraft:glowstone)
B(5,0,-3,minecraft:glowstone)
B(5,1,-3,minecraft:glowstone)
B(5,2,-3,minecraft:glowstone)
B(5,3,-3,minecraft:glowstone)
B(5,4,-3,minecraft:glowstone)
B(5,5,-3,minecraft:glowstone)
B(5,0,-2,minecraft:glowstone)
B(5,1,-2,minecraft:glowstone)
B(5,2,-2,minecraft:glowstone)
B(5,3,-2,minecraft:glowstone)
B(5,4,-2,minecraft:glowstone)
B(5,5,-2,minecraft:glowstone)
B(5,0,-1,minecraft:glowstone)
B(5,1,-1,minecraft:glowstone)
B(5,2,-1,minecraft:glowstone)
B(5,3,-1,minecraft:glowstone)
B(5,4,-1,minecraft:glowstone)
B(5,5,-1,minecraft:glowstone)
B(5,0,0,minecraft:glowstone)
B(5,1,0,minecraft:glowstone)
B(5,2,0,minecraft:glowstone)
B(5,3,0,minecraft:glowstone)
B(5,4,0,minecraft:glowstone)
B(5,5,0,minecraft:glowstone)
B(5,6,0,minecraft:glowstone)
B(5,0,1,minecraft:glowstone)
B(5,1,1,minecraft:glowstone)
B(5,2,1,minecraft:glowstone)
B(5,3,1,minecraft:glowstone)
B(5,4,1,minecraft:glowstone)
B(5,5,1,minecraft:glowstone)
B(5,0,2,minecraft:glowstone)
B(5,1,2,minecraft:glowstone)
B(5,2,2,minecraft:glowstone)
B(5,3,2,minecraft:glowstone)
B(5,4,2,minecraft:glowstone)
B(5,5,2,minecraft:glowstone)
B(5,0,3,minecraft:glowstone)
B(5,1,3,minecraft:glowstone)
B(5,2,3,minecraft:glowstone)
B(5,3,3,minecraft:glowstone)
B(5,4,3,minecraft:glowstone)
B(5,0,4,minecraft:glowstone)
B(5,1,4,minecraft:glowstone)
B(5,2,4,minecraft:glowstone)
B(5,3,4,minecraft:glowstone)
B(5,4,4,minecraft:glowstone)
B(5,0,5,minecraft:glowstone)
B(5,1,5,minecraft:glowstone)
B(5,2,5,minecraft:glowstone)
B(5,3,5,minecraft:glowstone)
B(5,4,5,minecraft:glowstone)
B(5,0,6,minecraft:glowstone)
B(5,1,6,minecraft:glowstone)
B(5,2,6,minecraft:glowstone)
B(5,3,6,minecraft:glowstone)
B(5,0,7,minecraft:glowstone)
B(5,1,7,minecraft:glowstone)
B(5,2,7,minecraft:glowstone)
B(5,3,7,minecraft:glowstone)
B(5,0,8,minecraft:glowstone)
B(5,1,8,minecraft:glowstone)
B(5,2,8,minecraft:glowstone)
B(5,0,9,minecraft:glowstone)
B(5,1,9,minecraft:glowstone)
B(5,2,9,minecraft:glowstone)
B(5,0,10,minecraft:glowstone)
B(5,1,10,minecraft:glowstone)
B(5,0,11,minecraft:glowstone)
B(5,1,11,minecraft:glowstone)
B(5,0,12,minecraft:glowstone)
B(6,0,-5,minecraft:glowstone)
B(6,1,-5,minecraft:glowstone)
B(6,2,-5,minecraft:glowstone)
B(6,3,-5,minecraft:glowstone)
B(6,0,-4,minecraft:glowstone)
B(6,1,-4,minecraft:glowstone)
B(6,2,-4,minecraft:glowstone)
B(6,3,-4,minecraft:glowstone)
B(6,4,-4,minecraft:glowstone)
B(6,0,-3,minecraft:glowstone)
B(6,1,-3,minecraft:glowstone)
B(6,2,-3,minecraft:glowstone)
B(6,3,-3,minecraft:glowstone)
B(6,4,-3,minecraft:glowstone)
B(6,5,-3,minecraft:glowstone)
B(6,0,-2,minecraft:glowstone)
B(6,1,-2,minecraft:glowstone)
B(6,2,-2,minecraft:glowstone)
B(6,3,-2,minecraft:glowstone)
B(6,4,-2,minecraft:glowstone)
B(6,5,-2,minecraft:glowstone)
B(6,0,-1,minecraft:glowstone)
B(6,1,-1,minecraft:glowstone)
B(6,2,-1,minecraft:glowstone)
B(6,3,-1,minecraft:glowstone)
B(6,4,-1,minecraft:glowstone)
B(6,5,-1,minecraft:glowstone)
B(6,0,0,minecraft:glowstone)
B(6,1,0,minecraft:glowstone)
B(6,2,0,minecraft:glowstone)
B(6,3,0,minecraft:glowstone)
B(6,4,0,minecraft:glowstone)
B(6,5,0,minecraft:glowstone)
B(6,0,1,minecraft:glowstone)
B(6,1,1,minecraft:glowstone)
B(6,2,1,minecraft:glowstone)
B(6,3,1,minecraft:glowstone)
B(6,4,1,minecraft:glowstone)
B(6,5,1,minecraft:glowstone)
B(6,0,2,minecraft:glowstone)
B(6,1,2,minecraft:glowstone)
B(6,2,2,minecraft:glowstone)
B(6,3,2,minecraft:glowstone)
B(6,4,2,minecraft:glowstone)
B(6,5,2,minecraft:glowstone)
B(6,0,3,minecraft:glowstone)
B(6,1,3,minecraft:glowstone)
B(6,2,3,minecraft:glowstone)
B(6,3,3,minecraft:glowstone)
B(6,4,3,minecraft:glowstone)
B(6,0,4,minecraft:glowstone)
B(6,1,4,minecraft:glowstone)
B(6,2,4,minecraft:glowstone)
B(6,3,4,minecraft:glowstone)
B(6,4,4,minecraft:glowstone)
B(6,0,5,minecraft:glowstone)
B(6,1,5,minecraft:glowstone)
B(6,2,5,minecraft:glowstone)
B(6,3,5,minecraft:glowstone)
B(6,0,6,minecraft:glowstone)
B(6,1,6,minecraft:glowstone)
B(6,2,6,minecraft:glowstone)
B(6,3,6,minecraft:glowstone)
B(6,0,7,minecraft:glowstone)
B(6,1,7,minecraft:glowstone)
B(6,2,7,minecraft:glowstone)
B(6,0,8,minecraft:glowstone)
B(6,1,8,minecraft:glowstone)
B(6,2,8,minecraft:glowstone)
B(6,0,9,minecraft:glowstone)
B(6,1,9,minecraft:glowstone)
B(6,2,9,minecraft:glowstone)
B(6,0,10,minecraft:glowstone)
B(6,1,10,minecraft:glowstone)
B(6,0,11,minecraft:glowstone)
B(6,0,12,minecraft:glowstone)
B(7,0,-5,minecraft:glowstone)
B(7,1,-5,minecraft:glowstone)
B(7,0,-4,minecraft:glowstone)
B(7,1,-4,minecraft:glowstone)
B(7,2,-4,minecraft:glowstone)
B(7,3,-4,minecraft:glowstone)
B(7,0,-3,minecraft:glowstone)
B(7,1,-3,minecraft:glowstone)
B(7,2,-3,minecraft:glowstone)
B(7,3,-3,minecraft:glowstone)
B(7,4,-3,minecraft:glowstone)
B(7,0,-2,minecraft:glowstone)
B(7,1,-2,minecraft:glowstone)
B(7,2,-2,minecraft:glowstone)
B(7,3,-2,minecraft:glowstone)
B(7,4,-2,minecraft:glowstone)
B(7,0,-1,minecraft:glowstone)
B(7,1,-1,minecraft:glowstone)
B(7,2,-1,minecraft:glowstone)
B(7,3,-1,minecraft:glowstone)
B(7,4,-1,minecraft:glowstone)
B(7,0,0,minecraft:glowstone)
B(7,1,0,minecraft:glowstone)
B(7,2,0,minecraft:glowstone)
B(7,3,0,minecraft:glowstone)
B(7,4,0,minecraft:glowstone)
B(7,0,1,minecraft:glowstone)
B(7,1,1,minecraft:glowstone)
B(7,2,1,minecraft:glowstone)
B(7,3,1,minecraft:glowstone)
B(7,4,1,minecraft:glowstone)
B(7,0,2,minecraft:glowstone)
B(7,1,2,minecraft:glowstone)
B(7,2,2,minecraft:glowstone)
B(7,3,2,minecraft:glowstone)
B(7,4,2,minecraft:glowstone)
B(7,0,3,minecraft:glowstone)
B(7,1,3,minecraft:glowstone)
B(7,2,3,minecraft:glowstone)
B(7,3,3,minecraft:glowstone)
B(7,4,3,minecraft:glowstone)
B(7,0,4,minecraft:glowstone)
B(7,1,4,minecraft:glowstone)
B(7,2,4,minecraft:glowstone)
B(7,3,4,minecraft:glowstone)
B(7,0,5,minecraft:glowstone)
B(7,1,5,minecraft:glowstone)
B(7,2,5,minecraft:glowstone)
B(7,3,5,minecraft:glowstone)
B(7,0,6,minecraft:glowstone)
B(7,1,6,minecraft:glowstone)
B(7,2,6,minecraft:glowstone)
B(7,0,7,minecraft:glowstone)
B(7,1,7,minecraft:glowstone)
B(7,2,7,minecraft:glowstone)
B(7,0,8,minecraft:glowstone)
B(7,1,8,minecraft:glowstone)
B(7,2,8,minecraft:glowstone)
B(7,0,9,minecraft:glowstone)
B(7,1,9,minecraft:glowstone)
B(7,0,10,minecraft:glowstone)
B(7,1,10,minecraft:glowstone)
B(7,0,11,minecraft:glowstone)
B(7,0,12,minecraft:glowstone)
B(8,0,-5,minecraft:glowstone)
B(8,0,-4,minecraft:glowstone)
B(8,1,-4,minecraft:glowstone)
B(8,2,-4,minecraft:glowstone)
B(8,0,-3,minecraft:glowstone)
B(8,1,-3,minecraft:glowstone)
B(8,2,-3,minecraft:glowstone)
B(8,3,-3,minecraft:glowstone)
B(8,0,-2,minecraft:glowstone)
B(8,1,-2,minecraft:glowstone)
B(8,2,-2,minecraft:glowstone)
B(8,3,-2,minecraft:glowstone)
B(8,0,-1,minecraft:glowstone)
B(8,1,-1,minecraft:glowstone)
B(8,2,-1,minecraft:glowstone)
B(8,3,-1,minecraft:glowstone)
B(8,0,0,minecraft:glowstone)
B(8,1,0,minecraft:glowstone)
B(8,2,0,minecraft:glowstone)
B(8,3,0,minecraft:glowstone)
B(8,0,1,minecraft:glowstone)
B(8,1,1,minecraft:glowstone)
B(8,2,1,minecraft:glowstone)
B(8,3,1,minecraft:glowstone)
B(8,0,2,minecraft:glowstone)
B(8,1,2,minecraft:glowstone)
B(8,2,2,minecraft:glowstone)
B(8,3,2,minecraft:glowstone)
B(8,4,2,minecraft:glowstone)
B(8,0,3,minecraft:glowstone)
B(8,1,3,minecraft:glowstone)
B(8,2,3,minecraft:glowstone)
B(8,3,3,minecraft:glowstone)
B(8,0,4,minecraft:glowstone)
B(8,1,4,minecraft:glowstone)
B(8,2,4,minecraft:glowstone)
B(8,3,4,minecraft:glowstone)
B(8,0,5,minecraft:glowstone)
B(8,1,5,minecraft:glowstone)
B(8,2,5,minecraft:glowstone)
B(8,3,5,minecraft:glowstone)
B(8,0,6,minecraft:glowstone)
B(8,1,6,minecraft:glowstone)
B(8,2,6,minecraft:glowstone)
B(8,0,7,minecraft:glowstone)
B(8,1,7,minecraft:glowstone)
B(8,2,7,minecraft:glowstone)
B(8,0,8,minecraft:glowstone)
B(8,1,8,minecraft:glowstone)
B(8,0,9,minecraft:glowstone)
B(8,1,9,minecraft:glowstone)
B(8,0,10,minecraft:glowstone)
B(8,0,11,minecraft:glowstone)
B(8,0,12,minecraft:glowstone)
B(9,0,-4,minecraft:glowstone)
B(9,0,-3,minecraft:glowstone)
B(9,1,-3,minecraft:glowstone)
B(9,2,-3,minecraft:glowstone)
B(9,0,-2,minecraft:glowstone)
B(9,1,-2,minecraft:glowstone)
B(9,2,-2,minecraft:glowstone)
B(9,0,-1,minecraft:glowstone)
B(9,1,-1,minecraft:glowstone)
B(9,2,-1,minecraft:glowstone)
B(9,0,0,minecraft:glowstone)
B(9,1,0,minecraft:glowstone)
B(9,2,0,minecraft:glowstone)
B(9,3,0,minecraft:glowstone)
B(9,0,1,minecraft:glowstone)
B(9,1,1,minecraft:glowstone)
B(9,2,1,minecraft:glowstone)
B(9,3,1,minecraft:glowstone)
B(9,0,2,minecraft:glowstone)
B(9,1,2,minecraft:glowstone)
B(9,2,2,minecraft:glowstone)
B(9,3,2,minecraft:glowstone)
B(9,0,3,minecraft:glowstone)
B(9,1,3,minecraft:glowstone)
B(9,2,3,minecraft:glowstone)
B(9,3,3,minecraft:glowstone)
B(9,0,4,minecraft:glowstone)
B(9,1,4,minecraft:glowstone)
B(9,2,4,minecraft:glowstone)
B(9,3,4,minecraft:glowstone)
B(9,0,5,minecraft:glowstone)
B(9,1,5,minecraft:glowstone)
B(9,2,5,minecraft:glowstone)
B(9,0,6,minecraft:glowstone)
B(9,1,6,minecraft:glowstone)
B(9,2,6,minecraft:glowstone)
B(9,0,7,minecraft:glowstone)
B(9,1,7,minecraft:glowstone)
B(9,0,8,minecraft:glowstone)
B(9,1,8,minecraft:glowstone)
B(9,0,9,minecraft:glowstone)
B(9,0,10,minecraft:glowstone)
B(9,0,11,minecraft:glowstone)
B(10,0,-3,minecraft:glowstone)
B(10,0,-2,minecraft:glowstone)
B(10,1,-2,minecraft:glowstone)
B(10,2,-2,minecraft:glowstone)
B(10,0,-1,minecraft:glowstone)
B(10,1,-1,minecraft:glowstone)
B(10,2,-1,minecraft:glowstone)
B(10,0,0,minecraft:glowstone)
B(10,1,0,minecraft:glowstone)
B(10,2,0,minecraft:glowstone)
B(10,0,1,minecraft:glowstone)
B(10,1,1,minecraft:glowstone)
B(10,2,1,minecraft:glowstone)
B(10,0,2,minecraft:glowstone)
B(10,1,2,minecraft:glowstone)
B(10,2,2,minecraft:glowstone)
B(10,0,3,minecraft:glowstone)
B(10,1,3,minecraft:glowstone)
B(10,2,3,minecraft:glowstone)
B(10,0,4,minecraft:glowstone)
B(10,1,4,minecraft:glowstone)
B(10,2,4,minecraft:glowstone)
B(10,0,5,minecraft:glowstone)
B(10,1,5,minecraft:glowstone)
B(10,2,5,minecraft:glowstone)
B(10,0,6,minecraft:glowstone)
B(10,1,6,minecraft:glowstone)
B(10,0,7,minecraft:glowstone)
B(10,1,7,minecraft:glowstone)
B(10,0,8,minecraft:glowstone)
B(10,1,8,minecraft:glowstone)
B(10,0,9,minecraft:glowstone)
B(10,0,10,minecraft:glowstone)
B(11,0,-2,minecraft:glowstone)
B(11,1,-2,minecraft:glowstone)
B(11,0,-1,minecraft:glowstone)
B(11,1,-1,minecraft:glowstone)
B(11,0,0,minecraft:glowstone)
B(11,1,0,minecraft:glowstone)
B(11,0,1,minecraft:glowstone)
B(11,1,1,minecraft:glowstone)
B(11,0,2,minecraft:glowstone)
B(11,1,2,minecraft:glowstone)
B(11,0,3,minecraft:glowstone)
B(11,1,3,minecraft:glowstone)
B(11,0,4,minecraft:glowstone)
B(11,1,4,minecraft:glowstone)
B(11,0,5,minecraft:glowstone)
B(11,1,5,minecraft:glowstone)
B(11,0,6,minecraft:glowstone)
B(11,1,6,minecraft:glowstone)
B(11,0,7,minecraft:glowstone)
B(11,1,7,minecraft:glowstone)
B(11,0,8,minecraft:glowstone)
B(11,0,9,minecraft:glowstone)
B(12,0,-1,minecraft:glowstone)
B(12,0,0,minecraft:glowstone)
B(12,0,1,minecraft:glowstone)
B(12,0,2,minecraft:glowstone)
B(12,1,2,minecraft:glowstone)
B(12,0,3,minecraft:glowstone)
B(12,1,3,minecraft:glowstone)
B(12,0,4,minecraft:glowstone)
B(12,1,4,minecraft:glowstone)
B(12,0,5,minecraft:glowstone)
B(12,1,5,minecraft:glowstone)
B(12,0,6,minecraft:glowstone)
B(12,1,6,minecraft:glowstone)
B(12,0,7,minecraft:glowstone)
B(12,0,8,minecraft:glowstone)
B(13,0,-1,minecraft:glowstone)
B(13,0,0,minecraft:glowstone)
B(13,0,1,minecraft:glowstone)
B(13,0,2,minecraft:glowstone)
B(13,0,3,minecraft:glowstone)
B(13,0,4,minecraft:glowstone)
B(13,0,5,minecraft:glowstone)
B(13,0,6,minecraft:glowstone)
B(13,0,7,minecraft:glowstone)
B(14,0,7,minecraft:glowstone)

#######################################################################
# +-----------------------------------------------------------------+ #
# |                            BO3 checks                           | #
# +-----------------------------------------------------------------+ #
#######################################################################

BlockCheckNot(0,-1,0,minecraft:air)
BlockCheckNot(-14,-1,-14,minecraft:air)
BlockCheckNot(-14,-1,7,minecraft:air)
BlockCheckNot(14,-1,-14,minecraft:air)
BlockCheckNot(14,-1,7,minecraft:air)

#######################################################################
# +-----------------------------------------------------------------+ #
# |                             Branches                            | #
# +-----------------------------------------------------------------+ #
#######################################################################


#######################################################################
# +-----------------------------------------------------------------+ #
# |                             Entities                            | #
# +-----------------------------------------------------------------+ #
#######################################################################

