

#######################################################################
# +-----------------------------------------------------------------+ #
# |                            BO3 object                           | #
# +-----------------------------------------------------------------+ #
#######################################################################

Author: Frank

Description: Medium glowstone spike

Version: 3

SettingsMode: WriteDisable


#######################################################################
# +-----------------------------------------------------------------+ #
# |                          Main settings                          | #
# +-----------------------------------------------------------------+ #
#######################################################################

Tree: true

Frequency: 10

Rarity: 100.0

MaxSpawn: 1

RotateRandomly: true

SpawnHeight: randomY

SpawnHeightOffset: 0

SpawnHeightVariance: 0

##############################
# Height Limits for the BO3. #
##############################

MinHeight: 50

MaxHeight: 65

######################
# Extrusion settings #
######################

ExtrudeMode: None

ExtrudeThroughBlocks: minecraft:air

MaxBranchDepth: 10


#######################################################################
# +-----------------------------------------------------------------+ #
# |                      Source block settings                      | #
# +-----------------------------------------------------------------+ #
#######################################################################

SourceBlocks: minecraft:air

MaxPercentageOutsideSourceBlock: 60

OutsideSourceBlock: placeAnyway

DoReplaceBlocks: true

IsOTGPlus: false


#######################################################################
# +-----------------------------------------------------------------+ #
# |                              Blocks                             | #
# +-----------------------------------------------------------------+ #
#######################################################################

B(-8,0,-5,minecraft:glowstone)
B(-7,0,-5,minecraft:glowstone)
B(-7,0,-4,minecraft:glowstone)
B(-7,0,-3,minecraft:glowstone)
B(-7,0,-2,minecraft:glowstone)
B(-7,0,-1,minecraft:glowstone)
B(-7,0,0,minecraft:glowstone)
B(-7,0,1,minecraft:glowstone)
B(-7,0,2,minecraft:glowstone)
B(-7,0,3,minecraft:glowstone)
B(-7,0,4,minecraft:glowstone)
B(-7,0,5,minecraft:glowstone)
B(-7,0,6,minecraft:glowstone)
B(-6,0,-5,minecraft:glowstone)
B(-6,1,-5,minecraft:glowstone)
B(-6,0,-4,minecraft:glowstone)
B(-6,1,-4,minecraft:glowstone)
B(-6,0,-3,minecraft:glowstone)
B(-6,1,-3,minecraft:glowstone)
B(-6,0,-2,minecraft:glowstone)
B(-6,1,-2,minecraft:glowstone)
B(-6,0,-1,minecraft:glowstone)
B(-6,1,-1,minecraft:glowstone)
B(-6,0,0,minecraft:glowstone)
B(-6,1,0,minecraft:glowstone)
B(-6,0,1,minecraft:glowstone)
B(-6,1,1,minecraft:glowstone)
B(-6,0,2,minecraft:glowstone)
B(-6,0,3,minecraft:glowstone)
B(-6,0,4,minecraft:glowstone)
B(-6,0,5,minecraft:glowstone)
B(-6,0,6,minecraft:glowstone)
B(-5,0,-5,minecraft:glowstone)
B(-5,1,-5,minecraft:glowstone)
B(-5,2,-5,minecraft:glowstone)
B(-5,0,-4,minecraft:glowstone)
B(-5,1,-4,minecraft:glowstone)
B(-5,2,-4,minecraft:glowstone)
B(-5,0,-3,minecraft:glowstone)
B(-5,1,-3,minecraft:glowstone)
B(-5,2,-3,minecraft:glowstone)
B(-5,0,-2,minecraft:glowstone)
B(-5,1,-2,minecraft:glowstone)
B(-5,0,-1,minecraft:glowstone)
B(-5,1,-1,minecraft:glowstone)
B(-5,0,0,minecraft:glowstone)
B(-5,1,0,minecraft:glowstone)
B(-5,0,1,minecraft:glowstone)
B(-5,1,1,minecraft:glowstone)
B(-5,0,2,minecraft:glowstone)
B(-5,1,2,minecraft:glowstone)
B(-5,0,3,minecraft:glowstone)
B(-5,1,3,minecraft:glowstone)
B(-5,0,4,minecraft:glowstone)
B(-5,1,4,minecraft:glowstone)
B(-5,0,5,minecraft:glowstone)
B(-5,1,5,minecraft:glowstone)
B(-5,0,6,minecraft:glowstone)
B(-5,0,7,minecraft:glowstone)
B(-4,0,-5,minecraft:glowstone)
B(-4,1,-5,minecraft:glowstone)
B(-4,2,-5,minecraft:glowstone)
B(-4,0,-4,minecraft:glowstone)
B(-4,1,-4,minecraft:glowstone)
B(-4,2,-4,minecraft:glowstone)
B(-4,0,-3,minecraft:glowstone)
B(-4,1,-3,minecraft:glowstone)
B(-4,2,-3,minecraft:glowstone)
B(-4,0,-2,minecraft:glowstone)
B(-4,1,-2,minecraft:glowstone)
B(-4,2,-2,minecraft:glowstone)
B(-4,0,-1,minecraft:glowstone)
B(-4,1,-1,minecraft:glowstone)
B(-4,2,-1,minecraft:glowstone)
B(-4,0,0,minecraft:glowstone)
B(-4,1,0,minecraft:glowstone)
B(-4,2,0,minecraft:glowstone)
B(-4,0,1,minecraft:glowstone)
B(-4,1,1,minecraft:glowstone)
B(-4,2,1,minecraft:glowstone)
B(-4,0,2,minecraft:glowstone)
B(-4,1,2,minecraft:glowstone)
B(-4,2,2,minecraft:glowstone)
B(-4,0,3,minecraft:glowstone)
B(-4,1,3,minecraft:glowstone)
B(-4,2,3,minecraft:glowstone)
B(-4,0,4,minecraft:glowstone)
B(-4,1,4,minecraft:glowstone)
B(-4,0,5,minecraft:glowstone)
B(-4,1,5,minecraft:glowstone)
B(-4,0,6,minecraft:glowstone)
B(-4,0,7,minecraft:glowstone)
B(-3,2,-6,minecraft:glowstone)
B(-3,3,-6,minecraft:glowstone)
B(-3,0,-5,minecraft:glowstone)
B(-3,1,-5,minecraft:glowstone)
B(-3,2,-5,minecraft:glowstone)
B(-3,3,-5,minecraft:glowstone)
B(-3,0,-4,minecraft:glowstone)
B(-3,1,-4,minecraft:glowstone)
B(-3,2,-4,minecraft:glowstone)
B(-3,3,-4,minecraft:glowstone)
B(-3,0,-3,minecraft:glowstone)
B(-3,1,-3,minecraft:glowstone)
B(-3,2,-3,minecraft:glowstone)
B(-3,3,-3,minecraft:glowstone)
B(-3,0,-2,minecraft:glowstone)
B(-3,1,-2,minecraft:glowstone)
B(-3,2,-2,minecraft:glowstone)
B(-3,3,-2,minecraft:glowstone)
B(-3,0,-1,minecraft:glowstone)
B(-3,1,-1,minecraft:glowstone)
B(-3,2,-1,minecraft:glowstone)
B(-3,3,-1,minecraft:glowstone)
B(-3,0,0,minecraft:glowstone)
B(-3,1,0,minecraft:glowstone)
B(-3,2,0,minecraft:glowstone)
B(-3,3,0,minecraft:glowstone)
B(-3,0,1,minecraft:glowstone)
B(-3,1,1,minecraft:glowstone)
B(-3,2,1,minecraft:glowstone)
B(-3,3,1,minecraft:glowstone)
B(-3,0,2,minecraft:glowstone)
B(-3,1,2,minecraft:glowstone)
B(-3,2,2,minecraft:glowstone)
B(-3,3,2,minecraft:glowstone)
B(-3,0,3,minecraft:glowstone)
B(-3,1,3,minecraft:glowstone)
B(-3,2,3,minecraft:glowstone)
B(-3,0,4,minecraft:glowstone)
B(-3,1,4,minecraft:glowstone)
B(-3,2,4,minecraft:glowstone)
B(-3,0,5,minecraft:glowstone)
B(-3,1,5,minecraft:glowstone)
B(-3,0,6,minecraft:glowstone)
B(-3,1,6,minecraft:glowstone)
B(-3,0,7,minecraft:glowstone)
B(-3,0,8,minecraft:glowstone)
B(-2,2,-6,minecraft:glowstone)
B(-2,3,-6,minecraft:glowstone)
B(-2,4,-6,minecraft:glowstone)
B(-2,0,-5,minecraft:glowstone)
B(-2,1,-5,minecraft:glowstone)
B(-2,2,-5,minecraft:glowstone)
B(-2,3,-5,minecraft:glowstone)
B(-2,4,-5,minecraft:glowstone)
B(-2,0,-4,minecraft:glowstone)
B(-2,1,-4,minecraft:glowstone)
B(-2,2,-4,minecraft:glowstone)
B(-2,3,-4,minecraft:glowstone)
B(-2,4,-4,minecraft:glowstone)
B(-2,0,-3,minecraft:glowstone)
B(-2,1,-3,minecraft:glowstone)
B(-2,2,-3,minecraft:glowstone)
B(-2,3,-3,minecraft:glowstone)
B(-2,4,-3,minecraft:glowstone)
B(-2,0,-2,minecraft:glowstone)
B(-2,1,-2,minecraft:glowstone)
B(-2,2,-2,minecraft:glowstone)
B(-2,3,-2,minecraft:glowstone)
B(-2,4,-2,minecraft:glowstone)
B(-2,0,-1,minecraft:glowstone)
B(-2,1,-1,minecraft:glowstone)
B(-2,2,-1,minecraft:glowstone)
B(-2,3,-1,minecraft:glowstone)
B(-2,4,-1,minecraft:glowstone)
B(-2,0,0,minecraft:glowstone)
B(-2,1,0,minecraft:glowstone)
B(-2,2,0,minecraft:glowstone)
B(-2,3,0,minecraft:glowstone)
B(-2,4,0,minecraft:glowstone)
B(-2,0,1,minecraft:glowstone)
B(-2,1,1,minecraft:glowstone)
B(-2,2,1,minecraft:glowstone)
B(-2,3,1,minecraft:glowstone)
B(-2,0,2,minecraft:glowstone)
B(-2,1,2,minecraft:glowstone)
B(-2,2,2,minecraft:glowstone)
B(-2,3,2,minecraft:glowstone)
B(-2,0,3,minecraft:glowstone)
B(-2,1,3,minecraft:glowstone)
B(-2,2,3,minecraft:glowstone)
B(-2,0,4,minecraft:glowstone)
B(-2,1,4,minecraft:glowstone)
B(-2,2,4,minecraft:glowstone)
B(-2,0,5,minecraft:glowstone)
B(-2,1,5,minecraft:glowstone)
B(-2,0,6,minecraft:glowstone)
B(-2,1,6,minecraft:glowstone)
B(-2,0,7,minecraft:glowstone)
B(-2,1,7,minecraft:glowstone)
B(-2,0,8,minecraft:glowstone)
B(-2,0,9,minecraft:glowstone)
B(-1,5,-7,minecraft:glowstone)
B(-1,2,-6,minecraft:glowstone)
B(-1,3,-6,minecraft:glowstone)
B(-1,4,-6,minecraft:glowstone)
B(-1,5,-6,minecraft:glowstone)
B(-1,0,-5,minecraft:glowstone)
B(-1,1,-5,minecraft:glowstone)
B(-1,2,-5,minecraft:glowstone)
B(-1,3,-5,minecraft:glowstone)
B(-1,4,-5,minecraft:glowstone)
B(-1,5,-5,minecraft:glowstone)
B(-1,0,-4,minecraft:glowstone)
B(-1,1,-4,minecraft:glowstone)
B(-1,2,-4,minecraft:glowstone)
B(-1,3,-4,minecraft:glowstone)
B(-1,4,-4,minecraft:glowstone)
B(-1,5,-4,minecraft:glowstone)
B(-1,0,-3,minecraft:glowstone)
B(-1,1,-3,minecraft:glowstone)
B(-1,2,-3,minecraft:glowstone)
B(-1,3,-3,minecraft:glowstone)
B(-1,4,-3,minecraft:glowstone)
B(-1,0,-2,minecraft:glowstone)
B(-1,1,-2,minecraft:glowstone)
B(-1,2,-2,minecraft:glowstone)
B(-1,3,-2,minecraft:glowstone)
B(-1,4,-2,minecraft:glowstone)
B(-1,0,-1,minecraft:glowstone)
B(-1,1,-1,minecraft:glowstone)
B(-1,2,-1,minecraft:glowstone)
B(-1,3,-1,minecraft:glowstone)
B(-1,4,-1,minecraft:glowstone)
B(-1,0,0,minecraft:glowstone)
B(-1,1,0,minecraft:glowstone)
B(-1,2,0,minecraft:glowstone)
B(-1,3,0,minecraft:glowstone)
B(-1,4,0,minecraft:glowstone)
B(-1,0,1,minecraft:glowstone)
B(-1,1,1,minecraft:glowstone)
B(-1,2,1,minecraft:glowstone)
B(-1,3,1,minecraft:glowstone)
B(-1,4,1,minecraft:glowstone)
B(-1,0,2,minecraft:glowstone)
B(-1,1,2,minecraft:glowstone)
B(-1,2,2,minecraft:glowstone)
B(-1,3,2,minecraft:glowstone)
B(-1,0,3,minecraft:glowstone)
B(-1,1,3,minecraft:glowstone)
B(-1,2,3,minecraft:glowstone)
B(-1,3,3,minecraft:glowstone)
B(-1,0,4,minecraft:glowstone)
B(-1,1,4,minecraft:glowstone)
B(-1,2,4,minecraft:glowstone)
B(-1,0,5,minecraft:glowstone)
B(-1,1,5,minecraft:glowstone)
B(-1,2,5,minecraft:glowstone)
B(-1,0,6,minecraft:glowstone)
B(-1,1,6,minecraft:glowstone)
B(-1,0,7,minecraft:glowstone)
B(-1,1,7,minecraft:glowstone)
B(-1,0,8,minecraft:glowstone)
B(-1,0,9,minecraft:glowstone)
B(0,5,-7,minecraft:glowstone)
B(0,1,-6,minecraft:glowstone)
B(0,2,-6,minecraft:glowstone)
B(0,3,-6,minecraft:glowstone)
B(0,4,-6,minecraft:glowstone)
B(0,5,-6,minecraft:glowstone)
B(0,0,-5,minecraft:glowstone)
B(0,1,-5,minecraft:glowstone)
B(0,2,-5,minecraft:glowstone)
B(0,3,-5,minecraft:glowstone)
B(0,4,-5,minecraft:glowstone)
B(0,5,-5,minecraft:glowstone)
B(0,0,-4,minecraft:glowstone)
B(0,1,-4,minecraft:glowstone)
B(0,2,-4,minecraft:glowstone)
B(0,3,-4,minecraft:glowstone)
B(0,4,-4,minecraft:glowstone)
B(0,5,-4,minecraft:glowstone)
B(0,0,-3,minecraft:glowstone)
B(0,1,-3,minecraft:glowstone)
B(0,2,-3,minecraft:glowstone)
B(0,3,-3,minecraft:glowstone)
B(0,4,-3,minecraft:glowstone)
B(0,5,-3,minecraft:glowstone)
B(0,0,-2,minecraft:glowstone)
B(0,1,-2,minecraft:glowstone)
B(0,2,-2,minecraft:glowstone)
B(0,3,-2,minecraft:glowstone)
B(0,4,-2,minecraft:glowstone)
B(0,5,-2,minecraft:glowstone)
B(0,0,-1,minecraft:glowstone)
B(0,1,-1,minecraft:glowstone)
B(0,2,-1,minecraft:glowstone)
B(0,3,-1,minecraft:glowstone)
B(0,4,-1,minecraft:glowstone)
B(0,5,-1,minecraft:glowstone)
B(0,0,0,minecraft:glowstone)
B(0,1,0,minecraft:glowstone)
B(0,2,0,minecraft:glowstone)
B(0,3,0,minecraft:glowstone)
B(0,4,0,minecraft:glowstone)
B(0,0,1,minecraft:glowstone)
B(0,1,1,minecraft:glowstone)
B(0,2,1,minecraft:glowstone)
B(0,3,1,minecraft:glowstone)
B(0,4,1,minecraft:glowstone)
B(0,0,2,minecraft:glowstone)
B(0,1,2,minecraft:glowstone)
B(0,2,2,minecraft:glowstone)
B(0,3,2,minecraft:glowstone)
B(0,0,3,minecraft:glowstone)
B(0,1,3,minecraft:glowstone)
B(0,2,3,minecraft:glowstone)
B(0,3,3,minecraft:glowstone)
B(0,0,4,minecraft:glowstone)
B(0,1,4,minecraft:glowstone)
B(0,2,4,minecraft:glowstone)
B(0,3,4,minecraft:glowstone)
B(0,0,5,minecraft:glowstone)
B(0,1,5,minecraft:glowstone)
B(0,2,5,minecraft:glowstone)
B(0,0,6,minecraft:glowstone)
B(0,1,6,minecraft:glowstone)
B(0,2,6,minecraft:glowstone)
B(0,0,7,minecraft:glowstone)
B(0,1,7,minecraft:glowstone)
B(0,0,8,minecraft:glowstone)
B(0,1,8,minecraft:glowstone)
B(0,0,9,minecraft:glowstone)
B(0,0,10,minecraft:glowstone)
B(1,4,-7,minecraft:glowstone)
B(1,5,-7,minecraft:glowstone)
B(1,6,-7,minecraft:glowstone)
B(1,1,-6,minecraft:glowstone)
B(1,2,-6,minecraft:glowstone)
B(1,3,-6,minecraft:glowstone)
B(1,4,-6,minecraft:glowstone)
B(1,5,-6,minecraft:glowstone)
B(1,6,-6,minecraft:glowstone)
B(1,0,-5,minecraft:glowstone)
B(1,1,-5,minecraft:glowstone)
B(1,2,-5,minecraft:glowstone)
B(1,3,-5,minecraft:glowstone)
B(1,4,-5,minecraft:glowstone)
B(1,5,-5,minecraft:glowstone)
B(1,6,-5,minecraft:glowstone)
B(1,0,-4,minecraft:glowstone)
B(1,1,-4,minecraft:glowstone)
B(1,2,-4,minecraft:glowstone)
B(1,3,-4,minecraft:glowstone)
B(1,4,-4,minecraft:glowstone)
B(1,5,-4,minecraft:glowstone)
B(1,6,-4,minecraft:glowstone)
B(1,0,-3,minecraft:glowstone)
B(1,1,-3,minecraft:glowstone)
B(1,2,-3,minecraft:glowstone)
B(1,3,-3,minecraft:glowstone)
B(1,4,-3,minecraft:glowstone)
B(1,5,-3,minecraft:glowstone)
B(1,6,-3,minecraft:glowstone)
B(1,0,-2,minecraft:glowstone)
B(1,1,-2,minecraft:glowstone)
B(1,2,-2,minecraft:glowstone)
B(1,3,-2,minecraft:glowstone)
B(1,4,-2,minecraft:glowstone)
B(1,5,-2,minecraft:glowstone)
B(1,6,-2,minecraft:glowstone)
B(1,0,-1,minecraft:glowstone)
B(1,1,-1,minecraft:glowstone)
B(1,2,-1,minecraft:glowstone)
B(1,3,-1,minecraft:glowstone)
B(1,4,-1,minecraft:glowstone)
B(1,5,-1,minecraft:glowstone)
B(1,0,0,minecraft:glowstone)
B(1,1,0,minecraft:glowstone)
B(1,2,0,minecraft:glowstone)
B(1,3,0,minecraft:glowstone)
B(1,4,0,minecraft:glowstone)
B(1,5,0,minecraft:glowstone)
B(1,0,1,minecraft:glowstone)
B(1,1,1,minecraft:glowstone)
B(1,2,1,minecraft:glowstone)
B(1,3,1,minecraft:glowstone)
B(1,4,1,minecraft:glowstone)
B(1,0,2,minecraft:glowstone)
B(1,1,2,minecraft:glowstone)
B(1,2,2,minecraft:glowstone)
B(1,3,2,minecraft:glowstone)
B(1,4,2,minecraft:glowstone)
B(1,0,3,minecraft:glowstone)
B(1,1,3,minecraft:glowstone)
B(1,2,3,minecraft:glowstone)
B(1,3,3,minecraft:glowstone)
B(1,0,4,minecraft:glowstone)
B(1,1,4,minecraft:glowstone)
B(1,2,4,minecraft:glowstone)
B(1,3,4,minecraft:glowstone)
B(1,0,5,minecraft:glowstone)
B(1,1,5,minecraft:glowstone)
B(1,2,5,minecraft:glowstone)
B(1,0,6,minecraft:glowstone)
B(1,1,6,minecraft:glowstone)
B(1,2,6,minecraft:glowstone)
B(1,0,7,minecraft:glowstone)
B(1,1,7,minecraft:glowstone)
B(1,0,8,minecraft:glowstone)
B(1,1,8,minecraft:glowstone)
B(1,0,9,minecraft:glowstone)
B(1,0,10,minecraft:glowstone)
B(1,0,11,minecraft:glowstone)
B(2,4,-7,minecraft:glowstone)
B(2,5,-7,minecraft:glowstone)
B(2,6,-7,minecraft:glowstone)
B(2,7,-7,minecraft:glowstone)
B(2,1,-6,minecraft:glowstone)
B(2,2,-6,minecraft:glowstone)
B(2,3,-6,minecraft:glowstone)
B(2,4,-6,minecraft:glowstone)
B(2,5,-6,minecraft:glowstone)
B(2,6,-6,minecraft:glowstone)
B(2,7,-6,minecraft:glowstone)
B(2,0,-5,minecraft:glowstone)
B(2,1,-5,minecraft:glowstone)
B(2,2,-5,minecraft:glowstone)
B(2,3,-5,minecraft:glowstone)
B(2,4,-5,minecraft:glowstone)
B(2,5,-5,minecraft:glowstone)
B(2,6,-5,minecraft:glowstone)
B(2,7,-5,minecraft:glowstone)
B(2,0,-4,minecraft:glowstone)
B(2,1,-4,minecraft:glowstone)
B(2,2,-4,minecraft:glowstone)
B(2,3,-4,minecraft:glowstone)
B(2,4,-4,minecraft:glowstone)
B(2,5,-4,minecraft:glowstone)
B(2,6,-4,minecraft:glowstone)
B(2,7,-4,minecraft:glowstone)
B(2,0,-3,minecraft:glowstone)
B(2,1,-3,minecraft:glowstone)
B(2,2,-3,minecraft:glowstone)
B(2,3,-3,minecraft:glowstone)
B(2,4,-3,minecraft:glowstone)
B(2,5,-3,minecraft:glowstone)
B(2,6,-3,minecraft:glowstone)
B(2,0,-2,minecraft:glowstone)
B(2,1,-2,minecraft:glowstone)
B(2,2,-2,minecraft:glowstone)
B(2,3,-2,minecraft:glowstone)
B(2,4,-2,minecraft:glowstone)
B(2,5,-2,minecraft:glowstone)
B(2,6,-2,minecraft:glowstone)
B(2,0,-1,minecraft:glowstone)
B(2,1,-1,minecraft:glowstone)
B(2,2,-1,minecraft:glowstone)
B(2,3,-1,minecraft:glowstone)
B(2,4,-1,minecraft:glowstone)
B(2,5,-1,minecraft:glowstone)
B(2,0,0,minecraft:glowstone)
B(2,1,0,minecraft:glowstone)
B(2,2,0,minecraft:glowstone)
B(2,3,0,minecraft:glowstone)
B(2,4,0,minecraft:glowstone)
B(2,5,0,minecraft:glowstone)
B(2,0,1,minecraft:glowstone)
B(2,1,1,minecraft:glowstone)
B(2,2,1,minecraft:glowstone)
B(2,3,1,minecraft:glowstone)
B(2,4,1,minecraft:glowstone)
B(2,5,1,minecraft:glowstone)
B(2,0,2,minecraft:glowstone)
B(2,1,2,minecraft:glowstone)
B(2,2,2,minecraft:glowstone)
B(2,3,2,minecraft:glowstone)
B(2,4,2,minecraft:glowstone)
B(2,0,3,minecraft:glowstone)
B(2,1,3,minecraft:glowstone)
B(2,2,3,minecraft:glowstone)
B(2,3,3,minecraft:glowstone)
B(2,4,3,minecraft:glowstone)
B(2,0,4,minecraft:glowstone)
B(2,1,4,minecraft:glowstone)
B(2,2,4,minecraft:glowstone)
B(2,3,4,minecraft:glowstone)
B(2,0,5,minecraft:glowstone)
B(2,1,5,minecraft:glowstone)
B(2,2,5,minecraft:glowstone)
B(2,3,5,minecraft:glowstone)
B(2,0,6,minecraft:glowstone)
B(2,1,6,minecraft:glowstone)
B(2,2,6,minecraft:glowstone)
B(2,0,7,minecraft:glowstone)
B(2,1,7,minecraft:glowstone)
B(2,2,7,minecraft:glowstone)
B(2,0,8,minecraft:glowstone)
B(2,1,8,minecraft:glowstone)
B(2,0,9,minecraft:glowstone)
B(2,0,10,minecraft:glowstone)
B(3,7,-8,minecraft:glowstone)
B(3,8,-8,minecraft:glowstone)
B(3,4,-7,minecraft:glowstone)
B(3,5,-7,minecraft:glowstone)
B(3,6,-7,minecraft:glowstone)
B(3,7,-7,minecraft:glowstone)
B(3,8,-7,minecraft:glowstone)
B(3,0,-6,minecraft:glowstone)
B(3,1,-6,minecraft:glowstone)
B(3,2,-6,minecraft:glowstone)
B(3,3,-6,minecraft:glowstone)
B(3,4,-6,minecraft:glowstone)
B(3,5,-6,minecraft:glowstone)
B(3,6,-6,minecraft:glowstone)
B(3,7,-6,minecraft:glowstone)
B(3,8,-6,minecraft:glowstone)
B(3,0,-5,minecraft:glowstone)
B(3,1,-5,minecraft:glowstone)
B(3,2,-5,minecraft:glowstone)
B(3,3,-5,minecraft:glowstone)
B(3,4,-5,minecraft:glowstone)
B(3,5,-5,minecraft:glowstone)
B(3,6,-5,minecraft:glowstone)
B(3,7,-5,minecraft:glowstone)
B(3,8,-5,minecraft:glowstone)
B(3,0,-4,minecraft:glowstone)
B(3,1,-4,minecraft:glowstone)
B(3,2,-4,minecraft:glowstone)
B(3,3,-4,minecraft:glowstone)
B(3,4,-4,minecraft:glowstone)
B(3,5,-4,minecraft:glowstone)
B(3,6,-4,minecraft:glowstone)
B(3,7,-4,minecraft:glowstone)
B(3,0,-3,minecraft:glowstone)
B(3,1,-3,minecraft:glowstone)
B(3,2,-3,minecraft:glowstone)
B(3,3,-3,minecraft:glowstone)
B(3,4,-3,minecraft:glowstone)
B(3,5,-3,minecraft:glowstone)
B(3,6,-3,minecraft:glowstone)
B(3,7,-3,minecraft:glowstone)
B(3,0,-2,minecraft:glowstone)
B(3,1,-2,minecraft:glowstone)
B(3,2,-2,minecraft:glowstone)
B(3,3,-2,minecraft:glowstone)
B(3,4,-2,minecraft:glowstone)
B(3,5,-2,minecraft:glowstone)
B(3,6,-2,minecraft:glowstone)
B(3,0,-1,minecraft:glowstone)
B(3,1,-1,minecraft:glowstone)
B(3,2,-1,minecraft:glowstone)
B(3,3,-1,minecraft:glowstone)
B(3,4,-1,minecraft:glowstone)
B(3,5,-1,minecraft:glowstone)
B(3,6,-1,minecraft:glowstone)
B(3,0,0,minecraft:glowstone)
B(3,1,0,minecraft:glowstone)
B(3,2,0,minecraft:glowstone)
B(3,3,0,minecraft:glowstone)
B(3,4,0,minecraft:glowstone)
B(3,5,0,minecraft:glowstone)
B(3,0,1,minecraft:glowstone)
B(3,1,1,minecraft:glowstone)
B(3,2,1,minecraft:glowstone)
B(3,3,1,minecraft:glowstone)
B(3,4,1,minecraft:glowstone)
B(3,5,1,minecraft:glowstone)
B(3,0,2,minecraft:glowstone)
B(3,1,2,minecraft:glowstone)
B(3,2,2,minecraft:glowstone)
B(3,3,2,minecraft:glowstone)
B(3,4,2,minecraft:glowstone)
B(3,0,3,minecraft:glowstone)
B(3,1,3,minecraft:glowstone)
B(3,2,3,minecraft:glowstone)
B(3,3,3,minecraft:glowstone)
B(3,4,3,minecraft:glowstone)
B(3,0,4,minecraft:glowstone)
B(3,1,4,minecraft:glowstone)
B(3,2,4,minecraft:glowstone)
B(3,3,4,minecraft:glowstone)
B(3,0,5,minecraft:glowstone)
B(3,1,5,minecraft:glowstone)
B(3,2,5,minecraft:glowstone)
B(3,3,5,minecraft:glowstone)
B(3,0,6,minecraft:glowstone)
B(3,1,6,minecraft:glowstone)
B(3,2,6,minecraft:glowstone)
B(3,0,7,minecraft:glowstone)
B(3,1,7,minecraft:glowstone)
B(3,0,8,minecraft:glowstone)
B(3,1,8,minecraft:glowstone)
B(3,0,9,minecraft:glowstone)
B(4,7,-8,minecraft:glowstone)
B(4,8,-8,minecraft:glowstone)
B(4,4,-7,minecraft:glowstone)
B(4,5,-7,minecraft:glowstone)
B(4,6,-7,minecraft:glowstone)
B(4,7,-7,minecraft:glowstone)
B(4,8,-7,minecraft:glowstone)
B(4,2,-6,minecraft:glowstone)
B(4,3,-6,minecraft:glowstone)
B(4,4,-6,minecraft:glowstone)
B(4,5,-6,minecraft:glowstone)
B(4,6,-6,minecraft:glowstone)
B(4,7,-6,minecraft:glowstone)
B(4,8,-6,minecraft:glowstone)
B(4,1,-5,minecraft:glowstone)
B(4,2,-5,minecraft:glowstone)
B(4,3,-5,minecraft:glowstone)
B(4,4,-5,minecraft:glowstone)
B(4,5,-5,minecraft:glowstone)
B(4,6,-5,minecraft:glowstone)
B(4,7,-5,minecraft:glowstone)
B(4,8,-5,minecraft:glowstone)
B(4,0,-4,minecraft:glowstone)
B(4,1,-4,minecraft:glowstone)
B(4,2,-4,minecraft:glowstone)
B(4,3,-4,minecraft:glowstone)
B(4,4,-4,minecraft:glowstone)
B(4,5,-4,minecraft:glowstone)
B(4,6,-4,minecraft:glowstone)
B(4,7,-4,minecraft:glowstone)
B(4,0,-3,minecraft:glowstone)
B(4,1,-3,minecraft:glowstone)
B(4,2,-3,minecraft:glowstone)
B(4,3,-3,minecraft:glowstone)
B(4,4,-3,minecraft:glowstone)
B(4,5,-3,minecraft:glowstone)
B(4,6,-3,minecraft:glowstone)
B(4,7,-3,minecraft:glowstone)
B(4,0,-2,minecraft:glowstone)
B(4,1,-2,minecraft:glowstone)
B(4,2,-2,minecraft:glowstone)
B(4,3,-2,minecraft:glowstone)
B(4,4,-2,minecraft:glowstone)
B(4,5,-2,minecraft:glowstone)
B(4,6,-2,minecraft:glowstone)
B(4,7,-2,minecraft:glowstone)
B(4,0,-1,minecraft:glowstone)
B(4,1,-1,minecraft:glowstone)
B(4,2,-1,minecraft:glowstone)
B(4,3,-1,minecraft:glowstone)
B(4,4,-1,minecraft:glowstone)
B(4,5,-1,minecraft:glowstone)
B(4,6,-1,minecraft:glowstone)
B(4,0,0,minecraft:glowstone)
B(4,1,0,minecraft:glowstone)
B(4,2,0,minecraft:glowstone)
B(4,3,0,minecraft:glowstone)
B(4,4,0,minecraft:glowstone)
B(4,5,0,minecraft:glowstone)
B(4,6,0,minecraft:glowstone)
B(4,0,1,minecraft:glowstone)
B(4,1,1,minecraft:glowstone)
B(4,2,1,minecraft:glowstone)
B(4,3,1,minecraft:glowstone)
B(4,4,1,minecraft:glowstone)
B(4,5,1,minecraft:glowstone)
B(4,0,2,minecraft:glowstone)
B(4,1,2,minecraft:glowstone)
B(4,2,2,minecraft:glowstone)
B(4,3,2,minecraft:glowstone)
B(4,4,2,minecraft:glowstone)
B(4,5,2,minecraft:glowstone)
B(4,0,3,minecraft:glowstone)
B(4,1,3,minecraft:glowstone)
B(4,2,3,minecraft:glowstone)
B(4,3,3,minecraft:glowstone)
B(4,4,3,minecraft:glowstone)
B(4,0,4,minecraft:glowstone)
B(4,1,4,minecraft:glowstone)
B(4,2,4,minecraft:glowstone)
B(4,3,4,minecraft:glowstone)
B(4,0,5,minecraft:glowstone)
B(4,1,5,minecraft:glowstone)
B(4,2,5,minecraft:glowstone)
B(4,0,6,minecraft:glowstone)
B(4,1,6,minecraft:glowstone)
B(4,2,6,minecraft:glowstone)
B(4,0,7,minecraft:glowstone)
B(4,1,7,minecraft:glowstone)
B(4,0,8,minecraft:glowstone)
B(4,0,9,minecraft:glowstone)
B(5,7,-8,minecraft:glowstone)
B(5,8,-8,minecraft:glowstone)
B(5,9,-8,minecraft:glowstone)
B(5,5,-7,minecraft:glowstone)
B(5,6,-7,minecraft:glowstone)
B(5,7,-7,minecraft:glowstone)
B(5,8,-7,minecraft:glowstone)
B(5,9,-7,minecraft:glowstone)
B(5,3,-6,minecraft:glowstone)
B(5,4,-6,minecraft:glowstone)
B(5,5,-6,minecraft:glowstone)
B(5,6,-6,minecraft:glowstone)
B(5,7,-6,minecraft:glowstone)
B(5,8,-6,minecraft:glowstone)
B(5,9,-6,minecraft:glowstone)
B(5,2,-5,minecraft:glowstone)
B(5,3,-5,minecraft:glowstone)
B(5,4,-5,minecraft:glowstone)
B(5,5,-5,minecraft:glowstone)
B(5,6,-5,minecraft:glowstone)
B(5,7,-5,minecraft:glowstone)
B(5,8,-5,minecraft:glowstone)
B(5,1,-4,minecraft:glowstone)
B(5,2,-4,minecraft:glowstone)
B(5,3,-4,minecraft:glowstone)
B(5,4,-4,minecraft:glowstone)
B(5,5,-4,minecraft:glowstone)
B(5,6,-4,minecraft:glowstone)
B(5,7,-4,minecraft:glowstone)
B(5,8,-4,minecraft:glowstone)
B(5,0,-3,minecraft:glowstone)
B(5,1,-3,minecraft:glowstone)
B(5,2,-3,minecraft:glowstone)
B(5,3,-3,minecraft:glowstone)
B(5,4,-3,minecraft:glowstone)
B(5,5,-3,minecraft:glowstone)
B(5,6,-3,minecraft:glowstone)
B(5,7,-3,minecraft:glowstone)
B(5,0,-2,minecraft:glowstone)
B(5,1,-2,minecraft:glowstone)
B(5,2,-2,minecraft:glowstone)
B(5,3,-2,minecraft:glowstone)
B(5,4,-2,minecraft:glowstone)
B(5,5,-2,minecraft:glowstone)
B(5,6,-2,minecraft:glowstone)
B(5,7,-2,minecraft:glowstone)
B(5,0,-1,minecraft:glowstone)
B(5,1,-1,minecraft:glowstone)
B(5,2,-1,minecraft:glowstone)
B(5,3,-1,minecraft:glowstone)
B(5,4,-1,minecraft:glowstone)
B(5,5,-1,minecraft:glowstone)
B(5,6,-1,minecraft:glowstone)
B(5,0,0,minecraft:glowstone)
B(5,1,0,minecraft:glowstone)
B(5,2,0,minecraft:glowstone)
B(5,3,0,minecraft:glowstone)
B(5,4,0,minecraft:glowstone)
B(5,5,0,minecraft:glowstone)
B(5,6,0,minecraft:glowstone)
B(5,0,1,minecraft:glowstone)
B(5,1,1,minecraft:glowstone)
B(5,2,1,minecraft:glowstone)
B(5,3,1,minecraft:glowstone)
B(5,4,1,minecraft:glowstone)
B(5,5,1,minecraft:glowstone)
B(5,0,2,minecraft:glowstone)
B(5,1,2,minecraft:glowstone)
B(5,2,2,minecraft:glowstone)
B(5,3,2,minecraft:glowstone)
B(5,4,2,minecraft:glowstone)
B(5,0,3,minecraft:glowstone)
B(5,1,3,minecraft:glowstone)
B(5,2,3,minecraft:glowstone)
B(5,3,3,minecraft:glowstone)
B(5,0,4,minecraft:glowstone)
B(5,1,4,minecraft:glowstone)
B(5,2,4,minecraft:glowstone)
B(5,3,4,minecraft:glowstone)
B(5,0,5,minecraft:glowstone)
B(5,1,5,minecraft:glowstone)
B(5,2,5,minecraft:glowstone)
B(5,0,6,minecraft:glowstone)
B(5,1,6,minecraft:glowstone)
B(5,0,7,minecraft:glowstone)
B(5,0,8,minecraft:glowstone)
B(6,10,-9,minecraft:glowstone)
B(6,7,-8,minecraft:glowstone)
B(6,8,-8,minecraft:glowstone)
B(6,9,-8,minecraft:glowstone)
B(6,10,-8,minecraft:glowstone)
B(6,6,-7,minecraft:glowstone)
B(6,7,-7,minecraft:glowstone)
B(6,8,-7,minecraft:glowstone)
B(6,9,-7,minecraft:glowstone)
B(6,5,-6,minecraft:glowstone)
B(6,6,-6,minecraft:glowstone)
B(6,7,-6,minecraft:glowstone)
B(6,8,-6,minecraft:glowstone)
B(6,9,-6,minecraft:glowstone)
B(6,4,-5,minecraft:glowstone)
B(6,5,-5,minecraft:glowstone)
B(6,6,-5,minecraft:glowstone)
B(6,7,-5,minecraft:glowstone)
B(6,8,-5,minecraft:glowstone)
B(6,9,-5,minecraft:glowstone)
B(6,3,-4,minecraft:glowstone)
B(6,4,-4,minecraft:glowstone)
B(6,5,-4,minecraft:glowstone)
B(6,6,-4,minecraft:glowstone)
B(6,7,-4,minecraft:glowstone)
B(6,8,-4,minecraft:glowstone)
B(6,1,-3,minecraft:glowstone)
B(6,2,-3,minecraft:glowstone)
B(6,3,-3,minecraft:glowstone)
B(6,4,-3,minecraft:glowstone)
B(6,5,-3,minecraft:glowstone)
B(6,6,-3,minecraft:glowstone)
B(6,7,-3,minecraft:glowstone)
B(6,0,-2,minecraft:glowstone)
B(6,1,-2,minecraft:glowstone)
B(6,2,-2,minecraft:glowstone)
B(6,3,-2,minecraft:glowstone)
B(6,4,-2,minecraft:glowstone)
B(6,5,-2,minecraft:glowstone)
B(6,6,-2,minecraft:glowstone)
B(6,7,-2,minecraft:glowstone)
B(6,0,-1,minecraft:glowstone)
B(6,1,-1,minecraft:glowstone)
B(6,2,-1,minecraft:glowstone)
B(6,3,-1,minecraft:glowstone)
B(6,4,-1,minecraft:glowstone)
B(6,5,-1,minecraft:glowstone)
B(6,6,-1,minecraft:glowstone)
B(6,0,0,minecraft:glowstone)
B(6,1,0,minecraft:glowstone)
B(6,2,0,minecraft:glowstone)
B(6,3,0,minecraft:glowstone)
B(6,4,0,minecraft:glowstone)
B(6,5,0,minecraft:glowstone)
B(6,0,1,minecraft:glowstone)
B(6,1,1,minecraft:glowstone)
B(6,2,1,minecraft:glowstone)
B(6,3,1,minecraft:glowstone)
B(6,4,1,minecraft:glowstone)
B(6,0,2,minecraft:glowstone)
B(6,1,2,minecraft:glowstone)
B(6,2,2,minecraft:glowstone)
B(6,3,2,minecraft:glowstone)
B(6,4,2,minecraft:glowstone)
B(6,0,3,minecraft:glowstone)
B(6,1,3,minecraft:glowstone)
B(6,2,3,minecraft:glowstone)
B(6,3,3,minecraft:glowstone)
B(6,0,4,minecraft:glowstone)
B(6,1,4,minecraft:glowstone)
B(6,2,4,minecraft:glowstone)
B(6,0,5,minecraft:glowstone)
B(6,1,5,minecraft:glowstone)
B(6,0,6,minecraft:glowstone)
B(6,1,6,minecraft:glowstone)
B(6,0,7,minecraft:glowstone)
B(7,10,-9,minecraft:glowstone)
B(7,11,-9,minecraft:glowstone)
B(7,9,-8,minecraft:glowstone)
B(7,10,-8,minecraft:glowstone)
B(7,8,-7,minecraft:glowstone)
B(7,9,-7,minecraft:glowstone)
B(7,10,-7,minecraft:glowstone)
B(7,6,-6,minecraft:glowstone)
B(7,7,-6,minecraft:glowstone)
B(7,8,-6,minecraft:glowstone)
B(7,9,-6,minecraft:glowstone)
B(7,5,-5,minecraft:glowstone)
B(7,6,-5,minecraft:glowstone)
B(7,7,-5,minecraft:glowstone)
B(7,8,-5,minecraft:glowstone)
B(7,4,-4,minecraft:glowstone)
B(7,5,-4,minecraft:glowstone)
B(7,6,-4,minecraft:glowstone)
B(7,7,-4,minecraft:glowstone)
B(7,8,-4,minecraft:glowstone)
B(7,3,-3,minecraft:glowstone)
B(7,4,-3,minecraft:glowstone)
B(7,5,-3,minecraft:glowstone)
B(7,6,-3,minecraft:glowstone)
B(7,7,-3,minecraft:glowstone)
B(7,2,-2,minecraft:glowstone)
B(7,3,-2,minecraft:glowstone)
B(7,4,-2,minecraft:glowstone)
B(7,5,-2,minecraft:glowstone)
B(7,6,-2,minecraft:glowstone)
B(7,0,-1,minecraft:glowstone)
B(7,1,-1,minecraft:glowstone)
B(7,2,-1,minecraft:glowstone)
B(7,3,-1,minecraft:glowstone)
B(7,4,-1,minecraft:glowstone)
B(7,5,-1,minecraft:glowstone)
B(7,0,0,minecraft:glowstone)
B(7,1,0,minecraft:glowstone)
B(7,2,0,minecraft:glowstone)
B(7,3,0,minecraft:glowstone)
B(7,4,0,minecraft:glowstone)
B(7,5,0,minecraft:glowstone)
B(7,0,1,minecraft:glowstone)
B(7,1,1,minecraft:glowstone)
B(7,2,1,minecraft:glowstone)
B(7,3,1,minecraft:glowstone)
B(7,4,1,minecraft:glowstone)
B(7,0,2,minecraft:glowstone)
B(7,1,2,minecraft:glowstone)
B(7,2,2,minecraft:glowstone)
B(7,3,2,minecraft:glowstone)
B(7,0,3,minecraft:glowstone)
B(7,1,3,minecraft:glowstone)
B(7,2,3,minecraft:glowstone)
B(7,0,4,minecraft:glowstone)
B(7,1,4,minecraft:glowstone)
B(7,2,4,minecraft:glowstone)
B(7,0,5,minecraft:glowstone)
B(7,1,5,minecraft:glowstone)
B(7,0,6,minecraft:glowstone)
B(7,0,7,minecraft:glowstone)

#######################################################################
# +-----------------------------------------------------------------+ #
# |                            BO3 checks                           | #
# +-----------------------------------------------------------------+ #
#######################################################################

BlockCheckNot(0,-1,0,minecraft:air)
BlockCheckNot(-8,-1,-5,minecraft:air)
BlockCheckNot(-8,-1,7,minecraft:air)
BlockCheckNot(7,-1,-5,minecraft:air)
BlockCheckNot(7,-1,7,minecraft:air)

#######################################################################
# +-----------------------------------------------------------------+ #
# |                             Branches                            | #
# +-----------------------------------------------------------------+ #
#######################################################################


#######################################################################
# +-----------------------------------------------------------------+ #
# |                             Entities                            | #
# +-----------------------------------------------------------------+ #
#######################################################################

