# ------------------------------------------------------------------- #
# "THE I WOULD LICENSE THIS UNDER BEER-WARE BUT I DON'T DRINK SO I'LL HAVE A DOUGHNUT INSTEAD LICENSE"
# <frank@infotoast.org> wrote this file.  As long as you retain this notice you
# can do whatever you want with this stuff. If we meet some day, and you think
# this stuff is worth it, you can buy me a doughnut in return.
# ------------------------------------------------------------------- #

#######################################################################
# +-----------------------------------------------------------------+ #
# |                            BO3 object                           | #
# +-----------------------------------------------------------------+ #
#######################################################################

Author: Frank

Description: Medium glowstone spike

Version: 3

SettingsMode: WriteDisable


#######################################################################
# +-----------------------------------------------------------------+ #
# |                          Main settings                          | #
# +-----------------------------------------------------------------+ #
#######################################################################

Tree: true

Frequency: 10

Rarity: 100.0

MaxSpawn: 1

RotateRandomly: true

SpawnHeight: randomY

SpawnHeightOffset: 0

SpawnHeightVariance: 0

##############################
# Height Limits for the BO3. #
##############################

MinHeight: 50

MaxHeight: 65

######################
# Extrusion settings #
######################

ExtrudeMode: None

ExtrudeThroughBlocks: minecraft:air

MaxBranchDepth: 10


#######################################################################
# +-----------------------------------------------------------------+ #
# |                      Source block settings                      | #
# +-----------------------------------------------------------------+ #
#######################################################################

SourceBlocks: minecraft:air

MaxPercentageOutsideSourceBlock: 60

OutsideSourceBlock: placeAnyway

DoReplaceBlocks: true

IsOTGPlus: false


#######################################################################
# +-----------------------------------------------------------------+ #
# |                              Blocks                             | #
# +-----------------------------------------------------------------+ #
#######################################################################

B(-7,0,-7,minecraft:glowstone)
B(-6,0,-8,minecraft:glowstone)
B(-6,0,-7,minecraft:glowstone)
B(-6,0,-6,minecraft:glowstone)
B(-6,0,-5,minecraft:glowstone)
B(-5,0,-10,minecraft:glowstone)
B(-5,0,-9,minecraft:glowstone)
B(-5,0,-8,minecraft:glowstone)
B(-5,0,-7,minecraft:glowstone)
B(-5,1,-7,minecraft:glowstone)
B(-5,0,-6,minecraft:glowstone)
B(-5,1,-6,minecraft:glowstone)
B(-5,0,-5,minecraft:glowstone)
B(-5,1,-5,minecraft:glowstone)
B(-5,0,-4,minecraft:glowstone)
B(-5,1,-4,minecraft:glowstone)
B(-5,0,-3,minecraft:glowstone)
B(-5,1,-3,minecraft:glowstone)
B(-4,0,-12,minecraft:glowstone)
B(-4,0,-11,minecraft:glowstone)
B(-4,0,-10,minecraft:glowstone)
B(-4,0,-9,minecraft:glowstone)
B(-4,0,-8,minecraft:glowstone)
B(-4,1,-8,minecraft:glowstone)
B(-4,0,-7,minecraft:glowstone)
B(-4,1,-7,minecraft:glowstone)
B(-4,0,-6,minecraft:glowstone)
B(-4,1,-6,minecraft:glowstone)
B(-4,0,-5,minecraft:glowstone)
B(-4,1,-5,minecraft:glowstone)
B(-4,2,-5,minecraft:glowstone)
B(-4,0,-4,minecraft:glowstone)
B(-4,1,-4,minecraft:glowstone)
B(-4,2,-4,minecraft:glowstone)
B(-4,0,-3,minecraft:glowstone)
B(-4,1,-3,minecraft:glowstone)
B(-4,2,-3,minecraft:glowstone)
B(-4,0,-2,minecraft:glowstone)
B(-4,1,-2,minecraft:glowstone)
B(-4,2,-2,minecraft:glowstone)
B(-4,3,-2,minecraft:glowstone)
B(-4,0,-1,minecraft:glowstone)
B(-4,1,-1,minecraft:glowstone)
B(-4,2,-1,minecraft:glowstone)
B(-4,0,0,minecraft:glowstone)
B(-3,0,-12,minecraft:glowstone)
B(-3,0,-11,minecraft:glowstone)
B(-3,0,-10,minecraft:glowstone)
B(-3,0,-9,minecraft:glowstone)
B(-3,1,-9,minecraft:glowstone)
B(-3,0,-8,minecraft:glowstone)
B(-3,1,-8,minecraft:glowstone)
B(-3,0,-7,minecraft:glowstone)
B(-3,1,-7,minecraft:glowstone)
B(-3,2,-7,minecraft:glowstone)
B(-3,0,-6,minecraft:glowstone)
B(-3,1,-6,minecraft:glowstone)
B(-3,2,-6,minecraft:glowstone)
B(-3,0,-5,minecraft:glowstone)
B(-3,1,-5,minecraft:glowstone)
B(-3,2,-5,minecraft:glowstone)
B(-3,0,-4,minecraft:glowstone)
B(-3,1,-4,minecraft:glowstone)
B(-3,2,-4,minecraft:glowstone)
B(-3,3,-4,minecraft:glowstone)
B(-3,0,-3,minecraft:glowstone)
B(-3,1,-3,minecraft:glowstone)
B(-3,2,-3,minecraft:glowstone)
B(-3,3,-3,minecraft:glowstone)
B(-3,0,-2,minecraft:glowstone)
B(-3,1,-2,minecraft:glowstone)
B(-3,2,-2,minecraft:glowstone)
B(-3,3,-2,minecraft:glowstone)
B(-3,0,-1,minecraft:glowstone)
B(-3,1,-1,minecraft:glowstone)
B(-3,2,-1,minecraft:glowstone)
B(-3,3,-1,minecraft:glowstone)
B(-3,0,0,minecraft:glowstone)
B(-3,1,0,minecraft:glowstone)
B(-3,2,0,minecraft:glowstone)
B(-3,3,0,minecraft:glowstone)
B(-3,4,0,minecraft:glowstone)
B(-3,0,1,minecraft:glowstone)
B(-3,1,1,minecraft:glowstone)
B(-3,2,1,minecraft:glowstone)
B(-3,3,1,minecraft:glowstone)
B(-3,0,2,minecraft:glowstone)
B(-3,1,2,minecraft:glowstone)
B(-2,0,-12,minecraft:glowstone)
B(-2,0,-11,minecraft:glowstone)
B(-2,0,-10,minecraft:glowstone)
B(-2,0,-9,minecraft:glowstone)
B(-2,1,-9,minecraft:glowstone)
B(-2,0,-8,minecraft:glowstone)
B(-2,1,-8,minecraft:glowstone)
B(-2,0,-7,minecraft:glowstone)
B(-2,1,-7,minecraft:glowstone)
B(-2,2,-7,minecraft:glowstone)
B(-2,0,-6,minecraft:glowstone)
B(-2,1,-6,minecraft:glowstone)
B(-2,2,-6,minecraft:glowstone)
B(-2,0,-5,minecraft:glowstone)
B(-2,1,-5,minecraft:glowstone)
B(-2,2,-5,minecraft:glowstone)
B(-2,3,-5,minecraft:glowstone)
B(-2,0,-4,minecraft:glowstone)
B(-2,1,-4,minecraft:glowstone)
B(-2,2,-4,minecraft:glowstone)
B(-2,3,-4,minecraft:glowstone)
B(-2,0,-3,minecraft:glowstone)
B(-2,1,-3,minecraft:glowstone)
B(-2,2,-3,minecraft:glowstone)
B(-2,3,-3,minecraft:glowstone)
B(-2,0,-2,minecraft:glowstone)
B(-2,1,-2,minecraft:glowstone)
B(-2,2,-2,minecraft:glowstone)
B(-2,3,-2,minecraft:glowstone)
B(-2,4,-2,minecraft:glowstone)
B(-2,0,-1,minecraft:glowstone)
B(-2,1,-1,minecraft:glowstone)
B(-2,2,-1,minecraft:glowstone)
B(-2,3,-1,minecraft:glowstone)
B(-2,4,-1,minecraft:glowstone)
B(-2,0,0,minecraft:glowstone)
B(-2,1,0,minecraft:glowstone)
B(-2,2,0,minecraft:glowstone)
B(-2,3,0,minecraft:glowstone)
B(-2,4,0,minecraft:glowstone)
B(-2,0,1,minecraft:glowstone)
B(-2,1,1,minecraft:glowstone)
B(-2,2,1,minecraft:glowstone)
B(-2,3,1,minecraft:glowstone)
B(-2,4,1,minecraft:glowstone)
B(-2,5,1,minecraft:glowstone)
B(-2,0,2,minecraft:glowstone)
B(-2,1,2,minecraft:glowstone)
B(-2,2,2,minecraft:glowstone)
B(-2,3,2,minecraft:glowstone)
B(-2,4,2,minecraft:glowstone)
B(-2,5,2,minecraft:glowstone)
B(-2,0,3,minecraft:glowstone)
B(-2,1,3,minecraft:glowstone)
B(-2,2,3,minecraft:glowstone)
B(-2,3,3,minecraft:glowstone)
B(-2,0,4,minecraft:glowstone)
B(-2,1,4,minecraft:glowstone)
B(-2,0,5,minecraft:glowstone)
B(-1,0,-12,minecraft:glowstone)
B(-1,0,-11,minecraft:glowstone)
B(-1,0,-10,minecraft:glowstone)
B(-1,0,-9,minecraft:glowstone)
B(-1,1,-9,minecraft:glowstone)
B(-1,0,-8,minecraft:glowstone)
B(-1,1,-8,minecraft:glowstone)
B(-1,0,-7,minecraft:glowstone)
B(-1,1,-7,minecraft:glowstone)
B(-1,2,-7,minecraft:glowstone)
B(-1,0,-6,minecraft:glowstone)
B(-1,1,-6,minecraft:glowstone)
B(-1,2,-6,minecraft:glowstone)
B(-1,0,-5,minecraft:glowstone)
B(-1,1,-5,minecraft:glowstone)
B(-1,2,-5,minecraft:glowstone)
B(-1,3,-5,minecraft:glowstone)
B(-1,0,-4,minecraft:glowstone)
B(-1,1,-4,minecraft:glowstone)
B(-1,2,-4,minecraft:glowstone)
B(-1,3,-4,minecraft:glowstone)
B(-1,0,-3,minecraft:glowstone)
B(-1,1,-3,minecraft:glowstone)
B(-1,2,-3,minecraft:glowstone)
B(-1,3,-3,minecraft:glowstone)
B(-1,4,-3,minecraft:glowstone)
B(-1,0,-2,minecraft:glowstone)
B(-1,1,-2,minecraft:glowstone)
B(-1,2,-2,minecraft:glowstone)
B(-1,3,-2,minecraft:glowstone)
B(-1,4,-2,minecraft:glowstone)
B(-1,0,-1,minecraft:glowstone)
B(-1,1,-1,minecraft:glowstone)
B(-1,2,-1,minecraft:glowstone)
B(-1,3,-1,minecraft:glowstone)
B(-1,4,-1,minecraft:glowstone)
B(-1,5,-1,minecraft:glowstone)
B(-1,0,0,minecraft:glowstone)
B(-1,1,0,minecraft:glowstone)
B(-1,2,0,minecraft:glowstone)
B(-1,3,0,minecraft:glowstone)
B(-1,4,0,minecraft:glowstone)
B(-1,5,0,minecraft:glowstone)
B(-1,0,1,minecraft:glowstone)
B(-1,1,1,minecraft:glowstone)
B(-1,2,1,minecraft:glowstone)
B(-1,3,1,minecraft:glowstone)
B(-1,4,1,minecraft:glowstone)
B(-1,5,1,minecraft:glowstone)
B(-1,0,2,minecraft:glowstone)
B(-1,1,2,minecraft:glowstone)
B(-1,2,2,minecraft:glowstone)
B(-1,3,2,minecraft:glowstone)
B(-1,4,2,minecraft:glowstone)
B(-1,5,2,minecraft:glowstone)
B(-1,0,3,minecraft:glowstone)
B(-1,1,3,minecraft:glowstone)
B(-1,2,3,minecraft:glowstone)
B(-1,3,3,minecraft:glowstone)
B(-1,4,3,minecraft:glowstone)
B(-1,5,3,minecraft:glowstone)
B(-1,6,3,minecraft:glowstone)
B(-1,0,4,minecraft:glowstone)
B(-1,1,4,minecraft:glowstone)
B(-1,2,4,minecraft:glowstone)
B(-1,3,4,minecraft:glowstone)
B(-1,4,4,minecraft:glowstone)
B(-1,5,4,minecraft:glowstone)
B(-1,6,4,minecraft:glowstone)
B(-1,1,5,minecraft:glowstone)
B(-1,2,5,minecraft:glowstone)
B(-1,3,5,minecraft:glowstone)
B(-1,4,5,minecraft:glowstone)
B(-1,2,6,minecraft:glowstone)
B(0,0,-12,minecraft:glowstone)
B(0,0,-11,minecraft:glowstone)
B(0,0,-10,minecraft:glowstone)
B(0,0,-9,minecraft:glowstone)
B(0,1,-9,minecraft:glowstone)
B(0,0,-8,minecraft:glowstone)
B(0,1,-8,minecraft:glowstone)
B(0,0,-7,minecraft:glowstone)
B(0,1,-7,minecraft:glowstone)
B(0,2,-7,minecraft:glowstone)
B(0,0,-6,minecraft:glowstone)
B(0,1,-6,minecraft:glowstone)
B(0,2,-6,minecraft:glowstone)
B(0,0,-5,minecraft:glowstone)
B(0,1,-5,minecraft:glowstone)
B(0,2,-5,minecraft:glowstone)
B(0,3,-5,minecraft:glowstone)
B(0,0,-4,minecraft:glowstone)
B(0,1,-4,minecraft:glowstone)
B(0,2,-4,minecraft:glowstone)
B(0,3,-4,minecraft:glowstone)
B(0,0,-3,minecraft:glowstone)
B(0,1,-3,minecraft:glowstone)
B(0,2,-3,minecraft:glowstone)
B(0,3,-3,minecraft:glowstone)
B(0,4,-3,minecraft:glowstone)
B(0,0,-2,minecraft:glowstone)
B(0,1,-2,minecraft:glowstone)
B(0,2,-2,minecraft:glowstone)
B(0,3,-2,minecraft:glowstone)
B(0,4,-2,minecraft:glowstone)
B(0,0,-1,minecraft:glowstone)
B(0,1,-1,minecraft:glowstone)
B(0,2,-1,minecraft:glowstone)
B(0,3,-1,minecraft:glowstone)
B(0,4,-1,minecraft:glowstone)
B(0,5,-1,minecraft:glowstone)
B(0,0,0,minecraft:glowstone)
B(0,1,0,minecraft:glowstone)
B(0,2,0,minecraft:glowstone)
B(0,3,0,minecraft:glowstone)
B(0,4,0,minecraft:glowstone)
B(0,5,0,minecraft:glowstone)
B(0,0,1,minecraft:glowstone)
B(0,1,1,minecraft:glowstone)
B(0,2,1,minecraft:glowstone)
B(0,3,1,minecraft:glowstone)
B(0,4,1,minecraft:glowstone)
B(0,5,1,minecraft:glowstone)
B(0,6,1,minecraft:glowstone)
B(0,0,2,minecraft:glowstone)
B(0,1,2,minecraft:glowstone)
B(0,2,2,minecraft:glowstone)
B(0,3,2,minecraft:glowstone)
B(0,4,2,minecraft:glowstone)
B(0,5,2,minecraft:glowstone)
B(0,6,2,minecraft:glowstone)
B(0,0,3,minecraft:glowstone)
B(0,1,3,minecraft:glowstone)
B(0,2,3,minecraft:glowstone)
B(0,3,3,minecraft:glowstone)
B(0,4,3,minecraft:glowstone)
B(0,5,3,minecraft:glowstone)
B(0,6,3,minecraft:glowstone)
B(0,0,4,minecraft:glowstone)
B(0,1,4,minecraft:glowstone)
B(0,2,4,minecraft:glowstone)
B(0,3,4,minecraft:glowstone)
B(0,4,4,minecraft:glowstone)
B(0,5,4,minecraft:glowstone)
B(0,6,4,minecraft:glowstone)
B(0,7,4,minecraft:glowstone)
B(0,1,5,minecraft:glowstone)
B(0,2,5,minecraft:glowstone)
B(0,3,5,minecraft:glowstone)
B(0,4,5,minecraft:glowstone)
B(0,5,5,minecraft:glowstone)
B(0,6,5,minecraft:glowstone)
B(0,7,5,minecraft:glowstone)
B(0,2,6,minecraft:glowstone)
B(0,3,6,minecraft:glowstone)
B(0,4,6,minecraft:glowstone)
B(0,5,6,minecraft:glowstone)
B(0,6,6,minecraft:glowstone)
B(0,7,6,minecraft:glowstone)
B(0,4,7,minecraft:glowstone)
B(0,5,7,minecraft:glowstone)
B(1,0,-12,minecraft:glowstone)
B(1,0,-11,minecraft:glowstone)
B(1,0,-10,minecraft:glowstone)
B(1,0,-9,minecraft:glowstone)
B(1,1,-9,minecraft:glowstone)
B(1,0,-8,minecraft:glowstone)
B(1,1,-8,minecraft:glowstone)
B(1,0,-7,minecraft:glowstone)
B(1,1,-7,minecraft:glowstone)
B(1,2,-7,minecraft:glowstone)
B(1,0,-6,minecraft:glowstone)
B(1,1,-6,minecraft:glowstone)
B(1,2,-6,minecraft:glowstone)
B(1,0,-5,minecraft:glowstone)
B(1,1,-5,minecraft:glowstone)
B(1,2,-5,minecraft:glowstone)
B(1,3,-5,minecraft:glowstone)
B(1,0,-4,minecraft:glowstone)
B(1,1,-4,minecraft:glowstone)
B(1,2,-4,minecraft:glowstone)
B(1,3,-4,minecraft:glowstone)
B(1,0,-3,minecraft:glowstone)
B(1,1,-3,minecraft:glowstone)
B(1,2,-3,minecraft:glowstone)
B(1,3,-3,minecraft:glowstone)
B(1,4,-3,minecraft:glowstone)
B(1,0,-2,minecraft:glowstone)
B(1,1,-2,minecraft:glowstone)
B(1,2,-2,minecraft:glowstone)
B(1,3,-2,minecraft:glowstone)
B(1,4,-2,minecraft:glowstone)
B(1,0,-1,minecraft:glowstone)
B(1,1,-1,minecraft:glowstone)
B(1,2,-1,minecraft:glowstone)
B(1,3,-1,minecraft:glowstone)
B(1,4,-1,minecraft:glowstone)
B(1,5,-1,minecraft:glowstone)
B(1,0,0,minecraft:glowstone)
B(1,1,0,minecraft:glowstone)
B(1,2,0,minecraft:glowstone)
B(1,3,0,minecraft:glowstone)
B(1,4,0,minecraft:glowstone)
B(1,5,0,minecraft:glowstone)
B(1,0,1,minecraft:glowstone)
B(1,1,1,minecraft:glowstone)
B(1,2,1,minecraft:glowstone)
B(1,3,1,minecraft:glowstone)
B(1,4,1,minecraft:glowstone)
B(1,5,1,minecraft:glowstone)
B(1,6,1,minecraft:glowstone)
B(1,0,2,minecraft:glowstone)
B(1,1,2,minecraft:glowstone)
B(1,2,2,minecraft:glowstone)
B(1,3,2,minecraft:glowstone)
B(1,4,2,minecraft:glowstone)
B(1,5,2,minecraft:glowstone)
B(1,6,2,minecraft:glowstone)
B(1,0,3,minecraft:glowstone)
B(1,1,3,minecraft:glowstone)
B(1,2,3,minecraft:glowstone)
B(1,3,3,minecraft:glowstone)
B(1,4,3,minecraft:glowstone)
B(1,5,3,minecraft:glowstone)
B(1,6,3,minecraft:glowstone)
B(1,7,3,minecraft:glowstone)
B(1,0,4,minecraft:glowstone)
B(1,1,4,minecraft:glowstone)
B(1,2,4,minecraft:glowstone)
B(1,3,4,minecraft:glowstone)
B(1,4,4,minecraft:glowstone)
B(1,5,4,minecraft:glowstone)
B(1,6,4,minecraft:glowstone)
B(1,7,4,minecraft:glowstone)
B(1,1,5,minecraft:glowstone)
B(1,2,5,minecraft:glowstone)
B(1,3,5,minecraft:glowstone)
B(1,4,5,minecraft:glowstone)
B(1,5,5,minecraft:glowstone)
B(1,6,5,minecraft:glowstone)
B(1,7,5,minecraft:glowstone)
B(1,3,6,minecraft:glowstone)
B(1,4,6,minecraft:glowstone)
B(1,5,6,minecraft:glowstone)
B(1,6,6,minecraft:glowstone)
B(1,7,6,minecraft:glowstone)
B(1,8,6,minecraft:glowstone)
B(1,4,7,minecraft:glowstone)
B(1,5,7,minecraft:glowstone)
B(1,6,7,minecraft:glowstone)
B(1,7,7,minecraft:glowstone)
B(1,8,7,minecraft:glowstone)
B(1,5,8,minecraft:glowstone)
B(1,6,8,minecraft:glowstone)
B(1,7,8,minecraft:glowstone)
B(1,6,9,minecraft:glowstone)
B(2,0,-12,minecraft:glowstone)
B(2,0,-11,minecraft:glowstone)
B(2,0,-10,minecraft:glowstone)
B(2,0,-9,minecraft:glowstone)
B(2,1,-9,minecraft:glowstone)
B(2,0,-8,minecraft:glowstone)
B(2,1,-8,minecraft:glowstone)
B(2,0,-7,minecraft:glowstone)
B(2,1,-7,minecraft:glowstone)
B(2,2,-7,minecraft:glowstone)
B(2,0,-6,minecraft:glowstone)
B(2,1,-6,minecraft:glowstone)
B(2,2,-6,minecraft:glowstone)
B(2,0,-5,minecraft:glowstone)
B(2,1,-5,minecraft:glowstone)
B(2,2,-5,minecraft:glowstone)
B(2,3,-5,minecraft:glowstone)
B(2,0,-4,minecraft:glowstone)
B(2,1,-4,minecraft:glowstone)
B(2,2,-4,minecraft:glowstone)
B(2,3,-4,minecraft:glowstone)
B(2,0,-3,minecraft:glowstone)
B(2,1,-3,minecraft:glowstone)
B(2,2,-3,minecraft:glowstone)
B(2,3,-3,minecraft:glowstone)
B(2,4,-3,minecraft:glowstone)
B(2,0,-2,minecraft:glowstone)
B(2,1,-2,minecraft:glowstone)
B(2,2,-2,minecraft:glowstone)
B(2,3,-2,minecraft:glowstone)
B(2,4,-2,minecraft:glowstone)
B(2,0,-1,minecraft:glowstone)
B(2,1,-1,minecraft:glowstone)
B(2,2,-1,minecraft:glowstone)
B(2,3,-1,minecraft:glowstone)
B(2,4,-1,minecraft:glowstone)
B(2,5,-1,minecraft:glowstone)
B(2,0,0,minecraft:glowstone)
B(2,1,0,minecraft:glowstone)
B(2,2,0,minecraft:glowstone)
B(2,3,0,minecraft:glowstone)
B(2,4,0,minecraft:glowstone)
B(2,5,0,minecraft:glowstone)
B(2,0,1,minecraft:glowstone)
B(2,1,1,minecraft:glowstone)
B(2,2,1,minecraft:glowstone)
B(2,3,1,minecraft:glowstone)
B(2,4,1,minecraft:glowstone)
B(2,5,1,minecraft:glowstone)
B(2,6,1,minecraft:glowstone)
B(2,0,2,minecraft:glowstone)
B(2,1,2,minecraft:glowstone)
B(2,2,2,minecraft:glowstone)
B(2,3,2,minecraft:glowstone)
B(2,4,2,minecraft:glowstone)
B(2,5,2,minecraft:glowstone)
B(2,6,2,minecraft:glowstone)
B(2,0,3,minecraft:glowstone)
B(2,1,3,minecraft:glowstone)
B(2,2,3,minecraft:glowstone)
B(2,3,3,minecraft:glowstone)
B(2,4,3,minecraft:glowstone)
B(2,5,3,minecraft:glowstone)
B(2,6,3,minecraft:glowstone)
B(2,7,3,minecraft:glowstone)
B(2,0,4,minecraft:glowstone)
B(2,1,4,minecraft:glowstone)
B(2,2,4,minecraft:glowstone)
B(2,3,4,minecraft:glowstone)
B(2,4,4,minecraft:glowstone)
B(2,5,4,minecraft:glowstone)
B(2,6,4,minecraft:glowstone)
B(2,7,4,minecraft:glowstone)
B(2,2,5,minecraft:glowstone)
B(2,3,5,minecraft:glowstone)
B(2,4,5,minecraft:glowstone)
B(2,5,5,minecraft:glowstone)
B(2,6,5,minecraft:glowstone)
B(2,7,5,minecraft:glowstone)
B(2,8,5,minecraft:glowstone)
B(2,3,6,minecraft:glowstone)
B(2,4,6,minecraft:glowstone)
B(2,5,6,minecraft:glowstone)
B(2,6,6,minecraft:glowstone)
B(2,7,6,minecraft:glowstone)
B(2,8,6,minecraft:glowstone)
B(2,4,7,minecraft:glowstone)
B(2,5,7,minecraft:glowstone)
B(2,6,7,minecraft:glowstone)
B(2,7,7,minecraft:glowstone)
B(2,8,7,minecraft:glowstone)
B(2,9,7,minecraft:glowstone)
B(2,6,8,minecraft:glowstone)
B(2,7,8,minecraft:glowstone)
B(2,8,8,minecraft:glowstone)
B(2,9,8,minecraft:glowstone)
B(2,7,9,minecraft:glowstone)
B(2,8,9,minecraft:glowstone)
B(2,9,9,minecraft:glowstone)
B(2,8,10,minecraft:glowstone)
B(3,0,-12,minecraft:glowstone)
B(3,0,-11,minecraft:glowstone)
B(3,0,-10,minecraft:glowstone)
B(3,0,-9,minecraft:glowstone)
B(3,1,-9,minecraft:glowstone)
B(3,0,-8,minecraft:glowstone)
B(3,1,-8,minecraft:glowstone)
B(3,0,-7,minecraft:glowstone)
B(3,1,-7,minecraft:glowstone)
B(3,2,-7,minecraft:glowstone)
B(3,0,-6,minecraft:glowstone)
B(3,1,-6,minecraft:glowstone)
B(3,2,-6,minecraft:glowstone)
B(3,0,-5,minecraft:glowstone)
B(3,1,-5,minecraft:glowstone)
B(3,2,-5,minecraft:glowstone)
B(3,3,-5,minecraft:glowstone)
B(3,0,-4,minecraft:glowstone)
B(3,1,-4,minecraft:glowstone)
B(3,2,-4,minecraft:glowstone)
B(3,3,-4,minecraft:glowstone)
B(3,0,-3,minecraft:glowstone)
B(3,1,-3,minecraft:glowstone)
B(3,2,-3,minecraft:glowstone)
B(3,3,-3,minecraft:glowstone)
B(3,4,-3,minecraft:glowstone)
B(3,0,-2,minecraft:glowstone)
B(3,1,-2,minecraft:glowstone)
B(3,2,-2,minecraft:glowstone)
B(3,3,-2,minecraft:glowstone)
B(3,4,-2,minecraft:glowstone)
B(3,0,-1,minecraft:glowstone)
B(3,1,-1,minecraft:glowstone)
B(3,2,-1,minecraft:glowstone)
B(3,3,-1,minecraft:glowstone)
B(3,4,-1,minecraft:glowstone)
B(3,5,-1,minecraft:glowstone)
B(3,0,0,minecraft:glowstone)
B(3,1,0,minecraft:glowstone)
B(3,2,0,minecraft:glowstone)
B(3,3,0,minecraft:glowstone)
B(3,4,0,minecraft:glowstone)
B(3,5,0,minecraft:glowstone)
B(3,0,1,minecraft:glowstone)
B(3,1,1,minecraft:glowstone)
B(3,2,1,minecraft:glowstone)
B(3,3,1,minecraft:glowstone)
B(3,4,1,minecraft:glowstone)
B(3,5,1,minecraft:glowstone)
B(3,6,1,minecraft:glowstone)
B(3,0,2,minecraft:glowstone)
B(3,1,2,minecraft:glowstone)
B(3,2,2,minecraft:glowstone)
B(3,3,2,minecraft:glowstone)
B(3,4,2,minecraft:glowstone)
B(3,5,2,minecraft:glowstone)
B(3,6,2,minecraft:glowstone)
B(3,0,3,minecraft:glowstone)
B(3,1,3,minecraft:glowstone)
B(3,2,3,minecraft:glowstone)
B(3,3,3,minecraft:glowstone)
B(3,4,3,minecraft:glowstone)
B(3,5,3,minecraft:glowstone)
B(3,6,3,minecraft:glowstone)
B(3,7,3,minecraft:glowstone)
B(3,1,4,minecraft:glowstone)
B(3,2,4,minecraft:glowstone)
B(3,3,4,minecraft:glowstone)
B(3,4,4,minecraft:glowstone)
B(3,5,4,minecraft:glowstone)
B(3,6,4,minecraft:glowstone)
B(3,7,4,minecraft:glowstone)
B(3,2,5,minecraft:glowstone)
B(3,3,5,minecraft:glowstone)
B(3,4,5,minecraft:glowstone)
B(3,5,5,minecraft:glowstone)
B(3,6,5,minecraft:glowstone)
B(3,7,5,minecraft:glowstone)
B(3,8,5,minecraft:glowstone)
B(3,3,6,minecraft:glowstone)
B(3,4,6,minecraft:glowstone)
B(3,5,6,minecraft:glowstone)
B(3,6,6,minecraft:glowstone)
B(3,7,6,minecraft:glowstone)
B(3,8,6,minecraft:glowstone)
B(3,5,7,minecraft:glowstone)
B(3,6,7,minecraft:glowstone)
B(3,7,7,minecraft:glowstone)
B(3,8,7,minecraft:glowstone)
B(3,9,7,minecraft:glowstone)
B(3,6,8,minecraft:glowstone)
B(3,7,8,minecraft:glowstone)
B(3,8,8,minecraft:glowstone)
B(3,9,8,minecraft:glowstone)
B(3,7,9,minecraft:glowstone)
B(3,8,9,minecraft:glowstone)
B(3,9,9,minecraft:glowstone)
B(3,10,9,minecraft:glowstone)
B(3,8,10,minecraft:glowstone)
B(3,9,10,minecraft:glowstone)
B(3,10,10,minecraft:glowstone)
B(3,10,11,minecraft:glowstone)
B(4,0,-12,minecraft:glowstone)
B(4,0,-11,minecraft:glowstone)
B(4,0,-10,minecraft:glowstone)
B(4,0,-9,minecraft:glowstone)
B(4,1,-9,minecraft:glowstone)
B(4,0,-8,minecraft:glowstone)
B(4,1,-8,minecraft:glowstone)
B(4,0,-7,minecraft:glowstone)
B(4,1,-7,minecraft:glowstone)
B(4,2,-7,minecraft:glowstone)
B(4,0,-6,minecraft:glowstone)
B(4,1,-6,minecraft:glowstone)
B(4,2,-6,minecraft:glowstone)
B(4,0,-5,minecraft:glowstone)
B(4,1,-5,minecraft:glowstone)
B(4,2,-5,minecraft:glowstone)
B(4,3,-5,minecraft:glowstone)
B(4,0,-4,minecraft:glowstone)
B(4,1,-4,minecraft:glowstone)
B(4,2,-4,minecraft:glowstone)
B(4,3,-4,minecraft:glowstone)
B(4,0,-3,minecraft:glowstone)
B(4,1,-3,minecraft:glowstone)
B(4,2,-3,minecraft:glowstone)
B(4,3,-3,minecraft:glowstone)
B(4,4,-3,minecraft:glowstone)
B(4,0,-2,minecraft:glowstone)
B(4,1,-2,minecraft:glowstone)
B(4,2,-2,minecraft:glowstone)
B(4,3,-2,minecraft:glowstone)
B(4,4,-2,minecraft:glowstone)
B(4,0,-1,minecraft:glowstone)
B(4,1,-1,minecraft:glowstone)
B(4,2,-1,minecraft:glowstone)
B(4,3,-1,minecraft:glowstone)
B(4,4,-1,minecraft:glowstone)
B(4,5,-1,minecraft:glowstone)
B(4,0,0,minecraft:glowstone)
B(4,1,0,minecraft:glowstone)
B(4,2,0,minecraft:glowstone)
B(4,3,0,minecraft:glowstone)
B(4,4,0,minecraft:glowstone)
B(4,5,0,minecraft:glowstone)
B(4,0,1,minecraft:glowstone)
B(4,1,1,minecraft:glowstone)
B(4,2,1,minecraft:glowstone)
B(4,3,1,minecraft:glowstone)
B(4,4,1,minecraft:glowstone)
B(4,5,1,minecraft:glowstone)
B(4,6,1,minecraft:glowstone)
B(4,0,2,minecraft:glowstone)
B(4,1,2,minecraft:glowstone)
B(4,2,2,minecraft:glowstone)
B(4,3,2,minecraft:glowstone)
B(4,4,2,minecraft:glowstone)
B(4,5,2,minecraft:glowstone)
B(4,6,2,minecraft:glowstone)
B(4,0,3,minecraft:glowstone)
B(4,1,3,minecraft:glowstone)
B(4,2,3,minecraft:glowstone)
B(4,3,3,minecraft:glowstone)
B(4,4,3,minecraft:glowstone)
B(4,5,3,minecraft:glowstone)
B(4,6,3,minecraft:glowstone)
B(4,7,3,minecraft:glowstone)
B(4,1,4,minecraft:glowstone)
B(4,2,4,minecraft:glowstone)
B(4,3,4,minecraft:glowstone)
B(4,4,4,minecraft:glowstone)
B(4,5,4,minecraft:glowstone)
B(4,6,4,minecraft:glowstone)
B(4,7,4,minecraft:glowstone)
B(4,2,5,minecraft:glowstone)
B(4,3,5,minecraft:glowstone)
B(4,4,5,minecraft:glowstone)
B(4,5,5,minecraft:glowstone)
B(4,6,5,minecraft:glowstone)
B(4,7,5,minecraft:glowstone)
B(4,8,5,minecraft:glowstone)
B(4,4,6,minecraft:glowstone)
B(4,5,6,minecraft:glowstone)
B(4,6,6,minecraft:glowstone)
B(4,7,6,minecraft:glowstone)
B(4,8,6,minecraft:glowstone)
B(4,5,7,minecraft:glowstone)
B(4,6,7,minecraft:glowstone)
B(4,7,7,minecraft:glowstone)
B(4,8,7,minecraft:glowstone)
B(4,9,7,minecraft:glowstone)
B(4,6,8,minecraft:glowstone)
B(4,7,8,minecraft:glowstone)
B(4,8,8,minecraft:glowstone)
B(4,9,8,minecraft:glowstone)
B(4,7,9,minecraft:glowstone)
B(4,8,9,minecraft:glowstone)
B(4,9,9,minecraft:glowstone)
B(4,10,9,minecraft:glowstone)
B(4,9,10,minecraft:glowstone)
B(4,10,10,minecraft:glowstone)
B(4,10,11,minecraft:glowstone)
B(4,11,11,minecraft:glowstone)
B(4,11,12,minecraft:glowstone)
B(4,12,13,minecraft:glowstone)
B(5,0,-10,minecraft:glowstone)
B(5,0,-9,minecraft:glowstone)
B(5,0,-8,minecraft:glowstone)
B(5,1,-8,minecraft:glowstone)
B(5,0,-7,minecraft:glowstone)
B(5,1,-7,minecraft:glowstone)
B(5,0,-6,minecraft:glowstone)
B(5,1,-6,minecraft:glowstone)
B(5,2,-6,minecraft:glowstone)
B(5,0,-5,minecraft:glowstone)
B(5,1,-5,minecraft:glowstone)
B(5,2,-5,minecraft:glowstone)
B(5,0,-4,minecraft:glowstone)
B(5,1,-4,minecraft:glowstone)
B(5,2,-4,minecraft:glowstone)
B(5,3,-4,minecraft:glowstone)
B(5,0,-3,minecraft:glowstone)
B(5,1,-3,minecraft:glowstone)
B(5,2,-3,minecraft:glowstone)
B(5,3,-3,minecraft:glowstone)
B(5,0,-2,minecraft:glowstone)
B(5,1,-2,minecraft:glowstone)
B(5,2,-2,minecraft:glowstone)
B(5,3,-2,minecraft:glowstone)
B(5,0,-1,minecraft:glowstone)
B(5,1,-1,minecraft:glowstone)
B(5,2,-1,minecraft:glowstone)
B(5,3,-1,minecraft:glowstone)
B(5,4,-1,minecraft:glowstone)
B(5,0,0,minecraft:glowstone)
B(5,1,0,minecraft:glowstone)
B(5,2,0,minecraft:glowstone)
B(5,3,0,minecraft:glowstone)
B(5,4,0,minecraft:glowstone)
B(5,0,1,minecraft:glowstone)
B(5,1,1,minecraft:glowstone)
B(5,2,1,minecraft:glowstone)
B(5,3,1,minecraft:glowstone)
B(5,4,1,minecraft:glowstone)
B(5,5,1,minecraft:glowstone)
B(5,0,2,minecraft:glowstone)
B(5,1,2,minecraft:glowstone)
B(5,2,2,minecraft:glowstone)
B(5,3,2,minecraft:glowstone)
B(5,4,2,minecraft:glowstone)
B(5,5,2,minecraft:glowstone)
B(5,0,3,minecraft:glowstone)
B(5,1,3,minecraft:glowstone)
B(5,2,3,minecraft:glowstone)
B(5,3,3,minecraft:glowstone)
B(5,4,3,minecraft:glowstone)
B(5,5,3,minecraft:glowstone)
B(5,6,3,minecraft:glowstone)
B(5,1,4,minecraft:glowstone)
B(5,2,4,minecraft:glowstone)
B(5,3,4,minecraft:glowstone)
B(5,4,4,minecraft:glowstone)
B(5,5,4,minecraft:glowstone)
B(5,6,4,minecraft:glowstone)
B(5,3,5,minecraft:glowstone)
B(5,4,5,minecraft:glowstone)
B(5,5,5,minecraft:glowstone)
B(5,6,5,minecraft:glowstone)
B(5,7,5,minecraft:glowstone)
B(5,4,6,minecraft:glowstone)
B(5,5,6,minecraft:glowstone)
B(5,6,6,minecraft:glowstone)
B(5,7,6,minecraft:glowstone)
B(5,5,7,minecraft:glowstone)
B(5,6,7,minecraft:glowstone)
B(5,7,7,minecraft:glowstone)
B(5,8,7,minecraft:glowstone)
B(5,6,8,minecraft:glowstone)
B(5,7,8,minecraft:glowstone)
B(5,8,8,minecraft:glowstone)
B(6,0,-8,minecraft:glowstone)
B(6,0,-7,minecraft:glowstone)
B(6,0,-6,minecraft:glowstone)
B(6,1,-6,minecraft:glowstone)
B(6,0,-5,minecraft:glowstone)
B(6,1,-5,minecraft:glowstone)
B(6,0,-4,minecraft:glowstone)
B(6,1,-4,minecraft:glowstone)
B(6,2,-4,minecraft:glowstone)
B(6,0,-3,minecraft:glowstone)
B(6,1,-3,minecraft:glowstone)
B(6,2,-3,minecraft:glowstone)
B(6,0,-2,minecraft:glowstone)
B(6,1,-2,minecraft:glowstone)
B(6,2,-2,minecraft:glowstone)
B(6,3,-2,minecraft:glowstone)
B(6,0,-1,minecraft:glowstone)
B(6,1,-1,minecraft:glowstone)
B(6,2,-1,minecraft:glowstone)
B(6,3,-1,minecraft:glowstone)
B(6,0,0,minecraft:glowstone)
B(6,1,0,minecraft:glowstone)
B(6,2,0,minecraft:glowstone)
B(6,3,0,minecraft:glowstone)
B(6,4,0,minecraft:glowstone)
B(6,0,1,minecraft:glowstone)
B(6,1,1,minecraft:glowstone)
B(6,2,1,minecraft:glowstone)
B(6,3,1,minecraft:glowstone)
B(6,4,1,minecraft:glowstone)
B(6,0,2,minecraft:glowstone)
B(6,1,2,minecraft:glowstone)
B(6,2,2,minecraft:glowstone)
B(6,3,2,minecraft:glowstone)
B(6,4,2,minecraft:glowstone)
B(6,5,2,minecraft:glowstone)
B(6,0,3,minecraft:glowstone)
B(6,1,3,minecraft:glowstone)
B(6,2,3,minecraft:glowstone)
B(6,3,3,minecraft:glowstone)
B(6,4,3,minecraft:glowstone)
B(6,5,3,minecraft:glowstone)
B(6,6,4,minecraft:glowstone)
B(7,0,-6,minecraft:glowstone)
B(7,0,-5,minecraft:glowstone)
B(7,0,-4,minecraft:glowstone)
B(7,1,-4,minecraft:glowstone)
B(7,0,-3,minecraft:glowstone)
B(7,1,-3,minecraft:glowstone)
B(7,0,-2,minecraft:glowstone)
B(7,1,-2,minecraft:glowstone)
B(7,2,-2,minecraft:glowstone)
B(7,0,-1,minecraft:glowstone)
B(7,1,-1,minecraft:glowstone)
B(7,2,-1,minecraft:glowstone)
B(8,0,-5,minecraft:glowstone)

#######################################################################
# +-----------------------------------------------------------------+ #
# |                            BO3 checks                           | #
# +-----------------------------------------------------------------+ #
#######################################################################

BlockCheckNot(0,-1,0,minecraft:air)
BlockCheckNot(-7,-1,-8,minecraft:air)
BlockCheckNot(-7,-1,4,minecraft:air)
BlockCheckNot(8,-1,-8,minecraft:air)
BlockCheckNot(8,-1,4,minecraft:air)

#######################################################################
# +-----------------------------------------------------------------+ #
# |                             Branches                            | #
# +-----------------------------------------------------------------+ #
#######################################################################


#######################################################################
# +-----------------------------------------------------------------+ #
# |                             Entities                            | #
# +-----------------------------------------------------------------+ #
#######################################################################

