Author: Bo3 BulkEdit

Description: Converted Schematic - Modified by Bo3BulkEdit

Version: 3

SettingsMode: WriteDisable

IsOTGPlus: false
Tree: false
Frequency: 1
Rarity: 100
RotateRandomly: true
SpawnHeight: randomY
SpawnHeightOffset: 0
SpawnHeightVariance: 0
MaxBranchDepth: 10
ExcludedBiomes: All

MinHeight: 40
MaxHeight: 60

SourceBlocks: AIR
MaxPercentageOutsideSourceBlock: 100
OutsideSourceBlock: placeAnyway

B(8,0,0,minecraft:warped_stem[axis=y])
BCN(8,0,0,minecraft:air)
B(9,0,1,minecraft:warped_stem[axis=y])
B(11,0,1,minecraft:warped_stem[axis=y])
B(12,0,1,minecraft:warped_stem[axis=y])
B(7,0,2,minecraft:warped_stem[axis=y])
B(8,0,2,minecraft:warped_stem[axis=y])
B(9,0,2,minecraft:warped_stem[axis=y])
B(10,0,2,minecraft:warped_stem[axis=y])
B(7,0,3,minecraft:warped_stem[axis=y])
B(8,0,3,minecraft:warped_stem[axis=y])
B(9,0,3,minecraft:warped_stem[axis=y])
B(10,0,3,minecraft:warped_stem[axis=y])
B(11,0,3,minecraft:warped_stem[axis=y])
B(6,0,4,minecraft:warped_stem[axis=y])
B(7,0,4,minecraft:warped_stem[axis=y])
B(8,0,4,minecraft:warped_stem[axis=y])
B(9,0,4,minecraft:warped_stem[axis=y])
B(10,0,4,minecraft:warped_stem[axis=y])
B(8,0,5,minecraft:warped_stem[axis=y])
B(9,0,5,minecraft:warped_stem[axis=y])
B(10,0,5,minecraft:warped_stem[axis=y])
B(11,0,5,minecraft:warped_stem[axis=y])
B(7,0,6,minecraft:warped_stem[axis=y])
B(9,0,6,minecraft:warped_stem[axis=y])
BCN(11,0,6,minecraft:air)
B(9,1,2,minecraft:warped_stem[axis=y])
B(10,1,2,minecraft:warped_stem[axis=y])
B(7,1,3,minecraft:warped_stem[axis=y])
B(8,1,3,minecraft:warped_stem[axis=y])
B(9,1,3,minecraft:warped_stem[axis=y])
B(10,1,3,minecraft:warped_stem[axis=y])
B(11,1,3,minecraft:warped_stem[axis=y])
B(7,1,4,minecraft:warped_stem[axis=y])
B(8,1,4,minecraft:warped_stem[axis=y])
B(9,1,4,minecraft:warped_stem[axis=y])
B(10,1,4,minecraft:warped_stem[axis=y])
B(8,1,5,minecraft:warped_stem[axis=y])
B(9,1,5,minecraft:warped_stem[axis=y])
B(10,1,5,minecraft:warped_stem[axis=y])
B(9,2,2,minecraft:warped_stem[axis=y])
B(10,2,2,minecraft:warped_stem[axis=y])
B(7,2,3,minecraft:warped_stem[axis=y])
B(8,2,3,minecraft:warped_stem[axis=y])
B(9,2,3,minecraft:warped_stem[axis=y])
B(10,2,3,minecraft:warped_stem[axis=y])
B(6,2,4,minecraft:small_amethyst_bud[facing=west,waterlogged=false])
B(7,2,4,minecraft:warped_stem[axis=y])
B(8,2,4,minecraft:warped_stem[axis=y])
B(9,2,4,minecraft:warped_stem[axis=y])
B(10,2,4,minecraft:warped_stem[axis=y])
B(8,2,5,minecraft:warped_stem[axis=y])
B(9,2,5,minecraft:warped_stem[axis=y])
B(10,2,5,minecraft:warped_stem[axis=y])
B(8,2,6,minecraft:small_amethyst_bud[facing=south,waterlogged=false])
B(9,3,2,minecraft:warped_stem[axis=y])
B(8,3,3,minecraft:warped_stem[axis=y])
B(9,3,3,minecraft:warped_stem[axis=y])
B(10,3,3,minecraft:warped_stem[axis=y])
B(7,3,4,minecraft:warped_stem[axis=y])
B(8,3,4,minecraft:warped_stem[axis=y])
B(9,3,4,minecraft:warped_stem[axis=y])
B(10,3,4,minecraft:warped_stem[axis=y])
B(8,3,5,minecraft:warped_stem[axis=y])
B(9,3,5,minecraft:warped_stem[axis=y])
B(8,3,6,minecraft:medium_amethyst_bud[facing=south,waterlogged=false])
B(9,3,6,minecraft:small_amethyst_bud[facing=south,waterlogged=false])
B(8,4,2,minecraft:medium_amethyst_bud[facing=north,waterlogged=false])
B(8,4,3,minecraft:warped_stem[axis=y])
B(9,4,3,minecraft:warped_stem[axis=y])
B(10,4,3,minecraft:warped_stem[axis=y])
B(7,4,4,minecraft:warped_stem[axis=y])
B(8,4,4,minecraft:warped_stem[axis=y])
B(9,4,4,minecraft:warped_stem[axis=y])
B(10,4,4,minecraft:warped_stem[axis=y])
B(7,4,5,minecraft:small_amethyst_bud[facing=west,waterlogged=false])
B(8,4,5,minecraft:warped_stem[axis=y])
B(9,4,5,minecraft:warped_stem[axis=y])
B(8,4,6,minecraft:small_amethyst_bud[facing=south,waterlogged=false])
B(8,5,3,minecraft:warped_stem[axis=y])
B(9,5,3,minecraft:warped_stem[axis=y])
B(10,5,3,minecraft:warped_stem[axis=y])
B(7,5,4,minecraft:warped_stem[axis=y])
B(8,5,4,minecraft:warped_stem[axis=y])
B(9,5,4,minecraft:warped_stem[axis=y])
B(10,5,4,minecraft:warped_stem[axis=y])
B(8,5,5,minecraft:warped_stem[axis=y])
B(9,5,5,minecraft:warped_stem[axis=y])
B(8,5,6,minecraft:small_amethyst_bud[facing=south,waterlogged=false])
B(9,6,2,minecraft:small_amethyst_bud[facing=north,waterlogged=false])
B(8,6,3,minecraft:warped_stem[axis=y])
B(9,6,3,minecraft:warped_stem[axis=y])
B(10,6,3,minecraft:warped_stem[axis=y])
B(7,6,4,minecraft:warped_stem[axis=y])
B(8,6,4,minecraft:warped_stem[axis=y])
B(9,6,4,minecraft:warped_stem[axis=y])
B(10,6,4,minecraft:warped_stem[axis=y])
B(11,6,4,minecraft:medium_amethyst_bud[facing=east,waterlogged=false])
B(8,6,5,minecraft:warped_stem[axis=y])
B(9,6,5,minecraft:warped_stem[axis=y])
B(8,7,3,minecraft:warped_stem[axis=y])
B(9,7,3,minecraft:warped_stem[axis=y])
B(10,7,3,minecraft:warped_stem[axis=y])
B(11,7,3,minecraft:small_amethyst_bud[facing=east,waterlogged=false])
B(8,7,4,minecraft:warped_stem[axis=y])
B(9,7,4,minecraft:warped_stem[axis=y])
B(10,7,4,minecraft:warped_stem[axis=y])
B(11,7,4,minecraft:small_amethyst_bud[facing=east,waterlogged=false])
B(8,7,5,minecraft:warped_stem[axis=y])
B(9,7,5,minecraft:warped_stem[axis=y])
B(8,8,3,minecraft:warped_stem[axis=y])
B(9,8,3,minecraft:warped_stem[axis=y])
B(10,8,3,minecraft:warped_stem[axis=y])
B(8,8,4,minecraft:warped_stem[axis=y])
B(9,8,4,minecraft:warped_stem[axis=y])
B(10,8,4,minecraft:warped_stem[axis=y])
B(11,8,4,minecraft:small_amethyst_bud[facing=east,waterlogged=false])
B(8,8,5,minecraft:warped_stem[axis=y])
B(9,8,5,minecraft:warped_stem[axis=y])
B(8,9,3,minecraft:warped_stem[axis=y])
B(9,9,3,minecraft:warped_stem[axis=y])
B(10,9,3,minecraft:warped_stem[axis=y])
B(8,9,4,minecraft:warped_stem[axis=y])
B(9,9,4,minecraft:warped_stem[axis=y])
B(10,9,4,minecraft:warped_stem[axis=y])
B(8,9,5,minecraft:warped_stem[axis=y])
B(9,9,5,minecraft:warped_stem[axis=y])
B(9,10,2,minecraft:small_amethyst_bud[facing=north,waterlogged=false])
B(8,10,3,minecraft:warped_stem[axis=y])
B(9,10,3,minecraft:warped_stem[axis=y])
B(10,10,3,minecraft:warped_stem[axis=y])
B(8,10,4,minecraft:warped_stem[axis=y])
B(9,10,4,minecraft:warped_stem[axis=y])
B(10,10,4,minecraft:warped_stem[axis=y])
B(8,10,5,minecraft:warped_stem[axis=y])
B(9,10,5,minecraft:warped_stem[axis=y])
B(8,11,2,minecraft:small_amethyst_bud[facing=north,waterlogged=false])
B(9,11,2,minecraft:small_amethyst_bud[facing=north,waterlogged=false])
B(8,11,3,minecraft:warped_stem[axis=y])
B(9,11,3,minecraft:warped_stem[axis=y])
B(10,11,3,minecraft:warped_stem[axis=y])
B(8,11,4,minecraft:warped_stem[axis=y])
B(9,11,4,minecraft:warped_stem[axis=y])
B(10,11,4,minecraft:warped_stem[axis=y])
B(8,11,5,minecraft:warped_stem[axis=y])
B(9,11,5,minecraft:warped_stem[axis=y])
B(9,12,2,minecraft:medium_amethyst_bud[facing=north,waterlogged=false])
B(8,12,3,minecraft:warped_stem[axis=y])
B(9,12,3,minecraft:warped_stem[axis=y])
B(10,12,3,minecraft:warped_stem[axis=y])
B(8,12,4,minecraft:warped_stem[axis=y])
B(9,12,4,minecraft:warped_stem[axis=y])
B(10,12,4,minecraft:warped_stem[axis=y])
B(8,12,5,minecraft:warped_stem[axis=y])
B(9,12,5,minecraft:warped_stem[axis=y])
B(8,13,3,minecraft:warped_stem[axis=y])
B(9,13,3,minecraft:warped_stem[axis=y])
B(10,13,3,minecraft:warped_stem[axis=y])
B(8,13,4,minecraft:warped_stem[axis=y])
B(9,13,4,minecraft:warped_stem[axis=y])
B(10,13,4,minecraft:warped_stem[axis=y])
B(9,13,5,minecraft:warped_stem[axis=y])
B(8,14,3,minecraft:warped_stem[axis=y])
B(9,14,3,minecraft:warped_stem[axis=y])
B(10,14,3,minecraft:warped_stem[axis=y])
B(7,14,4,minecraft:small_amethyst_bud[facing=west,waterlogged=false])
B(8,14,4,minecraft:warped_stem[axis=y])
B(9,14,4,minecraft:warped_stem[axis=y])
B(10,14,4,minecraft:warped_stem[axis=y])
B(9,14,5,minecraft:warped_stem[axis=y])
B(8,15,3,minecraft:warped_stem[axis=y])
B(9,15,3,minecraft:warped_stem[axis=y])
B(8,15,4,minecraft:warped_stem[axis=y])
B(9,15,4,minecraft:warped_stem[axis=y])
B(10,15,4,minecraft:warped_stem[axis=y])
B(9,15,5,minecraft:warped_stem[axis=y])
B(8,16,3,minecraft:warped_stem[axis=y])
B(9,16,3,minecraft:warped_stem[axis=y])
B(8,16,4,minecraft:warped_stem[axis=y])
B(9,16,4,minecraft:warped_stem[axis=y])
B(9,16,5,minecraft:warped_stem[axis=y])
B(8,17,3,minecraft:warped_stem[axis=y])
B(9,17,3,minecraft:warped_stem[axis=y])
B(8,17,4,minecraft:warped_stem[axis=y])
B(9,17,4,minecraft:warped_stem[axis=y])
B(9,17,5,minecraft:warped_stem[axis=y])
B(9,18,3,minecraft:warped_stem[axis=y])
B(8,18,4,minecraft:warped_stem[axis=y])
B(9,18,4,minecraft:warped_stem[axis=y])
B(9,18,5,minecraft:warped_stem[axis=y])
B(8,19,3,minecraft:small_amethyst_bud[facing=north,waterlogged=false])
B(9,19,3,minecraft:warped_stem[axis=y])
B(8,19,4,minecraft:warped_stem[axis=y])
B(9,19,4,minecraft:warped_stem[axis=y])
B(9,19,5,minecraft:warped_stem[axis=y])
B(9,20,3,minecraft:warped_stem[axis=y])
B(8,20,4,minecraft:warped_stem[axis=y])
B(9,20,4,minecraft:warped_stem[axis=y])
B(9,20,5,minecraft:warped_stem[axis=y])
B(10,20,5,minecraft:medium_amethyst_bud[facing=east,waterlogged=false])
B(8,21,4,minecraft:warped_stem[axis=y])
B(9,21,4,minecraft:warped_stem[axis=y])
B(9,21,5,minecraft:warped_stem[axis=y])
B(8,22,4,minecraft:warped_stem[axis=y])
B(9,22,4,minecraft:warped_stem[axis=y])
B(9,22,5,minecraft:warped_stem[axis=y])
B(9,22,6,minecraft:small_amethyst_bud[facing=south,waterlogged=false])
B(9,23,3,minecraft:small_amethyst_bud[facing=north,waterlogged=false])
B(7,23,4,minecraft:small_amethyst_bud[facing=west,waterlogged=false])
B(8,23,4,minecraft:warped_stem[axis=y])
B(9,23,4,minecraft:warped_stem[axis=y])
B(8,23,5,minecraft:medium_amethyst_bud[facing=west,waterlogged=false])
B(9,23,5,minecraft:warped_stem[axis=y])
B(8,24,4,minecraft:warped_stem[axis=y])
B(9,24,4,minecraft:warped_stem[axis=y])
B(8,24,5,minecraft:small_amethyst_bud[facing=west,waterlogged=false])
B(9,24,5,minecraft:warped_stem[axis=y])
B(8,25,4,minecraft:warped_stem[axis=y])
B(9,25,4,minecraft:warped_stem[axis=y])
B(9,25,5,minecraft:warped_stem[axis=y])
B(8,26,3,minecraft:warped_stem[axis=y])
B(8,26,4,minecraft:warped_stem[axis=y])
B(9,26,4,minecraft:warped_stem[axis=y])
B(9,26,5,minecraft:warped_stem[axis=y])
B(8,27,3,minecraft:warped_stem[axis=y])
B(8,27,4,minecraft:warped_stem[axis=y])
B(9,27,4,minecraft:warped_stem[axis=y])
B(9,27,5,minecraft:warped_stem[axis=y])
B(8,28,3,minecraft:warped_stem[axis=y])
B(9,28,4,minecraft:warped_stem[axis=y])
B(9,28,5,minecraft:warped_stem[axis=y])
B(10,28,5,minecraft:large_amethyst_bud[facing=east,waterlogged=false])
B(8,29,3,minecraft:warped_stem[axis=y])
B(10,29,4,minecraft:warped_stem[axis=y])
B(9,29,5,minecraft:warped_stem[axis=y])
B(0,30,-1,minecraft:warped_wart_block)
B(1,30,0,minecraft:sea_lantern)
B(2,30,0,minecraft:warped_wart_block)
B(1,30,1,minecraft:warped_wart_block)
B(7,30,2,minecraft:large_amethyst_bud[facing=down,waterlogged=false])
B(7,30,3,minecraft:warped_stem[axis=y])
B(10,30,4,minecraft:warped_stem[axis=y])
B(9,30,5,minecraft:warped_stem[axis=y])
B(10,30,5,minecraft:amethyst_cluster[facing=east,waterlogged=false])
B(8,30,8,minecraft:small_amethyst_bud[facing=down,waterlogged=false])
B(10,30,8,minecraft:warped_wart_block)
B(10,30,9,minecraft:warped_wart_block)
B(11,30,9,minecraft:sea_lantern)
B(8,30,10,minecraft:warped_wart_block)
B(10,30,10,minecraft:warped_wart_block)
B(9,30,11,minecraft:warped_wart_block)
B(1,31,-2,minecraft:warped_wart_block)
B(2,31,-2,minecraft:warped_wart_block)
B(0,31,-1,minecraft:warped_wart_block)
B(1,31,-1,minecraft:warped_wart_block)
B(2,31,-1,minecraft:warped_wart_block)
B(3,31,-1,minecraft:warped_wart_block)
B(0,31,0,minecraft:warped_wart_block)
B(1,31,0,minecraft:warped_wart_block)
B(2,31,0,minecraft:warped_wart_block)
B(3,31,0,minecraft:warped_wart_block)
B(0,31,1,minecraft:warped_wart_block)
B(1,31,1,minecraft:warped_wart_block)
B(2,31,1,minecraft:warped_wart_block)
B(1,31,2,minecraft:warped_wart_block)
B(2,31,2,minecraft:amethyst_cluster[facing=down,waterlogged=false])
B(7,31,2,minecraft:warped_stem[axis=y])
B(13,31,2,minecraft:medium_amethyst_bud[facing=down,waterlogged=false])
B(-1,31,3,minecraft:warped_wart_block)
B(0,31,3,minecraft:warped_wart_block)
B(1,31,3,minecraft:warped_wart_block)
B(5,31,3,minecraft:amethyst_cluster[facing=down,waterlogged=false])
B(6,31,3,minecraft:warped_stem[axis=y])
B(12,31,3,minecraft:medium_amethyst_bud[facing=down,waterlogged=false])
B(13,31,3,minecraft:warped_wart_block)
B(0,31,4,minecraft:warped_wart_block)
B(1,31,4,minecraft:warped_wart_block)
B(2,31,4,minecraft:warped_wart_block)
B(10,31,4,minecraft:medium_amethyst_bud[facing=up,waterlogged=false])
B(11,31,4,minecraft:warped_stem[axis=y])
B(0,31,5,minecraft:warped_wart_block)
B(1,31,5,minecraft:warped_wart_block)
B(2,31,5,minecraft:warped_wart_block)
B(3,31,5,minecraft:warped_wart_block)
B(1,31,6,minecraft:warped_wart_block)
B(8,31,6,minecraft:warped_stem[axis=y])
B(11,31,6,minecraft:amethyst_cluster[facing=down,waterlogged=false])
B(2,31,7,minecraft:sea_lantern)
B(3,31,7,minecraft:warped_wart_block)
B(8,31,7,minecraft:warped_stem[axis=y])
B(6,31,8,minecraft:small_amethyst_bud[facing=down,waterlogged=false])
B(8,31,8,minecraft:warped_stem[axis=y])
B(9,31,8,minecraft:warped_stem[axis=y])
B(10,31,8,minecraft:warped_wart_block)
B(11,31,8,minecraft:warped_wart_block)
B(14,31,8,minecraft:warped_wart_block)
B(15,31,8,minecraft:warped_wart_block)
B(16,31,8,minecraft:warped_wart_block)
B(8,31,9,minecraft:warped_wart_block)
B(9,31,9,minecraft:warped_wart_block)
B(10,31,9,minecraft:warped_stem[axis=y])
B(11,31,9,minecraft:warped_wart_block)
B(15,31,9,minecraft:warped_wart_block)
B(7,31,10,minecraft:warped_wart_block)
B(8,31,10,minecraft:warped_wart_block)
B(9,31,10,minecraft:warped_wart_block)
B(11,31,10,minecraft:warped_wart_block)
B(12,31,10,minecraft:warped_wart_block)
B(8,31,11,minecraft:warped_wart_block)
B(9,31,11,minecraft:warped_wart_block)
B(10,31,11,minecraft:warped_wart_block)
B(11,31,11,minecraft:warped_wart_block)
B(4,32,-2,minecraft:warped_wart_block)
B(3,32,-1,minecraft:warped_wart_block)
B(4,32,-1,minecraft:warped_wart_block)
B(5,32,-1,minecraft:warped_wart_block)
B(0,32,0,minecraft:warped_wart_block)
B(1,32,0,minecraft:warped_wart_block)
B(2,32,0,minecraft:warped_wart_block)
B(4,32,0,minecraft:warped_wart_block)
B(12,32,0,minecraft:warped_wart_block)
B(13,32,0,minecraft:medium_amethyst_bud[facing=down,waterlogged=false])
B(-1,32,1,minecraft:warped_wart_block)
B(0,32,1,minecraft:warped_wart_block)
B(1,32,1,minecraft:warped_stem[axis=y])
B(7,32,1,minecraft:warped_stem[axis=y])
B(13,32,1,minecraft:warped_wart_block)
B(14,32,1,minecraft:warped_wart_block)
B(-1,32,2,minecraft:warped_wart_block)
B(0,32,2,minecraft:warped_wart_block)
B(2,32,2,minecraft:warped_stem[axis=y])
B(4,32,2,minecraft:amethyst_cluster[facing=down,waterlogged=false])
B(12,32,2,minecraft:warped_wart_block)
B(13,32,2,minecraft:warped_stem[axis=y])
B(14,32,2,minecraft:warped_wart_block)
B(15,32,2,minecraft:warped_wart_block)
B(-1,32,3,minecraft:warped_wart_block)
B(0,32,3,minecraft:warped_stem[axis=y])
B(1,32,3,minecraft:warped_stem[axis=y])
B(5,32,3,minecraft:warped_stem[axis=y])
B(12,32,3,minecraft:warped_stem[axis=y])
B(13,32,3,minecraft:warped_wart_block)
B(14,32,3,minecraft:warped_wart_block)
B(-1,32,4,minecraft:warped_wart_block)
B(0,32,4,minecraft:warped_wart_block)
B(1,32,4,minecraft:warped_wart_block)
B(2,32,4,minecraft:warped_wart_block)
B(4,32,4,minecraft:warped_stem[axis=y])
B(-1,32,5,minecraft:warped_wart_block)
B(0,32,5,minecraft:warped_wart_block)
B(1,32,5,minecraft:warped_wart_block)
B(2,32,5,minecraft:warped_stem[axis=y])
B(3,32,5,minecraft:warped_stem[axis=y])
B(4,32,5,minecraft:medium_amethyst_bud[facing=south,waterlogged=false])
B(7,32,5,minecraft:medium_amethyst_bud[facing=west,waterlogged=false])
B(8,32,5,minecraft:warped_stem[axis=y])
B(11,32,5,minecraft:warped_stem[axis=y])
B(12,32,5,minecraft:medium_amethyst_bud[facing=east,waterlogged=false])
B(13,32,5,minecraft:sea_lantern)
B(14,32,5,minecraft:warped_wart_block)
B(0,32,6,minecraft:warped_wart_block)
B(1,32,6,minecraft:warped_wart_block)
B(2,32,6,minecraft:warped_wart_block)
B(3,32,6,minecraft:warped_stem[axis=y])
B(4,32,6,minecraft:medium_amethyst_bud[facing=east,waterlogged=false])
B(11,32,6,minecraft:warped_stem[axis=y])
B(13,32,6,minecraft:warped_wart_block)
B(14,32,6,minecraft:warped_wart_block)
B(15,32,6,minecraft:warped_wart_block)
B(0,32,7,minecraft:warped_wart_block)
B(1,32,7,minecraft:warped_wart_block)
B(2,32,7,minecraft:warped_stem[axis=y])
B(3,32,7,minecraft:warped_wart_block)
B(4,32,7,minecraft:warped_wart_block)
B(6,32,7,minecraft:medium_amethyst_bud[facing=west,waterlogged=false])
B(7,32,7,minecraft:warped_stem[axis=y])
B(13,32,7,minecraft:amethyst_cluster[facing=down,waterlogged=false])
B(14,32,7,minecraft:warped_wart_block)
B(15,32,7,minecraft:warped_wart_block)
B(16,32,7,minecraft:warped_wart_block)
B(0,32,8,minecraft:warped_wart_block)
B(1,32,8,minecraft:warped_wart_block)
B(2,32,8,minecraft:warped_wart_block)
B(3,32,8,minecraft:warped_wart_block)
B(4,32,8,minecraft:warped_wart_block)
B(6,32,8,minecraft:warped_stem[axis=y])
B(15,32,8,minecraft:warped_wart_block)
B(16,32,8,minecraft:warped_wart_block)
B(1,32,9,minecraft:warped_wart_block)
B(2,32,9,minecraft:warped_wart_block)
B(3,32,9,minecraft:warped_wart_block)
B(4,32,9,minecraft:warped_wart_block)
B(5,32,9,minecraft:sea_lantern)
B(6,32,9,minecraft:warped_wart_block)
B(7,32,9,minecraft:warped_wart_block)
B(8,32,9,minecraft:warped_stem[axis=y])
B(9,32,9,minecraft:warped_wart_block)
B(10,32,9,minecraft:warped_wart_block)
B(11,32,9,minecraft:warped_wart_block)
B(12,32,9,minecraft:warped_wart_block)
B(14,32,9,minecraft:warped_wart_block)
B(15,32,9,minecraft:warped_wart_block)
B(16,32,9,minecraft:warped_wart_block)
B(17,32,9,minecraft:medium_amethyst_bud[facing=down,waterlogged=false])
B(4,32,10,minecraft:warped_wart_block)
B(5,32,10,minecraft:warped_wart_block)
B(6,32,10,minecraft:warped_wart_block)
B(7,32,10,minecraft:warped_wart_block)
B(8,32,10,minecraft:warped_wart_block)
B(10,32,10,minecraft:warped_stem[axis=y])
B(11,32,10,minecraft:warped_wart_block)
B(12,32,10,minecraft:warped_wart_block)
B(5,32,11,minecraft:warped_wart_block)
B(6,32,11,minecraft:warped_wart_block)
B(9,32,11,minecraft:warped_wart_block)
B(10,32,11,minecraft:warped_wart_block)
B(11,32,11,minecraft:warped_wart_block)
B(12,32,11,minecraft:warped_wart_block)
B(10,32,12,minecraft:warped_wart_block)
B(11,32,12,minecraft:warped_wart_block)
B(5,33,-3,minecraft:warped_wart_block)
B(7,33,-3,minecraft:warped_wart_block)
B(3,33,-2,minecraft:warped_wart_block)
B(4,33,-2,minecraft:warped_wart_block)
B(5,33,-2,minecraft:warped_wart_block)
B(6,33,-2,minecraft:warped_wart_block)
B(7,33,-2,minecraft:warped_wart_block)
B(9,33,-2,minecraft:sea_lantern)
B(10,33,-2,minecraft:warped_wart_block)
B(4,33,-1,minecraft:warped_wart_block)
B(5,33,-1,minecraft:warped_wart_block)
B(6,33,-1,minecraft:warped_wart_block)
B(7,33,-1,minecraft:warped_wart_block)
B(9,33,-1,minecraft:warped_wart_block)
B(11,33,-1,minecraft:warped_wart_block)
B(1,33,0,minecraft:warped_wart_block)
B(3,33,0,minecraft:warped_wart_block)
B(4,33,0,minecraft:warped_wart_block)
B(5,33,0,minecraft:warped_wart_block)
B(6,33,0,minecraft:sea_lantern)
B(7,33,0,minecraft:large_amethyst_bud[facing=north,waterlogged=false])
B(11,33,0,minecraft:warped_wart_block)
B(12,33,0,minecraft:warped_wart_block)
B(13,33,0,minecraft:warped_wart_block)
B(1,33,1,minecraft:warped_wart_block)
B(2,33,1,minecraft:warped_wart_block)
B(3,33,1,minecraft:sea_lantern)
B(4,33,1,minecraft:warped_wart_block)
B(7,33,1,minecraft:warped_stem[axis=y])
B(10,33,1,minecraft:warped_wart_block)
B(11,33,1,minecraft:sea_lantern)
B(12,33,1,minecraft:warped_wart_block)
B(13,33,1,minecraft:warped_wart_block)
B(14,33,1,minecraft:sea_lantern)
B(0,33,2,minecraft:warped_wart_block)
B(1,33,2,minecraft:warped_wart_block)
B(3,33,2,minecraft:warped_stem[axis=y])
B(4,33,2,minecraft:warped_stem[axis=y])
B(7,33,2,minecraft:warped_wart_block)
B(8,33,2,minecraft:warped_wart_block)
B(10,33,2,minecraft:warped_wart_block)
B(11,33,2,minecraft:warped_wart_block)
B(13,33,2,minecraft:medium_amethyst_bud[facing=up,waterlogged=false])
B(0,33,3,minecraft:warped_wart_block)
B(1,33,3,minecraft:warped_wart_block)
B(10,33,3,minecraft:warped_wart_block)
B(11,33,3,minecraft:warped_stem[axis=y])
B(12,33,3,minecraft:medium_amethyst_bud[facing=east,waterlogged=false])
B(1,33,4,minecraft:warped_wart_block)
B(15,33,4,minecraft:warped_wart_block)
B(0,33,5,minecraft:warped_wart_block)
B(1,33,5,minecraft:warped_wart_block)
B(2,33,5,minecraft:warped_wart_block)
B(11,33,5,minecraft:medium_amethyst_bud[facing=up,waterlogged=false])
B(13,33,5,minecraft:warped_wart_block)
B(14,33,5,minecraft:warped_wart_block)
B(15,33,5,minecraft:warped_wart_block)
B(1,33,6,minecraft:warped_wart_block)
B(2,33,6,minecraft:warped_wart_block)
B(3,33,6,minecraft:warped_wart_block)
B(4,33,6,minecraft:warped_wart_block)
B(10,33,6,minecraft:warped_stem[axis=y])
B(12,33,6,minecraft:warped_stem[axis=y])
B(13,33,6,minecraft:warped_wart_block)
B(14,33,6,minecraft:warped_stem[axis=y])
B(16,33,6,minecraft:warped_wart_block)
B(1,33,7,minecraft:warped_wart_block)
B(4,33,7,minecraft:warped_wart_block)
B(5,33,7,minecraft:warped_wart_block)
B(7,33,7,minecraft:warped_stem[axis=y])
B(8,33,7,minecraft:medium_amethyst_bud[facing=east,waterlogged=false])
B(13,33,7,minecraft:warped_stem[axis=y])
B(14,33,7,minecraft:warped_stem[axis=y])
B(15,33,7,minecraft:warped_stem[axis=y])
B(16,33,7,minecraft:warped_wart_block)
B(17,33,7,minecraft:warped_wart_block)
B(1,33,8,minecraft:warped_wart_block)
B(2,33,8,minecraft:warped_wart_block)
B(3,33,8,minecraft:warped_wart_block)
B(4,33,8,minecraft:warped_stem[axis=y])
B(13,33,8,minecraft:warped_wart_block)
B(14,33,8,minecraft:warped_wart_block)
B(15,33,8,minecraft:warped_wart_block)
B(16,33,8,minecraft:warped_wart_block)
B(17,33,8,minecraft:warped_wart_block)
B(3,33,9,minecraft:warped_wart_block)
B(4,33,9,minecraft:warped_stem[axis=y])
B(5,33,9,minecraft:warped_stem[axis=y])
B(7,33,9,minecraft:warped_wart_block)
B(10,33,9,minecraft:warped_wart_block)
B(13,33,9,minecraft:warped_wart_block)
B(14,33,9,minecraft:warped_wart_block)
B(17,33,9,minecraft:warped_wart_block)
B(3,33,10,minecraft:warped_wart_block)
B(5,33,10,minecraft:warped_stem[axis=y])
B(6,33,10,minecraft:warped_wart_block)
B(7,33,10,minecraft:warped_stem[axis=y])
B(8,33,10,minecraft:warped_wart_block)
B(10,33,10,minecraft:warped_wart_block)
B(11,33,10,minecraft:warped_wart_block)
B(14,33,10,minecraft:warped_wart_block)
B(15,33,10,minecraft:warped_wart_block)
B(16,33,10,minecraft:warped_wart_block)
B(4,33,11,minecraft:warped_wart_block)
B(7,33,11,minecraft:warped_wart_block)
B(9,33,11,minecraft:warped_wart_block)
B(10,33,11,minecraft:warped_wart_block)
B(11,33,11,minecraft:warped_wart_block)
B(15,33,11,minecraft:warped_wart_block)
B(5,33,12,minecraft:warped_wart_block)
B(6,34,-4,minecraft:warped_wart_block)
B(7,34,-4,minecraft:warped_wart_block)
B(8,34,-4,minecraft:warped_wart_block)
B(9,34,-4,minecraft:warped_wart_block)
B(4,34,-3,minecraft:warped_wart_block)
B(5,34,-3,minecraft:warped_wart_block)
B(6,34,-3,minecraft:warped_wart_block)
B(7,34,-3,minecraft:warped_wart_block)
B(8,34,-3,minecraft:warped_wart_block)
B(9,34,-3,minecraft:warped_wart_block)
B(10,34,-3,minecraft:warped_wart_block)
B(4,34,-2,minecraft:warped_wart_block)
B(5,34,-2,minecraft:warped_wart_block)
B(6,34,-2,minecraft:warped_wart_block)
B(7,34,-2,minecraft:warped_wart_block)
B(8,34,-2,minecraft:warped_wart_block)
B(9,34,-2,minecraft:warped_wart_block)
B(11,34,-2,minecraft:warped_wart_block)
B(12,34,-2,minecraft:warped_wart_block)
B(3,34,-1,minecraft:warped_wart_block)
B(4,34,-1,minecraft:warped_wart_block)
B(5,34,-1,minecraft:warped_wart_block)
B(6,34,-1,minecraft:warped_wart_block)
B(7,34,-1,minecraft:warped_wart_block)
B(8,34,-1,minecraft:warped_stem[axis=y])
B(9,34,-1,minecraft:warped_wart_block)
B(10,34,-1,minecraft:warped_wart_block)
B(12,34,-1,minecraft:warped_wart_block)
B(13,34,-1,minecraft:warped_wart_block)
B(3,34,0,minecraft:warped_wart_block)
B(4,34,0,minecraft:warped_stem[axis=y])
B(5,34,0,minecraft:warped_wart_block)
B(6,34,0,minecraft:warped_stem[axis=y])
B(7,34,0,minecraft:warped_wart_block)
B(8,34,0,minecraft:warped_stem[axis=y])
B(9,34,0,minecraft:warped_wart_block)
B(11,34,0,minecraft:warped_stem[axis=y])
B(12,34,0,minecraft:warped_wart_block)
B(14,34,0,minecraft:warped_wart_block)
B(3,34,1,minecraft:warped_wart_block)
B(4,34,1,minecraft:warped_stem[axis=y])
B(5,34,1,minecraft:warped_wart_block)
B(6,34,1,minecraft:warped_wart_block)
B(8,34,1,minecraft:warped_wart_block)
B(9,34,1,minecraft:warped_wart_block)
B(10,34,1,minecraft:warped_wart_block)
B(11,34,1,minecraft:warped_stem[axis=y])
B(12,34,1,minecraft:warped_wart_block)
B(13,34,1,minecraft:warped_wart_block)
B(14,34,1,minecraft:warped_wart_block)
B(15,34,1,minecraft:warped_wart_block)
B(2,34,2,minecraft:warped_wart_block)
B(4,34,2,minecraft:warped_stem[axis=y])
B(5,34,2,minecraft:warped_wart_block)
B(6,34,2,minecraft:warped_wart_block)
B(7,34,2,minecraft:warped_stem[axis=y])
B(8,34,2,minecraft:warped_wart_block)
B(10,34,2,minecraft:warped_stem[axis=y])
B(14,34,2,minecraft:warped_wart_block)
B(1,34,3,minecraft:warped_wart_block)
B(2,34,3,minecraft:warped_wart_block)
B(3,34,3,minecraft:warped_wart_block)
B(5,34,3,minecraft:warped_wart_block)
B(6,34,3,minecraft:warped_wart_block)
B(7,34,3,minecraft:warped_wart_block)
B(8,34,3,minecraft:warped_wart_block)
B(9,34,3,minecraft:warped_wart_block)
B(11,34,3,minecraft:warped_stem[axis=y])
B(13,34,3,minecraft:warped_wart_block)
B(14,34,3,minecraft:warped_wart_block)
B(15,34,3,minecraft:warped_wart_block)
B(8,34,4,minecraft:warped_wart_block)
B(9,34,4,minecraft:warped_wart_block)
B(10,34,4,minecraft:warped_wart_block)
B(11,34,4,minecraft:warped_wart_block)
B(15,34,4,minecraft:warped_wart_block)
B(16,34,4,minecraft:warped_wart_block)
B(3,34,5,minecraft:sea_lantern)
B(6,34,5,minecraft:warped_wart_block)
B(10,34,5,minecraft:warped_wart_block)
B(13,34,5,minecraft:warped_wart_block)
B(14,34,5,minecraft:warped_wart_block)
B(15,34,5,minecraft:warped_stem[axis=y])
B(16,34,5,minecraft:warped_wart_block)
B(2,34,6,minecraft:warped_wart_block)
B(3,34,6,minecraft:warped_wart_block)
B(4,34,6,minecraft:warped_wart_block)
B(6,34,6,minecraft:medium_amethyst_bud[facing=down,waterlogged=false])
B(7,34,6,minecraft:warped_wart_block)
B(10,34,6,minecraft:warped_stem[axis=y])
B(11,34,6,minecraft:warped_wart_block)
B(13,34,6,minecraft:warped_wart_block)
B(14,34,6,minecraft:warped_wart_block)
B(15,34,6,minecraft:warped_wart_block)
B(1,34,7,minecraft:warped_wart_block)
B(2,34,7,minecraft:warped_wart_block)
B(3,34,7,minecraft:warped_wart_block)
B(4,34,7,minecraft:warped_stem[axis=y])
B(6,34,7,minecraft:warped_stem[axis=y])
B(9,34,7,minecraft:warped_wart_block)
B(10,34,7,minecraft:warped_wart_block)
B(12,34,7,minecraft:warped_wart_block)
B(13,34,7,minecraft:warped_wart_block)
B(14,34,7,minecraft:warped_wart_block)
B(15,34,7,minecraft:warped_wart_block)
B(1,34,8,minecraft:warped_wart_block)
B(2,34,8,minecraft:warped_wart_block)
B(5,34,8,minecraft:warped_wart_block)
B(9,34,8,minecraft:warped_wart_block)
B(10,34,8,minecraft:warped_wart_block)
B(13,34,8,minecraft:warped_wart_block)
B(14,34,8,minecraft:warped_stem[axis=y])
B(15,34,8,minecraft:warped_wart_block)
B(16,34,8,minecraft:warped_wart_block)
B(1,34,9,minecraft:warped_wart_block)
B(2,34,9,minecraft:warped_wart_block)
B(3,34,9,minecraft:warped_stem[axis=y])
B(4,34,9,minecraft:warped_wart_block)
B(5,34,9,minecraft:warped_wart_block)
B(14,34,9,minecraft:warped_stem[axis=y])
B(15,34,9,minecraft:warped_wart_block)
B(16,34,9,minecraft:warped_wart_block)
B(2,34,10,minecraft:warped_wart_block)
B(3,34,10,minecraft:warped_wart_block)
B(4,34,10,minecraft:warped_wart_block)
B(6,34,10,minecraft:warped_wart_block)
B(7,34,10,minecraft:warped_wart_block)
B(13,34,10,minecraft:warped_wart_block)
B(14,34,10,minecraft:warped_wart_block)
B(15,34,10,minecraft:warped_wart_block)
B(16,34,10,minecraft:warped_wart_block)
B(5,34,11,minecraft:warped_stem[axis=y])
B(6,34,11,minecraft:warped_wart_block)
B(7,34,11,minecraft:warped_wart_block)
B(15,34,11,minecraft:warped_wart_block)
B(16,34,11,minecraft:warped_wart_block)
B(4,34,12,minecraft:warped_wart_block)
B(5,34,12,minecraft:warped_wart_block)
B(6,34,12,minecraft:warped_wart_block)
B(9,35,-3,minecraft:warped_wart_block)
B(10,35,-3,minecraft:warped_wart_block)
B(11,35,-3,minecraft:warped_wart_block)
B(12,35,-3,minecraft:warped_wart_block)
B(4,35,-2,minecraft:warped_wart_block)
B(5,35,-2,minecraft:warped_wart_block)
B(6,35,-2,minecraft:warped_wart_block)
B(7,35,-2,minecraft:warped_wart_block)
B(8,35,-2,minecraft:warped_wart_block)
B(9,35,-2,minecraft:warped_wart_block)
B(10,35,-2,minecraft:warped_stem[axis=y])
B(11,35,-2,minecraft:warped_wart_block)
B(13,35,-2,minecraft:warped_wart_block)
B(4,35,-1,minecraft:warped_wart_block)
B(5,35,-1,minecraft:warped_wart_block)
B(7,35,-1,minecraft:warped_wart_block)
B(8,35,-1,minecraft:warped_wart_block)
B(9,35,-1,minecraft:warped_wart_block)
B(10,35,-1,minecraft:warped_stem[axis=y])
B(12,35,-1,minecraft:warped_stem[axis=y])
B(2,35,0,minecraft:warped_wart_block)
B(3,35,0,minecraft:warped_wart_block)
B(4,35,0,minecraft:warped_wart_block)
B(5,35,0,minecraft:warped_wart_block)
B(6,35,0,minecraft:warped_stem[axis=y])
B(7,35,0,minecraft:warped_wart_block)
B(8,35,0,minecraft:warped_wart_block)
B(10,35,0,minecraft:warped_wart_block)
B(11,35,0,minecraft:warped_wart_block)
B(12,35,0,minecraft:warped_wart_block)
B(13,35,0,minecraft:warped_wart_block)
B(14,35,0,minecraft:warped_wart_block)
B(15,35,0,minecraft:warped_wart_block)
B(1,35,1,minecraft:warped_wart_block)
B(2,35,1,minecraft:warped_wart_block)
B(3,35,1,minecraft:warped_wart_block)
B(4,35,1,minecraft:warped_wart_block)
B(5,35,1,minecraft:warped_wart_block)
B(6,35,1,minecraft:warped_wart_block)
B(7,35,1,minecraft:warped_wart_block)
B(8,35,1,minecraft:warped_wart_block)
B(9,35,1,minecraft:warped_wart_block)
B(10,35,1,minecraft:warped_wart_block)
B(11,35,1,minecraft:warped_wart_block)
B(12,35,1,minecraft:warped_wart_block)
B(13,35,1,minecraft:warped_wart_block)
B(14,35,1,minecraft:warped_stem[axis=y])
B(1,35,2,minecraft:warped_wart_block)
B(2,35,2,minecraft:warped_wart_block)
B(3,35,2,minecraft:warped_stem[axis=y])
B(4,35,2,minecraft:warped_wart_block)
B(5,35,2,minecraft:warped_wart_block)
B(6,35,2,minecraft:warped_wart_block)
B(7,35,2,minecraft:warped_wart_block)
B(8,35,2,minecraft:warped_wart_block)
B(9,35,2,minecraft:warped_wart_block)
B(10,35,2,minecraft:warped_wart_block)
B(11,35,2,minecraft:warped_wart_block)
B(12,35,2,minecraft:warped_stem[axis=y])
B(13,35,2,minecraft:warped_stem[axis=y])
B(14,35,2,minecraft:warped_wart_block)
B(15,35,2,minecraft:warped_wart_block)
B(1,35,3,minecraft:warped_wart_block)
B(2,35,3,minecraft:warped_stem[axis=y])
B(3,35,3,minecraft:warped_wart_block)
B(5,35,3,minecraft:warped_stem[axis=y])
B(6,35,3,minecraft:warped_wart_block)
B(7,35,3,minecraft:warped_wart_block)
B(9,35,3,minecraft:warped_wart_block)
B(10,35,3,minecraft:warped_wart_block)
B(11,35,3,minecraft:warped_wart_block)
B(12,35,3,minecraft:warped_wart_block)
B(13,35,3,minecraft:warped_wart_block)
B(14,35,3,minecraft:warped_stem[axis=y])
B(1,35,4,minecraft:warped_wart_block)
B(2,35,4,minecraft:warped_wart_block)
B(3,35,4,minecraft:warped_wart_block)
B(4,35,4,minecraft:warped_wart_block)
B(6,35,4,minecraft:warped_wart_block)
B(8,35,4,minecraft:warped_wart_block)
B(9,35,4,minecraft:warped_wart_block)
B(10,35,4,minecraft:warped_stem[axis=y])
B(12,35,4,minecraft:warped_wart_block)
B(13,35,4,minecraft:warped_wart_block)
B(15,35,4,minecraft:warped_wart_block)
B(2,35,5,minecraft:warped_wart_block)
B(3,35,5,minecraft:warped_wart_block)
B(4,35,5,minecraft:warped_wart_block)
B(5,35,5,minecraft:warped_stem[axis=y])
B(6,35,5,minecraft:warped_wart_block)
B(7,35,5,minecraft:sea_lantern)
B(9,35,5,minecraft:warped_wart_block)
B(10,35,5,minecraft:warped_wart_block)
B(11,35,5,minecraft:warped_wart_block)
B(12,35,5,minecraft:warped_wart_block)
B(13,35,5,minecraft:warped_wart_block)
B(14,35,5,minecraft:warped_wart_block)
B(16,35,5,minecraft:warped_wart_block)
B(2,35,6,minecraft:warped_wart_block)
B(3,35,6,minecraft:warped_wart_block)
B(4,35,6,minecraft:warped_wart_block)
B(5,35,6,minecraft:warped_wart_block)
B(6,35,6,minecraft:warped_stem[axis=y])
B(7,35,6,minecraft:warped_wart_block)
B(9,35,6,minecraft:medium_amethyst_bud[facing=west,waterlogged=false])
B(10,35,6,minecraft:warped_wart_block)
B(12,35,6,minecraft:warped_wart_block)
B(13,35,6,minecraft:warped_wart_block)
B(3,35,7,minecraft:warped_wart_block)
B(4,35,7,minecraft:warped_wart_block)
B(5,35,7,minecraft:warped_wart_block)
B(6,35,7,minecraft:warped_stem[axis=y])
B(7,35,7,minecraft:warped_wart_block)
B(8,35,7,minecraft:warped_wart_block)
B(9,35,7,minecraft:warped_stem[axis=y])
B(10,35,7,minecraft:warped_wart_block)
B(11,35,7,minecraft:warped_stem[axis=y])
B(12,35,7,minecraft:warped_wart_block)
B(14,35,7,minecraft:warped_wart_block)
B(3,35,8,minecraft:warped_wart_block)
B(4,35,8,minecraft:warped_wart_block)
B(8,35,8,minecraft:warped_wart_block)
B(9,35,8,minecraft:warped_stem[axis=y])
B(12,35,8,minecraft:warped_wart_block)
B(13,35,8,minecraft:warped_wart_block)
B(14,35,8,minecraft:warped_wart_block)
B(15,35,8,minecraft:warped_wart_block)
B(3,35,9,minecraft:warped_wart_block)
B(4,35,9,minecraft:warped_wart_block)
B(8,35,9,minecraft:warped_wart_block)
B(9,35,9,minecraft:warped_wart_block)
B(14,35,9,minecraft:warped_wart_block)
B(15,35,9,minecraft:warped_wart_block)
B(14,35,10,minecraft:warped_wart_block)
B(15,35,10,minecraft:warped_wart_block)
B(4,35,11,minecraft:warped_wart_block)
B(5,35,11,minecraft:warped_wart_block)
B(6,35,11,minecraft:warped_wart_block)
B(15,35,11,minecraft:warped_wart_block)
B(11,36,-2,minecraft:warped_wart_block)
B(6,36,-1,minecraft:warped_wart_block)
B(10,36,-1,minecraft:warped_wart_block)
B(11,36,-1,minecraft:warped_wart_block)
B(5,36,0,minecraft:warped_wart_block)
B(6,36,0,minecraft:warped_wart_block)
B(12,36,0,minecraft:warped_wart_block)
B(11,36,1,minecraft:warped_wart_block)
B(12,36,1,minecraft:warped_wart_block)
B(13,36,1,minecraft:warped_wart_block)
B(14,36,1,minecraft:warped_wart_block)
B(15,36,1,minecraft:warped_wart_block)
B(3,36,2,minecraft:warped_wart_block)
B(4,36,2,minecraft:warped_wart_block)
B(8,36,2,minecraft:warped_wart_block)
B(11,36,2,minecraft:warped_wart_block)
B(12,36,2,minecraft:warped_stem[axis=y])
B(13,36,2,minecraft:warped_wart_block)
B(14,36,2,minecraft:warped_wart_block)
B(2,36,3,minecraft:warped_wart_block)
B(3,36,3,minecraft:warped_wart_block)
B(4,36,3,minecraft:warped_wart_block)
B(5,36,3,minecraft:warped_wart_block)
B(8,36,3,minecraft:warped_wart_block)
B(9,36,3,minecraft:warped_wart_block)
B(10,36,3,minecraft:warped_wart_block)
B(11,36,3,minecraft:warped_wart_block)
B(12,36,3,minecraft:warped_wart_block)
B(13,36,3,minecraft:warped_wart_block)
B(14,36,3,minecraft:warped_wart_block)
B(15,36,3,minecraft:warped_wart_block)
B(5,36,4,minecraft:warped_wart_block)
B(7,36,4,minecraft:warped_wart_block)
B(8,36,4,minecraft:warped_wart_block)
B(9,36,4,minecraft:warped_stem[axis=y])
B(11,36,4,minecraft:warped_wart_block)
B(12,36,4,minecraft:warped_wart_block)
B(14,36,4,minecraft:warped_wart_block)
B(4,36,5,minecraft:warped_wart_block)
B(5,36,5,minecraft:warped_wart_block)
B(7,36,5,minecraft:warped_wart_block)
B(8,36,5,minecraft:warped_wart_block)
B(9,36,5,minecraft:warped_wart_block)
B(10,36,5,minecraft:warped_wart_block)
B(11,36,5,minecraft:warped_wart_block)
B(4,36,6,minecraft:warped_wart_block)
B(5,36,6,minecraft:warped_wart_block)
B(6,36,6,minecraft:warped_wart_block)
B(8,36,6,minecraft:warped_wart_block)
B(9,36,6,minecraft:warped_wart_block)
B(11,36,6,minecraft:warped_wart_block)
B(5,36,7,minecraft:warped_stem[axis=y])
B(6,36,7,minecraft:warped_wart_block)
B(7,36,7,minecraft:warped_wart_block)
B(8,36,7,minecraft:warped_stem[axis=y])
B(9,36,7,minecraft:warped_wart_block)
B(11,36,7,minecraft:warped_wart_block)
B(4,36,8,minecraft:warped_wart_block)
B(5,36,8,minecraft:warped_wart_block)
B(7,36,8,minecraft:warped_wart_block)
B(8,36,8,minecraft:warped_wart_block)
B(10,36,8,minecraft:warped_wart_block)
B(9,36,9,minecraft:warped_wart_block)
B(12,37,1,minecraft:warped_wart_block)
B(11,37,2,minecraft:warped_wart_block)
B(12,37,2,minecraft:warped_wart_block)
B(13,37,2,minecraft:warped_wart_block)
B(9,37,4,minecraft:warped_wart_block)
B(10,37,4,minecraft:warped_wart_block)
B(4,37,6,minecraft:warped_wart_block)
B(5,37,6,minecraft:warped_wart_block)
B(4,37,7,minecraft:warped_wart_block)
B(5,37,7,minecraft:warped_wart_block)
B(6,37,7,minecraft:warped_wart_block)
B(8,37,7,minecraft:warped_wart_block)
B(9,37,7,minecraft:warped_wart_block)
B(5,37,8,minecraft:warped_wart_block)
B(8,37,8,minecraft:warped_wart_block)

