Author: Frank

Description: Medium quartz spike

Version: 3

SettingsMode: WriteDisable

IsOTGPlus: false
Tree: true
Frequency: 10
Rarity: 100.0
RotateRandomly: true
SpawnHeight: randomY
SpawnHeightOffset: 0
SpawnHeightVariance: 0
MaxBranchDepth: 10
ExcludedBiomes: All

ExtrudeMode: None
ExtrudeThroughBlocks: minecraft:air

MinHeight: 50
MaxHeight: 65

SourceBlocks: AIR
MaxPercentageOutsideSourceBlock: 60
OutsideSourceBlock: placeAnyway

DoReplaceBlocks: true

RB(-7,0,-7,minecraft:chiseled_quartz_block,10,minecraft:quartz_pillar,10,minecraft:smooth_quartz,10,minecraft:quartz_block,100)
RB(-6,0,-8,minecraft:chiseled_quartz_block,10,minecraft:quartz_pillar,10,minecraft:smooth_quartz,10,minecraft:quartz_block,100)
RB(-6,0,-7,minecraft:chiseled_quartz_block,10,minecraft:quartz_pillar,10,minecraft:smooth_quartz,10,minecraft:quartz_block,100)
RB(-6,0,-6,minecraft:chiseled_quartz_block,10,minecraft:quartz_pillar,10,minecraft:smooth_quartz,10,minecraft:quartz_block,100)
RB(-6,0,-5,minecraft:chiseled_quartz_block,10,minecraft:quartz_pillar,10,minecraft:smooth_quartz,10,minecraft:quartz_block,100)
RB(-5,0,-10,minecraft:chiseled_quartz_block,10,minecraft:quartz_pillar,10,minecraft:smooth_quartz,10,minecraft:quartz_block,100)
RB(-5,0,-9,minecraft:chiseled_quartz_block,10,minecraft:quartz_pillar,10,minecraft:smooth_quartz,10,minecraft:quartz_block,100)
RB(-5,0,-8,minecraft:chiseled_quartz_block,10,minecraft:quartz_pillar,10,minecraft:smooth_quartz,10,minecraft:quartz_block,100)
RB(-5,0,-7,minecraft:chiseled_quartz_block,10,minecraft:quartz_pillar,10,minecraft:smooth_quartz,10,minecraft:quartz_block,100)
RB(-5,1,-7,minecraft:chiseled_quartz_block,10,minecraft:quartz_pillar,10,minecraft:smooth_quartz,10,minecraft:quartz_block,100)
RB(-5,0,-6,minecraft:chiseled_quartz_block,10,minecraft:quartz_pillar,10,minecraft:smooth_quartz,10,minecraft:quartz_block,100)
RB(-5,1,-6,minecraft:chiseled_quartz_block,10,minecraft:quartz_pillar,10,minecraft:smooth_quartz,10,minecraft:quartz_block,100)
RB(-5,0,-5,minecraft:chiseled_quartz_block,10,minecraft:quartz_pillar,10,minecraft:smooth_quartz,10,minecraft:quartz_block,100)
RB(-5,1,-5,minecraft:chiseled_quartz_block,10,minecraft:quartz_pillar,10,minecraft:smooth_quartz,10,minecraft:quartz_block,100)
RB(-5,0,-4,minecraft:chiseled_quartz_block,10,minecraft:quartz_pillar,10,minecraft:smooth_quartz,10,minecraft:quartz_block,100)
RB(-5,1,-4,minecraft:chiseled_quartz_block,10,minecraft:quartz_pillar,10,minecraft:smooth_quartz,10,minecraft:quartz_block,100)
RB(-5,0,-3,minecraft:chiseled_quartz_block,10,minecraft:quartz_pillar,10,minecraft:smooth_quartz,10,minecraft:quartz_block,100)
RB(-5,1,-3,minecraft:chiseled_quartz_block,10,minecraft:quartz_pillar,10,minecraft:smooth_quartz,10,minecraft:quartz_block,100)
RB(-4,0,-12,minecraft:chiseled_quartz_block,10,minecraft:quartz_pillar,10,minecraft:smooth_quartz,10,minecraft:quartz_block,100)
RB(-4,0,-11,minecraft:chiseled_quartz_block,10,minecraft:quartz_pillar,10,minecraft:smooth_quartz,10,minecraft:quartz_block,100)
RB(-4,0,-10,minecraft:chiseled_quartz_block,10,minecraft:quartz_pillar,10,minecraft:smooth_quartz,10,minecraft:quartz_block,100)
RB(-4,0,-9,minecraft:chiseled_quartz_block,10,minecraft:quartz_pillar,10,minecraft:smooth_quartz,10,minecraft:quartz_block,100)
RB(-4,0,-8,minecraft:chiseled_quartz_block,10,minecraft:quartz_pillar,10,minecraft:smooth_quartz,10,minecraft:quartz_block,100)
RB(-4,1,-8,minecraft:chiseled_quartz_block,10,minecraft:quartz_pillar,10,minecraft:smooth_quartz,10,minecraft:quartz_block,100)
RB(-4,0,-7,minecraft:chiseled_quartz_block,10,minecraft:quartz_pillar,10,minecraft:smooth_quartz,10,minecraft:quartz_block,100)
RB(-4,1,-7,minecraft:chiseled_quartz_block,10,minecraft:quartz_pillar,10,minecraft:smooth_quartz,10,minecraft:quartz_block,100)
RB(-4,0,-6,minecraft:chiseled_quartz_block,10,minecraft:quartz_pillar,10,minecraft:smooth_quartz,10,minecraft:quartz_block,100)
RB(-4,1,-6,minecraft:chiseled_quartz_block,10,minecraft:quartz_pillar,10,minecraft:smooth_quartz,10,minecraft:quartz_block,100)
RB(-4,0,-5,minecraft:chiseled_quartz_block,10,minecraft:quartz_pillar,10,minecraft:smooth_quartz,10,minecraft:quartz_block,100)
RB(-4,1,-5,minecraft:chiseled_quartz_block,10,minecraft:quartz_pillar,10,minecraft:smooth_quartz,10,minecraft:quartz_block,100)
RB(-4,2,-5,minecraft:chiseled_quartz_block,10,minecraft:quartz_pillar,10,minecraft:smooth_quartz,10,minecraft:quartz_block,100)
RB(-4,0,-4,minecraft:chiseled_quartz_block,10,minecraft:quartz_pillar,10,minecraft:smooth_quartz,10,minecraft:quartz_block,100)
RB(-4,1,-4,minecraft:chiseled_quartz_block,10,minecraft:quartz_pillar,10,minecraft:smooth_quartz,10,minecraft:quartz_block,100)
RB(-4,2,-4,minecraft:chiseled_quartz_block,10,minecraft:quartz_pillar,10,minecraft:smooth_quartz,10,minecraft:quartz_block,100)
RB(-4,0,-3,minecraft:chiseled_quartz_block,10,minecraft:quartz_pillar,10,minecraft:smooth_quartz,10,minecraft:quartz_block,100)
RB(-4,1,-3,minecraft:chiseled_quartz_block,10,minecraft:quartz_pillar,10,minecraft:smooth_quartz,10,minecraft:quartz_block,100)
RB(-4,2,-3,minecraft:chiseled_quartz_block,10,minecraft:quartz_pillar,10,minecraft:smooth_quartz,10,minecraft:quartz_block,100)
RB(-4,0,-2,minecraft:chiseled_quartz_block,10,minecraft:quartz_pillar,10,minecraft:smooth_quartz,10,minecraft:quartz_block,100)
RB(-4,1,-2,minecraft:chiseled_quartz_block,10,minecraft:quartz_pillar,10,minecraft:smooth_quartz,10,minecraft:quartz_block,100)
RB(-4,2,-2,minecraft:chiseled_quartz_block,10,minecraft:quartz_pillar,10,minecraft:smooth_quartz,10,minecraft:quartz_block,100)
RB(-4,3,-2,minecraft:chiseled_quartz_block,10,minecraft:quartz_pillar,10,minecraft:smooth_quartz,10,minecraft:quartz_block,100)
RB(-4,0,-1,minecraft:chiseled_quartz_block,10,minecraft:quartz_pillar,10,minecraft:smooth_quartz,10,minecraft:quartz_block,100)
RB(-4,1,-1,minecraft:chiseled_quartz_block,10,minecraft:quartz_pillar,10,minecraft:smooth_quartz,10,minecraft:quartz_block,100)
RB(-4,2,-1,minecraft:chiseled_quartz_block,10,minecraft:quartz_pillar,10,minecraft:smooth_quartz,10,minecraft:quartz_block,100)
RB(-4,0,0,minecraft:chiseled_quartz_block,10,minecraft:quartz_pillar,10,minecraft:smooth_quartz,10,minecraft:quartz_block,100)
RB(-3,0,-12,minecraft:chiseled_quartz_block,10,minecraft:quartz_pillar,10,minecraft:smooth_quartz,10,minecraft:quartz_block,100)
RB(-3,0,-11,minecraft:chiseled_quartz_block,10,minecraft:quartz_pillar,10,minecraft:smooth_quartz,10,minecraft:quartz_block,100)
RB(-3,0,-10,minecraft:chiseled_quartz_block,10,minecraft:quartz_pillar,10,minecraft:smooth_quartz,10,minecraft:quartz_block,100)
RB(-3,0,-9,minecraft:chiseled_quartz_block,10,minecraft:quartz_pillar,10,minecraft:smooth_quartz,10,minecraft:quartz_block,100)
RB(-3,1,-9,minecraft:chiseled_quartz_block,10,minecraft:quartz_pillar,10,minecraft:smooth_quartz,10,minecraft:quartz_block,100)
RB(-3,0,-8,minecraft:chiseled_quartz_block,10,minecraft:quartz_pillar,10,minecraft:smooth_quartz,10,minecraft:quartz_block,100)
RB(-3,1,-8,minecraft:chiseled_quartz_block,10,minecraft:quartz_pillar,10,minecraft:smooth_quartz,10,minecraft:quartz_block,100)
RB(-3,0,-7,minecraft:chiseled_quartz_block,10,minecraft:quartz_pillar,10,minecraft:smooth_quartz,10,minecraft:quartz_block,100)
RB(-3,1,-7,minecraft:chiseled_quartz_block,10,minecraft:quartz_pillar,10,minecraft:smooth_quartz,10,minecraft:quartz_block,100)
RB(-3,2,-7,minecraft:chiseled_quartz_block,10,minecraft:quartz_pillar,10,minecraft:smooth_quartz,10,minecraft:quartz_block,100)
RB(-3,0,-6,minecraft:chiseled_quartz_block,10,minecraft:quartz_pillar,10,minecraft:smooth_quartz,10,minecraft:quartz_block,100)
RB(-3,1,-6,minecraft:chiseled_quartz_block,10,minecraft:quartz_pillar,10,minecraft:smooth_quartz,10,minecraft:quartz_block,100)
RB(-3,2,-6,minecraft:chiseled_quartz_block,10,minecraft:quartz_pillar,10,minecraft:smooth_quartz,10,minecraft:quartz_block,100)
RB(-3,0,-5,minecraft:chiseled_quartz_block,10,minecraft:quartz_pillar,10,minecraft:smooth_quartz,10,minecraft:quartz_block,100)
RB(-3,1,-5,minecraft:chiseled_quartz_block,10,minecraft:quartz_pillar,10,minecraft:smooth_quartz,10,minecraft:quartz_block,100)
RB(-3,2,-5,minecraft:chiseled_quartz_block,10,minecraft:quartz_pillar,10,minecraft:smooth_quartz,10,minecraft:quartz_block,100)
RB(-3,0,-4,minecraft:chiseled_quartz_block,10,minecraft:quartz_pillar,10,minecraft:smooth_quartz,10,minecraft:quartz_block,100)
RB(-3,1,-4,minecraft:chiseled_quartz_block,10,minecraft:quartz_pillar,10,minecraft:smooth_quartz,10,minecraft:quartz_block,100)
RB(-3,2,-4,minecraft:chiseled_quartz_block,10,minecraft:quartz_pillar,10,minecraft:smooth_quartz,10,minecraft:quartz_block,100)
RB(-3,3,-4,minecraft:chiseled_quartz_block,10,minecraft:quartz_pillar,10,minecraft:smooth_quartz,10,minecraft:quartz_block,100)
RB(-3,0,-3,minecraft:chiseled_quartz_block,10,minecraft:quartz_pillar,10,minecraft:smooth_quartz,10,minecraft:quartz_block,100)
RB(-3,1,-3,minecraft:chiseled_quartz_block,10,minecraft:quartz_pillar,10,minecraft:smooth_quartz,10,minecraft:quartz_block,100)
RB(-3,2,-3,minecraft:chiseled_quartz_block,10,minecraft:quartz_pillar,10,minecraft:smooth_quartz,10,minecraft:quartz_block,100)
RB(-3,3,-3,minecraft:chiseled_quartz_block,10,minecraft:quartz_pillar,10,minecraft:smooth_quartz,10,minecraft:quartz_block,100)
RB(-3,0,-2,minecraft:chiseled_quartz_block,10,minecraft:quartz_pillar,10,minecraft:smooth_quartz,10,minecraft:quartz_block,100)
RB(-3,1,-2,minecraft:chiseled_quartz_block,10,minecraft:quartz_pillar,10,minecraft:smooth_quartz,10,minecraft:quartz_block,100)
RB(-3,2,-2,minecraft:chiseled_quartz_block,10,minecraft:quartz_pillar,10,minecraft:smooth_quartz,10,minecraft:quartz_block,100)
RB(-3,3,-2,minecraft:chiseled_quartz_block,10,minecraft:quartz_pillar,10,minecraft:smooth_quartz,10,minecraft:quartz_block,100)
RB(-3,0,-1,minecraft:chiseled_quartz_block,10,minecraft:quartz_pillar,10,minecraft:smooth_quartz,10,minecraft:quartz_block,100)
RB(-3,1,-1,minecraft:chiseled_quartz_block,10,minecraft:quartz_pillar,10,minecraft:smooth_quartz,10,minecraft:quartz_block,100)
RB(-3,2,-1,minecraft:chiseled_quartz_block,10,minecraft:quartz_pillar,10,minecraft:smooth_quartz,10,minecraft:quartz_block,100)
RB(-3,3,-1,minecraft:chiseled_quartz_block,10,minecraft:quartz_pillar,10,minecraft:smooth_quartz,10,minecraft:quartz_block,100)
RB(-3,0,0,minecraft:chiseled_quartz_block,10,minecraft:quartz_pillar,10,minecraft:smooth_quartz,10,minecraft:quartz_block,100)
RB(-3,1,0,minecraft:chiseled_quartz_block,10,minecraft:quartz_pillar,10,minecraft:smooth_quartz,10,minecraft:quartz_block,100)
RB(-3,2,0,minecraft:chiseled_quartz_block,10,minecraft:quartz_pillar,10,minecraft:smooth_quartz,10,minecraft:quartz_block,100)
RB(-3,3,0,minecraft:chiseled_quartz_block,10,minecraft:quartz_pillar,10,minecraft:smooth_quartz,10,minecraft:quartz_block,100)
RB(-3,4,0,minecraft:chiseled_quartz_block,10,minecraft:quartz_pillar,10,minecraft:smooth_quartz,10,minecraft:quartz_block,100)
RB(-3,0,1,minecraft:chiseled_quartz_block,10,minecraft:quartz_pillar,10,minecraft:smooth_quartz,10,minecraft:quartz_block,100)
RB(-3,1,1,minecraft:chiseled_quartz_block,10,minecraft:quartz_pillar,10,minecraft:smooth_quartz,10,minecraft:quartz_block,100)
RB(-3,2,1,minecraft:chiseled_quartz_block,10,minecraft:quartz_pillar,10,minecraft:smooth_quartz,10,minecraft:quartz_block,100)
RB(-3,3,1,minecraft:chiseled_quartz_block,10,minecraft:quartz_pillar,10,minecraft:smooth_quartz,10,minecraft:quartz_block,100)
RB(-3,0,2,minecraft:chiseled_quartz_block,10,minecraft:quartz_pillar,10,minecraft:smooth_quartz,10,minecraft:quartz_block,100)
RB(-3,1,2,minecraft:chiseled_quartz_block,10,minecraft:quartz_pillar,10,minecraft:smooth_quartz,10,minecraft:quartz_block,100)
RB(-2,0,-12,minecraft:chiseled_quartz_block,10,minecraft:quartz_pillar,10,minecraft:smooth_quartz,10,minecraft:quartz_block,100)
RB(-2,0,-11,minecraft:chiseled_quartz_block,10,minecraft:quartz_pillar,10,minecraft:smooth_quartz,10,minecraft:quartz_block,100)
RB(-2,0,-10,minecraft:chiseled_quartz_block,10,minecraft:quartz_pillar,10,minecraft:smooth_quartz,10,minecraft:quartz_block,100)
RB(-2,0,-9,minecraft:chiseled_quartz_block,10,minecraft:quartz_pillar,10,minecraft:smooth_quartz,10,minecraft:quartz_block,100)
RB(-2,1,-9,minecraft:chiseled_quartz_block,10,minecraft:quartz_pillar,10,minecraft:smooth_quartz,10,minecraft:quartz_block,100)
RB(-2,0,-8,minecraft:chiseled_quartz_block,10,minecraft:quartz_pillar,10,minecraft:smooth_quartz,10,minecraft:quartz_block,100)
RB(-2,1,-8,minecraft:chiseled_quartz_block,10,minecraft:quartz_pillar,10,minecraft:smooth_quartz,10,minecraft:quartz_block,100)
RB(-2,0,-7,minecraft:chiseled_quartz_block,10,minecraft:quartz_pillar,10,minecraft:smooth_quartz,10,minecraft:quartz_block,100)
RB(-2,1,-7,minecraft:chiseled_quartz_block,10,minecraft:quartz_pillar,10,minecraft:smooth_quartz,10,minecraft:quartz_block,100)
RB(-2,2,-7,minecraft:chiseled_quartz_block,10,minecraft:quartz_pillar,10,minecraft:smooth_quartz,10,minecraft:quartz_block,100)
RB(-2,0,-6,minecraft:chiseled_quartz_block,10,minecraft:quartz_pillar,10,minecraft:smooth_quartz,10,minecraft:quartz_block,100)
RB(-2,1,-6,minecraft:chiseled_quartz_block,10,minecraft:quartz_pillar,10,minecraft:smooth_quartz,10,minecraft:quartz_block,100)
RB(-2,2,-6,minecraft:chiseled_quartz_block,10,minecraft:quartz_pillar,10,minecraft:smooth_quartz,10,minecraft:quartz_block,100)
RB(-2,0,-5,minecraft:chiseled_quartz_block,10,minecraft:quartz_pillar,10,minecraft:smooth_quartz,10,minecraft:quartz_block,100)
RB(-2,1,-5,minecraft:chiseled_quartz_block,10,minecraft:quartz_pillar,10,minecraft:smooth_quartz,10,minecraft:quartz_block,100)
RB(-2,2,-5,minecraft:chiseled_quartz_block,10,minecraft:quartz_pillar,10,minecraft:smooth_quartz,10,minecraft:quartz_block,100)
RB(-2,3,-5,minecraft:chiseled_quartz_block,10,minecraft:quartz_pillar,10,minecraft:smooth_quartz,10,minecraft:quartz_block,100)
RB(-2,0,-4,minecraft:chiseled_quartz_block,10,minecraft:quartz_pillar,10,minecraft:smooth_quartz,10,minecraft:quartz_block,100)
RB(-2,1,-4,minecraft:chiseled_quartz_block,10,minecraft:quartz_pillar,10,minecraft:smooth_quartz,10,minecraft:quartz_block,100)
RB(-2,2,-4,minecraft:chiseled_quartz_block,10,minecraft:quartz_pillar,10,minecraft:smooth_quartz,10,minecraft:quartz_block,100)
RB(-2,3,-4,minecraft:chiseled_quartz_block,10,minecraft:quartz_pillar,10,minecraft:smooth_quartz,10,minecraft:quartz_block,100)
RB(-2,0,-3,minecraft:chiseled_quartz_block,10,minecraft:quartz_pillar,10,minecraft:smooth_quartz,10,minecraft:quartz_block,100)
RB(-2,1,-3,minecraft:chiseled_quartz_block,10,minecraft:quartz_pillar,10,minecraft:smooth_quartz,10,minecraft:quartz_block,100)
RB(-2,2,-3,minecraft:chiseled_quartz_block,10,minecraft:quartz_pillar,10,minecraft:smooth_quartz,10,minecraft:quartz_block,100)
RB(-2,3,-3,minecraft:chiseled_quartz_block,10,minecraft:quartz_pillar,10,minecraft:smooth_quartz,10,minecraft:quartz_block,100)
RB(-2,0,-2,minecraft:chiseled_quartz_block,10,minecraft:quartz_pillar,10,minecraft:smooth_quartz,10,minecraft:quartz_block,100)
RB(-2,1,-2,minecraft:chiseled_quartz_block,10,minecraft:quartz_pillar,10,minecraft:smooth_quartz,10,minecraft:quartz_block,100)
RB(-2,2,-2,minecraft:chiseled_quartz_block,10,minecraft:quartz_pillar,10,minecraft:smooth_quartz,10,minecraft:quartz_block,100)
RB(-2,3,-2,minecraft:chiseled_quartz_block,10,minecraft:quartz_pillar,10,minecraft:smooth_quartz,10,minecraft:quartz_block,100)
RB(-2,4,-2,minecraft:chiseled_quartz_block,10,minecraft:quartz_pillar,10,minecraft:smooth_quartz,10,minecraft:quartz_block,100)
RB(-2,0,-1,minecraft:chiseled_quartz_block,10,minecraft:quartz_pillar,10,minecraft:smooth_quartz,10,minecraft:quartz_block,100)
RB(-2,1,-1,minecraft:chiseled_quartz_block,10,minecraft:quartz_pillar,10,minecraft:smooth_quartz,10,minecraft:quartz_block,100)
RB(-2,2,-1,minecraft:chiseled_quartz_block,10,minecraft:quartz_pillar,10,minecraft:smooth_quartz,10,minecraft:quartz_block,100)
RB(-2,3,-1,minecraft:chiseled_quartz_block,10,minecraft:quartz_pillar,10,minecraft:smooth_quartz,10,minecraft:quartz_block,100)
RB(-2,4,-1,minecraft:chiseled_quartz_block,10,minecraft:quartz_pillar,10,minecraft:smooth_quartz,10,minecraft:quartz_block,100)
RB(-2,0,0,minecraft:chiseled_quartz_block,10,minecraft:quartz_pillar,10,minecraft:smooth_quartz,10,minecraft:quartz_block,100)
RB(-2,1,0,minecraft:chiseled_quartz_block,10,minecraft:quartz_pillar,10,minecraft:smooth_quartz,10,minecraft:quartz_block,100)
RB(-2,2,0,minecraft:chiseled_quartz_block,10,minecraft:quartz_pillar,10,minecraft:smooth_quartz,10,minecraft:quartz_block,100)
RB(-2,3,0,minecraft:chiseled_quartz_block,10,minecraft:quartz_pillar,10,minecraft:smooth_quartz,10,minecraft:quartz_block,100)
RB(-2,4,0,minecraft:chiseled_quartz_block,10,minecraft:quartz_pillar,10,minecraft:smooth_quartz,10,minecraft:quartz_block,100)
RB(-2,0,1,minecraft:chiseled_quartz_block,10,minecraft:quartz_pillar,10,minecraft:smooth_quartz,10,minecraft:quartz_block,100)
RB(-2,1,1,minecraft:chiseled_quartz_block,10,minecraft:quartz_pillar,10,minecraft:smooth_quartz,10,minecraft:quartz_block,100)
RB(-2,2,1,minecraft:chiseled_quartz_block,10,minecraft:quartz_pillar,10,minecraft:smooth_quartz,10,minecraft:quartz_block,100)
RB(-2,3,1,minecraft:chiseled_quartz_block,10,minecraft:quartz_pillar,10,minecraft:smooth_quartz,10,minecraft:quartz_block,100)
RB(-2,4,1,minecraft:chiseled_quartz_block,10,minecraft:quartz_pillar,10,minecraft:smooth_quartz,10,minecraft:quartz_block,100)
RB(-2,5,1,minecraft:chiseled_quartz_block,10,minecraft:quartz_pillar,10,minecraft:smooth_quartz,10,minecraft:quartz_block,100)
RB(-2,0,2,minecraft:chiseled_quartz_block,10,minecraft:quartz_pillar,10,minecraft:smooth_quartz,10,minecraft:quartz_block,100)
RB(-2,1,2,minecraft:chiseled_quartz_block,10,minecraft:quartz_pillar,10,minecraft:smooth_quartz,10,minecraft:quartz_block,100)
RB(-2,2,2,minecraft:chiseled_quartz_block,10,minecraft:quartz_pillar,10,minecraft:smooth_quartz,10,minecraft:quartz_block,100)
RB(-2,3,2,minecraft:chiseled_quartz_block,10,minecraft:quartz_pillar,10,minecraft:smooth_quartz,10,minecraft:quartz_block,100)
RB(-2,4,2,minecraft:chiseled_quartz_block,10,minecraft:quartz_pillar,10,minecraft:smooth_quartz,10,minecraft:quartz_block,100)
RB(-2,5,2,minecraft:chiseled_quartz_block,10,minecraft:quartz_pillar,10,minecraft:smooth_quartz,10,minecraft:quartz_block,100)
RB(-2,0,3,minecraft:chiseled_quartz_block,10,minecraft:quartz_pillar,10,minecraft:smooth_quartz,10,minecraft:quartz_block,100)
RB(-2,1,3,minecraft:chiseled_quartz_block,10,minecraft:quartz_pillar,10,minecraft:smooth_quartz,10,minecraft:quartz_block,100)
RB(-2,2,3,minecraft:chiseled_quartz_block,10,minecraft:quartz_pillar,10,minecraft:smooth_quartz,10,minecraft:quartz_block,100)
RB(-2,3,3,minecraft:chiseled_quartz_block,10,minecraft:quartz_pillar,10,minecraft:smooth_quartz,10,minecraft:quartz_block,100)
RB(-2,0,4,minecraft:chiseled_quartz_block,10,minecraft:quartz_pillar,10,minecraft:smooth_quartz,10,minecraft:quartz_block,100)
RB(-2,1,4,minecraft:chiseled_quartz_block,10,minecraft:quartz_pillar,10,minecraft:smooth_quartz,10,minecraft:quartz_block,100)
RB(-2,0,5,minecraft:chiseled_quartz_block,10,minecraft:quartz_pillar,10,minecraft:smooth_quartz,10,minecraft:quartz_block,100)
RB(-1,0,-12,minecraft:chiseled_quartz_block,10,minecraft:quartz_pillar,10,minecraft:smooth_quartz,10,minecraft:quartz_block,100)
RB(-1,0,-11,minecraft:chiseled_quartz_block,10,minecraft:quartz_pillar,10,minecraft:smooth_quartz,10,minecraft:quartz_block,100)
RB(-1,0,-10,minecraft:chiseled_quartz_block,10,minecraft:quartz_pillar,10,minecraft:smooth_quartz,10,minecraft:quartz_block,100)
RB(-1,0,-9,minecraft:chiseled_quartz_block,10,minecraft:quartz_pillar,10,minecraft:smooth_quartz,10,minecraft:quartz_block,100)
RB(-1,1,-9,minecraft:chiseled_quartz_block,10,minecraft:quartz_pillar,10,minecraft:smooth_quartz,10,minecraft:quartz_block,100)
RB(-1,0,-8,minecraft:chiseled_quartz_block,10,minecraft:quartz_pillar,10,minecraft:smooth_quartz,10,minecraft:quartz_block,100)
RB(-1,1,-8,minecraft:chiseled_quartz_block,10,minecraft:quartz_pillar,10,minecraft:smooth_quartz,10,minecraft:quartz_block,100)
RB(-1,0,-7,minecraft:chiseled_quartz_block,10,minecraft:quartz_pillar,10,minecraft:smooth_quartz,10,minecraft:quartz_block,100)
RB(-1,1,-7,minecraft:chiseled_quartz_block,10,minecraft:quartz_pillar,10,minecraft:smooth_quartz,10,minecraft:quartz_block,100)
RB(-1,2,-7,minecraft:chiseled_quartz_block,10,minecraft:quartz_pillar,10,minecraft:smooth_quartz,10,minecraft:quartz_block,100)
RB(-1,0,-6,minecraft:chiseled_quartz_block,10,minecraft:quartz_pillar,10,minecraft:smooth_quartz,10,minecraft:quartz_block,100)
RB(-1,1,-6,minecraft:chiseled_quartz_block,10,minecraft:quartz_pillar,10,minecraft:smooth_quartz,10,minecraft:quartz_block,100)
RB(-1,2,-6,minecraft:chiseled_quartz_block,10,minecraft:quartz_pillar,10,minecraft:smooth_quartz,10,minecraft:quartz_block,100)
RB(-1,0,-5,minecraft:chiseled_quartz_block,10,minecraft:quartz_pillar,10,minecraft:smooth_quartz,10,minecraft:quartz_block,100)
RB(-1,1,-5,minecraft:chiseled_quartz_block,10,minecraft:quartz_pillar,10,minecraft:smooth_quartz,10,minecraft:quartz_block,100)
RB(-1,2,-5,minecraft:chiseled_quartz_block,10,minecraft:quartz_pillar,10,minecraft:smooth_quartz,10,minecraft:quartz_block,100)
RB(-1,3,-5,minecraft:chiseled_quartz_block,10,minecraft:quartz_pillar,10,minecraft:smooth_quartz,10,minecraft:quartz_block,100)
RB(-1,0,-4,minecraft:chiseled_quartz_block,10,minecraft:quartz_pillar,10,minecraft:smooth_quartz,10,minecraft:quartz_block,100)
RB(-1,1,-4,minecraft:chiseled_quartz_block,10,minecraft:quartz_pillar,10,minecraft:smooth_quartz,10,minecraft:quartz_block,100)
RB(-1,2,-4,minecraft:chiseled_quartz_block,10,minecraft:quartz_pillar,10,minecraft:smooth_quartz,10,minecraft:quartz_block,100)
RB(-1,3,-4,minecraft:chiseled_quartz_block,10,minecraft:quartz_pillar,10,minecraft:smooth_quartz,10,minecraft:quartz_block,100)
RB(-1,0,-3,minecraft:chiseled_quartz_block,10,minecraft:quartz_pillar,10,minecraft:smooth_quartz,10,minecraft:quartz_block,100)
RB(-1,1,-3,minecraft:chiseled_quartz_block,10,minecraft:quartz_pillar,10,minecraft:smooth_quartz,10,minecraft:quartz_block,100)
RB(-1,2,-3,minecraft:chiseled_quartz_block,10,minecraft:quartz_pillar,10,minecraft:smooth_quartz,10,minecraft:quartz_block,100)
RB(-1,3,-3,minecraft:chiseled_quartz_block,10,minecraft:quartz_pillar,10,minecraft:smooth_quartz,10,minecraft:quartz_block,100)
RB(-1,4,-3,minecraft:chiseled_quartz_block,10,minecraft:quartz_pillar,10,minecraft:smooth_quartz,10,minecraft:quartz_block,100)
RB(-1,0,-2,minecraft:chiseled_quartz_block,10,minecraft:quartz_pillar,10,minecraft:smooth_quartz,10,minecraft:quartz_block,100)
RB(-1,1,-2,minecraft:chiseled_quartz_block,10,minecraft:quartz_pillar,10,minecraft:smooth_quartz,10,minecraft:quartz_block,100)
RB(-1,2,-2,minecraft:chiseled_quartz_block,10,minecraft:quartz_pillar,10,minecraft:smooth_quartz,10,minecraft:quartz_block,100)
RB(-1,3,-2,minecraft:chiseled_quartz_block,10,minecraft:quartz_pillar,10,minecraft:smooth_quartz,10,minecraft:quartz_block,100)
RB(-1,4,-2,minecraft:chiseled_quartz_block,10,minecraft:quartz_pillar,10,minecraft:smooth_quartz,10,minecraft:quartz_block,100)
RB(-1,0,-1,minecraft:chiseled_quartz_block,10,minecraft:quartz_pillar,10,minecraft:smooth_quartz,10,minecraft:quartz_block,100)
RB(-1,1,-1,minecraft:chiseled_quartz_block,10,minecraft:quartz_pillar,10,minecraft:smooth_quartz,10,minecraft:quartz_block,100)
RB(-1,2,-1,minecraft:chiseled_quartz_block,10,minecraft:quartz_pillar,10,minecraft:smooth_quartz,10,minecraft:quartz_block,100)
RB(-1,3,-1,minecraft:chiseled_quartz_block,10,minecraft:quartz_pillar,10,minecraft:smooth_quartz,10,minecraft:quartz_block,100)
RB(-1,4,-1,minecraft:chiseled_quartz_block,10,minecraft:quartz_pillar,10,minecraft:smooth_quartz,10,minecraft:quartz_block,100)
RB(-1,5,-1,minecraft:chiseled_quartz_block,10,minecraft:quartz_pillar,10,minecraft:smooth_quartz,10,minecraft:quartz_block,100)
RB(-1,0,0,minecraft:chiseled_quartz_block,10,minecraft:quartz_pillar,10,minecraft:smooth_quartz,10,minecraft:quartz_block,100)
RB(-1,1,0,minecraft:chiseled_quartz_block,10,minecraft:quartz_pillar,10,minecraft:smooth_quartz,10,minecraft:quartz_block,100)
RB(-1,2,0,minecraft:chiseled_quartz_block,10,minecraft:quartz_pillar,10,minecraft:smooth_quartz,10,minecraft:quartz_block,100)
RB(-1,3,0,minecraft:chiseled_quartz_block,10,minecraft:quartz_pillar,10,minecraft:smooth_quartz,10,minecraft:quartz_block,100)
RB(-1,4,0,minecraft:chiseled_quartz_block,10,minecraft:quartz_pillar,10,minecraft:smooth_quartz,10,minecraft:quartz_block,100)
RB(-1,5,0,minecraft:chiseled_quartz_block,10,minecraft:quartz_pillar,10,minecraft:smooth_quartz,10,minecraft:quartz_block,100)
RB(-1,0,1,minecraft:chiseled_quartz_block,10,minecraft:quartz_pillar,10,minecraft:smooth_quartz,10,minecraft:quartz_block,100)
RB(-1,1,1,minecraft:chiseled_quartz_block,10,minecraft:quartz_pillar,10,minecraft:smooth_quartz,10,minecraft:quartz_block,100)
RB(-1,2,1,minecraft:chiseled_quartz_block,10,minecraft:quartz_pillar,10,minecraft:smooth_quartz,10,minecraft:quartz_block,100)
RB(-1,3,1,minecraft:chiseled_quartz_block,10,minecraft:quartz_pillar,10,minecraft:smooth_quartz,10,minecraft:quartz_block,100)
RB(-1,4,1,minecraft:chiseled_quartz_block,10,minecraft:quartz_pillar,10,minecraft:smooth_quartz,10,minecraft:quartz_block,100)
RB(-1,5,1,minecraft:chiseled_quartz_block,10,minecraft:quartz_pillar,10,minecraft:smooth_quartz,10,minecraft:quartz_block,100)
RB(-1,0,2,minecraft:chiseled_quartz_block,10,minecraft:quartz_pillar,10,minecraft:smooth_quartz,10,minecraft:quartz_block,100)
RB(-1,1,2,minecraft:chiseled_quartz_block,10,minecraft:quartz_pillar,10,minecraft:smooth_quartz,10,minecraft:quartz_block,100)
RB(-1,2,2,minecraft:chiseled_quartz_block,10,minecraft:quartz_pillar,10,minecraft:smooth_quartz,10,minecraft:quartz_block,100)
RB(-1,3,2,minecraft:chiseled_quartz_block,10,minecraft:quartz_pillar,10,minecraft:smooth_quartz,10,minecraft:quartz_block,100)
RB(-1,4,2,minecraft:chiseled_quartz_block,10,minecraft:quartz_pillar,10,minecraft:smooth_quartz,10,minecraft:quartz_block,100)
RB(-1,5,2,minecraft:chiseled_quartz_block,10,minecraft:quartz_pillar,10,minecraft:smooth_quartz,10,minecraft:quartz_block,100)
RB(-1,0,3,minecraft:chiseled_quartz_block,10,minecraft:quartz_pillar,10,minecraft:smooth_quartz,10,minecraft:quartz_block,100)
RB(-1,1,3,minecraft:chiseled_quartz_block,10,minecraft:quartz_pillar,10,minecraft:smooth_quartz,10,minecraft:quartz_block,100)
RB(-1,2,3,minecraft:chiseled_quartz_block,10,minecraft:quartz_pillar,10,minecraft:smooth_quartz,10,minecraft:quartz_block,100)
RB(-1,3,3,minecraft:chiseled_quartz_block,10,minecraft:quartz_pillar,10,minecraft:smooth_quartz,10,minecraft:quartz_block,100)
RB(-1,4,3,minecraft:chiseled_quartz_block,10,minecraft:quartz_pillar,10,minecraft:smooth_quartz,10,minecraft:quartz_block,100)
RB(-1,5,3,minecraft:chiseled_quartz_block,10,minecraft:quartz_pillar,10,minecraft:smooth_quartz,10,minecraft:quartz_block,100)
RB(-1,6,3,minecraft:chiseled_quartz_block,10,minecraft:quartz_pillar,10,minecraft:smooth_quartz,10,minecraft:quartz_block,100)
RB(-1,0,4,minecraft:chiseled_quartz_block,10,minecraft:quartz_pillar,10,minecraft:smooth_quartz,10,minecraft:quartz_block,100)
RB(-1,1,4,minecraft:chiseled_quartz_block,10,minecraft:quartz_pillar,10,minecraft:smooth_quartz,10,minecraft:quartz_block,100)
RB(-1,2,4,minecraft:chiseled_quartz_block,10,minecraft:quartz_pillar,10,minecraft:smooth_quartz,10,minecraft:quartz_block,100)
RB(-1,3,4,minecraft:chiseled_quartz_block,10,minecraft:quartz_pillar,10,minecraft:smooth_quartz,10,minecraft:quartz_block,100)
RB(-1,4,4,minecraft:chiseled_quartz_block,10,minecraft:quartz_pillar,10,minecraft:smooth_quartz,10,minecraft:quartz_block,100)
RB(-1,5,4,minecraft:chiseled_quartz_block,10,minecraft:quartz_pillar,10,minecraft:smooth_quartz,10,minecraft:quartz_block,100)
RB(-1,6,4,minecraft:chiseled_quartz_block,10,minecraft:quartz_pillar,10,minecraft:smooth_quartz,10,minecraft:quartz_block,100)
RB(-1,1,5,minecraft:chiseled_quartz_block,10,minecraft:quartz_pillar,10,minecraft:smooth_quartz,10,minecraft:quartz_block,100)
RB(-1,2,5,minecraft:chiseled_quartz_block,10,minecraft:quartz_pillar,10,minecraft:smooth_quartz,10,minecraft:quartz_block,100)
RB(-1,3,5,minecraft:chiseled_quartz_block,10,minecraft:quartz_pillar,10,minecraft:smooth_quartz,10,minecraft:quartz_block,100)
RB(-1,4,5,minecraft:chiseled_quartz_block,10,minecraft:quartz_pillar,10,minecraft:smooth_quartz,10,minecraft:quartz_block,100)
RB(-1,2,6,minecraft:chiseled_quartz_block,10,minecraft:quartz_pillar,10,minecraft:smooth_quartz,10,minecraft:quartz_block,100)
RB(0,0,-12,minecraft:chiseled_quartz_block,10,minecraft:quartz_pillar,10,minecraft:smooth_quartz,10,minecraft:quartz_block,100)
RB(0,0,-11,minecraft:chiseled_quartz_block,10,minecraft:quartz_pillar,10,minecraft:smooth_quartz,10,minecraft:quartz_block,100)
RB(0,0,-10,minecraft:chiseled_quartz_block,10,minecraft:quartz_pillar,10,minecraft:smooth_quartz,10,minecraft:quartz_block,100)
RB(0,0,-9,minecraft:chiseled_quartz_block,10,minecraft:quartz_pillar,10,minecraft:smooth_quartz,10,minecraft:quartz_block,100)
RB(0,1,-9,minecraft:chiseled_quartz_block,10,minecraft:quartz_pillar,10,minecraft:smooth_quartz,10,minecraft:quartz_block,100)
RB(0,0,-8,minecraft:chiseled_quartz_block,10,minecraft:quartz_pillar,10,minecraft:smooth_quartz,10,minecraft:quartz_block,100)
RB(0,1,-8,minecraft:chiseled_quartz_block,10,minecraft:quartz_pillar,10,minecraft:smooth_quartz,10,minecraft:quartz_block,100)
RB(0,0,-7,minecraft:chiseled_quartz_block,10,minecraft:quartz_pillar,10,minecraft:smooth_quartz,10,minecraft:quartz_block,100)
RB(0,1,-7,minecraft:chiseled_quartz_block,10,minecraft:quartz_pillar,10,minecraft:smooth_quartz,10,minecraft:quartz_block,100)
RB(0,2,-7,minecraft:chiseled_quartz_block,10,minecraft:quartz_pillar,10,minecraft:smooth_quartz,10,minecraft:quartz_block,100)
RB(0,0,-6,minecraft:chiseled_quartz_block,10,minecraft:quartz_pillar,10,minecraft:smooth_quartz,10,minecraft:quartz_block,100)
RB(0,1,-6,minecraft:chiseled_quartz_block,10,minecraft:quartz_pillar,10,minecraft:smooth_quartz,10,minecraft:quartz_block,100)
RB(0,2,-6,minecraft:chiseled_quartz_block,10,minecraft:quartz_pillar,10,minecraft:smooth_quartz,10,minecraft:quartz_block,100)
RB(0,0,-5,minecraft:chiseled_quartz_block,10,minecraft:quartz_pillar,10,minecraft:smooth_quartz,10,minecraft:quartz_block,100)
RB(0,1,-5,minecraft:chiseled_quartz_block,10,minecraft:quartz_pillar,10,minecraft:smooth_quartz,10,minecraft:quartz_block,100)
RB(0,2,-5,minecraft:chiseled_quartz_block,10,minecraft:quartz_pillar,10,minecraft:smooth_quartz,10,minecraft:quartz_block,100)
RB(0,3,-5,minecraft:chiseled_quartz_block,10,minecraft:quartz_pillar,10,minecraft:smooth_quartz,10,minecraft:quartz_block,100)
RB(0,0,-4,minecraft:chiseled_quartz_block,10,minecraft:quartz_pillar,10,minecraft:smooth_quartz,10,minecraft:quartz_block,100)
RB(0,1,-4,minecraft:chiseled_quartz_block,10,minecraft:quartz_pillar,10,minecraft:smooth_quartz,10,minecraft:quartz_block,100)
RB(0,2,-4,minecraft:chiseled_quartz_block,10,minecraft:quartz_pillar,10,minecraft:smooth_quartz,10,minecraft:quartz_block,100)
RB(0,3,-4,minecraft:chiseled_quartz_block,10,minecraft:quartz_pillar,10,minecraft:smooth_quartz,10,minecraft:quartz_block,100)
RB(0,0,-3,minecraft:chiseled_quartz_block,10,minecraft:quartz_pillar,10,minecraft:smooth_quartz,10,minecraft:quartz_block,100)
RB(0,1,-3,minecraft:chiseled_quartz_block,10,minecraft:quartz_pillar,10,minecraft:smooth_quartz,10,minecraft:quartz_block,100)
RB(0,2,-3,minecraft:chiseled_quartz_block,10,minecraft:quartz_pillar,10,minecraft:smooth_quartz,10,minecraft:quartz_block,100)
RB(0,3,-3,minecraft:chiseled_quartz_block,10,minecraft:quartz_pillar,10,minecraft:smooth_quartz,10,minecraft:quartz_block,100)
RB(0,4,-3,minecraft:chiseled_quartz_block,10,minecraft:quartz_pillar,10,minecraft:smooth_quartz,10,minecraft:quartz_block,100)
RB(0,0,-2,minecraft:chiseled_quartz_block,10,minecraft:quartz_pillar,10,minecraft:smooth_quartz,10,minecraft:quartz_block,100)
RB(0,1,-2,minecraft:chiseled_quartz_block,10,minecraft:quartz_pillar,10,minecraft:smooth_quartz,10,minecraft:quartz_block,100)
RB(0,2,-2,minecraft:chiseled_quartz_block,10,minecraft:quartz_pillar,10,minecraft:smooth_quartz,10,minecraft:quartz_block,100)
RB(0,3,-2,minecraft:chiseled_quartz_block,10,minecraft:quartz_pillar,10,minecraft:smooth_quartz,10,minecraft:quartz_block,100)
RB(0,4,-2,minecraft:chiseled_quartz_block,10,minecraft:quartz_pillar,10,minecraft:smooth_quartz,10,minecraft:quartz_block,100)
RB(0,0,-1,minecraft:chiseled_quartz_block,10,minecraft:quartz_pillar,10,minecraft:smooth_quartz,10,minecraft:quartz_block,100)
RB(0,1,-1,minecraft:chiseled_quartz_block,10,minecraft:quartz_pillar,10,minecraft:smooth_quartz,10,minecraft:quartz_block,100)
RB(0,2,-1,minecraft:chiseled_quartz_block,10,minecraft:quartz_pillar,10,minecraft:smooth_quartz,10,minecraft:quartz_block,100)
RB(0,3,-1,minecraft:chiseled_quartz_block,10,minecraft:quartz_pillar,10,minecraft:smooth_quartz,10,minecraft:quartz_block,100)
RB(0,4,-1,minecraft:chiseled_quartz_block,10,minecraft:quartz_pillar,10,minecraft:smooth_quartz,10,minecraft:quartz_block,100)
RB(0,5,-1,minecraft:chiseled_quartz_block,10,minecraft:quartz_pillar,10,minecraft:smooth_quartz,10,minecraft:quartz_block,100)
RB(0,0,0,minecraft:chiseled_quartz_block,10,minecraft:quartz_pillar,10,minecraft:smooth_quartz,10,minecraft:quartz_block,100)
RB(0,1,0,minecraft:chiseled_quartz_block,10,minecraft:quartz_pillar,10,minecraft:smooth_quartz,10,minecraft:quartz_block,100)
RB(0,2,0,minecraft:chiseled_quartz_block,10,minecraft:quartz_pillar,10,minecraft:smooth_quartz,10,minecraft:quartz_block,100)
RB(0,3,0,minecraft:chiseled_quartz_block,10,minecraft:quartz_pillar,10,minecraft:smooth_quartz,10,minecraft:quartz_block,100)
RB(0,4,0,minecraft:chiseled_quartz_block,10,minecraft:quartz_pillar,10,minecraft:smooth_quartz,10,minecraft:quartz_block,100)
RB(0,5,0,minecraft:chiseled_quartz_block,10,minecraft:quartz_pillar,10,minecraft:smooth_quartz,10,minecraft:quartz_block,100)
RB(0,0,1,minecraft:chiseled_quartz_block,10,minecraft:quartz_pillar,10,minecraft:smooth_quartz,10,minecraft:quartz_block,100)
RB(0,1,1,minecraft:chiseled_quartz_block,10,minecraft:quartz_pillar,10,minecraft:smooth_quartz,10,minecraft:quartz_block,100)
RB(0,2,1,minecraft:chiseled_quartz_block,10,minecraft:quartz_pillar,10,minecraft:smooth_quartz,10,minecraft:quartz_block,100)
RB(0,3,1,minecraft:chiseled_quartz_block,10,minecraft:quartz_pillar,10,minecraft:smooth_quartz,10,minecraft:quartz_block,100)
RB(0,4,1,minecraft:chiseled_quartz_block,10,minecraft:quartz_pillar,10,minecraft:smooth_quartz,10,minecraft:quartz_block,100)
RB(0,5,1,minecraft:chiseled_quartz_block,10,minecraft:quartz_pillar,10,minecraft:smooth_quartz,10,minecraft:quartz_block,100)
RB(0,6,1,minecraft:chiseled_quartz_block,10,minecraft:quartz_pillar,10,minecraft:smooth_quartz,10,minecraft:quartz_block,100)
RB(0,0,2,minecraft:chiseled_quartz_block,10,minecraft:quartz_pillar,10,minecraft:smooth_quartz,10,minecraft:quartz_block,100)
RB(0,1,2,minecraft:chiseled_quartz_block,10,minecraft:quartz_pillar,10,minecraft:smooth_quartz,10,minecraft:quartz_block,100)
RB(0,2,2,minecraft:chiseled_quartz_block,10,minecraft:quartz_pillar,10,minecraft:smooth_quartz,10,minecraft:quartz_block,100)
RB(0,3,2,minecraft:chiseled_quartz_block,10,minecraft:quartz_pillar,10,minecraft:smooth_quartz,10,minecraft:quartz_block,100)
RB(0,4,2,minecraft:chiseled_quartz_block,10,minecraft:quartz_pillar,10,minecraft:smooth_quartz,10,minecraft:quartz_block,100)
RB(0,5,2,minecraft:chiseled_quartz_block,10,minecraft:quartz_pillar,10,minecraft:smooth_quartz,10,minecraft:quartz_block,100)
RB(0,6,2,minecraft:chiseled_quartz_block,10,minecraft:quartz_pillar,10,minecraft:smooth_quartz,10,minecraft:quartz_block,100)
RB(0,0,3,minecraft:chiseled_quartz_block,10,minecraft:quartz_pillar,10,minecraft:smooth_quartz,10,minecraft:quartz_block,100)
RB(0,1,3,minecraft:chiseled_quartz_block,10,minecraft:quartz_pillar,10,minecraft:smooth_quartz,10,minecraft:quartz_block,100)
RB(0,2,3,minecraft:chiseled_quartz_block,10,minecraft:quartz_pillar,10,minecraft:smooth_quartz,10,minecraft:quartz_block,100)
RB(0,3,3,minecraft:chiseled_quartz_block,10,minecraft:quartz_pillar,10,minecraft:smooth_quartz,10,minecraft:quartz_block,100)
RB(0,4,3,minecraft:chiseled_quartz_block,10,minecraft:quartz_pillar,10,minecraft:smooth_quartz,10,minecraft:quartz_block,100)
RB(0,5,3,minecraft:chiseled_quartz_block,10,minecraft:quartz_pillar,10,minecraft:smooth_quartz,10,minecraft:quartz_block,100)
RB(0,6,3,minecraft:chiseled_quartz_block,10,minecraft:quartz_pillar,10,minecraft:smooth_quartz,10,minecraft:quartz_block,100)
RB(0,0,4,minecraft:chiseled_quartz_block,10,minecraft:quartz_pillar,10,minecraft:smooth_quartz,10,minecraft:quartz_block,100)
RB(0,1,4,minecraft:chiseled_quartz_block,10,minecraft:quartz_pillar,10,minecraft:smooth_quartz,10,minecraft:quartz_block,100)
RB(0,2,4,minecraft:chiseled_quartz_block,10,minecraft:quartz_pillar,10,minecraft:smooth_quartz,10,minecraft:quartz_block,100)
RB(0,3,4,minecraft:chiseled_quartz_block,10,minecraft:quartz_pillar,10,minecraft:smooth_quartz,10,minecraft:quartz_block,100)
RB(0,4,4,minecraft:chiseled_quartz_block,10,minecraft:quartz_pillar,10,minecraft:smooth_quartz,10,minecraft:quartz_block,100)
RB(0,5,4,minecraft:chiseled_quartz_block,10,minecraft:quartz_pillar,10,minecraft:smooth_quartz,10,minecraft:quartz_block,100)
RB(0,6,4,minecraft:chiseled_quartz_block,10,minecraft:quartz_pillar,10,minecraft:smooth_quartz,10,minecraft:quartz_block,100)
RB(0,7,4,minecraft:chiseled_quartz_block,10,minecraft:quartz_pillar,10,minecraft:smooth_quartz,10,minecraft:quartz_block,100)
RB(0,1,5,minecraft:chiseled_quartz_block,10,minecraft:quartz_pillar,10,minecraft:smooth_quartz,10,minecraft:quartz_block,100)
RB(0,2,5,minecraft:chiseled_quartz_block,10,minecraft:quartz_pillar,10,minecraft:smooth_quartz,10,minecraft:quartz_block,100)
RB(0,3,5,minecraft:chiseled_quartz_block,10,minecraft:quartz_pillar,10,minecraft:smooth_quartz,10,minecraft:quartz_block,100)
RB(0,4,5,minecraft:chiseled_quartz_block,10,minecraft:quartz_pillar,10,minecraft:smooth_quartz,10,minecraft:quartz_block,100)
RB(0,5,5,minecraft:chiseled_quartz_block,10,minecraft:quartz_pillar,10,minecraft:smooth_quartz,10,minecraft:quartz_block,100)
RB(0,6,5,minecraft:chiseled_quartz_block,10,minecraft:quartz_pillar,10,minecraft:smooth_quartz,10,minecraft:quartz_block,100)
RB(0,7,5,minecraft:chiseled_quartz_block,10,minecraft:quartz_pillar,10,minecraft:smooth_quartz,10,minecraft:quartz_block,100)
RB(0,2,6,minecraft:chiseled_quartz_block,10,minecraft:quartz_pillar,10,minecraft:smooth_quartz,10,minecraft:quartz_block,100)
RB(0,3,6,minecraft:chiseled_quartz_block,10,minecraft:quartz_pillar,10,minecraft:smooth_quartz,10,minecraft:quartz_block,100)
RB(0,4,6,minecraft:chiseled_quartz_block,10,minecraft:quartz_pillar,10,minecraft:smooth_quartz,10,minecraft:quartz_block,100)
RB(0,5,6,minecraft:chiseled_quartz_block,10,minecraft:quartz_pillar,10,minecraft:smooth_quartz,10,minecraft:quartz_block,100)
RB(0,6,6,minecraft:chiseled_quartz_block,10,minecraft:quartz_pillar,10,minecraft:smooth_quartz,10,minecraft:quartz_block,100)
RB(0,7,6,minecraft:chiseled_quartz_block,10,minecraft:quartz_pillar,10,minecraft:smooth_quartz,10,minecraft:quartz_block,100)
RB(0,4,7,minecraft:chiseled_quartz_block,10,minecraft:quartz_pillar,10,minecraft:smooth_quartz,10,minecraft:quartz_block,100)
RB(0,5,7,minecraft:chiseled_quartz_block,10,minecraft:quartz_pillar,10,minecraft:smooth_quartz,10,minecraft:quartz_block,100)
RB(1,0,-12,minecraft:chiseled_quartz_block,10,minecraft:quartz_pillar,10,minecraft:smooth_quartz,10,minecraft:quartz_block,100)
RB(1,0,-11,minecraft:chiseled_quartz_block,10,minecraft:quartz_pillar,10,minecraft:smooth_quartz,10,minecraft:quartz_block,100)
RB(1,0,-10,minecraft:chiseled_quartz_block,10,minecraft:quartz_pillar,10,minecraft:smooth_quartz,10,minecraft:quartz_block,100)
RB(1,0,-9,minecraft:chiseled_quartz_block,10,minecraft:quartz_pillar,10,minecraft:smooth_quartz,10,minecraft:quartz_block,100)
RB(1,1,-9,minecraft:chiseled_quartz_block,10,minecraft:quartz_pillar,10,minecraft:smooth_quartz,10,minecraft:quartz_block,100)
RB(1,0,-8,minecraft:chiseled_quartz_block,10,minecraft:quartz_pillar,10,minecraft:smooth_quartz,10,minecraft:quartz_block,100)
RB(1,1,-8,minecraft:chiseled_quartz_block,10,minecraft:quartz_pillar,10,minecraft:smooth_quartz,10,minecraft:quartz_block,100)
RB(1,0,-7,minecraft:chiseled_quartz_block,10,minecraft:quartz_pillar,10,minecraft:smooth_quartz,10,minecraft:quartz_block,100)
RB(1,1,-7,minecraft:chiseled_quartz_block,10,minecraft:quartz_pillar,10,minecraft:smooth_quartz,10,minecraft:quartz_block,100)
RB(1,2,-7,minecraft:chiseled_quartz_block,10,minecraft:quartz_pillar,10,minecraft:smooth_quartz,10,minecraft:quartz_block,100)
RB(1,0,-6,minecraft:chiseled_quartz_block,10,minecraft:quartz_pillar,10,minecraft:smooth_quartz,10,minecraft:quartz_block,100)
RB(1,1,-6,minecraft:chiseled_quartz_block,10,minecraft:quartz_pillar,10,minecraft:smooth_quartz,10,minecraft:quartz_block,100)
RB(1,2,-6,minecraft:chiseled_quartz_block,10,minecraft:quartz_pillar,10,minecraft:smooth_quartz,10,minecraft:quartz_block,100)
RB(1,0,-5,minecraft:chiseled_quartz_block,10,minecraft:quartz_pillar,10,minecraft:smooth_quartz,10,minecraft:quartz_block,100)
RB(1,1,-5,minecraft:chiseled_quartz_block,10,minecraft:quartz_pillar,10,minecraft:smooth_quartz,10,minecraft:quartz_block,100)
RB(1,2,-5,minecraft:chiseled_quartz_block,10,minecraft:quartz_pillar,10,minecraft:smooth_quartz,10,minecraft:quartz_block,100)
RB(1,3,-5,minecraft:chiseled_quartz_block,10,minecraft:quartz_pillar,10,minecraft:smooth_quartz,10,minecraft:quartz_block,100)
RB(1,0,-4,minecraft:chiseled_quartz_block,10,minecraft:quartz_pillar,10,minecraft:smooth_quartz,10,minecraft:quartz_block,100)
RB(1,1,-4,minecraft:chiseled_quartz_block,10,minecraft:quartz_pillar,10,minecraft:smooth_quartz,10,minecraft:quartz_block,100)
RB(1,2,-4,minecraft:chiseled_quartz_block,10,minecraft:quartz_pillar,10,minecraft:smooth_quartz,10,minecraft:quartz_block,100)
RB(1,3,-4,minecraft:chiseled_quartz_block,10,minecraft:quartz_pillar,10,minecraft:smooth_quartz,10,minecraft:quartz_block,100)
RB(1,0,-3,minecraft:chiseled_quartz_block,10,minecraft:quartz_pillar,10,minecraft:smooth_quartz,10,minecraft:quartz_block,100)
RB(1,1,-3,minecraft:chiseled_quartz_block,10,minecraft:quartz_pillar,10,minecraft:smooth_quartz,10,minecraft:quartz_block,100)
RB(1,2,-3,minecraft:chiseled_quartz_block,10,minecraft:quartz_pillar,10,minecraft:smooth_quartz,10,minecraft:quartz_block,100)
RB(1,3,-3,minecraft:chiseled_quartz_block,10,minecraft:quartz_pillar,10,minecraft:smooth_quartz,10,minecraft:quartz_block,100)
RB(1,4,-3,minecraft:chiseled_quartz_block,10,minecraft:quartz_pillar,10,minecraft:smooth_quartz,10,minecraft:quartz_block,100)
RB(1,0,-2,minecraft:chiseled_quartz_block,10,minecraft:quartz_pillar,10,minecraft:smooth_quartz,10,minecraft:quartz_block,100)
RB(1,1,-2,minecraft:chiseled_quartz_block,10,minecraft:quartz_pillar,10,minecraft:smooth_quartz,10,minecraft:quartz_block,100)
RB(1,2,-2,minecraft:chiseled_quartz_block,10,minecraft:quartz_pillar,10,minecraft:smooth_quartz,10,minecraft:quartz_block,100)
RB(1,3,-2,minecraft:chiseled_quartz_block,10,minecraft:quartz_pillar,10,minecraft:smooth_quartz,10,minecraft:quartz_block,100)
RB(1,4,-2,minecraft:chiseled_quartz_block,10,minecraft:quartz_pillar,10,minecraft:smooth_quartz,10,minecraft:quartz_block,100)
RB(1,0,-1,minecraft:chiseled_quartz_block,10,minecraft:quartz_pillar,10,minecraft:smooth_quartz,10,minecraft:quartz_block,100)
RB(1,1,-1,minecraft:chiseled_quartz_block,10,minecraft:quartz_pillar,10,minecraft:smooth_quartz,10,minecraft:quartz_block,100)
RB(1,2,-1,minecraft:chiseled_quartz_block,10,minecraft:quartz_pillar,10,minecraft:smooth_quartz,10,minecraft:quartz_block,100)
RB(1,3,-1,minecraft:chiseled_quartz_block,10,minecraft:quartz_pillar,10,minecraft:smooth_quartz,10,minecraft:quartz_block,100)
RB(1,4,-1,minecraft:chiseled_quartz_block,10,minecraft:quartz_pillar,10,minecraft:smooth_quartz,10,minecraft:quartz_block,100)
RB(1,5,-1,minecraft:chiseled_quartz_block,10,minecraft:quartz_pillar,10,minecraft:smooth_quartz,10,minecraft:quartz_block,100)
RB(1,0,0,minecraft:chiseled_quartz_block,10,minecraft:quartz_pillar,10,minecraft:smooth_quartz,10,minecraft:quartz_block,100)
RB(1,1,0,minecraft:chiseled_quartz_block,10,minecraft:quartz_pillar,10,minecraft:smooth_quartz,10,minecraft:quartz_block,100)
RB(1,2,0,minecraft:chiseled_quartz_block,10,minecraft:quartz_pillar,10,minecraft:smooth_quartz,10,minecraft:quartz_block,100)
RB(1,3,0,minecraft:chiseled_quartz_block,10,minecraft:quartz_pillar,10,minecraft:smooth_quartz,10,minecraft:quartz_block,100)
RB(1,4,0,minecraft:chiseled_quartz_block,10,minecraft:quartz_pillar,10,minecraft:smooth_quartz,10,minecraft:quartz_block,100)
RB(1,5,0,minecraft:chiseled_quartz_block,10,minecraft:quartz_pillar,10,minecraft:smooth_quartz,10,minecraft:quartz_block,100)
RB(1,0,1,minecraft:chiseled_quartz_block,10,minecraft:quartz_pillar,10,minecraft:smooth_quartz,10,minecraft:quartz_block,100)
RB(1,1,1,minecraft:chiseled_quartz_block,10,minecraft:quartz_pillar,10,minecraft:smooth_quartz,10,minecraft:quartz_block,100)
RB(1,2,1,minecraft:chiseled_quartz_block,10,minecraft:quartz_pillar,10,minecraft:smooth_quartz,10,minecraft:quartz_block,100)
RB(1,3,1,minecraft:chiseled_quartz_block,10,minecraft:quartz_pillar,10,minecraft:smooth_quartz,10,minecraft:quartz_block,100)
RB(1,4,1,minecraft:chiseled_quartz_block,10,minecraft:quartz_pillar,10,minecraft:smooth_quartz,10,minecraft:quartz_block,100)
RB(1,5,1,minecraft:chiseled_quartz_block,10,minecraft:quartz_pillar,10,minecraft:smooth_quartz,10,minecraft:quartz_block,100)
RB(1,6,1,minecraft:chiseled_quartz_block,10,minecraft:quartz_pillar,10,minecraft:smooth_quartz,10,minecraft:quartz_block,100)
RB(1,0,2,minecraft:chiseled_quartz_block,10,minecraft:quartz_pillar,10,minecraft:smooth_quartz,10,minecraft:quartz_block,100)
RB(1,1,2,minecraft:chiseled_quartz_block,10,minecraft:quartz_pillar,10,minecraft:smooth_quartz,10,minecraft:quartz_block,100)
RB(1,2,2,minecraft:chiseled_quartz_block,10,minecraft:quartz_pillar,10,minecraft:smooth_quartz,10,minecraft:quartz_block,100)
RB(1,3,2,minecraft:chiseled_quartz_block,10,minecraft:quartz_pillar,10,minecraft:smooth_quartz,10,minecraft:quartz_block,100)
RB(1,4,2,minecraft:chiseled_quartz_block,10,minecraft:quartz_pillar,10,minecraft:smooth_quartz,10,minecraft:quartz_block,100)
RB(1,5,2,minecraft:chiseled_quartz_block,10,minecraft:quartz_pillar,10,minecraft:smooth_quartz,10,minecraft:quartz_block,100)
RB(1,6,2,minecraft:chiseled_quartz_block,10,minecraft:quartz_pillar,10,minecraft:smooth_quartz,10,minecraft:quartz_block,100)
RB(1,0,3,minecraft:chiseled_quartz_block,10,minecraft:quartz_pillar,10,minecraft:smooth_quartz,10,minecraft:quartz_block,100)
RB(1,1,3,minecraft:chiseled_quartz_block,10,minecraft:quartz_pillar,10,minecraft:smooth_quartz,10,minecraft:quartz_block,100)
RB(1,2,3,minecraft:chiseled_quartz_block,10,minecraft:quartz_pillar,10,minecraft:smooth_quartz,10,minecraft:quartz_block,100)
RB(1,3,3,minecraft:chiseled_quartz_block,10,minecraft:quartz_pillar,10,minecraft:smooth_quartz,10,minecraft:quartz_block,100)
RB(1,4,3,minecraft:chiseled_quartz_block,10,minecraft:quartz_pillar,10,minecraft:smooth_quartz,10,minecraft:quartz_block,100)
RB(1,5,3,minecraft:chiseled_quartz_block,10,minecraft:quartz_pillar,10,minecraft:smooth_quartz,10,minecraft:quartz_block,100)
RB(1,6,3,minecraft:chiseled_quartz_block,10,minecraft:quartz_pillar,10,minecraft:smooth_quartz,10,minecraft:quartz_block,100)
RB(1,7,3,minecraft:chiseled_quartz_block,10,minecraft:quartz_pillar,10,minecraft:smooth_quartz,10,minecraft:quartz_block,100)
RB(1,0,4,minecraft:chiseled_quartz_block,10,minecraft:quartz_pillar,10,minecraft:smooth_quartz,10,minecraft:quartz_block,100)
RB(1,1,4,minecraft:chiseled_quartz_block,10,minecraft:quartz_pillar,10,minecraft:smooth_quartz,10,minecraft:quartz_block,100)
RB(1,2,4,minecraft:chiseled_quartz_block,10,minecraft:quartz_pillar,10,minecraft:smooth_quartz,10,minecraft:quartz_block,100)
RB(1,3,4,minecraft:chiseled_quartz_block,10,minecraft:quartz_pillar,10,minecraft:smooth_quartz,10,minecraft:quartz_block,100)
RB(1,4,4,minecraft:chiseled_quartz_block,10,minecraft:quartz_pillar,10,minecraft:smooth_quartz,10,minecraft:quartz_block,100)
RB(1,5,4,minecraft:chiseled_quartz_block,10,minecraft:quartz_pillar,10,minecraft:smooth_quartz,10,minecraft:quartz_block,100)
RB(1,6,4,minecraft:chiseled_quartz_block,10,minecraft:quartz_pillar,10,minecraft:smooth_quartz,10,minecraft:quartz_block,100)
RB(1,7,4,minecraft:chiseled_quartz_block,10,minecraft:quartz_pillar,10,minecraft:smooth_quartz,10,minecraft:quartz_block,100)
RB(1,1,5,minecraft:chiseled_quartz_block,10,minecraft:quartz_pillar,10,minecraft:smooth_quartz,10,minecraft:quartz_block,100)
RB(1,2,5,minecraft:chiseled_quartz_block,10,minecraft:quartz_pillar,10,minecraft:smooth_quartz,10,minecraft:quartz_block,100)
RB(1,3,5,minecraft:chiseled_quartz_block,10,minecraft:quartz_pillar,10,minecraft:smooth_quartz,10,minecraft:quartz_block,100)
RB(1,4,5,minecraft:chiseled_quartz_block,10,minecraft:quartz_pillar,10,minecraft:smooth_quartz,10,minecraft:quartz_block,100)
RB(1,5,5,minecraft:chiseled_quartz_block,10,minecraft:quartz_pillar,10,minecraft:smooth_quartz,10,minecraft:quartz_block,100)
RB(1,6,5,minecraft:chiseled_quartz_block,10,minecraft:quartz_pillar,10,minecraft:smooth_quartz,10,minecraft:quartz_block,100)
RB(1,7,5,minecraft:chiseled_quartz_block,10,minecraft:quartz_pillar,10,minecraft:smooth_quartz,10,minecraft:quartz_block,100)
RB(1,3,6,minecraft:chiseled_quartz_block,10,minecraft:quartz_pillar,10,minecraft:smooth_quartz,10,minecraft:quartz_block,100)
RB(1,4,6,minecraft:chiseled_quartz_block,10,minecraft:quartz_pillar,10,minecraft:smooth_quartz,10,minecraft:quartz_block,100)
RB(1,5,6,minecraft:chiseled_quartz_block,10,minecraft:quartz_pillar,10,minecraft:smooth_quartz,10,minecraft:quartz_block,100)
RB(1,6,6,minecraft:chiseled_quartz_block,10,minecraft:quartz_pillar,10,minecraft:smooth_quartz,10,minecraft:quartz_block,100)
RB(1,7,6,minecraft:chiseled_quartz_block,10,minecraft:quartz_pillar,10,minecraft:smooth_quartz,10,minecraft:quartz_block,100)
RB(1,8,6,minecraft:chiseled_quartz_block,10,minecraft:quartz_pillar,10,minecraft:smooth_quartz,10,minecraft:quartz_block,100)
RB(1,4,7,minecraft:chiseled_quartz_block,10,minecraft:quartz_pillar,10,minecraft:smooth_quartz,10,minecraft:quartz_block,100)
RB(1,5,7,minecraft:chiseled_quartz_block,10,minecraft:quartz_pillar,10,minecraft:smooth_quartz,10,minecraft:quartz_block,100)
RB(1,6,7,minecraft:chiseled_quartz_block,10,minecraft:quartz_pillar,10,minecraft:smooth_quartz,10,minecraft:quartz_block,100)
RB(1,7,7,minecraft:chiseled_quartz_block,10,minecraft:quartz_pillar,10,minecraft:smooth_quartz,10,minecraft:quartz_block,100)
RB(1,8,7,minecraft:chiseled_quartz_block,10,minecraft:quartz_pillar,10,minecraft:smooth_quartz,10,minecraft:quartz_block,100)
RB(1,5,8,minecraft:chiseled_quartz_block,10,minecraft:quartz_pillar,10,minecraft:smooth_quartz,10,minecraft:quartz_block,100)
RB(1,6,8,minecraft:chiseled_quartz_block,10,minecraft:quartz_pillar,10,minecraft:smooth_quartz,10,minecraft:quartz_block,100)
RB(1,7,8,minecraft:chiseled_quartz_block,10,minecraft:quartz_pillar,10,minecraft:smooth_quartz,10,minecraft:quartz_block,100)
RB(1,6,9,minecraft:chiseled_quartz_block,10,minecraft:quartz_pillar,10,minecraft:smooth_quartz,10,minecraft:quartz_block,100)
RB(2,0,-12,minecraft:chiseled_quartz_block,10,minecraft:quartz_pillar,10,minecraft:smooth_quartz,10,minecraft:quartz_block,100)
RB(2,0,-11,minecraft:chiseled_quartz_block,10,minecraft:quartz_pillar,10,minecraft:smooth_quartz,10,minecraft:quartz_block,100)
RB(2,0,-10,minecraft:chiseled_quartz_block,10,minecraft:quartz_pillar,10,minecraft:smooth_quartz,10,minecraft:quartz_block,100)
RB(2,0,-9,minecraft:chiseled_quartz_block,10,minecraft:quartz_pillar,10,minecraft:smooth_quartz,10,minecraft:quartz_block,100)
RB(2,1,-9,minecraft:chiseled_quartz_block,10,minecraft:quartz_pillar,10,minecraft:smooth_quartz,10,minecraft:quartz_block,100)
RB(2,0,-8,minecraft:chiseled_quartz_block,10,minecraft:quartz_pillar,10,minecraft:smooth_quartz,10,minecraft:quartz_block,100)
RB(2,1,-8,minecraft:chiseled_quartz_block,10,minecraft:quartz_pillar,10,minecraft:smooth_quartz,10,minecraft:quartz_block,100)
RB(2,0,-7,minecraft:chiseled_quartz_block,10,minecraft:quartz_pillar,10,minecraft:smooth_quartz,10,minecraft:quartz_block,100)
RB(2,1,-7,minecraft:chiseled_quartz_block,10,minecraft:quartz_pillar,10,minecraft:smooth_quartz,10,minecraft:quartz_block,100)
RB(2,2,-7,minecraft:chiseled_quartz_block,10,minecraft:quartz_pillar,10,minecraft:smooth_quartz,10,minecraft:quartz_block,100)
RB(2,0,-6,minecraft:chiseled_quartz_block,10,minecraft:quartz_pillar,10,minecraft:smooth_quartz,10,minecraft:quartz_block,100)
RB(2,1,-6,minecraft:chiseled_quartz_block,10,minecraft:quartz_pillar,10,minecraft:smooth_quartz,10,minecraft:quartz_block,100)
RB(2,2,-6,minecraft:chiseled_quartz_block,10,minecraft:quartz_pillar,10,minecraft:smooth_quartz,10,minecraft:quartz_block,100)
RB(2,0,-5,minecraft:chiseled_quartz_block,10,minecraft:quartz_pillar,10,minecraft:smooth_quartz,10,minecraft:quartz_block,100)
RB(2,1,-5,minecraft:chiseled_quartz_block,10,minecraft:quartz_pillar,10,minecraft:smooth_quartz,10,minecraft:quartz_block,100)
RB(2,2,-5,minecraft:chiseled_quartz_block,10,minecraft:quartz_pillar,10,minecraft:smooth_quartz,10,minecraft:quartz_block,100)
RB(2,3,-5,minecraft:chiseled_quartz_block,10,minecraft:quartz_pillar,10,minecraft:smooth_quartz,10,minecraft:quartz_block,100)
RB(2,0,-4,minecraft:chiseled_quartz_block,10,minecraft:quartz_pillar,10,minecraft:smooth_quartz,10,minecraft:quartz_block,100)
RB(2,1,-4,minecraft:chiseled_quartz_block,10,minecraft:quartz_pillar,10,minecraft:smooth_quartz,10,minecraft:quartz_block,100)
RB(2,2,-4,minecraft:chiseled_quartz_block,10,minecraft:quartz_pillar,10,minecraft:smooth_quartz,10,minecraft:quartz_block,100)
RB(2,3,-4,minecraft:chiseled_quartz_block,10,minecraft:quartz_pillar,10,minecraft:smooth_quartz,10,minecraft:quartz_block,100)
RB(2,0,-3,minecraft:chiseled_quartz_block,10,minecraft:quartz_pillar,10,minecraft:smooth_quartz,10,minecraft:quartz_block,100)
RB(2,1,-3,minecraft:chiseled_quartz_block,10,minecraft:quartz_pillar,10,minecraft:smooth_quartz,10,minecraft:quartz_block,100)
RB(2,2,-3,minecraft:chiseled_quartz_block,10,minecraft:quartz_pillar,10,minecraft:smooth_quartz,10,minecraft:quartz_block,100)
RB(2,3,-3,minecraft:chiseled_quartz_block,10,minecraft:quartz_pillar,10,minecraft:smooth_quartz,10,minecraft:quartz_block,100)
RB(2,4,-3,minecraft:chiseled_quartz_block,10,minecraft:quartz_pillar,10,minecraft:smooth_quartz,10,minecraft:quartz_block,100)
RB(2,0,-2,minecraft:chiseled_quartz_block,10,minecraft:quartz_pillar,10,minecraft:smooth_quartz,10,minecraft:quartz_block,100)
RB(2,1,-2,minecraft:chiseled_quartz_block,10,minecraft:quartz_pillar,10,minecraft:smooth_quartz,10,minecraft:quartz_block,100)
RB(2,2,-2,minecraft:chiseled_quartz_block,10,minecraft:quartz_pillar,10,minecraft:smooth_quartz,10,minecraft:quartz_block,100)
RB(2,3,-2,minecraft:chiseled_quartz_block,10,minecraft:quartz_pillar,10,minecraft:smooth_quartz,10,minecraft:quartz_block,100)
RB(2,4,-2,minecraft:chiseled_quartz_block,10,minecraft:quartz_pillar,10,minecraft:smooth_quartz,10,minecraft:quartz_block,100)
RB(2,0,-1,minecraft:chiseled_quartz_block,10,minecraft:quartz_pillar,10,minecraft:smooth_quartz,10,minecraft:quartz_block,100)
RB(2,1,-1,minecraft:chiseled_quartz_block,10,minecraft:quartz_pillar,10,minecraft:smooth_quartz,10,minecraft:quartz_block,100)
RB(2,2,-1,minecraft:chiseled_quartz_block,10,minecraft:quartz_pillar,10,minecraft:smooth_quartz,10,minecraft:quartz_block,100)
RB(2,3,-1,minecraft:chiseled_quartz_block,10,minecraft:quartz_pillar,10,minecraft:smooth_quartz,10,minecraft:quartz_block,100)
RB(2,4,-1,minecraft:chiseled_quartz_block,10,minecraft:quartz_pillar,10,minecraft:smooth_quartz,10,minecraft:quartz_block,100)
RB(2,5,-1,minecraft:chiseled_quartz_block,10,minecraft:quartz_pillar,10,minecraft:smooth_quartz,10,minecraft:quartz_block,100)
RB(2,0,0,minecraft:chiseled_quartz_block,10,minecraft:quartz_pillar,10,minecraft:smooth_quartz,10,minecraft:quartz_block,100)
RB(2,1,0,minecraft:chiseled_quartz_block,10,minecraft:quartz_pillar,10,minecraft:smooth_quartz,10,minecraft:quartz_block,100)
RB(2,2,0,minecraft:chiseled_quartz_block,10,minecraft:quartz_pillar,10,minecraft:smooth_quartz,10,minecraft:quartz_block,100)
RB(2,3,0,minecraft:chiseled_quartz_block,10,minecraft:quartz_pillar,10,minecraft:smooth_quartz,10,minecraft:quartz_block,100)
RB(2,4,0,minecraft:chiseled_quartz_block,10,minecraft:quartz_pillar,10,minecraft:smooth_quartz,10,minecraft:quartz_block,100)
RB(2,5,0,minecraft:chiseled_quartz_block,10,minecraft:quartz_pillar,10,minecraft:smooth_quartz,10,minecraft:quartz_block,100)
RB(2,0,1,minecraft:chiseled_quartz_block,10,minecraft:quartz_pillar,10,minecraft:smooth_quartz,10,minecraft:quartz_block,100)
RB(2,1,1,minecraft:chiseled_quartz_block,10,minecraft:quartz_pillar,10,minecraft:smooth_quartz,10,minecraft:quartz_block,100)
RB(2,2,1,minecraft:chiseled_quartz_block,10,minecraft:quartz_pillar,10,minecraft:smooth_quartz,10,minecraft:quartz_block,100)
RB(2,3,1,minecraft:chiseled_quartz_block,10,minecraft:quartz_pillar,10,minecraft:smooth_quartz,10,minecraft:quartz_block,100)
RB(2,4,1,minecraft:chiseled_quartz_block,10,minecraft:quartz_pillar,10,minecraft:smooth_quartz,10,minecraft:quartz_block,100)
RB(2,5,1,minecraft:chiseled_quartz_block,10,minecraft:quartz_pillar,10,minecraft:smooth_quartz,10,minecraft:quartz_block,100)
RB(2,6,1,minecraft:chiseled_quartz_block,10,minecraft:quartz_pillar,10,minecraft:smooth_quartz,10,minecraft:quartz_block,100)
RB(2,0,2,minecraft:chiseled_quartz_block,10,minecraft:quartz_pillar,10,minecraft:smooth_quartz,10,minecraft:quartz_block,100)
RB(2,1,2,minecraft:chiseled_quartz_block,10,minecraft:quartz_pillar,10,minecraft:smooth_quartz,10,minecraft:quartz_block,100)
RB(2,2,2,minecraft:chiseled_quartz_block,10,minecraft:quartz_pillar,10,minecraft:smooth_quartz,10,minecraft:quartz_block,100)
RB(2,3,2,minecraft:chiseled_quartz_block,10,minecraft:quartz_pillar,10,minecraft:smooth_quartz,10,minecraft:quartz_block,100)
RB(2,4,2,minecraft:chiseled_quartz_block,10,minecraft:quartz_pillar,10,minecraft:smooth_quartz,10,minecraft:quartz_block,100)
RB(2,5,2,minecraft:chiseled_quartz_block,10,minecraft:quartz_pillar,10,minecraft:smooth_quartz,10,minecraft:quartz_block,100)
RB(2,6,2,minecraft:chiseled_quartz_block,10,minecraft:quartz_pillar,10,minecraft:smooth_quartz,10,minecraft:quartz_block,100)
RB(2,0,3,minecraft:chiseled_quartz_block,10,minecraft:quartz_pillar,10,minecraft:smooth_quartz,10,minecraft:quartz_block,100)
RB(2,1,3,minecraft:chiseled_quartz_block,10,minecraft:quartz_pillar,10,minecraft:smooth_quartz,10,minecraft:quartz_block,100)
RB(2,2,3,minecraft:chiseled_quartz_block,10,minecraft:quartz_pillar,10,minecraft:smooth_quartz,10,minecraft:quartz_block,100)
RB(2,3,3,minecraft:chiseled_quartz_block,10,minecraft:quartz_pillar,10,minecraft:smooth_quartz,10,minecraft:quartz_block,100)
RB(2,4,3,minecraft:chiseled_quartz_block,10,minecraft:quartz_pillar,10,minecraft:smooth_quartz,10,minecraft:quartz_block,100)
RB(2,5,3,minecraft:chiseled_quartz_block,10,minecraft:quartz_pillar,10,minecraft:smooth_quartz,10,minecraft:quartz_block,100)
RB(2,6,3,minecraft:chiseled_quartz_block,10,minecraft:quartz_pillar,10,minecraft:smooth_quartz,10,minecraft:quartz_block,100)
RB(2,7,3,minecraft:chiseled_quartz_block,10,minecraft:quartz_pillar,10,minecraft:smooth_quartz,10,minecraft:quartz_block,100)
RB(2,0,4,minecraft:chiseled_quartz_block,10,minecraft:quartz_pillar,10,minecraft:smooth_quartz,10,minecraft:quartz_block,100)
RB(2,1,4,minecraft:chiseled_quartz_block,10,minecraft:quartz_pillar,10,minecraft:smooth_quartz,10,minecraft:quartz_block,100)
RB(2,2,4,minecraft:chiseled_quartz_block,10,minecraft:quartz_pillar,10,minecraft:smooth_quartz,10,minecraft:quartz_block,100)
RB(2,3,4,minecraft:chiseled_quartz_block,10,minecraft:quartz_pillar,10,minecraft:smooth_quartz,10,minecraft:quartz_block,100)
RB(2,4,4,minecraft:chiseled_quartz_block,10,minecraft:quartz_pillar,10,minecraft:smooth_quartz,10,minecraft:quartz_block,100)
RB(2,5,4,minecraft:chiseled_quartz_block,10,minecraft:quartz_pillar,10,minecraft:smooth_quartz,10,minecraft:quartz_block,100)
RB(2,6,4,minecraft:chiseled_quartz_block,10,minecraft:quartz_pillar,10,minecraft:smooth_quartz,10,minecraft:quartz_block,100)
RB(2,7,4,minecraft:chiseled_quartz_block,10,minecraft:quartz_pillar,10,minecraft:smooth_quartz,10,minecraft:quartz_block,100)
RB(2,2,5,minecraft:chiseled_quartz_block,10,minecraft:quartz_pillar,10,minecraft:smooth_quartz,10,minecraft:quartz_block,100)
RB(2,3,5,minecraft:chiseled_quartz_block,10,minecraft:quartz_pillar,10,minecraft:smooth_quartz,10,minecraft:quartz_block,100)
RB(2,4,5,minecraft:chiseled_quartz_block,10,minecraft:quartz_pillar,10,minecraft:smooth_quartz,10,minecraft:quartz_block,100)
RB(2,5,5,minecraft:chiseled_quartz_block,10,minecraft:quartz_pillar,10,minecraft:smooth_quartz,10,minecraft:quartz_block,100)
RB(2,6,5,minecraft:chiseled_quartz_block,10,minecraft:quartz_pillar,10,minecraft:smooth_quartz,10,minecraft:quartz_block,100)
RB(2,7,5,minecraft:chiseled_quartz_block,10,minecraft:quartz_pillar,10,minecraft:smooth_quartz,10,minecraft:quartz_block,100)
RB(2,8,5,minecraft:chiseled_quartz_block,10,minecraft:quartz_pillar,10,minecraft:smooth_quartz,10,minecraft:quartz_block,100)
RB(2,3,6,minecraft:chiseled_quartz_block,10,minecraft:quartz_pillar,10,minecraft:smooth_quartz,10,minecraft:quartz_block,100)
RB(2,4,6,minecraft:chiseled_quartz_block,10,minecraft:quartz_pillar,10,minecraft:smooth_quartz,10,minecraft:quartz_block,100)
RB(2,5,6,minecraft:chiseled_quartz_block,10,minecraft:quartz_pillar,10,minecraft:smooth_quartz,10,minecraft:quartz_block,100)
RB(2,6,6,minecraft:chiseled_quartz_block,10,minecraft:quartz_pillar,10,minecraft:smooth_quartz,10,minecraft:quartz_block,100)
RB(2,7,6,minecraft:chiseled_quartz_block,10,minecraft:quartz_pillar,10,minecraft:smooth_quartz,10,minecraft:quartz_block,100)
RB(2,8,6,minecraft:chiseled_quartz_block,10,minecraft:quartz_pillar,10,minecraft:smooth_quartz,10,minecraft:quartz_block,100)
RB(2,4,7,minecraft:chiseled_quartz_block,10,minecraft:quartz_pillar,10,minecraft:smooth_quartz,10,minecraft:quartz_block,100)
RB(2,5,7,minecraft:chiseled_quartz_block,10,minecraft:quartz_pillar,10,minecraft:smooth_quartz,10,minecraft:quartz_block,100)
RB(2,6,7,minecraft:chiseled_quartz_block,10,minecraft:quartz_pillar,10,minecraft:smooth_quartz,10,minecraft:quartz_block,100)
RB(2,7,7,minecraft:chiseled_quartz_block,10,minecraft:quartz_pillar,10,minecraft:smooth_quartz,10,minecraft:quartz_block,100)
RB(2,8,7,minecraft:chiseled_quartz_block,10,minecraft:quartz_pillar,10,minecraft:smooth_quartz,10,minecraft:quartz_block,100)
RB(2,9,7,minecraft:chiseled_quartz_block,10,minecraft:quartz_pillar,10,minecraft:smooth_quartz,10,minecraft:quartz_block,100)
RB(2,6,8,minecraft:chiseled_quartz_block,10,minecraft:quartz_pillar,10,minecraft:smooth_quartz,10,minecraft:quartz_block,100)
RB(2,7,8,minecraft:chiseled_quartz_block,10,minecraft:quartz_pillar,10,minecraft:smooth_quartz,10,minecraft:quartz_block,100)
RB(2,8,8,minecraft:chiseled_quartz_block,10,minecraft:quartz_pillar,10,minecraft:smooth_quartz,10,minecraft:quartz_block,100)
RB(2,9,8,minecraft:chiseled_quartz_block,10,minecraft:quartz_pillar,10,minecraft:smooth_quartz,10,minecraft:quartz_block,100)
RB(2,7,9,minecraft:chiseled_quartz_block,10,minecraft:quartz_pillar,10,minecraft:smooth_quartz,10,minecraft:quartz_block,100)
RB(2,8,9,minecraft:chiseled_quartz_block,10,minecraft:quartz_pillar,10,minecraft:smooth_quartz,10,minecraft:quartz_block,100)
RB(2,9,9,minecraft:chiseled_quartz_block,10,minecraft:quartz_pillar,10,minecraft:smooth_quartz,10,minecraft:quartz_block,100)
RB(2,8,10,minecraft:chiseled_quartz_block,10,minecraft:quartz_pillar,10,minecraft:smooth_quartz,10,minecraft:quartz_block,100)
RB(3,0,-12,minecraft:chiseled_quartz_block,10,minecraft:quartz_pillar,10,minecraft:smooth_quartz,10,minecraft:quartz_block,100)
RB(3,0,-11,minecraft:chiseled_quartz_block,10,minecraft:quartz_pillar,10,minecraft:smooth_quartz,10,minecraft:quartz_block,100)
RB(3,0,-10,minecraft:chiseled_quartz_block,10,minecraft:quartz_pillar,10,minecraft:smooth_quartz,10,minecraft:quartz_block,100)
RB(3,0,-9,minecraft:chiseled_quartz_block,10,minecraft:quartz_pillar,10,minecraft:smooth_quartz,10,minecraft:quartz_block,100)
RB(3,1,-9,minecraft:chiseled_quartz_block,10,minecraft:quartz_pillar,10,minecraft:smooth_quartz,10,minecraft:quartz_block,100)
RB(3,0,-8,minecraft:chiseled_quartz_block,10,minecraft:quartz_pillar,10,minecraft:smooth_quartz,10,minecraft:quartz_block,100)
RB(3,1,-8,minecraft:chiseled_quartz_block,10,minecraft:quartz_pillar,10,minecraft:smooth_quartz,10,minecraft:quartz_block,100)
RB(3,0,-7,minecraft:chiseled_quartz_block,10,minecraft:quartz_pillar,10,minecraft:smooth_quartz,10,minecraft:quartz_block,100)
RB(3,1,-7,minecraft:chiseled_quartz_block,10,minecraft:quartz_pillar,10,minecraft:smooth_quartz,10,minecraft:quartz_block,100)
RB(3,2,-7,minecraft:chiseled_quartz_block,10,minecraft:quartz_pillar,10,minecraft:smooth_quartz,10,minecraft:quartz_block,100)
RB(3,0,-6,minecraft:chiseled_quartz_block,10,minecraft:quartz_pillar,10,minecraft:smooth_quartz,10,minecraft:quartz_block,100)
RB(3,1,-6,minecraft:chiseled_quartz_block,10,minecraft:quartz_pillar,10,minecraft:smooth_quartz,10,minecraft:quartz_block,100)
RB(3,2,-6,minecraft:chiseled_quartz_block,10,minecraft:quartz_pillar,10,minecraft:smooth_quartz,10,minecraft:quartz_block,100)
RB(3,0,-5,minecraft:chiseled_quartz_block,10,minecraft:quartz_pillar,10,minecraft:smooth_quartz,10,minecraft:quartz_block,100)
RB(3,1,-5,minecraft:chiseled_quartz_block,10,minecraft:quartz_pillar,10,minecraft:smooth_quartz,10,minecraft:quartz_block,100)
RB(3,2,-5,minecraft:chiseled_quartz_block,10,minecraft:quartz_pillar,10,minecraft:smooth_quartz,10,minecraft:quartz_block,100)
RB(3,3,-5,minecraft:chiseled_quartz_block,10,minecraft:quartz_pillar,10,minecraft:smooth_quartz,10,minecraft:quartz_block,100)
RB(3,0,-4,minecraft:chiseled_quartz_block,10,minecraft:quartz_pillar,10,minecraft:smooth_quartz,10,minecraft:quartz_block,100)
RB(3,1,-4,minecraft:chiseled_quartz_block,10,minecraft:quartz_pillar,10,minecraft:smooth_quartz,10,minecraft:quartz_block,100)
RB(3,2,-4,minecraft:chiseled_quartz_block,10,minecraft:quartz_pillar,10,minecraft:smooth_quartz,10,minecraft:quartz_block,100)
RB(3,3,-4,minecraft:chiseled_quartz_block,10,minecraft:quartz_pillar,10,minecraft:smooth_quartz,10,minecraft:quartz_block,100)
RB(3,0,-3,minecraft:chiseled_quartz_block,10,minecraft:quartz_pillar,10,minecraft:smooth_quartz,10,minecraft:quartz_block,100)
RB(3,1,-3,minecraft:chiseled_quartz_block,10,minecraft:quartz_pillar,10,minecraft:smooth_quartz,10,minecraft:quartz_block,100)
RB(3,2,-3,minecraft:chiseled_quartz_block,10,minecraft:quartz_pillar,10,minecraft:smooth_quartz,10,minecraft:quartz_block,100)
RB(3,3,-3,minecraft:chiseled_quartz_block,10,minecraft:quartz_pillar,10,minecraft:smooth_quartz,10,minecraft:quartz_block,100)
RB(3,4,-3,minecraft:chiseled_quartz_block,10,minecraft:quartz_pillar,10,minecraft:smooth_quartz,10,minecraft:quartz_block,100)
RB(3,0,-2,minecraft:chiseled_quartz_block,10,minecraft:quartz_pillar,10,minecraft:smooth_quartz,10,minecraft:quartz_block,100)
RB(3,1,-2,minecraft:chiseled_quartz_block,10,minecraft:quartz_pillar,10,minecraft:smooth_quartz,10,minecraft:quartz_block,100)
RB(3,2,-2,minecraft:chiseled_quartz_block,10,minecraft:quartz_pillar,10,minecraft:smooth_quartz,10,minecraft:quartz_block,100)
RB(3,3,-2,minecraft:chiseled_quartz_block,10,minecraft:quartz_pillar,10,minecraft:smooth_quartz,10,minecraft:quartz_block,100)
RB(3,4,-2,minecraft:chiseled_quartz_block,10,minecraft:quartz_pillar,10,minecraft:smooth_quartz,10,minecraft:quartz_block,100)
RB(3,0,-1,minecraft:chiseled_quartz_block,10,minecraft:quartz_pillar,10,minecraft:smooth_quartz,10,minecraft:quartz_block,100)
RB(3,1,-1,minecraft:chiseled_quartz_block,10,minecraft:quartz_pillar,10,minecraft:smooth_quartz,10,minecraft:quartz_block,100)
RB(3,2,-1,minecraft:chiseled_quartz_block,10,minecraft:quartz_pillar,10,minecraft:smooth_quartz,10,minecraft:quartz_block,100)
RB(3,3,-1,minecraft:chiseled_quartz_block,10,minecraft:quartz_pillar,10,minecraft:smooth_quartz,10,minecraft:quartz_block,100)
RB(3,4,-1,minecraft:chiseled_quartz_block,10,minecraft:quartz_pillar,10,minecraft:smooth_quartz,10,minecraft:quartz_block,100)
RB(3,5,-1,minecraft:chiseled_quartz_block,10,minecraft:quartz_pillar,10,minecraft:smooth_quartz,10,minecraft:quartz_block,100)
RB(3,0,0,minecraft:chiseled_quartz_block,10,minecraft:quartz_pillar,10,minecraft:smooth_quartz,10,minecraft:quartz_block,100)
RB(3,1,0,minecraft:chiseled_quartz_block,10,minecraft:quartz_pillar,10,minecraft:smooth_quartz,10,minecraft:quartz_block,100)
RB(3,2,0,minecraft:chiseled_quartz_block,10,minecraft:quartz_pillar,10,minecraft:smooth_quartz,10,minecraft:quartz_block,100)
RB(3,3,0,minecraft:chiseled_quartz_block,10,minecraft:quartz_pillar,10,minecraft:smooth_quartz,10,minecraft:quartz_block,100)
RB(3,4,0,minecraft:chiseled_quartz_block,10,minecraft:quartz_pillar,10,minecraft:smooth_quartz,10,minecraft:quartz_block,100)
RB(3,5,0,minecraft:chiseled_quartz_block,10,minecraft:quartz_pillar,10,minecraft:smooth_quartz,10,minecraft:quartz_block,100)
RB(3,0,1,minecraft:chiseled_quartz_block,10,minecraft:quartz_pillar,10,minecraft:smooth_quartz,10,minecraft:quartz_block,100)
RB(3,1,1,minecraft:chiseled_quartz_block,10,minecraft:quartz_pillar,10,minecraft:smooth_quartz,10,minecraft:quartz_block,100)
RB(3,2,1,minecraft:chiseled_quartz_block,10,minecraft:quartz_pillar,10,minecraft:smooth_quartz,10,minecraft:quartz_block,100)
RB(3,3,1,minecraft:chiseled_quartz_block,10,minecraft:quartz_pillar,10,minecraft:smooth_quartz,10,minecraft:quartz_block,100)
RB(3,4,1,minecraft:chiseled_quartz_block,10,minecraft:quartz_pillar,10,minecraft:smooth_quartz,10,minecraft:quartz_block,100)
RB(3,5,1,minecraft:chiseled_quartz_block,10,minecraft:quartz_pillar,10,minecraft:smooth_quartz,10,minecraft:quartz_block,100)
RB(3,6,1,minecraft:chiseled_quartz_block,10,minecraft:quartz_pillar,10,minecraft:smooth_quartz,10,minecraft:quartz_block,100)
RB(3,0,2,minecraft:chiseled_quartz_block,10,minecraft:quartz_pillar,10,minecraft:smooth_quartz,10,minecraft:quartz_block,100)
RB(3,1,2,minecraft:chiseled_quartz_block,10,minecraft:quartz_pillar,10,minecraft:smooth_quartz,10,minecraft:quartz_block,100)
RB(3,2,2,minecraft:chiseled_quartz_block,10,minecraft:quartz_pillar,10,minecraft:smooth_quartz,10,minecraft:quartz_block,100)
RB(3,3,2,minecraft:chiseled_quartz_block,10,minecraft:quartz_pillar,10,minecraft:smooth_quartz,10,minecraft:quartz_block,100)
RB(3,4,2,minecraft:chiseled_quartz_block,10,minecraft:quartz_pillar,10,minecraft:smooth_quartz,10,minecraft:quartz_block,100)
RB(3,5,2,minecraft:chiseled_quartz_block,10,minecraft:quartz_pillar,10,minecraft:smooth_quartz,10,minecraft:quartz_block,100)
RB(3,6,2,minecraft:chiseled_quartz_block,10,minecraft:quartz_pillar,10,minecraft:smooth_quartz,10,minecraft:quartz_block,100)
RB(3,0,3,minecraft:chiseled_quartz_block,10,minecraft:quartz_pillar,10,minecraft:smooth_quartz,10,minecraft:quartz_block,100)
RB(3,1,3,minecraft:chiseled_quartz_block,10,minecraft:quartz_pillar,10,minecraft:smooth_quartz,10,minecraft:quartz_block,100)
RB(3,2,3,minecraft:chiseled_quartz_block,10,minecraft:quartz_pillar,10,minecraft:smooth_quartz,10,minecraft:quartz_block,100)
RB(3,3,3,minecraft:chiseled_quartz_block,10,minecraft:quartz_pillar,10,minecraft:smooth_quartz,10,minecraft:quartz_block,100)
RB(3,4,3,minecraft:chiseled_quartz_block,10,minecraft:quartz_pillar,10,minecraft:smooth_quartz,10,minecraft:quartz_block,100)
RB(3,5,3,minecraft:chiseled_quartz_block,10,minecraft:quartz_pillar,10,minecraft:smooth_quartz,10,minecraft:quartz_block,100)
RB(3,6,3,minecraft:chiseled_quartz_block,10,minecraft:quartz_pillar,10,minecraft:smooth_quartz,10,minecraft:quartz_block,100)
RB(3,7,3,minecraft:chiseled_quartz_block,10,minecraft:quartz_pillar,10,minecraft:smooth_quartz,10,minecraft:quartz_block,100)
RB(3,1,4,minecraft:chiseled_quartz_block,10,minecraft:quartz_pillar,10,minecraft:smooth_quartz,10,minecraft:quartz_block,100)
RB(3,2,4,minecraft:chiseled_quartz_block,10,minecraft:quartz_pillar,10,minecraft:smooth_quartz,10,minecraft:quartz_block,100)
RB(3,3,4,minecraft:chiseled_quartz_block,10,minecraft:quartz_pillar,10,minecraft:smooth_quartz,10,minecraft:quartz_block,100)
RB(3,4,4,minecraft:chiseled_quartz_block,10,minecraft:quartz_pillar,10,minecraft:smooth_quartz,10,minecraft:quartz_block,100)
RB(3,5,4,minecraft:chiseled_quartz_block,10,minecraft:quartz_pillar,10,minecraft:smooth_quartz,10,minecraft:quartz_block,100)
RB(3,6,4,minecraft:chiseled_quartz_block,10,minecraft:quartz_pillar,10,minecraft:smooth_quartz,10,minecraft:quartz_block,100)
RB(3,7,4,minecraft:chiseled_quartz_block,10,minecraft:quartz_pillar,10,minecraft:smooth_quartz,10,minecraft:quartz_block,100)
RB(3,2,5,minecraft:chiseled_quartz_block,10,minecraft:quartz_pillar,10,minecraft:smooth_quartz,10,minecraft:quartz_block,100)
RB(3,3,5,minecraft:chiseled_quartz_block,10,minecraft:quartz_pillar,10,minecraft:smooth_quartz,10,minecraft:quartz_block,100)
RB(3,4,5,minecraft:chiseled_quartz_block,10,minecraft:quartz_pillar,10,minecraft:smooth_quartz,10,minecraft:quartz_block,100)
RB(3,5,5,minecraft:chiseled_quartz_block,10,minecraft:quartz_pillar,10,minecraft:smooth_quartz,10,minecraft:quartz_block,100)
RB(3,6,5,minecraft:chiseled_quartz_block,10,minecraft:quartz_pillar,10,minecraft:smooth_quartz,10,minecraft:quartz_block,100)
RB(3,7,5,minecraft:chiseled_quartz_block,10,minecraft:quartz_pillar,10,minecraft:smooth_quartz,10,minecraft:quartz_block,100)
RB(3,8,5,minecraft:chiseled_quartz_block,10,minecraft:quartz_pillar,10,minecraft:smooth_quartz,10,minecraft:quartz_block,100)
RB(3,3,6,minecraft:chiseled_quartz_block,10,minecraft:quartz_pillar,10,minecraft:smooth_quartz,10,minecraft:quartz_block,100)
RB(3,4,6,minecraft:chiseled_quartz_block,10,minecraft:quartz_pillar,10,minecraft:smooth_quartz,10,minecraft:quartz_block,100)
RB(3,5,6,minecraft:chiseled_quartz_block,10,minecraft:quartz_pillar,10,minecraft:smooth_quartz,10,minecraft:quartz_block,100)
RB(3,6,6,minecraft:chiseled_quartz_block,10,minecraft:quartz_pillar,10,minecraft:smooth_quartz,10,minecraft:quartz_block,100)
RB(3,7,6,minecraft:chiseled_quartz_block,10,minecraft:quartz_pillar,10,minecraft:smooth_quartz,10,minecraft:quartz_block,100)
RB(3,8,6,minecraft:chiseled_quartz_block,10,minecraft:quartz_pillar,10,minecraft:smooth_quartz,10,minecraft:quartz_block,100)
RB(3,5,7,minecraft:chiseled_quartz_block,10,minecraft:quartz_pillar,10,minecraft:smooth_quartz,10,minecraft:quartz_block,100)
RB(3,6,7,minecraft:chiseled_quartz_block,10,minecraft:quartz_pillar,10,minecraft:smooth_quartz,10,minecraft:quartz_block,100)
RB(3,7,7,minecraft:chiseled_quartz_block,10,minecraft:quartz_pillar,10,minecraft:smooth_quartz,10,minecraft:quartz_block,100)
RB(3,8,7,minecraft:chiseled_quartz_block,10,minecraft:quartz_pillar,10,minecraft:smooth_quartz,10,minecraft:quartz_block,100)
RB(3,9,7,minecraft:chiseled_quartz_block,10,minecraft:quartz_pillar,10,minecraft:smooth_quartz,10,minecraft:quartz_block,100)
RB(3,6,8,minecraft:chiseled_quartz_block,10,minecraft:quartz_pillar,10,minecraft:smooth_quartz,10,minecraft:quartz_block,100)
RB(3,7,8,minecraft:chiseled_quartz_block,10,minecraft:quartz_pillar,10,minecraft:smooth_quartz,10,minecraft:quartz_block,100)
RB(3,8,8,minecraft:chiseled_quartz_block,10,minecraft:quartz_pillar,10,minecraft:smooth_quartz,10,minecraft:quartz_block,100)
RB(3,9,8,minecraft:chiseled_quartz_block,10,minecraft:quartz_pillar,10,minecraft:smooth_quartz,10,minecraft:quartz_block,100)
RB(3,7,9,minecraft:chiseled_quartz_block,10,minecraft:quartz_pillar,10,minecraft:smooth_quartz,10,minecraft:quartz_block,100)
RB(3,8,9,minecraft:chiseled_quartz_block,10,minecraft:quartz_pillar,10,minecraft:smooth_quartz,10,minecraft:quartz_block,100)
RB(3,9,9,minecraft:chiseled_quartz_block,10,minecraft:quartz_pillar,10,minecraft:smooth_quartz,10,minecraft:quartz_block,100)
RB(3,10,9,minecraft:chiseled_quartz_block,10,minecraft:quartz_pillar,10,minecraft:smooth_quartz,10,minecraft:quartz_block,100)
RB(3,8,10,minecraft:chiseled_quartz_block,10,minecraft:quartz_pillar,10,minecraft:smooth_quartz,10,minecraft:quartz_block,100)
RB(3,9,10,minecraft:chiseled_quartz_block,10,minecraft:quartz_pillar,10,minecraft:smooth_quartz,10,minecraft:quartz_block,100)
RB(3,10,10,minecraft:chiseled_quartz_block,10,minecraft:quartz_pillar,10,minecraft:smooth_quartz,10,minecraft:quartz_block,100)
RB(3,10,11,minecraft:chiseled_quartz_block,10,minecraft:quartz_pillar,10,minecraft:smooth_quartz,10,minecraft:quartz_block,100)
RB(4,0,-12,minecraft:chiseled_quartz_block,10,minecraft:quartz_pillar,10,minecraft:smooth_quartz,10,minecraft:quartz_block,100)
RB(4,0,-11,minecraft:chiseled_quartz_block,10,minecraft:quartz_pillar,10,minecraft:smooth_quartz,10,minecraft:quartz_block,100)
RB(4,0,-10,minecraft:chiseled_quartz_block,10,minecraft:quartz_pillar,10,minecraft:smooth_quartz,10,minecraft:quartz_block,100)
RB(4,0,-9,minecraft:chiseled_quartz_block,10,minecraft:quartz_pillar,10,minecraft:smooth_quartz,10,minecraft:quartz_block,100)
RB(4,1,-9,minecraft:chiseled_quartz_block,10,minecraft:quartz_pillar,10,minecraft:smooth_quartz,10,minecraft:quartz_block,100)
RB(4,0,-8,minecraft:chiseled_quartz_block,10,minecraft:quartz_pillar,10,minecraft:smooth_quartz,10,minecraft:quartz_block,100)
RB(4,1,-8,minecraft:chiseled_quartz_block,10,minecraft:quartz_pillar,10,minecraft:smooth_quartz,10,minecraft:quartz_block,100)
RB(4,0,-7,minecraft:chiseled_quartz_block,10,minecraft:quartz_pillar,10,minecraft:smooth_quartz,10,minecraft:quartz_block,100)
RB(4,1,-7,minecraft:chiseled_quartz_block,10,minecraft:quartz_pillar,10,minecraft:smooth_quartz,10,minecraft:quartz_block,100)
RB(4,2,-7,minecraft:chiseled_quartz_block,10,minecraft:quartz_pillar,10,minecraft:smooth_quartz,10,minecraft:quartz_block,100)
RB(4,0,-6,minecraft:chiseled_quartz_block,10,minecraft:quartz_pillar,10,minecraft:smooth_quartz,10,minecraft:quartz_block,100)
RB(4,1,-6,minecraft:chiseled_quartz_block,10,minecraft:quartz_pillar,10,minecraft:smooth_quartz,10,minecraft:quartz_block,100)
RB(4,2,-6,minecraft:chiseled_quartz_block,10,minecraft:quartz_pillar,10,minecraft:smooth_quartz,10,minecraft:quartz_block,100)
RB(4,0,-5,minecraft:chiseled_quartz_block,10,minecraft:quartz_pillar,10,minecraft:smooth_quartz,10,minecraft:quartz_block,100)
RB(4,1,-5,minecraft:chiseled_quartz_block,10,minecraft:quartz_pillar,10,minecraft:smooth_quartz,10,minecraft:quartz_block,100)
RB(4,2,-5,minecraft:chiseled_quartz_block,10,minecraft:quartz_pillar,10,minecraft:smooth_quartz,10,minecraft:quartz_block,100)
RB(4,3,-5,minecraft:chiseled_quartz_block,10,minecraft:quartz_pillar,10,minecraft:smooth_quartz,10,minecraft:quartz_block,100)
RB(4,0,-4,minecraft:chiseled_quartz_block,10,minecraft:quartz_pillar,10,minecraft:smooth_quartz,10,minecraft:quartz_block,100)
RB(4,1,-4,minecraft:chiseled_quartz_block,10,minecraft:quartz_pillar,10,minecraft:smooth_quartz,10,minecraft:quartz_block,100)
RB(4,2,-4,minecraft:chiseled_quartz_block,10,minecraft:quartz_pillar,10,minecraft:smooth_quartz,10,minecraft:quartz_block,100)
RB(4,3,-4,minecraft:chiseled_quartz_block,10,minecraft:quartz_pillar,10,minecraft:smooth_quartz,10,minecraft:quartz_block,100)
RB(4,0,-3,minecraft:chiseled_quartz_block,10,minecraft:quartz_pillar,10,minecraft:smooth_quartz,10,minecraft:quartz_block,100)
RB(4,1,-3,minecraft:chiseled_quartz_block,10,minecraft:quartz_pillar,10,minecraft:smooth_quartz,10,minecraft:quartz_block,100)
RB(4,2,-3,minecraft:chiseled_quartz_block,10,minecraft:quartz_pillar,10,minecraft:smooth_quartz,10,minecraft:quartz_block,100)
RB(4,3,-3,minecraft:chiseled_quartz_block,10,minecraft:quartz_pillar,10,minecraft:smooth_quartz,10,minecraft:quartz_block,100)
RB(4,4,-3,minecraft:chiseled_quartz_block,10,minecraft:quartz_pillar,10,minecraft:smooth_quartz,10,minecraft:quartz_block,100)
RB(4,0,-2,minecraft:chiseled_quartz_block,10,minecraft:quartz_pillar,10,minecraft:smooth_quartz,10,minecraft:quartz_block,100)
RB(4,1,-2,minecraft:chiseled_quartz_block,10,minecraft:quartz_pillar,10,minecraft:smooth_quartz,10,minecraft:quartz_block,100)
RB(4,2,-2,minecraft:chiseled_quartz_block,10,minecraft:quartz_pillar,10,minecraft:smooth_quartz,10,minecraft:quartz_block,100)
RB(4,3,-2,minecraft:chiseled_quartz_block,10,minecraft:quartz_pillar,10,minecraft:smooth_quartz,10,minecraft:quartz_block,100)
RB(4,4,-2,minecraft:chiseled_quartz_block,10,minecraft:quartz_pillar,10,minecraft:smooth_quartz,10,minecraft:quartz_block,100)
RB(4,0,-1,minecraft:chiseled_quartz_block,10,minecraft:quartz_pillar,10,minecraft:smooth_quartz,10,minecraft:quartz_block,100)
RB(4,1,-1,minecraft:chiseled_quartz_block,10,minecraft:quartz_pillar,10,minecraft:smooth_quartz,10,minecraft:quartz_block,100)
RB(4,2,-1,minecraft:chiseled_quartz_block,10,minecraft:quartz_pillar,10,minecraft:smooth_quartz,10,minecraft:quartz_block,100)
RB(4,3,-1,minecraft:chiseled_quartz_block,10,minecraft:quartz_pillar,10,minecraft:smooth_quartz,10,minecraft:quartz_block,100)
RB(4,4,-1,minecraft:chiseled_quartz_block,10,minecraft:quartz_pillar,10,minecraft:smooth_quartz,10,minecraft:quartz_block,100)
RB(4,5,-1,minecraft:chiseled_quartz_block,10,minecraft:quartz_pillar,10,minecraft:smooth_quartz,10,minecraft:quartz_block,100)
RB(4,0,0,minecraft:chiseled_quartz_block,10,minecraft:quartz_pillar,10,minecraft:smooth_quartz,10,minecraft:quartz_block,100)
RB(4,1,0,minecraft:chiseled_quartz_block,10,minecraft:quartz_pillar,10,minecraft:smooth_quartz,10,minecraft:quartz_block,100)
RB(4,2,0,minecraft:chiseled_quartz_block,10,minecraft:quartz_pillar,10,minecraft:smooth_quartz,10,minecraft:quartz_block,100)
RB(4,3,0,minecraft:chiseled_quartz_block,10,minecraft:quartz_pillar,10,minecraft:smooth_quartz,10,minecraft:quartz_block,100)
RB(4,4,0,minecraft:chiseled_quartz_block,10,minecraft:quartz_pillar,10,minecraft:smooth_quartz,10,minecraft:quartz_block,100)
RB(4,5,0,minecraft:chiseled_quartz_block,10,minecraft:quartz_pillar,10,minecraft:smooth_quartz,10,minecraft:quartz_block,100)
RB(4,0,1,minecraft:chiseled_quartz_block,10,minecraft:quartz_pillar,10,minecraft:smooth_quartz,10,minecraft:quartz_block,100)
RB(4,1,1,minecraft:chiseled_quartz_block,10,minecraft:quartz_pillar,10,minecraft:smooth_quartz,10,minecraft:quartz_block,100)
RB(4,2,1,minecraft:chiseled_quartz_block,10,minecraft:quartz_pillar,10,minecraft:smooth_quartz,10,minecraft:quartz_block,100)
RB(4,3,1,minecraft:chiseled_quartz_block,10,minecraft:quartz_pillar,10,minecraft:smooth_quartz,10,minecraft:quartz_block,100)
RB(4,4,1,minecraft:chiseled_quartz_block,10,minecraft:quartz_pillar,10,minecraft:smooth_quartz,10,minecraft:quartz_block,100)
RB(4,5,1,minecraft:chiseled_quartz_block,10,minecraft:quartz_pillar,10,minecraft:smooth_quartz,10,minecraft:quartz_block,100)
RB(4,6,1,minecraft:chiseled_quartz_block,10,minecraft:quartz_pillar,10,minecraft:smooth_quartz,10,minecraft:quartz_block,100)
RB(4,0,2,minecraft:chiseled_quartz_block,10,minecraft:quartz_pillar,10,minecraft:smooth_quartz,10,minecraft:quartz_block,100)
RB(4,1,2,minecraft:chiseled_quartz_block,10,minecraft:quartz_pillar,10,minecraft:smooth_quartz,10,minecraft:quartz_block,100)
RB(4,2,2,minecraft:chiseled_quartz_block,10,minecraft:quartz_pillar,10,minecraft:smooth_quartz,10,minecraft:quartz_block,100)
RB(4,3,2,minecraft:chiseled_quartz_block,10,minecraft:quartz_pillar,10,minecraft:smooth_quartz,10,minecraft:quartz_block,100)
RB(4,4,2,minecraft:chiseled_quartz_block,10,minecraft:quartz_pillar,10,minecraft:smooth_quartz,10,minecraft:quartz_block,100)
RB(4,5,2,minecraft:chiseled_quartz_block,10,minecraft:quartz_pillar,10,minecraft:smooth_quartz,10,minecraft:quartz_block,100)
RB(4,6,2,minecraft:chiseled_quartz_block,10,minecraft:quartz_pillar,10,minecraft:smooth_quartz,10,minecraft:quartz_block,100)
RB(4,0,3,minecraft:chiseled_quartz_block,10,minecraft:quartz_pillar,10,minecraft:smooth_quartz,10,minecraft:quartz_block,100)
RB(4,1,3,minecraft:chiseled_quartz_block,10,minecraft:quartz_pillar,10,minecraft:smooth_quartz,10,minecraft:quartz_block,100)
RB(4,2,3,minecraft:chiseled_quartz_block,10,minecraft:quartz_pillar,10,minecraft:smooth_quartz,10,minecraft:quartz_block,100)
RB(4,3,3,minecraft:chiseled_quartz_block,10,minecraft:quartz_pillar,10,minecraft:smooth_quartz,10,minecraft:quartz_block,100)
RB(4,4,3,minecraft:chiseled_quartz_block,10,minecraft:quartz_pillar,10,minecraft:smooth_quartz,10,minecraft:quartz_block,100)
RB(4,5,3,minecraft:chiseled_quartz_block,10,minecraft:quartz_pillar,10,minecraft:smooth_quartz,10,minecraft:quartz_block,100)
RB(4,6,3,minecraft:chiseled_quartz_block,10,minecraft:quartz_pillar,10,minecraft:smooth_quartz,10,minecraft:quartz_block,100)
RB(4,7,3,minecraft:chiseled_quartz_block,10,minecraft:quartz_pillar,10,minecraft:smooth_quartz,10,minecraft:quartz_block,100)
RB(4,1,4,minecraft:chiseled_quartz_block,10,minecraft:quartz_pillar,10,minecraft:smooth_quartz,10,minecraft:quartz_block,100)
RB(4,2,4,minecraft:chiseled_quartz_block,10,minecraft:quartz_pillar,10,minecraft:smooth_quartz,10,minecraft:quartz_block,100)
RB(4,3,4,minecraft:chiseled_quartz_block,10,minecraft:quartz_pillar,10,minecraft:smooth_quartz,10,minecraft:quartz_block,100)
RB(4,4,4,minecraft:chiseled_quartz_block,10,minecraft:quartz_pillar,10,minecraft:smooth_quartz,10,minecraft:quartz_block,100)
RB(4,5,4,minecraft:chiseled_quartz_block,10,minecraft:quartz_pillar,10,minecraft:smooth_quartz,10,minecraft:quartz_block,100)
RB(4,6,4,minecraft:chiseled_quartz_block,10,minecraft:quartz_pillar,10,minecraft:smooth_quartz,10,minecraft:quartz_block,100)
RB(4,7,4,minecraft:chiseled_quartz_block,10,minecraft:quartz_pillar,10,minecraft:smooth_quartz,10,minecraft:quartz_block,100)
RB(4,2,5,minecraft:chiseled_quartz_block,10,minecraft:quartz_pillar,10,minecraft:smooth_quartz,10,minecraft:quartz_block,100)
RB(4,3,5,minecraft:chiseled_quartz_block,10,minecraft:quartz_pillar,10,minecraft:smooth_quartz,10,minecraft:quartz_block,100)
RB(4,4,5,minecraft:chiseled_quartz_block,10,minecraft:quartz_pillar,10,minecraft:smooth_quartz,10,minecraft:quartz_block,100)
RB(4,5,5,minecraft:chiseled_quartz_block,10,minecraft:quartz_pillar,10,minecraft:smooth_quartz,10,minecraft:quartz_block,100)
RB(4,6,5,minecraft:chiseled_quartz_block,10,minecraft:quartz_pillar,10,minecraft:smooth_quartz,10,minecraft:quartz_block,100)
RB(4,7,5,minecraft:chiseled_quartz_block,10,minecraft:quartz_pillar,10,minecraft:smooth_quartz,10,minecraft:quartz_block,100)
RB(4,8,5,minecraft:chiseled_quartz_block,10,minecraft:quartz_pillar,10,minecraft:smooth_quartz,10,minecraft:quartz_block,100)
RB(4,4,6,minecraft:chiseled_quartz_block,10,minecraft:quartz_pillar,10,minecraft:smooth_quartz,10,minecraft:quartz_block,100)
RB(4,5,6,minecraft:chiseled_quartz_block,10,minecraft:quartz_pillar,10,minecraft:smooth_quartz,10,minecraft:quartz_block,100)
RB(4,6,6,minecraft:chiseled_quartz_block,10,minecraft:quartz_pillar,10,minecraft:smooth_quartz,10,minecraft:quartz_block,100)
RB(4,7,6,minecraft:chiseled_quartz_block,10,minecraft:quartz_pillar,10,minecraft:smooth_quartz,10,minecraft:quartz_block,100)
RB(4,8,6,minecraft:chiseled_quartz_block,10,minecraft:quartz_pillar,10,minecraft:smooth_quartz,10,minecraft:quartz_block,100)
RB(4,5,7,minecraft:chiseled_quartz_block,10,minecraft:quartz_pillar,10,minecraft:smooth_quartz,10,minecraft:quartz_block,100)
RB(4,6,7,minecraft:chiseled_quartz_block,10,minecraft:quartz_pillar,10,minecraft:smooth_quartz,10,minecraft:quartz_block,100)
RB(4,7,7,minecraft:chiseled_quartz_block,10,minecraft:quartz_pillar,10,minecraft:smooth_quartz,10,minecraft:quartz_block,100)
RB(4,8,7,minecraft:chiseled_quartz_block,10,minecraft:quartz_pillar,10,minecraft:smooth_quartz,10,minecraft:quartz_block,100)
RB(4,9,7,minecraft:chiseled_quartz_block,10,minecraft:quartz_pillar,10,minecraft:smooth_quartz,10,minecraft:quartz_block,100)
RB(4,6,8,minecraft:chiseled_quartz_block,10,minecraft:quartz_pillar,10,minecraft:smooth_quartz,10,minecraft:quartz_block,100)
RB(4,7,8,minecraft:chiseled_quartz_block,10,minecraft:quartz_pillar,10,minecraft:smooth_quartz,10,minecraft:quartz_block,100)
RB(4,8,8,minecraft:chiseled_quartz_block,10,minecraft:quartz_pillar,10,minecraft:smooth_quartz,10,minecraft:quartz_block,100)
RB(4,9,8,minecraft:chiseled_quartz_block,10,minecraft:quartz_pillar,10,minecraft:smooth_quartz,10,minecraft:quartz_block,100)
RB(4,7,9,minecraft:chiseled_quartz_block,10,minecraft:quartz_pillar,10,minecraft:smooth_quartz,10,minecraft:quartz_block,100)
RB(4,8,9,minecraft:chiseled_quartz_block,10,minecraft:quartz_pillar,10,minecraft:smooth_quartz,10,minecraft:quartz_block,100)
RB(4,9,9,minecraft:chiseled_quartz_block,10,minecraft:quartz_pillar,10,minecraft:smooth_quartz,10,minecraft:quartz_block,100)
RB(4,10,9,minecraft:chiseled_quartz_block,10,minecraft:quartz_pillar,10,minecraft:smooth_quartz,10,minecraft:quartz_block,100)
RB(4,9,10,minecraft:chiseled_quartz_block,10,minecraft:quartz_pillar,10,minecraft:smooth_quartz,10,minecraft:quartz_block,100)
RB(4,10,10,minecraft:chiseled_quartz_block,10,minecraft:quartz_pillar,10,minecraft:smooth_quartz,10,minecraft:quartz_block,100)
RB(4,10,11,minecraft:chiseled_quartz_block,10,minecraft:quartz_pillar,10,minecraft:smooth_quartz,10,minecraft:quartz_block,100)
RB(4,11,11,minecraft:chiseled_quartz_block,10,minecraft:quartz_pillar,10,minecraft:smooth_quartz,10,minecraft:quartz_block,100)
RB(4,11,12,minecraft:chiseled_quartz_block,10,minecraft:quartz_pillar,10,minecraft:smooth_quartz,10,minecraft:quartz_block,100)
RB(4,12,13,minecraft:chiseled_quartz_block,10,minecraft:quartz_pillar,10,minecraft:smooth_quartz,10,minecraft:quartz_block,100)
RB(5,0,-10,minecraft:chiseled_quartz_block,10,minecraft:quartz_pillar,10,minecraft:smooth_quartz,10,minecraft:quartz_block,100)
RB(5,0,-9,minecraft:chiseled_quartz_block,10,minecraft:quartz_pillar,10,minecraft:smooth_quartz,10,minecraft:quartz_block,100)
RB(5,0,-8,minecraft:chiseled_quartz_block,10,minecraft:quartz_pillar,10,minecraft:smooth_quartz,10,minecraft:quartz_block,100)
RB(5,1,-8,minecraft:chiseled_quartz_block,10,minecraft:quartz_pillar,10,minecraft:smooth_quartz,10,minecraft:quartz_block,100)
RB(5,0,-7,minecraft:chiseled_quartz_block,10,minecraft:quartz_pillar,10,minecraft:smooth_quartz,10,minecraft:quartz_block,100)
RB(5,1,-7,minecraft:chiseled_quartz_block,10,minecraft:quartz_pillar,10,minecraft:smooth_quartz,10,minecraft:quartz_block,100)
RB(5,0,-6,minecraft:chiseled_quartz_block,10,minecraft:quartz_pillar,10,minecraft:smooth_quartz,10,minecraft:quartz_block,100)
RB(5,1,-6,minecraft:chiseled_quartz_block,10,minecraft:quartz_pillar,10,minecraft:smooth_quartz,10,minecraft:quartz_block,100)
RB(5,2,-6,minecraft:chiseled_quartz_block,10,minecraft:quartz_pillar,10,minecraft:smooth_quartz,10,minecraft:quartz_block,100)
RB(5,0,-5,minecraft:chiseled_quartz_block,10,minecraft:quartz_pillar,10,minecraft:smooth_quartz,10,minecraft:quartz_block,100)
RB(5,1,-5,minecraft:chiseled_quartz_block,10,minecraft:quartz_pillar,10,minecraft:smooth_quartz,10,minecraft:quartz_block,100)
RB(5,2,-5,minecraft:chiseled_quartz_block,10,minecraft:quartz_pillar,10,minecraft:smooth_quartz,10,minecraft:quartz_block,100)
RB(5,0,-4,minecraft:chiseled_quartz_block,10,minecraft:quartz_pillar,10,minecraft:smooth_quartz,10,minecraft:quartz_block,100)
RB(5,1,-4,minecraft:chiseled_quartz_block,10,minecraft:quartz_pillar,10,minecraft:smooth_quartz,10,minecraft:quartz_block,100)
RB(5,2,-4,minecraft:chiseled_quartz_block,10,minecraft:quartz_pillar,10,minecraft:smooth_quartz,10,minecraft:quartz_block,100)
RB(5,3,-4,minecraft:chiseled_quartz_block,10,minecraft:quartz_pillar,10,minecraft:smooth_quartz,10,minecraft:quartz_block,100)
RB(5,0,-3,minecraft:chiseled_quartz_block,10,minecraft:quartz_pillar,10,minecraft:smooth_quartz,10,minecraft:quartz_block,100)
RB(5,1,-3,minecraft:chiseled_quartz_block,10,minecraft:quartz_pillar,10,minecraft:smooth_quartz,10,minecraft:quartz_block,100)
RB(5,2,-3,minecraft:chiseled_quartz_block,10,minecraft:quartz_pillar,10,minecraft:smooth_quartz,10,minecraft:quartz_block,100)
RB(5,3,-3,minecraft:chiseled_quartz_block,10,minecraft:quartz_pillar,10,minecraft:smooth_quartz,10,minecraft:quartz_block,100)
RB(5,0,-2,minecraft:chiseled_quartz_block,10,minecraft:quartz_pillar,10,minecraft:smooth_quartz,10,minecraft:quartz_block,100)
RB(5,1,-2,minecraft:chiseled_quartz_block,10,minecraft:quartz_pillar,10,minecraft:smooth_quartz,10,minecraft:quartz_block,100)
RB(5,2,-2,minecraft:chiseled_quartz_block,10,minecraft:quartz_pillar,10,minecraft:smooth_quartz,10,minecraft:quartz_block,100)
RB(5,3,-2,minecraft:chiseled_quartz_block,10,minecraft:quartz_pillar,10,minecraft:smooth_quartz,10,minecraft:quartz_block,100)
RB(5,0,-1,minecraft:chiseled_quartz_block,10,minecraft:quartz_pillar,10,minecraft:smooth_quartz,10,minecraft:quartz_block,100)
RB(5,1,-1,minecraft:chiseled_quartz_block,10,minecraft:quartz_pillar,10,minecraft:smooth_quartz,10,minecraft:quartz_block,100)
RB(5,2,-1,minecraft:chiseled_quartz_block,10,minecraft:quartz_pillar,10,minecraft:smooth_quartz,10,minecraft:quartz_block,100)
RB(5,3,-1,minecraft:chiseled_quartz_block,10,minecraft:quartz_pillar,10,minecraft:smooth_quartz,10,minecraft:quartz_block,100)
RB(5,4,-1,minecraft:chiseled_quartz_block,10,minecraft:quartz_pillar,10,minecraft:smooth_quartz,10,minecraft:quartz_block,100)
RB(5,0,0,minecraft:chiseled_quartz_block,10,minecraft:quartz_pillar,10,minecraft:smooth_quartz,10,minecraft:quartz_block,100)
RB(5,1,0,minecraft:chiseled_quartz_block,10,minecraft:quartz_pillar,10,minecraft:smooth_quartz,10,minecraft:quartz_block,100)
RB(5,2,0,minecraft:chiseled_quartz_block,10,minecraft:quartz_pillar,10,minecraft:smooth_quartz,10,minecraft:quartz_block,100)
RB(5,3,0,minecraft:chiseled_quartz_block,10,minecraft:quartz_pillar,10,minecraft:smooth_quartz,10,minecraft:quartz_block,100)
RB(5,4,0,minecraft:chiseled_quartz_block,10,minecraft:quartz_pillar,10,minecraft:smooth_quartz,10,minecraft:quartz_block,100)
RB(5,0,1,minecraft:chiseled_quartz_block,10,minecraft:quartz_pillar,10,minecraft:smooth_quartz,10,minecraft:quartz_block,100)
RB(5,1,1,minecraft:chiseled_quartz_block,10,minecraft:quartz_pillar,10,minecraft:smooth_quartz,10,minecraft:quartz_block,100)
RB(5,2,1,minecraft:chiseled_quartz_block,10,minecraft:quartz_pillar,10,minecraft:smooth_quartz,10,minecraft:quartz_block,100)
RB(5,3,1,minecraft:chiseled_quartz_block,10,minecraft:quartz_pillar,10,minecraft:smooth_quartz,10,minecraft:quartz_block,100)
RB(5,4,1,minecraft:chiseled_quartz_block,10,minecraft:quartz_pillar,10,minecraft:smooth_quartz,10,minecraft:quartz_block,100)
RB(5,5,1,minecraft:chiseled_quartz_block,10,minecraft:quartz_pillar,10,minecraft:smooth_quartz,10,minecraft:quartz_block,100)
RB(5,0,2,minecraft:chiseled_quartz_block,10,minecraft:quartz_pillar,10,minecraft:smooth_quartz,10,minecraft:quartz_block,100)
RB(5,1,2,minecraft:chiseled_quartz_block,10,minecraft:quartz_pillar,10,minecraft:smooth_quartz,10,minecraft:quartz_block,100)
RB(5,2,2,minecraft:chiseled_quartz_block,10,minecraft:quartz_pillar,10,minecraft:smooth_quartz,10,minecraft:quartz_block,100)
RB(5,3,2,minecraft:chiseled_quartz_block,10,minecraft:quartz_pillar,10,minecraft:smooth_quartz,10,minecraft:quartz_block,100)
RB(5,4,2,minecraft:chiseled_quartz_block,10,minecraft:quartz_pillar,10,minecraft:smooth_quartz,10,minecraft:quartz_block,100)
RB(5,5,2,minecraft:chiseled_quartz_block,10,minecraft:quartz_pillar,10,minecraft:smooth_quartz,10,minecraft:quartz_block,100)
RB(5,0,3,minecraft:chiseled_quartz_block,10,minecraft:quartz_pillar,10,minecraft:smooth_quartz,10,minecraft:quartz_block,100)
RB(5,1,3,minecraft:chiseled_quartz_block,10,minecraft:quartz_pillar,10,minecraft:smooth_quartz,10,minecraft:quartz_block,100)
RB(5,2,3,minecraft:chiseled_quartz_block,10,minecraft:quartz_pillar,10,minecraft:smooth_quartz,10,minecraft:quartz_block,100)
RB(5,3,3,minecraft:chiseled_quartz_block,10,minecraft:quartz_pillar,10,minecraft:smooth_quartz,10,minecraft:quartz_block,100)
RB(5,4,3,minecraft:chiseled_quartz_block,10,minecraft:quartz_pillar,10,minecraft:smooth_quartz,10,minecraft:quartz_block,100)
RB(5,5,3,minecraft:chiseled_quartz_block,10,minecraft:quartz_pillar,10,minecraft:smooth_quartz,10,minecraft:quartz_block,100)
RB(5,6,3,minecraft:chiseled_quartz_block,10,minecraft:quartz_pillar,10,minecraft:smooth_quartz,10,minecraft:quartz_block,100)
RB(5,1,4,minecraft:chiseled_quartz_block,10,minecraft:quartz_pillar,10,minecraft:smooth_quartz,10,minecraft:quartz_block,100)
RB(5,2,4,minecraft:chiseled_quartz_block,10,minecraft:quartz_pillar,10,minecraft:smooth_quartz,10,minecraft:quartz_block,100)
RB(5,3,4,minecraft:chiseled_quartz_block,10,minecraft:quartz_pillar,10,minecraft:smooth_quartz,10,minecraft:quartz_block,100)
RB(5,4,4,minecraft:chiseled_quartz_block,10,minecraft:quartz_pillar,10,minecraft:smooth_quartz,10,minecraft:quartz_block,100)
RB(5,5,4,minecraft:chiseled_quartz_block,10,minecraft:quartz_pillar,10,minecraft:smooth_quartz,10,minecraft:quartz_block,100)
RB(5,6,4,minecraft:chiseled_quartz_block,10,minecraft:quartz_pillar,10,minecraft:smooth_quartz,10,minecraft:quartz_block,100)
RB(5,3,5,minecraft:chiseled_quartz_block,10,minecraft:quartz_pillar,10,minecraft:smooth_quartz,10,minecraft:quartz_block,100)
RB(5,4,5,minecraft:chiseled_quartz_block,10,minecraft:quartz_pillar,10,minecraft:smooth_quartz,10,minecraft:quartz_block,100)
RB(5,5,5,minecraft:chiseled_quartz_block,10,minecraft:quartz_pillar,10,minecraft:smooth_quartz,10,minecraft:quartz_block,100)
RB(5,6,5,minecraft:chiseled_quartz_block,10,minecraft:quartz_pillar,10,minecraft:smooth_quartz,10,minecraft:quartz_block,100)
RB(5,7,5,minecraft:chiseled_quartz_block,10,minecraft:quartz_pillar,10,minecraft:smooth_quartz,10,minecraft:quartz_block,100)
RB(5,4,6,minecraft:chiseled_quartz_block,10,minecraft:quartz_pillar,10,minecraft:smooth_quartz,10,minecraft:quartz_block,100)
RB(5,5,6,minecraft:chiseled_quartz_block,10,minecraft:quartz_pillar,10,minecraft:smooth_quartz,10,minecraft:quartz_block,100)
RB(5,6,6,minecraft:chiseled_quartz_block,10,minecraft:quartz_pillar,10,minecraft:smooth_quartz,10,minecraft:quartz_block,100)
RB(5,7,6,minecraft:chiseled_quartz_block,10,minecraft:quartz_pillar,10,minecraft:smooth_quartz,10,minecraft:quartz_block,100)
RB(5,5,7,minecraft:chiseled_quartz_block,10,minecraft:quartz_pillar,10,minecraft:smooth_quartz,10,minecraft:quartz_block,100)
RB(5,6,7,minecraft:chiseled_quartz_block,10,minecraft:quartz_pillar,10,minecraft:smooth_quartz,10,minecraft:quartz_block,100)
RB(5,7,7,minecraft:chiseled_quartz_block,10,minecraft:quartz_pillar,10,minecraft:smooth_quartz,10,minecraft:quartz_block,100)
RB(5,8,7,minecraft:chiseled_quartz_block,10,minecraft:quartz_pillar,10,minecraft:smooth_quartz,10,minecraft:quartz_block,100)
RB(5,6,8,minecraft:chiseled_quartz_block,10,minecraft:quartz_pillar,10,minecraft:smooth_quartz,10,minecraft:quartz_block,100)
RB(5,7,8,minecraft:chiseled_quartz_block,10,minecraft:quartz_pillar,10,minecraft:smooth_quartz,10,minecraft:quartz_block,100)
RB(5,8,8,minecraft:chiseled_quartz_block,10,minecraft:quartz_pillar,10,minecraft:smooth_quartz,10,minecraft:quartz_block,100)
RB(6,0,-8,minecraft:chiseled_quartz_block,10,minecraft:quartz_pillar,10,minecraft:smooth_quartz,10,minecraft:quartz_block,100)
