Author: Frank

Description: Medium quartz spike

Version: 3

SettingsMode: WriteDisable

IsOTGPlus: false
Tree: true
Frequency: 10
Rarity: 100.0
RotateRandomly: true
SpawnHeight: randomY
SpawnHeightOffset: 0
SpawnHeightVariance: 0
MaxBranchDepth: 10
ExcludedBiomes: All

ExtrudeMode: None
ExtrudeThroughBlocks: minecraft:air

MinHeight: 50
MaxHeight: 65

SourceBlocks: AIR
MaxPercentageOutsideSourceBlock: 60
OutsideSourceBlock: placeAnyway

DoReplaceBlocks: true

RB(-13,12,-12,minecraft:chiseled_quartz_block,10,minecraft:quartz_pillar,10,minecraft:smooth_quartz_block,10,minecraft:quartz_block,100)
RB(-13,12,-11,minecraft:chiseled_quartz_block,10,minecraft:quartz_pillar,10,minecraft:smooth_quartz_block,10,minecraft:quartz_block,100)
RB(-13,12,-10,minecraft:chiseled_quartz_block,10,minecraft:quartz_pillar,10,minecraft:smooth_quartz_block,10,minecraft:quartz_block,100)
RB(-13,11,-9,minecraft:chiseled_quartz_block,10,minecraft:quartz_pillar,10,minecraft:smooth_quartz_block,10,minecraft:quartz_block,100)
RB(-12,12,-13,minecraft:chiseled_quartz_block,10,minecraft:quartz_pillar,10,minecraft:smooth_quartz_block,10,minecraft:quartz_block,100)
RB(-12,11,-12,minecraft:chiseled_quartz_block,10,minecraft:quartz_pillar,10,minecraft:smooth_quartz_block,10,minecraft:quartz_block,100)
RB(-12,12,-12,minecraft:chiseled_quartz_block,10,minecraft:quartz_pillar,10,minecraft:smooth_quartz_block,10,minecraft:quartz_block,100)
RB(-12,10,-11,minecraft:chiseled_quartz_block,10,minecraft:quartz_pillar,10,minecraft:smooth_quartz_block,10,minecraft:quartz_block,100)
RB(-12,11,-11,minecraft:chiseled_quartz_block,10,minecraft:quartz_pillar,10,minecraft:smooth_quartz_block,10,minecraft:quartz_block,100)
RB(-12,12,-11,minecraft:chiseled_quartz_block,10,minecraft:quartz_pillar,10,minecraft:smooth_quartz_block,10,minecraft:quartz_block,100)
RB(-12,10,-10,minecraft:chiseled_quartz_block,10,minecraft:quartz_pillar,10,minecraft:smooth_quartz_block,10,minecraft:quartz_block,100)
RB(-12,11,-10,minecraft:chiseled_quartz_block,10,minecraft:quartz_pillar,10,minecraft:smooth_quartz_block,10,minecraft:quartz_block,100)
RB(-12,12,-10,minecraft:chiseled_quartz_block,10,minecraft:quartz_pillar,10,minecraft:smooth_quartz_block,10,minecraft:quartz_block,100)
RB(-12,10,-9,minecraft:chiseled_quartz_block,10,minecraft:quartz_pillar,10,minecraft:smooth_quartz_block,10,minecraft:quartz_block,100)
RB(-12,11,-9,minecraft:chiseled_quartz_block,10,minecraft:quartz_pillar,10,minecraft:smooth_quartz_block,10,minecraft:quartz_block,100)
RB(-12,12,-9,minecraft:chiseled_quartz_block,10,minecraft:quartz_pillar,10,minecraft:smooth_quartz_block,10,minecraft:quartz_block,100)
RB(-12,10,-8,minecraft:chiseled_quartz_block,10,minecraft:quartz_pillar,10,minecraft:smooth_quartz_block,10,minecraft:quartz_block,100)
RB(-12,11,-8,minecraft:chiseled_quartz_block,10,minecraft:quartz_pillar,10,minecraft:smooth_quartz_block,10,minecraft:quartz_block,100)
RB(-12,9,-7,minecraft:chiseled_quartz_block,10,minecraft:quartz_pillar,10,minecraft:smooth_quartz_block,10,minecraft:quartz_block,100)
RB(-12,10,-7,minecraft:chiseled_quartz_block,10,minecraft:quartz_pillar,10,minecraft:smooth_quartz_block,10,minecraft:quartz_block,100)
RB(-12,9,-6,minecraft:chiseled_quartz_block,10,minecraft:quartz_pillar,10,minecraft:smooth_quartz_block,10,minecraft:quartz_block,100)
RB(-11,12,-13,minecraft:chiseled_quartz_block,10,minecraft:quartz_pillar,10,minecraft:smooth_quartz_block,10,minecraft:quartz_block,100)
RB(-11,11,-12,minecraft:chiseled_quartz_block,10,minecraft:quartz_pillar,10,minecraft:smooth_quartz_block,10,minecraft:quartz_block,100)
RB(-11,12,-12,minecraft:chiseled_quartz_block,10,minecraft:quartz_pillar,10,minecraft:smooth_quartz_block,10,minecraft:quartz_block,100)
RB(-11,10,-11,minecraft:chiseled_quartz_block,10,minecraft:quartz_pillar,10,minecraft:smooth_quartz_block,10,minecraft:quartz_block,100)
RB(-11,11,-11,minecraft:chiseled_quartz_block,10,minecraft:quartz_pillar,10,minecraft:smooth_quartz_block,10,minecraft:quartz_block,100)
RB(-11,12,-11,minecraft:chiseled_quartz_block,10,minecraft:quartz_pillar,10,minecraft:smooth_quartz_block,10,minecraft:quartz_block,100)
RB(-11,9,-10,minecraft:chiseled_quartz_block,10,minecraft:quartz_pillar,10,minecraft:smooth_quartz_block,10,minecraft:quartz_block,100)
RB(-11,10,-10,minecraft:chiseled_quartz_block,10,minecraft:quartz_pillar,10,minecraft:smooth_quartz_block,10,minecraft:quartz_block,100)
RB(-11,11,-10,minecraft:chiseled_quartz_block,10,minecraft:quartz_pillar,10,minecraft:smooth_quartz_block,10,minecraft:quartz_block,100)
RB(-11,12,-10,minecraft:chiseled_quartz_block,10,minecraft:quartz_pillar,10,minecraft:smooth_quartz_block,10,minecraft:quartz_block,100)
RB(-11,9,-9,minecraft:chiseled_quartz_block,10,minecraft:quartz_pillar,10,minecraft:smooth_quartz_block,10,minecraft:quartz_block,100)
RB(-11,10,-9,minecraft:chiseled_quartz_block,10,minecraft:quartz_pillar,10,minecraft:smooth_quartz_block,10,minecraft:quartz_block,100)
RB(-11,11,-9,minecraft:chiseled_quartz_block,10,minecraft:quartz_pillar,10,minecraft:smooth_quartz_block,10,minecraft:quartz_block,100)
RB(-11,8,-8,minecraft:chiseled_quartz_block,10,minecraft:quartz_pillar,10,minecraft:smooth_quartz_block,10,minecraft:quartz_block,100)
RB(-11,9,-8,minecraft:chiseled_quartz_block,10,minecraft:quartz_pillar,10,minecraft:smooth_quartz_block,10,minecraft:quartz_block,100)
RB(-11,10,-8,minecraft:chiseled_quartz_block,10,minecraft:quartz_pillar,10,minecraft:smooth_quartz_block,10,minecraft:quartz_block,100)
RB(-11,11,-8,minecraft:chiseled_quartz_block,10,minecraft:quartz_pillar,10,minecraft:smooth_quartz_block,10,minecraft:quartz_block,100)
RB(-11,8,-7,minecraft:chiseled_quartz_block,10,minecraft:quartz_pillar,10,minecraft:smooth_quartz_block,10,minecraft:quartz_block,100)
RB(-11,9,-7,minecraft:chiseled_quartz_block,10,minecraft:quartz_pillar,10,minecraft:smooth_quartz_block,10,minecraft:quartz_block,100)
RB(-11,10,-7,minecraft:chiseled_quartz_block,10,minecraft:quartz_pillar,10,minecraft:smooth_quartz_block,10,minecraft:quartz_block,100)
RB(-11,11,-7,minecraft:chiseled_quartz_block,10,minecraft:quartz_pillar,10,minecraft:smooth_quartz_block,10,minecraft:quartz_block,100)
RB(-11,8,-6,minecraft:chiseled_quartz_block,10,minecraft:quartz_pillar,10,minecraft:smooth_quartz_block,10,minecraft:quartz_block,100)
RB(-11,9,-6,minecraft:chiseled_quartz_block,10,minecraft:quartz_pillar,10,minecraft:smooth_quartz_block,10,minecraft:quartz_block,100)
RB(-11,10,-6,minecraft:chiseled_quartz_block,10,minecraft:quartz_pillar,10,minecraft:smooth_quartz_block,10,minecraft:quartz_block,100)
RB(-11,8,-5,minecraft:chiseled_quartz_block,10,minecraft:quartz_pillar,10,minecraft:smooth_quartz_block,10,minecraft:quartz_block,100)
RB(-11,9,-5,minecraft:chiseled_quartz_block,10,minecraft:quartz_pillar,10,minecraft:smooth_quartz_block,10,minecraft:quartz_block,100)
RB(-11,7,-4,minecraft:chiseled_quartz_block,10,minecraft:quartz_pillar,10,minecraft:smooth_quartz_block,10,minecraft:quartz_block,100)
RB(-11,8,-4,minecraft:chiseled_quartz_block,10,minecraft:quartz_pillar,10,minecraft:smooth_quartz_block,10,minecraft:quartz_block,100)
RB(-11,7,-3,minecraft:chiseled_quartz_block,10,minecraft:quartz_pillar,10,minecraft:smooth_quartz_block,10,minecraft:quartz_block,100)
RB(-10,11,-13,minecraft:chiseled_quartz_block,10,minecraft:quartz_pillar,10,minecraft:smooth_quartz_block,10,minecraft:quartz_block,100)
RB(-10,10,-12,minecraft:chiseled_quartz_block,10,minecraft:quartz_pillar,10,minecraft:smooth_quartz_block,10,minecraft:quartz_block,100)
RB(-10,11,-12,minecraft:chiseled_quartz_block,10,minecraft:quartz_pillar,10,minecraft:smooth_quartz_block,10,minecraft:quartz_block,100)
RB(-10,12,-12,minecraft:chiseled_quartz_block,10,minecraft:quartz_pillar,10,minecraft:smooth_quartz_block,10,minecraft:quartz_block,100)
RB(-10,9,-11,minecraft:chiseled_quartz_block,10,minecraft:quartz_pillar,10,minecraft:smooth_quartz_block,10,minecraft:quartz_block,100)
RB(-10,10,-11,minecraft:chiseled_quartz_block,10,minecraft:quartz_pillar,10,minecraft:smooth_quartz_block,10,minecraft:quartz_block,100)
RB(-10,11,-11,minecraft:chiseled_quartz_block,10,minecraft:quartz_pillar,10,minecraft:smooth_quartz_block,10,minecraft:quartz_block,100)
RB(-10,12,-11,minecraft:chiseled_quartz_block,10,minecraft:quartz_pillar,10,minecraft:smooth_quartz_block,10,minecraft:quartz_block,100)
RB(-10,8,-10,minecraft:chiseled_quartz_block,10,minecraft:quartz_pillar,10,minecraft:smooth_quartz_block,10,minecraft:quartz_block,100)
RB(-10,9,-10,minecraft:chiseled_quartz_block,10,minecraft:quartz_pillar,10,minecraft:smooth_quartz_block,10,minecraft:quartz_block,100)
RB(-10,10,-10,minecraft:chiseled_quartz_block,10,minecraft:quartz_pillar,10,minecraft:smooth_quartz_block,10,minecraft:quartz_block,100)
RB(-10,11,-10,minecraft:chiseled_quartz_block,10,minecraft:quartz_pillar,10,minecraft:smooth_quartz_block,10,minecraft:quartz_block,100)
RB(-10,12,-10,minecraft:chiseled_quartz_block,10,minecraft:quartz_pillar,10,minecraft:smooth_quartz_block,10,minecraft:quartz_block,100)
RB(-10,7,-9,minecraft:chiseled_quartz_block,10,minecraft:quartz_pillar,10,minecraft:smooth_quartz_block,10,minecraft:quartz_block,100)
RB(-10,8,-9,minecraft:chiseled_quartz_block,10,minecraft:quartz_pillar,10,minecraft:smooth_quartz_block,10,minecraft:quartz_block,100)
RB(-10,9,-9,minecraft:chiseled_quartz_block,10,minecraft:quartz_pillar,10,minecraft:smooth_quartz_block,10,minecraft:quartz_block,100)
RB(-10,10,-9,minecraft:chiseled_quartz_block,10,minecraft:quartz_pillar,10,minecraft:smooth_quartz_block,10,minecraft:quartz_block,100)
RB(-10,11,-9,minecraft:chiseled_quartz_block,10,minecraft:quartz_pillar,10,minecraft:smooth_quartz_block,10,minecraft:quartz_block,100)
RB(-10,7,-8,minecraft:chiseled_quartz_block,10,minecraft:quartz_pillar,10,minecraft:smooth_quartz_block,10,minecraft:quartz_block,100)
RB(-10,8,-8,minecraft:chiseled_quartz_block,10,minecraft:quartz_pillar,10,minecraft:smooth_quartz_block,10,minecraft:quartz_block,100)
RB(-10,9,-8,minecraft:chiseled_quartz_block,10,minecraft:quartz_pillar,10,minecraft:smooth_quartz_block,10,minecraft:quartz_block,100)
RB(-10,10,-8,minecraft:chiseled_quartz_block,10,minecraft:quartz_pillar,10,minecraft:smooth_quartz_block,10,minecraft:quartz_block,100)
RB(-10,11,-8,minecraft:chiseled_quartz_block,10,minecraft:quartz_pillar,10,minecraft:smooth_quartz_block,10,minecraft:quartz_block,100)
RB(-10,7,-7,minecraft:chiseled_quartz_block,10,minecraft:quartz_pillar,10,minecraft:smooth_quartz_block,10,minecraft:quartz_block,100)
RB(-10,8,-7,minecraft:chiseled_quartz_block,10,minecraft:quartz_pillar,10,minecraft:smooth_quartz_block,10,minecraft:quartz_block,100)
RB(-10,9,-7,minecraft:chiseled_quartz_block,10,minecraft:quartz_pillar,10,minecraft:smooth_quartz_block,10,minecraft:quartz_block,100)
RB(-10,10,-7,minecraft:chiseled_quartz_block,10,minecraft:quartz_pillar,10,minecraft:smooth_quartz_block,10,minecraft:quartz_block,100)
RB(-10,6,-6,minecraft:chiseled_quartz_block,10,minecraft:quartz_pillar,10,minecraft:smooth_quartz_block,10,minecraft:quartz_block,100)
RB(-10,7,-6,minecraft:chiseled_quartz_block,10,minecraft:quartz_pillar,10,minecraft:smooth_quartz_block,10,minecraft:quartz_block,100)
RB(-10,8,-6,minecraft:chiseled_quartz_block,10,minecraft:quartz_pillar,10,minecraft:smooth_quartz_block,10,minecraft:quartz_block,100)
RB(-10,9,-6,minecraft:chiseled_quartz_block,10,minecraft:quartz_pillar,10,minecraft:smooth_quartz_block,10,minecraft:quartz_block,100)
RB(-10,10,-6,minecraft:chiseled_quartz_block,10,minecraft:quartz_pillar,10,minecraft:smooth_quartz_block,10,minecraft:quartz_block,100)
RB(-10,6,-5,minecraft:chiseled_quartz_block,10,minecraft:quartz_pillar,10,minecraft:smooth_quartz_block,10,minecraft:quartz_block,100)
RB(-10,7,-5,minecraft:chiseled_quartz_block,10,minecraft:quartz_pillar,10,minecraft:smooth_quartz_block,10,minecraft:quartz_block,100)
RB(-10,8,-5,minecraft:chiseled_quartz_block,10,minecraft:quartz_pillar,10,minecraft:smooth_quartz_block,10,minecraft:quartz_block,100)
RB(-10,9,-5,minecraft:chiseled_quartz_block,10,minecraft:quartz_pillar,10,minecraft:smooth_quartz_block,10,minecraft:quartz_block,100)
RB(-10,10,-5,minecraft:chiseled_quartz_block,10,minecraft:quartz_pillar,10,minecraft:smooth_quartz_block,10,minecraft:quartz_block,100)
RB(-10,6,-4,minecraft:chiseled_quartz_block,10,minecraft:quartz_pillar,10,minecraft:smooth_quartz_block,10,minecraft:quartz_block,100)
RB(-10,7,-4,minecraft:chiseled_quartz_block,10,minecraft:quartz_pillar,10,minecraft:smooth_quartz_block,10,minecraft:quartz_block,100)
RB(-10,8,-4,minecraft:chiseled_quartz_block,10,minecraft:quartz_pillar,10,minecraft:smooth_quartz_block,10,minecraft:quartz_block,100)
RB(-10,9,-4,minecraft:chiseled_quartz_block,10,minecraft:quartz_pillar,10,minecraft:smooth_quartz_block,10,minecraft:quartz_block,100)
RB(-10,6,-3,minecraft:chiseled_quartz_block,10,minecraft:quartz_pillar,10,minecraft:smooth_quartz_block,10,minecraft:quartz_block,100)
RB(-10,7,-3,minecraft:chiseled_quartz_block,10,minecraft:quartz_pillar,10,minecraft:smooth_quartz_block,10,minecraft:quartz_block,100)
RB(-10,8,-3,minecraft:chiseled_quartz_block,10,minecraft:quartz_pillar,10,minecraft:smooth_quartz_block,10,minecraft:quartz_block,100)
RB(-10,9,-3,minecraft:chiseled_quartz_block,10,minecraft:quartz_pillar,10,minecraft:smooth_quartz_block,10,minecraft:quartz_block,100)
RB(-10,5,-2,minecraft:chiseled_quartz_block,10,minecraft:quartz_pillar,10,minecraft:smooth_quartz_block,10,minecraft:quartz_block,100)
RB(-10,6,-2,minecraft:chiseled_quartz_block,10,minecraft:quartz_pillar,10,minecraft:smooth_quartz_block,10,minecraft:quartz_block,100)
RB(-10,7,-2,minecraft:chiseled_quartz_block,10,minecraft:quartz_pillar,10,minecraft:smooth_quartz_block,10,minecraft:quartz_block,100)
RB(-10,5,-1,minecraft:chiseled_quartz_block,10,minecraft:quartz_pillar,10,minecraft:smooth_quartz_block,10,minecraft:quartz_block,100)
RB(-10,6,-1,minecraft:chiseled_quartz_block,10,minecraft:quartz_pillar,10,minecraft:smooth_quartz_block,10,minecraft:quartz_block,100)
RB(-10,5,0,minecraft:chiseled_quartz_block,10,minecraft:quartz_pillar,10,minecraft:smooth_quartz_block,10,minecraft:quartz_block,100)
RB(-9,10,-12,minecraft:chiseled_quartz_block,10,minecraft:quartz_pillar,10,minecraft:smooth_quartz_block,10,minecraft:quartz_block,100)
RB(-9,11,-12,minecraft:chiseled_quartz_block,10,minecraft:quartz_pillar,10,minecraft:smooth_quartz_block,10,minecraft:quartz_block,100)
RB(-9,9,-11,minecraft:chiseled_quartz_block,10,minecraft:quartz_pillar,10,minecraft:smooth_quartz_block,10,minecraft:quartz_block,100)
RB(-9,10,-11,minecraft:chiseled_quartz_block,10,minecraft:quartz_pillar,10,minecraft:smooth_quartz_block,10,minecraft:quartz_block,100)
RB(-9,11,-11,minecraft:chiseled_quartz_block,10,minecraft:quartz_pillar,10,minecraft:smooth_quartz_block,10,minecraft:quartz_block,100)
RB(-9,8,-10,minecraft:chiseled_quartz_block,10,minecraft:quartz_pillar,10,minecraft:smooth_quartz_block,10,minecraft:quartz_block,100)
RB(-9,9,-10,minecraft:chiseled_quartz_block,10,minecraft:quartz_pillar,10,minecraft:smooth_quartz_block,10,minecraft:quartz_block,100)
RB(-9,10,-10,minecraft:chiseled_quartz_block,10,minecraft:quartz_pillar,10,minecraft:smooth_quartz_block,10,minecraft:quartz_block,100)
RB(-9,11,-10,minecraft:chiseled_quartz_block,10,minecraft:quartz_pillar,10,minecraft:smooth_quartz_block,10,minecraft:quartz_block,100)
RB(-9,7,-9,minecraft:chiseled_quartz_block,10,minecraft:quartz_pillar,10,minecraft:smooth_quartz_block,10,minecraft:quartz_block,100)
RB(-9,8,-9,minecraft:chiseled_quartz_block,10,minecraft:quartz_pillar,10,minecraft:smooth_quartz_block,10,minecraft:quartz_block,100)
RB(-9,9,-9,minecraft:chiseled_quartz_block,10,minecraft:quartz_pillar,10,minecraft:smooth_quartz_block,10,minecraft:quartz_block,100)
RB(-9,10,-9,minecraft:chiseled_quartz_block,10,minecraft:quartz_pillar,10,minecraft:smooth_quartz_block,10,minecraft:quartz_block,100)
RB(-9,11,-9,minecraft:chiseled_quartz_block,10,minecraft:quartz_pillar,10,minecraft:smooth_quartz_block,10,minecraft:quartz_block,100)
RB(-9,6,-8,minecraft:chiseled_quartz_block,10,minecraft:quartz_pillar,10,minecraft:smooth_quartz_block,10,minecraft:quartz_block,100)
RB(-9,7,-8,minecraft:chiseled_quartz_block,10,minecraft:quartz_pillar,10,minecraft:smooth_quartz_block,10,minecraft:quartz_block,100)
RB(-9,8,-8,minecraft:chiseled_quartz_block,10,minecraft:quartz_pillar,10,minecraft:smooth_quartz_block,10,minecraft:quartz_block,100)
RB(-9,9,-8,minecraft:chiseled_quartz_block,10,minecraft:quartz_pillar,10,minecraft:smooth_quartz_block,10,minecraft:quartz_block,100)
RB(-9,10,-8,minecraft:chiseled_quartz_block,10,minecraft:quartz_pillar,10,minecraft:smooth_quartz_block,10,minecraft:quartz_block,100)
RB(-9,11,-8,minecraft:chiseled_quartz_block,10,minecraft:quartz_pillar,10,minecraft:smooth_quartz_block,10,minecraft:quartz_block,100)
RB(-9,5,-7,minecraft:chiseled_quartz_block,10,minecraft:quartz_pillar,10,minecraft:smooth_quartz_block,10,minecraft:quartz_block,100)
RB(-9,6,-7,minecraft:chiseled_quartz_block,10,minecraft:quartz_pillar,10,minecraft:smooth_quartz_block,10,minecraft:quartz_block,100)
RB(-9,7,-7,minecraft:chiseled_quartz_block,10,minecraft:quartz_pillar,10,minecraft:smooth_quartz_block,10,minecraft:quartz_block,100)
RB(-9,8,-7,minecraft:chiseled_quartz_block,10,minecraft:quartz_pillar,10,minecraft:smooth_quartz_block,10,minecraft:quartz_block,100)
RB(-9,9,-7,minecraft:chiseled_quartz_block,10,minecraft:quartz_pillar,10,minecraft:smooth_quartz_block,10,minecraft:quartz_block,100)
RB(-9,10,-7,minecraft:chiseled_quartz_block,10,minecraft:quartz_pillar,10,minecraft:smooth_quartz_block,10,minecraft:quartz_block,100)
RB(-9,5,-6,minecraft:chiseled_quartz_block,10,minecraft:quartz_pillar,10,minecraft:smooth_quartz_block,10,minecraft:quartz_block,100)
RB(-9,6,-6,minecraft:chiseled_quartz_block,10,minecraft:quartz_pillar,10,minecraft:smooth_quartz_block,10,minecraft:quartz_block,100)
RB(-9,7,-6,minecraft:chiseled_quartz_block,10,minecraft:quartz_pillar,10,minecraft:smooth_quartz_block,10,minecraft:quartz_block,100)
RB(-9,8,-6,minecraft:chiseled_quartz_block,10,minecraft:quartz_pillar,10,minecraft:smooth_quartz_block,10,minecraft:quartz_block,100)
RB(-9,9,-6,minecraft:chiseled_quartz_block,10,minecraft:quartz_pillar,10,minecraft:smooth_quartz_block,10,minecraft:quartz_block,100)
RB(-9,10,-6,minecraft:chiseled_quartz_block,10,minecraft:quartz_pillar,10,minecraft:smooth_quartz_block,10,minecraft:quartz_block,100)
RB(-9,5,-5,minecraft:chiseled_quartz_block,10,minecraft:quartz_pillar,10,minecraft:smooth_quartz_block,10,minecraft:quartz_block,100)
RB(-9,6,-5,minecraft:chiseled_quartz_block,10,minecraft:quartz_pillar,10,minecraft:smooth_quartz_block,10,minecraft:quartz_block,100)
RB(-9,7,-5,minecraft:chiseled_quartz_block,10,minecraft:quartz_pillar,10,minecraft:smooth_quartz_block,10,minecraft:quartz_block,100)
RB(-9,8,-5,minecraft:chiseled_quartz_block,10,minecraft:quartz_pillar,10,minecraft:smooth_quartz_block,10,minecraft:quartz_block,100)
RB(-9,9,-5,minecraft:chiseled_quartz_block,10,minecraft:quartz_pillar,10,minecraft:smooth_quartz_block,10,minecraft:quartz_block,100)
RB(-9,5,-4,minecraft:chiseled_quartz_block,10,minecraft:quartz_pillar,10,minecraft:smooth_quartz_block,10,minecraft:quartz_block,100)
RB(-9,6,-4,minecraft:chiseled_quartz_block,10,minecraft:quartz_pillar,10,minecraft:smooth_quartz_block,10,minecraft:quartz_block,100)
RB(-9,7,-4,minecraft:chiseled_quartz_block,10,minecraft:quartz_pillar,10,minecraft:smooth_quartz_block,10,minecraft:quartz_block,100)
RB(-9,8,-4,minecraft:chiseled_quartz_block,10,minecraft:quartz_pillar,10,minecraft:smooth_quartz_block,10,minecraft:quartz_block,100)
RB(-9,9,-4,minecraft:chiseled_quartz_block,10,minecraft:quartz_pillar,10,minecraft:smooth_quartz_block,10,minecraft:quartz_block,100)
RB(-9,4,-3,minecraft:chiseled_quartz_block,10,minecraft:quartz_pillar,10,minecraft:smooth_quartz_block,10,minecraft:quartz_block,100)
RB(-9,5,-3,minecraft:chiseled_quartz_block,10,minecraft:quartz_pillar,10,minecraft:smooth_quartz_block,10,minecraft:quartz_block,100)
RB(-9,6,-3,minecraft:chiseled_quartz_block,10,minecraft:quartz_pillar,10,minecraft:smooth_quartz_block,10,minecraft:quartz_block,100)
RB(-9,7,-3,minecraft:chiseled_quartz_block,10,minecraft:quartz_pillar,10,minecraft:smooth_quartz_block,10,minecraft:quartz_block,100)
RB(-9,8,-3,minecraft:chiseled_quartz_block,10,minecraft:quartz_pillar,10,minecraft:smooth_quartz_block,10,minecraft:quartz_block,100)
RB(-9,9,-3,minecraft:chiseled_quartz_block,10,minecraft:quartz_pillar,10,minecraft:smooth_quartz_block,10,minecraft:quartz_block,100)
RB(-9,4,-2,minecraft:chiseled_quartz_block,10,minecraft:quartz_pillar,10,minecraft:smooth_quartz_block,10,minecraft:quartz_block,100)
RB(-9,5,-2,minecraft:chiseled_quartz_block,10,minecraft:quartz_pillar,10,minecraft:smooth_quartz_block,10,minecraft:quartz_block,100)
RB(-9,6,-2,minecraft:chiseled_quartz_block,10,minecraft:quartz_pillar,10,minecraft:smooth_quartz_block,10,minecraft:quartz_block,100)
RB(-9,7,-2,minecraft:chiseled_quartz_block,10,minecraft:quartz_pillar,10,minecraft:smooth_quartz_block,10,minecraft:quartz_block,100)
RB(-9,8,-2,minecraft:chiseled_quartz_block,10,minecraft:quartz_pillar,10,minecraft:smooth_quartz_block,10,minecraft:quartz_block,100)
RB(-9,4,-1,minecraft:chiseled_quartz_block,10,minecraft:quartz_pillar,10,minecraft:smooth_quartz_block,10,minecraft:quartz_block,100)
RB(-9,5,-1,minecraft:chiseled_quartz_block,10,minecraft:quartz_pillar,10,minecraft:smooth_quartz_block,10,minecraft:quartz_block,100)
RB(-9,6,-1,minecraft:chiseled_quartz_block,10,minecraft:quartz_pillar,10,minecraft:smooth_quartz_block,10,minecraft:quartz_block,100)
RB(-9,7,-1,minecraft:chiseled_quartz_block,10,minecraft:quartz_pillar,10,minecraft:smooth_quartz_block,10,minecraft:quartz_block,100)
RB(-9,8,-1,minecraft:chiseled_quartz_block,10,minecraft:quartz_pillar,10,minecraft:smooth_quartz_block,10,minecraft:quartz_block,100)
RB(-9,4,0,minecraft:chiseled_quartz_block,10,minecraft:quartz_pillar,10,minecraft:smooth_quartz_block,10,minecraft:quartz_block,100)
RB(-9,5,0,minecraft:chiseled_quartz_block,10,minecraft:quartz_pillar,10,minecraft:smooth_quartz_block,10,minecraft:quartz_block,100)
RB(-9,6,0,minecraft:chiseled_quartz_block,10,minecraft:quartz_pillar,10,minecraft:smooth_quartz_block,10,minecraft:quartz_block,100)
RB(-9,7,0,minecraft:chiseled_quartz_block,10,minecraft:quartz_pillar,10,minecraft:smooth_quartz_block,10,minecraft:quartz_block,100)
RB(-9,3,1,minecraft:chiseled_quartz_block,10,minecraft:quartz_pillar,10,minecraft:smooth_quartz_block,10,minecraft:quartz_block,100)
RB(-9,4,1,minecraft:chiseled_quartz_block,10,minecraft:quartz_pillar,10,minecraft:smooth_quartz_block,10,minecraft:quartz_block,100)
RB(-9,5,1,minecraft:chiseled_quartz_block,10,minecraft:quartz_pillar,10,minecraft:smooth_quartz_block,10,minecraft:quartz_block,100)
RB(-9,3,2,minecraft:chiseled_quartz_block,10,minecraft:quartz_pillar,10,minecraft:smooth_quartz_block,10,minecraft:quartz_block,100)
RB(-9,4,2,minecraft:chiseled_quartz_block,10,minecraft:quartz_pillar,10,minecraft:smooth_quartz_block,10,minecraft:quartz_block,100)
RB(-9,3,3,minecraft:chiseled_quartz_block,10,minecraft:quartz_pillar,10,minecraft:smooth_quartz_block,10,minecraft:quartz_block,100)
RB(-8,9,-12,minecraft:chiseled_quartz_block,10,minecraft:quartz_pillar,10,minecraft:smooth_quartz_block,10,minecraft:quartz_block,100)
RB(-8,10,-12,minecraft:chiseled_quartz_block,10,minecraft:quartz_pillar,10,minecraft:smooth_quartz_block,10,minecraft:quartz_block,100)
RB(-8,8,-11,minecraft:chiseled_quartz_block,10,minecraft:quartz_pillar,10,minecraft:smooth_quartz_block,10,minecraft:quartz_block,100)
RB(-8,9,-11,minecraft:chiseled_quartz_block,10,minecraft:quartz_pillar,10,minecraft:smooth_quartz_block,10,minecraft:quartz_block,100)
RB(-8,10,-11,minecraft:chiseled_quartz_block,10,minecraft:quartz_pillar,10,minecraft:smooth_quartz_block,10,minecraft:quartz_block,100)
RB(-8,11,-11,minecraft:chiseled_quartz_block,10,minecraft:quartz_pillar,10,minecraft:smooth_quartz_block,10,minecraft:quartz_block,100)
RB(-8,7,-10,minecraft:chiseled_quartz_block,10,minecraft:quartz_pillar,10,minecraft:smooth_quartz_block,10,minecraft:quartz_block,100)
RB(-8,8,-10,minecraft:chiseled_quartz_block,10,minecraft:quartz_pillar,10,minecraft:smooth_quartz_block,10,minecraft:quartz_block,100)
RB(-8,9,-10,minecraft:chiseled_quartz_block,10,minecraft:quartz_pillar,10,minecraft:smooth_quartz_block,10,minecraft:quartz_block,100)
RB(-8,10,-10,minecraft:chiseled_quartz_block,10,minecraft:quartz_pillar,10,minecraft:smooth_quartz_block,10,minecraft:quartz_block,100)
RB(-8,11,-10,minecraft:chiseled_quartz_block,10,minecraft:quartz_pillar,10,minecraft:smooth_quartz_block,10,minecraft:quartz_block,100)
RB(-8,6,-9,minecraft:chiseled_quartz_block,10,minecraft:quartz_pillar,10,minecraft:smooth_quartz_block,10,minecraft:quartz_block,100)
RB(-8,7,-9,minecraft:chiseled_quartz_block,10,minecraft:quartz_pillar,10,minecraft:smooth_quartz_block,10,minecraft:quartz_block,100)
RB(-8,8,-9,minecraft:chiseled_quartz_block,10,minecraft:quartz_pillar,10,minecraft:smooth_quartz_block,10,minecraft:quartz_block,100)
RB(-8,9,-9,minecraft:chiseled_quartz_block,10,minecraft:quartz_pillar,10,minecraft:smooth_quartz_block,10,minecraft:quartz_block,100)
RB(-8,10,-9,minecraft:chiseled_quartz_block,10,minecraft:quartz_pillar,10,minecraft:smooth_quartz_block,10,minecraft:quartz_block,100)
RB(-8,11,-9,minecraft:chiseled_quartz_block,10,minecraft:quartz_pillar,10,minecraft:smooth_quartz_block,10,minecraft:quartz_block,100)
RB(-8,5,-8,minecraft:chiseled_quartz_block,10,minecraft:quartz_pillar,10,minecraft:smooth_quartz_block,10,minecraft:quartz_block,100)
RB(-8,6,-8,minecraft:chiseled_quartz_block,10,minecraft:quartz_pillar,10,minecraft:smooth_quartz_block,10,minecraft:quartz_block,100)
RB(-8,7,-8,minecraft:chiseled_quartz_block,10,minecraft:quartz_pillar,10,minecraft:smooth_quartz_block,10,minecraft:quartz_block,100)
RB(-8,8,-8,minecraft:chiseled_quartz_block,10,minecraft:quartz_pillar,10,minecraft:smooth_quartz_block,10,minecraft:quartz_block,100)
RB(-8,9,-8,minecraft:chiseled_quartz_block,10,minecraft:quartz_pillar,10,minecraft:smooth_quartz_block,10,minecraft:quartz_block,100)
RB(-8,10,-8,minecraft:chiseled_quartz_block,10,minecraft:quartz_pillar,10,minecraft:smooth_quartz_block,10,minecraft:quartz_block,100)
RB(-8,11,-8,minecraft:chiseled_quartz_block,10,minecraft:quartz_pillar,10,minecraft:smooth_quartz_block,10,minecraft:quartz_block,100)
RB(-8,4,-7,minecraft:chiseled_quartz_block,10,minecraft:quartz_pillar,10,minecraft:smooth_quartz_block,10,minecraft:quartz_block,100)
RB(-8,5,-7,minecraft:chiseled_quartz_block,10,minecraft:quartz_pillar,10,minecraft:smooth_quartz_block,10,minecraft:quartz_block,100)
RB(-8,6,-7,minecraft:chiseled_quartz_block,10,minecraft:quartz_pillar,10,minecraft:smooth_quartz_block,10,minecraft:quartz_block,100)
RB(-8,7,-7,minecraft:chiseled_quartz_block,10,minecraft:quartz_pillar,10,minecraft:smooth_quartz_block,10,minecraft:quartz_block,100)
RB(-8,8,-7,minecraft:chiseled_quartz_block,10,minecraft:quartz_pillar,10,minecraft:smooth_quartz_block,10,minecraft:quartz_block,100)
RB(-8,9,-7,minecraft:chiseled_quartz_block,10,minecraft:quartz_pillar,10,minecraft:smooth_quartz_block,10,minecraft:quartz_block,100)
RB(-8,10,-7,minecraft:chiseled_quartz_block,10,minecraft:quartz_pillar,10,minecraft:smooth_quartz_block,10,minecraft:quartz_block,100)
RB(-8,4,-6,minecraft:chiseled_quartz_block,10,minecraft:quartz_pillar,10,minecraft:smooth_quartz_block,10,minecraft:quartz_block,100)
RB(-8,5,-6,minecraft:chiseled_quartz_block,10,minecraft:quartz_pillar,10,minecraft:smooth_quartz_block,10,minecraft:quartz_block,100)
RB(-8,6,-6,minecraft:chiseled_quartz_block,10,minecraft:quartz_pillar,10,minecraft:smooth_quartz_block,10,minecraft:quartz_block,100)
RB(-8,7,-6,minecraft:chiseled_quartz_block,10,minecraft:quartz_pillar,10,minecraft:smooth_quartz_block,10,minecraft:quartz_block,100)
RB(-8,8,-6,minecraft:chiseled_quartz_block,10,minecraft:quartz_pillar,10,minecraft:smooth_quartz_block,10,minecraft:quartz_block,100)
RB(-8,9,-6,minecraft:chiseled_quartz_block,10,minecraft:quartz_pillar,10,minecraft:smooth_quartz_block,10,minecraft:quartz_block,100)
RB(-8,10,-6,minecraft:chiseled_quartz_block,10,minecraft:quartz_pillar,10,minecraft:smooth_quartz_block,10,minecraft:quartz_block,100)
RB(-8,3,-5,minecraft:chiseled_quartz_block,10,minecraft:quartz_pillar,10,minecraft:smooth_quartz_block,10,minecraft:quartz_block,100)
RB(-8,4,-5,minecraft:chiseled_quartz_block,10,minecraft:quartz_pillar,10,minecraft:smooth_quartz_block,10,minecraft:quartz_block,100)
RB(-8,5,-5,minecraft:chiseled_quartz_block,10,minecraft:quartz_pillar,10,minecraft:smooth_quartz_block,10,minecraft:quartz_block,100)
RB(-8,6,-5,minecraft:chiseled_quartz_block,10,minecraft:quartz_pillar,10,minecraft:smooth_quartz_block,10,minecraft:quartz_block,100)
RB(-8,7,-5,minecraft:chiseled_quartz_block,10,minecraft:quartz_pillar,10,minecraft:smooth_quartz_block,10,minecraft:quartz_block,100)
RB(-8,8,-5,minecraft:chiseled_quartz_block,10,minecraft:quartz_pillar,10,minecraft:smooth_quartz_block,10,minecraft:quartz_block,100)
RB(-8,9,-5,minecraft:chiseled_quartz_block,10,minecraft:quartz_pillar,10,minecraft:smooth_quartz_block,10,minecraft:quartz_block,100)
RB(-8,3,-4,minecraft:chiseled_quartz_block,10,minecraft:quartz_pillar,10,minecraft:smooth_quartz_block,10,minecraft:quartz_block,100)
RB(-8,4,-4,minecraft:chiseled_quartz_block,10,minecraft:quartz_pillar,10,minecraft:smooth_quartz_block,10,minecraft:quartz_block,100)
RB(-8,5,-4,minecraft:chiseled_quartz_block,10,minecraft:quartz_pillar,10,minecraft:smooth_quartz_block,10,minecraft:quartz_block,100)
RB(-8,6,-4,minecraft:chiseled_quartz_block,10,minecraft:quartz_pillar,10,minecraft:smooth_quartz_block,10,minecraft:quartz_block,100)
RB(-8,7,-4,minecraft:chiseled_quartz_block,10,minecraft:quartz_pillar,10,minecraft:smooth_quartz_block,10,minecraft:quartz_block,100)
RB(-8,8,-4,minecraft:chiseled_quartz_block,10,minecraft:quartz_pillar,10,minecraft:smooth_quartz_block,10,minecraft:quartz_block,100)
RB(-8,9,-4,minecraft:chiseled_quartz_block,10,minecraft:quartz_pillar,10,minecraft:smooth_quartz_block,10,minecraft:quartz_block,100)
RB(-8,3,-3,minecraft:chiseled_quartz_block,10,minecraft:quartz_pillar,10,minecraft:smooth_quartz_block,10,minecraft:quartz_block,100)
RB(-8,4,-3,minecraft:chiseled_quartz_block,10,minecraft:quartz_pillar,10,minecraft:smooth_quartz_block,10,minecraft:quartz_block,100)
RB(-8,5,-3,minecraft:chiseled_quartz_block,10,minecraft:quartz_pillar,10,minecraft:smooth_quartz_block,10,minecraft:quartz_block,100)
RB(-8,6,-3,minecraft:chiseled_quartz_block,10,minecraft:quartz_pillar,10,minecraft:smooth_quartz_block,10,minecraft:quartz_block,100)
RB(-8,7,-3,minecraft:chiseled_quartz_block,10,minecraft:quartz_pillar,10,minecraft:smooth_quartz_block,10,minecraft:quartz_block,100)
RB(-8,8,-3,minecraft:chiseled_quartz_block,10,minecraft:quartz_pillar,10,minecraft:smooth_quartz_block,10,minecraft:quartz_block,100)
RB(-8,3,-2,minecraft:chiseled_quartz_block,10,minecraft:quartz_pillar,10,minecraft:smooth_quartz_block,10,minecraft:quartz_block,100)
RB(-8,4,-2,minecraft:chiseled_quartz_block,10,minecraft:quartz_pillar,10,minecraft:smooth_quartz_block,10,minecraft:quartz_block,100)
RB(-8,5,-2,minecraft:chiseled_quartz_block,10,minecraft:quartz_pillar,10,minecraft:smooth_quartz_block,10,minecraft:quartz_block,100)
RB(-8,6,-2,minecraft:chiseled_quartz_block,10,minecraft:quartz_pillar,10,minecraft:smooth_quartz_block,10,minecraft:quartz_block,100)
RB(-8,7,-2,minecraft:chiseled_quartz_block,10,minecraft:quartz_pillar,10,minecraft:smooth_quartz_block,10,minecraft:quartz_block,100)
RB(-8,8,-2,minecraft:chiseled_quartz_block,10,minecraft:quartz_pillar,10,minecraft:smooth_quartz_block,10,minecraft:quartz_block,100)
RB(-8,2,-1,minecraft:chiseled_quartz_block,10,minecraft:quartz_pillar,10,minecraft:smooth_quartz_block,10,minecraft:quartz_block,100)
RB(-8,3,-1,minecraft:chiseled_quartz_block,10,minecraft:quartz_pillar,10,minecraft:smooth_quartz_block,10,minecraft:quartz_block,100)
RB(-8,4,-1,minecraft:chiseled_quartz_block,10,minecraft:quartz_pillar,10,minecraft:smooth_quartz_block,10,minecraft:quartz_block,100)
RB(-8,5,-1,minecraft:chiseled_quartz_block,10,minecraft:quartz_pillar,10,minecraft:smooth_quartz_block,10,minecraft:quartz_block,100)
RB(-8,6,-1,minecraft:chiseled_quartz_block,10,minecraft:quartz_pillar,10,minecraft:smooth_quartz_block,10,minecraft:quartz_block,100)
RB(-8,7,-1,minecraft:chiseled_quartz_block,10,minecraft:quartz_pillar,10,minecraft:smooth_quartz_block,10,minecraft:quartz_block,100)
RB(-8,8,-1,minecraft:chiseled_quartz_block,10,minecraft:quartz_pillar,10,minecraft:smooth_quartz_block,10,minecraft:quartz_block,100)
RB(-8,2,0,minecraft:chiseled_quartz_block,10,minecraft:quartz_pillar,10,minecraft:smooth_quartz_block,10,minecraft:quartz_block,100)
RB(-8,3,0,minecraft:chiseled_quartz_block,10,minecraft:quartz_pillar,10,minecraft:smooth_quartz_block,10,minecraft:quartz_block,100)
RB(-8,4,0,minecraft:chiseled_quartz_block,10,minecraft:quartz_pillar,10,minecraft:smooth_quartz_block,10,minecraft:quartz_block,100)
RB(-8,5,0,minecraft:chiseled_quartz_block,10,minecraft:quartz_pillar,10,minecraft:smooth_quartz_block,10,minecraft:quartz_block,100)
RB(-8,6,0,minecraft:chiseled_quartz_block,10,minecraft:quartz_pillar,10,minecraft:smooth_quartz_block,10,minecraft:quartz_block,100)
RB(-8,7,0,minecraft:chiseled_quartz_block,10,minecraft:quartz_pillar,10,minecraft:smooth_quartz_block,10,minecraft:quartz_block,100)
RB(-8,2,1,minecraft:chiseled_quartz_block,10,minecraft:quartz_pillar,10,minecraft:smooth_quartz_block,10,minecraft:quartz_block,100)
RB(-8,3,1,minecraft:chiseled_quartz_block,10,minecraft:quartz_pillar,10,minecraft:smooth_quartz_block,10,minecraft:quartz_block,100)
RB(-8,4,1,minecraft:chiseled_quartz_block,10,minecraft:quartz_pillar,10,minecraft:smooth_quartz_block,10,minecraft:quartz_block,100)
RB(-8,5,1,minecraft:chiseled_quartz_block,10,minecraft:quartz_pillar,10,minecraft:smooth_quartz_block,10,minecraft:quartz_block,100)
RB(-8,6,1,minecraft:chiseled_quartz_block,10,minecraft:quartz_pillar,10,minecraft:smooth_quartz_block,10,minecraft:quartz_block,100)
RB(-8,7,1,minecraft:chiseled_quartz_block,10,minecraft:quartz_pillar,10,minecraft:smooth_quartz_block,10,minecraft:quartz_block,100)
RB(-8,2,2,minecraft:chiseled_quartz_block,10,minecraft:quartz_pillar,10,minecraft:smooth_quartz_block,10,minecraft:quartz_block,100)
RB(-8,3,2,minecraft:chiseled_quartz_block,10,minecraft:quartz_pillar,10,minecraft:smooth_quartz_block,10,minecraft:quartz_block,100)
RB(-8,4,2,minecraft:chiseled_quartz_block,10,minecraft:quartz_pillar,10,minecraft:smooth_quartz_block,10,minecraft:quartz_block,100)
RB(-8,5,2,minecraft:chiseled_quartz_block,10,minecraft:quartz_pillar,10,minecraft:smooth_quartz_block,10,minecraft:quartz_block,100)
RB(-8,6,2,minecraft:chiseled_quartz_block,10,minecraft:quartz_pillar,10,minecraft:smooth_quartz_block,10,minecraft:quartz_block,100)
RB(-8,1,3,minecraft:chiseled_quartz_block,10,minecraft:quartz_pillar,10,minecraft:smooth_quartz_block,10,minecraft:quartz_block,100)
RB(-8,2,3,minecraft:chiseled_quartz_block,10,minecraft:quartz_pillar,10,minecraft:smooth_quartz_block,10,minecraft:quartz_block,100)
RB(-8,3,3,minecraft:chiseled_quartz_block,10,minecraft:quartz_pillar,10,minecraft:smooth_quartz_block,10,minecraft:quartz_block,100)
RB(-8,4,3,minecraft:chiseled_quartz_block,10,minecraft:quartz_pillar,10,minecraft:smooth_quartz_block,10,minecraft:quartz_block,100)
RB(-8,5,3,minecraft:chiseled_quartz_block,10,minecraft:quartz_pillar,10,minecraft:smooth_quartz_block,10,minecraft:quartz_block,100)
RB(-8,1,4,minecraft:chiseled_quartz_block,10,minecraft:quartz_pillar,10,minecraft:smooth_quartz_block,10,minecraft:quartz_block,100)
RB(-8,2,4,minecraft:chiseled_quartz_block,10,minecraft:quartz_pillar,10,minecraft:smooth_quartz_block,10,minecraft:quartz_block,100)
RB(-8,3,4,minecraft:chiseled_quartz_block,10,minecraft:quartz_pillar,10,minecraft:smooth_quartz_block,10,minecraft:quartz_block,100)
RB(-8,1,5,minecraft:chiseled_quartz_block,10,minecraft:quartz_pillar,10,minecraft:smooth_quartz_block,10,minecraft:quartz_block,100)
RB(-8,2,5,minecraft:chiseled_quartz_block,10,minecraft:quartz_pillar,10,minecraft:smooth_quartz_block,10,minecraft:quartz_block,100)
RB(-8,1,6,minecraft:chiseled_quartz_block,10,minecraft:quartz_pillar,10,minecraft:smooth_quartz_block,10,minecraft:quartz_block,100)
RB(-8,0,7,minecraft:chiseled_quartz_block,10,minecraft:quartz_pillar,10,minecraft:smooth_quartz_block,10,minecraft:quartz_block,100)
RB(-7,9,-12,minecraft:chiseled_quartz_block,10,minecraft:quartz_pillar,10,minecraft:smooth_quartz_block,10,minecraft:quartz_block,100)
RB(-7,8,-11,minecraft:chiseled_quartz_block,10,minecraft:quartz_pillar,10,minecraft:smooth_quartz_block,10,minecraft:quartz_block,100)
RB(-7,9,-11,minecraft:chiseled_quartz_block,10,minecraft:quartz_pillar,10,minecraft:smooth_quartz_block,10,minecraft:quartz_block,100)
RB(-7,10,-11,minecraft:chiseled_quartz_block,10,minecraft:quartz_pillar,10,minecraft:smooth_quartz_block,10,minecraft:quartz_block,100)
RB(-7,7,-10,minecraft:chiseled_quartz_block,10,minecraft:quartz_pillar,10,minecraft:smooth_quartz_block,10,minecraft:quartz_block,100)
RB(-7,8,-10,minecraft:chiseled_quartz_block,10,minecraft:quartz_pillar,10,minecraft:smooth_quartz_block,10,minecraft:quartz_block,100)
RB(-7,9,-10,minecraft:chiseled_quartz_block,10,minecraft:quartz_pillar,10,minecraft:smooth_quartz_block,10,minecraft:quartz_block,100)
RB(-7,10,-10,minecraft:chiseled_quartz_block,10,minecraft:quartz_pillar,10,minecraft:smooth_quartz_block,10,minecraft:quartz_block,100)
RB(-7,6,-9,minecraft:chiseled_quartz_block,10,minecraft:quartz_pillar,10,minecraft:smooth_quartz_block,10,minecraft:quartz_block,100)
RB(-7,7,-9,minecraft:chiseled_quartz_block,10,minecraft:quartz_pillar,10,minecraft:smooth_quartz_block,10,minecraft:quartz_block,100)
RB(-7,8,-9,minecraft:chiseled_quartz_block,10,minecraft:quartz_pillar,10,minecraft:smooth_quartz_block,10,minecraft:quartz_block,100)
RB(-7,9,-9,minecraft:chiseled_quartz_block,10,minecraft:quartz_pillar,10,minecraft:smooth_quartz_block,10,minecraft:quartz_block,100)
RB(-7,10,-9,minecraft:chiseled_quartz_block,10,minecraft:quartz_pillar,10,minecraft:smooth_quartz_block,10,minecraft:quartz_block,100)
RB(-7,5,-8,minecraft:chiseled_quartz_block,10,minecraft:quartz_pillar,10,minecraft:smooth_quartz_block,10,minecraft:quartz_block,100)
RB(-7,6,-8,minecraft:chiseled_quartz_block,10,minecraft:quartz_pillar,10,minecraft:smooth_quartz_block,10,minecraft:quartz_block,100)
RB(-7,7,-8,minecraft:chiseled_quartz_block,10,minecraft:quartz_pillar,10,minecraft:smooth_quartz_block,10,minecraft:quartz_block,100)
RB(-7,8,-8,minecraft:chiseled_quartz_block,10,minecraft:quartz_pillar,10,minecraft:smooth_quartz_block,10,minecraft:quartz_block,100)
RB(-7,9,-8,minecraft:chiseled_quartz_block,10,minecraft:quartz_pillar,10,minecraft:smooth_quartz_block,10,minecraft:quartz_block,100)
RB(-7,10,-8,minecraft:chiseled_quartz_block,10,minecraft:quartz_pillar,10,minecraft:smooth_quartz_block,10,minecraft:quartz_block,100)
RB(-7,4,-7,minecraft:chiseled_quartz_block,10,minecraft:quartz_pillar,10,minecraft:smooth_quartz_block,10,minecraft:quartz_block,100)
RB(-7,5,-7,minecraft:chiseled_quartz_block,10,minecraft:quartz_pillar,10,minecraft:smooth_quartz_block,10,minecraft:quartz_block,100)
RB(-7,6,-7,minecraft:chiseled_quartz_block,10,minecraft:quartz_pillar,10,minecraft:smooth_quartz_block,10,minecraft:quartz_block,100)
RB(-7,7,-7,minecraft:chiseled_quartz_block,10,minecraft:quartz_pillar,10,minecraft:smooth_quartz_block,10,minecraft:quartz_block,100)
RB(-7,8,-7,minecraft:chiseled_quartz_block,10,minecraft:quartz_pillar,10,minecraft:smooth_quartz_block,10,minecraft:quartz_block,100)
RB(-7,9,-7,minecraft:chiseled_quartz_block,10,minecraft:quartz_pillar,10,minecraft:smooth_quartz_block,10,minecraft:quartz_block,100)
RB(-7,10,-7,minecraft:chiseled_quartz_block,10,minecraft:quartz_pillar,10,minecraft:smooth_quartz_block,10,minecraft:quartz_block,100)
RB(-7,3,-6,minecraft:chiseled_quartz_block,10,minecraft:quartz_pillar,10,minecraft:smooth_quartz_block,10,minecraft:quartz_block,100)
RB(-7,4,-6,minecraft:chiseled_quartz_block,10,minecraft:quartz_pillar,10,minecraft:smooth_quartz_block,10,minecraft:quartz_block,100)
RB(-7,5,-6,minecraft:chiseled_quartz_block,10,minecraft:quartz_pillar,10,minecraft:smooth_quartz_block,10,minecraft:quartz_block,100)
RB(-7,6,-6,minecraft:chiseled_quartz_block,10,minecraft:quartz_pillar,10,minecraft:smooth_quartz_block,10,minecraft:quartz_block,100)
RB(-7,7,-6,minecraft:chiseled_quartz_block,10,minecraft:quartz_pillar,10,minecraft:smooth_quartz_block,10,minecraft:quartz_block,100)
RB(-7,8,-6,minecraft:chiseled_quartz_block,10,minecraft:quartz_pillar,10,minecraft:smooth_quartz_block,10,minecraft:quartz_block,100)
RB(-7,9,-6,minecraft:chiseled_quartz_block,10,minecraft:quartz_pillar,10,minecraft:smooth_quartz_block,10,minecraft:quartz_block,100)
RB(-7,10,-6,minecraft:chiseled_quartz_block,10,minecraft:quartz_pillar,10,minecraft:smooth_quartz_block,10,minecraft:quartz_block,100)
RB(-7,2,-5,minecraft:chiseled_quartz_block,10,minecraft:quartz_pillar,10,minecraft:smooth_quartz_block,10,minecraft:quartz_block,100)
RB(-7,3,-5,minecraft:chiseled_quartz_block,10,minecraft:quartz_pillar,10,minecraft:smooth_quartz_block,10,minecraft:quartz_block,100)
RB(-7,4,-5,minecraft:chiseled_quartz_block,10,minecraft:quartz_pillar,10,minecraft:smooth_quartz_block,10,minecraft:quartz_block,100)
RB(-7,5,-5,minecraft:chiseled_quartz_block,10,minecraft:quartz_pillar,10,minecraft:smooth_quartz_block,10,minecraft:quartz_block,100)
RB(-7,6,-5,minecraft:chiseled_quartz_block,10,minecraft:quartz_pillar,10,minecraft:smooth_quartz_block,10,minecraft:quartz_block,100)
RB(-7,7,-5,minecraft:chiseled_quartz_block,10,minecraft:quartz_pillar,10,minecraft:smooth_quartz_block,10,minecraft:quartz_block,100)
RB(-7,8,-5,minecraft:chiseled_quartz_block,10,minecraft:quartz_pillar,10,minecraft:smooth_quartz_block,10,minecraft:quartz_block,100)
RB(-7,9,-5,minecraft:chiseled_quartz_block,10,minecraft:quartz_pillar,10,minecraft:smooth_quartz_block,10,minecraft:quartz_block,100)
RB(-7,2,-4,minecraft:chiseled_quartz_block,10,minecraft:quartz_pillar,10,minecraft:smooth_quartz_block,10,minecraft:quartz_block,100)
RB(-7,3,-4,minecraft:chiseled_quartz_block,10,minecraft:quartz_pillar,10,minecraft:smooth_quartz_block,10,minecraft:quartz_block,100)
RB(-7,4,-4,minecraft:chiseled_quartz_block,10,minecraft:quartz_pillar,10,minecraft:smooth_quartz_block,10,minecraft:quartz_block,100)
RB(-7,5,-4,minecraft:chiseled_quartz_block,10,minecraft:quartz_pillar,10,minecraft:smooth_quartz_block,10,minecraft:quartz_block,100)
RB(-7,6,-4,minecraft:chiseled_quartz_block,10,minecraft:quartz_pillar,10,minecraft:smooth_quartz_block,10,minecraft:quartz_block,100)
RB(-7,7,-4,minecraft:chiseled_quartz_block,10,minecraft:quartz_pillar,10,minecraft:smooth_quartz_block,10,minecraft:quartz_block,100)
RB(-7,8,-4,minecraft:chiseled_quartz_block,10,minecraft:quartz_pillar,10,minecraft:smooth_quartz_block,10,minecraft:quartz_block,100)
RB(-7,9,-4,minecraft:chiseled_quartz_block,10,minecraft:quartz_pillar,10,minecraft:smooth_quartz_block,10,minecraft:quartz_block,100)
RB(-7,2,-3,minecraft:chiseled_quartz_block,10,minecraft:quartz_pillar,10,minecraft:smooth_quartz_block,10,minecraft:quartz_block,100)
RB(-7,3,-3,minecraft:chiseled_quartz_block,10,minecraft:quartz_pillar,10,minecraft:smooth_quartz_block,10,minecraft:quartz_block,100)
RB(-7,4,-3,minecraft:chiseled_quartz_block,10,minecraft:quartz_pillar,10,minecraft:smooth_quartz_block,10,minecraft:quartz_block,100)
RB(-7,5,-3,minecraft:chiseled_quartz_block,10,minecraft:quartz_pillar,10,minecraft:smooth_quartz_block,10,minecraft:quartz_block,100)
RB(-7,6,-3,minecraft:chiseled_quartz_block,10,minecraft:quartz_pillar,10,minecraft:smooth_quartz_block,10,minecraft:quartz_block,100)
RB(-7,7,-3,minecraft:chiseled_quartz_block,10,minecraft:quartz_pillar,10,minecraft:smooth_quartz_block,10,minecraft:quartz_block,100)
RB(-7,8,-3,minecraft:chiseled_quartz_block,10,minecraft:quartz_pillar,10,minecraft:smooth_quartz_block,10,minecraft:quartz_block,100)
RB(-7,1,-2,minecraft:chiseled_quartz_block,10,minecraft:quartz_pillar,10,minecraft:smooth_quartz_block,10,minecraft:quartz_block,100)
RB(-7,2,-2,minecraft:chiseled_quartz_block,10,minecraft:quartz_pillar,10,minecraft:smooth_quartz_block,10,minecraft:quartz_block,100)
RB(-7,3,-2,minecraft:chiseled_quartz_block,10,minecraft:quartz_pillar,10,minecraft:smooth_quartz_block,10,minecraft:quartz_block,100)
RB(-7,4,-2,minecraft:chiseled_quartz_block,10,minecraft:quartz_pillar,10,minecraft:smooth_quartz_block,10,minecraft:quartz_block,100)
RB(-7,5,-2,minecraft:chiseled_quartz_block,10,minecraft:quartz_pillar,10,minecraft:smooth_quartz_block,10,minecraft:quartz_block,100)
RB(-7,6,-2,minecraft:chiseled_quartz_block,10,minecraft:quartz_pillar,10,minecraft:smooth_quartz_block,10,minecraft:quartz_block,100)
RB(-7,7,-2,minecraft:chiseled_quartz_block,10,minecraft:quartz_pillar,10,minecraft:smooth_quartz_block,10,minecraft:quartz_block,100)
RB(-7,8,-2,minecraft:chiseled_quartz_block,10,minecraft:quartz_pillar,10,minecraft:smooth_quartz_block,10,minecraft:quartz_block,100)
RB(-7,1,-1,minecraft:chiseled_quartz_block,10,minecraft:quartz_pillar,10,minecraft:smooth_quartz_block,10,minecraft:quartz_block,100)
RB(-7,2,-1,minecraft:chiseled_quartz_block,10,minecraft:quartz_pillar,10,minecraft:smooth_quartz_block,10,minecraft:quartz_block,100)
RB(-7,3,-1,minecraft:chiseled_quartz_block,10,minecraft:quartz_pillar,10,minecraft:smooth_quartz_block,10,minecraft:quartz_block,100)
RB(-7,4,-1,minecraft:chiseled_quartz_block,10,minecraft:quartz_pillar,10,minecraft:smooth_quartz_block,10,minecraft:quartz_block,100)
RB(-7,5,-1,minecraft:chiseled_quartz_block,10,minecraft:quartz_pillar,10,minecraft:smooth_quartz_block,10,minecraft:quartz_block,100)
RB(-7,6,-1,minecraft:chiseled_quartz_block,10,minecraft:quartz_pillar,10,minecraft:smooth_quartz_block,10,minecraft:quartz_block,100)
RB(-7,7,-1,minecraft:chiseled_quartz_block,10,minecraft:quartz_pillar,10,minecraft:smooth_quartz_block,10,minecraft:quartz_block,100)
RB(-7,1,0,minecraft:chiseled_quartz_block,10,minecraft:quartz_pillar,10,minecraft:smooth_quartz_block,10,minecraft:quartz_block,100)
RB(-7,2,0,minecraft:chiseled_quartz_block,10,minecraft:quartz_pillar,10,minecraft:smooth_quartz_block,10,minecraft:quartz_block,100)
RB(-7,3,0,minecraft:chiseled_quartz_block,10,minecraft:quartz_pillar,10,minecraft:smooth_quartz_block,10,minecraft:quartz_block,100)
RB(-7,4,0,minecraft:chiseled_quartz_block,10,minecraft:quartz_pillar,10,minecraft:smooth_quartz_block,10,minecraft:quartz_block,100)
RB(-7,5,0,minecraft:chiseled_quartz_block,10,minecraft:quartz_pillar,10,minecraft:smooth_quartz_block,10,minecraft:quartz_block,100)
RB(-7,6,0,minecraft:chiseled_quartz_block,10,minecraft:quartz_pillar,10,minecraft:smooth_quartz_block,10,minecraft:quartz_block,100)
RB(-7,7,0,minecraft:chiseled_quartz_block,10,minecraft:quartz_pillar,10,minecraft:smooth_quartz_block,10,minecraft:quartz_block,100)
RB(-7,1,1,minecraft:chiseled_quartz_block,10,minecraft:quartz_pillar,10,minecraft:smooth_quartz_block,10,minecraft:quartz_block,100)
RB(-7,2,1,minecraft:chiseled_quartz_block,10,minecraft:quartz_pillar,10,minecraft:smooth_quartz_block,10,minecraft:quartz_block,100)
RB(-7,3,1,minecraft:chiseled_quartz_block,10,minecraft:quartz_pillar,10,minecraft:smooth_quartz_block,10,minecraft:quartz_block,100)
RB(-7,4,1,minecraft:chiseled_quartz_block,10,minecraft:quartz_pillar,10,minecraft:smooth_quartz_block,10,minecraft:quartz_block,100)
RB(-7,5,1,minecraft:chiseled_quartz_block,10,minecraft:quartz_pillar,10,minecraft:smooth_quartz_block,10,minecraft:quartz_block,100)
RB(-7,6,1,minecraft:chiseled_quartz_block,10,minecraft:quartz_pillar,10,minecraft:smooth_quartz_block,10,minecraft:quartz_block,100)
RB(-7,7,1,minecraft:chiseled_quartz_block,10,minecraft:quartz_pillar,10,minecraft:smooth_quartz_block,10,minecraft:quartz_block,100)
RB(-7,0,2,minecraft:chiseled_quartz_block,10,minecraft:quartz_pillar,10,minecraft:smooth_quartz_block,10,minecraft:quartz_block,100)
RB(-7,1,2,minecraft:chiseled_quartz_block,10,minecraft:quartz_pillar,10,minecraft:smooth_quartz_block,10,minecraft:quartz_block,100)
RB(-7,2,2,minecraft:chiseled_quartz_block,10,minecraft:quartz_pillar,10,minecraft:smooth_quartz_block,10,minecraft:quartz_block,100)
RB(-7,3,2,minecraft:chiseled_quartz_block,10,minecraft:quartz_pillar,10,minecraft:smooth_quartz_block,10,minecraft:quartz_block,100)
RB(-7,4,2,minecraft:chiseled_quartz_block,10,minecraft:quartz_pillar,10,minecraft:smooth_quartz_block,10,minecraft:quartz_block,100)
RB(-7,5,2,minecraft:chiseled_quartz_block,10,minecraft:quartz_pillar,10,minecraft:smooth_quartz_block,10,minecraft:quartz_block,100)
RB(-7,6,2,minecraft:chiseled_quartz_block,10,minecraft:quartz_pillar,10,minecraft:smooth_quartz_block,10,minecraft:quartz_block,100)
RB(-7,0,3,minecraft:chiseled_quartz_block,10,minecraft:quartz_pillar,10,minecraft:smooth_quartz_block,10,minecraft:quartz_block,100)
RB(-7,1,3,minecraft:chiseled_quartz_block,10,minecraft:quartz_pillar,10,minecraft:smooth_quartz_block,10,minecraft:quartz_block,100)
RB(-7,2,3,minecraft:chiseled_quartz_block,10,minecraft:quartz_pillar,10,minecraft:smooth_quartz_block,10,minecraft:quartz_block,100)
RB(-7,3,3,minecraft:chiseled_quartz_block,10,minecraft:quartz_pillar,10,minecraft:smooth_quartz_block,10,minecraft:quartz_block,100)
RB(-7,4,3,minecraft:chiseled_quartz_block,10,minecraft:quartz_pillar,10,minecraft:smooth_quartz_block,10,minecraft:quartz_block,100)
RB(-7,5,3,minecraft:chiseled_quartz_block,10,minecraft:quartz_pillar,10,minecraft:smooth_quartz_block,10,minecraft:quartz_block,100)
RB(-7,6,3,minecraft:chiseled_quartz_block,10,minecraft:quartz_pillar,10,minecraft:smooth_quartz_block,10,minecraft:quartz_block,100)
RB(-7,0,4,minecraft:chiseled_quartz_block,10,minecraft:quartz_pillar,10,minecraft:smooth_quartz_block,10,minecraft:quartz_block,100)
RB(-7,1,4,minecraft:chiseled_quartz_block,10,minecraft:quartz_pillar,10,minecraft:smooth_quartz_block,10,minecraft:quartz_block,100)
RB(-7,2,4,minecraft:chiseled_quartz_block,10,minecraft:quartz_pillar,10,minecraft:smooth_quartz_block,10,minecraft:quartz_block,100)
RB(-7,3,4,minecraft:chiseled_quartz_block,10,minecraft:quartz_pillar,10,minecraft:smooth_quartz_block,10,minecraft:quartz_block,100)
RB(-7,4,4,minecraft:chiseled_quartz_block,10,minecraft:quartz_pillar,10,minecraft:smooth_quartz_block,10,minecraft:quartz_block,100)
RB(-7,5,4,minecraft:chiseled_quartz_block,10,minecraft:quartz_pillar,10,minecraft:smooth_quartz_block,10,minecraft:quartz_block,100)
RB(-7,0,5,minecraft:chiseled_quartz_block,10,minecraft:quartz_pillar,10,minecraft:smooth_quartz_block,10,minecraft:quartz_block,100)
RB(-7,1,5,minecraft:chiseled_quartz_block,10,minecraft:quartz_pillar,10,minecraft:smooth_quartz_block,10,minecraft:quartz_block,100)
RB(-7,2,5,minecraft:chiseled_quartz_block,10,minecraft:quartz_pillar,10,minecraft:smooth_quartz_block,10,minecraft:quartz_block,100)
RB(-7,3,5,minecraft:chiseled_quartz_block,10,minecraft:quartz_pillar,10,minecraft:smooth_quartz_block,10,minecraft:quartz_block,100)
RB(-7,4,5,minecraft:chiseled_quartz_block,10,minecraft:quartz_pillar,10,minecraft:smooth_quartz_block,10,minecraft:quartz_block,100)
RB(-7,0,6,minecraft:chiseled_quartz_block,10,minecraft:quartz_pillar,10,minecraft:smooth_quartz_block,10,minecraft:quartz_block,100)
RB(-7,1,6,minecraft:chiseled_quartz_block,10,minecraft:quartz_pillar,10,minecraft:smooth_quartz_block,10,minecraft:quartz_block,100)
RB(-7,2,6,minecraft:chiseled_quartz_block,10,minecraft:quartz_pillar,10,minecraft:smooth_quartz_block,10,minecraft:quartz_block,100)
RB(-7,3,6,minecraft:chiseled_quartz_block,10,minecraft:quartz_pillar,10,minecraft:smooth_quartz_block,10,minecraft:quartz_block,100)
RB(-7,0,7,minecraft:chiseled_quartz_block,10,minecraft:quartz_pillar,10,minecraft:smooth_quartz_block,10,minecraft:quartz_block,100)
RB(-7,1,7,minecraft:chiseled_quartz_block,10,minecraft:quartz_pillar,10,minecraft:smooth_quartz_block,10,minecraft:quartz_block,100)
RB(-7,0,8,minecraft:chiseled_quartz_block,10,minecraft:quartz_pillar,10,minecraft:smooth_quartz_block,10,minecraft:quartz_block,100)
RB(-6,8,-12,minecraft:chiseled_quartz_block,10,minecraft:quartz_pillar,10,minecraft:smooth_quartz_block,10,minecraft:quartz_block,100)
RB(-6,7,-11,minecraft:chiseled_quartz_block,10,minecraft:quartz_pillar,10,minecraft:smooth_quartz_block,10,minecraft:quartz_block,100)
RB(-6,8,-11,minecraft:chiseled_quartz_block,10,minecraft:quartz_pillar,10,minecraft:smooth_quartz_block,10,minecraft:quartz_block,100)
RB(-6,9,-11,minecraft:chiseled_quartz_block,10,minecraft:quartz_pillar,10,minecraft:smooth_quartz_block,10,minecraft:quartz_block,100)
RB(-6,6,-10,minecraft:chiseled_quartz_block,10,minecraft:quartz_pillar,10,minecraft:smooth_quartz_block,10,minecraft:quartz_block,100)
RB(-6,7,-10,minecraft:chiseled_quartz_block,10,minecraft:quartz_pillar,10,minecraft:smooth_quartz_block,10,minecraft:quartz_block,100)
RB(-6,8,-10,minecraft:chiseled_quartz_block,10,minecraft:quartz_pillar,10,minecraft:smooth_quartz_block,10,minecraft:quartz_block,100)
RB(-6,9,-10,minecraft:chiseled_quartz_block,10,minecraft:quartz_pillar,10,minecraft:smooth_quartz_block,10,minecraft:quartz_block,100)
RB(-6,10,-10,minecraft:chiseled_quartz_block,10,minecraft:quartz_pillar,10,minecraft:smooth_quartz_block,10,minecraft:quartz_block,100)
RB(-6,5,-9,minecraft:chiseled_quartz_block,10,minecraft:quartz_pillar,10,minecraft:smooth_quartz_block,10,minecraft:quartz_block,100)
RB(-6,6,-9,minecraft:chiseled_quartz_block,10,minecraft:quartz_pillar,10,minecraft:smooth_quartz_block,10,minecraft:quartz_block,100)
RB(-6,7,-9,minecraft:chiseled_quartz_block,10,minecraft:quartz_pillar,10,minecraft:smooth_quartz_block,10,minecraft:quartz_block,100)
RB(-6,8,-9,minecraft:chiseled_quartz_block,10,minecraft:quartz_pillar,10,minecraft:smooth_quartz_block,10,minecraft:quartz_block,100)
RB(-6,9,-9,minecraft:chiseled_quartz_block,10,minecraft:quartz_pillar,10,minecraft:smooth_quartz_block,10,minecraft:quartz_block,100)
RB(-6,10,-9,minecraft:chiseled_quartz_block,10,minecraft:quartz_pillar,10,minecraft:smooth_quartz_block,10,minecraft:quartz_block,100)
RB(-6,4,-8,minecraft:chiseled_quartz_block,10,minecraft:quartz_pillar,10,minecraft:smooth_quartz_block,10,minecraft:quartz_block,100)
RB(-6,5,-8,minecraft:chiseled_quartz_block,10,minecraft:quartz_pillar,10,minecraft:smooth_quartz_block,10,minecraft:quartz_block,100)
RB(-6,6,-8,minecraft:chiseled_quartz_block,10,minecraft:quartz_pillar,10,minecraft:smooth_quartz_block,10,minecraft:quartz_block,100)
RB(-6,7,-8,minecraft:chiseled_quartz_block,10,minecraft:quartz_pillar,10,minecraft:smooth_quartz_block,10,minecraft:quartz_block,100)
RB(-6,8,-8,minecraft:chiseled_quartz_block,10,minecraft:quartz_pillar,10,minecraft:smooth_quartz_block,10,minecraft:quartz_block,100)
RB(-6,9,-8,minecraft:chiseled_quartz_block,10,minecraft:quartz_pillar,10,minecraft:smooth_quartz_block,10,minecraft:quartz_block,100)
RB(-6,10,-8,minecraft:chiseled_quartz_block,10,minecraft:quartz_pillar,10,minecraft:smooth_quartz_block,10,minecraft:quartz_block,100)
RB(-6,3,-7,minecraft:chiseled_quartz_block,10,minecraft:quartz_pillar,10,minecraft:smooth_quartz_block,10,minecraft:quartz_block,100)
RB(-6,4,-7,minecraft:chiseled_quartz_block,10,minecraft:quartz_pillar,10,minecraft:smooth_quartz_block,10,minecraft:quartz_block,100)
RB(-6,5,-7,minecraft:chiseled_quartz_block,10,minecraft:quartz_pillar,10,minecraft:smooth_quartz_block,10,minecraft:quartz_block,100)
RB(-6,6,-7,minecraft:chiseled_quartz_block,10,minecraft:quartz_pillar,10,minecraft:smooth_quartz_block,10,minecraft:quartz_block,100)
RB(-6,7,-7,minecraft:chiseled_quartz_block,10,minecraft:quartz_pillar,10,minecraft:smooth_quartz_block,10,minecraft:quartz_block,100)
RB(-6,8,-7,minecraft:chiseled_quartz_block,10,minecraft:quartz_pillar,10,minecraft:smooth_quartz_block,10,minecraft:quartz_block,100)
RB(-6,9,-7,minecraft:chiseled_quartz_block,10,minecraft:quartz_pillar,10,minecraft:smooth_quartz_block,10,minecraft:quartz_block,100)
RB(-6,10,-7,minecraft:chiseled_quartz_block,10,minecraft:quartz_pillar,10,minecraft:smooth_quartz_block,10,minecraft:quartz_block,100)
RB(-6,2,-6,minecraft:chiseled_quartz_block,10,minecraft:quartz_pillar,10,minecraft:smooth_quartz_block,10,minecraft:quartz_block,100)
RB(-6,3,-6,minecraft:chiseled_quartz_block,10,minecraft:quartz_pillar,10,minecraft:smooth_quartz_block,10,minecraft:quartz_block,100)
RB(-6,4,-6,minecraft:chiseled_quartz_block,10,minecraft:quartz_pillar,10,minecraft:smooth_quartz_block,10,minecraft:quartz_block,100)
RB(-6,5,-6,minecraft:chiseled_quartz_block,10,minecraft:quartz_pillar,10,minecraft:smooth_quartz_block,10,minecraft:quartz_block,100)
RB(-6,6,-6,minecraft:chiseled_quartz_block,10,minecraft:quartz_pillar,10,minecraft:smooth_quartz_block,10,minecraft:quartz_block,100)
RB(-6,7,-6,minecraft:chiseled_quartz_block,10,minecraft:quartz_pillar,10,minecraft:smooth_quartz_block,10,minecraft:quartz_block,100)
RB(-6,8,-6,minecraft:chiseled_quartz_block,10,minecraft:quartz_pillar,10,minecraft:smooth_quartz_block,10,minecraft:quartz_block,100)
RB(-6,9,-6,minecraft:chiseled_quartz_block,10,minecraft:quartz_pillar,10,minecraft:smooth_quartz_block,10,minecraft:quartz_block,100)
RB(-6,1,-5,minecraft:chiseled_quartz_block,10,minecraft:quartz_pillar,10,minecraft:smooth_quartz_block,10,minecraft:quartz_block,100)
RB(-6,2,-5,minecraft:chiseled_quartz_block,10,minecraft:quartz_pillar,10,minecraft:smooth_quartz_block,10,minecraft:quartz_block,100)
RB(-6,3,-5,minecraft:chiseled_quartz_block,10,minecraft:quartz_pillar,10,minecraft:smooth_quartz_block,10,minecraft:quartz_block,100)
RB(-6,4,-5,minecraft:chiseled_quartz_block,10,minecraft:quartz_pillar,10,minecraft:smooth_quartz_block,10,minecraft:quartz_block,100)
RB(-6,5,-5,minecraft:chiseled_quartz_block,10,minecraft:quartz_pillar,10,minecraft:smooth_quartz_block,10,minecraft:quartz_block,100)
RB(-6,6,-5,minecraft:chiseled_quartz_block,10,minecraft:quartz_pillar,10,minecraft:smooth_quartz_block,10,minecraft:quartz_block,100)
RB(-6,7,-5,minecraft:chiseled_quartz_block,10,minecraft:quartz_pillar,10,minecraft:smooth_quartz_block,10,minecraft:quartz_block,100)
RB(-6,8,-5,minecraft:chiseled_quartz_block,10,minecraft:quartz_pillar,10,minecraft:smooth_quartz_block,10,minecraft:quartz_block,100)
RB(-6,9,-5,minecraft:chiseled_quartz_block,10,minecraft:quartz_pillar,10,minecraft:smooth_quartz_block,10,minecraft:quartz_block,100)
RB(-6,0,-4,minecraft:chiseled_quartz_block,10,minecraft:quartz_pillar,10,minecraft:smooth_quartz_block,10,minecraft:quartz_block,100)
RB(-6,1,-4,minecraft:chiseled_quartz_block,10,minecraft:quartz_pillar,10,minecraft:smooth_quartz_block,10,minecraft:quartz_block,100)
RB(-6,2,-4,minecraft:chiseled_quartz_block,10,minecraft:quartz_pillar,10,minecraft:smooth_quartz_block,10,minecraft:quartz_block,100)
RB(-6,3,-4,minecraft:chiseled_quartz_block,10,minecraft:quartz_pillar,10,minecraft:smooth_quartz_block,10,minecraft:quartz_block,100)
RB(-6,4,-4,minecraft:chiseled_quartz_block,10,minecraft:quartz_pillar,10,minecraft:smooth_quartz_block,10,minecraft:quartz_block,100)
RB(-6,5,-4,minecraft:chiseled_quartz_block,10,minecraft:quartz_pillar,10,minecraft:smooth_quartz_block,10,minecraft:quartz_block,100)
RB(-6,6,-4,minecraft:chiseled_quartz_block,10,minecraft:quartz_pillar,10,minecraft:smooth_quartz_block,10,minecraft:quartz_block,100)
RB(-6,7,-4,minecraft:chiseled_quartz_block,10,minecraft:quartz_pillar,10,minecraft:smooth_quartz_block,10,minecraft:quartz_block,100)
RB(-6,8,-4,minecraft:chiseled_quartz_block,10,minecraft:quartz_pillar,10,minecraft:smooth_quartz_block,10,minecraft:quartz_block,100)
RB(-6,9,-4,minecraft:chiseled_quartz_block,10,minecraft:quartz_pillar,10,minecraft:smooth_quartz_block,10,minecraft:quartz_block,100)
RB(-6,0,-3,minecraft:chiseled_quartz_block,10,minecraft:quartz_pillar,10,minecraft:smooth_quartz_block,10,minecraft:quartz_block,100)
RB(-6,1,-3,minecraft:chiseled_quartz_block,10,minecraft:quartz_pillar,10,minecraft:smooth_quartz_block,10,minecraft:quartz_block,100)
RB(-6,2,-3,minecraft:chiseled_quartz_block,10,minecraft:quartz_pillar,10,minecraft:smooth_quartz_block,10,minecraft:quartz_block,100)
RB(-6,3,-3,minecraft:chiseled_quartz_block,10,minecraft:quartz_pillar,10,minecraft:smooth_quartz_block,10,minecraft:quartz_block,100)
RB(-6,4,-3,minecraft:chiseled_quartz_block,10,minecraft:quartz_pillar,10,minecraft:smooth_quartz_block,10,minecraft:quartz_block,100)
RB(-6,5,-3,minecraft:chiseled_quartz_block,10,minecraft:quartz_pillar,10,minecraft:smooth_quartz_block,10,minecraft:quartz_block,100)
RB(-6,6,-3,minecraft:chiseled_quartz_block,10,minecraft:quartz_pillar,10,minecraft:smooth_quartz_block,10,minecraft:quartz_block,100)
RB(-6,7,-3,minecraft:chiseled_quartz_block,10,minecraft:quartz_pillar,10,minecraft:smooth_quartz_block,10,minecraft:quartz_block,100)
RB(-6,8,-3,minecraft:chiseled_quartz_block,10,minecraft:quartz_pillar,10,minecraft:smooth_quartz_block,10,minecraft:quartz_block,100)
RB(-6,0,-2,minecraft:chiseled_quartz_block,10,minecraft:quartz_pillar,10,minecraft:smooth_quartz_block,10,minecraft:quartz_block,100)
RB(-6,1,-2,minecraft:chiseled_quartz_block,10,minecraft:quartz_pillar,10,minecraft:smooth_quartz_block,10,minecraft:quartz_block,100)
RB(-6,2,-2,minecraft:chiseled_quartz_block,10,minecraft:quartz_pillar,10,minecraft:smooth_quartz_block,10,minecraft:quartz_block,100)
RB(-6,3,-2,minecraft:chiseled_quartz_block,10,minecraft:quartz_pillar,10,minecraft:smooth_quartz_block,10,minecraft:quartz_block,100)
RB(-6,4,-2,minecraft:chiseled_quartz_block,10,minecraft:quartz_pillar,10,minecraft:smooth_quartz_block,10,minecraft:quartz_block,100)
RB(-6,5,-2,minecraft:chiseled_quartz_block,10,minecraft:quartz_pillar,10,minecraft:smooth_quartz_block,10,minecraft:quartz_block,100)
RB(-6,6,-2,minecraft:chiseled_quartz_block,10,minecraft:quartz_pillar,10,minecraft:smooth_quartz_block,10,minecraft:quartz_block,100)
RB(-6,7,-2,minecraft:chiseled_quartz_block,10,minecraft:quartz_pillar,10,minecraft:smooth_quartz_block,10,minecraft:quartz_block,100)
RB(-6,8,-2,minecraft:chiseled_quartz_block,10,minecraft:quartz_pillar,10,minecraft:smooth_quartz_block,10,minecraft:quartz_block,100)
RB(-6,0,-1,minecraft:chiseled_quartz_block,10,minecraft:quartz_pillar,10,minecraft:smooth_quartz_block,10,minecraft:quartz_block,100)
RB(-6,1,-1,minecraft:chiseled_quartz_block,10,minecraft:quartz_pillar,10,minecraft:smooth_quartz_block,10,minecraft:quartz_block,100)
RB(-6,2,-1,minecraft:chiseled_quartz_block,10,minecraft:quartz_pillar,10,minecraft:smooth_quartz_block,10,minecraft:quartz_block,100)
RB(-6,3,-1,minecraft:chiseled_quartz_block,10,minecraft:quartz_pillar,10,minecraft:smooth_quartz_block,10,minecraft:quartz_block,100)
RB(-6,4,-1,minecraft:chiseled_quartz_block,10,minecraft:quartz_pillar,10,minecraft:smooth_quartz_block,10,minecraft:quartz_block,100)
RB(-6,5,-1,minecraft:chiseled_quartz_block,10,minecraft:quartz_pillar,10,minecraft:smooth_quartz_block,10,minecraft:quartz_block,100)
RB(-6,6,-1,minecraft:chiseled_quartz_block,10,minecraft:quartz_pillar,10,minecraft:smooth_quartz_block,10,minecraft:quartz_block,100)
RB(-6,7,-1,minecraft:chiseled_quartz_block,10,minecraft:quartz_pillar,10,minecraft:smooth_quartz_block,10,minecraft:quartz_block,100)
RB(-6,0,0,minecraft:chiseled_quartz_block,10,minecraft:quartz_pillar,10,minecraft:smooth_quartz_block,10,minecraft:quartz_block,100)
RB(-6,1,0,minecraft:chiseled_quartz_block,10,minecraft:quartz_pillar,10,minecraft:smooth_quartz_block,10,minecraft:quartz_block,100)
RB(-6,2,0,minecraft:chiseled_quartz_block,10,minecraft:quartz_pillar,10,minecraft:smooth_quartz_block,10,minecraft:quartz_block,100)
RB(-6,3,0,minecraft:chiseled_quartz_block,10,minecraft:quartz_pillar,10,minecraft:smooth_quartz_block,10,minecraft:quartz_block,100)
RB(-6,4,0,minecraft:chiseled_quartz_block,10,minecraft:quartz_pillar,10,minecraft:smooth_quartz_block,10,minecraft:quartz_block,100)
RB(-6,5,0,minecraft:chiseled_quartz_block,10,minecraft:quartz_pillar,10,minecraft:smooth_quartz_block,10,minecraft:quartz_block,100)
RB(-6,6,0,minecraft:chiseled_quartz_block,10,minecraft:quartz_pillar,10,minecraft:smooth_quartz_block,10,minecraft:quartz_block,100)
RB(-6,7,0,minecraft:chiseled_quartz_block,10,minecraft:quartz_pillar,10,minecraft:smooth_quartz_block,10,minecraft:quartz_block,100)
RB(-6,0,1,minecraft:chiseled_quartz_block,10,minecraft:quartz_pillar,10,minecraft:smooth_quartz_block,10,minecraft:quartz_block,100)
RB(-6,1,1,minecraft:chiseled_quartz_block,10,minecraft:quartz_pillar,10,minecraft:smooth_quartz_block,10,minecraft:quartz_block,100)
RB(-6,2,1,minecraft:chiseled_quartz_block,10,minecraft:quartz_pillar,10,minecraft:smooth_quartz_block,10,minecraft:quartz_block,100)
RB(-6,3,1,minecraft:chiseled_quartz_block,10,minecraft:quartz_pillar,10,minecraft:smooth_quartz_block,10,minecraft:quartz_block,100)
RB(-6,4,1,minecraft:chiseled_quartz_block,10,minecraft:quartz_pillar,10,minecraft:smooth_quartz_block,10,minecraft:quartz_block,100)
RB(-6,5,1,minecraft:chiseled_quartz_block,10,minecraft:quartz_pillar,10,minecraft:smooth_quartz_block,10,minecraft:quartz_block,100)
RB(-6,6,1,minecraft:chiseled_quartz_block,10,minecraft:quartz_pillar,10,minecraft:smooth_quartz_block,10,minecraft:quartz_block,100)
RB(-6,0,2,minecraft:chiseled_quartz_block,10,minecraft:quartz_pillar,10,minecraft:smooth_quartz_block,10,minecraft:quartz_block,100)
RB(-6,1,2,minecraft:chiseled_quartz_block,10,minecraft:quartz_pillar,10,minecraft:smooth_quartz_block,10,minecraft:quartz_block,100)
RB(-6,2,2,minecraft:chiseled_quartz_block,10,minecraft:quartz_pillar,10,minecraft:smooth_quartz_block,10,minecraft:quartz_block,100)
RB(-6,3,2,minecraft:chiseled_quartz_block,10,minecraft:quartz_pillar,10,minecraft:smooth_quartz_block,10,minecraft:quartz_block,100)
RB(-6,4,2,minecraft:chiseled_quartz_block,10,minecraft:quartz_pillar,10,minecraft:smooth_quartz_block,10,minecraft:quartz_block,100)
RB(-6,5,2,minecraft:chiseled_quartz_block,10,minecraft:quartz_pillar,10,minecraft:smooth_quartz_block,10,minecraft:quartz_block,100)
RB(-6,6,2,minecraft:chiseled_quartz_block,10,minecraft:quartz_pillar,10,minecraft:smooth_quartz_block,10,minecraft:quartz_block,100)
RB(-6,0,3,minecraft:chiseled_quartz_block,10,minecraft:quartz_pillar,10,minecraft:smooth_quartz_block,10,minecraft:quartz_block,100)
RB(-6,1,3,minecraft:chiseled_quartz_block,10,minecraft:quartz_pillar,10,minecraft:smooth_quartz_block,10,minecraft:quartz_block,100)
RB(-6,2,3,minecraft:chiseled_quartz_block,10,minecraft:quartz_pillar,10,minecraft:smooth_quartz_block,10,minecraft:quartz_block,100)
RB(-6,3,3,minecraft:chiseled_quartz_block,10,minecraft:quartz_pillar,10,minecraft:smooth_quartz_block,10,minecraft:quartz_block,100)
RB(-6,4,3,minecraft:chiseled_quartz_block,10,minecraft:quartz_pillar,10,minecraft:smooth_quartz_block,10,minecraft:quartz_block,100)
RB(-6,5,3,minecraft:chiseled_quartz_block,10,minecraft:quartz_pillar,10,minecraft:smooth_quartz_block,10,minecraft:quartz_block,100)
RB(-6,6,3,minecraft:chiseled_quartz_block,10,minecraft:quartz_pillar,10,minecraft:smooth_quartz_block,10,minecraft:quartz_block,100)
RB(-6,0,4,minecraft:chiseled_quartz_block,10,minecraft:quartz_pillar,10,minecraft:smooth_quartz_block,10,minecraft:quartz_block,100)
RB(-6,1,4,minecraft:chiseled_quartz_block,10,minecraft:quartz_pillar,10,minecraft:smooth_quartz_block,10,minecraft:quartz_block,100)
RB(-6,2,4,minecraft:chiseled_quartz_block,10,minecraft:quartz_pillar,10,minecraft:smooth_quartz_block,10,minecraft:quartz_block,100)
RB(-6,3,4,minecraft:chiseled_quartz_block,10,minecraft:quartz_pillar,10,minecraft:smooth_quartz_block,10,minecraft:quartz_block,100)
RB(-6,4,4,minecraft:chiseled_quartz_block,10,minecraft:quartz_pillar,10,minecraft:smooth_quartz_block,10,minecraft:quartz_block,100)
RB(-6,5,4,minecraft:chiseled_quartz_block,10,minecraft:quartz_pillar,10,minecraft:smooth_quartz_block,10,minecraft:quartz_block,100)
RB(-6,0,5,minecraft:chiseled_quartz_block,10,minecraft:quartz_pillar,10,minecraft:smooth_quartz_block,10,minecraft:quartz_block,100)
RB(-6,1,5,minecraft:chiseled_quartz_block,10,minecraft:quartz_pillar,10,minecraft:smooth_quartz_block,10,minecraft:quartz_block,100)
RB(-6,2,5,minecraft:chiseled_quartz_block,10,minecraft:quartz_pillar,10,minecraft:smooth_quartz_block,10,minecraft:quartz_block,100)
RB(-6,3,5,minecraft:chiseled_quartz_block,10,minecraft:quartz_pillar,10,minecraft:smooth_quartz_block,10,minecraft:quartz_block,100)
RB(-6,4,5,minecraft:chiseled_quartz_block,10,minecraft:quartz_pillar,10,minecraft:smooth_quartz_block,10,minecraft:quartz_block,100)
RB(-6,5,5,minecraft:chiseled_quartz_block,10,minecraft:quartz_pillar,10,minecraft:smooth_quartz_block,10,minecraft:quartz_block,100)
RB(-6,0,6,minecraft:chiseled_quartz_block,10,minecraft:quartz_pillar,10,minecraft:smooth_quartz_block,10,minecraft:quartz_block,100)
RB(-6,1,6,minecraft:chiseled_quartz_block,10,minecraft:quartz_pillar,10,minecraft:smooth_quartz_block,10,minecraft:quartz_block,100)
RB(-6,2,6,minecraft:chiseled_quartz_block,10,minecraft:quartz_pillar,10,minecraft:smooth_quartz_block,10,minecraft:quartz_block,100)
RB(-6,3,6,minecraft:chiseled_quartz_block,10,minecraft:quartz_pillar,10,minecraft:smooth_quartz_block,10,minecraft:quartz_block,100)
RB(-6,4,6,minecraft:chiseled_quartz_block,10,minecraft:quartz_pillar,10,minecraft:smooth_quartz_block,10,minecraft:quartz_block,100)
RB(-6,0,7,minecraft:chiseled_quartz_block,10,minecraft:quartz_pillar,10,minecraft:smooth_quartz_block,10,minecraft:quartz_block,100)
RB(-6,1,7,minecraft:chiseled_quartz_block,10,minecraft:quartz_pillar,10,minecraft:smooth_quartz_block,10,minecraft:quartz_block,100)
RB(-6,2,7,minecraft:chiseled_quartz_block,10,minecraft:quartz_pillar,10,minecraft:smooth_quartz_block,10,minecraft:quartz_block,100)
RB(-6,3,7,minecraft:chiseled_quartz_block,10,minecraft:quartz_pillar,10,minecraft:smooth_quartz_block,10,minecraft:quartz_block,100)
RB(-6,0,8,minecraft:chiseled_quartz_block,10,minecraft:quartz_pillar,10,minecraft:smooth_quartz_block,10,minecraft:quartz_block,100)
RB(-6,1,8,minecraft:chiseled_quartz_block,10,minecraft:quartz_pillar,10,minecraft:smooth_quartz_block,10,minecraft:quartz_block,100)
RB(-6,2,8,minecraft:chiseled_quartz_block,10,minecraft:quartz_pillar,10,minecraft:smooth_quartz_block,10,minecraft:quartz_block,100)
RB(-6,0,9,minecraft:chiseled_quartz_block,10,minecraft:quartz_pillar,10,minecraft:smooth_quartz_block,10,minecraft:quartz_block,100)
RB(-6,1,9,minecraft:chiseled_quartz_block,10,minecraft:quartz_pillar,10,minecraft:smooth_quartz_block,10,minecraft:quartz_block,100)
RB(-6,0,10,minecraft:chiseled_quartz_block,10,minecraft:quartz_pillar,10,minecraft:smooth_quartz_block,10,minecraft:quartz_block,100)
RB(-5,7,-11,minecraft:chiseled_quartz_block,10,minecraft:quartz_pillar,10,minecraft:smooth_quartz_block,10,minecraft:quartz_block,100)
RB(-5,8,-11,minecraft:chiseled_quartz_block,10,minecraft:quartz_pillar,10,minecraft:smooth_quartz_block,10,minecraft:quartz_block,100)
RB(-5,9,-11,minecraft:chiseled_quartz_block,10,minecraft:quartz_pillar,10,minecraft:smooth_quartz_block,10,minecraft:quartz_block,100)
RB(-5,6,-10,minecraft:chiseled_quartz_block,10,minecraft:quartz_pillar,10,minecraft:smooth_quartz_block,10,minecraft:quartz_block,100)
RB(-5,7,-10,minecraft:chiseled_quartz_block,10,minecraft:quartz_pillar,10,minecraft:smooth_quartz_block,10,minecraft:quartz_block,100)
RB(-5,8,-10,minecraft:chiseled_quartz_block,10,minecraft:quartz_pillar,10,minecraft:smooth_quartz_block,10,minecraft:quartz_block,100)
RB(-5,9,-10,minecraft:chiseled_quartz_block,10,minecraft:quartz_pillar,10,minecraft:smooth_quartz_block,10,minecraft:quartz_block,100)
RB(-5,5,-9,minecraft:chiseled_quartz_block,10,minecraft:quartz_pillar,10,minecraft:smooth_quartz_block,10,minecraft:quartz_block,100)
RB(-5,6,-9,minecraft:chiseled_quartz_block,10,minecraft:quartz_pillar,10,minecraft:smooth_quartz_block,10,minecraft:quartz_block,100)
RB(-5,7,-9,minecraft:chiseled_quartz_block,10,minecraft:quartz_pillar,10,minecraft:smooth_quartz_block,10,minecraft:quartz_block,100)
RB(-5,8,-9,minecraft:chiseled_quartz_block,10,minecraft:quartz_pillar,10,minecraft:smooth_quartz_block,10,minecraft:quartz_block,100)
RB(-5,9,-9,minecraft:chiseled_quartz_block,10,minecraft:quartz_pillar,10,minecraft:smooth_quartz_block,10,minecraft:quartz_block,100)
RB(-5,4,-8,minecraft:chiseled_quartz_block,10,minecraft:quartz_pillar,10,minecraft:smooth_quartz_block,10,minecraft:quartz_block,100)
RB(-5,5,-8,minecraft:chiseled_quartz_block,10,minecraft:quartz_pillar,10,minecraft:smooth_quartz_block,10,minecraft:quartz_block,100)
RB(-5,6,-8,minecraft:chiseled_quartz_block,10,minecraft:quartz_pillar,10,minecraft:smooth_quartz_block,10,minecraft:quartz_block,100)
RB(-5,7,-8,minecraft:chiseled_quartz_block,10,minecraft:quartz_pillar,10,minecraft:smooth_quartz_block,10,minecraft:quartz_block,100)
RB(-5,8,-8,minecraft:chiseled_quartz_block,10,minecraft:quartz_pillar,10,minecraft:smooth_quartz_block,10,minecraft:quartz_block,100)
RB(-5,9,-8,minecraft:chiseled_quartz_block,10,minecraft:quartz_pillar,10,minecraft:smooth_quartz_block,10,minecraft:quartz_block,100)
RB(-5,3,-7,minecraft:chiseled_quartz_block,10,minecraft:quartz_pillar,10,minecraft:smooth_quartz_block,10,minecraft:quartz_block,100)
RB(-5,4,-7,minecraft:chiseled_quartz_block,10,minecraft:quartz_pillar,10,minecraft:smooth_quartz_block,10,minecraft:quartz_block,100)
RB(-5,5,-7,minecraft:chiseled_quartz_block,10,minecraft:quartz_pillar,10,minecraft:smooth_quartz_block,10,minecraft:quartz_block,100)
RB(-5,6,-7,minecraft:chiseled_quartz_block,10,minecraft:quartz_pillar,10,minecraft:smooth_quartz_block,10,minecraft:quartz_block,100)
RB(-5,7,-7,minecraft:chiseled_quartz_block,10,minecraft:quartz_pillar,10,minecraft:smooth_quartz_block,10,minecraft:quartz_block,100)
RB(-5,8,-7,minecraft:chiseled_quartz_block,10,minecraft:quartz_pillar,10,minecraft:smooth_quartz_block,10,minecraft:quartz_block,100)
RB(-5,9,-7,minecraft:chiseled_quartz_block,10,minecraft:quartz_pillar,10,minecraft:smooth_quartz_block,10,minecraft:quartz_block,100)
RB(-5,2,-6,minecraft:chiseled_quartz_block,10,minecraft:quartz_pillar,10,minecraft:smooth_quartz_block,10,minecraft:quartz_block,100)
RB(-5,3,-6,minecraft:chiseled_quartz_block,10,minecraft:quartz_pillar,10,minecraft:smooth_quartz_block,10,minecraft:quartz_block,100)
RB(-5,4,-6,minecraft:chiseled_quartz_block,10,minecraft:quartz_pillar,10,minecraft:smooth_quartz_block,10,minecraft:quartz_block,100)
RB(-5,5,-6,minecraft:chiseled_quartz_block,10,minecraft:quartz_pillar,10,minecraft:smooth_quartz_block,10,minecraft:quartz_block,100)
RB(-5,6,-6,minecraft:chiseled_quartz_block,10,minecraft:quartz_pillar,10,minecraft:smooth_quartz_block,10,minecraft:quartz_block,100)
RB(-5,7,-6,minecraft:chiseled_quartz_block,10,minecraft:quartz_pillar,10,minecraft:smooth_quartz_block,10,minecraft:quartz_block,100)
RB(-5,8,-6,minecraft:chiseled_quartz_block,10,minecraft:quartz_pillar,10,minecraft:smooth_quartz_block,10,minecraft:quartz_block,100)
RB(-5,9,-6,minecraft:chiseled_quartz_block,10,minecraft:quartz_pillar,10,minecraft:smooth_quartz_block,10,minecraft:quartz_block,100)
RB(-5,1,-5,minecraft:chiseled_quartz_block,10,minecraft:quartz_pillar,10,minecraft:smooth_quartz_block,10,minecraft:quartz_block,100)
RB(-5,2,-5,minecraft:chiseled_quartz_block,10,minecraft:quartz_pillar,10,minecraft:smooth_quartz_block,10,minecraft:quartz_block,100)
RB(-5,3,-5,minecraft:chiseled_quartz_block,10,minecraft:quartz_pillar,10,minecraft:smooth_quartz_block,10,minecraft:quartz_block,100)
RB(-5,4,-5,minecraft:chiseled_quartz_block,10,minecraft:quartz_pillar,10,minecraft:smooth_quartz_block,10,minecraft:quartz_block,100)
RB(-5,5,-5,minecraft:chiseled_quartz_block,10,minecraft:quartz_pillar,10,minecraft:smooth_quartz_block,10,minecraft:quartz_block,100)
RB(-5,6,-5,minecraft:chiseled_quartz_block,10,minecraft:quartz_pillar,10,minecraft:smooth_quartz_block,10,minecraft:quartz_block,100)
RB(-5,7,-5,minecraft:chiseled_quartz_block,10,minecraft:quartz_pillar,10,minecraft:smooth_quartz_block,10,minecraft:quartz_block,100)
RB(-5,8,-5,minecraft:chiseled_quartz_block,10,minecraft:quartz_pillar,10,minecraft:smooth_quartz_block,10,minecraft:quartz_block,100)
RB(-5,9,-5,minecraft:chiseled_quartz_block,10,minecraft:quartz_pillar,10,minecraft:smooth_quartz_block,10,minecraft:quartz_block,100)
RB(-5,0,-4,minecraft:chiseled_quartz_block,10,minecraft:quartz_pillar,10,minecraft:smooth_quartz_block,10,minecraft:quartz_block,100)
RB(-5,1,-4,minecraft:chiseled_quartz_block,10,minecraft:quartz_pillar,10,minecraft:smooth_quartz_block,10,minecraft:quartz_block,100)
RB(-5,2,-4,minecraft:chiseled_quartz_block,10,minecraft:quartz_pillar,10,minecraft:smooth_quartz_block,10,minecraft:quartz_block,100)
RB(-5,3,-4,minecraft:chiseled_quartz_block,10,minecraft:quartz_pillar,10,minecraft:smooth_quartz_block,10,minecraft:quartz_block,100)
RB(-5,4,-4,minecraft:chiseled_quartz_block,10,minecraft:quartz_pillar,10,minecraft:smooth_quartz_block,10,minecraft:quartz_block,100)
RB(-5,5,-4,minecraft:chiseled_quartz_block,10,minecraft:quartz_pillar,10,minecraft:smooth_quartz_block,10,minecraft:quartz_block,100)
RB(-5,6,-4,minecraft:chiseled_quartz_block,10,minecraft:quartz_pillar,10,minecraft:smooth_quartz_block,10,minecraft:quartz_block,100)
RB(-5,7,-4,minecraft:chiseled_quartz_block,10,minecraft:quartz_pillar,10,minecraft:smooth_quartz_block,10,minecraft:quartz_block,100)
RB(-5,8,-4,minecraft:chiseled_quartz_block,10,minecraft:quartz_pillar,10,minecraft:smooth_quartz_block,10,minecraft:quartz_block,100)
RB(-5,0,-3,minecraft:chiseled_quartz_block,10,minecraft:quartz_pillar,10,minecraft:smooth_quartz_block,10,minecraft:quartz_block,100)
RB(-5,1,-3,minecraft:chiseled_quartz_block,10,minecraft:quartz_pillar,10,minecraft:smooth_quartz_block,10,minecraft:quartz_block,100)
RB(-5,2,-3,minecraft:chiseled_quartz_block,10,minecraft:quartz_pillar,10,minecraft:smooth_quartz_block,10,minecraft:quartz_block,100)
RB(-5,3,-3,minecraft:chiseled_quartz_block,10,minecraft:quartz_pillar,10,minecraft:smooth_quartz_block,10,minecraft:quartz_block,100)
RB(-5,4,-3,minecraft:chiseled_quartz_block,10,minecraft:quartz_pillar,10,minecraft:smooth_quartz_block,10,minecraft:quartz_block,100)
RB(-5,5,-3,minecraft:chiseled_quartz_block,10,minecraft:quartz_pillar,10,minecraft:smooth_quartz_block,10,minecraft:quartz_block,100)
RB(-5,6,-3,minecraft:chiseled_quartz_block,10,minecraft:quartz_pillar,10,minecraft:smooth_quartz_block,10,minecraft:quartz_block,100)
RB(-5,7,-3,minecraft:chiseled_quartz_block,10,minecraft:quartz_pillar,10,minecraft:smooth_quartz_block,10,minecraft:quartz_block,100)
RB(-5,8,-3,minecraft:chiseled_quartz_block,10,minecraft:quartz_pillar,10,minecraft:smooth_quartz_block,10,minecraft:quartz_block,100)
RB(-5,0,-2,minecraft:chiseled_quartz_block,10,minecraft:quartz_pillar,10,minecraft:smooth_quartz_block,10,minecraft:quartz_block,100)
RB(-5,1,-2,minecraft:chiseled_quartz_block,10,minecraft:quartz_pillar,10,minecraft:smooth_quartz_block,10,minecraft:quartz_block,100)
RB(-5,2,-2,minecraft:chiseled_quartz_block,10,minecraft:quartz_pillar,10,minecraft:smooth_quartz_block,10,minecraft:quartz_block,100)
RB(-5,3,-2,minecraft:chiseled_quartz_block,10,minecraft:quartz_pillar,10,minecraft:smooth_quartz_block,10,minecraft:quartz_block,100)
RB(-5,4,-2,minecraft:chiseled_quartz_block,10,minecraft:quartz_pillar,10,minecraft:smooth_quartz_block,10,minecraft:quartz_block,100)
RB(-5,5,-2,minecraft:chiseled_quartz_block,10,minecraft:quartz_pillar,10,minecraft:smooth_quartz_block,10,minecraft:quartz_block,100)
RB(-5,6,-2,minecraft:chiseled_quartz_block,10,minecraft:quartz_pillar,10,minecraft:smooth_quartz_block,10,minecraft:quartz_block,100)
RB(-5,7,-2,minecraft:chiseled_quartz_block,10,minecraft:quartz_pillar,10,minecraft:smooth_quartz_block,10,minecraft:quartz_block,100)
RB(-5,8,-2,minecraft:chiseled_quartz_block,10,minecraft:quartz_pillar,10,minecraft:smooth_quartz_block,10,minecraft:quartz_block,100)
RB(-5,0,-1,minecraft:chiseled_quartz_block,10,minecraft:quartz_pillar,10,minecraft:smooth_quartz_block,10,minecraft:quartz_block,100)
RB(-5,1,-1,minecraft:chiseled_quartz_block,10,minecraft:quartz_pillar,10,minecraft:smooth_quartz_block,10,minecraft:quartz_block,100)
RB(-5,2,-1,minecraft:chiseled_quartz_block,10,minecraft:quartz_pillar,10,minecraft:smooth_quartz_block,10,minecraft:quartz_block,100)
RB(-5,3,-1,minecraft:chiseled_quartz_block,10,minecraft:quartz_pillar,10,minecraft:smooth_quartz_block,10,minecraft:quartz_block,100)
RB(-5,4,-1,minecraft:chiseled_quartz_block,10,minecraft:quartz_pillar,10,minecraft:smooth_quartz_block,10,minecraft:quartz_block,100)
RB(-5,5,-1,minecraft:chiseled_quartz_block,10,minecraft:quartz_pillar,10,minecraft:smooth_quartz_block,10,minecraft:quartz_block,100)
RB(-5,6,-1,minecraft:chiseled_quartz_block,10,minecraft:quartz_pillar,10,minecraft:smooth_quartz_block,10,minecraft:quartz_block,100)
RB(-5,7,-1,minecraft:chiseled_quartz_block,10,minecraft:quartz_pillar,10,minecraft:smooth_quartz_block,10,minecraft:quartz_block,100)
RB(-5,0,0,minecraft:chiseled_quartz_block,10,minecraft:quartz_pillar,10,minecraft:smooth_quartz_block,10,minecraft:quartz_block,100)
RB(-5,1,0,minecraft:chiseled_quartz_block,10,minecraft:quartz_pillar,10,minecraft:smooth_quartz_block,10,minecraft:quartz_block,100)
RB(-5,2,0,minecraft:chiseled_quartz_block,10,minecraft:quartz_pillar,10,minecraft:smooth_quartz_block,10,minecraft:quartz_block,100)
RB(-5,3,0,minecraft:chiseled_quartz_block,10,minecraft:quartz_pillar,10,minecraft:smooth_quartz_block,10,minecraft:quartz_block,100)
RB(-5,4,0,minecraft:chiseled_quartz_block,10,minecraft:quartz_pillar,10,minecraft:smooth_quartz_block,10,minecraft:quartz_block,100)
RB(-5,5,0,minecraft:chiseled_quartz_block,10,minecraft:quartz_pillar,10,minecraft:smooth_quartz_block,10,minecraft:quartz_block,100)
RB(-5,6,0,minecraft:chiseled_quartz_block,10,minecraft:quartz_pillar,10,minecraft:smooth_quartz_block,10,minecraft:quartz_block,100)
RB(-5,7,0,minecraft:chiseled_quartz_block,10,minecraft:quartz_pillar,10,minecraft:smooth_quartz_block,10,minecraft:quartz_block,100)
RB(-5,0,1,minecraft:chiseled_quartz_block,10,minecraft:quartz_pillar,10,minecraft:smooth_quartz_block,10,minecraft:quartz_block,100)
RB(-5,1,1,minecraft:chiseled_quartz_block,10,minecraft:quartz_pillar,10,minecraft:smooth_quartz_block,10,minecraft:quartz_block,100)
RB(-5,2,1,minecraft:chiseled_quartz_block,10,minecraft:quartz_pillar,10,minecraft:smooth_quartz_block,10,minecraft:quartz_block,100)
RB(-5,3,1,minecraft:chiseled_quartz_block,10,minecraft:quartz_pillar,10,minecraft:smooth_quartz_block,10,minecraft:quartz_block,100)
RB(-5,4,1,minecraft:chiseled_quartz_block,10,minecraft:quartz_pillar,10,minecraft:smooth_quartz_block,10,minecraft:quartz_block,100)
RB(-5,5,1,minecraft:chiseled_quartz_block,10,minecraft:quartz_pillar,10,minecraft:smooth_quartz_block,10,minecraft:quartz_block,100)
RB(-5,6,1,minecraft:chiseled_quartz_block,10,minecraft:quartz_pillar,10,minecraft:smooth_quartz_block,10,minecraft:quartz_block,100)
RB(-5,0,2,minecraft:chiseled_quartz_block,10,minecraft:quartz_pillar,10,minecraft:smooth_quartz_block,10,minecraft:quartz_block,100)
RB(-5,1,2,minecraft:chiseled_quartz_block,10,minecraft:quartz_pillar,10,minecraft:smooth_quartz_block,10,minecraft:quartz_block,100)
RB(-5,2,2,minecraft:chiseled_quartz_block,10,minecraft:quartz_pillar,10,minecraft:smooth_quartz_block,10,minecraft:quartz_block,100)
RB(-5,3,2,minecraft:chiseled_quartz_block,10,minecraft:quartz_pillar,10,minecraft:smooth_quartz_block,10,minecraft:quartz_block,100)
RB(-5,4,2,minecraft:chiseled_quartz_block,10,minecraft:quartz_pillar,10,minecraft:smooth_quartz_block,10,minecraft:quartz_block,100)
RB(-5,5,2,minecraft:chiseled_quartz_block,10,minecraft:quartz_pillar,10,minecraft:smooth_quartz_block,10,minecraft:quartz_block,100)
RB(-5,6,2,minecraft:chiseled_quartz_block,10,minecraft:quartz_pillar,10,minecraft:smooth_quartz_block,10,minecraft:quartz_block,100)
RB(-5,0,3,minecraft:chiseled_quartz_block,10,minecraft:quartz_pillar,10,minecraft:smooth_quartz_block,10,minecraft:quartz_block,100)
RB(-5,1,3,minecraft:chiseled_quartz_block,10,minecraft:quartz_pillar,10,minecraft:smooth_quartz_block,10,minecraft:quartz_block,100)
RB(-5,2,3,minecraft:chiseled_quartz_block,10,minecraft:quartz_pillar,10,minecraft:smooth_quartz_block,10,minecraft:quartz_block,100)
RB(-5,3,3,minecraft:chiseled_quartz_block,10,minecraft:quartz_pillar,10,minecraft:smooth_quartz_block,10,minecraft:quartz_block,100)
RB(-5,4,3,minecraft:chiseled_quartz_block,10,minecraft:quartz_pillar,10,minecraft:smooth_quartz_block,10,minecraft:quartz_block,100)
RB(-5,5,3,minecraft:chiseled_quartz_block,10,minecraft:quartz_pillar,10,minecraft:smooth_quartz_block,10,minecraft:quartz_block,100)
RB(-5,0,4,minecraft:chiseled_quartz_block,10,minecraft:quartz_pillar,10,minecraft:smooth_quartz_block,10,minecraft:quartz_block,100)
RB(-5,1,4,minecraft:chiseled_quartz_block,10,minecraft:quartz_pillar,10,minecraft:smooth_quartz_block,10,minecraft:quartz_block,100)
RB(-5,2,4,minecraft:chiseled_quartz_block,10,minecraft:quartz_pillar,10,minecraft:smooth_quartz_block,10,minecraft:quartz_block,100)
RB(-5,3,4,minecraft:chiseled_quartz_block,10,minecraft:quartz_pillar,10,minecraft:smooth_quartz_block,10,minecraft:quartz_block,100)
RB(-5,4,4,minecraft:chiseled_quartz_block,10,minecraft:quartz_pillar,10,minecraft:smooth_quartz_block,10,minecraft:quartz_block,100)
RB(-5,5,4,minecraft:chiseled_quartz_block,10,minecraft:quartz_pillar,10,minecraft:smooth_quartz_block,10,minecraft:quartz_block,100)
RB(-5,0,5,minecraft:chiseled_quartz_block,10,minecraft:quartz_pillar,10,minecraft:smooth_quartz_block,10,minecraft:quartz_block,100)
RB(-5,1,5,minecraft:chiseled_quartz_block,10,minecraft:quartz_pillar,10,minecraft:smooth_quartz_block,10,minecraft:quartz_block,100)
RB(-5,2,5,minecraft:chiseled_quartz_block,10,minecraft:quartz_pillar,10,minecraft:smooth_quartz_block,10,minecraft:quartz_block,100)
RB(-5,3,5,minecraft:chiseled_quartz_block,10,minecraft:quartz_pillar,10,minecraft:smooth_quartz_block,10,minecraft:quartz_block,100)
RB(-5,4,5,minecraft:chiseled_quartz_block,10,minecraft:quartz_pillar,10,minecraft:smooth_quartz_block,10,minecraft:quartz_block,100)
RB(-5,5,5,minecraft:chiseled_quartz_block,10,minecraft:quartz_pillar,10,minecraft:smooth_quartz_block,10,minecraft:quartz_block,100)
RB(-5,0,6,minecraft:chiseled_quartz_block,10,minecraft:quartz_pillar,10,minecraft:smooth_quartz_block,10,minecraft:quartz_block,100)
RB(-5,1,6,minecraft:chiseled_quartz_block,10,minecraft:quartz_pillar,10,minecraft:smooth_quartz_block,10,minecraft:quartz_block,100)
RB(-5,2,6,minecraft:chiseled_quartz_block,10,minecraft:quartz_pillar,10,minecraft:smooth_quartz_block,10,minecraft:quartz_block,100)
RB(-5,3,6,minecraft:chiseled_quartz_block,10,minecraft:quartz_pillar,10,minecraft:smooth_quartz_block,10,minecraft:quartz_block,100)
RB(-5,4,6,minecraft:chiseled_quartz_block,10,minecraft:quartz_pillar,10,minecraft:smooth_quartz_block,10,minecraft:quartz_block,100)
RB(-5,0,7,minecraft:chiseled_quartz_block,10,minecraft:quartz_pillar,10,minecraft:smooth_quartz_block,10,minecraft:quartz_block,100)
RB(-5,1,7,minecraft:chiseled_quartz_block,10,minecraft:quartz_pillar,10,minecraft:smooth_quartz_block,10,minecraft:quartz_block,100)
RB(-5,2,7,minecraft:chiseled_quartz_block,10,minecraft:quartz_pillar,10,minecraft:smooth_quartz_block,10,minecraft:quartz_block,100)
RB(-5,3,7,minecraft:chiseled_quartz_block,10,minecraft:quartz_pillar,10,minecraft:smooth_quartz_block,10,minecraft:quartz_block,100)
RB(-5,4,7,minecraft:chiseled_quartz_block,10,minecraft:quartz_pillar,10,minecraft:smooth_quartz_block,10,minecraft:quartz_block,100)
RB(-5,0,8,minecraft:chiseled_quartz_block,10,minecraft:quartz_pillar,10,minecraft:smooth_quartz_block,10,minecraft:quartz_block,100)
RB(-5,1,8,minecraft:chiseled_quartz_block,10,minecraft:quartz_pillar,10,minecraft:smooth_quartz_block,10,minecraft:quartz_block,100)
RB(-5,2,8,minecraft:chiseled_quartz_block,10,minecraft:quartz_pillar,10,minecraft:smooth_quartz_block,10,minecraft:quartz_block,100)
RB(-5,3,8,minecraft:chiseled_quartz_block,10,minecraft:quartz_pillar,10,minecraft:smooth_quartz_block,10,minecraft:quartz_block,100)
RB(-5,0,9,minecraft:chiseled_quartz_block,10,minecraft:quartz_pillar,10,minecraft:smooth_quartz_block,10,minecraft:quartz_block,100)
RB(-5,1,9,minecraft:chiseled_quartz_block,10,minecraft:quartz_pillar,10,minecraft:smooth_quartz_block,10,minecraft:quartz_block,100)
RB(-5,2,9,minecraft:chiseled_quartz_block,10,minecraft:quartz_pillar,10,minecraft:smooth_quartz_block,10,minecraft:quartz_block,100)
RB(-5,3,9,minecraft:chiseled_quartz_block,10,minecraft:quartz_pillar,10,minecraft:smooth_quartz_block,10,minecraft:quartz_block,100)
RB(-5,0,10,minecraft:chiseled_quartz_block,10,minecraft:quartz_pillar,10,minecraft:smooth_quartz_block,10,minecraft:quartz_block,100)
RB(-5,1,10,minecraft:chiseled_quartz_block,10,minecraft:quartz_pillar,10,minecraft:smooth_quartz_block,10,minecraft:quartz_block,100)
RB(-5,0,11,minecraft:chiseled_quartz_block,10,minecraft:quartz_pillar,10,minecraft:smooth_quartz_block,10,minecraft:quartz_block,100)
RB(-4,7,-11,minecraft:chiseled_quartz_block,10,minecraft:quartz_pillar,10,minecraft:smooth_quartz_block,10,minecraft:quartz_block,100)
RB(-4,6,-10,minecraft:chiseled_quartz_block,10,minecraft:quartz_pillar,10,minecraft:smooth_quartz_block,10,minecraft:quartz_block,100)
RB(-4,7,-10,minecraft:chiseled_quartz_block,10,minecraft:quartz_pillar,10,minecraft:smooth_quartz_block,10,minecraft:quartz_block,100)
RB(-4,8,-10,minecraft:chiseled_quartz_block,10,minecraft:quartz_pillar,10,minecraft:smooth_quartz_block,10,minecraft:quartz_block,100)
RB(-4,5,-9,minecraft:chiseled_quartz_block,10,minecraft:quartz_pillar,10,minecraft:smooth_quartz_block,10,minecraft:quartz_block,100)
RB(-4,6,-9,minecraft:chiseled_quartz_block,10,minecraft:quartz_pillar,10,minecraft:smooth_quartz_block,10,minecraft:quartz_block,100)
RB(-4,7,-9,minecraft:chiseled_quartz_block,10,minecraft:quartz_pillar,10,minecraft:smooth_quartz_block,10,minecraft:quartz_block,100)
RB(-4,8,-9,minecraft:chiseled_quartz_block,10,minecraft:quartz_pillar,10,minecraft:smooth_quartz_block,10,minecraft:quartz_block,100)
RB(-4,9,-9,minecraft:chiseled_quartz_block,10,minecraft:quartz_pillar,10,minecraft:smooth_quartz_block,10,minecraft:quartz_block,100)
RB(-4,4,-8,minecraft:chiseled_quartz_block,10,minecraft:quartz_pillar,10,minecraft:smooth_quartz_block,10,minecraft:quartz_block,100)
RB(-4,5,-8,minecraft:chiseled_quartz_block,10,minecraft:quartz_pillar,10,minecraft:smooth_quartz_block,10,minecraft:quartz_block,100)
RB(-4,6,-8,minecraft:chiseled_quartz_block,10,minecraft:quartz_pillar,10,minecraft:smooth_quartz_block,10,minecraft:quartz_block,100)
RB(-4,7,-8,minecraft:chiseled_quartz_block,10,minecraft:quartz_pillar,10,minecraft:smooth_quartz_block,10,minecraft:quartz_block,100)
RB(-4,8,-8,minecraft:chiseled_quartz_block,10,minecraft:quartz_pillar,10,minecraft:smooth_quartz_block,10,minecraft:quartz_block,100)
RB(-4,9,-8,minecraft:chiseled_quartz_block,10,minecraft:quartz_pillar,10,minecraft:smooth_quartz_block,10,minecraft:quartz_block,100)
RB(-4,3,-7,minecraft:chiseled_quartz_block,10,minecraft:quartz_pillar,10,minecraft:smooth_quartz_block,10,minecraft:quartz_block,100)
RB(-4,4,-7,minecraft:chiseled_quartz_block,10,minecraft:quartz_pillar,10,minecraft:smooth_quartz_block,10,minecraft:quartz_block,100)
RB(-4,5,-7,minecraft:chiseled_quartz_block,10,minecraft:quartz_pillar,10,minecraft:smooth_quartz_block,10,minecraft:quartz_block,100)
RB(-4,6,-7,minecraft:chiseled_quartz_block,10,minecraft:quartz_pillar,10,minecraft:smooth_quartz_block,10,minecraft:quartz_block,100)
RB(-4,7,-7,minecraft:chiseled_quartz_block,10,minecraft:quartz_pillar,10,minecraft:smooth_quartz_block,10,minecraft:quartz_block,100)
RB(-4,8,-7,minecraft:chiseled_quartz_block,10,minecraft:quartz_pillar,10,minecraft:smooth_quartz_block,10,minecraft:quartz_block,100)
RB(-4,9,-7,minecraft:chiseled_quartz_block,10,minecraft:quartz_pillar,10,minecraft:smooth_quartz_block,10,minecraft:quartz_block,100)
RB(-4,2,-6,minecraft:chiseled_quartz_block,10,minecraft:quartz_pillar,10,minecraft:smooth_quartz_block,10,minecraft:quartz_block,100)
RB(-4,3,-6,minecraft:chiseled_quartz_block,10,minecraft:quartz_pillar,10,minecraft:smooth_quartz_block,10,minecraft:quartz_block,100)
RB(-4,4,-6,minecraft:chiseled_quartz_block,10,minecraft:quartz_pillar,10,minecraft:smooth_quartz_block,10,minecraft:quartz_block,100)
RB(-4,5,-6,minecraft:chiseled_quartz_block,10,minecraft:quartz_pillar,10,minecraft:smooth_quartz_block,10,minecraft:quartz_block,100)
RB(-4,6,-6,minecraft:chiseled_quartz_block,10,minecraft:quartz_pillar,10,minecraft:smooth_quartz_block,10,minecraft:quartz_block,100)
RB(-4,7,-6,minecraft:chiseled_quartz_block,10,minecraft:quartz_pillar,10,minecraft:smooth_quartz_block,10,minecraft:quartz_block,100)
RB(-4,8,-6,minecraft:chiseled_quartz_block,10,minecraft:quartz_pillar,10,minecraft:smooth_quartz_block,10,minecraft:quartz_block,100)
RB(-4,9,-6,minecraft:chiseled_quartz_block,10,minecraft:quartz_pillar,10,minecraft:smooth_quartz_block,10,minecraft:quartz_block,100)
RB(-4,1,-5,minecraft:chiseled_quartz_block,10,minecraft:quartz_pillar,10,minecraft:smooth_quartz_block,10,minecraft:quartz_block,100)
RB(-4,2,-5,minecraft:chiseled_quartz_block,10,minecraft:quartz_pillar,10,minecraft:smooth_quartz_block,10,minecraft:quartz_block,100)
RB(-4,3,-5,minecraft:chiseled_quartz_block,10,minecraft:quartz_pillar,10,minecraft:smooth_quartz_block,10,minecraft:quartz_block,100)
RB(-4,4,-5,minecraft:chiseled_quartz_block,10,minecraft:quartz_pillar,10,minecraft:smooth_quartz_block,10,minecraft:quartz_block,100)
RB(-4,5,-5,minecraft:chiseled_quartz_block,10,minecraft:quartz_pillar,10,minecraft:smooth_quartz_block,10,minecraft:quartz_block,100)
RB(-4,6,-5,minecraft:chiseled_quartz_block,10,minecraft:quartz_pillar,10,minecraft:smooth_quartz_block,10,minecraft:quartz_block,100)
RB(-4,7,-5,minecraft:chiseled_quartz_block,10,minecraft:quartz_pillar,10,minecraft:smooth_quartz_block,10,minecraft:quartz_block,100)
RB(-4,8,-5,minecraft:chiseled_quartz_block,10,minecraft:quartz_pillar,10,minecraft:smooth_quartz_block,10,minecraft:quartz_block,100)
RB(-4,0,-4,minecraft:chiseled_quartz_block,10,minecraft:quartz_pillar,10,minecraft:smooth_quartz_block,10,minecraft:quartz_block,100)
RB(-4,1,-4,minecraft:chiseled_quartz_block,10,minecraft:quartz_pillar,10,minecraft:smooth_quartz_block,10,minecraft:quartz_block,100)
RB(-4,2,-4,minecraft:chiseled_quartz_block,10,minecraft:quartz_pillar,10,minecraft:smooth_quartz_block,10,minecraft:quartz_block,100)
RB(-4,3,-4,minecraft:chiseled_quartz_block,10,minecraft:quartz_pillar,10,minecraft:smooth_quartz_block,10,minecraft:quartz_block,100)
RB(-4,4,-4,minecraft:chiseled_quartz_block,10,minecraft:quartz_pillar,10,minecraft:smooth_quartz_block,10,minecraft:quartz_block,100)
RB(-4,5,-4,minecraft:chiseled_quartz_block,10,minecraft:quartz_pillar,10,minecraft:smooth_quartz_block,10,minecraft:quartz_block,100)
RB(-4,6,-4,minecraft:chiseled_quartz_block,10,minecraft:quartz_pillar,10,minecraft:smooth_quartz_block,10,minecraft:quartz_block,100)
RB(-4,7,-4,minecraft:chiseled_quartz_block,10,minecraft:quartz_pillar,10,minecraft:smooth_quartz_block,10,minecraft:quartz_block,100)
RB(-4,8,-4,minecraft:chiseled_quartz_block,10,minecraft:quartz_pillar,10,minecraft:smooth_quartz_block,10,minecraft:quartz_block,100)
RB(-4,0,-3,minecraft:chiseled_quartz_block,10,minecraft:quartz_pillar,10,minecraft:smooth_quartz_block,10,minecraft:quartz_block,100)
RB(-4,1,-3,minecraft:chiseled_quartz_block,10,minecraft:quartz_pillar,10,minecraft:smooth_quartz_block,10,minecraft:quartz_block,100)
RB(-4,2,-3,minecraft:chiseled_quartz_block,10,minecraft:quartz_pillar,10,minecraft:smooth_quartz_block,10,minecraft:quartz_block,100)
RB(-4,3,-3,minecraft:chiseled_quartz_block,10,minecraft:quartz_pillar,10,minecraft:smooth_quartz_block,10,minecraft:quartz_block,100)
RB(-4,4,-3,minecraft:chiseled_quartz_block,10,minecraft:quartz_pillar,10,minecraft:smooth_quartz_block,10,minecraft:quartz_block,100)
RB(-4,5,-3,minecraft:chiseled_quartz_block,10,minecraft:quartz_pillar,10,minecraft:smooth_quartz_block,10,minecraft:quartz_block,100)
RB(-4,6,-3,minecraft:chiseled_quartz_block,10,minecraft:quartz_pillar,10,minecraft:smooth_quartz_block,10,minecraft:quartz_block,100)
RB(-4,7,-3,minecraft:chiseled_quartz_block,10,minecraft:quartz_pillar,10,minecraft:smooth_quartz_block,10,minecraft:quartz_block,100)
RB(-4,8,-3,minecraft:chiseled_quartz_block,10,minecraft:quartz_pillar,10,minecraft:smooth_quartz_block,10,minecraft:quartz_block,100)
RB(-4,0,-2,minecraft:chiseled_quartz_block,10,minecraft:quartz_pillar,10,minecraft:smooth_quartz_block,10,minecraft:quartz_block,100)
RB(-4,1,-2,minecraft:chiseled_quartz_block,10,minecraft:quartz_pillar,10,minecraft:smooth_quartz_block,10,minecraft:quartz_block,100)
RB(-4,2,-2,minecraft:chiseled_quartz_block,10,minecraft:quartz_pillar,10,minecraft:smooth_quartz_block,10,minecraft:quartz_block,100)
RB(-4,3,-2,minecraft:chiseled_quartz_block,10,minecraft:quartz_pillar,10,minecraft:smooth_quartz_block,10,minecraft:quartz_block,100)
RB(-4,4,-2,minecraft:chiseled_quartz_block,10,minecraft:quartz_pillar,10,minecraft:smooth_quartz_block,10,minecraft:quartz_block,100)
RB(-4,5,-2,minecraft:chiseled_quartz_block,10,minecraft:quartz_pillar,10,minecraft:smooth_quartz_block,10,minecraft:quartz_block,100)
RB(-4,6,-2,minecraft:chiseled_quartz_block,10,minecraft:quartz_pillar,10,minecraft:smooth_quartz_block,10,minecraft:quartz_block,100)
RB(-4,7,-2,minecraft:chiseled_quartz_block,10,minecraft:quartz_pillar,10,minecraft:smooth_quartz_block,10,minecraft:quartz_block,100)
RB(-4,0,-1,minecraft:chiseled_quartz_block,10,minecraft:quartz_pillar,10,minecraft:smooth_quartz_block,10,minecraft:quartz_block,100)
RB(-4,1,-1,minecraft:chiseled_quartz_block,10,minecraft:quartz_pillar,10,minecraft:smooth_quartz_block,10,minecraft:quartz_block,100)
RB(-4,2,-1,minecraft:chiseled_quartz_block,10,minecraft:quartz_pillar,10,minecraft:smooth_quartz_block,10,minecraft:quartz_block,100)
RB(-4,3,-1,minecraft:chiseled_quartz_block,10,minecraft:quartz_pillar,10,minecraft:smooth_quartz_block,10,minecraft:quartz_block,100)
RB(-4,4,-1,minecraft:chiseled_quartz_block,10,minecraft:quartz_pillar,10,minecraft:smooth_quartz_block,10,minecraft:quartz_block,100)
RB(-4,5,-1,minecraft:chiseled_quartz_block,10,minecraft:quartz_pillar,10,minecraft:smooth_quartz_block,10,minecraft:quartz_block,100)
RB(-4,6,-1,minecraft:chiseled_quartz_block,10,minecraft:quartz_pillar,10,minecraft:smooth_quartz_block,10,minecraft:quartz_block,100)
RB(-4,7,-1,minecraft:chiseled_quartz_block,10,minecraft:quartz_pillar,10,minecraft:smooth_quartz_block,10,minecraft:quartz_block,100)
RB(-4,0,0,minecraft:chiseled_quartz_block,10,minecraft:quartz_pillar,10,minecraft:smooth_quartz_block,10,minecraft:quartz_block,100)
RB(-4,1,0,minecraft:chiseled_quartz_block,10,minecraft:quartz_pillar,10,minecraft:smooth_quartz_block,10,minecraft:quartz_block,100)
RB(-4,2,0,minecraft:chiseled_quartz_block,10,minecraft:quartz_pillar,10,minecraft:smooth_quartz_block,10,minecraft:quartz_block,100)
RB(-4,3,0,minecraft:chiseled_quartz_block,10,minecraft:quartz_pillar,10,minecraft:smooth_quartz_block,10,minecraft:quartz_block,100)
RB(-4,4,0,minecraft:chiseled_quartz_block,10,minecraft:quartz_pillar,10,minecraft:smooth_quartz_block,10,minecraft:quartz_block,100)
RB(-4,5,0,minecraft:chiseled_quartz_block,10,minecraft:quartz_pillar,10,minecraft:smooth_quartz_block,10,minecraft:quartz_block,100)
