Author: Frank

Description: Medium quartz spike

Version: 3

SettingsMode: WriteDisable

IsOTGPlus: false
Tree: true
Frequency: 10
Rarity: 100.0
RotateRandomly: true
SpawnHeight: randomY
SpawnHeightOffset: 0
SpawnHeightVariance: 0
MaxBranchDepth: 10
ExcludedBiomes: All

ExtrudeMode: None
ExtrudeThroughBlocks: minecraft:air

MinHeight: 50
MaxHeight: 65

SourceBlocks: AIR
MaxPercentageOutsideSourceBlock: 60
OutsideSourceBlock: placeAnyway

DoReplaceBlocks: true

RB(-14,19,-14,minecraft:chiseled_quartz_block,10,minecraft:quartz_pillar,10,minecraft:smooth_quartz_block,10,minecraft:quartz_block,100)
RB(-13,16,-13,minecraft:chiseled_quartz_block,10,minecraft:quartz_pillar,10,minecraft:smooth_quartz_block,10,minecraft:quartz_block,100)
RB(-13,17,-13,minecraft:chiseled_quartz_block,10,minecraft:quartz_pillar,10,minecraft:smooth_quartz_block,10,minecraft:quartz_block,100)
RB(-13,18,-13,minecraft:chiseled_quartz_block,10,minecraft:quartz_pillar,10,minecraft:smooth_quartz_block,10,minecraft:quartz_block,100)
RB(-13,15,-12,minecraft:chiseled_quartz_block,10,minecraft:quartz_pillar,10,minecraft:smooth_quartz_block,10,minecraft:quartz_block,100)
RB(-13,16,-12,minecraft:chiseled_quartz_block,10,minecraft:quartz_pillar,10,minecraft:smooth_quartz_block,10,minecraft:quartz_block,100)
RB(-13,17,-12,minecraft:chiseled_quartz_block,10,minecraft:quartz_pillar,10,minecraft:smooth_quartz_block,10,minecraft:quartz_block,100)
RB(-13,15,-11,minecraft:chiseled_quartz_block,10,minecraft:quartz_pillar,10,minecraft:smooth_quartz_block,10,minecraft:quartz_block,100)
RB(-13,16,-11,minecraft:chiseled_quartz_block,10,minecraft:quartz_pillar,10,minecraft:smooth_quartz_block,10,minecraft:quartz_block,100)
RB(-13,15,-10,minecraft:chiseled_quartz_block,10,minecraft:quartz_pillar,10,minecraft:smooth_quartz_block,10,minecraft:quartz_block,100)
RB(-12,17,-13,minecraft:chiseled_quartz_block,10,minecraft:quartz_pillar,10,minecraft:smooth_quartz_block,10,minecraft:quartz_block,100)
RB(-12,13,-12,minecraft:chiseled_quartz_block,10,minecraft:quartz_pillar,10,minecraft:smooth_quartz_block,10,minecraft:quartz_block,100)
RB(-12,14,-12,minecraft:chiseled_quartz_block,10,minecraft:quartz_pillar,10,minecraft:smooth_quartz_block,10,minecraft:quartz_block,100)
RB(-12,15,-12,minecraft:chiseled_quartz_block,10,minecraft:quartz_pillar,10,minecraft:smooth_quartz_block,10,minecraft:quartz_block,100)
RB(-12,16,-12,minecraft:chiseled_quartz_block,10,minecraft:quartz_pillar,10,minecraft:smooth_quartz_block,10,minecraft:quartz_block,100)
RB(-12,17,-12,minecraft:chiseled_quartz_block,10,minecraft:quartz_pillar,10,minecraft:smooth_quartz_block,10,minecraft:quartz_block,100)
RB(-12,12,-11,minecraft:chiseled_quartz_block,10,minecraft:quartz_pillar,10,minecraft:smooth_quartz_block,10,minecraft:quartz_block,100)
RB(-12,13,-11,minecraft:chiseled_quartz_block,10,minecraft:quartz_pillar,10,minecraft:smooth_quartz_block,10,minecraft:quartz_block,100)
RB(-12,14,-11,minecraft:chiseled_quartz_block,10,minecraft:quartz_pillar,10,minecraft:smooth_quartz_block,10,minecraft:quartz_block,100)
RB(-12,15,-11,minecraft:chiseled_quartz_block,10,minecraft:quartz_pillar,10,minecraft:smooth_quartz_block,10,minecraft:quartz_block,100)
RB(-12,16,-11,minecraft:chiseled_quartz_block,10,minecraft:quartz_pillar,10,minecraft:smooth_quartz_block,10,minecraft:quartz_block,100)
RB(-12,11,-10,minecraft:chiseled_quartz_block,10,minecraft:quartz_pillar,10,minecraft:smooth_quartz_block,10,minecraft:quartz_block,100)
RB(-12,12,-10,minecraft:chiseled_quartz_block,10,minecraft:quartz_pillar,10,minecraft:smooth_quartz_block,10,minecraft:quartz_block,100)
RB(-12,13,-10,minecraft:chiseled_quartz_block,10,minecraft:quartz_pillar,10,minecraft:smooth_quartz_block,10,minecraft:quartz_block,100)
RB(-12,14,-10,minecraft:chiseled_quartz_block,10,minecraft:quartz_pillar,10,minecraft:smooth_quartz_block,10,minecraft:quartz_block,100)
RB(-12,15,-10,minecraft:chiseled_quartz_block,10,minecraft:quartz_pillar,10,minecraft:smooth_quartz_block,10,minecraft:quartz_block,100)
RB(-12,16,-10,minecraft:chiseled_quartz_block,10,minecraft:quartz_pillar,10,minecraft:smooth_quartz_block,10,minecraft:quartz_block,100)
RB(-12,11,-9,minecraft:chiseled_quartz_block,10,minecraft:quartz_pillar,10,minecraft:smooth_quartz_block,10,minecraft:quartz_block,100)
RB(-12,12,-9,minecraft:chiseled_quartz_block,10,minecraft:quartz_pillar,10,minecraft:smooth_quartz_block,10,minecraft:quartz_block,100)
RB(-12,13,-9,minecraft:chiseled_quartz_block,10,minecraft:quartz_pillar,10,minecraft:smooth_quartz_block,10,minecraft:quartz_block,100)
RB(-12,14,-9,minecraft:chiseled_quartz_block,10,minecraft:quartz_pillar,10,minecraft:smooth_quartz_block,10,minecraft:quartz_block,100)
RB(-12,15,-9,minecraft:chiseled_quartz_block,10,minecraft:quartz_pillar,10,minecraft:smooth_quartz_block,10,minecraft:quartz_block,100)
RB(-12,10,-8,minecraft:chiseled_quartz_block,10,minecraft:quartz_pillar,10,minecraft:smooth_quartz_block,10,minecraft:quartz_block,100)
RB(-12,11,-8,minecraft:chiseled_quartz_block,10,minecraft:quartz_pillar,10,minecraft:smooth_quartz_block,10,minecraft:quartz_block,100)
RB(-12,12,-8,minecraft:chiseled_quartz_block,10,minecraft:quartz_pillar,10,minecraft:smooth_quartz_block,10,minecraft:quartz_block,100)
RB(-12,13,-8,minecraft:chiseled_quartz_block,10,minecraft:quartz_pillar,10,minecraft:smooth_quartz_block,10,minecraft:quartz_block,100)
RB(-12,14,-8,minecraft:chiseled_quartz_block,10,minecraft:quartz_pillar,10,minecraft:smooth_quartz_block,10,minecraft:quartz_block,100)
RB(-12,11,-7,minecraft:chiseled_quartz_block,10,minecraft:quartz_pillar,10,minecraft:smooth_quartz_block,10,minecraft:quartz_block,100)
RB(-12,12,-7,minecraft:chiseled_quartz_block,10,minecraft:quartz_pillar,10,minecraft:smooth_quartz_block,10,minecraft:quartz_block,100)
RB(-12,13,-7,minecraft:chiseled_quartz_block,10,minecraft:quartz_pillar,10,minecraft:smooth_quartz_block,10,minecraft:quartz_block,100)
RB(-12,11,-6,minecraft:chiseled_quartz_block,10,minecraft:quartz_pillar,10,minecraft:smooth_quartz_block,10,minecraft:quartz_block,100)
RB(-12,12,-6,minecraft:chiseled_quartz_block,10,minecraft:quartz_pillar,10,minecraft:smooth_quartz_block,10,minecraft:quartz_block,100)
RB(-11,14,-12,minecraft:chiseled_quartz_block,10,minecraft:quartz_pillar,10,minecraft:smooth_quartz_block,10,minecraft:quartz_block,100)
RB(-11,15,-12,minecraft:chiseled_quartz_block,10,minecraft:quartz_pillar,10,minecraft:smooth_quartz_block,10,minecraft:quartz_block,100)
RB(-11,16,-12,minecraft:chiseled_quartz_block,10,minecraft:quartz_pillar,10,minecraft:smooth_quartz_block,10,minecraft:quartz_block,100)
RB(-11,10,-11,minecraft:chiseled_quartz_block,10,minecraft:quartz_pillar,10,minecraft:smooth_quartz_block,10,minecraft:quartz_block,100)
RB(-11,11,-11,minecraft:chiseled_quartz_block,10,minecraft:quartz_pillar,10,minecraft:smooth_quartz_block,10,minecraft:quartz_block,100)
RB(-11,12,-11,minecraft:chiseled_quartz_block,10,minecraft:quartz_pillar,10,minecraft:smooth_quartz_block,10,minecraft:quartz_block,100)
RB(-11,13,-11,minecraft:chiseled_quartz_block,10,minecraft:quartz_pillar,10,minecraft:smooth_quartz_block,10,minecraft:quartz_block,100)
RB(-11,14,-11,minecraft:chiseled_quartz_block,10,minecraft:quartz_pillar,10,minecraft:smooth_quartz_block,10,minecraft:quartz_block,100)
RB(-11,15,-11,minecraft:chiseled_quartz_block,10,minecraft:quartz_pillar,10,minecraft:smooth_quartz_block,10,minecraft:quartz_block,100)
RB(-11,16,-11,minecraft:chiseled_quartz_block,10,minecraft:quartz_pillar,10,minecraft:smooth_quartz_block,10,minecraft:quartz_block,100)
RB(-11,8,-10,minecraft:chiseled_quartz_block,10,minecraft:quartz_pillar,10,minecraft:smooth_quartz_block,10,minecraft:quartz_block,100)
RB(-11,9,-10,minecraft:chiseled_quartz_block,10,minecraft:quartz_pillar,10,minecraft:smooth_quartz_block,10,minecraft:quartz_block,100)
RB(-11,10,-10,minecraft:chiseled_quartz_block,10,minecraft:quartz_pillar,10,minecraft:smooth_quartz_block,10,minecraft:quartz_block,100)
RB(-11,11,-10,minecraft:chiseled_quartz_block,10,minecraft:quartz_pillar,10,minecraft:smooth_quartz_block,10,minecraft:quartz_block,100)
RB(-11,12,-10,minecraft:chiseled_quartz_block,10,minecraft:quartz_pillar,10,minecraft:smooth_quartz_block,10,minecraft:quartz_block,100)
RB(-11,13,-10,minecraft:chiseled_quartz_block,10,minecraft:quartz_pillar,10,minecraft:smooth_quartz_block,10,minecraft:quartz_block,100)
RB(-11,14,-10,minecraft:chiseled_quartz_block,10,minecraft:quartz_pillar,10,minecraft:smooth_quartz_block,10,minecraft:quartz_block,100)
RB(-11,15,-10,minecraft:chiseled_quartz_block,10,minecraft:quartz_pillar,10,minecraft:smooth_quartz_block,10,minecraft:quartz_block,100)
RB(-11,16,-10,minecraft:chiseled_quartz_block,10,minecraft:quartz_pillar,10,minecraft:smooth_quartz_block,10,minecraft:quartz_block,100)
RB(-11,7,-9,minecraft:chiseled_quartz_block,10,minecraft:quartz_pillar,10,minecraft:smooth_quartz_block,10,minecraft:quartz_block,100)
RB(-11,8,-9,minecraft:chiseled_quartz_block,10,minecraft:quartz_pillar,10,minecraft:smooth_quartz_block,10,minecraft:quartz_block,100)
RB(-11,9,-9,minecraft:chiseled_quartz_block,10,minecraft:quartz_pillar,10,minecraft:smooth_quartz_block,10,minecraft:quartz_block,100)
RB(-11,10,-9,minecraft:chiseled_quartz_block,10,minecraft:quartz_pillar,10,minecraft:smooth_quartz_block,10,minecraft:quartz_block,100)
RB(-11,11,-9,minecraft:chiseled_quartz_block,10,minecraft:quartz_pillar,10,minecraft:smooth_quartz_block,10,minecraft:quartz_block,100)
RB(-11,12,-9,minecraft:chiseled_quartz_block,10,minecraft:quartz_pillar,10,minecraft:smooth_quartz_block,10,minecraft:quartz_block,100)
RB(-11,13,-9,minecraft:chiseled_quartz_block,10,minecraft:quartz_pillar,10,minecraft:smooth_quartz_block,10,minecraft:quartz_block,100)
RB(-11,14,-9,minecraft:chiseled_quartz_block,10,minecraft:quartz_pillar,10,minecraft:smooth_quartz_block,10,minecraft:quartz_block,100)
RB(-11,15,-9,minecraft:chiseled_quartz_block,10,minecraft:quartz_pillar,10,minecraft:smooth_quartz_block,10,minecraft:quartz_block,100)
RB(-11,7,-8,minecraft:chiseled_quartz_block,10,minecraft:quartz_pillar,10,minecraft:smooth_quartz_block,10,minecraft:quartz_block,100)
RB(-11,8,-8,minecraft:chiseled_quartz_block,10,minecraft:quartz_pillar,10,minecraft:smooth_quartz_block,10,minecraft:quartz_block,100)
RB(-11,9,-8,minecraft:chiseled_quartz_block,10,minecraft:quartz_pillar,10,minecraft:smooth_quartz_block,10,minecraft:quartz_block,100)
RB(-11,10,-8,minecraft:chiseled_quartz_block,10,minecraft:quartz_pillar,10,minecraft:smooth_quartz_block,10,minecraft:quartz_block,100)
RB(-11,11,-8,minecraft:chiseled_quartz_block,10,minecraft:quartz_pillar,10,minecraft:smooth_quartz_block,10,minecraft:quartz_block,100)
RB(-11,12,-8,minecraft:chiseled_quartz_block,10,minecraft:quartz_pillar,10,minecraft:smooth_quartz_block,10,minecraft:quartz_block,100)
RB(-11,13,-8,minecraft:chiseled_quartz_block,10,minecraft:quartz_pillar,10,minecraft:smooth_quartz_block,10,minecraft:quartz_block,100)
RB(-11,14,-8,minecraft:chiseled_quartz_block,10,minecraft:quartz_pillar,10,minecraft:smooth_quartz_block,10,minecraft:quartz_block,100)
RB(-11,6,-7,minecraft:chiseled_quartz_block,10,minecraft:quartz_pillar,10,minecraft:smooth_quartz_block,10,minecraft:quartz_block,100)
RB(-11,7,-7,minecraft:chiseled_quartz_block,10,minecraft:quartz_pillar,10,minecraft:smooth_quartz_block,10,minecraft:quartz_block,100)
RB(-11,8,-7,minecraft:chiseled_quartz_block,10,minecraft:quartz_pillar,10,minecraft:smooth_quartz_block,10,minecraft:quartz_block,100)
RB(-11,9,-7,minecraft:chiseled_quartz_block,10,minecraft:quartz_pillar,10,minecraft:smooth_quartz_block,10,minecraft:quartz_block,100)
RB(-11,10,-7,minecraft:chiseled_quartz_block,10,minecraft:quartz_pillar,10,minecraft:smooth_quartz_block,10,minecraft:quartz_block,100)
RB(-11,11,-7,minecraft:chiseled_quartz_block,10,minecraft:quartz_pillar,10,minecraft:smooth_quartz_block,10,minecraft:quartz_block,100)
RB(-11,12,-7,minecraft:chiseled_quartz_block,10,minecraft:quartz_pillar,10,minecraft:smooth_quartz_block,10,minecraft:quartz_block,100)
RB(-11,13,-7,minecraft:chiseled_quartz_block,10,minecraft:quartz_pillar,10,minecraft:smooth_quartz_block,10,minecraft:quartz_block,100)
RB(-11,6,-6,minecraft:chiseled_quartz_block,10,minecraft:quartz_pillar,10,minecraft:smooth_quartz_block,10,minecraft:quartz_block,100)
RB(-11,7,-6,minecraft:chiseled_quartz_block,10,minecraft:quartz_pillar,10,minecraft:smooth_quartz_block,10,minecraft:quartz_block,100)
RB(-11,8,-6,minecraft:chiseled_quartz_block,10,minecraft:quartz_pillar,10,minecraft:smooth_quartz_block,10,minecraft:quartz_block,100)
RB(-11,9,-6,minecraft:chiseled_quartz_block,10,minecraft:quartz_pillar,10,minecraft:smooth_quartz_block,10,minecraft:quartz_block,100)
RB(-11,10,-6,minecraft:chiseled_quartz_block,10,minecraft:quartz_pillar,10,minecraft:smooth_quartz_block,10,minecraft:quartz_block,100)
RB(-11,11,-6,minecraft:chiseled_quartz_block,10,minecraft:quartz_pillar,10,minecraft:smooth_quartz_block,10,minecraft:quartz_block,100)
RB(-11,12,-6,minecraft:chiseled_quartz_block,10,minecraft:quartz_pillar,10,minecraft:smooth_quartz_block,10,minecraft:quartz_block,100)
RB(-11,5,-5,minecraft:chiseled_quartz_block,10,minecraft:quartz_pillar,10,minecraft:smooth_quartz_block,10,minecraft:quartz_block,100)
RB(-11,6,-5,minecraft:chiseled_quartz_block,10,minecraft:quartz_pillar,10,minecraft:smooth_quartz_block,10,minecraft:quartz_block,100)
RB(-11,7,-5,minecraft:chiseled_quartz_block,10,minecraft:quartz_pillar,10,minecraft:smooth_quartz_block,10,minecraft:quartz_block,100)
RB(-11,8,-5,minecraft:chiseled_quartz_block,10,minecraft:quartz_pillar,10,minecraft:smooth_quartz_block,10,minecraft:quartz_block,100)
RB(-11,9,-5,minecraft:chiseled_quartz_block,10,minecraft:quartz_pillar,10,minecraft:smooth_quartz_block,10,minecraft:quartz_block,100)
RB(-11,10,-5,minecraft:chiseled_quartz_block,10,minecraft:quartz_pillar,10,minecraft:smooth_quartz_block,10,minecraft:quartz_block,100)
RB(-11,11,-5,minecraft:chiseled_quartz_block,10,minecraft:quartz_pillar,10,minecraft:smooth_quartz_block,10,minecraft:quartz_block,100)
RB(-11,6,-4,minecraft:chiseled_quartz_block,10,minecraft:quartz_pillar,10,minecraft:smooth_quartz_block,10,minecraft:quartz_block,100)
RB(-11,7,-4,minecraft:chiseled_quartz_block,10,minecraft:quartz_pillar,10,minecraft:smooth_quartz_block,10,minecraft:quartz_block,100)
RB(-11,8,-4,minecraft:chiseled_quartz_block,10,minecraft:quartz_pillar,10,minecraft:smooth_quartz_block,10,minecraft:quartz_block,100)
RB(-11,9,-4,minecraft:chiseled_quartz_block,10,minecraft:quartz_pillar,10,minecraft:smooth_quartz_block,10,minecraft:quartz_block,100)
RB(-11,10,-4,minecraft:chiseled_quartz_block,10,minecraft:quartz_pillar,10,minecraft:smooth_quartz_block,10,minecraft:quartz_block,100)
RB(-11,7,-3,minecraft:chiseled_quartz_block,10,minecraft:quartz_pillar,10,minecraft:smooth_quartz_block,10,minecraft:quartz_block,100)
RB(-11,8,-3,minecraft:chiseled_quartz_block,10,minecraft:quartz_pillar,10,minecraft:smooth_quartz_block,10,minecraft:quartz_block,100)
RB(-11,9,-3,minecraft:chiseled_quartz_block,10,minecraft:quartz_pillar,10,minecraft:smooth_quartz_block,10,minecraft:quartz_block,100)
RB(-11,7,-2,minecraft:chiseled_quartz_block,10,minecraft:quartz_pillar,10,minecraft:smooth_quartz_block,10,minecraft:quartz_block,100)
RB(-11,8,-2,minecraft:chiseled_quartz_block,10,minecraft:quartz_pillar,10,minecraft:smooth_quartz_block,10,minecraft:quartz_block,100)
RB(-10,15,-12,minecraft:chiseled_quartz_block,10,minecraft:quartz_pillar,10,minecraft:smooth_quartz_block,10,minecraft:quartz_block,100)
RB(-10,16,-12,minecraft:chiseled_quartz_block,10,minecraft:quartz_pillar,10,minecraft:smooth_quartz_block,10,minecraft:quartz_block,100)
RB(-10,11,-11,minecraft:chiseled_quartz_block,10,minecraft:quartz_pillar,10,minecraft:smooth_quartz_block,10,minecraft:quartz_block,100)
RB(-10,12,-11,minecraft:chiseled_quartz_block,10,minecraft:quartz_pillar,10,minecraft:smooth_quartz_block,10,minecraft:quartz_block,100)
RB(-10,13,-11,minecraft:chiseled_quartz_block,10,minecraft:quartz_pillar,10,minecraft:smooth_quartz_block,10,minecraft:quartz_block,100)
RB(-10,14,-11,minecraft:chiseled_quartz_block,10,minecraft:quartz_pillar,10,minecraft:smooth_quartz_block,10,minecraft:quartz_block,100)
RB(-10,15,-11,minecraft:chiseled_quartz_block,10,minecraft:quartz_pillar,10,minecraft:smooth_quartz_block,10,minecraft:quartz_block,100)
RB(-10,16,-11,minecraft:chiseled_quartz_block,10,minecraft:quartz_pillar,10,minecraft:smooth_quartz_block,10,minecraft:quartz_block,100)
RB(-10,7,-10,minecraft:chiseled_quartz_block,10,minecraft:quartz_pillar,10,minecraft:smooth_quartz_block,10,minecraft:quartz_block,100)
RB(-10,8,-10,minecraft:chiseled_quartz_block,10,minecraft:quartz_pillar,10,minecraft:smooth_quartz_block,10,minecraft:quartz_block,100)
RB(-10,9,-10,minecraft:chiseled_quartz_block,10,minecraft:quartz_pillar,10,minecraft:smooth_quartz_block,10,minecraft:quartz_block,100)
RB(-10,10,-10,minecraft:chiseled_quartz_block,10,minecraft:quartz_pillar,10,minecraft:smooth_quartz_block,10,minecraft:quartz_block,100)
RB(-10,11,-10,minecraft:chiseled_quartz_block,10,minecraft:quartz_pillar,10,minecraft:smooth_quartz_block,10,minecraft:quartz_block,100)
RB(-10,12,-10,minecraft:chiseled_quartz_block,10,minecraft:quartz_pillar,10,minecraft:smooth_quartz_block,10,minecraft:quartz_block,100)
RB(-10,13,-10,minecraft:chiseled_quartz_block,10,minecraft:quartz_pillar,10,minecraft:smooth_quartz_block,10,minecraft:quartz_block,100)
RB(-10,14,-10,minecraft:chiseled_quartz_block,10,minecraft:quartz_pillar,10,minecraft:smooth_quartz_block,10,minecraft:quartz_block,100)
RB(-10,15,-10,minecraft:chiseled_quartz_block,10,minecraft:quartz_pillar,10,minecraft:smooth_quartz_block,10,minecraft:quartz_block,100)
RB(-10,4,-9,minecraft:chiseled_quartz_block,10,minecraft:quartz_pillar,10,minecraft:smooth_quartz_block,10,minecraft:quartz_block,100)
RB(-10,5,-9,minecraft:chiseled_quartz_block,10,minecraft:quartz_pillar,10,minecraft:smooth_quartz_block,10,minecraft:quartz_block,100)
RB(-10,6,-9,minecraft:chiseled_quartz_block,10,minecraft:quartz_pillar,10,minecraft:smooth_quartz_block,10,minecraft:quartz_block,100)
RB(-10,7,-9,minecraft:chiseled_quartz_block,10,minecraft:quartz_pillar,10,minecraft:smooth_quartz_block,10,minecraft:quartz_block,100)
RB(-10,8,-9,minecraft:chiseled_quartz_block,10,minecraft:quartz_pillar,10,minecraft:smooth_quartz_block,10,minecraft:quartz_block,100)
RB(-10,9,-9,minecraft:chiseled_quartz_block,10,minecraft:quartz_pillar,10,minecraft:smooth_quartz_block,10,minecraft:quartz_block,100)
RB(-10,10,-9,minecraft:chiseled_quartz_block,10,minecraft:quartz_pillar,10,minecraft:smooth_quartz_block,10,minecraft:quartz_block,100)
RB(-10,11,-9,minecraft:chiseled_quartz_block,10,minecraft:quartz_pillar,10,minecraft:smooth_quartz_block,10,minecraft:quartz_block,100)
RB(-10,12,-9,minecraft:chiseled_quartz_block,10,minecraft:quartz_pillar,10,minecraft:smooth_quartz_block,10,minecraft:quartz_block,100)
RB(-10,13,-9,minecraft:chiseled_quartz_block,10,minecraft:quartz_pillar,10,minecraft:smooth_quartz_block,10,minecraft:quartz_block,100)
RB(-10,14,-9,minecraft:chiseled_quartz_block,10,minecraft:quartz_pillar,10,minecraft:smooth_quartz_block,10,minecraft:quartz_block,100)
RB(-10,15,-9,minecraft:chiseled_quartz_block,10,minecraft:quartz_pillar,10,minecraft:smooth_quartz_block,10,minecraft:quartz_block,100)
RB(-10,4,-8,minecraft:chiseled_quartz_block,10,minecraft:quartz_pillar,10,minecraft:smooth_quartz_block,10,minecraft:quartz_block,100)
RB(-10,5,-8,minecraft:chiseled_quartz_block,10,minecraft:quartz_pillar,10,minecraft:smooth_quartz_block,10,minecraft:quartz_block,100)
RB(-10,6,-8,minecraft:chiseled_quartz_block,10,minecraft:quartz_pillar,10,minecraft:smooth_quartz_block,10,minecraft:quartz_block,100)
RB(-10,7,-8,minecraft:chiseled_quartz_block,10,minecraft:quartz_pillar,10,minecraft:smooth_quartz_block,10,minecraft:quartz_block,100)
RB(-10,8,-8,minecraft:chiseled_quartz_block,10,minecraft:quartz_pillar,10,minecraft:smooth_quartz_block,10,minecraft:quartz_block,100)
RB(-10,9,-8,minecraft:chiseled_quartz_block,10,minecraft:quartz_pillar,10,minecraft:smooth_quartz_block,10,minecraft:quartz_block,100)
RB(-10,10,-8,minecraft:chiseled_quartz_block,10,minecraft:quartz_pillar,10,minecraft:smooth_quartz_block,10,minecraft:quartz_block,100)
RB(-10,11,-8,minecraft:chiseled_quartz_block,10,minecraft:quartz_pillar,10,minecraft:smooth_quartz_block,10,minecraft:quartz_block,100)
RB(-10,12,-8,minecraft:chiseled_quartz_block,10,minecraft:quartz_pillar,10,minecraft:smooth_quartz_block,10,minecraft:quartz_block,100)
RB(-10,13,-8,minecraft:chiseled_quartz_block,10,minecraft:quartz_pillar,10,minecraft:smooth_quartz_block,10,minecraft:quartz_block,100)
RB(-10,14,-8,minecraft:chiseled_quartz_block,10,minecraft:quartz_pillar,10,minecraft:smooth_quartz_block,10,minecraft:quartz_block,100)
RB(-10,3,-7,minecraft:chiseled_quartz_block,10,minecraft:quartz_pillar,10,minecraft:smooth_quartz_block,10,minecraft:quartz_block,100)
RB(-10,4,-7,minecraft:chiseled_quartz_block,10,minecraft:quartz_pillar,10,minecraft:smooth_quartz_block,10,minecraft:quartz_block,100)
RB(-10,5,-7,minecraft:chiseled_quartz_block,10,minecraft:quartz_pillar,10,minecraft:smooth_quartz_block,10,minecraft:quartz_block,100)
RB(-10,6,-7,minecraft:chiseled_quartz_block,10,minecraft:quartz_pillar,10,minecraft:smooth_quartz_block,10,minecraft:quartz_block,100)
RB(-10,7,-7,minecraft:chiseled_quartz_block,10,minecraft:quartz_pillar,10,minecraft:smooth_quartz_block,10,minecraft:quartz_block,100)
RB(-10,8,-7,minecraft:chiseled_quartz_block,10,minecraft:quartz_pillar,10,minecraft:smooth_quartz_block,10,minecraft:quartz_block,100)
RB(-10,9,-7,minecraft:chiseled_quartz_block,10,minecraft:quartz_pillar,10,minecraft:smooth_quartz_block,10,minecraft:quartz_block,100)
RB(-10,10,-7,minecraft:chiseled_quartz_block,10,minecraft:quartz_pillar,10,minecraft:smooth_quartz_block,10,minecraft:quartz_block,100)
RB(-10,11,-7,minecraft:chiseled_quartz_block,10,minecraft:quartz_pillar,10,minecraft:smooth_quartz_block,10,minecraft:quartz_block,100)
RB(-10,12,-7,minecraft:chiseled_quartz_block,10,minecraft:quartz_pillar,10,minecraft:smooth_quartz_block,10,minecraft:quartz_block,100)
RB(-10,13,-7,minecraft:chiseled_quartz_block,10,minecraft:quartz_pillar,10,minecraft:smooth_quartz_block,10,minecraft:quartz_block,100)
RB(-10,14,-7,minecraft:chiseled_quartz_block,10,minecraft:quartz_pillar,10,minecraft:smooth_quartz_block,10,minecraft:quartz_block,100)
RB(-10,3,-6,minecraft:chiseled_quartz_block,10,minecraft:quartz_pillar,10,minecraft:smooth_quartz_block,10,minecraft:quartz_block,100)
RB(-10,4,-6,minecraft:chiseled_quartz_block,10,minecraft:quartz_pillar,10,minecraft:smooth_quartz_block,10,minecraft:quartz_block,100)
RB(-10,5,-6,minecraft:chiseled_quartz_block,10,minecraft:quartz_pillar,10,minecraft:smooth_quartz_block,10,minecraft:quartz_block,100)
RB(-10,6,-6,minecraft:chiseled_quartz_block,10,minecraft:quartz_pillar,10,minecraft:smooth_quartz_block,10,minecraft:quartz_block,100)
RB(-10,7,-6,minecraft:chiseled_quartz_block,10,minecraft:quartz_pillar,10,minecraft:smooth_quartz_block,10,minecraft:quartz_block,100)
RB(-10,8,-6,minecraft:chiseled_quartz_block,10,minecraft:quartz_pillar,10,minecraft:smooth_quartz_block,10,minecraft:quartz_block,100)
RB(-10,9,-6,minecraft:chiseled_quartz_block,10,minecraft:quartz_pillar,10,minecraft:smooth_quartz_block,10,minecraft:quartz_block,100)
RB(-10,10,-6,minecraft:chiseled_quartz_block,10,minecraft:quartz_pillar,10,minecraft:smooth_quartz_block,10,minecraft:quartz_block,100)
RB(-10,11,-6,minecraft:chiseled_quartz_block,10,minecraft:quartz_pillar,10,minecraft:smooth_quartz_block,10,minecraft:quartz_block,100)
RB(-10,12,-6,minecraft:chiseled_quartz_block,10,minecraft:quartz_pillar,10,minecraft:smooth_quartz_block,10,minecraft:quartz_block,100)
RB(-10,13,-6,minecraft:chiseled_quartz_block,10,minecraft:quartz_pillar,10,minecraft:smooth_quartz_block,10,minecraft:quartz_block,100)
RB(-10,2,-5,minecraft:chiseled_quartz_block,10,minecraft:quartz_pillar,10,minecraft:smooth_quartz_block,10,minecraft:quartz_block,100)
RB(-10,3,-5,minecraft:chiseled_quartz_block,10,minecraft:quartz_pillar,10,minecraft:smooth_quartz_block,10,minecraft:quartz_block,100)
RB(-10,4,-5,minecraft:chiseled_quartz_block,10,minecraft:quartz_pillar,10,minecraft:smooth_quartz_block,10,minecraft:quartz_block,100)
RB(-10,5,-5,minecraft:chiseled_quartz_block,10,minecraft:quartz_pillar,10,minecraft:smooth_quartz_block,10,minecraft:quartz_block,100)
RB(-10,6,-5,minecraft:chiseled_quartz_block,10,minecraft:quartz_pillar,10,minecraft:smooth_quartz_block,10,minecraft:quartz_block,100)
RB(-10,7,-5,minecraft:chiseled_quartz_block,10,minecraft:quartz_pillar,10,minecraft:smooth_quartz_block,10,minecraft:quartz_block,100)
RB(-10,8,-5,minecraft:chiseled_quartz_block,10,minecraft:quartz_pillar,10,minecraft:smooth_quartz_block,10,minecraft:quartz_block,100)
RB(-10,9,-5,minecraft:chiseled_quartz_block,10,minecraft:quartz_pillar,10,minecraft:smooth_quartz_block,10,minecraft:quartz_block,100)
RB(-10,10,-5,minecraft:chiseled_quartz_block,10,minecraft:quartz_pillar,10,minecraft:smooth_quartz_block,10,minecraft:quartz_block,100)
RB(-10,11,-5,minecraft:chiseled_quartz_block,10,minecraft:quartz_pillar,10,minecraft:smooth_quartz_block,10,minecraft:quartz_block,100)
RB(-10,12,-5,minecraft:chiseled_quartz_block,10,minecraft:quartz_pillar,10,minecraft:smooth_quartz_block,10,minecraft:quartz_block,100)
RB(-10,2,-4,minecraft:chiseled_quartz_block,10,minecraft:quartz_pillar,10,minecraft:smooth_quartz_block,10,minecraft:quartz_block,100)
RB(-10,3,-4,minecraft:chiseled_quartz_block,10,minecraft:quartz_pillar,10,minecraft:smooth_quartz_block,10,minecraft:quartz_block,100)
RB(-10,4,-4,minecraft:chiseled_quartz_block,10,minecraft:quartz_pillar,10,minecraft:smooth_quartz_block,10,minecraft:quartz_block,100)
RB(-10,5,-4,minecraft:chiseled_quartz_block,10,minecraft:quartz_pillar,10,minecraft:smooth_quartz_block,10,minecraft:quartz_block,100)
RB(-10,6,-4,minecraft:chiseled_quartz_block,10,minecraft:quartz_pillar,10,minecraft:smooth_quartz_block,10,minecraft:quartz_block,100)
RB(-10,7,-4,minecraft:chiseled_quartz_block,10,minecraft:quartz_pillar,10,minecraft:smooth_quartz_block,10,minecraft:quartz_block,100)
RB(-10,8,-4,minecraft:chiseled_quartz_block,10,minecraft:quartz_pillar,10,minecraft:smooth_quartz_block,10,minecraft:quartz_block,100)
RB(-10,9,-4,minecraft:chiseled_quartz_block,10,minecraft:quartz_pillar,10,minecraft:smooth_quartz_block,10,minecraft:quartz_block,100)
RB(-10,10,-4,minecraft:chiseled_quartz_block,10,minecraft:quartz_pillar,10,minecraft:smooth_quartz_block,10,minecraft:quartz_block,100)
RB(-10,11,-4,minecraft:chiseled_quartz_block,10,minecraft:quartz_pillar,10,minecraft:smooth_quartz_block,10,minecraft:quartz_block,100)
RB(-10,1,-3,minecraft:chiseled_quartz_block,10,minecraft:quartz_pillar,10,minecraft:smooth_quartz_block,10,minecraft:quartz_block,100)
RB(-10,2,-3,minecraft:chiseled_quartz_block,10,minecraft:quartz_pillar,10,minecraft:smooth_quartz_block,10,minecraft:quartz_block,100)
RB(-10,3,-3,minecraft:chiseled_quartz_block,10,minecraft:quartz_pillar,10,minecraft:smooth_quartz_block,10,minecraft:quartz_block,100)
RB(-10,4,-3,minecraft:chiseled_quartz_block,10,minecraft:quartz_pillar,10,minecraft:smooth_quartz_block,10,minecraft:quartz_block,100)
RB(-10,5,-3,minecraft:chiseled_quartz_block,10,minecraft:quartz_pillar,10,minecraft:smooth_quartz_block,10,minecraft:quartz_block,100)
RB(-10,6,-3,minecraft:chiseled_quartz_block,10,minecraft:quartz_pillar,10,minecraft:smooth_quartz_block,10,minecraft:quartz_block,100)
RB(-10,7,-3,minecraft:chiseled_quartz_block,10,minecraft:quartz_pillar,10,minecraft:smooth_quartz_block,10,minecraft:quartz_block,100)
RB(-10,8,-3,minecraft:chiseled_quartz_block,10,minecraft:quartz_pillar,10,minecraft:smooth_quartz_block,10,minecraft:quartz_block,100)
RB(-10,9,-3,minecraft:chiseled_quartz_block,10,minecraft:quartz_pillar,10,minecraft:smooth_quartz_block,10,minecraft:quartz_block,100)
RB(-10,10,-3,minecraft:chiseled_quartz_block,10,minecraft:quartz_pillar,10,minecraft:smooth_quartz_block,10,minecraft:quartz_block,100)
RB(-10,0,-2,minecraft:chiseled_quartz_block,10,minecraft:quartz_pillar,10,minecraft:smooth_quartz_block,10,minecraft:quartz_block,100)
RB(-10,1,-2,minecraft:chiseled_quartz_block,10,minecraft:quartz_pillar,10,minecraft:smooth_quartz_block,10,minecraft:quartz_block,100)
RB(-10,2,-2,minecraft:chiseled_quartz_block,10,minecraft:quartz_pillar,10,minecraft:smooth_quartz_block,10,minecraft:quartz_block,100)
RB(-10,3,-2,minecraft:chiseled_quartz_block,10,minecraft:quartz_pillar,10,minecraft:smooth_quartz_block,10,minecraft:quartz_block,100)
RB(-10,4,-2,minecraft:chiseled_quartz_block,10,minecraft:quartz_pillar,10,minecraft:smooth_quartz_block,10,minecraft:quartz_block,100)
RB(-10,5,-2,minecraft:chiseled_quartz_block,10,minecraft:quartz_pillar,10,minecraft:smooth_quartz_block,10,minecraft:quartz_block,100)
RB(-10,6,-2,minecraft:chiseled_quartz_block,10,minecraft:quartz_pillar,10,minecraft:smooth_quartz_block,10,minecraft:quartz_block,100)
RB(-10,7,-2,minecraft:chiseled_quartz_block,10,minecraft:quartz_pillar,10,minecraft:smooth_quartz_block,10,minecraft:quartz_block,100)
RB(-10,8,-2,minecraft:chiseled_quartz_block,10,minecraft:quartz_pillar,10,minecraft:smooth_quartz_block,10,minecraft:quartz_block,100)
RB(-10,9,-2,minecraft:chiseled_quartz_block,10,minecraft:quartz_pillar,10,minecraft:smooth_quartz_block,10,minecraft:quartz_block,100)
RB(-10,1,-1,minecraft:chiseled_quartz_block,10,minecraft:quartz_pillar,10,minecraft:smooth_quartz_block,10,minecraft:quartz_block,100)
RB(-10,2,-1,minecraft:chiseled_quartz_block,10,minecraft:quartz_pillar,10,minecraft:smooth_quartz_block,10,minecraft:quartz_block,100)
RB(-10,3,-1,minecraft:chiseled_quartz_block,10,minecraft:quartz_pillar,10,minecraft:smooth_quartz_block,10,minecraft:quartz_block,100)
RB(-10,4,-1,minecraft:chiseled_quartz_block,10,minecraft:quartz_pillar,10,minecraft:smooth_quartz_block,10,minecraft:quartz_block,100)
RB(-10,5,-1,minecraft:chiseled_quartz_block,10,minecraft:quartz_pillar,10,minecraft:smooth_quartz_block,10,minecraft:quartz_block,100)
RB(-10,6,-1,minecraft:chiseled_quartz_block,10,minecraft:quartz_pillar,10,minecraft:smooth_quartz_block,10,minecraft:quartz_block,100)
RB(-10,7,-1,minecraft:chiseled_quartz_block,10,minecraft:quartz_pillar,10,minecraft:smooth_quartz_block,10,minecraft:quartz_block,100)
RB(-10,8,-1,minecraft:chiseled_quartz_block,10,minecraft:quartz_pillar,10,minecraft:smooth_quartz_block,10,minecraft:quartz_block,100)
RB(-10,2,0,minecraft:chiseled_quartz_block,10,minecraft:quartz_pillar,10,minecraft:smooth_quartz_block,10,minecraft:quartz_block,100)
RB(-10,3,0,minecraft:chiseled_quartz_block,10,minecraft:quartz_pillar,10,minecraft:smooth_quartz_block,10,minecraft:quartz_block,100)
RB(-10,4,0,minecraft:chiseled_quartz_block,10,minecraft:quartz_pillar,10,minecraft:smooth_quartz_block,10,minecraft:quartz_block,100)
RB(-10,5,0,minecraft:chiseled_quartz_block,10,minecraft:quartz_pillar,10,minecraft:smooth_quartz_block,10,minecraft:quartz_block,100)
RB(-10,6,0,minecraft:chiseled_quartz_block,10,minecraft:quartz_pillar,10,minecraft:smooth_quartz_block,10,minecraft:quartz_block,100)
RB(-10,7,0,minecraft:chiseled_quartz_block,10,minecraft:quartz_pillar,10,minecraft:smooth_quartz_block,10,minecraft:quartz_block,100)
RB(-10,3,1,minecraft:chiseled_quartz_block,10,minecraft:quartz_pillar,10,minecraft:smooth_quartz_block,10,minecraft:quartz_block,100)
RB(-10,4,1,minecraft:chiseled_quartz_block,10,minecraft:quartz_pillar,10,minecraft:smooth_quartz_block,10,minecraft:quartz_block,100)
RB(-10,5,1,minecraft:chiseled_quartz_block,10,minecraft:quartz_pillar,10,minecraft:smooth_quartz_block,10,minecraft:quartz_block,100)
RB(-10,6,1,minecraft:chiseled_quartz_block,10,minecraft:quartz_pillar,10,minecraft:smooth_quartz_block,10,minecraft:quartz_block,100)
RB(-10,3,2,minecraft:chiseled_quartz_block,10,minecraft:quartz_pillar,10,minecraft:smooth_quartz_block,10,minecraft:quartz_block,100)
RB(-10,4,2,minecraft:chiseled_quartz_block,10,minecraft:quartz_pillar,10,minecraft:smooth_quartz_block,10,minecraft:quartz_block,100)
RB(-10,5,2,minecraft:chiseled_quartz_block,10,minecraft:quartz_pillar,10,minecraft:smooth_quartz_block,10,minecraft:quartz_block,100)
RB(-10,4,3,minecraft:chiseled_quartz_block,10,minecraft:quartz_pillar,10,minecraft:smooth_quartz_block,10,minecraft:quartz_block,100)
RB(-9,12,-11,minecraft:chiseled_quartz_block,10,minecraft:quartz_pillar,10,minecraft:smooth_quartz_block,10,minecraft:quartz_block,100)
RB(-9,13,-11,minecraft:chiseled_quartz_block,10,minecraft:quartz_pillar,10,minecraft:smooth_quartz_block,10,minecraft:quartz_block,100)
RB(-9,14,-11,minecraft:chiseled_quartz_block,10,minecraft:quartz_pillar,10,minecraft:smooth_quartz_block,10,minecraft:quartz_block,100)
RB(-9,15,-11,minecraft:chiseled_quartz_block,10,minecraft:quartz_pillar,10,minecraft:smooth_quartz_block,10,minecraft:quartz_block,100)
RB(-9,8,-10,minecraft:chiseled_quartz_block,10,minecraft:quartz_pillar,10,minecraft:smooth_quartz_block,10,minecraft:quartz_block,100)
RB(-9,9,-10,minecraft:chiseled_quartz_block,10,minecraft:quartz_pillar,10,minecraft:smooth_quartz_block,10,minecraft:quartz_block,100)
RB(-9,10,-10,minecraft:chiseled_quartz_block,10,minecraft:quartz_pillar,10,minecraft:smooth_quartz_block,10,minecraft:quartz_block,100)
RB(-9,11,-10,minecraft:chiseled_quartz_block,10,minecraft:quartz_pillar,10,minecraft:smooth_quartz_block,10,minecraft:quartz_block,100)
RB(-9,12,-10,minecraft:chiseled_quartz_block,10,minecraft:quartz_pillar,10,minecraft:smooth_quartz_block,10,minecraft:quartz_block,100)
RB(-9,13,-10,minecraft:chiseled_quartz_block,10,minecraft:quartz_pillar,10,minecraft:smooth_quartz_block,10,minecraft:quartz_block,100)
RB(-9,14,-10,minecraft:chiseled_quartz_block,10,minecraft:quartz_pillar,10,minecraft:smooth_quartz_block,10,minecraft:quartz_block,100)
RB(-9,15,-10,minecraft:chiseled_quartz_block,10,minecraft:quartz_pillar,10,minecraft:smooth_quartz_block,10,minecraft:quartz_block,100)
RB(-9,4,-9,minecraft:chiseled_quartz_block,10,minecraft:quartz_pillar,10,minecraft:smooth_quartz_block,10,minecraft:quartz_block,100)
RB(-9,5,-9,minecraft:chiseled_quartz_block,10,minecraft:quartz_pillar,10,minecraft:smooth_quartz_block,10,minecraft:quartz_block,100)
RB(-9,6,-9,minecraft:chiseled_quartz_block,10,minecraft:quartz_pillar,10,minecraft:smooth_quartz_block,10,minecraft:quartz_block,100)
RB(-9,7,-9,minecraft:chiseled_quartz_block,10,minecraft:quartz_pillar,10,minecraft:smooth_quartz_block,10,minecraft:quartz_block,100)
RB(-9,8,-9,minecraft:chiseled_quartz_block,10,minecraft:quartz_pillar,10,minecraft:smooth_quartz_block,10,minecraft:quartz_block,100)
RB(-9,9,-9,minecraft:chiseled_quartz_block,10,minecraft:quartz_pillar,10,minecraft:smooth_quartz_block,10,minecraft:quartz_block,100)
RB(-9,10,-9,minecraft:chiseled_quartz_block,10,minecraft:quartz_pillar,10,minecraft:smooth_quartz_block,10,minecraft:quartz_block,100)
RB(-9,11,-9,minecraft:chiseled_quartz_block,10,minecraft:quartz_pillar,10,minecraft:smooth_quartz_block,10,minecraft:quartz_block,100)
RB(-9,12,-9,minecraft:chiseled_quartz_block,10,minecraft:quartz_pillar,10,minecraft:smooth_quartz_block,10,minecraft:quartz_block,100)
RB(-9,13,-9,minecraft:chiseled_quartz_block,10,minecraft:quartz_pillar,10,minecraft:smooth_quartz_block,10,minecraft:quartz_block,100)
RB(-9,14,-9,minecraft:chiseled_quartz_block,10,minecraft:quartz_pillar,10,minecraft:smooth_quartz_block,10,minecraft:quartz_block,100)
RB(-9,15,-9,minecraft:chiseled_quartz_block,10,minecraft:quartz_pillar,10,minecraft:smooth_quartz_block,10,minecraft:quartz_block,100)
RB(-9,0,-8,minecraft:chiseled_quartz_block,10,minecraft:quartz_pillar,10,minecraft:smooth_quartz_block,10,minecraft:quartz_block,100)
RB(-9,1,-8,minecraft:chiseled_quartz_block,10,minecraft:quartz_pillar,10,minecraft:smooth_quartz_block,10,minecraft:quartz_block,100)
RB(-9,2,-8,minecraft:chiseled_quartz_block,10,minecraft:quartz_pillar,10,minecraft:smooth_quartz_block,10,minecraft:quartz_block,100)
RB(-9,3,-8,minecraft:chiseled_quartz_block,10,minecraft:quartz_pillar,10,minecraft:smooth_quartz_block,10,minecraft:quartz_block,100)
RB(-9,4,-8,minecraft:chiseled_quartz_block,10,minecraft:quartz_pillar,10,minecraft:smooth_quartz_block,10,minecraft:quartz_block,100)
RB(-9,5,-8,minecraft:chiseled_quartz_block,10,minecraft:quartz_pillar,10,minecraft:smooth_quartz_block,10,minecraft:quartz_block,100)
RB(-9,6,-8,minecraft:chiseled_quartz_block,10,minecraft:quartz_pillar,10,minecraft:smooth_quartz_block,10,minecraft:quartz_block,100)
RB(-9,7,-8,minecraft:chiseled_quartz_block,10,minecraft:quartz_pillar,10,minecraft:smooth_quartz_block,10,minecraft:quartz_block,100)
RB(-9,8,-8,minecraft:chiseled_quartz_block,10,minecraft:quartz_pillar,10,minecraft:smooth_quartz_block,10,minecraft:quartz_block,100)
RB(-9,9,-8,minecraft:chiseled_quartz_block,10,minecraft:quartz_pillar,10,minecraft:smooth_quartz_block,10,minecraft:quartz_block,100)
RB(-9,10,-8,minecraft:chiseled_quartz_block,10,minecraft:quartz_pillar,10,minecraft:smooth_quartz_block,10,minecraft:quartz_block,100)
RB(-9,11,-8,minecraft:chiseled_quartz_block,10,minecraft:quartz_pillar,10,minecraft:smooth_quartz_block,10,minecraft:quartz_block,100)
RB(-9,12,-8,minecraft:chiseled_quartz_block,10,minecraft:quartz_pillar,10,minecraft:smooth_quartz_block,10,minecraft:quartz_block,100)
RB(-9,13,-8,minecraft:chiseled_quartz_block,10,minecraft:quartz_pillar,10,minecraft:smooth_quartz_block,10,minecraft:quartz_block,100)
RB(-9,14,-8,minecraft:chiseled_quartz_block,10,minecraft:quartz_pillar,10,minecraft:smooth_quartz_block,10,minecraft:quartz_block,100)
RB(-9,0,-7,minecraft:chiseled_quartz_block,10,minecraft:quartz_pillar,10,minecraft:smooth_quartz_block,10,minecraft:quartz_block,100)
RB(-9,1,-7,minecraft:chiseled_quartz_block,10,minecraft:quartz_pillar,10,minecraft:smooth_quartz_block,10,minecraft:quartz_block,100)
RB(-9,2,-7,minecraft:chiseled_quartz_block,10,minecraft:quartz_pillar,10,minecraft:smooth_quartz_block,10,minecraft:quartz_block,100)
RB(-9,3,-7,minecraft:chiseled_quartz_block,10,minecraft:quartz_pillar,10,minecraft:smooth_quartz_block,10,minecraft:quartz_block,100)
RB(-9,4,-7,minecraft:chiseled_quartz_block,10,minecraft:quartz_pillar,10,minecraft:smooth_quartz_block,10,minecraft:quartz_block,100)
RB(-9,5,-7,minecraft:chiseled_quartz_block,10,minecraft:quartz_pillar,10,minecraft:smooth_quartz_block,10,minecraft:quartz_block,100)
RB(-9,6,-7,minecraft:chiseled_quartz_block,10,minecraft:quartz_pillar,10,minecraft:smooth_quartz_block,10,minecraft:quartz_block,100)
RB(-9,7,-7,minecraft:chiseled_quartz_block,10,minecraft:quartz_pillar,10,minecraft:smooth_quartz_block,10,minecraft:quartz_block,100)
RB(-9,8,-7,minecraft:chiseled_quartz_block,10,minecraft:quartz_pillar,10,minecraft:smooth_quartz_block,10,minecraft:quartz_block,100)
RB(-9,9,-7,minecraft:chiseled_quartz_block,10,minecraft:quartz_pillar,10,minecraft:smooth_quartz_block,10,minecraft:quartz_block,100)
RB(-9,10,-7,minecraft:chiseled_quartz_block,10,minecraft:quartz_pillar,10,minecraft:smooth_quartz_block,10,minecraft:quartz_block,100)
RB(-9,11,-7,minecraft:chiseled_quartz_block,10,minecraft:quartz_pillar,10,minecraft:smooth_quartz_block,10,minecraft:quartz_block,100)
RB(-9,12,-7,minecraft:chiseled_quartz_block,10,minecraft:quartz_pillar,10,minecraft:smooth_quartz_block,10,minecraft:quartz_block,100)
RB(-9,13,-7,minecraft:chiseled_quartz_block,10,minecraft:quartz_pillar,10,minecraft:smooth_quartz_block,10,minecraft:quartz_block,100)
RB(-9,14,-7,minecraft:chiseled_quartz_block,10,minecraft:quartz_pillar,10,minecraft:smooth_quartz_block,10,minecraft:quartz_block,100)
RB(-9,0,-6,minecraft:chiseled_quartz_block,10,minecraft:quartz_pillar,10,minecraft:smooth_quartz_block,10,minecraft:quartz_block,100)
RB(-9,1,-6,minecraft:chiseled_quartz_block,10,minecraft:quartz_pillar,10,minecraft:smooth_quartz_block,10,minecraft:quartz_block,100)
RB(-9,2,-6,minecraft:chiseled_quartz_block,10,minecraft:quartz_pillar,10,minecraft:smooth_quartz_block,10,minecraft:quartz_block,100)
RB(-9,3,-6,minecraft:chiseled_quartz_block,10,minecraft:quartz_pillar,10,minecraft:smooth_quartz_block,10,minecraft:quartz_block,100)
RB(-9,4,-6,minecraft:chiseled_quartz_block,10,minecraft:quartz_pillar,10,minecraft:smooth_quartz_block,10,minecraft:quartz_block,100)
RB(-9,5,-6,minecraft:chiseled_quartz_block,10,minecraft:quartz_pillar,10,minecraft:smooth_quartz_block,10,minecraft:quartz_block,100)
RB(-9,6,-6,minecraft:chiseled_quartz_block,10,minecraft:quartz_pillar,10,minecraft:smooth_quartz_block,10,minecraft:quartz_block,100)
RB(-9,7,-6,minecraft:chiseled_quartz_block,10,minecraft:quartz_pillar,10,minecraft:smooth_quartz_block,10,minecraft:quartz_block,100)
RB(-9,8,-6,minecraft:chiseled_quartz_block,10,minecraft:quartz_pillar,10,minecraft:smooth_quartz_block,10,minecraft:quartz_block,100)
RB(-9,9,-6,minecraft:chiseled_quartz_block,10,minecraft:quartz_pillar,10,minecraft:smooth_quartz_block,10,minecraft:quartz_block,100)
RB(-9,10,-6,minecraft:chiseled_quartz_block,10,minecraft:quartz_pillar,10,minecraft:smooth_quartz_block,10,minecraft:quartz_block,100)
RB(-9,11,-6,minecraft:chiseled_quartz_block,10,minecraft:quartz_pillar,10,minecraft:smooth_quartz_block,10,minecraft:quartz_block,100)
RB(-9,12,-6,minecraft:chiseled_quartz_block,10,minecraft:quartz_pillar,10,minecraft:smooth_quartz_block,10,minecraft:quartz_block,100)
RB(-9,13,-6,minecraft:chiseled_quartz_block,10,minecraft:quartz_pillar,10,minecraft:smooth_quartz_block,10,minecraft:quartz_block,100)
RB(-9,0,-5,minecraft:chiseled_quartz_block,10,minecraft:quartz_pillar,10,minecraft:smooth_quartz_block,10,minecraft:quartz_block,100)
RB(-9,1,-5,minecraft:chiseled_quartz_block,10,minecraft:quartz_pillar,10,minecraft:smooth_quartz_block,10,minecraft:quartz_block,100)
RB(-9,2,-5,minecraft:chiseled_quartz_block,10,minecraft:quartz_pillar,10,minecraft:smooth_quartz_block,10,minecraft:quartz_block,100)
RB(-9,3,-5,minecraft:chiseled_quartz_block,10,minecraft:quartz_pillar,10,minecraft:smooth_quartz_block,10,minecraft:quartz_block,100)
RB(-9,4,-5,minecraft:chiseled_quartz_block,10,minecraft:quartz_pillar,10,minecraft:smooth_quartz_block,10,minecraft:quartz_block,100)
RB(-9,5,-5,minecraft:chiseled_quartz_block,10,minecraft:quartz_pillar,10,minecraft:smooth_quartz_block,10,minecraft:quartz_block,100)
RB(-9,6,-5,minecraft:chiseled_quartz_block,10,minecraft:quartz_pillar,10,minecraft:smooth_quartz_block,10,minecraft:quartz_block,100)
RB(-9,7,-5,minecraft:chiseled_quartz_block,10,minecraft:quartz_pillar,10,minecraft:smooth_quartz_block,10,minecraft:quartz_block,100)
RB(-9,8,-5,minecraft:chiseled_quartz_block,10,minecraft:quartz_pillar,10,minecraft:smooth_quartz_block,10,minecraft:quartz_block,100)
RB(-9,9,-5,minecraft:chiseled_quartz_block,10,minecraft:quartz_pillar,10,minecraft:smooth_quartz_block,10,minecraft:quartz_block,100)
RB(-9,10,-5,minecraft:chiseled_quartz_block,10,minecraft:quartz_pillar,10,minecraft:smooth_quartz_block,10,minecraft:quartz_block,100)
RB(-9,11,-5,minecraft:chiseled_quartz_block,10,minecraft:quartz_pillar,10,minecraft:smooth_quartz_block,10,minecraft:quartz_block,100)
RB(-9,12,-5,minecraft:chiseled_quartz_block,10,minecraft:quartz_pillar,10,minecraft:smooth_quartz_block,10,minecraft:quartz_block,100)
RB(-9,0,-4,minecraft:chiseled_quartz_block,10,minecraft:quartz_pillar,10,minecraft:smooth_quartz_block,10,minecraft:quartz_block,100)
RB(-9,1,-4,minecraft:chiseled_quartz_block,10,minecraft:quartz_pillar,10,minecraft:smooth_quartz_block,10,minecraft:quartz_block,100)
RB(-9,2,-4,minecraft:chiseled_quartz_block,10,minecraft:quartz_pillar,10,minecraft:smooth_quartz_block,10,minecraft:quartz_block,100)
RB(-9,3,-4,minecraft:chiseled_quartz_block,10,minecraft:quartz_pillar,10,minecraft:smooth_quartz_block,10,minecraft:quartz_block,100)
RB(-9,4,-4,minecraft:chiseled_quartz_block,10,minecraft:quartz_pillar,10,minecraft:smooth_quartz_block,10,minecraft:quartz_block,100)
RB(-9,5,-4,minecraft:chiseled_quartz_block,10,minecraft:quartz_pillar,10,minecraft:smooth_quartz_block,10,minecraft:quartz_block,100)
RB(-9,6,-4,minecraft:chiseled_quartz_block,10,minecraft:quartz_pillar,10,minecraft:smooth_quartz_block,10,minecraft:quartz_block,100)
RB(-9,7,-4,minecraft:chiseled_quartz_block,10,minecraft:quartz_pillar,10,minecraft:smooth_quartz_block,10,minecraft:quartz_block,100)
RB(-9,8,-4,minecraft:chiseled_quartz_block,10,minecraft:quartz_pillar,10,minecraft:smooth_quartz_block,10,minecraft:quartz_block,100)
RB(-9,9,-4,minecraft:chiseled_quartz_block,10,minecraft:quartz_pillar,10,minecraft:smooth_quartz_block,10,minecraft:quartz_block,100)
RB(-9,10,-4,minecraft:chiseled_quartz_block,10,minecraft:quartz_pillar,10,minecraft:smooth_quartz_block,10,minecraft:quartz_block,100)
RB(-9,11,-4,minecraft:chiseled_quartz_block,10,minecraft:quartz_pillar,10,minecraft:smooth_quartz_block,10,minecraft:quartz_block,100)
RB(-9,12,-4,minecraft:chiseled_quartz_block,10,minecraft:quartz_pillar,10,minecraft:smooth_quartz_block,10,minecraft:quartz_block,100)
RB(-9,0,-3,minecraft:chiseled_quartz_block,10,minecraft:quartz_pillar,10,minecraft:smooth_quartz_block,10,minecraft:quartz_block,100)
RB(-9,1,-3,minecraft:chiseled_quartz_block,10,minecraft:quartz_pillar,10,minecraft:smooth_quartz_block,10,minecraft:quartz_block,100)
RB(-9,2,-3,minecraft:chiseled_quartz_block,10,minecraft:quartz_pillar,10,minecraft:smooth_quartz_block,10,minecraft:quartz_block,100)
RB(-9,3,-3,minecraft:chiseled_quartz_block,10,minecraft:quartz_pillar,10,minecraft:smooth_quartz_block,10,minecraft:quartz_block,100)
RB(-9,4,-3,minecraft:chiseled_quartz_block,10,minecraft:quartz_pillar,10,minecraft:smooth_quartz_block,10,minecraft:quartz_block,100)
RB(-9,5,-3,minecraft:chiseled_quartz_block,10,minecraft:quartz_pillar,10,minecraft:smooth_quartz_block,10,minecraft:quartz_block,100)
RB(-9,6,-3,minecraft:chiseled_quartz_block,10,minecraft:quartz_pillar,10,minecraft:smooth_quartz_block,10,minecraft:quartz_block,100)
RB(-9,7,-3,minecraft:chiseled_quartz_block,10,minecraft:quartz_pillar,10,minecraft:smooth_quartz_block,10,minecraft:quartz_block,100)
RB(-9,8,-3,minecraft:chiseled_quartz_block,10,minecraft:quartz_pillar,10,minecraft:smooth_quartz_block,10,minecraft:quartz_block,100)
RB(-9,9,-3,minecraft:chiseled_quartz_block,10,minecraft:quartz_pillar,10,minecraft:smooth_quartz_block,10,minecraft:quartz_block,100)
RB(-9,10,-3,minecraft:chiseled_quartz_block,10,minecraft:quartz_pillar,10,minecraft:smooth_quartz_block,10,minecraft:quartz_block,100)
RB(-9,11,-3,minecraft:chiseled_quartz_block,10,minecraft:quartz_pillar,10,minecraft:smooth_quartz_block,10,minecraft:quartz_block,100)
RB(-9,0,-2,minecraft:chiseled_quartz_block,10,minecraft:quartz_pillar,10,minecraft:smooth_quartz_block,10,minecraft:quartz_block,100)
RB(-9,1,-2,minecraft:chiseled_quartz_block,10,minecraft:quartz_pillar,10,minecraft:smooth_quartz_block,10,minecraft:quartz_block,100)
RB(-9,2,-2,minecraft:chiseled_quartz_block,10,minecraft:quartz_pillar,10,minecraft:smooth_quartz_block,10,minecraft:quartz_block,100)
RB(-9,3,-2,minecraft:chiseled_quartz_block,10,minecraft:quartz_pillar,10,minecraft:smooth_quartz_block,10,minecraft:quartz_block,100)
RB(-9,4,-2,minecraft:chiseled_quartz_block,10,minecraft:quartz_pillar,10,minecraft:smooth_quartz_block,10,minecraft:quartz_block,100)
RB(-9,5,-2,minecraft:chiseled_quartz_block,10,minecraft:quartz_pillar,10,minecraft:smooth_quartz_block,10,minecraft:quartz_block,100)
RB(-9,6,-2,minecraft:chiseled_quartz_block,10,minecraft:quartz_pillar,10,minecraft:smooth_quartz_block,10,minecraft:quartz_block,100)
RB(-9,7,-2,minecraft:chiseled_quartz_block,10,minecraft:quartz_pillar,10,minecraft:smooth_quartz_block,10,minecraft:quartz_block,100)
RB(-9,8,-2,minecraft:chiseled_quartz_block,10,minecraft:quartz_pillar,10,minecraft:smooth_quartz_block,10,minecraft:quartz_block,100)
RB(-9,9,-2,minecraft:chiseled_quartz_block,10,minecraft:quartz_pillar,10,minecraft:smooth_quartz_block,10,minecraft:quartz_block,100)
RB(-9,10,-2,minecraft:chiseled_quartz_block,10,minecraft:quartz_pillar,10,minecraft:smooth_quartz_block,10,minecraft:quartz_block,100)
RB(-9,0,-1,minecraft:chiseled_quartz_block,10,minecraft:quartz_pillar,10,minecraft:smooth_quartz_block,10,minecraft:quartz_block,100)
RB(-9,1,-1,minecraft:chiseled_quartz_block,10,minecraft:quartz_pillar,10,minecraft:smooth_quartz_block,10,minecraft:quartz_block,100)
RB(-9,2,-1,minecraft:chiseled_quartz_block,10,minecraft:quartz_pillar,10,minecraft:smooth_quartz_block,10,minecraft:quartz_block,100)
RB(-9,3,-1,minecraft:chiseled_quartz_block,10,minecraft:quartz_pillar,10,minecraft:smooth_quartz_block,10,minecraft:quartz_block,100)
RB(-9,4,-1,minecraft:chiseled_quartz_block,10,minecraft:quartz_pillar,10,minecraft:smooth_quartz_block,10,minecraft:quartz_block,100)
RB(-9,5,-1,minecraft:chiseled_quartz_block,10,minecraft:quartz_pillar,10,minecraft:smooth_quartz_block,10,minecraft:quartz_block,100)
RB(-9,6,-1,minecraft:chiseled_quartz_block,10,minecraft:quartz_pillar,10,minecraft:smooth_quartz_block,10,minecraft:quartz_block,100)
RB(-9,7,-1,minecraft:chiseled_quartz_block,10,minecraft:quartz_pillar,10,minecraft:smooth_quartz_block,10,minecraft:quartz_block,100)
RB(-9,8,-1,minecraft:chiseled_quartz_block,10,minecraft:quartz_pillar,10,minecraft:smooth_quartz_block,10,minecraft:quartz_block,100)
RB(-9,9,-1,minecraft:chiseled_quartz_block,10,minecraft:quartz_pillar,10,minecraft:smooth_quartz_block,10,minecraft:quartz_block,100)
RB(-9,0,0,minecraft:chiseled_quartz_block,10,minecraft:quartz_pillar,10,minecraft:smooth_quartz_block,10,minecraft:quartz_block,100)
RB(-9,1,0,minecraft:chiseled_quartz_block,10,minecraft:quartz_pillar,10,minecraft:smooth_quartz_block,10,minecraft:quartz_block,100)
RB(-9,2,0,minecraft:chiseled_quartz_block,10,minecraft:quartz_pillar,10,minecraft:smooth_quartz_block,10,minecraft:quartz_block,100)
RB(-9,3,0,minecraft:chiseled_quartz_block,10,minecraft:quartz_pillar,10,minecraft:smooth_quartz_block,10,minecraft:quartz_block,100)
RB(-9,4,0,minecraft:chiseled_quartz_block,10,minecraft:quartz_pillar,10,minecraft:smooth_quartz_block,10,minecraft:quartz_block,100)
RB(-9,5,0,minecraft:chiseled_quartz_block,10,minecraft:quartz_pillar,10,minecraft:smooth_quartz_block,10,minecraft:quartz_block,100)
RB(-9,6,0,minecraft:chiseled_quartz_block,10,minecraft:quartz_pillar,10,minecraft:smooth_quartz_block,10,minecraft:quartz_block,100)
RB(-9,7,0,minecraft:chiseled_quartz_block,10,minecraft:quartz_pillar,10,minecraft:smooth_quartz_block,10,minecraft:quartz_block,100)
RB(-9,8,0,minecraft:chiseled_quartz_block,10,minecraft:quartz_pillar,10,minecraft:smooth_quartz_block,10,minecraft:quartz_block,100)
RB(-9,0,1,minecraft:chiseled_quartz_block,10,minecraft:quartz_pillar,10,minecraft:smooth_quartz_block,10,minecraft:quartz_block,100)
RB(-9,1,1,minecraft:chiseled_quartz_block,10,minecraft:quartz_pillar,10,minecraft:smooth_quartz_block,10,minecraft:quartz_block,100)
RB(-9,2,1,minecraft:chiseled_quartz_block,10,minecraft:quartz_pillar,10,minecraft:smooth_quartz_block,10,minecraft:quartz_block,100)
RB(-9,3,1,minecraft:chiseled_quartz_block,10,minecraft:quartz_pillar,10,minecraft:smooth_quartz_block,10,minecraft:quartz_block,100)
RB(-9,4,1,minecraft:chiseled_quartz_block,10,minecraft:quartz_pillar,10,minecraft:smooth_quartz_block,10,minecraft:quartz_block,100)
RB(-9,5,1,minecraft:chiseled_quartz_block,10,minecraft:quartz_pillar,10,minecraft:smooth_quartz_block,10,minecraft:quartz_block,100)
RB(-9,6,1,minecraft:chiseled_quartz_block,10,minecraft:quartz_pillar,10,minecraft:smooth_quartz_block,10,minecraft:quartz_block,100)
RB(-9,7,1,minecraft:chiseled_quartz_block,10,minecraft:quartz_pillar,10,minecraft:smooth_quartz_block,10,minecraft:quartz_block,100)
RB(-9,0,2,minecraft:chiseled_quartz_block,10,minecraft:quartz_pillar,10,minecraft:smooth_quartz_block,10,minecraft:quartz_block,100)
RB(-9,1,2,minecraft:chiseled_quartz_block,10,minecraft:quartz_pillar,10,minecraft:smooth_quartz_block,10,minecraft:quartz_block,100)
RB(-9,2,2,minecraft:chiseled_quartz_block,10,minecraft:quartz_pillar,10,minecraft:smooth_quartz_block,10,minecraft:quartz_block,100)
RB(-9,3,2,minecraft:chiseled_quartz_block,10,minecraft:quartz_pillar,10,minecraft:smooth_quartz_block,10,minecraft:quartz_block,100)
RB(-9,4,2,minecraft:chiseled_quartz_block,10,minecraft:quartz_pillar,10,minecraft:smooth_quartz_block,10,minecraft:quartz_block,100)
RB(-9,5,2,minecraft:chiseled_quartz_block,10,minecraft:quartz_pillar,10,minecraft:smooth_quartz_block,10,minecraft:quartz_block,100)
RB(-9,6,2,minecraft:chiseled_quartz_block,10,minecraft:quartz_pillar,10,minecraft:smooth_quartz_block,10,minecraft:quartz_block,100)
RB(-9,0,3,minecraft:chiseled_quartz_block,10,minecraft:quartz_pillar,10,minecraft:smooth_quartz_block,10,minecraft:quartz_block,100)
RB(-9,1,3,minecraft:chiseled_quartz_block,10,minecraft:quartz_pillar,10,minecraft:smooth_quartz_block,10,minecraft:quartz_block,100)
RB(-9,2,3,minecraft:chiseled_quartz_block,10,minecraft:quartz_pillar,10,minecraft:smooth_quartz_block,10,minecraft:quartz_block,100)
RB(-9,3,3,minecraft:chiseled_quartz_block,10,minecraft:quartz_pillar,10,minecraft:smooth_quartz_block,10,minecraft:quartz_block,100)
RB(-9,4,3,minecraft:chiseled_quartz_block,10,minecraft:quartz_pillar,10,minecraft:smooth_quartz_block,10,minecraft:quartz_block,100)
RB(-9,5,3,minecraft:chiseled_quartz_block,10,minecraft:quartz_pillar,10,minecraft:smooth_quartz_block,10,minecraft:quartz_block,100)
RB(-9,0,4,minecraft:chiseled_quartz_block,10,minecraft:quartz_pillar,10,minecraft:smooth_quartz_block,10,minecraft:quartz_block,100)
RB(-9,1,4,minecraft:chiseled_quartz_block,10,minecraft:quartz_pillar,10,minecraft:smooth_quartz_block,10,minecraft:quartz_block,100)
RB(-9,2,4,minecraft:chiseled_quartz_block,10,minecraft:quartz_pillar,10,minecraft:smooth_quartz_block,10,minecraft:quartz_block,100)
RB(-9,3,4,minecraft:chiseled_quartz_block,10,minecraft:quartz_pillar,10,minecraft:smooth_quartz_block,10,minecraft:quartz_block,100)
RB(-9,4,4,minecraft:chiseled_quartz_block,10,minecraft:quartz_pillar,10,minecraft:smooth_quartz_block,10,minecraft:quartz_block,100)
RB(-9,0,5,minecraft:chiseled_quartz_block,10,minecraft:quartz_pillar,10,minecraft:smooth_quartz_block,10,minecraft:quartz_block,100)
RB(-9,1,5,minecraft:chiseled_quartz_block,10,minecraft:quartz_pillar,10,minecraft:smooth_quartz_block,10,minecraft:quartz_block,100)
RB(-9,2,5,minecraft:chiseled_quartz_block,10,minecraft:quartz_pillar,10,minecraft:smooth_quartz_block,10,minecraft:quartz_block,100)
RB(-9,3,5,minecraft:chiseled_quartz_block,10,minecraft:quartz_pillar,10,minecraft:smooth_quartz_block,10,minecraft:quartz_block,100)
RB(-9,0,6,minecraft:chiseled_quartz_block,10,minecraft:quartz_pillar,10,minecraft:smooth_quartz_block,10,minecraft:quartz_block,100)
RB(-9,1,6,minecraft:chiseled_quartz_block,10,minecraft:quartz_pillar,10,minecraft:smooth_quartz_block,10,minecraft:quartz_block,100)
RB(-9,2,6,minecraft:chiseled_quartz_block,10,minecraft:quartz_pillar,10,minecraft:smooth_quartz_block,10,minecraft:quartz_block,100)
RB(-9,0,7,minecraft:chiseled_quartz_block,10,minecraft:quartz_pillar,10,minecraft:smooth_quartz_block,10,minecraft:quartz_block,100)
RB(-9,1,7,minecraft:chiseled_quartz_block,10,minecraft:quartz_pillar,10,minecraft:smooth_quartz_block,10,minecraft:quartz_block,100)
RB(-9,0,8,minecraft:chiseled_quartz_block,10,minecraft:quartz_pillar,10,minecraft:smooth_quartz_block,10,minecraft:quartz_block,100)
RB(-8,12,-11,minecraft:chiseled_quartz_block,10,minecraft:quartz_pillar,10,minecraft:smooth_quartz_block,10,minecraft:quartz_block,100)
RB(-8,13,-11,minecraft:chiseled_quartz_block,10,minecraft:quartz_pillar,10,minecraft:smooth_quartz_block,10,minecraft:quartz_block,100)
RB(-8,14,-11,minecraft:chiseled_quartz_block,10,minecraft:quartz_pillar,10,minecraft:smooth_quartz_block,10,minecraft:quartz_block,100)
RB(-8,9,-10,minecraft:chiseled_quartz_block,10,minecraft:quartz_pillar,10,minecraft:smooth_quartz_block,10,minecraft:quartz_block,100)
RB(-8,10,-10,minecraft:chiseled_quartz_block,10,minecraft:quartz_pillar,10,minecraft:smooth_quartz_block,10,minecraft:quartz_block,100)
RB(-8,11,-10,minecraft:chiseled_quartz_block,10,minecraft:quartz_pillar,10,minecraft:smooth_quartz_block,10,minecraft:quartz_block,100)
RB(-8,12,-10,minecraft:chiseled_quartz_block,10,minecraft:quartz_pillar,10,minecraft:smooth_quartz_block,10,minecraft:quartz_block,100)
RB(-8,13,-10,minecraft:chiseled_quartz_block,10,minecraft:quartz_pillar,10,minecraft:smooth_quartz_block,10,minecraft:quartz_block,100)
RB(-8,14,-10,minecraft:chiseled_quartz_block,10,minecraft:quartz_pillar,10,minecraft:smooth_quartz_block,10,minecraft:quartz_block,100)
RB(-8,5,-9,minecraft:chiseled_quartz_block,10,minecraft:quartz_pillar,10,minecraft:smooth_quartz_block,10,minecraft:quartz_block,100)
RB(-8,6,-9,minecraft:chiseled_quartz_block,10,minecraft:quartz_pillar,10,minecraft:smooth_quartz_block,10,minecraft:quartz_block,100)
RB(-8,7,-9,minecraft:chiseled_quartz_block,10,minecraft:quartz_pillar,10,minecraft:smooth_quartz_block,10,minecraft:quartz_block,100)
RB(-8,8,-9,minecraft:chiseled_quartz_block,10,minecraft:quartz_pillar,10,minecraft:smooth_quartz_block,10,minecraft:quartz_block,100)
RB(-8,9,-9,minecraft:chiseled_quartz_block,10,minecraft:quartz_pillar,10,minecraft:smooth_quartz_block,10,minecraft:quartz_block,100)
RB(-8,10,-9,minecraft:chiseled_quartz_block,10,minecraft:quartz_pillar,10,minecraft:smooth_quartz_block,10,minecraft:quartz_block,100)
RB(-8,11,-9,minecraft:chiseled_quartz_block,10,minecraft:quartz_pillar,10,minecraft:smooth_quartz_block,10,minecraft:quartz_block,100)
RB(-8,12,-9,minecraft:chiseled_quartz_block,10,minecraft:quartz_pillar,10,minecraft:smooth_quartz_block,10,minecraft:quartz_block,100)
RB(-8,13,-9,minecraft:chiseled_quartz_block,10,minecraft:quartz_pillar,10,minecraft:smooth_quartz_block,10,minecraft:quartz_block,100)
RB(-8,14,-9,minecraft:chiseled_quartz_block,10,minecraft:quartz_pillar,10,minecraft:smooth_quartz_block,10,minecraft:quartz_block,100)
RB(-8,1,-8,minecraft:chiseled_quartz_block,10,minecraft:quartz_pillar,10,minecraft:smooth_quartz_block,10,minecraft:quartz_block,100)
RB(-8,2,-8,minecraft:chiseled_quartz_block,10,minecraft:quartz_pillar,10,minecraft:smooth_quartz_block,10,minecraft:quartz_block,100)
RB(-8,3,-8,minecraft:chiseled_quartz_block,10,minecraft:quartz_pillar,10,minecraft:smooth_quartz_block,10,minecraft:quartz_block,100)
RB(-8,4,-8,minecraft:chiseled_quartz_block,10,minecraft:quartz_pillar,10,minecraft:smooth_quartz_block,10,minecraft:quartz_block,100)
RB(-8,5,-8,minecraft:chiseled_quartz_block,10,minecraft:quartz_pillar,10,minecraft:smooth_quartz_block,10,minecraft:quartz_block,100)
RB(-8,6,-8,minecraft:chiseled_quartz_block,10,minecraft:quartz_pillar,10,minecraft:smooth_quartz_block,10,minecraft:quartz_block,100)
RB(-8,7,-8,minecraft:chiseled_quartz_block,10,minecraft:quartz_pillar,10,minecraft:smooth_quartz_block,10,minecraft:quartz_block,100)
RB(-8,8,-8,minecraft:chiseled_quartz_block,10,minecraft:quartz_pillar,10,minecraft:smooth_quartz_block,10,minecraft:quartz_block,100)
RB(-8,9,-8,minecraft:chiseled_quartz_block,10,minecraft:quartz_pillar,10,minecraft:smooth_quartz_block,10,minecraft:quartz_block,100)
RB(-8,10,-8,minecraft:chiseled_quartz_block,10,minecraft:quartz_pillar,10,minecraft:smooth_quartz_block,10,minecraft:quartz_block,100)
RB(-8,11,-8,minecraft:chiseled_quartz_block,10,minecraft:quartz_pillar,10,minecraft:smooth_quartz_block,10,minecraft:quartz_block,100)
RB(-8,12,-8,minecraft:chiseled_quartz_block,10,minecraft:quartz_pillar,10,minecraft:smooth_quartz_block,10,minecraft:quartz_block,100)
RB(-8,13,-8,minecraft:chiseled_quartz_block,10,minecraft:quartz_pillar,10,minecraft:smooth_quartz_block,10,minecraft:quartz_block,100)
RB(-8,14,-8,minecraft:chiseled_quartz_block,10,minecraft:quartz_pillar,10,minecraft:smooth_quartz_block,10,minecraft:quartz_block,100)
RB(-8,0,-7,minecraft:chiseled_quartz_block,10,minecraft:quartz_pillar,10,minecraft:smooth_quartz_block,10,minecraft:quartz_block,100)
RB(-8,1,-7,minecraft:chiseled_quartz_block,10,minecraft:quartz_pillar,10,minecraft:smooth_quartz_block,10,minecraft:quartz_block,100)
RB(-8,2,-7,minecraft:chiseled_quartz_block,10,minecraft:quartz_pillar,10,minecraft:smooth_quartz_block,10,minecraft:quartz_block,100)
RB(-8,3,-7,minecraft:chiseled_quartz_block,10,minecraft:quartz_pillar,10,minecraft:smooth_quartz_block,10,minecraft:quartz_block,100)
RB(-8,4,-7,minecraft:chiseled_quartz_block,10,minecraft:quartz_pillar,10,minecraft:smooth_quartz_block,10,minecraft:quartz_block,100)
RB(-8,5,-7,minecraft:chiseled_quartz_block,10,minecraft:quartz_pillar,10,minecraft:smooth_quartz_block,10,minecraft:quartz_block,100)
RB(-8,6,-7,minecraft:chiseled_quartz_block,10,minecraft:quartz_pillar,10,minecraft:smooth_quartz_block,10,minecraft:quartz_block,100)
RB(-8,7,-7,minecraft:chiseled_quartz_block,10,minecraft:quartz_pillar,10,minecraft:smooth_quartz_block,10,minecraft:quartz_block,100)
RB(-8,8,-7,minecraft:chiseled_quartz_block,10,minecraft:quartz_pillar,10,minecraft:smooth_quartz_block,10,minecraft:quartz_block,100)
RB(-8,9,-7,minecraft:chiseled_quartz_block,10,minecraft:quartz_pillar,10,minecraft:smooth_quartz_block,10,minecraft:quartz_block,100)
RB(-8,10,-7,minecraft:chiseled_quartz_block,10,minecraft:quartz_pillar,10,minecraft:smooth_quartz_block,10,minecraft:quartz_block,100)
RB(-8,11,-7,minecraft:chiseled_quartz_block,10,minecraft:quartz_pillar,10,minecraft:smooth_quartz_block,10,minecraft:quartz_block,100)
RB(-8,12,-7,minecraft:chiseled_quartz_block,10,minecraft:quartz_pillar,10,minecraft:smooth_quartz_block,10,minecraft:quartz_block,100)
RB(-8,13,-7,minecraft:chiseled_quartz_block,10,minecraft:quartz_pillar,10,minecraft:smooth_quartz_block,10,minecraft:quartz_block,100)
RB(-8,0,-6,minecraft:chiseled_quartz_block,10,minecraft:quartz_pillar,10,minecraft:smooth_quartz_block,10,minecraft:quartz_block,100)
RB(-8,1,-6,minecraft:chiseled_quartz_block,10,minecraft:quartz_pillar,10,minecraft:smooth_quartz_block,10,minecraft:quartz_block,100)
RB(-8,2,-6,minecraft:chiseled_quartz_block,10,minecraft:quartz_pillar,10,minecraft:smooth_quartz_block,10,minecraft:quartz_block,100)
RB(-8,3,-6,minecraft:chiseled_quartz_block,10,minecraft:quartz_pillar,10,minecraft:smooth_quartz_block,10,minecraft:quartz_block,100)
RB(-8,4,-6,minecraft:chiseled_quartz_block,10,minecraft:quartz_pillar,10,minecraft:smooth_quartz_block,10,minecraft:quartz_block,100)
RB(-8,5,-6,minecraft:chiseled_quartz_block,10,minecraft:quartz_pillar,10,minecraft:smooth_quartz_block,10,minecraft:quartz_block,100)
RB(-8,6,-6,minecraft:chiseled_quartz_block,10,minecraft:quartz_pillar,10,minecraft:smooth_quartz_block,10,minecraft:quartz_block,100)
RB(-8,7,-6,minecraft:chiseled_quartz_block,10,minecraft:quartz_pillar,10,minecraft:smooth_quartz_block,10,minecraft:quartz_block,100)
RB(-8,8,-6,minecraft:chiseled_quartz_block,10,minecraft:quartz_pillar,10,minecraft:smooth_quartz_block,10,minecraft:quartz_block,100)
RB(-8,9,-6,minecraft:chiseled_quartz_block,10,minecraft:quartz_pillar,10,minecraft:smooth_quartz_block,10,minecraft:quartz_block,100)
RB(-8,10,-6,minecraft:chiseled_quartz_block,10,minecraft:quartz_pillar,10,minecraft:smooth_quartz_block,10,minecraft:quartz_block,100)
RB(-8,11,-6,minecraft:chiseled_quartz_block,10,minecraft:quartz_pillar,10,minecraft:smooth_quartz_block,10,minecraft:quartz_block,100)
RB(-8,12,-6,minecraft:chiseled_quartz_block,10,minecraft:quartz_pillar,10,minecraft:smooth_quartz_block,10,minecraft:quartz_block,100)
RB(-8,13,-6,minecraft:chiseled_quartz_block,10,minecraft:quartz_pillar,10,minecraft:smooth_quartz_block,10,minecraft:quartz_block,100)
RB(-8,0,-5,minecraft:chiseled_quartz_block,10,minecraft:quartz_pillar,10,minecraft:smooth_quartz_block,10,minecraft:quartz_block,100)
RB(-8,1,-5,minecraft:chiseled_quartz_block,10,minecraft:quartz_pillar,10,minecraft:smooth_quartz_block,10,minecraft:quartz_block,100)
RB(-8,2,-5,minecraft:chiseled_quartz_block,10,minecraft:quartz_pillar,10,minecraft:smooth_quartz_block,10,minecraft:quartz_block,100)
RB(-8,3,-5,minecraft:chiseled_quartz_block,10,minecraft:quartz_pillar,10,minecraft:smooth_quartz_block,10,minecraft:quartz_block,100)
RB(-8,4,-5,minecraft:chiseled_quartz_block,10,minecraft:quartz_pillar,10,minecraft:smooth_quartz_block,10,minecraft:quartz_block,100)
RB(-8,5,-5,minecraft:chiseled_quartz_block,10,minecraft:quartz_pillar,10,minecraft:smooth_quartz_block,10,minecraft:quartz_block,100)
RB(-8,6,-5,minecraft:chiseled_quartz_block,10,minecraft:quartz_pillar,10,minecraft:smooth_quartz_block,10,minecraft:quartz_block,100)
RB(-8,7,-5,minecraft:chiseled_quartz_block,10,minecraft:quartz_pillar,10,minecraft:smooth_quartz_block,10,minecraft:quartz_block,100)
RB(-8,8,-5,minecraft:chiseled_quartz_block,10,minecraft:quartz_pillar,10,minecraft:smooth_quartz_block,10,minecraft:quartz_block,100)
RB(-8,9,-5,minecraft:chiseled_quartz_block,10,minecraft:quartz_pillar,10,minecraft:smooth_quartz_block,10,minecraft:quartz_block,100)
RB(-8,10,-5,minecraft:chiseled_quartz_block,10,minecraft:quartz_pillar,10,minecraft:smooth_quartz_block,10,minecraft:quartz_block,100)
RB(-8,11,-5,minecraft:chiseled_quartz_block,10,minecraft:quartz_pillar,10,minecraft:smooth_quartz_block,10,minecraft:quartz_block,100)
RB(-8,12,-5,minecraft:chiseled_quartz_block,10,minecraft:quartz_pillar,10,minecraft:smooth_quartz_block,10,minecraft:quartz_block,100)
RB(-8,0,-4,minecraft:chiseled_quartz_block,10,minecraft:quartz_pillar,10,minecraft:smooth_quartz_block,10,minecraft:quartz_block,100)
RB(-8,1,-4,minecraft:chiseled_quartz_block,10,minecraft:quartz_pillar,10,minecraft:smooth_quartz_block,10,minecraft:quartz_block,100)
RB(-8,2,-4,minecraft:chiseled_quartz_block,10,minecraft:quartz_pillar,10,minecraft:smooth_quartz_block,10,minecraft:quartz_block,100)
RB(-8,3,-4,minecraft:chiseled_quartz_block,10,minecraft:quartz_pillar,10,minecraft:smooth_quartz_block,10,minecraft:quartz_block,100)
RB(-8,4,-4,minecraft:chiseled_quartz_block,10,minecraft:quartz_pillar,10,minecraft:smooth_quartz_block,10,minecraft:quartz_block,100)
RB(-8,5,-4,minecraft:chiseled_quartz_block,10,minecraft:quartz_pillar,10,minecraft:smooth_quartz_block,10,minecraft:quartz_block,100)
RB(-8,6,-4,minecraft:chiseled_quartz_block,10,minecraft:quartz_pillar,10,minecraft:smooth_quartz_block,10,minecraft:quartz_block,100)
RB(-8,7,-4,minecraft:chiseled_quartz_block,10,minecraft:quartz_pillar,10,minecraft:smooth_quartz_block,10,minecraft:quartz_block,100)
RB(-8,8,-4,minecraft:chiseled_quartz_block,10,minecraft:quartz_pillar,10,minecraft:smooth_quartz_block,10,minecraft:quartz_block,100)
RB(-8,9,-4,minecraft:chiseled_quartz_block,10,minecraft:quartz_pillar,10,minecraft:smooth_quartz_block,10,minecraft:quartz_block,100)
RB(-8,10,-4,minecraft:chiseled_quartz_block,10,minecraft:quartz_pillar,10,minecraft:smooth_quartz_block,10,minecraft:quartz_block,100)
RB(-8,11,-4,minecraft:chiseled_quartz_block,10,minecraft:quartz_pillar,10,minecraft:smooth_quartz_block,10,minecraft:quartz_block,100)
RB(-8,12,-4,minecraft:chiseled_quartz_block,10,minecraft:quartz_pillar,10,minecraft:smooth_quartz_block,10,minecraft:quartz_block,100)
RB(-8,0,-3,minecraft:chiseled_quartz_block,10,minecraft:quartz_pillar,10,minecraft:smooth_quartz_block,10,minecraft:quartz_block,100)
RB(-8,1,-3,minecraft:chiseled_quartz_block,10,minecraft:quartz_pillar,10,minecraft:smooth_quartz_block,10,minecraft:quartz_block,100)
RB(-8,2,-3,minecraft:chiseled_quartz_block,10,minecraft:quartz_pillar,10,minecraft:smooth_quartz_block,10,minecraft:quartz_block,100)
RB(-8,3,-3,minecraft:chiseled_quartz_block,10,minecraft:quartz_pillar,10,minecraft:smooth_quartz_block,10,minecraft:quartz_block,100)
RB(-8,4,-3,minecraft:chiseled_quartz_block,10,minecraft:quartz_pillar,10,minecraft:smooth_quartz_block,10,minecraft:quartz_block,100)
RB(-8,5,-3,minecraft:chiseled_quartz_block,10,minecraft:quartz_pillar,10,minecraft:smooth_quartz_block,10,minecraft:quartz_block,100)
RB(-8,6,-3,minecraft:chiseled_quartz_block,10,minecraft:quartz_pillar,10,minecraft:smooth_quartz_block,10,minecraft:quartz_block,100)
RB(-8,7,-3,minecraft:chiseled_quartz_block,10,minecraft:quartz_pillar,10,minecraft:smooth_quartz_block,10,minecraft:quartz_block,100)
RB(-8,8,-3,minecraft:chiseled_quartz_block,10,minecraft:quartz_pillar,10,minecraft:smooth_quartz_block,10,minecraft:quartz_block,100)
RB(-8,9,-3,minecraft:chiseled_quartz_block,10,minecraft:quartz_pillar,10,minecraft:smooth_quartz_block,10,minecraft:quartz_block,100)
RB(-8,10,-3,minecraft:chiseled_quartz_block,10,minecraft:quartz_pillar,10,minecraft:smooth_quartz_block,10,minecraft:quartz_block,100)
RB(-8,11,-3,minecraft:chiseled_quartz_block,10,minecraft:quartz_pillar,10,minecraft:smooth_quartz_block,10,minecraft:quartz_block,100)
RB(-8,0,-2,minecraft:chiseled_quartz_block,10,minecraft:quartz_pillar,10,minecraft:smooth_quartz_block,10,minecraft:quartz_block,100)
RB(-8,1,-2,minecraft:chiseled_quartz_block,10,minecraft:quartz_pillar,10,minecraft:smooth_quartz_block,10,minecraft:quartz_block,100)
RB(-8,2,-2,minecraft:chiseled_quartz_block,10,minecraft:quartz_pillar,10,minecraft:smooth_quartz_block,10,minecraft:quartz_block,100)
RB(-8,3,-2,minecraft:chiseled_quartz_block,10,minecraft:quartz_pillar,10,minecraft:smooth_quartz_block,10,minecraft:quartz_block,100)
RB(-8,4,-2,minecraft:chiseled_quartz_block,10,minecraft:quartz_pillar,10,minecraft:smooth_quartz_block,10,minecraft:quartz_block,100)
RB(-8,5,-2,minecraft:chiseled_quartz_block,10,minecraft:quartz_pillar,10,minecraft:smooth_quartz_block,10,minecraft:quartz_block,100)
RB(-8,6,-2,minecraft:chiseled_quartz_block,10,minecraft:quartz_pillar,10,minecraft:smooth_quartz_block,10,minecraft:quartz_block,100)
RB(-8,7,-2,minecraft:chiseled_quartz_block,10,minecraft:quartz_pillar,10,minecraft:smooth_quartz_block,10,minecraft:quartz_block,100)
RB(-8,8,-2,minecraft:chiseled_quartz_block,10,minecraft:quartz_pillar,10,minecraft:smooth_quartz_block,10,minecraft:quartz_block,100)
RB(-8,9,-2,minecraft:chiseled_quartz_block,10,minecraft:quartz_pillar,10,minecraft:smooth_quartz_block,10,minecraft:quartz_block,100)
RB(-8,10,-2,minecraft:chiseled_quartz_block,10,minecraft:quartz_pillar,10,minecraft:smooth_quartz_block,10,minecraft:quartz_block,100)
RB(-8,0,-1,minecraft:chiseled_quartz_block,10,minecraft:quartz_pillar,10,minecraft:smooth_quartz_block,10,minecraft:quartz_block,100)
RB(-8,1,-1,minecraft:chiseled_quartz_block,10,minecraft:quartz_pillar,10,minecraft:smooth_quartz_block,10,minecraft:quartz_block,100)
RB(-8,2,-1,minecraft:chiseled_quartz_block,10,minecraft:quartz_pillar,10,minecraft:smooth_quartz_block,10,minecraft:quartz_block,100)
RB(-8,3,-1,minecraft:chiseled_quartz_block,10,minecraft:quartz_pillar,10,minecraft:smooth_quartz_block,10,minecraft:quartz_block,100)
RB(-8,4,-1,minecraft:chiseled_quartz_block,10,minecraft:quartz_pillar,10,minecraft:smooth_quartz_block,10,minecraft:quartz_block,100)
RB(-8,5,-1,minecraft:chiseled_quartz_block,10,minecraft:quartz_pillar,10,minecraft:smooth_quartz_block,10,minecraft:quartz_block,100)
RB(-8,6,-1,minecraft:chiseled_quartz_block,10,minecraft:quartz_pillar,10,minecraft:smooth_quartz_block,10,minecraft:quartz_block,100)
RB(-8,7,-1,minecraft:chiseled_quartz_block,10,minecraft:quartz_pillar,10,minecraft:smooth_quartz_block,10,minecraft:quartz_block,100)
RB(-8,8,-1,minecraft:chiseled_quartz_block,10,minecraft:quartz_pillar,10,minecraft:smooth_quartz_block,10,minecraft:quartz_block,100)
RB(-8,9,-1,minecraft:chiseled_quartz_block,10,minecraft:quartz_pillar,10,minecraft:smooth_quartz_block,10,minecraft:quartz_block,100)
RB(-8,0,0,minecraft:chiseled_quartz_block,10,minecraft:quartz_pillar,10,minecraft:smooth_quartz_block,10,minecraft:quartz_block,100)
RB(-8,1,0,minecraft:chiseled_quartz_block,10,minecraft:quartz_pillar,10,minecraft:smooth_quartz_block,10,minecraft:quartz_block,100)
RB(-8,2,0,minecraft:chiseled_quartz_block,10,minecraft:quartz_pillar,10,minecraft:smooth_quartz_block,10,minecraft:quartz_block,100)
RB(-8,3,0,minecraft:chiseled_quartz_block,10,minecraft:quartz_pillar,10,minecraft:smooth_quartz_block,10,minecraft:quartz_block,100)
RB(-8,4,0,minecraft:chiseled_quartz_block,10,minecraft:quartz_pillar,10,minecraft:smooth_quartz_block,10,minecraft:quartz_block,100)
RB(-8,5,0,minecraft:chiseled_quartz_block,10,minecraft:quartz_pillar,10,minecraft:smooth_quartz_block,10,minecraft:quartz_block,100)
RB(-8,6,0,minecraft:chiseled_quartz_block,10,minecraft:quartz_pillar,10,minecraft:smooth_quartz_block,10,minecraft:quartz_block,100)
RB(-8,7,0,minecraft:chiseled_quartz_block,10,minecraft:quartz_pillar,10,minecraft:smooth_quartz_block,10,minecraft:quartz_block,100)
RB(-8,8,0,minecraft:chiseled_quartz_block,10,minecraft:quartz_pillar,10,minecraft:smooth_quartz_block,10,minecraft:quartz_block,100)
RB(-8,0,1,minecraft:chiseled_quartz_block,10,minecraft:quartz_pillar,10,minecraft:smooth_quartz_block,10,minecraft:quartz_block,100)
RB(-8,1,1,minecraft:chiseled_quartz_block,10,minecraft:quartz_pillar,10,minecraft:smooth_quartz_block,10,minecraft:quartz_block,100)
RB(-8,2,1,minecraft:chiseled_quartz_block,10,minecraft:quartz_pillar,10,minecraft:smooth_quartz_block,10,minecraft:quartz_block,100)
RB(-8,3,1,minecraft:chiseled_quartz_block,10,minecraft:quartz_pillar,10,minecraft:smooth_quartz_block,10,minecraft:quartz_block,100)
RB(-8,4,1,minecraft:chiseled_quartz_block,10,minecraft:quartz_pillar,10,minecraft:smooth_quartz_block,10,minecraft:quartz_block,100)
RB(-8,5,1,minecraft:chiseled_quartz_block,10,minecraft:quartz_pillar,10,minecraft:smooth_quartz_block,10,minecraft:quartz_block,100)
RB(-8,6,1,minecraft:chiseled_quartz_block,10,minecraft:quartz_pillar,10,minecraft:smooth_quartz_block,10,minecraft:quartz_block,100)
RB(-8,7,1,minecraft:chiseled_quartz_block,10,minecraft:quartz_pillar,10,minecraft:smooth_quartz_block,10,minecraft:quartz_block,100)
RB(-8,0,2,minecraft:chiseled_quartz_block,10,minecraft:quartz_pillar,10,minecraft:smooth_quartz_block,10,minecraft:quartz_block,100)
RB(-8,1,2,minecraft:chiseled_quartz_block,10,minecraft:quartz_pillar,10,minecraft:smooth_quartz_block,10,minecraft:quartz_block,100)
RB(-8,2,2,minecraft:chiseled_quartz_block,10,minecraft:quartz_pillar,10,minecraft:smooth_quartz_block,10,minecraft:quartz_block,100)
RB(-8,3,2,minecraft:chiseled_quartz_block,10,minecraft:quartz_pillar,10,minecraft:smooth_quartz_block,10,minecraft:quartz_block,100)
RB(-8,4,2,minecraft:chiseled_quartz_block,10,minecraft:quartz_pillar,10,minecraft:smooth_quartz_block,10,minecraft:quartz_block,100)
RB(-8,5,2,minecraft:chiseled_quartz_block,10,minecraft:quartz_pillar,10,minecraft:smooth_quartz_block,10,minecraft:quartz_block,100)
RB(-8,6,2,minecraft:chiseled_quartz_block,10,minecraft:quartz_pillar,10,minecraft:smooth_quartz_block,10,minecraft:quartz_block,100)
RB(-8,0,3,minecraft:chiseled_quartz_block,10,minecraft:quartz_pillar,10,minecraft:smooth_quartz_block,10,minecraft:quartz_block,100)
RB(-8,1,3,minecraft:chiseled_quartz_block,10,minecraft:quartz_pillar,10,minecraft:smooth_quartz_block,10,minecraft:quartz_block,100)
RB(-8,2,3,minecraft:chiseled_quartz_block,10,minecraft:quartz_pillar,10,minecraft:smooth_quartz_block,10,minecraft:quartz_block,100)
RB(-8,3,3,minecraft:chiseled_quartz_block,10,minecraft:quartz_pillar,10,minecraft:smooth_quartz_block,10,minecraft:quartz_block,100)
RB(-8,4,3,minecraft:chiseled_quartz_block,10,minecraft:quartz_pillar,10,minecraft:smooth_quartz_block,10,minecraft:quartz_block,100)
RB(-8,5,3,minecraft:chiseled_quartz_block,10,minecraft:quartz_pillar,10,minecraft:smooth_quartz_block,10,minecraft:quartz_block,100)
RB(-8,0,4,minecraft:chiseled_quartz_block,10,minecraft:quartz_pillar,10,minecraft:smooth_quartz_block,10,minecraft:quartz_block,100)
RB(-8,1,4,minecraft:chiseled_quartz_block,10,minecraft:quartz_pillar,10,minecraft:smooth_quartz_block,10,minecraft:quartz_block,100)
RB(-8,2,4,minecraft:chiseled_quartz_block,10,minecraft:quartz_pillar,10,minecraft:smooth_quartz_block,10,minecraft:quartz_block,100)
RB(-8,3,4,minecraft:chiseled_quartz_block,10,minecraft:quartz_pillar,10,minecraft:smooth_quartz_block,10,minecraft:quartz_block,100)
RB(-8,4,4,minecraft:chiseled_quartz_block,10,minecraft:quartz_pillar,10,minecraft:smooth_quartz_block,10,minecraft:quartz_block,100)
RB(-8,0,5,minecraft:chiseled_quartz_block,10,minecraft:quartz_pillar,10,minecraft:smooth_quartz_block,10,minecraft:quartz_block,100)
RB(-8,1,5,minecraft:chiseled_quartz_block,10,minecraft:quartz_pillar,10,minecraft:smooth_quartz_block,10,minecraft:quartz_block,100)
RB(-8,2,5,minecraft:chiseled_quartz_block,10,minecraft:quartz_pillar,10,minecraft:smooth_quartz_block,10,minecraft:quartz_block,100)
RB(-8,3,5,minecraft:chiseled_quartz_block,10,minecraft:quartz_pillar,10,minecraft:smooth_quartz_block,10,minecraft:quartz_block,100)
RB(-8,0,6,minecraft:chiseled_quartz_block,10,minecraft:quartz_pillar,10,minecraft:smooth_quartz_block,10,minecraft:quartz_block,100)
RB(-8,1,6,minecraft:chiseled_quartz_block,10,minecraft:quartz_pillar,10,minecraft:smooth_quartz_block,10,minecraft:quartz_block,100)
RB(-8,2,6,minecraft:chiseled_quartz_block,10,minecraft:quartz_pillar,10,minecraft:smooth_quartz_block,10,minecraft:quartz_block,100)
RB(-8,0,7,minecraft:chiseled_quartz_block,10,minecraft:quartz_pillar,10,minecraft:smooth_quartz_block,10,minecraft:quartz_block,100)
RB(-8,1,7,minecraft:chiseled_quartz_block,10,minecraft:quartz_pillar,10,minecraft:smooth_quartz_block,10,minecraft:quartz_block,100)
RB(-8,0,8,minecraft:chiseled_quartz_block,10,minecraft:quartz_pillar,10,minecraft:smooth_quartz_block,10,minecraft:quartz_block,100)
RB(-7,13,-11,minecraft:chiseled_quartz_block,10,minecraft:quartz_pillar,10,minecraft:smooth_quartz_block,10,minecraft:quartz_block,100)
RB(-7,9,-10,minecraft:chiseled_quartz_block,10,minecraft:quartz_pillar,10,minecraft:smooth_quartz_block,10,minecraft:quartz_block,100)
RB(-7,10,-10,minecraft:chiseled_quartz_block,10,minecraft:quartz_pillar,10,minecraft:smooth_quartz_block,10,minecraft:quartz_block,100)
RB(-7,11,-10,minecraft:chiseled_quartz_block,10,minecraft:quartz_pillar,10,minecraft:smooth_quartz_block,10,minecraft:quartz_block,100)
RB(-7,12,-10,minecraft:chiseled_quartz_block,10,minecraft:quartz_pillar,10,minecraft:smooth_quartz_block,10,minecraft:quartz_block,100)
RB(-7,13,-10,minecraft:chiseled_quartz_block,10,minecraft:quartz_pillar,10,minecraft:smooth_quartz_block,10,minecraft:quartz_block,100)
RB(-7,14,-10,minecraft:chiseled_quartz_block,10,minecraft:quartz_pillar,10,minecraft:smooth_quartz_block,10,minecraft:quartz_block,100)
RB(-7,6,-9,minecraft:chiseled_quartz_block,10,minecraft:quartz_pillar,10,minecraft:smooth_quartz_block,10,minecraft:quartz_block,100)
RB(-7,7,-9,minecraft:chiseled_quartz_block,10,minecraft:quartz_pillar,10,minecraft:smooth_quartz_block,10,minecraft:quartz_block,100)
RB(-7,8,-9,minecraft:chiseled_quartz_block,10,minecraft:quartz_pillar,10,minecraft:smooth_quartz_block,10,minecraft:quartz_block,100)
RB(-7,9,-9,minecraft:chiseled_quartz_block,10,minecraft:quartz_pillar,10,minecraft:smooth_quartz_block,10,minecraft:quartz_block,100)
RB(-7,10,-9,minecraft:chiseled_quartz_block,10,minecraft:quartz_pillar,10,minecraft:smooth_quartz_block,10,minecraft:quartz_block,100)
RB(-7,11,-9,minecraft:chiseled_quartz_block,10,minecraft:quartz_pillar,10,minecraft:smooth_quartz_block,10,minecraft:quartz_block,100)
RB(-7,12,-9,minecraft:chiseled_quartz_block,10,minecraft:quartz_pillar,10,minecraft:smooth_quartz_block,10,minecraft:quartz_block,100)
RB(-7,13,-9,minecraft:chiseled_quartz_block,10,minecraft:quartz_pillar,10,minecraft:smooth_quartz_block,10,minecraft:quartz_block,100)
RB(-7,14,-9,minecraft:chiseled_quartz_block,10,minecraft:quartz_pillar,10,minecraft:smooth_quartz_block,10,minecraft:quartz_block,100)
RB(-7,2,-8,minecraft:chiseled_quartz_block,10,minecraft:quartz_pillar,10,minecraft:smooth_quartz_block,10,minecraft:quartz_block,100)
RB(-7,3,-8,minecraft:chiseled_quartz_block,10,minecraft:quartz_pillar,10,minecraft:smooth_quartz_block,10,minecraft:quartz_block,100)
RB(-7,4,-8,minecraft:chiseled_quartz_block,10,minecraft:quartz_pillar,10,minecraft:smooth_quartz_block,10,minecraft:quartz_block,100)
RB(-7,5,-8,minecraft:chiseled_quartz_block,10,minecraft:quartz_pillar,10,minecraft:smooth_quartz_block,10,minecraft:quartz_block,100)
RB(-7,6,-8,minecraft:chiseled_quartz_block,10,minecraft:quartz_pillar,10,minecraft:smooth_quartz_block,10,minecraft:quartz_block,100)
RB(-7,7,-8,minecraft:chiseled_quartz_block,10,minecraft:quartz_pillar,10,minecraft:smooth_quartz_block,10,minecraft:quartz_block,100)
RB(-7,8,-8,minecraft:chiseled_quartz_block,10,minecraft:quartz_pillar,10,minecraft:smooth_quartz_block,10,minecraft:quartz_block,100)
RB(-7,9,-8,minecraft:chiseled_quartz_block,10,minecraft:quartz_pillar,10,minecraft:smooth_quartz_block,10,minecraft:quartz_block,100)
RB(-7,10,-8,minecraft:chiseled_quartz_block,10,minecraft:quartz_pillar,10,minecraft:smooth_quartz_block,10,minecraft:quartz_block,100)
RB(-7,11,-8,minecraft:chiseled_quartz_block,10,minecraft:quartz_pillar,10,minecraft:smooth_quartz_block,10,minecraft:quartz_block,100)
RB(-7,12,-8,minecraft:chiseled_quartz_block,10,minecraft:quartz_pillar,10,minecraft:smooth_quartz_block,10,minecraft:quartz_block,100)
RB(-7,13,-8,minecraft:chiseled_quartz_block,10,minecraft:quartz_pillar,10,minecraft:smooth_quartz_block,10,minecraft:quartz_block,100)
RB(-7,0,-7,minecraft:chiseled_quartz_block,10,minecraft:quartz_pillar,10,minecraft:smooth_quartz_block,10,minecraft:quartz_block,100)
RB(-7,1,-7,minecraft:chiseled_quartz_block,10,minecraft:quartz_pillar,10,minecraft:smooth_quartz_block,10,minecraft:quartz_block,100)
RB(-7,2,-7,minecraft:chiseled_quartz_block,10,minecraft:quartz_pillar,10,minecraft:smooth_quartz_block,10,minecraft:quartz_block,100)
RB(-7,3,-7,minecraft:chiseled_quartz_block,10,minecraft:quartz_pillar,10,minecraft:smooth_quartz_block,10,minecraft:quartz_block,100)
RB(-7,4,-7,minecraft:chiseled_quartz_block,10,minecraft:quartz_pillar,10,minecraft:smooth_quartz_block,10,minecraft:quartz_block,100)
RB(-7,5,-7,minecraft:chiseled_quartz_block,10,minecraft:quartz_pillar,10,minecraft:smooth_quartz_block,10,minecraft:quartz_block,100)
RB(-7,6,-7,minecraft:chiseled_quartz_block,10,minecraft:quartz_pillar,10,minecraft:smooth_quartz_block,10,minecraft:quartz_block,100)
RB(-7,7,-7,minecraft:chiseled_quartz_block,10,minecraft:quartz_pillar,10,minecraft:smooth_quartz_block,10,minecraft:quartz_block,100)
RB(-7,8,-7,minecraft:chiseled_quartz_block,10,minecraft:quartz_pillar,10,minecraft:smooth_quartz_block,10,minecraft:quartz_block,100)
RB(-7,9,-7,minecraft:chiseled_quartz_block,10,minecraft:quartz_pillar,10,minecraft:smooth_quartz_block,10,minecraft:quartz_block,100)
RB(-7,10,-7,minecraft:chiseled_quartz_block,10,minecraft:quartz_pillar,10,minecraft:smooth_quartz_block,10,minecraft:quartz_block,100)
RB(-7,11,-7,minecraft:chiseled_quartz_block,10,minecraft:quartz_pillar,10,minecraft:smooth_quartz_block,10,minecraft:quartz_block,100)
RB(-7,12,-7,minecraft:chiseled_quartz_block,10,minecraft:quartz_pillar,10,minecraft:smooth_quartz_block,10,minecraft:quartz_block,100)
RB(-7,13,-7,minecraft:chiseled_quartz_block,10,minecraft:quartz_pillar,10,minecraft:smooth_quartz_block,10,minecraft:quartz_block,100)
RB(-7,0,-6,minecraft:chiseled_quartz_block,10,minecraft:quartz_pillar,10,minecraft:smooth_quartz_block,10,minecraft:quartz_block,100)
RB(-7,1,-6,minecraft:chiseled_quartz_block,10,minecraft:quartz_pillar,10,minecraft:smooth_quartz_block,10,minecraft:quartz_block,100)
RB(-7,2,-6,minecraft:chiseled_quartz_block,10,minecraft:quartz_pillar,10,minecraft:smooth_quartz_block,10,minecraft:quartz_block,100)
RB(-7,3,-6,minecraft:chiseled_quartz_block,10,minecraft:quartz_pillar,10,minecraft:smooth_quartz_block,10,minecraft:quartz_block,100)
RB(-7,4,-6,minecraft:chiseled_quartz_block,10,minecraft:quartz_pillar,10,minecraft:smooth_quartz_block,10,minecraft:quartz_block,100)
RB(-7,5,-6,minecraft:chiseled_quartz_block,10,minecraft:quartz_pillar,10,minecraft:smooth_quartz_block,10,minecraft:quartz_block,100)
RB(-7,6,-6,minecraft:chiseled_quartz_block,10,minecraft:quartz_pillar,10,minecraft:smooth_quartz_block,10,minecraft:quartz_block,100)
RB(-7,7,-6,minecraft:chiseled_quartz_block,10,minecraft:quartz_pillar,10,minecraft:smooth_quartz_block,10,minecraft:quartz_block,100)
RB(-7,8,-6,minecraft:chiseled_quartz_block,10,minecraft:quartz_pillar,10,minecraft:smooth_quartz_block,10,minecraft:quartz_block,100)
RB(-7,9,-6,minecraft:chiseled_quartz_block,10,minecraft:quartz_pillar,10,minecraft:smooth_quartz_block,10,minecraft:quartz_block,100)
RB(-7,10,-6,minecraft:chiseled_quartz_block,10,minecraft:quartz_pillar,10,minecraft:smooth_quartz_block,10,minecraft:quartz_block,100)
RB(-7,11,-6,minecraft:chiseled_quartz_block,10,minecraft:quartz_pillar,10,minecraft:smooth_quartz_block,10,minecraft:quartz_block,100)
RB(-7,12,-6,minecraft:chiseled_quartz_block,10,minecraft:quartz_pillar,10,minecraft:smooth_quartz_block,10,minecraft:quartz_block,100)
RB(-7,13,-6,minecraft:chiseled_quartz_block,10,minecraft:quartz_pillar,10,minecraft:smooth_quartz_block,10,minecraft:quartz_block,100)
RB(-7,0,-5,minecraft:chiseled_quartz_block,10,minecraft:quartz_pillar,10,minecraft:smooth_quartz_block,10,minecraft:quartz_block,100)
RB(-7,1,-5,minecraft:chiseled_quartz_block,10,minecraft:quartz_pillar,10,minecraft:smooth_quartz_block,10,minecraft:quartz_block,100)
RB(-7,2,-5,minecraft:chiseled_quartz_block,10,minecraft:quartz_pillar,10,minecraft:smooth_quartz_block,10,minecraft:quartz_block,100)
RB(-7,3,-5,minecraft:chiseled_quartz_block,10,minecraft:quartz_pillar,10,minecraft:smooth_quartz_block,10,minecraft:quartz_block,100)
RB(-7,4,-5,minecraft:chiseled_quartz_block,10,minecraft:quartz_pillar,10,minecraft:smooth_quartz_block,10,minecraft:quartz_block,100)
RB(-7,5,-5,minecraft:chiseled_quartz_block,10,minecraft:quartz_pillar,10,minecraft:smooth_quartz_block,10,minecraft:quartz_block,100)
RB(-7,6,-5,minecraft:chiseled_quartz_block,10,minecraft:quartz_pillar,10,minecraft:smooth_quartz_block,10,minecraft:quartz_block,100)
RB(-7,7,-5,minecraft:chiseled_quartz_block,10,minecraft:quartz_pillar,10,minecraft:smooth_quartz_block,10,minecraft:quartz_block,100)
RB(-7,8,-5,minecraft:chiseled_quartz_block,10,minecraft:quartz_pillar,10,minecraft:smooth_quartz_block,10,minecraft:quartz_block,100)
RB(-7,9,-5,minecraft:chiseled_quartz_block,10,minecraft:quartz_pillar,10,minecraft:smooth_quartz_block,10,minecraft:quartz_block,100)
RB(-7,10,-5,minecraft:chiseled_quartz_block,10,minecraft:quartz_pillar,10,minecraft:smooth_quartz_block,10,minecraft:quartz_block,100)
RB(-7,11,-5,minecraft:chiseled_quartz_block,10,minecraft:quartz_pillar,10,minecraft:smooth_quartz_block,10,minecraft:quartz_block,100)
RB(-7,12,-5,minecraft:chiseled_quartz_block,10,minecraft:quartz_pillar,10,minecraft:smooth_quartz_block,10,minecraft:quartz_block,100)
RB(-7,0,-4,minecraft:chiseled_quartz_block,10,minecraft:quartz_pillar,10,minecraft:smooth_quartz_block,10,minecraft:quartz_block,100)
RB(-7,1,-4,minecraft:chiseled_quartz_block,10,minecraft:quartz_pillar,10,minecraft:smooth_quartz_block,10,minecraft:quartz_block,100)
RB(-7,2,-4,minecraft:chiseled_quartz_block,10,minecraft:quartz_pillar,10,minecraft:smooth_quartz_block,10,minecraft:quartz_block,100)
RB(-7,3,-4,minecraft:chiseled_quartz_block,10,minecraft:quartz_pillar,10,minecraft:smooth_quartz_block,10,minecraft:quartz_block,100)
RB(-7,4,-4,minecraft:chiseled_quartz_block,10,minecraft:quartz_pillar,10,minecraft:smooth_quartz_block,10,minecraft:quartz_block,100)
RB(-7,5,-4,minecraft:chiseled_quartz_block,10,minecraft:quartz_pillar,10,minecraft:smooth_quartz_block,10,minecraft:quartz_block,100)
RB(-7,6,-4,minecraft:chiseled_quartz_block,10,minecraft:quartz_pillar,10,minecraft:smooth_quartz_block,10,minecraft:quartz_block,100)
RB(-7,7,-4,minecraft:chiseled_quartz_block,10,minecraft:quartz_pillar,10,minecraft:smooth_quartz_block,10,minecraft:quartz_block,100)
RB(-7,8,-4,minecraft:chiseled_quartz_block,10,minecraft:quartz_pillar,10,minecraft:smooth_quartz_block,10,minecraft:quartz_block,100)
RB(-7,9,-4,minecraft:chiseled_quartz_block,10,minecraft:quartz_pillar,10,minecraft:smooth_quartz_block,10,minecraft:quartz_block,100)
RB(-7,10,-4,minecraft:chiseled_quartz_block,10,minecraft:quartz_pillar,10,minecraft:smooth_quartz_block,10,minecraft:quartz_block,100)
RB(-7,11,-4,minecraft:chiseled_quartz_block,10,minecraft:quartz_pillar,10,minecraft:smooth_quartz_block,10,minecraft:quartz_block,100)
RB(-7,0,-3,minecraft:chiseled_quartz_block,10,minecraft:quartz_pillar,10,minecraft:smooth_quartz_block,10,minecraft:quartz_block,100)
RB(-7,1,-3,minecraft:chiseled_quartz_block,10,minecraft:quartz_pillar,10,minecraft:smooth_quartz_block,10,minecraft:quartz_block,100)
RB(-7,2,-3,minecraft:chiseled_quartz_block,10,minecraft:quartz_pillar,10,minecraft:smooth_quartz_block,10,minecraft:quartz_block,100)
RB(-7,3,-3,minecraft:chiseled_quartz_block,10,minecraft:quartz_pillar,10,minecraft:smooth_quartz_block,10,minecraft:quartz_block,100)
RB(-7,4,-3,minecraft:chiseled_quartz_block,10,minecraft:quartz_pillar,10,minecraft:smooth_quartz_block,10,minecraft:quartz_block,100)
RB(-7,5,-3,minecraft:chiseled_quartz_block,10,minecraft:quartz_pillar,10,minecraft:smooth_quartz_block,10,minecraft:quartz_block,100)
RB(-7,6,-3,minecraft:chiseled_quartz_block,10,minecraft:quartz_pillar,10,minecraft:smooth_quartz_block,10,minecraft:quartz_block,100)
RB(-7,7,-3,minecraft:chiseled_quartz_block,10,minecraft:quartz_pillar,10,minecraft:smooth_quartz_block,10,minecraft:quartz_block,100)
RB(-7,8,-3,minecraft:chiseled_quartz_block,10,minecraft:quartz_pillar,10,minecraft:smooth_quartz_block,10,minecraft:quartz_block,100)
RB(-7,9,-3,minecraft:chiseled_quartz_block,10,minecraft:quartz_pillar,10,minecraft:smooth_quartz_block,10,minecraft:quartz_block,100)
RB(-7,10,-3,minecraft:chiseled_quartz_block,10,minecraft:quartz_pillar,10,minecraft:smooth_quartz_block,10,minecraft:quartz_block,100)
RB(-7,11,-3,minecraft:chiseled_quartz_block,10,minecraft:quartz_pillar,10,minecraft:smooth_quartz_block,10,minecraft:quartz_block,100)
RB(-7,0,-2,minecraft:chiseled_quartz_block,10,minecraft:quartz_pillar,10,minecraft:smooth_quartz_block,10,minecraft:quartz_block,100)
RB(-7,1,-2,minecraft:chiseled_quartz_block,10,minecraft:quartz_pillar,10,minecraft:smooth_quartz_block,10,minecraft:quartz_block,100)
RB(-7,2,-2,minecraft:chiseled_quartz_block,10,minecraft:quartz_pillar,10,minecraft:smooth_quartz_block,10,minecraft:quartz_block,100)
RB(-7,3,-2,minecraft:chiseled_quartz_block,10,minecraft:quartz_pillar,10,minecraft:smooth_quartz_block,10,minecraft:quartz_block,100)
RB(-7,4,-2,minecraft:chiseled_quartz_block,10,minecraft:quartz_pillar,10,minecraft:smooth_quartz_block,10,minecraft:quartz_block,100)
RB(-7,5,-2,minecraft:chiseled_quartz_block,10,minecraft:quartz_pillar,10,minecraft:smooth_quartz_block,10,minecraft:quartz_block,100)
RB(-7,6,-2,minecraft:chiseled_quartz_block,10,minecraft:quartz_pillar,10,minecraft:smooth_quartz_block,10,minecraft:quartz_block,100)
RB(-7,7,-2,minecraft:chiseled_quartz_block,10,minecraft:quartz_pillar,10,minecraft:smooth_quartz_block,10,minecraft:quartz_block,100)
RB(-7,8,-2,minecraft:chiseled_quartz_block,10,minecraft:quartz_pillar,10,minecraft:smooth_quartz_block,10,minecraft:quartz_block,100)
RB(-7,9,-2,minecraft:chiseled_quartz_block,10,minecraft:quartz_pillar,10,minecraft:smooth_quartz_block,10,minecraft:quartz_block,100)
RB(-7,10,-2,minecraft:chiseled_quartz_block,10,minecraft:quartz_pillar,10,minecraft:smooth_quartz_block,10,minecraft:quartz_block,100)
RB(-7,0,-1,minecraft:chiseled_quartz_block,10,minecraft:quartz_pillar,10,minecraft:smooth_quartz_block,10,minecraft:quartz_block,100)
RB(-7,1,-1,minecraft:chiseled_quartz_block,10,minecraft:quartz_pillar,10,minecraft:smooth_quartz_block,10,minecraft:quartz_block,100)
RB(-7,2,-1,minecraft:chiseled_quartz_block,10,minecraft:quartz_pillar,10,minecraft:smooth_quartz_block,10,minecraft:quartz_block,100)
RB(-7,3,-1,minecraft:chiseled_quartz_block,10,minecraft:quartz_pillar,10,minecraft:smooth_quartz_block,10,minecraft:quartz_block,100)
RB(-7,4,-1,minecraft:chiseled_quartz_block,10,minecraft:quartz_pillar,10,minecraft:smooth_quartz_block,10,minecraft:quartz_block,100)
RB(-7,5,-1,minecraft:chiseled_quartz_block,10,minecraft:quartz_pillar,10,minecraft:smooth_quartz_block,10,minecraft:quartz_block,100)
RB(-7,6,-1,minecraft:chiseled_quartz_block,10,minecraft:quartz_pillar,10,minecraft:smooth_quartz_block,10,minecraft:quartz_block,100)
RB(-7,7,-1,minecraft:chiseled_quartz_block,10,minecraft:quartz_pillar,10,minecraft:smooth_quartz_block,10,minecraft:quartz_block,100)
RB(-7,8,-1,minecraft:chiseled_quartz_block,10,minecraft:quartz_pillar,10,minecraft:smooth_quartz_block,10,minecraft:quartz_block,100)
RB(-7,9,-1,minecraft:chiseled_quartz_block,10,minecraft:quartz_pillar,10,minecraft:smooth_quartz_block,10,minecraft:quartz_block,100)
RB(-7,10,-1,minecraft:chiseled_quartz_block,10,minecraft:quartz_pillar,10,minecraft:smooth_quartz_block,10,minecraft:quartz_block,100)
RB(-7,0,0,minecraft:chiseled_quartz_block,10,minecraft:quartz_pillar,10,minecraft:smooth_quartz_block,10,minecraft:quartz_block,100)
RB(-7,1,0,minecraft:chiseled_quartz_block,10,minecraft:quartz_pillar,10,minecraft:smooth_quartz_block,10,minecraft:quartz_block,100)
RB(-7,2,0,minecraft:chiseled_quartz_block,10,minecraft:quartz_pillar,10,minecraft:smooth_quartz_block,10,minecraft:quartz_block,100)
RB(-7,3,0,minecraft:chiseled_quartz_block,10,minecraft:quartz_pillar,10,minecraft:smooth_quartz_block,10,minecraft:quartz_block,100)
RB(-7,4,0,minecraft:chiseled_quartz_block,10,minecraft:quartz_pillar,10,minecraft:smooth_quartz_block,10,minecraft:quartz_block,100)
RB(-7,5,0,minecraft:chiseled_quartz_block,10,minecraft:quartz_pillar,10,minecraft:smooth_quartz_block,10,minecraft:quartz_block,100)
RB(-7,6,0,minecraft:chiseled_quartz_block,10,minecraft:quartz_pillar,10,minecraft:smooth_quartz_block,10,minecraft:quartz_block,100)
RB(-7,7,0,minecraft:chiseled_quartz_block,10,minecraft:quartz_pillar,10,minecraft:smooth_quartz_block,10,minecraft:quartz_block,100)
RB(-7,8,0,minecraft:chiseled_quartz_block,10,minecraft:quartz_pillar,10,minecraft:smooth_quartz_block,10,minecraft:quartz_block,100)
RB(-7,9,0,minecraft:chiseled_quartz_block,10,minecraft:quartz_pillar,10,minecraft:smooth_quartz_block,10,minecraft:quartz_block,100)
RB(-7,0,1,minecraft:chiseled_quartz_block,10,minecraft:quartz_pillar,10,minecraft:smooth_quartz_block,10,minecraft:quartz_block,100)
RB(-7,1,1,minecraft:chiseled_quartz_block,10,minecraft:quartz_pillar,10,minecraft:smooth_quartz_block,10,minecraft:quartz_block,100)
RB(-7,2,1,minecraft:chiseled_quartz_block,10,minecraft:quartz_pillar,10,minecraft:smooth_quartz_block,10,minecraft:quartz_block,100)
RB(-7,3,1,minecraft:chiseled_quartz_block,10,minecraft:quartz_pillar,10,minecraft:smooth_quartz_block,10,minecraft:quartz_block,100)
RB(-7,4,1,minecraft:chiseled_quartz_block,10,minecraft:quartz_pillar,10,minecraft:smooth_quartz_block,10,minecraft:quartz_block,100)
RB(-7,5,1,minecraft:chiseled_quartz_block,10,minecraft:quartz_pillar,10,minecraft:smooth_quartz_block,10,minecraft:quartz_block,100)
RB(-7,6,1,minecraft:chiseled_quartz_block,10,minecraft:quartz_pillar,10,minecraft:smooth_quartz_block,10,minecraft:quartz_block,100)
RB(-7,7,1,minecraft:chiseled_quartz_block,10,minecraft:quartz_pillar,10,minecraft:smooth_quartz_block,10,minecraft:quartz_block,100)
RB(-7,8,1,minecraft:chiseled_quartz_block,10,minecraft:quartz_pillar,10,minecraft:smooth_quartz_block,10,minecraft:quartz_block,100)
RB(-7,0,2,minecraft:chiseled_quartz_block,10,minecraft:quartz_pillar,10,minecraft:smooth_quartz_block,10,minecraft:quartz_block,100)
RB(-7,1,2,minecraft:chiseled_quartz_block,10,minecraft:quartz_pillar,10,minecraft:smooth_quartz_block,10,minecraft:quartz_block,100)
RB(-7,2,2,minecraft:chiseled_quartz_block,10,minecraft:quartz_pillar,10,minecraft:smooth_quartz_block,10,minecraft:quartz_block,100)
RB(-7,3,2,minecraft:chiseled_quartz_block,10,minecraft:quartz_pillar,10,minecraft:smooth_quartz_block,10,minecraft:quartz_block,100)
RB(-7,4,2,minecraft:chiseled_quartz_block,10,minecraft:quartz_pillar,10,minecraft:smooth_quartz_block,10,minecraft:quartz_block,100)
RB(-7,5,2,minecraft:chiseled_quartz_block,10,minecraft:quartz_pillar,10,minecraft:smooth_quartz_block,10,minecraft:quartz_block,100)
RB(-7,6,2,minecraft:chiseled_quartz_block,10,minecraft:quartz_pillar,10,minecraft:smooth_quartz_block,10,minecraft:quartz_block,100)
RB(-7,7,2,minecraft:chiseled_quartz_block,10,minecraft:quartz_pillar,10,minecraft:smooth_quartz_block,10,minecraft:quartz_block,100)
RB(-7,0,3,minecraft:chiseled_quartz_block,10,minecraft:quartz_pillar,10,minecraft:smooth_quartz_block,10,minecraft:quartz_block,100)
RB(-7,1,3,minecraft:chiseled_quartz_block,10,minecraft:quartz_pillar,10,minecraft:smooth_quartz_block,10,minecraft:quartz_block,100)
RB(-7,2,3,minecraft:chiseled_quartz_block,10,minecraft:quartz_pillar,10,minecraft:smooth_quartz_block,10,minecraft:quartz_block,100)
RB(-7,3,3,minecraft:chiseled_quartz_block,10,minecraft:quartz_pillar,10,minecraft:smooth_quartz_block,10,minecraft:quartz_block,100)
RB(-7,4,3,minecraft:chiseled_quartz_block,10,minecraft:quartz_pillar,10,minecraft:smooth_quartz_block,10,minecraft:quartz_block,100)
RB(-7,5,3,minecraft:chiseled_quartz_block,10,minecraft:quartz_pillar,10,minecraft:smooth_quartz_block,10,minecraft:quartz_block,100)
RB(-7,6,3,minecraft:chiseled_quartz_block,10,minecraft:quartz_pillar,10,minecraft:smooth_quartz_block,10,minecraft:quartz_block,100)
RB(-7,0,4,minecraft:chiseled_quartz_block,10,minecraft:quartz_pillar,10,minecraft:smooth_quartz_block,10,minecraft:quartz_block,100)
RB(-7,1,4,minecraft:chiseled_quartz_block,10,minecraft:quartz_pillar,10,minecraft:smooth_quartz_block,10,minecraft:quartz_block,100)
RB(-7,2,4,minecraft:chiseled_quartz_block,10,minecraft:quartz_pillar,10,minecraft:smooth_quartz_block,10,minecraft:quartz_block,100)
RB(-7,3,4,minecraft:chiseled_quartz_block,10,minecraft:quartz_pillar,10,minecraft:smooth_quartz_block,10,minecraft:quartz_block,100)
RB(-7,4,4,minecraft:chiseled_quartz_block,10,minecraft:quartz_pillar,10,minecraft:smooth_quartz_block,10,minecraft:quartz_block,100)
RB(-7,5,4,minecraft:chiseled_quartz_block,10,minecraft:quartz_pillar,10,minecraft:smooth_quartz_block,10,minecraft:quartz_block,100)
RB(-7,0,5,minecraft:chiseled_quartz_block,10,minecraft:quartz_pillar,10,minecraft:smooth_quartz_block,10,minecraft:quartz_block,100)
RB(-7,1,5,minecraft:chiseled_quartz_block,10,minecraft:quartz_pillar,10,minecraft:smooth_quartz_block,10,minecraft:quartz_block,100)
RB(-7,2,5,minecraft:chiseled_quartz_block,10,minecraft:quartz_pillar,10,minecraft:smooth_quartz_block,10,minecraft:quartz_block,100)
RB(-7,3,5,minecraft:chiseled_quartz_block,10,minecraft:quartz_pillar,10,minecraft:smooth_quartz_block,10,minecraft:quartz_block,100)
RB(-7,4,5,minecraft:chiseled_quartz_block,10,minecraft:quartz_pillar,10,minecraft:smooth_quartz_block,10,minecraft:quartz_block,100)
RB(-7,0,6,minecraft:chiseled_quartz_block,10,minecraft:quartz_pillar,10,minecraft:smooth_quartz_block,10,minecraft:quartz_block,100)
RB(-7,1,6,minecraft:chiseled_quartz_block,10,minecraft:quartz_pillar,10,minecraft:smooth_quartz_block,10,minecraft:quartz_block,100)
RB(-7,2,6,minecraft:chiseled_quartz_block,10,minecraft:quartz_pillar,10,minecraft:smooth_quartz_block,10,minecraft:quartz_block,100)
RB(-7,3,6,minecraft:chiseled_quartz_block,10,minecraft:quartz_pillar,10,minecraft:smooth_quartz_block,10,minecraft:quartz_block,100)
RB(-7,0,7,minecraft:chiseled_quartz_block,10,minecraft:quartz_pillar,10,minecraft:smooth_quartz_block,10,minecraft:quartz_block,100)
RB(-7,1,7,minecraft:chiseled_quartz_block,10,minecraft:quartz_pillar,10,minecraft:smooth_quartz_block,10,minecraft:quartz_block,100)
