
#######################################################################
# +-----------------------------------------------------------------+ #
# |                            BO3 object                           | #
# +-----------------------------------------------------------------+ #
#######################################################################

Author: Frank

Description: Shroomlight tree

Version: 3

SettingsMode: WriteDisable


#######################################################################
# +-----------------------------------------------------------------+ #
# |                          Main settings                          | #
# +-----------------------------------------------------------------+ #
#######################################################################

Tree: true

Frequency: 3

Rarity: 100.0

MaxSpawn: 2

RotateRandomly: true

SpawnHeight: randomY

SpawnHeightOffset: 0

SpawnHeightVariance: 0

##############################
# Height Limits for the BO3. #
##############################

MinHeight: 50

MaxHeight: 65

######################
# Extrusion settings #
######################

ExtrudeMode: None

ExtrudeThroughBlocks: minecraft:air

MaxBranchDepth: 10


#######################################################################
# +-----------------------------------------------------------------+ #
# |                      Source block settings                      | #
# +-----------------------------------------------------------------+ #
#######################################################################

SourceBlocks: minecraft:air

MaxPercentageOutsideSourceBlock: 10

OutsideSourceBlock: placeAnyway

DoReplaceBlocks: true

IsOTGPlus: false


#######################################################################
# +-----------------------------------------------------------------+ #
# |                              Blocks                             | #
# +-----------------------------------------------------------------+ #
#######################################################################

B(-4,9,-2,minecraft:shroomlight)
B(-4,9,-1,minecraft:shroomlight)
B(-4,9,0,minecraft:shroomlight)
B(-3,9,-3,minecraft:shroomlight)
B(-3,10,-2,minecraft:shroomlight)
B(-3,5,-1,minecraft:mushroom_stem[down=true,east=false,north=true,south=false,up=true,west=true])
B(-3,10,-1,minecraft:shroomlight)
B(-3,5,0,minecraft:mushroom_stem[down=true,east=true,north=false,south=false,up=true,west=true])
B(-3,10,0,minecraft:shroomlight)
B(-3,0,1,minecraft:mushroom_stem[down=true,east=true,north=true,south=true,up=false,west=true])
B(-3,1,1,minecraft:mushroom_stem[down=false,east=true,north=true,south=true,up=false,west=true])
B(-3,2,1,minecraft:mushroom_stem[down=false,east=true,north=true,south=true,up=false,west=true])
B(-3,3,1,minecraft:mushroom_stem[down=false,east=true,north=true,south=true,up=false,west=true])
B(-3,4,1,minecraft:mushroom_stem[down=false,east=true,north=true,south=true,up=false,west=true])
B(-3,5,1,minecraft:mushroom_stem[down=false,east=true,north=false,south=true,up=true,west=true])
B(-3,9,1,minecraft:shroomlight)
B(-2,9,-4,minecraft:shroomlight)
B(-2,10,-3,minecraft:shroomlight)
B(-2,10,-2,minecraft:shroomlight)
B(-2,11,-2,minecraft:shroomlight)
B(-2,5,-1,minecraft:mushroom_stem[down=true,east=false,north=true,south=true,up=true,west=false])
B(-2,10,-1,minecraft:shroomlight)
B(-2,11,-1,minecraft:shroomlight)
B(-2,10,0,minecraft:shroomlight)
B(-2,11,0,minecraft:shroomlight)
B(-2,10,1,minecraft:shroomlight)
B(-2,9,2,minecraft:shroomlight)
B(-1,9,-4,minecraft:shroomlight)
B(-1,10,-3,minecraft:shroomlight)
B(-1,10,-2,minecraft:shroomlight)
B(-1,11,-2,minecraft:shroomlight)
B(-1,5,-1,minecraft:mushroom_stem[down=true,east=true,north=true,south=true,up=false,west=false])
B(-1,6,-1,minecraft:mushroom_stem[down=false,east=true,north=true,south=true,up=false,west=true])
B(-1,7,-1,minecraft:mushroom_stem[down=false,east=true,north=true,south=true,up=false,west=true])
B(-1,8,-1,minecraft:mushroom_stem[down=false,east=true,north=true,south=true,up=false,west=true])
B(-1,9,-1,minecraft:mushroom_stem[down=false,east=true,north=true,south=true,up=true,west=true])
B(-1,10,-1,minecraft:shroomlight)
B(-1,11,-1,minecraft:shroomlight)
B(-1,10,0,minecraft:shroomlight)
B(-1,11,0,minecraft:shroomlight)
B(-1,10,1,minecraft:shroomlight)
B(-1,9,2,minecraft:shroomlight)
B(0,9,-4,minecraft:shroomlight)
B(0,10,-3,minecraft:shroomlight)
B(0,10,-2,minecraft:shroomlight)
B(0,11,-2,minecraft:shroomlight)
B(0,10,-1,minecraft:shroomlight)
B(0,11,-1,minecraft:shroomlight)
B(0,10,0,minecraft:shroomlight)
B(0,11,0,minecraft:shroomlight)
B(0,10,1,minecraft:shroomlight)
B(0,9,2,minecraft:shroomlight)
B(1,9,-3,minecraft:shroomlight)
B(1,10,-2,minecraft:shroomlight)
B(1,10,-1,minecraft:shroomlight)
B(1,10,0,minecraft:shroomlight)
B(1,9,1,minecraft:shroomlight)
B(2,9,-2,minecraft:shroomlight)
B(2,9,-1,minecraft:shroomlight)
B(2,9,0,minecraft:shroomlight)

#######################################################################
# +-----------------------------------------------------------------+ #
# |                            BO3 checks                           | #
# +-----------------------------------------------------------------+ #
#######################################################################

BlockCheckNot(-3,-1,1,minecraft:air)
BlockCheck(-3,2,1,minecraft:air)

#######################################################################
# +-----------------------------------------------------------------+ #
# |                             Branches                            | #
# +-----------------------------------------------------------------+ #
#######################################################################


#######################################################################
# +-----------------------------------------------------------------+ #
# |                             Entities                            | #
# +-----------------------------------------------------------------+ #
#######################################################################

