
#######################################################################
# +-----------------------------------------------------------------+ #
# |                            BO3 object                           | #
# +-----------------------------------------------------------------+ #
#######################################################################

Author: Frank

Description: Shroomlight tree 3

Version: 3

SettingsMode: WriteDisable


#######################################################################
# +-----------------------------------------------------------------+ #
# |                          Main settings                          | #
# +-----------------------------------------------------------------+ #
#######################################################################

Tree: true

Frequency: 3

Rarity: 100.0

MaxSpawn: 2

RotateRandomly: false

SpawnHeight: randomY

SpawnHeightOffset: 0

SpawnHeightVariance: 0

##############################
# Height Limits for the BO3. #
##############################

MinHeight: 50

MaxHeight: 65

######################
# Extrusion settings #
######################

ExtrudeMode: None

ExtrudeThroughBlocks: minecraft:air

MaxBranchDepth: 10


#######################################################################
# +-----------------------------------------------------------------+ #
# |                      Source block settings                      | #
# +-----------------------------------------------------------------+ #
#######################################################################

SourceBlocks: minecraft:air

MaxPercentageOutsideSourceBlock: 10

OutsideSourceBlock: placeAnyway

DoReplaceBlocks: true

IsOTGPlus: false


#######################################################################
# +-----------------------------------------------------------------+ #
# |                              Blocks                             | #
# +-----------------------------------------------------------------+ #
#######################################################################

B(-2,7,-1,minecraft:shroomlight)
B(-2,7,0,minecraft:shroomlight)
B(-2,7,1,minecraft:shroomlight)
B(-1,7,-2,minecraft:shroomlight)
B(-1,8,-1,minecraft:shroomlight)
B(-1,8,0,minecraft:shroomlight)
B(-1,8,1,minecraft:shroomlight)
B(-1,7,2,minecraft:shroomlight)
B(0,7,-3,minecraft:shroomlight)
B(0,8,-2,minecraft:shroomlight)
B(0,8,-1,minecraft:shroomlight)
B(0,9,-1,minecraft:shroomlight)
B(0,8,0,minecraft:shroomlight)
B(0,9,0,minecraft:shroomlight)
B(0,8,1,minecraft:shroomlight)
B(0,9,1,minecraft:shroomlight)
B(0,8,2,minecraft:shroomlight)
B(0,7,3,minecraft:shroomlight)
B(1,7,-3,minecraft:shroomlight)
B(1,8,-2,minecraft:shroomlight)
B(1,8,-1,minecraft:shroomlight)
B(1,9,-1,minecraft:shroomlight)
B(1,0,0,minecraft:mushroom_stem[down=true,east=true,north=true,south=true,up=false,west=true])
B(1,1,0,minecraft:mushroom_stem[down=false,east=true,north=true,south=true,up=false,west=true])
B(1,2,0,minecraft:mushroom_stem[down=false,east=true,north=true,south=true,up=false,west=true])
B(1,3,0,minecraft:mushroom_stem[down=false,east=true,north=true,south=true,up=false,west=true])
B(1,4,0,minecraft:mushroom_stem[down=false,east=true,north=true,south=true,up=false,west=true])
B(1,5,0,minecraft:mushroom_stem[down=false,east=true,north=true,south=true,up=false,west=true])
B(1,6,0,minecraft:mushroom_stem[down=false,east=true,north=true,south=true,up=false,west=true])
B(1,7,0,minecraft:mushroom_stem[down=false,east=true,north=true,south=true,up=true,west=true])
B(1,8,0,minecraft:shroomlight)
B(1,9,0,minecraft:shroomlight)
B(1,8,1,minecraft:shroomlight)
B(1,9,1,minecraft:shroomlight)
B(1,8,2,minecraft:shroomlight)
B(1,7,3,minecraft:shroomlight)
B(2,7,-3,minecraft:shroomlight)
B(2,8,-2,minecraft:shroomlight)
B(2,8,-1,minecraft:shroomlight)
B(2,9,-1,minecraft:shroomlight)
B(2,8,0,minecraft:shroomlight)
B(2,9,0,minecraft:shroomlight)
B(2,8,1,minecraft:shroomlight)
B(2,9,1,minecraft:shroomlight)
B(2,8,2,minecraft:shroomlight)
B(2,7,3,minecraft:shroomlight)
B(3,7,-2,minecraft:shroomlight)
B(3,8,-1,minecraft:shroomlight)
B(3,8,0,minecraft:shroomlight)
B(3,8,1,minecraft:shroomlight)
B(3,7,2,minecraft:shroomlight)
B(4,7,-1,minecraft:shroomlight)
B(4,7,0,minecraft:shroomlight)
B(4,7,1,minecraft:shroomlight)

#######################################################################
# +-----------------------------------------------------------------+ #
# |                            BO3 checks                           | #
# +-----------------------------------------------------------------+ #
#######################################################################

BlockCheckNot(1,-1,0,minecraft:air)
BlockCheck(1,2,0,minecraft:air)

#######################################################################
# +-----------------------------------------------------------------+ #
# |                             Branches                            | #
# +-----------------------------------------------------------------+ #
#######################################################################


#######################################################################
# +-----------------------------------------------------------------+ #
# |                             Entities                            | #
# +-----------------------------------------------------------------+ #
#######################################################################

