Author: Bo3 BulkEdit

Description: Converted Schematic - Modified by Bo3BulkEdit

Version: 3

SettingsMode: WriteDisable

IsOTGPlus: false
Tree: false
Frequency: 1
Rarity: 1
RotateRandomly: false
SpawnHeight: randomY
SpawnHeightOffset: 0
SpawnHeightVariance: 0
MaxBranchDepth: 10
ExcludedBiomes: All

MinHeight: 40
MaxHeight: 60

SourceBlocks: minecraft:netherrack,minecraft:basalt,minecraft:blackstone,minecraft:obsidian,minecraft:nether_wart_block
MaxPercentageOutsideSourceBlock: 40
OutsideSourceBlock: dontPlace

B(-3,0,-3,minecraft:red_nether_bricks)
B(-2,0,-3,minecraft:red_nether_bricks)
B(2,0,-3,minecraft:red_nether_bricks)
B(3,0,-3,minecraft:red_nether_bricks)
B(-3,0,-2,minecraft:red_nether_bricks)
B(-2,0,-2,minecraft:red_nether_bricks)
B(2,0,-2,minecraft:red_nether_bricks)
B(3,0,-2,minecraft:red_nether_bricks)
B(0,0,0,minecraft:red_nether_bricks)
B(-3,0,2,minecraft:red_nether_bricks)
B(-2,0,2,minecraft:red_nether_bricks)
B(2,0,2,minecraft:red_nether_bricks)
B(3,0,2,minecraft:red_nether_bricks)
B(-3,0,3,minecraft:red_nether_bricks)
B(-2,0,3,minecraft:red_nether_bricks)
B(2,0,3,minecraft:red_nether_bricks)
B(3,0,3,minecraft:red_nether_bricks)
B(-3,1,-5,minecraft:red_nether_bricks)
B(-2,1,-5,minecraft:red_nether_bricks)
B(2,1,-5,minecraft:red_nether_bricks)
B(3,1,-5,minecraft:red_nether_bricks)
B(-3,1,-4,minecraft:red_nether_bricks)
B(-2,1,-4,minecraft:red_nether_bricks)
B(2,1,-4,minecraft:red_nether_bricks)
B(3,1,-4,minecraft:red_nether_bricks)
B(-5,1,-3,minecraft:red_nether_bricks)
B(-4,1,-3,minecraft:red_nether_bricks)
B(-3,1,-3,minecraft:lava[level=0])
B(-2,1,-3,minecraft:lava[level=0])
B(-1,1,-3,minecraft:red_nether_bricks)
B(1,1,-3,minecraft:red_nether_bricks)
B(2,1,-3,minecraft:lava[level=0])
B(3,1,-3,minecraft:lava[level=0])
B(4,1,-3,minecraft:red_nether_bricks)
B(5,1,-3,minecraft:red_nether_bricks)
B(-5,1,-2,minecraft:red_nether_bricks)
B(-4,1,-2,minecraft:red_nether_bricks)
B(-3,1,-2,minecraft:lava[level=0])
B(-2,1,-2,minecraft:lava[level=0])
B(-1,1,-2,minecraft:red_nether_bricks)
B(1,1,-2,minecraft:red_nether_bricks)
B(2,1,-2,minecraft:lava[level=0])
B(3,1,-2,minecraft:lava[level=0])
B(4,1,-2,minecraft:red_nether_bricks)
B(5,1,-2,minecraft:red_nether_bricks)
B(-3,1,-1,minecraft:red_nether_bricks)
B(-2,1,-1,minecraft:red_nether_bricks)
B(0,1,-1,minecraft:red_nether_bricks)
B(2,1,-1,minecraft:red_nether_bricks)
B(3,1,-1,minecraft:red_nether_bricks)
B(-1,1,0,minecraft:red_nether_bricks)
B(0,1,0,minecraft:chest[facing=north,type=single,waterlogged=false],./SmallDungeon/chest.json)
B(1,1,0,minecraft:red_nether_bricks)
B(-3,1,1,minecraft:red_nether_bricks)
B(-2,1,1,minecraft:red_nether_bricks)
B(0,1,1,minecraft:red_nether_bricks)
B(2,1,1,minecraft:red_nether_bricks)
B(3,1,1,minecraft:red_nether_bricks)
B(-5,1,2,minecraft:red_nether_bricks)
B(-4,1,2,minecraft:red_nether_bricks)
B(-3,1,2,minecraft:lava[level=0])
B(-2,1,2,minecraft:lava[level=0])
B(-1,1,2,minecraft:red_nether_bricks)
B(1,1,2,minecraft:red_nether_bricks)
B(2,1,2,minecraft:lava[level=0])
B(3,1,2,minecraft:lava[level=0])
B(4,1,2,minecraft:red_nether_bricks)
B(5,1,2,minecraft:red_nether_bricks)
B(-5,1,3,minecraft:red_nether_bricks)
B(-4,1,3,minecraft:red_nether_bricks)
B(-3,1,3,minecraft:lava[level=0])
B(-2,1,3,minecraft:lava[level=0])
B(-1,1,3,minecraft:red_nether_bricks)
B(1,1,3,minecraft:red_nether_bricks)
B(2,1,3,minecraft:lava[level=0])
B(3,1,3,minecraft:lava[level=0])
B(4,1,3,minecraft:red_nether_bricks)
B(5,1,3,minecraft:red_nether_bricks)
B(-3,1,4,minecraft:red_nether_bricks)
B(-2,1,4,minecraft:red_nether_bricks)
B(2,1,4,minecraft:red_nether_bricks)
B(3,1,4,minecraft:red_nether_bricks)
B(-3,1,5,minecraft:red_nether_bricks)
B(-2,1,5,minecraft:red_nether_bricks)
B(2,1,5,minecraft:red_nether_bricks)
B(3,1,5,minecraft:red_nether_bricks)
B(-3,2,-6,minecraft:red_nether_bricks)
B(-2,2,-6,minecraft:red_nether_bricks)
B(2,2,-6,minecraft:red_nether_bricks)
B(3,2,-6,minecraft:red_nether_bricks)
B(-4,2,-5,minecraft:red_nether_bricks)
B(-3,2,-5,minecraft:lava[level=8])
B(-2,2,-5,minecraft:lava[level=8])
B(-1,2,-5,minecraft:red_nether_bricks)
B(1,2,-5,minecraft:red_nether_bricks)
B(2,2,-5,minecraft:lava[level=8])
B(3,2,-5,minecraft:lava[level=8])
B(4,2,-5,minecraft:red_nether_bricks)
B(-5,2,-4,minecraft:red_nether_bricks)
B(-4,2,-4,minecraft:red_nether_bricks)
B(-3,2,-4,minecraft:red_nether_bricks)
B(-2,2,-4,minecraft:red_nether_bricks)
B(-1,2,-4,minecraft:red_nether_bricks)
B(0,2,-4,minecraft:red_nether_bricks)
B(1,2,-4,minecraft:red_nether_bricks)
B(2,2,-4,minecraft:red_nether_bricks)
B(3,2,-4,minecraft:red_nether_bricks)
B(4,2,-4,minecraft:red_nether_bricks)
B(5,2,-4,minecraft:red_nether_bricks)
B(-6,2,-3,minecraft:red_nether_bricks)
B(-5,2,-3,minecraft:lava[level=8])
B(-4,2,-3,minecraft:red_nether_bricks)
B(-3,2,-3,minecraft:orange_stained_glass)
B(-2,2,-3,minecraft:orange_stained_glass)
B(-1,2,-3,minecraft:red_nether_bricks)
B(0,2,-3,minecraft:black_glazed_terracotta[facing=east])
B(1,2,-3,minecraft:red_nether_bricks)
B(2,2,-3,minecraft:orange_stained_glass)
B(3,2,-3,minecraft:orange_stained_glass)
B(4,2,-3,minecraft:red_nether_bricks)
B(5,2,-3,minecraft:lava[level=8])
B(6,2,-3,minecraft:red_nether_bricks)
B(-6,2,-2,minecraft:red_nether_bricks)
B(-5,2,-2,minecraft:lava[level=8])
B(-4,2,-2,minecraft:red_nether_bricks)
B(-3,2,-2,minecraft:orange_stained_glass)
B(-2,2,-2,minecraft:orange_stained_glass)
B(-1,2,-2,minecraft:red_nether_bricks)
B(0,2,-2,minecraft:red_nether_bricks)
B(1,2,-2,minecraft:red_nether_bricks)
B(2,2,-2,minecraft:orange_stained_glass)
B(3,2,-2,minecraft:orange_stained_glass)
B(4,2,-2,minecraft:red_nether_bricks)
B(5,2,-2,minecraft:lava[level=8])
B(6,2,-2,minecraft:red_nether_bricks)
B(-5,2,-1,minecraft:red_nether_bricks)
B(-4,2,-1,minecraft:red_nether_bricks)
B(-3,2,-1,minecraft:red_nether_bricks)
B(-2,2,-1,minecraft:red_nether_bricks)
B(-1,2,-1,minecraft:red_nether_bricks)
B(0,2,-1,minecraft:red_glazed_terracotta[facing=north])
B(1,2,-1,minecraft:red_nether_bricks)
B(2,2,-1,minecraft:red_nether_bricks)
B(3,2,-1,minecraft:red_nether_bricks)
B(4,2,-1,minecraft:red_nether_bricks)
B(5,2,-1,minecraft:red_nether_bricks)
B(-4,2,0,minecraft:red_nether_bricks)
B(-3,2,0,minecraft:black_glazed_terracotta[facing=west])
B(-2,2,0,minecraft:red_nether_bricks)
B(-1,2,0,minecraft:red_glazed_terracotta[facing=west])
B(0,2,0,minecraft:light_blue_stained_glass)
B(1,2,0,minecraft:red_glazed_terracotta[facing=north])
B(2,2,0,minecraft:red_nether_bricks)
B(3,2,0,minecraft:black_glazed_terracotta[facing=east])
B(4,2,0,minecraft:red_nether_bricks)
B(-5,2,1,minecraft:red_nether_bricks)
B(-4,2,1,minecraft:red_nether_bricks)
B(-3,2,1,minecraft:red_nether_bricks)
B(-2,2,1,minecraft:red_nether_bricks)
B(-1,2,1,minecraft:red_nether_bricks)
B(0,2,1,minecraft:red_glazed_terracotta[facing=north])
B(1,2,1,minecraft:red_nether_bricks)
B(2,2,1,minecraft:red_nether_bricks)
B(3,2,1,minecraft:red_nether_bricks)
B(4,2,1,minecraft:red_nether_bricks)
B(5,2,1,minecraft:red_nether_bricks)
B(-6,2,2,minecraft:red_nether_bricks)
B(-5,2,2,minecraft:lava[level=8])
B(-4,2,2,minecraft:red_nether_bricks)
B(-3,2,2,minecraft:orange_stained_glass)
B(-2,2,2,minecraft:orange_stained_glass)
B(-1,2,2,minecraft:red_nether_bricks)
B(0,2,2,minecraft:red_nether_bricks)
B(1,2,2,minecraft:red_nether_bricks)
B(2,2,2,minecraft:orange_stained_glass)
B(3,2,2,minecraft:orange_stained_glass)
B(4,2,2,minecraft:red_nether_bricks)
B(5,2,2,minecraft:lava[level=8])
B(6,2,2,minecraft:red_nether_bricks)
B(-6,2,3,minecraft:red_nether_bricks)
B(-5,2,3,minecraft:lava[level=8])
B(-4,2,3,minecraft:red_nether_bricks)
B(-3,2,3,minecraft:orange_stained_glass)
B(-2,2,3,minecraft:orange_stained_glass)
B(-1,2,3,minecraft:red_nether_bricks)
B(0,2,3,minecraft:black_glazed_terracotta[facing=north])
B(1,2,3,minecraft:red_nether_bricks)
B(2,2,3,minecraft:orange_stained_glass)
B(3,2,3,minecraft:orange_stained_glass)
B(4,2,3,minecraft:red_nether_bricks)
B(5,2,3,minecraft:lava[level=8])
B(6,2,3,minecraft:red_nether_bricks)
B(-5,2,4,minecraft:red_nether_bricks)
B(-4,2,4,minecraft:red_nether_bricks)
B(-3,2,4,minecraft:red_nether_bricks)
B(-2,2,4,minecraft:red_nether_bricks)
B(-1,2,4,minecraft:red_nether_bricks)
B(0,2,4,minecraft:red_nether_bricks)
B(1,2,4,minecraft:red_nether_bricks)
B(2,2,4,minecraft:red_nether_bricks)
B(3,2,4,minecraft:red_nether_bricks)
B(4,2,4,minecraft:red_nether_bricks)
B(5,2,4,minecraft:red_nether_bricks)
B(-4,2,5,minecraft:red_nether_bricks)
B(-3,2,5,minecraft:lava[level=8])
B(-2,2,5,minecraft:lava[level=8])
B(-1,2,5,minecraft:red_nether_bricks)
B(1,2,5,minecraft:red_nether_bricks)
B(2,2,5,minecraft:lava[level=8])
B(3,2,5,minecraft:lava[level=8])
B(4,2,5,minecraft:red_nether_bricks)
B(-3,2,6,minecraft:red_nether_bricks)
B(-2,2,6,minecraft:red_nether_bricks)
B(2,2,6,minecraft:red_nether_bricks)
B(3,2,6,minecraft:red_nether_bricks)
B(-4,3,-5,minecraft:red_nether_bricks)
B(-3,3,-5,minecraft:lava[level=8])
B(-2,3,-5,minecraft:lava[level=8])
B(-1,3,-5,minecraft:red_nether_bricks)
B(1,3,-5,minecraft:red_nether_bricks)
B(2,3,-5,minecraft:lava[level=8])
B(3,3,-5,minecraft:lava[level=8])
B(4,3,-5,minecraft:red_nether_bricks)
B(-5,3,-4,minecraft:red_nether_bricks)
B(-4,3,-4,minecraft:barrel[facing=south,open=false],./SmallDungeon/barrel.json)
B(-3,3,-4,minecraft:air)
B(-2,3,-4,minecraft:air)
B(-1,3,-4,minecraft:air)
B(0,3,-4,minecraft:air)
B(1,3,-4,minecraft:air)
B(2,3,-4,minecraft:air)
B(3,3,-4,minecraft:air)
B(4,3,-4,minecraft:barrel[facing=west,open=false],./SmallDungeon/barrel.json)
B(5,3,-4,minecraft:red_nether_bricks)
B(-5,3,-3,minecraft:lava[level=8])
B(-4,3,-3,minecraft:air)
B(-3,3,-3,minecraft:air)
B(-2,3,-3,minecraft:air)
B(-1,3,-3,minecraft:air)
B(0,3,-3,minecraft:air)
B(1,3,-3,minecraft:air)
B(2,3,-3,minecraft:air)
B(3,3,-3,minecraft:air)
B(4,3,-3,minecraft:air)
B(5,3,-3,minecraft:lava[level=8])
B(-5,3,-2,minecraft:lava[level=8])
B(-4,3,-2,minecraft:air)
B(-3,3,-2,minecraft:air)
B(-2,3,-2,minecraft:air)
B(-1,3,-2,minecraft:air)
B(0,3,-2,AIR)
B(1,3,-2,minecraft:air)
B(2,3,-2,minecraft:air)
B(3,3,-2,minecraft:air)
B(4,3,-2,minecraft:air)
B(5,3,-2,minecraft:lava[level=8])
B(-5,3,-1,minecraft:red_nether_bricks)
B(-4,3,-1,minecraft:air)
B(-3,3,-1,minecraft:air)
B(-2,3,-1,minecraft:air)
B(-1,3,-1,minecraft:air)
B(0,3,-1,minecraft:air)
B(1,3,-1,minecraft:air)
B(2,3,-1,minecraft:air)
B(3,3,-1,minecraft:air)
B(4,3,-1,minecraft:air)
B(5,3,-1,minecraft:red_nether_bricks)
B(-4,3,0,minecraft:air)
B(-3,3,0,minecraft:air)
B(-2,3,0,AIR)
B(-1,3,0,minecraft:air)
B(0,3,0,minecraft:air)
B(1,3,0,minecraft:air)
B(2,3,0,AIR)
B(3,3,0,minecraft:air)
B(4,3,0,minecraft:air)
B(-5,3,1,minecraft:red_nether_bricks)
B(-4,3,1,minecraft:air)
B(-3,3,1,minecraft:air)
B(-2,3,1,minecraft:air)
B(-1,3,1,minecraft:air)
B(0,3,1,minecraft:air)
B(1,3,1,minecraft:air)
B(2,3,1,minecraft:air)
B(3,3,1,minecraft:air)
B(4,3,1,minecraft:air)
B(5,3,1,minecraft:red_nether_bricks)
B(-5,3,2,minecraft:lava[level=8])
B(-4,3,2,minecraft:air)
B(-3,3,2,minecraft:air)
B(-2,3,2,minecraft:air)
B(-1,3,2,minecraft:air)
B(0,3,2,AIR)
B(1,3,2,minecraft:air)
B(2,3,2,minecraft:air)
B(3,3,2,minecraft:air)
B(4,3,2,minecraft:air)
B(5,3,2,minecraft:lava[level=8])
B(-5,3,3,minecraft:lava[level=8])
B(-4,3,3,minecraft:air)
B(-3,3,3,minecraft:air)
B(-2,3,3,minecraft:air)
B(-1,3,3,minecraft:air)
B(0,3,3,minecraft:air)
B(1,3,3,minecraft:air)
B(2,3,3,minecraft:air)
B(3,3,3,minecraft:air)
B(4,3,3,minecraft:air)
B(5,3,3,minecraft:lava[level=8])
B(-5,3,4,minecraft:red_nether_bricks)
B(-4,3,4,minecraft:barrel[facing=up,open=false],./SmallDungeon/barrel.json)
B(-3,3,4,minecraft:air)
B(-2,3,4,minecraft:air)
B(-1,3,4,minecraft:air)
B(0,3,4,minecraft:air)
B(1,3,4,minecraft:air)
B(2,3,4,minecraft:air)
B(3,3,4,minecraft:air)
B(4,3,4,minecraft:barrel[facing=north,open=false],./SmallDungeon/barrel.json)
B(5,3,4,minecraft:red_nether_bricks)
B(-4,3,5,minecraft:red_nether_bricks)
B(-3,3,5,minecraft:lava[level=8])
B(-2,3,5,minecraft:lava[level=8])
B(-1,3,5,minecraft:red_nether_bricks)
B(1,3,5,minecraft:red_nether_bricks)
B(2,3,5,minecraft:lava[level=8])
B(3,3,5,minecraft:lava[level=8])
B(4,3,5,minecraft:red_nether_bricks)
B(-4,4,-5,minecraft:red_nether_bricks)
B(-3,4,-5,minecraft:lava[level=8])
B(-2,4,-5,minecraft:lava[level=8])
B(-1,4,-5,minecraft:red_nether_bricks)
B(1,4,-5,minecraft:red_nether_bricks)
B(2,4,-5,minecraft:lava[level=8])
B(3,4,-5,minecraft:lava[level=8])
B(4,4,-5,minecraft:red_nether_bricks)
B(-5,4,-4,minecraft:red_nether_bricks)
B(-4,4,-4,minecraft:air)
B(-3,4,-4,minecraft:air)
B(-2,4,-4,minecraft:air)
B(-1,4,-4,minecraft:air)
B(0,4,-4,minecraft:air)
B(1,4,-4,minecraft:air)
B(2,4,-4,minecraft:air)
B(3,4,-4,minecraft:air)
B(4,4,-4,minecraft:air)
B(5,4,-4,minecraft:red_nether_bricks)
B(-5,4,-3,minecraft:lava[level=8])
B(-4,4,-3,minecraft:air)
B(-3,4,-3,minecraft:air)
B(-2,4,-3,minecraft:air)
B(-1,4,-3,minecraft:air)
B(0,4,-3,minecraft:air)
B(1,4,-3,minecraft:air)
B(2,4,-3,minecraft:air)
B(3,4,-3,minecraft:air)
B(4,4,-3,minecraft:air)
B(5,4,-3,minecraft:lava[level=8])
B(-5,4,-2,minecraft:lava[level=8])
B(-4,4,-2,minecraft:air)
B(-3,4,-2,minecraft:air)
B(-2,4,-2,minecraft:air)
B(-1,4,-2,minecraft:air)
B(0,4,-2,minecraft:air)
B(1,4,-2,minecraft:air)
B(2,4,-2,minecraft:air)
B(3,4,-2,minecraft:air)
B(4,4,-2,minecraft:air)
B(5,4,-2,minecraft:lava[level=8])
B(-5,4,-1,minecraft:red_nether_bricks)
B(-4,4,-1,minecraft:air)
B(-3,4,-1,minecraft:air)
B(-2,4,-1,minecraft:air)
B(-1,4,-1,minecraft:air)
B(0,4,-1,minecraft:air)
B(1,4,-1,minecraft:air)
B(2,4,-1,minecraft:air)
B(3,4,-1,minecraft:air)
B(4,4,-1,minecraft:air)
B(5,4,-1,minecraft:red_nether_bricks)
B(-4,4,0,minecraft:air)
B(-3,4,0,minecraft:air)
B(-2,4,0,minecraft:air)
B(-1,4,0,minecraft:air)
B(0,4,0,minecraft:air)
B(1,4,0,minecraft:air)
B(2,4,0,minecraft:air)
B(3,4,0,minecraft:air)
B(4,4,0,minecraft:air)
B(-5,4,1,minecraft:red_nether_bricks)
B(-4,4,1,minecraft:air)
B(-3,4,1,minecraft:air)
B(-2,4,1,minecraft:air)
B(-1,4,1,minecraft:air)
B(0,4,1,minecraft:air)
B(1,4,1,minecraft:air)
B(2,4,1,minecraft:air)
B(3,4,1,minecraft:air)
B(4,4,1,minecraft:air)
B(5,4,1,minecraft:red_nether_bricks)
B(-5,4,2,minecraft:lava[level=8])
B(-4,4,2,minecraft:air)
B(-3,4,2,minecraft:air)
B(-2,4,2,minecraft:air)
B(-1,4,2,minecraft:air)
B(0,4,2,minecraft:air)
B(1,4,2,minecraft:air)
B(2,4,2,minecraft:air)
B(3,4,2,minecraft:air)
B(4,4,2,minecraft:air)
B(5,4,2,minecraft:lava[level=8])
B(-5,4,3,minecraft:lava[level=8])
B(-4,4,3,minecraft:air)
B(-3,4,3,minecraft:air)
B(-2,4,3,minecraft:air)
B(-1,4,3,minecraft:air)
B(0,4,3,minecraft:air)
B(1,4,3,minecraft:air)
B(2,4,3,minecraft:air)
B(3,4,3,minecraft:air)
B(4,4,3,minecraft:air)
B(5,4,3,minecraft:lava[level=8])
B(-5,4,4,minecraft:red_nether_bricks)
B(-4,4,4,minecraft:air)
B(-3,4,4,minecraft:air)
B(-2,4,4,minecraft:air)
B(-1,4,4,minecraft:air)
B(0,4,4,minecraft:air)
B(1,4,4,minecraft:air)
B(2,4,4,minecraft:air)
B(3,4,4,minecraft:air)
B(4,4,4,minecraft:air)
B(5,4,4,minecraft:red_nether_bricks)
B(-4,4,5,minecraft:red_nether_bricks)
B(-3,4,5,minecraft:lava[level=8])
B(-2,4,5,minecraft:lava[level=8])
B(-1,4,5,minecraft:red_nether_bricks)
B(1,4,5,minecraft:red_nether_bricks)
B(2,4,5,minecraft:lava[level=8])
B(3,4,5,minecraft:lava[level=8])
B(4,4,5,minecraft:red_nether_bricks)
B(-4,5,-5,minecraft:red_nether_bricks)
B(-3,5,-5,minecraft:lava[level=8])
B(-2,5,-5,minecraft:lava[level=8])
B(-1,5,-5,minecraft:red_nether_bricks)
B(1,5,-5,minecraft:red_nether_bricks)
B(2,5,-5,minecraft:lava[level=8])
B(3,5,-5,minecraft:lava[level=8])
B(4,5,-5,minecraft:red_nether_bricks)
B(-5,5,-4,minecraft:red_nether_bricks)
B(-4,5,-4,minecraft:air)
B(-3,5,-4,minecraft:air)
B(-2,5,-4,minecraft:air)
B(-1,5,-4,minecraft:air)
B(0,5,-4,minecraft:air)
B(1,5,-4,minecraft:air)
B(2,5,-4,minecraft:air)
B(3,5,-4,minecraft:air)
B(4,5,-4,minecraft:air)
B(5,5,-4,minecraft:red_nether_bricks)
B(-5,5,-3,minecraft:lava[level=8])
B(-4,5,-3,minecraft:air)
B(-3,5,-3,minecraft:air)
B(-2,5,-3,minecraft:air)
B(-1,5,-3,minecraft:air)
B(0,5,-3,minecraft:air)
B(1,5,-3,minecraft:air)
B(2,5,-3,minecraft:air)
B(3,5,-3,minecraft:air)
B(4,5,-3,minecraft:air)
B(5,5,-3,minecraft:lava[level=8])
B(-5,5,-2,minecraft:lava[level=8])
B(-4,5,-2,minecraft:air)
B(-3,5,-2,minecraft:air)
B(-2,5,-2,minecraft:air)
B(-1,5,-2,minecraft:air)
B(0,5,-2,minecraft:air)
B(1,5,-2,minecraft:air)
B(2,5,-2,minecraft:air)
B(3,5,-2,minecraft:air)
B(4,5,-2,minecraft:air)
B(5,5,-2,minecraft:lava[level=8])
B(-5,5,-1,minecraft:red_nether_bricks)
B(-4,5,-1,minecraft:air)
B(-3,5,-1,minecraft:air)
B(-2,5,-1,minecraft:air)
B(-1,5,-1,minecraft:air)
B(0,5,-1,minecraft:air)
B(1,5,-1,minecraft:air)
B(2,5,-1,minecraft:air)
B(3,5,-1,minecraft:air)
B(4,5,-1,minecraft:air)
B(5,5,-1,minecraft:red_nether_bricks)
B(-4,5,0,minecraft:air)
B(-3,5,0,minecraft:air)
B(-2,5,0,minecraft:air)
B(-1,5,0,minecraft:air)
B(0,5,0,minecraft:air)
B(1,5,0,minecraft:air)
B(2,5,0,minecraft:air)
B(3,5,0,minecraft:air)
B(4,5,0,minecraft:air)
B(-5,5,1,minecraft:red_nether_bricks)
B(-4,5,1,minecraft:air)
B(-3,5,1,minecraft:air)
B(-2,5,1,minecraft:air)
B(-1,5,1,minecraft:air)
B(0,5,1,minecraft:air)
B(1,5,1,minecraft:air)
B(2,5,1,minecraft:air)
B(3,5,1,minecraft:air)
B(4,5,1,minecraft:air)
B(5,5,1,minecraft:red_nether_bricks)
B(-5,5,2,minecraft:lava[level=8])
B(-4,5,2,minecraft:air)
B(-3,5,2,minecraft:air)
B(-2,5,2,minecraft:air)
B(-1,5,2,minecraft:air)
B(0,5,2,minecraft:air)
B(1,5,2,minecraft:air)
B(2,5,2,minecraft:air)
B(3,5,2,minecraft:air)
B(4,5,2,minecraft:air)
B(5,5,2,minecraft:lava[level=8])
B(-5,5,3,minecraft:lava[level=8])
B(-4,5,3,minecraft:air)
B(-3,5,3,minecraft:air)
B(-2,5,3,minecraft:air)
B(-1,5,3,minecraft:air)
B(0,5,3,minecraft:air)
B(1,5,3,minecraft:air)
B(2,5,3,minecraft:air)
B(3,5,3,minecraft:air)
B(4,5,3,minecraft:air)
B(5,5,3,minecraft:lava[level=8])
B(-5,5,4,minecraft:red_nether_bricks)
B(-4,5,4,minecraft:air)
B(-3,5,4,minecraft:air)
B(-2,5,4,minecraft:air)
B(-1,5,4,minecraft:air)
B(0,5,4,minecraft:air)
B(1,5,4,minecraft:air)
B(2,5,4,minecraft:air)
B(3,5,4,minecraft:air)
B(4,5,4,minecraft:air)
B(5,5,4,minecraft:red_nether_bricks)
B(-4,5,5,minecraft:red_nether_bricks)
B(-3,5,5,minecraft:lava[level=8])
B(-2,5,5,minecraft:lava[level=8])
B(-1,5,5,minecraft:red_nether_bricks)
B(1,5,5,minecraft:red_nether_bricks)
B(2,5,5,minecraft:lava[level=8])
B(3,5,5,minecraft:lava[level=8])
B(4,5,5,minecraft:red_nether_bricks)
B(-3,6,-6,minecraft:red_nether_bricks)
B(-2,6,-6,minecraft:red_nether_bricks)
B(2,6,-6,minecraft:red_nether_bricks)
B(3,6,-6,minecraft:red_nether_bricks)
B(-4,6,-5,minecraft:red_nether_bricks)
B(-3,6,-5,minecraft:lava[level=0])
B(-2,6,-5,minecraft:lava[level=0])
B(-1,6,-5,minecraft:red_nether_bricks)
B(1,6,-5,minecraft:red_nether_bricks)
B(2,6,-5,minecraft:lava[level=0])
B(3,6,-5,minecraft:lava[level=0])
B(4,6,-5,minecraft:red_nether_bricks)
B(-5,6,-4,minecraft:red_nether_bricks)
RB(-4,6,-4,minecraft:crying_obsidian,20,minecraft:obsidian,100)
RB(-3,6,-4,minecraft:crying_obsidian,20,minecraft:obsidian,100)
RB(-2,6,-4,minecraft:crying_obsidian,20,minecraft:obsidian,100)
RB(-1,6,-4,minecraft:crying_obsidian,20,minecraft:obsidian,100)
RB(0,6,-4,minecraft:crying_obsidian,20,minecraft:obsidian,100)
RB(1,6,-4,minecraft:crying_obsidian,20,minecraft:obsidian,100)
RB(2,6,-4,minecraft:crying_obsidian,20,minecraft:obsidian,100)
RB(3,6,-4,minecraft:crying_obsidian,20,minecraft:obsidian,100)
RB(4,6,-4,minecraft:crying_obsidian,20,minecraft:obsidian,100)
B(5,6,-4,minecraft:red_nether_bricks)
B(-6,6,-3,minecraft:red_nether_bricks)
B(-5,6,-3,minecraft:lava[level=0])
RB(-4,6,-3,minecraft:crying_obsidian,20,minecraft:obsidian,100)
B(-3,6,-3,minecraft:red_glazed_terracotta[facing=east])
B(-2,6,-3,minecraft:red_glazed_terracotta[facing=west])
RB(-1,6,-3,minecraft:crying_obsidian,20,minecraft:obsidian,100)
B(0,6,-3,minecraft:black_glazed_terracotta[facing=south])
RB(1,6,-3,minecraft:crying_obsidian,20,minecraft:obsidian,100)
B(2,6,-3,minecraft:red_glazed_terracotta[facing=east])
B(3,6,-3,minecraft:red_glazed_terracotta[facing=west])
RB(4,6,-3,minecraft:crying_obsidian,20,minecraft:obsidian,100)
B(5,6,-3,minecraft:lava[level=0])
B(6,6,-3,minecraft:red_nether_bricks)
B(-6,6,-2,minecraft:red_nether_bricks)
B(-5,6,-2,minecraft:lava[level=0])
RB(-4,6,-2,minecraft:crying_obsidian,20,minecraft:obsidian,100)
B(-3,6,-2,minecraft:red_glazed_terracotta[facing=east])
B(-2,6,-2,minecraft:red_glazed_terracotta[facing=west])
RB(-1,6,-2,minecraft:crying_obsidian,20,minecraft:obsidian,100)
RB(0,6,-2,minecraft:crying_obsidian,20,minecraft:obsidian,100)
RB(1,6,-2,minecraft:crying_obsidian,20,minecraft:obsidian,100)
B(2,6,-2,minecraft:red_glazed_terracotta[facing=east])
B(3,6,-2,minecraft:red_glazed_terracotta[facing=west])
RB(4,6,-2,minecraft:crying_obsidian,20,minecraft:obsidian,100)
B(5,6,-2,minecraft:lava[level=0])
B(6,6,-2,minecraft:red_nether_bricks)
B(-5,6,-1,minecraft:red_nether_bricks)
RB(-4,6,-1,minecraft:crying_obsidian,20,minecraft:obsidian,100)
RB(-3,6,-1,minecraft:crying_obsidian,20,minecraft:obsidian,100)
RB(-2,6,-1,minecraft:crying_obsidian,20,minecraft:obsidian,100)
RB(-1,6,-1,minecraft:crying_obsidian,20,minecraft:obsidian,100)
B(0,6,-1,minecraft:red_glazed_terracotta[facing=south])
RB(1,6,-1,minecraft:crying_obsidian,20,minecraft:obsidian,100)
RB(2,6,-1,minecraft:crying_obsidian,20,minecraft:obsidian,100)
RB(3,6,-1,minecraft:crying_obsidian,20,minecraft:obsidian,100)
RB(4,6,-1,minecraft:crying_obsidian,20,minecraft:obsidian,100)
B(5,6,-1,minecraft:red_nether_bricks)
RB(-4,6,0,minecraft:crying_obsidian,20,minecraft:obsidian,100)
B(-3,6,0,minecraft:black_glazed_terracotta[facing=east])
RB(-2,6,0,minecraft:crying_obsidian,20,minecraft:obsidian,100)
B(-1,6,0,minecraft:red_glazed_terracotta[facing=east])
B(0,6,0,minecraft:orange_stained_glass)
B(1,6,0,minecraft:red_glazed_terracotta[facing=east])
RB(2,6,0,minecraft:crying_obsidian,20,minecraft:obsidian,100)
B(3,6,0,minecraft:black_glazed_terracotta[facing=west])
RB(4,6,0,minecraft:crying_obsidian,20,minecraft:obsidian,100)
B(-5,6,1,minecraft:red_nether_bricks)
RB(-4,6,1,minecraft:crying_obsidian,20,minecraft:obsidian,100)
RB(-3,6,1,minecraft:crying_obsidian,20,minecraft:obsidian,100)
RB(-2,6,1,minecraft:crying_obsidian,20,minecraft:obsidian,100)
RB(-1,6,1,minecraft:crying_obsidian,20,minecraft:obsidian,100)
B(0,6,1,minecraft:red_glazed_terracotta[facing=north])
RB(1,6,1,minecraft:crying_obsidian,20,minecraft:obsidian,100)
RB(2,6,1,minecraft:crying_obsidian,20,minecraft:obsidian,100)
RB(3,6,1,minecraft:crying_obsidian,20,minecraft:obsidian,100)
RB(4,6,1,minecraft:crying_obsidian,20,minecraft:obsidian,100)
B(5,6,1,minecraft:red_nether_bricks)
B(-6,6,2,minecraft:red_nether_bricks)
B(-5,6,2,minecraft:lava[level=0])
RB(-4,6,2,minecraft:crying_obsidian,20,minecraft:obsidian,100)
B(-3,6,2,minecraft:red_glazed_terracotta[facing=east])
B(-2,6,2,minecraft:red_glazed_terracotta[facing=west])
RB(-1,6,2,minecraft:crying_obsidian,20,minecraft:obsidian,100)
RB(0,6,2,minecraft:crying_obsidian,20,minecraft:obsidian,100)
RB(1,6,2,minecraft:crying_obsidian,20,minecraft:obsidian,100)
B(2,6,2,minecraft:red_glazed_terracotta[facing=east])
B(3,6,2,minecraft:red_glazed_terracotta[facing=west])
RB(4,6,2,minecraft:crying_obsidian,20,minecraft:obsidian,100)
B(5,6,2,minecraft:lava[level=0])
B(6,6,2,minecraft:red_nether_bricks)
B(-6,6,3,minecraft:red_nether_bricks)
B(-5,6,3,minecraft:lava[level=0])
RB(-4,6,3,minecraft:crying_obsidian,20,minecraft:obsidian,100)
B(-3,6,3,minecraft:red_glazed_terracotta[facing=east])
B(-2,6,3,minecraft:red_glazed_terracotta[facing=west])
RB(-1,6,3,minecraft:crying_obsidian,20,minecraft:obsidian,100)
B(0,6,3,minecraft:black_glazed_terracotta[facing=north])
RB(1,6,3,minecraft:crying_obsidian,20,minecraft:obsidian,100)
B(2,6,3,minecraft:red_glazed_terracotta[facing=east])
B(3,6,3,minecraft:red_glazed_terracotta[facing=west])
RB(4,6,3,minecraft:crying_obsidian,20,minecraft:obsidian,100)
B(5,6,3,minecraft:lava[level=0])
B(6,6,3,minecraft:red_nether_bricks)
B(-5,6,4,minecraft:red_nether_bricks)
RB(-4,6,4,minecraft:crying_obsidian,20,minecraft:obsidian,100)
RB(-3,6,4,minecraft:crying_obsidian,20,minecraft:obsidian,100)
RB(-2,6,4,minecraft:crying_obsidian,20,minecraft:obsidian,100)
RB(-1,6,4,minecraft:crying_obsidian,20,minecraft:obsidian,100)
RB(0,6,4,minecraft:crying_obsidian,20,minecraft:obsidian,100)
RB(1,6,4,minecraft:crying_obsidian,20,minecraft:obsidian,100)
RB(2,6,4,minecraft:crying_obsidian,20,minecraft:obsidian,100)
RB(3,6,4,minecraft:crying_obsidian,20,minecraft:obsidian,100)
RB(4,6,4,minecraft:crying_obsidian,20,minecraft:obsidian,100)
B(5,6,4,minecraft:red_nether_bricks)
B(-4,6,5,minecraft:red_nether_bricks)
B(-3,6,5,minecraft:lava[level=0])
B(-2,6,5,minecraft:lava[level=0])
B(-1,6,5,minecraft:red_nether_bricks)
B(1,6,5,minecraft:red_nether_bricks)
B(2,6,5,minecraft:lava[level=0])
B(3,6,5,minecraft:lava[level=0])
B(4,6,5,minecraft:red_nether_bricks)
B(-3,6,6,minecraft:red_nether_bricks)
B(-2,6,6,minecraft:red_nether_bricks)
B(2,6,6,minecraft:red_nether_bricks)
B(3,6,6,minecraft:red_nether_bricks)
B(0,7,-1,minecraft:red_nether_bricks)
B(-1,7,0,minecraft:red_nether_bricks)
B(0,7,0,minecraft:lava[level=0])
B(1,7,0,minecraft:red_nether_bricks)
B(0,7,1,minecraft:red_nether_bricks)

E(0,3,-2,minecraft:blaze,1)
E(-2,3,0,minecraft:wither_skeleton,1)
E(2,3,0,minecraft:piglin_brute,1)
E(0,3,2,minecraft:piglin_brute,1)

