Author: Frank

Description: Upside down medium sized quartz spike

Version: 3

SettingsMode: WriteDisable

IsOTGPlus: false
Tree: true
Frequency: 10
Rarity: 100.0
RotateRandomly: true
SpawnHeight: randomY
SpawnHeightOffset: 0
SpawnHeightVariance: 0
MaxBranchDepth: 10
ExcludedBiomes: All

ExtrudeMode: None
ExtrudeThroughBlocks: minecraft:air

MinHeight: 130
MaxHeight: 165

SourceBlocks: AIR
MaxPercentageOutsideSourceBlock: 60
OutsideSourceBlock: placeAnyway

DoReplaceBlocks: true

RB(-7,12,-6,minecraft:chiseled_quartz_block,10,minecraft:quartz_pillar,10,minecraft:smooth_quartz,10,minecraft:quartz_block,100)
RB(-6,12,-6,minecraft:chiseled_quartz_block,10,minecraft:quartz_pillar,10,minecraft:smooth_quartz,10,minecraft:quartz_block,100)
RB(-6,12,-5,minecraft:chiseled_quartz_block,10,minecraft:quartz_pillar,10,minecraft:smooth_quartz,10,minecraft:quartz_block,100)
RB(-6,12,-4,minecraft:chiseled_quartz_block,10,minecraft:quartz_pillar,10,minecraft:smooth_quartz,10,minecraft:quartz_block,100)
RB(-6,12,-3,minecraft:chiseled_quartz_block,10,minecraft:quartz_pillar,10,minecraft:smooth_quartz,10,minecraft:quartz_block,100)
RB(-6,12,-2,minecraft:chiseled_quartz_block,10,minecraft:quartz_pillar,10,minecraft:smooth_quartz,10,minecraft:quartz_block,100)
RB(-6,12,-1,minecraft:chiseled_quartz_block,10,minecraft:quartz_pillar,10,minecraft:smooth_quartz,10,minecraft:quartz_block,100)
RB(-6,12,0,minecraft:chiseled_quartz_block,10,minecraft:quartz_pillar,10,minecraft:smooth_quartz,10,minecraft:quartz_block,100)
RB(-6,12,1,minecraft:chiseled_quartz_block,10,minecraft:quartz_pillar,10,minecraft:smooth_quartz,10,minecraft:quartz_block,100)
RB(-6,12,2,minecraft:chiseled_quartz_block,10,minecraft:quartz_pillar,10,minecraft:smooth_quartz,10,minecraft:quartz_block,100)
RB(-6,12,3,minecraft:chiseled_quartz_block,10,minecraft:quartz_pillar,10,minecraft:smooth_quartz,10,minecraft:quartz_block,100)
RB(-6,12,4,minecraft:chiseled_quartz_block,10,minecraft:quartz_pillar,10,minecraft:smooth_quartz,10,minecraft:quartz_block,100)
RB(-6,12,5,minecraft:chiseled_quartz_block,10,minecraft:quartz_pillar,10,minecraft:smooth_quartz,10,minecraft:quartz_block,100)
RB(-5,11,-6,minecraft:chiseled_quartz_block,10,minecraft:quartz_pillar,10,minecraft:smooth_quartz,10,minecraft:quartz_block,100)
RB(-5,12,-6,minecraft:chiseled_quartz_block,10,minecraft:quartz_pillar,10,minecraft:smooth_quartz,10,minecraft:quartz_block,100)
RB(-5,11,-5,minecraft:chiseled_quartz_block,10,minecraft:quartz_pillar,10,minecraft:smooth_quartz,10,minecraft:quartz_block,100)
RB(-5,12,-5,minecraft:chiseled_quartz_block,10,minecraft:quartz_pillar,10,minecraft:smooth_quartz,10,minecraft:quartz_block,100)
RB(-5,11,-4,minecraft:chiseled_quartz_block,10,minecraft:quartz_pillar,10,minecraft:smooth_quartz,10,minecraft:quartz_block,100)
RB(-5,12,-4,minecraft:chiseled_quartz_block,10,minecraft:quartz_pillar,10,minecraft:smooth_quartz,10,minecraft:quartz_block,100)
RB(-5,11,-3,minecraft:chiseled_quartz_block,10,minecraft:quartz_pillar,10,minecraft:smooth_quartz,10,minecraft:quartz_block,100)
RB(-5,12,-3,minecraft:chiseled_quartz_block,10,minecraft:quartz_pillar,10,minecraft:smooth_quartz,10,minecraft:quartz_block,100)
RB(-5,11,-2,minecraft:chiseled_quartz_block,10,minecraft:quartz_pillar,10,minecraft:smooth_quartz,10,minecraft:quartz_block,100)
RB(-5,12,-2,minecraft:chiseled_quartz_block,10,minecraft:quartz_pillar,10,minecraft:smooth_quartz,10,minecraft:quartz_block,100)
RB(-5,11,-1,minecraft:chiseled_quartz_block,10,minecraft:quartz_pillar,10,minecraft:smooth_quartz,10,minecraft:quartz_block,100)
RB(-5,12,-1,minecraft:chiseled_quartz_block,10,minecraft:quartz_pillar,10,minecraft:smooth_quartz,10,minecraft:quartz_block,100)
RB(-5,11,0,minecraft:chiseled_quartz_block,10,minecraft:quartz_pillar,10,minecraft:smooth_quartz,10,minecraft:quartz_block,100)
RB(-5,12,0,minecraft:chiseled_quartz_block,10,minecraft:quartz_pillar,10,minecraft:smooth_quartz,10,minecraft:quartz_block,100)
RB(-5,12,1,minecraft:chiseled_quartz_block,10,minecraft:quartz_pillar,10,minecraft:smooth_quartz,10,minecraft:quartz_block,100)
RB(-5,12,2,minecraft:chiseled_quartz_block,10,minecraft:quartz_pillar,10,minecraft:smooth_quartz,10,minecraft:quartz_block,100)
RB(-5,12,3,minecraft:chiseled_quartz_block,10,minecraft:quartz_pillar,10,minecraft:smooth_quartz,10,minecraft:quartz_block,100)
RB(-5,12,4,minecraft:chiseled_quartz_block,10,minecraft:quartz_pillar,10,minecraft:smooth_quartz,10,minecraft:quartz_block,100)
RB(-5,12,5,minecraft:chiseled_quartz_block,10,minecraft:quartz_pillar,10,minecraft:smooth_quartz,10,minecraft:quartz_block,100)
RB(-4,10,-6,minecraft:chiseled_quartz_block,10,minecraft:quartz_pillar,10,minecraft:smooth_quartz,10,minecraft:quartz_block,100)
RB(-4,11,-6,minecraft:chiseled_quartz_block,10,minecraft:quartz_pillar,10,minecraft:smooth_quartz,10,minecraft:quartz_block,100)
RB(-4,12,-6,minecraft:chiseled_quartz_block,10,minecraft:quartz_pillar,10,minecraft:smooth_quartz,10,minecraft:quartz_block,100)
RB(-4,10,-5,minecraft:chiseled_quartz_block,10,minecraft:quartz_pillar,10,minecraft:smooth_quartz,10,minecraft:quartz_block,100)
RB(-4,11,-5,minecraft:chiseled_quartz_block,10,minecraft:quartz_pillar,10,minecraft:smooth_quartz,10,minecraft:quartz_block,100)
RB(-4,12,-5,minecraft:chiseled_quartz_block,10,minecraft:quartz_pillar,10,minecraft:smooth_quartz,10,minecraft:quartz_block,100)
RB(-4,10,-4,minecraft:chiseled_quartz_block,10,minecraft:quartz_pillar,10,minecraft:smooth_quartz,10,minecraft:quartz_block,100)
RB(-4,11,-4,minecraft:chiseled_quartz_block,10,minecraft:quartz_pillar,10,minecraft:smooth_quartz,10,minecraft:quartz_block,100)
RB(-4,12,-4,minecraft:chiseled_quartz_block,10,minecraft:quartz_pillar,10,minecraft:smooth_quartz,10,minecraft:quartz_block,100)
RB(-4,11,-3,minecraft:chiseled_quartz_block,10,minecraft:quartz_pillar,10,minecraft:smooth_quartz,10,minecraft:quartz_block,100)
RB(-4,12,-3,minecraft:chiseled_quartz_block,10,minecraft:quartz_pillar,10,minecraft:smooth_quartz,10,minecraft:quartz_block,100)
RB(-4,11,-2,minecraft:chiseled_quartz_block,10,minecraft:quartz_pillar,10,minecraft:smooth_quartz,10,minecraft:quartz_block,100)
RB(-4,12,-2,minecraft:chiseled_quartz_block,10,minecraft:quartz_pillar,10,minecraft:smooth_quartz,10,minecraft:quartz_block,100)
RB(-4,11,-1,minecraft:chiseled_quartz_block,10,minecraft:quartz_pillar,10,minecraft:smooth_quartz,10,minecraft:quartz_block,100)
RB(-4,12,-1,minecraft:chiseled_quartz_block,10,minecraft:quartz_pillar,10,minecraft:smooth_quartz,10,minecraft:quartz_block,100)
RB(-4,11,0,minecraft:chiseled_quartz_block,10,minecraft:quartz_pillar,10,minecraft:smooth_quartz,10,minecraft:quartz_block,100)
RB(-4,12,0,minecraft:chiseled_quartz_block,10,minecraft:quartz_pillar,10,minecraft:smooth_quartz,10,minecraft:quartz_block,100)
RB(-4,11,1,minecraft:chiseled_quartz_block,10,minecraft:quartz_pillar,10,minecraft:smooth_quartz,10,minecraft:quartz_block,100)
RB(-4,12,1,minecraft:chiseled_quartz_block,10,minecraft:quartz_pillar,10,minecraft:smooth_quartz,10,minecraft:quartz_block,100)
RB(-4,11,2,minecraft:chiseled_quartz_block,10,minecraft:quartz_pillar,10,minecraft:smooth_quartz,10,minecraft:quartz_block,100)
RB(-4,12,2,minecraft:chiseled_quartz_block,10,minecraft:quartz_pillar,10,minecraft:smooth_quartz,10,minecraft:quartz_block,100)
RB(-4,11,3,minecraft:chiseled_quartz_block,10,minecraft:quartz_pillar,10,minecraft:smooth_quartz,10,minecraft:quartz_block,100)
RB(-4,12,3,minecraft:chiseled_quartz_block,10,minecraft:quartz_pillar,10,minecraft:smooth_quartz,10,minecraft:quartz_block,100)
RB(-4,11,4,minecraft:chiseled_quartz_block,10,minecraft:quartz_pillar,10,minecraft:smooth_quartz,10,minecraft:quartz_block,100)
RB(-4,12,4,minecraft:chiseled_quartz_block,10,minecraft:quartz_pillar,10,minecraft:smooth_quartz,10,minecraft:quartz_block,100)
RB(-4,12,5,minecraft:chiseled_quartz_block,10,minecraft:quartz_pillar,10,minecraft:smooth_quartz,10,minecraft:quartz_block,100)
RB(-4,12,6,minecraft:chiseled_quartz_block,10,minecraft:quartz_pillar,10,minecraft:smooth_quartz,10,minecraft:quartz_block,100)
RB(-3,10,-6,minecraft:chiseled_quartz_block,10,minecraft:quartz_pillar,10,minecraft:smooth_quartz,10,minecraft:quartz_block,100)
RB(-3,11,-6,minecraft:chiseled_quartz_block,10,minecraft:quartz_pillar,10,minecraft:smooth_quartz,10,minecraft:quartz_block,100)
RB(-3,12,-6,minecraft:chiseled_quartz_block,10,minecraft:quartz_pillar,10,minecraft:smooth_quartz,10,minecraft:quartz_block,100)
RB(-3,10,-5,minecraft:chiseled_quartz_block,10,minecraft:quartz_pillar,10,minecraft:smooth_quartz,10,minecraft:quartz_block,100)
RB(-3,11,-5,minecraft:chiseled_quartz_block,10,minecraft:quartz_pillar,10,minecraft:smooth_quartz,10,minecraft:quartz_block,100)
RB(-3,12,-5,minecraft:chiseled_quartz_block,10,minecraft:quartz_pillar,10,minecraft:smooth_quartz,10,minecraft:quartz_block,100)
RB(-3,10,-4,minecraft:chiseled_quartz_block,10,minecraft:quartz_pillar,10,minecraft:smooth_quartz,10,minecraft:quartz_block,100)
RB(-3,11,-4,minecraft:chiseled_quartz_block,10,minecraft:quartz_pillar,10,minecraft:smooth_quartz,10,minecraft:quartz_block,100)
RB(-3,12,-4,minecraft:chiseled_quartz_block,10,minecraft:quartz_pillar,10,minecraft:smooth_quartz,10,minecraft:quartz_block,100)
RB(-3,10,-3,minecraft:chiseled_quartz_block,10,minecraft:quartz_pillar,10,minecraft:smooth_quartz,10,minecraft:quartz_block,100)
RB(-3,11,-3,minecraft:chiseled_quartz_block,10,minecraft:quartz_pillar,10,minecraft:smooth_quartz,10,minecraft:quartz_block,100)
RB(-3,12,-3,minecraft:chiseled_quartz_block,10,minecraft:quartz_pillar,10,minecraft:smooth_quartz,10,minecraft:quartz_block,100)
RB(-3,10,-2,minecraft:chiseled_quartz_block,10,minecraft:quartz_pillar,10,minecraft:smooth_quartz,10,minecraft:quartz_block,100)
RB(-3,11,-2,minecraft:chiseled_quartz_block,10,minecraft:quartz_pillar,10,minecraft:smooth_quartz,10,minecraft:quartz_block,100)
RB(-3,12,-2,minecraft:chiseled_quartz_block,10,minecraft:quartz_pillar,10,minecraft:smooth_quartz,10,minecraft:quartz_block,100)
RB(-3,10,-1,minecraft:chiseled_quartz_block,10,minecraft:quartz_pillar,10,minecraft:smooth_quartz,10,minecraft:quartz_block,100)
RB(-3,11,-1,minecraft:chiseled_quartz_block,10,minecraft:quartz_pillar,10,minecraft:smooth_quartz,10,minecraft:quartz_block,100)
RB(-3,12,-1,minecraft:chiseled_quartz_block,10,minecraft:quartz_pillar,10,minecraft:smooth_quartz,10,minecraft:quartz_block,100)
RB(-3,10,0,minecraft:chiseled_quartz_block,10,minecraft:quartz_pillar,10,minecraft:smooth_quartz,10,minecraft:quartz_block,100)
RB(-3,11,0,minecraft:chiseled_quartz_block,10,minecraft:quartz_pillar,10,minecraft:smooth_quartz,10,minecraft:quartz_block,100)
RB(-3,12,0,minecraft:chiseled_quartz_block,10,minecraft:quartz_pillar,10,minecraft:smooth_quartz,10,minecraft:quartz_block,100)
RB(-3,10,1,minecraft:chiseled_quartz_block,10,minecraft:quartz_pillar,10,minecraft:smooth_quartz,10,minecraft:quartz_block,100)
RB(-3,11,1,minecraft:chiseled_quartz_block,10,minecraft:quartz_pillar,10,minecraft:smooth_quartz,10,minecraft:quartz_block,100)
RB(-3,12,1,minecraft:chiseled_quartz_block,10,minecraft:quartz_pillar,10,minecraft:smooth_quartz,10,minecraft:quartz_block,100)
RB(-3,10,2,minecraft:chiseled_quartz_block,10,minecraft:quartz_pillar,10,minecraft:smooth_quartz,10,minecraft:quartz_block,100)
RB(-3,11,2,minecraft:chiseled_quartz_block,10,minecraft:quartz_pillar,10,minecraft:smooth_quartz,10,minecraft:quartz_block,100)
RB(-3,12,2,minecraft:chiseled_quartz_block,10,minecraft:quartz_pillar,10,minecraft:smooth_quartz,10,minecraft:quartz_block,100)
RB(-3,11,3,minecraft:chiseled_quartz_block,10,minecraft:quartz_pillar,10,minecraft:smooth_quartz,10,minecraft:quartz_block,100)
RB(-3,12,3,minecraft:chiseled_quartz_block,10,minecraft:quartz_pillar,10,minecraft:smooth_quartz,10,minecraft:quartz_block,100)
RB(-3,11,4,minecraft:chiseled_quartz_block,10,minecraft:quartz_pillar,10,minecraft:smooth_quartz,10,minecraft:quartz_block,100)
RB(-3,12,4,minecraft:chiseled_quartz_block,10,minecraft:quartz_pillar,10,minecraft:smooth_quartz,10,minecraft:quartz_block,100)
RB(-3,12,5,minecraft:chiseled_quartz_block,10,minecraft:quartz_pillar,10,minecraft:smooth_quartz,10,minecraft:quartz_block,100)
RB(-3,12,6,minecraft:chiseled_quartz_block,10,minecraft:quartz_pillar,10,minecraft:smooth_quartz,10,minecraft:quartz_block,100)
RB(-2,9,-7,minecraft:chiseled_quartz_block,10,minecraft:quartz_pillar,10,minecraft:smooth_quartz,10,minecraft:quartz_block,100)
RB(-2,10,-7,minecraft:chiseled_quartz_block,10,minecraft:quartz_pillar,10,minecraft:smooth_quartz,10,minecraft:quartz_block,100)
RB(-2,9,-6,minecraft:chiseled_quartz_block,10,minecraft:quartz_pillar,10,minecraft:smooth_quartz,10,minecraft:quartz_block,100)
RB(-2,10,-6,minecraft:chiseled_quartz_block,10,minecraft:quartz_pillar,10,minecraft:smooth_quartz,10,minecraft:quartz_block,100)
RB(-2,11,-6,minecraft:chiseled_quartz_block,10,minecraft:quartz_pillar,10,minecraft:smooth_quartz,10,minecraft:quartz_block,100)
RB(-2,12,-6,minecraft:chiseled_quartz_block,10,minecraft:quartz_pillar,10,minecraft:smooth_quartz,10,minecraft:quartz_block,100)
RB(-2,9,-5,minecraft:chiseled_quartz_block,10,minecraft:quartz_pillar,10,minecraft:smooth_quartz,10,minecraft:quartz_block,100)
RB(-2,10,-5,minecraft:chiseled_quartz_block,10,minecraft:quartz_pillar,10,minecraft:smooth_quartz,10,minecraft:quartz_block,100)
RB(-2,11,-5,minecraft:chiseled_quartz_block,10,minecraft:quartz_pillar,10,minecraft:smooth_quartz,10,minecraft:quartz_block,100)
RB(-2,12,-5,minecraft:chiseled_quartz_block,10,minecraft:quartz_pillar,10,minecraft:smooth_quartz,10,minecraft:quartz_block,100)
RB(-2,9,-4,minecraft:chiseled_quartz_block,10,minecraft:quartz_pillar,10,minecraft:smooth_quartz,10,minecraft:quartz_block,100)
RB(-2,10,-4,minecraft:chiseled_quartz_block,10,minecraft:quartz_pillar,10,minecraft:smooth_quartz,10,minecraft:quartz_block,100)
RB(-2,11,-4,minecraft:chiseled_quartz_block,10,minecraft:quartz_pillar,10,minecraft:smooth_quartz,10,minecraft:quartz_block,100)
RB(-2,12,-4,minecraft:chiseled_quartz_block,10,minecraft:quartz_pillar,10,minecraft:smooth_quartz,10,minecraft:quartz_block,100)
RB(-2,9,-3,minecraft:chiseled_quartz_block,10,minecraft:quartz_pillar,10,minecraft:smooth_quartz,10,minecraft:quartz_block,100)
RB(-2,10,-3,minecraft:chiseled_quartz_block,10,minecraft:quartz_pillar,10,minecraft:smooth_quartz,10,minecraft:quartz_block,100)
RB(-2,11,-3,minecraft:chiseled_quartz_block,10,minecraft:quartz_pillar,10,minecraft:smooth_quartz,10,minecraft:quartz_block,100)
RB(-2,12,-3,minecraft:chiseled_quartz_block,10,minecraft:quartz_pillar,10,minecraft:smooth_quartz,10,minecraft:quartz_block,100)
RB(-2,9,-2,minecraft:chiseled_quartz_block,10,minecraft:quartz_pillar,10,minecraft:smooth_quartz,10,minecraft:quartz_block,100)
RB(-2,10,-2,minecraft:chiseled_quartz_block,10,minecraft:quartz_pillar,10,minecraft:smooth_quartz,10,minecraft:quartz_block,100)
RB(-2,11,-2,minecraft:chiseled_quartz_block,10,minecraft:quartz_pillar,10,minecraft:smooth_quartz,10,minecraft:quartz_block,100)
RB(-2,12,-2,minecraft:chiseled_quartz_block,10,minecraft:quartz_pillar,10,minecraft:smooth_quartz,10,minecraft:quartz_block,100)
RB(-2,9,-1,minecraft:chiseled_quartz_block,10,minecraft:quartz_pillar,10,minecraft:smooth_quartz,10,minecraft:quartz_block,100)
RB(-2,10,-1,minecraft:chiseled_quartz_block,10,minecraft:quartz_pillar,10,minecraft:smooth_quartz,10,minecraft:quartz_block,100)
RB(-2,11,-1,minecraft:chiseled_quartz_block,10,minecraft:quartz_pillar,10,minecraft:smooth_quartz,10,minecraft:quartz_block,100)
RB(-2,12,-1,minecraft:chiseled_quartz_block,10,minecraft:quartz_pillar,10,minecraft:smooth_quartz,10,minecraft:quartz_block,100)
RB(-2,9,0,minecraft:chiseled_quartz_block,10,minecraft:quartz_pillar,10,minecraft:smooth_quartz,10,minecraft:quartz_block,100)
RB(-2,10,0,minecraft:chiseled_quartz_block,10,minecraft:quartz_pillar,10,minecraft:smooth_quartz,10,minecraft:quartz_block,100)
RB(-2,11,0,minecraft:chiseled_quartz_block,10,minecraft:quartz_pillar,10,minecraft:smooth_quartz,10,minecraft:quartz_block,100)
RB(-2,12,0,minecraft:chiseled_quartz_block,10,minecraft:quartz_pillar,10,minecraft:smooth_quartz,10,minecraft:quartz_block,100)
RB(-2,9,1,minecraft:chiseled_quartz_block,10,minecraft:quartz_pillar,10,minecraft:smooth_quartz,10,minecraft:quartz_block,100)
RB(-2,10,1,minecraft:chiseled_quartz_block,10,minecraft:quartz_pillar,10,minecraft:smooth_quartz,10,minecraft:quartz_block,100)
RB(-2,11,1,minecraft:chiseled_quartz_block,10,minecraft:quartz_pillar,10,minecraft:smooth_quartz,10,minecraft:quartz_block,100)
RB(-2,12,1,minecraft:chiseled_quartz_block,10,minecraft:quartz_pillar,10,minecraft:smooth_quartz,10,minecraft:quartz_block,100)
RB(-2,10,2,minecraft:chiseled_quartz_block,10,minecraft:quartz_pillar,10,minecraft:smooth_quartz,10,minecraft:quartz_block,100)
RB(-2,11,2,minecraft:chiseled_quartz_block,10,minecraft:quartz_pillar,10,minecraft:smooth_quartz,10,minecraft:quartz_block,100)
RB(-2,12,2,minecraft:chiseled_quartz_block,10,minecraft:quartz_pillar,10,minecraft:smooth_quartz,10,minecraft:quartz_block,100)
RB(-2,10,3,minecraft:chiseled_quartz_block,10,minecraft:quartz_pillar,10,minecraft:smooth_quartz,10,minecraft:quartz_block,100)
RB(-2,11,3,minecraft:chiseled_quartz_block,10,minecraft:quartz_pillar,10,minecraft:smooth_quartz,10,minecraft:quartz_block,100)
RB(-2,12,3,minecraft:chiseled_quartz_block,10,minecraft:quartz_pillar,10,minecraft:smooth_quartz,10,minecraft:quartz_block,100)
RB(-2,11,4,minecraft:chiseled_quartz_block,10,minecraft:quartz_pillar,10,minecraft:smooth_quartz,10,minecraft:quartz_block,100)
RB(-2,12,4,minecraft:chiseled_quartz_block,10,minecraft:quartz_pillar,10,minecraft:smooth_quartz,10,minecraft:quartz_block,100)
RB(-2,11,5,minecraft:chiseled_quartz_block,10,minecraft:quartz_pillar,10,minecraft:smooth_quartz,10,minecraft:quartz_block,100)
RB(-2,12,5,minecraft:chiseled_quartz_block,10,minecraft:quartz_pillar,10,minecraft:smooth_quartz,10,minecraft:quartz_block,100)
RB(-2,12,6,minecraft:chiseled_quartz_block,10,minecraft:quartz_pillar,10,minecraft:smooth_quartz,10,minecraft:quartz_block,100)
RB(-2,12,7,minecraft:chiseled_quartz_block,10,minecraft:quartz_pillar,10,minecraft:smooth_quartz,10,minecraft:quartz_block,100)
RB(-1,8,-7,minecraft:chiseled_quartz_block,10,minecraft:quartz_pillar,10,minecraft:smooth_quartz,10,minecraft:quartz_block,100)
RB(-1,9,-7,minecraft:chiseled_quartz_block,10,minecraft:quartz_pillar,10,minecraft:smooth_quartz,10,minecraft:quartz_block,100)
RB(-1,10,-7,minecraft:chiseled_quartz_block,10,minecraft:quartz_pillar,10,minecraft:smooth_quartz,10,minecraft:quartz_block,100)
RB(-1,8,-6,minecraft:chiseled_quartz_block,10,minecraft:quartz_pillar,10,minecraft:smooth_quartz,10,minecraft:quartz_block,100)
RB(-1,9,-6,minecraft:chiseled_quartz_block,10,minecraft:quartz_pillar,10,minecraft:smooth_quartz,10,minecraft:quartz_block,100)
RB(-1,10,-6,minecraft:chiseled_quartz_block,10,minecraft:quartz_pillar,10,minecraft:smooth_quartz,10,minecraft:quartz_block,100)
RB(-1,11,-6,minecraft:chiseled_quartz_block,10,minecraft:quartz_pillar,10,minecraft:smooth_quartz,10,minecraft:quartz_block,100)
RB(-1,12,-6,minecraft:chiseled_quartz_block,10,minecraft:quartz_pillar,10,minecraft:smooth_quartz,10,minecraft:quartz_block,100)
RB(-1,8,-5,minecraft:chiseled_quartz_block,10,minecraft:quartz_pillar,10,minecraft:smooth_quartz,10,minecraft:quartz_block,100)
RB(-1,9,-5,minecraft:chiseled_quartz_block,10,minecraft:quartz_pillar,10,minecraft:smooth_quartz,10,minecraft:quartz_block,100)
RB(-1,10,-5,minecraft:chiseled_quartz_block,10,minecraft:quartz_pillar,10,minecraft:smooth_quartz,10,minecraft:quartz_block,100)
RB(-1,11,-5,minecraft:chiseled_quartz_block,10,minecraft:quartz_pillar,10,minecraft:smooth_quartz,10,minecraft:quartz_block,100)
RB(-1,12,-5,minecraft:chiseled_quartz_block,10,minecraft:quartz_pillar,10,minecraft:smooth_quartz,10,minecraft:quartz_block,100)
RB(-1,8,-4,minecraft:chiseled_quartz_block,10,minecraft:quartz_pillar,10,minecraft:smooth_quartz,10,minecraft:quartz_block,100)
RB(-1,9,-4,minecraft:chiseled_quartz_block,10,minecraft:quartz_pillar,10,minecraft:smooth_quartz,10,minecraft:quartz_block,100)
RB(-1,10,-4,minecraft:chiseled_quartz_block,10,minecraft:quartz_pillar,10,minecraft:smooth_quartz,10,minecraft:quartz_block,100)
RB(-1,11,-4,minecraft:chiseled_quartz_block,10,minecraft:quartz_pillar,10,minecraft:smooth_quartz,10,minecraft:quartz_block,100)
RB(-1,12,-4,minecraft:chiseled_quartz_block,10,minecraft:quartz_pillar,10,minecraft:smooth_quartz,10,minecraft:quartz_block,100)
RB(-1,8,-3,minecraft:chiseled_quartz_block,10,minecraft:quartz_pillar,10,minecraft:smooth_quartz,10,minecraft:quartz_block,100)
RB(-1,9,-3,minecraft:chiseled_quartz_block,10,minecraft:quartz_pillar,10,minecraft:smooth_quartz,10,minecraft:quartz_block,100)
RB(-1,10,-3,minecraft:chiseled_quartz_block,10,minecraft:quartz_pillar,10,minecraft:smooth_quartz,10,minecraft:quartz_block,100)
RB(-1,11,-3,minecraft:chiseled_quartz_block,10,minecraft:quartz_pillar,10,minecraft:smooth_quartz,10,minecraft:quartz_block,100)
RB(-1,12,-3,minecraft:chiseled_quartz_block,10,minecraft:quartz_pillar,10,minecraft:smooth_quartz,10,minecraft:quartz_block,100)
RB(-1,8,-2,minecraft:chiseled_quartz_block,10,minecraft:quartz_pillar,10,minecraft:smooth_quartz,10,minecraft:quartz_block,100)
RB(-1,9,-2,minecraft:chiseled_quartz_block,10,minecraft:quartz_pillar,10,minecraft:smooth_quartz,10,minecraft:quartz_block,100)
RB(-1,10,-2,minecraft:chiseled_quartz_block,10,minecraft:quartz_pillar,10,minecraft:smooth_quartz,10,minecraft:quartz_block,100)
RB(-1,11,-2,minecraft:chiseled_quartz_block,10,minecraft:quartz_pillar,10,minecraft:smooth_quartz,10,minecraft:quartz_block,100)
RB(-1,12,-2,minecraft:chiseled_quartz_block,10,minecraft:quartz_pillar,10,minecraft:smooth_quartz,10,minecraft:quartz_block,100)
RB(-1,8,-1,minecraft:chiseled_quartz_block,10,minecraft:quartz_pillar,10,minecraft:smooth_quartz,10,minecraft:quartz_block,100)
RB(-1,9,-1,minecraft:chiseled_quartz_block,10,minecraft:quartz_pillar,10,minecraft:smooth_quartz,10,minecraft:quartz_block,100)
RB(-1,10,-1,minecraft:chiseled_quartz_block,10,minecraft:quartz_pillar,10,minecraft:smooth_quartz,10,minecraft:quartz_block,100)
RB(-1,11,-1,minecraft:chiseled_quartz_block,10,minecraft:quartz_pillar,10,minecraft:smooth_quartz,10,minecraft:quartz_block,100)
RB(-1,12,-1,minecraft:chiseled_quartz_block,10,minecraft:quartz_pillar,10,minecraft:smooth_quartz,10,minecraft:quartz_block,100)
RB(-1,9,0,minecraft:chiseled_quartz_block,10,minecraft:quartz_pillar,10,minecraft:smooth_quartz,10,minecraft:quartz_block,100)
RB(-1,10,0,minecraft:chiseled_quartz_block,10,minecraft:quartz_pillar,10,minecraft:smooth_quartz,10,minecraft:quartz_block,100)
RB(-1,11,0,minecraft:chiseled_quartz_block,10,minecraft:quartz_pillar,10,minecraft:smooth_quartz,10,minecraft:quartz_block,100)
RB(-1,12,0,minecraft:chiseled_quartz_block,10,minecraft:quartz_pillar,10,minecraft:smooth_quartz,10,minecraft:quartz_block,100)
RB(-1,9,1,minecraft:chiseled_quartz_block,10,minecraft:quartz_pillar,10,minecraft:smooth_quartz,10,minecraft:quartz_block,100)
RB(-1,10,1,minecraft:chiseled_quartz_block,10,minecraft:quartz_pillar,10,minecraft:smooth_quartz,10,minecraft:quartz_block,100)
RB(-1,11,1,minecraft:chiseled_quartz_block,10,minecraft:quartz_pillar,10,minecraft:smooth_quartz,10,minecraft:quartz_block,100)
RB(-1,12,1,minecraft:chiseled_quartz_block,10,minecraft:quartz_pillar,10,minecraft:smooth_quartz,10,minecraft:quartz_block,100)
RB(-1,10,2,minecraft:chiseled_quartz_block,10,minecraft:quartz_pillar,10,minecraft:smooth_quartz,10,minecraft:quartz_block,100)
RB(-1,11,2,minecraft:chiseled_quartz_block,10,minecraft:quartz_pillar,10,minecraft:smooth_quartz,10,minecraft:quartz_block,100)
RB(-1,12,2,minecraft:chiseled_quartz_block,10,minecraft:quartz_pillar,10,minecraft:smooth_quartz,10,minecraft:quartz_block,100)
RB(-1,10,3,minecraft:chiseled_quartz_block,10,minecraft:quartz_pillar,10,minecraft:smooth_quartz,10,minecraft:quartz_block,100)
RB(-1,11,3,minecraft:chiseled_quartz_block,10,minecraft:quartz_pillar,10,minecraft:smooth_quartz,10,minecraft:quartz_block,100)
RB(-1,12,3,minecraft:chiseled_quartz_block,10,minecraft:quartz_pillar,10,minecraft:smooth_quartz,10,minecraft:quartz_block,100)
RB(-1,11,4,minecraft:chiseled_quartz_block,10,minecraft:quartz_pillar,10,minecraft:smooth_quartz,10,minecraft:quartz_block,100)
RB(-1,12,4,minecraft:chiseled_quartz_block,10,minecraft:quartz_pillar,10,minecraft:smooth_quartz,10,minecraft:quartz_block,100)
RB(-1,11,5,minecraft:chiseled_quartz_block,10,minecraft:quartz_pillar,10,minecraft:smooth_quartz,10,minecraft:quartz_block,100)
RB(-1,12,5,minecraft:chiseled_quartz_block,10,minecraft:quartz_pillar,10,minecraft:smooth_quartz,10,minecraft:quartz_block,100)
RB(-1,11,6,minecraft:chiseled_quartz_block,10,minecraft:quartz_pillar,10,minecraft:smooth_quartz,10,minecraft:quartz_block,100)
RB(-1,12,6,minecraft:chiseled_quartz_block,10,minecraft:quartz_pillar,10,minecraft:smooth_quartz,10,minecraft:quartz_block,100)
RB(-1,12,7,minecraft:chiseled_quartz_block,10,minecraft:quartz_pillar,10,minecraft:smooth_quartz,10,minecraft:quartz_block,100)
RB(-1,12,8,minecraft:chiseled_quartz_block,10,minecraft:quartz_pillar,10,minecraft:smooth_quartz,10,minecraft:quartz_block,100)
RB(0,7,-8,minecraft:chiseled_quartz_block,10,minecraft:quartz_pillar,10,minecraft:smooth_quartz,10,minecraft:quartz_block,100)
RB(0,7,-7,minecraft:chiseled_quartz_block,10,minecraft:quartz_pillar,10,minecraft:smooth_quartz,10,minecraft:quartz_block,100)
RB(0,8,-7,minecraft:chiseled_quartz_block,10,minecraft:quartz_pillar,10,minecraft:smooth_quartz,10,minecraft:quartz_block,100)
RB(0,9,-7,minecraft:chiseled_quartz_block,10,minecraft:quartz_pillar,10,minecraft:smooth_quartz,10,minecraft:quartz_block,100)
RB(0,10,-7,minecraft:chiseled_quartz_block,10,minecraft:quartz_pillar,10,minecraft:smooth_quartz,10,minecraft:quartz_block,100)
RB(0,7,-6,minecraft:chiseled_quartz_block,10,minecraft:quartz_pillar,10,minecraft:smooth_quartz,10,minecraft:quartz_block,100)
RB(0,8,-6,minecraft:chiseled_quartz_block,10,minecraft:quartz_pillar,10,minecraft:smooth_quartz,10,minecraft:quartz_block,100)
RB(0,9,-6,minecraft:chiseled_quartz_block,10,minecraft:quartz_pillar,10,minecraft:smooth_quartz,10,minecraft:quartz_block,100)
RB(0,10,-6,minecraft:chiseled_quartz_block,10,minecraft:quartz_pillar,10,minecraft:smooth_quartz,10,minecraft:quartz_block,100)
RB(0,11,-6,minecraft:chiseled_quartz_block,10,minecraft:quartz_pillar,10,minecraft:smooth_quartz,10,minecraft:quartz_block,100)
RB(0,12,-6,minecraft:chiseled_quartz_block,10,minecraft:quartz_pillar,10,minecraft:smooth_quartz,10,minecraft:quartz_block,100)
RB(0,7,-5,minecraft:chiseled_quartz_block,10,minecraft:quartz_pillar,10,minecraft:smooth_quartz,10,minecraft:quartz_block,100)
RB(0,8,-5,minecraft:chiseled_quartz_block,10,minecraft:quartz_pillar,10,minecraft:smooth_quartz,10,minecraft:quartz_block,100)
RB(0,9,-5,minecraft:chiseled_quartz_block,10,minecraft:quartz_pillar,10,minecraft:smooth_quartz,10,minecraft:quartz_block,100)
RB(0,10,-5,minecraft:chiseled_quartz_block,10,minecraft:quartz_pillar,10,minecraft:smooth_quartz,10,minecraft:quartz_block,100)
RB(0,11,-5,minecraft:chiseled_quartz_block,10,minecraft:quartz_pillar,10,minecraft:smooth_quartz,10,minecraft:quartz_block,100)
RB(0,12,-5,minecraft:chiseled_quartz_block,10,minecraft:quartz_pillar,10,minecraft:smooth_quartz,10,minecraft:quartz_block,100)
RB(0,8,-4,minecraft:chiseled_quartz_block,10,minecraft:quartz_pillar,10,minecraft:smooth_quartz,10,minecraft:quartz_block,100)
RB(0,9,-4,minecraft:chiseled_quartz_block,10,minecraft:quartz_pillar,10,minecraft:smooth_quartz,10,minecraft:quartz_block,100)
RB(0,10,-4,minecraft:chiseled_quartz_block,10,minecraft:quartz_pillar,10,minecraft:smooth_quartz,10,minecraft:quartz_block,100)
RB(0,11,-4,minecraft:chiseled_quartz_block,10,minecraft:quartz_pillar,10,minecraft:smooth_quartz,10,minecraft:quartz_block,100)
RB(0,12,-4,minecraft:chiseled_quartz_block,10,minecraft:quartz_pillar,10,minecraft:smooth_quartz,10,minecraft:quartz_block,100)
RB(0,8,-3,minecraft:chiseled_quartz_block,10,minecraft:quartz_pillar,10,minecraft:smooth_quartz,10,minecraft:quartz_block,100)
RB(0,9,-3,minecraft:chiseled_quartz_block,10,minecraft:quartz_pillar,10,minecraft:smooth_quartz,10,minecraft:quartz_block,100)
RB(0,10,-3,minecraft:chiseled_quartz_block,10,minecraft:quartz_pillar,10,minecraft:smooth_quartz,10,minecraft:quartz_block,100)
RB(0,11,-3,minecraft:chiseled_quartz_block,10,minecraft:quartz_pillar,10,minecraft:smooth_quartz,10,minecraft:quartz_block,100)
RB(0,12,-3,minecraft:chiseled_quartz_block,10,minecraft:quartz_pillar,10,minecraft:smooth_quartz,10,minecraft:quartz_block,100)
RB(0,8,-2,minecraft:chiseled_quartz_block,10,minecraft:quartz_pillar,10,minecraft:smooth_quartz,10,minecraft:quartz_block,100)
RB(0,9,-2,minecraft:chiseled_quartz_block,10,minecraft:quartz_pillar,10,minecraft:smooth_quartz,10,minecraft:quartz_block,100)
RB(0,10,-2,minecraft:chiseled_quartz_block,10,minecraft:quartz_pillar,10,minecraft:smooth_quartz,10,minecraft:quartz_block,100)
RB(0,11,-2,minecraft:chiseled_quartz_block,10,minecraft:quartz_pillar,10,minecraft:smooth_quartz,10,minecraft:quartz_block,100)
RB(0,12,-2,minecraft:chiseled_quartz_block,10,minecraft:quartz_pillar,10,minecraft:smooth_quartz,10,minecraft:quartz_block,100)
RB(0,8,-1,minecraft:chiseled_quartz_block,10,minecraft:quartz_pillar,10,minecraft:smooth_quartz,10,minecraft:quartz_block,100)
RB(0,9,-1,minecraft:chiseled_quartz_block,10,minecraft:quartz_pillar,10,minecraft:smooth_quartz,10,minecraft:quartz_block,100)
RB(0,10,-1,minecraft:chiseled_quartz_block,10,minecraft:quartz_pillar,10,minecraft:smooth_quartz,10,minecraft:quartz_block,100)
RB(0,11,-1,minecraft:chiseled_quartz_block,10,minecraft:quartz_pillar,10,minecraft:smooth_quartz,10,minecraft:quartz_block,100)
RB(0,12,-1,minecraft:chiseled_quartz_block,10,minecraft:quartz_pillar,10,minecraft:smooth_quartz,10,minecraft:quartz_block,100)
RB(0,8,0,minecraft:chiseled_quartz_block,10,minecraft:quartz_pillar,10,minecraft:smooth_quartz,10,minecraft:quartz_block,100)
RB(0,9,0,minecraft:chiseled_quartz_block,10,minecraft:quartz_pillar,10,minecraft:smooth_quartz,10,minecraft:quartz_block,100)
RB(0,10,0,minecraft:chiseled_quartz_block,10,minecraft:quartz_pillar,10,minecraft:smooth_quartz,10,minecraft:quartz_block,100)
RB(0,11,0,minecraft:chiseled_quartz_block,10,minecraft:quartz_pillar,10,minecraft:smooth_quartz,10,minecraft:quartz_block,100)
RB(0,12,0,minecraft:chiseled_quartz_block,10,minecraft:quartz_pillar,10,minecraft:smooth_quartz,10,minecraft:quartz_block,100)
RB(0,9,1,minecraft:chiseled_quartz_block,10,minecraft:quartz_pillar,10,minecraft:smooth_quartz,10,minecraft:quartz_block,100)
RB(0,10,1,minecraft:chiseled_quartz_block,10,minecraft:quartz_pillar,10,minecraft:smooth_quartz,10,minecraft:quartz_block,100)
RB(0,11,1,minecraft:chiseled_quartz_block,10,minecraft:quartz_pillar,10,minecraft:smooth_quartz,10,minecraft:quartz_block,100)
RB(0,12,1,minecraft:chiseled_quartz_block,10,minecraft:quartz_pillar,10,minecraft:smooth_quartz,10,minecraft:quartz_block,100)
RB(0,9,2,minecraft:chiseled_quartz_block,10,minecraft:quartz_pillar,10,minecraft:smooth_quartz,10,minecraft:quartz_block,100)
RB(0,10,2,minecraft:chiseled_quartz_block,10,minecraft:quartz_pillar,10,minecraft:smooth_quartz,10,minecraft:quartz_block,100)
RB(0,11,2,minecraft:chiseled_quartz_block,10,minecraft:quartz_pillar,10,minecraft:smooth_quartz,10,minecraft:quartz_block,100)
RB(0,12,2,minecraft:chiseled_quartz_block,10,minecraft:quartz_pillar,10,minecraft:smooth_quartz,10,minecraft:quartz_block,100)
RB(0,10,3,minecraft:chiseled_quartz_block,10,minecraft:quartz_pillar,10,minecraft:smooth_quartz,10,minecraft:quartz_block,100)
RB(0,11,3,minecraft:chiseled_quartz_block,10,minecraft:quartz_pillar,10,minecraft:smooth_quartz,10,minecraft:quartz_block,100)
RB(0,12,3,minecraft:chiseled_quartz_block,10,minecraft:quartz_pillar,10,minecraft:smooth_quartz,10,minecraft:quartz_block,100)
RB(0,10,4,minecraft:chiseled_quartz_block,10,minecraft:quartz_pillar,10,minecraft:smooth_quartz,10,minecraft:quartz_block,100)
RB(0,11,4,minecraft:chiseled_quartz_block,10,minecraft:quartz_pillar,10,minecraft:smooth_quartz,10,minecraft:quartz_block,100)
RB(0,12,4,minecraft:chiseled_quartz_block,10,minecraft:quartz_pillar,10,minecraft:smooth_quartz,10,minecraft:quartz_block,100)
RB(0,11,5,minecraft:chiseled_quartz_block,10,minecraft:quartz_pillar,10,minecraft:smooth_quartz,10,minecraft:quartz_block,100)
RB(0,12,5,minecraft:chiseled_quartz_block,10,minecraft:quartz_pillar,10,minecraft:smooth_quartz,10,minecraft:quartz_block,100)
RB(0,11,6,minecraft:chiseled_quartz_block,10,minecraft:quartz_pillar,10,minecraft:smooth_quartz,10,minecraft:quartz_block,100)
RB(0,12,6,minecraft:chiseled_quartz_block,10,minecraft:quartz_pillar,10,minecraft:smooth_quartz,10,minecraft:quartz_block,100)
RB(0,12,7,minecraft:chiseled_quartz_block,10,minecraft:quartz_pillar,10,minecraft:smooth_quartz,10,minecraft:quartz_block,100)
RB(0,12,8,minecraft:chiseled_quartz_block,10,minecraft:quartz_pillar,10,minecraft:smooth_quartz,10,minecraft:quartz_block,100)
RB(1,7,-8,minecraft:chiseled_quartz_block,10,minecraft:quartz_pillar,10,minecraft:smooth_quartz,10,minecraft:quartz_block,100)
RB(1,7,-7,minecraft:chiseled_quartz_block,10,minecraft:quartz_pillar,10,minecraft:smooth_quartz,10,minecraft:quartz_block,100)
RB(1,8,-7,minecraft:chiseled_quartz_block,10,minecraft:quartz_pillar,10,minecraft:smooth_quartz,10,minecraft:quartz_block,100)
RB(1,9,-7,minecraft:chiseled_quartz_block,10,minecraft:quartz_pillar,10,minecraft:smooth_quartz,10,minecraft:quartz_block,100)
RB(1,10,-7,minecraft:chiseled_quartz_block,10,minecraft:quartz_pillar,10,minecraft:smooth_quartz,10,minecraft:quartz_block,100)
RB(1,11,-7,minecraft:chiseled_quartz_block,10,minecraft:quartz_pillar,10,minecraft:smooth_quartz,10,minecraft:quartz_block,100)
RB(1,7,-6,minecraft:chiseled_quartz_block,10,minecraft:quartz_pillar,10,minecraft:smooth_quartz,10,minecraft:quartz_block,100)
RB(1,8,-6,minecraft:chiseled_quartz_block,10,minecraft:quartz_pillar,10,minecraft:smooth_quartz,10,minecraft:quartz_block,100)
RB(1,9,-6,minecraft:chiseled_quartz_block,10,minecraft:quartz_pillar,10,minecraft:smooth_quartz,10,minecraft:quartz_block,100)
RB(1,10,-6,minecraft:chiseled_quartz_block,10,minecraft:quartz_pillar,10,minecraft:smooth_quartz,10,minecraft:quartz_block,100)
RB(1,11,-6,minecraft:chiseled_quartz_block,10,minecraft:quartz_pillar,10,minecraft:smooth_quartz,10,minecraft:quartz_block,100)
RB(1,12,-6,minecraft:chiseled_quartz_block,10,minecraft:quartz_pillar,10,minecraft:smooth_quartz,10,minecraft:quartz_block,100)
RB(1,7,-5,minecraft:chiseled_quartz_block,10,minecraft:quartz_pillar,10,minecraft:smooth_quartz,10,minecraft:quartz_block,100)
RB(1,8,-5,minecraft:chiseled_quartz_block,10,minecraft:quartz_pillar,10,minecraft:smooth_quartz,10,minecraft:quartz_block,100)
RB(1,9,-5,minecraft:chiseled_quartz_block,10,minecraft:quartz_pillar,10,minecraft:smooth_quartz,10,minecraft:quartz_block,100)
RB(1,10,-5,minecraft:chiseled_quartz_block,10,minecraft:quartz_pillar,10,minecraft:smooth_quartz,10,minecraft:quartz_block,100)
RB(1,11,-5,minecraft:chiseled_quartz_block,10,minecraft:quartz_pillar,10,minecraft:smooth_quartz,10,minecraft:quartz_block,100)
RB(1,12,-5,minecraft:chiseled_quartz_block,10,minecraft:quartz_pillar,10,minecraft:smooth_quartz,10,minecraft:quartz_block,100)
RB(1,7,-4,minecraft:chiseled_quartz_block,10,minecraft:quartz_pillar,10,minecraft:smooth_quartz,10,minecraft:quartz_block,100)
RB(1,8,-4,minecraft:chiseled_quartz_block,10,minecraft:quartz_pillar,10,minecraft:smooth_quartz,10,minecraft:quartz_block,100)
RB(1,9,-4,minecraft:chiseled_quartz_block,10,minecraft:quartz_pillar,10,minecraft:smooth_quartz,10,minecraft:quartz_block,100)
RB(1,10,-4,minecraft:chiseled_quartz_block,10,minecraft:quartz_pillar,10,minecraft:smooth_quartz,10,minecraft:quartz_block,100)
RB(1,11,-4,minecraft:chiseled_quartz_block,10,minecraft:quartz_pillar,10,minecraft:smooth_quartz,10,minecraft:quartz_block,100)
RB(1,12,-4,minecraft:chiseled_quartz_block,10,minecraft:quartz_pillar,10,minecraft:smooth_quartz,10,minecraft:quartz_block,100)
RB(1,7,-3,minecraft:chiseled_quartz_block,10,minecraft:quartz_pillar,10,minecraft:smooth_quartz,10,minecraft:quartz_block,100)
RB(1,8,-3,minecraft:chiseled_quartz_block,10,minecraft:quartz_pillar,10,minecraft:smooth_quartz,10,minecraft:quartz_block,100)
RB(1,9,-3,minecraft:chiseled_quartz_block,10,minecraft:quartz_pillar,10,minecraft:smooth_quartz,10,minecraft:quartz_block,100)
RB(1,10,-3,minecraft:chiseled_quartz_block,10,minecraft:quartz_pillar,10,minecraft:smooth_quartz,10,minecraft:quartz_block,100)
RB(1,11,-3,minecraft:chiseled_quartz_block,10,minecraft:quartz_pillar,10,minecraft:smooth_quartz,10,minecraft:quartz_block,100)
RB(1,12,-3,minecraft:chiseled_quartz_block,10,minecraft:quartz_pillar,10,minecraft:smooth_quartz,10,minecraft:quartz_block,100)
RB(1,7,-2,minecraft:chiseled_quartz_block,10,minecraft:quartz_pillar,10,minecraft:smooth_quartz,10,minecraft:quartz_block,100)
RB(1,8,-2,minecraft:chiseled_quartz_block,10,minecraft:quartz_pillar,10,minecraft:smooth_quartz,10,minecraft:quartz_block,100)
RB(1,9,-2,minecraft:chiseled_quartz_block,10,minecraft:quartz_pillar,10,minecraft:smooth_quartz,10,minecraft:quartz_block,100)
RB(1,10,-2,minecraft:chiseled_quartz_block,10,minecraft:quartz_pillar,10,minecraft:smooth_quartz,10,minecraft:quartz_block,100)
RB(1,11,-2,minecraft:chiseled_quartz_block,10,minecraft:quartz_pillar,10,minecraft:smooth_quartz,10,minecraft:quartz_block,100)
RB(1,12,-2,minecraft:chiseled_quartz_block,10,minecraft:quartz_pillar,10,minecraft:smooth_quartz,10,minecraft:quartz_block,100)
RB(1,8,-1,minecraft:chiseled_quartz_block,10,minecraft:quartz_pillar,10,minecraft:smooth_quartz,10,minecraft:quartz_block,100)
RB(1,9,-1,minecraft:chiseled_quartz_block,10,minecraft:quartz_pillar,10,minecraft:smooth_quartz,10,minecraft:quartz_block,100)
RB(1,10,-1,minecraft:chiseled_quartz_block,10,minecraft:quartz_pillar,10,minecraft:smooth_quartz,10,minecraft:quartz_block,100)
RB(1,11,-1,minecraft:chiseled_quartz_block,10,minecraft:quartz_pillar,10,minecraft:smooth_quartz,10,minecraft:quartz_block,100)
RB(1,12,-1,minecraft:chiseled_quartz_block,10,minecraft:quartz_pillar,10,minecraft:smooth_quartz,10,minecraft:quartz_block,100)
RB(1,8,0,minecraft:chiseled_quartz_block,10,minecraft:quartz_pillar,10,minecraft:smooth_quartz,10,minecraft:quartz_block,100)
RB(1,9,0,minecraft:chiseled_quartz_block,10,minecraft:quartz_pillar,10,minecraft:smooth_quartz,10,minecraft:quartz_block,100)
RB(1,10,0,minecraft:chiseled_quartz_block,10,minecraft:quartz_pillar,10,minecraft:smooth_quartz,10,minecraft:quartz_block,100)
RB(1,11,0,minecraft:chiseled_quartz_block,10,minecraft:quartz_pillar,10,minecraft:smooth_quartz,10,minecraft:quartz_block,100)
RB(1,12,0,minecraft:chiseled_quartz_block,10,minecraft:quartz_pillar,10,minecraft:smooth_quartz,10,minecraft:quartz_block,100)
RB(1,9,1,minecraft:chiseled_quartz_block,10,minecraft:quartz_pillar,10,minecraft:smooth_quartz,10,minecraft:quartz_block,100)
RB(1,10,1,minecraft:chiseled_quartz_block,10,minecraft:quartz_pillar,10,minecraft:smooth_quartz,10,minecraft:quartz_block,100)
RB(1,11,1,minecraft:chiseled_quartz_block,10,minecraft:quartz_pillar,10,minecraft:smooth_quartz,10,minecraft:quartz_block,100)
RB(1,12,1,minecraft:chiseled_quartz_block,10,minecraft:quartz_pillar,10,minecraft:smooth_quartz,10,minecraft:quartz_block,100)
RB(1,9,2,minecraft:chiseled_quartz_block,10,minecraft:quartz_pillar,10,minecraft:smooth_quartz,10,minecraft:quartz_block,100)
RB(1,10,2,minecraft:chiseled_quartz_block,10,minecraft:quartz_pillar,10,minecraft:smooth_quartz,10,minecraft:quartz_block,100)
RB(1,11,2,minecraft:chiseled_quartz_block,10,minecraft:quartz_pillar,10,minecraft:smooth_quartz,10,minecraft:quartz_block,100)
RB(1,12,2,minecraft:chiseled_quartz_block,10,minecraft:quartz_pillar,10,minecraft:smooth_quartz,10,minecraft:quartz_block,100)
RB(1,9,3,minecraft:chiseled_quartz_block,10,minecraft:quartz_pillar,10,minecraft:smooth_quartz,10,minecraft:quartz_block,100)
RB(1,10,3,minecraft:chiseled_quartz_block,10,minecraft:quartz_pillar,10,minecraft:smooth_quartz,10,minecraft:quartz_block,100)
RB(1,11,3,minecraft:chiseled_quartz_block,10,minecraft:quartz_pillar,10,minecraft:smooth_quartz,10,minecraft:quartz_block,100)
RB(1,12,3,minecraft:chiseled_quartz_block,10,minecraft:quartz_pillar,10,minecraft:smooth_quartz,10,minecraft:quartz_block,100)
RB(1,10,4,minecraft:chiseled_quartz_block,10,minecraft:quartz_pillar,10,minecraft:smooth_quartz,10,minecraft:quartz_block,100)
RB(1,11,4,minecraft:chiseled_quartz_block,10,minecraft:quartz_pillar,10,minecraft:smooth_quartz,10,minecraft:quartz_block,100)
RB(1,12,4,minecraft:chiseled_quartz_block,10,minecraft:quartz_pillar,10,minecraft:smooth_quartz,10,minecraft:quartz_block,100)
RB(1,10,5,minecraft:chiseled_quartz_block,10,minecraft:quartz_pillar,10,minecraft:smooth_quartz,10,minecraft:quartz_block,100)
RB(1,11,5,minecraft:chiseled_quartz_block,10,minecraft:quartz_pillar,10,minecraft:smooth_quartz,10,minecraft:quartz_block,100)
RB(1,12,5,minecraft:chiseled_quartz_block,10,minecraft:quartz_pillar,10,minecraft:smooth_quartz,10,minecraft:quartz_block,100)
RB(1,11,6,minecraft:chiseled_quartz_block,10,minecraft:quartz_pillar,10,minecraft:smooth_quartz,10,minecraft:quartz_block,100)
RB(1,12,6,minecraft:chiseled_quartz_block,10,minecraft:quartz_pillar,10,minecraft:smooth_quartz,10,minecraft:quartz_block,100)
RB(1,11,7,minecraft:chiseled_quartz_block,10,minecraft:quartz_pillar,10,minecraft:smooth_quartz,10,minecraft:quartz_block,100)
RB(1,12,7,minecraft:chiseled_quartz_block,10,minecraft:quartz_pillar,10,minecraft:smooth_quartz,10,minecraft:quartz_block,100)
RB(1,12,8,minecraft:chiseled_quartz_block,10,minecraft:quartz_pillar,10,minecraft:smooth_quartz,10,minecraft:quartz_block,100)
RB(1,12,9,minecraft:chiseled_quartz_block,10,minecraft:quartz_pillar,10,minecraft:smooth_quartz,10,minecraft:quartz_block,100)
RB(2,6,-8,minecraft:chiseled_quartz_block,10,minecraft:quartz_pillar,10,minecraft:smooth_quartz,10,minecraft:quartz_block,100)
RB(2,7,-8,minecraft:chiseled_quartz_block,10,minecraft:quartz_pillar,10,minecraft:smooth_quartz,10,minecraft:quartz_block,100)
RB(2,8,-8,minecraft:chiseled_quartz_block,10,minecraft:quartz_pillar,10,minecraft:smooth_quartz,10,minecraft:quartz_block,100)
RB(2,6,-7,minecraft:chiseled_quartz_block,10,minecraft:quartz_pillar,10,minecraft:smooth_quartz,10,minecraft:quartz_block,100)
RB(2,7,-7,minecraft:chiseled_quartz_block,10,minecraft:quartz_pillar,10,minecraft:smooth_quartz,10,minecraft:quartz_block,100)
RB(2,8,-7,minecraft:chiseled_quartz_block,10,minecraft:quartz_pillar,10,minecraft:smooth_quartz,10,minecraft:quartz_block,100)
RB(2,9,-7,minecraft:chiseled_quartz_block,10,minecraft:quartz_pillar,10,minecraft:smooth_quartz,10,minecraft:quartz_block,100)
RB(2,10,-7,minecraft:chiseled_quartz_block,10,minecraft:quartz_pillar,10,minecraft:smooth_quartz,10,minecraft:quartz_block,100)
RB(2,11,-7,minecraft:chiseled_quartz_block,10,minecraft:quartz_pillar,10,minecraft:smooth_quartz,10,minecraft:quartz_block,100)
RB(2,6,-6,minecraft:chiseled_quartz_block,10,minecraft:quartz_pillar,10,minecraft:smooth_quartz,10,minecraft:quartz_block,100)
RB(2,7,-6,minecraft:chiseled_quartz_block,10,minecraft:quartz_pillar,10,minecraft:smooth_quartz,10,minecraft:quartz_block,100)
RB(2,8,-6,minecraft:chiseled_quartz_block,10,minecraft:quartz_pillar,10,minecraft:smooth_quartz,10,minecraft:quartz_block,100)
RB(2,9,-6,minecraft:chiseled_quartz_block,10,minecraft:quartz_pillar,10,minecraft:smooth_quartz,10,minecraft:quartz_block,100)
RB(2,10,-6,minecraft:chiseled_quartz_block,10,minecraft:quartz_pillar,10,minecraft:smooth_quartz,10,minecraft:quartz_block,100)
RB(2,11,-6,minecraft:chiseled_quartz_block,10,minecraft:quartz_pillar,10,minecraft:smooth_quartz,10,minecraft:quartz_block,100)
RB(2,12,-6,minecraft:chiseled_quartz_block,10,minecraft:quartz_pillar,10,minecraft:smooth_quartz,10,minecraft:quartz_block,100)
RB(2,6,-5,minecraft:chiseled_quartz_block,10,minecraft:quartz_pillar,10,minecraft:smooth_quartz,10,minecraft:quartz_block,100)
RB(2,7,-5,minecraft:chiseled_quartz_block,10,minecraft:quartz_pillar,10,minecraft:smooth_quartz,10,minecraft:quartz_block,100)
RB(2,8,-5,minecraft:chiseled_quartz_block,10,minecraft:quartz_pillar,10,minecraft:smooth_quartz,10,minecraft:quartz_block,100)
RB(2,9,-5,minecraft:chiseled_quartz_block,10,minecraft:quartz_pillar,10,minecraft:smooth_quartz,10,minecraft:quartz_block,100)
RB(2,10,-5,minecraft:chiseled_quartz_block,10,minecraft:quartz_pillar,10,minecraft:smooth_quartz,10,minecraft:quartz_block,100)
RB(2,11,-5,minecraft:chiseled_quartz_block,10,minecraft:quartz_pillar,10,minecraft:smooth_quartz,10,minecraft:quartz_block,100)
RB(2,12,-5,minecraft:chiseled_quartz_block,10,minecraft:quartz_pillar,10,minecraft:smooth_quartz,10,minecraft:quartz_block,100)
RB(2,6,-4,minecraft:chiseled_quartz_block,10,minecraft:quartz_pillar,10,minecraft:smooth_quartz,10,minecraft:quartz_block,100)
RB(2,7,-4,minecraft:chiseled_quartz_block,10,minecraft:quartz_pillar,10,minecraft:smooth_quartz,10,minecraft:quartz_block,100)
RB(2,8,-4,minecraft:chiseled_quartz_block,10,minecraft:quartz_pillar,10,minecraft:smooth_quartz,10,minecraft:quartz_block,100)
RB(2,9,-4,minecraft:chiseled_quartz_block,10,minecraft:quartz_pillar,10,minecraft:smooth_quartz,10,minecraft:quartz_block,100)
RB(2,10,-4,minecraft:chiseled_quartz_block,10,minecraft:quartz_pillar,10,minecraft:smooth_quartz,10,minecraft:quartz_block,100)
RB(2,11,-4,minecraft:chiseled_quartz_block,10,minecraft:quartz_pillar,10,minecraft:smooth_quartz,10,minecraft:quartz_block,100)
RB(2,12,-4,minecraft:chiseled_quartz_block,10,minecraft:quartz_pillar,10,minecraft:smooth_quartz,10,minecraft:quartz_block,100)
RB(2,6,-3,minecraft:chiseled_quartz_block,10,minecraft:quartz_pillar,10,minecraft:smooth_quartz,10,minecraft:quartz_block,100)
RB(2,7,-3,minecraft:chiseled_quartz_block,10,minecraft:quartz_pillar,10,minecraft:smooth_quartz,10,minecraft:quartz_block,100)
RB(2,8,-3,minecraft:chiseled_quartz_block,10,minecraft:quartz_pillar,10,minecraft:smooth_quartz,10,minecraft:quartz_block,100)
RB(2,9,-3,minecraft:chiseled_quartz_block,10,minecraft:quartz_pillar,10,minecraft:smooth_quartz,10,minecraft:quartz_block,100)
RB(2,10,-3,minecraft:chiseled_quartz_block,10,minecraft:quartz_pillar,10,minecraft:smooth_quartz,10,minecraft:quartz_block,100)
RB(2,11,-3,minecraft:chiseled_quartz_block,10,minecraft:quartz_pillar,10,minecraft:smooth_quartz,10,minecraft:quartz_block,100)
RB(2,12,-3,minecraft:chiseled_quartz_block,10,minecraft:quartz_pillar,10,minecraft:smooth_quartz,10,minecraft:quartz_block,100)
RB(2,7,-2,minecraft:chiseled_quartz_block,10,minecraft:quartz_pillar,10,minecraft:smooth_quartz,10,minecraft:quartz_block,100)
RB(2,8,-2,minecraft:chiseled_quartz_block,10,minecraft:quartz_pillar,10,minecraft:smooth_quartz,10,minecraft:quartz_block,100)
RB(2,9,-2,minecraft:chiseled_quartz_block,10,minecraft:quartz_pillar,10,minecraft:smooth_quartz,10,minecraft:quartz_block,100)
RB(2,10,-2,minecraft:chiseled_quartz_block,10,minecraft:quartz_pillar,10,minecraft:smooth_quartz,10,minecraft:quartz_block,100)
RB(2,11,-2,minecraft:chiseled_quartz_block,10,minecraft:quartz_pillar,10,minecraft:smooth_quartz,10,minecraft:quartz_block,100)
RB(2,12,-2,minecraft:chiseled_quartz_block,10,minecraft:quartz_pillar,10,minecraft:smooth_quartz,10,minecraft:quartz_block,100)
RB(2,7,-1,minecraft:chiseled_quartz_block,10,minecraft:quartz_pillar,10,minecraft:smooth_quartz,10,minecraft:quartz_block,100)
RB(2,8,-1,minecraft:chiseled_quartz_block,10,minecraft:quartz_pillar,10,minecraft:smooth_quartz,10,minecraft:quartz_block,100)
RB(2,9,-1,minecraft:chiseled_quartz_block,10,minecraft:quartz_pillar,10,minecraft:smooth_quartz,10,minecraft:quartz_block,100)
RB(2,10,-1,minecraft:chiseled_quartz_block,10,minecraft:quartz_pillar,10,minecraft:smooth_quartz,10,minecraft:quartz_block,100)
RB(2,11,-1,minecraft:chiseled_quartz_block,10,minecraft:quartz_pillar,10,minecraft:smooth_quartz,10,minecraft:quartz_block,100)
RB(2,12,-1,minecraft:chiseled_quartz_block,10,minecraft:quartz_pillar,10,minecraft:smooth_quartz,10,minecraft:quartz_block,100)
RB(2,8,0,minecraft:chiseled_quartz_block,10,minecraft:quartz_pillar,10,minecraft:smooth_quartz,10,minecraft:quartz_block,100)
RB(2,9,0,minecraft:chiseled_quartz_block,10,minecraft:quartz_pillar,10,minecraft:smooth_quartz,10,minecraft:quartz_block,100)
RB(2,10,0,minecraft:chiseled_quartz_block,10,minecraft:quartz_pillar,10,minecraft:smooth_quartz,10,minecraft:quartz_block,100)
RB(2,11,0,minecraft:chiseled_quartz_block,10,minecraft:quartz_pillar,10,minecraft:smooth_quartz,10,minecraft:quartz_block,100)
RB(2,12,0,minecraft:chiseled_quartz_block,10,minecraft:quartz_pillar,10,minecraft:smooth_quartz,10,minecraft:quartz_block,100)
RB(2,8,1,minecraft:chiseled_quartz_block,10,minecraft:quartz_pillar,10,minecraft:smooth_quartz,10,minecraft:quartz_block,100)
RB(2,9,1,minecraft:chiseled_quartz_block,10,minecraft:quartz_pillar,10,minecraft:smooth_quartz,10,minecraft:quartz_block,100)
RB(2,10,1,minecraft:chiseled_quartz_block,10,minecraft:quartz_pillar,10,minecraft:smooth_quartz,10,minecraft:quartz_block,100)
RB(2,11,1,minecraft:chiseled_quartz_block,10,minecraft:quartz_pillar,10,minecraft:smooth_quartz,10,minecraft:quartz_block,100)
RB(2,12,1,minecraft:chiseled_quartz_block,10,minecraft:quartz_pillar,10,minecraft:smooth_quartz,10,minecraft:quartz_block,100)
RB(2,9,2,minecraft:chiseled_quartz_block,10,minecraft:quartz_pillar,10,minecraft:smooth_quartz,10,minecraft:quartz_block,100)
RB(2,10,2,minecraft:chiseled_quartz_block,10,minecraft:quartz_pillar,10,minecraft:smooth_quartz,10,minecraft:quartz_block,100)
RB(2,11,2,minecraft:chiseled_quartz_block,10,minecraft:quartz_pillar,10,minecraft:smooth_quartz,10,minecraft:quartz_block,100)
RB(2,12,2,minecraft:chiseled_quartz_block,10,minecraft:quartz_pillar,10,minecraft:smooth_quartz,10,minecraft:quartz_block,100)
RB(2,9,3,minecraft:chiseled_quartz_block,10,minecraft:quartz_pillar,10,minecraft:smooth_quartz,10,minecraft:quartz_block,100)
RB(2,10,3,minecraft:chiseled_quartz_block,10,minecraft:quartz_pillar,10,minecraft:smooth_quartz,10,minecraft:quartz_block,100)
RB(2,11,3,minecraft:chiseled_quartz_block,10,minecraft:quartz_pillar,10,minecraft:smooth_quartz,10,minecraft:quartz_block,100)
RB(2,12,3,minecraft:chiseled_quartz_block,10,minecraft:quartz_pillar,10,minecraft:smooth_quartz,10,minecraft:quartz_block,100)
RB(2,10,4,minecraft:chiseled_quartz_block,10,minecraft:quartz_pillar,10,minecraft:smooth_quartz,10,minecraft:quartz_block,100)
RB(2,11,4,minecraft:chiseled_quartz_block,10,minecraft:quartz_pillar,10,minecraft:smooth_quartz,10,minecraft:quartz_block,100)
RB(2,12,4,minecraft:chiseled_quartz_block,10,minecraft:quartz_pillar,10,minecraft:smooth_quartz,10,minecraft:quartz_block,100)
RB(2,10,5,minecraft:chiseled_quartz_block,10,minecraft:quartz_pillar,10,minecraft:smooth_quartz,10,minecraft:quartz_block,100)
RB(2,11,5,minecraft:chiseled_quartz_block,10,minecraft:quartz_pillar,10,minecraft:smooth_quartz,10,minecraft:quartz_block,100)
RB(2,12,5,minecraft:chiseled_quartz_block,10,minecraft:quartz_pillar,10,minecraft:smooth_quartz,10,minecraft:quartz_block,100)
RB(2,11,6,minecraft:chiseled_quartz_block,10,minecraft:quartz_pillar,10,minecraft:smooth_quartz,10,minecraft:quartz_block,100)
RB(2,12,6,minecraft:chiseled_quartz_block,10,minecraft:quartz_pillar,10,minecraft:smooth_quartz,10,minecraft:quartz_block,100)
RB(2,11,7,minecraft:chiseled_quartz_block,10,minecraft:quartz_pillar,10,minecraft:smooth_quartz,10,minecraft:quartz_block,100)
RB(2,12,7,minecraft:chiseled_quartz_block,10,minecraft:quartz_pillar,10,minecraft:smooth_quartz,10,minecraft:quartz_block,100)
RB(2,12,8,minecraft:chiseled_quartz_block,10,minecraft:quartz_pillar,10,minecraft:smooth_quartz,10,minecraft:quartz_block,100)
RB(2,12,9,minecraft:chiseled_quartz_block,10,minecraft:quartz_pillar,10,minecraft:smooth_quartz,10,minecraft:quartz_block,100)
RB(2,12,10,minecraft:chiseled_quartz_block,10,minecraft:quartz_pillar,10,minecraft:smooth_quartz,10,minecraft:quartz_block,100)
RB(3,5,-8,minecraft:chiseled_quartz_block,10,minecraft:quartz_pillar,10,minecraft:smooth_quartz,10,minecraft:quartz_block,100)
RB(3,6,-8,minecraft:chiseled_quartz_block,10,minecraft:quartz_pillar,10,minecraft:smooth_quartz,10,minecraft:quartz_block,100)
RB(3,7,-8,minecraft:chiseled_quartz_block,10,minecraft:quartz_pillar,10,minecraft:smooth_quartz,10,minecraft:quartz_block,100)
RB(3,8,-8,minecraft:chiseled_quartz_block,10,minecraft:quartz_pillar,10,minecraft:smooth_quartz,10,minecraft:quartz_block,100)
RB(3,5,-7,minecraft:chiseled_quartz_block,10,minecraft:quartz_pillar,10,minecraft:smooth_quartz,10,minecraft:quartz_block,100)
RB(3,6,-7,minecraft:chiseled_quartz_block,10,minecraft:quartz_pillar,10,minecraft:smooth_quartz,10,minecraft:quartz_block,100)
RB(3,7,-7,minecraft:chiseled_quartz_block,10,minecraft:quartz_pillar,10,minecraft:smooth_quartz,10,minecraft:quartz_block,100)
RB(3,8,-7,minecraft:chiseled_quartz_block,10,minecraft:quartz_pillar,10,minecraft:smooth_quartz,10,minecraft:quartz_block,100)
RB(3,9,-7,minecraft:chiseled_quartz_block,10,minecraft:quartz_pillar,10,minecraft:smooth_quartz,10,minecraft:quartz_block,100)
RB(3,10,-7,minecraft:chiseled_quartz_block,10,minecraft:quartz_pillar,10,minecraft:smooth_quartz,10,minecraft:quartz_block,100)
RB(3,11,-7,minecraft:chiseled_quartz_block,10,minecraft:quartz_pillar,10,minecraft:smooth_quartz,10,minecraft:quartz_block,100)
RB(3,5,-6,minecraft:chiseled_quartz_block,10,minecraft:quartz_pillar,10,minecraft:smooth_quartz,10,minecraft:quartz_block,100)
RB(3,6,-6,minecraft:chiseled_quartz_block,10,minecraft:quartz_pillar,10,minecraft:smooth_quartz,10,minecraft:quartz_block,100)
RB(3,7,-6,minecraft:chiseled_quartz_block,10,minecraft:quartz_pillar,10,minecraft:smooth_quartz,10,minecraft:quartz_block,100)
RB(3,8,-6,minecraft:chiseled_quartz_block,10,minecraft:quartz_pillar,10,minecraft:smooth_quartz,10,minecraft:quartz_block,100)
RB(3,9,-6,minecraft:chiseled_quartz_block,10,minecraft:quartz_pillar,10,minecraft:smooth_quartz,10,minecraft:quartz_block,100)
RB(3,10,-6,minecraft:chiseled_quartz_block,10,minecraft:quartz_pillar,10,minecraft:smooth_quartz,10,minecraft:quartz_block,100)
RB(3,11,-6,minecraft:chiseled_quartz_block,10,minecraft:quartz_pillar,10,minecraft:smooth_quartz,10,minecraft:quartz_block,100)
RB(3,12,-6,minecraft:chiseled_quartz_block,10,minecraft:quartz_pillar,10,minecraft:smooth_quartz,10,minecraft:quartz_block,100)
RB(3,5,-5,minecraft:chiseled_quartz_block,10,minecraft:quartz_pillar,10,minecraft:smooth_quartz,10,minecraft:quartz_block,100)
RB(3,6,-5,minecraft:chiseled_quartz_block,10,minecraft:quartz_pillar,10,minecraft:smooth_quartz,10,minecraft:quartz_block,100)
RB(3,7,-5,minecraft:chiseled_quartz_block,10,minecraft:quartz_pillar,10,minecraft:smooth_quartz,10,minecraft:quartz_block,100)
RB(3,8,-5,minecraft:chiseled_quartz_block,10,minecraft:quartz_pillar,10,minecraft:smooth_quartz,10,minecraft:quartz_block,100)
RB(3,9,-5,minecraft:chiseled_quartz_block,10,minecraft:quartz_pillar,10,minecraft:smooth_quartz,10,minecraft:quartz_block,100)
RB(3,10,-5,minecraft:chiseled_quartz_block,10,minecraft:quartz_pillar,10,minecraft:smooth_quartz,10,minecraft:quartz_block,100)
RB(3,11,-5,minecraft:chiseled_quartz_block,10,minecraft:quartz_pillar,10,minecraft:smooth_quartz,10,minecraft:quartz_block,100)
RB(3,12,-5,minecraft:chiseled_quartz_block,10,minecraft:quartz_pillar,10,minecraft:smooth_quartz,10,minecraft:quartz_block,100)
RB(3,6,-4,minecraft:chiseled_quartz_block,10,minecraft:quartz_pillar,10,minecraft:smooth_quartz,10,minecraft:quartz_block,100)
RB(3,7,-4,minecraft:chiseled_quartz_block,10,minecraft:quartz_pillar,10,minecraft:smooth_quartz,10,minecraft:quartz_block,100)
RB(3,8,-4,minecraft:chiseled_quartz_block,10,minecraft:quartz_pillar,10,minecraft:smooth_quartz,10,minecraft:quartz_block,100)
RB(3,9,-4,minecraft:chiseled_quartz_block,10,minecraft:quartz_pillar,10,minecraft:smooth_quartz,10,minecraft:quartz_block,100)
RB(3,10,-4,minecraft:chiseled_quartz_block,10,minecraft:quartz_pillar,10,minecraft:smooth_quartz,10,minecraft:quartz_block,100)
RB(3,11,-4,minecraft:chiseled_quartz_block,10,minecraft:quartz_pillar,10,minecraft:smooth_quartz,10,minecraft:quartz_block,100)
RB(3,12,-4,minecraft:chiseled_quartz_block,10,minecraft:quartz_pillar,10,minecraft:smooth_quartz,10,minecraft:quartz_block,100)
RB(3,6,-3,minecraft:chiseled_quartz_block,10,minecraft:quartz_pillar,10,minecraft:smooth_quartz,10,minecraft:quartz_block,100)
RB(3,7,-3,minecraft:chiseled_quartz_block,10,minecraft:quartz_pillar,10,minecraft:smooth_quartz,10,minecraft:quartz_block,100)
RB(3,8,-3,minecraft:chiseled_quartz_block,10,minecraft:quartz_pillar,10,minecraft:smooth_quartz,10,minecraft:quartz_block,100)
RB(3,9,-3,minecraft:chiseled_quartz_block,10,minecraft:quartz_pillar,10,minecraft:smooth_quartz,10,minecraft:quartz_block,100)
RB(3,10,-3,minecraft:chiseled_quartz_block,10,minecraft:quartz_pillar,10,minecraft:smooth_quartz,10,minecraft:quartz_block,100)
RB(3,11,-3,minecraft:chiseled_quartz_block,10,minecraft:quartz_pillar,10,minecraft:smooth_quartz,10,minecraft:quartz_block,100)
RB(3,12,-3,minecraft:chiseled_quartz_block,10,minecraft:quartz_pillar,10,minecraft:smooth_quartz,10,minecraft:quartz_block,100)
RB(3,7,-2,minecraft:chiseled_quartz_block,10,minecraft:quartz_pillar,10,minecraft:smooth_quartz,10,minecraft:quartz_block,100)
RB(3,8,-2,minecraft:chiseled_quartz_block,10,minecraft:quartz_pillar,10,minecraft:smooth_quartz,10,minecraft:quartz_block,100)
RB(3,9,-2,minecraft:chiseled_quartz_block,10,minecraft:quartz_pillar,10,minecraft:smooth_quartz,10,minecraft:quartz_block,100)
RB(3,10,-2,minecraft:chiseled_quartz_block,10,minecraft:quartz_pillar,10,minecraft:smooth_quartz,10,minecraft:quartz_block,100)
RB(3,11,-2,minecraft:chiseled_quartz_block,10,minecraft:quartz_pillar,10,minecraft:smooth_quartz,10,minecraft:quartz_block,100)
RB(3,12,-2,minecraft:chiseled_quartz_block,10,minecraft:quartz_pillar,10,minecraft:smooth_quartz,10,minecraft:quartz_block,100)
RB(3,7,-1,minecraft:chiseled_quartz_block,10,minecraft:quartz_pillar,10,minecraft:smooth_quartz,10,minecraft:quartz_block,100)
RB(3,8,-1,minecraft:chiseled_quartz_block,10,minecraft:quartz_pillar,10,minecraft:smooth_quartz,10,minecraft:quartz_block,100)
RB(3,9,-1,minecraft:chiseled_quartz_block,10,minecraft:quartz_pillar,10,minecraft:smooth_quartz,10,minecraft:quartz_block,100)
RB(3,10,-1,minecraft:chiseled_quartz_block,10,minecraft:quartz_pillar,10,minecraft:smooth_quartz,10,minecraft:quartz_block,100)
RB(3,11,-1,minecraft:chiseled_quartz_block,10,minecraft:quartz_pillar,10,minecraft:smooth_quartz,10,minecraft:quartz_block,100)
RB(3,12,-1,minecraft:chiseled_quartz_block,10,minecraft:quartz_pillar,10,minecraft:smooth_quartz,10,minecraft:quartz_block,100)
RB(3,7,0,minecraft:chiseled_quartz_block,10,minecraft:quartz_pillar,10,minecraft:smooth_quartz,10,minecraft:quartz_block,100)
RB(3,8,0,minecraft:chiseled_quartz_block,10,minecraft:quartz_pillar,10,minecraft:smooth_quartz,10,minecraft:quartz_block,100)
RB(3,9,0,minecraft:chiseled_quartz_block,10,minecraft:quartz_pillar,10,minecraft:smooth_quartz,10,minecraft:quartz_block,100)
RB(3,10,0,minecraft:chiseled_quartz_block,10,minecraft:quartz_pillar,10,minecraft:smooth_quartz,10,minecraft:quartz_block,100)
RB(3,11,0,minecraft:chiseled_quartz_block,10,minecraft:quartz_pillar,10,minecraft:smooth_quartz,10,minecraft:quartz_block,100)
RB(3,12,0,minecraft:chiseled_quartz_block,10,minecraft:quartz_pillar,10,minecraft:smooth_quartz,10,minecraft:quartz_block,100)
RB(3,8,1,minecraft:chiseled_quartz_block,10,minecraft:quartz_pillar,10,minecraft:smooth_quartz,10,minecraft:quartz_block,100)
RB(3,9,1,minecraft:chiseled_quartz_block,10,minecraft:quartz_pillar,10,minecraft:smooth_quartz,10,minecraft:quartz_block,100)
RB(3,10,1,minecraft:chiseled_quartz_block,10,minecraft:quartz_pillar,10,minecraft:smooth_quartz,10,minecraft:quartz_block,100)
RB(3,11,1,minecraft:chiseled_quartz_block,10,minecraft:quartz_pillar,10,minecraft:smooth_quartz,10,minecraft:quartz_block,100)
RB(3,12,1,minecraft:chiseled_quartz_block,10,minecraft:quartz_pillar,10,minecraft:smooth_quartz,10,minecraft:quartz_block,100)
RB(3,8,2,minecraft:chiseled_quartz_block,10,minecraft:quartz_pillar,10,minecraft:smooth_quartz,10,minecraft:quartz_block,100)
RB(3,9,2,minecraft:chiseled_quartz_block,10,minecraft:quartz_pillar,10,minecraft:smooth_quartz,10,minecraft:quartz_block,100)
RB(3,10,2,minecraft:chiseled_quartz_block,10,minecraft:quartz_pillar,10,minecraft:smooth_quartz,10,minecraft:quartz_block,100)
RB(3,11,2,minecraft:chiseled_quartz_block,10,minecraft:quartz_pillar,10,minecraft:smooth_quartz,10,minecraft:quartz_block,100)
RB(3,12,2,minecraft:chiseled_quartz_block,10,minecraft:quartz_pillar,10,minecraft:smooth_quartz,10,minecraft:quartz_block,100)
RB(3,9,3,minecraft:chiseled_quartz_block,10,minecraft:quartz_pillar,10,minecraft:smooth_quartz,10,minecraft:quartz_block,100)
RB(3,10,3,minecraft:chiseled_quartz_block,10,minecraft:quartz_pillar,10,minecraft:smooth_quartz,10,minecraft:quartz_block,100)
RB(3,11,3,minecraft:chiseled_quartz_block,10,minecraft:quartz_pillar,10,minecraft:smooth_quartz,10,minecraft:quartz_block,100)
RB(3,12,3,minecraft:chiseled_quartz_block,10,minecraft:quartz_pillar,10,minecraft:smooth_quartz,10,minecraft:quartz_block,100)
RB(3,9,4,minecraft:chiseled_quartz_block,10,minecraft:quartz_pillar,10,minecraft:smooth_quartz,10,minecraft:quartz_block,100)
RB(3,10,4,minecraft:chiseled_quartz_block,10,minecraft:quartz_pillar,10,minecraft:smooth_quartz,10,minecraft:quartz_block,100)
RB(3,11,4,minecraft:chiseled_quartz_block,10,minecraft:quartz_pillar,10,minecraft:smooth_quartz,10,minecraft:quartz_block,100)
RB(3,12,4,minecraft:chiseled_quartz_block,10,minecraft:quartz_pillar,10,minecraft:smooth_quartz,10,minecraft:quartz_block,100)
RB(3,10,5,minecraft:chiseled_quartz_block,10,minecraft:quartz_pillar,10,minecraft:smooth_quartz,10,minecraft:quartz_block,100)
RB(3,11,5,minecraft:chiseled_quartz_block,10,minecraft:quartz_pillar,10,minecraft:smooth_quartz,10,minecraft:quartz_block,100)
RB(3,12,5,minecraft:chiseled_quartz_block,10,minecraft:quartz_pillar,10,minecraft:smooth_quartz,10,minecraft:quartz_block,100)
RB(3,10,6,minecraft:chiseled_quartz_block,10,minecraft:quartz_pillar,10,minecraft:smooth_quartz,10,minecraft:quartz_block,100)
RB(3,11,6,minecraft:chiseled_quartz_block,10,minecraft:quartz_pillar,10,minecraft:smooth_quartz,10,minecraft:quartz_block,100)
RB(3,12,6,minecraft:chiseled_quartz_block,10,minecraft:quartz_pillar,10,minecraft:smooth_quartz,10,minecraft:quartz_block,100)
RB(3,11,7,minecraft:chiseled_quartz_block,10,minecraft:quartz_pillar,10,minecraft:smooth_quartz,10,minecraft:quartz_block,100)
RB(3,12,7,minecraft:chiseled_quartz_block,10,minecraft:quartz_pillar,10,minecraft:smooth_quartz,10,minecraft:quartz_block,100)
RB(3,12,8,minecraft:chiseled_quartz_block,10,minecraft:quartz_pillar,10,minecraft:smooth_quartz,10,minecraft:quartz_block,100)
RB(3,12,9,minecraft:chiseled_quartz_block,10,minecraft:quartz_pillar,10,minecraft:smooth_quartz,10,minecraft:quartz_block,100)
RB(4,4,-9,minecraft:chiseled_quartz_block,10,minecraft:quartz_pillar,10,minecraft:smooth_quartz,10,minecraft:quartz_block,100)
RB(4,5,-9,minecraft:chiseled_quartz_block,10,minecraft:quartz_pillar,10,minecraft:smooth_quartz,10,minecraft:quartz_block,100)
RB(4,4,-8,minecraft:chiseled_quartz_block,10,minecraft:quartz_pillar,10,minecraft:smooth_quartz,10,minecraft:quartz_block,100)
RB(4,5,-8,minecraft:chiseled_quartz_block,10,minecraft:quartz_pillar,10,minecraft:smooth_quartz,10,minecraft:quartz_block,100)
RB(4,6,-8,minecraft:chiseled_quartz_block,10,minecraft:quartz_pillar,10,minecraft:smooth_quartz,10,minecraft:quartz_block,100)
RB(4,7,-8,minecraft:chiseled_quartz_block,10,minecraft:quartz_pillar,10,minecraft:smooth_quartz,10,minecraft:quartz_block,100)
RB(4,8,-8,minecraft:chiseled_quartz_block,10,minecraft:quartz_pillar,10,minecraft:smooth_quartz,10,minecraft:quartz_block,100)
RB(4,4,-7,minecraft:chiseled_quartz_block,10,minecraft:quartz_pillar,10,minecraft:smooth_quartz,10,minecraft:quartz_block,100)
RB(4,5,-7,minecraft:chiseled_quartz_block,10,minecraft:quartz_pillar,10,minecraft:smooth_quartz,10,minecraft:quartz_block,100)
RB(4,6,-7,minecraft:chiseled_quartz_block,10,minecraft:quartz_pillar,10,minecraft:smooth_quartz,10,minecraft:quartz_block,100)
RB(4,7,-7,minecraft:chiseled_quartz_block,10,minecraft:quartz_pillar,10,minecraft:smooth_quartz,10,minecraft:quartz_block,100)
RB(4,8,-7,minecraft:chiseled_quartz_block,10,minecraft:quartz_pillar,10,minecraft:smooth_quartz,10,minecraft:quartz_block,100)
RB(4,9,-7,minecraft:chiseled_quartz_block,10,minecraft:quartz_pillar,10,minecraft:smooth_quartz,10,minecraft:quartz_block,100)
RB(4,10,-7,minecraft:chiseled_quartz_block,10,minecraft:quartz_pillar,10,minecraft:smooth_quartz,10,minecraft:quartz_block,100)
RB(4,11,-7,minecraft:chiseled_quartz_block,10,minecraft:quartz_pillar,10,minecraft:smooth_quartz,10,minecraft:quartz_block,100)
RB(4,12,-7,minecraft:chiseled_quartz_block,10,minecraft:quartz_pillar,10,minecraft:smooth_quartz,10,minecraft:quartz_block,100)
RB(4,4,-6,minecraft:chiseled_quartz_block,10,minecraft:quartz_pillar,10,minecraft:smooth_quartz,10,minecraft:quartz_block,100)
RB(4,5,-6,minecraft:chiseled_quartz_block,10,minecraft:quartz_pillar,10,minecraft:smooth_quartz,10,minecraft:quartz_block,100)
RB(4,6,-6,minecraft:chiseled_quartz_block,10,minecraft:quartz_pillar,10,minecraft:smooth_quartz,10,minecraft:quartz_block,100)
RB(4,7,-6,minecraft:chiseled_quartz_block,10,minecraft:quartz_pillar,10,minecraft:smooth_quartz,10,minecraft:quartz_block,100)
RB(4,8,-6,minecraft:chiseled_quartz_block,10,minecraft:quartz_pillar,10,minecraft:smooth_quartz,10,minecraft:quartz_block,100)
RB(4,9,-6,minecraft:chiseled_quartz_block,10,minecraft:quartz_pillar,10,minecraft:smooth_quartz,10,minecraft:quartz_block,100)
RB(4,10,-6,minecraft:chiseled_quartz_block,10,minecraft:quartz_pillar,10,minecraft:smooth_quartz,10,minecraft:quartz_block,100)
RB(4,11,-6,minecraft:chiseled_quartz_block,10,minecraft:quartz_pillar,10,minecraft:smooth_quartz,10,minecraft:quartz_block,100)
RB(4,12,-6,minecraft:chiseled_quartz_block,10,minecraft:quartz_pillar,10,minecraft:smooth_quartz,10,minecraft:quartz_block,100)
RB(4,5,-5,minecraft:chiseled_quartz_block,10,minecraft:quartz_pillar,10,minecraft:smooth_quartz,10,minecraft:quartz_block,100)
RB(4,6,-5,minecraft:chiseled_quartz_block,10,minecraft:quartz_pillar,10,minecraft:smooth_quartz,10,minecraft:quartz_block,100)
RB(4,7,-5,minecraft:chiseled_quartz_block,10,minecraft:quartz_pillar,10,minecraft:smooth_quartz,10,minecraft:quartz_block,100)
RB(4,8,-5,minecraft:chiseled_quartz_block,10,minecraft:quartz_pillar,10,minecraft:smooth_quartz,10,minecraft:quartz_block,100)
RB(4,9,-5,minecraft:chiseled_quartz_block,10,minecraft:quartz_pillar,10,minecraft:smooth_quartz,10,minecraft:quartz_block,100)
RB(4,10,-5,minecraft:chiseled_quartz_block,10,minecraft:quartz_pillar,10,minecraft:smooth_quartz,10,minecraft:quartz_block,100)
RB(4,11,-5,minecraft:chiseled_quartz_block,10,minecraft:quartz_pillar,10,minecraft:smooth_quartz,10,minecraft:quartz_block,100)
RB(4,12,-5,minecraft:chiseled_quartz_block,10,minecraft:quartz_pillar,10,minecraft:smooth_quartz,10,minecraft:quartz_block,100)
RB(4,5,-4,minecraft:chiseled_quartz_block,10,minecraft:quartz_pillar,10,minecraft:smooth_quartz,10,minecraft:quartz_block,100)
RB(4,6,-4,minecraft:chiseled_quartz_block,10,minecraft:quartz_pillar,10,minecraft:smooth_quartz,10,minecraft:quartz_block,100)
RB(4,7,-4,minecraft:chiseled_quartz_block,10,minecraft:quartz_pillar,10,minecraft:smooth_quartz,10,minecraft:quartz_block,100)
RB(4,8,-4,minecraft:chiseled_quartz_block,10,minecraft:quartz_pillar,10,minecraft:smooth_quartz,10,minecraft:quartz_block,100)
RB(4,9,-4,minecraft:chiseled_quartz_block,10,minecraft:quartz_pillar,10,minecraft:smooth_quartz,10,minecraft:quartz_block,100)
RB(4,10,-4,minecraft:chiseled_quartz_block,10,minecraft:quartz_pillar,10,minecraft:smooth_quartz,10,minecraft:quartz_block,100)
RB(4,11,-4,minecraft:chiseled_quartz_block,10,minecraft:quartz_pillar,10,minecraft:smooth_quartz,10,minecraft:quartz_block,100)
RB(4,12,-4,minecraft:chiseled_quartz_block,10,minecraft:quartz_pillar,10,minecraft:smooth_quartz,10,minecraft:quartz_block,100)
RB(4,6,-3,minecraft:chiseled_quartz_block,10,minecraft:quartz_pillar,10,minecraft:smooth_quartz,10,minecraft:quartz_block,100)
RB(4,7,-3,minecraft:chiseled_quartz_block,10,minecraft:quartz_pillar,10,minecraft:smooth_quartz,10,minecraft:quartz_block,100)
RB(4,8,-3,minecraft:chiseled_quartz_block,10,minecraft:quartz_pillar,10,minecraft:smooth_quartz,10,minecraft:quartz_block,100)
RB(4,9,-3,minecraft:chiseled_quartz_block,10,minecraft:quartz_pillar,10,minecraft:smooth_quartz,10,minecraft:quartz_block,100)
RB(4,10,-3,minecraft:chiseled_quartz_block,10,minecraft:quartz_pillar,10,minecraft:smooth_quartz,10,minecraft:quartz_block,100)
RB(4,11,-3,minecraft:chiseled_quartz_block,10,minecraft:quartz_pillar,10,minecraft:smooth_quartz,10,minecraft:quartz_block,100)
RB(4,12,-3,minecraft:chiseled_quartz_block,10,minecraft:quartz_pillar,10,minecraft:smooth_quartz,10,minecraft:quartz_block,100)
RB(4,6,-2,minecraft:chiseled_quartz_block,10,minecraft:quartz_pillar,10,minecraft:smooth_quartz,10,minecraft:quartz_block,100)
RB(4,7,-2,minecraft:chiseled_quartz_block,10,minecraft:quartz_pillar,10,minecraft:smooth_quartz,10,minecraft:quartz_block,100)
RB(4,8,-2,minecraft:chiseled_quartz_block,10,minecraft:quartz_pillar,10,minecraft:smooth_quartz,10,minecraft:quartz_block,100)
RB(4,9,-2,minecraft:chiseled_quartz_block,10,minecraft:quartz_pillar,10,minecraft:smooth_quartz,10,minecraft:quartz_block,100)
RB(4,10,-2,minecraft:chiseled_quartz_block,10,minecraft:quartz_pillar,10,minecraft:smooth_quartz,10,minecraft:quartz_block,100)
RB(4,11,-2,minecraft:chiseled_quartz_block,10,minecraft:quartz_pillar,10,minecraft:smooth_quartz,10,minecraft:quartz_block,100)
RB(4,12,-2,minecraft:chiseled_quartz_block,10,minecraft:quartz_pillar,10,minecraft:smooth_quartz,10,minecraft:quartz_block,100)
RB(4,7,-1,minecraft:chiseled_quartz_block,10,minecraft:quartz_pillar,10,minecraft:smooth_quartz,10,minecraft:quartz_block,100)
RB(4,8,-1,minecraft:chiseled_quartz_block,10,minecraft:quartz_pillar,10,minecraft:smooth_quartz,10,minecraft:quartz_block,100)
RB(4,9,-1,minecraft:chiseled_quartz_block,10,minecraft:quartz_pillar,10,minecraft:smooth_quartz,10,minecraft:quartz_block,100)
RB(4,10,-1,minecraft:chiseled_quartz_block,10,minecraft:quartz_pillar,10,minecraft:smooth_quartz,10,minecraft:quartz_block,100)
RB(4,11,-1,minecraft:chiseled_quartz_block,10,minecraft:quartz_pillar,10,minecraft:smooth_quartz,10,minecraft:quartz_block,100)
RB(4,12,-1,minecraft:chiseled_quartz_block,10,minecraft:quartz_pillar,10,minecraft:smooth_quartz,10,minecraft:quartz_block,100)
RB(4,7,0,minecraft:chiseled_quartz_block,10,minecraft:quartz_pillar,10,minecraft:smooth_quartz,10,minecraft:quartz_block,100)
RB(4,8,0,minecraft:chiseled_quartz_block,10,minecraft:quartz_pillar,10,minecraft:smooth_quartz,10,minecraft:quartz_block,100)
RB(4,9,0,minecraft:chiseled_quartz_block,10,minecraft:quartz_pillar,10,minecraft:smooth_quartz,10,minecraft:quartz_block,100)
RB(4,10,0,minecraft:chiseled_quartz_block,10,minecraft:quartz_pillar,10,minecraft:smooth_quartz,10,minecraft:quartz_block,100)
RB(4,11,0,minecraft:chiseled_quartz_block,10,minecraft:quartz_pillar,10,minecraft:smooth_quartz,10,minecraft:quartz_block,100)
RB(4,12,0,minecraft:chiseled_quartz_block,10,minecraft:quartz_pillar,10,minecraft:smooth_quartz,10,minecraft:quartz_block,100)
RB(4,8,1,minecraft:chiseled_quartz_block,10,minecraft:quartz_pillar,10,minecraft:smooth_quartz,10,minecraft:quartz_block,100)
RB(4,9,1,minecraft:chiseled_quartz_block,10,minecraft:quartz_pillar,10,minecraft:smooth_quartz,10,minecraft:quartz_block,100)
RB(4,10,1,minecraft:chiseled_quartz_block,10,minecraft:quartz_pillar,10,minecraft:smooth_quartz,10,minecraft:quartz_block,100)
RB(4,11,1,minecraft:chiseled_quartz_block,10,minecraft:quartz_pillar,10,minecraft:smooth_quartz,10,minecraft:quartz_block,100)
RB(4,12,1,minecraft:chiseled_quartz_block,10,minecraft:quartz_pillar,10,minecraft:smooth_quartz,10,minecraft:quartz_block,100)
RB(4,8,2,minecraft:chiseled_quartz_block,10,minecraft:quartz_pillar,10,minecraft:smooth_quartz,10,minecraft:quartz_block,100)
RB(4,9,2,minecraft:chiseled_quartz_block,10,minecraft:quartz_pillar,10,minecraft:smooth_quartz,10,minecraft:quartz_block,100)
RB(4,10,2,minecraft:chiseled_quartz_block,10,minecraft:quartz_pillar,10,minecraft:smooth_quartz,10,minecraft:quartz_block,100)
RB(4,11,2,minecraft:chiseled_quartz_block,10,minecraft:quartz_pillar,10,minecraft:smooth_quartz,10,minecraft:quartz_block,100)
RB(4,12,2,minecraft:chiseled_quartz_block,10,minecraft:quartz_pillar,10,minecraft:smooth_quartz,10,minecraft:quartz_block,100)
RB(4,9,3,minecraft:chiseled_quartz_block,10,minecraft:quartz_pillar,10,minecraft:smooth_quartz,10,minecraft:quartz_block,100)
RB(4,10,3,minecraft:chiseled_quartz_block,10,minecraft:quartz_pillar,10,minecraft:smooth_quartz,10,minecraft:quartz_block,100)
RB(4,11,3,minecraft:chiseled_quartz_block,10,minecraft:quartz_pillar,10,minecraft:smooth_quartz,10,minecraft:quartz_block,100)
RB(4,12,3,minecraft:chiseled_quartz_block,10,minecraft:quartz_pillar,10,minecraft:smooth_quartz,10,minecraft:quartz_block,100)
RB(4,9,4,minecraft:chiseled_quartz_block,10,minecraft:quartz_pillar,10,minecraft:smooth_quartz,10,minecraft:quartz_block,100)
RB(4,10,4,minecraft:chiseled_quartz_block,10,minecraft:quartz_pillar,10,minecraft:smooth_quartz,10,minecraft:quartz_block,100)
RB(4,11,4,minecraft:chiseled_quartz_block,10,minecraft:quartz_pillar,10,minecraft:smooth_quartz,10,minecraft:quartz_block,100)
RB(4,12,4,minecraft:chiseled_quartz_block,10,minecraft:quartz_pillar,10,minecraft:smooth_quartz,10,minecraft:quartz_block,100)
RB(4,10,5,minecraft:chiseled_quartz_block,10,minecraft:quartz_pillar,10,minecraft:smooth_quartz,10,minecraft:quartz_block,100)
RB(4,11,5,minecraft:chiseled_quartz_block,10,minecraft:quartz_pillar,10,minecraft:smooth_quartz,10,minecraft:quartz_block,100)
RB(4,12,5,minecraft:chiseled_quartz_block,10,minecraft:quartz_pillar,10,minecraft:smooth_quartz,10,minecraft:quartz_block,100)
RB(4,11,6,minecraft:chiseled_quartz_block,10,minecraft:quartz_pillar,10,minecraft:smooth_quartz,10,minecraft:quartz_block,100)
RB(4,12,6,minecraft:chiseled_quartz_block,10,minecraft:quartz_pillar,10,minecraft:smooth_quartz,10,minecraft:quartz_block,100)
RB(4,11,7,minecraft:chiseled_quartz_block,10,minecraft:quartz_pillar,10,minecraft:smooth_quartz,10,minecraft:quartz_block,100)
RB(4,12,7,minecraft:chiseled_quartz_block,10,minecraft:quartz_pillar,10,minecraft:smooth_quartz,10,minecraft:quartz_block,100)
RB(4,12,8,minecraft:chiseled_quartz_block,10,minecraft:quartz_pillar,10,minecraft:smooth_quartz,10,minecraft:quartz_block,100)
RB(5,4,-9,minecraft:chiseled_quartz_block,10,minecraft:quartz_pillar,10,minecraft:smooth_quartz,10,minecraft:quartz_block,100)
RB(5,5,-9,minecraft:chiseled_quartz_block,10,minecraft:quartz_pillar,10,minecraft:smooth_quartz,10,minecraft:quartz_block,100)
RB(5,4,-8,minecraft:chiseled_quartz_block,10,minecraft:quartz_pillar,10,minecraft:smooth_quartz,10,minecraft:quartz_block,100)
RB(5,5,-8,minecraft:chiseled_quartz_block,10,minecraft:quartz_pillar,10,minecraft:smooth_quartz,10,minecraft:quartz_block,100)
RB(5,6,-8,minecraft:chiseled_quartz_block,10,minecraft:quartz_pillar,10,minecraft:smooth_quartz,10,minecraft:quartz_block,100)
RB(5,7,-8,minecraft:chiseled_quartz_block,10,minecraft:quartz_pillar,10,minecraft:smooth_quartz,10,minecraft:quartz_block,100)
RB(5,8,-8,minecraft:chiseled_quartz_block,10,minecraft:quartz_pillar,10,minecraft:smooth_quartz,10,minecraft:quartz_block,100)
RB(5,4,-7,minecraft:chiseled_quartz_block,10,minecraft:quartz_pillar,10,minecraft:smooth_quartz,10,minecraft:quartz_block,100)
RB(5,5,-7,minecraft:chiseled_quartz_block,10,minecraft:quartz_pillar,10,minecraft:smooth_quartz,10,minecraft:quartz_block,100)
RB(5,6,-7,minecraft:chiseled_quartz_block,10,minecraft:quartz_pillar,10,minecraft:smooth_quartz,10,minecraft:quartz_block,100)
RB(5,7,-7,minecraft:chiseled_quartz_block,10,minecraft:quartz_pillar,10,minecraft:smooth_quartz,10,minecraft:quartz_block,100)
RB(5,8,-7,minecraft:chiseled_quartz_block,10,minecraft:quartz_pillar,10,minecraft:smooth_quartz,10,minecraft:quartz_block,100)
RB(5,9,-7,minecraft:chiseled_quartz_block,10,minecraft:quartz_pillar,10,minecraft:smooth_quartz,10,minecraft:quartz_block,100)
RB(5,10,-7,minecraft:chiseled_quartz_block,10,minecraft:quartz_pillar,10,minecraft:smooth_quartz,10,minecraft:quartz_block,100)
RB(5,4,-6,minecraft:chiseled_quartz_block,10,minecraft:quartz_pillar,10,minecraft:smooth_quartz,10,minecraft:quartz_block,100)
RB(5,5,-6,minecraft:chiseled_quartz_block,10,minecraft:quartz_pillar,10,minecraft:smooth_quartz,10,minecraft:quartz_block,100)
RB(5,6,-6,minecraft:chiseled_quartz_block,10,minecraft:quartz_pillar,10,minecraft:smooth_quartz,10,minecraft:quartz_block,100)
RB(5,7,-6,minecraft:chiseled_quartz_block,10,minecraft:quartz_pillar,10,minecraft:smooth_quartz,10,minecraft:quartz_block,100)
RB(5,8,-6,minecraft:chiseled_quartz_block,10,minecraft:quartz_pillar,10,minecraft:smooth_quartz,10,minecraft:quartz_block,100)
RB(5,9,-6,minecraft:chiseled_quartz_block,10,minecraft:quartz_pillar,10,minecraft:smooth_quartz,10,minecraft:quartz_block,100)
RB(5,10,-6,minecraft:chiseled_quartz_block,10,minecraft:quartz_pillar,10,minecraft:smooth_quartz,10,minecraft:quartz_block,100)
RB(5,11,-6,minecraft:chiseled_quartz_block,10,minecraft:quartz_pillar,10,minecraft:smooth_quartz,10,minecraft:quartz_block,100)
RB(5,5,-5,minecraft:chiseled_quartz_block,10,minecraft:quartz_pillar,10,minecraft:smooth_quartz,10,minecraft:quartz_block,100)
RB(5,6,-5,minecraft:chiseled_quartz_block,10,minecraft:quartz_pillar,10,minecraft:smooth_quartz,10,minecraft:quartz_block,100)
RB(5,7,-5,minecraft:chiseled_quartz_block,10,minecraft:quartz_pillar,10,minecraft:smooth_quartz,10,minecraft:quartz_block,100)
RB(5,8,-5,minecraft:chiseled_quartz_block,10,minecraft:quartz_pillar,10,minecraft:smooth_quartz,10,minecraft:quartz_block,100)
RB(5,9,-5,minecraft:chiseled_quartz_block,10,minecraft:quartz_pillar,10,minecraft:smooth_quartz,10,minecraft:quartz_block,100)
RB(5,10,-5,minecraft:chiseled_quartz_block,10,minecraft:quartz_pillar,10,minecraft:smooth_quartz,10,minecraft:quartz_block,100)
RB(5,11,-5,minecraft:chiseled_quartz_block,10,minecraft:quartz_pillar,10,minecraft:smooth_quartz,10,minecraft:quartz_block,100)
RB(5,12,-5,minecraft:chiseled_quartz_block,10,minecraft:quartz_pillar,10,minecraft:smooth_quartz,10,minecraft:quartz_block,100)
RB(5,5,-4,minecraft:chiseled_quartz_block,10,minecraft:quartz_pillar,10,minecraft:smooth_quartz,10,minecraft:quartz_block,100)
RB(5,6,-4,minecraft:chiseled_quartz_block,10,minecraft:quartz_pillar,10,minecraft:smooth_quartz,10,minecraft:quartz_block,100)
RB(5,7,-4,minecraft:chiseled_quartz_block,10,minecraft:quartz_pillar,10,minecraft:smooth_quartz,10,minecraft:quartz_block,100)
RB(5,8,-4,minecraft:chiseled_quartz_block,10,minecraft:quartz_pillar,10,minecraft:smooth_quartz,10,minecraft:quartz_block,100)
RB(5,9,-4,minecraft:chiseled_quartz_block,10,minecraft:quartz_pillar,10,minecraft:smooth_quartz,10,minecraft:quartz_block,100)
RB(5,10,-4,minecraft:chiseled_quartz_block,10,minecraft:quartz_pillar,10,minecraft:smooth_quartz,10,minecraft:quartz_block,100)
RB(5,11,-4,minecraft:chiseled_quartz_block,10,minecraft:quartz_pillar,10,minecraft:smooth_quartz,10,minecraft:quartz_block,100)
RB(5,12,-4,minecraft:chiseled_quartz_block,10,minecraft:quartz_pillar,10,minecraft:smooth_quartz,10,minecraft:quartz_block,100)
RB(5,5,-3,minecraft:chiseled_quartz_block,10,minecraft:quartz_pillar,10,minecraft:smooth_quartz,10,minecraft:quartz_block,100)
RB(5,6,-3,minecraft:chiseled_quartz_block,10,minecraft:quartz_pillar,10,minecraft:smooth_quartz,10,minecraft:quartz_block,100)
RB(5,7,-3,minecraft:chiseled_quartz_block,10,minecraft:quartz_pillar,10,minecraft:smooth_quartz,10,minecraft:quartz_block,100)
RB(5,8,-3,minecraft:chiseled_quartz_block,10,minecraft:quartz_pillar,10,minecraft:smooth_quartz,10,minecraft:quartz_block,100)
RB(5,9,-3,minecraft:chiseled_quartz_block,10,minecraft:quartz_pillar,10,minecraft:smooth_quartz,10,minecraft:quartz_block,100)
RB(5,10,-3,minecraft:chiseled_quartz_block,10,minecraft:quartz_pillar,10,minecraft:smooth_quartz,10,minecraft:quartz_block,100)
RB(5,11,-3,minecraft:chiseled_quartz_block,10,minecraft:quartz_pillar,10,minecraft:smooth_quartz,10,minecraft:quartz_block,100)
RB(5,12,-3,minecraft:chiseled_quartz_block,10,minecraft:quartz_pillar,10,minecraft:smooth_quartz,10,minecraft:quartz_block,100)
RB(5,6,-2,minecraft:chiseled_quartz_block,10,minecraft:quartz_pillar,10,minecraft:smooth_quartz,10,minecraft:quartz_block,100)
RB(5,7,-2,minecraft:chiseled_quartz_block,10,minecraft:quartz_pillar,10,minecraft:smooth_quartz,10,minecraft:quartz_block,100)
RB(5,8,-2,minecraft:chiseled_quartz_block,10,minecraft:quartz_pillar,10,minecraft:smooth_quartz,10,minecraft:quartz_block,100)
RB(5,9,-2,minecraft:chiseled_quartz_block,10,minecraft:quartz_pillar,10,minecraft:smooth_quartz,10,minecraft:quartz_block,100)
RB(5,10,-2,minecraft:chiseled_quartz_block,10,minecraft:quartz_pillar,10,minecraft:smooth_quartz,10,minecraft:quartz_block,100)
RB(5,11,-2,minecraft:chiseled_quartz_block,10,minecraft:quartz_pillar,10,minecraft:smooth_quartz,10,minecraft:quartz_block,100)
RB(5,12,-2,minecraft:chiseled_quartz_block,10,minecraft:quartz_pillar,10,minecraft:smooth_quartz,10,minecraft:quartz_block,100)
RB(5,6,-1,minecraft:chiseled_quartz_block,10,minecraft:quartz_pillar,10,minecraft:smooth_quartz,10,minecraft:quartz_block,100)
RB(5,7,-1,minecraft:chiseled_quartz_block,10,minecraft:quartz_pillar,10,minecraft:smooth_quartz,10,minecraft:quartz_block,100)
RB(5,8,-1,minecraft:chiseled_quartz_block,10,minecraft:quartz_pillar,10,minecraft:smooth_quartz,10,minecraft:quartz_block,100)
RB(5,9,-1,minecraft:chiseled_quartz_block,10,minecraft:quartz_pillar,10,minecraft:smooth_quartz,10,minecraft:quartz_block,100)
RB(5,10,-1,minecraft:chiseled_quartz_block,10,minecraft:quartz_pillar,10,minecraft:smooth_quartz,10,minecraft:quartz_block,100)
RB(5,11,-1,minecraft:chiseled_quartz_block,10,minecraft:quartz_pillar,10,minecraft:smooth_quartz,10,minecraft:quartz_block,100)
RB(5,12,-1,minecraft:chiseled_quartz_block,10,minecraft:quartz_pillar,10,minecraft:smooth_quartz,10,minecraft:quartz_block,100)
RB(5,7,0,minecraft:chiseled_quartz_block,10,minecraft:quartz_pillar,10,minecraft:smooth_quartz,10,minecraft:quartz_block,100)
RB(5,8,0,minecraft:chiseled_quartz_block,10,minecraft:quartz_pillar,10,minecraft:smooth_quartz,10,minecraft:quartz_block,100)
RB(5,9,0,minecraft:chiseled_quartz_block,10,minecraft:quartz_pillar,10,minecraft:smooth_quartz,10,minecraft:quartz_block,100)
RB(5,10,0,minecraft:chiseled_quartz_block,10,minecraft:quartz_pillar,10,minecraft:smooth_quartz,10,minecraft:quartz_block,100)
RB(5,11,0,minecraft:chiseled_quartz_block,10,minecraft:quartz_pillar,10,minecraft:smooth_quartz,10,minecraft:quartz_block,100)
RB(5,12,0,minecraft:chiseled_quartz_block,10,minecraft:quartz_pillar,10,minecraft:smooth_quartz,10,minecraft:quartz_block,100)
RB(5,7,1,minecraft:chiseled_quartz_block,10,minecraft:quartz_pillar,10,minecraft:smooth_quartz,10,minecraft:quartz_block,100)
RB(5,8,1,minecraft:chiseled_quartz_block,10,minecraft:quartz_pillar,10,minecraft:smooth_quartz,10,minecraft:quartz_block,100)
RB(5,9,1,minecraft:chiseled_quartz_block,10,minecraft:quartz_pillar,10,minecraft:smooth_quartz,10,minecraft:quartz_block,100)
RB(5,10,1,minecraft:chiseled_quartz_block,10,minecraft:quartz_pillar,10,minecraft:smooth_quartz,10,minecraft:quartz_block,100)
RB(5,11,1,minecraft:chiseled_quartz_block,10,minecraft:quartz_pillar,10,minecraft:smooth_quartz,10,minecraft:quartz_block,100)
RB(5,12,1,minecraft:chiseled_quartz_block,10,minecraft:quartz_pillar,10,minecraft:smooth_quartz,10,minecraft:quartz_block,100)
RB(5,8,2,minecraft:chiseled_quartz_block,10,minecraft:quartz_pillar,10,minecraft:smooth_quartz,10,minecraft:quartz_block,100)
RB(5,9,2,minecraft:chiseled_quartz_block,10,minecraft:quartz_pillar,10,minecraft:smooth_quartz,10,minecraft:quartz_block,100)
RB(5,10,2,minecraft:chiseled_quartz_block,10,minecraft:quartz_pillar,10,minecraft:smooth_quartz,10,minecraft:quartz_block,100)
RB(5,11,2,minecraft:chiseled_quartz_block,10,minecraft:quartz_pillar,10,minecraft:smooth_quartz,10,minecraft:quartz_block,100)
RB(5,12,2,minecraft:chiseled_quartz_block,10,minecraft:quartz_pillar,10,minecraft:smooth_quartz,10,minecraft:quartz_block,100)
RB(5,9,3,minecraft:chiseled_quartz_block,10,minecraft:quartz_pillar,10,minecraft:smooth_quartz,10,minecraft:quartz_block,100)
RB(5,10,3,minecraft:chiseled_quartz_block,10,minecraft:quartz_pillar,10,minecraft:smooth_quartz,10,minecraft:quartz_block,100)
RB(5,11,3,minecraft:chiseled_quartz_block,10,minecraft:quartz_pillar,10,minecraft:smooth_quartz,10,minecraft:quartz_block,100)
RB(5,12,3,minecraft:chiseled_quartz_block,10,minecraft:quartz_pillar,10,minecraft:smooth_quartz,10,minecraft:quartz_block,100)
RB(5,10,4,minecraft:chiseled_quartz_block,10,minecraft:quartz_pillar,10,minecraft:smooth_quartz,10,minecraft:quartz_block,100)
RB(5,11,4,minecraft:chiseled_quartz_block,10,minecraft:quartz_pillar,10,minecraft:smooth_quartz,10,minecraft:quartz_block,100)
RB(5,12,4,minecraft:chiseled_quartz_block,10,minecraft:quartz_pillar,10,minecraft:smooth_quartz,10,minecraft:quartz_block,100)
RB(5,10,5,minecraft:chiseled_quartz_block,10,minecraft:quartz_pillar,10,minecraft:smooth_quartz,10,minecraft:quartz_block,100)
RB(5,11,5,minecraft:chiseled_quartz_block,10,minecraft:quartz_pillar,10,minecraft:smooth_quartz,10,minecraft:quartz_block,100)
RB(5,12,5,minecraft:chiseled_quartz_block,10,minecraft:quartz_pillar,10,minecraft:smooth_quartz,10,minecraft:quartz_block,100)
RB(5,11,6,minecraft:chiseled_quartz_block,10,minecraft:quartz_pillar,10,minecraft:smooth_quartz,10,minecraft:quartz_block,100)
RB(5,12,6,minecraft:chiseled_quartz_block,10,minecraft:quartz_pillar,10,minecraft:smooth_quartz,10,minecraft:quartz_block,100)
RB(5,12,7,minecraft:chiseled_quartz_block,10,minecraft:quartz_pillar,10,minecraft:smooth_quartz,10,minecraft:quartz_block,100)
RB(5,12,8,minecraft:chiseled_quartz_block,10,minecraft:quartz_pillar,10,minecraft:smooth_quartz,10,minecraft:quartz_block,100)
RB(6,3,-9,minecraft:chiseled_quartz_block,10,minecraft:quartz_pillar,10,minecraft:smooth_quartz,10,minecraft:quartz_block,100)
RB(6,4,-9,minecraft:chiseled_quartz_block,10,minecraft:quartz_pillar,10,minecraft:smooth_quartz,10,minecraft:quartz_block,100)
RB(6,5,-9,minecraft:chiseled_quartz_block,10,minecraft:quartz_pillar,10,minecraft:smooth_quartz,10,minecraft:quartz_block,100)
RB(6,3,-8,minecraft:chiseled_quartz_block,10,minecraft:quartz_pillar,10,minecraft:smooth_quartz,10,minecraft:quartz_block,100)
RB(6,4,-8,minecraft:chiseled_quartz_block,10,minecraft:quartz_pillar,10,minecraft:smooth_quartz,10,minecraft:quartz_block,100)
RB(6,5,-8,minecraft:chiseled_quartz_block,10,minecraft:quartz_pillar,10,minecraft:smooth_quartz,10,minecraft:quartz_block,100)
RB(6,6,-8,minecraft:chiseled_quartz_block,10,minecraft:quartz_pillar,10,minecraft:smooth_quartz,10,minecraft:quartz_block,100)
RB(6,7,-8,minecraft:chiseled_quartz_block,10,minecraft:quartz_pillar,10,minecraft:smooth_quartz,10,minecraft:quartz_block,100)
RB(6,3,-7,minecraft:chiseled_quartz_block,10,minecraft:quartz_pillar,10,minecraft:smooth_quartz,10,minecraft:quartz_block,100)
RB(6,4,-7,minecraft:chiseled_quartz_block,10,minecraft:quartz_pillar,10,minecraft:smooth_quartz,10,minecraft:quartz_block,100)
RB(6,5,-7,minecraft:chiseled_quartz_block,10,minecraft:quartz_pillar,10,minecraft:smooth_quartz,10,minecraft:quartz_block,100)
RB(6,6,-7,minecraft:chiseled_quartz_block,10,minecraft:quartz_pillar,10,minecraft:smooth_quartz,10,minecraft:quartz_block,100)
RB(6,7,-7,minecraft:chiseled_quartz_block,10,minecraft:quartz_pillar,10,minecraft:smooth_quartz,10,minecraft:quartz_block,100)
RB(6,8,-7,minecraft:chiseled_quartz_block,10,minecraft:quartz_pillar,10,minecraft:smooth_quartz,10,minecraft:quartz_block,100)
RB(6,9,-7,minecraft:chiseled_quartz_block,10,minecraft:quartz_pillar,10,minecraft:smooth_quartz,10,minecraft:quartz_block,100)
RB(6,4,-6,minecraft:chiseled_quartz_block,10,minecraft:quartz_pillar,10,minecraft:smooth_quartz,10,minecraft:quartz_block,100)
RB(6,5,-6,minecraft:chiseled_quartz_block,10,minecraft:quartz_pillar,10,minecraft:smooth_quartz,10,minecraft:quartz_block,100)
RB(6,6,-6,minecraft:chiseled_quartz_block,10,minecraft:quartz_pillar,10,minecraft:smooth_quartz,10,minecraft:quartz_block,100)
RB(6,7,-6,minecraft:chiseled_quartz_block,10,minecraft:quartz_pillar,10,minecraft:smooth_quartz,10,minecraft:quartz_block,100)
RB(6,8,-6,minecraft:chiseled_quartz_block,10,minecraft:quartz_pillar,10,minecraft:smooth_quartz,10,minecraft:quartz_block,100)
RB(6,9,-6,minecraft:chiseled_quartz_block,10,minecraft:quartz_pillar,10,minecraft:smooth_quartz,10,minecraft:quartz_block,100)
RB(6,10,-6,minecraft:chiseled_quartz_block,10,minecraft:quartz_pillar,10,minecraft:smooth_quartz,10,minecraft:quartz_block,100)
RB(6,4,-5,minecraft:chiseled_quartz_block,10,minecraft:quartz_pillar,10,minecraft:smooth_quartz,10,minecraft:quartz_block,100)
RB(6,5,-5,minecraft:chiseled_quartz_block,10,minecraft:quartz_pillar,10,minecraft:smooth_quartz,10,minecraft:quartz_block,100)
RB(6,6,-5,minecraft:chiseled_quartz_block,10,minecraft:quartz_pillar,10,minecraft:smooth_quartz,10,minecraft:quartz_block,100)
RB(6,7,-5,minecraft:chiseled_quartz_block,10,minecraft:quartz_pillar,10,minecraft:smooth_quartz,10,minecraft:quartz_block,100)
RB(6,8,-5,minecraft:chiseled_quartz_block,10,minecraft:quartz_pillar,10,minecraft:smooth_quartz,10,minecraft:quartz_block,100)
RB(6,9,-5,minecraft:chiseled_quartz_block,10,minecraft:quartz_pillar,10,minecraft:smooth_quartz,10,minecraft:quartz_block,100)
RB(6,10,-5,minecraft:chiseled_quartz_block,10,minecraft:quartz_pillar,10,minecraft:smooth_quartz,10,minecraft:quartz_block,100)
RB(6,11,-5,minecraft:chiseled_quartz_block,10,minecraft:quartz_pillar,10,minecraft:smooth_quartz,10,minecraft:quartz_block,100)
RB(6,5,-4,minecraft:chiseled_quartz_block,10,minecraft:quartz_pillar,10,minecraft:smooth_quartz,10,minecraft:quartz_block,100)
RB(6,6,-4,minecraft:chiseled_quartz_block,10,minecraft:quartz_pillar,10,minecraft:smooth_quartz,10,minecraft:quartz_block,100)
RB(6,7,-4,minecraft:chiseled_quartz_block,10,minecraft:quartz_pillar,10,minecraft:smooth_quartz,10,minecraft:quartz_block,100)
RB(6,8,-4,minecraft:chiseled_quartz_block,10,minecraft:quartz_pillar,10,minecraft:smooth_quartz,10,minecraft:quartz_block,100)
RB(6,9,-4,minecraft:chiseled_quartz_block,10,minecraft:quartz_pillar,10,minecraft:smooth_quartz,10,minecraft:quartz_block,100)
RB(6,10,-4,minecraft:chiseled_quartz_block,10,minecraft:quartz_pillar,10,minecraft:smooth_quartz,10,minecraft:quartz_block,100)
RB(6,11,-4,minecraft:chiseled_quartz_block,10,minecraft:quartz_pillar,10,minecraft:smooth_quartz,10,minecraft:quartz_block,100)
RB(6,12,-4,minecraft:chiseled_quartz_block,10,minecraft:quartz_pillar,10,minecraft:smooth_quartz,10,minecraft:quartz_block,100)
RB(6,5,-3,minecraft:chiseled_quartz_block,10,minecraft:quartz_pillar,10,minecraft:smooth_quartz,10,minecraft:quartz_block,100)
RB(6,6,-3,minecraft:chiseled_quartz_block,10,minecraft:quartz_pillar,10,minecraft:smooth_quartz,10,minecraft:quartz_block,100)
RB(6,7,-3,minecraft:chiseled_quartz_block,10,minecraft:quartz_pillar,10,minecraft:smooth_quartz,10,minecraft:quartz_block,100)
RB(6,8,-3,minecraft:chiseled_quartz_block,10,minecraft:quartz_pillar,10,minecraft:smooth_quartz,10,minecraft:quartz_block,100)
RB(6,9,-3,minecraft:chiseled_quartz_block,10,minecraft:quartz_pillar,10,minecraft:smooth_quartz,10,minecraft:quartz_block,100)
RB(6,10,-3,minecraft:chiseled_quartz_block,10,minecraft:quartz_pillar,10,minecraft:smooth_quartz,10,minecraft:quartz_block,100)
RB(6,11,-3,minecraft:chiseled_quartz_block,10,minecraft:quartz_pillar,10,minecraft:smooth_quartz,10,minecraft:quartz_block,100)
RB(6,12,-3,minecraft:chiseled_quartz_block,10,minecraft:quartz_pillar,10,minecraft:smooth_quartz,10,minecraft:quartz_block,100)
RB(6,6,-2,minecraft:chiseled_quartz_block,10,minecraft:quartz_pillar,10,minecraft:smooth_quartz,10,minecraft:quartz_block,100)
RB(6,7,-2,minecraft:chiseled_quartz_block,10,minecraft:quartz_pillar,10,minecraft:smooth_quartz,10,minecraft:quartz_block,100)
RB(6,8,-2,minecraft:chiseled_quartz_block,10,minecraft:quartz_pillar,10,minecraft:smooth_quartz,10,minecraft:quartz_block,100)
RB(6,9,-2,minecraft:chiseled_quartz_block,10,minecraft:quartz_pillar,10,minecraft:smooth_quartz,10,minecraft:quartz_block,100)
RB(6,10,-2,minecraft:chiseled_quartz_block,10,minecraft:quartz_pillar,10,minecraft:smooth_quartz,10,minecraft:quartz_block,100)
RB(6,11,-2,minecraft:chiseled_quartz_block,10,minecraft:quartz_pillar,10,minecraft:smooth_quartz,10,minecraft:quartz_block,100)
RB(6,12,-2,minecraft:chiseled_quartz_block,10,minecraft:quartz_pillar,10,minecraft:smooth_quartz,10,minecraft:quartz_block,100)
RB(6,6,-1,minecraft:chiseled_quartz_block,10,minecraft:quartz_pillar,10,minecraft:smooth_quartz,10,minecraft:quartz_block,100)
RB(6,7,-1,minecraft:chiseled_quartz_block,10,minecraft:quartz_pillar,10,minecraft:smooth_quartz,10,minecraft:quartz_block,100)
RB(6,8,-1,minecraft:chiseled_quartz_block,10,minecraft:quartz_pillar,10,minecraft:smooth_quartz,10,minecraft:quartz_block,100)
RB(6,9,-1,minecraft:chiseled_quartz_block,10,minecraft:quartz_pillar,10,minecraft:smooth_quartz,10,minecraft:quartz_block,100)
RB(6,10,-1,minecraft:chiseled_quartz_block,10,minecraft:quartz_pillar,10,minecraft:smooth_quartz,10,minecraft:quartz_block,100)
RB(6,11,-1,minecraft:chiseled_quartz_block,10,minecraft:quartz_pillar,10,minecraft:smooth_quartz,10,minecraft:quartz_block,100)
RB(6,12,-1,minecraft:chiseled_quartz_block,10,minecraft:quartz_pillar,10,minecraft:smooth_quartz,10,minecraft:quartz_block,100)
RB(6,7,0,minecraft:chiseled_quartz_block,10,minecraft:quartz_pillar,10,minecraft:smooth_quartz,10,minecraft:quartz_block,100)
RB(6,8,0,minecraft:chiseled_quartz_block,10,minecraft:quartz_pillar,10,minecraft:smooth_quartz,10,minecraft:quartz_block,100)
RB(6,9,0,minecraft:chiseled_quartz_block,10,minecraft:quartz_pillar,10,minecraft:smooth_quartz,10,minecraft:quartz_block,100)
RB(6,10,0,minecraft:chiseled_quartz_block,10,minecraft:quartz_pillar,10,minecraft:smooth_quartz,10,minecraft:quartz_block,100)
RB(6,11,0,minecraft:chiseled_quartz_block,10,minecraft:quartz_pillar,10,minecraft:smooth_quartz,10,minecraft:quartz_block,100)
RB(6,12,0,minecraft:chiseled_quartz_block,10,minecraft:quartz_pillar,10,minecraft:smooth_quartz,10,minecraft:quartz_block,100)
RB(6,8,1,minecraft:chiseled_quartz_block,10,minecraft:quartz_pillar,10,minecraft:smooth_quartz,10,minecraft:quartz_block,100)
RB(6,9,1,minecraft:chiseled_quartz_block,10,minecraft:quartz_pillar,10,minecraft:smooth_quartz,10,minecraft:quartz_block,100)
RB(6,10,1,minecraft:chiseled_quartz_block,10,minecraft:quartz_pillar,10,minecraft:smooth_quartz,10,minecraft:quartz_block,100)
RB(6,11,1,minecraft:chiseled_quartz_block,10,minecraft:quartz_pillar,10,minecraft:smooth_quartz,10,minecraft:quartz_block,100)
RB(6,12,1,minecraft:chiseled_quartz_block,10,minecraft:quartz_pillar,10,minecraft:smooth_quartz,10,minecraft:quartz_block,100)
RB(6,9,2,minecraft:chiseled_quartz_block,10,minecraft:quartz_pillar,10,minecraft:smooth_quartz,10,minecraft:quartz_block,100)
RB(6,10,2,minecraft:chiseled_quartz_block,10,minecraft:quartz_pillar,10,minecraft:smooth_quartz,10,minecraft:quartz_block,100)
RB(6,11,2,minecraft:chiseled_quartz_block,10,minecraft:quartz_pillar,10,minecraft:smooth_quartz,10,minecraft:quartz_block,100)
RB(6,12,2,minecraft:chiseled_quartz_block,10,minecraft:quartz_pillar,10,minecraft:smooth_quartz,10,minecraft:quartz_block,100)
RB(6,9,3,minecraft:chiseled_quartz_block,10,minecraft:quartz_pillar,10,minecraft:smooth_quartz,10,minecraft:quartz_block,100)
RB(6,10,3,minecraft:chiseled_quartz_block,10,minecraft:quartz_pillar,10,minecraft:smooth_quartz,10,minecraft:quartz_block,100)
RB(6,11,3,minecraft:chiseled_quartz_block,10,minecraft:quartz_pillar,10,minecraft:smooth_quartz,10,minecraft:quartz_block,100)
RB(6,12,3,minecraft:chiseled_quartz_block,10,minecraft:quartz_pillar,10,minecraft:smooth_quartz,10,minecraft:quartz_block,100)
RB(6,10,4,minecraft:chiseled_quartz_block,10,minecraft:quartz_pillar,10,minecraft:smooth_quartz,10,minecraft:quartz_block,100)
RB(6,11,4,minecraft:chiseled_quartz_block,10,minecraft:quartz_pillar,10,minecraft:smooth_quartz,10,minecraft:quartz_block,100)
RB(6,12,4,minecraft:chiseled_quartz_block,10,minecraft:quartz_pillar,10,minecraft:smooth_quartz,10,minecraft:quartz_block,100)
RB(6,11,5,minecraft:chiseled_quartz_block,10,minecraft:quartz_pillar,10,minecraft:smooth_quartz,10,minecraft:quartz_block,100)
RB(6,12,5,minecraft:chiseled_quartz_block,10,minecraft:quartz_pillar,10,minecraft:smooth_quartz,10,minecraft:quartz_block,100)
RB(6,12,6,minecraft:chiseled_quartz_block,10,minecraft:quartz_pillar,10,minecraft:smooth_quartz,10,minecraft:quartz_block,100)
RB(6,12,7,minecraft:chiseled_quartz_block,10,minecraft:quartz_pillar,10,minecraft:smooth_quartz,10,minecraft:quartz_block,100)
RB(7,2,-10,minecraft:chiseled_quartz_block,10,minecraft:quartz_pillar,10,minecraft:smooth_quartz,10,minecraft:quartz_block,100)
RB(7,2,-9,minecraft:chiseled_quartz_block,10,minecraft:quartz_pillar,10,minecraft:smooth_quartz,10,minecraft:quartz_block,100)
RB(7,3,-9,minecraft:chiseled_quartz_block,10,minecraft:quartz_pillar,10,minecraft:smooth_quartz,10,minecraft:quartz_block,100)
RB(7,4,-9,minecraft:chiseled_quartz_block,10,minecraft:quartz_pillar,10,minecraft:smooth_quartz,10,minecraft:quartz_block,100)
RB(7,5,-9,minecraft:chiseled_quartz_block,10,minecraft:quartz_pillar,10,minecraft:smooth_quartz,10,minecraft:quartz_block,100)
RB(7,3,-8,minecraft:chiseled_quartz_block,10,minecraft:quartz_pillar,10,minecraft:smooth_quartz,10,minecraft:quartz_block,100)
RB(7,4,-8,minecraft:chiseled_quartz_block,10,minecraft:quartz_pillar,10,minecraft:smooth_quartz,10,minecraft:quartz_block,100)
RB(7,5,-8,minecraft:chiseled_quartz_block,10,minecraft:quartz_pillar,10,minecraft:smooth_quartz,10,minecraft:quartz_block,100)
RB(7,6,-8,minecraft:chiseled_quartz_block,10,minecraft:quartz_pillar,10,minecraft:smooth_quartz,10,minecraft:quartz_block,100)
RB(7,3,-7,minecraft:chiseled_quartz_block,10,minecraft:quartz_pillar,10,minecraft:smooth_quartz,10,minecraft:quartz_block,100)
RB(7,4,-7,minecraft:chiseled_quartz_block,10,minecraft:quartz_pillar,10,minecraft:smooth_quartz,10,minecraft:quartz_block,100)
RB(7,5,-7,minecraft:chiseled_quartz_block,10,minecraft:quartz_pillar,10,minecraft:smooth_quartz,10,minecraft:quartz_block,100)
RB(7,6,-7,minecraft:chiseled_quartz_block,10,minecraft:quartz_pillar,10,minecraft:smooth_quartz,10,minecraft:quartz_block,100)
RB(7,7,-7,minecraft:chiseled_quartz_block,10,minecraft:quartz_pillar,10,minecraft:smooth_quartz,10,minecraft:quartz_block,100)
RB(7,3,-6,minecraft:chiseled_quartz_block,10,minecraft:quartz_pillar,10,minecraft:smooth_quartz,10,minecraft:quartz_block,100)
RB(7,4,-6,minecraft:chiseled_quartz_block,10,minecraft:quartz_pillar,10,minecraft:smooth_quartz,10,minecraft:quartz_block,100)
RB(7,5,-6,minecraft:chiseled_quartz_block,10,minecraft:quartz_pillar,10,minecraft:smooth_quartz,10,minecraft:quartz_block,100)
RB(7,6,-6,minecraft:chiseled_quartz_block,10,minecraft:quartz_pillar,10,minecraft:smooth_quartz,10,minecraft:quartz_block,100)
