
#######################################################################
# +-----------------------------------------------------------------+ #
# |                            BO3 object                           | #
# +-----------------------------------------------------------------+ #
#######################################################################

Author: Frank

Description: Red gargoyle with fire eyes and wings

Version: 3

SettingsMode: WriteDisable


#######################################################################
# +-----------------------------------------------------------------+ #
# |                          Main settings                          | #
# +-----------------------------------------------------------------+ #
#######################################################################

Tree: true

Frequency: 1

Rarity: 1.0

MaxSpawn: 1

RotateRandomly: true

SpawnHeight: randomY

SpawnHeightOffset: 0

SpawnHeightVariance: 0

##############################
# Height Limits for the BO3. #
##############################

MinHeight: 50

MaxHeight: 65

######################
# Extrusion settings #
######################

ExtrudeMode: None

ExtrudeThroughBlocks: minecraft:air

MaxBranchDepth: 10


#######################################################################
# +-----------------------------------------------------------------+ #
# |                      Source block settings                      | #
# +-----------------------------------------------------------------+ #
#######################################################################

SourceBlocks: minecraft:air

MaxPercentageOutsideSourceBlock: 30

OutsideSourceBlock: dontPlace

DoReplaceBlocks: true

IsOTGPlus: false


#######################################################################
# +-----------------------------------------------------------------+ #
# |                              Blocks                             | #
# +-----------------------------------------------------------------+ #
#######################################################################

B(-6,18,-13,minecraft:red_nether_bricks)
B(-6,18,-11,minecraft:red_nether_bricks)
B(-6,18,-9,minecraft:red_nether_bricks)
B(-6,37,-5,minecraft:nether_wart_block)
B(-6,38,-5,minecraft:nether_wart_block)
B(-6,18,9,minecraft:red_nether_bricks)
B(-6,18,11,minecraft:red_nether_bricks)
B(-6,18,13,minecraft:red_nether_bricks)
B(-5,18,-13,minecraft:red_nether_bricks)
B(-5,18,-11,minecraft:red_nether_bricks)
B(-5,18,-9,minecraft:red_nether_bricks)
B(-5,37,-5,minecraft:nether_wart_block)
B(-5,36,-4,minecraft:nether_wart_block)
B(-5,37,-4,minecraft:nether_wart_block)
B(-5,36,-3,minecraft:nether_wart_block)
B(-5,18,9,minecraft:red_nether_bricks)
B(-5,18,11,minecraft:red_nether_bricks)
B(-5,18,13,minecraft:red_nether_bricks)
B(-4,18,-12,minecraft:red_nether_bricks)
B(-4,18,-11,minecraft:red_nether_bricks)
B(-4,18,-10,minecraft:red_nether_bricks)
B(-4,31,-3,minecraft:red_nether_bricks)
B(-4,32,-3,minecraft:red_nether_bricks)
B(-4,33,-3,minecraft:red_nether_bricks)
B(-4,35,-3,minecraft:nether_wart_block)
B(-4,36,-3,minecraft:nether_wart_block)
B(-4,30,-2,minecraft:red_nether_bricks)
B(-4,31,-2,minecraft:red_nether_bricks)
B(-4,33,-2,minecraft:red_nether_bricks)
B(-4,34,-2,minecraft:red_nether_bricks)
B(-4,29,-1,minecraft:red_nether_bricks)
B(-4,31,-1,minecraft:red_nether_brick_stairs[facing=south,half=top,shape=straight,waterlogged=false])
B(-4,32,-1,minecraft:red_nether_bricks)
B(-4,33,-1,minecraft:red_nether_bricks)
B(-4,34,-1,minecraft:red_nether_bricks)
B(-4,35,-1,minecraft:red_nether_bricks)
B(-4,29,0,minecraft:red_nether_bricks)
B(-4,31,0,minecraft:red_nether_brick_stairs[facing=south,half=top,shape=straight,waterlogged=false])
B(-4,32,0,minecraft:red_nether_bricks)
B(-4,33,0,minecraft:red_nether_bricks)
B(-4,34,0,minecraft:red_nether_bricks)
B(-4,35,0,minecraft:red_nether_bricks)
B(-4,30,1,minecraft:red_nether_bricks)
B(-4,31,1,minecraft:red_nether_bricks)
B(-4,33,1,minecraft:red_nether_bricks)
B(-4,34,1,minecraft:red_nether_bricks)
B(-4,31,2,minecraft:red_nether_bricks)
B(-4,32,2,minecraft:red_nether_bricks)
B(-4,33,2,minecraft:red_nether_bricks)
B(-4,39,4,minecraft:nether_wart_block)
B(-4,38,5,minecraft:nether_wart_block)
B(-4,39,5,minecraft:nether_wart_block)
B(-4,18,10,minecraft:red_nether_bricks)
B(-4,18,11,minecraft:red_nether_bricks)
B(-4,18,12,minecraft:red_nether_bricks)
B(-3,18,-12,minecraft:red_nether_bricks)
B(-3,17,-11,minecraft:red_nether_bricks)
B(-3,18,-11,minecraft:red_nether_bricks)
B(-3,19,-11,minecraft:red_nether_bricks)
B(-3,18,-10,minecraft:red_nether_bricks)
B(-3,0,-7,minecraft:red_nether_bricks)
B(-3,0,-5,minecraft:red_nether_bricks)
B(-3,31,-4,minecraft:red_nether_bricks)
B(-3,32,-4,minecraft:red_nether_bricks)
B(-3,33,-4,minecraft:red_nether_bricks)
B(-3,0,-3,minecraft:red_nether_bricks)
B(-3,30,-3,minecraft:red_nether_bricks)
B(-3,34,-3,minecraft:red_nether_bricks)
B(-3,35,-3,minecraft:nether_wart_block)
B(-3,29,-2,minecraft:red_nether_bricks)
B(-3,31,-2,minecraft:netherrack)
B(-3,32,-2,minecraft:fire[age=6,east=false,north=false,south=false,up=false,west=false])
B(-3,35,-2,minecraft:red_nether_bricks)
B(-3,28,-1,minecraft:red_nether_bricks)
B(-3,29,-1,minecraft:netherrack)
B(-3,30,-1,minecraft:fire[age=6,east=false,north=false,south=false,up=false,west=false])
B(-3,36,-1,minecraft:red_nether_bricks)
B(-3,28,0,minecraft:red_nether_bricks)
B(-3,29,0,minecraft:netherrack)
B(-3,30,0,minecraft:fire[age=8,east=false,north=false,south=false,up=false,west=false])
B(-3,36,0,minecraft:red_nether_bricks)
B(-3,29,1,minecraft:red_nether_bricks)
B(-3,31,1,minecraft:netherrack)
B(-3,32,1,minecraft:fire[age=4,east=false,north=false,south=false,up=false,west=false])
B(-3,35,1,minecraft:red_nether_bricks)
B(-3,0,2,minecraft:red_nether_bricks)
B(-3,30,2,minecraft:red_nether_bricks)
B(-3,34,2,minecraft:red_nether_bricks)
B(-3,31,3,minecraft:red_nether_bricks)
B(-3,32,3,minecraft:red_nether_bricks)
B(-3,33,3,minecraft:red_nether_bricks)
B(-3,38,3,minecraft:nether_wart_block)
B(-3,39,3,minecraft:nether_wart_block)
B(-3,0,4,minecraft:red_nether_bricks)
B(-3,39,4,minecraft:nether_wart_block)
B(-3,0,6,minecraft:red_nether_bricks)
B(-3,18,10,minecraft:red_nether_bricks)
B(-3,19,10,minecraft:red_nether_bricks)
B(-3,17,11,minecraft:red_nether_bricks)
B(-3,18,11,minecraft:red_nether_bricks)
B(-3,19,11,minecraft:red_nether_bricks)
B(-3,18,12,minecraft:red_nether_bricks)
B(-2,18,-12,minecraft:red_nether_bricks)
B(-2,17,-11,minecraft:red_nether_bricks)
B(-2,18,-11,minecraft:red_nether_bricks)
B(-2,19,-11,minecraft:red_nether_bricks)
B(-2,18,-10,minecraft:red_nether_bricks)
B(-2,19,-10,minecraft:red_nether_bricks)
B(-2,0,-8,minecraft:red_nether_bricks)
B(-2,0,-7,minecraft:red_nether_bricks)
B(-2,1,-7,minecraft:red_nether_bricks)
B(-2,0,-6,minecraft:red_nether_bricks)
B(-2,0,-5,minecraft:red_nether_bricks)
B(-2,1,-5,minecraft:red_nether_bricks)
B(-2,0,-4,minecraft:red_nether_bricks)
B(-2,30,-4,minecraft:red_nether_bricks)
B(-2,31,-4,minecraft:red_nether_bricks)
B(-2,32,-4,minecraft:red_nether_bricks)
B(-2,33,-4,minecraft:red_nether_bricks)
B(-2,34,-4,minecraft:red_nether_bricks)
B(-2,0,-3,minecraft:red_nether_bricks)
B(-2,1,-3,minecraft:red_nether_bricks)
B(-2,29,-3,minecraft:red_nether_bricks)
B(-2,35,-3,minecraft:red_nether_bricks)
B(-2,0,-2,minecraft:red_nether_bricks)
B(-2,28,-2,minecraft:red_nether_bricks)
B(-2,36,-2,minecraft:red_nether_bricks)
B(-2,12,-1,minecraft:red_nether_bricks)
B(-2,13,-1,minecraft:red_nether_bricks)
B(-2,14,-1,minecraft:red_nether_bricks)
B(-2,15,-1,minecraft:red_nether_bricks)
B(-2,16,-1,minecraft:red_nether_bricks)
B(-2,17,-1,minecraft:red_nether_bricks)
B(-2,18,-1,minecraft:red_nether_bricks)
B(-2,19,-1,minecraft:red_nether_bricks)
B(-2,20,-1,minecraft:red_nether_bricks)
B(-2,21,-1,minecraft:red_nether_bricks)
B(-2,27,-1,minecraft:red_nether_bricks)
B(-2,37,-1,minecraft:red_nether_bricks)
B(-2,12,0,minecraft:red_nether_bricks)
B(-2,13,0,minecraft:red_nether_bricks)
B(-2,14,0,minecraft:red_nether_bricks)
B(-2,15,0,minecraft:red_nether_bricks)
B(-2,16,0,minecraft:red_nether_bricks)
B(-2,17,0,minecraft:red_nether_bricks)
B(-2,18,0,minecraft:red_nether_bricks)
B(-2,19,0,minecraft:red_nether_bricks)
B(-2,20,0,minecraft:red_nether_bricks)
B(-2,21,0,minecraft:red_nether_bricks)
B(-2,27,0,minecraft:red_nether_bricks)
B(-2,37,0,minecraft:red_nether_bricks)
B(-2,0,1,minecraft:red_nether_bricks)
B(-2,28,1,minecraft:red_nether_bricks)
B(-2,36,1,minecraft:red_nether_bricks)
B(-2,37,1,minecraft:nether_wart_block)
B(-2,0,2,minecraft:red_nether_bricks)
B(-2,1,2,minecraft:red_nether_bricks)
B(-2,29,2,minecraft:red_nether_bricks)
B(-2,35,2,minecraft:red_nether_bricks)
B(-2,37,2,minecraft:nether_wart_block)
B(-2,38,2,minecraft:nether_wart_block)
B(-2,0,3,minecraft:red_nether_bricks)
B(-2,30,3,minecraft:red_nether_bricks)
B(-2,31,3,minecraft:red_nether_bricks)
B(-2,32,3,minecraft:red_nether_bricks)
B(-2,33,3,minecraft:red_nether_bricks)
B(-2,34,3,minecraft:red_nether_bricks)
B(-2,38,3,minecraft:nether_wart_block)
B(-2,0,4,minecraft:red_nether_bricks)
B(-2,1,4,minecraft:red_nether_bricks)
B(-2,0,5,minecraft:red_nether_bricks)
B(-2,0,6,minecraft:red_nether_bricks)
B(-2,1,6,minecraft:red_nether_bricks)
B(-2,0,7,minecraft:red_nether_bricks)
B(-2,19,9,minecraft:red_nether_bricks)
B(-2,18,10,minecraft:red_nether_bricks)
B(-2,19,10,minecraft:red_nether_bricks)
B(-2,20,10,minecraft:red_nether_bricks)
B(-2,17,11,minecraft:red_nether_bricks)
B(-2,18,11,minecraft:red_nether_bricks)
B(-2,19,11,minecraft:red_nether_bricks)
B(-1,17,-11,minecraft:red_nether_bricks)
B(-1,18,-11,minecraft:red_nether_bricks)
B(-1,19,-11,minecraft:red_nether_bricks)
B(-1,18,-10,minecraft:red_nether_bricks)
B(-1,19,-10,minecraft:red_nether_bricks)
B(-1,20,-10,minecraft:red_nether_bricks)
B(-1,19,-9,minecraft:red_nether_bricks)
B(-1,0,-8,minecraft:red_nether_bricks)
B(-1,0,-7,minecraft:red_nether_bricks)
B(-1,1,-7,minecraft:red_nether_bricks)
B(-1,0,-6,minecraft:red_nether_bricks)
B(-1,1,-6,minecraft:red_nether_bricks)
B(-1,0,-5,minecraft:red_nether_bricks)
B(-1,1,-5,minecraft:red_nether_bricks)
B(-1,2,-5,minecraft:red_nether_bricks)
B(-1,3,-5,minecraft:red_nether_bricks)
B(-1,4,-5,minecraft:red_nether_bricks)
B(-1,5,-5,minecraft:red_nether_bricks)
B(-1,6,-5,minecraft:red_nether_bricks)
B(-1,0,-4,minecraft:red_nether_bricks)
B(-1,1,-4,minecraft:red_nether_bricks)
B(-1,29,-4,minecraft:red_nether_bricks)
B(-1,30,-4,minecraft:red_nether_bricks)
B(-1,31,-4,minecraft:red_nether_bricks)
B(-1,32,-4,minecraft:red_nether_bricks)
B(-1,33,-4,minecraft:red_nether_bricks)
B(-1,34,-4,minecraft:red_nether_bricks)
B(-1,35,-4,minecraft:red_nether_bricks)
B(-1,0,-3,minecraft:red_nether_bricks)
B(-1,1,-3,minecraft:red_nether_bricks)
B(-1,12,-3,minecraft:red_nether_bricks)
B(-1,13,-3,minecraft:red_nether_bricks)
B(-1,14,-3,minecraft:red_nether_bricks)
B(-1,15,-3,minecraft:red_nether_bricks)
B(-1,16,-3,minecraft:red_nether_bricks)
B(-1,17,-3,minecraft:red_nether_bricks)
B(-1,18,-3,minecraft:red_nether_bricks)
B(-1,19,-3,minecraft:red_nether_bricks)
B(-1,20,-3,minecraft:red_nether_bricks)
B(-1,21,-3,minecraft:red_nether_bricks)
B(-1,28,-3,minecraft:red_nether_bricks)
B(-1,36,-3,minecraft:red_nether_bricks)
B(-1,0,-2,minecraft:red_nether_bricks)
B(-1,12,-2,minecraft:red_nether_bricks)
B(-1,13,-2,minecraft:red_nether_bricks)
B(-1,14,-2,minecraft:red_nether_bricks)
B(-1,15,-2,minecraft:red_nether_bricks)
B(-1,16,-2,minecraft:red_nether_bricks)
B(-1,17,-2,minecraft:red_nether_bricks)
B(-1,18,-2,minecraft:red_nether_bricks)
B(-1,19,-2,minecraft:red_nether_bricks)
B(-1,20,-2,minecraft:red_nether_bricks)
B(-1,21,-2,minecraft:red_nether_bricks)
B(-1,27,-2,minecraft:red_nether_bricks)
B(-1,37,-2,minecraft:red_nether_bricks)
B(-1,11,-1,minecraft:red_nether_bricks)
B(-1,12,-1,minecraft:red_nether_bricks)
B(-1,22,-1,minecraft:red_nether_bricks)
B(-1,26,-1,minecraft:red_nether_bricks)
B(-1,38,-1,minecraft:red_nether_bricks)
B(-1,11,0,minecraft:red_nether_bricks)
B(-1,12,0,minecraft:red_nether_bricks)
B(-1,22,0,minecraft:red_nether_bricks)
B(-1,26,0,minecraft:red_nether_bricks)
B(-1,38,0,minecraft:red_nether_bricks)
B(-1,0,1,minecraft:red_nether_bricks)
B(-1,12,1,minecraft:red_nether_bricks)
B(-1,13,1,minecraft:red_nether_bricks)
B(-1,14,1,minecraft:red_nether_bricks)
B(-1,15,1,minecraft:red_nether_bricks)
B(-1,16,1,minecraft:red_nether_bricks)
B(-1,17,1,minecraft:red_nether_bricks)
B(-1,18,1,minecraft:red_nether_bricks)
B(-1,19,1,minecraft:red_nether_bricks)
B(-1,20,1,minecraft:red_nether_bricks)
B(-1,21,1,minecraft:red_nether_bricks)
B(-1,27,1,minecraft:red_nether_bricks)
B(-1,37,1,minecraft:red_nether_bricks)
B(-1,0,2,minecraft:red_nether_bricks)
B(-1,1,2,minecraft:red_nether_bricks)
B(-1,12,2,minecraft:red_nether_bricks)
B(-1,13,2,minecraft:red_nether_bricks)
B(-1,14,2,minecraft:red_nether_bricks)
B(-1,15,2,minecraft:red_nether_bricks)
B(-1,16,2,minecraft:red_nether_bricks)
B(-1,17,2,minecraft:red_nether_bricks)
B(-1,18,2,minecraft:red_nether_bricks)
B(-1,19,2,minecraft:red_nether_bricks)
B(-1,20,2,minecraft:red_nether_bricks)
B(-1,21,2,minecraft:red_nether_bricks)
B(-1,28,2,minecraft:red_nether_bricks)
B(-1,36,2,minecraft:red_nether_bricks)
B(-1,0,3,minecraft:red_nether_bricks)
B(-1,1,3,minecraft:red_nether_bricks)
B(-1,29,3,minecraft:red_nether_bricks)
B(-1,30,3,minecraft:red_nether_bricks)
B(-1,31,3,minecraft:red_nether_bricks)
B(-1,32,3,minecraft:red_nether_bricks)
B(-1,33,3,minecraft:red_nether_bricks)
B(-1,34,3,minecraft:red_nether_bricks)
B(-1,35,3,minecraft:red_nether_bricks)
B(-1,0,4,minecraft:red_nether_bricks)
B(-1,1,4,minecraft:red_nether_bricks)
B(-1,2,4,minecraft:red_nether_bricks)
B(-1,3,4,minecraft:red_nether_bricks)
B(-1,4,4,minecraft:red_nether_bricks)
B(-1,5,4,minecraft:red_nether_bricks)
B(-1,6,4,minecraft:red_nether_bricks)
B(-1,0,5,minecraft:red_nether_bricks)
B(-1,1,5,minecraft:red_nether_bricks)
B(-1,0,6,minecraft:red_nether_bricks)
B(-1,1,6,minecraft:red_nether_bricks)
B(-1,0,7,minecraft:red_nether_bricks)
B(-1,19,8,minecraft:red_nether_bricks)
B(-1,18,9,minecraft:red_nether_bricks)
B(-1,19,9,minecraft:red_nether_bricks)
B(-1,20,9,minecraft:red_nether_bricks)
B(-1,19,10,minecraft:red_nether_bricks)
B(-1,18,11,minecraft:red_nether_bricks)
B(0,18,-11,minecraft:red_nether_bricks)
B(0,19,-10,minecraft:red_nether_bricks)
B(0,18,-9,minecraft:red_nether_bricks)
B(0,19,-9,minecraft:red_nether_bricks)
B(0,20,-9,minecraft:red_nether_bricks)
B(0,19,-8,minecraft:red_nether_bricks)
B(0,0,-7,minecraft:red_nether_bricks)
B(0,20,-7,minecraft:red_nether_bricks)
B(0,0,-6,minecraft:red_nether_bricks)
B(0,1,-6,minecraft:red_nether_bricks)
B(0,2,-6,minecraft:red_nether_bricks)
B(0,3,-6,minecraft:red_nether_bricks)
B(0,4,-6,minecraft:red_nether_bricks)
B(0,5,-6,minecraft:red_nether_bricks)
B(0,6,-6,minecraft:red_nether_bricks)
B(0,7,-6,minecraft:red_nether_bricks)
B(0,20,-6,minecraft:red_nether_bricks)
B(0,0,-5,minecraft:red_nether_bricks)
B(0,1,-5,minecraft:red_nether_bricks)
B(0,2,-5,minecraft:red_nether_bricks)
B(0,3,-5,minecraft:red_nether_bricks)
B(0,4,-5,minecraft:red_nether_bricks)
B(0,5,-5,minecraft:red_nether_bricks)
B(0,6,-5,minecraft:red_nether_bricks)
B(0,7,-5,minecraft:red_nether_bricks)
B(0,8,-5,minecraft:red_nether_bricks)
B(0,9,-5,minecraft:red_nether_bricks)
B(0,10,-5,minecraft:red_nether_bricks)
B(0,11,-5,minecraft:red_nether_bricks)
B(0,20,-5,minecraft:red_nether_bricks)
B(0,0,-4,minecraft:red_nether_bricks)
B(0,1,-4,minecraft:red_nether_bricks)
B(0,2,-4,minecraft:red_nether_bricks)
B(0,3,-4,minecraft:red_nether_bricks)
B(0,4,-4,minecraft:red_nether_bricks)
B(0,5,-4,minecraft:red_nether_bricks)
B(0,6,-4,minecraft:red_nether_bricks)
B(0,7,-4,minecraft:red_nether_bricks)
B(0,12,-4,minecraft:red_nether_bricks)
B(0,13,-4,minecraft:red_nether_bricks)
B(0,14,-4,minecraft:red_nether_bricks)
B(0,15,-4,minecraft:red_nether_bricks)
B(0,16,-4,minecraft:red_nether_bricks)
B(0,17,-4,minecraft:red_nether_bricks)
B(0,18,-4,minecraft:red_nether_bricks)
B(0,19,-4,minecraft:red_nether_bricks)
B(0,20,-4,minecraft:red_nether_bricks)
B(0,21,-4,minecraft:red_nether_bricks)
B(0,29,-4,minecraft:red_nether_bricks)
B(0,30,-4,minecraft:red_nether_bricks)
B(0,31,-4,minecraft:red_nether_bricks)
B(0,32,-4,minecraft:red_nether_bricks)
B(0,33,-4,minecraft:red_nether_bricks)
B(0,34,-4,minecraft:red_nether_bricks)
B(0,35,-4,minecraft:red_nether_bricks)
B(0,37,-4,minecraft:nether_wart_block)
B(0,38,-4,minecraft:nether_wart_block)
B(0,0,-3,minecraft:red_nether_bricks)
B(0,11,-3,minecraft:red_nether_bricks)
B(0,12,-3,minecraft:red_nether_bricks)
B(0,22,-3,minecraft:red_nether_bricks)
B(0,28,-3,minecraft:red_nether_bricks)
B(0,36,-3,minecraft:red_nether_bricks)
B(0,37,-3,minecraft:nether_wart_block)
B(0,10,-2,minecraft:red_nether_bricks)
B(0,11,-2,minecraft:red_nether_bricks)
B(0,12,-2,minecraft:red_nether_bricks)
B(0,22,-2,minecraft:red_nether_bricks)
B(0,27,-2,minecraft:red_nether_bricks)
B(0,37,-2,minecraft:red_nether_bricks)
B(0,10,-1,minecraft:red_nether_bricks)
B(0,11,-1,minecraft:red_nether_bricks)
B(0,12,-1,minecraft:red_nether_bricks)
B(0,23,-1,minecraft:red_nether_bricks)
B(0,25,-1,minecraft:red_nether_bricks)
B(0,26,-1,minecraft:red_nether_bricks)
B(0,38,-1,minecraft:red_nether_bricks)
B(0,10,0,minecraft:red_nether_bricks)
B(0,11,0,minecraft:red_nether_bricks)
B(0,12,0,minecraft:red_nether_bricks)
B(0,23,0,minecraft:red_nether_bricks)
B(0,25,0,minecraft:red_nether_bricks)
B(0,26,0,minecraft:red_nether_bricks)
B(0,38,0,minecraft:red_nether_bricks)
B(0,10,1,minecraft:red_nether_bricks)
B(0,11,1,minecraft:red_nether_bricks)
B(0,12,1,minecraft:red_nether_bricks)
B(0,22,1,minecraft:red_nether_bricks)
B(0,27,1,minecraft:red_nether_bricks)
B(0,37,1,minecraft:red_nether_bricks)
B(0,0,2,minecraft:red_nether_bricks)
B(0,11,2,minecraft:red_nether_bricks)
B(0,12,2,minecraft:red_nether_bricks)
B(0,22,2,minecraft:red_nether_bricks)
B(0,28,2,minecraft:red_nether_bricks)
B(0,36,2,minecraft:red_nether_bricks)
B(0,0,3,minecraft:red_nether_bricks)
B(0,1,3,minecraft:red_nether_bricks)
B(0,2,3,minecraft:red_nether_bricks)
B(0,3,3,minecraft:red_nether_bricks)
B(0,4,3,minecraft:red_nether_bricks)
B(0,5,3,minecraft:red_nether_bricks)
B(0,6,3,minecraft:red_nether_bricks)
B(0,7,3,minecraft:red_nether_bricks)
B(0,12,3,minecraft:red_nether_bricks)
B(0,13,3,minecraft:red_nether_bricks)
B(0,14,3,minecraft:red_nether_bricks)
B(0,15,3,minecraft:red_nether_bricks)
B(0,16,3,minecraft:red_nether_bricks)
B(0,17,3,minecraft:red_nether_bricks)
B(0,18,3,minecraft:red_nether_bricks)
B(0,19,3,minecraft:red_nether_bricks)
B(0,20,3,minecraft:red_nether_bricks)
B(0,21,3,minecraft:red_nether_bricks)
B(0,29,3,minecraft:red_nether_bricks)
B(0,30,3,minecraft:red_nether_bricks)
B(0,31,3,minecraft:red_nether_bricks)
B(0,32,3,minecraft:red_nether_bricks)
B(0,33,3,minecraft:red_nether_bricks)
B(0,34,3,minecraft:red_nether_bricks)
B(0,35,3,minecraft:red_nether_bricks)
B(0,0,4,minecraft:red_nether_bricks)
B(0,1,4,minecraft:red_nether_bricks)
B(0,2,4,minecraft:red_nether_bricks)
B(0,3,4,minecraft:red_nether_bricks)
B(0,4,4,minecraft:red_nether_bricks)
B(0,5,4,minecraft:red_nether_bricks)
B(0,6,4,minecraft:red_nether_bricks)
B(0,7,4,minecraft:red_nether_bricks)
B(0,8,4,minecraft:red_nether_bricks)
B(0,9,4,minecraft:red_nether_bricks)
B(0,10,4,minecraft:red_nether_bricks)
B(0,11,4,minecraft:red_nether_bricks)
B(0,20,4,minecraft:red_nether_bricks)
B(0,0,5,minecraft:red_nether_bricks)
B(0,1,5,minecraft:red_nether_bricks)
B(0,2,5,minecraft:red_nether_bricks)
B(0,3,5,minecraft:red_nether_bricks)
B(0,4,5,minecraft:red_nether_bricks)
B(0,5,5,minecraft:red_nether_bricks)
B(0,6,5,minecraft:red_nether_bricks)
B(0,7,5,minecraft:red_nether_bricks)
B(0,20,5,minecraft:red_nether_bricks)
B(0,0,6,minecraft:red_nether_bricks)
B(0,20,6,minecraft:red_nether_bricks)
B(0,19,7,minecraft:red_nether_bricks)
B(0,18,8,minecraft:red_nether_bricks)
B(0,19,8,minecraft:red_nether_bricks)
B(0,20,8,minecraft:red_nether_bricks)
B(0,19,9,minecraft:red_nether_bricks)
B(1,19,-9,minecraft:red_nether_bricks)
B(1,18,-8,minecraft:red_nether_bricks)
B(1,19,-8,minecraft:red_nether_bricks)
B(1,20,-8,minecraft:red_nether_bricks)
B(1,0,-7,minecraft:red_nether_bricks)
B(1,19,-7,minecraft:red_nether_bricks)
B(1,20,-7,minecraft:red_nether_bricks)
B(1,21,-7,minecraft:red_nether_bricks)
B(1,0,-6,minecraft:red_nether_bricks)
B(1,1,-6,minecraft:red_nether_bricks)
B(1,2,-6,minecraft:red_nether_bricks)
B(1,3,-6,minecraft:red_nether_bricks)
B(1,4,-6,minecraft:red_nether_bricks)
B(1,5,-6,minecraft:red_nether_bricks)
B(1,6,-6,minecraft:red_nether_bricks)
B(1,7,-6,minecraft:red_nether_bricks)
B(1,8,-6,minecraft:red_nether_bricks)
B(1,9,-6,minecraft:red_nether_bricks)
B(1,10,-6,minecraft:red_nether_bricks)
B(1,11,-6,minecraft:red_nether_bricks)
B(1,19,-6,minecraft:red_nether_bricks)
B(1,20,-6,minecraft:red_nether_bricks)
B(1,21,-6,minecraft:red_nether_bricks)
B(1,38,-6,minecraft:nether_wart_block)
B(1,39,-6,minecraft:nether_wart_block)
B(1,0,-5,minecraft:red_nether_bricks)
B(1,1,-5,minecraft:red_nether_bricks)
B(1,2,-5,minecraft:red_nether_bricks)
B(1,3,-5,minecraft:red_nether_bricks)
B(1,4,-5,minecraft:red_nether_bricks)
B(1,5,-5,minecraft:red_nether_bricks)
B(1,6,-5,minecraft:red_nether_bricks)
B(1,7,-5,minecraft:red_nether_bricks)
B(1,8,-5,minecraft:red_nether_bricks)
B(1,9,-5,minecraft:red_nether_bricks)
B(1,10,-5,minecraft:red_nether_bricks)
B(1,11,-5,minecraft:red_nether_bricks)
B(1,12,-5,minecraft:red_nether_bricks)
B(1,13,-5,minecraft:red_nether_bricks)
B(1,14,-5,minecraft:red_nether_bricks)
B(1,15,-5,minecraft:red_nether_bricks)
B(1,16,-5,minecraft:red_nether_bricks)
B(1,17,-5,minecraft:red_nether_bricks)
B(1,18,-5,minecraft:red_nether_bricks)
B(1,19,-5,minecraft:red_nether_bricks)
B(1,20,-5,minecraft:red_nether_bricks)
B(1,21,-5,minecraft:red_nether_bricks)
B(1,38,-5,minecraft:nether_wart_block)
B(1,0,-4,minecraft:red_nether_bricks)
B(1,1,-4,minecraft:red_nether_bricks)
B(1,2,-4,minecraft:red_nether_bricks)
B(1,3,-4,minecraft:red_nether_bricks)
B(1,4,-4,minecraft:red_nether_bricks)
B(1,5,-4,minecraft:red_nether_bricks)
B(1,6,-4,minecraft:red_nether_bricks)
B(1,7,-4,minecraft:red_nether_bricks)
B(1,8,-4,minecraft:red_nether_bricks)
B(1,9,-4,minecraft:red_nether_bricks)
B(1,10,-4,minecraft:red_nether_bricks)
B(1,11,-4,minecraft:red_nether_bricks)
B(1,12,-4,minecraft:red_nether_bricks)
B(1,22,-4,minecraft:red_nether_bricks)
B(1,0,-3,minecraft:red_nether_bricks)
B(1,11,-3,minecraft:red_nether_bricks)
B(1,12,-3,minecraft:red_nether_bricks)
B(1,23,-3,minecraft:red_nether_bricks)
B(1,29,-3,minecraft:red_nether_bricks)
B(1,30,-3,minecraft:red_nether_bricks)
B(1,31,-3,minecraft:red_nether_bricks)
B(1,32,-3,minecraft:red_nether_bricks)
B(1,33,-3,minecraft:red_nether_bricks)
B(1,34,-3,minecraft:red_nether_bricks)
B(1,35,-3,minecraft:red_nether_bricks)
B(1,10,-2,minecraft:red_nether_bricks)
B(1,11,-2,minecraft:red_nether_bricks)
B(1,12,-2,minecraft:red_nether_bricks)
B(1,23,-2,minecraft:red_nether_bricks)
B(1,28,-2,minecraft:red_nether_bricks)
B(1,36,-2,minecraft:red_nether_bricks)
B(1,9,-1,minecraft:red_nether_bricks)
B(1,10,-1,minecraft:red_nether_bricks)
B(1,11,-1,minecraft:red_nether_bricks)
B(1,12,-1,minecraft:red_nether_bricks)
B(1,24,-1,minecraft:red_nether_bricks)
B(1,25,-1,minecraft:red_nether_bricks)
B(1,27,-1,minecraft:red_nether_bricks)
B(1,37,-1,minecraft:red_nether_bricks)
B(1,9,0,minecraft:red_nether_bricks)
B(1,10,0,minecraft:red_nether_bricks)
B(1,11,0,minecraft:red_nether_bricks)
B(1,12,0,minecraft:red_nether_bricks)
B(1,24,0,minecraft:red_nether_bricks)
B(1,25,0,minecraft:red_nether_bricks)
B(1,27,0,minecraft:red_nether_bricks)
B(1,37,0,minecraft:red_nether_bricks)
B(1,10,1,minecraft:red_nether_bricks)
B(1,11,1,minecraft:red_nether_bricks)
B(1,12,1,minecraft:red_nether_bricks)
B(1,23,1,minecraft:red_nether_bricks)
B(1,28,1,minecraft:red_nether_bricks)
B(1,36,1,minecraft:red_nether_bricks)
B(1,37,1,minecraft:nether_wart_block)
B(1,0,2,minecraft:red_nether_bricks)
B(1,11,2,minecraft:red_nether_bricks)
B(1,12,2,minecraft:red_nether_bricks)
B(1,23,2,minecraft:red_nether_bricks)
B(1,29,2,minecraft:red_nether_bricks)
B(1,30,2,minecraft:red_nether_bricks)
B(1,31,2,minecraft:red_nether_bricks)
B(1,32,2,minecraft:red_nether_bricks)
B(1,33,2,minecraft:red_nether_bricks)
B(1,34,2,minecraft:red_nether_bricks)
B(1,35,2,minecraft:red_nether_bricks)
B(1,0,3,minecraft:red_nether_bricks)
B(1,1,3,minecraft:red_nether_bricks)
B(1,2,3,minecraft:red_nether_bricks)
B(1,3,3,minecraft:red_nether_bricks)
B(1,4,3,minecraft:red_nether_bricks)
B(1,5,3,minecraft:red_nether_bricks)
B(1,6,3,minecraft:red_nether_bricks)
B(1,7,3,minecraft:red_nether_bricks)
B(1,8,3,minecraft:red_nether_bricks)
B(1,9,3,minecraft:red_nether_bricks)
B(1,10,3,minecraft:red_nether_bricks)
B(1,11,3,minecraft:red_nether_bricks)
B(1,12,3,minecraft:red_nether_bricks)
B(1,22,3,minecraft:red_nether_bricks)
B(1,0,4,minecraft:red_nether_bricks)
B(1,1,4,minecraft:red_nether_bricks)
B(1,2,4,minecraft:red_nether_bricks)
B(1,3,4,minecraft:red_nether_bricks)
B(1,4,4,minecraft:red_nether_bricks)
B(1,5,4,minecraft:red_nether_bricks)
B(1,6,4,minecraft:red_nether_bricks)
B(1,7,4,minecraft:red_nether_bricks)
B(1,8,4,minecraft:red_nether_bricks)
B(1,9,4,minecraft:red_nether_bricks)
B(1,10,4,minecraft:red_nether_bricks)
B(1,11,4,minecraft:red_nether_bricks)
B(1,12,4,minecraft:red_nether_bricks)
B(1,13,4,minecraft:red_nether_bricks)
B(1,14,4,minecraft:red_nether_bricks)
B(1,15,4,minecraft:red_nether_bricks)
B(1,16,4,minecraft:red_nether_bricks)
B(1,17,4,minecraft:red_nether_bricks)
B(1,18,4,minecraft:red_nether_bricks)
B(1,19,4,minecraft:red_nether_bricks)
B(1,20,4,minecraft:red_nether_bricks)
B(1,21,4,minecraft:red_nether_bricks)
B(1,0,5,minecraft:red_nether_bricks)
B(1,1,5,minecraft:red_nether_bricks)
B(1,2,5,minecraft:red_nether_bricks)
B(1,3,5,minecraft:red_nether_bricks)
B(1,4,5,minecraft:red_nether_bricks)
B(1,5,5,minecraft:red_nether_bricks)
B(1,6,5,minecraft:red_nether_bricks)
B(1,7,5,minecraft:red_nether_bricks)
B(1,8,5,minecraft:red_nether_bricks)
B(1,9,5,minecraft:red_nether_bricks)
B(1,10,5,minecraft:red_nether_bricks)
B(1,11,5,minecraft:red_nether_bricks)
B(1,19,5,minecraft:red_nether_bricks)
B(1,20,5,minecraft:red_nether_bricks)
B(1,21,5,minecraft:red_nether_bricks)
B(1,0,6,minecraft:red_nether_bricks)
B(1,19,6,minecraft:red_nether_bricks)
B(1,20,6,minecraft:red_nether_bricks)
B(1,21,6,minecraft:red_nether_bricks)
B(1,18,7,minecraft:red_nether_bricks)
B(1,19,7,minecraft:red_nether_bricks)
B(1,20,7,minecraft:red_nether_bricks)
B(1,19,8,minecraft:red_nether_bricks)
B(2,19,-8,minecraft:red_nether_bricks)
B(2,0,-7,minecraft:red_nether_bricks)
B(2,20,-7,minecraft:red_nether_bricks)
B(2,0,-6,minecraft:red_nether_bricks)
B(2,1,-6,minecraft:red_nether_bricks)
B(2,2,-6,minecraft:red_nether_bricks)
B(2,3,-6,minecraft:red_nether_bricks)
B(2,4,-6,minecraft:red_nether_bricks)
B(2,5,-6,minecraft:red_nether_bricks)
B(2,6,-6,minecraft:red_nether_bricks)
B(2,7,-6,minecraft:red_nether_bricks)
B(2,8,-6,minecraft:red_nether_bricks)
B(2,9,-6,minecraft:red_nether_bricks)
B(2,10,-6,minecraft:red_nether_bricks)
B(2,11,-6,minecraft:red_nether_bricks)
B(2,20,-6,minecraft:red_nether_bricks)
B(2,0,-5,minecraft:red_nether_bricks)
B(2,1,-5,minecraft:red_nether_bricks)
B(2,2,-5,minecraft:red_nether_bricks)
B(2,3,-5,minecraft:red_nether_bricks)
B(2,4,-5,minecraft:red_nether_bricks)
B(2,5,-5,minecraft:red_nether_bricks)
B(2,6,-5,minecraft:red_nether_bricks)
B(2,7,-5,minecraft:red_nether_bricks)
B(2,8,-5,minecraft:red_nether_bricks)
B(2,9,-5,minecraft:red_nether_bricks)
B(2,10,-5,minecraft:red_nether_bricks)
B(2,11,-5,minecraft:red_nether_bricks)
B(2,12,-5,minecraft:red_nether_bricks)
B(2,13,-5,minecraft:red_nether_bricks)
B(2,14,-5,minecraft:red_nether_bricks)
B(2,15,-5,minecraft:red_nether_bricks)
B(2,16,-5,minecraft:red_nether_bricks)
B(2,17,-5,minecraft:red_nether_bricks)
B(2,18,-5,minecraft:red_nether_bricks)
B(2,19,-5,minecraft:red_nether_bricks)
B(2,20,-5,minecraft:red_nether_bricks)
B(2,21,-5,minecraft:red_nether_bricks)
B(2,0,-4,minecraft:red_nether_bricks)
B(2,1,-4,minecraft:red_nether_bricks)
B(2,2,-4,minecraft:red_nether_bricks)
B(2,3,-4,minecraft:red_nether_bricks)
B(2,4,-4,minecraft:red_nether_bricks)
B(2,5,-4,minecraft:red_nether_bricks)
B(2,6,-4,minecraft:red_nether_bricks)
B(2,7,-4,minecraft:red_nether_bricks)
B(2,8,-4,minecraft:red_nether_bricks)
B(2,9,-4,minecraft:red_nether_bricks)
B(2,10,-4,minecraft:red_nether_bricks)
B(2,11,-4,minecraft:red_nether_bricks)
B(2,12,-4,minecraft:red_nether_bricks)
B(2,22,-4,minecraft:red_nether_bricks)
B(2,0,-3,minecraft:red_nether_bricks)
B(2,11,-3,minecraft:red_nether_bricks)
B(2,12,-3,minecraft:red_nether_bricks)
B(2,23,-3,minecraft:red_nether_bricks)
B(2,10,-2,minecraft:red_nether_bricks)
B(2,11,-2,minecraft:red_nether_bricks)
B(2,12,-2,minecraft:red_nether_bricks)
B(2,23,-2,minecraft:red_nether_bricks)
B(2,29,-2,minecraft:red_nether_bricks)
B(2,30,-2,minecraft:red_nether_bricks)
B(2,31,-2,minecraft:red_nether_bricks)
B(2,32,-2,minecraft:red_nether_bricks)
B(2,33,-2,minecraft:red_nether_bricks)
B(2,34,-2,minecraft:red_nether_bricks)
B(2,35,-2,minecraft:red_nether_bricks)
B(2,9,-1,minecraft:red_nether_bricks)
B(2,10,-1,minecraft:red_nether_bricks)
B(2,11,-1,minecraft:red_nether_bricks)
B(2,12,-1,minecraft:red_nether_bricks)
B(2,24,-1,minecraft:red_nether_bricks)
B(2,28,-1,minecraft:red_nether_bricks)
B(2,36,-1,minecraft:red_nether_bricks)
B(2,9,0,minecraft:red_nether_bricks)
B(2,10,0,minecraft:red_nether_bricks)
B(2,11,0,minecraft:red_nether_bricks)
B(2,12,0,minecraft:red_nether_bricks)
B(2,24,0,minecraft:red_nether_bricks)
B(2,28,0,minecraft:red_nether_bricks)
B(2,36,0,minecraft:red_nether_bricks)
B(2,10,1,minecraft:red_nether_bricks)
B(2,11,1,minecraft:red_nether_bricks)
B(2,12,1,minecraft:red_nether_bricks)
B(2,23,1,minecraft:red_nether_bricks)
B(2,29,1,minecraft:red_nether_bricks)
B(2,30,1,minecraft:red_nether_bricks)
B(2,31,1,minecraft:red_nether_bricks)
B(2,32,1,minecraft:red_nether_bricks)
B(2,33,1,minecraft:red_nether_bricks)
B(2,34,1,minecraft:red_nether_bricks)
B(2,35,1,minecraft:red_nether_bricks)
B(2,37,1,minecraft:nether_wart_block)
B(2,0,2,minecraft:red_nether_bricks)
B(2,11,2,minecraft:red_nether_bricks)
B(2,12,2,minecraft:red_nether_bricks)
B(2,23,2,minecraft:red_nether_bricks)
B(2,0,3,minecraft:red_nether_bricks)
B(2,1,3,minecraft:red_nether_bricks)
B(2,2,3,minecraft:red_nether_bricks)
B(2,3,3,minecraft:red_nether_bricks)
B(2,4,3,minecraft:red_nether_bricks)
B(2,5,3,minecraft:red_nether_bricks)
B(2,6,3,minecraft:red_nether_bricks)
B(2,7,3,minecraft:red_nether_bricks)
B(2,8,3,minecraft:red_nether_bricks)
B(2,9,3,minecraft:red_nether_bricks)
B(2,10,3,minecraft:red_nether_bricks)
B(2,11,3,minecraft:red_nether_bricks)
B(2,12,3,minecraft:red_nether_bricks)
B(2,22,3,minecraft:red_nether_bricks)
B(2,0,4,minecraft:red_nether_bricks)
B(2,1,4,minecraft:red_nether_bricks)
B(2,2,4,minecraft:red_nether_bricks)
B(2,3,4,minecraft:red_nether_bricks)
B(2,4,4,minecraft:red_nether_bricks)
B(2,5,4,minecraft:red_nether_bricks)
B(2,6,4,minecraft:red_nether_bricks)
B(2,7,4,minecraft:red_nether_bricks)
B(2,8,4,minecraft:red_nether_bricks)
B(2,9,4,minecraft:red_nether_bricks)
B(2,10,4,minecraft:red_nether_bricks)
B(2,11,4,minecraft:red_nether_bricks)
B(2,12,4,minecraft:red_nether_bricks)
B(2,13,4,minecraft:red_nether_bricks)
B(2,14,4,minecraft:red_nether_bricks)
B(2,15,4,minecraft:red_nether_bricks)
B(2,16,4,minecraft:red_nether_bricks)
B(2,17,4,minecraft:red_nether_bricks)
B(2,18,4,minecraft:red_nether_bricks)
B(2,19,4,minecraft:red_nether_bricks)
B(2,20,4,minecraft:red_nether_bricks)
B(2,21,4,minecraft:red_nether_bricks)
B(2,0,5,minecraft:red_nether_bricks)
B(2,1,5,minecraft:red_nether_bricks)
B(2,2,5,minecraft:red_nether_bricks)
B(2,3,5,minecraft:red_nether_bricks)
B(2,4,5,minecraft:red_nether_bricks)
B(2,5,5,minecraft:red_nether_bricks)
B(2,6,5,minecraft:red_nether_bricks)
B(2,7,5,minecraft:red_nether_bricks)
B(2,8,5,minecraft:red_nether_bricks)
B(2,9,5,minecraft:red_nether_bricks)
B(2,10,5,minecraft:red_nether_bricks)
B(2,11,5,minecraft:red_nether_bricks)
B(2,20,5,minecraft:red_nether_bricks)
B(2,0,6,minecraft:red_nether_bricks)
B(2,20,6,minecraft:red_nether_bricks)
B(2,19,7,minecraft:red_nether_bricks)
B(3,0,-6,minecraft:red_nether_bricks)
B(3,7,-6,minecraft:red_nether_bricks)
B(3,8,-6,minecraft:red_nether_bricks)
B(3,9,-6,minecraft:red_nether_bricks)
B(3,10,-6,minecraft:red_nether_bricks)
B(3,11,-6,minecraft:red_nether_bricks)
B(3,1,-5,minecraft:red_nether_bricks)
B(3,7,-5,minecraft:red_nether_bricks)
B(3,8,-5,minecraft:red_nether_bricks)
B(3,9,-5,minecraft:red_nether_bricks)
B(3,10,-5,minecraft:red_nether_bricks)
B(3,11,-5,minecraft:red_nether_bricks)
B(3,0,-4,minecraft:red_nether_bricks)
B(3,7,-4,minecraft:red_nether_bricks)
B(3,8,-4,minecraft:red_nether_bricks)
B(3,9,-4,minecraft:red_nether_bricks)
B(3,10,-4,minecraft:red_nether_bricks)
B(3,11,-4,minecraft:red_nether_bricks)
B(3,12,-4,minecraft:red_nether_bricks)
B(3,13,-4,minecraft:red_nether_bricks)
B(3,14,-4,minecraft:red_nether_bricks)
B(3,15,-4,minecraft:red_nether_bricks)
B(3,16,-4,minecraft:red_nether_bricks)
B(3,17,-4,minecraft:red_nether_bricks)
B(3,18,-4,minecraft:red_nether_bricks)
B(3,19,-4,minecraft:red_nether_bricks)
B(3,20,-4,minecraft:red_nether_bricks)
B(3,21,-4,minecraft:red_nether_bricks)
B(3,11,-3,minecraft:red_nether_bricks)
B(3,12,-3,minecraft:red_nether_bricks)
B(3,22,-3,minecraft:red_nether_bricks)
B(3,10,-2,minecraft:red_nether_bricks)
B(3,11,-2,minecraft:red_nether_bricks)
B(3,12,-2,minecraft:red_nether_bricks)
B(3,22,-2,minecraft:red_nether_bricks)
B(3,10,-1,minecraft:red_nether_bricks)
B(3,11,-1,minecraft:red_nether_bricks)
B(3,12,-1,minecraft:red_nether_bricks)
B(3,23,-1,minecraft:red_nether_bricks)
B(3,29,-1,minecraft:red_nether_bricks)
B(3,30,-1,minecraft:red_nether_bricks)
B(3,31,-1,minecraft:red_nether_bricks)
B(3,32,-1,minecraft:red_nether_bricks)
B(3,33,-1,minecraft:red_nether_bricks)
B(3,34,-1,minecraft:red_nether_bricks)
B(3,35,-1,minecraft:red_nether_bricks)
B(3,10,0,minecraft:red_nether_bricks)
B(3,11,0,minecraft:red_nether_bricks)
B(3,12,0,minecraft:red_nether_bricks)
B(3,23,0,minecraft:red_nether_bricks)
B(3,29,0,minecraft:red_nether_bricks)
B(3,30,0,minecraft:red_nether_bricks)
B(3,31,0,minecraft:red_nether_bricks)
B(3,32,0,minecraft:red_nether_bricks)
B(3,33,0,minecraft:red_nether_bricks)
B(3,34,0,minecraft:red_nether_bricks)
B(3,35,0,minecraft:red_nether_bricks)
B(3,10,1,minecraft:red_nether_bricks)
B(3,11,1,minecraft:red_nether_bricks)
B(3,12,1,minecraft:red_nether_bricks)
B(3,22,1,minecraft:red_nether_bricks)
B(3,36,1,minecraft:nether_wart_block)
B(3,37,1,minecraft:nether_wart_block)
B(3,11,2,minecraft:red_nether_bricks)
B(3,12,2,minecraft:red_nether_bricks)
B(3,22,2,minecraft:red_nether_bricks)
B(3,0,3,minecraft:red_nether_bricks)
B(3,7,3,minecraft:red_nether_bricks)
B(3,8,3,minecraft:red_nether_bricks)
B(3,9,3,minecraft:red_nether_bricks)
B(3,10,3,minecraft:red_nether_bricks)
B(3,11,3,minecraft:red_nether_bricks)
B(3,12,3,minecraft:red_nether_bricks)
B(3,13,3,minecraft:red_nether_bricks)
B(3,14,3,minecraft:red_nether_bricks)
B(3,15,3,minecraft:red_nether_bricks)
B(3,16,3,minecraft:red_nether_bricks)
B(3,17,3,minecraft:red_nether_bricks)
B(3,18,3,minecraft:red_nether_bricks)
B(3,19,3,minecraft:red_nether_bricks)
B(3,20,3,minecraft:red_nether_bricks)
B(3,21,3,minecraft:red_nether_bricks)
B(3,0,4,minecraft:red_nether_bricks)
B(3,1,4,minecraft:red_nether_bricks)
B(3,7,4,minecraft:red_nether_bricks)
B(3,8,4,minecraft:red_nether_bricks)
B(3,9,4,minecraft:red_nether_bricks)
B(3,10,4,minecraft:red_nether_bricks)
B(3,11,4,minecraft:red_nether_bricks)
B(3,0,5,minecraft:red_nether_bricks)
B(3,7,5,minecraft:red_nether_bricks)
B(3,8,5,minecraft:red_nether_bricks)
B(3,9,5,minecraft:red_nether_bricks)
B(3,10,5,minecraft:red_nether_bricks)
B(3,11,5,minecraft:red_nether_bricks)
B(4,0,-5,minecraft:red_nether_bricks)
B(4,12,-3,minecraft:red_nether_bricks)
B(4,13,-3,minecraft:red_nether_bricks)
B(4,14,-3,minecraft:red_nether_bricks)
B(4,15,-3,minecraft:red_nether_bricks)
B(4,16,-3,minecraft:red_nether_bricks)
B(4,17,-3,minecraft:red_nether_bricks)
B(4,18,-3,minecraft:red_nether_bricks)
B(4,19,-3,minecraft:red_nether_bricks)
B(4,20,-3,minecraft:red_nether_bricks)
B(4,21,-3,minecraft:red_nether_bricks)
B(4,12,-2,minecraft:red_nether_bricks)
B(4,13,-2,minecraft:red_nether_bricks)
B(4,14,-2,minecraft:red_nether_bricks)
B(4,15,-2,minecraft:red_nether_bricks)
B(4,16,-2,minecraft:red_nether_bricks)
B(4,17,-2,minecraft:red_nether_bricks)
B(4,18,-2,minecraft:red_nether_bricks)
B(4,19,-2,minecraft:red_nether_bricks)
B(4,20,-2,minecraft:red_nether_bricks)
B(4,21,-2,minecraft:red_nether_bricks)
B(4,11,-1,minecraft:red_nether_bricks)
B(4,12,-1,minecraft:red_nether_bricks)
B(4,22,-1,minecraft:red_nether_bricks)
B(4,11,0,minecraft:red_nether_bricks)
B(4,12,0,minecraft:red_nether_bricks)
B(4,22,0,minecraft:red_nether_bricks)
B(4,12,1,minecraft:red_nether_bricks)
B(4,13,1,minecraft:red_nether_bricks)
B(4,14,1,minecraft:red_nether_bricks)
B(4,15,1,minecraft:red_nether_bricks)
B(4,16,1,minecraft:red_nether_bricks)
B(4,17,1,minecraft:red_nether_bricks)
B(4,18,1,minecraft:red_nether_bricks)
B(4,19,1,minecraft:red_nether_bricks)
B(4,20,1,minecraft:red_nether_bricks)
B(4,21,1,minecraft:red_nether_bricks)
B(4,36,1,minecraft:nether_wart_block)
B(4,12,2,minecraft:red_nether_bricks)
B(4,13,2,minecraft:red_nether_bricks)
B(4,14,2,minecraft:red_nether_bricks)
B(4,15,2,minecraft:red_nether_bricks)
B(4,16,2,minecraft:red_nether_bricks)
B(4,17,2,minecraft:red_nether_bricks)
B(4,18,2,minecraft:red_nether_bricks)
B(4,19,2,minecraft:red_nether_bricks)
B(4,20,2,minecraft:red_nether_bricks)
B(4,21,2,minecraft:red_nether_bricks)
B(4,35,2,minecraft:nether_wart_block)
B(4,36,2,minecraft:nether_wart_block)
B(4,35,3,minecraft:nether_wart_block)
B(4,0,4,minecraft:red_nether_bricks)
B(5,16,-3,minecraft:nether_wart_block)
B(5,17,-3,minecraft:nether_wart_block)
B(5,12,-1,minecraft:red_nether_bricks)
B(5,13,-1,minecraft:red_nether_bricks)
B(5,14,-1,minecraft:red_nether_bricks)
B(5,15,-1,minecraft:red_nether_bricks)
B(5,16,-1,minecraft:red_nether_bricks)
B(5,17,-1,minecraft:red_nether_bricks)
B(5,18,-1,minecraft:red_nether_bricks)
B(5,19,-1,minecraft:red_nether_bricks)
B(5,20,-1,minecraft:red_nether_bricks)
B(5,21,-1,minecraft:red_nether_bricks)
B(5,12,0,minecraft:red_nether_bricks)
B(5,13,0,minecraft:red_nether_bricks)
B(5,14,0,minecraft:red_nether_bricks)
B(5,15,0,minecraft:red_nether_bricks)
B(5,16,0,minecraft:red_nether_bricks)
B(5,17,0,minecraft:red_nether_bricks)
B(5,18,0,minecraft:red_nether_bricks)
B(5,19,0,minecraft:red_nether_bricks)
B(5,20,0,minecraft:red_nether_bricks)
B(5,21,0,minecraft:red_nether_bricks)
B(5,16,2,minecraft:nether_wart_block)
B(5,17,2,minecraft:nether_wart_block)
B(6,14,-5,minecraft:nether_wart_block)
B(6,15,-5,minecraft:nether_wart_block)
B(6,16,-5,minecraft:nether_wart_block)
B(6,17,-5,minecraft:nether_wart_block)
B(6,18,-5,minecraft:nether_wart_block)
B(6,19,-5,minecraft:nether_wart_block)
B(6,15,-4,minecraft:nether_wart_block)
B(6,16,-4,minecraft:nether_wart_block)
B(6,17,-4,minecraft:nether_wart_block)
B(6,18,-4,minecraft:nether_wart_block)
B(6,15,3,minecraft:nether_wart_block)
B(6,16,3,minecraft:nether_wart_block)
B(6,17,3,minecraft:nether_wart_block)
B(6,18,3,minecraft:nether_wart_block)
B(6,14,4,minecraft:nether_wart_block)
B(6,15,4,minecraft:nether_wart_block)
B(6,16,4,minecraft:nether_wart_block)
B(6,17,4,minecraft:nether_wart_block)
B(6,18,4,minecraft:nether_wart_block)
B(6,19,4,minecraft:nether_wart_block)
B(7,13,-7,minecraft:nether_wart_block)
B(7,14,-7,minecraft:nether_wart_block)
B(7,15,-7,minecraft:nether_wart_block)
B(7,16,-7,minecraft:nether_wart_block)
B(7,17,-7,minecraft:nether_wart_block)
B(7,18,-7,minecraft:nether_wart_block)
B(7,19,-7,minecraft:nether_wart_block)
B(7,20,-7,minecraft:nether_wart_block)
B(7,14,-6,minecraft:nether_wart_block)
B(7,15,-6,minecraft:nether_wart_block)
B(7,16,-6,minecraft:nether_wart_block)
B(7,17,-6,minecraft:nether_wart_block)
B(7,18,-6,minecraft:nether_wart_block)
B(7,19,-6,minecraft:nether_wart_block)
B(7,20,-6,minecraft:nether_wart_block)
B(7,14,5,minecraft:nether_wart_block)
B(7,15,5,minecraft:nether_wart_block)
B(7,16,5,minecraft:nether_wart_block)
B(7,17,5,minecraft:nether_wart_block)
B(7,18,5,minecraft:nether_wart_block)
B(7,19,5,minecraft:nether_wart_block)
B(7,20,5,minecraft:nether_wart_block)
B(7,13,6,minecraft:nether_wart_block)
B(7,14,6,minecraft:nether_wart_block)
B(7,15,6,minecraft:nether_wart_block)
B(7,16,6,minecraft:nether_wart_block)
B(7,17,6,minecraft:nether_wart_block)
B(7,18,6,minecraft:nether_wart_block)
B(7,19,6,minecraft:nether_wart_block)
B(7,20,6,minecraft:nether_wart_block)
B(8,11,-10,minecraft:nether_wart_block)
B(8,13,-10,minecraft:nether_wart_block)
B(8,15,-10,minecraft:nether_wart_block)
B(8,17,-10,minecraft:nether_wart_block)
B(8,19,-10,minecraft:nether_wart_block)
B(8,21,-10,minecraft:nether_wart_block)
B(8,22,-10,minecraft:nether_wart_block)
B(8,12,-9,minecraft:nether_wart_block)
B(8,13,-9,minecraft:nether_wart_block)
B(8,14,-9,minecraft:nether_wart_block)
B(8,15,-9,minecraft:nether_wart_block)
B(8,16,-9,minecraft:nether_wart_block)
B(8,17,-9,minecraft:nether_wart_block)
B(8,18,-9,minecraft:nether_wart_block)
B(8,19,-9,minecraft:nether_wart_block)
B(8,20,-9,minecraft:nether_wart_block)
B(8,21,-9,minecraft:nether_wart_block)
B(8,13,-8,minecraft:nether_wart_block)
B(8,14,-8,minecraft:nether_wart_block)
B(8,15,-8,minecraft:nether_wart_block)
B(8,16,-8,minecraft:nether_wart_block)
B(8,17,-8,minecraft:nether_wart_block)
B(8,18,-8,minecraft:nether_wart_block)
B(8,19,-8,minecraft:nether_wart_block)
B(8,20,-8,minecraft:nether_wart_block)
B(8,21,-8,minecraft:nether_wart_block)
B(8,13,7,minecraft:nether_wart_block)
B(8,14,7,minecraft:nether_wart_block)
B(8,15,7,minecraft:nether_wart_block)
B(8,16,7,minecraft:nether_wart_block)
B(8,17,7,minecraft:nether_wart_block)
B(8,18,7,minecraft:nether_wart_block)
B(8,19,7,minecraft:nether_wart_block)
B(8,20,7,minecraft:nether_wart_block)
B(8,21,7,minecraft:nether_wart_block)
B(8,12,8,minecraft:nether_wart_block)
B(8,13,8,minecraft:nether_wart_block)
B(8,14,8,minecraft:nether_wart_block)
B(8,15,8,minecraft:nether_wart_block)
B(8,16,8,minecraft:nether_wart_block)
B(8,17,8,minecraft:nether_wart_block)
B(8,18,8,minecraft:nether_wart_block)
B(8,19,8,minecraft:nether_wart_block)
B(8,20,8,minecraft:nether_wart_block)
B(8,21,8,minecraft:nether_wart_block)
B(8,11,9,minecraft:nether_wart_block)
B(8,13,9,minecraft:nether_wart_block)
B(8,15,9,minecraft:nether_wart_block)
B(8,17,9,minecraft:nether_wart_block)
B(8,19,9,minecraft:nether_wart_block)
B(8,21,9,minecraft:nether_wart_block)
B(8,22,9,minecraft:nether_wart_block)

#######################################################################
# +-----------------------------------------------------------------+ #
# |                            BO3 checks                           | #
# +-----------------------------------------------------------------+ #
#######################################################################

BlockCheckNot(0,-1,4,minecraft:air)
BlockCheckNot(0,-1,-4,minecraft:air)

#######################################################################
# +-----------------------------------------------------------------+ #
# |                             Branches                            | #
# +-----------------------------------------------------------------+ #
#######################################################################


#######################################################################
# +-----------------------------------------------------------------+ #
# |                             Entities                            | #
# +-----------------------------------------------------------------+ #
#######################################################################

