
#######################################################################
# +-----------------------------------------------------------------+ #
# |                            BO4 object                           | #
# +-----------------------------------------------------------------+ #
#######################################################################

Author: Unknown

Description: No description given

SettingsMode: WriteWithoutComments


#######################################################################
# +-----------------------------------------------------------------+ #
# |                          Main settings                          | #
# +-----------------------------------------------------------------+ #
#######################################################################

FixedRotation: 

Frequency: 0

SpawnHeight: highestBlock

UseCenterForHighestBlock: true

##############################
# Height Limits for the BO4. #
##############################

MinHeight: 0

MaxHeight: 255

InheritBO3: 

InheritBO3Rotation: NORTH

OverrideChildSettings: true

OverrideParentHeight: false

CanOverride: false

BranchFrequency: 0

BranchFrequencyGroup: 

MustBeBelowOther: false

MustBeInside: 

CannotBeInside: 

ReplacesBO3: 

MustBeInsideWorldBorders: false

CanSpawnOnWater: true

SpawnOnWaterOnly: false

SpawnUnderWater: false

SpawnAtWaterLevel: false

HeightOffset: 0

RemoveAir: true

ReplaceAbove: 

ReplaceBelow: 

ReplaceWithBiomeBlocks: true

ReplaceWithSurfaceBlock: GRASS

ReplaceWithGroundBlock: DIRT

ReplaceWithStoneBlock: STONE

SmoothRadius: 0

SmoothHeightOffset: 0

SmoothStartTop: false

SmoothStartWood: false

SmoothingSurfaceBlock: 

SmoothingGroundBlock: 

BO3Group: 

IsSpawnPoint: false

DoReplaceBlocks: true


#######################################################################
# +-----------------------------------------------------------------+ #
# |                              Blocks                             | #
# +-----------------------------------------------------------------+ #
#######################################################################

B(-8,0,-7,minecraft:blackstone)
B(-8,1,-7,minecraft:basalt)
B(-8,0,-6,minecraft:blackstone)
B(-8,1,-6,minecraft:basalt)
B(-8,0,-5,minecraft:blackstone)
B(-8,1,-5,minecraft:blackstone)
B(-8,2,-5,minecraft:basalt)
B(-8,0,-4,minecraft:blackstone)
B(-8,1,-4,minecraft:blackstone)
B(-8,2,-4,minecraft:basalt)
B(-8,0,-3,minecraft:blackstone)
B(-8,1,-3,minecraft:blackstone)
B(-8,2,-3,minecraft:basalt)
B(-8,0,-2,minecraft:blackstone)
B(-8,1,-2,minecraft:basalt)
B(-8,0,-1,minecraft:blackstone)
B(-8,1,-1,minecraft:basalt)
B(-8,0,0,minecraft:blackstone)
B(-8,1,0,minecraft:basalt)
B(-8,0,1,minecraft:basalt)
B(-7,0,-7,minecraft:blackstone)
B(-7,1,-7,minecraft:basalt)
B(-7,0,-6,minecraft:blackstone)
B(-7,1,-6,minecraft:basalt)
B(-7,0,-5,minecraft:blackstone)
B(-7,1,-5,minecraft:blackstone)
B(-7,2,-5,minecraft:basalt)
B(-7,0,-4,minecraft:blackstone)
B(-7,1,-4,minecraft:blackstone)
B(-7,2,-4,minecraft:basalt)
B(-7,0,-3,minecraft:blackstone)
B(-7,1,-3,minecraft:blackstone)
B(-7,2,-3,minecraft:basalt)
B(-7,0,-2,minecraft:blackstone)
B(-7,1,-2,minecraft:basalt)
B(-7,0,-1,minecraft:blackstone)
B(-7,1,-1,minecraft:basalt)
B(-7,0,0,minecraft:basalt)
B(-7,0,1,minecraft:basalt)
B(-6,0,-7,minecraft:blackstone)
B(-6,1,-7,minecraft:basalt)
B(-6,0,-6,minecraft:blackstone)
B(-6,1,-6,minecraft:blackstone)
B(-6,2,-6,minecraft:basalt)
B(-6,0,-5,minecraft:blackstone)
B(-6,1,-5,minecraft:blackstone)
B(-6,2,-5,minecraft:basalt)
B(-6,0,-4,minecraft:blackstone)
B(-6,1,-4,minecraft:blackstone)
B(-6,2,-4,minecraft:blackstone)
B(-6,3,-4,minecraft:basalt)
B(-6,0,-3,minecraft:blackstone)
B(-6,1,-3,minecraft:blackstone)
B(-6,2,-3,minecraft:basalt)
B(-6,0,-2,minecraft:blackstone)
B(-6,1,-2,minecraft:basalt)
B(-6,0,-1,minecraft:basalt)
B(-6,0,0,minecraft:basalt)
B(-5,0,-7,minecraft:blackstone)
B(-5,1,-7,minecraft:basalt)
B(-5,0,-6,minecraft:blackstone)
B(-5,1,-6,minecraft:blackstone)
B(-5,2,-6,minecraft:basalt)
B(-5,0,-5,minecraft:blackstone)
B(-5,1,-5,minecraft:blackstone)
B(-5,2,-5,minecraft:basalt)
B(-5,0,-4,minecraft:blackstone)
B(-5,1,-4,minecraft:blackstone)
B(-5,2,-4,minecraft:blackstone)
B(-5,3,-4,minecraft:basalt)
B(-5,0,-3,minecraft:blackstone)
B(-5,1,-3,minecraft:blackstone)
B(-5,2,-3,minecraft:basalt)
B(-5,0,-2,minecraft:blackstone)
B(-5,1,-2,minecraft:blackstone)
B(-5,2,-2,minecraft:basalt)
B(-5,0,-1,minecraft:blackstone)
B(-5,1,-1,minecraft:basalt)
B(-5,0,0,minecraft:blackstone)
B(-5,1,0,minecraft:basalt)
B(-5,0,1,minecraft:basalt)
B(-5,0,2,minecraft:basalt)
B(-4,0,-7,minecraft:blackstone)
B(-4,1,-7,minecraft:blackstone)
B(-4,2,-7,minecraft:basalt)
B(-4,0,-6,minecraft:blackstone)
B(-4,1,-6,minecraft:blackstone)
B(-4,2,-6,minecraft:basalt)
B(-4,0,-5,minecraft:blackstone)
B(-4,1,-5,minecraft:blackstone)
B(-4,2,-5,minecraft:blackstone)
B(-4,3,-5,minecraft:basalt)
B(-4,0,-4,minecraft:blackstone)
B(-4,1,-4,minecraft:blackstone)
B(-4,2,-4,minecraft:blackstone)
B(-4,3,-4,minecraft:basalt)
B(-4,0,-3,minecraft:blackstone)
B(-4,1,-3,minecraft:blackstone)
B(-4,2,-3,minecraft:blackstone)
B(-4,3,-3,minecraft:basalt)
B(-4,0,-2,minecraft:blackstone)
B(-4,1,-2,minecraft:blackstone)
B(-4,2,-2,minecraft:blackstone)
B(-4,3,-2,minecraft:basalt)
B(-4,0,-1,minecraft:blackstone)
B(-4,1,-1,minecraft:blackstone)
B(-4,2,-1,minecraft:basalt)
B(-4,0,0,minecraft:blackstone)
B(-4,1,0,minecraft:blackstone)
B(-4,2,0,minecraft:basalt)
B(-4,0,1,minecraft:blackstone)
B(-4,1,1,minecraft:basalt)
B(-4,0,2,minecraft:basalt)
B(-4,0,8,minecraft:basalt)
B(-3,0,-7,minecraft:blackstone)
B(-3,1,-7,minecraft:blackstone)
B(-3,2,-7,minecraft:basalt)
B(-3,0,-6,minecraft:blackstone)
B(-3,1,-6,minecraft:blackstone)
B(-3,2,-6,minecraft:blackstone)
B(-3,3,-6,minecraft:basalt)
B(-3,0,-5,minecraft:blackstone)
B(-3,1,-5,minecraft:blackstone)
B(-3,2,-5,minecraft:blackstone)
B(-3,3,-5,minecraft:basalt)
B(-3,0,-4,minecraft:blackstone)
B(-3,1,-4,minecraft:blackstone)
B(-3,2,-4,minecraft:blackstone)
B(-3,3,-4,minecraft:basalt)
B(-3,0,-3,minecraft:blackstone)
B(-3,1,-3,minecraft:blackstone)
B(-3,2,-3,minecraft:blackstone)
B(-3,3,-3,minecraft:basalt)
B(-3,0,-2,minecraft:blackstone)
B(-3,1,-2,minecraft:blackstone)
B(-3,2,-2,minecraft:blackstone)
B(-3,3,-2,minecraft:basalt)
B(-3,0,-1,minecraft:blackstone)
B(-3,1,-1,minecraft:blackstone)
B(-3,2,-1,minecraft:blackstone)
B(-3,3,-1,minecraft:basalt)
B(-3,0,0,minecraft:blackstone)
B(-3,1,0,minecraft:blackstone)
B(-3,2,0,minecraft:blackstone)
B(-3,3,0,minecraft:basalt)
B(-3,0,1,minecraft:blackstone)
B(-3,1,1,minecraft:blackstone)
B(-3,2,1,minecraft:basalt)
B(-3,0,2,minecraft:blackstone)
B(-3,1,2,minecraft:basalt)
B(-3,0,3,minecraft:basalt)
B(-3,0,7,minecraft:basalt)
B(-3,1,7,minecraft:basalt)
B(-3,0,8,minecraft:basalt)
B(-3,1,8,minecraft:basalt)
B(-3,2,8,minecraft:basalt)
B(-3,3,8,minecraft:basalt)
B(-3,4,8,minecraft:basalt)
B(-3,5,8,minecraft:basalt)
B(-2,0,-7,minecraft:blackstone)
B(-2,1,-7,minecraft:blackstone)
B(-2,2,-7,minecraft:blackstone)
B(-2,3,-7,minecraft:basalt)
B(-2,0,-6,minecraft:blackstone)
B(-2,1,-6,minecraft:blackstone)
B(-2,2,-6,minecraft:blackstone)
B(-2,3,-6,minecraft:basalt)
B(-2,0,-5,minecraft:blackstone)
B(-2,1,-5,minecraft:blackstone)
B(-2,2,-5,minecraft:blackstone)
B(-2,3,-5,minecraft:basalt)
B(-2,0,-4,minecraft:blackstone)
B(-2,1,-4,minecraft:blackstone)
B(-2,2,-4,minecraft:blackstone)
B(-2,3,-4,minecraft:basalt)
B(-2,0,-3,minecraft:blackstone)
B(-2,1,-3,minecraft:blackstone)
B(-2,2,-3,minecraft:blackstone)
B(-2,3,-3,minecraft:basalt)
B(-2,0,-2,minecraft:blackstone)
B(-2,1,-2,minecraft:blackstone)
B(-2,2,-2,minecraft:blackstone)
B(-2,3,-2,minecraft:basalt)
B(-2,4,-2,minecraft:basalt)
B(-2,5,-2,minecraft:basalt)
B(-2,6,-2,minecraft:basalt)
B(-2,0,-1,minecraft:blackstone)
B(-2,1,-1,minecraft:blackstone)
B(-2,2,-1,minecraft:blackstone)
B(-2,3,-1,minecraft:basalt)
B(-2,4,-1,minecraft:basalt)
B(-2,5,-1,minecraft:basalt)
B(-2,6,-1,minecraft:basalt)
B(-2,7,-1,minecraft:basalt)
B(-2,8,-1,minecraft:basalt)
B(-2,0,0,minecraft:blackstone)
B(-2,1,0,minecraft:blackstone)
B(-2,2,0,minecraft:blackstone)
B(-2,3,0,minecraft:basalt)
B(-2,4,0,minecraft:basalt)
B(-2,5,0,minecraft:basalt)
B(-2,6,0,minecraft:basalt)
B(-2,7,0,minecraft:basalt)
B(-2,8,0,minecraft:basalt)
B(-2,0,1,minecraft:blackstone)
B(-2,1,1,minecraft:blackstone)
B(-2,2,1,minecraft:blackstone)
B(-2,3,1,minecraft:basalt)
B(-2,4,1,minecraft:basalt)
B(-2,5,1,minecraft:basalt)
B(-2,6,1,minecraft:basalt)
B(-2,7,1,minecraft:basalt)
B(-2,8,1,minecraft:basalt)
B(-2,0,2,minecraft:blackstone)
B(-2,1,2,minecraft:blackstone)
B(-2,2,2,minecraft:basalt)
B(-2,3,2,minecraft:basalt)
B(-2,4,2,minecraft:basalt)
B(-2,5,2,minecraft:basalt)
B(-2,0,3,minecraft:basalt)
B(-2,0,6,minecraft:basalt)
B(-2,1,6,minecraft:basalt)
B(-2,0,7,minecraft:basalt)
B(-2,1,7,minecraft:basalt)
B(-2,2,7,minecraft:basalt)
B(-2,3,7,minecraft:basalt)
B(-2,4,7,minecraft:basalt)
B(-2,5,7,minecraft:basalt)
B(-2,6,7,minecraft:basalt)
B(-2,7,7,minecraft:basalt)
B(-2,8,7,minecraft:basalt)
B(-2,9,7,minecraft:basalt)
B(-2,10,7,minecraft:basalt)
B(-2,0,8,minecraft:basalt)
B(-2,1,8,minecraft:basalt)
B(-2,2,8,minecraft:basalt)
B(-2,3,8,minecraft:basalt)
B(-2,4,8,minecraft:basalt)
B(-2,5,8,minecraft:basalt)
B(-2,6,8,minecraft:basalt)
B(-2,7,8,minecraft:basalt)
B(-2,8,8,minecraft:basalt)
B(-2,9,8,minecraft:basalt)
B(-2,10,8,minecraft:basalt)
B(-2,11,8,minecraft:basalt)
B(-2,12,8,minecraft:basalt)
B(-2,13,8,minecraft:basalt)
B(-2,14,8,minecraft:basalt)
B(-2,15,8,minecraft:basalt)
B(-2,16,8,minecraft:basalt)
B(-2,17,8,minecraft:basalt)
B(-2,18,8,minecraft:basalt)
B(-2,19,8,minecraft:basalt)
B(-2,20,8,minecraft:basalt)
B(-2,21,8,minecraft:basalt)
B(-2,22,8,minecraft:basalt)
B(-2,23,8,minecraft:basalt)
B(-2,24,8,minecraft:basalt)
B(-2,25,8,minecraft:basalt)
B(-2,26,8,minecraft:basalt)
B(-1,0,-7,minecraft:blackstone)
B(-1,1,-7,minecraft:blackstone)
B(-1,2,-7,minecraft:blackstone)
B(-1,3,-7,minecraft:basalt)
B(-1,0,-6,minecraft:blackstone)
B(-1,1,-6,minecraft:blackstone)
B(-1,2,-6,minecraft:blackstone)
B(-1,3,-6,minecraft:basalt)
B(-1,0,-5,minecraft:blackstone)
B(-1,1,-5,minecraft:blackstone)
B(-1,2,-5,minecraft:blackstone)
B(-1,3,-5,minecraft:basalt)
B(-1,0,-4,minecraft:blackstone)
B(-1,1,-4,minecraft:blackstone)
B(-1,2,-4,minecraft:blackstone)
B(-1,3,-4,minecraft:basalt)
B(-1,0,-3,minecraft:blackstone)
B(-1,1,-3,minecraft:blackstone)
B(-1,2,-3,minecraft:blackstone)
B(-1,3,-3,minecraft:basalt)
B(-1,4,-3,minecraft:basalt)
B(-1,5,-3,minecraft:basalt)
B(-1,6,-3,minecraft:basalt)
B(-1,7,-3,minecraft:basalt)
B(-1,8,-3,minecraft:basalt)
B(-1,0,-2,minecraft:blackstone)
B(-1,1,-2,minecraft:blackstone)
B(-1,2,-2,minecraft:blackstone)
B(-1,3,-2,minecraft:basalt)
B(-1,4,-2,minecraft:basalt)
B(-1,5,-2,minecraft:basalt)
B(-1,6,-2,minecraft:basalt)
B(-1,7,-2,minecraft:basalt)
B(-1,8,-2,minecraft:basalt)
B(-1,9,-2,minecraft:basalt)
B(-1,10,-2,minecraft:basalt)
B(-1,0,-1,minecraft:blackstone)
B(-1,1,-1,minecraft:blackstone)
B(-1,2,-1,minecraft:blackstone)
B(-1,3,-1,minecraft:basalt)
B(-1,4,-1,minecraft:basalt)
B(-1,5,-1,minecraft:basalt)
B(-1,6,-1,minecraft:basalt)
B(-1,7,-1,minecraft:basalt)
B(-1,8,-1,minecraft:basalt)
B(-1,9,-1,minecraft:basalt)
B(-1,10,-1,minecraft:basalt)
B(-1,0,0,minecraft:blackstone)
B(-1,1,0,minecraft:blackstone)
B(-1,2,0,minecraft:blackstone)
B(-1,3,0,minecraft:basalt)
B(-1,4,0,minecraft:basalt)
B(-1,5,0,minecraft:basalt)
B(-1,6,0,minecraft:basalt)
B(-1,7,0,minecraft:basalt)
B(-1,8,0,minecraft:basalt)
B(-1,9,0,minecraft:basalt)
B(-1,10,0,minecraft:basalt)
B(-1,0,1,minecraft:blackstone)
B(-1,1,1,minecraft:blackstone)
B(-1,2,1,minecraft:blackstone)
B(-1,3,1,minecraft:basalt)
B(-1,4,1,minecraft:basalt)
B(-1,5,1,minecraft:basalt)
B(-1,6,1,minecraft:basalt)
B(-1,7,1,minecraft:basalt)
B(-1,8,1,minecraft:basalt)
B(-1,9,1,minecraft:basalt)
B(-1,10,1,minecraft:basalt)
B(-1,0,2,minecraft:blackstone)
B(-1,1,2,minecraft:blackstone)
B(-1,2,2,minecraft:basalt)
B(-1,3,2,minecraft:basalt)
B(-1,4,2,minecraft:basalt)
B(-1,5,2,minecraft:basalt)
B(-1,6,2,minecraft:basalt)
B(-1,7,2,minecraft:basalt)
B(-1,8,2,minecraft:basalt)
B(-1,9,2,minecraft:basalt)
B(-1,0,3,minecraft:blackstone)
B(-1,1,3,minecraft:basalt)
B(-1,2,3,minecraft:basalt)
B(-1,3,3,minecraft:basalt)
B(-1,4,3,minecraft:basalt)
B(-1,5,3,minecraft:basalt)
B(-1,6,3,minecraft:basalt)
B(-1,7,3,minecraft:basalt)
B(-1,8,3,minecraft:basalt)
B(-1,9,3,minecraft:basalt)
B(-1,10,3,minecraft:basalt)
B(-1,11,3,minecraft:basalt)
B(-1,12,3,minecraft:basalt)
B(-1,13,3,minecraft:basalt)
B(-1,14,3,minecraft:basalt)
B(-1,15,3,minecraft:basalt)
B(-1,16,3,minecraft:basalt)
B(-1,17,3,minecraft:basalt)
B(-1,18,3,minecraft:basalt)
B(-1,0,4,minecraft:basalt)
B(-1,1,4,minecraft:basalt)
B(-1,2,4,minecraft:basalt)
B(-1,3,4,minecraft:basalt)
B(-1,4,4,minecraft:basalt)
B(-1,5,4,minecraft:basalt)
B(-1,6,4,minecraft:basalt)
B(-1,7,4,minecraft:basalt)
B(-1,8,4,minecraft:basalt)
B(-1,9,4,minecraft:basalt)
B(-1,10,4,minecraft:basalt)
B(-1,11,4,minecraft:basalt)
B(-1,12,4,minecraft:basalt)
B(-1,13,4,minecraft:basalt)
B(-1,14,4,minecraft:basalt)
B(-1,15,4,minecraft:basalt)
B(-1,16,4,minecraft:basalt)
B(-1,17,4,minecraft:basalt)
B(-1,18,4,minecraft:basalt)
B(-1,19,4,minecraft:basalt)
B(-1,20,4,minecraft:basalt)
B(-1,21,4,minecraft:basalt)
B(-1,22,4,minecraft:basalt)
B(-1,23,4,minecraft:basalt)
B(-1,0,5,minecraft:basalt)
B(-1,1,5,minecraft:basalt)
B(-1,2,5,minecraft:basalt)
B(-1,3,5,minecraft:basalt)
B(-1,4,5,minecraft:basalt)
B(-1,5,5,minecraft:basalt)
B(-1,6,5,minecraft:basalt)
B(-1,7,5,minecraft:basalt)
B(-1,8,5,minecraft:basalt)
B(-1,9,5,minecraft:basalt)
B(-1,10,5,minecraft:basalt)
B(-1,11,5,minecraft:basalt)
B(-1,12,5,minecraft:basalt)
B(-1,13,5,minecraft:basalt)
B(-1,14,5,minecraft:basalt)
B(-1,15,5,minecraft:basalt)
B(-1,16,5,minecraft:basalt)
B(-1,17,5,minecraft:basalt)
B(-1,18,5,minecraft:basalt)
B(-1,19,5,minecraft:basalt)
B(-1,20,5,minecraft:basalt)
B(-1,21,5,minecraft:basalt)
B(-1,22,5,minecraft:basalt)
B(-1,23,5,minecraft:basalt)
B(-1,24,5,minecraft:basalt)
B(-1,25,5,minecraft:basalt)
B(-1,0,6,minecraft:basalt)
B(-1,1,6,minecraft:basalt)
B(-1,2,6,minecraft:basalt)
B(-1,3,6,minecraft:basalt)
B(-1,4,6,minecraft:basalt)
B(-1,5,6,minecraft:basalt)
B(-1,6,6,minecraft:basalt)
B(-1,7,6,minecraft:basalt)
B(-1,8,6,minecraft:basalt)
B(-1,9,6,minecraft:basalt)
B(-1,10,6,minecraft:basalt)
B(-1,11,6,minecraft:basalt)
B(-1,12,6,minecraft:basalt)
B(-1,13,6,minecraft:basalt)
B(-1,14,6,minecraft:basalt)
B(-1,15,6,minecraft:basalt)
B(-1,16,6,minecraft:basalt)
B(-1,17,6,minecraft:basalt)
B(-1,18,6,minecraft:basalt)
B(-1,19,6,minecraft:basalt)
B(-1,20,6,minecraft:basalt)
B(-1,21,6,minecraft:basalt)
B(-1,22,6,minecraft:basalt)
B(-1,23,6,minecraft:basalt)
B(-1,24,6,minecraft:basalt)
B(-1,25,6,minecraft:basalt)
B(-1,26,6,minecraft:basalt)
B(-1,27,6,minecraft:basalt)
B(-1,28,6,minecraft:basalt)
B(-1,29,6,minecraft:basalt)
B(-1,30,6,minecraft:basalt)
B(-1,31,6,minecraft:basalt)
B(-1,32,6,minecraft:basalt)
B(-1,33,6,minecraft:basalt)
B(-1,34,6,minecraft:basalt)
B(-1,35,6,minecraft:basalt)
B(-1,36,6,minecraft:basalt)
B(-1,37,6,minecraft:basalt)
B(-1,0,7,minecraft:basalt)
B(-1,1,7,minecraft:basalt)
B(-1,2,7,minecraft:basalt)
B(-1,3,7,minecraft:basalt)
B(-1,4,7,minecraft:basalt)
B(-1,5,7,minecraft:basalt)
B(-1,6,7,minecraft:basalt)
B(-1,7,7,minecraft:basalt)
B(-1,8,7,minecraft:basalt)
B(-1,9,7,minecraft:basalt)
B(-1,10,7,minecraft:basalt)
B(-1,11,7,minecraft:basalt)
B(-1,12,7,minecraft:basalt)
B(-1,13,7,minecraft:basalt)
B(-1,14,7,minecraft:basalt)
B(-1,15,7,minecraft:basalt)
B(-1,16,7,minecraft:basalt)
B(-1,17,7,minecraft:basalt)
B(-1,18,7,minecraft:basalt)
B(-1,19,7,minecraft:basalt)
B(-1,20,7,minecraft:basalt)
B(-1,21,7,minecraft:basalt)
B(-1,22,7,minecraft:basalt)
B(-1,23,7,minecraft:basalt)
B(-1,24,7,minecraft:basalt)
B(-1,25,7,minecraft:basalt)
B(-1,26,7,minecraft:basalt)
B(-1,27,7,minecraft:basalt)
B(-1,28,7,minecraft:basalt)
B(-1,29,7,minecraft:basalt)
B(-1,30,7,minecraft:basalt)
B(-1,31,7,minecraft:basalt)
B(-1,32,7,minecraft:basalt)
B(-1,33,7,minecraft:basalt)
B(-1,34,7,minecraft:basalt)
B(-1,35,7,minecraft:basalt)
B(-1,36,7,minecraft:basalt)
B(-1,37,7,minecraft:basalt)
B(-1,38,7,minecraft:basalt)
B(-1,39,7,minecraft:basalt)
B(-1,40,7,minecraft:basalt)
B(-1,41,7,minecraft:basalt)
B(-1,42,7,minecraft:basalt)
B(-1,43,7,minecraft:basalt)
B(-1,44,7,minecraft:basalt)
B(-1,45,7,minecraft:basalt)
B(-1,46,7,minecraft:basalt)
B(-1,47,7,minecraft:basalt)
B(-1,0,8,minecraft:basalt)
B(-1,1,8,minecraft:basalt)
B(-1,2,8,minecraft:basalt)
B(-1,3,8,minecraft:basalt)
B(-1,4,8,minecraft:basalt)
B(-1,5,8,minecraft:basalt)
B(-1,6,8,minecraft:basalt)
B(-1,7,8,minecraft:basalt)
B(-1,8,8,minecraft:basalt)
B(-1,9,8,minecraft:basalt)
B(-1,10,8,minecraft:basalt)
B(-1,11,8,minecraft:basalt)
B(-1,12,8,minecraft:basalt)
B(-1,13,8,minecraft:basalt)
B(-1,14,8,minecraft:basalt)
B(-1,15,8,minecraft:basalt)
B(-1,16,8,minecraft:basalt)
B(-1,17,8,minecraft:basalt)
B(-1,18,8,minecraft:basalt)
B(-1,19,8,minecraft:basalt)
B(-1,20,8,minecraft:basalt)
B(-1,21,8,minecraft:basalt)
B(-1,22,8,minecraft:basalt)
B(-1,23,8,minecraft:basalt)
B(-1,24,8,minecraft:basalt)
B(-1,25,8,minecraft:basalt)
B(-1,26,8,minecraft:basalt)
B(-1,27,8,minecraft:basalt)
B(-1,28,8,minecraft:basalt)
B(-1,29,8,minecraft:basalt)
B(-1,30,8,minecraft:basalt)
B(-1,31,8,minecraft:basalt)
B(-1,32,8,minecraft:basalt)
B(-1,33,8,minecraft:basalt)
B(-1,34,8,minecraft:basalt)
B(-1,35,8,minecraft:basalt)
B(-1,36,8,minecraft:basalt)
B(-1,37,8,minecraft:basalt)
B(-1,38,8,minecraft:basalt)
B(-1,39,8,minecraft:basalt)
B(-1,40,8,minecraft:basalt)
B(-1,41,8,minecraft:basalt)
B(0,0,-7,minecraft:blackstone)
B(0,1,-7,minecraft:blackstone)
B(0,2,-7,minecraft:blackstone)
B(0,3,-7,minecraft:basalt)
B(0,4,-7,minecraft:basalt)
B(0,5,-7,minecraft:basalt)
B(0,6,-7,minecraft:basalt)
B(0,7,-7,minecraft:basalt)
B(0,8,-7,minecraft:basalt)
B(0,9,-7,minecraft:basalt)
B(0,10,-7,minecraft:basalt)
B(0,11,-7,minecraft:basalt)
B(0,12,-7,minecraft:basalt)
B(0,13,-7,minecraft:basalt)
B(0,14,-7,minecraft:basalt)
B(0,15,-7,minecraft:basalt)
B(0,16,-7,minecraft:basalt)
B(0,17,-7,minecraft:basalt)
B(0,18,-7,minecraft:basalt)
B(0,19,-7,minecraft:basalt)
B(0,0,-6,minecraft:blackstone)
B(0,1,-6,minecraft:blackstone)
B(0,2,-6,minecraft:basalt)
B(0,3,-6,minecraft:basalt)
B(0,4,-6,minecraft:basalt)
B(0,5,-6,minecraft:basalt)
B(0,6,-6,minecraft:basalt)
B(0,7,-6,minecraft:basalt)
B(0,8,-6,minecraft:basalt)
B(0,9,-6,minecraft:basalt)
B(0,10,-6,minecraft:basalt)
B(0,11,-6,minecraft:basalt)
B(0,12,-6,minecraft:basalt)
B(0,13,-6,minecraft:basalt)
B(0,14,-6,minecraft:basalt)
B(0,15,-6,minecraft:basalt)
B(0,16,-6,minecraft:basalt)
B(0,17,-6,minecraft:basalt)
B(0,18,-6,minecraft:basalt)
B(0,19,-6,minecraft:basalt)
B(0,20,-6,minecraft:basalt)
B(0,21,-6,minecraft:basalt)
B(0,22,-6,minecraft:basalt)
B(0,23,-6,minecraft:basalt)
B(0,24,-6,minecraft:basalt)
B(0,0,-5,minecraft:blackstone)
B(0,1,-5,minecraft:basalt)
B(0,2,-5,minecraft:basalt)
B(0,3,-5,minecraft:basalt)
B(0,4,-5,minecraft:basalt)
B(0,5,-5,minecraft:basalt)
B(0,6,-5,minecraft:basalt)
B(0,7,-5,minecraft:basalt)
B(0,8,-5,minecraft:basalt)
B(0,9,-5,minecraft:basalt)
B(0,10,-5,minecraft:basalt)
B(0,11,-5,minecraft:basalt)
B(0,12,-5,minecraft:basalt)
B(0,13,-5,minecraft:basalt)
B(0,14,-5,minecraft:basalt)
B(0,15,-5,minecraft:basalt)
B(0,16,-5,minecraft:basalt)
B(0,17,-5,minecraft:basalt)
B(0,18,-5,minecraft:basalt)
B(0,19,-5,minecraft:basalt)
B(0,20,-5,minecraft:basalt)
B(0,21,-5,minecraft:basalt)
B(0,22,-5,minecraft:basalt)
B(0,23,-5,minecraft:basalt)
B(0,24,-5,minecraft:basalt)
B(0,25,-5,minecraft:basalt)
B(0,0,-4,minecraft:blackstone)
B(0,1,-4,minecraft:basalt)
B(0,2,-4,minecraft:basalt)
B(0,3,-4,minecraft:basalt)
B(0,4,-4,minecraft:basalt)
B(0,5,-4,minecraft:basalt)
B(0,6,-4,minecraft:basalt)
B(0,7,-4,minecraft:basalt)
B(0,8,-4,minecraft:basalt)
B(0,9,-4,minecraft:basalt)
B(0,10,-4,minecraft:basalt)
B(0,11,-4,minecraft:basalt)
B(0,12,-4,minecraft:basalt)
B(0,13,-4,minecraft:basalt)
B(0,14,-4,minecraft:basalt)
B(0,15,-4,minecraft:basalt)
B(0,16,-4,minecraft:basalt)
B(0,17,-4,minecraft:basalt)
B(0,18,-4,minecraft:basalt)
B(0,19,-4,minecraft:basalt)
B(0,20,-4,minecraft:basalt)
B(0,21,-4,minecraft:basalt)
B(0,22,-4,minecraft:basalt)
B(0,23,-4,minecraft:basalt)
B(0,24,-4,minecraft:basalt)
B(0,25,-4,minecraft:basalt)
B(0,26,-4,minecraft:basalt)
B(0,0,-3,minecraft:blackstone)
B(0,1,-3,minecraft:basalt)
B(0,2,-3,minecraft:basalt)
B(0,3,-3,minecraft:basalt)
B(0,4,-3,minecraft:basalt)
B(0,5,-3,minecraft:basalt)
B(0,6,-3,minecraft:basalt)
B(0,7,-3,minecraft:basalt)
B(0,8,-3,minecraft:basalt)
B(0,9,-3,minecraft:basalt)
B(0,10,-3,minecraft:basalt)
B(0,11,-3,minecraft:basalt)
B(0,12,-3,minecraft:basalt)
B(0,13,-3,minecraft:basalt)
B(0,14,-3,minecraft:basalt)
B(0,15,-3,minecraft:basalt)
B(0,16,-3,minecraft:basalt)
B(0,17,-3,minecraft:basalt)
B(0,18,-3,minecraft:basalt)
B(0,0,-2,minecraft:blackstone)
B(0,1,-2,minecraft:blackstone)
B(0,2,-2,minecraft:basalt)
B(0,3,-2,minecraft:basalt)
B(0,4,-2,minecraft:basalt)
B(0,5,-2,minecraft:basalt)
B(0,6,-2,minecraft:basalt)
B(0,7,-2,minecraft:basalt)
B(0,8,-2,minecraft:basalt)
B(0,9,-2,minecraft:basalt)
B(0,10,-2,minecraft:basalt)
B(0,11,-2,minecraft:basalt)
B(0,12,-2,minecraft:basalt)
B(0,13,-2,minecraft:basalt)
B(0,0,-1,minecraft:blackstone)
B(0,1,-1,minecraft:blackstone)
B(0,2,-1,minecraft:blackstone)
B(0,3,-1,minecraft:basalt)
B(0,4,-1,minecraft:basalt)
B(0,5,-1,minecraft:basalt)
B(0,6,-1,minecraft:basalt)
B(0,7,-1,minecraft:basalt)
B(0,8,-1,minecraft:basalt)
B(0,9,-1,minecraft:basalt)
B(0,10,-1,minecraft:basalt)
B(0,11,-1,minecraft:basalt)
B(0,12,-1,minecraft:basalt)
B(0,0,0,minecraft:blackstone)
B(0,1,0,minecraft:blackstone)
B(0,2,0,minecraft:blackstone)
B(0,3,0,minecraft:basalt)
B(0,4,0,minecraft:basalt)
B(0,5,0,minecraft:basalt)
B(0,6,0,minecraft:basalt)
B(0,7,0,minecraft:basalt)
B(0,8,0,minecraft:basalt)
B(0,9,0,minecraft:basalt)
B(0,10,0,minecraft:basalt)
B(0,11,0,minecraft:basalt)
B(0,12,0,minecraft:basalt)
B(0,13,0,minecraft:basalt)
B(0,14,0,minecraft:basalt)
B(0,15,0,minecraft:basalt)
B(0,0,1,minecraft:blackstone)
B(0,1,1,minecraft:blackstone)
B(0,2,1,minecraft:blackstone)
B(0,3,1,minecraft:basalt)
B(0,4,1,minecraft:basalt)
B(0,5,1,minecraft:basalt)
B(0,6,1,minecraft:basalt)
B(0,7,1,minecraft:basalt)
B(0,8,1,minecraft:basalt)
B(0,9,1,minecraft:basalt)
B(0,10,1,minecraft:basalt)
B(0,11,1,minecraft:basalt)
B(0,12,1,minecraft:basalt)
B(0,13,1,minecraft:basalt)
B(0,14,1,minecraft:basalt)
B(0,15,1,minecraft:basalt)
B(0,16,1,minecraft:basalt)
B(0,17,1,minecraft:basalt)
B(0,18,1,minecraft:basalt)
B(0,0,2,minecraft:blackstone)
B(0,1,2,minecraft:blackstone)
B(0,2,2,minecraft:basalt)
B(0,3,2,minecraft:basalt)
B(0,4,2,minecraft:basalt)
B(0,5,2,minecraft:basalt)
B(0,6,2,minecraft:basalt)
B(0,7,2,minecraft:basalt)
B(0,8,2,minecraft:basalt)
B(0,9,2,minecraft:basalt)
B(0,10,2,minecraft:basalt)
B(0,11,2,minecraft:basalt)
B(0,12,2,minecraft:basalt)
B(0,13,2,minecraft:basalt)
B(0,14,2,minecraft:basalt)
B(0,15,2,minecraft:basalt)
B(0,16,2,minecraft:basalt)
B(0,17,2,minecraft:basalt)
B(0,18,2,minecraft:basalt)
B(0,19,2,minecraft:basalt)
B(0,20,2,minecraft:basalt)
B(0,21,2,minecraft:basalt)
B(0,22,2,minecraft:basalt)
B(0,23,2,minecraft:basalt)
B(0,24,2,minecraft:basalt)
B(0,25,2,minecraft:basalt)
B(0,26,2,minecraft:basalt)
B(0,27,2,minecraft:basalt)
B(0,28,2,minecraft:basalt)
B(0,29,2,minecraft:basalt)
B(0,30,2,minecraft:basalt)
B(0,31,2,minecraft:basalt)
B(0,32,2,minecraft:basalt)
B(0,33,2,minecraft:basalt)
B(0,34,2,minecraft:basalt)
B(0,35,2,minecraft:basalt)
B(0,36,2,minecraft:basalt)
B(0,37,2,minecraft:basalt)
B(0,38,2,minecraft:basalt)
B(0,39,2,minecraft:basalt)
B(0,0,3,minecraft:blackstone)
B(0,1,3,minecraft:basalt)
B(0,2,3,minecraft:basalt)
B(0,3,3,minecraft:basalt)
B(0,4,3,minecraft:basalt)
B(0,5,3,minecraft:basalt)
B(0,6,3,minecraft:basalt)
B(0,7,3,minecraft:basalt)
B(0,8,3,minecraft:basalt)
B(0,9,3,minecraft:basalt)
B(0,10,3,minecraft:basalt)
B(0,11,3,minecraft:basalt)
B(0,12,3,minecraft:basalt)
B(0,13,3,minecraft:basalt)
B(0,14,3,minecraft:basalt)
B(0,15,3,minecraft:basalt)
B(0,16,3,minecraft:basalt)
B(0,17,3,minecraft:basalt)
B(0,18,3,minecraft:basalt)
B(0,19,3,minecraft:basalt)
B(0,20,3,minecraft:basalt)
B(0,21,3,minecraft:basalt)
B(0,22,3,minecraft:basalt)
B(0,23,3,minecraft:basalt)
B(0,24,3,minecraft:basalt)
B(0,25,3,minecraft:basalt)
B(0,26,3,minecraft:basalt)
B(0,27,3,minecraft:basalt)
B(0,28,3,minecraft:basalt)
B(0,29,3,minecraft:basalt)
B(0,30,3,minecraft:basalt)
B(0,31,3,minecraft:basalt)
B(0,32,3,minecraft:basalt)
B(0,33,3,minecraft:basalt)
B(0,34,3,minecraft:basalt)
B(0,35,3,minecraft:basalt)
B(0,36,3,minecraft:basalt)
B(0,37,3,minecraft:basalt)
B(0,38,3,minecraft:basalt)
B(0,39,3,minecraft:basalt)
B(0,0,4,minecraft:blackstone)
B(0,1,4,minecraft:basalt)
B(0,2,4,minecraft:basalt)
B(0,3,4,minecraft:basalt)
B(0,4,4,minecraft:basalt)
B(0,5,4,minecraft:basalt)
B(0,6,4,minecraft:basalt)
B(0,7,4,minecraft:basalt)
B(0,8,4,minecraft:basalt)
B(0,9,4,minecraft:basalt)
B(0,10,4,minecraft:basalt)
B(0,11,4,minecraft:basalt)
B(0,12,4,minecraft:basalt)
B(0,13,4,minecraft:basalt)
B(0,14,4,minecraft:basalt)
B(0,15,4,minecraft:basalt)
B(0,16,4,minecraft:basalt)
B(0,17,4,minecraft:basalt)
B(0,18,4,minecraft:basalt)
B(0,19,4,minecraft:basalt)
B(0,20,4,minecraft:basalt)
B(0,21,4,minecraft:basalt)
B(0,22,4,minecraft:basalt)
B(0,23,4,minecraft:basalt)
B(0,24,4,minecraft:basalt)
B(0,25,4,minecraft:basalt)
B(0,26,4,minecraft:basalt)
B(0,27,4,minecraft:basalt)
B(0,28,4,minecraft:basalt)
B(0,29,4,minecraft:basalt)
B(0,30,4,minecraft:basalt)
B(0,31,4,minecraft:basalt)
B(0,32,4,minecraft:basalt)
B(0,33,4,minecraft:basalt)
B(0,34,4,minecraft:basalt)
B(0,35,4,minecraft:basalt)
B(0,36,4,minecraft:basalt)
B(0,37,4,minecraft:basalt)
B(0,38,4,minecraft:basalt)
B(0,0,5,minecraft:basalt)
B(0,1,5,minecraft:basalt)
B(0,2,5,minecraft:basalt)
B(0,3,5,minecraft:basalt)
B(0,4,5,minecraft:basalt)
B(0,5,5,minecraft:basalt)
B(0,6,5,minecraft:basalt)
B(0,7,5,minecraft:basalt)
B(0,8,5,minecraft:basalt)
B(0,9,5,minecraft:basalt)
B(0,10,5,minecraft:basalt)
B(0,11,5,minecraft:basalt)
B(0,12,5,minecraft:basalt)
B(0,13,5,minecraft:basalt)
B(0,14,5,minecraft:basalt)
B(0,15,5,minecraft:basalt)
B(0,16,5,minecraft:basalt)
B(0,17,5,minecraft:basalt)
B(0,18,5,minecraft:basalt)
B(0,19,5,minecraft:basalt)
B(0,20,5,minecraft:basalt)
B(0,21,5,minecraft:basalt)
B(0,22,5,minecraft:basalt)
B(0,23,5,minecraft:basalt)
B(0,24,5,minecraft:basalt)
B(0,25,5,minecraft:basalt)
B(0,26,5,minecraft:basalt)
B(0,27,5,minecraft:basalt)
B(0,28,5,minecraft:basalt)
B(0,29,5,minecraft:basalt)
B(0,30,5,minecraft:basalt)
B(0,31,5,minecraft:basalt)
B(0,32,5,minecraft:basalt)
B(0,33,5,minecraft:basalt)
B(0,34,5,minecraft:basalt)
B(0,35,5,minecraft:basalt)
B(0,36,5,minecraft:basalt)
B(0,37,5,minecraft:basalt)
B(0,38,5,minecraft:basalt)
B(0,39,5,minecraft:basalt)
B(0,0,6,minecraft:basalt)
B(0,1,6,minecraft:basalt)
B(0,2,6,minecraft:basalt)
B(0,3,6,minecraft:basalt)
B(0,4,6,minecraft:basalt)
B(0,5,6,minecraft:basalt)
B(0,6,6,minecraft:basalt)
B(0,7,6,minecraft:basalt)
B(0,8,6,minecraft:basalt)
B(0,9,6,minecraft:basalt)
B(0,10,6,minecraft:basalt)
B(0,11,6,minecraft:basalt)
B(0,12,6,minecraft:basalt)
B(0,13,6,minecraft:basalt)
B(0,14,6,minecraft:basalt)
B(0,15,6,minecraft:basalt)
B(0,16,6,minecraft:basalt)
B(0,17,6,minecraft:basalt)
B(0,18,6,minecraft:basalt)
B(0,19,6,minecraft:basalt)
B(0,20,6,minecraft:basalt)
B(0,21,6,minecraft:basalt)
B(0,22,6,minecraft:basalt)
B(0,23,6,minecraft:basalt)
B(0,24,6,minecraft:basalt)
B(0,25,6,minecraft:basalt)
B(0,26,6,minecraft:basalt)
B(0,27,6,minecraft:basalt)
B(0,28,6,minecraft:basalt)
B(0,29,6,minecraft:basalt)
B(0,30,6,minecraft:basalt)
B(0,31,6,minecraft:basalt)
B(0,32,6,minecraft:basalt)
B(0,33,6,minecraft:basalt)
B(0,34,6,minecraft:basalt)
B(0,35,6,minecraft:basalt)
B(0,36,6,minecraft:basalt)
B(0,37,6,minecraft:basalt)
B(0,38,6,minecraft:basalt)
B(0,39,6,minecraft:basalt)
B(0,40,6,minecraft:basalt)
B(0,41,6,minecraft:basalt)
B(0,42,6,minecraft:basalt)
B(0,43,6,minecraft:basalt)
B(0,44,6,minecraft:basalt)
B(0,45,6,minecraft:basalt)
B(0,46,6,minecraft:basalt)
B(0,47,6,minecraft:basalt)
B(0,48,6,minecraft:basalt)
B(0,49,6,minecraft:basalt)
B(0,50,6,minecraft:basalt)
B(0,51,6,minecraft:basalt)
B(0,0,7,minecraft:basalt)
B(0,1,7,minecraft:basalt)
B(0,2,7,minecraft:basalt)
B(0,3,7,minecraft:basalt)
B(0,4,7,minecraft:basalt)
B(0,5,7,minecraft:basalt)
B(0,6,7,minecraft:basalt)
B(0,7,7,minecraft:basalt)
B(0,8,7,minecraft:basalt)
B(0,9,7,minecraft:basalt)
B(0,10,7,minecraft:basalt)
B(0,11,7,minecraft:basalt)
B(0,12,7,minecraft:basalt)
B(0,13,7,minecraft:basalt)
B(0,14,7,minecraft:basalt)
B(0,15,7,minecraft:basalt)
B(0,16,7,minecraft:basalt)
B(0,17,7,minecraft:basalt)
B(0,18,7,minecraft:basalt)
B(0,19,7,minecraft:basalt)
B(0,20,7,minecraft:basalt)
B(0,21,7,minecraft:basalt)
B(0,22,7,minecraft:basalt)
B(0,23,7,minecraft:basalt)
B(0,24,7,minecraft:basalt)
B(0,25,7,minecraft:basalt)
B(0,26,7,minecraft:basalt)
B(0,27,7,minecraft:basalt)
B(0,28,7,minecraft:basalt)
B(0,29,7,minecraft:basalt)
B(0,30,7,minecraft:basalt)
B(0,31,7,minecraft:basalt)
B(0,32,7,minecraft:basalt)
B(0,33,7,minecraft:basalt)
B(0,34,7,minecraft:basalt)
B(0,35,7,minecraft:basalt)
B(0,36,7,minecraft:basalt)
B(0,37,7,minecraft:basalt)
B(0,38,7,minecraft:basalt)
B(0,39,7,minecraft:basalt)
B(0,40,7,minecraft:basalt)
B(0,41,7,minecraft:basalt)
B(0,42,7,minecraft:basalt)
B(0,43,7,minecraft:basalt)
B(0,44,7,minecraft:basalt)
B(0,45,7,minecraft:basalt)
B(0,46,7,minecraft:basalt)
B(0,47,7,minecraft:basalt)
B(0,48,7,minecraft:basalt)
B(0,49,7,minecraft:basalt)
B(0,50,7,minecraft:basalt)
B(0,51,7,minecraft:basalt)
B(0,52,7,minecraft:basalt)
B(0,53,7,minecraft:basalt)
B(0,54,7,minecraft:basalt)
B(0,55,7,minecraft:basalt)
B(0,56,7,minecraft:basalt)
B(0,57,7,minecraft:basalt)
B(0,58,7,minecraft:basalt)
B(0,0,8,minecraft:basalt)
B(0,1,8,minecraft:basalt)
B(0,2,8,minecraft:basalt)
B(0,3,8,minecraft:basalt)
B(0,4,8,minecraft:basalt)
B(0,5,8,minecraft:basalt)
B(0,6,8,minecraft:basalt)
B(0,7,8,minecraft:basalt)
B(0,8,8,minecraft:basalt)
B(0,9,8,minecraft:basalt)
B(0,10,8,minecraft:basalt)
B(0,11,8,minecraft:basalt)
B(0,12,8,minecraft:basalt)
B(0,13,8,minecraft:basalt)
B(0,14,8,minecraft:basalt)
B(0,15,8,minecraft:basalt)
B(0,16,8,minecraft:basalt)
B(0,17,8,minecraft:basalt)
B(0,18,8,minecraft:basalt)
B(0,19,8,minecraft:basalt)
B(0,20,8,minecraft:basalt)
B(0,21,8,minecraft:basalt)
B(0,22,8,minecraft:basalt)
B(0,23,8,minecraft:basalt)
B(0,24,8,minecraft:basalt)
B(0,25,8,minecraft:basalt)
B(0,26,8,minecraft:basalt)
B(0,27,8,minecraft:basalt)
B(0,28,8,minecraft:basalt)
B(0,29,8,minecraft:basalt)
B(0,30,8,minecraft:basalt)
B(0,31,8,minecraft:basalt)
B(0,32,8,minecraft:basalt)
B(0,33,8,minecraft:basalt)
B(0,34,8,minecraft:basalt)
B(0,35,8,minecraft:basalt)
B(0,36,8,minecraft:basalt)
B(0,37,8,minecraft:basalt)
B(0,38,8,minecraft:basalt)
B(0,39,8,minecraft:basalt)
B(0,40,8,minecraft:basalt)
B(0,41,8,minecraft:basalt)
B(0,42,8,minecraft:basalt)
B(0,43,8,minecraft:basalt)
B(0,44,8,minecraft:basalt)
B(0,45,8,minecraft:basalt)
B(0,46,8,minecraft:basalt)
B(0,47,8,minecraft:basalt)
B(0,48,8,minecraft:basalt)
B(0,49,8,minecraft:basalt)
B(0,50,8,minecraft:basalt)
B(0,51,8,minecraft:basalt)
B(0,52,8,minecraft:basalt)
B(0,53,8,minecraft:basalt)
B(0,54,8,minecraft:basalt)
B(0,55,8,minecraft:basalt)
B(0,56,8,minecraft:basalt)
B(0,57,8,minecraft:basalt)
B(0,58,8,minecraft:basalt)
B(0,59,8,minecraft:basalt)
B(0,60,8,minecraft:basalt)
B(0,61,8,minecraft:basalt)
B(1,0,-7,minecraft:blackstone)
B(1,1,-7,minecraft:basalt)
B(1,2,-7,minecraft:basalt)
B(1,3,-7,minecraft:basalt)
B(1,4,-7,minecraft:basalt)
B(1,5,-7,minecraft:basalt)
B(1,6,-7,minecraft:basalt)
B(1,7,-7,minecraft:basalt)
B(1,8,-7,minecraft:basalt)
B(1,9,-7,minecraft:basalt)
B(1,10,-7,minecraft:basalt)
B(1,11,-7,minecraft:basalt)
B(1,12,-7,minecraft:basalt)
B(1,13,-7,minecraft:basalt)
B(1,14,-7,minecraft:basalt)
B(1,15,-7,minecraft:basalt)
B(1,16,-7,minecraft:basalt)
B(1,17,-7,minecraft:basalt)
B(1,18,-7,minecraft:basalt)
B(1,19,-7,minecraft:basalt)
B(1,20,-7,minecraft:basalt)
B(1,21,-7,minecraft:basalt)
B(1,22,-7,minecraft:basalt)
B(1,23,-7,minecraft:basalt)
B(1,24,-7,minecraft:basalt)
B(1,25,-7,minecraft:basalt)
B(1,26,-7,minecraft:basalt)
B(1,27,-7,minecraft:basalt)
B(1,28,-7,minecraft:basalt)
B(1,29,-7,minecraft:basalt)
B(1,30,-7,minecraft:basalt)
B(1,31,-7,minecraft:basalt)
B(1,32,-7,minecraft:basalt)
B(1,33,-7,minecraft:basalt)
B(1,34,-7,minecraft:basalt)
B(1,0,-6,minecraft:basalt)
B(1,1,-6,minecraft:basalt)
B(1,2,-6,minecraft:basalt)
B(1,3,-6,minecraft:basalt)
B(1,4,-6,minecraft:basalt)
B(1,5,-6,minecraft:basalt)
B(1,6,-6,minecraft:basalt)
B(1,7,-6,minecraft:basalt)
B(1,8,-6,minecraft:basalt)
B(1,9,-6,minecraft:basalt)
B(1,10,-6,minecraft:basalt)
B(1,11,-6,minecraft:basalt)
B(1,12,-6,minecraft:basalt)
B(1,13,-6,minecraft:basalt)
B(1,14,-6,minecraft:basalt)
B(1,15,-6,minecraft:basalt)
B(1,16,-6,minecraft:basalt)
B(1,17,-6,minecraft:basalt)
B(1,18,-6,minecraft:basalt)
B(1,19,-6,minecraft:basalt)
B(1,20,-6,minecraft:basalt)
B(1,21,-6,minecraft:basalt)
B(1,22,-6,minecraft:basalt)
B(1,23,-6,minecraft:basalt)
B(1,24,-6,minecraft:basalt)
B(1,25,-6,minecraft:basalt)
B(1,26,-6,minecraft:basalt)
B(1,27,-6,minecraft:basalt)
B(1,28,-6,minecraft:basalt)
B(1,29,-6,minecraft:basalt)
B(1,30,-6,minecraft:basalt)
B(1,31,-6,minecraft:basalt)
B(1,32,-6,minecraft:basalt)
B(1,33,-6,minecraft:basalt)
B(1,34,-6,minecraft:basalt)
B(1,35,-6,minecraft:basalt)
B(1,0,-5,minecraft:basalt)
B(1,1,-5,minecraft:basalt)
B(1,2,-5,minecraft:basalt)
B(1,3,-5,minecraft:basalt)
B(1,4,-5,minecraft:basalt)
B(1,5,-5,minecraft:basalt)
B(1,6,-5,minecraft:basalt)
B(1,7,-5,minecraft:basalt)
B(1,8,-5,minecraft:basalt)
B(1,9,-5,minecraft:basalt)
B(1,10,-5,minecraft:basalt)
B(1,11,-5,minecraft:basalt)
B(1,12,-5,minecraft:basalt)
B(1,13,-5,minecraft:basalt)
B(1,14,-5,minecraft:basalt)
B(1,15,-5,minecraft:basalt)
B(1,16,-5,minecraft:basalt)
B(1,17,-5,minecraft:basalt)
B(1,18,-5,minecraft:basalt)
B(1,19,-5,minecraft:basalt)
B(1,20,-5,minecraft:basalt)
B(1,21,-5,minecraft:basalt)
B(1,22,-5,minecraft:basalt)
B(1,23,-5,minecraft:basalt)
B(1,24,-5,minecraft:basalt)
B(1,25,-5,minecraft:basalt)
B(1,26,-5,minecraft:basalt)
B(1,27,-5,minecraft:basalt)
B(1,28,-5,minecraft:basalt)
B(1,29,-5,minecraft:basalt)
B(1,30,-5,minecraft:basalt)
B(1,31,-5,minecraft:basalt)
B(1,32,-5,minecraft:basalt)
B(1,33,-5,minecraft:basalt)
B(1,34,-5,minecraft:basalt)
B(1,35,-5,minecraft:basalt)
B(1,0,-4,minecraft:basalt)
B(1,1,-4,minecraft:basalt)
B(1,2,-4,minecraft:basalt)
B(1,3,-4,minecraft:basalt)
B(1,4,-4,minecraft:basalt)
B(1,5,-4,minecraft:basalt)
B(1,6,-4,minecraft:basalt)
B(1,7,-4,minecraft:basalt)
B(1,8,-4,minecraft:basalt)
B(1,9,-4,minecraft:basalt)
B(1,10,-4,minecraft:basalt)
B(1,11,-4,minecraft:basalt)
B(1,12,-4,minecraft:basalt)
B(1,13,-4,minecraft:basalt)
B(1,14,-4,minecraft:basalt)
B(1,15,-4,minecraft:basalt)
B(1,16,-4,minecraft:basalt)
B(1,17,-4,minecraft:basalt)
B(1,18,-4,minecraft:basalt)
B(1,19,-4,minecraft:basalt)
B(1,20,-4,minecraft:basalt)
B(1,21,-4,minecraft:basalt)
B(1,22,-4,minecraft:basalt)
B(1,23,-4,minecraft:basalt)
B(1,24,-4,minecraft:basalt)
B(1,25,-4,minecraft:basalt)
B(1,26,-4,minecraft:basalt)
B(1,27,-4,minecraft:basalt)
B(1,28,-4,minecraft:basalt)
B(1,29,-4,minecraft:basalt)
B(1,30,-4,minecraft:basalt)
B(1,31,-4,minecraft:basalt)
B(1,32,-4,minecraft:basalt)
B(1,33,-4,minecraft:basalt)
B(1,0,-3,minecraft:basalt)
B(1,1,-3,minecraft:basalt)
B(1,2,-3,minecraft:basalt)
B(1,3,-3,minecraft:basalt)
B(1,4,-3,minecraft:basalt)
B(1,5,-3,minecraft:basalt)
B(1,6,-3,minecraft:basalt)
B(1,7,-3,minecraft:basalt)
B(1,8,-3,minecraft:basalt)
B(1,9,-3,minecraft:basalt)
B(1,10,-3,minecraft:basalt)
B(1,11,-3,minecraft:basalt)
B(1,12,-3,minecraft:basalt)
B(1,13,-3,minecraft:basalt)
B(1,14,-3,minecraft:basalt)
B(1,15,-3,minecraft:basalt)
B(1,16,-3,minecraft:basalt)
B(1,17,-3,minecraft:basalt)
B(1,18,-3,minecraft:basalt)
B(1,19,-3,minecraft:basalt)
B(1,20,-3,minecraft:basalt)
B(1,21,-3,minecraft:basalt)
B(1,22,-3,minecraft:basalt)
B(1,23,-3,minecraft:basalt)
B(1,24,-3,minecraft:basalt)
B(1,25,-3,minecraft:basalt)
B(1,26,-3,minecraft:basalt)
B(1,27,-3,minecraft:basalt)
B(1,28,-3,minecraft:basalt)
B(1,29,-3,minecraft:basalt)
B(1,30,-3,minecraft:basalt)
B(1,0,-2,minecraft:basalt)
B(1,1,-2,minecraft:basalt)
B(1,2,-2,minecraft:basalt)
B(1,3,-2,minecraft:basalt)
B(1,4,-2,minecraft:basalt)
B(1,5,-2,minecraft:basalt)
B(1,6,-2,minecraft:basalt)
B(1,7,-2,minecraft:basalt)
B(1,8,-2,minecraft:basalt)
B(1,9,-2,minecraft:basalt)
B(1,10,-2,minecraft:basalt)
B(1,11,-2,minecraft:basalt)
B(1,12,-2,minecraft:basalt)
B(1,13,-2,minecraft:basalt)
B(1,14,-2,minecraft:basalt)
B(1,15,-2,minecraft:basalt)
B(1,16,-2,minecraft:basalt)
B(1,17,-2,minecraft:basalt)
B(1,18,-2,minecraft:basalt)
B(1,19,-2,minecraft:basalt)
B(1,20,-2,minecraft:basalt)
B(1,21,-2,minecraft:basalt)
B(1,22,-2,minecraft:basalt)
B(1,23,-2,minecraft:basalt)
B(1,24,-2,minecraft:basalt)
B(1,0,-1,minecraft:blackstone)
B(1,1,-1,minecraft:basalt)
B(1,2,-1,minecraft:basalt)
B(1,3,-1,minecraft:basalt)
B(1,4,-1,minecraft:basalt)
B(1,5,-1,minecraft:basalt)
B(1,6,-1,minecraft:basalt)
B(1,7,-1,minecraft:basalt)
B(1,8,-1,minecraft:basalt)
B(1,9,-1,minecraft:basalt)
B(1,10,-1,minecraft:basalt)
B(1,11,-1,minecraft:basalt)
B(1,12,-1,minecraft:basalt)
B(1,13,-1,minecraft:basalt)
B(1,14,-1,minecraft:basalt)
B(1,15,-1,minecraft:basalt)
B(1,16,-1,minecraft:basalt)
B(1,17,-1,minecraft:basalt)
B(1,18,-1,minecraft:basalt)
B(1,19,-1,minecraft:basalt)
B(1,20,-1,minecraft:basalt)
B(1,21,-1,minecraft:basalt)
B(1,0,0,minecraft:blackstone)
B(1,1,0,minecraft:blackstone)
B(1,2,0,minecraft:blackstone)
B(1,3,0,minecraft:basalt)
B(1,4,0,minecraft:basalt)
B(1,5,0,minecraft:basalt)
B(1,6,0,minecraft:basalt)
B(1,7,0,minecraft:basalt)
B(1,8,0,minecraft:basalt)
B(1,9,0,minecraft:basalt)
B(1,10,0,minecraft:basalt)
B(1,11,0,minecraft:basalt)
B(1,12,0,minecraft:basalt)
B(1,13,0,minecraft:basalt)
B(1,14,0,minecraft:basalt)
B(1,15,0,minecraft:basalt)
B(1,16,0,minecraft:basalt)
B(1,17,0,minecraft:basalt)
B(1,18,0,minecraft:basalt)
B(1,19,0,minecraft:basalt)
B(1,20,0,minecraft:basalt)
B(1,21,0,minecraft:basalt)
B(1,22,0,minecraft:basalt)
B(1,23,0,minecraft:basalt)
B(1,24,0,minecraft:basalt)
B(1,25,0,minecraft:basalt)
B(1,26,0,minecraft:basalt)
B(1,27,0,minecraft:basalt)
B(1,28,0,minecraft:basalt)
B(1,0,1,minecraft:blackstone)
B(1,1,1,minecraft:basalt)
B(1,2,1,minecraft:basalt)
B(1,3,1,minecraft:basalt)
B(1,4,1,minecraft:basalt)
B(1,5,1,minecraft:basalt)
B(1,6,1,minecraft:basalt)
B(1,7,1,minecraft:basalt)
B(1,8,1,minecraft:basalt)
B(1,9,1,minecraft:basalt)
B(1,10,1,minecraft:basalt)
B(1,11,1,minecraft:basalt)
B(1,12,1,minecraft:basalt)
B(1,13,1,minecraft:basalt)
B(1,14,1,minecraft:basalt)
B(1,15,1,minecraft:basalt)
B(1,16,1,minecraft:basalt)
B(1,17,1,minecraft:basalt)
B(1,18,1,minecraft:basalt)
B(1,19,1,minecraft:basalt)
B(1,20,1,minecraft:basalt)
B(1,21,1,minecraft:basalt)
B(1,22,1,minecraft:basalt)
B(1,23,1,minecraft:basalt)
B(1,24,1,minecraft:basalt)
B(1,25,1,minecraft:basalt)
B(1,26,1,minecraft:basalt)
B(1,27,1,minecraft:basalt)
B(1,28,1,minecraft:basalt)
B(1,29,1,minecraft:basalt)
B(1,30,1,minecraft:basalt)
B(1,31,1,minecraft:basalt)
B(1,32,1,minecraft:basalt)
B(1,33,1,minecraft:basalt)
B(1,34,1,minecraft:basalt)
B(1,35,1,minecraft:basalt)
B(1,36,1,minecraft:basalt)
B(1,37,1,minecraft:basalt)
B(1,38,1,minecraft:basalt)
B(1,39,1,minecraft:basalt)
B(1,40,1,minecraft:basalt)
B(1,41,1,minecraft:basalt)
B(1,42,1,minecraft:basalt)
B(1,43,1,minecraft:basalt)
B(1,44,1,minecraft:basalt)
B(1,45,1,minecraft:basalt)
B(1,46,1,minecraft:basalt)
B(1,47,1,minecraft:basalt)
B(1,48,1,minecraft:basalt)
B(1,0,2,minecraft:basalt)
B(1,1,2,minecraft:basalt)
B(1,2,2,minecraft:basalt)
B(1,3,2,minecraft:basalt)
B(1,4,2,minecraft:basalt)
B(1,5,2,minecraft:basalt)
B(1,6,2,minecraft:basalt)
B(1,7,2,minecraft:basalt)
B(1,8,2,minecraft:basalt)
B(1,9,2,minecraft:basalt)
B(1,10,2,minecraft:basalt)
B(1,11,2,minecraft:basalt)
B(1,12,2,minecraft:basalt)
B(1,13,2,minecraft:basalt)
B(1,14,2,minecraft:basalt)
B(1,15,2,minecraft:basalt)
B(1,16,2,minecraft:basalt)
B(1,17,2,minecraft:basalt)
B(1,18,2,minecraft:basalt)
B(1,19,2,minecraft:basalt)
B(1,20,2,minecraft:basalt)
B(1,21,2,minecraft:basalt)
B(1,22,2,minecraft:basalt)
B(1,23,2,minecraft:basalt)
B(1,24,2,minecraft:basalt)
B(1,25,2,minecraft:basalt)
B(1,26,2,minecraft:basalt)
B(1,27,2,minecraft:basalt)
B(1,28,2,minecraft:basalt)
B(1,29,2,minecraft:basalt)
B(1,30,2,minecraft:basalt)
B(1,31,2,minecraft:basalt)
B(1,32,2,minecraft:basalt)
B(1,33,2,minecraft:basalt)
B(1,34,2,minecraft:basalt)
B(1,35,2,minecraft:basalt)
B(1,36,2,minecraft:basalt)
B(1,37,2,minecraft:basalt)
B(1,38,2,minecraft:basalt)
B(1,39,2,minecraft:basalt)
B(1,40,2,minecraft:basalt)
B(1,41,2,minecraft:basalt)
B(1,42,2,minecraft:basalt)
B(1,43,2,minecraft:basalt)
B(1,44,2,minecraft:basalt)
B(1,45,2,minecraft:basalt)
B(1,46,2,minecraft:basalt)
B(1,47,2,minecraft:basalt)
B(1,48,2,minecraft:basalt)
B(1,49,2,minecraft:basalt)
B(1,0,3,minecraft:basalt)
B(1,1,3,minecraft:basalt)
B(1,2,3,minecraft:basalt)
B(1,3,3,minecraft:basalt)
B(1,4,3,minecraft:basalt)
B(1,5,3,minecraft:basalt)
B(1,6,3,minecraft:basalt)
B(1,7,3,minecraft:basalt)
B(1,8,3,minecraft:basalt)
B(1,9,3,minecraft:basalt)
B(1,10,3,minecraft:basalt)
B(1,11,3,minecraft:basalt)
B(1,12,3,minecraft:basalt)
B(1,13,3,minecraft:basalt)
B(1,14,3,minecraft:basalt)
B(1,15,3,minecraft:basalt)
B(1,16,3,minecraft:basalt)
B(1,17,3,minecraft:basalt)
B(1,18,3,minecraft:basalt)
B(1,19,3,minecraft:basalt)
B(1,20,3,minecraft:basalt)
B(1,21,3,minecraft:basalt)
B(1,22,3,minecraft:basalt)
B(1,23,3,minecraft:basalt)
B(1,24,3,minecraft:basalt)
B(1,25,3,minecraft:basalt)
B(1,26,3,minecraft:basalt)
B(1,27,3,minecraft:basalt)
B(1,28,3,minecraft:basalt)
B(1,29,3,minecraft:basalt)
B(1,30,3,minecraft:basalt)
B(1,31,3,minecraft:basalt)
B(1,32,3,minecraft:basalt)
B(1,33,3,minecraft:basalt)
B(1,34,3,minecraft:basalt)
B(1,35,3,minecraft:basalt)
B(1,36,3,minecraft:basalt)
B(1,37,3,minecraft:basalt)
B(1,38,3,minecraft:basalt)
B(1,39,3,minecraft:basalt)
B(1,40,3,minecraft:basalt)
B(1,41,3,minecraft:basalt)
B(1,42,3,minecraft:basalt)
B(1,43,3,minecraft:basalt)
B(1,44,3,minecraft:basalt)
B(1,45,3,minecraft:basalt)
B(1,46,3,minecraft:basalt)
B(1,47,3,minecraft:basalt)
B(1,48,3,minecraft:basalt)
B(1,49,3,minecraft:basalt)
B(1,0,4,minecraft:basalt)
B(1,1,4,minecraft:basalt)
B(1,2,4,minecraft:basalt)
B(1,3,4,minecraft:basalt)
B(1,4,4,minecraft:basalt)
B(1,5,4,minecraft:basalt)
B(1,6,4,minecraft:basalt)
B(1,7,4,minecraft:basalt)
B(1,8,4,minecraft:basalt)
B(1,9,4,minecraft:basalt)
B(1,10,4,minecraft:basalt)
B(1,11,4,minecraft:basalt)
B(1,12,4,minecraft:basalt)
B(1,13,4,minecraft:basalt)
B(1,14,4,minecraft:basalt)
B(1,15,4,minecraft:basalt)
B(1,16,4,minecraft:basalt)
B(1,17,4,minecraft:basalt)
B(1,18,4,minecraft:basalt)
B(1,19,4,minecraft:basalt)
B(1,20,4,minecraft:basalt)
B(1,21,4,minecraft:basalt)
B(1,22,4,minecraft:basalt)
B(1,23,4,minecraft:basalt)
B(1,24,4,minecraft:basalt)
B(1,25,4,minecraft:basalt)
B(1,26,4,minecraft:basalt)
B(1,27,4,minecraft:basalt)
B(1,28,4,minecraft:basalt)
B(1,29,4,minecraft:basalt)
B(1,30,4,minecraft:basalt)
B(1,31,4,minecraft:basalt)
B(1,32,4,minecraft:basalt)
B(1,33,4,minecraft:basalt)
B(1,34,4,minecraft:basalt)
B(1,35,4,minecraft:basalt)
B(1,36,4,minecraft:basalt)
B(1,37,4,minecraft:basalt)
B(1,38,4,minecraft:basalt)
B(1,39,4,minecraft:basalt)
B(1,40,4,minecraft:basalt)
B(1,41,4,minecraft:basalt)
B(1,42,4,minecraft:basalt)
B(1,43,4,minecraft:basalt)
B(1,44,4,minecraft:basalt)
B(1,45,4,minecraft:basalt)
B(1,46,4,minecraft:basalt)
B(1,47,4,minecraft:basalt)
B(1,48,4,minecraft:basalt)
B(1,49,4,minecraft:basalt)
B(1,0,5,minecraft:basalt)
B(1,1,5,minecraft:basalt)
B(1,2,5,minecraft:basalt)
B(1,3,5,minecraft:basalt)
B(1,4,5,minecraft:basalt)
B(1,5,5,minecraft:basalt)
B(1,6,5,minecraft:basalt)
B(1,7,5,minecraft:basalt)
B(1,8,5,minecraft:basalt)
B(1,9,5,minecraft:basalt)
B(1,10,5,minecraft:basalt)
B(1,11,5,minecraft:basalt)
B(1,12,5,minecraft:basalt)
B(1,13,5,minecraft:basalt)
B(1,14,5,minecraft:basalt)
B(1,15,5,minecraft:basalt)
B(1,16,5,minecraft:basalt)
B(1,17,5,minecraft:basalt)
B(1,18,5,minecraft:basalt)
B(1,19,5,minecraft:basalt)
B(1,20,5,minecraft:basalt)
B(1,21,5,minecraft:basalt)
B(1,22,5,minecraft:basalt)
B(1,23,5,minecraft:basalt)
B(1,24,5,minecraft:basalt)
B(1,25,5,minecraft:basalt)
B(1,26,5,minecraft:basalt)
B(1,27,5,minecraft:basalt)
B(1,28,5,minecraft:basalt)
B(1,29,5,minecraft:basalt)
B(1,30,5,minecraft:basalt)
B(1,31,5,minecraft:basalt)
B(1,32,5,minecraft:basalt)
B(1,33,5,minecraft:basalt)
B(1,34,5,minecraft:basalt)
B(1,35,5,minecraft:basalt)
B(1,36,5,minecraft:basalt)
B(1,37,5,minecraft:basalt)
B(1,38,5,minecraft:basalt)
B(1,39,5,minecraft:basalt)
B(1,40,5,minecraft:basalt)
B(1,41,5,minecraft:basalt)
B(1,42,5,minecraft:basalt)
B(1,43,5,minecraft:basalt)
B(1,44,5,minecraft:basalt)
B(1,45,5,minecraft:basalt)
B(1,46,5,minecraft:basalt)
B(1,47,5,minecraft:basalt)
B(1,48,5,minecraft:basalt)
B(1,49,5,minecraft:basalt)
B(1,50,5,minecraft:basalt)
B(1,0,6,minecraft:basalt)
B(1,1,6,minecraft:basalt)
B(1,2,6,minecraft:basalt)
B(1,3,6,minecraft:basalt)
B(1,4,6,minecraft:basalt)
B(1,5,6,minecraft:basalt)
B(1,6,6,minecraft:basalt)
B(1,7,6,minecraft:basalt)
B(1,8,6,minecraft:basalt)
B(1,9,6,minecraft:basalt)
B(1,10,6,minecraft:basalt)
B(1,11,6,minecraft:basalt)
B(1,12,6,minecraft:basalt)
B(1,13,6,minecraft:basalt)
B(1,14,6,minecraft:basalt)
B(1,15,6,minecraft:basalt)
B(1,16,6,minecraft:basalt)
B(1,17,6,minecraft:basalt)
B(1,18,6,minecraft:basalt)
B(1,19,6,minecraft:basalt)
B(1,20,6,minecraft:basalt)
B(1,21,6,minecraft:basalt)
B(1,22,6,minecraft:basalt)
B(1,23,6,minecraft:basalt)
B(1,24,6,minecraft:basalt)
B(1,25,6,minecraft:basalt)
B(1,26,6,minecraft:basalt)
B(1,27,6,minecraft:basalt)
B(1,28,6,minecraft:basalt)
B(1,29,6,minecraft:basalt)
B(1,30,6,minecraft:basalt)
B(1,31,6,minecraft:basalt)
B(1,32,6,minecraft:basalt)
B(1,33,6,minecraft:basalt)
B(1,34,6,minecraft:basalt)
B(1,35,6,minecraft:basalt)
B(1,36,6,minecraft:basalt)
B(1,37,6,minecraft:basalt)
B(1,38,6,minecraft:basalt)
B(1,39,6,minecraft:basalt)
B(1,40,6,minecraft:basalt)
B(1,41,6,minecraft:basalt)
B(1,42,6,minecraft:basalt)
B(1,43,6,minecraft:basalt)
B(1,44,6,minecraft:basalt)
B(1,45,6,minecraft:basalt)
B(1,46,6,minecraft:basalt)
B(1,47,6,minecraft:basalt)
B(1,48,6,minecraft:basalt)
B(1,49,6,minecraft:basalt)
B(1,50,6,minecraft:basalt)
B(1,51,6,minecraft:basalt)
B(1,52,6,minecraft:basalt)
B(1,53,6,minecraft:basalt)
B(1,54,6,minecraft:basalt)
B(1,55,6,minecraft:basalt)
B(1,56,6,minecraft:basalt)
B(1,57,6,minecraft:basalt)
B(1,58,6,minecraft:basalt)
B(1,0,7,minecraft:basalt)
B(1,1,7,minecraft:basalt)
B(1,2,7,minecraft:basalt)
B(1,3,7,minecraft:basalt)
B(1,4,7,minecraft:basalt)
B(1,5,7,minecraft:basalt)
B(1,6,7,minecraft:basalt)
B(1,7,7,minecraft:basalt)
B(1,8,7,minecraft:basalt)
B(1,9,7,minecraft:basalt)
B(1,10,7,minecraft:basalt)
B(1,11,7,minecraft:basalt)
B(1,12,7,minecraft:basalt)
B(1,13,7,minecraft:basalt)
B(1,14,7,minecraft:basalt)
B(1,15,7,minecraft:basalt)
B(1,16,7,minecraft:basalt)
B(1,17,7,minecraft:basalt)
B(1,18,7,minecraft:basalt)
B(1,19,7,minecraft:basalt)
B(1,20,7,minecraft:basalt)
B(1,21,7,minecraft:basalt)
B(1,22,7,minecraft:basalt)
B(1,23,7,minecraft:basalt)
B(1,24,7,minecraft:basalt)
B(1,25,7,minecraft:basalt)
B(1,26,7,minecraft:basalt)
B(1,27,7,minecraft:basalt)
B(1,28,7,minecraft:basalt)
B(1,29,7,minecraft:basalt)
B(1,30,7,minecraft:basalt)
B(1,31,7,minecraft:basalt)
B(1,32,7,minecraft:basalt)
B(1,33,7,minecraft:basalt)
B(1,34,7,minecraft:basalt)
B(1,35,7,minecraft:basalt)
B(1,36,7,minecraft:basalt)
B(1,37,7,minecraft:basalt)
B(1,38,7,minecraft:basalt)
B(1,39,7,minecraft:basalt)
B(1,40,7,minecraft:basalt)
B(1,41,7,minecraft:basalt)
B(1,42,7,minecraft:basalt)
B(1,43,7,minecraft:basalt)
B(1,44,7,minecraft:basalt)
B(1,45,7,minecraft:basalt)
B(1,46,7,minecraft:basalt)
B(1,47,7,minecraft:basalt)
B(1,48,7,minecraft:basalt)
B(1,49,7,minecraft:basalt)
B(1,50,7,minecraft:basalt)
B(1,51,7,minecraft:basalt)
B(1,52,7,minecraft:basalt)
B(1,53,7,minecraft:basalt)
B(1,54,7,minecraft:basalt)
B(1,55,7,minecraft:basalt)
B(1,56,7,minecraft:basalt)
B(1,57,7,minecraft:basalt)
B(1,58,7,minecraft:basalt)
B(1,59,7,minecraft:basalt)
B(1,60,7,minecraft:basalt)
B(1,61,7,minecraft:basalt)
B(1,0,8,minecraft:basalt)
B(1,1,8,minecraft:basalt)
B(1,2,8,minecraft:basalt)
B(1,3,8,minecraft:basalt)
B(1,4,8,minecraft:basalt)
B(1,5,8,minecraft:basalt)
B(1,6,8,minecraft:basalt)
B(1,7,8,minecraft:basalt)
B(1,8,8,minecraft:basalt)
B(1,9,8,minecraft:basalt)
B(1,10,8,minecraft:basalt)
B(1,11,8,minecraft:basalt)
B(1,12,8,minecraft:basalt)
B(1,13,8,minecraft:basalt)
B(1,14,8,minecraft:basalt)
B(1,15,8,minecraft:basalt)
B(1,16,8,minecraft:basalt)
B(1,17,8,minecraft:basalt)
B(1,18,8,minecraft:basalt)
B(1,19,8,minecraft:basalt)
B(1,20,8,minecraft:basalt)
B(1,21,8,minecraft:basalt)
B(1,22,8,minecraft:basalt)
B(1,23,8,minecraft:basalt)
B(1,24,8,minecraft:basalt)
B(1,25,8,minecraft:basalt)
B(1,26,8,minecraft:basalt)
B(1,27,8,minecraft:basalt)
B(1,28,8,minecraft:basalt)
B(1,29,8,minecraft:basalt)
B(1,30,8,minecraft:basalt)
B(1,31,8,minecraft:basalt)
B(1,32,8,minecraft:basalt)
B(1,33,8,minecraft:basalt)
B(1,34,8,minecraft:basalt)
B(1,35,8,minecraft:basalt)
B(1,36,8,minecraft:basalt)
B(1,37,8,minecraft:basalt)
B(1,38,8,minecraft:basalt)
B(1,39,8,minecraft:basalt)
B(1,40,8,minecraft:basalt)
B(1,41,8,minecraft:basalt)
B(1,42,8,minecraft:basalt)
B(1,43,8,minecraft:basalt)
B(1,44,8,minecraft:basalt)
B(1,45,8,minecraft:basalt)
B(1,46,8,minecraft:basalt)
B(1,47,8,minecraft:basalt)
B(1,48,8,minecraft:basalt)
B(1,49,8,minecraft:basalt)
B(1,50,8,minecraft:basalt)
B(1,51,8,minecraft:basalt)
B(1,52,8,minecraft:basalt)
B(1,53,8,minecraft:basalt)
B(1,54,8,minecraft:basalt)
B(1,55,8,minecraft:basalt)
B(1,56,8,minecraft:basalt)
B(1,57,8,minecraft:basalt)
B(1,58,8,minecraft:basalt)
B(1,59,8,minecraft:basalt)
B(1,60,8,minecraft:basalt)
B(1,61,8,minecraft:basalt)
B(1,62,8,minecraft:basalt)
B(2,0,-7,minecraft:basalt)
B(2,1,-7,minecraft:basalt)
B(2,2,-7,minecraft:basalt)
B(2,3,-7,minecraft:basalt)
B(2,4,-7,minecraft:basalt)
B(2,5,-7,minecraft:basalt)
B(2,6,-7,minecraft:basalt)
B(2,7,-7,minecraft:basalt)
B(2,8,-7,minecraft:basalt)
B(2,9,-7,minecraft:basalt)
B(2,10,-7,minecraft:basalt)
B(2,11,-7,minecraft:basalt)
B(2,12,-7,minecraft:basalt)
B(2,13,-7,minecraft:basalt)
B(2,14,-7,minecraft:basalt)
B(2,15,-7,minecraft:basalt)
B(2,16,-7,minecraft:basalt)
B(2,17,-7,minecraft:basalt)
B(2,18,-7,minecraft:basalt)
B(2,19,-7,minecraft:basalt)
B(2,20,-7,minecraft:basalt)
B(2,21,-7,minecraft:basalt)
B(2,22,-7,minecraft:basalt)
B(2,23,-7,minecraft:basalt)
B(2,24,-7,minecraft:basalt)
B(2,25,-7,minecraft:basalt)
B(2,26,-7,minecraft:basalt)
B(2,27,-7,minecraft:basalt)
B(2,28,-7,minecraft:basalt)
B(2,29,-7,minecraft:basalt)
B(2,30,-7,minecraft:basalt)
B(2,31,-7,minecraft:basalt)
B(2,32,-7,minecraft:basalt)
B(2,33,-7,minecraft:basalt)
B(2,34,-7,minecraft:basalt)
B(2,35,-7,minecraft:basalt)
B(2,36,-7,minecraft:basalt)
B(2,37,-7,minecraft:basalt)
B(2,38,-7,minecraft:basalt)
B(2,39,-7,minecraft:basalt)
B(2,40,-7,minecraft:basalt)
B(2,41,-7,minecraft:basalt)
B(2,42,-7,minecraft:basalt)
B(2,43,-7,minecraft:basalt)
B(2,44,-7,minecraft:basalt)
B(2,0,-6,minecraft:basalt)
B(2,1,-6,minecraft:basalt)
B(2,2,-6,minecraft:basalt)
B(2,3,-6,minecraft:basalt)
B(2,4,-6,minecraft:basalt)
B(2,5,-6,minecraft:basalt)
B(2,6,-6,minecraft:basalt)
B(2,7,-6,minecraft:basalt)
B(2,8,-6,minecraft:basalt)
B(2,9,-6,minecraft:basalt)
B(2,10,-6,minecraft:basalt)
B(2,11,-6,minecraft:basalt)
B(2,12,-6,minecraft:basalt)
B(2,13,-6,minecraft:basalt)
B(2,14,-6,minecraft:basalt)
B(2,15,-6,minecraft:basalt)
B(2,16,-6,minecraft:basalt)
B(2,17,-6,minecraft:basalt)
B(2,18,-6,minecraft:basalt)
B(2,19,-6,minecraft:basalt)
B(2,20,-6,minecraft:basalt)
B(2,21,-6,minecraft:basalt)
B(2,22,-6,minecraft:basalt)
B(2,23,-6,minecraft:basalt)
B(2,24,-6,minecraft:basalt)
B(2,25,-6,minecraft:basalt)
B(2,26,-6,minecraft:basalt)
B(2,27,-6,minecraft:basalt)
B(2,28,-6,minecraft:basalt)
B(2,29,-6,minecraft:basalt)
B(2,30,-6,minecraft:basalt)
B(2,31,-6,minecraft:basalt)
B(2,32,-6,minecraft:basalt)
B(2,33,-6,minecraft:basalt)
B(2,34,-6,minecraft:basalt)
B(2,35,-6,minecraft:basalt)
B(2,36,-6,minecraft:basalt)
B(2,37,-6,minecraft:basalt)
B(2,38,-6,minecraft:basalt)
B(2,39,-6,minecraft:basalt)
B(2,40,-6,minecraft:basalt)
B(2,41,-6,minecraft:basalt)
B(2,42,-6,minecraft:basalt)
B(2,43,-6,minecraft:basalt)
B(2,44,-6,minecraft:basalt)
B(2,45,-6,minecraft:basalt)
B(2,46,-6,minecraft:basalt)
B(2,47,-6,minecraft:basalt)
B(2,48,-6,minecraft:basalt)
B(2,0,-5,minecraft:basalt)
B(2,1,-5,minecraft:basalt)
B(2,2,-5,minecraft:basalt)
B(2,3,-5,minecraft:basalt)
B(2,4,-5,minecraft:basalt)
B(2,5,-5,minecraft:basalt)
B(2,6,-5,minecraft:basalt)
B(2,7,-5,minecraft:basalt)
B(2,8,-5,minecraft:basalt)
B(2,9,-5,minecraft:basalt)
B(2,10,-5,minecraft:basalt)
B(2,11,-5,minecraft:basalt)
B(2,12,-5,minecraft:basalt)
B(2,13,-5,minecraft:basalt)
B(2,14,-5,minecraft:basalt)
B(2,15,-5,minecraft:basalt)
B(2,16,-5,minecraft:basalt)
B(2,17,-5,minecraft:basalt)
B(2,18,-5,minecraft:basalt)
B(2,19,-5,minecraft:basalt)
B(2,20,-5,minecraft:basalt)
B(2,21,-5,minecraft:basalt)
B(2,22,-5,minecraft:basalt)
B(2,23,-5,minecraft:basalt)
B(2,24,-5,minecraft:basalt)
B(2,25,-5,minecraft:basalt)
B(2,26,-5,minecraft:basalt)
B(2,27,-5,minecraft:basalt)
B(2,28,-5,minecraft:basalt)
B(2,29,-5,minecraft:basalt)
B(2,30,-5,minecraft:basalt)
B(2,31,-5,minecraft:basalt)
B(2,32,-5,minecraft:basalt)
B(2,33,-5,minecraft:basalt)
B(2,34,-5,minecraft:basalt)
B(2,35,-5,minecraft:basalt)
B(2,36,-5,minecraft:basalt)
B(2,37,-5,minecraft:basalt)
B(2,38,-5,minecraft:basalt)
B(2,39,-5,minecraft:basalt)
B(2,40,-5,minecraft:basalt)
B(2,41,-5,minecraft:basalt)
B(2,42,-5,minecraft:basalt)
B(2,43,-5,minecraft:basalt)
B(2,44,-5,minecraft:basalt)
B(2,45,-5,minecraft:basalt)
B(2,46,-5,minecraft:basalt)
B(2,47,-5,minecraft:basalt)
B(2,48,-5,minecraft:basalt)
B(2,49,-5,minecraft:basalt)
B(2,50,-5,minecraft:basalt)
B(2,0,-4,minecraft:basalt)
B(2,1,-4,minecraft:basalt)
B(2,2,-4,minecraft:basalt)
B(2,3,-4,minecraft:basalt)
B(2,4,-4,minecraft:basalt)
B(2,5,-4,minecraft:basalt)
B(2,6,-4,minecraft:basalt)
B(2,7,-4,minecraft:basalt)
B(2,8,-4,minecraft:basalt)
B(2,9,-4,minecraft:basalt)
B(2,10,-4,minecraft:basalt)
B(2,11,-4,minecraft:basalt)
B(2,12,-4,minecraft:basalt)
B(2,13,-4,minecraft:basalt)
B(2,14,-4,minecraft:basalt)
B(2,15,-4,minecraft:basalt)
B(2,16,-4,minecraft:basalt)
B(2,17,-4,minecraft:basalt)
B(2,18,-4,minecraft:basalt)
B(2,19,-4,minecraft:basalt)
B(2,20,-4,minecraft:basalt)
B(2,21,-4,minecraft:basalt)
B(2,22,-4,minecraft:basalt)
B(2,23,-4,minecraft:basalt)
B(2,24,-4,minecraft:basalt)
B(2,25,-4,minecraft:basalt)
B(2,26,-4,minecraft:basalt)
B(2,27,-4,minecraft:basalt)
B(2,28,-4,minecraft:basalt)
B(2,29,-4,minecraft:basalt)
B(2,30,-4,minecraft:basalt)
B(2,31,-4,minecraft:basalt)
B(2,32,-4,minecraft:basalt)
B(2,33,-4,minecraft:basalt)
B(2,34,-4,minecraft:basalt)
B(2,35,-4,minecraft:basalt)
B(2,36,-4,minecraft:basalt)
B(2,37,-4,minecraft:basalt)
B(2,38,-4,minecraft:basalt)
B(2,39,-4,minecraft:basalt)
B(2,40,-4,minecraft:basalt)
B(2,41,-4,minecraft:basalt)
B(2,42,-4,minecraft:basalt)
B(2,43,-4,minecraft:basalt)
B(2,44,-4,minecraft:basalt)
B(2,45,-4,minecraft:basalt)
B(2,46,-4,minecraft:basalt)
B(2,47,-4,minecraft:basalt)
B(2,48,-4,minecraft:basalt)
B(2,0,-3,minecraft:basalt)
B(2,1,-3,minecraft:basalt)
B(2,2,-3,minecraft:basalt)
B(2,3,-3,minecraft:basalt)
B(2,4,-3,minecraft:basalt)
B(2,5,-3,minecraft:basalt)
B(2,6,-3,minecraft:basalt)
B(2,7,-3,minecraft:basalt)
B(2,8,-3,minecraft:basalt)
B(2,9,-3,minecraft:basalt)
B(2,10,-3,minecraft:basalt)
B(2,11,-3,minecraft:basalt)
B(2,12,-3,minecraft:basalt)
B(2,13,-3,minecraft:basalt)
B(2,14,-3,minecraft:basalt)
B(2,15,-3,minecraft:basalt)
B(2,16,-3,minecraft:basalt)
B(2,17,-3,minecraft:basalt)
B(2,18,-3,minecraft:basalt)
B(2,19,-3,minecraft:basalt)
B(2,20,-3,minecraft:basalt)
B(2,21,-3,minecraft:basalt)
B(2,22,-3,minecraft:basalt)
B(2,23,-3,minecraft:basalt)
B(2,24,-3,minecraft:basalt)
B(2,25,-3,minecraft:basalt)
B(2,26,-3,minecraft:basalt)
B(2,27,-3,minecraft:basalt)
B(2,28,-3,minecraft:basalt)
B(2,29,-3,minecraft:basalt)
B(2,30,-3,minecraft:basalt)
B(2,31,-3,minecraft:basalt)
B(2,32,-3,minecraft:basalt)
B(2,33,-3,minecraft:basalt)
B(2,34,-3,minecraft:basalt)
B(2,35,-3,minecraft:basalt)
B(2,36,-3,minecraft:basalt)
B(2,37,-3,minecraft:basalt)
B(2,38,-3,minecraft:basalt)
B(2,39,-3,minecraft:basalt)
B(2,40,-3,minecraft:basalt)
B(2,41,-3,minecraft:basalt)
B(2,42,-3,minecraft:basalt)
B(2,43,-3,minecraft:basalt)
B(2,0,-2,minecraft:basalt)
B(2,1,-2,minecraft:basalt)
B(2,2,-2,minecraft:basalt)
B(2,3,-2,minecraft:basalt)
B(2,4,-2,minecraft:basalt)
B(2,5,-2,minecraft:basalt)
B(2,6,-2,minecraft:basalt)
B(2,7,-2,minecraft:basalt)
B(2,8,-2,minecraft:basalt)
B(2,9,-2,minecraft:basalt)
B(2,10,-2,minecraft:basalt)
B(2,11,-2,minecraft:basalt)
B(2,12,-2,minecraft:basalt)
B(2,13,-2,minecraft:basalt)
B(2,14,-2,minecraft:basalt)
B(2,15,-2,minecraft:basalt)
B(2,16,-2,minecraft:basalt)
B(2,17,-2,minecraft:basalt)
B(2,18,-2,minecraft:basalt)
B(2,19,-2,minecraft:basalt)
B(2,20,-2,minecraft:basalt)
B(2,21,-2,minecraft:basalt)
B(2,22,-2,minecraft:basalt)
B(2,23,-2,minecraft:basalt)
B(2,24,-2,minecraft:basalt)
B(2,25,-2,minecraft:basalt)
B(2,26,-2,minecraft:basalt)
B(2,27,-2,minecraft:basalt)
B(2,28,-2,minecraft:basalt)
B(2,29,-2,minecraft:basalt)
B(2,30,-2,minecraft:basalt)
B(2,31,-2,minecraft:basalt)
B(2,32,-2,minecraft:basalt)
B(2,33,-2,minecraft:basalt)
B(2,34,-2,minecraft:basalt)
B(2,0,-1,minecraft:basalt)
B(2,1,-1,minecraft:basalt)
B(2,2,-1,minecraft:basalt)
B(2,3,-1,minecraft:basalt)
B(2,4,-1,minecraft:basalt)
B(2,5,-1,minecraft:basalt)
B(2,6,-1,minecraft:basalt)
B(2,7,-1,minecraft:basalt)
B(2,8,-1,minecraft:basalt)
B(2,9,-1,minecraft:basalt)
B(2,10,-1,minecraft:basalt)
B(2,11,-1,minecraft:basalt)
B(2,12,-1,minecraft:basalt)
B(2,13,-1,minecraft:basalt)
B(2,14,-1,minecraft:basalt)
B(2,15,-1,minecraft:basalt)
B(2,16,-1,minecraft:basalt)
B(2,17,-1,minecraft:basalt)
B(2,18,-1,minecraft:basalt)
B(2,19,-1,minecraft:basalt)
B(2,20,-1,minecraft:basalt)
B(2,21,-1,minecraft:basalt)
B(2,22,-1,minecraft:basalt)
B(2,23,-1,minecraft:basalt)
B(2,24,-1,minecraft:basalt)
B(2,25,-1,minecraft:basalt)
B(2,26,-1,minecraft:basalt)
B(2,27,-1,minecraft:basalt)
B(2,28,-1,minecraft:basalt)
B(2,29,-1,minecraft:basalt)
B(2,30,-1,minecraft:basalt)
B(2,31,-1,minecraft:basalt)
B(2,32,-1,minecraft:basalt)
B(2,33,-1,minecraft:basalt)
B(2,34,-1,minecraft:basalt)
B(2,35,-1,minecraft:basalt)
B(2,36,-1,minecraft:basalt)
B(2,37,-1,minecraft:basalt)
B(2,38,-1,minecraft:basalt)
B(2,39,-1,minecraft:basalt)
B(2,40,-1,minecraft:basalt)
B(2,41,-1,minecraft:basalt)
B(2,42,-1,minecraft:basalt)
B(2,0,0,minecraft:blackstone)
B(2,1,0,minecraft:basalt)
B(2,2,0,minecraft:basalt)
B(2,3,0,minecraft:basalt)
B(2,4,0,minecraft:basalt)
B(2,5,0,minecraft:basalt)
B(2,6,0,minecraft:basalt)
B(2,7,0,minecraft:basalt)
B(2,8,0,minecraft:basalt)
B(2,9,0,minecraft:basalt)
B(2,10,0,minecraft:basalt)
B(2,11,0,minecraft:basalt)
B(2,12,0,minecraft:basalt)
B(2,13,0,minecraft:basalt)
B(2,14,0,minecraft:basalt)
B(2,15,0,minecraft:basalt)
B(2,16,0,minecraft:basalt)
B(2,17,0,minecraft:basalt)
B(2,18,0,minecraft:basalt)
B(2,19,0,minecraft:basalt)
B(2,20,0,minecraft:basalt)
B(2,21,0,minecraft:basalt)
B(2,22,0,minecraft:basalt)
B(2,23,0,minecraft:basalt)
B(2,24,0,minecraft:basalt)
B(2,25,0,minecraft:basalt)
B(2,26,0,minecraft:basalt)
B(2,27,0,minecraft:basalt)
B(2,28,0,minecraft:basalt)
B(2,29,0,minecraft:basalt)
B(2,30,0,minecraft:basalt)
B(2,31,0,minecraft:basalt)
B(2,32,0,minecraft:basalt)
B(2,33,0,minecraft:basalt)
B(2,34,0,minecraft:basalt)
B(2,35,0,minecraft:basalt)
B(2,36,0,minecraft:basalt)
B(2,37,0,minecraft:basalt)
B(2,38,0,minecraft:basalt)
B(2,39,0,minecraft:basalt)
B(2,40,0,minecraft:basalt)
B(2,41,0,minecraft:basalt)
B(2,42,0,minecraft:basalt)
B(2,43,0,minecraft:basalt)
B(2,44,0,minecraft:basalt)
B(2,45,0,minecraft:basalt)
B(2,46,0,minecraft:basalt)
B(2,47,0,minecraft:basalt)
B(2,48,0,minecraft:basalt)
B(2,49,0,minecraft:basalt)
B(2,50,0,minecraft:basalt)
B(2,51,0,minecraft:basalt)
B(2,0,1,minecraft:basalt)
B(2,1,1,minecraft:basalt)
B(2,2,1,minecraft:basalt)
B(2,3,1,minecraft:basalt)
B(2,4,1,minecraft:basalt)
B(2,5,1,minecraft:basalt)
B(2,6,1,minecraft:basalt)
B(2,7,1,minecraft:basalt)
B(2,8,1,minecraft:basalt)
B(2,9,1,minecraft:basalt)
B(2,10,1,minecraft:basalt)
B(2,11,1,minecraft:basalt)
B(2,12,1,minecraft:basalt)
B(2,13,1,minecraft:basalt)
B(2,14,1,minecraft:basalt)
B(2,15,1,minecraft:basalt)
B(2,16,1,minecraft:basalt)
B(2,17,1,minecraft:basalt)
B(2,18,1,minecraft:basalt)
B(2,19,1,minecraft:basalt)
B(2,20,1,minecraft:basalt)
B(2,21,1,minecraft:basalt)
B(2,22,1,minecraft:basalt)
B(2,23,1,minecraft:basalt)
B(2,24,1,minecraft:basalt)
B(2,25,1,minecraft:basalt)
B(2,26,1,minecraft:basalt)
B(2,27,1,minecraft:basalt)
B(2,28,1,minecraft:basalt)
B(2,29,1,minecraft:basalt)
B(2,30,1,minecraft:basalt)
B(2,31,1,minecraft:basalt)
B(2,32,1,minecraft:basalt)
B(2,33,1,minecraft:basalt)
B(2,34,1,minecraft:basalt)
B(2,35,1,minecraft:basalt)
B(2,36,1,minecraft:basalt)
B(2,37,1,minecraft:basalt)
B(2,38,1,minecraft:basalt)
B(2,39,1,minecraft:basalt)
B(2,40,1,minecraft:basalt)
B(2,41,1,minecraft:basalt)
B(2,42,1,minecraft:basalt)
B(2,43,1,minecraft:basalt)
B(2,44,1,minecraft:basalt)
B(2,45,1,minecraft:basalt)
B(2,46,1,minecraft:basalt)
B(2,47,1,minecraft:basalt)
B(2,48,1,minecraft:basalt)
B(2,49,1,minecraft:basalt)
B(2,50,1,minecraft:basalt)
B(2,51,1,minecraft:basalt)
B(2,52,1,minecraft:basalt)
B(2,53,1,minecraft:basalt)
B(2,54,1,minecraft:basalt)
B(2,55,1,minecraft:basalt)
B(2,56,1,minecraft:basalt)
B(2,57,1,minecraft:basalt)
B(2,58,1,minecraft:basalt)
B(2,59,1,minecraft:basalt)
B(2,60,1,minecraft:basalt)
B(2,61,1,minecraft:basalt)
B(2,0,2,minecraft:basalt)
B(2,1,2,minecraft:basalt)
B(2,2,2,minecraft:basalt)
B(2,3,2,minecraft:basalt)
B(2,4,2,minecraft:basalt)
B(2,5,2,minecraft:basalt)
B(2,6,2,minecraft:basalt)
B(2,7,2,minecraft:basalt)
B(2,8,2,minecraft:basalt)
B(2,9,2,minecraft:basalt)
B(2,10,2,minecraft:basalt)
B(2,11,2,minecraft:basalt)
B(2,12,2,minecraft:basalt)
B(2,13,2,minecraft:basalt)
B(2,14,2,minecraft:basalt)
B(2,15,2,minecraft:basalt)
B(2,16,2,minecraft:basalt)
B(2,17,2,minecraft:basalt)
B(2,18,2,minecraft:basalt)
B(2,19,2,minecraft:basalt)
B(2,20,2,minecraft:basalt)
B(2,21,2,minecraft:basalt)
B(2,22,2,minecraft:basalt)
B(2,23,2,minecraft:basalt)
B(2,24,2,minecraft:basalt)
B(2,25,2,minecraft:basalt)
B(2,26,2,minecraft:basalt)
B(2,27,2,minecraft:basalt)
B(2,28,2,minecraft:basalt)
B(2,29,2,minecraft:basalt)
B(2,30,2,minecraft:basalt)
B(2,31,2,minecraft:basalt)
B(2,32,2,minecraft:basalt)
B(2,33,2,minecraft:basalt)
B(2,34,2,minecraft:basalt)
B(2,35,2,minecraft:basalt)
B(2,36,2,minecraft:basalt)
B(2,37,2,minecraft:basalt)
B(2,38,2,minecraft:basalt)
B(2,39,2,minecraft:basalt)
B(2,40,2,minecraft:basalt)
B(2,41,2,minecraft:basalt)
B(2,42,2,minecraft:basalt)
B(2,43,2,minecraft:basalt)
B(2,44,2,minecraft:basalt)
B(2,45,2,minecraft:basalt)
B(2,46,2,minecraft:basalt)
B(2,47,2,minecraft:basalt)
B(2,48,2,minecraft:basalt)
B(2,49,2,minecraft:basalt)
B(2,50,2,minecraft:basalt)
B(2,51,2,minecraft:basalt)
B(2,52,2,minecraft:basalt)
B(2,53,2,minecraft:basalt)
B(2,54,2,minecraft:basalt)
B(2,55,2,minecraft:basalt)
B(2,56,2,minecraft:basalt)
B(2,57,2,minecraft:basalt)
B(2,58,2,minecraft:basalt)
B(2,59,2,minecraft:basalt)
B(2,60,2,minecraft:basalt)
B(2,61,2,minecraft:basalt)
B(2,62,2,minecraft:basalt)
B(2,63,2,minecraft:basalt)
B(2,64,2,minecraft:basalt)
B(2,65,2,minecraft:basalt)
B(2,66,2,minecraft:basalt)
B(2,67,2,minecraft:basalt)
B(2,68,2,minecraft:basalt)
B(2,0,3,minecraft:basalt)
B(2,1,3,minecraft:basalt)
B(2,2,3,minecraft:basalt)
B(2,3,3,minecraft:basalt)
B(2,4,3,minecraft:basalt)
B(2,5,3,minecraft:basalt)
B(2,6,3,minecraft:basalt)
B(2,7,3,minecraft:basalt)
B(2,8,3,minecraft:basalt)
B(2,9,3,minecraft:basalt)
B(2,10,3,minecraft:basalt)
B(2,11,3,minecraft:basalt)
B(2,12,3,minecraft:basalt)
B(2,13,3,minecraft:basalt)
B(2,14,3,minecraft:basalt)
B(2,15,3,minecraft:basalt)
B(2,16,3,minecraft:basalt)
B(2,17,3,minecraft:basalt)
B(2,18,3,minecraft:basalt)
B(2,19,3,minecraft:basalt)
B(2,20,3,minecraft:basalt)
B(2,21,3,minecraft:basalt)
B(2,22,3,minecraft:basalt)
B(2,23,3,minecraft:basalt)
B(2,24,3,minecraft:basalt)
B(2,25,3,minecraft:basalt)
B(2,26,3,minecraft:basalt)
B(2,27,3,minecraft:basalt)
B(2,28,3,minecraft:basalt)
B(2,29,3,minecraft:basalt)
B(2,30,3,minecraft:basalt)
B(2,31,3,minecraft:basalt)
B(2,32,3,minecraft:basalt)
B(2,33,3,minecraft:basalt)
B(2,34,3,minecraft:basalt)
B(2,35,3,minecraft:basalt)
B(2,36,3,minecraft:basalt)
B(2,37,3,minecraft:basalt)
B(2,38,3,minecraft:basalt)
B(2,39,3,minecraft:basalt)
B(2,40,3,minecraft:basalt)
B(2,41,3,minecraft:basalt)
B(2,42,3,minecraft:basalt)
B(2,43,3,minecraft:basalt)
B(2,44,3,minecraft:basalt)
B(2,45,3,minecraft:basalt)
B(2,46,3,minecraft:basalt)
B(2,47,3,minecraft:basalt)
B(2,48,3,minecraft:basalt)
B(2,49,3,minecraft:basalt)
B(2,50,3,minecraft:basalt)
B(2,51,3,minecraft:basalt)
B(2,52,3,minecraft:basalt)
B(2,53,3,minecraft:basalt)
B(2,54,3,minecraft:basalt)
B(2,55,3,minecraft:basalt)
B(2,56,3,minecraft:basalt)
B(2,57,3,minecraft:basalt)
B(2,58,3,minecraft:basalt)
B(2,59,3,minecraft:basalt)
B(2,60,3,minecraft:basalt)
B(2,61,3,minecraft:basalt)
B(2,62,3,minecraft:basalt)
B(2,63,3,minecraft:basalt)
B(2,64,3,minecraft:basalt)
B(2,65,3,minecraft:basalt)
B(2,66,3,minecraft:basalt)
B(2,67,3,minecraft:basalt)
B(2,68,3,minecraft:basalt)
B(2,69,3,minecraft:basalt)
B(2,70,3,minecraft:basalt)
B(2,0,4,minecraft:basalt)
B(2,1,4,minecraft:basalt)
B(2,2,4,minecraft:basalt)
B(2,3,4,minecraft:basalt)
B(2,4,4,minecraft:basalt)
B(2,5,4,minecraft:basalt)
B(2,6,4,minecraft:basalt)
B(2,7,4,minecraft:basalt)
B(2,8,4,minecraft:basalt)
B(2,9,4,minecraft:basalt)
B(2,10,4,minecraft:basalt)
B(2,11,4,minecraft:basalt)
B(2,12,4,minecraft:basalt)
B(2,13,4,minecraft:basalt)
B(2,14,4,minecraft:basalt)
B(2,15,4,minecraft:basalt)
B(2,16,4,minecraft:basalt)
B(2,17,4,minecraft:basalt)
B(2,18,4,minecraft:basalt)
B(2,19,4,minecraft:basalt)
B(2,20,4,minecraft:basalt)
B(2,21,4,minecraft:basalt)
B(2,22,4,minecraft:basalt)
B(2,23,4,minecraft:basalt)
B(2,24,4,minecraft:basalt)
B(2,25,4,minecraft:basalt)
B(2,26,4,minecraft:basalt)
B(2,27,4,minecraft:basalt)
B(2,28,4,minecraft:basalt)
B(2,29,4,minecraft:basalt)
B(2,30,4,minecraft:basalt)
B(2,31,4,minecraft:basalt)
B(2,32,4,minecraft:basalt)
B(2,33,4,minecraft:basalt)
B(2,34,4,minecraft:basalt)
B(2,35,4,minecraft:basalt)
B(2,36,4,minecraft:basalt)
B(2,37,4,minecraft:basalt)
B(2,38,4,minecraft:basalt)
B(2,39,4,minecraft:basalt)
B(2,40,4,minecraft:basalt)
B(2,41,4,minecraft:basalt)
B(2,42,4,minecraft:basalt)
B(2,43,4,minecraft:basalt)
B(2,44,4,minecraft:basalt)
B(2,45,4,minecraft:basalt)
B(2,46,4,minecraft:basalt)
B(2,47,4,minecraft:basalt)
B(2,48,4,minecraft:basalt)
B(2,49,4,minecraft:basalt)
B(2,50,4,minecraft:basalt)
B(2,51,4,minecraft:basalt)
B(2,52,4,minecraft:basalt)
B(2,53,4,minecraft:basalt)
B(2,54,4,minecraft:basalt)
B(2,55,4,minecraft:basalt)
B(2,56,4,minecraft:basalt)
B(2,57,4,minecraft:basalt)
B(2,58,4,minecraft:basalt)
B(2,59,4,minecraft:basalt)
B(2,60,4,minecraft:basalt)
B(2,61,4,minecraft:basalt)
B(2,62,4,minecraft:basalt)
B(2,63,4,minecraft:basalt)
B(2,64,4,minecraft:basalt)
B(2,65,4,minecraft:basalt)
B(2,66,4,minecraft:basalt)
B(2,67,4,minecraft:basalt)
B(2,68,4,minecraft:basalt)
B(2,69,4,minecraft:basalt)
B(2,70,4,minecraft:basalt)
B(2,0,5,minecraft:basalt)
B(2,1,5,minecraft:basalt)
B(2,2,5,minecraft:basalt)
B(2,3,5,minecraft:basalt)
B(2,4,5,minecraft:basalt)
B(2,5,5,minecraft:basalt)
B(2,6,5,minecraft:basalt)
B(2,7,5,minecraft:basalt)
B(2,8,5,minecraft:basalt)
B(2,9,5,minecraft:basalt)
B(2,10,5,minecraft:basalt)
B(2,11,5,minecraft:basalt)
B(2,12,5,minecraft:basalt)
B(2,13,5,minecraft:basalt)
B(2,14,5,minecraft:basalt)
B(2,15,5,minecraft:basalt)
B(2,16,5,minecraft:basalt)
B(2,17,5,minecraft:basalt)
B(2,18,5,minecraft:basalt)
B(2,19,5,minecraft:basalt)
B(2,20,5,minecraft:basalt)
B(2,21,5,minecraft:basalt)
B(2,22,5,minecraft:basalt)
B(2,23,5,minecraft:basalt)
B(2,24,5,minecraft:basalt)
B(2,25,5,minecraft:basalt)
B(2,26,5,minecraft:basalt)
B(2,27,5,minecraft:basalt)
B(2,28,5,minecraft:basalt)
B(2,29,5,minecraft:basalt)
B(2,30,5,minecraft:basalt)
B(2,31,5,minecraft:basalt)
B(2,32,5,minecraft:basalt)
B(2,33,5,minecraft:basalt)
B(2,34,5,minecraft:basalt)
B(2,35,5,minecraft:basalt)
B(2,36,5,minecraft:basalt)
B(2,37,5,minecraft:basalt)
B(2,38,5,minecraft:basalt)
B(2,39,5,minecraft:basalt)
B(2,40,5,minecraft:basalt)
B(2,41,5,minecraft:basalt)
B(2,42,5,minecraft:basalt)
B(2,43,5,minecraft:basalt)
B(2,44,5,minecraft:basalt)
B(2,45,5,minecraft:basalt)
B(2,46,5,minecraft:basalt)
B(2,47,5,minecraft:basalt)
B(2,48,5,minecraft:basalt)
B(2,49,5,minecraft:basalt)
B(2,50,5,minecraft:basalt)
B(2,51,5,minecraft:basalt)
B(2,52,5,minecraft:basalt)
B(2,53,5,minecraft:basalt)
B(2,54,5,minecraft:basalt)
B(2,55,5,minecraft:basalt)
B(2,56,5,minecraft:basalt)
B(2,57,5,minecraft:basalt)
B(2,58,5,minecraft:basalt)
B(2,59,5,minecraft:basalt)
B(2,60,5,minecraft:basalt)
B(2,61,5,minecraft:basalt)
B(2,62,5,minecraft:basalt)
B(2,63,5,minecraft:basalt)
B(2,64,5,minecraft:basalt)
B(2,0,6,minecraft:basalt)
B(2,1,6,minecraft:basalt)
B(2,2,6,minecraft:basalt)
B(2,3,6,minecraft:basalt)
B(2,4,6,minecraft:basalt)
B(2,5,6,minecraft:basalt)
B(2,6,6,minecraft:basalt)
B(2,7,6,minecraft:basalt)
B(2,8,6,minecraft:basalt)
B(2,9,6,minecraft:basalt)
B(2,10,6,minecraft:basalt)
B(2,11,6,minecraft:basalt)
B(2,12,6,minecraft:basalt)
B(2,13,6,minecraft:basalt)
B(2,14,6,minecraft:basalt)
B(2,15,6,minecraft:basalt)
B(2,16,6,minecraft:basalt)
B(2,17,6,minecraft:basalt)
B(2,18,6,minecraft:basalt)
B(2,19,6,minecraft:basalt)
B(2,20,6,minecraft:basalt)
B(2,21,6,minecraft:basalt)
B(2,22,6,minecraft:basalt)
B(2,23,6,minecraft:basalt)
B(2,24,6,minecraft:basalt)
B(2,25,6,minecraft:basalt)
B(2,26,6,minecraft:basalt)
B(2,27,6,minecraft:basalt)
B(2,28,6,minecraft:basalt)
B(2,29,6,minecraft:basalt)
B(2,30,6,minecraft:basalt)
B(2,31,6,minecraft:basalt)
B(2,32,6,minecraft:basalt)
B(2,33,6,minecraft:basalt)
B(2,34,6,minecraft:basalt)
B(2,35,6,minecraft:basalt)
B(2,36,6,minecraft:basalt)
B(2,37,6,minecraft:basalt)
B(2,38,6,minecraft:basalt)
B(2,39,6,minecraft:basalt)
B(2,40,6,minecraft:basalt)
B(2,41,6,minecraft:basalt)
B(2,42,6,minecraft:basalt)
B(2,43,6,minecraft:basalt)
B(2,44,6,minecraft:basalt)
B(2,45,6,minecraft:basalt)
B(2,46,6,minecraft:basalt)
B(2,47,6,minecraft:basalt)
B(2,48,6,minecraft:basalt)
B(2,49,6,minecraft:basalt)
B(2,50,6,minecraft:basalt)
B(2,51,6,minecraft:basalt)
B(2,52,6,minecraft:basalt)
B(2,53,6,minecraft:basalt)
B(2,54,6,minecraft:basalt)
B(2,55,6,minecraft:basalt)
B(2,56,6,minecraft:basalt)
B(2,57,6,minecraft:basalt)
B(2,58,6,minecraft:basalt)
B(2,59,6,minecraft:basalt)
B(2,60,6,minecraft:basalt)
B(2,61,6,minecraft:basalt)
B(2,0,7,minecraft:basalt)
B(2,1,7,minecraft:basalt)
B(2,2,7,minecraft:basalt)
B(2,3,7,minecraft:basalt)
B(2,4,7,minecraft:basalt)
B(2,5,7,minecraft:basalt)
B(2,6,7,minecraft:basalt)
B(2,7,7,minecraft:basalt)
B(2,8,7,minecraft:basalt)
B(2,9,7,minecraft:basalt)
B(2,10,7,minecraft:basalt)
B(2,11,7,minecraft:basalt)
B(2,12,7,minecraft:basalt)
B(2,13,7,minecraft:basalt)
B(2,14,7,minecraft:basalt)
B(2,15,7,minecraft:basalt)
B(2,16,7,minecraft:basalt)
B(2,17,7,minecraft:basalt)
B(2,18,7,minecraft:basalt)
B(2,19,7,minecraft:basalt)
B(2,20,7,minecraft:basalt)
B(2,21,7,minecraft:basalt)
B(2,22,7,minecraft:basalt)
B(2,23,7,minecraft:basalt)
B(2,24,7,minecraft:basalt)
B(2,25,7,minecraft:basalt)
B(2,26,7,minecraft:basalt)
B(2,27,7,minecraft:basalt)
B(2,28,7,minecraft:basalt)
B(2,29,7,minecraft:basalt)
B(2,30,7,minecraft:basalt)
B(2,31,7,minecraft:basalt)
B(2,32,7,minecraft:basalt)
B(2,33,7,minecraft:basalt)
B(2,34,7,minecraft:basalt)
B(2,35,7,minecraft:basalt)
B(2,36,7,minecraft:basalt)
B(2,37,7,minecraft:basalt)
B(2,38,7,minecraft:basalt)
B(2,39,7,minecraft:basalt)
B(2,40,7,minecraft:basalt)
B(2,41,7,minecraft:basalt)
B(2,42,7,minecraft:basalt)
B(2,43,7,minecraft:basalt)
B(2,44,7,minecraft:basalt)
B(2,45,7,minecraft:basalt)
B(2,46,7,minecraft:basalt)
B(2,47,7,minecraft:basalt)
B(2,48,7,minecraft:basalt)
B(2,49,7,minecraft:basalt)
B(2,50,7,minecraft:basalt)
B(2,51,7,minecraft:basalt)
B(2,52,7,minecraft:basalt)
B(2,53,7,minecraft:basalt)
B(2,54,7,minecraft:basalt)
B(2,55,7,minecraft:basalt)
B(2,56,7,minecraft:basalt)
B(2,57,7,minecraft:basalt)
B(2,58,7,minecraft:basalt)
B(2,59,7,minecraft:basalt)
B(2,60,7,minecraft:basalt)
B(2,61,7,minecraft:basalt)
B(2,62,7,minecraft:basalt)
B(2,0,8,minecraft:basalt)
B(2,1,8,minecraft:basalt)
B(2,2,8,minecraft:basalt)
B(2,3,8,minecraft:basalt)
B(2,4,8,minecraft:basalt)
B(2,5,8,minecraft:basalt)
B(2,6,8,minecraft:basalt)
B(2,7,8,minecraft:basalt)
B(2,8,8,minecraft:basalt)
B(2,9,8,minecraft:basalt)
B(2,10,8,minecraft:basalt)
B(2,11,8,minecraft:basalt)
B(2,12,8,minecraft:basalt)
B(2,13,8,minecraft:basalt)
B(2,14,8,minecraft:basalt)
B(2,15,8,minecraft:basalt)
B(2,16,8,minecraft:basalt)
B(2,17,8,minecraft:basalt)
B(2,18,8,minecraft:basalt)
B(2,19,8,minecraft:basalt)
B(2,20,8,minecraft:basalt)
B(2,21,8,minecraft:basalt)
B(2,22,8,minecraft:basalt)
B(2,23,8,minecraft:basalt)
B(2,24,8,minecraft:basalt)
B(2,25,8,minecraft:basalt)
B(2,26,8,minecraft:basalt)
B(2,27,8,minecraft:basalt)
B(2,28,8,minecraft:basalt)
B(2,29,8,minecraft:basalt)
B(2,30,8,minecraft:basalt)
B(2,31,8,minecraft:basalt)
B(2,32,8,minecraft:basalt)
B(2,33,8,minecraft:basalt)
B(2,34,8,minecraft:basalt)
B(2,35,8,minecraft:basalt)
B(2,36,8,minecraft:basalt)
B(2,37,8,minecraft:basalt)
B(2,38,8,minecraft:basalt)
B(2,39,8,minecraft:basalt)
B(2,40,8,minecraft:basalt)
B(2,41,8,minecraft:basalt)
B(2,42,8,minecraft:basalt)
B(2,43,8,minecraft:basalt)
B(2,44,8,minecraft:basalt)
B(2,45,8,minecraft:basalt)
B(2,46,8,minecraft:basalt)
B(2,47,8,minecraft:basalt)
B(2,48,8,minecraft:basalt)
B(2,49,8,minecraft:basalt)
B(2,50,8,minecraft:basalt)
B(2,51,8,minecraft:basalt)
B(2,52,8,minecraft:basalt)
B(2,53,8,minecraft:basalt)
B(2,54,8,minecraft:basalt)
B(2,55,8,minecraft:basalt)
B(2,56,8,minecraft:basalt)
B(2,57,8,minecraft:basalt)
B(2,58,8,minecraft:basalt)
B(2,59,8,minecraft:basalt)
B(2,60,8,minecraft:basalt)
B(2,61,8,minecraft:basalt)
B(2,62,8,minecraft:basalt)
B(3,0,-7,minecraft:basalt)
B(3,1,-7,minecraft:basalt)
B(3,2,-7,minecraft:basalt)
B(3,3,-7,minecraft:basalt)
B(3,4,-7,minecraft:basalt)
B(3,5,-7,minecraft:basalt)
B(3,6,-7,minecraft:basalt)
B(3,7,-7,minecraft:basalt)
B(3,8,-7,minecraft:basalt)
B(3,9,-7,minecraft:basalt)
B(3,10,-7,minecraft:basalt)
B(3,11,-7,minecraft:basalt)
B(3,12,-7,minecraft:basalt)
B(3,13,-7,minecraft:basalt)
B(3,14,-7,minecraft:basalt)
B(3,15,-7,minecraft:basalt)
B(3,16,-7,minecraft:basalt)
B(3,17,-7,minecraft:basalt)
B(3,18,-7,minecraft:basalt)
B(3,19,-7,minecraft:basalt)
B(3,20,-7,minecraft:basalt)
B(3,21,-7,minecraft:basalt)
B(3,22,-7,minecraft:basalt)
B(3,23,-7,minecraft:basalt)
B(3,24,-7,minecraft:basalt)
B(3,25,-7,minecraft:basalt)
B(3,26,-7,minecraft:basalt)
B(3,27,-7,minecraft:basalt)
B(3,28,-7,minecraft:basalt)
B(3,29,-7,minecraft:basalt)
B(3,30,-7,minecraft:basalt)
B(3,31,-7,minecraft:basalt)
B(3,32,-7,minecraft:basalt)
B(3,33,-7,minecraft:basalt)
B(3,34,-7,minecraft:basalt)
B(3,35,-7,minecraft:basalt)
B(3,36,-7,minecraft:basalt)
B(3,37,-7,minecraft:basalt)
B(3,38,-7,minecraft:basalt)
B(3,39,-7,minecraft:basalt)
B(3,40,-7,minecraft:basalt)
B(3,41,-7,minecraft:basalt)
B(3,42,-7,minecraft:basalt)
B(3,43,-7,minecraft:basalt)
B(3,44,-7,minecraft:basalt)
B(3,45,-7,minecraft:basalt)
B(3,46,-7,minecraft:basalt)
B(3,47,-7,minecraft:basalt)
B(3,48,-7,minecraft:basalt)
B(3,49,-7,minecraft:basalt)
B(3,50,-7,minecraft:basalt)
B(3,51,-7,minecraft:basalt)
B(3,52,-7,minecraft:basalt)
B(3,0,-6,minecraft:basalt)
B(3,1,-6,minecraft:basalt)
B(3,2,-6,minecraft:basalt)
B(3,3,-6,minecraft:basalt)
B(3,4,-6,minecraft:basalt)
B(3,5,-6,minecraft:basalt)
B(3,6,-6,minecraft:basalt)
B(3,7,-6,minecraft:basalt)
B(3,8,-6,minecraft:basalt)
B(3,9,-6,minecraft:basalt)
B(3,10,-6,minecraft:basalt)
B(3,11,-6,minecraft:basalt)
B(3,12,-6,minecraft:basalt)
B(3,13,-6,minecraft:basalt)
B(3,14,-6,minecraft:basalt)
B(3,15,-6,minecraft:basalt)
B(3,16,-6,minecraft:basalt)
B(3,17,-6,minecraft:basalt)
B(3,18,-6,minecraft:basalt)
B(3,19,-6,minecraft:basalt)
B(3,20,-6,minecraft:basalt)
B(3,21,-6,minecraft:basalt)
B(3,22,-6,minecraft:basalt)
B(3,23,-6,minecraft:basalt)
B(3,24,-6,minecraft:basalt)
B(3,25,-6,minecraft:basalt)
B(3,26,-6,minecraft:basalt)
B(3,27,-6,minecraft:basalt)
B(3,28,-6,minecraft:basalt)
B(3,29,-6,minecraft:basalt)
B(3,30,-6,minecraft:basalt)
B(3,31,-6,minecraft:basalt)
B(3,32,-6,minecraft:basalt)
B(3,33,-6,minecraft:basalt)
B(3,34,-6,minecraft:basalt)
B(3,35,-6,minecraft:basalt)
B(3,36,-6,minecraft:basalt)
B(3,37,-6,minecraft:basalt)
B(3,38,-6,minecraft:basalt)
B(3,39,-6,minecraft:basalt)
B(3,40,-6,minecraft:basalt)
B(3,41,-6,minecraft:basalt)
B(3,42,-6,minecraft:basalt)
B(3,43,-6,minecraft:basalt)
B(3,44,-6,minecraft:basalt)
B(3,45,-6,minecraft:basalt)
B(3,46,-6,minecraft:basalt)
B(3,47,-6,minecraft:basalt)
B(3,48,-6,minecraft:basalt)
B(3,49,-6,minecraft:basalt)
B(3,50,-6,minecraft:basalt)
B(3,51,-6,minecraft:basalt)
B(3,52,-6,minecraft:basalt)
B(3,53,-6,minecraft:basalt)
B(3,54,-6,minecraft:basalt)
B(3,55,-6,minecraft:basalt)
B(3,56,-6,minecraft:basalt)
B(3,57,-6,minecraft:basalt)
B(3,58,-6,minecraft:basalt)
B(3,59,-6,minecraft:basalt)
B(3,0,-5,minecraft:basalt)
B(3,1,-5,minecraft:basalt)
B(3,2,-5,minecraft:basalt)
B(3,3,-5,minecraft:basalt)
B(3,4,-5,minecraft:basalt)
B(3,5,-5,minecraft:basalt)
B(3,6,-5,minecraft:basalt)
B(3,7,-5,minecraft:basalt)
B(3,8,-5,minecraft:basalt)
B(3,9,-5,minecraft:basalt)
B(3,10,-5,minecraft:basalt)
B(3,11,-5,minecraft:basalt)
B(3,12,-5,minecraft:basalt)
B(3,13,-5,minecraft:basalt)
B(3,14,-5,minecraft:basalt)
B(3,15,-5,minecraft:basalt)
B(3,16,-5,minecraft:basalt)
B(3,17,-5,minecraft:basalt)
B(3,18,-5,minecraft:basalt)
B(3,19,-5,minecraft:basalt)
B(3,20,-5,minecraft:basalt)
B(3,21,-5,minecraft:basalt)
B(3,22,-5,minecraft:basalt)
B(3,23,-5,minecraft:basalt)
B(3,24,-5,minecraft:basalt)
B(3,25,-5,minecraft:basalt)
B(3,26,-5,minecraft:basalt)
B(3,27,-5,minecraft:basalt)
B(3,28,-5,minecraft:basalt)
B(3,29,-5,minecraft:basalt)
B(3,30,-5,minecraft:basalt)
B(3,31,-5,minecraft:basalt)
B(3,32,-5,minecraft:basalt)
B(3,33,-5,minecraft:basalt)
B(3,34,-5,minecraft:basalt)
B(3,35,-5,minecraft:basalt)
B(3,36,-5,minecraft:basalt)
B(3,37,-5,minecraft:basalt)
B(3,38,-5,minecraft:basalt)
B(3,39,-5,minecraft:basalt)
B(3,40,-5,minecraft:basalt)
B(3,41,-5,minecraft:basalt)
B(3,42,-5,minecraft:basalt)
B(3,43,-5,minecraft:basalt)
B(3,44,-5,minecraft:basalt)
B(3,45,-5,minecraft:basalt)
B(3,46,-5,minecraft:basalt)
B(3,47,-5,minecraft:basalt)
B(3,48,-5,minecraft:basalt)
B(3,49,-5,minecraft:basalt)
B(3,50,-5,minecraft:basalt)
B(3,51,-5,minecraft:basalt)
B(3,52,-5,minecraft:basalt)
B(3,53,-5,minecraft:basalt)
B(3,54,-5,minecraft:basalt)
B(3,55,-5,minecraft:basalt)
B(3,56,-5,minecraft:basalt)
B(3,57,-5,minecraft:basalt)
B(3,58,-5,minecraft:basalt)
B(3,59,-5,minecraft:basalt)
B(3,60,-5,minecraft:basalt)
B(3,61,-5,minecraft:basalt)
B(3,0,-4,minecraft:basalt)
B(3,1,-4,minecraft:basalt)
B(3,2,-4,minecraft:basalt)
B(3,3,-4,minecraft:basalt)
B(3,4,-4,minecraft:basalt)
B(3,5,-4,minecraft:basalt)
B(3,6,-4,minecraft:basalt)
B(3,7,-4,minecraft:basalt)
B(3,8,-4,minecraft:basalt)
B(3,9,-4,minecraft:basalt)
B(3,10,-4,minecraft:basalt)
B(3,11,-4,minecraft:basalt)
B(3,12,-4,minecraft:basalt)
B(3,13,-4,minecraft:basalt)
B(3,14,-4,minecraft:basalt)
B(3,15,-4,minecraft:basalt)
B(3,16,-4,minecraft:basalt)
B(3,17,-4,minecraft:basalt)
B(3,18,-4,minecraft:basalt)
B(3,19,-4,minecraft:basalt)
B(3,20,-4,minecraft:basalt)
B(3,21,-4,minecraft:basalt)
B(3,22,-4,minecraft:basalt)
B(3,23,-4,minecraft:basalt)
B(3,24,-4,minecraft:basalt)
B(3,25,-4,minecraft:basalt)
B(3,26,-4,minecraft:basalt)
B(3,27,-4,minecraft:basalt)
B(3,28,-4,minecraft:basalt)
B(3,29,-4,minecraft:basalt)
B(3,30,-4,minecraft:basalt)
B(3,31,-4,minecraft:basalt)
B(3,32,-4,minecraft:basalt)
B(3,33,-4,minecraft:basalt)
B(3,34,-4,minecraft:basalt)
B(3,35,-4,minecraft:basalt)
B(3,36,-4,minecraft:basalt)
B(3,37,-4,minecraft:basalt)
B(3,38,-4,minecraft:basalt)
B(3,39,-4,minecraft:basalt)
B(3,40,-4,minecraft:basalt)
B(3,41,-4,minecraft:basalt)
B(3,42,-4,minecraft:basalt)
B(3,43,-4,minecraft:basalt)
B(3,44,-4,minecraft:basalt)
B(3,45,-4,minecraft:basalt)
B(3,46,-4,minecraft:basalt)
B(3,47,-4,minecraft:basalt)
B(3,48,-4,minecraft:basalt)
B(3,49,-4,minecraft:basalt)
B(3,50,-4,minecraft:basalt)
B(3,51,-4,minecraft:basalt)
B(3,52,-4,minecraft:basalt)
B(3,53,-4,minecraft:basalt)
B(3,54,-4,minecraft:basalt)
B(3,55,-4,minecraft:basalt)
B(3,56,-4,minecraft:basalt)
B(3,57,-4,minecraft:basalt)
B(3,58,-4,minecraft:basalt)
B(3,59,-4,minecraft:basalt)
B(3,60,-4,minecraft:basalt)
B(3,61,-4,minecraft:basalt)
B(3,0,-3,minecraft:basalt)
B(3,1,-3,minecraft:basalt)
B(3,2,-3,minecraft:basalt)
B(3,3,-3,minecraft:basalt)
B(3,4,-3,minecraft:basalt)
B(3,5,-3,minecraft:basalt)
B(3,6,-3,minecraft:basalt)
B(3,7,-3,minecraft:basalt)
B(3,8,-3,minecraft:basalt)
B(3,9,-3,minecraft:basalt)
B(3,10,-3,minecraft:basalt)
B(3,11,-3,minecraft:basalt)
B(3,12,-3,minecraft:basalt)
B(3,13,-3,minecraft:basalt)
B(3,14,-3,minecraft:basalt)
B(3,15,-3,minecraft:basalt)
B(3,16,-3,minecraft:basalt)
B(3,17,-3,minecraft:basalt)
B(3,18,-3,minecraft:basalt)
B(3,19,-3,minecraft:basalt)
B(3,20,-3,minecraft:basalt)
B(3,21,-3,minecraft:basalt)
B(3,22,-3,minecraft:basalt)
B(3,23,-3,minecraft:basalt)
B(3,24,-3,minecraft:basalt)
B(3,25,-3,minecraft:basalt)
B(3,26,-3,minecraft:basalt)
B(3,27,-3,minecraft:basalt)
B(3,28,-3,minecraft:basalt)
B(3,29,-3,minecraft:basalt)
B(3,30,-3,minecraft:basalt)
B(3,31,-3,minecraft:basalt)
B(3,32,-3,minecraft:basalt)
B(3,33,-3,minecraft:basalt)
B(3,34,-3,minecraft:basalt)
B(3,35,-3,minecraft:basalt)
B(3,36,-3,minecraft:basalt)
B(3,37,-3,minecraft:basalt)
B(3,38,-3,minecraft:basalt)
B(3,39,-3,minecraft:basalt)
B(3,40,-3,minecraft:basalt)
B(3,41,-3,minecraft:basalt)
B(3,42,-3,minecraft:basalt)
B(3,43,-3,minecraft:basalt)
B(3,44,-3,minecraft:basalt)
B(3,45,-3,minecraft:basalt)
B(3,46,-3,minecraft:basalt)
B(3,47,-3,minecraft:basalt)
B(3,48,-3,minecraft:basalt)
B(3,49,-3,minecraft:basalt)
B(3,50,-3,minecraft:basalt)
B(3,51,-3,minecraft:basalt)
B(3,52,-3,minecraft:basalt)
B(3,53,-3,minecraft:basalt)
B(3,54,-3,minecraft:basalt)
B(3,55,-3,minecraft:basalt)
B(3,56,-3,minecraft:basalt)
B(3,57,-3,minecraft:basalt)
B(3,58,-3,minecraft:basalt)
B(3,59,-3,minecraft:basalt)
B(3,60,-3,minecraft:basalt)
B(3,0,-2,minecraft:basalt)
B(3,1,-2,minecraft:basalt)
B(3,2,-2,minecraft:basalt)
B(3,3,-2,minecraft:basalt)
B(3,4,-2,minecraft:basalt)
B(3,5,-2,minecraft:basalt)
B(3,6,-2,minecraft:basalt)
B(3,7,-2,minecraft:basalt)
B(3,8,-2,minecraft:basalt)
B(3,9,-2,minecraft:basalt)
B(3,10,-2,minecraft:basalt)
B(3,11,-2,minecraft:basalt)
B(3,12,-2,minecraft:basalt)
B(3,13,-2,minecraft:basalt)
B(3,14,-2,minecraft:basalt)
B(3,15,-2,minecraft:basalt)
B(3,16,-2,minecraft:basalt)
B(3,17,-2,minecraft:basalt)
B(3,18,-2,minecraft:basalt)
B(3,19,-2,minecraft:basalt)
B(3,20,-2,minecraft:basalt)
B(3,21,-2,minecraft:basalt)
B(3,22,-2,minecraft:basalt)
B(3,23,-2,minecraft:basalt)
B(3,24,-2,minecraft:basalt)
B(3,25,-2,minecraft:basalt)
B(3,26,-2,minecraft:basalt)
B(3,27,-2,minecraft:basalt)
B(3,28,-2,minecraft:basalt)
B(3,29,-2,minecraft:basalt)
B(3,30,-2,minecraft:basalt)
B(3,31,-2,minecraft:basalt)
B(3,32,-2,minecraft:basalt)
B(3,33,-2,minecraft:basalt)
B(3,34,-2,minecraft:basalt)
B(3,35,-2,minecraft:basalt)
B(3,36,-2,minecraft:basalt)
B(3,37,-2,minecraft:basalt)
B(3,38,-2,minecraft:basalt)
B(3,39,-2,minecraft:basalt)
B(3,40,-2,minecraft:basalt)
B(3,41,-2,minecraft:basalt)
B(3,42,-2,minecraft:basalt)
B(3,43,-2,minecraft:basalt)
B(3,44,-2,minecraft:basalt)
B(3,45,-2,minecraft:basalt)
B(3,46,-2,minecraft:basalt)
B(3,47,-2,minecraft:basalt)
B(3,48,-2,minecraft:basalt)
B(3,49,-2,minecraft:basalt)
B(3,50,-2,minecraft:basalt)
B(3,51,-2,minecraft:basalt)
B(3,52,-2,minecraft:basalt)
B(3,53,-2,minecraft:basalt)
B(3,54,-2,minecraft:basalt)
B(3,55,-2,minecraft:basalt)
B(3,56,-2,minecraft:basalt)
B(3,57,-2,minecraft:basalt)
B(3,0,-1,minecraft:basalt)
B(3,1,-1,minecraft:basalt)
B(3,2,-1,minecraft:basalt)
B(3,3,-1,minecraft:basalt)
B(3,4,-1,minecraft:basalt)
B(3,5,-1,minecraft:basalt)
B(3,6,-1,minecraft:basalt)
B(3,7,-1,minecraft:basalt)
B(3,8,-1,minecraft:basalt)
B(3,9,-1,minecraft:basalt)
B(3,10,-1,minecraft:basalt)
B(3,11,-1,minecraft:basalt)
B(3,12,-1,minecraft:basalt)
B(3,13,-1,minecraft:basalt)
B(3,14,-1,minecraft:basalt)
B(3,15,-1,minecraft:basalt)
B(3,16,-1,minecraft:basalt)
B(3,17,-1,minecraft:basalt)
B(3,18,-1,minecraft:basalt)
B(3,19,-1,minecraft:basalt)
B(3,20,-1,minecraft:basalt)
B(3,21,-1,minecraft:basalt)
B(3,22,-1,minecraft:basalt)
B(3,23,-1,minecraft:basalt)
B(3,24,-1,minecraft:basalt)
B(3,25,-1,minecraft:basalt)
B(3,26,-1,minecraft:basalt)
B(3,27,-1,minecraft:basalt)
B(3,28,-1,minecraft:basalt)
B(3,29,-1,minecraft:basalt)
B(3,30,-1,minecraft:basalt)
B(3,31,-1,minecraft:basalt)
B(3,32,-1,minecraft:basalt)
B(3,33,-1,minecraft:basalt)
B(3,34,-1,minecraft:basalt)
B(3,35,-1,minecraft:basalt)
B(3,36,-1,minecraft:basalt)
B(3,37,-1,minecraft:basalt)
B(3,38,-1,minecraft:basalt)
B(3,39,-1,minecraft:basalt)
B(3,40,-1,minecraft:basalt)
B(3,41,-1,minecraft:basalt)
B(3,42,-1,minecraft:basalt)
B(3,43,-1,minecraft:basalt)
B(3,44,-1,minecraft:basalt)
B(3,45,-1,minecraft:basalt)
B(3,46,-1,minecraft:basalt)
B(3,47,-1,minecraft:basalt)
B(3,48,-1,minecraft:basalt)
B(3,49,-1,minecraft:basalt)
B(3,50,-1,minecraft:basalt)
B(3,51,-1,minecraft:basalt)
B(3,0,0,minecraft:basalt)
B(3,1,0,minecraft:basalt)
B(3,2,0,minecraft:basalt)
B(3,3,0,minecraft:basalt)
B(3,4,0,minecraft:basalt)
B(3,5,0,minecraft:basalt)
B(3,6,0,minecraft:basalt)
B(3,7,0,minecraft:basalt)
B(3,8,0,minecraft:basalt)
B(3,9,0,minecraft:basalt)
B(3,10,0,minecraft:basalt)
B(3,11,0,minecraft:basalt)
B(3,12,0,minecraft:basalt)
B(3,13,0,minecraft:basalt)
B(3,14,0,minecraft:basalt)
B(3,15,0,minecraft:basalt)
B(3,16,0,minecraft:basalt)
B(3,17,0,minecraft:basalt)
B(3,18,0,minecraft:basalt)
B(3,19,0,minecraft:basalt)
B(3,20,0,minecraft:basalt)
B(3,21,0,minecraft:basalt)
B(3,22,0,minecraft:basalt)
B(3,23,0,minecraft:basalt)
B(3,24,0,minecraft:basalt)
B(3,25,0,minecraft:basalt)
B(3,26,0,minecraft:basalt)
B(3,27,0,minecraft:basalt)
B(3,28,0,minecraft:basalt)
B(3,29,0,minecraft:basalt)
B(3,30,0,minecraft:basalt)
B(3,31,0,minecraft:basalt)
B(3,32,0,minecraft:basalt)
B(3,33,0,minecraft:basalt)
B(3,34,0,minecraft:basalt)
B(3,35,0,minecraft:basalt)
B(3,36,0,minecraft:basalt)
B(3,37,0,minecraft:basalt)
B(3,38,0,minecraft:basalt)
B(3,39,0,minecraft:basalt)
B(3,40,0,minecraft:basalt)
B(3,41,0,minecraft:basalt)
B(3,42,0,minecraft:basalt)
B(3,43,0,minecraft:basalt)
B(3,44,0,minecraft:basalt)
B(3,45,0,minecraft:basalt)
B(3,46,0,minecraft:basalt)
B(3,47,0,minecraft:basalt)
B(3,48,0,minecraft:basalt)
B(3,49,0,minecraft:basalt)
B(3,50,0,minecraft:basalt)
B(3,51,0,minecraft:basalt)
B(3,52,0,minecraft:basalt)
B(3,53,0,minecraft:basalt)
B(3,54,0,minecraft:basalt)
B(3,55,0,minecraft:basalt)
B(3,56,0,minecraft:basalt)
B(3,57,0,minecraft:basalt)
B(3,58,0,minecraft:basalt)
B(3,59,0,minecraft:basalt)
B(3,60,0,minecraft:basalt)
B(3,61,0,minecraft:basalt)
B(3,62,0,minecraft:basalt)
B(3,63,0,minecraft:basalt)
B(3,64,0,minecraft:basalt)
B(3,65,0,minecraft:basalt)
B(3,66,0,minecraft:basalt)
B(3,67,0,minecraft:basalt)
B(3,0,1,minecraft:basalt)
B(3,1,1,minecraft:basalt)
B(3,2,1,minecraft:basalt)
B(3,3,1,minecraft:basalt)
B(3,4,1,minecraft:basalt)
B(3,5,1,minecraft:basalt)
B(3,6,1,minecraft:basalt)
B(3,7,1,minecraft:basalt)
B(3,8,1,minecraft:basalt)
B(3,9,1,minecraft:basalt)
B(3,10,1,minecraft:basalt)
B(3,11,1,minecraft:basalt)
B(3,12,1,minecraft:basalt)
B(3,13,1,minecraft:basalt)
B(3,14,1,minecraft:basalt)
B(3,15,1,minecraft:basalt)
B(3,16,1,minecraft:basalt)
B(3,17,1,minecraft:basalt)
B(3,18,1,minecraft:basalt)
B(3,19,1,minecraft:basalt)
B(3,20,1,minecraft:basalt)
B(3,21,1,minecraft:basalt)
B(3,22,1,minecraft:basalt)
B(3,23,1,minecraft:basalt)
B(3,24,1,minecraft:basalt)
B(3,25,1,minecraft:basalt)
B(3,26,1,minecraft:basalt)
B(3,27,1,minecraft:basalt)
B(3,28,1,minecraft:basalt)
B(3,29,1,minecraft:basalt)
B(3,30,1,minecraft:basalt)
B(3,31,1,minecraft:basalt)
B(3,32,1,minecraft:basalt)
B(3,33,1,minecraft:basalt)
B(3,34,1,minecraft:basalt)
B(3,35,1,minecraft:basalt)
B(3,36,1,minecraft:basalt)
B(3,37,1,minecraft:basalt)
B(3,38,1,minecraft:basalt)
B(3,39,1,minecraft:basalt)
B(3,40,1,minecraft:basalt)
B(3,41,1,minecraft:basalt)
B(3,42,1,minecraft:basalt)
B(3,43,1,minecraft:basalt)
B(3,44,1,minecraft:basalt)
B(3,45,1,minecraft:basalt)
B(3,46,1,minecraft:basalt)
B(3,47,1,minecraft:basalt)
B(3,48,1,minecraft:basalt)
B(3,49,1,minecraft:basalt)
B(3,50,1,minecraft:basalt)
B(3,51,1,minecraft:basalt)
B(3,52,1,minecraft:basalt)
B(3,53,1,minecraft:basalt)
B(3,54,1,minecraft:basalt)
B(3,55,1,minecraft:basalt)
B(3,56,1,minecraft:basalt)
B(3,57,1,minecraft:basalt)
B(3,58,1,minecraft:basalt)
B(3,59,1,minecraft:basalt)
B(3,60,1,minecraft:basalt)
B(3,61,1,minecraft:basalt)
B(3,62,1,minecraft:basalt)
B(3,63,1,minecraft:basalt)
B(3,64,1,minecraft:basalt)
B(3,65,1,minecraft:basalt)
B(3,66,1,minecraft:basalt)
B(3,67,1,minecraft:basalt)
B(3,68,1,minecraft:basalt)
B(3,69,1,minecraft:basalt)
B(3,70,1,minecraft:basalt)
B(3,71,1,minecraft:basalt)
B(3,0,2,minecraft:basalt)
B(3,1,2,minecraft:basalt)
B(3,2,2,minecraft:basalt)
B(3,3,2,minecraft:basalt)
B(3,4,2,minecraft:basalt)
B(3,5,2,minecraft:basalt)
B(3,6,2,minecraft:basalt)
B(3,7,2,minecraft:basalt)
B(3,8,2,minecraft:basalt)
B(3,9,2,minecraft:basalt)
B(3,10,2,minecraft:basalt)
B(3,11,2,minecraft:basalt)
B(3,12,2,minecraft:basalt)
B(3,13,2,minecraft:basalt)
B(3,14,2,minecraft:basalt)
B(3,15,2,minecraft:basalt)
B(3,16,2,minecraft:basalt)
B(3,17,2,minecraft:basalt)
B(3,18,2,minecraft:basalt)
B(3,19,2,minecraft:basalt)
B(3,20,2,minecraft:basalt)
B(3,21,2,minecraft:basalt)
B(3,22,2,minecraft:basalt)
B(3,23,2,minecraft:basalt)
B(3,24,2,minecraft:basalt)
B(3,25,2,minecraft:basalt)
B(3,26,2,minecraft:basalt)
B(3,27,2,minecraft:basalt)
B(3,28,2,minecraft:basalt)
B(3,29,2,minecraft:basalt)
B(3,30,2,minecraft:basalt)
B(3,31,2,minecraft:basalt)
B(3,32,2,minecraft:basalt)
B(3,33,2,minecraft:basalt)
B(3,34,2,minecraft:basalt)
B(3,35,2,minecraft:basalt)
B(3,36,2,minecraft:basalt)
B(3,37,2,minecraft:basalt)
B(3,38,2,minecraft:basalt)
B(3,39,2,minecraft:basalt)
B(3,40,2,minecraft:basalt)
B(3,41,2,minecraft:basalt)
B(3,42,2,minecraft:basalt)
B(3,43,2,minecraft:basalt)
B(3,44,2,minecraft:basalt)
B(3,45,2,minecraft:basalt)
B(3,46,2,minecraft:basalt)
B(3,47,2,minecraft:basalt)
B(3,48,2,minecraft:basalt)
B(3,49,2,minecraft:basalt)
B(3,50,2,minecraft:basalt)
B(3,51,2,minecraft:basalt)
B(3,52,2,minecraft:basalt)
B(3,53,2,minecraft:basalt)
B(3,54,2,minecraft:basalt)
B(3,55,2,minecraft:basalt)
B(3,56,2,minecraft:basalt)
B(3,57,2,minecraft:basalt)
B(3,58,2,minecraft:basalt)
B(3,59,2,minecraft:basalt)
B(3,60,2,minecraft:basalt)
B(3,61,2,minecraft:basalt)
B(3,62,2,minecraft:basalt)
B(3,63,2,minecraft:basalt)
B(3,64,2,minecraft:basalt)
B(3,65,2,minecraft:basalt)
B(3,66,2,minecraft:basalt)
B(3,67,2,minecraft:basalt)
B(3,68,2,minecraft:basalt)
B(3,69,2,minecraft:basalt)
B(3,70,2,minecraft:basalt)
B(3,71,2,minecraft:basalt)
B(3,0,3,minecraft:basalt)
B(3,1,3,minecraft:basalt)
B(3,2,3,minecraft:basalt)
B(3,3,3,minecraft:basalt)
B(3,4,3,minecraft:basalt)
B(3,5,3,minecraft:basalt)
B(3,6,3,minecraft:basalt)
B(3,7,3,minecraft:basalt)
B(3,8,3,minecraft:basalt)
B(3,9,3,minecraft:basalt)
B(3,10,3,minecraft:basalt)
B(3,11,3,minecraft:basalt)
B(3,12,3,minecraft:basalt)
B(3,13,3,minecraft:basalt)
B(3,14,3,minecraft:basalt)
B(3,15,3,minecraft:basalt)
B(3,16,3,minecraft:basalt)
B(3,17,3,minecraft:basalt)
B(3,18,3,minecraft:basalt)
B(3,19,3,minecraft:basalt)
B(3,20,3,minecraft:basalt)
B(3,21,3,minecraft:basalt)
B(3,22,3,minecraft:basalt)
B(3,23,3,minecraft:basalt)
B(3,24,3,minecraft:basalt)
B(3,25,3,minecraft:basalt)
B(3,26,3,minecraft:basalt)
B(3,27,3,minecraft:basalt)
B(3,28,3,minecraft:basalt)
B(3,29,3,minecraft:basalt)
B(3,30,3,minecraft:basalt)
B(3,31,3,minecraft:basalt)
B(3,32,3,minecraft:basalt)
B(3,33,3,minecraft:basalt)
B(3,34,3,minecraft:basalt)
B(3,35,3,minecraft:basalt)
B(3,36,3,minecraft:basalt)
B(3,37,3,minecraft:basalt)
B(3,38,3,minecraft:basalt)
B(3,39,3,minecraft:basalt)
B(3,40,3,minecraft:basalt)
B(3,41,3,minecraft:basalt)
B(3,42,3,minecraft:basalt)
B(3,43,3,minecraft:basalt)
B(3,44,3,minecraft:basalt)
B(3,45,3,minecraft:basalt)
B(3,46,3,minecraft:basalt)
B(3,47,3,minecraft:basalt)
B(3,48,3,minecraft:basalt)
B(3,49,3,minecraft:basalt)
B(3,50,3,minecraft:basalt)
B(3,51,3,minecraft:basalt)
B(3,52,3,minecraft:basalt)
B(3,53,3,minecraft:basalt)
B(3,54,3,minecraft:basalt)
B(3,55,3,minecraft:basalt)
B(3,56,3,minecraft:basalt)
B(3,57,3,minecraft:basalt)
B(3,58,3,minecraft:basalt)
B(3,59,3,minecraft:basalt)
B(3,60,3,minecraft:basalt)
B(3,61,3,minecraft:basalt)
B(3,62,3,minecraft:basalt)
B(3,63,3,minecraft:basalt)
B(3,64,3,minecraft:basalt)
B(3,65,3,minecraft:basalt)
B(3,66,3,minecraft:basalt)
B(3,67,3,minecraft:basalt)
B(3,68,3,minecraft:basalt)
B(3,69,3,minecraft:basalt)
B(3,70,3,minecraft:basalt)
B(3,71,3,minecraft:basalt)
B(3,0,4,minecraft:basalt)
B(3,1,4,minecraft:basalt)
B(3,2,4,minecraft:basalt)
B(3,3,4,minecraft:basalt)
B(3,4,4,minecraft:basalt)
B(3,5,4,minecraft:basalt)
B(3,6,4,minecraft:basalt)
B(3,7,4,minecraft:basalt)
B(3,8,4,minecraft:basalt)
B(3,9,4,minecraft:basalt)
B(3,10,4,minecraft:basalt)
B(3,11,4,minecraft:basalt)
B(3,12,4,minecraft:basalt)
B(3,13,4,minecraft:basalt)
B(3,14,4,minecraft:basalt)
B(3,15,4,minecraft:basalt)
B(3,16,4,minecraft:basalt)
B(3,17,4,minecraft:basalt)
B(3,18,4,minecraft:basalt)
B(3,19,4,minecraft:basalt)
B(3,20,4,minecraft:basalt)
B(3,21,4,minecraft:basalt)
B(3,22,4,minecraft:basalt)
B(3,23,4,minecraft:basalt)
B(3,24,4,minecraft:basalt)
B(3,25,4,minecraft:basalt)
B(3,26,4,minecraft:basalt)
B(3,27,4,minecraft:basalt)
B(3,28,4,minecraft:basalt)
B(3,29,4,minecraft:basalt)
B(3,30,4,minecraft:basalt)
B(3,31,4,minecraft:basalt)
B(3,32,4,minecraft:basalt)
B(3,33,4,minecraft:basalt)
B(3,34,4,minecraft:basalt)
B(3,35,4,minecraft:basalt)
B(3,36,4,minecraft:basalt)
B(3,37,4,minecraft:basalt)
B(3,38,4,minecraft:basalt)
B(3,39,4,minecraft:basalt)
B(3,40,4,minecraft:basalt)
B(3,41,4,minecraft:basalt)
B(3,42,4,minecraft:basalt)
B(3,43,4,minecraft:basalt)
B(3,44,4,minecraft:basalt)
B(3,45,4,minecraft:basalt)
B(3,46,4,minecraft:basalt)
B(3,47,4,minecraft:basalt)
B(3,48,4,minecraft:basalt)
B(3,49,4,minecraft:basalt)
B(3,50,4,minecraft:basalt)
B(3,51,4,minecraft:basalt)
B(3,52,4,minecraft:basalt)
B(3,53,4,minecraft:basalt)
B(3,54,4,minecraft:basalt)
B(3,55,4,minecraft:basalt)
B(3,56,4,minecraft:basalt)
B(3,57,4,minecraft:basalt)
B(3,58,4,minecraft:basalt)
B(3,59,4,minecraft:basalt)
B(3,60,4,minecraft:basalt)
B(3,61,4,minecraft:basalt)
B(3,62,4,minecraft:basalt)
B(3,63,4,minecraft:basalt)
B(3,64,4,minecraft:basalt)
B(3,65,4,minecraft:basalt)
B(3,66,4,minecraft:basalt)
B(3,67,4,minecraft:basalt)
B(3,68,4,minecraft:basalt)
B(3,69,4,minecraft:basalt)
B(3,70,4,minecraft:basalt)
B(3,71,4,minecraft:basalt)
B(3,0,5,minecraft:basalt)
B(3,1,5,minecraft:basalt)
B(3,2,5,minecraft:basalt)
B(3,3,5,minecraft:basalt)
B(3,4,5,minecraft:basalt)
B(3,5,5,minecraft:basalt)
B(3,6,5,minecraft:basalt)
B(3,7,5,minecraft:basalt)
B(3,8,5,minecraft:basalt)
B(3,9,5,minecraft:basalt)
B(3,10,5,minecraft:basalt)
B(3,11,5,minecraft:basalt)
B(3,12,5,minecraft:basalt)
B(3,13,5,minecraft:basalt)
B(3,14,5,minecraft:basalt)
B(3,15,5,minecraft:basalt)
B(3,16,5,minecraft:basalt)
B(3,17,5,minecraft:basalt)
B(3,18,5,minecraft:basalt)
B(3,19,5,minecraft:basalt)
B(3,20,5,minecraft:basalt)
B(3,21,5,minecraft:basalt)
B(3,22,5,minecraft:basalt)
B(3,23,5,minecraft:basalt)
B(3,24,5,minecraft:basalt)
B(3,25,5,minecraft:basalt)
B(3,26,5,minecraft:basalt)
B(3,27,5,minecraft:basalt)
B(3,28,5,minecraft:basalt)
B(3,29,5,minecraft:basalt)
B(3,30,5,minecraft:basalt)
B(3,31,5,minecraft:basalt)
B(3,32,5,minecraft:basalt)
B(3,33,5,minecraft:basalt)
B(3,34,5,minecraft:basalt)
B(3,35,5,minecraft:basalt)
B(3,36,5,minecraft:basalt)
B(3,37,5,minecraft:basalt)
B(3,38,5,minecraft:basalt)
B(3,39,5,minecraft:basalt)
B(3,40,5,minecraft:basalt)
B(3,41,5,minecraft:basalt)
B(3,42,5,minecraft:basalt)
B(3,43,5,minecraft:basalt)
B(3,44,5,minecraft:basalt)
B(3,45,5,minecraft:basalt)
B(3,46,5,minecraft:basalt)
B(3,47,5,minecraft:basalt)
B(3,48,5,minecraft:basalt)
B(3,49,5,minecraft:basalt)
B(3,50,5,minecraft:basalt)
B(3,51,5,minecraft:basalt)
B(3,52,5,minecraft:basalt)
B(3,53,5,minecraft:basalt)
B(3,54,5,minecraft:basalt)
B(3,55,5,minecraft:basalt)
B(3,56,5,minecraft:basalt)
B(3,57,5,minecraft:basalt)
B(3,58,5,minecraft:basalt)
B(3,59,5,minecraft:basalt)
B(3,60,5,minecraft:basalt)
B(3,61,5,minecraft:basalt)
B(3,62,5,minecraft:basalt)
B(3,63,5,minecraft:basalt)
B(3,64,5,minecraft:basalt)
B(3,65,5,minecraft:basalt)
B(3,66,5,minecraft:basalt)
B(3,67,5,minecraft:basalt)
B(3,68,5,minecraft:basalt)
B(3,69,5,minecraft:basalt)
B(3,70,5,minecraft:basalt)
B(3,0,6,minecraft:basalt)
B(3,1,6,minecraft:basalt)
B(3,2,6,minecraft:basalt)
B(3,3,6,minecraft:basalt)
B(3,4,6,minecraft:basalt)
B(3,5,6,minecraft:basalt)
B(3,6,6,minecraft:basalt)
B(3,7,6,minecraft:basalt)
B(3,8,6,minecraft:basalt)
B(3,9,6,minecraft:basalt)
B(3,10,6,minecraft:basalt)
B(3,11,6,minecraft:basalt)
B(3,12,6,minecraft:basalt)
B(3,13,6,minecraft:basalt)
B(3,14,6,minecraft:basalt)
B(3,15,6,minecraft:basalt)
B(3,16,6,minecraft:basalt)
B(3,17,6,minecraft:basalt)
B(3,18,6,minecraft:basalt)
B(3,19,6,minecraft:basalt)
B(3,20,6,minecraft:basalt)
B(3,21,6,minecraft:basalt)
B(3,22,6,minecraft:basalt)
B(3,23,6,minecraft:basalt)
B(3,24,6,minecraft:basalt)
B(3,25,6,minecraft:basalt)
B(3,26,6,minecraft:basalt)
B(3,27,6,minecraft:basalt)
B(3,28,6,minecraft:basalt)
B(3,29,6,minecraft:basalt)
B(3,30,6,minecraft:basalt)
B(3,31,6,minecraft:basalt)
B(3,32,6,minecraft:basalt)
B(3,33,6,minecraft:basalt)
B(3,34,6,minecraft:basalt)
B(3,35,6,minecraft:basalt)
B(3,36,6,minecraft:basalt)
B(3,37,6,minecraft:basalt)
B(3,38,6,minecraft:basalt)
B(3,39,6,minecraft:basalt)
B(3,40,6,minecraft:basalt)
B(3,41,6,minecraft:basalt)
B(3,42,6,minecraft:basalt)
B(3,43,6,minecraft:basalt)
B(3,44,6,minecraft:basalt)
B(3,45,6,minecraft:basalt)
B(3,46,6,minecraft:basalt)
B(3,47,6,minecraft:basalt)
B(3,48,6,minecraft:basalt)
B(3,49,6,minecraft:basalt)
B(3,50,6,minecraft:basalt)
B(3,51,6,minecraft:basalt)
B(3,52,6,minecraft:basalt)
B(3,53,6,minecraft:basalt)
B(3,54,6,minecraft:basalt)
B(3,55,6,minecraft:basalt)
B(3,56,6,minecraft:basalt)
B(3,57,6,minecraft:basalt)
B(3,58,6,minecraft:basalt)
B(3,59,6,minecraft:basalt)
B(3,60,6,minecraft:basalt)
B(3,61,6,minecraft:basalt)
B(3,62,6,minecraft:basalt)
B(3,63,6,minecraft:basalt)
B(3,64,6,minecraft:basalt)
B(3,65,6,minecraft:basalt)
B(3,66,6,minecraft:basalt)
B(3,67,6,minecraft:basalt)
B(3,68,6,minecraft:basalt)
B(3,69,6,minecraft:basalt)
B(3,0,7,minecraft:basalt)
B(3,1,7,minecraft:basalt)
B(3,2,7,minecraft:basalt)
B(3,3,7,minecraft:basalt)
B(3,4,7,minecraft:basalt)
B(3,5,7,minecraft:basalt)
B(3,6,7,minecraft:basalt)
B(3,7,7,minecraft:basalt)
B(3,8,7,minecraft:basalt)
B(3,9,7,minecraft:basalt)
B(3,10,7,minecraft:basalt)
B(3,11,7,minecraft:basalt)
B(3,12,7,minecraft:basalt)
B(3,13,7,minecraft:basalt)
B(3,14,7,minecraft:basalt)
B(3,15,7,minecraft:basalt)
B(3,16,7,minecraft:basalt)
B(3,17,7,minecraft:basalt)
B(3,18,7,minecraft:basalt)
B(3,19,7,minecraft:basalt)
B(3,20,7,minecraft:basalt)
B(3,21,7,minecraft:basalt)
B(3,22,7,minecraft:basalt)
B(3,23,7,minecraft:basalt)
B(3,24,7,minecraft:basalt)
B(3,25,7,minecraft:basalt)
B(3,26,7,minecraft:basalt)
B(3,27,7,minecraft:basalt)
B(3,28,7,minecraft:basalt)
B(3,29,7,minecraft:basalt)
B(3,30,7,minecraft:basalt)
B(3,31,7,minecraft:basalt)
B(3,32,7,minecraft:basalt)
B(3,33,7,minecraft:basalt)
B(3,34,7,minecraft:basalt)
B(3,35,7,minecraft:basalt)
B(3,36,7,minecraft:basalt)
B(3,37,7,minecraft:basalt)
B(3,38,7,minecraft:basalt)
