#######################################################################
# +-----------------------------------------------------------------+ #
# |                            BO3 object                           | #
# +-----------------------------------------------------------------+ #
#######################################################################

Author: Bo3 BulkEdit

Description: Converted Schematic - Modified by Bo3BulkEdit

Version: 3

SettingsMode: WriteDisable

#######################################################################
# +-----------------------------------------------------------------+ #
# |                          Main settings                          | #
# +-----------------------------------------------------------------+ #
#######################################################################

IsOTGPlus: true
Tree: true
Frequency: 10
Rarity: 100
RotateRandomly: true
SpawnHeight: randomY
SpawnHeightOffset: 0
SpawnHeightVariance: 0
MaxBranchDepth: 10
ExcludedBiomes: All

##############################
# Height Limits for the BO3. #
##############################

MinHeight: 50
MaxHeight: 65

#######################################################################
# +-----------------------------------------------------------------+ #
# |                      Source block settings                      | #
# +-----------------------------------------------------------------+ #
#######################################################################

SourceBlocks: AIR
MaxPercentageOutsideSourceBlock: 100
OutsideSourceBlock: placeAnyway

#######################################################################
# +-----------------------------------------------------------------+ #
# |                               OTG+                              | #
# +-----------------------------------------------------------------+ #
#######################################################################

RemoveAir: true
ReplaceBelow: OBSIDIAN
ReplaceWithBiomeBlocks: false
ReplaceWithGroundBlock: OBSIDIAN
ReplaceWithSurfaceBlock: OBSIDIAN
ReplaceWithStoneBlock: OBSIDIAN
SmoothRadius: 30
SmoothingSurfaceBlock: OBSIDIAN
SmoothingGroundBlock: OBSIDIAN

#######################################################################
# +-----------------------------------------------------------------+ #
# |                              Blocks                             | #
# +-----------------------------------------------------------------+ #
#######################################################################

RB(0,0,0,minecraft:crying_obsidian,20,minecraft:obsidian,100)
RB(1,0,0,minecraft:crying_obsidian,20,minecraft:obsidian,100)
RB(2,0,0,minecraft:crying_obsidian,20,minecraft:obsidian,100)
RB(3,0,0,minecraft:crying_obsidian,20,minecraft:obsidian,100)
RB(4,0,0,minecraft:crying_obsidian,20,minecraft:obsidian,100)
RB(5,0,0,minecraft:crying_obsidian,20,minecraft:obsidian,100)
RB(6,0,0,minecraft:crying_obsidian,20,minecraft:obsidian,100)
RB(7,0,0,minecraft:crying_obsidian,20,minecraft:obsidian,100)
RB(8,0,0,minecraft:crying_obsidian,20,minecraft:obsidian,100)
RB(9,0,0,minecraft:crying_obsidian,20,minecraft:obsidian,100)
RB(10,0,0,minecraft:crying_obsidian,20,minecraft:obsidian,100)
RB(11,0,0,minecraft:crying_obsidian,20,minecraft:obsidian,100)
RB(12,0,0,minecraft:crying_obsidian,20,minecraft:obsidian,100)
RB(13,0,0,minecraft:crying_obsidian,20,minecraft:obsidian,100)
RB(14,0,0,minecraft:crying_obsidian,20,minecraft:obsidian,100)
RB(15,0,0,minecraft:crying_obsidian,20,minecraft:obsidian,100)
RB(0,0,1,minecraft:crying_obsidian,20,minecraft:obsidian,100)
RB(1,0,1,minecraft:crying_obsidian,20,minecraft:obsidian,100)
RB(2,0,1,minecraft:crying_obsidian,20,minecraft:obsidian,100)
RB(3,0,1,minecraft:crying_obsidian,20,minecraft:obsidian,100)
RB(4,0,1,minecraft:crying_obsidian,20,minecraft:obsidian,100)
RB(5,0,1,minecraft:crying_obsidian,20,minecraft:obsidian,100)
RB(6,0,1,minecraft:crying_obsidian,20,minecraft:obsidian,100)
RB(7,0,1,minecraft:crying_obsidian,20,minecraft:obsidian,100)
RB(8,0,1,minecraft:crying_obsidian,20,minecraft:obsidian,100)
RB(9,0,1,minecraft:crying_obsidian,20,minecraft:obsidian,100)
RB(10,0,1,minecraft:crying_obsidian,20,minecraft:obsidian,100)
RB(13,0,1,minecraft:crying_obsidian,20,minecraft:obsidian,100)
RB(14,0,1,minecraft:crying_obsidian,20,minecraft:obsidian,100)
RB(15,0,1,minecraft:crying_obsidian,20,minecraft:obsidian,100)
RB(0,0,2,minecraft:crying_obsidian,20,minecraft:obsidian,100)
RB(1,0,2,minecraft:crying_obsidian,20,minecraft:obsidian,100)
RB(2,0,2,minecraft:crying_obsidian,20,minecraft:obsidian,100)
RB(3,0,2,minecraft:crying_obsidian,20,minecraft:obsidian,100)
RB(4,0,2,minecraft:crying_obsidian,20,minecraft:obsidian,100)
RB(5,0,2,minecraft:crying_obsidian,20,minecraft:obsidian,100)
RB(6,0,2,minecraft:crying_obsidian,20,minecraft:obsidian,100)
RB(7,0,2,minecraft:crying_obsidian,20,minecraft:obsidian,100)
RB(8,0,2,minecraft:crying_obsidian,20,minecraft:obsidian,100)
RB(9,0,2,minecraft:crying_obsidian,20,minecraft:obsidian,100)
RB(0,0,3,minecraft:crying_obsidian,20,minecraft:obsidian,100)
RB(1,0,3,minecraft:crying_obsidian,20,minecraft:obsidian,100)
RB(2,0,3,minecraft:crying_obsidian,20,minecraft:obsidian,100)
RB(3,0,3,minecraft:crying_obsidian,20,minecraft:obsidian,100)
RB(4,0,3,minecraft:crying_obsidian,20,minecraft:obsidian,100)
RB(0,0,4,minecraft:crying_obsidian,20,minecraft:obsidian,100)
RB(1,0,4,minecraft:crying_obsidian,20,minecraft:obsidian,100)
RB(2,0,4,minecraft:crying_obsidian,20,minecraft:obsidian,100)
RB(3,0,4,minecraft:crying_obsidian,20,minecraft:obsidian,100)
RB(0,1,0,minecraft:crying_obsidian,20,minecraft:obsidian,100)
RB(1,1,0,minecraft:crying_obsidian,20,minecraft:obsidian,100)
RB(2,1,0,minecraft:crying_obsidian,20,minecraft:obsidian,100)
RB(3,1,0,minecraft:crying_obsidian,20,minecraft:obsidian,100)
RB(5,1,0,minecraft:crying_obsidian,20,minecraft:obsidian,100)
RB(6,1,0,minecraft:crying_obsidian,20,minecraft:obsidian,100)
RB(7,1,0,minecraft:crying_obsidian,20,minecraft:obsidian,100)
RB(8,1,0,minecraft:crying_obsidian,20,minecraft:obsidian,100)
RB(9,1,0,minecraft:crying_obsidian,20,minecraft:obsidian,100)
RB(10,1,0,minecraft:crying_obsidian,20,minecraft:obsidian,100)
RB(11,1,0,minecraft:crying_obsidian,20,minecraft:obsidian,100)
RB(12,1,0,minecraft:crying_obsidian,20,minecraft:obsidian,100)
RB(13,1,0,minecraft:crying_obsidian,20,minecraft:obsidian,100)
RB(14,1,0,minecraft:crying_obsidian,20,minecraft:obsidian,100)
RB(15,1,0,minecraft:crying_obsidian,20,minecraft:obsidian,100)
RB(0,1,1,minecraft:crying_obsidian,20,minecraft:obsidian,100)
RB(1,1,1,minecraft:crying_obsidian,20,minecraft:obsidian,100)
RB(2,1,1,minecraft:crying_obsidian,20,minecraft:obsidian,100)
RB(3,1,1,minecraft:crying_obsidian,20,minecraft:obsidian,100)
RB(4,1,1,minecraft:crying_obsidian,20,minecraft:obsidian,100)
RB(6,1,1,minecraft:crying_obsidian,20,minecraft:obsidian,100)
RB(7,1,1,minecraft:crying_obsidian,20,minecraft:obsidian,100)
RB(8,1,1,minecraft:crying_obsidian,20,minecraft:obsidian,100)
RB(0,1,2,minecraft:crying_obsidian,20,minecraft:obsidian,100)
RB(1,1,2,minecraft:crying_obsidian,20,minecraft:obsidian,100)
RB(2,1,2,minecraft:crying_obsidian,20,minecraft:obsidian,100)
RB(3,1,2,minecraft:crying_obsidian,20,minecraft:obsidian,100)
RB(4,1,2,minecraft:crying_obsidian,20,minecraft:obsidian,100)
RB(0,1,3,minecraft:crying_obsidian,20,minecraft:obsidian,100)
RB(1,1,3,minecraft:crying_obsidian,20,minecraft:obsidian,100)
RB(2,1,3,minecraft:crying_obsidian,20,minecraft:obsidian,100)
RB(3,1,3,minecraft:crying_obsidian,20,minecraft:obsidian,100)
RB(4,1,3,minecraft:crying_obsidian,20,minecraft:obsidian,100)
RB(0,2,0,minecraft:crying_obsidian,20,minecraft:obsidian,100)
RB(1,2,0,minecraft:crying_obsidian,20,minecraft:obsidian,100)
RB(2,2,0,minecraft:crying_obsidian,20,minecraft:obsidian,100)
RB(3,2,0,minecraft:crying_obsidian,20,minecraft:obsidian,100)
RB(5,2,0,minecraft:crying_obsidian,20,minecraft:obsidian,100)
RB(6,2,0,minecraft:crying_obsidian,20,minecraft:obsidian,100)
RB(7,2,0,minecraft:crying_obsidian,20,minecraft:obsidian,100)
RB(8,2,0,minecraft:crying_obsidian,20,minecraft:obsidian,100)
RB(9,2,0,minecraft:crying_obsidian,20,minecraft:obsidian,100)
RB(10,2,0,minecraft:crying_obsidian,20,minecraft:obsidian,100)
RB(11,2,0,minecraft:crying_obsidian,20,minecraft:obsidian,100)
RB(12,2,0,minecraft:crying_obsidian,20,minecraft:obsidian,100)
RB(13,2,0,minecraft:crying_obsidian,20,minecraft:obsidian,100)
RB(0,2,1,minecraft:crying_obsidian,20,minecraft:obsidian,100)
RB(1,2,1,minecraft:crying_obsidian,20,minecraft:obsidian,100)
RB(2,2,1,minecraft:crying_obsidian,20,minecraft:obsidian,100)
RB(3,2,1,minecraft:crying_obsidian,20,minecraft:obsidian,100)
RB(0,2,2,minecraft:crying_obsidian,20,minecraft:obsidian,100)
RB(1,2,2,minecraft:crying_obsidian,20,minecraft:obsidian,100)
RB(2,2,2,minecraft:crying_obsidian,20,minecraft:obsidian,100)
RB(3,2,2,minecraft:crying_obsidian,20,minecraft:obsidian,100)
RB(5,3,0,minecraft:crying_obsidian,20,minecraft:obsidian,100)
RB(6,3,0,minecraft:crying_obsidian,20,minecraft:obsidian,100)
RB(7,3,0,minecraft:crying_obsidian,20,minecraft:obsidian,100)
RB(8,3,0,minecraft:crying_obsidian,20,minecraft:obsidian,100)
RB(9,3,0,minecraft:crying_obsidian,20,minecraft:obsidian,100)
RB(10,3,0,minecraft:crying_obsidian,20,minecraft:obsidian,100)
RB(11,3,0,minecraft:crying_obsidian,20,minecraft:obsidian,100)
RB(12,3,0,minecraft:crying_obsidian,20,minecraft:obsidian,100)
RB(5,4,0,minecraft:crying_obsidian,20,minecraft:obsidian,100)
RB(6,4,0,minecraft:crying_obsidian,20,minecraft:obsidian,100)
RB(7,4,0,minecraft:crying_obsidian,20,minecraft:obsidian,100)
RB(8,4,0,minecraft:crying_obsidian,20,minecraft:obsidian,100)
RB(9,4,0,minecraft:crying_obsidian,20,minecraft:obsidian,100)
RB(6,5,0,minecraft:crying_obsidian,20,minecraft:obsidian,100)
RB(7,5,0,minecraft:crying_obsidian,20,minecraft:obsidian,100)
RB(8,5,0,minecraft:crying_obsidian,20,minecraft:obsidian,100)
RB(9,5,0,minecraft:crying_obsidian,20,minecraft:obsidian,100)
RB(6,6,0,minecraft:crying_obsidian,20,minecraft:obsidian,100)
RB(7,6,0,minecraft:crying_obsidian,20,minecraft:obsidian,100)
RB(8,6,0,minecraft:crying_obsidian,20,minecraft:obsidian,100)

#######################################################################
# +-----------------------------------------------------------------+ #
# |                             Branches                            | #
# +-----------------------------------------------------------------+ #
#######################################################################

BR(-16,0,0,true,ObsidianOozingMountain1_0x3,NORTH,100,0)
