
#######################################################################
# +-----------------------------------------------------------------+ #
# |                            BO4 object                           | #
# +-----------------------------------------------------------------+ #
#######################################################################

Author: Unknown

Description: No description given

SettingsMode: WriteWithoutComments


#######################################################################
# +-----------------------------------------------------------------+ #
# |                          Main settings                          | #
# +-----------------------------------------------------------------+ #
#######################################################################

FixedRotation: 

Frequency: 0

SpawnHeight: highestBlock

UseCenterForHighestBlock: true

##############################
# Height Limits for the BO4. #
##############################

MinHeight: 0

MaxHeight: 255

InheritBO3: 

InheritBO3Rotation: NORTH

OverrideChildSettings: true

OverrideParentHeight: false

CanOverride: false

BranchFrequency: 0

BranchFrequencyGroup: 

MustBeBelowOther: false

MustBeInside: 

CannotBeInside: 

ReplacesBO3: 

MustBeInsideWorldBorders: false

CanSpawnOnWater: true

SpawnOnWaterOnly: false

SpawnUnderWater: false

SpawnAtWaterLevel: false

HeightOffset: 0

RemoveAir: true

ReplaceAbove: 

ReplaceBelow: 

ReplaceWithBiomeBlocks: true

ReplaceWithSurfaceBlock: GRASS

ReplaceWithGroundBlock: DIRT

ReplaceWithStoneBlock: STONE

SmoothRadius: 0

SmoothHeightOffset: 0

SmoothStartTop: false

SmoothStartWood: false

SmoothingSurfaceBlock: 

SmoothingGroundBlock: 

BO3Group: 

IsSpawnPoint: false

DoReplaceBlocks: true


#######################################################################
# +-----------------------------------------------------------------+ #
# |                              Blocks                             | #
# +-----------------------------------------------------------------+ #
#######################################################################

B(-8,0,-7,minecraft:soul_sand)
B(-8,1,-7,minecraft:soul_sand)
B(-8,2,-7,minecraft:soul_sand)
B(-8,3,-7,minecraft:soul_sand)
B(-8,4,-7,minecraft:soul_sand)
B(-8,5,-7,minecraft:soul_sand)
B(-8,6,-7,minecraft:soul_sand)
B(-8,7,-7,minecraft:soul_sand)
B(-8,8,-7,minecraft:soul_sand)
B(-8,9,-7,minecraft:soul_sand)
B(-8,10,-7,minecraft:soul_sand)
B(-8,11,-7,minecraft:soul_sand)
B(-8,12,-7,minecraft:soul_sand)
B(-8,13,-7,minecraft:soul_sand)
B(-8,14,-7,minecraft:soul_sand)
B(-8,15,-7,minecraft:soul_sand)
B(-8,16,-7,minecraft:soul_sand)
B(-8,17,-7,minecraft:soul_sand)
B(-8,18,-7,minecraft:soul_sand)
B(-8,19,-7,minecraft:soul_sand)
B(-8,20,-7,minecraft:soul_sand)
B(-8,21,-7,minecraft:soul_sand)
B(-8,22,-7,minecraft:soul_sand)
B(-8,23,-7,minecraft:soul_sand)
B(-8,24,-7,minecraft:soul_sand)
B(-8,25,-7,minecraft:soul_sand)
B(-8,26,-7,minecraft:soul_sand)
B(-8,27,-7,minecraft:soul_sand)
B(-8,28,-7,minecraft:soul_sand)
B(-8,29,-7,minecraft:soul_sand)
B(-8,30,-7,minecraft:soul_sand)
B(-8,31,-7,minecraft:soul_sand)
B(-8,32,-7,minecraft:soul_sand)
B(-8,33,-7,minecraft:soul_sand)
B(-8,34,-7,minecraft:soul_sand)
B(-8,35,-7,minecraft:soul_sand)
B(-8,36,-7,minecraft:soul_sand)
B(-8,37,-7,minecraft:soul_sand)
B(-8,38,-7,minecraft:soul_sand)
B(-8,39,-7,minecraft:soul_sand)
B(-8,40,-7,minecraft:soul_sand)
B(-8,41,-7,minecraft:soul_sand)
B(-8,42,-7,minecraft:soul_sand)
B(-8,43,-7,minecraft:soul_sand)
B(-8,44,-7,minecraft:soul_sand)
B(-8,45,-7,minecraft:soul_sand)
B(-8,46,-7,minecraft:soul_sand)
B(-8,47,-7,minecraft:soul_sand)
B(-8,48,-7,minecraft:soul_sand)
B(-8,49,-7,minecraft:soul_sand)
B(-8,50,-7,minecraft:soul_sand)
B(-8,51,-7,minecraft:soul_sand)
B(-8,52,-7,minecraft:soul_sand)
B(-8,53,-7,minecraft:soul_sand)
B(-8,54,-7,minecraft:soul_sand)
B(-8,55,-7,minecraft:soul_sand)
B(-8,56,-7,minecraft:soul_sand)
B(-8,57,-7,minecraft:soul_sand)
B(-8,58,-7,minecraft:soul_sand)
B(-8,59,-7,minecraft:soul_sand)
B(-8,60,-7,minecraft:soul_sand)
B(-8,61,-7,minecraft:soul_sand)
B(-8,62,-7,minecraft:soul_sand)
B(-8,63,-7,minecraft:soul_sand)
B(-8,64,-7,minecraft:soul_sand)
B(-8,65,-7,minecraft:soul_sand)
B(-8,66,-7,minecraft:soul_sand)
B(-8,67,-7,minecraft:soul_sand)
B(-8,68,-7,minecraft:soul_sand)
B(-8,69,-7,minecraft:soul_sand)
B(-8,70,-7,minecraft:soul_sand)
B(-8,71,-7,minecraft:soul_sand)
B(-8,72,-7,minecraft:soul_sand)
B(-8,73,-7,minecraft:soul_sand)
B(-8,74,-7,minecraft:soul_sand)
B(-8,75,-7,minecraft:soul_sand)
B(-8,76,-7,minecraft:soul_sand)
B(-8,77,-7,minecraft:soul_sand)
B(-8,78,-7,minecraft:soul_sand)
B(-8,79,-7,minecraft:soul_sand)
B(-8,0,-6,minecraft:soul_sand)
B(-8,1,-6,minecraft:soul_sand)
B(-8,2,-6,minecraft:soul_sand)
B(-8,3,-6,minecraft:soul_sand)
B(-8,4,-6,minecraft:soul_sand)
B(-8,5,-6,minecraft:soul_sand)
B(-8,6,-6,minecraft:soul_sand)
B(-8,7,-6,minecraft:soul_sand)
B(-8,8,-6,minecraft:soul_sand)
B(-8,9,-6,minecraft:soul_sand)
B(-8,10,-6,minecraft:soul_sand)
B(-8,11,-6,minecraft:soul_sand)
B(-8,12,-6,minecraft:soul_sand)
B(-8,13,-6,minecraft:soul_sand)
B(-8,14,-6,minecraft:soul_sand)
B(-8,15,-6,minecraft:soul_sand)
B(-8,16,-6,minecraft:soul_sand)
B(-8,17,-6,minecraft:soul_sand)
B(-8,18,-6,minecraft:soul_sand)
B(-8,19,-6,minecraft:soul_sand)
B(-8,20,-6,minecraft:soul_sand)
B(-8,21,-6,minecraft:soul_sand)
B(-8,22,-6,minecraft:soul_sand)
B(-8,23,-6,minecraft:soul_sand)
B(-8,24,-6,minecraft:soul_sand)
B(-8,25,-6,minecraft:soul_sand)
B(-8,26,-6,minecraft:soul_sand)
B(-8,27,-6,minecraft:soul_sand)
B(-8,28,-6,minecraft:soul_sand)
B(-8,29,-6,minecraft:soul_sand)
B(-8,30,-6,minecraft:soul_sand)
B(-8,31,-6,minecraft:soul_sand)
B(-8,32,-6,minecraft:soul_sand)
B(-8,33,-6,minecraft:soul_sand)
B(-8,34,-6,minecraft:soul_sand)
B(-8,35,-6,minecraft:soul_sand)
B(-8,36,-6,minecraft:soul_sand)
B(-8,37,-6,minecraft:soul_sand)
B(-8,38,-6,minecraft:soul_sand)
B(-8,39,-6,minecraft:soul_sand)
B(-8,40,-6,minecraft:soul_sand)
B(-8,41,-6,minecraft:soul_sand)
B(-8,42,-6,minecraft:soul_sand)
B(-8,43,-6,minecraft:soul_sand)
B(-8,44,-6,minecraft:soul_sand)
B(-8,45,-6,minecraft:soul_sand)
B(-8,46,-6,minecraft:soul_sand)
B(-8,47,-6,minecraft:soul_sand)
B(-8,48,-6,minecraft:soul_sand)
B(-8,49,-6,minecraft:soul_sand)
B(-8,50,-6,minecraft:soul_sand)
B(-8,51,-6,minecraft:soul_sand)
B(-8,52,-6,minecraft:soul_sand)
B(-8,53,-6,minecraft:soul_sand)
B(-8,54,-6,minecraft:soul_sand)
B(-8,55,-6,minecraft:soul_sand)
B(-8,56,-6,minecraft:soul_sand)
B(-8,57,-6,minecraft:soul_sand)
B(-8,58,-6,minecraft:soul_sand)
B(-8,59,-6,minecraft:soul_sand)
B(-8,60,-6,minecraft:soul_sand)
B(-8,61,-6,minecraft:soul_sand)
B(-8,62,-6,minecraft:soul_sand)
B(-8,63,-6,minecraft:soul_sand)
B(-8,64,-6,minecraft:soul_sand)
B(-8,65,-6,minecraft:soul_sand)
B(-8,66,-6,minecraft:soul_sand)
B(-8,67,-6,minecraft:soul_sand)
B(-8,68,-6,minecraft:soul_sand)
B(-8,69,-6,minecraft:soul_sand)
B(-8,70,-6,minecraft:soul_sand)
B(-8,71,-6,minecraft:soul_sand)
B(-8,72,-6,minecraft:soul_sand)
B(-8,73,-6,minecraft:soul_sand)
B(-8,74,-6,minecraft:soul_sand)
B(-8,0,-5,minecraft:soul_sand)
B(-8,1,-5,minecraft:soul_sand)
B(-8,2,-5,minecraft:soul_sand)
B(-8,3,-5,minecraft:soul_sand)
B(-8,4,-5,minecraft:soul_sand)
B(-8,5,-5,minecraft:soul_sand)
B(-8,6,-5,minecraft:soul_sand)
B(-8,7,-5,minecraft:soul_sand)
B(-8,8,-5,minecraft:soul_sand)
B(-8,9,-5,minecraft:soul_sand)
B(-8,10,-5,minecraft:soul_sand)
B(-8,11,-5,minecraft:soul_sand)
B(-8,12,-5,minecraft:soul_sand)
B(-8,13,-5,minecraft:soul_sand)
B(-8,14,-5,minecraft:soul_sand)
B(-8,15,-5,minecraft:soul_sand)
B(-8,16,-5,minecraft:soul_sand)
B(-8,17,-5,minecraft:soul_sand)
B(-8,18,-5,minecraft:soul_sand)
B(-8,19,-5,minecraft:soul_sand)
B(-8,20,-5,minecraft:soul_sand)
B(-8,21,-5,minecraft:soul_sand)
B(-8,22,-5,minecraft:soul_sand)
B(-8,23,-5,minecraft:soul_sand)
B(-8,24,-5,minecraft:soul_sand)
B(-8,25,-5,minecraft:soul_sand)
B(-8,26,-5,minecraft:soul_sand)
B(-8,27,-5,minecraft:soul_sand)
B(-8,28,-5,minecraft:soul_sand)
B(-8,29,-5,minecraft:soul_sand)
B(-8,30,-5,minecraft:soul_sand)
B(-8,31,-5,minecraft:soul_sand)
B(-8,32,-5,minecraft:soul_sand)
B(-8,33,-5,minecraft:soul_sand)
B(-8,34,-5,minecraft:soul_sand)
B(-8,35,-5,minecraft:soul_sand)
B(-8,36,-5,minecraft:soul_sand)
B(-8,37,-5,minecraft:soul_sand)
B(-8,38,-5,minecraft:soul_sand)
B(-8,39,-5,minecraft:soul_sand)
B(-8,40,-5,minecraft:soul_sand)
B(-8,41,-5,minecraft:soul_sand)
B(-8,42,-5,minecraft:soul_sand)
B(-8,43,-5,minecraft:soul_sand)
B(-8,44,-5,minecraft:soul_sand)
B(-8,45,-5,minecraft:soul_sand)
B(-8,46,-5,minecraft:soul_sand)
B(-8,47,-5,minecraft:soul_sand)
B(-8,48,-5,minecraft:soul_sand)
B(-8,49,-5,minecraft:soul_sand)
B(-8,50,-5,minecraft:soul_sand)
B(-8,51,-5,minecraft:soul_sand)
B(-8,52,-5,minecraft:soul_sand)
B(-8,53,-5,minecraft:soul_sand)
B(-8,54,-5,minecraft:soul_sand)
B(-8,55,-5,minecraft:soul_sand)
B(-8,56,-5,minecraft:soul_sand)
B(-8,57,-5,minecraft:soul_sand)
B(-8,58,-5,minecraft:soul_sand)
B(-8,59,-5,minecraft:soul_sand)
B(-8,60,-5,minecraft:soul_sand)
B(-8,61,-5,minecraft:soul_sand)
B(-8,62,-5,minecraft:soul_sand)
B(-8,63,-5,minecraft:soul_sand)
B(-8,64,-5,minecraft:soul_sand)
B(-8,65,-5,minecraft:soul_sand)
B(-8,66,-5,minecraft:soul_sand)
B(-8,67,-5,minecraft:soul_sand)
B(-8,0,-4,minecraft:soul_sand)
B(-8,1,-4,minecraft:soul_sand)
B(-8,2,-4,minecraft:soul_sand)
B(-8,3,-4,minecraft:soul_sand)
B(-8,4,-4,minecraft:soul_sand)
B(-8,5,-4,minecraft:soul_sand)
B(-8,6,-4,minecraft:soul_sand)
B(-8,7,-4,minecraft:soul_sand)
B(-8,8,-4,minecraft:soul_sand)
B(-8,9,-4,minecraft:soul_sand)
B(-8,10,-4,minecraft:soul_sand)
B(-8,11,-4,minecraft:soul_sand)
B(-8,12,-4,minecraft:soul_sand)
B(-8,13,-4,minecraft:soul_sand)
B(-8,14,-4,minecraft:soul_sand)
B(-8,15,-4,minecraft:soul_sand)
B(-8,16,-4,minecraft:soul_sand)
B(-8,17,-4,minecraft:soul_sand)
B(-8,18,-4,minecraft:soul_sand)
B(-8,19,-4,minecraft:soul_sand)
B(-8,20,-4,minecraft:soul_sand)
B(-8,21,-4,minecraft:soul_sand)
B(-8,22,-4,minecraft:soul_sand)
B(-8,23,-4,minecraft:soul_sand)
B(-8,24,-4,minecraft:soul_sand)
B(-8,25,-4,minecraft:soul_sand)
B(-8,26,-4,minecraft:soul_sand)
B(-8,27,-4,minecraft:soul_sand)
B(-8,28,-4,minecraft:soul_sand)
B(-8,29,-4,minecraft:soul_sand)
B(-8,30,-4,minecraft:soul_sand)
B(-8,31,-4,minecraft:soul_sand)
B(-8,32,-4,minecraft:soul_sand)
B(-8,33,-4,minecraft:soul_sand)
B(-8,34,-4,minecraft:soul_sand)
B(-8,35,-4,minecraft:soul_sand)
B(-8,36,-4,minecraft:soul_sand)
B(-8,37,-4,minecraft:soul_sand)
B(-8,38,-4,minecraft:soul_sand)
B(-8,39,-4,minecraft:soul_sand)
B(-8,40,-4,minecraft:soul_sand)
B(-8,41,-4,minecraft:soul_sand)
B(-8,42,-4,minecraft:soul_sand)
B(-8,43,-4,minecraft:soul_sand)
B(-8,44,-4,minecraft:soul_sand)
B(-8,45,-4,minecraft:soul_sand)
B(-8,46,-4,minecraft:soul_sand)
B(-8,47,-4,minecraft:soul_sand)
B(-8,48,-4,minecraft:soul_sand)
B(-8,49,-4,minecraft:soul_sand)
B(-8,50,-4,minecraft:soul_sand)
B(-8,51,-4,minecraft:soul_sand)
B(-8,52,-4,minecraft:soul_sand)
B(-8,53,-4,minecraft:soul_sand)
B(-8,54,-4,minecraft:soul_sand)
B(-8,55,-4,minecraft:soul_sand)
B(-8,56,-4,minecraft:soul_sand)
B(-8,57,-4,minecraft:soul_sand)
B(-8,58,-4,minecraft:soul_sand)
B(-8,59,-4,minecraft:soul_sand)
B(-8,60,-4,minecraft:soul_sand)
B(-8,61,-4,minecraft:soul_sand)
B(-8,62,-4,minecraft:soul_sand)
B(-8,63,-4,minecraft:soul_sand)
B(-8,64,-4,minecraft:soul_sand)
B(-8,65,-4,minecraft:soul_sand)
B(-8,66,-4,minecraft:soul_sand)
B(-8,67,-4,minecraft:soul_sand)
B(-8,0,-3,minecraft:soul_sand)
B(-8,1,-3,minecraft:soul_sand)
B(-8,2,-3,minecraft:soul_sand)
B(-8,3,-3,minecraft:soul_sand)
B(-8,4,-3,minecraft:soul_sand)
B(-8,5,-3,minecraft:soul_sand)
B(-8,6,-3,minecraft:soul_sand)
B(-8,7,-3,minecraft:soul_sand)
B(-8,8,-3,minecraft:soul_sand)
B(-8,9,-3,minecraft:soul_sand)
B(-8,10,-3,minecraft:soul_sand)
B(-8,11,-3,minecraft:soul_sand)
B(-8,12,-3,minecraft:soul_sand)
B(-8,13,-3,minecraft:soul_sand)
B(-8,14,-3,minecraft:soul_sand)
B(-8,15,-3,minecraft:soul_sand)
B(-8,16,-3,minecraft:soul_sand)
B(-8,17,-3,minecraft:soul_sand)
B(-8,18,-3,minecraft:soul_sand)
B(-8,19,-3,minecraft:soul_sand)
B(-8,20,-3,minecraft:soul_sand)
B(-8,21,-3,minecraft:soul_sand)
B(-8,22,-3,minecraft:soul_sand)
B(-8,23,-3,minecraft:soul_sand)
B(-8,24,-3,minecraft:soul_sand)
B(-8,25,-3,minecraft:soul_sand)
B(-8,26,-3,minecraft:soul_sand)
B(-8,27,-3,minecraft:soul_sand)
B(-8,28,-3,minecraft:soul_sand)
B(-8,29,-3,minecraft:soul_sand)
B(-8,30,-3,minecraft:soul_sand)
B(-8,31,-3,minecraft:soul_sand)
B(-8,32,-3,minecraft:soul_sand)
B(-8,33,-3,minecraft:soul_sand)
B(-8,34,-3,minecraft:soul_sand)
B(-8,35,-3,minecraft:soul_sand)
B(-8,36,-3,minecraft:soul_sand)
B(-8,37,-3,minecraft:soul_sand)
B(-8,38,-3,minecraft:soul_sand)
B(-8,39,-3,minecraft:soul_sand)
B(-8,40,-3,minecraft:soul_sand)
B(-8,41,-3,minecraft:soul_sand)
B(-8,42,-3,minecraft:soul_sand)
B(-8,43,-3,minecraft:soul_sand)
B(-8,44,-3,minecraft:soul_sand)
B(-8,45,-3,minecraft:soul_sand)
B(-8,46,-3,minecraft:soul_sand)
B(-8,47,-3,minecraft:soul_sand)
B(-8,48,-3,minecraft:soul_sand)
B(-8,49,-3,minecraft:soul_sand)
B(-8,50,-3,minecraft:soul_sand)
B(-8,51,-3,minecraft:soul_sand)
B(-8,52,-3,minecraft:soul_sand)
B(-8,53,-3,minecraft:soul_sand)
B(-8,54,-3,minecraft:soul_sand)
B(-8,55,-3,minecraft:soul_sand)
B(-8,56,-3,minecraft:soul_sand)
B(-8,57,-3,minecraft:soul_sand)
B(-8,58,-3,minecraft:soul_sand)
B(-8,59,-3,minecraft:soul_sand)
B(-8,60,-3,minecraft:soul_sand)
B(-8,61,-3,minecraft:soul_sand)
B(-8,62,-3,minecraft:soul_sand)
B(-8,63,-3,minecraft:soul_sand)
B(-8,64,-3,minecraft:soul_sand)
B(-8,65,-3,minecraft:soul_sand)
B(-8,66,-3,minecraft:soul_sand)
B(-8,67,-3,minecraft:soul_sand)
B(-8,0,-2,minecraft:soul_sand)
B(-8,1,-2,minecraft:soul_sand)
B(-8,2,-2,minecraft:soul_sand)
B(-8,3,-2,minecraft:soul_sand)
B(-8,4,-2,minecraft:soul_sand)
B(-8,5,-2,minecraft:soul_sand)
B(-8,6,-2,minecraft:soul_sand)
B(-8,7,-2,minecraft:soul_sand)
B(-8,8,-2,minecraft:soul_sand)
B(-8,9,-2,minecraft:soul_sand)
B(-8,10,-2,minecraft:soul_sand)
B(-8,11,-2,minecraft:soul_sand)
B(-8,12,-2,minecraft:soul_sand)
B(-8,13,-2,minecraft:soul_sand)
B(-8,14,-2,minecraft:soul_sand)
B(-8,15,-2,minecraft:soul_sand)
B(-8,16,-2,minecraft:soul_sand)
B(-8,17,-2,minecraft:soul_sand)
B(-8,18,-2,minecraft:soul_sand)
B(-8,19,-2,minecraft:soul_sand)
B(-8,20,-2,minecraft:soul_sand)
B(-8,21,-2,minecraft:soul_sand)
B(-8,22,-2,minecraft:soul_sand)
B(-8,23,-2,minecraft:soul_sand)
B(-8,24,-2,minecraft:soul_sand)
B(-8,25,-2,minecraft:soul_sand)
B(-8,26,-2,minecraft:soul_sand)
B(-8,27,-2,minecraft:soul_sand)
B(-8,28,-2,minecraft:soul_sand)
B(-8,29,-2,minecraft:soul_sand)
B(-8,30,-2,minecraft:soul_sand)
B(-8,31,-2,minecraft:soul_sand)
B(-8,32,-2,minecraft:soul_sand)
B(-8,33,-2,minecraft:soul_sand)
B(-8,34,-2,minecraft:soul_sand)
B(-8,35,-2,minecraft:soul_sand)
B(-8,36,-2,minecraft:soul_sand)
B(-8,37,-2,minecraft:soul_sand)
B(-8,38,-2,minecraft:soul_sand)
B(-8,39,-2,minecraft:soul_sand)
B(-8,40,-2,minecraft:soul_sand)
B(-8,41,-2,minecraft:soul_sand)
B(-8,42,-2,minecraft:soul_sand)
B(-8,43,-2,minecraft:soul_sand)
B(-8,44,-2,minecraft:soul_sand)
B(-8,45,-2,minecraft:soul_sand)
B(-8,46,-2,minecraft:soul_sand)
B(-8,47,-2,minecraft:soul_sand)
B(-8,48,-2,minecraft:soul_sand)
B(-8,49,-2,minecraft:soul_sand)
B(-8,50,-2,minecraft:soul_sand)
B(-8,51,-2,minecraft:soul_sand)
B(-8,52,-2,minecraft:soul_sand)
B(-8,53,-2,minecraft:soul_sand)
B(-8,54,-2,minecraft:soul_sand)
B(-8,55,-2,minecraft:soul_sand)
B(-8,56,-2,minecraft:soul_sand)
B(-8,57,-2,minecraft:soul_sand)
B(-8,58,-2,minecraft:soul_sand)
B(-8,59,-2,minecraft:soul_sand)
B(-8,60,-2,minecraft:soul_sand)
B(-8,61,-2,minecraft:soul_sand)
B(-8,62,-2,minecraft:soul_sand)
B(-8,63,-2,minecraft:soul_sand)
B(-8,64,-2,minecraft:soul_sand)
B(-8,65,-2,minecraft:soul_sand)
B(-8,66,-2,minecraft:soul_sand)
B(-8,0,-1,minecraft:soul_sand)
B(-8,1,-1,minecraft:soul_sand)
B(-8,2,-1,minecraft:soul_sand)
B(-8,3,-1,minecraft:soul_sand)
B(-8,4,-1,minecraft:soul_sand)
B(-8,5,-1,minecraft:soul_sand)
B(-8,6,-1,minecraft:soul_sand)
B(-8,7,-1,minecraft:soul_sand)
B(-8,8,-1,minecraft:soul_sand)
B(-8,9,-1,minecraft:soul_sand)
B(-8,10,-1,minecraft:soul_sand)
B(-8,11,-1,minecraft:soul_sand)
B(-8,12,-1,minecraft:soul_sand)
B(-8,13,-1,minecraft:soul_sand)
B(-8,14,-1,minecraft:soul_sand)
B(-8,15,-1,minecraft:soul_sand)
B(-8,16,-1,minecraft:soul_sand)
B(-8,17,-1,minecraft:soul_sand)
B(-8,18,-1,minecraft:soul_sand)
B(-8,19,-1,minecraft:soul_sand)
B(-8,20,-1,minecraft:soul_sand)
B(-8,21,-1,minecraft:soul_sand)
B(-8,22,-1,minecraft:soul_sand)
B(-8,23,-1,minecraft:soul_sand)
B(-8,24,-1,minecraft:soul_sand)
B(-8,25,-1,minecraft:soul_sand)
B(-8,26,-1,minecraft:soul_sand)
B(-8,27,-1,minecraft:soul_sand)
B(-8,28,-1,minecraft:soul_sand)
B(-8,29,-1,minecraft:soul_sand)
B(-8,30,-1,minecraft:soul_sand)
B(-8,31,-1,minecraft:soul_sand)
B(-8,32,-1,minecraft:soul_sand)
B(-8,33,-1,minecraft:soul_sand)
B(-8,34,-1,minecraft:soul_sand)
B(-8,35,-1,minecraft:soul_sand)
B(-8,36,-1,minecraft:soul_sand)
B(-8,37,-1,minecraft:soul_sand)
B(-8,38,-1,minecraft:soul_sand)
B(-8,39,-1,minecraft:soul_sand)
B(-8,40,-1,minecraft:soul_sand)
B(-8,41,-1,minecraft:soul_sand)
B(-8,42,-1,minecraft:soul_sand)
B(-8,43,-1,minecraft:soul_sand)
B(-8,44,-1,minecraft:soul_sand)
B(-8,45,-1,minecraft:soul_sand)
B(-8,46,-1,minecraft:soul_sand)
B(-8,47,-1,minecraft:soul_sand)
B(-8,48,-1,minecraft:soul_sand)
B(-8,49,-1,minecraft:soul_sand)
B(-8,50,-1,minecraft:soul_sand)
B(-8,51,-1,minecraft:soul_sand)
B(-8,52,-1,minecraft:soul_sand)
B(-8,53,-1,minecraft:soul_sand)
B(-8,54,-1,minecraft:soul_sand)
B(-8,55,-1,minecraft:soul_sand)
B(-8,56,-1,minecraft:soul_sand)
B(-8,57,-1,minecraft:soul_sand)
B(-8,58,-1,minecraft:soul_sand)
B(-8,59,-1,minecraft:soul_sand)
B(-8,60,-1,minecraft:soul_sand)
B(-8,61,-1,minecraft:soul_sand)
B(-8,62,-1,minecraft:soul_sand)
B(-8,63,-1,minecraft:soul_sand)
B(-8,64,-1,minecraft:soul_sand)
B(-8,65,-1,minecraft:soul_sand)
B(-8,66,-1,minecraft:soul_sand)
B(-8,0,0,minecraft:soul_sand)
B(-8,1,0,minecraft:soul_sand)
B(-8,2,0,minecraft:soul_sand)
B(-8,3,0,minecraft:soul_sand)
B(-8,4,0,minecraft:soul_sand)
B(-8,5,0,minecraft:soul_sand)
B(-8,6,0,minecraft:soul_sand)
B(-8,7,0,minecraft:soul_sand)
B(-8,8,0,minecraft:soul_sand)
B(-8,9,0,minecraft:soul_sand)
B(-8,10,0,minecraft:soul_sand)
B(-8,11,0,minecraft:soul_sand)
B(-8,12,0,minecraft:soul_sand)
B(-8,13,0,minecraft:soul_sand)
B(-8,14,0,minecraft:soul_sand)
B(-8,15,0,minecraft:soul_sand)
B(-8,16,0,minecraft:soul_sand)
B(-8,17,0,minecraft:soul_sand)
B(-8,18,0,minecraft:soul_sand)
B(-8,19,0,minecraft:soul_sand)
B(-8,20,0,minecraft:soul_sand)
B(-8,21,0,minecraft:soul_sand)
B(-8,22,0,minecraft:soul_sand)
B(-8,23,0,minecraft:soul_sand)
B(-8,24,0,minecraft:soul_sand)
B(-8,25,0,minecraft:soul_sand)
B(-8,26,0,minecraft:soul_sand)
B(-8,27,0,minecraft:soul_sand)
B(-8,28,0,minecraft:soul_sand)
B(-8,29,0,minecraft:soul_sand)
B(-8,30,0,minecraft:soul_sand)
B(-8,31,0,minecraft:soul_sand)
B(-8,32,0,minecraft:soul_sand)
B(-8,33,0,minecraft:soul_sand)
B(-8,34,0,minecraft:soul_sand)
B(-8,35,0,minecraft:soul_sand)
B(-8,36,0,minecraft:soul_sand)
B(-8,37,0,minecraft:soul_sand)
B(-8,38,0,minecraft:soul_sand)
B(-8,39,0,minecraft:soul_sand)
B(-8,40,0,minecraft:soul_sand)
B(-8,41,0,minecraft:soul_sand)
B(-8,42,0,minecraft:soul_sand)
B(-8,43,0,minecraft:soul_sand)
B(-8,44,0,minecraft:soul_sand)
B(-8,45,0,minecraft:soul_sand)
B(-8,46,0,minecraft:soul_sand)
B(-8,47,0,minecraft:soul_sand)
B(-8,48,0,minecraft:soul_sand)
B(-8,49,0,minecraft:soul_sand)
B(-8,50,0,minecraft:soul_sand)
B(-8,51,0,minecraft:soul_sand)
B(-8,52,0,minecraft:soul_sand)
B(-8,53,0,minecraft:soul_sand)
B(-8,54,0,minecraft:soul_sand)
B(-8,55,0,minecraft:soul_sand)
B(-8,56,0,minecraft:soul_sand)
B(-8,57,0,minecraft:soul_sand)
B(-8,58,0,minecraft:soul_sand)
B(-8,59,0,minecraft:soul_sand)
B(-8,60,0,minecraft:soul_sand)
B(-8,61,0,minecraft:soul_sand)
B(-8,62,0,minecraft:soul_sand)
B(-8,63,0,minecraft:soul_sand)
B(-8,64,0,minecraft:soul_sand)
B(-8,65,0,minecraft:soul_sand)
B(-8,0,1,minecraft:soul_sand)
B(-8,1,1,minecraft:soul_sand)
B(-8,2,1,minecraft:soul_sand)
B(-8,3,1,minecraft:soul_sand)
B(-8,4,1,minecraft:soul_sand)
B(-8,5,1,minecraft:soul_sand)
B(-8,6,1,minecraft:soul_sand)
B(-8,7,1,minecraft:soul_sand)
B(-8,8,1,minecraft:soul_sand)
B(-8,9,1,minecraft:soul_sand)
B(-8,10,1,minecraft:soul_sand)
B(-8,11,1,minecraft:soul_sand)
B(-8,12,1,minecraft:soul_sand)
B(-8,13,1,minecraft:soul_sand)
B(-8,14,1,minecraft:soul_sand)
B(-8,15,1,minecraft:soul_sand)
B(-8,16,1,minecraft:soul_sand)
B(-8,17,1,minecraft:soul_sand)
B(-8,18,1,minecraft:soul_sand)
B(-8,19,1,minecraft:soul_sand)
B(-8,20,1,minecraft:soul_sand)
B(-8,21,1,minecraft:soul_sand)
B(-8,22,1,minecraft:soul_sand)
B(-8,23,1,minecraft:soul_sand)
B(-8,24,1,minecraft:soul_sand)
B(-8,25,1,minecraft:soul_sand)
B(-8,26,1,minecraft:soul_sand)
B(-8,27,1,minecraft:soul_sand)
B(-8,28,1,minecraft:soul_sand)
B(-8,29,1,minecraft:soul_sand)
B(-8,30,1,minecraft:soul_sand)
B(-8,31,1,minecraft:soul_sand)
B(-8,32,1,minecraft:soul_sand)
B(-8,33,1,minecraft:soul_sand)
B(-8,34,1,minecraft:soul_sand)
B(-8,35,1,minecraft:soul_sand)
B(-8,36,1,minecraft:soul_sand)
B(-8,37,1,minecraft:soul_sand)
B(-8,38,1,minecraft:soul_sand)
B(-8,39,1,minecraft:soul_sand)
B(-8,40,1,minecraft:soul_sand)
B(-8,41,1,minecraft:soul_sand)
B(-8,42,1,minecraft:soul_sand)
B(-8,43,1,minecraft:soul_sand)
B(-8,44,1,minecraft:soul_sand)
B(-8,45,1,minecraft:soul_sand)
B(-8,46,1,minecraft:soul_sand)
B(-8,47,1,minecraft:soul_sand)
B(-8,48,1,minecraft:soul_sand)
B(-8,49,1,minecraft:soul_sand)
B(-8,50,1,minecraft:soul_sand)
B(-8,51,1,minecraft:soul_sand)
B(-8,52,1,minecraft:soul_sand)
B(-8,53,1,minecraft:soul_sand)
B(-8,54,1,minecraft:soul_sand)
B(-8,55,1,minecraft:soul_sand)
B(-8,56,1,minecraft:soul_sand)
B(-8,57,1,minecraft:soul_sand)
B(-8,58,1,minecraft:soul_sand)
B(-8,59,1,minecraft:soul_sand)
B(-8,60,1,minecraft:soul_sand)
B(-8,61,1,minecraft:soul_sand)
B(-8,62,1,minecraft:soul_sand)
B(-8,0,2,minecraft:soul_sand)
B(-8,1,2,minecraft:soul_sand)
B(-8,2,2,minecraft:soul_sand)
B(-8,3,2,minecraft:soul_sand)
B(-8,4,2,minecraft:soul_sand)
B(-8,5,2,minecraft:soul_sand)
B(-8,6,2,minecraft:soul_sand)
B(-8,7,2,minecraft:soul_sand)
B(-8,8,2,minecraft:soul_sand)
B(-8,9,2,minecraft:soul_sand)
B(-8,10,2,minecraft:soul_sand)
B(-8,11,2,minecraft:soul_sand)
B(-8,12,2,minecraft:soul_sand)
B(-8,13,2,minecraft:soul_sand)
B(-8,14,2,minecraft:soul_sand)
B(-8,15,2,minecraft:soul_sand)
B(-8,16,2,minecraft:soul_sand)
B(-8,17,2,minecraft:soul_sand)
B(-8,18,2,minecraft:soul_sand)
B(-8,19,2,minecraft:soul_sand)
B(-8,20,2,minecraft:soul_sand)
B(-8,21,2,minecraft:soul_sand)
B(-8,22,2,minecraft:soul_sand)
B(-8,23,2,minecraft:soul_sand)
B(-8,24,2,minecraft:soul_sand)
B(-8,25,2,minecraft:soul_sand)
B(-8,26,2,minecraft:soul_sand)
B(-8,27,2,minecraft:soul_sand)
B(-8,28,2,minecraft:soul_sand)
B(-8,29,2,minecraft:soul_sand)
B(-8,30,2,minecraft:soul_sand)
B(-8,31,2,minecraft:soul_sand)
B(-8,32,2,minecraft:soul_sand)
B(-8,33,2,minecraft:soul_sand)
B(-8,34,2,minecraft:soul_sand)
B(-8,35,2,minecraft:soul_sand)
B(-8,36,2,minecraft:soul_sand)
B(-8,37,2,minecraft:soul_sand)
B(-8,38,2,minecraft:soul_sand)
B(-8,39,2,minecraft:soul_sand)
B(-8,40,2,minecraft:soul_sand)
B(-8,41,2,minecraft:soul_sand)
B(-8,42,2,minecraft:soul_sand)
B(-8,43,2,minecraft:soul_sand)
B(-8,44,2,minecraft:soul_sand)
B(-8,45,2,minecraft:soul_sand)
B(-8,46,2,minecraft:soul_sand)
B(-8,47,2,minecraft:soul_sand)
B(-8,48,2,minecraft:soul_sand)
B(-8,49,2,minecraft:soul_sand)
B(-8,50,2,minecraft:soul_sand)
B(-8,51,2,minecraft:soul_sand)
B(-8,52,2,minecraft:soul_sand)
B(-8,53,2,minecraft:soul_sand)
B(-8,54,2,minecraft:soul_sand)
B(-8,55,2,minecraft:soul_sand)
B(-8,0,3,minecraft:soul_sand)
B(-8,1,3,minecraft:soul_sand)
B(-8,2,3,minecraft:soul_sand)
B(-8,3,3,minecraft:soul_sand)
B(-8,4,3,minecraft:soul_sand)
B(-8,5,3,minecraft:soul_sand)
B(-8,6,3,minecraft:soul_sand)
B(-8,7,3,minecraft:soul_sand)
B(-8,8,3,minecraft:soul_sand)
B(-8,9,3,minecraft:soul_sand)
B(-8,10,3,minecraft:soul_sand)
B(-8,11,3,minecraft:soul_sand)
B(-8,12,3,minecraft:soul_sand)
B(-8,13,3,minecraft:soul_sand)
B(-8,14,3,minecraft:soul_sand)
B(-8,15,3,minecraft:soul_sand)
B(-8,16,3,minecraft:soul_sand)
B(-8,17,3,minecraft:soul_sand)
B(-8,18,3,minecraft:soul_sand)
B(-8,19,3,minecraft:soul_sand)
B(-8,20,3,minecraft:soul_sand)
B(-8,21,3,minecraft:soul_sand)
B(-8,22,3,minecraft:soul_sand)
B(-8,23,3,minecraft:soul_sand)
B(-8,24,3,minecraft:soul_sand)
B(-8,25,3,minecraft:soul_sand)
B(-8,26,3,minecraft:soul_sand)
B(-8,27,3,minecraft:soul_sand)
B(-8,28,3,minecraft:soul_sand)
B(-8,29,3,minecraft:soul_sand)
B(-8,30,3,minecraft:soul_sand)
B(-8,31,3,minecraft:soul_sand)
B(-8,32,3,minecraft:soul_sand)
B(-8,33,3,minecraft:soul_sand)
B(-8,34,3,minecraft:soul_sand)
B(-8,35,3,minecraft:soul_sand)
B(-8,36,3,minecraft:soul_sand)
B(-8,37,3,minecraft:soul_sand)
B(-8,38,3,minecraft:soul_sand)
B(-8,39,3,minecraft:soul_sand)
B(-8,40,3,minecraft:soul_sand)
B(-8,41,3,minecraft:soul_sand)
B(-8,42,3,minecraft:soul_sand)
B(-8,43,3,minecraft:soul_sand)
B(-8,44,3,minecraft:soul_sand)
B(-8,45,3,minecraft:soul_sand)
B(-8,46,3,minecraft:soul_sand)
B(-8,47,3,minecraft:soul_sand)
B(-8,48,3,minecraft:soul_sand)
B(-8,49,3,minecraft:soul_sand)
B(-8,50,3,minecraft:soul_sand)
B(-8,51,3,minecraft:soul_sand)
B(-8,52,3,minecraft:soul_sand)
B(-8,53,3,minecraft:soul_sand)
B(-8,54,3,minecraft:soul_sand)
B(-8,55,3,minecraft:soul_sand)
B(-8,56,3,minecraft:soul_sand)
B(-8,57,3,minecraft:soul_sand)
B(-8,58,3,minecraft:soul_sand)
B(-8,0,4,minecraft:soul_sand)
B(-8,1,4,minecraft:soul_sand)
B(-8,2,4,minecraft:soul_sand)
B(-8,3,4,minecraft:soul_sand)
B(-8,4,4,minecraft:soul_sand)
B(-8,5,4,minecraft:soul_sand)
B(-8,6,4,minecraft:soul_sand)
B(-8,7,4,minecraft:soul_sand)
B(-8,8,4,minecraft:soul_sand)
B(-8,9,4,minecraft:soul_sand)
B(-8,10,4,minecraft:soul_sand)
B(-8,11,4,minecraft:soul_sand)
B(-8,12,4,minecraft:soul_sand)
B(-8,13,4,minecraft:soul_sand)
B(-8,14,4,minecraft:soul_sand)
B(-8,15,4,minecraft:soul_sand)
B(-8,16,4,minecraft:soul_sand)
B(-8,17,4,minecraft:soul_sand)
B(-8,18,4,minecraft:soul_sand)
B(-8,19,4,minecraft:soul_sand)
B(-8,20,4,minecraft:soul_sand)
B(-8,21,4,minecraft:soul_sand)
B(-8,22,4,minecraft:soul_sand)
B(-8,23,4,minecraft:soul_sand)
B(-8,24,4,minecraft:soul_sand)
B(-8,25,4,minecraft:soul_sand)
B(-8,26,4,minecraft:soul_sand)
B(-8,27,4,minecraft:soul_sand)
B(-8,28,4,minecraft:soul_sand)
B(-8,29,4,minecraft:soul_sand)
B(-8,30,4,minecraft:soul_sand)
B(-8,31,4,minecraft:soul_sand)
B(-8,32,4,minecraft:soul_sand)
B(-8,33,4,minecraft:soul_sand)
B(-8,34,4,minecraft:soul_sand)
B(-8,35,4,minecraft:soul_sand)
B(-8,36,4,minecraft:soul_sand)
B(-8,37,4,minecraft:soul_sand)
B(-8,38,4,minecraft:soul_sand)
B(-8,39,4,minecraft:soul_sand)
B(-8,40,4,minecraft:soul_sand)
B(-8,41,4,minecraft:soul_sand)
B(-8,42,4,minecraft:soul_sand)
B(-8,43,4,minecraft:soul_sand)
B(-8,44,4,minecraft:soul_sand)
B(-8,45,4,minecraft:soul_sand)
B(-8,46,4,minecraft:soul_sand)
B(-8,47,4,minecraft:soul_sand)
B(-8,48,4,minecraft:soul_sand)
B(-8,49,4,minecraft:soul_sand)
B(-8,50,4,minecraft:soul_sand)
B(-8,51,4,minecraft:soul_sand)
B(-8,52,4,minecraft:soul_sand)
B(-8,53,4,minecraft:soul_sand)
B(-8,54,4,minecraft:soul_sand)
B(-8,55,4,minecraft:soul_sand)
B(-8,56,4,minecraft:soul_sand)
B(-8,57,4,minecraft:soul_sand)
B(-8,58,4,minecraft:soul_sand)
B(-8,59,4,minecraft:soul_sand)
B(-8,0,5,minecraft:soul_sand)
B(-8,1,5,minecraft:soul_sand)
B(-8,2,5,minecraft:soul_sand)
B(-8,3,5,minecraft:soul_sand)
B(-8,4,5,minecraft:soul_sand)
B(-8,5,5,minecraft:soul_sand)
B(-8,6,5,minecraft:soul_sand)
B(-8,7,5,minecraft:soul_sand)
B(-8,8,5,minecraft:soul_sand)
B(-8,9,5,minecraft:soul_sand)
B(-8,10,5,minecraft:soul_sand)
B(-8,11,5,minecraft:soul_sand)
B(-8,12,5,minecraft:soul_sand)
B(-8,13,5,minecraft:soul_sand)
B(-8,14,5,minecraft:soul_sand)
B(-8,15,5,minecraft:soul_sand)
B(-8,16,5,minecraft:soul_sand)
B(-8,17,5,minecraft:soul_sand)
B(-8,18,5,minecraft:soul_sand)
B(-8,19,5,minecraft:soul_sand)
B(-8,20,5,minecraft:soul_sand)
B(-8,21,5,minecraft:soul_sand)
B(-8,22,5,minecraft:soul_sand)
B(-8,23,5,minecraft:soul_sand)
B(-8,24,5,minecraft:soul_sand)
B(-8,25,5,minecraft:soul_sand)
B(-8,26,5,minecraft:soul_sand)
B(-8,27,5,minecraft:soul_sand)
B(-8,28,5,minecraft:soul_sand)
B(-8,29,5,minecraft:soul_sand)
B(-8,30,5,minecraft:soul_sand)
B(-8,31,5,minecraft:soul_sand)
B(-8,32,5,minecraft:soul_sand)
B(-8,33,5,minecraft:soul_sand)
B(-8,34,5,minecraft:soul_sand)
B(-8,35,5,minecraft:soul_sand)
B(-8,36,5,minecraft:soul_sand)
B(-8,37,5,minecraft:soul_sand)
B(-8,38,5,minecraft:soul_sand)
B(-8,39,5,minecraft:soul_sand)
B(-8,40,5,minecraft:soul_sand)
B(-8,41,5,minecraft:soul_sand)
B(-8,42,5,minecraft:soul_sand)
B(-8,43,5,minecraft:soul_sand)
B(-8,44,5,minecraft:soul_sand)
B(-8,45,5,minecraft:soul_sand)
B(-8,46,5,minecraft:soul_sand)
B(-8,47,5,minecraft:soul_sand)
B(-8,48,5,minecraft:soul_sand)
B(-8,49,5,minecraft:soul_sand)
B(-8,50,5,minecraft:soul_sand)
B(-8,51,5,minecraft:soul_sand)
B(-8,52,5,minecraft:soul_sand)
B(-8,53,5,minecraft:soul_sand)
B(-8,54,5,minecraft:soul_sand)
B(-8,55,5,minecraft:soul_sand)
B(-8,56,5,minecraft:soul_sand)
B(-8,0,6,minecraft:soul_sand)
B(-8,1,6,minecraft:soul_sand)
B(-8,2,6,minecraft:soul_sand)
B(-8,3,6,minecraft:soul_sand)
B(-8,4,6,minecraft:soul_sand)
B(-8,5,6,minecraft:soul_sand)
B(-8,6,6,minecraft:soul_sand)
B(-8,7,6,minecraft:soul_sand)
B(-8,8,6,minecraft:soul_sand)
B(-8,9,6,minecraft:soul_sand)
B(-8,10,6,minecraft:soul_sand)
B(-8,11,6,minecraft:soul_sand)
B(-8,12,6,minecraft:soul_sand)
B(-8,13,6,minecraft:soul_sand)
B(-8,14,6,minecraft:soul_sand)
B(-8,15,6,minecraft:soul_sand)
B(-8,16,6,minecraft:soul_sand)
B(-8,17,6,minecraft:soul_sand)
B(-8,18,6,minecraft:soul_sand)
B(-8,19,6,minecraft:soul_sand)
B(-8,20,6,minecraft:soul_sand)
B(-8,21,6,minecraft:soul_sand)
B(-8,22,6,minecraft:soul_sand)
B(-8,23,6,minecraft:soul_sand)
B(-8,24,6,minecraft:soul_sand)
B(-8,25,6,minecraft:soul_sand)
B(-8,26,6,minecraft:soul_sand)
B(-8,27,6,minecraft:soul_sand)
B(-8,28,6,minecraft:soul_sand)
B(-8,29,6,minecraft:soul_sand)
B(-8,30,6,minecraft:soul_sand)
B(-8,31,6,minecraft:soul_sand)
B(-8,32,6,minecraft:soul_sand)
B(-8,33,6,minecraft:soul_sand)
B(-8,34,6,minecraft:soul_sand)
B(-8,35,6,minecraft:soul_sand)
B(-8,36,6,minecraft:soul_sand)
B(-8,37,6,minecraft:soul_sand)
B(-8,38,6,minecraft:soul_sand)
B(-8,39,6,minecraft:soul_sand)
B(-8,40,6,minecraft:soul_sand)
B(-8,41,6,minecraft:soul_sand)
B(-8,42,6,minecraft:soul_sand)
B(-8,43,6,minecraft:soul_sand)
B(-8,44,6,minecraft:soul_sand)
B(-8,45,6,minecraft:soul_sand)
B(-8,46,6,minecraft:soul_sand)
B(-8,47,6,minecraft:soul_sand)
B(-8,48,6,minecraft:soul_sand)
B(-8,49,6,minecraft:soul_sand)
B(-8,50,6,minecraft:soul_sand)
B(-8,51,6,minecraft:soul_sand)
B(-8,52,6,minecraft:soul_sand)
B(-8,53,6,minecraft:soul_sand)
B(-8,54,6,minecraft:soul_sand)
B(-8,55,6,minecraft:soul_sand)
B(-8,56,6,minecraft:soul_sand)
B(-8,0,7,minecraft:soul_sand)
B(-8,1,7,minecraft:soul_sand)
B(-8,2,7,minecraft:soul_sand)
B(-8,3,7,minecraft:soul_sand)
B(-8,4,7,minecraft:soul_sand)
B(-8,5,7,minecraft:soul_sand)
B(-8,6,7,minecraft:soul_sand)
B(-8,7,7,minecraft:soul_sand)
B(-8,8,7,minecraft:soul_sand)
B(-8,9,7,minecraft:soul_sand)
B(-8,10,7,minecraft:soul_sand)
B(-8,11,7,minecraft:soul_sand)
B(-8,12,7,minecraft:soul_sand)
B(-8,13,7,minecraft:soul_sand)
B(-8,14,7,minecraft:soul_sand)
B(-8,15,7,minecraft:soul_sand)
B(-8,16,7,minecraft:soul_sand)
B(-8,17,7,minecraft:soul_sand)
B(-8,18,7,minecraft:soul_sand)
B(-8,19,7,minecraft:soul_sand)
B(-8,20,7,minecraft:soul_sand)
B(-8,21,7,minecraft:soul_sand)
B(-8,22,7,minecraft:soul_sand)
B(-8,23,7,minecraft:soul_sand)
B(-8,24,7,minecraft:soul_sand)
B(-8,25,7,minecraft:soul_sand)
B(-8,26,7,minecraft:soul_sand)
B(-8,27,7,minecraft:soul_sand)
B(-8,28,7,minecraft:soul_sand)
B(-8,29,7,minecraft:soul_sand)
B(-8,30,7,minecraft:soul_sand)
B(-8,31,7,minecraft:soul_sand)
B(-8,32,7,minecraft:soul_sand)
B(-8,33,7,minecraft:soul_sand)
B(-8,34,7,minecraft:soul_sand)
B(-8,35,7,minecraft:soul_sand)
B(-8,36,7,minecraft:soul_sand)
B(-8,37,7,minecraft:soul_sand)
B(-8,38,7,minecraft:soul_sand)
B(-8,39,7,minecraft:soul_sand)
B(-8,40,7,minecraft:soul_sand)
B(-8,41,7,minecraft:soul_sand)
B(-8,42,7,minecraft:soul_sand)
B(-8,43,7,minecraft:soul_sand)
B(-8,44,7,minecraft:soul_sand)
B(-8,45,7,minecraft:soul_sand)
B(-8,46,7,minecraft:soul_sand)
B(-8,47,7,minecraft:soul_sand)
B(-8,48,7,minecraft:soul_sand)
B(-8,49,7,minecraft:soul_sand)
B(-8,50,7,minecraft:soul_sand)
B(-8,51,7,minecraft:soul_sand)
B(-8,52,7,minecraft:soul_sand)
B(-8,53,7,minecraft:soul_sand)
B(-8,54,7,minecraft:soul_sand)
B(-8,55,7,minecraft:soul_sand)
B(-8,56,7,minecraft:soul_sand)
B(-8,0,8,minecraft:soul_sand)
B(-8,1,8,minecraft:soul_sand)
B(-8,2,8,minecraft:soul_sand)
B(-8,3,8,minecraft:soul_sand)
B(-8,4,8,minecraft:soul_sand)
B(-8,5,8,minecraft:soul_sand)
B(-8,6,8,minecraft:soul_sand)
B(-8,7,8,minecraft:soul_sand)
B(-8,8,8,minecraft:soul_sand)
B(-8,9,8,minecraft:soul_sand)
B(-8,10,8,minecraft:soul_sand)
B(-8,11,8,minecraft:soul_sand)
B(-8,12,8,minecraft:soul_sand)
B(-8,13,8,minecraft:soul_sand)
B(-8,14,8,minecraft:soul_sand)
B(-8,15,8,minecraft:soul_sand)
B(-8,16,8,minecraft:soul_sand)
B(-8,17,8,minecraft:soul_sand)
B(-8,18,8,minecraft:soul_sand)
B(-8,19,8,minecraft:soul_sand)
B(-8,20,8,minecraft:soul_sand)
B(-8,21,8,minecraft:soul_sand)
B(-8,22,8,minecraft:soul_sand)
B(-8,23,8,minecraft:soul_sand)
B(-8,24,8,minecraft:soul_sand)
B(-8,25,8,minecraft:soul_sand)
B(-8,26,8,minecraft:soul_sand)
B(-8,27,8,minecraft:soul_sand)
B(-8,28,8,minecraft:soul_sand)
B(-8,29,8,minecraft:soul_sand)
B(-8,30,8,minecraft:soul_sand)
B(-8,31,8,minecraft:soul_sand)
B(-8,32,8,minecraft:soul_sand)
B(-8,33,8,minecraft:soul_sand)
B(-8,34,8,minecraft:soul_sand)
B(-8,35,8,minecraft:soul_sand)
B(-8,36,8,minecraft:soul_sand)
B(-8,37,8,minecraft:soul_sand)
B(-8,38,8,minecraft:soul_sand)
B(-8,39,8,minecraft:soul_sand)
B(-8,40,8,minecraft:soul_sand)
B(-8,41,8,minecraft:soul_sand)
B(-8,42,8,minecraft:soul_sand)
B(-8,43,8,minecraft:soul_sand)
B(-8,44,8,minecraft:soul_sand)
B(-8,45,8,minecraft:soul_sand)
B(-8,46,8,minecraft:soul_sand)
B(-8,47,8,minecraft:soul_sand)
B(-8,48,8,minecraft:soul_sand)
B(-8,49,8,minecraft:soul_sand)
B(-8,50,8,minecraft:soul_sand)
B(-8,51,8,minecraft:soul_sand)
B(-8,52,8,minecraft:soul_sand)
B(-8,53,8,minecraft:soul_sand)
B(-8,54,8,minecraft:soul_sand)
B(-8,55,8,minecraft:soul_sand)
B(-7,0,-7,minecraft:soul_sand)
B(-7,1,-7,minecraft:soul_sand)
B(-7,2,-7,minecraft:soul_sand)
B(-7,3,-7,minecraft:soul_sand)
B(-7,4,-7,minecraft:soul_sand)
B(-7,5,-7,minecraft:soul_sand)
B(-7,6,-7,minecraft:soul_sand)
B(-7,7,-7,minecraft:soul_sand)
B(-7,8,-7,minecraft:soul_sand)
B(-7,9,-7,minecraft:soul_sand)
B(-7,10,-7,minecraft:soul_sand)
B(-7,11,-7,minecraft:soul_sand)
B(-7,12,-7,minecraft:soul_sand)
B(-7,13,-7,minecraft:soul_sand)
B(-7,14,-7,minecraft:soul_sand)
B(-7,15,-7,minecraft:soul_sand)
B(-7,16,-7,minecraft:soul_sand)
B(-7,17,-7,minecraft:soul_sand)
B(-7,18,-7,minecraft:soul_sand)
B(-7,19,-7,minecraft:soul_sand)
B(-7,20,-7,minecraft:soul_sand)
B(-7,21,-7,minecraft:soul_sand)
B(-7,22,-7,minecraft:soul_sand)
B(-7,23,-7,minecraft:soul_sand)
B(-7,24,-7,minecraft:soul_sand)
B(-7,25,-7,minecraft:soul_sand)
B(-7,26,-7,minecraft:soul_sand)
B(-7,27,-7,minecraft:soul_sand)
B(-7,28,-7,minecraft:soul_sand)
B(-7,29,-7,minecraft:soul_sand)
B(-7,30,-7,minecraft:soul_sand)
B(-7,31,-7,minecraft:soul_sand)
B(-7,32,-7,minecraft:soul_sand)
B(-7,33,-7,minecraft:soul_sand)
B(-7,34,-7,minecraft:soul_sand)
B(-7,35,-7,minecraft:soul_sand)
B(-7,36,-7,minecraft:soul_sand)
B(-7,37,-7,minecraft:soul_sand)
B(-7,38,-7,minecraft:soul_sand)
B(-7,39,-7,minecraft:soul_sand)
B(-7,40,-7,minecraft:soul_sand)
B(-7,41,-7,minecraft:soul_sand)
B(-7,42,-7,minecraft:soul_sand)
B(-7,43,-7,minecraft:soul_sand)
B(-7,44,-7,minecraft:soul_sand)
B(-7,45,-7,minecraft:soul_sand)
B(-7,46,-7,minecraft:soul_sand)
B(-7,47,-7,minecraft:soul_sand)
B(-7,48,-7,minecraft:soul_sand)
B(-7,49,-7,minecraft:soul_sand)
B(-7,50,-7,minecraft:soul_sand)
B(-7,51,-7,minecraft:soul_sand)
B(-7,52,-7,minecraft:soul_sand)
B(-7,53,-7,minecraft:soul_sand)
B(-7,54,-7,minecraft:soul_sand)
B(-7,55,-7,minecraft:soul_sand)
B(-7,56,-7,minecraft:soul_sand)
B(-7,57,-7,minecraft:soul_sand)
B(-7,58,-7,minecraft:soul_sand)
B(-7,59,-7,minecraft:soul_sand)
B(-7,60,-7,minecraft:soul_sand)
B(-7,61,-7,minecraft:soul_sand)
B(-7,62,-7,minecraft:soul_sand)
B(-7,63,-7,minecraft:soul_sand)
B(-7,64,-7,minecraft:soul_sand)
B(-7,65,-7,minecraft:soul_sand)
B(-7,66,-7,minecraft:soul_sand)
B(-7,67,-7,minecraft:soul_sand)
B(-7,68,-7,minecraft:soul_sand)
B(-7,69,-7,minecraft:soul_sand)
B(-7,70,-7,minecraft:soul_sand)
B(-7,71,-7,minecraft:soul_sand)
B(-7,72,-7,minecraft:soul_sand)
B(-7,73,-7,minecraft:soul_sand)
B(-7,74,-7,minecraft:soul_sand)
B(-7,75,-7,minecraft:soul_sand)
B(-7,76,-7,minecraft:soul_sand)
B(-7,77,-7,minecraft:soul_sand)
B(-7,78,-7,minecraft:soul_sand)
B(-7,0,-6,minecraft:soul_sand)
B(-7,1,-6,minecraft:soul_sand)
B(-7,2,-6,minecraft:soul_sand)
B(-7,3,-6,minecraft:soul_sand)
B(-7,4,-6,minecraft:soul_sand)
B(-7,5,-6,minecraft:soul_sand)
B(-7,6,-6,minecraft:soul_sand)
B(-7,7,-6,minecraft:soul_sand)
B(-7,8,-6,minecraft:soul_sand)
B(-7,9,-6,minecraft:soul_sand)
B(-7,10,-6,minecraft:soul_sand)
B(-7,11,-6,minecraft:soul_sand)
B(-7,12,-6,minecraft:soul_sand)
B(-7,13,-6,minecraft:soul_sand)
B(-7,14,-6,minecraft:soul_sand)
B(-7,15,-6,minecraft:soul_sand)
B(-7,16,-6,minecraft:soul_sand)
B(-7,17,-6,minecraft:soul_sand)
B(-7,18,-6,minecraft:soul_sand)
B(-7,19,-6,minecraft:soul_sand)
B(-7,20,-6,minecraft:soul_sand)
B(-7,21,-6,minecraft:soul_sand)
B(-7,22,-6,minecraft:soul_sand)
B(-7,23,-6,minecraft:soul_sand)
B(-7,24,-6,minecraft:soul_sand)
B(-7,25,-6,minecraft:soul_sand)
B(-7,26,-6,minecraft:soul_sand)
B(-7,27,-6,minecraft:soul_sand)
B(-7,28,-6,minecraft:soul_sand)
B(-7,29,-6,minecraft:soul_sand)
B(-7,30,-6,minecraft:soul_sand)
B(-7,31,-6,minecraft:soul_sand)
B(-7,32,-6,minecraft:soul_sand)
B(-7,33,-6,minecraft:soul_sand)
B(-7,34,-6,minecraft:soul_sand)
B(-7,35,-6,minecraft:soul_sand)
B(-7,36,-6,minecraft:soul_sand)
B(-7,37,-6,minecraft:soul_sand)
B(-7,38,-6,minecraft:soul_sand)
B(-7,39,-6,minecraft:soul_sand)
B(-7,40,-6,minecraft:soul_sand)
B(-7,41,-6,minecraft:soul_sand)
B(-7,42,-6,minecraft:soul_sand)
B(-7,43,-6,minecraft:soul_sand)
B(-7,44,-6,minecraft:soul_sand)
B(-7,45,-6,minecraft:soul_sand)
B(-7,46,-6,minecraft:soul_sand)
B(-7,47,-6,minecraft:soul_sand)
B(-7,48,-6,minecraft:soul_sand)
B(-7,49,-6,minecraft:soul_sand)
B(-7,50,-6,minecraft:soul_sand)
B(-7,51,-6,minecraft:soul_sand)
B(-7,52,-6,minecraft:soul_sand)
B(-7,53,-6,minecraft:soul_sand)
B(-7,54,-6,minecraft:soul_sand)
B(-7,55,-6,minecraft:soul_sand)
B(-7,56,-6,minecraft:soul_sand)
B(-7,57,-6,minecraft:soul_sand)
B(-7,58,-6,minecraft:soul_sand)
B(-7,59,-6,minecraft:soul_sand)
B(-7,60,-6,minecraft:soul_sand)
B(-7,61,-6,minecraft:soul_sand)
B(-7,62,-6,minecraft:soul_sand)
B(-7,63,-6,minecraft:soul_sand)
B(-7,64,-6,minecraft:soul_sand)
B(-7,65,-6,minecraft:soul_sand)
B(-7,66,-6,minecraft:soul_sand)
B(-7,67,-6,minecraft:soul_sand)
B(-7,68,-6,minecraft:soul_sand)
B(-7,69,-6,minecraft:soul_sand)
B(-7,70,-6,minecraft:soul_sand)
B(-7,71,-6,minecraft:soul_sand)
B(-7,0,-5,minecraft:soul_sand)
B(-7,1,-5,minecraft:soul_sand)
B(-7,2,-5,minecraft:soul_sand)
B(-7,3,-5,minecraft:soul_sand)
B(-7,4,-5,minecraft:soul_sand)
B(-7,5,-5,minecraft:soul_sand)
B(-7,6,-5,minecraft:soul_sand)
B(-7,7,-5,minecraft:soul_sand)
B(-7,8,-5,minecraft:soul_sand)
B(-7,9,-5,minecraft:soul_sand)
B(-7,10,-5,minecraft:soul_sand)
B(-7,11,-5,minecraft:soul_sand)
B(-7,12,-5,minecraft:soul_sand)
B(-7,13,-5,minecraft:soul_sand)
B(-7,14,-5,minecraft:soul_sand)
B(-7,15,-5,minecraft:soul_sand)
B(-7,16,-5,minecraft:soul_sand)
B(-7,17,-5,minecraft:soul_sand)
B(-7,18,-5,minecraft:soul_sand)
B(-7,19,-5,minecraft:soul_sand)
B(-7,20,-5,minecraft:soul_sand)
B(-7,21,-5,minecraft:soul_sand)
B(-7,22,-5,minecraft:soul_sand)
B(-7,23,-5,minecraft:soul_sand)
B(-7,24,-5,minecraft:soul_sand)
B(-7,25,-5,minecraft:soul_sand)
B(-7,26,-5,minecraft:soul_sand)
B(-7,27,-5,minecraft:soul_sand)
B(-7,28,-5,minecraft:soul_sand)
B(-7,29,-5,minecraft:soul_sand)
B(-7,30,-5,minecraft:soul_sand)
B(-7,31,-5,minecraft:soul_sand)
B(-7,32,-5,minecraft:soul_sand)
B(-7,33,-5,minecraft:soul_sand)
B(-7,34,-5,minecraft:soul_sand)
B(-7,35,-5,minecraft:soul_sand)
B(-7,36,-5,minecraft:soul_sand)
B(-7,37,-5,minecraft:soul_sand)
B(-7,38,-5,minecraft:soul_sand)
B(-7,39,-5,minecraft:soul_sand)
B(-7,40,-5,minecraft:soul_sand)
B(-7,41,-5,minecraft:soul_sand)
B(-7,42,-5,minecraft:soul_sand)
B(-7,43,-5,minecraft:soul_sand)
B(-7,44,-5,minecraft:soul_sand)
B(-7,45,-5,minecraft:soul_sand)
B(-7,46,-5,minecraft:soul_sand)
B(-7,47,-5,minecraft:soul_sand)
B(-7,48,-5,minecraft:soul_sand)
B(-7,49,-5,minecraft:soul_sand)
B(-7,50,-5,minecraft:soul_sand)
B(-7,51,-5,minecraft:soul_sand)
B(-7,52,-5,minecraft:soul_sand)
B(-7,53,-5,minecraft:soul_sand)
B(-7,54,-5,minecraft:soul_sand)
B(-7,55,-5,minecraft:soul_sand)
B(-7,56,-5,minecraft:soul_sand)
B(-7,57,-5,minecraft:soul_sand)
B(-7,58,-5,minecraft:soul_sand)
B(-7,59,-5,minecraft:soul_sand)
B(-7,60,-5,minecraft:soul_sand)
B(-7,61,-5,minecraft:soul_sand)
B(-7,62,-5,minecraft:soul_sand)
B(-7,63,-5,minecraft:soul_sand)
B(-7,64,-5,minecraft:soul_sand)
B(-7,65,-5,minecraft:soul_sand)
B(-7,66,-5,minecraft:soul_sand)
B(-7,67,-5,minecraft:soul_sand)
B(-7,0,-4,minecraft:soul_sand)
B(-7,1,-4,minecraft:soul_sand)
B(-7,2,-4,minecraft:soul_sand)
B(-7,3,-4,minecraft:soul_sand)
B(-7,4,-4,minecraft:soul_sand)
B(-7,5,-4,minecraft:soul_sand)
B(-7,6,-4,minecraft:soul_sand)
B(-7,7,-4,minecraft:soul_sand)
B(-7,8,-4,minecraft:soul_sand)
B(-7,9,-4,minecraft:soul_sand)
B(-7,10,-4,minecraft:soul_sand)
B(-7,11,-4,minecraft:soul_sand)
B(-7,12,-4,minecraft:soul_sand)
B(-7,13,-4,minecraft:soul_sand)
B(-7,14,-4,minecraft:soul_sand)
B(-7,15,-4,minecraft:soul_sand)
B(-7,16,-4,minecraft:soul_sand)
B(-7,17,-4,minecraft:soul_sand)
B(-7,18,-4,minecraft:soul_sand)
B(-7,19,-4,minecraft:soul_sand)
B(-7,20,-4,minecraft:soul_sand)
B(-7,21,-4,minecraft:soul_sand)
B(-7,22,-4,minecraft:soul_sand)
B(-7,23,-4,minecraft:soul_sand)
B(-7,24,-4,minecraft:soul_sand)
B(-7,25,-4,minecraft:soul_sand)
B(-7,26,-4,minecraft:soul_sand)
B(-7,27,-4,minecraft:soul_sand)
B(-7,28,-4,minecraft:soul_sand)
B(-7,29,-4,minecraft:soul_sand)
B(-7,30,-4,minecraft:soul_sand)
B(-7,31,-4,minecraft:soul_sand)
B(-7,32,-4,minecraft:soul_sand)
B(-7,33,-4,minecraft:soul_sand)
B(-7,34,-4,minecraft:soul_sand)
B(-7,35,-4,minecraft:soul_sand)
B(-7,36,-4,minecraft:soul_sand)
B(-7,37,-4,minecraft:soul_sand)
B(-7,38,-4,minecraft:soul_sand)
B(-7,39,-4,minecraft:soul_sand)
B(-7,40,-4,minecraft:soul_sand)
B(-7,41,-4,minecraft:soul_sand)
B(-7,42,-4,minecraft:soul_sand)
B(-7,43,-4,minecraft:soul_sand)
B(-7,44,-4,minecraft:soul_sand)
B(-7,45,-4,minecraft:soul_sand)
B(-7,46,-4,minecraft:soul_sand)
B(-7,47,-4,minecraft:soul_sand)
B(-7,48,-4,minecraft:soul_sand)
B(-7,49,-4,minecraft:soul_sand)
B(-7,50,-4,minecraft:soul_sand)
B(-7,51,-4,minecraft:soul_sand)
B(-7,52,-4,minecraft:soul_sand)
B(-7,53,-4,minecraft:soul_sand)
B(-7,54,-4,minecraft:soul_sand)
B(-7,55,-4,minecraft:soul_sand)
B(-7,56,-4,minecraft:soul_sand)
B(-7,57,-4,minecraft:soul_sand)
B(-7,58,-4,minecraft:soul_sand)
B(-7,59,-4,minecraft:soul_sand)
B(-7,60,-4,minecraft:soul_sand)
B(-7,61,-4,minecraft:soul_sand)
B(-7,62,-4,minecraft:soul_sand)
B(-7,63,-4,minecraft:soul_sand)
B(-7,64,-4,minecraft:soul_sand)
B(-7,65,-4,minecraft:soul_sand)
B(-7,66,-4,minecraft:soul_sand)
B(-7,67,-4,minecraft:soul_sand)
B(-7,0,-3,minecraft:soul_sand)
B(-7,1,-3,minecraft:soul_sand)
B(-7,2,-3,minecraft:soul_sand)
B(-7,3,-3,minecraft:soul_sand)
B(-7,4,-3,minecraft:soul_sand)
B(-7,5,-3,minecraft:soul_sand)
B(-7,6,-3,minecraft:soul_sand)
B(-7,7,-3,minecraft:soul_sand)
B(-7,8,-3,minecraft:soul_sand)
B(-7,9,-3,minecraft:soul_sand)
B(-7,10,-3,minecraft:soul_sand)
B(-7,11,-3,minecraft:soul_sand)
B(-7,12,-3,minecraft:soul_sand)
B(-7,13,-3,minecraft:soul_sand)
B(-7,14,-3,minecraft:soul_sand)
B(-7,15,-3,minecraft:soul_sand)
B(-7,16,-3,minecraft:soul_sand)
B(-7,17,-3,minecraft:soul_sand)
B(-7,18,-3,minecraft:soul_sand)
B(-7,19,-3,minecraft:soul_sand)
B(-7,20,-3,minecraft:soul_sand)
B(-7,21,-3,minecraft:soul_sand)
B(-7,22,-3,minecraft:soul_sand)
B(-7,23,-3,minecraft:soul_sand)
B(-7,24,-3,minecraft:soul_sand)
B(-7,25,-3,minecraft:soul_sand)
B(-7,26,-3,minecraft:soul_sand)
B(-7,27,-3,minecraft:soul_sand)
B(-7,28,-3,minecraft:soul_sand)
B(-7,29,-3,minecraft:soul_sand)
B(-7,30,-3,minecraft:soul_sand)
B(-7,31,-3,minecraft:soul_sand)
B(-7,32,-3,minecraft:soul_sand)
B(-7,33,-3,minecraft:soul_sand)
B(-7,34,-3,minecraft:soul_sand)
B(-7,35,-3,minecraft:soul_sand)
B(-7,36,-3,minecraft:soul_sand)
B(-7,37,-3,minecraft:soul_sand)
B(-7,38,-3,minecraft:soul_sand)
B(-7,39,-3,minecraft:soul_sand)
B(-7,40,-3,minecraft:soul_sand)
B(-7,41,-3,minecraft:soul_sand)
B(-7,42,-3,minecraft:soul_sand)
B(-7,43,-3,minecraft:soul_sand)
B(-7,44,-3,minecraft:soul_sand)
B(-7,45,-3,minecraft:soul_sand)
B(-7,46,-3,minecraft:soul_sand)
B(-7,47,-3,minecraft:soul_sand)
B(-7,48,-3,minecraft:soul_sand)
B(-7,49,-3,minecraft:soul_sand)
B(-7,50,-3,minecraft:soul_sand)
B(-7,51,-3,minecraft:soul_sand)
B(-7,52,-3,minecraft:soul_sand)
B(-7,53,-3,minecraft:soul_sand)
B(-7,54,-3,minecraft:soul_sand)
B(-7,55,-3,minecraft:soul_sand)
B(-7,56,-3,minecraft:soul_sand)
B(-7,57,-3,minecraft:soul_sand)
B(-7,58,-3,minecraft:soul_sand)
B(-7,59,-3,minecraft:soul_sand)
B(-7,60,-3,minecraft:soul_sand)
B(-7,61,-3,minecraft:soul_sand)
B(-7,62,-3,minecraft:soul_sand)
B(-7,63,-3,minecraft:soul_sand)
B(-7,64,-3,minecraft:soul_sand)
B(-7,65,-3,minecraft:soul_sand)
B(-7,66,-3,minecraft:soul_sand)
B(-7,67,-3,minecraft:soul_sand)
B(-7,0,-2,minecraft:soul_sand)
B(-7,1,-2,minecraft:soul_sand)
B(-7,2,-2,minecraft:soul_sand)
B(-7,3,-2,minecraft:soul_sand)
B(-7,4,-2,minecraft:soul_sand)
B(-7,5,-2,minecraft:soul_sand)
B(-7,6,-2,minecraft:soul_sand)
B(-7,7,-2,minecraft:soul_sand)
B(-7,8,-2,minecraft:soul_sand)
B(-7,9,-2,minecraft:soul_sand)
B(-7,10,-2,minecraft:soul_sand)
B(-7,11,-2,minecraft:soul_sand)
B(-7,12,-2,minecraft:soul_sand)
B(-7,13,-2,minecraft:soul_sand)
B(-7,14,-2,minecraft:soul_sand)
B(-7,15,-2,minecraft:soul_sand)
B(-7,16,-2,minecraft:soul_sand)
B(-7,17,-2,minecraft:soul_sand)
B(-7,18,-2,minecraft:soul_sand)
B(-7,19,-2,minecraft:soul_sand)
B(-7,20,-2,minecraft:soul_sand)
B(-7,21,-2,minecraft:soul_sand)
B(-7,22,-2,minecraft:soul_sand)
B(-7,23,-2,minecraft:soul_sand)
B(-7,24,-2,minecraft:soul_sand)
B(-7,25,-2,minecraft:soul_sand)
B(-7,26,-2,minecraft:soul_sand)
B(-7,27,-2,minecraft:soul_sand)
B(-7,28,-2,minecraft:soul_sand)
B(-7,29,-2,minecraft:soul_sand)
B(-7,30,-2,minecraft:soul_sand)
B(-7,31,-2,minecraft:soul_sand)
B(-7,32,-2,minecraft:soul_sand)
B(-7,33,-2,minecraft:soul_sand)
B(-7,34,-2,minecraft:soul_sand)
B(-7,35,-2,minecraft:soul_sand)
B(-7,36,-2,minecraft:soul_sand)
B(-7,37,-2,minecraft:soul_sand)
B(-7,38,-2,minecraft:soul_sand)
B(-7,39,-2,minecraft:soul_sand)
B(-7,40,-2,minecraft:soul_sand)
B(-7,41,-2,minecraft:soul_sand)
B(-7,42,-2,minecraft:soul_sand)
B(-7,43,-2,minecraft:soul_sand)
B(-7,44,-2,minecraft:soul_sand)
B(-7,45,-2,minecraft:soul_sand)
B(-7,46,-2,minecraft:soul_sand)
B(-7,47,-2,minecraft:soul_sand)
B(-7,48,-2,minecraft:soul_sand)
B(-7,49,-2,minecraft:soul_sand)
B(-7,50,-2,minecraft:soul_sand)
B(-7,51,-2,minecraft:soul_sand)
B(-7,52,-2,minecraft:soul_sand)
B(-7,53,-2,minecraft:soul_sand)
B(-7,54,-2,minecraft:soul_sand)
B(-7,55,-2,minecraft:soul_sand)
B(-7,56,-2,minecraft:soul_sand)
B(-7,57,-2,minecraft:soul_sand)
B(-7,58,-2,minecraft:soul_sand)
B(-7,59,-2,minecraft:soul_sand)
B(-7,60,-2,minecraft:soul_sand)
B(-7,61,-2,minecraft:soul_sand)
B(-7,62,-2,minecraft:soul_sand)
B(-7,63,-2,minecraft:soul_sand)
B(-7,64,-2,minecraft:soul_sand)
B(-7,65,-2,minecraft:soul_sand)
B(-7,66,-2,minecraft:soul_sand)
B(-7,67,-2,minecraft:soul_sand)
B(-7,0,-1,minecraft:soul_sand)
B(-7,1,-1,minecraft:soul_sand)
B(-7,2,-1,minecraft:soul_sand)
B(-7,3,-1,minecraft:soul_sand)
B(-7,4,-1,minecraft:soul_sand)
B(-7,5,-1,minecraft:soul_sand)
B(-7,6,-1,minecraft:soul_sand)
B(-7,7,-1,minecraft:soul_sand)
B(-7,8,-1,minecraft:soul_sand)
B(-7,9,-1,minecraft:soul_sand)
B(-7,10,-1,minecraft:soul_sand)
B(-7,11,-1,minecraft:soul_sand)
B(-7,12,-1,minecraft:soul_sand)
B(-7,13,-1,minecraft:soul_sand)
B(-7,14,-1,minecraft:soul_sand)
B(-7,15,-1,minecraft:soul_sand)
B(-7,16,-1,minecraft:soul_sand)
B(-7,17,-1,minecraft:soul_sand)
B(-7,18,-1,minecraft:soul_sand)
B(-7,19,-1,minecraft:soul_sand)
B(-7,20,-1,minecraft:soul_sand)
B(-7,21,-1,minecraft:soul_sand)
B(-7,22,-1,minecraft:soul_sand)
B(-7,23,-1,minecraft:soul_sand)
B(-7,24,-1,minecraft:soul_sand)
B(-7,25,-1,minecraft:soul_sand)
B(-7,26,-1,minecraft:soul_sand)
B(-7,27,-1,minecraft:soul_sand)
B(-7,28,-1,minecraft:soul_sand)
B(-7,29,-1,minecraft:soul_sand)
B(-7,30,-1,minecraft:soul_sand)
B(-7,31,-1,minecraft:soul_sand)
B(-7,32,-1,minecraft:soul_sand)
B(-7,33,-1,minecraft:soul_sand)
B(-7,34,-1,minecraft:soul_sand)
B(-7,35,-1,minecraft:soul_sand)
B(-7,36,-1,minecraft:soul_sand)
B(-7,37,-1,minecraft:soul_sand)
B(-7,38,-1,minecraft:soul_sand)
B(-7,39,-1,minecraft:soul_sand)
B(-7,40,-1,minecraft:soul_sand)
B(-7,41,-1,minecraft:soul_sand)
B(-7,42,-1,minecraft:soul_sand)
B(-7,43,-1,minecraft:soul_sand)
B(-7,44,-1,minecraft:soul_sand)
B(-7,45,-1,minecraft:soul_sand)
B(-7,46,-1,minecraft:soul_sand)
B(-7,47,-1,minecraft:soul_sand)
B(-7,48,-1,minecraft:soul_sand)
B(-7,49,-1,minecraft:soul_sand)
B(-7,50,-1,minecraft:soul_sand)
B(-7,51,-1,minecraft:soul_sand)
B(-7,52,-1,minecraft:soul_sand)
B(-7,53,-1,minecraft:soul_sand)
B(-7,54,-1,minecraft:soul_sand)
B(-7,55,-1,minecraft:soul_sand)
B(-7,56,-1,minecraft:soul_sand)
B(-7,57,-1,minecraft:soul_sand)
B(-7,58,-1,minecraft:soul_sand)
B(-7,59,-1,minecraft:soul_sand)
B(-7,60,-1,minecraft:soul_sand)
B(-7,61,-1,minecraft:soul_sand)
B(-7,62,-1,minecraft:soul_sand)
B(-7,63,-1,minecraft:soul_sand)
B(-7,64,-1,minecraft:soul_sand)
B(-7,65,-1,minecraft:soul_sand)
B(-7,66,-1,minecraft:soul_sand)
B(-7,0,0,minecraft:soul_sand)
B(-7,1,0,minecraft:soul_sand)
B(-7,2,0,minecraft:soul_sand)
B(-7,3,0,minecraft:soul_sand)
B(-7,4,0,minecraft:soul_sand)
B(-7,5,0,minecraft:soul_sand)
B(-7,6,0,minecraft:soul_sand)
B(-7,7,0,minecraft:soul_sand)
B(-7,8,0,minecraft:soul_sand)
B(-7,9,0,minecraft:soul_sand)
B(-7,10,0,minecraft:soul_sand)
B(-7,11,0,minecraft:soul_sand)
B(-7,12,0,minecraft:soul_sand)
B(-7,13,0,minecraft:soul_sand)
B(-7,14,0,minecraft:soul_sand)
B(-7,15,0,minecraft:soul_sand)
B(-7,16,0,minecraft:soul_sand)
B(-7,17,0,minecraft:soul_sand)
B(-7,18,0,minecraft:soul_sand)
B(-7,19,0,minecraft:soul_sand)
B(-7,20,0,minecraft:soul_sand)
B(-7,21,0,minecraft:soul_sand)
B(-7,22,0,minecraft:soul_sand)
B(-7,23,0,minecraft:soul_sand)
B(-7,24,0,minecraft:soul_sand)
B(-7,25,0,minecraft:soul_sand)
B(-7,26,0,minecraft:soul_sand)
B(-7,27,0,minecraft:soul_sand)
B(-7,28,0,minecraft:soul_sand)
B(-7,29,0,minecraft:soul_sand)
B(-7,30,0,minecraft:soul_sand)
B(-7,31,0,minecraft:soul_sand)
B(-7,32,0,minecraft:soul_sand)
B(-7,33,0,minecraft:soul_sand)
B(-7,34,0,minecraft:soul_sand)
B(-7,35,0,minecraft:soul_sand)
B(-7,36,0,minecraft:soul_sand)
B(-7,37,0,minecraft:soul_sand)
B(-7,38,0,minecraft:soul_sand)
B(-7,39,0,minecraft:soul_sand)
B(-7,40,0,minecraft:soul_sand)
B(-7,41,0,minecraft:soul_sand)
B(-7,42,0,minecraft:soul_sand)
B(-7,43,0,minecraft:soul_sand)
B(-7,44,0,minecraft:soul_sand)
B(-7,45,0,minecraft:soul_sand)
B(-7,46,0,minecraft:soul_sand)
B(-7,47,0,minecraft:soul_sand)
B(-7,48,0,minecraft:soul_sand)
B(-7,49,0,minecraft:soul_sand)
B(-7,50,0,minecraft:soul_sand)
B(-7,51,0,minecraft:soul_sand)
B(-7,52,0,minecraft:soul_sand)
B(-7,53,0,minecraft:soul_sand)
B(-7,54,0,minecraft:soul_sand)
B(-7,55,0,minecraft:soul_sand)
B(-7,56,0,minecraft:soul_sand)
B(-7,57,0,minecraft:soul_sand)
B(-7,58,0,minecraft:soul_sand)
B(-7,59,0,minecraft:soul_sand)
B(-7,60,0,minecraft:soul_sand)
B(-7,61,0,minecraft:soul_sand)
B(-7,62,0,minecraft:soul_sand)
B(-7,63,0,minecraft:soul_sand)
B(-7,64,0,minecraft:soul_sand)
B(-7,65,0,minecraft:soul_sand)
B(-7,0,1,minecraft:soul_sand)
B(-7,1,1,minecraft:soul_sand)
B(-7,2,1,minecraft:soul_sand)
B(-7,3,1,minecraft:soul_sand)
B(-7,4,1,minecraft:soul_sand)
B(-7,5,1,minecraft:soul_sand)
B(-7,6,1,minecraft:soul_sand)
B(-7,7,1,minecraft:soul_sand)
B(-7,8,1,minecraft:soul_sand)
B(-7,9,1,minecraft:soul_sand)
B(-7,10,1,minecraft:soul_sand)
B(-7,11,1,minecraft:soul_sand)
B(-7,12,1,minecraft:soul_sand)
B(-7,13,1,minecraft:soul_sand)
B(-7,14,1,minecraft:soul_sand)
B(-7,15,1,minecraft:soul_sand)
B(-7,16,1,minecraft:soul_sand)
B(-7,17,1,minecraft:soul_sand)
B(-7,18,1,minecraft:soul_sand)
B(-7,19,1,minecraft:soul_sand)
B(-7,20,1,minecraft:soul_sand)
B(-7,21,1,minecraft:soul_sand)
B(-7,22,1,minecraft:soul_sand)
B(-7,23,1,minecraft:soul_sand)
B(-7,24,1,minecraft:soul_sand)
B(-7,25,1,minecraft:soul_sand)
B(-7,26,1,minecraft:soul_sand)
B(-7,27,1,minecraft:soul_sand)
B(-7,28,1,minecraft:soul_sand)
B(-7,29,1,minecraft:soul_sand)
B(-7,30,1,minecraft:soul_sand)
B(-7,31,1,minecraft:soul_sand)
B(-7,32,1,minecraft:soul_sand)
B(-7,33,1,minecraft:soul_sand)
B(-7,34,1,minecraft:soul_sand)
B(-7,35,1,minecraft:soul_sand)
B(-7,36,1,minecraft:soul_sand)
B(-7,37,1,minecraft:soul_sand)
B(-7,38,1,minecraft:soul_sand)
B(-7,39,1,minecraft:soul_sand)
B(-7,40,1,minecraft:soul_sand)
B(-7,41,1,minecraft:soul_sand)
B(-7,42,1,minecraft:soul_sand)
B(-7,43,1,minecraft:soul_sand)
B(-7,44,1,minecraft:soul_sand)
B(-7,45,1,minecraft:soul_sand)
B(-7,46,1,minecraft:soul_sand)
B(-7,47,1,minecraft:soul_sand)
B(-7,48,1,minecraft:soul_sand)
B(-7,49,1,minecraft:soul_sand)
B(-7,50,1,minecraft:soul_sand)
B(-7,51,1,minecraft:soul_sand)
B(-7,52,1,minecraft:soul_sand)
B(-7,53,1,minecraft:soul_sand)
B(-7,54,1,minecraft:soul_sand)
B(-7,55,1,minecraft:soul_sand)
B(-7,56,1,minecraft:soul_sand)
B(-7,57,1,minecraft:soul_sand)
B(-7,58,1,minecraft:soul_sand)
B(-7,59,1,minecraft:soul_sand)
B(-7,60,1,minecraft:soul_sand)
B(-7,61,1,minecraft:soul_sand)
B(-7,62,1,minecraft:soul_sand)
B(-7,63,1,minecraft:soul_sand)
B(-7,64,1,minecraft:soul_sand)
B(-7,0,2,minecraft:soul_sand)
B(-7,1,2,minecraft:soul_sand)
B(-7,2,2,minecraft:soul_sand)
B(-7,3,2,minecraft:soul_sand)
B(-7,4,2,minecraft:soul_sand)
B(-7,5,2,minecraft:soul_sand)
B(-7,6,2,minecraft:soul_sand)
B(-7,7,2,minecraft:soul_sand)
B(-7,8,2,minecraft:soul_sand)
B(-7,9,2,minecraft:soul_sand)
B(-7,10,2,minecraft:soul_sand)
B(-7,11,2,minecraft:soul_sand)
B(-7,12,2,minecraft:soul_sand)
B(-7,13,2,minecraft:soul_sand)
B(-7,14,2,minecraft:soul_sand)
B(-7,15,2,minecraft:soul_sand)
B(-7,16,2,minecraft:soul_sand)
B(-7,17,2,minecraft:soul_sand)
B(-7,18,2,minecraft:soul_sand)
B(-7,19,2,minecraft:soul_sand)
B(-7,20,2,minecraft:soul_sand)
B(-7,21,2,minecraft:soul_sand)
B(-7,22,2,minecraft:soul_sand)
B(-7,23,2,minecraft:soul_sand)
B(-7,24,2,minecraft:soul_sand)
B(-7,25,2,minecraft:soul_sand)
B(-7,26,2,minecraft:soul_sand)
B(-7,27,2,minecraft:soul_sand)
B(-7,28,2,minecraft:soul_sand)
B(-7,29,2,minecraft:soul_sand)
B(-7,30,2,minecraft:soul_sand)
B(-7,31,2,minecraft:soul_sand)
B(-7,32,2,minecraft:soul_sand)
B(-7,33,2,minecraft:soul_sand)
B(-7,34,2,minecraft:soul_sand)
B(-7,35,2,minecraft:soul_sand)
B(-7,36,2,minecraft:soul_sand)
B(-7,37,2,minecraft:soul_sand)
B(-7,38,2,minecraft:soul_sand)
B(-7,39,2,minecraft:soul_sand)
B(-7,40,2,minecraft:soul_sand)
B(-7,41,2,minecraft:soul_sand)
B(-7,42,2,minecraft:soul_sand)
B(-7,43,2,minecraft:soul_sand)
B(-7,44,2,minecraft:soul_sand)
B(-7,45,2,minecraft:soul_sand)
B(-7,46,2,minecraft:soul_sand)
B(-7,47,2,minecraft:soul_sand)
B(-7,48,2,minecraft:soul_sand)
B(-7,49,2,minecraft:soul_sand)
B(-7,50,2,minecraft:soul_sand)
B(-7,51,2,minecraft:soul_sand)
B(-7,52,2,minecraft:soul_sand)
B(-7,53,2,minecraft:soul_sand)
B(-7,54,2,minecraft:soul_sand)
B(-7,55,2,minecraft:soul_sand)
B(-7,56,2,minecraft:soul_sand)
B(-7,57,2,minecraft:soul_sand)
B(-7,58,2,minecraft:soul_sand)
B(-7,59,2,minecraft:soul_sand)
B(-7,60,2,minecraft:soul_sand)
B(-7,0,3,minecraft:soul_sand)
B(-7,1,3,minecraft:soul_sand)
B(-7,2,3,minecraft:soul_sand)
B(-7,3,3,minecraft:soul_sand)
B(-7,4,3,minecraft:soul_sand)
B(-7,5,3,minecraft:soul_sand)
B(-7,6,3,minecraft:soul_sand)
B(-7,7,3,minecraft:soul_sand)
B(-7,8,3,minecraft:soul_sand)
B(-7,9,3,minecraft:soul_sand)
B(-7,10,3,minecraft:soul_sand)
B(-7,11,3,minecraft:soul_sand)
B(-7,12,3,minecraft:soul_sand)
B(-7,13,3,minecraft:soul_sand)
B(-7,14,3,minecraft:soul_sand)
B(-7,15,3,minecraft:soul_sand)
B(-7,16,3,minecraft:soul_sand)
B(-7,17,3,minecraft:soul_sand)
B(-7,18,3,minecraft:soul_sand)
B(-7,19,3,minecraft:soul_sand)
B(-7,20,3,minecraft:soul_sand)
B(-7,21,3,minecraft:soul_sand)
B(-7,22,3,minecraft:soul_sand)
B(-7,23,3,minecraft:soul_sand)
B(-7,24,3,minecraft:soul_sand)
B(-7,25,3,minecraft:soul_sand)
B(-7,26,3,minecraft:soul_sand)
B(-7,27,3,minecraft:soul_sand)
B(-7,28,3,minecraft:soul_sand)
B(-7,29,3,minecraft:soul_sand)
B(-7,30,3,minecraft:soul_sand)
B(-7,31,3,minecraft:soul_sand)
B(-7,32,3,minecraft:soul_sand)
B(-7,33,3,minecraft:soul_sand)
B(-7,34,3,minecraft:soul_sand)
B(-7,35,3,minecraft:soul_sand)
B(-7,36,3,minecraft:soul_sand)
B(-7,37,3,minecraft:soul_sand)
B(-7,38,3,minecraft:soul_sand)
B(-7,39,3,minecraft:soul_sand)
B(-7,40,3,minecraft:soul_sand)
B(-7,41,3,minecraft:soul_sand)
B(-7,42,3,minecraft:soul_sand)
B(-7,43,3,minecraft:soul_sand)
B(-7,44,3,minecraft:soul_sand)
B(-7,45,3,minecraft:soul_sand)
B(-7,46,3,minecraft:soul_sand)
B(-7,47,3,minecraft:soul_sand)
B(-7,48,3,minecraft:soul_sand)
B(-7,49,3,minecraft:soul_sand)
B(-7,50,3,minecraft:soul_sand)
B(-7,51,3,minecraft:soul_sand)
B(-7,52,3,minecraft:soul_sand)
B(-7,53,3,minecraft:soul_sand)
B(-7,54,3,minecraft:soul_sand)
B(-7,55,3,minecraft:soul_sand)
B(-7,56,3,minecraft:soul_sand)
B(-7,57,3,minecraft:soul_sand)
B(-7,58,3,minecraft:soul_sand)
B(-7,59,3,minecraft:soul_sand)
B(-7,60,3,minecraft:soul_sand)
B(-7,61,3,minecraft:soul_sand)
B(-7,0,4,minecraft:soul_sand)
B(-7,1,4,minecraft:soul_sand)
B(-7,2,4,minecraft:soul_sand)
B(-7,3,4,minecraft:soul_sand)
B(-7,4,4,minecraft:soul_sand)
B(-7,5,4,minecraft:soul_sand)
B(-7,6,4,minecraft:soul_sand)
B(-7,7,4,minecraft:soul_sand)
B(-7,8,4,minecraft:soul_sand)
B(-7,9,4,minecraft:soul_sand)
B(-7,10,4,minecraft:soul_sand)
B(-7,11,4,minecraft:soul_sand)
B(-7,12,4,minecraft:soul_sand)
B(-7,13,4,minecraft:soul_sand)
B(-7,14,4,minecraft:soul_sand)
B(-7,15,4,minecraft:soul_sand)
B(-7,16,4,minecraft:soul_sand)
B(-7,17,4,minecraft:soul_sand)
B(-7,18,4,minecraft:soul_sand)
B(-7,19,4,minecraft:soul_sand)
B(-7,20,4,minecraft:soul_sand)
B(-7,21,4,minecraft:soul_sand)
B(-7,22,4,minecraft:soul_sand)
B(-7,23,4,minecraft:soul_sand)
B(-7,24,4,minecraft:soul_sand)
B(-7,25,4,minecraft:soul_sand)
B(-7,26,4,minecraft:soul_sand)
B(-7,27,4,minecraft:soul_sand)
B(-7,28,4,minecraft:soul_sand)
B(-7,29,4,minecraft:soul_sand)
B(-7,30,4,minecraft:soul_sand)
B(-7,31,4,minecraft:soul_sand)
B(-7,32,4,minecraft:soul_sand)
B(-7,33,4,minecraft:soul_sand)
B(-7,34,4,minecraft:soul_sand)
B(-7,35,4,minecraft:soul_sand)
B(-7,36,4,minecraft:soul_sand)
B(-7,37,4,minecraft:soul_sand)
B(-7,38,4,minecraft:soul_sand)
B(-7,39,4,minecraft:soul_sand)
B(-7,40,4,minecraft:soul_sand)
B(-7,41,4,minecraft:soul_sand)
B(-7,42,4,minecraft:soul_sand)
B(-7,43,4,minecraft:soul_sand)
B(-7,44,4,minecraft:soul_sand)
B(-7,45,4,minecraft:soul_sand)
B(-7,46,4,minecraft:soul_sand)
B(-7,47,4,minecraft:soul_sand)
B(-7,48,4,minecraft:soul_sand)
B(-7,49,4,minecraft:soul_sand)
B(-7,50,4,minecraft:soul_sand)
B(-7,51,4,minecraft:soul_sand)
B(-7,52,4,minecraft:soul_sand)
B(-7,53,4,minecraft:soul_sand)
B(-7,54,4,minecraft:soul_sand)
B(-7,55,4,minecraft:soul_sand)
B(-7,56,4,minecraft:soul_sand)
B(-7,57,4,minecraft:soul_sand)
B(-7,58,4,minecraft:soul_sand)
B(-7,59,4,minecraft:soul_sand)
B(-7,60,4,minecraft:soul_sand)
B(-7,0,5,minecraft:soul_sand)
B(-7,1,5,minecraft:soul_sand)
B(-7,2,5,minecraft:soul_sand)
B(-7,3,5,minecraft:soul_sand)
B(-7,4,5,minecraft:soul_sand)
B(-7,5,5,minecraft:soul_sand)
B(-7,6,5,minecraft:soul_sand)
B(-7,7,5,minecraft:soul_sand)
B(-7,8,5,minecraft:soul_sand)
B(-7,9,5,minecraft:soul_sand)
B(-7,10,5,minecraft:soul_sand)
B(-7,11,5,minecraft:soul_sand)
B(-7,12,5,minecraft:soul_sand)
B(-7,13,5,minecraft:soul_sand)
B(-7,14,5,minecraft:soul_sand)
B(-7,15,5,minecraft:soul_sand)
B(-7,16,5,minecraft:soul_sand)
B(-7,17,5,minecraft:soul_sand)
B(-7,18,5,minecraft:soul_sand)
B(-7,19,5,minecraft:soul_sand)
B(-7,20,5,minecraft:soul_sand)
B(-7,21,5,minecraft:soul_sand)
B(-7,22,5,minecraft:soul_sand)
B(-7,23,5,minecraft:soul_sand)
B(-7,24,5,minecraft:soul_sand)
B(-7,25,5,minecraft:soul_sand)
B(-7,26,5,minecraft:soul_sand)
B(-7,27,5,minecraft:soul_sand)
B(-7,28,5,minecraft:soul_sand)
B(-7,29,5,minecraft:soul_sand)
B(-7,30,5,minecraft:soul_sand)
B(-7,31,5,minecraft:soul_sand)
B(-7,32,5,minecraft:soul_sand)
B(-7,33,5,minecraft:soul_sand)
B(-7,34,5,minecraft:soul_sand)
B(-7,35,5,minecraft:soul_sand)
B(-7,36,5,minecraft:soul_sand)
B(-7,37,5,minecraft:soul_sand)
B(-7,38,5,minecraft:soul_sand)
B(-7,39,5,minecraft:soul_sand)
B(-7,40,5,minecraft:soul_sand)
B(-7,41,5,minecraft:soul_sand)
B(-7,42,5,minecraft:soul_sand)
B(-7,43,5,minecraft:soul_sand)
B(-7,44,5,minecraft:soul_sand)
B(-7,45,5,minecraft:soul_sand)
B(-7,46,5,minecraft:soul_sand)
B(-7,47,5,minecraft:soul_sand)
B(-7,48,5,minecraft:soul_sand)
B(-7,49,5,minecraft:soul_sand)
B(-7,50,5,minecraft:soul_sand)
B(-7,51,5,minecraft:soul_sand)
B(-7,52,5,minecraft:soul_sand)
B(-7,53,5,minecraft:soul_sand)
B(-7,54,5,minecraft:soul_sand)
B(-7,55,5,minecraft:soul_sand)
B(-7,56,5,minecraft:soul_sand)
B(-7,57,5,minecraft:soul_sand)
B(-7,58,5,minecraft:soul_sand)
B(-7,0,6,minecraft:soul_sand)
B(-7,1,6,minecraft:soul_sand)
B(-7,2,6,minecraft:soul_sand)
B(-7,3,6,minecraft:soul_sand)
B(-7,4,6,minecraft:soul_sand)
B(-7,5,6,minecraft:soul_sand)
B(-7,6,6,minecraft:soul_sand)
B(-7,7,6,minecraft:soul_sand)
B(-7,8,6,minecraft:soul_sand)
B(-7,9,6,minecraft:soul_sand)
B(-7,10,6,minecraft:soul_sand)
B(-7,11,6,minecraft:soul_sand)
B(-7,12,6,minecraft:soul_sand)
B(-7,13,6,minecraft:soul_sand)
B(-7,14,6,minecraft:soul_sand)
B(-7,15,6,minecraft:soul_sand)
B(-7,16,6,minecraft:soul_sand)
B(-7,17,6,minecraft:soul_sand)
B(-7,18,6,minecraft:soul_sand)
B(-7,19,6,minecraft:soul_sand)
B(-7,20,6,minecraft:soul_sand)
B(-7,21,6,minecraft:soul_sand)
B(-7,22,6,minecraft:soul_sand)
B(-7,23,6,minecraft:soul_sand)
B(-7,24,6,minecraft:soul_sand)
B(-7,25,6,minecraft:soul_sand)
B(-7,26,6,minecraft:soul_sand)
B(-7,27,6,minecraft:soul_sand)
B(-7,28,6,minecraft:soul_sand)
B(-7,29,6,minecraft:soul_sand)
B(-7,30,6,minecraft:soul_sand)
B(-7,31,6,minecraft:soul_sand)
B(-7,32,6,minecraft:soul_sand)
B(-7,33,6,minecraft:soul_sand)
B(-7,34,6,minecraft:soul_sand)
B(-7,35,6,minecraft:soul_sand)
B(-7,36,6,minecraft:soul_sand)
B(-7,37,6,minecraft:soul_sand)
B(-7,38,6,minecraft:soul_sand)
B(-7,39,6,minecraft:soul_sand)
B(-7,40,6,minecraft:soul_sand)
B(-7,41,6,minecraft:soul_sand)
B(-7,42,6,minecraft:soul_sand)
B(-7,43,6,minecraft:soul_sand)
B(-7,44,6,minecraft:soul_sand)
B(-7,45,6,minecraft:soul_sand)
B(-7,46,6,minecraft:soul_sand)
B(-7,47,6,minecraft:soul_sand)
B(-7,48,6,minecraft:soul_sand)
B(-7,49,6,minecraft:soul_sand)
B(-7,50,6,minecraft:soul_sand)
B(-7,51,6,minecraft:soul_sand)
B(-7,52,6,minecraft:soul_sand)
B(-7,53,6,minecraft:soul_sand)
B(-7,54,6,minecraft:soul_sand)
B(-7,55,6,minecraft:soul_sand)
B(-7,56,6,minecraft:soul_sand)
B(-7,57,6,minecraft:soul_sand)
B(-7,0,7,minecraft:soul_sand)
B(-7,1,7,minecraft:soul_sand)
B(-7,2,7,minecraft:soul_sand)
B(-7,3,7,minecraft:soul_sand)
B(-7,4,7,minecraft:soul_sand)
B(-7,5,7,minecraft:soul_sand)
B(-7,6,7,minecraft:soul_sand)
B(-7,7,7,minecraft:soul_sand)
B(-7,8,7,minecraft:soul_sand)
B(-7,9,7,minecraft:soul_sand)
B(-7,10,7,minecraft:soul_sand)
B(-7,11,7,minecraft:soul_sand)
B(-7,12,7,minecraft:soul_sand)
B(-7,13,7,minecraft:soul_sand)
B(-7,14,7,minecraft:soul_sand)
B(-7,15,7,minecraft:soul_sand)
B(-7,16,7,minecraft:soul_sand)
B(-7,17,7,minecraft:soul_sand)
B(-7,18,7,minecraft:soul_sand)
B(-7,19,7,minecraft:soul_sand)
B(-7,20,7,minecraft:soul_sand)
B(-7,21,7,minecraft:soul_sand)
B(-7,22,7,minecraft:soul_sand)
B(-7,23,7,minecraft:soul_sand)
B(-7,24,7,minecraft:soul_sand)
B(-7,25,7,minecraft:soul_sand)
B(-7,26,7,minecraft:soul_sand)
B(-7,27,7,minecraft:soul_sand)
B(-7,28,7,minecraft:soul_sand)
B(-7,29,7,minecraft:soul_sand)
B(-7,30,7,minecraft:soul_sand)
B(-7,31,7,minecraft:soul_sand)
B(-7,32,7,minecraft:soul_sand)
B(-7,33,7,minecraft:soul_sand)
B(-7,34,7,minecraft:soul_sand)
B(-7,35,7,minecraft:soul_sand)
B(-7,36,7,minecraft:soul_sand)
B(-7,37,7,minecraft:soul_sand)
B(-7,38,7,minecraft:soul_sand)
B(-7,39,7,minecraft:soul_sand)
B(-7,40,7,minecraft:soul_sand)
B(-7,41,7,minecraft:soul_sand)
B(-7,42,7,minecraft:soul_sand)
B(-7,43,7,minecraft:soul_sand)
B(-7,44,7,minecraft:soul_sand)
B(-7,45,7,minecraft:soul_sand)
B(-7,46,7,minecraft:soul_sand)
B(-7,47,7,minecraft:soul_sand)
B(-7,48,7,minecraft:soul_sand)
B(-7,49,7,minecraft:soul_sand)
B(-7,50,7,minecraft:soul_sand)
B(-7,51,7,minecraft:soul_sand)
B(-7,52,7,minecraft:soul_sand)
B(-7,53,7,minecraft:soul_sand)
B(-7,54,7,minecraft:soul_sand)
B(-7,55,7,minecraft:soul_sand)
B(-7,56,7,minecraft:soul_sand)
B(-7,57,7,minecraft:soul_sand)
B(-7,0,8,minecraft:soul_sand)
B(-7,1,8,minecraft:soul_sand)
B(-7,2,8,minecraft:soul_sand)
B(-7,3,8,minecraft:soul_sand)
B(-7,4,8,minecraft:soul_sand)
B(-7,5,8,minecraft:soul_sand)
B(-7,6,8,minecraft:soul_sand)
B(-7,7,8,minecraft:soul_sand)
B(-7,8,8,minecraft:soul_sand)
B(-7,9,8,minecraft:soul_sand)
B(-7,10,8,minecraft:soul_sand)
B(-7,11,8,minecraft:soul_sand)
B(-7,12,8,minecraft:soul_sand)
B(-7,13,8,minecraft:soul_sand)
B(-7,14,8,minecraft:soul_sand)
B(-7,15,8,minecraft:soul_sand)
B(-7,16,8,minecraft:soul_sand)
B(-7,17,8,minecraft:soul_sand)
B(-7,18,8,minecraft:soul_sand)
B(-7,19,8,minecraft:soul_sand)
B(-7,20,8,minecraft:soul_sand)
B(-7,21,8,minecraft:soul_sand)
B(-7,22,8,minecraft:soul_sand)
B(-7,23,8,minecraft:soul_sand)
B(-7,24,8,minecraft:soul_sand)
B(-7,25,8,minecraft:soul_sand)
B(-7,26,8,minecraft:soul_sand)
B(-7,27,8,minecraft:soul_sand)
B(-7,28,8,minecraft:soul_sand)
B(-7,29,8,minecraft:soul_sand)
B(-7,30,8,minecraft:soul_sand)
B(-7,31,8,minecraft:soul_sand)
B(-7,32,8,minecraft:soul_sand)
B(-7,33,8,minecraft:soul_sand)
B(-7,34,8,minecraft:soul_sand)
B(-7,35,8,minecraft:soul_sand)
B(-7,36,8,minecraft:soul_sand)
B(-7,37,8,minecraft:soul_sand)
B(-7,38,8,minecraft:soul_sand)
B(-7,39,8,minecraft:soul_sand)
B(-7,40,8,minecraft:soul_sand)
B(-7,41,8,minecraft:soul_sand)
B(-7,42,8,minecraft:soul_sand)
B(-7,43,8,minecraft:soul_sand)
B(-7,44,8,minecraft:soul_sand)
B(-7,45,8,minecraft:soul_sand)
B(-7,46,8,minecraft:soul_sand)
B(-7,47,8,minecraft:soul_sand)
B(-7,48,8,minecraft:soul_sand)
B(-7,49,8,minecraft:soul_sand)
B(-7,50,8,minecraft:soul_sand)
B(-7,51,8,minecraft:soul_sand)
B(-7,52,8,minecraft:soul_sand)
B(-7,53,8,minecraft:soul_sand)
B(-7,54,8,minecraft:soul_sand)
B(-7,55,8,minecraft:soul_sand)
B(-7,56,8,minecraft:soul_sand)
B(-7,57,8,minecraft:soul_sand)
B(-6,0,-7,minecraft:soul_sand)
B(-6,1,-7,minecraft:soul_sand)
B(-6,2,-7,minecraft:soul_sand)
B(-6,3,-7,minecraft:soul_sand)
B(-6,4,-7,minecraft:soul_sand)
B(-6,5,-7,minecraft:soul_sand)
B(-6,6,-7,minecraft:soul_sand)
B(-6,7,-7,minecraft:soul_sand)
B(-6,8,-7,minecraft:soul_sand)
B(-6,9,-7,minecraft:soul_sand)
B(-6,10,-7,minecraft:soul_sand)
B(-6,11,-7,minecraft:soul_sand)
B(-6,12,-7,minecraft:soul_sand)
B(-6,13,-7,minecraft:soul_sand)
B(-6,14,-7,minecraft:soul_sand)
B(-6,15,-7,minecraft:soul_sand)
B(-6,16,-7,minecraft:soul_sand)
B(-6,17,-7,minecraft:soul_sand)
B(-6,18,-7,minecraft:soul_sand)
B(-6,19,-7,minecraft:soul_sand)
B(-6,20,-7,minecraft:soul_sand)
B(-6,21,-7,minecraft:soul_sand)
B(-6,22,-7,minecraft:soul_sand)
B(-6,23,-7,minecraft:soul_sand)
B(-6,24,-7,minecraft:soul_sand)
B(-6,25,-7,minecraft:soul_sand)
B(-6,26,-7,minecraft:soul_sand)
B(-6,27,-7,minecraft:soul_sand)
B(-6,28,-7,minecraft:soul_sand)
B(-6,29,-7,minecraft:soul_sand)
B(-6,30,-7,minecraft:soul_sand)
B(-6,31,-7,minecraft:soul_sand)
B(-6,32,-7,minecraft:soul_sand)
B(-6,33,-7,minecraft:soul_sand)
B(-6,34,-7,minecraft:soul_sand)
B(-6,35,-7,minecraft:soul_sand)
B(-6,36,-7,minecraft:soul_sand)
B(-6,37,-7,minecraft:soul_sand)
B(-6,38,-7,minecraft:soul_sand)
B(-6,39,-7,minecraft:soul_sand)
B(-6,40,-7,minecraft:soul_sand)
B(-6,41,-7,minecraft:soul_sand)
B(-6,42,-7,minecraft:soul_sand)
B(-6,43,-7,minecraft:soul_sand)
B(-6,44,-7,minecraft:soul_sand)
B(-6,45,-7,minecraft:soul_sand)
B(-6,46,-7,minecraft:soul_sand)
B(-6,47,-7,minecraft:soul_sand)
B(-6,48,-7,minecraft:soul_sand)
B(-6,49,-7,minecraft:soul_sand)
B(-6,50,-7,minecraft:soul_sand)
B(-6,51,-7,minecraft:soul_sand)
B(-6,52,-7,minecraft:soul_sand)
B(-6,53,-7,minecraft:soul_sand)
B(-6,54,-7,minecraft:soul_sand)
B(-6,55,-7,minecraft:soul_sand)
B(-6,56,-7,minecraft:soul_sand)
B(-6,57,-7,minecraft:soul_sand)
B(-6,58,-7,minecraft:soul_sand)
B(-6,59,-7,minecraft:soul_sand)
B(-6,60,-7,minecraft:soul_sand)
B(-6,61,-7,minecraft:soul_sand)
B(-6,62,-7,minecraft:soul_sand)
B(-6,63,-7,minecraft:soul_sand)
B(-6,64,-7,minecraft:soul_sand)
B(-6,65,-7,minecraft:soul_sand)
B(-6,66,-7,minecraft:soul_sand)
B(-6,67,-7,minecraft:soul_sand)
B(-6,68,-7,minecraft:soul_sand)
B(-6,69,-7,minecraft:soul_sand)
B(-6,70,-7,minecraft:soul_sand)
B(-6,71,-7,minecraft:soul_sand)
B(-6,72,-7,minecraft:soul_sand)
B(-6,73,-7,minecraft:soul_sand)
B(-6,74,-7,minecraft:soul_sand)
B(-6,0,-6,minecraft:soul_sand)
B(-6,1,-6,minecraft:soul_sand)
B(-6,2,-6,minecraft:soul_sand)
B(-6,3,-6,minecraft:soul_sand)
B(-6,4,-6,minecraft:soul_sand)
B(-6,5,-6,minecraft:soul_sand)
B(-6,6,-6,minecraft:soul_sand)
B(-6,7,-6,minecraft:soul_sand)
B(-6,8,-6,minecraft:soul_sand)
B(-6,9,-6,minecraft:soul_sand)
B(-6,10,-6,minecraft:soul_sand)
B(-6,11,-6,minecraft:soul_sand)
B(-6,12,-6,minecraft:soul_sand)
B(-6,13,-6,minecraft:soul_sand)
B(-6,14,-6,minecraft:soul_sand)
B(-6,15,-6,minecraft:soul_sand)
B(-6,16,-6,minecraft:soul_sand)
B(-6,17,-6,minecraft:soul_sand)
B(-6,18,-6,minecraft:soul_sand)
B(-6,19,-6,minecraft:soul_sand)
B(-6,20,-6,minecraft:soul_sand)
B(-6,21,-6,minecraft:soul_sand)
B(-6,22,-6,minecraft:soul_sand)
B(-6,23,-6,minecraft:soul_sand)
B(-6,24,-6,minecraft:soul_sand)
B(-6,25,-6,minecraft:soul_sand)
B(-6,26,-6,minecraft:soul_sand)
B(-6,27,-6,minecraft:soul_sand)
B(-6,28,-6,minecraft:soul_sand)
B(-6,29,-6,minecraft:soul_sand)
B(-6,30,-6,minecraft:soul_sand)
B(-6,31,-6,minecraft:soul_sand)
B(-6,32,-6,minecraft:soul_sand)
B(-6,33,-6,minecraft:soul_sand)
B(-6,34,-6,minecraft:soul_sand)
B(-6,35,-6,minecraft:soul_sand)
B(-6,36,-6,minecraft:soul_sand)
B(-6,37,-6,minecraft:soul_sand)
B(-6,38,-6,minecraft:soul_sand)
B(-6,39,-6,minecraft:soul_sand)
B(-6,40,-6,minecraft:soul_sand)
B(-6,41,-6,minecraft:soul_sand)
B(-6,42,-6,minecraft:soul_sand)
B(-6,43,-6,minecraft:soul_sand)
B(-6,44,-6,minecraft:soul_sand)
B(-6,45,-6,minecraft:soul_sand)
B(-6,46,-6,minecraft:soul_sand)
B(-6,47,-6,minecraft:soul_sand)
B(-6,48,-6,minecraft:soul_sand)
B(-6,49,-6,minecraft:soul_sand)
B(-6,50,-6,minecraft:soul_sand)
B(-6,51,-6,minecraft:soul_sand)
B(-6,52,-6,minecraft:soul_sand)
B(-6,53,-6,minecraft:soul_sand)
B(-6,54,-6,minecraft:soul_sand)
B(-6,55,-6,minecraft:soul_sand)
B(-6,56,-6,minecraft:soul_sand)
B(-6,57,-6,minecraft:soul_sand)
B(-6,58,-6,minecraft:soul_sand)
B(-6,59,-6,minecraft:soul_sand)
B(-6,60,-6,minecraft:soul_sand)
B(-6,61,-6,minecraft:soul_sand)
B(-6,62,-6,minecraft:soul_sand)
B(-6,63,-6,minecraft:soul_sand)
B(-6,64,-6,minecraft:soul_sand)
B(-6,65,-6,minecraft:soul_sand)
B(-6,66,-6,minecraft:soul_sand)
B(-6,67,-6,minecraft:soul_sand)
B(-6,0,-5,minecraft:soul_sand)
B(-6,1,-5,minecraft:soul_sand)
B(-6,2,-5,minecraft:soul_sand)
B(-6,3,-5,minecraft:soul_sand)
B(-6,4,-5,minecraft:soul_sand)
B(-6,5,-5,minecraft:soul_sand)
B(-6,6,-5,minecraft:soul_sand)
B(-6,7,-5,minecraft:soul_sand)
B(-6,8,-5,minecraft:soul_sand)
B(-6,9,-5,minecraft:soul_sand)
B(-6,10,-5,minecraft:soul_sand)
B(-6,11,-5,minecraft:soul_sand)
B(-6,12,-5,minecraft:soul_sand)
B(-6,13,-5,minecraft:soul_sand)
B(-6,14,-5,minecraft:soul_sand)
B(-6,15,-5,minecraft:soul_sand)
B(-6,16,-5,minecraft:soul_sand)
B(-6,17,-5,minecraft:soul_sand)
B(-6,18,-5,minecraft:soul_sand)
B(-6,19,-5,minecraft:soul_sand)
B(-6,20,-5,minecraft:soul_sand)
B(-6,21,-5,minecraft:soul_sand)
B(-6,22,-5,minecraft:soul_sand)
B(-6,23,-5,minecraft:soul_sand)
B(-6,24,-5,minecraft:soul_sand)
B(-6,25,-5,minecraft:soul_sand)
B(-6,26,-5,minecraft:soul_sand)
B(-6,27,-5,minecraft:soul_sand)
B(-6,28,-5,minecraft:soul_sand)
B(-6,29,-5,minecraft:soul_sand)
B(-6,30,-5,minecraft:soul_sand)
B(-6,31,-5,minecraft:soul_sand)
B(-6,32,-5,minecraft:soul_sand)
B(-6,33,-5,minecraft:soul_sand)
B(-6,34,-5,minecraft:soul_sand)
B(-6,35,-5,minecraft:soul_sand)
B(-6,36,-5,minecraft:soul_sand)
B(-6,37,-5,minecraft:soul_sand)
B(-6,38,-5,minecraft:soul_sand)
B(-6,39,-5,minecraft:soul_sand)
B(-6,40,-5,minecraft:soul_sand)
B(-6,41,-5,minecraft:soul_sand)
B(-6,42,-5,minecraft:soul_sand)
B(-6,43,-5,minecraft:soul_sand)
B(-6,44,-5,minecraft:soul_sand)
B(-6,45,-5,minecraft:soul_sand)
B(-6,46,-5,minecraft:soul_sand)
B(-6,47,-5,minecraft:soul_sand)
B(-6,48,-5,minecraft:soul_sand)
B(-6,49,-5,minecraft:soul_sand)
B(-6,50,-5,minecraft:soul_sand)
B(-6,51,-5,minecraft:soul_sand)
B(-6,52,-5,minecraft:soul_sand)
B(-6,53,-5,minecraft:soul_sand)
B(-6,54,-5,minecraft:soul_sand)
B(-6,55,-5,minecraft:soul_sand)
B(-6,56,-5,minecraft:soul_sand)
B(-6,57,-5,minecraft:soul_sand)
B(-6,58,-5,minecraft:soul_sand)
B(-6,59,-5,minecraft:soul_sand)
B(-6,60,-5,minecraft:soul_sand)
B(-6,61,-5,minecraft:soul_sand)
B(-6,62,-5,minecraft:soul_sand)
B(-6,63,-5,minecraft:soul_sand)
B(-6,64,-5,minecraft:soul_sand)
B(-6,65,-5,minecraft:soul_sand)
B(-6,66,-5,minecraft:soul_sand)
B(-6,67,-5,minecraft:soul_sand)
B(-6,0,-4,minecraft:soul_sand)
B(-6,1,-4,minecraft:soul_sand)
B(-6,2,-4,minecraft:soul_sand)
B(-6,3,-4,minecraft:soul_sand)
B(-6,4,-4,minecraft:soul_sand)
B(-6,5,-4,minecraft:soul_sand)
B(-6,6,-4,minecraft:soul_sand)
B(-6,7,-4,minecraft:soul_sand)
B(-6,8,-4,minecraft:soul_sand)
B(-6,9,-4,minecraft:soul_sand)
B(-6,10,-4,minecraft:soul_sand)
B(-6,11,-4,minecraft:soul_sand)
B(-6,12,-4,minecraft:soul_sand)
B(-6,13,-4,minecraft:soul_sand)
B(-6,14,-4,minecraft:soul_sand)
B(-6,15,-4,minecraft:soul_sand)
B(-6,16,-4,minecraft:soul_sand)
B(-6,17,-4,minecraft:soul_sand)
B(-6,18,-4,minecraft:soul_sand)
B(-6,19,-4,minecraft:soul_sand)
B(-6,20,-4,minecraft:soul_sand)
B(-6,21,-4,minecraft:soul_sand)
B(-6,22,-4,minecraft:soul_sand)
B(-6,23,-4,minecraft:soul_sand)
B(-6,24,-4,minecraft:soul_sand)
B(-6,25,-4,minecraft:soul_sand)
B(-6,26,-4,minecraft:soul_sand)
B(-6,27,-4,minecraft:soul_sand)
B(-6,28,-4,minecraft:soul_sand)
B(-6,29,-4,minecraft:soul_sand)
B(-6,30,-4,minecraft:soul_sand)
B(-6,31,-4,minecraft:soul_sand)
B(-6,32,-4,minecraft:soul_sand)
B(-6,33,-4,minecraft:soul_sand)
B(-6,34,-4,minecraft:soul_sand)
B(-6,35,-4,minecraft:soul_sand)
B(-6,36,-4,minecraft:soul_sand)
B(-6,37,-4,minecraft:soul_sand)
B(-6,38,-4,minecraft:soul_sand)
B(-6,39,-4,minecraft:soul_sand)
B(-6,40,-4,minecraft:soul_sand)
B(-6,41,-4,minecraft:soul_sand)
B(-6,42,-4,minecraft:soul_sand)
B(-6,43,-4,minecraft:soul_sand)
B(-6,44,-4,minecraft:soul_sand)
B(-6,45,-4,minecraft:soul_sand)
B(-6,46,-4,minecraft:soul_sand)
B(-6,47,-4,minecraft:soul_sand)
B(-6,48,-4,minecraft:soul_sand)
B(-6,49,-4,minecraft:soul_sand)
B(-6,50,-4,minecraft:soul_sand)
B(-6,51,-4,minecraft:soul_sand)
B(-6,52,-4,minecraft:soul_sand)
B(-6,53,-4,minecraft:soul_sand)
B(-6,54,-4,minecraft:soul_sand)
B(-6,55,-4,minecraft:soul_sand)
B(-6,56,-4,minecraft:soul_sand)
B(-6,57,-4,minecraft:soul_sand)
B(-6,58,-4,minecraft:soul_sand)
B(-6,59,-4,minecraft:soul_sand)
B(-6,60,-4,minecraft:soul_sand)
B(-6,61,-4,minecraft:soul_sand)
B(-6,62,-4,minecraft:soul_sand)
B(-6,63,-4,minecraft:soul_sand)
B(-6,64,-4,minecraft:soul_sand)
B(-6,65,-4,minecraft:soul_sand)
B(-6,66,-4,minecraft:soul_sand)
B(-6,67,-4,minecraft:soul_sand)
B(-6,0,-3,minecraft:soul_sand)
B(-6,1,-3,minecraft:soul_sand)
B(-6,2,-3,minecraft:soul_sand)
B(-6,3,-3,minecraft:soul_sand)
B(-6,4,-3,minecraft:soul_sand)
B(-6,5,-3,minecraft:soul_sand)
B(-6,6,-3,minecraft:soul_sand)
B(-6,7,-3,minecraft:soul_sand)
B(-6,8,-3,minecraft:soul_sand)
B(-6,9,-3,minecraft:soul_sand)
B(-6,10,-3,minecraft:soul_sand)
B(-6,11,-3,minecraft:soul_sand)
B(-6,12,-3,minecraft:soul_sand)
B(-6,13,-3,minecraft:soul_sand)
B(-6,14,-3,minecraft:soul_sand)
B(-6,15,-3,minecraft:soul_sand)
B(-6,16,-3,minecraft:soul_sand)
B(-6,17,-3,minecraft:soul_sand)
B(-6,18,-3,minecraft:soul_sand)
B(-6,19,-3,minecraft:soul_sand)
B(-6,20,-3,minecraft:soul_sand)
B(-6,21,-3,minecraft:soul_sand)
B(-6,22,-3,minecraft:soul_sand)
B(-6,23,-3,minecraft:soul_sand)
B(-6,24,-3,minecraft:soul_sand)
B(-6,25,-3,minecraft:soul_sand)
B(-6,26,-3,minecraft:soul_sand)
B(-6,27,-3,minecraft:soul_sand)
B(-6,28,-3,minecraft:soul_sand)
B(-6,29,-3,minecraft:soul_sand)
B(-6,30,-3,minecraft:soul_sand)
B(-6,31,-3,minecraft:soul_sand)
B(-6,32,-3,minecraft:soul_sand)
B(-6,33,-3,minecraft:soul_sand)
B(-6,34,-3,minecraft:soul_sand)
B(-6,35,-3,minecraft:soul_sand)
B(-6,36,-3,minecraft:soul_sand)
B(-6,37,-3,minecraft:soul_sand)
B(-6,38,-3,minecraft:soul_sand)
B(-6,39,-3,minecraft:soul_sand)
B(-6,40,-3,minecraft:soul_sand)
B(-6,41,-3,minecraft:soul_sand)
B(-6,42,-3,minecraft:soul_sand)
B(-6,43,-3,minecraft:soul_sand)
B(-6,44,-3,minecraft:soul_sand)
B(-6,45,-3,minecraft:soul_sand)
B(-6,46,-3,minecraft:soul_sand)
B(-6,47,-3,minecraft:soul_sand)
B(-6,48,-3,minecraft:soul_sand)
B(-6,49,-3,minecraft:soul_sand)
B(-6,50,-3,minecraft:soul_sand)
B(-6,51,-3,minecraft:soul_sand)
B(-6,52,-3,minecraft:soul_sand)
B(-6,53,-3,minecraft:soul_sand)
B(-6,54,-3,minecraft:soul_sand)
B(-6,55,-3,minecraft:soul_sand)
B(-6,56,-3,minecraft:soul_sand)
B(-6,57,-3,minecraft:soul_sand)
B(-6,58,-3,minecraft:soul_sand)
B(-6,59,-3,minecraft:soul_sand)
B(-6,60,-3,minecraft:soul_sand)
B(-6,61,-3,minecraft:soul_sand)
B(-6,62,-3,minecraft:soul_sand)
B(-6,63,-3,minecraft:soul_sand)
B(-6,64,-3,minecraft:soul_sand)
B(-6,65,-3,minecraft:soul_sand)
B(-6,66,-3,minecraft:soul_sand)
B(-6,67,-3,minecraft:soul_sand)
B(-6,0,-2,minecraft:soul_sand)
B(-6,1,-2,minecraft:soul_sand)
B(-6,2,-2,minecraft:soul_sand)
B(-6,3,-2,minecraft:soul_sand)
B(-6,4,-2,minecraft:soul_sand)
B(-6,5,-2,minecraft:soul_sand)
B(-6,6,-2,minecraft:soul_sand)
B(-6,7,-2,minecraft:soul_sand)
B(-6,8,-2,minecraft:soul_sand)
B(-6,9,-2,minecraft:soul_sand)
B(-6,10,-2,minecraft:soul_sand)
B(-6,11,-2,minecraft:soul_sand)
B(-6,12,-2,minecraft:soul_sand)
B(-6,13,-2,minecraft:soul_sand)
B(-6,14,-2,minecraft:soul_sand)
B(-6,15,-2,minecraft:soul_sand)
B(-6,16,-2,minecraft:soul_sand)
B(-6,17,-2,minecraft:soul_sand)
B(-6,18,-2,minecraft:soul_sand)
B(-6,19,-2,minecraft:soul_sand)
B(-6,20,-2,minecraft:soul_sand)
B(-6,21,-2,minecraft:soul_sand)
B(-6,22,-2,minecraft:soul_sand)
B(-6,23,-2,minecraft:soul_sand)
B(-6,24,-2,minecraft:soul_sand)
B(-6,25,-2,minecraft:soul_sand)
B(-6,26,-2,minecraft:soul_sand)
B(-6,27,-2,minecraft:soul_sand)
B(-6,28,-2,minecraft:soul_sand)
B(-6,29,-2,minecraft:soul_sand)
B(-6,30,-2,minecraft:soul_sand)
B(-6,31,-2,minecraft:soul_sand)
B(-6,32,-2,minecraft:soul_sand)
B(-6,33,-2,minecraft:soul_sand)
B(-6,34,-2,minecraft:soul_sand)
B(-6,35,-2,minecraft:soul_sand)
B(-6,36,-2,minecraft:soul_sand)
B(-6,37,-2,minecraft:soul_sand)
B(-6,38,-2,minecraft:soul_sand)
B(-6,39,-2,minecraft:soul_sand)
B(-6,40,-2,minecraft:soul_sand)
B(-6,41,-2,minecraft:soul_sand)
B(-6,42,-2,minecraft:soul_sand)
B(-6,43,-2,minecraft:soul_sand)
B(-6,44,-2,minecraft:soul_sand)
B(-6,45,-2,minecraft:soul_sand)
B(-6,46,-2,minecraft:soul_sand)
B(-6,47,-2,minecraft:soul_sand)
B(-6,48,-2,minecraft:soul_sand)
B(-6,49,-2,minecraft:soul_sand)
B(-6,50,-2,minecraft:soul_sand)
B(-6,51,-2,minecraft:soul_sand)
B(-6,52,-2,minecraft:soul_sand)
B(-6,53,-2,minecraft:soul_sand)
B(-6,54,-2,minecraft:soul_sand)
B(-6,55,-2,minecraft:soul_sand)
B(-6,56,-2,minecraft:soul_sand)
B(-6,57,-2,minecraft:soul_sand)
B(-6,58,-2,minecraft:soul_sand)
B(-6,59,-2,minecraft:soul_sand)
B(-6,60,-2,minecraft:soul_sand)
B(-6,61,-2,minecraft:soul_sand)
B(-6,62,-2,minecraft:soul_sand)
B(-6,63,-2,minecraft:soul_sand)
B(-6,64,-2,minecraft:soul_sand)
B(-6,65,-2,minecraft:soul_sand)
B(-6,66,-2,minecraft:soul_sand)
B(-6,67,-2,minecraft:soul_sand)
B(-6,0,-1,minecraft:soul_sand)
B(-6,1,-1,minecraft:soul_sand)
B(-6,2,-1,minecraft:soul_sand)
B(-6,3,-1,minecraft:soul_sand)
B(-6,4,-1,minecraft:soul_sand)
B(-6,5,-1,minecraft:soul_sand)
B(-6,6,-1,minecraft:soul_sand)
B(-6,7,-1,minecraft:soul_sand)
B(-6,8,-1,minecraft:soul_sand)
B(-6,9,-1,minecraft:soul_sand)
B(-6,10,-1,minecraft:soul_sand)
B(-6,11,-1,minecraft:soul_sand)
B(-6,12,-1,minecraft:soul_sand)
B(-6,13,-1,minecraft:soul_sand)
B(-6,14,-1,minecraft:soul_sand)
B(-6,15,-1,minecraft:soul_sand)
B(-6,16,-1,minecraft:soul_sand)
B(-6,17,-1,minecraft:soul_sand)
B(-6,18,-1,minecraft:soul_sand)
B(-6,19,-1,minecraft:soul_sand)
B(-6,20,-1,minecraft:soul_sand)
B(-6,21,-1,minecraft:soul_sand)
B(-6,22,-1,minecraft:soul_sand)
B(-6,23,-1,minecraft:soul_sand)
B(-6,24,-1,minecraft:soul_sand)
B(-6,25,-1,minecraft:soul_sand)
B(-6,26,-1,minecraft:soul_sand)
B(-6,27,-1,minecraft:soul_sand)
B(-6,28,-1,minecraft:soul_sand)
B(-6,29,-1,minecraft:soul_sand)
B(-6,30,-1,minecraft:soul_sand)
B(-6,31,-1,minecraft:soul_sand)
B(-6,32,-1,minecraft:soul_sand)
B(-6,33,-1,minecraft:soul_sand)
B(-6,34,-1,minecraft:soul_sand)
B(-6,35,-1,minecraft:soul_sand)
B(-6,36,-1,minecraft:soul_sand)
B(-6,37,-1,minecraft:soul_sand)
B(-6,38,-1,minecraft:soul_sand)
B(-6,39,-1,minecraft:soul_sand)
B(-6,40,-1,minecraft:soul_sand)
B(-6,41,-1,minecraft:soul_sand)
B(-6,42,-1,minecraft:soul_sand)
B(-6,43,-1,minecraft:soul_sand)
B(-6,44,-1,minecraft:soul_sand)
B(-6,45,-1,minecraft:soul_sand)
B(-6,46,-1,minecraft:soul_sand)
B(-6,47,-1,minecraft:soul_sand)
B(-6,48,-1,minecraft:soul_sand)
B(-6,49,-1,minecraft:soul_sand)
B(-6,50,-1,minecraft:soul_sand)
B(-6,51,-1,minecraft:soul_sand)
B(-6,52,-1,minecraft:soul_sand)
B(-6,53,-1,minecraft:soul_sand)
B(-6,54,-1,minecraft:soul_sand)
B(-6,55,-1,minecraft:soul_sand)
B(-6,56,-1,minecraft:soul_sand)
B(-6,57,-1,minecraft:soul_sand)
B(-6,58,-1,minecraft:soul_sand)
B(-6,59,-1,minecraft:soul_sand)
B(-6,60,-1,minecraft:soul_sand)
B(-6,61,-1,minecraft:soul_sand)
B(-6,62,-1,minecraft:soul_sand)
B(-6,63,-1,minecraft:soul_sand)
B(-6,64,-1,minecraft:soul_sand)
B(-6,65,-1,minecraft:soul_sand)
B(-6,66,-1,minecraft:soul_sand)
B(-6,0,0,minecraft:soul_sand)
B(-6,1,0,minecraft:soul_sand)
B(-6,2,0,minecraft:soul_sand)
B(-6,3,0,minecraft:soul_sand)
B(-6,4,0,minecraft:soul_sand)
B(-6,5,0,minecraft:soul_sand)
B(-6,6,0,minecraft:soul_sand)
B(-6,7,0,minecraft:soul_sand)
B(-6,8,0,minecraft:soul_sand)
B(-6,9,0,minecraft:soul_sand)
B(-6,10,0,minecraft:soul_sand)
B(-6,11,0,minecraft:soul_sand)
B(-6,12,0,minecraft:soul_sand)
B(-6,13,0,minecraft:soul_sand)
B(-6,14,0,minecraft:soul_sand)
B(-6,15,0,minecraft:soul_sand)
B(-6,16,0,minecraft:soul_sand)
B(-6,17,0,minecraft:soul_sand)
B(-6,18,0,minecraft:soul_sand)
B(-6,19,0,minecraft:soul_sand)
B(-6,20,0,minecraft:soul_sand)
B(-6,21,0,minecraft:soul_sand)
B(-6,22,0,minecraft:soul_sand)
B(-6,23,0,minecraft:soul_sand)
B(-6,24,0,minecraft:soul_sand)
B(-6,25,0,minecraft:soul_sand)
B(-6,26,0,minecraft:soul_sand)
B(-6,27,0,minecraft:soul_sand)
B(-6,28,0,minecraft:soul_sand)
B(-6,29,0,minecraft:soul_sand)
B(-6,30,0,minecraft:soul_sand)
B(-6,31,0,minecraft:soul_sand)
B(-6,32,0,minecraft:soul_sand)
B(-6,33,0,minecraft:soul_sand)
B(-6,34,0,minecraft:soul_sand)
B(-6,35,0,minecraft:soul_sand)
B(-6,36,0,minecraft:soul_sand)
B(-6,37,0,minecraft:soul_sand)
B(-6,38,0,minecraft:soul_sand)
B(-6,39,0,minecraft:soul_sand)
B(-6,40,0,minecraft:soul_sand)
B(-6,41,0,minecraft:soul_sand)
B(-6,42,0,minecraft:soul_sand)
B(-6,43,0,minecraft:soul_sand)
B(-6,44,0,minecraft:soul_sand)
B(-6,45,0,minecraft:soul_sand)
B(-6,46,0,minecraft:soul_sand)
B(-6,47,0,minecraft:soul_sand)
B(-6,48,0,minecraft:soul_sand)
B(-6,49,0,minecraft:soul_sand)
B(-6,50,0,minecraft:soul_sand)
B(-6,51,0,minecraft:soul_sand)
B(-6,52,0,minecraft:soul_sand)
B(-6,53,0,minecraft:soul_sand)
B(-6,54,0,minecraft:soul_sand)
B(-6,55,0,minecraft:soul_sand)
B(-6,56,0,minecraft:soul_sand)
B(-6,57,0,minecraft:soul_sand)
B(-6,58,0,minecraft:soul_sand)
B(-6,59,0,minecraft:soul_sand)
B(-6,60,0,minecraft:soul_sand)
B(-6,61,0,minecraft:soul_sand)
B(-6,62,0,minecraft:soul_sand)
B(-6,63,0,minecraft:soul_sand)
B(-6,64,0,minecraft:soul_sand)
B(-6,65,0,minecraft:soul_sand)
B(-6,0,1,minecraft:soul_sand)
B(-6,1,1,minecraft:soul_sand)
B(-6,2,1,minecraft:soul_sand)
B(-6,3,1,minecraft:soul_sand)
B(-6,4,1,minecraft:soul_sand)
B(-6,5,1,minecraft:soul_sand)
B(-6,6,1,minecraft:soul_sand)
B(-6,7,1,minecraft:soul_sand)
B(-6,8,1,minecraft:soul_sand)
B(-6,9,1,minecraft:soul_sand)
B(-6,10,1,minecraft:soul_sand)
B(-6,11,1,minecraft:soul_sand)
B(-6,12,1,minecraft:soul_sand)
B(-6,13,1,minecraft:soul_sand)
B(-6,14,1,minecraft:soul_sand)
B(-6,15,1,minecraft:soul_sand)
B(-6,16,1,minecraft:soul_sand)
B(-6,17,1,minecraft:soul_sand)
B(-6,18,1,minecraft:soul_sand)
B(-6,19,1,minecraft:soul_sand)
B(-6,20,1,minecraft:soul_sand)
B(-6,21,1,minecraft:soul_sand)
B(-6,22,1,minecraft:soul_sand)
B(-6,23,1,minecraft:soul_sand)
B(-6,24,1,minecraft:soul_sand)
B(-6,25,1,minecraft:soul_sand)
B(-6,26,1,minecraft:soul_sand)
B(-6,27,1,minecraft:soul_sand)
B(-6,28,1,minecraft:soul_sand)
B(-6,29,1,minecraft:soul_sand)
B(-6,30,1,minecraft:soul_sand)
B(-6,31,1,minecraft:soul_sand)
B(-6,32,1,minecraft:soul_sand)
B(-6,33,1,minecraft:soul_sand)
B(-6,34,1,minecraft:soul_sand)
B(-6,35,1,minecraft:soul_sand)
B(-6,36,1,minecraft:soul_sand)
B(-6,37,1,minecraft:soul_sand)
B(-6,38,1,minecraft:soul_sand)
B(-6,39,1,minecraft:soul_sand)
B(-6,40,1,minecraft:soul_sand)
B(-6,41,1,minecraft:soul_sand)
B(-6,42,1,minecraft:soul_sand)
B(-6,43,1,minecraft:soul_sand)
B(-6,44,1,minecraft:soul_sand)
B(-6,45,1,minecraft:soul_sand)
B(-6,46,1,minecraft:soul_sand)
B(-6,47,1,minecraft:soul_sand)
B(-6,48,1,minecraft:soul_sand)
B(-6,49,1,minecraft:soul_sand)
B(-6,50,1,minecraft:soul_sand)
B(-6,51,1,minecraft:soul_sand)
B(-6,52,1,minecraft:soul_sand)
B(-6,53,1,minecraft:soul_sand)
B(-6,54,1,minecraft:soul_sand)
B(-6,55,1,minecraft:soul_sand)
B(-6,56,1,minecraft:soul_sand)
B(-6,57,1,minecraft:soul_sand)
B(-6,58,1,minecraft:soul_sand)
B(-6,59,1,minecraft:soul_sand)
B(-6,60,1,minecraft:soul_sand)
B(-6,61,1,minecraft:soul_sand)
B(-6,62,1,minecraft:soul_sand)
B(-6,63,1,minecraft:soul_sand)
B(-6,64,1,minecraft:soul_sand)
B(-6,0,2,minecraft:soul_sand)
B(-6,1,2,minecraft:soul_sand)
B(-6,2,2,minecraft:soul_sand)
B(-6,3,2,minecraft:soul_sand)
B(-6,4,2,minecraft:soul_sand)
B(-6,5,2,minecraft:soul_sand)
B(-6,6,2,minecraft:soul_sand)
B(-6,7,2,minecraft:soul_sand)
B(-6,8,2,minecraft:soul_sand)
B(-6,9,2,minecraft:soul_sand)
B(-6,10,2,minecraft:soul_sand)
B(-6,11,2,minecraft:soul_sand)
B(-6,12,2,minecraft:soul_sand)
B(-6,13,2,minecraft:soul_sand)
B(-6,14,2,minecraft:soul_sand)
B(-6,15,2,minecraft:soul_sand)
B(-6,16,2,minecraft:soul_sand)
B(-6,17,2,minecraft:soul_sand)
B(-6,18,2,minecraft:soul_sand)
B(-6,19,2,minecraft:soul_sand)
B(-6,20,2,minecraft:soul_sand)
B(-6,21,2,minecraft:soul_sand)
B(-6,22,2,minecraft:soul_sand)
B(-6,23,2,minecraft:soul_sand)
B(-6,24,2,minecraft:soul_sand)
B(-6,25,2,minecraft:soul_sand)
B(-6,26,2,minecraft:soul_sand)
B(-6,27,2,minecraft:soul_sand)
B(-6,28,2,minecraft:soul_sand)
B(-6,29,2,minecraft:soul_sand)
B(-6,30,2,minecraft:soul_sand)
B(-6,31,2,minecraft:soul_sand)
B(-6,32,2,minecraft:soul_sand)
B(-6,33,2,minecraft:soul_sand)
B(-6,34,2,minecraft:soul_sand)
B(-6,35,2,minecraft:soul_sand)
B(-6,36,2,minecraft:soul_sand)
B(-6,37,2,minecraft:soul_sand)
B(-6,38,2,minecraft:soul_sand)
B(-6,39,2,minecraft:soul_sand)
B(-6,40,2,minecraft:soul_sand)
B(-6,41,2,minecraft:soul_sand)
B(-6,42,2,minecraft:soul_sand)
B(-6,43,2,minecraft:soul_sand)
B(-6,44,2,minecraft:soul_sand)
B(-6,45,2,minecraft:soul_sand)
B(-6,46,2,minecraft:soul_sand)
B(-6,47,2,minecraft:soul_sand)
B(-6,48,2,minecraft:soul_sand)
B(-6,49,2,minecraft:soul_sand)
B(-6,50,2,minecraft:soul_sand)
B(-6,51,2,minecraft:soul_sand)
B(-6,52,2,minecraft:soul_sand)
B(-6,53,2,minecraft:soul_sand)
B(-6,54,2,minecraft:soul_sand)
B(-6,55,2,minecraft:soul_sand)
B(-6,56,2,minecraft:soul_sand)
B(-6,57,2,minecraft:soul_sand)
B(-6,58,2,minecraft:soul_sand)
B(-6,59,2,minecraft:soul_sand)
B(-6,60,2,minecraft:soul_sand)
B(-6,61,2,minecraft:soul_sand)
B(-6,62,2,minecraft:soul_sand)
B(-6,0,3,minecraft:soul_sand)
B(-6,1,3,minecraft:soul_sand)
B(-6,2,3,minecraft:soul_sand)
B(-6,3,3,minecraft:soul_sand)
B(-6,4,3,minecraft:soul_sand)
B(-6,5,3,minecraft:soul_sand)
B(-6,6,3,minecraft:soul_sand)
B(-6,7,3,minecraft:soul_sand)
B(-6,8,3,minecraft:soul_sand)
B(-6,9,3,minecraft:soul_sand)
B(-6,10,3,minecraft:soul_sand)
B(-6,11,3,minecraft:soul_sand)
B(-6,12,3,minecraft:soul_sand)
B(-6,13,3,minecraft:soul_sand)
B(-6,14,3,minecraft:soul_sand)
B(-6,15,3,minecraft:soul_sand)
B(-6,16,3,minecraft:soul_sand)
B(-6,17,3,minecraft:soul_sand)
B(-6,18,3,minecraft:soul_sand)
B(-6,19,3,minecraft:soul_sand)
B(-6,20,3,minecraft:soul_sand)
B(-6,21,3,minecraft:soul_sand)
B(-6,22,3,minecraft:soul_sand)
B(-6,23,3,minecraft:soul_sand)
B(-6,24,3,minecraft:soul_sand)
B(-6,25,3,minecraft:soul_sand)
B(-6,26,3,minecraft:soul_sand)
B(-6,27,3,minecraft:soul_sand)
B(-6,28,3,minecraft:soul_sand)
B(-6,29,3,minecraft:soul_sand)
B(-6,30,3,minecraft:soul_sand)
B(-6,31,3,minecraft:soul_sand)
B(-6,32,3,minecraft:soul_sand)
B(-6,33,3,minecraft:soul_sand)
B(-6,34,3,minecraft:soul_sand)
B(-6,35,3,minecraft:soul_sand)
B(-6,36,3,minecraft:soul_sand)
B(-6,37,3,minecraft:soul_sand)
B(-6,38,3,minecraft:soul_sand)
B(-6,39,3,minecraft:soul_sand)
B(-6,40,3,minecraft:soul_sand)
B(-6,41,3,minecraft:soul_sand)
B(-6,42,3,minecraft:soul_sand)
B(-6,43,3,minecraft:soul_sand)
B(-6,44,3,minecraft:soul_sand)
B(-6,45,3,minecraft:soul_sand)
B(-6,46,3,minecraft:soul_sand)
B(-6,47,3,minecraft:soul_sand)
B(-6,48,3,minecraft:soul_sand)
B(-6,49,3,minecraft:soul_sand)
B(-6,50,3,minecraft:soul_sand)
B(-6,51,3,minecraft:soul_sand)
B(-6,52,3,minecraft:soul_sand)
B(-6,53,3,minecraft:soul_sand)
B(-6,54,3,minecraft:soul_sand)
B(-6,55,3,minecraft:soul_sand)
B(-6,56,3,minecraft:soul_sand)
B(-6,57,3,minecraft:soul_sand)
B(-6,58,3,minecraft:soul_sand)
B(-6,59,3,minecraft:soul_sand)
B(-6,60,3,minecraft:soul_sand)
B(-6,61,3,minecraft:soul_sand)
B(-6,0,4,minecraft:soul_sand)
B(-6,1,4,minecraft:soul_sand)
B(-6,2,4,minecraft:soul_sand)
B(-6,3,4,minecraft:soul_sand)
B(-6,4,4,minecraft:soul_sand)
B(-6,5,4,minecraft:soul_sand)
B(-6,6,4,minecraft:soul_sand)
B(-6,7,4,minecraft:soul_sand)
B(-6,8,4,minecraft:soul_sand)
B(-6,9,4,minecraft:soul_sand)
B(-6,10,4,minecraft:soul_sand)
B(-6,11,4,minecraft:soul_sand)
B(-6,12,4,minecraft:soul_sand)
B(-6,13,4,minecraft:soul_sand)
B(-6,14,4,minecraft:soul_sand)
B(-6,15,4,minecraft:soul_sand)
B(-6,16,4,minecraft:soul_sand)
B(-6,17,4,minecraft:soul_sand)
B(-6,18,4,minecraft:soul_sand)
B(-6,19,4,minecraft:soul_sand)
B(-6,20,4,minecraft:soul_sand)
B(-6,21,4,minecraft:soul_sand)
B(-6,22,4,minecraft:soul_sand)
B(-6,23,4,minecraft:soul_sand)
B(-6,24,4,minecraft:soul_sand)
B(-6,25,4,minecraft:soul_sand)
B(-6,26,4,minecraft:soul_sand)
B(-6,27,4,minecraft:soul_sand)
B(-6,28,4,minecraft:soul_sand)
B(-6,29,4,minecraft:soul_sand)
B(-6,30,4,minecraft:soul_sand)
B(-6,31,4,minecraft:soul_sand)
B(-6,32,4,minecraft:soul_sand)
B(-6,33,4,minecraft:soul_sand)
B(-6,34,4,minecraft:soul_sand)
B(-6,35,4,minecraft:soul_sand)
B(-6,36,4,minecraft:soul_sand)
B(-6,37,4,minecraft:soul_sand)
B(-6,38,4,minecraft:soul_sand)
B(-6,39,4,minecraft:soul_sand)
B(-6,40,4,minecraft:soul_sand)
B(-6,41,4,minecraft:soul_sand)
B(-6,42,4,minecraft:soul_sand)
B(-6,43,4,minecraft:soul_sand)
B(-6,44,4,minecraft:soul_sand)
B(-6,45,4,minecraft:soul_sand)
B(-6,46,4,minecraft:soul_sand)
B(-6,47,4,minecraft:soul_sand)
B(-6,48,4,minecraft:soul_sand)
B(-6,49,4,minecraft:soul_sand)
B(-6,50,4,minecraft:soul_sand)
B(-6,51,4,minecraft:soul_sand)
B(-6,52,4,minecraft:soul_sand)
B(-6,53,4,minecraft:soul_sand)
B(-6,54,4,minecraft:soul_sand)
B(-6,55,4,minecraft:soul_sand)
B(-6,56,4,minecraft:soul_sand)
B(-6,57,4,minecraft:soul_sand)
B(-6,58,4,minecraft:soul_sand)
B(-6,59,4,minecraft:soul_sand)
B(-6,60,4,minecraft:soul_sand)
B(-6,0,5,minecraft:soul_sand)
B(-6,1,5,minecraft:soul_sand)
B(-6,2,5,minecraft:soul_sand)
B(-6,3,5,minecraft:soul_sand)
B(-6,4,5,minecraft:soul_sand)
B(-6,5,5,minecraft:soul_sand)
B(-6,6,5,minecraft:soul_sand)
B(-6,7,5,minecraft:soul_sand)
B(-6,8,5,minecraft:soul_sand)
B(-6,9,5,minecraft:soul_sand)
B(-6,10,5,minecraft:soul_sand)
B(-6,11,5,minecraft:soul_sand)
B(-6,12,5,minecraft:soul_sand)
B(-6,13,5,minecraft:soul_sand)
B(-6,14,5,minecraft:soul_sand)
B(-6,15,5,minecraft:soul_sand)
B(-6,16,5,minecraft:soul_sand)
B(-6,17,5,minecraft:soul_sand)
B(-6,18,5,minecraft:soul_sand)
B(-6,19,5,minecraft:soul_sand)
B(-6,20,5,minecraft:soul_sand)
B(-6,21,5,minecraft:soul_sand)
B(-6,22,5,minecraft:soul_sand)
B(-6,23,5,minecraft:soul_sand)
B(-6,24,5,minecraft:soul_sand)
B(-6,25,5,minecraft:soul_sand)
B(-6,26,5,minecraft:soul_sand)
B(-6,27,5,minecraft:soul_sand)
B(-6,28,5,minecraft:soul_sand)
B(-6,29,5,minecraft:soul_sand)
B(-6,30,5,minecraft:soul_sand)
B(-6,31,5,minecraft:soul_sand)
B(-6,32,5,minecraft:soul_sand)
B(-6,33,5,minecraft:soul_sand)
B(-6,34,5,minecraft:soul_sand)
B(-6,35,5,minecraft:soul_sand)
B(-6,36,5,minecraft:soul_sand)
B(-6,37,5,minecraft:soul_sand)
B(-6,38,5,minecraft:soul_sand)
B(-6,39,5,minecraft:soul_sand)
B(-6,40,5,minecraft:soul_sand)
B(-6,41,5,minecraft:soul_sand)
B(-6,42,5,minecraft:soul_sand)
B(-6,43,5,minecraft:soul_sand)
B(-6,44,5,minecraft:soul_sand)
B(-6,45,5,minecraft:soul_sand)
B(-6,46,5,minecraft:soul_sand)
B(-6,47,5,minecraft:soul_sand)
B(-6,48,5,minecraft:soul_sand)
B(-6,49,5,minecraft:soul_sand)
B(-6,50,5,minecraft:soul_sand)
B(-6,51,5,minecraft:soul_sand)
B(-6,52,5,minecraft:soul_sand)
B(-6,53,5,minecraft:soul_sand)
B(-6,54,5,minecraft:soul_sand)
B(-6,55,5,minecraft:soul_sand)
B(-6,56,5,minecraft:soul_sand)
B(-6,57,5,minecraft:soul_sand)
B(-6,58,5,minecraft:soul_sand)
B(-6,59,5,minecraft:soul_sand)
B(-6,0,6,minecraft:soul_sand)
B(-6,1,6,minecraft:soul_sand)
B(-6,2,6,minecraft:soul_sand)
B(-6,3,6,minecraft:soul_sand)
B(-6,4,6,minecraft:soul_sand)
B(-6,5,6,minecraft:soul_sand)
B(-6,6,6,minecraft:soul_sand)
B(-6,7,6,minecraft:soul_sand)
B(-6,8,6,minecraft:soul_sand)
B(-6,9,6,minecraft:soul_sand)
B(-6,10,6,minecraft:soul_sand)
B(-6,11,6,minecraft:soul_sand)
B(-6,12,6,minecraft:soul_sand)
B(-6,13,6,minecraft:soul_sand)
B(-6,14,6,minecraft:soul_sand)
B(-6,15,6,minecraft:soul_sand)
B(-6,16,6,minecraft:soul_sand)
B(-6,17,6,minecraft:soul_sand)
B(-6,18,6,minecraft:soul_sand)
B(-6,19,6,minecraft:soul_sand)
B(-6,20,6,minecraft:soul_sand)
B(-6,21,6,minecraft:soul_sand)
B(-6,22,6,minecraft:soul_sand)
B(-6,23,6,minecraft:soul_sand)
B(-6,24,6,minecraft:soul_sand)
B(-6,25,6,minecraft:soul_sand)
B(-6,26,6,minecraft:soul_sand)
B(-6,27,6,minecraft:soul_sand)
B(-6,28,6,minecraft:soul_sand)
B(-6,29,6,minecraft:soul_sand)
B(-6,30,6,minecraft:soul_sand)
B(-6,31,6,minecraft:soul_sand)
B(-6,32,6,minecraft:soul_sand)
B(-6,33,6,minecraft:soul_sand)
B(-6,34,6,minecraft:soul_sand)
B(-6,35,6,minecraft:soul_sand)
B(-6,36,6,minecraft:soul_sand)
B(-6,37,6,minecraft:soul_sand)
B(-6,38,6,minecraft:soul_sand)
B(-6,39,6,minecraft:soul_sand)
B(-6,40,6,minecraft:soul_sand)
B(-6,41,6,minecraft:soul_sand)
B(-6,42,6,minecraft:soul_sand)
B(-6,43,6,minecraft:soul_sand)
B(-6,44,6,minecraft:soul_sand)
B(-6,45,6,minecraft:soul_sand)
B(-6,46,6,minecraft:soul_sand)
B(-6,47,6,minecraft:soul_sand)
B(-6,48,6,minecraft:soul_sand)
B(-6,49,6,minecraft:soul_sand)
B(-6,50,6,minecraft:soul_sand)
B(-6,51,6,minecraft:soul_sand)
B(-6,52,6,minecraft:soul_sand)
B(-6,53,6,minecraft:soul_sand)
B(-6,54,6,minecraft:soul_sand)
B(-6,55,6,minecraft:soul_sand)
B(-6,56,6,minecraft:soul_sand)
B(-6,57,6,minecraft:soul_sand)
B(-6,58,6,minecraft:soul_sand)
B(-6,0,7,minecraft:soul_sand)
B(-6,1,7,minecraft:soul_sand)
B(-6,2,7,minecraft:soul_sand)
B(-6,3,7,minecraft:soul_sand)
B(-6,4,7,minecraft:soul_sand)
B(-6,5,7,minecraft:soul_sand)
B(-6,6,7,minecraft:soul_sand)
B(-6,7,7,minecraft:soul_sand)
B(-6,8,7,minecraft:soul_sand)
B(-6,9,7,minecraft:soul_sand)
B(-6,10,7,minecraft:soul_sand)
B(-6,11,7,minecraft:soul_sand)
B(-6,12,7,minecraft:soul_sand)
B(-6,13,7,minecraft:soul_sand)
B(-6,14,7,minecraft:soul_sand)
B(-6,15,7,minecraft:soul_sand)
B(-6,16,7,minecraft:soul_sand)
B(-6,17,7,minecraft:soul_sand)
B(-6,18,7,minecraft:soul_sand)
B(-6,19,7,minecraft:soul_sand)
B(-6,20,7,minecraft:soul_sand)
B(-6,21,7,minecraft:soul_sand)
B(-6,22,7,minecraft:soul_sand)
B(-6,23,7,minecraft:soul_sand)
B(-6,24,7,minecraft:soul_sand)
B(-6,25,7,minecraft:soul_sand)
B(-6,26,7,minecraft:soul_sand)
B(-6,27,7,minecraft:soul_sand)
B(-6,28,7,minecraft:soul_sand)
B(-6,29,7,minecraft:soul_sand)
B(-6,30,7,minecraft:soul_sand)
B(-6,31,7,minecraft:soul_sand)
B(-6,32,7,minecraft:soul_sand)
B(-6,33,7,minecraft:soul_sand)
B(-6,34,7,minecraft:soul_sand)
B(-6,35,7,minecraft:soul_sand)
B(-6,36,7,minecraft:soul_sand)
B(-6,37,7,minecraft:soul_sand)
B(-6,38,7,minecraft:soul_sand)
B(-6,39,7,minecraft:soul_sand)
B(-6,40,7,minecraft:soul_sand)
B(-6,41,7,minecraft:soul_sand)
B(-6,42,7,minecraft:soul_sand)
B(-6,43,7,minecraft:soul_sand)
B(-6,44,7,minecraft:soul_sand)
B(-6,45,7,minecraft:soul_sand)
B(-6,46,7,minecraft:soul_sand)
B(-6,47,7,minecraft:soul_sand)
B(-6,48,7,minecraft:soul_sand)
B(-6,49,7,minecraft:soul_sand)
B(-6,50,7,minecraft:soul_sand)
B(-6,51,7,minecraft:soul_sand)
B(-6,52,7,minecraft:soul_sand)
B(-6,53,7,minecraft:soul_sand)
B(-6,54,7,minecraft:soul_sand)
B(-6,55,7,minecraft:soul_sand)
B(-6,56,7,minecraft:soul_sand)
B(-6,57,7,minecraft:soul_sand)
B(-6,58,7,minecraft:soul_sand)
B(-6,0,8,minecraft:soul_sand)
B(-6,1,8,minecraft:soul_sand)
B(-6,2,8,minecraft:soul_sand)
B(-6,3,8,minecraft:soul_sand)
B(-6,4,8,minecraft:soul_sand)
B(-6,5,8,minecraft:soul_sand)
B(-6,6,8,minecraft:soul_sand)
B(-6,7,8,minecraft:soul_sand)
B(-6,8,8,minecraft:soul_sand)
B(-6,9,8,minecraft:soul_sand)
B(-6,10,8,minecraft:soul_sand)
B(-6,11,8,minecraft:soul_sand)
B(-6,12,8,minecraft:soul_sand)
B(-6,13,8,minecraft:soul_sand)
B(-6,14,8,minecraft:soul_sand)
B(-6,15,8,minecraft:soul_sand)
B(-6,16,8,minecraft:soul_sand)
B(-6,17,8,minecraft:soul_sand)
B(-6,18,8,minecraft:soul_sand)
B(-6,19,8,minecraft:soul_sand)
B(-6,20,8,minecraft:soul_sand)
B(-6,21,8,minecraft:soul_sand)
B(-6,22,8,minecraft:soul_sand)
B(-6,23,8,minecraft:soul_sand)
B(-6,24,8,minecraft:soul_sand)
B(-6,25,8,minecraft:soul_sand)
B(-6,26,8,minecraft:soul_sand)
B(-6,27,8,minecraft:soul_sand)
B(-6,28,8,minecraft:soul_sand)
B(-6,29,8,minecraft:soul_sand)
B(-6,30,8,minecraft:soul_sand)
B(-6,31,8,minecraft:soul_sand)
B(-6,32,8,minecraft:soul_sand)
B(-6,33,8,minecraft:soul_sand)
B(-6,34,8,minecraft:soul_sand)
B(-6,35,8,minecraft:soul_sand)
B(-6,36,8,minecraft:soul_sand)
B(-6,37,8,minecraft:soul_sand)
B(-6,38,8,minecraft:soul_sand)
B(-6,39,8,minecraft:soul_sand)
B(-6,40,8,minecraft:soul_sand)
B(-6,41,8,minecraft:soul_sand)
B(-6,42,8,minecraft:soul_sand)
B(-6,43,8,minecraft:soul_sand)
B(-6,44,8,minecraft:soul_sand)
B(-6,45,8,minecraft:soul_sand)
B(-6,46,8,minecraft:soul_sand)
B(-6,47,8,minecraft:soul_sand)
B(-6,48,8,minecraft:soul_sand)
B(-6,49,8,minecraft:soul_sand)
B(-6,50,8,minecraft:soul_sand)
B(-6,51,8,minecraft:soul_sand)
B(-6,52,8,minecraft:soul_sand)
B(-6,53,8,minecraft:soul_sand)
B(-6,54,8,minecraft:soul_sand)
B(-6,55,8,minecraft:soul_sand)
B(-6,56,8,minecraft:soul_sand)
B(-6,57,8,minecraft:soul_sand)
B(-6,58,8,minecraft:soul_sand)
B(-5,0,-7,minecraft:soul_sand)
B(-5,1,-7,minecraft:soul_sand)
B(-5,2,-7,minecraft:soul_sand)
B(-5,3,-7,minecraft:soul_sand)
B(-5,4,-7,minecraft:soul_sand)
B(-5,5,-7,minecraft:soul_sand)
B(-5,6,-7,minecraft:soul_sand)
B(-5,7,-7,minecraft:soul_sand)
B(-5,8,-7,minecraft:soul_sand)
B(-5,9,-7,minecraft:soul_sand)
B(-5,10,-7,minecraft:soul_sand)
B(-5,11,-7,minecraft:soul_sand)
B(-5,12,-7,minecraft:soul_sand)
B(-5,13,-7,minecraft:soul_sand)
B(-5,14,-7,minecraft:soul_sand)
B(-5,15,-7,minecraft:soul_sand)
B(-5,16,-7,minecraft:soul_sand)
B(-5,17,-7,minecraft:soul_sand)
B(-5,18,-7,minecraft:soul_sand)
B(-5,19,-7,minecraft:soul_sand)
B(-5,20,-7,minecraft:soul_sand)
B(-5,21,-7,minecraft:soul_sand)
B(-5,22,-7,minecraft:soul_sand)
B(-5,23,-7,minecraft:soul_sand)
B(-5,24,-7,minecraft:soul_sand)
B(-5,25,-7,minecraft:soul_sand)
