
#######################################################################
# +-----------------------------------------------------------------+ #
# |                            BO4 object                           | #
# +-----------------------------------------------------------------+ #
#######################################################################

Author: Unknown

Description: No description given

SettingsMode: WriteWithoutComments


#######################################################################
# +-----------------------------------------------------------------+ #
# |                          Main settings                          | #
# +-----------------------------------------------------------------+ #
#######################################################################

FixedRotation: 

Frequency: 0

SpawnHeight: highestBlock

UseCenterForHighestBlock: true

##############################
# Height Limits for the BO4. #
##############################

MinHeight: 0

MaxHeight: 255

InheritBO3: 

InheritBO3Rotation: NORTH

OverrideChildSettings: true

OverrideParentHeight: false

CanOverride: false

BranchFrequency: 0

BranchFrequencyGroup: 

MustBeBelowOther: false

MustBeInside: 

CannotBeInside: 

ReplacesBO3: 

MustBeInsideWorldBorders: false

CanSpawnOnWater: true

SpawnOnWaterOnly: false

SpawnUnderWater: false

SpawnAtWaterLevel: false

HeightOffset: 0

RemoveAir: true

ReplaceAbove: 

ReplaceBelow: 

ReplaceWithBiomeBlocks: true

ReplaceWithSurfaceBlock: GRASS

ReplaceWithGroundBlock: DIRT

ReplaceWithStoneBlock: STONE

SmoothRadius: 0

SmoothHeightOffset: 0

SmoothStartTop: false

SmoothStartWood: false

SmoothingSurfaceBlock: 

SmoothingGroundBlock: 

BO3Group: 

IsSpawnPoint: false

DoReplaceBlocks: true


#######################################################################
# +-----------------------------------------------------------------+ #
# |                              Blocks                             | #
# +-----------------------------------------------------------------+ #
#######################################################################

B(-8,0,-7,minecraft:soul_sand)
B(-8,1,-7,minecraft:soul_sand)
B(-8,2,-7,minecraft:soul_sand)
B(-8,3,-7,minecraft:soul_sand)
B(-8,4,-7,minecraft:soul_sand)
B(-8,5,-7,minecraft:soul_sand)
B(-8,6,-7,minecraft:soul_sand)
B(-8,7,-7,minecraft:soul_sand)
B(-8,8,-7,minecraft:soul_sand)
B(-8,9,-7,minecraft:soul_sand)
B(-8,10,-7,minecraft:soul_sand)
B(-8,11,-7,minecraft:soul_sand)
B(-8,12,-7,minecraft:soul_sand)
B(-8,13,-7,minecraft:soul_sand)
B(-8,14,-7,minecraft:soul_sand)
B(-8,15,-7,minecraft:soul_sand)
B(-8,16,-7,minecraft:soul_sand)
B(-8,17,-7,minecraft:soul_sand)
B(-8,18,-7,minecraft:soul_sand)
B(-8,19,-7,minecraft:soul_sand)
B(-8,20,-7,minecraft:soul_sand)
B(-8,21,-7,minecraft:soul_sand)
B(-8,22,-7,minecraft:soul_sand)
B(-8,23,-7,minecraft:soul_sand)
B(-8,24,-7,minecraft:soul_sand)
B(-8,25,-7,minecraft:soul_sand)
B(-8,26,-7,minecraft:soul_sand)
B(-8,27,-7,minecraft:soul_sand)
B(-8,28,-7,minecraft:soul_sand)
B(-8,29,-7,minecraft:soul_sand)
B(-8,30,-7,minecraft:soul_sand)
B(-8,31,-7,minecraft:soul_sand)
B(-8,32,-7,minecraft:soul_sand)
B(-8,33,-7,minecraft:soul_sand)
B(-8,34,-7,minecraft:soul_sand)
B(-8,35,-7,minecraft:soul_sand)
B(-8,36,-7,minecraft:soul_sand)
B(-8,37,-7,minecraft:soul_sand)
B(-8,38,-7,minecraft:soul_sand)
B(-8,39,-7,minecraft:soul_sand)
B(-8,40,-7,minecraft:soul_sand)
B(-8,41,-7,minecraft:soul_sand)
B(-8,42,-7,minecraft:soul_sand)
B(-8,43,-7,minecraft:soul_sand)
B(-8,44,-7,minecraft:soul_sand)
B(-8,45,-7,minecraft:soul_sand)
B(-8,46,-7,minecraft:soul_sand)
B(-8,47,-7,minecraft:soul_sand)
B(-8,48,-7,minecraft:soul_sand)
B(-8,49,-7,minecraft:soul_sand)
B(-8,50,-7,minecraft:soul_sand)
B(-8,51,-7,minecraft:soul_sand)
B(-8,52,-7,minecraft:soul_sand)
B(-8,0,-6,minecraft:blackstone)
B(-8,1,-6,minecraft:soul_sand)
B(-8,2,-6,minecraft:soul_sand)
B(-8,3,-6,minecraft:soul_sand)
B(-8,4,-6,minecraft:soul_sand)
B(-8,5,-6,minecraft:soul_sand)
B(-8,6,-6,minecraft:soul_sand)
B(-8,7,-6,minecraft:soul_sand)
B(-8,8,-6,minecraft:soul_sand)
B(-8,9,-6,minecraft:soul_sand)
B(-8,10,-6,minecraft:soul_sand)
B(-8,11,-6,minecraft:soul_sand)
B(-8,12,-6,minecraft:soul_sand)
B(-8,13,-6,minecraft:soul_sand)
B(-8,14,-6,minecraft:soul_sand)
B(-8,15,-6,minecraft:soul_sand)
B(-8,16,-6,minecraft:soul_sand)
B(-8,17,-6,minecraft:soul_sand)
B(-8,18,-6,minecraft:soul_sand)
B(-8,19,-6,minecraft:soul_sand)
B(-8,20,-6,minecraft:soul_sand)
B(-8,21,-6,minecraft:soul_sand)
B(-8,22,-6,minecraft:soul_sand)
B(-8,23,-6,minecraft:soul_sand)
B(-8,24,-6,minecraft:soul_sand)
B(-8,25,-6,minecraft:soul_sand)
B(-8,26,-6,minecraft:soul_sand)
B(-8,27,-6,minecraft:soul_sand)
B(-8,28,-6,minecraft:soul_sand)
B(-8,29,-6,minecraft:soul_sand)
B(-8,30,-6,minecraft:soul_sand)
B(-8,31,-6,minecraft:soul_sand)
B(-8,32,-6,minecraft:soul_sand)
B(-8,33,-6,minecraft:soul_sand)
B(-8,34,-6,minecraft:soul_sand)
B(-8,35,-6,minecraft:soul_sand)
B(-8,36,-6,minecraft:soul_sand)
B(-8,0,-5,minecraft:blackstone)
B(-8,1,-5,minecraft:blackstone)
B(-8,2,-5,minecraft:soul_sand)
B(-8,3,-5,minecraft:soul_sand)
B(-8,4,-5,minecraft:soul_sand)
B(-8,5,-5,minecraft:soul_sand)
B(-8,6,-5,minecraft:soul_sand)
B(-8,7,-5,minecraft:soul_sand)
B(-8,8,-5,minecraft:soul_sand)
B(-8,9,-5,minecraft:soul_sand)
B(-8,10,-5,minecraft:soul_sand)
B(-8,11,-5,minecraft:soul_sand)
B(-8,12,-5,minecraft:soul_sand)
B(-8,13,-5,minecraft:soul_sand)
B(-8,14,-5,minecraft:soul_sand)
B(-8,15,-5,minecraft:soul_sand)
B(-8,16,-5,minecraft:soul_sand)
B(-8,17,-5,minecraft:soul_sand)
B(-8,18,-5,minecraft:soul_sand)
B(-8,19,-5,minecraft:soul_sand)
B(-8,20,-5,minecraft:soul_sand)
B(-8,21,-5,minecraft:soul_sand)
B(-8,22,-5,minecraft:soul_sand)
B(-8,23,-5,minecraft:soul_sand)
B(-8,24,-5,minecraft:soul_sand)
B(-8,25,-5,minecraft:soul_sand)
B(-8,26,-5,minecraft:soul_sand)
B(-8,27,-5,minecraft:soul_sand)
B(-8,28,-5,minecraft:soul_sand)
B(-8,29,-5,minecraft:soul_sand)
B(-8,30,-5,minecraft:soul_sand)
B(-8,31,-5,minecraft:soul_sand)
B(-8,32,-5,minecraft:soul_sand)
B(-8,33,-5,minecraft:soul_sand)
B(-8,34,-5,minecraft:soul_sand)
B(-8,35,-5,minecraft:soul_sand)
B(-8,36,-5,minecraft:soul_sand)
B(-8,37,-5,minecraft:soul_sand)
B(-8,38,-5,minecraft:soul_sand)
B(-8,39,-5,minecraft:soul_sand)
B(-8,40,-5,minecraft:soul_sand)
B(-8,41,-5,minecraft:soul_sand)
B(-8,42,-5,minecraft:soul_sand)
B(-8,0,-4,minecraft:blackstone)
B(-8,1,-4,minecraft:blackstone)
B(-8,2,-4,minecraft:soul_sand)
B(-8,3,-4,minecraft:soul_sand)
B(-8,4,-4,minecraft:soul_sand)
B(-8,5,-4,minecraft:soul_sand)
B(-8,6,-4,minecraft:soul_sand)
B(-8,7,-4,minecraft:soul_sand)
B(-8,8,-4,minecraft:soul_sand)
B(-8,9,-4,minecraft:soul_sand)
B(-8,10,-4,minecraft:soul_sand)
B(-8,11,-4,minecraft:soul_sand)
B(-8,12,-4,minecraft:soul_sand)
B(-8,13,-4,minecraft:soul_sand)
B(-8,14,-4,minecraft:soul_sand)
B(-8,15,-4,minecraft:soul_sand)
B(-8,16,-4,minecraft:soul_sand)
B(-8,17,-4,minecraft:soul_sand)
B(-8,18,-4,minecraft:soul_sand)
B(-8,19,-4,minecraft:soul_sand)
B(-8,20,-4,minecraft:soul_sand)
B(-8,21,-4,minecraft:soul_sand)
B(-8,22,-4,minecraft:soul_sand)
B(-8,23,-4,minecraft:soul_sand)
B(-8,24,-4,minecraft:soul_sand)
B(-8,25,-4,minecraft:soul_sand)
B(-8,26,-4,minecraft:soul_sand)
B(-8,27,-4,minecraft:soul_sand)
B(-8,28,-4,minecraft:soul_sand)
B(-8,29,-4,minecraft:soul_sand)
B(-8,30,-4,minecraft:soul_sand)
B(-8,31,-4,minecraft:soul_sand)
B(-8,32,-4,minecraft:soul_sand)
B(-8,33,-4,minecraft:soul_sand)
B(-8,34,-4,minecraft:soul_sand)
B(-8,35,-4,minecraft:soul_sand)
B(-8,36,-4,minecraft:soul_sand)
B(-8,37,-4,minecraft:soul_sand)
B(-8,38,-4,minecraft:soul_sand)
B(-8,39,-4,minecraft:soul_sand)
B(-8,40,-4,minecraft:soul_sand)
B(-8,41,-4,minecraft:soul_sand)
B(-8,42,-4,minecraft:soul_sand)
B(-8,43,-4,minecraft:soul_sand)
B(-8,44,-4,minecraft:soul_sand)
B(-8,45,-4,minecraft:soul_sand)
B(-8,46,-4,minecraft:soul_sand)
B(-8,47,-4,minecraft:soul_sand)
B(-8,48,-4,minecraft:soul_sand)
B(-8,49,-4,minecraft:soul_sand)
B(-8,50,-4,minecraft:soul_sand)
B(-8,0,-3,minecraft:blackstone)
B(-8,1,-3,minecraft:blackstone)
B(-8,2,-3,minecraft:soul_sand)
B(-8,3,-3,minecraft:soul_sand)
B(-8,4,-3,minecraft:soul_sand)
B(-8,5,-3,minecraft:soul_sand)
B(-8,6,-3,minecraft:soul_sand)
B(-8,7,-3,minecraft:soul_sand)
B(-8,8,-3,minecraft:soul_sand)
B(-8,9,-3,minecraft:soul_sand)
B(-8,10,-3,minecraft:soul_sand)
B(-8,11,-3,minecraft:soul_sand)
B(-8,12,-3,minecraft:soul_sand)
B(-8,13,-3,minecraft:soul_sand)
B(-8,14,-3,minecraft:soul_sand)
B(-8,15,-3,minecraft:soul_sand)
B(-8,16,-3,minecraft:soul_sand)
B(-8,17,-3,minecraft:soul_sand)
B(-8,18,-3,minecraft:soul_sand)
B(-8,19,-3,minecraft:soul_sand)
B(-8,20,-3,minecraft:soul_sand)
B(-8,21,-3,minecraft:soul_sand)
B(-8,22,-3,minecraft:soul_sand)
B(-8,23,-3,minecraft:soul_sand)
B(-8,24,-3,minecraft:soul_sand)
B(-8,25,-3,minecraft:soul_sand)
B(-8,26,-3,minecraft:soul_sand)
B(-8,27,-3,minecraft:soul_sand)
B(-8,28,-3,minecraft:soul_sand)
B(-8,29,-3,minecraft:soul_sand)
B(-8,30,-3,minecraft:soul_sand)
B(-8,31,-3,minecraft:soul_sand)
B(-8,32,-3,minecraft:soul_sand)
B(-8,33,-3,minecraft:soul_sand)
B(-8,34,-3,minecraft:soul_sand)
B(-8,35,-3,minecraft:soul_sand)
B(-8,36,-3,minecraft:soul_sand)
B(-8,37,-3,minecraft:soul_sand)
B(-8,38,-3,minecraft:soul_sand)
B(-8,39,-3,minecraft:soul_sand)
B(-8,40,-3,minecraft:soul_sand)
B(-8,41,-3,minecraft:soul_sand)
B(-8,42,-3,minecraft:soul_sand)
B(-8,43,-3,minecraft:soul_sand)
B(-8,44,-3,minecraft:soul_sand)
B(-8,45,-3,minecraft:soul_sand)
B(-8,46,-3,minecraft:soul_sand)
B(-8,47,-3,minecraft:soul_sand)
B(-8,48,-3,minecraft:soul_sand)
B(-8,49,-3,minecraft:soul_sand)
B(-8,50,-3,minecraft:soul_sand)
B(-8,0,-2,minecraft:blackstone)
B(-8,1,-2,minecraft:soul_sand)
B(-8,2,-2,minecraft:soul_sand)
B(-8,3,-2,minecraft:soul_sand)
B(-8,4,-2,minecraft:soul_sand)
B(-8,5,-2,minecraft:soul_sand)
B(-8,6,-2,minecraft:soul_sand)
B(-8,7,-2,minecraft:soul_sand)
B(-8,8,-2,minecraft:soul_sand)
B(-8,9,-2,minecraft:soul_sand)
B(-8,10,-2,minecraft:soul_sand)
B(-8,11,-2,minecraft:soul_sand)
B(-8,12,-2,minecraft:soul_sand)
B(-8,13,-2,minecraft:soul_sand)
B(-8,14,-2,minecraft:soul_sand)
B(-8,15,-2,minecraft:soul_sand)
B(-8,16,-2,minecraft:soul_sand)
B(-8,17,-2,minecraft:soul_sand)
B(-8,18,-2,minecraft:soul_sand)
B(-8,19,-2,minecraft:soul_sand)
B(-8,20,-2,minecraft:soul_sand)
B(-8,21,-2,minecraft:soul_sand)
B(-8,22,-2,minecraft:soul_sand)
B(-8,23,-2,minecraft:soul_sand)
B(-8,24,-2,minecraft:soul_sand)
B(-8,25,-2,minecraft:soul_sand)
B(-8,26,-2,minecraft:soul_sand)
B(-8,27,-2,minecraft:soul_sand)
B(-8,28,-2,minecraft:soul_sand)
B(-8,29,-2,minecraft:soul_sand)
B(-8,30,-2,minecraft:soul_sand)
B(-8,31,-2,minecraft:soul_sand)
B(-8,32,-2,minecraft:soul_sand)
B(-8,33,-2,minecraft:soul_sand)
B(-8,34,-2,minecraft:soul_sand)
B(-8,35,-2,minecraft:soul_sand)
B(-8,36,-2,minecraft:soul_sand)
B(-8,37,-2,minecraft:soul_sand)
B(-8,38,-2,minecraft:soul_sand)
B(-8,39,-2,minecraft:soul_sand)
B(-8,40,-2,minecraft:soul_sand)
B(-8,41,-2,minecraft:soul_sand)
B(-8,42,-2,minecraft:soul_sand)
B(-8,43,-2,minecraft:soul_sand)
B(-8,44,-2,minecraft:soul_sand)
B(-8,45,-2,minecraft:soul_sand)
B(-8,46,-2,minecraft:soul_sand)
B(-8,47,-2,minecraft:soul_sand)
B(-8,48,-2,minecraft:soul_sand)
B(-8,0,-1,minecraft:soul_sand)
B(-8,1,-1,minecraft:soul_sand)
B(-8,2,-1,minecraft:soul_sand)
B(-8,3,-1,minecraft:soul_sand)
B(-8,4,-1,minecraft:soul_sand)
B(-8,5,-1,minecraft:soul_sand)
B(-8,6,-1,minecraft:soul_sand)
B(-8,7,-1,minecraft:soul_sand)
B(-8,8,-1,minecraft:soul_sand)
B(-8,9,-1,minecraft:soul_sand)
B(-8,10,-1,minecraft:soul_sand)
B(-8,11,-1,minecraft:soul_sand)
B(-8,12,-1,minecraft:soul_sand)
B(-8,13,-1,minecraft:soul_sand)
B(-8,14,-1,minecraft:soul_sand)
B(-8,15,-1,minecraft:soul_sand)
B(-8,16,-1,minecraft:soul_sand)
B(-8,17,-1,minecraft:soul_sand)
B(-8,18,-1,minecraft:soul_sand)
B(-8,19,-1,minecraft:soul_sand)
B(-8,20,-1,minecraft:soul_sand)
B(-8,21,-1,minecraft:soul_sand)
B(-8,22,-1,minecraft:soul_sand)
B(-8,23,-1,minecraft:soul_sand)
B(-8,24,-1,minecraft:soul_sand)
B(-8,25,-1,minecraft:soul_sand)
B(-8,26,-1,minecraft:soul_sand)
B(-8,27,-1,minecraft:soul_sand)
B(-8,28,-1,minecraft:soul_sand)
B(-8,29,-1,minecraft:soul_sand)
B(-8,30,-1,minecraft:soul_sand)
B(-8,31,-1,minecraft:soul_sand)
B(-8,32,-1,minecraft:soul_sand)
B(-8,33,-1,minecraft:soul_sand)
B(-8,34,-1,minecraft:soul_sand)
B(-8,35,-1,minecraft:soul_sand)
B(-8,36,-1,minecraft:soul_sand)
B(-8,37,-1,minecraft:soul_sand)
B(-8,38,-1,minecraft:soul_sand)
B(-8,39,-1,minecraft:soul_sand)
B(-8,40,-1,minecraft:soul_sand)
B(-8,41,-1,minecraft:soul_sand)
B(-8,42,-1,minecraft:soul_sand)
B(-8,43,-1,minecraft:soul_sand)
B(-8,44,-1,minecraft:soul_sand)
B(-8,45,-1,minecraft:soul_sand)
B(-8,46,-1,minecraft:soul_sand)
B(-8,47,-1,minecraft:soul_sand)
B(-8,48,-1,minecraft:soul_sand)
B(-8,49,-1,minecraft:soul_sand)
B(-8,0,0,minecraft:soul_sand)
B(-8,1,0,minecraft:soul_sand)
B(-8,2,0,minecraft:soul_sand)
B(-8,3,0,minecraft:soul_sand)
B(-8,4,0,minecraft:soul_sand)
B(-8,5,0,minecraft:soul_sand)
B(-8,6,0,minecraft:soul_sand)
B(-8,7,0,minecraft:soul_sand)
B(-8,8,0,minecraft:soul_sand)
B(-8,9,0,minecraft:soul_sand)
B(-8,10,0,minecraft:soul_sand)
B(-8,11,0,minecraft:soul_sand)
B(-8,12,0,minecraft:soul_sand)
B(-8,13,0,minecraft:soul_sand)
B(-8,14,0,minecraft:soul_sand)
B(-8,15,0,minecraft:soul_sand)
B(-8,16,0,minecraft:soul_sand)
B(-8,17,0,minecraft:soul_sand)
B(-8,18,0,minecraft:soul_sand)
B(-8,19,0,minecraft:soul_sand)
B(-8,20,0,minecraft:soul_sand)
B(-8,21,0,minecraft:soul_sand)
B(-8,22,0,minecraft:soul_sand)
B(-8,23,0,minecraft:soul_sand)
B(-8,24,0,minecraft:soul_sand)
B(-8,25,0,minecraft:soul_sand)
B(-8,26,0,minecraft:soul_sand)
B(-8,27,0,minecraft:soul_sand)
B(-8,28,0,minecraft:soul_sand)
B(-8,29,0,minecraft:soul_sand)
B(-8,30,0,minecraft:soul_sand)
B(-8,31,0,minecraft:soul_sand)
B(-8,32,0,minecraft:soul_sand)
B(-8,33,0,minecraft:soul_sand)
B(-8,34,0,minecraft:soul_sand)
B(-8,35,0,minecraft:soul_sand)
B(-8,36,0,minecraft:soul_sand)
B(-8,37,0,minecraft:soul_sand)
B(-8,38,0,minecraft:soul_sand)
B(-8,39,0,minecraft:soul_sand)
B(-8,40,0,minecraft:soul_sand)
B(-8,41,0,minecraft:soul_sand)
B(-8,42,0,minecraft:soul_sand)
B(-8,43,0,minecraft:soul_sand)
B(-8,44,0,minecraft:soul_sand)
B(-8,45,0,minecraft:soul_sand)
B(-8,46,0,minecraft:soul_sand)
B(-8,0,1,minecraft:soul_sand)
B(-8,1,1,minecraft:soul_sand)
B(-8,2,1,minecraft:soul_sand)
B(-8,3,1,minecraft:soul_sand)
B(-8,4,1,minecraft:soul_sand)
B(-8,5,1,minecraft:soul_sand)
B(-8,6,1,minecraft:soul_sand)
B(-8,7,1,minecraft:soul_sand)
B(-8,8,1,minecraft:soul_sand)
B(-8,9,1,minecraft:soul_sand)
B(-8,10,1,minecraft:soul_sand)
B(-8,11,1,minecraft:soul_sand)
B(-8,12,1,minecraft:soul_sand)
B(-8,13,1,minecraft:soul_sand)
B(-8,14,1,minecraft:soul_sand)
B(-8,15,1,minecraft:soul_sand)
B(-8,16,1,minecraft:soul_sand)
B(-8,17,1,minecraft:soul_sand)
B(-8,18,1,minecraft:soul_sand)
B(-8,19,1,minecraft:soul_sand)
B(-8,20,1,minecraft:soul_sand)
B(-8,21,1,minecraft:soul_sand)
B(-8,22,1,minecraft:soul_sand)
B(-8,23,1,minecraft:soul_sand)
B(-8,24,1,minecraft:soul_sand)
B(-8,25,1,minecraft:soul_sand)
B(-8,26,1,minecraft:soul_sand)
B(-8,27,1,minecraft:soul_sand)
B(-8,28,1,minecraft:soul_sand)
B(-8,29,1,minecraft:soul_sand)
B(-8,30,1,minecraft:soul_sand)
B(-8,31,1,minecraft:soul_sand)
B(-8,32,1,minecraft:soul_sand)
B(-8,33,1,minecraft:soul_sand)
B(-8,34,1,minecraft:soul_sand)
B(-8,35,1,minecraft:soul_sand)
B(-8,36,1,minecraft:soul_sand)
B(-8,37,1,minecraft:soul_sand)
B(-8,38,1,minecraft:soul_sand)
B(-8,39,1,minecraft:soul_sand)
B(-8,40,1,minecraft:soul_sand)
B(-8,41,1,minecraft:soul_sand)
B(-8,42,1,minecraft:soul_sand)
B(-8,0,2,minecraft:blackstone)
B(-8,1,2,minecraft:soul_sand)
B(-8,2,2,minecraft:soul_sand)
B(-8,3,2,minecraft:soul_sand)
B(-8,4,2,minecraft:soul_sand)
B(-8,5,2,minecraft:soul_sand)
B(-8,6,2,minecraft:soul_sand)
B(-8,7,2,minecraft:soul_sand)
B(-8,8,2,minecraft:soul_sand)
B(-8,9,2,minecraft:soul_sand)
B(-8,10,2,minecraft:soul_sand)
B(-8,11,2,minecraft:soul_sand)
B(-8,12,2,minecraft:soul_sand)
B(-8,13,2,minecraft:soul_sand)
B(-8,14,2,minecraft:soul_sand)
B(-8,15,2,minecraft:soul_sand)
B(-8,16,2,minecraft:soul_sand)
B(-8,17,2,minecraft:soul_sand)
B(-8,18,2,minecraft:soul_sand)
B(-8,19,2,minecraft:soul_sand)
B(-8,20,2,minecraft:soul_sand)
B(-8,21,2,minecraft:soul_sand)
B(-8,22,2,minecraft:soul_sand)
B(-8,23,2,minecraft:soul_sand)
B(-8,24,2,minecraft:soul_sand)
B(-8,25,2,minecraft:soul_sand)
B(-8,26,2,minecraft:soul_sand)
B(-8,27,2,minecraft:soul_sand)
B(-8,28,2,minecraft:soul_sand)
B(-8,29,2,minecraft:soul_sand)
B(-8,30,2,minecraft:soul_sand)
B(-8,31,2,minecraft:soul_sand)
B(-8,32,2,minecraft:soul_sand)
B(-8,0,3,minecraft:soul_sand)
B(-8,1,3,minecraft:soul_sand)
B(-8,2,3,minecraft:soul_sand)
B(-8,3,3,minecraft:soul_sand)
B(-8,4,3,minecraft:soul_sand)
B(-8,5,3,minecraft:soul_sand)
B(-8,6,3,minecraft:soul_sand)
B(-8,7,3,minecraft:soul_sand)
B(-8,8,3,minecraft:soul_sand)
B(-8,9,3,minecraft:soul_sand)
B(-8,10,3,minecraft:soul_sand)
B(-8,11,3,minecraft:soul_sand)
B(-8,12,3,minecraft:soul_sand)
B(-8,13,3,minecraft:soul_sand)
B(-8,14,3,minecraft:soul_sand)
B(-8,15,3,minecraft:soul_sand)
B(-8,16,3,minecraft:soul_sand)
B(-8,17,3,minecraft:soul_sand)
B(-8,18,3,minecraft:soul_sand)
B(-8,19,3,minecraft:soul_sand)
B(-8,20,3,minecraft:soul_sand)
B(-8,21,3,minecraft:soul_sand)
B(-8,0,4,minecraft:soul_sand)
B(-8,1,4,minecraft:soul_sand)
B(-8,2,4,minecraft:soul_sand)
B(-8,3,4,minecraft:soul_sand)
B(-8,4,4,minecraft:soul_sand)
B(-7,0,-7,minecraft:blackstone)
B(-7,1,-7,minecraft:blackstone)
B(-7,2,-7,minecraft:soul_sand)
B(-7,3,-7,minecraft:soul_sand)
B(-7,4,-7,minecraft:soul_sand)
B(-7,5,-7,minecraft:soul_sand)
B(-7,6,-7,minecraft:soul_sand)
B(-7,7,-7,minecraft:soul_sand)
B(-7,8,-7,minecraft:soul_sand)
B(-7,9,-7,minecraft:soul_sand)
B(-7,10,-7,minecraft:soul_sand)
B(-7,11,-7,minecraft:soul_sand)
B(-7,12,-7,minecraft:soul_sand)
B(-7,13,-7,minecraft:soul_sand)
B(-7,14,-7,minecraft:soul_sand)
B(-7,15,-7,minecraft:soul_sand)
B(-7,16,-7,minecraft:soul_sand)
B(-7,17,-7,minecraft:soul_sand)
B(-7,18,-7,minecraft:soul_sand)
B(-7,19,-7,minecraft:soul_sand)
B(-7,20,-7,minecraft:soul_sand)
B(-7,21,-7,minecraft:soul_sand)
B(-7,22,-7,minecraft:soul_sand)
B(-7,23,-7,minecraft:soul_sand)
B(-7,24,-7,minecraft:soul_sand)
B(-7,25,-7,minecraft:soul_sand)
B(-7,26,-7,minecraft:soul_sand)
B(-7,27,-7,minecraft:soul_sand)
B(-7,28,-7,minecraft:soul_sand)
B(-7,29,-7,minecraft:soul_sand)
B(-7,30,-7,minecraft:soul_sand)
B(-7,31,-7,minecraft:soul_sand)
B(-7,32,-7,minecraft:soul_sand)
B(-7,33,-7,minecraft:soul_sand)
B(-7,0,-6,minecraft:blackstone)
B(-7,1,-6,minecraft:blackstone)
B(-7,2,-6,minecraft:soul_sand)
B(-7,3,-6,minecraft:soul_sand)
B(-7,4,-6,minecraft:soul_sand)
B(-7,5,-6,minecraft:soul_sand)
B(-7,6,-6,minecraft:soul_sand)
B(-7,7,-6,minecraft:soul_sand)
B(-7,8,-6,minecraft:soul_sand)
B(-7,9,-6,minecraft:soul_sand)
B(-7,10,-6,minecraft:soul_sand)
B(-7,11,-6,minecraft:soul_sand)
B(-7,12,-6,minecraft:soul_sand)
B(-7,13,-6,minecraft:soul_sand)
B(-7,14,-6,minecraft:soul_sand)
B(-7,15,-6,minecraft:soul_sand)
B(-7,16,-6,minecraft:soul_sand)
B(-7,17,-6,minecraft:soul_sand)
B(-7,18,-6,minecraft:soul_sand)
B(-7,19,-6,minecraft:soul_sand)
B(-7,20,-6,minecraft:soul_sand)
B(-7,21,-6,minecraft:soul_sand)
B(-7,22,-6,minecraft:soul_sand)
B(-7,23,-6,minecraft:soul_sand)
B(-7,24,-6,minecraft:soul_sand)
B(-7,0,-5,minecraft:blackstone)
B(-7,1,-5,minecraft:blackstone)
B(-7,2,-5,minecraft:soul_sand)
B(-7,3,-5,minecraft:soul_sand)
B(-7,4,-5,minecraft:soul_sand)
B(-7,5,-5,minecraft:soul_sand)
B(-7,6,-5,minecraft:soul_sand)
B(-7,7,-5,minecraft:soul_sand)
B(-7,8,-5,minecraft:soul_sand)
B(-7,9,-5,minecraft:soul_sand)
B(-7,10,-5,minecraft:soul_sand)
B(-7,11,-5,minecraft:soul_sand)
B(-7,12,-5,minecraft:soul_sand)
B(-7,13,-5,minecraft:soul_sand)
B(-7,14,-5,minecraft:soul_sand)
B(-7,15,-5,minecraft:soul_sand)
B(-7,16,-5,minecraft:soul_sand)
B(-7,17,-5,minecraft:soul_sand)
B(-7,18,-5,minecraft:soul_sand)
B(-7,0,-4,minecraft:blackstone)
B(-7,1,-4,minecraft:blackstone)
B(-7,2,-4,minecraft:soul_sand)
B(-7,3,-4,minecraft:soul_sand)
B(-7,4,-4,minecraft:soul_sand)
B(-7,5,-4,minecraft:soul_sand)
B(-7,6,-4,minecraft:soul_sand)
B(-7,7,-4,minecraft:soul_sand)
B(-7,8,-4,minecraft:soul_sand)
B(-7,9,-4,minecraft:soul_sand)
B(-7,10,-4,minecraft:soul_sand)
B(-7,11,-4,minecraft:soul_sand)
B(-7,12,-4,minecraft:soul_sand)
B(-7,13,-4,minecraft:soul_sand)
B(-7,14,-4,minecraft:soul_sand)
B(-7,15,-4,minecraft:soul_sand)
B(-7,16,-4,minecraft:soul_sand)
B(-7,17,-4,minecraft:soul_sand)
B(-7,18,-4,minecraft:soul_sand)
B(-7,19,-4,minecraft:soul_sand)
B(-7,20,-4,minecraft:soul_sand)
B(-7,21,-4,minecraft:soul_sand)
B(-7,22,-4,minecraft:soul_sand)
B(-7,23,-4,minecraft:soul_sand)
B(-7,24,-4,minecraft:soul_sand)
B(-7,25,-4,minecraft:soul_sand)
B(-7,26,-4,minecraft:soul_sand)
B(-7,27,-4,minecraft:soul_sand)
B(-7,28,-4,minecraft:soul_sand)
B(-7,29,-4,minecraft:soul_sand)
B(-7,30,-4,minecraft:soul_sand)
B(-7,0,-3,minecraft:blackstone)
B(-7,1,-3,minecraft:blackstone)
B(-7,2,-3,minecraft:soul_sand)
B(-7,3,-3,minecraft:soul_sand)
B(-7,4,-3,minecraft:soul_sand)
B(-7,5,-3,minecraft:soul_sand)
B(-7,6,-3,minecraft:soul_sand)
B(-7,7,-3,minecraft:soul_sand)
B(-7,8,-3,minecraft:soul_sand)
B(-7,9,-3,minecraft:soul_sand)
B(-7,10,-3,minecraft:soul_sand)
B(-7,11,-3,minecraft:soul_sand)
B(-7,12,-3,minecraft:soul_sand)
B(-7,13,-3,minecraft:soul_sand)
B(-7,14,-3,minecraft:soul_sand)
B(-7,15,-3,minecraft:soul_sand)
B(-7,16,-3,minecraft:soul_sand)
B(-7,17,-3,minecraft:soul_sand)
B(-7,18,-3,minecraft:soul_sand)
B(-7,19,-3,minecraft:soul_sand)
B(-7,20,-3,minecraft:soul_sand)
B(-7,21,-3,minecraft:soul_sand)
B(-7,22,-3,minecraft:soul_sand)
B(-7,23,-3,minecraft:soul_sand)
B(-7,24,-3,minecraft:soul_sand)
B(-7,25,-3,minecraft:soul_sand)
B(-7,26,-3,minecraft:soul_sand)
B(-7,27,-3,minecraft:soul_sand)
B(-7,28,-3,minecraft:soul_sand)
B(-7,29,-3,minecraft:soul_sand)
B(-7,30,-3,minecraft:soul_sand)
B(-7,31,-3,minecraft:soul_sand)
B(-7,32,-3,minecraft:soul_sand)
B(-7,0,-2,minecraft:blackstone)
B(-7,1,-2,minecraft:blackstone)
B(-7,2,-2,minecraft:soul_sand)
B(-7,3,-2,minecraft:soul_sand)
B(-7,4,-2,minecraft:soul_sand)
B(-7,5,-2,minecraft:soul_sand)
B(-7,6,-2,minecraft:soul_sand)
B(-7,7,-2,minecraft:soul_sand)
B(-7,8,-2,minecraft:soul_sand)
B(-7,9,-2,minecraft:soul_sand)
B(-7,10,-2,minecraft:soul_sand)
B(-7,11,-2,minecraft:soul_sand)
B(-7,12,-2,minecraft:soul_sand)
B(-7,13,-2,minecraft:soul_sand)
B(-7,14,-2,minecraft:soul_sand)
B(-7,15,-2,minecraft:soul_sand)
B(-7,16,-2,minecraft:soul_sand)
B(-7,17,-2,minecraft:soul_sand)
B(-7,18,-2,minecraft:soul_sand)
B(-7,19,-2,minecraft:soul_sand)
B(-7,20,-2,minecraft:soul_sand)
B(-7,21,-2,minecraft:soul_sand)
B(-7,22,-2,minecraft:soul_sand)
B(-7,23,-2,minecraft:soul_sand)
B(-7,24,-2,minecraft:soul_sand)
B(-7,25,-2,minecraft:soul_sand)
B(-7,26,-2,minecraft:soul_sand)
B(-7,27,-2,minecraft:soul_sand)
B(-7,28,-2,minecraft:soul_sand)
B(-7,29,-2,minecraft:soul_sand)
B(-7,30,-2,minecraft:soul_sand)
B(-7,31,-2,minecraft:soul_sand)
B(-7,32,-2,minecraft:soul_sand)
B(-7,33,-2,minecraft:soul_sand)
B(-7,34,-2,minecraft:soul_sand)
B(-7,0,-1,minecraft:blackstone)
B(-7,1,-1,minecraft:blackstone)
B(-7,2,-1,minecraft:soul_sand)
B(-7,3,-1,minecraft:soul_sand)
B(-7,4,-1,minecraft:soul_sand)
B(-7,5,-1,minecraft:soul_sand)
B(-7,6,-1,minecraft:soul_sand)
B(-7,7,-1,minecraft:soul_sand)
B(-7,8,-1,minecraft:soul_sand)
B(-7,9,-1,minecraft:soul_sand)
B(-7,10,-1,minecraft:soul_sand)
B(-7,11,-1,minecraft:soul_sand)
B(-7,12,-1,minecraft:soul_sand)
B(-7,13,-1,minecraft:soul_sand)
B(-7,14,-1,minecraft:soul_sand)
B(-7,15,-1,minecraft:soul_sand)
B(-7,16,-1,minecraft:soul_sand)
B(-7,17,-1,minecraft:soul_sand)
B(-7,18,-1,minecraft:soul_sand)
B(-7,19,-1,minecraft:soul_sand)
B(-7,20,-1,minecraft:soul_sand)
B(-7,21,-1,minecraft:soul_sand)
B(-7,22,-1,minecraft:soul_sand)
B(-7,23,-1,minecraft:soul_sand)
B(-7,24,-1,minecraft:soul_sand)
B(-7,25,-1,minecraft:soul_sand)
B(-7,26,-1,minecraft:soul_sand)
B(-7,27,-1,minecraft:soul_sand)
B(-7,28,-1,minecraft:soul_sand)
B(-7,29,-1,minecraft:soul_sand)
B(-7,30,-1,minecraft:soul_sand)
B(-7,31,-1,minecraft:soul_sand)
B(-7,32,-1,minecraft:soul_sand)
B(-7,33,-1,minecraft:soul_sand)
B(-7,34,-1,minecraft:soul_sand)
B(-7,0,0,minecraft:blackstone)
B(-7,1,0,minecraft:blackstone)
B(-7,2,0,minecraft:soul_sand)
B(-7,3,0,minecraft:soul_sand)
B(-7,4,0,minecraft:soul_sand)
B(-7,5,0,minecraft:soul_sand)
B(-7,6,0,minecraft:soul_sand)
B(-7,7,0,minecraft:soul_sand)
B(-7,8,0,minecraft:soul_sand)
B(-7,9,0,minecraft:soul_sand)
B(-7,10,0,minecraft:soul_sand)
B(-7,11,0,minecraft:soul_sand)
B(-7,12,0,minecraft:soul_sand)
B(-7,13,0,minecraft:soul_sand)
B(-7,14,0,minecraft:soul_sand)
B(-7,15,0,minecraft:soul_sand)
B(-7,16,0,minecraft:soul_sand)
B(-7,17,0,minecraft:soul_sand)
B(-7,18,0,minecraft:soul_sand)
B(-7,19,0,minecraft:soul_sand)
B(-7,20,0,minecraft:soul_sand)
B(-7,21,0,minecraft:soul_sand)
B(-7,22,0,minecraft:soul_sand)
B(-7,23,0,minecraft:soul_sand)
B(-7,24,0,minecraft:soul_sand)
B(-7,25,0,minecraft:soul_sand)
B(-7,26,0,minecraft:soul_sand)
B(-7,27,0,minecraft:soul_sand)
B(-7,28,0,minecraft:soul_sand)
B(-7,29,0,minecraft:soul_sand)
B(-7,30,0,minecraft:soul_sand)
B(-7,31,0,minecraft:soul_sand)
B(-7,32,0,minecraft:soul_sand)
B(-7,33,0,minecraft:soul_sand)
B(-7,0,1,minecraft:blackstone)
B(-7,1,1,minecraft:blackstone)
B(-7,2,1,minecraft:soul_sand)
B(-7,3,1,minecraft:soul_sand)
B(-7,4,1,minecraft:soul_sand)
B(-7,5,1,minecraft:soul_sand)
B(-7,6,1,minecraft:soul_sand)
B(-7,7,1,minecraft:soul_sand)
B(-7,8,1,minecraft:soul_sand)
B(-7,9,1,minecraft:soul_sand)
B(-7,10,1,minecraft:soul_sand)
B(-7,11,1,minecraft:soul_sand)
B(-7,12,1,minecraft:soul_sand)
B(-7,13,1,minecraft:soul_sand)
B(-7,14,1,minecraft:soul_sand)
B(-7,15,1,minecraft:soul_sand)
B(-7,16,1,minecraft:soul_sand)
B(-7,17,1,minecraft:soul_sand)
B(-7,18,1,minecraft:soul_sand)
B(-7,19,1,minecraft:soul_sand)
B(-7,20,1,minecraft:soul_sand)
B(-7,21,1,minecraft:soul_sand)
B(-7,22,1,minecraft:soul_sand)
B(-7,23,1,minecraft:soul_sand)
B(-7,24,1,minecraft:soul_sand)
B(-7,25,1,minecraft:soul_sand)
B(-7,26,1,minecraft:soul_sand)
B(-7,27,1,minecraft:soul_sand)
B(-7,28,1,minecraft:soul_sand)
B(-7,29,1,minecraft:soul_sand)
B(-7,0,2,minecraft:blackstone)
B(-7,1,2,minecraft:blackstone)
B(-7,2,2,minecraft:soul_sand)
B(-7,3,2,minecraft:soul_sand)
B(-7,4,2,minecraft:soul_sand)
B(-7,5,2,minecraft:soul_sand)
B(-7,6,2,minecraft:soul_sand)
B(-7,7,2,minecraft:soul_sand)
B(-7,8,2,minecraft:soul_sand)
B(-7,9,2,minecraft:soul_sand)
B(-7,10,2,minecraft:soul_sand)
B(-7,11,2,minecraft:soul_sand)
B(-7,12,2,minecraft:soul_sand)
B(-7,13,2,minecraft:soul_sand)
B(-7,14,2,minecraft:soul_sand)
B(-7,15,2,minecraft:soul_sand)
B(-7,16,2,minecraft:soul_sand)
B(-7,17,2,minecraft:soul_sand)
B(-7,18,2,minecraft:soul_sand)
B(-7,19,2,minecraft:soul_sand)
B(-7,20,2,minecraft:soul_sand)
B(-7,21,2,minecraft:soul_sand)
B(-7,22,2,minecraft:soul_sand)
B(-7,23,2,minecraft:soul_sand)
B(-7,0,3,minecraft:blackstone)
B(-7,1,3,minecraft:soul_sand)
B(-7,2,3,minecraft:soul_sand)
B(-7,3,3,minecraft:soul_sand)
B(-7,4,3,minecraft:soul_sand)
B(-7,5,3,minecraft:soul_sand)
B(-7,6,3,minecraft:soul_sand)
B(-7,0,4,minecraft:blackstone)
B(-7,1,4,minecraft:soul_sand)
B(-7,0,5,minecraft:soul_sand)
B(-7,0,6,minecraft:soul_sand)
B(-6,0,-7,minecraft:blackstone)
B(-6,1,-7,minecraft:blackstone)
B(-6,2,-7,minecraft:soul_sand)
B(-6,3,-7,minecraft:soul_sand)
B(-6,4,-7,minecraft:soul_sand)
B(-6,5,-7,minecraft:soul_sand)
B(-6,6,-7,minecraft:soul_sand)
B(-6,7,-7,minecraft:soul_sand)
B(-6,8,-7,minecraft:soul_sand)
B(-6,9,-7,minecraft:soul_sand)
B(-6,10,-7,minecraft:soul_sand)
B(-6,11,-7,minecraft:soul_sand)
B(-6,12,-7,minecraft:soul_sand)
B(-6,13,-7,minecraft:soul_sand)
B(-6,14,-7,minecraft:soul_sand)
B(-6,15,-7,minecraft:soul_sand)
B(-6,16,-7,minecraft:soul_sand)
B(-6,17,-7,minecraft:soul_sand)
B(-6,18,-7,minecraft:soul_sand)
B(-6,19,-7,minecraft:soul_sand)
B(-6,20,-7,minecraft:soul_sand)
B(-6,21,-7,minecraft:soul_sand)
B(-6,0,-6,minecraft:blackstone)
B(-6,1,-6,minecraft:blackstone)
B(-6,2,-6,minecraft:soul_sand)
B(-6,3,-6,minecraft:soul_sand)
B(-6,4,-6,minecraft:soul_sand)
B(-6,5,-6,minecraft:soul_sand)
B(-6,6,-6,minecraft:soul_sand)
B(-6,7,-6,minecraft:soul_sand)
B(-6,8,-6,minecraft:soul_sand)
B(-6,9,-6,minecraft:soul_sand)
B(-6,10,-6,minecraft:soul_sand)
B(-6,11,-6,minecraft:soul_sand)
B(-6,12,-6,minecraft:soul_sand)
B(-6,13,-6,minecraft:soul_sand)
B(-6,14,-6,minecraft:soul_sand)
B(-6,15,-6,minecraft:soul_sand)
B(-6,16,-6,minecraft:soul_sand)
B(-6,17,-6,minecraft:soul_sand)
B(-6,0,-5,minecraft:blackstone)
B(-6,1,-5,minecraft:blackstone)
B(-6,2,-5,minecraft:soul_sand)
B(-6,3,-5,minecraft:soul_sand)
B(-6,4,-5,minecraft:soul_sand)
B(-6,5,-5,minecraft:soul_sand)
B(-6,6,-5,minecraft:soul_sand)
B(-6,7,-5,minecraft:soul_sand)
B(-6,8,-5,minecraft:soul_sand)
B(-6,9,-5,minecraft:soul_sand)
B(-6,10,-5,minecraft:soul_sand)
B(-6,11,-5,minecraft:soul_sand)
B(-6,12,-5,minecraft:soul_sand)
B(-6,0,-4,minecraft:blackstone)
B(-6,1,-4,minecraft:blackstone)
B(-6,2,-4,minecraft:soul_sand)
B(-6,0,-3,minecraft:blackstone)
B(-6,1,-3,minecraft:blackstone)
B(-6,2,-3,minecraft:soul_sand)
B(-6,3,-3,minecraft:soul_sand)
B(-6,4,-3,minecraft:soul_sand)
B(-6,5,-3,minecraft:soul_sand)
B(-6,6,-3,minecraft:soul_sand)
B(-6,7,-3,minecraft:soul_sand)
B(-6,8,-3,minecraft:soul_sand)
B(-6,9,-3,minecraft:soul_sand)
B(-6,10,-3,minecraft:soul_sand)
B(-6,11,-3,minecraft:soul_sand)
B(-6,0,-2,minecraft:blackstone)
B(-6,1,-2,minecraft:blackstone)
B(-6,2,-2,minecraft:soul_sand)
B(-6,3,-2,minecraft:soul_sand)
B(-6,4,-2,minecraft:soul_sand)
B(-6,5,-2,minecraft:soul_sand)
B(-6,6,-2,minecraft:soul_sand)
B(-6,7,-2,minecraft:soul_sand)
B(-6,8,-2,minecraft:soul_sand)
B(-6,9,-2,minecraft:soul_sand)
B(-6,10,-2,minecraft:soul_sand)
B(-6,11,-2,minecraft:soul_sand)
B(-6,12,-2,minecraft:soul_sand)
B(-6,13,-2,minecraft:soul_sand)
B(-6,14,-2,minecraft:soul_sand)
B(-6,15,-2,minecraft:soul_sand)
B(-6,16,-2,minecraft:soul_sand)
B(-6,17,-2,minecraft:soul_sand)
B(-6,18,-2,minecraft:soul_sand)
B(-6,19,-2,minecraft:soul_sand)
B(-6,20,-2,minecraft:soul_sand)
B(-6,0,-1,minecraft:blackstone)
B(-6,1,-1,minecraft:blackstone)
B(-6,2,-1,minecraft:soul_sand)
B(-6,3,-1,minecraft:soul_sand)
B(-6,4,-1,minecraft:soul_sand)
B(-6,5,-1,minecraft:soul_sand)
B(-6,6,-1,minecraft:soul_sand)
B(-6,7,-1,minecraft:soul_sand)
B(-6,8,-1,minecraft:soul_sand)
B(-6,9,-1,minecraft:soul_sand)
B(-6,10,-1,minecraft:soul_sand)
B(-6,11,-1,minecraft:soul_sand)
B(-6,12,-1,minecraft:soul_sand)
B(-6,13,-1,minecraft:soul_sand)
B(-6,14,-1,minecraft:soul_sand)
B(-6,15,-1,minecraft:soul_sand)
B(-6,16,-1,minecraft:soul_sand)
B(-6,17,-1,minecraft:soul_sand)
B(-6,18,-1,minecraft:soul_sand)
B(-6,19,-1,minecraft:soul_sand)
B(-6,20,-1,minecraft:soul_sand)
B(-6,21,-1,minecraft:soul_sand)
B(-6,22,-1,minecraft:soul_sand)
B(-6,0,0,minecraft:blackstone)
B(-6,1,0,minecraft:blackstone)
B(-6,2,0,minecraft:soul_sand)
B(-6,3,0,minecraft:soul_sand)
B(-6,4,0,minecraft:soul_sand)
B(-6,5,0,minecraft:soul_sand)
B(-6,6,0,minecraft:soul_sand)
B(-6,7,0,minecraft:soul_sand)
B(-6,8,0,minecraft:soul_sand)
B(-6,9,0,minecraft:soul_sand)
B(-6,10,0,minecraft:soul_sand)
B(-6,11,0,minecraft:soul_sand)
B(-6,12,0,minecraft:soul_sand)
B(-6,13,0,minecraft:soul_sand)
B(-6,14,0,minecraft:soul_sand)
B(-6,15,0,minecraft:soul_sand)
B(-6,16,0,minecraft:soul_sand)
B(-6,17,0,minecraft:soul_sand)
B(-6,18,0,minecraft:soul_sand)
B(-6,19,0,minecraft:soul_sand)
B(-6,20,0,minecraft:soul_sand)
B(-6,21,0,minecraft:soul_sand)
B(-6,22,0,minecraft:soul_sand)
B(-6,0,1,minecraft:blackstone)
B(-6,1,1,minecraft:blackstone)
B(-6,2,1,minecraft:soul_sand)
B(-6,3,1,minecraft:soul_sand)
B(-6,4,1,minecraft:soul_sand)
B(-6,5,1,minecraft:soul_sand)
B(-6,6,1,minecraft:soul_sand)
B(-6,7,1,minecraft:soul_sand)
B(-6,8,1,minecraft:soul_sand)
B(-6,9,1,minecraft:soul_sand)
B(-6,10,1,minecraft:soul_sand)
B(-6,11,1,minecraft:soul_sand)
B(-6,12,1,minecraft:soul_sand)
B(-6,13,1,minecraft:soul_sand)
B(-6,14,1,minecraft:soul_sand)
B(-6,15,1,minecraft:soul_sand)
B(-6,0,2,minecraft:blackstone)
B(-6,1,2,minecraft:blackstone)
B(-6,2,2,minecraft:soul_sand)
B(-6,3,2,minecraft:soul_sand)
B(-6,4,2,minecraft:soul_sand)
B(-6,5,2,minecraft:soul_sand)
B(-6,0,3,minecraft:blackstone)
B(-6,1,3,minecraft:blackstone)
B(-6,2,3,minecraft:soul_sand)
B(-6,0,4,minecraft:blackstone)
B(-6,1,4,minecraft:blackstone)
B(-6,2,4,minecraft:soul_sand)
B(-6,0,5,minecraft:blackstone)
B(-6,1,5,minecraft:blackstone)
B(-6,2,5,minecraft:soul_sand)
B(-6,0,6,minecraft:soul_sand)
B(-5,0,-7,minecraft:blackstone)
B(-5,1,-7,minecraft:blackstone)
B(-5,2,-7,minecraft:soul_sand)
B(-5,3,-7,minecraft:soul_sand)
B(-5,4,-7,minecraft:soul_sand)
B(-5,5,-7,minecraft:soul_sand)
B(-5,6,-7,minecraft:soul_sand)
B(-5,7,-7,minecraft:soul_sand)
B(-5,8,-7,minecraft:soul_sand)
B(-5,9,-7,minecraft:soul_sand)
B(-5,10,-7,minecraft:soul_sand)
B(-5,11,-7,minecraft:soul_sand)
B(-5,12,-7,minecraft:soul_sand)
B(-5,0,-6,minecraft:blackstone)
B(-5,1,-6,minecraft:blackstone)
B(-5,2,-6,minecraft:soul_sand)
B(-5,3,-6,minecraft:soul_sand)
B(-5,4,-6,minecraft:soul_sand)
B(-5,5,-6,minecraft:soul_sand)
B(-5,6,-6,minecraft:soul_sand)
B(-5,7,-6,minecraft:soul_sand)
B(-5,8,-6,minecraft:soul_sand)
B(-5,0,-5,minecraft:blackstone)
B(-5,1,-5,minecraft:blackstone)
B(-5,2,-5,minecraft:soul_sand)
B(-5,0,-4,minecraft:blackstone)
B(-5,1,-4,minecraft:blackstone)
B(-5,2,-4,minecraft:soul_sand)
B(-5,0,-3,minecraft:blackstone)
B(-5,1,-3,minecraft:blackstone)
B(-5,2,-3,minecraft:soul_sand)
B(-5,0,-2,minecraft:blackstone)
B(-5,1,-2,minecraft:blackstone)
B(-5,2,-2,minecraft:soul_sand)
B(-5,0,-1,minecraft:blackstone)
B(-5,1,-1,minecraft:blackstone)
B(-5,2,-1,minecraft:soul_sand)
B(-5,0,0,minecraft:blackstone)
B(-5,1,0,minecraft:blackstone)
B(-5,2,0,minecraft:soul_sand)
B(-5,0,1,minecraft:blackstone)
B(-5,1,1,minecraft:blackstone)
B(-5,2,1,minecraft:soul_sand)
B(-5,0,2,minecraft:blackstone)
B(-5,1,2,minecraft:blackstone)
B(-5,2,2,minecraft:soul_sand)
B(-5,0,3,minecraft:blackstone)
B(-5,1,3,minecraft:blackstone)
B(-5,2,3,minecraft:soul_sand)
B(-5,0,4,minecraft:blackstone)
B(-5,1,4,minecraft:blackstone)
B(-5,2,4,minecraft:soul_sand)
B(-5,0,5,minecraft:blackstone)
B(-5,1,5,minecraft:blackstone)
B(-5,2,5,minecraft:soul_sand)
B(-5,0,6,minecraft:blackstone)
B(-5,1,6,minecraft:soul_sand)
B(-5,0,7,minecraft:soul_sand)
B(-4,0,-7,minecraft:blackstone)
B(-4,1,-7,minecraft:blackstone)
B(-4,2,-7,minecraft:soul_sand)
B(-4,0,-6,minecraft:blackstone)
B(-4,1,-6,minecraft:blackstone)
B(-4,2,-6,minecraft:soul_sand)
B(-4,0,-5,minecraft:blackstone)
B(-4,1,-5,minecraft:blackstone)
B(-4,2,-5,minecraft:soul_sand)
B(-4,0,-4,minecraft:blackstone)
B(-4,1,-4,minecraft:blackstone)
B(-4,2,-4,minecraft:soul_sand)
B(-4,0,-3,minecraft:blackstone)
B(-4,1,-3,minecraft:blackstone)
B(-4,2,-3,minecraft:soul_sand)
B(-4,0,-2,minecraft:blackstone)
B(-4,1,-2,minecraft:blackstone)
B(-4,2,-2,minecraft:soul_sand)
B(-4,0,-1,minecraft:blackstone)
B(-4,1,-1,minecraft:blackstone)
B(-4,2,-1,minecraft:soul_sand)
B(-4,0,0,minecraft:blackstone)
B(-4,1,0,minecraft:blackstone)
B(-4,2,0,minecraft:soul_sand)
B(-4,0,1,minecraft:blackstone)
B(-4,1,1,minecraft:blackstone)
B(-4,2,1,minecraft:soul_sand)
B(-4,0,2,minecraft:blackstone)
B(-4,1,2,minecraft:blackstone)
B(-4,2,2,minecraft:soul_sand)
B(-4,0,3,minecraft:blackstone)
B(-4,1,3,minecraft:blackstone)
B(-4,2,3,minecraft:soul_sand)
B(-4,0,4,minecraft:blackstone)
B(-4,1,4,minecraft:blackstone)
B(-4,2,4,minecraft:soul_sand)
B(-4,0,5,minecraft:blackstone)
B(-4,1,5,minecraft:blackstone)
B(-4,2,5,minecraft:soul_sand)
B(-4,0,6,minecraft:blackstone)
B(-4,1,6,minecraft:blackstone)
B(-4,2,6,minecraft:soul_sand)
B(-4,0,7,minecraft:soul_sand)
B(-3,0,-7,minecraft:blackstone)
B(-3,1,-7,minecraft:blackstone)
B(-3,2,-7,minecraft:soul_sand)
B(-3,0,-6,minecraft:blackstone)
B(-3,1,-6,minecraft:blackstone)
B(-3,2,-6,minecraft:soul_sand)
B(-3,0,-5,minecraft:blackstone)
B(-3,1,-5,minecraft:blackstone)
B(-3,2,-5,minecraft:soul_sand)
B(-3,0,-4,minecraft:blackstone)
B(-3,1,-4,minecraft:blackstone)
B(-3,2,-4,minecraft:soul_sand)
B(-3,0,-3,minecraft:blackstone)
B(-3,1,-3,minecraft:blackstone)
B(-3,2,-3,minecraft:soul_sand)
B(-3,0,-2,minecraft:blackstone)
B(-3,1,-2,minecraft:blackstone)
B(-3,2,-2,minecraft:soul_sand)
B(-3,0,-1,minecraft:blackstone)
B(-3,1,-1,minecraft:blackstone)
B(-3,2,-1,minecraft:soul_sand)
B(-3,0,0,minecraft:blackstone)
B(-3,1,0,minecraft:blackstone)
B(-3,2,0,minecraft:soul_sand)
B(-3,0,1,minecraft:blackstone)
B(-3,1,1,minecraft:blackstone)
B(-3,2,1,minecraft:soul_sand)
B(-3,0,2,minecraft:blackstone)
B(-3,1,2,minecraft:blackstone)
B(-3,2,2,minecraft:soul_sand)
B(-3,0,3,minecraft:blackstone)
B(-3,1,3,minecraft:blackstone)
B(-3,2,3,minecraft:soul_sand)
B(-3,0,4,minecraft:blackstone)
B(-3,1,4,minecraft:blackstone)
B(-3,2,4,minecraft:soul_sand)
B(-3,0,5,minecraft:blackstone)
B(-3,1,5,minecraft:blackstone)
B(-3,2,5,minecraft:soul_sand)
B(-3,0,6,minecraft:blackstone)
B(-3,1,6,minecraft:blackstone)
B(-3,2,6,minecraft:soul_sand)
B(-3,0,7,minecraft:soul_sand)
B(-2,0,-7,minecraft:blackstone)
B(-2,1,-7,minecraft:blackstone)
B(-2,2,-7,minecraft:soul_sand)
B(-2,0,-6,minecraft:blackstone)
B(-2,1,-6,minecraft:blackstone)
B(-2,2,-6,minecraft:soul_sand)
B(-2,0,-5,minecraft:blackstone)
B(-2,1,-5,minecraft:blackstone)
B(-2,2,-5,minecraft:soul_sand)
B(-2,0,-4,minecraft:blackstone)
B(-2,1,-4,minecraft:blackstone)
B(-2,2,-4,minecraft:soul_sand)
B(-2,0,-3,minecraft:blackstone)
B(-2,1,-3,minecraft:blackstone)
B(-2,2,-3,minecraft:soul_sand)
B(-2,0,-2,minecraft:blackstone)
B(-2,1,-2,minecraft:blackstone)
B(-2,2,-2,minecraft:soul_sand)
B(-2,0,-1,minecraft:blackstone)
B(-2,1,-1,minecraft:blackstone)
B(-2,2,-1,minecraft:soul_sand)
B(-2,0,0,minecraft:blackstone)
B(-2,1,0,minecraft:blackstone)
B(-2,2,0,minecraft:soul_sand)
B(-2,0,1,minecraft:blackstone)
B(-2,1,1,minecraft:blackstone)
B(-2,2,1,minecraft:soul_sand)
B(-2,0,2,minecraft:blackstone)
B(-2,1,2,minecraft:blackstone)
B(-2,2,2,minecraft:soul_sand)
B(-2,0,3,minecraft:blackstone)
B(-2,1,3,minecraft:blackstone)
B(-2,2,3,minecraft:soul_sand)
B(-2,0,4,minecraft:blackstone)
B(-2,1,4,minecraft:blackstone)
B(-2,2,4,minecraft:soul_sand)
B(-2,0,5,minecraft:blackstone)
B(-2,1,5,minecraft:blackstone)
B(-2,2,5,minecraft:soul_sand)
B(-2,0,6,minecraft:blackstone)
B(-2,1,6,minecraft:blackstone)
B(-2,2,6,minecraft:soul_sand)
B(-2,0,7,minecraft:soul_sand)
B(-1,0,-7,minecraft:blackstone)
B(-1,1,-7,minecraft:blackstone)
B(-1,2,-7,minecraft:soul_sand)
B(-1,0,-6,minecraft:blackstone)
B(-1,1,-6,minecraft:blackstone)
B(-1,2,-6,minecraft:soul_sand)
B(-1,0,-5,minecraft:blackstone)
B(-1,1,-5,minecraft:blackstone)
B(-1,2,-5,minecraft:soul_sand)
B(-1,0,-4,minecraft:blackstone)
B(-1,1,-4,minecraft:blackstone)
B(-1,2,-4,minecraft:soul_sand)
B(-1,0,-3,minecraft:blackstone)
B(-1,1,-3,minecraft:blackstone)
B(-1,2,-3,minecraft:soul_sand)
B(-1,0,-2,minecraft:blackstone)
B(-1,1,-2,minecraft:blackstone)
B(-1,2,-2,minecraft:soul_sand)
B(-1,0,-1,minecraft:blackstone)
B(-1,1,-1,minecraft:blackstone)
B(-1,2,-1,minecraft:soul_sand)
B(-1,0,0,minecraft:blackstone)
B(-1,1,0,minecraft:blackstone)
B(-1,2,0,minecraft:soul_sand)
B(-1,0,1,minecraft:blackstone)
B(-1,1,1,minecraft:blackstone)
B(-1,2,1,minecraft:soul_sand)
B(-1,0,2,minecraft:blackstone)
B(-1,1,2,minecraft:blackstone)
B(-1,2,2,minecraft:soul_sand)
B(-1,0,3,minecraft:blackstone)
B(-1,1,3,minecraft:blackstone)
B(-1,2,3,minecraft:soul_sand)
B(-1,0,4,minecraft:blackstone)
B(-1,1,4,minecraft:blackstone)
B(-1,2,4,minecraft:soul_sand)
B(-1,0,5,minecraft:blackstone)
B(-1,1,5,minecraft:blackstone)
B(-1,2,5,minecraft:soul_sand)
B(-1,0,6,minecraft:blackstone)
B(-1,1,6,minecraft:soul_sand)
B(-1,0,7,minecraft:soul_sand)
B(0,0,-7,minecraft:blackstone)
B(0,1,-7,minecraft:blackstone)
B(0,2,-7,minecraft:soul_sand)
B(0,0,-6,minecraft:blackstone)
B(0,1,-6,minecraft:blackstone)
B(0,2,-6,minecraft:soul_sand)
B(0,0,-5,minecraft:blackstone)
B(0,1,-5,minecraft:blackstone)
B(0,2,-5,minecraft:soul_sand)
B(0,0,-4,minecraft:blackstone)
B(0,1,-4,minecraft:blackstone)
B(0,2,-4,minecraft:soul_sand)
B(0,0,-3,minecraft:blackstone)
B(0,1,-3,minecraft:blackstone)
B(0,2,-3,minecraft:soul_sand)
B(0,0,-2,minecraft:blackstone)
B(0,1,-2,minecraft:blackstone)
B(0,2,-2,minecraft:soul_sand)
B(0,0,-1,minecraft:blackstone)
B(0,1,-1,minecraft:blackstone)
B(0,2,-1,minecraft:soul_sand)
B(0,0,0,minecraft:blackstone)
B(0,1,0,minecraft:blackstone)
B(0,2,0,minecraft:soul_sand)
B(0,0,1,minecraft:blackstone)
B(0,1,1,minecraft:blackstone)
B(0,2,1,minecraft:soul_sand)
B(0,0,2,minecraft:blackstone)
B(0,1,2,minecraft:blackstone)
B(0,2,2,minecraft:soul_sand)
B(0,0,3,minecraft:blackstone)
B(0,1,3,minecraft:blackstone)
B(0,2,3,minecraft:soul_sand)
B(0,0,4,minecraft:blackstone)
B(0,1,4,minecraft:blackstone)
B(0,2,4,minecraft:soul_sand)
B(0,0,5,minecraft:blackstone)
B(0,1,5,minecraft:blackstone)
B(0,2,5,minecraft:soul_sand)
B(0,0,6,minecraft:blackstone)
B(0,1,6,minecraft:soul_sand)
B(1,0,-7,minecraft:blackstone)
B(1,1,-7,minecraft:blackstone)
B(1,2,-7,minecraft:soul_sand)
B(1,0,-6,minecraft:blackstone)
B(1,1,-6,minecraft:blackstone)
B(1,2,-6,minecraft:soul_sand)
B(1,0,-5,minecraft:blackstone)
B(1,1,-5,minecraft:blackstone)
B(1,2,-5,minecraft:soul_sand)
B(1,0,-4,minecraft:blackstone)
B(1,1,-4,minecraft:blackstone)
B(1,2,-4,minecraft:soul_sand)
B(1,0,-3,minecraft:blackstone)
B(1,1,-3,minecraft:blackstone)
B(1,2,-3,minecraft:soul_sand)
B(1,0,-2,minecraft:blackstone)
B(1,1,-2,minecraft:blackstone)
B(1,2,-2,minecraft:soul_sand)
B(1,0,-1,minecraft:blackstone)
B(1,1,-1,minecraft:blackstone)
B(1,2,-1,minecraft:soul_sand)
B(1,0,0,minecraft:blackstone)
B(1,1,0,minecraft:blackstone)
B(1,2,0,minecraft:soul_sand)
B(1,0,1,minecraft:blackstone)
B(1,1,1,minecraft:blackstone)
B(1,2,1,minecraft:soul_sand)
B(1,0,2,minecraft:blackstone)
B(1,1,2,minecraft:blackstone)
B(1,2,2,minecraft:soul_sand)
B(1,0,3,minecraft:blackstone)
B(1,1,3,minecraft:blackstone)
B(1,2,3,minecraft:soul_sand)
B(1,0,4,minecraft:blackstone)
B(1,1,4,minecraft:blackstone)
B(1,2,4,minecraft:soul_sand)
B(1,0,5,minecraft:blackstone)
B(1,1,5,minecraft:blackstone)
B(1,2,5,minecraft:soul_sand)
B(1,0,6,minecraft:blackstone)
B(1,1,6,minecraft:soul_sand)
B(1,0,7,minecraft:soul_sand)
B(2,0,-7,minecraft:blackstone)
B(2,1,-7,minecraft:blackstone)
B(2,2,-7,minecraft:soul_sand)
B(2,0,-6,minecraft:blackstone)
B(2,1,-6,minecraft:blackstone)
B(2,2,-6,minecraft:soul_sand)
B(2,0,-5,minecraft:blackstone)
B(2,1,-5,minecraft:blackstone)
B(2,2,-5,minecraft:soul_sand)
B(2,0,-4,minecraft:blackstone)
B(2,1,-4,minecraft:blackstone)
B(2,2,-4,minecraft:soul_sand)
B(2,0,-3,minecraft:blackstone)
B(2,1,-3,minecraft:blackstone)
B(2,2,-3,minecraft:soul_sand)
B(2,0,-2,minecraft:blackstone)
B(2,1,-2,minecraft:blackstone)
B(2,2,-2,minecraft:soul_sand)
B(2,0,-1,minecraft:blackstone)
B(2,1,-1,minecraft:blackstone)
B(2,2,-1,minecraft:soul_sand)
B(2,0,0,minecraft:blackstone)
B(2,1,0,minecraft:blackstone)
B(2,2,0,minecraft:soul_sand)
B(2,0,1,minecraft:blackstone)
B(2,1,1,minecraft:blackstone)
B(2,2,1,minecraft:soul_sand)
B(2,0,2,minecraft:blackstone)
B(2,1,2,minecraft:blackstone)
B(2,2,2,minecraft:soul_sand)
B(2,0,3,minecraft:blackstone)
B(2,1,3,minecraft:blackstone)
B(2,2,3,minecraft:soul_sand)
B(2,0,4,minecraft:blackstone)
B(2,1,4,minecraft:blackstone)
B(2,2,4,minecraft:soul_sand)
B(2,0,5,minecraft:blackstone)
B(2,1,5,minecraft:blackstone)
B(2,2,5,minecraft:soul_sand)
B(2,0,6,minecraft:blackstone)
B(2,1,6,minecraft:soul_sand)
B(2,0,7,minecraft:soul_sand)
B(3,0,-7,minecraft:blackstone)
B(3,1,-7,minecraft:blackstone)
B(3,2,-7,minecraft:soul_sand)
B(3,0,-6,minecraft:blackstone)
B(3,1,-6,minecraft:blackstone)
B(3,2,-6,minecraft:soul_sand)
B(3,0,-5,minecraft:blackstone)
B(3,1,-5,minecraft:blackstone)
B(3,2,-5,minecraft:soul_sand)
B(3,0,-4,minecraft:blackstone)
B(3,1,-4,minecraft:blackstone)
B(3,2,-4,minecraft:soul_sand)
B(3,0,-3,minecraft:blackstone)
B(3,1,-3,minecraft:blackstone)
B(3,2,-3,minecraft:soul_sand)
B(3,0,-2,minecraft:blackstone)
B(3,1,-2,minecraft:blackstone)
B(3,2,-2,minecraft:soul_sand)
B(3,0,-1,minecraft:blackstone)
B(3,1,-1,minecraft:blackstone)
B(3,2,-1,minecraft:soul_sand)
B(3,0,0,minecraft:blackstone)
B(3,1,0,minecraft:blackstone)
B(3,2,0,minecraft:soul_sand)
B(3,0,1,minecraft:blackstone)
B(3,1,1,minecraft:blackstone)
B(3,2,1,minecraft:soul_sand)
B(3,0,2,minecraft:blackstone)
B(3,1,2,minecraft:blackstone)
B(3,2,2,minecraft:soul_sand)
B(3,0,3,minecraft:blackstone)
B(3,1,3,minecraft:blackstone)
B(3,2,3,minecraft:soul_sand)
B(3,0,4,minecraft:blackstone)
B(3,1,4,minecraft:blackstone)
B(3,2,4,minecraft:soul_sand)
B(3,0,5,minecraft:blackstone)
B(3,1,5,minecraft:soul_sand)
B(3,0,6,minecraft:blackstone)
B(3,1,6,minecraft:soul_sand)
B(3,0,7,minecraft:soul_sand)
B(3,0,8,minecraft:soul_sand)
B(4,0,-7,minecraft:blackstone)
B(4,1,-7,minecraft:blackstone)
B(4,2,-7,minecraft:soul_sand)
B(4,0,-6,minecraft:blackstone)
B(4,1,-6,minecraft:blackstone)
B(4,2,-6,minecraft:soul_sand)
B(4,0,-5,minecraft:blackstone)
B(4,1,-5,minecraft:blackstone)
B(4,2,-5,minecraft:soul_sand)
B(4,0,-4,minecraft:blackstone)
B(4,1,-4,minecraft:blackstone)
B(4,2,-4,minecraft:soul_sand)
B(4,0,-3,minecraft:blackstone)
B(4,1,-3,minecraft:blackstone)
B(4,2,-3,minecraft:soul_sand)
B(4,0,-2,minecraft:blackstone)
B(4,1,-2,minecraft:blackstone)
B(4,2,-2,minecraft:soul_sand)
B(4,0,-1,minecraft:blackstone)
B(4,1,-1,minecraft:blackstone)
B(4,2,-1,minecraft:soul_sand)
B(4,0,0,minecraft:blackstone)
B(4,1,0,minecraft:blackstone)
B(4,2,0,minecraft:soul_sand)
B(4,0,1,minecraft:blackstone)
B(4,1,1,minecraft:blackstone)
B(4,2,1,minecraft:soul_sand)
B(4,0,2,minecraft:blackstone)
B(4,1,2,minecraft:blackstone)
B(4,2,2,minecraft:soul_sand)
B(4,0,3,minecraft:blackstone)
B(4,1,3,minecraft:soul_sand)
B(4,0,4,minecraft:blackstone)
B(4,1,4,minecraft:soul_sand)
B(4,0,5,minecraft:blackstone)
B(4,1,5,minecraft:soul_sand)
B(4,0,6,minecraft:soul_sand)
B(4,0,7,minecraft:soul_sand)
B(4,0,8,minecraft:soul_sand)

#######################################################################
# +-----------------------------------------------------------------+ #
# |                             Branches                            | #
# +-----------------------------------------------------------------+ #
#######################################################################


#######################################################################
# +-----------------------------------------------------------------+ #
# |                             Entities                            | #
# +-----------------------------------------------------------------+ #
#######################################################################

