#######################################################################
# +-----------------------------------------------------------------+ #
# |                            BO3 object                           | #
# +-----------------------------------------------------------------+ #
#######################################################################

Author: Bo3 BulkEdit

Description: Converted Schematic - Modified by Bo3BulkEdit

Version: 3

SettingsMode: WriteDisable

#######################################################################
# +-----------------------------------------------------------------+ #
# |                          Main settings                          | #
# +-----------------------------------------------------------------+ #
#######################################################################

IsOTGPlus: true
Tree: true
Frequency: 10
Rarity: 100
RotateRandomly: true
SpawnHeight: randomY
SpawnHeightOffset: 0
SpawnHeightVariance: 0
MaxBranchDepth: 10
ExcludedBiomes: All

##############################
# Height Limits for the BO3. #
##############################

MinHeight: 50
MaxHeight: 65

#######################################################################
# +-----------------------------------------------------------------+ #
# |                      Source block settings                      | #
# +-----------------------------------------------------------------+ #
#######################################################################

SourceBlocks: AIR
MaxPercentageOutsideSourceBlock: 100
OutsideSourceBlock: placeAnyway

#######################################################################
# +-----------------------------------------------------------------+ #
# |                               OTG+                              | #
# +-----------------------------------------------------------------+ #
#######################################################################

RemoveAir: true
ReplaceBelow: OBSIDIAN
ReplaceWithBiomeBlocks: false
ReplaceWithGroundBlock: OBSIDIAN
ReplaceWithSurfaceBlock: OBSIDIAN
ReplaceWithStoneBlock: OBSIDIAN
SmoothRadius: 30
SmoothingSurfaceBlock: OBSIDIAN
SmoothingGroundBlock: OBSIDIAN

#######################################################################
# +-----------------------------------------------------------------+ #
# |                              Blocks                             | #
# +-----------------------------------------------------------------+ #
#######################################################################

RB(0,0,5,minecraft:crying_obsidian,20,minecraft:obsidian,100)
RB(1,0,5,minecraft:crying_obsidian,20,minecraft:obsidian,100)
RB(2,0,5,minecraft:crying_obsidian,20,minecraft:obsidian,100)
RB(3,0,5,minecraft:crying_obsidian,20,minecraft:obsidian,100)
RB(0,0,6,minecraft:crying_obsidian,20,minecraft:obsidian,100)
RB(1,0,6,minecraft:crying_obsidian,20,minecraft:obsidian,100)
RB(2,0,6,minecraft:crying_obsidian,20,minecraft:obsidian,100)
RB(3,0,6,minecraft:crying_obsidian,20,minecraft:obsidian,100)
RB(4,0,6,minecraft:crying_obsidian,20,minecraft:obsidian,100)
RB(7,0,6,minecraft:crying_obsidian,20,minecraft:obsidian,100)
RB(8,0,6,minecraft:crying_obsidian,20,minecraft:obsidian,100)
RB(9,0,6,minecraft:crying_obsidian,20,minecraft:obsidian,100)
RB(10,0,6,minecraft:crying_obsidian,20,minecraft:obsidian,100)
RB(11,0,6,minecraft:crying_obsidian,20,minecraft:obsidian,100)
RB(12,0,6,minecraft:crying_obsidian,20,minecraft:obsidian,100)
RB(13,0,6,minecraft:crying_obsidian,20,minecraft:obsidian,100)
RB(14,0,6,minecraft:crying_obsidian,20,minecraft:obsidian,100)
RB(0,0,7,minecraft:crying_obsidian,20,minecraft:obsidian,100)
RB(1,0,7,minecraft:crying_obsidian,20,minecraft:obsidian,100)
RB(2,0,7,minecraft:crying_obsidian,20,minecraft:obsidian,100)
RB(3,0,7,minecraft:crying_obsidian,20,minecraft:obsidian,100)
RB(4,0,7,minecraft:crying_obsidian,20,minecraft:obsidian,100)
RB(5,0,7,minecraft:crying_obsidian,20,minecraft:obsidian,100)
RB(6,0,7,minecraft:crying_obsidian,20,minecraft:obsidian,100)
RB(7,0,7,minecraft:crying_obsidian,20,minecraft:obsidian,100)
RB(8,0,7,minecraft:crying_obsidian,20,minecraft:obsidian,100)
RB(9,0,7,minecraft:crying_obsidian,20,minecraft:obsidian,100)
RB(10,0,7,minecraft:crying_obsidian,20,minecraft:obsidian,100)
RB(11,0,7,minecraft:crying_obsidian,20,minecraft:obsidian,100)
RB(12,0,7,minecraft:crying_obsidian,20,minecraft:obsidian,100)
RB(13,0,7,minecraft:crying_obsidian,20,minecraft:obsidian,100)
RB(14,0,7,minecraft:crying_obsidian,20,minecraft:obsidian,100)
RB(15,0,7,minecraft:crying_obsidian,20,minecraft:obsidian,100)
RB(0,0,8,minecraft:crying_obsidian,20,minecraft:obsidian,100)
RB(1,0,8,minecraft:crying_obsidian,20,minecraft:obsidian,100)
RB(2,0,8,minecraft:crying_obsidian,20,minecraft:obsidian,100)
RB(3,0,8,minecraft:crying_obsidian,20,minecraft:obsidian,100)
RB(4,0,8,minecraft:crying_obsidian,20,minecraft:obsidian,100)
RB(5,0,8,minecraft:crying_obsidian,20,minecraft:obsidian,100)
RB(6,0,8,minecraft:crying_obsidian,20,minecraft:obsidian,100)
RB(7,0,8,minecraft:crying_obsidian,20,minecraft:obsidian,100)
RB(8,0,8,minecraft:crying_obsidian,20,minecraft:obsidian,100)
RB(9,0,8,minecraft:crying_obsidian,20,minecraft:obsidian,100)
RB(10,0,8,minecraft:crying_obsidian,20,minecraft:obsidian,100)
RB(11,0,8,minecraft:crying_obsidian,20,minecraft:obsidian,100)
RB(12,0,8,minecraft:crying_obsidian,20,minecraft:obsidian,100)
RB(13,0,8,minecraft:crying_obsidian,20,minecraft:obsidian,100)
RB(14,0,8,minecraft:crying_obsidian,20,minecraft:obsidian,100)
RB(15,0,8,minecraft:crying_obsidian,20,minecraft:obsidian,100)
RB(0,0,9,minecraft:crying_obsidian,20,minecraft:obsidian,100)
RB(1,0,9,minecraft:crying_obsidian,20,minecraft:obsidian,100)
RB(2,0,9,minecraft:crying_obsidian,20,minecraft:obsidian,100)
RB(3,0,9,minecraft:crying_obsidian,20,minecraft:obsidian,100)
RB(4,0,9,minecraft:crying_obsidian,20,minecraft:obsidian,100)
RB(5,0,9,minecraft:crying_obsidian,20,minecraft:obsidian,100)
RB(6,0,9,minecraft:crying_obsidian,20,minecraft:obsidian,100)
RB(7,0,9,minecraft:crying_obsidian,20,minecraft:obsidian,100)
RB(8,0,9,minecraft:crying_obsidian,20,minecraft:obsidian,100)
RB(9,0,9,minecraft:crying_obsidian,20,minecraft:obsidian,100)
RB(10,0,9,minecraft:crying_obsidian,20,minecraft:obsidian,100)
RB(11,0,9,minecraft:crying_obsidian,20,minecraft:obsidian,100)
RB(12,0,9,minecraft:crying_obsidian,20,minecraft:obsidian,100)
RB(13,0,9,minecraft:crying_obsidian,20,minecraft:obsidian,100)
RB(14,0,9,minecraft:crying_obsidian,20,minecraft:obsidian,100)
RB(15,0,9,minecraft:crying_obsidian,20,minecraft:obsidian,100)
RB(0,0,10,minecraft:crying_obsidian,20,minecraft:obsidian,100)
RB(1,0,10,minecraft:crying_obsidian,20,minecraft:obsidian,100)
RB(2,0,10,minecraft:crying_obsidian,20,minecraft:obsidian,100)
RB(3,0,10,minecraft:crying_obsidian,20,minecraft:obsidian,100)
RB(4,0,10,minecraft:crying_obsidian,20,minecraft:obsidian,100)
RB(5,0,10,minecraft:crying_obsidian,20,minecraft:obsidian,100)
RB(6,0,10,minecraft:crying_obsidian,20,minecraft:obsidian,100)
RB(7,0,10,minecraft:crying_obsidian,20,minecraft:obsidian,100)
RB(8,0,10,minecraft:crying_obsidian,20,minecraft:obsidian,100)
RB(9,0,10,minecraft:crying_obsidian,20,minecraft:obsidian,100)
RB(10,0,10,minecraft:crying_obsidian,20,minecraft:obsidian,100)
RB(11,0,10,minecraft:crying_obsidian,20,minecraft:obsidian,100)
RB(12,0,10,minecraft:crying_obsidian,20,minecraft:obsidian,100)
RB(13,0,10,minecraft:crying_obsidian,20,minecraft:obsidian,100)
RB(14,0,10,minecraft:crying_obsidian,20,minecraft:obsidian,100)
RB(15,0,10,minecraft:crying_obsidian,20,minecraft:obsidian,100)
RB(0,0,11,minecraft:crying_obsidian,20,minecraft:obsidian,100)
RB(1,0,11,minecraft:crying_obsidian,20,minecraft:obsidian,100)
RB(2,0,11,minecraft:crying_obsidian,20,minecraft:obsidian,100)
RB(3,0,11,minecraft:crying_obsidian,20,minecraft:obsidian,100)
RB(4,0,11,minecraft:crying_obsidian,20,minecraft:obsidian,100)
RB(5,0,11,minecraft:crying_obsidian,20,minecraft:obsidian,100)
RB(6,0,11,minecraft:crying_obsidian,20,minecraft:obsidian,100)
RB(7,0,11,minecraft:crying_obsidian,20,minecraft:obsidian,100)
RB(8,0,11,minecraft:crying_obsidian,20,minecraft:obsidian,100)
RB(9,0,11,minecraft:crying_obsidian,20,minecraft:obsidian,100)
RB(10,0,11,minecraft:crying_obsidian,20,minecraft:obsidian,100)
RB(11,0,11,minecraft:crying_obsidian,20,minecraft:obsidian,100)
RB(12,0,11,minecraft:crying_obsidian,20,minecraft:obsidian,100)
RB(13,0,11,minecraft:crying_obsidian,20,minecraft:obsidian,100)
RB(14,0,11,minecraft:crying_obsidian,20,minecraft:obsidian,100)
RB(15,0,11,minecraft:crying_obsidian,20,minecraft:obsidian,100)
RB(0,0,12,minecraft:crying_obsidian,20,minecraft:obsidian,100)
RB(1,0,12,minecraft:crying_obsidian,20,minecraft:obsidian,100)
RB(2,0,12,minecraft:crying_obsidian,20,minecraft:obsidian,100)
RB(3,0,12,minecraft:crying_obsidian,20,minecraft:obsidian,100)
RB(4,0,12,minecraft:crying_obsidian,20,minecraft:obsidian,100)
RB(5,0,12,minecraft:crying_obsidian,20,minecraft:obsidian,100)
RB(6,0,12,minecraft:crying_obsidian,20,minecraft:obsidian,100)
RB(7,0,12,minecraft:crying_obsidian,20,minecraft:obsidian,100)
RB(8,0,12,minecraft:crying_obsidian,20,minecraft:obsidian,100)
RB(9,0,12,minecraft:crying_obsidian,20,minecraft:obsidian,100)
RB(10,0,12,minecraft:crying_obsidian,20,minecraft:obsidian,100)
RB(11,0,12,minecraft:crying_obsidian,20,minecraft:obsidian,100)
RB(12,0,12,minecraft:crying_obsidian,20,minecraft:obsidian,100)
RB(13,0,12,minecraft:crying_obsidian,20,minecraft:obsidian,100)
RB(14,0,12,minecraft:crying_obsidian,20,minecraft:obsidian,100)
RB(15,0,12,minecraft:crying_obsidian,20,minecraft:obsidian,100)
RB(0,0,13,minecraft:crying_obsidian,20,minecraft:obsidian,100)
RB(1,0,13,minecraft:crying_obsidian,20,minecraft:obsidian,100)
RB(2,0,13,minecraft:crying_obsidian,20,minecraft:obsidian,100)
RB(3,0,13,minecraft:crying_obsidian,20,minecraft:obsidian,100)
RB(4,0,13,minecraft:crying_obsidian,20,minecraft:obsidian,100)
RB(5,0,13,minecraft:crying_obsidian,20,minecraft:obsidian,100)
RB(6,0,13,minecraft:crying_obsidian,20,minecraft:obsidian,100)
RB(7,0,13,minecraft:crying_obsidian,20,minecraft:obsidian,100)
RB(8,0,13,minecraft:crying_obsidian,20,minecraft:obsidian,100)
RB(9,0,13,minecraft:crying_obsidian,20,minecraft:obsidian,100)
RB(10,0,13,minecraft:crying_obsidian,20,minecraft:obsidian,100)
RB(11,0,13,minecraft:crying_obsidian,20,minecraft:obsidian,100)
RB(12,0,13,minecraft:crying_obsidian,20,minecraft:obsidian,100)
RB(13,0,13,minecraft:crying_obsidian,20,minecraft:obsidian,100)
RB(14,0,13,minecraft:crying_obsidian,20,minecraft:obsidian,100)
RB(15,0,13,minecraft:crying_obsidian,20,minecraft:obsidian,100)
RB(0,0,14,minecraft:crying_obsidian,20,minecraft:obsidian,100)
RB(1,0,14,minecraft:crying_obsidian,20,minecraft:obsidian,100)
RB(2,0,14,minecraft:crying_obsidian,20,minecraft:obsidian,100)
RB(3,0,14,minecraft:crying_obsidian,20,minecraft:obsidian,100)
RB(4,0,14,minecraft:crying_obsidian,20,minecraft:obsidian,100)
RB(5,0,14,minecraft:crying_obsidian,20,minecraft:obsidian,100)
RB(6,0,14,minecraft:crying_obsidian,20,minecraft:obsidian,100)
RB(7,0,14,minecraft:crying_obsidian,20,minecraft:obsidian,100)
RB(8,0,14,minecraft:crying_obsidian,20,minecraft:obsidian,100)
RB(9,0,14,minecraft:crying_obsidian,20,minecraft:obsidian,100)
RB(10,0,14,minecraft:crying_obsidian,20,minecraft:obsidian,100)
RB(11,0,14,minecraft:crying_obsidian,20,minecraft:obsidian,100)
RB(12,0,14,minecraft:crying_obsidian,20,minecraft:obsidian,100)
RB(13,0,14,minecraft:crying_obsidian,20,minecraft:obsidian,100)
RB(14,0,14,minecraft:crying_obsidian,20,minecraft:obsidian,100)
RB(15,0,14,minecraft:crying_obsidian,20,minecraft:obsidian,100)
RB(0,0,15,minecraft:crying_obsidian,20,minecraft:obsidian,100)
RB(1,0,15,minecraft:crying_obsidian,20,minecraft:obsidian,100)
RB(2,0,15,minecraft:crying_obsidian,20,minecraft:obsidian,100)
RB(3,0,15,minecraft:crying_obsidian,20,minecraft:obsidian,100)
RB(4,0,15,minecraft:crying_obsidian,20,minecraft:obsidian,100)
RB(5,0,15,minecraft:crying_obsidian,20,minecraft:obsidian,100)
RB(6,0,15,minecraft:crying_obsidian,20,minecraft:obsidian,100)
RB(7,0,15,minecraft:crying_obsidian,20,minecraft:obsidian,100)
RB(8,0,15,minecraft:crying_obsidian,20,minecraft:obsidian,100)
RB(9,0,15,minecraft:crying_obsidian,20,minecraft:obsidian,100)
RB(10,0,15,minecraft:crying_obsidian,20,minecraft:obsidian,100)
RB(11,0,15,minecraft:crying_obsidian,20,minecraft:obsidian,100)
RB(12,0,15,minecraft:crying_obsidian,20,minecraft:obsidian,100)
RB(13,0,15,minecraft:crying_obsidian,20,minecraft:obsidian,100)
RB(14,0,15,minecraft:crying_obsidian,20,minecraft:obsidian,100)
RB(15,0,15,minecraft:crying_obsidian,20,minecraft:obsidian,100)
RB(0,1,5,minecraft:crying_obsidian,20,minecraft:obsidian,100)
RB(1,1,5,minecraft:crying_obsidian,20,minecraft:obsidian,100)
RB(2,1,5,minecraft:crying_obsidian,20,minecraft:obsidian,100)
RB(0,1,6,minecraft:crying_obsidian,20,minecraft:obsidian,100)
RB(1,1,6,minecraft:crying_obsidian,20,minecraft:obsidian,100)
RB(2,1,6,minecraft:crying_obsidian,20,minecraft:obsidian,100)
RB(3,1,6,minecraft:crying_obsidian,20,minecraft:obsidian,100)
RB(4,1,6,minecraft:crying_obsidian,20,minecraft:obsidian,100)
RB(8,1,6,minecraft:crying_obsidian,20,minecraft:obsidian,100)
RB(9,1,6,minecraft:crying_obsidian,20,minecraft:obsidian,100)
RB(10,1,6,minecraft:crying_obsidian,20,minecraft:obsidian,100)
RB(11,1,6,minecraft:crying_obsidian,20,minecraft:obsidian,100)
RB(0,1,7,minecraft:crying_obsidian,20,minecraft:obsidian,100)
RB(1,1,7,minecraft:crying_obsidian,20,minecraft:obsidian,100)
RB(2,1,7,minecraft:crying_obsidian,20,minecraft:obsidian,100)
RB(3,1,7,minecraft:crying_obsidian,20,minecraft:obsidian,100)
RB(4,1,7,minecraft:crying_obsidian,20,minecraft:obsidian,100)
RB(5,1,7,minecraft:crying_obsidian,20,minecraft:obsidian,100)
RB(6,1,7,minecraft:crying_obsidian,20,minecraft:obsidian,100)
RB(7,1,7,minecraft:crying_obsidian,20,minecraft:obsidian,100)
RB(8,1,7,minecraft:crying_obsidian,20,minecraft:obsidian,100)
RB(9,1,7,minecraft:crying_obsidian,20,minecraft:obsidian,100)
RB(10,1,7,minecraft:crying_obsidian,20,minecraft:obsidian,100)
RB(11,1,7,minecraft:crying_obsidian,20,minecraft:obsidian,100)
RB(12,1,7,minecraft:crying_obsidian,20,minecraft:obsidian,100)
RB(0,1,8,minecraft:crying_obsidian,20,minecraft:obsidian,100)
RB(1,1,8,minecraft:crying_obsidian,20,minecraft:obsidian,100)
RB(2,1,8,minecraft:crying_obsidian,20,minecraft:obsidian,100)
RB(3,1,8,minecraft:crying_obsidian,20,minecraft:obsidian,100)
RB(4,1,8,minecraft:crying_obsidian,20,minecraft:obsidian,100)
RB(5,1,8,minecraft:crying_obsidian,20,minecraft:obsidian,100)
RB(6,1,8,minecraft:crying_obsidian,20,minecraft:obsidian,100)
RB(7,1,8,minecraft:crying_obsidian,20,minecraft:obsidian,100)
RB(8,1,8,minecraft:crying_obsidian,20,minecraft:obsidian,100)
RB(9,1,8,minecraft:crying_obsidian,20,minecraft:obsidian,100)
RB(10,1,8,minecraft:crying_obsidian,20,minecraft:obsidian,100)
RB(11,1,8,minecraft:crying_obsidian,20,minecraft:obsidian,100)
RB(12,1,8,minecraft:crying_obsidian,20,minecraft:obsidian,100)
RB(13,1,8,minecraft:crying_obsidian,20,minecraft:obsidian,100)
RB(0,1,9,minecraft:crying_obsidian,20,minecraft:obsidian,100)
RB(1,1,9,minecraft:crying_obsidian,20,minecraft:obsidian,100)
RB(2,1,9,minecraft:crying_obsidian,20,minecraft:obsidian,100)
RB(3,1,9,minecraft:crying_obsidian,20,minecraft:obsidian,100)
RB(4,1,9,minecraft:crying_obsidian,20,minecraft:obsidian,100)
RB(5,1,9,minecraft:crying_obsidian,20,minecraft:obsidian,100)
RB(6,1,9,minecraft:crying_obsidian,20,minecraft:obsidian,100)
RB(7,1,9,minecraft:crying_obsidian,20,minecraft:obsidian,100)
RB(8,1,9,minecraft:crying_obsidian,20,minecraft:obsidian,100)
RB(9,1,9,minecraft:crying_obsidian,20,minecraft:obsidian,100)
RB(10,1,9,minecraft:crying_obsidian,20,minecraft:obsidian,100)
RB(11,1,9,minecraft:crying_obsidian,20,minecraft:obsidian,100)
RB(12,1,9,minecraft:crying_obsidian,20,minecraft:obsidian,100)
RB(13,1,9,minecraft:crying_obsidian,20,minecraft:obsidian,100)
RB(14,1,9,minecraft:crying_obsidian,20,minecraft:obsidian,100)
RB(15,1,9,minecraft:crying_obsidian,20,minecraft:obsidian,100)
RB(0,1,10,minecraft:crying_obsidian,20,minecraft:obsidian,100)
RB(1,1,10,minecraft:crying_obsidian,20,minecraft:obsidian,100)
RB(2,1,10,minecraft:crying_obsidian,20,minecraft:obsidian,100)
RB(3,1,10,minecraft:crying_obsidian,20,minecraft:obsidian,100)
RB(4,1,10,minecraft:crying_obsidian,20,minecraft:obsidian,100)
RB(5,1,10,minecraft:crying_obsidian,20,minecraft:obsidian,100)
RB(6,1,10,minecraft:crying_obsidian,20,minecraft:obsidian,100)
RB(7,1,10,minecraft:crying_obsidian,20,minecraft:obsidian,100)
RB(8,1,10,minecraft:crying_obsidian,20,minecraft:obsidian,100)
RB(9,1,10,minecraft:crying_obsidian,20,minecraft:obsidian,100)
RB(10,1,10,minecraft:crying_obsidian,20,minecraft:obsidian,100)
RB(11,1,10,minecraft:crying_obsidian,20,minecraft:obsidian,100)
RB(12,1,10,minecraft:crying_obsidian,20,minecraft:obsidian,100)
RB(13,1,10,minecraft:crying_obsidian,20,minecraft:obsidian,100)
RB(14,1,10,minecraft:crying_obsidian,20,minecraft:obsidian,100)
RB(15,1,10,minecraft:crying_obsidian,20,minecraft:obsidian,100)
RB(0,1,11,minecraft:crying_obsidian,20,minecraft:obsidian,100)
RB(1,1,11,minecraft:crying_obsidian,20,minecraft:obsidian,100)
RB(2,1,11,minecraft:crying_obsidian,20,minecraft:obsidian,100)
RB(3,1,11,minecraft:crying_obsidian,20,minecraft:obsidian,100)
RB(4,1,11,minecraft:crying_obsidian,20,minecraft:obsidian,100)
RB(5,1,11,minecraft:crying_obsidian,20,minecraft:obsidian,100)
RB(6,1,11,minecraft:crying_obsidian,20,minecraft:obsidian,100)
RB(7,1,11,minecraft:crying_obsidian,20,minecraft:obsidian,100)
RB(8,1,11,minecraft:crying_obsidian,20,minecraft:obsidian,100)
RB(9,1,11,minecraft:crying_obsidian,20,minecraft:obsidian,100)
RB(10,1,11,minecraft:crying_obsidian,20,minecraft:obsidian,100)
RB(11,1,11,minecraft:crying_obsidian,20,minecraft:obsidian,100)
RB(12,1,11,minecraft:crying_obsidian,20,minecraft:obsidian,100)
RB(13,1,11,minecraft:crying_obsidian,20,minecraft:obsidian,100)
RB(14,1,11,minecraft:crying_obsidian,20,minecraft:obsidian,100)
RB(15,1,11,minecraft:crying_obsidian,20,minecraft:obsidian,100)
RB(0,1,12,minecraft:crying_obsidian,20,minecraft:obsidian,100)
RB(1,1,12,minecraft:crying_obsidian,20,minecraft:obsidian,100)
RB(2,1,12,minecraft:crying_obsidian,20,minecraft:obsidian,100)
RB(3,1,12,minecraft:crying_obsidian,20,minecraft:obsidian,100)
RB(4,1,12,minecraft:crying_obsidian,20,minecraft:obsidian,100)
RB(5,1,12,minecraft:crying_obsidian,20,minecraft:obsidian,100)
RB(6,1,12,minecraft:crying_obsidian,20,minecraft:obsidian,100)
RB(7,1,12,minecraft:crying_obsidian,20,minecraft:obsidian,100)
RB(8,1,12,minecraft:crying_obsidian,20,minecraft:obsidian,100)
RB(9,1,12,minecraft:crying_obsidian,20,minecraft:obsidian,100)
RB(10,1,12,minecraft:crying_obsidian,20,minecraft:obsidian,100)
RB(11,1,12,minecraft:crying_obsidian,20,minecraft:obsidian,100)
RB(12,1,12,minecraft:crying_obsidian,20,minecraft:obsidian,100)
RB(13,1,12,minecraft:crying_obsidian,20,minecraft:obsidian,100)
RB(14,1,12,minecraft:crying_obsidian,20,minecraft:obsidian,100)
RB(15,1,12,minecraft:crying_obsidian,20,minecraft:obsidian,100)
RB(0,1,13,minecraft:crying_obsidian,20,minecraft:obsidian,100)
RB(1,1,13,minecraft:crying_obsidian,20,minecraft:obsidian,100)
RB(2,1,13,minecraft:crying_obsidian,20,minecraft:obsidian,100)
RB(3,1,13,minecraft:crying_obsidian,20,minecraft:obsidian,100)
RB(4,1,13,minecraft:crying_obsidian,20,minecraft:obsidian,100)
RB(5,1,13,minecraft:crying_obsidian,20,minecraft:obsidian,100)
RB(6,1,13,minecraft:crying_obsidian,20,minecraft:obsidian,100)
RB(7,1,13,minecraft:crying_obsidian,20,minecraft:obsidian,100)
RB(8,1,13,minecraft:crying_obsidian,20,minecraft:obsidian,100)
RB(9,1,13,minecraft:crying_obsidian,20,minecraft:obsidian,100)
RB(10,1,13,minecraft:crying_obsidian,20,minecraft:obsidian,100)
RB(11,1,13,minecraft:crying_obsidian,20,minecraft:obsidian,100)
RB(12,1,13,minecraft:crying_obsidian,20,minecraft:obsidian,100)
RB(13,1,13,minecraft:crying_obsidian,20,minecraft:obsidian,100)
RB(14,1,13,minecraft:crying_obsidian,20,minecraft:obsidian,100)
RB(15,1,13,minecraft:crying_obsidian,20,minecraft:obsidian,100)
RB(0,1,14,minecraft:crying_obsidian,20,minecraft:obsidian,100)
RB(1,1,14,minecraft:crying_obsidian,20,minecraft:obsidian,100)
RB(2,1,14,minecraft:crying_obsidian,20,minecraft:obsidian,100)
RB(3,1,14,minecraft:crying_obsidian,20,minecraft:obsidian,100)
RB(4,1,14,minecraft:crying_obsidian,20,minecraft:obsidian,100)
RB(5,1,14,minecraft:crying_obsidian,20,minecraft:obsidian,100)
RB(6,1,14,minecraft:crying_obsidian,20,minecraft:obsidian,100)
RB(7,1,14,minecraft:crying_obsidian,20,minecraft:obsidian,100)
RB(8,1,14,minecraft:crying_obsidian,20,minecraft:obsidian,100)
RB(9,1,14,minecraft:crying_obsidian,20,minecraft:obsidian,100)
RB(10,1,14,minecraft:crying_obsidian,20,minecraft:obsidian,100)
RB(11,1,14,minecraft:crying_obsidian,20,minecraft:obsidian,100)
RB(12,1,14,minecraft:crying_obsidian,20,minecraft:obsidian,100)
RB(13,1,14,minecraft:crying_obsidian,20,minecraft:obsidian,100)
RB(14,1,14,minecraft:crying_obsidian,20,minecraft:obsidian,100)
RB(15,1,14,minecraft:crying_obsidian,20,minecraft:obsidian,100)
RB(0,1,15,minecraft:crying_obsidian,20,minecraft:obsidian,100)
RB(1,1,15,minecraft:crying_obsidian,20,minecraft:obsidian,100)
RB(2,1,15,minecraft:crying_obsidian,20,minecraft:obsidian,100)
RB(3,1,15,minecraft:crying_obsidian,20,minecraft:obsidian,100)
RB(4,1,15,minecraft:crying_obsidian,20,minecraft:obsidian,100)
RB(5,1,15,minecraft:crying_obsidian,20,minecraft:obsidian,100)
RB(6,1,15,minecraft:crying_obsidian,20,minecraft:obsidian,100)
RB(7,1,15,minecraft:crying_obsidian,20,minecraft:obsidian,100)
RB(8,1,15,minecraft:crying_obsidian,20,minecraft:obsidian,100)
RB(9,1,15,minecraft:crying_obsidian,20,minecraft:obsidian,100)
RB(10,1,15,minecraft:crying_obsidian,20,minecraft:obsidian,100)
RB(11,1,15,minecraft:crying_obsidian,20,minecraft:obsidian,100)
RB(12,1,15,minecraft:crying_obsidian,20,minecraft:obsidian,100)
RB(13,1,15,minecraft:crying_obsidian,20,minecraft:obsidian,100)
RB(14,1,15,minecraft:crying_obsidian,20,minecraft:obsidian,100)
RB(15,1,15,minecraft:crying_obsidian,20,minecraft:obsidian,100)
RB(0,2,6,minecraft:crying_obsidian,20,minecraft:obsidian,100)
RB(1,2,6,minecraft:crying_obsidian,20,minecraft:obsidian,100)
RB(2,2,6,minecraft:crying_obsidian,20,minecraft:obsidian,100)
RB(3,2,6,minecraft:crying_obsidian,20,minecraft:obsidian,100)
RB(9,2,6,minecraft:crying_obsidian,20,minecraft:obsidian,100)
RB(10,2,6,minecraft:crying_obsidian,20,minecraft:obsidian,100)
RB(11,2,6,minecraft:crying_obsidian,20,minecraft:obsidian,100)
RB(0,2,7,minecraft:crying_obsidian,20,minecraft:obsidian,100)
RB(1,2,7,minecraft:crying_obsidian,20,minecraft:obsidian,100)
RB(2,2,7,minecraft:crying_obsidian,20,minecraft:obsidian,100)
RB(3,2,7,minecraft:crying_obsidian,20,minecraft:obsidian,100)
RB(4,2,7,minecraft:crying_obsidian,20,minecraft:obsidian,100)
RB(6,2,7,minecraft:crying_obsidian,20,minecraft:obsidian,100)
RB(7,2,7,minecraft:crying_obsidian,20,minecraft:obsidian,100)
RB(8,2,7,minecraft:crying_obsidian,20,minecraft:obsidian,100)
RB(9,2,7,minecraft:crying_obsidian,20,minecraft:obsidian,100)
RB(10,2,7,minecraft:crying_obsidian,20,minecraft:obsidian,100)
RB(11,2,7,minecraft:crying_obsidian,20,minecraft:obsidian,100)
RB(12,2,7,minecraft:crying_obsidian,20,minecraft:obsidian,100)
RB(0,2,8,minecraft:crying_obsidian,20,minecraft:obsidian,100)
RB(1,2,8,minecraft:crying_obsidian,20,minecraft:obsidian,100)
RB(2,2,8,minecraft:crying_obsidian,20,minecraft:obsidian,100)
RB(3,2,8,minecraft:crying_obsidian,20,minecraft:obsidian,100)
RB(4,2,8,minecraft:crying_obsidian,20,minecraft:obsidian,100)
RB(5,2,8,minecraft:crying_obsidian,20,minecraft:obsidian,100)
RB(6,2,8,minecraft:crying_obsidian,20,minecraft:obsidian,100)
RB(7,2,8,minecraft:crying_obsidian,20,minecraft:obsidian,100)
RB(8,2,8,minecraft:crying_obsidian,20,minecraft:obsidian,100)
RB(9,2,8,minecraft:crying_obsidian,20,minecraft:obsidian,100)
RB(10,2,8,minecraft:crying_obsidian,20,minecraft:obsidian,100)
RB(11,2,8,minecraft:crying_obsidian,20,minecraft:obsidian,100)
RB(12,2,8,minecraft:crying_obsidian,20,minecraft:obsidian,100)
RB(13,2,8,minecraft:crying_obsidian,20,minecraft:obsidian,100)
RB(0,2,9,minecraft:crying_obsidian,20,minecraft:obsidian,100)
RB(1,2,9,minecraft:crying_obsidian,20,minecraft:obsidian,100)
RB(2,2,9,minecraft:crying_obsidian,20,minecraft:obsidian,100)
RB(3,2,9,minecraft:crying_obsidian,20,minecraft:obsidian,100)
RB(4,2,9,minecraft:crying_obsidian,20,minecraft:obsidian,100)
RB(5,2,9,minecraft:crying_obsidian,20,minecraft:obsidian,100)
RB(6,2,9,minecraft:crying_obsidian,20,minecraft:obsidian,100)
RB(7,2,9,minecraft:crying_obsidian,20,minecraft:obsidian,100)
RB(8,2,9,minecraft:crying_obsidian,20,minecraft:obsidian,100)
RB(9,2,9,minecraft:crying_obsidian,20,minecraft:obsidian,100)
RB(10,2,9,minecraft:crying_obsidian,20,minecraft:obsidian,100)
RB(11,2,9,minecraft:crying_obsidian,20,minecraft:obsidian,100)
RB(12,2,9,minecraft:crying_obsidian,20,minecraft:obsidian,100)
RB(13,2,9,minecraft:crying_obsidian,20,minecraft:obsidian,100)
RB(14,2,9,minecraft:crying_obsidian,20,minecraft:obsidian,100)
RB(15,2,9,minecraft:crying_obsidian,20,minecraft:obsidian,100)
RB(0,2,10,minecraft:crying_obsidian,20,minecraft:obsidian,100)
RB(1,2,10,minecraft:crying_obsidian,20,minecraft:obsidian,100)
RB(2,2,10,minecraft:crying_obsidian,20,minecraft:obsidian,100)
RB(3,2,10,minecraft:crying_obsidian,20,minecraft:obsidian,100)
RB(4,2,10,minecraft:crying_obsidian,20,minecraft:obsidian,100)
RB(5,2,10,minecraft:crying_obsidian,20,minecraft:obsidian,100)
RB(6,2,10,minecraft:crying_obsidian,20,minecraft:obsidian,100)
RB(7,2,10,minecraft:crying_obsidian,20,minecraft:obsidian,100)
RB(8,2,10,minecraft:crying_obsidian,20,minecraft:obsidian,100)
RB(9,2,10,minecraft:crying_obsidian,20,minecraft:obsidian,100)
RB(10,2,10,minecraft:crying_obsidian,20,minecraft:obsidian,100)
RB(11,2,10,minecraft:crying_obsidian,20,minecraft:obsidian,100)
RB(12,2,10,minecraft:crying_obsidian,20,minecraft:obsidian,100)
RB(13,2,10,minecraft:crying_obsidian,20,minecraft:obsidian,100)
RB(14,2,10,minecraft:crying_obsidian,20,minecraft:obsidian,100)
RB(15,2,10,minecraft:crying_obsidian,20,minecraft:obsidian,100)
RB(0,2,11,minecraft:crying_obsidian,20,minecraft:obsidian,100)
RB(1,2,11,minecraft:crying_obsidian,20,minecraft:obsidian,100)
RB(2,2,11,minecraft:crying_obsidian,20,minecraft:obsidian,100)
RB(3,2,11,minecraft:crying_obsidian,20,minecraft:obsidian,100)
RB(4,2,11,minecraft:crying_obsidian,20,minecraft:obsidian,100)
RB(5,2,11,minecraft:crying_obsidian,20,minecraft:obsidian,100)
RB(6,2,11,minecraft:crying_obsidian,20,minecraft:obsidian,100)
RB(7,2,11,minecraft:crying_obsidian,20,minecraft:obsidian,100)
RB(8,2,11,minecraft:crying_obsidian,20,minecraft:obsidian,100)
RB(9,2,11,minecraft:crying_obsidian,20,minecraft:obsidian,100)
RB(10,2,11,minecraft:crying_obsidian,20,minecraft:obsidian,100)
RB(11,2,11,minecraft:crying_obsidian,20,minecraft:obsidian,100)
RB(12,2,11,minecraft:crying_obsidian,20,minecraft:obsidian,100)
RB(13,2,11,minecraft:crying_obsidian,20,minecraft:obsidian,100)
RB(14,2,11,minecraft:crying_obsidian,20,minecraft:obsidian,100)
RB(15,2,11,minecraft:crying_obsidian,20,minecraft:obsidian,100)
RB(0,2,12,minecraft:crying_obsidian,20,minecraft:obsidian,100)
RB(1,2,12,minecraft:crying_obsidian,20,minecraft:obsidian,100)
RB(2,2,12,minecraft:crying_obsidian,20,minecraft:obsidian,100)
RB(3,2,12,minecraft:crying_obsidian,20,minecraft:obsidian,100)
RB(4,2,12,minecraft:crying_obsidian,20,minecraft:obsidian,100)
RB(5,2,12,minecraft:crying_obsidian,20,minecraft:obsidian,100)
RB(6,2,12,minecraft:crying_obsidian,20,minecraft:obsidian,100)
RB(7,2,12,minecraft:crying_obsidian,20,minecraft:obsidian,100)
RB(8,2,12,minecraft:crying_obsidian,20,minecraft:obsidian,100)
RB(9,2,12,minecraft:crying_obsidian,20,minecraft:obsidian,100)
RB(10,2,12,minecraft:crying_obsidian,20,minecraft:obsidian,100)
RB(11,2,12,minecraft:crying_obsidian,20,minecraft:obsidian,100)
RB(12,2,12,minecraft:crying_obsidian,20,minecraft:obsidian,100)
RB(13,2,12,minecraft:crying_obsidian,20,minecraft:obsidian,100)
RB(14,2,12,minecraft:crying_obsidian,20,minecraft:obsidian,100)
RB(15,2,12,minecraft:crying_obsidian,20,minecraft:obsidian,100)
RB(0,2,13,minecraft:crying_obsidian,20,minecraft:obsidian,100)
RB(1,2,13,minecraft:crying_obsidian,20,minecraft:obsidian,100)
RB(2,2,13,minecraft:crying_obsidian,20,minecraft:obsidian,100)
RB(3,2,13,minecraft:crying_obsidian,20,minecraft:obsidian,100)
RB(4,2,13,minecraft:crying_obsidian,20,minecraft:obsidian,100)
RB(5,2,13,minecraft:crying_obsidian,20,minecraft:obsidian,100)
RB(6,2,13,minecraft:crying_obsidian,20,minecraft:obsidian,100)
RB(7,2,13,minecraft:crying_obsidian,20,minecraft:obsidian,100)
RB(8,2,13,minecraft:crying_obsidian,20,minecraft:obsidian,100)
RB(9,2,13,minecraft:crying_obsidian,20,minecraft:obsidian,100)
RB(10,2,13,minecraft:crying_obsidian,20,minecraft:obsidian,100)
RB(11,2,13,minecraft:crying_obsidian,20,minecraft:obsidian,100)
RB(12,2,13,minecraft:crying_obsidian,20,minecraft:obsidian,100)
RB(13,2,13,minecraft:crying_obsidian,20,minecraft:obsidian,100)
RB(14,2,13,minecraft:crying_obsidian,20,minecraft:obsidian,100)
RB(15,2,13,minecraft:crying_obsidian,20,minecraft:obsidian,100)
RB(0,2,14,minecraft:crying_obsidian,20,minecraft:obsidian,100)
RB(1,2,14,minecraft:crying_obsidian,20,minecraft:obsidian,100)
RB(2,2,14,minecraft:crying_obsidian,20,minecraft:obsidian,100)
RB(3,2,14,minecraft:crying_obsidian,20,minecraft:obsidian,100)
RB(4,2,14,minecraft:crying_obsidian,20,minecraft:obsidian,100)
RB(5,2,14,minecraft:crying_obsidian,20,minecraft:obsidian,100)
RB(6,2,14,minecraft:crying_obsidian,20,minecraft:obsidian,100)
RB(7,2,14,minecraft:crying_obsidian,20,minecraft:obsidian,100)
RB(8,2,14,minecraft:crying_obsidian,20,minecraft:obsidian,100)
RB(9,2,14,minecraft:crying_obsidian,20,minecraft:obsidian,100)
RB(10,2,14,minecraft:crying_obsidian,20,minecraft:obsidian,100)
RB(11,2,14,minecraft:crying_obsidian,20,minecraft:obsidian,100)
RB(12,2,14,minecraft:crying_obsidian,20,minecraft:obsidian,100)
RB(13,2,14,minecraft:crying_obsidian,20,minecraft:obsidian,100)
RB(14,2,14,minecraft:crying_obsidian,20,minecraft:obsidian,100)
RB(15,2,14,minecraft:crying_obsidian,20,minecraft:obsidian,100)
RB(0,2,15,minecraft:crying_obsidian,20,minecraft:obsidian,100)
RB(1,2,15,minecraft:crying_obsidian,20,minecraft:obsidian,100)
RB(2,2,15,minecraft:crying_obsidian,20,minecraft:obsidian,100)
RB(3,2,15,minecraft:crying_obsidian,20,minecraft:obsidian,100)
RB(4,2,15,minecraft:crying_obsidian,20,minecraft:obsidian,100)
RB(5,2,15,minecraft:crying_obsidian,20,minecraft:obsidian,100)
RB(6,2,15,minecraft:crying_obsidian,20,minecraft:obsidian,100)
RB(7,2,15,minecraft:crying_obsidian,20,minecraft:obsidian,100)
RB(8,2,15,minecraft:crying_obsidian,20,minecraft:obsidian,100)
RB(9,2,15,minecraft:crying_obsidian,20,minecraft:obsidian,100)
RB(10,2,15,minecraft:crying_obsidian,20,minecraft:obsidian,100)
RB(11,2,15,minecraft:crying_obsidian,20,minecraft:obsidian,100)
RB(12,2,15,minecraft:crying_obsidian,20,minecraft:obsidian,100)
RB(13,2,15,minecraft:crying_obsidian,20,minecraft:obsidian,100)
RB(14,2,15,minecraft:crying_obsidian,20,minecraft:obsidian,100)
RB(15,2,15,minecraft:crying_obsidian,20,minecraft:obsidian,100)
RB(9,3,6,minecraft:crying_obsidian,20,minecraft:obsidian,100)
RB(10,3,6,minecraft:crying_obsidian,20,minecraft:obsidian,100)
RB(0,3,7,minecraft:crying_obsidian,20,minecraft:obsidian,100)
RB(1,3,7,minecraft:crying_obsidian,20,minecraft:obsidian,100)
RB(2,3,7,minecraft:crying_obsidian,20,minecraft:obsidian,100)
RB(3,3,7,minecraft:crying_obsidian,20,minecraft:obsidian,100)
RB(6,3,7,minecraft:crying_obsidian,20,minecraft:obsidian,100)
RB(7,3,7,minecraft:crying_obsidian,20,minecraft:obsidian,100)
RB(8,3,7,minecraft:crying_obsidian,20,minecraft:obsidian,100)
RB(9,3,7,minecraft:crying_obsidian,20,minecraft:obsidian,100)
RB(10,3,7,minecraft:crying_obsidian,20,minecraft:obsidian,100)
RB(11,3,7,minecraft:crying_obsidian,20,minecraft:obsidian,100)
RB(12,3,7,minecraft:crying_obsidian,20,minecraft:obsidian,100)
RB(0,3,8,minecraft:crying_obsidian,20,minecraft:obsidian,100)
RB(1,3,8,minecraft:crying_obsidian,20,minecraft:obsidian,100)
RB(2,3,8,minecraft:crying_obsidian,20,minecraft:obsidian,100)
RB(3,3,8,minecraft:crying_obsidian,20,minecraft:obsidian,100)
RB(4,3,8,minecraft:crying_obsidian,20,minecraft:obsidian,100)
RB(5,3,8,minecraft:crying_obsidian,20,minecraft:obsidian,100)
RB(6,3,8,minecraft:crying_obsidian,20,minecraft:obsidian,100)
RB(7,3,8,minecraft:crying_obsidian,20,minecraft:obsidian,100)
RB(8,3,8,minecraft:crying_obsidian,20,minecraft:obsidian,100)
RB(9,3,8,minecraft:crying_obsidian,20,minecraft:obsidian,100)
RB(10,3,8,minecraft:crying_obsidian,20,minecraft:obsidian,100)
RB(11,3,8,minecraft:crying_obsidian,20,minecraft:obsidian,100)
RB(12,3,8,minecraft:crying_obsidian,20,minecraft:obsidian,100)
RB(13,3,8,minecraft:crying_obsidian,20,minecraft:obsidian,100)
RB(0,3,9,minecraft:crying_obsidian,20,minecraft:obsidian,100)
RB(1,3,9,minecraft:crying_obsidian,20,minecraft:obsidian,100)
RB(2,3,9,minecraft:crying_obsidian,20,minecraft:obsidian,100)
RB(3,3,9,minecraft:crying_obsidian,20,minecraft:obsidian,100)
RB(4,3,9,minecraft:crying_obsidian,20,minecraft:obsidian,100)
RB(5,3,9,minecraft:crying_obsidian,20,minecraft:obsidian,100)
RB(6,3,9,minecraft:crying_obsidian,20,minecraft:obsidian,100)
RB(7,3,9,minecraft:crying_obsidian,20,minecraft:obsidian,100)
RB(8,3,9,minecraft:crying_obsidian,20,minecraft:obsidian,100)
RB(9,3,9,minecraft:crying_obsidian,20,minecraft:obsidian,100)
RB(10,3,9,minecraft:crying_obsidian,20,minecraft:obsidian,100)
RB(11,3,9,minecraft:crying_obsidian,20,minecraft:obsidian,100)
RB(12,3,9,minecraft:crying_obsidian,20,minecraft:obsidian,100)
RB(13,3,9,minecraft:crying_obsidian,20,minecraft:obsidian,100)
RB(0,3,10,minecraft:crying_obsidian,20,minecraft:obsidian,100)
RB(1,3,10,minecraft:crying_obsidian,20,minecraft:obsidian,100)
RB(2,3,10,minecraft:crying_obsidian,20,minecraft:obsidian,100)
RB(3,3,10,minecraft:crying_obsidian,20,minecraft:obsidian,100)
RB(4,3,10,minecraft:crying_obsidian,20,minecraft:obsidian,100)
RB(5,3,10,minecraft:crying_obsidian,20,minecraft:obsidian,100)
RB(6,3,10,minecraft:crying_obsidian,20,minecraft:obsidian,100)
RB(7,3,10,minecraft:crying_obsidian,20,minecraft:obsidian,100)
RB(8,3,10,minecraft:crying_obsidian,20,minecraft:obsidian,100)
RB(9,3,10,minecraft:crying_obsidian,20,minecraft:obsidian,100)
RB(10,3,10,minecraft:crying_obsidian,20,minecraft:obsidian,100)
RB(11,3,10,minecraft:crying_obsidian,20,minecraft:obsidian,100)
RB(12,3,10,minecraft:crying_obsidian,20,minecraft:obsidian,100)
RB(13,3,10,minecraft:crying_obsidian,20,minecraft:obsidian,100)
RB(14,3,10,minecraft:crying_obsidian,20,minecraft:obsidian,100)
RB(15,3,10,minecraft:crying_obsidian,20,minecraft:obsidian,100)
RB(0,3,11,minecraft:crying_obsidian,20,minecraft:obsidian,100)
RB(1,3,11,minecraft:crying_obsidian,20,minecraft:obsidian,100)
RB(2,3,11,minecraft:crying_obsidian,20,minecraft:obsidian,100)
RB(3,3,11,minecraft:crying_obsidian,20,minecraft:obsidian,100)
RB(4,3,11,minecraft:crying_obsidian,20,minecraft:obsidian,100)
RB(5,3,11,minecraft:crying_obsidian,20,minecraft:obsidian,100)
RB(6,3,11,minecraft:crying_obsidian,20,minecraft:obsidian,100)
RB(7,3,11,minecraft:crying_obsidian,20,minecraft:obsidian,100)
RB(8,3,11,minecraft:crying_obsidian,20,minecraft:obsidian,100)
RB(9,3,11,minecraft:crying_obsidian,20,minecraft:obsidian,100)
RB(10,3,11,minecraft:crying_obsidian,20,minecraft:obsidian,100)
RB(11,3,11,minecraft:crying_obsidian,20,minecraft:obsidian,100)
RB(12,3,11,minecraft:crying_obsidian,20,minecraft:obsidian,100)
RB(13,3,11,minecraft:crying_obsidian,20,minecraft:obsidian,100)
RB(14,3,11,minecraft:crying_obsidian,20,minecraft:obsidian,100)
RB(15,3,11,minecraft:crying_obsidian,20,minecraft:obsidian,100)
RB(0,3,12,minecraft:crying_obsidian,20,minecraft:obsidian,100)
RB(1,3,12,minecraft:crying_obsidian,20,minecraft:obsidian,100)
RB(2,3,12,minecraft:crying_obsidian,20,minecraft:obsidian,100)
RB(3,3,12,minecraft:crying_obsidian,20,minecraft:obsidian,100)
RB(4,3,12,minecraft:crying_obsidian,20,minecraft:obsidian,100)
RB(5,3,12,minecraft:crying_obsidian,20,minecraft:obsidian,100)
RB(6,3,12,minecraft:crying_obsidian,20,minecraft:obsidian,100)
RB(7,3,12,minecraft:crying_obsidian,20,minecraft:obsidian,100)
RB(8,3,12,minecraft:crying_obsidian,20,minecraft:obsidian,100)
RB(9,3,12,minecraft:crying_obsidian,20,minecraft:obsidian,100)
RB(10,3,12,minecraft:crying_obsidian,20,minecraft:obsidian,100)
RB(11,3,12,minecraft:crying_obsidian,20,minecraft:obsidian,100)
RB(12,3,12,minecraft:crying_obsidian,20,minecraft:obsidian,100)
RB(13,3,12,minecraft:crying_obsidian,20,minecraft:obsidian,100)
RB(14,3,12,minecraft:crying_obsidian,20,minecraft:obsidian,100)
RB(15,3,12,minecraft:crying_obsidian,20,minecraft:obsidian,100)
RB(0,3,13,minecraft:crying_obsidian,20,minecraft:obsidian,100)
RB(1,3,13,minecraft:crying_obsidian,20,minecraft:obsidian,100)
RB(2,3,13,minecraft:crying_obsidian,20,minecraft:obsidian,100)
RB(3,3,13,minecraft:crying_obsidian,20,minecraft:obsidian,100)
RB(4,3,13,minecraft:crying_obsidian,20,minecraft:obsidian,100)
RB(5,3,13,minecraft:crying_obsidian,20,minecraft:obsidian,100)
RB(6,3,13,minecraft:crying_obsidian,20,minecraft:obsidian,100)
RB(7,3,13,minecraft:crying_obsidian,20,minecraft:obsidian,100)
RB(8,3,13,minecraft:crying_obsidian,20,minecraft:obsidian,100)
RB(9,3,13,minecraft:crying_obsidian,20,minecraft:obsidian,100)
RB(10,3,13,minecraft:crying_obsidian,20,minecraft:obsidian,100)
RB(11,3,13,minecraft:crying_obsidian,20,minecraft:obsidian,100)
RB(12,3,13,minecraft:crying_obsidian,20,minecraft:obsidian,100)
RB(13,3,13,minecraft:crying_obsidian,20,minecraft:obsidian,100)
RB(14,3,13,minecraft:crying_obsidian,20,minecraft:obsidian,100)
RB(15,3,13,minecraft:crying_obsidian,20,minecraft:obsidian,100)
RB(0,3,14,minecraft:crying_obsidian,20,minecraft:obsidian,100)
RB(1,3,14,minecraft:crying_obsidian,20,minecraft:obsidian,100)
RB(2,3,14,minecraft:crying_obsidian,20,minecraft:obsidian,100)
RB(3,3,14,minecraft:crying_obsidian,20,minecraft:obsidian,100)
RB(4,3,14,minecraft:crying_obsidian,20,minecraft:obsidian,100)
RB(5,3,14,minecraft:crying_obsidian,20,minecraft:obsidian,100)
RB(6,3,14,minecraft:crying_obsidian,20,minecraft:obsidian,100)
RB(7,3,14,minecraft:crying_obsidian,20,minecraft:obsidian,100)
RB(8,3,14,minecraft:crying_obsidian,20,minecraft:obsidian,100)
RB(9,3,14,minecraft:crying_obsidian,20,minecraft:obsidian,100)
RB(10,3,14,minecraft:crying_obsidian,20,minecraft:obsidian,100)
RB(11,3,14,minecraft:crying_obsidian,20,minecraft:obsidian,100)
RB(12,3,14,minecraft:crying_obsidian,20,minecraft:obsidian,100)
RB(13,3,14,minecraft:crying_obsidian,20,minecraft:obsidian,100)
RB(14,3,14,minecraft:crying_obsidian,20,minecraft:obsidian,100)
RB(15,3,14,minecraft:crying_obsidian,20,minecraft:obsidian,100)
RB(0,3,15,minecraft:crying_obsidian,20,minecraft:obsidian,100)
RB(1,3,15,minecraft:crying_obsidian,20,minecraft:obsidian,100)
RB(2,3,15,minecraft:crying_obsidian,20,minecraft:obsidian,100)
RB(3,3,15,minecraft:crying_obsidian,20,minecraft:obsidian,100)
RB(4,3,15,minecraft:crying_obsidian,20,minecraft:obsidian,100)
RB(5,3,15,minecraft:crying_obsidian,20,minecraft:obsidian,100)
RB(6,3,15,minecraft:crying_obsidian,20,minecraft:obsidian,100)
RB(7,3,15,minecraft:crying_obsidian,20,minecraft:obsidian,100)
RB(8,3,15,minecraft:crying_obsidian,20,minecraft:obsidian,100)
RB(9,3,15,minecraft:crying_obsidian,20,minecraft:obsidian,100)
RB(10,3,15,minecraft:crying_obsidian,20,minecraft:obsidian,100)
RB(11,3,15,minecraft:crying_obsidian,20,minecraft:obsidian,100)
RB(12,3,15,minecraft:crying_obsidian,20,minecraft:obsidian,100)
RB(13,3,15,minecraft:crying_obsidian,20,minecraft:obsidian,100)
RB(14,3,15,minecraft:crying_obsidian,20,minecraft:obsidian,100)
RB(15,3,15,minecraft:crying_obsidian,20,minecraft:obsidian,100)
RB(7,4,7,minecraft:crying_obsidian,20,minecraft:obsidian,100)
RB(8,4,7,minecraft:crying_obsidian,20,minecraft:obsidian,100)
RB(9,4,7,minecraft:crying_obsidian,20,minecraft:obsidian,100)
RB(10,4,7,minecraft:crying_obsidian,20,minecraft:obsidian,100)
RB(11,4,7,minecraft:crying_obsidian,20,minecraft:obsidian,100)
RB(0,4,8,minecraft:crying_obsidian,20,minecraft:obsidian,100)
RB(1,4,8,minecraft:crying_obsidian,20,minecraft:obsidian,100)
RB(2,4,8,minecraft:crying_obsidian,20,minecraft:obsidian,100)
RB(6,4,8,minecraft:crying_obsidian,20,minecraft:obsidian,100)
RB(7,4,8,minecraft:crying_obsidian,20,minecraft:obsidian,100)
RB(8,4,8,minecraft:crying_obsidian,20,minecraft:obsidian,100)
RB(9,4,8,minecraft:crying_obsidian,20,minecraft:obsidian,100)
RB(10,4,8,minecraft:crying_obsidian,20,minecraft:obsidian,100)
RB(11,4,8,minecraft:crying_obsidian,20,minecraft:obsidian,100)
RB(12,4,8,minecraft:crying_obsidian,20,minecraft:obsidian,100)
RB(0,4,9,minecraft:crying_obsidian,20,minecraft:obsidian,100)
RB(1,4,9,minecraft:crying_obsidian,20,minecraft:obsidian,100)
RB(2,4,9,minecraft:crying_obsidian,20,minecraft:obsidian,100)
RB(3,4,9,minecraft:crying_obsidian,20,minecraft:obsidian,100)
RB(5,4,9,minecraft:crying_obsidian,20,minecraft:obsidian,100)
RB(6,4,9,minecraft:crying_obsidian,20,minecraft:obsidian,100)
RB(7,4,9,minecraft:crying_obsidian,20,minecraft:obsidian,100)
RB(8,4,9,minecraft:crying_obsidian,20,minecraft:obsidian,100)
RB(9,4,9,minecraft:crying_obsidian,20,minecraft:obsidian,100)
RB(10,4,9,minecraft:crying_obsidian,20,minecraft:obsidian,100)
RB(11,4,9,minecraft:crying_obsidian,20,minecraft:obsidian,100)
RB(12,4,9,minecraft:crying_obsidian,20,minecraft:obsidian,100)
RB(13,4,9,minecraft:crying_obsidian,20,minecraft:obsidian,100)
RB(0,4,10,minecraft:crying_obsidian,20,minecraft:obsidian,100)
RB(1,4,10,minecraft:crying_obsidian,20,minecraft:obsidian,100)
RB(2,4,10,minecraft:crying_obsidian,20,minecraft:obsidian,100)
RB(3,4,10,minecraft:crying_obsidian,20,minecraft:obsidian,100)
RB(5,4,10,minecraft:crying_obsidian,20,minecraft:obsidian,100)
RB(6,4,10,minecraft:crying_obsidian,20,minecraft:obsidian,100)
RB(7,4,10,minecraft:crying_obsidian,20,minecraft:obsidian,100)
RB(8,4,10,minecraft:crying_obsidian,20,minecraft:obsidian,100)
RB(9,4,10,minecraft:crying_obsidian,20,minecraft:obsidian,100)
RB(10,4,10,minecraft:crying_obsidian,20,minecraft:obsidian,100)
RB(11,4,10,minecraft:crying_obsidian,20,minecraft:obsidian,100)
RB(12,4,10,minecraft:crying_obsidian,20,minecraft:obsidian,100)
RB(13,4,10,minecraft:crying_obsidian,20,minecraft:obsidian,100)
RB(0,4,11,minecraft:crying_obsidian,20,minecraft:obsidian,100)
RB(1,4,11,minecraft:crying_obsidian,20,minecraft:obsidian,100)
RB(2,4,11,minecraft:crying_obsidian,20,minecraft:obsidian,100)
RB(3,4,11,minecraft:crying_obsidian,20,minecraft:obsidian,100)
RB(4,4,11,minecraft:crying_obsidian,20,minecraft:obsidian,100)
RB(5,4,11,minecraft:crying_obsidian,20,minecraft:obsidian,100)
RB(6,4,11,minecraft:crying_obsidian,20,minecraft:obsidian,100)
RB(7,4,11,minecraft:crying_obsidian,20,minecraft:obsidian,100)
RB(8,4,11,minecraft:crying_obsidian,20,minecraft:obsidian,100)
RB(9,4,11,minecraft:crying_obsidian,20,minecraft:obsidian,100)
RB(10,4,11,minecraft:crying_obsidian,20,minecraft:obsidian,100)
RB(11,4,11,minecraft:crying_obsidian,20,minecraft:obsidian,100)
RB(12,4,11,minecraft:crying_obsidian,20,minecraft:obsidian,100)
RB(13,4,11,minecraft:crying_obsidian,20,minecraft:obsidian,100)
RB(0,4,12,minecraft:crying_obsidian,20,minecraft:obsidian,100)
RB(1,4,12,minecraft:crying_obsidian,20,minecraft:obsidian,100)
RB(2,4,12,minecraft:crying_obsidian,20,minecraft:obsidian,100)
RB(3,4,12,minecraft:crying_obsidian,20,minecraft:obsidian,100)
RB(4,4,12,minecraft:crying_obsidian,20,minecraft:obsidian,100)
RB(5,4,12,minecraft:crying_obsidian,20,minecraft:obsidian,100)
RB(6,4,12,minecraft:crying_obsidian,20,minecraft:obsidian,100)
RB(7,4,12,minecraft:crying_obsidian,20,minecraft:obsidian,100)
RB(8,4,12,minecraft:crying_obsidian,20,minecraft:obsidian,100)
RB(9,4,12,minecraft:crying_obsidian,20,minecraft:obsidian,100)
RB(10,4,12,minecraft:crying_obsidian,20,minecraft:obsidian,100)
RB(11,4,12,minecraft:crying_obsidian,20,minecraft:obsidian,100)
RB(12,4,12,minecraft:crying_obsidian,20,minecraft:obsidian,100)
RB(13,4,12,minecraft:crying_obsidian,20,minecraft:obsidian,100)
RB(14,4,12,minecraft:crying_obsidian,20,minecraft:obsidian,100)
RB(0,4,13,minecraft:crying_obsidian,20,minecraft:obsidian,100)
RB(1,4,13,minecraft:crying_obsidian,20,minecraft:obsidian,100)
RB(2,4,13,minecraft:crying_obsidian,20,minecraft:obsidian,100)
RB(3,4,13,minecraft:crying_obsidian,20,minecraft:obsidian,100)
RB(4,4,13,minecraft:crying_obsidian,20,minecraft:obsidian,100)
RB(5,4,13,minecraft:crying_obsidian,20,minecraft:obsidian,100)
RB(6,4,13,minecraft:crying_obsidian,20,minecraft:obsidian,100)
RB(7,4,13,minecraft:crying_obsidian,20,minecraft:obsidian,100)
RB(8,4,13,minecraft:crying_obsidian,20,minecraft:obsidian,100)
RB(9,4,13,minecraft:crying_obsidian,20,minecraft:obsidian,100)
RB(10,4,13,minecraft:crying_obsidian,20,minecraft:obsidian,100)
RB(11,4,13,minecraft:crying_obsidian,20,minecraft:obsidian,100)
RB(12,4,13,minecraft:crying_obsidian,20,minecraft:obsidian,100)
RB(13,4,13,minecraft:crying_obsidian,20,minecraft:obsidian,100)
RB(14,4,13,minecraft:crying_obsidian,20,minecraft:obsidian,100)
RB(15,4,13,minecraft:crying_obsidian,20,minecraft:obsidian,100)
RB(0,4,14,minecraft:crying_obsidian,20,minecraft:obsidian,100)
RB(1,4,14,minecraft:crying_obsidian,20,minecraft:obsidian,100)
RB(2,4,14,minecraft:crying_obsidian,20,minecraft:obsidian,100)
RB(3,4,14,minecraft:crying_obsidian,20,minecraft:obsidian,100)
RB(4,4,14,minecraft:crying_obsidian,20,minecraft:obsidian,100)
RB(5,4,14,minecraft:crying_obsidian,20,minecraft:obsidian,100)
RB(6,4,14,minecraft:crying_obsidian,20,minecraft:obsidian,100)
RB(7,4,14,minecraft:crying_obsidian,20,minecraft:obsidian,100)
RB(8,4,14,minecraft:crying_obsidian,20,minecraft:obsidian,100)
RB(9,4,14,minecraft:crying_obsidian,20,minecraft:obsidian,100)
RB(10,4,14,minecraft:crying_obsidian,20,minecraft:obsidian,100)
RB(11,4,14,minecraft:crying_obsidian,20,minecraft:obsidian,100)
RB(12,4,14,minecraft:crying_obsidian,20,minecraft:obsidian,100)
RB(13,4,14,minecraft:crying_obsidian,20,minecraft:obsidian,100)
RB(14,4,14,minecraft:crying_obsidian,20,minecraft:obsidian,100)
RB(15,4,14,minecraft:crying_obsidian,20,minecraft:obsidian,100)
RB(0,4,15,minecraft:crying_obsidian,20,minecraft:obsidian,100)
RB(1,4,15,minecraft:crying_obsidian,20,minecraft:obsidian,100)
RB(2,4,15,minecraft:crying_obsidian,20,minecraft:obsidian,100)
RB(3,4,15,minecraft:crying_obsidian,20,minecraft:obsidian,100)
RB(4,4,15,minecraft:crying_obsidian,20,minecraft:obsidian,100)
RB(5,4,15,minecraft:crying_obsidian,20,minecraft:obsidian,100)
RB(6,4,15,minecraft:crying_obsidian,20,minecraft:obsidian,100)
RB(7,4,15,minecraft:crying_obsidian,20,minecraft:obsidian,100)
RB(8,4,15,minecraft:crying_obsidian,20,minecraft:obsidian,100)
RB(9,4,15,minecraft:crying_obsidian,20,minecraft:obsidian,100)
RB(10,4,15,minecraft:crying_obsidian,20,minecraft:obsidian,100)
RB(11,4,15,minecraft:crying_obsidian,20,minecraft:obsidian,100)
RB(12,4,15,minecraft:crying_obsidian,20,minecraft:obsidian,100)
RB(13,4,15,minecraft:crying_obsidian,20,minecraft:obsidian,100)
RB(14,4,15,minecraft:crying_obsidian,20,minecraft:obsidian,100)
RB(15,4,15,minecraft:crying_obsidian,20,minecraft:obsidian,100)
RB(7,5,8,minecraft:crying_obsidian,20,minecraft:obsidian,100)
RB(8,5,8,minecraft:crying_obsidian,20,minecraft:obsidian,100)
RB(9,5,8,minecraft:crying_obsidian,20,minecraft:obsidian,100)
RB(10,5,8,minecraft:crying_obsidian,20,minecraft:obsidian,100)
RB(11,5,8,minecraft:crying_obsidian,20,minecraft:obsidian,100)
RB(6,5,9,minecraft:crying_obsidian,20,minecraft:obsidian,100)
RB(7,5,9,minecraft:crying_obsidian,20,minecraft:obsidian,100)
RB(8,5,9,minecraft:crying_obsidian,20,minecraft:obsidian,100)
RB(9,5,9,minecraft:crying_obsidian,20,minecraft:obsidian,100)
RB(10,5,9,minecraft:crying_obsidian,20,minecraft:obsidian,100)
RB(11,5,9,minecraft:crying_obsidian,20,minecraft:obsidian,100)
RB(12,5,9,minecraft:crying_obsidian,20,minecraft:obsidian,100)
RB(6,5,10,minecraft:crying_obsidian,20,minecraft:obsidian,100)
RB(7,5,10,minecraft:crying_obsidian,20,minecraft:obsidian,100)
RB(8,5,10,minecraft:crying_obsidian,20,minecraft:obsidian,100)
RB(9,5,10,minecraft:crying_obsidian,20,minecraft:obsidian,100)
RB(10,5,10,minecraft:crying_obsidian,20,minecraft:obsidian,100)
RB(11,5,10,minecraft:crying_obsidian,20,minecraft:obsidian,100)
RB(12,5,10,minecraft:crying_obsidian,20,minecraft:obsidian,100)
RB(0,5,11,minecraft:crying_obsidian,20,minecraft:obsidian,100)
RB(1,5,11,minecraft:crying_obsidian,20,minecraft:obsidian,100)
RB(2,5,11,minecraft:crying_obsidian,20,minecraft:obsidian,100)
RB(3,5,11,minecraft:crying_obsidian,20,minecraft:obsidian,100)
RB(4,5,11,minecraft:crying_obsidian,20,minecraft:obsidian,100)
RB(5,5,11,minecraft:crying_obsidian,20,minecraft:obsidian,100)
RB(6,5,11,minecraft:crying_obsidian,20,minecraft:obsidian,100)
RB(7,5,11,minecraft:crying_obsidian,20,minecraft:obsidian,100)
RB(8,5,11,minecraft:crying_obsidian,20,minecraft:obsidian,100)
RB(9,5,11,minecraft:crying_obsidian,20,minecraft:obsidian,100)
RB(10,5,11,minecraft:crying_obsidian,20,minecraft:obsidian,100)
RB(11,5,11,minecraft:crying_obsidian,20,minecraft:obsidian,100)
RB(12,5,11,minecraft:crying_obsidian,20,minecraft:obsidian,100)
RB(0,5,12,minecraft:crying_obsidian,20,minecraft:obsidian,100)
RB(1,5,12,minecraft:crying_obsidian,20,minecraft:obsidian,100)
RB(2,5,12,minecraft:crying_obsidian,20,minecraft:obsidian,100)
RB(3,5,12,minecraft:crying_obsidian,20,minecraft:obsidian,100)
RB(4,5,12,minecraft:crying_obsidian,20,minecraft:obsidian,100)
RB(5,5,12,minecraft:crying_obsidian,20,minecraft:obsidian,100)
RB(6,5,12,minecraft:crying_obsidian,20,minecraft:obsidian,100)
RB(7,5,12,minecraft:crying_obsidian,20,minecraft:obsidian,100)
RB(8,5,12,minecraft:crying_obsidian,20,minecraft:obsidian,100)
RB(9,5,12,minecraft:crying_obsidian,20,minecraft:obsidian,100)
RB(10,5,12,minecraft:crying_obsidian,20,minecraft:obsidian,100)
RB(11,5,12,minecraft:crying_obsidian,20,minecraft:obsidian,100)
RB(12,5,12,minecraft:crying_obsidian,20,minecraft:obsidian,100)
RB(13,5,12,minecraft:crying_obsidian,20,minecraft:obsidian,100)
RB(0,5,13,minecraft:crying_obsidian,20,minecraft:obsidian,100)
RB(1,5,13,minecraft:crying_obsidian,20,minecraft:obsidian,100)
RB(2,5,13,minecraft:crying_obsidian,20,minecraft:obsidian,100)
RB(3,5,13,minecraft:crying_obsidian,20,minecraft:obsidian,100)
RB(4,5,13,minecraft:crying_obsidian,20,minecraft:obsidian,100)
RB(5,5,13,minecraft:crying_obsidian,20,minecraft:obsidian,100)
RB(6,5,13,minecraft:crying_obsidian,20,minecraft:obsidian,100)
RB(7,5,13,minecraft:crying_obsidian,20,minecraft:obsidian,100)
RB(8,5,13,minecraft:crying_obsidian,20,minecraft:obsidian,100)
RB(9,5,13,minecraft:crying_obsidian,20,minecraft:obsidian,100)
RB(10,5,13,minecraft:crying_obsidian,20,minecraft:obsidian,100)
RB(11,5,13,minecraft:crying_obsidian,20,minecraft:obsidian,100)
RB(12,5,13,minecraft:crying_obsidian,20,minecraft:obsidian,100)
RB(13,5,13,minecraft:crying_obsidian,20,minecraft:obsidian,100)
RB(14,5,13,minecraft:crying_obsidian,20,minecraft:obsidian,100)
RB(15,5,13,minecraft:crying_obsidian,20,minecraft:obsidian,100)
RB(0,5,14,minecraft:crying_obsidian,20,minecraft:obsidian,100)
RB(1,5,14,minecraft:crying_obsidian,20,minecraft:obsidian,100)
RB(2,5,14,minecraft:crying_obsidian,20,minecraft:obsidian,100)
RB(3,5,14,minecraft:crying_obsidian,20,minecraft:obsidian,100)
RB(4,5,14,minecraft:crying_obsidian,20,minecraft:obsidian,100)
RB(5,5,14,minecraft:crying_obsidian,20,minecraft:obsidian,100)
RB(6,5,14,minecraft:crying_obsidian,20,minecraft:obsidian,100)
RB(7,5,14,minecraft:crying_obsidian,20,minecraft:obsidian,100)
RB(8,5,14,minecraft:crying_obsidian,20,minecraft:obsidian,100)
RB(9,5,14,minecraft:crying_obsidian,20,minecraft:obsidian,100)
RB(10,5,14,minecraft:crying_obsidian,20,minecraft:obsidian,100)
RB(11,5,14,minecraft:crying_obsidian,20,minecraft:obsidian,100)
RB(12,5,14,minecraft:crying_obsidian,20,minecraft:obsidian,100)
RB(13,5,14,minecraft:crying_obsidian,20,minecraft:obsidian,100)
RB(14,5,14,minecraft:crying_obsidian,20,minecraft:obsidian,100)
RB(15,5,14,minecraft:crying_obsidian,20,minecraft:obsidian,100)
RB(0,5,15,minecraft:crying_obsidian,20,minecraft:obsidian,100)
RB(1,5,15,minecraft:crying_obsidian,20,minecraft:obsidian,100)
RB(2,5,15,minecraft:crying_obsidian,20,minecraft:obsidian,100)
RB(3,5,15,minecraft:crying_obsidian,20,minecraft:obsidian,100)
RB(4,5,15,minecraft:crying_obsidian,20,minecraft:obsidian,100)
RB(5,5,15,minecraft:crying_obsidian,20,minecraft:obsidian,100)
RB(6,5,15,minecraft:crying_obsidian,20,minecraft:obsidian,100)
RB(7,5,15,minecraft:crying_obsidian,20,minecraft:obsidian,100)
RB(8,5,15,minecraft:crying_obsidian,20,minecraft:obsidian,100)
RB(9,5,15,minecraft:crying_obsidian,20,minecraft:obsidian,100)
RB(10,5,15,minecraft:crying_obsidian,20,minecraft:obsidian,100)
RB(11,5,15,minecraft:crying_obsidian,20,minecraft:obsidian,100)
RB(12,5,15,minecraft:crying_obsidian,20,minecraft:obsidian,100)
RB(13,5,15,minecraft:crying_obsidian,20,minecraft:obsidian,100)
RB(14,5,15,minecraft:crying_obsidian,20,minecraft:obsidian,100)
RB(15,5,15,minecraft:crying_obsidian,20,minecraft:obsidian,100)
RB(8,6,9,minecraft:crying_obsidian,20,minecraft:obsidian,100)
RB(9,6,9,minecraft:crying_obsidian,20,minecraft:obsidian,100)
RB(10,6,9,minecraft:crying_obsidian,20,minecraft:obsidian,100)
RB(7,6,10,minecraft:crying_obsidian,20,minecraft:obsidian,100)
RB(8,6,10,minecraft:crying_obsidian,20,minecraft:obsidian,100)
RB(9,6,10,minecraft:crying_obsidian,20,minecraft:obsidian,100)
RB(10,6,10,minecraft:crying_obsidian,20,minecraft:obsidian,100)
RB(11,6,10,minecraft:crying_obsidian,20,minecraft:obsidian,100)
RB(0,6,11,minecraft:crying_obsidian,20,minecraft:obsidian,100)
RB(1,6,11,minecraft:crying_obsidian,20,minecraft:obsidian,100)
RB(2,6,11,minecraft:crying_obsidian,20,minecraft:obsidian,100)
RB(3,6,11,minecraft:crying_obsidian,20,minecraft:obsidian,100)
RB(4,6,11,minecraft:crying_obsidian,20,minecraft:obsidian,100)
RB(5,6,11,minecraft:crying_obsidian,20,minecraft:obsidian,100)
RB(6,6,11,minecraft:crying_obsidian,20,minecraft:obsidian,100)
RB(7,6,11,minecraft:crying_obsidian,20,minecraft:obsidian,100)
RB(8,6,11,minecraft:crying_obsidian,20,minecraft:obsidian,100)
RB(9,6,11,minecraft:crying_obsidian,20,minecraft:obsidian,100)
RB(10,6,11,minecraft:crying_obsidian,20,minecraft:obsidian,100)
RB(11,6,11,minecraft:crying_obsidian,20,minecraft:obsidian,100)
RB(0,6,12,minecraft:crying_obsidian,20,minecraft:obsidian,100)
RB(1,6,12,minecraft:crying_obsidian,20,minecraft:obsidian,100)
RB(2,6,12,minecraft:crying_obsidian,20,minecraft:obsidian,100)
RB(3,6,12,minecraft:crying_obsidian,20,minecraft:obsidian,100)
RB(4,6,12,minecraft:crying_obsidian,20,minecraft:obsidian,100)
RB(5,6,12,minecraft:crying_obsidian,20,minecraft:obsidian,100)
RB(6,6,12,minecraft:crying_obsidian,20,minecraft:obsidian,100)
RB(7,6,12,minecraft:crying_obsidian,20,minecraft:obsidian,100)
RB(8,6,12,minecraft:crying_obsidian,20,minecraft:obsidian,100)
RB(9,6,12,minecraft:crying_obsidian,20,minecraft:obsidian,100)
RB(10,6,12,minecraft:crying_obsidian,20,minecraft:obsidian,100)
RB(11,6,12,minecraft:crying_obsidian,20,minecraft:obsidian,100)
RB(12,6,12,minecraft:crying_obsidian,20,minecraft:obsidian,100)
RB(13,6,12,minecraft:crying_obsidian,20,minecraft:obsidian,100)
RB(0,6,13,minecraft:crying_obsidian,20,minecraft:obsidian,100)
RB(1,6,13,minecraft:crying_obsidian,20,minecraft:obsidian,100)
RB(2,6,13,minecraft:crying_obsidian,20,minecraft:obsidian,100)
RB(3,6,13,minecraft:crying_obsidian,20,minecraft:obsidian,100)
RB(4,6,13,minecraft:crying_obsidian,20,minecraft:obsidian,100)
RB(5,6,13,minecraft:crying_obsidian,20,minecraft:obsidian,100)
RB(6,6,13,minecraft:crying_obsidian,20,minecraft:obsidian,100)
RB(7,6,13,minecraft:crying_obsidian,20,minecraft:obsidian,100)
RB(8,6,13,minecraft:crying_obsidian,20,minecraft:obsidian,100)
RB(9,6,13,minecraft:crying_obsidian,20,minecraft:obsidian,100)
RB(10,6,13,minecraft:crying_obsidian,20,minecraft:obsidian,100)
RB(11,6,13,minecraft:crying_obsidian,20,minecraft:obsidian,100)
RB(12,6,13,minecraft:crying_obsidian,20,minecraft:obsidian,100)
RB(13,6,13,minecraft:crying_obsidian,20,minecraft:obsidian,100)
RB(14,6,13,minecraft:crying_obsidian,20,minecraft:obsidian,100)
RB(0,6,14,minecraft:crying_obsidian,20,minecraft:obsidian,100)
RB(1,6,14,minecraft:crying_obsidian,20,minecraft:obsidian,100)
RB(2,6,14,minecraft:crying_obsidian,20,minecraft:obsidian,100)
RB(3,6,14,minecraft:crying_obsidian,20,minecraft:obsidian,100)
RB(4,6,14,minecraft:crying_obsidian,20,minecraft:obsidian,100)
RB(5,6,14,minecraft:crying_obsidian,20,minecraft:obsidian,100)
RB(6,6,14,minecraft:crying_obsidian,20,minecraft:obsidian,100)
RB(7,6,14,minecraft:crying_obsidian,20,minecraft:obsidian,100)
RB(8,6,14,minecraft:crying_obsidian,20,minecraft:obsidian,100)
RB(9,6,14,minecraft:crying_obsidian,20,minecraft:obsidian,100)
RB(10,6,14,minecraft:crying_obsidian,20,minecraft:obsidian,100)
RB(11,6,14,minecraft:crying_obsidian,20,minecraft:obsidian,100)
RB(12,6,14,minecraft:crying_obsidian,20,minecraft:obsidian,100)
RB(13,6,14,minecraft:crying_obsidian,20,minecraft:obsidian,100)
RB(14,6,14,minecraft:crying_obsidian,20,minecraft:obsidian,100)
RB(15,6,14,minecraft:crying_obsidian,20,minecraft:obsidian,100)
RB(0,6,15,minecraft:crying_obsidian,20,minecraft:obsidian,100)
RB(1,6,15,minecraft:crying_obsidian,20,minecraft:obsidian,100)
RB(2,6,15,minecraft:crying_obsidian,20,minecraft:obsidian,100)
RB(3,6,15,minecraft:crying_obsidian,20,minecraft:obsidian,100)
RB(4,6,15,minecraft:crying_obsidian,20,minecraft:obsidian,100)
RB(5,6,15,minecraft:crying_obsidian,20,minecraft:obsidian,100)
RB(6,6,15,minecraft:crying_obsidian,20,minecraft:obsidian,100)
RB(7,6,15,minecraft:crying_obsidian,20,minecraft:obsidian,100)
RB(8,6,15,minecraft:crying_obsidian,20,minecraft:obsidian,100)
RB(9,6,15,minecraft:crying_obsidian,20,minecraft:obsidian,100)
RB(10,6,15,minecraft:crying_obsidian,20,minecraft:obsidian,100)
RB(11,6,15,minecraft:crying_obsidian,20,minecraft:obsidian,100)
RB(12,6,15,minecraft:crying_obsidian,20,minecraft:obsidian,100)
RB(13,6,15,minecraft:crying_obsidian,20,minecraft:obsidian,100)
RB(14,6,15,minecraft:crying_obsidian,20,minecraft:obsidian,100)
RB(15,6,15,minecraft:crying_obsidian,20,minecraft:obsidian,100)
RB(0,7,11,minecraft:crying_obsidian,20,minecraft:obsidian,100)
RB(1,7,11,minecraft:crying_obsidian,20,minecraft:obsidian,100)
RB(2,7,11,minecraft:crying_obsidian,20,minecraft:obsidian,100)
RB(3,7,11,minecraft:crying_obsidian,20,minecraft:obsidian,100)
RB(4,7,11,minecraft:crying_obsidian,20,minecraft:obsidian,100)
RB(5,7,11,minecraft:crying_obsidian,20,minecraft:obsidian,100)
RB(6,7,11,minecraft:crying_obsidian,20,minecraft:obsidian,100)
RB(7,7,11,minecraft:crying_obsidian,20,minecraft:obsidian,100)
RB(0,7,12,minecraft:crying_obsidian,20,minecraft:obsidian,100)
RB(1,7,12,minecraft:crying_obsidian,20,minecraft:obsidian,100)
RB(2,7,12,minecraft:crying_obsidian,20,minecraft:obsidian,100)
RB(3,7,12,minecraft:crying_obsidian,20,minecraft:obsidian,100)
RB(4,7,12,minecraft:crying_obsidian,20,minecraft:obsidian,100)
RB(5,7,12,minecraft:crying_obsidian,20,minecraft:obsidian,100)
RB(6,7,12,minecraft:crying_obsidian,20,minecraft:obsidian,100)
RB(7,7,12,minecraft:crying_obsidian,20,minecraft:obsidian,100)
RB(8,7,12,minecraft:crying_obsidian,20,minecraft:obsidian,100)
RB(9,7,12,minecraft:crying_obsidian,20,minecraft:obsidian,100)
RB(10,7,12,minecraft:crying_obsidian,20,minecraft:obsidian,100)
RB(11,7,12,minecraft:crying_obsidian,20,minecraft:obsidian,100)
RB(12,7,12,minecraft:crying_obsidian,20,minecraft:obsidian,100)
RB(13,7,12,minecraft:crying_obsidian,20,minecraft:obsidian,100)
RB(0,7,13,minecraft:crying_obsidian,20,minecraft:obsidian,100)
RB(1,7,13,minecraft:crying_obsidian,20,minecraft:obsidian,100)
RB(2,7,13,minecraft:crying_obsidian,20,minecraft:obsidian,100)
RB(3,7,13,minecraft:crying_obsidian,20,minecraft:obsidian,100)
RB(4,7,13,minecraft:crying_obsidian,20,minecraft:obsidian,100)
RB(5,7,13,minecraft:crying_obsidian,20,minecraft:obsidian,100)
RB(6,7,13,minecraft:crying_obsidian,20,minecraft:obsidian,100)
RB(7,7,13,minecraft:crying_obsidian,20,minecraft:obsidian,100)
RB(8,7,13,minecraft:crying_obsidian,20,minecraft:obsidian,100)
RB(9,7,13,minecraft:crying_obsidian,20,minecraft:obsidian,100)
RB(10,7,13,minecraft:crying_obsidian,20,minecraft:obsidian,100)
RB(11,7,13,minecraft:crying_obsidian,20,minecraft:obsidian,100)
RB(12,7,13,minecraft:crying_obsidian,20,minecraft:obsidian,100)
RB(13,7,13,minecraft:crying_obsidian,20,minecraft:obsidian,100)
RB(14,7,13,minecraft:crying_obsidian,20,minecraft:obsidian,100)
RB(0,7,14,minecraft:crying_obsidian,20,minecraft:obsidian,100)
RB(1,7,14,minecraft:crying_obsidian,20,minecraft:obsidian,100)
RB(2,7,14,minecraft:crying_obsidian,20,minecraft:obsidian,100)
RB(3,7,14,minecraft:crying_obsidian,20,minecraft:obsidian,100)
RB(4,7,14,minecraft:crying_obsidian,20,minecraft:obsidian,100)
RB(5,7,14,minecraft:crying_obsidian,20,minecraft:obsidian,100)
RB(6,7,14,minecraft:crying_obsidian,20,minecraft:obsidian,100)
RB(7,7,14,minecraft:crying_obsidian,20,minecraft:obsidian,100)
RB(8,7,14,minecraft:crying_obsidian,20,minecraft:obsidian,100)
RB(9,7,14,minecraft:crying_obsidian,20,minecraft:obsidian,100)
RB(10,7,14,minecraft:crying_obsidian,20,minecraft:obsidian,100)
RB(11,7,14,minecraft:crying_obsidian,20,minecraft:obsidian,100)
RB(12,7,14,minecraft:crying_obsidian,20,minecraft:obsidian,100)
RB(13,7,14,minecraft:crying_obsidian,20,minecraft:obsidian,100)
RB(14,7,14,minecraft:crying_obsidian,20,minecraft:obsidian,100)
RB(15,7,14,minecraft:crying_obsidian,20,minecraft:obsidian,100)
RB(0,7,15,minecraft:crying_obsidian,20,minecraft:obsidian,100)
RB(1,7,15,minecraft:crying_obsidian,20,minecraft:obsidian,100)
RB(2,7,15,minecraft:crying_obsidian,20,minecraft:obsidian,100)
RB(3,7,15,minecraft:crying_obsidian,20,minecraft:obsidian,100)
RB(4,7,15,minecraft:crying_obsidian,20,minecraft:obsidian,100)
RB(5,7,15,minecraft:crying_obsidian,20,minecraft:obsidian,100)
RB(6,7,15,minecraft:crying_obsidian,20,minecraft:obsidian,100)
RB(7,7,15,minecraft:crying_obsidian,20,minecraft:obsidian,100)
RB(8,7,15,minecraft:crying_obsidian,20,minecraft:obsidian,100)
RB(9,7,15,minecraft:crying_obsidian,20,minecraft:obsidian,100)
RB(10,7,15,minecraft:crying_obsidian,20,minecraft:obsidian,100)
RB(11,7,15,minecraft:crying_obsidian,20,minecraft:obsidian,100)
RB(12,7,15,minecraft:crying_obsidian,20,minecraft:obsidian,100)
RB(13,7,15,minecraft:crying_obsidian,20,minecraft:obsidian,100)
RB(14,7,15,minecraft:crying_obsidian,20,minecraft:obsidian,100)
RB(15,7,15,minecraft:crying_obsidian,20,minecraft:obsidian,100)
RB(0,8,11,minecraft:crying_obsidian,20,minecraft:obsidian,100)
RB(4,8,11,minecraft:crying_obsidian,20,minecraft:obsidian,100)
RB(5,8,11,minecraft:crying_obsidian,20,minecraft:obsidian,100)
RB(6,8,11,minecraft:crying_obsidian,20,minecraft:obsidian,100)
RB(7,8,11,minecraft:crying_obsidian,20,minecraft:obsidian,100)
RB(0,8,12,minecraft:crying_obsidian,20,minecraft:obsidian,100)
RB(1,8,12,minecraft:crying_obsidian,20,minecraft:obsidian,100)
RB(2,8,12,minecraft:crying_obsidian,20,minecraft:obsidian,100)
RB(3,8,12,minecraft:crying_obsidian,20,minecraft:obsidian,100)
RB(4,8,12,minecraft:crying_obsidian,20,minecraft:obsidian,100)
RB(5,8,12,minecraft:crying_obsidian,20,minecraft:obsidian,100)
RB(6,8,12,minecraft:crying_obsidian,20,minecraft:obsidian,100)
RB(7,8,12,minecraft:crying_obsidian,20,minecraft:obsidian,100)
RB(8,8,12,minecraft:crying_obsidian,20,minecraft:obsidian,100)
RB(9,8,12,minecraft:crying_obsidian,20,minecraft:obsidian,100)
RB(10,8,12,minecraft:crying_obsidian,20,minecraft:obsidian,100)
RB(11,8,12,minecraft:crying_obsidian,20,minecraft:obsidian,100)
RB(12,8,12,minecraft:crying_obsidian,20,minecraft:obsidian,100)
RB(13,8,12,minecraft:crying_obsidian,20,minecraft:obsidian,100)
RB(0,8,13,minecraft:crying_obsidian,20,minecraft:obsidian,100)
RB(1,8,13,minecraft:crying_obsidian,20,minecraft:obsidian,100)
RB(2,8,13,minecraft:crying_obsidian,20,minecraft:obsidian,100)
RB(3,8,13,minecraft:crying_obsidian,20,minecraft:obsidian,100)
RB(4,8,13,minecraft:crying_obsidian,20,minecraft:obsidian,100)
RB(5,8,13,minecraft:crying_obsidian,20,minecraft:obsidian,100)
RB(6,8,13,minecraft:crying_obsidian,20,minecraft:obsidian,100)
RB(7,8,13,minecraft:crying_obsidian,20,minecraft:obsidian,100)
RB(8,8,13,minecraft:crying_obsidian,20,minecraft:obsidian,100)
RB(9,8,13,minecraft:crying_obsidian,20,minecraft:obsidian,100)
RB(10,8,13,minecraft:crying_obsidian,20,minecraft:obsidian,100)
RB(11,8,13,minecraft:crying_obsidian,20,minecraft:obsidian,100)
RB(12,8,13,minecraft:crying_obsidian,20,minecraft:obsidian,100)
RB(13,8,13,minecraft:crying_obsidian,20,minecraft:obsidian,100)
RB(14,8,13,minecraft:crying_obsidian,20,minecraft:obsidian,100)
RB(0,8,14,minecraft:crying_obsidian,20,minecraft:obsidian,100)
RB(1,8,14,minecraft:crying_obsidian,20,minecraft:obsidian,100)
RB(2,8,14,minecraft:crying_obsidian,20,minecraft:obsidian,100)
RB(3,8,14,minecraft:crying_obsidian,20,minecraft:obsidian,100)
RB(4,8,14,minecraft:crying_obsidian,20,minecraft:obsidian,100)
RB(5,8,14,minecraft:crying_obsidian,20,minecraft:obsidian,100)
RB(6,8,14,minecraft:crying_obsidian,20,minecraft:obsidian,100)
RB(7,8,14,minecraft:crying_obsidian,20,minecraft:obsidian,100)
RB(8,8,14,minecraft:crying_obsidian,20,minecraft:obsidian,100)
RB(9,8,14,minecraft:crying_obsidian,20,minecraft:obsidian,100)
RB(10,8,14,minecraft:crying_obsidian,20,minecraft:obsidian,100)
RB(11,8,14,minecraft:crying_obsidian,20,minecraft:obsidian,100)
RB(12,8,14,minecraft:crying_obsidian,20,minecraft:obsidian,100)
RB(13,8,14,minecraft:crying_obsidian,20,minecraft:obsidian,100)
RB(14,8,14,minecraft:crying_obsidian,20,minecraft:obsidian,100)
RB(15,8,14,minecraft:crying_obsidian,20,minecraft:obsidian,100)
RB(0,8,15,minecraft:crying_obsidian,20,minecraft:obsidian,100)
RB(1,8,15,minecraft:crying_obsidian,20,minecraft:obsidian,100)
RB(2,8,15,minecraft:crying_obsidian,20,minecraft:obsidian,100)
RB(3,8,15,minecraft:crying_obsidian,20,minecraft:obsidian,100)
RB(4,8,15,minecraft:crying_obsidian,20,minecraft:obsidian,100)
RB(5,8,15,minecraft:crying_obsidian,20,minecraft:obsidian,100)
RB(6,8,15,minecraft:crying_obsidian,20,minecraft:obsidian,100)
RB(7,8,15,minecraft:crying_obsidian,20,minecraft:obsidian,100)
RB(8,8,15,minecraft:crying_obsidian,20,minecraft:obsidian,100)
RB(9,8,15,minecraft:crying_obsidian,20,minecraft:obsidian,100)
RB(10,8,15,minecraft:crying_obsidian,20,minecraft:obsidian,100)
RB(11,8,15,minecraft:crying_obsidian,20,minecraft:obsidian,100)
RB(12,8,15,minecraft:crying_obsidian,20,minecraft:obsidian,100)
RB(13,8,15,minecraft:crying_obsidian,20,minecraft:obsidian,100)
RB(14,8,15,minecraft:crying_obsidian,20,minecraft:obsidian,100)
RB(15,8,15,minecraft:crying_obsidian,20,minecraft:obsidian,100)
RB(0,9,11,minecraft:crying_obsidian,20,minecraft:obsidian,100)
RB(5,9,11,minecraft:crying_obsidian,20,minecraft:obsidian,100)
RB(6,9,11,minecraft:crying_obsidian,20,minecraft:obsidian,100)
RB(7,9,11,minecraft:crying_obsidian,20,minecraft:obsidian,100)
RB(0,9,12,minecraft:crying_obsidian,20,minecraft:obsidian,100)
RB(1,9,12,minecraft:crying_obsidian,20,minecraft:obsidian,100)
RB(2,9,12,minecraft:crying_obsidian,20,minecraft:obsidian,100)
RB(3,9,12,minecraft:crying_obsidian,20,minecraft:obsidian,100)
RB(4,9,12,minecraft:crying_obsidian,20,minecraft:obsidian,100)
RB(5,9,12,minecraft:crying_obsidian,20,minecraft:obsidian,100)
RB(6,9,12,minecraft:crying_obsidian,20,minecraft:obsidian,100)
RB(7,9,12,minecraft:crying_obsidian,20,minecraft:obsidian,100)
RB(8,9,12,minecraft:crying_obsidian,20,minecraft:obsidian,100)
RB(9,9,12,minecraft:crying_obsidian,20,minecraft:obsidian,100)
RB(10,9,12,minecraft:crying_obsidian,20,minecraft:obsidian,100)
RB(11,9,12,minecraft:crying_obsidian,20,minecraft:obsidian,100)
RB(12,9,12,minecraft:crying_obsidian,20,minecraft:obsidian,100)
RB(13,9,12,minecraft:crying_obsidian,20,minecraft:obsidian,100)
RB(0,9,13,minecraft:crying_obsidian,20,minecraft:obsidian,100)
RB(1,9,13,minecraft:crying_obsidian,20,minecraft:obsidian,100)
RB(2,9,13,minecraft:crying_obsidian,20,minecraft:obsidian,100)
RB(3,9,13,minecraft:crying_obsidian,20,minecraft:obsidian,100)
RB(4,9,13,minecraft:crying_obsidian,20,minecraft:obsidian,100)
RB(5,9,13,minecraft:crying_obsidian,20,minecraft:obsidian,100)
RB(6,9,13,minecraft:crying_obsidian,20,minecraft:obsidian,100)
RB(7,9,13,minecraft:crying_obsidian,20,minecraft:obsidian,100)
RB(8,9,13,minecraft:crying_obsidian,20,minecraft:obsidian,100)
RB(9,9,13,minecraft:crying_obsidian,20,minecraft:obsidian,100)
RB(10,9,13,minecraft:crying_obsidian,20,minecraft:obsidian,100)
RB(11,9,13,minecraft:crying_obsidian,20,minecraft:obsidian,100)
RB(12,9,13,minecraft:crying_obsidian,20,minecraft:obsidian,100)
RB(13,9,13,minecraft:crying_obsidian,20,minecraft:obsidian,100)
RB(14,9,13,minecraft:crying_obsidian,20,minecraft:obsidian,100)
RB(0,9,14,minecraft:crying_obsidian,20,minecraft:obsidian,100)
RB(1,9,14,minecraft:crying_obsidian,20,minecraft:obsidian,100)
RB(2,9,14,minecraft:crying_obsidian,20,minecraft:obsidian,100)
RB(3,9,14,minecraft:crying_obsidian,20,minecraft:obsidian,100)
RB(4,9,14,minecraft:crying_obsidian,20,minecraft:obsidian,100)
RB(5,9,14,minecraft:crying_obsidian,20,minecraft:obsidian,100)
RB(6,9,14,minecraft:crying_obsidian,20,minecraft:obsidian,100)
RB(7,9,14,minecraft:crying_obsidian,20,minecraft:obsidian,100)
RB(8,9,14,minecraft:crying_obsidian,20,minecraft:obsidian,100)
RB(9,9,14,minecraft:crying_obsidian,20,minecraft:obsidian,100)
RB(10,9,14,minecraft:crying_obsidian,20,minecraft:obsidian,100)
RB(11,9,14,minecraft:crying_obsidian,20,minecraft:obsidian,100)
RB(12,9,14,minecraft:crying_obsidian,20,minecraft:obsidian,100)
RB(13,9,14,minecraft:crying_obsidian,20,minecraft:obsidian,100)
RB(14,9,14,minecraft:crying_obsidian,20,minecraft:obsidian,100)
RB(15,9,14,minecraft:crying_obsidian,20,minecraft:obsidian,100)
RB(0,9,15,minecraft:crying_obsidian,20,minecraft:obsidian,100)
RB(1,9,15,minecraft:crying_obsidian,20,minecraft:obsidian,100)
RB(2,9,15,minecraft:crying_obsidian,20,minecraft:obsidian,100)
RB(3,9,15,minecraft:crying_obsidian,20,minecraft:obsidian,100)
RB(4,9,15,minecraft:crying_obsidian,20,minecraft:obsidian,100)
RB(5,9,15,minecraft:crying_obsidian,20,minecraft:obsidian,100)
RB(6,9,15,minecraft:crying_obsidian,20,minecraft:obsidian,100)
RB(7,9,15,minecraft:crying_obsidian,20,minecraft:obsidian,100)
RB(8,9,15,minecraft:crying_obsidian,20,minecraft:obsidian,100)
RB(9,9,15,minecraft:crying_obsidian,20,minecraft:obsidian,100)
RB(10,9,15,minecraft:crying_obsidian,20,minecraft:obsidian,100)
RB(11,9,15,minecraft:crying_obsidian,20,minecraft:obsidian,100)
RB(12,9,15,minecraft:crying_obsidian,20,minecraft:obsidian,100)
RB(13,9,15,minecraft:crying_obsidian,20,minecraft:obsidian,100)
RB(14,9,15,minecraft:crying_obsidian,20,minecraft:obsidian,100)
RB(15,9,15,minecraft:crying_obsidian,20,minecraft:obsidian,100)
RB(6,10,11,minecraft:crying_obsidian,20,minecraft:obsidian,100)
RB(0,10,12,minecraft:crying_obsidian,20,minecraft:obsidian,100)
RB(1,10,12,minecraft:crying_obsidian,20,minecraft:obsidian,100)
RB(2,10,12,minecraft:crying_obsidian,20,minecraft:obsidian,100)
RB(3,10,12,minecraft:crying_obsidian,20,minecraft:obsidian,100)
RB(4,10,12,minecraft:crying_obsidian,20,minecraft:obsidian,100)
RB(5,10,12,minecraft:crying_obsidian,20,minecraft:obsidian,100)
RB(6,10,12,minecraft:crying_obsidian,20,minecraft:obsidian,100)
RB(7,10,12,minecraft:crying_obsidian,20,minecraft:obsidian,100)
RB(8,10,12,minecraft:crying_obsidian,20,minecraft:obsidian,100)
RB(9,10,12,minecraft:crying_obsidian,20,minecraft:obsidian,100)
RB(10,10,12,minecraft:crying_obsidian,20,minecraft:obsidian,100)
RB(11,10,12,minecraft:crying_obsidian,20,minecraft:obsidian,100)
RB(12,10,12,minecraft:crying_obsidian,20,minecraft:obsidian,100)
RB(0,10,13,minecraft:crying_obsidian,20,minecraft:obsidian,100)
RB(1,10,13,minecraft:crying_obsidian,20,minecraft:obsidian,100)
RB(2,10,13,minecraft:crying_obsidian,20,minecraft:obsidian,100)
RB(3,10,13,minecraft:crying_obsidian,20,minecraft:obsidian,100)
RB(4,10,13,minecraft:crying_obsidian,20,minecraft:obsidian,100)
RB(5,10,13,minecraft:crying_obsidian,20,minecraft:obsidian,100)
RB(6,10,13,minecraft:crying_obsidian,20,minecraft:obsidian,100)
RB(7,10,13,minecraft:crying_obsidian,20,minecraft:obsidian,100)
RB(8,10,13,minecraft:crying_obsidian,20,minecraft:obsidian,100)
RB(9,10,13,minecraft:crying_obsidian,20,minecraft:obsidian,100)
RB(10,10,13,minecraft:crying_obsidian,20,minecraft:obsidian,100)
RB(11,10,13,minecraft:crying_obsidian,20,minecraft:obsidian,100)
RB(12,10,13,minecraft:crying_obsidian,20,minecraft:obsidian,100)
RB(13,10,13,minecraft:crying_obsidian,20,minecraft:obsidian,100)
RB(14,10,13,minecraft:crying_obsidian,20,minecraft:obsidian,100)
RB(0,10,14,minecraft:crying_obsidian,20,minecraft:obsidian,100)
RB(1,10,14,minecraft:crying_obsidian,20,minecraft:obsidian,100)
RB(2,10,14,minecraft:crying_obsidian,20,minecraft:obsidian,100)
RB(3,10,14,minecraft:crying_obsidian,20,minecraft:obsidian,100)
RB(4,10,14,minecraft:crying_obsidian,20,minecraft:obsidian,100)
RB(5,10,14,minecraft:crying_obsidian,20,minecraft:obsidian,100)
RB(6,10,14,minecraft:crying_obsidian,20,minecraft:obsidian,100)
RB(7,10,14,minecraft:crying_obsidian,20,minecraft:obsidian,100)
RB(8,10,14,minecraft:crying_obsidian,20,minecraft:obsidian,100)
RB(9,10,14,minecraft:crying_obsidian,20,minecraft:obsidian,100)
RB(10,10,14,minecraft:crying_obsidian,20,minecraft:obsidian,100)
RB(11,10,14,minecraft:crying_obsidian,20,minecraft:obsidian,100)
RB(12,10,14,minecraft:crying_obsidian,20,minecraft:obsidian,100)
RB(13,10,14,minecraft:crying_obsidian,20,minecraft:obsidian,100)
RB(14,10,14,minecraft:crying_obsidian,20,minecraft:obsidian,100)
RB(15,10,14,minecraft:crying_obsidian,20,minecraft:obsidian,100)
RB(0,10,15,minecraft:crying_obsidian,20,minecraft:obsidian,100)
RB(1,10,15,minecraft:crying_obsidian,20,minecraft:obsidian,100)
RB(2,10,15,minecraft:crying_obsidian,20,minecraft:obsidian,100)
RB(3,10,15,minecraft:crying_obsidian,20,minecraft:obsidian,100)
RB(4,10,15,minecraft:crying_obsidian,20,minecraft:obsidian,100)
RB(5,10,15,minecraft:crying_obsidian,20,minecraft:obsidian,100)
RB(6,10,15,minecraft:crying_obsidian,20,minecraft:obsidian,100)
RB(7,10,15,minecraft:crying_obsidian,20,minecraft:obsidian,100)
RB(8,10,15,minecraft:crying_obsidian,20,minecraft:obsidian,100)
RB(9,10,15,minecraft:crying_obsidian,20,minecraft:obsidian,100)
RB(10,10,15,minecraft:crying_obsidian,20,minecraft:obsidian,100)
RB(11,10,15,minecraft:crying_obsidian,20,minecraft:obsidian,100)
RB(12,10,15,minecraft:crying_obsidian,20,minecraft:obsidian,100)
RB(13,10,15,minecraft:crying_obsidian,20,minecraft:obsidian,100)
RB(14,10,15,minecraft:crying_obsidian,20,minecraft:obsidian,100)
RB(15,10,15,minecraft:crying_obsidian,20,minecraft:obsidian,100)
RB(1,11,12,minecraft:crying_obsidian,20,minecraft:obsidian,100)
RB(2,11,12,minecraft:crying_obsidian,20,minecraft:obsidian,100)
RB(3,11,12,minecraft:crying_obsidian,20,minecraft:obsidian,100)
RB(4,11,12,minecraft:crying_obsidian,20,minecraft:obsidian,100)
RB(5,11,12,minecraft:crying_obsidian,20,minecraft:obsidian,100)
RB(6,11,12,minecraft:crying_obsidian,20,minecraft:obsidian,100)
RB(7,11,12,minecraft:crying_obsidian,20,minecraft:obsidian,100)
RB(8,11,12,minecraft:crying_obsidian,20,minecraft:obsidian,100)
RB(10,11,12,minecraft:crying_obsidian,20,minecraft:obsidian,100)
RB(11,11,12,minecraft:crying_obsidian,20,minecraft:obsidian,100)
RB(12,11,12,minecraft:crying_obsidian,20,minecraft:obsidian,100)
RB(0,11,13,minecraft:crying_obsidian,20,minecraft:obsidian,100)
RB(1,11,13,minecraft:crying_obsidian,20,minecraft:obsidian,100)
RB(2,11,13,minecraft:crying_obsidian,20,minecraft:obsidian,100)
RB(3,11,13,minecraft:crying_obsidian,20,minecraft:obsidian,100)
RB(4,11,13,minecraft:crying_obsidian,20,minecraft:obsidian,100)
RB(5,11,13,minecraft:crying_obsidian,20,minecraft:obsidian,100)
RB(6,11,13,minecraft:crying_obsidian,20,minecraft:obsidian,100)
RB(7,11,13,minecraft:crying_obsidian,20,minecraft:obsidian,100)
RB(8,11,13,minecraft:crying_obsidian,20,minecraft:obsidian,100)
RB(9,11,13,minecraft:crying_obsidian,20,minecraft:obsidian,100)
RB(10,11,13,minecraft:crying_obsidian,20,minecraft:obsidian,100)
RB(11,11,13,minecraft:crying_obsidian,20,minecraft:obsidian,100)
RB(12,11,13,minecraft:crying_obsidian,20,minecraft:obsidian,100)
RB(13,11,13,minecraft:crying_obsidian,20,minecraft:obsidian,100)
RB(14,11,13,minecraft:crying_obsidian,20,minecraft:obsidian,100)
RB(0,11,14,minecraft:crying_obsidian,20,minecraft:obsidian,100)
RB(1,11,14,minecraft:crying_obsidian,20,minecraft:obsidian,100)
RB(2,11,14,minecraft:crying_obsidian,20,minecraft:obsidian,100)
RB(3,11,14,minecraft:crying_obsidian,20,minecraft:obsidian,100)
RB(4,11,14,minecraft:crying_obsidian,20,minecraft:obsidian,100)
RB(5,11,14,minecraft:crying_obsidian,20,minecraft:obsidian,100)
RB(6,11,14,minecraft:crying_obsidian,20,minecraft:obsidian,100)
RB(7,11,14,minecraft:crying_obsidian,20,minecraft:obsidian,100)
RB(8,11,14,minecraft:crying_obsidian,20,minecraft:obsidian,100)
RB(9,11,14,minecraft:crying_obsidian,20,minecraft:obsidian,100)
RB(10,11,14,minecraft:crying_obsidian,20,minecraft:obsidian,100)
RB(11,11,14,minecraft:crying_obsidian,20,minecraft:obsidian,100)
RB(12,11,14,minecraft:crying_obsidian,20,minecraft:obsidian,100)
RB(13,11,14,minecraft:crying_obsidian,20,minecraft:obsidian,100)
RB(14,11,14,minecraft:crying_obsidian,20,minecraft:obsidian,100)
RB(15,11,14,minecraft:crying_obsidian,20,minecraft:obsidian,100)
RB(0,11,15,minecraft:crying_obsidian,20,minecraft:obsidian,100)
RB(1,11,15,minecraft:crying_obsidian,20,minecraft:obsidian,100)
RB(2,11,15,minecraft:crying_obsidian,20,minecraft:obsidian,100)
RB(3,11,15,minecraft:crying_obsidian,20,minecraft:obsidian,100)
RB(4,11,15,minecraft:crying_obsidian,20,minecraft:obsidian,100)
RB(5,11,15,minecraft:crying_obsidian,20,minecraft:obsidian,100)
RB(6,11,15,minecraft:crying_obsidian,20,minecraft:obsidian,100)
RB(7,11,15,minecraft:crying_obsidian,20,minecraft:obsidian,100)
RB(8,11,15,minecraft:crying_obsidian,20,minecraft:obsidian,100)
RB(9,11,15,minecraft:crying_obsidian,20,minecraft:obsidian,100)
RB(10,11,15,minecraft:crying_obsidian,20,minecraft:obsidian,100)
RB(11,11,15,minecraft:crying_obsidian,20,minecraft:obsidian,100)
RB(12,11,15,minecraft:crying_obsidian,20,minecraft:obsidian,100)
RB(13,11,15,minecraft:crying_obsidian,20,minecraft:obsidian,100)
RB(14,11,15,minecraft:crying_obsidian,20,minecraft:obsidian,100)
RB(15,11,15,minecraft:crying_obsidian,20,minecraft:obsidian,100)
RB(1,12,12,minecraft:crying_obsidian,20,minecraft:obsidian,100)
RB(2,12,12,minecraft:crying_obsidian,20,minecraft:obsidian,100)
RB(3,12,12,minecraft:crying_obsidian,20,minecraft:obsidian,100)
RB(4,12,12,minecraft:crying_obsidian,20,minecraft:obsidian,100)
RB(5,12,12,minecraft:crying_obsidian,20,minecraft:obsidian,100)
RB(6,12,12,minecraft:crying_obsidian,20,minecraft:obsidian,100)
RB(7,12,12,minecraft:crying_obsidian,20,minecraft:obsidian,100)
RB(10,12,12,minecraft:crying_obsidian,20,minecraft:obsidian,100)
RB(0,12,13,minecraft:crying_obsidian,20,minecraft:obsidian,100)
RB(1,12,13,minecraft:crying_obsidian,20,minecraft:obsidian,100)
RB(2,12,13,minecraft:crying_obsidian,20,minecraft:obsidian,100)
RB(3,12,13,minecraft:crying_obsidian,20,minecraft:obsidian,100)
RB(4,12,13,minecraft:crying_obsidian,20,minecraft:obsidian,100)
RB(5,12,13,minecraft:crying_obsidian,20,minecraft:obsidian,100)
RB(6,12,13,minecraft:crying_obsidian,20,minecraft:obsidian,100)
RB(7,12,13,minecraft:crying_obsidian,20,minecraft:obsidian,100)
RB(8,12,13,minecraft:crying_obsidian,20,minecraft:obsidian,100)
RB(9,12,13,minecraft:crying_obsidian,20,minecraft:obsidian,100)
RB(10,12,13,minecraft:crying_obsidian,20,minecraft:obsidian,100)
RB(11,12,13,minecraft:crying_obsidian,20,minecraft:obsidian,100)
RB(12,12,13,minecraft:crying_obsidian,20,minecraft:obsidian,100)
RB(13,12,13,minecraft:crying_obsidian,20,minecraft:obsidian,100)
RB(14,12,13,minecraft:crying_obsidian,20,minecraft:obsidian,100)
RB(0,12,14,minecraft:crying_obsidian,20,minecraft:obsidian,100)
RB(1,12,14,minecraft:crying_obsidian,20,minecraft:obsidian,100)
RB(2,12,14,minecraft:crying_obsidian,20,minecraft:obsidian,100)
RB(3,12,14,minecraft:crying_obsidian,20,minecraft:obsidian,100)
RB(4,12,14,minecraft:crying_obsidian,20,minecraft:obsidian,100)
RB(5,12,14,minecraft:crying_obsidian,20,minecraft:obsidian,100)
RB(6,12,14,minecraft:crying_obsidian,20,minecraft:obsidian,100)
RB(7,12,14,minecraft:crying_obsidian,20,minecraft:obsidian,100)
RB(8,12,14,minecraft:crying_obsidian,20,minecraft:obsidian,100)
RB(9,12,14,minecraft:crying_obsidian,20,minecraft:obsidian,100)
RB(10,12,14,minecraft:crying_obsidian,20,minecraft:obsidian,100)
RB(11,12,14,minecraft:crying_obsidian,20,minecraft:obsidian,100)
RB(12,12,14,minecraft:crying_obsidian,20,minecraft:obsidian,100)
RB(13,12,14,minecraft:crying_obsidian,20,minecraft:obsidian,100)
RB(14,12,14,minecraft:crying_obsidian,20,minecraft:obsidian,100)
RB(15,12,14,minecraft:crying_obsidian,20,minecraft:obsidian,100)
RB(0,12,15,minecraft:crying_obsidian,20,minecraft:obsidian,100)
RB(1,12,15,minecraft:crying_obsidian,20,minecraft:obsidian,100)
RB(2,12,15,minecraft:crying_obsidian,20,minecraft:obsidian,100)
RB(3,12,15,minecraft:crying_obsidian,20,minecraft:obsidian,100)
RB(4,12,15,minecraft:crying_obsidian,20,minecraft:obsidian,100)
RB(5,12,15,minecraft:crying_obsidian,20,minecraft:obsidian,100)
RB(6,12,15,minecraft:crying_obsidian,20,minecraft:obsidian,100)
RB(7,12,15,minecraft:crying_obsidian,20,minecraft:obsidian,100)
RB(8,12,15,minecraft:crying_obsidian,20,minecraft:obsidian,100)
RB(9,12,15,minecraft:crying_obsidian,20,minecraft:obsidian,100)
RB(10,12,15,minecraft:crying_obsidian,20,minecraft:obsidian,100)
RB(11,12,15,minecraft:crying_obsidian,20,minecraft:obsidian,100)
RB(12,12,15,minecraft:crying_obsidian,20,minecraft:obsidian,100)
RB(13,12,15,minecraft:crying_obsidian,20,minecraft:obsidian,100)
RB(14,12,15,minecraft:crying_obsidian,20,minecraft:obsidian,100)
RB(15,12,15,minecraft:crying_obsidian,20,minecraft:obsidian,100)
RB(2,13,12,minecraft:crying_obsidian,20,minecraft:obsidian,100)
RB(3,13,12,minecraft:crying_obsidian,20,minecraft:obsidian,100)
RB(4,13,12,minecraft:crying_obsidian,20,minecraft:obsidian,100)
RB(5,13,12,minecraft:crying_obsidian,20,minecraft:obsidian,100)
RB(7,13,12,minecraft:crying_obsidian,20,minecraft:obsidian,100)
RB(1,13,13,minecraft:crying_obsidian,20,minecraft:obsidian,100)
RB(2,13,13,minecraft:crying_obsidian,20,minecraft:obsidian,100)
RB(3,13,13,minecraft:crying_obsidian,20,minecraft:obsidian,100)
RB(4,13,13,minecraft:crying_obsidian,20,minecraft:obsidian,100)
RB(5,13,13,minecraft:crying_obsidian,20,minecraft:obsidian,100)
RB(6,13,13,minecraft:crying_obsidian,20,minecraft:obsidian,100)
RB(7,13,13,minecraft:crying_obsidian,20,minecraft:obsidian,100)
RB(8,13,13,minecraft:crying_obsidian,20,minecraft:obsidian,100)
RB(9,13,13,minecraft:crying_obsidian,20,minecraft:obsidian,100)
RB(10,13,13,minecraft:crying_obsidian,20,minecraft:obsidian,100)
RB(11,13,13,minecraft:crying_obsidian,20,minecraft:obsidian,100)
RB(12,13,13,minecraft:crying_obsidian,20,minecraft:obsidian,100)
RB(13,13,13,minecraft:crying_obsidian,20,minecraft:obsidian,100)
RB(0,13,14,minecraft:crying_obsidian,20,minecraft:obsidian,100)
RB(1,13,14,minecraft:crying_obsidian,20,minecraft:obsidian,100)
RB(2,13,14,minecraft:crying_obsidian,20,minecraft:obsidian,100)
RB(3,13,14,minecraft:crying_obsidian,20,minecraft:obsidian,100)
RB(4,13,14,minecraft:crying_obsidian,20,minecraft:obsidian,100)
RB(5,13,14,minecraft:crying_obsidian,20,minecraft:obsidian,100)
RB(6,13,14,minecraft:crying_obsidian,20,minecraft:obsidian,100)
RB(7,13,14,minecraft:crying_obsidian,20,minecraft:obsidian,100)
RB(8,13,14,minecraft:crying_obsidian,20,minecraft:obsidian,100)
RB(9,13,14,minecraft:crying_obsidian,20,minecraft:obsidian,100)
RB(10,13,14,minecraft:crying_obsidian,20,minecraft:obsidian,100)
RB(11,13,14,minecraft:crying_obsidian,20,minecraft:obsidian,100)
RB(12,13,14,minecraft:crying_obsidian,20,minecraft:obsidian,100)
RB(13,13,14,minecraft:crying_obsidian,20,minecraft:obsidian,100)
RB(14,13,14,minecraft:crying_obsidian,20,minecraft:obsidian,100)
RB(15,13,14,minecraft:crying_obsidian,20,minecraft:obsidian,100)
RB(0,13,15,minecraft:crying_obsidian,20,minecraft:obsidian,100)
RB(1,13,15,minecraft:crying_obsidian,20,minecraft:obsidian,100)
RB(2,13,15,minecraft:crying_obsidian,20,minecraft:obsidian,100)
RB(3,13,15,minecraft:crying_obsidian,20,minecraft:obsidian,100)
RB(4,13,15,minecraft:crying_obsidian,20,minecraft:obsidian,100)
RB(5,13,15,minecraft:crying_obsidian,20,minecraft:obsidian,100)
RB(6,13,15,minecraft:crying_obsidian,20,minecraft:obsidian,100)
RB(7,13,15,minecraft:crying_obsidian,20,minecraft:obsidian,100)
RB(8,13,15,minecraft:crying_obsidian,20,minecraft:obsidian,100)
RB(9,13,15,minecraft:crying_obsidian,20,minecraft:obsidian,100)
RB(10,13,15,minecraft:crying_obsidian,20,minecraft:obsidian,100)
RB(11,13,15,minecraft:crying_obsidian,20,minecraft:obsidian,100)
RB(12,13,15,minecraft:crying_obsidian,20,minecraft:obsidian,100)
RB(13,13,15,minecraft:crying_obsidian,20,minecraft:obsidian,100)
RB(14,13,15,minecraft:crying_obsidian,20,minecraft:obsidian,100)
RB(15,13,15,minecraft:crying_obsidian,20,minecraft:obsidian,100)
RB(4,14,12,minecraft:crying_obsidian,20,minecraft:obsidian,100)
RB(5,14,12,minecraft:crying_obsidian,20,minecraft:obsidian,100)
RB(1,14,13,minecraft:crying_obsidian,20,minecraft:obsidian,100)
RB(2,14,13,minecraft:crying_obsidian,20,minecraft:obsidian,100)
RB(3,14,13,minecraft:crying_obsidian,20,minecraft:obsidian,100)
RB(4,14,13,minecraft:crying_obsidian,20,minecraft:obsidian,100)
RB(5,14,13,minecraft:crying_obsidian,20,minecraft:obsidian,100)
RB(6,14,13,minecraft:crying_obsidian,20,minecraft:obsidian,100)
RB(7,14,13,minecraft:crying_obsidian,20,minecraft:obsidian,100)
RB(8,14,13,minecraft:crying_obsidian,20,minecraft:obsidian,100)
RB(9,14,13,minecraft:crying_obsidian,20,minecraft:obsidian,100)
RB(10,14,13,minecraft:crying_obsidian,20,minecraft:obsidian,100)
RB(11,14,13,minecraft:crying_obsidian,20,minecraft:obsidian,100)
RB(12,14,13,minecraft:crying_obsidian,20,minecraft:obsidian,100)
RB(13,14,13,minecraft:crying_obsidian,20,minecraft:obsidian,100)
RB(1,14,14,minecraft:crying_obsidian,20,minecraft:obsidian,100)
RB(2,14,14,minecraft:crying_obsidian,20,minecraft:obsidian,100)
RB(3,14,14,minecraft:crying_obsidian,20,minecraft:obsidian,100)
RB(4,14,14,minecraft:crying_obsidian,20,minecraft:obsidian,100)
RB(5,14,14,minecraft:crying_obsidian,20,minecraft:obsidian,100)
RB(6,14,14,minecraft:crying_obsidian,20,minecraft:obsidian,100)
RB(7,14,14,minecraft:crying_obsidian,20,minecraft:obsidian,100)
RB(8,14,14,minecraft:crying_obsidian,20,minecraft:obsidian,100)
RB(9,14,14,minecraft:crying_obsidian,20,minecraft:obsidian,100)
RB(10,14,14,minecraft:crying_obsidian,20,minecraft:obsidian,100)
RB(11,14,14,minecraft:crying_obsidian,20,minecraft:obsidian,100)
RB(12,14,14,minecraft:crying_obsidian,20,minecraft:obsidian,100)
RB(13,14,14,minecraft:crying_obsidian,20,minecraft:obsidian,100)
RB(14,14,14,minecraft:crying_obsidian,20,minecraft:obsidian,100)
RB(15,14,14,minecraft:crying_obsidian,20,minecraft:obsidian,100)
RB(0,14,15,minecraft:crying_obsidian,20,minecraft:obsidian,100)
RB(1,14,15,minecraft:crying_obsidian,20,minecraft:obsidian,100)
RB(2,14,15,minecraft:crying_obsidian,20,minecraft:obsidian,100)
RB(3,14,15,minecraft:crying_obsidian,20,minecraft:obsidian,100)
RB(4,14,15,minecraft:crying_obsidian,20,minecraft:obsidian,100)
RB(5,14,15,minecraft:crying_obsidian,20,minecraft:obsidian,100)
RB(6,14,15,minecraft:crying_obsidian,20,minecraft:obsidian,100)
RB(7,14,15,minecraft:crying_obsidian,20,minecraft:obsidian,100)
RB(8,14,15,minecraft:crying_obsidian,20,minecraft:obsidian,100)
RB(9,14,15,minecraft:crying_obsidian,20,minecraft:obsidian,100)
RB(10,14,15,minecraft:crying_obsidian,20,minecraft:obsidian,100)
RB(11,14,15,minecraft:crying_obsidian,20,minecraft:obsidian,100)
RB(12,14,15,minecraft:crying_obsidian,20,minecraft:obsidian,100)
RB(13,14,15,minecraft:crying_obsidian,20,minecraft:obsidian,100)
RB(14,14,15,minecraft:crying_obsidian,20,minecraft:obsidian,100)
RB(15,14,15,minecraft:crying_obsidian,20,minecraft:obsidian,100)
RB(4,15,12,minecraft:crying_obsidian,20,minecraft:obsidian,100)
RB(4,15,13,minecraft:crying_obsidian,20,minecraft:obsidian,100)
RB(5,15,13,minecraft:crying_obsidian,20,minecraft:obsidian,100)
RB(6,15,13,minecraft:crying_obsidian,20,minecraft:obsidian,100)
RB(7,15,13,minecraft:crying_obsidian,20,minecraft:obsidian,100)
RB(8,15,13,minecraft:crying_obsidian,20,minecraft:obsidian,100)
RB(9,15,13,minecraft:crying_obsidian,20,minecraft:obsidian,100)
RB(10,15,13,minecraft:crying_obsidian,20,minecraft:obsidian,100)
RB(11,15,13,minecraft:crying_obsidian,20,minecraft:obsidian,100)
RB(12,15,13,minecraft:crying_obsidian,20,minecraft:obsidian,100)
RB(13,15,13,minecraft:crying_obsidian,20,minecraft:obsidian,100)
RB(1,15,14,minecraft:crying_obsidian,20,minecraft:obsidian,100)
RB(2,15,14,minecraft:crying_obsidian,20,minecraft:obsidian,100)
RB(3,15,14,minecraft:crying_obsidian,20,minecraft:obsidian,100)
RB(4,15,14,minecraft:crying_obsidian,20,minecraft:obsidian,100)
RB(5,15,14,minecraft:crying_obsidian,20,minecraft:obsidian,100)
RB(6,15,14,minecraft:crying_obsidian,20,minecraft:obsidian,100)
RB(7,15,14,minecraft:crying_obsidian,20,minecraft:obsidian,100)
RB(8,15,14,minecraft:crying_obsidian,20,minecraft:obsidian,100)
RB(9,15,14,minecraft:crying_obsidian,20,minecraft:obsidian,100)
RB(10,15,14,minecraft:crying_obsidian,20,minecraft:obsidian,100)
RB(11,15,14,minecraft:crying_obsidian,20,minecraft:obsidian,100)
RB(12,15,14,minecraft:crying_obsidian,20,minecraft:obsidian,100)
RB(13,15,14,minecraft:crying_obsidian,20,minecraft:obsidian,100)
RB(14,15,14,minecraft:crying_obsidian,20,minecraft:obsidian,100)
RB(15,15,14,minecraft:crying_obsidian,20,minecraft:obsidian,100)
RB(0,15,15,minecraft:crying_obsidian,20,minecraft:obsidian,100)
RB(1,15,15,minecraft:crying_obsidian,20,minecraft:obsidian,100)
RB(2,15,15,minecraft:crying_obsidian,20,minecraft:obsidian,100)
RB(3,15,15,minecraft:crying_obsidian,20,minecraft:obsidian,100)
RB(4,15,15,minecraft:crying_obsidian,20,minecraft:obsidian,100)
RB(5,15,15,minecraft:crying_obsidian,20,minecraft:obsidian,100)
RB(6,15,15,minecraft:crying_obsidian,20,minecraft:obsidian,100)
RB(7,15,15,minecraft:crying_obsidian,20,minecraft:obsidian,100)
RB(8,15,15,minecraft:crying_obsidian,20,minecraft:obsidian,100)
RB(9,15,15,minecraft:crying_obsidian,20,minecraft:obsidian,100)
RB(10,15,15,minecraft:crying_obsidian,20,minecraft:obsidian,100)
RB(11,15,15,minecraft:crying_obsidian,20,minecraft:obsidian,100)
RB(12,15,15,minecraft:crying_obsidian,20,minecraft:obsidian,100)
RB(13,15,15,minecraft:crying_obsidian,20,minecraft:obsidian,100)
RB(14,15,15,minecraft:crying_obsidian,20,minecraft:obsidian,100)
RB(15,15,15,minecraft:crying_obsidian,20,minecraft:obsidian,100)
RB(4,16,12,minecraft:crying_obsidian,20,minecraft:obsidian,100)
RB(4,16,13,minecraft:crying_obsidian,20,minecraft:obsidian,100)
RB(5,16,13,minecraft:crying_obsidian,20,minecraft:obsidian,100)
RB(6,16,13,minecraft:crying_obsidian,20,minecraft:obsidian,100)
RB(8,16,13,minecraft:crying_obsidian,20,minecraft:obsidian,100)
RB(9,16,13,minecraft:crying_obsidian,20,minecraft:obsidian,100)
RB(3,16,14,minecraft:crying_obsidian,20,minecraft:obsidian,100)
RB(4,16,14,minecraft:crying_obsidian,20,minecraft:obsidian,100)
RB(5,16,14,minecraft:crying_obsidian,20,minecraft:obsidian,100)
RB(6,16,14,minecraft:crying_obsidian,20,minecraft:obsidian,100)
RB(7,16,14,minecraft:crying_obsidian,20,minecraft:obsidian,100)
RB(8,16,14,minecraft:crying_obsidian,20,minecraft:obsidian,100)
RB(9,16,14,minecraft:crying_obsidian,20,minecraft:obsidian,100)
RB(10,16,14,minecraft:crying_obsidian,20,minecraft:obsidian,100)
RB(11,16,14,minecraft:crying_obsidian,20,minecraft:obsidian,100)
RB(12,16,14,minecraft:crying_obsidian,20,minecraft:obsidian,100)
RB(13,16,14,minecraft:crying_obsidian,20,minecraft:obsidian,100)
RB(14,16,14,minecraft:crying_obsidian,20,minecraft:obsidian,100)
RB(15,16,14,minecraft:crying_obsidian,20,minecraft:obsidian,100)
RB(1,16,15,minecraft:crying_obsidian,20,minecraft:obsidian,100)
RB(2,16,15,minecraft:crying_obsidian,20,minecraft:obsidian,100)
RB(3,16,15,minecraft:crying_obsidian,20,minecraft:obsidian,100)
RB(4,16,15,minecraft:crying_obsidian,20,minecraft:obsidian,100)
RB(5,16,15,minecraft:crying_obsidian,20,minecraft:obsidian,100)
RB(6,16,15,minecraft:crying_obsidian,20,minecraft:obsidian,100)
RB(7,16,15,minecraft:crying_obsidian,20,minecraft:obsidian,100)
RB(8,16,15,minecraft:crying_obsidian,20,minecraft:obsidian,100)
RB(9,16,15,minecraft:crying_obsidian,20,minecraft:obsidian,100)
RB(10,16,15,minecraft:crying_obsidian,20,minecraft:obsidian,100)
RB(11,16,15,minecraft:crying_obsidian,20,minecraft:obsidian,100)
RB(12,16,15,minecraft:crying_obsidian,20,minecraft:obsidian,100)
RB(13,16,15,minecraft:crying_obsidian,20,minecraft:obsidian,100)
RB(14,16,15,minecraft:crying_obsidian,20,minecraft:obsidian,100)
RB(15,16,15,minecraft:crying_obsidian,20,minecraft:obsidian,100)
RB(4,17,12,minecraft:crying_obsidian,20,minecraft:obsidian,100)
RB(4,17,13,minecraft:crying_obsidian,20,minecraft:obsidian,100)
RB(5,17,13,minecraft:crying_obsidian,20,minecraft:obsidian,100)
RB(6,17,13,minecraft:crying_obsidian,20,minecraft:obsidian,100)
RB(8,17,13,minecraft:crying_obsidian,20,minecraft:obsidian,100)
RB(9,17,13,minecraft:crying_obsidian,20,minecraft:obsidian,100)
RB(4,17,14,minecraft:crying_obsidian,20,minecraft:obsidian,100)
RB(5,17,14,minecraft:crying_obsidian,20,minecraft:obsidian,100)
RB(6,17,14,minecraft:crying_obsidian,20,minecraft:obsidian,100)
RB(7,17,14,minecraft:crying_obsidian,20,minecraft:obsidian,100)
RB(8,17,14,minecraft:crying_obsidian,20,minecraft:obsidian,100)
RB(9,17,14,minecraft:crying_obsidian,20,minecraft:obsidian,100)
RB(10,17,14,minecraft:crying_obsidian,20,minecraft:obsidian,100)
RB(11,17,14,minecraft:crying_obsidian,20,minecraft:obsidian,100)
RB(12,17,14,minecraft:crying_obsidian,20,minecraft:obsidian,100)
RB(13,17,14,minecraft:crying_obsidian,20,minecraft:obsidian,100)
RB(14,17,14,minecraft:crying_obsidian,20,minecraft:obsidian,100)
RB(15,17,14,minecraft:crying_obsidian,20,minecraft:obsidian,100)
RB(3,17,15,minecraft:crying_obsidian,20,minecraft:obsidian,100)
RB(4,17,15,minecraft:crying_obsidian,20,minecraft:obsidian,100)
RB(5,17,15,minecraft:crying_obsidian,20,minecraft:obsidian,100)
RB(6,17,15,minecraft:crying_obsidian,20,minecraft:obsidian,100)
RB(7,17,15,minecraft:crying_obsidian,20,minecraft:obsidian,100)
RB(8,17,15,minecraft:crying_obsidian,20,minecraft:obsidian,100)
RB(9,17,15,minecraft:crying_obsidian,20,minecraft:obsidian,100)
RB(10,17,15,minecraft:crying_obsidian,20,minecraft:obsidian,100)
RB(11,17,15,minecraft:crying_obsidian,20,minecraft:obsidian,100)
RB(12,17,15,minecraft:crying_obsidian,20,minecraft:obsidian,100)
RB(13,17,15,minecraft:crying_obsidian,20,minecraft:obsidian,100)
RB(14,17,15,minecraft:crying_obsidian,20,minecraft:obsidian,100)
RB(15,17,15,minecraft:crying_obsidian,20,minecraft:obsidian,100)
RB(4,18,13,minecraft:crying_obsidian,20,minecraft:obsidian,100)
RB(5,18,13,minecraft:crying_obsidian,20,minecraft:obsidian,100)
RB(6,18,13,minecraft:crying_obsidian,20,minecraft:obsidian,100)
RB(9,18,13,minecraft:crying_obsidian,20,minecraft:obsidian,100)
RB(4,18,14,minecraft:crying_obsidian,20,minecraft:obsidian,100)
RB(5,18,14,minecraft:crying_obsidian,20,minecraft:obsidian,100)
RB(6,18,14,minecraft:crying_obsidian,20,minecraft:obsidian,100)
RB(8,18,14,minecraft:crying_obsidian,20,minecraft:obsidian,100)
RB(9,18,14,minecraft:crying_obsidian,20,minecraft:obsidian,100)
RB(10,18,14,minecraft:crying_obsidian,20,minecraft:obsidian,100)
RB(11,18,14,minecraft:crying_obsidian,20,minecraft:obsidian,100)
RB(12,18,14,minecraft:crying_obsidian,20,minecraft:obsidian,100)
RB(13,18,14,minecraft:crying_obsidian,20,minecraft:obsidian,100)
RB(14,18,14,minecraft:crying_obsidian,20,minecraft:obsidian,100)
RB(4,18,15,minecraft:crying_obsidian,20,minecraft:obsidian,100)
RB(5,18,15,minecraft:crying_obsidian,20,minecraft:obsidian,100)
RB(6,18,15,minecraft:crying_obsidian,20,minecraft:obsidian,100)
RB(7,18,15,minecraft:crying_obsidian,20,minecraft:obsidian,100)
RB(8,18,15,minecraft:crying_obsidian,20,minecraft:obsidian,100)
RB(9,18,15,minecraft:crying_obsidian,20,minecraft:obsidian,100)
RB(10,18,15,minecraft:crying_obsidian,20,minecraft:obsidian,100)
RB(11,18,15,minecraft:crying_obsidian,20,minecraft:obsidian,100)
RB(12,18,15,minecraft:crying_obsidian,20,minecraft:obsidian,100)
RB(13,18,15,minecraft:crying_obsidian,20,minecraft:obsidian,100)
RB(14,18,15,minecraft:crying_obsidian,20,minecraft:obsidian,100)
RB(15,18,15,minecraft:crying_obsidian,20,minecraft:obsidian,100)
RB(4,19,14,minecraft:crying_obsidian,20,minecraft:obsidian,100)
RB(5,19,14,minecraft:crying_obsidian,20,minecraft:obsidian,100)
RB(6,19,14,minecraft:crying_obsidian,20,minecraft:obsidian,100)
RB(9,19,14,minecraft:crying_obsidian,20,minecraft:obsidian,100)
RB(10,19,14,minecraft:crying_obsidian,20,minecraft:obsidian,100)
RB(11,19,14,minecraft:crying_obsidian,20,minecraft:obsidian,100)
RB(4,19,15,minecraft:crying_obsidian,20,minecraft:obsidian,100)
RB(5,19,15,minecraft:crying_obsidian,20,minecraft:obsidian,100)
RB(6,19,15,minecraft:crying_obsidian,20,minecraft:obsidian,100)
RB(7,19,15,minecraft:crying_obsidian,20,minecraft:obsidian,100)
RB(8,19,15,minecraft:crying_obsidian,20,minecraft:obsidian,100)
RB(9,19,15,minecraft:crying_obsidian,20,minecraft:obsidian,100)
RB(10,19,15,minecraft:crying_obsidian,20,minecraft:obsidian,100)
RB(11,19,15,minecraft:crying_obsidian,20,minecraft:obsidian,100)
RB(12,19,15,minecraft:crying_obsidian,20,minecraft:obsidian,100)
RB(13,19,15,minecraft:crying_obsidian,20,minecraft:obsidian,100)
RB(5,20,14,minecraft:crying_obsidian,20,minecraft:obsidian,100)
RB(6,20,14,minecraft:crying_obsidian,20,minecraft:obsidian,100)
RB(9,20,14,minecraft:crying_obsidian,20,minecraft:obsidian,100)
RB(4,20,15,minecraft:crying_obsidian,20,minecraft:obsidian,100)
RB(5,20,15,minecraft:crying_obsidian,20,minecraft:obsidian,100)
RB(6,20,15,minecraft:crying_obsidian,20,minecraft:obsidian,100)
RB(7,20,15,minecraft:crying_obsidian,20,minecraft:obsidian,100)
RB(8,20,15,minecraft:crying_obsidian,20,minecraft:obsidian,100)
RB(9,20,15,minecraft:crying_obsidian,20,minecraft:obsidian,100)
RB(10,20,15,minecraft:crying_obsidian,20,minecraft:obsidian,100)
RB(11,20,15,minecraft:crying_obsidian,20,minecraft:obsidian,100)
RB(6,21,15,minecraft:crying_obsidian,20,minecraft:obsidian,100)
RB(7,21,15,minecraft:crying_obsidian,20,minecraft:obsidian,100)
RB(8,21,15,minecraft:crying_obsidian,20,minecraft:obsidian,100)
RB(9,21,15,minecraft:crying_obsidian,20,minecraft:obsidian,100)

#######################################################################
# +-----------------------------------------------------------------+ #
# |                             Branches                            | #
# +-----------------------------------------------------------------+ #
#######################################################################

BR(-16,0,0,true,ObsidianOozingMountain2_1x0,NORTH,100,0)
BR(-16,0,0,true,ObsidianOozingMountain2_3x0,NORTH,100,0)
