#######################################################################
# +-----------------------------------------------------------------+ #
# |                            BO3 object                           | #
# +-----------------------------------------------------------------+ #
#######################################################################

Author: Bo3 BulkEdit

Description: Converted Schematic - Modified by Bo3BulkEdit

Version: 3

SettingsMode: WriteDisable

#######################################################################
# +-----------------------------------------------------------------+ #
# |                          Main settings                          | #
# +-----------------------------------------------------------------+ #
#######################################################################

IsOTGPlus: true
Tree: true
Frequency: 10
Rarity: 100
RotateRandomly: true
SpawnHeight: randomY
SpawnHeightOffset: 0
SpawnHeightVariance: 0
MaxBranchDepth: 10
ExcludedBiomes: All

##############################
# Height Limits for the BO3. #
##############################

MinHeight: 50
MaxHeight: 65

#######################################################################
# +-----------------------------------------------------------------+ #
# |                      Source block settings                      | #
# +-----------------------------------------------------------------+ #
#######################################################################

SourceBlocks: AIR
MaxPercentageOutsideSourceBlock: 100
OutsideSourceBlock: placeAnyway

#######################################################################
# +-----------------------------------------------------------------+ #
# |                               OTG+                              | #
# +-----------------------------------------------------------------+ #
#######################################################################

RemoveAir: true
ReplaceBelow: OBSIDIAN
ReplaceWithBiomeBlocks: false
ReplaceWithGroundBlock: OBSIDIAN
ReplaceWithSurfaceBlock: OBSIDIAN
ReplaceWithStoneBlock: OBSIDIAN
SmoothRadius: 30
SmoothingSurfaceBlock: OBSIDIAN
SmoothingGroundBlock: OBSIDIAN

#######################################################################
# +-----------------------------------------------------------------+ #
# |                              Blocks                             | #
# +-----------------------------------------------------------------+ #
#######################################################################

RB(15,0,5,minecraft:crying_obsidian,20,minecraft:obsidian,100)
RB(13,0,6,minecraft:crying_obsidian,20,minecraft:obsidian,100)
RB(14,0,6,minecraft:crying_obsidian,20,minecraft:obsidian,100)
RB(15,0,6,minecraft:crying_obsidian,20,minecraft:obsidian,100)
RB(10,0,7,minecraft:crying_obsidian,20,minecraft:obsidian,100)
RB(11,0,7,minecraft:crying_obsidian,20,minecraft:obsidian,100)
RB(12,0,7,minecraft:crying_obsidian,20,minecraft:obsidian,100)
RB(13,0,7,minecraft:crying_obsidian,20,minecraft:obsidian,100)
RB(14,0,7,minecraft:crying_obsidian,20,minecraft:obsidian,100)
RB(15,0,7,minecraft:crying_obsidian,20,minecraft:obsidian,100)
RB(9,0,8,minecraft:crying_obsidian,20,minecraft:obsidian,100)
RB(10,0,8,minecraft:crying_obsidian,20,minecraft:obsidian,100)
RB(11,0,8,minecraft:crying_obsidian,20,minecraft:obsidian,100)
RB(12,0,8,minecraft:crying_obsidian,20,minecraft:obsidian,100)
RB(13,0,8,minecraft:crying_obsidian,20,minecraft:obsidian,100)
RB(14,0,8,minecraft:crying_obsidian,20,minecraft:obsidian,100)
RB(15,0,8,minecraft:crying_obsidian,20,minecraft:obsidian,100)
RB(8,0,9,minecraft:crying_obsidian,20,minecraft:obsidian,100)
RB(9,0,9,minecraft:crying_obsidian,20,minecraft:obsidian,100)
RB(10,0,9,minecraft:crying_obsidian,20,minecraft:obsidian,100)
RB(11,0,9,minecraft:crying_obsidian,20,minecraft:obsidian,100)
RB(12,0,9,minecraft:crying_obsidian,20,minecraft:obsidian,100)
RB(13,0,9,minecraft:crying_obsidian,20,minecraft:obsidian,100)
RB(14,0,9,minecraft:crying_obsidian,20,minecraft:obsidian,100)
RB(15,0,9,minecraft:crying_obsidian,20,minecraft:obsidian,100)
RB(8,0,10,minecraft:crying_obsidian,20,minecraft:obsidian,100)
RB(9,0,10,minecraft:crying_obsidian,20,minecraft:obsidian,100)
RB(10,0,10,minecraft:crying_obsidian,20,minecraft:obsidian,100)
RB(11,0,10,minecraft:crying_obsidian,20,minecraft:obsidian,100)
RB(12,0,10,minecraft:crying_obsidian,20,minecraft:obsidian,100)
RB(13,0,10,minecraft:crying_obsidian,20,minecraft:obsidian,100)
RB(14,0,10,minecraft:crying_obsidian,20,minecraft:obsidian,100)
RB(15,0,10,minecraft:crying_obsidian,20,minecraft:obsidian,100)
RB(8,0,11,minecraft:crying_obsidian,20,minecraft:obsidian,100)
RB(9,0,11,minecraft:crying_obsidian,20,minecraft:obsidian,100)
RB(10,0,11,minecraft:crying_obsidian,20,minecraft:obsidian,100)
RB(11,0,11,minecraft:crying_obsidian,20,minecraft:obsidian,100)
RB(12,0,11,minecraft:crying_obsidian,20,minecraft:obsidian,100)
RB(13,0,11,minecraft:crying_obsidian,20,minecraft:obsidian,100)
RB(14,0,11,minecraft:crying_obsidian,20,minecraft:obsidian,100)
RB(15,0,11,minecraft:crying_obsidian,20,minecraft:obsidian,100)
RB(8,0,12,minecraft:crying_obsidian,20,minecraft:obsidian,100)
RB(9,0,12,minecraft:crying_obsidian,20,minecraft:obsidian,100)
RB(10,0,12,minecraft:crying_obsidian,20,minecraft:obsidian,100)
RB(11,0,12,minecraft:crying_obsidian,20,minecraft:obsidian,100)
RB(12,0,12,minecraft:crying_obsidian,20,minecraft:obsidian,100)
RB(13,0,12,minecraft:crying_obsidian,20,minecraft:obsidian,100)
RB(14,0,12,minecraft:crying_obsidian,20,minecraft:obsidian,100)
RB(15,0,12,minecraft:crying_obsidian,20,minecraft:obsidian,100)
RB(8,0,13,minecraft:crying_obsidian,20,minecraft:obsidian,100)
RB(9,0,13,minecraft:crying_obsidian,20,minecraft:obsidian,100)
RB(10,0,13,minecraft:crying_obsidian,20,minecraft:obsidian,100)
RB(11,0,13,minecraft:crying_obsidian,20,minecraft:obsidian,100)
RB(12,0,13,minecraft:crying_obsidian,20,minecraft:obsidian,100)
RB(13,0,13,minecraft:crying_obsidian,20,minecraft:obsidian,100)
RB(14,0,13,minecraft:crying_obsidian,20,minecraft:obsidian,100)
RB(15,0,13,minecraft:crying_obsidian,20,minecraft:obsidian,100)
RB(9,0,14,minecraft:crying_obsidian,20,minecraft:obsidian,100)
RB(10,0,14,minecraft:crying_obsidian,20,minecraft:obsidian,100)
RB(11,0,14,minecraft:crying_obsidian,20,minecraft:obsidian,100)
RB(12,0,14,minecraft:crying_obsidian,20,minecraft:obsidian,100)
RB(13,0,14,minecraft:crying_obsidian,20,minecraft:obsidian,100)
RB(14,0,14,minecraft:crying_obsidian,20,minecraft:obsidian,100)
RB(15,0,14,minecraft:crying_obsidian,20,minecraft:obsidian,100)
RB(8,0,15,minecraft:crying_obsidian,20,minecraft:obsidian,100)
RB(9,0,15,minecraft:crying_obsidian,20,minecraft:obsidian,100)
RB(10,0,15,minecraft:crying_obsidian,20,minecraft:obsidian,100)
RB(11,0,15,minecraft:crying_obsidian,20,minecraft:obsidian,100)
RB(12,0,15,minecraft:crying_obsidian,20,minecraft:obsidian,100)
RB(13,0,15,minecraft:crying_obsidian,20,minecraft:obsidian,100)
RB(14,0,15,minecraft:crying_obsidian,20,minecraft:obsidian,100)
RB(15,0,15,minecraft:crying_obsidian,20,minecraft:obsidian,100)
RB(13,1,6,minecraft:crying_obsidian,20,minecraft:obsidian,100)
RB(14,1,6,minecraft:crying_obsidian,20,minecraft:obsidian,100)
RB(15,1,6,minecraft:crying_obsidian,20,minecraft:obsidian,100)
RB(12,1,7,minecraft:crying_obsidian,20,minecraft:obsidian,100)
RB(13,1,7,minecraft:crying_obsidian,20,minecraft:obsidian,100)
RB(14,1,7,minecraft:crying_obsidian,20,minecraft:obsidian,100)
RB(15,1,7,minecraft:crying_obsidian,20,minecraft:obsidian,100)
RB(10,1,8,minecraft:crying_obsidian,20,minecraft:obsidian,100)
RB(11,1,8,minecraft:crying_obsidian,20,minecraft:obsidian,100)
RB(12,1,8,minecraft:crying_obsidian,20,minecraft:obsidian,100)
RB(13,1,8,minecraft:crying_obsidian,20,minecraft:obsidian,100)
RB(14,1,8,minecraft:crying_obsidian,20,minecraft:obsidian,100)
RB(15,1,8,minecraft:crying_obsidian,20,minecraft:obsidian,100)
RB(9,1,9,minecraft:crying_obsidian,20,minecraft:obsidian,100)
RB(10,1,9,minecraft:crying_obsidian,20,minecraft:obsidian,100)
RB(11,1,9,minecraft:crying_obsidian,20,minecraft:obsidian,100)
RB(12,1,9,minecraft:crying_obsidian,20,minecraft:obsidian,100)
RB(13,1,9,minecraft:crying_obsidian,20,minecraft:obsidian,100)
RB(14,1,9,minecraft:crying_obsidian,20,minecraft:obsidian,100)
RB(15,1,9,minecraft:crying_obsidian,20,minecraft:obsidian,100)
RB(9,1,10,minecraft:crying_obsidian,20,minecraft:obsidian,100)
RB(10,1,10,minecraft:crying_obsidian,20,minecraft:obsidian,100)
RB(11,1,10,minecraft:crying_obsidian,20,minecraft:obsidian,100)
RB(12,1,10,minecraft:crying_obsidian,20,minecraft:obsidian,100)
RB(13,1,10,minecraft:crying_obsidian,20,minecraft:obsidian,100)
RB(14,1,10,minecraft:crying_obsidian,20,minecraft:obsidian,100)
RB(15,1,10,minecraft:crying_obsidian,20,minecraft:obsidian,100)
RB(9,1,11,minecraft:crying_obsidian,20,minecraft:obsidian,100)
RB(10,1,11,minecraft:crying_obsidian,20,minecraft:obsidian,100)
RB(11,1,11,minecraft:crying_obsidian,20,minecraft:obsidian,100)
RB(12,1,11,minecraft:crying_obsidian,20,minecraft:obsidian,100)
RB(13,1,11,minecraft:crying_obsidian,20,minecraft:obsidian,100)
RB(14,1,11,minecraft:crying_obsidian,20,minecraft:obsidian,100)
RB(15,1,11,minecraft:crying_obsidian,20,minecraft:obsidian,100)
RB(9,1,12,minecraft:crying_obsidian,20,minecraft:obsidian,100)
RB(10,1,12,minecraft:crying_obsidian,20,minecraft:obsidian,100)
RB(11,1,12,minecraft:crying_obsidian,20,minecraft:obsidian,100)
RB(12,1,12,minecraft:crying_obsidian,20,minecraft:obsidian,100)
RB(13,1,12,minecraft:crying_obsidian,20,minecraft:obsidian,100)
RB(14,1,12,minecraft:crying_obsidian,20,minecraft:obsidian,100)
RB(15,1,12,minecraft:crying_obsidian,20,minecraft:obsidian,100)
RB(9,1,13,minecraft:crying_obsidian,20,minecraft:obsidian,100)
RB(10,1,13,minecraft:crying_obsidian,20,minecraft:obsidian,100)
RB(11,1,13,minecraft:crying_obsidian,20,minecraft:obsidian,100)
RB(12,1,13,minecraft:crying_obsidian,20,minecraft:obsidian,100)
RB(13,1,13,minecraft:crying_obsidian,20,minecraft:obsidian,100)
RB(14,1,13,minecraft:crying_obsidian,20,minecraft:obsidian,100)
RB(15,1,13,minecraft:crying_obsidian,20,minecraft:obsidian,100)
RB(9,1,14,minecraft:crying_obsidian,20,minecraft:obsidian,100)
RB(10,1,14,minecraft:crying_obsidian,20,minecraft:obsidian,100)
RB(11,1,14,minecraft:crying_obsidian,20,minecraft:obsidian,100)
RB(12,1,14,minecraft:crying_obsidian,20,minecraft:obsidian,100)
RB(13,1,14,minecraft:crying_obsidian,20,minecraft:obsidian,100)
RB(14,1,14,minecraft:crying_obsidian,20,minecraft:obsidian,100)
RB(15,1,14,minecraft:crying_obsidian,20,minecraft:obsidian,100)
RB(8,1,15,minecraft:crying_obsidian,20,minecraft:obsidian,100)
RB(9,1,15,minecraft:crying_obsidian,20,minecraft:obsidian,100)
RB(10,1,15,minecraft:crying_obsidian,20,minecraft:obsidian,100)
RB(11,1,15,minecraft:crying_obsidian,20,minecraft:obsidian,100)
RB(12,1,15,minecraft:crying_obsidian,20,minecraft:obsidian,100)
RB(13,1,15,minecraft:crying_obsidian,20,minecraft:obsidian,100)
RB(14,1,15,minecraft:crying_obsidian,20,minecraft:obsidian,100)
RB(15,1,15,minecraft:crying_obsidian,20,minecraft:obsidian,100)
RB(13,2,6,minecraft:crying_obsidian,20,minecraft:obsidian,100)
RB(14,2,6,minecraft:crying_obsidian,20,minecraft:obsidian,100)
RB(15,2,6,minecraft:crying_obsidian,20,minecraft:obsidian,100)
RB(12,2,7,minecraft:crying_obsidian,20,minecraft:obsidian,100)
RB(13,2,7,minecraft:crying_obsidian,20,minecraft:obsidian,100)
RB(14,2,7,minecraft:crying_obsidian,20,minecraft:obsidian,100)
RB(15,2,7,minecraft:crying_obsidian,20,minecraft:obsidian,100)
RB(12,2,8,minecraft:crying_obsidian,20,minecraft:obsidian,100)
RB(13,2,8,minecraft:crying_obsidian,20,minecraft:obsidian,100)
RB(14,2,8,minecraft:crying_obsidian,20,minecraft:obsidian,100)
RB(15,2,8,minecraft:crying_obsidian,20,minecraft:obsidian,100)
RB(11,2,9,minecraft:crying_obsidian,20,minecraft:obsidian,100)
RB(12,2,9,minecraft:crying_obsidian,20,minecraft:obsidian,100)
RB(13,2,9,minecraft:crying_obsidian,20,minecraft:obsidian,100)
RB(14,2,9,minecraft:crying_obsidian,20,minecraft:obsidian,100)
RB(15,2,9,minecraft:crying_obsidian,20,minecraft:obsidian,100)
RB(10,2,10,minecraft:crying_obsidian,20,minecraft:obsidian,100)
RB(11,2,10,minecraft:crying_obsidian,20,minecraft:obsidian,100)
RB(12,2,10,minecraft:crying_obsidian,20,minecraft:obsidian,100)
RB(13,2,10,minecraft:crying_obsidian,20,minecraft:obsidian,100)
RB(14,2,10,minecraft:crying_obsidian,20,minecraft:obsidian,100)
RB(15,2,10,minecraft:crying_obsidian,20,minecraft:obsidian,100)
RB(10,2,11,minecraft:crying_obsidian,20,minecraft:obsidian,100)
RB(11,2,11,minecraft:crying_obsidian,20,minecraft:obsidian,100)
RB(12,2,11,minecraft:crying_obsidian,20,minecraft:obsidian,100)
RB(13,2,11,minecraft:crying_obsidian,20,minecraft:obsidian,100)
RB(14,2,11,minecraft:crying_obsidian,20,minecraft:obsidian,100)
RB(15,2,11,minecraft:crying_obsidian,20,minecraft:obsidian,100)
RB(10,2,12,minecraft:crying_obsidian,20,minecraft:obsidian,100)
RB(11,2,12,minecraft:crying_obsidian,20,minecraft:obsidian,100)
RB(12,2,12,minecraft:crying_obsidian,20,minecraft:obsidian,100)
RB(13,2,12,minecraft:crying_obsidian,20,minecraft:obsidian,100)
RB(14,2,12,minecraft:crying_obsidian,20,minecraft:obsidian,100)
RB(15,2,12,minecraft:crying_obsidian,20,minecraft:obsidian,100)
RB(10,2,13,minecraft:crying_obsidian,20,minecraft:obsidian,100)
RB(11,2,13,minecraft:crying_obsidian,20,minecraft:obsidian,100)
RB(12,2,13,minecraft:crying_obsidian,20,minecraft:obsidian,100)
RB(13,2,13,minecraft:crying_obsidian,20,minecraft:obsidian,100)
RB(14,2,13,minecraft:crying_obsidian,20,minecraft:obsidian,100)
RB(15,2,13,minecraft:crying_obsidian,20,minecraft:obsidian,100)
RB(9,2,14,minecraft:crying_obsidian,20,minecraft:obsidian,100)
RB(10,2,14,minecraft:crying_obsidian,20,minecraft:obsidian,100)
RB(11,2,14,minecraft:crying_obsidian,20,minecraft:obsidian,100)
RB(12,2,14,minecraft:crying_obsidian,20,minecraft:obsidian,100)
RB(13,2,14,minecraft:crying_obsidian,20,minecraft:obsidian,100)
RB(14,2,14,minecraft:crying_obsidian,20,minecraft:obsidian,100)
RB(15,2,14,minecraft:crying_obsidian,20,minecraft:obsidian,100)
RB(8,2,15,minecraft:crying_obsidian,20,minecraft:obsidian,100)
RB(9,2,15,minecraft:crying_obsidian,20,minecraft:obsidian,100)
RB(10,2,15,minecraft:crying_obsidian,20,minecraft:obsidian,100)
RB(11,2,15,minecraft:crying_obsidian,20,minecraft:obsidian,100)
RB(12,2,15,minecraft:crying_obsidian,20,minecraft:obsidian,100)
RB(13,2,15,minecraft:crying_obsidian,20,minecraft:obsidian,100)
RB(14,2,15,minecraft:crying_obsidian,20,minecraft:obsidian,100)
RB(15,2,15,minecraft:crying_obsidian,20,minecraft:obsidian,100)
RB(14,3,6,minecraft:crying_obsidian,20,minecraft:obsidian,100)
RB(13,3,7,minecraft:crying_obsidian,20,minecraft:obsidian,100)
RB(14,3,7,minecraft:crying_obsidian,20,minecraft:obsidian,100)
RB(15,3,7,minecraft:crying_obsidian,20,minecraft:obsidian,100)
RB(12,3,8,minecraft:crying_obsidian,20,minecraft:obsidian,100)
RB(13,3,8,minecraft:crying_obsidian,20,minecraft:obsidian,100)
RB(14,3,8,minecraft:crying_obsidian,20,minecraft:obsidian,100)
RB(15,3,8,minecraft:crying_obsidian,20,minecraft:obsidian,100)
RB(12,3,9,minecraft:crying_obsidian,20,minecraft:obsidian,100)
RB(13,3,9,minecraft:crying_obsidian,20,minecraft:obsidian,100)
RB(14,3,9,minecraft:crying_obsidian,20,minecraft:obsidian,100)
RB(15,3,9,minecraft:crying_obsidian,20,minecraft:obsidian,100)
RB(12,3,10,minecraft:crying_obsidian,20,minecraft:obsidian,100)
RB(13,3,10,minecraft:crying_obsidian,20,minecraft:obsidian,100)
RB(14,3,10,minecraft:crying_obsidian,20,minecraft:obsidian,100)
RB(15,3,10,minecraft:crying_obsidian,20,minecraft:obsidian,100)
RB(12,3,11,minecraft:crying_obsidian,20,minecraft:obsidian,100)
RB(13,3,11,minecraft:crying_obsidian,20,minecraft:obsidian,100)
RB(14,3,11,minecraft:crying_obsidian,20,minecraft:obsidian,100)
RB(15,3,11,minecraft:crying_obsidian,20,minecraft:obsidian,100)
RB(11,3,12,minecraft:crying_obsidian,20,minecraft:obsidian,100)
RB(12,3,12,minecraft:crying_obsidian,20,minecraft:obsidian,100)
RB(13,3,12,minecraft:crying_obsidian,20,minecraft:obsidian,100)
RB(14,3,12,minecraft:crying_obsidian,20,minecraft:obsidian,100)
RB(15,3,12,minecraft:crying_obsidian,20,minecraft:obsidian,100)
RB(10,3,13,minecraft:crying_obsidian,20,minecraft:obsidian,100)
RB(11,3,13,minecraft:crying_obsidian,20,minecraft:obsidian,100)
RB(12,3,13,minecraft:crying_obsidian,20,minecraft:obsidian,100)
RB(13,3,13,minecraft:crying_obsidian,20,minecraft:obsidian,100)
RB(14,3,13,minecraft:crying_obsidian,20,minecraft:obsidian,100)
RB(15,3,13,minecraft:crying_obsidian,20,minecraft:obsidian,100)
RB(9,3,14,minecraft:crying_obsidian,20,minecraft:obsidian,100)
RB(10,3,14,minecraft:crying_obsidian,20,minecraft:obsidian,100)
RB(11,3,14,minecraft:crying_obsidian,20,minecraft:obsidian,100)
RB(12,3,14,minecraft:crying_obsidian,20,minecraft:obsidian,100)
RB(13,3,14,minecraft:crying_obsidian,20,minecraft:obsidian,100)
RB(14,3,14,minecraft:crying_obsidian,20,minecraft:obsidian,100)
RB(15,3,14,minecraft:crying_obsidian,20,minecraft:obsidian,100)
RB(9,3,15,minecraft:crying_obsidian,20,minecraft:obsidian,100)
RB(10,3,15,minecraft:crying_obsidian,20,minecraft:obsidian,100)
RB(11,3,15,minecraft:crying_obsidian,20,minecraft:obsidian,100)
RB(12,3,15,minecraft:crying_obsidian,20,minecraft:obsidian,100)
RB(13,3,15,minecraft:crying_obsidian,20,minecraft:obsidian,100)
RB(14,3,15,minecraft:crying_obsidian,20,minecraft:obsidian,100)
RB(15,3,15,minecraft:crying_obsidian,20,minecraft:obsidian,100)
RB(14,4,7,minecraft:crying_obsidian,20,minecraft:obsidian,100)
RB(15,4,7,minecraft:crying_obsidian,20,minecraft:obsidian,100)
RB(13,4,8,minecraft:crying_obsidian,20,minecraft:obsidian,100)
RB(14,4,8,minecraft:crying_obsidian,20,minecraft:obsidian,100)
RB(15,4,8,minecraft:crying_obsidian,20,minecraft:obsidian,100)
RB(13,4,9,minecraft:crying_obsidian,20,minecraft:obsidian,100)
RB(14,4,9,minecraft:crying_obsidian,20,minecraft:obsidian,100)
RB(15,4,9,minecraft:crying_obsidian,20,minecraft:obsidian,100)
RB(13,4,10,minecraft:crying_obsidian,20,minecraft:obsidian,100)
RB(14,4,10,minecraft:crying_obsidian,20,minecraft:obsidian,100)
RB(15,4,10,minecraft:crying_obsidian,20,minecraft:obsidian,100)
RB(13,4,11,minecraft:crying_obsidian,20,minecraft:obsidian,100)
RB(14,4,11,minecraft:crying_obsidian,20,minecraft:obsidian,100)
RB(15,4,11,minecraft:crying_obsidian,20,minecraft:obsidian,100)
RB(12,4,12,minecraft:crying_obsidian,20,minecraft:obsidian,100)
RB(13,4,12,minecraft:crying_obsidian,20,minecraft:obsidian,100)
RB(14,4,12,minecraft:crying_obsidian,20,minecraft:obsidian,100)
RB(15,4,12,minecraft:crying_obsidian,20,minecraft:obsidian,100)
RB(10,4,13,minecraft:crying_obsidian,20,minecraft:obsidian,100)
RB(11,4,13,minecraft:crying_obsidian,20,minecraft:obsidian,100)
RB(12,4,13,minecraft:crying_obsidian,20,minecraft:obsidian,100)
RB(13,4,13,minecraft:crying_obsidian,20,minecraft:obsidian,100)
RB(14,4,13,minecraft:crying_obsidian,20,minecraft:obsidian,100)
RB(15,4,13,minecraft:crying_obsidian,20,minecraft:obsidian,100)
RB(9,4,14,minecraft:crying_obsidian,20,minecraft:obsidian,100)
RB(10,4,14,minecraft:crying_obsidian,20,minecraft:obsidian,100)
RB(11,4,14,minecraft:crying_obsidian,20,minecraft:obsidian,100)
RB(12,4,14,minecraft:crying_obsidian,20,minecraft:obsidian,100)
RB(13,4,14,minecraft:crying_obsidian,20,minecraft:obsidian,100)
RB(14,4,14,minecraft:crying_obsidian,20,minecraft:obsidian,100)
RB(15,4,14,minecraft:crying_obsidian,20,minecraft:obsidian,100)
RB(9,4,15,minecraft:crying_obsidian,20,minecraft:obsidian,100)
RB(10,4,15,minecraft:crying_obsidian,20,minecraft:obsidian,100)
RB(11,4,15,minecraft:crying_obsidian,20,minecraft:obsidian,100)
RB(12,4,15,minecraft:crying_obsidian,20,minecraft:obsidian,100)
RB(13,4,15,minecraft:crying_obsidian,20,minecraft:obsidian,100)
RB(14,4,15,minecraft:crying_obsidian,20,minecraft:obsidian,100)
RB(15,4,15,minecraft:crying_obsidian,20,minecraft:obsidian,100)
RB(15,5,8,minecraft:crying_obsidian,20,minecraft:obsidian,100)
RB(14,5,9,minecraft:crying_obsidian,20,minecraft:obsidian,100)
RB(15,5,9,minecraft:crying_obsidian,20,minecraft:obsidian,100)
RB(14,5,10,minecraft:crying_obsidian,20,minecraft:obsidian,100)
RB(15,5,10,minecraft:crying_obsidian,20,minecraft:obsidian,100)
RB(14,5,11,minecraft:crying_obsidian,20,minecraft:obsidian,100)
RB(15,5,11,minecraft:crying_obsidian,20,minecraft:obsidian,100)
RB(15,5,12,minecraft:crying_obsidian,20,minecraft:obsidian,100)
RB(11,5,13,minecraft:crying_obsidian,20,minecraft:obsidian,100)
RB(12,5,13,minecraft:crying_obsidian,20,minecraft:obsidian,100)
RB(13,5,13,minecraft:crying_obsidian,20,minecraft:obsidian,100)
RB(14,5,13,minecraft:crying_obsidian,20,minecraft:obsidian,100)
RB(15,5,13,minecraft:crying_obsidian,20,minecraft:obsidian,100)
RB(10,5,14,minecraft:crying_obsidian,20,minecraft:obsidian,100)
RB(11,5,14,minecraft:crying_obsidian,20,minecraft:obsidian,100)
RB(12,5,14,minecraft:crying_obsidian,20,minecraft:obsidian,100)
RB(13,5,14,minecraft:crying_obsidian,20,minecraft:obsidian,100)
RB(14,5,14,minecraft:crying_obsidian,20,minecraft:obsidian,100)
RB(15,5,14,minecraft:crying_obsidian,20,minecraft:obsidian,100)
RB(9,5,15,minecraft:crying_obsidian,20,minecraft:obsidian,100)
RB(10,5,15,minecraft:crying_obsidian,20,minecraft:obsidian,100)
RB(11,5,15,minecraft:crying_obsidian,20,minecraft:obsidian,100)
RB(12,5,15,minecraft:crying_obsidian,20,minecraft:obsidian,100)
RB(13,5,15,minecraft:crying_obsidian,20,minecraft:obsidian,100)
RB(14,5,15,minecraft:crying_obsidian,20,minecraft:obsidian,100)
RB(15,5,15,minecraft:crying_obsidian,20,minecraft:obsidian,100)
RB(11,6,14,minecraft:crying_obsidian,20,minecraft:obsidian,100)
RB(12,6,14,minecraft:crying_obsidian,20,minecraft:obsidian,100)
RB(13,6,14,minecraft:crying_obsidian,20,minecraft:obsidian,100)
RB(14,6,14,minecraft:crying_obsidian,20,minecraft:obsidian,100)
RB(15,6,14,minecraft:crying_obsidian,20,minecraft:obsidian,100)
RB(10,6,15,minecraft:crying_obsidian,20,minecraft:obsidian,100)
RB(11,6,15,minecraft:crying_obsidian,20,minecraft:obsidian,100)
RB(12,6,15,minecraft:crying_obsidian,20,minecraft:obsidian,100)
RB(13,6,15,minecraft:crying_obsidian,20,minecraft:obsidian,100)
RB(14,6,15,minecraft:crying_obsidian,20,minecraft:obsidian,100)
RB(15,6,15,minecraft:crying_obsidian,20,minecraft:obsidian,100)
RB(12,7,15,minecraft:crying_obsidian,20,minecraft:obsidian,100)
RB(13,7,15,minecraft:crying_obsidian,20,minecraft:obsidian,100)
RB(14,7,15,minecraft:crying_obsidian,20,minecraft:obsidian,100)

