
#######################################################################
# +-----------------------------------------------------------------+ #
# |                            BO4 object                           | #
# +-----------------------------------------------------------------+ #
#######################################################################

Author: Unknown

Description: No description given

SettingsMode: WriteWithoutComments


#######################################################################
# +-----------------------------------------------------------------+ #
# |                          Main settings                          | #
# +-----------------------------------------------------------------+ #
#######################################################################

FixedRotation: 

Frequency: 0

SpawnHeight: highestBlock

UseCenterForHighestBlock: true

##############################
# Height Limits for the BO4. #
##############################

MinHeight: 0

MaxHeight: 255

InheritBO3: 

InheritBO3Rotation: NORTH

OverrideChildSettings: true

OverrideParentHeight: false

CanOverride: false

BranchFrequency: 0

BranchFrequencyGroup: 

MustBeBelowOther: false

MustBeInside: 

CannotBeInside: 

ReplacesBO3: 

MustBeInsideWorldBorders: false

CanSpawnOnWater: true

SpawnOnWaterOnly: false

SpawnUnderWater: false

SpawnAtWaterLevel: false

HeightOffset: 0

RemoveAir: true

ReplaceAbove: 

ReplaceBelow: 

ReplaceWithBiomeBlocks: true

ReplaceWithSurfaceBlock: GRASS

ReplaceWithGroundBlock: DIRT

ReplaceWithStoneBlock: STONE

SmoothRadius: 0

SmoothHeightOffset: 0

SmoothStartTop: false

SmoothStartWood: false

SmoothingSurfaceBlock: 

SmoothingGroundBlock: 

BO3Group: 

IsSpawnPoint: false

DoReplaceBlocks: true


#######################################################################
# +-----------------------------------------------------------------+ #
# |                              Blocks                             | #
# +-----------------------------------------------------------------+ #
#######################################################################

B(-8,0,5,minecraft:netherrack)
B(-8,0,6,minecraft:netherrack)
B(-8,1,6,minecraft:netherrack)
B(-8,0,7,minecraft:netherrack)
B(-8,1,7,minecraft:netherrack)
B(-8,2,7,minecraft:netherrack)
B(-8,0,8,minecraft:netherrack)
B(-8,1,8,minecraft:netherrack)
B(-8,2,8,minecraft:netherrack)
B(-7,0,3,minecraft:netherrack)
B(-7,0,4,minecraft:netherrack)
B(-7,0,5,minecraft:netherrack)
B(-7,1,5,minecraft:netherrack)
B(-7,0,6,minecraft:netherrack)
B(-7,1,6,minecraft:netherrack)
B(-7,2,6,minecraft:netherrack)
B(-7,0,7,minecraft:netherrack)
B(-7,1,7,minecraft:netherrack)
B(-7,2,7,minecraft:netherrack)
B(-7,0,8,minecraft:netherrack)
B(-7,1,8,minecraft:netherrack)
B(-7,2,8,minecraft:netherrack)
B(-6,0,2,minecraft:netherrack)
B(-6,0,3,minecraft:netherrack)
B(-6,1,3,minecraft:netherrack)
B(-6,0,4,minecraft:netherrack)
B(-6,1,4,minecraft:netherrack)
B(-6,2,4,minecraft:netherrack)
B(-6,0,5,minecraft:netherrack)
B(-6,1,5,minecraft:netherrack)
B(-6,2,5,minecraft:netherrack)
B(-6,0,6,minecraft:netherrack)
B(-6,1,6,minecraft:netherrack)
B(-6,2,6,minecraft:netherrack)
B(-6,0,7,minecraft:netherrack)
B(-6,1,7,minecraft:netherrack)
B(-6,2,7,minecraft:netherrack)
B(-6,0,8,minecraft:netherrack)
B(-6,1,8,minecraft:netherrack)
B(-6,2,8,minecraft:netherrack)
B(-5,0,1,minecraft:netherrack)
B(-5,0,2,minecraft:netherrack)
B(-5,1,2,minecraft:netherrack)
B(-5,2,2,minecraft:netherrack)
B(-5,0,3,minecraft:netherrack)
B(-5,1,3,minecraft:netherrack)
B(-5,2,3,minecraft:netherrack)
B(-5,3,3,minecraft:netherrack)
B(-5,0,4,minecraft:netherrack)
B(-5,1,4,minecraft:netherrack)
B(-5,2,4,minecraft:netherrack)
B(-5,3,4,minecraft:nether_quartz_ore)
B(-5,0,5,minecraft:netherrack)
B(-5,1,5,minecraft:netherrack)
B(-5,2,5,minecraft:netherrack)
B(-5,3,5,minecraft:nether_quartz_ore)
B(-5,0,6,minecraft:netherrack)
B(-5,1,6,minecraft:netherrack)
B(-5,2,6,minecraft:netherrack)
B(-5,0,7,minecraft:netherrack)
B(-5,1,7,minecraft:netherrack)
B(-5,2,7,minecraft:netherrack)
B(-5,0,8,minecraft:netherrack)
B(-5,1,8,minecraft:netherrack)
B(-5,2,8,minecraft:netherrack)
B(-4,0,1,minecraft:netherrack)
B(-4,0,2,minecraft:netherrack)
B(-4,1,2,minecraft:netherrack)
B(-4,0,3,minecraft:netherrack)
B(-4,1,3,minecraft:netherrack)
B(-4,2,3,minecraft:netherrack)
B(-4,3,3,minecraft:netherrack)
B(-4,0,4,minecraft:netherrack)
B(-4,1,4,minecraft:netherrack)
B(-4,2,4,minecraft:netherrack)
B(-4,0,5,minecraft:netherrack)
B(-4,1,5,minecraft:netherrack)
B(-4,2,5,minecraft:netherrack)
B(-4,0,6,minecraft:netherrack)
B(-4,1,6,minecraft:netherrack)
B(-4,2,6,minecraft:netherrack)
B(-4,0,7,minecraft:netherrack)
B(-4,1,7,minecraft:netherrack)
B(-4,2,7,minecraft:netherrack)
B(-4,0,8,minecraft:netherrack)
B(-4,1,8,minecraft:netherrack)
B(-3,0,1,minecraft:netherrack)
B(-3,0,2,minecraft:netherrack)
B(-3,1,2,minecraft:netherrack)
B(-3,0,3,minecraft:netherrack)
B(-3,1,3,minecraft:netherrack)
B(-3,2,3,minecraft:netherrack)
B(-3,0,4,minecraft:netherrack)
B(-3,1,4,minecraft:netherrack)
B(-3,2,4,minecraft:netherrack)
B(-3,0,5,minecraft:netherrack)
B(-3,1,5,minecraft:netherrack)
B(-3,2,5,minecraft:netherrack)
B(-3,0,6,minecraft:netherrack)
B(-3,1,6,minecraft:netherrack)
B(-3,2,6,minecraft:netherrack)
B(-3,0,7,minecraft:netherrack)
B(-3,1,7,minecraft:netherrack)
B(-3,2,7,minecraft:netherrack)
B(-3,0,8,minecraft:netherrack)
B(-3,1,8,minecraft:netherrack)
B(-2,0,1,minecraft:netherrack)
B(-2,0,2,minecraft:netherrack)
B(-2,1,2,minecraft:netherrack)
B(-2,0,3,minecraft:netherrack)
B(-2,1,3,minecraft:netherrack)
B(-2,2,3,minecraft:netherrack)
B(-2,0,4,minecraft:netherrack)
B(-2,1,4,minecraft:netherrack)
B(-2,2,4,minecraft:netherrack)
B(-2,0,5,minecraft:netherrack)
B(-2,1,5,minecraft:netherrack)
B(-2,2,5,minecraft:netherrack)
B(-2,0,6,minecraft:netherrack)
B(-2,1,6,minecraft:netherrack)
B(-2,2,6,minecraft:netherrack)
B(-2,0,7,minecraft:netherrack)
B(-2,1,7,minecraft:netherrack)
B(-2,0,8,minecraft:netherrack)
B(-2,1,8,minecraft:netherrack)
B(-1,0,1,minecraft:netherrack)
B(-1,0,2,minecraft:netherrack)
B(-1,0,3,minecraft:netherrack)
B(-1,1,3,minecraft:netherrack)
B(-1,0,4,minecraft:netherrack)
B(-1,1,4,minecraft:netherrack)
B(-1,0,5,minecraft:netherrack)
B(-1,1,5,minecraft:netherrack)
B(-1,0,6,minecraft:netherrack)
B(-1,1,6,minecraft:netherrack)
B(-1,0,7,minecraft:netherrack)
B(-1,1,7,minecraft:netherrack)
B(-1,0,8,minecraft:netherrack)
B(-1,1,8,minecraft:netherrack)
B(0,0,2,minecraft:netherrack)
B(0,0,3,minecraft:netherrack)
B(0,1,3,minecraft:netherrack)
B(0,0,4,minecraft:netherrack)
B(0,1,4,minecraft:netherrack)
B(0,0,5,minecraft:netherrack)
B(0,1,5,minecraft:netherrack)
B(0,0,6,minecraft:netherrack)
B(0,1,6,minecraft:netherrack)
B(0,0,7,minecraft:netherrack)
B(0,1,7,minecraft:netherrack)
B(0,0,8,minecraft:netherrack)
B(0,1,8,minecraft:netherrack)
B(1,0,2,minecraft:netherrack)
B(1,0,3,minecraft:netherrack)
B(1,0,4,minecraft:netherrack)
B(1,0,5,minecraft:netherrack)
B(1,1,5,minecraft:netherrack)
B(1,0,6,minecraft:netherrack)
B(1,1,6,minecraft:netherrack)
B(1,0,7,minecraft:netherrack)
B(1,1,7,minecraft:netherrack)
B(1,0,8,minecraft:netherrack)
B(1,1,8,minecraft:netherrack)
B(2,0,3,minecraft:netherrack)
B(2,0,4,minecraft:netherrack)
B(2,0,5,minecraft:netherrack)
B(2,0,6,minecraft:netherrack)
B(2,1,6,minecraft:netherrack)
B(2,0,7,minecraft:netherrack)
B(2,1,7,minecraft:netherrack)
B(2,0,8,minecraft:netherrack)
B(2,1,8,minecraft:netherrack)
B(3,36,-3,minecraft:warped_hyphae)
B(3,37,-3,minecraft:warped_hyphae)
B(3,38,-3,minecraft:warped_hyphae)
B(3,36,-2,minecraft:warped_hyphae)
B(3,37,-2,minecraft:warped_hyphae)
B(3,38,-2,minecraft:warped_hyphae)
B(3,36,-1,minecraft:warped_hyphae)
B(3,37,-1,minecraft:warped_hyphae)
B(3,38,-1,minecraft:warped_hyphae)
B(3,0,5,minecraft:netherrack)
B(3,0,6,minecraft:netherrack)
B(3,0,7,minecraft:netherrack)
B(3,1,7,minecraft:netherrack)
B(3,0,8,minecraft:netherrack)
B(4,35,-6,minecraft:warped_hyphae)
B(4,36,-6,minecraft:warped_hyphae)
B(4,37,-6,minecraft:warped_hyphae)
B(4,35,-5,minecraft:warped_hyphae)
B(4,36,-5,minecraft:warped_hyphae)
B(4,37,-5,minecraft:warped_hyphae)
B(4,35,-4,minecraft:warped_hyphae)
B(4,36,-4,minecraft:warped_hyphae)
B(4,37,-4,minecraft:warped_hyphae)
B(4,38,-4,minecraft:warped_hyphae)
B(4,39,-4,minecraft:warped_hyphae)
B(4,35,-3,minecraft:warped_hyphae)
B(4,36,-3,minecraft:warped_hyphae)
B(4,37,-3,minecraft:warped_hyphae)
B(4,38,-3,minecraft:warped_hyphae)
B(4,39,-3,minecraft:warped_hyphae)
B(4,35,-2,minecraft:warped_hyphae)
B(4,36,-2,minecraft:warped_hyphae)
B(4,37,-2,minecraft:warped_hyphae)
B(4,38,-2,minecraft:warped_hyphae)
B(4,39,-2,minecraft:warped_hyphae)
B(4,35,-1,minecraft:warped_hyphae)
B(4,36,-1,minecraft:warped_hyphae)
B(4,37,-1,minecraft:warped_hyphae)
B(4,38,-1,minecraft:warped_hyphae)
B(4,39,-1,minecraft:warped_hyphae)
B(4,35,0,minecraft:warped_hyphae)
B(4,36,0,minecraft:warped_hyphae)
B(4,37,0,minecraft:warped_hyphae)
B(4,38,0,minecraft:warped_hyphae)
B(4,39,0,minecraft:warped_hyphae)
B(4,0,5,minecraft:netherrack)
B(4,0,6,minecraft:netherrack)
B(4,0,7,minecraft:netherrack)
B(4,1,7,minecraft:netherrack)
B(4,0,8,minecraft:netherrack)
B(5,34,-7,minecraft:warped_hyphae)
B(5,35,-7,minecraft:warped_hyphae)
B(5,36,-7,minecraft:warped_hyphae)
B(5,37,-7,minecraft:warped_hyphae)
B(5,38,-7,minecraft:warped_hyphae)
B(5,0,-6,minecraft:netherrack)
B(5,34,-6,minecraft:warped_hyphae)
B(5,35,-6,minecraft:warped_hyphae)
B(5,36,-6,minecraft:warped_hyphae)
B(5,37,-6,minecraft:warped_hyphae)
B(5,38,-6,minecraft:warped_hyphae)
B(5,0,-5,minecraft:netherrack)
B(5,34,-5,minecraft:warped_hyphae)
B(5,35,-5,minecraft:warped_hyphae)
B(5,36,-5,minecraft:warped_hyphae)
B(5,37,-5,minecraft:warped_hyphae)
B(5,38,-5,minecraft:warped_hyphae)
B(5,0,-4,minecraft:netherrack)
B(5,34,-4,minecraft:warped_hyphae)
B(5,35,-4,minecraft:warped_hyphae)
B(5,36,-4,minecraft:warped_hyphae)
B(5,37,-4,minecraft:warped_hyphae)
B(5,38,-4,minecraft:warped_hyphae)
B(5,39,-4,minecraft:warped_hyphae)
B(5,0,-3,minecraft:netherrack)
B(5,34,-3,minecraft:warped_hyphae)
B(5,35,-3,minecraft:warped_hyphae)
B(5,36,-3,minecraft:warped_hyphae)
B(5,37,-3,minecraft:warped_hyphae)
B(5,38,-3,minecraft:warped_hyphae)
B(5,39,-3,minecraft:warped_hyphae)
B(5,40,-3,minecraft:warped_hyphae)
B(5,0,-2,minecraft:netherrack)
B(5,34,-2,minecraft:warped_hyphae)
B(5,35,-2,minecraft:warped_hyphae)
B(5,36,-2,minecraft:warped_hyphae)
B(5,37,-2,minecraft:warped_hyphae)
B(5,38,-2,minecraft:warped_hyphae)
B(5,39,-2,minecraft:warped_hyphae)
B(5,40,-2,minecraft:warped_hyphae)
B(5,0,-1,minecraft:netherrack)
B(5,34,-1,minecraft:warped_hyphae)
B(5,35,-1,minecraft:warped_hyphae)
B(5,36,-1,minecraft:warped_hyphae)
B(5,37,-1,minecraft:warped_hyphae)
B(5,38,-1,minecraft:warped_hyphae)
B(5,39,-1,minecraft:warped_hyphae)
B(5,40,-1,minecraft:warped_hyphae)
B(5,35,0,minecraft:warped_hyphae)
B(5,36,0,minecraft:warped_hyphae)
B(5,37,0,minecraft:warped_hyphae)
B(5,38,0,minecraft:warped_hyphae)
B(5,39,0,minecraft:warped_hyphae)
B(5,36,1,minecraft:warped_hyphae)
B(5,37,1,minecraft:warped_hyphae)
B(5,38,1,minecraft:warped_hyphae)
B(5,0,5,minecraft:netherrack)
B(5,0,6,minecraft:netherrack)
B(5,0,7,minecraft:netherrack)
B(5,1,7,minecraft:netherrack)
B(5,0,8,minecraft:netherrack)
B(6,0,-7,minecraft:netherrack)
B(6,33,-7,minecraft:warped_hyphae)
B(6,34,-7,minecraft:warped_hyphae)
B(6,35,-7,minecraft:warped_hyphae)
B(6,36,-7,minecraft:warped_hyphae)
B(6,37,-7,minecraft:warped_hyphae)
B(6,38,-7,minecraft:warped_hyphae)
B(6,0,-6,minecraft:netherrack)
B(6,33,-6,minecraft:warped_hyphae)
B(6,34,-6,minecraft:warped_hyphae)
B(6,35,-6,minecraft:warped_hyphae)
B(6,36,-6,minecraft:warped_hyphae)
B(6,37,-6,minecraft:warped_hyphae)
B(6,38,-6,minecraft:warped_hyphae)
B(6,39,-6,minecraft:warped_hyphae)
B(6,0,-5,minecraft:netherrack)
B(6,1,-5,minecraft:netherrack)
B(6,33,-5,minecraft:warped_hyphae)
B(6,34,-5,minecraft:warped_hyphae)
B(6,35,-5,minecraft:warped_hyphae)
B(6,36,-5,minecraft:warped_hyphae)
B(6,37,-5,minecraft:warped_hyphae)
B(6,38,-5,minecraft:warped_hyphae)
B(6,39,-5,minecraft:warped_hyphae)
B(6,0,-4,minecraft:netherrack)
B(6,33,-4,minecraft:warped_hyphae)
B(6,34,-4,minecraft:warped_hyphae)
B(6,35,-4,minecraft:warped_hyphae)
B(6,36,-4,minecraft:warped_hyphae)
B(6,37,-4,minecraft:warped_hyphae)
B(6,38,-4,minecraft:warped_hyphae)
B(6,39,-4,minecraft:warped_hyphae)
B(6,0,-3,minecraft:netherrack)
B(6,34,-3,minecraft:warped_hyphae)
B(6,35,-3,minecraft:warped_hyphae)
B(6,36,-3,minecraft:warped_hyphae)
B(6,37,-3,minecraft:warped_hyphae)
B(6,38,-3,minecraft:warped_hyphae)
B(6,39,-3,minecraft:warped_hyphae)
B(6,40,-3,minecraft:warped_hyphae)
B(6,0,-2,minecraft:netherrack)
B(6,34,-2,minecraft:warped_hyphae)
B(6,35,-2,minecraft:warped_hyphae)
B(6,36,-2,minecraft:warped_hyphae)
B(6,37,-2,minecraft:warped_hyphae)
B(6,38,-2,minecraft:warped_hyphae)
B(6,39,-2,minecraft:warped_hyphae)
B(6,40,-2,minecraft:warped_hyphae)
B(6,0,-1,minecraft:netherrack)
B(6,34,-1,minecraft:warped_hyphae)
B(6,35,-1,minecraft:warped_hyphae)
B(6,36,-1,minecraft:warped_hyphae)
B(6,37,-1,minecraft:warped_hyphae)
B(6,38,-1,minecraft:warped_hyphae)
B(6,39,-1,minecraft:warped_hyphae)
B(6,40,-1,minecraft:warped_hyphae)
B(6,0,0,minecraft:netherrack)
B(6,35,0,minecraft:warped_hyphae)
B(6,36,0,minecraft:warped_hyphae)
B(6,37,0,minecraft:warped_hyphae)
B(6,38,0,minecraft:warped_hyphae)
B(6,39,0,minecraft:warped_hyphae)
B(6,0,1,minecraft:netherrack)
B(6,36,1,minecraft:warped_hyphae)
B(6,37,1,minecraft:warped_hyphae)
B(6,38,1,minecraft:warped_hyphae)
B(6,0,4,minecraft:netherrack)
B(6,0,5,minecraft:netherrack)
B(6,0,6,minecraft:netherrack)
B(6,0,7,minecraft:netherrack)
B(6,0,8,minecraft:netherrack)
B(7,0,-7,minecraft:netherrack)
B(7,1,-7,minecraft:netherrack)
B(7,32,-7,minecraft:warped_hyphae)
B(7,33,-7,minecraft:warped_hyphae)
B(7,34,-7,minecraft:warped_hyphae)
B(7,35,-7,minecraft:warped_hyphae)
B(7,36,-7,minecraft:warped_hyphae)
B(7,37,-7,minecraft:warped_hyphae)
B(7,38,-7,minecraft:warped_hyphae)
B(7,0,-6,minecraft:netherrack)
B(7,1,-6,minecraft:netherrack)
B(7,32,-6,minecraft:warped_hyphae)
B(7,33,-6,minecraft:warped_hyphae)
B(7,34,-6,minecraft:warped_hyphae)
B(7,35,-6,minecraft:warped_hyphae)
B(7,36,-6,minecraft:warped_hyphae)
B(7,37,-6,minecraft:warped_hyphae)
B(7,38,-6,minecraft:warped_hyphae)
B(7,39,-6,minecraft:warped_hyphae)
B(7,0,-5,minecraft:netherrack)
B(7,1,-5,minecraft:netherrack)
B(7,32,-5,minecraft:warped_hyphae)
B(7,33,-5,minecraft:warped_hyphae)
B(7,34,-5,minecraft:warped_hyphae)
B(7,35,-5,minecraft:warped_hyphae)
B(7,36,-5,minecraft:warped_hyphae)
B(7,37,-5,minecraft:warped_hyphae)
B(7,38,-5,minecraft:warped_hyphae)
B(7,39,-5,minecraft:warped_hyphae)
B(7,0,-4,minecraft:netherrack)
B(7,1,-4,minecraft:netherrack)
B(7,33,-4,minecraft:warped_hyphae)
B(7,34,-4,minecraft:warped_hyphae)
B(7,35,-4,minecraft:warped_hyphae)
B(7,36,-4,minecraft:warped_hyphae)
B(7,37,-4,minecraft:warped_hyphae)
B(7,38,-4,minecraft:warped_hyphae)
B(7,39,-4,minecraft:warped_hyphae)
B(7,0,-3,minecraft:netherrack)
B(7,1,-3,minecraft:netherrack)
B(7,34,-3,minecraft:warped_hyphae)
B(7,35,-3,minecraft:warped_hyphae)
B(7,36,-3,minecraft:warped_hyphae)
B(7,37,-3,minecraft:warped_hyphae)
B(7,38,-3,minecraft:warped_hyphae)
B(7,39,-3,minecraft:warped_hyphae)
B(7,40,-3,minecraft:warped_hyphae)
B(7,0,-2,minecraft:netherrack)
B(7,1,-2,minecraft:netherrack)
B(7,34,-2,minecraft:warped_hyphae)
B(7,35,-2,minecraft:warped_hyphae)
B(7,36,-2,minecraft:warped_hyphae)
B(7,37,-2,minecraft:warped_hyphae)
B(7,38,-2,minecraft:warped_hyphae)
B(7,39,-2,minecraft:warped_hyphae)
B(7,40,-2,minecraft:warped_hyphae)
B(7,0,-1,minecraft:netherrack)
B(7,1,-1,minecraft:netherrack)
B(7,34,-1,minecraft:warped_hyphae)
B(7,35,-1,minecraft:warped_hyphae)
B(7,36,-1,minecraft:warped_hyphae)
B(7,37,-1,minecraft:warped_hyphae)
B(7,38,-1,minecraft:warped_hyphae)
B(7,39,-1,minecraft:warped_hyphae)
B(7,40,-1,minecraft:warped_hyphae)
B(7,0,0,minecraft:netherrack)
B(7,35,0,minecraft:warped_hyphae)
B(7,36,0,minecraft:warped_hyphae)
B(7,37,0,minecraft:warped_hyphae)
B(7,38,0,minecraft:warped_hyphae)
B(7,39,0,minecraft:warped_hyphae)
B(7,0,1,minecraft:netherrack)
B(7,36,1,minecraft:warped_hyphae)
B(7,37,1,minecraft:warped_hyphae)
B(7,38,1,minecraft:warped_hyphae)
B(7,0,2,minecraft:netherrack)
B(7,0,4,minecraft:netherrack)
B(7,0,5,minecraft:netherrack)
B(7,0,6,minecraft:netherrack)
B(7,0,7,minecraft:netherrack)
B(7,0,8,minecraft:netherrack)

#######################################################################
# +-----------------------------------------------------------------+ #
# |                             Branches                            | #
# +-----------------------------------------------------------------+ #
#######################################################################

Branch(16,0,0,true,WarpedBeanstalk1_C1_R1,NORTH,100.0,0)
Branch(0,0,16,true,WarpedBeanstalk1_C0_R2,NORTH,100.0,0)

#######################################################################
# +-----------------------------------------------------------------+ #
# |                             Entities                            | #
# +-----------------------------------------------------------------+ #
#######################################################################

