
#######################################################################
# +-----------------------------------------------------------------+ #
# |                            BO4 object                           | #
# +-----------------------------------------------------------------+ #
#######################################################################

Author: Unknown

Description: No description given

SettingsMode: WriteWithoutComments


#######################################################################
# +-----------------------------------------------------------------+ #
# |                          Main settings                          | #
# +-----------------------------------------------------------------+ #
#######################################################################

FixedRotation: 

Frequency: 0

SpawnHeight: highestBlock

UseCenterForHighestBlock: true

##############################
# Height Limits for the BO4. #
##############################

MinHeight: 0

MaxHeight: 255

InheritBO3: 

InheritBO3Rotation: NORTH

OverrideChildSettings: true

OverrideParentHeight: false

CanOverride: false

BranchFrequency: 0

BranchFrequencyGroup: 

MustBeBelowOther: false

MustBeInside: 

CannotBeInside: 

ReplacesBO3: 

MustBeInsideWorldBorders: false

CanSpawnOnWater: true

SpawnOnWaterOnly: false

SpawnUnderWater: false

SpawnAtWaterLevel: false

HeightOffset: 0

RemoveAir: true

ReplaceAbove: 

ReplaceBelow: 

ReplaceWithBiomeBlocks: true

ReplaceWithSurfaceBlock: GRASS

ReplaceWithGroundBlock: DIRT

ReplaceWithStoneBlock: STONE

SmoothRadius: 0

SmoothHeightOffset: 0

SmoothStartTop: false

SmoothStartWood: false

SmoothingSurfaceBlock: 

SmoothingGroundBlock: 

BO3Group: 

IsSpawnPoint: false

DoReplaceBlocks: true


#######################################################################
# +-----------------------------------------------------------------+ #
# |                              Blocks                             | #
# +-----------------------------------------------------------------+ #
#######################################################################

B(-4,0,-7,minecraft:netherrack)
B(-3,0,-7,minecraft:netherrack)
B(-3,0,-6,minecraft:netherrack)
B(-3,0,-5,minecraft:netherrack)
B(-2,0,-7,minecraft:netherrack)
B(-2,0,-6,minecraft:netherrack)
B(-2,0,-5,minecraft:netherrack)
B(-2,0,-4,minecraft:netherrack)
B(-1,0,-7,minecraft:netherrack)
B(-1,0,-6,minecraft:netherrack)
B(-1,0,-5,minecraft:netherrack)
B(-1,0,-4,minecraft:netherrack)
B(-1,0,-3,minecraft:netherrack)
B(-1,0,-2,minecraft:netherrack)
B(-1,0,-1,minecraft:netherrack)
B(0,0,-7,minecraft:netherrack)
B(0,0,-6,minecraft:netherrack)
B(0,0,-5,minecraft:netherrack)
B(0,0,-4,minecraft:netherrack)
B(0,0,-3,minecraft:netherrack)
B(1,0,-7,minecraft:netherrack)
B(1,0,-6,minecraft:netherrack)
B(1,0,-5,minecraft:netherrack)
B(1,0,-4,minecraft:netherrack)
B(2,0,-7,minecraft:netherrack)
B(2,0,-6,minecraft:netherrack)
B(2,0,-5,minecraft:netherrack)
B(3,0,-7,minecraft:netherrack)
B(3,0,-6,minecraft:netherrack)
B(3,0,-5,minecraft:netherrack)
B(4,0,-7,minecraft:netherrack)
B(4,0,-6,minecraft:netherrack)
B(4,0,-5,minecraft:netherrack)
B(5,0,-7,minecraft:netherrack)
B(5,0,-6,minecraft:netherrack)
B(5,0,-5,minecraft:netherrack)
B(6,0,-7,minecraft:netherrack)
B(6,0,-6,minecraft:netherrack)
B(6,0,-5,minecraft:netherrack)
B(6,0,-4,minecraft:netherrack)
B(6,0,7,minecraft:netherrack)
B(6,0,8,minecraft:netherrack)
B(6,33,8,minecraft:warped_hyphae)
B(6,34,8,minecraft:warped_hyphae)
B(6,35,8,minecraft:warped_hyphae)
B(6,36,8,minecraft:warped_hyphae)
B(6,37,8,minecraft:warped_hyphae)
B(7,0,-7,minecraft:netherrack)
B(7,0,-6,minecraft:netherrack)
B(7,0,-5,minecraft:netherrack)
B(7,0,-4,minecraft:netherrack)
B(7,0,-3,minecraft:netherrack)
B(7,0,-2,minecraft:netherrack)
B(7,0,6,minecraft:netherrack)
B(7,0,7,minecraft:netherrack)
B(7,32,7,minecraft:warped_hyphae)
B(7,33,7,minecraft:warped_hyphae)
B(7,34,7,minecraft:warped_hyphae)
B(7,35,7,minecraft:warped_hyphae)
B(7,36,7,minecraft:warped_hyphae)
B(7,0,8,minecraft:netherrack)
B(7,32,8,minecraft:warped_hyphae)
B(7,33,8,minecraft:warped_hyphae)
B(7,34,8,minecraft:warped_hyphae)
B(7,35,8,minecraft:warped_hyphae)
B(7,36,8,minecraft:warped_hyphae)
B(7,37,8,minecraft:warped_hyphae)

#######################################################################
# +-----------------------------------------------------------------+ #
# |                             Branches                            | #
# +-----------------------------------------------------------------+ #
#######################################################################

Branch(16,0,0,true,WarpedBeanstalk1_C1_R0,NORTH,100.0,0)
Branch(0,0,16,true,WarpedBeanstalk1_C0_R1,NORTH,100.0,0)

#######################################################################
# +-----------------------------------------------------------------+ #
# |                             Entities                            | #
# +-----------------------------------------------------------------+ #
#######################################################################

