
#######################################################################
# +-----------------------------------------------------------------+ #
# |                            BO4 object                           | #
# +-----------------------------------------------------------------+ #
#######################################################################

Author: Unknown

Description: No description given

SettingsMode: WriteWithoutComments


#######################################################################
# +-----------------------------------------------------------------+ #
# |                          Main settings                          | #
# +-----------------------------------------------------------------+ #
#######################################################################

FixedRotation: 

Frequency: 0

SpawnHeight: highestBlock

UseCenterForHighestBlock: true

##############################
# Height Limits for the BO4. #
##############################

MinHeight: 0

MaxHeight: 255

InheritBO3: 

InheritBO3Rotation: NORTH

OverrideChildSettings: true

OverrideParentHeight: false

CanOverride: false

BranchFrequency: 0

BranchFrequencyGroup: 

MustBeBelowOther: false

MustBeInside: 

CannotBeInside: 

ReplacesBO3: 

MustBeInsideWorldBorders: false

CanSpawnOnWater: true

SpawnOnWaterOnly: false

SpawnUnderWater: false

SpawnAtWaterLevel: false

HeightOffset: 0

RemoveAir: true

ReplaceAbove: 

ReplaceBelow: 

ReplaceWithBiomeBlocks: true

ReplaceWithSurfaceBlock: GRASS

ReplaceWithGroundBlock: DIRT

ReplaceWithStoneBlock: STONE

SmoothRadius: 0

SmoothHeightOffset: 0

SmoothStartTop: false

SmoothStartWood: false

SmoothingSurfaceBlock: 

SmoothingGroundBlock: 

BO3Group: 

IsSpawnPoint: false

DoReplaceBlocks: true


#######################################################################
# +-----------------------------------------------------------------+ #
# |                              Blocks                             | #
# +-----------------------------------------------------------------+ #
#######################################################################

B(-8,0,-7,minecraft:netherrack)
B(-8,0,-6,minecraft:netherrack)
B(-8,0,-5,minecraft:netherrack)
B(-8,0,-4,minecraft:netherrack)
B(-8,0,-3,minecraft:netherrack)
B(-8,0,-2,minecraft:netherrack)
B(-8,0,5,minecraft:netherrack)
B(-8,0,6,minecraft:netherrack)
B(-8,31,6,minecraft:warped_hyphae)
B(-8,32,6,minecraft:warped_hyphae)
B(-8,33,6,minecraft:warped_hyphae)
B(-8,34,6,minecraft:warped_hyphae)
B(-8,35,6,minecraft:warped_hyphae)
B(-8,0,7,minecraft:netherrack)
B(-8,1,7,minecraft:netherrack)
B(-8,31,7,minecraft:warped_hyphae)
B(-8,32,7,minecraft:warped_hyphae)
B(-8,33,7,minecraft:warped_hyphae)
B(-8,34,7,minecraft:warped_hyphae)
B(-8,35,7,minecraft:warped_hyphae)
B(-8,36,7,minecraft:warped_hyphae)
B(-8,0,8,minecraft:netherrack)
B(-8,1,8,minecraft:netherrack)
B(-8,31,8,minecraft:warped_hyphae)
B(-8,32,8,minecraft:warped_hyphae)
B(-8,33,8,minecraft:warped_hyphae)
B(-8,34,8,minecraft:warped_hyphae)
B(-8,35,8,minecraft:warped_hyphae)
B(-8,36,8,minecraft:warped_hyphae)
B(-8,37,8,minecraft:warped_hyphae)
B(-8,44,8,minecraft:warped_hyphae)
B(-8,45,8,minecraft:warped_hyphae)
B(-8,46,8,minecraft:warped_hyphae)
B(-7,0,-7,minecraft:netherrack)
B(-7,0,-6,minecraft:netherrack)
B(-7,0,-5,minecraft:netherrack)
B(-7,0,-4,minecraft:netherrack)
B(-7,0,-3,minecraft:netherrack)
B(-7,0,-2,minecraft:netherrack)
B(-7,0,4,minecraft:netherrack)
B(-7,0,5,minecraft:netherrack)
B(-7,30,5,minecraft:warped_hyphae)
B(-7,31,5,minecraft:warped_hyphae)
B(-7,32,5,minecraft:warped_hyphae)
B(-7,33,5,minecraft:warped_hyphae)
B(-7,34,5,minecraft:warped_hyphae)
B(-7,0,6,minecraft:netherrack)
B(-7,1,6,minecraft:netherrack)
B(-7,30,6,minecraft:warped_hyphae)
B(-7,31,6,minecraft:warped_hyphae)
B(-7,32,6,minecraft:warped_hyphae)
B(-7,33,6,minecraft:warped_hyphae)
B(-7,34,6,minecraft:warped_hyphae)
B(-7,35,6,minecraft:warped_hyphae)
B(-7,42,6,minecraft:warped_hyphae)
B(-7,43,6,minecraft:warped_hyphae)
B(-7,44,6,minecraft:warped_hyphae)
B(-7,0,7,minecraft:netherrack)
B(-7,1,7,minecraft:netherrack)
B(-7,30,7,minecraft:warped_hyphae)
B(-7,31,7,minecraft:warped_hyphae)
B(-7,32,7,minecraft:warped_hyphae)
B(-7,33,7,minecraft:warped_hyphae)
B(-7,34,7,minecraft:warped_hyphae)
B(-7,35,7,minecraft:warped_hyphae)
B(-7,36,7,minecraft:warped_hyphae)
B(-7,42,7,minecraft:warped_hyphae)
B(-7,43,7,minecraft:warped_hyphae)
B(-7,44,7,minecraft:warped_hyphae)
B(-7,45,7,minecraft:warped_hyphae)
B(-7,46,7,minecraft:warped_hyphae)
B(-7,47,7,minecraft:warped_hyphae)
B(-7,0,8,minecraft:netherrack)
B(-7,1,8,minecraft:netherrack)
B(-7,2,8,minecraft:netherrack)
B(-7,30,8,minecraft:warped_hyphae)
B(-7,31,8,minecraft:warped_hyphae)
B(-7,32,8,minecraft:warped_hyphae)
B(-7,33,8,minecraft:warped_hyphae)
B(-7,34,8,minecraft:warped_hyphae)
B(-7,35,8,minecraft:warped_hyphae)
B(-7,36,8,minecraft:warped_hyphae)
B(-7,37,8,minecraft:warped_hyphae)
B(-7,42,8,minecraft:warped_hyphae)
B(-7,43,8,minecraft:warped_hyphae)
B(-7,44,8,minecraft:warped_hyphae)
B(-7,45,8,minecraft:warped_hyphae)
B(-7,46,8,minecraft:warped_hyphae)
B(-7,47,8,minecraft:warped_hyphae)
B(-6,0,-7,minecraft:netherrack)
B(-6,0,-6,minecraft:netherrack)
B(-6,0,-5,minecraft:netherrack)
B(-6,0,-4,minecraft:netherrack)
B(-6,0,-3,minecraft:netherrack)
B(-6,0,1,minecraft:netherrack)
B(-6,0,2,minecraft:netherrack)
B(-6,0,3,minecraft:netherrack)
B(-6,0,4,minecraft:netherrack)
B(-6,31,4,minecraft:warped_hyphae)
B(-6,32,4,minecraft:warped_hyphae)
B(-6,33,4,minecraft:warped_hyphae)
B(-6,0,5,minecraft:netherrack)
B(-6,30,5,minecraft:warped_hyphae)
B(-6,31,5,minecraft:warped_hyphae)
B(-6,32,5,minecraft:warped_hyphae)
B(-6,33,5,minecraft:warped_hyphae)
B(-6,34,5,minecraft:warped_hyphae)
B(-6,41,5,minecraft:warped_hyphae)
B(-6,42,5,minecraft:warped_hyphae)
B(-6,43,5,minecraft:warped_hyphae)
B(-6,44,5,minecraft:warped_hyphae)
B(-6,45,5,minecraft:warped_hyphae)
B(-6,0,6,minecraft:netherrack)
B(-6,1,6,minecraft:netherrack)
B(-6,2,6,minecraft:netherrack)
B(-6,29,6,minecraft:warped_hyphae)
B(-6,30,6,minecraft:warped_hyphae)
B(-6,31,6,minecraft:warped_hyphae)
B(-6,32,6,minecraft:warped_hyphae)
B(-6,33,6,minecraft:warped_hyphae)
B(-6,34,6,minecraft:warped_hyphae)
B(-6,35,6,minecraft:warped_hyphae)
B(-6,41,6,minecraft:warped_hyphae)
B(-6,42,6,minecraft:warped_hyphae)
B(-6,43,6,minecraft:warped_hyphae)
B(-6,44,6,minecraft:warped_hyphae)
B(-6,45,6,minecraft:warped_hyphae)
B(-6,46,6,minecraft:warped_hyphae)
B(-6,0,7,minecraft:netherrack)
B(-6,1,7,minecraft:netherrack)
B(-6,2,7,minecraft:netherrack)
B(-6,29,7,minecraft:warped_hyphae)
B(-6,30,7,minecraft:warped_hyphae)
B(-6,31,7,minecraft:warped_hyphae)
B(-6,32,7,minecraft:warped_hyphae)
B(-6,33,7,minecraft:warped_hyphae)
B(-6,34,7,minecraft:warped_hyphae)
B(-6,35,7,minecraft:warped_hyphae)
B(-6,36,7,minecraft:warped_hyphae)
B(-6,41,7,minecraft:warped_hyphae)
B(-6,42,7,minecraft:warped_hyphae)
B(-6,43,7,minecraft:warped_hyphae)
B(-6,44,7,minecraft:warped_hyphae)
B(-6,45,7,minecraft:warped_hyphae)
B(-6,46,7,minecraft:warped_hyphae)
B(-6,47,7,minecraft:warped_hyphae)
B(-6,0,8,minecraft:netherrack)
B(-6,1,8,minecraft:netherrack)
B(-6,2,8,minecraft:netherrack)
B(-6,29,8,minecraft:warped_hyphae)
B(-6,30,8,minecraft:warped_hyphae)
B(-6,31,8,minecraft:warped_hyphae)
B(-6,32,8,minecraft:warped_hyphae)
B(-6,33,8,minecraft:warped_hyphae)
B(-6,34,8,minecraft:warped_hyphae)
B(-6,35,8,minecraft:warped_hyphae)
B(-6,36,8,minecraft:warped_hyphae)
B(-6,37,8,minecraft:warped_hyphae)
B(-6,41,8,minecraft:warped_hyphae)
B(-6,42,8,minecraft:warped_hyphae)
B(-6,43,8,minecraft:warped_hyphae)
B(-6,44,8,minecraft:warped_hyphae)
B(-6,45,8,minecraft:warped_hyphae)
B(-6,46,8,minecraft:warped_hyphae)
B(-6,47,8,minecraft:warped_hyphae)
B(-6,48,8,minecraft:warped_hyphae)
B(-5,0,-7,minecraft:netherrack)
B(-5,0,-6,minecraft:netherrack)
B(-5,0,-5,minecraft:netherrack)
B(-5,0,-4,minecraft:netherrack)
B(-5,0,-3,minecraft:netherrack)
B(-5,0,0,minecraft:netherrack)
B(-5,0,1,minecraft:netherrack)
B(-5,0,2,minecraft:netherrack)
B(-5,31,4,minecraft:warped_hyphae)
B(-5,32,4,minecraft:warped_hyphae)
B(-5,33,4,minecraft:warped_hyphae)
B(-5,40,4,minecraft:warped_hyphae)
B(-5,41,4,minecraft:warped_hyphae)
B(-5,42,4,minecraft:warped_hyphae)
B(-5,43,4,minecraft:warped_hyphae)
B(-5,44,4,minecraft:warped_hyphae)
B(-5,0,5,minecraft:netherrack)
B(-5,30,5,minecraft:warped_hyphae)
B(-5,31,5,minecraft:warped_hyphae)
B(-5,32,5,minecraft:warped_hyphae)
B(-5,33,5,minecraft:warped_hyphae)
B(-5,34,5,minecraft:warped_hyphae)
B(-5,40,5,minecraft:warped_hyphae)
B(-5,41,5,minecraft:warped_hyphae)
B(-5,42,5,minecraft:warped_hyphae)
B(-5,43,5,minecraft:warped_hyphae)
B(-5,44,5,minecraft:warped_hyphae)
B(-5,45,5,minecraft:warped_hyphae)
B(-5,0,6,minecraft:netherrack)
B(-5,29,6,minecraft:warped_hyphae)
B(-5,30,6,minecraft:warped_hyphae)
B(-5,31,6,minecraft:warped_hyphae)
B(-5,32,6,minecraft:warped_hyphae)
B(-5,33,6,minecraft:warped_hyphae)
B(-5,34,6,minecraft:warped_hyphae)
B(-5,35,6,minecraft:warped_hyphae)
B(-5,40,6,minecraft:warped_hyphae)
B(-5,41,6,minecraft:warped_hyphae)
B(-5,42,6,minecraft:warped_hyphae)
B(-5,43,6,minecraft:warped_hyphae)
B(-5,44,6,minecraft:warped_hyphae)
B(-5,45,6,minecraft:warped_hyphae)
B(-5,46,6,minecraft:warped_hyphae)
B(-5,0,7,minecraft:netherrack)
B(-5,1,7,minecraft:netherrack)
B(-5,2,7,minecraft:netherrack)
B(-5,3,7,minecraft:netherrack)
B(-5,29,7,minecraft:warped_hyphae)
B(-5,30,7,minecraft:warped_hyphae)
B(-5,31,7,minecraft:warped_hyphae)
B(-5,32,7,minecraft:warped_hyphae)
B(-5,33,7,minecraft:warped_hyphae)
B(-5,34,7,minecraft:warped_hyphae)
B(-5,35,7,minecraft:warped_hyphae)
B(-5,36,7,minecraft:warped_hyphae)
B(-5,40,7,minecraft:warped_hyphae)
B(-5,41,7,minecraft:warped_hyphae)
B(-5,42,7,minecraft:warped_hyphae)
B(-5,43,7,minecraft:warped_hyphae)
B(-5,44,7,minecraft:warped_hyphae)
B(-5,45,7,minecraft:warped_hyphae)
B(-5,46,7,minecraft:warped_hyphae)
B(-5,47,7,minecraft:warped_hyphae)
B(-5,0,8,minecraft:netherrack)
B(-5,1,8,minecraft:netherrack)
B(-5,2,8,minecraft:netherrack)
B(-5,3,8,minecraft:netherrack)
B(-5,29,8,minecraft:warped_hyphae)
B(-5,30,8,minecraft:warped_hyphae)
B(-5,31,8,minecraft:warped_hyphae)
B(-5,32,8,minecraft:warped_hyphae)
B(-5,33,8,minecraft:warped_hyphae)
B(-5,34,8,minecraft:warped_hyphae)
B(-5,35,8,minecraft:warped_hyphae)
B(-5,36,8,minecraft:warped_hyphae)
B(-5,40,8,minecraft:warped_hyphae)
B(-5,41,8,minecraft:warped_hyphae)
B(-5,42,8,minecraft:warped_hyphae)
B(-5,43,8,minecraft:warped_hyphae)
B(-5,44,8,minecraft:warped_hyphae)
B(-5,45,8,minecraft:warped_hyphae)
B(-5,46,8,minecraft:warped_hyphae)
B(-5,47,8,minecraft:warped_hyphae)
B(-5,48,8,minecraft:warped_hyphae)
B(-4,0,1,minecraft:netherrack)
B(-4,0,2,minecraft:netherrack)
B(-4,37,3,minecraft:warped_hyphae)
B(-4,38,3,minecraft:warped_hyphae)
B(-4,39,3,minecraft:warped_hyphae)
B(-4,40,3,minecraft:warped_hyphae)
B(-4,41,3,minecraft:warped_hyphae)
B(-4,42,3,minecraft:warped_hyphae)
B(-4,43,3,minecraft:warped_hyphae)
B(-4,30,4,minecraft:warped_hyphae)
B(-4,31,4,minecraft:warped_hyphae)
B(-4,32,4,minecraft:warped_hyphae)
B(-4,33,4,minecraft:warped_hyphae)
B(-4,34,4,minecraft:warped_hyphae)
B(-4,37,4,minecraft:warped_hyphae)
B(-4,38,4,minecraft:warped_hyphae)
B(-4,39,4,minecraft:warped_hyphae)
B(-4,40,4,minecraft:warped_hyphae)
B(-4,41,4,minecraft:warped_hyphae)
B(-4,42,4,minecraft:warped_hyphae)
B(-4,43,4,minecraft:warped_hyphae)
B(-4,44,4,minecraft:warped_hyphae)
B(-4,30,5,minecraft:warped_hyphae)
B(-4,31,5,minecraft:warped_hyphae)
B(-4,32,5,minecraft:warped_hyphae)
B(-4,33,5,minecraft:warped_hyphae)
B(-4,34,5,minecraft:warped_hyphae)
B(-4,37,5,minecraft:warped_hyphae)
B(-4,38,5,minecraft:warped_hyphae)
B(-4,39,5,minecraft:warped_hyphae)
B(-4,40,5,minecraft:warped_hyphae)
B(-4,41,5,minecraft:warped_hyphae)
B(-4,42,5,minecraft:warped_hyphae)
B(-4,43,5,minecraft:warped_hyphae)
B(-4,44,5,minecraft:warped_hyphae)
B(-4,45,5,minecraft:warped_hyphae)
B(-4,0,6,minecraft:netherrack)
B(-4,1,6,minecraft:netherrack)
B(-4,2,6,minecraft:netherrack)
B(-4,29,6,minecraft:warped_hyphae)
B(-4,30,6,minecraft:warped_hyphae)
B(-4,31,6,minecraft:warped_hyphae)
B(-4,32,6,minecraft:warped_hyphae)
B(-4,33,6,minecraft:warped_hyphae)
B(-4,34,6,minecraft:warped_hyphae)
B(-4,35,6,minecraft:warped_hyphae)
B(-4,39,6,minecraft:warped_hyphae)
B(-4,40,6,minecraft:warped_hyphae)
B(-4,41,6,minecraft:warped_hyphae)
B(-4,42,6,minecraft:warped_hyphae)
B(-4,43,6,minecraft:warped_hyphae)
B(-4,44,6,minecraft:warped_hyphae)
B(-4,45,6,minecraft:warped_hyphae)
B(-4,46,6,minecraft:warped_hyphae)
B(-4,0,7,minecraft:netherrack)
B(-4,1,7,minecraft:netherrack)
B(-4,2,7,minecraft:netherrack)
B(-4,3,7,minecraft:netherrack)
B(-4,29,7,minecraft:warped_hyphae)
B(-4,30,7,minecraft:warped_hyphae)
B(-4,31,7,minecraft:warped_hyphae)
B(-4,32,7,minecraft:warped_hyphae)
B(-4,33,7,minecraft:warped_hyphae)
B(-4,34,7,minecraft:warped_hyphae)
B(-4,35,7,minecraft:warped_hyphae)
B(-4,39,7,minecraft:warped_hyphae)
B(-4,40,7,minecraft:warped_hyphae)
B(-4,41,7,minecraft:warped_hyphae)
B(-4,42,7,minecraft:warped_hyphae)
B(-4,43,7,minecraft:warped_hyphae)
B(-4,44,7,minecraft:warped_hyphae)
B(-4,45,7,minecraft:warped_hyphae)
B(-4,46,7,minecraft:warped_hyphae)
B(-4,47,7,minecraft:warped_hyphae)
B(-4,0,8,minecraft:netherrack)
B(-4,1,8,minecraft:netherrack)
B(-4,2,8,minecraft:netherrack)
B(-4,3,8,minecraft:netherrack)
B(-4,7,8,minecraft:warped_hyphae)
B(-4,8,8,minecraft:warped_hyphae)
B(-4,9,8,minecraft:warped_hyphae)
B(-4,29,8,minecraft:warped_hyphae)
B(-4,30,8,minecraft:warped_hyphae)
B(-4,31,8,minecraft:warped_hyphae)
B(-4,32,8,minecraft:warped_hyphae)
B(-4,33,8,minecraft:warped_hyphae)
B(-4,34,8,minecraft:warped_hyphae)
B(-4,35,8,minecraft:warped_hyphae)
B(-4,40,8,minecraft:warped_hyphae)
B(-4,41,8,minecraft:warped_hyphae)
B(-4,42,8,minecraft:warped_hyphae)
B(-4,43,8,minecraft:warped_hyphae)
B(-4,44,8,minecraft:warped_hyphae)
B(-4,45,8,minecraft:warped_hyphae)
B(-4,46,8,minecraft:warped_hyphae)
B(-4,47,8,minecraft:warped_hyphae)
B(-4,48,8,minecraft:warped_hyphae)
B(-3,36,2,minecraft:warped_hyphae)
B(-3,37,2,minecraft:warped_hyphae)
B(-3,38,2,minecraft:warped_hyphae)
B(-3,39,2,minecraft:warped_hyphae)
B(-3,40,2,minecraft:warped_hyphae)
B(-3,41,2,minecraft:warped_hyphae)
B(-3,42,2,minecraft:warped_hyphae)
B(-3,31,3,minecraft:warped_hyphae)
B(-3,32,3,minecraft:warped_hyphae)
B(-3,33,3,minecraft:warped_hyphae)
B(-3,34,3,minecraft:warped_hyphae)
B(-3,35,3,minecraft:warped_hyphae)
B(-3,36,3,minecraft:warped_hyphae)
B(-3,37,3,minecraft:warped_hyphae)
B(-3,38,3,minecraft:warped_hyphae)
B(-3,39,3,minecraft:warped_hyphae)
B(-3,40,3,minecraft:warped_hyphae)
B(-3,41,3,minecraft:warped_hyphae)
B(-3,42,3,minecraft:warped_hyphae)
B(-3,43,3,minecraft:warped_hyphae)
B(-3,30,4,minecraft:warped_hyphae)
B(-3,31,4,minecraft:warped_hyphae)
B(-3,32,4,minecraft:warped_hyphae)
B(-3,33,4,minecraft:warped_hyphae)
B(-3,34,4,minecraft:warped_hyphae)
B(-3,35,4,minecraft:warped_hyphae)
B(-3,36,4,minecraft:warped_hyphae)
B(-3,37,4,minecraft:warped_hyphae)
B(-3,38,4,minecraft:warped_hyphae)
B(-3,39,4,minecraft:warped_hyphae)
B(-3,40,4,minecraft:warped_hyphae)
B(-3,41,4,minecraft:warped_hyphae)
B(-3,42,4,minecraft:warped_hyphae)
B(-3,43,4,minecraft:warped_hyphae)
B(-3,44,4,minecraft:warped_hyphae)
B(-3,2,5,minecraft:netherrack)
B(-3,29,5,minecraft:warped_hyphae)
B(-3,30,5,minecraft:warped_hyphae)
B(-3,31,5,minecraft:warped_hyphae)
B(-3,32,5,minecraft:warped_hyphae)
B(-3,33,5,minecraft:warped_hyphae)
B(-3,34,5,minecraft:warped_hyphae)
B(-3,35,5,minecraft:warped_hyphae)
B(-3,36,5,minecraft:warped_hyphae)
B(-3,37,5,minecraft:warped_hyphae)
B(-3,38,5,minecraft:warped_hyphae)
B(-3,39,5,minecraft:warped_hyphae)
B(-3,40,5,minecraft:warped_hyphae)
B(-3,41,5,minecraft:warped_hyphae)
B(-3,42,5,minecraft:warped_hyphae)
B(-3,43,5,minecraft:warped_hyphae)
B(-3,44,5,minecraft:warped_hyphae)
B(-3,45,5,minecraft:warped_hyphae)
B(-3,0,6,minecraft:netherrack)
B(-3,1,6,minecraft:netherrack)
B(-3,2,6,minecraft:netherrack)
B(-3,29,6,minecraft:warped_hyphae)
B(-3,30,6,minecraft:warped_hyphae)
B(-3,31,6,minecraft:warped_hyphae)
B(-3,32,6,minecraft:warped_hyphae)
B(-3,33,6,minecraft:warped_hyphae)
B(-3,34,6,minecraft:warped_hyphae)
B(-3,35,6,minecraft:warped_hyphae)
B(-3,36,6,minecraft:warped_hyphae)
B(-3,37,6,minecraft:warped_hyphae)
B(-3,38,6,minecraft:warped_hyphae)
B(-3,39,6,minecraft:warped_hyphae)
B(-3,40,6,minecraft:warped_hyphae)
B(-3,41,6,minecraft:warped_hyphae)
B(-3,42,6,minecraft:warped_hyphae)
B(-3,43,6,minecraft:warped_hyphae)
B(-3,44,6,minecraft:warped_hyphae)
B(-3,45,6,minecraft:warped_hyphae)
B(-3,46,6,minecraft:warped_hyphae)
B(-3,0,7,minecraft:netherrack)
B(-3,1,7,minecraft:netherrack)
B(-3,2,7,minecraft:netherrack)
B(-3,3,7,minecraft:netherrack)
B(-3,6,7,minecraft:warped_hyphae)
B(-3,7,7,minecraft:warped_hyphae)
B(-3,8,7,minecraft:warped_hyphae)
B(-3,9,7,minecraft:warped_hyphae)
B(-3,10,7,minecraft:warped_hyphae)
B(-3,11,7,minecraft:warped_hyphae)
B(-3,12,7,minecraft:warped_hyphae)
B(-3,27,7,minecraft:warped_hyphae)
B(-3,28,7,minecraft:warped_hyphae)
B(-3,29,7,minecraft:warped_hyphae)
B(-3,30,7,minecraft:warped_hyphae)
B(-3,31,7,minecraft:warped_hyphae)
B(-3,32,7,minecraft:warped_hyphae)
B(-3,33,7,minecraft:warped_hyphae)
B(-3,34,7,minecraft:warped_hyphae)
B(-3,35,7,minecraft:warped_hyphae)
B(-3,39,7,minecraft:warped_hyphae)
B(-3,40,7,minecraft:warped_hyphae)
B(-3,41,7,minecraft:warped_hyphae)
B(-3,42,7,minecraft:warped_hyphae)
B(-3,43,7,minecraft:warped_hyphae)
B(-3,44,7,minecraft:warped_hyphae)
B(-3,45,7,minecraft:warped_hyphae)
B(-3,46,7,minecraft:warped_hyphae)
B(-3,47,7,minecraft:warped_hyphae)
B(-3,0,8,minecraft:netherrack)
B(-3,1,8,minecraft:netherrack)
B(-3,2,8,minecraft:netherrack)
B(-3,3,8,minecraft:netherrack)
B(-3,6,8,minecraft:warped_hyphae)
B(-3,7,8,minecraft:warped_hyphae)
B(-3,8,8,minecraft:warped_hyphae)
B(-3,9,8,minecraft:warped_hyphae)
B(-3,10,8,minecraft:warped_hyphae)
B(-3,11,8,minecraft:warped_hyphae)
B(-3,12,8,minecraft:warped_hyphae)
B(-3,13,8,minecraft:warped_hyphae)
B(-3,14,8,minecraft:warped_hyphae)
B(-3,15,8,minecraft:warped_hyphae)
B(-3,27,8,minecraft:warped_hyphae)
B(-3,28,8,minecraft:warped_hyphae)
B(-3,29,8,minecraft:warped_hyphae)
B(-3,30,8,minecraft:warped_hyphae)
B(-3,31,8,minecraft:warped_hyphae)
B(-3,32,8,minecraft:warped_hyphae)
B(-3,33,8,minecraft:warped_hyphae)
B(-3,34,8,minecraft:warped_hyphae)
B(-3,40,8,minecraft:warped_hyphae)
B(-3,41,8,minecraft:warped_hyphae)
B(-3,42,8,minecraft:warped_hyphae)
B(-3,43,8,minecraft:warped_hyphae)
B(-3,44,8,minecraft:warped_hyphae)
B(-3,45,8,minecraft:warped_hyphae)
B(-3,46,8,minecraft:warped_hyphae)
B(-3,47,8,minecraft:warped_hyphae)
B(-2,37,1,minecraft:warped_hyphae)
B(-2,38,1,minecraft:warped_hyphae)
B(-2,39,1,minecraft:warped_hyphae)
B(-2,33,2,minecraft:warped_hyphae)
B(-2,34,2,minecraft:warped_hyphae)
B(-2,35,2,minecraft:warped_hyphae)
B(-2,36,2,minecraft:warped_hyphae)
B(-2,37,2,minecraft:warped_hyphae)
B(-2,38,2,minecraft:warped_hyphae)
B(-2,39,2,minecraft:warped_hyphae)
B(-2,40,2,minecraft:warped_hyphae)
B(-2,41,2,minecraft:warped_hyphae)
B(-2,42,2,minecraft:warped_hyphae)
B(-2,31,3,minecraft:warped_hyphae)
B(-2,32,3,minecraft:warped_hyphae)
B(-2,33,3,minecraft:warped_hyphae)
B(-2,34,3,minecraft:warped_hyphae)
B(-2,35,3,minecraft:warped_hyphae)
B(-2,36,3,minecraft:warped_hyphae)
B(-2,37,3,minecraft:warped_hyphae)
B(-2,38,3,minecraft:warped_hyphae)
B(-2,39,3,minecraft:warped_hyphae)
B(-2,40,3,minecraft:warped_hyphae)
B(-2,41,3,minecraft:warped_hyphae)
B(-2,42,3,minecraft:warped_hyphae)
B(-2,43,3,minecraft:warped_hyphae)
B(-2,30,4,minecraft:warped_hyphae)
B(-2,31,4,minecraft:warped_hyphae)
B(-2,32,4,minecraft:warped_hyphae)
B(-2,33,4,minecraft:warped_hyphae)
B(-2,34,4,minecraft:warped_hyphae)
B(-2,35,4,minecraft:warped_hyphae)
B(-2,36,4,minecraft:warped_hyphae)
B(-2,37,4,minecraft:warped_hyphae)
B(-2,38,4,minecraft:warped_hyphae)
B(-2,39,4,minecraft:warped_hyphae)
B(-2,40,4,minecraft:warped_hyphae)
B(-2,41,4,minecraft:warped_hyphae)
B(-2,42,4,minecraft:warped_hyphae)
B(-2,43,4,minecraft:warped_hyphae)
B(-2,44,4,minecraft:warped_hyphae)
B(-2,58,4,minecraft:warped_hyphae)
B(-2,59,4,minecraft:warped_hyphae)
B(-2,60,4,minecraft:warped_hyphae)
B(-2,1,5,minecraft:netherrack)
B(-2,2,5,minecraft:netherrack)
B(-2,29,5,minecraft:warped_hyphae)
B(-2,30,5,minecraft:warped_hyphae)
B(-2,31,5,minecraft:warped_hyphae)
B(-2,32,5,minecraft:warped_hyphae)
B(-2,33,5,minecraft:warped_hyphae)
B(-2,34,5,minecraft:warped_hyphae)
B(-2,35,5,minecraft:warped_hyphae)
B(-2,36,5,minecraft:warped_hyphae)
B(-2,37,5,minecraft:warped_hyphae)
B(-2,38,5,minecraft:warped_hyphae)
B(-2,39,5,minecraft:warped_hyphae)
B(-2,40,5,minecraft:warped_hyphae)
B(-2,41,5,minecraft:warped_hyphae)
B(-2,42,5,minecraft:warped_hyphae)
B(-2,43,5,minecraft:warped_hyphae)
B(-2,44,5,minecraft:warped_hyphae)
B(-2,45,5,minecraft:warped_hyphae)
B(-2,58,5,minecraft:warped_hyphae)
B(-2,59,5,minecraft:warped_hyphae)
B(-2,60,5,minecraft:warped_hyphae)
B(-2,0,6,minecraft:netherrack)
B(-2,1,6,minecraft:netherrack)
B(-2,2,6,minecraft:netherrack)
B(-2,7,6,minecraft:warped_hyphae)
B(-2,8,6,minecraft:warped_hyphae)
B(-2,9,6,minecraft:warped_hyphae)
B(-2,10,6,minecraft:warped_hyphae)
B(-2,11,6,minecraft:warped_hyphae)
B(-2,12,6,minecraft:warped_hyphae)
B(-2,13,6,minecraft:warped_hyphae)
B(-2,26,6,minecraft:warped_hyphae)
B(-2,27,6,minecraft:warped_hyphae)
B(-2,28,6,minecraft:warped_hyphae)
B(-2,29,6,minecraft:warped_hyphae)
B(-2,30,6,minecraft:warped_hyphae)
B(-2,31,6,minecraft:warped_hyphae)
B(-2,32,6,minecraft:warped_hyphae)
B(-2,33,6,minecraft:warped_hyphae)
B(-2,34,6,minecraft:warped_hyphae)
B(-2,35,6,minecraft:warped_hyphae)
B(-2,36,6,minecraft:warped_hyphae)
B(-2,37,6,minecraft:warped_hyphae)
B(-2,38,6,minecraft:warped_hyphae)
B(-2,39,6,minecraft:warped_hyphae)
B(-2,40,6,minecraft:warped_hyphae)
B(-2,41,6,minecraft:warped_hyphae)
B(-2,42,6,minecraft:warped_hyphae)
B(-2,43,6,minecraft:warped_hyphae)
B(-2,44,6,minecraft:warped_hyphae)
B(-2,45,6,minecraft:warped_hyphae)
B(-2,56,6,minecraft:warped_hyphae)
B(-2,57,6,minecraft:warped_hyphae)
B(-2,58,6,minecraft:warped_hyphae)
B(-2,59,6,minecraft:warped_hyphae)
B(-2,60,6,minecraft:warped_hyphae)
B(-2,0,7,minecraft:netherrack)
B(-2,1,7,minecraft:netherrack)
B(-2,2,7,minecraft:netherrack)
B(-2,3,7,minecraft:netherrack)
B(-2,6,7,minecraft:warped_hyphae)
B(-2,7,7,minecraft:warped_hyphae)
B(-2,8,7,minecraft:warped_hyphae)
B(-2,9,7,minecraft:warped_hyphae)
B(-2,10,7,minecraft:warped_hyphae)
B(-2,11,7,minecraft:warped_hyphae)
B(-2,12,7,minecraft:warped_hyphae)
B(-2,13,7,minecraft:warped_hyphae)
B(-2,14,7,minecraft:warped_hyphae)
B(-2,15,7,minecraft:warped_hyphae)
B(-2,16,7,minecraft:warped_hyphae)
B(-2,26,7,minecraft:warped_hyphae)
B(-2,27,7,minecraft:warped_hyphae)
B(-2,28,7,minecraft:warped_hyphae)
B(-2,29,7,minecraft:warped_hyphae)
B(-2,30,7,minecraft:warped_hyphae)
B(-2,31,7,minecraft:warped_hyphae)
B(-2,32,7,minecraft:warped_hyphae)
B(-2,33,7,minecraft:warped_hyphae)
B(-2,34,7,minecraft:warped_hyphae)
B(-2,35,7,minecraft:warped_hyphae)
B(-2,37,7,minecraft:warped_hyphae)
B(-2,38,7,minecraft:warped_hyphae)
B(-2,39,7,minecraft:warped_hyphae)
B(-2,40,7,minecraft:warped_hyphae)
B(-2,41,7,minecraft:warped_hyphae)
B(-2,42,7,minecraft:warped_hyphae)
B(-2,43,7,minecraft:warped_hyphae)
B(-2,44,7,minecraft:warped_hyphae)
B(-2,45,7,minecraft:warped_hyphae)
B(-2,56,7,minecraft:warped_hyphae)
B(-2,57,7,minecraft:warped_hyphae)
B(-2,58,7,minecraft:warped_hyphae)
B(-2,0,8,minecraft:netherrack)
B(-2,1,8,minecraft:netherrack)
B(-2,2,8,minecraft:netherrack)
B(-2,3,8,minecraft:netherrack)
B(-2,5,8,minecraft:warped_hyphae)
B(-2,6,8,minecraft:warped_hyphae)
B(-2,7,8,minecraft:warped_hyphae)
B(-2,8,8,minecraft:warped_hyphae)
B(-2,9,8,minecraft:warped_hyphae)
B(-2,10,8,minecraft:warped_hyphae)
B(-2,11,8,minecraft:warped_hyphae)
B(-2,12,8,minecraft:warped_hyphae)
B(-2,13,8,minecraft:warped_hyphae)
B(-2,14,8,minecraft:warped_hyphae)
B(-2,15,8,minecraft:warped_hyphae)
B(-2,16,8,minecraft:warped_hyphae)
B(-2,17,8,minecraft:warped_hyphae)
B(-2,18,8,minecraft:warped_hyphae)
B(-2,19,8,minecraft:warped_hyphae)
B(-2,26,8,minecraft:warped_hyphae)
B(-2,27,8,minecraft:warped_hyphae)
B(-2,28,8,minecraft:warped_hyphae)
B(-2,29,8,minecraft:warped_hyphae)
B(-2,30,8,minecraft:warped_hyphae)
B(-2,31,8,minecraft:warped_hyphae)
B(-2,32,8,minecraft:warped_hyphae)
B(-2,33,8,minecraft:warped_hyphae)
B(-2,34,8,minecraft:warped_hyphae)
B(-2,40,8,minecraft:warped_hyphae)
B(-2,41,8,minecraft:warped_hyphae)
B(-2,42,8,minecraft:warped_hyphae)
B(-2,43,8,minecraft:warped_hyphae)
B(-2,44,8,minecraft:warped_hyphae)
B(-2,45,8,minecraft:warped_hyphae)
B(-2,46,8,minecraft:warped_hyphae)
B(-2,53,8,minecraft:warped_hyphae)
B(-2,54,8,minecraft:warped_hyphae)
B(-2,55,8,minecraft:warped_hyphae)
B(-2,56,8,minecraft:warped_hyphae)
B(-2,57,8,minecraft:warped_hyphae)
B(-2,58,8,minecraft:warped_hyphae)
B(-1,34,1,minecraft:warped_hyphae)
B(-1,35,1,minecraft:warped_hyphae)
B(-1,36,1,minecraft:warped_hyphae)
B(-1,37,1,minecraft:warped_hyphae)
B(-1,38,1,minecraft:warped_hyphae)
B(-1,39,1,minecraft:warped_hyphae)
B(-1,33,2,minecraft:warped_hyphae)
B(-1,34,2,minecraft:warped_hyphae)
B(-1,35,2,minecraft:warped_hyphae)
B(-1,36,2,minecraft:warped_hyphae)
B(-1,37,2,minecraft:warped_hyphae)
B(-1,38,2,minecraft:warped_hyphae)
B(-1,39,2,minecraft:warped_hyphae)
B(-1,40,2,minecraft:warped_hyphae)
B(-1,41,2,minecraft:warped_hyphae)
B(-1,42,2,minecraft:warped_hyphae)
B(-1,1,3,minecraft:netherrack)
B(-1,31,3,minecraft:warped_hyphae)
B(-1,32,3,minecraft:warped_hyphae)
B(-1,33,3,minecraft:warped_hyphae)
B(-1,34,3,minecraft:warped_hyphae)
B(-1,35,3,minecraft:warped_hyphae)
B(-1,36,3,minecraft:warped_hyphae)
B(-1,37,3,minecraft:warped_hyphae)
B(-1,38,3,minecraft:warped_hyphae)
B(-1,39,3,minecraft:warped_hyphae)
B(-1,40,3,minecraft:warped_hyphae)
B(-1,41,3,minecraft:warped_hyphae)
B(-1,42,3,minecraft:warped_hyphae)
B(-1,43,3,minecraft:warped_hyphae)
B(-1,57,3,minecraft:warped_hyphae)
B(-1,58,3,minecraft:warped_hyphae)
B(-1,59,3,minecraft:warped_hyphae)
B(-1,60,3,minecraft:warped_hyphae)
B(-1,61,3,minecraft:warped_hyphae)
B(-1,1,4,minecraft:netherrack)
B(-1,2,4,minecraft:netherrack)
B(-1,30,4,minecraft:warped_hyphae)
B(-1,31,4,minecraft:warped_hyphae)
B(-1,32,4,minecraft:warped_hyphae)
B(-1,33,4,minecraft:warped_hyphae)
B(-1,34,4,minecraft:warped_hyphae)
B(-1,35,4,minecraft:warped_hyphae)
B(-1,36,4,minecraft:warped_hyphae)
B(-1,37,4,minecraft:warped_hyphae)
B(-1,38,4,minecraft:warped_hyphae)
B(-1,39,4,minecraft:warped_hyphae)
B(-1,40,4,minecraft:warped_hyphae)
B(-1,41,4,minecraft:warped_hyphae)
B(-1,42,4,minecraft:warped_hyphae)
B(-1,43,4,minecraft:warped_hyphae)
B(-1,44,4,minecraft:warped_hyphae)
B(-1,57,4,minecraft:warped_hyphae)
B(-1,58,4,minecraft:warped_hyphae)
B(-1,59,4,minecraft:warped_hyphae)
B(-1,60,4,minecraft:warped_hyphae)
B(-1,61,4,minecraft:warped_hyphae)
B(-1,0,5,minecraft:netherrack)
B(-1,1,5,minecraft:netherrack)
B(-1,2,5,minecraft:netherrack)
B(-1,10,5,minecraft:warped_hyphae)
B(-1,11,5,minecraft:warped_hyphae)
B(-1,12,5,minecraft:warped_hyphae)
B(-1,27,5,minecraft:warped_hyphae)
B(-1,28,5,minecraft:warped_hyphae)
B(-1,29,5,minecraft:warped_hyphae)
B(-1,30,5,minecraft:warped_hyphae)
B(-1,31,5,minecraft:warped_hyphae)
B(-1,32,5,minecraft:warped_hyphae)
B(-1,33,5,minecraft:warped_hyphae)
B(-1,34,5,minecraft:warped_hyphae)
B(-1,35,5,minecraft:warped_hyphae)
B(-1,36,5,minecraft:warped_hyphae)
B(-1,37,5,minecraft:warped_hyphae)
B(-1,38,5,minecraft:warped_hyphae)
B(-1,39,5,minecraft:warped_hyphae)
B(-1,40,5,minecraft:warped_hyphae)
B(-1,41,5,minecraft:warped_hyphae)
B(-1,42,5,minecraft:warped_hyphae)
B(-1,43,5,minecraft:warped_hyphae)
B(-1,44,5,minecraft:warped_hyphae)
B(-1,55,5,minecraft:warped_hyphae)
B(-1,56,5,minecraft:warped_hyphae)
B(-1,57,5,minecraft:warped_hyphae)
B(-1,58,5,minecraft:warped_hyphae)
B(-1,59,5,minecraft:warped_hyphae)
B(-1,60,5,minecraft:warped_hyphae)
B(-1,61,5,minecraft:warped_hyphae)
B(-1,0,6,minecraft:netherrack)
B(-1,1,6,minecraft:netherrack)
B(-1,2,6,minecraft:netherrack)
B(-1,7,6,minecraft:warped_hyphae)
B(-1,8,6,minecraft:warped_hyphae)
B(-1,9,6,minecraft:warped_hyphae)
B(-1,10,6,minecraft:warped_hyphae)
B(-1,11,6,minecraft:warped_hyphae)
B(-1,12,6,minecraft:warped_hyphae)
B(-1,13,6,minecraft:warped_hyphae)
B(-1,14,6,minecraft:warped_hyphae)
B(-1,15,6,minecraft:warped_hyphae)
B(-1,26,6,minecraft:warped_hyphae)
B(-1,27,6,minecraft:warped_hyphae)
B(-1,28,6,minecraft:warped_hyphae)
B(-1,29,6,minecraft:warped_hyphae)
B(-1,30,6,minecraft:warped_hyphae)
B(-1,31,6,minecraft:warped_hyphae)
B(-1,32,6,minecraft:warped_hyphae)
B(-1,33,6,minecraft:warped_hyphae)
B(-1,34,6,minecraft:warped_hyphae)
B(-1,35,6,minecraft:warped_hyphae)
B(-1,36,6,minecraft:warped_hyphae)
B(-1,37,6,minecraft:warped_hyphae)
B(-1,38,6,minecraft:warped_hyphae)
B(-1,39,6,minecraft:warped_hyphae)
B(-1,40,6,minecraft:warped_hyphae)
B(-1,41,6,minecraft:warped_hyphae)
B(-1,42,6,minecraft:warped_hyphae)
B(-1,43,6,minecraft:warped_hyphae)
B(-1,44,6,minecraft:warped_hyphae)
B(-1,55,6,minecraft:warped_hyphae)
B(-1,56,6,minecraft:warped_hyphae)
B(-1,57,6,minecraft:warped_hyphae)
B(-1,58,6,minecraft:warped_hyphae)
B(-1,59,6,minecraft:warped_hyphae)
B(-1,60,6,minecraft:warped_hyphae)
B(-1,61,6,minecraft:warped_hyphae)
B(-1,0,7,minecraft:netherrack)
B(-1,1,7,minecraft:netherrack)
B(-1,2,7,minecraft:netherrack)
B(-1,6,7,minecraft:warped_hyphae)
B(-1,7,7,minecraft:warped_hyphae)
B(-1,8,7,minecraft:warped_hyphae)
B(-1,9,7,minecraft:warped_hyphae)
B(-1,10,7,minecraft:warped_hyphae)
B(-1,11,7,minecraft:warped_hyphae)
B(-1,12,7,minecraft:warped_hyphae)
B(-1,13,7,minecraft:warped_hyphae)
B(-1,14,7,minecraft:warped_hyphae)
B(-1,15,7,minecraft:warped_hyphae)
B(-1,16,7,minecraft:warped_hyphae)
B(-1,17,7,minecraft:warped_hyphae)
B(-1,18,7,minecraft:warped_hyphae)
B(-1,25,7,minecraft:warped_hyphae)
B(-1,26,7,minecraft:warped_hyphae)
B(-1,27,7,minecraft:warped_hyphae)
B(-1,28,7,minecraft:warped_hyphae)
B(-1,29,7,minecraft:warped_hyphae)
B(-1,30,7,minecraft:warped_hyphae)
B(-1,31,7,minecraft:warped_hyphae)
B(-1,32,7,minecraft:warped_hyphae)
B(-1,33,7,minecraft:warped_hyphae)
B(-1,34,7,minecraft:warped_hyphae)
B(-1,35,7,minecraft:warped_hyphae)
B(-1,36,7,minecraft:warped_hyphae)
B(-1,37,7,minecraft:warped_hyphae)
B(-1,38,7,minecraft:warped_hyphae)
B(-1,39,7,minecraft:warped_hyphae)
B(-1,40,7,minecraft:warped_hyphae)
B(-1,41,7,minecraft:warped_hyphae)
B(-1,42,7,minecraft:warped_hyphae)
B(-1,43,7,minecraft:warped_hyphae)
B(-1,44,7,minecraft:warped_hyphae)
B(-1,55,7,minecraft:warped_hyphae)
B(-1,56,7,minecraft:warped_hyphae)
B(-1,57,7,minecraft:warped_hyphae)
B(-1,58,7,minecraft:warped_hyphae)
B(-1,59,7,minecraft:warped_hyphae)
B(-1,60,7,minecraft:warped_hyphae)
B(-1,61,7,minecraft:warped_hyphae)
B(-1,0,8,minecraft:netherrack)
B(-1,1,8,minecraft:netherrack)
B(-1,2,8,minecraft:warped_hyphae)
B(-1,3,8,minecraft:warped_hyphae)
B(-1,4,8,minecraft:warped_hyphae)
B(-1,5,8,minecraft:warped_hyphae)
B(-1,6,8,minecraft:warped_hyphae)
B(-1,7,8,minecraft:warped_hyphae)
B(-1,8,8,minecraft:warped_hyphae)
B(-1,9,8,minecraft:warped_hyphae)
B(-1,10,8,minecraft:warped_hyphae)
B(-1,11,8,minecraft:warped_hyphae)
B(-1,12,8,minecraft:warped_hyphae)
B(-1,13,8,minecraft:warped_hyphae)
B(-1,14,8,minecraft:warped_hyphae)
B(-1,15,8,minecraft:warped_hyphae)
B(-1,16,8,minecraft:warped_hyphae)
B(-1,17,8,minecraft:warped_hyphae)
B(-1,18,8,minecraft:warped_hyphae)
B(-1,19,8,minecraft:warped_hyphae)
B(-1,20,8,minecraft:warped_hyphae)
B(-1,21,8,minecraft:warped_hyphae)
B(-1,22,8,minecraft:warped_hyphae)
B(-1,23,8,minecraft:warped_hyphae)
B(-1,24,8,minecraft:warped_hyphae)
B(-1,25,8,minecraft:warped_hyphae)
B(-1,26,8,minecraft:warped_hyphae)
B(-1,27,8,minecraft:warped_hyphae)
B(-1,28,8,minecraft:warped_hyphae)
B(-1,29,8,minecraft:warped_hyphae)
B(-1,30,8,minecraft:warped_hyphae)
B(-1,31,8,minecraft:warped_hyphae)
B(-1,32,8,minecraft:warped_hyphae)
B(-1,33,8,minecraft:warped_hyphae)
B(-1,34,8,minecraft:warped_hyphae)
B(-1,40,8,minecraft:warped_hyphae)
B(-1,41,8,minecraft:warped_hyphae)
B(-1,42,8,minecraft:warped_hyphae)
B(-1,43,8,minecraft:warped_hyphae)
B(-1,44,8,minecraft:warped_hyphae)
B(-1,53,8,minecraft:warped_hyphae)
B(-1,54,8,minecraft:warped_hyphae)
B(-1,55,8,minecraft:warped_hyphae)
B(-1,56,8,minecraft:warped_hyphae)
B(-1,57,8,minecraft:warped_hyphae)
B(-1,58,8,minecraft:warped_hyphae)
B(-1,59,8,minecraft:warped_hyphae)
B(0,34,1,minecraft:warped_hyphae)
B(0,35,1,minecraft:warped_hyphae)
B(0,36,1,minecraft:warped_hyphae)
B(0,37,1,minecraft:warped_hyphae)
B(0,38,1,minecraft:warped_hyphae)
B(0,39,1,minecraft:warped_hyphae)
B(0,32,2,minecraft:warped_hyphae)
B(0,33,2,minecraft:warped_hyphae)
B(0,34,2,minecraft:warped_hyphae)
B(0,35,2,minecraft:warped_hyphae)
B(0,36,2,minecraft:warped_hyphae)
B(0,37,2,minecraft:warped_hyphae)
B(0,38,2,minecraft:warped_hyphae)
B(0,39,2,minecraft:warped_hyphae)
B(0,40,2,minecraft:warped_hyphae)
B(0,58,2,minecraft:warped_hyphae)
B(0,59,2,minecraft:warped_hyphae)
B(0,60,2,minecraft:warped_hyphae)
B(0,0,3,minecraft:netherrack)
B(0,31,3,minecraft:warped_hyphae)
B(0,32,3,minecraft:warped_hyphae)
B(0,33,3,minecraft:warped_hyphae)
B(0,34,3,minecraft:warped_hyphae)
B(0,35,3,minecraft:warped_hyphae)
B(0,36,3,minecraft:warped_hyphae)
B(0,37,3,minecraft:warped_hyphae)
B(0,38,3,minecraft:warped_hyphae)
B(0,39,3,minecraft:warped_hyphae)
B(0,40,3,minecraft:warped_hyphae)
B(0,41,3,minecraft:warped_hyphae)
B(0,42,3,minecraft:warped_hyphae)
B(0,43,3,minecraft:warped_hyphae)
B(0,57,3,minecraft:warped_hyphae)
B(0,58,3,minecraft:warped_hyphae)
B(0,59,3,minecraft:warped_hyphae)
B(0,60,3,minecraft:warped_hyphae)
B(0,61,3,minecraft:warped_hyphae)
B(0,0,4,minecraft:netherrack)
B(0,28,4,minecraft:warped_hyphae)
B(0,29,4,minecraft:warped_hyphae)
B(0,30,4,minecraft:warped_hyphae)
B(0,31,4,minecraft:warped_hyphae)
B(0,32,4,minecraft:warped_hyphae)
B(0,33,4,minecraft:warped_hyphae)
B(0,34,4,minecraft:warped_hyphae)
B(0,35,4,minecraft:warped_hyphae)
B(0,36,4,minecraft:warped_hyphae)
B(0,37,4,minecraft:warped_hyphae)
B(0,38,4,minecraft:warped_hyphae)
B(0,39,4,minecraft:warped_hyphae)
B(0,40,4,minecraft:warped_hyphae)
B(0,41,4,minecraft:warped_hyphae)
B(0,42,4,minecraft:warped_hyphae)
B(0,43,4,minecraft:warped_hyphae)
B(0,56,4,minecraft:warped_hyphae)
B(0,57,4,minecraft:warped_hyphae)
B(0,58,4,minecraft:warped_hyphae)
B(0,59,4,minecraft:warped_hyphae)
B(0,60,4,minecraft:warped_hyphae)
B(0,61,4,minecraft:warped_hyphae)
B(0,62,4,minecraft:warped_hyphae)
B(0,0,5,minecraft:netherrack)
B(0,1,5,minecraft:netherrack)
B(0,10,5,minecraft:warped_hyphae)
B(0,11,5,minecraft:warped_hyphae)
B(0,12,5,minecraft:warped_hyphae)
B(0,27,5,minecraft:warped_hyphae)
B(0,28,5,minecraft:warped_hyphae)
B(0,29,5,minecraft:warped_hyphae)
B(0,30,5,minecraft:warped_hyphae)
B(0,31,5,minecraft:warped_hyphae)
B(0,32,5,minecraft:warped_hyphae)
B(0,33,5,minecraft:warped_hyphae)
B(0,34,5,minecraft:warped_hyphae)
B(0,35,5,minecraft:warped_hyphae)
B(0,36,5,minecraft:warped_hyphae)
B(0,37,5,minecraft:warped_hyphae)
B(0,38,5,minecraft:warped_hyphae)
B(0,39,5,minecraft:warped_hyphae)
B(0,40,5,minecraft:warped_hyphae)
B(0,41,5,minecraft:warped_hyphae)
B(0,42,5,minecraft:warped_hyphae)
B(0,43,5,minecraft:warped_hyphae)
B(0,55,5,minecraft:warped_hyphae)
B(0,56,5,minecraft:warped_hyphae)
B(0,57,5,minecraft:warped_hyphae)
B(0,58,5,minecraft:warped_hyphae)
B(0,59,5,minecraft:warped_hyphae)
B(0,60,5,minecraft:warped_hyphae)
B(0,61,5,minecraft:warped_hyphae)
B(0,62,5,minecraft:warped_hyphae)
B(0,0,6,minecraft:netherrack)
B(0,1,6,minecraft:netherrack)
B(0,2,6,minecraft:netherrack)
B(0,7,6,minecraft:warped_hyphae)
B(0,8,6,minecraft:warped_hyphae)
B(0,9,6,minecraft:warped_hyphae)
B(0,10,6,minecraft:warped_hyphae)
B(0,11,6,minecraft:warped_hyphae)
B(0,12,6,minecraft:warped_hyphae)
B(0,13,6,minecraft:warped_hyphae)
B(0,14,6,minecraft:warped_hyphae)
B(0,15,6,minecraft:warped_hyphae)
B(0,26,6,minecraft:warped_hyphae)
B(0,27,6,minecraft:warped_hyphae)
B(0,28,6,minecraft:warped_hyphae)
B(0,29,6,minecraft:warped_hyphae)
B(0,30,6,minecraft:warped_hyphae)
B(0,31,6,minecraft:warped_hyphae)
B(0,32,6,minecraft:warped_hyphae)
B(0,33,6,minecraft:warped_hyphae)
B(0,34,6,minecraft:warped_hyphae)
B(0,35,6,minecraft:warped_hyphae)
B(0,36,6,minecraft:warped_hyphae)
B(0,37,6,minecraft:warped_hyphae)
B(0,38,6,minecraft:warped_hyphae)
B(0,39,6,minecraft:warped_hyphae)
B(0,40,6,minecraft:warped_hyphae)
B(0,41,6,minecraft:warped_hyphae)
B(0,42,6,minecraft:warped_hyphae)
B(0,43,6,minecraft:warped_hyphae)
B(0,54,6,minecraft:warped_hyphae)
B(0,55,6,minecraft:warped_hyphae)
B(0,56,6,minecraft:warped_hyphae)
B(0,57,6,minecraft:warped_hyphae)
B(0,58,6,minecraft:warped_hyphae)
B(0,59,6,minecraft:warped_hyphae)
B(0,60,6,minecraft:warped_hyphae)
B(0,61,6,minecraft:warped_hyphae)
B(0,62,6,minecraft:warped_hyphae)
B(0,0,7,minecraft:netherrack)
B(0,1,7,minecraft:netherrack)
B(0,2,7,minecraft:netherrack)
B(0,3,7,minecraft:netherrack)
B(0,6,7,minecraft:warped_hyphae)
B(0,7,7,minecraft:warped_hyphae)
B(0,8,7,minecraft:warped_hyphae)
B(0,9,7,minecraft:warped_hyphae)
B(0,10,7,minecraft:warped_hyphae)
B(0,11,7,minecraft:warped_hyphae)
B(0,12,7,minecraft:warped_hyphae)
B(0,13,7,minecraft:warped_hyphae)
B(0,14,7,minecraft:warped_hyphae)
B(0,15,7,minecraft:warped_hyphae)
B(0,16,7,minecraft:warped_hyphae)
B(0,17,7,minecraft:warped_hyphae)
B(0,18,7,minecraft:warped_hyphae)
B(0,19,7,minecraft:warped_hyphae)
B(0,20,7,minecraft:warped_hyphae)
B(0,21,7,minecraft:warped_hyphae)
B(0,22,7,minecraft:warped_hyphae)
B(0,23,7,minecraft:warped_hyphae)
B(0,24,7,minecraft:warped_hyphae)
B(0,25,7,minecraft:warped_hyphae)
B(0,26,7,minecraft:warped_hyphae)
B(0,27,7,minecraft:warped_hyphae)
B(0,28,7,minecraft:warped_hyphae)
B(0,29,7,minecraft:warped_hyphae)
B(0,30,7,minecraft:warped_hyphae)
B(0,31,7,minecraft:warped_hyphae)
B(0,32,7,minecraft:warped_hyphae)
B(0,33,7,minecraft:warped_hyphae)
B(0,34,7,minecraft:warped_hyphae)
B(0,35,7,minecraft:warped_hyphae)
B(0,36,7,minecraft:warped_hyphae)
B(0,37,7,minecraft:warped_hyphae)
B(0,38,7,minecraft:warped_hyphae)
B(0,39,7,minecraft:warped_hyphae)
B(0,40,7,minecraft:warped_hyphae)
B(0,41,7,minecraft:warped_hyphae)
B(0,42,7,minecraft:warped_hyphae)
B(0,43,7,minecraft:warped_hyphae)
B(0,54,7,minecraft:warped_hyphae)
B(0,55,7,minecraft:warped_hyphae)
B(0,56,7,minecraft:warped_hyphae)
B(0,57,7,minecraft:warped_hyphae)
B(0,58,7,minecraft:warped_hyphae)
B(0,59,7,minecraft:warped_hyphae)
B(0,60,7,minecraft:warped_hyphae)
B(0,61,7,minecraft:warped_hyphae)
B(0,0,8,minecraft:netherrack)
B(0,1,8,minecraft:netherrack)
B(0,2,8,minecraft:warped_hyphae)
B(0,3,8,minecraft:warped_hyphae)
B(0,4,8,minecraft:warped_hyphae)
B(0,5,8,minecraft:warped_hyphae)
B(0,6,8,minecraft:warped_hyphae)
B(0,7,8,minecraft:warped_hyphae)
B(0,8,8,minecraft:warped_hyphae)
B(0,9,8,minecraft:warped_hyphae)
B(0,10,8,minecraft:warped_hyphae)
B(0,11,8,minecraft:warped_hyphae)
B(0,12,8,minecraft:warped_hyphae)
B(0,13,8,minecraft:warped_hyphae)
B(0,14,8,minecraft:warped_hyphae)
B(0,15,8,minecraft:warped_hyphae)
B(0,16,8,minecraft:warped_hyphae)
B(0,17,8,minecraft:warped_hyphae)
B(0,18,8,minecraft:warped_hyphae)
B(0,19,8,minecraft:warped_hyphae)
B(0,20,8,minecraft:warped_hyphae)
B(0,21,8,minecraft:warped_hyphae)
B(0,22,8,minecraft:warped_hyphae)
B(0,23,8,minecraft:warped_hyphae)
B(0,24,8,minecraft:warped_hyphae)
B(0,25,8,minecraft:warped_hyphae)
B(0,26,8,minecraft:warped_hyphae)
B(0,27,8,minecraft:warped_hyphae)
B(0,28,8,minecraft:warped_hyphae)
B(0,29,8,minecraft:warped_hyphae)
B(0,30,8,minecraft:warped_hyphae)
B(0,31,8,minecraft:warped_hyphae)
B(0,32,8,minecraft:warped_hyphae)
B(0,33,8,minecraft:warped_hyphae)
B(0,34,8,minecraft:warped_hyphae)
B(0,53,8,minecraft:warped_hyphae)
B(0,54,8,minecraft:warped_hyphae)
B(0,55,8,minecraft:warped_hyphae)
B(0,56,8,minecraft:warped_hyphae)
B(0,57,8,minecraft:warped_hyphae)
B(0,58,8,minecraft:warped_hyphae)
B(0,59,8,minecraft:warped_hyphae)
B(0,60,8,minecraft:warped_hyphae)
B(1,34,1,minecraft:warped_hyphae)
B(1,35,1,minecraft:warped_hyphae)
B(1,36,1,minecraft:warped_hyphae)
B(1,32,2,minecraft:warped_hyphae)
B(1,33,2,minecraft:warped_hyphae)
B(1,34,2,minecraft:warped_hyphae)
B(1,35,2,minecraft:warped_hyphae)
B(1,36,2,minecraft:warped_hyphae)
B(1,37,2,minecraft:warped_hyphae)
B(1,38,2,minecraft:warped_hyphae)
B(1,39,2,minecraft:warped_hyphae)
B(1,40,2,minecraft:warped_hyphae)
B(1,58,2,minecraft:warped_hyphae)
B(1,59,2,minecraft:warped_hyphae)
B(1,60,2,minecraft:warped_hyphae)
B(1,29,3,minecraft:warped_hyphae)
B(1,30,3,minecraft:warped_hyphae)
B(1,31,3,minecraft:warped_hyphae)
B(1,32,3,minecraft:warped_hyphae)
B(1,33,3,minecraft:warped_hyphae)
B(1,34,3,minecraft:warped_hyphae)
B(1,35,3,minecraft:warped_hyphae)
B(1,36,3,minecraft:warped_hyphae)
B(1,37,3,minecraft:warped_hyphae)
B(1,38,3,minecraft:warped_hyphae)
B(1,39,3,minecraft:warped_hyphae)
B(1,40,3,minecraft:warped_hyphae)
B(1,57,3,minecraft:warped_hyphae)
B(1,58,3,minecraft:warped_hyphae)
B(1,59,3,minecraft:warped_hyphae)
B(1,60,3,minecraft:warped_hyphae)
B(1,61,3,minecraft:warped_hyphae)
B(1,28,4,minecraft:warped_hyphae)
B(1,29,4,minecraft:warped_hyphae)
B(1,30,4,minecraft:warped_hyphae)
B(1,31,4,minecraft:warped_hyphae)
B(1,32,4,minecraft:warped_hyphae)
B(1,33,4,minecraft:warped_hyphae)
B(1,34,4,minecraft:warped_hyphae)
B(1,35,4,minecraft:warped_hyphae)
B(1,36,4,minecraft:warped_hyphae)
B(1,37,4,minecraft:warped_hyphae)
B(1,38,4,minecraft:warped_hyphae)
B(1,39,4,minecraft:warped_hyphae)
B(1,40,4,minecraft:warped_hyphae)
B(1,41,4,minecraft:warped_hyphae)
B(1,42,4,minecraft:warped_hyphae)
B(1,56,4,minecraft:warped_hyphae)
B(1,57,4,minecraft:warped_hyphae)
B(1,58,4,minecraft:warped_hyphae)
B(1,59,4,minecraft:warped_hyphae)
B(1,60,4,minecraft:warped_hyphae)
B(1,61,4,minecraft:warped_hyphae)
B(1,62,4,minecraft:warped_hyphae)
B(1,0,5,minecraft:netherrack)
B(1,10,5,minecraft:warped_hyphae)
B(1,11,5,minecraft:warped_hyphae)
B(1,12,5,minecraft:warped_hyphae)
B(1,27,5,minecraft:warped_hyphae)
B(1,28,5,minecraft:warped_hyphae)
B(1,29,5,minecraft:warped_hyphae)
B(1,30,5,minecraft:warped_hyphae)
B(1,31,5,minecraft:warped_hyphae)
B(1,32,5,minecraft:warped_hyphae)
B(1,33,5,minecraft:warped_hyphae)
B(1,34,5,minecraft:warped_hyphae)
B(1,35,5,minecraft:warped_hyphae)
B(1,36,5,minecraft:warped_hyphae)
B(1,37,5,minecraft:warped_hyphae)
B(1,38,5,minecraft:warped_hyphae)
B(1,39,5,minecraft:warped_hyphae)
B(1,40,5,minecraft:warped_hyphae)
B(1,41,5,minecraft:warped_hyphae)
B(1,42,5,minecraft:warped_hyphae)
B(1,55,5,minecraft:warped_hyphae)
B(1,56,5,minecraft:warped_hyphae)
B(1,57,5,minecraft:warped_hyphae)
B(1,58,5,minecraft:warped_hyphae)
B(1,59,5,minecraft:warped_hyphae)
B(1,60,5,minecraft:warped_hyphae)
B(1,61,5,minecraft:warped_hyphae)
B(1,62,5,minecraft:warped_hyphae)
B(1,0,6,minecraft:netherrack)
B(1,1,6,minecraft:netherrack)
B(1,2,6,minecraft:netherrack)
B(1,9,6,minecraft:warped_hyphae)
B(1,10,6,minecraft:warped_hyphae)
B(1,11,6,minecraft:warped_hyphae)
B(1,12,6,minecraft:warped_hyphae)
B(1,13,6,minecraft:warped_hyphae)
B(1,14,6,minecraft:warped_hyphae)
B(1,15,6,minecraft:warped_hyphae)
B(1,16,6,minecraft:warped_hyphae)
B(1,17,6,minecraft:warped_hyphae)
B(1,22,6,minecraft:warped_hyphae)
B(1,23,6,minecraft:warped_hyphae)
B(1,24,6,minecraft:warped_hyphae)
B(1,26,6,minecraft:warped_hyphae)
B(1,27,6,minecraft:warped_hyphae)
B(1,28,6,minecraft:warped_hyphae)
B(1,29,6,minecraft:warped_hyphae)
B(1,30,6,minecraft:warped_hyphae)
B(1,31,6,minecraft:warped_hyphae)
B(1,32,6,minecraft:warped_hyphae)
B(1,33,6,minecraft:warped_hyphae)
B(1,34,6,minecraft:warped_hyphae)
B(1,35,6,minecraft:warped_hyphae)
B(1,36,6,minecraft:warped_hyphae)
B(1,37,6,minecraft:warped_hyphae)
B(1,38,6,minecraft:warped_hyphae)
B(1,39,6,minecraft:warped_hyphae)
B(1,40,6,minecraft:warped_hyphae)
B(1,41,6,minecraft:warped_hyphae)
B(1,42,6,minecraft:warped_hyphae)
B(1,54,6,minecraft:warped_hyphae)
B(1,55,6,minecraft:warped_hyphae)
B(1,56,6,minecraft:warped_hyphae)
B(1,57,6,minecraft:warped_hyphae)
B(1,58,6,minecraft:warped_hyphae)
B(1,59,6,minecraft:warped_hyphae)
B(1,60,6,minecraft:warped_hyphae)
B(1,61,6,minecraft:warped_hyphae)
B(1,62,6,minecraft:warped_hyphae)
B(1,0,7,minecraft:netherrack)
B(1,1,7,minecraft:netherrack)
B(1,2,7,minecraft:netherrack)
B(1,3,7,minecraft:netherrack)
B(1,6,7,minecraft:warped_hyphae)
B(1,7,7,minecraft:warped_hyphae)
B(1,8,7,minecraft:warped_hyphae)
B(1,9,7,minecraft:warped_hyphae)
B(1,10,7,minecraft:warped_hyphae)
B(1,11,7,minecraft:warped_hyphae)
B(1,12,7,minecraft:warped_hyphae)
B(1,13,7,minecraft:warped_hyphae)
B(1,14,7,minecraft:warped_hyphae)
B(1,15,7,minecraft:warped_hyphae)
B(1,16,7,minecraft:warped_hyphae)
B(1,17,7,minecraft:warped_hyphae)
B(1,18,7,minecraft:warped_hyphae)
B(1,19,7,minecraft:warped_hyphae)
B(1,20,7,minecraft:warped_hyphae)
B(1,21,7,minecraft:warped_hyphae)
B(1,22,7,minecraft:warped_hyphae)
B(1,23,7,minecraft:warped_hyphae)
B(1,24,7,minecraft:warped_hyphae)
B(1,25,7,minecraft:warped_hyphae)
B(1,26,7,minecraft:warped_hyphae)
B(1,27,7,minecraft:warped_hyphae)
B(1,28,7,minecraft:warped_hyphae)
B(1,29,7,minecraft:warped_hyphae)
B(1,30,7,minecraft:warped_hyphae)
B(1,31,7,minecraft:warped_hyphae)
B(1,32,7,minecraft:warped_hyphae)
B(1,33,7,minecraft:warped_hyphae)
B(1,34,7,minecraft:warped_hyphae)
B(1,35,7,minecraft:warped_hyphae)
B(1,36,7,minecraft:warped_hyphae)
B(1,54,7,minecraft:warped_hyphae)
B(1,55,7,minecraft:warped_hyphae)
B(1,56,7,minecraft:warped_hyphae)
B(1,57,7,minecraft:warped_hyphae)
B(1,58,7,minecraft:warped_hyphae)
B(1,59,7,minecraft:warped_hyphae)
B(1,60,7,minecraft:warped_hyphae)
B(1,61,7,minecraft:warped_hyphae)
B(1,0,8,minecraft:netherrack)
B(1,1,8,minecraft:netherrack)
B(1,2,8,minecraft:warped_hyphae)
B(1,3,8,minecraft:warped_hyphae)
B(1,4,8,minecraft:warped_hyphae)
B(1,5,8,minecraft:warped_hyphae)
B(1,6,8,minecraft:warped_hyphae)
B(1,7,8,minecraft:warped_hyphae)
B(1,8,8,minecraft:warped_hyphae)
B(1,9,8,minecraft:warped_hyphae)
B(1,10,8,minecraft:warped_hyphae)
B(1,11,8,minecraft:warped_hyphae)
B(1,12,8,minecraft:warped_hyphae)
B(1,13,8,minecraft:warped_hyphae)
B(1,14,8,minecraft:warped_hyphae)
B(1,15,8,minecraft:warped_hyphae)
B(1,16,8,minecraft:warped_hyphae)
B(1,17,8,minecraft:warped_hyphae)
B(1,18,8,minecraft:warped_hyphae)
B(1,19,8,minecraft:warped_hyphae)
B(1,20,8,minecraft:warped_hyphae)
B(1,21,8,minecraft:warped_hyphae)
B(1,22,8,minecraft:warped_hyphae)
B(1,23,8,minecraft:warped_hyphae)
B(1,24,8,minecraft:warped_hyphae)
B(1,25,8,minecraft:warped_hyphae)
B(1,26,8,minecraft:warped_hyphae)
B(1,27,8,minecraft:warped_hyphae)
B(1,28,8,minecraft:warped_hyphae)
B(1,29,8,minecraft:warped_hyphae)
B(1,30,8,minecraft:warped_hyphae)
B(1,31,8,minecraft:warped_hyphae)
B(1,32,8,minecraft:warped_hyphae)
B(1,33,8,minecraft:warped_hyphae)
B(1,34,8,minecraft:warped_hyphae)
B(1,54,8,minecraft:warped_hyphae)
B(1,55,8,minecraft:warped_hyphae)
B(1,56,8,minecraft:warped_hyphae)
B(1,57,8,minecraft:warped_hyphae)
B(1,58,8,minecraft:warped_hyphae)
B(1,59,8,minecraft:warped_hyphae)
B(1,60,8,minecraft:warped_hyphae)
B(2,32,2,minecraft:warped_hyphae)
B(2,33,2,minecraft:warped_hyphae)
B(2,34,2,minecraft:warped_hyphae)
B(2,35,2,minecraft:warped_hyphae)
B(2,36,2,minecraft:warped_hyphae)
B(2,37,2,minecraft:warped_hyphae)
B(2,58,2,minecraft:warped_hyphae)
B(2,59,2,minecraft:warped_hyphae)
B(2,60,2,minecraft:warped_hyphae)
B(2,29,3,minecraft:warped_hyphae)
B(2,30,3,minecraft:warped_hyphae)
B(2,31,3,minecraft:warped_hyphae)
B(2,32,3,minecraft:warped_hyphae)
B(2,33,3,minecraft:warped_hyphae)
B(2,34,3,minecraft:warped_hyphae)
B(2,35,3,minecraft:warped_hyphae)
B(2,36,3,minecraft:warped_hyphae)
B(2,37,3,minecraft:warped_hyphae)
B(2,38,3,minecraft:warped_hyphae)
B(2,39,3,minecraft:warped_hyphae)
B(2,57,3,minecraft:warped_hyphae)
B(2,58,3,minecraft:warped_hyphae)
B(2,59,3,minecraft:warped_hyphae)
B(2,60,3,minecraft:warped_hyphae)
B(2,61,3,minecraft:warped_hyphae)
B(2,28,4,minecraft:warped_hyphae)
B(2,29,4,minecraft:warped_hyphae)
B(2,30,4,minecraft:warped_hyphae)
B(2,31,4,minecraft:warped_hyphae)
B(2,32,4,minecraft:warped_hyphae)
B(2,33,4,minecraft:warped_hyphae)
B(2,34,4,minecraft:warped_hyphae)
B(2,35,4,minecraft:warped_hyphae)
B(2,36,4,minecraft:warped_hyphae)
B(2,37,4,minecraft:warped_hyphae)
B(2,38,4,minecraft:warped_hyphae)
B(2,39,4,minecraft:warped_hyphae)
B(2,56,4,minecraft:warped_hyphae)
B(2,57,4,minecraft:warped_hyphae)
B(2,58,4,minecraft:warped_hyphae)
B(2,59,4,minecraft:warped_hyphae)
B(2,60,4,minecraft:warped_hyphae)
B(2,61,4,minecraft:warped_hyphae)
B(2,62,4,minecraft:warped_hyphae)
B(2,0,5,minecraft:netherrack)
B(2,14,5,minecraft:warped_hyphae)
B(2,15,5,minecraft:warped_hyphae)
B(2,16,5,minecraft:warped_hyphae)
B(2,27,5,minecraft:warped_hyphae)
B(2,28,5,minecraft:warped_hyphae)
B(2,29,5,minecraft:warped_hyphae)
B(2,30,5,minecraft:warped_hyphae)
B(2,31,5,minecraft:warped_hyphae)
B(2,32,5,minecraft:warped_hyphae)
B(2,33,5,minecraft:warped_hyphae)
B(2,34,5,minecraft:warped_hyphae)
B(2,35,5,minecraft:warped_hyphae)
B(2,36,5,minecraft:warped_hyphae)
B(2,37,5,minecraft:warped_hyphae)
B(2,38,5,minecraft:warped_hyphae)
B(2,39,5,minecraft:warped_hyphae)
B(2,55,5,minecraft:warped_hyphae)
B(2,56,5,minecraft:warped_hyphae)
B(2,57,5,minecraft:warped_hyphae)
B(2,58,5,minecraft:warped_hyphae)
B(2,59,5,minecraft:warped_hyphae)
B(2,60,5,minecraft:warped_hyphae)
B(2,61,5,minecraft:warped_hyphae)
B(2,62,5,minecraft:warped_hyphae)
B(2,0,6,minecraft:netherrack)
B(2,1,6,minecraft:netherrack)
B(2,9,6,minecraft:warped_hyphae)
B(2,10,6,minecraft:warped_hyphae)
B(2,11,6,minecraft:warped_hyphae)
B(2,12,6,minecraft:warped_hyphae)
B(2,13,6,minecraft:warped_hyphae)
B(2,14,6,minecraft:warped_hyphae)
B(2,15,6,minecraft:warped_hyphae)
B(2,16,6,minecraft:warped_hyphae)
B(2,17,6,minecraft:warped_hyphae)
B(2,22,6,minecraft:warped_hyphae)
B(2,23,6,minecraft:warped_hyphae)
B(2,24,6,minecraft:warped_hyphae)
B(2,25,6,minecraft:warped_hyphae)
B(2,26,6,minecraft:warped_hyphae)
B(2,27,6,minecraft:warped_hyphae)
B(2,28,6,minecraft:warped_hyphae)
B(2,29,6,minecraft:warped_hyphae)
B(2,30,6,minecraft:warped_hyphae)
B(2,31,6,minecraft:warped_hyphae)
B(2,32,6,minecraft:warped_hyphae)
B(2,33,6,minecraft:warped_hyphae)
B(2,34,6,minecraft:warped_hyphae)
B(2,35,6,minecraft:warped_hyphae)
B(2,36,6,minecraft:warped_hyphae)
B(2,37,6,minecraft:warped_hyphae)
B(2,54,6,minecraft:warped_hyphae)
B(2,55,6,minecraft:warped_hyphae)
B(2,56,6,minecraft:warped_hyphae)
B(2,57,6,minecraft:warped_hyphae)
B(2,58,6,minecraft:warped_hyphae)
B(2,59,6,minecraft:warped_hyphae)
B(2,60,6,minecraft:warped_hyphae)
B(2,61,6,minecraft:warped_hyphae)
B(2,62,6,minecraft:warped_hyphae)
B(2,0,7,minecraft:netherrack)
B(2,1,7,minecraft:netherrack)
B(2,2,7,minecraft:netherrack)
B(2,3,7,minecraft:netherrack)
B(2,9,7,minecraft:warped_hyphae)
B(2,10,7,minecraft:warped_hyphae)
B(2,11,7,minecraft:warped_hyphae)
B(2,12,7,minecraft:warped_hyphae)
B(2,13,7,minecraft:warped_hyphae)
B(2,14,7,minecraft:warped_hyphae)
B(2,15,7,minecraft:warped_hyphae)
B(2,16,7,minecraft:warped_hyphae)
B(2,17,7,minecraft:warped_hyphae)
B(2,18,7,minecraft:warped_hyphae)
B(2,19,7,minecraft:warped_hyphae)
B(2,20,7,minecraft:warped_hyphae)
B(2,21,7,minecraft:warped_hyphae)
B(2,22,7,minecraft:warped_hyphae)
B(2,23,7,minecraft:warped_hyphae)
B(2,24,7,minecraft:warped_hyphae)
B(2,25,7,minecraft:warped_hyphae)
B(2,26,7,minecraft:warped_hyphae)
B(2,27,7,minecraft:warped_hyphae)
B(2,28,7,minecraft:warped_hyphae)
B(2,29,7,minecraft:warped_hyphae)
B(2,30,7,minecraft:warped_hyphae)
B(2,31,7,minecraft:warped_hyphae)
B(2,32,7,minecraft:warped_hyphae)
B(2,33,7,minecraft:warped_hyphae)
B(2,34,7,minecraft:warped_hyphae)
B(2,35,7,minecraft:warped_hyphae)
B(2,54,7,minecraft:warped_hyphae)
B(2,55,7,minecraft:warped_hyphae)
B(2,56,7,minecraft:warped_hyphae)
B(2,57,7,minecraft:warped_hyphae)
B(2,58,7,minecraft:warped_hyphae)
B(2,59,7,minecraft:warped_hyphae)
B(2,60,7,minecraft:warped_hyphae)
B(2,61,7,minecraft:warped_hyphae)
B(2,0,8,minecraft:netherrack)
B(2,1,8,minecraft:netherrack)
B(2,2,8,minecraft:netherrack)
B(2,3,8,minecraft:netherrack)
B(2,7,8,minecraft:warped_hyphae)
B(2,8,8,minecraft:warped_hyphae)
B(2,9,8,minecraft:warped_hyphae)
B(2,10,8,minecraft:warped_hyphae)
B(2,11,8,minecraft:warped_hyphae)
B(2,12,8,minecraft:warped_hyphae)
B(2,13,8,minecraft:warped_hyphae)
B(2,14,8,minecraft:warped_hyphae)
B(2,15,8,minecraft:warped_hyphae)
B(2,16,8,minecraft:warped_hyphae)
B(2,17,8,minecraft:warped_hyphae)
B(2,18,8,minecraft:warped_hyphae)
B(2,19,8,minecraft:warped_hyphae)
B(2,20,8,minecraft:warped_hyphae)
B(2,21,8,minecraft:warped_hyphae)
B(2,22,8,minecraft:warped_hyphae)
B(2,23,8,minecraft:warped_hyphae)
B(2,24,8,minecraft:warped_hyphae)
B(2,25,8,minecraft:warped_hyphae)
B(2,26,8,minecraft:warped_hyphae)
B(2,27,8,minecraft:warped_hyphae)
B(2,28,8,minecraft:warped_hyphae)
B(2,29,8,minecraft:warped_hyphae)
B(2,30,8,minecraft:warped_hyphae)
B(2,31,8,minecraft:warped_hyphae)
B(2,32,8,minecraft:warped_hyphae)
B(2,33,8,minecraft:warped_hyphae)
B(2,34,8,minecraft:warped_hyphae)
B(2,54,8,minecraft:warped_hyphae)
B(2,55,8,minecraft:warped_hyphae)
B(2,56,8,minecraft:warped_hyphae)
B(2,57,8,minecraft:warped_hyphae)
B(2,58,8,minecraft:warped_hyphae)
B(2,59,8,minecraft:warped_hyphae)
B(2,60,8,minecraft:warped_hyphae)
B(3,29,3,minecraft:warped_hyphae)
B(3,30,3,minecraft:warped_hyphae)
B(3,31,3,minecraft:warped_hyphae)
B(3,32,3,minecraft:warped_hyphae)
B(3,33,3,minecraft:warped_hyphae)
B(3,34,3,minecraft:warped_hyphae)
B(3,35,3,minecraft:warped_hyphae)
B(3,36,3,minecraft:warped_hyphae)
B(3,57,3,minecraft:warped_hyphae)
B(3,58,3,minecraft:warped_hyphae)
B(3,59,3,minecraft:warped_hyphae)
B(3,60,3,minecraft:warped_hyphae)
B(3,61,3,minecraft:warped_hyphae)
B(3,28,4,minecraft:warped_hyphae)
B(3,29,4,minecraft:warped_hyphae)
B(3,30,4,minecraft:warped_hyphae)
B(3,31,4,minecraft:warped_hyphae)
B(3,32,4,minecraft:warped_hyphae)
B(3,33,4,minecraft:warped_hyphae)
B(3,34,4,minecraft:warped_hyphae)
B(3,35,4,minecraft:warped_hyphae)
B(3,36,4,minecraft:warped_hyphae)
B(3,57,4,minecraft:warped_hyphae)
B(3,58,4,minecraft:warped_hyphae)
B(3,59,4,minecraft:warped_hyphae)
B(3,60,4,minecraft:warped_hyphae)
B(3,61,4,minecraft:warped_hyphae)
B(3,14,5,minecraft:warped_hyphae)
B(3,15,5,minecraft:warped_hyphae)
B(3,16,5,minecraft:warped_hyphae)
B(3,24,5,minecraft:warped_hyphae)
B(3,25,5,minecraft:warped_hyphae)
B(3,26,5,minecraft:warped_hyphae)
B(3,27,5,minecraft:warped_hyphae)
B(3,28,5,minecraft:warped_hyphae)
B(3,29,5,minecraft:warped_hyphae)
B(3,30,5,minecraft:warped_hyphae)
B(3,31,5,minecraft:warped_hyphae)
B(3,32,5,minecraft:warped_hyphae)
B(3,33,5,minecraft:warped_hyphae)
B(3,34,5,minecraft:warped_hyphae)
B(3,35,5,minecraft:warped_hyphae)
B(3,36,5,minecraft:warped_hyphae)
B(3,55,5,minecraft:warped_hyphae)
B(3,56,5,minecraft:warped_hyphae)
B(3,57,5,minecraft:warped_hyphae)
B(3,58,5,minecraft:warped_hyphae)
B(3,59,5,minecraft:warped_hyphae)
B(3,60,5,minecraft:warped_hyphae)
B(3,61,5,minecraft:warped_hyphae)
B(3,0,6,minecraft:netherrack)
B(3,1,6,minecraft:netherrack)
B(3,13,6,minecraft:warped_hyphae)
B(3,14,6,minecraft:warped_hyphae)
B(3,15,6,minecraft:warped_hyphae)
B(3,16,6,minecraft:warped_hyphae)
B(3,17,6,minecraft:warped_hyphae)
B(3,22,6,minecraft:warped_hyphae)
B(3,23,6,minecraft:warped_hyphae)
B(3,24,6,minecraft:warped_hyphae)
B(3,25,6,minecraft:warped_hyphae)
B(3,26,6,minecraft:warped_hyphae)
B(3,27,6,minecraft:warped_hyphae)
B(3,28,6,minecraft:warped_hyphae)
B(3,29,6,minecraft:warped_hyphae)
B(3,30,6,minecraft:warped_hyphae)
B(3,31,6,minecraft:warped_hyphae)
B(3,32,6,minecraft:warped_hyphae)
B(3,33,6,minecraft:warped_hyphae)
B(3,34,6,minecraft:warped_hyphae)
B(3,35,6,minecraft:warped_hyphae)
B(3,55,6,minecraft:warped_hyphae)
B(3,56,6,minecraft:warped_hyphae)
B(3,57,6,minecraft:warped_hyphae)
B(3,58,6,minecraft:warped_hyphae)
B(3,59,6,minecraft:warped_hyphae)
B(3,60,6,minecraft:warped_hyphae)
B(3,61,6,minecraft:warped_hyphae)
B(3,0,7,minecraft:netherrack)
B(3,1,7,minecraft:netherrack)
B(3,2,7,minecraft:netherrack)
B(3,3,7,minecraft:netherrack)
B(3,10,7,minecraft:warped_hyphae)
B(3,11,7,minecraft:warped_hyphae)
B(3,12,7,minecraft:warped_hyphae)
B(3,13,7,minecraft:warped_hyphae)
B(3,14,7,minecraft:warped_hyphae)
B(3,15,7,minecraft:warped_hyphae)
B(3,16,7,minecraft:warped_hyphae)
B(3,17,7,minecraft:warped_hyphae)
B(3,18,7,minecraft:warped_hyphae)
B(3,21,7,minecraft:warped_hyphae)
B(3,22,7,minecraft:warped_hyphae)
B(3,23,7,minecraft:warped_hyphae)
B(3,24,7,minecraft:warped_hyphae)
B(3,25,7,minecraft:warped_hyphae)
B(3,26,7,minecraft:warped_hyphae)
B(3,27,7,minecraft:warped_hyphae)
B(3,28,7,minecraft:warped_hyphae)
B(3,29,7,minecraft:warped_hyphae)
B(3,30,7,minecraft:warped_hyphae)
B(3,31,7,minecraft:warped_hyphae)
B(3,32,7,minecraft:warped_hyphae)
B(3,33,7,minecraft:warped_hyphae)
B(3,34,7,minecraft:warped_hyphae)
B(3,35,7,minecraft:warped_hyphae)
B(3,55,7,minecraft:warped_hyphae)
B(3,56,7,minecraft:warped_hyphae)
B(3,57,7,minecraft:warped_hyphae)
B(3,58,7,minecraft:warped_hyphae)
B(3,59,7,minecraft:warped_hyphae)
B(3,60,7,minecraft:warped_hyphae)
B(3,61,7,minecraft:warped_hyphae)
B(3,0,8,minecraft:netherrack)
B(3,1,8,minecraft:netherrack)
B(3,2,8,minecraft:netherrack)
B(3,3,8,minecraft:netherrack)
B(3,10,8,minecraft:warped_hyphae)
B(3,11,8,minecraft:warped_hyphae)
B(3,12,8,minecraft:warped_hyphae)
B(3,13,8,minecraft:warped_hyphae)
B(3,14,8,minecraft:warped_hyphae)
B(3,15,8,minecraft:warped_hyphae)
B(3,16,8,minecraft:warped_hyphae)
B(3,17,8,minecraft:warped_hyphae)
B(3,18,8,minecraft:warped_hyphae)
B(3,19,8,minecraft:warped_hyphae)
B(3,20,8,minecraft:warped_hyphae)
B(3,21,8,minecraft:warped_hyphae)
B(3,22,8,minecraft:warped_hyphae)
B(3,23,8,minecraft:warped_hyphae)
B(3,24,8,minecraft:warped_hyphae)
B(3,25,8,minecraft:warped_hyphae)
B(3,26,8,minecraft:warped_hyphae)
B(3,27,8,minecraft:warped_hyphae)
B(3,28,8,minecraft:warped_hyphae)
B(3,29,8,minecraft:warped_hyphae)
B(3,30,8,minecraft:warped_hyphae)
B(3,31,8,minecraft:warped_hyphae)
B(3,32,8,minecraft:warped_hyphae)
B(3,55,8,minecraft:warped_hyphae)
B(3,56,8,minecraft:warped_hyphae)
B(3,57,8,minecraft:warped_hyphae)
B(3,58,8,minecraft:warped_hyphae)
B(3,59,8,minecraft:warped_hyphae)
B(4,28,4,minecraft:warped_hyphae)
B(4,29,4,minecraft:warped_hyphae)
B(4,30,4,minecraft:warped_hyphae)
B(4,31,4,minecraft:warped_hyphae)
B(4,32,4,minecraft:warped_hyphae)
B(4,33,4,minecraft:warped_hyphae)
B(4,34,4,minecraft:warped_hyphae)
B(4,58,4,minecraft:warped_hyphae)
B(4,59,4,minecraft:warped_hyphae)
B(4,60,4,minecraft:warped_hyphae)
B(4,14,5,minecraft:warped_hyphae)
B(4,15,5,minecraft:warped_hyphae)
B(4,16,5,minecraft:warped_hyphae)
B(4,24,5,minecraft:warped_hyphae)
B(4,25,5,minecraft:warped_hyphae)
B(4,26,5,minecraft:warped_hyphae)
B(4,27,5,minecraft:warped_hyphae)
B(4,28,5,minecraft:warped_hyphae)
B(4,29,5,minecraft:warped_hyphae)
B(4,30,5,minecraft:warped_hyphae)
B(4,31,5,minecraft:warped_hyphae)
B(4,32,5,minecraft:warped_hyphae)
B(4,33,5,minecraft:warped_hyphae)
B(4,34,5,minecraft:warped_hyphae)
B(4,58,5,minecraft:warped_hyphae)
B(4,59,5,minecraft:warped_hyphae)
B(4,60,5,minecraft:warped_hyphae)
B(4,0,6,minecraft:netherrack)
B(4,13,6,minecraft:warped_hyphae)
B(4,14,6,minecraft:warped_hyphae)
B(4,15,6,minecraft:warped_hyphae)
B(4,16,6,minecraft:warped_hyphae)
B(4,17,6,minecraft:warped_hyphae)
B(4,23,6,minecraft:warped_hyphae)
B(4,24,6,minecraft:warped_hyphae)
B(4,25,6,minecraft:warped_hyphae)
B(4,26,6,minecraft:warped_hyphae)
B(4,27,6,minecraft:warped_hyphae)
B(4,28,6,minecraft:warped_hyphae)
B(4,29,6,minecraft:warped_hyphae)
B(4,30,6,minecraft:warped_hyphae)
B(4,31,6,minecraft:warped_hyphae)
B(4,32,6,minecraft:warped_hyphae)
B(4,33,6,minecraft:warped_hyphae)
B(4,34,6,minecraft:warped_hyphae)
B(4,56,6,minecraft:warped_hyphae)
B(4,57,6,minecraft:warped_hyphae)
B(4,58,6,minecraft:warped_hyphae)
B(4,59,6,minecraft:warped_hyphae)
B(4,60,6,minecraft:warped_hyphae)
B(4,0,7,minecraft:netherrack)
B(4,1,7,minecraft:netherrack)
B(4,2,7,minecraft:netherrack)
B(4,12,7,minecraft:warped_hyphae)
B(4,13,7,minecraft:warped_hyphae)
B(4,14,7,minecraft:warped_hyphae)
B(4,15,7,minecraft:warped_hyphae)
B(4,16,7,minecraft:warped_hyphae)
B(4,17,7,minecraft:warped_hyphae)
B(4,18,7,minecraft:warped_hyphae)
B(4,21,7,minecraft:warped_hyphae)
B(4,22,7,minecraft:warped_hyphae)
B(4,23,7,minecraft:warped_hyphae)
B(4,24,7,minecraft:warped_hyphae)
B(4,25,7,minecraft:warped_hyphae)
B(4,26,7,minecraft:warped_hyphae)
B(4,27,7,minecraft:warped_hyphae)
B(4,28,7,minecraft:warped_hyphae)
B(4,29,7,minecraft:warped_hyphae)
B(4,30,7,minecraft:warped_hyphae)
B(4,31,7,minecraft:warped_hyphae)
B(4,32,7,minecraft:warped_hyphae)
B(4,56,7,minecraft:warped_hyphae)
B(4,57,7,minecraft:warped_hyphae)
B(4,58,7,minecraft:warped_hyphae)
B(4,0,8,minecraft:netherrack)
B(4,1,8,minecraft:netherrack)
B(4,2,8,minecraft:netherrack)
B(4,12,8,minecraft:warped_hyphae)
B(4,13,8,minecraft:warped_hyphae)
B(4,14,8,minecraft:warped_hyphae)
B(4,15,8,minecraft:warped_hyphae)
B(4,16,8,minecraft:warped_hyphae)
B(4,17,8,minecraft:warped_hyphae)
B(4,18,8,minecraft:warped_hyphae)
B(4,21,8,minecraft:warped_hyphae)
B(4,22,8,minecraft:warped_hyphae)
B(4,23,8,minecraft:warped_hyphae)
B(4,24,8,minecraft:warped_hyphae)
B(4,25,8,minecraft:warped_hyphae)
B(4,26,8,minecraft:warped_hyphae)
B(4,27,8,minecraft:warped_hyphae)
B(4,28,8,minecraft:warped_hyphae)
B(4,29,8,minecraft:warped_hyphae)
B(4,30,8,minecraft:warped_hyphae)
B(4,31,8,minecraft:warped_hyphae)
B(4,32,8,minecraft:warped_hyphae)
B(4,56,8,minecraft:warped_hyphae)
B(4,57,8,minecraft:warped_hyphae)
B(4,58,8,minecraft:warped_hyphae)
B(5,14,5,minecraft:warped_hyphae)
B(5,15,5,minecraft:warped_hyphae)
B(5,16,5,minecraft:warped_hyphae)
B(5,24,5,minecraft:warped_hyphae)
B(5,25,5,minecraft:warped_hyphae)
B(5,26,5,minecraft:warped_hyphae)
B(5,27,5,minecraft:warped_hyphae)
B(5,28,5,minecraft:warped_hyphae)
B(5,29,5,minecraft:warped_hyphae)
B(5,30,5,minecraft:warped_hyphae)
B(5,31,5,minecraft:warped_hyphae)
B(5,0,6,minecraft:netherrack)
B(5,13,6,minecraft:warped_hyphae)
B(5,14,6,minecraft:warped_hyphae)
B(5,15,6,minecraft:warped_hyphae)
B(5,16,6,minecraft:warped_hyphae)
B(5,17,6,minecraft:warped_hyphae)
B(5,23,6,minecraft:warped_hyphae)
B(5,24,6,minecraft:warped_hyphae)
B(5,25,6,minecraft:warped_hyphae)
B(5,26,6,minecraft:warped_hyphae)
B(5,27,6,minecraft:warped_hyphae)
B(5,28,6,minecraft:warped_hyphae)
B(5,29,6,minecraft:warped_hyphae)
B(5,30,6,minecraft:warped_hyphae)
B(5,31,6,minecraft:warped_hyphae)
B(5,0,7,minecraft:netherrack)
B(5,1,7,minecraft:netherrack)
B(5,2,7,minecraft:netherrack)
B(5,12,7,minecraft:warped_hyphae)
B(5,13,7,minecraft:warped_hyphae)
B(5,14,7,minecraft:warped_hyphae)
B(5,15,7,minecraft:warped_hyphae)
B(5,16,7,minecraft:warped_hyphae)
B(5,17,7,minecraft:warped_hyphae)
B(5,18,7,minecraft:warped_hyphae)
B(5,22,7,minecraft:warped_hyphae)
B(5,23,7,minecraft:warped_hyphae)
B(5,24,7,minecraft:warped_hyphae)
B(5,25,7,minecraft:warped_hyphae)
B(5,26,7,minecraft:warped_hyphae)
B(5,27,7,minecraft:warped_hyphae)
B(5,28,7,minecraft:warped_hyphae)
B(5,29,7,minecraft:warped_hyphae)
B(5,30,7,minecraft:warped_hyphae)
B(5,31,7,minecraft:warped_hyphae)
B(5,0,8,minecraft:netherrack)
B(5,1,8,minecraft:netherrack)
B(5,12,8,minecraft:warped_hyphae)
B(5,13,8,minecraft:warped_hyphae)
B(5,14,8,minecraft:warped_hyphae)
B(5,15,8,minecraft:warped_hyphae)
B(5,16,8,minecraft:warped_hyphae)
B(5,17,8,minecraft:warped_hyphae)
B(5,18,8,minecraft:warped_hyphae)
B(5,22,8,minecraft:warped_hyphae)
B(5,23,8,minecraft:warped_hyphae)
B(5,24,8,minecraft:warped_hyphae)
B(5,25,8,minecraft:warped_hyphae)
B(5,26,8,minecraft:warped_hyphae)
B(5,27,8,minecraft:warped_hyphae)
B(5,28,8,minecraft:warped_hyphae)
B(5,29,8,minecraft:warped_hyphae)
B(5,30,8,minecraft:warped_hyphae)
B(5,31,8,minecraft:warped_hyphae)
B(6,14,5,minecraft:warped_hyphae)
B(6,15,5,minecraft:warped_hyphae)
B(6,16,5,minecraft:warped_hyphae)
B(6,13,6,minecraft:warped_hyphae)
B(6,14,6,minecraft:warped_hyphae)
B(6,15,6,minecraft:warped_hyphae)
B(6,16,6,minecraft:warped_hyphae)
B(6,17,6,minecraft:warped_hyphae)
B(6,23,6,minecraft:warped_hyphae)
B(6,24,6,minecraft:warped_hyphae)
B(6,25,6,minecraft:warped_hyphae)
B(6,26,6,minecraft:warped_hyphae)
B(6,27,6,minecraft:warped_hyphae)
B(6,28,6,minecraft:warped_hyphae)
B(6,29,6,minecraft:warped_hyphae)
B(6,30,6,minecraft:warped_hyphae)
B(6,0,7,minecraft:netherrack)
B(6,1,7,minecraft:netherrack)
B(6,12,7,minecraft:warped_hyphae)
B(6,13,7,minecraft:warped_hyphae)
B(6,14,7,minecraft:warped_hyphae)
B(6,15,7,minecraft:warped_hyphae)
B(6,16,7,minecraft:warped_hyphae)
B(6,17,7,minecraft:warped_hyphae)
B(6,18,7,minecraft:warped_hyphae)
B(6,23,7,minecraft:warped_hyphae)
B(6,24,7,minecraft:warped_hyphae)
B(6,25,7,minecraft:warped_hyphae)
B(6,26,7,minecraft:warped_hyphae)
B(6,27,7,minecraft:warped_hyphae)
B(6,28,7,minecraft:warped_hyphae)
B(6,29,7,minecraft:warped_hyphae)
B(6,30,7,minecraft:warped_hyphae)
B(6,0,8,minecraft:netherrack)
B(6,1,8,minecraft:netherrack)
B(6,12,8,minecraft:warped_hyphae)
B(6,13,8,minecraft:warped_hyphae)
B(6,14,8,minecraft:warped_hyphae)
B(6,15,8,minecraft:warped_hyphae)
B(6,16,8,minecraft:warped_hyphae)
B(6,17,8,minecraft:warped_hyphae)
B(6,18,8,minecraft:warped_hyphae)
B(6,23,8,minecraft:warped_hyphae)
B(6,24,8,minecraft:warped_hyphae)
B(6,25,8,minecraft:warped_hyphae)
B(6,26,8,minecraft:warped_hyphae)
B(6,27,8,minecraft:warped_hyphae)
B(6,28,8,minecraft:warped_hyphae)
B(6,29,8,minecraft:warped_hyphae)
B(6,30,8,minecraft:warped_hyphae)
B(6,73,8,minecraft:warped_hyphae)
B(6,74,8,minecraft:warped_hyphae)
B(6,75,8,minecraft:warped_hyphae)
B(7,14,5,minecraft:warped_hyphae)
B(7,15,5,minecraft:warped_hyphae)
B(7,16,5,minecraft:warped_hyphae)
B(7,17,5,minecraft:warped_hyphae)
B(7,18,5,minecraft:warped_hyphae)
B(7,13,6,minecraft:warped_hyphae)
B(7,14,6,minecraft:warped_hyphae)
B(7,15,6,minecraft:warped_hyphae)
B(7,16,6,minecraft:warped_hyphae)
B(7,17,6,minecraft:warped_hyphae)
B(7,18,6,minecraft:warped_hyphae)
B(7,0,7,minecraft:netherrack)
B(7,12,7,minecraft:warped_hyphae)
B(7,13,7,minecraft:warped_hyphae)
B(7,14,7,minecraft:warped_hyphae)
B(7,15,7,minecraft:warped_hyphae)
B(7,16,7,minecraft:warped_hyphae)
B(7,17,7,minecraft:warped_hyphae)
B(7,18,7,minecraft:warped_hyphae)
B(7,24,7,minecraft:warped_hyphae)
B(7,25,7,minecraft:warped_hyphae)
B(7,26,7,minecraft:warped_hyphae)
B(7,27,7,minecraft:warped_hyphae)
B(7,28,7,minecraft:warped_hyphae)
B(7,29,7,minecraft:warped_hyphae)
B(7,0,8,minecraft:netherrack)
B(7,12,8,minecraft:warped_hyphae)
B(7,13,8,minecraft:warped_hyphae)
B(7,14,8,minecraft:warped_hyphae)
B(7,15,8,minecraft:warped_hyphae)
B(7,16,8,minecraft:warped_hyphae)
B(7,17,8,minecraft:warped_hyphae)
B(7,18,8,minecraft:warped_hyphae)
B(7,24,8,minecraft:warped_hyphae)
B(7,25,8,minecraft:warped_hyphae)
B(7,26,8,minecraft:warped_hyphae)
B(7,27,8,minecraft:warped_hyphae)
B(7,28,8,minecraft:warped_hyphae)
B(7,29,8,minecraft:warped_hyphae)
B(7,73,8,minecraft:warped_hyphae)
B(7,74,8,minecraft:warped_hyphae)
B(7,75,8,minecraft:warped_hyphae)

#######################################################################
# +-----------------------------------------------------------------+ #
# |                             Branches                            | #
# +-----------------------------------------------------------------+ #
#######################################################################

Branch(16,0,0,true,WarpedBeanstalk1_C2_R0,NORTH,100.0,0)

#######################################################################
# +-----------------------------------------------------------------+ #
# |                             Entities                            | #
# +-----------------------------------------------------------------+ #
#######################################################################

