
#######################################################################
# +-----------------------------------------------------------------+ #
# |                            BO4 object                           | #
# +-----------------------------------------------------------------+ #
#######################################################################

Author: Unknown

Description: No description given

SettingsMode: WriteWithoutComments


#######################################################################
# +-----------------------------------------------------------------+ #
# |                          Main settings                          | #
# +-----------------------------------------------------------------+ #
#######################################################################

FixedRotation: 

Frequency: 0

SpawnHeight: highestBlock

UseCenterForHighestBlock: true

##############################
# Height Limits for the BO4. #
##############################

MinHeight: 0

MaxHeight: 255

InheritBO3: 

InheritBO3Rotation: NORTH

OverrideChildSettings: true

OverrideParentHeight: false

CanOverride: false

BranchFrequency: 0

BranchFrequencyGroup: 

MustBeBelowOther: false

MustBeInside: 

CannotBeInside: 

ReplacesBO3: 

MustBeInsideWorldBorders: false

CanSpawnOnWater: true

SpawnOnWaterOnly: false

SpawnUnderWater: false

SpawnAtWaterLevel: false

HeightOffset: 0

RemoveAir: true

ReplaceAbove: 

ReplaceBelow: 

ReplaceWithBiomeBlocks: true

ReplaceWithSurfaceBlock: GRASS

ReplaceWithGroundBlock: DIRT

ReplaceWithStoneBlock: STONE

SmoothRadius: 0

SmoothHeightOffset: 0

SmoothStartTop: false

SmoothStartWood: false

SmoothingSurfaceBlock: 

SmoothingGroundBlock: 

BO3Group: 

IsSpawnPoint: false

DoReplaceBlocks: true


#######################################################################
# +-----------------------------------------------------------------+ #
# |                              Blocks                             | #
# +-----------------------------------------------------------------+ #
#######################################################################

B(-8,51,-7,minecraft:basalt)
B(-8,51,-6,minecraft:basalt)
B(-8,51,-5,minecraft:basalt)
B(-8,51,-4,minecraft:basalt)
B(-8,51,-3,minecraft:basalt)
B(-7,50,-7,minecraft:basalt)
B(-7,51,-7,minecraft:blackstone)
B(-7,51,-6,minecraft:basalt)
B(-7,51,-5,minecraft:basalt)
B(-7,51,-4,minecraft:basalt)
B(-7,51,-3,minecraft:basalt)
B(-6,50,-7,minecraft:basalt)
B(-6,51,-7,minecraft:basalt)
B(-6,50,-6,minecraft:basalt)
B(-6,51,-6,minecraft:blackstone)
B(-6,51,-5,minecraft:basalt)
B(-6,51,-4,minecraft:basalt)
B(-6,51,-3,minecraft:basalt)
B(-5,49,-7,minecraft:basalt)
B(-5,50,-7,minecraft:basalt)
B(-5,51,-7,minecraft:basalt)
B(-5,50,-6,minecraft:basalt)
B(-5,51,-6,minecraft:basalt)
B(-5,51,-5,minecraft:basalt)
B(-5,51,-4,minecraft:basalt)
B(-5,51,-3,minecraft:basalt)
B(-4,49,-7,minecraft:basalt)
B(-4,50,-7,minecraft:basalt)
B(-4,51,-7,minecraft:basalt)
B(-4,50,-6,minecraft:basalt)
B(-4,51,-6,minecraft:basalt)
B(-4,51,-5,minecraft:basalt)
B(-4,51,-4,minecraft:basalt)
B(-4,51,-3,minecraft:basalt)
B(-3,49,-7,minecraft:basalt)
B(-3,50,-7,minecraft:basalt)
B(-3,51,-7,minecraft:basalt)
B(-3,50,-6,minecraft:basalt)
B(-3,51,-6,minecraft:basalt)
B(-3,51,-5,minecraft:basalt)
B(-3,51,-4,minecraft:basalt)
B(-2,49,-7,minecraft:basalt)
B(-2,50,-7,minecraft:basalt)
B(-2,51,-7,minecraft:basalt)
B(-2,50,-6,minecraft:basalt)
B(-2,51,-6,minecraft:basalt)
B(-2,51,-5,minecraft:basalt)
B(-2,51,-4,minecraft:basalt)
B(-2,51,-3,minecraft:basalt)
B(-1,49,-7,minecraft:basalt)
B(-1,50,-7,minecraft:basalt)
B(-1,51,-7,minecraft:basalt)
B(-1,50,-6,minecraft:basalt)
B(-1,51,-6,minecraft:basalt)
B(-1,50,-5,minecraft:basalt)
B(-1,51,-5,minecraft:basalt)
B(-1,51,-4,minecraft:basalt)
B(-1,51,-3,minecraft:basalt)
B(0,49,-7,minecraft:basalt)
B(0,50,-7,minecraft:basalt)
B(0,51,-7,minecraft:basalt)
B(0,49,-6,minecraft:basalt)
B(0,50,-6,minecraft:basalt)
B(0,51,-6,minecraft:basalt)
B(0,50,-5,minecraft:basalt)
B(0,51,-5,minecraft:basalt)
B(0,50,-4,minecraft:basalt)
B(0,51,-4,minecraft:basalt)
B(0,51,-3,minecraft:basalt)
B(1,48,-7,minecraft:basalt)
B(1,49,-7,minecraft:basalt)
B(1,50,-7,minecraft:basalt)
B(1,51,-7,minecraft:basalt)
B(1,49,-6,minecraft:basalt)
B(1,50,-6,minecraft:basalt)
B(1,51,-6,minecraft:basalt)
B(1,49,-5,minecraft:basalt)
B(1,50,-5,minecraft:basalt)
B(1,51,-5,minecraft:basalt)
B(1,50,-4,minecraft:basalt)
B(1,51,-4,minecraft:basalt)
B(1,50,-3,minecraft:basalt)
B(1,51,-3,minecraft:basalt)
B(2,48,-7,minecraft:basalt)
B(2,49,-7,minecraft:basalt)
B(2,50,-7,minecraft:basalt)
B(2,51,-7,minecraft:basalt)
B(2,48,-6,minecraft:basalt)
B(2,49,-6,minecraft:basalt)
B(2,50,-6,minecraft:basalt)
B(2,51,-6,minecraft:basalt)
B(2,49,-5,minecraft:basalt)
B(2,50,-5,minecraft:basalt)
B(2,51,-5,minecraft:basalt)
B(2,49,-4,minecraft:basalt)
B(2,50,-4,minecraft:basalt)
B(2,51,-4,minecraft:basalt)
B(2,50,-3,minecraft:basalt)
B(2,51,-3,minecraft:basalt)
B(3,48,-7,minecraft:basalt)
B(3,49,-7,minecraft:basalt)
B(3,50,-7,minecraft:basalt)
B(3,51,-7,minecraft:basalt)
B(3,48,-6,minecraft:basalt)
B(3,49,-6,minecraft:basalt)
B(3,50,-6,minecraft:basalt)
B(3,51,-6,minecraft:basalt)
B(3,49,-5,minecraft:basalt)
B(3,50,-5,minecraft:basalt)
B(3,51,-5,minecraft:basalt)
B(3,49,-4,minecraft:basalt)
B(3,50,-4,minecraft:basalt)
B(3,51,-4,minecraft:basalt)
B(3,50,-3,minecraft:basalt)
B(3,51,-3,minecraft:basalt)
B(4,48,-7,minecraft:basalt)
B(4,49,-7,minecraft:basalt)
B(4,50,-7,minecraft:basalt)
B(4,51,-7,minecraft:basalt)
B(4,49,-6,minecraft:basalt)
B(4,50,-6,minecraft:basalt)
B(4,51,-6,minecraft:basalt)
B(4,49,-5,minecraft:basalt)
B(4,50,-5,minecraft:basalt)
B(4,51,-5,minecraft:basalt)
B(4,49,-4,minecraft:basalt)
B(4,50,-4,minecraft:basalt)
B(4,51,-4,minecraft:basalt)
B(4,50,-3,minecraft:basalt)
B(4,51,-3,minecraft:basalt)
B(5,49,-7,minecraft:basalt)
B(5,50,-7,minecraft:basalt)
B(5,51,-7,minecraft:basalt)
B(5,49,-6,minecraft:basalt)
B(5,50,-6,minecraft:basalt)
B(5,51,-6,minecraft:basalt)
B(5,49,-5,minecraft:basalt)
B(5,50,-5,minecraft:basalt)
B(5,51,-5,minecraft:basalt)
B(5,49,-4,minecraft:basalt)
B(5,50,-4,minecraft:basalt)
B(5,51,-4,minecraft:basalt)
B(5,50,-3,minecraft:basalt)
B(5,51,-3,minecraft:basalt)
B(6,49,-7,minecraft:basalt)
B(6,50,-7,minecraft:basalt)
B(6,51,-7,minecraft:basalt)
B(6,49,-6,minecraft:basalt)
B(6,50,-6,minecraft:basalt)
B(6,51,-6,minecraft:basalt)
B(6,49,-5,minecraft:basalt)
B(6,50,-5,minecraft:basalt)
B(6,51,-5,minecraft:basalt)
B(6,49,-4,minecraft:basalt)
B(6,50,-4,minecraft:basalt)
B(6,51,-4,minecraft:basalt)
B(6,50,-3,minecraft:basalt)
B(6,51,-3,minecraft:basalt)
B(7,49,-7,minecraft:basalt)
B(7,50,-7,minecraft:basalt)
B(7,51,-7,minecraft:basalt)
B(7,49,-6,minecraft:basalt)
B(7,50,-6,minecraft:basalt)
B(7,51,-6,minecraft:basalt)
B(7,49,-5,minecraft:basalt)
B(7,50,-5,minecraft:basalt)
B(7,51,-5,minecraft:basalt)
B(7,49,-4,minecraft:basalt)
B(7,50,-4,minecraft:basalt)
B(7,51,-4,minecraft:basalt)
B(7,50,-3,minecraft:basalt)
B(7,51,-3,minecraft:basalt)

#######################################################################
# +-----------------------------------------------------------------+ #
# |                             Branches                            | #
# +-----------------------------------------------------------------+ #
#######################################################################

Branch(16,0,0,true,GiantBasaltStalactite1_C1_R3,NORTH,100.0,0)

#######################################################################
# +-----------------------------------------------------------------+ #
# |                             Entities                            | #
# +-----------------------------------------------------------------+ #
#######################################################################

