Author: Bo3 BulkEdit

Description: Converted Schematic - Modified by Bo3BulkEdit

Version: 3

SettingsMode: WriteDisable

IsOTGPlus: true
Tree: false
Frequency: 1
Rarity: 100
RotateRandomly: false
SpawnHeight: randomY
SpawnHeightOffset: 0
SpawnHeightVariance: 0
MaxBranchDepth: 10
ExcludedBiomes: All

MinHeight: 25
MaxHeight: 30

SourceBlocks: AIR
MaxPercentageOutsideSourceBlock: 100
OutsideSourceBlock: placeAnyway

B(8,24,15,minecraft:glowstone)
B(8,25,15,minecraft:chain[axis=y,waterlogged=false])
B(8,26,15,minecraft:glowstone)
RB(7,27,15,minecraft:crying_obsidian,10,minecraft:obsidian,100)
RB(9,27,15,minecraft:crying_obsidian,10,minecraft:obsidian,100)
RB(6,28,14,minecraft:crying_obsidian,10,minecraft:obsidian,100)
RB(10,28,14,minecraft:crying_obsidian,10,minecraft:obsidian,100)
RB(6,29,14,minecraft:crying_obsidian,10,minecraft:obsidian,100)
RB(10,29,14,minecraft:crying_obsidian,10,minecraft:obsidian,100)
RB(6,30,14,minecraft:crying_obsidian,10,minecraft:obsidian,100)
RB(10,30,14,minecraft:crying_obsidian,10,minecraft:obsidian,100)
RB(7,31,14,minecraft:crying_obsidian,10,minecraft:obsidian,100)
RB(9,31,14,minecraft:crying_obsidian,10,minecraft:obsidian,100)
B(8,32,13,minecraft:glowstone)
B(8,33,13,minecraft:chain[axis=y,waterlogged=false])
B(8,34,13,minecraft:glowstone)
RB(7,35,13,minecraft:crying_obsidian,10,minecraft:obsidian,100)
RB(9,35,13,minecraft:crying_obsidian,10,minecraft:obsidian,100)
RB(6,36,12,minecraft:crying_obsidian,10,minecraft:obsidian,100)
RB(10,36,12,minecraft:crying_obsidian,10,minecraft:obsidian,100)
RB(6,37,12,minecraft:crying_obsidian,10,minecraft:obsidian,100)
RB(10,37,12,minecraft:crying_obsidian,10,minecraft:obsidian,100)
RB(6,38,12,minecraft:crying_obsidian,10,minecraft:obsidian,100)
RB(10,38,12,minecraft:crying_obsidian,10,minecraft:obsidian,100)
RB(7,39,12,minecraft:crying_obsidian,10,minecraft:obsidian,100)
RB(9,39,12,minecraft:crying_obsidian,10,minecraft:obsidian,100)
B(8,40,11,minecraft:glowstone)
B(8,41,11,minecraft:chain[axis=y,waterlogged=false])
B(8,42,11,minecraft:glowstone)
RB(7,43,11,minecraft:crying_obsidian,10,minecraft:obsidian,100)
RB(9,43,11,minecraft:crying_obsidian,10,minecraft:obsidian,100)
RB(6,44,10,minecraft:crying_obsidian,10,minecraft:obsidian,100)
RB(10,44,10,minecraft:crying_obsidian,10,minecraft:obsidian,100)
RB(6,45,10,minecraft:crying_obsidian,10,minecraft:obsidian,100)
RB(10,45,10,minecraft:crying_obsidian,10,minecraft:obsidian,100)
RB(6,46,10,minecraft:crying_obsidian,10,minecraft:obsidian,100)
RB(10,46,10,minecraft:crying_obsidian,10,minecraft:obsidian,100)
RB(7,47,10,minecraft:crying_obsidian,10,minecraft:obsidian,100)
RB(9,47,10,minecraft:crying_obsidian,10,minecraft:obsidian,100)
B(8,48,9,minecraft:glowstone)
B(8,49,9,minecraft:chain[axis=y,waterlogged=false])
B(8,50,9,minecraft:glowstone)
RB(7,51,9,minecraft:crying_obsidian,10,minecraft:obsidian,100)
RB(9,51,9,minecraft:crying_obsidian,10,minecraft:obsidian,100)
RB(6,52,8,minecraft:crying_obsidian,10,minecraft:obsidian,100)
RB(10,52,8,minecraft:crying_obsidian,10,minecraft:obsidian,100)
RB(6,53,8,minecraft:crying_obsidian,10,minecraft:obsidian,100)
RB(10,53,8,minecraft:crying_obsidian,10,minecraft:obsidian,100)
RB(6,54,8,minecraft:crying_obsidian,10,minecraft:obsidian,100)
RB(10,54,8,minecraft:crying_obsidian,10,minecraft:obsidian,100)
RB(7,55,8,minecraft:crying_obsidian,10,minecraft:obsidian,100)
RB(9,55,8,minecraft:crying_obsidian,10,minecraft:obsidian,100)
B(8,56,7,minecraft:glowstone)
B(8,57,7,minecraft:chain[axis=y,waterlogged=false])
B(8,58,7,minecraft:glowstone)
RB(7,59,7,minecraft:crying_obsidian,10,minecraft:obsidian,100)
RB(9,59,7,minecraft:crying_obsidian,10,minecraft:obsidian,100)
RB(6,60,6,minecraft:crying_obsidian,10,minecraft:obsidian,100)
RB(10,60,6,minecraft:crying_obsidian,10,minecraft:obsidian,100)
RB(6,61,6,minecraft:crying_obsidian,10,minecraft:obsidian,100)
RB(10,61,6,minecraft:crying_obsidian,10,minecraft:obsidian,100)
RB(6,62,6,minecraft:crying_obsidian,10,minecraft:obsidian,100)
RB(10,62,6,minecraft:crying_obsidian,10,minecraft:obsidian,100)
RB(7,63,6,minecraft:crying_obsidian,10,minecraft:obsidian,100)
RB(9,63,6,minecraft:crying_obsidian,10,minecraft:obsidian,100)
B(8,64,5,minecraft:glowstone)
B(8,65,5,minecraft:chain[axis=y,waterlogged=false])
B(8,66,5,minecraft:glowstone)
RB(7,67,5,minecraft:crying_obsidian,10,minecraft:obsidian,100)
RB(9,67,5,minecraft:crying_obsidian,10,minecraft:obsidian,100)
RB(6,68,4,minecraft:crying_obsidian,10,minecraft:obsidian,100)
RB(10,68,4,minecraft:crying_obsidian,10,minecraft:obsidian,100)
RB(6,69,4,minecraft:crying_obsidian,10,minecraft:obsidian,100)
RB(10,69,4,minecraft:crying_obsidian,10,minecraft:obsidian,100)
RB(6,70,4,minecraft:crying_obsidian,10,minecraft:obsidian,100)
RB(10,70,4,minecraft:crying_obsidian,10,minecraft:obsidian,100)
RB(7,71,4,minecraft:crying_obsidian,10,minecraft:obsidian,100)
RB(9,71,4,minecraft:crying_obsidian,10,minecraft:obsidian,100)
B(8,72,3,minecraft:glowstone)
B(8,73,3,minecraft:chain[axis=y,waterlogged=false])
B(8,74,3,minecraft:glowstone)
RB(7,75,3,minecraft:crying_obsidian,10,minecraft:obsidian,100)
RB(9,75,3,minecraft:crying_obsidian,10,minecraft:obsidian,100)
RB(6,76,2,minecraft:crying_obsidian,10,minecraft:obsidian,100)
RB(10,76,2,minecraft:crying_obsidian,10,minecraft:obsidian,100)
RB(6,77,2,minecraft:crying_obsidian,10,minecraft:obsidian,100)
RB(10,77,2,minecraft:crying_obsidian,10,minecraft:obsidian,100)
RB(6,78,2,minecraft:crying_obsidian,10,minecraft:obsidian,100)
RB(10,78,2,minecraft:crying_obsidian,10,minecraft:obsidian,100)
RB(7,79,2,minecraft:crying_obsidian,10,minecraft:obsidian,100)
RB(9,79,2,minecraft:crying_obsidian,10,minecraft:obsidian,100)
B(8,80,1,minecraft:glowstone)
B(8,81,1,minecraft:chain[axis=y,waterlogged=false])
B(8,82,1,minecraft:glowstone)
RB(7,83,1,minecraft:crying_obsidian,10,minecraft:obsidian,100)
RB(9,83,1,minecraft:crying_obsidian,10,minecraft:obsidian,100)
RB(6,84,0,minecraft:crying_obsidian,10,minecraft:obsidian,100)
RB(10,84,0,minecraft:crying_obsidian,10,minecraft:obsidian,100)
RB(6,85,0,minecraft:crying_obsidian,10,minecraft:obsidian,100)
RB(10,85,0,minecraft:crying_obsidian,10,minecraft:obsidian,100)
RB(6,86,0,minecraft:crying_obsidian,10,minecraft:obsidian,100)
RB(10,86,0,minecraft:crying_obsidian,10,minecraft:obsidian,100)
RB(7,87,0,minecraft:crying_obsidian,10,minecraft:obsidian,100)
RB(9,87,0,minecraft:crying_obsidian,10,minecraft:obsidian,100)

BR(0,0,16,true,ObsidianChain2_0x2,NORTH,100,0)
BR(0,0,-16,true,ObsidianChain2_0x0,NORTH,100,0)
