Author: Bo3 BulkEdit

Description: Converted Schematic - Modified by Bo3BulkEdit

Version: 3

SettingsMode: WriteDisable

IsOTGPlus: true
Tree: false
Frequency: 10
Rarity: 100
RotateRandomly: true
SpawnHeight: randomY
SpawnHeightOffset: 0
SpawnHeightVariance: 0
MaxBranchDepth: 10
ExcludedBiomes: All

MinHeight: 50
MaxHeight: 65

SourceBlocks: AIR
MaxPercentageOutsideSourceBlock: 100
OutsideSourceBlock: placeAnyway

ReplaceBelow: BLACKSTONE
ReplaceWithBiomeBlocks: false
ReplaceWithGroundBlock: BLACKSTONE
ReplaceWithSurfaceBlock: BLACKSTONE
ReplaceWithStoneBlock: BLACKSTONE
SmoothRadius: 30
SmoothingSurfaceBlock: BLACKSTONE
SmoothingGroundBlock: BLACKSTONE

B(0,750,0,AIR)
B(15,750,15,AIR)
B(6,0,0,minecraft:blackstone)
B(7,0,0,minecraft:blackstone)
B(8,0,0,minecraft:blackstone)
B(9,0,0,minecraft:blackstone)
B(10,0,0,minecraft:blackstone)
B(11,0,0,minecraft:blackstone)
B(12,0,0,minecraft:blackstone)
B(13,0,0,minecraft:blackstone)
B(14,0,0,minecraft:blackstone)
B(15,0,0,minecraft:blackstone)
B(6,0,1,minecraft:blackstone)
B(7,0,1,minecraft:blackstone)
B(8,0,1,minecraft:blackstone)
B(9,0,1,minecraft:blackstone)
B(10,0,1,minecraft:blackstone)
B(11,0,1,minecraft:blackstone)
B(12,0,1,minecraft:blackstone)
B(13,0,1,minecraft:blackstone)
B(14,0,1,minecraft:blackstone)
B(15,0,1,minecraft:blackstone)
B(6,0,2,minecraft:blackstone)
B(7,0,2,minecraft:blackstone)
B(8,0,2,minecraft:blackstone)
B(9,0,2,minecraft:blackstone)
B(10,0,2,minecraft:blackstone)
B(11,0,2,minecraft:blackstone)
B(12,0,2,minecraft:blackstone)
B(13,0,2,minecraft:blackstone)
B(14,0,2,minecraft:blackstone)
B(15,0,2,minecraft:blackstone)
B(6,0,3,minecraft:blackstone)
B(7,0,3,minecraft:blackstone)
B(8,0,3,minecraft:blackstone)
B(9,0,3,minecraft:blackstone)
B(10,0,3,minecraft:blackstone)
B(11,0,3,minecraft:blackstone)
B(12,0,3,minecraft:blackstone)
B(13,0,3,minecraft:blackstone)
B(14,0,3,minecraft:blackstone)
B(15,0,3,minecraft:blackstone)
B(7,0,4,minecraft:blackstone)
B(8,0,4,minecraft:blackstone)
B(9,0,4,minecraft:blackstone)
B(10,0,4,minecraft:blackstone)
B(11,0,4,minecraft:blackstone)
B(12,0,4,minecraft:blackstone)
B(13,0,4,minecraft:blackstone)
B(14,0,4,minecraft:blackstone)
B(15,0,4,minecraft:blackstone)
B(8,0,5,minecraft:blackstone)
B(9,0,5,minecraft:blackstone)
B(10,0,5,minecraft:blackstone)
B(11,0,5,minecraft:blackstone)
B(12,0,5,minecraft:blackstone)
B(13,0,5,minecraft:blackstone)
B(14,0,5,minecraft:blackstone)
B(15,0,5,minecraft:blackstone)
B(9,0,6,minecraft:blackstone)
B(10,0,6,minecraft:blackstone)
B(11,0,6,minecraft:blackstone)
B(12,0,6,minecraft:blackstone)
B(13,0,6,minecraft:blackstone)
B(14,0,6,minecraft:blackstone)
B(15,0,6,minecraft:blackstone)
B(10,0,7,minecraft:blackstone)
B(11,0,7,minecraft:blackstone)
B(12,0,7,minecraft:blackstone)
B(13,0,7,minecraft:blackstone)
B(14,0,7,minecraft:blackstone)
B(15,0,7,minecraft:blackstone)
B(10,0,8,minecraft:blackstone)
B(11,0,8,minecraft:blackstone)
B(12,0,8,minecraft:blackstone)
B(13,0,8,minecraft:blackstone)
B(14,0,8,minecraft:blackstone)
B(15,0,8,minecraft:blackstone)
B(10,0,9,minecraft:blackstone)
B(11,0,9,minecraft:blackstone)
B(12,0,9,minecraft:blackstone)
B(13,0,9,minecraft:blackstone)
B(14,0,9,minecraft:blackstone)
B(15,0,9,minecraft:blackstone)
B(11,0,10,minecraft:blackstone)
B(12,0,10,minecraft:blackstone)
B(13,0,10,minecraft:blackstone)
B(14,0,10,minecraft:blackstone)
B(15,0,10,minecraft:blackstone)
B(11,0,11,minecraft:blackstone)
B(12,0,11,minecraft:blackstone)
B(13,0,11,minecraft:blackstone)
B(14,0,11,minecraft:blackstone)
B(15,0,11,minecraft:blackstone)
B(13,0,12,minecraft:blackstone)
B(14,0,12,minecraft:blackstone)
B(15,0,12,minecraft:blackstone)
B(6,1,0,minecraft:blackstone)
B(7,1,0,minecraft:blackstone)
B(8,1,0,minecraft:blackstone)
B(9,1,0,minecraft:blackstone)
B(10,1,0,minecraft:blackstone)
B(11,1,0,minecraft:blackstone)
B(12,1,0,minecraft:blackstone)
B(13,1,0,minecraft:blackstone)
B(14,1,0,minecraft:blackstone)
B(15,1,0,minecraft:blackstone)
B(6,1,1,minecraft:blackstone)
B(7,1,1,minecraft:blackstone)
B(8,1,1,minecraft:blackstone)
B(9,1,1,minecraft:blackstone)
B(10,1,1,minecraft:blackstone)
B(11,1,1,minecraft:blackstone)
B(12,1,1,minecraft:blackstone)
B(13,1,1,minecraft:blackstone)
B(14,1,1,minecraft:blackstone)
B(15,1,1,minecraft:blackstone)
B(6,1,2,minecraft:blackstone)
B(7,1,2,minecraft:blackstone)
B(8,1,2,minecraft:blackstone)
B(9,1,2,minecraft:blackstone)
B(10,1,2,minecraft:blackstone)
B(11,1,2,minecraft:blackstone)
B(12,1,2,minecraft:blackstone)
B(13,1,2,minecraft:blackstone)
B(14,1,2,minecraft:blackstone)
B(15,1,2,minecraft:blackstone)
B(6,1,3,minecraft:blackstone)
B(7,1,3,minecraft:blackstone)
B(8,1,3,minecraft:blackstone)
B(9,1,3,minecraft:blackstone)
B(10,1,3,minecraft:blackstone)
B(11,1,3,minecraft:blackstone)
B(12,1,3,minecraft:blackstone)
B(13,1,3,minecraft:blackstone)
B(14,1,3,minecraft:blackstone)
B(15,1,3,minecraft:blackstone)
B(7,1,4,minecraft:blackstone)
B(8,1,4,minecraft:blackstone)
B(9,1,4,minecraft:blackstone)
B(10,1,4,minecraft:blackstone)
B(11,1,4,minecraft:blackstone)
B(12,1,4,minecraft:blackstone)
B(13,1,4,minecraft:blackstone)
B(14,1,4,minecraft:blackstone)
B(15,1,4,minecraft:blackstone)
B(8,1,5,minecraft:blackstone)
B(9,1,5,minecraft:blackstone)
B(10,1,5,minecraft:blackstone)
B(11,1,5,minecraft:blackstone)
B(12,1,5,minecraft:blackstone)
B(13,1,5,minecraft:blackstone)
B(14,1,5,minecraft:blackstone)
B(15,1,5,minecraft:blackstone)
B(9,1,6,minecraft:blackstone)
B(10,1,6,minecraft:blackstone)
B(11,1,6,minecraft:blackstone)
B(12,1,6,minecraft:blackstone)
B(13,1,6,minecraft:blackstone)
B(14,1,6,minecraft:blackstone)
B(15,1,6,minecraft:blackstone)
B(10,1,7,minecraft:blackstone)
B(11,1,7,minecraft:blackstone)
B(12,1,7,minecraft:blackstone)
B(13,1,7,minecraft:blackstone)
B(14,1,7,minecraft:blackstone)
B(15,1,7,minecraft:blackstone)
B(10,1,8,minecraft:blackstone)
B(11,1,8,minecraft:blackstone)
B(12,1,8,minecraft:blackstone)
B(13,1,8,minecraft:blackstone)
B(14,1,8,minecraft:blackstone)
B(15,1,8,minecraft:blackstone)
B(10,1,9,minecraft:blackstone)
B(11,1,9,minecraft:blackstone)
B(12,1,9,minecraft:blackstone)
B(13,1,9,minecraft:blackstone)
B(14,1,9,minecraft:blackstone)
B(15,1,9,minecraft:blackstone)
B(11,1,10,minecraft:blackstone)
B(12,1,10,minecraft:blackstone)
B(13,1,10,minecraft:blackstone)
B(14,1,10,minecraft:blackstone)
B(15,1,10,minecraft:blackstone)
B(11,1,11,minecraft:blackstone)
B(12,1,11,minecraft:blackstone)
B(13,1,11,minecraft:blackstone)
B(14,1,11,minecraft:blackstone)
B(15,1,11,minecraft:blackstone)
B(13,1,12,minecraft:blackstone)
B(14,1,12,minecraft:blackstone)
B(15,1,12,minecraft:blackstone)
B(6,2,0,minecraft:blackstone)
B(7,2,0,minecraft:blackstone)
B(8,2,0,minecraft:blackstone)
B(9,2,0,minecraft:blackstone)
B(10,2,0,minecraft:blackstone)
B(11,2,0,minecraft:blackstone)
B(12,2,0,minecraft:blackstone)
B(13,2,0,minecraft:blackstone)
B(14,2,0,minecraft:blackstone)
B(15,2,0,minecraft:blackstone)
B(6,2,1,minecraft:blackstone)
B(7,2,1,minecraft:blackstone)
B(8,2,1,minecraft:blackstone)
B(9,2,1,minecraft:blackstone)
B(10,2,1,minecraft:blackstone)
B(11,2,1,minecraft:blackstone)
B(12,2,1,minecraft:blackstone)
B(13,2,1,minecraft:blackstone)
B(14,2,1,minecraft:blackstone)
B(15,2,1,minecraft:blackstone)
B(6,2,2,minecraft:blackstone)
B(7,2,2,minecraft:blackstone)
B(8,2,2,minecraft:blackstone)
B(9,2,2,minecraft:blackstone)
B(10,2,2,minecraft:blackstone)
B(11,2,2,minecraft:blackstone)
B(12,2,2,minecraft:blackstone)
B(13,2,2,minecraft:blackstone)
B(14,2,2,minecraft:blackstone)
B(15,2,2,minecraft:blackstone)
B(6,2,3,minecraft:blackstone)
B(7,2,3,minecraft:blackstone)
B(8,2,3,minecraft:blackstone)
B(9,2,3,minecraft:blackstone)
B(10,2,3,minecraft:blackstone)
B(11,2,3,minecraft:blackstone)
B(12,2,3,minecraft:blackstone)
B(13,2,3,minecraft:blackstone)
B(14,2,3,minecraft:blackstone)
B(15,2,3,minecraft:blackstone)
B(7,2,4,minecraft:blackstone)
B(8,2,4,minecraft:blackstone)
B(9,2,4,minecraft:blackstone)
B(10,2,4,minecraft:blackstone)
B(11,2,4,minecraft:blackstone)
B(12,2,4,minecraft:blackstone)
B(13,2,4,minecraft:blackstone)
B(14,2,4,minecraft:blackstone)
B(15,2,4,minecraft:blackstone)
B(8,2,5,minecraft:blackstone)
B(9,2,5,minecraft:blackstone)
B(10,2,5,minecraft:blackstone)
B(11,2,5,minecraft:blackstone)
B(12,2,5,minecraft:blackstone)
B(13,2,5,minecraft:blackstone)
B(14,2,5,minecraft:blackstone)
B(15,2,5,minecraft:blackstone)
B(9,2,6,minecraft:blackstone)
B(10,2,6,minecraft:blackstone)
B(11,2,6,minecraft:blackstone)
B(12,2,6,minecraft:blackstone)
B(13,2,6,minecraft:blackstone)
B(14,2,6,minecraft:blackstone)
B(15,2,6,minecraft:blackstone)
B(10,2,7,minecraft:blackstone)
B(11,2,7,minecraft:blackstone)
B(12,2,7,minecraft:blackstone)
B(13,2,7,minecraft:blackstone)
B(14,2,7,minecraft:blackstone)
B(15,2,7,minecraft:blackstone)
B(10,2,8,minecraft:blackstone)
B(11,2,8,minecraft:blackstone)
B(12,2,8,minecraft:blackstone)
B(13,2,8,minecraft:blackstone)
B(14,2,8,minecraft:blackstone)
B(15,2,8,minecraft:blackstone)
B(10,2,9,minecraft:blackstone)
B(11,2,9,minecraft:blackstone)
B(12,2,9,minecraft:blackstone)
B(13,2,9,minecraft:blackstone)
B(14,2,9,minecraft:blackstone)
B(15,2,9,minecraft:blackstone)
B(11,2,10,minecraft:blackstone)
B(12,2,10,minecraft:blackstone)
B(13,2,10,minecraft:blackstone)
B(14,2,10,minecraft:blackstone)
B(15,2,10,minecraft:blackstone)
B(11,2,11,minecraft:blackstone)
B(12,2,11,minecraft:blackstone)
B(13,2,11,minecraft:blackstone)
B(14,2,11,minecraft:blackstone)
B(15,2,11,minecraft:blackstone)
B(13,2,12,minecraft:blackstone)
B(14,2,12,minecraft:blackstone)
B(15,2,12,minecraft:blackstone)
B(6,3,0,minecraft:blackstone)
B(7,3,0,minecraft:blackstone)
B(8,3,0,minecraft:blackstone)
B(9,3,0,minecraft:blackstone)
B(10,3,0,minecraft:blackstone)
B(11,3,0,minecraft:blackstone)
B(12,3,0,minecraft:blackstone)
B(13,3,0,minecraft:blackstone)
B(14,3,0,minecraft:blackstone)
B(15,3,0,minecraft:blackstone)
B(6,3,1,minecraft:blackstone)
B(7,3,1,minecraft:blackstone)
B(8,3,1,minecraft:blackstone)
B(9,3,1,minecraft:blackstone)
B(10,3,1,minecraft:blackstone)
B(11,3,1,minecraft:blackstone)
B(12,3,1,minecraft:blackstone)
B(13,3,1,minecraft:blackstone)
B(14,3,1,minecraft:blackstone)
B(15,3,1,minecraft:blackstone)
B(6,3,2,minecraft:blackstone)
B(7,3,2,minecraft:blackstone)
B(8,3,2,minecraft:blackstone)
B(9,3,2,minecraft:blackstone)
B(10,3,2,minecraft:blackstone)
B(11,3,2,minecraft:blackstone)
B(12,3,2,minecraft:blackstone)
B(13,3,2,minecraft:blackstone)
B(14,3,2,minecraft:blackstone)
B(15,3,2,minecraft:blackstone)
B(6,3,3,minecraft:blackstone)
B(7,3,3,minecraft:blackstone)
B(8,3,3,minecraft:blackstone)
B(9,3,3,minecraft:blackstone)
B(10,3,3,minecraft:blackstone)
B(11,3,3,minecraft:blackstone)
B(12,3,3,minecraft:blackstone)
B(13,3,3,minecraft:blackstone)
B(14,3,3,minecraft:blackstone)
B(15,3,3,minecraft:blackstone)
B(7,3,4,minecraft:blackstone)
B(8,3,4,minecraft:blackstone)
B(9,3,4,minecraft:blackstone)
B(10,3,4,minecraft:blackstone)
B(11,3,4,minecraft:blackstone)
B(12,3,4,minecraft:blackstone)
B(13,3,4,minecraft:blackstone)
B(14,3,4,minecraft:blackstone)
B(15,3,4,minecraft:blackstone)
B(8,3,5,minecraft:blackstone)
B(9,3,5,minecraft:blackstone)
B(10,3,5,minecraft:blackstone)
B(11,3,5,minecraft:blackstone)
B(12,3,5,minecraft:blackstone)
B(13,3,5,minecraft:blackstone)
B(14,3,5,minecraft:blackstone)
B(15,3,5,minecraft:blackstone)
B(9,3,6,minecraft:blackstone)
B(10,3,6,minecraft:blackstone)
B(11,3,6,minecraft:blackstone)
B(12,3,6,minecraft:blackstone)
B(13,3,6,minecraft:blackstone)
B(14,3,6,minecraft:blackstone)
B(15,3,6,minecraft:blackstone)
B(10,3,7,minecraft:blackstone)
B(11,3,7,minecraft:blackstone)
B(12,3,7,minecraft:blackstone)
B(13,3,7,minecraft:blackstone)
B(14,3,7,minecraft:blackstone)
B(15,3,7,minecraft:blackstone)
B(10,3,8,minecraft:blackstone)
B(11,3,8,minecraft:blackstone)
B(12,3,8,minecraft:blackstone)
B(13,3,8,minecraft:blackstone)
B(14,3,8,minecraft:blackstone)
B(15,3,8,minecraft:blackstone)
B(10,3,9,minecraft:blackstone)
B(11,3,9,minecraft:blackstone)
B(12,3,9,minecraft:blackstone)
B(13,3,9,minecraft:blackstone)
B(14,3,9,minecraft:blackstone)
B(15,3,9,minecraft:blackstone)
B(11,3,10,minecraft:blackstone)
B(12,3,10,minecraft:blackstone)
B(13,3,10,minecraft:blackstone)
B(14,3,10,minecraft:blackstone)
B(15,3,10,minecraft:blackstone)
B(11,3,11,minecraft:blackstone)
B(12,3,11,minecraft:blackstone)
B(13,3,11,minecraft:blackstone)
B(14,3,11,minecraft:blackstone)
B(15,3,11,minecraft:blackstone)
B(13,3,12,minecraft:blackstone)
B(14,3,12,minecraft:blackstone)
B(15,3,12,minecraft:blackstone)
B(6,4,0,minecraft:blackstone)
B(7,4,0,minecraft:blackstone)
B(8,4,0,minecraft:blackstone)
B(9,4,0,minecraft:blackstone)
B(10,4,0,minecraft:blackstone)
B(11,4,0,minecraft:blackstone)
B(12,4,0,minecraft:blackstone)
B(13,4,0,minecraft:blackstone)
B(14,4,0,minecraft:blackstone)
B(15,4,0,minecraft:blackstone)
B(6,4,1,minecraft:blackstone)
B(7,4,1,minecraft:blackstone)
B(8,4,1,minecraft:blackstone)
B(9,4,1,minecraft:blackstone)
B(10,4,1,minecraft:blackstone)
B(11,4,1,minecraft:blackstone)
B(12,4,1,minecraft:blackstone)
B(13,4,1,minecraft:blackstone)
B(14,4,1,minecraft:blackstone)
B(15,4,1,minecraft:blackstone)
B(6,4,2,minecraft:blackstone)
B(7,4,2,minecraft:blackstone)
B(8,4,2,minecraft:blackstone)
B(9,4,2,minecraft:blackstone)
B(10,4,2,minecraft:blackstone)
B(11,4,2,minecraft:blackstone)
B(12,4,2,minecraft:blackstone)
B(13,4,2,minecraft:blackstone)
B(14,4,2,minecraft:blackstone)
B(15,4,2,minecraft:blackstone)
B(6,4,3,minecraft:blackstone)
B(7,4,3,minecraft:blackstone)
B(8,4,3,minecraft:blackstone)
B(9,4,3,minecraft:blackstone)
B(10,4,3,minecraft:blackstone)
B(11,4,3,minecraft:blackstone)
B(12,4,3,minecraft:blackstone)
B(13,4,3,minecraft:blackstone)
B(14,4,3,minecraft:blackstone)
B(15,4,3,minecraft:blackstone)
B(7,4,4,minecraft:blackstone)
B(8,4,4,minecraft:blackstone)
B(9,4,4,minecraft:blackstone)
B(10,4,4,minecraft:blackstone)
B(11,4,4,minecraft:blackstone)
B(12,4,4,minecraft:blackstone)
B(13,4,4,minecraft:blackstone)
B(14,4,4,minecraft:blackstone)
B(15,4,4,minecraft:blackstone)
B(8,4,5,minecraft:blackstone)
B(9,4,5,minecraft:blackstone)
B(10,4,5,minecraft:blackstone)
B(11,4,5,minecraft:blackstone)
B(12,4,5,minecraft:blackstone)
B(13,4,5,minecraft:blackstone)
B(14,4,5,minecraft:blackstone)
B(15,4,5,minecraft:blackstone)
B(9,4,6,minecraft:blackstone)
B(10,4,6,minecraft:blackstone)
B(11,4,6,minecraft:blackstone)
B(12,4,6,minecraft:blackstone)
B(13,4,6,minecraft:blackstone)
B(14,4,6,minecraft:blackstone)
B(15,4,6,minecraft:blackstone)
B(10,4,7,minecraft:blackstone)
B(11,4,7,minecraft:blackstone)
B(12,4,7,minecraft:blackstone)
B(13,4,7,minecraft:blackstone)
B(14,4,7,minecraft:blackstone)
B(15,4,7,minecraft:blackstone)
B(10,4,8,minecraft:blackstone)
B(11,4,8,minecraft:blackstone)
B(12,4,8,minecraft:blackstone)
B(13,4,8,minecraft:blackstone)
B(14,4,8,minecraft:blackstone)
B(15,4,8,minecraft:blackstone)
B(10,4,9,minecraft:blackstone)
B(11,4,9,minecraft:blackstone)
B(12,4,9,minecraft:blackstone)
B(13,4,9,minecraft:blackstone)
B(14,4,9,minecraft:blackstone)
B(15,4,9,minecraft:blackstone)
B(11,4,10,minecraft:blackstone)
B(12,4,10,minecraft:blackstone)
B(13,4,10,minecraft:blackstone)
B(14,4,10,minecraft:blackstone)
B(15,4,10,minecraft:blackstone)
B(11,4,11,minecraft:blackstone)
B(12,4,11,minecraft:blackstone)
B(13,4,11,minecraft:blackstone)
B(14,4,11,minecraft:blackstone)
B(15,4,11,minecraft:blackstone)
B(13,4,12,minecraft:blackstone)
B(14,4,12,minecraft:blackstone)
B(15,4,12,minecraft:blackstone)
B(6,5,0,minecraft:blackstone)
B(7,5,0,minecraft:blackstone)
B(8,5,0,minecraft:blackstone)
B(9,5,0,minecraft:blackstone)
B(10,5,0,minecraft:blackstone)
B(11,5,0,minecraft:blackstone)
B(12,5,0,minecraft:blackstone)
B(13,5,0,minecraft:blackstone)
B(14,5,0,minecraft:blackstone)
B(15,5,0,minecraft:blackstone)
B(6,5,1,minecraft:blackstone)
B(7,5,1,minecraft:blackstone)
B(8,5,1,minecraft:blackstone)
B(9,5,1,minecraft:blackstone)
B(10,5,1,minecraft:blackstone)
B(11,5,1,minecraft:blackstone)
B(12,5,1,minecraft:blackstone)
B(13,5,1,minecraft:blackstone)
B(14,5,1,minecraft:blackstone)
B(15,5,1,minecraft:blackstone)
B(6,5,2,minecraft:blackstone)
B(7,5,2,minecraft:blackstone)
B(8,5,2,minecraft:blackstone)
B(9,5,2,minecraft:blackstone)
B(10,5,2,minecraft:blackstone)
B(11,5,2,minecraft:blackstone)
B(12,5,2,minecraft:blackstone)
B(13,5,2,minecraft:blackstone)
B(14,5,2,minecraft:blackstone)
B(15,5,2,minecraft:blackstone)
B(6,5,3,minecraft:blackstone)
B(7,5,3,minecraft:blackstone)
B(8,5,3,minecraft:blackstone)
B(9,5,3,minecraft:blackstone)
B(10,5,3,minecraft:blackstone)
B(11,5,3,minecraft:blackstone)
B(12,5,3,minecraft:blackstone)
B(13,5,3,minecraft:blackstone)
B(14,5,3,minecraft:blackstone)
B(15,5,3,minecraft:blackstone)
B(7,5,4,minecraft:blackstone)
B(8,5,4,minecraft:blackstone)
B(9,5,4,minecraft:blackstone)
B(10,5,4,minecraft:blackstone)
B(11,5,4,minecraft:blackstone)
B(12,5,4,minecraft:blackstone)
B(13,5,4,minecraft:blackstone)
B(14,5,4,minecraft:blackstone)
B(15,5,4,minecraft:blackstone)
B(8,5,5,minecraft:blackstone)
B(9,5,5,minecraft:blackstone)
B(10,5,5,minecraft:blackstone)
B(11,5,5,minecraft:blackstone)
B(12,5,5,minecraft:blackstone)
B(13,5,5,minecraft:blackstone)
B(14,5,5,minecraft:blackstone)
B(15,5,5,minecraft:blackstone)
B(9,5,6,minecraft:blackstone)
B(10,5,6,minecraft:blackstone)
B(11,5,6,minecraft:blackstone)
B(12,5,6,minecraft:blackstone)
B(13,5,6,minecraft:blackstone)
B(14,5,6,minecraft:blackstone)
B(15,5,6,minecraft:blackstone)
B(10,5,7,minecraft:blackstone)
B(11,5,7,minecraft:blackstone)
B(12,5,7,minecraft:blackstone)
B(13,5,7,minecraft:blackstone)
B(14,5,7,minecraft:blackstone)
B(15,5,7,minecraft:blackstone)
B(10,5,8,minecraft:blackstone)
B(11,5,8,minecraft:blackstone)
B(12,5,8,minecraft:blackstone)
B(13,5,8,minecraft:blackstone)
B(14,5,8,minecraft:blackstone)
B(15,5,8,minecraft:blackstone)
B(10,5,9,minecraft:blackstone)
B(11,5,9,minecraft:blackstone)
B(12,5,9,minecraft:blackstone)
B(13,5,9,minecraft:blackstone)
B(14,5,9,minecraft:blackstone)
B(15,5,9,minecraft:blackstone)
B(11,5,10,minecraft:blackstone)
B(12,5,10,minecraft:blackstone)
B(13,5,10,minecraft:blackstone)
B(14,5,10,minecraft:blackstone)
B(15,5,10,minecraft:blackstone)
B(11,5,11,minecraft:blackstone)
B(12,5,11,minecraft:blackstone)
B(13,5,11,minecraft:blackstone)
B(14,5,11,minecraft:blackstone)
B(15,5,11,minecraft:blackstone)
B(13,5,12,minecraft:blackstone)
B(14,5,12,minecraft:blackstone)
B(15,5,12,minecraft:blackstone)
B(6,6,0,minecraft:blackstone)
B(7,6,0,minecraft:blackstone)
B(8,6,0,minecraft:blackstone)
B(9,6,0,minecraft:blackstone)
B(10,6,0,minecraft:blackstone)
B(11,6,0,minecraft:blackstone)
B(12,6,0,minecraft:blackstone)
B(13,6,0,minecraft:blackstone)
B(14,6,0,minecraft:blackstone)
B(15,6,0,minecraft:blackstone)
B(6,6,1,minecraft:blackstone)
B(7,6,1,minecraft:blackstone)
B(8,6,1,minecraft:blackstone)
B(9,6,1,minecraft:blackstone)
B(10,6,1,minecraft:blackstone)
B(11,6,1,minecraft:blackstone)
B(12,6,1,minecraft:blackstone)
B(13,6,1,minecraft:blackstone)
B(14,6,1,minecraft:blackstone)
B(15,6,1,minecraft:blackstone)
B(6,6,2,minecraft:blackstone)
B(7,6,2,minecraft:blackstone)
B(8,6,2,minecraft:blackstone)
B(9,6,2,minecraft:blackstone)
B(10,6,2,minecraft:blackstone)
B(11,6,2,minecraft:blackstone)
B(12,6,2,minecraft:blackstone)
B(13,6,2,minecraft:blackstone)
B(14,6,2,minecraft:blackstone)
B(15,6,2,minecraft:blackstone)
B(6,6,3,minecraft:blackstone)
B(7,6,3,minecraft:blackstone)
B(8,6,3,minecraft:blackstone)
B(9,6,3,minecraft:blackstone)
B(10,6,3,minecraft:blackstone)
B(11,6,3,minecraft:blackstone)
B(12,6,3,minecraft:blackstone)
B(13,6,3,minecraft:blackstone)
B(14,6,3,minecraft:blackstone)
B(15,6,3,minecraft:blackstone)
B(7,6,4,minecraft:blackstone)
B(8,6,4,minecraft:blackstone)
B(9,6,4,minecraft:blackstone)
B(10,6,4,minecraft:blackstone)
B(11,6,4,minecraft:blackstone)
B(12,6,4,minecraft:blackstone)
B(13,6,4,minecraft:blackstone)
B(14,6,4,minecraft:blackstone)
B(15,6,4,minecraft:blackstone)
B(8,6,5,minecraft:blackstone)
B(9,6,5,minecraft:blackstone)
B(10,6,5,minecraft:blackstone)
B(11,6,5,minecraft:blackstone)
B(12,6,5,minecraft:blackstone)
B(13,6,5,minecraft:blackstone)
B(14,6,5,minecraft:blackstone)
B(15,6,5,minecraft:blackstone)
B(9,6,6,minecraft:blackstone)
B(10,6,6,minecraft:blackstone)
B(11,6,6,minecraft:blackstone)
B(12,6,6,minecraft:blackstone)
B(13,6,6,minecraft:blackstone)
B(14,6,6,minecraft:blackstone)
B(15,6,6,minecraft:blackstone)
B(10,6,7,minecraft:blackstone)
B(11,6,7,minecraft:blackstone)
B(12,6,7,minecraft:blackstone)
B(13,6,7,minecraft:blackstone)
B(14,6,7,minecraft:blackstone)
B(15,6,7,minecraft:blackstone)
B(10,6,8,minecraft:blackstone)
B(11,6,8,minecraft:blackstone)
B(12,6,8,minecraft:blackstone)
B(13,6,8,minecraft:blackstone)
B(14,6,8,minecraft:blackstone)
B(15,6,8,minecraft:blackstone)
B(10,6,9,minecraft:blackstone)
B(11,6,9,minecraft:blackstone)
B(12,6,9,minecraft:blackstone)
B(13,6,9,minecraft:blackstone)
B(14,6,9,minecraft:blackstone)
B(15,6,9,minecraft:blackstone)
B(11,6,10,minecraft:blackstone)
B(12,6,10,minecraft:blackstone)
B(13,6,10,minecraft:blackstone)
B(14,6,10,minecraft:blackstone)
B(15,6,10,minecraft:blackstone)
B(11,6,11,minecraft:blackstone)
B(12,6,11,minecraft:blackstone)
B(13,6,11,minecraft:blackstone)
B(14,6,11,minecraft:blackstone)
B(15,6,11,minecraft:blackstone)
B(13,6,12,minecraft:blackstone)
B(14,6,12,minecraft:blackstone)
B(15,6,12,minecraft:blackstone)
B(6,7,0,minecraft:blackstone)
B(7,7,0,minecraft:blackstone)
B(8,7,0,minecraft:blackstone)
B(9,7,0,minecraft:blackstone)
B(10,7,0,minecraft:blackstone)
B(11,7,0,minecraft:blackstone)
B(12,7,0,minecraft:blackstone)
B(13,7,0,minecraft:blackstone)
B(14,7,0,minecraft:blackstone)
B(15,7,0,minecraft:blackstone)
B(6,7,1,minecraft:blackstone)
B(7,7,1,minecraft:blackstone)
B(8,7,1,minecraft:blackstone)
B(9,7,1,minecraft:blackstone)
B(10,7,1,minecraft:blackstone)
B(11,7,1,minecraft:blackstone)
B(12,7,1,minecraft:blackstone)
B(13,7,1,minecraft:blackstone)
B(14,7,1,minecraft:blackstone)
B(15,7,1,minecraft:blackstone)
B(6,7,2,minecraft:blackstone)
B(7,7,2,minecraft:blackstone)
B(8,7,2,minecraft:blackstone)
B(9,7,2,minecraft:blackstone)
B(10,7,2,minecraft:blackstone)
B(11,7,2,minecraft:blackstone)
B(12,7,2,minecraft:blackstone)
B(13,7,2,minecraft:blackstone)
B(14,7,2,minecraft:blackstone)
B(15,7,2,minecraft:blackstone)
B(6,7,3,minecraft:blackstone)
B(7,7,3,minecraft:blackstone)
B(8,7,3,minecraft:blackstone)
B(9,7,3,minecraft:blackstone)
B(10,7,3,minecraft:blackstone)
B(11,7,3,minecraft:blackstone)
B(12,7,3,minecraft:blackstone)
B(13,7,3,minecraft:blackstone)
B(14,7,3,minecraft:blackstone)
B(15,7,3,minecraft:blackstone)
B(7,7,4,minecraft:blackstone)
B(8,7,4,minecraft:blackstone)
B(9,7,4,minecraft:blackstone)
B(10,7,4,minecraft:blackstone)
B(11,7,4,minecraft:blackstone)
B(12,7,4,minecraft:blackstone)
B(13,7,4,minecraft:blackstone)
B(14,7,4,minecraft:blackstone)
B(15,7,4,minecraft:blackstone)
B(8,7,5,minecraft:blackstone)
B(9,7,5,minecraft:blackstone)
B(10,7,5,minecraft:blackstone)
B(11,7,5,minecraft:blackstone)
B(12,7,5,minecraft:blackstone)
B(13,7,5,minecraft:blackstone)
B(14,7,5,minecraft:blackstone)
B(15,7,5,minecraft:blackstone)
B(9,7,6,minecraft:blackstone)
B(10,7,6,minecraft:blackstone)
B(11,7,6,minecraft:blackstone)
B(12,7,6,minecraft:blackstone)
B(13,7,6,minecraft:blackstone)
B(14,7,6,minecraft:blackstone)
B(15,7,6,minecraft:blackstone)
B(10,7,7,minecraft:blackstone)
B(11,7,7,minecraft:blackstone)
B(12,7,7,minecraft:blackstone)
B(13,7,7,minecraft:blackstone)
B(14,7,7,minecraft:blackstone)
B(15,7,7,minecraft:blackstone)
B(10,7,8,minecraft:blackstone)
B(11,7,8,minecraft:blackstone)
B(12,7,8,minecraft:blackstone)
B(13,7,8,minecraft:blackstone)
B(14,7,8,minecraft:blackstone)
B(15,7,8,minecraft:blackstone)
B(10,7,9,minecraft:blackstone)
B(11,7,9,minecraft:blackstone)
B(12,7,9,minecraft:blackstone)
B(13,7,9,minecraft:blackstone)
B(14,7,9,minecraft:blackstone)
B(15,7,9,minecraft:blackstone)
B(11,7,10,minecraft:blackstone)
B(12,7,10,minecraft:blackstone)
B(13,7,10,minecraft:blackstone)
B(14,7,10,minecraft:blackstone)
B(15,7,10,minecraft:blackstone)
B(11,7,11,minecraft:blackstone)
B(12,7,11,minecraft:blackstone)
B(13,7,11,minecraft:blackstone)
B(14,7,11,minecraft:blackstone)
B(15,7,11,minecraft:blackstone)
B(13,7,12,minecraft:blackstone)
B(14,7,12,minecraft:blackstone)
B(15,7,12,minecraft:blackstone)
B(6,8,0,minecraft:blackstone)
B(7,8,0,minecraft:blackstone)
B(8,8,0,minecraft:blackstone)
B(9,8,0,minecraft:blackstone)
B(10,8,0,minecraft:blackstone)
B(11,8,0,minecraft:blackstone)
B(12,8,0,minecraft:blackstone)
B(13,8,0,minecraft:blackstone)
B(14,8,0,minecraft:blackstone)
B(15,8,0,minecraft:blackstone)
B(6,8,1,minecraft:blackstone)
B(7,8,1,minecraft:blackstone)
B(8,8,1,minecraft:blackstone)
B(9,8,1,minecraft:blackstone)
B(10,8,1,minecraft:blackstone)
B(11,8,1,minecraft:blackstone)
B(12,8,1,minecraft:blackstone)
B(13,8,1,minecraft:blackstone)
B(14,8,1,minecraft:blackstone)
B(15,8,1,minecraft:blackstone)
B(6,8,2,minecraft:blackstone)
B(7,8,2,minecraft:blackstone)
B(8,8,2,minecraft:blackstone)
B(9,8,2,minecraft:blackstone)
B(10,8,2,minecraft:blackstone)
B(11,8,2,minecraft:blackstone)
B(12,8,2,minecraft:blackstone)
B(13,8,2,minecraft:blackstone)
B(14,8,2,minecraft:blackstone)
B(15,8,2,minecraft:blackstone)
B(6,8,3,minecraft:blackstone)
B(7,8,3,minecraft:blackstone)
B(8,8,3,minecraft:blackstone)
B(9,8,3,minecraft:blackstone)
B(10,8,3,minecraft:blackstone)
B(11,8,3,minecraft:blackstone)
B(12,8,3,minecraft:blackstone)
B(13,8,3,minecraft:blackstone)
B(14,8,3,minecraft:blackstone)
B(15,8,3,minecraft:blackstone)
B(7,8,4,minecraft:blackstone)
B(8,8,4,minecraft:blackstone)
B(9,8,4,minecraft:blackstone)
B(10,8,4,minecraft:blackstone)
B(11,8,4,minecraft:blackstone)
B(12,8,4,minecraft:blackstone)
B(13,8,4,minecraft:blackstone)
B(14,8,4,minecraft:blackstone)
B(15,8,4,minecraft:blackstone)
B(8,8,5,minecraft:blackstone)
B(9,8,5,minecraft:blackstone)
B(10,8,5,minecraft:blackstone)
B(11,8,5,minecraft:blackstone)
B(12,8,5,minecraft:blackstone)
B(13,8,5,minecraft:blackstone)
B(14,8,5,minecraft:blackstone)
B(15,8,5,minecraft:blackstone)
B(9,8,6,minecraft:blackstone)
B(10,8,6,minecraft:blackstone)
B(11,8,6,minecraft:blackstone)
B(12,8,6,minecraft:blackstone)
B(13,8,6,minecraft:blackstone)
B(14,8,6,minecraft:blackstone)
B(15,8,6,minecraft:blackstone)
B(10,8,7,minecraft:blackstone)
B(11,8,7,minecraft:blackstone)
B(12,8,7,minecraft:blackstone)
B(13,8,7,minecraft:blackstone)
B(14,8,7,minecraft:blackstone)
B(15,8,7,minecraft:blackstone)
B(10,8,8,minecraft:blackstone)
B(11,8,8,minecraft:blackstone)
B(12,8,8,minecraft:blackstone)
B(13,8,8,minecraft:blackstone)
B(14,8,8,minecraft:blackstone)
B(15,8,8,minecraft:blackstone)
B(10,8,9,minecraft:blackstone)
B(11,8,9,minecraft:blackstone)
B(12,8,9,minecraft:blackstone)
B(13,8,9,minecraft:blackstone)
B(14,8,9,minecraft:blackstone)
B(15,8,9,minecraft:blackstone)
B(11,8,10,minecraft:blackstone)
B(12,8,10,minecraft:blackstone)
B(13,8,10,minecraft:blackstone)
B(14,8,10,minecraft:blackstone)
B(15,8,10,minecraft:blackstone)
B(11,8,11,minecraft:blackstone)
B(12,8,11,minecraft:blackstone)
B(13,8,11,minecraft:blackstone)
B(14,8,11,minecraft:blackstone)
B(15,8,11,minecraft:blackstone)
B(13,8,12,minecraft:blackstone)
B(14,8,12,minecraft:blackstone)
B(15,8,12,minecraft:blackstone)
B(6,9,0,minecraft:blackstone)
B(7,9,0,minecraft:blackstone)
B(8,9,0,minecraft:blackstone)
B(9,9,0,minecraft:blackstone)
B(10,9,0,minecraft:blackstone)
B(11,9,0,minecraft:blackstone)
B(12,9,0,minecraft:blackstone)
B(13,9,0,minecraft:blackstone)
B(14,9,0,minecraft:blackstone)
B(15,9,0,minecraft:blackstone)
B(6,9,1,minecraft:blackstone)
B(7,9,1,minecraft:blackstone)
B(8,9,1,minecraft:blackstone)
B(9,9,1,minecraft:blackstone)
B(10,9,1,minecraft:blackstone)
B(11,9,1,minecraft:blackstone)
B(12,9,1,minecraft:blackstone)
B(13,9,1,minecraft:blackstone)
B(14,9,1,minecraft:blackstone)
B(15,9,1,minecraft:blackstone)
B(6,9,2,minecraft:blackstone)
B(7,9,2,minecraft:blackstone)
B(8,9,2,minecraft:blackstone)
B(9,9,2,minecraft:blackstone)
B(10,9,2,minecraft:blackstone)
B(11,9,2,minecraft:blackstone)
B(12,9,2,minecraft:blackstone)
B(13,9,2,minecraft:blackstone)
B(14,9,2,minecraft:blackstone)
B(15,9,2,minecraft:blackstone)
B(6,9,3,minecraft:blackstone)
B(7,9,3,minecraft:blackstone)
B(8,9,3,minecraft:blackstone)
B(9,9,3,minecraft:blackstone)
B(10,9,3,minecraft:blackstone)
B(11,9,3,minecraft:blackstone)
B(12,9,3,minecraft:blackstone)
B(13,9,3,minecraft:blackstone)
B(14,9,3,minecraft:blackstone)
B(15,9,3,minecraft:blackstone)
B(7,9,4,minecraft:blackstone)
B(8,9,4,minecraft:blackstone)
B(9,9,4,minecraft:blackstone)
B(10,9,4,minecraft:blackstone)
B(11,9,4,minecraft:blackstone)
B(12,9,4,minecraft:blackstone)
B(13,9,4,minecraft:blackstone)
B(14,9,4,minecraft:blackstone)
B(15,9,4,minecraft:blackstone)
B(8,9,5,minecraft:blackstone)
B(9,9,5,minecraft:blackstone)
B(10,9,5,minecraft:blackstone)
B(11,9,5,minecraft:blackstone)
B(12,9,5,minecraft:blackstone)
B(13,9,5,minecraft:blackstone)
B(14,9,5,minecraft:blackstone)
B(15,9,5,minecraft:blackstone)
B(9,9,6,minecraft:blackstone)
B(10,9,6,minecraft:blackstone)
B(11,9,6,minecraft:blackstone)
B(12,9,6,minecraft:blackstone)
B(13,9,6,minecraft:blackstone)
B(14,9,6,minecraft:blackstone)
B(15,9,6,minecraft:blackstone)
B(10,9,7,minecraft:blackstone)
B(11,9,7,minecraft:blackstone)
B(12,9,7,minecraft:blackstone)
B(13,9,7,minecraft:blackstone)
B(14,9,7,minecraft:blackstone)
B(15,9,7,minecraft:blackstone)
B(10,9,8,minecraft:blackstone)
B(11,9,8,minecraft:blackstone)
B(12,9,8,minecraft:blackstone)
B(13,9,8,minecraft:blackstone)
B(14,9,8,minecraft:blackstone)
B(15,9,8,minecraft:blackstone)
B(10,9,9,minecraft:blackstone)
B(11,9,9,minecraft:blackstone)
B(12,9,9,minecraft:blackstone)
B(13,9,9,minecraft:blackstone)
B(14,9,9,minecraft:blackstone)
B(15,9,9,minecraft:blackstone)
B(11,9,10,minecraft:blackstone)
B(12,9,10,minecraft:blackstone)
B(13,9,10,minecraft:blackstone)
B(14,9,10,minecraft:blackstone)
B(15,9,10,minecraft:blackstone)
B(11,9,11,minecraft:blackstone)
B(12,9,11,minecraft:blackstone)
B(13,9,11,minecraft:blackstone)
B(14,9,11,minecraft:blackstone)
B(15,9,11,minecraft:blackstone)
B(13,9,12,minecraft:blackstone)
B(14,9,12,minecraft:blackstone)
B(15,9,12,minecraft:blackstone)
B(6,10,0,minecraft:blackstone)
B(7,10,0,minecraft:blackstone)
B(8,10,0,minecraft:blackstone)
B(9,10,0,minecraft:blackstone)
B(10,10,0,minecraft:blackstone)
B(11,10,0,minecraft:blackstone)
B(12,10,0,minecraft:blackstone)
B(13,10,0,minecraft:blackstone)
B(14,10,0,minecraft:blackstone)
B(15,10,0,minecraft:blackstone)
B(6,10,1,minecraft:blackstone)
B(7,10,1,minecraft:blackstone)
B(8,10,1,minecraft:blackstone)
B(9,10,1,minecraft:blackstone)
B(10,10,1,minecraft:blackstone)
B(11,10,1,minecraft:blackstone)
B(12,10,1,minecraft:blackstone)
B(13,10,1,minecraft:blackstone)
B(14,10,1,minecraft:blackstone)
B(15,10,1,minecraft:blackstone)
B(6,10,2,minecraft:blackstone)
B(7,10,2,minecraft:blackstone)
B(8,10,2,minecraft:blackstone)
B(9,10,2,minecraft:blackstone)
B(10,10,2,minecraft:blackstone)
B(11,10,2,minecraft:blackstone)
B(12,10,2,minecraft:blackstone)
B(13,10,2,minecraft:blackstone)
B(14,10,2,minecraft:blackstone)
B(15,10,2,minecraft:blackstone)
B(6,10,3,minecraft:blackstone)
B(7,10,3,minecraft:blackstone)
B(8,10,3,minecraft:blackstone)
B(9,10,3,minecraft:blackstone)
B(10,10,3,minecraft:blackstone)
B(11,10,3,minecraft:blackstone)
B(12,10,3,minecraft:blackstone)
B(13,10,3,minecraft:blackstone)
B(14,10,3,minecraft:blackstone)
B(15,10,3,minecraft:blackstone)
B(7,10,4,minecraft:blackstone)
B(8,10,4,minecraft:blackstone)
B(9,10,4,minecraft:blackstone)
B(10,10,4,minecraft:blackstone)
B(11,10,4,minecraft:blackstone)
B(12,10,4,minecraft:blackstone)
B(13,10,4,minecraft:blackstone)
B(14,10,4,minecraft:blackstone)
B(15,10,4,minecraft:blackstone)
B(8,10,5,minecraft:blackstone)
B(9,10,5,minecraft:blackstone)
B(10,10,5,minecraft:blackstone)
B(11,10,5,minecraft:blackstone)
B(12,10,5,minecraft:blackstone)
B(13,10,5,minecraft:blackstone)
B(14,10,5,minecraft:blackstone)
B(15,10,5,minecraft:blackstone)
B(9,10,6,minecraft:blackstone)
B(10,10,6,minecraft:blackstone)
B(11,10,6,minecraft:blackstone)
B(12,10,6,minecraft:blackstone)
B(13,10,6,minecraft:blackstone)
B(14,10,6,minecraft:blackstone)
B(15,10,6,minecraft:blackstone)
B(10,10,7,minecraft:blackstone)
B(11,10,7,minecraft:blackstone)
B(12,10,7,minecraft:blackstone)
B(13,10,7,minecraft:blackstone)
B(14,10,7,minecraft:blackstone)
B(15,10,7,minecraft:blackstone)
B(10,10,8,minecraft:blackstone)
B(11,10,8,minecraft:blackstone)
B(12,10,8,minecraft:blackstone)
B(13,10,8,minecraft:blackstone)
B(14,10,8,minecraft:blackstone)
B(15,10,8,minecraft:blackstone)
B(10,10,9,minecraft:blackstone)
B(11,10,9,minecraft:blackstone)
B(12,10,9,minecraft:blackstone)
B(13,10,9,minecraft:blackstone)
B(14,10,9,minecraft:blackstone)
B(15,10,9,minecraft:blackstone)
B(11,10,10,minecraft:blackstone)
B(12,10,10,minecraft:blackstone)
B(13,10,10,minecraft:blackstone)
B(14,10,10,minecraft:blackstone)
B(15,10,10,minecraft:blackstone)
B(11,10,11,minecraft:blackstone)
B(12,10,11,minecraft:blackstone)
B(13,10,11,minecraft:blackstone)
B(14,10,11,minecraft:blackstone)
B(15,10,11,minecraft:blackstone)
B(13,10,12,minecraft:blackstone)
B(14,10,12,minecraft:blackstone)
B(15,10,12,minecraft:blackstone)
B(6,11,0,minecraft:blackstone)
B(7,11,0,minecraft:blackstone)
B(8,11,0,minecraft:blackstone)
B(9,11,0,minecraft:blackstone)
B(10,11,0,minecraft:blackstone)
B(11,11,0,minecraft:blackstone)
B(12,11,0,minecraft:blackstone)
B(13,11,0,minecraft:blackstone)
B(14,11,0,minecraft:blackstone)
B(15,11,0,minecraft:blackstone)
B(6,11,1,minecraft:blackstone)
B(7,11,1,minecraft:blackstone)
B(8,11,1,minecraft:blackstone)
B(9,11,1,minecraft:blackstone)
B(10,11,1,minecraft:blackstone)
B(11,11,1,minecraft:blackstone)
B(12,11,1,minecraft:blackstone)
B(13,11,1,minecraft:blackstone)
B(14,11,1,minecraft:blackstone)
B(15,11,1,minecraft:blackstone)
B(6,11,2,minecraft:blackstone)
B(7,11,2,minecraft:blackstone)
B(8,11,2,minecraft:blackstone)
B(9,11,2,minecraft:blackstone)
B(10,11,2,minecraft:blackstone)
B(11,11,2,minecraft:blackstone)
B(12,11,2,minecraft:blackstone)
B(13,11,2,minecraft:blackstone)
B(14,11,2,minecraft:blackstone)
B(15,11,2,minecraft:blackstone)
B(6,11,3,minecraft:blackstone)
B(7,11,3,minecraft:blackstone)
B(8,11,3,minecraft:blackstone)
B(9,11,3,minecraft:blackstone)
B(10,11,3,minecraft:blackstone)
B(11,11,3,minecraft:blackstone)
B(12,11,3,minecraft:blackstone)
B(13,11,3,minecraft:blackstone)
B(14,11,3,minecraft:blackstone)
B(15,11,3,minecraft:blackstone)
B(7,11,4,minecraft:blackstone)
B(8,11,4,minecraft:blackstone)
B(9,11,4,minecraft:blackstone)
B(10,11,4,minecraft:blackstone)
B(11,11,4,minecraft:blackstone)
B(12,11,4,minecraft:blackstone)
B(13,11,4,minecraft:blackstone)
B(14,11,4,minecraft:blackstone)
B(15,11,4,minecraft:blackstone)
B(8,11,5,minecraft:blackstone)
B(9,11,5,minecraft:blackstone)
B(10,11,5,minecraft:blackstone)
B(11,11,5,minecraft:blackstone)
B(12,11,5,minecraft:blackstone)
B(13,11,5,minecraft:blackstone)
B(14,11,5,minecraft:blackstone)
B(15,11,5,minecraft:blackstone)
B(9,11,6,minecraft:blackstone)
B(10,11,6,minecraft:blackstone)
B(11,11,6,minecraft:blackstone)
B(12,11,6,minecraft:blackstone)
B(13,11,6,minecraft:blackstone)
B(14,11,6,minecraft:blackstone)
B(15,11,6,minecraft:blackstone)
B(10,11,7,minecraft:blackstone)
B(11,11,7,minecraft:blackstone)
B(12,11,7,minecraft:blackstone)
B(13,11,7,minecraft:blackstone)
B(14,11,7,minecraft:blackstone)
B(15,11,7,minecraft:blackstone)
B(10,11,8,minecraft:blackstone)
B(11,11,8,minecraft:blackstone)
B(12,11,8,minecraft:blackstone)
B(13,11,8,minecraft:blackstone)
B(14,11,8,minecraft:blackstone)
B(15,11,8,minecraft:blackstone)
B(10,11,9,minecraft:blackstone)
B(11,11,9,minecraft:blackstone)
B(12,11,9,minecraft:blackstone)
B(13,11,9,minecraft:blackstone)
B(14,11,9,minecraft:blackstone)
B(15,11,9,minecraft:blackstone)
B(11,11,10,minecraft:blackstone)
B(12,11,10,minecraft:blackstone)
B(13,11,10,minecraft:blackstone)
B(14,11,10,minecraft:blackstone)
B(15,11,10,minecraft:blackstone)
B(11,11,11,minecraft:blackstone)
B(12,11,11,minecraft:blackstone)
B(13,11,11,minecraft:blackstone)
B(14,11,11,minecraft:blackstone)
B(15,11,11,minecraft:blackstone)
B(13,11,12,minecraft:blackstone)
B(14,11,12,minecraft:blackstone)
B(15,11,12,minecraft:blackstone)
B(6,12,0,minecraft:blackstone)
B(7,12,0,minecraft:blackstone)
B(8,12,0,minecraft:blackstone)
B(9,12,0,minecraft:blackstone)
B(10,12,0,minecraft:blackstone)
B(11,12,0,minecraft:blackstone)
B(12,12,0,minecraft:blackstone)
B(13,12,0,minecraft:blackstone)
B(14,12,0,minecraft:blackstone)
B(15,12,0,minecraft:blackstone)
B(6,12,1,minecraft:blackstone)
B(7,12,1,minecraft:blackstone)
B(8,12,1,minecraft:blackstone)
B(9,12,1,minecraft:blackstone)
B(10,12,1,minecraft:blackstone)
B(11,12,1,minecraft:blackstone)
B(12,12,1,minecraft:blackstone)
B(13,12,1,minecraft:blackstone)
B(14,12,1,minecraft:blackstone)
B(15,12,1,minecraft:blackstone)
B(6,12,2,minecraft:blackstone)
B(7,12,2,minecraft:blackstone)
B(8,12,2,minecraft:blackstone)
B(9,12,2,minecraft:blackstone)
B(10,12,2,minecraft:blackstone)
B(11,12,2,minecraft:blackstone)
B(12,12,2,minecraft:blackstone)
B(13,12,2,minecraft:blackstone)
B(14,12,2,minecraft:blackstone)
B(15,12,2,minecraft:blackstone)
B(6,12,3,minecraft:blackstone)
B(7,12,3,minecraft:blackstone)
B(8,12,3,minecraft:blackstone)
B(9,12,3,minecraft:blackstone)
B(10,12,3,minecraft:blackstone)
B(11,12,3,minecraft:blackstone)
B(12,12,3,minecraft:blackstone)
B(13,12,3,minecraft:blackstone)
B(14,12,3,minecraft:blackstone)
B(15,12,3,minecraft:blackstone)
B(7,12,4,minecraft:blackstone)
B(8,12,4,minecraft:blackstone)
B(9,12,4,minecraft:blackstone)
B(10,12,4,minecraft:blackstone)
B(11,12,4,minecraft:blackstone)
B(12,12,4,minecraft:blackstone)
B(13,12,4,minecraft:blackstone)
B(14,12,4,minecraft:blackstone)
B(15,12,4,minecraft:blackstone)
B(8,12,5,minecraft:blackstone)
B(9,12,5,minecraft:blackstone)
B(10,12,5,minecraft:blackstone)
B(11,12,5,minecraft:blackstone)
B(12,12,5,minecraft:blackstone)
B(13,12,5,minecraft:blackstone)
B(14,12,5,minecraft:blackstone)
B(15,12,5,minecraft:blackstone)
B(9,12,6,minecraft:blackstone)
B(10,12,6,minecraft:blackstone)
B(11,12,6,minecraft:blackstone)
B(12,12,6,minecraft:blackstone)
B(13,12,6,minecraft:blackstone)
B(14,12,6,minecraft:blackstone)
B(15,12,6,minecraft:blackstone)
B(10,12,7,minecraft:blackstone)
B(11,12,7,minecraft:blackstone)
B(12,12,7,minecraft:blackstone)
B(13,12,7,minecraft:blackstone)
B(14,12,7,minecraft:blackstone)
B(15,12,7,minecraft:blackstone)
B(10,12,8,minecraft:blackstone)
B(11,12,8,minecraft:blackstone)
B(12,12,8,minecraft:blackstone)
B(13,12,8,minecraft:blackstone)
B(14,12,8,minecraft:blackstone)
B(15,12,8,minecraft:blackstone)
B(10,12,9,minecraft:blackstone)
B(11,12,9,minecraft:blackstone)
B(12,12,9,minecraft:blackstone)
B(13,12,9,minecraft:blackstone)
B(14,12,9,minecraft:blackstone)
B(15,12,9,minecraft:blackstone)
B(11,12,10,minecraft:blackstone)
B(12,12,10,minecraft:blackstone)
B(13,12,10,minecraft:blackstone)
B(14,12,10,minecraft:blackstone)
B(15,12,10,minecraft:blackstone)
B(11,12,11,minecraft:blackstone)
B(12,12,11,minecraft:blackstone)
B(13,12,11,minecraft:blackstone)
B(14,12,11,minecraft:blackstone)
B(15,12,11,minecraft:blackstone)
B(13,12,12,minecraft:blackstone)
B(14,12,12,minecraft:blackstone)
B(15,12,12,minecraft:blackstone)
B(6,13,0,minecraft:blackstone)
B(7,13,0,minecraft:blackstone)
B(8,13,0,minecraft:blackstone)
B(9,13,0,minecraft:blackstone)
B(10,13,0,minecraft:blackstone)
B(11,13,0,minecraft:blackstone)
B(12,13,0,minecraft:blackstone)
B(13,13,0,minecraft:blackstone)
B(14,13,0,minecraft:blackstone)
B(15,13,0,minecraft:blackstone)
B(6,13,1,minecraft:blackstone)
B(7,13,1,minecraft:blackstone)
B(8,13,1,minecraft:blackstone)
B(9,13,1,minecraft:blackstone)
B(10,13,1,minecraft:blackstone)
B(11,13,1,minecraft:blackstone)
B(12,13,1,minecraft:blackstone)
B(13,13,1,minecraft:blackstone)
B(14,13,1,minecraft:blackstone)
B(15,13,1,minecraft:blackstone)
B(6,13,2,minecraft:blackstone)
B(7,13,2,minecraft:blackstone)
B(8,13,2,minecraft:blackstone)
B(9,13,2,minecraft:blackstone)
B(10,13,2,minecraft:blackstone)
B(11,13,2,minecraft:blackstone)
B(12,13,2,minecraft:blackstone)
B(13,13,2,minecraft:blackstone)
B(14,13,2,minecraft:blackstone)
B(15,13,2,minecraft:blackstone)
B(6,13,3,minecraft:blackstone)
B(7,13,3,minecraft:blackstone)
B(8,13,3,minecraft:blackstone)
B(9,13,3,minecraft:blackstone)
B(10,13,3,minecraft:blackstone)
B(11,13,3,minecraft:blackstone)
B(12,13,3,minecraft:blackstone)
B(13,13,3,minecraft:blackstone)
B(14,13,3,minecraft:blackstone)
B(15,13,3,minecraft:blackstone)
B(7,13,4,minecraft:blackstone)
B(8,13,4,minecraft:blackstone)
B(9,13,4,minecraft:blackstone)
B(10,13,4,minecraft:blackstone)
B(11,13,4,minecraft:blackstone)
B(12,13,4,minecraft:blackstone)
B(13,13,4,minecraft:blackstone)
B(14,13,4,minecraft:blackstone)
B(15,13,4,minecraft:blackstone)
B(8,13,5,minecraft:blackstone)
B(9,13,5,minecraft:blackstone)
B(10,13,5,minecraft:blackstone)
B(11,13,5,minecraft:blackstone)
B(12,13,5,minecraft:blackstone)
B(13,13,5,minecraft:blackstone)
B(14,13,5,minecraft:blackstone)
B(15,13,5,minecraft:blackstone)
B(9,13,6,minecraft:blackstone)
B(10,13,6,minecraft:blackstone)
B(11,13,6,minecraft:blackstone)
B(12,13,6,minecraft:blackstone)
B(13,13,6,minecraft:blackstone)
B(14,13,6,minecraft:blackstone)
B(15,13,6,minecraft:blackstone)
B(10,13,7,minecraft:blackstone)
B(11,13,7,minecraft:blackstone)
B(12,13,7,minecraft:blackstone)
B(13,13,7,minecraft:blackstone)
B(14,13,7,minecraft:blackstone)
B(15,13,7,minecraft:blackstone)
B(10,13,8,minecraft:blackstone)
B(11,13,8,minecraft:blackstone)
B(12,13,8,minecraft:blackstone)
B(13,13,8,minecraft:blackstone)
B(14,13,8,minecraft:blackstone)
B(15,13,8,minecraft:blackstone)
B(10,13,9,minecraft:blackstone)
B(11,13,9,minecraft:blackstone)
B(12,13,9,minecraft:blackstone)
B(13,13,9,minecraft:blackstone)
B(14,13,9,minecraft:blackstone)
B(15,13,9,minecraft:blackstone)
B(11,13,10,minecraft:blackstone)
B(12,13,10,minecraft:blackstone)
B(13,13,10,minecraft:blackstone)
B(14,13,10,minecraft:blackstone)
B(15,13,10,minecraft:blackstone)
B(11,13,11,minecraft:blackstone)
B(12,13,11,minecraft:blackstone)
B(13,13,11,minecraft:blackstone)
B(14,13,11,minecraft:blackstone)
B(15,13,11,minecraft:blackstone)
B(13,13,12,minecraft:blackstone)
B(14,13,12,minecraft:blackstone)
B(15,13,12,minecraft:blackstone)
B(6,14,0,minecraft:blackstone)
B(7,14,0,minecraft:blackstone)
B(8,14,0,minecraft:blackstone)
B(9,14,0,minecraft:blackstone)
B(10,14,0,minecraft:blackstone)
B(11,14,0,minecraft:blackstone)
B(12,14,0,minecraft:blackstone)
B(13,14,0,minecraft:blackstone)
B(14,14,0,minecraft:blackstone)
B(15,14,0,minecraft:blackstone)
B(6,14,1,minecraft:blackstone)
B(7,14,1,minecraft:blackstone)
B(8,14,1,minecraft:blackstone)
B(9,14,1,minecraft:blackstone)
B(10,14,1,minecraft:blackstone)
B(11,14,1,minecraft:blackstone)
B(12,14,1,minecraft:blackstone)
B(13,14,1,minecraft:blackstone)
B(14,14,1,minecraft:blackstone)
B(15,14,1,minecraft:blackstone)
B(6,14,2,minecraft:blackstone)
B(7,14,2,minecraft:blackstone)
B(8,14,2,minecraft:blackstone)
B(9,14,2,minecraft:blackstone)
B(10,14,2,minecraft:blackstone)
B(11,14,2,minecraft:blackstone)
B(12,14,2,minecraft:blackstone)
B(13,14,2,minecraft:blackstone)
B(14,14,2,minecraft:blackstone)
B(15,14,2,minecraft:blackstone)
B(6,14,3,minecraft:blackstone)
B(7,14,3,minecraft:blackstone)
B(8,14,3,minecraft:blackstone)
B(9,14,3,minecraft:blackstone)
B(10,14,3,minecraft:blackstone)
B(11,14,3,minecraft:blackstone)
B(12,14,3,minecraft:blackstone)
B(13,14,3,minecraft:blackstone)
B(14,14,3,minecraft:blackstone)
B(15,14,3,minecraft:blackstone)
B(7,14,4,minecraft:blackstone)
B(8,14,4,minecraft:blackstone)
B(9,14,4,minecraft:blackstone)
B(10,14,4,minecraft:blackstone)
B(11,14,4,minecraft:blackstone)
B(12,14,4,minecraft:blackstone)
B(13,14,4,minecraft:blackstone)
B(14,14,4,minecraft:blackstone)
B(15,14,4,minecraft:blackstone)
B(8,14,5,minecraft:blackstone)
B(9,14,5,minecraft:blackstone)
B(10,14,5,minecraft:blackstone)
B(11,14,5,minecraft:blackstone)
B(12,14,5,minecraft:blackstone)
B(13,14,5,minecraft:blackstone)
B(14,14,5,minecraft:blackstone)
B(15,14,5,minecraft:blackstone)
B(9,14,6,minecraft:blackstone)
B(10,14,6,minecraft:blackstone)
B(11,14,6,minecraft:blackstone)
B(12,14,6,minecraft:blackstone)
B(13,14,6,minecraft:blackstone)
B(14,14,6,minecraft:blackstone)
B(15,14,6,minecraft:blackstone)
B(10,14,7,minecraft:blackstone)
B(11,14,7,minecraft:blackstone)
B(12,14,7,minecraft:blackstone)
B(13,14,7,minecraft:blackstone)
B(14,14,7,minecraft:blackstone)
B(15,14,7,minecraft:blackstone)
B(10,14,8,minecraft:blackstone)
B(11,14,8,minecraft:blackstone)
B(12,14,8,minecraft:blackstone)
B(13,14,8,minecraft:blackstone)
B(14,14,8,minecraft:blackstone)
B(15,14,8,minecraft:blackstone)
B(10,14,9,minecraft:blackstone)
B(11,14,9,minecraft:blackstone)
B(12,14,9,minecraft:blackstone)
B(13,14,9,minecraft:blackstone)
B(14,14,9,minecraft:blackstone)
B(15,14,9,minecraft:blackstone)
B(11,14,10,minecraft:blackstone)
B(12,14,10,minecraft:blackstone)
B(13,14,10,minecraft:blackstone)
B(14,14,10,minecraft:blackstone)
B(15,14,10,minecraft:blackstone)
B(11,14,11,minecraft:blackstone)
B(12,14,11,minecraft:blackstone)
B(13,14,11,minecraft:blackstone)
B(14,14,11,minecraft:blackstone)
B(15,14,11,minecraft:blackstone)
B(13,14,12,minecraft:blackstone)
B(14,14,12,minecraft:blackstone)
B(15,14,12,minecraft:blackstone)
B(6,15,0,minecraft:blackstone)
B(7,15,0,minecraft:blackstone)
B(8,15,0,minecraft:blackstone)
B(9,15,0,minecraft:blackstone)
B(10,15,0,minecraft:blackstone)
B(11,15,0,minecraft:blackstone)
B(12,15,0,minecraft:blackstone)
B(13,15,0,minecraft:blackstone)
B(14,15,0,minecraft:blackstone)
B(15,15,0,minecraft:blackstone)
B(6,15,1,minecraft:blackstone)
B(7,15,1,minecraft:blackstone)
B(8,15,1,minecraft:blackstone)
B(9,15,1,minecraft:blackstone)
B(10,15,1,minecraft:blackstone)
B(11,15,1,minecraft:blackstone)
B(12,15,1,minecraft:blackstone)
B(13,15,1,minecraft:blackstone)
B(14,15,1,minecraft:blackstone)
B(15,15,1,minecraft:blackstone)
B(6,15,2,minecraft:blackstone)
B(7,15,2,minecraft:blackstone)
B(8,15,2,minecraft:blackstone)
B(9,15,2,minecraft:blackstone)
B(10,15,2,minecraft:blackstone)
B(11,15,2,minecraft:blackstone)
B(12,15,2,minecraft:blackstone)
B(13,15,2,minecraft:blackstone)
B(14,15,2,minecraft:blackstone)
B(15,15,2,minecraft:blackstone)
B(6,15,3,minecraft:blackstone)
B(7,15,3,minecraft:blackstone)
B(8,15,3,minecraft:blackstone)
B(9,15,3,minecraft:blackstone)
B(10,15,3,minecraft:blackstone)
B(11,15,3,minecraft:blackstone)
B(12,15,3,minecraft:blackstone)
B(13,15,3,minecraft:blackstone)
B(14,15,3,minecraft:blackstone)
B(15,15,3,minecraft:blackstone)
B(7,15,4,minecraft:blackstone)
B(8,15,4,minecraft:blackstone)
B(9,15,4,minecraft:blackstone)
B(10,15,4,minecraft:blackstone)
B(11,15,4,minecraft:blackstone)
B(12,15,4,minecraft:blackstone)
B(13,15,4,minecraft:blackstone)
B(14,15,4,minecraft:blackstone)
B(15,15,4,minecraft:blackstone)
B(8,15,5,minecraft:blackstone)
B(9,15,5,minecraft:blackstone)
B(10,15,5,minecraft:blackstone)
B(11,15,5,minecraft:blackstone)
B(12,15,5,minecraft:blackstone)
B(13,15,5,minecraft:blackstone)
B(14,15,5,minecraft:blackstone)
B(15,15,5,minecraft:blackstone)
B(9,15,6,minecraft:blackstone)
B(10,15,6,minecraft:blackstone)
B(11,15,6,minecraft:blackstone)
B(12,15,6,minecraft:blackstone)
B(13,15,6,minecraft:blackstone)
B(14,15,6,minecraft:blackstone)
B(15,15,6,minecraft:blackstone)
B(10,15,7,minecraft:blackstone)
B(11,15,7,minecraft:blackstone)
B(12,15,7,minecraft:blackstone)
B(13,15,7,minecraft:blackstone)
B(14,15,7,minecraft:blackstone)
B(15,15,7,minecraft:blackstone)
B(10,15,8,minecraft:blackstone)
B(11,15,8,minecraft:blackstone)
B(12,15,8,minecraft:blackstone)
B(13,15,8,minecraft:blackstone)
B(14,15,8,minecraft:blackstone)
B(15,15,8,minecraft:blackstone)
B(10,15,9,minecraft:blackstone)
B(11,15,9,minecraft:blackstone)
B(12,15,9,minecraft:blackstone)
B(13,15,9,minecraft:blackstone)
B(14,15,9,minecraft:blackstone)
B(15,15,9,minecraft:blackstone)
B(11,15,10,minecraft:blackstone)
B(12,15,10,minecraft:blackstone)
B(13,15,10,minecraft:blackstone)
B(14,15,10,minecraft:blackstone)
B(15,15,10,minecraft:blackstone)
B(11,15,11,minecraft:blackstone)
B(12,15,11,minecraft:blackstone)
B(13,15,11,minecraft:blackstone)
B(14,15,11,minecraft:blackstone)
B(15,15,11,minecraft:blackstone)
B(13,15,12,minecraft:blackstone)
B(14,15,12,minecraft:blackstone)
B(15,15,12,minecraft:blackstone)
B(6,16,0,minecraft:blackstone)
B(7,16,0,minecraft:blackstone)
B(8,16,0,minecraft:blackstone)
B(9,16,0,minecraft:blackstone)
B(10,16,0,minecraft:blackstone)
B(11,16,0,minecraft:blackstone)
B(12,16,0,minecraft:blackstone)
B(13,16,0,minecraft:blackstone)
B(14,16,0,minecraft:blackstone)
B(15,16,0,minecraft:blackstone)
B(6,16,1,minecraft:blackstone)
B(7,16,1,minecraft:blackstone)
B(8,16,1,minecraft:blackstone)
B(9,16,1,minecraft:blackstone)
B(10,16,1,minecraft:blackstone)
B(11,16,1,minecraft:blackstone)
B(12,16,1,minecraft:blackstone)
B(13,16,1,minecraft:blackstone)
B(14,16,1,minecraft:blackstone)
B(15,16,1,minecraft:blackstone)
B(6,16,2,minecraft:blackstone)
B(7,16,2,minecraft:blackstone)
B(8,16,2,minecraft:blackstone)
B(9,16,2,minecraft:blackstone)
B(10,16,2,minecraft:blackstone)
B(11,16,2,minecraft:blackstone)
B(12,16,2,minecraft:blackstone)
B(13,16,2,minecraft:blackstone)
B(14,16,2,minecraft:blackstone)
B(15,16,2,minecraft:blackstone)
B(6,16,3,minecraft:blackstone)
B(7,16,3,minecraft:blackstone)
B(8,16,3,minecraft:blackstone)
B(9,16,3,minecraft:blackstone)
B(10,16,3,minecraft:blackstone)
B(11,16,3,minecraft:blackstone)
B(12,16,3,minecraft:blackstone)
B(13,16,3,minecraft:blackstone)
B(14,16,3,minecraft:blackstone)
B(15,16,3,minecraft:blackstone)
B(7,16,4,minecraft:blackstone)
B(8,16,4,minecraft:blackstone)
B(9,16,4,minecraft:blackstone)
B(10,16,4,minecraft:blackstone)
B(11,16,4,minecraft:blackstone)
B(12,16,4,minecraft:blackstone)
B(13,16,4,minecraft:blackstone)
B(14,16,4,minecraft:blackstone)
B(15,16,4,minecraft:blackstone)
B(8,16,5,minecraft:blackstone)
B(9,16,5,minecraft:blackstone)
B(10,16,5,minecraft:blackstone)
B(11,16,5,minecraft:blackstone)
B(12,16,5,minecraft:blackstone)
B(13,16,5,minecraft:blackstone)
B(14,16,5,minecraft:blackstone)
B(15,16,5,minecraft:blackstone)
B(9,16,6,minecraft:blackstone)
B(10,16,6,minecraft:blackstone)
B(11,16,6,minecraft:blackstone)
B(12,16,6,minecraft:blackstone)
B(13,16,6,minecraft:blackstone)
B(14,16,6,minecraft:blackstone)
B(15,16,6,minecraft:blackstone)
B(10,16,7,minecraft:blackstone)
B(11,16,7,minecraft:blackstone)
B(12,16,7,minecraft:blackstone)
B(13,16,7,minecraft:blackstone)
B(14,16,7,minecraft:blackstone)
B(15,16,7,minecraft:blackstone)
B(10,16,8,minecraft:blackstone)
B(11,16,8,minecraft:blackstone)
B(12,16,8,minecraft:blackstone)
B(13,16,8,minecraft:blackstone)
B(14,16,8,minecraft:blackstone)
B(15,16,8,minecraft:blackstone)
B(10,16,9,minecraft:blackstone)
B(11,16,9,minecraft:blackstone)
B(12,16,9,minecraft:blackstone)
B(13,16,9,minecraft:blackstone)
B(14,16,9,minecraft:blackstone)
B(15,16,9,minecraft:blackstone)
B(11,16,10,minecraft:blackstone)
B(12,16,10,minecraft:blackstone)
B(13,16,10,minecraft:blackstone)
B(14,16,10,minecraft:blackstone)
B(15,16,10,minecraft:blackstone)
B(11,16,11,minecraft:blackstone)
B(12,16,11,minecraft:blackstone)
B(13,16,11,minecraft:blackstone)
B(14,16,11,minecraft:blackstone)
B(15,16,11,minecraft:blackstone)
B(13,16,12,minecraft:blackstone)
B(14,16,12,minecraft:blackstone)
B(15,16,12,minecraft:blackstone)
B(6,17,0,minecraft:blackstone)
B(7,17,0,minecraft:blackstone)
B(8,17,0,minecraft:blackstone)
B(9,17,0,minecraft:blackstone)
B(10,17,0,minecraft:blackstone)
B(11,17,0,minecraft:blackstone)
B(12,17,0,minecraft:blackstone)
B(13,17,0,minecraft:blackstone)
B(14,17,0,minecraft:blackstone)
B(15,17,0,minecraft:blackstone)
B(6,17,1,minecraft:blackstone)
B(7,17,1,minecraft:blackstone)
B(8,17,1,minecraft:blackstone)
B(9,17,1,minecraft:blackstone)
B(10,17,1,minecraft:blackstone)
B(11,17,1,minecraft:blackstone)
B(12,17,1,minecraft:blackstone)
B(13,17,1,minecraft:blackstone)
B(14,17,1,minecraft:blackstone)
B(15,17,1,minecraft:blackstone)
B(6,17,2,minecraft:blackstone)
B(7,17,2,minecraft:blackstone)
B(8,17,2,minecraft:blackstone)
B(9,17,2,minecraft:blackstone)
B(10,17,2,minecraft:blackstone)
B(11,17,2,minecraft:blackstone)
B(12,17,2,minecraft:blackstone)
B(13,17,2,minecraft:blackstone)
B(14,17,2,minecraft:blackstone)
B(15,17,2,minecraft:blackstone)
B(6,17,3,minecraft:blackstone)
B(7,17,3,minecraft:blackstone)
B(8,17,3,minecraft:blackstone)
B(9,17,3,minecraft:blackstone)
B(10,17,3,minecraft:blackstone)
B(11,17,3,minecraft:blackstone)
B(12,17,3,minecraft:blackstone)
B(13,17,3,minecraft:blackstone)
B(14,17,3,minecraft:blackstone)
B(15,17,3,minecraft:blackstone)
B(7,17,4,minecraft:blackstone)
B(8,17,4,minecraft:blackstone)
B(9,17,4,minecraft:blackstone)
B(10,17,4,minecraft:blackstone)
B(11,17,4,minecraft:blackstone)
B(12,17,4,minecraft:blackstone)
B(13,17,4,minecraft:blackstone)
B(14,17,4,minecraft:blackstone)
B(15,17,4,minecraft:blackstone)
B(8,17,5,minecraft:blackstone)
B(9,17,5,minecraft:blackstone)
B(10,17,5,minecraft:blackstone)
B(11,17,5,minecraft:blackstone)
B(12,17,5,minecraft:blackstone)
B(13,17,5,minecraft:blackstone)
B(14,17,5,minecraft:blackstone)
B(15,17,5,minecraft:blackstone)
B(9,17,6,minecraft:blackstone)
B(10,17,6,minecraft:blackstone)
B(11,17,6,minecraft:blackstone)
B(12,17,6,minecraft:blackstone)
B(13,17,6,minecraft:blackstone)
B(14,17,6,minecraft:blackstone)
B(15,17,6,minecraft:blackstone)
B(10,17,7,minecraft:blackstone)
B(11,17,7,minecraft:blackstone)
B(12,17,7,minecraft:blackstone)
B(13,17,7,minecraft:blackstone)
B(14,17,7,minecraft:blackstone)
B(15,17,7,minecraft:blackstone)
B(10,17,8,minecraft:blackstone)
B(11,17,8,minecraft:blackstone)
B(12,17,8,minecraft:blackstone)
B(13,17,8,minecraft:blackstone)
B(14,17,8,minecraft:blackstone)
B(15,17,8,minecraft:blackstone)
B(10,17,9,minecraft:blackstone)
B(11,17,9,minecraft:blackstone)
B(12,17,9,minecraft:blackstone)
B(13,17,9,minecraft:blackstone)
B(14,17,9,minecraft:blackstone)
B(15,17,9,minecraft:blackstone)
B(11,17,10,minecraft:blackstone)
B(12,17,10,minecraft:blackstone)
B(13,17,10,minecraft:blackstone)
B(14,17,10,minecraft:blackstone)
B(15,17,10,minecraft:blackstone)
B(11,17,11,minecraft:blackstone)
B(12,17,11,minecraft:blackstone)
B(13,17,11,minecraft:blackstone)
B(14,17,11,minecraft:blackstone)
B(15,17,11,minecraft:blackstone)
B(13,17,12,minecraft:blackstone)
B(14,17,12,minecraft:blackstone)
B(15,17,12,minecraft:blackstone)
B(6,18,0,minecraft:blackstone)
B(7,18,0,minecraft:blackstone)
B(8,18,0,minecraft:blackstone)
B(9,18,0,minecraft:blackstone)
B(10,18,0,minecraft:blackstone)
B(11,18,0,minecraft:blackstone)
B(12,18,0,minecraft:blackstone)
B(13,18,0,minecraft:blackstone)
B(14,18,0,minecraft:blackstone)
B(15,18,0,minecraft:blackstone)
B(6,18,1,minecraft:blackstone)
B(7,18,1,minecraft:blackstone)
B(8,18,1,minecraft:blackstone)
B(9,18,1,minecraft:blackstone)
B(10,18,1,minecraft:blackstone)
B(11,18,1,minecraft:blackstone)
B(12,18,1,minecraft:blackstone)
B(13,18,1,minecraft:blackstone)
B(14,18,1,minecraft:blackstone)
B(15,18,1,minecraft:blackstone)
B(6,18,2,minecraft:blackstone)
B(7,18,2,minecraft:blackstone)
B(8,18,2,minecraft:blackstone)
B(9,18,2,minecraft:blackstone)
B(10,18,2,minecraft:blackstone)
B(11,18,2,minecraft:blackstone)
B(12,18,2,minecraft:blackstone)
B(13,18,2,minecraft:blackstone)
B(14,18,2,minecraft:blackstone)
B(15,18,2,minecraft:blackstone)
B(6,18,3,minecraft:blackstone)
B(7,18,3,minecraft:blackstone)
B(8,18,3,minecraft:blackstone)
B(9,18,3,minecraft:blackstone)
B(10,18,3,minecraft:blackstone)
B(11,18,3,minecraft:blackstone)
B(12,18,3,minecraft:blackstone)
B(13,18,3,minecraft:blackstone)
B(14,18,3,minecraft:blackstone)
B(15,18,3,minecraft:blackstone)
B(7,18,4,minecraft:blackstone)
B(8,18,4,minecraft:blackstone)
B(9,18,4,minecraft:blackstone)
B(10,18,4,minecraft:blackstone)
B(11,18,4,minecraft:blackstone)
B(12,18,4,minecraft:blackstone)
B(13,18,4,minecraft:blackstone)
B(14,18,4,minecraft:blackstone)
B(15,18,4,minecraft:blackstone)
B(8,18,5,minecraft:blackstone)
B(9,18,5,minecraft:blackstone)
B(10,18,5,minecraft:blackstone)
B(11,18,5,minecraft:blackstone)
B(12,18,5,minecraft:blackstone)
B(13,18,5,minecraft:blackstone)
B(14,18,5,minecraft:blackstone)
B(15,18,5,minecraft:blackstone)
B(9,18,6,minecraft:blackstone)
B(10,18,6,minecraft:blackstone)
B(11,18,6,minecraft:blackstone)
B(12,18,6,minecraft:blackstone)
B(13,18,6,minecraft:blackstone)
B(14,18,6,minecraft:blackstone)
B(15,18,6,minecraft:blackstone)
B(10,18,7,minecraft:blackstone)
B(11,18,7,minecraft:blackstone)
B(12,18,7,minecraft:blackstone)
B(13,18,7,minecraft:blackstone)
B(14,18,7,minecraft:blackstone)
B(15,18,7,minecraft:blackstone)
B(10,18,8,minecraft:blackstone)
B(11,18,8,minecraft:blackstone)
B(12,18,8,minecraft:blackstone)
B(13,18,8,minecraft:blackstone)
B(14,18,8,minecraft:blackstone)
B(15,18,8,minecraft:blackstone)
B(10,18,9,minecraft:blackstone)
B(11,18,9,minecraft:blackstone)
B(12,18,9,minecraft:blackstone)
B(13,18,9,minecraft:blackstone)
B(14,18,9,minecraft:blackstone)
B(15,18,9,minecraft:blackstone)
B(11,18,10,minecraft:blackstone)
B(12,18,10,minecraft:blackstone)
B(13,18,10,minecraft:blackstone)
B(14,18,10,minecraft:blackstone)
B(15,18,10,minecraft:blackstone)
B(11,18,11,minecraft:blackstone)
B(12,18,11,minecraft:blackstone)
B(13,18,11,minecraft:blackstone)
B(14,18,11,minecraft:blackstone)
B(15,18,11,minecraft:blackstone)
B(13,18,12,minecraft:blackstone)
B(14,18,12,minecraft:blackstone)
B(15,18,12,minecraft:blackstone)
B(7,19,0,minecraft:blackstone)
B(8,19,0,minecraft:blackstone)
B(9,19,0,minecraft:blackstone)
B(10,19,0,minecraft:blackstone)
B(11,19,0,minecraft:blackstone)
B(12,19,0,minecraft:blackstone)
B(13,19,0,minecraft:blackstone)
B(14,19,0,minecraft:blackstone)
B(15,19,0,minecraft:blackstone)
B(7,19,1,minecraft:blackstone)
B(8,19,1,minecraft:blackstone)
B(9,19,1,minecraft:blackstone)
B(10,19,1,minecraft:blackstone)
B(11,19,1,minecraft:blackstone)
B(12,19,1,minecraft:blackstone)
B(13,19,1,minecraft:blackstone)
B(14,19,1,minecraft:blackstone)
B(15,19,1,minecraft:blackstone)
B(7,19,2,minecraft:blackstone)
B(8,19,2,minecraft:blackstone)
B(9,19,2,minecraft:blackstone)
B(10,19,2,minecraft:blackstone)
B(11,19,2,minecraft:blackstone)
B(12,19,2,minecraft:blackstone)
B(13,19,2,minecraft:blackstone)
B(14,19,2,minecraft:blackstone)
B(15,19,2,minecraft:blackstone)
B(7,19,3,minecraft:blackstone)
B(8,19,3,minecraft:blackstone)
B(9,19,3,minecraft:blackstone)
B(10,19,3,minecraft:blackstone)
B(11,19,3,minecraft:blackstone)
B(12,19,3,minecraft:blackstone)
B(13,19,3,minecraft:blackstone)
B(14,19,3,minecraft:blackstone)
B(15,19,3,minecraft:blackstone)
B(7,19,4,minecraft:blackstone)
B(8,19,4,minecraft:blackstone)
B(9,19,4,minecraft:blackstone)
B(10,19,4,minecraft:blackstone)
B(11,19,4,minecraft:blackstone)
B(12,19,4,minecraft:blackstone)
B(13,19,4,minecraft:blackstone)
B(14,19,4,minecraft:blackstone)
B(15,19,4,minecraft:blackstone)
B(8,19,5,minecraft:blackstone)
B(9,19,5,minecraft:blackstone)
B(10,19,5,minecraft:blackstone)
B(11,19,5,minecraft:blackstone)
B(12,19,5,minecraft:blackstone)
B(13,19,5,minecraft:blackstone)
B(14,19,5,minecraft:blackstone)
B(15,19,5,minecraft:blackstone)
B(9,19,6,minecraft:blackstone)
B(10,19,6,minecraft:blackstone)
B(11,19,6,minecraft:blackstone)
B(12,19,6,minecraft:blackstone)
B(13,19,6,minecraft:blackstone)
B(14,19,6,minecraft:blackstone)
B(15,19,6,minecraft:blackstone)
B(10,19,7,minecraft:blackstone)
B(11,19,7,minecraft:blackstone)
B(12,19,7,minecraft:blackstone)
B(13,19,7,minecraft:blackstone)
B(14,19,7,minecraft:blackstone)
B(15,19,7,minecraft:blackstone)
B(10,19,8,minecraft:blackstone)
B(11,19,8,minecraft:blackstone)
B(12,19,8,minecraft:blackstone)
B(13,19,8,minecraft:blackstone)
B(14,19,8,minecraft:blackstone)
B(15,19,8,minecraft:blackstone)
B(10,19,9,minecraft:blackstone)
B(11,19,9,minecraft:blackstone)
B(12,19,9,minecraft:blackstone)
B(13,19,9,minecraft:blackstone)
B(14,19,9,minecraft:blackstone)
B(15,19,9,minecraft:blackstone)
B(11,19,10,minecraft:blackstone)
B(12,19,10,minecraft:blackstone)
B(13,19,10,minecraft:blackstone)
B(14,19,10,minecraft:blackstone)
B(15,19,10,minecraft:blackstone)
B(11,19,11,minecraft:blackstone)
B(12,19,11,minecraft:blackstone)
B(13,19,11,minecraft:blackstone)
B(14,19,11,minecraft:blackstone)
B(15,19,11,minecraft:blackstone)
B(13,19,12,minecraft:blackstone)
B(14,19,12,minecraft:blackstone)
B(15,19,12,minecraft:blackstone)
B(7,20,0,minecraft:blackstone)
B(8,20,0,minecraft:blackstone)
B(9,20,0,minecraft:blackstone)
B(10,20,0,minecraft:blackstone)
B(11,20,0,minecraft:blackstone)
B(12,20,0,minecraft:blackstone)
B(13,20,0,minecraft:blackstone)
B(14,20,0,minecraft:blackstone)
B(15,20,0,minecraft:blackstone)
B(7,20,1,minecraft:blackstone)
B(8,20,1,minecraft:blackstone)
B(9,20,1,minecraft:blackstone)
B(10,20,1,minecraft:blackstone)
B(11,20,1,minecraft:blackstone)
B(12,20,1,minecraft:blackstone)
B(13,20,1,minecraft:blackstone)
B(14,20,1,minecraft:blackstone)
B(15,20,1,minecraft:blackstone)
B(7,20,2,minecraft:blackstone)
B(8,20,2,minecraft:blackstone)
B(9,20,2,minecraft:blackstone)
B(10,20,2,minecraft:blackstone)
B(11,20,2,minecraft:blackstone)
B(12,20,2,minecraft:blackstone)
B(13,20,2,minecraft:blackstone)
B(14,20,2,minecraft:blackstone)
B(15,20,2,minecraft:blackstone)
B(7,20,3,minecraft:blackstone)
B(8,20,3,minecraft:blackstone)
B(9,20,3,minecraft:blackstone)
B(10,20,3,minecraft:blackstone)
B(11,20,3,minecraft:blackstone)
B(12,20,3,minecraft:blackstone)
B(13,20,3,minecraft:blackstone)
B(14,20,3,minecraft:blackstone)
B(15,20,3,minecraft:blackstone)
B(7,20,4,minecraft:blackstone)
B(8,20,4,minecraft:blackstone)
B(9,20,4,minecraft:blackstone)
B(10,20,4,minecraft:blackstone)
B(11,20,4,minecraft:blackstone)
B(12,20,4,minecraft:blackstone)
B(13,20,4,minecraft:blackstone)
B(14,20,4,minecraft:blackstone)
B(15,20,4,minecraft:blackstone)
B(8,20,5,minecraft:blackstone)
B(9,20,5,minecraft:blackstone)
B(10,20,5,minecraft:blackstone)
B(11,20,5,minecraft:blackstone)
B(12,20,5,minecraft:blackstone)
B(13,20,5,minecraft:blackstone)
B(14,20,5,minecraft:blackstone)
B(15,20,5,minecraft:blackstone)
B(9,20,6,minecraft:blackstone)
B(10,20,6,minecraft:blackstone)
B(11,20,6,minecraft:blackstone)
B(12,20,6,minecraft:blackstone)
B(13,20,6,minecraft:blackstone)
B(14,20,6,minecraft:blackstone)
B(15,20,6,minecraft:blackstone)
B(10,20,7,minecraft:blackstone)
B(11,20,7,minecraft:blackstone)
B(12,20,7,minecraft:blackstone)
B(13,20,7,minecraft:blackstone)
B(14,20,7,minecraft:blackstone)
B(15,20,7,minecraft:blackstone)
B(10,20,8,minecraft:blackstone)
B(11,20,8,minecraft:blackstone)
B(12,20,8,minecraft:blackstone)
B(13,20,8,minecraft:blackstone)
B(14,20,8,minecraft:blackstone)
B(15,20,8,minecraft:blackstone)
B(10,20,9,minecraft:blackstone)
B(11,20,9,minecraft:blackstone)
B(12,20,9,minecraft:blackstone)
B(13,20,9,minecraft:blackstone)
B(14,20,9,minecraft:blackstone)
B(15,20,9,minecraft:blackstone)
B(11,20,10,minecraft:blackstone)
B(12,20,10,minecraft:blackstone)
B(13,20,10,minecraft:blackstone)
B(14,20,10,minecraft:blackstone)
B(15,20,10,minecraft:blackstone)
B(11,20,11,minecraft:blackstone)
B(12,20,11,minecraft:blackstone)
B(13,20,11,minecraft:blackstone)
B(14,20,11,minecraft:blackstone)
B(15,20,11,minecraft:blackstone)
B(13,20,12,minecraft:blackstone)
B(14,20,12,minecraft:blackstone)
B(15,20,12,minecraft:blackstone)
B(7,21,0,minecraft:blackstone)
B(8,21,0,minecraft:blackstone)
B(9,21,0,minecraft:blackstone)
B(10,21,0,minecraft:blackstone)
B(11,21,0,minecraft:blackstone)
B(12,21,0,minecraft:blackstone)
B(13,21,0,minecraft:blackstone)
B(14,21,0,minecraft:blackstone)
B(15,21,0,minecraft:blackstone)
B(7,21,1,minecraft:blackstone)
B(8,21,1,minecraft:blackstone)
B(9,21,1,minecraft:blackstone)
B(10,21,1,minecraft:blackstone)
B(11,21,1,minecraft:blackstone)
B(12,21,1,minecraft:blackstone)
B(13,21,1,minecraft:blackstone)
B(14,21,1,minecraft:blackstone)
B(15,21,1,minecraft:blackstone)
B(7,21,2,minecraft:blackstone)
B(8,21,2,minecraft:blackstone)
B(9,21,2,minecraft:blackstone)
B(10,21,2,minecraft:blackstone)
B(11,21,2,minecraft:blackstone)
B(12,21,2,minecraft:blackstone)
B(13,21,2,minecraft:blackstone)
B(14,21,2,minecraft:blackstone)
B(15,21,2,minecraft:blackstone)
B(7,21,3,minecraft:blackstone)
B(8,21,3,minecraft:blackstone)
B(9,21,3,minecraft:blackstone)
B(10,21,3,minecraft:blackstone)
B(11,21,3,minecraft:blackstone)
B(12,21,3,minecraft:blackstone)
B(13,21,3,minecraft:blackstone)
B(14,21,3,minecraft:blackstone)
B(15,21,3,minecraft:blackstone)
B(7,21,4,minecraft:blackstone)
B(8,21,4,minecraft:blackstone)
B(9,21,4,minecraft:blackstone)
B(10,21,4,minecraft:blackstone)
B(11,21,4,minecraft:blackstone)
B(12,21,4,minecraft:blackstone)
B(13,21,4,minecraft:blackstone)
B(14,21,4,minecraft:blackstone)
B(15,21,4,minecraft:blackstone)
B(8,21,5,minecraft:blackstone)
B(9,21,5,minecraft:blackstone)
B(10,21,5,minecraft:blackstone)
B(11,21,5,minecraft:blackstone)
B(12,21,5,minecraft:blackstone)
B(13,21,5,minecraft:blackstone)
B(14,21,5,minecraft:blackstone)
B(15,21,5,minecraft:blackstone)
B(9,21,6,minecraft:blackstone)
B(10,21,6,minecraft:blackstone)
B(11,21,6,minecraft:blackstone)
B(12,21,6,minecraft:blackstone)
B(13,21,6,minecraft:blackstone)
B(14,21,6,minecraft:blackstone)
B(15,21,6,minecraft:blackstone)
B(10,21,7,minecraft:blackstone)
B(11,21,7,minecraft:blackstone)
B(12,21,7,minecraft:blackstone)
B(13,21,7,minecraft:blackstone)
B(14,21,7,minecraft:blackstone)
B(15,21,7,minecraft:blackstone)
B(10,21,8,minecraft:blackstone)
B(11,21,8,minecraft:blackstone)
B(12,21,8,minecraft:blackstone)
B(13,21,8,minecraft:blackstone)
B(14,21,8,minecraft:blackstone)
B(15,21,8,minecraft:blackstone)
B(10,21,9,minecraft:blackstone)
B(11,21,9,minecraft:blackstone)
B(12,21,9,minecraft:blackstone)
B(13,21,9,minecraft:blackstone)
B(14,21,9,minecraft:blackstone)
B(15,21,9,minecraft:blackstone)
B(11,21,10,minecraft:blackstone)
B(12,21,10,minecraft:blackstone)
B(13,21,10,minecraft:blackstone)
B(14,21,10,minecraft:blackstone)
B(15,21,10,minecraft:blackstone)
B(11,21,11,minecraft:blackstone)
B(12,21,11,minecraft:blackstone)
B(13,21,11,minecraft:blackstone)
B(14,21,11,minecraft:blackstone)
B(15,21,11,minecraft:blackstone)
B(13,21,12,minecraft:blackstone)
B(14,21,12,minecraft:blackstone)
B(15,21,12,minecraft:blackstone)
B(7,22,0,minecraft:blackstone)
B(8,22,0,minecraft:blackstone)
B(9,22,0,minecraft:blackstone)
B(10,22,0,minecraft:blackstone)
B(11,22,0,minecraft:blackstone)
B(12,22,0,minecraft:blackstone)
B(13,22,0,minecraft:blackstone)
B(14,22,0,minecraft:blackstone)
B(15,22,0,minecraft:blackstone)
B(7,22,1,minecraft:blackstone)
B(8,22,1,minecraft:blackstone)
B(9,22,1,minecraft:blackstone)
B(10,22,1,minecraft:blackstone)
B(11,22,1,minecraft:blackstone)
B(12,22,1,minecraft:blackstone)
B(13,22,1,minecraft:blackstone)
B(14,22,1,minecraft:blackstone)
B(15,22,1,minecraft:blackstone)
B(7,22,2,minecraft:blackstone)
B(8,22,2,minecraft:blackstone)
B(9,22,2,minecraft:blackstone)
B(10,22,2,minecraft:blackstone)
B(11,22,2,minecraft:blackstone)
B(12,22,2,minecraft:blackstone)
B(13,22,2,minecraft:blackstone)
B(14,22,2,minecraft:blackstone)
B(15,22,2,minecraft:blackstone)
B(7,22,3,minecraft:blackstone)
B(8,22,3,minecraft:blackstone)
B(9,22,3,minecraft:blackstone)
B(10,22,3,minecraft:blackstone)
B(11,22,3,minecraft:blackstone)
B(12,22,3,minecraft:blackstone)
B(13,22,3,minecraft:blackstone)
B(14,22,3,minecraft:blackstone)
B(15,22,3,minecraft:blackstone)
B(7,22,4,minecraft:blackstone)
B(8,22,4,minecraft:blackstone)
B(9,22,4,minecraft:blackstone)
B(10,22,4,minecraft:blackstone)
B(11,22,4,minecraft:blackstone)
B(12,22,4,minecraft:blackstone)
B(13,22,4,minecraft:blackstone)
B(14,22,4,minecraft:blackstone)
B(15,22,4,minecraft:blackstone)
B(8,22,5,minecraft:blackstone)
B(9,22,5,minecraft:blackstone)
B(10,22,5,minecraft:blackstone)
B(11,22,5,minecraft:blackstone)
B(12,22,5,minecraft:blackstone)
B(13,22,5,minecraft:blackstone)
B(14,22,5,minecraft:blackstone)
B(15,22,5,minecraft:blackstone)
B(9,22,6,minecraft:blackstone)
B(10,22,6,minecraft:blackstone)
B(11,22,6,minecraft:blackstone)
B(12,22,6,minecraft:blackstone)
B(13,22,6,minecraft:blackstone)
B(14,22,6,minecraft:blackstone)
B(15,22,6,minecraft:blackstone)
B(10,22,7,minecraft:blackstone)
B(11,22,7,minecraft:blackstone)
B(12,22,7,minecraft:blackstone)
B(13,22,7,minecraft:blackstone)
B(14,22,7,minecraft:blackstone)
B(15,22,7,minecraft:blackstone)
B(10,22,8,minecraft:blackstone)
B(11,22,8,minecraft:blackstone)
B(12,22,8,minecraft:blackstone)
B(13,22,8,minecraft:blackstone)
B(14,22,8,minecraft:blackstone)
B(15,22,8,minecraft:blackstone)
B(10,22,9,minecraft:blackstone)
B(11,22,9,minecraft:blackstone)
B(12,22,9,minecraft:blackstone)
B(13,22,9,minecraft:blackstone)
B(14,22,9,minecraft:blackstone)
B(15,22,9,minecraft:blackstone)
B(11,22,10,minecraft:blackstone)
B(12,22,10,minecraft:blackstone)
B(13,22,10,minecraft:blackstone)
B(14,22,10,minecraft:blackstone)
B(15,22,10,minecraft:blackstone)
B(11,22,11,minecraft:blackstone)
B(12,22,11,minecraft:blackstone)
B(13,22,11,minecraft:blackstone)
B(14,22,11,minecraft:blackstone)
B(15,22,11,minecraft:blackstone)
B(13,22,12,minecraft:blackstone)
B(14,22,12,minecraft:blackstone)
B(15,22,12,minecraft:blackstone)
B(7,23,0,minecraft:blackstone)
B(8,23,0,minecraft:blackstone)
B(9,23,0,minecraft:blackstone)
B(10,23,0,minecraft:blackstone)
B(11,23,0,minecraft:blackstone)
B(12,23,0,minecraft:blackstone)
B(13,23,0,minecraft:blackstone)
B(14,23,0,minecraft:blackstone)
B(15,23,0,minecraft:blackstone)
B(7,23,1,minecraft:blackstone)
B(8,23,1,minecraft:blackstone)
B(9,23,1,minecraft:blackstone)
B(10,23,1,minecraft:blackstone)
B(11,23,1,minecraft:blackstone)
B(12,23,1,minecraft:blackstone)
B(13,23,1,minecraft:blackstone)
B(14,23,1,minecraft:blackstone)
B(15,23,1,minecraft:blackstone)
B(7,23,2,minecraft:blackstone)
B(8,23,2,minecraft:blackstone)
B(9,23,2,minecraft:blackstone)
B(10,23,2,minecraft:blackstone)
B(11,23,2,minecraft:blackstone)
B(12,23,2,minecraft:blackstone)
B(13,23,2,minecraft:blackstone)
B(14,23,2,minecraft:blackstone)
B(15,23,2,minecraft:blackstone)
B(7,23,3,minecraft:blackstone)
B(8,23,3,minecraft:blackstone)
B(9,23,3,minecraft:blackstone)
B(10,23,3,minecraft:blackstone)
B(11,23,3,minecraft:blackstone)
B(12,23,3,minecraft:blackstone)
B(13,23,3,minecraft:blackstone)
B(14,23,3,minecraft:blackstone)
B(15,23,3,minecraft:blackstone)
B(7,23,4,minecraft:blackstone)
B(8,23,4,minecraft:blackstone)
B(9,23,4,minecraft:blackstone)
B(10,23,4,minecraft:blackstone)
B(11,23,4,minecraft:blackstone)
B(12,23,4,minecraft:blackstone)
B(13,23,4,minecraft:blackstone)
B(14,23,4,minecraft:blackstone)
B(15,23,4,minecraft:blackstone)
B(8,23,5,minecraft:blackstone)
B(9,23,5,minecraft:blackstone)
B(10,23,5,minecraft:blackstone)
B(11,23,5,minecraft:blackstone)
B(12,23,5,minecraft:blackstone)
B(13,23,5,minecraft:blackstone)
B(14,23,5,minecraft:blackstone)
B(15,23,5,minecraft:blackstone)
B(9,23,6,minecraft:blackstone)
B(10,23,6,minecraft:blackstone)
B(11,23,6,minecraft:blackstone)
B(12,23,6,minecraft:blackstone)
B(13,23,6,minecraft:blackstone)
B(14,23,6,minecraft:blackstone)
B(15,23,6,minecraft:blackstone)
B(10,23,7,minecraft:blackstone)
B(11,23,7,minecraft:blackstone)
B(12,23,7,minecraft:blackstone)
B(13,23,7,minecraft:blackstone)
B(14,23,7,minecraft:blackstone)
B(15,23,7,minecraft:blackstone)
B(10,23,8,minecraft:blackstone)
B(11,23,8,minecraft:blackstone)
B(12,23,8,minecraft:blackstone)
B(13,23,8,minecraft:blackstone)
B(14,23,8,minecraft:blackstone)
B(15,23,8,minecraft:blackstone)
B(10,23,9,minecraft:blackstone)
B(11,23,9,minecraft:blackstone)
B(12,23,9,minecraft:blackstone)
B(13,23,9,minecraft:blackstone)
B(14,23,9,minecraft:blackstone)
B(15,23,9,minecraft:blackstone)
B(11,23,10,minecraft:blackstone)
B(12,23,10,minecraft:blackstone)
B(13,23,10,minecraft:blackstone)
B(14,23,10,minecraft:blackstone)
B(15,23,10,minecraft:blackstone)
B(11,23,11,minecraft:blackstone)
B(12,23,11,minecraft:blackstone)
B(13,23,11,minecraft:blackstone)
B(14,23,11,minecraft:blackstone)
B(15,23,11,minecraft:blackstone)
B(13,23,12,minecraft:blackstone)
B(14,23,12,minecraft:blackstone)
B(15,23,12,minecraft:blackstone)
B(7,24,0,minecraft:blackstone)
B(8,24,0,minecraft:blackstone)
B(9,24,0,minecraft:blackstone)
B(10,24,0,minecraft:blackstone)
B(11,24,0,minecraft:blackstone)
B(12,24,0,minecraft:blackstone)
B(13,24,0,minecraft:blackstone)
B(14,24,0,minecraft:blackstone)
B(15,24,0,minecraft:blackstone)
B(7,24,1,minecraft:blackstone)
B(8,24,1,minecraft:blackstone)
B(9,24,1,minecraft:blackstone)
B(10,24,1,minecraft:blackstone)
B(11,24,1,minecraft:blackstone)
B(12,24,1,minecraft:blackstone)
B(13,24,1,minecraft:blackstone)
B(14,24,1,minecraft:blackstone)
B(15,24,1,minecraft:blackstone)
B(7,24,2,minecraft:blackstone)
B(8,24,2,minecraft:blackstone)
B(9,24,2,minecraft:blackstone)
B(10,24,2,minecraft:blackstone)
B(11,24,2,minecraft:blackstone)
B(12,24,2,minecraft:blackstone)
B(13,24,2,minecraft:blackstone)
B(14,24,2,minecraft:blackstone)
B(15,24,2,minecraft:blackstone)
B(7,24,3,minecraft:blackstone)
B(8,24,3,minecraft:blackstone)
B(9,24,3,minecraft:blackstone)
B(10,24,3,minecraft:blackstone)
B(11,24,3,minecraft:blackstone)
B(12,24,3,minecraft:blackstone)
B(13,24,3,minecraft:blackstone)
B(14,24,3,minecraft:blackstone)
B(15,24,3,minecraft:blackstone)
B(7,24,4,minecraft:blackstone)
B(8,24,4,minecraft:blackstone)
B(9,24,4,minecraft:blackstone)
B(10,24,4,minecraft:blackstone)
B(11,24,4,minecraft:blackstone)
B(12,24,4,minecraft:blackstone)
B(13,24,4,minecraft:blackstone)
B(14,24,4,minecraft:blackstone)
B(15,24,4,minecraft:blackstone)
B(8,24,5,minecraft:blackstone)
B(9,24,5,minecraft:blackstone)
B(10,24,5,minecraft:blackstone)
B(11,24,5,minecraft:blackstone)
B(12,24,5,minecraft:blackstone)
B(13,24,5,minecraft:blackstone)
B(14,24,5,minecraft:blackstone)
B(15,24,5,minecraft:blackstone)
B(9,24,6,minecraft:blackstone)
B(10,24,6,minecraft:blackstone)
B(11,24,6,minecraft:blackstone)
B(12,24,6,minecraft:blackstone)
B(13,24,6,minecraft:blackstone)
B(14,24,6,minecraft:blackstone)
B(15,24,6,minecraft:blackstone)
B(10,24,7,minecraft:blackstone)
B(11,24,7,minecraft:blackstone)
B(12,24,7,minecraft:blackstone)
B(13,24,7,minecraft:blackstone)
B(14,24,7,minecraft:blackstone)
B(15,24,7,minecraft:blackstone)
B(10,24,8,minecraft:blackstone)
B(11,24,8,minecraft:blackstone)
B(12,24,8,minecraft:blackstone)
B(13,24,8,minecraft:blackstone)
B(14,24,8,minecraft:blackstone)
B(15,24,8,minecraft:blackstone)
B(10,24,9,minecraft:blackstone)
B(11,24,9,minecraft:blackstone)
B(12,24,9,minecraft:blackstone)
B(13,24,9,minecraft:blackstone)
B(14,24,9,minecraft:blackstone)
B(15,24,9,minecraft:blackstone)
B(11,24,10,minecraft:blackstone)
B(12,24,10,minecraft:blackstone)
B(13,24,10,minecraft:blackstone)
B(14,24,10,minecraft:blackstone)
B(15,24,10,minecraft:blackstone)
B(11,24,11,minecraft:blackstone)
B(12,24,11,minecraft:blackstone)
B(13,24,11,minecraft:blackstone)
B(14,24,11,minecraft:blackstone)
B(15,24,11,minecraft:blackstone)
B(13,24,12,minecraft:blackstone)
B(14,24,12,minecraft:blackstone)
B(15,24,12,minecraft:blackstone)
B(7,25,0,minecraft:blackstone)
B(8,25,0,minecraft:blackstone)
B(9,25,0,minecraft:blackstone)
B(10,25,0,minecraft:blackstone)
B(11,25,0,minecraft:blackstone)
B(12,25,0,minecraft:blackstone)
B(13,25,0,minecraft:blackstone)
B(14,25,0,minecraft:blackstone)
B(15,25,0,minecraft:blackstone)
B(7,25,1,minecraft:blackstone)
B(8,25,1,minecraft:blackstone)
B(9,25,1,minecraft:blackstone)
B(10,25,1,minecraft:blackstone)
B(11,25,1,minecraft:blackstone)
B(12,25,1,minecraft:blackstone)
B(13,25,1,minecraft:blackstone)
B(14,25,1,minecraft:blackstone)
B(15,25,1,minecraft:blackstone)
B(7,25,2,minecraft:blackstone)
B(8,25,2,minecraft:blackstone)
B(9,25,2,minecraft:blackstone)
B(10,25,2,minecraft:blackstone)
B(11,25,2,minecraft:blackstone)
B(12,25,2,minecraft:blackstone)
B(13,25,2,minecraft:blackstone)
B(14,25,2,minecraft:blackstone)
B(15,25,2,minecraft:blackstone)
B(7,25,3,minecraft:blackstone)
B(8,25,3,minecraft:blackstone)
B(9,25,3,minecraft:blackstone)
B(10,25,3,minecraft:blackstone)
B(11,25,3,minecraft:blackstone)
B(12,25,3,minecraft:blackstone)
B(13,25,3,minecraft:blackstone)
B(14,25,3,minecraft:blackstone)
B(15,25,3,minecraft:blackstone)
B(7,25,4,minecraft:blackstone)
B(8,25,4,minecraft:blackstone)
B(9,25,4,minecraft:blackstone)
B(10,25,4,minecraft:blackstone)
B(11,25,4,minecraft:blackstone)
B(12,25,4,minecraft:blackstone)
B(13,25,4,minecraft:blackstone)
B(14,25,4,minecraft:blackstone)
B(15,25,4,minecraft:blackstone)
B(8,25,5,minecraft:blackstone)
B(9,25,5,minecraft:blackstone)
B(10,25,5,minecraft:blackstone)
B(11,25,5,minecraft:blackstone)
B(12,25,5,minecraft:blackstone)
B(13,25,5,minecraft:blackstone)
B(14,25,5,minecraft:blackstone)
B(15,25,5,minecraft:blackstone)
B(9,25,6,minecraft:blackstone)
B(10,25,6,minecraft:blackstone)
B(11,25,6,minecraft:blackstone)
B(12,25,6,minecraft:blackstone)
B(13,25,6,minecraft:blackstone)
B(14,25,6,minecraft:blackstone)
B(15,25,6,minecraft:blackstone)
B(10,25,7,minecraft:blackstone)
B(11,25,7,minecraft:blackstone)
B(12,25,7,minecraft:blackstone)
B(13,25,7,minecraft:blackstone)
B(14,25,7,minecraft:blackstone)
B(15,25,7,minecraft:blackstone)
B(10,25,8,minecraft:blackstone)
B(11,25,8,minecraft:blackstone)
B(12,25,8,minecraft:blackstone)
B(13,25,8,minecraft:blackstone)
B(14,25,8,minecraft:blackstone)
B(15,25,8,minecraft:blackstone)
B(10,25,9,minecraft:blackstone)
B(11,25,9,minecraft:blackstone)
B(12,25,9,minecraft:blackstone)
B(13,25,9,minecraft:blackstone)
B(14,25,9,minecraft:blackstone)
B(15,25,9,minecraft:blackstone)
B(11,25,10,minecraft:blackstone)
B(12,25,10,minecraft:blackstone)
B(13,25,10,minecraft:blackstone)
B(14,25,10,minecraft:blackstone)
B(15,25,10,minecraft:blackstone)
B(11,25,11,minecraft:blackstone)
B(12,25,11,minecraft:blackstone)
B(13,25,11,minecraft:blackstone)
B(14,25,11,minecraft:blackstone)
B(15,25,11,minecraft:blackstone)
B(13,25,12,minecraft:blackstone)
B(14,25,12,minecraft:blackstone)
B(15,25,12,minecraft:blackstone)
B(7,26,0,minecraft:blackstone)
B(8,26,0,minecraft:blackstone)
B(9,26,0,minecraft:blackstone)
B(10,26,0,minecraft:blackstone)
B(11,26,0,minecraft:blackstone)
B(12,26,0,minecraft:blackstone)
B(13,26,0,minecraft:blackstone)
B(14,26,0,minecraft:blackstone)
B(15,26,0,minecraft:blackstone)
B(7,26,1,minecraft:blackstone)
B(8,26,1,minecraft:blackstone)
B(9,26,1,minecraft:blackstone)
B(10,26,1,minecraft:blackstone)
B(11,26,1,minecraft:blackstone)
B(12,26,1,minecraft:blackstone)
B(13,26,1,minecraft:blackstone)
B(14,26,1,minecraft:blackstone)
B(15,26,1,minecraft:blackstone)
B(7,26,2,minecraft:blackstone)
B(8,26,2,minecraft:blackstone)
B(9,26,2,minecraft:blackstone)
B(10,26,2,minecraft:blackstone)
B(11,26,2,minecraft:blackstone)
B(12,26,2,minecraft:blackstone)
B(13,26,2,minecraft:blackstone)
B(14,26,2,minecraft:blackstone)
B(15,26,2,minecraft:blackstone)
B(7,26,3,minecraft:blackstone)
B(8,26,3,minecraft:blackstone)
B(9,26,3,minecraft:blackstone)
B(10,26,3,minecraft:blackstone)
B(11,26,3,minecraft:blackstone)
B(12,26,3,minecraft:blackstone)
B(13,26,3,minecraft:blackstone)
B(14,26,3,minecraft:blackstone)
B(15,26,3,minecraft:blackstone)
B(7,26,4,minecraft:blackstone)
B(8,26,4,minecraft:blackstone)
B(9,26,4,minecraft:blackstone)
B(10,26,4,minecraft:blackstone)
B(11,26,4,minecraft:blackstone)
B(12,26,4,minecraft:blackstone)
B(13,26,4,minecraft:blackstone)
B(14,26,4,minecraft:blackstone)
B(15,26,4,minecraft:blackstone)
B(8,26,5,minecraft:blackstone)
B(9,26,5,minecraft:blackstone)
B(10,26,5,minecraft:blackstone)
B(11,26,5,minecraft:blackstone)
B(12,26,5,minecraft:blackstone)
B(13,26,5,minecraft:blackstone)
B(14,26,5,minecraft:blackstone)
B(15,26,5,minecraft:blackstone)
B(9,26,6,minecraft:blackstone)
B(10,26,6,minecraft:blackstone)
B(11,26,6,minecraft:blackstone)
B(12,26,6,minecraft:blackstone)
B(13,26,6,minecraft:blackstone)
B(14,26,6,minecraft:blackstone)
B(15,26,6,minecraft:blackstone)
B(10,26,7,minecraft:blackstone)
B(11,26,7,minecraft:blackstone)
B(12,26,7,minecraft:blackstone)
B(13,26,7,minecraft:blackstone)
B(14,26,7,minecraft:blackstone)
B(15,26,7,minecraft:blackstone)
B(10,26,8,minecraft:blackstone)
B(11,26,8,minecraft:blackstone)
B(12,26,8,minecraft:blackstone)
B(13,26,8,minecraft:blackstone)
B(14,26,8,minecraft:blackstone)
B(15,26,8,minecraft:blackstone)
B(10,26,9,minecraft:blackstone)
B(11,26,9,minecraft:blackstone)
B(12,26,9,minecraft:blackstone)
B(13,26,9,minecraft:blackstone)
B(14,26,9,minecraft:blackstone)
B(15,26,9,minecraft:blackstone)
B(11,26,10,minecraft:blackstone)
B(12,26,10,minecraft:blackstone)
B(13,26,10,minecraft:blackstone)
B(14,26,10,minecraft:blackstone)
B(15,26,10,minecraft:blackstone)
B(11,26,11,minecraft:blackstone)
B(12,26,11,minecraft:blackstone)
B(13,26,11,minecraft:blackstone)
B(14,26,11,minecraft:blackstone)
B(15,26,11,minecraft:blackstone)
B(13,26,12,minecraft:blackstone)
B(14,26,12,minecraft:blackstone)
B(15,26,12,minecraft:blackstone)
B(7,27,0,minecraft:blackstone)
B(8,27,0,minecraft:blackstone)
B(9,27,0,minecraft:blackstone)
B(10,27,0,minecraft:blackstone)
B(11,27,0,minecraft:blackstone)
B(12,27,0,minecraft:blackstone)
B(13,27,0,minecraft:blackstone)
B(14,27,0,minecraft:blackstone)
B(15,27,0,minecraft:blackstone)
B(7,27,1,minecraft:blackstone)
B(8,27,1,minecraft:blackstone)
B(9,27,1,minecraft:blackstone)
B(10,27,1,minecraft:blackstone)
B(11,27,1,minecraft:blackstone)
B(12,27,1,minecraft:blackstone)
B(13,27,1,minecraft:blackstone)
B(14,27,1,minecraft:blackstone)
B(15,27,1,minecraft:blackstone)
B(7,27,2,minecraft:blackstone)
B(8,27,2,minecraft:blackstone)
B(9,27,2,minecraft:blackstone)
B(10,27,2,minecraft:blackstone)
B(11,27,2,minecraft:blackstone)
B(12,27,2,minecraft:blackstone)
B(13,27,2,minecraft:blackstone)
B(14,27,2,minecraft:blackstone)
B(15,27,2,minecraft:blackstone)
B(7,27,3,minecraft:blackstone)
B(8,27,3,minecraft:blackstone)
B(9,27,3,minecraft:blackstone)
B(10,27,3,minecraft:blackstone)
B(11,27,3,minecraft:blackstone)
B(12,27,3,minecraft:blackstone)
B(13,27,3,minecraft:blackstone)
B(14,27,3,minecraft:blackstone)
B(15,27,3,minecraft:blackstone)
B(7,27,4,minecraft:blackstone)
B(8,27,4,minecraft:blackstone)
B(9,27,4,minecraft:blackstone)
B(10,27,4,minecraft:blackstone)
B(11,27,4,minecraft:blackstone)
B(12,27,4,minecraft:blackstone)
B(13,27,4,minecraft:blackstone)
B(14,27,4,minecraft:blackstone)
B(15,27,4,minecraft:blackstone)
B(8,27,5,minecraft:blackstone)
B(9,27,5,minecraft:blackstone)
B(10,27,5,minecraft:blackstone)
B(11,27,5,minecraft:blackstone)
B(12,27,5,minecraft:blackstone)
B(13,27,5,minecraft:blackstone)
B(14,27,5,minecraft:blackstone)
B(15,27,5,minecraft:blackstone)
B(9,27,6,minecraft:blackstone)
B(10,27,6,minecraft:blackstone)
B(11,27,6,minecraft:blackstone)
B(12,27,6,minecraft:blackstone)
B(13,27,6,minecraft:blackstone)
B(14,27,6,minecraft:blackstone)
B(15,27,6,minecraft:blackstone)
B(10,27,7,minecraft:blackstone)
B(11,27,7,minecraft:blackstone)
B(12,27,7,minecraft:blackstone)
B(13,27,7,minecraft:blackstone)
B(14,27,7,minecraft:blackstone)
B(15,27,7,minecraft:blackstone)
B(10,27,8,minecraft:blackstone)
B(11,27,8,minecraft:blackstone)
B(12,27,8,minecraft:blackstone)
B(13,27,8,minecraft:blackstone)
B(14,27,8,minecraft:blackstone)
B(15,27,8,minecraft:blackstone)
B(10,27,9,minecraft:blackstone)
B(11,27,9,minecraft:blackstone)
B(12,27,9,minecraft:blackstone)
B(13,27,9,minecraft:blackstone)
B(14,27,9,minecraft:blackstone)
B(15,27,9,minecraft:blackstone)
B(11,27,10,minecraft:blackstone)
B(12,27,10,minecraft:blackstone)
B(13,27,10,minecraft:blackstone)
B(14,27,10,minecraft:blackstone)
B(15,27,10,minecraft:blackstone)
B(11,27,11,minecraft:blackstone)
B(12,27,11,minecraft:blackstone)
B(13,27,11,minecraft:blackstone)
B(14,27,11,minecraft:blackstone)
B(15,27,11,minecraft:blackstone)
B(13,27,12,minecraft:blackstone)
B(14,27,12,minecraft:blackstone)
B(15,27,12,minecraft:blackstone)
B(7,28,0,minecraft:blackstone)
B(8,28,0,minecraft:blackstone)
B(9,28,0,minecraft:blackstone)
B(10,28,0,minecraft:blackstone)
B(11,28,0,minecraft:blackstone)
B(12,28,0,minecraft:blackstone)
B(13,28,0,minecraft:blackstone)
B(14,28,0,minecraft:blackstone)
B(15,28,0,minecraft:blackstone)
B(7,28,1,minecraft:blackstone)
B(8,28,1,minecraft:blackstone)
B(9,28,1,minecraft:blackstone)
B(10,28,1,minecraft:blackstone)
B(11,28,1,minecraft:blackstone)
B(12,28,1,minecraft:blackstone)
B(13,28,1,minecraft:blackstone)
B(14,28,1,minecraft:blackstone)
B(15,28,1,minecraft:blackstone)
B(7,28,2,minecraft:blackstone)
B(8,28,2,minecraft:blackstone)
B(9,28,2,minecraft:blackstone)
B(10,28,2,minecraft:blackstone)
B(11,28,2,minecraft:blackstone)
B(12,28,2,minecraft:blackstone)
B(13,28,2,minecraft:blackstone)
B(14,28,2,minecraft:blackstone)
B(15,28,2,minecraft:blackstone)
B(7,28,3,minecraft:blackstone)
B(8,28,3,minecraft:blackstone)
B(9,28,3,minecraft:blackstone)
B(10,28,3,minecraft:blackstone)
B(11,28,3,minecraft:blackstone)
B(12,28,3,minecraft:blackstone)
B(13,28,3,minecraft:blackstone)
B(14,28,3,minecraft:blackstone)
B(15,28,3,minecraft:blackstone)
B(7,28,4,minecraft:blackstone)
B(8,28,4,minecraft:blackstone)
B(9,28,4,minecraft:blackstone)
B(10,28,4,minecraft:blackstone)
B(11,28,4,minecraft:blackstone)
B(12,28,4,minecraft:blackstone)
B(13,28,4,minecraft:blackstone)
B(14,28,4,minecraft:blackstone)
B(15,28,4,minecraft:blackstone)
B(8,28,5,minecraft:blackstone)
B(9,28,5,minecraft:blackstone)
B(10,28,5,minecraft:blackstone)
B(11,28,5,minecraft:blackstone)
B(12,28,5,minecraft:blackstone)
B(13,28,5,minecraft:blackstone)
B(14,28,5,minecraft:blackstone)
B(15,28,5,minecraft:blackstone)
B(9,28,6,minecraft:blackstone)
B(10,28,6,minecraft:blackstone)
B(11,28,6,minecraft:blackstone)
B(12,28,6,minecraft:blackstone)
B(13,28,6,minecraft:blackstone)
B(14,28,6,minecraft:blackstone)
B(15,28,6,minecraft:blackstone)
B(10,28,7,minecraft:blackstone)
B(11,28,7,minecraft:blackstone)
B(12,28,7,minecraft:blackstone)
B(13,28,7,minecraft:blackstone)
B(14,28,7,minecraft:blackstone)
B(15,28,7,minecraft:blackstone)
B(10,28,8,minecraft:blackstone)
B(11,28,8,minecraft:blackstone)
B(12,28,8,minecraft:blackstone)
B(13,28,8,minecraft:blackstone)
B(14,28,8,minecraft:blackstone)
B(15,28,8,minecraft:blackstone)
B(10,28,9,minecraft:blackstone)
B(11,28,9,minecraft:blackstone)
B(12,28,9,minecraft:blackstone)
B(13,28,9,minecraft:blackstone)
B(14,28,9,minecraft:blackstone)
B(15,28,9,minecraft:blackstone)
B(11,28,10,minecraft:blackstone)
B(12,28,10,minecraft:blackstone)
B(13,28,10,minecraft:blackstone)
B(14,28,10,minecraft:blackstone)
B(15,28,10,minecraft:blackstone)
B(11,28,11,minecraft:blackstone)
B(12,28,11,minecraft:blackstone)
B(13,28,11,minecraft:blackstone)
B(14,28,11,minecraft:blackstone)
B(15,28,11,minecraft:blackstone)
B(13,28,12,minecraft:blackstone)
B(14,28,12,minecraft:blackstone)
B(15,28,12,minecraft:blackstone)
B(8,29,0,minecraft:blackstone)
B(9,29,0,minecraft:blackstone)
B(10,29,0,minecraft:blackstone)
B(11,29,0,minecraft:blackstone)
B(12,29,0,minecraft:blackstone)
B(13,29,0,minecraft:blackstone)
B(14,29,0,minecraft:blackstone)
B(15,29,0,minecraft:blackstone)
B(7,29,1,minecraft:blackstone)
B(8,29,1,minecraft:blackstone)
B(9,29,1,minecraft:blackstone)
B(10,29,1,minecraft:blackstone)
B(11,29,1,minecraft:blackstone)
B(12,29,1,minecraft:blackstone)
B(13,29,1,minecraft:blackstone)
B(14,29,1,minecraft:blackstone)
B(15,29,1,minecraft:blackstone)
B(7,29,2,minecraft:blackstone)
B(8,29,2,minecraft:blackstone)
B(9,29,2,minecraft:blackstone)
B(10,29,2,minecraft:blackstone)
B(11,29,2,minecraft:blackstone)
B(12,29,2,minecraft:blackstone)
B(13,29,2,minecraft:blackstone)
B(14,29,2,minecraft:blackstone)
B(15,29,2,minecraft:blackstone)
B(7,29,3,minecraft:blackstone)
B(8,29,3,minecraft:blackstone)
B(9,29,3,minecraft:blackstone)
B(10,29,3,minecraft:blackstone)
B(11,29,3,minecraft:blackstone)
B(12,29,3,minecraft:blackstone)
B(13,29,3,minecraft:blackstone)
B(14,29,3,minecraft:blackstone)
B(15,29,3,minecraft:blackstone)
B(7,29,4,minecraft:blackstone)
B(8,29,4,minecraft:blackstone)
B(9,29,4,minecraft:blackstone)
B(10,29,4,minecraft:blackstone)
B(11,29,4,minecraft:blackstone)
B(12,29,4,minecraft:blackstone)
B(13,29,4,minecraft:blackstone)
B(14,29,4,minecraft:blackstone)
B(15,29,4,minecraft:blackstone)
B(8,29,5,minecraft:blackstone)
B(9,29,5,minecraft:blackstone)
B(10,29,5,minecraft:blackstone)
B(11,29,5,minecraft:blackstone)
B(12,29,5,minecraft:blackstone)
B(13,29,5,minecraft:blackstone)
B(14,29,5,minecraft:blackstone)
B(15,29,5,minecraft:blackstone)
B(9,29,6,minecraft:blackstone)
B(10,29,6,minecraft:blackstone)
B(11,29,6,minecraft:blackstone)
B(12,29,6,minecraft:blackstone)
B(13,29,6,minecraft:blackstone)
B(14,29,6,minecraft:blackstone)
B(15,29,6,minecraft:blackstone)
B(10,29,7,minecraft:blackstone)
B(11,29,7,minecraft:blackstone)
B(12,29,7,minecraft:blackstone)
B(13,29,7,minecraft:blackstone)
B(14,29,7,minecraft:blackstone)
B(15,29,7,minecraft:blackstone)
B(10,29,8,minecraft:blackstone)
B(11,29,8,minecraft:blackstone)
B(12,29,8,minecraft:blackstone)
B(13,29,8,minecraft:blackstone)
B(14,29,8,minecraft:blackstone)
B(15,29,8,minecraft:blackstone)
B(10,29,9,minecraft:blackstone)
B(11,29,9,minecraft:blackstone)
B(12,29,9,minecraft:blackstone)
B(13,29,9,minecraft:blackstone)
B(14,29,9,minecraft:blackstone)
B(15,29,9,minecraft:blackstone)
B(11,29,10,minecraft:blackstone)
B(12,29,10,minecraft:blackstone)
B(13,29,10,minecraft:blackstone)
B(14,29,10,minecraft:blackstone)
B(15,29,10,minecraft:blackstone)
B(11,29,11,minecraft:blackstone)
B(12,29,11,minecraft:blackstone)
B(13,29,11,minecraft:blackstone)
B(14,29,11,minecraft:blackstone)
B(15,29,11,minecraft:blackstone)
B(13,29,12,minecraft:blackstone)
B(14,29,12,minecraft:blackstone)
B(15,29,12,minecraft:blackstone)
B(8,30,0,minecraft:blackstone)
B(9,30,0,minecraft:blackstone)
B(10,30,0,minecraft:blackstone)
B(11,30,0,minecraft:blackstone)
B(12,30,0,minecraft:blackstone)
B(13,30,0,minecraft:blackstone)
B(14,30,0,minecraft:blackstone)
B(15,30,0,minecraft:blackstone)
B(7,30,1,minecraft:blackstone)
B(8,30,1,minecraft:blackstone)
B(9,30,1,minecraft:blackstone)
B(10,30,1,minecraft:blackstone)
B(11,30,1,minecraft:blackstone)
B(12,30,1,minecraft:blackstone)
B(13,30,1,minecraft:blackstone)
B(14,30,1,minecraft:blackstone)
B(15,30,1,minecraft:blackstone)
B(7,30,2,minecraft:blackstone)
B(8,30,2,minecraft:blackstone)
B(9,30,2,minecraft:blackstone)
B(10,30,2,minecraft:blackstone)
B(11,30,2,minecraft:blackstone)
B(12,30,2,minecraft:blackstone)
B(13,30,2,minecraft:blackstone)
B(14,30,2,minecraft:blackstone)
B(15,30,2,minecraft:blackstone)
B(7,30,3,minecraft:blackstone)
B(8,30,3,minecraft:blackstone)
B(9,30,3,minecraft:blackstone)
B(10,30,3,minecraft:blackstone)
B(11,30,3,minecraft:blackstone)
B(12,30,3,minecraft:blackstone)
B(13,30,3,minecraft:blackstone)
B(14,30,3,minecraft:blackstone)
B(15,30,3,minecraft:blackstone)
B(7,30,4,minecraft:blackstone)
B(8,30,4,minecraft:blackstone)
B(9,30,4,minecraft:blackstone)
B(10,30,4,minecraft:blackstone)
B(11,30,4,minecraft:blackstone)
B(12,30,4,minecraft:blackstone)
B(13,30,4,minecraft:blackstone)
B(14,30,4,minecraft:blackstone)
B(15,30,4,minecraft:blackstone)
B(8,30,5,minecraft:blackstone)
B(9,30,5,minecraft:blackstone)
B(10,30,5,minecraft:blackstone)
B(11,30,5,minecraft:blackstone)
B(12,30,5,minecraft:blackstone)
B(13,30,5,minecraft:blackstone)
B(14,30,5,minecraft:blackstone)
B(15,30,5,minecraft:blackstone)
B(9,30,6,minecraft:blackstone)
B(10,30,6,minecraft:blackstone)
B(11,30,6,minecraft:blackstone)
B(12,30,6,minecraft:blackstone)
B(13,30,6,minecraft:blackstone)
B(14,30,6,minecraft:blackstone)
B(15,30,6,minecraft:blackstone)
B(10,30,7,minecraft:blackstone)
B(11,30,7,minecraft:blackstone)
B(12,30,7,minecraft:blackstone)
B(13,30,7,minecraft:blackstone)
B(14,30,7,minecraft:blackstone)
B(15,30,7,minecraft:blackstone)
B(10,30,8,minecraft:blackstone)
B(11,30,8,minecraft:blackstone)
B(12,30,8,minecraft:blackstone)
B(13,30,8,minecraft:blackstone)
B(14,30,8,minecraft:blackstone)
B(15,30,8,minecraft:blackstone)
B(10,30,9,minecraft:blackstone)
B(11,30,9,minecraft:blackstone)
B(12,30,9,minecraft:blackstone)
B(13,30,9,minecraft:blackstone)
B(14,30,9,minecraft:blackstone)
B(15,30,9,minecraft:blackstone)
B(11,30,10,minecraft:blackstone)
B(12,30,10,minecraft:blackstone)
B(13,30,10,minecraft:blackstone)
B(14,30,10,minecraft:blackstone)
B(15,30,10,minecraft:blackstone)
B(11,30,11,minecraft:blackstone)
B(12,30,11,minecraft:blackstone)
B(13,30,11,minecraft:blackstone)
B(14,30,11,minecraft:blackstone)
B(15,30,11,minecraft:blackstone)
B(13,30,12,minecraft:blackstone)
B(14,30,12,minecraft:blackstone)
B(15,30,12,minecraft:blackstone)
B(8,31,0,minecraft:blackstone)
B(9,31,0,minecraft:blackstone)
B(10,31,0,minecraft:blackstone)
B(11,31,0,minecraft:blackstone)
B(12,31,0,minecraft:blackstone)
B(13,31,0,minecraft:blackstone)
B(14,31,0,minecraft:blackstone)
B(15,31,0,minecraft:blackstone)
B(7,31,1,minecraft:blackstone)
B(8,31,1,minecraft:blackstone)
B(9,31,1,minecraft:blackstone)
B(10,31,1,minecraft:blackstone)
B(11,31,1,minecraft:blackstone)
B(12,31,1,minecraft:blackstone)
B(13,31,1,minecraft:blackstone)
B(14,31,1,minecraft:blackstone)
B(15,31,1,minecraft:blackstone)
B(7,31,2,minecraft:blackstone)
B(8,31,2,minecraft:blackstone)
B(9,31,2,minecraft:blackstone)
B(10,31,2,minecraft:blackstone)
B(11,31,2,minecraft:blackstone)
B(12,31,2,minecraft:blackstone)
B(13,31,2,minecraft:blackstone)
B(14,31,2,minecraft:blackstone)
B(15,31,2,minecraft:blackstone)
B(7,31,3,minecraft:blackstone)
B(8,31,3,minecraft:blackstone)
B(9,31,3,minecraft:blackstone)
B(10,31,3,minecraft:blackstone)
B(11,31,3,minecraft:blackstone)
B(12,31,3,minecraft:blackstone)
B(13,31,3,minecraft:blackstone)
B(14,31,3,minecraft:blackstone)
B(15,31,3,minecraft:blackstone)
B(7,31,4,minecraft:blackstone)
B(8,31,4,minecraft:blackstone)
B(9,31,4,minecraft:blackstone)
B(10,31,4,minecraft:blackstone)
B(11,31,4,minecraft:blackstone)
B(12,31,4,minecraft:blackstone)
B(13,31,4,minecraft:blackstone)
B(14,31,4,minecraft:blackstone)
B(15,31,4,minecraft:blackstone)
B(8,31,5,minecraft:blackstone)
B(9,31,5,minecraft:blackstone)
B(10,31,5,minecraft:blackstone)
B(11,31,5,minecraft:blackstone)
B(12,31,5,minecraft:blackstone)
B(13,31,5,minecraft:blackstone)
B(14,31,5,minecraft:blackstone)
B(15,31,5,minecraft:blackstone)
B(9,31,6,minecraft:blackstone)
B(10,31,6,minecraft:blackstone)
B(11,31,6,minecraft:blackstone)
B(12,31,6,minecraft:blackstone)
B(13,31,6,minecraft:blackstone)
B(14,31,6,minecraft:blackstone)
B(15,31,6,minecraft:blackstone)
B(10,31,7,minecraft:blackstone)
B(11,31,7,minecraft:blackstone)
B(12,31,7,minecraft:blackstone)
B(13,31,7,minecraft:blackstone)
B(14,31,7,minecraft:blackstone)
B(15,31,7,minecraft:blackstone)
B(10,31,8,minecraft:blackstone)
B(11,31,8,minecraft:blackstone)
B(12,31,8,minecraft:blackstone)
B(13,31,8,minecraft:blackstone)
B(14,31,8,minecraft:blackstone)
B(15,31,8,minecraft:blackstone)
B(10,31,9,minecraft:blackstone)
B(11,31,9,minecraft:blackstone)
B(12,31,9,minecraft:blackstone)
B(13,31,9,minecraft:blackstone)
B(14,31,9,minecraft:blackstone)
B(15,31,9,minecraft:blackstone)
B(11,31,10,minecraft:blackstone)
B(12,31,10,minecraft:blackstone)
B(13,31,10,minecraft:blackstone)
B(14,31,10,minecraft:blackstone)
B(15,31,10,minecraft:blackstone)
B(11,31,11,minecraft:blackstone)
B(12,31,11,minecraft:blackstone)
B(13,31,11,minecraft:blackstone)
B(14,31,11,minecraft:blackstone)
B(15,31,11,minecraft:blackstone)
B(13,31,12,minecraft:blackstone)
B(14,31,12,minecraft:blackstone)
B(15,31,12,minecraft:blackstone)
B(8,32,0,minecraft:blackstone)
B(9,32,0,minecraft:blackstone)
B(10,32,0,minecraft:blackstone)
B(11,32,0,minecraft:blackstone)
B(12,32,0,minecraft:blackstone)
B(13,32,0,minecraft:blackstone)
B(14,32,0,minecraft:blackstone)
B(15,32,0,minecraft:blackstone)
B(8,32,1,minecraft:blackstone)
B(9,32,1,minecraft:blackstone)
B(10,32,1,minecraft:blackstone)
B(11,32,1,minecraft:blackstone)
B(12,32,1,minecraft:blackstone)
B(13,32,1,minecraft:blackstone)
B(14,32,1,minecraft:blackstone)
B(15,32,1,minecraft:blackstone)
B(7,32,2,minecraft:blackstone)
B(8,32,2,minecraft:blackstone)
B(9,32,2,minecraft:blackstone)
B(10,32,2,minecraft:blackstone)
B(11,32,2,minecraft:blackstone)
B(12,32,2,minecraft:blackstone)
B(13,32,2,minecraft:blackstone)
B(14,32,2,minecraft:blackstone)
B(15,32,2,minecraft:blackstone)
B(7,32,3,minecraft:blackstone)
B(8,32,3,minecraft:blackstone)
B(9,32,3,minecraft:blackstone)
B(10,32,3,minecraft:blackstone)
B(11,32,3,minecraft:blackstone)
B(12,32,3,minecraft:blackstone)
B(13,32,3,minecraft:blackstone)
B(14,32,3,minecraft:blackstone)
B(15,32,3,minecraft:blackstone)
B(7,32,4,minecraft:blackstone)
B(8,32,4,minecraft:blackstone)
B(9,32,4,minecraft:blackstone)
B(10,32,4,minecraft:blackstone)
B(11,32,4,minecraft:blackstone)
B(12,32,4,minecraft:blackstone)
B(13,32,4,minecraft:blackstone)
B(14,32,4,minecraft:blackstone)
B(15,32,4,minecraft:blackstone)
B(8,32,5,minecraft:blackstone)
B(9,32,5,minecraft:blackstone)
B(10,32,5,minecraft:blackstone)
B(11,32,5,minecraft:blackstone)
B(12,32,5,minecraft:blackstone)
B(13,32,5,minecraft:blackstone)
B(14,32,5,minecraft:blackstone)
B(15,32,5,minecraft:blackstone)
B(9,32,6,minecraft:blackstone)
B(10,32,6,minecraft:blackstone)
B(11,32,6,minecraft:blackstone)
B(12,32,6,minecraft:blackstone)
B(13,32,6,minecraft:blackstone)
B(14,32,6,minecraft:blackstone)
B(15,32,6,minecraft:blackstone)
B(10,32,7,minecraft:blackstone)
B(11,32,7,minecraft:blackstone)
B(12,32,7,minecraft:blackstone)
B(13,32,7,minecraft:blackstone)
B(14,32,7,minecraft:blackstone)
B(15,32,7,minecraft:blackstone)
B(10,32,8,minecraft:blackstone)
B(11,32,8,minecraft:blackstone)
B(12,32,8,minecraft:blackstone)
B(13,32,8,minecraft:blackstone)
B(14,32,8,minecraft:blackstone)
B(15,32,8,minecraft:blackstone)
B(11,32,9,minecraft:blackstone)
B(12,32,9,minecraft:blackstone)
B(13,32,9,minecraft:blackstone)
B(14,32,9,minecraft:blackstone)
B(15,32,9,minecraft:blackstone)
B(11,32,10,minecraft:blackstone)
B(12,32,10,minecraft:blackstone)
B(13,32,10,minecraft:blackstone)
B(14,32,10,minecraft:blackstone)
B(15,32,10,minecraft:blackstone)
B(11,32,11,minecraft:blackstone)
B(12,32,11,minecraft:blackstone)
B(13,32,11,minecraft:blackstone)
B(14,32,11,minecraft:blackstone)
B(15,32,11,minecraft:blackstone)
B(13,32,12,minecraft:blackstone)
B(14,32,12,minecraft:blackstone)
B(15,32,12,minecraft:blackstone)
B(8,33,0,minecraft:blackstone)
B(9,33,0,minecraft:blackstone)
B(10,33,0,minecraft:blackstone)
B(11,33,0,minecraft:blackstone)
B(12,33,0,minecraft:blackstone)
B(13,33,0,minecraft:blackstone)
B(14,33,0,minecraft:blackstone)
B(15,33,0,minecraft:blackstone)
B(8,33,1,minecraft:blackstone)
B(9,33,1,minecraft:blackstone)
B(10,33,1,minecraft:blackstone)
B(11,33,1,minecraft:blackstone)
B(12,33,1,minecraft:blackstone)
B(13,33,1,minecraft:blackstone)
B(14,33,1,minecraft:blackstone)
B(15,33,1,minecraft:blackstone)
B(7,33,2,minecraft:blackstone)
B(8,33,2,minecraft:blackstone)
B(9,33,2,minecraft:blackstone)
B(10,33,2,minecraft:blackstone)
B(11,33,2,minecraft:blackstone)
B(12,33,2,minecraft:blackstone)
B(13,33,2,minecraft:blackstone)
B(14,33,2,minecraft:blackstone)
B(15,33,2,minecraft:blackstone)
B(7,33,3,minecraft:blackstone)
B(8,33,3,minecraft:blackstone)
B(9,33,3,minecraft:blackstone)
B(10,33,3,minecraft:blackstone)
B(11,33,3,minecraft:blackstone)
B(12,33,3,minecraft:blackstone)
B(13,33,3,minecraft:blackstone)
B(14,33,3,minecraft:blackstone)
B(15,33,3,minecraft:blackstone)
B(7,33,4,minecraft:blackstone)
B(8,33,4,minecraft:blackstone)
B(9,33,4,minecraft:blackstone)
B(10,33,4,minecraft:blackstone)
B(11,33,4,minecraft:blackstone)
B(12,33,4,minecraft:blackstone)
B(13,33,4,minecraft:blackstone)
B(14,33,4,minecraft:blackstone)
B(15,33,4,minecraft:blackstone)
B(8,33,5,minecraft:blackstone)
B(9,33,5,minecraft:blackstone)
B(10,33,5,minecraft:blackstone)
B(11,33,5,minecraft:blackstone)
B(12,33,5,minecraft:blackstone)
B(13,33,5,minecraft:blackstone)
B(14,33,5,minecraft:blackstone)
B(15,33,5,minecraft:blackstone)
B(9,33,6,minecraft:blackstone)
B(10,33,6,minecraft:blackstone)
B(11,33,6,minecraft:blackstone)
B(12,33,6,minecraft:blackstone)
B(13,33,6,minecraft:blackstone)
B(14,33,6,minecraft:blackstone)
B(15,33,6,minecraft:blackstone)
B(10,33,7,minecraft:blackstone)
B(11,33,7,minecraft:blackstone)
B(12,33,7,minecraft:blackstone)
B(13,33,7,minecraft:blackstone)
B(14,33,7,minecraft:blackstone)
B(15,33,7,minecraft:blackstone)
B(10,33,8,minecraft:blackstone)
B(11,33,8,minecraft:blackstone)
B(12,33,8,minecraft:blackstone)
