Author: Bo3 BulkEdit

Description: Converted Schematic - Modified by Bo3BulkEdit

Version: 3

SettingsMode: WriteDisable

IsOTGPlus: true
Tree: false
Frequency: 10
Rarity: 100
RotateRandomly: true
SpawnHeight: randomY
SpawnHeightOffset: 0
SpawnHeightVariance: 0
MaxBranchDepth: 10
ExcludedBiomes: All

MinHeight: 50
MaxHeight: 65

SourceBlocks: AIR
MaxPercentageOutsideSourceBlock: 100
OutsideSourceBlock: placeAnyway

ReplaceBelow: BLACKSTONE
ReplaceWithBiomeBlocks: false
ReplaceWithGroundBlock: BLACKSTONE
ReplaceWithSurfaceBlock: BLACKSTONE
ReplaceWithStoneBlock: BLACKSTONE
SmoothRadius: 30
SmoothingSurfaceBlock: BLACKSTONE
SmoothingGroundBlock: BLACKSTONE

B(0,750,0,AIR)
B(15,750,15,AIR)
B(15,0,0,minecraft:blackstone)
B(14,0,1,minecraft:blackstone)
B(15,0,1,minecraft:blackstone)
B(13,0,2,minecraft:blackstone)
B(14,0,2,minecraft:blackstone)
B(15,0,2,minecraft:blackstone)
B(12,0,3,minecraft:blackstone)
B(13,0,3,minecraft:blackstone)
B(14,0,3,minecraft:blackstone)
B(15,0,3,minecraft:blackstone)
B(12,0,4,minecraft:blackstone)
B(13,0,4,minecraft:blackstone)
B(14,0,4,minecraft:blackstone)
B(15,0,4,minecraft:blackstone)
B(12,0,5,minecraft:blackstone)
B(13,0,5,minecraft:blackstone)
B(14,0,5,minecraft:blackstone)
B(15,0,5,minecraft:blackstone)
B(12,0,6,minecraft:blackstone)
B(13,0,6,minecraft:blackstone)
B(14,0,6,minecraft:blackstone)
B(15,0,6,minecraft:blackstone)
B(13,0,7,minecraft:blackstone)
B(14,0,7,minecraft:blackstone)
B(15,0,7,minecraft:blackstone)
B(13,0,8,minecraft:blackstone)
B(14,0,8,minecraft:blackstone)
B(15,0,8,minecraft:blackstone)
B(14,0,9,minecraft:blackstone)
B(15,0,9,minecraft:blackstone)
B(15,1,0,minecraft:blackstone)
B(14,1,1,minecraft:blackstone)
B(15,1,1,minecraft:blackstone)
B(13,1,2,minecraft:blackstone)
B(14,1,2,minecraft:blackstone)
B(15,1,2,minecraft:blackstone)
B(12,1,3,minecraft:blackstone)
B(13,1,3,minecraft:blackstone)
B(14,1,3,minecraft:blackstone)
B(15,1,3,minecraft:blackstone)
B(12,1,4,minecraft:blackstone)
B(13,1,4,minecraft:blackstone)
B(14,1,4,minecraft:blackstone)
B(15,1,4,minecraft:blackstone)
B(12,1,5,minecraft:blackstone)
B(13,1,5,minecraft:blackstone)
B(14,1,5,minecraft:blackstone)
B(15,1,5,minecraft:blackstone)
B(12,1,6,minecraft:blackstone)
B(13,1,6,minecraft:blackstone)
B(14,1,6,minecraft:blackstone)
B(15,1,6,minecraft:blackstone)
B(13,1,7,minecraft:blackstone)
B(14,1,7,minecraft:blackstone)
B(15,1,7,minecraft:blackstone)
B(13,1,8,minecraft:blackstone)
B(14,1,8,minecraft:blackstone)
B(15,1,8,minecraft:blackstone)
B(14,1,9,minecraft:blackstone)
B(15,1,9,minecraft:blackstone)
B(15,2,0,minecraft:blackstone)
B(14,2,1,minecraft:blackstone)
B(15,2,1,minecraft:blackstone)
B(13,2,2,minecraft:blackstone)
B(14,2,2,minecraft:blackstone)
B(15,2,2,minecraft:blackstone)
B(12,2,3,minecraft:blackstone)
B(13,2,3,minecraft:blackstone)
B(14,2,3,minecraft:blackstone)
B(15,2,3,minecraft:blackstone)
B(12,2,4,minecraft:blackstone)
B(13,2,4,minecraft:blackstone)
B(14,2,4,minecraft:blackstone)
B(15,2,4,minecraft:blackstone)
B(12,2,5,minecraft:blackstone)
B(13,2,5,minecraft:blackstone)
B(14,2,5,minecraft:blackstone)
B(15,2,5,minecraft:blackstone)
B(12,2,6,minecraft:blackstone)
B(13,2,6,minecraft:blackstone)
B(14,2,6,minecraft:blackstone)
B(15,2,6,minecraft:blackstone)
B(13,2,7,minecraft:blackstone)
B(14,2,7,minecraft:blackstone)
B(15,2,7,minecraft:blackstone)
B(13,2,8,minecraft:blackstone)
B(14,2,8,minecraft:blackstone)
B(15,2,8,minecraft:blackstone)
B(14,2,9,minecraft:blackstone)
B(15,2,9,minecraft:blackstone)
B(15,3,0,minecraft:blackstone)
B(14,3,1,minecraft:blackstone)
B(15,3,1,minecraft:blackstone)
B(13,3,2,minecraft:blackstone)
B(14,3,2,minecraft:blackstone)
B(15,3,2,minecraft:blackstone)
B(12,3,3,minecraft:blackstone)
B(13,3,3,minecraft:blackstone)
B(14,3,3,minecraft:blackstone)
B(15,3,3,minecraft:blackstone)
B(12,3,4,minecraft:blackstone)
B(13,3,4,minecraft:blackstone)
B(14,3,4,minecraft:blackstone)
B(15,3,4,minecraft:blackstone)
B(12,3,5,minecraft:blackstone)
B(13,3,5,minecraft:blackstone)
B(14,3,5,minecraft:blackstone)
B(15,3,5,minecraft:blackstone)
B(12,3,6,minecraft:blackstone)
B(13,3,6,minecraft:blackstone)
B(14,3,6,minecraft:blackstone)
B(15,3,6,minecraft:blackstone)
B(13,3,7,minecraft:blackstone)
B(14,3,7,minecraft:blackstone)
B(15,3,7,minecraft:blackstone)
B(13,3,8,minecraft:blackstone)
B(14,3,8,minecraft:blackstone)
B(15,3,8,minecraft:blackstone)
B(14,3,9,minecraft:blackstone)
B(15,3,9,minecraft:blackstone)
B(15,4,0,minecraft:blackstone)
B(14,4,1,minecraft:blackstone)
B(15,4,1,minecraft:blackstone)
B(13,4,2,minecraft:blackstone)
B(14,4,2,minecraft:blackstone)
B(15,4,2,minecraft:blackstone)
B(12,4,3,minecraft:blackstone)
B(13,4,3,minecraft:blackstone)
B(14,4,3,minecraft:blackstone)
B(15,4,3,minecraft:blackstone)
B(12,4,4,minecraft:blackstone)
B(13,4,4,minecraft:blackstone)
B(14,4,4,minecraft:blackstone)
B(15,4,4,minecraft:blackstone)
B(12,4,5,minecraft:blackstone)
B(13,4,5,minecraft:blackstone)
B(14,4,5,minecraft:blackstone)
B(15,4,5,minecraft:blackstone)
B(12,4,6,minecraft:blackstone)
B(13,4,6,minecraft:blackstone)
B(14,4,6,minecraft:blackstone)
B(15,4,6,minecraft:blackstone)
B(13,4,7,minecraft:blackstone)
B(14,4,7,minecraft:blackstone)
B(15,4,7,minecraft:blackstone)
B(13,4,8,minecraft:blackstone)
B(14,4,8,minecraft:blackstone)
B(15,4,8,minecraft:blackstone)
B(14,4,9,minecraft:blackstone)
B(15,4,9,minecraft:blackstone)
B(15,5,0,minecraft:blackstone)
B(14,5,1,minecraft:blackstone)
B(15,5,1,minecraft:blackstone)
B(13,5,2,minecraft:blackstone)
B(14,5,2,minecraft:blackstone)
B(15,5,2,minecraft:blackstone)
B(12,5,3,minecraft:blackstone)
B(13,5,3,minecraft:blackstone)
B(14,5,3,minecraft:blackstone)
B(15,5,3,minecraft:blackstone)
B(12,5,4,minecraft:blackstone)
B(13,5,4,minecraft:blackstone)
B(14,5,4,minecraft:blackstone)
B(15,5,4,minecraft:blackstone)
B(12,5,5,minecraft:blackstone)
B(13,5,5,minecraft:blackstone)
B(14,5,5,minecraft:blackstone)
B(15,5,5,minecraft:blackstone)
B(12,5,6,minecraft:blackstone)
B(13,5,6,minecraft:blackstone)
B(14,5,6,minecraft:blackstone)
B(15,5,6,minecraft:blackstone)
B(13,5,7,minecraft:blackstone)
B(14,5,7,minecraft:blackstone)
B(15,5,7,minecraft:blackstone)
B(13,5,8,minecraft:blackstone)
B(14,5,8,minecraft:blackstone)
B(15,5,8,minecraft:blackstone)
B(14,5,9,minecraft:blackstone)
B(15,5,9,minecraft:blackstone)
B(15,6,0,minecraft:blackstone)
B(14,6,1,minecraft:blackstone)
B(15,6,1,minecraft:blackstone)
B(13,6,2,minecraft:blackstone)
B(14,6,2,minecraft:blackstone)
B(15,6,2,minecraft:blackstone)
B(12,6,3,minecraft:blackstone)
B(13,6,3,minecraft:blackstone)
B(14,6,3,minecraft:blackstone)
B(15,6,3,minecraft:blackstone)
B(12,6,4,minecraft:blackstone)
B(13,6,4,minecraft:blackstone)
B(14,6,4,minecraft:blackstone)
B(15,6,4,minecraft:blackstone)
B(12,6,5,minecraft:blackstone)
B(13,6,5,minecraft:blackstone)
B(14,6,5,minecraft:blackstone)
B(15,6,5,minecraft:blackstone)
B(12,6,6,minecraft:blackstone)
B(13,6,6,minecraft:blackstone)
B(14,6,6,minecraft:blackstone)
B(15,6,6,minecraft:blackstone)
B(13,6,7,minecraft:blackstone)
B(14,6,7,minecraft:blackstone)
B(15,6,7,minecraft:blackstone)
B(13,6,8,minecraft:blackstone)
B(14,6,8,minecraft:blackstone)
B(15,6,8,minecraft:blackstone)
B(14,6,9,minecraft:blackstone)
B(15,6,9,minecraft:blackstone)
B(15,7,0,minecraft:blackstone)
B(14,7,1,minecraft:blackstone)
B(15,7,1,minecraft:blackstone)
B(13,7,2,minecraft:blackstone)
B(14,7,2,minecraft:blackstone)
B(15,7,2,minecraft:blackstone)
B(12,7,3,minecraft:blackstone)
B(13,7,3,minecraft:blackstone)
B(14,7,3,minecraft:blackstone)
B(15,7,3,minecraft:blackstone)
B(12,7,4,minecraft:blackstone)
B(13,7,4,minecraft:blackstone)
B(14,7,4,minecraft:blackstone)
B(15,7,4,minecraft:blackstone)
B(12,7,5,minecraft:blackstone)
B(13,7,5,minecraft:blackstone)
B(14,7,5,minecraft:blackstone)
B(15,7,5,minecraft:blackstone)
B(12,7,6,minecraft:blackstone)
B(13,7,6,minecraft:blackstone)
B(14,7,6,minecraft:blackstone)
B(15,7,6,minecraft:blackstone)
B(13,7,7,minecraft:blackstone)
B(14,7,7,minecraft:blackstone)
B(15,7,7,minecraft:blackstone)
B(13,7,8,minecraft:blackstone)
B(14,7,8,minecraft:blackstone)
B(15,7,8,minecraft:blackstone)
B(14,7,9,minecraft:blackstone)
B(15,7,9,minecraft:blackstone)
B(14,8,1,minecraft:blackstone)
B(15,8,1,minecraft:blackstone)
B(13,8,2,minecraft:blackstone)
B(14,8,2,minecraft:blackstone)
B(15,8,2,minecraft:blackstone)
B(13,8,3,minecraft:blackstone)
B(14,8,3,minecraft:blackstone)
B(15,8,3,minecraft:blackstone)
B(12,8,4,minecraft:blackstone)
B(13,8,4,minecraft:blackstone)
B(14,8,4,minecraft:blackstone)
B(15,8,4,minecraft:blackstone)
B(12,8,5,minecraft:blackstone)
B(13,8,5,minecraft:blackstone)
B(14,8,5,minecraft:blackstone)
B(15,8,5,minecraft:blackstone)
B(12,8,6,minecraft:blackstone)
B(13,8,6,minecraft:blackstone)
B(14,8,6,minecraft:blackstone)
B(15,8,6,minecraft:blackstone)
B(13,8,7,minecraft:blackstone)
B(14,8,7,minecraft:blackstone)
B(15,8,7,minecraft:blackstone)
B(13,8,8,minecraft:blackstone)
B(14,8,8,minecraft:blackstone)
B(15,8,8,minecraft:blackstone)
B(14,8,9,minecraft:blackstone)
B(15,8,9,minecraft:blackstone)
B(14,9,1,minecraft:blackstone)
B(15,9,1,minecraft:blackstone)
B(13,9,2,minecraft:blackstone)
B(14,9,2,minecraft:blackstone)
B(15,9,2,minecraft:blackstone)
B(13,9,3,minecraft:blackstone)
B(14,9,3,minecraft:blackstone)
B(15,9,3,minecraft:blackstone)
B(12,9,4,minecraft:blackstone)
B(13,9,4,minecraft:blackstone)
B(14,9,4,minecraft:blackstone)
B(15,9,4,minecraft:blackstone)
B(12,9,5,minecraft:blackstone)
B(13,9,5,minecraft:blackstone)
B(14,9,5,minecraft:blackstone)
B(15,9,5,minecraft:blackstone)
B(12,9,6,minecraft:blackstone)
B(13,9,6,minecraft:blackstone)
B(14,9,6,minecraft:blackstone)
B(15,9,6,minecraft:blackstone)
B(13,9,7,minecraft:blackstone)
B(14,9,7,minecraft:blackstone)
B(15,9,7,minecraft:blackstone)
B(13,9,8,minecraft:blackstone)
B(14,9,8,minecraft:blackstone)
B(15,9,8,minecraft:blackstone)
B(14,9,9,minecraft:blackstone)
B(15,9,9,minecraft:blackstone)
B(14,10,1,minecraft:blackstone)
B(15,10,1,minecraft:blackstone)
B(13,10,2,minecraft:blackstone)
B(14,10,2,minecraft:blackstone)
B(15,10,2,minecraft:blackstone)
B(13,10,3,minecraft:blackstone)
B(14,10,3,minecraft:blackstone)
B(15,10,3,minecraft:blackstone)
B(12,10,4,minecraft:blackstone)
B(13,10,4,minecraft:blackstone)
B(14,10,4,minecraft:blackstone)
B(15,10,4,minecraft:blackstone)
B(12,10,5,minecraft:blackstone)
B(13,10,5,minecraft:blackstone)
B(14,10,5,minecraft:blackstone)
B(15,10,5,minecraft:blackstone)
B(12,10,6,minecraft:blackstone)
B(13,10,6,minecraft:blackstone)
B(14,10,6,minecraft:blackstone)
B(15,10,6,minecraft:blackstone)
B(13,10,7,minecraft:blackstone)
B(14,10,7,minecraft:blackstone)
B(15,10,7,minecraft:blackstone)
B(13,10,8,minecraft:blackstone)
B(14,10,8,minecraft:blackstone)
B(15,10,8,minecraft:blackstone)
B(14,10,9,minecraft:blackstone)
B(15,10,9,minecraft:blackstone)
B(14,11,1,minecraft:blackstone)
B(15,11,1,minecraft:blackstone)
B(13,11,2,minecraft:blackstone)
B(14,11,2,minecraft:blackstone)
B(15,11,2,minecraft:blackstone)
B(13,11,3,minecraft:blackstone)
B(14,11,3,minecraft:blackstone)
B(15,11,3,minecraft:blackstone)
B(12,11,4,minecraft:blackstone)
B(13,11,4,minecraft:blackstone)
B(14,11,4,minecraft:blackstone)
B(15,11,4,minecraft:blackstone)
B(12,11,5,minecraft:blackstone)
B(13,11,5,minecraft:blackstone)
B(14,11,5,minecraft:blackstone)
B(15,11,5,minecraft:blackstone)
B(12,11,6,minecraft:blackstone)
B(13,11,6,minecraft:blackstone)
B(14,11,6,minecraft:blackstone)
B(15,11,6,minecraft:blackstone)
B(13,11,7,minecraft:blackstone)
B(14,11,7,minecraft:blackstone)
B(15,11,7,minecraft:blackstone)
B(13,11,8,minecraft:blackstone)
B(14,11,8,minecraft:blackstone)
B(15,11,8,minecraft:blackstone)
B(14,11,9,minecraft:blackstone)
B(15,11,9,minecraft:blackstone)
B(15,12,1,minecraft:blackstone)
B(14,12,2,minecraft:blackstone)
B(15,12,2,minecraft:blackstone)
B(13,12,3,minecraft:blackstone)
B(14,12,3,minecraft:blackstone)
B(15,12,3,minecraft:blackstone)
B(12,12,4,minecraft:blackstone)
B(13,12,4,minecraft:blackstone)
B(14,12,4,minecraft:blackstone)
B(15,12,4,minecraft:blackstone)
B(12,12,5,minecraft:blackstone)
B(13,12,5,minecraft:blackstone)
B(14,12,5,minecraft:blackstone)
B(15,12,5,minecraft:blackstone)
B(12,12,6,minecraft:blackstone)
B(13,12,6,minecraft:blackstone)
B(14,12,6,minecraft:blackstone)
B(15,12,6,minecraft:blackstone)
B(13,12,7,minecraft:blackstone)
B(14,12,7,minecraft:blackstone)
B(15,12,7,minecraft:blackstone)
B(13,12,8,minecraft:blackstone)
B(14,12,8,minecraft:blackstone)
B(15,12,8,minecraft:blackstone)
B(14,12,9,minecraft:blackstone)
B(15,12,9,minecraft:blackstone)
B(15,13,1,minecraft:blackstone)
B(14,13,2,minecraft:blackstone)
B(15,13,2,minecraft:blackstone)
B(13,13,3,minecraft:blackstone)
B(14,13,3,minecraft:blackstone)
B(15,13,3,minecraft:blackstone)
B(12,13,4,minecraft:blackstone)
B(13,13,4,minecraft:blackstone)
B(14,13,4,minecraft:blackstone)
B(15,13,4,minecraft:blackstone)
B(12,13,5,minecraft:blackstone)
B(13,13,5,minecraft:blackstone)
B(14,13,5,minecraft:blackstone)
B(15,13,5,minecraft:blackstone)
B(12,13,6,minecraft:blackstone)
B(13,13,6,minecraft:blackstone)
B(14,13,6,minecraft:blackstone)
B(15,13,6,minecraft:blackstone)
B(13,13,7,minecraft:blackstone)
B(14,13,7,minecraft:blackstone)
B(15,13,7,minecraft:blackstone)
B(13,13,8,minecraft:blackstone)
B(14,13,8,minecraft:blackstone)
B(15,13,8,minecraft:blackstone)
B(14,13,9,minecraft:blackstone)
B(15,13,9,minecraft:blackstone)
B(15,14,1,minecraft:blackstone)
B(14,14,2,minecraft:blackstone)
B(15,14,2,minecraft:blackstone)
B(13,14,3,minecraft:blackstone)
B(14,14,3,minecraft:blackstone)
B(15,14,3,minecraft:blackstone)
B(12,14,4,minecraft:blackstone)
B(13,14,4,minecraft:blackstone)
B(14,14,4,minecraft:blackstone)
B(15,14,4,minecraft:blackstone)
B(12,14,5,minecraft:blackstone)
B(13,14,5,minecraft:blackstone)
B(14,14,5,minecraft:blackstone)
B(15,14,5,minecraft:blackstone)
B(12,14,6,minecraft:blackstone)
B(13,14,6,minecraft:blackstone)
B(14,14,6,minecraft:blackstone)
B(15,14,6,minecraft:blackstone)
B(13,14,7,minecraft:blackstone)
B(14,14,7,minecraft:blackstone)
B(15,14,7,minecraft:blackstone)
B(13,14,8,minecraft:blackstone)
B(14,14,8,minecraft:blackstone)
B(15,14,8,minecraft:blackstone)
B(14,14,9,minecraft:blackstone)
B(15,14,9,minecraft:blackstone)
B(15,15,1,minecraft:blackstone)
B(14,15,2,minecraft:blackstone)
B(15,15,2,minecraft:blackstone)
B(13,15,3,minecraft:blackstone)
B(14,15,3,minecraft:blackstone)
B(15,15,3,minecraft:blackstone)
B(12,15,4,minecraft:blackstone)
B(13,15,4,minecraft:blackstone)
B(14,15,4,minecraft:blackstone)
B(15,15,4,minecraft:blackstone)
B(12,15,5,minecraft:blackstone)
B(13,15,5,minecraft:blackstone)
B(14,15,5,minecraft:blackstone)
B(15,15,5,minecraft:blackstone)
B(12,15,6,minecraft:blackstone)
B(13,15,6,minecraft:blackstone)
B(14,15,6,minecraft:blackstone)
B(15,15,6,minecraft:blackstone)
B(13,15,7,minecraft:blackstone)
B(14,15,7,minecraft:blackstone)
B(15,15,7,minecraft:blackstone)
B(13,15,8,minecraft:blackstone)
B(14,15,8,minecraft:blackstone)
B(15,15,8,minecraft:blackstone)
B(14,15,9,minecraft:blackstone)
B(15,15,9,minecraft:blackstone)
B(15,16,1,minecraft:blackstone)
B(14,16,2,minecraft:blackstone)
B(15,16,2,minecraft:blackstone)
B(13,16,3,minecraft:blackstone)
B(14,16,3,minecraft:blackstone)
B(15,16,3,minecraft:blackstone)
B(12,16,4,minecraft:blackstone)
B(13,16,4,minecraft:blackstone)
B(14,16,4,minecraft:blackstone)
B(15,16,4,minecraft:blackstone)
B(12,16,5,minecraft:blackstone)
B(13,16,5,minecraft:blackstone)
B(14,16,5,minecraft:blackstone)
B(15,16,5,minecraft:blackstone)
B(12,16,6,minecraft:blackstone)
B(13,16,6,minecraft:blackstone)
B(14,16,6,minecraft:blackstone)
B(15,16,6,minecraft:blackstone)
B(13,16,7,minecraft:blackstone)
B(14,16,7,minecraft:blackstone)
B(15,16,7,minecraft:blackstone)
B(13,16,8,minecraft:blackstone)
B(14,16,8,minecraft:blackstone)
B(15,16,8,minecraft:blackstone)
B(14,16,9,minecraft:blackstone)
B(15,16,9,minecraft:blackstone)
B(15,17,1,minecraft:blackstone)
B(14,17,2,minecraft:blackstone)
B(15,17,2,minecraft:blackstone)
B(13,17,3,minecraft:blackstone)
B(14,17,3,minecraft:blackstone)
B(15,17,3,minecraft:blackstone)
B(12,17,4,minecraft:blackstone)
B(13,17,4,minecraft:blackstone)
B(14,17,4,minecraft:blackstone)
B(15,17,4,minecraft:blackstone)
B(12,17,5,minecraft:blackstone)
B(13,17,5,minecraft:blackstone)
B(14,17,5,minecraft:blackstone)
B(15,17,5,minecraft:blackstone)
B(12,17,6,minecraft:blackstone)
B(13,17,6,minecraft:blackstone)
B(14,17,6,minecraft:blackstone)
B(15,17,6,minecraft:blackstone)
B(13,17,7,minecraft:blackstone)
B(14,17,7,minecraft:blackstone)
B(15,17,7,minecraft:blackstone)
B(13,17,8,minecraft:blackstone)
B(14,17,8,minecraft:blackstone)
B(15,17,8,minecraft:blackstone)
B(14,17,9,minecraft:blackstone)
B(15,17,9,minecraft:blackstone)
B(15,18,1,minecraft:blackstone)
B(14,18,2,minecraft:blackstone)
B(15,18,2,minecraft:blackstone)
B(13,18,3,minecraft:blackstone)
B(14,18,3,minecraft:blackstone)
B(15,18,3,minecraft:blackstone)
B(13,18,4,minecraft:blackstone)
B(14,18,4,minecraft:blackstone)
B(15,18,4,minecraft:blackstone)
B(12,18,5,minecraft:blackstone)
B(13,18,5,minecraft:blackstone)
B(14,18,5,minecraft:blackstone)
B(15,18,5,minecraft:blackstone)
B(12,18,6,minecraft:blackstone)
B(13,18,6,minecraft:blackstone)
B(14,18,6,minecraft:blackstone)
B(15,18,6,minecraft:blackstone)
B(13,18,7,minecraft:blackstone)
B(14,18,7,minecraft:blackstone)
B(15,18,7,minecraft:blackstone)
B(13,18,8,minecraft:blackstone)
B(14,18,8,minecraft:blackstone)
B(15,18,8,minecraft:blackstone)
B(14,18,9,minecraft:blackstone)
B(15,18,9,minecraft:blackstone)
B(15,19,1,minecraft:blackstone)
B(14,19,2,minecraft:blackstone)
B(15,19,2,minecraft:blackstone)
B(13,19,3,minecraft:blackstone)
B(14,19,3,minecraft:blackstone)
B(15,19,3,minecraft:blackstone)
B(13,19,4,minecraft:blackstone)
B(14,19,4,minecraft:blackstone)
B(15,19,4,minecraft:blackstone)
B(12,19,5,minecraft:blackstone)
B(13,19,5,minecraft:blackstone)
B(14,19,5,minecraft:blackstone)
B(15,19,5,minecraft:blackstone)
B(12,19,6,minecraft:blackstone)
B(13,19,6,minecraft:blackstone)
B(14,19,6,minecraft:blackstone)
B(15,19,6,minecraft:blackstone)
B(13,19,7,minecraft:blackstone)
B(14,19,7,minecraft:blackstone)
B(15,19,7,minecraft:blackstone)
B(13,19,8,minecraft:blackstone)
B(14,19,8,minecraft:blackstone)
B(15,19,8,minecraft:blackstone)
B(14,19,9,minecraft:blackstone)
B(15,19,9,minecraft:blackstone)
B(15,20,1,minecraft:blackstone)
B(14,20,2,minecraft:blackstone)
B(15,20,2,minecraft:blackstone)
B(13,20,3,minecraft:blackstone)
B(14,20,3,minecraft:blackstone)
B(15,20,3,minecraft:blackstone)
B(13,20,4,minecraft:blackstone)
B(14,20,4,minecraft:blackstone)
B(15,20,4,minecraft:blackstone)
B(12,20,5,minecraft:blackstone)
B(13,20,5,minecraft:blackstone)
B(14,20,5,minecraft:blackstone)
B(15,20,5,minecraft:blackstone)
B(12,20,6,minecraft:blackstone)
B(13,20,6,minecraft:blackstone)
B(14,20,6,minecraft:blackstone)
B(15,20,6,minecraft:blackstone)
B(13,20,7,minecraft:blackstone)
B(14,20,7,minecraft:blackstone)
B(15,20,7,minecraft:blackstone)
B(13,20,8,minecraft:blackstone)
B(14,20,8,minecraft:blackstone)
B(15,20,8,minecraft:blackstone)
B(14,20,9,minecraft:blackstone)
B(15,20,9,minecraft:blackstone)
B(15,21,1,minecraft:blackstone)
B(14,21,2,minecraft:blackstone)
B(15,21,2,minecraft:blackstone)
B(13,21,3,minecraft:blackstone)
B(14,21,3,minecraft:blackstone)
B(15,21,3,minecraft:blackstone)
B(13,21,4,minecraft:blackstone)
B(14,21,4,minecraft:blackstone)
B(15,21,4,minecraft:blackstone)
B(12,21,5,minecraft:blackstone)
B(13,21,5,minecraft:blackstone)
B(14,21,5,minecraft:blackstone)
B(15,21,5,minecraft:blackstone)
B(13,21,6,minecraft:blackstone)
B(14,21,6,minecraft:blackstone)
B(15,21,6,minecraft:blackstone)
B(13,21,7,minecraft:blackstone)
B(14,21,7,minecraft:blackstone)
B(15,21,7,minecraft:blackstone)
B(13,21,8,minecraft:blackstone)
B(14,21,8,minecraft:blackstone)
B(15,21,8,minecraft:blackstone)
B(14,21,9,minecraft:blackstone)
B(15,21,9,minecraft:blackstone)
B(14,22,2,minecraft:blackstone)
B(15,22,2,minecraft:blackstone)
B(13,22,3,minecraft:blackstone)
B(14,22,3,minecraft:blackstone)
B(15,22,3,minecraft:blackstone)
B(13,22,4,minecraft:blackstone)
B(14,22,4,minecraft:blackstone)
B(15,22,4,minecraft:blackstone)
B(13,22,5,minecraft:blackstone)
B(14,22,5,minecraft:blackstone)
B(15,22,5,minecraft:blackstone)
B(13,22,6,minecraft:blackstone)
B(14,22,6,minecraft:blackstone)
B(15,22,6,minecraft:blackstone)
B(13,22,7,minecraft:blackstone)
B(14,22,7,minecraft:blackstone)
B(15,22,7,minecraft:blackstone)
B(13,22,8,minecraft:blackstone)
B(14,22,8,minecraft:blackstone)
B(15,22,8,minecraft:blackstone)
B(14,22,9,minecraft:blackstone)
B(15,22,9,minecraft:blackstone)
B(14,23,2,minecraft:blackstone)
B(15,23,2,minecraft:blackstone)
B(13,23,3,minecraft:blackstone)
B(14,23,3,minecraft:blackstone)
B(15,23,3,minecraft:blackstone)
B(13,23,4,minecraft:blackstone)
B(14,23,4,minecraft:blackstone)
B(15,23,4,minecraft:blackstone)
B(13,23,5,minecraft:blackstone)
B(14,23,5,minecraft:blackstone)
B(15,23,5,minecraft:blackstone)
B(13,23,6,minecraft:blackstone)
B(14,23,6,minecraft:blackstone)
B(15,23,6,minecraft:blackstone)
B(13,23,7,minecraft:blackstone)
B(14,23,7,minecraft:blackstone)
B(15,23,7,minecraft:blackstone)
B(13,23,8,minecraft:blackstone)
B(14,23,8,minecraft:blackstone)
B(15,23,8,minecraft:blackstone)
B(14,23,9,minecraft:blackstone)
B(15,23,9,minecraft:blackstone)
B(14,24,2,minecraft:blackstone)
B(15,24,2,minecraft:blackstone)
B(13,24,3,minecraft:blackstone)
B(14,24,3,minecraft:blackstone)
B(15,24,3,minecraft:blackstone)
B(13,24,4,minecraft:blackstone)
B(14,24,4,minecraft:blackstone)
B(15,24,4,minecraft:blackstone)
B(13,24,5,minecraft:blackstone)
B(14,24,5,minecraft:blackstone)
B(15,24,5,minecraft:blackstone)
B(13,24,6,minecraft:blackstone)
B(14,24,6,minecraft:blackstone)
B(15,24,6,minecraft:blackstone)
B(13,24,7,minecraft:blackstone)
B(14,24,7,minecraft:blackstone)
B(15,24,7,minecraft:blackstone)
B(13,24,8,minecraft:blackstone)
B(14,24,8,minecraft:blackstone)
B(15,24,8,minecraft:blackstone)
B(14,24,9,minecraft:blackstone)
B(15,24,9,minecraft:blackstone)
B(14,25,2,minecraft:blackstone)
B(15,25,2,minecraft:blackstone)
B(14,25,3,minecraft:blackstone)
B(15,25,3,minecraft:blackstone)
B(13,25,4,minecraft:blackstone)
B(14,25,4,minecraft:blackstone)
B(15,25,4,minecraft:blackstone)
B(13,25,5,minecraft:blackstone)
B(14,25,5,minecraft:blackstone)
B(15,25,5,minecraft:blackstone)
B(13,25,6,minecraft:blackstone)
B(14,25,6,minecraft:blackstone)
B(15,25,6,minecraft:blackstone)
B(13,25,7,minecraft:blackstone)
B(14,25,7,minecraft:blackstone)
B(15,25,7,minecraft:blackstone)
B(13,25,8,minecraft:blackstone)
B(14,25,8,minecraft:blackstone)
B(15,25,8,minecraft:blackstone)
B(14,25,9,minecraft:blackstone)
B(15,25,9,minecraft:blackstone)
B(15,26,2,minecraft:blackstone)
B(14,26,3,minecraft:blackstone)
B(15,26,3,minecraft:blackstone)
B(13,26,4,minecraft:blackstone)
B(14,26,4,minecraft:blackstone)
B(15,26,4,minecraft:blackstone)
B(13,26,5,minecraft:blackstone)
B(14,26,5,minecraft:blackstone)
B(15,26,5,minecraft:blackstone)
B(13,26,6,minecraft:blackstone)
B(14,26,6,minecraft:blackstone)
B(15,26,6,minecraft:blackstone)
B(13,26,7,minecraft:blackstone)
B(14,26,7,minecraft:blackstone)
B(15,26,7,minecraft:blackstone)
B(13,26,8,minecraft:blackstone)
B(14,26,8,minecraft:blackstone)
B(15,26,8,minecraft:blackstone)
B(14,26,9,minecraft:blackstone)
B(15,26,9,minecraft:blackstone)
B(15,27,2,minecraft:blackstone)
B(14,27,3,minecraft:blackstone)
B(15,27,3,minecraft:blackstone)
B(13,27,4,minecraft:blackstone)
B(14,27,4,minecraft:blackstone)
B(15,27,4,minecraft:blackstone)
B(13,27,5,minecraft:blackstone)
B(14,27,5,minecraft:blackstone)
B(15,27,5,minecraft:blackstone)
B(13,27,6,minecraft:blackstone)
B(14,27,6,minecraft:blackstone)
B(15,27,6,minecraft:blackstone)
B(13,27,7,minecraft:blackstone)
B(14,27,7,minecraft:blackstone)
B(15,27,7,minecraft:blackstone)
B(13,27,8,minecraft:blackstone)
B(14,27,8,minecraft:blackstone)
B(15,27,8,minecraft:blackstone)
B(14,27,9,minecraft:blackstone)
B(15,27,9,minecraft:blackstone)
B(15,28,2,minecraft:blackstone)
B(14,28,3,minecraft:blackstone)
B(15,28,3,minecraft:blackstone)
B(13,28,4,minecraft:blackstone)
B(14,28,4,minecraft:blackstone)
B(15,28,4,minecraft:blackstone)
B(13,28,5,minecraft:blackstone)
B(14,28,5,minecraft:blackstone)
B(15,28,5,minecraft:blackstone)
B(13,28,6,minecraft:blackstone)
B(14,28,6,minecraft:blackstone)
B(15,28,6,minecraft:blackstone)
B(13,28,7,minecraft:blackstone)
B(14,28,7,minecraft:blackstone)
B(15,28,7,minecraft:blackstone)
B(13,28,8,minecraft:blackstone)
B(14,28,8,minecraft:blackstone)
B(15,28,8,minecraft:blackstone)
B(14,28,9,minecraft:blackstone)
B(15,28,9,minecraft:blackstone)
B(15,29,2,minecraft:blackstone)
B(14,29,3,minecraft:blackstone)
B(15,29,3,minecraft:blackstone)
B(13,29,4,minecraft:blackstone)
B(14,29,4,minecraft:blackstone)
B(15,29,4,minecraft:blackstone)
B(13,29,5,minecraft:blackstone)
B(14,29,5,minecraft:blackstone)
B(15,29,5,minecraft:blackstone)
B(13,29,6,minecraft:blackstone)
B(14,29,6,minecraft:blackstone)
B(15,29,6,minecraft:blackstone)
B(13,29,7,minecraft:blackstone)
B(14,29,7,minecraft:blackstone)
B(15,29,7,minecraft:blackstone)
B(13,29,8,minecraft:blackstone)
B(14,29,8,minecraft:blackstone)
B(15,29,8,minecraft:blackstone)
B(14,29,9,minecraft:blackstone)
B(15,29,9,minecraft:blackstone)
B(15,30,2,minecraft:blackstone)
B(14,30,3,minecraft:blackstone)
B(15,30,3,minecraft:blackstone)
B(14,30,4,minecraft:blackstone)
B(15,30,4,minecraft:blackstone)
B(13,30,5,minecraft:blackstone)
B(14,30,5,minecraft:blackstone)
B(15,30,5,minecraft:blackstone)
B(13,30,6,minecraft:blackstone)
B(14,30,6,minecraft:blackstone)
B(15,30,6,minecraft:blackstone)
B(13,30,7,minecraft:blackstone)
B(14,30,7,minecraft:blackstone)
B(15,30,7,minecraft:blackstone)
B(13,30,8,minecraft:blackstone)
B(14,30,8,minecraft:blackstone)
B(15,30,8,minecraft:blackstone)
B(14,30,9,minecraft:blackstone)
B(15,30,9,minecraft:blackstone)
B(15,31,3,minecraft:blackstone)
B(14,31,4,minecraft:blackstone)
B(15,31,4,minecraft:blackstone)
B(13,31,5,minecraft:blackstone)
B(14,31,5,minecraft:blackstone)
B(15,31,5,minecraft:blackstone)
B(13,31,6,minecraft:blackstone)
B(14,31,6,minecraft:blackstone)
B(15,31,6,minecraft:blackstone)
B(13,31,7,minecraft:blackstone)
B(14,31,7,minecraft:blackstone)
B(15,31,7,minecraft:blackstone)
B(13,31,8,minecraft:blackstone)
B(14,31,8,minecraft:blackstone)
B(15,31,8,minecraft:blackstone)
B(14,31,9,minecraft:blackstone)
B(15,31,9,minecraft:blackstone)
B(15,32,3,minecraft:blackstone)
B(14,32,4,minecraft:blackstone)
B(15,32,4,minecraft:blackstone)
B(13,32,5,minecraft:blackstone)
B(14,32,5,minecraft:blackstone)
B(15,32,5,minecraft:blackstone)
B(13,32,6,minecraft:blackstone)
B(14,32,6,minecraft:blackstone)
B(15,32,6,minecraft:blackstone)
B(13,32,7,minecraft:blackstone)
B(14,32,7,minecraft:blackstone)
B(15,32,7,minecraft:blackstone)
B(14,32,8,minecraft:blackstone)
B(15,32,8,minecraft:blackstone)
B(14,32,9,minecraft:blackstone)
B(15,32,9,minecraft:blackstone)
B(15,33,3,minecraft:blackstone)
B(14,33,4,minecraft:blackstone)
B(15,33,4,minecraft:blackstone)
B(14,33,5,minecraft:blackstone)
B(15,33,5,minecraft:blackstone)
B(13,33,6,minecraft:blackstone)
B(14,33,6,minecraft:blackstone)
B(15,33,6,minecraft:blackstone)
B(13,33,7,minecraft:blackstone)
B(14,33,7,minecraft:blackstone)
B(15,33,7,minecraft:blackstone)
B(14,33,8,minecraft:blackstone)
B(15,33,8,minecraft:blackstone)
B(14,33,9,minecraft:blackstone)
B(15,33,9,minecraft:blackstone)
B(15,34,3,minecraft:blackstone)
B(14,34,4,minecraft:blackstone)
B(15,34,4,minecraft:blackstone)
B(14,34,5,minecraft:blackstone)
B(15,34,5,minecraft:blackstone)
B(13,34,6,minecraft:blackstone)
B(14,34,6,minecraft:blackstone)
B(15,34,6,minecraft:blackstone)
B(13,34,7,minecraft:blackstone)
B(14,34,7,minecraft:blackstone)
B(15,34,7,minecraft:blackstone)
B(14,34,8,minecraft:blackstone)
B(15,34,8,minecraft:blackstone)
B(14,34,9,minecraft:blackstone)
B(15,34,9,minecraft:blackstone)
B(15,35,3,minecraft:blackstone)
B(14,35,4,minecraft:blackstone)
B(15,35,4,minecraft:blackstone)
B(14,35,5,minecraft:blackstone)
B(15,35,5,minecraft:blackstone)
B(13,35,6,minecraft:blackstone)
B(14,35,6,minecraft:blackstone)
B(15,35,6,minecraft:blackstone)
B(13,35,7,minecraft:blackstone)
B(14,35,7,minecraft:blackstone)
B(15,35,7,minecraft:blackstone)
B(14,35,8,minecraft:blackstone)
B(15,35,8,minecraft:blackstone)
B(14,35,9,minecraft:blackstone)
B(15,35,9,minecraft:blackstone)
B(15,36,4,minecraft:blackstone)
B(14,36,5,minecraft:blackstone)
B(15,36,5,minecraft:blackstone)
B(13,36,6,minecraft:blackstone)
B(14,36,6,minecraft:blackstone)
B(15,36,6,minecraft:blackstone)
B(13,36,7,minecraft:blackstone)
B(14,36,7,minecraft:blackstone)
B(15,36,7,minecraft:blackstone)
B(14,36,8,minecraft:blackstone)
B(15,36,8,minecraft:blackstone)
B(15,36,9,minecraft:blackstone)
B(15,37,4,minecraft:blackstone)
B(14,37,5,minecraft:blackstone)
B(15,37,5,minecraft:blackstone)
B(13,37,6,minecraft:blackstone)
B(14,37,6,minecraft:blackstone)
B(15,37,6,minecraft:blackstone)
B(13,37,7,minecraft:blackstone)
B(14,37,7,minecraft:blackstone)
B(15,37,7,minecraft:blackstone)
B(14,37,8,minecraft:blackstone)
B(15,37,8,minecraft:blackstone)
B(15,37,9,minecraft:blackstone)
B(15,38,4,minecraft:blackstone)
B(14,38,5,minecraft:blackstone)
B(15,38,5,minecraft:blackstone)
B(14,38,6,minecraft:blackstone)
B(15,38,6,minecraft:blackstone)
B(13,38,7,minecraft:blackstone)
B(14,38,7,minecraft:blackstone)
B(15,38,7,minecraft:blackstone)
B(14,38,8,minecraft:blackstone)
B(15,38,8,minecraft:blackstone)
B(15,38,9,minecraft:blackstone)
B(15,39,4,minecraft:blackstone)
B(14,39,5,minecraft:blackstone)
B(15,39,5,minecraft:blackstone)
B(14,39,6,minecraft:blackstone)
B(15,39,6,minecraft:blackstone)
B(14,39,7,minecraft:blackstone)
B(15,39,7,minecraft:blackstone)
B(14,39,8,minecraft:blackstone)
B(15,39,8,minecraft:blackstone)
B(15,39,9,minecraft:blackstone)
B(15,40,4,minecraft:blackstone)
B(14,40,5,minecraft:blackstone)
B(15,40,5,minecraft:blackstone)
B(14,40,6,minecraft:blackstone)
B(15,40,6,minecraft:blackstone)
B(14,40,7,minecraft:blackstone)
B(15,40,7,minecraft:blackstone)
B(14,40,8,minecraft:blackstone)
B(15,40,8,minecraft:blackstone)
B(15,40,9,minecraft:blackstone)
B(15,41,5,minecraft:blackstone)
B(14,41,6,minecraft:blackstone)
B(15,41,6,minecraft:blackstone)
B(14,41,7,minecraft:blackstone)
B(15,41,7,minecraft:blackstone)
B(14,41,8,minecraft:blackstone)
B(15,41,8,minecraft:blackstone)
B(15,41,9,minecraft:blackstone)
B(15,42,6,minecraft:blackstone)
B(15,42,7,minecraft:blackstone)
B(15,42,8,minecraft:blackstone)
B(15,42,9,minecraft:blackstone)

