Author: Bo3 BulkEdit

Description: Converted Schematic - Modified by Bo3BulkEdit

Version: 3

SettingsMode: WriteDisable

IsOTGPlus: true
Tree: false
Frequency: 10
Rarity: 100
RotateRandomly: true
SpawnHeight: randomY
SpawnHeightOffset: 0
SpawnHeightVariance: 0
MaxBranchDepth: 10
ExcludedBiomes: All

MinHeight: 50
MaxHeight: 65

SourceBlocks: AIR
MaxPercentageOutsideSourceBlock: 100
OutsideSourceBlock: placeAnyway

ReplaceBelow: BLACKSTONE
ReplaceWithBiomeBlocks: false
ReplaceWithGroundBlock: BLACKSTONE
ReplaceWithSurfaceBlock: BLACKSTONE
ReplaceWithStoneBlock: BLACKSTONE
SmoothRadius: 30
SmoothingSurfaceBlock: BLACKSTONE
SmoothingGroundBlock: BLACKSTONE

B(0,750,0,AIR)
B(15,750,15,AIR)
B(0,0,4,minecraft:blackstone)
B(1,0,4,minecraft:blackstone)
B(0,0,5,minecraft:blackstone)
B(1,0,5,minecraft:blackstone)
B(2,0,5,minecraft:blackstone)
B(3,0,5,minecraft:blackstone)
B(0,0,6,minecraft:blackstone)
B(1,0,6,minecraft:blackstone)
B(2,0,6,minecraft:blackstone)
B(3,0,6,minecraft:blackstone)
B(4,0,6,minecraft:blackstone)
B(0,0,7,minecraft:blackstone)
B(1,0,7,minecraft:blackstone)
B(2,0,7,minecraft:blackstone)
B(3,0,7,minecraft:blackstone)
B(4,0,7,minecraft:blackstone)
B(5,0,7,minecraft:blackstone)
B(0,0,8,minecraft:blackstone)
B(1,0,8,minecraft:blackstone)
B(2,0,8,minecraft:blackstone)
B(3,0,8,minecraft:blackstone)
B(4,0,8,minecraft:blackstone)
B(5,0,8,minecraft:blackstone)
B(6,0,8,minecraft:blackstone)
B(7,0,8,minecraft:blackstone)
B(8,0,8,minecraft:blackstone)
B(0,0,9,minecraft:blackstone)
B(1,0,9,minecraft:blackstone)
B(2,0,9,minecraft:blackstone)
B(3,0,9,minecraft:blackstone)
B(4,0,9,minecraft:blackstone)
B(5,0,9,minecraft:blackstone)
B(6,0,9,minecraft:blackstone)
B(7,0,9,minecraft:blackstone)
B(8,0,9,minecraft:blackstone)
B(9,0,9,minecraft:blackstone)
B(0,0,10,minecraft:blackstone)
B(1,0,10,minecraft:blackstone)
B(2,0,10,minecraft:blackstone)
B(3,0,10,minecraft:blackstone)
B(4,0,10,minecraft:blackstone)
B(5,0,10,minecraft:blackstone)
B(6,0,10,minecraft:blackstone)
B(7,0,10,minecraft:blackstone)
B(8,0,10,minecraft:blackstone)
B(9,0,10,minecraft:blackstone)
B(10,0,10,minecraft:blackstone)
B(11,0,10,minecraft:blackstone)
B(12,0,10,minecraft:blackstone)
B(13,0,10,minecraft:blackstone)
B(14,0,10,minecraft:blackstone)
B(0,0,11,minecraft:blackstone)
B(1,0,11,minecraft:blackstone)
B(2,0,11,minecraft:blackstone)
B(3,0,11,minecraft:blackstone)
B(4,0,11,minecraft:blackstone)
B(5,0,11,minecraft:blackstone)
B(6,0,11,minecraft:blackstone)
B(7,0,11,minecraft:blackstone)
B(8,0,11,minecraft:blackstone)
B(9,0,11,minecraft:blackstone)
B(10,0,11,minecraft:blackstone)
B(11,0,11,minecraft:blackstone)
B(12,0,11,minecraft:blackstone)
B(13,0,11,minecraft:blackstone)
B(14,0,11,minecraft:blackstone)
B(15,0,11,minecraft:blackstone)
B(0,0,12,minecraft:blackstone)
B(1,0,12,minecraft:blackstone)
B(2,0,12,minecraft:blackstone)
B(3,0,12,minecraft:blackstone)
B(4,0,12,minecraft:blackstone)
B(5,0,12,minecraft:blackstone)
B(6,0,12,minecraft:blackstone)
B(7,0,12,minecraft:blackstone)
B(8,0,12,minecraft:blackstone)
B(9,0,12,minecraft:blackstone)
B(10,0,12,minecraft:blackstone)
B(11,0,12,minecraft:blackstone)
B(12,0,12,minecraft:blackstone)
B(13,0,12,minecraft:blackstone)
B(14,0,12,minecraft:blackstone)
B(15,0,12,minecraft:blackstone)
B(0,0,13,minecraft:blackstone)
B(1,0,13,minecraft:blackstone)
B(2,0,13,minecraft:blackstone)
B(3,0,13,minecraft:blackstone)
B(4,0,13,minecraft:blackstone)
B(5,0,13,minecraft:blackstone)
B(6,0,13,minecraft:blackstone)
B(7,0,13,minecraft:blackstone)
B(8,0,13,minecraft:blackstone)
B(9,0,13,minecraft:blackstone)
B(10,0,13,minecraft:blackstone)
B(11,0,13,minecraft:blackstone)
B(12,0,13,minecraft:blackstone)
B(13,0,13,minecraft:blackstone)
B(14,0,13,minecraft:blackstone)
B(15,0,13,minecraft:blackstone)
B(0,0,14,minecraft:blackstone)
B(1,0,14,minecraft:blackstone)
B(2,0,14,minecraft:blackstone)
B(3,0,14,minecraft:blackstone)
B(4,0,14,minecraft:blackstone)
B(5,0,14,minecraft:blackstone)
B(6,0,14,minecraft:blackstone)
B(7,0,14,minecraft:blackstone)
B(8,0,14,minecraft:blackstone)
B(9,0,14,minecraft:blackstone)
B(10,0,14,minecraft:blackstone)
B(11,0,14,minecraft:blackstone)
B(12,0,14,minecraft:blackstone)
B(13,0,14,minecraft:blackstone)
B(14,0,14,minecraft:blackstone)
B(15,0,14,minecraft:blackstone)
B(1,0,15,minecraft:blackstone)
B(2,0,15,minecraft:blackstone)
B(3,0,15,minecraft:blackstone)
B(4,0,15,minecraft:blackstone)
B(5,0,15,minecraft:blackstone)
B(6,0,15,minecraft:blackstone)
B(7,0,15,minecraft:blackstone)
B(8,0,15,minecraft:blackstone)
B(9,0,15,minecraft:blackstone)
B(10,0,15,minecraft:blackstone)
B(11,0,15,minecraft:blackstone)
B(12,0,15,minecraft:blackstone)
B(13,0,15,minecraft:blackstone)
B(14,0,15,minecraft:blackstone)
B(15,0,15,minecraft:blackstone)
B(0,1,4,minecraft:blackstone)
B(1,1,4,minecraft:blackstone)
B(0,1,5,minecraft:blackstone)
B(1,1,5,minecraft:blackstone)
B(2,1,5,minecraft:blackstone)
B(3,1,5,minecraft:blackstone)
B(0,1,6,minecraft:blackstone)
B(1,1,6,minecraft:blackstone)
B(2,1,6,minecraft:blackstone)
B(3,1,6,minecraft:blackstone)
B(4,1,6,minecraft:blackstone)
B(0,1,7,minecraft:blackstone)
B(1,1,7,minecraft:blackstone)
B(2,1,7,minecraft:blackstone)
B(3,1,7,minecraft:blackstone)
B(4,1,7,minecraft:blackstone)
B(5,1,7,minecraft:blackstone)
B(0,1,8,minecraft:blackstone)
B(1,1,8,minecraft:blackstone)
B(2,1,8,minecraft:blackstone)
B(3,1,8,minecraft:blackstone)
B(4,1,8,minecraft:blackstone)
B(5,1,8,minecraft:blackstone)
B(6,1,8,minecraft:blackstone)
B(7,1,8,minecraft:blackstone)
B(8,1,8,minecraft:blackstone)
B(0,1,9,minecraft:blackstone)
B(1,1,9,minecraft:blackstone)
B(2,1,9,minecraft:blackstone)
B(3,1,9,minecraft:blackstone)
B(4,1,9,minecraft:blackstone)
B(5,1,9,minecraft:blackstone)
B(6,1,9,minecraft:blackstone)
B(7,1,9,minecraft:blackstone)
B(8,1,9,minecraft:blackstone)
B(9,1,9,minecraft:blackstone)
B(0,1,10,minecraft:blackstone)
B(1,1,10,minecraft:blackstone)
B(2,1,10,minecraft:blackstone)
B(3,1,10,minecraft:blackstone)
B(4,1,10,minecraft:blackstone)
B(5,1,10,minecraft:blackstone)
B(6,1,10,minecraft:blackstone)
B(7,1,10,minecraft:blackstone)
B(8,1,10,minecraft:blackstone)
B(9,1,10,minecraft:blackstone)
B(10,1,10,minecraft:blackstone)
B(11,1,10,minecraft:blackstone)
B(12,1,10,minecraft:blackstone)
B(13,1,10,minecraft:blackstone)
B(14,1,10,minecraft:blackstone)
B(0,1,11,minecraft:blackstone)
B(1,1,11,minecraft:blackstone)
B(2,1,11,minecraft:blackstone)
B(3,1,11,minecraft:blackstone)
B(4,1,11,minecraft:blackstone)
B(5,1,11,minecraft:blackstone)
B(6,1,11,minecraft:blackstone)
B(7,1,11,minecraft:blackstone)
B(8,1,11,minecraft:blackstone)
B(9,1,11,minecraft:blackstone)
B(10,1,11,minecraft:blackstone)
B(11,1,11,minecraft:blackstone)
B(12,1,11,minecraft:blackstone)
B(13,1,11,minecraft:blackstone)
B(14,1,11,minecraft:blackstone)
B(15,1,11,minecraft:blackstone)
B(0,1,12,minecraft:blackstone)
B(1,1,12,minecraft:blackstone)
B(2,1,12,minecraft:blackstone)
B(3,1,12,minecraft:blackstone)
B(4,1,12,minecraft:blackstone)
B(5,1,12,minecraft:blackstone)
B(6,1,12,minecraft:blackstone)
B(7,1,12,minecraft:blackstone)
B(8,1,12,minecraft:blackstone)
B(9,1,12,minecraft:blackstone)
B(10,1,12,minecraft:blackstone)
B(11,1,12,minecraft:blackstone)
B(12,1,12,minecraft:blackstone)
B(13,1,12,minecraft:blackstone)
B(14,1,12,minecraft:blackstone)
B(15,1,12,minecraft:blackstone)
B(0,1,13,minecraft:blackstone)
B(1,1,13,minecraft:blackstone)
B(2,1,13,minecraft:blackstone)
B(3,1,13,minecraft:blackstone)
B(4,1,13,minecraft:blackstone)
B(5,1,13,minecraft:blackstone)
B(6,1,13,minecraft:blackstone)
B(7,1,13,minecraft:blackstone)
B(8,1,13,minecraft:blackstone)
B(9,1,13,minecraft:blackstone)
B(10,1,13,minecraft:blackstone)
B(11,1,13,minecraft:blackstone)
B(12,1,13,minecraft:blackstone)
B(13,1,13,minecraft:blackstone)
B(14,1,13,minecraft:blackstone)
B(15,1,13,minecraft:blackstone)
B(0,1,14,minecraft:blackstone)
B(1,1,14,minecraft:blackstone)
B(2,1,14,minecraft:blackstone)
B(3,1,14,minecraft:blackstone)
B(4,1,14,minecraft:blackstone)
B(5,1,14,minecraft:blackstone)
B(6,1,14,minecraft:blackstone)
B(7,1,14,minecraft:blackstone)
B(8,1,14,minecraft:blackstone)
B(9,1,14,minecraft:blackstone)
B(10,1,14,minecraft:blackstone)
B(11,1,14,minecraft:blackstone)
B(12,1,14,minecraft:blackstone)
B(13,1,14,minecraft:blackstone)
B(14,1,14,minecraft:blackstone)
B(15,1,14,minecraft:blackstone)
B(1,1,15,minecraft:blackstone)
B(2,1,15,minecraft:blackstone)
B(3,1,15,minecraft:blackstone)
B(4,1,15,minecraft:blackstone)
B(5,1,15,minecraft:blackstone)
B(6,1,15,minecraft:blackstone)
B(7,1,15,minecraft:blackstone)
B(8,1,15,minecraft:blackstone)
B(9,1,15,minecraft:blackstone)
B(10,1,15,minecraft:blackstone)
B(11,1,15,minecraft:blackstone)
B(12,1,15,minecraft:blackstone)
B(13,1,15,minecraft:blackstone)
B(14,1,15,minecraft:blackstone)
B(15,1,15,minecraft:blackstone)
B(0,2,4,minecraft:blackstone)
B(1,2,4,minecraft:blackstone)
B(0,2,5,minecraft:blackstone)
B(1,2,5,minecraft:blackstone)
B(2,2,5,minecraft:blackstone)
B(3,2,5,minecraft:blackstone)
B(0,2,6,minecraft:blackstone)
B(1,2,6,minecraft:blackstone)
B(2,2,6,minecraft:blackstone)
B(3,2,6,minecraft:blackstone)
B(4,2,6,minecraft:blackstone)
B(0,2,7,minecraft:blackstone)
B(1,2,7,minecraft:blackstone)
B(2,2,7,minecraft:blackstone)
B(3,2,7,minecraft:blackstone)
B(4,2,7,minecraft:blackstone)
B(5,2,7,minecraft:blackstone)
B(0,2,8,minecraft:blackstone)
B(1,2,8,minecraft:blackstone)
B(2,2,8,minecraft:blackstone)
B(3,2,8,minecraft:blackstone)
B(4,2,8,minecraft:blackstone)
B(5,2,8,minecraft:blackstone)
B(6,2,8,minecraft:blackstone)
B(7,2,8,minecraft:blackstone)
B(8,2,8,minecraft:blackstone)
B(0,2,9,minecraft:blackstone)
B(1,2,9,minecraft:blackstone)
B(2,2,9,minecraft:blackstone)
B(3,2,9,minecraft:blackstone)
B(4,2,9,minecraft:blackstone)
B(5,2,9,minecraft:blackstone)
B(6,2,9,minecraft:blackstone)
B(7,2,9,minecraft:blackstone)
B(8,2,9,minecraft:blackstone)
B(9,2,9,minecraft:blackstone)
B(0,2,10,minecraft:blackstone)
B(1,2,10,minecraft:blackstone)
B(2,2,10,minecraft:blackstone)
B(3,2,10,minecraft:blackstone)
B(4,2,10,minecraft:blackstone)
B(5,2,10,minecraft:blackstone)
B(6,2,10,minecraft:blackstone)
B(7,2,10,minecraft:blackstone)
B(8,2,10,minecraft:blackstone)
B(9,2,10,minecraft:blackstone)
B(10,2,10,minecraft:blackstone)
B(11,2,10,minecraft:blackstone)
B(12,2,10,minecraft:blackstone)
B(13,2,10,minecraft:blackstone)
B(14,2,10,minecraft:blackstone)
B(0,2,11,minecraft:blackstone)
B(1,2,11,minecraft:blackstone)
B(2,2,11,minecraft:blackstone)
B(3,2,11,minecraft:blackstone)
B(4,2,11,minecraft:blackstone)
B(5,2,11,minecraft:blackstone)
B(6,2,11,minecraft:blackstone)
B(7,2,11,minecraft:blackstone)
B(8,2,11,minecraft:blackstone)
B(9,2,11,minecraft:blackstone)
B(10,2,11,minecraft:blackstone)
B(11,2,11,minecraft:blackstone)
B(12,2,11,minecraft:blackstone)
B(13,2,11,minecraft:blackstone)
B(14,2,11,minecraft:blackstone)
B(15,2,11,minecraft:blackstone)
B(0,2,12,minecraft:blackstone)
B(1,2,12,minecraft:blackstone)
B(2,2,12,minecraft:blackstone)
B(3,2,12,minecraft:blackstone)
B(4,2,12,minecraft:blackstone)
B(5,2,12,minecraft:blackstone)
B(6,2,12,minecraft:blackstone)
B(7,2,12,minecraft:blackstone)
B(8,2,12,minecraft:blackstone)
B(9,2,12,minecraft:blackstone)
B(10,2,12,minecraft:blackstone)
B(11,2,12,minecraft:blackstone)
B(12,2,12,minecraft:blackstone)
B(13,2,12,minecraft:blackstone)
B(14,2,12,minecraft:blackstone)
B(15,2,12,minecraft:blackstone)
B(0,2,13,minecraft:blackstone)
B(1,2,13,minecraft:blackstone)
B(2,2,13,minecraft:blackstone)
B(3,2,13,minecraft:blackstone)
B(4,2,13,minecraft:blackstone)
B(5,2,13,minecraft:blackstone)
B(6,2,13,minecraft:blackstone)
B(7,2,13,minecraft:blackstone)
B(8,2,13,minecraft:blackstone)
B(9,2,13,minecraft:blackstone)
B(10,2,13,minecraft:blackstone)
B(11,2,13,minecraft:blackstone)
B(12,2,13,minecraft:blackstone)
B(13,2,13,minecraft:blackstone)
B(14,2,13,minecraft:blackstone)
B(15,2,13,minecraft:blackstone)
B(0,2,14,minecraft:blackstone)
B(1,2,14,minecraft:blackstone)
B(2,2,14,minecraft:blackstone)
B(3,2,14,minecraft:blackstone)
B(4,2,14,minecraft:blackstone)
B(5,2,14,minecraft:blackstone)
B(6,2,14,minecraft:blackstone)
B(7,2,14,minecraft:blackstone)
B(8,2,14,minecraft:blackstone)
B(9,2,14,minecraft:blackstone)
B(10,2,14,minecraft:blackstone)
B(11,2,14,minecraft:blackstone)
B(12,2,14,minecraft:blackstone)
B(13,2,14,minecraft:blackstone)
B(14,2,14,minecraft:blackstone)
B(15,2,14,minecraft:blackstone)
B(1,2,15,minecraft:blackstone)
B(2,2,15,minecraft:blackstone)
B(3,2,15,minecraft:blackstone)
B(4,2,15,minecraft:blackstone)
B(5,2,15,minecraft:blackstone)
B(6,2,15,minecraft:blackstone)
B(7,2,15,minecraft:blackstone)
B(8,2,15,minecraft:blackstone)
B(9,2,15,minecraft:blackstone)
B(10,2,15,minecraft:blackstone)
B(11,2,15,minecraft:blackstone)
B(12,2,15,minecraft:blackstone)
B(13,2,15,minecraft:blackstone)
B(14,2,15,minecraft:blackstone)
B(15,2,15,minecraft:blackstone)
B(0,3,4,minecraft:blackstone)
B(1,3,4,minecraft:blackstone)
B(0,3,5,minecraft:blackstone)
B(1,3,5,minecraft:blackstone)
B(2,3,5,minecraft:blackstone)
B(0,3,6,minecraft:blackstone)
B(1,3,6,minecraft:blackstone)
B(2,3,6,minecraft:blackstone)
B(3,3,6,minecraft:blackstone)
B(4,3,6,minecraft:blackstone)
B(0,3,7,minecraft:blackstone)
B(1,3,7,minecraft:blackstone)
B(2,3,7,minecraft:blackstone)
B(3,3,7,minecraft:blackstone)
B(4,3,7,minecraft:blackstone)
B(5,3,7,minecraft:blackstone)
B(0,3,8,minecraft:blackstone)
B(1,3,8,minecraft:blackstone)
B(2,3,8,minecraft:blackstone)
B(3,3,8,minecraft:blackstone)
B(4,3,8,minecraft:blackstone)
B(5,3,8,minecraft:blackstone)
B(6,3,8,minecraft:blackstone)
B(7,3,8,minecraft:blackstone)
B(8,3,8,minecraft:blackstone)
B(0,3,9,minecraft:blackstone)
B(1,3,9,minecraft:blackstone)
B(2,3,9,minecraft:blackstone)
B(3,3,9,minecraft:blackstone)
B(4,3,9,minecraft:blackstone)
B(5,3,9,minecraft:blackstone)
B(6,3,9,minecraft:blackstone)
B(7,3,9,minecraft:blackstone)
B(8,3,9,minecraft:blackstone)
B(9,3,9,minecraft:blackstone)
B(0,3,10,minecraft:blackstone)
B(1,3,10,minecraft:blackstone)
B(2,3,10,minecraft:blackstone)
B(3,3,10,minecraft:blackstone)
B(4,3,10,minecraft:blackstone)
B(5,3,10,minecraft:blackstone)
B(6,3,10,minecraft:blackstone)
B(7,3,10,minecraft:blackstone)
B(8,3,10,minecraft:blackstone)
B(9,3,10,minecraft:blackstone)
B(10,3,10,minecraft:blackstone)
B(11,3,10,minecraft:blackstone)
B(12,3,10,minecraft:blackstone)
B(13,3,10,minecraft:blackstone)
B(14,3,10,minecraft:blackstone)
B(0,3,11,minecraft:blackstone)
B(1,3,11,minecraft:blackstone)
B(2,3,11,minecraft:blackstone)
B(3,3,11,minecraft:blackstone)
B(4,3,11,minecraft:blackstone)
B(5,3,11,minecraft:blackstone)
B(6,3,11,minecraft:blackstone)
B(7,3,11,minecraft:blackstone)
B(8,3,11,minecraft:blackstone)
B(9,3,11,minecraft:blackstone)
B(10,3,11,minecraft:blackstone)
B(11,3,11,minecraft:blackstone)
B(12,3,11,minecraft:blackstone)
B(13,3,11,minecraft:blackstone)
B(14,3,11,minecraft:blackstone)
B(15,3,11,minecraft:blackstone)
B(0,3,12,minecraft:blackstone)
B(1,3,12,minecraft:blackstone)
B(2,3,12,minecraft:blackstone)
B(3,3,12,minecraft:blackstone)
B(4,3,12,minecraft:blackstone)
B(5,3,12,minecraft:blackstone)
B(6,3,12,minecraft:blackstone)
B(7,3,12,minecraft:blackstone)
B(8,3,12,minecraft:blackstone)
B(9,3,12,minecraft:blackstone)
B(10,3,12,minecraft:blackstone)
B(11,3,12,minecraft:blackstone)
B(12,3,12,minecraft:blackstone)
B(13,3,12,minecraft:blackstone)
B(14,3,12,minecraft:blackstone)
B(15,3,12,minecraft:blackstone)
B(0,3,13,minecraft:blackstone)
B(1,3,13,minecraft:blackstone)
B(2,3,13,minecraft:blackstone)
B(3,3,13,minecraft:blackstone)
B(4,3,13,minecraft:blackstone)
B(5,3,13,minecraft:blackstone)
B(6,3,13,minecraft:blackstone)
B(7,3,13,minecraft:blackstone)
B(8,3,13,minecraft:blackstone)
B(9,3,13,minecraft:blackstone)
B(10,3,13,minecraft:blackstone)
B(11,3,13,minecraft:blackstone)
B(12,3,13,minecraft:blackstone)
B(13,3,13,minecraft:blackstone)
B(14,3,13,minecraft:blackstone)
B(15,3,13,minecraft:blackstone)
B(0,3,14,minecraft:blackstone)
B(1,3,14,minecraft:blackstone)
B(2,3,14,minecraft:blackstone)
B(3,3,14,minecraft:blackstone)
B(4,3,14,minecraft:blackstone)
B(5,3,14,minecraft:blackstone)
B(6,3,14,minecraft:blackstone)
B(7,3,14,minecraft:blackstone)
B(8,3,14,minecraft:blackstone)
B(9,3,14,minecraft:blackstone)
B(10,3,14,minecraft:blackstone)
B(11,3,14,minecraft:blackstone)
B(12,3,14,minecraft:blackstone)
B(13,3,14,minecraft:blackstone)
B(14,3,14,minecraft:blackstone)
B(15,3,14,minecraft:blackstone)
B(1,3,15,minecraft:blackstone)
B(2,3,15,minecraft:blackstone)
B(3,3,15,minecraft:blackstone)
B(4,3,15,minecraft:blackstone)
B(5,3,15,minecraft:blackstone)
B(6,3,15,minecraft:blackstone)
B(7,3,15,minecraft:blackstone)
B(8,3,15,minecraft:blackstone)
B(9,3,15,minecraft:blackstone)
B(10,3,15,minecraft:blackstone)
B(11,3,15,minecraft:blackstone)
B(12,3,15,minecraft:blackstone)
B(13,3,15,minecraft:blackstone)
B(14,3,15,minecraft:blackstone)
B(15,3,15,minecraft:blackstone)
B(0,4,4,minecraft:blackstone)
B(1,4,4,minecraft:blackstone)
B(0,4,5,minecraft:blackstone)
B(1,4,5,minecraft:blackstone)
B(2,4,5,minecraft:blackstone)
B(0,4,6,minecraft:blackstone)
B(1,4,6,minecraft:blackstone)
B(2,4,6,minecraft:blackstone)
B(3,4,6,minecraft:blackstone)
B(4,4,6,minecraft:blackstone)
B(0,4,7,minecraft:blackstone)
B(1,4,7,minecraft:blackstone)
B(2,4,7,minecraft:blackstone)
B(3,4,7,minecraft:blackstone)
B(4,4,7,minecraft:blackstone)
B(5,4,7,minecraft:blackstone)
B(0,4,8,minecraft:blackstone)
B(1,4,8,minecraft:blackstone)
B(2,4,8,minecraft:blackstone)
B(3,4,8,minecraft:blackstone)
B(4,4,8,minecraft:blackstone)
B(5,4,8,minecraft:blackstone)
B(6,4,8,minecraft:blackstone)
B(7,4,8,minecraft:blackstone)
B(8,4,8,minecraft:blackstone)
B(0,4,9,minecraft:blackstone)
B(1,4,9,minecraft:blackstone)
B(2,4,9,minecraft:blackstone)
B(3,4,9,minecraft:blackstone)
B(4,4,9,minecraft:blackstone)
B(5,4,9,minecraft:blackstone)
B(6,4,9,minecraft:blackstone)
B(7,4,9,minecraft:blackstone)
B(8,4,9,minecraft:blackstone)
B(9,4,9,minecraft:blackstone)
B(0,4,10,minecraft:blackstone)
B(1,4,10,minecraft:blackstone)
B(2,4,10,minecraft:blackstone)
B(3,4,10,minecraft:blackstone)
B(4,4,10,minecraft:blackstone)
B(5,4,10,minecraft:blackstone)
B(6,4,10,minecraft:blackstone)
B(7,4,10,minecraft:blackstone)
B(8,4,10,minecraft:blackstone)
B(9,4,10,minecraft:blackstone)
B(10,4,10,minecraft:blackstone)
B(11,4,10,minecraft:blackstone)
B(12,4,10,minecraft:blackstone)
B(13,4,10,minecraft:blackstone)
B(14,4,10,minecraft:blackstone)
B(0,4,11,minecraft:blackstone)
B(1,4,11,minecraft:blackstone)
B(2,4,11,minecraft:blackstone)
B(3,4,11,minecraft:blackstone)
B(4,4,11,minecraft:blackstone)
B(5,4,11,minecraft:blackstone)
B(6,4,11,minecraft:blackstone)
B(7,4,11,minecraft:blackstone)
B(8,4,11,minecraft:blackstone)
B(9,4,11,minecraft:blackstone)
B(10,4,11,minecraft:blackstone)
B(11,4,11,minecraft:blackstone)
B(12,4,11,minecraft:blackstone)
B(13,4,11,minecraft:blackstone)
B(14,4,11,minecraft:blackstone)
B(15,4,11,minecraft:blackstone)
B(0,4,12,minecraft:blackstone)
B(1,4,12,minecraft:blackstone)
B(2,4,12,minecraft:blackstone)
B(3,4,12,minecraft:blackstone)
B(4,4,12,minecraft:blackstone)
B(5,4,12,minecraft:blackstone)
B(6,4,12,minecraft:blackstone)
B(7,4,12,minecraft:blackstone)
B(8,4,12,minecraft:blackstone)
B(9,4,12,minecraft:blackstone)
B(10,4,12,minecraft:blackstone)
B(11,4,12,minecraft:blackstone)
B(12,4,12,minecraft:blackstone)
B(13,4,12,minecraft:blackstone)
B(14,4,12,minecraft:blackstone)
B(15,4,12,minecraft:blackstone)
B(0,4,13,minecraft:blackstone)
B(1,4,13,minecraft:blackstone)
B(2,4,13,minecraft:blackstone)
B(3,4,13,minecraft:blackstone)
B(4,4,13,minecraft:blackstone)
B(5,4,13,minecraft:blackstone)
B(6,4,13,minecraft:blackstone)
B(7,4,13,minecraft:blackstone)
B(8,4,13,minecraft:blackstone)
B(9,4,13,minecraft:blackstone)
B(10,4,13,minecraft:blackstone)
B(11,4,13,minecraft:blackstone)
B(12,4,13,minecraft:blackstone)
B(13,4,13,minecraft:blackstone)
B(14,4,13,minecraft:blackstone)
B(15,4,13,minecraft:blackstone)
B(0,4,14,minecraft:blackstone)
B(1,4,14,minecraft:blackstone)
B(2,4,14,minecraft:blackstone)
B(3,4,14,minecraft:blackstone)
B(4,4,14,minecraft:blackstone)
B(5,4,14,minecraft:blackstone)
B(6,4,14,minecraft:blackstone)
B(7,4,14,minecraft:blackstone)
B(8,4,14,minecraft:blackstone)
B(9,4,14,minecraft:blackstone)
B(10,4,14,minecraft:blackstone)
B(11,4,14,minecraft:blackstone)
B(12,4,14,minecraft:blackstone)
B(13,4,14,minecraft:blackstone)
B(14,4,14,minecraft:blackstone)
B(15,4,14,minecraft:blackstone)
B(1,4,15,minecraft:blackstone)
B(2,4,15,minecraft:blackstone)
B(3,4,15,minecraft:blackstone)
B(4,4,15,minecraft:blackstone)
B(5,4,15,minecraft:blackstone)
B(6,4,15,minecraft:blackstone)
B(7,4,15,minecraft:blackstone)
B(8,4,15,minecraft:blackstone)
B(9,4,15,minecraft:blackstone)
B(10,4,15,minecraft:blackstone)
B(11,4,15,minecraft:blackstone)
B(12,4,15,minecraft:blackstone)
B(13,4,15,minecraft:blackstone)
B(14,4,15,minecraft:blackstone)
B(15,4,15,minecraft:blackstone)
B(0,5,4,minecraft:blackstone)
B(1,5,4,minecraft:blackstone)
B(0,5,5,minecraft:blackstone)
B(1,5,5,minecraft:blackstone)
B(2,5,5,minecraft:blackstone)
B(0,5,6,minecraft:blackstone)
B(1,5,6,minecraft:blackstone)
B(2,5,6,minecraft:blackstone)
B(3,5,6,minecraft:blackstone)
B(4,5,6,minecraft:blackstone)
B(0,5,7,minecraft:blackstone)
B(1,5,7,minecraft:blackstone)
B(2,5,7,minecraft:blackstone)
B(3,5,7,minecraft:blackstone)
B(4,5,7,minecraft:blackstone)
B(5,5,7,minecraft:blackstone)
B(0,5,8,minecraft:blackstone)
B(1,5,8,minecraft:blackstone)
B(2,5,8,minecraft:blackstone)
B(3,5,8,minecraft:blackstone)
B(4,5,8,minecraft:blackstone)
B(5,5,8,minecraft:blackstone)
B(6,5,8,minecraft:blackstone)
B(7,5,8,minecraft:blackstone)
B(8,5,8,minecraft:blackstone)
B(0,5,9,minecraft:blackstone)
B(1,5,9,minecraft:blackstone)
B(2,5,9,minecraft:blackstone)
B(3,5,9,minecraft:blackstone)
B(4,5,9,minecraft:blackstone)
B(5,5,9,minecraft:blackstone)
B(6,5,9,minecraft:blackstone)
B(7,5,9,minecraft:blackstone)
B(8,5,9,minecraft:blackstone)
B(9,5,9,minecraft:blackstone)
B(0,5,10,minecraft:blackstone)
B(1,5,10,minecraft:blackstone)
B(2,5,10,minecraft:blackstone)
B(3,5,10,minecraft:blackstone)
B(4,5,10,minecraft:blackstone)
B(5,5,10,minecraft:blackstone)
B(6,5,10,minecraft:blackstone)
B(7,5,10,minecraft:blackstone)
B(8,5,10,minecraft:blackstone)
B(9,5,10,minecraft:blackstone)
B(10,5,10,minecraft:blackstone)
B(11,5,10,minecraft:blackstone)
B(12,5,10,minecraft:blackstone)
B(13,5,10,minecraft:blackstone)
B(14,5,10,minecraft:blackstone)
B(0,5,11,minecraft:blackstone)
B(1,5,11,minecraft:blackstone)
B(2,5,11,minecraft:blackstone)
B(3,5,11,minecraft:blackstone)
B(4,5,11,minecraft:blackstone)
B(5,5,11,minecraft:blackstone)
B(6,5,11,minecraft:blackstone)
B(7,5,11,minecraft:blackstone)
B(8,5,11,minecraft:blackstone)
B(9,5,11,minecraft:blackstone)
B(10,5,11,minecraft:blackstone)
B(11,5,11,minecraft:blackstone)
B(12,5,11,minecraft:blackstone)
B(13,5,11,minecraft:blackstone)
B(14,5,11,minecraft:blackstone)
B(15,5,11,minecraft:blackstone)
B(0,5,12,minecraft:blackstone)
B(1,5,12,minecraft:blackstone)
B(2,5,12,minecraft:blackstone)
B(3,5,12,minecraft:blackstone)
B(4,5,12,minecraft:blackstone)
B(5,5,12,minecraft:blackstone)
B(6,5,12,minecraft:blackstone)
B(7,5,12,minecraft:blackstone)
B(8,5,12,minecraft:blackstone)
B(9,5,12,minecraft:blackstone)
B(10,5,12,minecraft:blackstone)
B(11,5,12,minecraft:blackstone)
B(12,5,12,minecraft:blackstone)
B(13,5,12,minecraft:blackstone)
B(14,5,12,minecraft:blackstone)
B(15,5,12,minecraft:blackstone)
B(0,5,13,minecraft:blackstone)
B(1,5,13,minecraft:blackstone)
B(2,5,13,minecraft:blackstone)
B(3,5,13,minecraft:blackstone)
B(4,5,13,minecraft:blackstone)
B(5,5,13,minecraft:blackstone)
B(6,5,13,minecraft:blackstone)
B(7,5,13,minecraft:blackstone)
B(8,5,13,minecraft:blackstone)
B(9,5,13,minecraft:blackstone)
B(10,5,13,minecraft:blackstone)
B(11,5,13,minecraft:blackstone)
B(12,5,13,minecraft:blackstone)
B(13,5,13,minecraft:blackstone)
B(14,5,13,minecraft:blackstone)
B(15,5,13,minecraft:blackstone)
B(0,5,14,minecraft:blackstone)
B(1,5,14,minecraft:blackstone)
B(2,5,14,minecraft:blackstone)
B(3,5,14,minecraft:blackstone)
B(4,5,14,minecraft:blackstone)
B(5,5,14,minecraft:blackstone)
B(6,5,14,minecraft:blackstone)
B(7,5,14,minecraft:blackstone)
B(8,5,14,minecraft:blackstone)
B(9,5,14,minecraft:blackstone)
B(10,5,14,minecraft:blackstone)
B(11,5,14,minecraft:blackstone)
B(12,5,14,minecraft:blackstone)
B(13,5,14,minecraft:blackstone)
B(14,5,14,minecraft:blackstone)
B(15,5,14,minecraft:blackstone)
B(1,5,15,minecraft:blackstone)
B(2,5,15,minecraft:blackstone)
B(3,5,15,minecraft:blackstone)
B(4,5,15,minecraft:blackstone)
B(5,5,15,minecraft:blackstone)
B(6,5,15,minecraft:blackstone)
B(7,5,15,minecraft:blackstone)
B(8,5,15,minecraft:blackstone)
B(9,5,15,minecraft:blackstone)
B(10,5,15,minecraft:blackstone)
B(11,5,15,minecraft:blackstone)
B(12,5,15,minecraft:blackstone)
B(13,5,15,minecraft:blackstone)
B(14,5,15,minecraft:blackstone)
B(15,5,15,minecraft:blackstone)
B(0,6,4,minecraft:blackstone)
B(1,6,4,minecraft:blackstone)
B(0,6,5,minecraft:blackstone)
B(1,6,5,minecraft:blackstone)
B(2,6,5,minecraft:blackstone)
B(0,6,6,minecraft:blackstone)
B(1,6,6,minecraft:blackstone)
B(2,6,6,minecraft:blackstone)
B(3,6,6,minecraft:blackstone)
B(4,6,6,minecraft:blackstone)
B(0,6,7,minecraft:blackstone)
B(1,6,7,minecraft:blackstone)
B(2,6,7,minecraft:blackstone)
B(3,6,7,minecraft:blackstone)
B(4,6,7,minecraft:blackstone)
B(5,6,7,minecraft:blackstone)
B(0,6,8,minecraft:blackstone)
B(1,6,8,minecraft:blackstone)
B(2,6,8,minecraft:blackstone)
B(3,6,8,minecraft:blackstone)
B(4,6,8,minecraft:blackstone)
B(5,6,8,minecraft:blackstone)
B(6,6,8,minecraft:blackstone)
B(7,6,8,minecraft:blackstone)
B(8,6,8,minecraft:blackstone)
B(0,6,9,minecraft:blackstone)
B(1,6,9,minecraft:blackstone)
B(2,6,9,minecraft:blackstone)
B(3,6,9,minecraft:blackstone)
B(4,6,9,minecraft:blackstone)
B(5,6,9,minecraft:blackstone)
B(6,6,9,minecraft:blackstone)
B(7,6,9,minecraft:blackstone)
B(8,6,9,minecraft:blackstone)
B(9,6,9,minecraft:blackstone)
B(0,6,10,minecraft:blackstone)
B(1,6,10,minecraft:blackstone)
B(2,6,10,minecraft:blackstone)
B(3,6,10,minecraft:blackstone)
B(4,6,10,minecraft:blackstone)
B(5,6,10,minecraft:blackstone)
B(6,6,10,minecraft:blackstone)
B(7,6,10,minecraft:blackstone)
B(8,6,10,minecraft:blackstone)
B(9,6,10,minecraft:blackstone)
B(10,6,10,minecraft:blackstone)
B(11,6,10,minecraft:blackstone)
B(12,6,10,minecraft:blackstone)
B(13,6,10,minecraft:blackstone)
B(14,6,10,minecraft:blackstone)
B(0,6,11,minecraft:blackstone)
B(1,6,11,minecraft:blackstone)
B(2,6,11,minecraft:blackstone)
B(3,6,11,minecraft:blackstone)
B(4,6,11,minecraft:blackstone)
B(5,6,11,minecraft:blackstone)
B(6,6,11,minecraft:blackstone)
B(7,6,11,minecraft:blackstone)
B(8,6,11,minecraft:blackstone)
B(9,6,11,minecraft:blackstone)
B(10,6,11,minecraft:blackstone)
B(11,6,11,minecraft:blackstone)
B(12,6,11,minecraft:blackstone)
B(13,6,11,minecraft:blackstone)
B(14,6,11,minecraft:blackstone)
B(15,6,11,minecraft:blackstone)
B(0,6,12,minecraft:blackstone)
B(1,6,12,minecraft:blackstone)
B(2,6,12,minecraft:blackstone)
B(3,6,12,minecraft:blackstone)
B(4,6,12,minecraft:blackstone)
B(5,6,12,minecraft:blackstone)
B(6,6,12,minecraft:blackstone)
B(7,6,12,minecraft:blackstone)
B(8,6,12,minecraft:blackstone)
B(9,6,12,minecraft:blackstone)
B(10,6,12,minecraft:blackstone)
B(11,6,12,minecraft:blackstone)
B(12,6,12,minecraft:blackstone)
B(13,6,12,minecraft:blackstone)
B(14,6,12,minecraft:blackstone)
B(15,6,12,minecraft:blackstone)
B(0,6,13,minecraft:blackstone)
B(1,6,13,minecraft:blackstone)
B(2,6,13,minecraft:blackstone)
B(3,6,13,minecraft:blackstone)
B(4,6,13,minecraft:blackstone)
B(5,6,13,minecraft:blackstone)
B(6,6,13,minecraft:blackstone)
B(7,6,13,minecraft:blackstone)
B(8,6,13,minecraft:blackstone)
B(9,6,13,minecraft:blackstone)
B(10,6,13,minecraft:blackstone)
B(11,6,13,minecraft:blackstone)
B(12,6,13,minecraft:blackstone)
B(13,6,13,minecraft:blackstone)
B(14,6,13,minecraft:blackstone)
B(15,6,13,minecraft:blackstone)
B(0,6,14,minecraft:blackstone)
B(1,6,14,minecraft:blackstone)
B(2,6,14,minecraft:blackstone)
B(3,6,14,minecraft:blackstone)
B(4,6,14,minecraft:blackstone)
B(5,6,14,minecraft:blackstone)
B(6,6,14,minecraft:blackstone)
B(7,6,14,minecraft:blackstone)
B(8,6,14,minecraft:blackstone)
B(9,6,14,minecraft:blackstone)
B(10,6,14,minecraft:blackstone)
B(11,6,14,minecraft:blackstone)
B(12,6,14,minecraft:blackstone)
B(13,6,14,minecraft:blackstone)
B(14,6,14,minecraft:blackstone)
B(15,6,14,minecraft:blackstone)
B(1,6,15,minecraft:blackstone)
B(2,6,15,minecraft:blackstone)
B(3,6,15,minecraft:blackstone)
B(4,6,15,minecraft:blackstone)
B(5,6,15,minecraft:blackstone)
B(6,6,15,minecraft:blackstone)
B(7,6,15,minecraft:blackstone)
B(8,6,15,minecraft:blackstone)
B(9,6,15,minecraft:blackstone)
B(10,6,15,minecraft:blackstone)
B(11,6,15,minecraft:blackstone)
B(12,6,15,minecraft:blackstone)
B(13,6,15,minecraft:blackstone)
B(14,6,15,minecraft:blackstone)
B(15,6,15,minecraft:blackstone)
B(0,7,4,minecraft:blackstone)
B(1,7,4,minecraft:blackstone)
B(0,7,5,minecraft:blackstone)
B(1,7,5,minecraft:blackstone)
B(2,7,5,minecraft:blackstone)
B(0,7,6,minecraft:blackstone)
B(1,7,6,minecraft:blackstone)
B(2,7,6,minecraft:blackstone)
B(3,7,6,minecraft:blackstone)
B(4,7,6,minecraft:blackstone)
B(0,7,7,minecraft:blackstone)
B(1,7,7,minecraft:blackstone)
B(2,7,7,minecraft:blackstone)
B(3,7,7,minecraft:blackstone)
B(4,7,7,minecraft:blackstone)
B(5,7,7,minecraft:blackstone)
B(0,7,8,minecraft:blackstone)
B(1,7,8,minecraft:blackstone)
B(2,7,8,minecraft:blackstone)
B(3,7,8,minecraft:blackstone)
B(4,7,8,minecraft:blackstone)
B(5,7,8,minecraft:blackstone)
B(6,7,8,minecraft:blackstone)
B(7,7,8,minecraft:blackstone)
B(8,7,8,minecraft:blackstone)
B(0,7,9,minecraft:blackstone)
B(1,7,9,minecraft:blackstone)
B(2,7,9,minecraft:blackstone)
B(3,7,9,minecraft:blackstone)
B(4,7,9,minecraft:blackstone)
B(5,7,9,minecraft:blackstone)
B(6,7,9,minecraft:blackstone)
B(7,7,9,minecraft:blackstone)
B(8,7,9,minecraft:blackstone)
B(9,7,9,minecraft:blackstone)
B(0,7,10,minecraft:blackstone)
B(1,7,10,minecraft:blackstone)
B(2,7,10,minecraft:blackstone)
B(3,7,10,minecraft:blackstone)
B(4,7,10,minecraft:blackstone)
B(5,7,10,minecraft:blackstone)
B(6,7,10,minecraft:blackstone)
B(7,7,10,minecraft:blackstone)
B(8,7,10,minecraft:blackstone)
B(9,7,10,minecraft:blackstone)
B(10,7,10,minecraft:blackstone)
B(11,7,10,minecraft:blackstone)
B(12,7,10,minecraft:blackstone)
B(13,7,10,minecraft:blackstone)
B(14,7,10,minecraft:blackstone)
B(0,7,11,minecraft:blackstone)
B(1,7,11,minecraft:blackstone)
B(2,7,11,minecraft:blackstone)
B(3,7,11,minecraft:blackstone)
B(4,7,11,minecraft:blackstone)
B(5,7,11,minecraft:blackstone)
B(6,7,11,minecraft:blackstone)
B(7,7,11,minecraft:blackstone)
B(8,7,11,minecraft:blackstone)
B(9,7,11,minecraft:blackstone)
B(10,7,11,minecraft:blackstone)
B(11,7,11,minecraft:blackstone)
B(12,7,11,minecraft:blackstone)
B(13,7,11,minecraft:blackstone)
B(14,7,11,minecraft:blackstone)
B(15,7,11,minecraft:blackstone)
B(0,7,12,minecraft:blackstone)
B(1,7,12,minecraft:blackstone)
B(2,7,12,minecraft:blackstone)
B(3,7,12,minecraft:blackstone)
B(4,7,12,minecraft:blackstone)
B(5,7,12,minecraft:blackstone)
B(6,7,12,minecraft:blackstone)
B(7,7,12,minecraft:blackstone)
B(8,7,12,minecraft:blackstone)
B(9,7,12,minecraft:blackstone)
B(10,7,12,minecraft:blackstone)
B(11,7,12,minecraft:blackstone)
B(12,7,12,minecraft:blackstone)
B(13,7,12,minecraft:blackstone)
B(14,7,12,minecraft:blackstone)
B(15,7,12,minecraft:blackstone)
B(0,7,13,minecraft:blackstone)
B(1,7,13,minecraft:blackstone)
B(2,7,13,minecraft:blackstone)
B(3,7,13,minecraft:blackstone)
B(4,7,13,minecraft:blackstone)
B(5,7,13,minecraft:blackstone)
B(6,7,13,minecraft:blackstone)
B(7,7,13,minecraft:blackstone)
B(8,7,13,minecraft:blackstone)
B(9,7,13,minecraft:blackstone)
B(10,7,13,minecraft:blackstone)
B(11,7,13,minecraft:blackstone)
B(12,7,13,minecraft:blackstone)
B(13,7,13,minecraft:blackstone)
B(14,7,13,minecraft:blackstone)
B(15,7,13,minecraft:blackstone)
B(0,7,14,minecraft:blackstone)
B(1,7,14,minecraft:blackstone)
B(2,7,14,minecraft:blackstone)
B(3,7,14,minecraft:blackstone)
B(4,7,14,minecraft:blackstone)
B(5,7,14,minecraft:blackstone)
B(6,7,14,minecraft:blackstone)
B(7,7,14,minecraft:blackstone)
B(8,7,14,minecraft:blackstone)
B(9,7,14,minecraft:blackstone)
B(10,7,14,minecraft:blackstone)
B(11,7,14,minecraft:blackstone)
B(12,7,14,minecraft:blackstone)
B(13,7,14,minecraft:blackstone)
B(14,7,14,minecraft:blackstone)
B(15,7,14,minecraft:blackstone)
B(1,7,15,minecraft:blackstone)
B(2,7,15,minecraft:blackstone)
B(3,7,15,minecraft:blackstone)
B(4,7,15,minecraft:blackstone)
B(5,7,15,minecraft:blackstone)
B(6,7,15,minecraft:blackstone)
B(7,7,15,minecraft:blackstone)
B(8,7,15,minecraft:blackstone)
B(9,7,15,minecraft:blackstone)
B(10,7,15,minecraft:blackstone)
B(11,7,15,minecraft:blackstone)
B(12,7,15,minecraft:blackstone)
B(13,7,15,minecraft:blackstone)
B(14,7,15,minecraft:blackstone)
B(15,7,15,minecraft:blackstone)
B(0,8,4,minecraft:blackstone)
B(1,8,4,minecraft:blackstone)
B(0,8,5,minecraft:blackstone)
B(1,8,5,minecraft:blackstone)
B(2,8,5,minecraft:blackstone)
B(0,8,6,minecraft:blackstone)
B(1,8,6,minecraft:blackstone)
B(2,8,6,minecraft:blackstone)
B(3,8,6,minecraft:blackstone)
B(4,8,6,minecraft:blackstone)
B(0,8,7,minecraft:blackstone)
B(1,8,7,minecraft:blackstone)
B(2,8,7,minecraft:blackstone)
B(3,8,7,minecraft:blackstone)
B(4,8,7,minecraft:blackstone)
B(5,8,7,minecraft:blackstone)
B(0,8,8,minecraft:blackstone)
B(1,8,8,minecraft:blackstone)
B(2,8,8,minecraft:blackstone)
B(3,8,8,minecraft:blackstone)
B(4,8,8,minecraft:blackstone)
B(5,8,8,minecraft:blackstone)
B(6,8,8,minecraft:blackstone)
B(7,8,8,minecraft:blackstone)
B(8,8,8,minecraft:blackstone)
B(0,8,9,minecraft:blackstone)
B(1,8,9,minecraft:blackstone)
B(2,8,9,minecraft:blackstone)
B(3,8,9,minecraft:blackstone)
B(4,8,9,minecraft:blackstone)
B(5,8,9,minecraft:blackstone)
B(6,8,9,minecraft:blackstone)
B(7,8,9,minecraft:blackstone)
B(8,8,9,minecraft:blackstone)
B(9,8,9,minecraft:blackstone)
B(0,8,10,minecraft:blackstone)
B(1,8,10,minecraft:blackstone)
B(2,8,10,minecraft:blackstone)
B(3,8,10,minecraft:blackstone)
B(4,8,10,minecraft:blackstone)
B(5,8,10,minecraft:blackstone)
B(6,8,10,minecraft:blackstone)
B(7,8,10,minecraft:blackstone)
B(8,8,10,minecraft:blackstone)
B(9,8,10,minecraft:blackstone)
B(10,8,10,minecraft:blackstone)
B(11,8,10,minecraft:blackstone)
B(12,8,10,minecraft:blackstone)
B(13,8,10,minecraft:blackstone)
B(14,8,10,minecraft:blackstone)
B(0,8,11,minecraft:blackstone)
B(1,8,11,minecraft:blackstone)
B(2,8,11,minecraft:blackstone)
B(3,8,11,minecraft:blackstone)
B(4,8,11,minecraft:blackstone)
B(5,8,11,minecraft:blackstone)
B(6,8,11,minecraft:blackstone)
B(7,8,11,minecraft:blackstone)
B(8,8,11,minecraft:blackstone)
B(9,8,11,minecraft:blackstone)
B(10,8,11,minecraft:blackstone)
B(11,8,11,minecraft:blackstone)
B(12,8,11,minecraft:blackstone)
B(13,8,11,minecraft:blackstone)
B(14,8,11,minecraft:blackstone)
B(15,8,11,minecraft:blackstone)
B(0,8,12,minecraft:blackstone)
B(1,8,12,minecraft:blackstone)
B(2,8,12,minecraft:blackstone)
B(3,8,12,minecraft:blackstone)
B(4,8,12,minecraft:blackstone)
B(5,8,12,minecraft:blackstone)
B(6,8,12,minecraft:blackstone)
B(7,8,12,minecraft:blackstone)
B(8,8,12,minecraft:blackstone)
B(9,8,12,minecraft:blackstone)
B(10,8,12,minecraft:blackstone)
B(11,8,12,minecraft:blackstone)
B(12,8,12,minecraft:blackstone)
B(13,8,12,minecraft:blackstone)
B(14,8,12,minecraft:blackstone)
B(15,8,12,minecraft:blackstone)
B(0,8,13,minecraft:blackstone)
B(1,8,13,minecraft:blackstone)
B(2,8,13,minecraft:blackstone)
B(3,8,13,minecraft:blackstone)
B(4,8,13,minecraft:blackstone)
B(5,8,13,minecraft:blackstone)
B(6,8,13,minecraft:blackstone)
B(7,8,13,minecraft:blackstone)
B(8,8,13,minecraft:blackstone)
B(9,8,13,minecraft:blackstone)
B(10,8,13,minecraft:blackstone)
B(11,8,13,minecraft:blackstone)
B(12,8,13,minecraft:blackstone)
B(13,8,13,minecraft:blackstone)
B(14,8,13,minecraft:blackstone)
B(15,8,13,minecraft:blackstone)
B(0,8,14,minecraft:blackstone)
B(1,8,14,minecraft:blackstone)
B(2,8,14,minecraft:blackstone)
B(3,8,14,minecraft:blackstone)
B(4,8,14,minecraft:blackstone)
B(5,8,14,minecraft:blackstone)
B(6,8,14,minecraft:blackstone)
B(7,8,14,minecraft:blackstone)
B(8,8,14,minecraft:blackstone)
B(9,8,14,minecraft:blackstone)
B(10,8,14,minecraft:blackstone)
B(11,8,14,minecraft:blackstone)
B(12,8,14,minecraft:blackstone)
B(13,8,14,minecraft:blackstone)
B(14,8,14,minecraft:blackstone)
B(15,8,14,minecraft:blackstone)
B(1,8,15,minecraft:blackstone)
B(2,8,15,minecraft:blackstone)
B(3,8,15,minecraft:blackstone)
B(4,8,15,minecraft:blackstone)
B(5,8,15,minecraft:blackstone)
B(6,8,15,minecraft:blackstone)
B(7,8,15,minecraft:blackstone)
B(8,8,15,minecraft:blackstone)
B(9,8,15,minecraft:blackstone)
B(10,8,15,minecraft:blackstone)
B(11,8,15,minecraft:blackstone)
B(12,8,15,minecraft:blackstone)
B(13,8,15,minecraft:blackstone)
B(14,8,15,minecraft:blackstone)
B(15,8,15,minecraft:blackstone)
B(0,9,4,minecraft:blackstone)
B(1,9,4,minecraft:blackstone)
B(0,9,5,minecraft:blackstone)
B(1,9,5,minecraft:blackstone)
B(2,9,5,minecraft:blackstone)
B(0,9,6,minecraft:blackstone)
B(1,9,6,minecraft:blackstone)
B(2,9,6,minecraft:blackstone)
B(3,9,6,minecraft:blackstone)
B(4,9,6,minecraft:blackstone)
B(0,9,7,minecraft:blackstone)
B(1,9,7,minecraft:blackstone)
B(2,9,7,minecraft:blackstone)
B(3,9,7,minecraft:blackstone)
B(4,9,7,minecraft:blackstone)
B(5,9,7,minecraft:blackstone)
B(0,9,8,minecraft:blackstone)
B(1,9,8,minecraft:blackstone)
B(2,9,8,minecraft:blackstone)
B(3,9,8,minecraft:blackstone)
B(4,9,8,minecraft:blackstone)
B(5,9,8,minecraft:blackstone)
B(6,9,8,minecraft:blackstone)
B(7,9,8,minecraft:blackstone)
B(8,9,8,minecraft:blackstone)
B(0,9,9,minecraft:blackstone)
B(1,9,9,minecraft:blackstone)
B(2,9,9,minecraft:blackstone)
B(3,9,9,minecraft:blackstone)
B(4,9,9,minecraft:blackstone)
B(5,9,9,minecraft:blackstone)
B(6,9,9,minecraft:blackstone)
B(7,9,9,minecraft:blackstone)
B(8,9,9,minecraft:blackstone)
B(9,9,9,minecraft:blackstone)
B(0,9,10,minecraft:blackstone)
B(1,9,10,minecraft:blackstone)
B(2,9,10,minecraft:blackstone)
B(3,9,10,minecraft:blackstone)
B(4,9,10,minecraft:blackstone)
B(5,9,10,minecraft:blackstone)
B(6,9,10,minecraft:blackstone)
B(7,9,10,minecraft:blackstone)
B(8,9,10,minecraft:blackstone)
B(9,9,10,minecraft:blackstone)
B(10,9,10,minecraft:blackstone)
B(11,9,10,minecraft:blackstone)
B(12,9,10,minecraft:blackstone)
B(13,9,10,minecraft:blackstone)
B(14,9,10,minecraft:blackstone)
B(0,9,11,minecraft:blackstone)
B(1,9,11,minecraft:blackstone)
B(2,9,11,minecraft:blackstone)
B(3,9,11,minecraft:blackstone)
B(4,9,11,minecraft:blackstone)
B(5,9,11,minecraft:blackstone)
B(6,9,11,minecraft:blackstone)
B(7,9,11,minecraft:blackstone)
B(8,9,11,minecraft:blackstone)
B(9,9,11,minecraft:blackstone)
B(10,9,11,minecraft:blackstone)
B(11,9,11,minecraft:blackstone)
B(12,9,11,minecraft:blackstone)
B(13,9,11,minecraft:blackstone)
B(14,9,11,minecraft:blackstone)
B(15,9,11,minecraft:blackstone)
B(0,9,12,minecraft:blackstone)
B(1,9,12,minecraft:blackstone)
B(2,9,12,minecraft:blackstone)
B(3,9,12,minecraft:blackstone)
B(4,9,12,minecraft:blackstone)
B(5,9,12,minecraft:blackstone)
B(6,9,12,minecraft:blackstone)
B(7,9,12,minecraft:blackstone)
B(8,9,12,minecraft:blackstone)
B(9,9,12,minecraft:blackstone)
B(10,9,12,minecraft:blackstone)
B(11,9,12,minecraft:blackstone)
B(12,9,12,minecraft:blackstone)
B(13,9,12,minecraft:blackstone)
B(14,9,12,minecraft:blackstone)
B(15,9,12,minecraft:blackstone)
B(0,9,13,minecraft:blackstone)
B(1,9,13,minecraft:blackstone)
B(2,9,13,minecraft:blackstone)
B(3,9,13,minecraft:blackstone)
B(4,9,13,minecraft:blackstone)
B(5,9,13,minecraft:blackstone)
B(6,9,13,minecraft:blackstone)
B(7,9,13,minecraft:blackstone)
B(8,9,13,minecraft:blackstone)
B(9,9,13,minecraft:blackstone)
B(10,9,13,minecraft:blackstone)
B(11,9,13,minecraft:blackstone)
B(12,9,13,minecraft:blackstone)
B(13,9,13,minecraft:blackstone)
B(14,9,13,minecraft:blackstone)
B(15,9,13,minecraft:blackstone)
B(0,9,14,minecraft:blackstone)
B(1,9,14,minecraft:blackstone)
B(2,9,14,minecraft:blackstone)
B(3,9,14,minecraft:blackstone)
B(4,9,14,minecraft:blackstone)
B(5,9,14,minecraft:blackstone)
B(6,9,14,minecraft:blackstone)
B(7,9,14,minecraft:blackstone)
B(8,9,14,minecraft:blackstone)
B(9,9,14,minecraft:blackstone)
B(10,9,14,minecraft:blackstone)
B(11,9,14,minecraft:blackstone)
B(12,9,14,minecraft:blackstone)
B(13,9,14,minecraft:blackstone)
B(14,9,14,minecraft:blackstone)
B(15,9,14,minecraft:blackstone)
B(1,9,15,minecraft:blackstone)
B(2,9,15,minecraft:blackstone)
B(3,9,15,minecraft:blackstone)
B(4,9,15,minecraft:blackstone)
B(5,9,15,minecraft:blackstone)
B(6,9,15,minecraft:blackstone)
B(7,9,15,minecraft:blackstone)
B(8,9,15,minecraft:blackstone)
B(9,9,15,minecraft:blackstone)
B(10,9,15,minecraft:blackstone)
B(11,9,15,minecraft:blackstone)
B(12,9,15,minecraft:blackstone)
B(13,9,15,minecraft:blackstone)
B(14,9,15,minecraft:blackstone)
B(15,9,15,minecraft:blackstone)
B(0,10,4,minecraft:blackstone)
B(0,10,5,minecraft:blackstone)
B(1,10,5,minecraft:blackstone)
B(2,10,5,minecraft:blackstone)
B(0,10,6,minecraft:blackstone)
B(1,10,6,minecraft:blackstone)
B(2,10,6,minecraft:blackstone)
B(3,10,6,minecraft:blackstone)
B(4,10,6,minecraft:blackstone)
B(0,10,7,minecraft:blackstone)
B(1,10,7,minecraft:blackstone)
B(2,10,7,minecraft:blackstone)
B(3,10,7,minecraft:blackstone)
B(4,10,7,minecraft:blackstone)
B(5,10,7,minecraft:blackstone)
B(0,10,8,minecraft:blackstone)
B(1,10,8,minecraft:blackstone)
B(2,10,8,minecraft:blackstone)
B(3,10,8,minecraft:blackstone)
B(4,10,8,minecraft:blackstone)
B(5,10,8,minecraft:blackstone)
B(6,10,8,minecraft:blackstone)
B(7,10,8,minecraft:blackstone)
B(8,10,8,minecraft:blackstone)
B(0,10,9,minecraft:blackstone)
B(1,10,9,minecraft:blackstone)
B(2,10,9,minecraft:blackstone)
B(3,10,9,minecraft:blackstone)
B(4,10,9,minecraft:blackstone)
B(5,10,9,minecraft:blackstone)
B(6,10,9,minecraft:blackstone)
B(7,10,9,minecraft:blackstone)
B(8,10,9,minecraft:blackstone)
B(9,10,9,minecraft:blackstone)
B(0,10,10,minecraft:blackstone)
B(1,10,10,minecraft:blackstone)
B(2,10,10,minecraft:blackstone)
B(3,10,10,minecraft:blackstone)
B(4,10,10,minecraft:blackstone)
B(5,10,10,minecraft:blackstone)
B(6,10,10,minecraft:blackstone)
B(7,10,10,minecraft:blackstone)
B(8,10,10,minecraft:blackstone)
B(9,10,10,minecraft:blackstone)
B(10,10,10,minecraft:blackstone)
B(11,10,10,minecraft:blackstone)
B(12,10,10,minecraft:blackstone)
B(13,10,10,minecraft:blackstone)
B(14,10,10,minecraft:blackstone)
B(0,10,11,minecraft:blackstone)
B(1,10,11,minecraft:blackstone)
B(2,10,11,minecraft:blackstone)
B(3,10,11,minecraft:blackstone)
B(4,10,11,minecraft:blackstone)
B(5,10,11,minecraft:blackstone)
B(6,10,11,minecraft:blackstone)
B(7,10,11,minecraft:blackstone)
B(8,10,11,minecraft:blackstone)
B(9,10,11,minecraft:blackstone)
B(10,10,11,minecraft:blackstone)
B(11,10,11,minecraft:blackstone)
B(12,10,11,minecraft:blackstone)
B(13,10,11,minecraft:blackstone)
B(14,10,11,minecraft:blackstone)
B(15,10,11,minecraft:blackstone)
B(0,10,12,minecraft:blackstone)
B(1,10,12,minecraft:blackstone)
B(2,10,12,minecraft:blackstone)
B(3,10,12,minecraft:blackstone)
B(4,10,12,minecraft:blackstone)
B(5,10,12,minecraft:blackstone)
B(6,10,12,minecraft:blackstone)
B(7,10,12,minecraft:blackstone)
B(8,10,12,minecraft:blackstone)
B(9,10,12,minecraft:blackstone)
B(10,10,12,minecraft:blackstone)
B(11,10,12,minecraft:blackstone)
B(12,10,12,minecraft:blackstone)
B(13,10,12,minecraft:blackstone)
B(14,10,12,minecraft:blackstone)
B(15,10,12,minecraft:blackstone)
B(0,10,13,minecraft:blackstone)
B(1,10,13,minecraft:blackstone)
B(2,10,13,minecraft:blackstone)
B(3,10,13,minecraft:blackstone)
B(4,10,13,minecraft:blackstone)
B(5,10,13,minecraft:blackstone)
B(6,10,13,minecraft:blackstone)
B(7,10,13,minecraft:blackstone)
B(8,10,13,minecraft:blackstone)
B(9,10,13,minecraft:blackstone)
B(10,10,13,minecraft:blackstone)
B(11,10,13,minecraft:blackstone)
B(12,10,13,minecraft:blackstone)
B(13,10,13,minecraft:blackstone)
B(14,10,13,minecraft:blackstone)
B(15,10,13,minecraft:blackstone)
B(0,10,14,minecraft:blackstone)
B(1,10,14,minecraft:blackstone)
B(2,10,14,minecraft:blackstone)
B(3,10,14,minecraft:blackstone)
B(4,10,14,minecraft:blackstone)
B(5,10,14,minecraft:blackstone)
B(6,10,14,minecraft:blackstone)
B(7,10,14,minecraft:blackstone)
B(8,10,14,minecraft:blackstone)
B(9,10,14,minecraft:blackstone)
B(10,10,14,minecraft:blackstone)
B(11,10,14,minecraft:blackstone)
B(12,10,14,minecraft:blackstone)
B(13,10,14,minecraft:blackstone)
B(14,10,14,minecraft:blackstone)
B(15,10,14,minecraft:blackstone)
B(1,10,15,minecraft:blackstone)
B(2,10,15,minecraft:blackstone)
B(3,10,15,minecraft:blackstone)
B(4,10,15,minecraft:blackstone)
B(5,10,15,minecraft:blackstone)
B(6,10,15,minecraft:blackstone)
B(7,10,15,minecraft:blackstone)
B(8,10,15,minecraft:blackstone)
B(9,10,15,minecraft:blackstone)
B(10,10,15,minecraft:blackstone)
B(11,10,15,minecraft:blackstone)
B(12,10,15,minecraft:blackstone)
B(13,10,15,minecraft:blackstone)
B(14,10,15,minecraft:blackstone)
B(15,10,15,minecraft:blackstone)
B(0,11,4,minecraft:blackstone)
B(0,11,5,minecraft:blackstone)
B(1,11,5,minecraft:blackstone)
B(2,11,5,minecraft:blackstone)
B(0,11,6,minecraft:blackstone)
B(1,11,6,minecraft:blackstone)
B(2,11,6,minecraft:blackstone)
B(3,11,6,minecraft:blackstone)
B(4,11,6,minecraft:blackstone)
B(0,11,7,minecraft:blackstone)
B(1,11,7,minecraft:blackstone)
B(2,11,7,minecraft:blackstone)
B(3,11,7,minecraft:blackstone)
B(4,11,7,minecraft:blackstone)
B(5,11,7,minecraft:blackstone)
B(0,11,8,minecraft:blackstone)
B(1,11,8,minecraft:blackstone)
B(2,11,8,minecraft:blackstone)
B(3,11,8,minecraft:blackstone)
B(4,11,8,minecraft:blackstone)
B(5,11,8,minecraft:blackstone)
B(6,11,8,minecraft:blackstone)
B(7,11,8,minecraft:blackstone)
B(8,11,8,minecraft:blackstone)
B(0,11,9,minecraft:blackstone)
B(1,11,9,minecraft:blackstone)
B(2,11,9,minecraft:blackstone)
B(3,11,9,minecraft:blackstone)
B(4,11,9,minecraft:blackstone)
B(5,11,9,minecraft:blackstone)
B(6,11,9,minecraft:blackstone)
B(7,11,9,minecraft:blackstone)
B(8,11,9,minecraft:blackstone)
B(9,11,9,minecraft:blackstone)
B(0,11,10,minecraft:blackstone)
B(1,11,10,minecraft:blackstone)
B(2,11,10,minecraft:blackstone)
B(3,11,10,minecraft:blackstone)
B(4,11,10,minecraft:blackstone)
B(5,11,10,minecraft:blackstone)
B(6,11,10,minecraft:blackstone)
B(7,11,10,minecraft:blackstone)
B(8,11,10,minecraft:blackstone)
B(9,11,10,minecraft:blackstone)
B(10,11,10,minecraft:blackstone)
B(11,11,10,minecraft:blackstone)
B(12,11,10,minecraft:blackstone)
B(13,11,10,minecraft:blackstone)
B(14,11,10,minecraft:blackstone)
B(0,11,11,minecraft:blackstone)
B(1,11,11,minecraft:blackstone)
B(2,11,11,minecraft:blackstone)
B(3,11,11,minecraft:blackstone)
B(4,11,11,minecraft:blackstone)
B(5,11,11,minecraft:blackstone)
B(6,11,11,minecraft:blackstone)
B(7,11,11,minecraft:blackstone)
B(8,11,11,minecraft:blackstone)
B(9,11,11,minecraft:blackstone)
B(10,11,11,minecraft:blackstone)
B(11,11,11,minecraft:blackstone)
B(12,11,11,minecraft:blackstone)
B(13,11,11,minecraft:blackstone)
B(14,11,11,minecraft:blackstone)
B(15,11,11,minecraft:blackstone)
B(0,11,12,minecraft:blackstone)
B(1,11,12,minecraft:blackstone)
B(2,11,12,minecraft:blackstone)
B(3,11,12,minecraft:blackstone)
B(4,11,12,minecraft:blackstone)
B(5,11,12,minecraft:blackstone)
B(6,11,12,minecraft:blackstone)
B(7,11,12,minecraft:blackstone)
B(8,11,12,minecraft:blackstone)
B(9,11,12,minecraft:blackstone)
B(10,11,12,minecraft:blackstone)
B(11,11,12,minecraft:blackstone)
B(12,11,12,minecraft:blackstone)
B(13,11,12,minecraft:blackstone)
B(14,11,12,minecraft:blackstone)
B(15,11,12,minecraft:blackstone)
B(0,11,13,minecraft:blackstone)
B(1,11,13,minecraft:blackstone)
B(2,11,13,minecraft:blackstone)
B(3,11,13,minecraft:blackstone)
B(4,11,13,minecraft:blackstone)
B(5,11,13,minecraft:blackstone)
B(6,11,13,minecraft:blackstone)
B(7,11,13,minecraft:blackstone)
B(8,11,13,minecraft:blackstone)
B(9,11,13,minecraft:blackstone)
B(10,11,13,minecraft:blackstone)
B(11,11,13,minecraft:blackstone)
B(12,11,13,minecraft:blackstone)
B(13,11,13,minecraft:blackstone)
B(14,11,13,minecraft:blackstone)
B(15,11,13,minecraft:blackstone)
B(0,11,14,minecraft:blackstone)
B(1,11,14,minecraft:blackstone)
B(2,11,14,minecraft:blackstone)
B(3,11,14,minecraft:blackstone)
B(4,11,14,minecraft:blackstone)
B(5,11,14,minecraft:blackstone)
B(6,11,14,minecraft:blackstone)
B(7,11,14,minecraft:blackstone)
B(8,11,14,minecraft:blackstone)
B(9,11,14,minecraft:blackstone)
B(10,11,14,minecraft:blackstone)
B(11,11,14,minecraft:blackstone)
B(12,11,14,minecraft:blackstone)
B(13,11,14,minecraft:blackstone)
B(14,11,14,minecraft:blackstone)
B(15,11,14,minecraft:blackstone)
B(1,11,15,minecraft:blackstone)
B(2,11,15,minecraft:blackstone)
B(3,11,15,minecraft:blackstone)
B(4,11,15,minecraft:blackstone)
B(5,11,15,minecraft:blackstone)
B(6,11,15,minecraft:blackstone)
B(7,11,15,minecraft:blackstone)
B(8,11,15,minecraft:blackstone)
B(9,11,15,minecraft:blackstone)
B(10,11,15,minecraft:blackstone)
B(11,11,15,minecraft:blackstone)
B(12,11,15,minecraft:blackstone)
B(13,11,15,minecraft:blackstone)
B(14,11,15,minecraft:blackstone)
B(15,11,15,minecraft:blackstone)
B(0,12,4,minecraft:blackstone)
B(0,12,5,minecraft:blackstone)
B(1,12,5,minecraft:blackstone)
B(2,12,5,minecraft:blackstone)
B(0,12,6,minecraft:blackstone)
B(1,12,6,minecraft:blackstone)
B(2,12,6,minecraft:blackstone)
B(3,12,6,minecraft:blackstone)
B(4,12,6,minecraft:blackstone)
B(0,12,7,minecraft:blackstone)
B(1,12,7,minecraft:blackstone)
B(2,12,7,minecraft:blackstone)
B(3,12,7,minecraft:blackstone)
B(4,12,7,minecraft:blackstone)
B(5,12,7,minecraft:blackstone)
B(0,12,8,minecraft:blackstone)
B(1,12,8,minecraft:blackstone)
B(2,12,8,minecraft:blackstone)
B(3,12,8,minecraft:blackstone)
B(4,12,8,minecraft:blackstone)
B(5,12,8,minecraft:blackstone)
B(6,12,8,minecraft:blackstone)
B(7,12,8,minecraft:blackstone)
B(8,12,8,minecraft:blackstone)
B(0,12,9,minecraft:blackstone)
B(1,12,9,minecraft:blackstone)
B(2,12,9,minecraft:blackstone)
B(3,12,9,minecraft:blackstone)
B(4,12,9,minecraft:blackstone)
B(5,12,9,minecraft:blackstone)
B(6,12,9,minecraft:blackstone)
B(7,12,9,minecraft:blackstone)
B(8,12,9,minecraft:blackstone)
B(9,12,9,minecraft:blackstone)
B(0,12,10,minecraft:blackstone)
B(1,12,10,minecraft:blackstone)
B(2,12,10,minecraft:blackstone)
B(3,12,10,minecraft:blackstone)
B(4,12,10,minecraft:blackstone)
B(5,12,10,minecraft:blackstone)
B(6,12,10,minecraft:blackstone)
B(7,12,10,minecraft:blackstone)
B(8,12,10,minecraft:blackstone)
B(9,12,10,minecraft:blackstone)
B(10,12,10,minecraft:blackstone)
B(11,12,10,minecraft:blackstone)
B(12,12,10,minecraft:blackstone)
B(13,12,10,minecraft:blackstone)
B(14,12,10,minecraft:blackstone)
B(0,12,11,minecraft:blackstone)
B(1,12,11,minecraft:blackstone)
B(2,12,11,minecraft:blackstone)
B(3,12,11,minecraft:blackstone)
B(4,12,11,minecraft:blackstone)
B(5,12,11,minecraft:blackstone)
B(6,12,11,minecraft:blackstone)
B(7,12,11,minecraft:blackstone)
B(8,12,11,minecraft:blackstone)
B(9,12,11,minecraft:blackstone)
B(10,12,11,minecraft:blackstone)
B(11,12,11,minecraft:blackstone)
B(12,12,11,minecraft:blackstone)
B(13,12,11,minecraft:blackstone)
B(14,12,11,minecraft:blackstone)
B(15,12,11,minecraft:blackstone)
B(0,12,12,minecraft:blackstone)
B(1,12,12,minecraft:blackstone)
B(2,12,12,minecraft:blackstone)
B(3,12,12,minecraft:blackstone)
B(4,12,12,minecraft:blackstone)
B(5,12,12,minecraft:blackstone)
B(6,12,12,minecraft:blackstone)
B(7,12,12,minecraft:blackstone)
B(8,12,12,minecraft:blackstone)
B(9,12,12,minecraft:blackstone)
B(10,12,12,minecraft:blackstone)
B(11,12,12,minecraft:blackstone)
B(12,12,12,minecraft:blackstone)
B(13,12,12,minecraft:blackstone)
B(14,12,12,minecraft:blackstone)
B(15,12,12,minecraft:blackstone)
B(0,12,13,minecraft:blackstone)
B(1,12,13,minecraft:blackstone)
B(2,12,13,minecraft:blackstone)
B(3,12,13,minecraft:blackstone)
B(4,12,13,minecraft:blackstone)
B(5,12,13,minecraft:blackstone)
B(6,12,13,minecraft:blackstone)
B(7,12,13,minecraft:blackstone)
B(8,12,13,minecraft:blackstone)
B(9,12,13,minecraft:blackstone)
B(10,12,13,minecraft:blackstone)
B(11,12,13,minecraft:blackstone)
B(12,12,13,minecraft:blackstone)
B(13,12,13,minecraft:blackstone)
B(14,12,13,minecraft:blackstone)
B(15,12,13,minecraft:blackstone)
B(0,12,14,minecraft:blackstone)
B(1,12,14,minecraft:blackstone)
B(2,12,14,minecraft:blackstone)
B(3,12,14,minecraft:blackstone)
B(4,12,14,minecraft:blackstone)
B(5,12,14,minecraft:blackstone)
B(6,12,14,minecraft:blackstone)
B(7,12,14,minecraft:blackstone)
B(8,12,14,minecraft:blackstone)
B(9,12,14,minecraft:blackstone)
B(10,12,14,minecraft:blackstone)
B(11,12,14,minecraft:blackstone)
B(12,12,14,minecraft:blackstone)
B(13,12,14,minecraft:blackstone)
B(14,12,14,minecraft:blackstone)
B(15,12,14,minecraft:blackstone)
B(1,12,15,minecraft:blackstone)
B(2,12,15,minecraft:blackstone)
B(3,12,15,minecraft:blackstone)
B(4,12,15,minecraft:blackstone)
B(5,12,15,minecraft:blackstone)
B(6,12,15,minecraft:blackstone)
B(7,12,15,minecraft:blackstone)
B(8,12,15,minecraft:blackstone)
B(9,12,15,minecraft:blackstone)
B(10,12,15,minecraft:blackstone)
B(11,12,15,minecraft:blackstone)
B(12,12,15,minecraft:blackstone)
B(13,12,15,minecraft:blackstone)
B(14,12,15,minecraft:blackstone)
B(15,12,15,minecraft:blackstone)
B(0,13,4,minecraft:blackstone)
B(0,13,5,minecraft:blackstone)
B(1,13,5,minecraft:blackstone)
B(2,13,5,minecraft:blackstone)
B(0,13,6,minecraft:blackstone)
B(1,13,6,minecraft:blackstone)
B(2,13,6,minecraft:blackstone)
B(3,13,6,minecraft:blackstone)
B(4,13,6,minecraft:blackstone)
B(0,13,7,minecraft:blackstone)
B(1,13,7,minecraft:blackstone)
B(2,13,7,minecraft:blackstone)
B(3,13,7,minecraft:blackstone)
B(4,13,7,minecraft:blackstone)
B(5,13,7,minecraft:blackstone)
B(0,13,8,minecraft:blackstone)
B(1,13,8,minecraft:blackstone)
B(2,13,8,minecraft:blackstone)
B(3,13,8,minecraft:blackstone)
B(4,13,8,minecraft:blackstone)
B(5,13,8,minecraft:blackstone)
B(6,13,8,minecraft:blackstone)
B(7,13,8,minecraft:blackstone)
B(8,13,8,minecraft:blackstone)
B(0,13,9,minecraft:blackstone)
B(1,13,9,minecraft:blackstone)
B(2,13,9,minecraft:blackstone)
B(3,13,9,minecraft:blackstone)
B(4,13,9,minecraft:blackstone)
B(5,13,9,minecraft:blackstone)
B(6,13,9,minecraft:blackstone)
B(7,13,9,minecraft:blackstone)
B(8,13,9,minecraft:blackstone)
B(9,13,9,minecraft:blackstone)
B(0,13,10,minecraft:blackstone)
B(1,13,10,minecraft:blackstone)
B(2,13,10,minecraft:blackstone)
B(3,13,10,minecraft:blackstone)
B(4,13,10,minecraft:blackstone)
B(5,13,10,minecraft:blackstone)
B(6,13,10,minecraft:blackstone)
B(7,13,10,minecraft:blackstone)
B(8,13,10,minecraft:blackstone)
B(9,13,10,minecraft:blackstone)
B(10,13,10,minecraft:blackstone)
B(11,13,10,minecraft:blackstone)
B(12,13,10,minecraft:blackstone)
B(13,13,10,minecraft:blackstone)
B(14,13,10,minecraft:blackstone)
B(0,13,11,minecraft:blackstone)
B(1,13,11,minecraft:blackstone)
B(2,13,11,minecraft:blackstone)
B(3,13,11,minecraft:blackstone)
B(4,13,11,minecraft:blackstone)
B(5,13,11,minecraft:blackstone)
B(6,13,11,minecraft:blackstone)
B(7,13,11,minecraft:blackstone)
B(8,13,11,minecraft:blackstone)
B(9,13,11,minecraft:blackstone)
B(10,13,11,minecraft:blackstone)
B(11,13,11,minecraft:blackstone)
B(12,13,11,minecraft:blackstone)
B(13,13,11,minecraft:blackstone)
B(14,13,11,minecraft:blackstone)
B(15,13,11,minecraft:blackstone)
B(0,13,12,minecraft:blackstone)
B(1,13,12,minecraft:blackstone)
B(2,13,12,minecraft:blackstone)
B(3,13,12,minecraft:blackstone)
B(4,13,12,minecraft:blackstone)
B(5,13,12,minecraft:blackstone)
B(6,13,12,minecraft:blackstone)
B(7,13,12,minecraft:blackstone)
B(8,13,12,minecraft:blackstone)
B(9,13,12,minecraft:blackstone)
B(10,13,12,minecraft:blackstone)
B(11,13,12,minecraft:blackstone)
B(12,13,12,minecraft:blackstone)
B(13,13,12,minecraft:blackstone)
B(14,13,12,minecraft:blackstone)
B(15,13,12,minecraft:blackstone)
B(0,13,13,minecraft:blackstone)
B(1,13,13,minecraft:blackstone)
B(2,13,13,minecraft:blackstone)
B(3,13,13,minecraft:blackstone)
B(4,13,13,minecraft:blackstone)
B(5,13,13,minecraft:blackstone)
B(6,13,13,minecraft:blackstone)
B(7,13,13,minecraft:blackstone)
B(8,13,13,minecraft:blackstone)
B(9,13,13,minecraft:blackstone)
B(10,13,13,minecraft:blackstone)
B(11,13,13,minecraft:blackstone)
B(12,13,13,minecraft:blackstone)
B(13,13,13,minecraft:blackstone)
B(14,13,13,minecraft:blackstone)
B(15,13,13,minecraft:blackstone)
B(0,13,14,minecraft:blackstone)
B(1,13,14,minecraft:blackstone)
B(2,13,14,minecraft:blackstone)
B(3,13,14,minecraft:blackstone)
B(4,13,14,minecraft:blackstone)
B(5,13,14,minecraft:blackstone)
B(6,13,14,minecraft:blackstone)
B(7,13,14,minecraft:blackstone)
B(8,13,14,minecraft:blackstone)
B(9,13,14,minecraft:blackstone)
B(10,13,14,minecraft:blackstone)
B(11,13,14,minecraft:blackstone)
B(12,13,14,minecraft:blackstone)
B(13,13,14,minecraft:blackstone)
B(14,13,14,minecraft:blackstone)
B(15,13,14,minecraft:blackstone)
B(1,13,15,minecraft:blackstone)
B(2,13,15,minecraft:blackstone)
B(3,13,15,minecraft:blackstone)
B(4,13,15,minecraft:blackstone)
B(5,13,15,minecraft:blackstone)
B(6,13,15,minecraft:blackstone)
B(7,13,15,minecraft:blackstone)
B(8,13,15,minecraft:blackstone)
B(9,13,15,minecraft:blackstone)
B(10,13,15,minecraft:blackstone)
B(11,13,15,minecraft:blackstone)
B(12,13,15,minecraft:blackstone)
B(13,13,15,minecraft:blackstone)
B(14,13,15,minecraft:blackstone)
B(15,13,15,minecraft:blackstone)
B(0,14,4,minecraft:blackstone)
B(0,14,5,minecraft:blackstone)
B(1,14,5,minecraft:blackstone)
B(2,14,5,minecraft:blackstone)
B(0,14,6,minecraft:blackstone)
B(1,14,6,minecraft:blackstone)
B(2,14,6,minecraft:blackstone)
B(3,14,6,minecraft:blackstone)
B(4,14,6,minecraft:blackstone)
B(0,14,7,minecraft:blackstone)
B(1,14,7,minecraft:blackstone)
B(2,14,7,minecraft:blackstone)
B(3,14,7,minecraft:blackstone)
B(4,14,7,minecraft:blackstone)
B(5,14,7,minecraft:blackstone)
B(0,14,8,minecraft:blackstone)
B(1,14,8,minecraft:blackstone)
B(2,14,8,minecraft:blackstone)
B(3,14,8,minecraft:blackstone)
B(4,14,8,minecraft:blackstone)
B(5,14,8,minecraft:blackstone)
B(6,14,8,minecraft:blackstone)
B(7,14,8,minecraft:blackstone)
B(8,14,8,minecraft:blackstone)
B(0,14,9,minecraft:blackstone)
B(1,14,9,minecraft:blackstone)
B(2,14,9,minecraft:blackstone)
B(3,14,9,minecraft:blackstone)
B(4,14,9,minecraft:blackstone)
B(5,14,9,minecraft:blackstone)
B(6,14,9,minecraft:blackstone)
B(7,14,9,minecraft:blackstone)
B(8,14,9,minecraft:blackstone)
B(9,14,9,minecraft:blackstone)
B(0,14,10,minecraft:blackstone)
B(1,14,10,minecraft:blackstone)
B(2,14,10,minecraft:blackstone)
B(3,14,10,minecraft:blackstone)
B(4,14,10,minecraft:blackstone)
B(5,14,10,minecraft:blackstone)
B(6,14,10,minecraft:blackstone)
B(7,14,10,minecraft:blackstone)
B(8,14,10,minecraft:blackstone)
B(9,14,10,minecraft:blackstone)
B(10,14,10,minecraft:blackstone)
B(11,14,10,minecraft:blackstone)
B(12,14,10,minecraft:blackstone)
B(13,14,10,minecraft:blackstone)
B(14,14,10,minecraft:blackstone)
B(0,14,11,minecraft:blackstone)
B(1,14,11,minecraft:blackstone)
B(2,14,11,minecraft:blackstone)
B(3,14,11,minecraft:blackstone)
B(4,14,11,minecraft:blackstone)
B(5,14,11,minecraft:blackstone)
B(6,14,11,minecraft:blackstone)
B(7,14,11,minecraft:blackstone)
B(8,14,11,minecraft:blackstone)
B(9,14,11,minecraft:blackstone)
B(10,14,11,minecraft:blackstone)
B(11,14,11,minecraft:blackstone)
B(12,14,11,minecraft:blackstone)
B(13,14,11,minecraft:blackstone)
B(14,14,11,minecraft:blackstone)
B(15,14,11,minecraft:blackstone)
B(0,14,12,minecraft:blackstone)
B(1,14,12,minecraft:blackstone)
B(2,14,12,minecraft:blackstone)
B(3,14,12,minecraft:blackstone)
B(4,14,12,minecraft:blackstone)
B(5,14,12,minecraft:blackstone)
B(6,14,12,minecraft:blackstone)
B(7,14,12,minecraft:blackstone)
B(8,14,12,minecraft:blackstone)
B(9,14,12,minecraft:blackstone)
B(10,14,12,minecraft:blackstone)
B(11,14,12,minecraft:blackstone)
B(12,14,12,minecraft:blackstone)
B(13,14,12,minecraft:blackstone)
B(14,14,12,minecraft:blackstone)
B(15,14,12,minecraft:blackstone)
B(0,14,13,minecraft:blackstone)
B(1,14,13,minecraft:blackstone)
B(2,14,13,minecraft:blackstone)
B(3,14,13,minecraft:blackstone)
B(4,14,13,minecraft:blackstone)
B(5,14,13,minecraft:blackstone)
B(6,14,13,minecraft:blackstone)
B(7,14,13,minecraft:blackstone)
B(8,14,13,minecraft:blackstone)
B(9,14,13,minecraft:blackstone)
B(10,14,13,minecraft:blackstone)
B(11,14,13,minecraft:blackstone)
B(12,14,13,minecraft:blackstone)
B(13,14,13,minecraft:blackstone)
B(14,14,13,minecraft:blackstone)
B(15,14,13,minecraft:blackstone)
B(0,14,14,minecraft:blackstone)
B(1,14,14,minecraft:blackstone)
B(2,14,14,minecraft:blackstone)
B(3,14,14,minecraft:blackstone)
B(4,14,14,minecraft:blackstone)
B(5,14,14,minecraft:blackstone)
B(6,14,14,minecraft:blackstone)
B(7,14,14,minecraft:blackstone)
B(8,14,14,minecraft:blackstone)
B(9,14,14,minecraft:blackstone)
B(10,14,14,minecraft:blackstone)
B(11,14,14,minecraft:blackstone)
B(12,14,14,minecraft:blackstone)
B(13,14,14,minecraft:blackstone)
B(14,14,14,minecraft:blackstone)
B(15,14,14,minecraft:blackstone)
B(1,14,15,minecraft:blackstone)
B(2,14,15,minecraft:blackstone)
B(3,14,15,minecraft:blackstone)
B(4,14,15,minecraft:blackstone)
B(5,14,15,minecraft:blackstone)
B(6,14,15,minecraft:blackstone)
B(7,14,15,minecraft:blackstone)
B(8,14,15,minecraft:blackstone)
B(9,14,15,minecraft:blackstone)
B(10,14,15,minecraft:blackstone)
B(11,14,15,minecraft:blackstone)
B(12,14,15,minecraft:blackstone)
B(13,14,15,minecraft:blackstone)
B(14,14,15,minecraft:blackstone)
B(15,14,15,minecraft:blackstone)
B(0,15,4,minecraft:blackstone)
B(0,15,5,minecraft:blackstone)
B(1,15,5,minecraft:blackstone)
B(2,15,5,minecraft:blackstone)
B(0,15,6,minecraft:blackstone)
B(1,15,6,minecraft:blackstone)
B(2,15,6,minecraft:blackstone)
B(3,15,6,minecraft:blackstone)
B(4,15,6,minecraft:blackstone)
B(0,15,7,minecraft:blackstone)
B(1,15,7,minecraft:blackstone)
B(2,15,7,minecraft:blackstone)
B(3,15,7,minecraft:blackstone)
B(4,15,7,minecraft:blackstone)
B(5,15,7,minecraft:blackstone)
B(0,15,8,minecraft:blackstone)
B(1,15,8,minecraft:blackstone)
B(2,15,8,minecraft:blackstone)
B(3,15,8,minecraft:blackstone)
B(4,15,8,minecraft:blackstone)
B(5,15,8,minecraft:blackstone)
B(6,15,8,minecraft:blackstone)
B(7,15,8,minecraft:blackstone)
B(8,15,8,minecraft:blackstone)
B(0,15,9,minecraft:blackstone)
B(1,15,9,minecraft:blackstone)
B(2,15,9,minecraft:blackstone)
B(3,15,9,minecraft:blackstone)
B(4,15,9,minecraft:blackstone)
B(5,15,9,minecraft:blackstone)
B(6,15,9,minecraft:blackstone)
B(7,15,9,minecraft:blackstone)
B(8,15,9,minecraft:blackstone)
B(9,15,9,minecraft:blackstone)
B(0,15,10,minecraft:blackstone)
B(1,15,10,minecraft:blackstone)
B(2,15,10,minecraft:blackstone)
B(3,15,10,minecraft:blackstone)
B(4,15,10,minecraft:blackstone)
B(5,15,10,minecraft:blackstone)
B(6,15,10,minecraft:blackstone)
B(7,15,10,minecraft:blackstone)
B(8,15,10,minecraft:blackstone)
B(9,15,10,minecraft:blackstone)
B(10,15,10,minecraft:blackstone)
B(11,15,10,minecraft:blackstone)
B(12,15,10,minecraft:blackstone)
B(13,15,10,minecraft:blackstone)
B(14,15,10,minecraft:blackstone)
B(0,15,11,minecraft:blackstone)
B(1,15,11,minecraft:blackstone)
B(2,15,11,minecraft:blackstone)
B(3,15,11,minecraft:blackstone)
B(4,15,11,minecraft:blackstone)
B(5,15,11,minecraft:blackstone)
B(6,15,11,minecraft:blackstone)
B(7,15,11,minecraft:blackstone)
B(8,15,11,minecraft:blackstone)
B(9,15,11,minecraft:blackstone)
B(10,15,11,minecraft:blackstone)
B(11,15,11,minecraft:blackstone)
B(12,15,11,minecraft:blackstone)
B(13,15,11,minecraft:blackstone)
B(14,15,11,minecraft:blackstone)
B(15,15,11,minecraft:blackstone)
B(0,15,12,minecraft:blackstone)
B(1,15,12,minecraft:blackstone)
B(2,15,12,minecraft:blackstone)
B(3,15,12,minecraft:blackstone)
B(4,15,12,minecraft:blackstone)
B(5,15,12,minecraft:blackstone)
B(6,15,12,minecraft:blackstone)
B(7,15,12,minecraft:blackstone)
B(8,15,12,minecraft:blackstone)
B(9,15,12,minecraft:blackstone)
B(10,15,12,minecraft:blackstone)
B(11,15,12,minecraft:blackstone)
B(12,15,12,minecraft:blackstone)
B(13,15,12,minecraft:blackstone)
B(14,15,12,minecraft:blackstone)
B(15,15,12,minecraft:blackstone)
B(0,15,13,minecraft:blackstone)
B(1,15,13,minecraft:blackstone)
B(2,15,13,minecraft:blackstone)
B(3,15,13,minecraft:blackstone)
B(4,15,13,minecraft:blackstone)
B(5,15,13,minecraft:blackstone)
B(6,15,13,minecraft:blackstone)
B(7,15,13,minecraft:blackstone)
B(8,15,13,minecraft:blackstone)
B(9,15,13,minecraft:blackstone)
B(10,15,13,minecraft:blackstone)
B(11,15,13,minecraft:blackstone)
B(12,15,13,minecraft:blackstone)
B(13,15,13,minecraft:blackstone)
B(14,15,13,minecraft:blackstone)
B(15,15,13,minecraft:blackstone)
B(0,15,14,minecraft:blackstone)
B(1,15,14,minecraft:blackstone)
B(2,15,14,minecraft:blackstone)
B(3,15,14,minecraft:blackstone)
B(4,15,14,minecraft:blackstone)
B(5,15,14,minecraft:blackstone)
B(6,15,14,minecraft:blackstone)
B(7,15,14,minecraft:blackstone)
B(8,15,14,minecraft:blackstone)
B(9,15,14,minecraft:blackstone)
B(10,15,14,minecraft:blackstone)
B(11,15,14,minecraft:blackstone)
B(12,15,14,minecraft:blackstone)
B(13,15,14,minecraft:blackstone)
B(14,15,14,minecraft:blackstone)
B(15,15,14,minecraft:blackstone)
B(1,15,15,minecraft:blackstone)
B(2,15,15,minecraft:blackstone)
B(3,15,15,minecraft:blackstone)
B(4,15,15,minecraft:blackstone)
B(5,15,15,minecraft:blackstone)
B(6,15,15,minecraft:blackstone)
B(7,15,15,minecraft:blackstone)
B(8,15,15,minecraft:blackstone)
B(9,15,15,minecraft:blackstone)
B(10,15,15,minecraft:blackstone)
B(11,15,15,minecraft:blackstone)
B(12,15,15,minecraft:blackstone)
B(13,15,15,minecraft:blackstone)
B(14,15,15,minecraft:blackstone)
B(15,15,15,minecraft:blackstone)
B(0,16,4,minecraft:blackstone)
B(0,16,5,minecraft:blackstone)
B(1,16,5,minecraft:blackstone)
B(2,16,5,minecraft:blackstone)
B(0,16,6,minecraft:blackstone)
B(1,16,6,minecraft:blackstone)
B(2,16,6,minecraft:blackstone)
B(3,16,6,minecraft:blackstone)
B(4,16,6,minecraft:blackstone)
B(0,16,7,minecraft:blackstone)
B(1,16,7,minecraft:blackstone)
B(2,16,7,minecraft:blackstone)
B(3,16,7,minecraft:blackstone)
B(4,16,7,minecraft:blackstone)
B(5,16,7,minecraft:blackstone)
B(0,16,8,minecraft:blackstone)
B(1,16,8,minecraft:blackstone)
B(2,16,8,minecraft:blackstone)
B(3,16,8,minecraft:blackstone)
B(4,16,8,minecraft:blackstone)
B(5,16,8,minecraft:blackstone)
B(6,16,8,minecraft:blackstone)
B(7,16,8,minecraft:blackstone)
B(8,16,8,minecraft:blackstone)
B(0,16,9,minecraft:blackstone)
B(1,16,9,minecraft:blackstone)
B(2,16,9,minecraft:blackstone)
B(3,16,9,minecraft:blackstone)
B(4,16,9,minecraft:blackstone)
B(5,16,9,minecraft:blackstone)
B(6,16,9,minecraft:blackstone)
B(7,16,9,minecraft:blackstone)
B(8,16,9,minecraft:blackstone)
B(9,16,9,minecraft:blackstone)
B(0,16,10,minecraft:blackstone)
B(1,16,10,minecraft:blackstone)
B(2,16,10,minecraft:blackstone)
B(3,16,10,minecraft:blackstone)
B(4,16,10,minecraft:blackstone)
B(5,16,10,minecraft:blackstone)
B(6,16,10,minecraft:blackstone)
B(7,16,10,minecraft:blackstone)
B(8,16,10,minecraft:blackstone)
B(9,16,10,minecraft:blackstone)
B(10,16,10,minecraft:blackstone)
B(11,16,10,minecraft:blackstone)
B(12,16,10,minecraft:blackstone)
B(13,16,10,minecraft:blackstone)
B(14,16,10,minecraft:blackstone)
B(0,16,11,minecraft:blackstone)
B(1,16,11,minecraft:blackstone)
B(2,16,11,minecraft:blackstone)
B(3,16,11,minecraft:blackstone)
B(4,16,11,minecraft:blackstone)
B(5,16,11,minecraft:blackstone)
B(6,16,11,minecraft:blackstone)
B(7,16,11,minecraft:blackstone)
B(8,16,11,minecraft:blackstone)
B(9,16,11,minecraft:blackstone)
B(10,16,11,minecraft:blackstone)
B(11,16,11,minecraft:blackstone)
B(12,16,11,minecraft:blackstone)
B(13,16,11,minecraft:blackstone)
B(14,16,11,minecraft:blackstone)
B(15,16,11,minecraft:blackstone)
B(0,16,12,minecraft:blackstone)
B(1,16,12,minecraft:blackstone)
B(2,16,12,minecraft:blackstone)
B(3,16,12,minecraft:blackstone)
B(4,16,12,minecraft:blackstone)
B(5,16,12,minecraft:blackstone)
B(6,16,12,minecraft:blackstone)
B(7,16,12,minecraft:blackstone)
B(8,16,12,minecraft:blackstone)
B(9,16,12,minecraft:blackstone)
B(10,16,12,minecraft:blackstone)
B(11,16,12,minecraft:blackstone)
B(12,16,12,minecraft:blackstone)
B(13,16,12,minecraft:blackstone)
B(14,16,12,minecraft:blackstone)
B(15,16,12,minecraft:blackstone)
B(0,16,13,minecraft:blackstone)
B(1,16,13,minecraft:blackstone)
B(2,16,13,minecraft:blackstone)
B(3,16,13,minecraft:blackstone)
B(4,16,13,minecraft:blackstone)
B(5,16,13,minecraft:blackstone)
B(6,16,13,minecraft:blackstone)
B(7,16,13,minecraft:blackstone)
B(8,16,13,minecraft:blackstone)
B(9,16,13,minecraft:blackstone)
B(10,16,13,minecraft:blackstone)
B(11,16,13,minecraft:blackstone)
B(12,16,13,minecraft:blackstone)
B(13,16,13,minecraft:blackstone)
B(14,16,13,minecraft:blackstone)
B(15,16,13,minecraft:blackstone)
B(0,16,14,minecraft:blackstone)
B(1,16,14,minecraft:blackstone)
B(2,16,14,minecraft:blackstone)
B(3,16,14,minecraft:blackstone)
B(4,16,14,minecraft:blackstone)
B(5,16,14,minecraft:blackstone)
B(6,16,14,minecraft:blackstone)
B(7,16,14,minecraft:blackstone)
B(8,16,14,minecraft:blackstone)
B(9,16,14,minecraft:blackstone)
B(10,16,14,minecraft:blackstone)
B(11,16,14,minecraft:blackstone)
B(12,16,14,minecraft:blackstone)
B(13,16,14,minecraft:blackstone)
B(14,16,14,minecraft:blackstone)
B(15,16,14,minecraft:blackstone)
B(1,16,15,minecraft:blackstone)
B(2,16,15,minecraft:blackstone)
B(3,16,15,minecraft:blackstone)
B(4,16,15,minecraft:blackstone)
B(5,16,15,minecraft:blackstone)
B(6,16,15,minecraft:blackstone)
B(7,16,15,minecraft:blackstone)
B(8,16,15,minecraft:blackstone)
B(9,16,15,minecraft:blackstone)
B(10,16,15,minecraft:blackstone)
B(11,16,15,minecraft:blackstone)
B(12,16,15,minecraft:blackstone)
B(13,16,15,minecraft:blackstone)
B(14,16,15,minecraft:blackstone)
B(15,16,15,minecraft:blackstone)
B(0,17,4,minecraft:blackstone)
B(0,17,5,minecraft:blackstone)
B(1,17,5,minecraft:blackstone)
B(2,17,5,minecraft:blackstone)
B(0,17,6,minecraft:blackstone)
B(1,17,6,minecraft:blackstone)
B(2,17,6,minecraft:blackstone)
B(3,17,6,minecraft:blackstone)
B(4,17,6,minecraft:blackstone)
B(0,17,7,minecraft:blackstone)
B(1,17,7,minecraft:blackstone)
B(2,17,7,minecraft:blackstone)
B(3,17,7,minecraft:blackstone)
B(4,17,7,minecraft:blackstone)
B(5,17,7,minecraft:blackstone)
B(0,17,8,minecraft:blackstone)
B(1,17,8,minecraft:blackstone)
B(2,17,8,minecraft:blackstone)
B(3,17,8,minecraft:blackstone)
B(4,17,8,minecraft:blackstone)
B(5,17,8,minecraft:blackstone)
B(6,17,8,minecraft:blackstone)
B(7,17,8,minecraft:blackstone)
B(8,17,8,minecraft:blackstone)
B(0,17,9,minecraft:blackstone)
B(1,17,9,minecraft:blackstone)
B(2,17,9,minecraft:blackstone)
B(3,17,9,minecraft:blackstone)
B(4,17,9,minecraft:blackstone)
B(5,17,9,minecraft:blackstone)
B(6,17,9,minecraft:blackstone)
B(7,17,9,minecraft:blackstone)
B(8,17,9,minecraft:blackstone)
B(9,17,9,minecraft:blackstone)
B(0,17,10,minecraft:blackstone)
B(1,17,10,minecraft:blackstone)
B(2,17,10,minecraft:blackstone)
B(3,17,10,minecraft:blackstone)
B(4,17,10,minecraft:blackstone)
B(5,17,10,minecraft:blackstone)
B(6,17,10,minecraft:blackstone)
B(7,17,10,minecraft:blackstone)
B(8,17,10,minecraft:blackstone)
B(9,17,10,minecraft:blackstone)
B(10,17,10,minecraft:blackstone)
B(11,17,10,minecraft:blackstone)
B(12,17,10,minecraft:blackstone)
B(13,17,10,minecraft:blackstone)
B(14,17,10,minecraft:blackstone)
B(0,17,11,minecraft:blackstone)
B(1,17,11,minecraft:blackstone)
B(2,17,11,minecraft:blackstone)
B(3,17,11,minecraft:blackstone)
B(4,17,11,minecraft:blackstone)
B(5,17,11,minecraft:blackstone)
B(6,17,11,minecraft:blackstone)
B(7,17,11,minecraft:blackstone)
B(8,17,11,minecraft:blackstone)
B(9,17,11,minecraft:blackstone)
B(10,17,11,minecraft:blackstone)
B(11,17,11,minecraft:blackstone)
B(12,17,11,minecraft:blackstone)
B(13,17,11,minecraft:blackstone)
B(14,17,11,minecraft:blackstone)
B(15,17,11,minecraft:blackstone)
B(0,17,12,minecraft:blackstone)
B(1,17,12,minecraft:blackstone)
B(2,17,12,minecraft:blackstone)
B(3,17,12,minecraft:blackstone)
B(4,17,12,minecraft:blackstone)
B(5,17,12,minecraft:blackstone)
B(6,17,12,minecraft:blackstone)
B(7,17,12,minecraft:blackstone)
B(8,17,12,minecraft:blackstone)
B(9,17,12,minecraft:blackstone)
B(10,17,12,minecraft:blackstone)
B(11,17,12,minecraft:blackstone)
B(12,17,12,minecraft:blackstone)
B(13,17,12,minecraft:blackstone)
B(14,17,12,minecraft:blackstone)
B(15,17,12,minecraft:blackstone)
B(0,17,13,minecraft:blackstone)
B(1,17,13,minecraft:blackstone)
B(2,17,13,minecraft:blackstone)
B(3,17,13,minecraft:blackstone)
B(4,17,13,minecraft:blackstone)
B(5,17,13,minecraft:blackstone)
B(6,17,13,minecraft:blackstone)
B(7,17,13,minecraft:blackstone)
B(8,17,13,minecraft:blackstone)
B(9,17,13,minecraft:blackstone)
B(10,17,13,minecraft:blackstone)
B(11,17,13,minecraft:blackstone)
B(12,17,13,minecraft:blackstone)
B(13,17,13,minecraft:blackstone)
B(14,17,13,minecraft:blackstone)
B(15,17,13,minecraft:blackstone)
B(0,17,14,minecraft:blackstone)
B(1,17,14,minecraft:blackstone)
B(2,17,14,minecraft:blackstone)
B(3,17,14,minecraft:blackstone)
B(4,17,14,minecraft:blackstone)
B(5,17,14,minecraft:blackstone)
B(6,17,14,minecraft:blackstone)
B(7,17,14,minecraft:blackstone)
B(8,17,14,minecraft:blackstone)
B(9,17,14,minecraft:blackstone)
B(10,17,14,minecraft:blackstone)
B(11,17,14,minecraft:blackstone)
B(12,17,14,minecraft:blackstone)
B(13,17,14,minecraft:blackstone)
B(14,17,14,minecraft:blackstone)
B(15,17,14,minecraft:blackstone)
B(1,17,15,minecraft:blackstone)
B(2,17,15,minecraft:blackstone)
B(3,17,15,minecraft:blackstone)
B(4,17,15,minecraft:blackstone)
B(5,17,15,minecraft:blackstone)
B(6,17,15,minecraft:blackstone)
B(7,17,15,minecraft:blackstone)
B(8,17,15,minecraft:blackstone)
B(9,17,15,minecraft:blackstone)
B(10,17,15,minecraft:blackstone)
B(11,17,15,minecraft:blackstone)
B(12,17,15,minecraft:blackstone)
B(13,17,15,minecraft:blackstone)
B(14,17,15,minecraft:blackstone)
B(15,17,15,minecraft:blackstone)
B(0,18,4,minecraft:blackstone)
B(0,18,5,minecraft:blackstone)
B(1,18,5,minecraft:blackstone)
B(0,18,6,minecraft:blackstone)
B(1,18,6,minecraft:blackstone)
B(2,18,6,minecraft:blackstone)
B(3,18,6,minecraft:blackstone)
B(4,18,6,minecraft:blackstone)
B(0,18,7,minecraft:blackstone)
B(1,18,7,minecraft:blackstone)
B(2,18,7,minecraft:blackstone)
B(3,18,7,minecraft:blackstone)
B(4,18,7,minecraft:blackstone)
B(5,18,7,minecraft:blackstone)
B(0,18,8,minecraft:blackstone)
B(1,18,8,minecraft:blackstone)
B(2,18,8,minecraft:blackstone)
B(3,18,8,minecraft:blackstone)
B(4,18,8,minecraft:blackstone)
B(5,18,8,minecraft:blackstone)
B(6,18,8,minecraft:blackstone)
B(7,18,8,minecraft:blackstone)
B(8,18,8,minecraft:blackstone)
B(0,18,9,minecraft:blackstone)
B(1,18,9,minecraft:blackstone)
B(2,18,9,minecraft:blackstone)
B(3,18,9,minecraft:blackstone)
B(4,18,9,minecraft:blackstone)
B(5,18,9,minecraft:blackstone)
B(6,18,9,minecraft:blackstone)
B(7,18,9,minecraft:blackstone)
B(8,18,9,minecraft:blackstone)
B(9,18,9,minecraft:blackstone)
B(0,18,10,minecraft:blackstone)
B(1,18,10,minecraft:blackstone)
B(2,18,10,minecraft:blackstone)
B(3,18,10,minecraft:blackstone)
B(4,18,10,minecraft:blackstone)
B(5,18,10,minecraft:blackstone)
B(6,18,10,minecraft:blackstone)
B(7,18,10,minecraft:blackstone)
B(8,18,10,minecraft:blackstone)
B(9,18,10,minecraft:blackstone)
B(10,18,10,minecraft:blackstone)
B(11,18,10,minecraft:blackstone)
B(12,18,10,minecraft:blackstone)
B(13,18,10,minecraft:blackstone)
B(14,18,10,minecraft:blackstone)
B(0,18,11,minecraft:blackstone)
B(1,18,11,minecraft:blackstone)
B(2,18,11,minecraft:blackstone)
B(3,18,11,minecraft:blackstone)
B(4,18,11,minecraft:blackstone)
B(5,18,11,minecraft:blackstone)
B(6,18,11,minecraft:blackstone)
B(7,18,11,minecraft:blackstone)
B(8,18,11,minecraft:blackstone)
B(9,18,11,minecraft:blackstone)
B(10,18,11,minecraft:blackstone)
B(11,18,11,minecraft:blackstone)
B(12,18,11,minecraft:blackstone)
B(13,18,11,minecraft:blackstone)
B(14,18,11,minecraft:blackstone)
B(15,18,11,minecraft:blackstone)
B(0,18,12,minecraft:blackstone)
B(1,18,12,minecraft:blackstone)
B(2,18,12,minecraft:blackstone)
B(3,18,12,minecraft:blackstone)
B(4,18,12,minecraft:blackstone)
B(5,18,12,minecraft:blackstone)
B(6,18,12,minecraft:blackstone)
B(7,18,12,minecraft:blackstone)
B(8,18,12,minecraft:blackstone)
B(9,18,12,minecraft:blackstone)
B(10,18,12,minecraft:blackstone)
B(11,18,12,minecraft:blackstone)
B(12,18,12,minecraft:blackstone)
B(13,18,12,minecraft:blackstone)
B(14,18,12,minecraft:blackstone)
B(15,18,12,minecraft:blackstone)
B(0,18,13,minecraft:blackstone)
B(1,18,13,minecraft:blackstone)
B(2,18,13,minecraft:blackstone)
B(3,18,13,minecraft:blackstone)
B(4,18,13,minecraft:blackstone)
B(5,18,13,minecraft:blackstone)
B(6,18,13,minecraft:blackstone)
B(7,18,13,minecraft:blackstone)
B(8,18,13,minecraft:blackstone)
B(9,18,13,minecraft:blackstone)
B(10,18,13,minecraft:blackstone)
B(11,18,13,minecraft:blackstone)
B(12,18,13,minecraft:blackstone)
B(13,18,13,minecraft:blackstone)
B(14,18,13,minecraft:blackstone)
B(15,18,13,minecraft:blackstone)
B(0,18,14,minecraft:blackstone)
B(1,18,14,minecraft:blackstone)
B(2,18,14,minecraft:blackstone)
B(3,18,14,minecraft:blackstone)
B(4,18,14,minecraft:blackstone)
B(5,18,14,minecraft:blackstone)
B(6,18,14,minecraft:blackstone)
B(7,18,14,minecraft:blackstone)
B(8,18,14,minecraft:blackstone)
B(9,18,14,minecraft:blackstone)
B(10,18,14,minecraft:blackstone)
B(11,18,14,minecraft:blackstone)
B(12,18,14,minecraft:blackstone)
B(13,18,14,minecraft:blackstone)
B(14,18,14,minecraft:blackstone)
B(15,18,14,minecraft:blackstone)
B(2,18,15,minecraft:blackstone)
B(3,18,15,minecraft:blackstone)
B(4,18,15,minecraft:blackstone)
B(5,18,15,minecraft:blackstone)
B(6,18,15,minecraft:blackstone)
B(7,18,15,minecraft:blackstone)
B(8,18,15,minecraft:blackstone)
B(9,18,15,minecraft:blackstone)
B(10,18,15,minecraft:blackstone)
B(11,18,15,minecraft:blackstone)
B(12,18,15,minecraft:blackstone)
B(13,18,15,minecraft:blackstone)
B(14,18,15,minecraft:blackstone)
B(15,18,15,minecraft:blackstone)
B(0,19,4,minecraft:blackstone)
B(0,19,5,minecraft:blackstone)
B(1,19,5,minecraft:blackstone)
B(0,19,6,minecraft:blackstone)
B(1,19,6,minecraft:blackstone)
B(2,19,6,minecraft:blackstone)
B(3,19,6,minecraft:blackstone)
B(4,19,6,minecraft:blackstone)
B(0,19,7,minecraft:blackstone)
B(1,19,7,minecraft:blackstone)
B(2,19,7,minecraft:blackstone)
B(3,19,7,minecraft:blackstone)
B(4,19,7,minecraft:blackstone)
B(5,19,7,minecraft:blackstone)
B(0,19,8,minecraft:blackstone)
B(1,19,8,minecraft:blackstone)
B(2,19,8,minecraft:blackstone)
B(3,19,8,minecraft:blackstone)
B(4,19,8,minecraft:blackstone)
B(5,19,8,minecraft:blackstone)
B(6,19,8,minecraft:blackstone)
B(7,19,8,minecraft:blackstone)
B(8,19,8,minecraft:blackstone)
B(0,19,9,minecraft:blackstone)
B(1,19,9,minecraft:blackstone)
B(2,19,9,minecraft:blackstone)
B(3,19,9,minecraft:blackstone)
B(4,19,9,minecraft:blackstone)
B(5,19,9,minecraft:blackstone)
B(6,19,9,minecraft:blackstone)
B(7,19,9,minecraft:blackstone)
B(8,19,9,minecraft:blackstone)
B(9,19,9,minecraft:blackstone)
B(0,19,10,minecraft:blackstone)
B(1,19,10,minecraft:blackstone)
B(2,19,10,minecraft:blackstone)
B(3,19,10,minecraft:blackstone)
B(4,19,10,minecraft:blackstone)
B(5,19,10,minecraft:blackstone)
B(6,19,10,minecraft:blackstone)
B(7,19,10,minecraft:blackstone)
B(8,19,10,minecraft:blackstone)
B(9,19,10,minecraft:blackstone)
B(10,19,10,minecraft:blackstone)
B(11,19,10,minecraft:blackstone)
B(12,19,10,minecraft:blackstone)
B(13,19,10,minecraft:blackstone)
B(14,19,10,minecraft:blackstone)
B(0,19,11,minecraft:blackstone)
B(1,19,11,minecraft:blackstone)
B(2,19,11,minecraft:blackstone)
B(3,19,11,minecraft:blackstone)
B(4,19,11,minecraft:blackstone)
B(5,19,11,minecraft:blackstone)
B(6,19,11,minecraft:blackstone)
B(7,19,11,minecraft:blackstone)
B(8,19,11,minecraft:blackstone)
B(9,19,11,minecraft:blackstone)
B(10,19,11,minecraft:blackstone)
B(11,19,11,minecraft:blackstone)
B(12,19,11,minecraft:blackstone)
B(13,19,11,minecraft:blackstone)
B(14,19,11,minecraft:blackstone)
B(15,19,11,minecraft:blackstone)
B(0,19,12,minecraft:blackstone)
B(1,19,12,minecraft:blackstone)
B(2,19,12,minecraft:blackstone)
B(3,19,12,minecraft:blackstone)
B(4,19,12,minecraft:blackstone)
B(5,19,12,minecraft:blackstone)
B(6,19,12,minecraft:blackstone)
B(7,19,12,minecraft:blackstone)
B(8,19,12,minecraft:blackstone)
B(9,19,12,minecraft:blackstone)
B(10,19,12,minecraft:blackstone)
B(11,19,12,minecraft:blackstone)
B(12,19,12,minecraft:blackstone)
B(13,19,12,minecraft:blackstone)
B(14,19,12,minecraft:blackstone)
B(15,19,12,minecraft:blackstone)
B(0,19,13,minecraft:blackstone)
B(1,19,13,minecraft:blackstone)
B(2,19,13,minecraft:blackstone)
B(3,19,13,minecraft:blackstone)
B(4,19,13,minecraft:blackstone)
B(5,19,13,minecraft:blackstone)
B(6,19,13,minecraft:blackstone)
B(7,19,13,minecraft:blackstone)
B(8,19,13,minecraft:blackstone)
B(9,19,13,minecraft:blackstone)
B(10,19,13,minecraft:blackstone)
B(11,19,13,minecraft:blackstone)
B(12,19,13,minecraft:blackstone)
B(13,19,13,minecraft:blackstone)
B(14,19,13,minecraft:blackstone)
B(15,19,13,minecraft:blackstone)
B(0,19,14,minecraft:blackstone)
B(1,19,14,minecraft:blackstone)
B(2,19,14,minecraft:blackstone)
B(3,19,14,minecraft:blackstone)
B(4,19,14,minecraft:blackstone)
B(5,19,14,minecraft:blackstone)
B(6,19,14,minecraft:blackstone)
B(7,19,14,minecraft:blackstone)
B(8,19,14,minecraft:blackstone)
B(9,19,14,minecraft:blackstone)
B(10,19,14,minecraft:blackstone)
B(11,19,14,minecraft:blackstone)
B(12,19,14,minecraft:blackstone)
B(13,19,14,minecraft:blackstone)
B(14,19,14,minecraft:blackstone)
B(15,19,14,minecraft:blackstone)
B(2,19,15,minecraft:blackstone)
B(3,19,15,minecraft:blackstone)
B(4,19,15,minecraft:blackstone)
B(5,19,15,minecraft:blackstone)
B(6,19,15,minecraft:blackstone)
B(7,19,15,minecraft:blackstone)
B(8,19,15,minecraft:blackstone)
B(9,19,15,minecraft:blackstone)
B(10,19,15,minecraft:blackstone)
B(11,19,15,minecraft:blackstone)
B(12,19,15,minecraft:blackstone)
B(13,19,15,minecraft:blackstone)
B(14,19,15,minecraft:blackstone)
B(15,19,15,minecraft:blackstone)
B(0,20,4,minecraft:blackstone)
B(0,20,5,minecraft:blackstone)
B(1,20,5,minecraft:blackstone)
B(0,20,6,minecraft:blackstone)
B(1,20,6,minecraft:blackstone)
B(2,20,6,minecraft:blackstone)
B(3,20,6,minecraft:blackstone)
B(4,20,6,minecraft:blackstone)
B(0,20,7,minecraft:blackstone)
B(1,20,7,minecraft:blackstone)
B(2,20,7,minecraft:blackstone)
B(3,20,7,minecraft:blackstone)
B(4,20,7,minecraft:blackstone)
B(5,20,7,minecraft:blackstone)
B(0,20,8,minecraft:blackstone)
B(1,20,8,minecraft:blackstone)
B(2,20,8,minecraft:blackstone)
B(3,20,8,minecraft:blackstone)
B(4,20,8,minecraft:blackstone)
B(5,20,8,minecraft:blackstone)
B(6,20,8,minecraft:blackstone)
B(7,20,8,minecraft:blackstone)
B(8,20,8,minecraft:blackstone)
B(0,20,9,minecraft:blackstone)
B(1,20,9,minecraft:blackstone)
B(2,20,9,minecraft:blackstone)
B(3,20,9,minecraft:blackstone)
B(4,20,9,minecraft:blackstone)
B(5,20,9,minecraft:blackstone)
B(6,20,9,minecraft:blackstone)
B(7,20,9,minecraft:blackstone)
B(8,20,9,minecraft:blackstone)
B(9,20,9,minecraft:blackstone)
B(0,20,10,minecraft:blackstone)
B(1,20,10,minecraft:blackstone)
B(2,20,10,minecraft:blackstone)
B(3,20,10,minecraft:blackstone)
B(4,20,10,minecraft:blackstone)
B(5,20,10,minecraft:blackstone)
B(6,20,10,minecraft:blackstone)
B(7,20,10,minecraft:blackstone)
B(8,20,10,minecraft:blackstone)
B(9,20,10,minecraft:blackstone)
B(10,20,10,minecraft:blackstone)
B(11,20,10,minecraft:blackstone)
B(12,20,10,minecraft:blackstone)
B(13,20,10,minecraft:blackstone)
B(14,20,10,minecraft:blackstone)
B(0,20,11,minecraft:blackstone)
B(1,20,11,minecraft:blackstone)
B(2,20,11,minecraft:blackstone)
B(3,20,11,minecraft:blackstone)
B(4,20,11,minecraft:blackstone)
B(5,20,11,minecraft:blackstone)
B(6,20,11,minecraft:blackstone)
B(7,20,11,minecraft:blackstone)
B(8,20,11,minecraft:blackstone)
B(9,20,11,minecraft:blackstone)
B(10,20,11,minecraft:blackstone)
B(11,20,11,minecraft:blackstone)
B(12,20,11,minecraft:blackstone)
B(13,20,11,minecraft:blackstone)
B(14,20,11,minecraft:blackstone)
B(15,20,11,minecraft:blackstone)
B(0,20,12,minecraft:blackstone)
B(1,20,12,minecraft:blackstone)
B(2,20,12,minecraft:blackstone)
B(3,20,12,minecraft:blackstone)
B(4,20,12,minecraft:blackstone)
B(5,20,12,minecraft:blackstone)
B(6,20,12,minecraft:blackstone)
B(7,20,12,minecraft:blackstone)
B(8,20,12,minecraft:blackstone)
B(9,20,12,minecraft:blackstone)
B(10,20,12,minecraft:blackstone)
B(11,20,12,minecraft:blackstone)
B(12,20,12,minecraft:blackstone)
B(13,20,12,minecraft:blackstone)
B(14,20,12,minecraft:blackstone)
B(15,20,12,minecraft:blackstone)
B(0,20,13,minecraft:blackstone)
B(1,20,13,minecraft:blackstone)
B(2,20,13,minecraft:blackstone)
B(3,20,13,minecraft:blackstone)
B(4,20,13,minecraft:blackstone)
B(5,20,13,minecraft:blackstone)
B(6,20,13,minecraft:blackstone)
B(7,20,13,minecraft:blackstone)
B(8,20,13,minecraft:blackstone)
B(9,20,13,minecraft:blackstone)
B(10,20,13,minecraft:blackstone)
B(11,20,13,minecraft:blackstone)
B(12,20,13,minecraft:blackstone)
B(13,20,13,minecraft:blackstone)
B(14,20,13,minecraft:blackstone)
B(15,20,13,minecraft:blackstone)
B(0,20,14,minecraft:blackstone)
B(1,20,14,minecraft:blackstone)
B(2,20,14,minecraft:blackstone)
B(3,20,14,minecraft:blackstone)
B(4,20,14,minecraft:blackstone)
B(5,20,14,minecraft:blackstone)
B(6,20,14,minecraft:blackstone)
B(7,20,14,minecraft:blackstone)
B(8,20,14,minecraft:blackstone)
B(9,20,14,minecraft:blackstone)
B(10,20,14,minecraft:blackstone)
B(11,20,14,minecraft:blackstone)
B(12,20,14,minecraft:blackstone)
B(13,20,14,minecraft:blackstone)
B(14,20,14,minecraft:blackstone)
B(15,20,14,minecraft:blackstone)
B(2,20,15,minecraft:blackstone)
B(3,20,15,minecraft:blackstone)
B(4,20,15,minecraft:blackstone)
B(5,20,15,minecraft:blackstone)
B(6,20,15,minecraft:blackstone)
B(7,20,15,minecraft:blackstone)
B(8,20,15,minecraft:blackstone)
B(9,20,15,minecraft:blackstone)
B(10,20,15,minecraft:blackstone)
B(11,20,15,minecraft:blackstone)
B(12,20,15,minecraft:blackstone)
B(13,20,15,minecraft:blackstone)
B(14,20,15,minecraft:blackstone)
B(15,20,15,minecraft:blackstone)
B(0,21,4,minecraft:blackstone)
B(0,21,5,minecraft:blackstone)
B(1,21,5,minecraft:blackstone)
B(0,21,6,minecraft:blackstone)
B(1,21,6,minecraft:blackstone)
B(2,21,6,minecraft:blackstone)
B(3,21,6,minecraft:blackstone)
B(4,21,6,minecraft:blackstone)
B(0,21,7,minecraft:blackstone)
B(1,21,7,minecraft:blackstone)
B(2,21,7,minecraft:blackstone)
B(3,21,7,minecraft:blackstone)
B(4,21,7,minecraft:blackstone)
B(5,21,7,minecraft:blackstone)
B(0,21,8,minecraft:blackstone)
B(1,21,8,minecraft:blackstone)
B(2,21,8,minecraft:blackstone)
B(3,21,8,minecraft:blackstone)
B(4,21,8,minecraft:blackstone)
B(5,21,8,minecraft:blackstone)
B(6,21,8,minecraft:blackstone)
B(7,21,8,minecraft:blackstone)
B(8,21,8,minecraft:blackstone)
B(0,21,9,minecraft:blackstone)
B(1,21,9,minecraft:blackstone)
B(2,21,9,minecraft:blackstone)
B(3,21,9,minecraft:blackstone)
B(4,21,9,minecraft:blackstone)
B(5,21,9,minecraft:blackstone)
B(6,21,9,minecraft:blackstone)
B(7,21,9,minecraft:blackstone)
B(8,21,9,minecraft:blackstone)
B(9,21,9,minecraft:blackstone)
B(0,21,10,minecraft:blackstone)
B(1,21,10,minecraft:blackstone)
B(2,21,10,minecraft:blackstone)
B(3,21,10,minecraft:blackstone)
B(4,21,10,minecraft:blackstone)
B(5,21,10,minecraft:blackstone)
B(6,21,10,minecraft:blackstone)
B(7,21,10,minecraft:blackstone)
B(8,21,10,minecraft:blackstone)
B(9,21,10,minecraft:blackstone)
B(10,21,10,minecraft:blackstone)
B(11,21,10,minecraft:blackstone)
B(12,21,10,minecraft:blackstone)
B(13,21,10,minecraft:blackstone)
B(14,21,10,minecraft:blackstone)
B(0,21,11,minecraft:blackstone)
B(1,21,11,minecraft:blackstone)
B(2,21,11,minecraft:blackstone)
B(3,21,11,minecraft:blackstone)
B(4,21,11,minecraft:blackstone)
B(5,21,11,minecraft:blackstone)
B(6,21,11,minecraft:blackstone)
B(7,21,11,minecraft:blackstone)
B(8,21,11,minecraft:blackstone)
B(9,21,11,minecraft:blackstone)
B(10,21,11,minecraft:blackstone)
B(11,21,11,minecraft:blackstone)
B(12,21,11,minecraft:blackstone)
B(13,21,11,minecraft:blackstone)
B(14,21,11,minecraft:blackstone)
B(15,21,11,minecraft:blackstone)
B(0,21,12,minecraft:blackstone)
B(1,21,12,minecraft:blackstone)
B(2,21,12,minecraft:blackstone)
B(3,21,12,minecraft:blackstone)
B(4,21,12,minecraft:blackstone)
B(5,21,12,minecraft:blackstone)
B(6,21,12,minecraft:blackstone)
B(7,21,12,minecraft:blackstone)
B(8,21,12,minecraft:blackstone)
B(9,21,12,minecraft:blackstone)
B(10,21,12,minecraft:blackstone)
B(11,21,12,minecraft:blackstone)
B(12,21,12,minecraft:blackstone)
B(13,21,12,minecraft:blackstone)
B(14,21,12,minecraft:blackstone)
B(15,21,12,minecraft:blackstone)
B(0,21,13,minecraft:blackstone)
B(1,21,13,minecraft:blackstone)
B(2,21,13,minecraft:blackstone)
B(3,21,13,minecraft:blackstone)
B(4,21,13,minecraft:blackstone)
B(5,21,13,minecraft:blackstone)
B(6,21,13,minecraft:blackstone)
B(7,21,13,minecraft:blackstone)
B(8,21,13,minecraft:blackstone)
B(9,21,13,minecraft:blackstone)
B(10,21,13,minecraft:blackstone)
B(11,21,13,minecraft:blackstone)
B(12,21,13,minecraft:blackstone)
B(13,21,13,minecraft:blackstone)
B(14,21,13,minecraft:blackstone)
B(15,21,13,minecraft:blackstone)
B(0,21,14,minecraft:blackstone)
B(1,21,14,minecraft:blackstone)
B(2,21,14,minecraft:blackstone)
B(3,21,14,minecraft:blackstone)
B(4,21,14,minecraft:blackstone)
B(5,21,14,minecraft:blackstone)
B(6,21,14,minecraft:blackstone)
B(7,21,14,minecraft:blackstone)
B(8,21,14,minecraft:blackstone)
B(9,21,14,minecraft:blackstone)
B(10,21,14,minecraft:blackstone)
B(11,21,14,minecraft:blackstone)
B(12,21,14,minecraft:blackstone)
B(13,21,14,minecraft:blackstone)
B(14,21,14,minecraft:blackstone)
B(15,21,14,minecraft:blackstone)
B(2,21,15,minecraft:blackstone)
B(3,21,15,minecraft:blackstone)
B(4,21,15,minecraft:blackstone)
B(5,21,15,minecraft:blackstone)
B(6,21,15,minecraft:blackstone)
B(7,21,15,minecraft:blackstone)
B(8,21,15,minecraft:blackstone)
B(9,21,15,minecraft:blackstone)
B(10,21,15,minecraft:blackstone)
B(11,21,15,minecraft:blackstone)
B(12,21,15,minecraft:blackstone)
B(13,21,15,minecraft:blackstone)
B(14,21,15,minecraft:blackstone)
B(15,21,15,minecraft:blackstone)
B(0,22,4,minecraft:blackstone)
B(0,22,5,minecraft:blackstone)
B(1,22,5,minecraft:blackstone)
B(0,22,6,minecraft:blackstone)
B(1,22,6,minecraft:blackstone)
B(2,22,6,minecraft:blackstone)
B(3,22,6,minecraft:blackstone)
B(4,22,6,minecraft:blackstone)
B(0,22,7,minecraft:blackstone)
B(1,22,7,minecraft:blackstone)
B(2,22,7,minecraft:blackstone)
B(3,22,7,minecraft:blackstone)
B(4,22,7,minecraft:blackstone)
B(5,22,7,minecraft:blackstone)
B(0,22,8,minecraft:blackstone)
B(1,22,8,minecraft:blackstone)
B(2,22,8,minecraft:blackstone)
B(3,22,8,minecraft:blackstone)
B(4,22,8,minecraft:blackstone)
B(5,22,8,minecraft:blackstone)
B(6,22,8,minecraft:blackstone)
B(7,22,8,minecraft:blackstone)
B(8,22,8,minecraft:blackstone)
B(0,22,9,minecraft:blackstone)
B(1,22,9,minecraft:blackstone)
B(2,22,9,minecraft:blackstone)
B(3,22,9,minecraft:blackstone)
B(4,22,9,minecraft:blackstone)
B(5,22,9,minecraft:blackstone)
B(6,22,9,minecraft:blackstone)
B(7,22,9,minecraft:blackstone)
B(8,22,9,minecraft:blackstone)
B(9,22,9,minecraft:blackstone)
B(0,22,10,minecraft:blackstone)
B(1,22,10,minecraft:blackstone)
B(2,22,10,minecraft:blackstone)
B(3,22,10,minecraft:blackstone)
B(4,22,10,minecraft:blackstone)
B(5,22,10,minecraft:blackstone)
B(6,22,10,minecraft:blackstone)
B(7,22,10,minecraft:blackstone)
B(8,22,10,minecraft:blackstone)
B(9,22,10,minecraft:blackstone)
B(10,22,10,minecraft:blackstone)
B(11,22,10,minecraft:blackstone)
B(12,22,10,minecraft:blackstone)
B(13,22,10,minecraft:blackstone)
B(14,22,10,minecraft:blackstone)
B(0,22,11,minecraft:blackstone)
B(1,22,11,minecraft:blackstone)
B(2,22,11,minecraft:blackstone)
B(3,22,11,minecraft:blackstone)
B(4,22,11,minecraft:blackstone)
B(5,22,11,minecraft:blackstone)
B(6,22,11,minecraft:blackstone)
B(7,22,11,minecraft:blackstone)
B(8,22,11,minecraft:blackstone)
B(9,22,11,minecraft:blackstone)
B(10,22,11,minecraft:blackstone)
B(11,22,11,minecraft:blackstone)
B(12,22,11,minecraft:blackstone)
B(13,22,11,minecraft:blackstone)
B(14,22,11,minecraft:blackstone)
B(15,22,11,minecraft:blackstone)
B(0,22,12,minecraft:blackstone)
B(1,22,12,minecraft:blackstone)
B(2,22,12,minecraft:blackstone)
B(3,22,12,minecraft:blackstone)
B(4,22,12,minecraft:blackstone)
B(5,22,12,minecraft:blackstone)
B(6,22,12,minecraft:blackstone)
B(7,22,12,minecraft:blackstone)
B(8,22,12,minecraft:blackstone)
B(9,22,12,minecraft:blackstone)
B(10,22,12,minecraft:blackstone)
B(11,22,12,minecraft:blackstone)
B(12,22,12,minecraft:blackstone)
B(13,22,12,minecraft:blackstone)
B(14,22,12,minecraft:blackstone)
B(15,22,12,minecraft:blackstone)
B(0,22,13,minecraft:blackstone)
B(1,22,13,minecraft:blackstone)
B(2,22,13,minecraft:blackstone)
B(3,22,13,minecraft:blackstone)
B(4,22,13,minecraft:blackstone)
B(5,22,13,minecraft:blackstone)
B(6,22,13,minecraft:blackstone)
B(7,22,13,minecraft:blackstone)
B(8,22,13,minecraft:blackstone)
B(9,22,13,minecraft:blackstone)
B(10,22,13,minecraft:blackstone)
B(11,22,13,minecraft:blackstone)
B(12,22,13,minecraft:blackstone)
B(13,22,13,minecraft:blackstone)
B(14,22,13,minecraft:blackstone)
B(15,22,13,minecraft:blackstone)
B(0,22,14,minecraft:blackstone)
B(1,22,14,minecraft:blackstone)
B(2,22,14,minecraft:blackstone)
B(3,22,14,minecraft:blackstone)
B(4,22,14,minecraft:blackstone)
B(5,22,14,minecraft:blackstone)
B(6,22,14,minecraft:blackstone)
B(7,22,14,minecraft:blackstone)
B(8,22,14,minecraft:blackstone)
B(9,22,14,minecraft:blackstone)
B(10,22,14,minecraft:blackstone)
B(11,22,14,minecraft:blackstone)
B(12,22,14,minecraft:blackstone)
B(13,22,14,minecraft:blackstone)
B(14,22,14,minecraft:blackstone)
B(15,22,14,minecraft:blackstone)
B(2,22,15,minecraft:blackstone)
B(3,22,15,minecraft:blackstone)
B(4,22,15,minecraft:blackstone)
B(5,22,15,minecraft:blackstone)
B(6,22,15,minecraft:blackstone)
B(7,22,15,minecraft:blackstone)
B(8,22,15,minecraft:blackstone)
B(9,22,15,minecraft:blackstone)
B(10,22,15,minecraft:blackstone)
B(11,22,15,minecraft:blackstone)
B(12,22,15,minecraft:blackstone)
B(13,22,15,minecraft:blackstone)
B(14,22,15,minecraft:blackstone)
B(15,22,15,minecraft:blackstone)
B(0,23,4,minecraft:blackstone)
B(0,23,5,minecraft:blackstone)
B(1,23,5,minecraft:blackstone)
B(0,23,6,minecraft:blackstone)
B(1,23,6,minecraft:blackstone)
B(2,23,6,minecraft:blackstone)
B(3,23,6,minecraft:blackstone)
B(4,23,6,minecraft:blackstone)
B(0,23,7,minecraft:blackstone)
B(1,23,7,minecraft:blackstone)
B(2,23,7,minecraft:blackstone)
B(3,23,7,minecraft:blackstone)
B(4,23,7,minecraft:blackstone)
B(5,23,7,minecraft:blackstone)
B(0,23,8,minecraft:blackstone)
B(1,23,8,minecraft:blackstone)
B(2,23,8,minecraft:blackstone)
B(3,23,8,minecraft:blackstone)
B(4,23,8,minecraft:blackstone)
B(5,23,8,minecraft:blackstone)
B(6,23,8,minecraft:blackstone)
B(7,23,8,minecraft:blackstone)
B(8,23,8,minecraft:blackstone)
B(0,23,9,minecraft:blackstone)
B(1,23,9,minecraft:blackstone)
B(2,23,9,minecraft:blackstone)
B(3,23,9,minecraft:blackstone)
B(4,23,9,minecraft:blackstone)
B(5,23,9,minecraft:blackstone)
B(6,23,9,minecraft:blackstone)
B(7,23,9,minecraft:blackstone)
B(8,23,9,minecraft:blackstone)
B(9,23,9,minecraft:blackstone)
B(0,23,10,minecraft:blackstone)
B(1,23,10,minecraft:blackstone)
B(2,23,10,minecraft:blackstone)
B(3,23,10,minecraft:blackstone)
B(4,23,10,minecraft:blackstone)
B(5,23,10,minecraft:blackstone)
B(6,23,10,minecraft:blackstone)
B(7,23,10,minecraft:blackstone)
B(8,23,10,minecraft:blackstone)
B(9,23,10,minecraft:blackstone)
B(10,23,10,minecraft:blackstone)
B(11,23,10,minecraft:blackstone)
B(12,23,10,minecraft:blackstone)
B(13,23,10,minecraft:blackstone)
B(14,23,10,minecraft:blackstone)
B(0,23,11,minecraft:blackstone)
B(1,23,11,minecraft:blackstone)
B(2,23,11,minecraft:blackstone)
B(3,23,11,minecraft:blackstone)
B(4,23,11,minecraft:blackstone)
B(5,23,11,minecraft:blackstone)
B(6,23,11,minecraft:blackstone)
B(7,23,11,minecraft:blackstone)
B(8,23,11,minecraft:blackstone)
B(9,23,11,minecraft:blackstone)
B(10,23,11,minecraft:blackstone)
B(11,23,11,minecraft:blackstone)
B(12,23,11,minecraft:blackstone)
B(13,23,11,minecraft:blackstone)
B(14,23,11,minecraft:blackstone)
B(15,23,11,minecraft:blackstone)
B(0,23,12,minecraft:blackstone)
B(1,23,12,minecraft:blackstone)
B(2,23,12,minecraft:blackstone)
B(3,23,12,minecraft:blackstone)
B(4,23,12,minecraft:blackstone)
B(5,23,12,minecraft:blackstone)
B(6,23,12,minecraft:blackstone)
B(7,23,12,minecraft:blackstone)
B(8,23,12,minecraft:blackstone)
B(9,23,12,minecraft:blackstone)
B(10,23,12,minecraft:blackstone)
B(11,23,12,minecraft:blackstone)
B(12,23,12,minecraft:blackstone)
B(13,23,12,minecraft:blackstone)
B(14,23,12,minecraft:blackstone)
B(15,23,12,minecraft:blackstone)
B(0,23,13,minecraft:blackstone)
B(1,23,13,minecraft:blackstone)
B(2,23,13,minecraft:blackstone)
B(3,23,13,minecraft:blackstone)
B(4,23,13,minecraft:blackstone)
B(5,23,13,minecraft:blackstone)
B(6,23,13,minecraft:blackstone)
B(7,23,13,minecraft:blackstone)
B(8,23,13,minecraft:blackstone)
B(9,23,13,minecraft:blackstone)
B(10,23,13,minecraft:blackstone)
B(11,23,13,minecraft:blackstone)
B(12,23,13,minecraft:blackstone)
B(13,23,13,minecraft:blackstone)
B(14,23,13,minecraft:blackstone)
B(15,23,13,minecraft:blackstone)
B(0,23,14,minecraft:blackstone)
B(1,23,14,minecraft:blackstone)
B(2,23,14,minecraft:blackstone)
B(3,23,14,minecraft:blackstone)
B(4,23,14,minecraft:blackstone)
B(5,23,14,minecraft:blackstone)
B(6,23,14,minecraft:blackstone)
B(7,23,14,minecraft:blackstone)
B(8,23,14,minecraft:blackstone)
B(9,23,14,minecraft:blackstone)
B(10,23,14,minecraft:blackstone)
B(11,23,14,minecraft:blackstone)
B(12,23,14,minecraft:blackstone)
B(13,23,14,minecraft:blackstone)
B(14,23,14,minecraft:blackstone)
B(15,23,14,minecraft:blackstone)
B(2,23,15,minecraft:blackstone)
B(3,23,15,minecraft:blackstone)
B(4,23,15,minecraft:blackstone)
B(5,23,15,minecraft:blackstone)
B(6,23,15,minecraft:blackstone)
B(7,23,15,minecraft:blackstone)
B(8,23,15,minecraft:blackstone)
B(9,23,15,minecraft:blackstone)
B(10,23,15,minecraft:blackstone)
B(11,23,15,minecraft:blackstone)
B(12,23,15,minecraft:blackstone)
B(13,23,15,minecraft:blackstone)
B(14,23,15,minecraft:blackstone)
B(15,23,15,minecraft:blackstone)
B(0,24,4,minecraft:blackstone)
B(0,24,5,minecraft:blackstone)
B(1,24,5,minecraft:blackstone)
B(0,24,6,minecraft:blackstone)
B(1,24,6,minecraft:blackstone)
B(2,24,6,minecraft:blackstone)
B(3,24,6,minecraft:blackstone)
B(4,24,6,minecraft:blackstone)
B(0,24,7,minecraft:blackstone)
B(1,24,7,minecraft:blackstone)
B(2,24,7,minecraft:blackstone)
B(3,24,7,minecraft:blackstone)
B(4,24,7,minecraft:blackstone)
B(5,24,7,minecraft:blackstone)
B(0,24,8,minecraft:blackstone)
B(1,24,8,minecraft:blackstone)
B(2,24,8,minecraft:blackstone)
B(3,24,8,minecraft:blackstone)
B(4,24,8,minecraft:blackstone)
B(5,24,8,minecraft:blackstone)
B(6,24,8,minecraft:blackstone)
B(7,24,8,minecraft:blackstone)
B(8,24,8,minecraft:blackstone)
B(0,24,9,minecraft:blackstone)
B(1,24,9,minecraft:blackstone)
B(2,24,9,minecraft:blackstone)
B(3,24,9,minecraft:blackstone)
B(4,24,9,minecraft:blackstone)
B(5,24,9,minecraft:blackstone)
B(6,24,9,minecraft:blackstone)
B(7,24,9,minecraft:blackstone)
B(8,24,9,minecraft:blackstone)
B(9,24,9,minecraft:blackstone)
B(0,24,10,minecraft:blackstone)
B(1,24,10,minecraft:blackstone)
B(2,24,10,minecraft:blackstone)
B(3,24,10,minecraft:blackstone)
B(4,24,10,minecraft:blackstone)
B(5,24,10,minecraft:blackstone)
B(6,24,10,minecraft:blackstone)
B(7,24,10,minecraft:blackstone)
B(8,24,10,minecraft:blackstone)
B(9,24,10,minecraft:blackstone)
B(10,24,10,minecraft:blackstone)
B(11,24,10,minecraft:blackstone)
B(12,24,10,minecraft:blackstone)
B(13,24,10,minecraft:blackstone)
B(14,24,10,minecraft:blackstone)
B(0,24,11,minecraft:blackstone)
B(1,24,11,minecraft:blackstone)
B(2,24,11,minecraft:blackstone)
B(3,24,11,minecraft:blackstone)
B(4,24,11,minecraft:blackstone)
B(5,24,11,minecraft:blackstone)
B(6,24,11,minecraft:blackstone)
B(7,24,11,minecraft:blackstone)
B(8,24,11,minecraft:blackstone)
B(9,24,11,minecraft:blackstone)
B(10,24,11,minecraft:blackstone)
B(11,24,11,minecraft:blackstone)
B(12,24,11,minecraft:blackstone)
B(13,24,11,minecraft:blackstone)
B(14,24,11,minecraft:blackstone)
B(15,24,11,minecraft:blackstone)
B(0,24,12,minecraft:blackstone)
B(1,24,12,minecraft:blackstone)
B(2,24,12,minecraft:blackstone)
B(3,24,12,minecraft:blackstone)
B(4,24,12,minecraft:blackstone)
B(5,24,12,minecraft:blackstone)
