
#######################################################################
# +-----------------------------------------------------------------+ #
# |                            BO4 object                           | #
# +-----------------------------------------------------------------+ #
#######################################################################

Author: Unknown

Description: No description given

SettingsMode: WriteWithoutComments


#######################################################################
# +-----------------------------------------------------------------+ #
# |                          Main settings                          | #
# +-----------------------------------------------------------------+ #
#######################################################################

FixedRotation: 

Frequency: 0

SpawnHeight: highestBlock

UseCenterForHighestBlock: true

##############################
# Height Limits for the BO4. #
##############################

MinHeight: 0

MaxHeight: 255

InheritBO3: 

InheritBO3Rotation: NORTH

OverrideChildSettings: true

OverrideParentHeight: false

CanOverride: false

BranchFrequency: 0

BranchFrequencyGroup: 

MustBeBelowOther: false

MustBeInside: 

CannotBeInside: 

ReplacesBO3: 

MustBeInsideWorldBorders: false

CanSpawnOnWater: true

SpawnOnWaterOnly: false

SpawnUnderWater: false

SpawnAtWaterLevel: false

HeightOffset: 0

RemoveAir: true

ReplaceAbove: 

ReplaceBelow: 

ReplaceWithBiomeBlocks: true

ReplaceWithSurfaceBlock: GRASS

ReplaceWithGroundBlock: DIRT

ReplaceWithStoneBlock: STONE

SmoothRadius: 0

SmoothHeightOffset: 0

SmoothStartTop: false

SmoothStartWood: false

SmoothingSurfaceBlock: 

SmoothingGroundBlock: 

BO3Group: 

IsSpawnPoint: false

DoReplaceBlocks: true


#######################################################################
# +-----------------------------------------------------------------+ #
# |                              Blocks                             | #
# +-----------------------------------------------------------------+ #
#######################################################################

B(-8,15,-7,minecraft:nether_wart_block)
B(-8,14,-6,minecraft:nether_wart_block)
B(-8,15,-6,minecraft:nether_wart_block)
B(-8,16,-6,minecraft:nether_wart_block)
B(-8,15,-5,minecraft:nether_wart_block)
B(-7,16,-7,minecraft:nether_wart_block)
B(-7,15,-6,minecraft:nether_wart_block)
B(-7,16,-6,minecraft:nether_wart_block)
B(-7,17,-6,minecraft:nether_wart_block)
B(-7,16,-5,minecraft:nether_wart_block)
B(-6,17,-7,minecraft:nether_wart_block)
B(-6,16,-6,minecraft:nether_wart_block)
B(-6,17,-6,minecraft:nether_wart_block)
B(-6,18,-6,minecraft:nether_wart_block)
B(-6,17,-5,minecraft:nether_wart_block)
B(-5,18,-7,minecraft:nether_wart_block)
B(-5,17,-6,minecraft:nether_wart_block)
B(-5,18,-6,minecraft:nether_wart_block)
B(-5,19,-6,minecraft:nether_wart_block)
B(-5,18,-5,minecraft:nether_wart_block)
B(-4,19,-7,minecraft:nether_wart_block)
B(-4,18,-6,minecraft:nether_wart_block)
B(-4,19,-6,minecraft:nether_wart_block)
B(-4,20,-6,minecraft:nether_wart_block)
B(-4,19,-5,minecraft:nether_wart_block)
B(-3,20,-7,minecraft:nether_wart_block)
B(-3,19,-6,minecraft:nether_wart_block)
B(-3,20,-6,minecraft:nether_wart_block)
B(-3,21,-6,minecraft:nether_wart_block)
B(-3,20,-5,minecraft:nether_wart_block)
B(-2,21,-7,minecraft:nether_wart_block)
B(-2,20,-6,minecraft:nether_wart_block)
B(-2,21,-6,minecraft:nether_wart_block)
B(-2,22,-6,minecraft:nether_wart_block)
B(-2,21,-5,minecraft:nether_wart_block)
B(-1,22,-7,minecraft:nether_wart_block)
B(-1,21,-6,minecraft:nether_wart_block)
B(-1,22,-6,minecraft:nether_wart_block)
B(-1,23,-6,minecraft:nether_wart_block)
B(-1,22,-5,minecraft:nether_wart_block)
B(0,23,-7,minecraft:nether_wart_block)
B(0,22,-6,minecraft:nether_wart_block)
B(0,23,-6,minecraft:nether_wart_block)
B(0,24,-6,minecraft:nether_wart_block)
B(0,23,-5,minecraft:nether_wart_block)
B(1,24,-7,minecraft:nether_wart_block)
B(1,23,-6,minecraft:nether_wart_block)
B(1,24,-6,minecraft:nether_wart_block)
B(1,25,-6,minecraft:nether_wart_block)
B(1,24,-5,minecraft:nether_wart_block)
B(2,25,-7,minecraft:nether_wart_block)
B(2,24,-6,minecraft:nether_wart_block)
B(2,25,-6,minecraft:nether_wart_block)
B(2,26,-6,minecraft:nether_wart_block)
B(2,25,-5,minecraft:nether_wart_block)
B(3,26,-7,minecraft:nether_wart_block)
B(3,25,-6,minecraft:nether_wart_block)
B(3,26,-6,minecraft:nether_wart_block)
B(3,27,-6,minecraft:nether_wart_block)
B(3,26,-5,minecraft:nether_wart_block)
B(4,27,-7,minecraft:nether_wart_block)
B(4,26,-6,minecraft:nether_wart_block)
B(4,27,-6,minecraft:nether_wart_block)
B(4,28,-6,minecraft:nether_wart_block)
B(4,27,-5,minecraft:nether_wart_block)
B(5,28,-7,minecraft:nether_wart_block)
B(5,27,-6,minecraft:nether_wart_block)
B(5,28,-6,minecraft:nether_wart_block)
B(5,29,-6,minecraft:nether_wart_block)
B(5,28,-5,minecraft:nether_wart_block)
B(6,29,-7,minecraft:nether_wart_block)
B(6,28,-6,minecraft:nether_wart_block)
B(6,29,-6,minecraft:nether_wart_block)
B(6,30,-6,minecraft:nether_wart_block)
B(6,29,-5,minecraft:nether_wart_block)
B(7,30,-7,minecraft:nether_wart_block)
B(7,29,-6,minecraft:nether_wart_block)
B(7,30,-6,minecraft:nether_wart_block)
B(7,31,-6,minecraft:nether_wart_block)
B(7,30,-5,minecraft:nether_wart_block)

#######################################################################
# +-----------------------------------------------------------------+ #
# |                             Branches                            | #
# +-----------------------------------------------------------------+ #
#######################################################################

Branch(16,0,0,true,FleshString1_C2_R0,NORTH,100.0,0)

#######################################################################
# +-----------------------------------------------------------------+ #
# |                             Entities                            | #
# +-----------------------------------------------------------------+ #
#######################################################################

