
#######################################################################
# +-----------------------------------------------------------------+ #
# |                            BO4 object                           | #
# +-----------------------------------------------------------------+ #
#######################################################################

Author: Unknown

Description: No description given

SettingsMode: WriteWithoutComments


#######################################################################
# +-----------------------------------------------------------------+ #
# |                          Main settings                          | #
# +-----------------------------------------------------------------+ #
#######################################################################

FixedRotation: 

Frequency: 0

SpawnHeight: highestBlock

UseCenterForHighestBlock: true

##############################
# Height Limits for the BO4. #
##############################

MinHeight: 0

MaxHeight: 255

InheritBO3: 

InheritBO3Rotation: NORTH

OverrideChildSettings: true

OverrideParentHeight: false

CanOverride: false

BranchFrequency: 0

BranchFrequencyGroup: 

MustBeBelowOther: false

MustBeInside: 

CannotBeInside: 

ReplacesBO3: 

MustBeInsideWorldBorders: false

CanSpawnOnWater: true

SpawnOnWaterOnly: false

SpawnUnderWater: false

SpawnAtWaterLevel: false

HeightOffset: 0

RemoveAir: true

ReplaceAbove: 

ReplaceBelow: 

ReplaceWithBiomeBlocks: true

ReplaceWithSurfaceBlock: GRASS

ReplaceWithGroundBlock: DIRT

ReplaceWithStoneBlock: STONE

SmoothRadius: 0

SmoothHeightOffset: 0

SmoothStartTop: false

SmoothStartWood: false

SmoothingSurfaceBlock: 

SmoothingGroundBlock: 

BO3Group: 

IsSpawnPoint: false

DoReplaceBlocks: true


#######################################################################
# +-----------------------------------------------------------------+ #
# |                              Blocks                             | #
# +-----------------------------------------------------------------+ #
#######################################################################

B(-8,111,-7,minecraft:nether_wart_block)
B(-8,110,-6,minecraft:nether_wart_block)
B(-8,111,-6,minecraft:nether_wart_block)
B(-8,112,-6,minecraft:nether_wart_block)
B(-8,111,-5,minecraft:nether_wart_block)
B(-7,112,-7,minecraft:nether_wart_block)
B(-7,111,-6,minecraft:nether_wart_block)
B(-7,112,-6,minecraft:nether_wart_block)
B(-7,113,-6,minecraft:nether_wart_block)
B(-7,112,-5,minecraft:nether_wart_block)
B(-6,113,-7,minecraft:nether_wart_block)
B(-6,112,-6,minecraft:nether_wart_block)
B(-6,113,-6,minecraft:nether_wart_block)
B(-6,114,-6,minecraft:nether_wart_block)
B(-6,113,-5,minecraft:nether_wart_block)
B(-5,114,-7,minecraft:nether_wart_block)
B(-5,113,-6,minecraft:nether_wart_block)
B(-5,114,-6,minecraft:nether_wart_block)
B(-5,115,-6,minecraft:nether_wart_block)
B(-5,114,-5,minecraft:nether_wart_block)
B(-4,115,-7,minecraft:nether_wart_block)
B(-4,114,-6,minecraft:nether_wart_block)
B(-4,115,-6,minecraft:nether_wart_block)
B(-4,116,-6,minecraft:nether_wart_block)
B(-4,115,-5,minecraft:nether_wart_block)
B(-3,116,-7,minecraft:nether_wart_block)
B(-3,115,-6,minecraft:nether_wart_block)
B(-3,116,-6,minecraft:nether_wart_block)
B(-3,117,-6,minecraft:nether_wart_block)
B(-3,116,-5,minecraft:nether_wart_block)
B(-2,117,-7,minecraft:nether_wart_block)
B(-2,116,-6,minecraft:nether_wart_block)
B(-2,117,-6,minecraft:nether_wart_block)
B(-2,118,-6,minecraft:nether_wart_block)
B(-2,117,-5,minecraft:nether_wart_block)
B(-1,118,-7,minecraft:nether_wart_block)
B(-1,117,-6,minecraft:nether_wart_block)
B(-1,118,-6,minecraft:nether_wart_block)
B(-1,119,-6,minecraft:nether_wart_block)
B(-1,118,-5,minecraft:nether_wart_block)
B(0,119,-7,minecraft:nether_wart_block)
B(0,118,-6,minecraft:nether_wart_block)
B(0,119,-6,minecraft:nether_wart_block)
B(0,120,-6,minecraft:nether_wart_block)
B(0,119,-5,minecraft:nether_wart_block)
B(1,120,-7,minecraft:nether_wart_block)
B(1,119,-6,minecraft:nether_wart_block)
B(1,120,-6,minecraft:nether_wart_block)
B(1,121,-6,minecraft:nether_wart_block)
B(1,120,-5,minecraft:nether_wart_block)
B(2,121,-7,minecraft:nether_wart_block)
B(2,120,-6,minecraft:nether_wart_block)
B(2,121,-6,minecraft:nether_wart_block)
B(2,122,-6,minecraft:nether_wart_block)
B(2,121,-5,minecraft:nether_wart_block)
B(3,122,-7,minecraft:nether_wart_block)
B(3,121,-6,minecraft:nether_wart_block)
B(3,122,-6,minecraft:nether_wart_block)
B(3,123,-6,minecraft:nether_wart_block)
B(3,122,-5,minecraft:nether_wart_block)
B(4,123,-7,minecraft:nether_wart_block)
B(4,122,-6,minecraft:nether_wart_block)
B(4,123,-6,minecraft:nether_wart_block)
B(4,124,-6,minecraft:nether_wart_block)
B(4,123,-5,minecraft:nether_wart_block)
B(5,124,-7,minecraft:nether_wart_block)
B(5,123,-6,minecraft:nether_wart_block)
B(5,124,-6,minecraft:nether_wart_block)
B(5,125,-6,minecraft:nether_wart_block)
B(5,124,-5,minecraft:nether_wart_block)
B(6,125,-7,minecraft:nether_wart_block)
B(6,124,-6,minecraft:nether_wart_block)
B(6,125,-6,minecraft:nether_wart_block)
B(6,126,-6,minecraft:nether_wart_block)
B(6,125,-5,minecraft:nether_wart_block)
B(7,126,-7,minecraft:nether_wart_block)
B(7,125,-6,minecraft:nether_wart_block)
B(7,126,-6,minecraft:nether_wart_block)
B(7,127,-6,minecraft:nether_wart_block)
B(7,126,-5,minecraft:nether_wart_block)

#######################################################################
# +-----------------------------------------------------------------+ #
# |                             Branches                            | #
# +-----------------------------------------------------------------+ #
#######################################################################

Branch(16,0,0,true,FleshString1_C8_R0,NORTH,100.0,0)

#######################################################################
# +-----------------------------------------------------------------+ #
# |                             Entities                            | #
# +-----------------------------------------------------------------+ #
#######################################################################

