
#######################################################################
# +-----------------------------------------------------------------+ #
# |                            BO4 object                           | #
# +-----------------------------------------------------------------+ #
#######################################################################

Author: Unknown

Description: No description given

SettingsMode: WriteWithoutComments


#######################################################################
# +-----------------------------------------------------------------+ #
# |                          Main settings                          | #
# +-----------------------------------------------------------------+ #
#######################################################################

FixedRotation: 

Frequency: 0

SpawnHeight: highestBlock

UseCenterForHighestBlock: true

##############################
# Height Limits for the BO4. #
##############################

MinHeight: 0

MaxHeight: 255

InheritBO3: 

InheritBO3Rotation: NORTH

OverrideChildSettings: true

OverrideParentHeight: false

CanOverride: false

BranchFrequency: 0

BranchFrequencyGroup: 

MustBeBelowOther: false

MustBeInside: 

CannotBeInside: 

ReplacesBO3: 

MustBeInsideWorldBorders: false

CanSpawnOnWater: true

SpawnOnWaterOnly: false

SpawnUnderWater: false

SpawnAtWaterLevel: false

HeightOffset: 0

RemoveAir: true

ReplaceAbove: 

ReplaceBelow: 

ReplaceWithBiomeBlocks: true

ReplaceWithSurfaceBlock: GRASS

ReplaceWithGroundBlock: DIRT

ReplaceWithStoneBlock: STONE

SmoothRadius: 0

SmoothHeightOffset: 0

SmoothStartTop: false

SmoothStartWood: false

SmoothingSurfaceBlock: 

SmoothingGroundBlock: 

BO3Group: 

IsSpawnPoint: false

DoReplaceBlocks: true


#######################################################################
# +-----------------------------------------------------------------+ #
# |                              Blocks                             | #
# +-----------------------------------------------------------------+ #
#######################################################################

B(-8,79,-7,minecraft:nether_wart_block)
B(-8,78,-6,minecraft:nether_wart_block)
B(-8,79,-6,minecraft:nether_wart_block)
B(-8,80,-6,minecraft:nether_wart_block)
B(-8,79,-5,minecraft:nether_wart_block)
B(-7,80,-7,minecraft:nether_wart_block)
B(-7,79,-6,minecraft:nether_wart_block)
B(-7,80,-6,minecraft:nether_wart_block)
B(-7,81,-6,minecraft:nether_wart_block)
B(-7,80,-5,minecraft:nether_wart_block)
B(-6,81,-7,minecraft:nether_wart_block)
B(-6,80,-6,minecraft:nether_wart_block)
B(-6,81,-6,minecraft:nether_wart_block)
B(-6,82,-6,minecraft:nether_wart_block)
B(-6,81,-5,minecraft:nether_wart_block)
B(-5,82,-7,minecraft:nether_wart_block)
B(-5,81,-6,minecraft:nether_wart_block)
B(-5,82,-6,minecraft:nether_wart_block)
B(-5,83,-6,minecraft:nether_wart_block)
B(-5,82,-5,minecraft:nether_wart_block)
B(-4,83,-7,minecraft:nether_wart_block)
B(-4,82,-6,minecraft:nether_wart_block)
B(-4,83,-6,minecraft:nether_wart_block)
B(-4,84,-6,minecraft:nether_wart_block)
B(-4,83,-5,minecraft:nether_wart_block)
B(-3,84,-7,minecraft:nether_wart_block)
B(-3,83,-6,minecraft:nether_wart_block)
B(-3,84,-6,minecraft:nether_wart_block)
B(-3,85,-6,minecraft:nether_wart_block)
B(-3,84,-5,minecraft:nether_wart_block)
B(-2,85,-7,minecraft:nether_wart_block)
B(-2,84,-6,minecraft:nether_wart_block)
B(-2,85,-6,minecraft:nether_wart_block)
B(-2,86,-6,minecraft:nether_wart_block)
B(-2,85,-5,minecraft:nether_wart_block)
B(-1,86,-7,minecraft:nether_wart_block)
B(-1,85,-6,minecraft:nether_wart_block)
B(-1,86,-6,minecraft:nether_wart_block)
B(-1,87,-6,minecraft:nether_wart_block)
B(-1,86,-5,minecraft:nether_wart_block)
B(0,87,-7,minecraft:nether_wart_block)
B(0,86,-6,minecraft:nether_wart_block)
B(0,87,-6,minecraft:nether_wart_block)
B(0,88,-6,minecraft:nether_wart_block)
B(0,87,-5,minecraft:nether_wart_block)
B(1,88,-7,minecraft:nether_wart_block)
B(1,87,-6,minecraft:nether_wart_block)
B(1,88,-6,minecraft:nether_wart_block)
B(1,89,-6,minecraft:nether_wart_block)
B(1,88,-5,minecraft:nether_wart_block)
B(2,89,-7,minecraft:nether_wart_block)
B(2,88,-6,minecraft:nether_wart_block)
B(2,89,-6,minecraft:nether_wart_block)
B(2,90,-6,minecraft:nether_wart_block)
B(2,89,-5,minecraft:nether_wart_block)
B(3,90,-7,minecraft:nether_wart_block)
B(3,89,-6,minecraft:nether_wart_block)
B(3,90,-6,minecraft:nether_wart_block)
B(3,91,-6,minecraft:nether_wart_block)
B(3,90,-5,minecraft:nether_wart_block)
B(4,91,-7,minecraft:nether_wart_block)
B(4,90,-6,minecraft:nether_wart_block)
B(4,91,-6,minecraft:nether_wart_block)
B(4,92,-6,minecraft:nether_wart_block)
B(4,91,-5,minecraft:nether_wart_block)
B(5,92,-7,minecraft:nether_wart_block)
B(5,91,-6,minecraft:nether_wart_block)
B(5,92,-6,minecraft:nether_wart_block)
B(5,93,-6,minecraft:nether_wart_block)
B(5,92,-5,minecraft:nether_wart_block)
B(6,93,-7,minecraft:nether_wart_block)
B(6,92,-6,minecraft:nether_wart_block)
B(6,93,-6,minecraft:nether_wart_block)
B(6,94,-6,minecraft:nether_wart_block)
B(6,93,-5,minecraft:nether_wart_block)
B(7,94,-7,minecraft:nether_wart_block)
B(7,93,-6,minecraft:nether_wart_block)
B(7,94,-6,minecraft:nether_wart_block)
B(7,95,-6,minecraft:nether_wart_block)
B(7,94,-5,minecraft:nether_wart_block)

#######################################################################
# +-----------------------------------------------------------------+ #
# |                             Branches                            | #
# +-----------------------------------------------------------------+ #
#######################################################################

Branch(16,0,0,true,FleshString1_C6_R0,NORTH,100.0,0)

#######################################################################
# +-----------------------------------------------------------------+ #
# |                             Entities                            | #
# +-----------------------------------------------------------------+ #
#######################################################################

