
#######################################################################
# +-----------------------------------------------------------------+ #
# |                            BO4 object                           | #
# +-----------------------------------------------------------------+ #
#######################################################################

Author: Unknown

Description: No description given

SettingsMode: WriteWithoutComments


#######################################################################
# +-----------------------------------------------------------------+ #
# |                          Main settings                          | #
# +-----------------------------------------------------------------+ #
#######################################################################

FixedRotation: 

Frequency: 0

SpawnHeight: highestBlock

UseCenterForHighestBlock: true

##############################
# Height Limits for the BO4. #
##############################

MinHeight: 0

MaxHeight: 255

InheritBO3: 

InheritBO3Rotation: NORTH

OverrideChildSettings: true

OverrideParentHeight: false

CanOverride: false

BranchFrequency: 0

BranchFrequencyGroup: 

MustBeBelowOther: false

MustBeInside: 

CannotBeInside: 

ReplacesBO3: 

MustBeInsideWorldBorders: false

CanSpawnOnWater: true

SpawnOnWaterOnly: false

SpawnUnderWater: false

SpawnAtWaterLevel: false

HeightOffset: 0

RemoveAir: true

ReplaceAbove: 

ReplaceBelow: 

ReplaceWithBiomeBlocks: true

ReplaceWithSurfaceBlock: GRASS

ReplaceWithGroundBlock: DIRT

ReplaceWithStoneBlock: STONE

SmoothRadius: 0

SmoothHeightOffset: 0

SmoothStartTop: false

SmoothStartWood: false

SmoothingSurfaceBlock: 

SmoothingGroundBlock: 

BO3Group: 

IsSpawnPoint: false

DoReplaceBlocks: true


#######################################################################
# +-----------------------------------------------------------------+ #
# |                              Blocks                             | #
# +-----------------------------------------------------------------+ #
#######################################################################

B(-8,3,-5,minecraft:polished_blackstone_bricks)
B(-8,4,-5,minecraft:polished_blackstone_bricks)
B(-8,5,-5,minecraft:polished_blackstone_bricks)
B(-8,6,-5,minecraft:polished_blackstone_bricks)
B(-8,7,-5,minecraft:polished_blackstone_bricks)
B(-8,8,-5,minecraft:polished_blackstone_bricks)
B(-8,3,-4,minecraft:polished_blackstone_bricks)
B(-8,6,-4,minecraft:polished_blackstone_bricks)
B(-8,8,-4,minecraft:polished_blackstone_bricks)
B(-8,9,-4,minecraft:polished_blackstone_bricks)
B(-8,10,-4,minecraft:polished_blackstone_bricks)
B(-8,11,-4,minecraft:polished_blackstone_bricks)
B(-8,12,-4,minecraft:polished_blackstone_bricks)
B(-8,13,-4,minecraft:polished_blackstone_bricks)
B(-8,14,-4,minecraft:polished_blackstone_bricks)
B(-8,3,-3,minecraft:polished_blackstone_bricks)
B(-8,4,-3,minecraft:polished_blackstone_bricks)
B(-8,5,-3,minecraft:polished_blackstone_bricks)
B(-8,6,-3,minecraft:polished_blackstone_bricks)
B(-8,7,-3,minecraft:polished_blackstone_bricks)
B(-8,8,-3,minecraft:polished_blackstone_bricks)
B(-8,9,-3,minecraft:polished_blackstone_bricks)
B(-8,12,-3,minecraft:polished_blackstone_bricks)
B(-8,14,-3,minecraft:polished_blackstone_bricks)
B(-8,3,-2,minecraft:polished_blackstone_bricks)
B(-8,4,-2,minecraft:polished_blackstone_bricks)
B(-8,5,-2,minecraft:polished_blackstone_bricks)
B(-8,6,-2,minecraft:polished_blackstone_bricks)
B(-8,7,-2,minecraft:polished_blackstone_bricks)
B(-8,8,-2,minecraft:polished_blackstone_bricks)
B(-8,9,-2,minecraft:polished_blackstone_bricks)
B(-8,10,-2,minecraft:polished_blackstone_bricks)
B(-8,11,-2,minecraft:polished_blackstone_bricks)
B(-8,12,-2,minecraft:polished_blackstone_bricks)
B(-8,13,-2,minecraft:polished_blackstone_bricks)
B(-8,14,-2,minecraft:polished_blackstone_bricks)
B(-8,3,-1,minecraft:polished_blackstone_bricks)
B(-8,4,-1,minecraft:polished_blackstone_bricks)
B(-8,5,-1,minecraft:polished_blackstone_bricks)
B(-8,6,-1,minecraft:polished_blackstone_bricks)
B(-8,7,-1,minecraft:polished_blackstone_bricks)
B(-8,8,-1,minecraft:polished_blackstone_bricks)
B(-8,9,-1,minecraft:polished_blackstone_bricks)
B(-8,10,-1,minecraft:polished_blackstone_bricks)
B(-8,11,-1,minecraft:polished_blackstone_bricks)
B(-8,12,-1,minecraft:polished_blackstone_bricks)
B(-8,13,-1,minecraft:polished_blackstone_bricks)
B(-8,14,-1,minecraft:polished_blackstone_bricks)
B(-8,3,0,minecraft:polished_blackstone_bricks)
B(-8,4,0,minecraft:polished_blackstone_bricks)
B(-8,5,0,minecraft:polished_blackstone_bricks)
B(-8,6,0,minecraft:polished_blackstone_bricks)
B(-8,7,0,minecraft:polished_blackstone_bricks)
B(-8,8,0,minecraft:polished_blackstone_bricks)
B(-8,9,0,minecraft:polished_blackstone_bricks)
B(-8,10,0,minecraft:polished_blackstone_bricks)
B(-8,11,0,minecraft:polished_blackstone_bricks)
B(-8,12,0,minecraft:polished_blackstone_bricks)
B(-8,13,0,minecraft:polished_blackstone_bricks)
B(-8,14,0,minecraft:polished_blackstone_bricks)
B(-8,3,1,minecraft:polished_blackstone_bricks)
B(-8,4,1,minecraft:polished_blackstone_bricks)
B(-8,5,1,minecraft:polished_blackstone_bricks)
B(-8,6,1,minecraft:polished_blackstone_bricks)
B(-8,7,1,minecraft:polished_blackstone_bricks)
B(-8,8,1,minecraft:polished_blackstone_bricks)
B(-8,9,1,minecraft:polished_blackstone_bricks)
B(-8,10,1,minecraft:polished_blackstone_bricks)
B(-8,11,1,minecraft:polished_blackstone_bricks)
B(-8,12,1,minecraft:polished_blackstone_bricks)
B(-8,13,1,minecraft:polished_blackstone_bricks)
B(-8,14,1,minecraft:polished_blackstone_bricks)
B(-8,15,1,minecraft:polished_blackstone_bricks)
B(-8,16,1,minecraft:polished_blackstone_bricks)
B(-8,17,1,minecraft:polished_blackstone_bricks)
B(-8,18,1,minecraft:polished_blackstone_bricks)
B(-8,19,1,minecraft:polished_blackstone_bricks)
B(-8,20,1,minecraft:polished_blackstone_bricks)
B(-8,3,2,minecraft:polished_blackstone_bricks)
B(-8,4,2,minecraft:polished_blackstone_bricks)
B(-8,5,2,minecraft:polished_blackstone_bricks)
B(-8,6,2,minecraft:polished_blackstone_bricks)
B(-8,7,2,minecraft:polished_blackstone_bricks)
B(-8,8,2,minecraft:polished_blackstone_bricks)
B(-8,9,2,minecraft:polished_blackstone_bricks)
B(-8,10,2,minecraft:polished_blackstone_bricks)
B(-8,11,2,minecraft:polished_blackstone_bricks)
B(-8,12,2,minecraft:polished_blackstone_bricks)
B(-8,13,2,minecraft:polished_blackstone_bricks)
B(-8,14,2,minecraft:polished_blackstone_bricks)
B(-8,15,2,minecraft:polished_blackstone_bricks)
B(-8,16,2,minecraft:polished_blackstone_bricks)
B(-8,17,2,minecraft:polished_blackstone_bricks)
B(-8,18,2,minecraft:polished_blackstone_bricks)
B(-8,19,2,minecraft:polished_blackstone_bricks)
B(-8,20,2,minecraft:polished_blackstone_bricks)
B(-8,3,3,minecraft:polished_blackstone_bricks)
B(-8,4,3,minecraft:polished_blackstone_bricks)
B(-8,5,3,minecraft:polished_blackstone_bricks)
B(-8,6,3,minecraft:polished_blackstone_bricks)
B(-8,7,3,minecraft:polished_blackstone_bricks)
B(-8,8,3,minecraft:polished_blackstone_bricks)
B(-8,9,3,minecraft:polished_blackstone_bricks)
B(-8,10,3,minecraft:polished_blackstone_bricks)
B(-8,11,3,minecraft:polished_blackstone_bricks)
B(-8,12,3,minecraft:polished_blackstone_bricks)
B(-8,13,3,minecraft:polished_blackstone_bricks)
B(-8,14,3,minecraft:polished_blackstone_bricks)
B(-8,15,3,minecraft:polished_blackstone_bricks)
B(-8,18,3,minecraft:polished_blackstone_bricks)
B(-8,20,3,minecraft:polished_blackstone_bricks)
B(-8,3,4,minecraft:polished_blackstone_bricks)
B(-8,4,4,minecraft:polished_blackstone_bricks)
B(-8,5,4,minecraft:polished_blackstone_bricks)
B(-8,6,4,minecraft:polished_blackstone_bricks)
B(-8,7,4,minecraft:polished_blackstone_bricks)
B(-8,8,4,minecraft:polished_blackstone_bricks)
B(-8,9,4,minecraft:polished_blackstone_bricks)
B(-8,10,4,minecraft:polished_blackstone_bricks)
B(-8,11,4,minecraft:polished_blackstone_bricks)
B(-8,12,4,minecraft:polished_blackstone_bricks)
B(-8,13,4,minecraft:polished_blackstone_bricks)
B(-8,14,4,minecraft:polished_blackstone_bricks)
B(-8,15,4,minecraft:polished_blackstone_bricks)
B(-8,16,4,minecraft:polished_blackstone_bricks)
B(-8,17,4,minecraft:polished_blackstone_bricks)
B(-8,18,4,minecraft:polished_blackstone_bricks)
B(-8,19,4,minecraft:polished_blackstone_bricks)
B(-8,20,4,minecraft:polished_blackstone_bricks)
B(-8,3,5,minecraft:polished_blackstone_bricks)
B(-8,4,5,minecraft:polished_blackstone_bricks)
B(-8,5,5,minecraft:polished_blackstone_bricks)
B(-8,6,5,minecraft:polished_blackstone_bricks)
B(-8,7,5,minecraft:polished_blackstone_bricks)
B(-8,8,5,minecraft:polished_blackstone_bricks)
B(-8,9,5,minecraft:polished_blackstone_bricks)
B(-8,10,5,minecraft:polished_blackstone_bricks)
B(-8,11,5,minecraft:polished_blackstone_bricks)
B(-8,12,5,minecraft:polished_blackstone_bricks)
B(-8,13,5,minecraft:polished_blackstone_bricks)
B(-8,14,5,minecraft:polished_blackstone_bricks)
B(-8,15,5,minecraft:polished_blackstone_bricks)
B(-8,16,5,minecraft:polished_blackstone_bricks)
B(-8,17,5,minecraft:polished_blackstone_bricks)
B(-8,18,5,minecraft:polished_blackstone_bricks)
B(-8,19,5,minecraft:polished_blackstone_bricks)
B(-8,20,5,minecraft:polished_blackstone_bricks)
B(-8,3,6,minecraft:polished_blackstone_bricks)
B(-8,4,6,minecraft:polished_blackstone_bricks)
B(-8,5,6,minecraft:polished_blackstone_bricks)
B(-8,6,6,minecraft:polished_blackstone_bricks)
B(-8,7,6,minecraft:polished_blackstone_bricks)
B(-8,8,6,minecraft:polished_blackstone_bricks)
B(-8,9,6,minecraft:polished_blackstone_bricks)
B(-8,10,6,minecraft:polished_blackstone_bricks)
B(-8,11,6,minecraft:polished_blackstone_bricks)
B(-8,12,6,minecraft:polished_blackstone_bricks)
B(-8,13,6,minecraft:polished_blackstone_bricks)
B(-8,14,6,minecraft:polished_blackstone_bricks)
B(-8,15,6,minecraft:polished_blackstone_bricks)
B(-8,16,6,minecraft:polished_blackstone_bricks)
B(-8,17,6,minecraft:polished_blackstone_bricks)
B(-8,18,6,minecraft:polished_blackstone_bricks)
B(-8,19,6,minecraft:polished_blackstone_bricks)
B(-8,20,6,minecraft:polished_blackstone_bricks)
B(-8,3,7,minecraft:polished_blackstone_bricks)
B(-8,4,7,minecraft:polished_blackstone_bricks)
B(-8,5,7,minecraft:polished_blackstone_bricks)
B(-8,6,7,minecraft:polished_blackstone_bricks)
B(-8,7,7,minecraft:polished_blackstone_bricks)
B(-8,8,7,minecraft:polished_blackstone_bricks)
B(-8,9,7,minecraft:polished_blackstone_bricks)
B(-8,10,7,minecraft:polished_blackstone_bricks)
B(-8,11,7,minecraft:polished_blackstone_bricks)
B(-8,12,7,minecraft:polished_blackstone_bricks)
B(-8,13,7,minecraft:polished_blackstone_bricks)
B(-8,14,7,minecraft:polished_blackstone_bricks)
B(-8,15,7,minecraft:polished_blackstone_bricks)
B(-8,16,7,minecraft:polished_blackstone_bricks)
B(-8,17,7,minecraft:polished_blackstone_bricks)
B(-8,18,7,minecraft:polished_blackstone_bricks)
B(-8,19,7,minecraft:polished_blackstone_bricks)
B(-8,20,7,minecraft:polished_blackstone_bricks)
B(-8,3,8,minecraft:polished_blackstone_bricks)
B(-8,4,8,minecraft:polished_blackstone_bricks)
B(-8,5,8,minecraft:polished_blackstone_bricks)
B(-8,6,8,minecraft:polished_blackstone_bricks)
B(-8,7,8,minecraft:polished_blackstone_bricks)
B(-8,8,8,minecraft:polished_blackstone_bricks)
B(-8,9,8,minecraft:polished_blackstone_bricks)
B(-8,10,8,minecraft:polished_blackstone_bricks)
B(-8,11,8,minecraft:polished_blackstone_bricks)
B(-8,12,8,minecraft:polished_blackstone_bricks)
B(-8,13,8,minecraft:polished_blackstone_bricks)
B(-8,14,8,minecraft:polished_blackstone_bricks)
B(-8,15,8,minecraft:polished_blackstone_bricks)
B(-8,16,8,minecraft:polished_blackstone_bricks)
B(-8,17,8,minecraft:polished_blackstone_bricks)
B(-8,18,8,minecraft:polished_blackstone_bricks)
B(-8,19,8,minecraft:polished_blackstone_bricks)
B(-8,20,8,minecraft:polished_blackstone_bricks)
B(-7,3,-3,minecraft:polished_blackstone_bricks)
B(-7,4,-3,minecraft:polished_blackstone_bricks)
B(-7,5,-3,minecraft:polished_blackstone_bricks)
B(-7,6,-3,minecraft:polished_blackstone_bricks)
B(-7,7,-3,minecraft:polished_blackstone_bricks)
B(-7,8,-3,minecraft:polished_blackstone_bricks)
B(-7,3,-2,minecraft:polished_blackstone_bricks)
B(-7,6,-2,minecraft:polished_blackstone_bricks)
B(-7,8,-2,minecraft:polished_blackstone_bricks)
B(-7,9,-2,minecraft:polished_blackstone_bricks)
B(-7,10,-2,minecraft:polished_blackstone_bricks)
B(-7,11,-2,minecraft:polished_blackstone_bricks)
B(-7,12,-2,minecraft:polished_blackstone_bricks)
B(-7,13,-2,minecraft:polished_blackstone_bricks)
B(-7,14,-2,minecraft:polished_blackstone_bricks)
B(-7,3,-1,minecraft:polished_blackstone_bricks)
B(-7,4,-1,minecraft:polished_blackstone_bricks)
B(-7,5,-1,minecraft:polished_blackstone_bricks)
B(-7,6,-1,minecraft:polished_blackstone_bricks)
B(-7,7,-1,minecraft:polished_blackstone_bricks)
B(-7,8,-1,minecraft:polished_blackstone_bricks)
B(-7,9,-1,minecraft:polished_blackstone_bricks)
B(-7,12,-1,minecraft:polished_blackstone_bricks)
B(-7,14,-1,minecraft:polished_blackstone_bricks)
B(-7,3,0,minecraft:polished_blackstone_bricks)
B(-7,4,0,minecraft:polished_blackstone_bricks)
B(-7,5,0,minecraft:polished_blackstone_bricks)
B(-7,6,0,minecraft:polished_blackstone_bricks)
B(-7,7,0,minecraft:polished_blackstone_bricks)
B(-7,8,0,minecraft:polished_blackstone_bricks)
B(-7,9,0,minecraft:polished_blackstone_bricks)
B(-7,10,0,minecraft:polished_blackstone_bricks)
B(-7,11,0,minecraft:polished_blackstone_bricks)
B(-7,12,0,minecraft:polished_blackstone_bricks)
B(-7,13,0,minecraft:polished_blackstone_bricks)
B(-7,14,0,minecraft:polished_blackstone_bricks)
B(-7,3,1,minecraft:polished_blackstone_bricks)
B(-7,4,1,minecraft:polished_blackstone_bricks)
B(-7,5,1,minecraft:polished_blackstone_bricks)
B(-7,6,1,minecraft:polished_blackstone_bricks)
B(-7,7,1,minecraft:polished_blackstone_bricks)
B(-7,8,1,minecraft:polished_blackstone_bricks)
B(-7,9,1,minecraft:polished_blackstone_bricks)
B(-7,10,1,minecraft:polished_blackstone_bricks)
B(-7,11,1,minecraft:polished_blackstone_bricks)
B(-7,12,1,minecraft:polished_blackstone_bricks)
B(-7,13,1,minecraft:polished_blackstone_bricks)
B(-7,14,1,minecraft:polished_blackstone_bricks)
B(-7,3,2,minecraft:polished_blackstone_bricks)
B(-7,4,2,minecraft:polished_blackstone_bricks)
B(-7,5,2,minecraft:polished_blackstone_bricks)
B(-7,6,2,minecraft:polished_blackstone_bricks)
B(-7,7,2,minecraft:polished_blackstone_bricks)
B(-7,8,2,minecraft:polished_blackstone_bricks)
B(-7,9,2,minecraft:polished_blackstone_bricks)
B(-7,10,2,minecraft:polished_blackstone_bricks)
B(-7,11,2,minecraft:polished_blackstone_bricks)
B(-7,12,2,minecraft:polished_blackstone_bricks)
B(-7,13,2,minecraft:polished_blackstone_bricks)
B(-7,14,2,minecraft:polished_blackstone_bricks)
B(-7,3,3,minecraft:polished_blackstone_bricks)
B(-7,4,3,minecraft:polished_blackstone_bricks)
B(-7,5,3,minecraft:polished_blackstone_bricks)
B(-7,6,3,minecraft:polished_blackstone_bricks)
B(-7,7,3,minecraft:polished_blackstone_bricks)
B(-7,8,3,minecraft:polished_blackstone_bricks)
B(-7,9,3,minecraft:polished_blackstone_bricks)
B(-7,10,3,minecraft:polished_blackstone_bricks)
B(-7,11,3,minecraft:polished_blackstone_bricks)
B(-7,12,3,minecraft:polished_blackstone_bricks)
B(-7,13,3,minecraft:polished_blackstone_bricks)
B(-7,14,3,minecraft:polished_blackstone_bricks)
B(-7,3,4,minecraft:polished_blackstone_bricks)
B(-7,4,4,minecraft:polished_blackstone_bricks)
B(-7,5,4,minecraft:polished_blackstone_bricks)
B(-7,6,4,minecraft:polished_blackstone_bricks)
B(-7,7,4,minecraft:polished_blackstone_bricks)
B(-7,8,4,minecraft:polished_blackstone_bricks)
B(-7,9,4,minecraft:polished_blackstone_bricks)
B(-7,10,4,minecraft:polished_blackstone_bricks)
B(-7,11,4,minecraft:polished_blackstone_bricks)
B(-7,12,4,minecraft:polished_blackstone_bricks)
B(-7,13,4,minecraft:polished_blackstone_bricks)
B(-7,14,4,minecraft:polished_blackstone_bricks)
B(-7,3,5,minecraft:polished_blackstone_bricks)
B(-7,4,5,minecraft:polished_blackstone_bricks)
B(-7,5,5,minecraft:polished_blackstone_bricks)
B(-7,6,5,minecraft:polished_blackstone_bricks)
B(-7,7,5,minecraft:polished_blackstone_bricks)
B(-7,8,5,minecraft:polished_blackstone_bricks)
B(-7,9,5,minecraft:polished_blackstone_bricks)
B(-7,10,5,minecraft:polished_blackstone_bricks)
B(-7,11,5,minecraft:polished_blackstone_bricks)
B(-7,12,5,minecraft:polished_blackstone_bricks)
B(-7,13,5,minecraft:polished_blackstone_bricks)
B(-7,14,5,minecraft:polished_blackstone_bricks)
B(-7,15,5,minecraft:polished_blackstone_bricks)
B(-7,16,5,minecraft:polished_blackstone_bricks)
B(-7,17,5,minecraft:polished_blackstone_bricks)
B(-7,18,5,minecraft:polished_blackstone_bricks)
B(-7,19,5,minecraft:polished_blackstone_bricks)
B(-7,20,5,minecraft:polished_blackstone_bricks)
B(-7,3,6,minecraft:polished_blackstone_bricks)
B(-7,4,6,minecraft:polished_blackstone_bricks)
B(-7,5,6,minecraft:polished_blackstone_bricks)
B(-7,6,6,minecraft:polished_blackstone_bricks)
B(-7,7,6,minecraft:polished_blackstone_bricks)
B(-7,8,6,minecraft:polished_blackstone_bricks)
B(-7,9,6,minecraft:polished_blackstone_bricks)
B(-7,10,6,minecraft:polished_blackstone_bricks)
B(-7,11,6,minecraft:polished_blackstone_bricks)
B(-7,12,6,minecraft:polished_blackstone_bricks)
B(-7,13,6,minecraft:polished_blackstone_bricks)
B(-7,14,6,minecraft:polished_blackstone_bricks)
B(-7,15,6,minecraft:polished_blackstone_bricks)
B(-7,18,6,minecraft:polished_blackstone_bricks)
B(-7,20,6,minecraft:polished_blackstone_bricks)
B(-7,3,7,minecraft:polished_blackstone_bricks)
B(-7,4,7,minecraft:polished_blackstone_bricks)
B(-7,5,7,minecraft:polished_blackstone_bricks)
B(-7,6,7,minecraft:polished_blackstone_bricks)
B(-7,7,7,minecraft:polished_blackstone_bricks)
B(-7,8,7,minecraft:polished_blackstone_bricks)
B(-7,9,7,minecraft:polished_blackstone_bricks)
B(-7,10,7,minecraft:polished_blackstone_bricks)
B(-7,11,7,minecraft:polished_blackstone_bricks)
B(-7,12,7,minecraft:polished_blackstone_bricks)
B(-7,13,7,minecraft:polished_blackstone_bricks)
B(-7,14,7,minecraft:polished_blackstone_bricks)
B(-7,15,7,minecraft:polished_blackstone_bricks)
B(-7,18,7,minecraft:polished_blackstone_bricks)
B(-7,19,7,minecraft:polished_blackstone_bricks)
B(-7,20,7,minecraft:polished_blackstone_bricks)
B(-7,3,8,minecraft:polished_blackstone_bricks)
B(-7,4,8,minecraft:polished_blackstone_bricks)
B(-7,5,8,minecraft:polished_blackstone_bricks)
B(-7,6,8,minecraft:polished_blackstone_bricks)
B(-7,7,8,minecraft:polished_blackstone_bricks)
B(-7,8,8,minecraft:polished_blackstone_bricks)
B(-7,9,8,minecraft:polished_blackstone_bricks)
B(-7,10,8,minecraft:polished_blackstone_bricks)
B(-7,11,8,minecraft:polished_blackstone_bricks)
B(-7,12,8,minecraft:polished_blackstone_bricks)
B(-7,13,8,minecraft:polished_blackstone_bricks)
B(-7,14,8,minecraft:polished_blackstone_bricks)
B(-7,15,8,minecraft:polished_blackstone_bricks)
B(-7,18,8,minecraft:polished_blackstone_bricks)
B(-7,20,8,minecraft:polished_blackstone_bricks)
B(-6,3,-1,minecraft:polished_blackstone_bricks)
B(-6,4,-1,minecraft:polished_blackstone_bricks)
B(-6,5,-1,minecraft:polished_blackstone_bricks)
B(-6,6,-1,minecraft:polished_blackstone_bricks)
B(-6,7,-1,minecraft:polished_blackstone_bricks)
B(-6,8,-1,minecraft:polished_blackstone_bricks)
B(-6,3,0,minecraft:polished_blackstone_bricks)
B(-6,6,0,minecraft:polished_blackstone_bricks)
B(-6,8,0,minecraft:polished_blackstone_bricks)
B(-6,3,1,minecraft:polished_blackstone_bricks)
B(-6,4,1,minecraft:polished_blackstone_bricks)
B(-6,5,1,minecraft:polished_blackstone_bricks)
B(-6,6,1,minecraft:polished_blackstone_bricks)
B(-6,7,1,minecraft:polished_blackstone_bricks)
B(-6,8,1,minecraft:polished_blackstone_bricks)
B(-6,9,1,minecraft:polished_blackstone_bricks)
B(-6,10,1,minecraft:polished_blackstone_bricks)
B(-6,11,1,minecraft:polished_blackstone_bricks)
B(-6,12,1,minecraft:polished_blackstone_bricks)
B(-6,13,1,minecraft:polished_blackstone_bricks)
B(-6,14,1,minecraft:polished_blackstone_bricks)
B(-6,3,2,minecraft:polished_blackstone_bricks)
B(-6,4,2,minecraft:polished_blackstone_bricks)
B(-6,5,2,minecraft:polished_blackstone_bricks)
B(-6,6,2,minecraft:polished_blackstone_bricks)
B(-6,7,2,minecraft:polished_blackstone_bricks)
B(-6,8,2,minecraft:polished_blackstone_bricks)
B(-6,9,2,minecraft:polished_blackstone_bricks)
B(-6,10,2,minecraft:polished_blackstone_bricks)
B(-6,11,2,minecraft:polished_blackstone_bricks)
B(-6,12,2,minecraft:polished_blackstone_bricks)
B(-6,13,2,minecraft:polished_blackstone_bricks)
B(-6,14,2,minecraft:polished_blackstone_bricks)
B(-6,3,3,minecraft:polished_blackstone_bricks)
B(-6,4,3,minecraft:polished_blackstone_bricks)
B(-6,5,3,minecraft:polished_blackstone_bricks)
B(-6,6,3,minecraft:polished_blackstone_bricks)
B(-6,7,3,minecraft:polished_blackstone_bricks)
B(-6,8,3,minecraft:polished_blackstone_bricks)
B(-6,9,3,minecraft:polished_blackstone_bricks)
B(-6,12,3,minecraft:polished_blackstone_bricks)
B(-6,14,3,minecraft:polished_blackstone_bricks)
B(-6,3,4,minecraft:polished_blackstone_bricks)
B(-6,4,4,minecraft:polished_blackstone_bricks)
B(-6,5,4,minecraft:polished_blackstone_bricks)
B(-6,6,4,minecraft:polished_blackstone_bricks)
B(-6,7,4,minecraft:polished_blackstone_bricks)
B(-6,8,4,minecraft:polished_blackstone_bricks)
B(-6,9,4,minecraft:polished_blackstone_bricks)
B(-6,10,4,minecraft:polished_blackstone_bricks)
B(-6,11,4,minecraft:polished_blackstone_bricks)
B(-6,12,4,minecraft:polished_blackstone_bricks)
B(-6,13,4,minecraft:polished_blackstone_bricks)
B(-6,14,4,minecraft:polished_blackstone_bricks)
B(-6,3,5,minecraft:polished_blackstone_bricks)
B(-6,4,5,minecraft:polished_blackstone_bricks)
B(-6,5,5,minecraft:polished_blackstone_bricks)
B(-6,6,5,minecraft:polished_blackstone_bricks)
B(-6,7,5,minecraft:polished_blackstone_bricks)
B(-6,8,5,minecraft:polished_blackstone_bricks)
B(-6,9,5,minecraft:polished_blackstone_bricks)
B(-6,10,5,minecraft:polished_blackstone_bricks)
B(-6,11,5,minecraft:polished_blackstone_bricks)
B(-6,12,5,minecraft:polished_blackstone_bricks)
B(-6,13,5,minecraft:polished_blackstone_bricks)
B(-6,14,5,minecraft:polished_blackstone_bricks)
B(-6,3,6,minecraft:polished_blackstone_bricks)
B(-6,4,6,minecraft:polished_blackstone_bricks)
B(-6,5,6,minecraft:polished_blackstone_bricks)
B(-6,6,6,minecraft:polished_blackstone_bricks)
B(-6,7,6,minecraft:polished_blackstone_bricks)
B(-6,8,6,minecraft:polished_blackstone_bricks)
B(-6,9,6,minecraft:polished_blackstone_bricks)
B(-6,10,6,minecraft:polished_blackstone_bricks)
B(-6,11,6,minecraft:polished_blackstone_bricks)
B(-6,12,6,minecraft:polished_blackstone_bricks)
B(-6,13,6,minecraft:polished_blackstone_bricks)
B(-6,14,6,minecraft:polished_blackstone_bricks)
B(-6,3,7,minecraft:polished_blackstone_bricks)
B(-6,4,7,minecraft:polished_blackstone_bricks)
B(-6,5,7,minecraft:polished_blackstone_bricks)
B(-6,6,7,minecraft:polished_blackstone_bricks)
B(-6,7,7,minecraft:polished_blackstone_bricks)
B(-6,8,7,minecraft:polished_blackstone_bricks)
B(-6,9,7,minecraft:polished_blackstone_bricks)
B(-6,10,7,minecraft:polished_blackstone_bricks)
B(-6,11,7,minecraft:polished_blackstone_bricks)
B(-6,12,7,minecraft:polished_blackstone_bricks)
B(-6,13,7,minecraft:polished_blackstone_bricks)
B(-6,14,7,minecraft:polished_blackstone_bricks)
B(-6,3,8,minecraft:polished_blackstone_bricks)
B(-6,4,8,minecraft:polished_blackstone_bricks)
B(-6,5,8,minecraft:polished_blackstone_bricks)
B(-6,6,8,minecraft:polished_blackstone_bricks)
B(-6,7,8,minecraft:polished_blackstone_bricks)
B(-6,8,8,minecraft:polished_blackstone_bricks)
B(-6,9,8,minecraft:polished_blackstone_bricks)
B(-6,10,8,minecraft:polished_blackstone_bricks)
B(-6,11,8,minecraft:polished_blackstone_bricks)
B(-6,12,8,minecraft:polished_blackstone_bricks)
B(-6,13,8,minecraft:polished_blackstone_bricks)
B(-6,14,8,minecraft:polished_blackstone_bricks)
B(-5,3,2,minecraft:polished_blackstone_bricks)
B(-5,4,2,minecraft:polished_blackstone_bricks)
B(-5,5,2,minecraft:polished_blackstone_bricks)
B(-5,6,2,minecraft:polished_blackstone_bricks)
B(-5,7,2,minecraft:polished_blackstone_bricks)
B(-5,8,2,minecraft:polished_blackstone_bricks)
B(-5,3,3,minecraft:polished_blackstone_bricks)
B(-5,6,3,minecraft:polished_blackstone_bricks)
B(-5,8,3,minecraft:polished_blackstone_bricks)
B(-5,3,4,minecraft:polished_blackstone_bricks)
B(-5,4,4,minecraft:polished_blackstone_bricks)
B(-5,5,4,minecraft:polished_blackstone_bricks)
B(-5,6,4,minecraft:polished_blackstone_bricks)
B(-5,7,4,minecraft:polished_blackstone_bricks)
B(-5,8,4,minecraft:polished_blackstone_bricks)
B(-5,3,5,minecraft:polished_blackstone_bricks)
B(-5,4,5,minecraft:polished_blackstone_bricks)
B(-5,5,5,minecraft:polished_blackstone_bricks)
B(-5,6,5,minecraft:polished_blackstone_bricks)
B(-5,7,5,minecraft:polished_blackstone_bricks)
B(-5,8,5,minecraft:polished_blackstone_bricks)
B(-5,9,5,minecraft:polished_blackstone_bricks)
B(-5,10,5,minecraft:polished_blackstone_bricks)
B(-5,11,5,minecraft:polished_blackstone_bricks)
B(-5,12,5,minecraft:polished_blackstone_bricks)
B(-5,13,5,minecraft:polished_blackstone_bricks)
B(-5,14,5,minecraft:polished_blackstone_bricks)
B(-5,3,6,minecraft:polished_blackstone_bricks)
B(-5,4,6,minecraft:polished_blackstone_bricks)
B(-5,5,6,minecraft:polished_blackstone_bricks)
B(-5,6,6,minecraft:polished_blackstone_bricks)
B(-5,7,6,minecraft:polished_blackstone_bricks)
B(-5,8,6,minecraft:polished_blackstone_bricks)
B(-5,9,6,minecraft:polished_blackstone_bricks)
B(-5,12,6,minecraft:polished_blackstone_bricks)
B(-5,14,6,minecraft:polished_blackstone_bricks)
B(-5,3,7,minecraft:polished_blackstone_bricks)
B(-5,4,7,minecraft:polished_blackstone_bricks)
B(-5,5,7,minecraft:polished_blackstone_bricks)
B(-5,6,7,minecraft:polished_blackstone_bricks)
B(-5,7,7,minecraft:polished_blackstone_bricks)
B(-5,8,7,minecraft:polished_blackstone_bricks)
B(-5,9,7,minecraft:polished_blackstone_bricks)
B(-5,12,7,minecraft:polished_blackstone_bricks)
B(-5,13,7,minecraft:polished_blackstone_bricks)
B(-5,14,7,minecraft:polished_blackstone_bricks)
B(-5,3,8,minecraft:polished_blackstone_bricks)
B(-5,4,8,minecraft:polished_blackstone_bricks)
B(-5,5,8,minecraft:polished_blackstone_bricks)
B(-5,6,8,minecraft:polished_blackstone_bricks)
B(-5,7,8,minecraft:polished_blackstone_bricks)
B(-5,8,8,minecraft:polished_blackstone_bricks)
B(-5,9,8,minecraft:polished_blackstone_bricks)
B(-5,12,8,minecraft:polished_blackstone_bricks)
B(-5,14,8,minecraft:polished_blackstone_bricks)
B(-4,3,5,minecraft:polished_blackstone_bricks)
B(-4,4,5,minecraft:polished_blackstone_bricks)
B(-4,5,5,minecraft:polished_blackstone_bricks)
B(-4,6,5,minecraft:polished_blackstone_bricks)
B(-4,7,5,minecraft:polished_blackstone_bricks)
B(-4,8,5,minecraft:polished_blackstone_bricks)
B(-4,3,6,minecraft:polished_blackstone_bricks)
B(-4,6,6,minecraft:polished_blackstone_bricks)
B(-4,8,6,minecraft:polished_blackstone_bricks)
B(-4,3,7,minecraft:polished_blackstone_bricks)
B(-4,6,7,minecraft:polished_blackstone_bricks)
B(-4,7,7,minecraft:polished_blackstone_bricks)
B(-4,8,7,minecraft:polished_blackstone_bricks)
B(-4,3,8,minecraft:polished_blackstone_bricks)
B(-4,6,8,minecraft:polished_blackstone_bricks)
B(-4,8,8,minecraft:polished_blackstone_bricks)

#######################################################################
# +-----------------------------------------------------------------+ #
# |                             Branches                            | #
# +-----------------------------------------------------------------+ #
#######################################################################


#######################################################################
# +-----------------------------------------------------------------+ #
# |                             Entities                            | #
# +-----------------------------------------------------------------+ #
#######################################################################

