Author: Bo3 BulkEdit

Description: Converted Schematic - Modified by Bo3BulkEdit

Version: 3

SettingsMode: WriteDisable

IsOTGPlus: true
Tree: false
Frequency: 10
Rarity: 100
RotateRandomly: true
SpawnHeight: randomY
SpawnHeightOffset: 0
SpawnHeightVariance: 0
MaxBranchDepth: 10
ExcludedBiomes: All

MinHeight: 50
MaxHeight: 65

SourceBlocks: AIR
MaxPercentageOutsideSourceBlock: 100
OutsideSourceBlock: placeAnyway

ReplaceBelow: NETHER_WART_BLOCK
ReplaceWithBiomeBlocks: false
ReplaceWithGroundBlock: NETHER_WART_BLOCK
ReplaceWithSurfaceBlock: NETHER_WART_BLOCK
ReplaceWithStoneBlock: NETHER_WART_BLOCK
SmoothRadius: 30
SmoothHeightOffset: 0
SmoothStartTop: false
SmoothStartWood: false
SmoothingSurfaceBlock: NETHER_WART_BLOCK
SmoothingGroundBlock: NETHER_WART_BLOCK

B(0,750,0,AIR)
B(15,750,15,AIR)
B(2,0,0,minecraft:nether_wart_block)
B(3,0,0,minecraft:nether_wart_block)
B(4,0,0,minecraft:nether_wart_block)
B(5,0,0,minecraft:nether_wart_block)
B(6,0,0,minecraft:nether_wart_block)
B(7,0,0,minecraft:nether_wart_block)
B(8,0,0,minecraft:nether_wart_block)
B(9,0,0,minecraft:nether_wart_block)
B(10,0,0,minecraft:nether_wart_block)
B(11,0,0,minecraft:nether_wart_block)
B(12,0,0,minecraft:nether_wart_block)
B(13,0,0,minecraft:nether_wart_block)
B(14,0,0,minecraft:nether_wart_block)
B(15,0,0,minecraft:nether_wart_block)
B(2,0,1,minecraft:nether_wart_block)
B(3,0,1,minecraft:nether_wart_block)
B(4,0,1,minecraft:nether_wart_block)
B(5,0,1,minecraft:nether_wart_block)
B(6,0,1,minecraft:nether_wart_block)
B(7,0,1,minecraft:nether_wart_block)
B(8,0,1,minecraft:nether_wart_block)
B(9,0,1,minecraft:nether_wart_block)
B(10,0,1,minecraft:nether_wart_block)
B(11,0,1,minecraft:nether_wart_block)
B(12,0,1,minecraft:nether_wart_block)
B(13,0,1,minecraft:nether_wart_block)
B(14,0,1,minecraft:nether_wart_block)
B(15,0,1,minecraft:nether_wart_block)
B(2,0,2,minecraft:nether_wart_block)
B(3,0,2,minecraft:nether_wart_block)
B(4,0,2,minecraft:nether_wart_block)
B(5,0,2,minecraft:nether_wart_block)
B(6,0,2,minecraft:nether_wart_block)
B(7,0,2,minecraft:nether_wart_block)
B(8,0,2,minecraft:nether_wart_block)
B(9,0,2,minecraft:nether_wart_block)
B(10,0,2,minecraft:nether_wart_block)
B(11,0,2,minecraft:nether_wart_block)
B(12,0,2,minecraft:nether_wart_block)
B(13,0,2,minecraft:nether_wart_block)
B(14,0,2,minecraft:nether_wart_block)
B(15,0,2,minecraft:nether_wart_block)
B(2,0,3,minecraft:nether_wart_block)
B(3,0,3,minecraft:nether_wart_block)
B(4,0,3,minecraft:nether_wart_block)
B(5,0,3,minecraft:nether_wart_block)
B(6,0,3,minecraft:nether_wart_block)
B(7,0,3,minecraft:nether_wart_block)
B(8,0,3,minecraft:nether_wart_block)
B(9,0,3,minecraft:nether_wart_block)
B(10,0,3,minecraft:nether_wart_block)
B(11,0,3,minecraft:nether_wart_block)
B(12,0,3,minecraft:nether_wart_block)
B(13,0,3,minecraft:nether_wart_block)
B(14,0,3,minecraft:nether_wart_block)
B(15,0,3,minecraft:nether_wart_block)
B(2,0,4,minecraft:nether_wart_block)
B(3,0,4,minecraft:nether_wart_block)
B(4,0,4,minecraft:nether_wart_block)
B(5,0,4,minecraft:nether_wart_block)
B(6,0,4,minecraft:nether_wart_block)
B(7,0,4,minecraft:nether_wart_block)
B(8,0,4,minecraft:nether_wart_block)
B(9,0,4,minecraft:nether_wart_block)
B(10,0,4,minecraft:nether_wart_block)
B(11,0,4,minecraft:nether_wart_block)
B(12,0,4,minecraft:nether_wart_block)
B(13,0,4,minecraft:nether_wart_block)
B(14,0,4,minecraft:nether_wart_block)
B(15,0,4,minecraft:nether_wart_block)
B(2,0,5,minecraft:nether_wart_block)
B(3,0,5,minecraft:nether_wart_block)
B(4,0,5,minecraft:nether_wart_block)
B(5,0,5,minecraft:nether_wart_block)
B(6,0,5,minecraft:nether_wart_block)
B(7,0,5,minecraft:nether_wart_block)
B(8,0,5,minecraft:nether_wart_block)
B(9,0,5,minecraft:nether_wart_block)
B(10,0,5,minecraft:nether_wart_block)
B(11,0,5,minecraft:nether_wart_block)
B(12,0,5,minecraft:nether_wart_block)
B(13,0,5,minecraft:nether_wart_block)
B(14,0,5,minecraft:nether_wart_block)
B(15,0,5,minecraft:nether_wart_block)
B(2,0,6,minecraft:nether_wart_block)
B(3,0,6,minecraft:nether_wart_block)
B(4,0,6,minecraft:nether_wart_block)
B(5,0,6,minecraft:nether_wart_block)
B(6,0,6,minecraft:nether_wart_block)
B(7,0,6,minecraft:nether_wart_block)
B(8,0,6,minecraft:nether_wart_block)
B(9,0,6,minecraft:nether_wart_block)
B(10,0,6,minecraft:nether_wart_block)
B(11,0,6,minecraft:nether_wart_block)
B(12,0,6,minecraft:nether_wart_block)
B(13,0,6,minecraft:nether_wart_block)
B(14,0,6,minecraft:nether_wart_block)
B(15,0,6,minecraft:nether_wart_block)
B(2,0,7,minecraft:nether_wart_block)
B(3,0,7,minecraft:nether_wart_block)
B(4,0,7,minecraft:nether_wart_block)
B(5,0,7,minecraft:nether_wart_block)
B(6,0,7,minecraft:nether_wart_block)
B(7,0,7,minecraft:nether_wart_block)
B(8,0,7,minecraft:nether_wart_block)
B(9,0,7,minecraft:nether_wart_block)
B(10,0,7,minecraft:nether_wart_block)
B(11,0,7,minecraft:nether_wart_block)
B(12,0,7,minecraft:nether_wart_block)
B(13,0,7,minecraft:nether_wart_block)
B(14,0,7,minecraft:nether_wart_block)
B(15,0,7,minecraft:nether_wart_block)
B(2,0,8,minecraft:nether_wart_block)
B(3,0,8,minecraft:nether_wart_block)
B(4,0,8,minecraft:nether_wart_block)
B(5,0,8,minecraft:nether_wart_block)
B(6,0,8,minecraft:nether_wart_block)
B(7,0,8,minecraft:nether_wart_block)
B(8,0,8,minecraft:nether_wart_block)
B(9,0,8,minecraft:nether_wart_block)
B(10,0,8,minecraft:nether_wart_block)
B(11,0,8,minecraft:nether_wart_block)
B(12,0,8,minecraft:nether_wart_block)
B(13,0,8,minecraft:nether_wart_block)
B(15,0,8,minecraft:nether_wart_block)
B(2,0,9,minecraft:nether_wart_block)
B(3,0,9,minecraft:nether_wart_block)
B(4,0,9,minecraft:nether_wart_block)
B(5,0,9,minecraft:nether_wart_block)
B(6,0,9,minecraft:nether_wart_block)
B(7,0,9,minecraft:nether_wart_block)
B(8,0,9,minecraft:nether_wart_block)
B(9,0,9,minecraft:nether_wart_block)
B(10,0,9,minecraft:nether_wart_block)
B(11,0,9,minecraft:nether_wart_block)
B(12,0,9,minecraft:nether_wart_block)
B(13,0,9,minecraft:nether_wart_block)
B(14,0,9,minecraft:nether_wart_block)
B(15,0,9,minecraft:nether_wart_block)
B(2,0,10,minecraft:nether_wart_block)
B(3,0,10,minecraft:nether_wart_block)
B(4,0,10,minecraft:nether_wart_block)
B(5,0,10,minecraft:nether_wart_block)
B(6,0,10,minecraft:nether_wart_block)
B(7,0,10,minecraft:nether_wart_block)
B(8,0,10,minecraft:nether_wart_block)
B(9,0,10,minecraft:nether_wart_block)
B(10,0,10,minecraft:nether_wart_block)
B(11,0,10,minecraft:nether_wart_block)
B(12,0,10,minecraft:nether_wart_block)
B(13,0,10,minecraft:nether_wart_block)
B(14,0,10,minecraft:nether_wart_block)
B(15,0,10,minecraft:nether_wart_block)
B(2,0,11,minecraft:nether_wart_block)
B(3,0,11,minecraft:nether_wart_block)
B(4,0,11,minecraft:nether_wart_block)
B(5,0,11,minecraft:nether_wart_block)
B(6,0,11,minecraft:nether_wart_block)
B(7,0,11,minecraft:nether_wart_block)
B(8,0,11,minecraft:nether_wart_block)
B(9,0,11,minecraft:nether_wart_block)
B(10,0,11,minecraft:nether_wart_block)
B(11,0,11,minecraft:nether_wart_block)
B(12,0,11,minecraft:nether_wart_block)
B(13,0,11,minecraft:nether_wart_block)
B(14,0,11,minecraft:nether_wart_block)
B(15,0,11,minecraft:nether_wart_block)
B(2,0,12,minecraft:nether_wart_block)
B(3,0,12,minecraft:nether_wart_block)
B(4,0,12,minecraft:nether_wart_block)
B(5,0,12,minecraft:nether_wart_block)
B(6,0,12,minecraft:nether_wart_block)
B(7,0,12,minecraft:nether_wart_block)
B(8,0,12,minecraft:nether_wart_block)
B(9,0,12,minecraft:nether_wart_block)
B(10,0,12,minecraft:nether_wart_block)
B(11,0,12,minecraft:nether_wart_block)
B(12,0,12,minecraft:nether_wart_block)
B(13,0,12,minecraft:nether_wart_block)
B(14,0,12,minecraft:nether_wart_block)
B(15,0,12,minecraft:nether_wart_block)
B(2,0,13,minecraft:nether_wart_block)
B(3,0,13,minecraft:nether_wart_block)
B(4,0,13,minecraft:nether_wart_block)
B(5,0,13,minecraft:nether_wart_block)
B(6,0,13,minecraft:nether_wart_block)
B(7,0,13,minecraft:nether_wart_block)
B(8,0,13,minecraft:nether_wart_block)
B(9,0,13,minecraft:nether_wart_block)
B(10,0,13,minecraft:nether_wart_block)
B(11,0,13,minecraft:nether_wart_block)
B(12,0,13,minecraft:nether_wart_block)
B(13,0,13,minecraft:nether_wart_block)
B(14,0,13,minecraft:nether_wart_block)
B(15,0,13,minecraft:nether_wart_block)
B(5,0,14,minecraft:nether_wart_block)
B(6,0,14,minecraft:nether_wart_block)
B(7,0,14,minecraft:nether_wart_block)
B(8,0,14,minecraft:nether_wart_block)
B(9,0,14,minecraft:nether_wart_block)
B(10,0,14,minecraft:nether_wart_block)
B(11,0,14,minecraft:nether_wart_block)
B(12,0,14,minecraft:nether_wart_block)
B(13,0,14,minecraft:nether_wart_block)
B(14,0,14,minecraft:nether_wart_block)
B(15,0,14,minecraft:nether_wart_block)
B(6,0,15,minecraft:nether_wart_block)
B(7,0,15,minecraft:nether_wart_block)
B(8,0,15,minecraft:nether_wart_block)
B(9,0,15,minecraft:nether_wart_block)
B(10,0,15,minecraft:nether_wart_block)
B(11,0,15,minecraft:nether_wart_block)
B(12,0,15,minecraft:nether_wart_block)
B(13,0,15,minecraft:nether_wart_block)
B(14,0,15,minecraft:nether_wart_block)
B(15,0,15,minecraft:nether_wart_block)
B(2,1,0,minecraft:nether_wart_block)
B(3,1,0,minecraft:nether_wart_block)
B(4,1,0,minecraft:nether_wart_block)
B(5,1,0,minecraft:nether_wart_block)
B(6,1,0,minecraft:nether_wart_block)
B(7,1,0,minecraft:nether_wart_block)
B(8,1,0,minecraft:nether_wart_block)
B(9,1,0,minecraft:nether_wart_block)
B(10,1,0,minecraft:nether_wart_block)
B(11,1,0,minecraft:nether_wart_block)
B(12,1,0,minecraft:nether_wart_block)
B(13,1,0,minecraft:nether_wart_block)
B(14,1,0,minecraft:nether_wart_block)
B(15,1,0,minecraft:nether_wart_block)
B(2,1,1,minecraft:nether_wart_block)
B(3,1,1,minecraft:nether_wart_block)
B(4,1,1,minecraft:nether_wart_block)
B(5,1,1,minecraft:nether_wart_block)
B(6,1,1,minecraft:nether_wart_block)
B(7,1,1,minecraft:nether_wart_block)
B(8,1,1,minecraft:nether_wart_block)
B(9,1,1,minecraft:nether_wart_block)
B(10,1,1,minecraft:nether_wart_block)
B(11,1,1,minecraft:nether_wart_block)
B(12,1,1,minecraft:nether_wart_block)
B(13,1,1,minecraft:nether_wart_block)
B(14,1,1,minecraft:nether_wart_block)
B(15,1,1,minecraft:nether_wart_block)
B(2,1,2,minecraft:nether_wart_block)
B(3,1,2,minecraft:nether_wart_block)
B(4,1,2,minecraft:nether_wart_block)
B(5,1,2,minecraft:nether_wart_block)
B(6,1,2,minecraft:nether_wart_block)
B(7,1,2,minecraft:nether_wart_block)
B(8,1,2,minecraft:nether_wart_block)
B(9,1,2,minecraft:nether_wart_block)
B(10,1,2,minecraft:nether_wart_block)
B(11,1,2,minecraft:nether_wart_block)
B(12,1,2,minecraft:nether_wart_block)
B(13,1,2,minecraft:nether_wart_block)
B(14,1,2,minecraft:nether_wart_block)
B(15,1,2,minecraft:nether_wart_block)
B(2,1,3,minecraft:nether_wart_block)
B(3,1,3,minecraft:nether_wart_block)
B(4,1,3,minecraft:nether_wart_block)
B(5,1,3,minecraft:nether_wart_block)
B(6,1,3,minecraft:nether_wart_block)
B(7,1,3,minecraft:nether_wart_block)
B(8,1,3,minecraft:nether_wart_block)
B(9,1,3,minecraft:nether_wart_block)
B(10,1,3,minecraft:nether_wart_block)
B(11,1,3,minecraft:nether_wart_block)
B(12,1,3,minecraft:nether_wart_block)
B(13,1,3,minecraft:nether_wart_block)
B(14,1,3,minecraft:nether_wart_block)
B(15,1,3,minecraft:nether_wart_block)
B(2,1,4,minecraft:nether_wart_block)
B(3,1,4,minecraft:nether_wart_block)
B(4,1,4,minecraft:nether_wart_block)
B(5,1,4,minecraft:nether_wart_block)
B(6,1,4,minecraft:nether_wart_block)
B(7,1,4,minecraft:nether_wart_block)
B(8,1,4,minecraft:nether_wart_block)
B(9,1,4,minecraft:nether_wart_block)
B(10,1,4,minecraft:nether_wart_block)
B(11,1,4,minecraft:nether_wart_block)
B(12,1,4,minecraft:nether_wart_block)
B(13,1,4,minecraft:nether_wart_block)
B(14,1,4,minecraft:nether_wart_block)
B(15,1,4,minecraft:nether_wart_block)
B(2,1,5,minecraft:nether_wart_block)
B(3,1,5,minecraft:nether_wart_block)
B(4,1,5,minecraft:nether_wart_block)
B(5,1,5,minecraft:nether_wart_block)
B(6,1,5,minecraft:nether_wart_block)
B(7,1,5,minecraft:nether_wart_block)
B(8,1,5,minecraft:nether_wart_block)
B(9,1,5,minecraft:nether_wart_block)
B(10,1,5,minecraft:nether_wart_block)
B(11,1,5,minecraft:nether_wart_block)
B(12,1,5,minecraft:nether_wart_block)
B(13,1,5,minecraft:nether_wart_block)
B(14,1,5,minecraft:nether_wart_block)
B(15,1,5,minecraft:nether_wart_block)
B(2,1,6,minecraft:nether_wart_block)
B(3,1,6,minecraft:nether_wart_block)
B(4,1,6,minecraft:nether_wart_block)
B(5,1,6,minecraft:nether_wart_block)
B(6,1,6,minecraft:nether_wart_block)
B(7,1,6,minecraft:nether_wart_block)
B(8,1,6,minecraft:nether_wart_block)
B(9,1,6,minecraft:nether_wart_block)
B(10,1,6,minecraft:nether_wart_block)
B(11,1,6,minecraft:nether_wart_block)
B(12,1,6,minecraft:nether_wart_block)
B(13,1,6,minecraft:nether_wart_block)
B(14,1,6,minecraft:nether_wart_block)
B(15,1,6,minecraft:nether_wart_block)
B(2,1,7,minecraft:nether_wart_block)
B(3,1,7,minecraft:nether_wart_block)
B(4,1,7,minecraft:nether_wart_block)
B(5,1,7,minecraft:nether_wart_block)
B(6,1,7,minecraft:nether_wart_block)
B(7,1,7,minecraft:nether_wart_block)
B(8,1,7,minecraft:nether_wart_block)
B(9,1,7,minecraft:nether_wart_block)
B(10,1,7,minecraft:nether_wart_block)
B(11,1,7,minecraft:nether_wart_block)
B(12,1,7,minecraft:nether_wart_block)
B(13,1,7,minecraft:nether_wart_block)
B(14,1,7,minecraft:nether_wart_block)
B(15,1,7,minecraft:nether_wart_block)
B(2,1,8,minecraft:nether_wart_block)
B(3,1,8,minecraft:nether_wart_block)
B(4,1,8,minecraft:nether_wart_block)
B(5,1,8,minecraft:nether_wart_block)
B(6,1,8,minecraft:nether_wart_block)
B(7,1,8,minecraft:nether_wart_block)
B(8,1,8,minecraft:nether_wart_block)
B(9,1,8,minecraft:nether_wart_block)
B(10,1,8,minecraft:nether_wart_block)
B(11,1,8,minecraft:nether_wart_block)
B(12,1,8,minecraft:nether_wart_block)
B(13,1,8,minecraft:nether_wart_block)
B(2,1,9,minecraft:nether_wart_block)
B(3,1,9,minecraft:nether_wart_block)
B(4,1,9,minecraft:nether_wart_block)
B(5,1,9,minecraft:nether_wart_block)
B(6,1,9,minecraft:nether_wart_block)
B(7,1,9,minecraft:nether_wart_block)
B(8,1,9,minecraft:nether_wart_block)
B(9,1,9,minecraft:nether_wart_block)
B(10,1,9,minecraft:nether_wart_block)
B(11,1,9,minecraft:nether_wart_block)
B(15,1,9,minecraft:nether_wart_block)
B(2,1,10,minecraft:nether_wart_block)
B(3,1,10,minecraft:nether_wart_block)
B(4,1,10,minecraft:nether_wart_block)
B(5,1,10,minecraft:nether_wart_block)
B(6,1,10,minecraft:nether_wart_block)
B(7,1,10,minecraft:nether_wart_block)
B(8,1,10,minecraft:nether_wart_block)
B(9,1,10,minecraft:nether_wart_block)
B(10,1,10,minecraft:nether_wart_block)
B(11,1,10,minecraft:nether_wart_block)
B(12,1,10,minecraft:nether_wart_block)
B(15,1,10,minecraft:nether_wart_block)
B(2,1,11,minecraft:nether_wart_block)
B(3,1,11,minecraft:nether_wart_block)
B(4,1,11,minecraft:nether_wart_block)
B(5,1,11,minecraft:nether_wart_block)
B(6,1,11,minecraft:nether_wart_block)
B(7,1,11,minecraft:nether_wart_block)
B(8,1,11,minecraft:nether_wart_block)
B(9,1,11,minecraft:nether_wart_block)
B(10,1,11,minecraft:nether_wart_block)
B(11,1,11,minecraft:nether_wart_block)
B(12,1,11,minecraft:nether_wart_block)
B(13,1,11,minecraft:nether_wart_block)
B(14,1,11,minecraft:nether_wart_block)
B(15,1,11,minecraft:nether_wart_block)
B(2,1,12,minecraft:nether_wart_block)
B(3,1,12,minecraft:nether_wart_block)
B(4,1,12,minecraft:nether_wart_block)
B(5,1,12,minecraft:nether_wart_block)
B(6,1,12,minecraft:nether_wart_block)
B(7,1,12,minecraft:nether_wart_block)
B(8,1,12,minecraft:nether_wart_block)
B(9,1,12,minecraft:nether_wart_block)
B(10,1,12,minecraft:nether_wart_block)
B(11,1,12,minecraft:nether_wart_block)
B(12,1,12,minecraft:nether_wart_block)
B(13,1,12,minecraft:nether_wart_block)
B(14,1,12,minecraft:nether_wart_block)
B(15,1,12,minecraft:nether_wart_block)
B(6,1,13,minecraft:nether_wart_block)
B(7,1,13,minecraft:nether_wart_block)
B(8,1,13,minecraft:nether_wart_block)
B(9,1,13,minecraft:nether_wart_block)
B(10,1,13,minecraft:nether_wart_block)
B(11,1,13,minecraft:nether_wart_block)
B(12,1,13,minecraft:nether_wart_block)
B(13,1,13,minecraft:nether_wart_block)
B(14,1,13,minecraft:nether_wart_block)
B(15,1,13,minecraft:nether_wart_block)
B(7,1,14,minecraft:nether_wart_block)
B(8,1,14,minecraft:nether_wart_block)
B(9,1,14,minecraft:nether_wart_block)
B(10,1,14,minecraft:nether_wart_block)
B(11,1,14,minecraft:nether_wart_block)
B(12,1,14,minecraft:nether_wart_block)
B(13,1,14,minecraft:nether_wart_block)
B(14,1,14,minecraft:nether_wart_block)
B(15,1,14,minecraft:nether_wart_block)
B(8,1,15,minecraft:nether_wart_block)
B(9,1,15,minecraft:nether_wart_block)
B(10,1,15,minecraft:nether_wart_block)
B(11,1,15,minecraft:nether_wart_block)
B(12,1,15,minecraft:nether_wart_block)
B(13,1,15,minecraft:nether_wart_block)
B(14,1,15,minecraft:nether_wart_block)
B(15,1,15,minecraft:nether_wart_block)
B(2,2,0,minecraft:nether_wart_block)
B(3,2,0,minecraft:nether_wart_block)
B(4,2,0,minecraft:nether_wart_block)
B(5,2,0,minecraft:nether_wart_block)
B(6,2,0,minecraft:nether_wart_block)
B(7,2,0,minecraft:nether_wart_block)
B(8,2,0,minecraft:nether_wart_block)
B(9,2,0,minecraft:nether_wart_block)
B(10,2,0,minecraft:nether_wart_block)
B(11,2,0,minecraft:nether_wart_block)
B(12,2,0,minecraft:nether_wart_block)
B(13,2,0,minecraft:nether_wart_block)
B(14,2,0,minecraft:nether_wart_block)
B(15,2,0,minecraft:nether_wart_block)
B(3,2,1,minecraft:nether_wart_block)
B(4,2,1,minecraft:nether_wart_block)
B(5,2,1,minecraft:nether_wart_block)
B(6,2,1,minecraft:nether_wart_block)
B(7,2,1,minecraft:nether_wart_block)
B(8,2,1,minecraft:nether_wart_block)
B(9,2,1,minecraft:nether_wart_block)
B(10,2,1,minecraft:nether_wart_block)
B(11,2,1,minecraft:nether_wart_block)
B(12,2,1,minecraft:nether_wart_block)
B(13,2,1,minecraft:nether_wart_block)
B(14,2,1,minecraft:nether_wart_block)
B(15,2,1,minecraft:nether_wart_block)
B(3,2,2,minecraft:nether_wart_block)
B(4,2,2,minecraft:nether_wart_block)
B(5,2,2,minecraft:nether_wart_block)
B(6,2,2,minecraft:nether_wart_block)
B(7,2,2,minecraft:nether_wart_block)
B(8,2,2,minecraft:nether_wart_block)
B(9,2,2,minecraft:nether_wart_block)
B(10,2,2,minecraft:nether_wart_block)
B(11,2,2,minecraft:nether_wart_block)
B(12,2,2,minecraft:nether_wart_block)
B(13,2,2,minecraft:nether_wart_block)
B(14,2,2,minecraft:nether_wart_block)
B(15,2,2,minecraft:nether_wart_block)
B(3,2,3,minecraft:nether_wart_block)
B(4,2,3,minecraft:nether_wart_block)
B(5,2,3,minecraft:nether_wart_block)
B(6,2,3,minecraft:nether_wart_block)
B(7,2,3,minecraft:nether_wart_block)
B(8,2,3,minecraft:nether_wart_block)
B(9,2,3,minecraft:nether_wart_block)
B(10,2,3,minecraft:nether_wart_block)
B(11,2,3,minecraft:nether_wart_block)
B(12,2,3,minecraft:nether_wart_block)
B(13,2,3,minecraft:nether_wart_block)
B(14,2,3,minecraft:nether_wart_block)
B(15,2,3,minecraft:nether_wart_block)
B(3,2,4,minecraft:nether_wart_block)
B(4,2,4,minecraft:nether_wart_block)
B(5,2,4,minecraft:nether_wart_block)
B(6,2,4,minecraft:nether_wart_block)
B(7,2,4,minecraft:nether_wart_block)
B(8,2,4,minecraft:nether_wart_block)
B(9,2,4,minecraft:nether_wart_block)
B(10,2,4,minecraft:nether_wart_block)
B(11,2,4,minecraft:nether_wart_block)
B(12,2,4,minecraft:nether_wart_block)
B(13,2,4,minecraft:nether_wart_block)
B(14,2,4,minecraft:nether_wart_block)
B(15,2,4,minecraft:nether_wart_block)
B(2,2,5,minecraft:nether_wart_block)
B(3,2,5,minecraft:nether_wart_block)
B(4,2,5,minecraft:nether_wart_block)
B(5,2,5,minecraft:nether_wart_block)
B(6,2,5,minecraft:nether_wart_block)
B(7,2,5,minecraft:nether_wart_block)
B(8,2,5,minecraft:nether_wart_block)
B(9,2,5,minecraft:nether_wart_block)
B(10,2,5,minecraft:nether_wart_block)
B(11,2,5,minecraft:nether_wart_block)
B(12,2,5,minecraft:nether_wart_block)
B(13,2,5,minecraft:nether_wart_block)
B(14,2,5,minecraft:nether_wart_block)
B(15,2,5,minecraft:nether_wart_block)
B(2,2,6,minecraft:nether_wart_block)
B(3,2,6,minecraft:nether_wart_block)
B(4,2,6,minecraft:nether_wart_block)
B(5,2,6,minecraft:nether_wart_block)
B(6,2,6,minecraft:nether_wart_block)
B(7,2,6,minecraft:nether_wart_block)
B(8,2,6,minecraft:nether_wart_block)
B(9,2,6,minecraft:nether_wart_block)
B(10,2,6,minecraft:nether_wart_block)
B(11,2,6,minecraft:nether_wart_block)
B(12,2,6,minecraft:nether_wart_block)
B(13,2,6,minecraft:nether_wart_block)
B(14,2,6,minecraft:nether_wart_block)
B(15,2,6,minecraft:nether_wart_block)
B(2,2,7,minecraft:nether_wart_block)
B(3,2,7,minecraft:nether_wart_block)
B(4,2,7,minecraft:nether_wart_block)
B(5,2,7,minecraft:nether_wart_block)
B(6,2,7,minecraft:nether_wart_block)
B(7,2,7,minecraft:nether_wart_block)
B(8,2,7,minecraft:nether_wart_block)
B(9,2,7,minecraft:nether_wart_block)
B(10,2,7,minecraft:nether_wart_block)
B(11,2,7,minecraft:nether_wart_block)
B(12,2,7,minecraft:nether_wart_block)
B(13,2,7,minecraft:nether_wart_block)
B(14,2,7,minecraft:nether_wart_block)
B(15,2,7,minecraft:nether_wart_block)
B(2,2,8,minecraft:nether_wart_block)
B(3,2,8,minecraft:nether_wart_block)
B(4,2,8,minecraft:nether_wart_block)
B(5,2,8,minecraft:nether_wart_block)
B(6,2,8,minecraft:nether_wart_block)
B(7,2,8,minecraft:nether_wart_block)
B(8,2,8,minecraft:nether_wart_block)
B(9,2,8,minecraft:nether_wart_block)
B(10,2,8,minecraft:nether_wart_block)
B(11,2,8,minecraft:nether_wart_block)
B(12,2,8,minecraft:nether_wart_block)
B(13,2,8,minecraft:nether_wart_block)
B(2,2,9,minecraft:nether_wart_block)
B(3,2,9,minecraft:nether_wart_block)
B(4,2,9,minecraft:nether_wart_block)
B(5,2,9,minecraft:nether_wart_block)
B(6,2,9,minecraft:nether_wart_block)
B(7,2,9,minecraft:nether_wart_block)
B(8,2,9,minecraft:nether_wart_block)
B(9,2,9,minecraft:nether_wart_block)
B(10,2,9,minecraft:nether_wart_block)
B(11,2,9,minecraft:nether_wart_block)
B(15,2,9,minecraft:nether_wart_block)
B(2,2,10,minecraft:nether_wart_block)
B(3,2,10,minecraft:nether_wart_block)
B(4,2,10,minecraft:nether_wart_block)
B(5,2,10,minecraft:nether_wart_block)
B(6,2,10,minecraft:nether_wart_block)
B(7,2,10,minecraft:nether_wart_block)
B(8,2,10,minecraft:nether_wart_block)
B(9,2,10,minecraft:nether_wart_block)
B(10,2,10,minecraft:nether_wart_block)
B(11,2,10,minecraft:nether_wart_block)
B(12,2,10,minecraft:nether_wart_block)
B(15,2,10,minecraft:nether_wart_block)
B(3,2,11,minecraft:nether_wart_block)
B(4,2,11,minecraft:nether_wart_block)
B(5,2,11,minecraft:nether_wart_block)
B(6,2,11,minecraft:nether_wart_block)
B(7,2,11,minecraft:nether_wart_block)
B(8,2,11,minecraft:nether_wart_block)
B(9,2,11,minecraft:nether_wart_block)
B(10,2,11,minecraft:nether_wart_block)
B(11,2,11,minecraft:nether_wart_block)
B(7,2,12,minecraft:nether_wart_block)
B(8,2,12,minecraft:nether_wart_block)
B(9,2,12,minecraft:nether_wart_block)
B(10,2,12,minecraft:nether_wart_block)
B(8,2,13,minecraft:nether_wart_block)
B(9,2,13,minecraft:nether_wart_block)
B(4,3,0,minecraft:nether_wart_block)
B(5,3,0,minecraft:nether_wart_block)
B(6,3,0,minecraft:nether_wart_block)
B(7,3,0,minecraft:nether_wart_block)
B(8,3,0,minecraft:nether_wart_block)
B(9,3,0,minecraft:nether_wart_block)
B(10,3,0,minecraft:nether_wart_block)
B(11,3,0,minecraft:nether_wart_block)
B(12,3,0,minecraft:nether_wart_block)
B(13,3,0,minecraft:nether_wart_block)
B(14,3,0,minecraft:nether_wart_block)
B(15,3,0,minecraft:nether_wart_block)
B(4,3,1,minecraft:nether_wart_block)
B(5,3,1,minecraft:nether_wart_block)
B(6,3,1,minecraft:nether_wart_block)
B(7,3,1,minecraft:nether_wart_block)
B(8,3,1,minecraft:nether_wart_block)
B(9,3,1,minecraft:nether_wart_block)
B(10,3,1,minecraft:nether_wart_block)
B(11,3,1,minecraft:nether_wart_block)
B(12,3,1,minecraft:nether_wart_block)
B(13,3,1,minecraft:nether_wart_block)
B(14,3,1,minecraft:nether_wart_block)
B(15,3,1,minecraft:nether_wart_block)
B(4,3,2,minecraft:nether_wart_block)
B(5,3,2,minecraft:nether_wart_block)
B(6,3,2,minecraft:nether_wart_block)
B(7,3,2,minecraft:nether_wart_block)
B(8,3,2,minecraft:nether_wart_block)
B(9,3,2,minecraft:nether_wart_block)
B(10,3,2,minecraft:nether_wart_block)
B(11,3,2,minecraft:nether_wart_block)
B(12,3,2,minecraft:nether_wart_block)
B(13,3,2,minecraft:nether_wart_block)
B(14,3,2,minecraft:nether_wart_block)
B(15,3,2,minecraft:nether_wart_block)
B(5,3,3,minecraft:nether_wart_block)
B(6,3,3,minecraft:nether_wart_block)
B(7,3,3,minecraft:nether_wart_block)
B(8,3,3,minecraft:nether_wart_block)
B(9,3,3,minecraft:nether_wart_block)
B(10,3,3,minecraft:nether_wart_block)
B(11,3,3,minecraft:nether_wart_block)
B(12,3,3,minecraft:nether_wart_block)
B(13,3,3,minecraft:nether_wart_block)
B(14,3,3,minecraft:nether_wart_block)
B(15,3,3,minecraft:nether_wart_block)
B(6,3,4,minecraft:nether_wart_block)
B(7,3,4,minecraft:nether_wart_block)
B(8,3,4,minecraft:nether_wart_block)
B(9,3,4,minecraft:nether_wart_block)
B(10,3,4,minecraft:nether_wart_block)
B(11,3,4,minecraft:nether_wart_block)
B(12,3,4,minecraft:nether_wart_block)
B(13,3,4,minecraft:nether_wart_block)
B(14,3,4,minecraft:nether_wart_block)
B(15,3,4,minecraft:nether_wart_block)
B(6,3,5,minecraft:nether_wart_block)
B(7,3,5,minecraft:nether_wart_block)
B(8,3,5,minecraft:nether_wart_block)
B(9,3,5,minecraft:nether_wart_block)
B(10,3,5,minecraft:nether_wart_block)
B(11,3,5,minecraft:nether_wart_block)
B(12,3,5,minecraft:nether_wart_block)
B(13,3,5,minecraft:nether_wart_block)
B(14,3,5,minecraft:nether_wart_block)
B(15,3,5,minecraft:nether_wart_block)
B(4,3,6,minecraft:nether_wart_block)
B(5,3,6,minecraft:nether_wart_block)
B(6,3,6,minecraft:nether_wart_block)
B(7,3,6,minecraft:nether_wart_block)
B(8,3,6,minecraft:nether_wart_block)
B(9,3,6,minecraft:nether_wart_block)
B(10,3,6,minecraft:nether_wart_block)
B(11,3,6,minecraft:nether_wart_block)
B(12,3,6,minecraft:nether_wart_block)
B(13,3,6,minecraft:nether_wart_block)
B(14,3,6,minecraft:nether_wart_block)
B(15,3,6,minecraft:nether_wart_block)
B(3,3,7,minecraft:nether_wart_block)
B(4,3,7,minecraft:nether_wart_block)
B(5,3,7,minecraft:nether_wart_block)
B(6,3,7,minecraft:nether_wart_block)
B(7,3,7,minecraft:nether_wart_block)
B(8,3,7,minecraft:nether_wart_block)
B(9,3,7,minecraft:nether_wart_block)
B(10,3,7,minecraft:nether_wart_block)
B(11,3,7,minecraft:nether_wart_block)
B(12,3,7,minecraft:nether_wart_block)
B(13,3,7,minecraft:nether_wart_block)
B(14,3,7,minecraft:nether_wart_block)
B(15,3,7,minecraft:nether_wart_block)
B(3,3,8,minecraft:nether_wart_block)
B(4,3,8,minecraft:nether_wart_block)
B(5,3,8,minecraft:nether_wart_block)
B(9,3,8,minecraft:nether_wart_block)
B(10,3,8,minecraft:nether_wart_block)
B(11,3,8,minecraft:nether_wart_block)
B(12,3,8,minecraft:nether_wart_block)
B(13,3,8,minecraft:nether_wart_block)
B(4,3,9,minecraft:nether_wart_block)
B(15,3,9,minecraft:nether_wart_block)
B(5,4,0,minecraft:nether_wart_block)
B(6,4,0,minecraft:nether_wart_block)
B(7,4,0,minecraft:nether_wart_block)
B(8,4,0,minecraft:nether_wart_block)
B(9,4,0,minecraft:nether_wart_block)
B(10,4,0,minecraft:nether_wart_block)
B(11,4,0,minecraft:nether_wart_block)
B(12,4,0,minecraft:nether_wart_block)
B(13,4,0,minecraft:nether_wart_block)
B(14,4,0,minecraft:nether_wart_block)
B(15,4,0,minecraft:nether_wart_block)
B(6,4,1,minecraft:nether_wart_block)
B(7,4,1,minecraft:nether_wart_block)
B(8,4,1,minecraft:nether_wart_block)
B(9,4,1,minecraft:nether_wart_block)
B(10,4,1,minecraft:nether_wart_block)
B(11,4,1,minecraft:nether_wart_block)
B(12,4,1,minecraft:nether_wart_block)
B(13,4,1,minecraft:nether_wart_block)
B(14,4,1,minecraft:nether_wart_block)
B(15,4,1,minecraft:nether_wart_block)
B(7,4,2,minecraft:nether_wart_block)
B(8,4,2,minecraft:nether_wart_block)
B(9,4,2,minecraft:nether_wart_block)
B(10,4,2,minecraft:nether_wart_block)
B(11,4,2,minecraft:nether_wart_block)
B(12,4,2,minecraft:nether_wart_block)
B(13,4,2,minecraft:nether_wart_block)
B(14,4,2,minecraft:nether_wart_block)
B(15,4,2,minecraft:nether_wart_block)
B(7,4,3,minecraft:nether_wart_block)
B(8,4,3,minecraft:nether_wart_block)
B(9,4,3,minecraft:nether_wart_block)
B(10,4,3,minecraft:nether_wart_block)
B(11,4,3,minecraft:nether_wart_block)
B(12,4,3,minecraft:nether_wart_block)
B(13,4,3,minecraft:nether_wart_block)
B(14,4,3,minecraft:nether_wart_block)
B(15,4,3,minecraft:nether_wart_block)
B(7,4,4,minecraft:nether_wart_block)
B(8,4,4,minecraft:nether_wart_block)
B(9,4,4,minecraft:nether_wart_block)
B(10,4,4,minecraft:nether_wart_block)
B(11,4,4,minecraft:nether_wart_block)
B(12,4,4,minecraft:nether_wart_block)
B(13,4,4,minecraft:nether_wart_block)
B(14,4,4,minecraft:nether_wart_block)
B(15,4,4,minecraft:nether_wart_block)
B(7,4,5,minecraft:nether_wart_block)
B(8,4,5,minecraft:nether_wart_block)
B(9,4,5,minecraft:nether_wart_block)
B(10,4,5,minecraft:nether_wart_block)
B(11,4,5,minecraft:nether_wart_block)
B(12,4,5,minecraft:nether_wart_block)
B(13,4,5,minecraft:nether_wart_block)
B(14,4,5,minecraft:nether_wart_block)
B(15,4,5,minecraft:nether_wart_block)
B(9,4,6,minecraft:nether_wart_block)
B(10,4,6,minecraft:nether_wart_block)
B(11,4,6,minecraft:nether_wart_block)
B(12,4,6,minecraft:nether_wart_block)
B(13,4,6,minecraft:nether_wart_block)
B(14,4,6,minecraft:nether_wart_block)
B(15,4,6,minecraft:nether_wart_block)
B(9,4,7,minecraft:nether_wart_block)
B(10,4,7,minecraft:nether_wart_block)
B(11,4,7,minecraft:nether_wart_block)
B(12,4,7,minecraft:nether_wart_block)
B(13,4,7,minecraft:nether_wart_block)
B(14,4,7,minecraft:nether_wart_block)
B(15,4,7,minecraft:nether_wart_block)
B(8,5,0,minecraft:nether_wart_block)
B(9,5,0,minecraft:nether_wart_block)
B(10,5,0,minecraft:nether_wart_block)
B(11,5,0,minecraft:nether_wart_block)
B(12,5,0,minecraft:nether_wart_block)
B(13,5,0,minecraft:nether_wart_block)
B(14,5,0,minecraft:nether_wart_block)
B(15,5,0,minecraft:nether_wart_block)
B(7,5,1,minecraft:nether_wart_block)
B(8,5,1,minecraft:nether_wart_block)
B(9,5,1,minecraft:nether_wart_block)
B(10,5,1,minecraft:nether_wart_block)
B(11,5,1,minecraft:nether_wart_block)
B(12,5,1,minecraft:nether_wart_block)
B(13,5,1,minecraft:nether_wart_block)
B(14,5,1,minecraft:nether_wart_block)
B(15,5,1,minecraft:nether_wart_block)
B(7,5,2,minecraft:nether_wart_block)
B(8,5,2,minecraft:nether_wart_block)
B(9,5,2,minecraft:nether_wart_block)
B(10,5,2,minecraft:nether_wart_block)
B(11,5,2,minecraft:nether_wart_block)
B(12,5,2,minecraft:nether_wart_block)
B(13,5,2,minecraft:nether_wart_block)
B(14,5,2,minecraft:nether_wart_block)
B(15,5,2,minecraft:nether_wart_block)
B(7,5,3,minecraft:nether_wart_block)
B(8,5,3,minecraft:nether_wart_block)
B(9,5,3,minecraft:nether_wart_block)
B(10,5,3,minecraft:nether_wart_block)
B(11,5,3,minecraft:nether_wart_block)
B(12,5,3,minecraft:nether_wart_block)
B(13,5,3,minecraft:nether_wart_block)
B(14,5,3,minecraft:nether_wart_block)
B(15,5,3,minecraft:nether_wart_block)
B(7,5,4,minecraft:nether_wart_block)
B(8,5,4,minecraft:nether_wart_block)
B(9,5,4,minecraft:nether_wart_block)
B(10,5,4,minecraft:nether_wart_block)
B(11,5,4,minecraft:nether_wart_block)
B(12,5,4,minecraft:nether_wart_block)
B(13,5,4,minecraft:nether_wart_block)
B(14,5,4,minecraft:nether_wart_block)
B(15,5,4,minecraft:nether_wart_block)
B(7,5,5,minecraft:nether_wart_block)
B(8,5,5,minecraft:nether_wart_block)
B(9,5,5,minecraft:nether_wart_block)
B(10,5,5,minecraft:nether_wart_block)
B(11,5,5,minecraft:nether_wart_block)
B(12,5,5,minecraft:nether_wart_block)
B(13,5,5,minecraft:nether_wart_block)
B(14,5,5,minecraft:nether_wart_block)
B(15,5,5,minecraft:nether_wart_block)
B(9,5,6,minecraft:nether_wart_block)
B(10,5,6,minecraft:nether_wart_block)
B(11,5,6,minecraft:nether_wart_block)
B(12,5,6,minecraft:nether_wart_block)
B(13,5,6,minecraft:nether_wart_block)
B(14,5,6,minecraft:nether_wart_block)
B(15,5,6,minecraft:nether_wart_block)
B(14,5,7,minecraft:nether_wart_block)
B(15,5,7,minecraft:nether_wart_block)
B(9,6,0,minecraft:nether_wart_block)
B(10,6,0,minecraft:nether_wart_block)
B(11,6,0,minecraft:nether_wart_block)
B(12,6,0,minecraft:nether_wart_block)
B(13,6,0,minecraft:nether_wart_block)
B(14,6,0,minecraft:nether_wart_block)
B(15,6,0,minecraft:nether_wart_block)
B(8,6,1,minecraft:nether_wart_block)
B(9,6,1,minecraft:nether_wart_block)
B(10,6,1,minecraft:nether_wart_block)
B(11,6,1,minecraft:nether_wart_block)
B(12,6,1,minecraft:nether_wart_block)
B(13,6,1,minecraft:nether_wart_block)
B(14,6,1,minecraft:nether_wart_block)
B(15,6,1,minecraft:nether_wart_block)
B(8,6,2,minecraft:nether_wart_block)
B(9,6,2,minecraft:nether_wart_block)
B(10,6,2,minecraft:nether_wart_block)
B(11,6,2,minecraft:nether_wart_block)
B(12,6,2,minecraft:nether_wart_block)
B(13,6,2,minecraft:nether_wart_block)
B(14,6,2,minecraft:nether_wart_block)
B(15,6,2,minecraft:nether_wart_block)
B(8,6,3,minecraft:nether_wart_block)
B(9,6,3,minecraft:nether_wart_block)
B(10,6,3,minecraft:nether_wart_block)
B(11,6,3,minecraft:nether_wart_block)
B(12,6,3,minecraft:nether_wart_block)
B(13,6,3,minecraft:nether_wart_block)
B(14,6,3,minecraft:nether_wart_block)
B(15,6,3,minecraft:nether_wart_block)
B(9,6,4,minecraft:nether_wart_block)
B(10,6,4,minecraft:nether_wart_block)
B(11,6,4,minecraft:nether_wart_block)
B(12,6,4,minecraft:nether_wart_block)
B(13,6,4,minecraft:nether_wart_block)
B(14,6,4,minecraft:nether_wart_block)
B(15,6,4,minecraft:nether_wart_block)
B(10,6,5,minecraft:nether_wart_block)
B(11,6,5,minecraft:nether_wart_block)
B(12,6,5,minecraft:nether_wart_block)
B(13,6,5,minecraft:nether_wart_block)
B(14,6,5,minecraft:nether_wart_block)
B(15,6,5,minecraft:nether_wart_block)
B(13,6,6,minecraft:nether_wart_block)
B(14,6,6,minecraft:nether_wart_block)
B(15,6,6,minecraft:nether_wart_block)
B(15,6,7,minecraft:nether_wart_block)
B(11,7,0,minecraft:nether_wart_block)
B(12,7,0,minecraft:nether_wart_block)
B(13,7,0,minecraft:nether_wart_block)
B(14,7,0,minecraft:nether_wart_block)
B(15,7,0,minecraft:nether_wart_block)
B(10,7,1,minecraft:nether_wart_block)
B(11,7,1,minecraft:nether_wart_block)
B(12,7,1,minecraft:nether_wart_block)
B(13,7,1,minecraft:nether_wart_block)
B(14,7,1,minecraft:nether_wart_block)
B(15,7,1,minecraft:nether_wart_block)
B(10,7,2,minecraft:nether_wart_block)
B(11,7,2,minecraft:nether_wart_block)
B(12,7,2,minecraft:nether_wart_block)
B(13,7,2,minecraft:nether_wart_block)
B(14,7,2,minecraft:nether_wart_block)
B(15,7,2,minecraft:nether_wart_block)
B(10,7,3,minecraft:nether_wart_block)
B(11,7,3,minecraft:nether_wart_block)
B(12,7,3,minecraft:nether_wart_block)
B(13,7,3,minecraft:nether_wart_block)
B(14,7,3,minecraft:nether_wart_block)
B(15,7,3,minecraft:nether_wart_block)
B(11,7,4,minecraft:nether_wart_block)
B(12,7,4,minecraft:nether_wart_block)
B(13,7,4,minecraft:nether_wart_block)
B(14,7,4,minecraft:nether_wart_block)
B(15,7,4,minecraft:nether_wart_block)
B(13,7,5,minecraft:nether_wart_block)
B(14,7,5,minecraft:nether_wart_block)
B(15,7,5,minecraft:nether_wart_block)
B(15,7,6,minecraft:nether_wart_block)
B(11,8,0,minecraft:nether_wart_block)
B(12,8,0,minecraft:nether_wart_block)
B(13,8,0,minecraft:nether_wart_block)
B(14,8,0,minecraft:nether_wart_block)
B(15,8,0,minecraft:nether_wart_block)
B(11,8,1,minecraft:nether_wart_block)
B(12,8,1,minecraft:nether_wart_block)
B(13,8,1,minecraft:nether_wart_block)
B(14,8,1,minecraft:nether_wart_block)
B(15,8,1,minecraft:nether_wart_block)
B(11,8,2,minecraft:nether_wart_block)
B(12,8,2,minecraft:nether_wart_block)
B(13,8,2,minecraft:nether_wart_block)
B(14,8,2,minecraft:nether_wart_block)
B(15,8,2,minecraft:nether_wart_block)
B(12,8,3,minecraft:nether_wart_block)
B(13,8,3,minecraft:nether_wart_block)
B(14,8,3,minecraft:nether_wart_block)
B(15,8,3,minecraft:nether_wart_block)
B(13,8,4,minecraft:nether_wart_block)
B(14,8,4,minecraft:nether_wart_block)
B(15,8,4,minecraft:nether_wart_block)
B(14,8,5,minecraft:nether_wart_block)
B(15,8,5,minecraft:nether_wart_block)
B(11,9,0,minecraft:nether_wart_block)
B(12,9,0,minecraft:nether_wart_block)
B(13,9,0,minecraft:nether_wart_block)
B(14,9,0,minecraft:nether_wart_block)
B(15,9,0,minecraft:nether_wart_block)
B(12,9,1,minecraft:nether_wart_block)
B(13,9,1,minecraft:nether_wart_block)
B(14,9,1,minecraft:nether_wart_block)
B(15,9,1,minecraft:nether_wart_block)
B(12,9,2,minecraft:nether_wart_block)
B(13,9,2,minecraft:nether_wart_block)
B(14,9,2,minecraft:nether_wart_block)
B(15,9,2,minecraft:nether_wart_block)
B(13,9,3,minecraft:nether_wart_block)
B(14,9,3,minecraft:nether_wart_block)
B(15,9,3,minecraft:nether_wart_block)
B(14,9,4,minecraft:nether_wart_block)
B(15,9,4,minecraft:nether_wart_block)
B(15,9,5,minecraft:nether_wart_block)
B(11,10,0,minecraft:nether_wart_block)
B(12,10,0,minecraft:nether_wart_block)
B(13,10,0,minecraft:nether_wart_block)
B(14,10,0,minecraft:nether_wart_block)
B(15,10,0,minecraft:nether_wart_block)
B(13,10,1,minecraft:nether_wart_block)
B(14,10,1,minecraft:nether_wart_block)
B(15,10,1,minecraft:nether_wart_block)
B(13,10,2,minecraft:nether_wart_block)
B(14,10,2,minecraft:nether_wart_block)
B(15,10,2,minecraft:nether_wart_block)
B(14,10,3,minecraft:nether_wart_block)
B(15,10,3,minecraft:nether_wart_block)
B(15,10,4,minecraft:nether_wart_block)
B(11,11,0,minecraft:nether_wart_block)
B(12,11,0,minecraft:nether_wart_block)
B(13,11,0,minecraft:nether_wart_block)
B(14,11,0,minecraft:nether_wart_block)
B(15,11,0,minecraft:nether_wart_block)
B(13,11,1,minecraft:nether_wart_block)
B(14,11,1,minecraft:nether_wart_block)
B(15,11,1,minecraft:nether_wart_block)
B(14,11,2,minecraft:nether_wart_block)
B(15,11,2,minecraft:nether_wart_block)
B(15,11,3,minecraft:nether_wart_block)
B(12,12,0,minecraft:nether_wart_block)
B(13,12,0,minecraft:nether_wart_block)
B(14,12,0,minecraft:nether_wart_block)
B(15,12,0,minecraft:nether_wart_block)
B(14,12,1,minecraft:nether_wart_block)
B(15,12,1,minecraft:nether_wart_block)
B(15,12,2,minecraft:nether_wart_block)
B(15,12,3,minecraft:nether_wart_block)
B(13,13,0,minecraft:nether_wart_block)
B(14,13,0,minecraft:nether_wart_block)
B(15,13,0,minecraft:nether_wart_block)
B(15,13,1,minecraft:nether_wart_block)
B(15,13,2,minecraft:nether_wart_block)
B(14,14,0,minecraft:nether_wart_block)
B(15,14,0,minecraft:nether_wart_block)
B(14,15,0,minecraft:nether_wart_block)
B(15,15,0,minecraft:nether_wart_block)
B(15,16,0,minecraft:nether_wart_block)

