Author: Bo3 BulkEdit

Description: Converted Schematic - Modified by Bo3BulkEdit

Version: 3

SettingsMode: WriteDisable

IsOTGPlus: true
Tree: false
Frequency: 10
Rarity: 100
RotateRandomly: true
SpawnHeight: randomY
SpawnHeightOffset: 0
SpawnHeightVariance: 0
MaxBranchDepth: 10
ExcludedBiomes: All

MinHeight: 50
MaxHeight: 65

SourceBlocks: AIR
MaxPercentageOutsideSourceBlock: 100
OutsideSourceBlock: placeAnyway

ReplaceBelow: NETHER_WART_BLOCK
ReplaceWithBiomeBlocks: false
ReplaceWithGroundBlock: NETHER_WART_BLOCK
ReplaceWithSurfaceBlock: NETHER_WART_BLOCK
ReplaceWithStoneBlock: NETHER_WART_BLOCK
SmoothRadius: 30
SmoothHeightOffset: 0
SmoothStartTop: false
SmoothStartWood: false
SmoothingSurfaceBlock: NETHER_WART_BLOCK
SmoothingGroundBlock: NETHER_WART_BLOCK

B(0,750,0,AIR)
B(15,750,15,AIR)
B(0,0,5,minecraft:nether_wart_block)
B(1,0,5,minecraft:nether_wart_block)
B(2,0,5,minecraft:nether_wart_block)
B(3,0,5,minecraft:nether_wart_block)
B(4,0,5,minecraft:nether_wart_block)
B(5,0,5,minecraft:nether_wart_block)
B(0,0,6,minecraft:nether_wart_block)
B(1,0,6,minecraft:nether_wart_block)
B(2,0,6,minecraft:nether_wart_block)
B(3,0,6,minecraft:nether_wart_block)
B(4,0,6,minecraft:nether_wart_block)
B(5,0,6,minecraft:nether_wart_block)
B(6,0,6,minecraft:nether_wart_block)
B(7,0,6,minecraft:nether_wart_block)
B(8,0,6,minecraft:nether_wart_block)
B(0,0,7,minecraft:nether_wart_block)
B(1,0,7,minecraft:nether_wart_block)
B(2,0,7,minecraft:nether_wart_block)
B(3,0,7,minecraft:nether_wart_block)
B(4,0,7,minecraft:nether_wart_block)
B(5,0,7,minecraft:nether_wart_block)
B(6,0,7,minecraft:nether_wart_block)
B(7,0,7,minecraft:nether_wart_block)
B(8,0,7,minecraft:nether_wart_block)
B(9,0,7,minecraft:nether_wart_block)
B(10,0,7,minecraft:nether_wart_block)
B(0,0,8,minecraft:nether_wart_block)
B(1,0,8,minecraft:nether_wart_block)
B(2,0,8,minecraft:nether_wart_block)
B(3,0,8,minecraft:nether_wart_block)
B(4,0,8,minecraft:nether_wart_block)
B(5,0,8,minecraft:nether_wart_block)
B(6,0,8,minecraft:nether_wart_block)
B(7,0,8,minecraft:nether_wart_block)
B(8,0,8,minecraft:nether_wart_block)
B(9,0,8,minecraft:nether_wart_block)
B(10,0,8,minecraft:nether_wart_block)
B(11,0,8,minecraft:nether_wart_block)
B(0,0,9,minecraft:nether_wart_block)
B(1,0,9,minecraft:nether_wart_block)
B(2,0,9,minecraft:nether_wart_block)
B(3,0,9,minecraft:nether_wart_block)
B(4,0,9,minecraft:nether_wart_block)
B(5,0,9,minecraft:nether_wart_block)
B(6,0,9,minecraft:nether_wart_block)
B(7,0,9,minecraft:nether_wart_block)
B(8,0,9,minecraft:nether_wart_block)
B(9,0,9,minecraft:nether_wart_block)
B(10,0,9,minecraft:nether_wart_block)
B(11,0,9,minecraft:nether_wart_block)
B(0,0,10,minecraft:nether_wart_block)
B(1,0,10,minecraft:nether_wart_block)
B(2,0,10,minecraft:nether_wart_block)
B(3,0,10,minecraft:nether_wart_block)
B(4,0,10,minecraft:nether_wart_block)
B(5,0,10,minecraft:nether_wart_block)
B(6,0,10,minecraft:nether_wart_block)
B(7,0,10,minecraft:nether_wart_block)
B(8,0,10,minecraft:nether_wart_block)
B(9,0,10,minecraft:nether_wart_block)
B(10,0,10,minecraft:nether_wart_block)
B(11,0,10,minecraft:nether_wart_block)
B(0,0,11,minecraft:nether_wart_block)
B(1,0,11,minecraft:nether_wart_block)
B(2,0,11,minecraft:nether_wart_block)
B(3,0,11,minecraft:nether_wart_block)
B(4,0,11,minecraft:nether_wart_block)
B(5,0,11,minecraft:nether_wart_block)
B(6,0,11,minecraft:nether_wart_block)
B(7,0,11,minecraft:nether_wart_block)
B(8,0,11,minecraft:nether_wart_block)
B(9,0,11,minecraft:nether_wart_block)
B(10,0,11,minecraft:nether_wart_block)
B(11,0,11,minecraft:nether_wart_block)
B(0,0,12,minecraft:nether_wart_block)
B(1,0,12,minecraft:nether_wart_block)
B(2,0,12,minecraft:nether_wart_block)
B(3,0,12,minecraft:nether_wart_block)
B(4,0,12,minecraft:nether_wart_block)
B(5,0,12,minecraft:nether_wart_block)
B(6,0,12,minecraft:nether_wart_block)
B(7,0,12,minecraft:nether_wart_block)
B(8,0,12,minecraft:nether_wart_block)
B(9,0,12,minecraft:nether_wart_block)
B(10,0,12,minecraft:nether_wart_block)
B(11,0,12,minecraft:nether_wart_block)
B(0,0,13,minecraft:nether_wart_block)
B(1,0,13,minecraft:nether_wart_block)
B(2,0,13,minecraft:nether_wart_block)
B(3,0,13,minecraft:nether_wart_block)
B(4,0,13,minecraft:nether_wart_block)
B(5,0,13,minecraft:nether_wart_block)
B(6,0,13,minecraft:nether_wart_block)
B(7,0,13,minecraft:nether_wart_block)
B(8,0,13,minecraft:nether_wart_block)
B(9,0,13,minecraft:nether_wart_block)
B(10,0,13,minecraft:nether_wart_block)
B(11,0,13,minecraft:nether_wart_block)
B(0,0,14,minecraft:nether_wart_block)
B(1,0,14,minecraft:nether_wart_block)
B(2,0,14,minecraft:nether_wart_block)
B(3,0,14,minecraft:nether_wart_block)
B(4,0,14,minecraft:nether_wart_block)
B(5,0,14,minecraft:nether_wart_block)
B(6,0,14,minecraft:nether_wart_block)
B(7,0,14,minecraft:nether_wart_block)
B(8,0,14,minecraft:nether_wart_block)
B(9,0,14,minecraft:nether_wart_block)
B(10,0,14,minecraft:nether_wart_block)
B(11,0,14,minecraft:nether_wart_block)
B(0,0,15,minecraft:nether_wart_block)
B(1,0,15,minecraft:nether_wart_block)
B(2,0,15,minecraft:nether_wart_block)
B(3,0,15,minecraft:nether_wart_block)
B(4,0,15,minecraft:nether_wart_block)
B(5,0,15,minecraft:nether_wart_block)
B(6,0,15,minecraft:nether_wart_block)
B(7,0,15,minecraft:nether_wart_block)
B(8,0,15,minecraft:nether_wart_block)
B(9,0,15,minecraft:nether_wart_block)
B(10,0,15,minecraft:nether_wart_block)
B(11,0,15,minecraft:nether_wart_block)
B(0,1,6,minecraft:nether_wart_block)
B(1,1,6,minecraft:nether_wart_block)
B(2,1,6,minecraft:nether_wart_block)
B(3,1,6,minecraft:nether_wart_block)
B(4,1,6,minecraft:nether_wart_block)
B(0,1,7,minecraft:nether_wart_block)
B(1,1,7,minecraft:nether_wart_block)
B(2,1,7,minecraft:nether_wart_block)
B(3,1,7,minecraft:nether_wart_block)
B(4,1,7,minecraft:nether_wart_block)
B(5,1,7,minecraft:nether_wart_block)
B(6,1,7,minecraft:nether_wart_block)
B(7,1,7,minecraft:nether_wart_block)
B(8,1,7,minecraft:nether_wart_block)
B(9,1,7,minecraft:nether_wart_block)
B(0,1,8,minecraft:nether_wart_block)
B(1,1,8,minecraft:nether_wart_block)
B(2,1,8,minecraft:nether_wart_block)
B(3,1,8,minecraft:nether_wart_block)
B(4,1,8,minecraft:nether_wart_block)
B(5,1,8,minecraft:nether_wart_block)
B(6,1,8,minecraft:nether_wart_block)
B(7,1,8,minecraft:nether_wart_block)
B(8,1,8,minecraft:nether_wart_block)
B(9,1,8,minecraft:nether_wart_block)
B(10,1,8,minecraft:nether_wart_block)
B(0,1,9,minecraft:nether_wart_block)
B(1,1,9,minecraft:nether_wart_block)
B(2,1,9,minecraft:nether_wart_block)
B(3,1,9,minecraft:nether_wart_block)
B(4,1,9,minecraft:nether_wart_block)
B(5,1,9,minecraft:nether_wart_block)
B(6,1,9,minecraft:nether_wart_block)
B(7,1,9,minecraft:nether_wart_block)
B(8,1,9,minecraft:nether_wart_block)
B(9,1,9,minecraft:nether_wart_block)
B(10,1,9,minecraft:nether_wart_block)
B(11,1,9,minecraft:nether_wart_block)
B(0,1,10,minecraft:nether_wart_block)
B(1,1,10,minecraft:nether_wart_block)
B(2,1,10,minecraft:nether_wart_block)
B(3,1,10,minecraft:nether_wart_block)
B(4,1,10,minecraft:nether_wart_block)
B(5,1,10,minecraft:nether_wart_block)
B(6,1,10,minecraft:nether_wart_block)
B(7,1,10,minecraft:nether_wart_block)
B(8,1,10,minecraft:nether_wart_block)
B(9,1,10,minecraft:nether_wart_block)
B(10,1,10,minecraft:nether_wart_block)
B(11,1,10,minecraft:nether_wart_block)
B(0,1,11,minecraft:nether_wart_block)
B(1,1,11,minecraft:nether_wart_block)
B(2,1,11,minecraft:nether_wart_block)
B(3,1,11,minecraft:nether_wart_block)
B(4,1,11,minecraft:nether_wart_block)
B(5,1,11,minecraft:nether_wart_block)
B(6,1,11,minecraft:nether_wart_block)
B(7,1,11,minecraft:nether_wart_block)
B(8,1,11,minecraft:nether_wart_block)
B(9,1,11,minecraft:nether_wart_block)
B(10,1,11,minecraft:nether_wart_block)
B(0,1,12,minecraft:nether_wart_block)
B(1,1,12,minecraft:nether_wart_block)
B(2,1,12,minecraft:nether_wart_block)
B(3,1,12,minecraft:nether_wart_block)
B(4,1,12,minecraft:nether_wart_block)
B(5,1,12,minecraft:nether_wart_block)
B(6,1,12,minecraft:nether_wart_block)
B(7,1,12,minecraft:nether_wart_block)
B(8,1,12,minecraft:nether_wart_block)
B(9,1,12,minecraft:nether_wart_block)
B(10,1,12,minecraft:nether_wart_block)
B(0,1,13,minecraft:nether_wart_block)
B(1,1,13,minecraft:nether_wart_block)
B(2,1,13,minecraft:nether_wart_block)
B(3,1,13,minecraft:nether_wart_block)
B(4,1,13,minecraft:nether_wart_block)
B(5,1,13,minecraft:nether_wart_block)
B(6,1,13,minecraft:nether_wart_block)
B(7,1,13,minecraft:nether_wart_block)
B(8,1,13,minecraft:nether_wart_block)
B(9,1,13,minecraft:nether_wart_block)
B(10,1,13,minecraft:nether_wart_block)
B(0,1,14,minecraft:nether_wart_block)
B(1,1,14,minecraft:nether_wart_block)
B(2,1,14,minecraft:nether_wart_block)
B(3,1,14,minecraft:nether_wart_block)
B(4,1,14,minecraft:nether_wart_block)
B(5,1,14,minecraft:nether_wart_block)
B(6,1,14,minecraft:nether_wart_block)
B(7,1,14,minecraft:nether_wart_block)
B(8,1,14,minecraft:nether_wart_block)
B(9,1,14,minecraft:nether_wart_block)
B(10,1,14,minecraft:nether_wart_block)
B(0,1,15,minecraft:nether_wart_block)
B(1,1,15,minecraft:nether_wart_block)
B(2,1,15,minecraft:nether_wart_block)
B(3,1,15,minecraft:nether_wart_block)
B(4,1,15,minecraft:nether_wart_block)
B(5,1,15,minecraft:nether_wart_block)
B(6,1,15,minecraft:nether_wart_block)
B(7,1,15,minecraft:nether_wart_block)
B(8,1,15,minecraft:nether_wart_block)
B(9,1,15,minecraft:nether_wart_block)
B(1,2,7,minecraft:nether_wart_block)
B(2,2,7,minecraft:nether_wart_block)
B(3,2,7,minecraft:nether_wart_block)
B(0,2,8,minecraft:nether_wart_block)
B(1,2,8,minecraft:nether_wart_block)
B(2,2,8,minecraft:nether_wart_block)
B(3,2,8,minecraft:nether_wart_block)
B(4,2,8,minecraft:nether_wart_block)
B(5,2,8,minecraft:nether_wart_block)
B(6,2,8,minecraft:nether_wart_block)
B(7,2,8,minecraft:nether_wart_block)
B(8,2,8,minecraft:nether_wart_block)
B(9,2,8,minecraft:nether_wart_block)
B(0,2,9,minecraft:nether_wart_block)
B(1,2,9,minecraft:nether_wart_block)
B(2,2,9,minecraft:nether_wart_block)
B(3,2,9,minecraft:nether_wart_block)
B(4,2,9,minecraft:nether_wart_block)
B(5,2,9,minecraft:nether_wart_block)
B(6,2,9,minecraft:nether_wart_block)
B(7,2,9,minecraft:nether_wart_block)
B(8,2,9,minecraft:nether_wart_block)
B(9,2,9,minecraft:nether_wart_block)
B(10,2,9,minecraft:nether_wart_block)
B(0,2,10,minecraft:nether_wart_block)
B(1,2,10,minecraft:nether_wart_block)
B(2,2,10,minecraft:nether_wart_block)
B(3,2,10,minecraft:nether_wart_block)
B(4,2,10,minecraft:nether_wart_block)
B(5,2,10,minecraft:nether_wart_block)
B(6,2,10,minecraft:nether_wart_block)
B(7,2,10,minecraft:nether_wart_block)
B(8,2,10,minecraft:nether_wart_block)
B(9,2,10,minecraft:nether_wart_block)
B(10,2,10,minecraft:nether_wart_block)
B(0,2,11,minecraft:nether_wart_block)
B(1,2,11,minecraft:nether_wart_block)
B(2,2,11,minecraft:nether_wart_block)
B(3,2,11,minecraft:nether_wart_block)
B(4,2,11,minecraft:nether_wart_block)
B(5,2,11,minecraft:nether_wart_block)
B(6,2,11,minecraft:nether_wart_block)
B(7,2,11,minecraft:nether_wart_block)
B(8,2,11,minecraft:nether_wart_block)
B(9,2,11,minecraft:nether_wart_block)
B(0,2,12,minecraft:nether_wart_block)
B(1,2,12,minecraft:nether_wart_block)
B(2,2,12,minecraft:nether_wart_block)
B(3,2,12,minecraft:nether_wart_block)
B(4,2,12,minecraft:nether_wart_block)
B(5,2,12,minecraft:nether_wart_block)
B(6,2,12,minecraft:nether_wart_block)
B(7,2,12,minecraft:nether_wart_block)
B(8,2,12,minecraft:nether_wart_block)
B(9,2,12,minecraft:nether_wart_block)
B(0,2,13,minecraft:nether_wart_block)
B(1,2,13,minecraft:nether_wart_block)
B(2,2,13,minecraft:nether_wart_block)
B(3,2,13,minecraft:nether_wart_block)
B(4,2,13,minecraft:nether_wart_block)
B(5,2,13,minecraft:nether_wart_block)
B(6,2,13,minecraft:nether_wart_block)
B(7,2,13,minecraft:nether_wart_block)
B(8,2,13,minecraft:nether_wart_block)
B(9,2,13,minecraft:nether_wart_block)
B(0,2,14,minecraft:nether_wart_block)
B(1,2,14,minecraft:nether_wart_block)
B(2,2,14,minecraft:nether_wart_block)
B(3,2,14,minecraft:nether_wart_block)
B(4,2,14,minecraft:nether_wart_block)
B(5,2,14,minecraft:nether_wart_block)
B(6,2,14,minecraft:nether_wart_block)
B(7,2,14,minecraft:nether_wart_block)
B(8,2,14,minecraft:nether_wart_block)
B(0,2,15,minecraft:nether_wart_block)
B(1,2,15,minecraft:nether_wart_block)
B(2,2,15,minecraft:nether_wart_block)
B(3,2,15,minecraft:nether_wart_block)
B(4,2,15,minecraft:nether_wart_block)
B(5,2,15,minecraft:nether_wart_block)
B(6,2,15,minecraft:nether_wart_block)
B(0,3,9,minecraft:nether_wart_block)
B(1,3,9,minecraft:nether_wart_block)
B(2,3,9,minecraft:nether_wart_block)
B(3,3,9,minecraft:nether_wart_block)
B(6,3,9,minecraft:nether_wart_block)
B(7,3,9,minecraft:nether_wart_block)
B(8,3,9,minecraft:nether_wart_block)
B(0,3,10,minecraft:nether_wart_block)
B(1,3,10,minecraft:nether_wart_block)
B(2,3,10,minecraft:nether_wart_block)
B(3,3,10,minecraft:nether_wart_block)
B(4,3,10,minecraft:nether_wart_block)
B(5,3,10,minecraft:nether_wart_block)
B(6,3,10,minecraft:nether_wart_block)
B(7,3,10,minecraft:nether_wart_block)
B(8,3,10,minecraft:nether_wart_block)
B(0,3,11,minecraft:nether_wart_block)
B(1,3,11,minecraft:nether_wart_block)
B(2,3,11,minecraft:nether_wart_block)
B(3,3,11,minecraft:nether_wart_block)
B(4,3,11,minecraft:nether_wart_block)
B(5,3,11,minecraft:nether_wart_block)
B(6,3,11,minecraft:nether_wart_block)
B(7,3,11,minecraft:nether_wart_block)
B(8,3,11,minecraft:nether_wart_block)
B(0,3,12,minecraft:nether_wart_block)
B(1,3,12,minecraft:nether_wart_block)
B(2,3,12,minecraft:nether_wart_block)
B(3,3,12,minecraft:nether_wart_block)
B(4,3,12,minecraft:nether_wart_block)
B(5,3,12,minecraft:nether_wart_block)
B(6,3,12,minecraft:nether_wart_block)
B(7,3,12,minecraft:nether_wart_block)
B(0,3,13,minecraft:nether_wart_block)
B(1,3,13,minecraft:nether_wart_block)
B(2,3,13,minecraft:nether_wart_block)
B(3,3,13,minecraft:nether_wart_block)
B(4,3,13,minecraft:nether_wart_block)
B(0,3,14,minecraft:nether_wart_block)
B(1,3,14,minecraft:nether_wart_block)
B(2,3,14,minecraft:nether_wart_block)
B(3,3,14,minecraft:nether_wart_block)
B(4,3,14,minecraft:nether_wart_block)
B(0,3,15,minecraft:nether_wart_block)
B(1,3,15,minecraft:nether_wart_block)
B(2,3,15,minecraft:nether_wart_block)
B(3,3,15,minecraft:nether_wart_block)
B(4,3,15,minecraft:nether_wart_block)
B(0,4,10,minecraft:nether_wart_block)
B(1,4,10,minecraft:nether_wart_block)
B(0,4,11,minecraft:nether_wart_block)
B(1,4,11,minecraft:nether_wart_block)
B(2,4,11,minecraft:nether_wart_block)
B(0,4,12,minecraft:nether_wart_block)
B(1,4,12,minecraft:nether_wart_block)
B(2,4,12,minecraft:nether_wart_block)
B(3,4,12,minecraft:nether_wart_block)
B(0,4,13,minecraft:nether_wart_block)
B(1,4,13,minecraft:nether_wart_block)
B(2,4,13,minecraft:nether_wart_block)
B(3,4,13,minecraft:nether_wart_block)
B(0,4,14,minecraft:nether_wart_block)
B(1,4,14,minecraft:nether_wart_block)
B(2,4,14,minecraft:nether_wart_block)
B(3,4,14,minecraft:nether_wart_block)
B(0,4,15,minecraft:nether_wart_block)
B(1,4,15,minecraft:nether_wart_block)
B(2,4,15,minecraft:nether_wart_block)
B(3,4,15,minecraft:nether_wart_block)
B(0,5,13,minecraft:nether_wart_block)
B(1,5,13,minecraft:nether_wart_block)
B(2,5,13,minecraft:nether_wart_block)
B(0,5,14,minecraft:nether_wart_block)
B(1,5,14,minecraft:nether_wart_block)
B(0,5,15,minecraft:nether_wart_block)
B(1,5,15,minecraft:nether_wart_block)
B(0,6,14,minecraft:nether_wart_block)
B(0,6,15,minecraft:nether_wart_block)

