
#######################################################################
# +-----------------------------------------------------------------+ #
# |                            BO4 object                           | #
# +-----------------------------------------------------------------+ #
#######################################################################

Author: Unknown

Description: No description given

SettingsMode: WriteWithoutComments


#######################################################################
# +-----------------------------------------------------------------+ #
# |                          Main settings                          | #
# +-----------------------------------------------------------------+ #
#######################################################################

FixedRotation: 

Frequency: 0

SpawnHeight: highestBlock

UseCenterForHighestBlock: true

##############################
# Height Limits for the BO4. #
##############################

MinHeight: 0

MaxHeight: 255

InheritBO3: 

InheritBO3Rotation: NORTH

OverrideChildSettings: true

OverrideParentHeight: false

CanOverride: false

BranchFrequency: 0

BranchFrequencyGroup: 

MustBeBelowOther: false

MustBeInside: 

CannotBeInside: 

ReplacesBO3: 

MustBeInsideWorldBorders: false

CanSpawnOnWater: true

SpawnOnWaterOnly: false

SpawnUnderWater: false

SpawnAtWaterLevel: false

HeightOffset: 0

RemoveAir: true

ReplaceAbove: 

ReplaceBelow: 

ReplaceWithBiomeBlocks: true

ReplaceWithSurfaceBlock: GRASS

ReplaceWithGroundBlock: DIRT

ReplaceWithStoneBlock: STONE

SmoothRadius: 0

SmoothHeightOffset: 0

SmoothStartTop: false

SmoothStartWood: false

SmoothingSurfaceBlock: 

SmoothingGroundBlock: 

BO3Group: 

IsSpawnPoint: false

DoReplaceBlocks: true


#######################################################################
# +-----------------------------------------------------------------+ #
# |                              Blocks                             | #
# +-----------------------------------------------------------------+ #
#######################################################################

B(1,74,7,minecraft:blackstone)
B(1,75,7,minecraft:blackstone)
B(1,76,7,minecraft:blackstone)
B(1,73,8,minecraft:blackstone)
B(2,82,5,minecraft:blackstone)
B(2,83,5,minecraft:blackstone)
B(2,84,5,minecraft:blackstone)
B(2,81,6,minecraft:blackstone)
B(2,77,7,minecraft:blackstone)
B(3,90,3,minecraft:blackstone)
B(3,91,3,minecraft:blackstone)
B(3,92,3,minecraft:blackstone)
B(3,89,4,minecraft:blackstone)
B(3,85,5,minecraft:blackstone)
B(3,78,7,minecraft:glowstone)
B(3,79,7,minecraft:chain)
B(3,80,7,minecraft:glowstone)
B(4,98,1,minecraft:blackstone)
B(4,99,1,minecraft:blackstone)
B(4,100,1,minecraft:blackstone)
B(4,97,2,minecraft:blackstone)
B(4,93,3,minecraft:blackstone)
B(4,86,5,minecraft:glowstone)
B(4,87,5,minecraft:chain)
B(4,88,5,minecraft:glowstone)
B(4,81,7,minecraft:blackstone)
B(4,77,8,minecraft:blackstone)
B(5,106,-1,minecraft:blackstone)
B(5,107,-1,minecraft:blackstone)
B(5,108,-1,minecraft:blackstone)
B(5,105,0,minecraft:blackstone)
B(5,101,1,minecraft:blackstone)
B(5,94,3,minecraft:glowstone)
B(5,95,3,minecraft:chain)
B(5,96,3,minecraft:glowstone)
B(5,89,5,minecraft:blackstone)
B(5,85,6,minecraft:blackstone)
B(5,82,7,minecraft:blackstone)
B(5,83,7,minecraft:blackstone)
B(5,84,7,minecraft:blackstone)
B(6,114,-3,minecraft:blackstone)
B(6,115,-3,minecraft:blackstone)
B(6,116,-3,minecraft:blackstone)
B(6,113,-2,minecraft:blackstone)
B(6,109,-1,minecraft:blackstone)
B(6,102,1,minecraft:glowstone)
B(6,103,1,minecraft:chain)
B(6,104,1,minecraft:glowstone)
B(6,97,3,minecraft:blackstone)
B(6,93,4,minecraft:blackstone)
B(6,90,5,minecraft:blackstone)
B(6,91,5,minecraft:blackstone)
B(6,92,5,minecraft:blackstone)
B(7,122,-5,minecraft:blackstone)
B(7,123,-5,minecraft:blackstone)
B(7,124,-5,minecraft:blackstone)
B(7,121,-4,minecraft:blackstone)
B(7,117,-3,minecraft:blackstone)
B(7,110,-1,minecraft:glowstone)
B(7,111,-1,minecraft:chain)
B(7,112,-1,minecraft:glowstone)
B(7,105,1,minecraft:blackstone)
B(7,101,2,minecraft:blackstone)
B(7,98,3,minecraft:blackstone)
B(7,99,3,minecraft:blackstone)
B(7,100,3,minecraft:blackstone)

#######################################################################
# +-----------------------------------------------------------------+ #
# |                             Branches                            | #
# +-----------------------------------------------------------------+ #
#######################################################################

Branch(16,0,0,true,BlackstoneChain1_C1_R0,NORTH,100.0,0)
Branch(0,0,16,true,BlackstoneChain1_C0_R1,NORTH,100.0,0)

#######################################################################
# +-----------------------------------------------------------------+ #
# |                             Entities                            | #
# +-----------------------------------------------------------------+ #
#######################################################################

