
#######################################################################
# +-----------------------------------------------------------------+ #
# |                            BO4 object                           | #
# +-----------------------------------------------------------------+ #
#######################################################################

Author: Unknown

Description: No description given

SettingsMode: WriteWithoutComments


#######################################################################
# +-----------------------------------------------------------------+ #
# |                          Main settings                          | #
# +-----------------------------------------------------------------+ #
#######################################################################

FixedRotation: 

Frequency: 0

SpawnHeight: highestBlock

UseCenterForHighestBlock: true

##############################
# Height Limits for the BO4. #
##############################

MinHeight: 0

MaxHeight: 255

InheritBO3: 

InheritBO3Rotation: NORTH

OverrideChildSettings: true

OverrideParentHeight: false

CanOverride: false

BranchFrequency: 0

BranchFrequencyGroup: 

MustBeBelowOther: false

MustBeInside: 

CannotBeInside: 

ReplacesBO3: 

MustBeInsideWorldBorders: false

CanSpawnOnWater: true

SpawnOnWaterOnly: false

SpawnUnderWater: false

SpawnAtWaterLevel: false

HeightOffset: 0

RemoveAir: true

ReplaceAbove: 

ReplaceBelow: 

ReplaceWithBiomeBlocks: true

ReplaceWithSurfaceBlock: GRASS

ReplaceWithGroundBlock: DIRT

ReplaceWithStoneBlock: STONE

SmoothRadius: 0

SmoothHeightOffset: 0

SmoothStartTop: false

SmoothStartWood: false

SmoothingSurfaceBlock: 

SmoothingGroundBlock: 

BO3Group: 

IsSpawnPoint: false

DoReplaceBlocks: true


#######################################################################
# +-----------------------------------------------------------------+ #
# |                              Blocks                             | #
# +-----------------------------------------------------------------+ #
#######################################################################

B(-8,133,-1,minecraft:netherrack)
B(-8,134,-1,minecraft:netherrack)
B(-8,130,0,minecraft:netherrack)
B(-8,131,0,minecraft:netherrack)
B(-8,132,0,minecraft:netherrack)
B(-8,133,0,minecraft:netherrack)
B(-8,134,0,minecraft:netherrack)
B(-8,128,1,minecraft:netherrack)
B(-8,129,1,minecraft:netherrack)
B(-8,130,1,minecraft:netherrack)
B(-8,131,1,minecraft:netherrack)
B(-8,132,1,minecraft:netherrack)
B(-8,133,1,minecraft:netherrack)
B(-8,134,1,minecraft:netherrack)
B(-8,125,2,minecraft:netherrack)
B(-8,126,2,minecraft:netherrack)
B(-8,127,2,minecraft:netherrack)
B(-8,128,2,minecraft:netherrack)
B(-8,129,2,minecraft:netherrack)
B(-8,130,2,minecraft:netherrack)
B(-8,131,2,minecraft:netherrack)
B(-8,132,2,minecraft:netherrack)
B(-8,133,2,minecraft:netherrack)
B(-8,134,2,minecraft:netherrack)
B(-8,122,3,minecraft:netherrack)
B(-8,123,3,minecraft:netherrack)
B(-8,124,3,minecraft:netherrack)
B(-8,125,3,minecraft:netherrack)
B(-8,126,3,minecraft:netherrack)
B(-8,127,3,minecraft:netherrack)
B(-8,128,3,minecraft:netherrack)
B(-8,129,3,minecraft:netherrack)
B(-8,130,3,minecraft:netherrack)
B(-8,131,3,minecraft:netherrack)
B(-8,132,3,minecraft:netherrack)
B(-8,133,3,minecraft:netherrack)
B(-8,134,3,minecraft:netherrack)
B(-8,119,4,minecraft:netherrack)
B(-8,120,4,minecraft:netherrack)
B(-8,121,4,minecraft:netherrack)
B(-8,122,4,minecraft:netherrack)
B(-8,123,4,minecraft:netherrack)
B(-8,124,4,minecraft:netherrack)
B(-8,125,4,minecraft:netherrack)
B(-8,126,4,minecraft:netherrack)
B(-8,127,4,minecraft:netherrack)
B(-8,128,4,minecraft:netherrack)
B(-8,129,4,minecraft:netherrack)
B(-8,130,4,minecraft:netherrack)
B(-8,131,4,minecraft:netherrack)
B(-8,132,4,minecraft:netherrack)
B(-8,133,4,minecraft:netherrack)
B(-8,134,4,minecraft:netherrack)
B(-8,116,5,minecraft:netherrack)
B(-8,117,5,minecraft:netherrack)
B(-8,118,5,minecraft:netherrack)
B(-8,119,5,minecraft:netherrack)
B(-8,120,5,minecraft:netherrack)
B(-8,121,5,minecraft:netherrack)
B(-8,122,5,minecraft:netherrack)
B(-8,123,5,minecraft:netherrack)
B(-8,124,5,minecraft:netherrack)
B(-8,125,5,minecraft:netherrack)
B(-8,126,5,minecraft:netherrack)
B(-8,127,5,minecraft:netherrack)
B(-8,128,5,minecraft:netherrack)
B(-8,129,5,minecraft:netherrack)
B(-8,130,5,minecraft:netherrack)
B(-8,131,5,minecraft:netherrack)
B(-8,132,5,minecraft:netherrack)
B(-8,133,5,minecraft:netherrack)
B(-8,134,5,minecraft:netherrack)
B(-8,113,6,minecraft:netherrack)
B(-8,114,6,minecraft:netherrack)
B(-8,115,6,minecraft:netherrack)
B(-8,116,6,minecraft:netherrack)
B(-8,117,6,minecraft:netherrack)
B(-8,118,6,minecraft:netherrack)
B(-8,119,6,minecraft:netherrack)
B(-8,120,6,minecraft:netherrack)
B(-8,121,6,minecraft:netherrack)
B(-8,122,6,minecraft:netherrack)
B(-8,123,6,minecraft:netherrack)
B(-8,124,6,minecraft:netherrack)
B(-8,125,6,minecraft:netherrack)
B(-8,126,6,minecraft:netherrack)
B(-8,127,6,minecraft:netherrack)
B(-8,128,6,minecraft:netherrack)
B(-8,129,6,minecraft:netherrack)
B(-8,130,6,minecraft:netherrack)
B(-8,131,6,minecraft:netherrack)
B(-8,132,6,minecraft:netherrack)
B(-8,133,6,minecraft:netherrack)
B(-8,134,6,minecraft:netherrack)
B(-8,112,7,minecraft:netherrack)
B(-8,113,7,minecraft:netherrack)
B(-8,114,7,minecraft:netherrack)
B(-8,115,7,minecraft:netherrack)
B(-8,116,7,minecraft:netherrack)
B(-8,117,7,minecraft:netherrack)
B(-8,118,7,minecraft:netherrack)
B(-8,119,7,minecraft:netherrack)
B(-8,120,7,minecraft:netherrack)
B(-8,121,7,minecraft:netherrack)
B(-8,122,7,minecraft:netherrack)
B(-8,123,7,minecraft:netherrack)
B(-8,124,7,minecraft:netherrack)
B(-8,125,7,minecraft:netherrack)
B(-8,126,7,minecraft:netherrack)
B(-8,127,7,minecraft:netherrack)
B(-8,128,7,minecraft:netherrack)
B(-8,129,7,minecraft:netherrack)
B(-8,130,7,minecraft:netherrack)
B(-8,131,7,minecraft:netherrack)
B(-8,132,7,minecraft:netherrack)
B(-8,133,7,minecraft:netherrack)
B(-8,134,7,minecraft:netherrack)
B(-8,111,8,minecraft:netherrack)
B(-8,112,8,minecraft:netherrack)
B(-8,113,8,minecraft:netherrack)
B(-8,114,8,minecraft:netherrack)
B(-8,115,8,minecraft:netherrack)
B(-8,116,8,minecraft:netherrack)
B(-8,117,8,minecraft:netherrack)
B(-8,118,8,minecraft:netherrack)
B(-8,119,8,minecraft:netherrack)
B(-8,120,8,minecraft:netherrack)
B(-8,121,8,minecraft:netherrack)
B(-8,122,8,minecraft:netherrack)
B(-8,123,8,minecraft:netherrack)
B(-8,124,8,minecraft:netherrack)
B(-8,125,8,minecraft:netherrack)
B(-8,126,8,minecraft:netherrack)
B(-8,127,8,minecraft:netherrack)
B(-8,128,8,minecraft:netherrack)
B(-8,129,8,minecraft:netherrack)
B(-8,130,8,minecraft:netherrack)
B(-8,131,8,minecraft:netherrack)
B(-8,132,8,minecraft:netherrack)
B(-8,133,8,minecraft:netherrack)
B(-8,134,8,minecraft:netherrack)
B(-7,133,-1,minecraft:netherrack)
B(-7,134,-1,minecraft:netherrack)
B(-7,130,0,minecraft:netherrack)
B(-7,131,0,minecraft:netherrack)
B(-7,132,0,minecraft:netherrack)
B(-7,133,0,minecraft:netherrack)
B(-7,134,0,minecraft:netherrack)
B(-7,128,1,minecraft:netherrack)
B(-7,129,1,minecraft:netherrack)
B(-7,130,1,minecraft:netherrack)
B(-7,131,1,minecraft:netherrack)
B(-7,132,1,minecraft:netherrack)
B(-7,133,1,minecraft:netherrack)
B(-7,134,1,minecraft:netherrack)
B(-7,125,2,minecraft:netherrack)
B(-7,126,2,minecraft:netherrack)
B(-7,127,2,minecraft:netherrack)
B(-7,128,2,minecraft:netherrack)
B(-7,129,2,minecraft:netherrack)
B(-7,130,2,minecraft:netherrack)
B(-7,131,2,minecraft:netherrack)
B(-7,132,2,minecraft:netherrack)
B(-7,133,2,minecraft:netherrack)
B(-7,134,2,minecraft:netherrack)
B(-7,122,3,minecraft:netherrack)
B(-7,123,3,minecraft:netherrack)
B(-7,124,3,minecraft:netherrack)
B(-7,125,3,minecraft:netherrack)
B(-7,126,3,minecraft:netherrack)
B(-7,127,3,minecraft:netherrack)
B(-7,128,3,minecraft:netherrack)
B(-7,129,3,minecraft:netherrack)
B(-7,130,3,minecraft:netherrack)
B(-7,131,3,minecraft:netherrack)
B(-7,132,3,minecraft:netherrack)
B(-7,133,3,minecraft:netherrack)
B(-7,134,3,minecraft:netherrack)
B(-7,118,4,minecraft:netherrack)
B(-7,119,4,minecraft:netherrack)
B(-7,120,4,minecraft:netherrack)
B(-7,121,4,minecraft:netherrack)
B(-7,122,4,minecraft:netherrack)
B(-7,123,4,minecraft:netherrack)
B(-7,124,4,minecraft:netherrack)
B(-7,125,4,minecraft:netherrack)
B(-7,126,4,minecraft:netherrack)
B(-7,127,4,minecraft:netherrack)
B(-7,128,4,minecraft:netherrack)
B(-7,129,4,minecraft:netherrack)
B(-7,130,4,minecraft:netherrack)
B(-7,131,4,minecraft:netherrack)
B(-7,132,4,minecraft:netherrack)
B(-7,133,4,minecraft:netherrack)
B(-7,134,4,minecraft:netherrack)
B(-7,116,5,minecraft:netherrack)
B(-7,117,5,minecraft:netherrack)
B(-7,118,5,minecraft:netherrack)
B(-7,119,5,minecraft:netherrack)
B(-7,120,5,minecraft:netherrack)
B(-7,121,5,minecraft:netherrack)
B(-7,122,5,minecraft:netherrack)
B(-7,123,5,minecraft:netherrack)
B(-7,124,5,minecraft:netherrack)
B(-7,125,5,minecraft:netherrack)
B(-7,126,5,minecraft:netherrack)
B(-7,127,5,minecraft:netherrack)
B(-7,128,5,minecraft:netherrack)
B(-7,129,5,minecraft:netherrack)
B(-7,130,5,minecraft:netherrack)
B(-7,131,5,minecraft:netherrack)
B(-7,132,5,minecraft:netherrack)
B(-7,133,5,minecraft:netherrack)
B(-7,134,5,minecraft:netherrack)
B(-7,113,6,minecraft:netherrack)
B(-7,114,6,minecraft:netherrack)
B(-7,115,6,minecraft:netherrack)
B(-7,116,6,minecraft:netherrack)
B(-7,117,6,minecraft:netherrack)
B(-7,118,6,minecraft:netherrack)
B(-7,119,6,minecraft:netherrack)
B(-7,120,6,minecraft:netherrack)
B(-7,121,6,minecraft:netherrack)
B(-7,122,6,minecraft:netherrack)
B(-7,123,6,minecraft:netherrack)
B(-7,124,6,minecraft:netherrack)
B(-7,125,6,minecraft:netherrack)
B(-7,126,6,minecraft:netherrack)
B(-7,127,6,minecraft:netherrack)
B(-7,128,6,minecraft:netherrack)
B(-7,129,6,minecraft:netherrack)
B(-7,130,6,minecraft:netherrack)
B(-7,131,6,minecraft:netherrack)
B(-7,132,6,minecraft:netherrack)
B(-7,133,6,minecraft:netherrack)
B(-7,134,6,minecraft:netherrack)
B(-7,112,7,minecraft:netherrack)
B(-7,113,7,minecraft:netherrack)
B(-7,114,7,minecraft:netherrack)
B(-7,115,7,minecraft:netherrack)
B(-7,116,7,minecraft:netherrack)
B(-7,117,7,minecraft:netherrack)
B(-7,118,7,minecraft:netherrack)
B(-7,119,7,minecraft:netherrack)
B(-7,120,7,minecraft:netherrack)
B(-7,121,7,minecraft:netherrack)
B(-7,122,7,minecraft:netherrack)
B(-7,123,7,minecraft:netherrack)
B(-7,124,7,minecraft:netherrack)
B(-7,125,7,minecraft:netherrack)
B(-7,126,7,minecraft:netherrack)
B(-7,127,7,minecraft:netherrack)
B(-7,128,7,minecraft:netherrack)
B(-7,129,7,minecraft:netherrack)
B(-7,130,7,minecraft:netherrack)
B(-7,131,7,minecraft:netherrack)
B(-7,132,7,minecraft:netherrack)
B(-7,133,7,minecraft:netherrack)
B(-7,134,7,minecraft:netherrack)
B(-7,111,8,minecraft:netherrack)
B(-7,112,8,minecraft:netherrack)
B(-7,113,8,minecraft:netherrack)
B(-7,114,8,minecraft:netherrack)
B(-7,115,8,minecraft:netherrack)
B(-7,116,8,minecraft:netherrack)
B(-7,117,8,minecraft:netherrack)
B(-7,118,8,minecraft:netherrack)
B(-7,119,8,minecraft:netherrack)
B(-7,120,8,minecraft:netherrack)
B(-7,121,8,minecraft:netherrack)
B(-7,122,8,minecraft:netherrack)
B(-7,123,8,minecraft:netherrack)
B(-7,124,8,minecraft:netherrack)
B(-7,125,8,minecraft:netherrack)
B(-7,126,8,minecraft:netherrack)
B(-7,127,8,minecraft:netherrack)
B(-7,128,8,minecraft:netherrack)
B(-7,129,8,minecraft:netherrack)
B(-7,130,8,minecraft:netherrack)
B(-7,131,8,minecraft:netherrack)
B(-7,132,8,minecraft:netherrack)
B(-7,133,8,minecraft:netherrack)
B(-7,134,8,minecraft:netherrack)
B(-6,133,-1,minecraft:netherrack)
B(-6,134,-1,minecraft:netherrack)
B(-6,130,0,minecraft:netherrack)
B(-6,131,0,minecraft:netherrack)
B(-6,132,0,minecraft:netherrack)
B(-6,133,0,minecraft:netherrack)
B(-6,134,0,minecraft:netherrack)
B(-6,128,1,minecraft:netherrack)
B(-6,129,1,minecraft:netherrack)
B(-6,130,1,minecraft:netherrack)
B(-6,131,1,minecraft:netherrack)
B(-6,132,1,minecraft:netherrack)
B(-6,133,1,minecraft:netherrack)
B(-6,134,1,minecraft:netherrack)
B(-6,125,2,minecraft:netherrack)
B(-6,126,2,minecraft:netherrack)
B(-6,127,2,minecraft:netherrack)
B(-6,128,2,minecraft:netherrack)
B(-6,129,2,minecraft:netherrack)
B(-6,130,2,minecraft:netherrack)
B(-6,131,2,minecraft:netherrack)
B(-6,132,2,minecraft:netherrack)
B(-6,133,2,minecraft:netherrack)
B(-6,134,2,minecraft:netherrack)
B(-6,122,3,minecraft:netherrack)
B(-6,123,3,minecraft:netherrack)
B(-6,124,3,minecraft:netherrack)
B(-6,125,3,minecraft:netherrack)
B(-6,126,3,minecraft:netherrack)
B(-6,127,3,minecraft:netherrack)
B(-6,128,3,minecraft:netherrack)
B(-6,129,3,minecraft:netherrack)
B(-6,130,3,minecraft:netherrack)
B(-6,131,3,minecraft:netherrack)
B(-6,132,3,minecraft:netherrack)
B(-6,133,3,minecraft:netherrack)
B(-6,134,3,minecraft:netherrack)
B(-6,118,4,minecraft:netherrack)
B(-6,119,4,minecraft:netherrack)
B(-6,120,4,minecraft:netherrack)
B(-6,121,4,minecraft:netherrack)
B(-6,122,4,minecraft:netherrack)
B(-6,123,4,minecraft:netherrack)
B(-6,124,4,minecraft:netherrack)
B(-6,125,4,minecraft:netherrack)
B(-6,126,4,minecraft:netherrack)
B(-6,127,4,minecraft:netherrack)
B(-6,128,4,minecraft:netherrack)
B(-6,129,4,minecraft:netherrack)
B(-6,130,4,minecraft:netherrack)
B(-6,131,4,minecraft:netherrack)
B(-6,132,4,minecraft:netherrack)
B(-6,133,4,minecraft:netherrack)
B(-6,134,4,minecraft:netherrack)
B(-6,115,5,minecraft:netherrack)
B(-6,116,5,minecraft:netherrack)
B(-6,117,5,minecraft:netherrack)
B(-6,118,5,minecraft:netherrack)
B(-6,119,5,minecraft:netherrack)
B(-6,120,5,minecraft:netherrack)
B(-6,121,5,minecraft:netherrack)
B(-6,122,5,minecraft:netherrack)
B(-6,123,5,minecraft:netherrack)
B(-6,124,5,minecraft:netherrack)
B(-6,125,5,minecraft:netherrack)
B(-6,126,5,minecraft:netherrack)
B(-6,127,5,minecraft:netherrack)
B(-6,128,5,minecraft:netherrack)
B(-6,129,5,minecraft:netherrack)
B(-6,130,5,minecraft:netherrack)
B(-6,131,5,minecraft:netherrack)
B(-6,132,5,minecraft:netherrack)
B(-6,133,5,minecraft:netherrack)
B(-6,134,5,minecraft:netherrack)
B(-6,113,6,minecraft:netherrack)
B(-6,114,6,minecraft:netherrack)
B(-6,115,6,minecraft:netherrack)
B(-6,116,6,minecraft:netherrack)
B(-6,117,6,minecraft:netherrack)
B(-6,118,6,minecraft:netherrack)
B(-6,119,6,minecraft:netherrack)
B(-6,120,6,minecraft:netherrack)
B(-6,121,6,minecraft:netherrack)
B(-6,122,6,minecraft:netherrack)
B(-6,123,6,minecraft:netherrack)
B(-6,124,6,minecraft:netherrack)
B(-6,125,6,minecraft:netherrack)
B(-6,126,6,minecraft:netherrack)
B(-6,127,6,minecraft:netherrack)
B(-6,128,6,minecraft:netherrack)
B(-6,129,6,minecraft:netherrack)
B(-6,130,6,minecraft:netherrack)
B(-6,131,6,minecraft:netherrack)
B(-6,132,6,minecraft:netherrack)
B(-6,133,6,minecraft:netherrack)
B(-6,134,6,minecraft:netherrack)
B(-6,112,7,minecraft:netherrack)
B(-6,113,7,minecraft:netherrack)
B(-6,114,7,minecraft:netherrack)
B(-6,115,7,minecraft:netherrack)
B(-6,116,7,minecraft:netherrack)
B(-6,117,7,minecraft:netherrack)
B(-6,118,7,minecraft:netherrack)
B(-6,119,7,minecraft:netherrack)
B(-6,120,7,minecraft:netherrack)
B(-6,121,7,minecraft:netherrack)
B(-6,122,7,minecraft:netherrack)
B(-6,123,7,minecraft:netherrack)
B(-6,124,7,minecraft:netherrack)
B(-6,125,7,minecraft:netherrack)
B(-6,126,7,minecraft:netherrack)
B(-6,127,7,minecraft:netherrack)
B(-6,128,7,minecraft:netherrack)
B(-6,129,7,minecraft:netherrack)
B(-6,130,7,minecraft:netherrack)
B(-6,131,7,minecraft:netherrack)
B(-6,132,7,minecraft:netherrack)
B(-6,133,7,minecraft:netherrack)
B(-6,134,7,minecraft:netherrack)
B(-6,111,8,minecraft:netherrack)
B(-6,112,8,minecraft:netherrack)
B(-6,113,8,minecraft:netherrack)
B(-6,114,8,minecraft:netherrack)
B(-6,115,8,minecraft:netherrack)
B(-6,116,8,minecraft:netherrack)
B(-6,117,8,minecraft:netherrack)
B(-6,118,8,minecraft:netherrack)
B(-6,119,8,minecraft:netherrack)
B(-6,120,8,minecraft:netherrack)
B(-6,121,8,minecraft:netherrack)
B(-6,122,8,minecraft:netherrack)
B(-6,123,8,minecraft:netherrack)
B(-6,124,8,minecraft:netherrack)
B(-6,125,8,minecraft:netherrack)
B(-6,126,8,minecraft:netherrack)
B(-6,127,8,minecraft:netherrack)
B(-6,128,8,minecraft:netherrack)
B(-6,129,8,minecraft:netherrack)
B(-6,130,8,minecraft:netherrack)
B(-6,131,8,minecraft:netherrack)
B(-6,132,8,minecraft:netherrack)
B(-6,133,8,minecraft:netherrack)
B(-6,134,8,minecraft:netherrack)
B(-5,133,-1,minecraft:netherrack)
B(-5,134,-1,minecraft:netherrack)
B(-5,130,0,minecraft:netherrack)
B(-5,131,0,minecraft:netherrack)
B(-5,132,0,minecraft:netherrack)
B(-5,133,0,minecraft:netherrack)
B(-5,134,0,minecraft:netherrack)
B(-5,128,1,minecraft:netherrack)
B(-5,129,1,minecraft:netherrack)
B(-5,130,1,minecraft:netherrack)
B(-5,131,1,minecraft:netherrack)
B(-5,132,1,minecraft:netherrack)
B(-5,133,1,minecraft:netherrack)
B(-5,134,1,minecraft:netherrack)
B(-5,125,2,minecraft:netherrack)
B(-5,126,2,minecraft:netherrack)
B(-5,127,2,minecraft:netherrack)
B(-5,128,2,minecraft:netherrack)
B(-5,129,2,minecraft:netherrack)
B(-5,130,2,minecraft:netherrack)
B(-5,131,2,minecraft:netherrack)
B(-5,132,2,minecraft:netherrack)
B(-5,133,2,minecraft:netherrack)
B(-5,134,2,minecraft:netherrack)
B(-5,122,3,minecraft:netherrack)
B(-5,123,3,minecraft:netherrack)
B(-5,124,3,minecraft:netherrack)
B(-5,125,3,minecraft:netherrack)
B(-5,126,3,minecraft:netherrack)
B(-5,127,3,minecraft:netherrack)
B(-5,128,3,minecraft:netherrack)
B(-5,129,3,minecraft:netherrack)
B(-5,130,3,minecraft:netherrack)
B(-5,131,3,minecraft:netherrack)
B(-5,132,3,minecraft:netherrack)
B(-5,133,3,minecraft:netherrack)
B(-5,134,3,minecraft:netherrack)
B(-5,118,4,minecraft:netherrack)
B(-5,119,4,minecraft:netherrack)
B(-5,120,4,minecraft:netherrack)
B(-5,121,4,minecraft:netherrack)
B(-5,122,4,minecraft:netherrack)
B(-5,123,4,minecraft:netherrack)
B(-5,124,4,minecraft:netherrack)
B(-5,125,4,minecraft:netherrack)
B(-5,126,4,minecraft:netherrack)
B(-5,127,4,minecraft:netherrack)
B(-5,128,4,minecraft:netherrack)
B(-5,129,4,minecraft:netherrack)
B(-5,130,4,minecraft:netherrack)
B(-5,131,4,minecraft:netherrack)
B(-5,132,4,minecraft:netherrack)
B(-5,133,4,minecraft:netherrack)
B(-5,134,4,minecraft:netherrack)
B(-5,115,5,minecraft:netherrack)
B(-5,116,5,minecraft:netherrack)
B(-5,117,5,minecraft:netherrack)
B(-5,118,5,minecraft:netherrack)
B(-5,119,5,minecraft:netherrack)
B(-5,120,5,minecraft:netherrack)
B(-5,121,5,minecraft:netherrack)
B(-5,122,5,minecraft:netherrack)
B(-5,123,5,minecraft:netherrack)
B(-5,124,5,minecraft:netherrack)
B(-5,125,5,minecraft:netherrack)
B(-5,126,5,minecraft:netherrack)
B(-5,127,5,minecraft:netherrack)
B(-5,128,5,minecraft:netherrack)
B(-5,129,5,minecraft:netherrack)
B(-5,130,5,minecraft:netherrack)
B(-5,131,5,minecraft:netherrack)
B(-5,132,5,minecraft:netherrack)
B(-5,133,5,minecraft:netherrack)
B(-5,134,5,minecraft:netherrack)
B(-5,112,6,minecraft:netherrack)
B(-5,113,6,minecraft:netherrack)
B(-5,114,6,minecraft:netherrack)
B(-5,115,6,minecraft:netherrack)
B(-5,116,6,minecraft:netherrack)
B(-5,117,6,minecraft:netherrack)
B(-5,118,6,minecraft:netherrack)
B(-5,119,6,minecraft:netherrack)
B(-5,120,6,minecraft:netherrack)
B(-5,121,6,minecraft:netherrack)
B(-5,122,6,minecraft:netherrack)
B(-5,123,6,minecraft:netherrack)
B(-5,124,6,minecraft:netherrack)
B(-5,125,6,minecraft:netherrack)
B(-5,126,6,minecraft:netherrack)
B(-5,127,6,minecraft:netherrack)
B(-5,128,6,minecraft:netherrack)
B(-5,129,6,minecraft:netherrack)
B(-5,130,6,minecraft:netherrack)
B(-5,131,6,minecraft:netherrack)
B(-5,132,6,minecraft:netherrack)
B(-5,133,6,minecraft:netherrack)
B(-5,134,6,minecraft:netherrack)
B(-5,112,7,minecraft:netherrack)
B(-5,113,7,minecraft:netherrack)
B(-5,114,7,minecraft:netherrack)
B(-5,115,7,minecraft:netherrack)
B(-5,116,7,minecraft:netherrack)
B(-5,117,7,minecraft:netherrack)
B(-5,118,7,minecraft:netherrack)
B(-5,119,7,minecraft:netherrack)
B(-5,120,7,minecraft:netherrack)
B(-5,121,7,minecraft:netherrack)
B(-5,122,7,minecraft:netherrack)
B(-5,123,7,minecraft:netherrack)
B(-5,124,7,minecraft:netherrack)
B(-5,125,7,minecraft:netherrack)
B(-5,126,7,minecraft:netherrack)
B(-5,127,7,minecraft:netherrack)
B(-5,128,7,minecraft:netherrack)
B(-5,129,7,minecraft:netherrack)
B(-5,130,7,minecraft:netherrack)
B(-5,131,7,minecraft:netherrack)
B(-5,132,7,minecraft:netherrack)
B(-5,133,7,minecraft:netherrack)
B(-5,134,7,minecraft:netherrack)
B(-5,111,8,minecraft:netherrack)
B(-5,112,8,minecraft:netherrack)
B(-5,113,8,minecraft:netherrack)
B(-5,114,8,minecraft:netherrack)
B(-5,115,8,minecraft:netherrack)
B(-5,116,8,minecraft:netherrack)
B(-5,117,8,minecraft:netherrack)
B(-5,118,8,minecraft:netherrack)
B(-5,119,8,minecraft:netherrack)
B(-5,120,8,minecraft:netherrack)
B(-5,121,8,minecraft:netherrack)
B(-5,122,8,minecraft:netherrack)
B(-5,123,8,minecraft:netherrack)
B(-5,124,8,minecraft:netherrack)
B(-5,125,8,minecraft:netherrack)
B(-5,126,8,minecraft:netherrack)
B(-5,127,8,minecraft:netherrack)
B(-5,128,8,minecraft:netherrack)
B(-5,129,8,minecraft:netherrack)
B(-5,130,8,minecraft:netherrack)
B(-5,131,8,minecraft:netherrack)
B(-5,132,8,minecraft:netherrack)
B(-5,133,8,minecraft:netherrack)
B(-5,134,8,minecraft:netherrack)

#######################################################################
# +-----------------------------------------------------------------+ #
# |                             Branches                            | #
# +-----------------------------------------------------------------+ #
#######################################################################


#######################################################################
# +-----------------------------------------------------------------+ #
# |                             Entities                            | #
# +-----------------------------------------------------------------+ #
#######################################################################

