
#######################################################################
# +-----------------------------------------------------------------+ #
# |                            BO4 object                           | #
# +-----------------------------------------------------------------+ #
#######################################################################

Author: Unknown

Description: No description given

SettingsMode: WriteWithoutComments


#######################################################################
# +-----------------------------------------------------------------+ #
# |                          Main settings                          | #
# +-----------------------------------------------------------------+ #
#######################################################################

FixedRotation: 

Frequency: 0

SpawnHeight: highestBlock

UseCenterForHighestBlock: true

##############################
# Height Limits for the BO4. #
##############################

MinHeight: 0

MaxHeight: 255

InheritBO3: 

InheritBO3Rotation: NORTH

OverrideChildSettings: true

OverrideParentHeight: false

CanOverride: false

BranchFrequency: 0

BranchFrequencyGroup: 

MustBeBelowOther: false

MustBeInside: 

CannotBeInside: 

ReplacesBO3: 

MustBeInsideWorldBorders: false

CanSpawnOnWater: true

SpawnOnWaterOnly: false

SpawnUnderWater: false

SpawnAtWaterLevel: false

HeightOffset: 0

RemoveAir: true

ReplaceAbove: 

ReplaceBelow: 

ReplaceWithBiomeBlocks: true

ReplaceWithSurfaceBlock: GRASS

ReplaceWithGroundBlock: DIRT

ReplaceWithStoneBlock: STONE

SmoothRadius: 0

SmoothHeightOffset: 0

SmoothStartTop: false

SmoothStartWood: false

SmoothingSurfaceBlock: 

SmoothingGroundBlock: 

BO3Group: 

IsSpawnPoint: false

DoReplaceBlocks: true


#######################################################################
# +-----------------------------------------------------------------+ #
# |                              Blocks                             | #
# +-----------------------------------------------------------------+ #
#######################################################################

B(-8,110,-7,minecraft:netherrack)
B(-8,111,-7,minecraft:netherrack)
B(-8,112,-7,minecraft:netherrack)
B(-8,113,-7,minecraft:netherrack)
B(-8,114,-7,minecraft:netherrack)
B(-8,115,-7,minecraft:netherrack)
B(-8,116,-7,minecraft:netherrack)
B(-8,117,-7,minecraft:netherrack)
B(-8,118,-7,minecraft:netherrack)
B(-8,119,-7,minecraft:netherrack)
B(-8,120,-7,minecraft:netherrack)
B(-8,121,-7,minecraft:netherrack)
B(-8,122,-7,minecraft:netherrack)
B(-8,123,-7,minecraft:netherrack)
B(-8,124,-7,minecraft:netherrack)
B(-8,125,-7,minecraft:netherrack)
B(-8,126,-7,minecraft:netherrack)
B(-8,127,-7,minecraft:netherrack)
B(-8,128,-7,minecraft:netherrack)
B(-8,129,-7,minecraft:netherrack)
B(-8,130,-7,minecraft:netherrack)
B(-8,131,-7,minecraft:netherrack)
B(-8,132,-7,minecraft:netherrack)
B(-8,133,-7,minecraft:netherrack)
B(-8,134,-7,minecraft:netherrack)
B(-8,110,-6,minecraft:netherrack)
B(-8,111,-6,minecraft:netherrack)
B(-8,112,-6,minecraft:netherrack)
B(-8,113,-6,minecraft:netherrack)
B(-8,114,-6,minecraft:netherrack)
B(-8,115,-6,minecraft:netherrack)
B(-8,116,-6,minecraft:netherrack)
B(-8,117,-6,minecraft:netherrack)
B(-8,118,-6,minecraft:netherrack)
B(-8,119,-6,minecraft:netherrack)
B(-8,120,-6,minecraft:netherrack)
B(-8,121,-6,minecraft:netherrack)
B(-8,122,-6,minecraft:netherrack)
B(-8,123,-6,minecraft:netherrack)
B(-8,124,-6,minecraft:netherrack)
B(-8,125,-6,minecraft:netherrack)
B(-8,126,-6,minecraft:netherrack)
B(-8,127,-6,minecraft:netherrack)
B(-8,128,-6,minecraft:netherrack)
B(-8,129,-6,minecraft:netherrack)
B(-8,130,-6,minecraft:netherrack)
B(-8,131,-6,minecraft:netherrack)
B(-8,132,-6,minecraft:netherrack)
B(-8,133,-6,minecraft:netherrack)
B(-8,134,-6,minecraft:netherrack)
B(-8,109,-5,minecraft:netherrack)
B(-8,110,-5,minecraft:netherrack)
B(-8,111,-5,minecraft:netherrack)
B(-8,112,-5,minecraft:netherrack)
B(-8,113,-5,minecraft:netherrack)
B(-8,114,-5,minecraft:netherrack)
B(-8,115,-5,minecraft:netherrack)
B(-8,116,-5,minecraft:netherrack)
B(-8,117,-5,minecraft:netherrack)
B(-8,118,-5,minecraft:netherrack)
B(-8,119,-5,minecraft:netherrack)
B(-8,120,-5,minecraft:netherrack)
B(-8,121,-5,minecraft:netherrack)
B(-8,122,-5,minecraft:netherrack)
B(-8,123,-5,minecraft:netherrack)
B(-8,124,-5,minecraft:netherrack)
B(-8,125,-5,minecraft:netherrack)
B(-8,126,-5,minecraft:netherrack)
B(-8,127,-5,minecraft:netherrack)
B(-8,128,-5,minecraft:netherrack)
B(-8,129,-5,minecraft:netherrack)
B(-8,130,-5,minecraft:netherrack)
B(-8,131,-5,minecraft:netherrack)
B(-8,132,-5,minecraft:netherrack)
B(-8,133,-5,minecraft:netherrack)
B(-8,134,-5,minecraft:netherrack)
B(-7,111,-7,minecraft:netherrack)
B(-7,112,-7,minecraft:netherrack)
B(-7,113,-7,minecraft:netherrack)
B(-7,114,-7,minecraft:netherrack)
B(-7,115,-7,minecraft:netherrack)
B(-7,116,-7,minecraft:netherrack)
B(-7,117,-7,minecraft:netherrack)
B(-7,118,-7,minecraft:netherrack)
B(-7,119,-7,minecraft:netherrack)
B(-7,120,-7,minecraft:netherrack)
B(-7,121,-7,minecraft:netherrack)
B(-7,122,-7,minecraft:netherrack)
B(-7,123,-7,minecraft:netherrack)
B(-7,124,-7,minecraft:netherrack)
B(-7,125,-7,minecraft:netherrack)
B(-7,126,-7,minecraft:netherrack)
B(-7,127,-7,minecraft:netherrack)
B(-7,128,-7,minecraft:netherrack)
B(-7,129,-7,minecraft:netherrack)
B(-7,130,-7,minecraft:netherrack)
B(-7,131,-7,minecraft:netherrack)
B(-7,132,-7,minecraft:netherrack)
B(-7,133,-7,minecraft:netherrack)
B(-7,134,-7,minecraft:netherrack)
B(-7,110,-6,minecraft:netherrack)
B(-7,111,-6,minecraft:netherrack)
B(-7,112,-6,minecraft:netherrack)
B(-7,113,-6,minecraft:netherrack)
B(-7,114,-6,minecraft:netherrack)
B(-7,115,-6,minecraft:netherrack)
B(-7,116,-6,minecraft:netherrack)
B(-7,117,-6,minecraft:netherrack)
B(-7,118,-6,minecraft:netherrack)
B(-7,119,-6,minecraft:netherrack)
B(-7,120,-6,minecraft:netherrack)
B(-7,121,-6,minecraft:netherrack)
B(-7,122,-6,minecraft:netherrack)
B(-7,123,-6,minecraft:netherrack)
B(-7,124,-6,minecraft:netherrack)
B(-7,125,-6,minecraft:netherrack)
B(-7,126,-6,minecraft:netherrack)
B(-7,127,-6,minecraft:netherrack)
B(-7,128,-6,minecraft:netherrack)
B(-7,129,-6,minecraft:netherrack)
B(-7,130,-6,minecraft:netherrack)
B(-7,131,-6,minecraft:netherrack)
B(-7,132,-6,minecraft:netherrack)
B(-7,133,-6,minecraft:netherrack)
B(-7,134,-6,minecraft:netherrack)
B(-7,109,-5,minecraft:netherrack)
B(-7,110,-5,minecraft:netherrack)
B(-7,111,-5,minecraft:netherrack)
B(-7,112,-5,minecraft:netherrack)
B(-7,113,-5,minecraft:netherrack)
B(-7,114,-5,minecraft:netherrack)
B(-7,115,-5,minecraft:netherrack)
B(-7,116,-5,minecraft:netherrack)
B(-7,117,-5,minecraft:netherrack)
B(-7,118,-5,minecraft:netherrack)
B(-7,119,-5,minecraft:netherrack)
B(-7,120,-5,minecraft:netherrack)
B(-7,121,-5,minecraft:netherrack)
B(-7,122,-5,minecraft:netherrack)
B(-7,123,-5,minecraft:netherrack)
B(-7,124,-5,minecraft:netherrack)
B(-7,125,-5,minecraft:netherrack)
B(-7,126,-5,minecraft:netherrack)
B(-7,127,-5,minecraft:netherrack)
B(-7,128,-5,minecraft:netherrack)
B(-7,129,-5,minecraft:netherrack)
B(-7,130,-5,minecraft:netherrack)
B(-7,131,-5,minecraft:netherrack)
B(-7,132,-5,minecraft:netherrack)
B(-7,133,-5,minecraft:netherrack)
B(-7,134,-5,minecraft:netherrack)
B(-6,111,-7,minecraft:netherrack)
B(-6,112,-7,minecraft:netherrack)
B(-6,113,-7,minecraft:netherrack)
B(-6,114,-7,minecraft:netherrack)
B(-6,115,-7,minecraft:netherrack)
B(-6,116,-7,minecraft:netherrack)
B(-6,117,-7,minecraft:netherrack)
B(-6,118,-7,minecraft:netherrack)
B(-6,119,-7,minecraft:netherrack)
B(-6,120,-7,minecraft:netherrack)
B(-6,121,-7,minecraft:netherrack)
B(-6,122,-7,minecraft:netherrack)
B(-6,123,-7,minecraft:netherrack)
B(-6,124,-7,minecraft:netherrack)
B(-6,125,-7,minecraft:netherrack)
B(-6,126,-7,minecraft:netherrack)
B(-6,127,-7,minecraft:netherrack)
B(-6,128,-7,minecraft:netherrack)
B(-6,129,-7,minecraft:netherrack)
B(-6,130,-7,minecraft:netherrack)
B(-6,131,-7,minecraft:netherrack)
B(-6,132,-7,minecraft:netherrack)
B(-6,133,-7,minecraft:netherrack)
B(-6,134,-7,minecraft:netherrack)
B(-6,110,-6,minecraft:netherrack)
B(-6,111,-6,minecraft:netherrack)
B(-6,112,-6,minecraft:netherrack)
B(-6,113,-6,minecraft:netherrack)
B(-6,114,-6,minecraft:netherrack)
B(-6,115,-6,minecraft:netherrack)
B(-6,116,-6,minecraft:netherrack)
B(-6,117,-6,minecraft:netherrack)
B(-6,118,-6,minecraft:netherrack)
B(-6,119,-6,minecraft:netherrack)
B(-6,120,-6,minecraft:netherrack)
B(-6,121,-6,minecraft:netherrack)
B(-6,122,-6,minecraft:netherrack)
B(-6,123,-6,minecraft:netherrack)
B(-6,124,-6,minecraft:netherrack)
B(-6,125,-6,minecraft:netherrack)
B(-6,126,-6,minecraft:netherrack)
B(-6,127,-6,minecraft:netherrack)
B(-6,128,-6,minecraft:netherrack)
B(-6,129,-6,minecraft:netherrack)
B(-6,130,-6,minecraft:netherrack)
B(-6,131,-6,minecraft:netherrack)
B(-6,132,-6,minecraft:netherrack)
B(-6,133,-6,minecraft:netherrack)
B(-6,134,-6,minecraft:netherrack)
B(-6,109,-5,minecraft:netherrack)
B(-6,110,-5,minecraft:netherrack)
B(-6,111,-5,minecraft:netherrack)
B(-6,112,-5,minecraft:netherrack)
B(-6,113,-5,minecraft:netherrack)
B(-6,114,-5,minecraft:netherrack)
B(-6,115,-5,minecraft:netherrack)
B(-6,116,-5,minecraft:netherrack)
B(-6,117,-5,minecraft:netherrack)
B(-6,118,-5,minecraft:netherrack)
B(-6,119,-5,minecraft:netherrack)
B(-6,120,-5,minecraft:netherrack)
B(-6,121,-5,minecraft:netherrack)
B(-6,122,-5,minecraft:netherrack)
B(-6,123,-5,minecraft:netherrack)
B(-6,124,-5,minecraft:netherrack)
B(-6,125,-5,minecraft:netherrack)
B(-6,126,-5,minecraft:netherrack)
B(-6,127,-5,minecraft:netherrack)
B(-6,128,-5,minecraft:netherrack)
B(-6,129,-5,minecraft:netherrack)
B(-6,130,-5,minecraft:netherrack)
B(-6,131,-5,minecraft:netherrack)
B(-6,132,-5,minecraft:netherrack)
B(-6,133,-5,minecraft:netherrack)
B(-6,134,-5,minecraft:netherrack)
B(-5,110,-7,minecraft:netherrack)
B(-5,111,-7,minecraft:netherrack)
B(-5,112,-7,minecraft:netherrack)
B(-5,113,-7,minecraft:netherrack)
B(-5,114,-7,minecraft:netherrack)
B(-5,115,-7,minecraft:netherrack)
B(-5,116,-7,minecraft:netherrack)
B(-5,117,-7,minecraft:netherrack)
B(-5,118,-7,minecraft:netherrack)
B(-5,119,-7,minecraft:netherrack)
B(-5,120,-7,minecraft:netherrack)
B(-5,121,-7,minecraft:netherrack)
B(-5,122,-7,minecraft:netherrack)
B(-5,123,-7,minecraft:netherrack)
B(-5,124,-7,minecraft:netherrack)
B(-5,125,-7,minecraft:netherrack)
B(-5,126,-7,minecraft:netherrack)
B(-5,127,-7,minecraft:netherrack)
B(-5,128,-7,minecraft:netherrack)
B(-5,129,-7,minecraft:netherrack)
B(-5,130,-7,minecraft:netherrack)
B(-5,131,-7,minecraft:netherrack)
B(-5,132,-7,minecraft:netherrack)
B(-5,133,-7,minecraft:netherrack)
B(-5,134,-7,minecraft:netherrack)
B(-5,109,-6,minecraft:netherrack)
B(-5,110,-6,minecraft:netherrack)
B(-5,111,-6,minecraft:netherrack)
B(-5,112,-6,minecraft:netherrack)
B(-5,113,-6,minecraft:netherrack)
B(-5,114,-6,minecraft:netherrack)
B(-5,115,-6,minecraft:netherrack)
B(-5,116,-6,minecraft:netherrack)
B(-5,117,-6,minecraft:netherrack)
B(-5,118,-6,minecraft:netherrack)
B(-5,119,-6,minecraft:netherrack)
B(-5,120,-6,minecraft:netherrack)
B(-5,121,-6,minecraft:netherrack)
B(-5,122,-6,minecraft:netherrack)
B(-5,123,-6,minecraft:netherrack)
B(-5,124,-6,minecraft:netherrack)
B(-5,125,-6,minecraft:netherrack)
B(-5,126,-6,minecraft:netherrack)
B(-5,127,-6,minecraft:netherrack)
B(-5,128,-6,minecraft:netherrack)
B(-5,129,-6,minecraft:netherrack)
B(-5,130,-6,minecraft:netherrack)
B(-5,131,-6,minecraft:netherrack)
B(-5,132,-6,minecraft:netherrack)
B(-5,133,-6,minecraft:netherrack)
B(-5,134,-6,minecraft:netherrack)
B(-5,108,-5,minecraft:netherrack)
B(-5,109,-5,minecraft:netherrack)
B(-5,110,-5,minecraft:netherrack)
B(-5,111,-5,minecraft:netherrack)
B(-5,112,-5,minecraft:netherrack)
B(-5,113,-5,minecraft:netherrack)
B(-5,114,-5,minecraft:netherrack)
B(-5,115,-5,minecraft:netherrack)
B(-5,116,-5,minecraft:netherrack)
B(-5,117,-5,minecraft:netherrack)
B(-5,118,-5,minecraft:netherrack)
B(-5,119,-5,minecraft:netherrack)
B(-5,120,-5,minecraft:netherrack)
B(-5,121,-5,minecraft:netherrack)
B(-5,122,-5,minecraft:netherrack)
B(-5,123,-5,minecraft:netherrack)
B(-5,124,-5,minecraft:netherrack)
B(-5,125,-5,minecraft:netherrack)
B(-5,126,-5,minecraft:netherrack)
B(-5,127,-5,minecraft:netherrack)
B(-5,128,-5,minecraft:netherrack)
B(-5,129,-5,minecraft:netherrack)
B(-5,130,-5,minecraft:netherrack)
B(-5,131,-5,minecraft:netherrack)
B(-5,132,-5,minecraft:netherrack)
B(-5,133,-5,minecraft:netherrack)
B(-5,134,-5,minecraft:netherrack)

#######################################################################
# +-----------------------------------------------------------------+ #
# |                             Branches                            | #
# +-----------------------------------------------------------------+ #
#######################################################################


#######################################################################
# +-----------------------------------------------------------------+ #
# |                             Entities                            | #
# +-----------------------------------------------------------------+ #
#######################################################################

