#######################################################################
# +-----------------------------------------------------------------+ #
# |                            BO3 object                           | #
# +-----------------------------------------------------------------+ #
#######################################################################

Author: Bo3 BulkEdit

Description: Converted Schematic - Modified by Bo3BulkEdit

Version: 3

SettingsMode: WriteDisable

#######################################################################
# +-----------------------------------------------------------------+ #
# |                          Main settings                          | #
# +-----------------------------------------------------------------+ #
#######################################################################

IsOTGPlus: true
Tree: true
Frequency: 10
Rarity: 100
RotateRandomly: true
SpawnHeight: randomY
SpawnHeightOffset: 0
SpawnHeightVariance: 0
MaxBranchDepth: 10
ExcludedBiomes: All

##############################
# Height Limits for the BO3. #
##############################

MinHeight: 50
MaxHeight: 65

#######################################################################
# +-----------------------------------------------------------------+ #
# |                      Source block settings                      | #
# +-----------------------------------------------------------------+ #
#######################################################################

SourceBlocks: AIR
MaxPercentageOutsideSourceBlock: 100
OutsideSourceBlock: placeAnyway

#######################################################################
# +-----------------------------------------------------------------+ #
# |                               OTG+                              | #
# +-----------------------------------------------------------------+ #
#######################################################################

RemoveAir: true
ReplaceBelow: OBSIDIAN
ReplaceWithBiomeBlocks: false
ReplaceWithGroundBlock: OBSIDIAN
ReplaceWithSurfaceBlock: OBSIDIAN
ReplaceWithStoneBlock: OBSIDIAN
SmoothRadius: 30
SmoothingSurfaceBlock: OBSIDIAN
SmoothingGroundBlock: OBSIDIAN

#######################################################################
# +-----------------------------------------------------------------+ #
# |                              Blocks                             | #
# +-----------------------------------------------------------------+ #
#######################################################################

RB(0,0,0,minecraft:crying_obsidian,20,minecraft:obsidian,100)
RB(1,0,0,minecraft:crying_obsidian,20,minecraft:obsidian,100)
RB(2,0,0,minecraft:crying_obsidian,20,minecraft:obsidian,100)
RB(3,0,0,minecraft:crying_obsidian,20,minecraft:obsidian,100)
RB(4,0,0,minecraft:crying_obsidian,20,minecraft:obsidian,100)
RB(5,0,0,minecraft:crying_obsidian,20,minecraft:obsidian,100)
RB(0,0,1,minecraft:crying_obsidian,20,minecraft:obsidian,100)
RB(1,0,1,minecraft:crying_obsidian,20,minecraft:obsidian,100)
RB(2,0,1,minecraft:crying_obsidian,20,minecraft:obsidian,100)
RB(3,0,1,minecraft:crying_obsidian,20,minecraft:obsidian,100)
RB(0,0,2,minecraft:crying_obsidian,20,minecraft:obsidian,100)
RB(1,0,2,minecraft:crying_obsidian,20,minecraft:obsidian,100)
RB(2,0,2,minecraft:crying_obsidian,20,minecraft:obsidian,100)
RB(3,0,2,minecraft:crying_obsidian,20,minecraft:obsidian,100)
RB(0,0,3,minecraft:crying_obsidian,20,minecraft:obsidian,100)
RB(1,0,3,minecraft:crying_obsidian,20,minecraft:obsidian,100)
RB(2,0,3,minecraft:crying_obsidian,20,minecraft:obsidian,100)
RB(3,0,3,minecraft:crying_obsidian,20,minecraft:obsidian,100)
RB(0,0,4,minecraft:crying_obsidian,20,minecraft:obsidian,100)
RB(1,0,4,minecraft:crying_obsidian,20,minecraft:obsidian,100)
RB(2,0,4,minecraft:crying_obsidian,20,minecraft:obsidian,100)
RB(0,0,5,minecraft:crying_obsidian,20,minecraft:obsidian,100)
RB(1,0,5,minecraft:crying_obsidian,20,minecraft:obsidian,100)
RB(2,0,5,minecraft:crying_obsidian,20,minecraft:obsidian,100)
RB(0,0,6,minecraft:crying_obsidian,20,minecraft:obsidian,100)
RB(1,0,6,minecraft:crying_obsidian,20,minecraft:obsidian,100)
RB(0,0,7,minecraft:crying_obsidian,20,minecraft:obsidian,100)
RB(1,0,7,minecraft:crying_obsidian,20,minecraft:obsidian,100)
RB(0,0,8,minecraft:crying_obsidian,20,minecraft:obsidian,100)
RB(0,0,11,minecraft:crying_obsidian,20,minecraft:obsidian,100)
RB(0,0,12,minecraft:crying_obsidian,20,minecraft:obsidian,100)
RB(0,0,13,minecraft:crying_obsidian,20,minecraft:obsidian,100)
RB(0,0,14,minecraft:crying_obsidian,20,minecraft:obsidian,100)
RB(0,0,15,minecraft:crying_obsidian,20,minecraft:obsidian,100)
RB(0,1,0,minecraft:crying_obsidian,20,minecraft:obsidian,100)
RB(1,1,0,minecraft:crying_obsidian,20,minecraft:obsidian,100)
RB(2,1,0,minecraft:crying_obsidian,20,minecraft:obsidian,100)
RB(3,1,0,minecraft:crying_obsidian,20,minecraft:obsidian,100)
RB(4,1,0,minecraft:crying_obsidian,20,minecraft:obsidian,100)
RB(0,1,1,minecraft:crying_obsidian,20,minecraft:obsidian,100)
RB(1,1,1,minecraft:crying_obsidian,20,minecraft:obsidian,100)
RB(2,1,1,minecraft:crying_obsidian,20,minecraft:obsidian,100)
RB(3,1,1,minecraft:crying_obsidian,20,minecraft:obsidian,100)
RB(0,1,2,minecraft:crying_obsidian,20,minecraft:obsidian,100)
RB(1,1,2,minecraft:crying_obsidian,20,minecraft:obsidian,100)
RB(2,1,2,minecraft:crying_obsidian,20,minecraft:obsidian,100)
RB(0,1,3,minecraft:crying_obsidian,20,minecraft:obsidian,100)
RB(1,1,3,minecraft:crying_obsidian,20,minecraft:obsidian,100)
RB(2,1,3,minecraft:crying_obsidian,20,minecraft:obsidian,100)
RB(0,1,4,minecraft:crying_obsidian,20,minecraft:obsidian,100)
RB(1,1,4,minecraft:crying_obsidian,20,minecraft:obsidian,100)
RB(2,1,4,minecraft:crying_obsidian,20,minecraft:obsidian,100)
RB(0,1,5,minecraft:crying_obsidian,20,minecraft:obsidian,100)
RB(1,1,5,minecraft:crying_obsidian,20,minecraft:obsidian,100)
RB(0,1,6,minecraft:crying_obsidian,20,minecraft:obsidian,100)
RB(1,1,6,minecraft:crying_obsidian,20,minecraft:obsidian,100)
RB(0,1,7,minecraft:crying_obsidian,20,minecraft:obsidian,100)
RB(1,1,7,minecraft:crying_obsidian,20,minecraft:obsidian,100)
RB(0,1,8,minecraft:crying_obsidian,20,minecraft:obsidian,100)
RB(0,1,11,minecraft:crying_obsidian,20,minecraft:obsidian,100)
RB(0,1,12,minecraft:crying_obsidian,20,minecraft:obsidian,100)
RB(0,1,13,minecraft:crying_obsidian,20,minecraft:obsidian,100)
RB(0,1,14,minecraft:crying_obsidian,20,minecraft:obsidian,100)
RB(0,2,0,minecraft:crying_obsidian,20,minecraft:obsidian,100)
RB(1,2,0,minecraft:crying_obsidian,20,minecraft:obsidian,100)
RB(2,2,0,minecraft:crying_obsidian,20,minecraft:obsidian,100)
RB(3,2,0,minecraft:crying_obsidian,20,minecraft:obsidian,100)
RB(4,2,0,minecraft:crying_obsidian,20,minecraft:obsidian,100)
RB(0,2,1,minecraft:crying_obsidian,20,minecraft:obsidian,100)
RB(1,2,1,minecraft:crying_obsidian,20,minecraft:obsidian,100)
RB(2,2,1,minecraft:crying_obsidian,20,minecraft:obsidian,100)
RB(3,2,1,minecraft:crying_obsidian,20,minecraft:obsidian,100)
RB(0,2,2,minecraft:crying_obsidian,20,minecraft:obsidian,100)
RB(1,2,2,minecraft:crying_obsidian,20,minecraft:obsidian,100)
RB(2,2,2,minecraft:crying_obsidian,20,minecraft:obsidian,100)
RB(0,2,3,minecraft:crying_obsidian,20,minecraft:obsidian,100)
RB(1,2,3,minecraft:crying_obsidian,20,minecraft:obsidian,100)
RB(0,2,4,minecraft:crying_obsidian,20,minecraft:obsidian,100)
RB(1,2,4,minecraft:crying_obsidian,20,minecraft:obsidian,100)
RB(0,2,5,minecraft:crying_obsidian,20,minecraft:obsidian,100)
RB(1,2,5,minecraft:crying_obsidian,20,minecraft:obsidian,100)
RB(0,2,6,minecraft:crying_obsidian,20,minecraft:obsidian,100)
RB(1,2,6,minecraft:crying_obsidian,20,minecraft:obsidian,100)
RB(0,2,7,minecraft:crying_obsidian,20,minecraft:obsidian,100)
RB(0,2,8,minecraft:crying_obsidian,20,minecraft:obsidian,100)
RB(0,2,11,minecraft:crying_obsidian,20,minecraft:obsidian,100)
RB(0,2,12,minecraft:crying_obsidian,20,minecraft:obsidian,100)
RB(0,2,13,minecraft:crying_obsidian,20,minecraft:obsidian,100)
RB(0,2,14,minecraft:crying_obsidian,20,minecraft:obsidian,100)
RB(0,3,0,minecraft:crying_obsidian,20,minecraft:obsidian,100)
RB(1,3,0,minecraft:crying_obsidian,20,minecraft:obsidian,100)
RB(2,3,0,minecraft:crying_obsidian,20,minecraft:obsidian,100)
RB(3,3,0,minecraft:crying_obsidian,20,minecraft:obsidian,100)
RB(4,3,0,minecraft:crying_obsidian,20,minecraft:obsidian,100)
RB(0,3,1,minecraft:crying_obsidian,20,minecraft:obsidian,100)
RB(1,3,1,minecraft:crying_obsidian,20,minecraft:obsidian,100)
RB(2,3,1,minecraft:crying_obsidian,20,minecraft:obsidian,100)
RB(3,3,1,minecraft:crying_obsidian,20,minecraft:obsidian,100)
RB(0,3,2,minecraft:crying_obsidian,20,minecraft:obsidian,100)
RB(1,3,2,minecraft:crying_obsidian,20,minecraft:obsidian,100)
RB(2,3,2,minecraft:crying_obsidian,20,minecraft:obsidian,100)
RB(0,3,3,minecraft:crying_obsidian,20,minecraft:obsidian,100)
RB(1,3,3,minecraft:crying_obsidian,20,minecraft:obsidian,100)
RB(0,3,4,minecraft:crying_obsidian,20,minecraft:obsidian,100)
RB(1,3,4,minecraft:crying_obsidian,20,minecraft:obsidian,100)
RB(0,3,5,minecraft:crying_obsidian,20,minecraft:obsidian,100)
RB(1,3,5,minecraft:crying_obsidian,20,minecraft:obsidian,100)
RB(0,3,6,minecraft:crying_obsidian,20,minecraft:obsidian,100)
RB(1,3,6,minecraft:crying_obsidian,20,minecraft:obsidian,100)
RB(0,3,7,minecraft:crying_obsidian,20,minecraft:obsidian,100)
RB(0,3,8,minecraft:crying_obsidian,20,minecraft:obsidian,100)
RB(0,3,12,minecraft:crying_obsidian,20,minecraft:obsidian,100)
RB(0,3,13,minecraft:crying_obsidian,20,minecraft:obsidian,100)
RB(0,3,14,minecraft:crying_obsidian,20,minecraft:obsidian,100)
RB(0,4,0,minecraft:crying_obsidian,20,minecraft:obsidian,100)
RB(1,4,0,minecraft:crying_obsidian,20,minecraft:obsidian,100)
RB(2,4,0,minecraft:crying_obsidian,20,minecraft:obsidian,100)
RB(3,4,0,minecraft:crying_obsidian,20,minecraft:obsidian,100)
RB(4,4,0,minecraft:crying_obsidian,20,minecraft:obsidian,100)
RB(0,4,1,minecraft:crying_obsidian,20,minecraft:obsidian,100)
RB(1,4,1,minecraft:crying_obsidian,20,minecraft:obsidian,100)
RB(2,4,1,minecraft:crying_obsidian,20,minecraft:obsidian,100)
RB(3,4,1,minecraft:crying_obsidian,20,minecraft:obsidian,100)
RB(0,4,2,minecraft:crying_obsidian,20,minecraft:obsidian,100)
RB(1,4,2,minecraft:crying_obsidian,20,minecraft:obsidian,100)
RB(2,4,2,minecraft:crying_obsidian,20,minecraft:obsidian,100)
RB(0,4,3,minecraft:crying_obsidian,20,minecraft:obsidian,100)
RB(1,4,3,minecraft:crying_obsidian,20,minecraft:obsidian,100)
RB(0,4,4,minecraft:crying_obsidian,20,minecraft:obsidian,100)
RB(1,4,4,minecraft:crying_obsidian,20,minecraft:obsidian,100)
RB(0,4,5,minecraft:crying_obsidian,20,minecraft:obsidian,100)
RB(1,4,5,minecraft:crying_obsidian,20,minecraft:obsidian,100)
RB(0,4,6,minecraft:crying_obsidian,20,minecraft:obsidian,100)
RB(1,4,6,minecraft:crying_obsidian,20,minecraft:obsidian,100)
RB(0,4,7,minecraft:crying_obsidian,20,minecraft:obsidian,100)
RB(0,4,12,minecraft:crying_obsidian,20,minecraft:obsidian,100)
RB(0,4,13,minecraft:crying_obsidian,20,minecraft:obsidian,100)
RB(0,5,0,minecraft:crying_obsidian,20,minecraft:obsidian,100)
RB(1,5,0,minecraft:crying_obsidian,20,minecraft:obsidian,100)
RB(2,5,0,minecraft:crying_obsidian,20,minecraft:obsidian,100)
RB(3,5,0,minecraft:crying_obsidian,20,minecraft:obsidian,100)
RB(4,5,0,minecraft:crying_obsidian,20,minecraft:obsidian,100)
RB(0,5,1,minecraft:crying_obsidian,20,minecraft:obsidian,100)
RB(1,5,1,minecraft:crying_obsidian,20,minecraft:obsidian,100)
RB(2,5,1,minecraft:crying_obsidian,20,minecraft:obsidian,100)
RB(0,5,2,minecraft:crying_obsidian,20,minecraft:obsidian,100)
RB(1,5,2,minecraft:crying_obsidian,20,minecraft:obsidian,100)
RB(0,5,3,minecraft:crying_obsidian,20,minecraft:obsidian,100)
RB(1,5,3,minecraft:crying_obsidian,20,minecraft:obsidian,100)
RB(0,5,4,minecraft:crying_obsidian,20,minecraft:obsidian,100)
RB(1,5,4,minecraft:crying_obsidian,20,minecraft:obsidian,100)
RB(0,5,5,minecraft:crying_obsidian,20,minecraft:obsidian,100)
RB(1,5,5,minecraft:crying_obsidian,20,minecraft:obsidian,100)
RB(0,5,6,minecraft:crying_obsidian,20,minecraft:obsidian,100)
RB(1,5,6,minecraft:crying_obsidian,20,minecraft:obsidian,100)
RB(0,5,7,minecraft:crying_obsidian,20,minecraft:obsidian,100)
RB(0,6,0,minecraft:crying_obsidian,20,minecraft:obsidian,100)
RB(1,6,0,minecraft:crying_obsidian,20,minecraft:obsidian,100)
RB(2,6,0,minecraft:crying_obsidian,20,minecraft:obsidian,100)
RB(3,6,0,minecraft:crying_obsidian,20,minecraft:obsidian,100)
RB(0,6,1,minecraft:crying_obsidian,20,minecraft:obsidian,100)
RB(1,6,1,minecraft:crying_obsidian,20,minecraft:obsidian,100)
RB(0,6,2,minecraft:crying_obsidian,20,minecraft:obsidian,100)
RB(0,6,3,minecraft:crying_obsidian,20,minecraft:obsidian,100)
RB(1,6,3,minecraft:crying_obsidian,20,minecraft:obsidian,100)
RB(0,6,4,minecraft:crying_obsidian,20,minecraft:obsidian,100)
RB(1,6,4,minecraft:crying_obsidian,20,minecraft:obsidian,100)
RB(0,6,5,minecraft:crying_obsidian,20,minecraft:obsidian,100)
RB(1,6,5,minecraft:crying_obsidian,20,minecraft:obsidian,100)
RB(0,6,6,minecraft:crying_obsidian,20,minecraft:obsidian,100)
RB(0,6,7,minecraft:crying_obsidian,20,minecraft:obsidian,100)
RB(0,7,0,minecraft:crying_obsidian,20,minecraft:obsidian,100)
RB(1,7,0,minecraft:crying_obsidian,20,minecraft:obsidian,100)
RB(0,7,1,minecraft:crying_obsidian,20,minecraft:obsidian,100)
RB(0,7,2,minecraft:crying_obsidian,20,minecraft:obsidian,100)
RB(0,7,3,minecraft:crying_obsidian,20,minecraft:obsidian,100)
RB(0,7,4,minecraft:crying_obsidian,20,minecraft:obsidian,100)
RB(1,7,4,minecraft:crying_obsidian,20,minecraft:obsidian,100)
RB(0,7,5,minecraft:crying_obsidian,20,minecraft:obsidian,100)
RB(0,7,6,minecraft:crying_obsidian,20,minecraft:obsidian,100)
RB(0,8,0,minecraft:crying_obsidian,20,minecraft:obsidian,100)
RB(1,8,0,minecraft:crying_obsidian,20,minecraft:obsidian,100)
RB(0,8,1,minecraft:crying_obsidian,20,minecraft:obsidian,100)
RB(0,8,2,minecraft:crying_obsidian,20,minecraft:obsidian,100)
RB(0,8,3,minecraft:crying_obsidian,20,minecraft:obsidian,100)
RB(0,8,4,minecraft:crying_obsidian,20,minecraft:obsidian,100)
RB(0,8,5,minecraft:crying_obsidian,20,minecraft:obsidian,100)
RB(0,8,6,minecraft:crying_obsidian,20,minecraft:obsidian,100)
RB(0,9,0,minecraft:crying_obsidian,20,minecraft:obsidian,100)
RB(1,9,0,minecraft:crying_obsidian,20,minecraft:obsidian,100)
RB(0,9,1,minecraft:crying_obsidian,20,minecraft:obsidian,100)
RB(0,9,2,minecraft:crying_obsidian,20,minecraft:obsidian,100)
RB(0,9,3,minecraft:crying_obsidian,20,minecraft:obsidian,100)
RB(0,9,4,minecraft:crying_obsidian,20,minecraft:obsidian,100)
RB(0,9,5,minecraft:crying_obsidian,20,minecraft:obsidian,100)
RB(0,10,0,minecraft:crying_obsidian,20,minecraft:obsidian,100)
RB(0,10,1,minecraft:crying_obsidian,20,minecraft:obsidian,100)
RB(0,10,2,minecraft:crying_obsidian,20,minecraft:obsidian,100)
RB(0,10,3,minecraft:crying_obsidian,20,minecraft:obsidian,100)
RB(0,11,0,minecraft:crying_obsidian,20,minecraft:obsidian,100)
RB(0,11,1,minecraft:crying_obsidian,20,minecraft:obsidian,100)
RB(0,11,3,minecraft:crying_obsidian,20,minecraft:obsidian,100)
RB(0,12,0,minecraft:crying_obsidian,20,minecraft:obsidian,100)
RB(0,13,0,minecraft:crying_obsidian,20,minecraft:obsidian,100)
RB(0,14,0,minecraft:crying_obsidian,20,minecraft:obsidian,100)

