#######################################################################
# +-----------------------------------------------------------------+ #
# |                            BO3 object                           | #
# +-----------------------------------------------------------------+ #
#######################################################################

Author: Bo3 BulkEdit

Description: Converted Schematic - Modified by Bo3BulkEdit

Version: 3

SettingsMode: WriteDisable

#######################################################################
# +-----------------------------------------------------------------+ #
# |                          Main settings                          | #
# +-----------------------------------------------------------------+ #
#######################################################################

IsOTGPlus: true
Tree: true
Frequency: 10
Rarity: 100
RotateRandomly: true
SpawnHeight: randomY
SpawnHeightOffset: 0
SpawnHeightVariance: 0
MaxBranchDepth: 10
ExcludedBiomes: All

##############################
# Height Limits for the BO3. #
##############################

MinHeight: 50
MaxHeight: 65

#######################################################################
# +-----------------------------------------------------------------+ #
# |                      Source block settings                      | #
# +-----------------------------------------------------------------+ #
#######################################################################

SourceBlocks: AIR
MaxPercentageOutsideSourceBlock: 100
OutsideSourceBlock: placeAnyway

#######################################################################
# +-----------------------------------------------------------------+ #
# |                               OTG+                              | #
# +-----------------------------------------------------------------+ #
#######################################################################

RemoveAir: true
ReplaceBelow: OBSIDIAN
ReplaceWithBiomeBlocks: false
ReplaceWithGroundBlock: OBSIDIAN
ReplaceWithSurfaceBlock: OBSIDIAN
ReplaceWithStoneBlock: OBSIDIAN
SmoothRadius: 30
SmoothingSurfaceBlock: OBSIDIAN
SmoothingGroundBlock: OBSIDIAN

#######################################################################
# +-----------------------------------------------------------------+ #
# |                              Blocks                             | #
# +-----------------------------------------------------------------+ #
#######################################################################

RB(0,0,0,minecraft:crying_obsidian,20,minecraft:obsidian,100)
RB(1,0,0,minecraft:crying_obsidian,20,minecraft:obsidian,100)
RB(2,0,0,minecraft:crying_obsidian,20,minecraft:obsidian,100)
RB(3,0,0,minecraft:crying_obsidian,20,minecraft:obsidian,100)
RB(4,0,0,minecraft:crying_obsidian,20,minecraft:obsidian,100)
B(5,0,0,minecraft:lava[level=8])
B(6,0,0,minecraft:lava[level=2])
RB(0,0,1,minecraft:crying_obsidian,20,minecraft:obsidian,100)
RB(1,0,1,minecraft:crying_obsidian,20,minecraft:obsidian,100)
RB(2,0,1,minecraft:crying_obsidian,20,minecraft:obsidian,100)
RB(3,0,1,minecraft:crying_obsidian,20,minecraft:obsidian,100)
RB(4,0,1,minecraft:crying_obsidian,20,minecraft:obsidian,100)
RB(5,0,1,minecraft:crying_obsidian,20,minecraft:obsidian,100)
B(6,0,1,minecraft:lava[level=8])
B(7,0,1,minecraft:lava[level=2])
RB(0,0,2,minecraft:crying_obsidian,20,minecraft:obsidian,100)
RB(1,0,2,minecraft:crying_obsidian,20,minecraft:obsidian,100)
RB(2,0,2,minecraft:crying_obsidian,20,minecraft:obsidian,100)
RB(3,0,2,minecraft:crying_obsidian,20,minecraft:obsidian,100)
RB(4,0,2,minecraft:crying_obsidian,20,minecraft:obsidian,100)
RB(5,0,2,minecraft:crying_obsidian,20,minecraft:obsidian,100)
RB(6,0,2,minecraft:crying_obsidian,20,minecraft:obsidian,100)
B(7,0,2,minecraft:lava[level=8])
B(8,0,2,minecraft:lava[level=2])
RB(0,0,3,minecraft:crying_obsidian,20,minecraft:obsidian,100)
RB(1,0,3,minecraft:crying_obsidian,20,minecraft:obsidian,100)
RB(2,0,3,minecraft:crying_obsidian,20,minecraft:obsidian,100)
RB(3,0,3,minecraft:crying_obsidian,20,minecraft:obsidian,100)
RB(4,0,3,minecraft:crying_obsidian,20,minecraft:obsidian,100)
RB(5,0,3,minecraft:crying_obsidian,20,minecraft:obsidian,100)
RB(6,0,3,minecraft:crying_obsidian,20,minecraft:obsidian,100)
RB(7,0,3,minecraft:crying_obsidian,20,minecraft:obsidian,100)
B(8,0,3,minecraft:lava[level=8])
RB(0,0,4,minecraft:crying_obsidian,20,minecraft:obsidian,100)
RB(1,0,4,minecraft:crying_obsidian,20,minecraft:obsidian,100)
RB(2,0,4,minecraft:crying_obsidian,20,minecraft:obsidian,100)
RB(3,0,4,minecraft:crying_obsidian,20,minecraft:obsidian,100)
RB(4,0,4,minecraft:crying_obsidian,20,minecraft:obsidian,100)
RB(5,0,4,minecraft:crying_obsidian,20,minecraft:obsidian,100)
RB(6,0,4,minecraft:crying_obsidian,20,minecraft:obsidian,100)
RB(7,0,4,minecraft:crying_obsidian,20,minecraft:obsidian,100)
B(8,0,4,minecraft:lava[level=8])
B(9,0,4,minecraft:lava[level=2])
RB(0,0,5,minecraft:crying_obsidian,20,minecraft:obsidian,100)
RB(1,0,5,minecraft:crying_obsidian,20,minecraft:obsidian,100)
RB(2,0,5,minecraft:crying_obsidian,20,minecraft:obsidian,100)
RB(3,0,5,minecraft:crying_obsidian,20,minecraft:obsidian,100)
RB(4,0,5,minecraft:crying_obsidian,20,minecraft:obsidian,100)
RB(5,0,5,minecraft:crying_obsidian,20,minecraft:obsidian,100)
RB(6,0,5,minecraft:crying_obsidian,20,minecraft:obsidian,100)
RB(7,0,5,minecraft:crying_obsidian,20,minecraft:obsidian,100)
B(8,0,5,minecraft:lava[level=8])
B(9,0,5,minecraft:lava[level=2])
RB(0,0,6,minecraft:crying_obsidian,20,minecraft:obsidian,100)
RB(1,0,6,minecraft:crying_obsidian,20,minecraft:obsidian,100)
RB(2,0,6,minecraft:crying_obsidian,20,minecraft:obsidian,100)
RB(3,0,6,minecraft:crying_obsidian,20,minecraft:obsidian,100)
RB(4,0,6,minecraft:crying_obsidian,20,minecraft:obsidian,100)
RB(5,0,6,minecraft:crying_obsidian,20,minecraft:obsidian,100)
RB(6,0,6,minecraft:crying_obsidian,20,minecraft:obsidian,100)
RB(7,0,6,minecraft:crying_obsidian,20,minecraft:obsidian,100)
B(8,0,6,minecraft:lava[level=8])
B(9,0,6,minecraft:lava[level=2])
RB(0,0,7,minecraft:crying_obsidian,20,minecraft:obsidian,100)
RB(1,0,7,minecraft:crying_obsidian,20,minecraft:obsidian,100)
RB(2,0,7,minecraft:crying_obsidian,20,minecraft:obsidian,100)
RB(3,0,7,minecraft:crying_obsidian,20,minecraft:obsidian,100)
RB(4,0,7,minecraft:crying_obsidian,20,minecraft:obsidian,100)
RB(5,0,7,minecraft:crying_obsidian,20,minecraft:obsidian,100)
RB(6,0,7,minecraft:crying_obsidian,20,minecraft:obsidian,100)
RB(7,0,7,minecraft:crying_obsidian,20,minecraft:obsidian,100)
B(8,0,7,minecraft:lava[level=2])
RB(0,0,8,minecraft:crying_obsidian,20,minecraft:obsidian,100)
RB(1,0,8,minecraft:crying_obsidian,20,minecraft:obsidian,100)
RB(2,0,8,minecraft:crying_obsidian,20,minecraft:obsidian,100)
RB(3,0,8,minecraft:crying_obsidian,20,minecraft:obsidian,100)
RB(4,0,8,minecraft:crying_obsidian,20,minecraft:obsidian,100)
RB(5,0,8,minecraft:crying_obsidian,20,minecraft:obsidian,100)
RB(6,0,8,minecraft:crying_obsidian,20,minecraft:obsidian,100)
RB(7,0,8,minecraft:crying_obsidian,20,minecraft:obsidian,100)
RB(0,0,9,minecraft:crying_obsidian,20,minecraft:obsidian,100)
RB(1,0,9,minecraft:crying_obsidian,20,minecraft:obsidian,100)
RB(2,0,9,minecraft:crying_obsidian,20,minecraft:obsidian,100)
RB(3,0,9,minecraft:crying_obsidian,20,minecraft:obsidian,100)
RB(4,0,9,minecraft:crying_obsidian,20,minecraft:obsidian,100)
RB(5,0,9,minecraft:crying_obsidian,20,minecraft:obsidian,100)
RB(6,0,9,minecraft:crying_obsidian,20,minecraft:obsidian,100)
RB(7,0,9,minecraft:crying_obsidian,20,minecraft:obsidian,100)
RB(0,0,10,minecraft:crying_obsidian,20,minecraft:obsidian,100)
RB(1,0,10,minecraft:crying_obsidian,20,minecraft:obsidian,100)
RB(2,0,10,minecraft:crying_obsidian,20,minecraft:obsidian,100)
RB(3,0,10,minecraft:crying_obsidian,20,minecraft:obsidian,100)
RB(4,0,10,minecraft:crying_obsidian,20,minecraft:obsidian,100)
RB(5,0,10,minecraft:crying_obsidian,20,minecraft:obsidian,100)
RB(6,0,10,minecraft:crying_obsidian,20,minecraft:obsidian,100)
RB(7,0,10,minecraft:crying_obsidian,20,minecraft:obsidian,100)
RB(8,0,10,minecraft:crying_obsidian,20,minecraft:obsidian,100)
RB(0,0,11,minecraft:crying_obsidian,20,minecraft:obsidian,100)
RB(1,0,11,minecraft:crying_obsidian,20,minecraft:obsidian,100)
RB(2,0,11,minecraft:crying_obsidian,20,minecraft:obsidian,100)
RB(3,0,11,minecraft:crying_obsidian,20,minecraft:obsidian,100)
RB(4,0,11,minecraft:crying_obsidian,20,minecraft:obsidian,100)
RB(5,0,11,minecraft:crying_obsidian,20,minecraft:obsidian,100)
RB(6,0,11,minecraft:crying_obsidian,20,minecraft:obsidian,100)
RB(7,0,11,minecraft:crying_obsidian,20,minecraft:obsidian,100)
RB(8,0,11,minecraft:crying_obsidian,20,minecraft:obsidian,100)
RB(0,0,12,minecraft:crying_obsidian,20,minecraft:obsidian,100)
RB(1,0,12,minecraft:crying_obsidian,20,minecraft:obsidian,100)
RB(2,0,12,minecraft:crying_obsidian,20,minecraft:obsidian,100)
RB(3,0,12,minecraft:crying_obsidian,20,minecraft:obsidian,100)
RB(4,0,12,minecraft:crying_obsidian,20,minecraft:obsidian,100)
RB(5,0,12,minecraft:crying_obsidian,20,minecraft:obsidian,100)
RB(6,0,12,minecraft:crying_obsidian,20,minecraft:obsidian,100)
RB(7,0,12,minecraft:crying_obsidian,20,minecraft:obsidian,100)
RB(8,0,12,minecraft:crying_obsidian,20,minecraft:obsidian,100)
RB(0,0,13,minecraft:crying_obsidian,20,minecraft:obsidian,100)
RB(1,0,13,minecraft:crying_obsidian,20,minecraft:obsidian,100)
RB(2,0,13,minecraft:crying_obsidian,20,minecraft:obsidian,100)
RB(3,0,13,minecraft:crying_obsidian,20,minecraft:obsidian,100)
RB(4,0,13,minecraft:crying_obsidian,20,minecraft:obsidian,100)
RB(5,0,13,minecraft:crying_obsidian,20,minecraft:obsidian,100)
RB(6,0,13,minecraft:crying_obsidian,20,minecraft:obsidian,100)
RB(7,0,13,minecraft:crying_obsidian,20,minecraft:obsidian,100)
RB(8,0,13,minecraft:crying_obsidian,20,minecraft:obsidian,100)
RB(0,0,14,minecraft:crying_obsidian,20,minecraft:obsidian,100)
RB(1,0,14,minecraft:crying_obsidian,20,minecraft:obsidian,100)
RB(2,0,14,minecraft:crying_obsidian,20,minecraft:obsidian,100)
RB(3,0,14,minecraft:crying_obsidian,20,minecraft:obsidian,100)
RB(4,0,14,minecraft:crying_obsidian,20,minecraft:obsidian,100)
RB(5,0,14,minecraft:crying_obsidian,20,minecraft:obsidian,100)
RB(6,0,14,minecraft:crying_obsidian,20,minecraft:obsidian,100)
RB(7,0,14,minecraft:crying_obsidian,20,minecraft:obsidian,100)
RB(0,0,15,minecraft:crying_obsidian,20,minecraft:obsidian,100)
RB(1,0,15,minecraft:crying_obsidian,20,minecraft:obsidian,100)
RB(2,0,15,minecraft:crying_obsidian,20,minecraft:obsidian,100)
RB(3,0,15,minecraft:crying_obsidian,20,minecraft:obsidian,100)
RB(4,0,15,minecraft:crying_obsidian,20,minecraft:obsidian,100)
RB(5,0,15,minecraft:crying_obsidian,20,minecraft:obsidian,100)
RB(6,0,15,minecraft:crying_obsidian,20,minecraft:obsidian,100)
RB(0,1,0,minecraft:crying_obsidian,20,minecraft:obsidian,100)
RB(1,1,0,minecraft:crying_obsidian,20,minecraft:obsidian,100)
RB(2,1,0,minecraft:crying_obsidian,20,minecraft:obsidian,100)
RB(3,1,0,minecraft:crying_obsidian,20,minecraft:obsidian,100)
RB(4,1,0,minecraft:crying_obsidian,20,minecraft:obsidian,100)
B(5,1,0,minecraft:lava[level=2])
RB(0,1,1,minecraft:crying_obsidian,20,minecraft:obsidian,100)
RB(1,1,1,minecraft:crying_obsidian,20,minecraft:obsidian,100)
RB(2,1,1,minecraft:crying_obsidian,20,minecraft:obsidian,100)
RB(3,1,1,minecraft:crying_obsidian,20,minecraft:obsidian,100)
RB(4,1,1,minecraft:crying_obsidian,20,minecraft:obsidian,100)
B(5,1,1,minecraft:lava[level=8])
B(6,1,1,minecraft:lava[level=2])
RB(0,1,2,minecraft:crying_obsidian,20,minecraft:obsidian,100)
RB(1,1,2,minecraft:crying_obsidian,20,minecraft:obsidian,100)
RB(2,1,2,minecraft:crying_obsidian,20,minecraft:obsidian,100)
RB(3,1,2,minecraft:crying_obsidian,20,minecraft:obsidian,100)
RB(4,1,2,minecraft:crying_obsidian,20,minecraft:obsidian,100)
RB(5,1,2,minecraft:crying_obsidian,20,minecraft:obsidian,100)
B(6,1,2,minecraft:lava[level=8])
B(7,1,2,minecraft:lava[level=2])
RB(0,1,3,minecraft:crying_obsidian,20,minecraft:obsidian,100)
RB(1,1,3,minecraft:crying_obsidian,20,minecraft:obsidian,100)
RB(2,1,3,minecraft:crying_obsidian,20,minecraft:obsidian,100)
RB(3,1,3,minecraft:crying_obsidian,20,minecraft:obsidian,100)
RB(4,1,3,minecraft:crying_obsidian,20,minecraft:obsidian,100)
RB(5,1,3,minecraft:crying_obsidian,20,minecraft:obsidian,100)
RB(6,1,3,minecraft:crying_obsidian,20,minecraft:obsidian,100)
B(7,1,3,minecraft:lava[level=8])
B(8,1,3,minecraft:lava[level=2])
RB(0,1,4,minecraft:crying_obsidian,20,minecraft:obsidian,100)
RB(1,1,4,minecraft:crying_obsidian,20,minecraft:obsidian,100)
RB(2,1,4,minecraft:crying_obsidian,20,minecraft:obsidian,100)
RB(3,1,4,minecraft:crying_obsidian,20,minecraft:obsidian,100)
RB(4,1,4,minecraft:crying_obsidian,20,minecraft:obsidian,100)
RB(5,1,4,minecraft:crying_obsidian,20,minecraft:obsidian,100)
RB(6,1,4,minecraft:crying_obsidian,20,minecraft:obsidian,100)
B(7,1,4,minecraft:lava[level=8])
B(8,1,4,minecraft:lava[level=2])
RB(0,1,5,minecraft:crying_obsidian,20,minecraft:obsidian,100)
RB(1,1,5,minecraft:crying_obsidian,20,minecraft:obsidian,100)
RB(2,1,5,minecraft:crying_obsidian,20,minecraft:obsidian,100)
RB(3,1,5,minecraft:crying_obsidian,20,minecraft:obsidian,100)
RB(4,1,5,minecraft:crying_obsidian,20,minecraft:obsidian,100)
RB(5,1,5,minecraft:crying_obsidian,20,minecraft:obsidian,100)
RB(6,1,5,minecraft:crying_obsidian,20,minecraft:obsidian,100)
B(7,1,5,minecraft:lava[level=8])
B(8,1,5,minecraft:lava[level=2])
RB(0,1,6,minecraft:crying_obsidian,20,minecraft:obsidian,100)
RB(1,1,6,minecraft:crying_obsidian,20,minecraft:obsidian,100)
RB(2,1,6,minecraft:crying_obsidian,20,minecraft:obsidian,100)
RB(3,1,6,minecraft:crying_obsidian,20,minecraft:obsidian,100)
RB(4,1,6,minecraft:crying_obsidian,20,minecraft:obsidian,100)
RB(5,1,6,minecraft:crying_obsidian,20,minecraft:obsidian,100)
RB(6,1,6,minecraft:crying_obsidian,20,minecraft:obsidian,100)
B(7,1,6,minecraft:lava[level=8])
B(8,1,6,minecraft:lava[level=2])
RB(0,1,7,minecraft:crying_obsidian,20,minecraft:obsidian,100)
RB(1,1,7,minecraft:crying_obsidian,20,minecraft:obsidian,100)
RB(2,1,7,minecraft:crying_obsidian,20,minecraft:obsidian,100)
RB(3,1,7,minecraft:crying_obsidian,20,minecraft:obsidian,100)
RB(4,1,7,minecraft:crying_obsidian,20,minecraft:obsidian,100)
RB(5,1,7,minecraft:crying_obsidian,20,minecraft:obsidian,100)
RB(6,1,7,minecraft:crying_obsidian,20,minecraft:obsidian,100)
RB(0,1,8,minecraft:crying_obsidian,20,minecraft:obsidian,100)
RB(1,1,8,minecraft:crying_obsidian,20,minecraft:obsidian,100)
RB(2,1,8,minecraft:crying_obsidian,20,minecraft:obsidian,100)
RB(3,1,8,minecraft:crying_obsidian,20,minecraft:obsidian,100)
RB(4,1,8,minecraft:crying_obsidian,20,minecraft:obsidian,100)
RB(5,1,8,minecraft:crying_obsidian,20,minecraft:obsidian,100)
RB(6,1,8,minecraft:crying_obsidian,20,minecraft:obsidian,100)
RB(7,1,8,minecraft:crying_obsidian,20,minecraft:obsidian,100)
RB(0,1,9,minecraft:crying_obsidian,20,minecraft:obsidian,100)
RB(1,1,9,minecraft:crying_obsidian,20,minecraft:obsidian,100)
RB(2,1,9,minecraft:crying_obsidian,20,minecraft:obsidian,100)
RB(3,1,9,minecraft:crying_obsidian,20,minecraft:obsidian,100)
RB(4,1,9,minecraft:crying_obsidian,20,minecraft:obsidian,100)
RB(5,1,9,minecraft:crying_obsidian,20,minecraft:obsidian,100)
RB(6,1,9,minecraft:crying_obsidian,20,minecraft:obsidian,100)
RB(7,1,9,minecraft:crying_obsidian,20,minecraft:obsidian,100)
RB(0,1,10,minecraft:crying_obsidian,20,minecraft:obsidian,100)
RB(1,1,10,minecraft:crying_obsidian,20,minecraft:obsidian,100)
RB(2,1,10,minecraft:crying_obsidian,20,minecraft:obsidian,100)
RB(3,1,10,minecraft:crying_obsidian,20,minecraft:obsidian,100)
RB(4,1,10,minecraft:crying_obsidian,20,minecraft:obsidian,100)
RB(5,1,10,minecraft:crying_obsidian,20,minecraft:obsidian,100)
RB(6,1,10,minecraft:crying_obsidian,20,minecraft:obsidian,100)
RB(7,1,10,minecraft:crying_obsidian,20,minecraft:obsidian,100)
RB(8,1,10,minecraft:crying_obsidian,20,minecraft:obsidian,100)
RB(0,1,11,minecraft:crying_obsidian,20,minecraft:obsidian,100)
RB(1,1,11,minecraft:crying_obsidian,20,minecraft:obsidian,100)
RB(2,1,11,minecraft:crying_obsidian,20,minecraft:obsidian,100)
RB(3,1,11,minecraft:crying_obsidian,20,minecraft:obsidian,100)
RB(4,1,11,minecraft:crying_obsidian,20,minecraft:obsidian,100)
RB(5,1,11,minecraft:crying_obsidian,20,minecraft:obsidian,100)
RB(6,1,11,minecraft:crying_obsidian,20,minecraft:obsidian,100)
RB(7,1,11,minecraft:crying_obsidian,20,minecraft:obsidian,100)
RB(8,1,11,minecraft:crying_obsidian,20,minecraft:obsidian,100)
RB(0,1,12,minecraft:crying_obsidian,20,minecraft:obsidian,100)
RB(1,1,12,minecraft:crying_obsidian,20,minecraft:obsidian,100)
RB(2,1,12,minecraft:crying_obsidian,20,minecraft:obsidian,100)
RB(3,1,12,minecraft:crying_obsidian,20,minecraft:obsidian,100)
RB(4,1,12,minecraft:crying_obsidian,20,minecraft:obsidian,100)
RB(5,1,12,minecraft:crying_obsidian,20,minecraft:obsidian,100)
RB(6,1,12,minecraft:crying_obsidian,20,minecraft:obsidian,100)
RB(7,1,12,minecraft:crying_obsidian,20,minecraft:obsidian,100)
RB(8,1,12,minecraft:crying_obsidian,20,minecraft:obsidian,100)
RB(0,1,13,minecraft:crying_obsidian,20,minecraft:obsidian,100)
RB(1,1,13,minecraft:crying_obsidian,20,minecraft:obsidian,100)
RB(2,1,13,minecraft:crying_obsidian,20,minecraft:obsidian,100)
RB(3,1,13,minecraft:crying_obsidian,20,minecraft:obsidian,100)
RB(4,1,13,minecraft:crying_obsidian,20,minecraft:obsidian,100)
RB(5,1,13,minecraft:crying_obsidian,20,minecraft:obsidian,100)
RB(6,1,13,minecraft:crying_obsidian,20,minecraft:obsidian,100)
RB(7,1,13,minecraft:crying_obsidian,20,minecraft:obsidian,100)
RB(0,1,14,minecraft:crying_obsidian,20,minecraft:obsidian,100)
RB(1,1,14,minecraft:crying_obsidian,20,minecraft:obsidian,100)
RB(2,1,14,minecraft:crying_obsidian,20,minecraft:obsidian,100)
RB(3,1,14,minecraft:crying_obsidian,20,minecraft:obsidian,100)
RB(4,1,14,minecraft:crying_obsidian,20,minecraft:obsidian,100)
RB(5,1,14,minecraft:crying_obsidian,20,minecraft:obsidian,100)
RB(6,1,14,minecraft:crying_obsidian,20,minecraft:obsidian,100)
RB(7,1,14,minecraft:crying_obsidian,20,minecraft:obsidian,100)
RB(0,1,15,minecraft:crying_obsidian,20,minecraft:obsidian,100)
RB(1,1,15,minecraft:crying_obsidian,20,minecraft:obsidian,100)
RB(2,1,15,minecraft:crying_obsidian,20,minecraft:obsidian,100)
RB(3,1,15,minecraft:crying_obsidian,20,minecraft:obsidian,100)
RB(4,1,15,minecraft:crying_obsidian,20,minecraft:obsidian,100)
RB(5,1,15,minecraft:crying_obsidian,20,minecraft:obsidian,100)
RB(6,1,15,minecraft:crying_obsidian,20,minecraft:obsidian,100)
RB(0,2,0,minecraft:crying_obsidian,20,minecraft:obsidian,100)
RB(1,2,0,minecraft:crying_obsidian,20,minecraft:obsidian,100)
RB(2,2,0,minecraft:crying_obsidian,20,minecraft:obsidian,100)
RB(3,2,0,minecraft:crying_obsidian,20,minecraft:obsidian,100)
RB(4,2,0,minecraft:crying_obsidian,20,minecraft:obsidian,100)
RB(0,2,1,minecraft:crying_obsidian,20,minecraft:obsidian,100)
RB(1,2,1,minecraft:crying_obsidian,20,minecraft:obsidian,100)
RB(2,2,1,minecraft:crying_obsidian,20,minecraft:obsidian,100)
RB(3,2,1,minecraft:crying_obsidian,20,minecraft:obsidian,100)
RB(4,2,1,minecraft:crying_obsidian,20,minecraft:obsidian,100)
B(5,2,1,minecraft:lava[level=4])
RB(0,2,2,minecraft:crying_obsidian,20,minecraft:obsidian,100)
RB(1,2,2,minecraft:crying_obsidian,20,minecraft:obsidian,100)
RB(2,2,2,minecraft:crying_obsidian,20,minecraft:obsidian,100)
RB(3,2,2,minecraft:crying_obsidian,20,minecraft:obsidian,100)
RB(4,2,2,minecraft:crying_obsidian,20,minecraft:obsidian,100)
B(5,2,2,minecraft:lava[level=2])
B(6,2,2,minecraft:lava[level=4])
RB(0,2,3,minecraft:crying_obsidian,20,minecraft:obsidian,100)
RB(1,2,3,minecraft:crying_obsidian,20,minecraft:obsidian,100)
RB(2,2,3,minecraft:crying_obsidian,20,minecraft:obsidian,100)
RB(3,2,3,minecraft:crying_obsidian,20,minecraft:obsidian,100)
RB(4,2,3,minecraft:crying_obsidian,20,minecraft:obsidian,100)
B(5,2,3,minecraft:lava[level=8])
B(6,2,3,minecraft:lava[level=2])
B(7,2,3,minecraft:lava[level=4])
RB(0,2,4,minecraft:crying_obsidian,20,minecraft:obsidian,100)
RB(1,2,4,minecraft:crying_obsidian,20,minecraft:obsidian,100)
RB(2,2,4,minecraft:crying_obsidian,20,minecraft:obsidian,100)
RB(3,2,4,minecraft:crying_obsidian,20,minecraft:obsidian,100)
RB(4,2,4,minecraft:crying_obsidian,20,minecraft:obsidian,100)
RB(5,2,4,minecraft:crying_obsidian,20,minecraft:obsidian,100)
B(6,2,4,minecraft:lava[level=8])
B(7,2,4,minecraft:lava[level=2])
RB(0,2,5,minecraft:crying_obsidian,20,minecraft:obsidian,100)
RB(1,2,5,minecraft:crying_obsidian,20,minecraft:obsidian,100)
RB(2,2,5,minecraft:crying_obsidian,20,minecraft:obsidian,100)
RB(3,2,5,minecraft:crying_obsidian,20,minecraft:obsidian,100)
RB(4,2,5,minecraft:crying_obsidian,20,minecraft:obsidian,100)
RB(5,2,5,minecraft:crying_obsidian,20,minecraft:obsidian,100)
B(6,2,5,minecraft:lava[level=8])
B(7,2,5,minecraft:lava[level=2])
RB(0,2,6,minecraft:crying_obsidian,20,minecraft:obsidian,100)
RB(1,2,6,minecraft:crying_obsidian,20,minecraft:obsidian,100)
RB(2,2,6,minecraft:crying_obsidian,20,minecraft:obsidian,100)
RB(3,2,6,minecraft:crying_obsidian,20,minecraft:obsidian,100)
RB(4,2,6,minecraft:crying_obsidian,20,minecraft:obsidian,100)
RB(5,2,6,minecraft:crying_obsidian,20,minecraft:obsidian,100)
B(6,2,6,minecraft:lava[level=8])
B(7,2,6,minecraft:lava[level=2])
RB(0,2,7,minecraft:crying_obsidian,20,minecraft:obsidian,100)
RB(1,2,7,minecraft:crying_obsidian,20,minecraft:obsidian,100)
RB(2,2,7,minecraft:crying_obsidian,20,minecraft:obsidian,100)
RB(3,2,7,minecraft:crying_obsidian,20,minecraft:obsidian,100)
RB(4,2,7,minecraft:crying_obsidian,20,minecraft:obsidian,100)
RB(5,2,7,minecraft:crying_obsidian,20,minecraft:obsidian,100)
RB(6,2,7,minecraft:crying_obsidian,20,minecraft:obsidian,100)
RB(0,2,8,minecraft:crying_obsidian,20,minecraft:obsidian,100)
RB(1,2,8,minecraft:crying_obsidian,20,minecraft:obsidian,100)
RB(2,2,8,minecraft:crying_obsidian,20,minecraft:obsidian,100)
RB(3,2,8,minecraft:crying_obsidian,20,minecraft:obsidian,100)
RB(4,2,8,minecraft:crying_obsidian,20,minecraft:obsidian,100)
RB(5,2,8,minecraft:crying_obsidian,20,minecraft:obsidian,100)
RB(6,2,8,minecraft:crying_obsidian,20,minecraft:obsidian,100)
RB(7,2,8,minecraft:crying_obsidian,20,minecraft:obsidian,100)
RB(0,2,9,minecraft:crying_obsidian,20,minecraft:obsidian,100)
RB(1,2,9,minecraft:crying_obsidian,20,minecraft:obsidian,100)
RB(2,2,9,minecraft:crying_obsidian,20,minecraft:obsidian,100)
RB(3,2,9,minecraft:crying_obsidian,20,minecraft:obsidian,100)
RB(4,2,9,minecraft:crying_obsidian,20,minecraft:obsidian,100)
RB(5,2,9,minecraft:crying_obsidian,20,minecraft:obsidian,100)
RB(6,2,9,minecraft:crying_obsidian,20,minecraft:obsidian,100)
RB(7,2,9,minecraft:crying_obsidian,20,minecraft:obsidian,100)
RB(0,2,10,minecraft:crying_obsidian,20,minecraft:obsidian,100)
RB(1,2,10,minecraft:crying_obsidian,20,minecraft:obsidian,100)
RB(2,2,10,minecraft:crying_obsidian,20,minecraft:obsidian,100)
RB(3,2,10,minecraft:crying_obsidian,20,minecraft:obsidian,100)
RB(4,2,10,minecraft:crying_obsidian,20,minecraft:obsidian,100)
RB(5,2,10,minecraft:crying_obsidian,20,minecraft:obsidian,100)
RB(6,2,10,minecraft:crying_obsidian,20,minecraft:obsidian,100)
RB(7,2,10,minecraft:crying_obsidian,20,minecraft:obsidian,100)
RB(8,2,10,minecraft:crying_obsidian,20,minecraft:obsidian,100)
RB(0,2,11,minecraft:crying_obsidian,20,minecraft:obsidian,100)
RB(1,2,11,minecraft:crying_obsidian,20,minecraft:obsidian,100)
RB(2,2,11,minecraft:crying_obsidian,20,minecraft:obsidian,100)
RB(3,2,11,minecraft:crying_obsidian,20,minecraft:obsidian,100)
RB(4,2,11,minecraft:crying_obsidian,20,minecraft:obsidian,100)
RB(5,2,11,minecraft:crying_obsidian,20,minecraft:obsidian,100)
RB(6,2,11,minecraft:crying_obsidian,20,minecraft:obsidian,100)
RB(7,2,11,minecraft:crying_obsidian,20,minecraft:obsidian,100)
RB(8,2,11,minecraft:crying_obsidian,20,minecraft:obsidian,100)
RB(0,2,12,minecraft:crying_obsidian,20,minecraft:obsidian,100)
RB(1,2,12,minecraft:crying_obsidian,20,minecraft:obsidian,100)
RB(2,2,12,minecraft:crying_obsidian,20,minecraft:obsidian,100)
RB(3,2,12,minecraft:crying_obsidian,20,minecraft:obsidian,100)
RB(4,2,12,minecraft:crying_obsidian,20,minecraft:obsidian,100)
RB(5,2,12,minecraft:crying_obsidian,20,minecraft:obsidian,100)
RB(6,2,12,minecraft:crying_obsidian,20,minecraft:obsidian,100)
RB(7,2,12,minecraft:crying_obsidian,20,minecraft:obsidian,100)
RB(8,2,12,minecraft:crying_obsidian,20,minecraft:obsidian,100)
RB(0,2,13,minecraft:crying_obsidian,20,minecraft:obsidian,100)
RB(1,2,13,minecraft:crying_obsidian,20,minecraft:obsidian,100)
RB(2,2,13,minecraft:crying_obsidian,20,minecraft:obsidian,100)
RB(3,2,13,minecraft:crying_obsidian,20,minecraft:obsidian,100)
RB(4,2,13,minecraft:crying_obsidian,20,minecraft:obsidian,100)
RB(5,2,13,minecraft:crying_obsidian,20,minecraft:obsidian,100)
RB(6,2,13,minecraft:crying_obsidian,20,minecraft:obsidian,100)
RB(7,2,13,minecraft:crying_obsidian,20,minecraft:obsidian,100)
RB(0,2,14,minecraft:crying_obsidian,20,minecraft:obsidian,100)
RB(1,2,14,minecraft:crying_obsidian,20,minecraft:obsidian,100)
RB(2,2,14,minecraft:crying_obsidian,20,minecraft:obsidian,100)
RB(3,2,14,minecraft:crying_obsidian,20,minecraft:obsidian,100)
RB(4,2,14,minecraft:crying_obsidian,20,minecraft:obsidian,100)
RB(5,2,14,minecraft:crying_obsidian,20,minecraft:obsidian,100)
RB(6,2,14,minecraft:crying_obsidian,20,minecraft:obsidian,100)
RB(7,2,14,minecraft:crying_obsidian,20,minecraft:obsidian,100)
RB(0,2,15,minecraft:crying_obsidian,20,minecraft:obsidian,100)
RB(1,2,15,minecraft:crying_obsidian,20,minecraft:obsidian,100)
RB(2,2,15,minecraft:crying_obsidian,20,minecraft:obsidian,100)
RB(3,2,15,minecraft:crying_obsidian,20,minecraft:obsidian,100)
RB(4,2,15,minecraft:crying_obsidian,20,minecraft:obsidian,100)
RB(5,2,15,minecraft:crying_obsidian,20,minecraft:obsidian,100)
RB(6,2,15,minecraft:crying_obsidian,20,minecraft:obsidian,100)
RB(0,3,0,minecraft:crying_obsidian,20,minecraft:obsidian,100)
RB(1,3,0,minecraft:crying_obsidian,20,minecraft:obsidian,100)
RB(2,3,0,minecraft:crying_obsidian,20,minecraft:obsidian,100)
RB(3,3,0,minecraft:crying_obsidian,20,minecraft:obsidian,100)
RB(4,3,0,minecraft:crying_obsidian,20,minecraft:obsidian,100)
RB(0,3,1,minecraft:crying_obsidian,20,minecraft:obsidian,100)
RB(1,3,1,minecraft:crying_obsidian,20,minecraft:obsidian,100)
RB(2,3,1,minecraft:crying_obsidian,20,minecraft:obsidian,100)
RB(3,3,1,minecraft:crying_obsidian,20,minecraft:obsidian,100)
RB(4,3,1,minecraft:crying_obsidian,20,minecraft:obsidian,100)
RB(0,3,2,minecraft:crying_obsidian,20,minecraft:obsidian,100)
RB(1,3,2,minecraft:crying_obsidian,20,minecraft:obsidian,100)
RB(2,3,2,minecraft:crying_obsidian,20,minecraft:obsidian,100)
RB(3,3,2,minecraft:crying_obsidian,20,minecraft:obsidian,100)
RB(4,3,2,minecraft:crying_obsidian,20,minecraft:obsidian,100)
RB(0,3,3,minecraft:crying_obsidian,20,minecraft:obsidian,100)
RB(1,3,3,minecraft:crying_obsidian,20,minecraft:obsidian,100)
RB(2,3,3,minecraft:crying_obsidian,20,minecraft:obsidian,100)
RB(3,3,3,minecraft:crying_obsidian,20,minecraft:obsidian,100)
RB(4,3,3,minecraft:crying_obsidian,20,minecraft:obsidian,100)
B(5,3,3,minecraft:lava[level=4])
RB(0,3,4,minecraft:crying_obsidian,20,minecraft:obsidian,100)
RB(1,3,4,minecraft:crying_obsidian,20,minecraft:obsidian,100)
RB(2,3,4,minecraft:crying_obsidian,20,minecraft:obsidian,100)
RB(3,3,4,minecraft:crying_obsidian,20,minecraft:obsidian,100)
B(4,3,4,minecraft:lava[level=8])
B(5,3,4,minecraft:lava[level=2])
B(6,3,4,minecraft:lava[level=4])
RB(0,3,5,minecraft:crying_obsidian,20,minecraft:obsidian,100)
RB(1,3,5,minecraft:crying_obsidian,20,minecraft:obsidian,100)
RB(2,3,5,minecraft:crying_obsidian,20,minecraft:obsidian,100)
RB(3,3,5,minecraft:crying_obsidian,20,minecraft:obsidian,100)
B(4,3,5,minecraft:lava[level=8])
B(5,3,5,minecraft:lava[level=8])
B(6,3,5,minecraft:lava[level=2])
RB(0,3,6,minecraft:crying_obsidian,20,minecraft:obsidian,100)
RB(1,3,6,minecraft:crying_obsidian,20,minecraft:obsidian,100)
RB(2,3,6,minecraft:crying_obsidian,20,minecraft:obsidian,100)
RB(3,3,6,minecraft:crying_obsidian,20,minecraft:obsidian,100)
RB(4,3,6,minecraft:crying_obsidian,20,minecraft:obsidian,100)
RB(5,3,6,minecraft:crying_obsidian,20,minecraft:obsidian,100)
B(6,3,6,minecraft:lava[level=4])
RB(0,3,7,minecraft:crying_obsidian,20,minecraft:obsidian,100)
RB(1,3,7,minecraft:crying_obsidian,20,minecraft:obsidian,100)
RB(2,3,7,minecraft:crying_obsidian,20,minecraft:obsidian,100)
RB(3,3,7,minecraft:crying_obsidian,20,minecraft:obsidian,100)
RB(4,3,7,minecraft:crying_obsidian,20,minecraft:obsidian,100)
RB(5,3,7,minecraft:crying_obsidian,20,minecraft:obsidian,100)
RB(6,3,7,minecraft:crying_obsidian,20,minecraft:obsidian,100)
RB(0,3,8,minecraft:crying_obsidian,20,minecraft:obsidian,100)
RB(1,3,8,minecraft:crying_obsidian,20,minecraft:obsidian,100)
RB(2,3,8,minecraft:crying_obsidian,20,minecraft:obsidian,100)
RB(3,3,8,minecraft:crying_obsidian,20,minecraft:obsidian,100)
RB(4,3,8,minecraft:crying_obsidian,20,minecraft:obsidian,100)
RB(5,3,8,minecraft:crying_obsidian,20,minecraft:obsidian,100)
RB(6,3,8,minecraft:crying_obsidian,20,minecraft:obsidian,100)
RB(7,3,8,minecraft:crying_obsidian,20,minecraft:obsidian,100)
RB(0,3,9,minecraft:crying_obsidian,20,minecraft:obsidian,100)
RB(1,3,9,minecraft:crying_obsidian,20,minecraft:obsidian,100)
RB(2,3,9,minecraft:crying_obsidian,20,minecraft:obsidian,100)
RB(3,3,9,minecraft:crying_obsidian,20,minecraft:obsidian,100)
RB(4,3,9,minecraft:crying_obsidian,20,minecraft:obsidian,100)
RB(5,3,9,minecraft:crying_obsidian,20,minecraft:obsidian,100)
RB(6,3,9,minecraft:crying_obsidian,20,minecraft:obsidian,100)
RB(7,3,9,minecraft:crying_obsidian,20,minecraft:obsidian,100)
RB(0,3,10,minecraft:crying_obsidian,20,minecraft:obsidian,100)
RB(1,3,10,minecraft:crying_obsidian,20,minecraft:obsidian,100)
RB(2,3,10,minecraft:crying_obsidian,20,minecraft:obsidian,100)
RB(3,3,10,minecraft:crying_obsidian,20,minecraft:obsidian,100)
RB(4,3,10,minecraft:crying_obsidian,20,minecraft:obsidian,100)
RB(5,3,10,minecraft:crying_obsidian,20,minecraft:obsidian,100)
RB(6,3,10,minecraft:crying_obsidian,20,minecraft:obsidian,100)
RB(7,3,10,minecraft:crying_obsidian,20,minecraft:obsidian,100)
RB(0,3,11,minecraft:crying_obsidian,20,minecraft:obsidian,100)
RB(1,3,11,minecraft:crying_obsidian,20,minecraft:obsidian,100)
RB(2,3,11,minecraft:crying_obsidian,20,minecraft:obsidian,100)
RB(3,3,11,minecraft:crying_obsidian,20,minecraft:obsidian,100)
RB(4,3,11,minecraft:crying_obsidian,20,minecraft:obsidian,100)
RB(5,3,11,minecraft:crying_obsidian,20,minecraft:obsidian,100)
RB(6,3,11,minecraft:crying_obsidian,20,minecraft:obsidian,100)
RB(7,3,11,minecraft:crying_obsidian,20,minecraft:obsidian,100)
RB(0,3,12,minecraft:crying_obsidian,20,minecraft:obsidian,100)
RB(1,3,12,minecraft:crying_obsidian,20,minecraft:obsidian,100)
RB(2,3,12,minecraft:crying_obsidian,20,minecraft:obsidian,100)
RB(3,3,12,minecraft:crying_obsidian,20,minecraft:obsidian,100)
RB(4,3,12,minecraft:crying_obsidian,20,minecraft:obsidian,100)
RB(5,3,12,minecraft:crying_obsidian,20,minecraft:obsidian,100)
RB(6,3,12,minecraft:crying_obsidian,20,minecraft:obsidian,100)
RB(7,3,12,minecraft:crying_obsidian,20,minecraft:obsidian,100)
RB(0,3,13,minecraft:crying_obsidian,20,minecraft:obsidian,100)
RB(1,3,13,minecraft:crying_obsidian,20,minecraft:obsidian,100)
RB(2,3,13,minecraft:crying_obsidian,20,minecraft:obsidian,100)
RB(3,3,13,minecraft:crying_obsidian,20,minecraft:obsidian,100)
RB(4,3,13,minecraft:crying_obsidian,20,minecraft:obsidian,100)
RB(5,3,13,minecraft:crying_obsidian,20,minecraft:obsidian,100)
RB(6,3,13,minecraft:crying_obsidian,20,minecraft:obsidian,100)
RB(7,3,13,minecraft:crying_obsidian,20,minecraft:obsidian,100)
RB(0,3,14,minecraft:crying_obsidian,20,minecraft:obsidian,100)
RB(1,3,14,minecraft:crying_obsidian,20,minecraft:obsidian,100)
RB(2,3,14,minecraft:crying_obsidian,20,minecraft:obsidian,100)
RB(3,3,14,minecraft:crying_obsidian,20,minecraft:obsidian,100)
RB(4,3,14,minecraft:crying_obsidian,20,minecraft:obsidian,100)
RB(5,3,14,minecraft:crying_obsidian,20,minecraft:obsidian,100)
RB(6,3,14,minecraft:crying_obsidian,20,minecraft:obsidian,100)
RB(7,3,14,minecraft:crying_obsidian,20,minecraft:obsidian,100)
RB(0,3,15,minecraft:crying_obsidian,20,minecraft:obsidian,100)
RB(1,3,15,minecraft:crying_obsidian,20,minecraft:obsidian,100)
RB(2,3,15,minecraft:crying_obsidian,20,minecraft:obsidian,100)
RB(3,3,15,minecraft:crying_obsidian,20,minecraft:obsidian,100)
RB(4,3,15,minecraft:crying_obsidian,20,minecraft:obsidian,100)
RB(5,3,15,minecraft:crying_obsidian,20,minecraft:obsidian,100)
RB(6,3,15,minecraft:crying_obsidian,20,minecraft:obsidian,100)
RB(0,4,0,minecraft:crying_obsidian,20,minecraft:obsidian,100)
RB(1,4,0,minecraft:crying_obsidian,20,minecraft:obsidian,100)
RB(2,4,0,minecraft:crying_obsidian,20,minecraft:obsidian,100)
RB(3,4,0,minecraft:crying_obsidian,20,minecraft:obsidian,100)
RB(4,4,0,minecraft:crying_obsidian,20,minecraft:obsidian,100)
RB(0,4,1,minecraft:crying_obsidian,20,minecraft:obsidian,100)
RB(1,4,1,minecraft:crying_obsidian,20,minecraft:obsidian,100)
RB(2,4,1,minecraft:crying_obsidian,20,minecraft:obsidian,100)
RB(3,4,1,minecraft:crying_obsidian,20,minecraft:obsidian,100)
RB(4,4,1,minecraft:crying_obsidian,20,minecraft:obsidian,100)
RB(0,4,2,minecraft:crying_obsidian,20,minecraft:obsidian,100)
RB(1,4,2,minecraft:crying_obsidian,20,minecraft:obsidian,100)
RB(2,4,2,minecraft:crying_obsidian,20,minecraft:obsidian,100)
RB(3,4,2,minecraft:crying_obsidian,20,minecraft:obsidian,100)
RB(4,4,2,minecraft:crying_obsidian,20,minecraft:obsidian,100)
RB(0,4,3,minecraft:crying_obsidian,20,minecraft:obsidian,100)
RB(1,4,3,minecraft:crying_obsidian,20,minecraft:obsidian,100)
RB(2,4,3,minecraft:crying_obsidian,20,minecraft:obsidian,100)
RB(3,4,3,minecraft:crying_obsidian,20,minecraft:obsidian,100)
RB(4,4,3,minecraft:crying_obsidian,20,minecraft:obsidian,100)
RB(0,4,4,minecraft:crying_obsidian,20,minecraft:obsidian,100)
RB(1,4,4,minecraft:crying_obsidian,20,minecraft:obsidian,100)
RB(2,4,4,minecraft:crying_obsidian,20,minecraft:obsidian,100)
RB(3,4,4,minecraft:crying_obsidian,20,minecraft:obsidian,100)
B(4,4,4,minecraft:lava[level=6])
RB(0,4,5,minecraft:crying_obsidian,20,minecraft:obsidian,100)
RB(1,4,5,minecraft:crying_obsidian,20,minecraft:obsidian,100)
RB(2,4,5,minecraft:crying_obsidian,20,minecraft:obsidian,100)
B(3,4,5,minecraft:lava[level=6])
B(5,4,5,minecraft:lava[level=6])
RB(0,4,6,minecraft:crying_obsidian,20,minecraft:obsidian,100)
RB(1,4,6,minecraft:crying_obsidian,20,minecraft:obsidian,100)
RB(2,4,6,minecraft:crying_obsidian,20,minecraft:obsidian,100)
RB(3,4,6,minecraft:crying_obsidian,20,minecraft:obsidian,100)
RB(4,4,6,minecraft:crying_obsidian,20,minecraft:obsidian,100)
RB(5,4,6,minecraft:crying_obsidian,20,minecraft:obsidian,100)
RB(0,4,7,minecraft:crying_obsidian,20,minecraft:obsidian,100)
RB(1,4,7,minecraft:crying_obsidian,20,minecraft:obsidian,100)
RB(2,4,7,minecraft:crying_obsidian,20,minecraft:obsidian,100)
RB(3,4,7,minecraft:crying_obsidian,20,minecraft:obsidian,100)
RB(4,4,7,minecraft:crying_obsidian,20,minecraft:obsidian,100)
RB(5,4,7,minecraft:crying_obsidian,20,minecraft:obsidian,100)
RB(6,4,7,minecraft:crying_obsidian,20,minecraft:obsidian,100)
RB(0,4,8,minecraft:crying_obsidian,20,minecraft:obsidian,100)
RB(1,4,8,minecraft:crying_obsidian,20,minecraft:obsidian,100)
RB(2,4,8,minecraft:crying_obsidian,20,minecraft:obsidian,100)
RB(3,4,8,minecraft:crying_obsidian,20,minecraft:obsidian,100)
RB(4,4,8,minecraft:crying_obsidian,20,minecraft:obsidian,100)
RB(5,4,8,minecraft:crying_obsidian,20,minecraft:obsidian,100)
RB(6,4,8,minecraft:crying_obsidian,20,minecraft:obsidian,100)
RB(7,4,8,minecraft:crying_obsidian,20,minecraft:obsidian,100)
RB(0,4,9,minecraft:crying_obsidian,20,minecraft:obsidian,100)
RB(1,4,9,minecraft:crying_obsidian,20,minecraft:obsidian,100)
RB(2,4,9,minecraft:crying_obsidian,20,minecraft:obsidian,100)
RB(3,4,9,minecraft:crying_obsidian,20,minecraft:obsidian,100)
RB(4,4,9,minecraft:crying_obsidian,20,minecraft:obsidian,100)
RB(5,4,9,minecraft:crying_obsidian,20,minecraft:obsidian,100)
RB(6,4,9,minecraft:crying_obsidian,20,minecraft:obsidian,100)
RB(7,4,9,minecraft:crying_obsidian,20,minecraft:obsidian,100)
RB(0,4,10,minecraft:crying_obsidian,20,minecraft:obsidian,100)
RB(1,4,10,minecraft:crying_obsidian,20,minecraft:obsidian,100)
RB(2,4,10,minecraft:crying_obsidian,20,minecraft:obsidian,100)
RB(3,4,10,minecraft:crying_obsidian,20,minecraft:obsidian,100)
RB(4,4,10,minecraft:crying_obsidian,20,minecraft:obsidian,100)
RB(5,4,10,minecraft:crying_obsidian,20,minecraft:obsidian,100)
RB(6,4,10,minecraft:crying_obsidian,20,minecraft:obsidian,100)
RB(7,4,10,minecraft:crying_obsidian,20,minecraft:obsidian,100)
RB(0,4,11,minecraft:crying_obsidian,20,minecraft:obsidian,100)
RB(1,4,11,minecraft:crying_obsidian,20,minecraft:obsidian,100)
RB(2,4,11,minecraft:crying_obsidian,20,minecraft:obsidian,100)
RB(3,4,11,minecraft:crying_obsidian,20,minecraft:obsidian,100)
RB(4,4,11,minecraft:crying_obsidian,20,minecraft:obsidian,100)
RB(5,4,11,minecraft:crying_obsidian,20,minecraft:obsidian,100)
RB(6,4,11,minecraft:crying_obsidian,20,minecraft:obsidian,100)
RB(7,4,11,minecraft:crying_obsidian,20,minecraft:obsidian,100)
RB(0,4,12,minecraft:crying_obsidian,20,minecraft:obsidian,100)
RB(1,4,12,minecraft:crying_obsidian,20,minecraft:obsidian,100)
RB(2,4,12,minecraft:crying_obsidian,20,minecraft:obsidian,100)
RB(3,4,12,minecraft:crying_obsidian,20,minecraft:obsidian,100)
RB(4,4,12,minecraft:crying_obsidian,20,minecraft:obsidian,100)
RB(5,4,12,minecraft:crying_obsidian,20,minecraft:obsidian,100)
RB(6,4,12,minecraft:crying_obsidian,20,minecraft:obsidian,100)
RB(7,4,12,minecraft:crying_obsidian,20,minecraft:obsidian,100)
RB(0,4,13,minecraft:crying_obsidian,20,minecraft:obsidian,100)
RB(1,4,13,minecraft:crying_obsidian,20,minecraft:obsidian,100)
RB(2,4,13,minecraft:crying_obsidian,20,minecraft:obsidian,100)
RB(3,4,13,minecraft:crying_obsidian,20,minecraft:obsidian,100)
RB(4,4,13,minecraft:crying_obsidian,20,minecraft:obsidian,100)
RB(5,4,13,minecraft:crying_obsidian,20,minecraft:obsidian,100)
RB(6,4,13,minecraft:crying_obsidian,20,minecraft:obsidian,100)
RB(7,4,13,minecraft:crying_obsidian,20,minecraft:obsidian,100)
RB(0,4,14,minecraft:crying_obsidian,20,minecraft:obsidian,100)
RB(1,4,14,minecraft:crying_obsidian,20,minecraft:obsidian,100)
RB(2,4,14,minecraft:crying_obsidian,20,minecraft:obsidian,100)
RB(3,4,14,minecraft:crying_obsidian,20,minecraft:obsidian,100)
RB(4,4,14,minecraft:crying_obsidian,20,minecraft:obsidian,100)
RB(5,4,14,minecraft:crying_obsidian,20,minecraft:obsidian,100)
RB(6,4,14,minecraft:crying_obsidian,20,minecraft:obsidian,100)
RB(0,4,15,minecraft:crying_obsidian,20,minecraft:obsidian,100)
RB(1,4,15,minecraft:crying_obsidian,20,minecraft:obsidian,100)
RB(2,4,15,minecraft:crying_obsidian,20,minecraft:obsidian,100)
RB(3,4,15,minecraft:crying_obsidian,20,minecraft:obsidian,100)
RB(4,4,15,minecraft:crying_obsidian,20,minecraft:obsidian,100)
RB(5,4,15,minecraft:crying_obsidian,20,minecraft:obsidian,100)
RB(0,5,0,minecraft:crying_obsidian,20,minecraft:obsidian,100)
RB(1,5,0,minecraft:crying_obsidian,20,minecraft:obsidian,100)
RB(2,5,0,minecraft:crying_obsidian,20,minecraft:obsidian,100)
RB(3,5,0,minecraft:crying_obsidian,20,minecraft:obsidian,100)
RB(4,5,0,minecraft:crying_obsidian,20,minecraft:obsidian,100)
RB(0,5,1,minecraft:crying_obsidian,20,minecraft:obsidian,100)
RB(1,5,1,minecraft:crying_obsidian,20,minecraft:obsidian,100)
RB(2,5,1,minecraft:crying_obsidian,20,minecraft:obsidian,100)
RB(3,5,1,minecraft:crying_obsidian,20,minecraft:obsidian,100)
RB(4,5,1,minecraft:crying_obsidian,20,minecraft:obsidian,100)
RB(0,5,2,minecraft:crying_obsidian,20,minecraft:obsidian,100)
RB(1,5,2,minecraft:crying_obsidian,20,minecraft:obsidian,100)
RB(2,5,2,minecraft:crying_obsidian,20,minecraft:obsidian,100)
RB(3,5,2,minecraft:crying_obsidian,20,minecraft:obsidian,100)
RB(4,5,2,minecraft:crying_obsidian,20,minecraft:obsidian,100)
RB(0,5,3,minecraft:crying_obsidian,20,minecraft:obsidian,100)
RB(1,5,3,minecraft:crying_obsidian,20,minecraft:obsidian,100)
RB(2,5,3,minecraft:crying_obsidian,20,minecraft:obsidian,100)
RB(3,5,3,minecraft:crying_obsidian,20,minecraft:obsidian,100)
RB(4,5,3,minecraft:crying_obsidian,20,minecraft:obsidian,100)
RB(0,5,4,minecraft:crying_obsidian,20,minecraft:obsidian,100)
RB(1,5,4,minecraft:crying_obsidian,20,minecraft:obsidian,100)
RB(2,5,4,minecraft:crying_obsidian,20,minecraft:obsidian,100)
RB(3,5,4,minecraft:crying_obsidian,20,minecraft:obsidian,100)
RB(0,5,5,minecraft:crying_obsidian,20,minecraft:obsidian,100)
RB(1,5,5,minecraft:crying_obsidian,20,minecraft:obsidian,100)
RB(2,5,5,minecraft:crying_obsidian,20,minecraft:obsidian,100)
RB(0,5,6,minecraft:crying_obsidian,20,minecraft:obsidian,100)
RB(1,5,6,minecraft:crying_obsidian,20,minecraft:obsidian,100)
RB(2,5,6,minecraft:crying_obsidian,20,minecraft:obsidian,100)
RB(3,5,6,minecraft:crying_obsidian,20,minecraft:obsidian,100)
RB(4,5,6,minecraft:crying_obsidian,20,minecraft:obsidian,100)
RB(5,5,6,minecraft:crying_obsidian,20,minecraft:obsidian,100)
RB(0,5,7,minecraft:crying_obsidian,20,minecraft:obsidian,100)
RB(1,5,7,minecraft:crying_obsidian,20,minecraft:obsidian,100)
RB(2,5,7,minecraft:crying_obsidian,20,minecraft:obsidian,100)
RB(3,5,7,minecraft:crying_obsidian,20,minecraft:obsidian,100)
RB(4,5,7,minecraft:crying_obsidian,20,minecraft:obsidian,100)
RB(5,5,7,minecraft:crying_obsidian,20,minecraft:obsidian,100)
RB(6,5,7,minecraft:crying_obsidian,20,minecraft:obsidian,100)
RB(0,5,8,minecraft:crying_obsidian,20,minecraft:obsidian,100)
RB(1,5,8,minecraft:crying_obsidian,20,minecraft:obsidian,100)
RB(2,5,8,minecraft:crying_obsidian,20,minecraft:obsidian,100)
RB(3,5,8,minecraft:crying_obsidian,20,minecraft:obsidian,100)
RB(4,5,8,minecraft:crying_obsidian,20,minecraft:obsidian,100)
RB(5,5,8,minecraft:crying_obsidian,20,minecraft:obsidian,100)
RB(6,5,8,minecraft:crying_obsidian,20,minecraft:obsidian,100)
RB(0,5,9,minecraft:crying_obsidian,20,minecraft:obsidian,100)
RB(1,5,9,minecraft:crying_obsidian,20,minecraft:obsidian,100)
RB(2,5,9,minecraft:crying_obsidian,20,minecraft:obsidian,100)
RB(3,5,9,minecraft:crying_obsidian,20,minecraft:obsidian,100)
RB(4,5,9,minecraft:crying_obsidian,20,minecraft:obsidian,100)
RB(5,5,9,minecraft:crying_obsidian,20,minecraft:obsidian,100)
RB(6,5,9,minecraft:crying_obsidian,20,minecraft:obsidian,100)
RB(0,5,10,minecraft:crying_obsidian,20,minecraft:obsidian,100)
RB(1,5,10,minecraft:crying_obsidian,20,minecraft:obsidian,100)
RB(2,5,10,minecraft:crying_obsidian,20,minecraft:obsidian,100)
RB(3,5,10,minecraft:crying_obsidian,20,minecraft:obsidian,100)
RB(4,5,10,minecraft:crying_obsidian,20,minecraft:obsidian,100)
RB(5,5,10,minecraft:crying_obsidian,20,minecraft:obsidian,100)
RB(6,5,10,minecraft:crying_obsidian,20,minecraft:obsidian,100)
RB(7,5,10,minecraft:crying_obsidian,20,minecraft:obsidian,100)
RB(0,5,11,minecraft:crying_obsidian,20,minecraft:obsidian,100)
RB(1,5,11,minecraft:crying_obsidian,20,minecraft:obsidian,100)
RB(2,5,11,minecraft:crying_obsidian,20,minecraft:obsidian,100)
RB(3,5,11,minecraft:crying_obsidian,20,minecraft:obsidian,100)
RB(4,5,11,minecraft:crying_obsidian,20,minecraft:obsidian,100)
RB(5,5,11,minecraft:crying_obsidian,20,minecraft:obsidian,100)
RB(6,5,11,minecraft:crying_obsidian,20,minecraft:obsidian,100)
RB(7,5,11,minecraft:crying_obsidian,20,minecraft:obsidian,100)
RB(0,5,12,minecraft:crying_obsidian,20,minecraft:obsidian,100)
RB(1,5,12,minecraft:crying_obsidian,20,minecraft:obsidian,100)
RB(2,5,12,minecraft:crying_obsidian,20,minecraft:obsidian,100)
RB(3,5,12,minecraft:crying_obsidian,20,minecraft:obsidian,100)
RB(4,5,12,minecraft:crying_obsidian,20,minecraft:obsidian,100)
RB(5,5,12,minecraft:crying_obsidian,20,minecraft:obsidian,100)
RB(6,5,12,minecraft:crying_obsidian,20,minecraft:obsidian,100)
RB(7,5,12,minecraft:crying_obsidian,20,minecraft:obsidian,100)
RB(0,5,13,minecraft:crying_obsidian,20,minecraft:obsidian,100)
RB(1,5,13,minecraft:crying_obsidian,20,minecraft:obsidian,100)
RB(2,5,13,minecraft:crying_obsidian,20,minecraft:obsidian,100)
RB(3,5,13,minecraft:crying_obsidian,20,minecraft:obsidian,100)
RB(4,5,13,minecraft:crying_obsidian,20,minecraft:obsidian,100)
RB(5,5,13,minecraft:crying_obsidian,20,minecraft:obsidian,100)
RB(6,5,13,minecraft:crying_obsidian,20,minecraft:obsidian,100)
RB(7,5,13,minecraft:crying_obsidian,20,minecraft:obsidian,100)
RB(0,5,14,minecraft:crying_obsidian,20,minecraft:obsidian,100)
RB(1,5,14,minecraft:crying_obsidian,20,minecraft:obsidian,100)
RB(2,5,14,minecraft:crying_obsidian,20,minecraft:obsidian,100)
RB(3,5,14,minecraft:crying_obsidian,20,minecraft:obsidian,100)
RB(4,5,14,minecraft:crying_obsidian,20,minecraft:obsidian,100)
RB(5,5,14,minecraft:crying_obsidian,20,minecraft:obsidian,100)
RB(6,5,14,minecraft:crying_obsidian,20,minecraft:obsidian,100)
RB(0,5,15,minecraft:crying_obsidian,20,minecraft:obsidian,100)
RB(1,5,15,minecraft:crying_obsidian,20,minecraft:obsidian,100)
RB(2,5,15,minecraft:crying_obsidian,20,minecraft:obsidian,100)
RB(3,5,15,minecraft:crying_obsidian,20,minecraft:obsidian,100)
RB(4,5,15,minecraft:crying_obsidian,20,minecraft:obsidian,100)
RB(5,5,15,minecraft:crying_obsidian,20,minecraft:obsidian,100)
RB(0,6,0,minecraft:crying_obsidian,20,minecraft:obsidian,100)
RB(1,6,0,minecraft:crying_obsidian,20,minecraft:obsidian,100)
RB(2,6,0,minecraft:crying_obsidian,20,minecraft:obsidian,100)
RB(3,6,0,minecraft:crying_obsidian,20,minecraft:obsidian,100)
RB(4,6,0,minecraft:crying_obsidian,20,minecraft:obsidian,100)
RB(0,6,1,minecraft:crying_obsidian,20,minecraft:obsidian,100)
RB(1,6,1,minecraft:crying_obsidian,20,minecraft:obsidian,100)
RB(2,6,1,minecraft:crying_obsidian,20,minecraft:obsidian,100)
RB(3,6,1,minecraft:crying_obsidian,20,minecraft:obsidian,100)
RB(0,6,2,minecraft:crying_obsidian,20,minecraft:obsidian,100)
RB(1,6,2,minecraft:crying_obsidian,20,minecraft:obsidian,100)
RB(2,6,2,minecraft:crying_obsidian,20,minecraft:obsidian,100)
RB(3,6,2,minecraft:crying_obsidian,20,minecraft:obsidian,100)
RB(4,6,2,minecraft:crying_obsidian,20,minecraft:obsidian,100)
RB(0,6,3,minecraft:crying_obsidian,20,minecraft:obsidian,100)
RB(1,6,3,minecraft:crying_obsidian,20,minecraft:obsidian,100)
RB(2,6,3,minecraft:crying_obsidian,20,minecraft:obsidian,100)
RB(3,6,3,minecraft:crying_obsidian,20,minecraft:obsidian,100)
RB(0,6,4,minecraft:crying_obsidian,20,minecraft:obsidian,100)
RB(1,6,4,minecraft:crying_obsidian,20,minecraft:obsidian,100)
RB(2,6,4,minecraft:crying_obsidian,20,minecraft:obsidian,100)
RB(3,6,4,minecraft:crying_obsidian,20,minecraft:obsidian,100)
RB(0,6,5,minecraft:crying_obsidian,20,minecraft:obsidian,100)
RB(1,6,5,minecraft:crying_obsidian,20,minecraft:obsidian,100)
RB(2,6,5,minecraft:crying_obsidian,20,minecraft:obsidian,100)
RB(0,6,6,minecraft:crying_obsidian,20,minecraft:obsidian,100)
RB(1,6,6,minecraft:crying_obsidian,20,minecraft:obsidian,100)
RB(2,6,6,minecraft:crying_obsidian,20,minecraft:obsidian,100)
RB(3,6,6,minecraft:crying_obsidian,20,minecraft:obsidian,100)
RB(4,6,6,minecraft:crying_obsidian,20,minecraft:obsidian,100)
RB(0,6,7,minecraft:crying_obsidian,20,minecraft:obsidian,100)
RB(1,6,7,minecraft:crying_obsidian,20,minecraft:obsidian,100)
RB(2,6,7,minecraft:crying_obsidian,20,minecraft:obsidian,100)
RB(3,6,7,minecraft:crying_obsidian,20,minecraft:obsidian,100)
RB(4,6,7,minecraft:crying_obsidian,20,minecraft:obsidian,100)
RB(5,6,7,minecraft:crying_obsidian,20,minecraft:obsidian,100)
RB(6,6,7,minecraft:crying_obsidian,20,minecraft:obsidian,100)
RB(0,6,8,minecraft:crying_obsidian,20,minecraft:obsidian,100)
RB(1,6,8,minecraft:crying_obsidian,20,minecraft:obsidian,100)
RB(2,6,8,minecraft:crying_obsidian,20,minecraft:obsidian,100)
RB(3,6,8,minecraft:crying_obsidian,20,minecraft:obsidian,100)
RB(4,6,8,minecraft:crying_obsidian,20,minecraft:obsidian,100)
RB(5,6,8,minecraft:crying_obsidian,20,minecraft:obsidian,100)
RB(6,6,8,minecraft:crying_obsidian,20,minecraft:obsidian,100)
RB(0,6,9,minecraft:crying_obsidian,20,minecraft:obsidian,100)
RB(1,6,9,minecraft:crying_obsidian,20,minecraft:obsidian,100)
RB(2,6,9,minecraft:crying_obsidian,20,minecraft:obsidian,100)
RB(3,6,9,minecraft:crying_obsidian,20,minecraft:obsidian,100)
RB(4,6,9,minecraft:crying_obsidian,20,minecraft:obsidian,100)
RB(5,6,9,minecraft:crying_obsidian,20,minecraft:obsidian,100)
RB(6,6,9,minecraft:crying_obsidian,20,minecraft:obsidian,100)
RB(0,6,10,minecraft:crying_obsidian,20,minecraft:obsidian,100)
RB(1,6,10,minecraft:crying_obsidian,20,minecraft:obsidian,100)
RB(2,6,10,minecraft:crying_obsidian,20,minecraft:obsidian,100)
RB(3,6,10,minecraft:crying_obsidian,20,minecraft:obsidian,100)
RB(4,6,10,minecraft:crying_obsidian,20,minecraft:obsidian,100)
RB(5,6,10,minecraft:crying_obsidian,20,minecraft:obsidian,100)
RB(6,6,10,minecraft:crying_obsidian,20,minecraft:obsidian,100)
RB(0,6,11,minecraft:crying_obsidian,20,minecraft:obsidian,100)
RB(1,6,11,minecraft:crying_obsidian,20,minecraft:obsidian,100)
RB(2,6,11,minecraft:crying_obsidian,20,minecraft:obsidian,100)
RB(3,6,11,minecraft:crying_obsidian,20,minecraft:obsidian,100)
RB(4,6,11,minecraft:crying_obsidian,20,minecraft:obsidian,100)
RB(5,6,11,minecraft:crying_obsidian,20,minecraft:obsidian,100)
RB(6,6,11,minecraft:crying_obsidian,20,minecraft:obsidian,100)
RB(0,6,12,minecraft:crying_obsidian,20,minecraft:obsidian,100)
RB(1,6,12,minecraft:crying_obsidian,20,minecraft:obsidian,100)
RB(2,6,12,minecraft:crying_obsidian,20,minecraft:obsidian,100)
RB(3,6,12,minecraft:crying_obsidian,20,minecraft:obsidian,100)
RB(4,6,12,minecraft:crying_obsidian,20,minecraft:obsidian,100)
RB(5,6,12,minecraft:crying_obsidian,20,minecraft:obsidian,100)
RB(6,6,12,minecraft:crying_obsidian,20,minecraft:obsidian,100)
RB(0,6,13,minecraft:crying_obsidian,20,minecraft:obsidian,100)
RB(1,6,13,minecraft:crying_obsidian,20,minecraft:obsidian,100)
RB(2,6,13,minecraft:crying_obsidian,20,minecraft:obsidian,100)
RB(3,6,13,minecraft:crying_obsidian,20,minecraft:obsidian,100)
RB(4,6,13,minecraft:crying_obsidian,20,minecraft:obsidian,100)
RB(5,6,13,minecraft:crying_obsidian,20,minecraft:obsidian,100)
RB(6,6,13,minecraft:crying_obsidian,20,minecraft:obsidian,100)
RB(0,6,14,minecraft:crying_obsidian,20,minecraft:obsidian,100)
RB(1,6,14,minecraft:crying_obsidian,20,minecraft:obsidian,100)
RB(2,6,14,minecraft:crying_obsidian,20,minecraft:obsidian,100)
RB(3,6,14,minecraft:crying_obsidian,20,minecraft:obsidian,100)
RB(4,6,14,minecraft:crying_obsidian,20,minecraft:obsidian,100)
RB(5,6,14,minecraft:crying_obsidian,20,minecraft:obsidian,100)
RB(0,6,15,minecraft:crying_obsidian,20,minecraft:obsidian,100)
RB(1,6,15,minecraft:crying_obsidian,20,minecraft:obsidian,100)
RB(2,6,15,minecraft:crying_obsidian,20,minecraft:obsidian,100)
RB(3,6,15,minecraft:crying_obsidian,20,minecraft:obsidian,100)
RB(4,6,15,minecraft:crying_obsidian,20,minecraft:obsidian,100)
RB(0,7,0,minecraft:crying_obsidian,20,minecraft:obsidian,100)
RB(1,7,0,minecraft:crying_obsidian,20,minecraft:obsidian,100)
RB(2,7,0,minecraft:crying_obsidian,20,minecraft:obsidian,100)
RB(3,7,0,minecraft:crying_obsidian,20,minecraft:obsidian,100)
RB(0,7,1,minecraft:crying_obsidian,20,minecraft:obsidian,100)
RB(1,7,1,minecraft:crying_obsidian,20,minecraft:obsidian,100)
RB(2,7,1,minecraft:crying_obsidian,20,minecraft:obsidian,100)
RB(3,7,1,minecraft:crying_obsidian,20,minecraft:obsidian,100)
RB(0,7,2,minecraft:crying_obsidian,20,minecraft:obsidian,100)
RB(1,7,2,minecraft:crying_obsidian,20,minecraft:obsidian,100)
RB(2,7,2,minecraft:crying_obsidian,20,minecraft:obsidian,100)
RB(3,7,2,minecraft:crying_obsidian,20,minecraft:obsidian,100)
RB(0,7,3,minecraft:crying_obsidian,20,minecraft:obsidian,100)
RB(1,7,3,minecraft:crying_obsidian,20,minecraft:obsidian,100)
RB(2,7,3,minecraft:crying_obsidian,20,minecraft:obsidian,100)
RB(3,7,3,minecraft:crying_obsidian,20,minecraft:obsidian,100)
RB(0,7,4,minecraft:crying_obsidian,20,minecraft:obsidian,100)
RB(1,7,4,minecraft:crying_obsidian,20,minecraft:obsidian,100)
RB(2,7,4,minecraft:crying_obsidian,20,minecraft:obsidian,100)
RB(3,7,4,minecraft:crying_obsidian,20,minecraft:obsidian,100)
RB(0,7,5,minecraft:crying_obsidian,20,minecraft:obsidian,100)
RB(1,7,5,minecraft:crying_obsidian,20,minecraft:obsidian,100)
RB(2,7,5,minecraft:crying_obsidian,20,minecraft:obsidian,100)
RB(0,7,6,minecraft:crying_obsidian,20,minecraft:obsidian,100)
RB(1,7,6,minecraft:crying_obsidian,20,minecraft:obsidian,100)
RB(2,7,6,minecraft:crying_obsidian,20,minecraft:obsidian,100)
RB(3,7,6,minecraft:crying_obsidian,20,minecraft:obsidian,100)
RB(0,7,7,minecraft:crying_obsidian,20,minecraft:obsidian,100)
RB(1,7,7,minecraft:crying_obsidian,20,minecraft:obsidian,100)
RB(2,7,7,minecraft:crying_obsidian,20,minecraft:obsidian,100)
RB(3,7,7,minecraft:crying_obsidian,20,minecraft:obsidian,100)
RB(4,7,7,minecraft:crying_obsidian,20,minecraft:obsidian,100)
RB(5,7,7,minecraft:crying_obsidian,20,minecraft:obsidian,100)
RB(0,7,8,minecraft:crying_obsidian,20,minecraft:obsidian,100)
RB(1,7,8,minecraft:crying_obsidian,20,minecraft:obsidian,100)
RB(2,7,8,minecraft:crying_obsidian,20,minecraft:obsidian,100)
RB(3,7,8,minecraft:crying_obsidian,20,minecraft:obsidian,100)
RB(4,7,8,minecraft:crying_obsidian,20,minecraft:obsidian,100)
RB(5,7,8,minecraft:crying_obsidian,20,minecraft:obsidian,100)
RB(6,7,8,minecraft:crying_obsidian,20,minecraft:obsidian,100)
RB(0,7,9,minecraft:crying_obsidian,20,minecraft:obsidian,100)
RB(1,7,9,minecraft:crying_obsidian,20,minecraft:obsidian,100)
RB(2,7,9,minecraft:crying_obsidian,20,minecraft:obsidian,100)
RB(3,7,9,minecraft:crying_obsidian,20,minecraft:obsidian,100)
RB(4,7,9,minecraft:crying_obsidian,20,minecraft:obsidian,100)
RB(5,7,9,minecraft:crying_obsidian,20,minecraft:obsidian,100)
RB(6,7,9,minecraft:crying_obsidian,20,minecraft:obsidian,100)
RB(0,7,10,minecraft:crying_obsidian,20,minecraft:obsidian,100)
RB(1,7,10,minecraft:crying_obsidian,20,minecraft:obsidian,100)
RB(2,7,10,minecraft:crying_obsidian,20,minecraft:obsidian,100)
RB(3,7,10,minecraft:crying_obsidian,20,minecraft:obsidian,100)
RB(4,7,10,minecraft:crying_obsidian,20,minecraft:obsidian,100)
RB(5,7,10,minecraft:crying_obsidian,20,minecraft:obsidian,100)
RB(6,7,10,minecraft:crying_obsidian,20,minecraft:obsidian,100)
RB(0,7,11,minecraft:crying_obsidian,20,minecraft:obsidian,100)
RB(1,7,11,minecraft:crying_obsidian,20,minecraft:obsidian,100)
RB(2,7,11,minecraft:crying_obsidian,20,minecraft:obsidian,100)
RB(3,7,11,minecraft:crying_obsidian,20,minecraft:obsidian,100)
RB(4,7,11,minecraft:crying_obsidian,20,minecraft:obsidian,100)
RB(5,7,11,minecraft:crying_obsidian,20,minecraft:obsidian,100)
RB(6,7,11,minecraft:crying_obsidian,20,minecraft:obsidian,100)
RB(0,7,12,minecraft:crying_obsidian,20,minecraft:obsidian,100)
RB(1,7,12,minecraft:crying_obsidian,20,minecraft:obsidian,100)
RB(2,7,12,minecraft:crying_obsidian,20,minecraft:obsidian,100)
RB(3,7,12,minecraft:crying_obsidian,20,minecraft:obsidian,100)
RB(4,7,12,minecraft:crying_obsidian,20,minecraft:obsidian,100)
RB(5,7,12,minecraft:crying_obsidian,20,minecraft:obsidian,100)
RB(6,7,12,minecraft:crying_obsidian,20,minecraft:obsidian,100)
RB(0,7,13,minecraft:crying_obsidian,20,minecraft:obsidian,100)
RB(1,7,13,minecraft:crying_obsidian,20,minecraft:obsidian,100)
RB(2,7,13,minecraft:crying_obsidian,20,minecraft:obsidian,100)
RB(3,7,13,minecraft:crying_obsidian,20,minecraft:obsidian,100)
RB(4,7,13,minecraft:crying_obsidian,20,minecraft:obsidian,100)
RB(5,7,13,minecraft:crying_obsidian,20,minecraft:obsidian,100)
RB(6,7,13,minecraft:crying_obsidian,20,minecraft:obsidian,100)
RB(0,7,14,minecraft:crying_obsidian,20,minecraft:obsidian,100)
RB(1,7,14,minecraft:crying_obsidian,20,minecraft:obsidian,100)
RB(2,7,14,minecraft:crying_obsidian,20,minecraft:obsidian,100)
RB(3,7,14,minecraft:crying_obsidian,20,minecraft:obsidian,100)
RB(4,7,14,minecraft:crying_obsidian,20,minecraft:obsidian,100)
RB(5,7,14,minecraft:crying_obsidian,20,minecraft:obsidian,100)
RB(0,7,15,minecraft:crying_obsidian,20,minecraft:obsidian,100)
RB(1,7,15,minecraft:crying_obsidian,20,minecraft:obsidian,100)
RB(2,7,15,minecraft:crying_obsidian,20,minecraft:obsidian,100)
RB(3,7,15,minecraft:crying_obsidian,20,minecraft:obsidian,100)
RB(4,7,15,minecraft:crying_obsidian,20,minecraft:obsidian,100)
RB(0,8,0,minecraft:crying_obsidian,20,minecraft:obsidian,100)
RB(1,8,0,minecraft:crying_obsidian,20,minecraft:obsidian,100)
RB(2,8,0,minecraft:crying_obsidian,20,minecraft:obsidian,100)
RB(3,8,0,minecraft:crying_obsidian,20,minecraft:obsidian,100)
RB(0,8,1,minecraft:crying_obsidian,20,minecraft:obsidian,100)
RB(1,8,1,minecraft:crying_obsidian,20,minecraft:obsidian,100)
RB(2,8,1,minecraft:crying_obsidian,20,minecraft:obsidian,100)
RB(3,8,1,minecraft:crying_obsidian,20,minecraft:obsidian,100)
RB(0,8,2,minecraft:crying_obsidian,20,minecraft:obsidian,100)
RB(1,8,2,minecraft:crying_obsidian,20,minecraft:obsidian,100)
RB(2,8,2,minecraft:crying_obsidian,20,minecraft:obsidian,100)
RB(3,8,2,minecraft:crying_obsidian,20,minecraft:obsidian,100)
RB(0,8,3,minecraft:crying_obsidian,20,minecraft:obsidian,100)
RB(1,8,3,minecraft:crying_obsidian,20,minecraft:obsidian,100)
RB(2,8,3,minecraft:crying_obsidian,20,minecraft:obsidian,100)
RB(3,8,3,minecraft:crying_obsidian,20,minecraft:obsidian,100)
RB(0,8,4,minecraft:crying_obsidian,20,minecraft:obsidian,100)
RB(1,8,4,minecraft:crying_obsidian,20,minecraft:obsidian,100)
RB(2,8,4,minecraft:crying_obsidian,20,minecraft:obsidian,100)
RB(0,8,5,minecraft:crying_obsidian,20,minecraft:obsidian,100)
RB(1,8,5,minecraft:crying_obsidian,20,minecraft:obsidian,100)
RB(2,8,5,minecraft:crying_obsidian,20,minecraft:obsidian,100)
RB(0,8,6,minecraft:crying_obsidian,20,minecraft:obsidian,100)
RB(1,8,6,minecraft:crying_obsidian,20,minecraft:obsidian,100)
RB(2,8,6,minecraft:crying_obsidian,20,minecraft:obsidian,100)
RB(3,8,6,minecraft:crying_obsidian,20,minecraft:obsidian,100)
RB(0,8,7,minecraft:crying_obsidian,20,minecraft:obsidian,100)
RB(1,8,7,minecraft:crying_obsidian,20,minecraft:obsidian,100)
RB(2,8,7,minecraft:crying_obsidian,20,minecraft:obsidian,100)
RB(3,8,7,minecraft:crying_obsidian,20,minecraft:obsidian,100)
RB(0,8,8,minecraft:crying_obsidian,20,minecraft:obsidian,100)
RB(1,8,8,minecraft:crying_obsidian,20,minecraft:obsidian,100)
RB(2,8,8,minecraft:crying_obsidian,20,minecraft:obsidian,100)
RB(3,8,8,minecraft:crying_obsidian,20,minecraft:obsidian,100)
RB(4,8,8,minecraft:crying_obsidian,20,minecraft:obsidian,100)
RB(5,8,8,minecraft:crying_obsidian,20,minecraft:obsidian,100)
RB(0,8,9,minecraft:crying_obsidian,20,minecraft:obsidian,100)
RB(1,8,9,minecraft:crying_obsidian,20,minecraft:obsidian,100)
RB(2,8,9,minecraft:crying_obsidian,20,minecraft:obsidian,100)
RB(3,8,9,minecraft:crying_obsidian,20,minecraft:obsidian,100)
RB(4,8,9,minecraft:crying_obsidian,20,minecraft:obsidian,100)
RB(5,8,9,minecraft:crying_obsidian,20,minecraft:obsidian,100)
RB(6,8,9,minecraft:crying_obsidian,20,minecraft:obsidian,100)
RB(0,8,10,minecraft:crying_obsidian,20,minecraft:obsidian,100)
RB(1,8,10,minecraft:crying_obsidian,20,minecraft:obsidian,100)
RB(2,8,10,minecraft:crying_obsidian,20,minecraft:obsidian,100)
RB(3,8,10,minecraft:crying_obsidian,20,minecraft:obsidian,100)
RB(4,8,10,minecraft:crying_obsidian,20,minecraft:obsidian,100)
RB(5,8,10,minecraft:crying_obsidian,20,minecraft:obsidian,100)
RB(6,8,10,minecraft:crying_obsidian,20,minecraft:obsidian,100)
RB(0,8,11,minecraft:crying_obsidian,20,minecraft:obsidian,100)
RB(1,8,11,minecraft:crying_obsidian,20,minecraft:obsidian,100)
RB(2,8,11,minecraft:crying_obsidian,20,minecraft:obsidian,100)
RB(3,8,11,minecraft:crying_obsidian,20,minecraft:obsidian,100)
RB(4,8,11,minecraft:crying_obsidian,20,minecraft:obsidian,100)
RB(5,8,11,minecraft:crying_obsidian,20,minecraft:obsidian,100)
RB(6,8,11,minecraft:crying_obsidian,20,minecraft:obsidian,100)
RB(0,8,12,minecraft:crying_obsidian,20,minecraft:obsidian,100)
RB(1,8,12,minecraft:crying_obsidian,20,minecraft:obsidian,100)
RB(2,8,12,minecraft:crying_obsidian,20,minecraft:obsidian,100)
RB(3,8,12,minecraft:crying_obsidian,20,minecraft:obsidian,100)
RB(4,8,12,minecraft:crying_obsidian,20,minecraft:obsidian,100)
RB(5,8,12,minecraft:crying_obsidian,20,minecraft:obsidian,100)
RB(6,8,12,minecraft:crying_obsidian,20,minecraft:obsidian,100)
RB(0,8,13,minecraft:crying_obsidian,20,minecraft:obsidian,100)
RB(1,8,13,minecraft:crying_obsidian,20,minecraft:obsidian,100)
RB(2,8,13,minecraft:crying_obsidian,20,minecraft:obsidian,100)
RB(3,8,13,minecraft:crying_obsidian,20,minecraft:obsidian,100)
RB(4,8,13,minecraft:crying_obsidian,20,minecraft:obsidian,100)
RB(5,8,13,minecraft:crying_obsidian,20,minecraft:obsidian,100)
RB(6,8,13,minecraft:crying_obsidian,20,minecraft:obsidian,100)
RB(0,8,14,minecraft:crying_obsidian,20,minecraft:obsidian,100)
RB(1,8,14,minecraft:crying_obsidian,20,minecraft:obsidian,100)
RB(2,8,14,minecraft:crying_obsidian,20,minecraft:obsidian,100)
RB(3,8,14,minecraft:crying_obsidian,20,minecraft:obsidian,100)
RB(4,8,14,minecraft:crying_obsidian,20,minecraft:obsidian,100)
RB(5,8,14,minecraft:crying_obsidian,20,minecraft:obsidian,100)
RB(0,8,15,minecraft:crying_obsidian,20,minecraft:obsidian,100)
RB(1,8,15,minecraft:crying_obsidian,20,minecraft:obsidian,100)
RB(0,9,0,minecraft:crying_obsidian,20,minecraft:obsidian,100)
RB(1,9,0,minecraft:crying_obsidian,20,minecraft:obsidian,100)
RB(2,9,0,minecraft:crying_obsidian,20,minecraft:obsidian,100)
RB(0,9,1,minecraft:crying_obsidian,20,minecraft:obsidian,100)
RB(1,9,1,minecraft:crying_obsidian,20,minecraft:obsidian,100)
RB(2,9,1,minecraft:crying_obsidian,20,minecraft:obsidian,100)
RB(0,9,2,minecraft:crying_obsidian,20,minecraft:obsidian,100)
RB(1,9,2,minecraft:crying_obsidian,20,minecraft:obsidian,100)
RB(2,9,2,minecraft:crying_obsidian,20,minecraft:obsidian,100)
RB(0,9,3,minecraft:crying_obsidian,20,minecraft:obsidian,100)
RB(1,9,3,minecraft:crying_obsidian,20,minecraft:obsidian,100)
RB(2,9,3,minecraft:crying_obsidian,20,minecraft:obsidian,100)
RB(0,9,4,minecraft:crying_obsidian,20,minecraft:obsidian,100)
RB(1,9,4,minecraft:crying_obsidian,20,minecraft:obsidian,100)
RB(0,9,5,minecraft:crying_obsidian,20,minecraft:obsidian,100)
RB(1,9,5,minecraft:crying_obsidian,20,minecraft:obsidian,100)
RB(2,9,5,minecraft:crying_obsidian,20,minecraft:obsidian,100)
RB(0,9,6,minecraft:crying_obsidian,20,minecraft:obsidian,100)
RB(1,9,6,minecraft:crying_obsidian,20,minecraft:obsidian,100)
RB(2,9,6,minecraft:crying_obsidian,20,minecraft:obsidian,100)
RB(3,9,6,minecraft:crying_obsidian,20,minecraft:obsidian,100)
RB(0,9,7,minecraft:crying_obsidian,20,minecraft:obsidian,100)
RB(1,9,7,minecraft:crying_obsidian,20,minecraft:obsidian,100)
RB(2,9,7,minecraft:crying_obsidian,20,minecraft:obsidian,100)
RB(3,9,7,minecraft:crying_obsidian,20,minecraft:obsidian,100)
RB(0,9,8,minecraft:crying_obsidian,20,minecraft:obsidian,100)
RB(1,9,8,minecraft:crying_obsidian,20,minecraft:obsidian,100)
RB(2,9,8,minecraft:crying_obsidian,20,minecraft:obsidian,100)
RB(3,9,8,minecraft:crying_obsidian,20,minecraft:obsidian,100)
RB(0,9,9,minecraft:crying_obsidian,20,minecraft:obsidian,100)
RB(1,9,9,minecraft:crying_obsidian,20,minecraft:obsidian,100)
RB(2,9,9,minecraft:crying_obsidian,20,minecraft:obsidian,100)
RB(3,9,9,minecraft:crying_obsidian,20,minecraft:obsidian,100)
RB(4,9,9,minecraft:crying_obsidian,20,minecraft:obsidian,100)
RB(0,9,10,minecraft:crying_obsidian,20,minecraft:obsidian,100)
RB(1,9,10,minecraft:crying_obsidian,20,minecraft:obsidian,100)
RB(2,9,10,minecraft:crying_obsidian,20,minecraft:obsidian,100)
RB(3,9,10,minecraft:crying_obsidian,20,minecraft:obsidian,100)
RB(4,9,10,minecraft:crying_obsidian,20,minecraft:obsidian,100)
RB(5,9,10,minecraft:crying_obsidian,20,minecraft:obsidian,100)
RB(0,9,11,minecraft:crying_obsidian,20,minecraft:obsidian,100)
RB(1,9,11,minecraft:crying_obsidian,20,minecraft:obsidian,100)
RB(2,9,11,minecraft:crying_obsidian,20,minecraft:obsidian,100)
RB(3,9,11,minecraft:crying_obsidian,20,minecraft:obsidian,100)
RB(4,9,11,minecraft:crying_obsidian,20,minecraft:obsidian,100)
RB(5,9,11,minecraft:crying_obsidian,20,minecraft:obsidian,100)
RB(0,9,12,minecraft:crying_obsidian,20,minecraft:obsidian,100)
RB(1,9,12,minecraft:crying_obsidian,20,minecraft:obsidian,100)
RB(2,9,12,minecraft:crying_obsidian,20,minecraft:obsidian,100)
RB(3,9,12,minecraft:crying_obsidian,20,minecraft:obsidian,100)
RB(4,9,12,minecraft:crying_obsidian,20,minecraft:obsidian,100)
RB(5,9,12,minecraft:crying_obsidian,20,minecraft:obsidian,100)
RB(0,9,13,minecraft:crying_obsidian,20,minecraft:obsidian,100)
RB(1,9,13,minecraft:crying_obsidian,20,minecraft:obsidian,100)
RB(2,9,13,minecraft:crying_obsidian,20,minecraft:obsidian,100)
RB(3,9,13,minecraft:crying_obsidian,20,minecraft:obsidian,100)
RB(4,9,13,minecraft:crying_obsidian,20,minecraft:obsidian,100)
RB(0,9,14,minecraft:crying_obsidian,20,minecraft:obsidian,100)
RB(1,9,14,minecraft:crying_obsidian,20,minecraft:obsidian,100)
RB(0,9,15,minecraft:crying_obsidian,20,minecraft:obsidian,100)
RB(1,9,15,minecraft:crying_obsidian,20,minecraft:obsidian,100)
RB(0,10,0,minecraft:crying_obsidian,20,minecraft:obsidian,100)
RB(1,10,0,minecraft:crying_obsidian,20,minecraft:obsidian,100)
RB(2,10,0,minecraft:crying_obsidian,20,minecraft:obsidian,100)
RB(0,10,1,minecraft:crying_obsidian,20,minecraft:obsidian,100)
RB(1,10,1,minecraft:crying_obsidian,20,minecraft:obsidian,100)
RB(2,10,1,minecraft:crying_obsidian,20,minecraft:obsidian,100)
RB(0,10,2,minecraft:crying_obsidian,20,minecraft:obsidian,100)
RB(1,10,2,minecraft:crying_obsidian,20,minecraft:obsidian,100)
RB(2,10,2,minecraft:crying_obsidian,20,minecraft:obsidian,100)
RB(0,10,3,minecraft:crying_obsidian,20,minecraft:obsidian,100)
RB(1,10,3,minecraft:crying_obsidian,20,minecraft:obsidian,100)
RB(2,10,3,minecraft:crying_obsidian,20,minecraft:obsidian,100)
RB(0,10,4,minecraft:crying_obsidian,20,minecraft:obsidian,100)
RB(1,10,4,minecraft:crying_obsidian,20,minecraft:obsidian,100)
RB(0,10,5,minecraft:crying_obsidian,20,minecraft:obsidian,100)
RB(1,10,5,minecraft:crying_obsidian,20,minecraft:obsidian,100)
RB(2,10,5,minecraft:crying_obsidian,20,minecraft:obsidian,100)
RB(0,10,6,minecraft:crying_obsidian,20,minecraft:obsidian,100)
RB(1,10,6,minecraft:crying_obsidian,20,minecraft:obsidian,100)
RB(2,10,6,minecraft:crying_obsidian,20,minecraft:obsidian,100)
RB(0,10,7,minecraft:crying_obsidian,20,minecraft:obsidian,100)
RB(1,10,7,minecraft:crying_obsidian,20,minecraft:obsidian,100)
RB(2,10,7,minecraft:crying_obsidian,20,minecraft:obsidian,100)
RB(3,10,7,minecraft:crying_obsidian,20,minecraft:obsidian,100)
RB(0,10,8,minecraft:crying_obsidian,20,minecraft:obsidian,100)
RB(1,10,8,minecraft:crying_obsidian,20,minecraft:obsidian,100)
RB(2,10,8,minecraft:crying_obsidian,20,minecraft:obsidian,100)
RB(3,10,8,minecraft:crying_obsidian,20,minecraft:obsidian,100)
RB(0,10,9,minecraft:crying_obsidian,20,minecraft:obsidian,100)
RB(1,10,9,minecraft:crying_obsidian,20,minecraft:obsidian,100)
RB(2,10,9,minecraft:crying_obsidian,20,minecraft:obsidian,100)
RB(3,10,9,minecraft:crying_obsidian,20,minecraft:obsidian,100)
RB(0,10,10,minecraft:crying_obsidian,20,minecraft:obsidian,100)
RB(1,10,10,minecraft:crying_obsidian,20,minecraft:obsidian,100)
RB(2,10,10,minecraft:crying_obsidian,20,minecraft:obsidian,100)
RB(3,10,10,minecraft:crying_obsidian,20,minecraft:obsidian,100)
RB(0,10,11,minecraft:crying_obsidian,20,minecraft:obsidian,100)
RB(1,10,11,minecraft:crying_obsidian,20,minecraft:obsidian,100)
RB(2,10,11,minecraft:crying_obsidian,20,minecraft:obsidian,100)
RB(0,10,12,minecraft:crying_obsidian,20,minecraft:obsidian,100)
RB(1,10,12,minecraft:crying_obsidian,20,minecraft:obsidian,100)
RB(0,10,13,minecraft:crying_obsidian,20,minecraft:obsidian,100)
RB(1,10,13,minecraft:crying_obsidian,20,minecraft:obsidian,100)
RB(0,10,14,minecraft:crying_obsidian,20,minecraft:obsidian,100)
RB(1,10,14,minecraft:crying_obsidian,20,minecraft:obsidian,100)
RB(0,10,15,minecraft:crying_obsidian,20,minecraft:obsidian,100)
RB(1,10,15,minecraft:crying_obsidian,20,minecraft:obsidian,100)
RB(0,11,0,minecraft:crying_obsidian,20,minecraft:obsidian,100)
RB(1,11,0,minecraft:crying_obsidian,20,minecraft:obsidian,100)
RB(2,11,0,minecraft:crying_obsidian,20,minecraft:obsidian,100)
RB(0,11,1,minecraft:crying_obsidian,20,minecraft:obsidian,100)
RB(1,11,1,minecraft:crying_obsidian,20,minecraft:obsidian,100)
RB(2,11,1,minecraft:crying_obsidian,20,minecraft:obsidian,100)
RB(0,11,2,minecraft:crying_obsidian,20,minecraft:obsidian,100)
RB(1,11,2,minecraft:crying_obsidian,20,minecraft:obsidian,100)
RB(2,11,2,minecraft:crying_obsidian,20,minecraft:obsidian,100)
RB(0,11,3,minecraft:crying_obsidian,20,minecraft:obsidian,100)
RB(1,11,3,minecraft:crying_obsidian,20,minecraft:obsidian,100)
RB(2,11,3,minecraft:crying_obsidian,20,minecraft:obsidian,100)
RB(0,11,4,minecraft:crying_obsidian,20,minecraft:obsidian,100)
RB(1,11,4,minecraft:crying_obsidian,20,minecraft:obsidian,100)
RB(0,11,5,minecraft:crying_obsidian,20,minecraft:obsidian,100)
RB(1,11,5,minecraft:crying_obsidian,20,minecraft:obsidian,100)
RB(2,11,5,minecraft:crying_obsidian,20,minecraft:obsidian,100)
RB(0,11,6,minecraft:crying_obsidian,20,minecraft:obsidian,100)
RB(1,11,6,minecraft:crying_obsidian,20,minecraft:obsidian,100)
RB(2,11,6,minecraft:crying_obsidian,20,minecraft:obsidian,100)
RB(0,11,7,minecraft:crying_obsidian,20,minecraft:obsidian,100)
RB(1,11,7,minecraft:crying_obsidian,20,minecraft:obsidian,100)
RB(2,11,7,minecraft:crying_obsidian,20,minecraft:obsidian,100)
RB(3,11,7,minecraft:crying_obsidian,20,minecraft:obsidian,100)
RB(0,11,8,minecraft:crying_obsidian,20,minecraft:obsidian,100)
RB(1,11,8,minecraft:crying_obsidian,20,minecraft:obsidian,100)
RB(2,11,8,minecraft:crying_obsidian,20,minecraft:obsidian,100)
RB(3,11,8,minecraft:crying_obsidian,20,minecraft:obsidian,100)
RB(0,11,9,minecraft:crying_obsidian,20,minecraft:obsidian,100)
RB(1,11,9,minecraft:crying_obsidian,20,minecraft:obsidian,100)
RB(2,11,9,minecraft:crying_obsidian,20,minecraft:obsidian,100)
RB(3,11,9,minecraft:crying_obsidian,20,minecraft:obsidian,100)
RB(0,11,10,minecraft:crying_obsidian,20,minecraft:obsidian,100)
RB(1,11,10,minecraft:crying_obsidian,20,minecraft:obsidian,100)
RB(2,11,10,minecraft:crying_obsidian,20,minecraft:obsidian,100)
RB(3,11,10,minecraft:crying_obsidian,20,minecraft:obsidian,100)
RB(0,11,11,minecraft:crying_obsidian,20,minecraft:obsidian,100)
RB(1,11,11,minecraft:crying_obsidian,20,minecraft:obsidian,100)
RB(2,11,11,minecraft:crying_obsidian,20,minecraft:obsidian,100)
RB(0,11,12,minecraft:crying_obsidian,20,minecraft:obsidian,100)
RB(1,11,12,minecraft:crying_obsidian,20,minecraft:obsidian,100)
RB(0,11,13,minecraft:crying_obsidian,20,minecraft:obsidian,100)
RB(1,11,13,minecraft:crying_obsidian,20,minecraft:obsidian,100)
RB(0,11,14,minecraft:crying_obsidian,20,minecraft:obsidian,100)
RB(1,11,14,minecraft:crying_obsidian,20,minecraft:obsidian,100)
RB(0,11,15,minecraft:crying_obsidian,20,minecraft:obsidian,100)
RB(1,11,15,minecraft:crying_obsidian,20,minecraft:obsidian,100)
RB(0,12,0,minecraft:crying_obsidian,20,minecraft:obsidian,100)
RB(1,12,0,minecraft:crying_obsidian,20,minecraft:obsidian,100)
RB(2,12,0,minecraft:crying_obsidian,20,minecraft:obsidian,100)
RB(0,12,1,minecraft:crying_obsidian,20,minecraft:obsidian,100)
RB(1,12,1,minecraft:crying_obsidian,20,minecraft:obsidian,100)
RB(2,12,1,minecraft:crying_obsidian,20,minecraft:obsidian,100)
RB(0,12,2,minecraft:crying_obsidian,20,minecraft:obsidian,100)
RB(1,12,2,minecraft:crying_obsidian,20,minecraft:obsidian,100)
RB(2,12,2,minecraft:crying_obsidian,20,minecraft:obsidian,100)
RB(0,12,3,minecraft:crying_obsidian,20,minecraft:obsidian,100)
RB(1,12,3,minecraft:crying_obsidian,20,minecraft:obsidian,100)
RB(2,12,3,minecraft:crying_obsidian,20,minecraft:obsidian,100)
RB(0,12,4,minecraft:crying_obsidian,20,minecraft:obsidian,100)
RB(1,12,4,minecraft:crying_obsidian,20,minecraft:obsidian,100)
RB(0,12,5,minecraft:crying_obsidian,20,minecraft:obsidian,100)
RB(1,12,5,minecraft:crying_obsidian,20,minecraft:obsidian,100)
RB(2,12,5,minecraft:crying_obsidian,20,minecraft:obsidian,100)
RB(0,12,6,minecraft:crying_obsidian,20,minecraft:obsidian,100)
RB(1,12,6,minecraft:crying_obsidian,20,minecraft:obsidian,100)
RB(2,12,6,minecraft:crying_obsidian,20,minecraft:obsidian,100)
RB(0,12,7,minecraft:crying_obsidian,20,minecraft:obsidian,100)
RB(1,12,7,minecraft:crying_obsidian,20,minecraft:obsidian,100)
RB(2,12,7,minecraft:crying_obsidian,20,minecraft:obsidian,100)
RB(3,12,7,minecraft:crying_obsidian,20,minecraft:obsidian,100)
RB(0,12,8,minecraft:crying_obsidian,20,minecraft:obsidian,100)
RB(1,12,8,minecraft:crying_obsidian,20,minecraft:obsidian,100)
RB(2,12,8,minecraft:crying_obsidian,20,minecraft:obsidian,100)
RB(3,12,8,minecraft:crying_obsidian,20,minecraft:obsidian,100)
RB(0,12,9,minecraft:crying_obsidian,20,minecraft:obsidian,100)
RB(1,12,9,minecraft:crying_obsidian,20,minecraft:obsidian,100)
RB(2,12,9,minecraft:crying_obsidian,20,minecraft:obsidian,100)
RB(3,12,9,minecraft:crying_obsidian,20,minecraft:obsidian,100)
RB(0,12,10,minecraft:crying_obsidian,20,minecraft:obsidian,100)
RB(1,12,10,minecraft:crying_obsidian,20,minecraft:obsidian,100)
RB(2,12,10,minecraft:crying_obsidian,20,minecraft:obsidian,100)
RB(3,12,10,minecraft:crying_obsidian,20,minecraft:obsidian,100)
RB(0,12,11,minecraft:crying_obsidian,20,minecraft:obsidian,100)
RB(1,12,11,minecraft:crying_obsidian,20,minecraft:obsidian,100)
RB(2,12,11,minecraft:crying_obsidian,20,minecraft:obsidian,100)
RB(0,12,12,minecraft:crying_obsidian,20,minecraft:obsidian,100)
RB(1,12,12,minecraft:crying_obsidian,20,minecraft:obsidian,100)
RB(0,12,13,minecraft:crying_obsidian,20,minecraft:obsidian,100)
RB(1,12,13,minecraft:crying_obsidian,20,minecraft:obsidian,100)
RB(0,12,14,minecraft:crying_obsidian,20,minecraft:obsidian,100)
RB(1,12,14,minecraft:crying_obsidian,20,minecraft:obsidian,100)
RB(0,12,15,minecraft:crying_obsidian,20,minecraft:obsidian,100)
RB(1,12,15,minecraft:crying_obsidian,20,minecraft:obsidian,100)
RB(0,13,0,minecraft:crying_obsidian,20,minecraft:obsidian,100)
RB(1,13,0,minecraft:crying_obsidian,20,minecraft:obsidian,100)
RB(2,13,0,minecraft:crying_obsidian,20,minecraft:obsidian,100)
RB(0,13,1,minecraft:crying_obsidian,20,minecraft:obsidian,100)
RB(1,13,1,minecraft:crying_obsidian,20,minecraft:obsidian,100)
RB(2,13,1,minecraft:crying_obsidian,20,minecraft:obsidian,100)
RB(0,13,2,minecraft:crying_obsidian,20,minecraft:obsidian,100)
RB(1,13,2,minecraft:crying_obsidian,20,minecraft:obsidian,100)
RB(2,13,2,minecraft:crying_obsidian,20,minecraft:obsidian,100)
RB(0,13,3,minecraft:crying_obsidian,20,minecraft:obsidian,100)
RB(1,13,3,minecraft:crying_obsidian,20,minecraft:obsidian,100)
RB(0,13,4,minecraft:crying_obsidian,20,minecraft:obsidian,100)
RB(1,13,4,minecraft:crying_obsidian,20,minecraft:obsidian,100)
RB(0,13,5,minecraft:crying_obsidian,20,minecraft:obsidian,100)
RB(1,13,5,minecraft:crying_obsidian,20,minecraft:obsidian,100)
RB(0,13,6,minecraft:crying_obsidian,20,minecraft:obsidian,100)
RB(1,13,6,minecraft:crying_obsidian,20,minecraft:obsidian,100)
RB(2,13,6,minecraft:crying_obsidian,20,minecraft:obsidian,100)
RB(0,13,7,minecraft:crying_obsidian,20,minecraft:obsidian,100)
RB(1,13,7,minecraft:crying_obsidian,20,minecraft:obsidian,100)
RB(2,13,7,minecraft:crying_obsidian,20,minecraft:obsidian,100)
RB(0,13,8,minecraft:crying_obsidian,20,minecraft:obsidian,100)
RB(1,13,8,minecraft:crying_obsidian,20,minecraft:obsidian,100)
RB(2,13,8,minecraft:crying_obsidian,20,minecraft:obsidian,100)
RB(3,13,8,minecraft:crying_obsidian,20,minecraft:obsidian,100)
RB(0,13,9,minecraft:crying_obsidian,20,minecraft:obsidian,100)
RB(1,13,9,minecraft:crying_obsidian,20,minecraft:obsidian,100)
RB(2,13,9,minecraft:crying_obsidian,20,minecraft:obsidian,100)
RB(3,13,9,minecraft:crying_obsidian,20,minecraft:obsidian,100)
RB(0,13,10,minecraft:crying_obsidian,20,minecraft:obsidian,100)
RB(1,13,10,minecraft:crying_obsidian,20,minecraft:obsidian,100)
RB(2,13,10,minecraft:crying_obsidian,20,minecraft:obsidian,100)
RB(0,13,11,minecraft:crying_obsidian,20,minecraft:obsidian,100)
RB(1,13,11,minecraft:crying_obsidian,20,minecraft:obsidian,100)
RB(2,13,11,minecraft:crying_obsidian,20,minecraft:obsidian,100)
RB(0,13,12,minecraft:crying_obsidian,20,minecraft:obsidian,100)
RB(1,13,12,minecraft:crying_obsidian,20,minecraft:obsidian,100)
RB(0,13,13,minecraft:crying_obsidian,20,minecraft:obsidian,100)
RB(1,13,13,minecraft:crying_obsidian,20,minecraft:obsidian,100)
RB(0,13,14,minecraft:crying_obsidian,20,minecraft:obsidian,100)
RB(1,13,14,minecraft:crying_obsidian,20,minecraft:obsidian,100)
RB(0,13,15,minecraft:crying_obsidian,20,minecraft:obsidian,100)
RB(0,14,0,minecraft:crying_obsidian,20,minecraft:obsidian,100)
RB(1,14,0,minecraft:crying_obsidian,20,minecraft:obsidian,100)
RB(0,14,1,minecraft:crying_obsidian,20,minecraft:obsidian,100)
RB(1,14,1,minecraft:crying_obsidian,20,minecraft:obsidian,100)
RB(0,14,2,minecraft:crying_obsidian,20,minecraft:obsidian,100)
RB(1,14,2,minecraft:crying_obsidian,20,minecraft:obsidian,100)
RB(0,14,3,minecraft:crying_obsidian,20,minecraft:obsidian,100)
RB(1,14,3,minecraft:crying_obsidian,20,minecraft:obsidian,100)
RB(0,14,4,minecraft:crying_obsidian,20,minecraft:obsidian,100)
RB(1,14,4,minecraft:crying_obsidian,20,minecraft:obsidian,100)
RB(0,14,5,minecraft:crying_obsidian,20,minecraft:obsidian,100)
RB(1,14,5,minecraft:crying_obsidian,20,minecraft:obsidian,100)
RB(0,14,6,minecraft:crying_obsidian,20,minecraft:obsidian,100)
RB(1,14,6,minecraft:crying_obsidian,20,minecraft:obsidian,100)
RB(0,14,7,minecraft:crying_obsidian,20,minecraft:obsidian,100)
RB(1,14,7,minecraft:crying_obsidian,20,minecraft:obsidian,100)
RB(2,14,7,minecraft:crying_obsidian,20,minecraft:obsidian,100)
RB(0,14,8,minecraft:crying_obsidian,20,minecraft:obsidian,100)
RB(1,14,8,minecraft:crying_obsidian,20,minecraft:obsidian,100)
RB(2,14,8,minecraft:crying_obsidian,20,minecraft:obsidian,100)
RB(0,14,9,minecraft:crying_obsidian,20,minecraft:obsidian,100)
RB(1,14,9,minecraft:crying_obsidian,20,minecraft:obsidian,100)
RB(2,14,9,minecraft:crying_obsidian,20,minecraft:obsidian,100)
RB(3,14,9,minecraft:crying_obsidian,20,minecraft:obsidian,100)
RB(0,14,10,minecraft:crying_obsidian,20,minecraft:obsidian,100)
RB(1,14,10,minecraft:crying_obsidian,20,minecraft:obsidian,100)
RB(2,14,10,minecraft:crying_obsidian,20,minecraft:obsidian,100)
RB(0,14,11,minecraft:crying_obsidian,20,minecraft:obsidian,100)
RB(1,14,11,minecraft:crying_obsidian,20,minecraft:obsidian,100)
RB(2,14,11,minecraft:crying_obsidian,20,minecraft:obsidian,100)
RB(0,14,12,minecraft:crying_obsidian,20,minecraft:obsidian,100)
RB(1,14,12,minecraft:crying_obsidian,20,minecraft:obsidian,100)
RB(0,14,13,minecraft:crying_obsidian,20,minecraft:obsidian,100)
RB(1,14,13,minecraft:crying_obsidian,20,minecraft:obsidian,100)
RB(0,14,14,minecraft:crying_obsidian,20,minecraft:obsidian,100)
RB(1,14,14,minecraft:crying_obsidian,20,minecraft:obsidian,100)
RB(0,14,15,minecraft:crying_obsidian,20,minecraft:obsidian,100)
RB(0,15,0,minecraft:crying_obsidian,20,minecraft:obsidian,100)
RB(0,15,1,minecraft:crying_obsidian,20,minecraft:obsidian,100)
RB(0,15,2,minecraft:crying_obsidian,20,minecraft:obsidian,100)
RB(0,15,3,minecraft:crying_obsidian,20,minecraft:obsidian,100)
RB(0,15,4,minecraft:crying_obsidian,20,minecraft:obsidian,100)
RB(0,15,5,minecraft:crying_obsidian,20,minecraft:obsidian,100)
RB(1,15,5,minecraft:crying_obsidian,20,minecraft:obsidian,100)
RB(0,15,6,minecraft:crying_obsidian,20,minecraft:obsidian,100)
RB(1,15,6,minecraft:crying_obsidian,20,minecraft:obsidian,100)
RB(0,15,7,minecraft:crying_obsidian,20,minecraft:obsidian,100)
RB(1,15,7,minecraft:crying_obsidian,20,minecraft:obsidian,100)
RB(2,15,7,minecraft:crying_obsidian,20,minecraft:obsidian,100)
RB(0,15,8,minecraft:crying_obsidian,20,minecraft:obsidian,100)
RB(1,15,8,minecraft:crying_obsidian,20,minecraft:obsidian,100)
RB(2,15,8,minecraft:crying_obsidian,20,minecraft:obsidian,100)
RB(0,15,9,minecraft:crying_obsidian,20,minecraft:obsidian,100)
RB(1,15,9,minecraft:crying_obsidian,20,minecraft:obsidian,100)
RB(2,15,9,minecraft:crying_obsidian,20,minecraft:obsidian,100)
RB(0,15,10,minecraft:crying_obsidian,20,minecraft:obsidian,100)
RB(1,15,10,minecraft:crying_obsidian,20,minecraft:obsidian,100)
RB(2,15,10,minecraft:crying_obsidian,20,minecraft:obsidian,100)
RB(0,15,11,minecraft:crying_obsidian,20,minecraft:obsidian,100)
RB(1,15,11,minecraft:crying_obsidian,20,minecraft:obsidian,100)
RB(0,15,12,minecraft:crying_obsidian,20,minecraft:obsidian,100)
RB(1,15,12,minecraft:crying_obsidian,20,minecraft:obsidian,100)
RB(0,15,13,minecraft:crying_obsidian,20,minecraft:obsidian,100)
RB(1,15,13,minecraft:crying_obsidian,20,minecraft:obsidian,100)
RB(0,15,14,minecraft:crying_obsidian,20,minecraft:obsidian,100)
RB(1,15,14,minecraft:crying_obsidian,20,minecraft:obsidian,100)
RB(0,15,15,minecraft:crying_obsidian,20,minecraft:obsidian,100)
RB(0,16,4,minecraft:crying_obsidian,20,minecraft:obsidian,100)
RB(0,16,5,minecraft:crying_obsidian,20,minecraft:obsidian,100)
RB(0,16,6,minecraft:crying_obsidian,20,minecraft:obsidian,100)
RB(1,16,6,minecraft:crying_obsidian,20,minecraft:obsidian,100)
RB(0,16,7,minecraft:crying_obsidian,20,minecraft:obsidian,100)
RB(1,16,7,minecraft:crying_obsidian,20,minecraft:obsidian,100)
RB(2,16,7,minecraft:crying_obsidian,20,minecraft:obsidian,100)
RB(0,16,8,minecraft:crying_obsidian,20,minecraft:obsidian,100)
RB(1,16,8,minecraft:crying_obsidian,20,minecraft:obsidian,100)
RB(2,16,8,minecraft:crying_obsidian,20,minecraft:obsidian,100)
RB(0,16,9,minecraft:crying_obsidian,20,minecraft:obsidian,100)
RB(1,16,9,minecraft:crying_obsidian,20,minecraft:obsidian,100)
RB(2,16,9,minecraft:crying_obsidian,20,minecraft:obsidian,100)
RB(0,16,10,minecraft:crying_obsidian,20,minecraft:obsidian,100)
RB(1,16,10,minecraft:crying_obsidian,20,minecraft:obsidian,100)
RB(2,16,10,minecraft:crying_obsidian,20,minecraft:obsidian,100)
RB(0,16,11,minecraft:crying_obsidian,20,minecraft:obsidian,100)
RB(1,16,11,minecraft:crying_obsidian,20,minecraft:obsidian,100)
RB(0,16,12,minecraft:crying_obsidian,20,minecraft:obsidian,100)
RB(1,16,12,minecraft:crying_obsidian,20,minecraft:obsidian,100)
RB(0,16,13,minecraft:crying_obsidian,20,minecraft:obsidian,100)
RB(1,16,13,minecraft:crying_obsidian,20,minecraft:obsidian,100)
RB(0,16,14,minecraft:crying_obsidian,20,minecraft:obsidian,100)
RB(1,16,14,minecraft:crying_obsidian,20,minecraft:obsidian,100)
RB(0,16,15,minecraft:crying_obsidian,20,minecraft:obsidian,100)
RB(0,17,5,minecraft:crying_obsidian,20,minecraft:obsidian,100)
RB(0,17,6,minecraft:crying_obsidian,20,minecraft:obsidian,100)
RB(0,17,7,minecraft:crying_obsidian,20,minecraft:obsidian,100)
RB(1,17,7,minecraft:crying_obsidian,20,minecraft:obsidian,100)
RB(2,17,7,minecraft:crying_obsidian,20,minecraft:obsidian,100)
RB(0,17,8,minecraft:crying_obsidian,20,minecraft:obsidian,100)
RB(1,17,8,minecraft:crying_obsidian,20,minecraft:obsidian,100)
RB(0,17,9,minecraft:crying_obsidian,20,minecraft:obsidian,100)
RB(1,17,9,minecraft:crying_obsidian,20,minecraft:obsidian,100)
RB(0,17,10,minecraft:crying_obsidian,20,minecraft:obsidian,100)
RB(1,17,10,minecraft:crying_obsidian,20,minecraft:obsidian,100)
RB(2,17,10,minecraft:crying_obsidian,20,minecraft:obsidian,100)
RB(0,17,11,minecraft:crying_obsidian,20,minecraft:obsidian,100)
RB(1,17,11,minecraft:crying_obsidian,20,minecraft:obsidian,100)
RB(0,17,12,minecraft:crying_obsidian,20,minecraft:obsidian,100)
RB(1,17,12,minecraft:crying_obsidian,20,minecraft:obsidian,100)
RB(0,17,13,minecraft:crying_obsidian,20,minecraft:obsidian,100)
RB(1,17,13,minecraft:crying_obsidian,20,minecraft:obsidian,100)
RB(0,17,14,minecraft:crying_obsidian,20,minecraft:obsidian,100)
RB(1,17,14,minecraft:crying_obsidian,20,minecraft:obsidian,100)
RB(0,17,15,minecraft:crying_obsidian,20,minecraft:obsidian,100)
RB(0,18,6,minecraft:crying_obsidian,20,minecraft:obsidian,100)
RB(2,18,7,minecraft:crying_obsidian,20,minecraft:obsidian,100)
RB(0,18,8,minecraft:crying_obsidian,20,minecraft:obsidian,100)
RB(1,18,8,minecraft:crying_obsidian,20,minecraft:obsidian,100)
RB(0,18,9,minecraft:crying_obsidian,20,minecraft:obsidian,100)
RB(0,18,10,minecraft:crying_obsidian,20,minecraft:obsidian,100)
RB(0,18,11,minecraft:crying_obsidian,20,minecraft:obsidian,100)
RB(1,18,11,minecraft:crying_obsidian,20,minecraft:obsidian,100)
RB(0,18,12,minecraft:crying_obsidian,20,minecraft:obsidian,100)
RB(1,18,12,minecraft:crying_obsidian,20,minecraft:obsidian,100)
RB(0,18,13,minecraft:crying_obsidian,20,minecraft:obsidian,100)
RB(1,18,13,minecraft:crying_obsidian,20,minecraft:obsidian,100)
RB(0,18,14,minecraft:crying_obsidian,20,minecraft:obsidian,100)
RB(1,18,14,minecraft:crying_obsidian,20,minecraft:obsidian,100)
RB(0,18,15,minecraft:crying_obsidian,20,minecraft:obsidian,100)
RB(2,19,7,minecraft:crying_obsidian,20,minecraft:obsidian,100)
RB(0,19,8,minecraft:crying_obsidian,20,minecraft:obsidian,100)
RB(1,19,8,minecraft:crying_obsidian,20,minecraft:obsidian,100)
RB(0,19,11,minecraft:crying_obsidian,20,minecraft:obsidian,100)
RB(0,19,12,minecraft:crying_obsidian,20,minecraft:obsidian,100)
RB(0,19,13,minecraft:crying_obsidian,20,minecraft:obsidian,100)
RB(0,19,14,minecraft:crying_obsidian,20,minecraft:obsidian,100)
RB(0,19,15,minecraft:crying_obsidian,20,minecraft:obsidian,100)

