#######################################################################
# +-----------------------------------------------------------------+ #
# |                            BO3 object                           | #
# +-----------------------------------------------------------------+ #
#######################################################################

Author: Bo3 BulkEdit

Description: Converted Schematic - Modified by Bo3BulkEdit

Version: 3

SettingsMode: WriteDisable

#######################################################################
# +-----------------------------------------------------------------+ #
# |                          Main settings                          | #
# +-----------------------------------------------------------------+ #
#######################################################################

IsOTGPlus: true
Tree: true
Frequency: 10
Rarity: 100
RotateRandomly: true
SpawnHeight: randomY
SpawnHeightOffset: 0
SpawnHeightVariance: 0
MaxBranchDepth: 10
ExcludedBiomes: All

##############################
# Height Limits for the BO3. #
##############################

MinHeight: 50
MaxHeight: 65

#######################################################################
# +-----------------------------------------------------------------+ #
# |                      Source block settings                      | #
# +-----------------------------------------------------------------+ #
#######################################################################

SourceBlocks: AIR
MaxPercentageOutsideSourceBlock: 100
OutsideSourceBlock: placeAnyway

#######################################################################
# +-----------------------------------------------------------------+ #
# |                               OTG+                              | #
# +-----------------------------------------------------------------+ #
#######################################################################

RemoveAir: true
ReplaceBelow: OBSIDIAN
ReplaceWithBiomeBlocks: false
ReplaceWithGroundBlock: OBSIDIAN
ReplaceWithSurfaceBlock: OBSIDIAN
ReplaceWithStoneBlock: OBSIDIAN
SmoothRadius: 30
SmoothingSurfaceBlock: OBSIDIAN
SmoothingGroundBlock: OBSIDIAN

#######################################################################
# +-----------------------------------------------------------------+ #
# |                              Blocks                             | #
# +-----------------------------------------------------------------+ #
#######################################################################

RB(10,0,0,minecraft:crying_obsidian,20,minecraft:obsidian,100)
RB(11,0,0,minecraft:crying_obsidian,20,minecraft:obsidian,100)
RB(12,0,0,minecraft:crying_obsidian,20,minecraft:obsidian,100)
RB(13,0,0,minecraft:crying_obsidian,20,minecraft:obsidian,100)
RB(14,0,0,minecraft:crying_obsidian,20,minecraft:obsidian,100)
RB(15,0,0,minecraft:crying_obsidian,20,minecraft:obsidian,100)
RB(13,0,1,minecraft:crying_obsidian,20,minecraft:obsidian,100)
RB(14,0,1,minecraft:crying_obsidian,20,minecraft:obsidian,100)
RB(15,0,1,minecraft:crying_obsidian,20,minecraft:obsidian,100)
RB(14,0,2,minecraft:crying_obsidian,20,minecraft:obsidian,100)
RB(15,0,2,minecraft:crying_obsidian,20,minecraft:obsidian,100)
RB(15,0,3,minecraft:crying_obsidian,20,minecraft:obsidian,100)
RB(11,1,0,minecraft:crying_obsidian,20,minecraft:obsidian,100)
RB(12,1,0,minecraft:crying_obsidian,20,minecraft:obsidian,100)
RB(13,1,0,minecraft:crying_obsidian,20,minecraft:obsidian,100)
RB(14,1,0,minecraft:crying_obsidian,20,minecraft:obsidian,100)
RB(15,1,0,minecraft:crying_obsidian,20,minecraft:obsidian,100)
RB(13,1,1,minecraft:crying_obsidian,20,minecraft:obsidian,100)
RB(14,1,1,minecraft:crying_obsidian,20,minecraft:obsidian,100)
RB(15,1,1,minecraft:crying_obsidian,20,minecraft:obsidian,100)
RB(14,1,2,minecraft:crying_obsidian,20,minecraft:obsidian,100)
RB(15,1,2,minecraft:crying_obsidian,20,minecraft:obsidian,100)
RB(15,1,3,minecraft:crying_obsidian,20,minecraft:obsidian,100)
RB(12,2,0,minecraft:crying_obsidian,20,minecraft:obsidian,100)
RB(13,2,0,minecraft:crying_obsidian,20,minecraft:obsidian,100)
RB(14,2,0,minecraft:crying_obsidian,20,minecraft:obsidian,100)
RB(15,2,0,minecraft:crying_obsidian,20,minecraft:obsidian,100)
RB(13,2,1,minecraft:crying_obsidian,20,minecraft:obsidian,100)
RB(14,2,1,minecraft:crying_obsidian,20,minecraft:obsidian,100)
RB(15,2,1,minecraft:crying_obsidian,20,minecraft:obsidian,100)
RB(14,2,2,minecraft:crying_obsidian,20,minecraft:obsidian,100)
RB(15,2,2,minecraft:crying_obsidian,20,minecraft:obsidian,100)
RB(15,2,3,minecraft:crying_obsidian,20,minecraft:obsidian,100)
RB(12,3,0,minecraft:crying_obsidian,20,minecraft:obsidian,100)
RB(13,3,0,minecraft:crying_obsidian,20,minecraft:obsidian,100)
RB(14,3,0,minecraft:crying_obsidian,20,minecraft:obsidian,100)
RB(15,3,0,minecraft:crying_obsidian,20,minecraft:obsidian,100)
RB(13,3,1,minecraft:crying_obsidian,20,minecraft:obsidian,100)
RB(14,3,1,minecraft:crying_obsidian,20,minecraft:obsidian,100)
RB(15,3,1,minecraft:crying_obsidian,20,minecraft:obsidian,100)
RB(14,3,2,minecraft:crying_obsidian,20,minecraft:obsidian,100)
RB(15,3,2,minecraft:crying_obsidian,20,minecraft:obsidian,100)
RB(15,3,3,minecraft:crying_obsidian,20,minecraft:obsidian,100)
RB(12,4,0,minecraft:crying_obsidian,20,minecraft:obsidian,100)
RB(13,4,0,minecraft:crying_obsidian,20,minecraft:obsidian,100)
RB(14,4,0,minecraft:crying_obsidian,20,minecraft:obsidian,100)
RB(15,4,0,minecraft:crying_obsidian,20,minecraft:obsidian,100)
RB(13,4,1,minecraft:crying_obsidian,20,minecraft:obsidian,100)
RB(14,4,1,minecraft:crying_obsidian,20,minecraft:obsidian,100)
RB(15,4,1,minecraft:crying_obsidian,20,minecraft:obsidian,100)
RB(14,4,2,minecraft:crying_obsidian,20,minecraft:obsidian,100)
RB(15,4,2,minecraft:crying_obsidian,20,minecraft:obsidian,100)
RB(15,4,3,minecraft:crying_obsidian,20,minecraft:obsidian,100)
RB(12,5,0,minecraft:crying_obsidian,20,minecraft:obsidian,100)
RB(13,5,0,minecraft:crying_obsidian,20,minecraft:obsidian,100)
RB(14,5,0,minecraft:crying_obsidian,20,minecraft:obsidian,100)
RB(15,5,0,minecraft:crying_obsidian,20,minecraft:obsidian,100)
RB(13,5,1,minecraft:crying_obsidian,20,minecraft:obsidian,100)
RB(14,5,1,minecraft:crying_obsidian,20,minecraft:obsidian,100)
RB(15,5,1,minecraft:crying_obsidian,20,minecraft:obsidian,100)
RB(14,5,2,minecraft:crying_obsidian,20,minecraft:obsidian,100)
RB(15,5,2,minecraft:crying_obsidian,20,minecraft:obsidian,100)
RB(15,5,3,minecraft:crying_obsidian,20,minecraft:obsidian,100)
RB(12,6,0,minecraft:crying_obsidian,20,minecraft:obsidian,100)
RB(13,6,0,minecraft:crying_obsidian,20,minecraft:obsidian,100)
RB(14,6,0,minecraft:crying_obsidian,20,minecraft:obsidian,100)
RB(15,6,0,minecraft:crying_obsidian,20,minecraft:obsidian,100)
RB(13,6,1,minecraft:crying_obsidian,20,minecraft:obsidian,100)
RB(14,6,1,minecraft:crying_obsidian,20,minecraft:obsidian,100)
RB(15,6,1,minecraft:crying_obsidian,20,minecraft:obsidian,100)
RB(14,6,2,minecraft:crying_obsidian,20,minecraft:obsidian,100)
RB(15,6,2,minecraft:crying_obsidian,20,minecraft:obsidian,100)
RB(15,6,3,minecraft:crying_obsidian,20,minecraft:obsidian,100)
RB(12,7,0,minecraft:crying_obsidian,20,minecraft:obsidian,100)
RB(13,7,0,minecraft:crying_obsidian,20,minecraft:obsidian,100)
RB(14,7,0,minecraft:crying_obsidian,20,minecraft:obsidian,100)
RB(15,7,0,minecraft:crying_obsidian,20,minecraft:obsidian,100)
RB(13,7,1,minecraft:crying_obsidian,20,minecraft:obsidian,100)
RB(14,7,1,minecraft:crying_obsidian,20,minecraft:obsidian,100)
RB(15,7,1,minecraft:crying_obsidian,20,minecraft:obsidian,100)
RB(14,7,2,minecraft:crying_obsidian,20,minecraft:obsidian,100)
RB(15,7,2,minecraft:crying_obsidian,20,minecraft:obsidian,100)
RB(15,7,3,minecraft:crying_obsidian,20,minecraft:obsidian,100)
RB(12,8,0,minecraft:crying_obsidian,20,minecraft:obsidian,100)
RB(13,8,0,minecraft:crying_obsidian,20,minecraft:obsidian,100)
RB(14,8,0,minecraft:crying_obsidian,20,minecraft:obsidian,100)
RB(15,8,0,minecraft:crying_obsidian,20,minecraft:obsidian,100)
RB(13,8,1,minecraft:crying_obsidian,20,minecraft:obsidian,100)
RB(14,8,1,minecraft:crying_obsidian,20,minecraft:obsidian,100)
RB(15,8,1,minecraft:crying_obsidian,20,minecraft:obsidian,100)
RB(14,8,2,minecraft:crying_obsidian,20,minecraft:obsidian,100)
RB(15,8,2,minecraft:crying_obsidian,20,minecraft:obsidian,100)
RB(15,8,3,minecraft:crying_obsidian,20,minecraft:obsidian,100)
RB(12,9,0,minecraft:crying_obsidian,20,minecraft:obsidian,100)
RB(13,9,0,minecraft:crying_obsidian,20,minecraft:obsidian,100)
RB(14,9,0,minecraft:crying_obsidian,20,minecraft:obsidian,100)
RB(15,9,0,minecraft:crying_obsidian,20,minecraft:obsidian,100)
RB(13,9,1,minecraft:crying_obsidian,20,minecraft:obsidian,100)
RB(14,9,1,minecraft:crying_obsidian,20,minecraft:obsidian,100)
RB(15,9,1,minecraft:crying_obsidian,20,minecraft:obsidian,100)
RB(14,9,2,minecraft:crying_obsidian,20,minecraft:obsidian,100)
RB(15,9,2,minecraft:crying_obsidian,20,minecraft:obsidian,100)
RB(15,9,3,minecraft:crying_obsidian,20,minecraft:obsidian,100)
RB(12,10,0,minecraft:crying_obsidian,20,minecraft:obsidian,100)
RB(13,10,0,minecraft:crying_obsidian,20,minecraft:obsidian,100)
RB(14,10,0,minecraft:crying_obsidian,20,minecraft:obsidian,100)
RB(15,10,0,minecraft:crying_obsidian,20,minecraft:obsidian,100)
RB(13,10,1,minecraft:crying_obsidian,20,minecraft:obsidian,100)
RB(14,10,1,minecraft:crying_obsidian,20,minecraft:obsidian,100)
RB(15,10,1,minecraft:crying_obsidian,20,minecraft:obsidian,100)
RB(14,10,2,minecraft:crying_obsidian,20,minecraft:obsidian,100)
RB(15,10,2,minecraft:crying_obsidian,20,minecraft:obsidian,100)
RB(15,10,3,minecraft:crying_obsidian,20,minecraft:obsidian,100)
RB(12,11,0,minecraft:crying_obsidian,20,minecraft:obsidian,100)
RB(13,11,0,minecraft:crying_obsidian,20,minecraft:obsidian,100)
RB(14,11,0,minecraft:crying_obsidian,20,minecraft:obsidian,100)
RB(15,11,0,minecraft:crying_obsidian,20,minecraft:obsidian,100)
RB(13,11,1,minecraft:crying_obsidian,20,minecraft:obsidian,100)
RB(14,11,1,minecraft:crying_obsidian,20,minecraft:obsidian,100)
RB(15,11,1,minecraft:crying_obsidian,20,minecraft:obsidian,100)
RB(14,11,2,minecraft:crying_obsidian,20,minecraft:obsidian,100)
RB(15,11,2,minecraft:crying_obsidian,20,minecraft:obsidian,100)
RB(15,11,3,minecraft:crying_obsidian,20,minecraft:obsidian,100)
RB(12,12,0,minecraft:crying_obsidian,20,minecraft:obsidian,100)
RB(13,12,0,minecraft:crying_obsidian,20,minecraft:obsidian,100)
RB(14,12,0,minecraft:crying_obsidian,20,minecraft:obsidian,100)
RB(15,12,0,minecraft:crying_obsidian,20,minecraft:obsidian,100)
RB(13,12,1,minecraft:crying_obsidian,20,minecraft:obsidian,100)
RB(14,12,1,minecraft:crying_obsidian,20,minecraft:obsidian,100)
RB(15,12,1,minecraft:crying_obsidian,20,minecraft:obsidian,100)
RB(14,12,2,minecraft:crying_obsidian,20,minecraft:obsidian,100)
RB(15,12,2,minecraft:crying_obsidian,20,minecraft:obsidian,100)
RB(15,12,3,minecraft:crying_obsidian,20,minecraft:obsidian,100)
RB(12,13,0,minecraft:crying_obsidian,20,minecraft:obsidian,100)
RB(13,13,0,minecraft:crying_obsidian,20,minecraft:obsidian,100)
RB(14,13,0,minecraft:crying_obsidian,20,minecraft:obsidian,100)
RB(15,13,0,minecraft:crying_obsidian,20,minecraft:obsidian,100)
RB(13,13,1,minecraft:crying_obsidian,20,minecraft:obsidian,100)
RB(14,13,1,minecraft:crying_obsidian,20,minecraft:obsidian,100)
RB(15,13,1,minecraft:crying_obsidian,20,minecraft:obsidian,100)
RB(14,13,2,minecraft:crying_obsidian,20,minecraft:obsidian,100)
RB(15,13,2,minecraft:crying_obsidian,20,minecraft:obsidian,100)
RB(15,13,3,minecraft:crying_obsidian,20,minecraft:obsidian,100)
RB(12,14,0,minecraft:crying_obsidian,20,minecraft:obsidian,100)
RB(13,14,0,minecraft:crying_obsidian,20,minecraft:obsidian,100)
RB(14,14,0,minecraft:crying_obsidian,20,minecraft:obsidian,100)
RB(15,14,0,minecraft:crying_obsidian,20,minecraft:obsidian,100)
RB(13,14,1,minecraft:crying_obsidian,20,minecraft:obsidian,100)
RB(14,14,1,minecraft:crying_obsidian,20,minecraft:obsidian,100)
RB(15,14,1,minecraft:crying_obsidian,20,minecraft:obsidian,100)
RB(14,14,2,minecraft:crying_obsidian,20,minecraft:obsidian,100)
RB(15,14,2,minecraft:crying_obsidian,20,minecraft:obsidian,100)
RB(15,14,3,minecraft:crying_obsidian,20,minecraft:obsidian,100)
RB(12,15,0,minecraft:crying_obsidian,20,minecraft:obsidian,100)
RB(13,15,0,minecraft:crying_obsidian,20,minecraft:obsidian,100)
RB(14,15,0,minecraft:crying_obsidian,20,minecraft:obsidian,100)
RB(15,15,0,minecraft:crying_obsidian,20,minecraft:obsidian,100)
RB(13,15,1,minecraft:crying_obsidian,20,minecraft:obsidian,100)
RB(14,15,1,minecraft:crying_obsidian,20,minecraft:obsidian,100)
RB(15,15,1,minecraft:crying_obsidian,20,minecraft:obsidian,100)
RB(15,15,2,minecraft:crying_obsidian,20,minecraft:obsidian,100)
RB(14,16,0,minecraft:crying_obsidian,20,minecraft:obsidian,100)
RB(15,16,0,minecraft:crying_obsidian,20,minecraft:obsidian,100)
RB(15,16,1,minecraft:crying_obsidian,20,minecraft:obsidian,100)
RB(15,17,0,minecraft:crying_obsidian,20,minecraft:obsidian,100)

