Author: Bo3 BulkEdit

Description: Converted Schematic - Modified by Bo3BulkEdit

Version: 3

SettingsMode: WriteDisable

IsOTGPlus: true
Tree: false
Frequency: 10
Rarity: 100
RotateRandomly: true
SpawnHeight: randomY
SpawnHeightOffset: 0
SpawnHeightVariance: 0
MaxBranchDepth: 10
ExcludedBiomes: All

MinHeight: 50
MaxHeight: 65

SourceBlocks: AIR
MaxPercentageOutsideSourceBlock: 100
OutsideSourceBlock: placeAnyway

ReplaceBelow: NETHER_WART_BLOCK
ReplaceWithBiomeBlocks: false
ReplaceWithGroundBlock: NETHER_WART_BLOCK
ReplaceWithSurfaceBlock: NETHER_WART_BLOCK
ReplaceWithStoneBlock: NETHER_WART_BLOCK
SmoothRadius: 30
SmoothHeightOffset: 0
SmoothStartTop: false
SmoothStartWood: false
SmoothingSurfaceBlock: NETHER_WART_BLOCK
SmoothingGroundBlock: NETHER_WART_BLOCK

B(0,750,0,AIR)
B(15,750,15,AIR)
B(0,0,0,minecraft:nether_wart_block)
B(1,0,0,minecraft:nether_wart_block)
B(2,0,0,minecraft:nether_wart_block)
B(3,0,0,minecraft:nether_wart_block)
B(4,0,0,minecraft:nether_wart_block)
B(5,0,0,minecraft:nether_wart_block)
B(6,0,0,minecraft:nether_wart_block)
B(7,0,0,minecraft:nether_wart_block)
B(8,0,0,minecraft:nether_wart_block)
B(9,0,0,minecraft:nether_wart_block)
B(10,0,0,minecraft:nether_wart_block)
B(11,0,0,minecraft:nether_wart_block)
B(12,0,0,minecraft:nether_wart_block)
B(13,0,0,minecraft:nether_wart_block)
B(14,0,0,minecraft:nether_wart_block)
B(15,0,0,minecraft:nether_wart_block)
B(0,0,1,minecraft:nether_wart_block)
B(1,0,1,minecraft:nether_wart_block)
B(2,0,1,minecraft:nether_wart_block)
B(3,0,1,minecraft:nether_wart_block)
B(4,0,1,minecraft:nether_wart_block)
B(5,0,1,minecraft:nether_wart_block)
B(6,0,1,minecraft:nether_wart_block)
B(7,0,1,minecraft:nether_wart_block)
B(8,0,1,minecraft:nether_wart_block)
B(9,0,1,minecraft:nether_wart_block)
B(10,0,1,minecraft:nether_wart_block)
B(11,0,1,minecraft:nether_wart_block)
B(12,0,1,minecraft:nether_wart_block)
B(13,0,1,minecraft:nether_wart_block)
B(14,0,1,minecraft:nether_wart_block)
B(15,0,1,minecraft:nether_wart_block)
B(0,0,2,minecraft:nether_wart_block)
B(1,0,2,minecraft:nether_wart_block)
B(2,0,2,minecraft:nether_wart_block)
B(3,0,2,minecraft:nether_wart_block)
B(4,0,2,minecraft:nether_wart_block)
B(5,0,2,minecraft:nether_wart_block)
B(6,0,2,minecraft:nether_wart_block)
B(7,0,2,minecraft:nether_wart_block)
B(8,0,2,minecraft:nether_wart_block)
B(9,0,2,minecraft:nether_wart_block)
B(10,0,2,minecraft:nether_wart_block)
B(11,0,2,minecraft:nether_wart_block)
B(12,0,2,minecraft:nether_wart_block)
B(13,0,2,minecraft:nether_wart_block)
B(14,0,2,minecraft:nether_wart_block)
B(15,0,2,minecraft:nether_wart_block)
B(0,0,3,minecraft:nether_wart_block)
B(1,0,3,minecraft:nether_wart_block)
B(2,0,3,minecraft:nether_wart_block)
B(3,0,3,minecraft:nether_wart_block)
B(4,0,3,minecraft:nether_wart_block)
B(5,0,3,minecraft:nether_wart_block)
B(6,0,3,minecraft:nether_wart_block)
B(7,0,3,minecraft:nether_wart_block)
B(8,0,3,minecraft:nether_wart_block)
B(9,0,3,minecraft:nether_wart_block)
B(10,0,3,minecraft:nether_wart_block)
B(11,0,3,minecraft:nether_wart_block)
B(12,0,3,minecraft:nether_wart_block)
B(13,0,3,minecraft:nether_wart_block)
B(14,0,3,minecraft:nether_wart_block)
B(15,0,3,minecraft:lava[level=8])
B(0,0,4,minecraft:nether_wart_block)
B(1,0,4,minecraft:nether_wart_block)
B(2,0,4,minecraft:nether_wart_block)
B(3,0,4,minecraft:nether_wart_block)
B(4,0,4,minecraft:nether_wart_block)
B(5,0,4,minecraft:nether_wart_block)
B(6,0,4,minecraft:nether_wart_block)
B(7,0,4,minecraft:nether_wart_block)
B(8,0,4,minecraft:nether_wart_block)
B(9,0,4,minecraft:nether_wart_block)
B(10,0,4,minecraft:nether_wart_block)
B(11,0,4,minecraft:nether_wart_block)
B(12,0,4,minecraft:nether_wart_block)
B(14,0,4,minecraft:lava[level=8])
B(0,0,5,minecraft:nether_wart_block)
B(1,0,5,minecraft:nether_wart_block)
B(2,0,5,minecraft:nether_wart_block)
B(3,0,5,minecraft:nether_wart_block)
B(4,0,5,minecraft:nether_wart_block)
B(5,0,5,minecraft:nether_wart_block)
B(6,0,5,minecraft:nether_wart_block)
B(7,0,5,minecraft:nether_wart_block)
B(8,0,5,minecraft:nether_wart_block)
B(9,0,5,minecraft:nether_wart_block)
B(10,0,5,minecraft:nether_wart_block)
B(11,0,5,minecraft:nether_wart_block)
B(12,0,5,minecraft:nether_wart_block)
B(0,0,6,minecraft:nether_wart_block)
B(1,0,6,minecraft:nether_wart_block)
B(2,0,6,minecraft:nether_wart_block)
B(3,0,6,minecraft:nether_wart_block)
B(4,0,6,minecraft:nether_wart_block)
B(5,0,6,minecraft:nether_wart_block)
B(6,0,6,minecraft:nether_wart_block)
B(7,0,6,minecraft:nether_wart_block)
B(8,0,6,minecraft:nether_wart_block)
B(9,0,6,minecraft:nether_wart_block)
B(10,0,6,minecraft:nether_wart_block)
B(11,0,6,minecraft:nether_wart_block)
B(0,0,7,minecraft:nether_wart_block)
B(1,0,7,minecraft:nether_wart_block)
B(2,0,7,minecraft:nether_wart_block)
B(3,0,7,minecraft:nether_wart_block)
B(4,0,7,minecraft:nether_wart_block)
B(5,0,7,minecraft:nether_wart_block)
B(6,0,7,minecraft:nether_wart_block)
B(7,0,7,minecraft:nether_wart_block)
B(8,0,7,minecraft:nether_wart_block)
B(9,0,7,minecraft:nether_wart_block)
B(10,0,7,minecraft:nether_wart_block)
B(0,0,8,minecraft:nether_wart_block)
B(1,0,8,minecraft:nether_wart_block)
B(2,0,8,minecraft:nether_wart_block)
B(3,0,8,minecraft:nether_wart_block)
B(4,0,8,minecraft:nether_wart_block)
B(5,0,8,minecraft:nether_wart_block)
B(6,0,8,minecraft:nether_wart_block)
B(7,0,8,minecraft:nether_wart_block)
B(8,0,8,minecraft:nether_wart_block)
B(0,0,9,minecraft:nether_wart_block)
B(1,0,9,minecraft:nether_wart_block)
B(2,0,9,minecraft:nether_wart_block)
B(3,0,9,minecraft:nether_wart_block)
B(4,0,9,minecraft:nether_wart_block)
B(5,0,9,minecraft:nether_wart_block)
B(6,0,9,minecraft:nether_wart_block)
B(7,0,9,minecraft:nether_wart_block)
B(0,0,10,minecraft:nether_wart_block)
B(1,0,10,minecraft:nether_wart_block)
B(2,0,10,minecraft:nether_wart_block)
B(3,0,10,minecraft:nether_wart_block)
B(4,0,10,minecraft:nether_wart_block)
B(5,0,10,minecraft:nether_wart_block)
B(6,0,10,minecraft:nether_wart_block)
B(0,0,11,minecraft:nether_wart_block)
B(1,0,11,minecraft:nether_wart_block)
B(2,0,11,minecraft:nether_wart_block)
B(3,0,11,minecraft:nether_wart_block)
B(4,0,11,minecraft:nether_wart_block)
B(5,0,11,minecraft:nether_wart_block)
B(0,0,12,minecraft:nether_wart_block)
B(1,0,12,minecraft:nether_wart_block)
B(2,0,12,minecraft:nether_wart_block)
B(3,0,12,minecraft:nether_wart_block)
B(4,0,12,minecraft:nether_wart_block)
B(5,0,12,minecraft:nether_wart_block)
B(0,0,13,minecraft:nether_wart_block)
B(1,0,13,minecraft:nether_wart_block)
B(2,0,13,minecraft:nether_wart_block)
B(3,0,13,minecraft:nether_wart_block)
B(4,0,13,minecraft:nether_wart_block)
B(5,0,13,minecraft:nether_wart_block)
B(0,0,14,minecraft:nether_wart_block)
B(1,0,14,minecraft:nether_wart_block)
B(2,0,14,minecraft:nether_wart_block)
B(3,0,14,minecraft:nether_wart_block)
B(4,0,14,minecraft:nether_wart_block)
B(5,0,14,minecraft:nether_wart_block)
B(0,0,15,minecraft:nether_wart_block)
B(1,0,15,minecraft:nether_wart_block)
B(2,0,15,minecraft:nether_wart_block)
B(3,0,15,minecraft:nether_wart_block)
B(4,0,15,minecraft:nether_wart_block)
B(5,0,15,minecraft:nether_wart_block)
B(0,1,0,minecraft:nether_wart_block)
B(1,1,0,minecraft:nether_wart_block)
B(2,1,0,minecraft:nether_wart_block)
B(3,1,0,minecraft:nether_wart_block)
B(4,1,0,minecraft:nether_wart_block)
B(5,1,0,minecraft:nether_wart_block)
B(6,1,0,minecraft:nether_wart_block)
B(7,1,0,minecraft:nether_wart_block)
B(8,1,0,minecraft:nether_wart_block)
B(9,1,0,minecraft:nether_wart_block)
B(10,1,0,minecraft:nether_wart_block)
B(11,1,0,minecraft:nether_wart_block)
B(12,1,0,minecraft:nether_wart_block)
B(13,1,0,minecraft:nether_wart_block)
B(14,1,0,minecraft:nether_wart_block)
B(15,1,0,minecraft:nether_wart_block)
B(0,1,1,minecraft:nether_wart_block)
B(1,1,1,minecraft:nether_wart_block)
B(2,1,1,minecraft:nether_wart_block)
B(3,1,1,minecraft:nether_wart_block)
B(4,1,1,minecraft:nether_wart_block)
B(5,1,1,minecraft:nether_wart_block)
B(6,1,1,minecraft:nether_wart_block)
B(7,1,1,minecraft:nether_wart_block)
B(8,1,1,minecraft:nether_wart_block)
B(9,1,1,minecraft:nether_wart_block)
B(10,1,1,minecraft:nether_wart_block)
B(11,1,1,minecraft:nether_wart_block)
B(12,1,1,minecraft:nether_wart_block)
B(13,1,1,minecraft:nether_wart_block)
B(14,1,1,minecraft:nether_wart_block)
B(15,1,1,minecraft:nether_wart_block)
B(0,1,2,minecraft:nether_wart_block)
B(1,1,2,minecraft:nether_wart_block)
B(2,1,2,minecraft:nether_wart_block)
B(3,1,2,minecraft:nether_wart_block)
B(4,1,2,minecraft:nether_wart_block)
B(5,1,2,minecraft:nether_wart_block)
B(6,1,2,minecraft:nether_wart_block)
B(7,1,2,minecraft:nether_wart_block)
B(8,1,2,minecraft:nether_wart_block)
B(9,1,2,minecraft:nether_wart_block)
B(10,1,2,minecraft:nether_wart_block)
B(11,1,2,minecraft:nether_wart_block)
B(12,1,2,minecraft:nether_wart_block)
B(13,1,2,minecraft:nether_wart_block)
B(14,1,2,minecraft:nether_wart_block)
B(15,1,2,minecraft:nether_wart_block)
B(0,1,3,minecraft:nether_wart_block)
B(1,1,3,minecraft:nether_wart_block)
B(2,1,3,minecraft:nether_wart_block)
B(3,1,3,minecraft:nether_wart_block)
B(4,1,3,minecraft:nether_wart_block)
B(5,1,3,minecraft:nether_wart_block)
B(6,1,3,minecraft:nether_wart_block)
B(7,1,3,minecraft:nether_wart_block)
B(8,1,3,minecraft:nether_wart_block)
B(9,1,3,minecraft:nether_wart_block)
B(10,1,3,minecraft:nether_wart_block)
B(11,1,3,minecraft:nether_wart_block)
B(12,1,3,minecraft:nether_wart_block)
B(13,1,3,minecraft:nether_wart_block)
B(14,1,3,minecraft:lava[level=8])
B(15,1,3,minecraft:lava[level=8])
B(0,1,4,minecraft:nether_wart_block)
B(1,1,4,minecraft:nether_wart_block)
B(2,1,4,minecraft:nether_wart_block)
B(3,1,4,minecraft:nether_wart_block)
B(4,1,4,minecraft:nether_wart_block)
B(5,1,4,minecraft:nether_wart_block)
B(6,1,4,minecraft:nether_wart_block)
B(7,1,4,minecraft:nether_wart_block)
B(8,1,4,minecraft:nether_wart_block)
B(9,1,4,minecraft:nether_wart_block)
B(10,1,4,minecraft:nether_wart_block)
B(11,1,4,minecraft:nether_wart_block)
B(14,1,4,minecraft:lava[level=2])
B(0,1,5,minecraft:nether_wart_block)
B(1,1,5,minecraft:nether_wart_block)
B(2,1,5,minecraft:nether_wart_block)
B(3,1,5,minecraft:nether_wart_block)
B(4,1,5,minecraft:nether_wart_block)
B(5,1,5,minecraft:nether_wart_block)
B(6,1,5,minecraft:nether_wart_block)
B(7,1,5,minecraft:nether_wart_block)
B(8,1,5,minecraft:nether_wart_block)
B(9,1,5,minecraft:nether_wart_block)
B(10,1,5,minecraft:nether_wart_block)
B(11,1,5,minecraft:nether_wart_block)
B(0,1,6,minecraft:nether_wart_block)
B(1,1,6,minecraft:nether_wart_block)
B(2,1,6,minecraft:nether_wart_block)
B(3,1,6,minecraft:nether_wart_block)
B(4,1,6,minecraft:nether_wart_block)
B(5,1,6,minecraft:nether_wart_block)
B(6,1,6,minecraft:nether_wart_block)
B(7,1,6,minecraft:nether_wart_block)
B(8,1,6,minecraft:nether_wart_block)
B(9,1,6,minecraft:nether_wart_block)
B(10,1,6,minecraft:nether_wart_block)
B(0,1,7,minecraft:nether_wart_block)
B(1,1,7,minecraft:nether_wart_block)
B(2,1,7,minecraft:nether_wart_block)
B(3,1,7,minecraft:nether_wart_block)
B(4,1,7,minecraft:nether_wart_block)
B(5,1,7,minecraft:nether_wart_block)
B(6,1,7,minecraft:nether_wart_block)
B(7,1,7,minecraft:nether_wart_block)
B(8,1,7,minecraft:nether_wart_block)
B(0,1,8,minecraft:nether_wart_block)
B(1,1,8,minecraft:nether_wart_block)
B(2,1,8,minecraft:nether_wart_block)
B(3,1,8,minecraft:nether_wart_block)
B(4,1,8,minecraft:nether_wart_block)
B(5,1,8,minecraft:nether_wart_block)
B(6,1,8,minecraft:nether_wart_block)
B(7,1,8,minecraft:nether_wart_block)
B(8,1,8,minecraft:nether_wart_block)
B(0,1,9,minecraft:nether_wart_block)
B(1,1,9,minecraft:nether_wart_block)
B(2,1,9,minecraft:nether_wart_block)
B(3,1,9,minecraft:nether_wart_block)
B(4,1,9,minecraft:nether_wart_block)
B(5,1,9,minecraft:nether_wart_block)
B(6,1,9,minecraft:nether_wart_block)
B(7,1,9,minecraft:nether_wart_block)
B(0,1,10,minecraft:nether_wart_block)
B(1,1,10,minecraft:nether_wart_block)
B(2,1,10,minecraft:nether_wart_block)
B(3,1,10,minecraft:nether_wart_block)
B(4,1,10,minecraft:nether_wart_block)
B(5,1,10,minecraft:nether_wart_block)
B(6,1,10,minecraft:nether_wart_block)
B(0,1,11,minecraft:nether_wart_block)
B(1,1,11,minecraft:nether_wart_block)
B(2,1,11,minecraft:nether_wart_block)
B(3,1,11,minecraft:nether_wart_block)
B(4,1,11,minecraft:nether_wart_block)
B(5,1,11,minecraft:nether_wart_block)
B(0,1,12,minecraft:nether_wart_block)
B(1,1,12,minecraft:nether_wart_block)
B(2,1,12,minecraft:nether_wart_block)
B(3,1,12,minecraft:nether_quartz_ore)
B(0,1,13,minecraft:nether_wart_block)
B(1,1,13,minecraft:nether_wart_block)
B(2,1,13,minecraft:nether_wart_block)
B(3,1,13,minecraft:nether_quartz_ore)
B(0,1,14,minecraft:nether_wart_block)
B(1,1,14,minecraft:nether_wart_block)
B(2,1,14,minecraft:nether_wart_block)
B(3,1,14,minecraft:nether_wart_block)
B(4,1,14,minecraft:nether_wart_block)
B(0,1,15,minecraft:nether_wart_block)
B(1,1,15,minecraft:nether_wart_block)
B(2,1,15,minecraft:nether_wart_block)
B(3,1,15,minecraft:nether_wart_block)
B(4,1,15,minecraft:nether_wart_block)
B(0,2,0,minecraft:nether_wart_block)
B(1,2,0,minecraft:nether_wart_block)
B(2,2,0,minecraft:nether_wart_block)
B(3,2,0,minecraft:nether_wart_block)
B(4,2,0,minecraft:nether_wart_block)
B(5,2,0,minecraft:nether_wart_block)
B(6,2,0,minecraft:nether_wart_block)
B(7,2,0,minecraft:nether_wart_block)
B(8,2,0,minecraft:nether_wart_block)
B(9,2,0,minecraft:nether_wart_block)
B(10,2,0,minecraft:nether_wart_block)
B(11,2,0,minecraft:nether_wart_block)
B(12,2,0,minecraft:nether_wart_block)
B(13,2,0,minecraft:nether_wart_block)
B(14,2,0,minecraft:nether_wart_block)
B(15,2,0,minecraft:nether_wart_block)
B(0,2,1,minecraft:nether_wart_block)
B(1,2,1,minecraft:nether_wart_block)
B(2,2,1,minecraft:nether_wart_block)
B(3,2,1,minecraft:nether_wart_block)
B(4,2,1,minecraft:nether_wart_block)
B(5,2,1,minecraft:nether_wart_block)
B(6,2,1,minecraft:nether_wart_block)
B(7,2,1,minecraft:nether_wart_block)
B(8,2,1,minecraft:nether_wart_block)
B(9,2,1,minecraft:nether_wart_block)
B(10,2,1,minecraft:nether_wart_block)
B(11,2,1,minecraft:nether_wart_block)
B(12,2,1,minecraft:nether_wart_block)
B(13,2,1,minecraft:nether_wart_block)
B(14,2,1,minecraft:nether_wart_block)
B(15,2,1,minecraft:nether_wart_block)
B(0,2,2,minecraft:nether_wart_block)
B(1,2,2,minecraft:nether_wart_block)
B(2,2,2,minecraft:nether_wart_block)
B(3,2,2,minecraft:nether_wart_block)
B(4,2,2,minecraft:nether_wart_block)
B(5,2,2,minecraft:nether_wart_block)
B(6,2,2,minecraft:nether_wart_block)
B(7,2,2,minecraft:nether_wart_block)
B(8,2,2,minecraft:nether_wart_block)
B(9,2,2,minecraft:nether_wart_block)
B(10,2,2,minecraft:nether_wart_block)
B(11,2,2,minecraft:nether_wart_block)
B(12,2,2,minecraft:nether_wart_block)
B(13,2,2,minecraft:nether_wart_block)
B(14,2,2,minecraft:nether_wart_block)
B(15,2,2,minecraft:lava[level=8])
B(0,2,3,minecraft:nether_wart_block)
B(1,2,3,minecraft:nether_wart_block)
B(2,2,3,minecraft:nether_wart_block)
B(3,2,3,minecraft:nether_wart_block)
B(4,2,3,minecraft:nether_wart_block)
B(5,2,3,minecraft:nether_wart_block)
B(6,2,3,minecraft:nether_wart_block)
B(7,2,3,minecraft:nether_wart_block)
B(8,2,3,minecraft:nether_wart_block)
B(9,2,3,minecraft:nether_wart_block)
B(10,2,3,minecraft:nether_wart_block)
B(14,2,3,minecraft:lava[level=8])
B(15,2,3,minecraft:lava[level=2])
B(0,2,4,minecraft:nether_wart_block)
B(1,2,4,minecraft:nether_wart_block)
B(2,2,4,minecraft:nether_wart_block)
B(3,2,4,minecraft:nether_wart_block)
B(4,2,4,minecraft:nether_wart_block)
B(5,2,4,minecraft:nether_wart_block)
B(6,2,4,minecraft:nether_wart_block)
B(7,2,4,minecraft:nether_wart_block)
B(8,2,4,minecraft:nether_wart_block)
B(9,2,4,minecraft:nether_wart_block)
B(10,2,4,minecraft:nether_wart_block)
B(0,2,5,minecraft:nether_wart_block)
B(1,2,5,minecraft:nether_wart_block)
B(2,2,5,minecraft:nether_wart_block)
B(3,2,5,minecraft:nether_wart_block)
B(4,2,5,minecraft:nether_wart_block)
B(5,2,5,minecraft:nether_wart_block)
B(6,2,5,minecraft:nether_wart_block)
B(7,2,5,minecraft:nether_wart_block)
B(8,2,5,minecraft:nether_wart_block)
B(9,2,5,minecraft:nether_wart_block)
B(0,2,6,minecraft:nether_wart_block)
B(1,2,6,minecraft:nether_wart_block)
B(2,2,6,minecraft:nether_wart_block)
B(3,2,6,minecraft:nether_wart_block)
B(4,2,6,minecraft:nether_wart_block)
B(5,2,6,minecraft:nether_wart_block)
B(6,2,6,minecraft:nether_wart_block)
B(7,2,6,minecraft:nether_wart_block)
B(8,2,6,minecraft:nether_wart_block)
B(0,2,7,minecraft:nether_wart_block)
B(1,2,7,minecraft:nether_wart_block)
B(2,2,7,minecraft:nether_wart_block)
B(3,2,7,minecraft:nether_wart_block)
B(4,2,7,minecraft:nether_wart_block)
B(5,2,7,minecraft:nether_wart_block)
B(6,2,7,minecraft:nether_wart_block)
B(7,2,7,minecraft:nether_wart_block)
B(8,2,7,minecraft:nether_wart_block)
B(0,2,8,minecraft:nether_wart_block)
B(1,2,8,minecraft:nether_wart_block)
B(2,2,8,minecraft:nether_wart_block)
B(3,2,8,minecraft:nether_wart_block)
B(4,2,8,minecraft:nether_wart_block)
B(5,2,8,minecraft:nether_wart_block)
B(6,2,8,minecraft:nether_wart_block)
B(7,2,8,minecraft:nether_wart_block)
B(8,2,8,minecraft:nether_wart_block)
B(0,2,9,minecraft:nether_wart_block)
B(1,2,9,minecraft:nether_wart_block)
B(2,2,9,minecraft:nether_wart_block)
B(3,2,9,minecraft:nether_wart_block)
B(4,2,9,minecraft:nether_wart_block)
B(5,2,9,minecraft:nether_wart_block)
B(6,2,9,minecraft:nether_wart_block)
B(7,2,9,minecraft:nether_wart_block)
B(0,2,10,minecraft:nether_wart_block)
B(1,2,10,minecraft:nether_wart_block)
B(2,2,10,minecraft:nether_wart_block)
B(3,2,10,minecraft:nether_wart_block)
B(4,2,10,minecraft:nether_wart_block)
B(5,2,10,minecraft:nether_wart_block)
B(6,2,10,minecraft:nether_wart_block)
B(0,2,11,minecraft:nether_wart_block)
B(1,2,11,minecraft:nether_wart_block)
B(2,2,11,minecraft:nether_wart_block)
B(3,2,11,minecraft:nether_wart_block)
B(4,2,11,minecraft:nether_wart_block)
B(5,2,11,minecraft:nether_wart_block)
B(0,2,12,minecraft:nether_wart_block)
B(1,2,12,minecraft:nether_wart_block)
B(2,2,12,minecraft:nether_wart_block)
B(0,2,13,minecraft:nether_wart_block)
B(1,2,13,minecraft:nether_wart_block)
B(2,2,13,minecraft:nether_wart_block)
B(0,2,14,minecraft:nether_wart_block)
B(1,2,14,minecraft:nether_wart_block)
B(2,2,14,minecraft:nether_wart_block)
B(0,2,15,minecraft:nether_wart_block)
B(1,2,15,minecraft:nether_wart_block)
B(0,3,0,minecraft:nether_wart_block)
B(1,3,0,minecraft:nether_wart_block)
B(2,3,0,minecraft:nether_wart_block)
B(3,3,0,minecraft:nether_wart_block)
B(4,3,0,minecraft:nether_wart_block)
B(5,3,0,minecraft:nether_wart_block)
B(6,3,0,minecraft:nether_wart_block)
B(7,3,0,minecraft:nether_wart_block)
B(8,3,0,minecraft:nether_wart_block)
B(9,3,0,minecraft:nether_wart_block)
B(10,3,0,minecraft:nether_wart_block)
B(11,3,0,minecraft:nether_wart_block)
B(12,3,0,minecraft:nether_wart_block)
B(13,3,0,minecraft:nether_wart_block)
B(14,3,0,minecraft:nether_wart_block)
B(15,3,0,minecraft:nether_wart_block)
B(0,3,1,minecraft:nether_wart_block)
B(1,3,1,minecraft:nether_wart_block)
B(2,3,1,minecraft:nether_wart_block)
B(3,3,1,minecraft:nether_wart_block)
B(4,3,1,minecraft:nether_wart_block)
B(5,3,1,minecraft:nether_wart_block)
B(6,3,1,minecraft:nether_wart_block)
B(7,3,1,minecraft:nether_wart_block)
B(8,3,1,minecraft:nether_wart_block)
B(9,3,1,minecraft:nether_wart_block)
B(10,3,1,minecraft:nether_wart_block)
B(11,3,1,minecraft:nether_wart_block)
B(12,3,1,minecraft:nether_wart_block)
B(13,3,1,minecraft:nether_wart_block)
B(14,3,1,minecraft:nether_wart_block)
B(15,3,1,minecraft:lava[level=8])
B(0,3,2,minecraft:nether_wart_block)
B(1,3,2,minecraft:nether_wart_block)
B(2,3,2,minecraft:nether_wart_block)
B(3,3,2,minecraft:nether_wart_block)
B(4,3,2,minecraft:nether_wart_block)
B(5,3,2,minecraft:nether_wart_block)
B(6,3,2,minecraft:nether_wart_block)
B(7,3,2,minecraft:nether_wart_block)
B(8,3,2,minecraft:nether_wart_block)
B(9,3,2,minecraft:nether_wart_block)
B(10,3,2,minecraft:nether_wart_block)
B(11,3,2,minecraft:nether_wart_block)
B(14,3,2,minecraft:lava[level=8])
B(15,3,2,minecraft:lava[level=2])
B(0,3,3,minecraft:nether_wart_block)
B(1,3,3,minecraft:nether_wart_block)
B(2,3,3,minecraft:nether_wart_block)
B(3,3,3,minecraft:nether_wart_block)
B(4,3,3,minecraft:nether_wart_block)
B(5,3,3,minecraft:nether_wart_block)
B(6,3,3,minecraft:nether_wart_block)
B(7,3,3,minecraft:nether_wart_block)
B(8,3,3,minecraft:nether_wart_block)
B(9,3,3,minecraft:nether_wart_block)
B(10,3,3,minecraft:nether_wart_block)
B(14,3,3,minecraft:lava[level=2])
B(0,3,4,minecraft:nether_wart_block)
B(1,3,4,minecraft:nether_wart_block)
B(2,3,4,minecraft:nether_wart_block)
B(3,3,4,minecraft:nether_wart_block)
B(4,3,4,minecraft:nether_wart_block)
B(5,3,4,minecraft:nether_wart_block)
B(6,3,4,minecraft:nether_wart_block)
B(7,3,4,minecraft:nether_wart_block)
B(8,3,4,minecraft:nether_wart_block)
B(9,3,4,minecraft:nether_wart_block)
B(0,3,5,minecraft:nether_wart_block)
B(1,3,5,minecraft:nether_wart_block)
B(2,3,5,minecraft:nether_wart_block)
B(3,3,5,minecraft:nether_wart_block)
B(4,3,5,minecraft:nether_wart_block)
B(5,3,5,minecraft:nether_wart_block)
B(6,3,5,minecraft:nether_wart_block)
B(7,3,5,minecraft:nether_wart_block)
B(8,3,5,minecraft:nether_wart_block)
B(0,3,6,minecraft:nether_wart_block)
B(1,3,6,minecraft:nether_wart_block)
B(2,3,6,minecraft:nether_wart_block)
B(3,3,6,minecraft:nether_wart_block)
B(4,3,6,minecraft:nether_wart_block)
B(5,3,6,minecraft:nether_wart_block)
B(6,3,6,minecraft:nether_wart_block)
B(7,3,6,minecraft:nether_wart_block)
B(8,3,6,minecraft:nether_wart_block)
B(0,3,7,minecraft:nether_wart_block)
B(1,3,7,minecraft:nether_wart_block)
B(2,3,7,minecraft:nether_wart_block)
B(3,3,7,minecraft:nether_wart_block)
B(4,3,7,minecraft:nether_wart_block)
B(5,3,7,minecraft:nether_wart_block)
B(6,3,7,minecraft:nether_wart_block)
B(7,3,7,minecraft:nether_wart_block)
B(8,3,7,minecraft:nether_wart_block)
B(0,3,8,minecraft:nether_wart_block)
B(1,3,8,minecraft:nether_wart_block)
B(2,3,8,minecraft:nether_wart_block)
B(3,3,8,minecraft:nether_wart_block)
B(4,3,8,minecraft:nether_wart_block)
B(5,3,8,minecraft:nether_wart_block)
B(6,3,8,minecraft:nether_wart_block)
B(7,3,8,minecraft:nether_wart_block)
B(0,3,9,minecraft:nether_wart_block)
B(1,3,9,minecraft:nether_wart_block)
B(2,3,9,minecraft:nether_wart_block)
B(3,3,9,minecraft:nether_wart_block)
B(4,3,9,minecraft:nether_wart_block)
B(5,3,9,minecraft:nether_wart_block)
B(6,3,9,minecraft:nether_wart_block)
B(7,3,9,minecraft:nether_wart_block)
B(0,3,10,minecraft:nether_wart_block)
B(1,3,10,minecraft:nether_wart_block)
B(2,3,10,minecraft:nether_wart_block)
B(3,3,10,minecraft:nether_wart_block)
B(4,3,10,minecraft:nether_wart_block)
B(5,3,10,minecraft:nether_wart_block)
B(6,3,10,minecraft:nether_wart_block)
B(0,3,11,minecraft:nether_wart_block)
B(1,3,11,minecraft:nether_wart_block)
B(2,3,11,minecraft:nether_wart_block)
B(3,3,11,minecraft:nether_wart_block)
B(4,3,11,minecraft:nether_wart_block)
B(5,3,11,minecraft:nether_wart_block)
B(0,3,12,minecraft:nether_wart_block)
B(1,3,12,minecraft:nether_wart_block)
B(2,3,12,minecraft:nether_wart_block)
B(0,3,13,minecraft:nether_wart_block)
B(1,3,13,minecraft:nether_wart_block)
B(2,3,13,minecraft:nether_wart_block)
B(0,3,14,minecraft:nether_wart_block)
B(1,3,14,minecraft:nether_wart_block)
B(2,3,14,minecraft:nether_wart_block)
B(0,4,0,minecraft:nether_wart_block)
B(1,4,0,minecraft:nether_wart_block)
B(2,4,0,minecraft:nether_wart_block)
B(3,4,0,minecraft:nether_wart_block)
B(4,4,0,minecraft:nether_wart_block)
B(5,4,0,minecraft:nether_wart_block)
B(6,4,0,minecraft:nether_wart_block)
B(7,4,0,minecraft:nether_wart_block)
B(8,4,0,minecraft:nether_wart_block)
B(9,4,0,minecraft:nether_wart_block)
B(10,4,0,minecraft:nether_wart_block)
B(11,4,0,minecraft:nether_wart_block)
B(12,4,0,minecraft:nether_wart_block)
B(13,4,0,minecraft:nether_wart_block)
B(14,4,0,minecraft:lava[level=8])
B(15,4,0,minecraft:lava[level=2])
B(0,4,1,minecraft:nether_wart_block)
B(1,4,1,minecraft:nether_wart_block)
B(2,4,1,minecraft:nether_wart_block)
B(3,4,1,minecraft:nether_wart_block)
B(4,4,1,minecraft:nether_wart_block)
B(5,4,1,minecraft:nether_wart_block)
B(6,4,1,minecraft:nether_wart_block)
B(7,4,1,minecraft:nether_wart_block)
B(8,4,1,minecraft:nether_wart_block)
B(9,4,1,minecraft:nether_wart_block)
B(10,4,1,minecraft:nether_wart_block)
B(11,4,1,minecraft:nether_wart_block)
B(12,4,1,minecraft:nether_wart_block)
B(14,4,1,minecraft:lava[level=2])
B(15,4,1,minecraft:lava[level=4])
B(0,4,2,minecraft:nether_wart_block)
B(1,4,2,minecraft:nether_wart_block)
B(2,4,2,minecraft:nether_wart_block)
B(3,4,2,minecraft:nether_wart_block)
B(4,4,2,minecraft:nether_wart_block)
B(5,4,2,minecraft:nether_wart_block)
B(6,4,2,minecraft:nether_wart_block)
B(7,4,2,minecraft:nether_wart_block)
B(8,4,2,minecraft:nether_wart_block)
B(9,4,2,minecraft:nether_wart_block)
B(10,4,2,minecraft:nether_wart_block)
B(11,4,2,minecraft:nether_wart_block)
B(14,4,2,minecraft:lava[level=4])
B(0,4,3,minecraft:nether_wart_block)
B(1,4,3,minecraft:nether_wart_block)
B(2,4,3,minecraft:nether_wart_block)
B(3,4,3,minecraft:nether_wart_block)
B(4,4,3,minecraft:nether_wart_block)
B(5,4,3,minecraft:nether_wart_block)
B(6,4,3,minecraft:nether_wart_block)
B(7,4,3,minecraft:nether_wart_block)
B(8,4,3,minecraft:nether_wart_block)
B(9,4,3,minecraft:nether_wart_block)
B(10,4,3,minecraft:nether_wart_block)
B(0,4,4,minecraft:nether_wart_block)
B(1,4,4,minecraft:nether_wart_block)
B(2,4,4,minecraft:nether_wart_block)
B(3,4,4,minecraft:nether_wart_block)
B(4,4,4,minecraft:nether_wart_block)
B(5,4,4,minecraft:nether_wart_block)
B(6,4,4,minecraft:nether_wart_block)
B(7,4,4,minecraft:nether_wart_block)
B(8,4,4,minecraft:nether_wart_block)
B(9,4,4,minecraft:nether_wart_block)
B(0,4,5,minecraft:nether_wart_block)
B(1,4,5,minecraft:nether_wart_block)
B(2,4,5,minecraft:nether_wart_block)
B(3,4,5,minecraft:nether_wart_block)
B(4,4,5,minecraft:nether_wart_block)
B(5,4,5,minecraft:nether_wart_block)
B(6,4,5,minecraft:nether_wart_block)
B(7,4,5,minecraft:nether_wart_block)
B(8,4,5,minecraft:nether_wart_block)
B(0,4,6,minecraft:nether_wart_block)
B(1,4,6,minecraft:nether_wart_block)
B(2,4,6,minecraft:nether_wart_block)
B(3,4,6,minecraft:nether_wart_block)
B(4,4,6,minecraft:nether_wart_block)
B(5,4,6,minecraft:nether_wart_block)
B(6,4,6,minecraft:nether_wart_block)
B(7,4,6,minecraft:nether_wart_block)
B(8,4,6,minecraft:nether_wart_block)
B(0,4,7,minecraft:nether_wart_block)
B(1,4,7,minecraft:nether_wart_block)
B(2,4,7,minecraft:nether_wart_block)
B(3,4,7,minecraft:nether_wart_block)
B(4,4,7,minecraft:nether_wart_block)
B(5,4,7,minecraft:nether_wart_block)
B(6,4,7,minecraft:nether_wart_block)
B(7,4,7,minecraft:nether_wart_block)
B(8,4,7,minecraft:nether_wart_block)
B(0,4,8,minecraft:nether_wart_block)
B(1,4,8,minecraft:nether_wart_block)
B(2,4,8,minecraft:nether_wart_block)
B(3,4,8,minecraft:nether_wart_block)
B(4,4,8,minecraft:nether_wart_block)
B(5,4,8,minecraft:nether_wart_block)
B(6,4,8,minecraft:nether_wart_block)
B(7,4,8,minecraft:nether_wart_block)
B(0,4,9,minecraft:nether_wart_block)
B(1,4,9,minecraft:nether_wart_block)
B(2,4,9,minecraft:nether_wart_block)
B(3,4,9,minecraft:nether_wart_block)
B(4,4,9,minecraft:nether_wart_block)
B(5,4,9,minecraft:nether_wart_block)
B(6,4,9,minecraft:nether_wart_block)
B(7,4,9,minecraft:nether_wart_block)
B(0,4,10,minecraft:nether_wart_block)
B(1,4,10,minecraft:nether_wart_block)
B(2,4,10,minecraft:nether_wart_block)
B(3,4,10,minecraft:nether_wart_block)
B(4,4,10,minecraft:nether_wart_block)
B(5,4,10,minecraft:nether_wart_block)
B(6,4,10,minecraft:nether_wart_block)
B(0,4,11,minecraft:nether_wart_block)
B(1,4,11,minecraft:nether_wart_block)
B(2,4,11,minecraft:nether_wart_block)
B(3,4,11,minecraft:nether_wart_block)
B(4,4,11,minecraft:nether_wart_block)
B(0,4,12,minecraft:nether_wart_block)
B(1,4,12,minecraft:nether_wart_block)
B(2,4,12,minecraft:nether_wart_block)
B(0,4,13,minecraft:nether_wart_block)
B(1,4,13,minecraft:nether_wart_block)
B(2,4,13,minecraft:nether_wart_block)
B(0,5,0,minecraft:nether_wart_block)
B(1,5,0,minecraft:nether_wart_block)
B(2,5,0,minecraft:nether_wart_block)
B(3,5,0,minecraft:nether_wart_block)
B(4,5,0,minecraft:nether_wart_block)
B(5,5,0,minecraft:nether_wart_block)
B(6,5,0,minecraft:nether_wart_block)
B(7,5,0,minecraft:nether_wart_block)
B(8,5,0,minecraft:nether_wart_block)
B(9,5,0,minecraft:nether_wart_block)
B(10,5,0,minecraft:nether_wart_block)
B(11,5,0,minecraft:nether_wart_block)
B(12,5,0,minecraft:nether_wart_block)
B(13,5,0,minecraft:nether_wart_block)
B(14,5,0,minecraft:lava[level=2])
B(0,5,1,minecraft:nether_wart_block)
B(1,5,1,minecraft:nether_wart_block)
B(2,5,1,minecraft:nether_wart_block)
B(3,5,1,minecraft:nether_wart_block)
B(4,5,1,minecraft:nether_wart_block)
B(5,5,1,minecraft:nether_wart_block)
B(6,5,1,minecraft:nether_wart_block)
B(7,5,1,minecraft:nether_wart_block)
B(8,5,1,minecraft:nether_wart_block)
B(9,5,1,minecraft:nether_wart_block)
B(10,5,1,minecraft:nether_wart_block)
B(11,5,1,minecraft:nether_wart_block)
B(12,5,1,minecraft:nether_wart_block)
B(0,5,2,minecraft:nether_wart_block)
B(1,5,2,minecraft:nether_wart_block)
B(2,5,2,minecraft:nether_wart_block)
B(3,5,2,minecraft:nether_wart_block)
B(4,5,2,minecraft:nether_wart_block)
B(5,5,2,minecraft:nether_wart_block)
B(6,5,2,minecraft:nether_wart_block)
B(7,5,2,minecraft:nether_wart_block)
B(8,5,2,minecraft:nether_wart_block)
B(9,5,2,minecraft:nether_wart_block)
B(10,5,2,minecraft:nether_wart_block)
B(11,5,2,minecraft:nether_wart_block)
B(0,5,3,minecraft:nether_wart_block)
B(1,5,3,minecraft:nether_wart_block)
B(2,5,3,minecraft:nether_wart_block)
B(3,5,3,minecraft:nether_wart_block)
B(4,5,3,minecraft:nether_wart_block)
B(5,5,3,minecraft:nether_wart_block)
B(6,5,3,minecraft:nether_wart_block)
B(7,5,3,minecraft:nether_wart_block)
B(8,5,3,minecraft:nether_wart_block)
B(9,5,3,minecraft:nether_wart_block)
B(10,5,3,minecraft:nether_wart_block)
B(0,5,4,minecraft:nether_wart_block)
B(1,5,4,minecraft:nether_wart_block)
B(2,5,4,minecraft:nether_wart_block)
B(3,5,4,minecraft:nether_wart_block)
B(4,5,4,minecraft:nether_wart_block)
B(5,5,4,minecraft:nether_wart_block)
B(6,5,4,minecraft:nether_wart_block)
B(7,5,4,minecraft:nether_wart_block)
B(8,5,4,minecraft:nether_wart_block)
B(9,5,4,minecraft:nether_wart_block)
B(0,5,5,minecraft:nether_wart_block)
B(1,5,5,minecraft:nether_wart_block)
B(2,5,5,minecraft:nether_wart_block)
B(3,5,5,minecraft:nether_wart_block)
B(4,5,5,minecraft:nether_wart_block)
B(5,5,5,minecraft:nether_wart_block)
B(6,5,5,minecraft:nether_wart_block)
B(7,5,5,minecraft:nether_wart_block)
B(8,5,5,minecraft:nether_wart_block)
B(0,5,6,minecraft:nether_wart_block)
B(1,5,6,minecraft:nether_wart_block)
B(2,5,6,minecraft:nether_wart_block)
B(3,5,6,minecraft:nether_wart_block)
B(4,5,6,minecraft:nether_wart_block)
B(5,5,6,minecraft:nether_wart_block)
B(6,5,6,minecraft:nether_wart_block)
B(7,5,6,minecraft:nether_wart_block)
B(8,5,6,minecraft:nether_wart_block)
B(0,5,7,minecraft:nether_wart_block)
B(1,5,7,minecraft:nether_wart_block)
B(2,5,7,minecraft:nether_wart_block)
B(3,5,7,minecraft:nether_wart_block)
B(4,5,7,minecraft:nether_wart_block)
B(5,5,7,minecraft:nether_wart_block)
B(6,5,7,minecraft:nether_wart_block)
B(7,5,7,minecraft:nether_wart_block)
B(8,5,7,minecraft:nether_wart_block)
B(0,5,8,minecraft:nether_wart_block)
B(1,5,8,minecraft:nether_wart_block)
B(2,5,8,minecraft:nether_wart_block)
B(3,5,8,minecraft:nether_wart_block)
B(4,5,8,minecraft:nether_wart_block)
B(5,5,8,minecraft:nether_wart_block)
B(6,5,8,minecraft:nether_wart_block)
B(7,5,8,minecraft:nether_wart_block)
B(0,5,9,minecraft:nether_wart_block)
B(1,5,9,minecraft:nether_wart_block)
B(2,5,9,minecraft:nether_wart_block)
B(3,5,9,minecraft:nether_wart_block)
B(4,5,9,minecraft:nether_wart_block)
B(5,5,9,minecraft:nether_wart_block)
B(6,5,9,minecraft:nether_wart_block)
B(7,5,9,minecraft:nether_wart_block)
B(0,5,10,minecraft:nether_wart_block)
B(1,5,10,minecraft:nether_wart_block)
B(2,5,10,minecraft:nether_wart_block)
B(3,5,10,minecraft:nether_wart_block)
B(4,5,10,minecraft:nether_wart_block)
B(5,5,10,minecraft:nether_wart_block)
B(6,5,10,minecraft:nether_wart_block)
B(0,5,11,minecraft:nether_wart_block)
B(1,5,11,minecraft:nether_wart_block)
B(2,5,11,minecraft:nether_wart_block)
B(3,5,11,minecraft:nether_wart_block)
B(4,5,11,minecraft:nether_wart_block)
B(0,5,12,minecraft:nether_wart_block)
B(1,5,12,minecraft:nether_wart_block)
B(2,5,12,minecraft:nether_wart_block)
B(0,5,13,minecraft:nether_wart_block)
B(0,6,0,minecraft:nether_wart_block)
B(1,6,0,minecraft:nether_wart_block)
B(2,6,0,minecraft:nether_wart_block)
B(3,6,0,minecraft:nether_wart_block)
B(4,6,0,minecraft:nether_wart_block)
B(5,6,0,minecraft:nether_wart_block)
B(6,6,0,minecraft:nether_wart_block)
B(7,6,0,minecraft:nether_wart_block)
B(8,6,0,minecraft:nether_wart_block)
B(9,6,0,minecraft:nether_wart_block)
B(10,6,0,minecraft:nether_wart_block)
B(11,6,0,minecraft:nether_wart_block)
B(12,6,0,minecraft:nether_wart_block)
B(13,6,0,minecraft:nether_wart_block)
B(0,6,1,minecraft:nether_wart_block)
B(1,6,1,minecraft:nether_wart_block)
B(2,6,1,minecraft:nether_wart_block)
B(3,6,1,minecraft:nether_wart_block)
B(4,6,1,minecraft:nether_wart_block)
B(5,6,1,minecraft:nether_wart_block)
B(6,6,1,minecraft:nether_wart_block)
B(7,6,1,minecraft:nether_wart_block)
B(8,6,1,minecraft:nether_wart_block)
B(9,6,1,minecraft:nether_wart_block)
B(10,6,1,minecraft:nether_wart_block)
B(11,6,1,minecraft:nether_wart_block)
B(12,6,1,minecraft:nether_wart_block)
B(0,6,2,minecraft:nether_wart_block)
B(1,6,2,minecraft:nether_wart_block)
B(2,6,2,minecraft:nether_wart_block)
B(3,6,2,minecraft:nether_wart_block)
B(4,6,2,minecraft:nether_wart_block)
B(5,6,2,minecraft:nether_wart_block)
B(6,6,2,minecraft:nether_wart_block)
B(7,6,2,minecraft:nether_wart_block)
B(8,6,2,minecraft:nether_wart_block)
B(9,6,2,minecraft:nether_wart_block)
B(10,6,2,minecraft:nether_wart_block)
B(11,6,2,minecraft:nether_wart_block)
B(0,6,3,minecraft:nether_wart_block)
B(1,6,3,minecraft:nether_wart_block)
B(2,6,3,minecraft:nether_wart_block)
B(3,6,3,minecraft:nether_wart_block)
B(4,6,3,minecraft:nether_wart_block)
B(5,6,3,minecraft:nether_wart_block)
B(6,6,3,minecraft:nether_wart_block)
B(7,6,3,minecraft:nether_wart_block)
B(8,6,3,minecraft:nether_wart_block)
B(9,6,3,minecraft:nether_wart_block)
B(10,6,3,minecraft:nether_wart_block)
B(0,6,4,minecraft:nether_wart_block)
B(1,6,4,minecraft:nether_wart_block)
B(2,6,4,minecraft:nether_wart_block)
B(3,6,4,minecraft:nether_wart_block)
B(4,6,4,minecraft:nether_wart_block)
B(5,6,4,minecraft:nether_wart_block)
B(6,6,4,minecraft:nether_wart_block)
B(7,6,4,minecraft:nether_wart_block)
B(8,6,4,minecraft:nether_wart_block)
B(9,6,4,minecraft:nether_wart_block)
B(0,6,5,minecraft:nether_wart_block)
B(1,6,5,minecraft:nether_wart_block)
B(2,6,5,minecraft:nether_wart_block)
B(3,6,5,minecraft:nether_wart_block)
B(4,6,5,minecraft:nether_wart_block)
B(5,6,5,minecraft:nether_wart_block)
B(6,6,5,minecraft:nether_wart_block)
B(7,6,5,minecraft:nether_wart_block)
B(8,6,5,minecraft:nether_wart_block)
B(0,6,6,minecraft:nether_wart_block)
B(1,6,6,minecraft:nether_wart_block)
B(2,6,6,minecraft:nether_wart_block)
B(3,6,6,minecraft:nether_wart_block)
B(4,6,6,minecraft:nether_wart_block)
B(5,6,6,minecraft:nether_wart_block)
B(6,6,6,minecraft:nether_wart_block)
B(7,6,6,minecraft:nether_wart_block)
B(8,6,6,minecraft:nether_wart_block)
B(0,6,7,minecraft:nether_wart_block)
B(1,6,7,minecraft:nether_wart_block)
B(2,6,7,minecraft:nether_wart_block)
B(3,6,7,minecraft:nether_wart_block)
B(4,6,7,minecraft:nether_wart_block)
B(5,6,7,minecraft:nether_wart_block)
B(6,6,7,minecraft:nether_wart_block)
B(7,6,7,minecraft:nether_wart_block)
B(0,6,8,minecraft:nether_wart_block)
B(1,6,8,minecraft:nether_wart_block)
B(2,6,8,minecraft:nether_wart_block)
B(3,6,8,minecraft:nether_wart_block)
B(4,6,8,minecraft:nether_wart_block)
B(5,6,8,minecraft:nether_wart_block)
B(6,6,8,minecraft:nether_wart_block)
B(7,6,8,minecraft:nether_wart_block)
B(0,6,9,minecraft:nether_wart_block)
B(1,6,9,minecraft:nether_wart_block)
B(2,6,9,minecraft:nether_wart_block)
B(3,6,9,minecraft:nether_wart_block)
B(4,6,9,minecraft:nether_wart_block)
B(5,6,9,minecraft:nether_wart_block)
B(6,6,9,minecraft:nether_wart_block)
B(0,6,10,minecraft:nether_wart_block)
B(1,6,10,minecraft:nether_wart_block)
B(2,6,10,minecraft:nether_wart_block)
B(3,6,10,minecraft:nether_wart_block)
B(4,6,10,minecraft:nether_wart_block)
B(5,6,10,minecraft:nether_wart_block)
B(0,6,11,minecraft:nether_wart_block)
B(1,6,11,minecraft:nether_wart_block)
B(2,6,11,minecraft:nether_wart_block)
B(3,6,11,minecraft:nether_wart_block)
B(0,6,12,minecraft:nether_wart_block)
B(1,6,12,minecraft:nether_wart_block)
B(2,6,12,minecraft:nether_wart_block)
B(0,7,0,minecraft:nether_wart_block)
B(1,7,0,minecraft:nether_wart_block)
B(2,7,0,minecraft:nether_wart_block)
B(3,7,0,minecraft:nether_wart_block)
B(4,7,0,minecraft:nether_wart_block)
B(5,7,0,minecraft:nether_wart_block)
B(6,7,0,minecraft:nether_wart_block)
B(7,7,0,minecraft:nether_wart_block)
B(8,7,0,minecraft:nether_wart_block)
B(9,7,0,minecraft:nether_wart_block)
B(10,7,0,minecraft:nether_wart_block)
B(11,7,0,minecraft:nether_wart_block)
B(12,7,0,minecraft:nether_wart_block)
B(13,7,0,minecraft:nether_wart_block)
B(0,7,1,minecraft:nether_wart_block)
B(1,7,1,minecraft:nether_wart_block)
B(2,7,1,minecraft:nether_wart_block)
B(3,7,1,minecraft:nether_wart_block)
B(4,7,1,minecraft:nether_wart_block)
B(5,7,1,minecraft:nether_wart_block)
B(6,7,1,minecraft:nether_wart_block)
B(7,7,1,minecraft:nether_wart_block)
B(8,7,1,minecraft:nether_wart_block)
B(9,7,1,minecraft:nether_wart_block)
B(10,7,1,minecraft:nether_wart_block)
B(11,7,1,minecraft:nether_wart_block)
B(12,7,1,minecraft:nether_wart_block)
B(0,7,2,minecraft:nether_wart_block)
B(1,7,2,minecraft:nether_wart_block)
B(2,7,2,minecraft:nether_wart_block)
B(3,7,2,minecraft:nether_wart_block)
B(4,7,2,minecraft:nether_wart_block)
B(5,7,2,minecraft:nether_wart_block)
B(6,7,2,minecraft:nether_wart_block)
B(7,7,2,minecraft:nether_wart_block)
B(8,7,2,minecraft:nether_wart_block)
B(9,7,2,minecraft:nether_wart_block)
B(10,7,2,minecraft:nether_wart_block)
B(11,7,2,minecraft:nether_wart_block)
B(0,7,3,minecraft:nether_wart_block)
B(1,7,3,minecraft:nether_wart_block)
B(2,7,3,minecraft:nether_wart_block)
B(3,7,3,minecraft:nether_wart_block)
B(4,7,3,minecraft:nether_wart_block)
B(5,7,3,minecraft:nether_wart_block)
B(6,7,3,minecraft:nether_wart_block)
B(7,7,3,minecraft:nether_wart_block)
B(8,7,3,minecraft:nether_wart_block)
B(9,7,3,minecraft:nether_wart_block)
B(10,7,3,minecraft:nether_wart_block)
B(0,7,4,minecraft:nether_wart_block)
B(1,7,4,minecraft:nether_wart_block)
B(2,7,4,minecraft:nether_wart_block)
B(3,7,4,minecraft:nether_wart_block)
B(4,7,4,minecraft:nether_wart_block)
B(5,7,4,minecraft:nether_wart_block)
B(6,7,4,minecraft:nether_wart_block)
B(7,7,4,minecraft:nether_wart_block)
B(8,7,4,minecraft:nether_wart_block)
B(9,7,4,minecraft:nether_wart_block)
B(0,7,5,minecraft:nether_wart_block)
B(1,7,5,minecraft:nether_wart_block)
B(2,7,5,minecraft:nether_wart_block)
B(3,7,5,minecraft:nether_wart_block)
B(4,7,5,minecraft:nether_wart_block)
B(5,7,5,minecraft:nether_wart_block)
B(6,7,5,minecraft:nether_wart_block)
B(7,7,5,minecraft:nether_wart_block)
B(8,7,5,minecraft:nether_wart_block)
B(0,7,6,minecraft:nether_wart_block)
B(1,7,6,minecraft:nether_wart_block)
B(2,7,6,minecraft:nether_wart_block)
B(3,7,6,minecraft:nether_wart_block)
B(4,7,6,minecraft:nether_wart_block)
B(5,7,6,minecraft:nether_wart_block)
B(6,7,6,minecraft:nether_wart_block)
B(7,7,6,minecraft:nether_wart_block)
B(0,7,7,minecraft:nether_wart_block)
B(1,7,7,minecraft:nether_wart_block)
B(2,7,7,minecraft:nether_wart_block)
B(3,7,7,minecraft:nether_wart_block)
B(4,7,7,minecraft:nether_wart_block)
B(5,7,7,minecraft:nether_wart_block)
B(6,7,7,minecraft:nether_wart_block)
B(7,7,7,minecraft:nether_wart_block)
B(0,7,8,minecraft:nether_wart_block)
B(1,7,8,minecraft:nether_wart_block)
B(2,7,8,minecraft:nether_wart_block)
B(3,7,8,minecraft:nether_wart_block)
B(4,7,8,minecraft:nether_wart_block)
B(5,7,8,minecraft:nether_wart_block)
B(6,7,8,minecraft:nether_wart_block)
B(7,7,8,minecraft:nether_wart_block)
B(0,7,9,minecraft:nether_wart_block)
B(1,7,9,minecraft:nether_wart_block)
B(2,7,9,minecraft:nether_wart_block)
B(3,7,9,minecraft:nether_wart_block)
B(4,7,9,minecraft:nether_wart_block)
B(5,7,9,minecraft:nether_wart_block)
B(6,7,9,minecraft:nether_wart_block)
B(0,7,10,minecraft:nether_wart_block)
B(1,7,10,minecraft:nether_wart_block)
B(2,7,10,minecraft:nether_wart_block)
B(3,7,10,minecraft:nether_wart_block)
B(4,7,10,minecraft:nether_wart_block)
B(5,7,10,minecraft:nether_wart_block)
B(0,7,11,minecraft:nether_wart_block)
B(1,7,11,minecraft:nether_wart_block)
B(2,7,11,minecraft:nether_wart_block)
B(3,7,11,minecraft:nether_wart_block)
B(0,7,12,minecraft:nether_wart_block)
B(1,7,12,minecraft:nether_wart_block)
B(2,7,12,minecraft:nether_wart_block)
B(0,8,0,minecraft:nether_wart_block)
B(1,8,0,minecraft:nether_wart_block)
B(2,8,0,minecraft:nether_wart_block)
B(3,8,0,minecraft:nether_wart_block)
B(4,8,0,minecraft:nether_wart_block)
B(5,8,0,minecraft:nether_wart_block)
B(6,8,0,minecraft:nether_wart_block)
B(7,8,0,minecraft:nether_wart_block)
B(8,8,0,minecraft:nether_wart_block)
B(9,8,0,minecraft:nether_wart_block)
B(10,8,0,minecraft:nether_wart_block)
B(11,8,0,minecraft:nether_wart_block)
B(12,8,0,minecraft:nether_wart_block)
B(13,8,0,minecraft:nether_wart_block)
B(0,8,1,minecraft:nether_wart_block)
B(1,8,1,minecraft:nether_wart_block)
B(2,8,1,minecraft:nether_wart_block)
B(3,8,1,minecraft:nether_wart_block)
B(4,8,1,minecraft:nether_wart_block)
B(5,8,1,minecraft:nether_wart_block)
B(6,8,1,minecraft:nether_wart_block)
B(7,8,1,minecraft:nether_wart_block)
B(8,8,1,minecraft:nether_wart_block)
B(9,8,1,minecraft:nether_wart_block)
B(10,8,1,minecraft:nether_wart_block)
B(11,8,1,minecraft:nether_wart_block)
B(12,8,1,minecraft:nether_wart_block)
B(0,8,2,minecraft:nether_wart_block)
B(1,8,2,minecraft:nether_wart_block)
B(2,8,2,minecraft:nether_wart_block)
B(3,8,2,minecraft:nether_wart_block)
B(4,8,2,minecraft:nether_wart_block)
B(5,8,2,minecraft:nether_wart_block)
B(6,8,2,minecraft:nether_wart_block)
B(7,8,2,minecraft:nether_wart_block)
B(8,8,2,minecraft:nether_wart_block)
B(9,8,2,minecraft:nether_wart_block)
B(10,8,2,minecraft:nether_wart_block)
B(11,8,2,minecraft:nether_wart_block)
B(0,8,3,minecraft:nether_wart_block)
B(1,8,3,minecraft:nether_wart_block)
B(2,8,3,minecraft:nether_wart_block)
B(3,8,3,minecraft:nether_wart_block)
B(4,8,3,minecraft:nether_wart_block)
B(5,8,3,minecraft:nether_wart_block)
B(6,8,3,minecraft:nether_wart_block)
B(7,8,3,minecraft:nether_wart_block)
B(8,8,3,minecraft:nether_wart_block)
B(9,8,3,minecraft:nether_wart_block)
B(10,8,3,minecraft:nether_wart_block)
B(0,8,4,minecraft:nether_wart_block)
B(1,8,4,minecraft:nether_wart_block)
B(2,8,4,minecraft:nether_wart_block)
B(3,8,4,minecraft:nether_wart_block)
B(4,8,4,minecraft:nether_wart_block)
B(5,8,4,minecraft:nether_wart_block)
B(6,8,4,minecraft:nether_wart_block)
B(7,8,4,minecraft:nether_wart_block)
B(8,8,4,minecraft:nether_wart_block)
B(9,8,4,minecraft:nether_wart_block)
B(0,8,5,minecraft:nether_wart_block)
B(1,8,5,minecraft:nether_wart_block)
B(2,8,5,minecraft:nether_wart_block)
B(3,8,5,minecraft:nether_wart_block)
B(4,8,5,minecraft:nether_wart_block)
B(5,8,5,minecraft:nether_wart_block)
B(6,8,5,minecraft:nether_wart_block)
B(7,8,5,minecraft:nether_wart_block)
B(8,8,5,minecraft:nether_wart_block)
B(0,8,6,minecraft:nether_wart_block)
B(1,8,6,minecraft:nether_wart_block)
B(2,8,6,minecraft:nether_wart_block)
B(3,8,6,minecraft:nether_wart_block)
B(4,8,6,minecraft:nether_wart_block)
B(5,8,6,minecraft:nether_wart_block)
B(6,8,6,minecraft:nether_wart_block)
B(7,8,6,minecraft:nether_wart_block)
B(0,8,7,minecraft:nether_wart_block)
B(1,8,7,minecraft:nether_wart_block)
B(2,8,7,minecraft:nether_wart_block)
B(3,8,7,minecraft:nether_wart_block)
B(4,8,7,minecraft:nether_wart_block)
B(5,8,7,minecraft:nether_wart_block)
B(6,8,7,minecraft:nether_wart_block)
B(0,8,8,minecraft:nether_wart_block)
B(1,8,8,minecraft:nether_wart_block)
B(2,8,8,minecraft:nether_wart_block)
B(3,8,8,minecraft:nether_wart_block)
B(4,8,8,minecraft:nether_wart_block)
B(5,8,8,minecraft:nether_wart_block)
B(6,8,8,minecraft:nether_wart_block)
B(0,8,9,minecraft:nether_wart_block)
B(1,8,9,minecraft:nether_wart_block)
B(2,8,9,minecraft:nether_wart_block)
B(3,8,9,minecraft:nether_wart_block)
B(4,8,9,minecraft:nether_wart_block)
B(5,8,9,minecraft:nether_wart_block)
B(0,8,10,minecraft:nether_wart_block)
B(1,8,10,minecraft:nether_wart_block)
B(2,8,10,minecraft:nether_wart_block)
B(3,8,10,minecraft:nether_wart_block)
B(4,8,10,minecraft:nether_wart_block)
B(0,8,11,minecraft:nether_wart_block)
B(1,8,11,minecraft:nether_wart_block)
B(2,8,11,minecraft:nether_wart_block)
B(3,8,11,minecraft:nether_wart_block)
B(0,9,0,minecraft:nether_wart_block)
B(1,9,0,minecraft:nether_wart_block)
B(2,9,0,minecraft:nether_wart_block)
B(3,9,0,minecraft:nether_wart_block)
B(4,9,0,minecraft:nether_wart_block)
B(5,9,0,minecraft:nether_wart_block)
B(6,9,0,minecraft:nether_wart_block)
B(7,9,0,minecraft:nether_wart_block)
B(8,9,0,minecraft:nether_wart_block)
B(9,9,0,minecraft:nether_wart_block)
B(10,9,0,minecraft:nether_wart_block)
B(11,9,0,minecraft:nether_wart_block)
B(12,9,0,minecraft:nether_wart_block)
B(0,9,1,minecraft:nether_wart_block)
B(1,9,1,minecraft:nether_wart_block)
B(2,9,1,minecraft:nether_wart_block)
B(3,9,1,minecraft:nether_wart_block)
B(4,9,1,minecraft:nether_wart_block)
B(5,9,1,minecraft:nether_wart_block)
B(6,9,1,minecraft:nether_wart_block)
B(7,9,1,minecraft:nether_wart_block)
B(8,9,1,minecraft:nether_wart_block)
B(9,9,1,minecraft:nether_wart_block)
B(10,9,1,minecraft:nether_wart_block)
B(11,9,1,minecraft:nether_wart_block)
B(12,9,1,minecraft:nether_wart_block)
B(0,9,2,minecraft:nether_wart_block)
B(1,9,2,minecraft:nether_wart_block)
B(2,9,2,minecraft:nether_wart_block)
B(3,9,2,minecraft:nether_wart_block)
B(4,9,2,minecraft:nether_wart_block)
B(5,9,2,minecraft:nether_wart_block)
B(6,9,2,minecraft:nether_wart_block)
B(7,9,2,minecraft:nether_wart_block)
B(8,9,2,minecraft:nether_wart_block)
B(9,9,2,minecraft:nether_wart_block)
B(10,9,2,minecraft:nether_wart_block)
B(11,9,2,minecraft:nether_wart_block)
B(0,9,3,minecraft:nether_wart_block)
B(1,9,3,minecraft:nether_wart_block)
B(2,9,3,minecraft:nether_wart_block)
B(3,9,3,minecraft:nether_wart_block)
B(4,9,3,minecraft:nether_wart_block)
B(5,9,3,minecraft:nether_wart_block)
B(6,9,3,minecraft:nether_wart_block)
B(7,9,3,minecraft:nether_wart_block)
B(8,9,3,minecraft:nether_wart_block)
B(9,9,3,minecraft:nether_wart_block)
B(10,9,3,minecraft:nether_wart_block)
B(0,9,4,minecraft:nether_wart_block)
B(1,9,4,minecraft:nether_wart_block)
B(2,9,4,minecraft:nether_wart_block)
B(3,9,4,minecraft:nether_wart_block)
B(4,9,4,minecraft:nether_wart_block)
B(5,9,4,minecraft:nether_wart_block)
B(6,9,4,minecraft:nether_wart_block)
B(7,9,4,minecraft:nether_wart_block)
B(8,9,4,minecraft:nether_wart_block)
B(9,9,4,minecraft:nether_wart_block)
B(0,9,5,minecraft:nether_wart_block)
B(1,9,5,minecraft:nether_wart_block)
B(2,9,5,minecraft:nether_wart_block)
B(3,9,5,minecraft:nether_wart_block)
B(4,9,5,minecraft:nether_wart_block)
B(5,9,5,minecraft:nether_wart_block)
B(6,9,5,minecraft:nether_wart_block)
B(7,9,5,minecraft:nether_wart_block)
B(8,9,5,minecraft:nether_wart_block)
B(0,9,6,minecraft:nether_wart_block)
B(1,9,6,minecraft:nether_wart_block)
B(2,9,6,minecraft:nether_wart_block)
B(3,9,6,minecraft:nether_wart_block)
B(4,9,6,minecraft:nether_wart_block)
B(5,9,6,minecraft:nether_wart_block)
B(6,9,6,minecraft:nether_wart_block)
B(0,9,7,minecraft:nether_wart_block)
B(1,9,7,minecraft:nether_wart_block)
B(2,9,7,minecraft:nether_wart_block)
B(3,9,7,minecraft:nether_wart_block)
B(4,9,7,minecraft:nether_wart_block)
B(5,9,7,minecraft:nether_wart_block)
B(6,9,7,minecraft:nether_wart_block)
B(0,9,8,minecraft:nether_wart_block)
B(1,9,8,minecraft:nether_wart_block)
B(2,9,8,minecraft:nether_wart_block)
B(3,9,8,minecraft:nether_wart_block)
B(4,9,8,minecraft:nether_wart_block)
B(5,9,8,minecraft:nether_wart_block)
B(6,9,8,minecraft:nether_wart_block)
B(0,9,9,minecraft:nether_wart_block)
B(1,9,9,minecraft:nether_wart_block)
B(2,9,9,minecraft:nether_wart_block)
B(3,9,9,minecraft:nether_wart_block)
B(4,9,9,minecraft:nether_wart_block)
B(5,9,9,minecraft:nether_wart_block)
B(0,9,10,minecraft:nether_wart_block)
B(1,9,10,minecraft:nether_wart_block)
B(2,9,10,minecraft:nether_wart_block)
B(3,9,10,minecraft:nether_wart_block)
B(4,9,10,minecraft:nether_wart_block)
B(0,9,11,minecraft:nether_wart_block)
B(1,9,11,minecraft:nether_wart_block)
B(2,9,11,minecraft:nether_wart_block)
B(3,9,11,minecraft:nether_wart_block)
B(0,10,0,minecraft:nether_wart_block)
B(1,10,0,minecraft:nether_wart_block)
B(2,10,0,minecraft:nether_wart_block)
B(3,10,0,minecraft:nether_wart_block)
B(4,10,0,minecraft:nether_wart_block)
B(5,10,0,minecraft:nether_wart_block)
B(6,10,0,minecraft:nether_wart_block)
B(7,10,0,minecraft:nether_wart_block)
B(8,10,0,minecraft:nether_wart_block)
B(9,10,0,minecraft:nether_wart_block)
B(10,10,0,minecraft:nether_wart_block)
B(11,10,0,minecraft:nether_wart_block)
B(12,10,0,minecraft:nether_wart_block)
B(0,10,1,minecraft:nether_wart_block)
B(1,10,1,minecraft:nether_wart_block)
B(2,10,1,minecraft:nether_wart_block)
B(3,10,1,minecraft:nether_wart_block)
B(4,10,1,minecraft:nether_wart_block)
B(5,10,1,minecraft:nether_wart_block)
B(6,10,1,minecraft:nether_wart_block)
B(7,10,1,minecraft:nether_wart_block)
B(8,10,1,minecraft:nether_wart_block)
B(9,10,1,minecraft:nether_wart_block)
B(10,10,1,minecraft:nether_wart_block)
B(11,10,1,minecraft:nether_wart_block)
B(12,10,1,minecraft:nether_wart_block)
B(0,10,2,minecraft:nether_wart_block)
B(1,10,2,minecraft:nether_wart_block)
B(2,10,2,minecraft:nether_wart_block)
B(3,10,2,minecraft:nether_wart_block)
B(4,10,2,minecraft:nether_wart_block)
B(5,10,2,minecraft:nether_wart_block)
B(6,10,2,minecraft:nether_wart_block)
B(7,10,2,minecraft:nether_wart_block)
B(8,10,2,minecraft:nether_wart_block)
B(9,10,2,minecraft:nether_wart_block)
B(10,10,2,minecraft:nether_wart_block)
B(11,10,2,minecraft:nether_wart_block)
B(0,10,3,minecraft:nether_wart_block)
B(1,10,3,minecraft:nether_wart_block)
B(2,10,3,minecraft:nether_wart_block)
B(3,10,3,minecraft:nether_wart_block)
B(4,10,3,minecraft:nether_wart_block)
B(5,10,3,minecraft:nether_wart_block)
B(6,10,3,minecraft:nether_wart_block)
B(7,10,3,minecraft:nether_wart_block)
B(8,10,3,minecraft:nether_wart_block)
B(9,10,3,minecraft:nether_wart_block)
B(10,10,3,minecraft:nether_wart_block)
B(0,10,4,minecraft:nether_wart_block)
B(1,10,4,minecraft:nether_wart_block)
B(2,10,4,minecraft:nether_wart_block)
B(3,10,4,minecraft:nether_wart_block)
B(4,10,4,minecraft:nether_wart_block)
B(5,10,4,minecraft:nether_wart_block)
B(6,10,4,minecraft:nether_wart_block)
B(7,10,4,minecraft:nether_wart_block)
B(8,10,4,minecraft:nether_wart_block)
B(9,10,4,minecraft:nether_wart_block)
B(0,10,5,minecraft:nether_wart_block)
B(1,10,5,minecraft:nether_wart_block)
B(2,10,5,minecraft:nether_wart_block)
B(3,10,5,minecraft:nether_wart_block)
B(4,10,5,minecraft:nether_wart_block)
B(5,10,5,minecraft:nether_wart_block)
B(6,10,5,minecraft:nether_wart_block)
B(7,10,5,minecraft:nether_wart_block)
B(8,10,5,minecraft:nether_wart_block)
B(0,10,6,minecraft:nether_wart_block)
B(1,10,6,minecraft:nether_wart_block)
B(2,10,6,minecraft:nether_wart_block)
B(3,10,6,minecraft:nether_wart_block)
B(4,10,6,minecraft:nether_wart_block)
B(5,10,6,minecraft:nether_wart_block)
B(6,10,6,minecraft:nether_wart_block)
B(0,10,7,minecraft:nether_wart_block)
B(1,10,7,minecraft:nether_wart_block)
B(2,10,7,minecraft:nether_wart_block)
B(3,10,7,minecraft:nether_wart_block)
B(4,10,7,minecraft:nether_wart_block)
B(5,10,7,minecraft:nether_wart_block)
B(6,10,7,minecraft:nether_wart_block)
B(0,10,8,minecraft:nether_wart_block)
B(1,10,8,minecraft:nether_wart_block)
B(2,10,8,minecraft:nether_wart_block)
B(3,10,8,minecraft:nether_wart_block)
B(4,10,8,minecraft:nether_wart_block)
B(5,10,8,minecraft:nether_wart_block)
B(6,10,8,minecraft:nether_wart_block)
B(0,10,9,minecraft:nether_wart_block)
B(1,10,9,minecraft:nether_wart_block)
B(2,10,9,minecraft:nether_wart_block)
B(3,10,9,minecraft:nether_wart_block)
B(4,10,9,minecraft:nether_wart_block)
B(5,10,9,minecraft:nether_wart_block)
B(0,10,10,minecraft:nether_wart_block)
B(1,10,10,minecraft:nether_wart_block)
B(2,10,10,minecraft:nether_wart_block)
B(3,10,10,minecraft:nether_wart_block)
B(4,10,10,minecraft:nether_wart_block)
B(0,10,11,minecraft:nether_wart_block)
B(1,10,11,minecraft:nether_wart_block)
B(2,10,11,minecraft:nether_wart_block)
B(0,11,0,minecraft:nether_wart_block)
B(1,11,0,minecraft:nether_wart_block)
B(2,11,0,minecraft:nether_wart_block)
B(3,11,0,minecraft:nether_wart_block)
B(4,11,0,minecraft:nether_wart_block)
B(5,11,0,minecraft:nether_wart_block)
B(6,11,0,minecraft:nether_wart_block)
B(7,11,0,minecraft:nether_wart_block)
B(8,11,0,minecraft:nether_wart_block)
B(9,11,0,minecraft:nether_wart_block)
B(10,11,0,minecraft:nether_wart_block)
B(11,11,0,minecraft:nether_wart_block)
B(12,11,0,minecraft:nether_wart_block)
B(0,11,1,minecraft:nether_wart_block)
B(1,11,1,minecraft:nether_wart_block)
B(2,11,1,minecraft:nether_wart_block)
B(3,11,1,minecraft:nether_wart_block)
B(4,11,1,minecraft:nether_wart_block)
B(5,11,1,minecraft:nether_wart_block)
B(6,11,1,minecraft:nether_wart_block)
B(7,11,1,minecraft:nether_wart_block)
B(8,11,1,minecraft:nether_wart_block)
B(9,11,1,minecraft:nether_wart_block)
B(10,11,1,minecraft:nether_wart_block)
B(11,11,1,minecraft:nether_wart_block)
B(12,11,1,minecraft:nether_wart_block)
B(0,11,2,minecraft:nether_wart_block)
B(1,11,2,minecraft:nether_wart_block)
B(2,11,2,minecraft:nether_wart_block)
B(3,11,2,minecraft:nether_wart_block)
B(4,11,2,minecraft:nether_wart_block)
B(5,11,2,minecraft:nether_wart_block)
B(6,11,2,minecraft:nether_wart_block)
B(7,11,2,minecraft:nether_wart_block)
B(8,11,2,minecraft:nether_wart_block)
B(9,11,2,minecraft:nether_wart_block)
B(10,11,2,minecraft:nether_wart_block)
B(11,11,2,minecraft:nether_wart_block)
B(0,11,3,minecraft:nether_wart_block)
B(1,11,3,minecraft:nether_wart_block)
B(2,11,3,minecraft:nether_wart_block)
B(3,11,3,minecraft:nether_wart_block)
B(4,11,3,minecraft:nether_wart_block)
B(5,11,3,minecraft:nether_wart_block)
B(6,11,3,minecraft:nether_wart_block)
B(7,11,3,minecraft:nether_wart_block)
B(8,11,3,minecraft:nether_wart_block)
B(9,11,3,minecraft:nether_wart_block)
B(10,11,3,minecraft:nether_wart_block)
B(0,11,4,minecraft:nether_wart_block)
B(1,11,4,minecraft:nether_wart_block)
B(2,11,4,minecraft:nether_wart_block)
B(3,11,4,minecraft:nether_wart_block)
B(4,11,4,minecraft:nether_wart_block)
B(5,11,4,minecraft:nether_wart_block)
B(6,11,4,minecraft:nether_wart_block)
B(7,11,4,minecraft:nether_wart_block)
B(8,11,4,minecraft:nether_wart_block)
B(9,11,4,minecraft:nether_wart_block)
B(0,11,5,minecraft:nether_wart_block)
B(1,11,5,minecraft:nether_wart_block)
B(2,11,5,minecraft:nether_wart_block)
B(3,11,5,minecraft:nether_wart_block)
B(4,11,5,minecraft:nether_wart_block)
B(5,11,5,minecraft:nether_wart_block)
B(6,11,5,minecraft:nether_wart_block)
B(7,11,5,minecraft:nether_wart_block)
B(8,11,5,minecraft:nether_wart_block)
B(0,11,6,minecraft:nether_wart_block)
B(1,11,6,minecraft:nether_wart_block)
B(2,11,6,minecraft:nether_wart_block)
B(3,11,6,minecraft:nether_wart_block)
B(4,11,6,minecraft:nether_wart_block)
B(5,11,6,minecraft:nether_wart_block)
B(6,11,6,minecraft:nether_wart_block)
B(0,11,7,minecraft:nether_wart_block)
B(1,11,7,minecraft:nether_wart_block)
B(2,11,7,minecraft:nether_wart_block)
B(3,11,7,minecraft:nether_wart_block)
B(4,11,7,minecraft:nether_wart_block)
B(5,11,7,minecraft:nether_wart_block)
B(6,11,7,minecraft:nether_wart_block)
B(0,11,8,minecraft:nether_wart_block)
B(1,11,8,minecraft:nether_wart_block)
B(2,11,8,minecraft:nether_wart_block)
B(3,11,8,minecraft:nether_wart_block)
B(4,11,8,minecraft:nether_wart_block)
B(5,11,8,minecraft:nether_wart_block)
B(6,11,8,minecraft:nether_wart_block)
B(0,11,9,minecraft:nether_wart_block)
B(1,11,9,minecraft:nether_wart_block)
B(2,11,9,minecraft:nether_wart_block)
B(3,11,9,minecraft:nether_wart_block)
B(4,11,9,minecraft:nether_wart_block)
B(5,11,9,minecraft:nether_wart_block)
B(0,11,10,minecraft:nether_wart_block)
B(1,11,10,minecraft:nether_wart_block)
B(2,11,10,minecraft:nether_wart_block)
B(3,11,10,minecraft:nether_wart_block)
B(4,11,10,minecraft:nether_wart_block)
B(1,11,11,minecraft:nether_wart_block)
B(2,11,11,minecraft:nether_wart_block)
B(0,12,0,minecraft:nether_wart_block)
B(1,12,0,minecraft:nether_wart_block)
B(2,12,0,minecraft:nether_wart_block)
B(3,12,0,minecraft:nether_wart_block)
B(4,12,0,minecraft:nether_wart_block)
B(5,12,0,minecraft:nether_wart_block)
B(6,12,0,minecraft:nether_wart_block)
B(7,12,0,minecraft:nether_wart_block)
B(8,12,0,minecraft:nether_wart_block)
B(9,12,0,minecraft:nether_wart_block)
B(10,12,0,minecraft:nether_wart_block)
B(11,12,0,minecraft:nether_wart_block)
B(12,12,0,minecraft:nether_wart_block)
B(0,12,1,minecraft:nether_wart_block)
B(1,12,1,minecraft:nether_wart_block)
B(2,12,1,minecraft:nether_wart_block)
B(3,12,1,minecraft:nether_wart_block)
B(4,12,1,minecraft:nether_wart_block)
B(5,12,1,minecraft:nether_wart_block)
B(6,12,1,minecraft:nether_wart_block)
B(7,12,1,minecraft:nether_wart_block)
B(8,12,1,minecraft:nether_wart_block)
B(9,12,1,minecraft:nether_wart_block)
B(10,12,1,minecraft:nether_wart_block)
B(11,12,1,minecraft:nether_wart_block)
B(12,12,1,minecraft:nether_wart_block)
B(0,12,2,minecraft:nether_wart_block)
B(1,12,2,minecraft:nether_wart_block)
B(2,12,2,minecraft:nether_wart_block)
B(3,12,2,minecraft:nether_wart_block)
B(4,12,2,minecraft:nether_wart_block)
B(5,12,2,minecraft:nether_wart_block)
B(6,12,2,minecraft:nether_wart_block)
B(7,12,2,minecraft:nether_wart_block)
B(8,12,2,minecraft:nether_wart_block)
B(9,12,2,minecraft:nether_wart_block)
B(10,12,2,minecraft:nether_wart_block)
B(11,12,2,minecraft:nether_wart_block)
B(0,12,3,minecraft:nether_wart_block)
B(1,12,3,minecraft:nether_wart_block)
B(2,12,3,minecraft:nether_wart_block)
B(3,12,3,minecraft:nether_wart_block)
B(4,12,3,minecraft:nether_wart_block)
B(5,12,3,minecraft:nether_wart_block)
B(6,12,3,minecraft:nether_wart_block)
B(7,12,3,minecraft:nether_wart_block)
B(8,12,3,minecraft:nether_wart_block)
B(9,12,3,minecraft:nether_wart_block)
B(10,12,3,minecraft:nether_wart_block)
B(0,12,4,minecraft:nether_wart_block)
B(1,12,4,minecraft:nether_wart_block)
B(2,12,4,minecraft:nether_wart_block)
B(3,12,4,minecraft:nether_wart_block)
B(4,12,4,minecraft:nether_wart_block)
B(5,12,4,minecraft:nether_wart_block)
B(6,12,4,minecraft:nether_wart_block)
B(7,12,4,minecraft:nether_wart_block)
B(8,12,4,minecraft:nether_wart_block)
B(9,12,4,minecraft:nether_wart_block)
B(0,12,5,minecraft:nether_wart_block)
B(1,12,5,minecraft:nether_wart_block)
B(2,12,5,minecraft:nether_wart_block)
B(3,12,5,minecraft:nether_wart_block)
B(4,12,5,minecraft:nether_wart_block)
B(5,12,5,minecraft:nether_wart_block)
B(6,12,5,minecraft:nether_wart_block)
B(7,12,5,minecraft:nether_wart_block)
B(8,12,5,minecraft:nether_wart_block)
B(0,12,6,minecraft:nether_wart_block)
B(1,12,6,minecraft:nether_wart_block)
B(2,12,6,minecraft:nether_wart_block)
B(3,12,6,minecraft:nether_wart_block)
B(4,12,6,minecraft:nether_wart_block)
B(5,12,6,minecraft:nether_wart_block)
B(6,12,6,minecraft:nether_wart_block)
B(0,12,7,minecraft:nether_wart_block)
B(1,12,7,minecraft:nether_wart_block)
B(2,12,7,minecraft:nether_wart_block)
B(3,12,7,minecraft:nether_wart_block)
B(4,12,7,minecraft:nether_wart_block)
B(5,12,7,minecraft:nether_wart_block)
B(6,12,7,minecraft:nether_wart_block)
B(0,12,8,minecraft:nether_wart_block)
B(1,12,8,minecraft:nether_wart_block)
B(2,12,8,minecraft:nether_wart_block)
B(3,12,8,minecraft:nether_wart_block)
B(4,12,8,minecraft:nether_wart_block)
B(5,12,8,minecraft:nether_wart_block)
B(6,12,8,minecraft:nether_wart_block)
B(0,12,9,minecraft:nether_wart_block)
B(1,12,9,minecraft:nether_wart_block)
B(2,12,9,minecraft:nether_wart_block)
B(3,12,9,minecraft:nether_wart_block)
B(4,12,9,minecraft:nether_wart_block)
B(5,12,9,minecraft:nether_wart_block)
B(0,12,10,minecraft:nether_wart_block)
B(1,12,10,minecraft:nether_wart_block)
B(2,12,10,minecraft:nether_wart_block)
B(3,12,10,minecraft:nether_wart_block)
B(4,12,10,minecraft:nether_wart_block)
B(0,13,0,minecraft:nether_wart_block)
B(1,13,0,minecraft:nether_wart_block)
B(2,13,0,minecraft:nether_wart_block)
B(3,13,0,minecraft:nether_wart_block)
B(4,13,0,minecraft:nether_wart_block)
B(5,13,0,minecraft:nether_wart_block)
B(6,13,0,minecraft:nether_wart_block)
B(7,13,0,minecraft:nether_wart_block)
B(8,13,0,minecraft:nether_wart_block)
B(9,13,0,minecraft:nether_wart_block)
B(10,13,0,minecraft:nether_wart_block)
B(11,13,0,minecraft:nether_wart_block)
B(12,13,0,minecraft:nether_wart_block)
B(0,13,1,minecraft:nether_wart_block)
B(1,13,1,minecraft:nether_wart_block)
B(2,13,1,minecraft:nether_wart_block)
B(3,13,1,minecraft:nether_wart_block)
B(4,13,1,minecraft:nether_wart_block)
B(5,13,1,minecraft:nether_wart_block)
B(6,13,1,minecraft:nether_wart_block)
B(7,13,1,minecraft:nether_wart_block)
B(8,13,1,minecraft:nether_wart_block)
B(9,13,1,minecraft:nether_wart_block)
B(10,13,1,minecraft:nether_wart_block)
B(11,13,1,minecraft:nether_wart_block)
B(12,13,1,minecraft:nether_wart_block)
B(0,13,2,minecraft:nether_wart_block)
B(1,13,2,minecraft:nether_wart_block)
B(2,13,2,minecraft:nether_wart_block)
B(3,13,2,minecraft:nether_wart_block)
B(4,13,2,minecraft:nether_wart_block)
B(5,13,2,minecraft:nether_wart_block)
B(6,13,2,minecraft:nether_wart_block)
B(7,13,2,minecraft:nether_wart_block)
B(8,13,2,minecraft:nether_wart_block)
B(9,13,2,minecraft:nether_wart_block)
B(10,13,2,minecraft:nether_wart_block)
B(11,13,2,minecraft:nether_wart_block)
B(0,13,3,minecraft:nether_wart_block)
B(1,13,3,minecraft:nether_wart_block)
B(2,13,3,minecraft:nether_wart_block)
B(3,13,3,minecraft:nether_wart_block)
B(4,13,3,minecraft:nether_wart_block)
B(5,13,3,minecraft:nether_wart_block)
B(6,13,3,minecraft:nether_wart_block)
B(7,13,3,minecraft:nether_wart_block)
B(8,13,3,minecraft:nether_wart_block)
B(9,13,3,minecraft:nether_wart_block)
B(10,13,3,minecraft:nether_wart_block)
B(0,13,4,minecraft:nether_wart_block)
B(1,13,4,minecraft:nether_wart_block)
B(2,13,4,minecraft:nether_wart_block)
B(3,13,4,minecraft:nether_wart_block)
B(4,13,4,minecraft:nether_wart_block)
B(5,13,4,minecraft:nether_wart_block)
B(6,13,4,minecraft:nether_wart_block)
B(7,13,4,minecraft:nether_wart_block)
B(8,13,4,minecraft:nether_wart_block)
B(9,13,4,minecraft:nether_wart_block)
B(0,13,5,minecraft:nether_wart_block)
B(1,13,5,minecraft:nether_wart_block)
B(2,13,5,minecraft:nether_wart_block)
B(3,13,5,minecraft:nether_wart_block)
B(4,13,5,minecraft:nether_wart_block)
B(5,13,5,minecraft:nether_wart_block)
B(6,13,5,minecraft:nether_wart_block)
B(7,13,5,minecraft:nether_wart_block)
B(8,13,5,minecraft:nether_wart_block)
B(0,13,6,minecraft:nether_wart_block)
B(1,13,6,minecraft:nether_wart_block)
B(2,13,6,minecraft:nether_wart_block)
B(3,13,6,minecraft:nether_wart_block)
B(4,13,6,minecraft:nether_wart_block)
B(5,13,6,minecraft:nether_wart_block)
B(6,13,6,minecraft:nether_wart_block)
B(0,13,7,minecraft:nether_wart_block)
B(1,13,7,minecraft:nether_wart_block)
B(2,13,7,minecraft:nether_wart_block)
B(3,13,7,minecraft:nether_wart_block)
B(4,13,7,minecraft:nether_wart_block)
B(5,13,7,minecraft:nether_wart_block)
B(6,13,7,minecraft:nether_wart_block)
B(0,13,8,minecraft:nether_wart_block)
B(1,13,8,minecraft:nether_wart_block)
B(2,13,8,minecraft:nether_wart_block)
B(3,13,8,minecraft:nether_wart_block)
B(4,13,8,minecraft:nether_wart_block)
B(5,13,8,minecraft:nether_wart_block)
B(0,13,9,minecraft:nether_wart_block)
B(1,13,9,minecraft:nether_wart_block)
B(2,13,9,minecraft:nether_wart_block)
B(3,13,9,minecraft:nether_wart_block)
B(4,13,9,minecraft:nether_wart_block)
B(5,13,9,minecraft:nether_wart_block)
B(0,13,10,minecraft:nether_wart_block)
B(1,13,10,minecraft:nether_wart_block)
B(2,13,10,minecraft:nether_wart_block)
B(3,13,10,minecraft:nether_wart_block)
B(0,14,0,minecraft:nether_wart_block)
B(1,14,0,minecraft:nether_wart_block)
B(2,14,0,minecraft:nether_wart_block)
B(3,14,0,minecraft:nether_wart_block)
B(4,14,0,minecraft:nether_wart_block)
B(5,14,0,minecraft:nether_wart_block)
B(6,14,0,minecraft:nether_wart_block)
B(7,14,0,minecraft:nether_wart_block)
B(8,14,0,minecraft:nether_wart_block)
B(9,14,0,minecraft:nether_wart_block)
B(10,14,0,minecraft:nether_wart_block)
B(11,14,0,minecraft:nether_wart_block)
B(12,14,0,minecraft:nether_wart_block)
B(0,14,1,minecraft:nether_wart_block)
B(1,14,1,minecraft:nether_wart_block)
B(2,14,1,minecraft:nether_wart_block)
B(3,14,1,minecraft:nether_wart_block)
B(4,14,1,minecraft:nether_wart_block)
B(5,14,1,minecraft:nether_wart_block)
B(6,14,1,minecraft:nether_wart_block)
B(7,14,1,minecraft:nether_wart_block)
B(8,14,1,minecraft:nether_wart_block)
B(9,14,1,minecraft:nether_wart_block)
B(10,14,1,minecraft:nether_wart_block)
B(11,14,1,minecraft:nether_wart_block)
B(12,14,1,minecraft:nether_wart_block)
B(0,14,2,minecraft:nether_wart_block)
B(1,14,2,minecraft:nether_wart_block)
B(2,14,2,minecraft:nether_wart_block)
B(3,14,2,minecraft:nether_wart_block)
B(4,14,2,minecraft:nether_wart_block)
B(5,14,2,minecraft:nether_wart_block)
B(6,14,2,minecraft:nether_wart_block)
B(7,14,2,minecraft:nether_wart_block)
B(8,14,2,minecraft:nether_wart_block)
B(9,14,2,minecraft:nether_wart_block)
B(10,14,2,minecraft:nether_wart_block)
B(11,14,2,minecraft:nether_wart_block)
B(0,14,3,minecraft:nether_wart_block)
B(1,14,3,minecraft:nether_wart_block)
B(2,14,3,minecraft:nether_wart_block)
B(3,14,3,minecraft:nether_wart_block)
B(4,14,3,minecraft:nether_wart_block)
B(5,14,3,minecraft:nether_wart_block)
B(6,14,3,minecraft:nether_wart_block)
B(7,14,3,minecraft:nether_wart_block)
B(8,14,3,minecraft:nether_wart_block)
B(9,14,3,minecraft:nether_wart_block)
B(10,14,3,minecraft:nether_wart_block)
B(0,14,4,minecraft:nether_wart_block)
B(1,14,4,minecraft:nether_wart_block)
B(2,14,4,minecraft:nether_wart_block)
B(3,14,4,minecraft:nether_wart_block)
B(4,14,4,minecraft:nether_wart_block)
B(5,14,4,minecraft:nether_wart_block)
B(6,14,4,minecraft:nether_wart_block)
B(7,14,4,minecraft:nether_wart_block)
B(8,14,4,minecraft:nether_wart_block)
B(9,14,4,minecraft:nether_wart_block)
B(0,14,5,minecraft:nether_wart_block)
B(1,14,5,minecraft:nether_wart_block)
B(2,14,5,minecraft:nether_wart_block)
B(3,14,5,minecraft:nether_wart_block)
B(4,14,5,minecraft:nether_wart_block)
B(5,14,5,minecraft:nether_wart_block)
B(6,14,5,minecraft:nether_wart_block)
B(7,14,5,minecraft:nether_wart_block)
B(8,14,5,minecraft:nether_wart_block)
B(0,14,6,minecraft:nether_wart_block)
B(1,14,6,minecraft:nether_wart_block)
B(2,14,6,minecraft:nether_wart_block)
B(3,14,6,minecraft:nether_wart_block)
B(4,14,6,minecraft:nether_wart_block)
B(5,14,6,minecraft:nether_wart_block)
B(6,14,6,minecraft:nether_wart_block)
B(0,14,7,minecraft:nether_wart_block)
B(1,14,7,minecraft:nether_wart_block)
B(2,14,7,minecraft:nether_wart_block)
B(3,14,7,minecraft:nether_wart_block)
B(4,14,7,minecraft:nether_wart_block)
B(5,14,7,minecraft:nether_wart_block)
B(6,14,7,minecraft:nether_wart_block)
B(0,14,8,minecraft:nether_wart_block)
B(1,14,8,minecraft:nether_wart_block)
B(2,14,8,minecraft:nether_wart_block)
B(3,14,8,minecraft:nether_wart_block)
B(4,14,8,minecraft:nether_wart_block)
B(5,14,8,minecraft:nether_wart_block)
B(0,14,9,minecraft:nether_wart_block)
B(1,14,9,minecraft:nether_wart_block)
B(2,14,9,minecraft:nether_wart_block)
B(3,14,9,minecraft:nether_wart_block)
B(4,14,9,minecraft:nether_wart_block)
B(1,14,10,minecraft:nether_wart_block)
B(2,14,10,minecraft:nether_wart_block)
B(3,14,10,minecraft:nether_wart_block)
B(0,15,0,minecraft:nether_wart_block)
B(1,15,0,minecraft:nether_wart_block)
B(2,15,0,minecraft:nether_wart_block)
B(3,15,0,minecraft:nether_wart_block)
B(4,15,0,minecraft:nether_wart_block)
B(5,15,0,minecraft:nether_wart_block)
B(6,15,0,minecraft:nether_wart_block)
B(7,15,0,minecraft:nether_wart_block)
B(8,15,0,minecraft:nether_wart_block)
B(9,15,0,minecraft:nether_wart_block)
B(10,15,0,minecraft:nether_wart_block)
B(11,15,0,minecraft:nether_wart_block)
B(12,15,0,minecraft:nether_wart_block)
B(0,15,1,minecraft:nether_wart_block)
B(1,15,1,minecraft:nether_wart_block)
B(2,15,1,minecraft:nether_wart_block)
B(3,15,1,minecraft:nether_wart_block)
B(4,15,1,minecraft:nether_wart_block)
B(5,15,1,minecraft:nether_wart_block)
B(6,15,1,minecraft:nether_wart_block)
B(7,15,1,minecraft:nether_wart_block)
B(8,15,1,minecraft:nether_wart_block)
B(9,15,1,minecraft:nether_wart_block)
B(10,15,1,minecraft:nether_wart_block)
B(11,15,1,minecraft:nether_wart_block)
B(12,15,1,minecraft:nether_wart_block)
B(0,15,2,minecraft:nether_wart_block)
B(1,15,2,minecraft:nether_wart_block)
B(2,15,2,minecraft:nether_wart_block)
B(3,15,2,minecraft:nether_wart_block)
B(4,15,2,minecraft:nether_wart_block)
B(5,15,2,minecraft:nether_wart_block)
B(6,15,2,minecraft:nether_wart_block)
B(7,15,2,minecraft:nether_wart_block)
B(8,15,2,minecraft:nether_wart_block)
B(9,15,2,minecraft:nether_wart_block)
B(10,15,2,minecraft:nether_wart_block)
B(11,15,2,minecraft:nether_wart_block)
B(0,15,3,minecraft:nether_wart_block)
B(1,15,3,minecraft:nether_wart_block)
B(2,15,3,minecraft:nether_wart_block)
B(3,15,3,minecraft:nether_wart_block)
B(4,15,3,minecraft:nether_wart_block)
B(5,15,3,minecraft:nether_wart_block)
B(6,15,3,minecraft:nether_wart_block)
B(7,15,3,minecraft:nether_wart_block)
B(8,15,3,minecraft:nether_wart_block)
B(9,15,3,minecraft:nether_wart_block)
B(10,15,3,minecraft:nether_wart_block)
B(0,15,4,minecraft:nether_wart_block)
B(1,15,4,minecraft:nether_wart_block)
B(2,15,4,minecraft:nether_wart_block)
B(3,15,4,minecraft:nether_wart_block)
B(4,15,4,minecraft:nether_wart_block)
B(5,15,4,minecraft:nether_wart_block)
B(6,15,4,minecraft:nether_wart_block)
B(7,15,4,minecraft:nether_wart_block)
B(8,15,4,minecraft:nether_wart_block)
B(9,15,4,minecraft:nether_wart_block)
B(0,15,5,minecraft:nether_wart_block)
B(1,15,5,minecraft:nether_wart_block)
B(2,15,5,minecraft:nether_wart_block)
B(3,15,5,minecraft:nether_wart_block)
B(4,15,5,minecraft:nether_wart_block)
B(5,15,5,minecraft:nether_wart_block)
B(6,15,5,minecraft:nether_wart_block)
B(7,15,5,minecraft:nether_wart_block)
B(8,15,5,minecraft:nether_wart_block)
B(0,15,6,minecraft:nether_wart_block)
B(1,15,6,minecraft:nether_wart_block)
B(2,15,6,minecraft:nether_wart_block)
B(3,15,6,minecraft:nether_wart_block)
B(4,15,6,minecraft:nether_wart_block)
B(5,15,6,minecraft:nether_wart_block)
B(6,15,6,minecraft:nether_wart_block)
B(0,15,7,minecraft:nether_wart_block)
B(1,15,7,minecraft:nether_wart_block)
B(2,15,7,minecraft:nether_wart_block)
B(3,15,7,minecraft:nether_wart_block)
B(4,15,7,minecraft:nether_wart_block)
B(5,15,7,minecraft:nether_wart_block)
B(6,15,7,minecraft:nether_wart_block)
B(0,15,8,minecraft:nether_wart_block)
B(1,15,8,minecraft:nether_wart_block)
B(2,15,8,minecraft:nether_wart_block)
B(3,15,8,minecraft:nether_wart_block)
B(4,15,8,minecraft:nether_wart_block)
B(5,15,8,minecraft:nether_wart_block)
B(0,15,9,minecraft:nether_wart_block)
B(1,15,9,minecraft:nether_wart_block)
B(2,15,9,minecraft:nether_wart_block)
B(3,15,9,minecraft:nether_wart_block)
B(4,15,9,minecraft:nether_wart_block)
B(3,15,10,minecraft:nether_wart_block)
B(0,16,0,minecraft:nether_wart_block)
B(1,16,0,minecraft:nether_wart_block)
B(2,16,0,minecraft:nether_wart_block)
B(3,16,0,minecraft:nether_wart_block)
B(4,16,0,minecraft:nether_wart_block)
B(5,16,0,minecraft:nether_wart_block)
B(6,16,0,minecraft:nether_wart_block)
B(7,16,0,minecraft:nether_wart_block)
B(8,16,0,minecraft:nether_wart_block)
B(9,16,0,minecraft:nether_wart_block)
B(10,16,0,minecraft:nether_wart_block)
B(11,16,0,minecraft:nether_wart_block)
B(12,16,0,minecraft:nether_wart_block)
B(0,16,1,minecraft:nether_wart_block)
B(1,16,1,minecraft:nether_wart_block)
B(2,16,1,minecraft:nether_wart_block)
B(3,16,1,minecraft:nether_wart_block)
B(4,16,1,minecraft:nether_wart_block)
B(5,16,1,minecraft:nether_wart_block)
B(6,16,1,minecraft:nether_wart_block)
B(7,16,1,minecraft:nether_wart_block)
B(8,16,1,minecraft:nether_wart_block)
B(9,16,1,minecraft:nether_wart_block)
B(10,16,1,minecraft:nether_wart_block)
B(11,16,1,minecraft:nether_wart_block)
B(12,16,1,minecraft:nether_wart_block)
B(0,16,2,minecraft:nether_wart_block)
B(1,16,2,minecraft:nether_wart_block)
B(2,16,2,minecraft:nether_wart_block)
B(3,16,2,minecraft:nether_wart_block)
B(4,16,2,minecraft:nether_wart_block)
B(5,16,2,minecraft:nether_wart_block)
B(6,16,2,minecraft:nether_wart_block)
B(7,16,2,minecraft:nether_wart_block)
B(8,16,2,minecraft:nether_wart_block)
B(9,16,2,minecraft:nether_wart_block)
B(10,16,2,minecraft:nether_wart_block)
B(11,16,2,minecraft:nether_wart_block)
B(0,16,3,minecraft:nether_wart_block)
B(1,16,3,minecraft:nether_wart_block)
B(2,16,3,minecraft:nether_wart_block)
B(3,16,3,minecraft:nether_wart_block)
B(4,16,3,minecraft:nether_wart_block)
B(5,16,3,minecraft:nether_wart_block)
B(6,16,3,minecraft:nether_wart_block)
B(7,16,3,minecraft:nether_wart_block)
B(8,16,3,minecraft:nether_wart_block)
B(9,16,3,minecraft:nether_wart_block)
B(10,16,3,minecraft:nether_wart_block)
B(0,16,4,minecraft:nether_wart_block)
B(1,16,4,minecraft:nether_wart_block)
B(2,16,4,minecraft:nether_wart_block)
B(3,16,4,minecraft:nether_wart_block)
B(4,16,4,minecraft:nether_wart_block)
B(5,16,4,minecraft:nether_wart_block)
B(6,16,4,minecraft:nether_wart_block)
B(7,16,4,minecraft:nether_wart_block)
B(8,16,4,minecraft:nether_wart_block)
B(9,16,4,minecraft:nether_wart_block)
B(0,16,5,minecraft:nether_wart_block)
B(1,16,5,minecraft:nether_wart_block)
B(2,16,5,minecraft:nether_wart_block)
B(3,16,5,minecraft:nether_wart_block)
B(4,16,5,minecraft:nether_wart_block)
B(5,16,5,minecraft:nether_wart_block)
B(6,16,5,minecraft:nether_wart_block)
B(7,16,5,minecraft:nether_wart_block)
B(8,16,5,minecraft:nether_wart_block)
B(0,16,6,minecraft:nether_wart_block)
B(1,16,6,minecraft:nether_wart_block)
B(2,16,6,minecraft:nether_wart_block)
B(3,16,6,minecraft:nether_wart_block)
B(4,16,6,minecraft:nether_wart_block)
B(5,16,6,minecraft:nether_wart_block)
B(6,16,6,minecraft:nether_wart_block)
B(0,16,7,minecraft:nether_wart_block)
B(1,16,7,minecraft:nether_wart_block)
B(2,16,7,minecraft:nether_wart_block)
B(3,16,7,minecraft:nether_wart_block)
B(4,16,7,minecraft:nether_wart_block)
B(5,16,7,minecraft:nether_wart_block)
B(6,16,7,minecraft:nether_wart_block)
B(0,16,8,minecraft:nether_wart_block)
B(1,16,8,minecraft:nether_wart_block)
B(2,16,8,minecraft:nether_wart_block)
B(3,16,8,minecraft:nether_wart_block)
B(4,16,8,minecraft:nether_wart_block)
B(5,16,8,minecraft:nether_wart_block)
B(0,16,9,minecraft:nether_wart_block)
B(1,16,9,minecraft:nether_wart_block)
B(2,16,9,minecraft:nether_wart_block)
B(3,16,9,minecraft:nether_wart_block)
B(4,16,9,minecraft:nether_wart_block)
B(3,16,10,minecraft:nether_wart_block)
B(0,17,0,minecraft:nether_wart_block)
B(1,17,0,minecraft:nether_wart_block)
B(2,17,0,minecraft:nether_wart_block)
B(3,17,0,minecraft:nether_wart_block)
B(4,17,0,minecraft:nether_wart_block)
B(5,17,0,minecraft:nether_wart_block)
B(6,17,0,minecraft:nether_wart_block)
B(7,17,0,minecraft:nether_wart_block)
B(8,17,0,minecraft:nether_wart_block)
B(9,17,0,minecraft:nether_wart_block)
B(10,17,0,minecraft:nether_wart_block)
B(11,17,0,minecraft:nether_wart_block)
B(12,17,0,minecraft:nether_wart_block)
B(0,17,1,minecraft:nether_wart_block)
B(1,17,1,minecraft:nether_wart_block)
B(2,17,1,minecraft:nether_wart_block)
B(3,17,1,minecraft:nether_wart_block)
B(4,17,1,minecraft:nether_wart_block)
B(5,17,1,minecraft:nether_wart_block)
B(6,17,1,minecraft:nether_wart_block)
B(7,17,1,minecraft:nether_wart_block)
B(8,17,1,minecraft:nether_wart_block)
B(9,17,1,minecraft:nether_wart_block)
B(10,17,1,minecraft:nether_wart_block)
B(11,17,1,minecraft:nether_wart_block)
B(0,17,2,minecraft:nether_wart_block)
B(1,17,2,minecraft:nether_wart_block)
B(2,17,2,minecraft:nether_wart_block)
B(3,17,2,minecraft:nether_wart_block)
B(4,17,2,minecraft:nether_wart_block)
B(5,17,2,minecraft:nether_wart_block)
B(6,17,2,minecraft:nether_wart_block)
B(7,17,2,minecraft:nether_wart_block)
B(8,17,2,minecraft:nether_wart_block)
B(9,17,2,minecraft:nether_wart_block)
B(10,17,2,minecraft:nether_wart_block)
B(11,17,2,minecraft:nether_wart_block)
B(0,17,3,minecraft:nether_wart_block)
B(1,17,3,minecraft:nether_wart_block)
B(2,17,3,minecraft:nether_wart_block)
B(3,17,3,minecraft:nether_wart_block)
B(4,17,3,minecraft:nether_wart_block)
B(5,17,3,minecraft:nether_wart_block)
B(6,17,3,minecraft:nether_wart_block)
B(7,17,3,minecraft:nether_wart_block)
B(8,17,3,minecraft:nether_wart_block)
B(9,17,3,minecraft:nether_wart_block)
B(10,17,3,minecraft:nether_wart_block)
B(0,17,4,minecraft:nether_wart_block)
B(1,17,4,minecraft:nether_wart_block)
B(2,17,4,minecraft:nether_wart_block)
B(3,17,4,minecraft:nether_wart_block)
B(4,17,4,minecraft:nether_wart_block)
B(5,17,4,minecraft:nether_wart_block)
B(6,17,4,minecraft:nether_wart_block)
B(7,17,4,minecraft:nether_wart_block)
B(8,17,4,minecraft:nether_wart_block)
B(9,17,4,minecraft:nether_wart_block)
B(0,17,5,minecraft:nether_wart_block)
B(1,17,5,minecraft:nether_wart_block)
B(2,17,5,minecraft:nether_wart_block)
B(3,17,5,minecraft:nether_wart_block)
B(4,17,5,minecraft:nether_wart_block)
B(5,17,5,minecraft:nether_wart_block)
B(6,17,5,minecraft:nether_wart_block)
B(7,17,5,minecraft:nether_wart_block)
B(8,17,5,minecraft:nether_wart_block)
B(0,17,6,minecraft:nether_wart_block)
B(1,17,6,minecraft:nether_wart_block)
B(2,17,6,minecraft:nether_wart_block)
B(3,17,6,minecraft:nether_wart_block)
B(4,17,6,minecraft:nether_wart_block)
B(5,17,6,minecraft:nether_wart_block)
B(6,17,6,minecraft:nether_wart_block)
B(0,17,7,minecraft:nether_wart_block)
B(1,17,7,minecraft:nether_wart_block)
B(2,17,7,minecraft:nether_wart_block)
B(3,17,7,minecraft:nether_wart_block)
B(4,17,7,minecraft:nether_wart_block)
B(5,17,7,minecraft:nether_wart_block)
B(6,17,7,minecraft:nether_wart_block)
B(0,17,8,minecraft:nether_wart_block)
B(1,17,8,minecraft:nether_wart_block)
B(2,17,8,minecraft:nether_wart_block)
B(3,17,8,minecraft:nether_wart_block)
B(4,17,8,minecraft:nether_wart_block)
B(5,17,8,minecraft:nether_wart_block)
B(0,17,9,minecraft:nether_wart_block)
B(1,17,9,minecraft:nether_wart_block)
B(2,17,9,minecraft:nether_wart_block)
B(3,17,9,minecraft:nether_wart_block)
B(4,17,9,minecraft:nether_wart_block)
B(3,17,10,minecraft:nether_wart_block)
B(0,18,0,minecraft:nether_wart_block)
B(1,18,0,minecraft:nether_wart_block)
B(2,18,0,minecraft:nether_wart_block)
B(3,18,0,minecraft:nether_wart_block)
B(4,18,0,minecraft:nether_wart_block)
B(5,18,0,minecraft:nether_wart_block)
B(6,18,0,minecraft:nether_wart_block)
B(7,18,0,minecraft:nether_wart_block)
B(8,18,0,minecraft:nether_wart_block)
B(9,18,0,minecraft:nether_wart_block)
B(10,18,0,minecraft:nether_wart_block)
B(11,18,0,minecraft:nether_wart_block)
B(0,18,1,minecraft:nether_wart_block)
B(1,18,1,minecraft:nether_wart_block)
B(2,18,1,minecraft:nether_wart_block)
B(3,18,1,minecraft:nether_wart_block)
B(4,18,1,minecraft:nether_wart_block)
B(5,18,1,minecraft:nether_wart_block)
B(6,18,1,minecraft:nether_wart_block)
B(7,18,1,minecraft:nether_wart_block)
B(8,18,1,minecraft:nether_wart_block)
B(9,18,1,minecraft:nether_wart_block)
B(10,18,1,minecraft:nether_wart_block)
B(11,18,1,minecraft:nether_wart_block)
B(0,18,2,minecraft:nether_wart_block)
B(1,18,2,minecraft:nether_wart_block)
B(2,18,2,minecraft:nether_wart_block)
B(3,18,2,minecraft:nether_wart_block)
B(4,18,2,minecraft:nether_wart_block)
B(5,18,2,minecraft:nether_wart_block)
B(6,18,2,minecraft:nether_wart_block)
B(7,18,2,minecraft:nether_wart_block)
B(8,18,2,minecraft:nether_wart_block)
B(9,18,2,minecraft:nether_wart_block)
B(10,18,2,minecraft:nether_wart_block)
B(11,18,2,minecraft:nether_wart_block)
B(0,18,3,minecraft:nether_wart_block)
B(1,18,3,minecraft:nether_wart_block)
B(2,18,3,minecraft:nether_wart_block)
B(3,18,3,minecraft:nether_wart_block)
B(4,18,3,minecraft:nether_wart_block)
B(5,18,3,minecraft:nether_wart_block)
B(6,18,3,minecraft:nether_wart_block)
B(7,18,3,minecraft:nether_wart_block)
B(8,18,3,minecraft:nether_wart_block)
B(9,18,3,minecraft:nether_wart_block)
B(10,18,3,minecraft:nether_wart_block)
B(0,18,4,minecraft:nether_wart_block)
B(1,18,4,minecraft:nether_wart_block)
B(2,18,4,minecraft:nether_wart_block)
B(3,18,4,minecraft:nether_wart_block)
B(4,18,4,minecraft:nether_wart_block)
B(5,18,4,minecraft:nether_wart_block)
B(6,18,4,minecraft:nether_wart_block)
B(7,18,4,minecraft:nether_wart_block)
B(8,18,4,minecraft:nether_wart_block)
B(9,18,4,minecraft:nether_wart_block)
B(0,18,5,minecraft:nether_wart_block)
B(1,18,5,minecraft:nether_wart_block)
B(2,18,5,minecraft:nether_wart_block)
B(3,18,5,minecraft:nether_wart_block)
B(4,18,5,minecraft:nether_wart_block)
B(5,18,5,minecraft:nether_wart_block)
B(6,18,5,minecraft:nether_wart_block)
B(7,18,5,minecraft:nether_wart_block)
B(8,18,5,minecraft:nether_wart_block)
B(0,18,6,minecraft:nether_wart_block)
B(1,18,6,minecraft:nether_wart_block)
B(2,18,6,minecraft:nether_wart_block)
B(3,18,6,minecraft:nether_wart_block)
B(4,18,6,minecraft:nether_wart_block)
B(5,18,6,minecraft:nether_wart_block)
B(6,18,6,minecraft:nether_wart_block)
B(0,18,7,minecraft:nether_wart_block)
B(1,18,7,minecraft:nether_wart_block)
B(2,18,7,minecraft:nether_wart_block)
B(3,18,7,minecraft:nether_wart_block)
B(4,18,7,minecraft:nether_wart_block)
B(5,18,7,minecraft:nether_wart_block)
B(6,18,7,minecraft:nether_wart_block)
B(0,18,8,minecraft:nether_wart_block)
B(1,18,8,minecraft:nether_wart_block)
B(2,18,8,minecraft:nether_wart_block)
B(3,18,8,minecraft:nether_wart_block)
B(4,18,8,minecraft:nether_wart_block)
B(5,18,8,minecraft:nether_wart_block)
B(0,18,9,minecraft:nether_wart_block)
B(1,18,9,minecraft:nether_wart_block)
B(2,18,9,minecraft:nether_wart_block)
B(3,18,9,minecraft:nether_wart_block)
B(4,18,9,minecraft:nether_wart_block)
B(3,18,10,minecraft:nether_wart_block)
B(0,19,0,minecraft:nether_wart_block)
B(1,19,0,minecraft:nether_wart_block)
B(2,19,0,minecraft:nether_wart_block)
B(3,19,0,minecraft:nether_wart_block)
B(4,19,0,minecraft:nether_wart_block)
B(5,19,0,minecraft:nether_wart_block)
B(6,19,0,minecraft:nether_wart_block)
B(7,19,0,minecraft:nether_wart_block)
B(8,19,0,minecraft:nether_wart_block)
B(9,19,0,minecraft:nether_wart_block)
B(10,19,0,minecraft:nether_wart_block)
B(11,19,0,minecraft:nether_wart_block)
B(0,19,1,minecraft:nether_wart_block)
B(1,19,1,minecraft:nether_wart_block)
B(2,19,1,minecraft:nether_wart_block)
B(3,19,1,minecraft:nether_wart_block)
B(4,19,1,minecraft:nether_wart_block)
B(5,19,1,minecraft:nether_wart_block)
B(6,19,1,minecraft:nether_wart_block)
B(7,19,1,minecraft:nether_wart_block)
B(8,19,1,minecraft:nether_wart_block)
B(9,19,1,minecraft:nether_wart_block)
B(10,19,1,minecraft:nether_wart_block)
B(11,19,1,minecraft:nether_wart_block)
B(0,19,2,minecraft:nether_wart_block)
B(1,19,2,minecraft:nether_wart_block)
B(2,19,2,minecraft:nether_wart_block)
B(3,19,2,minecraft:nether_wart_block)
B(4,19,2,minecraft:nether_wart_block)
B(5,19,2,minecraft:nether_wart_block)
B(6,19,2,minecraft:nether_wart_block)
B(7,19,2,minecraft:nether_wart_block)
B(8,19,2,minecraft:nether_wart_block)
B(9,19,2,minecraft:nether_wart_block)
B(10,19,2,minecraft:nether_wart_block)
B(11,19,2,minecraft:nether_wart_block)
B(0,19,3,minecraft:nether_wart_block)
B(1,19,3,minecraft:nether_wart_block)
B(2,19,3,minecraft:nether_wart_block)
B(3,19,3,minecraft:nether_wart_block)
B(4,19,3,minecraft:nether_wart_block)
B(5,19,3,minecraft:nether_wart_block)
B(6,19,3,minecraft:nether_wart_block)
B(7,19,3,minecraft:nether_wart_block)
B(8,19,3,minecraft:nether_wart_block)
B(9,19,3,minecraft:nether_wart_block)
B(10,19,3,minecraft:nether_wart_block)
B(0,19,4,minecraft:nether_wart_block)
B(1,19,4,minecraft:nether_wart_block)
B(2,19,4,minecraft:nether_wart_block)
B(3,19,4,minecraft:nether_wart_block)
B(4,19,4,minecraft:nether_wart_block)
B(5,19,4,minecraft:nether_wart_block)
B(6,19,4,minecraft:nether_wart_block)
B(7,19,4,minecraft:nether_wart_block)
B(8,19,4,minecraft:nether_wart_block)
B(9,19,4,minecraft:nether_wart_block)
B(0,19,5,minecraft:nether_wart_block)
B(1,19,5,minecraft:nether_wart_block)
B(2,19,5,minecraft:nether_wart_block)
B(3,19,5,minecraft:nether_wart_block)
B(4,19,5,minecraft:nether_wart_block)
B(5,19,5,minecraft:nether_wart_block)
B(6,19,5,minecraft:nether_wart_block)
B(7,19,5,minecraft:nether_wart_block)
B(8,19,5,minecraft:nether_wart_block)
B(0,19,6,minecraft:nether_wart_block)
B(1,19,6,minecraft:nether_wart_block)
B(2,19,6,minecraft:nether_wart_block)
B(3,19,6,minecraft:nether_wart_block)
B(4,19,6,minecraft:nether_wart_block)
B(5,19,6,minecraft:nether_wart_block)
B(6,19,6,minecraft:nether_wart_block)
B(0,19,7,minecraft:nether_wart_block)
B(1,19,7,minecraft:nether_wart_block)
B(2,19,7,minecraft:nether_wart_block)
B(3,19,7,minecraft:nether_wart_block)
B(4,19,7,minecraft:nether_wart_block)
B(5,19,7,minecraft:nether_wart_block)
B(0,19,8,minecraft:nether_wart_block)
B(1,19,8,minecraft:nether_wart_block)
B(2,19,8,minecraft:nether_wart_block)
B(3,19,8,minecraft:nether_wart_block)
B(4,19,8,minecraft:nether_wart_block)
B(5,19,8,minecraft:nether_wart_block)
B(0,19,9,minecraft:nether_wart_block)
B(1,19,9,minecraft:nether_wart_block)
B(2,19,9,minecraft:nether_wart_block)
B(3,19,9,minecraft:nether_wart_block)
B(4,19,9,minecraft:nether_wart_block)
B(3,19,10,minecraft:nether_wart_block)
B(0,20,0,minecraft:nether_wart_block)
B(1,20,0,minecraft:nether_wart_block)
B(2,20,0,minecraft:nether_wart_block)
B(3,20,0,minecraft:nether_wart_block)
B(4,20,0,minecraft:nether_wart_block)
B(5,20,0,minecraft:nether_wart_block)
B(6,20,0,minecraft:nether_wart_block)
B(7,20,0,minecraft:nether_wart_block)
B(8,20,0,minecraft:nether_wart_block)
B(9,20,0,minecraft:nether_wart_block)
B(10,20,0,minecraft:nether_wart_block)
B(11,20,0,minecraft:nether_wart_block)
B(0,20,1,minecraft:nether_wart_block)
B(1,20,1,minecraft:nether_wart_block)
B(2,20,1,minecraft:nether_wart_block)
B(3,20,1,minecraft:nether_wart_block)
B(4,20,1,minecraft:nether_wart_block)
B(5,20,1,minecraft:nether_wart_block)
B(6,20,1,minecraft:nether_wart_block)
B(7,20,1,minecraft:nether_wart_block)
B(8,20,1,minecraft:nether_wart_block)
B(9,20,1,minecraft:nether_wart_block)
B(10,20,1,minecraft:nether_wart_block)
B(11,20,1,minecraft:nether_wart_block)
B(0,20,2,minecraft:nether_wart_block)
B(1,20,2,minecraft:nether_wart_block)
B(2,20,2,minecraft:nether_wart_block)
B(3,20,2,minecraft:nether_wart_block)
B(4,20,2,minecraft:nether_wart_block)
B(5,20,2,minecraft:nether_wart_block)
B(6,20,2,minecraft:nether_wart_block)
B(7,20,2,minecraft:nether_wart_block)
B(8,20,2,minecraft:nether_wart_block)
B(9,20,2,minecraft:nether_wart_block)
B(10,20,2,minecraft:nether_wart_block)
B(0,20,3,minecraft:nether_wart_block)
B(1,20,3,minecraft:nether_wart_block)
B(2,20,3,minecraft:nether_wart_block)
B(3,20,3,minecraft:nether_wart_block)
B(4,20,3,minecraft:nether_wart_block)
B(5,20,3,minecraft:nether_wart_block)
B(6,20,3,minecraft:nether_wart_block)
B(7,20,3,minecraft:nether_wart_block)
B(8,20,3,minecraft:nether_wart_block)
B(9,20,3,minecraft:nether_wart_block)
B(0,20,4,minecraft:nether_wart_block)
B(1,20,4,minecraft:nether_wart_block)
B(2,20,4,minecraft:nether_wart_block)
B(3,20,4,minecraft:nether_wart_block)
B(4,20,4,minecraft:nether_wart_block)
B(5,20,4,minecraft:nether_wart_block)
B(6,20,4,minecraft:nether_wart_block)
B(7,20,4,minecraft:nether_wart_block)
B(8,20,4,minecraft:nether_wart_block)
B(9,20,4,minecraft:nether_wart_block)
B(0,20,5,minecraft:nether_wart_block)
B(1,20,5,minecraft:nether_wart_block)
B(2,20,5,minecraft:nether_wart_block)
B(3,20,5,minecraft:nether_wart_block)
B(4,20,5,minecraft:nether_wart_block)
B(5,20,5,minecraft:nether_wart_block)
B(6,20,5,minecraft:nether_wart_block)
B(7,20,5,minecraft:nether_wart_block)
B(8,20,5,minecraft:nether_wart_block)
B(0,20,6,minecraft:nether_wart_block)
B(1,20,6,minecraft:nether_wart_block)
B(2,20,6,minecraft:nether_wart_block)
B(3,20,6,minecraft:nether_wart_block)
B(4,20,6,minecraft:nether_wart_block)
B(5,20,6,minecraft:nether_wart_block)
B(0,20,7,minecraft:nether_wart_block)
B(1,20,7,minecraft:nether_wart_block)
B(2,20,7,minecraft:nether_wart_block)
B(3,20,7,minecraft:nether_wart_block)
B(4,20,7,minecraft:nether_wart_block)
B(5,20,7,minecraft:nether_wart_block)
B(0,20,8,minecraft:nether_wart_block)
B(1,20,8,minecraft:nether_wart_block)
B(2,20,8,minecraft:nether_wart_block)
B(3,20,8,minecraft:nether_wart_block)
B(4,20,8,minecraft:nether_wart_block)
B(5,20,8,minecraft:nether_wart_block)
B(0,20,9,minecraft:nether_wart_block)
B(1,20,9,minecraft:nether_wart_block)
B(2,20,9,minecraft:nether_wart_block)
B(0,21,0,minecraft:nether_wart_block)
B(1,21,0,minecraft:nether_wart_block)
B(2,21,0,minecraft:nether_wart_block)
B(3,21,0,minecraft:nether_wart_block)
B(4,21,0,minecraft:nether_wart_block)
B(5,21,0,minecraft:nether_wart_block)
B(6,21,0,minecraft:nether_wart_block)
B(7,21,0,minecraft:nether_wart_block)
B(8,21,0,minecraft:nether_wart_block)
B(9,21,0,minecraft:nether_wart_block)
B(10,21,0,minecraft:nether_wart_block)
B(11,21,0,minecraft:nether_wart_block)
B(0,21,1,minecraft:nether_wart_block)
B(1,21,1,minecraft:nether_wart_block)
B(2,21,1,minecraft:nether_wart_block)
B(3,21,1,minecraft:nether_wart_block)
B(4,21,1,minecraft:nether_wart_block)
B(5,21,1,minecraft:nether_wart_block)
B(6,21,1,minecraft:nether_wart_block)
B(7,21,1,minecraft:nether_wart_block)
B(8,21,1,minecraft:nether_wart_block)
B(9,21,1,minecraft:nether_wart_block)
B(10,21,1,minecraft:nether_wart_block)
B(0,21,2,minecraft:nether_wart_block)
B(1,21,2,minecraft:nether_wart_block)
B(2,21,2,minecraft:nether_wart_block)
B(3,21,2,minecraft:nether_wart_block)
B(4,21,2,minecraft:nether_wart_block)
B(5,21,2,minecraft:nether_wart_block)
B(6,21,2,minecraft:nether_wart_block)
B(7,21,2,minecraft:nether_wart_block)
B(8,21,2,minecraft:nether_wart_block)
B(9,21,2,minecraft:nether_wart_block)
B(0,21,3,minecraft:nether_wart_block)
B(1,21,3,minecraft:nether_wart_block)
B(2,21,3,minecraft:nether_wart_block)
B(3,21,3,minecraft:nether_wart_block)
B(4,21,3,minecraft:nether_wart_block)
B(5,21,3,minecraft:nether_wart_block)
B(6,21,3,minecraft:nether_wart_block)
B(7,21,3,minecraft:nether_wart_block)
B(8,21,3,minecraft:nether_wart_block)
B(0,21,4,minecraft:nether_wart_block)
B(1,21,4,minecraft:nether_wart_block)
B(2,21,4,minecraft:nether_wart_block)
B(3,21,4,minecraft:nether_wart_block)
B(4,21,4,minecraft:nether_wart_block)
B(5,21,4,minecraft:nether_wart_block)
B(6,21,4,minecraft:nether_wart_block)
B(7,21,4,minecraft:nether_wart_block)
B(0,21,5,minecraft:nether_wart_block)
B(1,21,5,minecraft:nether_wart_block)
B(2,21,5,minecraft:nether_wart_block)
B(3,21,5,minecraft:nether_wart_block)
B(4,21,5,minecraft:nether_wart_block)
B(5,21,5,minecraft:nether_wart_block)
B(6,21,5,minecraft:nether_wart_block)
B(7,21,5,minecraft:nether_wart_block)
B(0,21,6,minecraft:nether_wart_block)
B(1,21,6,minecraft:nether_wart_block)
B(2,21,6,minecraft:nether_wart_block)
B(3,21,6,minecraft:nether_wart_block)
B(4,21,6,minecraft:nether_wart_block)
B(5,21,6,minecraft:nether_wart_block)
B(0,21,7,minecraft:nether_wart_block)
B(1,21,7,minecraft:nether_wart_block)
B(2,21,7,minecraft:nether_wart_block)
B(3,21,7,minecraft:nether_wart_block)
B(4,21,7,minecraft:nether_wart_block)
B(5,21,7,minecraft:nether_wart_block)
B(0,21,8,minecraft:nether_wart_block)
B(1,21,8,minecraft:nether_wart_block)
B(2,21,8,minecraft:nether_wart_block)
B(0,22,0,minecraft:nether_wart_block)
B(1,22,0,minecraft:nether_wart_block)
B(2,22,0,minecraft:nether_wart_block)
B(3,22,0,minecraft:nether_wart_block)
B(4,22,0,minecraft:nether_wart_block)
B(5,22,0,minecraft:nether_wart_block)
B(6,22,0,minecraft:nether_wart_block)
B(7,22,0,minecraft:nether_wart_block)
B(8,22,0,minecraft:nether_wart_block)
B(9,22,0,minecraft:nether_wart_block)
B(10,22,0,minecraft:nether_wart_block)
B(0,22,1,minecraft:nether_wart_block)
B(1,22,1,minecraft:nether_wart_block)
B(2,22,1,minecraft:nether_wart_block)
B(3,22,1,minecraft:nether_wart_block)
B(4,22,1,minecraft:nether_wart_block)
B(5,22,1,minecraft:nether_wart_block)
B(6,22,1,minecraft:nether_wart_block)
B(7,22,1,minecraft:nether_wart_block)
B(8,22,1,minecraft:nether_wart_block)
B(9,22,1,minecraft:nether_wart_block)
B(0,22,2,minecraft:nether_wart_block)
B(1,22,2,minecraft:nether_wart_block)
B(2,22,2,minecraft:nether_wart_block)
B(3,22,2,minecraft:nether_wart_block)
B(4,22,2,minecraft:nether_wart_block)
B(5,22,2,minecraft:nether_wart_block)
B(6,22,2,minecraft:nether_wart_block)
B(7,22,2,minecraft:nether_wart_block)
B(8,22,2,minecraft:nether_wart_block)
B(0,22,3,minecraft:nether_wart_block)
B(1,22,3,minecraft:nether_wart_block)
B(2,22,3,minecraft:nether_wart_block)
B(3,22,3,minecraft:nether_wart_block)
B(4,22,3,minecraft:nether_wart_block)
B(5,22,3,minecraft:nether_wart_block)
B(6,22,3,minecraft:nether_wart_block)
B(7,22,3,minecraft:nether_wart_block)
B(0,22,4,minecraft:nether_wart_block)
B(1,22,4,minecraft:nether_wart_block)
B(2,22,4,minecraft:nether_wart_block)
B(3,22,4,minecraft:nether_wart_block)
B(4,22,4,minecraft:nether_wart_block)
B(5,22,4,minecraft:nether_wart_block)
B(6,22,4,minecraft:nether_wart_block)
B(7,22,4,minecraft:nether_wart_block)
B(0,22,5,minecraft:nether_wart_block)
B(1,22,5,minecraft:nether_wart_block)
B(2,22,5,minecraft:nether_wart_block)
B(3,22,5,minecraft:nether_wart_block)
B(4,22,5,minecraft:nether_wart_block)
B(5,22,5,minecraft:nether_wart_block)
B(6,22,5,minecraft:nether_wart_block)
B(0,22,6,minecraft:nether_wart_block)
B(1,22,6,minecraft:nether_wart_block)
B(2,22,6,minecraft:nether_wart_block)
B(3,22,6,minecraft:nether_wart_block)
B(4,22,6,minecraft:nether_wart_block)
B(5,22,6,minecraft:nether_wart_block)
B(0,22,7,minecraft:nether_wart_block)
B(1,22,7,minecraft:nether_wart_block)
B(2,22,7,minecraft:nether_wart_block)
B(0,23,0,minecraft:nether_wart_block)
B(1,23,0,minecraft:nether_wart_block)
B(2,23,0,minecraft:nether_wart_block)
B(3,23,0,minecraft:nether_wart_block)
B(4,23,0,minecraft:nether_wart_block)
B(5,23,0,minecraft:nether_wart_block)
B(6,23,0,minecraft:nether_wart_block)
B(7,23,0,minecraft:nether_wart_block)
B(8,23,0,minecraft:nether_wart_block)
B(9,23,0,minecraft:nether_wart_block)
B(0,23,1,minecraft:nether_wart_block)
B(1,23,1,minecraft:nether_wart_block)
B(2,23,1,minecraft:nether_wart_block)
B(3,23,1,minecraft:nether_wart_block)
B(4,23,1,minecraft:nether_wart_block)
B(5,23,1,minecraft:nether_wart_block)
B(6,23,1,minecraft:nether_wart_block)
B(7,23,1,minecraft:nether_wart_block)
B(8,23,1,minecraft:nether_wart_block)
B(0,23,2,minecraft:nether_wart_block)
B(1,23,2,minecraft:nether_wart_block)
B(2,23,2,minecraft:nether_wart_block)
B(3,23,2,minecraft:nether_wart_block)
B(4,23,2,minecraft:nether_wart_block)
B(5,23,2,minecraft:nether_wart_block)
B(6,23,2,minecraft:nether_wart_block)
B(7,23,2,minecraft:nether_wart_block)
B(0,23,3,minecraft:nether_wart_block)
B(1,23,3,minecraft:nether_wart_block)
B(2,23,3,minecraft:nether_wart_block)
B(3,23,3,minecraft:nether_wart_block)
B(4,23,3,minecraft:nether_wart_block)
B(5,23,3,minecraft:nether_wart_block)
B(6,23,3,minecraft:nether_wart_block)
B(0,23,4,minecraft:nether_wart_block)
B(1,23,4,minecraft:nether_wart_block)
B(2,23,4,minecraft:nether_wart_block)
B(3,23,4,minecraft:nether_wart_block)
B(4,23,4,minecraft:nether_wart_block)
B(5,23,4,minecraft:nether_wart_block)
B(6,23,4,minecraft:nether_wart_block)
B(0,23,5,minecraft:nether_wart_block)
B(1,23,5,minecraft:nether_wart_block)
B(2,23,5,minecraft:nether_wart_block)
B(3,23,5,minecraft:nether_wart_block)
B(4,23,5,minecraft:nether_wart_block)
B(5,23,5,minecraft:nether_wart_block)
B(0,23,6,minecraft:nether_wart_block)
B(1,23,6,minecraft:nether_wart_block)
B(2,23,6,minecraft:nether_wart_block)
B(3,23,6,minecraft:nether_wart_block)
B(0,24,0,minecraft:nether_wart_block)
B(1,24,0,minecraft:nether_wart_block)
B(2,24,0,minecraft:nether_wart_block)
B(3,24,0,minecraft:nether_wart_block)
B(4,24,0,minecraft:nether_wart_block)
B(5,24,0,minecraft:nether_wart_block)
B(6,24,0,minecraft:nether_wart_block)
B(7,24,0,minecraft:nether_wart_block)
B(8,24,0,minecraft:nether_wart_block)
B(0,24,1,minecraft:nether_wart_block)
B(1,24,1,minecraft:nether_wart_block)
B(2,24,1,minecraft:nether_wart_block)
B(3,24,1,minecraft:nether_wart_block)
B(4,24,1,minecraft:nether_wart_block)
B(5,24,1,minecraft:nether_wart_block)
B(6,24,1,minecraft:nether_wart_block)
B(7,24,1,minecraft:nether_wart_block)
B(8,24,1,minecraft:nether_wart_block)
B(0,24,2,minecraft:nether_wart_block)
B(1,24,2,minecraft:nether_wart_block)
B(2,24,2,minecraft:nether_wart_block)
B(3,24,2,minecraft:nether_wart_block)
B(4,24,2,minecraft:nether_wart_block)
B(5,24,2,minecraft:nether_wart_block)
B(6,24,2,minecraft:nether_wart_block)
B(7,24,2,minecraft:nether_wart_block)
B(0,24,3,minecraft:nether_wart_block)
B(1,24,3,minecraft:nether_wart_block)
B(2,24,3,minecraft:nether_wart_block)
B(3,24,3,minecraft:nether_wart_block)
B(4,24,3,minecraft:nether_wart_block)
B(5,24,3,minecraft:nether_wart_block)
B(6,24,3,minecraft:nether_wart_block)
B(0,24,4,minecraft:nether_wart_block)
B(1,24,4,minecraft:nether_wart_block)
B(2,24,4,minecraft:nether_wart_block)
B(3,24,4,minecraft:nether_wart_block)
B(4,24,4,minecraft:nether_wart_block)
B(5,24,4,minecraft:nether_wart_block)
B(0,24,5,minecraft:nether_wart_block)
B(1,24,5,minecraft:nether_wart_block)
B(2,24,5,minecraft:nether_wart_block)
B(3,24,5,minecraft:nether_wart_block)
B(4,24,5,minecraft:nether_wart_block)
B(0,25,0,minecraft:nether_wart_block)
B(1,25,0,minecraft:nether_wart_block)
B(2,25,0,minecraft:nether_wart_block)
B(3,25,0,minecraft:nether_wart_block)
B(4,25,0,minecraft:nether_wart_block)
B(5,25,0,minecraft:nether_wart_block)
B(6,25,0,minecraft:nether_wart_block)
B(7,25,0,minecraft:nether_wart_block)
B(8,25,0,minecraft:nether_wart_block)
B(0,25,1,minecraft:nether_wart_block)
B(1,25,1,minecraft:nether_wart_block)
B(2,25,1,minecraft:nether_wart_block)
B(3,25,1,minecraft:nether_wart_block)
B(4,25,1,minecraft:nether_wart_block)
B(5,25,1,minecraft:nether_wart_block)
B(6,25,1,minecraft:nether_wart_block)
B(7,25,1,minecraft:nether_wart_block)
B(0,25,2,minecraft:nether_wart_block)
B(1,25,2,minecraft:nether_wart_block)
B(2,25,2,minecraft:nether_wart_block)
B(3,25,2,minecraft:nether_wart_block)
B(4,25,2,minecraft:nether_wart_block)
B(5,25,2,minecraft:nether_wart_block)
B(6,25,2,minecraft:nether_wart_block)
B(0,25,3,minecraft:nether_wart_block)
B(1,25,3,minecraft:nether_wart_block)
B(2,25,3,minecraft:nether_wart_block)
B(3,25,3,minecraft:nether_wart_block)
B(4,25,3,minecraft:nether_wart_block)
B(5,25,3,minecraft:nether_wart_block)
B(0,25,4,minecraft:nether_wart_block)
B(1,25,4,minecraft:nether_wart_block)
B(2,25,4,minecraft:nether_wart_block)
B(3,25,4,minecraft:nether_wart_block)
B(4,25,4,minecraft:nether_wart_block)
B(5,25,4,minecraft:nether_wart_block)
B(0,25,5,minecraft:nether_wart_block)
B(1,25,5,minecraft:nether_wart_block)
B(2,25,5,minecraft:nether_wart_block)
B(3,25,5,minecraft:nether_wart_block)
B(4,25,5,minecraft:nether_wart_block)
B(0,26,0,minecraft:nether_wart_block)
B(1,26,0,minecraft:nether_wart_block)
B(2,26,0,minecraft:nether_wart_block)
B(3,26,0,minecraft:nether_wart_block)
B(4,26,0,minecraft:nether_wart_block)
B(5,26,0,minecraft:nether_wart_block)
B(6,26,0,minecraft:nether_wart_block)
B(7,26,0,minecraft:nether_wart_block)
B(0,26,1,minecraft:nether_wart_block)
B(1,26,1,minecraft:nether_wart_block)
B(2,26,1,minecraft:nether_wart_block)
B(3,26,1,minecraft:nether_wart_block)
B(4,26,1,minecraft:nether_wart_block)
B(5,26,1,minecraft:nether_wart_block)
B(6,26,1,minecraft:nether_wart_block)
B(0,26,2,minecraft:nether_wart_block)
B(1,26,2,minecraft:nether_wart_block)
B(2,26,2,minecraft:nether_wart_block)
B(3,26,2,minecraft:nether_wart_block)
B(4,26,2,minecraft:nether_wart_block)
B(5,26,2,minecraft:nether_wart_block)
B(0,26,3,minecraft:nether_wart_block)
B(1,26,3,minecraft:nether_wart_block)
B(2,26,3,minecraft:nether_wart_block)
B(3,26,3,minecraft:nether_wart_block)
B(4,26,3,minecraft:nether_wart_block)
B(5,26,3,minecraft:nether_wart_block)
B(0,26,4,minecraft:nether_wart_block)
B(1,26,4,minecraft:nether_wart_block)
B(2,26,4,minecraft:nether_wart_block)
B(3,26,4,minecraft:nether_wart_block)
B(0,26,5,minecraft:nether_wart_block)
