Author: Bo3 BulkEdit

Description: Converted Schematic - Modified by Bo3BulkEdit

Version: 3

SettingsMode: WriteDisable

IsOTGPlus: true
Tree: false
Frequency: 10
Rarity: 100
RotateRandomly: true
SpawnHeight: randomY
SpawnHeightOffset: 0
SpawnHeightVariance: 0
MaxBranchDepth: 10
ExcludedBiomes: All

MinHeight: 50
MaxHeight: 65

SourceBlocks: AIR
MaxPercentageOutsideSourceBlock: 100
OutsideSourceBlock: placeAnyway

ReplaceBelow: NETHER_WART_BLOCK
ReplaceWithBiomeBlocks: false
ReplaceWithGroundBlock: NETHER_WART_BLOCK
ReplaceWithSurfaceBlock: NETHER_WART_BLOCK
ReplaceWithStoneBlock: NETHER_WART_BLOCK
SmoothRadius: 30
SmoothHeightOffset: 0
SmoothStartTop: false
SmoothStartWood: false
SmoothingSurfaceBlock: NETHER_WART_BLOCK
SmoothingGroundBlock: NETHER_WART_BLOCK

B(0,750,0,AIR)
B(15,750,15,AIR)
B(6,0,0,minecraft:nether_wart_block)
B(7,0,0,minecraft:nether_wart_block)
B(8,0,0,minecraft:nether_wart_block)
B(9,0,0,minecraft:nether_wart_block)
B(10,0,0,minecraft:nether_wart_block)
B(11,0,0,minecraft:nether_wart_block)
B(12,0,0,minecraft:nether_wart_block)
B(13,0,0,minecraft:nether_wart_block)
B(14,0,0,minecraft:nether_quartz_ore)
B(15,0,0,minecraft:nether_quartz_ore)
B(6,0,1,minecraft:nether_wart_block)
B(7,0,1,minecraft:nether_wart_block)
B(8,0,1,minecraft:nether_wart_block)
B(9,0,1,minecraft:nether_wart_block)
B(10,0,1,minecraft:nether_wart_block)
B(11,0,1,minecraft:nether_wart_block)
B(12,0,1,minecraft:nether_wart_block)
B(13,0,1,minecraft:nether_wart_block)
B(14,0,1,minecraft:nether_wart_block)
B(15,0,1,minecraft:nether_quartz_ore)
B(5,0,2,minecraft:nether_wart_block)
B(6,0,2,minecraft:nether_wart_block)
B(7,0,2,minecraft:nether_wart_block)
B(8,0,2,minecraft:nether_wart_block)
B(9,0,2,minecraft:nether_wart_block)
B(10,0,2,minecraft:nether_wart_block)
B(11,0,2,minecraft:nether_wart_block)
B(12,0,2,minecraft:nether_wart_block)
B(13,0,2,minecraft:nether_wart_block)
B(14,0,2,minecraft:nether_wart_block)
B(15,0,2,minecraft:nether_quartz_ore)
B(5,0,3,minecraft:nether_wart_block)
B(6,0,3,minecraft:nether_wart_block)
B(7,0,3,minecraft:nether_wart_block)
B(8,0,3,minecraft:nether_wart_block)
B(9,0,3,minecraft:nether_wart_block)
B(10,0,3,minecraft:nether_wart_block)
B(11,0,3,minecraft:nether_wart_block)
B(12,0,3,minecraft:nether_wart_block)
B(13,0,3,minecraft:nether_wart_block)
B(14,0,3,minecraft:nether_wart_block)
B(15,0,3,minecraft:nether_quartz_ore)
B(8,0,4,minecraft:nether_wart_block)
B(9,0,4,minecraft:nether_wart_block)
B(10,0,4,minecraft:nether_wart_block)
B(11,0,4,minecraft:nether_wart_block)
B(12,0,4,minecraft:nether_wart_block)
B(13,0,4,minecraft:nether_wart_block)
B(14,0,4,minecraft:nether_wart_block)
B(15,0,4,minecraft:nether_wart_block)
B(6,1,0,minecraft:nether_wart_block)
B(8,1,0,minecraft:nether_wart_block)
B(9,1,0,minecraft:nether_wart_block)
B(10,1,0,minecraft:nether_wart_block)
B(11,1,0,minecraft:nether_wart_block)
B(12,1,0,minecraft:nether_wart_block)
B(13,1,0,minecraft:nether_wart_block)
B(14,1,0,minecraft:nether_wart_block)
B(15,1,0,minecraft:nether_wart_block)
B(8,1,1,minecraft:nether_wart_block)
B(9,1,1,minecraft:nether_wart_block)
B(10,1,1,minecraft:nether_wart_block)
B(11,1,1,minecraft:nether_wart_block)
B(12,1,1,minecraft:nether_wart_block)
B(13,1,1,minecraft:nether_wart_block)
B(14,1,1,minecraft:nether_wart_block)
B(15,1,1,minecraft:nether_wart_block)
B(9,1,2,minecraft:nether_wart_block)
B(10,1,2,minecraft:nether_wart_block)
B(11,1,2,minecraft:nether_wart_block)
B(12,1,2,minecraft:nether_wart_block)
B(13,1,2,minecraft:nether_wart_block)
B(14,1,2,minecraft:nether_wart_block)
B(15,1,2,minecraft:nether_quartz_ore)
B(10,1,3,minecraft:nether_wart_block)
B(11,1,3,minecraft:nether_wart_block)
B(12,1,3,minecraft:nether_wart_block)
B(13,1,3,minecraft:nether_wart_block)
B(14,1,3,minecraft:nether_wart_block)
B(15,1,3,minecraft:nether_wart_block)
B(10,1,4,minecraft:nether_wart_block)
B(11,1,4,minecraft:nether_wart_block)
B(14,1,4,minecraft:nether_wart_block)
B(15,1,4,minecraft:nether_wart_block)
B(1,2,0,minecraft:nether_wart_block)
B(5,2,0,minecraft:nether_wart_block)
B(9,2,0,minecraft:nether_wart_block)
B(10,2,0,minecraft:nether_wart_block)
B(11,2,0,minecraft:nether_wart_block)
B(12,2,0,minecraft:nether_wart_block)
B(13,2,0,minecraft:nether_wart_block)
B(14,2,0,minecraft:nether_wart_block)
B(15,2,0,minecraft:nether_wart_block)
B(10,2,1,minecraft:nether_wart_block)
B(11,2,1,minecraft:nether_wart_block)
B(12,2,1,minecraft:nether_wart_block)
B(13,2,1,minecraft:nether_wart_block)
B(14,2,1,minecraft:nether_wart_block)
B(15,2,1,minecraft:nether_wart_block)
B(11,2,2,minecraft:nether_wart_block)
B(12,2,2,minecraft:nether_wart_block)
B(13,2,2,minecraft:nether_wart_block)
B(14,2,2,minecraft:nether_wart_block)
B(15,2,2,minecraft:nether_wart_block)
B(13,2,3,minecraft:nether_wart_block)
B(14,2,3,minecraft:nether_wart_block)
B(15,2,3,minecraft:nether_wart_block)
B(14,2,4,minecraft:nether_wart_block)
B(15,2,4,minecraft:nether_wart_block)
B(2,3,0,minecraft:nether_wart_block)
B(3,3,0,minecraft:nether_wart_block)
B(4,3,0,minecraft:nether_wart_block)
B(10,3,0,minecraft:nether_wart_block)
B(11,3,0,minecraft:nether_wart_block)
B(12,3,0,minecraft:nether_wart_block)
B(13,3,0,minecraft:nether_wart_block)
B(11,3,1,minecraft:nether_wart_block)

BR(-16,0,0,true,FleshVolcano2_0x4,NORTH,100,0)
