Author: Bo3 BulkEdit

Description: Converted Schematic - Modified by Bo3BulkEdit

Version: 3

SettingsMode: WriteDisable

IsOTGPlus: true
Tree: false
Frequency: 10
Rarity: 100
RotateRandomly: true
SpawnHeight: randomY
SpawnHeightOffset: 0
SpawnHeightVariance: 0
MaxBranchDepth: 10
ExcludedBiomes: All

MinHeight: 50
MaxHeight: 65

SourceBlocks: AIR
MaxPercentageOutsideSourceBlock: 100
OutsideSourceBlock: placeAnyway

ReplaceBelow: NETHER_WART_BLOCK
ReplaceWithBiomeBlocks: false
ReplaceWithGroundBlock: NETHER_WART_BLOCK
ReplaceWithSurfaceBlock: NETHER_WART_BLOCK
ReplaceWithStoneBlock: NETHER_WART_BLOCK
SmoothRadius: 30
SmoothHeightOffset: 0
SmoothStartTop: false
SmoothStartWood: false
SmoothingSurfaceBlock: NETHER_WART_BLOCK
SmoothingGroundBlock: NETHER_WART_BLOCK

B(0,750,0,AIR)
B(15,750,15,AIR)
B(0,0,0,minecraft:nether_wart_block)
B(1,0,0,minecraft:nether_wart_block)
B(5,0,0,minecraft:nether_wart_block)
B(0,0,1,minecraft:nether_wart_block)
B(0,0,6,minecraft:nether_wart_block)
B(0,0,7,minecraft:nether_wart_block)
B(1,0,7,minecraft:nether_wart_block)
B(0,0,11,minecraft:nether_wart_block)
B(1,0,11,minecraft:lava[level=8])
B(0,0,12,minecraft:nether_wart_block)
B(1,0,12,minecraft:nether_wart_block)
B(2,0,12,minecraft:lava[level=8])
B(0,0,13,minecraft:nether_wart_block)
B(1,0,13,minecraft:nether_wart_block)
B(2,0,13,minecraft:lava[level=8])
B(0,0,14,minecraft:nether_wart_block)
B(1,0,14,minecraft:nether_wart_block)
B(2,0,14,minecraft:lava[level=8])
B(0,0,15,minecraft:nether_wart_block)
B(1,0,15,minecraft:nether_wart_block)
B(2,0,15,minecraft:lava[level=8])
B(0,1,11,minecraft:nether_wart_block)
B(1,1,11,minecraft:lava[level=2])
B(0,1,12,minecraft:nether_wart_block)
B(1,1,12,minecraft:lava[level=8])
B(2,1,12,minecraft:lava[level=2])
B(0,1,13,minecraft:nether_wart_block)
B(1,1,13,minecraft:nether_wart_block)
B(2,1,13,minecraft:lava[level=8])
B(0,1,14,minecraft:nether_wart_block)
B(1,1,14,minecraft:nether_wart_block)
B(2,1,14,minecraft:lava[level=8])
B(0,1,15,minecraft:nether_wart_block)
B(1,1,15,minecraft:nether_wart_block)
B(2,1,15,minecraft:lava[level=8])
B(0,2,12,minecraft:nether_wart_block)
B(1,2,12,minecraft:lava[level=2])
B(0,2,13,minecraft:nether_wart_block)
B(1,2,13,minecraft:lava[level=8])
B(2,2,13,minecraft:lava[level=2])
B(0,2,14,minecraft:nether_wart_block)
B(1,2,14,minecraft:lava[level=8])
B(2,2,14,minecraft:lava[level=2])
B(0,2,15,minecraft:nether_wart_block)
B(1,2,15,minecraft:lava[level=8])
B(2,2,15,minecraft:lava[level=2])
B(0,3,13,minecraft:lava[level=8])
B(1,3,13,minecraft:lava[level=2])
B(0,3,14,minecraft:lava[level=8])
B(1,3,14,minecraft:lava[level=2])
B(0,3,15,minecraft:lava[level=8])
B(1,3,15,minecraft:lava[level=2])
B(0,4,13,minecraft:lava[level=2])
B(0,4,14,minecraft:lava[level=2])
B(0,4,15,minecraft:lava[level=2])

