#######################################################################
# +-----------------------------------------------------------------+ #
# |                            BO3 object                           | #
# +-----------------------------------------------------------------+ #
#######################################################################

Author: Bo3 BulkEdit

Description: Converted Schematic - Modified by Bo3BulkEdit

Version: 3

SettingsMode: WriteDisable

#######################################################################
# +-----------------------------------------------------------------+ #
# |                          Main settings                          | #
# +-----------------------------------------------------------------+ #
#######################################################################

IsOTGPlus: true
Tree: true
Frequency: 10
Rarity: 100
RotateRandomly: true
SpawnHeight: randomY
SpawnHeightOffset: 0
SpawnHeightVariance: 0
MaxBranchDepth: 10
ExcludedBiomes: All

##############################
# Height Limits for the BO3. #
##############################

MinHeight: 50
MaxHeight: 65

#######################################################################
# +-----------------------------------------------------------------+ #
# |                      Source block settings                      | #
# +-----------------------------------------------------------------+ #
#######################################################################

SourceBlocks: AIR
MaxPercentageOutsideSourceBlock: 100
OutsideSourceBlock: placeAnyway

#######################################################################
# +-----------------------------------------------------------------+ #
# |                               OTG+                              | #
# +-----------------------------------------------------------------+ #
#######################################################################

RemoveAir: true
ReplaceBelow: OBSIDIAN
ReplaceWithBiomeBlocks: false
ReplaceWithGroundBlock: OBSIDIAN
ReplaceWithSurfaceBlock: OBSIDIAN
ReplaceWithStoneBlock: OBSIDIAN
SmoothRadius: 30
SmoothingSurfaceBlock: OBSIDIAN
SmoothingGroundBlock: OBSIDIAN

#######################################################################
# +-----------------------------------------------------------------+ #
# |                              Blocks                             | #
# +-----------------------------------------------------------------+ #
#######################################################################

RB(0,0,0,minecraft:crying_obsidian,20,minecraft:obsidian,100)
RB(1,0,0,minecraft:crying_obsidian,20,minecraft:obsidian,100)
RB(2,0,0,minecraft:crying_obsidian,20,minecraft:obsidian,100)
RB(3,0,0,minecraft:crying_obsidian,20,minecraft:obsidian,100)
RB(4,0,0,minecraft:crying_obsidian,20,minecraft:obsidian,100)
RB(5,0,0,minecraft:crying_obsidian,20,minecraft:obsidian,100)
RB(6,0,0,minecraft:crying_obsidian,20,minecraft:obsidian,100)
RB(7,0,0,minecraft:crying_obsidian,20,minecraft:obsidian,100)
RB(8,0,0,minecraft:crying_obsidian,20,minecraft:obsidian,100)
RB(9,0,0,minecraft:crying_obsidian,20,minecraft:obsidian,100)
RB(10,0,0,minecraft:crying_obsidian,20,minecraft:obsidian,100)
RB(0,0,1,minecraft:crying_obsidian,20,minecraft:obsidian,100)
RB(1,0,1,minecraft:crying_obsidian,20,minecraft:obsidian,100)
RB(2,0,1,minecraft:crying_obsidian,20,minecraft:obsidian,100)
RB(3,0,1,minecraft:crying_obsidian,20,minecraft:obsidian,100)
RB(4,0,1,minecraft:crying_obsidian,20,minecraft:obsidian,100)
RB(5,0,1,minecraft:crying_obsidian,20,minecraft:obsidian,100)
RB(6,0,1,minecraft:crying_obsidian,20,minecraft:obsidian,100)
RB(7,0,1,minecraft:crying_obsidian,20,minecraft:obsidian,100)
RB(8,0,1,minecraft:crying_obsidian,20,minecraft:obsidian,100)
RB(9,0,1,minecraft:crying_obsidian,20,minecraft:obsidian,100)
RB(0,0,2,minecraft:crying_obsidian,20,minecraft:obsidian,100)
RB(1,0,2,minecraft:crying_obsidian,20,minecraft:obsidian,100)
RB(2,0,2,minecraft:crying_obsidian,20,minecraft:obsidian,100)
RB(3,0,2,minecraft:crying_obsidian,20,minecraft:obsidian,100)
RB(4,0,2,minecraft:crying_obsidian,20,minecraft:obsidian,100)
RB(5,0,2,minecraft:crying_obsidian,20,minecraft:obsidian,100)
RB(6,0,2,minecraft:crying_obsidian,20,minecraft:obsidian,100)
RB(7,0,2,minecraft:crying_obsidian,20,minecraft:obsidian,100)
RB(8,0,2,minecraft:crying_obsidian,20,minecraft:obsidian,100)
RB(0,0,3,minecraft:crying_obsidian,20,minecraft:obsidian,100)
RB(1,0,3,minecraft:crying_obsidian,20,minecraft:obsidian,100)
RB(2,0,3,minecraft:crying_obsidian,20,minecraft:obsidian,100)
RB(3,0,3,minecraft:crying_obsidian,20,minecraft:obsidian,100)
RB(4,0,3,minecraft:crying_obsidian,20,minecraft:obsidian,100)
RB(5,0,3,minecraft:crying_obsidian,20,minecraft:obsidian,100)
RB(6,0,3,minecraft:crying_obsidian,20,minecraft:obsidian,100)
RB(7,0,3,minecraft:crying_obsidian,20,minecraft:obsidian,100)
RB(8,0,3,minecraft:crying_obsidian,20,minecraft:obsidian,100)
RB(0,0,4,minecraft:crying_obsidian,20,minecraft:obsidian,100)
RB(1,0,4,minecraft:crying_obsidian,20,minecraft:obsidian,100)
RB(2,0,4,minecraft:crying_obsidian,20,minecraft:obsidian,100)
RB(3,0,4,minecraft:crying_obsidian,20,minecraft:obsidian,100)
RB(4,0,4,minecraft:crying_obsidian,20,minecraft:obsidian,100)
RB(5,0,4,minecraft:crying_obsidian,20,minecraft:obsidian,100)
RB(6,0,4,minecraft:crying_obsidian,20,minecraft:obsidian,100)
RB(7,0,4,minecraft:crying_obsidian,20,minecraft:obsidian,100)
RB(8,0,4,minecraft:crying_obsidian,20,minecraft:obsidian,100)
RB(0,0,5,minecraft:crying_obsidian,20,minecraft:obsidian,100)
RB(1,0,5,minecraft:crying_obsidian,20,minecraft:obsidian,100)
RB(2,0,5,minecraft:crying_obsidian,20,minecraft:obsidian,100)
RB(3,0,5,minecraft:crying_obsidian,20,minecraft:obsidian,100)
RB(4,0,5,minecraft:crying_obsidian,20,minecraft:obsidian,100)
RB(5,0,5,minecraft:crying_obsidian,20,minecraft:obsidian,100)
RB(6,0,5,minecraft:crying_obsidian,20,minecraft:obsidian,100)
RB(7,0,5,minecraft:crying_obsidian,20,minecraft:obsidian,100)
RB(8,0,5,minecraft:crying_obsidian,20,minecraft:obsidian,100)
RB(9,0,5,minecraft:crying_obsidian,20,minecraft:obsidian,100)
RB(10,0,5,minecraft:crying_obsidian,20,minecraft:obsidian,100)
RB(0,0,6,minecraft:crying_obsidian,20,minecraft:obsidian,100)
RB(1,0,6,minecraft:crying_obsidian,20,minecraft:obsidian,100)
RB(2,0,6,minecraft:crying_obsidian,20,minecraft:obsidian,100)
RB(3,0,6,minecraft:crying_obsidian,20,minecraft:obsidian,100)
RB(4,0,6,minecraft:crying_obsidian,20,minecraft:obsidian,100)
RB(5,0,6,minecraft:crying_obsidian,20,minecraft:obsidian,100)
RB(6,0,6,minecraft:crying_obsidian,20,minecraft:obsidian,100)
RB(7,0,6,minecraft:crying_obsidian,20,minecraft:obsidian,100)
RB(8,0,6,minecraft:crying_obsidian,20,minecraft:obsidian,100)
RB(9,0,6,minecraft:crying_obsidian,20,minecraft:obsidian,100)
RB(10,0,6,minecraft:crying_obsidian,20,minecraft:obsidian,100)
RB(0,0,7,minecraft:crying_obsidian,20,minecraft:obsidian,100)
RB(1,0,7,minecraft:crying_obsidian,20,minecraft:obsidian,100)
RB(2,0,7,minecraft:crying_obsidian,20,minecraft:obsidian,100)
RB(3,0,7,minecraft:crying_obsidian,20,minecraft:obsidian,100)
RB(4,0,7,minecraft:crying_obsidian,20,minecraft:obsidian,100)
RB(5,0,7,minecraft:crying_obsidian,20,minecraft:obsidian,100)
RB(6,0,7,minecraft:crying_obsidian,20,minecraft:obsidian,100)
RB(7,0,7,minecraft:crying_obsidian,20,minecraft:obsidian,100)
RB(8,0,7,minecraft:crying_obsidian,20,minecraft:obsidian,100)
RB(9,0,7,minecraft:crying_obsidian,20,minecraft:obsidian,100)
RB(10,0,7,minecraft:crying_obsidian,20,minecraft:obsidian,100)
RB(0,0,8,minecraft:crying_obsidian,20,minecraft:obsidian,100)
RB(1,0,8,minecraft:crying_obsidian,20,minecraft:obsidian,100)
RB(2,0,8,minecraft:crying_obsidian,20,minecraft:obsidian,100)
RB(3,0,8,minecraft:crying_obsidian,20,minecraft:obsidian,100)
RB(4,0,8,minecraft:crying_obsidian,20,minecraft:obsidian,100)
RB(5,0,8,minecraft:crying_obsidian,20,minecraft:obsidian,100)
RB(6,0,8,minecraft:crying_obsidian,20,minecraft:obsidian,100)
RB(7,0,8,minecraft:crying_obsidian,20,minecraft:obsidian,100)
RB(8,0,8,minecraft:crying_obsidian,20,minecraft:obsidian,100)
RB(9,0,8,minecraft:crying_obsidian,20,minecraft:obsidian,100)
RB(10,0,8,minecraft:crying_obsidian,20,minecraft:obsidian,100)
RB(11,0,8,minecraft:crying_obsidian,20,minecraft:obsidian,100)
RB(0,0,9,minecraft:crying_obsidian,20,minecraft:obsidian,100)
RB(1,0,9,minecraft:crying_obsidian,20,minecraft:obsidian,100)
RB(2,0,9,minecraft:crying_obsidian,20,minecraft:obsidian,100)
RB(3,0,9,minecraft:crying_obsidian,20,minecraft:obsidian,100)
RB(4,0,9,minecraft:crying_obsidian,20,minecraft:obsidian,100)
RB(5,0,9,minecraft:crying_obsidian,20,minecraft:obsidian,100)
RB(6,0,9,minecraft:crying_obsidian,20,minecraft:obsidian,100)
RB(7,0,9,minecraft:crying_obsidian,20,minecraft:obsidian,100)
RB(8,0,9,minecraft:crying_obsidian,20,minecraft:obsidian,100)
RB(9,0,9,minecraft:crying_obsidian,20,minecraft:obsidian,100)
RB(10,0,9,minecraft:crying_obsidian,20,minecraft:obsidian,100)
RB(11,0,9,minecraft:crying_obsidian,20,minecraft:obsidian,100)
RB(0,0,10,minecraft:crying_obsidian,20,minecraft:obsidian,100)
RB(1,0,10,minecraft:crying_obsidian,20,minecraft:obsidian,100)
RB(2,0,10,minecraft:crying_obsidian,20,minecraft:obsidian,100)
RB(3,0,10,minecraft:crying_obsidian,20,minecraft:obsidian,100)
RB(4,0,10,minecraft:crying_obsidian,20,minecraft:obsidian,100)
RB(5,0,10,minecraft:crying_obsidian,20,minecraft:obsidian,100)
RB(6,0,10,minecraft:crying_obsidian,20,minecraft:obsidian,100)
RB(7,0,10,minecraft:crying_obsidian,20,minecraft:obsidian,100)
RB(8,0,10,minecraft:crying_obsidian,20,minecraft:obsidian,100)
RB(9,0,10,minecraft:crying_obsidian,20,minecraft:obsidian,100)
RB(10,0,10,minecraft:crying_obsidian,20,minecraft:obsidian,100)
RB(0,0,11,minecraft:crying_obsidian,20,minecraft:obsidian,100)
RB(1,0,11,minecraft:crying_obsidian,20,minecraft:obsidian,100)
RB(2,0,11,minecraft:crying_obsidian,20,minecraft:obsidian,100)
RB(3,0,11,minecraft:crying_obsidian,20,minecraft:obsidian,100)
RB(4,0,11,minecraft:crying_obsidian,20,minecraft:obsidian,100)
RB(5,0,11,minecraft:crying_obsidian,20,minecraft:obsidian,100)
RB(6,0,11,minecraft:crying_obsidian,20,minecraft:obsidian,100)
RB(7,0,11,minecraft:crying_obsidian,20,minecraft:obsidian,100)
RB(8,0,11,minecraft:crying_obsidian,20,minecraft:obsidian,100)
RB(9,0,11,minecraft:crying_obsidian,20,minecraft:obsidian,100)
RB(0,0,12,minecraft:crying_obsidian,20,minecraft:obsidian,100)
RB(1,0,12,minecraft:crying_obsidian,20,minecraft:obsidian,100)
RB(2,0,12,minecraft:crying_obsidian,20,minecraft:obsidian,100)
RB(3,0,12,minecraft:crying_obsidian,20,minecraft:obsidian,100)
RB(4,0,12,minecraft:crying_obsidian,20,minecraft:obsidian,100)
RB(5,0,12,minecraft:crying_obsidian,20,minecraft:obsidian,100)
RB(6,0,12,minecraft:crying_obsidian,20,minecraft:obsidian,100)
RB(7,0,12,minecraft:crying_obsidian,20,minecraft:obsidian,100)
RB(8,0,12,minecraft:crying_obsidian,20,minecraft:obsidian,100)
RB(9,0,12,minecraft:crying_obsidian,20,minecraft:obsidian,100)
RB(0,0,13,minecraft:crying_obsidian,20,minecraft:obsidian,100)
RB(1,0,13,minecraft:crying_obsidian,20,minecraft:obsidian,100)
RB(2,0,13,minecraft:crying_obsidian,20,minecraft:obsidian,100)
RB(3,0,13,minecraft:crying_obsidian,20,minecraft:obsidian,100)
RB(4,0,13,minecraft:crying_obsidian,20,minecraft:obsidian,100)
RB(5,0,13,minecraft:crying_obsidian,20,minecraft:obsidian,100)
RB(6,0,13,minecraft:crying_obsidian,20,minecraft:obsidian,100)
RB(7,0,13,minecraft:crying_obsidian,20,minecraft:obsidian,100)
RB(8,0,13,minecraft:crying_obsidian,20,minecraft:obsidian,100)
RB(9,0,13,minecraft:crying_obsidian,20,minecraft:obsidian,100)
RB(0,0,14,minecraft:crying_obsidian,20,minecraft:obsidian,100)
RB(1,0,14,minecraft:crying_obsidian,20,minecraft:obsidian,100)
RB(2,0,14,minecraft:crying_obsidian,20,minecraft:obsidian,100)
RB(3,0,14,minecraft:crying_obsidian,20,minecraft:obsidian,100)
RB(4,0,14,minecraft:crying_obsidian,20,minecraft:obsidian,100)
RB(5,0,14,minecraft:crying_obsidian,20,minecraft:obsidian,100)
RB(6,0,14,minecraft:crying_obsidian,20,minecraft:obsidian,100)
RB(7,0,14,minecraft:crying_obsidian,20,minecraft:obsidian,100)
RB(8,0,14,minecraft:crying_obsidian,20,minecraft:obsidian,100)
RB(0,1,0,minecraft:crying_obsidian,20,minecraft:obsidian,100)
RB(1,1,0,minecraft:crying_obsidian,20,minecraft:obsidian,100)
RB(2,1,0,minecraft:crying_obsidian,20,minecraft:obsidian,100)
RB(3,1,0,minecraft:crying_obsidian,20,minecraft:obsidian,100)
RB(4,1,0,minecraft:crying_obsidian,20,minecraft:obsidian,100)
RB(5,1,0,minecraft:crying_obsidian,20,minecraft:obsidian,100)
RB(6,1,0,minecraft:crying_obsidian,20,minecraft:obsidian,100)
RB(7,1,0,minecraft:crying_obsidian,20,minecraft:obsidian,100)
RB(8,1,0,minecraft:crying_obsidian,20,minecraft:obsidian,100)
RB(9,1,0,minecraft:crying_obsidian,20,minecraft:obsidian,100)
RB(0,1,1,minecraft:crying_obsidian,20,minecraft:obsidian,100)
RB(1,1,1,minecraft:crying_obsidian,20,minecraft:obsidian,100)
RB(2,1,1,minecraft:crying_obsidian,20,minecraft:obsidian,100)
RB(3,1,1,minecraft:crying_obsidian,20,minecraft:obsidian,100)
RB(4,1,1,minecraft:crying_obsidian,20,minecraft:obsidian,100)
RB(5,1,1,minecraft:crying_obsidian,20,minecraft:obsidian,100)
RB(6,1,1,minecraft:crying_obsidian,20,minecraft:obsidian,100)
RB(7,1,1,minecraft:crying_obsidian,20,minecraft:obsidian,100)
RB(0,1,2,minecraft:crying_obsidian,20,minecraft:obsidian,100)
RB(1,1,2,minecraft:crying_obsidian,20,minecraft:obsidian,100)
RB(2,1,2,minecraft:crying_obsidian,20,minecraft:obsidian,100)
RB(3,1,2,minecraft:crying_obsidian,20,minecraft:obsidian,100)
RB(4,1,2,minecraft:crying_obsidian,20,minecraft:obsidian,100)
RB(5,1,2,minecraft:crying_obsidian,20,minecraft:obsidian,100)
RB(6,1,2,minecraft:crying_obsidian,20,minecraft:obsidian,100)
RB(7,1,2,minecraft:crying_obsidian,20,minecraft:obsidian,100)
RB(8,1,2,minecraft:crying_obsidian,20,minecraft:obsidian,100)
RB(0,1,3,minecraft:crying_obsidian,20,minecraft:obsidian,100)
RB(1,1,3,minecraft:crying_obsidian,20,minecraft:obsidian,100)
RB(2,1,3,minecraft:crying_obsidian,20,minecraft:obsidian,100)
RB(3,1,3,minecraft:crying_obsidian,20,minecraft:obsidian,100)
RB(4,1,3,minecraft:crying_obsidian,20,minecraft:obsidian,100)
RB(5,1,3,minecraft:crying_obsidian,20,minecraft:obsidian,100)
RB(6,1,3,minecraft:crying_obsidian,20,minecraft:obsidian,100)
RB(7,1,3,minecraft:crying_obsidian,20,minecraft:obsidian,100)
RB(8,1,3,minecraft:crying_obsidian,20,minecraft:obsidian,100)
RB(0,1,4,minecraft:crying_obsidian,20,minecraft:obsidian,100)
RB(1,1,4,minecraft:crying_obsidian,20,minecraft:obsidian,100)
RB(2,1,4,minecraft:crying_obsidian,20,minecraft:obsidian,100)
RB(3,1,4,minecraft:crying_obsidian,20,minecraft:obsidian,100)
RB(4,1,4,minecraft:crying_obsidian,20,minecraft:obsidian,100)
RB(5,1,4,minecraft:crying_obsidian,20,minecraft:obsidian,100)
RB(6,1,4,minecraft:crying_obsidian,20,minecraft:obsidian,100)
RB(7,1,4,minecraft:crying_obsidian,20,minecraft:obsidian,100)
RB(8,1,4,minecraft:crying_obsidian,20,minecraft:obsidian,100)
RB(0,1,5,minecraft:crying_obsidian,20,minecraft:obsidian,100)
RB(1,1,5,minecraft:crying_obsidian,20,minecraft:obsidian,100)
RB(2,1,5,minecraft:crying_obsidian,20,minecraft:obsidian,100)
RB(3,1,5,minecraft:crying_obsidian,20,minecraft:obsidian,100)
RB(4,1,5,minecraft:crying_obsidian,20,minecraft:obsidian,100)
RB(5,1,5,minecraft:crying_obsidian,20,minecraft:obsidian,100)
RB(6,1,5,minecraft:crying_obsidian,20,minecraft:obsidian,100)
RB(7,1,5,minecraft:crying_obsidian,20,minecraft:obsidian,100)
RB(8,1,5,minecraft:crying_obsidian,20,minecraft:obsidian,100)
RB(0,1,6,minecraft:crying_obsidian,20,minecraft:obsidian,100)
RB(1,1,6,minecraft:crying_obsidian,20,minecraft:obsidian,100)
RB(2,1,6,minecraft:crying_obsidian,20,minecraft:obsidian,100)
RB(3,1,6,minecraft:crying_obsidian,20,minecraft:obsidian,100)
RB(4,1,6,minecraft:crying_obsidian,20,minecraft:obsidian,100)
RB(5,1,6,minecraft:crying_obsidian,20,minecraft:obsidian,100)
RB(6,1,6,minecraft:crying_obsidian,20,minecraft:obsidian,100)
RB(7,1,6,minecraft:crying_obsidian,20,minecraft:obsidian,100)
RB(8,1,6,minecraft:crying_obsidian,20,minecraft:obsidian,100)
RB(0,1,7,minecraft:crying_obsidian,20,minecraft:obsidian,100)
RB(1,1,7,minecraft:crying_obsidian,20,minecraft:obsidian,100)
RB(2,1,7,minecraft:crying_obsidian,20,minecraft:obsidian,100)
RB(3,1,7,minecraft:crying_obsidian,20,minecraft:obsidian,100)
RB(4,1,7,minecraft:crying_obsidian,20,minecraft:obsidian,100)
RB(5,1,7,minecraft:crying_obsidian,20,minecraft:obsidian,100)
RB(6,1,7,minecraft:crying_obsidian,20,minecraft:obsidian,100)
RB(7,1,7,minecraft:crying_obsidian,20,minecraft:obsidian,100)
RB(8,1,7,minecraft:crying_obsidian,20,minecraft:obsidian,100)
RB(9,1,7,minecraft:crying_obsidian,20,minecraft:obsidian,100)
RB(0,1,8,minecraft:crying_obsidian,20,minecraft:obsidian,100)
RB(1,1,8,minecraft:crying_obsidian,20,minecraft:obsidian,100)
RB(2,1,8,minecraft:crying_obsidian,20,minecraft:obsidian,100)
RB(3,1,8,minecraft:crying_obsidian,20,minecraft:obsidian,100)
RB(4,1,8,minecraft:crying_obsidian,20,minecraft:obsidian,100)
RB(5,1,8,minecraft:crying_obsidian,20,minecraft:obsidian,100)
RB(6,1,8,minecraft:crying_obsidian,20,minecraft:obsidian,100)
RB(7,1,8,minecraft:crying_obsidian,20,minecraft:obsidian,100)
RB(8,1,8,minecraft:crying_obsidian,20,minecraft:obsidian,100)
RB(9,1,8,minecraft:crying_obsidian,20,minecraft:obsidian,100)
RB(0,1,9,minecraft:crying_obsidian,20,minecraft:obsidian,100)
RB(1,1,9,minecraft:crying_obsidian,20,minecraft:obsidian,100)
RB(2,1,9,minecraft:crying_obsidian,20,minecraft:obsidian,100)
RB(3,1,9,minecraft:crying_obsidian,20,minecraft:obsidian,100)
RB(4,1,9,minecraft:crying_obsidian,20,minecraft:obsidian,100)
RB(5,1,9,minecraft:crying_obsidian,20,minecraft:obsidian,100)
RB(6,1,9,minecraft:crying_obsidian,20,minecraft:obsidian,100)
RB(7,1,9,minecraft:crying_obsidian,20,minecraft:obsidian,100)
RB(8,1,9,minecraft:crying_obsidian,20,minecraft:obsidian,100)
RB(9,1,9,minecraft:crying_obsidian,20,minecraft:obsidian,100)
RB(0,1,10,minecraft:crying_obsidian,20,minecraft:obsidian,100)
RB(1,1,10,minecraft:crying_obsidian,20,minecraft:obsidian,100)
RB(2,1,10,minecraft:crying_obsidian,20,minecraft:obsidian,100)
RB(3,1,10,minecraft:crying_obsidian,20,minecraft:obsidian,100)
RB(4,1,10,minecraft:crying_obsidian,20,minecraft:obsidian,100)
RB(5,1,10,minecraft:crying_obsidian,20,minecraft:obsidian,100)
RB(6,1,10,minecraft:crying_obsidian,20,minecraft:obsidian,100)
RB(7,1,10,minecraft:crying_obsidian,20,minecraft:obsidian,100)
RB(8,1,10,minecraft:crying_obsidian,20,minecraft:obsidian,100)
RB(9,1,10,minecraft:crying_obsidian,20,minecraft:obsidian,100)
RB(0,1,11,minecraft:crying_obsidian,20,minecraft:obsidian,100)
RB(1,1,11,minecraft:crying_obsidian,20,minecraft:obsidian,100)
RB(2,1,11,minecraft:crying_obsidian,20,minecraft:obsidian,100)
RB(3,1,11,minecraft:crying_obsidian,20,minecraft:obsidian,100)
RB(4,1,11,minecraft:crying_obsidian,20,minecraft:obsidian,100)
RB(5,1,11,minecraft:crying_obsidian,20,minecraft:obsidian,100)
RB(6,1,11,minecraft:crying_obsidian,20,minecraft:obsidian,100)
RB(7,1,11,minecraft:crying_obsidian,20,minecraft:obsidian,100)
RB(8,1,11,minecraft:crying_obsidian,20,minecraft:obsidian,100)
RB(9,1,11,minecraft:crying_obsidian,20,minecraft:obsidian,100)
RB(0,1,12,minecraft:crying_obsidian,20,minecraft:obsidian,100)
RB(1,1,12,minecraft:crying_obsidian,20,minecraft:obsidian,100)
RB(2,1,12,minecraft:crying_obsidian,20,minecraft:obsidian,100)
RB(3,1,12,minecraft:crying_obsidian,20,minecraft:obsidian,100)
RB(4,1,12,minecraft:crying_obsidian,20,minecraft:obsidian,100)
RB(5,1,12,minecraft:crying_obsidian,20,minecraft:obsidian,100)
RB(6,1,12,minecraft:crying_obsidian,20,minecraft:obsidian,100)
RB(7,1,12,minecraft:crying_obsidian,20,minecraft:obsidian,100)
RB(8,1,12,minecraft:crying_obsidian,20,minecraft:obsidian,100)
RB(0,1,13,minecraft:crying_obsidian,20,minecraft:obsidian,100)
RB(1,1,13,minecraft:crying_obsidian,20,minecraft:obsidian,100)
RB(2,1,13,minecraft:crying_obsidian,20,minecraft:obsidian,100)
RB(3,1,13,minecraft:crying_obsidian,20,minecraft:obsidian,100)
RB(4,1,13,minecraft:crying_obsidian,20,minecraft:obsidian,100)
RB(5,1,13,minecraft:crying_obsidian,20,minecraft:obsidian,100)
RB(6,1,13,minecraft:crying_obsidian,20,minecraft:obsidian,100)
RB(7,1,13,minecraft:crying_obsidian,20,minecraft:obsidian,100)
RB(8,1,13,minecraft:crying_obsidian,20,minecraft:obsidian,100)
RB(0,1,14,minecraft:crying_obsidian,20,minecraft:obsidian,100)
RB(1,1,14,minecraft:crying_obsidian,20,minecraft:obsidian,100)
RB(2,1,14,minecraft:crying_obsidian,20,minecraft:obsidian,100)
RB(3,1,14,minecraft:crying_obsidian,20,minecraft:obsidian,100)
RB(4,1,14,minecraft:crying_obsidian,20,minecraft:obsidian,100)
RB(5,1,14,minecraft:crying_obsidian,20,minecraft:obsidian,100)
RB(6,1,14,minecraft:crying_obsidian,20,minecraft:obsidian,100)
RB(7,1,14,minecraft:crying_obsidian,20,minecraft:obsidian,100)
RB(0,2,0,minecraft:crying_obsidian,20,minecraft:obsidian,100)
RB(1,2,0,minecraft:crying_obsidian,20,minecraft:obsidian,100)
RB(2,2,0,minecraft:crying_obsidian,20,minecraft:obsidian,100)
RB(3,2,0,minecraft:crying_obsidian,20,minecraft:obsidian,100)
RB(4,2,0,minecraft:crying_obsidian,20,minecraft:obsidian,100)
RB(5,2,0,minecraft:crying_obsidian,20,minecraft:obsidian,100)
RB(6,2,0,minecraft:crying_obsidian,20,minecraft:obsidian,100)
RB(7,2,0,minecraft:crying_obsidian,20,minecraft:obsidian,100)
RB(8,2,0,minecraft:crying_obsidian,20,minecraft:obsidian,100)
RB(0,2,1,minecraft:crying_obsidian,20,minecraft:obsidian,100)
RB(1,2,1,minecraft:crying_obsidian,20,minecraft:obsidian,100)
RB(2,2,1,minecraft:crying_obsidian,20,minecraft:obsidian,100)
RB(3,2,1,minecraft:crying_obsidian,20,minecraft:obsidian,100)
RB(4,2,1,minecraft:crying_obsidian,20,minecraft:obsidian,100)
RB(5,2,1,minecraft:crying_obsidian,20,minecraft:obsidian,100)
RB(6,2,1,minecraft:crying_obsidian,20,minecraft:obsidian,100)
RB(7,2,1,minecraft:crying_obsidian,20,minecraft:obsidian,100)
RB(0,2,2,minecraft:crying_obsidian,20,minecraft:obsidian,100)
RB(1,2,2,minecraft:crying_obsidian,20,minecraft:obsidian,100)
RB(2,2,2,minecraft:crying_obsidian,20,minecraft:obsidian,100)
RB(3,2,2,minecraft:crying_obsidian,20,minecraft:obsidian,100)
RB(4,2,2,minecraft:crying_obsidian,20,minecraft:obsidian,100)
RB(5,2,2,minecraft:crying_obsidian,20,minecraft:obsidian,100)
RB(6,2,2,minecraft:crying_obsidian,20,minecraft:obsidian,100)
RB(7,2,2,minecraft:crying_obsidian,20,minecraft:obsidian,100)
RB(8,2,2,minecraft:crying_obsidian,20,minecraft:obsidian,100)
RB(0,2,3,minecraft:crying_obsidian,20,minecraft:obsidian,100)
RB(1,2,3,minecraft:crying_obsidian,20,minecraft:obsidian,100)
RB(2,2,3,minecraft:crying_obsidian,20,minecraft:obsidian,100)
RB(3,2,3,minecraft:crying_obsidian,20,minecraft:obsidian,100)
RB(4,2,3,minecraft:crying_obsidian,20,minecraft:obsidian,100)
RB(5,2,3,minecraft:crying_obsidian,20,minecraft:obsidian,100)
RB(6,2,3,minecraft:crying_obsidian,20,minecraft:obsidian,100)
RB(7,2,3,minecraft:crying_obsidian,20,minecraft:obsidian,100)
RB(8,2,3,minecraft:crying_obsidian,20,minecraft:obsidian,100)
RB(0,2,4,minecraft:crying_obsidian,20,minecraft:obsidian,100)
RB(1,2,4,minecraft:crying_obsidian,20,minecraft:obsidian,100)
RB(2,2,4,minecraft:crying_obsidian,20,minecraft:obsidian,100)
RB(3,2,4,minecraft:crying_obsidian,20,minecraft:obsidian,100)
RB(4,2,4,minecraft:crying_obsidian,20,minecraft:obsidian,100)
RB(5,2,4,minecraft:crying_obsidian,20,minecraft:obsidian,100)
RB(6,2,4,minecraft:crying_obsidian,20,minecraft:obsidian,100)
RB(7,2,4,minecraft:crying_obsidian,20,minecraft:obsidian,100)
RB(8,2,4,minecraft:crying_obsidian,20,minecraft:obsidian,100)
RB(0,2,5,minecraft:crying_obsidian,20,minecraft:obsidian,100)
RB(1,2,5,minecraft:crying_obsidian,20,minecraft:obsidian,100)
RB(2,2,5,minecraft:crying_obsidian,20,minecraft:obsidian,100)
RB(3,2,5,minecraft:crying_obsidian,20,minecraft:obsidian,100)
RB(4,2,5,minecraft:crying_obsidian,20,minecraft:obsidian,100)
RB(5,2,5,minecraft:crying_obsidian,20,minecraft:obsidian,100)
RB(6,2,5,minecraft:crying_obsidian,20,minecraft:obsidian,100)
RB(7,2,5,minecraft:crying_obsidian,20,minecraft:obsidian,100)
RB(8,2,5,minecraft:crying_obsidian,20,minecraft:obsidian,100)
RB(0,2,6,minecraft:crying_obsidian,20,minecraft:obsidian,100)
RB(1,2,6,minecraft:crying_obsidian,20,minecraft:obsidian,100)
RB(2,2,6,minecraft:crying_obsidian,20,minecraft:obsidian,100)
RB(3,2,6,minecraft:crying_obsidian,20,minecraft:obsidian,100)
RB(4,2,6,minecraft:crying_obsidian,20,minecraft:obsidian,100)
RB(5,2,6,minecraft:crying_obsidian,20,minecraft:obsidian,100)
RB(6,2,6,minecraft:crying_obsidian,20,minecraft:obsidian,100)
RB(7,2,6,minecraft:crying_obsidian,20,minecraft:obsidian,100)
RB(8,2,6,minecraft:crying_obsidian,20,minecraft:obsidian,100)
RB(0,2,7,minecraft:crying_obsidian,20,minecraft:obsidian,100)
RB(1,2,7,minecraft:crying_obsidian,20,minecraft:obsidian,100)
RB(2,2,7,minecraft:crying_obsidian,20,minecraft:obsidian,100)
RB(3,2,7,minecraft:crying_obsidian,20,minecraft:obsidian,100)
RB(4,2,7,minecraft:crying_obsidian,20,minecraft:obsidian,100)
RB(5,2,7,minecraft:crying_obsidian,20,minecraft:obsidian,100)
RB(6,2,7,minecraft:crying_obsidian,20,minecraft:obsidian,100)
RB(7,2,7,minecraft:crying_obsidian,20,minecraft:obsidian,100)
RB(0,2,8,minecraft:crying_obsidian,20,minecraft:obsidian,100)
RB(1,2,8,minecraft:crying_obsidian,20,minecraft:obsidian,100)
RB(2,2,8,minecraft:crying_obsidian,20,minecraft:obsidian,100)
RB(3,2,8,minecraft:crying_obsidian,20,minecraft:obsidian,100)
RB(4,2,8,minecraft:crying_obsidian,20,minecraft:obsidian,100)
RB(5,2,8,minecraft:crying_obsidian,20,minecraft:obsidian,100)
RB(6,2,8,minecraft:crying_obsidian,20,minecraft:obsidian,100)
RB(0,2,9,minecraft:crying_obsidian,20,minecraft:obsidian,100)
RB(1,2,9,minecraft:crying_obsidian,20,minecraft:obsidian,100)
RB(2,2,9,minecraft:crying_obsidian,20,minecraft:obsidian,100)
RB(3,2,9,minecraft:crying_obsidian,20,minecraft:obsidian,100)
RB(4,2,9,minecraft:crying_obsidian,20,minecraft:obsidian,100)
RB(5,2,9,minecraft:crying_obsidian,20,minecraft:obsidian,100)
RB(0,2,10,minecraft:crying_obsidian,20,minecraft:obsidian,100)
RB(1,2,10,minecraft:crying_obsidian,20,minecraft:obsidian,100)
RB(2,2,10,minecraft:crying_obsidian,20,minecraft:obsidian,100)
RB(3,2,10,minecraft:crying_obsidian,20,minecraft:obsidian,100)
RB(4,2,10,minecraft:crying_obsidian,20,minecraft:obsidian,100)
RB(0,2,11,minecraft:crying_obsidian,20,minecraft:obsidian,100)
RB(1,2,11,minecraft:crying_obsidian,20,minecraft:obsidian,100)
RB(2,2,11,minecraft:crying_obsidian,20,minecraft:obsidian,100)
RB(3,2,11,minecraft:crying_obsidian,20,minecraft:obsidian,100)
RB(4,2,11,minecraft:crying_obsidian,20,minecraft:obsidian,100)
RB(0,2,12,minecraft:crying_obsidian,20,minecraft:obsidian,100)
RB(1,2,12,minecraft:crying_obsidian,20,minecraft:obsidian,100)
RB(2,2,12,minecraft:crying_obsidian,20,minecraft:obsidian,100)
RB(3,2,12,minecraft:crying_obsidian,20,minecraft:obsidian,100)
RB(4,2,12,minecraft:crying_obsidian,20,minecraft:obsidian,100)
RB(0,2,13,minecraft:crying_obsidian,20,minecraft:obsidian,100)
RB(1,2,13,minecraft:crying_obsidian,20,minecraft:obsidian,100)
RB(2,2,13,minecraft:crying_obsidian,20,minecraft:obsidian,100)
RB(3,2,13,minecraft:crying_obsidian,20,minecraft:obsidian,100)
RB(0,2,14,minecraft:crying_obsidian,20,minecraft:obsidian,100)
RB(1,2,14,minecraft:crying_obsidian,20,minecraft:obsidian,100)
RB(2,2,14,minecraft:crying_obsidian,20,minecraft:obsidian,100)
RB(0,3,0,minecraft:crying_obsidian,20,minecraft:obsidian,100)
RB(1,3,0,minecraft:crying_obsidian,20,minecraft:obsidian,100)
RB(2,3,0,minecraft:crying_obsidian,20,minecraft:obsidian,100)
RB(3,3,0,minecraft:crying_obsidian,20,minecraft:obsidian,100)
RB(4,3,0,minecraft:crying_obsidian,20,minecraft:obsidian,100)
RB(5,3,0,minecraft:crying_obsidian,20,minecraft:obsidian,100)
RB(6,3,0,minecraft:crying_obsidian,20,minecraft:obsidian,100)
RB(7,3,0,minecraft:crying_obsidian,20,minecraft:obsidian,100)
RB(8,3,0,minecraft:crying_obsidian,20,minecraft:obsidian,100)
RB(0,3,1,minecraft:crying_obsidian,20,minecraft:obsidian,100)
RB(1,3,1,minecraft:crying_obsidian,20,minecraft:obsidian,100)
RB(2,3,1,minecraft:crying_obsidian,20,minecraft:obsidian,100)
RB(3,3,1,minecraft:crying_obsidian,20,minecraft:obsidian,100)
RB(4,3,1,minecraft:crying_obsidian,20,minecraft:obsidian,100)
RB(5,3,1,minecraft:crying_obsidian,20,minecraft:obsidian,100)
RB(6,3,1,minecraft:crying_obsidian,20,minecraft:obsidian,100)
RB(7,3,1,minecraft:crying_obsidian,20,minecraft:obsidian,100)
RB(0,3,2,minecraft:crying_obsidian,20,minecraft:obsidian,100)
RB(1,3,2,minecraft:crying_obsidian,20,minecraft:obsidian,100)
RB(2,3,2,minecraft:crying_obsidian,20,minecraft:obsidian,100)
RB(3,3,2,minecraft:crying_obsidian,20,minecraft:obsidian,100)
RB(4,3,2,minecraft:crying_obsidian,20,minecraft:obsidian,100)
RB(5,3,2,minecraft:crying_obsidian,20,minecraft:obsidian,100)
RB(6,3,2,minecraft:crying_obsidian,20,minecraft:obsidian,100)
RB(7,3,2,minecraft:crying_obsidian,20,minecraft:obsidian,100)
RB(0,3,3,minecraft:crying_obsidian,20,minecraft:obsidian,100)
RB(1,3,3,minecraft:crying_obsidian,20,minecraft:obsidian,100)
RB(2,3,3,minecraft:crying_obsidian,20,minecraft:obsidian,100)
RB(3,3,3,minecraft:crying_obsidian,20,minecraft:obsidian,100)
RB(4,3,3,minecraft:crying_obsidian,20,minecraft:obsidian,100)
RB(5,3,3,minecraft:crying_obsidian,20,minecraft:obsidian,100)
RB(6,3,3,minecraft:crying_obsidian,20,minecraft:obsidian,100)
RB(7,3,3,minecraft:crying_obsidian,20,minecraft:obsidian,100)
RB(8,3,3,minecraft:crying_obsidian,20,minecraft:obsidian,100)
RB(0,3,4,minecraft:crying_obsidian,20,minecraft:obsidian,100)
RB(1,3,4,minecraft:crying_obsidian,20,minecraft:obsidian,100)
RB(2,3,4,minecraft:crying_obsidian,20,minecraft:obsidian,100)
RB(3,3,4,minecraft:crying_obsidian,20,minecraft:obsidian,100)
RB(4,3,4,minecraft:crying_obsidian,20,minecraft:obsidian,100)
RB(5,3,4,minecraft:crying_obsidian,20,minecraft:obsidian,100)
RB(6,3,4,minecraft:crying_obsidian,20,minecraft:obsidian,100)
RB(7,3,4,minecraft:crying_obsidian,20,minecraft:obsidian,100)
RB(8,3,4,minecraft:crying_obsidian,20,minecraft:obsidian,100)
RB(0,3,5,minecraft:crying_obsidian,20,minecraft:obsidian,100)
RB(1,3,5,minecraft:crying_obsidian,20,minecraft:obsidian,100)
RB(2,3,5,minecraft:crying_obsidian,20,minecraft:obsidian,100)
RB(3,3,5,minecraft:crying_obsidian,20,minecraft:obsidian,100)
RB(4,3,5,minecraft:crying_obsidian,20,minecraft:obsidian,100)
RB(5,3,5,minecraft:crying_obsidian,20,minecraft:obsidian,100)
RB(6,3,5,minecraft:crying_obsidian,20,minecraft:obsidian,100)
RB(7,3,5,minecraft:crying_obsidian,20,minecraft:obsidian,100)
RB(8,3,5,minecraft:crying_obsidian,20,minecraft:obsidian,100)
RB(0,3,6,minecraft:crying_obsidian,20,minecraft:obsidian,100)
RB(1,3,6,minecraft:crying_obsidian,20,minecraft:obsidian,100)
RB(2,3,6,minecraft:crying_obsidian,20,minecraft:obsidian,100)
RB(3,3,6,minecraft:crying_obsidian,20,minecraft:obsidian,100)
RB(4,3,6,minecraft:crying_obsidian,20,minecraft:obsidian,100)
RB(5,3,6,minecraft:crying_obsidian,20,minecraft:obsidian,100)
RB(6,3,6,minecraft:crying_obsidian,20,minecraft:obsidian,100)
RB(7,3,6,minecraft:crying_obsidian,20,minecraft:obsidian,100)
RB(8,3,6,minecraft:crying_obsidian,20,minecraft:obsidian,100)
RB(0,3,7,minecraft:crying_obsidian,20,minecraft:obsidian,100)
RB(1,3,7,minecraft:crying_obsidian,20,minecraft:obsidian,100)
RB(2,3,7,minecraft:crying_obsidian,20,minecraft:obsidian,100)
RB(3,3,7,minecraft:crying_obsidian,20,minecraft:obsidian,100)
RB(4,3,7,minecraft:crying_obsidian,20,minecraft:obsidian,100)
RB(5,3,7,minecraft:crying_obsidian,20,minecraft:obsidian,100)
RB(6,3,7,minecraft:crying_obsidian,20,minecraft:obsidian,100)
RB(7,3,7,minecraft:crying_obsidian,20,minecraft:obsidian,100)
RB(0,3,8,minecraft:crying_obsidian,20,minecraft:obsidian,100)
RB(1,3,8,minecraft:crying_obsidian,20,minecraft:obsidian,100)
RB(2,3,8,minecraft:crying_obsidian,20,minecraft:obsidian,100)
RB(3,3,8,minecraft:crying_obsidian,20,minecraft:obsidian,100)
RB(4,3,8,minecraft:crying_obsidian,20,minecraft:obsidian,100)
RB(5,3,8,minecraft:crying_obsidian,20,minecraft:obsidian,100)
RB(6,3,8,minecraft:crying_obsidian,20,minecraft:obsidian,100)
RB(0,3,9,minecraft:crying_obsidian,20,minecraft:obsidian,100)
RB(1,3,9,minecraft:crying_obsidian,20,minecraft:obsidian,100)
RB(2,3,9,minecraft:crying_obsidian,20,minecraft:obsidian,100)
RB(3,3,9,minecraft:crying_obsidian,20,minecraft:obsidian,100)
RB(4,3,9,minecraft:crying_obsidian,20,minecraft:obsidian,100)
RB(5,3,9,minecraft:crying_obsidian,20,minecraft:obsidian,100)
RB(0,3,10,minecraft:crying_obsidian,20,minecraft:obsidian,100)
RB(1,3,10,minecraft:crying_obsidian,20,minecraft:obsidian,100)
RB(2,3,10,minecraft:crying_obsidian,20,minecraft:obsidian,100)
RB(3,3,10,minecraft:crying_obsidian,20,minecraft:obsidian,100)
RB(4,3,10,minecraft:crying_obsidian,20,minecraft:obsidian,100)
RB(0,3,11,minecraft:crying_obsidian,20,minecraft:obsidian,100)
RB(1,3,11,minecraft:crying_obsidian,20,minecraft:obsidian,100)
RB(2,3,11,minecraft:crying_obsidian,20,minecraft:obsidian,100)
RB(3,3,11,minecraft:crying_obsidian,20,minecraft:obsidian,100)
RB(4,3,11,minecraft:crying_obsidian,20,minecraft:obsidian,100)
RB(0,3,12,minecraft:crying_obsidian,20,minecraft:obsidian,100)
RB(1,3,12,minecraft:crying_obsidian,20,minecraft:obsidian,100)
RB(2,3,12,minecraft:crying_obsidian,20,minecraft:obsidian,100)
RB(3,3,12,minecraft:crying_obsidian,20,minecraft:obsidian,100)
RB(0,3,13,minecraft:crying_obsidian,20,minecraft:obsidian,100)
RB(1,3,13,minecraft:crying_obsidian,20,minecraft:obsidian,100)
RB(2,3,13,minecraft:crying_obsidian,20,minecraft:obsidian,100)
RB(3,3,13,minecraft:crying_obsidian,20,minecraft:obsidian,100)
RB(0,3,14,minecraft:crying_obsidian,20,minecraft:obsidian,100)
RB(1,3,14,minecraft:crying_obsidian,20,minecraft:obsidian,100)
RB(2,3,14,minecraft:crying_obsidian,20,minecraft:obsidian,100)
RB(0,4,0,minecraft:crying_obsidian,20,minecraft:obsidian,100)
RB(1,4,0,minecraft:crying_obsidian,20,minecraft:obsidian,100)
RB(2,4,0,minecraft:crying_obsidian,20,minecraft:obsidian,100)
RB(3,4,0,minecraft:crying_obsidian,20,minecraft:obsidian,100)
RB(4,4,0,minecraft:crying_obsidian,20,minecraft:obsidian,100)
RB(5,4,0,minecraft:crying_obsidian,20,minecraft:obsidian,100)
RB(6,4,0,minecraft:crying_obsidian,20,minecraft:obsidian,100)
RB(7,4,0,minecraft:crying_obsidian,20,minecraft:obsidian,100)
RB(8,4,0,minecraft:crying_obsidian,20,minecraft:obsidian,100)
RB(0,4,1,minecraft:crying_obsidian,20,minecraft:obsidian,100)
RB(1,4,1,minecraft:crying_obsidian,20,minecraft:obsidian,100)
RB(2,4,1,minecraft:crying_obsidian,20,minecraft:obsidian,100)
RB(3,4,1,minecraft:crying_obsidian,20,minecraft:obsidian,100)
RB(4,4,1,minecraft:crying_obsidian,20,minecraft:obsidian,100)
RB(5,4,1,minecraft:crying_obsidian,20,minecraft:obsidian,100)
RB(6,4,1,minecraft:crying_obsidian,20,minecraft:obsidian,100)
RB(7,4,1,minecraft:crying_obsidian,20,minecraft:obsidian,100)
RB(0,4,2,minecraft:crying_obsidian,20,minecraft:obsidian,100)
RB(1,4,2,minecraft:crying_obsidian,20,minecraft:obsidian,100)
RB(2,4,2,minecraft:crying_obsidian,20,minecraft:obsidian,100)
RB(3,4,2,minecraft:crying_obsidian,20,minecraft:obsidian,100)
RB(4,4,2,minecraft:crying_obsidian,20,minecraft:obsidian,100)
RB(5,4,2,minecraft:crying_obsidian,20,minecraft:obsidian,100)
RB(6,4,2,minecraft:crying_obsidian,20,minecraft:obsidian,100)
RB(7,4,2,minecraft:crying_obsidian,20,minecraft:obsidian,100)
RB(0,4,3,minecraft:crying_obsidian,20,minecraft:obsidian,100)
RB(1,4,3,minecraft:crying_obsidian,20,minecraft:obsidian,100)
RB(2,4,3,minecraft:crying_obsidian,20,minecraft:obsidian,100)
RB(3,4,3,minecraft:crying_obsidian,20,minecraft:obsidian,100)
RB(4,4,3,minecraft:crying_obsidian,20,minecraft:obsidian,100)
RB(5,4,3,minecraft:crying_obsidian,20,minecraft:obsidian,100)
RB(6,4,3,minecraft:crying_obsidian,20,minecraft:obsidian,100)
RB(7,4,3,minecraft:crying_obsidian,20,minecraft:obsidian,100)
RB(8,4,3,minecraft:crying_obsidian,20,minecraft:obsidian,100)
RB(0,4,4,minecraft:crying_obsidian,20,minecraft:obsidian,100)
RB(1,4,4,minecraft:crying_obsidian,20,minecraft:obsidian,100)
RB(2,4,4,minecraft:crying_obsidian,20,minecraft:obsidian,100)
RB(3,4,4,minecraft:crying_obsidian,20,minecraft:obsidian,100)
RB(4,4,4,minecraft:crying_obsidian,20,minecraft:obsidian,100)
RB(5,4,4,minecraft:crying_obsidian,20,minecraft:obsidian,100)
RB(6,4,4,minecraft:crying_obsidian,20,minecraft:obsidian,100)
RB(7,4,4,minecraft:crying_obsidian,20,minecraft:obsidian,100)
RB(8,4,4,minecraft:crying_obsidian,20,minecraft:obsidian,100)
RB(0,4,5,minecraft:crying_obsidian,20,minecraft:obsidian,100)
RB(1,4,5,minecraft:crying_obsidian,20,minecraft:obsidian,100)
RB(2,4,5,minecraft:crying_obsidian,20,minecraft:obsidian,100)
RB(3,4,5,minecraft:crying_obsidian,20,minecraft:obsidian,100)
RB(4,4,5,minecraft:crying_obsidian,20,minecraft:obsidian,100)
RB(5,4,5,minecraft:crying_obsidian,20,minecraft:obsidian,100)
RB(6,4,5,minecraft:crying_obsidian,20,minecraft:obsidian,100)
RB(7,4,5,minecraft:crying_obsidian,20,minecraft:obsidian,100)
RB(8,4,5,minecraft:crying_obsidian,20,minecraft:obsidian,100)
RB(0,4,6,minecraft:crying_obsidian,20,minecraft:obsidian,100)
RB(1,4,6,minecraft:crying_obsidian,20,minecraft:obsidian,100)
RB(2,4,6,minecraft:crying_obsidian,20,minecraft:obsidian,100)
RB(3,4,6,minecraft:crying_obsidian,20,minecraft:obsidian,100)
RB(4,4,6,minecraft:crying_obsidian,20,minecraft:obsidian,100)
RB(5,4,6,minecraft:crying_obsidian,20,minecraft:obsidian,100)
RB(6,4,6,minecraft:crying_obsidian,20,minecraft:obsidian,100)
RB(7,4,6,minecraft:crying_obsidian,20,minecraft:obsidian,100)
RB(8,4,6,minecraft:crying_obsidian,20,minecraft:obsidian,100)
RB(0,4,7,minecraft:crying_obsidian,20,minecraft:obsidian,100)
RB(1,4,7,minecraft:crying_obsidian,20,minecraft:obsidian,100)
RB(2,4,7,minecraft:crying_obsidian,20,minecraft:obsidian,100)
RB(3,4,7,minecraft:crying_obsidian,20,minecraft:obsidian,100)
RB(4,4,7,minecraft:crying_obsidian,20,minecraft:obsidian,100)
RB(5,4,7,minecraft:crying_obsidian,20,minecraft:obsidian,100)
RB(6,4,7,minecraft:crying_obsidian,20,minecraft:obsidian,100)
RB(7,4,7,minecraft:crying_obsidian,20,minecraft:obsidian,100)
RB(0,4,8,minecraft:crying_obsidian,20,minecraft:obsidian,100)
RB(1,4,8,minecraft:crying_obsidian,20,minecraft:obsidian,100)
RB(2,4,8,minecraft:crying_obsidian,20,minecraft:obsidian,100)
RB(3,4,8,minecraft:crying_obsidian,20,minecraft:obsidian,100)
RB(4,4,8,minecraft:crying_obsidian,20,minecraft:obsidian,100)
RB(5,4,8,minecraft:crying_obsidian,20,minecraft:obsidian,100)
RB(6,4,8,minecraft:crying_obsidian,20,minecraft:obsidian,100)
RB(0,4,9,minecraft:crying_obsidian,20,minecraft:obsidian,100)
RB(1,4,9,minecraft:crying_obsidian,20,minecraft:obsidian,100)
RB(2,4,9,minecraft:crying_obsidian,20,minecraft:obsidian,100)
RB(3,4,9,minecraft:crying_obsidian,20,minecraft:obsidian,100)
RB(4,4,9,minecraft:crying_obsidian,20,minecraft:obsidian,100)
RB(5,4,9,minecraft:crying_obsidian,20,minecraft:obsidian,100)
RB(0,4,10,minecraft:crying_obsidian,20,minecraft:obsidian,100)
RB(1,4,10,minecraft:crying_obsidian,20,minecraft:obsidian,100)
RB(2,4,10,minecraft:crying_obsidian,20,minecraft:obsidian,100)
RB(3,4,10,minecraft:crying_obsidian,20,minecraft:obsidian,100)
RB(0,4,11,minecraft:crying_obsidian,20,minecraft:obsidian,100)
RB(1,4,11,minecraft:crying_obsidian,20,minecraft:obsidian,100)
RB(2,4,11,minecraft:crying_obsidian,20,minecraft:obsidian,100)
RB(3,4,11,minecraft:crying_obsidian,20,minecraft:obsidian,100)
RB(0,4,12,minecraft:crying_obsidian,20,minecraft:obsidian,100)
RB(1,4,12,minecraft:crying_obsidian,20,minecraft:obsidian,100)
RB(2,4,12,minecraft:crying_obsidian,20,minecraft:obsidian,100)
RB(3,4,12,minecraft:crying_obsidian,20,minecraft:obsidian,100)
RB(0,4,13,minecraft:crying_obsidian,20,minecraft:obsidian,100)
RB(1,4,13,minecraft:crying_obsidian,20,minecraft:obsidian,100)
RB(2,4,13,minecraft:crying_obsidian,20,minecraft:obsidian,100)
RB(0,4,14,minecraft:crying_obsidian,20,minecraft:obsidian,100)
RB(1,4,14,minecraft:crying_obsidian,20,minecraft:obsidian,100)
RB(0,5,0,minecraft:crying_obsidian,20,minecraft:obsidian,100)
RB(1,5,0,minecraft:crying_obsidian,20,minecraft:obsidian,100)
RB(2,5,0,minecraft:crying_obsidian,20,minecraft:obsidian,100)
RB(3,5,0,minecraft:crying_obsidian,20,minecraft:obsidian,100)
RB(4,5,0,minecraft:crying_obsidian,20,minecraft:obsidian,100)
RB(5,5,0,minecraft:crying_obsidian,20,minecraft:obsidian,100)
RB(6,5,0,minecraft:crying_obsidian,20,minecraft:obsidian,100)
RB(7,5,0,minecraft:crying_obsidian,20,minecraft:obsidian,100)
RB(0,5,1,minecraft:crying_obsidian,20,minecraft:obsidian,100)
RB(1,5,1,minecraft:crying_obsidian,20,minecraft:obsidian,100)
RB(2,5,1,minecraft:crying_obsidian,20,minecraft:obsidian,100)
RB(3,5,1,minecraft:crying_obsidian,20,minecraft:obsidian,100)
RB(4,5,1,minecraft:crying_obsidian,20,minecraft:obsidian,100)
RB(5,5,1,minecraft:crying_obsidian,20,minecraft:obsidian,100)
RB(6,5,1,minecraft:crying_obsidian,20,minecraft:obsidian,100)
RB(7,5,1,minecraft:crying_obsidian,20,minecraft:obsidian,100)
RB(0,5,2,minecraft:crying_obsidian,20,minecraft:obsidian,100)
RB(1,5,2,minecraft:crying_obsidian,20,minecraft:obsidian,100)
RB(2,5,2,minecraft:crying_obsidian,20,minecraft:obsidian,100)
RB(3,5,2,minecraft:crying_obsidian,20,minecraft:obsidian,100)
RB(4,5,2,minecraft:crying_obsidian,20,minecraft:obsidian,100)
RB(5,5,2,minecraft:crying_obsidian,20,minecraft:obsidian,100)
RB(6,5,2,minecraft:crying_obsidian,20,minecraft:obsidian,100)
RB(7,5,2,minecraft:crying_obsidian,20,minecraft:obsidian,100)
RB(0,5,3,minecraft:crying_obsidian,20,minecraft:obsidian,100)
RB(1,5,3,minecraft:crying_obsidian,20,minecraft:obsidian,100)
RB(2,5,3,minecraft:crying_obsidian,20,minecraft:obsidian,100)
RB(3,5,3,minecraft:crying_obsidian,20,minecraft:obsidian,100)
RB(4,5,3,minecraft:crying_obsidian,20,minecraft:obsidian,100)
RB(5,5,3,minecraft:crying_obsidian,20,minecraft:obsidian,100)
RB(6,5,3,minecraft:crying_obsidian,20,minecraft:obsidian,100)
RB(7,5,3,minecraft:crying_obsidian,20,minecraft:obsidian,100)
RB(0,5,4,minecraft:crying_obsidian,20,minecraft:obsidian,100)
RB(1,5,4,minecraft:crying_obsidian,20,minecraft:obsidian,100)
RB(2,5,4,minecraft:crying_obsidian,20,minecraft:obsidian,100)
RB(3,5,4,minecraft:crying_obsidian,20,minecraft:obsidian,100)
RB(4,5,4,minecraft:crying_obsidian,20,minecraft:obsidian,100)
RB(5,5,4,minecraft:crying_obsidian,20,minecraft:obsidian,100)
RB(6,5,4,minecraft:crying_obsidian,20,minecraft:obsidian,100)
RB(7,5,4,minecraft:crying_obsidian,20,minecraft:obsidian,100)
RB(8,5,4,minecraft:crying_obsidian,20,minecraft:obsidian,100)
RB(0,5,5,minecraft:crying_obsidian,20,minecraft:obsidian,100)
RB(1,5,5,minecraft:crying_obsidian,20,minecraft:obsidian,100)
RB(2,5,5,minecraft:crying_obsidian,20,minecraft:obsidian,100)
RB(3,5,5,minecraft:crying_obsidian,20,minecraft:obsidian,100)
RB(4,5,5,minecraft:crying_obsidian,20,minecraft:obsidian,100)
RB(5,5,5,minecraft:crying_obsidian,20,minecraft:obsidian,100)
RB(6,5,5,minecraft:crying_obsidian,20,minecraft:obsidian,100)
RB(7,5,5,minecraft:crying_obsidian,20,minecraft:obsidian,100)
RB(8,5,5,minecraft:crying_obsidian,20,minecraft:obsidian,100)
RB(0,5,6,minecraft:crying_obsidian,20,minecraft:obsidian,100)
RB(1,5,6,minecraft:crying_obsidian,20,minecraft:obsidian,100)
RB(2,5,6,minecraft:crying_obsidian,20,minecraft:obsidian,100)
RB(3,5,6,minecraft:crying_obsidian,20,minecraft:obsidian,100)
RB(4,5,6,minecraft:crying_obsidian,20,minecraft:obsidian,100)
RB(5,5,6,minecraft:crying_obsidian,20,minecraft:obsidian,100)
RB(6,5,6,minecraft:crying_obsidian,20,minecraft:obsidian,100)
RB(7,5,6,minecraft:crying_obsidian,20,minecraft:obsidian,100)
RB(0,5,7,minecraft:crying_obsidian,20,minecraft:obsidian,100)
RB(1,5,7,minecraft:crying_obsidian,20,minecraft:obsidian,100)
RB(2,5,7,minecraft:crying_obsidian,20,minecraft:obsidian,100)
RB(3,5,7,minecraft:crying_obsidian,20,minecraft:obsidian,100)
RB(4,5,7,minecraft:crying_obsidian,20,minecraft:obsidian,100)
RB(5,5,7,minecraft:crying_obsidian,20,minecraft:obsidian,100)
RB(6,5,7,minecraft:crying_obsidian,20,minecraft:obsidian,100)
RB(7,5,7,minecraft:crying_obsidian,20,minecraft:obsidian,100)
RB(0,5,8,minecraft:crying_obsidian,20,minecraft:obsidian,100)
RB(1,5,8,minecraft:crying_obsidian,20,minecraft:obsidian,100)
RB(2,5,8,minecraft:crying_obsidian,20,minecraft:obsidian,100)
RB(3,5,8,minecraft:crying_obsidian,20,minecraft:obsidian,100)
RB(4,5,8,minecraft:crying_obsidian,20,minecraft:obsidian,100)
RB(5,5,8,minecraft:crying_obsidian,20,minecraft:obsidian,100)
RB(6,5,8,minecraft:crying_obsidian,20,minecraft:obsidian,100)
RB(0,5,9,minecraft:crying_obsidian,20,minecraft:obsidian,100)
RB(1,5,9,minecraft:crying_obsidian,20,minecraft:obsidian,100)
RB(2,5,9,minecraft:crying_obsidian,20,minecraft:obsidian,100)
RB(3,5,9,minecraft:crying_obsidian,20,minecraft:obsidian,100)
RB(4,5,9,minecraft:crying_obsidian,20,minecraft:obsidian,100)
RB(5,5,9,minecraft:crying_obsidian,20,minecraft:obsidian,100)
RB(0,5,10,minecraft:crying_obsidian,20,minecraft:obsidian,100)
RB(1,5,10,minecraft:crying_obsidian,20,minecraft:obsidian,100)
RB(2,5,10,minecraft:crying_obsidian,20,minecraft:obsidian,100)
RB(3,5,10,minecraft:crying_obsidian,20,minecraft:obsidian,100)
RB(0,5,11,minecraft:crying_obsidian,20,minecraft:obsidian,100)
RB(1,5,11,minecraft:crying_obsidian,20,minecraft:obsidian,100)
RB(2,5,11,minecraft:crying_obsidian,20,minecraft:obsidian,100)
RB(3,5,11,minecraft:crying_obsidian,20,minecraft:obsidian,100)
RB(0,5,12,minecraft:crying_obsidian,20,minecraft:obsidian,100)
RB(1,5,12,minecraft:crying_obsidian,20,minecraft:obsidian,100)
RB(2,5,12,minecraft:crying_obsidian,20,minecraft:obsidian,100)
RB(3,5,12,minecraft:crying_obsidian,20,minecraft:obsidian,100)
RB(0,5,13,minecraft:crying_obsidian,20,minecraft:obsidian,100)
RB(1,5,13,minecraft:crying_obsidian,20,minecraft:obsidian,100)
RB(2,5,13,minecraft:crying_obsidian,20,minecraft:obsidian,100)
RB(0,5,14,minecraft:crying_obsidian,20,minecraft:obsidian,100)
RB(1,5,14,minecraft:crying_obsidian,20,minecraft:obsidian,100)
RB(0,6,0,minecraft:crying_obsidian,20,minecraft:obsidian,100)
RB(1,6,0,minecraft:crying_obsidian,20,minecraft:obsidian,100)
RB(2,6,0,minecraft:crying_obsidian,20,minecraft:obsidian,100)
RB(3,6,0,minecraft:crying_obsidian,20,minecraft:obsidian,100)
RB(4,6,0,minecraft:crying_obsidian,20,minecraft:obsidian,100)
RB(5,6,0,minecraft:crying_obsidian,20,minecraft:obsidian,100)
RB(6,6,0,minecraft:crying_obsidian,20,minecraft:obsidian,100)
RB(7,6,0,minecraft:crying_obsidian,20,minecraft:obsidian,100)
RB(0,6,1,minecraft:crying_obsidian,20,minecraft:obsidian,100)
RB(1,6,1,minecraft:crying_obsidian,20,minecraft:obsidian,100)
RB(2,6,1,minecraft:crying_obsidian,20,minecraft:obsidian,100)
RB(3,6,1,minecraft:crying_obsidian,20,minecraft:obsidian,100)
RB(4,6,1,minecraft:crying_obsidian,20,minecraft:obsidian,100)
RB(5,6,1,minecraft:crying_obsidian,20,minecraft:obsidian,100)
RB(6,6,1,minecraft:crying_obsidian,20,minecraft:obsidian,100)
RB(7,6,1,minecraft:crying_obsidian,20,minecraft:obsidian,100)
RB(0,6,2,minecraft:crying_obsidian,20,minecraft:obsidian,100)
RB(1,6,2,minecraft:crying_obsidian,20,minecraft:obsidian,100)
RB(2,6,2,minecraft:crying_obsidian,20,minecraft:obsidian,100)
RB(3,6,2,minecraft:crying_obsidian,20,minecraft:obsidian,100)
RB(4,6,2,minecraft:crying_obsidian,20,minecraft:obsidian,100)
RB(5,6,2,minecraft:crying_obsidian,20,minecraft:obsidian,100)
RB(6,6,2,minecraft:crying_obsidian,20,minecraft:obsidian,100)
RB(7,6,2,minecraft:crying_obsidian,20,minecraft:obsidian,100)
RB(0,6,3,minecraft:crying_obsidian,20,minecraft:obsidian,100)
RB(1,6,3,minecraft:crying_obsidian,20,minecraft:obsidian,100)
RB(2,6,3,minecraft:crying_obsidian,20,minecraft:obsidian,100)
RB(3,6,3,minecraft:crying_obsidian,20,minecraft:obsidian,100)
RB(4,6,3,minecraft:crying_obsidian,20,minecraft:obsidian,100)
RB(5,6,3,minecraft:crying_obsidian,20,minecraft:obsidian,100)
RB(6,6,3,minecraft:crying_obsidian,20,minecraft:obsidian,100)
RB(7,6,3,minecraft:crying_obsidian,20,minecraft:obsidian,100)
RB(0,6,4,minecraft:crying_obsidian,20,minecraft:obsidian,100)
RB(1,6,4,minecraft:crying_obsidian,20,minecraft:obsidian,100)
RB(2,6,4,minecraft:crying_obsidian,20,minecraft:obsidian,100)
RB(3,6,4,minecraft:crying_obsidian,20,minecraft:obsidian,100)
RB(4,6,4,minecraft:crying_obsidian,20,minecraft:obsidian,100)
RB(5,6,4,minecraft:crying_obsidian,20,minecraft:obsidian,100)
RB(6,6,4,minecraft:crying_obsidian,20,minecraft:obsidian,100)
RB(7,6,4,minecraft:crying_obsidian,20,minecraft:obsidian,100)
RB(0,6,5,minecraft:crying_obsidian,20,minecraft:obsidian,100)
RB(1,6,5,minecraft:crying_obsidian,20,minecraft:obsidian,100)
RB(2,6,5,minecraft:crying_obsidian,20,minecraft:obsidian,100)
RB(3,6,5,minecraft:crying_obsidian,20,minecraft:obsidian,100)
RB(4,6,5,minecraft:crying_obsidian,20,minecraft:obsidian,100)
RB(5,6,5,minecraft:crying_obsidian,20,minecraft:obsidian,100)
RB(6,6,5,minecraft:crying_obsidian,20,minecraft:obsidian,100)
RB(7,6,5,minecraft:crying_obsidian,20,minecraft:obsidian,100)
RB(8,6,5,minecraft:crying_obsidian,20,minecraft:obsidian,100)
RB(0,6,6,minecraft:crying_obsidian,20,minecraft:obsidian,100)
RB(1,6,6,minecraft:crying_obsidian,20,minecraft:obsidian,100)
RB(2,6,6,minecraft:crying_obsidian,20,minecraft:obsidian,100)
RB(3,6,6,minecraft:crying_obsidian,20,minecraft:obsidian,100)
RB(4,6,6,minecraft:crying_obsidian,20,minecraft:obsidian,100)
RB(5,6,6,minecraft:crying_obsidian,20,minecraft:obsidian,100)
RB(6,6,6,minecraft:crying_obsidian,20,minecraft:obsidian,100)
RB(7,6,6,minecraft:crying_obsidian,20,minecraft:obsidian,100)
RB(0,6,7,minecraft:crying_obsidian,20,minecraft:obsidian,100)
RB(1,6,7,minecraft:crying_obsidian,20,minecraft:obsidian,100)
RB(2,6,7,minecraft:crying_obsidian,20,minecraft:obsidian,100)
RB(3,6,7,minecraft:crying_obsidian,20,minecraft:obsidian,100)
RB(4,6,7,minecraft:crying_obsidian,20,minecraft:obsidian,100)
RB(5,6,7,minecraft:crying_obsidian,20,minecraft:obsidian,100)
RB(6,6,7,minecraft:crying_obsidian,20,minecraft:obsidian,100)
RB(7,6,7,minecraft:crying_obsidian,20,minecraft:obsidian,100)
RB(0,6,8,minecraft:crying_obsidian,20,minecraft:obsidian,100)
RB(1,6,8,minecraft:crying_obsidian,20,minecraft:obsidian,100)
RB(2,6,8,minecraft:crying_obsidian,20,minecraft:obsidian,100)
RB(3,6,8,minecraft:crying_obsidian,20,minecraft:obsidian,100)
RB(4,6,8,minecraft:crying_obsidian,20,minecraft:obsidian,100)
RB(5,6,8,minecraft:crying_obsidian,20,minecraft:obsidian,100)
RB(6,6,8,minecraft:crying_obsidian,20,minecraft:obsidian,100)
RB(0,6,9,minecraft:crying_obsidian,20,minecraft:obsidian,100)
RB(1,6,9,minecraft:crying_obsidian,20,minecraft:obsidian,100)
RB(2,6,9,minecraft:crying_obsidian,20,minecraft:obsidian,100)
RB(3,6,9,minecraft:crying_obsidian,20,minecraft:obsidian,100)
RB(4,6,9,minecraft:crying_obsidian,20,minecraft:obsidian,100)
RB(5,6,9,minecraft:crying_obsidian,20,minecraft:obsidian,100)
RB(0,6,10,minecraft:crying_obsidian,20,minecraft:obsidian,100)
RB(1,6,10,minecraft:crying_obsidian,20,minecraft:obsidian,100)
RB(2,6,10,minecraft:crying_obsidian,20,minecraft:obsidian,100)
RB(3,6,10,minecraft:crying_obsidian,20,minecraft:obsidian,100)
RB(0,6,11,minecraft:crying_obsidian,20,minecraft:obsidian,100)
RB(1,6,11,minecraft:crying_obsidian,20,minecraft:obsidian,100)
RB(2,6,11,minecraft:crying_obsidian,20,minecraft:obsidian,100)
RB(3,6,11,minecraft:crying_obsidian,20,minecraft:obsidian,100)
RB(0,6,12,minecraft:crying_obsidian,20,minecraft:obsidian,100)
RB(1,6,12,minecraft:crying_obsidian,20,minecraft:obsidian,100)
RB(2,6,12,minecraft:crying_obsidian,20,minecraft:obsidian,100)
RB(3,6,12,minecraft:crying_obsidian,20,minecraft:obsidian,100)
RB(0,6,13,minecraft:crying_obsidian,20,minecraft:obsidian,100)
RB(1,6,13,minecraft:crying_obsidian,20,minecraft:obsidian,100)
RB(0,7,0,minecraft:crying_obsidian,20,minecraft:obsidian,100)
RB(1,7,0,minecraft:crying_obsidian,20,minecraft:obsidian,100)
RB(2,7,0,minecraft:crying_obsidian,20,minecraft:obsidian,100)
RB(3,7,0,minecraft:crying_obsidian,20,minecraft:obsidian,100)
RB(4,7,0,minecraft:crying_obsidian,20,minecraft:obsidian,100)
RB(5,7,0,minecraft:crying_obsidian,20,minecraft:obsidian,100)
RB(6,7,0,minecraft:crying_obsidian,20,minecraft:obsidian,100)
RB(7,7,0,minecraft:crying_obsidian,20,minecraft:obsidian,100)
RB(0,7,1,minecraft:crying_obsidian,20,minecraft:obsidian,100)
RB(1,7,1,minecraft:crying_obsidian,20,minecraft:obsidian,100)
RB(2,7,1,minecraft:crying_obsidian,20,minecraft:obsidian,100)
RB(3,7,1,minecraft:crying_obsidian,20,minecraft:obsidian,100)
RB(4,7,1,minecraft:crying_obsidian,20,minecraft:obsidian,100)
RB(5,7,1,minecraft:crying_obsidian,20,minecraft:obsidian,100)
RB(6,7,1,minecraft:crying_obsidian,20,minecraft:obsidian,100)
RB(7,7,1,minecraft:crying_obsidian,20,minecraft:obsidian,100)
RB(0,7,2,minecraft:crying_obsidian,20,minecraft:obsidian,100)
RB(1,7,2,minecraft:crying_obsidian,20,minecraft:obsidian,100)
RB(2,7,2,minecraft:crying_obsidian,20,minecraft:obsidian,100)
RB(3,7,2,minecraft:crying_obsidian,20,minecraft:obsidian,100)
RB(4,7,2,minecraft:crying_obsidian,20,minecraft:obsidian,100)
RB(5,7,2,minecraft:crying_obsidian,20,minecraft:obsidian,100)
RB(6,7,2,minecraft:crying_obsidian,20,minecraft:obsidian,100)
RB(0,7,3,minecraft:crying_obsidian,20,minecraft:obsidian,100)
RB(1,7,3,minecraft:crying_obsidian,20,minecraft:obsidian,100)
RB(2,7,3,minecraft:crying_obsidian,20,minecraft:obsidian,100)
RB(3,7,3,minecraft:crying_obsidian,20,minecraft:obsidian,100)
RB(4,7,3,minecraft:crying_obsidian,20,minecraft:obsidian,100)
RB(5,7,3,minecraft:crying_obsidian,20,minecraft:obsidian,100)
RB(6,7,3,minecraft:crying_obsidian,20,minecraft:obsidian,100)
RB(7,7,3,minecraft:crying_obsidian,20,minecraft:obsidian,100)
RB(0,7,4,minecraft:crying_obsidian,20,minecraft:obsidian,100)
RB(1,7,4,minecraft:crying_obsidian,20,minecraft:obsidian,100)
RB(2,7,4,minecraft:crying_obsidian,20,minecraft:obsidian,100)
RB(3,7,4,minecraft:crying_obsidian,20,minecraft:obsidian,100)
RB(4,7,4,minecraft:crying_obsidian,20,minecraft:obsidian,100)
RB(5,7,4,minecraft:crying_obsidian,20,minecraft:obsidian,100)
RB(6,7,4,minecraft:crying_obsidian,20,minecraft:obsidian,100)
RB(7,7,4,minecraft:crying_obsidian,20,minecraft:obsidian,100)
RB(0,7,5,minecraft:crying_obsidian,20,minecraft:obsidian,100)
RB(1,7,5,minecraft:crying_obsidian,20,minecraft:obsidian,100)
RB(2,7,5,minecraft:crying_obsidian,20,minecraft:obsidian,100)
RB(3,7,5,minecraft:crying_obsidian,20,minecraft:obsidian,100)
RB(4,7,5,minecraft:crying_obsidian,20,minecraft:obsidian,100)
RB(5,7,5,minecraft:crying_obsidian,20,minecraft:obsidian,100)
RB(6,7,5,minecraft:crying_obsidian,20,minecraft:obsidian,100)
RB(7,7,5,minecraft:crying_obsidian,20,minecraft:obsidian,100)
RB(0,7,6,minecraft:crying_obsidian,20,minecraft:obsidian,100)
RB(1,7,6,minecraft:crying_obsidian,20,minecraft:obsidian,100)
RB(2,7,6,minecraft:crying_obsidian,20,minecraft:obsidian,100)
RB(3,7,6,minecraft:crying_obsidian,20,minecraft:obsidian,100)
RB(4,7,6,minecraft:crying_obsidian,20,minecraft:obsidian,100)
RB(5,7,6,minecraft:crying_obsidian,20,minecraft:obsidian,100)
RB(6,7,6,minecraft:crying_obsidian,20,minecraft:obsidian,100)
RB(7,7,6,minecraft:crying_obsidian,20,minecraft:obsidian,100)
RB(0,7,7,minecraft:crying_obsidian,20,minecraft:obsidian,100)
RB(1,7,7,minecraft:crying_obsidian,20,minecraft:obsidian,100)
RB(2,7,7,minecraft:crying_obsidian,20,minecraft:obsidian,100)
RB(3,7,7,minecraft:crying_obsidian,20,minecraft:obsidian,100)
RB(4,7,7,minecraft:crying_obsidian,20,minecraft:obsidian,100)
RB(5,7,7,minecraft:crying_obsidian,20,minecraft:obsidian,100)
RB(6,7,7,minecraft:crying_obsidian,20,minecraft:obsidian,100)
RB(0,7,8,minecraft:crying_obsidian,20,minecraft:obsidian,100)
RB(1,7,8,minecraft:crying_obsidian,20,minecraft:obsidian,100)
RB(2,7,8,minecraft:crying_obsidian,20,minecraft:obsidian,100)
RB(3,7,8,minecraft:crying_obsidian,20,minecraft:obsidian,100)
RB(4,7,8,minecraft:crying_obsidian,20,minecraft:obsidian,100)
RB(5,7,8,minecraft:crying_obsidian,20,minecraft:obsidian,100)
RB(0,7,9,minecraft:crying_obsidian,20,minecraft:obsidian,100)
RB(1,7,9,minecraft:crying_obsidian,20,minecraft:obsidian,100)
RB(2,7,9,minecraft:crying_obsidian,20,minecraft:obsidian,100)
RB(3,7,9,minecraft:crying_obsidian,20,minecraft:obsidian,100)
RB(4,7,9,minecraft:crying_obsidian,20,minecraft:obsidian,100)
RB(5,7,9,minecraft:crying_obsidian,20,minecraft:obsidian,100)
RB(0,7,10,minecraft:crying_obsidian,20,minecraft:obsidian,100)
RB(1,7,10,minecraft:crying_obsidian,20,minecraft:obsidian,100)
RB(2,7,10,minecraft:crying_obsidian,20,minecraft:obsidian,100)
RB(3,7,10,minecraft:crying_obsidian,20,minecraft:obsidian,100)
RB(0,7,11,minecraft:crying_obsidian,20,minecraft:obsidian,100)
RB(1,7,11,minecraft:crying_obsidian,20,minecraft:obsidian,100)
RB(2,7,11,minecraft:crying_obsidian,20,minecraft:obsidian,100)
RB(3,7,11,minecraft:crying_obsidian,20,minecraft:obsidian,100)
RB(0,7,12,minecraft:crying_obsidian,20,minecraft:obsidian,100)
RB(1,7,12,minecraft:crying_obsidian,20,minecraft:obsidian,100)
RB(0,8,0,minecraft:crying_obsidian,20,minecraft:obsidian,100)
RB(1,8,0,minecraft:crying_obsidian,20,minecraft:obsidian,100)
RB(2,8,0,minecraft:crying_obsidian,20,minecraft:obsidian,100)
RB(3,8,0,minecraft:crying_obsidian,20,minecraft:obsidian,100)
RB(4,8,0,minecraft:crying_obsidian,20,minecraft:obsidian,100)
RB(5,8,0,minecraft:crying_obsidian,20,minecraft:obsidian,100)
RB(6,8,0,minecraft:crying_obsidian,20,minecraft:obsidian,100)
RB(7,8,0,minecraft:crying_obsidian,20,minecraft:obsidian,100)
RB(0,8,1,minecraft:crying_obsidian,20,minecraft:obsidian,100)
RB(1,8,1,minecraft:crying_obsidian,20,minecraft:obsidian,100)
RB(2,8,1,minecraft:crying_obsidian,20,minecraft:obsidian,100)
RB(3,8,1,minecraft:crying_obsidian,20,minecraft:obsidian,100)
RB(4,8,1,minecraft:crying_obsidian,20,minecraft:obsidian,100)
RB(5,8,1,minecraft:crying_obsidian,20,minecraft:obsidian,100)
RB(6,8,1,minecraft:crying_obsidian,20,minecraft:obsidian,100)
RB(7,8,1,minecraft:crying_obsidian,20,minecraft:obsidian,100)
RB(0,8,2,minecraft:crying_obsidian,20,minecraft:obsidian,100)
RB(1,8,2,minecraft:crying_obsidian,20,minecraft:obsidian,100)
RB(2,8,2,minecraft:crying_obsidian,20,minecraft:obsidian,100)
RB(3,8,2,minecraft:crying_obsidian,20,minecraft:obsidian,100)
RB(4,8,2,minecraft:crying_obsidian,20,minecraft:obsidian,100)
RB(5,8,2,minecraft:crying_obsidian,20,minecraft:obsidian,100)
RB(6,8,2,minecraft:crying_obsidian,20,minecraft:obsidian,100)
RB(0,8,3,minecraft:crying_obsidian,20,minecraft:obsidian,100)
RB(1,8,3,minecraft:crying_obsidian,20,minecraft:obsidian,100)
RB(2,8,3,minecraft:crying_obsidian,20,minecraft:obsidian,100)
RB(3,8,3,minecraft:crying_obsidian,20,minecraft:obsidian,100)
RB(4,8,3,minecraft:crying_obsidian,20,minecraft:obsidian,100)
RB(5,8,3,minecraft:crying_obsidian,20,minecraft:obsidian,100)
RB(6,8,3,minecraft:crying_obsidian,20,minecraft:obsidian,100)
RB(0,8,4,minecraft:crying_obsidian,20,minecraft:obsidian,100)
RB(1,8,4,minecraft:crying_obsidian,20,minecraft:obsidian,100)
RB(2,8,4,minecraft:crying_obsidian,20,minecraft:obsidian,100)
RB(3,8,4,minecraft:crying_obsidian,20,minecraft:obsidian,100)
RB(4,8,4,minecraft:crying_obsidian,20,minecraft:obsidian,100)
RB(5,8,4,minecraft:crying_obsidian,20,minecraft:obsidian,100)
RB(6,8,4,minecraft:crying_obsidian,20,minecraft:obsidian,100)
RB(0,8,5,minecraft:crying_obsidian,20,minecraft:obsidian,100)
RB(1,8,5,minecraft:crying_obsidian,20,minecraft:obsidian,100)
RB(2,8,5,minecraft:crying_obsidian,20,minecraft:obsidian,100)
RB(3,8,5,minecraft:crying_obsidian,20,minecraft:obsidian,100)
RB(4,8,5,minecraft:crying_obsidian,20,minecraft:obsidian,100)
RB(5,8,5,minecraft:crying_obsidian,20,minecraft:obsidian,100)
RB(6,8,5,minecraft:crying_obsidian,20,minecraft:obsidian,100)
RB(7,8,5,minecraft:crying_obsidian,20,minecraft:obsidian,100)
RB(0,8,6,minecraft:crying_obsidian,20,minecraft:obsidian,100)
RB(1,8,6,minecraft:crying_obsidian,20,minecraft:obsidian,100)
RB(2,8,6,minecraft:crying_obsidian,20,minecraft:obsidian,100)
RB(3,8,6,minecraft:crying_obsidian,20,minecraft:obsidian,100)
RB(4,8,6,minecraft:crying_obsidian,20,minecraft:obsidian,100)
RB(5,8,6,minecraft:crying_obsidian,20,minecraft:obsidian,100)
RB(6,8,6,minecraft:crying_obsidian,20,minecraft:obsidian,100)
RB(7,8,6,minecraft:crying_obsidian,20,minecraft:obsidian,100)
RB(0,8,7,minecraft:crying_obsidian,20,minecraft:obsidian,100)
RB(1,8,7,minecraft:crying_obsidian,20,minecraft:obsidian,100)
RB(2,8,7,minecraft:crying_obsidian,20,minecraft:obsidian,100)
RB(3,8,7,minecraft:crying_obsidian,20,minecraft:obsidian,100)
RB(4,8,7,minecraft:crying_obsidian,20,minecraft:obsidian,100)
RB(5,8,7,minecraft:crying_obsidian,20,minecraft:obsidian,100)
RB(6,8,7,minecraft:crying_obsidian,20,minecraft:obsidian,100)
RB(0,8,8,minecraft:crying_obsidian,20,minecraft:obsidian,100)
RB(1,8,8,minecraft:crying_obsidian,20,minecraft:obsidian,100)
RB(2,8,8,minecraft:crying_obsidian,20,minecraft:obsidian,100)
RB(3,8,8,minecraft:crying_obsidian,20,minecraft:obsidian,100)
RB(4,8,8,minecraft:crying_obsidian,20,minecraft:obsidian,100)
RB(5,8,8,minecraft:crying_obsidian,20,minecraft:obsidian,100)
RB(0,8,9,minecraft:crying_obsidian,20,minecraft:obsidian,100)
RB(1,8,9,minecraft:crying_obsidian,20,minecraft:obsidian,100)
RB(2,8,9,minecraft:crying_obsidian,20,minecraft:obsidian,100)
RB(3,8,9,minecraft:crying_obsidian,20,minecraft:obsidian,100)
RB(4,8,9,minecraft:crying_obsidian,20,minecraft:obsidian,100)
RB(5,8,9,minecraft:crying_obsidian,20,minecraft:obsidian,100)
RB(0,8,10,minecraft:crying_obsidian,20,minecraft:obsidian,100)
RB(1,8,10,minecraft:crying_obsidian,20,minecraft:obsidian,100)
RB(2,8,10,minecraft:crying_obsidian,20,minecraft:obsidian,100)
RB(3,8,10,minecraft:crying_obsidian,20,minecraft:obsidian,100)
RB(0,8,11,minecraft:crying_obsidian,20,minecraft:obsidian,100)
RB(1,8,11,minecraft:crying_obsidian,20,minecraft:obsidian,100)
RB(2,8,11,minecraft:crying_obsidian,20,minecraft:obsidian,100)
RB(0,8,12,minecraft:crying_obsidian,20,minecraft:obsidian,100)
RB(0,9,0,minecraft:crying_obsidian,20,minecraft:obsidian,100)
RB(1,9,0,minecraft:crying_obsidian,20,minecraft:obsidian,100)
RB(2,9,0,minecraft:crying_obsidian,20,minecraft:obsidian,100)
RB(3,9,0,minecraft:crying_obsidian,20,minecraft:obsidian,100)
RB(4,9,0,minecraft:crying_obsidian,20,minecraft:obsidian,100)
RB(5,9,0,minecraft:crying_obsidian,20,minecraft:obsidian,100)
RB(6,9,0,minecraft:crying_obsidian,20,minecraft:obsidian,100)
RB(0,9,1,minecraft:crying_obsidian,20,minecraft:obsidian,100)
RB(1,9,1,minecraft:crying_obsidian,20,minecraft:obsidian,100)
RB(2,9,1,minecraft:crying_obsidian,20,minecraft:obsidian,100)
RB(3,9,1,minecraft:crying_obsidian,20,minecraft:obsidian,100)
RB(4,9,1,minecraft:crying_obsidian,20,minecraft:obsidian,100)
RB(5,9,1,minecraft:crying_obsidian,20,minecraft:obsidian,100)
RB(6,9,1,minecraft:crying_obsidian,20,minecraft:obsidian,100)
RB(7,9,1,minecraft:crying_obsidian,20,minecraft:obsidian,100)
RB(0,9,2,minecraft:crying_obsidian,20,minecraft:obsidian,100)
RB(1,9,2,minecraft:crying_obsidian,20,minecraft:obsidian,100)
RB(2,9,2,minecraft:crying_obsidian,20,minecraft:obsidian,100)
RB(3,9,2,minecraft:crying_obsidian,20,minecraft:obsidian,100)
RB(4,9,2,minecraft:crying_obsidian,20,minecraft:obsidian,100)
RB(5,9,2,minecraft:crying_obsidian,20,minecraft:obsidian,100)
RB(6,9,2,minecraft:crying_obsidian,20,minecraft:obsidian,100)
RB(0,9,3,minecraft:crying_obsidian,20,minecraft:obsidian,100)
RB(1,9,3,minecraft:crying_obsidian,20,minecraft:obsidian,100)
RB(2,9,3,minecraft:crying_obsidian,20,minecraft:obsidian,100)
RB(3,9,3,minecraft:crying_obsidian,20,minecraft:obsidian,100)
RB(4,9,3,minecraft:crying_obsidian,20,minecraft:obsidian,100)
RB(5,9,3,minecraft:crying_obsidian,20,minecraft:obsidian,100)
RB(6,9,3,minecraft:crying_obsidian,20,minecraft:obsidian,100)
RB(0,9,4,minecraft:crying_obsidian,20,minecraft:obsidian,100)
RB(1,9,4,minecraft:crying_obsidian,20,minecraft:obsidian,100)
RB(2,9,4,minecraft:crying_obsidian,20,minecraft:obsidian,100)
RB(3,9,4,minecraft:crying_obsidian,20,minecraft:obsidian,100)
RB(4,9,4,minecraft:crying_obsidian,20,minecraft:obsidian,100)
RB(5,9,4,minecraft:crying_obsidian,20,minecraft:obsidian,100)
RB(6,9,4,minecraft:crying_obsidian,20,minecraft:obsidian,100)
RB(0,9,5,minecraft:crying_obsidian,20,minecraft:obsidian,100)
RB(1,9,5,minecraft:crying_obsidian,20,minecraft:obsidian,100)
RB(2,9,5,minecraft:crying_obsidian,20,minecraft:obsidian,100)
RB(3,9,5,minecraft:crying_obsidian,20,minecraft:obsidian,100)
RB(4,9,5,minecraft:crying_obsidian,20,minecraft:obsidian,100)
RB(5,9,5,minecraft:crying_obsidian,20,minecraft:obsidian,100)
RB(6,9,5,minecraft:crying_obsidian,20,minecraft:obsidian,100)
RB(0,9,6,minecraft:crying_obsidian,20,minecraft:obsidian,100)
RB(1,9,6,minecraft:crying_obsidian,20,minecraft:obsidian,100)
RB(2,9,6,minecraft:crying_obsidian,20,minecraft:obsidian,100)
RB(3,9,6,minecraft:crying_obsidian,20,minecraft:obsidian,100)
RB(4,9,6,minecraft:crying_obsidian,20,minecraft:obsidian,100)
RB(5,9,6,minecraft:crying_obsidian,20,minecraft:obsidian,100)
RB(6,9,6,minecraft:crying_obsidian,20,minecraft:obsidian,100)
RB(0,9,7,minecraft:crying_obsidian,20,minecraft:obsidian,100)
RB(1,9,7,minecraft:crying_obsidian,20,minecraft:obsidian,100)
RB(2,9,7,minecraft:crying_obsidian,20,minecraft:obsidian,100)
RB(3,9,7,minecraft:crying_obsidian,20,minecraft:obsidian,100)
RB(4,9,7,minecraft:crying_obsidian,20,minecraft:obsidian,100)
RB(5,9,7,minecraft:crying_obsidian,20,minecraft:obsidian,100)
RB(0,9,8,minecraft:crying_obsidian,20,minecraft:obsidian,100)
RB(1,9,8,minecraft:crying_obsidian,20,minecraft:obsidian,100)
RB(2,9,8,minecraft:crying_obsidian,20,minecraft:obsidian,100)
RB(3,9,8,minecraft:crying_obsidian,20,minecraft:obsidian,100)
RB(4,9,8,minecraft:crying_obsidian,20,minecraft:obsidian,100)
RB(5,9,8,minecraft:crying_obsidian,20,minecraft:obsidian,100)
RB(0,9,9,minecraft:crying_obsidian,20,minecraft:obsidian,100)
RB(1,9,9,minecraft:crying_obsidian,20,minecraft:obsidian,100)
RB(2,9,9,minecraft:crying_obsidian,20,minecraft:obsidian,100)
RB(3,9,9,minecraft:crying_obsidian,20,minecraft:obsidian,100)
RB(4,9,9,minecraft:crying_obsidian,20,minecraft:obsidian,100)
RB(0,9,10,minecraft:crying_obsidian,20,minecraft:obsidian,100)
RB(1,9,10,minecraft:crying_obsidian,20,minecraft:obsidian,100)
RB(2,9,10,minecraft:crying_obsidian,20,minecraft:obsidian,100)
RB(3,9,10,minecraft:crying_obsidian,20,minecraft:obsidian,100)
RB(0,9,11,minecraft:crying_obsidian,20,minecraft:obsidian,100)
RB(1,9,11,minecraft:crying_obsidian,20,minecraft:obsidian,100)
RB(0,10,0,minecraft:crying_obsidian,20,minecraft:obsidian,100)
RB(1,10,0,minecraft:crying_obsidian,20,minecraft:obsidian,100)
RB(2,10,0,minecraft:crying_obsidian,20,minecraft:obsidian,100)
RB(3,10,0,minecraft:crying_obsidian,20,minecraft:obsidian,100)
RB(4,10,0,minecraft:crying_obsidian,20,minecraft:obsidian,100)
RB(5,10,0,minecraft:crying_obsidian,20,minecraft:obsidian,100)
RB(6,10,0,minecraft:crying_obsidian,20,minecraft:obsidian,100)
RB(0,10,1,minecraft:crying_obsidian,20,minecraft:obsidian,100)
RB(1,10,1,minecraft:crying_obsidian,20,minecraft:obsidian,100)
RB(2,10,1,minecraft:crying_obsidian,20,minecraft:obsidian,100)
RB(3,10,1,minecraft:crying_obsidian,20,minecraft:obsidian,100)
RB(4,10,1,minecraft:crying_obsidian,20,minecraft:obsidian,100)
RB(5,10,1,minecraft:crying_obsidian,20,minecraft:obsidian,100)
RB(6,10,1,minecraft:crying_obsidian,20,minecraft:obsidian,100)
RB(7,10,1,minecraft:crying_obsidian,20,minecraft:obsidian,100)
RB(0,10,2,minecraft:crying_obsidian,20,minecraft:obsidian,100)
RB(1,10,2,minecraft:crying_obsidian,20,minecraft:obsidian,100)
RB(2,10,2,minecraft:crying_obsidian,20,minecraft:obsidian,100)
RB(3,10,2,minecraft:crying_obsidian,20,minecraft:obsidian,100)
RB(4,10,2,minecraft:crying_obsidian,20,minecraft:obsidian,100)
RB(5,10,2,minecraft:crying_obsidian,20,minecraft:obsidian,100)
RB(6,10,2,minecraft:crying_obsidian,20,minecraft:obsidian,100)
RB(0,10,3,minecraft:crying_obsidian,20,minecraft:obsidian,100)
RB(1,10,3,minecraft:crying_obsidian,20,minecraft:obsidian,100)
RB(2,10,3,minecraft:crying_obsidian,20,minecraft:obsidian,100)
RB(3,10,3,minecraft:crying_obsidian,20,minecraft:obsidian,100)
RB(4,10,3,minecraft:crying_obsidian,20,minecraft:obsidian,100)
RB(5,10,3,minecraft:crying_obsidian,20,minecraft:obsidian,100)
RB(6,10,3,minecraft:crying_obsidian,20,minecraft:obsidian,100)
RB(0,10,4,minecraft:crying_obsidian,20,minecraft:obsidian,100)
RB(1,10,4,minecraft:crying_obsidian,20,minecraft:obsidian,100)
RB(2,10,4,minecraft:crying_obsidian,20,minecraft:obsidian,100)
RB(3,10,4,minecraft:crying_obsidian,20,minecraft:obsidian,100)
RB(4,10,4,minecraft:crying_obsidian,20,minecraft:obsidian,100)
RB(5,10,4,minecraft:crying_obsidian,20,minecraft:obsidian,100)
RB(6,10,4,minecraft:crying_obsidian,20,minecraft:obsidian,100)
RB(0,10,5,minecraft:crying_obsidian,20,minecraft:obsidian,100)
RB(1,10,5,minecraft:crying_obsidian,20,minecraft:obsidian,100)
RB(2,10,5,minecraft:crying_obsidian,20,minecraft:obsidian,100)
RB(3,10,5,minecraft:crying_obsidian,20,minecraft:obsidian,100)
RB(4,10,5,minecraft:crying_obsidian,20,minecraft:obsidian,100)
RB(5,10,5,minecraft:crying_obsidian,20,minecraft:obsidian,100)
RB(6,10,5,minecraft:crying_obsidian,20,minecraft:obsidian,100)
RB(0,10,6,minecraft:crying_obsidian,20,minecraft:obsidian,100)
RB(1,10,6,minecraft:crying_obsidian,20,minecraft:obsidian,100)
RB(2,10,6,minecraft:crying_obsidian,20,minecraft:obsidian,100)
RB(3,10,6,minecraft:crying_obsidian,20,minecraft:obsidian,100)
RB(4,10,6,minecraft:crying_obsidian,20,minecraft:obsidian,100)
RB(5,10,6,minecraft:crying_obsidian,20,minecraft:obsidian,100)
RB(6,10,6,minecraft:crying_obsidian,20,minecraft:obsidian,100)
RB(0,10,7,minecraft:crying_obsidian,20,minecraft:obsidian,100)
RB(1,10,7,minecraft:crying_obsidian,20,minecraft:obsidian,100)
RB(2,10,7,minecraft:crying_obsidian,20,minecraft:obsidian,100)
RB(3,10,7,minecraft:crying_obsidian,20,minecraft:obsidian,100)
RB(4,10,7,minecraft:crying_obsidian,20,minecraft:obsidian,100)
RB(5,10,7,minecraft:crying_obsidian,20,minecraft:obsidian,100)
RB(0,10,8,minecraft:crying_obsidian,20,minecraft:obsidian,100)
RB(1,10,8,minecraft:crying_obsidian,20,minecraft:obsidian,100)
RB(2,10,8,minecraft:crying_obsidian,20,minecraft:obsidian,100)
RB(3,10,8,minecraft:crying_obsidian,20,minecraft:obsidian,100)
RB(4,10,8,minecraft:crying_obsidian,20,minecraft:obsidian,100)
RB(5,10,8,minecraft:crying_obsidian,20,minecraft:obsidian,100)
RB(0,10,9,minecraft:crying_obsidian,20,minecraft:obsidian,100)
RB(1,10,9,minecraft:crying_obsidian,20,minecraft:obsidian,100)
RB(2,10,9,minecraft:crying_obsidian,20,minecraft:obsidian,100)
RB(3,10,9,minecraft:crying_obsidian,20,minecraft:obsidian,100)
RB(0,10,10,minecraft:crying_obsidian,20,minecraft:obsidian,100)
RB(1,10,10,minecraft:crying_obsidian,20,minecraft:obsidian,100)
RB(2,10,10,minecraft:crying_obsidian,20,minecraft:obsidian,100)
RB(0,10,11,minecraft:crying_obsidian,20,minecraft:obsidian,100)
RB(0,11,0,minecraft:crying_obsidian,20,minecraft:obsidian,100)
RB(1,11,0,minecraft:crying_obsidian,20,minecraft:obsidian,100)
RB(2,11,0,minecraft:crying_obsidian,20,minecraft:obsidian,100)
RB(3,11,0,minecraft:crying_obsidian,20,minecraft:obsidian,100)
RB(4,11,0,minecraft:crying_obsidian,20,minecraft:obsidian,100)
RB(5,11,0,minecraft:crying_obsidian,20,minecraft:obsidian,100)
RB(6,11,0,minecraft:crying_obsidian,20,minecraft:obsidian,100)
RB(0,11,1,minecraft:crying_obsidian,20,minecraft:obsidian,100)
RB(1,11,1,minecraft:crying_obsidian,20,minecraft:obsidian,100)
RB(2,11,1,minecraft:crying_obsidian,20,minecraft:obsidian,100)
RB(3,11,1,minecraft:crying_obsidian,20,minecraft:obsidian,100)
RB(4,11,1,minecraft:crying_obsidian,20,minecraft:obsidian,100)
RB(5,11,1,minecraft:crying_obsidian,20,minecraft:obsidian,100)
RB(6,11,1,minecraft:crying_obsidian,20,minecraft:obsidian,100)
RB(0,11,2,minecraft:crying_obsidian,20,minecraft:obsidian,100)
RB(1,11,2,minecraft:crying_obsidian,20,minecraft:obsidian,100)
RB(2,11,2,minecraft:crying_obsidian,20,minecraft:obsidian,100)
RB(3,11,2,minecraft:crying_obsidian,20,minecraft:obsidian,100)
RB(4,11,2,minecraft:crying_obsidian,20,minecraft:obsidian,100)
RB(5,11,2,minecraft:crying_obsidian,20,minecraft:obsidian,100)
RB(6,11,2,minecraft:crying_obsidian,20,minecraft:obsidian,100)
RB(0,11,3,minecraft:crying_obsidian,20,minecraft:obsidian,100)
RB(1,11,3,minecraft:crying_obsidian,20,minecraft:obsidian,100)
RB(2,11,3,minecraft:crying_obsidian,20,minecraft:obsidian,100)
RB(3,11,3,minecraft:crying_obsidian,20,minecraft:obsidian,100)
RB(4,11,3,minecraft:crying_obsidian,20,minecraft:obsidian,100)
RB(5,11,3,minecraft:crying_obsidian,20,minecraft:obsidian,100)
RB(6,11,3,minecraft:crying_obsidian,20,minecraft:obsidian,100)
RB(0,11,4,minecraft:crying_obsidian,20,minecraft:obsidian,100)
RB(1,11,4,minecraft:crying_obsidian,20,minecraft:obsidian,100)
RB(2,11,4,minecraft:crying_obsidian,20,minecraft:obsidian,100)
RB(3,11,4,minecraft:crying_obsidian,20,minecraft:obsidian,100)
RB(4,11,4,minecraft:crying_obsidian,20,minecraft:obsidian,100)
RB(5,11,4,minecraft:crying_obsidian,20,minecraft:obsidian,100)
RB(6,11,4,minecraft:crying_obsidian,20,minecraft:obsidian,100)
RB(0,11,5,minecraft:crying_obsidian,20,minecraft:obsidian,100)
RB(1,11,5,minecraft:crying_obsidian,20,minecraft:obsidian,100)
RB(2,11,5,minecraft:crying_obsidian,20,minecraft:obsidian,100)
RB(3,11,5,minecraft:crying_obsidian,20,minecraft:obsidian,100)
RB(4,11,5,minecraft:crying_obsidian,20,minecraft:obsidian,100)
RB(5,11,5,minecraft:crying_obsidian,20,minecraft:obsidian,100)
RB(6,11,5,minecraft:crying_obsidian,20,minecraft:obsidian,100)
RB(0,11,6,minecraft:crying_obsidian,20,minecraft:obsidian,100)
RB(1,11,6,minecraft:crying_obsidian,20,minecraft:obsidian,100)
RB(2,11,6,minecraft:crying_obsidian,20,minecraft:obsidian,100)
RB(3,11,6,minecraft:crying_obsidian,20,minecraft:obsidian,100)
RB(4,11,6,minecraft:crying_obsidian,20,minecraft:obsidian,100)
RB(5,11,6,minecraft:crying_obsidian,20,minecraft:obsidian,100)
RB(0,11,7,minecraft:crying_obsidian,20,minecraft:obsidian,100)
RB(1,11,7,minecraft:crying_obsidian,20,minecraft:obsidian,100)
RB(2,11,7,minecraft:crying_obsidian,20,minecraft:obsidian,100)
RB(3,11,7,minecraft:crying_obsidian,20,minecraft:obsidian,100)
RB(4,11,7,minecraft:crying_obsidian,20,minecraft:obsidian,100)
RB(5,11,7,minecraft:crying_obsidian,20,minecraft:obsidian,100)
RB(0,11,8,minecraft:crying_obsidian,20,minecraft:obsidian,100)
RB(1,11,8,minecraft:crying_obsidian,20,minecraft:obsidian,100)
RB(2,11,8,minecraft:crying_obsidian,20,minecraft:obsidian,100)
RB(3,11,8,minecraft:crying_obsidian,20,minecraft:obsidian,100)
RB(4,11,8,minecraft:crying_obsidian,20,minecraft:obsidian,100)
RB(0,11,9,minecraft:crying_obsidian,20,minecraft:obsidian,100)
RB(1,11,9,minecraft:crying_obsidian,20,minecraft:obsidian,100)
RB(2,11,9,minecraft:crying_obsidian,20,minecraft:obsidian,100)
RB(3,11,9,minecraft:crying_obsidian,20,minecraft:obsidian,100)
RB(0,11,10,minecraft:crying_obsidian,20,minecraft:obsidian,100)
RB(1,11,10,minecraft:crying_obsidian,20,minecraft:obsidian,100)
RB(0,12,0,minecraft:crying_obsidian,20,minecraft:obsidian,100)
RB(1,12,0,minecraft:crying_obsidian,20,minecraft:obsidian,100)
RB(2,12,0,minecraft:crying_obsidian,20,minecraft:obsidian,100)
RB(3,12,0,minecraft:crying_obsidian,20,minecraft:obsidian,100)
RB(4,12,0,minecraft:crying_obsidian,20,minecraft:obsidian,100)
RB(5,12,0,minecraft:crying_obsidian,20,minecraft:obsidian,100)
RB(6,12,0,minecraft:crying_obsidian,20,minecraft:obsidian,100)
RB(0,12,1,minecraft:crying_obsidian,20,minecraft:obsidian,100)
RB(1,12,1,minecraft:crying_obsidian,20,minecraft:obsidian,100)
RB(2,12,1,minecraft:crying_obsidian,20,minecraft:obsidian,100)
RB(3,12,1,minecraft:crying_obsidian,20,minecraft:obsidian,100)
RB(4,12,1,minecraft:crying_obsidian,20,minecraft:obsidian,100)
RB(5,12,1,minecraft:crying_obsidian,20,minecraft:obsidian,100)
RB(6,12,1,minecraft:crying_obsidian,20,minecraft:obsidian,100)
RB(0,12,2,minecraft:crying_obsidian,20,minecraft:obsidian,100)
RB(1,12,2,minecraft:crying_obsidian,20,minecraft:obsidian,100)
RB(2,12,2,minecraft:crying_obsidian,20,minecraft:obsidian,100)
RB(3,12,2,minecraft:crying_obsidian,20,minecraft:obsidian,100)
RB(4,12,2,minecraft:crying_obsidian,20,minecraft:obsidian,100)
RB(5,12,2,minecraft:crying_obsidian,20,minecraft:obsidian,100)
RB(6,12,2,minecraft:crying_obsidian,20,minecraft:obsidian,100)
RB(0,12,3,minecraft:crying_obsidian,20,minecraft:obsidian,100)
RB(1,12,3,minecraft:crying_obsidian,20,minecraft:obsidian,100)
RB(2,12,3,minecraft:crying_obsidian,20,minecraft:obsidian,100)
RB(3,12,3,minecraft:crying_obsidian,20,minecraft:obsidian,100)
RB(4,12,3,minecraft:crying_obsidian,20,minecraft:obsidian,100)
RB(5,12,3,minecraft:crying_obsidian,20,minecraft:obsidian,100)
RB(6,12,3,minecraft:crying_obsidian,20,minecraft:obsidian,100)
RB(0,12,4,minecraft:crying_obsidian,20,minecraft:obsidian,100)
RB(1,12,4,minecraft:crying_obsidian,20,minecraft:obsidian,100)
RB(2,12,4,minecraft:crying_obsidian,20,minecraft:obsidian,100)
RB(3,12,4,minecraft:crying_obsidian,20,minecraft:obsidian,100)
RB(4,12,4,minecraft:crying_obsidian,20,minecraft:obsidian,100)
RB(5,12,4,minecraft:crying_obsidian,20,minecraft:obsidian,100)
RB(6,12,4,minecraft:crying_obsidian,20,minecraft:obsidian,100)
RB(0,12,5,minecraft:crying_obsidian,20,minecraft:obsidian,100)
RB(1,12,5,minecraft:crying_obsidian,20,minecraft:obsidian,100)
RB(2,12,5,minecraft:crying_obsidian,20,minecraft:obsidian,100)
RB(3,12,5,minecraft:crying_obsidian,20,minecraft:obsidian,100)
RB(4,12,5,minecraft:crying_obsidian,20,minecraft:obsidian,100)
RB(5,12,5,minecraft:crying_obsidian,20,minecraft:obsidian,100)
RB(0,12,6,minecraft:crying_obsidian,20,minecraft:obsidian,100)
RB(1,12,6,minecraft:crying_obsidian,20,minecraft:obsidian,100)
RB(2,12,6,minecraft:crying_obsidian,20,minecraft:obsidian,100)
RB(3,12,6,minecraft:crying_obsidian,20,minecraft:obsidian,100)
RB(4,12,6,minecraft:crying_obsidian,20,minecraft:obsidian,100)
RB(5,12,6,minecraft:crying_obsidian,20,minecraft:obsidian,100)
RB(0,12,7,minecraft:crying_obsidian,20,minecraft:obsidian,100)
RB(1,12,7,minecraft:crying_obsidian,20,minecraft:obsidian,100)
RB(2,12,7,minecraft:crying_obsidian,20,minecraft:obsidian,100)
RB(3,12,7,minecraft:crying_obsidian,20,minecraft:obsidian,100)
RB(4,12,7,minecraft:crying_obsidian,20,minecraft:obsidian,100)
RB(0,12,8,minecraft:crying_obsidian,20,minecraft:obsidian,100)
RB(1,12,8,minecraft:crying_obsidian,20,minecraft:obsidian,100)
RB(2,12,8,minecraft:crying_obsidian,20,minecraft:obsidian,100)
RB(3,12,8,minecraft:crying_obsidian,20,minecraft:obsidian,100)
RB(0,12,9,minecraft:crying_obsidian,20,minecraft:obsidian,100)
RB(1,12,9,minecraft:crying_obsidian,20,minecraft:obsidian,100)
RB(2,12,9,minecraft:crying_obsidian,20,minecraft:obsidian,100)
RB(0,12,10,minecraft:crying_obsidian,20,minecraft:obsidian,100)
RB(0,13,0,minecraft:crying_obsidian,20,minecraft:obsidian,100)
RB(1,13,0,minecraft:crying_obsidian,20,minecraft:obsidian,100)
RB(2,13,0,minecraft:crying_obsidian,20,minecraft:obsidian,100)
RB(3,13,0,minecraft:crying_obsidian,20,minecraft:obsidian,100)
RB(4,13,0,minecraft:crying_obsidian,20,minecraft:obsidian,100)
RB(5,13,0,minecraft:crying_obsidian,20,minecraft:obsidian,100)
RB(6,13,0,minecraft:crying_obsidian,20,minecraft:obsidian,100)
RB(0,13,1,minecraft:crying_obsidian,20,minecraft:obsidian,100)
RB(1,13,1,minecraft:crying_obsidian,20,minecraft:obsidian,100)
RB(2,13,1,minecraft:crying_obsidian,20,minecraft:obsidian,100)
RB(3,13,1,minecraft:crying_obsidian,20,minecraft:obsidian,100)
RB(4,13,1,minecraft:crying_obsidian,20,minecraft:obsidian,100)
RB(5,13,1,minecraft:crying_obsidian,20,minecraft:obsidian,100)
RB(6,13,1,minecraft:crying_obsidian,20,minecraft:obsidian,100)
RB(0,13,2,minecraft:crying_obsidian,20,minecraft:obsidian,100)
RB(1,13,2,minecraft:crying_obsidian,20,minecraft:obsidian,100)
RB(2,13,2,minecraft:crying_obsidian,20,minecraft:obsidian,100)
RB(3,13,2,minecraft:crying_obsidian,20,minecraft:obsidian,100)
RB(4,13,2,minecraft:crying_obsidian,20,minecraft:obsidian,100)
RB(5,13,2,minecraft:crying_obsidian,20,minecraft:obsidian,100)
RB(6,13,2,minecraft:crying_obsidian,20,minecraft:obsidian,100)
RB(0,13,3,minecraft:crying_obsidian,20,minecraft:obsidian,100)
RB(1,13,3,minecraft:crying_obsidian,20,minecraft:obsidian,100)
RB(2,13,3,minecraft:crying_obsidian,20,minecraft:obsidian,100)
RB(3,13,3,minecraft:crying_obsidian,20,minecraft:obsidian,100)
RB(4,13,3,minecraft:crying_obsidian,20,minecraft:obsidian,100)
RB(5,13,3,minecraft:crying_obsidian,20,minecraft:obsidian,100)
RB(0,13,4,minecraft:crying_obsidian,20,minecraft:obsidian,100)
RB(1,13,4,minecraft:crying_obsidian,20,minecraft:obsidian,100)
RB(2,13,4,minecraft:crying_obsidian,20,minecraft:obsidian,100)
RB(3,13,4,minecraft:crying_obsidian,20,minecraft:obsidian,100)
RB(4,13,4,minecraft:crying_obsidian,20,minecraft:obsidian,100)
RB(5,13,4,minecraft:crying_obsidian,20,minecraft:obsidian,100)
RB(0,13,5,minecraft:crying_obsidian,20,minecraft:obsidian,100)
RB(1,13,5,minecraft:crying_obsidian,20,minecraft:obsidian,100)
RB(2,13,5,minecraft:crying_obsidian,20,minecraft:obsidian,100)
RB(3,13,5,minecraft:crying_obsidian,20,minecraft:obsidian,100)
RB(4,13,5,minecraft:crying_obsidian,20,minecraft:obsidian,100)
RB(5,13,5,minecraft:crying_obsidian,20,minecraft:obsidian,100)
RB(0,13,6,minecraft:crying_obsidian,20,minecraft:obsidian,100)
RB(1,13,6,minecraft:crying_obsidian,20,minecraft:obsidian,100)
RB(2,13,6,minecraft:crying_obsidian,20,minecraft:obsidian,100)
RB(3,13,6,minecraft:crying_obsidian,20,minecraft:obsidian,100)
RB(4,13,6,minecraft:crying_obsidian,20,minecraft:obsidian,100)
RB(0,13,7,minecraft:crying_obsidian,20,minecraft:obsidian,100)
RB(1,13,7,minecraft:crying_obsidian,20,minecraft:obsidian,100)
RB(2,13,7,minecraft:crying_obsidian,20,minecraft:obsidian,100)
RB(3,13,7,minecraft:crying_obsidian,20,minecraft:obsidian,100)
RB(4,13,7,minecraft:crying_obsidian,20,minecraft:obsidian,100)
RB(0,13,8,minecraft:crying_obsidian,20,minecraft:obsidian,100)
RB(1,13,8,minecraft:crying_obsidian,20,minecraft:obsidian,100)
RB(2,13,8,minecraft:crying_obsidian,20,minecraft:obsidian,100)
RB(0,13,9,minecraft:crying_obsidian,20,minecraft:obsidian,100)
RB(1,13,9,minecraft:crying_obsidian,20,minecraft:obsidian,100)
RB(0,14,0,minecraft:crying_obsidian,20,minecraft:obsidian,100)
RB(1,14,0,minecraft:crying_obsidian,20,minecraft:obsidian,100)
RB(2,14,0,minecraft:crying_obsidian,20,minecraft:obsidian,100)
RB(3,14,0,minecraft:crying_obsidian,20,minecraft:obsidian,100)
RB(4,14,0,minecraft:crying_obsidian,20,minecraft:obsidian,100)
RB(5,14,0,minecraft:crying_obsidian,20,minecraft:obsidian,100)
RB(0,14,1,minecraft:crying_obsidian,20,minecraft:obsidian,100)
RB(1,14,1,minecraft:crying_obsidian,20,minecraft:obsidian,100)
RB(2,14,1,minecraft:crying_obsidian,20,minecraft:obsidian,100)
RB(3,14,1,minecraft:crying_obsidian,20,minecraft:obsidian,100)
RB(4,14,1,minecraft:crying_obsidian,20,minecraft:obsidian,100)
RB(5,14,1,minecraft:crying_obsidian,20,minecraft:obsidian,100)
RB(6,14,1,minecraft:crying_obsidian,20,minecraft:obsidian,100)
RB(0,14,2,minecraft:crying_obsidian,20,minecraft:obsidian,100)
RB(1,14,2,minecraft:crying_obsidian,20,minecraft:obsidian,100)
RB(2,14,2,minecraft:crying_obsidian,20,minecraft:obsidian,100)
RB(3,14,2,minecraft:crying_obsidian,20,minecraft:obsidian,100)
RB(4,14,2,minecraft:crying_obsidian,20,minecraft:obsidian,100)
RB(5,14,2,minecraft:crying_obsidian,20,minecraft:obsidian,100)
RB(6,14,2,minecraft:crying_obsidian,20,minecraft:obsidian,100)
RB(0,14,3,minecraft:crying_obsidian,20,minecraft:obsidian,100)
RB(1,14,3,minecraft:crying_obsidian,20,minecraft:obsidian,100)
RB(2,14,3,minecraft:crying_obsidian,20,minecraft:obsidian,100)
RB(3,14,3,minecraft:crying_obsidian,20,minecraft:obsidian,100)
RB(4,14,3,minecraft:crying_obsidian,20,minecraft:obsidian,100)
RB(5,14,3,minecraft:crying_obsidian,20,minecraft:obsidian,100)
RB(0,14,4,minecraft:crying_obsidian,20,minecraft:obsidian,100)
RB(1,14,4,minecraft:crying_obsidian,20,minecraft:obsidian,100)
RB(2,14,4,minecraft:crying_obsidian,20,minecraft:obsidian,100)
RB(3,14,4,minecraft:crying_obsidian,20,minecraft:obsidian,100)
RB(4,14,4,minecraft:crying_obsidian,20,minecraft:obsidian,100)
RB(5,14,4,minecraft:crying_obsidian,20,minecraft:obsidian,100)
RB(0,14,5,minecraft:crying_obsidian,20,minecraft:obsidian,100)
RB(1,14,5,minecraft:crying_obsidian,20,minecraft:obsidian,100)
RB(2,14,5,minecraft:crying_obsidian,20,minecraft:obsidian,100)
RB(3,14,5,minecraft:crying_obsidian,20,minecraft:obsidian,100)
RB(4,14,5,minecraft:crying_obsidian,20,minecraft:obsidian,100)
RB(5,14,5,minecraft:crying_obsidian,20,minecraft:obsidian,100)
RB(0,14,6,minecraft:crying_obsidian,20,minecraft:obsidian,100)
RB(1,14,6,minecraft:crying_obsidian,20,minecraft:obsidian,100)
RB(2,14,6,minecraft:crying_obsidian,20,minecraft:obsidian,100)
RB(3,14,6,minecraft:crying_obsidian,20,minecraft:obsidian,100)
RB(0,14,7,minecraft:crying_obsidian,20,minecraft:obsidian,100)
RB(1,14,7,minecraft:crying_obsidian,20,minecraft:obsidian,100)
RB(2,14,7,minecraft:crying_obsidian,20,minecraft:obsidian,100)
RB(3,14,7,minecraft:crying_obsidian,20,minecraft:obsidian,100)
RB(0,14,8,minecraft:crying_obsidian,20,minecraft:obsidian,100)
RB(1,14,8,minecraft:crying_obsidian,20,minecraft:obsidian,100)
RB(2,14,8,minecraft:crying_obsidian,20,minecraft:obsidian,100)
RB(0,14,9,minecraft:crying_obsidian,20,minecraft:obsidian,100)
RB(0,15,0,minecraft:crying_obsidian,20,minecraft:obsidian,100)
RB(1,15,0,minecraft:crying_obsidian,20,minecraft:obsidian,100)
RB(2,15,0,minecraft:crying_obsidian,20,minecraft:obsidian,100)
RB(3,15,0,minecraft:crying_obsidian,20,minecraft:obsidian,100)
RB(4,15,0,minecraft:crying_obsidian,20,minecraft:obsidian,100)
RB(5,15,0,minecraft:crying_obsidian,20,minecraft:obsidian,100)
RB(0,15,1,minecraft:crying_obsidian,20,minecraft:obsidian,100)
RB(1,15,1,minecraft:crying_obsidian,20,minecraft:obsidian,100)
RB(2,15,1,minecraft:crying_obsidian,20,minecraft:obsidian,100)
RB(3,15,1,minecraft:crying_obsidian,20,minecraft:obsidian,100)
RB(4,15,1,minecraft:crying_obsidian,20,minecraft:obsidian,100)
RB(5,15,1,minecraft:crying_obsidian,20,minecraft:obsidian,100)
RB(0,15,2,minecraft:crying_obsidian,20,minecraft:obsidian,100)
RB(1,15,2,minecraft:crying_obsidian,20,minecraft:obsidian,100)
RB(2,15,2,minecraft:crying_obsidian,20,minecraft:obsidian,100)
RB(3,15,2,minecraft:crying_obsidian,20,minecraft:obsidian,100)
RB(4,15,2,minecraft:crying_obsidian,20,minecraft:obsidian,100)
RB(5,15,2,minecraft:crying_obsidian,20,minecraft:obsidian,100)
RB(6,15,2,minecraft:crying_obsidian,20,minecraft:obsidian,100)
RB(0,15,3,minecraft:crying_obsidian,20,minecraft:obsidian,100)
RB(1,15,3,minecraft:crying_obsidian,20,minecraft:obsidian,100)
RB(2,15,3,minecraft:crying_obsidian,20,minecraft:obsidian,100)
RB(3,15,3,minecraft:crying_obsidian,20,minecraft:obsidian,100)
RB(4,15,3,minecraft:crying_obsidian,20,minecraft:obsidian,100)
RB(5,15,3,minecraft:crying_obsidian,20,minecraft:obsidian,100)
RB(0,15,4,minecraft:crying_obsidian,20,minecraft:obsidian,100)
RB(1,15,4,minecraft:crying_obsidian,20,minecraft:obsidian,100)
RB(2,15,4,minecraft:crying_obsidian,20,minecraft:obsidian,100)
RB(3,15,4,minecraft:crying_obsidian,20,minecraft:obsidian,100)
RB(4,15,4,minecraft:crying_obsidian,20,minecraft:obsidian,100)
RB(5,15,4,minecraft:crying_obsidian,20,minecraft:obsidian,100)
RB(0,15,5,minecraft:crying_obsidian,20,minecraft:obsidian,100)
RB(1,15,5,minecraft:crying_obsidian,20,minecraft:obsidian,100)
RB(2,15,5,minecraft:crying_obsidian,20,minecraft:obsidian,100)
RB(3,15,5,minecraft:crying_obsidian,20,minecraft:obsidian,100)
RB(4,15,5,minecraft:crying_obsidian,20,minecraft:obsidian,100)
RB(5,15,5,minecraft:crying_obsidian,20,minecraft:obsidian,100)
RB(0,15,6,minecraft:crying_obsidian,20,minecraft:obsidian,100)
RB(1,15,6,minecraft:crying_obsidian,20,minecraft:obsidian,100)
RB(2,15,6,minecraft:crying_obsidian,20,minecraft:obsidian,100)
RB(3,15,6,minecraft:crying_obsidian,20,minecraft:obsidian,100)
RB(0,15,7,minecraft:crying_obsidian,20,minecraft:obsidian,100)
RB(1,15,7,minecraft:crying_obsidian,20,minecraft:obsidian,100)
RB(2,15,7,minecraft:crying_obsidian,20,minecraft:obsidian,100)
RB(0,15,8,minecraft:crying_obsidian,20,minecraft:obsidian,100)
RB(1,15,8,minecraft:crying_obsidian,20,minecraft:obsidian,100)
RB(0,16,0,minecraft:crying_obsidian,20,minecraft:obsidian,100)
RB(1,16,0,minecraft:crying_obsidian,20,minecraft:obsidian,100)
RB(2,16,0,minecraft:crying_obsidian,20,minecraft:obsidian,100)
RB(3,16,0,minecraft:crying_obsidian,20,minecraft:obsidian,100)
RB(4,16,0,minecraft:crying_obsidian,20,minecraft:obsidian,100)
RB(0,16,1,minecraft:crying_obsidian,20,minecraft:obsidian,100)
RB(1,16,1,minecraft:crying_obsidian,20,minecraft:obsidian,100)
RB(2,16,1,minecraft:crying_obsidian,20,minecraft:obsidian,100)
RB(3,16,1,minecraft:crying_obsidian,20,minecraft:obsidian,100)
RB(4,16,1,minecraft:crying_obsidian,20,minecraft:obsidian,100)
RB(0,16,2,minecraft:crying_obsidian,20,minecraft:obsidian,100)
RB(1,16,2,minecraft:crying_obsidian,20,minecraft:obsidian,100)
RB(2,16,2,minecraft:crying_obsidian,20,minecraft:obsidian,100)
RB(3,16,2,minecraft:crying_obsidian,20,minecraft:obsidian,100)
RB(4,16,2,minecraft:crying_obsidian,20,minecraft:obsidian,100)
RB(0,16,3,minecraft:crying_obsidian,20,minecraft:obsidian,100)
RB(1,16,3,minecraft:crying_obsidian,20,minecraft:obsidian,100)
RB(2,16,3,minecraft:crying_obsidian,20,minecraft:obsidian,100)
RB(3,16,3,minecraft:crying_obsidian,20,minecraft:obsidian,100)
RB(4,16,3,minecraft:crying_obsidian,20,minecraft:obsidian,100)
RB(5,16,3,minecraft:crying_obsidian,20,minecraft:obsidian,100)
RB(0,16,4,minecraft:crying_obsidian,20,minecraft:obsidian,100)
RB(1,16,4,minecraft:crying_obsidian,20,minecraft:obsidian,100)
RB(2,16,4,minecraft:crying_obsidian,20,minecraft:obsidian,100)
RB(3,16,4,minecraft:crying_obsidian,20,minecraft:obsidian,100)
RB(4,16,4,minecraft:crying_obsidian,20,minecraft:obsidian,100)
RB(0,16,5,minecraft:crying_obsidian,20,minecraft:obsidian,100)
RB(1,16,5,minecraft:crying_obsidian,20,minecraft:obsidian,100)
RB(2,16,5,minecraft:crying_obsidian,20,minecraft:obsidian,100)
RB(3,16,5,minecraft:crying_obsidian,20,minecraft:obsidian,100)
RB(4,16,5,minecraft:crying_obsidian,20,minecraft:obsidian,100)
RB(0,16,6,minecraft:crying_obsidian,20,minecraft:obsidian,100)
RB(1,16,6,minecraft:crying_obsidian,20,minecraft:obsidian,100)
RB(2,16,6,minecraft:crying_obsidian,20,minecraft:obsidian,100)
RB(0,16,7,minecraft:crying_obsidian,20,minecraft:obsidian,100)
RB(1,16,7,minecraft:crying_obsidian,20,minecraft:obsidian,100)
RB(0,16,8,minecraft:crying_obsidian,20,minecraft:obsidian,100)
RB(0,17,0,minecraft:crying_obsidian,20,minecraft:obsidian,100)
RB(1,17,0,minecraft:crying_obsidian,20,minecraft:obsidian,100)
RB(2,17,0,minecraft:crying_obsidian,20,minecraft:obsidian,100)
RB(3,17,0,minecraft:crying_obsidian,20,minecraft:obsidian,100)
RB(0,17,1,minecraft:crying_obsidian,20,minecraft:obsidian,100)
RB(1,17,1,minecraft:crying_obsidian,20,minecraft:obsidian,100)
RB(2,17,1,minecraft:crying_obsidian,20,minecraft:obsidian,100)
RB(3,17,1,minecraft:crying_obsidian,20,minecraft:obsidian,100)
RB(0,17,2,minecraft:crying_obsidian,20,minecraft:obsidian,100)
RB(1,17,2,minecraft:crying_obsidian,20,minecraft:obsidian,100)
RB(2,17,2,minecraft:crying_obsidian,20,minecraft:obsidian,100)
RB(3,17,2,minecraft:crying_obsidian,20,minecraft:obsidian,100)
RB(0,17,3,minecraft:crying_obsidian,20,minecraft:obsidian,100)
RB(1,17,3,minecraft:crying_obsidian,20,minecraft:obsidian,100)
RB(2,17,3,minecraft:crying_obsidian,20,minecraft:obsidian,100)
RB(0,17,4,minecraft:crying_obsidian,20,minecraft:obsidian,100)
RB(1,17,4,minecraft:crying_obsidian,20,minecraft:obsidian,100)
RB(2,17,4,minecraft:crying_obsidian,20,minecraft:obsidian,100)
RB(0,17,5,minecraft:crying_obsidian,20,minecraft:obsidian,100)
RB(1,17,5,minecraft:crying_obsidian,20,minecraft:obsidian,100)
RB(2,17,5,minecraft:crying_obsidian,20,minecraft:obsidian,100)
RB(0,17,6,minecraft:crying_obsidian,20,minecraft:obsidian,100)
RB(1,17,6,minecraft:crying_obsidian,20,minecraft:obsidian,100)
RB(0,17,7,minecraft:crying_obsidian,20,minecraft:obsidian,100)
RB(0,18,0,minecraft:crying_obsidian,20,minecraft:obsidian,100)
RB(1,18,0,minecraft:crying_obsidian,20,minecraft:obsidian,100)
RB(2,18,0,minecraft:crying_obsidian,20,minecraft:obsidian,100)
RB(0,18,1,minecraft:crying_obsidian,20,minecraft:obsidian,100)
RB(1,18,1,minecraft:crying_obsidian,20,minecraft:obsidian,100)
RB(2,18,1,minecraft:crying_obsidian,20,minecraft:obsidian,100)
RB(0,18,2,minecraft:crying_obsidian,20,minecraft:obsidian,100)
RB(1,18,2,minecraft:crying_obsidian,20,minecraft:obsidian,100)
RB(0,18,3,minecraft:crying_obsidian,20,minecraft:obsidian,100)
RB(1,18,3,minecraft:crying_obsidian,20,minecraft:obsidian,100)
RB(0,18,4,minecraft:crying_obsidian,20,minecraft:obsidian,100)
RB(0,18,5,minecraft:crying_obsidian,20,minecraft:obsidian,100)
RB(1,18,5,minecraft:crying_obsidian,20,minecraft:obsidian,100)
RB(0,19,0,minecraft:crying_obsidian,20,minecraft:obsidian,100)
RB(0,19,1,minecraft:crying_obsidian,20,minecraft:obsidian,100)
RB(0,19,2,minecraft:crying_obsidian,20,minecraft:obsidian,100)
RB(0,19,3,minecraft:crying_obsidian,20,minecraft:obsidian,100)
RB(0,19,4,minecraft:crying_obsidian,20,minecraft:obsidian,100)

