Author: Bo3 BulkEdit

Description: Converted Schematic - Modified by Bo3BulkEdit

Version: 3

SettingsMode: WriteDisable

IsOTGPlus: true
Tree: false
Frequency: 3
Rarity: 100
RotateRandomly: false
SpawnHeight: randomY
SpawnHeightOffset: 0
SpawnHeightVariance: 0
MaxBranchDepth: 10
ExcludedBiomes: All

MinHeight: 5
MaxHeight: 20

SourceBlocks: AIR
MaxPercentageOutsideSourceBlock: 100
OutsideSourceBlock: placeAnyway

B(1,1,0,minecraft:crimson_stem[axis=y])
B(2,1,0,minecraft:crimson_stem[axis=y])
B(3,1,0,minecraft:crimson_stem[axis=y])
B(4,1,0,minecraft:crimson_stem[axis=y])
B(5,1,0,minecraft:crimson_stem[axis=y])
B(6,1,0,minecraft:crimson_stem[axis=y])
B(7,1,0,minecraft:crimson_stem[axis=y])
B(8,1,0,minecraft:crimson_stem[axis=y])
B(9,1,0,minecraft:crimson_stem[axis=y])
B(10,1,0,minecraft:blackstone)
B(11,1,0,minecraft:blackstone)
B(12,1,0,minecraft:blackstone)
B(15,1,0,minecraft:crimson_stem[axis=y])
B(2,1,1,minecraft:crimson_stem[axis=y])
B(3,1,1,minecraft:crimson_stem[axis=y])
B(4,1,1,minecraft:crimson_stem[axis=y])
B(5,1,1,minecraft:crimson_stem[axis=y])
B(6,1,1,minecraft:crimson_stem[axis=y])
B(7,1,1,minecraft:crimson_stem[axis=y])
B(8,1,1,minecraft:crimson_stem[axis=y])
B(9,1,1,minecraft:crimson_stem[axis=y])
B(10,1,1,minecraft:crimson_stem[axis=y])
B(11,1,1,minecraft:blackstone)
B(12,1,1,minecraft:blackstone)
B(13,1,1,minecraft:crimson_stem[axis=y])
B(0,1,2,minecraft:crimson_stem[axis=y])
B(1,1,2,minecraft:crimson_stem[axis=y])
B(3,1,2,minecraft:crimson_stem[axis=y])
B(4,1,2,minecraft:crimson_stem[axis=y])
B(5,1,2,minecraft:crimson_stem[axis=y])
B(6,1,2,minecraft:crimson_stem[axis=y])
B(7,1,2,minecraft:crimson_stem[axis=y])
B(8,1,2,minecraft:crimson_stem[axis=y])
B(9,1,2,minecraft:crimson_stem[axis=y])
B(10,1,2,minecraft:crimson_stem[axis=y])
B(11,1,2,minecraft:crimson_stem[axis=y])
B(13,1,2,minecraft:crimson_stem[axis=y])
B(15,1,2,minecraft:crimson_stem[axis=y])
B(1,1,3,minecraft:crimson_stem[axis=y])
B(3,1,3,minecraft:crimson_stem[axis=y])
B(4,1,3,minecraft:blackstone)
B(5,1,3,minecraft:blackstone)
B(6,1,3,minecraft:blackstone)
B(7,1,3,minecraft:crimson_stem[axis=y])
B(8,1,3,minecraft:crimson_stem[axis=y])
B(9,1,3,minecraft:crimson_stem[axis=y])
B(10,1,3,minecraft:crimson_stem[axis=y])
B(11,1,3,minecraft:crimson_stem[axis=y])
B(1,1,4,minecraft:crimson_stem[axis=y])
B(4,1,4,minecraft:blackstone)
B(5,1,4,minecraft:blackstone)
B(6,1,4,minecraft:blackstone)
B(7,1,4,minecraft:crimson_stem[axis=y])
B(8,1,4,minecraft:crimson_stem[axis=y])
B(9,1,4,minecraft:crimson_stem[axis=y])
B(10,1,4,minecraft:crimson_stem[axis=y])
B(12,1,4,minecraft:crimson_stem[axis=y])
B(3,1,5,minecraft:crimson_stem[axis=y])
B(5,1,5,minecraft:crimson_stem[axis=y])
B(6,1,5,minecraft:blackstone)
B(7,1,5,minecraft:crimson_stem[axis=y])
B(8,1,5,minecraft:crimson_stem[axis=y])
B(10,1,5,minecraft:crimson_stem[axis=y])
B(14,1,5,minecraft:crimson_stem[axis=y])
B(1,1,6,minecraft:crimson_stem[axis=y])
B(10,1,6,minecraft:crimson_stem[axis=y])
B(11,1,6,minecraft:crimson_stem[axis=y])
B(15,1,6,minecraft:crimson_stem[axis=y])
B(1,1,7,minecraft:crimson_stem[axis=y])
B(5,1,7,minecraft:crimson_stem[axis=y])
B(12,1,7,minecraft:crimson_stem[axis=y])
B(15,1,7,minecraft:crimson_stem[axis=y])
B(1,1,8,minecraft:crimson_stem[axis=y])
B(4,1,8,minecraft:crimson_stem[axis=y])
B(5,1,8,minecraft:crimson_stem[axis=y])
B(8,1,8,minecraft:crimson_stem[axis=y])
B(9,1,8,minecraft:crimson_stem[axis=y])
B(11,1,8,minecraft:crimson_stem[axis=y])
B(0,1,9,minecraft:crimson_stem[axis=y])
B(1,1,9,minecraft:crimson_stem[axis=y])
B(3,1,9,minecraft:crimson_stem[axis=y])
B(6,1,9,minecraft:crimson_stem[axis=y])
B(10,1,9,minecraft:crimson_stem[axis=y])
B(6,1,10,minecraft:crimson_stem[axis=y])
B(7,1,10,minecraft:crimson_stem[axis=y])
B(10,1,10,minecraft:crimson_stem[axis=y])
B(5,1,11,minecraft:crimson_stem[axis=y])
B(7,1,11,minecraft:crimson_stem[axis=y])
B(10,1,11,minecraft:crimson_stem[axis=y])
B(5,1,12,minecraft:crimson_stem[axis=y])
B(5,1,13,minecraft:crimson_stem[axis=y])
B(1,2,0,minecraft:blackstone)
B(2,2,0,minecraft:blackstone)
B(3,2,0,minecraft:crimson_stem[axis=y])
B(4,2,0,minecraft:crimson_stem[axis=y])
B(5,2,0,minecraft:crimson_stem[axis=y])
B(6,2,0,minecraft:crimson_stem[axis=y])
B(7,2,0,minecraft:crimson_stem[axis=y])
B(8,2,0,minecraft:crimson_stem[axis=y])
B(9,2,0,minecraft:crimson_stem[axis=y])
B(10,2,0,minecraft:blackstone)
B(11,2,0,minecraft:blackstone)
B(12,2,0,minecraft:blackstone)
B(13,2,0,minecraft:crimson_stem[axis=y])
B(14,2,0,minecraft:crimson_stem[axis=y])
B(1,2,1,minecraft:crimson_stem[axis=y])
B(2,2,1,minecraft:crimson_stem[axis=y])
B(3,2,1,minecraft:crimson_stem[axis=y])
B(4,2,1,minecraft:crimson_stem[axis=y])
B(5,2,1,minecraft:crimson_stem[axis=y])
B(6,2,1,minecraft:crimson_stem[axis=y])
B(7,2,1,minecraft:crimson_stem[axis=y])
B(8,2,1,minecraft:crimson_stem[axis=y])
B(9,2,1,minecraft:crimson_stem[axis=y])
B(10,2,1,minecraft:crimson_stem[axis=y])
B(11,2,1,minecraft:blackstone)
B(12,2,1,minecraft:crimson_stem[axis=y])
B(0,2,2,minecraft:crimson_stem[axis=y])
B(1,2,2,minecraft:crimson_stem[axis=y])
B(3,2,2,minecraft:blackstone)
B(4,2,2,minecraft:blackstone)
B(5,2,2,minecraft:blackstone)
B(6,2,2,minecraft:blackstone)
B(7,2,2,minecraft:blackstone)
B(8,2,2,minecraft:crimson_stem[axis=y])
B(9,2,2,minecraft:crimson_stem[axis=y])
B(10,2,2,minecraft:crimson_stem[axis=y])
B(11,2,2,minecraft:crimson_stem[axis=y])
B(3,2,3,minecraft:blackstone)
B(4,2,3,minecraft:blackstone)
B(5,2,3,minecraft:blackstone)
B(6,2,3,minecraft:blackstone)
B(7,2,3,minecraft:blackstone)
B(8,2,3,minecraft:crimson_stem[axis=y])
B(9,2,3,minecraft:crimson_stem[axis=y])
B(10,2,3,minecraft:crimson_stem[axis=y])
B(4,2,4,minecraft:crimson_stem[axis=y])
B(5,2,4,minecraft:blackstone)
B(6,2,4,minecraft:blackstone)
B(7,2,4,minecraft:blackstone)
B(8,2,4,minecraft:crimson_stem[axis=y])
B(9,2,4,minecraft:crimson_stem[axis=y])
B(10,2,4,minecraft:crimson_stem[axis=y])
B(11,2,4,minecraft:crimson_stem[axis=y])
B(12,2,4,minecraft:crimson_stem[axis=y])
B(4,2,5,minecraft:crimson_stem[axis=y])
B(5,2,5,minecraft:crimson_stem[axis=y])
B(6,2,5,minecraft:blackstone)
B(7,2,5,minecraft:blackstone)
B(8,2,5,minecraft:crimson_stem[axis=y])
B(10,2,5,minecraft:crimson_stem[axis=y])
B(11,2,5,minecraft:crimson_stem[axis=y])
B(12,2,5,minecraft:crimson_stem[axis=y])
B(7,2,6,minecraft:crimson_stem[axis=y])
B(7,2,7,minecraft:crimson_stem[axis=y])
B(7,2,8,minecraft:crimson_stem[axis=y])
B(7,2,9,minecraft:crimson_stem[axis=y])
B(7,2,10,minecraft:crimson_stem[axis=y])
B(1,3,0,minecraft:crimson_stem[axis=y])
B(2,3,0,minecraft:blackstone)
B(3,3,0,minecraft:crimson_stem[axis=y])
B(4,3,0,minecraft:crimson_stem[axis=y])
B(5,3,0,minecraft:crimson_stem[axis=y])
B(6,3,0,minecraft:crimson_stem[axis=y])
B(7,3,0,minecraft:crimson_stem[axis=y])
B(8,3,0,minecraft:crimson_stem[axis=y])
B(9,3,0,minecraft:crimson_stem[axis=y])
B(10,3,0,minecraft:blackstone)
B(11,3,0,minecraft:blackstone)
B(12,3,0,minecraft:crimson_stem[axis=y])
B(2,3,1,minecraft:crimson_stem[axis=y])
B(3,3,1,minecraft:crimson_stem[axis=y])
B(4,3,1,minecraft:blackstone)
B(5,3,1,minecraft:blackstone)
B(6,3,1,minecraft:blackstone)
B(7,3,1,minecraft:crimson_stem[axis=y])
B(8,3,1,minecraft:crimson_stem[axis=y])
B(9,3,1,minecraft:crimson_stem[axis=y])
B(10,3,1,minecraft:crimson_stem[axis=y])
B(11,3,1,minecraft:blackstone)
B(1,3,2,minecraft:crimson_stem[axis=y])
B(2,3,2,minecraft:crimson_stem[axis=y])
B(3,3,2,minecraft:blackstone)
B(4,3,2,minecraft:blackstone)
B(5,3,2,minecraft:blackstone)
B(6,3,2,minecraft:blackstone)
B(7,3,2,minecraft:blackstone)
B(8,3,2,minecraft:crimson_stem[axis=y])
B(9,3,2,minecraft:crimson_stem[axis=y])
B(10,3,2,minecraft:crimson_stem[axis=y])
B(11,3,2,minecraft:crimson_stem[axis=y])
B(1,3,3,minecraft:crimson_stem[axis=y])
B(2,3,3,minecraft:crimson_stem[axis=y])
B(4,3,3,minecraft:blackstone)
B(5,3,3,minecraft:blackstone)
B(6,3,3,minecraft:blackstone)
B(7,3,3,minecraft:blackstone)
B(8,3,3,minecraft:blackstone)
B(9,3,3,minecraft:crimson_stem[axis=y])
B(10,3,3,minecraft:crimson_stem[axis=y])
B(0,3,4,minecraft:crimson_stem[axis=y])
B(1,3,4,minecraft:crimson_stem[axis=y])
B(4,3,4,minecraft:crimson_stem[axis=y])
B(5,3,4,minecraft:blackstone)
B(6,3,4,minecraft:blackstone)
B(7,3,4,minecraft:blackstone)
B(8,3,4,minecraft:blackstone)
B(9,3,4,minecraft:crimson_stem[axis=y])
B(10,3,4,minecraft:crimson_stem[axis=y])
B(11,3,4,minecraft:crimson_stem[axis=y])
B(0,3,5,minecraft:crimson_stem[axis=y])
B(5,3,5,minecraft:crimson_stem[axis=y])
B(6,3,5,minecraft:blackstone)
B(7,3,5,minecraft:blackstone)
B(8,3,5,minecraft:blackstone)
B(0,3,6,minecraft:crimson_stem[axis=y])
B(5,3,6,minecraft:crimson_stem[axis=y])
B(7,3,6,minecraft:crimson_stem[axis=y])
B(7,3,7,minecraft:crimson_stem[axis=y])
B(6,3,8,minecraft:crimson_stem[axis=y])
B(7,3,8,minecraft:crimson_stem[axis=y])
B(2,4,0,minecraft:blackstone)
B(3,4,0,minecraft:crimson_stem[axis=y])
B(4,4,0,minecraft:crimson_stem[axis=y])
B(5,4,0,minecraft:crimson_stem[axis=y])
B(6,4,0,minecraft:crimson_stem[axis=y])
B(7,4,0,minecraft:crimson_stem[axis=y])
B(8,4,0,minecraft:crimson_stem[axis=y])
B(9,4,0,minecraft:crimson_stem[axis=y])
B(10,4,0,minecraft:blackstone)
B(11,4,0,minecraft:blackstone)
B(12,4,0,minecraft:crimson_stem[axis=y])
B(2,4,1,minecraft:crimson_stem[axis=y])
B(3,4,1,minecraft:crimson_stem[axis=y])
B(4,4,1,minecraft:blackstone)
B(5,4,1,minecraft:blackstone)
B(6,4,1,minecraft:blackstone)
B(7,4,1,minecraft:crimson_stem[axis=y])
B(8,4,1,minecraft:crimson_stem[axis=y])
B(9,4,1,minecraft:crimson_stem[axis=y])
B(10,4,1,minecraft:crimson_stem[axis=y])
B(11,4,1,minecraft:blackstone)
B(2,4,2,minecraft:crimson_stem[axis=y])
B(3,4,2,minecraft:blackstone)
B(4,4,2,minecraft:blackstone)
B(5,4,2,minecraft:blackstone)
B(6,4,2,minecraft:blackstone)
B(7,4,2,minecraft:blackstone)
B(8,4,2,minecraft:blackstone)
B(9,4,2,minecraft:crimson_stem[axis=y])
B(10,4,2,minecraft:crimson_stem[axis=y])
B(11,4,2,minecraft:crimson_stem[axis=y])
B(2,4,3,minecraft:crimson_stem[axis=y])
B(4,4,3,minecraft:blackstone)
B(5,4,3,minecraft:crimson_stem[axis=y])
B(6,4,3,minecraft:blackstone)
B(7,4,3,minecraft:blackstone)
B(8,4,3,minecraft:blackstone)
B(9,4,3,minecraft:crimson_stem[axis=y])
B(10,4,3,minecraft:crimson_stem[axis=y])
B(4,4,4,minecraft:crimson_stem[axis=y])
B(5,4,4,minecraft:blackstone)
B(6,4,4,minecraft:blackstone)
B(7,4,4,minecraft:blackstone)
B(8,4,4,minecraft:blackstone)
B(9,4,4,minecraft:crimson_stem[axis=y])
B(10,4,4,minecraft:crimson_stem[axis=y])
B(6,4,5,minecraft:blackstone)
B(7,4,5,minecraft:blackstone)
B(8,4,5,minecraft:blackstone)
B(7,4,6,minecraft:crimson_stem[axis=y])
B(2,5,0,minecraft:blackstone)
B(3,5,0,minecraft:blackstone)
B(4,5,0,minecraft:crimson_stem[axis=y])
B(5,5,0,minecraft:crimson_stem[axis=y])
B(6,5,0,minecraft:crimson_stem[axis=y])
B(7,5,0,minecraft:crimson_stem[axis=y])
B(8,5,0,minecraft:crimson_stem[axis=y])
B(9,5,0,minecraft:crimson_stem[axis=y])
B(10,5,0,minecraft:blackstone)
B(11,5,0,minecraft:blackstone)
B(12,5,0,minecraft:crimson_stem[axis=y])
B(2,5,1,minecraft:crimson_stem[axis=y])
B(3,5,1,minecraft:crimson_stem[axis=y])
B(4,5,1,minecraft:blackstone)
B(5,5,1,minecraft:blackstone)
B(6,5,1,minecraft:blackstone)
B(7,5,1,minecraft:blackstone)
B(8,5,1,minecraft:crimson_stem[axis=y])
B(9,5,1,minecraft:crimson_stem[axis=y])
B(10,5,1,minecraft:crimson_stem[axis=y])
B(11,5,1,minecraft:crimson_stem[axis=y])
B(2,5,2,minecraft:crimson_stem[axis=y])
B(3,5,2,minecraft:blackstone)
B(4,5,2,minecraft:blackstone)
B(5,5,2,minecraft:blackstone)
B(6,5,2,minecraft:blackstone)
B(7,5,2,minecraft:blackstone)
B(8,5,2,minecraft:blackstone)
B(9,5,2,minecraft:crimson_stem[axis=y])
B(10,5,2,minecraft:crimson_stem[axis=y])
B(11,5,2,minecraft:crimson_stem[axis=y])
B(4,5,3,minecraft:blackstone)
B(5,5,3,minecraft:crimson_stem[axis=y])
B(6,5,3,minecraft:blackstone)
B(7,5,3,minecraft:blackstone)
B(8,5,3,minecraft:blackstone)
B(9,5,3,minecraft:blackstone)
B(4,5,4,minecraft:crimson_stem[axis=y])
B(6,5,4,minecraft:blackstone)
B(7,5,4,minecraft:blackstone)
B(8,5,4,minecraft:blackstone)
B(9,5,4,minecraft:blackstone)
B(6,5,5,minecraft:blackstone)
B(7,5,5,minecraft:blackstone)
B(8,5,5,minecraft:blackstone)
B(7,5,6,minecraft:crimson_stem[axis=y])
B(2,6,0,minecraft:blackstone)
B(3,6,0,minecraft:blackstone)
B(4,6,0,minecraft:crimson_stem[axis=y])
B(5,6,0,minecraft:crimson_stem[axis=y])
B(6,6,0,minecraft:crimson_stem[axis=y])
B(7,6,0,minecraft:crimson_stem[axis=y])
B(8,6,0,minecraft:crimson_stem[axis=y])
B(9,6,0,minecraft:crimson_stem[axis=y])
B(10,6,0,minecraft:blackstone)
B(11,6,0,minecraft:blackstone)
B(2,6,1,minecraft:crimson_stem[axis=y])
B(3,6,1,minecraft:crimson_stem[axis=y])
B(4,6,1,minecraft:crimson_stem[axis=y])
B(5,6,1,minecraft:blackstone)
B(6,6,1,minecraft:blackstone)
B(7,6,1,minecraft:blackstone)
B(8,6,1,minecraft:crimson_stem[axis=y])
B(9,6,1,minecraft:crimson_stem[axis=y])
B(10,6,1,minecraft:crimson_stem[axis=y])
B(11,6,1,minecraft:crimson_stem[axis=y])
B(4,6,2,minecraft:blackstone)
B(5,6,2,minecraft:blackstone)
B(6,6,2,minecraft:blackstone)
B(7,6,2,minecraft:blackstone)
B(8,6,2,minecraft:blackstone)
B(9,6,2,minecraft:crimson_stem[axis=y])
B(10,6,2,minecraft:crimson_stem[axis=y])
B(4,6,3,minecraft:blackstone)
B(5,6,3,minecraft:crimson_stem[axis=y])
B(6,6,3,minecraft:blackstone)
B(7,6,3,minecraft:blackstone)
B(8,6,3,minecraft:blackstone)
B(9,6,3,minecraft:blackstone)
B(6,6,4,minecraft:blackstone)
B(7,6,4,minecraft:blackstone)
B(8,6,4,minecraft:blackstone)
B(9,6,4,minecraft:blackstone)
B(6,6,5,minecraft:blackstone)
B(7,6,5,minecraft:blackstone)
B(8,6,5,minecraft:blackstone)
B(7,6,6,minecraft:crimson_stem[axis=y])
B(2,7,0,minecraft:blackstone)
B(3,7,0,minecraft:blackstone)
B(4,7,0,minecraft:crimson_stem[axis=y])
B(5,7,0,minecraft:crimson_stem[axis=y])
B(6,7,0,minecraft:crimson_stem[axis=y])
B(7,7,0,minecraft:crimson_stem[axis=y])
B(8,7,0,minecraft:crimson_stem[axis=y])
B(9,7,0,minecraft:crimson_stem[axis=y])
B(10,7,0,minecraft:blackstone)
B(11,7,0,minecraft:blackstone)
B(2,7,1,minecraft:crimson_stem[axis=y])
B(3,7,1,minecraft:crimson_stem[axis=y])
B(4,7,1,minecraft:crimson_stem[axis=y])
B(5,7,1,minecraft:blackstone)
B(6,7,1,minecraft:blackstone)
B(7,7,1,minecraft:blackstone)
B(8,7,1,minecraft:crimson_stem[axis=y])
B(9,7,1,minecraft:crimson_stem[axis=y])
B(10,7,1,minecraft:blackstone)
B(11,7,1,minecraft:crimson_stem[axis=y])
B(4,7,2,minecraft:blackstone)
B(5,7,2,minecraft:blackstone)
B(6,7,2,minecraft:blackstone)
B(7,7,2,minecraft:blackstone)
B(8,7,2,minecraft:blackstone)
B(9,7,2,minecraft:crimson_stem[axis=y])
B(10,7,2,minecraft:crimson_stem[axis=y])
B(4,7,3,minecraft:blackstone)
B(5,7,3,minecraft:crimson_stem[axis=y])
B(6,7,3,minecraft:blackstone)
B(7,7,3,minecraft:blackstone)
B(8,7,3,minecraft:blackstone)
B(9,7,3,minecraft:blackstone)
B(6,7,4,minecraft:blackstone)
B(7,7,4,minecraft:blackstone)
B(8,7,4,minecraft:blackstone)
B(9,7,4,minecraft:blackstone)
B(7,7,5,minecraft:crimson_stem[axis=y])
B(2,8,0,minecraft:blackstone)
B(3,8,0,minecraft:blackstone)
B(4,8,0,minecraft:crimson_stem[axis=y])
B(5,8,0,minecraft:crimson_stem[axis=y])
B(6,8,0,minecraft:crimson_stem[axis=y])
B(7,8,0,minecraft:crimson_stem[axis=y])
B(8,8,0,minecraft:crimson_stem[axis=y])
B(9,8,0,minecraft:blackstone)
B(10,8,0,minecraft:blackstone)
B(11,8,0,minecraft:blackstone)
B(3,8,1,minecraft:crimson_stem[axis=y])
B(4,8,1,minecraft:crimson_stem[axis=y])
B(5,8,1,minecraft:crimson_stem[axis=y])
B(6,8,1,minecraft:crimson_stem[axis=y])
B(7,8,1,minecraft:crimson_stem[axis=y])
B(8,8,1,minecraft:crimson_stem[axis=y])
B(9,8,1,minecraft:crimson_stem[axis=y])
B(10,8,1,minecraft:blackstone)
B(4,8,2,minecraft:blackstone)
B(5,8,2,minecraft:blackstone)
B(6,8,2,minecraft:blackstone)
B(7,8,2,minecraft:blackstone)
B(8,8,2,minecraft:blackstone)
B(9,8,2,minecraft:crimson_stem[axis=y])
B(10,8,2,minecraft:crimson_stem[axis=y])
B(4,8,3,minecraft:blackstone)
B(5,8,3,minecraft:crimson_stem[axis=y])
B(6,8,3,minecraft:blackstone)
B(7,8,3,minecraft:blackstone)
B(8,8,3,minecraft:blackstone)
B(9,8,3,minecraft:crimson_stem[axis=y])
B(6,8,4,minecraft:blackstone)
B(7,8,4,minecraft:blackstone)
B(8,8,4,minecraft:blackstone)
B(9,8,4,minecraft:crimson_stem[axis=y])
B(7,8,5,minecraft:crimson_stem[axis=y])
B(2,9,0,minecraft:blackstone)
B(3,9,0,minecraft:blackstone)
B(4,9,0,minecraft:crimson_stem[axis=y])
B(5,9,0,minecraft:crimson_stem[axis=y])
B(6,9,0,minecraft:crimson_stem[axis=y])
B(7,9,0,minecraft:crimson_stem[axis=y])
B(8,9,0,minecraft:crimson_stem[axis=y])
B(9,9,0,minecraft:blackstone)
B(10,9,0,minecraft:blackstone)
B(11,9,0,minecraft:blackstone)
B(3,9,1,minecraft:crimson_stem[axis=y])
B(4,9,1,minecraft:crimson_stem[axis=y])
B(5,9,1,minecraft:blackstone)
B(6,9,1,minecraft:blackstone)
B(7,9,1,minecraft:blackstone)
B(8,9,1,minecraft:crimson_stem[axis=y])
B(9,9,1,minecraft:crimson_stem[axis=y])
B(10,9,1,minecraft:blackstone)
B(4,9,2,minecraft:blackstone)
B(5,9,2,minecraft:blackstone)
B(6,9,2,minecraft:blackstone)
B(7,9,2,minecraft:blackstone)
B(8,9,2,minecraft:blackstone)
B(9,9,2,minecraft:crimson_stem[axis=y])
B(10,9,2,minecraft:crimson_stem[axis=y])
B(5,9,3,minecraft:crimson_stem[axis=y])
B(6,9,3,minecraft:blackstone)
B(7,9,3,minecraft:blackstone)
B(8,9,3,minecraft:blackstone)
B(9,9,3,minecraft:blackstone)
B(6,9,4,minecraft:blackstone)
B(7,9,4,minecraft:blackstone)
B(8,9,4,minecraft:blackstone)
B(7,9,5,minecraft:crimson_stem[axis=y])
B(2,10,0,minecraft:blackstone)
B(3,10,0,minecraft:blackstone)
B(4,10,0,minecraft:crimson_stem[axis=y])
B(5,10,0,minecraft:crimson_stem[axis=y])
B(6,10,0,minecraft:crimson_stem[axis=y])
B(7,10,0,minecraft:crimson_stem[axis=y])
B(8,10,0,minecraft:blackstone)
B(9,10,0,minecraft:blackstone)
B(10,10,0,minecraft:blackstone)
B(3,10,1,minecraft:crimson_stem[axis=y])
B(4,10,1,minecraft:crimson_stem[axis=y])
B(5,10,1,minecraft:blackstone)
B(6,10,1,minecraft:blackstone)
B(7,10,1,minecraft:blackstone)
B(8,10,1,minecraft:crimson_stem[axis=y])
B(9,10,1,minecraft:crimson_stem[axis=y])
B(10,10,1,minecraft:blackstone)
B(4,10,2,minecraft:blackstone)
B(5,10,2,minecraft:blackstone)
B(6,10,2,minecraft:blackstone)
B(7,10,2,minecraft:blackstone)
B(8,10,2,minecraft:blackstone)
B(9,10,2,minecraft:blackstone)
B(10,10,2,minecraft:crimson_stem[axis=y])
B(5,10,3,minecraft:crimson_stem[axis=y])
B(6,10,3,minecraft:blackstone)
B(7,10,3,minecraft:blackstone)
B(8,10,3,minecraft:blackstone)
B(9,10,3,minecraft:blackstone)
B(6,10,4,minecraft:crimson_stem[axis=y])
B(7,10,4,minecraft:crimson_stem[axis=y])
B(8,10,4,minecraft:blackstone)
B(7,10,5,minecraft:crimson_stem[axis=y])
B(2,11,0,minecraft:crimson_stem[axis=y])
B(3,11,0,minecraft:crimson_stem[axis=y])
B(4,11,0,minecraft:crimson_stem[axis=y])
B(5,11,0,minecraft:crimson_stem[axis=y])
B(6,11,0,minecraft:crimson_stem[axis=y])
B(7,11,0,minecraft:crimson_stem[axis=y])
B(8,11,0,minecraft:blackstone)
B(9,11,0,minecraft:blackstone)
B(10,11,0,minecraft:blackstone)
B(3,11,1,minecraft:crimson_stem[axis=y])
B(4,11,1,minecraft:crimson_stem[axis=y])
B(5,11,1,minecraft:blackstone)
B(6,11,1,minecraft:blackstone)
B(7,11,1,minecraft:blackstone)
B(8,11,1,minecraft:blackstone)
B(9,11,1,minecraft:blackstone)
B(10,11,1,minecraft:blackstone)
B(4,11,2,minecraft:blackstone)
B(5,11,2,minecraft:blackstone)
B(6,11,2,minecraft:blackstone)
B(7,11,2,minecraft:blackstone)
B(8,11,2,minecraft:blackstone)
B(9,11,2,minecraft:blackstone)
B(10,11,2,minecraft:crimson_stem[axis=y])
B(5,11,3,minecraft:crimson_stem[axis=y])
B(6,11,3,minecraft:blackstone)
B(7,11,3,minecraft:blackstone)
B(8,11,3,minecraft:blackstone)
B(9,11,3,minecraft:blackstone)
B(6,11,4,minecraft:crimson_stem[axis=y])
B(7,11,4,minecraft:crimson_stem[axis=y])
B(2,12,0,minecraft:crimson_stem[axis=y])
B(3,12,0,minecraft:crimson_stem[axis=y])
B(4,12,0,minecraft:crimson_stem[axis=y])
B(5,12,0,minecraft:crimson_stem[axis=y])
B(6,12,0,minecraft:crimson_stem[axis=y])
B(7,12,0,minecraft:crimson_stem[axis=y])
B(8,12,0,minecraft:blackstone)
B(9,12,0,minecraft:blackstone)
B(10,12,0,minecraft:blackstone)
B(3,12,1,minecraft:crimson_stem[axis=y])
B(4,12,1,minecraft:crimson_stem[axis=y])
B(5,12,1,minecraft:crimson_stem[axis=y])
B(6,12,1,minecraft:blackstone)
B(7,12,1,minecraft:blackstone)
B(8,12,1,minecraft:blackstone)
B(9,12,1,minecraft:blackstone)
B(10,12,1,minecraft:blackstone)
B(4,12,2,minecraft:blackstone)
B(5,12,2,minecraft:blackstone)
B(6,12,2,minecraft:blackstone)
B(7,12,2,minecraft:blackstone)
B(8,12,2,minecraft:blackstone)
B(9,12,2,minecraft:blackstone)
B(10,12,2,minecraft:crimson_stem[axis=y])
B(5,12,3,minecraft:crimson_stem[axis=y])
B(6,12,3,minecraft:blackstone)
B(7,12,3,minecraft:blackstone)
B(8,12,3,minecraft:blackstone)
B(9,12,3,minecraft:blackstone)
B(6,12,4,minecraft:blackstone)
B(7,12,4,minecraft:crimson_stem[axis=y])
B(2,13,0,minecraft:crimson_stem[axis=y])
B(3,13,0,minecraft:crimson_stem[axis=y])
B(4,13,0,minecraft:crimson_stem[axis=y])
B(5,13,0,minecraft:crimson_stem[axis=y])
B(6,13,0,minecraft:crimson_stem[axis=y])
B(7,13,0,minecraft:crimson_stem[axis=y])
B(8,13,0,minecraft:blackstone)
B(9,13,0,minecraft:blackstone)
B(10,13,0,minecraft:blackstone)
B(3,13,1,minecraft:crimson_stem[axis=y])
B(4,13,1,minecraft:crimson_stem[axis=y])
B(5,13,1,minecraft:crimson_stem[axis=y])
B(6,13,1,minecraft:blackstone)
B(7,13,1,minecraft:blackstone)
B(8,13,1,minecraft:blackstone)
B(9,13,1,minecraft:blackstone)
B(10,13,1,minecraft:blackstone)
B(4,13,2,minecraft:crimson_stem[axis=y])
B(5,13,2,minecraft:blackstone)
B(6,13,2,minecraft:blackstone)
B(7,13,2,minecraft:blackstone)
B(8,13,2,minecraft:blackstone)
B(9,13,2,minecraft:blackstone)
B(10,13,2,minecraft:crimson_stem[axis=y])
B(5,13,3,minecraft:blackstone)
B(6,13,3,minecraft:blackstone)
B(7,13,3,minecraft:blackstone)
B(8,13,3,minecraft:blackstone)
B(9,13,3,minecraft:blackstone)
B(6,13,4,minecraft:blackstone)
B(7,13,4,minecraft:crimson_stem[axis=y])
B(3,14,0,minecraft:crimson_stem[axis=y])
B(4,14,0,minecraft:crimson_stem[axis=y])
B(5,14,0,minecraft:crimson_stem[axis=y])
B(6,14,0,minecraft:crimson_stem[axis=y])
B(7,14,0,minecraft:crimson_stem[axis=y])
B(8,14,0,minecraft:blackstone)
B(9,14,0,minecraft:blackstone)
B(10,14,0,minecraft:blackstone)
B(3,14,1,minecraft:crimson_stem[axis=y])
B(4,14,1,minecraft:crimson_stem[axis=y])
B(5,14,1,minecraft:crimson_stem[axis=y])
B(6,14,1,minecraft:blackstone)
B(7,14,1,minecraft:blackstone)
B(8,14,1,minecraft:blackstone)
B(9,14,1,minecraft:blackstone)
B(10,14,1,minecraft:blackstone)
B(4,14,2,minecraft:crimson_stem[axis=y])
B(5,14,2,minecraft:blackstone)
B(6,14,2,minecraft:blackstone)
B(7,14,2,minecraft:blackstone)
B(8,14,2,minecraft:blackstone)
B(9,14,2,minecraft:blackstone)
B(5,14,3,minecraft:blackstone)
B(7,14,3,minecraft:blackstone)
B(8,14,3,minecraft:blackstone)
B(6,14,4,minecraft:blackstone)
B(7,14,4,minecraft:crimson_stem[axis=y])
B(3,15,0,minecraft:crimson_stem[axis=y])
B(4,15,0,minecraft:crimson_stem[axis=y])
B(5,15,0,minecraft:crimson_stem[axis=y])
B(6,15,0,minecraft:crimson_stem[axis=y])
B(7,15,0,minecraft:crimson_stem[axis=y])
B(8,15,0,minecraft:blackstone)
B(9,15,0,minecraft:blackstone)
B(10,15,0,minecraft:blackstone)
B(3,15,1,minecraft:crimson_stem[axis=y])
B(4,15,1,minecraft:crimson_stem[axis=y])
B(5,15,1,minecraft:crimson_stem[axis=y])
B(6,15,1,minecraft:blackstone)
B(7,15,1,minecraft:blackstone)
B(8,15,1,minecraft:blackstone)
B(9,15,1,minecraft:blackstone)
B(10,15,1,minecraft:blackstone)
B(4,15,2,minecraft:crimson_stem[axis=y])
B(5,15,2,minecraft:blackstone)
B(7,15,2,minecraft:blackstone)
B(8,15,2,minecraft:blackstone)
B(9,15,2,minecraft:blackstone)
B(5,15,3,minecraft:blackstone)
B(6,15,3,minecraft:blackstone)
B(7,15,3,minecraft:blackstone)
B(8,15,3,minecraft:crimson_stem[axis=y])
B(6,15,4,minecraft:blackstone)
B(7,15,4,minecraft:crimson_stem[axis=y])
B(3,16,0,minecraft:crimson_stem[axis=y])
B(4,16,0,minecraft:crimson_stem[axis=y])
B(5,16,0,minecraft:crimson_stem[axis=y])
B(6,16,0,minecraft:crimson_stem[axis=y])
B(7,16,0,minecraft:crimson_stem[axis=y])
B(8,16,0,minecraft:blackstone)
B(9,16,0,minecraft:blackstone)
B(10,16,0,minecraft:blackstone)
B(4,16,1,minecraft:crimson_stem[axis=y])
B(5,16,1,minecraft:crimson_stem[axis=y])
B(6,16,1,minecraft:blackstone)
B(7,16,1,minecraft:blackstone)
B(8,16,1,minecraft:blackstone)
B(9,16,1,minecraft:blackstone)
B(10,16,1,minecraft:blackstone)
B(4,16,2,minecraft:crimson_stem[axis=y])
B(5,16,2,minecraft:blackstone)
B(6,16,2,minecraft:blackstone)
B(7,16,2,minecraft:blackstone)
B(8,16,2,minecraft:blackstone)
B(9,16,2,minecraft:blackstone)
B(5,16,3,minecraft:blackstone)
B(6,16,3,minecraft:blackstone)
B(7,16,3,minecraft:blackstone)
B(8,16,3,minecraft:crimson_stem[axis=y])
B(6,16,4,minecraft:blackstone)
B(3,17,0,minecraft:crimson_stem[axis=y])
B(4,17,0,minecraft:crimson_stem[axis=y])
B(5,17,0,minecraft:crimson_stem[axis=y])
B(6,17,0,minecraft:crimson_stem[axis=y])
B(7,17,0,minecraft:crimson_stem[axis=y])
B(8,17,0,minecraft:blackstone)
B(9,17,0,minecraft:blackstone)
B(10,17,0,minecraft:blackstone)
B(4,17,1,minecraft:crimson_stem[axis=y])
B(5,17,1,minecraft:blackstone)
B(6,17,1,minecraft:blackstone)
B(7,17,1,minecraft:blackstone)
B(8,17,1,minecraft:blackstone)
B(9,17,1,minecraft:blackstone)
B(10,17,1,minecraft:blackstone)
B(4,17,2,minecraft:crimson_stem[axis=y])
B(5,17,2,minecraft:blackstone)
B(6,17,2,minecraft:blackstone)
B(7,17,2,minecraft:blackstone)
B(8,17,2,minecraft:blackstone)
B(9,17,2,minecraft:blackstone)
B(5,17,3,minecraft:blackstone)
B(6,17,3,minecraft:blackstone)
B(7,17,3,minecraft:blackstone)
B(8,17,3,minecraft:crimson_stem[axis=y])
B(6,17,4,minecraft:blackstone)
B(3,18,0,minecraft:crimson_stem[axis=y])
B(4,18,0,minecraft:crimson_stem[axis=y])
B(5,18,0,minecraft:crimson_stem[axis=y])
B(6,18,0,minecraft:blackstone)
B(7,18,0,minecraft:blackstone)
B(8,18,0,minecraft:blackstone)
B(9,18,0,minecraft:blackstone)
B(10,18,0,minecraft:blackstone)
B(4,18,1,minecraft:crimson_stem[axis=y])
B(5,18,1,minecraft:blackstone)
B(6,18,1,minecraft:blackstone)
B(7,18,1,minecraft:blackstone)
B(8,18,1,minecraft:blackstone)
B(9,18,1,minecraft:blackstone)
B(10,18,1,minecraft:blackstone)
B(4,18,2,minecraft:blackstone)
B(5,18,2,minecraft:blackstone)
B(6,18,2,minecraft:blackstone)
B(7,18,2,minecraft:blackstone)
B(8,18,2,minecraft:blackstone)
B(9,18,2,minecraft:blackstone)
B(6,18,3,minecraft:blackstone)
B(7,18,3,minecraft:blackstone)
B(8,18,3,minecraft:crimson_stem[axis=y])
B(3,19,0,minecraft:crimson_stem[axis=y])
B(4,19,0,minecraft:crimson_stem[axis=y])
B(5,19,0,minecraft:crimson_stem[axis=y])
B(6,19,0,minecraft:blackstone)
B(7,19,0,minecraft:blackstone)
B(8,19,0,minecraft:blackstone)
B(9,19,0,minecraft:blackstone)
B(10,19,0,minecraft:blackstone)
B(4,19,1,minecraft:crimson_stem[axis=y])
B(5,19,1,minecraft:blackstone)
B(6,19,1,minecraft:blackstone)
B(7,19,1,minecraft:blackstone)
B(8,19,1,minecraft:blackstone)
B(9,19,1,minecraft:blackstone)
B(10,19,1,minecraft:blackstone)
B(4,19,2,minecraft:blackstone)
B(5,19,2,minecraft:blackstone)
B(6,19,2,minecraft:blackstone)
B(7,19,2,minecraft:blackstone)
B(8,19,2,minecraft:blackstone)
B(9,19,2,minecraft:blackstone)
B(6,19,3,minecraft:blackstone)
B(7,19,3,minecraft:blackstone)
B(8,19,3,minecraft:crimson_stem[axis=y])
B(3,20,0,minecraft:crimson_stem[axis=y])
B(4,20,0,minecraft:crimson_stem[axis=y])
B(5,20,0,minecraft:crimson_stem[axis=y])
B(6,20,0,minecraft:blackstone)
B(7,20,0,minecraft:blackstone)
B(8,20,0,minecraft:blackstone)
B(9,20,0,minecraft:blackstone)
B(10,20,0,minecraft:blackstone)
B(4,20,1,minecraft:crimson_stem[axis=y])
B(5,20,1,minecraft:blackstone)
B(6,20,1,minecraft:blackstone)
B(7,20,1,minecraft:blackstone)
B(8,20,1,minecraft:blackstone)
B(9,20,1,minecraft:blackstone)
B(10,20,1,minecraft:blackstone)
B(4,20,2,minecraft:blackstone)
B(5,20,2,minecraft:blackstone)
B(7,20,2,minecraft:blackstone)
B(8,20,2,minecraft:blackstone)
B(9,20,2,minecraft:blackstone)
B(6,20,3,minecraft:blackstone)
B(7,20,3,minecraft:blackstone)
B(8,20,3,minecraft:crimson_stem[axis=y])
B(3,21,0,minecraft:crimson_stem[axis=y])
B(4,21,0,minecraft:crimson_stem[axis=y])
B(5,21,0,minecraft:crimson_stem[axis=y])
B(6,21,0,minecraft:crimson_stem[axis=y])
B(7,21,0,minecraft:blackstone)
B(8,21,0,minecraft:blackstone)
B(9,21,0,minecraft:blackstone)
B(10,21,0,minecraft:blackstone)
B(4,21,1,minecraft:crimson_stem[axis=y])
B(5,21,1,minecraft:blackstone)
B(6,21,1,minecraft:blackstone)
B(7,21,1,minecraft:blackstone)
B(8,21,1,minecraft:blackstone)
B(9,21,1,minecraft:blackstone)
B(10,21,1,minecraft:blackstone)
B(4,21,2,minecraft:crimson_stem[axis=y])
B(5,21,2,minecraft:blackstone)
B(6,21,2,minecraft:blackstone)
B(7,21,2,minecraft:blackstone)
B(8,21,2,minecraft:blackstone)
B(9,21,2,minecraft:blackstone)
B(6,21,3,minecraft:blackstone)
B(7,21,3,minecraft:blackstone)
B(8,21,3,minecraft:crimson_stem[axis=y])
B(3,22,0,minecraft:crimson_stem[axis=y])
B(4,22,0,minecraft:crimson_stem[axis=y])
B(5,22,0,minecraft:crimson_stem[axis=y])
B(6,22,0,minecraft:crimson_stem[axis=y])
B(7,22,0,minecraft:blackstone)
B(8,22,0,minecraft:blackstone)
B(9,22,0,minecraft:blackstone)
B(10,22,0,minecraft:blackstone)
B(4,22,1,minecraft:crimson_stem[axis=y])
B(5,22,1,minecraft:crimson_stem[axis=y])
B(6,22,1,minecraft:blackstone)
B(7,22,1,minecraft:blackstone)
B(8,22,1,minecraft:blackstone)
B(9,22,1,minecraft:blackstone)
B(10,22,1,minecraft:blackstone)
B(4,22,2,minecraft:crimson_stem[axis=y])
B(5,22,2,minecraft:blackstone)
B(6,22,2,minecraft:blackstone)
B(7,22,2,minecraft:blackstone)
B(8,22,2,minecraft:blackstone)
B(9,22,2,minecraft:blackstone)
B(7,22,3,minecraft:blackstone)
B(8,22,3,minecraft:crimson_stem[axis=y])
B(3,23,0,minecraft:crimson_stem[axis=y])
B(4,23,0,minecraft:crimson_stem[axis=y])
B(5,23,0,minecraft:crimson_stem[axis=y])
B(6,23,0,minecraft:crimson_stem[axis=y])
B(7,23,0,minecraft:blackstone)
B(8,23,0,minecraft:blackstone)
B(9,23,0,minecraft:blackstone)
B(10,23,0,minecraft:blackstone)
B(4,23,1,minecraft:blackstone)
B(5,23,1,minecraft:crimson_stem[axis=y])
B(6,23,1,minecraft:blackstone)
B(7,23,1,minecraft:blackstone)
B(8,23,1,minecraft:blackstone)
B(9,23,1,minecraft:blackstone)
B(10,23,1,minecraft:blackstone)
B(4,23,2,minecraft:crimson_stem[axis=y])
B(5,23,2,minecraft:blackstone)
B(6,23,2,minecraft:blackstone)
B(7,23,2,minecraft:blackstone)
B(8,23,2,minecraft:blackstone)
B(9,23,2,minecraft:blackstone)
B(7,23,3,minecraft:blackstone)
B(8,23,3,minecraft:crimson_stem[axis=y])
B(3,24,0,minecraft:blackstone)
B(4,24,0,minecraft:blackstone)
B(5,24,0,minecraft:crimson_stem[axis=y])
B(6,24,0,minecraft:crimson_stem[axis=y])
B(7,24,0,minecraft:crimson_stem[axis=y])
B(8,24,0,minecraft:crimson_stem[axis=y])
B(9,24,0,minecraft:blackstone)
B(10,24,0,minecraft:blackstone)
B(5,24,1,minecraft:crimson_stem[axis=y])
B(6,24,1,minecraft:blackstone)
B(7,24,1,minecraft:blackstone)
B(8,24,1,minecraft:blackstone)
B(9,24,1,minecraft:blackstone)
B(10,24,1,minecraft:blackstone)
B(5,24,2,minecraft:crimson_stem[axis=y])
B(6,24,2,minecraft:blackstone)
B(7,24,2,minecraft:blackstone)
B(8,24,2,minecraft:blackstone)
B(9,24,2,minecraft:blackstone)
B(7,24,3,minecraft:blackstone)
B(8,24,3,minecraft:crimson_stem[axis=y])
B(4,25,0,minecraft:blackstone)
B(5,25,0,minecraft:blackstone)
B(6,25,0,minecraft:blackstone)
B(7,25,0,minecraft:blackstone)
B(8,25,0,minecraft:blackstone)
B(9,25,0,minecraft:blackstone)
B(10,25,0,minecraft:blackstone)
B(4,25,1,minecraft:blackstone)
B(5,25,1,minecraft:crimson_stem[axis=y])
B(6,25,1,minecraft:blackstone)
B(7,25,1,minecraft:blackstone)
B(8,25,1,minecraft:blackstone)
B(9,25,1,minecraft:blackstone)
B(10,25,1,minecraft:blackstone)
B(5,25,2,minecraft:crimson_stem[axis=y])
B(6,25,2,minecraft:blackstone)
B(7,25,2,minecraft:blackstone)
B(8,25,2,minecraft:blackstone)
B(9,25,2,minecraft:blackstone)
B(7,25,3,minecraft:blackstone)
B(8,25,3,minecraft:crimson_stem[axis=y])
B(4,26,0,minecraft:blackstone)
B(5,26,0,minecraft:blackstone)
B(6,26,0,minecraft:blackstone)
B(7,26,0,minecraft:blackstone)
B(8,26,0,minecraft:blackstone)
B(9,26,0,minecraft:blackstone)
B(10,26,0,minecraft:blackstone)
B(5,26,1,minecraft:blackstone)
B(6,26,1,minecraft:blackstone)
B(7,26,1,minecraft:blackstone)
B(8,26,1,minecraft:blackstone)
B(9,26,1,minecraft:blackstone)
B(10,26,1,minecraft:blackstone)
B(6,26,2,minecraft:blackstone)
B(7,26,2,minecraft:blackstone)
B(8,26,2,minecraft:blackstone)
B(9,26,2,minecraft:crimson_stem[axis=y])
B(7,26,3,minecraft:blackstone)
B(8,26,3,minecraft:blackstone)
B(4,27,0,minecraft:blackstone)
B(5,27,0,minecraft:blackstone)
B(6,27,0,minecraft:blackstone)
B(7,27,0,minecraft:blackstone)
B(8,27,0,minecraft:blackstone)
B(9,27,0,minecraft:blackstone)
B(10,27,0,minecraft:blackstone)
B(5,27,1,minecraft:blackstone)
B(6,27,1,minecraft:blackstone)
B(7,27,1,minecraft:blackstone)
B(8,27,1,minecraft:blackstone)
B(9,27,1,minecraft:blackstone)
B(10,27,1,minecraft:blackstone)
B(6,27,2,minecraft:blackstone)
B(7,27,2,minecraft:blackstone)
B(8,27,2,minecraft:blackstone)
B(9,27,2,minecraft:crimson_stem[axis=y])
B(7,27,3,minecraft:crimson_stem[axis=y])
B(8,27,3,minecraft:blackstone)
B(4,28,0,minecraft:crimson_stem[axis=y])
B(5,28,0,minecraft:blackstone)
B(6,28,0,minecraft:blackstone)
B(7,28,0,minecraft:blackstone)
B(8,28,0,minecraft:blackstone)
B(9,28,0,minecraft:blackstone)
B(10,28,0,minecraft:blackstone)
B(5,28,1,minecraft:blackstone)
B(6,28,1,minecraft:blackstone)
B(7,28,1,minecraft:blackstone)
B(8,28,1,minecraft:blackstone)
B(9,28,1,minecraft:blackstone)
B(10,28,1,minecraft:crimson_stem[axis=y])
B(6,28,2,minecraft:blackstone)
B(7,28,2,minecraft:blackstone)
B(8,28,2,minecraft:blackstone)
B(9,28,2,minecraft:crimson_stem[axis=y])
B(7,28,3,minecraft:crimson_stem[axis=y])
B(5,29,0,minecraft:blackstone)
B(6,29,0,minecraft:blackstone)
B(7,29,0,minecraft:blackstone)
B(8,29,0,minecraft:blackstone)
B(9,29,0,minecraft:blackstone)
B(10,29,0,minecraft:blackstone)
B(5,29,1,minecraft:blackstone)
B(6,29,1,minecraft:blackstone)
B(7,29,1,minecraft:blackstone)
B(8,29,1,minecraft:blackstone)
B(9,29,1,minecraft:blackstone)
B(10,29,1,minecraft:crimson_stem[axis=y])
B(6,29,2,minecraft:blackstone)
B(7,29,2,minecraft:crimson_stem[axis=y])
B(8,29,2,minecraft:blackstone)
B(9,29,2,minecraft:crimson_stem[axis=y])
B(5,30,0,minecraft:blackstone)
B(6,30,0,minecraft:blackstone)
B(7,30,0,minecraft:crimson_stem[axis=y])
B(8,30,0,minecraft:crimson_stem[axis=y])
B(9,30,0,minecraft:crimson_stem[axis=y])
B(10,30,0,minecraft:crimson_stem[axis=y])
B(6,30,1,minecraft:blackstone)
B(7,30,1,minecraft:blackstone)
B(8,30,1,minecraft:blackstone)
B(9,30,1,minecraft:blackstone)
B(10,30,1,minecraft:crimson_stem[axis=y])
B(6,30,2,minecraft:blackstone)
B(7,30,2,minecraft:crimson_stem[axis=y])
B(8,30,2,minecraft:crimson_stem[axis=y])
B(5,31,0,minecraft:blackstone)
B(6,31,0,minecraft:blackstone)
B(7,31,0,minecraft:blackstone)
B(8,31,0,minecraft:crimson_stem[axis=y])
B(9,31,0,minecraft:blackstone)
B(10,31,0,minecraft:crimson_stem[axis=y])
B(6,31,1,minecraft:blackstone)
B(7,31,1,minecraft:blackstone)
B(8,31,1,minecraft:crimson_stem[axis=y])
B(9,31,1,minecraft:crimson_stem[axis=y])
B(10,31,1,minecraft:crimson_stem[axis=y])
B(6,31,2,minecraft:blackstone)
B(7,31,2,minecraft:blackstone)
B(8,31,2,minecraft:crimson_stem[axis=y])
B(5,32,0,minecraft:crimson_stem[axis=y])
B(6,32,0,minecraft:blackstone)
B(7,32,0,minecraft:crimson_stem[axis=y])
B(8,32,0,minecraft:blackstone)
B(9,32,0,minecraft:blackstone)
B(10,32,0,minecraft:crimson_stem[axis=y])
B(6,32,1,minecraft:blackstone)
B(7,32,1,minecraft:blackstone)
B(8,32,1,minecraft:blackstone)
B(9,32,1,minecraft:crimson_stem[axis=y])
B(10,32,1,minecraft:crimson_stem[axis=y])
B(6,32,2,minecraft:blackstone)
B(7,32,2,minecraft:blackstone)
B(8,32,2,minecraft:crimson_stem[axis=y])
B(5,33,0,minecraft:blackstone)
B(6,33,0,minecraft:blackstone)
B(7,33,0,minecraft:blackstone)
B(8,33,0,minecraft:crimson_stem[axis=y])
B(9,33,0,minecraft:blackstone)
B(10,33,0,minecraft:crimson_stem[axis=y])
B(6,33,1,minecraft:blackstone)
B(7,33,1,minecraft:blackstone)
B(8,33,1,minecraft:blackstone)
B(9,33,1,minecraft:blackstone)
B(7,33,2,minecraft:blackstone)
B(8,33,2,minecraft:crimson_stem[axis=y])
B(5,34,0,minecraft:crimson_stem[axis=y])
B(6,34,0,minecraft:blackstone)
B(7,34,0,minecraft:crimson_stem[axis=y])
B(8,34,0,minecraft:blackstone)
B(9,34,0,minecraft:blackstone)
B(10,34,0,minecraft:crimson_stem[axis=y])
B(6,34,1,minecraft:blackstone)
B(7,34,1,minecraft:blackstone)
B(8,34,1,minecraft:blackstone)
B(9,34,1,minecraft:crimson_stem[axis=y])
B(7,34,2,minecraft:blackstone)
B(8,34,2,minecraft:crimson_stem[axis=y])
B(5,35,0,minecraft:blackstone)
B(6,35,0,minecraft:blackstone)
B(7,35,0,minecraft:blackstone)
B(8,35,0,minecraft:crimson_stem[axis=y])
B(9,35,0,minecraft:blackstone)
B(10,35,0,minecraft:crimson_stem[axis=y])
B(6,35,1,minecraft:blackstone)
B(7,35,1,minecraft:blackstone)
B(9,35,1,minecraft:blackstone)
B(7,35,2,minecraft:blackstone)
B(8,35,2,minecraft:crimson_stem[axis=y])
B(5,36,0,minecraft:crimson_stem[axis=y])
B(6,36,0,minecraft:blackstone)
B(7,36,0,minecraft:crimson_stem[axis=y])
B(8,36,0,minecraft:blackstone)
B(9,36,0,minecraft:blackstone)
B(10,36,0,minecraft:crimson_stem[axis=y])
B(6,36,1,minecraft:crimson_stem[axis=y])
B(7,36,1,minecraft:blackstone)
B(8,36,1,minecraft:blackstone)
B(9,36,1,minecraft:blackstone)
B(7,36,2,minecraft:blackstone)
B(8,36,2,minecraft:crimson_stem[axis=y])
B(5,37,0,minecraft:blackstone)
B(6,37,0,minecraft:blackstone)
B(7,37,0,minecraft:blackstone)
B(8,37,0,minecraft:blackstone)
B(9,37,0,minecraft:blackstone)
B(10,37,0,minecraft:crimson_stem[axis=y])
B(6,37,1,minecraft:crimson_stem[axis=y])
B(7,37,1,minecraft:blackstone)
B(8,37,1,minecraft:blackstone)
B(9,37,1,minecraft:blackstone)
B(7,37,2,minecraft:blackstone)
B(8,37,2,minecraft:crimson_stem[axis=y])
B(9,37,2,minecraft:blackstone)
B(5,38,0,minecraft:crimson_stem[axis=y])
B(6,38,0,minecraft:blackstone)
B(7,38,0,minecraft:crimson_stem[axis=y])
B(8,38,0,minecraft:crimson_stem[axis=y])
B(9,38,0,minecraft:blackstone)
B(10,38,0,minecraft:crimson_stem[axis=y])
B(6,38,1,minecraft:crimson_stem[axis=y])
B(7,38,1,minecraft:blackstone)
B(8,38,1,minecraft:crimson_stem[axis=y])
B(9,38,1,minecraft:blackstone)
B(7,38,2,minecraft:crimson_stem[axis=y])
B(8,38,2,minecraft:crimson_stem[axis=y])
B(9,38,2,minecraft:blackstone)
B(5,39,0,minecraft:crimson_stem[axis=y])
B(6,39,0,minecraft:blackstone)
B(7,39,0,minecraft:crimson_stem[axis=y])
B(8,39,0,minecraft:crimson_stem[axis=y])
B(9,39,0,minecraft:crimson_stem[axis=y])
B(10,39,0,minecraft:crimson_stem[axis=y])
B(6,39,1,minecraft:crimson_stem[axis=y])
B(7,39,1,minecraft:blackstone)
B(8,39,1,minecraft:blackstone)
B(9,39,1,minecraft:blackstone)
B(8,39,2,minecraft:crimson_stem[axis=y])
B(9,39,2,minecraft:blackstone)
B(5,40,0,minecraft:blackstone)
B(6,40,0,minecraft:blackstone)
B(7,40,0,minecraft:blackstone)
B(8,40,0,minecraft:crimson_stem[axis=y])
B(9,40,0,minecraft:crimson_stem[axis=y])
B(10,40,0,minecraft:crimson_stem[axis=y])
B(6,40,1,minecraft:blackstone)
B(7,40,1,minecraft:blackstone)
B(8,40,1,minecraft:blackstone)
B(9,40,1,minecraft:blackstone)
B(8,40,2,minecraft:crimson_stem[axis=y])
B(9,40,2,minecraft:blackstone)
B(5,41,0,minecraft:crimson_stem[axis=y])
B(6,41,0,minecraft:blackstone)
B(7,41,0,minecraft:crimson_stem[axis=y])
B(8,41,0,minecraft:crimson_stem[axis=y])
B(9,41,0,minecraft:crimson_stem[axis=y])
B(10,41,0,minecraft:crimson_stem[axis=y])
B(6,41,1,minecraft:crimson_stem[axis=y])
B(7,41,1,minecraft:blackstone)
B(8,41,1,minecraft:crimson_stem[axis=y])
B(9,41,1,minecraft:blackstone)
B(8,41,2,minecraft:crimson_stem[axis=y])
B(9,41,2,minecraft:blackstone)
B(5,42,0,minecraft:blackstone)
B(6,42,0,minecraft:blackstone)
B(7,42,0,minecraft:blackstone)
B(8,42,0,minecraft:crimson_stem[axis=y])
B(9,42,0,minecraft:crimson_stem[axis=y])
B(10,42,0,minecraft:crimson_stem[axis=y])
B(6,42,1,minecraft:crimson_stem[axis=y])
B(7,42,1,minecraft:blackstone)
B(8,42,1,minecraft:blackstone)
B(9,42,1,minecraft:blackstone)
B(10,42,1,minecraft:blackstone)
B(8,42,2,minecraft:crimson_stem[axis=y])
B(9,42,2,minecraft:blackstone)
B(5,43,0,minecraft:crimson_stem[axis=y])
B(6,43,0,minecraft:blackstone)
B(7,43,0,minecraft:blackstone)
B(8,43,0,minecraft:crimson_stem[axis=y])
B(9,43,0,minecraft:crimson_stem[axis=y])
B(10,43,0,minecraft:crimson_stem[axis=y])
B(6,43,1,minecraft:crimson_stem[axis=y])
B(7,43,1,minecraft:crimson_stem[axis=y])
B(8,43,1,minecraft:blackstone)
B(9,43,1,minecraft:blackstone)
B(10,43,1,minecraft:blackstone)
B(8,43,2,minecraft:blackstone)
B(9,43,2,minecraft:blackstone)
B(5,44,0,minecraft:crimson_stem[axis=y])
B(6,44,0,minecraft:blackstone)
B(7,44,0,minecraft:blackstone)
B(8,44,0,minecraft:blackstone)
B(9,44,0,minecraft:crimson_stem[axis=y])
B(10,44,0,minecraft:crimson_stem[axis=y])
B(6,44,1,minecraft:crimson_stem[axis=y])
B(7,44,1,minecraft:crimson_stem[axis=y])
B(8,44,1,minecraft:blackstone)
B(9,44,1,minecraft:blackstone)
B(10,44,1,minecraft:crimson_stem[axis=y])
B(8,44,2,minecraft:blackstone)
B(9,44,2,minecraft:blackstone)
B(5,45,0,minecraft:crimson_stem[axis=y])
B(6,45,0,minecraft:crimson_stem[axis=y])
B(7,45,0,minecraft:blackstone)
B(8,45,0,minecraft:crimson_stem[axis=y])
B(9,45,0,minecraft:crimson_stem[axis=y])
B(10,45,0,minecraft:crimson_stem[axis=y])
B(6,45,1,minecraft:crimson_stem[axis=y])
B(7,45,1,minecraft:crimson_stem[axis=y])
B(8,45,1,minecraft:blackstone)
B(9,45,1,minecraft:blackstone)
B(10,45,1,minecraft:crimson_stem[axis=y])
B(8,45,2,minecraft:blackstone)
B(9,45,2,minecraft:blackstone)
B(6,46,0,minecraft:blackstone)
B(7,46,0,minecraft:blackstone)
B(8,46,0,minecraft:blackstone)
B(9,46,0,minecraft:crimson_stem[axis=y])
B(10,46,0,minecraft:crimson_stem[axis=y])
B(7,46,1,minecraft:crimson_stem[axis=y])
B(8,46,1,minecraft:blackstone)
B(9,46,1,minecraft:blackstone)
B(10,46,1,minecraft:blackstone)
B(8,46,2,minecraft:blackstone)
B(9,46,2,minecraft:blackstone)
B(6,47,0,minecraft:crimson_stem[axis=y])
B(7,47,0,minecraft:blackstone)
B(8,47,0,minecraft:crimson_stem[axis=y])
B(9,47,0,minecraft:crimson_stem[axis=y])
B(10,47,0,minecraft:crimson_stem[axis=y])
B(7,47,1,minecraft:blackstone)
B(8,47,1,minecraft:blackstone)
B(9,47,1,minecraft:blackstone)
B(10,47,1,minecraft:crimson_stem[axis=y])
B(8,47,2,minecraft:blackstone)
B(9,47,2,minecraft:blackstone)
B(6,48,0,minecraft:crimson_stem[axis=y])
B(7,48,0,minecraft:blackstone)
B(8,48,0,minecraft:crimson_stem[axis=y])
B(9,48,0,minecraft:crimson_stem[axis=y])
B(10,48,0,minecraft:crimson_stem[axis=y])
B(7,48,1,minecraft:blackstone)
B(8,48,1,minecraft:blackstone)
B(9,48,1,minecraft:blackstone)
B(10,48,1,minecraft:blackstone)
B(8,48,2,minecraft:crimson_stem[axis=y])
B(9,48,2,minecraft:blackstone)
B(10,48,2,minecraft:blackstone)
B(6,49,0,minecraft:blackstone)
B(7,49,0,minecraft:blackstone)
B(8,49,0,minecraft:blackstone)
B(9,49,0,minecraft:crimson_stem[axis=y])
B(10,49,0,minecraft:crimson_stem[axis=y])
B(7,49,1,minecraft:blackstone)
B(8,49,1,minecraft:blackstone)
B(9,49,1,minecraft:blackstone)
B(10,49,1,minecraft:blackstone)
B(8,49,2,minecraft:crimson_stem[axis=y])
B(9,49,2,minecraft:blackstone)
B(10,49,2,minecraft:blackstone)
B(6,50,0,minecraft:crimson_stem[axis=y])
B(7,50,0,minecraft:blackstone)
B(8,50,0,minecraft:crimson_stem[axis=y])
B(9,50,0,minecraft:crimson_stem[axis=y])
B(10,50,0,minecraft:crimson_stem[axis=y])
B(7,50,1,minecraft:blackstone)
B(8,50,1,minecraft:blackstone)
B(9,50,1,minecraft:blackstone)
B(10,50,1,minecraft:blackstone)
B(8,50,2,minecraft:crimson_stem[axis=y])
B(9,50,2,minecraft:blackstone)
B(10,50,2,minecraft:blackstone)
B(6,51,0,minecraft:crimson_stem[axis=y])
B(7,51,0,minecraft:crimson_stem[axis=y])
B(8,51,0,minecraft:crimson_stem[axis=y])
B(9,51,0,minecraft:crimson_stem[axis=y])
B(10,51,0,minecraft:crimson_stem[axis=y])
B(7,51,1,minecraft:crimson_stem[axis=y])
B(8,51,1,minecraft:crimson_stem[axis=y])
B(9,51,1,minecraft:crimson_stem[axis=y])
B(10,51,1,minecraft:blackstone)
B(8,51,2,minecraft:crimson_stem[axis=y])
B(9,51,2,minecraft:blackstone)
B(10,51,2,minecraft:blackstone)
B(6,52,0,minecraft:crimson_stem[axis=y])
B(7,52,0,minecraft:crimson_stem[axis=y])
B(8,52,0,minecraft:crimson_stem[axis=y])
B(9,52,0,minecraft:crimson_stem[axis=y])
B(10,52,0,minecraft:crimson_stem[axis=y])
B(7,52,1,minecraft:crimson_stem[axis=y])
B(8,52,1,minecraft:crimson_stem[axis=y])
B(9,52,1,minecraft:crimson_stem[axis=y])
B(10,52,1,minecraft:blackstone)
B(8,52,2,minecraft:crimson_stem[axis=y])
B(9,52,2,minecraft:blackstone)
B(10,52,2,minecraft:blackstone)
B(6,53,0,minecraft:crimson_stem[axis=y])
B(7,53,0,minecraft:crimson_stem[axis=y])
B(8,53,0,minecraft:crimson_stem[axis=y])
B(9,53,0,minecraft:crimson_stem[axis=y])
B(10,53,0,minecraft:crimson_stem[axis=y])
B(7,53,1,minecraft:crimson_stem[axis=y])
B(8,53,1,minecraft:crimson_stem[axis=y])
B(9,53,1,minecraft:blackstone)
B(10,53,1,minecraft:blackstone)
B(8,53,2,minecraft:crimson_stem[axis=y])
B(9,53,2,minecraft:blackstone)
B(10,53,2,minecraft:blackstone)
B(6,54,0,minecraft:crimson_stem[axis=y])
B(7,54,0,minecraft:crimson_stem[axis=y])
B(8,54,0,minecraft:crimson_stem[axis=y])
B(9,54,0,minecraft:crimson_stem[axis=y])
B(10,54,0,minecraft:crimson_stem[axis=y])
B(7,54,1,minecraft:crimson_stem[axis=y])
B(8,54,1,minecraft:crimson_stem[axis=y])
B(9,54,1,minecraft:crimson_stem[axis=y])
B(10,54,1,minecraft:blackstone)
B(11,54,1,minecraft:crimson_stem[axis=y])
B(8,54,2,minecraft:crimson_stem[axis=y])
B(9,54,2,minecraft:blackstone)
B(10,54,2,minecraft:blackstone)
B(6,55,0,minecraft:crimson_stem[axis=y])
B(7,55,0,minecraft:crimson_stem[axis=y])
B(8,55,0,minecraft:crimson_stem[axis=y])
B(9,55,0,minecraft:crimson_stem[axis=y])
B(10,55,0,minecraft:crimson_stem[axis=y])
B(7,55,1,minecraft:crimson_stem[axis=y])
B(8,55,1,minecraft:crimson_stem[axis=y])
B(9,55,1,minecraft:crimson_stem[axis=y])
B(10,55,1,minecraft:crimson_stem[axis=y])
B(11,55,1,minecraft:crimson_stem[axis=y])
B(8,55,2,minecraft:crimson_stem[axis=y])
B(9,55,2,minecraft:crimson_stem[axis=y])
B(10,55,2,minecraft:crimson_stem[axis=y])
B(6,56,0,minecraft:blackstone)
B(7,56,0,minecraft:crimson_stem[axis=y])
B(8,56,0,minecraft:crimson_stem[axis=y])
B(9,56,0,minecraft:crimson_stem[axis=y])
B(10,56,0,minecraft:blackstone)
B(7,56,1,minecraft:crimson_stem[axis=y])
B(8,56,1,minecraft:crimson_stem[axis=y])
B(9,56,1,minecraft:blackstone)
B(10,56,1,minecraft:blackstone)
B(11,56,1,minecraft:blackstone)
B(8,56,2,minecraft:crimson_stem[axis=y])
B(9,56,2,minecraft:crimson_stem[axis=y])
B(6,57,0,minecraft:crimson_stem[axis=y])
B(7,57,0,minecraft:blackstone)
B(8,57,0,minecraft:crimson_stem[axis=y])
B(9,57,0,minecraft:blackstone)
B(10,57,0,minecraft:blackstone)
B(7,57,1,minecraft:crimson_stem[axis=y])
B(8,57,1,minecraft:crimson_stem[axis=y])
B(9,57,1,minecraft:blackstone)
B(10,57,1,minecraft:blackstone)
B(11,57,1,minecraft:blackstone)
B(8,57,2,minecraft:crimson_stem[axis=y])
B(9,57,2,minecraft:blackstone)
B(6,58,0,minecraft:crimson_stem[axis=y])
B(7,58,0,minecraft:blackstone)
B(8,58,0,minecraft:crimson_stem[axis=y])
B(9,58,0,minecraft:crimson_stem[axis=y])
B(10,58,0,minecraft:blackstone)
B(7,58,1,minecraft:crimson_stem[axis=y])
B(8,58,1,minecraft:crimson_stem[axis=y])
B(9,58,1,minecraft:blackstone)
B(10,58,1,minecraft:blackstone)
B(11,58,1,minecraft:blackstone)
B(8,58,2,minecraft:crimson_stem[axis=y])
B(9,58,2,minecraft:crimson_stem[axis=y])
B(6,59,0,minecraft:crimson_stem[axis=y])
B(7,59,0,minecraft:blackstone)
B(8,59,0,minecraft:blackstone)
B(9,59,0,minecraft:blackstone)
B(10,59,0,minecraft:blackstone)
B(7,59,1,minecraft:crimson_stem[axis=y])
B(8,59,1,minecraft:crimson_stem[axis=y])
B(9,59,1,minecraft:blackstone)
B(10,59,1,minecraft:blackstone)
B(11,59,1,minecraft:blackstone)
B(8,59,2,minecraft:crimson_stem[axis=y])
B(9,59,2,minecraft:blackstone)
B(6,60,0,minecraft:crimson_stem[axis=y])
B(7,60,0,minecraft:blackstone)
B(8,60,0,minecraft:crimson_stem[axis=y])
B(9,60,0,minecraft:crimson_stem[axis=y])
B(10,60,0,minecraft:blackstone)
B(7,60,1,minecraft:blackstone)
B(8,60,1,minecraft:crimson_stem[axis=y])
B(9,60,1,minecraft:blackstone)
B(10,60,1,minecraft:blackstone)
B(11,60,1,minecraft:blackstone)
B(8,60,2,minecraft:crimson_stem[axis=y])
B(9,60,2,minecraft:crimson_stem[axis=y])
B(6,61,0,minecraft:crimson_stem[axis=y])
B(7,61,0,minecraft:blackstone)
B(8,61,0,minecraft:crimson_stem[axis=y])
B(9,61,0,minecraft:blackstone)
B(10,61,0,minecraft:blackstone)
B(7,61,1,minecraft:crimson_stem[axis=y])
B(8,61,1,minecraft:crimson_stem[axis=y])
B(9,61,1,minecraft:blackstone)
B(10,61,1,minecraft:blackstone)
B(11,61,1,minecraft:blackstone)
B(8,61,2,minecraft:crimson_stem[axis=y])
B(9,61,2,minecraft:blackstone)
B(6,62,0,minecraft:crimson_stem[axis=y])
B(7,62,0,minecraft:blackstone)
B(8,62,0,minecraft:blackstone)
B(9,62,0,minecraft:crimson_stem[axis=y])
B(10,62,0,minecraft:blackstone)
B(11,62,0,minecraft:crimson_stem[axis=y])
B(7,62,1,minecraft:blackstone)
B(8,62,1,minecraft:crimson_stem[axis=y])
B(9,62,1,minecraft:blackstone)
B(10,62,1,minecraft:blackstone)
B(11,62,1,minecraft:blackstone)
B(8,62,2,minecraft:crimson_stem[axis=y])
B(9,62,2,minecraft:crimson_stem[axis=y])
B(7,63,0,minecraft:blackstone)
B(8,63,0,minecraft:blackstone)
B(9,63,0,minecraft:crimson_stem[axis=y])
B(10,63,0,minecraft:blackstone)
B(11,63,0,minecraft:crimson_stem[axis=y])
B(7,63,1,minecraft:blackstone)
B(8,63,1,minecraft:blackstone)
B(9,63,1,minecraft:blackstone)
B(10,63,1,minecraft:blackstone)
B(11,63,1,minecraft:blackstone)
B(8,63,2,minecraft:crimson_stem[axis=y])
B(9,63,2,minecraft:crimson_stem[axis=y])
B(7,64,0,minecraft:blackstone)
B(8,64,0,minecraft:blackstone)
B(9,64,0,minecraft:blackstone)
B(10,64,0,minecraft:blackstone)
B(11,64,0,minecraft:blackstone)
B(7,64,1,minecraft:blackstone)
B(8,64,1,minecraft:blackstone)
B(9,64,1,minecraft:blackstone)
B(10,64,1,minecraft:blackstone)
B(11,64,1,minecraft:blackstone)
B(8,64,2,minecraft:crimson_stem[axis=y])
B(9,64,2,minecraft:blackstone)
B(7,65,0,minecraft:blackstone)
B(8,65,0,minecraft:blackstone)
B(9,65,0,minecraft:crimson_stem[axis=y])
B(10,65,0,minecraft:blackstone)
B(11,65,0,minecraft:blackstone)
B(7,65,1,minecraft:blackstone)
B(8,65,1,minecraft:blackstone)
B(9,65,1,minecraft:blackstone)
B(10,65,1,minecraft:blackstone)
B(11,65,1,minecraft:blackstone)
B(8,65,2,minecraft:blackstone)
B(9,65,2,minecraft:crimson_stem[axis=y])
B(9,65,3,minecraft:crimson_stem[axis=y])
B(7,66,0,minecraft:blackstone)
B(8,66,0,minecraft:crimson_stem[axis=y])
B(9,66,0,minecraft:crimson_stem[axis=y])
B(10,66,0,minecraft:blackstone)
B(11,66,0,minecraft:blackstone)
B(7,66,1,minecraft:blackstone)
B(8,66,1,minecraft:blackstone)
B(9,66,1,minecraft:crimson_stem[axis=y])
B(10,66,1,minecraft:blackstone)
B(11,66,1,minecraft:blackstone)
B(8,66,2,minecraft:crimson_stem[axis=y])
B(9,66,2,minecraft:crimson_stem[axis=y])
B(9,66,3,minecraft:crimson_stem[axis=y])
B(7,67,0,minecraft:crimson_stem[axis=y])
B(8,67,0,minecraft:crimson_stem[axis=y])
B(9,67,0,minecraft:blackstone)
B(10,67,0,minecraft:blackstone)
B(11,67,0,minecraft:blackstone)
B(7,67,1,minecraft:crimson_stem[axis=y])
B(8,67,1,minecraft:crimson_stem[axis=y])
B(9,67,1,minecraft:crimson_stem[axis=y])
B(10,67,1,minecraft:blackstone)
B(11,67,1,minecraft:blackstone)
B(9,67,2,minecraft:crimson_stem[axis=y])
B(9,67,3,minecraft:crimson_stem[axis=y])
B(7,68,0,minecraft:crimson_stem[axis=y])
B(8,68,0,minecraft:crimson_stem[axis=y])
B(9,68,0,minecraft:crimson_stem[axis=y])
B(10,68,0,minecraft:blackstone)
B(11,68,0,minecraft:blackstone)
B(8,68,1,minecraft:crimson_stem[axis=y])
B(9,68,1,minecraft:crimson_stem[axis=y])
B(10,68,1,minecraft:blackstone)
B(11,68,1,minecraft:blackstone)
B(9,68,2,minecraft:crimson_stem[axis=y])
B(9,68,3,minecraft:crimson_stem[axis=y])
B(7,69,0,minecraft:crimson_stem[axis=y])
B(8,69,0,minecraft:crimson_stem[axis=y])
B(9,69,0,minecraft:crimson_stem[axis=y])
B(10,69,0,minecraft:crimson_stem[axis=y])
B(11,69,0,minecraft:blackstone)
B(8,69,1,minecraft:crimson_stem[axis=y])
B(9,69,1,minecraft:crimson_stem[axis=y])
B(10,69,1,minecraft:blackstone)
B(11,69,1,minecraft:blackstone)
B(9,69,3,minecraft:blackstone)
B(7,70,0,minecraft:crimson_stem[axis=y])
B(8,70,0,minecraft:crimson_stem[axis=y])
B(9,70,0,minecraft:crimson_stem[axis=y])
B(10,70,0,minecraft:blackstone)
B(11,70,0,minecraft:crimson_stem[axis=y])
B(8,70,1,minecraft:crimson_stem[axis=y])
B(9,70,1,minecraft:blackstone)
B(10,70,1,minecraft:blackstone)
B(9,70,3,minecraft:blackstone)
B(7,71,0,minecraft:crimson_stem[axis=y])
B(8,71,0,minecraft:crimson_stem[axis=y])
B(9,71,0,minecraft:blackstone)
B(10,71,0,minecraft:blackstone)
B(11,71,0,minecraft:blackstone)
B(8,71,1,minecraft:crimson_stem[axis=y])
B(9,71,1,minecraft:blackstone)
B(10,71,1,minecraft:blackstone)
B(9,71,3,minecraft:blackstone)
B(7,72,0,minecraft:crimson_stem[axis=y])
B(8,72,0,minecraft:crimson_stem[axis=y])
B(9,72,0,minecraft:crimson_stem[axis=y])
B(10,72,0,minecraft:blackstone)
B(11,72,0,minecraft:crimson_stem[axis=y])
B(8,72,1,minecraft:crimson_stem[axis=y])
B(9,72,1,minecraft:blackstone)
B(9,72,4,minecraft:crimson_stem[axis=y])
B(7,73,0,minecraft:crimson_stem[axis=y])
B(8,73,0,minecraft:crimson_stem[axis=y])
B(9,73,0,minecraft:blackstone)
B(10,73,0,minecraft:blackstone)
B(11,73,0,minecraft:blackstone)
B(9,73,1,minecraft:crimson_stem[axis=y])
B(9,73,4,minecraft:blackstone)
B(6,74,0,minecraft:crimson_stem[axis=y])
B(7,74,0,minecraft:crimson_stem[axis=y])
B(8,74,0,minecraft:crimson_stem[axis=y])
B(9,74,0,minecraft:blackstone)
B(10,74,0,minecraft:blackstone)
B(11,74,0,minecraft:blackstone)
B(9,74,1,minecraft:blackstone)
B(10,74,4,minecraft:blackstone)
B(8,74,5,minecraft:crimson_stem[axis=y])
B(6,75,0,minecraft:crimson_stem[axis=y])
B(8,75,0,minecraft:crimson_stem[axis=y])
B(9,75,0,minecraft:blackstone)
B(10,75,0,minecraft:blackstone)
B(11,75,0,minecraft:blackstone)
B(10,75,4,minecraft:blackstone)
B(7,75,5,minecraft:crimson_stem[axis=y])
B(8,75,5,minecraft:crimson_stem[axis=y])
RB(14,75,7,minecraft:air,20,minecraft:coal_ore,3,minecraft:gold_ore,1,minecraft:basalt[axis=y],100)
RB(15,75,7,minecraft:air,20,minecraft:coal_ore,3,minecraft:gold_ore,1,minecraft:basalt[axis=y],100)
RB(14,75,8,minecraft:air,20,minecraft:coal_ore,3,minecraft:gold_ore,1,minecraft:basalt[axis=y],100)
RB(15,75,8,minecraft:air,20,minecraft:coal_ore,3,minecraft:gold_ore,1,minecraft:basalt[axis=y],100)
RB(14,75,9,minecraft:air,20,minecraft:coal_ore,3,minecraft:gold_ore,1,minecraft:basalt[axis=y],100)
RB(15,75,9,minecraft:air,20,minecraft:coal_ore,3,minecraft:gold_ore,1,minecraft:basalt[axis=y],100)
B(6,76,0,minecraft:crimson_stem[axis=y])
B(8,76,0,minecraft:crimson_stem[axis=y])
B(9,76,0,minecraft:blackstone)
B(10,76,0,minecraft:blackstone)
B(11,76,0,minecraft:blackstone)
B(12,76,0,minecraft:crimson_stem[axis=y])
B(10,76,4,minecraft:crimson_stem[axis=y])
B(7,76,5,minecraft:crimson_stem[axis=y])
B(11,76,5,minecraft:crimson_stem[axis=y])
B(8,76,6,minecraft:crimson_stem[axis=y])
RB(13,76,6,minecraft:air,20,minecraft:coal_ore,3,minecraft:gold_ore,1,minecraft:basalt[axis=y],100)
RB(13,76,7,minecraft:air,20,minecraft:coal_ore,3,minecraft:gold_ore,1,minecraft:basalt[axis=y],100)
RB(15,76,7,minecraft:air,20,minecraft:coal_ore,3,minecraft:gold_ore,1,minecraft:basalt[axis=y],100)
RB(12,76,8,minecraft:air,20,minecraft:coal_ore,3,minecraft:gold_ore,1,minecraft:basalt[axis=y],100)
RB(13,76,8,minecraft:air,20,minecraft:coal_ore,3,minecraft:gold_ore,1,minecraft:basalt[axis=y],100)
RB(15,76,8,minecraft:air,20,minecraft:coal_ore,3,minecraft:gold_ore,1,minecraft:basalt[axis=y],100)
RB(1,76,9,minecraft:air,20,minecraft:coal_ore,3,minecraft:gold_ore,1,minecraft:basalt[axis=y],100)
RB(2,76,9,minecraft:air,20,minecraft:coal_ore,3,minecraft:gold_ore,1,minecraft:basalt[axis=y],100)
RB(3,76,9,minecraft:air,20,minecraft:coal_ore,3,minecraft:gold_ore,1,minecraft:basalt[axis=y],100)
RB(12,76,9,minecraft:air,20,minecraft:coal_ore,3,minecraft:gold_ore,1,minecraft:basalt[axis=y],100)
RB(14,76,9,minecraft:air,20,minecraft:coal_ore,3,minecraft:gold_ore,1,minecraft:basalt[axis=y],100)
RB(15,76,9,minecraft:air,20,minecraft:coal_ore,3,minecraft:gold_ore,1,minecraft:basalt[axis=y],100)
RB(1,76,10,minecraft:air,20,minecraft:coal_ore,3,minecraft:gold_ore,1,minecraft:basalt[axis=y],100)
RB(3,76,10,minecraft:air,20,minecraft:coal_ore,3,minecraft:gold_ore,1,minecraft:basalt[axis=y],100)
RB(14,76,10,minecraft:air,20,minecraft:coal_ore,3,minecraft:gold_ore,1,minecraft:basalt[axis=y],100)
RB(2,76,11,minecraft:air,20,minecraft:coal_ore,3,minecraft:gold_ore,1,minecraft:basalt[axis=y],100)
RB(14,76,12,minecraft:air,20,minecraft:coal_ore,3,minecraft:gold_ore,1,minecraft:basalt[axis=y],100)
RB(15,76,13,minecraft:air,20,minecraft:coal_ore,3,minecraft:gold_ore,1,minecraft:basalt[axis=y],100)
RB(14,76,14,minecraft:air,20,minecraft:coal_ore,3,minecraft:gold_ore,1,minecraft:basalt[axis=y],100)
B(6,77,0,minecraft:crimson_stem[axis=y])
B(8,77,0,minecraft:crimson_stem[axis=y])
B(9,77,0,minecraft:blackstone)
B(10,77,0,minecraft:blackstone)
B(11,77,0,minecraft:blackstone)
B(12,77,0,minecraft:blackstone)
B(11,77,1,minecraft:blackstone)
B(10,77,3,minecraft:crimson_stem[axis=y])
B(10,77,4,minecraft:crimson_stem[axis=y])
B(6,77,6,minecraft:crimson_stem[axis=y])
B(8,77,6,minecraft:crimson_stem[axis=y])
B(12,77,6,minecraft:crimson_stem[axis=y])
B(13,77,6,minecraft:crimson_stem[axis=y])
RB(15,77,6,minecraft:air,20,minecraft:coal_ore,3,minecraft:gold_ore,1,minecraft:basalt[axis=y],100)
B(12,77,7,minecraft:crimson_stem[axis=y])
B(14,77,7,minecraft:crimson_stem[axis=y])
B(15,77,7,minecraft:crimson_stem[axis=y])
RB(2,77,8,minecraft:air,20,minecraft:coal_ore,3,minecraft:gold_ore,1,minecraft:basalt[axis=y],100)
RB(3,77,8,minecraft:air,20,minecraft:coal_ore,3,minecraft:gold_ore,1,minecraft:basalt[axis=y],100)
B(12,77,8,minecraft:crimson_stem[axis=y])
B(14,77,8,minecraft:crimson_stem[axis=y])
RB(0,77,9,minecraft:air,20,minecraft:coal_ore,3,minecraft:gold_ore,1,minecraft:basalt[axis=y],100)
RB(1,77,9,minecraft:air,20,minecraft:coal_ore,3,minecraft:gold_ore,1,minecraft:basalt[axis=y],100)
RB(4,77,9,minecraft:air,20,minecraft:coal_ore,3,minecraft:gold_ore,1,minecraft:basalt[axis=y],100)
RB(8,77,9,minecraft:air,20,minecraft:coal_ore,3,minecraft:gold_ore,1,minecraft:basalt[axis=y],100)
RB(9,77,9,minecraft:air,20,minecraft:coal_ore,3,minecraft:gold_ore,1,minecraft:basalt[axis=y],100)
RB(10,77,9,minecraft:air,20,minecraft:coal_ore,3,minecraft:gold_ore,1,minecraft:basalt[axis=y],100)
RB(13,77,9,minecraft:air,20,minecraft:coal_ore,3,minecraft:gold_ore,1,minecraft:basalt[axis=y],100)
RB(15,77,9,minecraft:air,20,minecraft:coal_ore,3,minecraft:gold_ore,1,minecraft:basalt[axis=y],100)
RB(0,77,10,minecraft:air,20,minecraft:coal_ore,3,minecraft:gold_ore,1,minecraft:basalt[axis=y],100)
RB(1,77,10,minecraft:air,20,minecraft:coal_ore,3,minecraft:gold_ore,1,minecraft:basalt[axis=y],100)
RB(4,77,10,minecraft:air,20,minecraft:coal_ore,3,minecraft:gold_ore,1,minecraft:basalt[axis=y],100)
RB(10,77,10,minecraft:air,20,minecraft:coal_ore,3,minecraft:gold_ore,1,minecraft:basalt[axis=y],100)
RB(13,77,10,minecraft:air,20,minecraft:coal_ore,3,minecraft:gold_ore,1,minecraft:basalt[axis=y],100)
RB(14,77,10,minecraft:air,20,minecraft:coal_ore,3,minecraft:gold_ore,1,minecraft:basalt[axis=y],100)
RB(3,77,11,minecraft:air,20,minecraft:coal_ore,3,minecraft:gold_ore,1,minecraft:basalt[axis=y],100)
RB(4,77,11,minecraft:air,20,minecraft:coal_ore,3,minecraft:gold_ore,1,minecraft:basalt[axis=y],100)
RB(8,77,11,minecraft:air,20,minecraft:coal_ore,3,minecraft:gold_ore,1,minecraft:basalt[axis=y],100)
RB(9,77,11,minecraft:air,20,minecraft:coal_ore,3,minecraft:gold_ore,1,minecraft:basalt[axis=y],100)
RB(10,77,11,minecraft:air,20,minecraft:coal_ore,3,minecraft:gold_ore,1,minecraft:basalt[axis=y],100)
RB(13,77,11,minecraft:air,20,minecraft:coal_ore,3,minecraft:gold_ore,1,minecraft:basalt[axis=y],100)
RB(15,77,11,minecraft:air,20,minecraft:coal_ore,3,minecraft:gold_ore,1,minecraft:basalt[axis=y],100)
RB(4,77,12,minecraft:air,20,minecraft:coal_ore,3,minecraft:gold_ore,1,minecraft:basalt[axis=y],100)
RB(5,77,12,minecraft:air,20,minecraft:coal_ore,3,minecraft:gold_ore,1,minecraft:basalt[axis=y],100)
RB(14,77,12,minecraft:air,20,minecraft:coal_ore,3,minecraft:gold_ore,1,minecraft:basalt[axis=y],100)
RB(15,77,12,minecraft:air,20,minecraft:coal_ore,3,minecraft:gold_ore,1,minecraft:basalt[axis=y],100)
RB(13,77,13,minecraft:air,20,minecraft:coal_ore,3,minecraft:gold_ore,1,minecraft:basalt[axis=y],100)
RB(12,77,14,minecraft:air,20,minecraft:coal_ore,3,minecraft:gold_ore,1,minecraft:basalt[axis=y],100)
RB(14,77,15,minecraft:air,20,minecraft:coal_ore,3,minecraft:gold_ore,1,minecraft:basalt[axis=y],100)
B(5,78,0,minecraft:crimson_stem[axis=y])
B(9,78,0,minecraft:blackstone)
B(10,78,0,minecraft:blackstone)
B(11,78,0,minecraft:blackstone)
B(12,78,0,minecraft:crimson_stem[axis=y])
B(11,78,1,minecraft:blackstone)
B(11,78,3,minecraft:crimson_stem[axis=y])
B(12,78,3,minecraft:crimson_stem[axis=y])
RB(15,78,5,minecraft:air,20,minecraft:coal_ore,3,minecraft:gold_ore,1,minecraft:basalt[axis=y],100)
RB(13,78,6,minecraft:air,20,minecraft:coal_ore,3,minecraft:gold_ore,1,minecraft:basalt[axis=y],100)
RB(15,78,6,minecraft:air,20,minecraft:coal_ore,3,minecraft:gold_ore,1,minecraft:basalt[axis=y],100)
B(5,78,7,minecraft:crimson_stem[axis=y])
B(8,78,7,minecraft:crimson_stem[axis=y])
RB(12,78,7,minecraft:air,20,minecraft:coal_ore,3,minecraft:gold_ore,1,minecraft:basalt[axis=y],100)
RB(13,78,7,minecraft:air,20,minecraft:coal_ore,3,minecraft:gold_ore,1,minecraft:basalt[axis=y],100)
RB(15,78,7,minecraft:air,20,minecraft:coal_ore,3,minecraft:gold_ore,1,minecraft:basalt[axis=y],100)
RB(2,78,8,minecraft:air,20,minecraft:coal_ore,3,minecraft:gold_ore,1,minecraft:basalt[axis=y],100)
RB(3,78,8,minecraft:air,20,minecraft:coal_ore,3,minecraft:gold_ore,1,minecraft:basalt[axis=y],100)
B(4,78,8,minecraft:crimson_stem[axis=y])
B(5,78,8,minecraft:crimson_stem[axis=y])
RB(8,78,8,minecraft:air,20,minecraft:coal_ore,3,minecraft:gold_ore,1,minecraft:basalt[axis=y],100)
RB(9,78,8,minecraft:air,20,minecraft:coal_ore,3,minecraft:gold_ore,1,minecraft:basalt[axis=y],100)
RB(12,78,8,minecraft:air,20,minecraft:coal_ore,3,minecraft:gold_ore,1,minecraft:basalt[axis=y],100)
RB(13,78,8,minecraft:air,20,minecraft:coal_ore,3,minecraft:gold_ore,1,minecraft:basalt[axis=y],100)
RB(14,78,8,minecraft:air,20,minecraft:coal_ore,3,minecraft:gold_ore,1,minecraft:basalt[axis=y],100)
B(3,78,9,minecraft:crimson_stem[axis=y])
B(4,78,9,minecraft:crimson_stem[axis=y])
RB(5,78,9,minecraft:air,20,minecraft:coal_ore,3,minecraft:gold_ore,1,minecraft:basalt[axis=y],100)
RB(9,78,9,minecraft:air,20,minecraft:coal_ore,3,minecraft:gold_ore,1,minecraft:basalt[axis=y],100)
B(12,78,9,minecraft:crimson_stem[axis=y])
RB(13,78,9,minecraft:air,20,minecraft:coal_ore,3,minecraft:gold_ore,1,minecraft:basalt[axis=y],100)
RB(0,78,10,minecraft:air,20,minecraft:coal_ore,3,minecraft:gold_ore,1,minecraft:basalt[axis=y],100)
RB(1,78,10,minecraft:air,20,minecraft:coal_ore,3,minecraft:gold_ore,1,minecraft:basalt[axis=y],100)
B(2,78,10,minecraft:crimson_stem[axis=y])
RB(3,78,10,minecraft:air,20,minecraft:coal_ore,3,minecraft:gold_ore,1,minecraft:basalt[axis=y],100)
RB(6,78,10,minecraft:air,20,minecraft:coal_ore,3,minecraft:gold_ore,1,minecraft:basalt[axis=y],100)
RB(10,78,10,minecraft:air,20,minecraft:coal_ore,3,minecraft:gold_ore,1,minecraft:basalt[axis=y],100)
RB(11,78,10,minecraft:air,20,minecraft:coal_ore,3,minecraft:gold_ore,1,minecraft:basalt[axis=y],100)
B(12,78,10,minecraft:crimson_stem[axis=y])
RB(13,78,10,minecraft:air,20,minecraft:coal_ore,3,minecraft:gold_ore,1,minecraft:basalt[axis=y],100)
RB(14,78,10,minecraft:air,20,minecraft:coal_ore,3,minecraft:gold_ore,1,minecraft:basalt[axis=y],100)
B(0,78,11,minecraft:basalt[axis=z])
RB(3,78,11,minecraft:air,20,minecraft:coal_ore,3,minecraft:gold_ore,1,minecraft:basalt[axis=y],100)
RB(4,78,11,minecraft:air,20,minecraft:coal_ore,3,minecraft:gold_ore,1,minecraft:basalt[axis=y],100)
RB(5,78,11,minecraft:air,20,minecraft:coal_ore,3,minecraft:gold_ore,1,minecraft:basalt[axis=y],100)
RB(8,78,11,minecraft:air,20,minecraft:coal_ore,3,minecraft:gold_ore,1,minecraft:basalt[axis=y],100)
RB(9,78,11,minecraft:air,20,minecraft:coal_ore,3,minecraft:gold_ore,1,minecraft:basalt[axis=y],100)
B(12,78,11,minecraft:crimson_stem[axis=y])
B(13,78,11,minecraft:crimson_stem[axis=y])
RB(2,78,12,minecraft:air,20,minecraft:coal_ore,3,minecraft:gold_ore,1,minecraft:basalt[axis=y],100)
RB(9,78,12,minecraft:air,20,minecraft:coal_ore,3,minecraft:gold_ore,1,minecraft:basalt[axis=y],100)
B(12,78,12,minecraft:crimson_stem[axis=y])
B(14,78,12,minecraft:crimson_stem[axis=y])
RB(15,78,12,minecraft:air,20,minecraft:coal_ore,3,minecraft:gold_ore,1,minecraft:basalt[axis=y],100)
RB(4,78,13,minecraft:air,20,minecraft:coal_ore,3,minecraft:gold_ore,1,minecraft:basalt[axis=y],100)
RB(5,78,13,minecraft:air,20,minecraft:coal_ore,3,minecraft:gold_ore,1,minecraft:basalt[axis=y],100)
RB(9,78,13,minecraft:air,20,minecraft:coal_ore,3,minecraft:gold_ore,1,minecraft:basalt[axis=y],100)
RB(10,78,13,minecraft:air,20,minecraft:coal_ore,3,minecraft:gold_ore,1,minecraft:basalt[axis=y],100)
RB(11,78,13,minecraft:air,20,minecraft:coal_ore,3,minecraft:gold_ore,1,minecraft:basalt[axis=y],100)
B(12,78,13,minecraft:crimson_stem[axis=y])
RB(13,78,13,minecraft:air,20,minecraft:coal_ore,3,minecraft:gold_ore,1,minecraft:basalt[axis=y],100)
B(14,78,13,minecraft:crimson_stem[axis=y])
RB(15,78,13,minecraft:air,20,minecraft:coal_ore,3,minecraft:gold_ore,1,minecraft:basalt[axis=y],100)
RB(5,78,14,minecraft:air,20,minecraft:coal_ore,3,minecraft:gold_ore,1,minecraft:basalt[axis=y],100)
RB(9,78,14,minecraft:air,20,minecraft:coal_ore,3,minecraft:gold_ore,1,minecraft:basalt[axis=y],100)
RB(11,78,14,minecraft:air,20,minecraft:coal_ore,3,minecraft:gold_ore,1,minecraft:basalt[axis=y],100)
RB(12,78,14,minecraft:air,20,minecraft:coal_ore,3,minecraft:gold_ore,1,minecraft:basalt[axis=y],100)
RB(13,78,14,minecraft:air,20,minecraft:coal_ore,3,minecraft:gold_ore,1,minecraft:basalt[axis=y],100)
RB(15,78,14,minecraft:air,20,minecraft:coal_ore,3,minecraft:gold_ore,1,minecraft:basalt[axis=y],100)
RB(7,78,15,minecraft:air,20,minecraft:coal_ore,3,minecraft:gold_ore,1,minecraft:basalt[axis=y],100)
B(5,79,0,minecraft:crimson_stem[axis=y])
B(9,79,0,minecraft:blackstone)
B(10,79,0,minecraft:blackstone)
B(11,79,0,minecraft:crimson_stem[axis=y])
B(12,79,0,minecraft:crimson_stem[axis=y])
B(10,79,1,minecraft:crimson_stem[axis=y])
B(11,79,1,minecraft:crimson_stem[axis=y])
B(13,79,3,minecraft:crimson_stem[axis=y])
B(14,79,3,minecraft:crimson_stem[axis=y])
B(15,79,3,minecraft:crimson_stem[axis=y])
RB(13,79,7,minecraft:air,20,minecraft:coal_ore,3,minecraft:gold_ore,1,minecraft:basalt[axis=y],100)
RB(14,79,7,minecraft:air,20,minecraft:coal_ore,3,minecraft:gold_ore,1,minecraft:basalt[axis=y],100)
RB(15,79,7,minecraft:air,20,minecraft:coal_ore,3,minecraft:gold_ore,1,minecraft:basalt[axis=y],100)
RB(3,79,8,minecraft:air,20,minecraft:coal_ore,3,minecraft:gold_ore,1,minecraft:basalt[axis=y],100)
B(8,79,8,minecraft:crimson_stem[axis=y])
RB(9,79,8,minecraft:air,20,minecraft:coal_ore,3,minecraft:gold_ore,1,minecraft:basalt[axis=y],100)
RB(15,79,8,minecraft:air,20,minecraft:coal_ore,3,minecraft:gold_ore,1,minecraft:basalt[axis=y],100)
RB(1,79,9,minecraft:air,20,minecraft:coal_ore,3,minecraft:gold_ore,1,minecraft:basalt[axis=y],100)
RB(2,79,9,minecraft:air,20,minecraft:coal_ore,3,minecraft:gold_ore,1,minecraft:basalt[axis=y],100)
RB(3,79,9,minecraft:air,20,minecraft:coal_ore,3,minecraft:gold_ore,1,minecraft:basalt[axis=y],100)
B(4,79,9,minecraft:crimson_stem[axis=y])
RB(7,79,9,minecraft:air,20,minecraft:coal_ore,3,minecraft:gold_ore,1,minecraft:basalt[axis=y],100)
B(8,79,9,minecraft:crimson_stem[axis=y])
B(9,79,9,minecraft:crimson_stem[axis=y])
RB(13,79,9,minecraft:air,20,minecraft:coal_ore,3,minecraft:gold_ore,1,minecraft:basalt[axis=y],100)
RB(0,79,10,minecraft:air,20,minecraft:coal_ore,3,minecraft:gold_ore,1,minecraft:basalt[axis=y],100)
RB(2,79,10,minecraft:air,20,minecraft:coal_ore,3,minecraft:gold_ore,1,minecraft:basalt[axis=y],100)
RB(3,79,10,minecraft:air,20,minecraft:coal_ore,3,minecraft:gold_ore,1,minecraft:basalt[axis=y],100)
B(4,79,10,minecraft:crimson_stem[axis=y])
RB(5,79,10,minecraft:air,20,minecraft:coal_ore,3,minecraft:gold_ore,1,minecraft:basalt[axis=y],100)
B(7,79,10,minecraft:crimson_stem[axis=y])
B(9,79,10,minecraft:crimson_stem[axis=y])
RB(11,79,10,minecraft:air,20,minecraft:coal_ore,3,minecraft:gold_ore,1,minecraft:basalt[axis=y],100)
B(0,79,11,minecraft:basalt[axis=z])
B(4,79,11,minecraft:crimson_stem[axis=y])
B(7,79,11,minecraft:crimson_stem[axis=y])
RB(9,79,11,minecraft:air,20,minecraft:coal_ore,3,minecraft:gold_ore,1,minecraft:basalt[axis=y],100)
RB(15,79,11,minecraft:air,20,minecraft:coal_ore,3,minecraft:gold_ore,1,minecraft:basalt[axis=y],100)
RB(3,79,12,minecraft:air,20,minecraft:coal_ore,3,minecraft:gold_ore,1,minecraft:basalt[axis=y],100)
RB(6,79,12,minecraft:air,20,minecraft:coal_ore,3,minecraft:gold_ore,1,minecraft:basalt[axis=y],100)
B(7,79,12,minecraft:crimson_stem[axis=y])
RB(8,79,12,minecraft:air,20,minecraft:coal_ore,3,minecraft:gold_ore,1,minecraft:basalt[axis=y],100)
RB(11,79,12,minecraft:air,20,minecraft:coal_ore,3,minecraft:gold_ore,1,minecraft:basalt[axis=y],100)
RB(13,79,12,minecraft:air,20,minecraft:coal_ore,3,minecraft:gold_ore,1,minecraft:basalt[axis=y],100)
RB(15,79,12,minecraft:air,20,minecraft:coal_ore,3,minecraft:gold_ore,1,minecraft:basalt[axis=y],100)
RB(3,79,13,minecraft:air,20,minecraft:coal_ore,3,minecraft:gold_ore,1,minecraft:basalt[axis=y],100)
RB(4,79,13,minecraft:air,20,minecraft:coal_ore,3,minecraft:gold_ore,1,minecraft:basalt[axis=y],100)
RB(5,79,13,minecraft:air,20,minecraft:coal_ore,3,minecraft:gold_ore,1,minecraft:basalt[axis=y],100)
B(6,79,13,minecraft:crimson_stem[axis=y])
RB(7,79,13,minecraft:air,20,minecraft:coal_ore,3,minecraft:gold_ore,1,minecraft:basalt[axis=y],100)
RB(8,79,13,minecraft:air,20,minecraft:coal_ore,3,minecraft:gold_ore,1,minecraft:basalt[axis=y],100)
RB(10,79,13,minecraft:air,20,minecraft:coal_ore,3,minecraft:gold_ore,1,minecraft:basalt[axis=y],100)
RB(11,79,13,minecraft:air,20,minecraft:coal_ore,3,minecraft:gold_ore,1,minecraft:basalt[axis=y],100)
RB(13,79,13,minecraft:air,20,minecraft:coal_ore,3,minecraft:gold_ore,1,minecraft:basalt[axis=y],100)
RB(15,79,13,minecraft:air,20,minecraft:coal_ore,3,minecraft:gold_ore,1,minecraft:basalt[axis=y],100)
RB(4,79,14,minecraft:air,20,minecraft:coal_ore,3,minecraft:gold_ore,1,minecraft:basalt[axis=y],100)
RB(6,79,14,minecraft:air,20,minecraft:coal_ore,3,minecraft:gold_ore,1,minecraft:basalt[axis=y],100)
RB(7,79,14,minecraft:air,20,minecraft:coal_ore,3,minecraft:gold_ore,1,minecraft:basalt[axis=y],100)
RB(8,79,14,minecraft:air,20,minecraft:coal_ore,3,minecraft:gold_ore,1,minecraft:basalt[axis=y],100)
RB(10,79,14,minecraft:air,20,minecraft:coal_ore,3,minecraft:gold_ore,1,minecraft:basalt[axis=y],100)
RB(13,79,14,minecraft:air,20,minecraft:coal_ore,3,minecraft:gold_ore,1,minecraft:basalt[axis=y],100)
RB(15,79,14,minecraft:air,20,minecraft:coal_ore,3,minecraft:gold_ore,1,minecraft:basalt[axis=y],100)
RB(4,79,15,minecraft:air,20,minecraft:coal_ore,3,minecraft:gold_ore,1,minecraft:basalt[axis=y],100)
RB(5,79,15,minecraft:air,20,minecraft:coal_ore,3,minecraft:gold_ore,1,minecraft:basalt[axis=y],100)
RB(6,79,15,minecraft:air,20,minecraft:coal_ore,3,minecraft:gold_ore,1,minecraft:basalt[axis=y],100)
B(5,80,0,minecraft:crimson_stem[axis=y])
B(9,80,0,minecraft:blackstone)
B(10,80,0,minecraft:blackstone)
B(11,80,0,minecraft:crimson_stem[axis=y])
B(12,80,0,minecraft:crimson_stem[axis=y])
B(10,80,1,minecraft:blackstone)
B(11,80,1,minecraft:crimson_stem[axis=y])
RB(15,80,5,minecraft:air,20,minecraft:coal_ore,3,minecraft:gold_ore,1,minecraft:basalt[axis=y],100)
RB(8,80,8,minecraft:air,20,minecraft:coal_ore,3,minecraft:gold_ore,1,minecraft:basalt[axis=y],100)
RB(10,80,8,minecraft:air,20,minecraft:coal_ore,3,minecraft:gold_ore,1,minecraft:basalt[axis=y],100)
RB(1,80,9,minecraft:air,20,minecraft:coal_ore,3,minecraft:gold_ore,1,minecraft:basalt[axis=y],100)
RB(3,80,9,minecraft:air,20,minecraft:coal_ore,3,minecraft:gold_ore,1,minecraft:basalt[axis=y],100)
RB(4,80,9,minecraft:air,20,minecraft:coal_ore,3,minecraft:gold_ore,1,minecraft:basalt[axis=y],100)
RB(8,80,9,minecraft:air,20,minecraft:coal_ore,3,minecraft:gold_ore,1,minecraft:basalt[axis=y],100)
RB(10,80,9,minecraft:air,20,minecraft:coal_ore,3,minecraft:gold_ore,1,minecraft:basalt[axis=y],100)
RB(11,80,9,minecraft:air,20,minecraft:coal_ore,3,minecraft:gold_ore,1,minecraft:basalt[axis=y],100)
RB(2,80,10,minecraft:air,20,minecraft:coal_ore,3,minecraft:gold_ore,1,minecraft:basalt[axis=y],100)
RB(10,80,10,minecraft:air,20,minecraft:coal_ore,3,minecraft:gold_ore,1,minecraft:basalt[axis=y],100)
RB(6,80,11,minecraft:air,20,minecraft:coal_ore,3,minecraft:gold_ore,1,minecraft:basalt[axis=y],100)
RB(8,80,11,minecraft:air,20,minecraft:coal_ore,3,minecraft:gold_ore,1,minecraft:basalt[axis=y],100)
B(10,80,11,minecraft:crimson_stem[axis=y])
RB(3,80,12,minecraft:air,20,minecraft:coal_ore,3,minecraft:gold_ore,1,minecraft:basalt[axis=y],100)
RB(4,80,12,minecraft:air,20,minecraft:coal_ore,3,minecraft:gold_ore,1,minecraft:basalt[axis=y],100)
RB(5,80,12,minecraft:air,20,minecraft:coal_ore,3,minecraft:gold_ore,1,minecraft:basalt[axis=y],100)
B(10,80,12,minecraft:crimson_stem[axis=y])
RB(14,80,12,minecraft:air,20,minecraft:coal_ore,3,minecraft:gold_ore,1,minecraft:basalt[axis=y],100)
RB(4,80,13,minecraft:air,20,minecraft:coal_ore,3,minecraft:gold_ore,1,minecraft:basalt[axis=y],100)
RB(6,80,13,minecraft:air,20,minecraft:coal_ore,3,minecraft:gold_ore,1,minecraft:basalt[axis=y],100)
B(8,80,13,minecraft:crimson_stem[axis=y])
RB(9,80,13,minecraft:air,20,minecraft:coal_ore,3,minecraft:gold_ore,1,minecraft:basalt[axis=y],100)
B(10,80,13,minecraft:crimson_stem[axis=y])
RB(11,80,13,minecraft:air,20,minecraft:coal_ore,3,minecraft:gold_ore,1,minecraft:basalt[axis=y],100)
B(6,80,14,minecraft:crimson_stem[axis=y])
B(8,80,14,minecraft:crimson_stem[axis=y])
B(10,80,14,minecraft:crimson_stem[axis=y])
RB(4,80,15,minecraft:air,20,minecraft:coal_ore,3,minecraft:gold_ore,1,minecraft:basalt[axis=y],100)
B(6,80,15,minecraft:crimson_stem[axis=y])
RB(8,80,15,minecraft:air,20,minecraft:coal_ore,3,minecraft:gold_ore,1,minecraft:basalt[axis=y],100)
RB(9,80,15,minecraft:air,20,minecraft:coal_ore,3,minecraft:gold_ore,1,minecraft:basalt[axis=y],100)
RB(11,80,15,minecraft:air,20,minecraft:coal_ore,3,minecraft:gold_ore,1,minecraft:basalt[axis=y],100)
B(4,81,0,minecraft:crimson_stem[axis=y])
B(9,81,0,minecraft:blackstone)
B(10,81,0,minecraft:blackstone)
B(11,81,0,minecraft:crimson_stem[axis=y])
B(12,81,0,minecraft:crimson_stem[axis=y])
B(10,81,1,minecraft:crimson_stem[axis=y])
B(11,81,1,minecraft:crimson_stem[axis=y])
RB(9,81,9,minecraft:air,20,minecraft:coal_ore,3,minecraft:gold_ore,1,minecraft:basalt[axis=y],100)
RB(10,81,9,minecraft:air,20,minecraft:coal_ore,3,minecraft:gold_ore,1,minecraft:basalt[axis=y],100)
RB(3,81,10,minecraft:air,20,minecraft:coal_ore,3,minecraft:gold_ore,1,minecraft:basalt[axis=y],100)
RB(4,81,10,minecraft:air,20,minecraft:coal_ore,3,minecraft:gold_ore,1,minecraft:basalt[axis=y],100)
RB(8,81,10,minecraft:air,20,minecraft:coal_ore,3,minecraft:gold_ore,1,minecraft:basalt[axis=y],100)
RB(4,81,11,minecraft:air,20,minecraft:coal_ore,3,minecraft:gold_ore,1,minecraft:basalt[axis=y],100)
RB(5,81,11,minecraft:air,20,minecraft:coal_ore,3,minecraft:gold_ore,1,minecraft:basalt[axis=y],100)
RB(9,81,11,minecraft:air,20,minecraft:coal_ore,3,minecraft:gold_ore,1,minecraft:basalt[axis=y],100)
RB(4,81,12,minecraft:air,20,minecraft:coal_ore,3,minecraft:gold_ore,1,minecraft:basalt[axis=y],100)
RB(5,81,12,minecraft:air,20,minecraft:coal_ore,3,minecraft:gold_ore,1,minecraft:basalt[axis=y],100)
RB(10,81,12,minecraft:air,20,minecraft:coal_ore,3,minecraft:gold_ore,1,minecraft:basalt[axis=y],100)
RB(11,81,12,minecraft:air,20,minecraft:coal_ore,3,minecraft:gold_ore,1,minecraft:basalt[axis=y],100)
RB(5,81,13,minecraft:air,20,minecraft:coal_ore,3,minecraft:gold_ore,1,minecraft:basalt[axis=y],100)
RB(8,81,13,minecraft:air,20,minecraft:coal_ore,3,minecraft:gold_ore,1,minecraft:basalt[axis=y],100)
RB(11,81,13,minecraft:air,20,minecraft:coal_ore,3,minecraft:gold_ore,1,minecraft:basalt[axis=y],100)
RB(12,81,13,minecraft:air,20,minecraft:coal_ore,3,minecraft:gold_ore,1,minecraft:basalt[axis=y],100)
RB(6,81,14,minecraft:air,20,minecraft:coal_ore,3,minecraft:gold_ore,1,minecraft:basalt[axis=y],100)
RB(8,81,14,minecraft:air,20,minecraft:coal_ore,3,minecraft:gold_ore,1,minecraft:basalt[axis=y],100)
RB(9,81,14,minecraft:air,20,minecraft:coal_ore,3,minecraft:gold_ore,1,minecraft:basalt[axis=y],100)
RB(11,81,14,minecraft:air,20,minecraft:coal_ore,3,minecraft:gold_ore,1,minecraft:basalt[axis=y],100)
RB(4,81,15,minecraft:air,20,minecraft:coal_ore,3,minecraft:gold_ore,1,minecraft:basalt[axis=y],100)
RB(7,81,15,minecraft:air,20,minecraft:coal_ore,3,minecraft:gold_ore,1,minecraft:basalt[axis=y],100)
RB(8,81,15,minecraft:air,20,minecraft:coal_ore,3,minecraft:gold_ore,1,minecraft:basalt[axis=y],100)
RB(12,81,15,minecraft:air,20,minecraft:coal_ore,3,minecraft:gold_ore,1,minecraft:basalt[axis=y],100)
B(4,82,0,minecraft:crimson_stem[axis=y])
B(10,82,0,minecraft:blackstone)
B(11,82,0,minecraft:crimson_stem[axis=y])
B(12,82,0,minecraft:crimson_stem[axis=y])
B(10,82,1,minecraft:blackstone)
B(11,82,1,minecraft:blackstone)
B(10,82,2,minecraft:blackstone)
RB(9,82,13,minecraft:air,20,minecraft:coal_ore,3,minecraft:gold_ore,1,minecraft:basalt[axis=y],100)
RB(11,82,13,minecraft:air,20,minecraft:coal_ore,3,minecraft:gold_ore,1,minecraft:basalt[axis=y],100)
RB(9,82,14,minecraft:air,20,minecraft:coal_ore,3,minecraft:gold_ore,1,minecraft:basalt[axis=y],100)
RB(10,82,14,minecraft:air,20,minecraft:coal_ore,3,minecraft:gold_ore,1,minecraft:basalt[axis=y],100)
RB(6,82,15,minecraft:air,20,minecraft:coal_ore,3,minecraft:gold_ore,1,minecraft:basalt[axis=y],100)
RB(7,82,15,minecraft:air,20,minecraft:coal_ore,3,minecraft:gold_ore,1,minecraft:basalt[axis=y],100)
RB(9,82,15,minecraft:air,20,minecraft:coal_ore,3,minecraft:gold_ore,1,minecraft:basalt[axis=y],100)
RB(10,82,15,minecraft:air,20,minecraft:coal_ore,3,minecraft:gold_ore,1,minecraft:basalt[axis=y],100)
B(4,83,0,minecraft:smooth_basalt)
B(10,83,0,minecraft:blackstone)
B(11,83,0,minecraft:blackstone)
B(12,83,0,minecraft:crimson_stem[axis=y])
B(10,83,1,minecraft:blackstone)
B(11,83,1,minecraft:blackstone)
B(10,83,2,minecraft:blackstone)
B(3,84,0,minecraft:smooth_basalt)
B(4,84,0,minecraft:smooth_basalt)
B(11,84,0,minecraft:blackstone)
B(12,84,0,minecraft:blackstone)
RB(13,84,0,minecraft:air,20,minecraft:coal_ore,3,minecraft:gold_ore,1,minecraft:basalt[axis=y],100)
RB(14,84,0,minecraft:air,20,minecraft:coal_ore,3,minecraft:gold_ore,1,minecraft:basalt[axis=y],100)
B(10,84,1,minecraft:blackstone)
B(11,84,1,minecraft:blackstone)
B(9,84,2,minecraft:blackstone)
B(10,84,2,minecraft:blackstone)
B(10,84,3,minecraft:blackstone)
B(4,85,0,minecraft:smooth_basalt)
B(11,85,0,minecraft:blackstone)
B(12,85,0,minecraft:blackstone)
B(13,85,0,minecraft:crimson_stem[axis=y])
B(14,85,0,minecraft:crimson_stem[axis=y])
RB(15,85,0,minecraft:air,20,minecraft:coal_ore,3,minecraft:gold_ore,1,minecraft:basalt[axis=y],100)
B(9,85,2,minecraft:blackstone)
B(10,85,2,minecraft:blackstone)
RB(15,85,2,minecraft:air,20,minecraft:coal_ore,3,minecraft:gold_ore,1,minecraft:basalt[axis=y],100)
B(10,85,3,minecraft:crimson_stem[axis=y])
B(4,86,0,minecraft:crimson_stem[axis=y])
B(11,86,0,minecraft:blackstone)
B(12,86,0,minecraft:blackstone)
RB(14,86,1,minecraft:air,20,minecraft:coal_ore,3,minecraft:gold_ore,1,minecraft:basalt[axis=y],100)
B(15,86,1,minecraft:crimson_stem[axis=y])
B(8,86,2,minecraft:blackstone)
B(9,86,2,minecraft:blackstone)
B(10,86,2,minecraft:blackstone)
B(10,86,3,minecraft:blackstone)
RB(15,86,3,minecraft:air,20,minecraft:coal_ore,3,minecraft:gold_ore,1,minecraft:basalt[axis=y],100)
B(4,87,0,minecraft:crimson_stem[axis=y])
B(11,87,0,minecraft:crimson_stem[axis=y])
B(12,87,0,minecraft:blackstone)
B(13,87,0,minecraft:crimson_stem[axis=y])
RB(14,87,0,minecraft:air,20,minecraft:coal_ore,3,minecraft:gold_ore,1,minecraft:basalt[axis=y],100)
RB(14,87,1,minecraft:air,20,minecraft:coal_ore,3,minecraft:gold_ore,1,minecraft:basalt[axis=y],100)
B(8,87,2,minecraft:blackstone)
RB(14,87,2,minecraft:air,20,minecraft:coal_ore,3,minecraft:gold_ore,1,minecraft:basalt[axis=y],100)
B(10,87,3,minecraft:crimson_stem[axis=y])
RB(6,87,8,minecraft:air,20,minecraft:coal_ore,3,minecraft:gold_ore,1,minecraft:basalt[axis=y],100)
RB(7,87,8,minecraft:air,20,minecraft:coal_ore,3,minecraft:gold_ore,1,minecraft:basalt[axis=y],100)
RB(4,87,9,minecraft:air,20,minecraft:coal_ore,3,minecraft:gold_ore,1,minecraft:basalt[axis=y],100)
RB(6,87,9,minecraft:air,20,minecraft:coal_ore,3,minecraft:gold_ore,1,minecraft:basalt[axis=y],100)
RB(5,87,10,minecraft:air,20,minecraft:coal_ore,3,minecraft:gold_ore,1,minecraft:basalt[axis=y],100)
RB(7,87,10,minecraft:air,20,minecraft:coal_ore,3,minecraft:gold_ore,1,minecraft:basalt[axis=y],100)
B(4,88,0,minecraft:crimson_stem[axis=y])
B(11,88,0,minecraft:crimson_stem[axis=y])
B(12,88,0,minecraft:crimson_stem[axis=y])
B(13,88,0,minecraft:crimson_stem[axis=y])
RB(3,88,1,minecraft:air,20,minecraft:coal_ore,3,minecraft:gold_ore,1,minecraft:basalt[axis=y],100)
B(4,88,1,minecraft:crimson_stem[axis=y])
RB(15,88,1,minecraft:air,20,minecraft:coal_ore,3,minecraft:gold_ore,1,minecraft:basalt[axis=y],100)
RB(1,88,2,minecraft:air,20,minecraft:coal_ore,3,minecraft:gold_ore,1,minecraft:basalt[axis=y],100)
RB(2,88,2,minecraft:air,20,minecraft:coal_ore,3,minecraft:gold_ore,1,minecraft:basalt[axis=y],100)
RB(3,88,2,minecraft:air,20,minecraft:coal_ore,3,minecraft:gold_ore,1,minecraft:basalt[axis=y],100)
B(4,88,2,minecraft:crimson_stem[axis=y])
B(8,88,3,minecraft:crimson_stem[axis=y])
B(10,88,3,minecraft:crimson_stem[axis=y])
B(10,88,4,minecraft:crimson_stem[axis=y])
RB(1,88,7,minecraft:air,20,minecraft:coal_ore,3,minecraft:gold_ore,1,minecraft:basalt[axis=y],100)
RB(7,88,7,minecraft:air,20,minecraft:coal_ore,3,minecraft:gold_ore,1,minecraft:basalt[axis=y],100)
RB(4,88,8,minecraft:air,20,minecraft:coal_ore,3,minecraft:gold_ore,1,minecraft:basalt[axis=y],100)
RB(5,88,8,minecraft:air,20,minecraft:coal_ore,3,minecraft:gold_ore,1,minecraft:basalt[axis=y],100)
RB(3,88,9,minecraft:air,20,minecraft:coal_ore,3,minecraft:gold_ore,1,minecraft:basalt[axis=y],100)
RB(4,88,9,minecraft:air,20,minecraft:coal_ore,3,minecraft:gold_ore,1,minecraft:basalt[axis=y],100)
RB(8,88,9,minecraft:air,20,minecraft:coal_ore,3,minecraft:gold_ore,1,minecraft:basalt[axis=y],100)
RB(2,88,10,minecraft:air,20,minecraft:coal_ore,3,minecraft:gold_ore,1,minecraft:basalt[axis=y],100)
RB(4,88,10,minecraft:air,20,minecraft:coal_ore,3,minecraft:gold_ore,1,minecraft:basalt[axis=y],100)
RB(5,88,10,minecraft:air,20,minecraft:coal_ore,3,minecraft:gold_ore,1,minecraft:basalt[axis=y],100)
RB(8,88,10,minecraft:air,20,minecraft:coal_ore,3,minecraft:gold_ore,1,minecraft:basalt[axis=y],100)
RB(9,88,10,minecraft:air,20,minecraft:coal_ore,3,minecraft:gold_ore,1,minecraft:basalt[axis=y],100)
RB(10,88,10,minecraft:air,20,minecraft:coal_ore,3,minecraft:gold_ore,1,minecraft:basalt[axis=y],100)
RB(11,88,10,minecraft:air,20,minecraft:coal_ore,3,minecraft:gold_ore,1,minecraft:basalt[axis=y],100)
RB(15,88,10,minecraft:air,20,minecraft:coal_ore,3,minecraft:gold_ore,1,minecraft:basalt[axis=y],100)
RB(2,88,11,minecraft:air,20,minecraft:coal_ore,3,minecraft:gold_ore,1,minecraft:basalt[axis=y],100)
RB(5,88,11,minecraft:air,20,minecraft:coal_ore,3,minecraft:gold_ore,1,minecraft:basalt[axis=y],100)
RB(6,88,11,minecraft:air,20,minecraft:coal_ore,3,minecraft:gold_ore,1,minecraft:basalt[axis=y],100)
RB(7,88,11,minecraft:air,20,minecraft:coal_ore,3,minecraft:gold_ore,1,minecraft:basalt[axis=y],100)
RB(11,88,11,minecraft:air,20,minecraft:coal_ore,3,minecraft:gold_ore,1,minecraft:basalt[axis=y],100)
RB(15,88,11,minecraft:air,20,minecraft:coal_ore,3,minecraft:gold_ore,1,minecraft:basalt[axis=y],100)
RB(4,88,12,minecraft:air,20,minecraft:coal_ore,3,minecraft:gold_ore,1,minecraft:basalt[axis=y],100)
RB(5,88,12,minecraft:air,20,minecraft:coal_ore,3,minecraft:gold_ore,1,minecraft:basalt[axis=y],100)
RB(10,88,12,minecraft:air,20,minecraft:coal_ore,3,minecraft:gold_ore,1,minecraft:basalt[axis=y],100)
RB(1,89,0,minecraft:air,20,minecraft:coal_ore,3,minecraft:gold_ore,1,minecraft:basalt[axis=y],100)
RB(2,89,0,minecraft:air,20,minecraft:coal_ore,3,minecraft:gold_ore,1,minecraft:basalt[axis=y],100)
RB(3,89,0,minecraft:air,20,minecraft:coal_ore,3,minecraft:gold_ore,1,minecraft:basalt[axis=y],100)
B(11,89,0,minecraft:crimson_stem[axis=y])
B(12,89,0,minecraft:blackstone)
B(13,89,0,minecraft:blackstone)
RB(0,89,2,minecraft:air,20,minecraft:coal_ore,3,minecraft:gold_ore,1,minecraft:basalt[axis=y],100)
RB(3,89,2,minecraft:air,20,minecraft:coal_ore,3,minecraft:gold_ore,1,minecraft:basalt[axis=y],100)
B(4,89,2,minecraft:crimson_stem[axis=y])
B(5,89,2,minecraft:crimson_stem[axis=y])
RB(0,89,3,minecraft:air,20,minecraft:coal_ore,3,minecraft:gold_ore,1,minecraft:basalt[axis=y],100)
B(6,89,3,minecraft:crimson_stem[axis=y])
B(8,89,3,minecraft:crimson_stem[axis=y])
RB(1,89,4,minecraft:air,20,minecraft:coal_ore,3,minecraft:gold_ore,1,minecraft:basalt[axis=y],100)
RB(2,89,4,minecraft:air,20,minecraft:coal_ore,3,minecraft:gold_ore,1,minecraft:basalt[axis=y],100)
B(10,89,4,minecraft:crimson_stem[axis=y])
RB(0,89,5,minecraft:air,20,minecraft:coal_ore,3,minecraft:gold_ore,1,minecraft:basalt[axis=y],100)
RB(2,89,5,minecraft:air,20,minecraft:coal_ore,3,minecraft:gold_ore,1,minecraft:basalt[axis=y],100)
RB(0,89,6,minecraft:air,20,minecraft:coal_ore,3,minecraft:gold_ore,1,minecraft:basalt[axis=y],100)
RB(1,89,6,minecraft:air,20,minecraft:coal_ore,3,minecraft:gold_ore,1,minecraft:basalt[axis=y],100)
B(5,89,6,minecraft:crimson_stem[axis=y])
B(7,89,6,minecraft:crimson_stem[axis=y])
RB(2,89,7,minecraft:air,20,minecraft:coal_ore,3,minecraft:gold_ore,1,minecraft:basalt[axis=y],100)
B(5,89,7,minecraft:crimson_stem[axis=y])
B(5,89,8,minecraft:crimson_stem[axis=y])
RB(6,89,8,minecraft:air,20,minecraft:coal_ore,3,minecraft:gold_ore,1,minecraft:basalt[axis=y],100)
RB(15,89,8,minecraft:air,20,minecraft:coal_ore,3,minecraft:gold_ore,1,minecraft:basalt[axis=y],100)
RB(2,89,9,minecraft:air,20,minecraft:coal_ore,3,minecraft:gold_ore,1,minecraft:basalt[axis=y],100)
RB(3,89,9,minecraft:air,20,minecraft:coal_ore,3,minecraft:gold_ore,1,minecraft:basalt[axis=y],100)
B(4,89,9,minecraft:crimson_stem[axis=y])
B(6,89,9,minecraft:crimson_stem[axis=y])
RB(7,89,9,minecraft:air,20,minecraft:coal_ore,3,minecraft:gold_ore,1,minecraft:basalt[axis=y],100)
RB(10,89,9,minecraft:air,20,minecraft:coal_ore,3,minecraft:gold_ore,1,minecraft:basalt[axis=y],100)
RB(15,89,9,minecraft:air,20,minecraft:coal_ore,3,minecraft:gold_ore,1,minecraft:basalt[axis=y],100)
RB(3,89,10,minecraft:air,20,minecraft:coal_ore,3,minecraft:gold_ore,1,minecraft:basalt[axis=y],100)
RB(6,89,10,minecraft:air,20,minecraft:coal_ore,3,minecraft:gold_ore,1,minecraft:basalt[axis=y],100)
RB(9,89,10,minecraft:air,20,minecraft:coal_ore,3,minecraft:gold_ore,1,minecraft:basalt[axis=y],100)
RB(10,89,10,minecraft:air,20,minecraft:coal_ore,3,minecraft:gold_ore,1,minecraft:basalt[axis=y],100)
RB(11,89,10,minecraft:air,20,minecraft:coal_ore,3,minecraft:gold_ore,1,minecraft:basalt[axis=y],100)
RB(14,89,10,minecraft:air,20,minecraft:coal_ore,3,minecraft:gold_ore,1,minecraft:basalt[axis=y],100)
RB(2,89,11,minecraft:air,20,minecraft:coal_ore,3,minecraft:gold_ore,1,minecraft:basalt[axis=y],100)
RB(3,89,11,minecraft:air,20,minecraft:coal_ore,3,minecraft:gold_ore,1,minecraft:basalt[axis=y],100)
RB(5,89,11,minecraft:air,20,minecraft:coal_ore,3,minecraft:gold_ore,1,minecraft:basalt[axis=y],100)
RB(6,89,11,minecraft:air,20,minecraft:coal_ore,3,minecraft:gold_ore,1,minecraft:basalt[axis=y],100)
RB(10,89,11,minecraft:air,20,minecraft:coal_ore,3,minecraft:gold_ore,1,minecraft:basalt[axis=y],100)
RB(12,89,11,minecraft:air,20,minecraft:coal_ore,3,minecraft:gold_ore,1,minecraft:basalt[axis=y],100)
RB(5,89,12,minecraft:air,20,minecraft:coal_ore,3,minecraft:gold_ore,1,minecraft:basalt[axis=y],100)
RB(9,89,12,minecraft:air,20,minecraft:coal_ore,3,minecraft:gold_ore,1,minecraft:basalt[axis=y],100)
RB(11,89,12,minecraft:air,20,minecraft:coal_ore,3,minecraft:gold_ore,1,minecraft:basalt[axis=y],100)
RB(0,90,0,minecraft:air,20,minecraft:coal_ore,3,minecraft:gold_ore,1,minecraft:basalt[axis=y],100)
B(12,90,0,minecraft:blackstone)
B(13,90,0,minecraft:blackstone)
RB(0,90,1,minecraft:air,20,minecraft:coal_ore,3,minecraft:gold_ore,1,minecraft:basalt[axis=y],100)
RB(1,90,1,minecraft:air,20,minecraft:coal_ore,3,minecraft:gold_ore,1,minecraft:basalt[axis=y],100)
RB(3,90,1,minecraft:air,20,minecraft:coal_ore,3,minecraft:gold_ore,1,minecraft:basalt[axis=y],100)
B(2,90,2,minecraft:crimson_stem[axis=y])
B(3,90,2,minecraft:crimson_stem[axis=y])
RB(1,90,3,minecraft:air,20,minecraft:coal_ore,3,minecraft:gold_ore,1,minecraft:basalt[axis=y],100)
B(3,90,3,minecraft:crimson_stem[axis=y])
RB(4,90,3,minecraft:air,20,minecraft:coal_ore,3,minecraft:gold_ore,1,minecraft:basalt[axis=y],100)
B(8,90,3,minecraft:crimson_stem[axis=y])
RB(1,90,4,minecraft:air,20,minecraft:coal_ore,3,minecraft:gold_ore,1,minecraft:basalt[axis=y],100)
B(3,90,4,minecraft:crimson_stem[axis=y])
B(6,90,4,minecraft:crimson_stem[axis=y])
B(10,90,4,minecraft:crimson_stem[axis=y])
B(11,90,4,minecraft:crimson_stem[axis=y])
B(1,90,5,minecraft:crimson_stem[axis=y])
B(2,90,5,minecraft:crimson_stem[axis=y])
B(6,90,5,minecraft:crimson_stem[axis=y])
B(11,90,5,minecraft:crimson_stem[axis=y])
B(15,90,5,minecraft:crimson_stem[axis=y])
B(0,90,6,minecraft:crimson_stem[axis=y])
B(3,90,6,minecraft:crimson_stem[axis=y])
B(6,90,6,minecraft:crimson_stem[axis=y])
B(11,90,6,minecraft:crimson_stem[axis=y])
B(14,90,6,minecraft:crimson_stem[axis=y])
RB(6,90,7,minecraft:air,20,minecraft:coal_ore,3,minecraft:gold_ore,1,minecraft:basalt[axis=y],100)
B(15,90,7,minecraft:crimson_stem[axis=y])
RB(1,90,8,minecraft:air,20,minecraft:coal_ore,3,minecraft:gold_ore,1,minecraft:basalt[axis=y],100)
RB(3,90,8,minecraft:air,20,minecraft:coal_ore,3,minecraft:gold_ore,1,minecraft:basalt[axis=y],100)
RB(4,90,8,minecraft:air,20,minecraft:coal_ore,3,minecraft:gold_ore,1,minecraft:basalt[axis=y],100)
RB(5,90,8,minecraft:air,20,minecraft:coal_ore,3,minecraft:gold_ore,1,minecraft:basalt[axis=y],100)
RB(6,90,8,minecraft:air,20,minecraft:coal_ore,3,minecraft:gold_ore,1,minecraft:basalt[axis=y],100)
RB(15,90,8,minecraft:air,20,minecraft:coal_ore,3,minecraft:gold_ore,1,minecraft:basalt[axis=y],100)
RB(3,90,9,minecraft:air,20,minecraft:coal_ore,3,minecraft:gold_ore,1,minecraft:basalt[axis=y],100)
RB(4,90,9,minecraft:air,20,minecraft:coal_ore,3,minecraft:gold_ore,1,minecraft:basalt[axis=y],100)
RB(5,90,9,minecraft:air,20,minecraft:coal_ore,3,minecraft:gold_ore,1,minecraft:basalt[axis=y],100)
RB(7,90,9,minecraft:air,20,minecraft:coal_ore,3,minecraft:gold_ore,1,minecraft:basalt[axis=y],100)
RB(14,90,9,minecraft:air,20,minecraft:coal_ore,3,minecraft:gold_ore,1,minecraft:basalt[axis=y],100)
RB(4,90,10,minecraft:air,20,minecraft:coal_ore,3,minecraft:gold_ore,1,minecraft:basalt[axis=y],100)
RB(7,90,10,minecraft:air,20,minecraft:coal_ore,3,minecraft:gold_ore,1,minecraft:basalt[axis=y],100)
B(10,90,10,minecraft:crimson_stem[axis=y])
RB(3,90,11,minecraft:air,20,minecraft:coal_ore,3,minecraft:gold_ore,1,minecraft:basalt[axis=y],100)
RB(4,90,11,minecraft:air,20,minecraft:coal_ore,3,minecraft:gold_ore,1,minecraft:basalt[axis=y],100)
RB(5,90,11,minecraft:air,20,minecraft:coal_ore,3,minecraft:gold_ore,1,minecraft:basalt[axis=y],100)
RB(6,90,11,minecraft:air,20,minecraft:coal_ore,3,minecraft:gold_ore,1,minecraft:basalt[axis=y],100)
RB(7,90,11,minecraft:air,20,minecraft:coal_ore,3,minecraft:gold_ore,1,minecraft:basalt[axis=y],100)
B(10,90,11,minecraft:crimson_stem[axis=y])
RB(11,90,11,minecraft:air,20,minecraft:coal_ore,3,minecraft:gold_ore,1,minecraft:basalt[axis=y],100)
RB(12,90,11,minecraft:air,20,minecraft:coal_ore,3,minecraft:gold_ore,1,minecraft:basalt[axis=y],100)
RB(15,90,11,minecraft:air,20,minecraft:coal_ore,3,minecraft:gold_ore,1,minecraft:basalt[axis=y],100)
RB(4,90,12,minecraft:air,20,minecraft:coal_ore,3,minecraft:gold_ore,1,minecraft:basalt[axis=y],100)
RB(5,90,12,minecraft:air,20,minecraft:coal_ore,3,minecraft:gold_ore,1,minecraft:basalt[axis=y],100)
RB(9,90,12,minecraft:air,20,minecraft:coal_ore,3,minecraft:gold_ore,1,minecraft:basalt[axis=y],100)
RB(10,90,12,minecraft:air,20,minecraft:coal_ore,3,minecraft:gold_ore,1,minecraft:basalt[axis=y],100)
RB(11,90,12,minecraft:air,20,minecraft:coal_ore,3,minecraft:gold_ore,1,minecraft:basalt[axis=y],100)
RB(12,90,12,minecraft:air,20,minecraft:coal_ore,3,minecraft:gold_ore,1,minecraft:basalt[axis=y],100)
RB(15,90,12,minecraft:air,20,minecraft:coal_ore,3,minecraft:gold_ore,1,minecraft:basalt[axis=y],100)
RB(0,91,0,minecraft:air,20,minecraft:coal_ore,3,minecraft:gold_ore,1,minecraft:basalt[axis=y],100)
RB(1,91,0,minecraft:air,20,minecraft:coal_ore,3,minecraft:gold_ore,1,minecraft:basalt[axis=y],100)
RB(2,91,0,minecraft:air,20,minecraft:coal_ore,3,minecraft:gold_ore,1,minecraft:basalt[axis=y],100)
B(12,91,0,minecraft:blackstone)
B(13,91,0,minecraft:blackstone)
RB(0,91,1,minecraft:air,20,minecraft:coal_ore,3,minecraft:gold_ore,1,minecraft:basalt[axis=y],100)
B(3,91,2,minecraft:crimson_stem[axis=y])
RB(4,91,2,minecraft:air,20,minecraft:coal_ore,3,minecraft:gold_ore,1,minecraft:basalt[axis=y],100)
RB(0,91,3,minecraft:air,20,minecraft:coal_ore,3,minecraft:gold_ore,1,minecraft:basalt[axis=y],100)
RB(2,91,3,minecraft:air,20,minecraft:coal_ore,3,minecraft:gold_ore,1,minecraft:basalt[axis=y],100)
RB(3,91,3,minecraft:air,20,minecraft:coal_ore,3,minecraft:gold_ore,1,minecraft:basalt[axis=y],100)
RB(0,91,4,minecraft:air,20,minecraft:coal_ore,3,minecraft:gold_ore,1,minecraft:basalt[axis=y],100)
RB(2,91,4,minecraft:air,20,minecraft:coal_ore,3,minecraft:gold_ore,1,minecraft:basalt[axis=y],100)
RB(3,91,4,minecraft:air,20,minecraft:coal_ore,3,minecraft:gold_ore,1,minecraft:basalt[axis=y],100)
B(8,91,4,minecraft:crimson_stem[axis=y])
B(12,91,4,minecraft:crimson_stem[axis=y])
RB(0,91,5,minecraft:air,20,minecraft:coal_ore,3,minecraft:gold_ore,1,minecraft:basalt[axis=y],100)
RB(1,91,5,minecraft:air,20,minecraft:coal_ore,3,minecraft:gold_ore,1,minecraft:basalt[axis=y],100)
RB(0,91,6,minecraft:air,20,minecraft:coal_ore,3,minecraft:gold_ore,1,minecraft:basalt[axis=y],100)
RB(1,91,6,minecraft:air,20,minecraft:coal_ore,3,minecraft:gold_ore,1,minecraft:basalt[axis=y],100)
RB(2,91,6,minecraft:air,20,minecraft:coal_ore,3,minecraft:gold_ore,1,minecraft:basalt[axis=y],100)
B(11,91,6,minecraft:crimson_stem[axis=y])
RB(0,91,7,minecraft:air,20,minecraft:coal_ore,3,minecraft:gold_ore,1,minecraft:basalt[axis=y],100)
RB(2,91,7,minecraft:air,20,minecraft:coal_ore,3,minecraft:gold_ore,1,minecraft:basalt[axis=y],100)
B(11,91,7,minecraft:crimson_stem[axis=y])
RB(14,91,7,minecraft:air,20,minecraft:coal_ore,3,minecraft:gold_ore,1,minecraft:basalt[axis=y],100)
RB(15,91,7,minecraft:air,20,minecraft:coal_ore,3,minecraft:gold_ore,1,minecraft:basalt[axis=y],100)
RB(0,91,8,minecraft:air,20,minecraft:coal_ore,3,minecraft:gold_ore,1,minecraft:basalt[axis=y],100)
RB(1,91,8,minecraft:air,20,minecraft:coal_ore,3,minecraft:gold_ore,1,minecraft:basalt[axis=y],100)
RB(5,91,8,minecraft:air,20,minecraft:coal_ore,3,minecraft:gold_ore,1,minecraft:basalt[axis=y],100)
RB(6,91,8,minecraft:air,20,minecraft:coal_ore,3,minecraft:gold_ore,1,minecraft:basalt[axis=y],100)
RB(7,91,8,minecraft:air,20,minecraft:coal_ore,3,minecraft:gold_ore,1,minecraft:basalt[axis=y],100)
B(11,91,8,minecraft:crimson_stem[axis=y])
RB(14,91,8,minecraft:air,20,minecraft:coal_ore,3,minecraft:gold_ore,1,minecraft:basalt[axis=y],100)
RB(15,91,8,minecraft:air,20,minecraft:coal_ore,3,minecraft:gold_ore,1,minecraft:basalt[axis=y],100)
RB(10,91,9,minecraft:air,20,minecraft:coal_ore,3,minecraft:gold_ore,1,minecraft:basalt[axis=y],100)
B(11,91,9,minecraft:crimson_stem[axis=y])
RB(4,91,10,minecraft:air,20,minecraft:coal_ore,3,minecraft:gold_ore,1,minecraft:basalt[axis=y],100)
RB(6,91,10,minecraft:air,20,minecraft:coal_ore,3,minecraft:gold_ore,1,minecraft:basalt[axis=y],100)
RB(8,91,10,minecraft:air,20,minecraft:coal_ore,3,minecraft:gold_ore,1,minecraft:basalt[axis=y],100)
B(12,91,10,minecraft:crimson_stem[axis=y])
RB(4,91,11,minecraft:air,20,minecraft:coal_ore,3,minecraft:gold_ore,1,minecraft:basalt[axis=y],100)
RB(7,91,11,minecraft:air,20,minecraft:coal_ore,3,minecraft:gold_ore,1,minecraft:basalt[axis=y],100)
RB(9,91,11,minecraft:air,20,minecraft:coal_ore,3,minecraft:gold_ore,1,minecraft:basalt[axis=y],100)
RB(10,91,11,minecraft:air,20,minecraft:coal_ore,3,minecraft:gold_ore,1,minecraft:basalt[axis=y],100)
RB(15,91,11,minecraft:air,20,minecraft:coal_ore,3,minecraft:gold_ore,1,minecraft:basalt[axis=y],100)
RB(8,91,12,minecraft:air,20,minecraft:coal_ore,3,minecraft:gold_ore,1,minecraft:basalt[axis=y],100)
RB(10,91,12,minecraft:air,20,minecraft:coal_ore,3,minecraft:gold_ore,1,minecraft:basalt[axis=y],100)
RB(15,91,12,minecraft:air,20,minecraft:coal_ore,3,minecraft:gold_ore,1,minecraft:basalt[axis=y],100)
RB(11,91,13,minecraft:air,20,minecraft:coal_ore,3,minecraft:gold_ore,1,minecraft:basalt[axis=y],100)
RB(0,92,0,minecraft:air,20,minecraft:coal_ore,3,minecraft:gold_ore,1,minecraft:basalt[axis=y],100)
B(11,92,0,minecraft:crimson_stem[axis=y])
B(13,92,0,minecraft:crimson_stem[axis=y])
RB(1,92,1,minecraft:air,20,minecraft:coal_ore,3,minecraft:gold_ore,1,minecraft:basalt[axis=y],100)
RB(2,92,1,minecraft:air,20,minecraft:coal_ore,3,minecraft:gold_ore,1,minecraft:basalt[axis=y],100)
RB(3,92,1,minecraft:air,20,minecraft:coal_ore,3,minecraft:gold_ore,1,minecraft:basalt[axis=y],100)
B(3,92,2,minecraft:blackstone)
B(13,92,3,minecraft:crimson_stem[axis=y])
B(14,92,3,minecraft:blackstone)
B(15,92,3,minecraft:blackstone)
B(8,92,4,minecraft:crimson_stem[axis=y])
RB(1,92,5,minecraft:air,20,minecraft:coal_ore,3,minecraft:gold_ore,1,minecraft:basalt[axis=y],100)
B(7,92,5,minecraft:crimson_stem[axis=y])
B(9,92,5,minecraft:crimson_stem[axis=y])
RB(0,92,6,minecraft:air,20,minecraft:coal_ore,3,minecraft:gold_ore,1,minecraft:basalt[axis=y],100)
B(7,92,6,minecraft:crimson_stem[axis=y])
RB(1,92,7,minecraft:air,20,minecraft:coal_ore,3,minecraft:gold_ore,1,minecraft:basalt[axis=y],100)
RB(14,92,7,minecraft:air,20,minecraft:coal_ore,3,minecraft:gold_ore,1,minecraft:basalt[axis=y],100)
RB(15,92,7,minecraft:air,20,minecraft:coal_ore,3,minecraft:gold_ore,1,minecraft:basalt[axis=y],100)
RB(6,92,8,minecraft:air,20,minecraft:coal_ore,3,minecraft:gold_ore,1,minecraft:basalt[axis=y],100)
RB(7,92,8,minecraft:air,20,minecraft:coal_ore,3,minecraft:gold_ore,1,minecraft:basalt[axis=y],100)
RB(5,92,9,minecraft:air,20,minecraft:coal_ore,3,minecraft:gold_ore,1,minecraft:basalt[axis=y],100)
RB(8,92,9,minecraft:air,20,minecraft:coal_ore,3,minecraft:gold_ore,1,minecraft:basalt[axis=y],100)
RB(15,92,9,minecraft:air,20,minecraft:coal_ore,3,minecraft:gold_ore,1,minecraft:basalt[axis=y],100)
RB(6,92,10,minecraft:air,20,minecraft:coal_ore,3,minecraft:gold_ore,1,minecraft:basalt[axis=y],100)
RB(8,92,10,minecraft:air,20,minecraft:coal_ore,3,minecraft:gold_ore,1,minecraft:basalt[axis=y],100)
RB(11,92,10,minecraft:air,20,minecraft:coal_ore,3,minecraft:gold_ore,1,minecraft:basalt[axis=y],100)
RB(5,92,11,minecraft:air,20,minecraft:coal_ore,3,minecraft:gold_ore,1,minecraft:basalt[axis=y],100)
RB(7,92,11,minecraft:air,20,minecraft:coal_ore,3,minecraft:gold_ore,1,minecraft:basalt[axis=y],100)
RB(8,92,11,minecraft:air,20,minecraft:coal_ore,3,minecraft:gold_ore,1,minecraft:basalt[axis=y],100)
RB(7,92,12,minecraft:air,20,minecraft:coal_ore,3,minecraft:gold_ore,1,minecraft:basalt[axis=y],100)
RB(10,92,12,minecraft:air,20,minecraft:coal_ore,3,minecraft:gold_ore,1,minecraft:basalt[axis=y],100)
RB(11,92,12,minecraft:air,20,minecraft:coal_ore,3,minecraft:gold_ore,1,minecraft:basalt[axis=y],100)
RB(12,92,12,minecraft:air,20,minecraft:coal_ore,3,minecraft:gold_ore,1,minecraft:basalt[axis=y],100)
RB(12,92,13,minecraft:air,20,minecraft:coal_ore,3,minecraft:gold_ore,1,minecraft:basalt[axis=y],100)
B(5,93,0,minecraft:crimson_stem[axis=y])
B(7,93,0,minecraft:blackstone)
B(11,93,0,minecraft:crimson_stem[axis=y])
B(13,93,0,minecraft:blackstone)
B(2,93,2,minecraft:blackstone)
RB(15,93,5,minecraft:air,20,minecraft:coal_ore,3,minecraft:gold_ore,1,minecraft:basalt[axis=y],100)
B(9,93,6,minecraft:crimson_stem[axis=y])
RB(14,93,6,minecraft:air,20,minecraft:coal_ore,3,minecraft:gold_ore,1,minecraft:basalt[axis=y],100)
