
#######################################################################
# +-----------------------------------------------------------------+ #
# |                            BO4 object                           | #
# +-----------------------------------------------------------------+ #
#######################################################################

Author: Unknown

Description: No description given

SettingsMode: WriteWithoutComments


#######################################################################
# +-----------------------------------------------------------------+ #
# |                          Main settings                          | #
# +-----------------------------------------------------------------+ #
#######################################################################

FixedRotation: 

Frequency: 0

SpawnHeight: highestBlock

UseCenterForHighestBlock: true

##############################
# Height Limits for the BO4. #
##############################

MinHeight: 0

MaxHeight: 255

InheritBO3: 

InheritBO3Rotation: NORTH

OverrideChildSettings: true

OverrideParentHeight: false

CanOverride: false

BranchFrequency: 0

BranchFrequencyGroup: 

MustBeBelowOther: false

MustBeInside: 

CannotBeInside: 

ReplacesBO3: 

MustBeInsideWorldBorders: false

CanSpawnOnWater: true

SpawnOnWaterOnly: false

SpawnUnderWater: false

SpawnAtWaterLevel: false

HeightOffset: 0

RemoveAir: true

ReplaceAbove: 

ReplaceBelow: 

ReplaceWithBiomeBlocks: true

ReplaceWithSurfaceBlock: GRASS

ReplaceWithGroundBlock: DIRT

ReplaceWithStoneBlock: STONE

SmoothRadius: 0

SmoothHeightOffset: 0

SmoothStartTop: false

SmoothStartWood: false

SmoothingSurfaceBlock: 

SmoothingGroundBlock: 

BO3Group: 

IsSpawnPoint: false

DoReplaceBlocks: true


#######################################################################
# +-----------------------------------------------------------------+ #
# |                              Blocks                             | #
# +-----------------------------------------------------------------+ #
#######################################################################

B(-4,0,-7,minecraft:netherrack)
B(-4,1,-7,minecraft:netherrack)
B(-3,0,-7,minecraft:netherrack)
B(-3,1,-7,minecraft:netherrack)
B(-3,2,-7,minecraft:netherrack)
B(-3,3,-7,minecraft:netherrack)
B(-3,4,-7,minecraft:netherrack)
B(-3,5,-7,minecraft:netherrack)
B(-3,6,-7,minecraft:netherrack)
B(-3,7,-7,minecraft:netherrack)
B(-3,8,-7,minecraft:netherrack)
B(-3,9,-7,minecraft:netherrack)
B(-3,10,-7,minecraft:netherrack)
B(-3,11,-7,minecraft:netherrack)
B(-3,0,-6,minecraft:netherrack)
B(-3,1,-6,minecraft:netherrack)
B(-3,2,-6,minecraft:netherrack)
B(-3,3,-6,minecraft:netherrack)
B(-3,4,-6,minecraft:netherrack)
B(-3,0,-3,minecraft:netherrack)
B(-2,0,-7,minecraft:netherrack)
B(-2,1,-7,minecraft:netherrack)
B(-2,2,-7,minecraft:netherrack)
B(-2,3,-7,minecraft:netherrack)
B(-2,4,-7,minecraft:netherrack)
B(-2,5,-7,minecraft:netherrack)
B(-2,6,-7,minecraft:netherrack)
B(-2,7,-7,minecraft:netherrack)
B(-2,8,-7,minecraft:netherrack)
B(-2,9,-7,minecraft:netherrack)
B(-2,10,-7,minecraft:netherrack)
B(-2,11,-7,minecraft:netherrack)
B(-2,12,-7,minecraft:netherrack)
B(-2,13,-7,minecraft:netherrack)
B(-2,14,-7,minecraft:netherrack)
B(-2,15,-7,minecraft:netherrack)
B(-2,16,-7,minecraft:netherrack)
B(-2,17,-7,minecraft:netherrack)
B(-2,18,-7,minecraft:netherrack)
B(-2,0,-6,minecraft:netherrack)
B(-2,1,-6,minecraft:netherrack)
B(-2,2,-6,minecraft:netherrack)
B(-2,3,-6,minecraft:netherrack)
B(-2,4,-6,minecraft:netherrack)
B(-2,5,-6,minecraft:netherrack)
B(-2,6,-6,minecraft:netherrack)
B(-2,7,-6,minecraft:netherrack)
B(-2,8,-6,minecraft:netherrack)
B(-2,9,-6,minecraft:netherrack)
B(-2,0,-5,minecraft:netherrack)
B(-2,1,-5,minecraft:netherrack)
B(-2,2,-5,minecraft:netherrack)
B(-2,3,-5,minecraft:netherrack)
B(-2,4,-5,minecraft:netherrack)
B(-2,0,-4,minecraft:netherrack)
B(-2,0,-3,minecraft:netherrack)
B(-1,0,-7,minecraft:netherrack)
B(-1,1,-7,minecraft:netherrack)
B(-1,2,-7,minecraft:netherrack)
B(-1,3,-7,minecraft:netherrack)
B(-1,4,-7,minecraft:netherrack)
B(-1,5,-7,minecraft:netherrack)
B(-1,6,-7,minecraft:netherrack)
B(-1,7,-7,minecraft:netherrack)
B(-1,8,-7,minecraft:netherrack)
B(-1,9,-7,minecraft:netherrack)
B(-1,10,-7,minecraft:netherrack)
B(-1,11,-7,minecraft:netherrack)
B(-1,12,-7,minecraft:netherrack)
B(-1,13,-7,minecraft:netherrack)
B(-1,14,-7,minecraft:netherrack)
B(-1,15,-7,minecraft:netherrack)
B(-1,16,-7,minecraft:netherrack)
B(-1,17,-7,minecraft:netherrack)
B(-1,18,-7,minecraft:netherrack)
B(-1,0,-6,minecraft:netherrack)
B(-1,1,-6,minecraft:netherrack)
B(-1,2,-6,minecraft:netherrack)
B(-1,3,-6,minecraft:netherrack)
B(-1,4,-6,minecraft:netherrack)
B(-1,5,-6,minecraft:netherrack)
B(-1,6,-6,minecraft:netherrack)
B(-1,7,-6,minecraft:netherrack)
B(-1,8,-6,minecraft:netherrack)
B(-1,9,-6,minecraft:netherrack)
B(-1,10,-6,minecraft:netherrack)
B(-1,11,-6,minecraft:netherrack)
B(-1,12,-6,minecraft:netherrack)
B(-1,13,-6,minecraft:netherrack)
B(-1,14,-6,minecraft:netherrack)
B(-1,15,-6,minecraft:netherrack)
B(-1,16,-6,minecraft:netherrack)
B(-1,0,-5,minecraft:netherrack)
B(-1,1,-5,minecraft:netherrack)
B(-1,2,-5,minecraft:netherrack)
B(-1,3,-5,minecraft:netherrack)
B(-1,4,-5,minecraft:netherrack)
B(-1,5,-5,minecraft:netherrack)
B(-1,6,-5,minecraft:netherrack)
B(-1,7,-5,minecraft:netherrack)
B(-1,0,-4,minecraft:netherrack)
B(-1,1,-4,minecraft:netherrack)
B(-1,2,-4,minecraft:netherrack)
B(-1,3,-4,minecraft:netherrack)
B(-1,0,-3,minecraft:netherrack)
B(0,0,-7,minecraft:netherrack)
B(0,1,-7,minecraft:netherrack)
B(0,2,-7,minecraft:netherrack)
B(0,3,-7,minecraft:netherrack)
B(0,4,-7,minecraft:netherrack)
B(0,5,-7,minecraft:netherrack)
B(0,6,-7,minecraft:netherrack)
B(0,7,-7,minecraft:netherrack)
B(0,8,-7,minecraft:netherrack)
B(0,9,-7,minecraft:netherrack)
B(0,10,-7,minecraft:netherrack)
B(0,11,-7,minecraft:netherrack)
B(0,12,-7,minecraft:netherrack)
B(0,13,-7,minecraft:netherrack)
B(0,14,-7,minecraft:netherrack)
B(0,15,-7,minecraft:netherrack)
B(0,16,-7,minecraft:netherrack)
B(0,17,-7,minecraft:netherrack)
B(0,18,-7,minecraft:netherrack)
B(0,0,-6,minecraft:netherrack)
B(0,1,-6,minecraft:netherrack)
B(0,2,-6,minecraft:netherrack)
B(0,3,-6,minecraft:netherrack)
B(0,4,-6,minecraft:netherrack)
B(0,5,-6,minecraft:netherrack)
B(0,6,-6,minecraft:netherrack)
B(0,7,-6,minecraft:netherrack)
B(0,8,-6,minecraft:netherrack)
B(0,9,-6,minecraft:netherrack)
B(0,10,-6,minecraft:netherrack)
B(0,11,-6,minecraft:netherrack)
B(0,12,-6,minecraft:netherrack)
B(0,13,-6,minecraft:netherrack)
B(0,14,-6,minecraft:netherrack)
B(0,15,-6,minecraft:netherrack)
B(0,16,-6,minecraft:netherrack)
B(0,17,-6,minecraft:netherrack)
B(0,0,-5,minecraft:netherrack)
B(0,1,-5,minecraft:netherrack)
B(0,2,-5,minecraft:netherrack)
B(0,3,-5,minecraft:netherrack)
B(0,4,-5,minecraft:netherrack)
B(0,5,-5,minecraft:netherrack)
B(0,6,-5,minecraft:netherrack)
B(0,7,-5,minecraft:netherrack)
B(0,8,-5,minecraft:netherrack)
B(0,0,-4,minecraft:netherrack)
B(0,1,-4,minecraft:netherrack)
B(0,2,-4,minecraft:netherrack)
B(0,3,-4,minecraft:netherrack)
B(0,4,-4,minecraft:netherrack)
B(0,5,-4,minecraft:netherrack)
B(0,0,-3,minecraft:netherrack)
B(1,0,-7,minecraft:netherrack)
B(1,1,-7,minecraft:netherrack)
B(1,2,-7,minecraft:netherrack)
B(1,3,-7,minecraft:netherrack)
B(1,4,-7,minecraft:netherrack)
B(1,5,-7,minecraft:netherrack)
B(1,6,-7,minecraft:netherrack)
B(1,7,-7,minecraft:netherrack)
B(1,8,-7,minecraft:netherrack)
B(1,9,-7,minecraft:netherrack)
B(1,10,-7,minecraft:netherrack)
B(1,11,-7,minecraft:netherrack)
B(1,12,-7,minecraft:netherrack)
B(1,13,-7,minecraft:netherrack)
B(1,14,-7,minecraft:netherrack)
B(1,15,-7,minecraft:netherrack)
B(1,16,-7,minecraft:netherrack)
B(1,17,-7,minecraft:netherrack)
B(1,18,-7,minecraft:netherrack)
B(1,0,-6,minecraft:netherrack)
B(1,1,-6,minecraft:netherrack)
B(1,2,-6,minecraft:netherrack)
B(1,3,-6,minecraft:netherrack)
B(1,4,-6,minecraft:netherrack)
B(1,5,-6,minecraft:netherrack)
B(1,6,-6,minecraft:netherrack)
B(1,7,-6,minecraft:netherrack)
B(1,8,-6,minecraft:netherrack)
B(1,9,-6,minecraft:netherrack)
B(1,10,-6,minecraft:netherrack)
B(1,11,-6,minecraft:netherrack)
B(1,12,-6,minecraft:netherrack)
B(1,13,-6,minecraft:netherrack)
B(1,14,-6,minecraft:netherrack)
B(1,15,-6,minecraft:netherrack)
B(1,16,-6,minecraft:netherrack)
B(1,17,-6,minecraft:netherrack)
B(1,0,-5,minecraft:netherrack)
B(1,1,-5,minecraft:netherrack)
B(1,2,-5,minecraft:netherrack)
B(1,3,-5,minecraft:netherrack)
B(1,4,-5,minecraft:netherrack)
B(1,5,-5,minecraft:netherrack)
B(1,6,-5,minecraft:netherrack)
B(1,7,-5,minecraft:netherrack)
B(1,8,-5,minecraft:netherrack)
B(1,0,-4,minecraft:netherrack)
B(1,1,-4,minecraft:netherrack)
B(1,2,-4,minecraft:netherrack)
B(1,3,-4,minecraft:netherrack)
B(1,4,-4,minecraft:netherrack)
B(1,5,-4,minecraft:netherrack)
B(1,6,-4,minecraft:netherrack)
B(1,0,-3,minecraft:netherrack)
B(2,0,-7,minecraft:netherrack)
B(2,1,-7,minecraft:netherrack)
B(2,2,-7,minecraft:netherrack)
B(2,3,-7,minecraft:netherrack)
B(2,4,-7,minecraft:netherrack)
B(2,5,-7,minecraft:netherrack)
B(2,6,-7,minecraft:netherrack)
B(2,7,-7,minecraft:netherrack)
B(2,8,-7,minecraft:netherrack)
B(2,9,-7,minecraft:netherrack)
B(2,10,-7,minecraft:netherrack)
B(2,11,-7,minecraft:netherrack)
B(2,12,-7,minecraft:netherrack)
B(2,13,-7,minecraft:netherrack)
B(2,14,-7,minecraft:netherrack)
B(2,15,-7,minecraft:netherrack)
B(2,16,-7,minecraft:netherrack)
B(2,17,-7,minecraft:netherrack)
B(2,18,-7,minecraft:netherrack)
B(2,0,-6,minecraft:netherrack)
B(2,1,-6,minecraft:netherrack)
B(2,2,-6,minecraft:netherrack)
B(2,3,-6,minecraft:netherrack)
B(2,4,-6,minecraft:netherrack)
B(2,5,-6,minecraft:netherrack)
B(2,6,-6,minecraft:netherrack)
B(2,7,-6,minecraft:netherrack)
B(2,8,-6,minecraft:netherrack)
B(2,9,-6,minecraft:netherrack)
B(2,10,-6,minecraft:netherrack)
B(2,11,-6,minecraft:netherrack)
B(2,12,-6,minecraft:netherrack)
B(2,13,-6,minecraft:netherrack)
B(2,14,-6,minecraft:netherrack)
B(2,15,-6,minecraft:netherrack)
B(2,0,-5,minecraft:netherrack)
B(2,1,-5,minecraft:netherrack)
B(2,2,-5,minecraft:netherrack)
B(2,3,-5,minecraft:netherrack)
B(2,4,-5,minecraft:netherrack)
B(2,5,-5,minecraft:netherrack)
B(2,6,-5,minecraft:netherrack)
B(2,7,-5,minecraft:netherrack)
B(2,8,-5,minecraft:netherrack)
B(2,0,-4,minecraft:netherrack)
B(2,1,-4,minecraft:netherrack)
B(2,2,-4,minecraft:netherrack)
B(2,3,-4,minecraft:netherrack)
B(2,4,-4,minecraft:netherrack)
B(2,5,-4,minecraft:netherrack)
B(2,6,-4,minecraft:netherrack)
B(2,7,-4,minecraft:netherrack)
B(2,0,-3,minecraft:netherrack)
B(3,0,-7,minecraft:netherrack)
B(3,1,-7,minecraft:netherrack)
B(3,2,-7,minecraft:netherrack)
B(3,3,-7,minecraft:netherrack)
B(3,4,-7,minecraft:netherrack)
B(3,5,-7,minecraft:netherrack)
B(3,6,-7,minecraft:netherrack)
B(3,7,-7,minecraft:netherrack)
B(3,8,-7,minecraft:netherrack)
B(3,9,-7,minecraft:netherrack)
B(3,10,-7,minecraft:netherrack)
B(3,11,-7,minecraft:netherrack)
B(3,12,-7,minecraft:netherrack)
B(3,13,-7,minecraft:netherrack)
B(3,14,-7,minecraft:netherrack)
B(3,15,-7,minecraft:netherrack)
B(3,16,-7,minecraft:netherrack)
B(3,17,-7,minecraft:netherrack)
B(3,0,-6,minecraft:netherrack)
B(3,1,-6,minecraft:netherrack)
B(3,2,-6,minecraft:netherrack)
B(3,3,-6,minecraft:netherrack)
B(3,4,-6,minecraft:netherrack)
B(3,5,-6,minecraft:netherrack)
B(3,6,-6,minecraft:netherrack)
B(3,7,-6,minecraft:netherrack)
B(3,8,-6,minecraft:netherrack)
B(3,9,-6,minecraft:netherrack)
B(3,10,-6,minecraft:netherrack)
B(3,11,-6,minecraft:netherrack)
B(3,0,-5,minecraft:netherrack)
B(3,1,-5,minecraft:netherrack)
B(3,2,-5,minecraft:netherrack)
B(3,3,-5,minecraft:netherrack)
B(3,4,-5,minecraft:netherrack)
B(3,5,-5,minecraft:netherrack)
B(3,6,-5,minecraft:netherrack)
B(3,7,-5,minecraft:netherrack)
B(3,8,-5,minecraft:netherrack)
B(3,0,-4,minecraft:netherrack)
B(3,1,-4,minecraft:netherrack)
B(3,2,-4,minecraft:netherrack)
B(3,3,-4,minecraft:netherrack)
B(3,4,-4,minecraft:netherrack)
B(3,5,-4,minecraft:netherrack)
B(3,0,-3,minecraft:blackstone)
B(3,1,-3,minecraft:netherrack)
B(4,0,-7,minecraft:netherrack)
B(4,1,-7,minecraft:netherrack)
B(4,2,-7,minecraft:netherrack)
B(4,3,-7,minecraft:netherrack)
B(4,4,-7,minecraft:netherrack)
B(4,5,-7,minecraft:netherrack)
B(4,6,-7,minecraft:netherrack)
B(4,7,-7,minecraft:netherrack)
B(4,8,-7,minecraft:netherrack)
B(4,9,-7,minecraft:netherrack)
B(4,10,-7,minecraft:netherrack)
B(4,11,-7,minecraft:netherrack)
B(4,12,-7,minecraft:netherrack)
B(4,0,-6,minecraft:netherrack)
B(4,1,-6,minecraft:netherrack)
B(4,2,-6,minecraft:netherrack)
B(4,3,-6,minecraft:netherrack)
B(4,4,-6,minecraft:netherrack)
B(4,5,-6,minecraft:netherrack)
B(4,6,-6,minecraft:netherrack)
B(4,7,-6,minecraft:netherrack)
B(4,8,-6,minecraft:netherrack)
B(4,0,-5,minecraft:netherrack)
B(4,1,-5,minecraft:netherrack)
B(4,2,-5,minecraft:netherrack)
B(4,3,-5,minecraft:netherrack)
B(4,4,-5,minecraft:netherrack)
B(4,5,-5,minecraft:netherrack)
B(4,6,-5,minecraft:netherrack)
B(4,7,-5,minecraft:netherrack)
B(4,0,-4,minecraft:netherrack)
B(4,1,-4,minecraft:netherrack)
B(4,2,-4,minecraft:netherrack)
B(4,0,-3,minecraft:blackstone)
B(4,1,-3,minecraft:netherrack)
B(5,0,-7,minecraft:netherrack)
B(5,1,-7,minecraft:netherrack)
B(5,2,-7,minecraft:netherrack)
B(5,3,-7,minecraft:netherrack)
B(5,4,-7,minecraft:netherrack)
B(5,5,-7,minecraft:netherrack)
B(5,6,-7,minecraft:netherrack)
B(5,7,-7,minecraft:netherrack)
B(5,8,-7,minecraft:netherrack)
B(5,0,-6,minecraft:netherrack)
B(5,1,-6,minecraft:netherrack)
B(5,2,-6,minecraft:netherrack)
B(5,3,-6,minecraft:netherrack)
B(5,4,-6,minecraft:netherrack)
B(5,5,-6,minecraft:netherrack)
B(5,6,-6,minecraft:netherrack)
B(5,7,-6,minecraft:netherrack)
B(5,0,-5,minecraft:netherrack)
B(5,1,-5,minecraft:netherrack)
B(5,2,-5,minecraft:netherrack)
B(5,3,-5,minecraft:netherrack)
B(5,0,-4,minecraft:netherrack)
B(5,1,-4,minecraft:netherrack)
B(5,0,-3,minecraft:blackstone)
B(5,1,-3,minecraft:netherrack)
B(6,0,-7,minecraft:netherrack)
B(6,1,-7,minecraft:netherrack)
B(6,2,-7,minecraft:netherrack)
B(6,3,-7,minecraft:netherrack)
B(6,4,-7,minecraft:netherrack)
B(6,5,-7,minecraft:netherrack)
B(6,6,-7,minecraft:netherrack)
B(6,7,-7,minecraft:netherrack)
B(6,8,-7,minecraft:netherrack)
B(6,9,-7,minecraft:netherrack)
B(6,10,-7,minecraft:netherrack)
B(6,11,-7,minecraft:netherrack)
B(6,12,-7,minecraft:netherrack)
B(6,13,-7,minecraft:netherrack)
B(6,0,-6,minecraft:netherrack)
B(6,1,-6,minecraft:netherrack)
B(6,2,-6,minecraft:netherrack)
B(6,3,-6,minecraft:netherrack)
B(6,4,-6,minecraft:netherrack)
B(6,5,-6,minecraft:netherrack)
B(6,0,-5,minecraft:netherrack)
B(6,1,-5,minecraft:netherrack)
B(6,2,-5,minecraft:netherrack)
B(6,0,-4,minecraft:blackstone)
B(6,1,-4,minecraft:netherrack)
B(6,0,-3,minecraft:netherrack)
B(7,0,-7,minecraft:netherrack)
B(7,1,-7,minecraft:netherrack)
B(7,2,-7,minecraft:netherrack)
B(7,3,-7,minecraft:netherrack)
B(7,4,-7,minecraft:netherrack)
B(7,5,-7,minecraft:netherrack)
B(7,6,-7,minecraft:netherrack)
B(7,7,-7,minecraft:netherrack)
B(7,8,-7,minecraft:netherrack)
B(7,9,-7,minecraft:netherrack)
B(7,10,-7,minecraft:netherrack)
B(7,11,-7,minecraft:netherrack)
B(7,12,-7,minecraft:netherrack)
B(7,13,-7,minecraft:netherrack)
B(7,14,-7,minecraft:netherrack)
B(7,15,-7,minecraft:netherrack)
B(7,16,-7,minecraft:netherrack)
B(7,17,-7,minecraft:netherrack)
B(7,18,-7,minecraft:netherrack)
B(7,19,-7,minecraft:netherrack)
B(7,20,-7,minecraft:netherrack)
B(7,21,-7,minecraft:netherrack)
B(7,22,-7,minecraft:netherrack)
B(7,0,-6,minecraft:netherrack)
B(7,1,-6,minecraft:netherrack)
B(7,2,-6,minecraft:netherrack)
B(7,3,-6,minecraft:netherrack)
B(7,4,-6,minecraft:netherrack)
B(7,5,-6,minecraft:netherrack)
B(7,6,-6,minecraft:netherrack)
B(7,7,-6,minecraft:netherrack)
B(7,0,-5,minecraft:netherrack)
B(7,1,-5,minecraft:netherrack)
B(7,2,-5,minecraft:netherrack)
B(7,3,-5,minecraft:netherrack)
B(7,0,-4,minecraft:netherrack)
B(7,0,-3,minecraft:netherrack)

#######################################################################
# +-----------------------------------------------------------------+ #
# |                             Branches                            | #
# +-----------------------------------------------------------------+ #
#######################################################################

Branch(16,0,0,true,NetherrackWall1_C1_R9,NORTH,100.0,0)

#######################################################################
# +-----------------------------------------------------------------+ #
# |                             Entities                            | #
# +-----------------------------------------------------------------+ #
#######################################################################

