
#######################################################################
# +-----------------------------------------------------------------+ #
# |                            BO4 object                           | #
# +-----------------------------------------------------------------+ #
#######################################################################

Author: Unknown

Description: No description given

SettingsMode: WriteWithoutComments


#######################################################################
# +-----------------------------------------------------------------+ #
# |                          Main settings                          | #
# +-----------------------------------------------------------------+ #
#######################################################################

FixedRotation: 

Frequency: 0

SpawnHeight: highestBlock

UseCenterForHighestBlock: true

##############################
# Height Limits for the BO4. #
##############################

MinHeight: 0

MaxHeight: 255

InheritBO3: 

InheritBO3Rotation: NORTH

OverrideChildSettings: true

OverrideParentHeight: false

CanOverride: false

BranchFrequency: 0

BranchFrequencyGroup: 

MustBeBelowOther: false

MustBeInside: 

CannotBeInside: 

ReplacesBO3: 

MustBeInsideWorldBorders: false

CanSpawnOnWater: true

SpawnOnWaterOnly: false

SpawnUnderWater: false

SpawnAtWaterLevel: false

HeightOffset: 0

RemoveAir: true

ReplaceAbove: 

ReplaceBelow: 

ReplaceWithBiomeBlocks: true

ReplaceWithSurfaceBlock: GRASS

ReplaceWithGroundBlock: DIRT

ReplaceWithStoneBlock: STONE

SmoothRadius: 0

SmoothHeightOffset: 0

SmoothStartTop: false

SmoothStartWood: false

SmoothingSurfaceBlock: 

SmoothingGroundBlock: 

BO3Group: 

IsSpawnPoint: false

DoReplaceBlocks: true


#######################################################################
# +-----------------------------------------------------------------+ #
# |                              Blocks                             | #
# +-----------------------------------------------------------------+ #
#######################################################################

B(-7,0,5,minecraft:netherrack)
B(-7,0,6,minecraft:netherrack)
B(-7,1,6,minecraft:netherrack)
B(-7,2,6,minecraft:netherrack)
B(-7,3,6,minecraft:netherrack)
B(-7,0,7,minecraft:netherrack)
B(-7,1,7,minecraft:netherrack)
B(-7,2,7,minecraft:netherrack)
B(-7,3,7,minecraft:netherrack)
B(-7,0,8,minecraft:netherrack)
B(-7,1,8,minecraft:netherrack)
B(-7,2,8,minecraft:netherrack)
B(-7,3,8,minecraft:netherrack)
B(-6,0,4,minecraft:netherrack)
B(-6,1,4,minecraft:netherrack)
B(-6,2,4,minecraft:netherrack)
B(-6,0,5,minecraft:netherrack)
B(-6,1,5,minecraft:netherrack)
B(-6,2,5,minecraft:netherrack)
B(-6,3,5,minecraft:netherrack)
B(-6,4,5,minecraft:netherrack)
B(-6,0,6,minecraft:netherrack)
B(-6,1,6,minecraft:netherrack)
B(-6,2,6,minecraft:netherrack)
B(-6,3,6,minecraft:netherrack)
B(-6,4,6,minecraft:netherrack)
B(-6,5,6,minecraft:netherrack)
B(-6,0,7,minecraft:netherrack)
B(-6,1,7,minecraft:netherrack)
B(-6,2,7,minecraft:netherrack)
B(-6,3,7,minecraft:netherrack)
B(-6,4,7,minecraft:netherrack)
B(-6,5,7,minecraft:netherrack)
B(-6,6,7,minecraft:netherrack)
B(-6,7,7,minecraft:netherrack)
B(-6,8,7,minecraft:netherrack)
B(-6,0,8,minecraft:netherrack)
B(-6,1,8,minecraft:netherrack)
B(-6,2,8,minecraft:netherrack)
B(-6,3,8,minecraft:netherrack)
B(-6,4,8,minecraft:netherrack)
B(-6,5,8,minecraft:netherrack)
B(-6,6,8,minecraft:netherrack)
B(-6,7,8,minecraft:netherrack)
B(-6,8,8,minecraft:netherrack)
B(-6,9,8,minecraft:netherrack)
B(-5,0,3,minecraft:netherrack)
B(-5,1,3,minecraft:netherrack)
B(-5,2,3,minecraft:netherrack)
B(-5,0,4,minecraft:netherrack)
B(-5,1,4,minecraft:netherrack)
B(-5,2,4,minecraft:netherrack)
B(-5,3,4,minecraft:netherrack)
B(-5,4,4,minecraft:netherrack)
B(-5,0,5,minecraft:netherrack)
B(-5,1,5,minecraft:netherrack)
B(-5,2,5,minecraft:netherrack)
B(-5,3,5,minecraft:netherrack)
B(-5,4,5,minecraft:netherrack)
B(-5,5,5,minecraft:netherrack)
B(-5,6,5,minecraft:netherrack)
B(-5,0,6,minecraft:netherrack)
B(-5,1,6,minecraft:netherrack)
B(-5,2,6,minecraft:netherrack)
B(-5,3,6,minecraft:netherrack)
B(-5,4,6,minecraft:netherrack)
B(-5,5,6,minecraft:netherrack)
B(-5,6,6,minecraft:netherrack)
B(-5,7,6,minecraft:netherrack)
B(-5,8,6,minecraft:netherrack)
B(-5,9,6,minecraft:netherrack)
B(-5,10,6,minecraft:netherrack)
B(-5,0,7,minecraft:netherrack)
B(-5,1,7,minecraft:netherrack)
B(-5,2,7,minecraft:netherrack)
B(-5,3,7,minecraft:netherrack)
B(-5,4,7,minecraft:netherrack)
B(-5,5,7,minecraft:netherrack)
B(-5,6,7,minecraft:netherrack)
B(-5,7,7,minecraft:netherrack)
B(-5,8,7,minecraft:netherrack)
B(-5,9,7,minecraft:netherrack)
B(-5,10,7,minecraft:netherrack)
B(-5,11,7,minecraft:netherrack)
B(-5,0,8,minecraft:netherrack)
B(-5,1,8,minecraft:netherrack)
B(-5,2,8,minecraft:netherrack)
B(-5,3,8,minecraft:netherrack)
B(-5,4,8,minecraft:netherrack)
B(-5,5,8,minecraft:netherrack)
B(-5,6,8,minecraft:netherrack)
B(-5,7,8,minecraft:netherrack)
B(-5,8,8,minecraft:netherrack)
B(-5,9,8,minecraft:netherrack)
B(-5,10,8,minecraft:netherrack)
B(-5,11,8,minecraft:netherrack)
B(-5,12,8,minecraft:netherrack)
B(-5,13,8,minecraft:netherrack)
B(-5,14,8,minecraft:netherrack)
B(-4,0,2,minecraft:netherrack)
B(-4,0,3,minecraft:netherrack)
B(-4,1,3,minecraft:netherrack)
B(-4,2,3,minecraft:netherrack)
B(-4,3,3,minecraft:netherrack)
B(-4,4,3,minecraft:netherrack)
B(-4,0,4,minecraft:netherrack)
B(-4,1,4,minecraft:netherrack)
B(-4,2,4,minecraft:netherrack)
B(-4,3,4,minecraft:netherrack)
B(-4,4,4,minecraft:netherrack)
B(-4,5,4,minecraft:netherrack)
B(-4,6,4,minecraft:netherrack)
B(-4,0,5,minecraft:netherrack)
B(-4,1,5,minecraft:netherrack)
B(-4,2,5,minecraft:netherrack)
B(-4,3,5,minecraft:netherrack)
B(-4,4,5,minecraft:netherrack)
B(-4,5,5,minecraft:netherrack)
B(-4,6,5,minecraft:netherrack)
B(-4,7,5,minecraft:netherrack)
B(-4,8,5,minecraft:netherrack)
B(-4,9,5,minecraft:netherrack)
B(-4,0,6,minecraft:netherrack)
B(-4,1,6,minecraft:netherrack)
B(-4,2,6,minecraft:netherrack)
B(-4,3,6,minecraft:netherrack)
B(-4,4,6,minecraft:netherrack)
B(-4,5,6,minecraft:netherrack)
B(-4,6,6,minecraft:netherrack)
B(-4,7,6,minecraft:netherrack)
B(-4,8,6,minecraft:netherrack)
B(-4,9,6,minecraft:netherrack)
B(-4,10,6,minecraft:netherrack)
B(-4,11,6,minecraft:netherrack)
B(-4,12,6,minecraft:netherrack)
B(-4,0,7,minecraft:netherrack)
B(-4,1,7,minecraft:netherrack)
B(-4,2,7,minecraft:netherrack)
B(-4,3,7,minecraft:netherrack)
B(-4,4,7,minecraft:netherrack)
B(-4,5,7,minecraft:netherrack)
B(-4,6,7,minecraft:netherrack)
B(-4,7,7,minecraft:netherrack)
B(-4,8,7,minecraft:netherrack)
B(-4,9,7,minecraft:netherrack)
B(-4,10,7,minecraft:netherrack)
B(-4,11,7,minecraft:netherrack)
B(-4,12,7,minecraft:netherrack)
B(-4,13,7,minecraft:netherrack)
B(-4,14,7,minecraft:netherrack)
B(-4,15,7,minecraft:netherrack)
B(-4,16,7,minecraft:netherrack)
B(-4,0,8,minecraft:netherrack)
B(-4,1,8,minecraft:netherrack)
B(-4,2,8,minecraft:netherrack)
B(-4,3,8,minecraft:netherrack)
B(-4,4,8,minecraft:netherrack)
B(-4,5,8,minecraft:netherrack)
B(-4,6,8,minecraft:netherrack)
B(-4,7,8,minecraft:netherrack)
B(-4,8,8,minecraft:netherrack)
B(-4,9,8,minecraft:netherrack)
B(-4,10,8,minecraft:netherrack)
B(-4,11,8,minecraft:netherrack)
B(-4,12,8,minecraft:netherrack)
B(-4,13,8,minecraft:netherrack)
B(-4,14,8,minecraft:netherrack)
B(-4,15,8,minecraft:netherrack)
B(-4,16,8,minecraft:netherrack)
B(-4,17,8,minecraft:netherrack)
B(-3,0,2,minecraft:netherrack)
B(-3,1,2,minecraft:netherrack)
B(-3,0,3,minecraft:netherrack)
B(-3,1,3,minecraft:netherrack)
B(-3,2,3,minecraft:netherrack)
B(-3,3,3,minecraft:netherrack)
B(-3,0,4,minecraft:netherrack)
B(-3,1,4,minecraft:netherrack)
B(-3,2,4,minecraft:netherrack)
B(-3,3,4,minecraft:netherrack)
B(-3,4,4,minecraft:netherrack)
B(-3,5,4,minecraft:netherrack)
B(-3,6,4,minecraft:netherrack)
B(-3,7,4,minecraft:netherrack)
B(-3,8,4,minecraft:netherrack)
B(-3,0,5,minecraft:netherrack)
B(-3,1,5,minecraft:netherrack)
B(-3,2,5,minecraft:netherrack)
B(-3,3,5,minecraft:netherrack)
B(-3,4,5,minecraft:netherrack)
B(-3,5,5,minecraft:netherrack)
B(-3,6,5,minecraft:netherrack)
B(-3,7,5,minecraft:netherrack)
B(-3,8,5,minecraft:netherrack)
B(-3,9,5,minecraft:netherrack)
B(-3,10,5,minecraft:netherrack)
B(-3,11,5,minecraft:netherrack)
B(-3,0,6,minecraft:netherrack)
B(-3,1,6,minecraft:netherrack)
B(-3,2,6,minecraft:netherrack)
B(-3,3,6,minecraft:netherrack)
B(-3,4,6,minecraft:netherrack)
B(-3,5,6,minecraft:netherrack)
B(-3,6,6,minecraft:netherrack)
B(-3,7,6,minecraft:netherrack)
B(-3,8,6,minecraft:netherrack)
B(-3,9,6,minecraft:netherrack)
B(-3,10,6,minecraft:netherrack)
B(-3,11,6,minecraft:netherrack)
B(-3,12,6,minecraft:netherrack)
B(-3,13,6,minecraft:netherrack)
B(-3,14,6,minecraft:netherrack)
B(-3,15,6,minecraft:netherrack)
B(-3,0,7,minecraft:netherrack)
B(-3,1,7,minecraft:netherrack)
B(-3,2,7,minecraft:netherrack)
B(-3,3,7,minecraft:netherrack)
B(-3,4,7,minecraft:netherrack)
B(-3,5,7,minecraft:netherrack)
B(-3,6,7,minecraft:netherrack)
B(-3,7,7,minecraft:netherrack)
B(-3,8,7,minecraft:netherrack)
B(-3,9,7,minecraft:netherrack)
B(-3,10,7,minecraft:netherrack)
B(-3,11,7,minecraft:netherrack)
B(-3,12,7,minecraft:netherrack)
B(-3,13,7,minecraft:netherrack)
B(-3,14,7,minecraft:netherrack)
B(-3,15,7,minecraft:netherrack)
B(-3,16,7,minecraft:netherrack)
B(-3,17,7,minecraft:netherrack)
B(-3,0,8,minecraft:netherrack)
B(-3,1,8,minecraft:netherrack)
B(-3,2,8,minecraft:netherrack)
B(-3,3,8,minecraft:netherrack)
B(-3,4,8,minecraft:netherrack)
B(-3,5,8,minecraft:netherrack)
B(-3,6,8,minecraft:netherrack)
B(-3,7,8,minecraft:netherrack)
B(-3,8,8,minecraft:netherrack)
B(-3,9,8,minecraft:netherrack)
B(-3,10,8,minecraft:netherrack)
B(-3,11,8,minecraft:netherrack)
B(-3,12,8,minecraft:netherrack)
B(-3,13,8,minecraft:netherrack)
B(-3,14,8,minecraft:netherrack)
B(-3,15,8,minecraft:netherrack)
B(-3,16,8,minecraft:netherrack)
B(-3,17,8,minecraft:netherrack)
B(-3,18,8,minecraft:netherrack)
B(-2,0,-2,minecraft:netherrack)
B(-2,1,-2,minecraft:netherrack)
B(-2,2,-2,minecraft:netherrack)
B(-2,3,-2,minecraft:netherrack)
B(-2,0,-1,minecraft:netherrack)
B(-2,1,-1,minecraft:netherrack)
B(-2,2,-1,minecraft:netherrack)
B(-2,3,-1,minecraft:netherrack)
B(-2,4,-1,minecraft:netherrack)
B(-2,5,-1,minecraft:netherrack)
B(-2,6,-1,minecraft:netherrack)
B(-2,7,-1,minecraft:netherrack)
B(-2,8,-1,minecraft:netherrack)
B(-2,9,-1,minecraft:netherrack)
B(-2,10,-1,minecraft:netherrack)
B(-2,0,0,minecraft:netherrack)
B(-2,1,0,minecraft:netherrack)
B(-2,2,0,minecraft:netherrack)
B(-2,3,0,minecraft:netherrack)
B(-2,4,0,minecraft:netherrack)
B(-2,5,0,minecraft:netherrack)
B(-2,6,0,minecraft:netherrack)
B(-2,7,0,minecraft:netherrack)
B(-2,8,0,minecraft:netherrack)
B(-2,9,0,minecraft:netherrack)
B(-2,10,0,minecraft:netherrack)
B(-2,0,1,minecraft:netherrack)
B(-2,1,1,minecraft:netherrack)
B(-2,2,1,minecraft:netherrack)
B(-2,3,1,minecraft:netherrack)
B(-2,4,1,minecraft:netherrack)
B(-2,5,1,minecraft:netherrack)
B(-2,6,1,minecraft:netherrack)
B(-2,7,1,minecraft:netherrack)
B(-2,8,1,minecraft:netherrack)
B(-2,9,1,minecraft:netherrack)
B(-2,10,1,minecraft:netherrack)
B(-2,0,2,minecraft:netherrack)
B(-2,1,2,minecraft:netherrack)
B(-2,2,2,minecraft:netherrack)
B(-2,3,2,minecraft:netherrack)
B(-2,4,2,minecraft:netherrack)
B(-2,5,2,minecraft:netherrack)
B(-2,6,2,minecraft:netherrack)
B(-2,0,3,minecraft:netherrack)
B(-2,1,3,minecraft:netherrack)
B(-2,2,3,minecraft:netherrack)
B(-2,3,3,minecraft:netherrack)
B(-2,0,4,minecraft:netherrack)
B(-2,1,4,minecraft:netherrack)
B(-2,2,4,minecraft:netherrack)
B(-2,3,4,minecraft:netherrack)
B(-2,4,4,minecraft:netherrack)
B(-2,5,4,minecraft:netherrack)
B(-2,6,4,minecraft:netherrack)
B(-2,7,4,minecraft:netherrack)
B(-2,8,4,minecraft:netherrack)
B(-2,0,5,minecraft:netherrack)
B(-2,1,5,minecraft:netherrack)
B(-2,2,5,minecraft:netherrack)
B(-2,3,5,minecraft:netherrack)
B(-2,4,5,minecraft:netherrack)
B(-2,5,5,minecraft:netherrack)
B(-2,6,5,minecraft:netherrack)
B(-2,7,5,minecraft:netherrack)
B(-2,8,5,minecraft:netherrack)
B(-2,9,5,minecraft:netherrack)
B(-2,10,5,minecraft:netherrack)
B(-2,11,5,minecraft:netherrack)
B(-2,12,5,minecraft:netherrack)
B(-2,13,5,minecraft:netherrack)
B(-2,0,6,minecraft:netherrack)
B(-2,1,6,minecraft:netherrack)
B(-2,2,6,minecraft:netherrack)
B(-2,3,6,minecraft:netherrack)
B(-2,4,6,minecraft:netherrack)
B(-2,5,6,minecraft:netherrack)
B(-2,6,6,minecraft:netherrack)
B(-2,7,6,minecraft:netherrack)
B(-2,8,6,minecraft:netherrack)
B(-2,9,6,minecraft:netherrack)
B(-2,10,6,minecraft:netherrack)
B(-2,11,6,minecraft:netherrack)
B(-2,12,6,minecraft:netherrack)
B(-2,13,6,minecraft:netherrack)
B(-2,14,6,minecraft:netherrack)
B(-2,15,6,minecraft:netherrack)
B(-2,16,6,minecraft:netherrack)
B(-2,0,7,minecraft:netherrack)
B(-2,1,7,minecraft:netherrack)
B(-2,2,7,minecraft:netherrack)
B(-2,3,7,minecraft:netherrack)
B(-2,4,7,minecraft:netherrack)
B(-2,5,7,minecraft:netherrack)
B(-2,6,7,minecraft:netherrack)
B(-2,7,7,minecraft:netherrack)
B(-2,8,7,minecraft:netherrack)
B(-2,9,7,minecraft:netherrack)
B(-2,10,7,minecraft:netherrack)
B(-2,11,7,minecraft:netherrack)
B(-2,12,7,minecraft:netherrack)
B(-2,13,7,minecraft:netherrack)
B(-2,14,7,minecraft:netherrack)
B(-2,15,7,minecraft:netherrack)
B(-2,16,7,minecraft:netherrack)
B(-2,17,7,minecraft:netherrack)
B(-2,0,8,minecraft:netherrack)
B(-2,1,8,minecraft:netherrack)
B(-2,2,8,minecraft:netherrack)
B(-2,3,8,minecraft:netherrack)
B(-2,4,8,minecraft:netherrack)
B(-2,5,8,minecraft:netherrack)
B(-2,6,8,minecraft:netherrack)
B(-2,7,8,minecraft:netherrack)
B(-2,8,8,minecraft:netherrack)
B(-2,9,8,minecraft:netherrack)
B(-2,10,8,minecraft:netherrack)
B(-2,11,8,minecraft:netherrack)
B(-2,12,8,minecraft:netherrack)
B(-2,13,8,minecraft:netherrack)
B(-2,14,8,minecraft:netherrack)
B(-2,15,8,minecraft:netherrack)
B(-2,16,8,minecraft:netherrack)
B(-2,17,8,minecraft:netherrack)
B(-2,18,8,minecraft:netherrack)
B(-2,19,8,minecraft:netherrack)
B(-2,20,8,minecraft:netherrack)
B(-2,21,8,minecraft:netherrack)
B(-1,0,-3,minecraft:netherrack)
B(-1,1,-3,minecraft:netherrack)
B(-1,2,-3,minecraft:netherrack)
B(-1,3,-3,minecraft:netherrack)
B(-1,4,-3,minecraft:netherrack)
B(-1,5,-3,minecraft:netherrack)
B(-1,6,-3,minecraft:netherrack)
B(-1,7,-3,minecraft:netherrack)
B(-1,8,-3,minecraft:netherrack)
B(-1,9,-3,minecraft:netherrack)
B(-1,0,-1,minecraft:netherrack)
B(-1,1,-1,minecraft:netherrack)
B(-1,0,0,minecraft:netherrack)
B(-1,1,0,minecraft:netherrack)
B(-1,0,1,minecraft:netherrack)
B(-1,1,1,minecraft:netherrack)
B(-1,2,1,minecraft:netherrack)
B(-1,0,2,minecraft:netherrack)
B(-1,1,2,minecraft:netherrack)
B(-1,2,2,minecraft:netherrack)
B(-1,3,2,minecraft:netherrack)
B(-1,4,2,minecraft:netherrack)
B(-1,5,2,minecraft:netherrack)
B(-1,6,2,minecraft:netherrack)
B(-1,7,2,minecraft:netherrack)
B(-1,8,2,minecraft:netherrack)
B(-1,9,2,minecraft:netherrack)
B(-1,10,2,minecraft:netherrack)
B(-1,11,2,minecraft:netherrack)
B(-1,12,2,minecraft:netherrack)
B(-1,13,2,minecraft:netherrack)
B(-1,14,2,minecraft:netherrack)
B(-1,15,2,minecraft:netherrack)
B(-1,16,2,minecraft:netherrack)
B(-1,0,3,minecraft:netherrack)
B(-1,1,3,minecraft:netherrack)
B(-1,2,3,minecraft:netherrack)
B(-1,3,3,minecraft:netherrack)
B(-1,4,3,minecraft:netherrack)
B(-1,5,3,minecraft:netherrack)
B(-1,6,3,minecraft:netherrack)
B(-1,7,3,minecraft:netherrack)
B(-1,8,3,minecraft:netherrack)
B(-1,9,3,minecraft:netherrack)
B(-1,10,3,minecraft:netherrack)
B(-1,0,4,minecraft:netherrack)
B(-1,1,4,minecraft:netherrack)
B(-1,2,4,minecraft:netherrack)
B(-1,3,4,minecraft:netherrack)
B(-1,4,4,minecraft:netherrack)
B(-1,5,4,minecraft:netherrack)
B(-1,6,4,minecraft:netherrack)
B(-1,7,4,minecraft:netherrack)
B(-1,0,5,minecraft:netherrack)
B(-1,1,5,minecraft:netherrack)
B(-1,2,5,minecraft:netherrack)
B(-1,3,5,minecraft:netherrack)
B(-1,4,5,minecraft:netherrack)
B(-1,5,5,minecraft:netherrack)
B(-1,6,5,minecraft:netherrack)
B(-1,7,5,minecraft:netherrack)
B(-1,8,5,minecraft:netherrack)
B(-1,9,5,minecraft:netherrack)
B(-1,10,5,minecraft:netherrack)
B(-1,11,5,minecraft:netherrack)
B(-1,12,5,minecraft:netherrack)
B(-1,13,5,minecraft:netherrack)
B(-1,14,5,minecraft:netherrack)
B(-1,0,6,minecraft:netherrack)
B(-1,1,6,minecraft:netherrack)
B(-1,2,6,minecraft:netherrack)
B(-1,3,6,minecraft:netherrack)
B(-1,4,6,minecraft:netherrack)
B(-1,5,6,minecraft:netherrack)
B(-1,6,6,minecraft:netherrack)
B(-1,7,6,minecraft:netherrack)
B(-1,8,6,minecraft:netherrack)
B(-1,9,6,minecraft:netherrack)
B(-1,10,6,minecraft:netherrack)
B(-1,11,6,minecraft:netherrack)
B(-1,12,6,minecraft:netherrack)
B(-1,13,6,minecraft:netherrack)
B(-1,14,6,minecraft:netherrack)
B(-1,15,6,minecraft:netherrack)
B(-1,0,7,minecraft:netherrack)
B(-1,1,7,minecraft:netherrack)
B(-1,2,7,minecraft:netherrack)
B(-1,3,7,minecraft:netherrack)
B(-1,4,7,minecraft:netherrack)
B(-1,5,7,minecraft:netherrack)
B(-1,6,7,minecraft:netherrack)
B(-1,7,7,minecraft:netherrack)
B(-1,8,7,minecraft:netherrack)
B(-1,9,7,minecraft:netherrack)
B(-1,10,7,minecraft:netherrack)
B(-1,11,7,minecraft:netherrack)
B(-1,12,7,minecraft:netherrack)
B(-1,13,7,minecraft:netherrack)
B(-1,14,7,minecraft:netherrack)
B(-1,15,7,minecraft:netherrack)
B(-1,16,7,minecraft:netherrack)
B(-1,17,7,minecraft:netherrack)
B(-1,18,7,minecraft:netherrack)
B(-1,19,7,minecraft:netherrack)
B(-1,0,8,minecraft:netherrack)
B(-1,1,8,minecraft:netherrack)
B(-1,2,8,minecraft:netherrack)
B(-1,3,8,minecraft:netherrack)
B(-1,4,8,minecraft:netherrack)
B(-1,5,8,minecraft:netherrack)
B(-1,6,8,minecraft:netherrack)
B(-1,7,8,minecraft:netherrack)
B(-1,8,8,minecraft:netherrack)
B(-1,9,8,minecraft:netherrack)
B(-1,10,8,minecraft:netherrack)
B(-1,11,8,minecraft:netherrack)
B(-1,12,8,minecraft:netherrack)
B(-1,13,8,minecraft:netherrack)
B(-1,14,8,minecraft:netherrack)
B(-1,15,8,minecraft:netherrack)
B(-1,16,8,minecraft:netherrack)
B(-1,17,8,minecraft:netherrack)
B(-1,18,8,minecraft:netherrack)
B(-1,19,8,minecraft:netherrack)
B(-1,20,8,minecraft:netherrack)
B(-1,21,8,minecraft:netherrack)
B(0,0,-7,minecraft:netherrack)
B(0,0,-3,minecraft:netherrack)
B(0,1,-3,minecraft:netherrack)
B(0,0,-2,minecraft:netherrack)
B(0,1,-2,minecraft:netherrack)
B(0,2,-2,minecraft:netherrack)
B(0,3,-2,minecraft:netherrack)
B(0,4,-2,minecraft:netherrack)
B(0,5,-2,minecraft:netherrack)
B(0,6,-2,minecraft:netherrack)
B(0,7,-2,minecraft:netherrack)
B(0,8,-2,minecraft:netherrack)
B(0,9,-2,minecraft:netherrack)
B(0,10,-2,minecraft:netherrack)
B(0,11,-2,minecraft:netherrack)
B(0,0,-1,minecraft:netherrack)
B(0,1,-1,minecraft:netherrack)
B(0,2,-1,minecraft:netherrack)
B(0,3,-1,minecraft:netherrack)
B(0,4,-1,minecraft:netherrack)
B(0,5,-1,minecraft:netherrack)
B(0,6,-1,minecraft:netherrack)
B(0,7,-1,minecraft:netherrack)
B(0,8,-1,minecraft:netherrack)
B(0,9,-1,minecraft:netherrack)
B(0,10,-1,minecraft:netherrack)
B(0,11,-1,minecraft:netherrack)
B(0,12,-1,minecraft:netherrack)
B(0,13,-1,minecraft:netherrack)
B(0,0,0,minecraft:netherrack)
B(0,1,0,minecraft:netherrack)
B(0,2,0,minecraft:netherrack)
B(0,3,0,minecraft:netherrack)
B(0,4,0,minecraft:netherrack)
B(0,5,0,minecraft:netherrack)
B(0,6,0,minecraft:netherrack)
B(0,7,0,minecraft:netherrack)
B(0,8,0,minecraft:netherrack)
B(0,9,0,minecraft:netherrack)
B(0,10,0,minecraft:netherrack)
B(0,11,0,minecraft:netherrack)
B(0,12,0,minecraft:netherrack)
B(0,13,0,minecraft:netherrack)
B(0,0,1,minecraft:netherrack)
B(0,1,1,minecraft:netherrack)
B(0,2,1,minecraft:netherrack)
B(0,3,1,minecraft:netherrack)
B(0,4,1,minecraft:netherrack)
B(0,5,1,minecraft:netherrack)
B(0,6,1,minecraft:netherrack)
B(0,7,1,minecraft:netherrack)
B(0,8,1,minecraft:netherrack)
B(0,9,1,minecraft:netherrack)
B(0,10,1,minecraft:netherrack)
B(0,11,1,minecraft:netherrack)
B(0,12,1,minecraft:netherrack)
B(0,13,1,minecraft:netherrack)
B(0,0,2,minecraft:netherrack)
B(0,1,2,minecraft:netherrack)
B(0,2,2,minecraft:netherrack)
B(0,3,2,minecraft:netherrack)
B(0,4,2,minecraft:netherrack)
B(0,5,2,minecraft:netherrack)
B(0,6,2,minecraft:netherrack)
B(0,7,2,minecraft:netherrack)
B(0,8,2,minecraft:netherrack)
B(0,9,2,minecraft:netherrack)
B(0,10,2,minecraft:netherrack)
B(0,11,2,minecraft:netherrack)
B(0,12,2,minecraft:netherrack)
B(0,13,2,minecraft:netherrack)
B(0,14,2,minecraft:netherrack)
B(0,0,3,minecraft:netherrack)
B(0,1,3,minecraft:netherrack)
B(0,2,3,minecraft:netherrack)
B(0,3,3,minecraft:netherrack)
B(0,4,3,minecraft:netherrack)
B(0,5,3,minecraft:netherrack)
B(0,6,3,minecraft:netherrack)
B(0,7,3,minecraft:netherrack)
B(0,0,4,minecraft:netherrack)
B(0,1,4,minecraft:netherrack)
B(0,2,4,minecraft:netherrack)
B(0,3,4,minecraft:netherrack)
B(0,4,4,minecraft:netherrack)
B(0,5,4,minecraft:netherrack)
B(0,6,4,minecraft:netherrack)
B(0,7,4,minecraft:netherrack)
B(0,8,4,minecraft:netherrack)
B(0,9,4,minecraft:netherrack)
B(0,10,4,minecraft:netherrack)
B(0,11,4,minecraft:netherrack)
B(0,12,4,minecraft:netherrack)
B(0,13,4,minecraft:netherrack)
B(0,14,4,minecraft:netherrack)
B(0,15,4,minecraft:netherrack)
B(0,16,4,minecraft:netherrack)
B(0,0,5,minecraft:netherrack)
B(0,1,5,minecraft:netherrack)
B(0,2,5,minecraft:netherrack)
B(0,3,5,minecraft:netherrack)
B(0,4,5,minecraft:netherrack)
B(0,5,5,minecraft:netherrack)
B(0,6,5,minecraft:netherrack)
B(0,7,5,minecraft:netherrack)
B(0,8,5,minecraft:netherrack)
B(0,9,5,minecraft:netherrack)
B(0,10,5,minecraft:netherrack)
B(0,11,5,minecraft:netherrack)
B(0,12,5,minecraft:netherrack)
B(0,13,5,minecraft:netherrack)
B(0,14,5,minecraft:netherrack)
B(0,15,5,minecraft:netherrack)
B(0,16,5,minecraft:netherrack)
B(0,0,6,minecraft:netherrack)
B(0,1,6,minecraft:netherrack)
B(0,2,6,minecraft:netherrack)
B(0,3,6,minecraft:netherrack)
B(0,4,6,minecraft:netherrack)
B(0,5,6,minecraft:netherrack)
B(0,6,6,minecraft:netherrack)
B(0,7,6,minecraft:netherrack)
B(0,8,6,minecraft:netherrack)
B(0,9,6,minecraft:netherrack)
B(0,10,6,minecraft:netherrack)
B(0,11,6,minecraft:netherrack)
B(0,12,6,minecraft:netherrack)
B(0,13,6,minecraft:netherrack)
B(0,14,6,minecraft:netherrack)
B(0,15,6,minecraft:netherrack)
B(0,0,7,minecraft:netherrack)
B(0,1,7,minecraft:netherrack)
B(0,2,7,minecraft:netherrack)
B(0,3,7,minecraft:netherrack)
B(0,4,7,minecraft:netherrack)
B(0,5,7,minecraft:netherrack)
B(0,6,7,minecraft:netherrack)
B(0,7,7,minecraft:netherrack)
B(0,8,7,minecraft:netherrack)
B(0,9,7,minecraft:netherrack)
B(0,10,7,minecraft:netherrack)
B(0,11,7,minecraft:netherrack)
B(0,12,7,minecraft:netherrack)
B(0,13,7,minecraft:netherrack)
B(0,14,7,minecraft:netherrack)
B(0,15,7,minecraft:netherrack)
B(0,16,7,minecraft:netherrack)
B(0,17,7,minecraft:netherrack)
B(0,18,7,minecraft:netherrack)
B(0,19,7,minecraft:netherrack)
B(0,0,8,minecraft:netherrack)
B(0,1,8,minecraft:netherrack)
B(0,2,8,minecraft:netherrack)
B(0,3,8,minecraft:netherrack)
B(0,4,8,minecraft:netherrack)
B(0,5,8,minecraft:netherrack)
B(0,6,8,minecraft:netherrack)
B(0,7,8,minecraft:netherrack)
B(0,8,8,minecraft:netherrack)
B(0,9,8,minecraft:netherrack)
B(0,10,8,minecraft:netherrack)
B(0,11,8,minecraft:netherrack)
B(0,12,8,minecraft:netherrack)
B(0,13,8,minecraft:netherrack)
B(0,14,8,minecraft:netherrack)
B(0,15,8,minecraft:netherrack)
B(0,16,8,minecraft:netherrack)
B(0,17,8,minecraft:netherrack)
B(0,18,8,minecraft:netherrack)
B(0,19,8,minecraft:netherrack)
B(0,20,8,minecraft:netherrack)
B(0,21,8,minecraft:netherrack)
B(0,22,8,minecraft:netherrack)
B(0,23,8,minecraft:netherrack)
B(0,24,8,minecraft:netherrack)
B(1,0,-7,minecraft:netherrack)
B(1,1,-7,minecraft:netherrack)
B(1,2,-7,minecraft:netherrack)
B(1,3,-7,minecraft:netherrack)
B(1,4,-7,minecraft:netherrack)
B(1,5,-7,minecraft:netherrack)
B(1,6,-7,minecraft:netherrack)
B(1,0,-6,minecraft:netherrack)
B(1,1,-6,minecraft:netherrack)
B(1,2,-6,minecraft:netherrack)
B(1,3,-6,minecraft:netherrack)
B(1,0,-5,minecraft:netherrack)
B(1,1,-5,minecraft:netherrack)
B(1,2,-5,minecraft:netherrack)
B(1,3,-5,minecraft:netherrack)
B(1,4,-5,minecraft:netherrack)
B(1,0,-4,minecraft:netherrack)
B(1,1,-4,minecraft:netherrack)
B(1,2,-4,minecraft:netherrack)
B(1,3,-4,minecraft:netherrack)
B(1,4,-4,minecraft:netherrack)
B(1,0,-3,minecraft:netherrack)
B(1,1,-3,minecraft:netherrack)
B(1,2,-3,minecraft:netherrack)
B(1,3,-3,minecraft:netherrack)
B(1,4,-3,minecraft:netherrack)
B(1,5,-3,minecraft:netherrack)
B(1,6,-3,minecraft:netherrack)
B(1,7,-3,minecraft:netherrack)
B(1,8,-3,minecraft:netherrack)
B(1,9,-3,minecraft:netherrack)
B(1,10,-3,minecraft:netherrack)
B(1,11,-3,minecraft:netherrack)
B(1,12,-3,minecraft:netherrack)
B(1,0,-2,minecraft:netherrack)
B(1,1,-2,minecraft:netherrack)
B(1,2,-2,minecraft:netherrack)
B(1,3,-2,minecraft:netherrack)
B(1,4,-2,minecraft:netherrack)
B(1,5,-2,minecraft:netherrack)
B(1,6,-2,minecraft:netherrack)
B(1,7,-2,minecraft:netherrack)
B(1,8,-2,minecraft:netherrack)
B(1,9,-2,minecraft:netherrack)
B(1,10,-2,minecraft:netherrack)
B(1,11,-2,minecraft:netherrack)
B(1,12,-2,minecraft:netherrack)
B(1,13,-2,minecraft:netherrack)
B(1,0,-1,minecraft:netherrack)
B(1,1,-1,minecraft:netherrack)
B(1,2,-1,minecraft:netherrack)
B(1,3,-1,minecraft:netherrack)
B(1,4,-1,minecraft:netherrack)
B(1,5,-1,minecraft:netherrack)
B(1,6,-1,minecraft:netherrack)
B(1,7,-1,minecraft:netherrack)
B(1,8,-1,minecraft:netherrack)
B(1,9,-1,minecraft:netherrack)
B(1,10,-1,minecraft:netherrack)
B(1,11,-1,minecraft:netherrack)
B(1,12,-1,minecraft:netherrack)
B(1,13,-1,minecraft:netherrack)
B(1,14,-1,minecraft:netherrack)
B(1,15,-1,minecraft:netherrack)
B(1,0,0,minecraft:netherrack)
B(1,1,0,minecraft:netherrack)
B(1,2,0,minecraft:netherrack)
B(1,3,0,minecraft:netherrack)
B(1,4,0,minecraft:netherrack)
B(1,5,0,minecraft:netherrack)
B(1,6,0,minecraft:netherrack)
B(1,7,0,minecraft:netherrack)
B(1,8,0,minecraft:netherrack)
B(1,9,0,minecraft:netherrack)
B(1,10,0,minecraft:netherrack)
B(1,11,0,minecraft:netherrack)
B(1,12,0,minecraft:netherrack)
B(1,13,0,minecraft:netherrack)
B(1,14,0,minecraft:netherrack)
B(1,15,0,minecraft:netherrack)
B(1,0,1,minecraft:netherrack)
B(1,1,1,minecraft:netherrack)
B(1,2,1,minecraft:netherrack)
B(1,3,1,minecraft:netherrack)
B(1,4,1,minecraft:netherrack)
B(1,5,1,minecraft:netherrack)
B(1,6,1,minecraft:netherrack)
B(1,7,1,minecraft:netherrack)
B(1,8,1,minecraft:netherrack)
B(1,9,1,minecraft:netherrack)
B(1,10,1,minecraft:netherrack)
B(1,11,1,minecraft:netherrack)
B(1,12,1,minecraft:netherrack)
B(1,13,1,minecraft:netherrack)
B(1,14,1,minecraft:netherrack)
B(1,15,1,minecraft:netherrack)
B(1,16,1,minecraft:netherrack)
B(1,0,2,minecraft:netherrack)
B(1,1,2,minecraft:netherrack)
B(1,2,2,minecraft:netherrack)
B(1,3,2,minecraft:netherrack)
B(1,4,2,minecraft:netherrack)
B(1,5,2,minecraft:netherrack)
B(1,6,2,minecraft:netherrack)
B(1,7,2,minecraft:netherrack)
B(1,8,2,minecraft:netherrack)
B(1,9,2,minecraft:netherrack)
B(1,10,2,minecraft:netherrack)
B(1,11,2,minecraft:netherrack)
B(1,12,2,minecraft:netherrack)
B(1,13,2,minecraft:netherrack)
B(1,14,2,minecraft:netherrack)
B(1,15,2,minecraft:netherrack)
B(1,16,2,minecraft:netherrack)
B(1,17,2,minecraft:netherrack)
B(1,0,3,minecraft:netherrack)
B(1,1,3,minecraft:netherrack)
B(1,2,3,minecraft:netherrack)
B(1,3,3,minecraft:netherrack)
B(1,4,3,minecraft:netherrack)
B(1,5,3,minecraft:netherrack)
B(1,6,3,minecraft:netherrack)
B(1,7,3,minecraft:netherrack)
B(1,8,3,minecraft:netherrack)
B(1,9,3,minecraft:netherrack)
B(1,10,3,minecraft:netherrack)
B(1,11,3,minecraft:netherrack)
B(1,12,3,minecraft:netherrack)
B(1,13,3,minecraft:netherrack)
B(1,14,3,minecraft:netherrack)
B(1,15,3,minecraft:netherrack)
B(1,16,3,minecraft:netherrack)
B(1,17,3,minecraft:netherrack)
B(1,18,3,minecraft:netherrack)
B(1,19,3,minecraft:netherrack)
B(1,20,3,minecraft:netherrack)
B(1,0,4,minecraft:netherrack)
B(1,1,4,minecraft:netherrack)
B(1,2,4,minecraft:netherrack)
B(1,3,4,minecraft:netherrack)
B(1,4,4,minecraft:netherrack)
B(1,5,4,minecraft:netherrack)
B(1,6,4,minecraft:netherrack)
B(1,7,4,minecraft:netherrack)
B(1,8,4,minecraft:netherrack)
B(1,9,4,minecraft:netherrack)
B(1,10,4,minecraft:netherrack)
B(1,11,4,minecraft:netherrack)
B(1,12,4,minecraft:netherrack)
B(1,13,4,minecraft:netherrack)
B(1,14,4,minecraft:netherrack)
B(1,0,5,minecraft:netherrack)
B(1,1,5,minecraft:netherrack)
B(1,2,5,minecraft:netherrack)
B(1,3,5,minecraft:netherrack)
B(1,4,5,minecraft:netherrack)
B(1,5,5,minecraft:netherrack)
B(1,6,5,minecraft:netherrack)
B(1,7,5,minecraft:netherrack)
B(1,8,5,minecraft:netherrack)
B(1,9,5,minecraft:netherrack)
B(1,10,5,minecraft:netherrack)
B(1,11,5,minecraft:netherrack)
B(1,12,5,minecraft:netherrack)
B(1,13,5,minecraft:netherrack)
B(1,14,5,minecraft:netherrack)
B(1,15,5,minecraft:netherrack)
B(1,16,5,minecraft:netherrack)
B(1,17,5,minecraft:netherrack)
B(1,18,5,minecraft:netherrack)
B(1,19,5,minecraft:netherrack)
B(1,20,5,minecraft:netherrack)
B(1,21,5,minecraft:netherrack)
B(1,22,5,minecraft:netherrack)
B(1,0,6,minecraft:netherrack)
B(1,1,6,minecraft:netherrack)
B(1,2,6,minecraft:netherrack)
B(1,3,6,minecraft:netherrack)
B(1,4,6,minecraft:netherrack)
B(1,5,6,minecraft:netherrack)
B(1,6,6,minecraft:netherrack)
B(1,7,6,minecraft:netherrack)
B(1,8,6,minecraft:netherrack)
B(1,9,6,minecraft:netherrack)
B(1,10,6,minecraft:netherrack)
B(1,11,6,minecraft:netherrack)
B(1,12,6,minecraft:netherrack)
B(1,13,6,minecraft:netherrack)
B(1,14,6,minecraft:netherrack)
B(1,15,6,minecraft:netherrack)
B(1,16,6,minecraft:netherrack)
B(1,17,6,minecraft:netherrack)
B(1,18,6,minecraft:netherrack)
B(1,19,6,minecraft:netherrack)
B(1,20,6,minecraft:netherrack)
B(1,21,6,minecraft:netherrack)
B(1,22,6,minecraft:netherrack)
B(1,0,7,minecraft:netherrack)
B(1,1,7,minecraft:netherrack)
B(1,2,7,minecraft:netherrack)
B(1,3,7,minecraft:netherrack)
B(1,4,7,minecraft:netherrack)
B(1,5,7,minecraft:netherrack)
B(1,6,7,minecraft:netherrack)
B(1,7,7,minecraft:netherrack)
B(1,8,7,minecraft:netherrack)
B(1,9,7,minecraft:netherrack)
B(1,10,7,minecraft:netherrack)
B(1,11,7,minecraft:netherrack)
B(1,12,7,minecraft:netherrack)
B(1,13,7,minecraft:netherrack)
B(1,14,7,minecraft:netherrack)
B(1,15,7,minecraft:netherrack)
B(1,16,7,minecraft:netherrack)
B(1,17,7,minecraft:netherrack)
B(1,18,7,minecraft:netherrack)
B(1,19,7,minecraft:netherrack)
B(1,20,7,minecraft:netherrack)
B(1,21,7,minecraft:netherrack)
B(1,22,7,minecraft:netherrack)
B(1,23,7,minecraft:netherrack)
B(1,24,7,minecraft:netherrack)
B(1,0,8,minecraft:netherrack)
B(1,1,8,minecraft:netherrack)
B(1,2,8,minecraft:netherrack)
B(1,3,8,minecraft:netherrack)
B(1,4,8,minecraft:netherrack)
B(1,5,8,minecraft:netherrack)
B(1,6,8,minecraft:netherrack)
B(1,7,8,minecraft:netherrack)
B(1,8,8,minecraft:netherrack)
B(1,9,8,minecraft:netherrack)
B(1,10,8,minecraft:netherrack)
B(1,11,8,minecraft:netherrack)
B(1,12,8,minecraft:netherrack)
B(1,13,8,minecraft:netherrack)
B(1,14,8,minecraft:netherrack)
B(1,15,8,minecraft:netherrack)
B(1,16,8,minecraft:netherrack)
B(1,17,8,minecraft:netherrack)
B(1,18,8,minecraft:netherrack)
B(1,19,8,minecraft:netherrack)
B(1,20,8,minecraft:netherrack)
B(1,21,8,minecraft:netherrack)
B(1,22,8,minecraft:netherrack)
B(1,23,8,minecraft:netherrack)
B(2,0,-7,minecraft:netherrack)
B(2,1,-7,minecraft:netherrack)
B(2,2,-7,minecraft:netherrack)
B(2,3,-7,minecraft:netherrack)
B(2,4,-7,minecraft:netherrack)
B(2,5,-7,minecraft:netherrack)
B(2,6,-7,minecraft:netherrack)
B(2,7,-7,minecraft:netherrack)
B(2,8,-7,minecraft:netherrack)
B(2,9,-7,minecraft:netherrack)
B(2,10,-7,minecraft:netherrack)
B(2,0,-6,minecraft:netherrack)
B(2,1,-6,minecraft:netherrack)
B(2,2,-6,minecraft:netherrack)
B(2,3,-6,minecraft:netherrack)
B(2,4,-6,minecraft:netherrack)
B(2,5,-6,minecraft:netherrack)
B(2,6,-6,minecraft:netherrack)
B(2,7,-6,minecraft:netherrack)
B(2,8,-6,minecraft:netherrack)
B(2,9,-6,minecraft:netherrack)
B(2,0,-5,minecraft:netherrack)
B(2,1,-5,minecraft:netherrack)
B(2,2,-5,minecraft:netherrack)
B(2,3,-5,minecraft:netherrack)
B(2,4,-5,minecraft:netherrack)
B(2,5,-5,minecraft:netherrack)
B(2,6,-5,minecraft:netherrack)
B(2,7,-5,minecraft:netherrack)
B(2,8,-5,minecraft:netherrack)
B(2,9,-5,minecraft:netherrack)
B(2,10,-5,minecraft:netherrack)
B(2,11,-5,minecraft:netherrack)
B(2,0,-4,minecraft:netherrack)
B(2,1,-4,minecraft:netherrack)
B(2,2,-4,minecraft:netherrack)
B(2,3,-4,minecraft:netherrack)
B(2,4,-4,minecraft:netherrack)
B(2,5,-4,minecraft:netherrack)
B(2,6,-4,minecraft:netherrack)
B(2,7,-4,minecraft:netherrack)
B(2,8,-4,minecraft:netherrack)
B(2,9,-4,minecraft:netherrack)
B(2,10,-4,minecraft:netherrack)
B(2,11,-4,minecraft:netherrack)
B(2,0,-3,minecraft:netherrack)
B(2,1,-3,minecraft:netherrack)
B(2,2,-3,minecraft:netherrack)
B(2,3,-3,minecraft:netherrack)
B(2,4,-3,minecraft:netherrack)
B(2,5,-3,minecraft:netherrack)
B(2,6,-3,minecraft:netherrack)
B(2,7,-3,minecraft:netherrack)
B(2,8,-3,minecraft:netherrack)
B(2,9,-3,minecraft:netherrack)
B(2,10,-3,minecraft:netherrack)
B(2,11,-3,minecraft:netherrack)
B(2,12,-3,minecraft:netherrack)
B(2,13,-3,minecraft:netherrack)
B(2,0,-2,minecraft:netherrack)
B(2,1,-2,minecraft:netherrack)
B(2,2,-2,minecraft:netherrack)
B(2,3,-2,minecraft:netherrack)
B(2,4,-2,minecraft:netherrack)
B(2,5,-2,minecraft:netherrack)
B(2,6,-2,minecraft:netherrack)
B(2,7,-2,minecraft:netherrack)
B(2,8,-2,minecraft:netherrack)
B(2,9,-2,minecraft:netherrack)
B(2,10,-2,minecraft:netherrack)
B(2,11,-2,minecraft:netherrack)
B(2,12,-2,minecraft:netherrack)
B(2,13,-2,minecraft:netherrack)
B(2,14,-2,minecraft:netherrack)
B(2,0,-1,minecraft:netherrack)
B(2,1,-1,minecraft:netherrack)
B(2,2,-1,minecraft:netherrack)
B(2,3,-1,minecraft:netherrack)
B(2,4,-1,minecraft:netherrack)
B(2,5,-1,minecraft:netherrack)
B(2,6,-1,minecraft:netherrack)
B(2,7,-1,minecraft:netherrack)
B(2,8,-1,minecraft:netherrack)
B(2,9,-1,minecraft:netherrack)
B(2,10,-1,minecraft:netherrack)
B(2,11,-1,minecraft:netherrack)
B(2,12,-1,minecraft:netherrack)
B(2,13,-1,minecraft:netherrack)
B(2,14,-1,minecraft:netherrack)
B(2,15,-1,minecraft:netherrack)
B(2,0,0,minecraft:netherrack)
B(2,1,0,minecraft:netherrack)
B(2,2,0,minecraft:netherrack)
B(2,3,0,minecraft:netherrack)
B(2,4,0,minecraft:netherrack)
B(2,5,0,minecraft:netherrack)
B(2,6,0,minecraft:netherrack)
B(2,7,0,minecraft:netherrack)
B(2,8,0,minecraft:netherrack)
B(2,9,0,minecraft:netherrack)
B(2,10,0,minecraft:netherrack)
B(2,11,0,minecraft:netherrack)
B(2,12,0,minecraft:netherrack)
B(2,13,0,minecraft:netherrack)
B(2,14,0,minecraft:netherrack)
B(2,15,0,minecraft:netherrack)
B(2,16,0,minecraft:netherrack)
B(2,0,1,minecraft:netherrack)
B(2,1,1,minecraft:netherrack)
B(2,2,1,minecraft:netherrack)
B(2,3,1,minecraft:netherrack)
B(2,4,1,minecraft:netherrack)
B(2,5,1,minecraft:netherrack)
B(2,6,1,minecraft:netherrack)
B(2,7,1,minecraft:netherrack)
B(2,8,1,minecraft:netherrack)
B(2,9,1,minecraft:netherrack)
B(2,10,1,minecraft:netherrack)
B(2,11,1,minecraft:netherrack)
B(2,12,1,minecraft:netherrack)
B(2,13,1,minecraft:netherrack)
B(2,14,1,minecraft:netherrack)
B(2,15,1,minecraft:netherrack)
B(2,16,1,minecraft:netherrack)
B(2,17,1,minecraft:netherrack)
B(2,0,2,minecraft:netherrack)
B(2,1,2,minecraft:netherrack)
B(2,2,2,minecraft:netherrack)
B(2,3,2,minecraft:netherrack)
B(2,4,2,minecraft:netherrack)
B(2,5,2,minecraft:netherrack)
B(2,6,2,minecraft:netherrack)
B(2,7,2,minecraft:netherrack)
B(2,8,2,minecraft:netherrack)
B(2,9,2,minecraft:netherrack)
B(2,10,2,minecraft:netherrack)
B(2,11,2,minecraft:netherrack)
B(2,12,2,minecraft:netherrack)
B(2,13,2,minecraft:netherrack)
B(2,14,2,minecraft:netherrack)
B(2,15,2,minecraft:netherrack)
B(2,16,2,minecraft:netherrack)
B(2,17,2,minecraft:netherrack)
B(2,18,2,minecraft:netherrack)
B(2,19,2,minecraft:netherrack)
B(2,20,2,minecraft:netherrack)
B(2,21,2,minecraft:netherrack)
B(2,22,2,minecraft:netherrack)
B(2,23,2,minecraft:netherrack)
B(2,0,3,minecraft:netherrack)
B(2,1,3,minecraft:netherrack)
B(2,2,3,minecraft:netherrack)
B(2,3,3,minecraft:netherrack)
B(2,4,3,minecraft:netherrack)
B(2,5,3,minecraft:netherrack)
B(2,6,3,minecraft:netherrack)
B(2,7,3,minecraft:netherrack)
B(2,8,3,minecraft:netherrack)
B(2,9,3,minecraft:netherrack)
B(2,10,3,minecraft:netherrack)
B(2,11,3,minecraft:netherrack)
B(2,12,3,minecraft:netherrack)
B(2,13,3,minecraft:netherrack)
B(2,14,3,minecraft:netherrack)
B(2,15,3,minecraft:netherrack)
B(2,16,3,minecraft:netherrack)
B(2,17,3,minecraft:netherrack)
B(2,18,3,minecraft:netherrack)
B(2,19,3,minecraft:netherrack)
B(2,20,3,minecraft:netherrack)
B(2,21,3,minecraft:netherrack)
B(2,22,3,minecraft:netherrack)
B(2,23,3,minecraft:netherrack)
B(2,24,3,minecraft:netherrack)
B(2,25,3,minecraft:netherrack)
B(2,0,4,minecraft:netherrack)
B(2,1,4,minecraft:netherrack)
B(2,2,4,minecraft:netherrack)
B(2,3,4,minecraft:netherrack)
B(2,4,4,minecraft:netherrack)
B(2,5,4,minecraft:netherrack)
B(2,6,4,minecraft:netherrack)
B(2,7,4,minecraft:netherrack)
B(2,8,4,minecraft:netherrack)
B(2,9,4,minecraft:netherrack)
B(2,10,4,minecraft:netherrack)
B(2,11,4,minecraft:netherrack)
B(2,12,4,minecraft:netherrack)
B(2,13,4,minecraft:netherrack)
B(2,14,4,minecraft:netherrack)
B(2,15,4,minecraft:netherrack)
B(2,16,4,minecraft:netherrack)
B(2,17,4,minecraft:netherrack)
B(2,18,4,minecraft:netherrack)
B(2,19,4,minecraft:netherrack)
B(2,20,4,minecraft:netherrack)
B(2,21,4,minecraft:netherrack)
B(2,22,4,minecraft:netherrack)
B(2,23,4,minecraft:netherrack)
B(2,24,4,minecraft:netherrack)
B(2,25,4,minecraft:netherrack)
B(2,0,5,minecraft:netherrack)
B(2,1,5,minecraft:netherrack)
B(2,2,5,minecraft:netherrack)
B(2,3,5,minecraft:netherrack)
B(2,4,5,minecraft:netherrack)
B(2,5,5,minecraft:netherrack)
B(2,6,5,minecraft:netherrack)
B(2,7,5,minecraft:netherrack)
B(2,8,5,minecraft:netherrack)
B(2,9,5,minecraft:netherrack)
B(2,10,5,minecraft:netherrack)
B(2,11,5,minecraft:netherrack)
B(2,12,5,minecraft:netherrack)
B(2,13,5,minecraft:netherrack)
B(2,14,5,minecraft:netherrack)
B(2,15,5,minecraft:netherrack)
B(2,16,5,minecraft:netherrack)
B(2,17,5,minecraft:netherrack)
B(2,18,5,minecraft:netherrack)
B(2,19,5,minecraft:netherrack)
B(2,20,5,minecraft:netherrack)
B(2,21,5,minecraft:netherrack)
B(2,22,5,minecraft:netherrack)
B(2,23,5,minecraft:netherrack)
B(2,24,5,minecraft:netherrack)
B(2,25,5,minecraft:netherrack)
B(2,0,6,minecraft:netherrack)
B(2,1,6,minecraft:netherrack)
B(2,2,6,minecraft:netherrack)
B(2,3,6,minecraft:netherrack)
B(2,4,6,minecraft:netherrack)
B(2,5,6,minecraft:netherrack)
B(2,6,6,minecraft:netherrack)
B(2,7,6,minecraft:netherrack)
B(2,8,6,minecraft:netherrack)
B(2,9,6,minecraft:netherrack)
B(2,10,6,minecraft:netherrack)
B(2,11,6,minecraft:netherrack)
B(2,12,6,minecraft:netherrack)
B(2,13,6,minecraft:netherrack)
B(2,14,6,minecraft:netherrack)
B(2,15,6,minecraft:netherrack)
B(2,16,6,minecraft:netherrack)
B(2,17,6,minecraft:netherrack)
B(2,18,6,minecraft:netherrack)
B(2,19,6,minecraft:netherrack)
B(2,20,6,minecraft:netherrack)
B(2,21,6,minecraft:netherrack)
B(2,22,6,minecraft:netherrack)
B(2,23,6,minecraft:netherrack)
B(2,24,6,minecraft:netherrack)
B(2,25,6,minecraft:netherrack)
B(2,0,7,minecraft:netherrack)
B(2,1,7,minecraft:netherrack)
B(2,2,7,minecraft:netherrack)
B(2,3,7,minecraft:netherrack)
B(2,4,7,minecraft:netherrack)
B(2,5,7,minecraft:netherrack)
B(2,6,7,minecraft:netherrack)
B(2,7,7,minecraft:netherrack)
B(2,8,7,minecraft:netherrack)
B(2,9,7,minecraft:netherrack)
B(2,10,7,minecraft:netherrack)
B(2,11,7,minecraft:netherrack)
B(2,12,7,minecraft:netherrack)
B(2,13,7,minecraft:netherrack)
B(2,14,7,minecraft:netherrack)
B(2,15,7,minecraft:netherrack)
B(2,16,7,minecraft:netherrack)
B(2,17,7,minecraft:netherrack)
B(2,18,7,minecraft:netherrack)
B(2,19,7,minecraft:netherrack)
B(2,20,7,minecraft:netherrack)
B(2,21,7,minecraft:netherrack)
B(2,22,7,minecraft:netherrack)
B(2,23,7,minecraft:netherrack)
B(2,24,7,minecraft:netherrack)
B(2,25,7,minecraft:netherrack)
B(2,26,7,minecraft:netherrack)
B(2,27,7,minecraft:netherrack)
B(2,28,7,minecraft:netherrack)
B(2,29,7,minecraft:netherrack)
B(2,30,7,minecraft:netherrack)
B(2,31,7,minecraft:netherrack)
B(2,32,7,minecraft:netherrack)
B(2,0,8,minecraft:netherrack)
B(2,1,8,minecraft:netherrack)
B(2,2,8,minecraft:netherrack)
B(2,3,8,minecraft:netherrack)
B(2,4,8,minecraft:netherrack)
B(2,5,8,minecraft:netherrack)
B(2,6,8,minecraft:netherrack)
B(2,7,8,minecraft:netherrack)
B(2,8,8,minecraft:netherrack)
B(2,9,8,minecraft:netherrack)
B(2,10,8,minecraft:netherrack)
B(2,11,8,minecraft:netherrack)
B(2,12,8,minecraft:netherrack)
B(2,13,8,minecraft:netherrack)
B(2,14,8,minecraft:netherrack)
B(2,15,8,minecraft:netherrack)
B(2,16,8,minecraft:netherrack)
B(2,17,8,minecraft:netherrack)
B(2,18,8,minecraft:netherrack)
B(2,19,8,minecraft:netherrack)
B(2,20,8,minecraft:netherrack)
B(2,21,8,minecraft:netherrack)
B(2,22,8,minecraft:netherrack)
B(2,23,8,minecraft:netherrack)
B(2,24,8,minecraft:netherrack)
B(2,25,8,minecraft:netherrack)
B(2,26,8,minecraft:netherrack)
B(2,27,8,minecraft:netherrack)
B(2,28,8,minecraft:netherrack)
B(2,29,8,minecraft:netherrack)
B(2,30,8,minecraft:netherrack)
B(2,31,8,minecraft:netherrack)
B(2,32,8,minecraft:netherrack)
B(2,33,8,minecraft:netherrack)
B(2,34,8,minecraft:netherrack)
B(2,35,8,minecraft:netherrack)
B(2,36,8,minecraft:netherrack)
B(2,37,8,minecraft:netherrack)
B(2,38,8,minecraft:netherrack)
B(2,39,8,minecraft:netherrack)
B(2,40,8,minecraft:netherrack)
B(2,41,8,minecraft:netherrack)
B(3,0,-7,minecraft:netherrack)
B(3,1,-7,minecraft:netherrack)
B(3,2,-7,minecraft:netherrack)
B(3,3,-7,minecraft:netherrack)
B(3,4,-7,minecraft:netherrack)
B(3,5,-7,minecraft:netherrack)
B(3,6,-7,minecraft:netherrack)
B(3,7,-7,minecraft:netherrack)
B(3,8,-7,minecraft:netherrack)
B(3,9,-7,minecraft:netherrack)
B(3,10,-7,minecraft:netherrack)
B(3,11,-7,minecraft:netherrack)
B(3,0,-6,minecraft:netherrack)
B(3,1,-6,minecraft:netherrack)
B(3,2,-6,minecraft:netherrack)
B(3,3,-6,minecraft:netherrack)
B(3,4,-6,minecraft:netherrack)
B(3,5,-6,minecraft:netherrack)
B(3,6,-6,minecraft:netherrack)
B(3,7,-6,minecraft:netherrack)
B(3,8,-6,minecraft:netherrack)
B(3,9,-6,minecraft:netherrack)
B(3,10,-6,minecraft:netherrack)
B(3,0,-5,minecraft:netherrack)
B(3,1,-5,minecraft:netherrack)
B(3,2,-5,minecraft:netherrack)
B(3,3,-5,minecraft:netherrack)
B(3,4,-5,minecraft:netherrack)
B(3,5,-5,minecraft:netherrack)
B(3,6,-5,minecraft:netherrack)
B(3,7,-5,minecraft:netherrack)
B(3,8,-5,minecraft:netherrack)
B(3,9,-5,minecraft:netherrack)
B(3,10,-5,minecraft:netherrack)
B(3,11,-5,minecraft:netherrack)
B(3,12,-5,minecraft:netherrack)
B(3,0,-4,minecraft:netherrack)
B(3,1,-4,minecraft:netherrack)
B(3,2,-4,minecraft:netherrack)
B(3,3,-4,minecraft:netherrack)
B(3,4,-4,minecraft:netherrack)
B(3,5,-4,minecraft:netherrack)
B(3,6,-4,minecraft:netherrack)
B(3,7,-4,minecraft:netherrack)
B(3,8,-4,minecraft:netherrack)
B(3,9,-4,minecraft:netherrack)
B(3,10,-4,minecraft:netherrack)
B(3,11,-4,minecraft:netherrack)
B(3,12,-4,minecraft:netherrack)
B(3,0,-3,minecraft:netherrack)
B(3,1,-3,minecraft:netherrack)
B(3,2,-3,minecraft:netherrack)
B(3,3,-3,minecraft:netherrack)
B(3,4,-3,minecraft:netherrack)
B(3,5,-3,minecraft:netherrack)
B(3,6,-3,minecraft:netherrack)
B(3,7,-3,minecraft:netherrack)
B(3,8,-3,minecraft:netherrack)
B(3,9,-3,minecraft:netherrack)
B(3,10,-3,minecraft:netherrack)
B(3,11,-3,minecraft:netherrack)
B(3,12,-3,minecraft:netherrack)
B(3,13,-3,minecraft:netherrack)
B(3,14,-3,minecraft:netherrack)
B(3,15,-3,minecraft:netherrack)
B(3,16,-3,minecraft:netherrack)
B(3,0,-2,minecraft:netherrack)
B(3,1,-2,minecraft:netherrack)
B(3,2,-2,minecraft:netherrack)
B(3,3,-2,minecraft:netherrack)
B(3,4,-2,minecraft:netherrack)
B(3,5,-2,minecraft:netherrack)
B(3,6,-2,minecraft:netherrack)
B(3,7,-2,minecraft:netherrack)
B(3,8,-2,minecraft:netherrack)
B(3,9,-2,minecraft:netherrack)
B(3,10,-2,minecraft:netherrack)
B(3,11,-2,minecraft:netherrack)
B(3,12,-2,minecraft:netherrack)
B(3,13,-2,minecraft:netherrack)
B(3,14,-2,minecraft:netherrack)
B(3,15,-2,minecraft:netherrack)
B(3,16,-2,minecraft:netherrack)
B(3,17,-2,minecraft:netherrack)
B(3,18,-2,minecraft:netherrack)
B(3,19,-2,minecraft:netherrack)
B(3,20,-2,minecraft:netherrack)
B(3,0,-1,minecraft:netherrack)
B(3,1,-1,minecraft:netherrack)
B(3,2,-1,minecraft:netherrack)
B(3,3,-1,minecraft:netherrack)
B(3,4,-1,minecraft:netherrack)
B(3,5,-1,minecraft:netherrack)
B(3,6,-1,minecraft:netherrack)
B(3,7,-1,minecraft:netherrack)
B(3,8,-1,minecraft:netherrack)
B(3,9,-1,minecraft:netherrack)
B(3,10,-1,minecraft:netherrack)
B(3,11,-1,minecraft:netherrack)
B(3,12,-1,minecraft:netherrack)
B(3,13,-1,minecraft:netherrack)
B(3,14,-1,minecraft:netherrack)
B(3,15,-1,minecraft:netherrack)
B(3,16,-1,minecraft:netherrack)
B(3,17,-1,minecraft:netherrack)
B(3,18,-1,minecraft:netherrack)
B(3,19,-1,minecraft:netherrack)
B(3,20,-1,minecraft:netherrack)
B(3,21,-1,minecraft:netherrack)
B(3,22,-1,minecraft:netherrack)
B(3,23,-1,minecraft:netherrack)
B(3,0,0,minecraft:netherrack)
B(3,1,0,minecraft:netherrack)
B(3,2,0,minecraft:netherrack)
B(3,3,0,minecraft:netherrack)
B(3,4,0,minecraft:netherrack)
B(3,5,0,minecraft:netherrack)
B(3,6,0,minecraft:netherrack)
B(3,7,0,minecraft:netherrack)
B(3,8,0,minecraft:netherrack)
B(3,9,0,minecraft:netherrack)
B(3,10,0,minecraft:netherrack)
B(3,11,0,minecraft:netherrack)
B(3,12,0,minecraft:netherrack)
B(3,13,0,minecraft:netherrack)
B(3,14,0,minecraft:netherrack)
B(3,15,0,minecraft:netherrack)
B(3,16,0,minecraft:netherrack)
B(3,17,0,minecraft:netherrack)
B(3,18,0,minecraft:netherrack)
B(3,19,0,minecraft:netherrack)
B(3,20,0,minecraft:netherrack)
B(3,21,0,minecraft:netherrack)
B(3,22,0,minecraft:netherrack)
B(3,23,0,minecraft:netherrack)
B(3,24,0,minecraft:netherrack)
B(3,25,0,minecraft:netherrack)
B(3,26,0,minecraft:netherrack)
B(3,27,0,minecraft:netherrack)
B(3,0,1,minecraft:netherrack)
B(3,1,1,minecraft:netherrack)
B(3,2,1,minecraft:netherrack)
B(3,3,1,minecraft:netherrack)
B(3,4,1,minecraft:netherrack)
B(3,5,1,minecraft:netherrack)
B(3,6,1,minecraft:netherrack)
B(3,7,1,minecraft:netherrack)
B(3,8,1,minecraft:netherrack)
B(3,9,1,minecraft:netherrack)
B(3,10,1,minecraft:netherrack)
B(3,11,1,minecraft:netherrack)
B(3,12,1,minecraft:netherrack)
B(3,13,1,minecraft:netherrack)
B(3,14,1,minecraft:netherrack)
B(3,15,1,minecraft:netherrack)
B(3,16,1,minecraft:netherrack)
B(3,17,1,minecraft:netherrack)
B(3,18,1,minecraft:netherrack)
B(3,19,1,minecraft:netherrack)
B(3,20,1,minecraft:netherrack)
B(3,21,1,minecraft:netherrack)
B(3,22,1,minecraft:netherrack)
B(3,23,1,minecraft:netherrack)
B(3,24,1,minecraft:netherrack)
B(3,25,1,minecraft:netherrack)
B(3,26,1,minecraft:netherrack)
B(3,27,1,minecraft:netherrack)
B(3,28,1,minecraft:netherrack)
B(3,29,1,minecraft:netherrack)
B(3,30,1,minecraft:netherrack)
B(3,31,1,minecraft:netherrack)
B(3,0,2,minecraft:netherrack)
B(3,1,2,minecraft:netherrack)
B(3,2,2,minecraft:netherrack)
B(3,3,2,minecraft:netherrack)
B(3,4,2,minecraft:netherrack)
B(3,5,2,minecraft:netherrack)
B(3,6,2,minecraft:netherrack)
B(3,7,2,minecraft:netherrack)
B(3,8,2,minecraft:netherrack)
B(3,9,2,minecraft:netherrack)
B(3,10,2,minecraft:netherrack)
B(3,11,2,minecraft:netherrack)
B(3,12,2,minecraft:netherrack)
B(3,13,2,minecraft:netherrack)
B(3,14,2,minecraft:netherrack)
B(3,15,2,minecraft:netherrack)
B(3,16,2,minecraft:netherrack)
B(3,17,2,minecraft:netherrack)
B(3,18,2,minecraft:netherrack)
B(3,19,2,minecraft:netherrack)
B(3,20,2,minecraft:netherrack)
B(3,21,2,minecraft:netherrack)
B(3,22,2,minecraft:netherrack)
B(3,23,2,minecraft:netherrack)
B(3,24,2,minecraft:netherrack)
B(3,25,2,minecraft:netherrack)
B(3,26,2,minecraft:netherrack)
B(3,27,2,minecraft:netherrack)
B(3,28,2,minecraft:netherrack)
B(3,29,2,minecraft:netherrack)
B(3,30,2,minecraft:netherrack)
B(3,0,3,minecraft:netherrack)
B(3,1,3,minecraft:netherrack)
B(3,2,3,minecraft:netherrack)
B(3,3,3,minecraft:netherrack)
B(3,4,3,minecraft:netherrack)
B(3,5,3,minecraft:netherrack)
B(3,6,3,minecraft:netherrack)
B(3,7,3,minecraft:netherrack)
B(3,8,3,minecraft:netherrack)
B(3,9,3,minecraft:netherrack)
B(3,10,3,minecraft:netherrack)
B(3,11,3,minecraft:netherrack)
B(3,12,3,minecraft:netherrack)
B(3,13,3,minecraft:netherrack)
B(3,14,3,minecraft:netherrack)
B(3,15,3,minecraft:netherrack)
B(3,16,3,minecraft:netherrack)
B(3,17,3,minecraft:netherrack)
B(3,18,3,minecraft:netherrack)
B(3,19,3,minecraft:netherrack)
B(3,20,3,minecraft:netherrack)
B(3,21,3,minecraft:netherrack)
B(3,22,3,minecraft:netherrack)
B(3,23,3,minecraft:netherrack)
B(3,24,3,minecraft:netherrack)
B(3,25,3,minecraft:netherrack)
B(3,26,3,minecraft:netherrack)
B(3,27,3,minecraft:netherrack)
B(3,28,3,minecraft:netherrack)
B(3,29,3,minecraft:netherrack)
B(3,30,3,minecraft:netherrack)
B(3,31,3,minecraft:netherrack)
B(3,0,4,minecraft:netherrack)
B(3,1,4,minecraft:netherrack)
B(3,2,4,minecraft:netherrack)
B(3,3,4,minecraft:netherrack)
B(3,4,4,minecraft:netherrack)
B(3,5,4,minecraft:netherrack)
B(3,6,4,minecraft:netherrack)
B(3,7,4,minecraft:netherrack)
B(3,8,4,minecraft:netherrack)
B(3,9,4,minecraft:netherrack)
B(3,10,4,minecraft:netherrack)
B(3,11,4,minecraft:netherrack)
B(3,12,4,minecraft:netherrack)
B(3,13,4,minecraft:netherrack)
B(3,14,4,minecraft:netherrack)
B(3,15,4,minecraft:netherrack)
B(3,16,4,minecraft:netherrack)
B(3,17,4,minecraft:netherrack)
B(3,18,4,minecraft:netherrack)
B(3,19,4,minecraft:netherrack)
B(3,20,4,minecraft:netherrack)
B(3,21,4,minecraft:netherrack)
B(3,22,4,minecraft:netherrack)
B(3,23,4,minecraft:netherrack)
B(3,24,4,minecraft:netherrack)
B(3,25,4,minecraft:netherrack)
B(3,26,4,minecraft:netherrack)
B(3,27,4,minecraft:netherrack)
B(3,28,4,minecraft:netherrack)
B(3,0,5,minecraft:netherrack)
B(3,1,5,minecraft:netherrack)
B(3,2,5,minecraft:netherrack)
B(3,3,5,minecraft:netherrack)
B(3,4,5,minecraft:netherrack)
B(3,5,5,minecraft:netherrack)
B(3,6,5,minecraft:netherrack)
B(3,7,5,minecraft:netherrack)
B(3,8,5,minecraft:netherrack)
B(3,9,5,minecraft:netherrack)
B(3,10,5,minecraft:netherrack)
B(3,11,5,minecraft:netherrack)
B(3,12,5,minecraft:netherrack)
B(3,13,5,minecraft:netherrack)
B(3,14,5,minecraft:netherrack)
B(3,15,5,minecraft:netherrack)
B(3,16,5,minecraft:netherrack)
B(3,17,5,minecraft:netherrack)
B(3,18,5,minecraft:netherrack)
B(3,19,5,minecraft:netherrack)
B(3,20,5,minecraft:netherrack)
B(3,21,5,minecraft:netherrack)
B(3,22,5,minecraft:netherrack)
B(3,23,5,minecraft:netherrack)
B(3,24,5,minecraft:netherrack)
B(3,25,5,minecraft:netherrack)
B(3,26,5,minecraft:netherrack)
B(3,27,5,minecraft:netherrack)
B(3,28,5,minecraft:netherrack)
B(3,0,6,minecraft:netherrack)
B(3,1,6,minecraft:netherrack)
B(3,2,6,minecraft:netherrack)
B(3,3,6,minecraft:netherrack)
B(3,4,6,minecraft:netherrack)
B(3,5,6,minecraft:netherrack)
B(3,6,6,minecraft:netherrack)
B(3,7,6,minecraft:netherrack)
B(3,8,6,minecraft:netherrack)
B(3,9,6,minecraft:netherrack)
B(3,10,6,minecraft:netherrack)
B(3,11,6,minecraft:netherrack)
B(3,12,6,minecraft:netherrack)
B(3,13,6,minecraft:netherrack)
B(3,14,6,minecraft:netherrack)
B(3,15,6,minecraft:netherrack)
B(3,16,6,minecraft:netherrack)
B(3,17,6,minecraft:netherrack)
B(3,18,6,minecraft:netherrack)
B(3,19,6,minecraft:netherrack)
B(3,20,6,minecraft:netherrack)
B(3,21,6,minecraft:netherrack)
B(3,22,6,minecraft:netherrack)
B(3,23,6,minecraft:netherrack)
B(3,24,6,minecraft:netherrack)
B(3,25,6,minecraft:netherrack)
B(3,26,6,minecraft:netherrack)
B(3,27,6,minecraft:netherrack)
B(3,28,6,minecraft:netherrack)
B(3,29,6,minecraft:netherrack)
B(3,30,6,minecraft:netherrack)
B(3,31,6,minecraft:netherrack)
B(3,0,7,minecraft:netherrack)
B(3,1,7,minecraft:netherrack)
B(3,2,7,minecraft:netherrack)
B(3,3,7,minecraft:netherrack)
B(3,4,7,minecraft:netherrack)
B(3,5,7,minecraft:netherrack)
B(3,6,7,minecraft:netherrack)
B(3,7,7,minecraft:netherrack)
B(3,8,7,minecraft:netherrack)
B(3,9,7,minecraft:netherrack)
B(3,10,7,minecraft:netherrack)
B(3,11,7,minecraft:netherrack)
B(3,12,7,minecraft:netherrack)
B(3,13,7,minecraft:netherrack)
B(3,14,7,minecraft:netherrack)
B(3,15,7,minecraft:netherrack)
B(3,16,7,minecraft:netherrack)
B(3,17,7,minecraft:netherrack)
B(3,18,7,minecraft:netherrack)
B(3,19,7,minecraft:netherrack)
B(3,20,7,minecraft:netherrack)
B(3,21,7,minecraft:netherrack)
B(3,22,7,minecraft:netherrack)
B(3,23,7,minecraft:netherrack)
B(3,24,7,minecraft:netherrack)
B(3,25,7,minecraft:netherrack)
B(3,26,7,minecraft:netherrack)
B(3,27,7,minecraft:netherrack)
B(3,28,7,minecraft:netherrack)
B(3,29,7,minecraft:netherrack)
B(3,30,7,minecraft:netherrack)
B(3,31,7,minecraft:netherrack)
B(3,32,7,minecraft:netherrack)
B(3,33,7,minecraft:netherrack)
B(3,34,7,minecraft:netherrack)
B(3,35,7,minecraft:netherrack)
B(3,36,7,minecraft:netherrack)
B(3,37,7,minecraft:netherrack)
B(3,38,7,minecraft:netherrack)
B(3,39,7,minecraft:netherrack)
B(3,40,7,minecraft:netherrack)
B(3,41,7,minecraft:netherrack)
B(3,42,7,minecraft:netherrack)
B(3,43,7,minecraft:netherrack)
B(3,44,7,minecraft:netherrack)
B(3,45,7,minecraft:netherrack)
B(3,46,7,minecraft:netherrack)
B(3,47,7,minecraft:netherrack)
B(3,0,8,minecraft:netherrack)
B(3,1,8,minecraft:netherrack)
B(3,2,8,minecraft:netherrack)
B(3,3,8,minecraft:netherrack)
B(3,4,8,minecraft:netherrack)
B(3,5,8,minecraft:netherrack)
B(3,6,8,minecraft:netherrack)
B(3,7,8,minecraft:netherrack)
B(3,8,8,minecraft:netherrack)
B(3,9,8,minecraft:netherrack)
B(3,10,8,minecraft:netherrack)
B(3,11,8,minecraft:netherrack)
B(3,12,8,minecraft:netherrack)
B(3,13,8,minecraft:netherrack)
B(3,14,8,minecraft:netherrack)
B(3,15,8,minecraft:netherrack)
B(3,16,8,minecraft:netherrack)
B(3,17,8,minecraft:netherrack)
B(3,18,8,minecraft:netherrack)
B(3,19,8,minecraft:netherrack)
B(3,20,8,minecraft:netherrack)
B(3,21,8,minecraft:netherrack)
B(3,22,8,minecraft:netherrack)
B(3,23,8,minecraft:netherrack)
B(3,24,8,minecraft:netherrack)
B(3,25,8,minecraft:netherrack)
B(3,26,8,minecraft:netherrack)
B(3,27,8,minecraft:netherrack)
B(3,28,8,minecraft:netherrack)
B(3,29,8,minecraft:netherrack)
B(3,30,8,minecraft:netherrack)
B(3,31,8,minecraft:netherrack)
B(3,32,8,minecraft:netherrack)
B(3,33,8,minecraft:netherrack)
B(3,34,8,minecraft:netherrack)
B(3,35,8,minecraft:netherrack)
B(3,36,8,minecraft:netherrack)
B(3,37,8,minecraft:netherrack)
B(3,38,8,minecraft:netherrack)
B(3,39,8,minecraft:netherrack)
B(3,40,8,minecraft:netherrack)
B(3,41,8,minecraft:netherrack)
B(3,42,8,minecraft:netherrack)
B(3,43,8,minecraft:netherrack)
B(3,44,8,minecraft:netherrack)
B(3,45,8,minecraft:netherrack)
B(3,46,8,minecraft:netherrack)
B(3,47,8,minecraft:netherrack)
B(3,48,8,minecraft:netherrack)
B(3,49,8,minecraft:netherrack)
B(3,50,8,minecraft:netherrack)
B(3,51,8,minecraft:netherrack)
B(3,52,8,minecraft:netherrack)
B(3,53,8,minecraft:netherrack)
B(3,54,8,minecraft:netherrack)
B(3,55,8,minecraft:netherrack)
B(3,56,8,minecraft:netherrack)
B(3,57,8,minecraft:netherrack)
B(3,58,8,minecraft:netherrack)
B(3,59,8,minecraft:netherrack)
B(3,60,8,minecraft:netherrack)
B(3,61,8,minecraft:netherrack)
B(3,62,8,minecraft:netherrack)
B(3,63,8,minecraft:netherrack)
B(3,64,8,minecraft:netherrack)
B(3,65,8,minecraft:netherrack)
B(4,0,-7,minecraft:netherrack)
B(4,1,-7,minecraft:netherrack)
B(4,2,-7,minecraft:netherrack)
B(4,3,-7,minecraft:netherrack)
B(4,4,-7,minecraft:netherrack)
B(4,5,-7,minecraft:netherrack)
B(4,6,-7,minecraft:netherrack)
B(4,7,-7,minecraft:netherrack)
B(4,8,-7,minecraft:netherrack)
B(4,9,-7,minecraft:netherrack)
B(4,10,-7,minecraft:netherrack)
B(4,11,-7,minecraft:netherrack)
B(4,12,-7,minecraft:netherrack)
B(4,0,-6,minecraft:netherrack)
B(4,1,-6,minecraft:netherrack)
B(4,2,-6,minecraft:netherrack)
B(4,3,-6,minecraft:netherrack)
B(4,4,-6,minecraft:netherrack)
B(4,5,-6,minecraft:netherrack)
B(4,6,-6,minecraft:netherrack)
B(4,7,-6,minecraft:netherrack)
B(4,8,-6,minecraft:netherrack)
B(4,9,-6,minecraft:netherrack)
B(4,10,-6,minecraft:netherrack)
B(4,11,-6,minecraft:netherrack)
B(4,0,-5,minecraft:netherrack)
B(4,1,-5,minecraft:netherrack)
B(4,2,-5,minecraft:netherrack)
B(4,3,-5,minecraft:netherrack)
B(4,4,-5,minecraft:netherrack)
B(4,5,-5,minecraft:netherrack)
B(4,6,-5,minecraft:netherrack)
B(4,7,-5,minecraft:netherrack)
B(4,8,-5,minecraft:netherrack)
B(4,9,-5,minecraft:netherrack)
B(4,10,-5,minecraft:netherrack)
B(4,11,-5,minecraft:netherrack)
B(4,12,-5,minecraft:netherrack)
B(4,13,-5,minecraft:netherrack)
B(4,0,-4,minecraft:netherrack)
B(4,1,-4,minecraft:netherrack)
B(4,2,-4,minecraft:netherrack)
B(4,3,-4,minecraft:netherrack)
B(4,4,-4,minecraft:netherrack)
B(4,5,-4,minecraft:netherrack)
B(4,6,-4,minecraft:netherrack)
B(4,7,-4,minecraft:netherrack)
B(4,8,-4,minecraft:netherrack)
B(4,9,-4,minecraft:netherrack)
B(4,10,-4,minecraft:netherrack)
B(4,11,-4,minecraft:netherrack)
B(4,12,-4,minecraft:netherrack)
B(4,13,-4,minecraft:netherrack)
B(4,14,-4,minecraft:netherrack)
B(4,15,-4,minecraft:netherrack)
B(4,16,-4,minecraft:netherrack)
B(4,17,-4,minecraft:netherrack)
B(4,0,-3,minecraft:netherrack)
B(4,1,-3,minecraft:netherrack)
B(4,2,-3,minecraft:netherrack)
B(4,3,-3,minecraft:netherrack)
B(4,4,-3,minecraft:netherrack)
B(4,5,-3,minecraft:netherrack)
B(4,6,-3,minecraft:netherrack)
B(4,7,-3,minecraft:netherrack)
B(4,8,-3,minecraft:netherrack)
B(4,9,-3,minecraft:netherrack)
B(4,10,-3,minecraft:netherrack)
B(4,11,-3,minecraft:netherrack)
B(4,12,-3,minecraft:netherrack)
B(4,13,-3,minecraft:netherrack)
B(4,14,-3,minecraft:netherrack)
B(4,15,-3,minecraft:netherrack)
B(4,16,-3,minecraft:netherrack)
B(4,17,-3,minecraft:netherrack)
B(4,18,-3,minecraft:netherrack)
B(4,19,-3,minecraft:netherrack)
B(4,20,-3,minecraft:netherrack)
B(4,0,-2,minecraft:netherrack)
B(4,1,-2,minecraft:netherrack)
B(4,2,-2,minecraft:netherrack)
B(4,3,-2,minecraft:netherrack)
B(4,4,-2,minecraft:netherrack)
B(4,5,-2,minecraft:netherrack)
B(4,6,-2,minecraft:netherrack)
B(4,7,-2,minecraft:netherrack)
B(4,8,-2,minecraft:netherrack)
B(4,9,-2,minecraft:netherrack)
B(4,10,-2,minecraft:netherrack)
B(4,11,-2,minecraft:netherrack)
B(4,12,-2,minecraft:netherrack)
B(4,13,-2,minecraft:netherrack)
B(4,14,-2,minecraft:netherrack)
B(4,15,-2,minecraft:netherrack)
B(4,16,-2,minecraft:netherrack)
B(4,17,-2,minecraft:netherrack)
B(4,18,-2,minecraft:netherrack)
B(4,19,-2,minecraft:netherrack)
B(4,20,-2,minecraft:netherrack)
B(4,21,-2,minecraft:netherrack)
B(4,22,-2,minecraft:netherrack)
B(4,23,-2,minecraft:netherrack)
B(4,24,-2,minecraft:netherrack)
B(4,25,-2,minecraft:netherrack)
B(4,26,-2,minecraft:netherrack)
B(4,27,-2,minecraft:netherrack)
B(4,0,-1,minecraft:netherrack)
B(4,1,-1,minecraft:netherrack)
B(4,2,-1,minecraft:netherrack)
B(4,3,-1,minecraft:netherrack)
B(4,4,-1,minecraft:netherrack)
B(4,5,-1,minecraft:netherrack)
B(4,6,-1,minecraft:netherrack)
B(4,7,-1,minecraft:netherrack)
B(4,8,-1,minecraft:netherrack)
B(4,9,-1,minecraft:netherrack)
B(4,10,-1,minecraft:netherrack)
B(4,11,-1,minecraft:netherrack)
B(4,12,-1,minecraft:netherrack)
B(4,13,-1,minecraft:netherrack)
B(4,14,-1,minecraft:netherrack)
B(4,15,-1,minecraft:netherrack)
B(4,16,-1,minecraft:netherrack)
B(4,17,-1,minecraft:netherrack)
B(4,18,-1,minecraft:netherrack)
B(4,19,-1,minecraft:netherrack)
B(4,20,-1,minecraft:netherrack)
B(4,21,-1,minecraft:netherrack)
B(4,22,-1,minecraft:netherrack)
B(4,23,-1,minecraft:netherrack)
B(4,24,-1,minecraft:netherrack)
B(4,25,-1,minecraft:netherrack)
B(4,26,-1,minecraft:netherrack)
B(4,27,-1,minecraft:netherrack)
B(4,28,-1,minecraft:netherrack)
B(4,29,-1,minecraft:netherrack)
B(4,30,-1,minecraft:netherrack)
B(4,31,-1,minecraft:netherrack)
B(4,32,-1,minecraft:netherrack)
B(4,33,-1,minecraft:netherrack)
B(4,34,-1,minecraft:netherrack)
B(4,35,-1,minecraft:netherrack)
B(4,36,-1,minecraft:netherrack)
B(4,37,-1,minecraft:netherrack)
B(4,38,-1,minecraft:netherrack)
B(4,39,-1,minecraft:netherrack)
B(4,40,-1,minecraft:netherrack)
B(4,41,-1,minecraft:netherrack)
B(4,42,-1,minecraft:netherrack)
B(4,0,0,minecraft:netherrack)
B(4,1,0,minecraft:netherrack)
B(4,2,0,minecraft:netherrack)
B(4,3,0,minecraft:netherrack)
B(4,4,0,minecraft:netherrack)
B(4,5,0,minecraft:netherrack)
B(4,6,0,minecraft:netherrack)
B(4,7,0,minecraft:netherrack)
B(4,8,0,minecraft:netherrack)
B(4,9,0,minecraft:netherrack)
B(4,10,0,minecraft:netherrack)
B(4,11,0,minecraft:netherrack)
B(4,12,0,minecraft:netherrack)
B(4,13,0,minecraft:netherrack)
B(4,14,0,minecraft:netherrack)
B(4,15,0,minecraft:netherrack)
B(4,16,0,minecraft:netherrack)
B(4,17,0,minecraft:netherrack)
B(4,18,0,minecraft:netherrack)
B(4,19,0,minecraft:netherrack)
B(4,20,0,minecraft:netherrack)
B(4,21,0,minecraft:netherrack)
B(4,22,0,minecraft:netherrack)
B(4,23,0,minecraft:netherrack)
B(4,24,0,minecraft:netherrack)
B(4,25,0,minecraft:netherrack)
B(4,26,0,minecraft:netherrack)
B(4,27,0,minecraft:netherrack)
B(4,28,0,minecraft:netherrack)
B(4,29,0,minecraft:netherrack)
B(4,30,0,minecraft:netherrack)
B(4,31,0,minecraft:netherrack)
B(4,32,0,minecraft:netherrack)
B(4,33,0,minecraft:netherrack)
B(4,34,0,minecraft:netherrack)
B(4,35,0,minecraft:netherrack)
B(4,36,0,minecraft:netherrack)
B(4,37,0,minecraft:netherrack)
B(4,38,0,minecraft:netherrack)
B(4,39,0,minecraft:netherrack)
B(4,40,0,minecraft:netherrack)
B(4,41,0,minecraft:netherrack)
B(4,42,0,minecraft:netherrack)
B(4,43,0,minecraft:netherrack)
B(4,44,0,minecraft:netherrack)
B(4,45,0,minecraft:netherrack)
B(4,46,0,minecraft:netherrack)
B(4,47,0,minecraft:netherrack)
B(4,48,0,minecraft:netherrack)
B(4,49,0,minecraft:netherrack)
B(4,50,0,minecraft:netherrack)
B(4,51,0,minecraft:netherrack)
B(4,52,0,minecraft:netherrack)
B(4,53,0,minecraft:netherrack)
B(4,54,0,minecraft:netherrack)
B(4,55,0,minecraft:netherrack)
B(4,0,1,minecraft:netherrack)
B(4,1,1,minecraft:netherrack)
B(4,2,1,minecraft:netherrack)
B(4,3,1,minecraft:netherrack)
B(4,4,1,minecraft:netherrack)
B(4,5,1,minecraft:netherrack)
B(4,6,1,minecraft:netherrack)
B(4,7,1,minecraft:netherrack)
B(4,8,1,minecraft:netherrack)
B(4,9,1,minecraft:netherrack)
B(4,10,1,minecraft:netherrack)
B(4,11,1,minecraft:netherrack)
B(4,12,1,minecraft:netherrack)
B(4,13,1,minecraft:netherrack)
B(4,14,1,minecraft:netherrack)
B(4,15,1,minecraft:netherrack)
B(4,16,1,minecraft:netherrack)
B(4,17,1,minecraft:netherrack)
B(4,18,1,minecraft:netherrack)
B(4,19,1,minecraft:netherrack)
B(4,20,1,minecraft:netherrack)
B(4,21,1,minecraft:netherrack)
B(4,22,1,minecraft:netherrack)
B(4,23,1,minecraft:netherrack)
B(4,24,1,minecraft:netherrack)
B(4,25,1,minecraft:netherrack)
B(4,26,1,minecraft:netherrack)
B(4,27,1,minecraft:netherrack)
B(4,28,1,minecraft:netherrack)
B(4,29,1,minecraft:netherrack)
B(4,30,1,minecraft:netherrack)
B(4,31,1,minecraft:netherrack)
B(4,32,1,minecraft:netherrack)
B(4,33,1,minecraft:netherrack)
B(4,34,1,minecraft:netherrack)
B(4,35,1,minecraft:netherrack)
B(4,36,1,minecraft:netherrack)
B(4,37,1,minecraft:netherrack)
B(4,38,1,minecraft:netherrack)
B(4,39,1,minecraft:netherrack)
B(4,40,1,minecraft:netherrack)
B(4,41,1,minecraft:netherrack)
B(4,42,1,minecraft:netherrack)
B(4,43,1,minecraft:netherrack)
B(4,44,1,minecraft:netherrack)
B(4,45,1,minecraft:netherrack)
B(4,46,1,minecraft:netherrack)
B(4,47,1,minecraft:netherrack)
B(4,48,1,minecraft:netherrack)
B(4,49,1,minecraft:netherrack)
B(4,50,1,minecraft:netherrack)
B(4,51,1,minecraft:netherrack)
B(4,52,1,minecraft:netherrack)
B(4,53,1,minecraft:netherrack)
B(4,54,1,minecraft:netherrack)
B(4,55,1,minecraft:netherrack)
B(4,56,1,minecraft:netherrack)
B(4,57,1,minecraft:netherrack)
B(4,58,1,minecraft:netherrack)
B(4,59,1,minecraft:netherrack)
B(4,60,1,minecraft:netherrack)
B(4,61,1,minecraft:netherrack)
B(4,62,1,minecraft:netherrack)
B(4,63,1,minecraft:netherrack)
B(4,64,1,minecraft:netherrack)
B(4,0,2,minecraft:netherrack)
B(4,1,2,minecraft:netherrack)
B(4,2,2,minecraft:netherrack)
B(4,3,2,minecraft:netherrack)
B(4,4,2,minecraft:netherrack)
B(4,5,2,minecraft:netherrack)
B(4,6,2,minecraft:netherrack)
B(4,7,2,minecraft:netherrack)
B(4,8,2,minecraft:netherrack)
B(4,9,2,minecraft:netherrack)
B(4,10,2,minecraft:netherrack)
B(4,11,2,minecraft:netherrack)
B(4,12,2,minecraft:netherrack)
B(4,13,2,minecraft:netherrack)
B(4,14,2,minecraft:netherrack)
B(4,15,2,minecraft:netherrack)
B(4,16,2,minecraft:netherrack)
B(4,17,2,minecraft:netherrack)
B(4,18,2,minecraft:netherrack)
B(4,19,2,minecraft:netherrack)
B(4,20,2,minecraft:netherrack)
B(4,21,2,minecraft:netherrack)
B(4,22,2,minecraft:netherrack)
B(4,23,2,minecraft:netherrack)
B(4,24,2,minecraft:netherrack)
B(4,25,2,minecraft:netherrack)
B(4,26,2,minecraft:netherrack)
B(4,27,2,minecraft:netherrack)
B(4,28,2,minecraft:netherrack)
B(4,29,2,minecraft:netherrack)
B(4,30,2,minecraft:netherrack)
B(4,31,2,minecraft:netherrack)
B(4,32,2,minecraft:netherrack)
B(4,33,2,minecraft:netherrack)
B(4,34,2,minecraft:netherrack)
B(4,35,2,minecraft:netherrack)
B(4,36,2,minecraft:netherrack)
B(4,37,2,minecraft:netherrack)
B(4,38,2,minecraft:netherrack)
B(4,39,2,minecraft:netherrack)
B(4,40,2,minecraft:netherrack)
B(4,41,2,minecraft:netherrack)
B(4,42,2,minecraft:netherrack)
B(4,43,2,minecraft:netherrack)
B(4,44,2,minecraft:netherrack)
B(4,45,2,minecraft:netherrack)
B(4,46,2,minecraft:netherrack)
B(4,47,2,minecraft:netherrack)
B(4,48,2,minecraft:netherrack)
B(4,49,2,minecraft:netherrack)
B(4,50,2,minecraft:netherrack)
B(4,51,2,minecraft:netherrack)
B(4,52,2,minecraft:netherrack)
B(4,53,2,minecraft:netherrack)
B(4,54,2,minecraft:netherrack)
B(4,55,2,minecraft:netherrack)
B(4,56,2,minecraft:netherrack)
B(4,57,2,minecraft:netherrack)
B(4,58,2,minecraft:netherrack)
B(4,59,2,minecraft:netherrack)
B(4,60,2,minecraft:netherrack)
B(4,61,2,minecraft:netherrack)
B(4,62,2,minecraft:netherrack)
B(4,63,2,minecraft:netherrack)
B(4,64,2,minecraft:netherrack)
B(4,65,2,minecraft:netherrack)
B(4,66,2,minecraft:netherrack)
B(4,0,3,minecraft:netherrack)
B(4,1,3,minecraft:netherrack)
B(4,2,3,minecraft:netherrack)
B(4,3,3,minecraft:netherrack)
B(4,4,3,minecraft:netherrack)
B(4,5,3,minecraft:netherrack)
B(4,6,3,minecraft:netherrack)
B(4,7,3,minecraft:netherrack)
B(4,8,3,minecraft:netherrack)
B(4,9,3,minecraft:netherrack)
B(4,10,3,minecraft:netherrack)
B(4,11,3,minecraft:netherrack)
B(4,12,3,minecraft:netherrack)
B(4,13,3,minecraft:netherrack)
B(4,14,3,minecraft:netherrack)
B(4,15,3,minecraft:netherrack)
B(4,16,3,minecraft:netherrack)
B(4,17,3,minecraft:netherrack)
B(4,18,3,minecraft:netherrack)
B(4,19,3,minecraft:netherrack)
B(4,20,3,minecraft:netherrack)
B(4,21,3,minecraft:netherrack)
B(4,22,3,minecraft:netherrack)
B(4,23,3,minecraft:netherrack)
B(4,24,3,minecraft:netherrack)
B(4,25,3,minecraft:netherrack)
B(4,26,3,minecraft:netherrack)
B(4,27,3,minecraft:netherrack)
B(4,28,3,minecraft:netherrack)
B(4,29,3,minecraft:netherrack)
B(4,30,3,minecraft:netherrack)
B(4,31,3,minecraft:netherrack)
B(4,32,3,minecraft:netherrack)
B(4,33,3,minecraft:netherrack)
B(4,34,3,minecraft:netherrack)
B(4,35,3,minecraft:netherrack)
B(4,36,3,minecraft:netherrack)
B(4,37,3,minecraft:netherrack)
B(4,38,3,minecraft:netherrack)
B(4,39,3,minecraft:netherrack)
B(4,40,3,minecraft:netherrack)
B(4,41,3,minecraft:netherrack)
B(4,42,3,minecraft:netherrack)
B(4,43,3,minecraft:netherrack)
B(4,44,3,minecraft:netherrack)
B(4,45,3,minecraft:netherrack)
B(4,46,3,minecraft:netherrack)
B(4,47,3,minecraft:netherrack)
B(4,48,3,minecraft:netherrack)
B(4,49,3,minecraft:netherrack)
B(4,50,3,minecraft:netherrack)
B(4,51,3,minecraft:netherrack)
B(4,52,3,minecraft:netherrack)
B(4,53,3,minecraft:netherrack)
B(4,54,3,minecraft:netherrack)
B(4,55,3,minecraft:netherrack)
B(4,56,3,minecraft:netherrack)
B(4,57,3,minecraft:netherrack)
B(4,58,3,minecraft:netherrack)
B(4,59,3,minecraft:netherrack)
B(4,60,3,minecraft:netherrack)
B(4,0,4,minecraft:netherrack)
B(4,1,4,minecraft:netherrack)
B(4,2,4,minecraft:netherrack)
B(4,3,4,minecraft:netherrack)
B(4,4,4,minecraft:netherrack)
B(4,5,4,minecraft:netherrack)
B(4,6,4,minecraft:netherrack)
B(4,7,4,minecraft:netherrack)
B(4,8,4,minecraft:netherrack)
B(4,9,4,minecraft:netherrack)
B(4,10,4,minecraft:netherrack)
B(4,11,4,minecraft:netherrack)
B(4,12,4,minecraft:netherrack)
B(4,13,4,minecraft:netherrack)
B(4,14,4,minecraft:netherrack)
B(4,15,4,minecraft:netherrack)
B(4,16,4,minecraft:netherrack)
B(4,17,4,minecraft:netherrack)
B(4,18,4,minecraft:netherrack)
B(4,19,4,minecraft:netherrack)
B(4,20,4,minecraft:netherrack)
B(4,21,4,minecraft:netherrack)
B(4,22,4,minecraft:netherrack)
B(4,23,4,minecraft:netherrack)
B(4,24,4,minecraft:netherrack)
B(4,25,4,minecraft:netherrack)
B(4,26,4,minecraft:netherrack)
B(4,27,4,minecraft:netherrack)
B(4,28,4,minecraft:netherrack)
B(4,29,4,minecraft:netherrack)
B(4,30,4,minecraft:netherrack)
B(4,31,4,minecraft:netherrack)
B(4,32,4,minecraft:netherrack)
B(4,33,4,minecraft:netherrack)
B(4,34,4,minecraft:netherrack)
B(4,35,4,minecraft:netherrack)
B(4,36,4,minecraft:netherrack)
B(4,37,4,minecraft:netherrack)
B(4,38,4,minecraft:netherrack)
B(4,39,4,minecraft:netherrack)
B(4,40,4,minecraft:netherrack)
B(4,41,4,minecraft:netherrack)
B(4,42,4,minecraft:netherrack)
B(4,43,4,minecraft:netherrack)
B(4,44,4,minecraft:netherrack)
B(4,45,4,minecraft:netherrack)
B(4,46,4,minecraft:netherrack)
B(4,47,4,minecraft:netherrack)
B(4,48,4,minecraft:netherrack)
B(4,0,5,minecraft:netherrack)
B(4,1,5,minecraft:netherrack)
B(4,2,5,minecraft:netherrack)
B(4,3,5,minecraft:netherrack)
B(4,4,5,minecraft:netherrack)
B(4,5,5,minecraft:netherrack)
B(4,6,5,minecraft:netherrack)
B(4,7,5,minecraft:netherrack)
B(4,8,5,minecraft:netherrack)
B(4,9,5,minecraft:netherrack)
B(4,10,5,minecraft:netherrack)
B(4,11,5,minecraft:netherrack)
B(4,12,5,minecraft:netherrack)
B(4,13,5,minecraft:netherrack)
B(4,14,5,minecraft:netherrack)
B(4,15,5,minecraft:netherrack)
B(4,16,5,minecraft:netherrack)
B(4,17,5,minecraft:netherrack)
B(4,18,5,minecraft:netherrack)
B(4,19,5,minecraft:netherrack)
B(4,20,5,minecraft:netherrack)
B(4,21,5,minecraft:netherrack)
B(4,22,5,minecraft:netherrack)
B(4,23,5,minecraft:netherrack)
B(4,24,5,minecraft:netherrack)
B(4,25,5,minecraft:netherrack)
B(4,26,5,minecraft:netherrack)
B(4,27,5,minecraft:netherrack)
B(4,28,5,minecraft:netherrack)
B(4,29,5,minecraft:netherrack)
B(4,30,5,minecraft:netherrack)
B(4,31,5,minecraft:netherrack)
B(4,32,5,minecraft:netherrack)
B(4,33,5,minecraft:netherrack)
B(4,34,5,minecraft:netherrack)
B(4,35,5,minecraft:netherrack)
B(4,36,5,minecraft:netherrack)
B(4,37,5,minecraft:netherrack)
B(4,38,5,minecraft:netherrack)
B(4,39,5,minecraft:netherrack)
B(4,40,5,minecraft:netherrack)
B(4,0,6,minecraft:netherrack)
B(4,1,6,minecraft:netherrack)
B(4,2,6,minecraft:netherrack)
B(4,3,6,minecraft:netherrack)
B(4,4,6,minecraft:netherrack)
B(4,5,6,minecraft:netherrack)
B(4,6,6,minecraft:netherrack)
B(4,7,6,minecraft:netherrack)
B(4,8,6,minecraft:netherrack)
B(4,9,6,minecraft:netherrack)
B(4,10,6,minecraft:netherrack)
B(4,11,6,minecraft:netherrack)
B(4,12,6,minecraft:netherrack)
B(4,13,6,minecraft:netherrack)
B(4,14,6,minecraft:netherrack)
B(4,15,6,minecraft:netherrack)
B(4,16,6,minecraft:netherrack)
B(4,17,6,minecraft:netherrack)
B(4,18,6,minecraft:netherrack)
B(4,19,6,minecraft:netherrack)
B(4,20,6,minecraft:netherrack)
B(4,21,6,minecraft:netherrack)
B(4,22,6,minecraft:netherrack)
B(4,23,6,minecraft:netherrack)
B(4,24,6,minecraft:netherrack)
B(4,25,6,minecraft:netherrack)
B(4,26,6,minecraft:netherrack)
B(4,27,6,minecraft:netherrack)
B(4,28,6,minecraft:netherrack)
B(4,29,6,minecraft:netherrack)
B(4,30,6,minecraft:netherrack)
B(4,31,6,minecraft:netherrack)
B(4,32,6,minecraft:netherrack)
B(4,33,6,minecraft:netherrack)
B(4,34,6,minecraft:netherrack)
B(4,35,6,minecraft:netherrack)
B(4,36,6,minecraft:netherrack)
B(4,37,6,minecraft:netherrack)
B(4,38,6,minecraft:netherrack)
B(4,39,6,minecraft:netherrack)
B(4,40,6,minecraft:netherrack)
B(4,41,6,minecraft:netherrack)
B(4,42,6,minecraft:netherrack)
B(4,43,6,minecraft:netherrack)
B(4,44,6,minecraft:netherrack)
B(4,45,6,minecraft:netherrack)
B(4,0,7,minecraft:netherrack)
B(4,1,7,minecraft:netherrack)
B(4,2,7,minecraft:netherrack)
B(4,3,7,minecraft:netherrack)
B(4,4,7,minecraft:netherrack)
B(4,5,7,minecraft:netherrack)
B(4,6,7,minecraft:netherrack)
B(4,7,7,minecraft:netherrack)
B(4,8,7,minecraft:netherrack)
B(4,9,7,minecraft:netherrack)
B(4,10,7,minecraft:netherrack)
B(4,11,7,minecraft:netherrack)
B(4,12,7,minecraft:netherrack)
B(4,13,7,minecraft:netherrack)
B(4,14,7,minecraft:netherrack)
B(4,15,7,minecraft:netherrack)
B(4,16,7,minecraft:netherrack)
B(4,17,7,minecraft:netherrack)
B(4,18,7,minecraft:netherrack)
B(4,19,7,minecraft:netherrack)
B(4,20,7,minecraft:netherrack)
B(4,21,7,minecraft:netherrack)
B(4,22,7,minecraft:netherrack)
B(4,23,7,minecraft:netherrack)
B(4,24,7,minecraft:netherrack)
B(4,25,7,minecraft:netherrack)
B(4,26,7,minecraft:netherrack)
B(4,27,7,minecraft:netherrack)
B(4,28,7,minecraft:netherrack)
B(4,29,7,minecraft:netherrack)
B(4,30,7,minecraft:netherrack)
B(4,31,7,minecraft:netherrack)
B(4,32,7,minecraft:netherrack)
B(4,33,7,minecraft:netherrack)
B(4,34,7,minecraft:netherrack)
B(4,35,7,minecraft:netherrack)
B(4,36,7,minecraft:netherrack)
B(4,37,7,minecraft:netherrack)
B(4,38,7,minecraft:netherrack)
B(4,39,7,minecraft:netherrack)
B(4,40,7,minecraft:netherrack)
B(4,41,7,minecraft:netherrack)
B(4,42,7,minecraft:netherrack)
B(4,43,7,minecraft:netherrack)
B(4,44,7,minecraft:netherrack)
B(4,45,7,minecraft:netherrack)
B(4,46,7,minecraft:netherrack)
B(4,47,7,minecraft:netherrack)
B(4,48,7,minecraft:netherrack)
B(4,49,7,minecraft:netherrack)
B(4,50,7,minecraft:netherrack)
B(4,51,7,minecraft:netherrack)
B(4,52,7,minecraft:netherrack)
B(4,53,7,minecraft:netherrack)
B(4,54,7,minecraft:netherrack)
B(4,55,7,minecraft:netherrack)
B(4,56,7,minecraft:netherrack)
B(4,57,7,minecraft:netherrack)
B(4,58,7,minecraft:netherrack)
B(4,59,7,minecraft:netherrack)
B(4,60,7,minecraft:netherrack)
B(4,61,7,minecraft:netherrack)
B(4,62,7,minecraft:netherrack)
B(4,63,7,minecraft:netherrack)
B(4,0,8,minecraft:netherrack)
B(4,1,8,minecraft:netherrack)
B(4,2,8,minecraft:netherrack)
B(4,3,8,minecraft:netherrack)
B(4,4,8,minecraft:netherrack)
B(4,5,8,minecraft:netherrack)
B(4,6,8,minecraft:netherrack)
B(4,7,8,minecraft:netherrack)
B(4,8,8,minecraft:netherrack)
B(4,9,8,minecraft:netherrack)
B(4,10,8,minecraft:netherrack)
B(4,11,8,minecraft:netherrack)
B(4,12,8,minecraft:netherrack)
B(4,13,8,minecraft:netherrack)
B(4,14,8,minecraft:netherrack)
B(4,15,8,minecraft:netherrack)
B(4,16,8,minecraft:netherrack)
B(4,17,8,minecraft:netherrack)
B(4,18,8,minecraft:netherrack)
B(4,19,8,minecraft:netherrack)
B(4,20,8,minecraft:netherrack)
B(4,21,8,minecraft:netherrack)
B(4,22,8,minecraft:netherrack)
B(4,23,8,minecraft:netherrack)
B(4,24,8,minecraft:netherrack)
B(4,25,8,minecraft:netherrack)
B(4,26,8,minecraft:netherrack)
B(4,27,8,minecraft:netherrack)
B(4,28,8,minecraft:netherrack)
B(4,29,8,minecraft:netherrack)
B(4,30,8,minecraft:netherrack)
B(4,31,8,minecraft:netherrack)
B(4,32,8,minecraft:netherrack)
B(4,33,8,minecraft:netherrack)
B(4,34,8,minecraft:netherrack)
B(4,35,8,minecraft:netherrack)
B(4,36,8,minecraft:netherrack)
B(4,37,8,minecraft:netherrack)
B(4,38,8,minecraft:netherrack)
B(4,39,8,minecraft:netherrack)
B(4,40,8,minecraft:netherrack)
B(4,41,8,minecraft:netherrack)
B(4,42,8,minecraft:netherrack)
B(4,43,8,minecraft:netherrack)
B(4,44,8,minecraft:netherrack)
B(4,45,8,minecraft:netherrack)
B(4,46,8,minecraft:netherrack)
B(4,47,8,minecraft:netherrack)
B(4,48,8,minecraft:netherrack)
B(4,49,8,minecraft:netherrack)
B(4,50,8,minecraft:netherrack)
B(4,51,8,minecraft:netherrack)
B(4,52,8,minecraft:netherrack)
B(4,53,8,minecraft:netherrack)
B(4,54,8,minecraft:netherrack)
B(4,55,8,minecraft:netherrack)
B(4,56,8,minecraft:netherrack)
B(4,57,8,minecraft:netherrack)
B(4,58,8,minecraft:netherrack)
B(4,59,8,minecraft:netherrack)
B(4,60,8,minecraft:netherrack)
B(4,61,8,minecraft:netherrack)
B(4,62,8,minecraft:netherrack)
B(4,63,8,minecraft:netherrack)
B(4,64,8,minecraft:netherrack)
B(4,65,8,minecraft:netherrack)
B(4,66,8,minecraft:netherrack)
B(5,0,-7,minecraft:netherrack)
B(5,1,-7,minecraft:netherrack)
B(5,2,-7,minecraft:netherrack)
B(5,3,-7,minecraft:netherrack)
B(5,4,-7,minecraft:netherrack)
B(5,5,-7,minecraft:netherrack)
B(5,6,-7,minecraft:netherrack)
B(5,7,-7,minecraft:netherrack)
B(5,8,-7,minecraft:netherrack)
B(5,9,-7,minecraft:netherrack)
B(5,10,-7,minecraft:netherrack)
B(5,11,-7,minecraft:netherrack)
B(5,0,-6,minecraft:netherrack)
B(5,1,-6,minecraft:netherrack)
B(5,2,-6,minecraft:netherrack)
B(5,3,-6,minecraft:netherrack)
B(5,4,-6,minecraft:netherrack)
B(5,5,-6,minecraft:netherrack)
B(5,6,-6,minecraft:netherrack)
B(5,7,-6,minecraft:netherrack)
B(5,8,-6,minecraft:netherrack)
B(5,9,-6,minecraft:netherrack)
B(5,10,-6,minecraft:netherrack)
B(5,11,-6,minecraft:netherrack)
B(5,0,-5,minecraft:netherrack)
B(5,1,-5,minecraft:netherrack)
B(5,2,-5,minecraft:netherrack)
B(5,3,-5,minecraft:netherrack)
B(5,4,-5,minecraft:netherrack)
B(5,5,-5,minecraft:netherrack)
B(5,6,-5,minecraft:netherrack)
B(5,7,-5,minecraft:netherrack)
B(5,8,-5,minecraft:netherrack)
B(5,9,-5,minecraft:netherrack)
B(5,10,-5,minecraft:netherrack)
B(5,11,-5,minecraft:netherrack)
B(5,12,-5,minecraft:netherrack)
B(5,13,-5,minecraft:netherrack)
B(5,14,-5,minecraft:netherrack)
B(5,15,-5,minecraft:netherrack)
B(5,16,-5,minecraft:netherrack)
B(5,17,-5,minecraft:netherrack)
B(5,18,-5,minecraft:netherrack)
B(5,0,-4,minecraft:netherrack)
B(5,1,-4,minecraft:netherrack)
B(5,2,-4,minecraft:netherrack)
B(5,3,-4,minecraft:netherrack)
B(5,4,-4,minecraft:netherrack)
B(5,5,-4,minecraft:netherrack)
B(5,6,-4,minecraft:netherrack)
B(5,7,-4,minecraft:netherrack)
B(5,8,-4,minecraft:netherrack)
B(5,9,-4,minecraft:netherrack)
B(5,10,-4,minecraft:netherrack)
B(5,11,-4,minecraft:netherrack)
B(5,12,-4,minecraft:netherrack)
B(5,13,-4,minecraft:netherrack)
B(5,14,-4,minecraft:netherrack)
B(5,15,-4,minecraft:netherrack)
B(5,16,-4,minecraft:netherrack)
B(5,17,-4,minecraft:netherrack)
B(5,18,-4,minecraft:netherrack)
B(5,19,-4,minecraft:netherrack)
B(5,20,-4,minecraft:netherrack)
B(5,0,-3,minecraft:netherrack)
B(5,1,-3,minecraft:netherrack)
B(5,2,-3,minecraft:netherrack)
B(5,3,-3,minecraft:netherrack)
B(5,4,-3,minecraft:netherrack)
B(5,5,-3,minecraft:netherrack)
B(5,6,-3,minecraft:netherrack)
B(5,7,-3,minecraft:netherrack)
B(5,8,-3,minecraft:netherrack)
B(5,9,-3,minecraft:netherrack)
B(5,10,-3,minecraft:netherrack)
B(5,11,-3,minecraft:netherrack)
B(5,12,-3,minecraft:netherrack)
B(5,13,-3,minecraft:netherrack)
B(5,14,-3,minecraft:netherrack)
B(5,15,-3,minecraft:netherrack)
B(5,16,-3,minecraft:netherrack)
B(5,17,-3,minecraft:netherrack)
B(5,18,-3,minecraft:netherrack)
B(5,19,-3,minecraft:netherrack)
B(5,20,-3,minecraft:netherrack)
B(5,21,-3,minecraft:netherrack)
B(5,22,-3,minecraft:netherrack)
B(5,23,-3,minecraft:netherrack)
B(5,24,-3,minecraft:netherrack)
B(5,25,-3,minecraft:netherrack)
B(5,26,-3,minecraft:netherrack)
B(5,27,-3,minecraft:netherrack)
B(5,0,-2,minecraft:netherrack)
B(5,1,-2,minecraft:netherrack)
B(5,2,-2,minecraft:netherrack)
B(5,3,-2,minecraft:netherrack)
B(5,4,-2,minecraft:netherrack)
B(5,5,-2,minecraft:netherrack)
B(5,6,-2,minecraft:netherrack)
B(5,7,-2,minecraft:netherrack)
B(5,8,-2,minecraft:netherrack)
B(5,9,-2,minecraft:netherrack)
B(5,10,-2,minecraft:netherrack)
B(5,11,-2,minecraft:netherrack)
B(5,12,-2,minecraft:netherrack)
B(5,13,-2,minecraft:netherrack)
B(5,14,-2,minecraft:netherrack)
B(5,15,-2,minecraft:netherrack)
B(5,16,-2,minecraft:netherrack)
B(5,17,-2,minecraft:netherrack)
B(5,18,-2,minecraft:netherrack)
B(5,19,-2,minecraft:netherrack)
B(5,20,-2,minecraft:netherrack)
B(5,21,-2,minecraft:netherrack)
B(5,22,-2,minecraft:netherrack)
B(5,23,-2,minecraft:netherrack)
B(5,24,-2,minecraft:netherrack)
B(5,25,-2,minecraft:netherrack)
B(5,26,-2,minecraft:netherrack)
B(5,27,-2,minecraft:netherrack)
B(5,28,-2,minecraft:netherrack)
B(5,29,-2,minecraft:netherrack)
B(5,30,-2,minecraft:netherrack)
B(5,31,-2,minecraft:netherrack)
B(5,32,-2,minecraft:netherrack)
B(5,33,-2,minecraft:netherrack)
B(5,34,-2,minecraft:netherrack)
B(5,35,-2,minecraft:netherrack)
B(5,36,-2,minecraft:netherrack)
B(5,37,-2,minecraft:netherrack)
B(5,38,-2,minecraft:netherrack)
B(5,39,-2,minecraft:netherrack)
B(5,40,-2,minecraft:netherrack)
B(5,41,-2,minecraft:netherrack)
B(5,42,-2,minecraft:netherrack)
B(5,43,-2,minecraft:netherrack)
B(5,44,-2,minecraft:netherrack)
B(5,45,-2,minecraft:netherrack)
B(5,46,-2,minecraft:netherrack)
B(5,47,-2,minecraft:netherrack)
B(5,48,-2,minecraft:netherrack)
B(5,0,-1,minecraft:netherrack)
B(5,1,-1,minecraft:netherrack)
B(5,2,-1,minecraft:netherrack)
B(5,3,-1,minecraft:netherrack)
B(5,4,-1,minecraft:netherrack)
B(5,5,-1,minecraft:netherrack)
B(5,6,-1,minecraft:netherrack)
B(5,7,-1,minecraft:netherrack)
B(5,8,-1,minecraft:netherrack)
B(5,9,-1,minecraft:netherrack)
B(5,10,-1,minecraft:netherrack)
B(5,11,-1,minecraft:netherrack)
B(5,12,-1,minecraft:netherrack)
B(5,13,-1,minecraft:netherrack)
B(5,14,-1,minecraft:netherrack)
B(5,15,-1,minecraft:netherrack)
B(5,16,-1,minecraft:netherrack)
B(5,17,-1,minecraft:netherrack)
B(5,18,-1,minecraft:netherrack)
B(5,19,-1,minecraft:netherrack)
B(5,20,-1,minecraft:netherrack)
B(5,21,-1,minecraft:netherrack)
B(5,22,-1,minecraft:netherrack)
B(5,23,-1,minecraft:netherrack)
B(5,24,-1,minecraft:netherrack)
B(5,25,-1,minecraft:netherrack)
B(5,26,-1,minecraft:netherrack)
B(5,27,-1,minecraft:netherrack)
B(5,28,-1,minecraft:netherrack)
B(5,29,-1,minecraft:netherrack)
B(5,30,-1,minecraft:netherrack)
B(5,31,-1,minecraft:netherrack)
B(5,32,-1,minecraft:netherrack)
B(5,33,-1,minecraft:netherrack)
B(5,34,-1,minecraft:netherrack)
B(5,35,-1,minecraft:netherrack)
B(5,36,-1,minecraft:netherrack)
B(5,37,-1,minecraft:netherrack)
B(5,38,-1,minecraft:netherrack)
B(5,39,-1,minecraft:netherrack)
B(5,40,-1,minecraft:netherrack)
B(5,41,-1,minecraft:netherrack)
B(5,42,-1,minecraft:netherrack)
B(5,43,-1,minecraft:netherrack)
B(5,44,-1,minecraft:netherrack)
B(5,45,-1,minecraft:netherrack)
B(5,46,-1,minecraft:netherrack)
B(5,47,-1,minecraft:netherrack)
B(5,48,-1,minecraft:netherrack)
B(5,49,-1,minecraft:netherrack)
B(5,50,-1,minecraft:netherrack)
B(5,51,-1,minecraft:netherrack)
B(5,52,-1,minecraft:netherrack)
B(5,53,-1,minecraft:netherrack)
B(5,54,-1,minecraft:netherrack)
B(5,55,-1,minecraft:netherrack)
B(5,56,-1,minecraft:netherrack)
B(5,57,-1,minecraft:netherrack)
B(5,0,0,minecraft:netherrack)
B(5,1,0,minecraft:netherrack)
B(5,2,0,minecraft:netherrack)
B(5,3,0,minecraft:netherrack)
B(5,4,0,minecraft:netherrack)
B(5,5,0,minecraft:netherrack)
B(5,6,0,minecraft:netherrack)
B(5,7,0,minecraft:netherrack)
B(5,8,0,minecraft:netherrack)
B(5,9,0,minecraft:netherrack)
B(5,10,0,minecraft:netherrack)
B(5,11,0,minecraft:netherrack)
B(5,12,0,minecraft:netherrack)
B(5,13,0,minecraft:netherrack)
B(5,14,0,minecraft:netherrack)
B(5,15,0,minecraft:netherrack)
B(5,16,0,minecraft:netherrack)
B(5,17,0,minecraft:netherrack)
B(5,18,0,minecraft:netherrack)
B(5,19,0,minecraft:netherrack)
B(5,20,0,minecraft:netherrack)
B(5,21,0,minecraft:netherrack)
B(5,22,0,minecraft:netherrack)
B(5,23,0,minecraft:netherrack)
B(5,24,0,minecraft:netherrack)
B(5,25,0,minecraft:netherrack)
B(5,26,0,minecraft:netherrack)
B(5,27,0,minecraft:netherrack)
B(5,28,0,minecraft:netherrack)
B(5,29,0,minecraft:netherrack)
B(5,30,0,minecraft:netherrack)
B(5,31,0,minecraft:netherrack)
B(5,32,0,minecraft:netherrack)
B(5,33,0,minecraft:netherrack)
B(5,34,0,minecraft:netherrack)
B(5,35,0,minecraft:netherrack)
B(5,36,0,minecraft:netherrack)
B(5,37,0,minecraft:netherrack)
B(5,38,0,minecraft:netherrack)
B(5,39,0,minecraft:netherrack)
B(5,40,0,minecraft:netherrack)
B(5,41,0,minecraft:netherrack)
B(5,42,0,minecraft:netherrack)
B(5,43,0,minecraft:netherrack)
B(5,44,0,minecraft:netherrack)
B(5,45,0,minecraft:netherrack)
B(5,46,0,minecraft:netherrack)
B(5,47,0,minecraft:netherrack)
B(5,48,0,minecraft:netherrack)
B(5,49,0,minecraft:netherrack)
B(5,50,0,minecraft:netherrack)
B(5,51,0,minecraft:netherrack)
B(5,52,0,minecraft:netherrack)
B(5,53,0,minecraft:netherrack)
B(5,54,0,minecraft:netherrack)
B(5,55,0,minecraft:netherrack)
B(5,56,0,minecraft:netherrack)
B(5,57,0,minecraft:netherrack)
B(5,58,0,minecraft:netherrack)
B(5,59,0,minecraft:netherrack)
B(5,60,0,minecraft:netherrack)
B(5,61,0,minecraft:netherrack)
B(5,62,0,minecraft:netherrack)
B(5,63,0,minecraft:netherrack)
B(5,64,0,minecraft:netherrack)
B(5,65,0,minecraft:netherrack)
B(5,0,1,minecraft:netherrack)
B(5,1,1,minecraft:netherrack)
B(5,2,1,minecraft:netherrack)
B(5,3,1,minecraft:netherrack)
B(5,4,1,minecraft:netherrack)
B(5,5,1,minecraft:netherrack)
B(5,6,1,minecraft:netherrack)
B(5,7,1,minecraft:netherrack)
B(5,8,1,minecraft:netherrack)
B(5,9,1,minecraft:netherrack)
B(5,10,1,minecraft:netherrack)
B(5,11,1,minecraft:netherrack)
B(5,12,1,minecraft:netherrack)
B(5,13,1,minecraft:netherrack)
B(5,14,1,minecraft:netherrack)
B(5,15,1,minecraft:netherrack)
B(5,16,1,minecraft:netherrack)
B(5,17,1,minecraft:netherrack)
B(5,18,1,minecraft:netherrack)
B(5,19,1,minecraft:netherrack)
B(5,20,1,minecraft:netherrack)
B(5,21,1,minecraft:netherrack)
B(5,22,1,minecraft:netherrack)
B(5,23,1,minecraft:netherrack)
B(5,24,1,minecraft:netherrack)
B(5,25,1,minecraft:netherrack)
B(5,26,1,minecraft:netherrack)
B(5,27,1,minecraft:netherrack)
B(5,28,1,minecraft:netherrack)
B(5,29,1,minecraft:netherrack)
B(5,30,1,minecraft:netherrack)
B(5,31,1,minecraft:netherrack)
B(5,32,1,minecraft:netherrack)
B(5,33,1,minecraft:netherrack)
B(5,34,1,minecraft:netherrack)
B(5,35,1,minecraft:netherrack)
B(5,36,1,minecraft:netherrack)
B(5,37,1,minecraft:netherrack)
B(5,38,1,minecraft:netherrack)
B(5,39,1,minecraft:netherrack)
B(5,40,1,minecraft:netherrack)
B(5,41,1,minecraft:netherrack)
B(5,42,1,minecraft:netherrack)
B(5,43,1,minecraft:netherrack)
B(5,44,1,minecraft:netherrack)
B(5,45,1,minecraft:netherrack)
B(5,46,1,minecraft:netherrack)
B(5,47,1,minecraft:netherrack)
B(5,48,1,minecraft:netherrack)
B(5,49,1,minecraft:netherrack)
B(5,50,1,minecraft:netherrack)
B(5,51,1,minecraft:netherrack)
B(5,52,1,minecraft:netherrack)
B(5,53,1,minecraft:netherrack)
B(5,54,1,minecraft:netherrack)
B(5,55,1,minecraft:netherrack)
B(5,56,1,minecraft:netherrack)
B(5,57,1,minecraft:netherrack)
B(5,58,1,minecraft:netherrack)
B(5,59,1,minecraft:netherrack)
B(5,60,1,minecraft:netherrack)
B(5,61,1,minecraft:netherrack)
B(5,62,1,minecraft:netherrack)
B(5,63,1,minecraft:netherrack)
B(5,64,1,minecraft:netherrack)
B(5,65,1,minecraft:netherrack)
B(5,0,2,minecraft:netherrack)
B(5,1,2,minecraft:netherrack)
B(5,2,2,minecraft:netherrack)
B(5,3,2,minecraft:netherrack)
B(5,4,2,minecraft:netherrack)
B(5,5,2,minecraft:netherrack)
B(5,6,2,minecraft:netherrack)
B(5,7,2,minecraft:netherrack)
B(5,8,2,minecraft:netherrack)
B(5,9,2,minecraft:netherrack)
B(5,10,2,minecraft:netherrack)
B(5,11,2,minecraft:netherrack)
B(5,12,2,minecraft:netherrack)
B(5,13,2,minecraft:netherrack)
B(5,14,2,minecraft:netherrack)
B(5,15,2,minecraft:netherrack)
B(5,16,2,minecraft:netherrack)
B(5,17,2,minecraft:netherrack)
B(5,18,2,minecraft:netherrack)
B(5,19,2,minecraft:netherrack)
B(5,20,2,minecraft:netherrack)
B(5,21,2,minecraft:netherrack)
B(5,22,2,minecraft:netherrack)
B(5,23,2,minecraft:netherrack)
B(5,24,2,minecraft:netherrack)
B(5,25,2,minecraft:netherrack)
B(5,26,2,minecraft:netherrack)
B(5,27,2,minecraft:netherrack)
B(5,28,2,minecraft:netherrack)
B(5,29,2,minecraft:netherrack)
B(5,30,2,minecraft:netherrack)
B(5,31,2,minecraft:netherrack)
B(5,32,2,minecraft:netherrack)
B(5,33,2,minecraft:netherrack)
B(5,34,2,minecraft:netherrack)
B(5,35,2,minecraft:netherrack)
B(5,36,2,minecraft:netherrack)
B(5,37,2,minecraft:netherrack)
B(5,38,2,minecraft:netherrack)
B(5,39,2,minecraft:netherrack)
B(5,40,2,minecraft:netherrack)
B(5,41,2,minecraft:netherrack)
B(5,42,2,minecraft:netherrack)
B(5,43,2,minecraft:netherrack)
B(5,44,2,minecraft:netherrack)
B(5,45,2,minecraft:netherrack)
B(5,46,2,minecraft:netherrack)
B(5,47,2,minecraft:netherrack)
B(5,48,2,minecraft:netherrack)
B(5,49,2,minecraft:netherrack)
B(5,50,2,minecraft:netherrack)
B(5,51,2,minecraft:netherrack)
B(5,52,2,minecraft:netherrack)
B(5,53,2,minecraft:netherrack)
B(5,54,2,minecraft:netherrack)
B(5,55,2,minecraft:netherrack)
B(5,56,2,minecraft:netherrack)
B(5,57,2,minecraft:netherrack)
B(5,58,2,minecraft:netherrack)
B(5,59,2,minecraft:netherrack)
B(5,60,2,minecraft:netherrack)
B(5,61,2,minecraft:netherrack)
B(5,62,2,minecraft:netherrack)
B(5,63,2,minecraft:netherrack)
B(5,64,2,minecraft:netherrack)
B(5,65,2,minecraft:netherrack)
B(5,66,2,minecraft:netherrack)
B(5,0,3,minecraft:netherrack)
B(5,1,3,minecraft:netherrack)
B(5,2,3,minecraft:netherrack)
B(5,3,3,minecraft:netherrack)
B(5,4,3,minecraft:netherrack)
B(5,5,3,minecraft:netherrack)
B(5,6,3,minecraft:netherrack)
B(5,7,3,minecraft:netherrack)
B(5,8,3,minecraft:netherrack)
B(5,9,3,minecraft:netherrack)
B(5,10,3,minecraft:netherrack)
B(5,11,3,minecraft:netherrack)
B(5,12,3,minecraft:netherrack)
B(5,13,3,minecraft:netherrack)
B(5,14,3,minecraft:netherrack)
B(5,15,3,minecraft:netherrack)
B(5,16,3,minecraft:netherrack)
B(5,17,3,minecraft:netherrack)
B(5,18,3,minecraft:netherrack)
B(5,19,3,minecraft:netherrack)
B(5,20,3,minecraft:netherrack)
B(5,21,3,minecraft:netherrack)
B(5,22,3,minecraft:netherrack)
B(5,23,3,minecraft:netherrack)
B(5,24,3,minecraft:netherrack)
B(5,25,3,minecraft:netherrack)
B(5,26,3,minecraft:netherrack)
B(5,27,3,minecraft:netherrack)
B(5,28,3,minecraft:netherrack)
B(5,29,3,minecraft:netherrack)
B(5,30,3,minecraft:netherrack)
B(5,31,3,minecraft:netherrack)
B(5,32,3,minecraft:netherrack)
B(5,33,3,minecraft:netherrack)
B(5,34,3,minecraft:netherrack)
B(5,35,3,minecraft:netherrack)
B(5,36,3,minecraft:netherrack)
B(5,37,3,minecraft:netherrack)
B(5,38,3,minecraft:netherrack)
B(5,39,3,minecraft:netherrack)
B(5,40,3,minecraft:netherrack)
B(5,41,3,minecraft:netherrack)
B(5,42,3,minecraft:netherrack)
B(5,43,3,minecraft:netherrack)
B(5,44,3,minecraft:netherrack)
B(5,45,3,minecraft:netherrack)
B(5,46,3,minecraft:netherrack)
B(5,47,3,minecraft:netherrack)
B(5,48,3,minecraft:netherrack)
B(5,49,3,minecraft:netherrack)
B(5,50,3,minecraft:netherrack)
B(5,51,3,minecraft:netherrack)
B(5,52,3,minecraft:netherrack)
B(5,53,3,minecraft:netherrack)
B(5,54,3,minecraft:netherrack)
B(5,55,3,minecraft:netherrack)
B(5,56,3,minecraft:netherrack)
B(5,57,3,minecraft:netherrack)
B(5,58,3,minecraft:netherrack)
B(5,59,3,minecraft:netherrack)
B(5,60,3,minecraft:netherrack)
B(5,61,3,minecraft:netherrack)
B(5,62,3,minecraft:netherrack)
B(5,63,3,minecraft:netherrack)
B(5,64,3,minecraft:netherrack)
B(5,65,3,minecraft:netherrack)
B(5,66,3,minecraft:netherrack)
B(5,67,3,minecraft:netherrack)
B(5,0,4,minecraft:netherrack)
B(5,1,4,minecraft:netherrack)
B(5,2,4,minecraft:netherrack)
B(5,3,4,minecraft:netherrack)
B(5,4,4,minecraft:netherrack)
B(5,5,4,minecraft:netherrack)
B(5,6,4,minecraft:netherrack)
B(5,7,4,minecraft:netherrack)
B(5,8,4,minecraft:netherrack)
B(5,9,4,minecraft:netherrack)
B(5,10,4,minecraft:netherrack)
B(5,11,4,minecraft:netherrack)
B(5,12,4,minecraft:netherrack)
B(5,13,4,minecraft:netherrack)
B(5,14,4,minecraft:netherrack)
B(5,15,4,minecraft:netherrack)
B(5,16,4,minecraft:netherrack)
B(5,17,4,minecraft:netherrack)
B(5,18,4,minecraft:netherrack)
B(5,19,4,minecraft:netherrack)
B(5,20,4,minecraft:netherrack)
B(5,21,4,minecraft:netherrack)
B(5,22,4,minecraft:netherrack)
B(5,23,4,minecraft:netherrack)
B(5,24,4,minecraft:netherrack)
B(5,25,4,minecraft:netherrack)
B(5,26,4,minecraft:netherrack)
B(5,27,4,minecraft:netherrack)
B(5,28,4,minecraft:netherrack)
B(5,29,4,minecraft:netherrack)
B(5,30,4,minecraft:netherrack)
B(5,31,4,minecraft:netherrack)
B(5,32,4,minecraft:netherrack)
B(5,33,4,minecraft:netherrack)
B(5,34,4,minecraft:netherrack)
B(5,35,4,minecraft:netherrack)
B(5,36,4,minecraft:netherrack)
B(5,37,4,minecraft:netherrack)
B(5,38,4,minecraft:netherrack)
B(5,39,4,minecraft:netherrack)
B(5,40,4,minecraft:netherrack)
B(5,41,4,minecraft:netherrack)
B(5,42,4,minecraft:netherrack)
B(5,43,4,minecraft:netherrack)
B(5,44,4,minecraft:netherrack)
B(5,45,4,minecraft:netherrack)
B(5,46,4,minecraft:netherrack)
B(5,47,4,minecraft:netherrack)
B(5,48,4,minecraft:netherrack)
B(5,49,4,minecraft:netherrack)
B(5,50,4,minecraft:netherrack)
B(5,51,4,minecraft:netherrack)
B(5,52,4,minecraft:netherrack)
B(5,53,4,minecraft:netherrack)
B(5,54,4,minecraft:netherrack)
B(5,55,4,minecraft:netherrack)
B(5,56,4,minecraft:netherrack)
B(5,57,4,minecraft:netherrack)
B(5,58,4,minecraft:netherrack)
B(5,59,4,minecraft:netherrack)
B(5,60,4,minecraft:netherrack)
B(5,61,4,minecraft:netherrack)
B(5,62,4,minecraft:netherrack)
B(5,63,4,minecraft:netherrack)
B(5,64,4,minecraft:netherrack)
B(5,65,4,minecraft:netherrack)
B(5,66,4,minecraft:netherrack)
B(5,67,4,minecraft:netherrack)
B(5,0,5,minecraft:netherrack)
B(5,1,5,minecraft:netherrack)
B(5,2,5,minecraft:netherrack)
B(5,3,5,minecraft:netherrack)
B(5,4,5,minecraft:netherrack)
B(5,5,5,minecraft:netherrack)
B(5,6,5,minecraft:netherrack)
B(5,7,5,minecraft:netherrack)
B(5,8,5,minecraft:netherrack)
B(5,9,5,minecraft:netherrack)
B(5,10,5,minecraft:netherrack)
B(5,11,5,minecraft:netherrack)
B(5,12,5,minecraft:netherrack)
B(5,13,5,minecraft:netherrack)
B(5,14,5,minecraft:netherrack)
B(5,15,5,minecraft:netherrack)
B(5,16,5,minecraft:netherrack)
B(5,17,5,minecraft:netherrack)
B(5,18,5,minecraft:netherrack)
B(5,19,5,minecraft:netherrack)
B(5,20,5,minecraft:netherrack)
B(5,21,5,minecraft:netherrack)
B(5,22,5,minecraft:netherrack)
B(5,23,5,minecraft:netherrack)
B(5,24,5,minecraft:netherrack)
B(5,25,5,minecraft:netherrack)
B(5,26,5,minecraft:netherrack)
B(5,27,5,minecraft:netherrack)
B(5,28,5,minecraft:netherrack)
B(5,29,5,minecraft:netherrack)
B(5,30,5,minecraft:netherrack)
B(5,31,5,minecraft:netherrack)
B(5,32,5,minecraft:netherrack)
B(5,33,5,minecraft:netherrack)
B(5,34,5,minecraft:netherrack)
B(5,35,5,minecraft:netherrack)
B(5,36,5,minecraft:netherrack)
B(5,37,5,minecraft:netherrack)
B(5,38,5,minecraft:netherrack)
B(5,39,5,minecraft:netherrack)
B(5,40,5,minecraft:netherrack)
B(5,41,5,minecraft:netherrack)
B(5,42,5,minecraft:netherrack)
B(5,43,5,minecraft:netherrack)
B(5,44,5,minecraft:netherrack)
B(5,45,5,minecraft:netherrack)
B(5,46,5,minecraft:netherrack)
B(5,47,5,minecraft:netherrack)
B(5,48,5,minecraft:netherrack)
B(5,49,5,minecraft:netherrack)
B(5,50,5,minecraft:netherrack)
B(5,51,5,minecraft:netherrack)
B(5,52,5,minecraft:netherrack)
B(5,53,5,minecraft:netherrack)
B(5,54,5,minecraft:netherrack)
B(5,55,5,minecraft:netherrack)
B(5,56,5,minecraft:netherrack)
B(5,57,5,minecraft:netherrack)
B(5,58,5,minecraft:netherrack)
B(5,59,5,minecraft:netherrack)
B(5,60,5,minecraft:netherrack)
B(5,61,5,minecraft:netherrack)
B(5,62,5,minecraft:netherrack)
B(5,63,5,minecraft:netherrack)
B(5,64,5,minecraft:netherrack)
B(5,65,5,minecraft:netherrack)
B(5,66,5,minecraft:netherrack)
B(5,0,6,minecraft:netherrack)
B(5,1,6,minecraft:netherrack)
B(5,2,6,minecraft:netherrack)
B(5,3,6,minecraft:netherrack)
B(5,4,6,minecraft:netherrack)
B(5,5,6,minecraft:netherrack)
B(5,6,6,minecraft:netherrack)
B(5,7,6,minecraft:netherrack)
B(5,8,6,minecraft:netherrack)
B(5,9,6,minecraft:netherrack)
B(5,10,6,minecraft:netherrack)
B(5,11,6,minecraft:netherrack)
B(5,12,6,minecraft:netherrack)
B(5,13,6,minecraft:netherrack)
B(5,14,6,minecraft:netherrack)
B(5,15,6,minecraft:netherrack)
B(5,16,6,minecraft:netherrack)
B(5,17,6,minecraft:netherrack)
B(5,18,6,minecraft:netherrack)
B(5,19,6,minecraft:netherrack)
B(5,20,6,minecraft:netherrack)
B(5,21,6,minecraft:netherrack)
B(5,22,6,minecraft:netherrack)
B(5,23,6,minecraft:netherrack)
B(5,24,6,minecraft:netherrack)
B(5,25,6,minecraft:netherrack)
B(5,26,6,minecraft:netherrack)
B(5,27,6,minecraft:netherrack)
B(5,28,6,minecraft:netherrack)
B(5,29,6,minecraft:netherrack)
B(5,30,6,minecraft:netherrack)
B(5,31,6,minecraft:netherrack)
B(5,32,6,minecraft:netherrack)
B(5,33,6,minecraft:netherrack)
B(5,34,6,minecraft:netherrack)
B(5,35,6,minecraft:netherrack)
B(5,36,6,minecraft:netherrack)
B(5,37,6,minecraft:netherrack)
B(5,38,6,minecraft:netherrack)
B(5,39,6,minecraft:netherrack)
B(5,40,6,minecraft:netherrack)
B(5,41,6,minecraft:netherrack)
B(5,42,6,minecraft:netherrack)
B(5,43,6,minecraft:netherrack)
B(5,44,6,minecraft:netherrack)
B(5,45,6,minecraft:netherrack)
B(5,46,6,minecraft:netherrack)
B(5,47,6,minecraft:netherrack)
B(5,48,6,minecraft:netherrack)
B(5,49,6,minecraft:netherrack)
B(5,50,6,minecraft:netherrack)
B(5,51,6,minecraft:netherrack)
B(5,52,6,minecraft:netherrack)
B(5,53,6,minecraft:netherrack)
B(5,54,6,minecraft:netherrack)
B(5,55,6,minecraft:netherrack)
B(5,56,6,minecraft:netherrack)
B(5,57,6,minecraft:netherrack)
B(5,58,6,minecraft:netherrack)
B(5,59,6,minecraft:netherrack)
B(5,60,6,minecraft:netherrack)
B(5,61,6,minecraft:netherrack)
B(5,62,6,minecraft:netherrack)
B(5,63,6,minecraft:netherrack)
B(5,64,6,minecraft:netherrack)
B(5,65,6,minecraft:netherrack)
B(5,0,7,minecraft:netherrack)
B(5,1,7,minecraft:netherrack)
B(5,2,7,minecraft:netherrack)
B(5,3,7,minecraft:netherrack)
B(5,4,7,minecraft:netherrack)
B(5,5,7,minecraft:netherrack)
B(5,6,7,minecraft:netherrack)
B(5,7,7,minecraft:netherrack)
B(5,8,7,minecraft:netherrack)
B(5,9,7,minecraft:netherrack)
B(5,10,7,minecraft:netherrack)
B(5,11,7,minecraft:netherrack)
B(5,12,7,minecraft:netherrack)
B(5,13,7,minecraft:netherrack)
B(5,14,7,minecraft:netherrack)
B(5,15,7,minecraft:netherrack)
B(5,16,7,minecraft:netherrack)
B(5,17,7,minecraft:netherrack)
B(5,18,7,minecraft:netherrack)
B(5,19,7,minecraft:netherrack)
B(5,20,7,minecraft:netherrack)
B(5,21,7,minecraft:netherrack)
B(5,22,7,minecraft:netherrack)
B(5,23,7,minecraft:netherrack)
B(5,24,7,minecraft:netherrack)
B(5,25,7,minecraft:netherrack)
B(5,26,7,minecraft:netherrack)
B(5,27,7,minecraft:netherrack)
B(5,28,7,minecraft:netherrack)
B(5,29,7,minecraft:netherrack)
B(5,30,7,minecraft:netherrack)
B(5,31,7,minecraft:netherrack)
B(5,32,7,minecraft:netherrack)
B(5,33,7,minecraft:netherrack)
B(5,34,7,minecraft:netherrack)
B(5,35,7,minecraft:netherrack)
B(5,36,7,minecraft:netherrack)
B(5,37,7,minecraft:netherrack)
B(5,38,7,minecraft:netherrack)
B(5,39,7,minecraft:netherrack)
B(5,40,7,minecraft:netherrack)
B(5,41,7,minecraft:netherrack)
B(5,42,7,minecraft:netherrack)
B(5,43,7,minecraft:netherrack)
B(5,44,7,minecraft:netherrack)
B(5,45,7,minecraft:netherrack)
B(5,46,7,minecraft:netherrack)
B(5,47,7,minecraft:netherrack)
B(5,48,7,minecraft:netherrack)
B(5,49,7,minecraft:netherrack)
B(5,50,7,minecraft:netherrack)
B(5,51,7,minecraft:netherrack)
B(5,52,7,minecraft:netherrack)
B(5,53,7,minecraft:netherrack)
B(5,54,7,minecraft:netherrack)
B(5,55,7,minecraft:netherrack)
B(5,56,7,minecraft:netherrack)
B(5,57,7,minecraft:netherrack)
B(5,58,7,minecraft:netherrack)
B(5,59,7,minecraft:netherrack)
B(5,60,7,minecraft:netherrack)
B(5,61,7,minecraft:netherrack)
B(5,62,7,minecraft:netherrack)
B(5,63,7,minecraft:netherrack)
B(5,64,7,minecraft:netherrack)
B(5,65,7,minecraft:netherrack)
B(5,66,7,minecraft:netherrack)
B(5,67,7,minecraft:netherrack)
B(5,0,8,minecraft:netherrack)
B(5,1,8,minecraft:netherrack)
B(5,2,8,minecraft:netherrack)
B(5,3,8,minecraft:netherrack)
B(5,4,8,minecraft:netherrack)
B(5,5,8,minecraft:netherrack)
B(5,6,8,minecraft:netherrack)
B(5,7,8,minecraft:netherrack)
B(5,8,8,minecraft:netherrack)
B(5,9,8,minecraft:netherrack)
B(5,10,8,minecraft:netherrack)
B(5,11,8,minecraft:netherrack)
B(5,12,8,minecraft:netherrack)
B(5,13,8,minecraft:netherrack)
B(5,14,8,minecraft:netherrack)
B(5,15,8,minecraft:netherrack)
B(5,16,8,minecraft:netherrack)
B(5,17,8,minecraft:netherrack)
B(5,18,8,minecraft:netherrack)
B(5,19,8,minecraft:netherrack)
B(5,20,8,minecraft:netherrack)
B(5,21,8,minecraft:netherrack)
B(5,22,8,minecraft:netherrack)
B(5,23,8,minecraft:netherrack)
B(5,24,8,minecraft:netherrack)
B(5,25,8,minecraft:netherrack)
B(5,26,8,minecraft:netherrack)
B(5,27,8,minecraft:netherrack)
B(5,28,8,minecraft:netherrack)
B(5,29,8,minecraft:netherrack)
B(5,30,8,minecraft:netherrack)
B(5,31,8,minecraft:netherrack)
B(5,32,8,minecraft:netherrack)
B(5,33,8,minecraft:netherrack)
B(5,34,8,minecraft:netherrack)
B(5,35,8,minecraft:netherrack)
B(5,36,8,minecraft:netherrack)
B(5,37,8,minecraft:netherrack)
B(5,38,8,minecraft:netherrack)
B(5,39,8,minecraft:netherrack)
B(5,40,8,minecraft:netherrack)
B(5,41,8,minecraft:netherrack)
B(5,42,8,minecraft:netherrack)
B(5,43,8,minecraft:netherrack)
B(5,44,8,minecraft:netherrack)
B(5,45,8,minecraft:netherrack)
B(5,46,8,minecraft:netherrack)
B(5,47,8,minecraft:netherrack)
B(5,48,8,minecraft:netherrack)
B(5,49,8,minecraft:netherrack)
B(5,50,8,minecraft:netherrack)
B(5,51,8,minecraft:netherrack)
B(5,52,8,minecraft:netherrack)
B(5,53,8,minecraft:netherrack)
B(5,54,8,minecraft:netherrack)
B(5,55,8,minecraft:netherrack)
B(5,56,8,minecraft:netherrack)
B(5,57,8,minecraft:netherrack)
B(5,58,8,minecraft:netherrack)
B(5,59,8,minecraft:netherrack)
B(5,60,8,minecraft:netherrack)
B(5,61,8,minecraft:netherrack)
B(5,62,8,minecraft:netherrack)
B(5,63,8,minecraft:netherrack)
B(5,64,8,minecraft:netherrack)
B(5,65,8,minecraft:netherrack)
B(5,66,8,minecraft:netherrack)
B(6,0,-7,minecraft:netherrack)
B(6,1,-7,minecraft:netherrack)
