
#######################################################################
# +-----------------------------------------------------------------+ #
# |                            BO4 object                           | #
# +-----------------------------------------------------------------+ #
#######################################################################

Author: Unknown

Description: No description given

SettingsMode: WriteWithoutComments


#######################################################################
# +-----------------------------------------------------------------+ #
# |                          Main settings                          | #
# +-----------------------------------------------------------------+ #
#######################################################################

FixedRotation: 

Frequency: 0

SpawnHeight: highestBlock

UseCenterForHighestBlock: true

##############################
# Height Limits for the BO4. #
##############################

MinHeight: 0

MaxHeight: 255

InheritBO3: 

InheritBO3Rotation: NORTH

OverrideChildSettings: true

OverrideParentHeight: false

CanOverride: false

BranchFrequency: 0

BranchFrequencyGroup: 

MustBeBelowOther: false

MustBeInside: 

CannotBeInside: 

ReplacesBO3: 

MustBeInsideWorldBorders: false

CanSpawnOnWater: true

SpawnOnWaterOnly: false

SpawnUnderWater: false

SpawnAtWaterLevel: false

HeightOffset: 0

RemoveAir: true

ReplaceAbove: 

ReplaceBelow: 

ReplaceWithBiomeBlocks: true

ReplaceWithSurfaceBlock: GRASS

ReplaceWithGroundBlock: DIRT

ReplaceWithStoneBlock: STONE

SmoothRadius: 0

SmoothHeightOffset: 0

SmoothStartTop: false

SmoothStartWood: false

SmoothingSurfaceBlock: 

SmoothingGroundBlock: 

BO3Group: 

IsSpawnPoint: false

DoReplaceBlocks: true


#######################################################################
# +-----------------------------------------------------------------+ #
# |                              Blocks                             | #
# +-----------------------------------------------------------------+ #
#######################################################################

B(-8,53,7,minecraft:soul_sand)
B(-8,54,7,minecraft:soul_sand)
B(-8,55,7,minecraft:soul_sand)
B(-8,51,8,minecraft:soul_sand)
B(-8,52,8,minecraft:soul_sand)
B(-8,53,8,minecraft:soul_sand)
B(-8,54,8,minecraft:soul_sand)
B(-8,55,8,minecraft:soul_sand)
B(-7,54,6,minecraft:soul_sand)
B(-7,55,6,minecraft:soul_sand)
B(-7,52,7,minecraft:soul_sand)
B(-7,53,7,minecraft:soul_sand)
B(-7,54,7,minecraft:soul_sand)
B(-7,55,7,minecraft:soul_sand)
B(-7,49,8,minecraft:soul_sand)
B(-7,50,8,minecraft:soul_sand)
B(-7,51,8,minecraft:soul_sand)
B(-7,52,8,minecraft:soul_sand)
B(-7,53,8,minecraft:soul_sand)
B(-7,54,8,minecraft:soul_sand)
B(-7,55,8,minecraft:soul_sand)
B(-6,55,5,minecraft:soul_sand)
B(-6,53,6,minecraft:soul_sand)
B(-6,54,6,minecraft:soul_sand)
B(-6,55,6,minecraft:soul_sand)
B(-6,50,7,minecraft:soul_sand)
B(-6,51,7,minecraft:soul_sand)
B(-6,52,7,minecraft:soul_sand)
B(-6,53,7,minecraft:soul_sand)
B(-6,54,7,minecraft:soul_sand)
B(-6,55,7,minecraft:soul_sand)
B(-6,42,8,minecraft:soul_sand)
B(-6,43,8,minecraft:soul_sand)
B(-6,44,8,minecraft:soul_sand)
B(-6,45,8,minecraft:soul_sand)
B(-6,46,8,minecraft:soul_sand)
B(-6,47,8,minecraft:soul_sand)
B(-6,48,8,minecraft:soul_sand)
B(-6,49,8,minecraft:soul_sand)
B(-6,50,8,minecraft:soul_sand)
B(-6,51,8,minecraft:soul_sand)
B(-6,52,8,minecraft:soul_sand)
B(-6,53,8,minecraft:soul_sand)
B(-6,54,8,minecraft:soul_sand)
B(-6,55,8,minecraft:soul_sand)
B(-5,55,4,minecraft:soul_sand)
B(-5,53,5,minecraft:soul_sand)
B(-5,54,5,minecraft:soul_sand)
B(-5,55,5,minecraft:soul_sand)
B(-5,50,6,minecraft:soul_sand)
B(-5,51,6,minecraft:soul_sand)
B(-5,52,6,minecraft:soul_sand)
B(-5,53,6,minecraft:soul_sand)
B(-5,54,6,minecraft:soul_sand)
B(-5,55,6,minecraft:soul_sand)
B(-5,43,7,minecraft:soul_sand)
B(-5,44,7,minecraft:soul_sand)
B(-5,45,7,minecraft:soul_sand)
B(-5,46,7,minecraft:soul_sand)
B(-5,47,7,minecraft:soul_sand)
B(-5,48,7,minecraft:soul_sand)
B(-5,49,7,minecraft:soul_sand)
B(-5,50,7,minecraft:soul_sand)
B(-5,51,7,minecraft:soul_sand)
B(-5,52,7,minecraft:soul_sand)
B(-5,53,7,minecraft:soul_sand)
B(-5,54,7,minecraft:soul_sand)
B(-5,55,7,minecraft:soul_sand)
B(-5,41,8,minecraft:soul_sand)
B(-5,42,8,minecraft:soul_sand)
B(-5,43,8,minecraft:soul_sand)
B(-5,44,8,minecraft:soul_sand)
B(-5,45,8,minecraft:soul_sand)
B(-5,46,8,minecraft:soul_sand)
B(-5,47,8,minecraft:soul_sand)
B(-5,48,8,minecraft:soul_sand)
B(-5,49,8,minecraft:soul_sand)
B(-5,50,8,minecraft:soul_sand)
B(-5,51,8,minecraft:soul_sand)
B(-5,52,8,minecraft:soul_sand)
B(-5,53,8,minecraft:soul_sand)
B(-5,54,8,minecraft:soul_sand)
B(-5,55,8,minecraft:soul_sand)
B(-4,55,3,minecraft:soul_sand)
B(-4,53,4,minecraft:soul_sand)
B(-4,54,4,minecraft:soul_sand)
B(-4,55,4,minecraft:soul_sand)
B(-4,51,5,minecraft:soul_sand)
B(-4,52,5,minecraft:soul_sand)
B(-4,53,5,minecraft:soul_sand)
B(-4,54,5,minecraft:soul_sand)
B(-4,55,5,minecraft:soul_sand)
B(-4,48,6,minecraft:soul_sand)
B(-4,49,6,minecraft:soul_sand)
B(-4,50,6,minecraft:soul_sand)
B(-4,51,6,minecraft:soul_sand)
B(-4,52,6,minecraft:soul_sand)
B(-4,53,6,minecraft:soul_sand)
B(-4,54,6,minecraft:soul_sand)
B(-4,55,6,minecraft:soul_sand)
B(-4,42,7,minecraft:soul_sand)
B(-4,43,7,minecraft:soul_sand)
B(-4,44,7,minecraft:soul_sand)
B(-4,45,7,minecraft:soul_sand)
B(-4,46,7,minecraft:soul_sand)
B(-4,47,7,minecraft:soul_sand)
B(-4,48,7,minecraft:soul_sand)
B(-4,49,7,minecraft:soul_sand)
B(-4,50,7,minecraft:soul_sand)
B(-4,51,7,minecraft:soul_sand)
B(-4,52,7,minecraft:soul_sand)
B(-4,53,7,minecraft:soul_sand)
B(-4,54,7,minecraft:soul_sand)
B(-4,55,7,minecraft:soul_sand)
B(-4,38,8,minecraft:soul_sand)
B(-4,39,8,minecraft:soul_sand)
B(-4,40,8,minecraft:soul_sand)
B(-4,41,8,minecraft:soul_sand)
B(-4,42,8,minecraft:soul_sand)
B(-4,43,8,minecraft:soul_sand)
B(-4,44,8,minecraft:soul_sand)
B(-4,45,8,minecraft:soul_sand)
B(-4,46,8,minecraft:soul_sand)
B(-4,47,8,minecraft:soul_sand)
B(-4,48,8,minecraft:soul_sand)
B(-4,49,8,minecraft:soul_sand)
B(-4,50,8,minecraft:soul_sand)
B(-4,51,8,minecraft:soul_sand)
B(-4,52,8,minecraft:soul_sand)
B(-4,53,8,minecraft:soul_sand)
B(-4,54,8,minecraft:soul_sand)
B(-4,55,8,minecraft:soul_sand)
B(-3,55,2,minecraft:soul_sand)
B(-3,50,3,minecraft:soul_sand)
B(-3,51,3,minecraft:soul_sand)
B(-3,52,3,minecraft:soul_sand)
B(-3,53,3,minecraft:soul_sand)
B(-3,54,3,minecraft:soul_sand)
B(-3,55,3,minecraft:soul_sand)
B(-3,48,4,minecraft:soul_sand)
B(-3,49,4,minecraft:soul_sand)
B(-3,50,4,minecraft:soul_sand)
B(-3,51,4,minecraft:soul_sand)
B(-3,52,4,minecraft:soul_sand)
B(-3,53,4,minecraft:soul_sand)
B(-3,54,4,minecraft:soul_sand)
B(-3,55,4,minecraft:soul_sand)
B(-3,45,5,minecraft:soul_sand)
B(-3,46,5,minecraft:soul_sand)
B(-3,47,5,minecraft:soul_sand)
B(-3,48,5,minecraft:soul_sand)
B(-3,49,5,minecraft:soul_sand)
B(-3,50,5,minecraft:soul_sand)
B(-3,51,5,minecraft:soul_sand)
B(-3,52,5,minecraft:soul_sand)
B(-3,53,5,minecraft:soul_sand)
B(-3,54,5,minecraft:soul_sand)
B(-3,55,5,minecraft:soul_sand)
B(-3,42,6,minecraft:soul_sand)
B(-3,43,6,minecraft:soul_sand)
B(-3,44,6,minecraft:soul_sand)
B(-3,45,6,minecraft:soul_sand)
B(-3,46,6,minecraft:soul_sand)
B(-3,47,6,minecraft:soul_sand)
B(-3,48,6,minecraft:soul_sand)
B(-3,49,6,minecraft:soul_sand)
B(-3,50,6,minecraft:soul_sand)
B(-3,51,6,minecraft:soul_sand)
B(-3,52,6,minecraft:soul_sand)
B(-3,53,6,minecraft:soul_sand)
B(-3,54,6,minecraft:soul_sand)
B(-3,55,6,minecraft:soul_sand)
B(-3,40,7,minecraft:soul_sand)
B(-3,41,7,minecraft:soul_sand)
B(-3,42,7,minecraft:soul_sand)
B(-3,43,7,minecraft:soul_sand)
B(-3,44,7,minecraft:soul_sand)
B(-3,45,7,minecraft:soul_sand)
B(-3,46,7,minecraft:soul_sand)
B(-3,47,7,minecraft:soul_sand)
B(-3,48,7,minecraft:soul_sand)
B(-3,49,7,minecraft:soul_sand)
B(-3,50,7,minecraft:soul_sand)
B(-3,51,7,minecraft:soul_sand)
B(-3,52,7,minecraft:soul_sand)
B(-3,53,7,minecraft:soul_sand)
B(-3,54,7,minecraft:soul_sand)
B(-3,55,7,minecraft:soul_sand)
B(-3,37,8,minecraft:soul_sand)
B(-3,38,8,minecraft:soul_sand)
B(-3,39,8,minecraft:soul_sand)
B(-3,40,8,minecraft:soul_sand)
B(-3,41,8,minecraft:soul_sand)
B(-3,42,8,minecraft:soul_sand)
B(-3,43,8,minecraft:soul_sand)
B(-3,44,8,minecraft:soul_sand)
B(-3,45,8,minecraft:soul_sand)
B(-3,46,8,minecraft:soul_sand)
B(-3,47,8,minecraft:soul_sand)
B(-3,48,8,minecraft:soul_sand)
B(-3,49,8,minecraft:soul_sand)
B(-3,50,8,minecraft:soul_sand)
B(-3,51,8,minecraft:soul_sand)
B(-3,52,8,minecraft:soul_sand)
B(-3,53,8,minecraft:soul_sand)
B(-3,54,8,minecraft:soul_sand)
B(-3,55,8,minecraft:soul_sand)
B(-2,54,2,minecraft:soul_sand)
B(-2,55,2,minecraft:soul_sand)
B(-2,50,3,minecraft:soul_sand)
B(-2,51,3,minecraft:soul_sand)
B(-2,52,3,minecraft:soul_sand)
B(-2,53,3,minecraft:soul_sand)
B(-2,54,3,minecraft:soul_sand)
B(-2,55,3,minecraft:soul_sand)
B(-2,47,4,minecraft:soul_sand)
B(-2,48,4,minecraft:soul_sand)
B(-2,49,4,minecraft:soul_sand)
B(-2,50,4,minecraft:soul_sand)
B(-2,51,4,minecraft:soul_sand)
B(-2,52,4,minecraft:soul_sand)
B(-2,53,4,minecraft:soul_sand)
B(-2,54,4,minecraft:soul_sand)
B(-2,55,4,minecraft:soul_sand)
B(-2,45,5,minecraft:soul_sand)
B(-2,46,5,minecraft:soul_sand)
B(-2,47,5,minecraft:soul_sand)
B(-2,48,5,minecraft:soul_sand)
B(-2,49,5,minecraft:soul_sand)
B(-2,50,5,minecraft:soul_sand)
B(-2,51,5,minecraft:soul_sand)
B(-2,52,5,minecraft:soul_sand)
B(-2,53,5,minecraft:soul_sand)
B(-2,54,5,minecraft:soul_sand)
B(-2,55,5,minecraft:soul_sand)
B(-2,42,6,minecraft:soul_sand)
B(-2,43,6,minecraft:soul_sand)
B(-2,44,6,minecraft:soul_sand)
B(-2,45,6,minecraft:soul_sand)
B(-2,46,6,minecraft:soul_sand)
B(-2,47,6,minecraft:soul_sand)
B(-2,48,6,minecraft:soul_sand)
B(-2,49,6,minecraft:soul_sand)
B(-2,50,6,minecraft:soul_sand)
B(-2,51,6,minecraft:soul_sand)
B(-2,52,6,minecraft:soul_sand)
B(-2,53,6,minecraft:soul_sand)
B(-2,54,6,minecraft:soul_sand)
B(-2,55,6,minecraft:soul_sand)
B(-2,39,7,minecraft:soul_sand)
B(-2,40,7,minecraft:soul_sand)
B(-2,41,7,minecraft:soul_sand)
B(-2,42,7,minecraft:soul_sand)
B(-2,43,7,minecraft:soul_sand)
B(-2,44,7,minecraft:soul_sand)
B(-2,45,7,minecraft:soul_sand)
B(-2,46,7,minecraft:soul_sand)
B(-2,47,7,minecraft:soul_sand)
B(-2,48,7,minecraft:soul_sand)
B(-2,49,7,minecraft:soul_sand)
B(-2,50,7,minecraft:soul_sand)
B(-2,51,7,minecraft:soul_sand)
B(-2,52,7,minecraft:soul_sand)
B(-2,53,7,minecraft:soul_sand)
B(-2,54,7,minecraft:soul_sand)
B(-2,55,7,minecraft:soul_sand)
B(-2,36,8,minecraft:soul_sand)
B(-2,37,8,minecraft:soul_sand)
B(-2,38,8,minecraft:soul_sand)
B(-2,39,8,minecraft:soul_sand)
B(-2,40,8,minecraft:soul_sand)
B(-2,41,8,minecraft:soul_sand)
B(-2,42,8,minecraft:soul_sand)
B(-2,43,8,minecraft:soul_sand)
B(-2,44,8,minecraft:soul_sand)
B(-2,45,8,minecraft:soul_sand)
B(-2,46,8,minecraft:soul_sand)
B(-2,47,8,minecraft:soul_sand)
B(-2,48,8,minecraft:soul_sand)
B(-2,49,8,minecraft:soul_sand)
B(-2,50,8,minecraft:soul_sand)
B(-2,51,8,minecraft:soul_sand)
B(-2,52,8,minecraft:soul_sand)
B(-2,53,8,minecraft:soul_sand)
B(-2,54,8,minecraft:soul_sand)
B(-2,55,8,minecraft:soul_sand)
B(-1,55,1,minecraft:soul_sand)
B(-1,54,2,minecraft:soul_sand)
B(-1,55,2,minecraft:soul_sand)
B(-1,50,3,minecraft:soul_sand)
B(-1,51,3,minecraft:soul_sand)
B(-1,52,3,minecraft:soul_sand)
B(-1,53,3,minecraft:soul_sand)
B(-1,54,3,minecraft:soul_sand)
B(-1,55,3,minecraft:soul_sand)
B(-1,47,4,minecraft:soul_sand)
B(-1,48,4,minecraft:soul_sand)
B(-1,49,4,minecraft:soul_sand)
B(-1,50,4,minecraft:soul_sand)
B(-1,51,4,minecraft:soul_sand)
B(-1,52,4,minecraft:soul_sand)
B(-1,53,4,minecraft:soul_sand)
B(-1,54,4,minecraft:soul_sand)
B(-1,55,4,minecraft:soul_sand)
B(-1,44,5,minecraft:soul_sand)
B(-1,45,5,minecraft:soul_sand)
B(-1,46,5,minecraft:soul_sand)
B(-1,47,5,minecraft:soul_sand)
B(-1,48,5,minecraft:soul_sand)
B(-1,49,5,minecraft:soul_sand)
B(-1,50,5,minecraft:soul_sand)
B(-1,51,5,minecraft:soul_sand)
B(-1,52,5,minecraft:soul_sand)
B(-1,53,5,minecraft:soul_sand)
B(-1,54,5,minecraft:soul_sand)
B(-1,55,5,minecraft:soul_sand)
B(-1,41,6,minecraft:soul_sand)
B(-1,42,6,minecraft:soul_sand)
B(-1,43,6,minecraft:soul_sand)
B(-1,44,6,minecraft:soul_sand)
B(-1,45,6,minecraft:soul_sand)
B(-1,46,6,minecraft:soul_sand)
B(-1,47,6,minecraft:soul_sand)
B(-1,48,6,minecraft:soul_sand)
B(-1,49,6,minecraft:soul_sand)
B(-1,50,6,minecraft:soul_sand)
B(-1,51,6,minecraft:soul_sand)
B(-1,52,6,minecraft:soul_sand)
B(-1,53,6,minecraft:soul_sand)
B(-1,54,6,minecraft:soul_sand)
B(-1,55,6,minecraft:soul_sand)
B(-1,38,7,minecraft:soul_sand)
B(-1,39,7,minecraft:soul_sand)
B(-1,40,7,minecraft:soul_sand)
B(-1,41,7,minecraft:soul_sand)
B(-1,42,7,minecraft:soul_sand)
B(-1,43,7,minecraft:soul_sand)
B(-1,44,7,minecraft:soul_sand)
B(-1,45,7,minecraft:soul_sand)
B(-1,46,7,minecraft:soul_sand)
B(-1,47,7,minecraft:soul_sand)
B(-1,48,7,minecraft:soul_sand)
B(-1,49,7,minecraft:soul_sand)
B(-1,50,7,minecraft:soul_sand)
B(-1,51,7,minecraft:soul_sand)
B(-1,52,7,minecraft:soul_sand)
B(-1,53,7,minecraft:soul_sand)
B(-1,54,7,minecraft:soul_sand)
B(-1,55,7,minecraft:soul_sand)
B(-1,32,8,minecraft:soul_sand)
B(-1,33,8,minecraft:soul_sand)
B(-1,34,8,minecraft:soul_sand)
B(-1,35,8,minecraft:soul_sand)
B(-1,36,8,minecraft:soul_sand)
B(-1,37,8,minecraft:soul_sand)
B(-1,38,8,minecraft:soul_sand)
B(-1,39,8,minecraft:soul_sand)
B(-1,40,8,minecraft:soul_sand)
B(-1,41,8,minecraft:soul_sand)
B(-1,42,8,minecraft:soul_sand)
B(-1,43,8,minecraft:soul_sand)
B(-1,44,8,minecraft:soul_sand)
B(-1,45,8,minecraft:soul_sand)
B(-1,46,8,minecraft:soul_sand)
B(-1,47,8,minecraft:soul_sand)
B(-1,48,8,minecraft:soul_sand)
B(-1,49,8,minecraft:soul_sand)
B(-1,50,8,minecraft:soul_sand)
B(-1,51,8,minecraft:soul_sand)
B(-1,52,8,minecraft:soul_sand)
B(-1,53,8,minecraft:soul_sand)
B(-1,54,8,minecraft:soul_sand)
B(-1,55,8,minecraft:soul_sand)
B(0,50,3,minecraft:soul_sand)
B(0,51,3,minecraft:soul_sand)
B(0,52,3,minecraft:soul_sand)
B(0,53,3,minecraft:soul_sand)
B(0,54,3,minecraft:soul_sand)
B(0,55,3,minecraft:soul_sand)
B(0,47,4,minecraft:soul_sand)
B(0,48,4,minecraft:soul_sand)
B(0,49,4,minecraft:soul_sand)
B(0,50,4,minecraft:soul_sand)
B(0,51,4,minecraft:soul_sand)
B(0,52,4,minecraft:soul_sand)
B(0,53,4,minecraft:soul_sand)
B(0,54,4,minecraft:soul_sand)
B(0,55,4,minecraft:soul_sand)
B(0,44,5,minecraft:soul_sand)
B(0,45,5,minecraft:soul_sand)
B(0,46,5,minecraft:soul_sand)
B(0,47,5,minecraft:soul_sand)
B(0,48,5,minecraft:soul_sand)
B(0,49,5,minecraft:soul_sand)
B(0,50,5,minecraft:soul_sand)
B(0,51,5,minecraft:soul_sand)
B(0,52,5,minecraft:soul_sand)
B(0,53,5,minecraft:soul_sand)
B(0,54,5,minecraft:soul_sand)
B(0,55,5,minecraft:soul_sand)
B(0,41,6,minecraft:soul_sand)
B(0,42,6,minecraft:soul_sand)
B(0,43,6,minecraft:soul_sand)
B(0,44,6,minecraft:soul_sand)
B(0,45,6,minecraft:soul_sand)
B(0,46,6,minecraft:soul_sand)
B(0,47,6,minecraft:soul_sand)
B(0,48,6,minecraft:soul_sand)
B(0,49,6,minecraft:soul_sand)
B(0,50,6,minecraft:soul_sand)
B(0,51,6,minecraft:soul_sand)
B(0,52,6,minecraft:soul_sand)
B(0,53,6,minecraft:soul_sand)
B(0,54,6,minecraft:soul_sand)
B(0,55,6,minecraft:soul_sand)
B(0,38,7,minecraft:soul_sand)
B(0,39,7,minecraft:soul_sand)
B(0,40,7,minecraft:soul_sand)
B(0,41,7,minecraft:soul_sand)
B(0,42,7,minecraft:soul_sand)
B(0,43,7,minecraft:soul_sand)
B(0,44,7,minecraft:soul_sand)
B(0,45,7,minecraft:soul_sand)
B(0,46,7,minecraft:soul_sand)
B(0,47,7,minecraft:soul_sand)
B(0,48,7,minecraft:soul_sand)
B(0,49,7,minecraft:soul_sand)
B(0,50,7,minecraft:soul_sand)
B(0,51,7,minecraft:soul_sand)
B(0,52,7,minecraft:soul_sand)
B(0,53,7,minecraft:soul_sand)
B(0,54,7,minecraft:soul_sand)
B(0,55,7,minecraft:soul_sand)
B(0,31,8,minecraft:soul_sand)
B(0,32,8,minecraft:soul_sand)
B(0,33,8,minecraft:soul_sand)
B(0,34,8,minecraft:soul_sand)
B(0,35,8,minecraft:soul_sand)
B(0,36,8,minecraft:soul_sand)
B(0,37,8,minecraft:soul_sand)
B(0,38,8,minecraft:soul_sand)
B(0,39,8,minecraft:soul_sand)
B(0,40,8,minecraft:soul_sand)
B(0,41,8,minecraft:soul_sand)
B(0,42,8,minecraft:soul_sand)
B(0,43,8,minecraft:soul_sand)
B(0,44,8,minecraft:soul_sand)
B(0,45,8,minecraft:soul_sand)
B(0,46,8,minecraft:soul_sand)
B(0,47,8,minecraft:soul_sand)
B(0,48,8,minecraft:soul_sand)
B(0,49,8,minecraft:soul_sand)
B(0,50,8,minecraft:soul_sand)
B(0,51,8,minecraft:soul_sand)
B(0,52,8,minecraft:soul_sand)
B(0,53,8,minecraft:soul_sand)
B(0,54,8,minecraft:soul_sand)
B(0,55,8,minecraft:soul_sand)
B(1,54,3,minecraft:soul_sand)
B(1,55,3,minecraft:soul_sand)
B(1,47,4,minecraft:soul_sand)
B(1,48,4,minecraft:soul_sand)
B(1,49,4,minecraft:soul_sand)
B(1,50,4,minecraft:soul_sand)
B(1,51,4,minecraft:soul_sand)
B(1,52,4,minecraft:soul_sand)
B(1,53,4,minecraft:soul_sand)
B(1,54,4,minecraft:soul_sand)
B(1,55,4,minecraft:soul_sand)
B(1,44,5,minecraft:soul_sand)
B(1,45,5,minecraft:soul_sand)
B(1,46,5,minecraft:soul_sand)
B(1,47,5,minecraft:soul_sand)
B(1,48,5,minecraft:soul_sand)
B(1,49,5,minecraft:soul_sand)
B(1,50,5,minecraft:soul_sand)
B(1,51,5,minecraft:soul_sand)
B(1,52,5,minecraft:soul_sand)
B(1,53,5,minecraft:soul_sand)
B(1,54,5,minecraft:soul_sand)
B(1,55,5,minecraft:soul_sand)
B(1,41,6,minecraft:soul_sand)
B(1,42,6,minecraft:soul_sand)
B(1,43,6,minecraft:soul_sand)
B(1,44,6,minecraft:soul_sand)
B(1,45,6,minecraft:soul_sand)
B(1,46,6,minecraft:soul_sand)
B(1,47,6,minecraft:soul_sand)
B(1,48,6,minecraft:soul_sand)
B(1,49,6,minecraft:soul_sand)
B(1,50,6,minecraft:soul_sand)
B(1,51,6,minecraft:soul_sand)
B(1,52,6,minecraft:soul_sand)
B(1,53,6,minecraft:soul_sand)
B(1,54,6,minecraft:soul_sand)
B(1,55,6,minecraft:soul_sand)
B(1,39,7,minecraft:soul_sand)
B(1,40,7,minecraft:soul_sand)
B(1,41,7,minecraft:soul_sand)
B(1,42,7,minecraft:soul_sand)
B(1,43,7,minecraft:soul_sand)
B(1,44,7,minecraft:soul_sand)
B(1,45,7,minecraft:soul_sand)
B(1,46,7,minecraft:soul_sand)
B(1,47,7,minecraft:soul_sand)
B(1,48,7,minecraft:soul_sand)
B(1,49,7,minecraft:soul_sand)
B(1,50,7,minecraft:soul_sand)
B(1,51,7,minecraft:soul_sand)
B(1,52,7,minecraft:soul_sand)
B(1,53,7,minecraft:soul_sand)
B(1,54,7,minecraft:soul_sand)
B(1,55,7,minecraft:soul_sand)
B(1,32,8,minecraft:soul_sand)
B(1,33,8,minecraft:soul_sand)
B(1,34,8,minecraft:soul_sand)
B(1,35,8,minecraft:soul_sand)
B(1,36,8,minecraft:soul_sand)
B(1,37,8,minecraft:soul_sand)
B(1,38,8,minecraft:soul_sand)
B(1,39,8,minecraft:soul_sand)
B(1,40,8,minecraft:soul_sand)
B(1,41,8,minecraft:soul_sand)
B(1,42,8,minecraft:soul_sand)
B(1,43,8,minecraft:soul_sand)
B(1,44,8,minecraft:soul_sand)
B(1,45,8,minecraft:soul_sand)
B(1,46,8,minecraft:soul_sand)
B(1,47,8,minecraft:soul_sand)
B(1,48,8,minecraft:soul_sand)
B(1,49,8,minecraft:soul_sand)
B(1,50,8,minecraft:soul_sand)
B(1,51,8,minecraft:soul_sand)
B(1,52,8,minecraft:soul_sand)
B(1,53,8,minecraft:soul_sand)
B(1,54,8,minecraft:soul_sand)
B(1,55,8,minecraft:soul_sand)
B(2,49,4,minecraft:soul_sand)
B(2,50,4,minecraft:soul_sand)
B(2,51,4,minecraft:soul_sand)
B(2,52,4,minecraft:soul_sand)
B(2,53,4,minecraft:soul_sand)
B(2,54,4,minecraft:soul_sand)
B(2,55,4,minecraft:soul_sand)
B(2,46,5,minecraft:soul_sand)
B(2,47,5,minecraft:soul_sand)
B(2,48,5,minecraft:soul_sand)
B(2,49,5,minecraft:soul_sand)
B(2,50,5,minecraft:soul_sand)
B(2,51,5,minecraft:soul_sand)
B(2,52,5,minecraft:soul_sand)
B(2,53,5,minecraft:soul_sand)
B(2,54,5,minecraft:soul_sand)
B(2,55,5,minecraft:soul_sand)
B(2,44,6,minecraft:soul_sand)
B(2,45,6,minecraft:soul_sand)
B(2,46,6,minecraft:soul_sand)
B(2,47,6,minecraft:soul_sand)
B(2,48,6,minecraft:soul_sand)
B(2,49,6,minecraft:soul_sand)
B(2,50,6,minecraft:soul_sand)
B(2,51,6,minecraft:soul_sand)
B(2,52,6,minecraft:soul_sand)
B(2,53,6,minecraft:soul_sand)
B(2,54,6,minecraft:soul_sand)
B(2,55,6,minecraft:soul_sand)
B(2,41,7,minecraft:soul_sand)
B(2,42,7,minecraft:soul_sand)
B(2,43,7,minecraft:soul_sand)
B(2,44,7,minecraft:soul_sand)
B(2,45,7,minecraft:soul_sand)
B(2,46,7,minecraft:soul_sand)
B(2,47,7,minecraft:soul_sand)
B(2,48,7,minecraft:soul_sand)
B(2,49,7,minecraft:soul_sand)
B(2,50,7,minecraft:soul_sand)
B(2,51,7,minecraft:soul_sand)
B(2,52,7,minecraft:soul_sand)
B(2,53,7,minecraft:soul_sand)
B(2,54,7,minecraft:soul_sand)
B(2,55,7,minecraft:soul_sand)
B(2,38,8,minecraft:soul_sand)
B(2,39,8,minecraft:soul_sand)
B(2,40,8,minecraft:soul_sand)
B(2,41,8,minecraft:soul_sand)
B(2,42,8,minecraft:soul_sand)
B(2,43,8,minecraft:soul_sand)
B(2,44,8,minecraft:soul_sand)
B(2,45,8,minecraft:soul_sand)
B(2,46,8,minecraft:soul_sand)
B(2,47,8,minecraft:soul_sand)
B(2,48,8,minecraft:soul_sand)
B(2,49,8,minecraft:soul_sand)
B(2,50,8,minecraft:soul_sand)
B(2,51,8,minecraft:soul_sand)
B(2,52,8,minecraft:soul_sand)
B(2,53,8,minecraft:soul_sand)
B(2,54,8,minecraft:soul_sand)
B(2,55,8,minecraft:soul_sand)
B(3,47,5,minecraft:soul_sand)
B(3,48,5,minecraft:soul_sand)
B(3,49,5,minecraft:soul_sand)
B(3,50,5,minecraft:soul_sand)
B(3,51,5,minecraft:soul_sand)
B(3,52,5,minecraft:soul_sand)
B(3,53,5,minecraft:soul_sand)
B(3,54,5,minecraft:soul_sand)
B(3,55,5,minecraft:soul_sand)
B(3,44,6,minecraft:soul_sand)
B(3,45,6,minecraft:soul_sand)
B(3,46,6,minecraft:soul_sand)
B(3,47,6,minecraft:soul_sand)
B(3,48,6,minecraft:soul_sand)
B(3,49,6,minecraft:soul_sand)
B(3,50,6,minecraft:soul_sand)
B(3,51,6,minecraft:soul_sand)
B(3,52,6,minecraft:soul_sand)
B(3,53,6,minecraft:soul_sand)
B(3,54,6,minecraft:soul_sand)
B(3,55,6,minecraft:soul_sand)
B(3,41,7,minecraft:soul_sand)
B(3,42,7,minecraft:soul_sand)
B(3,43,7,minecraft:soul_sand)
B(3,44,7,minecraft:soul_sand)
B(3,45,7,minecraft:soul_sand)
B(3,46,7,minecraft:soul_sand)
B(3,47,7,minecraft:soul_sand)
B(3,48,7,minecraft:soul_sand)
B(3,49,7,minecraft:soul_sand)
B(3,50,7,minecraft:soul_sand)
B(3,51,7,minecraft:soul_sand)
B(3,52,7,minecraft:soul_sand)
B(3,53,7,minecraft:soul_sand)
B(3,54,7,minecraft:soul_sand)
B(3,55,7,minecraft:soul_sand)
B(3,39,8,minecraft:soul_sand)
B(3,40,8,minecraft:soul_sand)
B(3,41,8,minecraft:soul_sand)
B(3,42,8,minecraft:soul_sand)
B(3,43,8,minecraft:soul_sand)
B(3,44,8,minecraft:soul_sand)
B(3,45,8,minecraft:soul_sand)
B(3,46,8,minecraft:soul_sand)
B(3,47,8,minecraft:soul_sand)
B(3,48,8,minecraft:soul_sand)
B(3,49,8,minecraft:soul_sand)
B(3,50,8,minecraft:soul_sand)
B(3,51,8,minecraft:soul_sand)
B(3,52,8,minecraft:soul_sand)
B(3,53,8,minecraft:soul_sand)
B(3,54,8,minecraft:soul_sand)
B(3,55,8,minecraft:soul_sand)
B(4,45,6,minecraft:soul_sand)
B(4,46,6,minecraft:soul_sand)
B(4,47,6,minecraft:soul_sand)
B(4,48,6,minecraft:soul_sand)
B(4,49,6,minecraft:soul_sand)
B(4,50,6,minecraft:soul_sand)
B(4,51,6,minecraft:soul_sand)
B(4,52,6,minecraft:soul_sand)
B(4,53,6,minecraft:soul_sand)
B(4,54,6,minecraft:soul_sand)
B(4,55,6,minecraft:soul_sand)
B(4,42,7,minecraft:soul_sand)
B(4,43,7,minecraft:soul_sand)
B(4,44,7,minecraft:soul_sand)
B(4,45,7,minecraft:soul_sand)
B(4,46,7,minecraft:soul_sand)
B(4,47,7,minecraft:soul_sand)
B(4,48,7,minecraft:soul_sand)
B(4,49,7,minecraft:soul_sand)
B(4,50,7,minecraft:soul_sand)
B(4,51,7,minecraft:soul_sand)
B(4,52,7,minecraft:soul_sand)
B(4,53,7,minecraft:soul_sand)
B(4,54,7,minecraft:soul_sand)
B(4,55,7,minecraft:soul_sand)
B(4,39,8,minecraft:soul_sand)
B(4,40,8,minecraft:soul_sand)
B(4,41,8,minecraft:soul_sand)
B(4,42,8,minecraft:soul_sand)
B(4,43,8,minecraft:soul_sand)
B(4,44,8,minecraft:soul_sand)
B(4,45,8,minecraft:soul_sand)
B(4,46,8,minecraft:soul_sand)
B(4,47,8,minecraft:soul_sand)
B(4,48,8,minecraft:soul_sand)
B(4,49,8,minecraft:soul_sand)
B(4,50,8,minecraft:soul_sand)
B(4,51,8,minecraft:soul_sand)
B(4,52,8,minecraft:soul_sand)
B(4,53,8,minecraft:soul_sand)
B(4,54,8,minecraft:soul_sand)
B(4,55,8,minecraft:soul_sand)
B(5,42,7,minecraft:soul_sand)
B(5,43,7,minecraft:soul_sand)
B(5,44,7,minecraft:soul_sand)
B(5,45,7,minecraft:soul_sand)
B(5,46,7,minecraft:soul_sand)
B(5,47,7,minecraft:soul_sand)
B(5,48,7,minecraft:soul_sand)
B(5,49,7,minecraft:soul_sand)
B(5,50,7,minecraft:soul_sand)
B(5,51,7,minecraft:soul_sand)
B(5,52,7,minecraft:soul_sand)
B(5,53,7,minecraft:soul_sand)
B(5,54,7,minecraft:soul_sand)
B(5,55,7,minecraft:soul_sand)
B(5,39,8,minecraft:soul_sand)
B(5,40,8,minecraft:soul_sand)
B(5,41,8,minecraft:soul_sand)
B(5,42,8,minecraft:soul_sand)
B(5,43,8,minecraft:soul_sand)
B(5,44,8,minecraft:soul_sand)
B(5,45,8,minecraft:soul_sand)
B(5,46,8,minecraft:soul_sand)
B(5,47,8,minecraft:soul_sand)
B(5,48,8,minecraft:soul_sand)
B(5,49,8,minecraft:soul_sand)
B(5,50,8,minecraft:soul_sand)
B(5,51,8,minecraft:soul_sand)
B(5,52,8,minecraft:soul_sand)
B(5,53,8,minecraft:soul_sand)
B(5,54,8,minecraft:soul_sand)
B(5,55,8,minecraft:soul_sand)
B(6,46,6,minecraft:soul_sand)
B(6,47,6,minecraft:soul_sand)
B(6,48,6,minecraft:soul_sand)
B(6,49,6,minecraft:soul_sand)
B(6,50,6,minecraft:soul_sand)
B(6,51,6,minecraft:soul_sand)
B(6,52,6,minecraft:soul_sand)
B(6,53,6,minecraft:soul_sand)
B(6,54,6,minecraft:soul_sand)
B(6,55,6,minecraft:soul_sand)
B(6,43,7,minecraft:soul_sand)
B(6,44,7,minecraft:soul_sand)
B(6,45,7,minecraft:soul_sand)
B(6,46,7,minecraft:soul_sand)
B(6,47,7,minecraft:soul_sand)
B(6,48,7,minecraft:soul_sand)
B(6,49,7,minecraft:soul_sand)
B(6,50,7,minecraft:soul_sand)
B(6,51,7,minecraft:soul_sand)
B(6,52,7,minecraft:soul_sand)
B(6,53,7,minecraft:soul_sand)
B(6,54,7,minecraft:soul_sand)
B(6,55,7,minecraft:soul_sand)
B(6,36,8,minecraft:soul_sand)
B(6,37,8,minecraft:soul_sand)
B(6,38,8,minecraft:soul_sand)
B(6,39,8,minecraft:soul_sand)
B(6,40,8,minecraft:soul_sand)
B(6,41,8,minecraft:soul_sand)
B(6,42,8,minecraft:soul_sand)
B(6,43,8,minecraft:soul_sand)
B(6,44,8,minecraft:soul_sand)
B(6,45,8,minecraft:soul_sand)
B(6,46,8,minecraft:soul_sand)
B(6,47,8,minecraft:soul_sand)
B(6,48,8,minecraft:soul_sand)
B(6,49,8,minecraft:soul_sand)
B(6,50,8,minecraft:soul_sand)
B(6,51,8,minecraft:soul_sand)
B(6,52,8,minecraft:soul_sand)
B(6,53,8,minecraft:soul_sand)
B(6,54,8,minecraft:soul_sand)
B(6,55,8,minecraft:soul_sand)
B(7,46,6,minecraft:soul_sand)
B(7,47,6,minecraft:soul_sand)
B(7,48,6,minecraft:soul_sand)
B(7,49,6,minecraft:soul_sand)
B(7,50,6,minecraft:soul_sand)
B(7,51,6,minecraft:soul_sand)
B(7,52,6,minecraft:soul_sand)
B(7,53,6,minecraft:soul_sand)
B(7,54,6,minecraft:soul_sand)
B(7,55,6,minecraft:soul_sand)
B(7,43,7,minecraft:soul_sand)
B(7,44,7,minecraft:soul_sand)
B(7,45,7,minecraft:soul_sand)
B(7,46,7,minecraft:soul_sand)
B(7,47,7,minecraft:soul_sand)
B(7,48,7,minecraft:soul_sand)
B(7,49,7,minecraft:soul_sand)
B(7,50,7,minecraft:soul_sand)
B(7,51,7,minecraft:soul_sand)
B(7,52,7,minecraft:soul_sand)
B(7,53,7,minecraft:soul_sand)
B(7,54,7,minecraft:soul_sand)
B(7,55,7,minecraft:soul_sand)
B(7,39,8,minecraft:soul_sand)
B(7,40,8,minecraft:soul_sand)
B(7,41,8,minecraft:soul_sand)
B(7,42,8,minecraft:soul_sand)
B(7,43,8,minecraft:soul_sand)
B(7,44,8,minecraft:soul_sand)
B(7,45,8,minecraft:soul_sand)
B(7,46,8,minecraft:soul_sand)
B(7,47,8,minecraft:soul_sand)
B(7,48,8,minecraft:soul_sand)
B(7,49,8,minecraft:soul_sand)
B(7,50,8,minecraft:soul_sand)
B(7,51,8,minecraft:soul_sand)
B(7,52,8,minecraft:soul_sand)
B(7,53,8,minecraft:soul_sand)
B(7,54,8,minecraft:soul_sand)
B(7,55,8,minecraft:soul_sand)

#######################################################################
# +-----------------------------------------------------------------+ #
# |                             Branches                            | #
# +-----------------------------------------------------------------+ #
#######################################################################

Branch(16,0,0,true,GiantSoulSandStalactite3_C2_R0,NORTH,100.0,0)

#######################################################################
# +-----------------------------------------------------------------+ #
# |                             Entities                            | #
# +-----------------------------------------------------------------+ #
#######################################################################

