Author: Bo3 BulkEdit

Description: Converted Schematic - Modified by Bo3BulkEdit

Version: 3

SettingsMode: WriteDisable

IsOTGPlus: true
Tree: false
Frequency: 1
Rarity: 100
RotateRandomly: false
SpawnHeight: randomY
SpawnHeightOffset: 0
SpawnHeightVariance: 0
MaxBranchDepth: 10
ExcludedBiomes: All

MinHeight: 25
MaxHeight: 30

SourceBlocks: AIR
MaxPercentageOutsideSourceBlock: 100
OutsideSourceBlock: placeAnyway

RB(15,28,11,minecraft:crying_obsidian,10,minecraft:obsidian,100)
RB(15,29,11,minecraft:crying_obsidian,10,minecraft:obsidian,100)
RB(15,30,11,minecraft:crying_obsidian,10,minecraft:obsidian,100)
RB(15,31,10,minecraft:crying_obsidian,10,minecraft:obsidian,100)
B(15,32,9,minecraft:glowstone)
B(15,33,9,minecraft:chain[axis=y,waterlogged=false])
B(15,34,9,minecraft:glowstone)
RB(15,35,8,minecraft:crying_obsidian,10,minecraft:obsidian,100)
RB(14,35,10,minecraft:crying_obsidian,10,minecraft:obsidian,100)
RB(15,36,7,minecraft:crying_obsidian,10,minecraft:obsidian,100)
RB(13,36,10,minecraft:crying_obsidian,10,minecraft:obsidian,100)
RB(15,37,7,minecraft:crying_obsidian,10,minecraft:obsidian,100)
RB(13,37,10,minecraft:crying_obsidian,10,minecraft:obsidian,100)
RB(15,38,7,minecraft:crying_obsidian,10,minecraft:obsidian,100)
RB(13,38,10,minecraft:crying_obsidian,10,minecraft:obsidian,100)
RB(14,39,7,minecraft:crying_obsidian,10,minecraft:obsidian,100)
RB(13,39,9,minecraft:crying_obsidian,10,minecraft:obsidian,100)
B(13,40,8,minecraft:glowstone)
B(13,41,8,minecraft:chain[axis=y,waterlogged=false])
B(13,42,8,minecraft:glowstone)
RB(13,43,7,minecraft:crying_obsidian,10,minecraft:obsidian,100)
RB(12,43,9,minecraft:crying_obsidian,10,minecraft:obsidian,100)
RB(13,44,6,minecraft:crying_obsidian,10,minecraft:obsidian,100)
RB(11,44,9,minecraft:crying_obsidian,10,minecraft:obsidian,100)
RB(13,45,6,minecraft:crying_obsidian,10,minecraft:obsidian,100)
RB(11,45,9,minecraft:crying_obsidian,10,minecraft:obsidian,100)
RB(13,46,6,minecraft:crying_obsidian,10,minecraft:obsidian,100)
RB(11,46,9,minecraft:crying_obsidian,10,minecraft:obsidian,100)
RB(12,47,6,minecraft:crying_obsidian,10,minecraft:obsidian,100)
RB(11,47,8,minecraft:crying_obsidian,10,minecraft:obsidian,100)
B(11,48,7,minecraft:glowstone)
B(11,49,7,minecraft:chain[axis=y,waterlogged=false])
B(11,50,7,minecraft:glowstone)
RB(11,51,6,minecraft:crying_obsidian,10,minecraft:obsidian,100)
RB(10,51,8,minecraft:crying_obsidian,10,minecraft:obsidian,100)
RB(11,52,5,minecraft:crying_obsidian,10,minecraft:obsidian,100)
RB(9,52,8,minecraft:crying_obsidian,10,minecraft:obsidian,100)
RB(11,53,5,minecraft:crying_obsidian,10,minecraft:obsidian,100)
RB(9,53,8,minecraft:crying_obsidian,10,minecraft:obsidian,100)
RB(11,54,5,minecraft:crying_obsidian,10,minecraft:obsidian,100)
RB(9,54,8,minecraft:crying_obsidian,10,minecraft:obsidian,100)
RB(10,55,5,minecraft:crying_obsidian,10,minecraft:obsidian,100)
RB(9,55,7,minecraft:crying_obsidian,10,minecraft:obsidian,100)
B(9,56,6,minecraft:glowstone)
B(9,57,6,minecraft:chain[axis=y,waterlogged=false])
B(9,58,6,minecraft:glowstone)
RB(9,59,5,minecraft:crying_obsidian,10,minecraft:obsidian,100)
RB(8,59,7,minecraft:crying_obsidian,10,minecraft:obsidian,100)
RB(9,60,4,minecraft:crying_obsidian,10,minecraft:obsidian,100)
RB(7,60,7,minecraft:crying_obsidian,10,minecraft:obsidian,100)
RB(9,61,4,minecraft:crying_obsidian,10,minecraft:obsidian,100)
RB(7,61,7,minecraft:crying_obsidian,10,minecraft:obsidian,100)
RB(9,62,4,minecraft:crying_obsidian,10,minecraft:obsidian,100)
RB(7,62,7,minecraft:crying_obsidian,10,minecraft:obsidian,100)
RB(8,63,4,minecraft:crying_obsidian,10,minecraft:obsidian,100)
RB(7,63,6,minecraft:crying_obsidian,10,minecraft:obsidian,100)
B(7,64,5,minecraft:glowstone)
B(7,65,5,minecraft:chain[axis=y,waterlogged=false])
B(7,66,5,minecraft:glowstone)
RB(7,67,4,minecraft:crying_obsidian,10,minecraft:obsidian,100)
RB(6,67,6,minecraft:crying_obsidian,10,minecraft:obsidian,100)
RB(7,68,3,minecraft:crying_obsidian,10,minecraft:obsidian,100)
RB(5,68,6,minecraft:crying_obsidian,10,minecraft:obsidian,100)
RB(7,69,3,minecraft:crying_obsidian,10,minecraft:obsidian,100)
RB(5,69,6,minecraft:crying_obsidian,10,minecraft:obsidian,100)
RB(7,70,3,minecraft:crying_obsidian,10,minecraft:obsidian,100)
RB(5,70,6,minecraft:crying_obsidian,10,minecraft:obsidian,100)
RB(6,71,3,minecraft:crying_obsidian,10,minecraft:obsidian,100)
RB(5,71,5,minecraft:crying_obsidian,10,minecraft:obsidian,100)
B(5,72,4,minecraft:glowstone)
B(5,73,4,minecraft:chain[axis=y,waterlogged=false])
B(5,74,4,minecraft:glowstone)
RB(5,75,3,minecraft:crying_obsidian,10,minecraft:obsidian,100)
RB(4,75,5,minecraft:crying_obsidian,10,minecraft:obsidian,100)
RB(5,76,2,minecraft:crying_obsidian,10,minecraft:obsidian,100)
RB(3,76,5,minecraft:crying_obsidian,10,minecraft:obsidian,100)
RB(5,77,2,minecraft:crying_obsidian,10,minecraft:obsidian,100)
RB(3,77,5,minecraft:crying_obsidian,10,minecraft:obsidian,100)
RB(5,78,2,minecraft:crying_obsidian,10,minecraft:obsidian,100)
RB(3,78,5,minecraft:crying_obsidian,10,minecraft:obsidian,100)
RB(4,79,2,minecraft:crying_obsidian,10,minecraft:obsidian,100)
RB(3,79,4,minecraft:crying_obsidian,10,minecraft:obsidian,100)
B(3,80,3,minecraft:glowstone)
B(3,81,3,minecraft:chain[axis=y,waterlogged=false])
B(3,82,3,minecraft:glowstone)
RB(3,83,2,minecraft:crying_obsidian,10,minecraft:obsidian,100)
RB(2,83,4,minecraft:crying_obsidian,10,minecraft:obsidian,100)
RB(3,84,1,minecraft:crying_obsidian,10,minecraft:obsidian,100)
RB(1,84,4,minecraft:crying_obsidian,10,minecraft:obsidian,100)
RB(3,85,1,minecraft:crying_obsidian,10,minecraft:obsidian,100)
RB(1,85,4,minecraft:crying_obsidian,10,minecraft:obsidian,100)
RB(3,86,1,minecraft:crying_obsidian,10,minecraft:obsidian,100)
RB(1,86,4,minecraft:crying_obsidian,10,minecraft:obsidian,100)
RB(2,87,1,minecraft:crying_obsidian,10,minecraft:obsidian,100)
RB(1,87,3,minecraft:crying_obsidian,10,minecraft:obsidian,100)
B(1,88,2,minecraft:glowstone)
B(1,89,2,minecraft:chain[axis=y,waterlogged=false])
B(1,90,2,minecraft:glowstone)
RB(1,91,1,minecraft:crying_obsidian,10,minecraft:obsidian,100)
RB(0,91,3,minecraft:crying_obsidian,10,minecraft:obsidian,100)
RB(1,92,0,minecraft:crying_obsidian,10,minecraft:obsidian,100)
RB(1,93,0,minecraft:crying_obsidian,10,minecraft:obsidian,100)
RB(1,94,0,minecraft:crying_obsidian,10,minecraft:obsidian,100)
RB(0,95,0,minecraft:crying_obsidian,10,minecraft:obsidian,100)

BR(16,0,0,true,ObsidianChain1_2x1,NORTH,100,0)
BR(-16,0,0,true,ObsidianChain1_0x1,NORTH,100,0)
