
#######################################################################
# +-----------------------------------------------------------------+ #
# |                            BO4 object                           | #
# +-----------------------------------------------------------------+ #
#######################################################################

Author: Unknown

Description: No description given

SettingsMode: WriteWithoutComments


#######################################################################
# +-----------------------------------------------------------------+ #
# |                          Main settings                          | #
# +-----------------------------------------------------------------+ #
#######################################################################

FixedRotation: 

Frequency: 0

SpawnHeight: highestBlock

UseCenterForHighestBlock: true

##############################
# Height Limits for the BO4. #
##############################

MinHeight: 0

MaxHeight: 255

InheritBO3: 

InheritBO3Rotation: NORTH

OverrideChildSettings: true

OverrideParentHeight: false

CanOverride: false

BranchFrequency: 0

BranchFrequencyGroup: 

MustBeBelowOther: false

MustBeInside: 

CannotBeInside: 

ReplacesBO3: 

MustBeInsideWorldBorders: false

CanSpawnOnWater: true

SpawnOnWaterOnly: false

SpawnUnderWater: false

SpawnAtWaterLevel: false

HeightOffset: 0

RemoveAir: true

ReplaceAbove: 

ReplaceBelow: 

ReplaceWithBiomeBlocks: true

ReplaceWithSurfaceBlock: GRASS

ReplaceWithGroundBlock: DIRT

ReplaceWithStoneBlock: STONE

SmoothRadius: 0

SmoothHeightOffset: 0

SmoothStartTop: false

SmoothStartWood: false

SmoothingSurfaceBlock: 

SmoothingGroundBlock: 

BO3Group: 

IsSpawnPoint: false

DoReplaceBlocks: true


#######################################################################
# +-----------------------------------------------------------------+ #
# |                              Blocks                             | #
# +-----------------------------------------------------------------+ #
#######################################################################

B(-8,0,5,minecraft:netherrack)
B(-8,1,5,minecraft:netherrack)
B(-8,0,6,minecraft:netherrack)
B(-8,1,6,minecraft:netherrack)
B(-8,2,6,minecraft:netherrack)
B(-8,0,7,minecraft:netherrack)
B(-8,1,7,minecraft:netherrack)
B(-8,2,7,minecraft:netherrack)
B(-8,3,7,minecraft:netherrack)
B(-8,4,7,minecraft:netherrack)
B(-8,5,7,minecraft:netherrack)
B(-8,0,8,minecraft:netherrack)
B(-8,1,8,minecraft:netherrack)
B(-8,2,8,minecraft:netherrack)
B(-8,3,8,minecraft:netherrack)
B(-8,4,8,minecraft:netherrack)
B(-8,5,8,minecraft:netherrack)
B(-8,6,8,minecraft:netherrack)
B(-7,0,5,minecraft:netherrack)
B(-7,1,5,minecraft:netherrack)
B(-7,0,6,minecraft:netherrack)
B(-7,1,6,minecraft:netherrack)
B(-7,2,6,minecraft:netherrack)
B(-7,3,6,minecraft:netherrack)
B(-7,4,6,minecraft:netherrack)
B(-7,0,7,minecraft:netherrack)
B(-7,1,7,minecraft:netherrack)
B(-7,2,7,minecraft:netherrack)
B(-7,3,7,minecraft:netherrack)
B(-7,4,7,minecraft:netherrack)
B(-7,5,7,minecraft:netherrack)
B(-7,6,7,minecraft:netherrack)
B(-7,0,8,minecraft:netherrack)
B(-7,1,8,minecraft:netherrack)
B(-7,2,8,minecraft:netherrack)
B(-7,3,8,minecraft:netherrack)
B(-7,4,8,minecraft:netherrack)
B(-7,5,8,minecraft:netherrack)
B(-7,6,8,minecraft:netherrack)
B(-7,7,8,minecraft:netherrack)
B(-6,0,4,minecraft:netherrack)
B(-6,0,5,minecraft:netherrack)
B(-6,1,5,minecraft:netherrack)
B(-6,0,6,minecraft:netherrack)
B(-6,1,6,minecraft:netherrack)
B(-6,2,6,minecraft:netherrack)
B(-6,3,6,minecraft:netherrack)
B(-6,4,6,minecraft:netherrack)
B(-6,5,6,minecraft:netherrack)
B(-6,0,7,minecraft:netherrack)
B(-6,1,7,minecraft:netherrack)
B(-6,2,7,minecraft:netherrack)
B(-6,3,7,minecraft:netherrack)
B(-6,4,7,minecraft:netherrack)
B(-6,5,7,minecraft:netherrack)
B(-6,6,7,minecraft:netherrack)
B(-6,0,8,minecraft:netherrack)
B(-6,1,8,minecraft:netherrack)
B(-6,2,8,minecraft:netherrack)
B(-6,3,8,minecraft:netherrack)
B(-6,4,8,minecraft:netherrack)
B(-6,5,8,minecraft:netherrack)
B(-6,6,8,minecraft:netherrack)
B(-6,7,8,minecraft:netherrack)
B(-5,0,3,minecraft:netherrack)
B(-5,1,3,minecraft:netherrack)
B(-5,0,4,minecraft:netherrack)
B(-5,1,4,minecraft:netherrack)
B(-5,2,4,minecraft:netherrack)
B(-5,0,5,minecraft:netherrack)
B(-5,1,5,minecraft:netherrack)
B(-5,2,5,minecraft:netherrack)
B(-5,0,6,minecraft:netherrack)
B(-5,1,6,minecraft:netherrack)
B(-5,2,6,minecraft:netherrack)
B(-5,3,6,minecraft:netherrack)
B(-5,4,6,minecraft:netherrack)
B(-5,5,6,minecraft:netherrack)
B(-5,0,7,minecraft:netherrack)
B(-5,1,7,minecraft:netherrack)
B(-5,2,7,minecraft:netherrack)
B(-5,3,7,minecraft:netherrack)
B(-5,4,7,minecraft:netherrack)
B(-5,5,7,minecraft:netherrack)
B(-5,6,7,minecraft:netherrack)
B(-5,0,8,minecraft:netherrack)
B(-5,1,8,minecraft:netherrack)
B(-5,2,8,minecraft:netherrack)
B(-5,3,8,minecraft:netherrack)
B(-5,4,8,minecraft:netherrack)
B(-5,5,8,minecraft:netherrack)
B(-5,6,8,minecraft:netherrack)
B(-5,7,8,minecraft:netherrack)
B(-4,0,2,minecraft:netherrack)
B(-4,1,2,minecraft:netherrack)
B(-4,0,3,minecraft:netherrack)
B(-4,1,3,minecraft:netherrack)
B(-4,2,3,minecraft:netherrack)
B(-4,0,4,minecraft:netherrack)
B(-4,1,4,minecraft:netherrack)
B(-4,2,4,minecraft:netherrack)
B(-4,3,4,minecraft:netherrack)
B(-4,0,5,minecraft:netherrack)
B(-4,1,5,minecraft:netherrack)
B(-4,2,5,minecraft:netherrack)
B(-4,3,5,minecraft:netherrack)
B(-4,0,6,minecraft:netherrack)
B(-4,1,6,minecraft:netherrack)
B(-4,2,6,minecraft:netherrack)
B(-4,3,6,minecraft:netherrack)
B(-4,4,6,minecraft:netherrack)
B(-4,5,6,minecraft:netherrack)
B(-4,0,7,minecraft:netherrack)
B(-4,1,7,minecraft:netherrack)
B(-4,2,7,minecraft:netherrack)
B(-4,3,7,minecraft:netherrack)
B(-4,4,7,minecraft:netherrack)
B(-4,5,7,minecraft:netherrack)
B(-4,6,7,minecraft:netherrack)
B(-4,7,7,minecraft:netherrack)
B(-4,0,8,minecraft:netherrack)
B(-4,1,8,minecraft:netherrack)
B(-4,2,8,minecraft:netherrack)
B(-4,3,8,minecraft:netherrack)
B(-4,4,8,minecraft:netherrack)
B(-4,5,8,minecraft:netherrack)
B(-4,6,8,minecraft:netherrack)
B(-4,7,8,minecraft:netherrack)
B(-3,0,0,minecraft:lava[level=7])
B(-3,0,1,minecraft:netherrack)
B(-3,0,2,minecraft:netherrack)
B(-3,1,2,minecraft:netherrack)
B(-3,2,2,minecraft:netherrack)
B(-3,0,3,minecraft:netherrack)
B(-3,1,3,minecraft:netherrack)
B(-3,2,3,minecraft:netherrack)
B(-3,3,3,minecraft:netherrack)
B(-3,0,4,minecraft:netherrack)
B(-3,1,4,minecraft:netherrack)
B(-3,2,4,minecraft:netherrack)
B(-3,3,4,minecraft:netherrack)
B(-3,0,5,minecraft:netherrack)
B(-3,1,5,minecraft:netherrack)
B(-3,2,5,minecraft:netherrack)
B(-3,3,5,minecraft:netherrack)
B(-3,4,5,minecraft:netherrack)
B(-3,0,6,minecraft:netherrack)
B(-3,1,6,minecraft:netherrack)
B(-3,2,6,minecraft:netherrack)
B(-3,3,6,minecraft:netherrack)
B(-3,4,6,minecraft:netherrack)
B(-3,0,7,minecraft:netherrack)
B(-3,1,7,minecraft:netherrack)
B(-3,2,7,minecraft:netherrack)
B(-3,3,7,minecraft:netherrack)
B(-3,4,7,minecraft:netherrack)
B(-3,5,7,minecraft:netherrack)
B(-3,6,7,minecraft:netherrack)
B(-3,7,7,minecraft:netherrack)
B(-3,0,8,minecraft:netherrack)
B(-3,1,8,minecraft:netherrack)
B(-3,2,8,minecraft:netherrack)
B(-3,3,8,minecraft:netherrack)
B(-3,4,8,minecraft:netherrack)
B(-3,5,8,minecraft:netherrack)
B(-3,6,8,minecraft:netherrack)
B(-3,7,8,minecraft:netherrack)
B(-2,0,-1,minecraft:lava[level=7])
B(-2,0,0,minecraft:lava[level=6])
B(-2,0,1,minecraft:netherrack)
B(-2,1,1,minecraft:netherrack)
B(-2,0,2,minecraft:netherrack)
B(-2,1,2,minecraft:netherrack)
B(-2,2,2,minecraft:netherrack)
B(-2,0,3,minecraft:netherrack)
B(-2,1,3,minecraft:netherrack)
B(-2,2,3,minecraft:netherrack)
B(-2,3,3,minecraft:netherrack)
B(-2,0,4,minecraft:netherrack)
B(-2,1,4,minecraft:netherrack)
B(-2,2,4,minecraft:netherrack)
B(-2,3,4,minecraft:netherrack)
B(-2,4,4,minecraft:netherrack)
B(-2,0,5,minecraft:netherrack)
B(-2,1,5,minecraft:netherrack)
B(-2,2,5,minecraft:netherrack)
B(-2,3,5,minecraft:netherrack)
B(-2,4,5,minecraft:netherrack)
B(-2,5,5,minecraft:netherrack)
B(-2,0,6,minecraft:netherrack)
B(-2,1,6,minecraft:netherrack)
B(-2,2,6,minecraft:netherrack)
B(-2,3,6,minecraft:netherrack)
B(-2,4,6,minecraft:netherrack)
B(-2,5,6,minecraft:netherrack)
B(-2,6,6,minecraft:netherrack)
B(-2,0,7,minecraft:netherrack)
B(-2,1,7,minecraft:netherrack)
B(-2,2,7,minecraft:netherrack)
B(-2,3,7,minecraft:netherrack)
B(-2,4,7,minecraft:netherrack)
B(-2,5,7,minecraft:netherrack)
B(-2,6,7,minecraft:netherrack)
B(-2,7,7,minecraft:netherrack)
B(-2,0,8,minecraft:netherrack)
B(-2,1,8,minecraft:netherrack)
B(-2,2,8,minecraft:netherrack)
B(-2,3,8,minecraft:netherrack)
B(-2,4,8,minecraft:netherrack)
B(-2,5,8,minecraft:netherrack)
B(-2,6,8,minecraft:netherrack)
B(-2,7,8,minecraft:netherrack)
B(-1,0,-2,minecraft:lava[level=7])
B(-1,0,-1,minecraft:lava[level=6])
B(-1,0,0,minecraft:lava[level=5])
B(-1,0,1,minecraft:netherrack)
B(-1,1,1,minecraft:netherrack)
B(-1,0,2,minecraft:netherrack)
B(-1,1,2,minecraft:netherrack)
B(-1,2,2,minecraft:netherrack)
B(-1,0,3,minecraft:netherrack)
B(-1,1,3,minecraft:netherrack)
B(-1,2,3,minecraft:netherrack)
B(-1,3,3,minecraft:netherrack)
B(-1,0,4,minecraft:netherrack)
B(-1,1,4,minecraft:netherrack)
B(-1,2,4,minecraft:netherrack)
B(-1,3,4,minecraft:netherrack)
B(-1,4,4,minecraft:netherrack)
B(-1,5,4,minecraft:netherrack)
B(-1,0,5,minecraft:netherrack)
B(-1,1,5,minecraft:netherrack)
B(-1,2,5,minecraft:netherrack)
B(-1,3,5,minecraft:netherrack)
B(-1,4,5,minecraft:netherrack)
B(-1,5,5,minecraft:netherrack)
B(-1,6,5,minecraft:netherrack)
B(-1,0,6,minecraft:netherrack)
B(-1,1,6,minecraft:netherrack)
B(-1,2,6,minecraft:netherrack)
B(-1,3,6,minecraft:netherrack)
B(-1,4,6,minecraft:netherrack)
B(-1,5,6,minecraft:netherrack)
B(-1,6,6,minecraft:netherrack)
B(-1,7,6,minecraft:netherrack)
B(-1,0,7,minecraft:netherrack)
B(-1,1,7,minecraft:netherrack)
B(-1,2,7,minecraft:netherrack)
B(-1,3,7,minecraft:netherrack)
B(-1,4,7,minecraft:netherrack)
B(-1,5,7,minecraft:netherrack)
B(-1,6,7,minecraft:netherrack)
B(-1,7,7,minecraft:netherrack)
B(-1,0,8,minecraft:netherrack)
B(-1,1,8,minecraft:netherrack)
B(-1,2,8,minecraft:netherrack)
B(-1,3,8,minecraft:netherrack)
B(-1,4,8,minecraft:netherrack)
B(-1,5,8,minecraft:netherrack)
B(-1,6,8,minecraft:netherrack)
B(-1,7,8,minecraft:netherrack)
B(-1,8,8,minecraft:netherrack)
B(0,0,-3,minecraft:lava[level=7])
B(0,0,-2,minecraft:lava[level=6])
B(0,0,-1,minecraft:lava[level=5])
B(0,0,0,minecraft:lava[level=4])
B(0,0,1,minecraft:netherrack)
B(0,1,1,minecraft:netherrack)
B(0,0,2,minecraft:netherrack)
B(0,1,2,minecraft:netherrack)
B(0,2,2,minecraft:netherrack)
B(0,0,3,minecraft:netherrack)
B(0,1,3,minecraft:netherrack)
B(0,2,3,minecraft:netherrack)
B(0,3,3,minecraft:netherrack)
B(0,0,4,minecraft:netherrack)
B(0,1,4,minecraft:netherrack)
B(0,2,4,minecraft:netherrack)
B(0,3,4,minecraft:netherrack)
B(0,4,4,minecraft:netherrack)
B(0,5,4,minecraft:netherrack)
B(0,6,4,minecraft:netherrack)
B(0,0,5,minecraft:netherrack)
B(0,1,5,minecraft:netherrack)
B(0,2,5,minecraft:netherrack)
B(0,3,5,minecraft:netherrack)
B(0,4,5,minecraft:netherrack)
B(0,5,5,minecraft:netherrack)
B(0,6,5,minecraft:netherrack)
B(0,7,5,minecraft:netherrack)
B(0,0,6,minecraft:netherrack)
B(0,1,6,minecraft:netherrack)
B(0,2,6,minecraft:netherrack)
B(0,3,6,minecraft:netherrack)
B(0,4,6,minecraft:netherrack)
B(0,5,6,minecraft:netherrack)
B(0,6,6,minecraft:netherrack)
B(0,7,6,minecraft:netherrack)
B(0,0,7,minecraft:netherrack)
B(0,1,7,minecraft:netherrack)
B(0,2,7,minecraft:netherrack)
B(0,3,7,minecraft:netherrack)
B(0,4,7,minecraft:netherrack)
B(0,5,7,minecraft:netherrack)
B(0,6,7,minecraft:netherrack)
B(0,7,7,minecraft:netherrack)
B(0,8,7,minecraft:netherrack)
B(0,0,8,minecraft:netherrack)
B(0,1,8,minecraft:netherrack)
B(0,2,8,minecraft:netherrack)
B(0,3,8,minecraft:netherrack)
B(0,4,8,minecraft:netherrack)
B(0,5,8,minecraft:netherrack)
B(0,6,8,minecraft:netherrack)
B(0,7,8,minecraft:netherrack)
B(0,8,8,minecraft:netherrack)
B(1,0,-4,minecraft:lava[level=7])
B(1,0,-3,minecraft:lava[level=6])
B(1,0,-2,minecraft:lava[level=5])
B(1,0,-1,minecraft:lava[level=4])
B(1,0,0,minecraft:lava[level=3])
B(1,0,1,minecraft:lava[level=4])
B(1,0,2,minecraft:netherrack)
B(1,1,2,minecraft:netherrack)
B(1,2,2,minecraft:netherrack)
B(1,0,3,minecraft:netherrack)
B(1,1,3,minecraft:netherrack)
B(1,2,3,minecraft:netherrack)
B(1,3,3,minecraft:netherrack)
B(1,4,3,minecraft:netherrack)
B(1,5,3,minecraft:netherrack)
B(1,0,4,minecraft:netherrack)
B(1,1,4,minecraft:netherrack)
B(1,2,4,minecraft:netherrack)
B(1,3,4,minecraft:netherrack)
B(1,4,4,minecraft:netherrack)
B(1,5,4,minecraft:netherrack)
B(1,6,4,minecraft:netherrack)
B(1,0,5,minecraft:netherrack)
B(1,1,5,minecraft:netherrack)
B(1,2,5,minecraft:netherrack)
B(1,3,5,minecraft:netherrack)
B(1,4,5,minecraft:netherrack)
B(1,5,5,minecraft:netherrack)
B(1,6,5,minecraft:netherrack)
B(1,7,5,minecraft:netherrack)
B(1,0,6,minecraft:netherrack)
B(1,1,6,minecraft:netherrack)
B(1,2,6,minecraft:netherrack)
B(1,3,6,minecraft:netherrack)
B(1,4,6,minecraft:netherrack)
B(1,5,6,minecraft:netherrack)
B(1,6,6,minecraft:netherrack)
B(1,7,6,minecraft:netherrack)
B(1,8,6,minecraft:netherrack)
B(1,0,7,minecraft:netherrack)
B(1,1,7,minecraft:netherrack)
B(1,2,7,minecraft:netherrack)
B(1,3,7,minecraft:netherrack)
B(1,4,7,minecraft:netherrack)
B(1,5,7,minecraft:netherrack)
B(1,6,7,minecraft:netherrack)
B(1,7,7,minecraft:netherrack)
B(1,8,7,minecraft:netherrack)
B(1,0,8,minecraft:netherrack)
B(1,1,8,minecraft:netherrack)
B(1,2,8,minecraft:netherrack)
B(1,3,8,minecraft:netherrack)
B(1,4,8,minecraft:netherrack)
B(1,5,8,minecraft:netherrack)
B(1,6,8,minecraft:netherrack)
B(1,7,8,minecraft:netherrack)
B(1,8,8,minecraft:netherrack)
B(2,0,-5,minecraft:lava[level=7])
B(2,0,-4,minecraft:lava[level=6])
B(2,0,-3,minecraft:lava[level=5])
B(2,0,-2,minecraft:lava[level=4])
B(2,0,-1,minecraft:lava[level=3])
B(2,0,0,minecraft:lava[level=2])
B(2,0,1,minecraft:lava[level=3])
B(2,0,2,minecraft:netherrack)
B(2,1,2,minecraft:netherrack)
B(2,0,3,minecraft:netherrack)
B(2,1,3,minecraft:netherrack)
B(2,2,3,minecraft:netherrack)
B(2,3,3,minecraft:netherrack)
B(2,4,3,minecraft:netherrack)
B(2,5,3,minecraft:netherrack)
B(2,0,4,minecraft:netherrack)
B(2,1,4,minecraft:netherrack)
B(2,2,4,minecraft:netherrack)
B(2,3,4,minecraft:netherrack)
B(2,4,4,minecraft:netherrack)
B(2,5,4,minecraft:netherrack)
B(2,6,4,minecraft:netherrack)
B(2,0,5,minecraft:netherrack)
B(2,1,5,minecraft:netherrack)
B(2,2,5,minecraft:netherrack)
B(2,3,5,minecraft:netherrack)
B(2,4,5,minecraft:netherrack)
B(2,5,5,minecraft:netherrack)
B(2,6,5,minecraft:netherrack)
B(2,7,5,minecraft:netherrack)
B(2,0,6,minecraft:netherrack)
B(2,1,6,minecraft:netherrack)
B(2,2,6,minecraft:netherrack)
B(2,3,6,minecraft:netherrack)
B(2,4,6,minecraft:netherrack)
B(2,5,6,minecraft:netherrack)
B(2,6,6,minecraft:netherrack)
B(2,7,6,minecraft:netherrack)
B(2,8,6,minecraft:netherrack)
B(2,0,7,minecraft:netherrack)
B(2,1,7,minecraft:netherrack)
B(2,2,7,minecraft:netherrack)
B(2,3,7,minecraft:netherrack)
B(2,4,7,minecraft:netherrack)
B(2,5,7,minecraft:netherrack)
B(2,6,7,minecraft:netherrack)
B(2,7,7,minecraft:netherrack)
B(2,8,7,minecraft:netherrack)
B(2,0,8,minecraft:netherrack)
B(2,1,8,minecraft:netherrack)
B(2,2,8,minecraft:netherrack)
B(2,3,8,minecraft:netherrack)
B(2,4,8,minecraft:netherrack)
B(2,5,8,minecraft:netherrack)
B(2,6,8,minecraft:netherrack)
B(2,7,8,minecraft:netherrack)
B(2,8,8,minecraft:netherrack)
B(3,0,-6,minecraft:lava[level=7])
B(3,0,-5,minecraft:lava[level=6])
B(3,0,-4,minecraft:lava[level=5])
B(3,0,-3,minecraft:lava[level=4])
B(3,0,-2,minecraft:lava[level=3])
B(3,0,-1,minecraft:lava[level=2])
B(3,0,0,minecraft:lava[level=1])
B(3,0,1,minecraft:lava[level=2])
B(3,0,2,minecraft:netherrack)
B(3,1,2,minecraft:netherrack)
B(3,0,3,minecraft:netherrack)
B(3,1,3,minecraft:netherrack)
B(3,2,3,minecraft:netherrack)
B(3,3,3,minecraft:netherrack)
B(3,4,3,minecraft:netherrack)
B(3,5,3,minecraft:netherrack)
B(3,0,4,minecraft:netherrack)
B(3,1,4,minecraft:netherrack)
B(3,2,4,minecraft:netherrack)
B(3,3,4,minecraft:netherrack)
B(3,4,4,minecraft:netherrack)
B(3,5,4,minecraft:netherrack)
B(3,6,4,minecraft:netherrack)
B(3,0,5,minecraft:netherrack)
B(3,1,5,minecraft:netherrack)
B(3,2,5,minecraft:netherrack)
B(3,3,5,minecraft:netherrack)
B(3,4,5,minecraft:netherrack)
B(3,5,5,minecraft:netherrack)
B(3,6,5,minecraft:netherrack)
B(3,7,5,minecraft:netherrack)
B(3,0,6,minecraft:netherrack)
B(3,1,6,minecraft:netherrack)
B(3,2,6,minecraft:netherrack)
B(3,3,6,minecraft:netherrack)
B(3,4,6,minecraft:netherrack)
B(3,5,6,minecraft:netherrack)
B(3,6,6,minecraft:netherrack)
B(3,7,6,minecraft:netherrack)
B(3,8,6,minecraft:netherrack)
B(3,0,7,minecraft:netherrack)
B(3,1,7,minecraft:netherrack)
B(3,2,7,minecraft:netherrack)
B(3,3,7,minecraft:netherrack)
B(3,4,7,minecraft:netherrack)
B(3,5,7,minecraft:netherrack)
B(3,6,7,minecraft:netherrack)
B(3,7,7,minecraft:netherrack)
B(3,8,7,minecraft:netherrack)
B(3,0,8,minecraft:netherrack)
B(3,1,8,minecraft:netherrack)
B(3,2,8,minecraft:netherrack)
B(3,3,8,minecraft:netherrack)
B(3,4,8,minecraft:netherrack)
B(3,5,8,minecraft:netherrack)
B(3,6,8,minecraft:netherrack)
B(3,7,8,minecraft:netherrack)
B(3,8,8,minecraft:netherrack)
B(4,0,-7,minecraft:lava[level=7])
B(4,0,-6,minecraft:lava[level=6])
B(4,0,-5,minecraft:lava[level=5])
B(4,0,-4,minecraft:lava[level=4])
B(4,0,-3,minecraft:lava[level=3])
B(4,0,-2,minecraft:lava[level=2])
B(4,0,-1,minecraft:lava[level=1])
B(4,0,0,minecraft:lava[level=8])
B(4,1,0,minecraft:lava[level=3])
B(4,0,1,minecraft:netherrack)
B(4,1,1,minecraft:netherrack)
B(4,0,2,minecraft:netherrack)
B(4,1,2,minecraft:netherrack)
B(4,2,2,minecraft:netherrack)
B(4,0,3,minecraft:netherrack)
B(4,1,3,minecraft:netherrack)
B(4,2,3,minecraft:netherrack)
B(4,3,3,minecraft:netherrack)
B(4,4,3,minecraft:netherrack)
B(4,0,4,minecraft:netherrack)
B(4,1,4,minecraft:netherrack)
B(4,2,4,minecraft:netherrack)
B(4,3,4,minecraft:netherrack)
B(4,4,4,minecraft:netherrack)
B(4,5,4,minecraft:netherrack)
B(4,6,4,minecraft:netherrack)
B(4,0,5,minecraft:netherrack)
B(4,1,5,minecraft:netherrack)
B(4,2,5,minecraft:netherrack)
B(4,3,5,minecraft:netherrack)
B(4,4,5,minecraft:netherrack)
B(4,5,5,minecraft:netherrack)
B(4,6,5,minecraft:netherrack)
B(4,7,5,minecraft:netherrack)
B(4,0,6,minecraft:netherrack)
B(4,1,6,minecraft:netherrack)
B(4,2,6,minecraft:netherrack)
B(4,3,6,minecraft:netherrack)
B(4,4,6,minecraft:netherrack)
B(4,5,6,minecraft:netherrack)
B(4,6,6,minecraft:netherrack)
B(4,7,6,minecraft:netherrack)
B(4,0,7,minecraft:netherrack)
B(4,1,7,minecraft:netherrack)
B(4,2,7,minecraft:netherrack)
B(4,3,7,minecraft:netherrack)
B(4,4,7,minecraft:netherrack)
B(4,5,7,minecraft:netherrack)
B(4,6,7,minecraft:netherrack)
B(4,7,7,minecraft:netherrack)
B(4,8,7,minecraft:netherrack)
B(4,0,8,minecraft:netherrack)
B(4,1,8,minecraft:netherrack)
B(4,2,8,minecraft:netherrack)
B(4,3,8,minecraft:netherrack)
B(4,4,8,minecraft:netherrack)
B(4,5,8,minecraft:netherrack)
B(4,6,8,minecraft:netherrack)
B(4,7,8,minecraft:netherrack)
B(4,8,8,minecraft:netherrack)
B(5,0,-6,minecraft:lava[level=7])
B(5,0,-5,minecraft:lava[level=6])
B(5,0,-4,minecraft:lava[level=5])
B(5,0,-3,minecraft:lava[level=4])
B(5,0,-2,minecraft:lava[level=3])
B(5,0,-1,minecraft:netherrack)
B(5,1,-1,minecraft:netherrack)
B(5,0,0,minecraft:netherrack)
B(5,1,0,minecraft:lava[level=2])
B(5,0,1,minecraft:netherrack)
B(5,1,1,minecraft:netherrack)
B(5,2,1,minecraft:netherrack)
B(5,0,2,minecraft:netherrack)
B(5,1,2,minecraft:netherrack)
B(5,2,2,minecraft:netherrack)
B(5,3,2,minecraft:netherrack)
B(5,0,3,minecraft:netherrack)
B(5,1,3,minecraft:netherrack)
B(5,2,3,minecraft:netherrack)
B(5,3,3,minecraft:netherrack)
B(5,4,3,minecraft:netherrack)
B(5,5,3,minecraft:netherrack)
B(5,0,4,minecraft:netherrack)
B(5,1,4,minecraft:netherrack)
B(5,2,4,minecraft:netherrack)
B(5,3,4,minecraft:netherrack)
B(5,4,4,minecraft:netherrack)
B(5,5,4,minecraft:netherrack)
B(5,0,5,minecraft:netherrack)
B(5,1,5,minecraft:netherrack)
B(5,2,5,minecraft:netherrack)
B(5,3,5,minecraft:netherrack)
B(5,4,5,minecraft:netherrack)
B(5,5,5,minecraft:netherrack)
B(5,6,5,minecraft:netherrack)
B(5,7,5,minecraft:netherrack)
B(5,0,6,minecraft:netherrack)
B(5,1,6,minecraft:netherrack)
B(5,2,6,minecraft:netherrack)
B(5,3,6,minecraft:netherrack)
B(5,4,6,minecraft:netherrack)
B(5,5,6,minecraft:netherrack)
B(5,6,6,minecraft:netherrack)
B(5,7,6,minecraft:netherrack)
B(5,0,7,minecraft:netherrack)
B(5,1,7,minecraft:netherrack)
B(5,2,7,minecraft:netherrack)
B(5,3,7,minecraft:netherrack)
B(5,4,7,minecraft:netherrack)
B(5,5,7,minecraft:netherrack)
B(5,6,7,minecraft:netherrack)
B(5,7,7,minecraft:netherrack)
B(5,8,7,minecraft:netherrack)
B(5,9,7,minecraft:netherrack)
B(5,0,8,minecraft:netherrack)
B(5,1,8,minecraft:netherrack)
B(5,2,8,minecraft:netherrack)
B(5,3,8,minecraft:netherrack)
B(5,4,8,minecraft:netherrack)
B(5,5,8,minecraft:netherrack)
B(5,6,8,minecraft:netherrack)
B(5,7,8,minecraft:netherrack)
B(5,8,8,minecraft:netherrack)
B(5,9,8,minecraft:netherrack)
B(6,0,-5,minecraft:lava[level=7])
B(6,0,-4,minecraft:lava[level=6])
B(6,0,-3,minecraft:lava[level=5])
B(6,0,-2,minecraft:lava[level=4])
B(6,0,-1,minecraft:netherrack)
B(6,1,-1,minecraft:netherrack)
B(6,0,0,minecraft:netherrack)
B(6,1,0,minecraft:lava[level=1])
B(6,0,1,minecraft:netherrack)
B(6,1,1,minecraft:lava[level=8])
B(6,2,1,minecraft:lava[level=1])
B(6,0,2,minecraft:netherrack)
B(6,1,2,minecraft:netherrack)
B(6,2,2,minecraft:lava[level=8])
B(6,3,2,minecraft:lava[level=1])
B(6,0,3,minecraft:netherrack)
B(6,1,3,minecraft:netherrack)
B(6,2,3,minecraft:netherrack)
B(6,3,3,minecraft:lava[level=8])
B(6,4,3,minecraft:lava[level=8])
B(6,5,3,minecraft:lava[level=2])
B(6,0,4,minecraft:netherrack)
B(6,1,4,minecraft:netherrack)
B(6,2,4,minecraft:netherrack)
B(6,3,4,minecraft:netherrack)
B(6,4,4,minecraft:netherrack)
B(6,5,4,minecraft:lava[level=1])
B(6,0,5,minecraft:netherrack)
B(6,1,5,minecraft:netherrack)
B(6,2,5,minecraft:netherrack)
B(6,3,5,minecraft:netherrack)
B(6,4,5,minecraft:netherrack)
B(6,5,5,minecraft:lava[level=8])
B(6,6,5,minecraft:lava[level=2])
B(6,0,6,minecraft:netherrack)
B(6,1,6,minecraft:netherrack)
B(6,2,6,minecraft:netherrack)
B(6,3,6,minecraft:netherrack)
B(6,4,6,minecraft:netherrack)
B(6,5,6,minecraft:netherrack)
B(6,6,6,minecraft:lava[level=1])
B(6,0,7,minecraft:netherrack)
B(6,1,7,minecraft:netherrack)
B(6,2,7,minecraft:netherrack)
B(6,3,7,minecraft:netherrack)
B(6,4,7,minecraft:netherrack)
B(6,5,7,minecraft:netherrack)
B(6,6,7,minecraft:lava[level=8])
B(6,7,7,minecraft:lava[level=1])
B(6,0,8,minecraft:netherrack)
B(6,1,8,minecraft:netherrack)
B(6,2,8,minecraft:netherrack)
B(6,3,8,minecraft:netherrack)
B(6,4,8,minecraft:netherrack)
B(6,5,8,minecraft:netherrack)
B(6,6,8,minecraft:netherrack)
B(6,7,8,minecraft:lava[level=8])
B(6,8,8,minecraft:lava[level=1])
B(7,0,-4,minecraft:lava[level=7])
B(7,0,-3,minecraft:lava[level=6])
B(7,0,-2,minecraft:lava[level=5])
B(7,0,-1,minecraft:lava[level=6])
B(7,0,0,minecraft:netherrack)
B(7,1,0,minecraft:netherrack)
B(7,0,1,minecraft:netherrack)
B(7,1,1,minecraft:netherrack)
B(7,2,1,minecraft:netherrack)
B(7,0,2,minecraft:netherrack)
B(7,1,2,minecraft:netherrack)
B(7,2,2,minecraft:netherrack)
B(7,3,2,minecraft:netherrack)
B(7,0,3,minecraft:netherrack)
B(7,1,3,minecraft:netherrack)
B(7,2,3,minecraft:netherrack)
B(7,3,3,minecraft:netherrack)
B(7,4,3,minecraft:netherrack)
B(7,5,3,minecraft:netherrack)
B(7,0,4,minecraft:netherrack)
B(7,1,4,minecraft:netherrack)
B(7,2,4,minecraft:netherrack)
B(7,3,4,minecraft:netherrack)
B(7,4,4,minecraft:netherrack)
B(7,5,4,minecraft:netherrack)
B(7,6,4,minecraft:netherrack)
B(7,0,5,minecraft:netherrack)
B(7,1,5,minecraft:netherrack)
B(7,2,5,minecraft:netherrack)
B(7,3,5,minecraft:netherrack)
B(7,4,5,minecraft:netherrack)
B(7,5,5,minecraft:netherrack)
B(7,6,5,minecraft:netherrack)
B(7,7,5,minecraft:netherrack)
B(7,0,6,minecraft:netherrack)
B(7,1,6,minecraft:netherrack)
B(7,2,6,minecraft:netherrack)
B(7,3,6,minecraft:netherrack)
B(7,4,6,minecraft:netherrack)
B(7,5,6,minecraft:netherrack)
B(7,6,6,minecraft:netherrack)
B(7,7,6,minecraft:netherrack)
B(7,0,7,minecraft:netherrack)
B(7,1,7,minecraft:netherrack)
B(7,2,7,minecraft:netherrack)
B(7,3,7,minecraft:netherrack)
B(7,4,7,minecraft:netherrack)
B(7,5,7,minecraft:netherrack)
B(7,6,7,minecraft:netherrack)
B(7,7,7,minecraft:netherrack)
B(7,8,7,minecraft:netherrack)
B(7,9,7,minecraft:netherrack)
B(7,0,8,minecraft:netherrack)
B(7,1,8,minecraft:netherrack)
B(7,2,8,minecraft:netherrack)
B(7,3,8,minecraft:netherrack)
B(7,4,8,minecraft:netherrack)
B(7,5,8,minecraft:netherrack)
B(7,6,8,minecraft:netherrack)
B(7,7,8,minecraft:netherrack)
B(7,8,8,minecraft:netherrack)
B(7,9,8,minecraft:netherrack)

#######################################################################
# +-----------------------------------------------------------------+ #
# |                             Branches                            | #
# +-----------------------------------------------------------------+ #
#######################################################################

Branch(16,0,0,true,NetherrackOozingMountain3_C2_R0,NORTH,100.0,0)

#######################################################################
# +-----------------------------------------------------------------+ #
# |                             Entities                            | #
# +-----------------------------------------------------------------+ #
#######################################################################

