
#######################################################################
# +-----------------------------------------------------------------+ #
# |                            BO4 object                           | #
# +-----------------------------------------------------------------+ #
#######################################################################

Author: Unknown

Description: No description given

SettingsMode: WriteWithoutComments


#######################################################################
# +-----------------------------------------------------------------+ #
# |                          Main settings                          | #
# +-----------------------------------------------------------------+ #
#######################################################################

FixedRotation: 

Frequency: 0

SpawnHeight: highestBlock

UseCenterForHighestBlock: true

##############################
# Height Limits for the BO4. #
##############################

MinHeight: 0

MaxHeight: 255

InheritBO3: 

InheritBO3Rotation: NORTH

OverrideChildSettings: true

OverrideParentHeight: false

CanOverride: false

BranchFrequency: 0

BranchFrequencyGroup: 

MustBeBelowOther: false

MustBeInside: 

CannotBeInside: 

ReplacesBO3: 

MustBeInsideWorldBorders: false

CanSpawnOnWater: true

SpawnOnWaterOnly: false

SpawnUnderWater: false

SpawnAtWaterLevel: false

HeightOffset: 0

RemoveAir: true

ReplaceAbove: 

ReplaceBelow: 

ReplaceWithBiomeBlocks: true

ReplaceWithSurfaceBlock: GRASS

ReplaceWithGroundBlock: DIRT

ReplaceWithStoneBlock: STONE

SmoothRadius: 0

SmoothHeightOffset: 0

SmoothStartTop: false

SmoothStartWood: false

SmoothingSurfaceBlock: 

SmoothingGroundBlock: 

BO3Group: 

IsSpawnPoint: false

DoReplaceBlocks: true


#######################################################################
# +-----------------------------------------------------------------+ #
# |                              Blocks                             | #
# +-----------------------------------------------------------------+ #
#######################################################################

B(-8,61,-7,minecraft:netherrack)
B(-8,62,-7,minecraft:netherrack)
B(-8,63,-7,minecraft:netherrack)
B(-8,64,-7,minecraft:netherrack)
B(-8,65,-7,minecraft:netherrack)
B(-8,66,-7,minecraft:netherrack)
B(-8,60,-6,minecraft:netherrack)
B(-8,61,-6,minecraft:netherrack)
B(-8,62,-6,minecraft:netherrack)
B(-8,63,-6,minecraft:netherrack)
B(-8,64,-6,minecraft:netherrack)
B(-8,65,-6,minecraft:netherrack)
B(-8,66,-6,minecraft:netherrack)
B(-8,59,-5,minecraft:netherrack)
B(-8,60,-5,minecraft:netherrack)
B(-8,61,-5,minecraft:netherrack)
B(-8,62,-5,minecraft:netherrack)
B(-8,63,-5,minecraft:netherrack)
B(-8,64,-5,minecraft:netherrack)
B(-8,65,-5,minecraft:netherrack)
B(-8,66,-5,minecraft:netherrack)
B(-8,58,-4,minecraft:netherrack)
B(-8,59,-4,minecraft:netherrack)
B(-8,60,-4,minecraft:netherrack)
B(-8,61,-4,minecraft:netherrack)
B(-8,62,-4,minecraft:netherrack)
B(-8,63,-4,minecraft:netherrack)
B(-8,64,-4,minecraft:netherrack)
B(-8,65,-4,minecraft:netherrack)
B(-8,66,-4,minecraft:netherrack)
B(-8,56,-3,minecraft:netherrack)
B(-8,57,-3,minecraft:netherrack)
B(-8,58,-3,minecraft:netherrack)
B(-8,59,-3,minecraft:netherrack)
B(-8,60,-3,minecraft:netherrack)
B(-8,61,-3,minecraft:netherrack)
B(-8,62,-3,minecraft:netherrack)
B(-8,63,-3,minecraft:netherrack)
B(-8,64,-3,minecraft:netherrack)
B(-8,65,-3,minecraft:netherrack)
B(-8,66,-3,minecraft:netherrack)
B(-8,55,-2,minecraft:netherrack)
B(-8,56,-2,minecraft:netherrack)
B(-8,57,-2,minecraft:netherrack)
B(-8,58,-2,minecraft:netherrack)
B(-8,59,-2,minecraft:netherrack)
B(-8,60,-2,minecraft:netherrack)
B(-8,61,-2,minecraft:netherrack)
B(-8,62,-2,minecraft:netherrack)
B(-8,63,-2,minecraft:netherrack)
B(-8,64,-2,minecraft:netherrack)
B(-8,65,-2,minecraft:netherrack)
B(-8,66,-2,minecraft:netherrack)
B(-8,54,-1,minecraft:netherrack)
B(-8,55,-1,minecraft:netherrack)
B(-8,56,-1,minecraft:netherrack)
B(-8,57,-1,minecraft:netherrack)
B(-8,58,-1,minecraft:netherrack)
B(-8,59,-1,minecraft:netherrack)
B(-8,60,-1,minecraft:netherrack)
B(-8,61,-1,minecraft:netherrack)
B(-8,62,-1,minecraft:netherrack)
B(-8,63,-1,minecraft:netherrack)
B(-8,64,-1,minecraft:netherrack)
B(-8,65,-1,minecraft:netherrack)
B(-8,66,-1,minecraft:netherrack)
B(-8,51,0,minecraft:netherrack)
B(-8,52,0,minecraft:netherrack)
B(-8,53,0,minecraft:netherrack)
B(-8,54,0,minecraft:netherrack)
B(-8,55,0,minecraft:netherrack)
B(-8,56,0,minecraft:netherrack)
B(-8,57,0,minecraft:netherrack)
B(-8,58,0,minecraft:netherrack)
B(-8,59,0,minecraft:netherrack)
B(-8,60,0,minecraft:netherrack)
B(-8,61,0,minecraft:netherrack)
B(-8,62,0,minecraft:netherrack)
B(-8,63,0,minecraft:netherrack)
B(-8,64,0,minecraft:netherrack)
B(-8,65,0,minecraft:netherrack)
B(-8,66,0,minecraft:netherrack)
B(-8,36,1,minecraft:netherrack)
B(-8,37,1,minecraft:netherrack)
B(-8,38,1,minecraft:netherrack)
B(-8,39,1,minecraft:netherrack)
B(-8,40,1,minecraft:netherrack)
B(-8,41,1,minecraft:netherrack)
B(-8,42,1,minecraft:netherrack)
B(-8,43,1,minecraft:netherrack)
B(-8,44,1,minecraft:netherrack)
B(-8,45,1,minecraft:netherrack)
B(-8,46,1,minecraft:netherrack)
B(-8,47,1,minecraft:netherrack)
B(-8,48,1,minecraft:netherrack)
B(-8,49,1,minecraft:netherrack)
B(-8,50,1,minecraft:netherrack)
B(-8,51,1,minecraft:netherrack)
B(-8,52,1,minecraft:netherrack)
B(-8,53,1,minecraft:netherrack)
B(-8,54,1,minecraft:netherrack)
B(-8,55,1,minecraft:netherrack)
B(-8,56,1,minecraft:netherrack)
B(-8,57,1,minecraft:netherrack)
B(-8,58,1,minecraft:netherrack)
B(-8,59,1,minecraft:netherrack)
B(-8,60,1,minecraft:netherrack)
B(-8,61,1,minecraft:netherrack)
B(-8,62,1,minecraft:netherrack)
B(-8,63,1,minecraft:netherrack)
B(-8,64,1,minecraft:netherrack)
B(-8,65,1,minecraft:netherrack)
B(-8,66,1,minecraft:netherrack)
B(-8,32,2,minecraft:netherrack)
B(-8,33,2,minecraft:netherrack)
B(-8,34,2,minecraft:netherrack)
B(-8,35,2,minecraft:netherrack)
B(-8,36,2,minecraft:netherrack)
B(-8,37,2,minecraft:netherrack)
B(-8,38,2,minecraft:netherrack)
B(-8,39,2,minecraft:netherrack)
B(-8,40,2,minecraft:netherrack)
B(-8,41,2,minecraft:netherrack)
B(-8,42,2,minecraft:netherrack)
B(-8,43,2,minecraft:netherrack)
B(-8,44,2,minecraft:netherrack)
B(-8,45,2,minecraft:netherrack)
B(-8,46,2,minecraft:netherrack)
B(-8,47,2,minecraft:netherrack)
B(-8,48,2,minecraft:netherrack)
B(-8,49,2,minecraft:netherrack)
B(-8,50,2,minecraft:netherrack)
B(-8,51,2,minecraft:netherrack)
B(-8,52,2,minecraft:netherrack)
B(-8,53,2,minecraft:netherrack)
B(-8,54,2,minecraft:netherrack)
B(-8,55,2,minecraft:netherrack)
B(-8,56,2,minecraft:netherrack)
B(-8,57,2,minecraft:netherrack)
B(-8,58,2,minecraft:netherrack)
B(-8,59,2,minecraft:netherrack)
B(-8,60,2,minecraft:netherrack)
B(-8,61,2,minecraft:netherrack)
B(-8,62,2,minecraft:netherrack)
B(-8,63,2,minecraft:netherrack)
B(-8,64,2,minecraft:netherrack)
B(-8,65,2,minecraft:netherrack)
B(-8,66,2,minecraft:netherrack)
B(-8,28,3,minecraft:netherrack)
B(-8,29,3,minecraft:netherrack)
B(-8,30,3,minecraft:netherrack)
B(-8,31,3,minecraft:netherrack)
B(-8,32,3,minecraft:netherrack)
B(-8,33,3,minecraft:netherrack)
B(-8,34,3,minecraft:netherrack)
B(-8,35,3,minecraft:netherrack)
B(-8,36,3,minecraft:netherrack)
B(-8,37,3,minecraft:netherrack)
B(-8,38,3,minecraft:netherrack)
B(-8,39,3,minecraft:netherrack)
B(-8,40,3,minecraft:netherrack)
B(-8,41,3,minecraft:netherrack)
B(-8,42,3,minecraft:netherrack)
B(-8,43,3,minecraft:netherrack)
B(-8,44,3,minecraft:netherrack)
B(-8,45,3,minecraft:netherrack)
B(-8,46,3,minecraft:netherrack)
B(-8,47,3,minecraft:netherrack)
B(-8,48,3,minecraft:netherrack)
B(-8,49,3,minecraft:netherrack)
B(-8,50,3,minecraft:netherrack)
B(-8,51,3,minecraft:netherrack)
B(-8,52,3,minecraft:netherrack)
B(-8,53,3,minecraft:netherrack)
B(-8,54,3,minecraft:netherrack)
B(-8,55,3,minecraft:netherrack)
B(-8,56,3,minecraft:netherrack)
B(-8,57,3,minecraft:netherrack)
B(-8,58,3,minecraft:netherrack)
B(-8,59,3,minecraft:netherrack)
B(-8,60,3,minecraft:netherrack)
B(-8,61,3,minecraft:netherrack)
B(-8,62,3,minecraft:netherrack)
B(-8,63,3,minecraft:netherrack)
B(-8,64,3,minecraft:netherrack)
B(-8,65,3,minecraft:netherrack)
B(-8,66,3,minecraft:netherrack)
B(-8,22,4,minecraft:netherrack)
B(-8,23,4,minecraft:netherrack)
B(-8,24,4,minecraft:netherrack)
B(-8,25,4,minecraft:netherrack)
B(-8,26,4,minecraft:netherrack)
B(-8,27,4,minecraft:netherrack)
B(-8,28,4,minecraft:netherrack)
B(-8,29,4,minecraft:netherrack)
B(-8,30,4,minecraft:netherrack)
B(-8,31,4,minecraft:netherrack)
B(-8,32,4,minecraft:netherrack)
B(-8,33,4,minecraft:netherrack)
B(-8,34,4,minecraft:netherrack)
B(-8,35,4,minecraft:netherrack)
B(-8,36,4,minecraft:netherrack)
B(-8,37,4,minecraft:netherrack)
B(-8,38,4,minecraft:netherrack)
B(-8,39,4,minecraft:netherrack)
B(-8,40,4,minecraft:netherrack)
B(-8,41,4,minecraft:netherrack)
B(-8,42,4,minecraft:netherrack)
B(-8,43,4,minecraft:netherrack)
B(-8,44,4,minecraft:netherrack)
B(-8,45,4,minecraft:netherrack)
B(-8,46,4,minecraft:netherrack)
B(-8,47,4,minecraft:netherrack)
B(-8,48,4,minecraft:netherrack)
B(-8,49,4,minecraft:netherrack)
B(-8,50,4,minecraft:netherrack)
B(-8,51,4,minecraft:netherrack)
B(-8,52,4,minecraft:netherrack)
B(-8,53,4,minecraft:netherrack)
B(-8,54,4,minecraft:netherrack)
B(-8,55,4,minecraft:netherrack)
B(-8,56,4,minecraft:netherrack)
B(-8,57,4,minecraft:netherrack)
B(-8,58,4,minecraft:netherrack)
B(-8,59,4,minecraft:netherrack)
B(-8,60,4,minecraft:netherrack)
B(-8,61,4,minecraft:netherrack)
B(-8,62,4,minecraft:netherrack)
B(-8,63,4,minecraft:netherrack)
B(-8,64,4,minecraft:netherrack)
B(-8,65,4,minecraft:netherrack)
B(-8,66,4,minecraft:netherrack)
B(-8,19,5,minecraft:netherrack)
B(-8,20,5,minecraft:netherrack)
B(-8,21,5,minecraft:netherrack)
B(-8,22,5,minecraft:netherrack)
B(-8,23,5,minecraft:netherrack)
B(-8,24,5,minecraft:netherrack)
B(-8,25,5,minecraft:netherrack)
B(-8,26,5,minecraft:netherrack)
B(-8,27,5,minecraft:netherrack)
B(-8,28,5,minecraft:netherrack)
B(-8,29,5,minecraft:netherrack)
B(-8,30,5,minecraft:netherrack)
B(-8,31,5,minecraft:netherrack)
B(-8,32,5,minecraft:netherrack)
B(-8,33,5,minecraft:netherrack)
B(-8,34,5,minecraft:netherrack)
B(-8,35,5,minecraft:netherrack)
B(-8,36,5,minecraft:netherrack)
B(-8,37,5,minecraft:netherrack)
B(-8,38,5,minecraft:netherrack)
B(-8,39,5,minecraft:netherrack)
B(-8,40,5,minecraft:netherrack)
B(-8,41,5,minecraft:netherrack)
B(-8,42,5,minecraft:netherrack)
B(-8,43,5,minecraft:netherrack)
B(-8,44,5,minecraft:netherrack)
B(-8,45,5,minecraft:netherrack)
B(-8,46,5,minecraft:netherrack)
B(-8,47,5,minecraft:netherrack)
B(-8,48,5,minecraft:netherrack)
B(-8,49,5,minecraft:netherrack)
B(-8,50,5,minecraft:netherrack)
B(-8,51,5,minecraft:netherrack)
B(-8,52,5,minecraft:netherrack)
B(-8,53,5,minecraft:netherrack)
B(-8,54,5,minecraft:netherrack)
B(-8,55,5,minecraft:netherrack)
B(-8,56,5,minecraft:netherrack)
B(-8,57,5,minecraft:netherrack)
B(-8,58,5,minecraft:netherrack)
B(-8,59,5,minecraft:netherrack)
B(-8,60,5,minecraft:netherrack)
B(-8,61,5,minecraft:netherrack)
B(-8,62,5,minecraft:netherrack)
B(-8,63,5,minecraft:netherrack)
B(-8,64,5,minecraft:netherrack)
B(-8,65,5,minecraft:netherrack)
B(-8,66,5,minecraft:netherrack)
B(-8,16,6,minecraft:netherrack)
B(-8,17,6,minecraft:netherrack)
B(-8,18,6,minecraft:netherrack)
B(-8,19,6,minecraft:netherrack)
B(-8,20,6,minecraft:netherrack)
B(-8,21,6,minecraft:netherrack)
B(-8,22,6,minecraft:netherrack)
B(-8,23,6,minecraft:netherrack)
B(-8,24,6,minecraft:netherrack)
B(-8,25,6,minecraft:netherrack)
B(-8,26,6,minecraft:netherrack)
B(-8,27,6,minecraft:netherrack)
B(-8,28,6,minecraft:netherrack)
B(-8,29,6,minecraft:netherrack)
B(-8,30,6,minecraft:netherrack)
B(-8,31,6,minecraft:netherrack)
B(-8,32,6,minecraft:netherrack)
B(-8,33,6,minecraft:netherrack)
B(-8,34,6,minecraft:netherrack)
B(-8,35,6,minecraft:netherrack)
B(-8,36,6,minecraft:netherrack)
B(-8,37,6,minecraft:netherrack)
B(-8,38,6,minecraft:netherrack)
B(-8,39,6,minecraft:netherrack)
B(-8,40,6,minecraft:netherrack)
B(-8,41,6,minecraft:netherrack)
B(-8,42,6,minecraft:netherrack)
B(-8,43,6,minecraft:netherrack)
B(-8,44,6,minecraft:netherrack)
B(-8,45,6,minecraft:netherrack)
B(-8,46,6,minecraft:netherrack)
B(-8,47,6,minecraft:netherrack)
B(-8,48,6,minecraft:netherrack)
B(-8,49,6,minecraft:netherrack)
B(-8,50,6,minecraft:netherrack)
B(-8,51,6,minecraft:netherrack)
B(-8,52,6,minecraft:netherrack)
B(-8,53,6,minecraft:netherrack)
B(-8,54,6,minecraft:netherrack)
B(-8,55,6,minecraft:netherrack)
B(-8,56,6,minecraft:netherrack)
B(-8,57,6,minecraft:netherrack)
B(-8,58,6,minecraft:netherrack)
B(-8,59,6,minecraft:netherrack)
B(-8,60,6,minecraft:netherrack)
B(-8,61,6,minecraft:netherrack)
B(-8,62,6,minecraft:netherrack)
B(-8,63,6,minecraft:netherrack)
B(-8,64,6,minecraft:netherrack)
B(-8,65,6,minecraft:netherrack)
B(-8,66,6,minecraft:netherrack)
B(-8,14,7,minecraft:netherrack)
B(-8,15,7,minecraft:netherrack)
B(-8,16,7,minecraft:netherrack)
B(-8,17,7,minecraft:netherrack)
B(-8,18,7,minecraft:netherrack)
B(-8,19,7,minecraft:netherrack)
B(-8,20,7,minecraft:netherrack)
B(-8,21,7,minecraft:netherrack)
B(-8,22,7,minecraft:netherrack)
B(-8,23,7,minecraft:netherrack)
B(-8,24,7,minecraft:netherrack)
B(-8,25,7,minecraft:netherrack)
B(-8,26,7,minecraft:netherrack)
B(-8,27,7,minecraft:netherrack)
B(-8,28,7,minecraft:netherrack)
B(-8,29,7,minecraft:netherrack)
B(-8,30,7,minecraft:netherrack)
B(-8,31,7,minecraft:netherrack)
B(-8,32,7,minecraft:netherrack)
B(-8,33,7,minecraft:netherrack)
B(-8,34,7,minecraft:netherrack)
B(-8,35,7,minecraft:netherrack)
B(-8,36,7,minecraft:netherrack)
B(-8,37,7,minecraft:netherrack)
B(-8,38,7,minecraft:netherrack)
B(-8,39,7,minecraft:netherrack)
B(-8,40,7,minecraft:netherrack)
B(-8,41,7,minecraft:netherrack)
B(-8,42,7,minecraft:netherrack)
B(-8,43,7,minecraft:netherrack)
B(-8,44,7,minecraft:netherrack)
B(-8,45,7,minecraft:netherrack)
B(-8,46,7,minecraft:netherrack)
B(-8,47,7,minecraft:netherrack)
B(-8,48,7,minecraft:netherrack)
B(-8,49,7,minecraft:netherrack)
B(-8,50,7,minecraft:netherrack)
B(-8,51,7,minecraft:netherrack)
B(-8,52,7,minecraft:netherrack)
B(-8,53,7,minecraft:netherrack)
B(-8,54,7,minecraft:netherrack)
B(-8,55,7,minecraft:netherrack)
B(-8,56,7,minecraft:netherrack)
B(-8,57,7,minecraft:netherrack)
B(-8,58,7,minecraft:netherrack)
B(-8,59,7,minecraft:netherrack)
B(-8,60,7,minecraft:netherrack)
B(-8,61,7,minecraft:netherrack)
B(-8,62,7,minecraft:netherrack)
B(-8,63,7,minecraft:netherrack)
B(-8,64,7,minecraft:netherrack)
B(-8,65,7,minecraft:netherrack)
B(-8,66,7,minecraft:netherrack)
B(-8,9,8,minecraft:netherrack)
B(-8,10,8,minecraft:netherrack)
B(-8,11,8,minecraft:netherrack)
B(-8,12,8,minecraft:netherrack)
B(-8,13,8,minecraft:netherrack)
B(-8,14,8,minecraft:netherrack)
B(-8,15,8,minecraft:netherrack)
B(-8,16,8,minecraft:netherrack)
B(-8,17,8,minecraft:netherrack)
B(-8,18,8,minecraft:netherrack)
B(-8,19,8,minecraft:netherrack)
B(-8,20,8,minecraft:netherrack)
B(-8,21,8,minecraft:netherrack)
B(-8,22,8,minecraft:netherrack)
B(-8,23,8,minecraft:netherrack)
B(-8,24,8,minecraft:netherrack)
B(-8,25,8,minecraft:netherrack)
B(-8,26,8,minecraft:netherrack)
B(-8,27,8,minecraft:netherrack)
B(-8,28,8,minecraft:netherrack)
B(-8,29,8,minecraft:netherrack)
B(-8,30,8,minecraft:netherrack)
B(-8,31,8,minecraft:netherrack)
B(-8,32,8,minecraft:netherrack)
B(-8,33,8,minecraft:netherrack)
B(-8,34,8,minecraft:netherrack)
B(-8,35,8,minecraft:netherrack)
B(-8,36,8,minecraft:netherrack)
B(-8,37,8,minecraft:netherrack)
B(-8,38,8,minecraft:netherrack)
B(-8,39,8,minecraft:netherrack)
B(-8,40,8,minecraft:netherrack)
B(-8,41,8,minecraft:netherrack)
B(-8,42,8,minecraft:netherrack)
B(-8,43,8,minecraft:netherrack)
B(-8,44,8,minecraft:netherrack)
B(-8,45,8,minecraft:netherrack)
B(-8,46,8,minecraft:netherrack)
B(-8,47,8,minecraft:netherrack)
B(-8,48,8,minecraft:netherrack)
B(-8,49,8,minecraft:netherrack)
B(-8,50,8,minecraft:netherrack)
B(-8,51,8,minecraft:netherrack)
B(-8,52,8,minecraft:netherrack)
B(-8,53,8,minecraft:netherrack)
B(-8,54,8,minecraft:netherrack)
B(-8,55,8,minecraft:netherrack)
B(-8,56,8,minecraft:netherrack)
B(-8,57,8,minecraft:netherrack)
B(-8,58,8,minecraft:netherrack)
B(-8,59,8,minecraft:netherrack)
B(-8,60,8,minecraft:netherrack)
B(-8,61,8,minecraft:netherrack)
B(-8,62,8,minecraft:netherrack)
B(-8,63,8,minecraft:netherrack)
B(-8,64,8,minecraft:netherrack)
B(-8,65,8,minecraft:netherrack)
B(-8,66,8,minecraft:netherrack)
B(-7,61,-7,minecraft:netherrack)
B(-7,62,-7,minecraft:netherrack)
B(-7,63,-7,minecraft:netherrack)
B(-7,64,-7,minecraft:netherrack)
B(-7,65,-7,minecraft:netherrack)
B(-7,66,-7,minecraft:netherrack)
B(-7,60,-6,minecraft:netherrack)
B(-7,61,-6,minecraft:netherrack)
B(-7,62,-6,minecraft:netherrack)
B(-7,63,-6,minecraft:netherrack)
B(-7,64,-6,minecraft:netherrack)
B(-7,65,-6,minecraft:netherrack)
B(-7,66,-6,minecraft:netherrack)
B(-7,58,-5,minecraft:netherrack)
B(-7,59,-5,minecraft:netherrack)
B(-7,60,-5,minecraft:netherrack)
B(-7,61,-5,minecraft:netherrack)
B(-7,62,-5,minecraft:netherrack)
B(-7,63,-5,minecraft:netherrack)
B(-7,64,-5,minecraft:netherrack)
B(-7,65,-5,minecraft:netherrack)
B(-7,66,-5,minecraft:netherrack)
B(-7,57,-4,minecraft:netherrack)
B(-7,58,-4,minecraft:netherrack)
B(-7,59,-4,minecraft:netherrack)
B(-7,60,-4,minecraft:netherrack)
B(-7,61,-4,minecraft:netherrack)
B(-7,62,-4,minecraft:netherrack)
B(-7,63,-4,minecraft:netherrack)
B(-7,64,-4,minecraft:netherrack)
B(-7,65,-4,minecraft:netherrack)
B(-7,66,-4,minecraft:netherrack)
B(-7,56,-3,minecraft:netherrack)
B(-7,57,-3,minecraft:netherrack)
B(-7,58,-3,minecraft:netherrack)
B(-7,59,-3,minecraft:netherrack)
B(-7,60,-3,minecraft:netherrack)
B(-7,61,-3,minecraft:netherrack)
B(-7,62,-3,minecraft:netherrack)
B(-7,63,-3,minecraft:netherrack)
B(-7,64,-3,minecraft:netherrack)
B(-7,65,-3,minecraft:netherrack)
B(-7,66,-3,minecraft:netherrack)
B(-7,55,-2,minecraft:netherrack)
B(-7,56,-2,minecraft:netherrack)
B(-7,57,-2,minecraft:netherrack)
B(-7,58,-2,minecraft:netherrack)
B(-7,59,-2,minecraft:netherrack)
B(-7,60,-2,minecraft:netherrack)
B(-7,61,-2,minecraft:netherrack)
B(-7,62,-2,minecraft:netherrack)
B(-7,63,-2,minecraft:netherrack)
B(-7,64,-2,minecraft:netherrack)
B(-7,65,-2,minecraft:netherrack)
B(-7,66,-2,minecraft:netherrack)
B(-7,54,-1,minecraft:netherrack)
B(-7,55,-1,minecraft:netherrack)
B(-7,56,-1,minecraft:netherrack)
B(-7,57,-1,minecraft:netherrack)
B(-7,58,-1,minecraft:netherrack)
B(-7,59,-1,minecraft:netherrack)
B(-7,60,-1,minecraft:netherrack)
B(-7,61,-1,minecraft:netherrack)
B(-7,62,-1,minecraft:netherrack)
B(-7,63,-1,minecraft:netherrack)
B(-7,64,-1,minecraft:netherrack)
B(-7,65,-1,minecraft:netherrack)
B(-7,66,-1,minecraft:netherrack)
B(-7,51,0,minecraft:netherrack)
B(-7,52,0,minecraft:netherrack)
B(-7,53,0,minecraft:netherrack)
B(-7,54,0,minecraft:netherrack)
B(-7,55,0,minecraft:netherrack)
B(-7,56,0,minecraft:netherrack)
B(-7,57,0,minecraft:netherrack)
B(-7,58,0,minecraft:netherrack)
B(-7,59,0,minecraft:netherrack)
B(-7,60,0,minecraft:netherrack)
B(-7,61,0,minecraft:netherrack)
B(-7,62,0,minecraft:netherrack)
B(-7,63,0,minecraft:netherrack)
B(-7,64,0,minecraft:netherrack)
B(-7,65,0,minecraft:netherrack)
B(-7,66,0,minecraft:netherrack)
B(-7,36,1,minecraft:netherrack)
B(-7,37,1,minecraft:netherrack)
B(-7,38,1,minecraft:netherrack)
B(-7,39,1,minecraft:netherrack)
B(-7,40,1,minecraft:netherrack)
B(-7,41,1,minecraft:netherrack)
B(-7,42,1,minecraft:netherrack)
B(-7,43,1,minecraft:netherrack)
B(-7,44,1,minecraft:netherrack)
B(-7,45,1,minecraft:netherrack)
B(-7,46,1,minecraft:netherrack)
B(-7,47,1,minecraft:netherrack)
B(-7,48,1,minecraft:netherrack)
B(-7,49,1,minecraft:netherrack)
B(-7,50,1,minecraft:netherrack)
B(-7,51,1,minecraft:netherrack)
B(-7,52,1,minecraft:netherrack)
B(-7,53,1,minecraft:netherrack)
B(-7,54,1,minecraft:netherrack)
B(-7,55,1,minecraft:netherrack)
B(-7,56,1,minecraft:netherrack)
B(-7,57,1,minecraft:netherrack)
B(-7,58,1,minecraft:netherrack)
B(-7,59,1,minecraft:netherrack)
B(-7,60,1,minecraft:netherrack)
B(-7,61,1,minecraft:netherrack)
B(-7,62,1,minecraft:netherrack)
B(-7,63,1,minecraft:netherrack)
B(-7,64,1,minecraft:netherrack)
B(-7,65,1,minecraft:netherrack)
B(-7,66,1,minecraft:netherrack)
B(-7,33,2,minecraft:netherrack)
B(-7,34,2,minecraft:netherrack)
B(-7,35,2,minecraft:netherrack)
B(-7,36,2,minecraft:netherrack)
B(-7,37,2,minecraft:netherrack)
B(-7,38,2,minecraft:netherrack)
B(-7,39,2,minecraft:netherrack)
B(-7,40,2,minecraft:netherrack)
B(-7,41,2,minecraft:netherrack)
B(-7,42,2,minecraft:netherrack)
B(-7,43,2,minecraft:netherrack)
B(-7,44,2,minecraft:netherrack)
B(-7,45,2,minecraft:netherrack)
B(-7,46,2,minecraft:netherrack)
B(-7,47,2,minecraft:netherrack)
B(-7,48,2,minecraft:netherrack)
B(-7,49,2,minecraft:netherrack)
B(-7,50,2,minecraft:netherrack)
B(-7,51,2,minecraft:netherrack)
B(-7,52,2,minecraft:netherrack)
B(-7,53,2,minecraft:netherrack)
B(-7,54,2,minecraft:netherrack)
B(-7,55,2,minecraft:netherrack)
B(-7,56,2,minecraft:netherrack)
B(-7,57,2,minecraft:netherrack)
B(-7,58,2,minecraft:netherrack)
B(-7,59,2,minecraft:netherrack)
B(-7,60,2,minecraft:netherrack)
B(-7,61,2,minecraft:netherrack)
B(-7,62,2,minecraft:netherrack)
B(-7,63,2,minecraft:netherrack)
B(-7,64,2,minecraft:netherrack)
B(-7,65,2,minecraft:netherrack)
B(-7,66,2,minecraft:netherrack)
B(-7,27,3,minecraft:netherrack)
B(-7,28,3,minecraft:netherrack)
B(-7,29,3,minecraft:netherrack)
B(-7,30,3,minecraft:netherrack)
B(-7,31,3,minecraft:netherrack)
B(-7,32,3,minecraft:netherrack)
B(-7,33,3,minecraft:netherrack)
B(-7,34,3,minecraft:netherrack)
B(-7,35,3,minecraft:netherrack)
B(-7,36,3,minecraft:netherrack)
B(-7,37,3,minecraft:netherrack)
B(-7,38,3,minecraft:netherrack)
B(-7,39,3,minecraft:netherrack)
B(-7,40,3,minecraft:netherrack)
B(-7,41,3,minecraft:netherrack)
B(-7,42,3,minecraft:netherrack)
B(-7,43,3,minecraft:netherrack)
B(-7,44,3,minecraft:netherrack)
B(-7,45,3,minecraft:netherrack)
B(-7,46,3,minecraft:netherrack)
B(-7,47,3,minecraft:netherrack)
B(-7,48,3,minecraft:netherrack)
B(-7,49,3,minecraft:netherrack)
B(-7,50,3,minecraft:netherrack)
B(-7,51,3,minecraft:netherrack)
B(-7,52,3,minecraft:netherrack)
B(-7,53,3,minecraft:netherrack)
B(-7,54,3,minecraft:netherrack)
B(-7,55,3,minecraft:netherrack)
B(-7,56,3,minecraft:netherrack)
B(-7,57,3,minecraft:netherrack)
B(-7,58,3,minecraft:netherrack)
B(-7,59,3,minecraft:netherrack)
B(-7,60,3,minecraft:netherrack)
B(-7,61,3,minecraft:netherrack)
B(-7,62,3,minecraft:netherrack)
B(-7,63,3,minecraft:netherrack)
B(-7,64,3,minecraft:netherrack)
B(-7,65,3,minecraft:netherrack)
B(-7,66,3,minecraft:netherrack)
B(-7,23,4,minecraft:netherrack)
B(-7,24,4,minecraft:netherrack)
B(-7,25,4,minecraft:netherrack)
B(-7,26,4,minecraft:netherrack)
B(-7,27,4,minecraft:netherrack)
B(-7,28,4,minecraft:netherrack)
B(-7,29,4,minecraft:netherrack)
B(-7,30,4,minecraft:netherrack)
B(-7,31,4,minecraft:netherrack)
B(-7,32,4,minecraft:netherrack)
B(-7,33,4,minecraft:netherrack)
B(-7,34,4,minecraft:netherrack)
B(-7,35,4,minecraft:netherrack)
B(-7,36,4,minecraft:netherrack)
B(-7,37,4,minecraft:netherrack)
B(-7,38,4,minecraft:netherrack)
B(-7,39,4,minecraft:netherrack)
B(-7,40,4,minecraft:netherrack)
B(-7,41,4,minecraft:netherrack)
B(-7,42,4,minecraft:netherrack)
B(-7,43,4,minecraft:netherrack)
B(-7,44,4,minecraft:netherrack)
B(-7,45,4,minecraft:netherrack)
B(-7,46,4,minecraft:netherrack)
B(-7,47,4,minecraft:netherrack)
B(-7,48,4,minecraft:netherrack)
B(-7,49,4,minecraft:netherrack)
B(-7,50,4,minecraft:netherrack)
B(-7,51,4,minecraft:netherrack)
B(-7,52,4,minecraft:netherrack)
B(-7,53,4,minecraft:netherrack)
B(-7,54,4,minecraft:netherrack)
B(-7,55,4,minecraft:netherrack)
B(-7,56,4,minecraft:netherrack)
B(-7,57,4,minecraft:netherrack)
B(-7,58,4,minecraft:netherrack)
B(-7,59,4,minecraft:netherrack)
B(-7,60,4,minecraft:netherrack)
B(-7,61,4,minecraft:netherrack)
B(-7,62,4,minecraft:netherrack)
B(-7,63,4,minecraft:netherrack)
B(-7,64,4,minecraft:netherrack)
B(-7,65,4,minecraft:netherrack)
B(-7,66,4,minecraft:netherrack)
B(-7,19,5,minecraft:netherrack)
B(-7,20,5,minecraft:netherrack)
B(-7,21,5,minecraft:netherrack)
B(-7,22,5,minecraft:netherrack)
B(-7,23,5,minecraft:netherrack)
B(-7,24,5,minecraft:netherrack)
B(-7,25,5,minecraft:netherrack)
B(-7,26,5,minecraft:netherrack)
B(-7,27,5,minecraft:netherrack)
B(-7,28,5,minecraft:netherrack)
B(-7,29,5,minecraft:netherrack)
B(-7,30,5,minecraft:netherrack)
B(-7,31,5,minecraft:netherrack)
B(-7,32,5,minecraft:netherrack)
B(-7,33,5,minecraft:netherrack)
B(-7,34,5,minecraft:netherrack)
B(-7,35,5,minecraft:netherrack)
B(-7,36,5,minecraft:netherrack)
B(-7,37,5,minecraft:netherrack)
B(-7,38,5,minecraft:netherrack)
B(-7,39,5,minecraft:netherrack)
B(-7,40,5,minecraft:netherrack)
B(-7,41,5,minecraft:netherrack)
B(-7,42,5,minecraft:netherrack)
B(-7,43,5,minecraft:netherrack)
B(-7,44,5,minecraft:netherrack)
B(-7,45,5,minecraft:netherrack)
B(-7,46,5,minecraft:netherrack)
B(-7,47,5,minecraft:netherrack)
B(-7,48,5,minecraft:netherrack)
B(-7,49,5,minecraft:netherrack)
B(-7,50,5,minecraft:netherrack)
B(-7,51,5,minecraft:netherrack)
B(-7,52,5,minecraft:netherrack)
B(-7,53,5,minecraft:netherrack)
B(-7,54,5,minecraft:netherrack)
B(-7,55,5,minecraft:netherrack)
B(-7,56,5,minecraft:netherrack)
B(-7,57,5,minecraft:netherrack)
B(-7,58,5,minecraft:netherrack)
B(-7,59,5,minecraft:netherrack)
B(-7,60,5,minecraft:netherrack)
B(-7,61,5,minecraft:netherrack)
B(-7,62,5,minecraft:netherrack)
B(-7,63,5,minecraft:netherrack)
B(-7,64,5,minecraft:netherrack)
B(-7,65,5,minecraft:netherrack)
B(-7,66,5,minecraft:netherrack)
B(-7,16,6,minecraft:netherrack)
B(-7,17,6,minecraft:netherrack)
B(-7,18,6,minecraft:netherrack)
B(-7,19,6,minecraft:netherrack)
B(-7,20,6,minecraft:netherrack)
B(-7,21,6,minecraft:netherrack)
B(-7,22,6,minecraft:netherrack)
B(-7,23,6,minecraft:netherrack)
B(-7,24,6,minecraft:netherrack)
B(-7,25,6,minecraft:netherrack)
B(-7,26,6,minecraft:netherrack)
B(-7,27,6,minecraft:netherrack)
B(-7,28,6,minecraft:netherrack)
B(-7,29,6,minecraft:netherrack)
B(-7,30,6,minecraft:netherrack)
B(-7,31,6,minecraft:netherrack)
B(-7,32,6,minecraft:netherrack)
B(-7,33,6,minecraft:netherrack)
B(-7,34,6,minecraft:netherrack)
B(-7,35,6,minecraft:netherrack)
B(-7,36,6,minecraft:netherrack)
B(-7,37,6,minecraft:netherrack)
B(-7,38,6,minecraft:netherrack)
B(-7,39,6,minecraft:netherrack)
B(-7,40,6,minecraft:netherrack)
B(-7,41,6,minecraft:netherrack)
B(-7,42,6,minecraft:netherrack)
B(-7,43,6,minecraft:netherrack)
B(-7,44,6,minecraft:netherrack)
B(-7,45,6,minecraft:netherrack)
B(-7,46,6,minecraft:netherrack)
B(-7,47,6,minecraft:netherrack)
B(-7,48,6,minecraft:netherrack)
B(-7,49,6,minecraft:netherrack)
B(-7,50,6,minecraft:netherrack)
B(-7,51,6,minecraft:netherrack)
B(-7,52,6,minecraft:netherrack)
B(-7,53,6,minecraft:netherrack)
B(-7,54,6,minecraft:netherrack)
B(-7,55,6,minecraft:netherrack)
B(-7,56,6,minecraft:netherrack)
B(-7,57,6,minecraft:netherrack)
B(-7,58,6,minecraft:netherrack)
B(-7,59,6,minecraft:netherrack)
B(-7,60,6,minecraft:netherrack)
B(-7,61,6,minecraft:netherrack)
B(-7,62,6,minecraft:netherrack)
B(-7,63,6,minecraft:netherrack)
B(-7,64,6,minecraft:netherrack)
B(-7,65,6,minecraft:netherrack)
B(-7,66,6,minecraft:netherrack)
B(-7,13,7,minecraft:netherrack)
B(-7,14,7,minecraft:netherrack)
B(-7,15,7,minecraft:netherrack)
B(-7,16,7,minecraft:netherrack)
B(-7,17,7,minecraft:netherrack)
B(-7,18,7,minecraft:netherrack)
B(-7,19,7,minecraft:netherrack)
B(-7,20,7,minecraft:netherrack)
B(-7,21,7,minecraft:netherrack)
B(-7,22,7,minecraft:netherrack)
B(-7,23,7,minecraft:netherrack)
B(-7,24,7,minecraft:netherrack)
B(-7,25,7,minecraft:netherrack)
B(-7,26,7,minecraft:netherrack)
B(-7,27,7,minecraft:netherrack)
B(-7,28,7,minecraft:netherrack)
B(-7,29,7,minecraft:netherrack)
B(-7,30,7,minecraft:netherrack)
B(-7,31,7,minecraft:netherrack)
B(-7,32,7,minecraft:netherrack)
B(-7,33,7,minecraft:netherrack)
B(-7,34,7,minecraft:netherrack)
B(-7,35,7,minecraft:netherrack)
B(-7,36,7,minecraft:netherrack)
B(-7,37,7,minecraft:netherrack)
B(-7,38,7,minecraft:netherrack)
B(-7,39,7,minecraft:netherrack)
B(-7,40,7,minecraft:netherrack)
B(-7,41,7,minecraft:netherrack)
B(-7,42,7,minecraft:netherrack)
B(-7,43,7,minecraft:netherrack)
B(-7,44,7,minecraft:netherrack)
B(-7,45,7,minecraft:netherrack)
B(-7,46,7,minecraft:netherrack)
B(-7,47,7,minecraft:netherrack)
B(-7,48,7,minecraft:netherrack)
B(-7,49,7,minecraft:netherrack)
B(-7,50,7,minecraft:netherrack)
B(-7,51,7,minecraft:netherrack)
B(-7,52,7,minecraft:netherrack)
B(-7,53,7,minecraft:netherrack)
B(-7,54,7,minecraft:netherrack)
B(-7,55,7,minecraft:netherrack)
B(-7,56,7,minecraft:netherrack)
B(-7,57,7,minecraft:netherrack)
B(-7,58,7,minecraft:netherrack)
B(-7,59,7,minecraft:netherrack)
B(-7,60,7,minecraft:netherrack)
B(-7,61,7,minecraft:netherrack)
B(-7,62,7,minecraft:netherrack)
B(-7,63,7,minecraft:netherrack)
B(-7,64,7,minecraft:netherrack)
B(-7,65,7,minecraft:netherrack)
B(-7,66,7,minecraft:netherrack)
B(-7,7,8,minecraft:netherrack)
B(-7,8,8,minecraft:netherrack)
B(-7,9,8,minecraft:netherrack)
B(-7,10,8,minecraft:netherrack)
B(-7,11,8,minecraft:netherrack)
B(-7,12,8,minecraft:netherrack)
B(-7,13,8,minecraft:netherrack)
B(-7,14,8,minecraft:netherrack)
B(-7,15,8,minecraft:netherrack)
B(-7,16,8,minecraft:netherrack)
B(-7,17,8,minecraft:netherrack)
B(-7,18,8,minecraft:netherrack)
B(-7,19,8,minecraft:netherrack)
B(-7,20,8,minecraft:netherrack)
B(-7,21,8,minecraft:netherrack)
B(-7,22,8,minecraft:netherrack)
B(-7,23,8,minecraft:netherrack)
B(-7,24,8,minecraft:netherrack)
B(-7,25,8,minecraft:netherrack)
B(-7,26,8,minecraft:netherrack)
B(-7,27,8,minecraft:netherrack)
B(-7,28,8,minecraft:netherrack)
B(-7,29,8,minecraft:netherrack)
B(-7,30,8,minecraft:netherrack)
B(-7,31,8,minecraft:netherrack)
B(-7,32,8,minecraft:netherrack)
B(-7,33,8,minecraft:netherrack)
B(-7,34,8,minecraft:netherrack)
B(-7,35,8,minecraft:netherrack)
B(-7,36,8,minecraft:netherrack)
B(-7,37,8,minecraft:netherrack)
B(-7,38,8,minecraft:netherrack)
B(-7,39,8,minecraft:netherrack)
B(-7,40,8,minecraft:netherrack)
B(-7,41,8,minecraft:netherrack)
B(-7,42,8,minecraft:netherrack)
B(-7,43,8,minecraft:netherrack)
B(-7,44,8,minecraft:netherrack)
B(-7,45,8,minecraft:netherrack)
B(-7,46,8,minecraft:netherrack)
B(-7,47,8,minecraft:netherrack)
B(-7,48,8,minecraft:netherrack)
B(-7,49,8,minecraft:netherrack)
B(-7,50,8,minecraft:netherrack)
B(-7,51,8,minecraft:netherrack)
B(-7,52,8,minecraft:netherrack)
B(-7,53,8,minecraft:netherrack)
B(-7,54,8,minecraft:netherrack)
B(-7,55,8,minecraft:netherrack)
B(-7,56,8,minecraft:netherrack)
B(-7,57,8,minecraft:netherrack)
B(-7,58,8,minecraft:netherrack)
B(-7,59,8,minecraft:netherrack)
B(-7,60,8,minecraft:netherrack)
B(-7,61,8,minecraft:netherrack)
B(-7,62,8,minecraft:netherrack)
B(-7,63,8,minecraft:netherrack)
B(-7,64,8,minecraft:netherrack)
B(-7,65,8,minecraft:netherrack)
B(-7,66,8,minecraft:netherrack)
B(-6,60,-7,minecraft:netherrack)
B(-6,61,-7,minecraft:netherrack)
B(-6,62,-7,minecraft:netherrack)
B(-6,63,-7,minecraft:netherrack)
B(-6,64,-7,minecraft:netherrack)
B(-6,65,-7,minecraft:netherrack)
B(-6,66,-7,minecraft:netherrack)
B(-6,59,-6,minecraft:netherrack)
B(-6,60,-6,minecraft:netherrack)
B(-6,61,-6,minecraft:netherrack)
B(-6,62,-6,minecraft:netherrack)
B(-6,63,-6,minecraft:netherrack)
B(-6,64,-6,minecraft:netherrack)
B(-6,65,-6,minecraft:netherrack)
B(-6,66,-6,minecraft:netherrack)
B(-6,58,-5,minecraft:netherrack)
B(-6,59,-5,minecraft:netherrack)
B(-6,60,-5,minecraft:netherrack)
B(-6,61,-5,minecraft:netherrack)
B(-6,62,-5,minecraft:netherrack)
B(-6,63,-5,minecraft:netherrack)
B(-6,64,-5,minecraft:netherrack)
B(-6,65,-5,minecraft:netherrack)
B(-6,66,-5,minecraft:netherrack)
B(-6,57,-4,minecraft:netherrack)
B(-6,58,-4,minecraft:netherrack)
B(-6,59,-4,minecraft:netherrack)
B(-6,60,-4,minecraft:netherrack)
B(-6,61,-4,minecraft:netherrack)
B(-6,62,-4,minecraft:netherrack)
B(-6,63,-4,minecraft:netherrack)
B(-6,64,-4,minecraft:netherrack)
B(-6,65,-4,minecraft:netherrack)
B(-6,66,-4,minecraft:netherrack)
B(-6,56,-3,minecraft:netherrack)
B(-6,57,-3,minecraft:netherrack)
B(-6,58,-3,minecraft:netherrack)
B(-6,59,-3,minecraft:netherrack)
B(-6,60,-3,minecraft:netherrack)
B(-6,61,-3,minecraft:netherrack)
B(-6,62,-3,minecraft:netherrack)
B(-6,63,-3,minecraft:netherrack)
B(-6,64,-3,minecraft:netherrack)
B(-6,65,-3,minecraft:netherrack)
B(-6,66,-3,minecraft:netherrack)
B(-6,55,-2,minecraft:netherrack)
B(-6,56,-2,minecraft:netherrack)
B(-6,57,-2,minecraft:netherrack)
B(-6,58,-2,minecraft:netherrack)
B(-6,59,-2,minecraft:netherrack)
B(-6,60,-2,minecraft:netherrack)
B(-6,61,-2,minecraft:netherrack)
B(-6,62,-2,minecraft:netherrack)
B(-6,63,-2,minecraft:netherrack)
B(-6,64,-2,minecraft:netherrack)
B(-6,65,-2,minecraft:netherrack)
B(-6,66,-2,minecraft:netherrack)
B(-6,54,-1,minecraft:netherrack)
B(-6,55,-1,minecraft:netherrack)
B(-6,56,-1,minecraft:netherrack)
B(-6,57,-1,minecraft:netherrack)
B(-6,58,-1,minecraft:netherrack)
B(-6,59,-1,minecraft:netherrack)
B(-6,60,-1,minecraft:netherrack)
B(-6,61,-1,minecraft:netherrack)
B(-6,62,-1,minecraft:netherrack)
B(-6,63,-1,minecraft:netherrack)
B(-6,64,-1,minecraft:netherrack)
B(-6,65,-1,minecraft:netherrack)
B(-6,66,-1,minecraft:netherrack)
B(-6,51,0,minecraft:netherrack)
B(-6,52,0,minecraft:netherrack)
B(-6,53,0,minecraft:netherrack)
B(-6,54,0,minecraft:netherrack)
B(-6,55,0,minecraft:netherrack)
B(-6,56,0,minecraft:netherrack)
B(-6,57,0,minecraft:netherrack)
B(-6,58,0,minecraft:netherrack)
B(-6,59,0,minecraft:netherrack)
B(-6,60,0,minecraft:netherrack)
B(-6,61,0,minecraft:netherrack)
B(-6,62,0,minecraft:netherrack)
B(-6,63,0,minecraft:netherrack)
B(-6,64,0,minecraft:netherrack)
B(-6,65,0,minecraft:netherrack)
B(-6,66,0,minecraft:netherrack)
B(-6,37,1,minecraft:netherrack)
B(-6,38,1,minecraft:netherrack)
B(-6,39,1,minecraft:netherrack)
B(-6,40,1,minecraft:netherrack)
B(-6,41,1,minecraft:netherrack)
B(-6,42,1,minecraft:netherrack)
B(-6,43,1,minecraft:netherrack)
B(-6,44,1,minecraft:netherrack)
B(-6,45,1,minecraft:netherrack)
B(-6,46,1,minecraft:netherrack)
B(-6,47,1,minecraft:netherrack)
B(-6,48,1,minecraft:netherrack)
B(-6,49,1,minecraft:netherrack)
B(-6,50,1,minecraft:netherrack)
B(-6,51,1,minecraft:netherrack)
B(-6,52,1,minecraft:netherrack)
B(-6,53,1,minecraft:netherrack)
B(-6,54,1,minecraft:netherrack)
B(-6,55,1,minecraft:netherrack)
B(-6,56,1,minecraft:netherrack)
B(-6,57,1,minecraft:netherrack)
B(-6,58,1,minecraft:netherrack)
B(-6,59,1,minecraft:netherrack)
B(-6,60,1,minecraft:netherrack)
B(-6,61,1,minecraft:netherrack)
B(-6,62,1,minecraft:netherrack)
B(-6,63,1,minecraft:netherrack)
B(-6,64,1,minecraft:netherrack)
B(-6,65,1,minecraft:netherrack)
B(-6,66,1,minecraft:netherrack)
B(-6,33,2,minecraft:netherrack)
B(-6,34,2,minecraft:netherrack)
B(-6,35,2,minecraft:netherrack)
B(-6,36,2,minecraft:netherrack)
B(-6,37,2,minecraft:netherrack)
B(-6,38,2,minecraft:netherrack)
B(-6,39,2,minecraft:netherrack)
B(-6,40,2,minecraft:netherrack)
B(-6,41,2,minecraft:netherrack)
B(-6,42,2,minecraft:netherrack)
B(-6,43,2,minecraft:netherrack)
B(-6,44,2,minecraft:netherrack)
B(-6,45,2,minecraft:netherrack)
B(-6,46,2,minecraft:netherrack)
B(-6,47,2,minecraft:netherrack)
B(-6,48,2,minecraft:netherrack)
B(-6,49,2,minecraft:netherrack)
B(-6,50,2,minecraft:netherrack)
B(-6,51,2,minecraft:netherrack)
B(-6,52,2,minecraft:netherrack)
B(-6,53,2,minecraft:netherrack)
B(-6,54,2,minecraft:netherrack)
B(-6,55,2,minecraft:netherrack)
B(-6,56,2,minecraft:netherrack)
B(-6,57,2,minecraft:netherrack)
B(-6,58,2,minecraft:netherrack)
B(-6,59,2,minecraft:netherrack)
B(-6,60,2,minecraft:netherrack)
B(-6,61,2,minecraft:netherrack)
B(-6,62,2,minecraft:netherrack)
B(-6,63,2,minecraft:netherrack)
B(-6,64,2,minecraft:netherrack)
B(-6,65,2,minecraft:netherrack)
B(-6,66,2,minecraft:netherrack)
B(-6,29,3,minecraft:netherrack)
B(-6,30,3,minecraft:netherrack)
B(-6,31,3,minecraft:netherrack)
B(-6,32,3,minecraft:netherrack)
B(-6,33,3,minecraft:netherrack)
B(-6,34,3,minecraft:netherrack)
B(-6,35,3,minecraft:netherrack)
B(-6,36,3,minecraft:netherrack)
B(-6,37,3,minecraft:netherrack)
B(-6,38,3,minecraft:netherrack)
B(-6,39,3,minecraft:netherrack)
B(-6,40,3,minecraft:netherrack)
B(-6,41,3,minecraft:netherrack)
B(-6,42,3,minecraft:netherrack)
B(-6,43,3,minecraft:netherrack)
B(-6,44,3,minecraft:netherrack)
B(-6,45,3,minecraft:netherrack)
B(-6,46,3,minecraft:netherrack)
B(-6,47,3,minecraft:netherrack)
B(-6,48,3,minecraft:netherrack)
B(-6,49,3,minecraft:netherrack)
B(-6,50,3,minecraft:netherrack)
B(-6,51,3,minecraft:netherrack)
B(-6,52,3,minecraft:netherrack)
B(-6,53,3,minecraft:netherrack)
B(-6,54,3,minecraft:netherrack)
B(-6,55,3,minecraft:netherrack)
B(-6,56,3,minecraft:netherrack)
B(-6,57,3,minecraft:netherrack)
B(-6,58,3,minecraft:netherrack)
B(-6,59,3,minecraft:netherrack)
B(-6,60,3,minecraft:netherrack)
B(-6,61,3,minecraft:netherrack)
B(-6,62,3,minecraft:netherrack)
B(-6,63,3,minecraft:netherrack)
B(-6,64,3,minecraft:netherrack)
B(-6,65,3,minecraft:netherrack)
B(-6,66,3,minecraft:netherrack)
B(-6,23,4,minecraft:netherrack)
B(-6,24,4,minecraft:netherrack)
B(-6,25,4,minecraft:netherrack)
B(-6,26,4,minecraft:netherrack)
B(-6,27,4,minecraft:netherrack)
B(-6,28,4,minecraft:netherrack)
B(-6,29,4,minecraft:netherrack)
B(-6,30,4,minecraft:netherrack)
B(-6,31,4,minecraft:netherrack)
B(-6,32,4,minecraft:netherrack)
B(-6,33,4,minecraft:netherrack)
B(-6,34,4,minecraft:netherrack)
B(-6,35,4,minecraft:netherrack)
B(-6,36,4,minecraft:netherrack)
B(-6,37,4,minecraft:netherrack)
B(-6,38,4,minecraft:netherrack)
B(-6,39,4,minecraft:netherrack)
B(-6,40,4,minecraft:netherrack)
B(-6,41,4,minecraft:netherrack)
B(-6,42,4,minecraft:netherrack)
B(-6,43,4,minecraft:netherrack)
B(-6,44,4,minecraft:netherrack)
B(-6,45,4,minecraft:netherrack)
B(-6,46,4,minecraft:netherrack)
B(-6,47,4,minecraft:netherrack)
B(-6,48,4,minecraft:netherrack)
B(-6,49,4,minecraft:netherrack)
B(-6,50,4,minecraft:netherrack)
B(-6,51,4,minecraft:netherrack)
B(-6,52,4,minecraft:netherrack)
B(-6,53,4,minecraft:netherrack)
B(-6,54,4,minecraft:netherrack)
B(-6,55,4,minecraft:netherrack)
B(-6,56,4,minecraft:netherrack)
B(-6,57,4,minecraft:netherrack)
B(-6,58,4,minecraft:netherrack)
B(-6,59,4,minecraft:netherrack)
B(-6,60,4,minecraft:netherrack)
B(-6,61,4,minecraft:netherrack)
B(-6,62,4,minecraft:netherrack)
B(-6,63,4,minecraft:netherrack)
B(-6,64,4,minecraft:netherrack)
B(-6,65,4,minecraft:netherrack)
B(-6,66,4,minecraft:netherrack)
B(-6,19,5,minecraft:netherrack)
B(-6,20,5,minecraft:netherrack)
B(-6,21,5,minecraft:netherrack)
B(-6,22,5,minecraft:netherrack)
B(-6,23,5,minecraft:netherrack)
B(-6,24,5,minecraft:netherrack)
B(-6,25,5,minecraft:netherrack)
B(-6,26,5,minecraft:netherrack)
B(-6,27,5,minecraft:netherrack)
B(-6,28,5,minecraft:netherrack)
B(-6,29,5,minecraft:netherrack)
B(-6,30,5,minecraft:netherrack)
B(-6,31,5,minecraft:netherrack)
B(-6,32,5,minecraft:netherrack)
B(-6,33,5,minecraft:netherrack)
B(-6,34,5,minecraft:netherrack)
B(-6,35,5,minecraft:netherrack)
B(-6,36,5,minecraft:netherrack)
B(-6,37,5,minecraft:netherrack)
B(-6,38,5,minecraft:netherrack)
B(-6,39,5,minecraft:netherrack)
B(-6,40,5,minecraft:netherrack)
B(-6,41,5,minecraft:netherrack)
B(-6,42,5,minecraft:netherrack)
B(-6,43,5,minecraft:netherrack)
B(-6,44,5,minecraft:netherrack)
B(-6,45,5,minecraft:netherrack)
B(-6,46,5,minecraft:netherrack)
B(-6,47,5,minecraft:netherrack)
B(-6,48,5,minecraft:netherrack)
B(-6,49,5,minecraft:netherrack)
B(-6,50,5,minecraft:netherrack)
B(-6,51,5,minecraft:netherrack)
B(-6,52,5,minecraft:netherrack)
B(-6,53,5,minecraft:netherrack)
B(-6,54,5,minecraft:netherrack)
B(-6,55,5,minecraft:netherrack)
B(-6,56,5,minecraft:netherrack)
B(-6,57,5,minecraft:netherrack)
B(-6,58,5,minecraft:netherrack)
B(-6,59,5,minecraft:netherrack)
B(-6,60,5,minecraft:netherrack)
B(-6,61,5,minecraft:netherrack)
B(-6,62,5,minecraft:netherrack)
B(-6,63,5,minecraft:netherrack)
B(-6,64,5,minecraft:netherrack)
B(-6,65,5,minecraft:netherrack)
B(-6,66,5,minecraft:netherrack)
B(-6,15,6,minecraft:netherrack)
B(-6,16,6,minecraft:netherrack)
B(-6,17,6,minecraft:netherrack)
B(-6,18,6,minecraft:netherrack)
B(-6,19,6,minecraft:netherrack)
B(-6,20,6,minecraft:netherrack)
B(-6,21,6,minecraft:netherrack)
B(-6,22,6,minecraft:netherrack)
B(-6,23,6,minecraft:netherrack)
B(-6,24,6,minecraft:netherrack)
B(-6,25,6,minecraft:netherrack)
B(-6,26,6,minecraft:netherrack)
B(-6,27,6,minecraft:netherrack)
B(-6,28,6,minecraft:netherrack)
B(-6,29,6,minecraft:netherrack)
B(-6,30,6,minecraft:netherrack)
B(-6,31,6,minecraft:netherrack)
B(-6,32,6,minecraft:netherrack)
B(-6,33,6,minecraft:netherrack)
B(-6,34,6,minecraft:netherrack)
B(-6,35,6,minecraft:netherrack)
B(-6,36,6,minecraft:netherrack)
B(-6,37,6,minecraft:netherrack)
B(-6,38,6,minecraft:netherrack)
B(-6,39,6,minecraft:netherrack)
B(-6,40,6,minecraft:netherrack)
B(-6,41,6,minecraft:netherrack)
B(-6,42,6,minecraft:netherrack)
B(-6,43,6,minecraft:netherrack)
B(-6,44,6,minecraft:netherrack)
B(-6,45,6,minecraft:netherrack)
B(-6,46,6,minecraft:netherrack)
B(-6,47,6,minecraft:netherrack)
B(-6,48,6,minecraft:netherrack)
B(-6,49,6,minecraft:netherrack)
B(-6,50,6,minecraft:netherrack)
B(-6,51,6,minecraft:netherrack)
B(-6,52,6,minecraft:netherrack)
B(-6,53,6,minecraft:netherrack)
B(-6,54,6,minecraft:netherrack)
B(-6,55,6,minecraft:netherrack)
B(-6,56,6,minecraft:netherrack)
B(-6,57,6,minecraft:netherrack)
B(-6,58,6,minecraft:netherrack)
B(-6,59,6,minecraft:netherrack)
B(-6,60,6,minecraft:netherrack)
B(-6,61,6,minecraft:netherrack)
B(-6,62,6,minecraft:netherrack)
B(-6,63,6,minecraft:netherrack)
B(-6,64,6,minecraft:netherrack)
B(-6,65,6,minecraft:netherrack)
B(-6,66,6,minecraft:netherrack)
B(-6,13,7,minecraft:netherrack)
B(-6,14,7,minecraft:netherrack)
B(-6,15,7,minecraft:netherrack)
B(-6,16,7,minecraft:netherrack)
B(-6,17,7,minecraft:netherrack)
B(-6,18,7,minecraft:netherrack)
B(-6,19,7,minecraft:netherrack)
B(-6,20,7,minecraft:netherrack)
B(-6,21,7,minecraft:netherrack)
B(-6,22,7,minecraft:netherrack)
B(-6,23,7,minecraft:netherrack)
B(-6,24,7,minecraft:netherrack)
B(-6,25,7,minecraft:netherrack)
B(-6,26,7,minecraft:netherrack)
B(-6,27,7,minecraft:netherrack)
B(-6,28,7,minecraft:netherrack)
B(-6,29,7,minecraft:netherrack)
B(-6,30,7,minecraft:netherrack)
B(-6,31,7,minecraft:netherrack)
B(-6,32,7,minecraft:netherrack)
B(-6,33,7,minecraft:netherrack)
B(-6,34,7,minecraft:netherrack)
B(-6,35,7,minecraft:netherrack)
B(-6,36,7,minecraft:netherrack)
B(-6,37,7,minecraft:netherrack)
B(-6,38,7,minecraft:netherrack)
B(-6,39,7,minecraft:netherrack)
B(-6,40,7,minecraft:netherrack)
B(-6,41,7,minecraft:netherrack)
B(-6,42,7,minecraft:netherrack)
B(-6,43,7,minecraft:netherrack)
B(-6,44,7,minecraft:netherrack)
B(-6,45,7,minecraft:netherrack)
B(-6,46,7,minecraft:netherrack)
B(-6,47,7,minecraft:netherrack)
B(-6,48,7,minecraft:netherrack)
B(-6,49,7,minecraft:netherrack)
B(-6,50,7,minecraft:netherrack)
B(-6,51,7,minecraft:netherrack)
B(-6,52,7,minecraft:netherrack)
B(-6,53,7,minecraft:netherrack)
B(-6,54,7,minecraft:netherrack)
B(-6,55,7,minecraft:netherrack)
B(-6,56,7,minecraft:netherrack)
B(-6,57,7,minecraft:netherrack)
B(-6,58,7,minecraft:netherrack)
B(-6,59,7,minecraft:netherrack)
B(-6,60,7,minecraft:netherrack)
B(-6,61,7,minecraft:netherrack)
B(-6,62,7,minecraft:netherrack)
B(-6,63,7,minecraft:netherrack)
B(-6,64,7,minecraft:netherrack)
B(-6,65,7,minecraft:netherrack)
B(-6,66,7,minecraft:netherrack)
B(-6,6,8,minecraft:netherrack)
B(-6,7,8,minecraft:netherrack)
B(-6,8,8,minecraft:netherrack)
B(-6,9,8,minecraft:netherrack)
B(-6,10,8,minecraft:netherrack)
B(-6,11,8,minecraft:netherrack)
B(-6,12,8,minecraft:netherrack)
B(-6,13,8,minecraft:netherrack)
B(-6,14,8,minecraft:netherrack)
B(-6,15,8,minecraft:netherrack)
B(-6,16,8,minecraft:netherrack)
B(-6,17,8,minecraft:netherrack)
B(-6,18,8,minecraft:netherrack)
B(-6,19,8,minecraft:netherrack)
B(-6,20,8,minecraft:netherrack)
B(-6,21,8,minecraft:netherrack)
B(-6,22,8,minecraft:netherrack)
B(-6,23,8,minecraft:netherrack)
B(-6,24,8,minecraft:netherrack)
B(-6,25,8,minecraft:netherrack)
B(-6,26,8,minecraft:netherrack)
B(-6,27,8,minecraft:netherrack)
B(-6,28,8,minecraft:netherrack)
B(-6,29,8,minecraft:netherrack)
B(-6,30,8,minecraft:netherrack)
B(-6,31,8,minecraft:netherrack)
B(-6,32,8,minecraft:netherrack)
B(-6,33,8,minecraft:netherrack)
B(-6,34,8,minecraft:netherrack)
B(-6,35,8,minecraft:netherrack)
B(-6,36,8,minecraft:netherrack)
B(-6,37,8,minecraft:netherrack)
B(-6,38,8,minecraft:netherrack)
B(-6,39,8,minecraft:netherrack)
B(-6,40,8,minecraft:netherrack)
B(-6,41,8,minecraft:netherrack)
B(-6,42,8,minecraft:netherrack)
B(-6,43,8,minecraft:netherrack)
B(-6,44,8,minecraft:netherrack)
B(-6,45,8,minecraft:netherrack)
B(-6,46,8,minecraft:netherrack)
B(-6,47,8,minecraft:netherrack)
B(-6,48,8,minecraft:netherrack)
B(-6,49,8,minecraft:netherrack)
B(-6,50,8,minecraft:netherrack)
B(-6,51,8,minecraft:netherrack)
B(-6,52,8,minecraft:netherrack)
B(-6,53,8,minecraft:netherrack)
B(-6,54,8,minecraft:netherrack)
B(-6,55,8,minecraft:netherrack)
B(-6,56,8,minecraft:netherrack)
B(-6,57,8,minecraft:netherrack)
B(-6,58,8,minecraft:netherrack)
B(-6,59,8,minecraft:netherrack)
B(-6,60,8,minecraft:netherrack)
B(-6,61,8,minecraft:netherrack)
B(-6,62,8,minecraft:netherrack)
B(-6,63,8,minecraft:netherrack)
B(-6,64,8,minecraft:netherrack)
B(-6,65,8,minecraft:netherrack)
B(-6,66,8,minecraft:netherrack)
B(-5,60,-7,minecraft:netherrack)
B(-5,61,-7,minecraft:netherrack)
B(-5,62,-7,minecraft:netherrack)
B(-5,63,-7,minecraft:netherrack)
B(-5,64,-7,minecraft:netherrack)
B(-5,65,-7,minecraft:netherrack)
B(-5,66,-7,minecraft:netherrack)
B(-5,59,-6,minecraft:netherrack)
B(-5,60,-6,minecraft:netherrack)
B(-5,61,-6,minecraft:netherrack)
B(-5,62,-6,minecraft:netherrack)
B(-5,63,-6,minecraft:netherrack)
B(-5,64,-6,minecraft:netherrack)
B(-5,65,-6,minecraft:netherrack)
B(-5,66,-6,minecraft:netherrack)
B(-5,58,-5,minecraft:netherrack)
B(-5,59,-5,minecraft:netherrack)
B(-5,60,-5,minecraft:netherrack)
B(-5,61,-5,minecraft:netherrack)
B(-5,62,-5,minecraft:netherrack)
B(-5,63,-5,minecraft:netherrack)
B(-5,64,-5,minecraft:netherrack)
B(-5,65,-5,minecraft:netherrack)
B(-5,66,-5,minecraft:netherrack)
B(-5,57,-4,minecraft:netherrack)
B(-5,58,-4,minecraft:netherrack)
B(-5,59,-4,minecraft:netherrack)
B(-5,60,-4,minecraft:netherrack)
B(-5,61,-4,minecraft:netherrack)
B(-5,62,-4,minecraft:netherrack)
B(-5,63,-4,minecraft:netherrack)
B(-5,64,-4,minecraft:netherrack)
B(-5,65,-4,minecraft:netherrack)
B(-5,66,-4,minecraft:netherrack)
B(-5,56,-3,minecraft:netherrack)
B(-5,57,-3,minecraft:netherrack)
B(-5,58,-3,minecraft:netherrack)
B(-5,59,-3,minecraft:netherrack)
B(-5,60,-3,minecraft:netherrack)
B(-5,61,-3,minecraft:netherrack)
B(-5,62,-3,minecraft:netherrack)
B(-5,63,-3,minecraft:netherrack)
B(-5,64,-3,minecraft:netherrack)
B(-5,65,-3,minecraft:netherrack)
B(-5,66,-3,minecraft:netherrack)
B(-5,55,-2,minecraft:netherrack)
B(-5,56,-2,minecraft:netherrack)
B(-5,57,-2,minecraft:netherrack)
B(-5,58,-2,minecraft:netherrack)
B(-5,59,-2,minecraft:netherrack)
B(-5,60,-2,minecraft:netherrack)
B(-5,61,-2,minecraft:netherrack)
B(-5,62,-2,minecraft:netherrack)
B(-5,63,-2,minecraft:netherrack)
B(-5,64,-2,minecraft:netherrack)
B(-5,65,-2,minecraft:netherrack)
B(-5,66,-2,minecraft:netherrack)
B(-5,53,-1,minecraft:netherrack)
B(-5,54,-1,minecraft:netherrack)
B(-5,55,-1,minecraft:netherrack)
B(-5,56,-1,minecraft:netherrack)
B(-5,57,-1,minecraft:netherrack)
B(-5,58,-1,minecraft:netherrack)
B(-5,59,-1,minecraft:netherrack)
B(-5,60,-1,minecraft:netherrack)
B(-5,61,-1,minecraft:netherrack)
B(-5,62,-1,minecraft:netherrack)
B(-5,63,-1,minecraft:netherrack)
B(-5,64,-1,minecraft:netherrack)
B(-5,65,-1,minecraft:netherrack)
B(-5,66,-1,minecraft:netherrack)
B(-5,51,0,minecraft:netherrack)
B(-5,52,0,minecraft:netherrack)
B(-5,53,0,minecraft:netherrack)
B(-5,54,0,minecraft:netherrack)
B(-5,55,0,minecraft:netherrack)
B(-5,56,0,minecraft:netherrack)
B(-5,57,0,minecraft:netherrack)
B(-5,58,0,minecraft:netherrack)
B(-5,59,0,minecraft:netherrack)
B(-5,60,0,minecraft:netherrack)
B(-5,61,0,minecraft:netherrack)
B(-5,62,0,minecraft:netherrack)
B(-5,63,0,minecraft:netherrack)
B(-5,64,0,minecraft:netherrack)
B(-5,65,0,minecraft:netherrack)
B(-5,66,0,minecraft:netherrack)
B(-5,38,1,minecraft:netherrack)
B(-5,39,1,minecraft:netherrack)
B(-5,40,1,minecraft:netherrack)
B(-5,41,1,minecraft:netherrack)
B(-5,42,1,minecraft:netherrack)
B(-5,43,1,minecraft:netherrack)
B(-5,44,1,minecraft:netherrack)
B(-5,45,1,minecraft:netherrack)
B(-5,46,1,minecraft:netherrack)
B(-5,47,1,minecraft:netherrack)
B(-5,48,1,minecraft:netherrack)
B(-5,49,1,minecraft:netherrack)
B(-5,50,1,minecraft:netherrack)
B(-5,51,1,minecraft:netherrack)
B(-5,52,1,minecraft:netherrack)
B(-5,53,1,minecraft:netherrack)
B(-5,54,1,minecraft:netherrack)
B(-5,55,1,minecraft:netherrack)
B(-5,56,1,minecraft:netherrack)
B(-5,57,1,minecraft:netherrack)
B(-5,58,1,minecraft:netherrack)
B(-5,59,1,minecraft:netherrack)
B(-5,60,1,minecraft:netherrack)
B(-5,61,1,minecraft:netherrack)
B(-5,62,1,minecraft:netherrack)
B(-5,63,1,minecraft:netherrack)
B(-5,64,1,minecraft:netherrack)
B(-5,65,1,minecraft:netherrack)
B(-5,66,1,minecraft:netherrack)
B(-5,34,2,minecraft:netherrack)
B(-5,35,2,minecraft:netherrack)
B(-5,36,2,minecraft:netherrack)
B(-5,37,2,minecraft:netherrack)
B(-5,38,2,minecraft:netherrack)
B(-5,39,2,minecraft:netherrack)
B(-5,40,2,minecraft:netherrack)
B(-5,41,2,minecraft:netherrack)
B(-5,42,2,minecraft:netherrack)
B(-5,43,2,minecraft:netherrack)
B(-5,44,2,minecraft:netherrack)
B(-5,45,2,minecraft:netherrack)
B(-5,46,2,minecraft:netherrack)
B(-5,47,2,minecraft:netherrack)
B(-5,48,2,minecraft:netherrack)
B(-5,49,2,minecraft:netherrack)
B(-5,50,2,minecraft:netherrack)
B(-5,51,2,minecraft:netherrack)
B(-5,52,2,minecraft:netherrack)
B(-5,53,2,minecraft:netherrack)
B(-5,54,2,minecraft:netherrack)
B(-5,55,2,minecraft:netherrack)
B(-5,56,2,minecraft:netherrack)
B(-5,57,2,minecraft:netherrack)
B(-5,58,2,minecraft:netherrack)
B(-5,59,2,minecraft:netherrack)
B(-5,60,2,minecraft:netherrack)
B(-5,61,2,minecraft:netherrack)
B(-5,62,2,minecraft:netherrack)
B(-5,63,2,minecraft:netherrack)
B(-5,64,2,minecraft:netherrack)
B(-5,65,2,minecraft:netherrack)
B(-5,66,2,minecraft:netherrack)
B(-5,30,3,minecraft:netherrack)
B(-5,31,3,minecraft:netherrack)
B(-5,32,3,minecraft:netherrack)
B(-5,33,3,minecraft:netherrack)
B(-5,34,3,minecraft:netherrack)
B(-5,35,3,minecraft:netherrack)
B(-5,36,3,minecraft:netherrack)
B(-5,37,3,minecraft:netherrack)
B(-5,38,3,minecraft:netherrack)
B(-5,39,3,minecraft:netherrack)
B(-5,40,3,minecraft:netherrack)
B(-5,41,3,minecraft:netherrack)
B(-5,42,3,minecraft:netherrack)
B(-5,43,3,minecraft:netherrack)
B(-5,44,3,minecraft:netherrack)
B(-5,45,3,minecraft:netherrack)
B(-5,46,3,minecraft:netherrack)
B(-5,47,3,minecraft:netherrack)
B(-5,48,3,minecraft:netherrack)
B(-5,49,3,minecraft:netherrack)
B(-5,50,3,minecraft:netherrack)
B(-5,51,3,minecraft:netherrack)
B(-5,52,3,minecraft:netherrack)
B(-5,53,3,minecraft:netherrack)
B(-5,54,3,minecraft:netherrack)
B(-5,55,3,minecraft:netherrack)
B(-5,56,3,minecraft:netherrack)
B(-5,57,3,minecraft:netherrack)
B(-5,58,3,minecraft:netherrack)
B(-5,59,3,minecraft:netherrack)
B(-5,60,3,minecraft:netherrack)
B(-5,61,3,minecraft:netherrack)
B(-5,62,3,minecraft:netherrack)
B(-5,63,3,minecraft:netherrack)
B(-5,64,3,minecraft:netherrack)
B(-5,65,3,minecraft:netherrack)
B(-5,66,3,minecraft:netherrack)
B(-5,24,4,minecraft:netherrack)
B(-5,25,4,minecraft:netherrack)
B(-5,26,4,minecraft:netherrack)
B(-5,27,4,minecraft:netherrack)
B(-5,28,4,minecraft:netherrack)
B(-5,29,4,minecraft:netherrack)
B(-5,30,4,minecraft:netherrack)
B(-5,31,4,minecraft:netherrack)
B(-5,32,4,minecraft:netherrack)
B(-5,33,4,minecraft:netherrack)
B(-5,34,4,minecraft:netherrack)
B(-5,35,4,minecraft:netherrack)
B(-5,36,4,minecraft:netherrack)
B(-5,37,4,minecraft:netherrack)
B(-5,38,4,minecraft:netherrack)
B(-5,39,4,minecraft:netherrack)
B(-5,40,4,minecraft:netherrack)
B(-5,41,4,minecraft:netherrack)
B(-5,42,4,minecraft:netherrack)
B(-5,43,4,minecraft:netherrack)
B(-5,44,4,minecraft:netherrack)
B(-5,45,4,minecraft:netherrack)
B(-5,46,4,minecraft:netherrack)
B(-5,47,4,minecraft:netherrack)
B(-5,48,4,minecraft:netherrack)
B(-5,49,4,minecraft:netherrack)
B(-5,50,4,minecraft:netherrack)
B(-5,51,4,minecraft:netherrack)
B(-5,52,4,minecraft:netherrack)
B(-5,53,4,minecraft:netherrack)
B(-5,54,4,minecraft:netherrack)
B(-5,55,4,minecraft:netherrack)
B(-5,56,4,minecraft:netherrack)
B(-5,57,4,minecraft:netherrack)
B(-5,58,4,minecraft:netherrack)
B(-5,59,4,minecraft:netherrack)
B(-5,60,4,minecraft:netherrack)
B(-5,61,4,minecraft:netherrack)
B(-5,62,4,minecraft:netherrack)
B(-5,63,4,minecraft:netherrack)
B(-5,64,4,minecraft:netherrack)
B(-5,65,4,minecraft:netherrack)
B(-5,66,4,minecraft:netherrack)
B(-5,20,5,minecraft:netherrack)
B(-5,21,5,minecraft:netherrack)
B(-5,22,5,minecraft:netherrack)
B(-5,23,5,minecraft:netherrack)
B(-5,24,5,minecraft:netherrack)
B(-5,25,5,minecraft:netherrack)
B(-5,26,5,minecraft:netherrack)
B(-5,27,5,minecraft:netherrack)
B(-5,28,5,minecraft:netherrack)
B(-5,29,5,minecraft:netherrack)
B(-5,30,5,minecraft:netherrack)
B(-5,31,5,minecraft:netherrack)
B(-5,32,5,minecraft:netherrack)
B(-5,33,5,minecraft:netherrack)
B(-5,34,5,minecraft:netherrack)
B(-5,35,5,minecraft:netherrack)
B(-5,36,5,minecraft:netherrack)
B(-5,37,5,minecraft:netherrack)
B(-5,38,5,minecraft:netherrack)
B(-5,39,5,minecraft:netherrack)
B(-5,40,5,minecraft:netherrack)
B(-5,41,5,minecraft:netherrack)
B(-5,42,5,minecraft:netherrack)
B(-5,43,5,minecraft:netherrack)
B(-5,44,5,minecraft:netherrack)
B(-5,45,5,minecraft:netherrack)
B(-5,46,5,minecraft:netherrack)
B(-5,47,5,minecraft:netherrack)
B(-5,48,5,minecraft:netherrack)
B(-5,49,5,minecraft:netherrack)
B(-5,50,5,minecraft:netherrack)
B(-5,51,5,minecraft:netherrack)
B(-5,52,5,minecraft:netherrack)
B(-5,53,5,minecraft:netherrack)
B(-5,54,5,minecraft:netherrack)
B(-5,55,5,minecraft:netherrack)
B(-5,56,5,minecraft:netherrack)
B(-5,57,5,minecraft:netherrack)
B(-5,58,5,minecraft:netherrack)
B(-5,59,5,minecraft:netherrack)
B(-5,60,5,minecraft:netherrack)
B(-5,61,5,minecraft:netherrack)
B(-5,62,5,minecraft:netherrack)
B(-5,63,5,minecraft:netherrack)
B(-5,64,5,minecraft:netherrack)
B(-5,65,5,minecraft:netherrack)
B(-5,66,5,minecraft:netherrack)
B(-5,16,6,minecraft:netherrack)
B(-5,17,6,minecraft:netherrack)
B(-5,18,6,minecraft:netherrack)
B(-5,19,6,minecraft:netherrack)
B(-5,20,6,minecraft:netherrack)
B(-5,21,6,minecraft:netherrack)
B(-5,22,6,minecraft:netherrack)
B(-5,23,6,minecraft:netherrack)
B(-5,24,6,minecraft:netherrack)
B(-5,25,6,minecraft:netherrack)
B(-5,26,6,minecraft:netherrack)
B(-5,27,6,minecraft:netherrack)
B(-5,28,6,minecraft:netherrack)
B(-5,29,6,minecraft:netherrack)
B(-5,30,6,minecraft:netherrack)
B(-5,31,6,minecraft:netherrack)
B(-5,32,6,minecraft:netherrack)
B(-5,33,6,minecraft:netherrack)
B(-5,34,6,minecraft:netherrack)
B(-5,35,6,minecraft:netherrack)
B(-5,36,6,minecraft:netherrack)
B(-5,37,6,minecraft:netherrack)
B(-5,38,6,minecraft:netherrack)
B(-5,39,6,minecraft:netherrack)
B(-5,40,6,minecraft:netherrack)
B(-5,41,6,minecraft:netherrack)
B(-5,42,6,minecraft:netherrack)
B(-5,43,6,minecraft:netherrack)
B(-5,44,6,minecraft:netherrack)
B(-5,45,6,minecraft:netherrack)
B(-5,46,6,minecraft:netherrack)
B(-5,47,6,minecraft:netherrack)
B(-5,48,6,minecraft:netherrack)
B(-5,49,6,minecraft:netherrack)
B(-5,50,6,minecraft:netherrack)
B(-5,51,6,minecraft:netherrack)
B(-5,52,6,minecraft:netherrack)
B(-5,53,6,minecraft:netherrack)
B(-5,54,6,minecraft:netherrack)
B(-5,55,6,minecraft:netherrack)
B(-5,56,6,minecraft:netherrack)
B(-5,57,6,minecraft:netherrack)
B(-5,58,6,minecraft:netherrack)
B(-5,59,6,minecraft:netherrack)
B(-5,60,6,minecraft:netherrack)
B(-5,61,6,minecraft:netherrack)
B(-5,62,6,minecraft:netherrack)
B(-5,63,6,minecraft:netherrack)
B(-5,64,6,minecraft:netherrack)
B(-5,65,6,minecraft:netherrack)
B(-5,66,6,minecraft:netherrack)
B(-5,12,7,minecraft:netherrack)
B(-5,13,7,minecraft:netherrack)
B(-5,14,7,minecraft:netherrack)
B(-5,15,7,minecraft:netherrack)
B(-5,16,7,minecraft:netherrack)
B(-5,17,7,minecraft:netherrack)
B(-5,18,7,minecraft:netherrack)
B(-5,19,7,minecraft:netherrack)
B(-5,20,7,minecraft:netherrack)
B(-5,21,7,minecraft:netherrack)
B(-5,22,7,minecraft:netherrack)
B(-5,23,7,minecraft:netherrack)
B(-5,24,7,minecraft:netherrack)
B(-5,25,7,minecraft:netherrack)
B(-5,26,7,minecraft:netherrack)
B(-5,27,7,minecraft:netherrack)
B(-5,28,7,minecraft:netherrack)
B(-5,29,7,minecraft:netherrack)
B(-5,30,7,minecraft:netherrack)
B(-5,31,7,minecraft:netherrack)
B(-5,32,7,minecraft:netherrack)
B(-5,33,7,minecraft:netherrack)
B(-5,34,7,minecraft:netherrack)
B(-5,35,7,minecraft:netherrack)
B(-5,36,7,minecraft:netherrack)
B(-5,37,7,minecraft:netherrack)
B(-5,38,7,minecraft:netherrack)
B(-5,39,7,minecraft:netherrack)
B(-5,40,7,minecraft:netherrack)
B(-5,41,7,minecraft:netherrack)
B(-5,42,7,minecraft:netherrack)
B(-5,43,7,minecraft:netherrack)
B(-5,44,7,minecraft:netherrack)
B(-5,45,7,minecraft:netherrack)
B(-5,46,7,minecraft:netherrack)
B(-5,47,7,minecraft:netherrack)
B(-5,48,7,minecraft:netherrack)
B(-5,49,7,minecraft:netherrack)
B(-5,50,7,minecraft:netherrack)
B(-5,51,7,minecraft:netherrack)
B(-5,52,7,minecraft:netherrack)
B(-5,53,7,minecraft:netherrack)
B(-5,54,7,minecraft:netherrack)
B(-5,55,7,minecraft:netherrack)
B(-5,56,7,minecraft:netherrack)
B(-5,57,7,minecraft:netherrack)
B(-5,58,7,minecraft:netherrack)
B(-5,59,7,minecraft:netherrack)
B(-5,60,7,minecraft:netherrack)
B(-5,61,7,minecraft:netherrack)
B(-5,62,7,minecraft:netherrack)
B(-5,63,7,minecraft:netherrack)
B(-5,64,7,minecraft:netherrack)
B(-5,65,7,minecraft:netherrack)
B(-5,66,7,minecraft:netherrack)
B(-5,5,8,minecraft:netherrack)
B(-5,6,8,minecraft:netherrack)
B(-5,7,8,minecraft:netherrack)
B(-5,8,8,minecraft:netherrack)
B(-5,9,8,minecraft:netherrack)
B(-5,10,8,minecraft:netherrack)
B(-5,11,8,minecraft:netherrack)
B(-5,12,8,minecraft:netherrack)
B(-5,13,8,minecraft:netherrack)
B(-5,14,8,minecraft:netherrack)
B(-5,15,8,minecraft:netherrack)
B(-5,16,8,minecraft:netherrack)
B(-5,17,8,minecraft:netherrack)
B(-5,18,8,minecraft:netherrack)
B(-5,19,8,minecraft:netherrack)
B(-5,20,8,minecraft:netherrack)
B(-5,21,8,minecraft:netherrack)
B(-5,22,8,minecraft:netherrack)
B(-5,23,8,minecraft:netherrack)
B(-5,24,8,minecraft:netherrack)
B(-5,25,8,minecraft:netherrack)
B(-5,26,8,minecraft:netherrack)
B(-5,27,8,minecraft:netherrack)
B(-5,28,8,minecraft:netherrack)
B(-5,29,8,minecraft:netherrack)
B(-5,30,8,minecraft:netherrack)
B(-5,31,8,minecraft:netherrack)
B(-5,32,8,minecraft:netherrack)
B(-5,33,8,minecraft:netherrack)
B(-5,34,8,minecraft:netherrack)
B(-5,35,8,minecraft:netherrack)
B(-5,36,8,minecraft:netherrack)
B(-5,37,8,minecraft:netherrack)
B(-5,38,8,minecraft:netherrack)
B(-5,39,8,minecraft:netherrack)
B(-5,40,8,minecraft:netherrack)
B(-5,41,8,minecraft:netherrack)
B(-5,42,8,minecraft:netherrack)
B(-5,43,8,minecraft:netherrack)
B(-5,44,8,minecraft:netherrack)
B(-5,45,8,minecraft:netherrack)
B(-5,46,8,minecraft:netherrack)
B(-5,47,8,minecraft:netherrack)
B(-5,48,8,minecraft:netherrack)
B(-5,49,8,minecraft:netherrack)
B(-5,50,8,minecraft:netherrack)
B(-5,51,8,minecraft:netherrack)
B(-5,52,8,minecraft:netherrack)
B(-5,53,8,minecraft:netherrack)
B(-5,54,8,minecraft:netherrack)
B(-5,55,8,minecraft:netherrack)
B(-5,56,8,minecraft:netherrack)
B(-5,57,8,minecraft:netherrack)
B(-5,58,8,minecraft:netherrack)
B(-5,59,8,minecraft:netherrack)
B(-5,60,8,minecraft:netherrack)
B(-5,61,8,minecraft:netherrack)
B(-5,62,8,minecraft:netherrack)
B(-5,63,8,minecraft:netherrack)
B(-5,64,8,minecraft:netherrack)
B(-5,65,8,minecraft:netherrack)
B(-5,66,8,minecraft:netherrack)
B(-4,62,-7,minecraft:netherrack)
B(-4,63,-7,minecraft:netherrack)
B(-4,64,-7,minecraft:netherrack)
B(-4,65,-7,minecraft:netherrack)
B(-4,66,-7,minecraft:netherrack)
B(-4,59,-6,minecraft:netherrack)
B(-4,60,-6,minecraft:netherrack)
B(-4,61,-6,minecraft:netherrack)
B(-4,62,-6,minecraft:netherrack)
B(-4,63,-6,minecraft:netherrack)
B(-4,64,-6,minecraft:netherrack)
B(-4,65,-6,minecraft:netherrack)
B(-4,66,-6,minecraft:netherrack)
B(-4,59,-5,minecraft:netherrack)
B(-4,60,-5,minecraft:netherrack)
B(-4,61,-5,minecraft:netherrack)
B(-4,62,-5,minecraft:netherrack)
B(-4,63,-5,minecraft:netherrack)
B(-4,64,-5,minecraft:netherrack)
B(-4,65,-5,minecraft:netherrack)
B(-4,66,-5,minecraft:netherrack)
B(-4,57,-4,minecraft:netherrack)
B(-4,58,-4,minecraft:netherrack)
B(-4,59,-4,minecraft:netherrack)
B(-4,60,-4,minecraft:netherrack)
B(-4,61,-4,minecraft:netherrack)
B(-4,62,-4,minecraft:netherrack)
B(-4,63,-4,minecraft:netherrack)
B(-4,64,-4,minecraft:netherrack)
B(-4,65,-4,minecraft:netherrack)
B(-4,66,-4,minecraft:netherrack)
B(-4,56,-3,minecraft:netherrack)
B(-4,57,-3,minecraft:netherrack)
B(-4,58,-3,minecraft:netherrack)
B(-4,59,-3,minecraft:netherrack)
B(-4,60,-3,minecraft:netherrack)
B(-4,61,-3,minecraft:netherrack)
B(-4,62,-3,minecraft:netherrack)
B(-4,63,-3,minecraft:netherrack)
B(-4,64,-3,minecraft:netherrack)
B(-4,65,-3,minecraft:netherrack)
B(-4,66,-3,minecraft:netherrack)
B(-4,56,-2,minecraft:netherrack)
B(-4,57,-2,minecraft:netherrack)
B(-4,58,-2,minecraft:netherrack)
B(-4,59,-2,minecraft:netherrack)
B(-4,60,-2,minecraft:netherrack)
B(-4,61,-2,minecraft:netherrack)
B(-4,62,-2,minecraft:netherrack)
B(-4,63,-2,minecraft:netherrack)
B(-4,64,-2,minecraft:netherrack)
B(-4,65,-2,minecraft:netherrack)
B(-4,66,-2,minecraft:netherrack)
B(-4,55,-1,minecraft:netherrack)
B(-4,56,-1,minecraft:netherrack)
B(-4,57,-1,minecraft:netherrack)
B(-4,58,-1,minecraft:netherrack)
B(-4,59,-1,minecraft:netherrack)
B(-4,60,-1,minecraft:netherrack)
B(-4,61,-1,minecraft:netherrack)
B(-4,62,-1,minecraft:netherrack)
B(-4,63,-1,minecraft:netherrack)
B(-4,64,-1,minecraft:netherrack)
B(-4,65,-1,minecraft:netherrack)
B(-4,66,-1,minecraft:netherrack)
B(-4,52,0,minecraft:netherrack)
B(-4,53,0,minecraft:netherrack)
B(-4,54,0,minecraft:netherrack)
B(-4,55,0,minecraft:netherrack)
B(-4,56,0,minecraft:netherrack)
B(-4,57,0,minecraft:netherrack)
B(-4,58,0,minecraft:netherrack)
B(-4,59,0,minecraft:netherrack)
B(-4,60,0,minecraft:netherrack)
B(-4,61,0,minecraft:netherrack)
B(-4,62,0,minecraft:netherrack)
B(-4,63,0,minecraft:netherrack)
B(-4,64,0,minecraft:netherrack)
B(-4,65,0,minecraft:netherrack)
B(-4,66,0,minecraft:netherrack)
B(-4,46,1,minecraft:netherrack)
B(-4,47,1,minecraft:netherrack)
B(-4,48,1,minecraft:netherrack)
B(-4,49,1,minecraft:netherrack)
B(-4,50,1,minecraft:netherrack)
B(-4,51,1,minecraft:netherrack)
B(-4,52,1,minecraft:netherrack)
B(-4,53,1,minecraft:netherrack)
B(-4,54,1,minecraft:netherrack)
B(-4,55,1,minecraft:netherrack)
B(-4,56,1,minecraft:netherrack)
B(-4,57,1,minecraft:netherrack)
B(-4,58,1,minecraft:netherrack)
B(-4,59,1,minecraft:netherrack)
B(-4,60,1,minecraft:netherrack)
B(-4,61,1,minecraft:netherrack)
B(-4,62,1,minecraft:netherrack)
B(-4,63,1,minecraft:netherrack)
B(-4,64,1,minecraft:netherrack)
B(-4,65,1,minecraft:netherrack)
B(-4,66,1,minecraft:netherrack)
B(-4,35,2,minecraft:netherrack)
B(-4,36,2,minecraft:netherrack)
B(-4,37,2,minecraft:netherrack)
B(-4,38,2,minecraft:netherrack)
B(-4,39,2,minecraft:netherrack)
B(-4,40,2,minecraft:netherrack)
B(-4,41,2,minecraft:netherrack)
B(-4,42,2,minecraft:netherrack)
B(-4,43,2,minecraft:netherrack)
B(-4,44,2,minecraft:netherrack)
B(-4,45,2,minecraft:netherrack)
B(-4,46,2,minecraft:netherrack)
B(-4,47,2,minecraft:netherrack)
B(-4,48,2,minecraft:netherrack)
B(-4,49,2,minecraft:netherrack)
B(-4,50,2,minecraft:netherrack)
B(-4,51,2,minecraft:netherrack)
B(-4,52,2,minecraft:netherrack)
B(-4,53,2,minecraft:netherrack)
B(-4,54,2,minecraft:netherrack)
B(-4,55,2,minecraft:netherrack)
B(-4,56,2,minecraft:netherrack)
B(-4,57,2,minecraft:netherrack)
B(-4,58,2,minecraft:netherrack)
B(-4,59,2,minecraft:netherrack)
B(-4,60,2,minecraft:netherrack)
B(-4,61,2,minecraft:netherrack)
B(-4,62,2,minecraft:netherrack)
B(-4,63,2,minecraft:netherrack)
B(-4,64,2,minecraft:netherrack)
B(-4,65,2,minecraft:netherrack)
B(-4,66,2,minecraft:netherrack)
B(-4,32,3,minecraft:netherrack)
B(-4,33,3,minecraft:netherrack)
B(-4,34,3,minecraft:netherrack)
B(-4,35,3,minecraft:netherrack)
B(-4,36,3,minecraft:netherrack)
B(-4,37,3,minecraft:netherrack)
B(-4,38,3,minecraft:netherrack)
B(-4,39,3,minecraft:netherrack)
B(-4,40,3,minecraft:netherrack)
B(-4,41,3,minecraft:netherrack)
B(-4,42,3,minecraft:netherrack)
B(-4,43,3,minecraft:netherrack)
B(-4,44,3,minecraft:netherrack)
B(-4,45,3,minecraft:netherrack)
B(-4,46,3,minecraft:netherrack)
B(-4,47,3,minecraft:netherrack)
B(-4,48,3,minecraft:netherrack)
B(-4,49,3,minecraft:netherrack)
B(-4,50,3,minecraft:netherrack)
B(-4,51,3,minecraft:netherrack)
B(-4,52,3,minecraft:netherrack)
B(-4,53,3,minecraft:netherrack)
B(-4,54,3,minecraft:netherrack)
B(-4,55,3,minecraft:netherrack)
B(-4,56,3,minecraft:netherrack)
B(-4,57,3,minecraft:netherrack)
B(-4,58,3,minecraft:netherrack)
B(-4,59,3,minecraft:netherrack)
B(-4,60,3,minecraft:netherrack)
B(-4,61,3,minecraft:netherrack)
B(-4,62,3,minecraft:netherrack)
B(-4,63,3,minecraft:netherrack)
B(-4,64,3,minecraft:netherrack)
B(-4,65,3,minecraft:netherrack)
B(-4,66,3,minecraft:netherrack)
B(-4,26,4,minecraft:netherrack)
B(-4,27,4,minecraft:netherrack)
B(-4,28,4,minecraft:netherrack)
B(-4,29,4,minecraft:netherrack)
B(-4,30,4,minecraft:netherrack)
B(-4,31,4,minecraft:netherrack)
B(-4,32,4,minecraft:netherrack)
B(-4,33,4,minecraft:netherrack)
B(-4,34,4,minecraft:netherrack)
B(-4,35,4,minecraft:netherrack)
B(-4,36,4,minecraft:netherrack)
B(-4,37,4,minecraft:netherrack)
B(-4,38,4,minecraft:netherrack)
B(-4,39,4,minecraft:netherrack)
B(-4,40,4,minecraft:netherrack)
B(-4,41,4,minecraft:netherrack)
B(-4,42,4,minecraft:netherrack)
B(-4,43,4,minecraft:netherrack)
B(-4,44,4,minecraft:netherrack)
B(-4,45,4,minecraft:netherrack)
B(-4,46,4,minecraft:netherrack)
B(-4,47,4,minecraft:netherrack)
B(-4,48,4,minecraft:netherrack)
B(-4,49,4,minecraft:netherrack)
B(-4,50,4,minecraft:netherrack)
B(-4,51,4,minecraft:netherrack)
B(-4,52,4,minecraft:netherrack)
B(-4,53,4,minecraft:netherrack)
B(-4,54,4,minecraft:netherrack)
B(-4,55,4,minecraft:netherrack)
B(-4,56,4,minecraft:netherrack)
B(-4,57,4,minecraft:netherrack)
B(-4,58,4,minecraft:netherrack)
B(-4,59,4,minecraft:netherrack)
B(-4,60,4,minecraft:netherrack)
B(-4,61,4,minecraft:netherrack)
B(-4,62,4,minecraft:netherrack)
B(-4,63,4,minecraft:netherrack)
B(-4,64,4,minecraft:netherrack)
B(-4,65,4,minecraft:netherrack)
B(-4,66,4,minecraft:netherrack)
B(-4,20,5,minecraft:netherrack)
B(-4,21,5,minecraft:netherrack)
B(-4,22,5,minecraft:netherrack)
B(-4,23,5,minecraft:netherrack)
B(-4,24,5,minecraft:netherrack)
B(-4,25,5,minecraft:netherrack)
B(-4,26,5,minecraft:netherrack)
B(-4,27,5,minecraft:netherrack)
B(-4,28,5,minecraft:netherrack)
B(-4,29,5,minecraft:netherrack)
B(-4,30,5,minecraft:netherrack)
B(-4,31,5,minecraft:netherrack)
B(-4,32,5,minecraft:netherrack)
B(-4,33,5,minecraft:netherrack)
B(-4,34,5,minecraft:netherrack)
B(-4,35,5,minecraft:netherrack)
B(-4,36,5,minecraft:netherrack)
B(-4,37,5,minecraft:netherrack)
B(-4,38,5,minecraft:netherrack)
B(-4,39,5,minecraft:netherrack)
B(-4,40,5,minecraft:netherrack)
B(-4,41,5,minecraft:netherrack)
B(-4,42,5,minecraft:netherrack)
B(-4,43,5,minecraft:netherrack)
B(-4,44,5,minecraft:netherrack)
B(-4,45,5,minecraft:netherrack)
B(-4,46,5,minecraft:netherrack)
B(-4,47,5,minecraft:netherrack)
B(-4,48,5,minecraft:netherrack)
B(-4,49,5,minecraft:netherrack)
B(-4,50,5,minecraft:netherrack)
B(-4,51,5,minecraft:netherrack)
B(-4,52,5,minecraft:netherrack)
B(-4,53,5,minecraft:netherrack)
B(-4,54,5,minecraft:netherrack)
B(-4,55,5,minecraft:netherrack)
B(-4,56,5,minecraft:netherrack)
B(-4,57,5,minecraft:netherrack)
B(-4,58,5,minecraft:netherrack)
B(-4,59,5,minecraft:netherrack)
B(-4,60,5,minecraft:netherrack)
B(-4,61,5,minecraft:netherrack)
B(-4,62,5,minecraft:netherrack)
B(-4,63,5,minecraft:netherrack)
B(-4,64,5,minecraft:netherrack)
B(-4,65,5,minecraft:netherrack)
B(-4,66,5,minecraft:netherrack)
B(-4,16,6,minecraft:netherrack)
B(-4,17,6,minecraft:netherrack)
B(-4,18,6,minecraft:netherrack)
B(-4,19,6,minecraft:netherrack)
B(-4,20,6,minecraft:netherrack)
B(-4,21,6,minecraft:netherrack)
B(-4,22,6,minecraft:netherrack)
B(-4,23,6,minecraft:netherrack)
B(-4,24,6,minecraft:netherrack)
B(-4,25,6,minecraft:netherrack)
B(-4,26,6,minecraft:netherrack)
B(-4,27,6,minecraft:netherrack)
B(-4,28,6,minecraft:netherrack)
B(-4,29,6,minecraft:netherrack)
B(-4,30,6,minecraft:netherrack)
B(-4,31,6,minecraft:netherrack)
B(-4,32,6,minecraft:netherrack)
B(-4,33,6,minecraft:netherrack)
B(-4,34,6,minecraft:netherrack)
B(-4,35,6,minecraft:netherrack)
B(-4,36,6,minecraft:netherrack)
B(-4,37,6,minecraft:netherrack)
B(-4,38,6,minecraft:netherrack)
B(-4,39,6,minecraft:netherrack)
B(-4,40,6,minecraft:netherrack)
B(-4,41,6,minecraft:netherrack)
B(-4,42,6,minecraft:netherrack)
B(-4,43,6,minecraft:netherrack)
B(-4,44,6,minecraft:netherrack)
B(-4,45,6,minecraft:netherrack)
B(-4,46,6,minecraft:netherrack)
B(-4,47,6,minecraft:netherrack)
B(-4,48,6,minecraft:netherrack)
B(-4,49,6,minecraft:netherrack)
B(-4,50,6,minecraft:netherrack)
B(-4,51,6,minecraft:netherrack)
B(-4,52,6,minecraft:netherrack)
B(-4,53,6,minecraft:netherrack)
B(-4,54,6,minecraft:netherrack)
B(-4,55,6,minecraft:netherrack)
B(-4,56,6,minecraft:netherrack)
B(-4,57,6,minecraft:netherrack)
B(-4,58,6,minecraft:netherrack)
B(-4,59,6,minecraft:netherrack)
B(-4,60,6,minecraft:netherrack)
B(-4,61,6,minecraft:netherrack)
B(-4,62,6,minecraft:netherrack)
B(-4,63,6,minecraft:netherrack)
B(-4,64,6,minecraft:netherrack)
B(-4,65,6,minecraft:netherrack)
B(-4,66,6,minecraft:netherrack)
B(-4,12,7,minecraft:netherrack)
B(-4,13,7,minecraft:netherrack)
B(-4,14,7,minecraft:netherrack)
B(-4,15,7,minecraft:netherrack)
B(-4,16,7,minecraft:netherrack)
B(-4,17,7,minecraft:netherrack)
B(-4,18,7,minecraft:netherrack)
B(-4,19,7,minecraft:netherrack)
B(-4,20,7,minecraft:netherrack)
B(-4,21,7,minecraft:netherrack)
B(-4,22,7,minecraft:netherrack)
B(-4,23,7,minecraft:netherrack)
B(-4,24,7,minecraft:netherrack)
B(-4,25,7,minecraft:netherrack)
B(-4,26,7,minecraft:netherrack)
B(-4,27,7,minecraft:netherrack)
B(-4,28,7,minecraft:netherrack)
B(-4,29,7,minecraft:netherrack)
B(-4,30,7,minecraft:netherrack)
B(-4,31,7,minecraft:netherrack)
B(-4,32,7,minecraft:netherrack)
B(-4,33,7,minecraft:netherrack)
B(-4,34,7,minecraft:netherrack)
B(-4,35,7,minecraft:netherrack)
B(-4,36,7,minecraft:netherrack)
B(-4,37,7,minecraft:netherrack)
B(-4,38,7,minecraft:netherrack)
B(-4,39,7,minecraft:netherrack)
B(-4,40,7,minecraft:netherrack)
B(-4,41,7,minecraft:netherrack)
B(-4,42,7,minecraft:netherrack)
B(-4,43,7,minecraft:netherrack)
B(-4,44,7,minecraft:netherrack)
B(-4,45,7,minecraft:netherrack)
B(-4,46,7,minecraft:netherrack)
B(-4,47,7,minecraft:netherrack)
B(-4,48,7,minecraft:netherrack)
B(-4,49,7,minecraft:netherrack)
B(-4,50,7,minecraft:netherrack)
B(-4,51,7,minecraft:netherrack)
B(-4,52,7,minecraft:netherrack)
B(-4,53,7,minecraft:netherrack)
B(-4,54,7,minecraft:netherrack)
B(-4,55,7,minecraft:netherrack)
B(-4,56,7,minecraft:netherrack)
B(-4,57,7,minecraft:netherrack)
B(-4,58,7,minecraft:netherrack)
B(-4,59,7,minecraft:netherrack)
B(-4,60,7,minecraft:netherrack)
B(-4,61,7,minecraft:netherrack)
B(-4,62,7,minecraft:netherrack)
B(-4,63,7,minecraft:netherrack)
B(-4,64,7,minecraft:netherrack)
B(-4,65,7,minecraft:netherrack)
B(-4,66,7,minecraft:netherrack)
B(-4,5,8,minecraft:netherrack)
B(-4,6,8,minecraft:netherrack)
B(-4,7,8,minecraft:netherrack)
B(-4,8,8,minecraft:netherrack)
B(-4,9,8,minecraft:netherrack)
B(-4,10,8,minecraft:netherrack)
B(-4,11,8,minecraft:netherrack)
B(-4,12,8,minecraft:netherrack)
B(-4,13,8,minecraft:netherrack)
B(-4,14,8,minecraft:netherrack)
B(-4,15,8,minecraft:netherrack)
B(-4,16,8,minecraft:netherrack)
B(-4,17,8,minecraft:netherrack)
B(-4,18,8,minecraft:netherrack)
B(-4,19,8,minecraft:netherrack)
B(-4,20,8,minecraft:netherrack)
B(-4,21,8,minecraft:netherrack)
B(-4,22,8,minecraft:netherrack)
B(-4,23,8,minecraft:netherrack)
B(-4,24,8,minecraft:netherrack)
B(-4,25,8,minecraft:netherrack)
B(-4,26,8,minecraft:netherrack)
B(-4,27,8,minecraft:netherrack)
B(-4,28,8,minecraft:netherrack)
B(-4,29,8,minecraft:netherrack)
B(-4,30,8,minecraft:netherrack)
B(-4,31,8,minecraft:netherrack)
B(-4,32,8,minecraft:netherrack)
B(-4,33,8,minecraft:netherrack)
B(-4,34,8,minecraft:netherrack)
B(-4,35,8,minecraft:netherrack)
B(-4,36,8,minecraft:netherrack)
B(-4,37,8,minecraft:netherrack)
B(-4,38,8,minecraft:netherrack)
B(-4,39,8,minecraft:netherrack)
B(-4,40,8,minecraft:netherrack)
B(-4,41,8,minecraft:netherrack)
B(-4,42,8,minecraft:netherrack)
B(-4,43,8,minecraft:netherrack)
B(-4,44,8,minecraft:netherrack)
B(-4,45,8,minecraft:netherrack)
B(-4,46,8,minecraft:netherrack)
B(-4,47,8,minecraft:netherrack)
B(-4,48,8,minecraft:netherrack)
B(-4,49,8,minecraft:netherrack)
B(-4,50,8,minecraft:netherrack)
B(-4,51,8,minecraft:netherrack)
B(-4,52,8,minecraft:netherrack)
B(-4,53,8,minecraft:netherrack)
B(-4,54,8,minecraft:netherrack)
B(-4,55,8,minecraft:netherrack)
B(-4,56,8,minecraft:netherrack)
B(-4,57,8,minecraft:netherrack)
B(-4,58,8,minecraft:netherrack)
B(-4,59,8,minecraft:netherrack)
B(-4,60,8,minecraft:netherrack)
B(-4,61,8,minecraft:netherrack)
B(-4,62,8,minecraft:netherrack)
B(-4,63,8,minecraft:netherrack)
B(-4,64,8,minecraft:netherrack)
B(-4,65,8,minecraft:netherrack)
B(-4,66,8,minecraft:netherrack)
B(-3,62,-7,minecraft:netherrack)
B(-3,63,-7,minecraft:netherrack)
B(-3,64,-7,minecraft:netherrack)
B(-3,65,-7,minecraft:netherrack)
B(-3,66,-7,minecraft:netherrack)
B(-3,60,-6,minecraft:netherrack)
B(-3,61,-6,minecraft:netherrack)
B(-3,62,-6,minecraft:netherrack)
B(-3,63,-6,minecraft:netherrack)
B(-3,64,-6,minecraft:netherrack)
B(-3,65,-6,minecraft:netherrack)
B(-3,66,-6,minecraft:netherrack)
B(-3,59,-5,minecraft:netherrack)
B(-3,60,-5,minecraft:netherrack)
B(-3,61,-5,minecraft:netherrack)
B(-3,62,-5,minecraft:netherrack)
B(-3,63,-5,minecraft:netherrack)
B(-3,64,-5,minecraft:netherrack)
B(-3,65,-5,minecraft:netherrack)
B(-3,66,-5,minecraft:netherrack)
B(-3,58,-4,minecraft:netherrack)
B(-3,59,-4,minecraft:netherrack)
B(-3,60,-4,minecraft:netherrack)
B(-3,61,-4,minecraft:netherrack)
B(-3,62,-4,minecraft:netherrack)
B(-3,63,-4,minecraft:netherrack)
B(-3,64,-4,minecraft:netherrack)
B(-3,65,-4,minecraft:netherrack)
B(-3,66,-4,minecraft:netherrack)
B(-3,57,-3,minecraft:netherrack)
B(-3,58,-3,minecraft:netherrack)
B(-3,59,-3,minecraft:netherrack)
B(-3,60,-3,minecraft:netherrack)
B(-3,61,-3,minecraft:netherrack)
B(-3,62,-3,minecraft:netherrack)
B(-3,63,-3,minecraft:netherrack)
B(-3,64,-3,minecraft:netherrack)
B(-3,65,-3,minecraft:netherrack)
B(-3,66,-3,minecraft:netherrack)
B(-3,56,-2,minecraft:netherrack)
B(-3,57,-2,minecraft:netherrack)
B(-3,58,-2,minecraft:netherrack)
B(-3,59,-2,minecraft:netherrack)
B(-3,60,-2,minecraft:netherrack)
B(-3,61,-2,minecraft:netherrack)
B(-3,62,-2,minecraft:netherrack)
B(-3,63,-2,minecraft:netherrack)
B(-3,64,-2,minecraft:netherrack)
B(-3,65,-2,minecraft:netherrack)
B(-3,66,-2,minecraft:netherrack)
B(-3,56,-1,minecraft:netherrack)
B(-3,57,-1,minecraft:netherrack)
B(-3,58,-1,minecraft:netherrack)
B(-3,59,-1,minecraft:netherrack)
B(-3,60,-1,minecraft:netherrack)
B(-3,61,-1,minecraft:netherrack)
B(-3,62,-1,minecraft:netherrack)
B(-3,63,-1,minecraft:netherrack)
B(-3,64,-1,minecraft:netherrack)
B(-3,65,-1,minecraft:netherrack)
B(-3,66,-1,minecraft:netherrack)
B(-3,56,0,minecraft:netherrack)
B(-3,57,0,minecraft:netherrack)
B(-3,58,0,minecraft:netherrack)
B(-3,59,0,minecraft:netherrack)
B(-3,60,0,minecraft:netherrack)
B(-3,61,0,minecraft:netherrack)
B(-3,62,0,minecraft:netherrack)
B(-3,63,0,minecraft:netherrack)
B(-3,64,0,minecraft:netherrack)
B(-3,65,0,minecraft:netherrack)
B(-3,66,0,minecraft:netherrack)
B(-3,47,1,minecraft:netherrack)
B(-3,48,1,minecraft:netherrack)
B(-3,49,1,minecraft:netherrack)
B(-3,50,1,minecraft:netherrack)
B(-3,51,1,minecraft:netherrack)
B(-3,52,1,minecraft:netherrack)
B(-3,53,1,minecraft:netherrack)
B(-3,54,1,minecraft:netherrack)
B(-3,55,1,minecraft:netherrack)
B(-3,56,1,minecraft:netherrack)
B(-3,57,1,minecraft:netherrack)
B(-3,58,1,minecraft:netherrack)
B(-3,59,1,minecraft:netherrack)
B(-3,60,1,minecraft:netherrack)
B(-3,61,1,minecraft:netherrack)
B(-3,62,1,minecraft:netherrack)
B(-3,63,1,minecraft:netherrack)
B(-3,64,1,minecraft:netherrack)
B(-3,65,1,minecraft:netherrack)
B(-3,66,1,minecraft:netherrack)
B(-3,36,2,minecraft:netherrack)
B(-3,37,2,minecraft:netherrack)
B(-3,38,2,minecraft:netherrack)
B(-3,39,2,minecraft:netherrack)
B(-3,40,2,minecraft:netherrack)
B(-3,41,2,minecraft:netherrack)
B(-3,42,2,minecraft:netherrack)
B(-3,43,2,minecraft:netherrack)
B(-3,44,2,minecraft:netherrack)
B(-3,45,2,minecraft:netherrack)
B(-3,46,2,minecraft:netherrack)
B(-3,47,2,minecraft:netherrack)
B(-3,48,2,minecraft:netherrack)
B(-3,49,2,minecraft:netherrack)
B(-3,50,2,minecraft:netherrack)
B(-3,51,2,minecraft:netherrack)
B(-3,52,2,minecraft:netherrack)
B(-3,53,2,minecraft:netherrack)
B(-3,54,2,minecraft:netherrack)
B(-3,55,2,minecraft:netherrack)
B(-3,56,2,minecraft:netherrack)
B(-3,57,2,minecraft:netherrack)
B(-3,58,2,minecraft:netherrack)
B(-3,59,2,minecraft:netherrack)
B(-3,60,2,minecraft:netherrack)
B(-3,61,2,minecraft:netherrack)
B(-3,62,2,minecraft:netherrack)
B(-3,63,2,minecraft:netherrack)
B(-3,64,2,minecraft:netherrack)
B(-3,65,2,minecraft:netherrack)
B(-3,66,2,minecraft:netherrack)
B(-3,33,3,minecraft:netherrack)
B(-3,34,3,minecraft:netherrack)
B(-3,35,3,minecraft:netherrack)
B(-3,36,3,minecraft:netherrack)
B(-3,37,3,minecraft:netherrack)
B(-3,38,3,minecraft:netherrack)
B(-3,39,3,minecraft:netherrack)
B(-3,40,3,minecraft:netherrack)
B(-3,41,3,minecraft:netherrack)
B(-3,42,3,minecraft:netherrack)
B(-3,43,3,minecraft:netherrack)
B(-3,44,3,minecraft:netherrack)
B(-3,45,3,minecraft:netherrack)
B(-3,46,3,minecraft:netherrack)
B(-3,47,3,minecraft:netherrack)
B(-3,48,3,minecraft:netherrack)
B(-3,49,3,minecraft:netherrack)
B(-3,50,3,minecraft:netherrack)
B(-3,51,3,minecraft:netherrack)
B(-3,52,3,minecraft:netherrack)
B(-3,53,3,minecraft:netherrack)
B(-3,54,3,minecraft:netherrack)
B(-3,55,3,minecraft:netherrack)
B(-3,56,3,minecraft:netherrack)
B(-3,57,3,minecraft:netherrack)
B(-3,58,3,minecraft:netherrack)
B(-3,59,3,minecraft:netherrack)
B(-3,60,3,minecraft:netherrack)
B(-3,61,3,minecraft:netherrack)
B(-3,62,3,minecraft:netherrack)
B(-3,63,3,minecraft:netherrack)
B(-3,64,3,minecraft:netherrack)
B(-3,65,3,minecraft:netherrack)
B(-3,66,3,minecraft:netherrack)
B(-3,28,4,minecraft:netherrack)
B(-3,29,4,minecraft:netherrack)
B(-3,30,4,minecraft:netherrack)
B(-3,31,4,minecraft:netherrack)
B(-3,32,4,minecraft:netherrack)
B(-3,33,4,minecraft:netherrack)
B(-3,34,4,minecraft:netherrack)
B(-3,35,4,minecraft:netherrack)
B(-3,36,4,minecraft:netherrack)
B(-3,37,4,minecraft:netherrack)
B(-3,38,4,minecraft:netherrack)
B(-3,39,4,minecraft:netherrack)
B(-3,40,4,minecraft:netherrack)
B(-3,41,4,minecraft:netherrack)
B(-3,42,4,minecraft:netherrack)
B(-3,43,4,minecraft:netherrack)
B(-3,44,4,minecraft:netherrack)
B(-3,45,4,minecraft:netherrack)
B(-3,46,4,minecraft:netherrack)
B(-3,47,4,minecraft:netherrack)
B(-3,48,4,minecraft:netherrack)
B(-3,49,4,minecraft:netherrack)
B(-3,50,4,minecraft:netherrack)
B(-3,51,4,minecraft:netherrack)
B(-3,52,4,minecraft:netherrack)
B(-3,53,4,minecraft:netherrack)
B(-3,54,4,minecraft:netherrack)
B(-3,55,4,minecraft:netherrack)
B(-3,56,4,minecraft:netherrack)
B(-3,57,4,minecraft:netherrack)
B(-3,58,4,minecraft:netherrack)
B(-3,59,4,minecraft:netherrack)
B(-3,60,4,minecraft:netherrack)
B(-3,61,4,minecraft:netherrack)
B(-3,62,4,minecraft:netherrack)
B(-3,63,4,minecraft:netherrack)
B(-3,64,4,minecraft:netherrack)
B(-3,65,4,minecraft:netherrack)
B(-3,66,4,minecraft:netherrack)
B(-3,25,5,minecraft:netherrack)
B(-3,26,5,minecraft:netherrack)
B(-3,27,5,minecraft:netherrack)
B(-3,28,5,minecraft:netherrack)
B(-3,29,5,minecraft:netherrack)
B(-3,30,5,minecraft:netherrack)
B(-3,31,5,minecraft:netherrack)
B(-3,32,5,minecraft:netherrack)
B(-3,33,5,minecraft:netherrack)
B(-3,34,5,minecraft:netherrack)
B(-3,35,5,minecraft:netherrack)
B(-3,36,5,minecraft:netherrack)
B(-3,37,5,minecraft:netherrack)
B(-3,38,5,minecraft:netherrack)
B(-3,39,5,minecraft:netherrack)
B(-3,40,5,minecraft:netherrack)
B(-3,41,5,minecraft:netherrack)
B(-3,42,5,minecraft:netherrack)
B(-3,43,5,minecraft:netherrack)
B(-3,44,5,minecraft:netherrack)
B(-3,45,5,minecraft:netherrack)
B(-3,46,5,minecraft:netherrack)
B(-3,47,5,minecraft:netherrack)
B(-3,48,5,minecraft:netherrack)
B(-3,49,5,minecraft:netherrack)
B(-3,50,5,minecraft:netherrack)
B(-3,51,5,minecraft:netherrack)
B(-3,52,5,minecraft:netherrack)
B(-3,53,5,minecraft:netherrack)
B(-3,54,5,minecraft:netherrack)
B(-3,55,5,minecraft:netherrack)
B(-3,56,5,minecraft:netherrack)
B(-3,57,5,minecraft:netherrack)
B(-3,58,5,minecraft:netherrack)
B(-3,59,5,minecraft:netherrack)
B(-3,60,5,minecraft:netherrack)
B(-3,61,5,minecraft:netherrack)
B(-3,62,5,minecraft:netherrack)
B(-3,63,5,minecraft:netherrack)
B(-3,64,5,minecraft:netherrack)
B(-3,65,5,minecraft:netherrack)
B(-3,66,5,minecraft:netherrack)
B(-3,24,6,minecraft:netherrack)
B(-3,25,6,minecraft:netherrack)
B(-3,26,6,minecraft:netherrack)
B(-3,27,6,minecraft:netherrack)
B(-3,28,6,minecraft:netherrack)
B(-3,29,6,minecraft:netherrack)
B(-3,30,6,minecraft:netherrack)
B(-3,31,6,minecraft:netherrack)
B(-3,32,6,minecraft:netherrack)
B(-3,33,6,minecraft:netherrack)
B(-3,34,6,minecraft:netherrack)
B(-3,35,6,minecraft:netherrack)
B(-3,36,6,minecraft:netherrack)
B(-3,37,6,minecraft:netherrack)
B(-3,38,6,minecraft:netherrack)
B(-3,39,6,minecraft:netherrack)
B(-3,40,6,minecraft:netherrack)
B(-3,41,6,minecraft:netherrack)
B(-3,42,6,minecraft:netherrack)
B(-3,43,6,minecraft:netherrack)
B(-3,44,6,minecraft:netherrack)
B(-3,45,6,minecraft:netherrack)
B(-3,46,6,minecraft:netherrack)
B(-3,47,6,minecraft:netherrack)
B(-3,48,6,minecraft:netherrack)
B(-3,49,6,minecraft:netherrack)
B(-3,50,6,minecraft:netherrack)
B(-3,51,6,minecraft:netherrack)
B(-3,52,6,minecraft:netherrack)
B(-3,53,6,minecraft:netherrack)
B(-3,54,6,minecraft:netherrack)
B(-3,55,6,minecraft:netherrack)
B(-3,56,6,minecraft:netherrack)
B(-3,57,6,minecraft:netherrack)
B(-3,58,6,minecraft:netherrack)
B(-3,59,6,minecraft:netherrack)
B(-3,60,6,minecraft:netherrack)
B(-3,61,6,minecraft:netherrack)
B(-3,62,6,minecraft:netherrack)
B(-3,63,6,minecraft:netherrack)
B(-3,64,6,minecraft:netherrack)
B(-3,65,6,minecraft:netherrack)
B(-3,66,6,minecraft:netherrack)
B(-3,12,7,minecraft:netherrack)
B(-3,13,7,minecraft:netherrack)
B(-3,14,7,minecraft:netherrack)
B(-3,15,7,minecraft:netherrack)
B(-3,16,7,minecraft:netherrack)
B(-3,17,7,minecraft:netherrack)
B(-3,18,7,minecraft:netherrack)
B(-3,19,7,minecraft:netherrack)
B(-3,20,7,minecraft:netherrack)
B(-3,21,7,minecraft:netherrack)
B(-3,22,7,minecraft:netherrack)
B(-3,23,7,minecraft:netherrack)
B(-3,24,7,minecraft:netherrack)
B(-3,25,7,minecraft:netherrack)
B(-3,26,7,minecraft:netherrack)
B(-3,27,7,minecraft:netherrack)
B(-3,28,7,minecraft:netherrack)
B(-3,29,7,minecraft:netherrack)
B(-3,30,7,minecraft:netherrack)
B(-3,31,7,minecraft:netherrack)
B(-3,32,7,minecraft:netherrack)
B(-3,33,7,minecraft:netherrack)
B(-3,34,7,minecraft:netherrack)
B(-3,35,7,minecraft:netherrack)
B(-3,36,7,minecraft:netherrack)
B(-3,37,7,minecraft:netherrack)
B(-3,38,7,minecraft:netherrack)
B(-3,39,7,minecraft:netherrack)
B(-3,40,7,minecraft:netherrack)
B(-3,41,7,minecraft:netherrack)
B(-3,42,7,minecraft:netherrack)
B(-3,43,7,minecraft:netherrack)
B(-3,44,7,minecraft:netherrack)
B(-3,45,7,minecraft:netherrack)
B(-3,46,7,minecraft:netherrack)
B(-3,47,7,minecraft:netherrack)
B(-3,48,7,minecraft:netherrack)
B(-3,49,7,minecraft:netherrack)
B(-3,50,7,minecraft:netherrack)
B(-3,51,7,minecraft:netherrack)
B(-3,52,7,minecraft:netherrack)
B(-3,53,7,minecraft:netherrack)
B(-3,54,7,minecraft:netherrack)
B(-3,55,7,minecraft:netherrack)
B(-3,56,7,minecraft:netherrack)
B(-3,57,7,minecraft:netherrack)
B(-3,58,7,minecraft:netherrack)
B(-3,59,7,minecraft:netherrack)
B(-3,60,7,minecraft:netherrack)
B(-3,61,7,minecraft:netherrack)
B(-3,62,7,minecraft:netherrack)
B(-3,63,7,minecraft:netherrack)
B(-3,64,7,minecraft:netherrack)
B(-3,65,7,minecraft:netherrack)
B(-3,66,7,minecraft:netherrack)
B(-3,2,8,minecraft:netherrack)
B(-3,3,8,minecraft:netherrack)
B(-3,4,8,minecraft:netherrack)
B(-3,5,8,minecraft:netherrack)
B(-3,6,8,minecraft:netherrack)
B(-3,7,8,minecraft:netherrack)
B(-3,8,8,minecraft:netherrack)
B(-3,9,8,minecraft:netherrack)
B(-3,10,8,minecraft:netherrack)
B(-3,11,8,minecraft:netherrack)
B(-3,12,8,minecraft:netherrack)
B(-3,13,8,minecraft:netherrack)
B(-3,14,8,minecraft:netherrack)
B(-3,15,8,minecraft:netherrack)
B(-3,16,8,minecraft:netherrack)
B(-3,17,8,minecraft:netherrack)
B(-3,18,8,minecraft:netherrack)
B(-3,19,8,minecraft:netherrack)
B(-3,20,8,minecraft:netherrack)
B(-3,21,8,minecraft:netherrack)
B(-3,22,8,minecraft:netherrack)
B(-3,23,8,minecraft:netherrack)
B(-3,24,8,minecraft:netherrack)
B(-3,25,8,minecraft:netherrack)
B(-3,26,8,minecraft:netherrack)
B(-3,27,8,minecraft:netherrack)
B(-3,28,8,minecraft:netherrack)
B(-3,29,8,minecraft:netherrack)
B(-3,30,8,minecraft:netherrack)
B(-3,31,8,minecraft:netherrack)
B(-3,32,8,minecraft:netherrack)
B(-3,33,8,minecraft:netherrack)
B(-3,34,8,minecraft:netherrack)
B(-3,35,8,minecraft:netherrack)
B(-3,36,8,minecraft:netherrack)
B(-3,37,8,minecraft:netherrack)
B(-3,38,8,minecraft:netherrack)
B(-3,39,8,minecraft:netherrack)
B(-3,40,8,minecraft:netherrack)
B(-3,41,8,minecraft:netherrack)
B(-3,42,8,minecraft:netherrack)
B(-3,43,8,minecraft:netherrack)
B(-3,44,8,minecraft:netherrack)
B(-3,45,8,minecraft:netherrack)
B(-3,46,8,minecraft:netherrack)
B(-3,47,8,minecraft:netherrack)
B(-3,48,8,minecraft:netherrack)
B(-3,49,8,minecraft:netherrack)
B(-3,50,8,minecraft:netherrack)
B(-3,51,8,minecraft:netherrack)
B(-3,52,8,minecraft:netherrack)
B(-3,53,8,minecraft:netherrack)
B(-3,54,8,minecraft:netherrack)
B(-3,55,8,minecraft:netherrack)
B(-3,56,8,minecraft:netherrack)
B(-3,57,8,minecraft:netherrack)
B(-3,58,8,minecraft:netherrack)
B(-3,59,8,minecraft:netherrack)
B(-3,60,8,minecraft:netherrack)
B(-3,61,8,minecraft:netherrack)
B(-3,62,8,minecraft:netherrack)
B(-3,63,8,minecraft:netherrack)
B(-3,64,8,minecraft:netherrack)
B(-3,65,8,minecraft:netherrack)
B(-3,66,8,minecraft:netherrack)
B(-2,62,-7,minecraft:netherrack)
B(-2,63,-7,minecraft:netherrack)
B(-2,64,-7,minecraft:netherrack)
B(-2,65,-7,minecraft:netherrack)
B(-2,66,-7,minecraft:netherrack)
B(-2,60,-6,minecraft:netherrack)
B(-2,61,-6,minecraft:netherrack)
B(-2,62,-6,minecraft:netherrack)
B(-2,63,-6,minecraft:netherrack)
B(-2,64,-6,minecraft:netherrack)
B(-2,65,-6,minecraft:netherrack)
B(-2,66,-6,minecraft:netherrack)
B(-2,60,-5,minecraft:netherrack)
B(-2,61,-5,minecraft:netherrack)
B(-2,62,-5,minecraft:netherrack)
B(-2,63,-5,minecraft:netherrack)
B(-2,64,-5,minecraft:netherrack)
B(-2,65,-5,minecraft:netherrack)
B(-2,66,-5,minecraft:netherrack)
B(-2,60,-4,minecraft:netherrack)
B(-2,61,-4,minecraft:netherrack)
B(-2,62,-4,minecraft:netherrack)
B(-2,63,-4,minecraft:netherrack)
B(-2,64,-4,minecraft:netherrack)
B(-2,65,-4,minecraft:netherrack)
B(-2,66,-4,minecraft:netherrack)
B(-2,58,-3,minecraft:netherrack)
B(-2,59,-3,minecraft:netherrack)
B(-2,60,-3,minecraft:netherrack)
B(-2,61,-3,minecraft:netherrack)
B(-2,62,-3,minecraft:netherrack)
B(-2,63,-3,minecraft:netherrack)
B(-2,64,-3,minecraft:netherrack)
B(-2,65,-3,minecraft:netherrack)
B(-2,66,-3,minecraft:netherrack)
B(-2,57,-2,minecraft:netherrack)
B(-2,58,-2,minecraft:netherrack)
B(-2,59,-2,minecraft:netherrack)
B(-2,60,-2,minecraft:netherrack)
B(-2,61,-2,minecraft:netherrack)
B(-2,62,-2,minecraft:netherrack)
B(-2,63,-2,minecraft:netherrack)
B(-2,64,-2,minecraft:netherrack)
B(-2,65,-2,minecraft:netherrack)
B(-2,66,-2,minecraft:netherrack)
B(-2,57,-1,minecraft:netherrack)
B(-2,58,-1,minecraft:netherrack)
B(-2,59,-1,minecraft:netherrack)
B(-2,60,-1,minecraft:netherrack)
B(-2,61,-1,minecraft:netherrack)
B(-2,62,-1,minecraft:netherrack)
B(-2,63,-1,minecraft:netherrack)
B(-2,64,-1,minecraft:netherrack)
B(-2,65,-1,minecraft:netherrack)
B(-2,66,-1,minecraft:netherrack)
B(-2,56,0,minecraft:netherrack)
B(-2,57,0,minecraft:netherrack)
B(-2,58,0,minecraft:netherrack)
B(-2,59,0,minecraft:netherrack)
B(-2,60,0,minecraft:netherrack)
B(-2,61,0,minecraft:netherrack)
B(-2,62,0,minecraft:netherrack)
B(-2,63,0,minecraft:netherrack)
B(-2,64,0,minecraft:netherrack)
B(-2,65,0,minecraft:netherrack)
B(-2,66,0,minecraft:netherrack)
B(-2,52,1,minecraft:netherrack)
B(-2,53,1,minecraft:netherrack)
B(-2,54,1,minecraft:netherrack)
B(-2,55,1,minecraft:netherrack)
B(-2,56,1,minecraft:netherrack)
B(-2,57,1,minecraft:netherrack)
B(-2,58,1,minecraft:netherrack)
B(-2,59,1,minecraft:netherrack)
B(-2,60,1,minecraft:netherrack)
B(-2,61,1,minecraft:netherrack)
B(-2,62,1,minecraft:netherrack)
B(-2,63,1,minecraft:netherrack)
B(-2,64,1,minecraft:netherrack)
B(-2,65,1,minecraft:netherrack)
B(-2,66,1,minecraft:netherrack)
B(-2,46,2,minecraft:netherrack)
B(-2,47,2,minecraft:netherrack)
B(-2,48,2,minecraft:netherrack)
B(-2,49,2,minecraft:netherrack)
B(-2,50,2,minecraft:netherrack)
B(-2,51,2,minecraft:netherrack)
B(-2,52,2,minecraft:netherrack)
B(-2,53,2,minecraft:netherrack)
B(-2,54,2,minecraft:netherrack)
B(-2,55,2,minecraft:netherrack)
B(-2,56,2,minecraft:netherrack)
B(-2,57,2,minecraft:netherrack)
B(-2,58,2,minecraft:netherrack)
B(-2,59,2,minecraft:netherrack)
B(-2,60,2,minecraft:netherrack)
B(-2,61,2,minecraft:netherrack)
B(-2,62,2,minecraft:netherrack)
B(-2,63,2,minecraft:netherrack)
B(-2,64,2,minecraft:netherrack)
B(-2,65,2,minecraft:netherrack)
B(-2,66,2,minecraft:netherrack)
B(-2,34,3,minecraft:netherrack)
B(-2,35,3,minecraft:netherrack)
B(-2,36,3,minecraft:netherrack)
B(-2,37,3,minecraft:netherrack)
B(-2,38,3,minecraft:netherrack)
B(-2,39,3,minecraft:netherrack)
B(-2,40,3,minecraft:netherrack)
B(-2,41,3,minecraft:netherrack)
B(-2,42,3,minecraft:netherrack)
B(-2,43,3,minecraft:netherrack)
B(-2,44,3,minecraft:netherrack)
B(-2,45,3,minecraft:netherrack)
B(-2,46,3,minecraft:netherrack)
B(-2,47,3,minecraft:netherrack)
B(-2,48,3,minecraft:netherrack)
B(-2,49,3,minecraft:netherrack)
B(-2,50,3,minecraft:netherrack)
B(-2,51,3,minecraft:netherrack)
B(-2,52,3,minecraft:netherrack)
B(-2,53,3,minecraft:netherrack)
B(-2,54,3,minecraft:netherrack)
B(-2,55,3,minecraft:netherrack)
B(-2,56,3,minecraft:netherrack)
B(-2,57,3,minecraft:netherrack)
B(-2,58,3,minecraft:netherrack)
B(-2,59,3,minecraft:netherrack)
B(-2,60,3,minecraft:netherrack)
B(-2,61,3,minecraft:netherrack)
B(-2,62,3,minecraft:netherrack)
B(-2,63,3,minecraft:netherrack)
B(-2,64,3,minecraft:netherrack)
B(-2,65,3,minecraft:netherrack)
B(-2,66,3,minecraft:netherrack)
B(-2,31,4,minecraft:netherrack)
B(-2,32,4,minecraft:netherrack)
B(-2,33,4,minecraft:netherrack)
B(-2,34,4,minecraft:netherrack)
B(-2,35,4,minecraft:netherrack)
B(-2,36,4,minecraft:netherrack)
B(-2,37,4,minecraft:netherrack)
B(-2,38,4,minecraft:netherrack)
B(-2,39,4,minecraft:netherrack)
B(-2,40,4,minecraft:netherrack)
B(-2,41,4,minecraft:netherrack)
B(-2,42,4,minecraft:netherrack)
B(-2,43,4,minecraft:netherrack)
B(-2,44,4,minecraft:netherrack)
B(-2,45,4,minecraft:netherrack)
B(-2,46,4,minecraft:netherrack)
B(-2,47,4,minecraft:netherrack)
B(-2,48,4,minecraft:netherrack)
B(-2,49,4,minecraft:netherrack)
B(-2,50,4,minecraft:netherrack)
B(-2,51,4,minecraft:netherrack)
B(-2,52,4,minecraft:netherrack)
B(-2,53,4,minecraft:netherrack)
B(-2,54,4,minecraft:netherrack)
B(-2,55,4,minecraft:netherrack)
B(-2,56,4,minecraft:netherrack)
B(-2,57,4,minecraft:netherrack)
B(-2,58,4,minecraft:netherrack)
B(-2,59,4,minecraft:netherrack)
B(-2,60,4,minecraft:netherrack)
B(-2,61,4,minecraft:netherrack)
B(-2,62,4,minecraft:netherrack)
B(-2,63,4,minecraft:netherrack)
B(-2,64,4,minecraft:netherrack)
B(-2,65,4,minecraft:netherrack)
B(-2,66,4,minecraft:netherrack)
B(-2,27,5,minecraft:netherrack)
B(-2,28,5,minecraft:netherrack)
B(-2,29,5,minecraft:netherrack)
B(-2,30,5,minecraft:netherrack)
B(-2,31,5,minecraft:netherrack)
B(-2,32,5,minecraft:netherrack)
B(-2,33,5,minecraft:netherrack)
B(-2,34,5,minecraft:netherrack)
B(-2,35,5,minecraft:netherrack)
B(-2,36,5,minecraft:netherrack)
B(-2,37,5,minecraft:netherrack)
B(-2,38,5,minecraft:netherrack)
B(-2,39,5,minecraft:netherrack)
B(-2,40,5,minecraft:netherrack)
B(-2,41,5,minecraft:netherrack)
B(-2,42,5,minecraft:netherrack)
B(-2,43,5,minecraft:netherrack)
B(-2,44,5,minecraft:netherrack)
B(-2,45,5,minecraft:netherrack)
B(-2,46,5,minecraft:netherrack)
B(-2,47,5,minecraft:netherrack)
B(-2,48,5,minecraft:netherrack)
B(-2,49,5,minecraft:netherrack)
B(-2,50,5,minecraft:netherrack)
B(-2,51,5,minecraft:netherrack)
B(-2,52,5,minecraft:netherrack)
B(-2,53,5,minecraft:netherrack)
B(-2,54,5,minecraft:netherrack)
B(-2,55,5,minecraft:netherrack)
B(-2,56,5,minecraft:netherrack)
B(-2,57,5,minecraft:netherrack)
B(-2,58,5,minecraft:netherrack)
B(-2,59,5,minecraft:netherrack)
B(-2,60,5,minecraft:netherrack)
B(-2,61,5,minecraft:netherrack)
B(-2,62,5,minecraft:netherrack)
B(-2,63,5,minecraft:netherrack)
B(-2,64,5,minecraft:netherrack)
B(-2,65,5,minecraft:netherrack)
B(-2,66,5,minecraft:netherrack)
B(-2,25,6,minecraft:netherrack)
B(-2,26,6,minecraft:netherrack)
B(-2,27,6,minecraft:netherrack)
B(-2,28,6,minecraft:netherrack)
B(-2,29,6,minecraft:netherrack)
B(-2,30,6,minecraft:netherrack)
B(-2,31,6,minecraft:netherrack)
B(-2,32,6,minecraft:netherrack)
B(-2,33,6,minecraft:netherrack)
B(-2,34,6,minecraft:netherrack)
B(-2,35,6,minecraft:netherrack)
B(-2,36,6,minecraft:netherrack)
B(-2,37,6,minecraft:netherrack)
B(-2,38,6,minecraft:netherrack)
B(-2,39,6,minecraft:netherrack)
B(-2,40,6,minecraft:netherrack)
B(-2,41,6,minecraft:netherrack)
B(-2,42,6,minecraft:netherrack)
B(-2,43,6,minecraft:netherrack)
B(-2,44,6,minecraft:netherrack)
B(-2,45,6,minecraft:netherrack)
B(-2,46,6,minecraft:netherrack)
B(-2,47,6,minecraft:netherrack)
B(-2,48,6,minecraft:netherrack)
B(-2,49,6,minecraft:netherrack)
B(-2,50,6,minecraft:netherrack)
B(-2,51,6,minecraft:netherrack)
B(-2,52,6,minecraft:netherrack)
B(-2,53,6,minecraft:netherrack)
B(-2,54,6,minecraft:netherrack)
B(-2,55,6,minecraft:netherrack)
B(-2,56,6,minecraft:netherrack)
B(-2,57,6,minecraft:netherrack)
B(-2,58,6,minecraft:netherrack)
B(-2,59,6,minecraft:netherrack)
B(-2,60,6,minecraft:netherrack)
B(-2,61,6,minecraft:netherrack)
B(-2,62,6,minecraft:netherrack)
B(-2,63,6,minecraft:netherrack)
B(-2,64,6,minecraft:netherrack)
B(-2,65,6,minecraft:netherrack)
B(-2,66,6,minecraft:netherrack)
B(-2,17,7,minecraft:netherrack)
B(-2,18,7,minecraft:netherrack)
B(-2,19,7,minecraft:netherrack)
B(-2,20,7,minecraft:netherrack)
B(-2,21,7,minecraft:netherrack)
B(-2,22,7,minecraft:netherrack)
B(-2,23,7,minecraft:netherrack)
B(-2,24,7,minecraft:netherrack)
B(-2,25,7,minecraft:netherrack)
B(-2,26,7,minecraft:netherrack)
B(-2,27,7,minecraft:netherrack)
B(-2,28,7,minecraft:netherrack)
B(-2,29,7,minecraft:netherrack)
B(-2,30,7,minecraft:netherrack)
B(-2,31,7,minecraft:netherrack)
B(-2,32,7,minecraft:netherrack)
B(-2,33,7,minecraft:netherrack)
B(-2,34,7,minecraft:netherrack)
B(-2,35,7,minecraft:netherrack)
B(-2,36,7,minecraft:netherrack)
B(-2,37,7,minecraft:netherrack)
B(-2,38,7,minecraft:netherrack)
B(-2,39,7,minecraft:netherrack)
B(-2,40,7,minecraft:netherrack)
B(-2,41,7,minecraft:netherrack)
B(-2,42,7,minecraft:netherrack)
B(-2,43,7,minecraft:netherrack)
B(-2,44,7,minecraft:netherrack)
B(-2,45,7,minecraft:netherrack)
B(-2,46,7,minecraft:netherrack)
B(-2,47,7,minecraft:netherrack)
B(-2,48,7,minecraft:netherrack)
B(-2,49,7,minecraft:netherrack)
B(-2,50,7,minecraft:netherrack)
B(-2,51,7,minecraft:netherrack)
B(-2,52,7,minecraft:netherrack)
B(-2,53,7,minecraft:netherrack)
B(-2,54,7,minecraft:netherrack)
B(-2,55,7,minecraft:netherrack)
B(-2,56,7,minecraft:netherrack)
B(-2,57,7,minecraft:netherrack)
B(-2,58,7,minecraft:netherrack)
B(-2,59,7,minecraft:netherrack)
B(-2,60,7,minecraft:netherrack)
B(-2,61,7,minecraft:netherrack)
B(-2,62,7,minecraft:netherrack)
B(-2,63,7,minecraft:netherrack)
B(-2,64,7,minecraft:netherrack)
B(-2,65,7,minecraft:netherrack)
B(-2,66,7,minecraft:netherrack)
B(-2,12,8,minecraft:netherrack)
B(-2,13,8,minecraft:netherrack)
B(-2,14,8,minecraft:netherrack)
B(-2,15,8,minecraft:netherrack)
B(-2,16,8,minecraft:netherrack)
B(-2,17,8,minecraft:netherrack)
B(-2,18,8,minecraft:netherrack)
B(-2,19,8,minecraft:netherrack)
B(-2,20,8,minecraft:netherrack)
B(-2,21,8,minecraft:netherrack)
B(-2,22,8,minecraft:netherrack)
B(-2,23,8,minecraft:netherrack)
B(-2,24,8,minecraft:netherrack)
B(-2,25,8,minecraft:netherrack)
B(-2,26,8,minecraft:netherrack)
B(-2,27,8,minecraft:netherrack)
B(-2,28,8,minecraft:netherrack)
B(-2,29,8,minecraft:netherrack)
B(-2,30,8,minecraft:netherrack)
B(-2,31,8,minecraft:netherrack)
B(-2,32,8,minecraft:netherrack)
B(-2,33,8,minecraft:netherrack)
B(-2,34,8,minecraft:netherrack)
B(-2,35,8,minecraft:netherrack)
B(-2,36,8,minecraft:netherrack)
B(-2,37,8,minecraft:netherrack)
B(-2,38,8,minecraft:netherrack)
B(-2,39,8,minecraft:netherrack)
B(-2,40,8,minecraft:netherrack)
B(-2,41,8,minecraft:netherrack)
B(-2,42,8,minecraft:netherrack)
B(-2,43,8,minecraft:netherrack)
B(-2,44,8,minecraft:netherrack)
B(-2,45,8,minecraft:netherrack)
B(-2,46,8,minecraft:netherrack)
B(-2,47,8,minecraft:netherrack)
B(-2,48,8,minecraft:netherrack)
B(-2,49,8,minecraft:netherrack)
B(-2,50,8,minecraft:netherrack)
B(-2,51,8,minecraft:netherrack)
B(-2,52,8,minecraft:netherrack)
B(-2,53,8,minecraft:netherrack)
B(-2,54,8,minecraft:netherrack)
B(-2,55,8,minecraft:netherrack)
B(-2,56,8,minecraft:netherrack)
B(-2,57,8,minecraft:netherrack)
B(-2,58,8,minecraft:netherrack)
B(-2,59,8,minecraft:netherrack)
B(-2,60,8,minecraft:netherrack)
B(-2,61,8,minecraft:netherrack)
B(-2,62,8,minecraft:netherrack)
B(-2,63,8,minecraft:netherrack)
B(-2,64,8,minecraft:netherrack)
B(-2,65,8,minecraft:netherrack)
B(-2,66,8,minecraft:netherrack)
B(-1,62,-7,minecraft:netherrack)
B(-1,63,-7,minecraft:netherrack)
B(-1,64,-7,minecraft:netherrack)
B(-1,65,-7,minecraft:netherrack)
B(-1,66,-7,minecraft:netherrack)
B(-1,61,-6,minecraft:netherrack)
B(-1,62,-6,minecraft:netherrack)
B(-1,63,-6,minecraft:netherrack)
B(-1,64,-6,minecraft:netherrack)
B(-1,65,-6,minecraft:netherrack)
B(-1,66,-6,minecraft:netherrack)
B(-1,61,-5,minecraft:netherrack)
B(-1,62,-5,minecraft:netherrack)
B(-1,63,-5,minecraft:netherrack)
B(-1,64,-5,minecraft:netherrack)
B(-1,65,-5,minecraft:netherrack)
B(-1,66,-5,minecraft:netherrack)
B(-1,60,-4,minecraft:netherrack)
B(-1,61,-4,minecraft:netherrack)
B(-1,62,-4,minecraft:netherrack)
B(-1,63,-4,minecraft:netherrack)
B(-1,64,-4,minecraft:netherrack)
B(-1,65,-4,minecraft:netherrack)
B(-1,66,-4,minecraft:netherrack)
B(-1,59,-3,minecraft:netherrack)
B(-1,60,-3,minecraft:netherrack)
B(-1,61,-3,minecraft:netherrack)
B(-1,62,-3,minecraft:netherrack)
B(-1,63,-3,minecraft:netherrack)
B(-1,64,-3,minecraft:netherrack)
B(-1,65,-3,minecraft:netherrack)
B(-1,66,-3,minecraft:netherrack)
B(-1,59,-2,minecraft:netherrack)
B(-1,60,-2,minecraft:netherrack)
B(-1,61,-2,minecraft:netherrack)
B(-1,62,-2,minecraft:netherrack)
B(-1,63,-2,minecraft:netherrack)
B(-1,64,-2,minecraft:netherrack)
B(-1,65,-2,minecraft:netherrack)
B(-1,66,-2,minecraft:netherrack)
B(-1,56,-1,minecraft:netherrack)
B(-1,57,-1,minecraft:netherrack)
B(-1,58,-1,minecraft:netherrack)
B(-1,59,-1,minecraft:netherrack)
B(-1,60,-1,minecraft:netherrack)
B(-1,61,-1,minecraft:netherrack)
B(-1,62,-1,minecraft:netherrack)
B(-1,63,-1,minecraft:netherrack)
B(-1,64,-1,minecraft:netherrack)
B(-1,65,-1,minecraft:netherrack)
B(-1,66,-1,minecraft:netherrack)
B(-1,55,0,minecraft:netherrack)
B(-1,56,0,minecraft:netherrack)
B(-1,57,0,minecraft:netherrack)
B(-1,58,0,minecraft:netherrack)
B(-1,59,0,minecraft:netherrack)
B(-1,60,0,minecraft:netherrack)
B(-1,61,0,minecraft:netherrack)
B(-1,62,0,minecraft:netherrack)
B(-1,63,0,minecraft:netherrack)
B(-1,64,0,minecraft:netherrack)
B(-1,65,0,minecraft:netherrack)
B(-1,66,0,minecraft:netherrack)
B(-1,54,1,minecraft:netherrack)
B(-1,55,1,minecraft:netherrack)
B(-1,56,1,minecraft:netherrack)
B(-1,57,1,minecraft:netherrack)
B(-1,58,1,minecraft:netherrack)
B(-1,59,1,minecraft:netherrack)
B(-1,60,1,minecraft:netherrack)
B(-1,61,1,minecraft:netherrack)
B(-1,62,1,minecraft:netherrack)
B(-1,63,1,minecraft:netherrack)
B(-1,64,1,minecraft:netherrack)
B(-1,65,1,minecraft:netherrack)
B(-1,66,1,minecraft:netherrack)
B(-1,47,2,minecraft:netherrack)
B(-1,48,2,minecraft:netherrack)
B(-1,49,2,minecraft:netherrack)
B(-1,50,2,minecraft:netherrack)
B(-1,51,2,minecraft:netherrack)
