
#######################################################################
# +-----------------------------------------------------------------+ #
# |                            BO4 object                           | #
# +-----------------------------------------------------------------+ #
#######################################################################

Author: Unknown

Description: No description given

SettingsMode: WriteWithoutComments


#######################################################################
# +-----------------------------------------------------------------+ #
# |                          Main settings                          | #
# +-----------------------------------------------------------------+ #
#######################################################################

FixedRotation: 

Frequency: 0

SpawnHeight: highestBlock

UseCenterForHighestBlock: true

##############################
# Height Limits for the BO4. #
##############################

MinHeight: 0

MaxHeight: 255

InheritBO3: 

InheritBO3Rotation: NORTH

OverrideChildSettings: true

OverrideParentHeight: false

CanOverride: false

BranchFrequency: 0

BranchFrequencyGroup: 

MustBeBelowOther: false

MustBeInside: 

CannotBeInside: 

ReplacesBO3: 

MustBeInsideWorldBorders: false

CanSpawnOnWater: true

SpawnOnWaterOnly: false

SpawnUnderWater: false

SpawnAtWaterLevel: false

HeightOffset: 0

RemoveAir: true

ReplaceAbove: 

ReplaceBelow: 

ReplaceWithBiomeBlocks: true

ReplaceWithSurfaceBlock: GRASS

ReplaceWithGroundBlock: DIRT

ReplaceWithStoneBlock: STONE

SmoothRadius: 0

SmoothHeightOffset: 0

SmoothStartTop: false

SmoothStartWood: false

SmoothingSurfaceBlock: 

SmoothingGroundBlock: 

BO3Group: 

IsSpawnPoint: false

DoReplaceBlocks: true


#######################################################################
# +-----------------------------------------------------------------+ #
# |                              Blocks                             | #
# +-----------------------------------------------------------------+ #
#######################################################################

B(-8,63,-7,minecraft:netherrack)
B(-8,64,-7,minecraft:netherrack)
B(-8,65,-7,minecraft:netherrack)
B(-8,66,-7,minecraft:netherrack)
B(-8,63,-6,minecraft:netherrack)
B(-8,64,-6,minecraft:netherrack)
B(-8,65,-6,minecraft:netherrack)
B(-8,66,-6,minecraft:netherrack)
B(-8,62,-5,minecraft:netherrack)
B(-8,63,-5,minecraft:netherrack)
B(-8,64,-5,minecraft:netherrack)
B(-8,65,-5,minecraft:netherrack)
B(-8,66,-5,minecraft:netherrack)
B(-8,62,-4,minecraft:netherrack)
B(-8,63,-4,minecraft:netherrack)
B(-8,64,-4,minecraft:netherrack)
B(-8,65,-4,minecraft:netherrack)
B(-8,66,-4,minecraft:netherrack)
B(-8,62,-3,minecraft:netherrack)
B(-8,63,-3,minecraft:netherrack)
B(-8,64,-3,minecraft:netherrack)
B(-8,65,-3,minecraft:netherrack)
B(-8,66,-3,minecraft:netherrack)
B(-8,62,-2,minecraft:netherrack)
B(-8,63,-2,minecraft:netherrack)
B(-8,64,-2,minecraft:netherrack)
B(-8,65,-2,minecraft:netherrack)
B(-8,66,-2,minecraft:netherrack)
B(-8,62,-1,minecraft:netherrack)
B(-8,63,-1,minecraft:netherrack)
B(-8,64,-1,minecraft:netherrack)
B(-8,65,-1,minecraft:netherrack)
B(-8,66,-1,minecraft:netherrack)
B(-8,62,0,minecraft:netherrack)
B(-8,63,0,minecraft:netherrack)
B(-8,64,0,minecraft:netherrack)
B(-8,65,0,minecraft:netherrack)
B(-8,66,0,minecraft:netherrack)
B(-8,62,1,minecraft:netherrack)
B(-8,63,1,minecraft:netherrack)
B(-8,64,1,minecraft:netherrack)
B(-8,65,1,minecraft:netherrack)
B(-8,66,1,minecraft:netherrack)
B(-8,63,2,minecraft:netherrack)
B(-8,64,2,minecraft:netherrack)
B(-8,65,2,minecraft:netherrack)
B(-8,66,2,minecraft:netherrack)
B(-8,64,3,minecraft:netherrack)
B(-8,65,3,minecraft:netherrack)
B(-8,66,3,minecraft:netherrack)
B(-8,64,4,minecraft:netherrack)
B(-8,65,4,minecraft:netherrack)
B(-8,66,4,minecraft:netherrack)
B(-8,65,5,minecraft:netherrack)
B(-8,66,5,minecraft:netherrack)
B(-8,65,6,minecraft:netherrack)
B(-8,66,6,minecraft:netherrack)
B(-8,65,7,minecraft:netherrack)
B(-8,66,7,minecraft:netherrack)
B(-8,65,8,minecraft:netherrack)
B(-8,66,8,minecraft:netherrack)
B(-7,64,-7,minecraft:netherrack)
B(-7,65,-7,minecraft:netherrack)
B(-7,66,-7,minecraft:netherrack)
B(-7,63,-6,minecraft:netherrack)
B(-7,64,-6,minecraft:netherrack)
B(-7,65,-6,minecraft:netherrack)
B(-7,66,-6,minecraft:netherrack)
B(-7,63,-5,minecraft:netherrack)
B(-7,64,-5,minecraft:netherrack)
B(-7,65,-5,minecraft:netherrack)
B(-7,66,-5,minecraft:netherrack)
B(-7,63,-4,minecraft:netherrack)
B(-7,64,-4,minecraft:netherrack)
B(-7,65,-4,minecraft:netherrack)
B(-7,66,-4,minecraft:netherrack)
B(-7,63,-3,minecraft:netherrack)
B(-7,64,-3,minecraft:netherrack)
B(-7,65,-3,minecraft:netherrack)
B(-7,66,-3,minecraft:netherrack)
B(-7,63,-2,minecraft:netherrack)
B(-7,64,-2,minecraft:netherrack)
B(-7,65,-2,minecraft:netherrack)
B(-7,66,-2,minecraft:netherrack)
B(-7,63,-1,minecraft:netherrack)
B(-7,64,-1,minecraft:netherrack)
B(-7,65,-1,minecraft:netherrack)
B(-7,66,-1,minecraft:netherrack)
B(-7,63,0,minecraft:netherrack)
B(-7,64,0,minecraft:netherrack)
B(-7,65,0,minecraft:netherrack)
B(-7,66,0,minecraft:netherrack)
B(-7,64,1,minecraft:netherrack)
B(-7,65,1,minecraft:netherrack)
B(-7,66,1,minecraft:netherrack)
B(-7,64,2,minecraft:netherrack)
B(-7,65,2,minecraft:netherrack)
B(-7,66,2,minecraft:netherrack)
B(-7,65,3,minecraft:netherrack)
B(-7,66,3,minecraft:netherrack)
B(-7,65,4,minecraft:netherrack)
B(-7,66,4,minecraft:netherrack)
B(-7,66,5,minecraft:netherrack)
B(-7,66,6,minecraft:netherrack)
B(-7,66,7,minecraft:netherrack)
B(-6,65,-7,minecraft:netherrack)
B(-6,66,-7,minecraft:netherrack)
B(-6,64,-6,minecraft:netherrack)
B(-6,65,-6,minecraft:netherrack)
B(-6,66,-6,minecraft:netherrack)
B(-6,64,-5,minecraft:netherrack)
B(-6,65,-5,minecraft:netherrack)
B(-6,66,-5,minecraft:netherrack)
B(-6,64,-4,minecraft:netherrack)
B(-6,65,-4,minecraft:netherrack)
B(-6,66,-4,minecraft:netherrack)
B(-6,64,-3,minecraft:netherrack)
B(-6,65,-3,minecraft:netherrack)
B(-6,66,-3,minecraft:netherrack)
B(-6,64,-2,minecraft:netherrack)
B(-6,65,-2,minecraft:netherrack)
B(-6,66,-2,minecraft:netherrack)
B(-6,64,-1,minecraft:netherrack)
B(-6,65,-1,minecraft:netherrack)
B(-6,66,-1,minecraft:netherrack)
B(-6,65,0,minecraft:netherrack)
B(-6,66,0,minecraft:netherrack)
B(-6,65,1,minecraft:netherrack)
B(-6,66,1,minecraft:netherrack)
B(-6,65,2,minecraft:netherrack)
B(-6,66,2,minecraft:netherrack)
B(-6,66,3,minecraft:netherrack)
B(-6,66,4,minecraft:netherrack)
B(-5,66,-7,minecraft:netherrack)
B(-5,65,-6,minecraft:netherrack)
B(-5,66,-6,minecraft:netherrack)
B(-5,65,-5,minecraft:netherrack)
B(-5,66,-5,minecraft:netherrack)
B(-5,65,-4,minecraft:netherrack)
B(-5,66,-4,minecraft:netherrack)
B(-5,66,-3,minecraft:netherrack)
B(-5,66,-2,minecraft:netherrack)
B(-5,66,-1,minecraft:netherrack)
B(-5,66,0,minecraft:netherrack)
B(-5,66,1,minecraft:netherrack)
B(-4,66,-5,minecraft:netherrack)

#######################################################################
# +-----------------------------------------------------------------+ #
# |                             Branches                            | #
# +-----------------------------------------------------------------+ #
#######################################################################


#######################################################################
# +-----------------------------------------------------------------+ #
# |                             Entities                            | #
# +-----------------------------------------------------------------+ #
#######################################################################

