
#######################################################################
# +-----------------------------------------------------------------+ #
# |                            BO4 object                           | #
# +-----------------------------------------------------------------+ #
#######################################################################

Author: Unknown

Description: No description given

SettingsMode: WriteWithoutComments


#######################################################################
# +-----------------------------------------------------------------+ #
# |                          Main settings                          | #
# +-----------------------------------------------------------------+ #
#######################################################################

FixedRotation: 

Frequency: 0

SpawnHeight: highestBlock

UseCenterForHighestBlock: true

##############################
# Height Limits for the BO4. #
##############################

MinHeight: 0

MaxHeight: 255

InheritBO3: 

InheritBO3Rotation: NORTH

OverrideChildSettings: true

OverrideParentHeight: false

CanOverride: false

BranchFrequency: 0

BranchFrequencyGroup: 

MustBeBelowOther: false

MustBeInside: 

CannotBeInside: 

ReplacesBO3: 

MustBeInsideWorldBorders: false

CanSpawnOnWater: true

SpawnOnWaterOnly: false

SpawnUnderWater: false

SpawnAtWaterLevel: false

HeightOffset: 0

RemoveAir: true

ReplaceAbove: 

ReplaceBelow: 

ReplaceWithBiomeBlocks: true

ReplaceWithSurfaceBlock: GRASS

ReplaceWithGroundBlock: DIRT

ReplaceWithStoneBlock: STONE

SmoothRadius: 0

SmoothHeightOffset: 0

SmoothStartTop: false

SmoothStartWood: false

SmoothingSurfaceBlock: 

SmoothingGroundBlock: 

BO3Group: 

IsSpawnPoint: false

DoReplaceBlocks: true


#######################################################################
# +-----------------------------------------------------------------+ #
# |                              Blocks                             | #
# +-----------------------------------------------------------------+ #
#######################################################################

B(-8,68,-6,minecraft:blackstone)
B(-8,69,-6,minecraft:blackstone)
B(-8,70,-6,minecraft:blackstone)
B(-8,71,-5,minecraft:blackstone)
B(-8,71,-3,minecraft:blackstone)
B(-8,68,-2,minecraft:blackstone)
B(-8,69,-2,minecraft:blackstone)
B(-8,70,-2,minecraft:blackstone)
B(-7,67,-5,minecraft:blackstone)
B(-7,64,-4,minecraft:glowstone)
B(-7,65,-4,minecraft:chain)
B(-7,66,-4,minecraft:glowstone)
B(-7,67,-3,minecraft:blackstone)
B(-6,60,-6,minecraft:blackstone)
B(-6,61,-6,minecraft:blackstone)
B(-6,62,-6,minecraft:blackstone)
B(-6,63,-5,minecraft:blackstone)
B(-6,63,-3,minecraft:blackstone)
B(-6,60,-2,minecraft:blackstone)
B(-6,61,-2,minecraft:blackstone)
B(-6,62,-2,minecraft:blackstone)
B(-5,59,-5,minecraft:blackstone)
B(-5,56,-4,minecraft:glowstone)
B(-5,57,-4,minecraft:chain)
B(-5,58,-4,minecraft:glowstone)
B(-5,59,-3,minecraft:blackstone)
B(-4,52,-6,minecraft:blackstone)
B(-4,53,-6,minecraft:blackstone)
B(-4,54,-6,minecraft:blackstone)
B(-4,55,-5,minecraft:blackstone)
B(-4,55,-3,minecraft:blackstone)
B(-4,52,-2,minecraft:blackstone)
B(-4,53,-2,minecraft:blackstone)
B(-4,54,-2,minecraft:blackstone)
B(-3,51,-5,minecraft:blackstone)
B(-3,48,-4,minecraft:glowstone)
B(-3,49,-4,minecraft:chain)
B(-3,50,-4,minecraft:glowstone)
B(-3,51,-3,minecraft:blackstone)
B(-3,129,-1,minecraft:netherrack)
B(-2,44,-6,minecraft:blackstone)
B(-2,45,-6,minecraft:blackstone)
B(-2,46,-6,minecraft:blackstone)
B(-2,47,-5,minecraft:blackstone)
B(-2,47,-3,minecraft:blackstone)
B(-2,129,-3,minecraft:netherrack)
B(-2,44,-2,minecraft:blackstone)
B(-2,45,-2,minecraft:blackstone)
B(-2,46,-2,minecraft:blackstone)
B(-2,129,-2,minecraft:netherrack)
B(-2,128,-1,minecraft:netherrack)
B(-2,129,-1,minecraft:netherrack)
B(-1,43,-5,minecraft:blackstone)
B(-1,129,-5,minecraft:netherrack)
B(-1,40,-4,minecraft:glowstone)
B(-1,41,-4,minecraft:chain)
B(-1,42,-4,minecraft:glowstone)
B(-1,129,-4,minecraft:netherrack)
B(-1,43,-3,minecraft:blackstone)
B(-1,129,-3,minecraft:netherrack)
B(-1,128,-2,minecraft:netherrack)
B(-1,129,-2,minecraft:netherrack)
B(-1,128,-1,minecraft:netherrack)
B(-1,129,-1,minecraft:netherrack)
B(0,129,-7,minecraft:netherrack)
B(0,36,-6,minecraft:blackstone)
B(0,37,-6,minecraft:blackstone)
B(0,38,-6,minecraft:blackstone)
B(0,129,-6,minecraft:netherrack)
B(0,39,-5,minecraft:blackstone)
B(0,129,-5,minecraft:netherrack)
B(0,128,-4,minecraft:netherrack)
B(0,129,-4,minecraft:netherrack)
B(0,39,-3,minecraft:blackstone)
B(0,128,-3,minecraft:netherrack)
B(0,129,-3,minecraft:netherrack)
B(0,36,-2,minecraft:blackstone)
B(0,37,-2,minecraft:blackstone)
B(0,38,-2,minecraft:blackstone)
B(0,127,-2,minecraft:netherrack)
B(0,128,-2,minecraft:netherrack)
B(0,129,-2,minecraft:netherrack)
B(0,127,-1,minecraft:netherrack)
B(0,128,-1,minecraft:netherrack)
B(0,129,-1,minecraft:netherrack)
B(1,129,-7,minecraft:netherrack)
B(1,129,-6,minecraft:netherrack)
B(1,35,-5,minecraft:blackstone)
B(1,128,-5,minecraft:netherrack)
B(1,129,-5,minecraft:netherrack)
B(1,32,-4,minecraft:glowstone)
B(1,33,-4,minecraft:chain)
B(1,34,-4,minecraft:glowstone)
B(1,128,-4,minecraft:netherrack)
B(1,129,-4,minecraft:netherrack)
B(1,35,-3,minecraft:blackstone)
B(1,128,-3,minecraft:netherrack)
B(1,129,-3,minecraft:netherrack)
B(1,127,-2,minecraft:netherrack)
B(1,128,-2,minecraft:netherrack)
B(1,129,-2,minecraft:netherrack)
B(1,126,-1,minecraft:netherrack)
B(1,127,-1,minecraft:netherrack)
B(1,128,-1,minecraft:netherrack)
B(1,129,-1,minecraft:netherrack)
B(2,128,-7,minecraft:netherrack)
B(2,129,-7,minecraft:netherrack)
B(2,28,-6,minecraft:blackstone)
B(2,29,-6,minecraft:blackstone)
B(2,30,-6,minecraft:blackstone)
B(2,128,-6,minecraft:netherrack)
B(2,129,-6,minecraft:netherrack)
B(2,31,-5,minecraft:blackstone)
B(2,127,-5,minecraft:netherrack)
B(2,128,-5,minecraft:netherrack)
B(2,129,-5,minecraft:netherrack)
B(2,127,-4,minecraft:netherrack)
B(2,128,-4,minecraft:netherrack)
B(2,129,-4,minecraft:netherrack)
B(2,31,-3,minecraft:blackstone)
B(2,126,-3,minecraft:netherrack)
B(2,127,-3,minecraft:netherrack)
B(2,128,-3,minecraft:netherrack)
B(2,129,-3,minecraft:netherrack)
B(2,28,-2,minecraft:blackstone)
B(2,29,-2,minecraft:blackstone)
B(2,30,-2,minecraft:blackstone)
B(2,125,-2,minecraft:netherrack)
B(2,126,-2,minecraft:netherrack)
B(2,127,-2,minecraft:netherrack)
B(2,128,-2,minecraft:netherrack)
B(2,129,-2,minecraft:netherrack)
B(2,124,-1,minecraft:netherrack)
B(2,125,-1,minecraft:netherrack)
B(2,126,-1,minecraft:netherrack)
B(2,127,-1,minecraft:netherrack)
B(2,128,-1,minecraft:netherrack)
B(2,129,-1,minecraft:netherrack)
B(3,128,-7,minecraft:netherrack)
B(3,129,-7,minecraft:netherrack)
B(3,127,-6,minecraft:netherrack)
B(3,128,-6,minecraft:netherrack)
B(3,129,-6,minecraft:netherrack)
B(3,27,-5,minecraft:blackstone)
B(3,126,-5,minecraft:netherrack)
B(3,127,-5,minecraft:netherrack)
B(3,128,-5,minecraft:netherrack)
B(3,129,-5,minecraft:netherrack)
B(3,24,-4,minecraft:glowstone)
B(3,25,-4,minecraft:chain)
B(3,26,-4,minecraft:glowstone)
B(3,126,-4,minecraft:netherrack)
B(3,127,-4,minecraft:netherrack)
B(3,128,-4,minecraft:netherrack)
B(3,129,-4,minecraft:netherrack)
B(3,27,-3,minecraft:blackstone)
B(3,125,-3,minecraft:netherrack)
B(3,126,-3,minecraft:netherrack)
B(3,127,-3,minecraft:netherrack)
B(3,128,-3,minecraft:netherrack)
B(3,129,-3,minecraft:netherrack)
B(3,124,-2,minecraft:netherrack)
B(3,125,-2,minecraft:netherrack)
B(3,126,-2,minecraft:netherrack)
B(3,127,-2,minecraft:netherrack)
B(3,128,-2,minecraft:netherrack)
B(3,129,-2,minecraft:netherrack)
B(3,123,-1,minecraft:netherrack)
B(3,124,-1,minecraft:netherrack)
B(3,125,-1,minecraft:netherrack)
B(3,126,-1,minecraft:netherrack)
B(3,127,-1,minecraft:netherrack)
B(3,128,-1,minecraft:netherrack)
B(3,129,-1,minecraft:netherrack)
B(4,127,-7,minecraft:netherrack)
B(4,128,-7,minecraft:netherrack)
B(4,129,-7,minecraft:netherrack)
B(4,20,-6,minecraft:blackstone)
B(4,21,-6,minecraft:blackstone)
B(4,22,-6,minecraft:blackstone)
B(4,126,-6,minecraft:netherrack)
B(4,127,-6,minecraft:netherrack)
B(4,128,-6,minecraft:netherrack)
B(4,129,-6,minecraft:netherrack)
B(4,23,-5,minecraft:blackstone)
B(4,125,-5,minecraft:netherrack)
B(4,126,-5,minecraft:netherrack)
B(4,127,-5,minecraft:netherrack)
B(4,128,-5,minecraft:netherrack)
B(4,129,-5,minecraft:netherrack)
B(4,125,-4,minecraft:netherrack)
B(4,126,-4,minecraft:netherrack)
B(4,127,-4,minecraft:netherrack)
B(4,128,-4,minecraft:netherrack)
B(4,129,-4,minecraft:netherrack)
B(4,23,-3,minecraft:blackstone)
B(4,124,-3,minecraft:netherrack)
B(4,125,-3,minecraft:netherrack)
B(4,126,-3,minecraft:netherrack)
B(4,127,-3,minecraft:netherrack)
B(4,128,-3,minecraft:netherrack)
B(4,129,-3,minecraft:netherrack)
B(4,20,-2,minecraft:blackstone)
B(4,21,-2,minecraft:blackstone)
B(4,22,-2,minecraft:blackstone)
B(4,122,-2,minecraft:netherrack)
B(4,123,-2,minecraft:netherrack)
B(4,124,-2,minecraft:netherrack)
B(4,125,-2,minecraft:netherrack)
B(4,126,-2,minecraft:netherrack)
B(4,127,-2,minecraft:netherrack)
B(4,128,-2,minecraft:netherrack)
B(4,129,-2,minecraft:netherrack)
B(4,121,-1,minecraft:netherrack)
B(4,122,-1,minecraft:netherrack)
B(4,123,-1,minecraft:netherrack)
B(4,124,-1,minecraft:netherrack)
B(4,125,-1,minecraft:netherrack)
B(4,126,-1,minecraft:netherrack)
B(4,127,-1,minecraft:netherrack)
B(4,128,-1,minecraft:netherrack)
B(4,129,-1,minecraft:netherrack)
B(5,127,-7,minecraft:netherrack)
B(5,128,-7,minecraft:netherrack)
B(5,129,-7,minecraft:netherrack)
B(5,126,-6,minecraft:netherrack)
B(5,127,-6,minecraft:netherrack)
B(5,128,-6,minecraft:netherrack)
B(5,129,-6,minecraft:netherrack)
B(5,19,-5,minecraft:blackstone)
B(5,125,-5,minecraft:netherrack)
B(5,126,-5,minecraft:netherrack)
B(5,127,-5,minecraft:netherrack)
B(5,128,-5,minecraft:netherrack)
B(5,129,-5,minecraft:netherrack)
B(5,16,-4,minecraft:glowstone)
B(5,17,-4,minecraft:chain)
B(5,18,-4,minecraft:glowstone)
B(5,123,-4,minecraft:netherrack)
B(5,124,-4,minecraft:netherrack)
B(5,125,-4,minecraft:netherrack)
B(5,126,-4,minecraft:netherrack)
B(5,127,-4,minecraft:netherrack)
B(5,128,-4,minecraft:netherrack)
B(5,129,-4,minecraft:netherrack)
B(5,19,-3,minecraft:blackstone)
B(5,122,-3,minecraft:netherrack)
B(5,123,-3,minecraft:netherrack)
B(5,124,-3,minecraft:netherrack)
B(5,125,-3,minecraft:netherrack)
B(5,126,-3,minecraft:netherrack)
B(5,127,-3,minecraft:netherrack)
B(5,128,-3,minecraft:netherrack)
B(5,129,-3,minecraft:netherrack)
B(5,121,-2,minecraft:netherrack)
B(5,122,-2,minecraft:netherrack)
B(5,123,-2,minecraft:netherrack)
B(5,124,-2,minecraft:netherrack)
B(5,125,-2,minecraft:netherrack)
B(5,126,-2,minecraft:netherrack)
B(5,127,-2,minecraft:netherrack)
B(5,128,-2,minecraft:netherrack)
B(5,129,-2,minecraft:netherrack)
B(5,119,-1,minecraft:netherrack)
B(5,120,-1,minecraft:netherrack)
B(5,121,-1,minecraft:netherrack)
B(5,122,-1,minecraft:netherrack)
B(5,123,-1,minecraft:netherrack)
B(5,124,-1,minecraft:netherrack)
B(5,125,-1,minecraft:netherrack)
B(5,126,-1,minecraft:netherrack)
B(5,127,-1,minecraft:netherrack)
B(5,128,-1,minecraft:netherrack)
B(5,129,-1,minecraft:netherrack)
B(6,126,-7,minecraft:netherrack)
B(6,127,-7,minecraft:netherrack)
B(6,128,-7,minecraft:netherrack)
B(6,129,-7,minecraft:netherrack)
B(6,12,-6,minecraft:blackstone)
B(6,13,-6,minecraft:blackstone)
B(6,14,-6,minecraft:blackstone)
B(6,125,-6,minecraft:netherrack)
B(6,126,-6,minecraft:netherrack)
B(6,127,-6,minecraft:netherrack)
B(6,128,-6,minecraft:netherrack)
B(6,129,-6,minecraft:netherrack)
B(6,15,-5,minecraft:blackstone)
B(6,124,-5,minecraft:netherrack)
B(6,125,-5,minecraft:netherrack)
B(6,126,-5,minecraft:netherrack)
B(6,127,-5,minecraft:netherrack)
B(6,128,-5,minecraft:netherrack)
B(6,129,-5,minecraft:netherrack)
B(6,123,-4,minecraft:netherrack)
B(6,124,-4,minecraft:netherrack)
B(6,125,-4,minecraft:netherrack)
B(6,126,-4,minecraft:netherrack)
B(6,127,-4,minecraft:netherrack)
B(6,128,-4,minecraft:netherrack)
B(6,129,-4,minecraft:netherrack)
B(6,15,-3,minecraft:blackstone)
B(6,122,-3,minecraft:netherrack)
B(6,123,-3,minecraft:netherrack)
B(6,124,-3,minecraft:netherrack)
B(6,125,-3,minecraft:netherrack)
B(6,126,-3,minecraft:netherrack)
B(6,127,-3,minecraft:netherrack)
B(6,128,-3,minecraft:netherrack)
B(6,129,-3,minecraft:netherrack)
B(6,12,-2,minecraft:blackstone)
B(6,13,-2,minecraft:blackstone)
B(6,14,-2,minecraft:blackstone)
B(6,120,-2,minecraft:netherrack)
B(6,121,-2,minecraft:netherrack)
B(6,122,-2,minecraft:netherrack)
B(6,123,-2,minecraft:netherrack)
B(6,124,-2,minecraft:netherrack)
B(6,125,-2,minecraft:netherrack)
B(6,126,-2,minecraft:netherrack)
B(6,127,-2,minecraft:netherrack)
B(6,128,-2,minecraft:netherrack)
B(6,129,-2,minecraft:netherrack)
B(6,118,-1,minecraft:netherrack)
B(6,119,-1,minecraft:netherrack)
B(6,120,-1,minecraft:netherrack)
B(6,121,-1,minecraft:netherrack)
B(6,122,-1,minecraft:netherrack)
B(6,123,-1,minecraft:netherrack)
B(6,124,-1,minecraft:netherrack)
B(6,125,-1,minecraft:netherrack)
B(6,126,-1,minecraft:netherrack)
B(6,127,-1,minecraft:netherrack)
B(6,128,-1,minecraft:netherrack)
B(6,129,-1,minecraft:netherrack)
B(7,125,-7,minecraft:netherrack)
B(7,126,-7,minecraft:netherrack)
B(7,127,-7,minecraft:netherrack)
B(7,128,-7,minecraft:netherrack)
B(7,129,-7,minecraft:netherrack)
B(7,124,-6,minecraft:netherrack)
B(7,125,-6,minecraft:netherrack)
B(7,126,-6,minecraft:netherrack)
B(7,127,-6,minecraft:netherrack)
B(7,128,-6,minecraft:netherrack)
B(7,129,-6,minecraft:netherrack)
B(7,11,-5,minecraft:blackstone)
B(7,123,-5,minecraft:netherrack)
B(7,124,-5,minecraft:netherrack)
B(7,125,-5,minecraft:netherrack)
B(7,126,-5,minecraft:netherrack)
B(7,127,-5,minecraft:netherrack)
B(7,128,-5,minecraft:netherrack)
B(7,129,-5,minecraft:netherrack)
B(7,8,-4,minecraft:glowstone)
B(7,9,-4,minecraft:chain)
B(7,10,-4,minecraft:glowstone)
B(7,122,-4,minecraft:netherrack)
B(7,123,-4,minecraft:netherrack)
B(7,124,-4,minecraft:netherrack)
B(7,125,-4,minecraft:netherrack)
B(7,126,-4,minecraft:netherrack)
B(7,127,-4,minecraft:netherrack)
B(7,128,-4,minecraft:netherrack)
B(7,129,-4,minecraft:netherrack)
B(7,11,-3,minecraft:blackstone)
B(7,121,-3,minecraft:netherrack)
B(7,122,-3,minecraft:netherrack)
B(7,123,-3,minecraft:netherrack)
B(7,124,-3,minecraft:netherrack)
B(7,125,-3,minecraft:netherrack)
B(7,126,-3,minecraft:netherrack)
B(7,127,-3,minecraft:netherrack)
B(7,128,-3,minecraft:netherrack)
B(7,129,-3,minecraft:netherrack)
B(7,119,-2,minecraft:netherrack)
B(7,120,-2,minecraft:netherrack)
B(7,121,-2,minecraft:netherrack)
B(7,122,-2,minecraft:netherrack)
B(7,123,-2,minecraft:netherrack)
B(7,124,-2,minecraft:netherrack)
B(7,125,-2,minecraft:netherrack)
B(7,126,-2,minecraft:netherrack)
B(7,127,-2,minecraft:netherrack)
B(7,128,-2,minecraft:netherrack)
B(7,129,-2,minecraft:netherrack)
B(7,117,-1,minecraft:netherrack)
B(7,118,-1,minecraft:netherrack)
B(7,119,-1,minecraft:netherrack)
B(7,120,-1,minecraft:netherrack)
B(7,121,-1,minecraft:netherrack)
B(7,122,-1,minecraft:netherrack)
B(7,123,-1,minecraft:netherrack)
B(7,124,-1,minecraft:netherrack)
B(7,125,-1,minecraft:netherrack)
B(7,126,-1,minecraft:netherrack)
B(7,127,-1,minecraft:netherrack)
B(7,128,-1,minecraft:netherrack)
B(7,129,-1,minecraft:netherrack)

#######################################################################
# +-----------------------------------------------------------------+ #
# |                             Branches                            | #
# +-----------------------------------------------------------------+ #
#######################################################################

Branch(16,0,0,true,BlackstoneChain2_C2_R0,NORTH,100.0,0)

#######################################################################
# +-----------------------------------------------------------------+ #
# |                             Entities                            | #
# +-----------------------------------------------------------------+ #
#######################################################################

