
#######################################################################
# +-----------------------------------------------------------------+ #
# |                            BO4 object                           | #
# +-----------------------------------------------------------------+ #
#######################################################################

Author: Unknown

Description: No description given

SettingsMode: WriteWithoutComments


#######################################################################
# +-----------------------------------------------------------------+ #
# |                          Main settings                          | #
# +-----------------------------------------------------------------+ #
#######################################################################

FixedRotation: 

Frequency: 0

SpawnHeight: highestBlock

UseCenterForHighestBlock: true

##############################
# Height Limits for the BO4. #
##############################

MinHeight: 0

MaxHeight: 255

InheritBO3: 

InheritBO3Rotation: NORTH

OverrideChildSettings: true

OverrideParentHeight: false

CanOverride: false

BranchFrequency: 0

BranchFrequencyGroup: 

MustBeBelowOther: false

MustBeInside: 

CannotBeInside: 

ReplacesBO3: 

MustBeInsideWorldBorders: false

CanSpawnOnWater: true

SpawnOnWaterOnly: false

SpawnUnderWater: false

SpawnAtWaterLevel: false

HeightOffset: 0

RemoveAir: true

ReplaceAbove: 

ReplaceBelow: 

ReplaceWithBiomeBlocks: true

ReplaceWithSurfaceBlock: GRASS

ReplaceWithGroundBlock: DIRT

ReplaceWithStoneBlock: STONE

SmoothRadius: 0

SmoothHeightOffset: 0

SmoothStartTop: false

SmoothStartWood: false

SmoothingSurfaceBlock: 

SmoothingGroundBlock: 

BO3Group: 

IsSpawnPoint: false

DoReplaceBlocks: true


#######################################################################
# +-----------------------------------------------------------------+ #
# |                              Blocks                             | #
# +-----------------------------------------------------------------+ #
#######################################################################

B(3,17,3,minecraft:warped_hyphae)
B(3,18,3,minecraft:warped_hyphae)
B(3,19,3,minecraft:warped_hyphae)
B(3,16,4,minecraft:warped_hyphae)
B(3,17,4,minecraft:warped_hyphae)
B(3,18,4,minecraft:warped_hyphae)
B(3,19,4,minecraft:warped_hyphae)
B(3,20,4,minecraft:warped_hyphae)
B(3,16,5,minecraft:warped_hyphae)
B(3,17,5,minecraft:warped_hyphae)
B(3,18,5,minecraft:warped_hyphae)
B(3,19,5,minecraft:warped_hyphae)
B(3,20,5,minecraft:warped_hyphae)
B(3,16,6,minecraft:warped_hyphae)
B(3,17,6,minecraft:warped_hyphae)
B(3,18,6,minecraft:warped_hyphae)
B(3,19,6,minecraft:warped_hyphae)
B(3,20,6,minecraft:warped_hyphae)
B(3,17,7,minecraft:warped_hyphae)
B(3,18,7,minecraft:warped_hyphae)
B(3,19,7,minecraft:warped_hyphae)
B(4,16,2,minecraft:warped_hyphae)
B(4,17,2,minecraft:warped_hyphae)
B(4,18,2,minecraft:warped_hyphae)
B(4,19,2,minecraft:warped_hyphae)
B(4,20,2,minecraft:warped_hyphae)
B(4,15,3,minecraft:warped_hyphae)
B(4,16,3,minecraft:warped_hyphae)
B(4,17,3,minecraft:warped_hyphae)
B(4,18,3,minecraft:warped_hyphae)
B(4,19,3,minecraft:warped_hyphae)
B(4,20,3,minecraft:warped_hyphae)
B(4,21,3,minecraft:warped_hyphae)
B(4,15,4,minecraft:warped_hyphae)
B(4,16,4,minecraft:warped_hyphae)
B(4,17,4,minecraft:warped_hyphae)
B(4,18,4,minecraft:warped_hyphae)
B(4,19,4,minecraft:warped_hyphae)
B(4,20,4,minecraft:warped_hyphae)
B(4,21,4,minecraft:warped_hyphae)
B(4,15,5,minecraft:warped_hyphae)
B(4,16,5,minecraft:warped_hyphae)
B(4,17,5,minecraft:warped_hyphae)
B(4,18,5,minecraft:warped_hyphae)
B(4,19,5,minecraft:warped_hyphae)
B(4,20,5,minecraft:warped_hyphae)
B(4,21,5,minecraft:warped_hyphae)
B(4,15,6,minecraft:warped_hyphae)
B(4,16,6,minecraft:warped_hyphae)
B(4,17,6,minecraft:warped_hyphae)
B(4,18,6,minecraft:warped_hyphae)
B(4,19,6,minecraft:warped_hyphae)
B(4,20,6,minecraft:warped_hyphae)
B(4,21,6,minecraft:warped_hyphae)
B(4,15,7,minecraft:warped_hyphae)
B(4,16,7,minecraft:warped_hyphae)
B(4,17,7,minecraft:warped_hyphae)
B(4,18,7,minecraft:warped_hyphae)
B(4,19,7,minecraft:warped_hyphae)
B(4,20,7,minecraft:warped_hyphae)
B(4,21,7,minecraft:warped_hyphae)
B(4,16,8,minecraft:warped_hyphae)
B(4,17,8,minecraft:warped_hyphae)
B(4,18,8,minecraft:warped_hyphae)
B(4,19,8,minecraft:warped_hyphae)
B(4,20,8,minecraft:warped_hyphae)
B(5,16,1,minecraft:warped_hyphae)
B(5,17,1,minecraft:warped_hyphae)
B(5,18,1,minecraft:warped_hyphae)
B(5,19,1,minecraft:warped_hyphae)
B(5,20,1,minecraft:warped_hyphae)
B(5,15,2,minecraft:warped_hyphae)
B(5,16,2,minecraft:warped_hyphae)
B(5,17,2,minecraft:warped_hyphae)
B(5,18,2,minecraft:warped_hyphae)
B(5,19,2,minecraft:warped_hyphae)
B(5,20,2,minecraft:warped_hyphae)
B(5,21,2,minecraft:warped_hyphae)
B(5,14,3,minecraft:warped_hyphae)
B(5,15,3,minecraft:warped_hyphae)
B(5,16,3,minecraft:warped_hyphae)
B(5,17,3,minecraft:warped_hyphae)
B(5,18,3,minecraft:warped_hyphae)
B(5,19,3,minecraft:warped_hyphae)
B(5,20,3,minecraft:warped_hyphae)
B(5,21,3,minecraft:warped_hyphae)
B(5,22,3,minecraft:warped_hyphae)
B(5,14,4,minecraft:warped_hyphae)
B(5,15,4,minecraft:warped_hyphae)
B(5,16,4,minecraft:warped_hyphae)
B(5,17,4,minecraft:warped_hyphae)
B(5,18,4,minecraft:warped_hyphae)
B(5,19,4,minecraft:warped_hyphae)
B(5,20,4,minecraft:warped_hyphae)
B(5,21,4,minecraft:warped_hyphae)
B(5,22,4,minecraft:warped_hyphae)
B(5,14,5,minecraft:warped_hyphae)
B(5,15,5,minecraft:warped_hyphae)
B(5,16,5,minecraft:warped_hyphae)
B(5,17,5,minecraft:warped_hyphae)
B(5,18,5,minecraft:warped_hyphae)
B(5,19,5,minecraft:warped_hyphae)
B(5,20,5,minecraft:warped_hyphae)
B(5,21,5,minecraft:warped_hyphae)
B(5,22,5,minecraft:warped_hyphae)
B(5,14,6,minecraft:warped_hyphae)
B(5,15,6,minecraft:warped_hyphae)
B(5,16,6,minecraft:warped_hyphae)
B(5,17,6,minecraft:warped_hyphae)
B(5,18,6,minecraft:warped_hyphae)
B(5,19,6,minecraft:warped_hyphae)
B(5,20,6,minecraft:warped_hyphae)
B(5,21,6,minecraft:warped_hyphae)
B(5,22,6,minecraft:warped_hyphae)
B(5,14,7,minecraft:warped_hyphae)
B(5,15,7,minecraft:warped_hyphae)
B(5,16,7,minecraft:warped_hyphae)
B(5,17,7,minecraft:warped_hyphae)
B(5,18,7,minecraft:warped_hyphae)
B(5,19,7,minecraft:warped_hyphae)
B(5,20,7,minecraft:warped_hyphae)
B(5,21,7,minecraft:warped_hyphae)
B(5,22,7,minecraft:warped_hyphae)
B(5,15,8,minecraft:warped_hyphae)
B(5,16,8,minecraft:warped_hyphae)
B(5,17,8,minecraft:warped_hyphae)
B(5,18,8,minecraft:warped_hyphae)
B(5,19,8,minecraft:warped_hyphae)
B(5,20,8,minecraft:warped_hyphae)
B(5,21,8,minecraft:warped_hyphae)
B(6,17,0,minecraft:warped_hyphae)
B(6,18,0,minecraft:warped_hyphae)
B(6,19,0,minecraft:warped_hyphae)
B(6,20,0,minecraft:warped_hyphae)
B(6,21,0,minecraft:warped_hyphae)
B(6,22,0,minecraft:warped_hyphae)
B(6,15,1,minecraft:warped_hyphae)
B(6,16,1,minecraft:warped_hyphae)
B(6,17,1,minecraft:warped_hyphae)
B(6,18,1,minecraft:warped_hyphae)
B(6,19,1,minecraft:warped_hyphae)
B(6,20,1,minecraft:warped_hyphae)
B(6,21,1,minecraft:warped_hyphae)
B(6,22,1,minecraft:warped_hyphae)
B(6,23,1,minecraft:warped_hyphae)
B(6,14,2,minecraft:warped_hyphae)
B(6,15,2,minecraft:warped_hyphae)
B(6,16,2,minecraft:warped_hyphae)
B(6,17,2,minecraft:warped_hyphae)
B(6,18,2,minecraft:warped_hyphae)
B(6,19,2,minecraft:warped_hyphae)
B(6,20,2,minecraft:warped_hyphae)
B(6,21,2,minecraft:warped_hyphae)
B(6,22,2,minecraft:warped_hyphae)
B(6,23,2,minecraft:warped_hyphae)
B(6,14,3,minecraft:warped_hyphae)
B(6,15,3,minecraft:warped_hyphae)
B(6,16,3,minecraft:warped_hyphae)
B(6,17,3,minecraft:warped_hyphae)
B(6,18,3,minecraft:warped_hyphae)
B(6,19,3,minecraft:warped_hyphae)
B(6,20,3,minecraft:warped_hyphae)
B(6,21,3,minecraft:warped_hyphae)
B(6,22,3,minecraft:warped_hyphae)
B(6,23,3,minecraft:warped_hyphae)
B(6,13,4,minecraft:warped_hyphae)
B(6,14,4,minecraft:warped_hyphae)
B(6,15,4,minecraft:warped_hyphae)
B(6,16,4,minecraft:warped_hyphae)
B(6,17,4,minecraft:warped_hyphae)
B(6,18,4,minecraft:warped_hyphae)
B(6,19,4,minecraft:warped_hyphae)
B(6,20,4,minecraft:warped_hyphae)
B(6,21,4,minecraft:warped_hyphae)
B(6,22,4,minecraft:warped_hyphae)
B(6,23,4,minecraft:warped_hyphae)
B(6,13,5,minecraft:warped_hyphae)
B(6,14,5,minecraft:warped_hyphae)
B(6,15,5,minecraft:warped_hyphae)
B(6,16,5,minecraft:warped_hyphae)
B(6,17,5,minecraft:warped_hyphae)
B(6,18,5,minecraft:warped_hyphae)
B(6,19,5,minecraft:warped_hyphae)
B(6,20,5,minecraft:warped_hyphae)
B(6,21,5,minecraft:warped_hyphae)
B(6,22,5,minecraft:warped_hyphae)
B(6,23,5,minecraft:warped_hyphae)
B(6,13,6,minecraft:warped_hyphae)
B(6,14,6,minecraft:warped_hyphae)
B(6,15,6,minecraft:warped_hyphae)
B(6,16,6,minecraft:warped_hyphae)
B(6,17,6,minecraft:warped_hyphae)
B(6,18,6,minecraft:warped_hyphae)
B(6,19,6,minecraft:warped_hyphae)
B(6,20,6,minecraft:warped_hyphae)
B(6,21,6,minecraft:warped_hyphae)
B(6,22,6,minecraft:warped_hyphae)
B(6,23,6,minecraft:warped_hyphae)
B(6,14,7,minecraft:warped_hyphae)
B(6,15,7,minecraft:warped_hyphae)
B(6,16,7,minecraft:warped_hyphae)
B(6,17,7,minecraft:warped_hyphae)
B(6,18,7,minecraft:warped_hyphae)
B(6,19,7,minecraft:warped_hyphae)
B(6,20,7,minecraft:warped_hyphae)
B(6,21,7,minecraft:warped_hyphae)
B(6,22,7,minecraft:warped_hyphae)
B(6,14,8,minecraft:warped_hyphae)
B(6,15,8,minecraft:warped_hyphae)
B(6,16,8,minecraft:warped_hyphae)
B(6,17,8,minecraft:warped_hyphae)
B(6,18,8,minecraft:warped_hyphae)
B(6,19,8,minecraft:warped_hyphae)
B(6,20,8,minecraft:warped_hyphae)
B(6,21,8,minecraft:warped_hyphae)
B(6,22,8,minecraft:warped_hyphae)
B(7,19,-1,minecraft:warped_hyphae)
B(7,20,-1,minecraft:warped_hyphae)
B(7,21,-1,minecraft:warped_hyphae)
B(7,22,-1,minecraft:warped_hyphae)
B(7,23,-1,minecraft:warped_hyphae)
B(7,16,0,minecraft:warped_hyphae)
B(7,17,0,minecraft:warped_hyphae)
B(7,18,0,minecraft:warped_hyphae)
B(7,19,0,minecraft:warped_hyphae)
B(7,20,0,minecraft:warped_hyphae)
B(7,21,0,minecraft:warped_hyphae)
B(7,22,0,minecraft:warped_hyphae)
B(7,23,0,minecraft:warped_hyphae)
B(7,24,0,minecraft:warped_hyphae)
B(7,15,1,minecraft:warped_hyphae)
B(7,16,1,minecraft:warped_hyphae)
B(7,17,1,minecraft:warped_hyphae)
B(7,18,1,minecraft:warped_hyphae)
B(7,19,1,minecraft:warped_hyphae)
B(7,20,1,minecraft:warped_hyphae)
B(7,21,1,minecraft:warped_hyphae)
B(7,22,1,minecraft:warped_hyphae)
B(7,23,1,minecraft:warped_hyphae)
B(7,24,1,minecraft:warped_hyphae)
B(7,14,2,minecraft:warped_hyphae)
B(7,15,2,minecraft:warped_hyphae)
B(7,16,2,minecraft:warped_hyphae)
B(7,17,2,minecraft:warped_hyphae)
B(7,18,2,minecraft:warped_hyphae)
B(7,19,2,minecraft:warped_hyphae)
B(7,20,2,minecraft:warped_hyphae)
B(7,21,2,minecraft:warped_hyphae)
B(7,22,2,minecraft:warped_hyphae)
B(7,23,2,minecraft:warped_hyphae)
B(7,24,2,minecraft:warped_hyphae)
B(7,13,3,minecraft:warped_hyphae)
B(7,14,3,minecraft:warped_hyphae)
B(7,15,3,minecraft:warped_hyphae)
B(7,16,3,minecraft:warped_hyphae)
B(7,17,3,minecraft:warped_hyphae)
B(7,18,3,minecraft:warped_hyphae)
B(7,19,3,minecraft:warped_hyphae)
B(7,20,3,minecraft:warped_hyphae)
B(7,21,3,minecraft:warped_hyphae)
B(7,22,3,minecraft:warped_hyphae)
B(7,23,3,minecraft:warped_hyphae)
B(7,24,3,minecraft:warped_hyphae)
B(7,13,4,minecraft:warped_hyphae)
B(7,14,4,minecraft:warped_hyphae)
B(7,15,4,minecraft:warped_hyphae)
B(7,16,4,minecraft:warped_hyphae)
B(7,17,4,minecraft:warped_hyphae)
B(7,18,4,minecraft:warped_hyphae)
B(7,19,4,minecraft:warped_hyphae)
B(7,20,4,minecraft:warped_hyphae)
B(7,21,4,minecraft:warped_hyphae)
B(7,22,4,minecraft:warped_hyphae)
B(7,23,4,minecraft:warped_hyphae)
B(7,24,4,minecraft:warped_hyphae)
B(7,13,5,minecraft:warped_hyphae)
B(7,14,5,minecraft:warped_hyphae)
B(7,15,5,minecraft:warped_hyphae)
B(7,16,5,minecraft:warped_hyphae)
B(7,17,5,minecraft:warped_hyphae)
B(7,18,5,minecraft:warped_hyphae)
B(7,19,5,minecraft:warped_hyphae)
B(7,20,5,minecraft:warped_hyphae)
B(7,21,5,minecraft:warped_hyphae)
B(7,22,5,minecraft:warped_hyphae)
B(7,23,5,minecraft:warped_hyphae)
B(7,13,6,minecraft:warped_hyphae)
B(7,14,6,minecraft:warped_hyphae)
B(7,15,6,minecraft:warped_hyphae)
B(7,16,6,minecraft:warped_hyphae)
B(7,17,6,minecraft:warped_hyphae)
B(7,18,6,minecraft:warped_hyphae)
B(7,19,6,minecraft:warped_hyphae)
B(7,20,6,minecraft:warped_hyphae)
B(7,21,6,minecraft:warped_hyphae)
B(7,22,6,minecraft:warped_hyphae)
B(7,23,6,minecraft:warped_hyphae)
B(7,13,7,minecraft:warped_hyphae)
B(7,14,7,minecraft:warped_hyphae)
B(7,15,7,minecraft:warped_hyphae)
B(7,16,7,minecraft:warped_hyphae)
B(7,17,7,minecraft:warped_hyphae)
B(7,18,7,minecraft:warped_hyphae)
B(7,19,7,minecraft:warped_hyphae)
B(7,20,7,minecraft:warped_hyphae)
B(7,21,7,minecraft:warped_hyphae)
B(7,22,7,minecraft:warped_hyphae)
B(7,23,7,minecraft:warped_hyphae)
B(7,14,8,minecraft:warped_hyphae)
B(7,15,8,minecraft:warped_hyphae)
B(7,16,8,minecraft:warped_hyphae)
B(7,17,8,minecraft:warped_hyphae)
B(7,18,8,minecraft:warped_hyphae)
B(7,19,8,minecraft:warped_hyphae)
B(7,20,8,minecraft:warped_hyphae)
B(7,21,8,minecraft:warped_hyphae)
B(7,22,8,minecraft:warped_hyphae)

#######################################################################
# +-----------------------------------------------------------------+ #
# |                             Branches                            | #
# +-----------------------------------------------------------------+ #
#######################################################################

Branch(16,0,0,true,WarpedBeanstalk2_C1_R2,NORTH,100.0,0)
Branch(0,0,16,true,WarpedBeanstalk2_C0_R3,NORTH,100.0,0)

#######################################################################
# +-----------------------------------------------------------------+ #
# |                             Entities                            | #
# +-----------------------------------------------------------------+ #
#######################################################################

