
#######################################################################
# +-----------------------------------------------------------------+ #
# |                            BO4 object                           | #
# +-----------------------------------------------------------------+ #
#######################################################################

Author: Unknown

Description: No description given

SettingsMode: WriteWithoutComments


#######################################################################
# +-----------------------------------------------------------------+ #
# |                          Main settings                          | #
# +-----------------------------------------------------------------+ #
#######################################################################

FixedRotation: 

Frequency: 0

SpawnHeight: highestBlock

UseCenterForHighestBlock: true

##############################
# Height Limits for the BO4. #
##############################

MinHeight: 0

MaxHeight: 255

InheritBO3: 

InheritBO3Rotation: NORTH

OverrideChildSettings: true

OverrideParentHeight: false

CanOverride: false

BranchFrequency: 0

BranchFrequencyGroup: 

MustBeBelowOther: false

MustBeInside: 

CannotBeInside: 

ReplacesBO3: 

MustBeInsideWorldBorders: false

CanSpawnOnWater: true

SpawnOnWaterOnly: false

SpawnUnderWater: false

SpawnAtWaterLevel: false

HeightOffset: 0

RemoveAir: true

ReplaceAbove: 

ReplaceBelow: 

ReplaceWithBiomeBlocks: true

ReplaceWithSurfaceBlock: GRASS

ReplaceWithGroundBlock: DIRT

ReplaceWithStoneBlock: STONE

SmoothRadius: 0

SmoothHeightOffset: 0

SmoothStartTop: false

SmoothStartWood: false

SmoothingSurfaceBlock: 

SmoothingGroundBlock: 

BO3Group: 

IsSpawnPoint: false

DoReplaceBlocks: true


#######################################################################
# +-----------------------------------------------------------------+ #
# |                              Blocks                             | #
# +-----------------------------------------------------------------+ #
#######################################################################

B(-8,19,-2,minecraft:warped_hyphae)
B(-8,20,-2,minecraft:warped_hyphae)
B(-8,21,-2,minecraft:warped_hyphae)
B(-8,22,-2,minecraft:warped_hyphae)
B(-8,23,-2,minecraft:warped_hyphae)
B(-8,18,-1,minecraft:warped_hyphae)
B(-8,19,-1,minecraft:warped_hyphae)
B(-8,20,-1,minecraft:warped_hyphae)
B(-8,21,-1,minecraft:warped_hyphae)
B(-8,22,-1,minecraft:warped_hyphae)
B(-8,23,-1,minecraft:warped_hyphae)
B(-8,24,-1,minecraft:warped_hyphae)
B(-8,16,0,minecraft:warped_hyphae)
B(-8,17,0,minecraft:warped_hyphae)
B(-8,18,0,minecraft:warped_hyphae)
B(-8,19,0,minecraft:warped_hyphae)
B(-8,20,0,minecraft:warped_hyphae)
B(-8,21,0,minecraft:warped_hyphae)
B(-8,22,0,minecraft:warped_hyphae)
B(-8,23,0,minecraft:warped_hyphae)
B(-8,24,0,minecraft:warped_hyphae)
B(-8,25,0,minecraft:warped_hyphae)
B(-8,15,1,minecraft:warped_hyphae)
B(-8,16,1,minecraft:warped_hyphae)
B(-8,17,1,minecraft:warped_hyphae)
B(-8,18,1,minecraft:warped_hyphae)
B(-8,19,1,minecraft:warped_hyphae)
B(-8,20,1,minecraft:warped_hyphae)
B(-8,21,1,minecraft:warped_hyphae)
B(-8,22,1,minecraft:warped_hyphae)
B(-8,23,1,minecraft:warped_hyphae)
B(-8,24,1,minecraft:warped_hyphae)
B(-8,25,1,minecraft:warped_hyphae)
B(-8,14,2,minecraft:warped_hyphae)
B(-8,15,2,minecraft:warped_hyphae)
B(-8,16,2,minecraft:warped_hyphae)
B(-8,17,2,minecraft:warped_hyphae)
B(-8,18,2,minecraft:warped_hyphae)
B(-8,19,2,minecraft:warped_hyphae)
B(-8,20,2,minecraft:warped_hyphae)
B(-8,21,2,minecraft:warped_hyphae)
B(-8,22,2,minecraft:warped_hyphae)
B(-8,23,2,minecraft:warped_hyphae)
B(-8,24,2,minecraft:warped_hyphae)
B(-8,25,2,minecraft:warped_hyphae)
B(-8,13,3,minecraft:warped_hyphae)
B(-8,14,3,minecraft:warped_hyphae)
B(-8,15,3,minecraft:warped_hyphae)
B(-8,16,3,minecraft:warped_hyphae)
B(-8,17,3,minecraft:warped_hyphae)
B(-8,18,3,minecraft:warped_hyphae)
B(-8,19,3,minecraft:warped_hyphae)
B(-8,20,3,minecraft:warped_hyphae)
B(-8,21,3,minecraft:warped_hyphae)
B(-8,22,3,minecraft:warped_hyphae)
B(-8,23,3,minecraft:warped_hyphae)
B(-8,24,3,minecraft:warped_hyphae)
B(-8,25,3,minecraft:warped_hyphae)
B(-8,13,4,minecraft:warped_hyphae)
B(-8,14,4,minecraft:warped_hyphae)
B(-8,15,4,minecraft:warped_hyphae)
B(-8,16,4,minecraft:warped_hyphae)
B(-8,17,4,minecraft:warped_hyphae)
B(-8,18,4,minecraft:warped_hyphae)
B(-8,19,4,minecraft:warped_hyphae)
B(-8,20,4,minecraft:warped_hyphae)
B(-8,21,4,minecraft:warped_hyphae)
B(-8,22,4,minecraft:warped_hyphae)
B(-8,23,4,minecraft:warped_hyphae)
B(-8,24,4,minecraft:warped_hyphae)
B(-8,25,4,minecraft:warped_hyphae)
B(-8,13,5,minecraft:warped_hyphae)
B(-8,14,5,minecraft:warped_hyphae)
B(-8,15,5,minecraft:warped_hyphae)
B(-8,16,5,minecraft:warped_hyphae)
B(-8,17,5,minecraft:warped_hyphae)
B(-8,18,5,minecraft:warped_hyphae)
B(-8,19,5,minecraft:warped_hyphae)
B(-8,20,5,minecraft:warped_hyphae)
B(-8,21,5,minecraft:warped_hyphae)
B(-8,22,5,minecraft:warped_hyphae)
B(-8,23,5,minecraft:warped_hyphae)
B(-8,24,5,minecraft:warped_hyphae)
B(-8,13,6,minecraft:warped_hyphae)
B(-8,14,6,minecraft:warped_hyphae)
B(-8,15,6,minecraft:warped_hyphae)
B(-8,16,6,minecraft:warped_hyphae)
B(-8,17,6,minecraft:warped_hyphae)
B(-8,18,6,minecraft:warped_hyphae)
B(-8,19,6,minecraft:warped_hyphae)
B(-8,20,6,minecraft:warped_hyphae)
B(-8,21,6,minecraft:warped_hyphae)
B(-8,22,6,minecraft:warped_hyphae)
B(-8,23,6,minecraft:warped_hyphae)
B(-8,13,7,minecraft:warped_hyphae)
B(-8,14,7,minecraft:warped_hyphae)
B(-8,15,7,minecraft:warped_hyphae)
B(-8,16,7,minecraft:warped_hyphae)
B(-8,17,7,minecraft:warped_hyphae)
B(-8,18,7,minecraft:warped_hyphae)
B(-8,19,7,minecraft:warped_hyphae)
B(-8,20,7,minecraft:warped_hyphae)
B(-8,21,7,minecraft:warped_hyphae)
B(-8,22,7,minecraft:warped_hyphae)
B(-8,23,7,minecraft:warped_hyphae)
B(-8,14,8,minecraft:warped_hyphae)
B(-8,15,8,minecraft:warped_hyphae)
B(-8,16,8,minecraft:warped_hyphae)
B(-8,17,8,minecraft:warped_hyphae)
B(-8,18,8,minecraft:warped_hyphae)
B(-8,19,8,minecraft:warped_hyphae)
B(-8,20,8,minecraft:warped_hyphae)
B(-8,21,8,minecraft:warped_hyphae)
B(-8,22,8,minecraft:warped_hyphae)
B(-7,73,-7,minecraft:warped_hyphae)
B(-7,74,-7,minecraft:warped_hyphae)
B(-7,75,-7,minecraft:warped_hyphae)
B(-7,76,-7,minecraft:warped_hyphae)
B(-7,77,-7,minecraft:warped_hyphae)
B(-7,73,-6,minecraft:warped_hyphae)
B(-7,74,-6,minecraft:warped_hyphae)
B(-7,75,-6,minecraft:warped_hyphae)
B(-7,76,-6,minecraft:warped_hyphae)
B(-7,77,-6,minecraft:warped_hyphae)
B(-7,73,-5,minecraft:warped_hyphae)
B(-7,74,-5,minecraft:warped_hyphae)
B(-7,75,-5,minecraft:warped_hyphae)
B(-7,76,-5,minecraft:warped_hyphae)
B(-7,77,-5,minecraft:warped_hyphae)
B(-7,74,-4,minecraft:warped_hyphae)
B(-7,75,-4,minecraft:warped_hyphae)
B(-7,76,-4,minecraft:warped_hyphae)
B(-7,20,-3,minecraft:warped_hyphae)
B(-7,21,-3,minecraft:warped_hyphae)
B(-7,22,-3,minecraft:warped_hyphae)
B(-7,18,-2,minecraft:warped_hyphae)
B(-7,19,-2,minecraft:warped_hyphae)
B(-7,20,-2,minecraft:warped_hyphae)
B(-7,21,-2,minecraft:warped_hyphae)
B(-7,22,-2,minecraft:warped_hyphae)
B(-7,23,-2,minecraft:warped_hyphae)
B(-7,24,-2,minecraft:warped_hyphae)
B(-7,25,-2,minecraft:warped_hyphae)
B(-7,26,-2,minecraft:warped_hyphae)
B(-7,17,-1,minecraft:warped_hyphae)
B(-7,18,-1,minecraft:warped_hyphae)
B(-7,19,-1,minecraft:warped_hyphae)
B(-7,20,-1,minecraft:warped_hyphae)
B(-7,21,-1,minecraft:warped_hyphae)
B(-7,22,-1,minecraft:warped_hyphae)
B(-7,23,-1,minecraft:warped_hyphae)
B(-7,24,-1,minecraft:warped_hyphae)
B(-7,25,-1,minecraft:warped_hyphae)
B(-7,26,-1,minecraft:warped_hyphae)
B(-7,27,-1,minecraft:warped_hyphae)
B(-7,16,0,minecraft:warped_hyphae)
B(-7,17,0,minecraft:warped_hyphae)
B(-7,18,0,minecraft:warped_hyphae)
B(-7,19,0,minecraft:warped_hyphae)
B(-7,20,0,minecraft:warped_hyphae)
B(-7,21,0,minecraft:warped_hyphae)
B(-7,22,0,minecraft:warped_hyphae)
B(-7,23,0,minecraft:warped_hyphae)
B(-7,24,0,minecraft:warped_hyphae)
B(-7,25,0,minecraft:warped_hyphae)
B(-7,26,0,minecraft:warped_hyphae)
B(-7,27,0,minecraft:warped_hyphae)
B(-7,15,1,minecraft:warped_hyphae)
B(-7,16,1,minecraft:warped_hyphae)
B(-7,17,1,minecraft:warped_hyphae)
B(-7,18,1,minecraft:warped_hyphae)
B(-7,19,1,minecraft:warped_hyphae)
B(-7,20,1,minecraft:warped_hyphae)
B(-7,21,1,minecraft:warped_hyphae)
B(-7,22,1,minecraft:warped_hyphae)
B(-7,23,1,minecraft:warped_hyphae)
B(-7,24,1,minecraft:warped_hyphae)
B(-7,25,1,minecraft:warped_hyphae)
B(-7,26,1,minecraft:warped_hyphae)
B(-7,27,1,minecraft:warped_hyphae)
B(-7,14,2,minecraft:warped_hyphae)
B(-7,15,2,minecraft:warped_hyphae)
B(-7,16,2,minecraft:warped_hyphae)
B(-7,17,2,minecraft:warped_hyphae)
B(-7,18,2,minecraft:warped_hyphae)
B(-7,19,2,minecraft:warped_hyphae)
B(-7,20,2,minecraft:warped_hyphae)
B(-7,21,2,minecraft:warped_hyphae)
B(-7,22,2,minecraft:warped_hyphae)
B(-7,23,2,minecraft:warped_hyphae)
B(-7,24,2,minecraft:warped_hyphae)
B(-7,25,2,minecraft:warped_hyphae)
B(-7,26,2,minecraft:warped_hyphae)
B(-7,13,3,minecraft:warped_hyphae)
B(-7,14,3,minecraft:warped_hyphae)
B(-7,15,3,minecraft:warped_hyphae)
B(-7,16,3,minecraft:warped_hyphae)
B(-7,17,3,minecraft:warped_hyphae)
B(-7,18,3,minecraft:warped_hyphae)
B(-7,19,3,minecraft:warped_hyphae)
B(-7,20,3,minecraft:warped_hyphae)
B(-7,21,3,minecraft:warped_hyphae)
B(-7,22,3,minecraft:warped_hyphae)
B(-7,23,3,minecraft:warped_hyphae)
B(-7,24,3,minecraft:warped_hyphae)
B(-7,25,3,minecraft:warped_hyphae)
B(-7,26,3,minecraft:warped_hyphae)
B(-7,13,4,minecraft:warped_hyphae)
B(-7,14,4,minecraft:warped_hyphae)
B(-7,15,4,minecraft:warped_hyphae)
B(-7,16,4,minecraft:warped_hyphae)
B(-7,17,4,minecraft:warped_hyphae)
B(-7,18,4,minecraft:warped_hyphae)
B(-7,19,4,minecraft:warped_hyphae)
B(-7,20,4,minecraft:warped_hyphae)
B(-7,21,4,minecraft:warped_hyphae)
B(-7,22,4,minecraft:warped_hyphae)
B(-7,23,4,minecraft:warped_hyphae)
B(-7,24,4,minecraft:warped_hyphae)
B(-7,25,4,minecraft:warped_hyphae)
B(-7,13,5,minecraft:warped_hyphae)
B(-7,14,5,minecraft:warped_hyphae)
B(-7,15,5,minecraft:warped_hyphae)
B(-7,16,5,minecraft:warped_hyphae)
B(-7,17,5,minecraft:warped_hyphae)
B(-7,18,5,minecraft:warped_hyphae)
B(-7,19,5,minecraft:warped_hyphae)
B(-7,20,5,minecraft:warped_hyphae)
B(-7,21,5,minecraft:warped_hyphae)
B(-7,22,5,minecraft:warped_hyphae)
B(-7,23,5,minecraft:warped_hyphae)
B(-7,24,5,minecraft:warped_hyphae)
B(-7,25,5,minecraft:warped_hyphae)
B(-7,13,6,minecraft:warped_hyphae)
B(-7,14,6,minecraft:warped_hyphae)
B(-7,15,6,minecraft:warped_hyphae)
B(-7,16,6,minecraft:warped_hyphae)
B(-7,17,6,minecraft:warped_hyphae)
B(-7,18,6,minecraft:warped_hyphae)
B(-7,19,6,minecraft:warped_hyphae)
B(-7,20,6,minecraft:warped_hyphae)
B(-7,21,6,minecraft:warped_hyphae)
B(-7,22,6,minecraft:warped_hyphae)
B(-7,23,6,minecraft:warped_hyphae)
B(-7,24,6,minecraft:warped_hyphae)
B(-7,13,7,minecraft:warped_hyphae)
B(-7,14,7,minecraft:warped_hyphae)
B(-7,15,7,minecraft:warped_hyphae)
B(-7,16,7,minecraft:warped_hyphae)
B(-7,17,7,minecraft:warped_hyphae)
B(-7,18,7,minecraft:warped_hyphae)
B(-7,19,7,minecraft:warped_hyphae)
B(-7,20,7,minecraft:warped_hyphae)
B(-7,21,7,minecraft:warped_hyphae)
B(-7,22,7,minecraft:warped_hyphae)
B(-7,23,7,minecraft:warped_hyphae)
B(-7,14,8,minecraft:warped_hyphae)
B(-7,15,8,minecraft:warped_hyphae)
B(-7,16,8,minecraft:warped_hyphae)
B(-7,17,8,minecraft:warped_hyphae)
B(-7,18,8,minecraft:warped_hyphae)
B(-7,19,8,minecraft:warped_hyphae)
B(-7,20,8,minecraft:warped_hyphae)
B(-7,21,8,minecraft:warped_hyphae)
B(-7,22,8,minecraft:warped_hyphae)
B(-6,72,-7,minecraft:warped_hyphae)
B(-6,73,-7,minecraft:warped_hyphae)
B(-6,74,-7,minecraft:warped_hyphae)
B(-6,75,-7,minecraft:warped_hyphae)
B(-6,76,-7,minecraft:warped_hyphae)
B(-6,77,-7,minecraft:warped_hyphae)
B(-6,78,-7,minecraft:warped_hyphae)
B(-6,72,-6,minecraft:warped_hyphae)
B(-6,73,-6,minecraft:warped_hyphae)
B(-6,74,-6,minecraft:warped_hyphae)
B(-6,75,-6,minecraft:warped_hyphae)
B(-6,76,-6,minecraft:warped_hyphae)
B(-6,77,-6,minecraft:warped_hyphae)
B(-6,78,-6,minecraft:warped_hyphae)
B(-6,72,-5,minecraft:warped_hyphae)
B(-6,73,-5,minecraft:warped_hyphae)
B(-6,74,-5,minecraft:warped_hyphae)
B(-6,75,-5,minecraft:warped_hyphae)
B(-6,76,-5,minecraft:warped_hyphae)
B(-6,77,-5,minecraft:warped_hyphae)
B(-6,78,-5,minecraft:warped_hyphae)
B(-6,72,-4,minecraft:warped_hyphae)
B(-6,73,-4,minecraft:warped_hyphae)
B(-6,74,-4,minecraft:warped_hyphae)
B(-6,75,-4,minecraft:warped_hyphae)
B(-6,76,-4,minecraft:warped_hyphae)
B(-6,77,-4,minecraft:warped_hyphae)
B(-6,78,-4,minecraft:warped_hyphae)
B(-6,19,-3,minecraft:warped_hyphae)
B(-6,20,-3,minecraft:warped_hyphae)
B(-6,21,-3,minecraft:warped_hyphae)
B(-6,22,-3,minecraft:warped_hyphae)
B(-6,23,-3,minecraft:warped_hyphae)
B(-6,24,-3,minecraft:warped_hyphae)
B(-6,25,-3,minecraft:warped_hyphae)
B(-6,26,-3,minecraft:warped_hyphae)
B(-6,27,-3,minecraft:warped_hyphae)
B(-6,73,-3,minecraft:warped_hyphae)
B(-6,74,-3,minecraft:warped_hyphae)
B(-6,75,-3,minecraft:warped_hyphae)
B(-6,76,-3,minecraft:warped_hyphae)
B(-6,77,-3,minecraft:warped_hyphae)
B(-6,18,-2,minecraft:warped_hyphae)
B(-6,19,-2,minecraft:warped_hyphae)
B(-6,20,-2,minecraft:warped_hyphae)
B(-6,21,-2,minecraft:warped_hyphae)
B(-6,22,-2,minecraft:warped_hyphae)
B(-6,23,-2,minecraft:warped_hyphae)
B(-6,24,-2,minecraft:warped_hyphae)
B(-6,25,-2,minecraft:warped_hyphae)
B(-6,26,-2,minecraft:warped_hyphae)
B(-6,27,-2,minecraft:warped_hyphae)
B(-6,28,-2,minecraft:warped_hyphae)
B(-6,17,-1,minecraft:warped_hyphae)
B(-6,18,-1,minecraft:warped_hyphae)
B(-6,19,-1,minecraft:warped_hyphae)
B(-6,20,-1,minecraft:warped_hyphae)
B(-6,21,-1,minecraft:warped_hyphae)
B(-6,22,-1,minecraft:warped_hyphae)
B(-6,23,-1,minecraft:warped_hyphae)
B(-6,24,-1,minecraft:warped_hyphae)
B(-6,25,-1,minecraft:warped_hyphae)
B(-6,26,-1,minecraft:warped_hyphae)
B(-6,27,-1,minecraft:warped_hyphae)
B(-6,28,-1,minecraft:warped_hyphae)
B(-6,16,0,minecraft:warped_hyphae)
B(-6,17,0,minecraft:warped_hyphae)
B(-6,18,0,minecraft:warped_hyphae)
B(-6,19,0,minecraft:warped_hyphae)
B(-6,20,0,minecraft:warped_hyphae)
B(-6,21,0,minecraft:warped_hyphae)
B(-6,22,0,minecraft:warped_hyphae)
B(-6,23,0,minecraft:warped_hyphae)
B(-6,24,0,minecraft:warped_hyphae)
B(-6,25,0,minecraft:warped_hyphae)
B(-6,26,0,minecraft:warped_hyphae)
B(-6,27,0,minecraft:warped_hyphae)
B(-6,28,0,minecraft:warped_hyphae)
B(-6,15,1,minecraft:warped_hyphae)
B(-6,16,1,minecraft:warped_hyphae)
B(-6,17,1,minecraft:warped_hyphae)
B(-6,18,1,minecraft:warped_hyphae)
B(-6,19,1,minecraft:warped_hyphae)
B(-6,20,1,minecraft:warped_hyphae)
B(-6,21,1,minecraft:warped_hyphae)
B(-6,22,1,minecraft:warped_hyphae)
B(-6,23,1,minecraft:warped_hyphae)
B(-6,24,1,minecraft:warped_hyphae)
B(-6,25,1,minecraft:warped_hyphae)
B(-6,26,1,minecraft:warped_hyphae)
B(-6,27,1,minecraft:warped_hyphae)
B(-6,28,1,minecraft:warped_hyphae)
B(-6,14,2,minecraft:warped_hyphae)
B(-6,15,2,minecraft:warped_hyphae)
B(-6,16,2,minecraft:warped_hyphae)
B(-6,17,2,minecraft:warped_hyphae)
B(-6,18,2,minecraft:warped_hyphae)
B(-6,19,2,minecraft:warped_hyphae)
B(-6,20,2,minecraft:warped_hyphae)
B(-6,21,2,minecraft:warped_hyphae)
B(-6,22,2,minecraft:warped_hyphae)
B(-6,23,2,minecraft:warped_hyphae)
B(-6,24,2,minecraft:warped_hyphae)
B(-6,25,2,minecraft:warped_hyphae)
B(-6,26,2,minecraft:warped_hyphae)
B(-6,27,2,minecraft:warped_hyphae)
B(-6,28,2,minecraft:warped_hyphae)
B(-6,14,3,minecraft:warped_hyphae)
B(-6,15,3,minecraft:warped_hyphae)
B(-6,16,3,minecraft:warped_hyphae)
B(-6,17,3,minecraft:warped_hyphae)
B(-6,18,3,minecraft:warped_hyphae)
B(-6,19,3,minecraft:warped_hyphae)
B(-6,20,3,minecraft:warped_hyphae)
B(-6,21,3,minecraft:warped_hyphae)
B(-6,22,3,minecraft:warped_hyphae)
B(-6,23,3,minecraft:warped_hyphae)
B(-6,24,3,minecraft:warped_hyphae)
B(-6,25,3,minecraft:warped_hyphae)
B(-6,26,3,minecraft:warped_hyphae)
B(-6,27,3,minecraft:warped_hyphae)
B(-6,13,4,minecraft:warped_hyphae)
B(-6,14,4,minecraft:warped_hyphae)
B(-6,15,4,minecraft:warped_hyphae)
B(-6,16,4,minecraft:warped_hyphae)
B(-6,17,4,minecraft:warped_hyphae)
B(-6,18,4,minecraft:warped_hyphae)
B(-6,19,4,minecraft:warped_hyphae)
B(-6,20,4,minecraft:warped_hyphae)
B(-6,21,4,minecraft:warped_hyphae)
B(-6,22,4,minecraft:warped_hyphae)
B(-6,23,4,minecraft:warped_hyphae)
B(-6,24,4,minecraft:warped_hyphae)
B(-6,25,4,minecraft:warped_hyphae)
B(-6,26,4,minecraft:warped_hyphae)
B(-6,13,5,minecraft:warped_hyphae)
B(-6,14,5,minecraft:warped_hyphae)
B(-6,15,5,minecraft:warped_hyphae)
B(-6,16,5,minecraft:warped_hyphae)
B(-6,17,5,minecraft:warped_hyphae)
B(-6,18,5,minecraft:warped_hyphae)
B(-6,19,5,minecraft:warped_hyphae)
B(-6,20,5,minecraft:warped_hyphae)
B(-6,21,5,minecraft:warped_hyphae)
B(-6,22,5,minecraft:warped_hyphae)
B(-6,23,5,minecraft:warped_hyphae)
B(-6,24,5,minecraft:warped_hyphae)
B(-6,25,5,minecraft:warped_hyphae)
B(-6,13,6,minecraft:warped_hyphae)
B(-6,14,6,minecraft:warped_hyphae)
B(-6,15,6,minecraft:warped_hyphae)
B(-6,16,6,minecraft:warped_hyphae)
B(-6,17,6,minecraft:warped_hyphae)
B(-6,18,6,minecraft:warped_hyphae)
B(-6,19,6,minecraft:warped_hyphae)
B(-6,20,6,minecraft:warped_hyphae)
B(-6,21,6,minecraft:warped_hyphae)
B(-6,22,6,minecraft:warped_hyphae)
B(-6,23,6,minecraft:warped_hyphae)
B(-6,24,6,minecraft:warped_hyphae)
B(-6,14,7,minecraft:warped_hyphae)
B(-6,15,7,minecraft:warped_hyphae)
B(-6,16,7,minecraft:warped_hyphae)
B(-6,17,7,minecraft:warped_hyphae)
B(-6,18,7,minecraft:warped_hyphae)
B(-6,19,7,minecraft:warped_hyphae)
B(-6,20,7,minecraft:warped_hyphae)
B(-6,21,7,minecraft:warped_hyphae)
B(-6,22,7,minecraft:warped_hyphae)
B(-6,23,7,minecraft:warped_hyphae)
B(-6,14,8,minecraft:warped_hyphae)
B(-6,15,8,minecraft:warped_hyphae)
B(-6,16,8,minecraft:warped_hyphae)
B(-6,17,8,minecraft:warped_hyphae)
B(-6,18,8,minecraft:warped_hyphae)
B(-6,19,8,minecraft:warped_hyphae)
B(-6,20,8,minecraft:warped_hyphae)
B(-6,21,8,minecraft:warped_hyphae)
B(-6,22,8,minecraft:warped_hyphae)
B(-5,71,-7,minecraft:warped_hyphae)
B(-5,72,-7,minecraft:warped_hyphae)
B(-5,73,-7,minecraft:warped_hyphae)
B(-5,74,-7,minecraft:warped_hyphae)
B(-5,75,-7,minecraft:warped_hyphae)
B(-5,76,-7,minecraft:warped_hyphae)
B(-5,77,-7,minecraft:warped_hyphae)
B(-5,78,-7,minecraft:warped_hyphae)
B(-5,79,-7,minecraft:warped_hyphae)
B(-5,71,-6,minecraft:warped_hyphae)
B(-5,72,-6,minecraft:warped_hyphae)
B(-5,73,-6,minecraft:warped_hyphae)
B(-5,74,-6,minecraft:warped_hyphae)
B(-5,75,-6,minecraft:warped_hyphae)
B(-5,76,-6,minecraft:warped_hyphae)
B(-5,77,-6,minecraft:warped_hyphae)
B(-5,78,-6,minecraft:warped_hyphae)
B(-5,79,-6,minecraft:warped_hyphae)
B(-5,71,-5,minecraft:warped_hyphae)
B(-5,72,-5,minecraft:warped_hyphae)
B(-5,73,-5,minecraft:warped_hyphae)
B(-5,74,-5,minecraft:warped_hyphae)
B(-5,75,-5,minecraft:warped_hyphae)
B(-5,76,-5,minecraft:warped_hyphae)
B(-5,77,-5,minecraft:warped_hyphae)
B(-5,78,-5,minecraft:warped_hyphae)
B(-5,79,-5,minecraft:warped_hyphae)
B(-5,23,-4,minecraft:warped_hyphae)
B(-5,24,-4,minecraft:warped_hyphae)
B(-5,25,-4,minecraft:warped_hyphae)
B(-5,26,-4,minecraft:warped_hyphae)
B(-5,27,-4,minecraft:warped_hyphae)
B(-5,71,-4,minecraft:warped_hyphae)
B(-5,72,-4,minecraft:warped_hyphae)
B(-5,73,-4,minecraft:warped_hyphae)
B(-5,74,-4,minecraft:warped_hyphae)
B(-5,75,-4,minecraft:warped_hyphae)
B(-5,76,-4,minecraft:warped_hyphae)
B(-5,77,-4,minecraft:warped_hyphae)
B(-5,78,-4,minecraft:warped_hyphae)
B(-5,79,-4,minecraft:warped_hyphae)
B(-5,19,-3,minecraft:warped_hyphae)
B(-5,20,-3,minecraft:warped_hyphae)
B(-5,21,-3,minecraft:warped_hyphae)
B(-5,22,-3,minecraft:warped_hyphae)
B(-5,23,-3,minecraft:warped_hyphae)
B(-5,24,-3,minecraft:warped_hyphae)
B(-5,25,-3,minecraft:warped_hyphae)
B(-5,26,-3,minecraft:warped_hyphae)
B(-5,27,-3,minecraft:warped_hyphae)
B(-5,28,-3,minecraft:warped_hyphae)
B(-5,72,-3,minecraft:warped_hyphae)
B(-5,73,-3,minecraft:warped_hyphae)
B(-5,74,-3,minecraft:warped_hyphae)
B(-5,75,-3,minecraft:warped_hyphae)
B(-5,76,-3,minecraft:warped_hyphae)
B(-5,77,-3,minecraft:warped_hyphae)
B(-5,78,-3,minecraft:warped_hyphae)
B(-5,18,-2,minecraft:warped_hyphae)
B(-5,19,-2,minecraft:warped_hyphae)
B(-5,20,-2,minecraft:warped_hyphae)
B(-5,21,-2,minecraft:warped_hyphae)
B(-5,22,-2,minecraft:warped_hyphae)
B(-5,23,-2,minecraft:warped_hyphae)
B(-5,24,-2,minecraft:warped_hyphae)
B(-5,25,-2,minecraft:warped_hyphae)
B(-5,26,-2,minecraft:warped_hyphae)
B(-5,27,-2,minecraft:warped_hyphae)
B(-5,28,-2,minecraft:warped_hyphae)
B(-5,29,-2,minecraft:warped_hyphae)
B(-5,73,-2,minecraft:warped_hyphae)
B(-5,74,-2,minecraft:warped_hyphae)
B(-5,75,-2,minecraft:warped_hyphae)
B(-5,76,-2,minecraft:warped_hyphae)
B(-5,77,-2,minecraft:warped_hyphae)
B(-5,17,-1,minecraft:warped_hyphae)
B(-5,18,-1,minecraft:warped_hyphae)
B(-5,19,-1,minecraft:warped_hyphae)
B(-5,20,-1,minecraft:warped_hyphae)
B(-5,21,-1,minecraft:warped_hyphae)
B(-5,22,-1,minecraft:warped_hyphae)
B(-5,23,-1,minecraft:warped_hyphae)
B(-5,24,-1,minecraft:warped_hyphae)
B(-5,25,-1,minecraft:warped_hyphae)
B(-5,26,-1,minecraft:warped_hyphae)
B(-5,27,-1,minecraft:warped_hyphae)
B(-5,28,-1,minecraft:warped_hyphae)
B(-5,29,-1,minecraft:warped_hyphae)
B(-5,16,0,minecraft:warped_hyphae)
B(-5,17,0,minecraft:warped_hyphae)
B(-5,18,0,minecraft:warped_hyphae)
B(-5,19,0,minecraft:warped_hyphae)
B(-5,20,0,minecraft:warped_hyphae)
B(-5,21,0,minecraft:warped_hyphae)
B(-5,22,0,minecraft:warped_hyphae)
B(-5,23,0,minecraft:warped_hyphae)
B(-5,24,0,minecraft:warped_hyphae)
B(-5,25,0,minecraft:warped_hyphae)
B(-5,26,0,minecraft:warped_hyphae)
B(-5,27,0,minecraft:warped_hyphae)
B(-5,28,0,minecraft:warped_hyphae)
B(-5,29,0,minecraft:warped_hyphae)
B(-5,16,1,minecraft:warped_hyphae)
B(-5,17,1,minecraft:warped_hyphae)
B(-5,18,1,minecraft:warped_hyphae)
B(-5,19,1,minecraft:warped_hyphae)
B(-5,20,1,minecraft:warped_hyphae)
B(-5,21,1,minecraft:warped_hyphae)
B(-5,22,1,minecraft:warped_hyphae)
B(-5,23,1,minecraft:warped_hyphae)
B(-5,24,1,minecraft:warped_hyphae)
B(-5,25,1,minecraft:warped_hyphae)
B(-5,26,1,minecraft:warped_hyphae)
B(-5,27,1,minecraft:warped_hyphae)
B(-5,28,1,minecraft:warped_hyphae)
B(-5,29,1,minecraft:warped_hyphae)
B(-5,15,2,minecraft:warped_hyphae)
B(-5,16,2,minecraft:warped_hyphae)
B(-5,17,2,minecraft:warped_hyphae)
B(-5,18,2,minecraft:warped_hyphae)
B(-5,19,2,minecraft:warped_hyphae)
B(-5,20,2,minecraft:warped_hyphae)
B(-5,21,2,minecraft:warped_hyphae)
B(-5,22,2,minecraft:warped_hyphae)
B(-5,23,2,minecraft:warped_hyphae)
B(-5,24,2,minecraft:warped_hyphae)
B(-5,25,2,minecraft:warped_hyphae)
B(-5,26,2,minecraft:warped_hyphae)
B(-5,27,2,minecraft:warped_hyphae)
B(-5,28,2,minecraft:warped_hyphae)
B(-5,29,2,minecraft:warped_hyphae)
B(-5,14,3,minecraft:warped_hyphae)
B(-5,15,3,minecraft:warped_hyphae)
B(-5,16,3,minecraft:warped_hyphae)
B(-5,17,3,minecraft:warped_hyphae)
B(-5,18,3,minecraft:warped_hyphae)
B(-5,19,3,minecraft:warped_hyphae)
B(-5,20,3,minecraft:warped_hyphae)
B(-5,21,3,minecraft:warped_hyphae)
B(-5,22,3,minecraft:warped_hyphae)
B(-5,23,3,minecraft:warped_hyphae)
B(-5,24,3,minecraft:warped_hyphae)
B(-5,25,3,minecraft:warped_hyphae)
B(-5,26,3,minecraft:warped_hyphae)
B(-5,27,3,minecraft:warped_hyphae)
B(-5,28,3,minecraft:warped_hyphae)
B(-5,14,4,minecraft:warped_hyphae)
B(-5,15,4,minecraft:warped_hyphae)
B(-5,16,4,minecraft:warped_hyphae)
B(-5,17,4,minecraft:warped_hyphae)
B(-5,18,4,minecraft:warped_hyphae)
B(-5,19,4,minecraft:warped_hyphae)
B(-5,20,4,minecraft:warped_hyphae)
B(-5,21,4,minecraft:warped_hyphae)
B(-5,22,4,minecraft:warped_hyphae)
B(-5,23,4,minecraft:warped_hyphae)
B(-5,24,4,minecraft:warped_hyphae)
B(-5,25,4,minecraft:warped_hyphae)
B(-5,26,4,minecraft:warped_hyphae)
B(-5,27,4,minecraft:warped_hyphae)
B(-5,14,5,minecraft:warped_hyphae)
B(-5,15,5,minecraft:warped_hyphae)
B(-5,16,5,minecraft:warped_hyphae)
B(-5,17,5,minecraft:warped_hyphae)
B(-5,18,5,minecraft:warped_hyphae)
B(-5,19,5,minecraft:warped_hyphae)
B(-5,20,5,minecraft:warped_hyphae)
B(-5,21,5,minecraft:warped_hyphae)
B(-5,22,5,minecraft:warped_hyphae)
B(-5,23,5,minecraft:warped_hyphae)
B(-5,24,5,minecraft:warped_hyphae)
B(-5,25,5,minecraft:warped_hyphae)
B(-5,14,6,minecraft:warped_hyphae)
B(-5,15,6,minecraft:warped_hyphae)
B(-5,16,6,minecraft:warped_hyphae)
B(-5,17,6,minecraft:warped_hyphae)
B(-5,18,6,minecraft:warped_hyphae)
B(-5,19,6,minecraft:warped_hyphae)
B(-5,20,6,minecraft:warped_hyphae)
B(-5,21,6,minecraft:warped_hyphae)
B(-5,22,6,minecraft:warped_hyphae)
B(-5,23,6,minecraft:warped_hyphae)
B(-5,24,6,minecraft:warped_hyphae)
B(-5,14,7,minecraft:warped_hyphae)
B(-5,15,7,minecraft:warped_hyphae)
B(-5,16,7,minecraft:warped_hyphae)
B(-5,17,7,minecraft:warped_hyphae)
B(-5,18,7,minecraft:warped_hyphae)
B(-5,19,7,minecraft:warped_hyphae)
B(-5,20,7,minecraft:warped_hyphae)
B(-5,21,7,minecraft:warped_hyphae)
B(-5,22,7,minecraft:warped_hyphae)
B(-5,23,7,minecraft:warped_hyphae)
B(-5,15,8,minecraft:warped_hyphae)
B(-5,16,8,minecraft:warped_hyphae)
B(-5,17,8,minecraft:warped_hyphae)
B(-5,18,8,minecraft:warped_hyphae)
B(-5,19,8,minecraft:warped_hyphae)
B(-5,20,8,minecraft:warped_hyphae)
B(-5,21,8,minecraft:warped_hyphae)
B(-4,69,-7,minecraft:warped_hyphae)
B(-4,70,-7,minecraft:warped_hyphae)
B(-4,71,-7,minecraft:warped_hyphae)
B(-4,72,-7,minecraft:warped_hyphae)
B(-4,73,-7,minecraft:warped_hyphae)
B(-4,74,-7,minecraft:warped_hyphae)
B(-4,75,-7,minecraft:warped_hyphae)
B(-4,76,-7,minecraft:warped_hyphae)
B(-4,77,-7,minecraft:warped_hyphae)
B(-4,78,-7,minecraft:warped_hyphae)
B(-4,79,-7,minecraft:warped_hyphae)
B(-4,80,-7,minecraft:warped_hyphae)
B(-4,69,-6,minecraft:warped_hyphae)
B(-4,70,-6,minecraft:warped_hyphae)
B(-4,71,-6,minecraft:warped_hyphae)
B(-4,72,-6,minecraft:warped_hyphae)
B(-4,73,-6,minecraft:warped_hyphae)
B(-4,74,-6,minecraft:warped_hyphae)
B(-4,75,-6,minecraft:warped_hyphae)
B(-4,76,-6,minecraft:warped_hyphae)
B(-4,77,-6,minecraft:warped_hyphae)
B(-4,78,-6,minecraft:warped_hyphae)
B(-4,79,-6,minecraft:warped_hyphae)
B(-4,80,-6,minecraft:warped_hyphae)
B(-4,24,-5,minecraft:warped_hyphae)
B(-4,25,-5,minecraft:warped_hyphae)
B(-4,26,-5,minecraft:warped_hyphae)
B(-4,27,-5,minecraft:warped_hyphae)
B(-4,28,-5,minecraft:warped_hyphae)
B(-4,69,-5,minecraft:warped_hyphae)
B(-4,70,-5,minecraft:warped_hyphae)
B(-4,71,-5,minecraft:warped_hyphae)
B(-4,72,-5,minecraft:warped_hyphae)
B(-4,73,-5,minecraft:warped_hyphae)
B(-4,74,-5,minecraft:warped_hyphae)
B(-4,75,-5,minecraft:warped_hyphae)
B(-4,76,-5,minecraft:warped_hyphae)
B(-4,77,-5,minecraft:warped_hyphae)
B(-4,78,-5,minecraft:warped_hyphae)
B(-4,79,-5,minecraft:warped_hyphae)
B(-4,80,-5,minecraft:warped_hyphae)
B(-4,22,-4,minecraft:warped_hyphae)
B(-4,23,-4,minecraft:warped_hyphae)
B(-4,24,-4,minecraft:warped_hyphae)
B(-4,25,-4,minecraft:warped_hyphae)
B(-4,26,-4,minecraft:warped_hyphae)
B(-4,27,-4,minecraft:warped_hyphae)
B(-4,28,-4,minecraft:warped_hyphae)
B(-4,29,-4,minecraft:warped_hyphae)
B(-4,70,-4,minecraft:warped_hyphae)
B(-4,71,-4,minecraft:warped_hyphae)
B(-4,72,-4,minecraft:warped_hyphae)
B(-4,73,-4,minecraft:warped_hyphae)
B(-4,74,-4,minecraft:warped_hyphae)
B(-4,75,-4,minecraft:warped_hyphae)
B(-4,76,-4,minecraft:warped_hyphae)
B(-4,77,-4,minecraft:warped_hyphae)
B(-4,78,-4,minecraft:warped_hyphae)
B(-4,79,-4,minecraft:warped_hyphae)
B(-4,19,-3,minecraft:warped_hyphae)
B(-4,20,-3,minecraft:warped_hyphae)
B(-4,21,-3,minecraft:warped_hyphae)
B(-4,22,-3,minecraft:warped_hyphae)
B(-4,23,-3,minecraft:warped_hyphae)
B(-4,24,-3,minecraft:warped_hyphae)
B(-4,25,-3,minecraft:warped_hyphae)
B(-4,26,-3,minecraft:warped_hyphae)
B(-4,27,-3,minecraft:warped_hyphae)
B(-4,28,-3,minecraft:warped_hyphae)
B(-4,29,-3,minecraft:warped_hyphae)
B(-4,71,-3,minecraft:warped_hyphae)
B(-4,72,-3,minecraft:warped_hyphae)
B(-4,73,-3,minecraft:warped_hyphae)
B(-4,74,-3,minecraft:warped_hyphae)
B(-4,75,-3,minecraft:warped_hyphae)
B(-4,76,-3,minecraft:warped_hyphae)
B(-4,77,-3,minecraft:warped_hyphae)
B(-4,78,-3,minecraft:warped_hyphae)
B(-4,79,-3,minecraft:warped_hyphae)
B(-4,18,-2,minecraft:warped_hyphae)
B(-4,19,-2,minecraft:warped_hyphae)
B(-4,20,-2,minecraft:warped_hyphae)
B(-4,21,-2,minecraft:warped_hyphae)
B(-4,22,-2,minecraft:warped_hyphae)
B(-4,23,-2,minecraft:warped_hyphae)
B(-4,24,-2,minecraft:warped_hyphae)
B(-4,25,-2,minecraft:warped_hyphae)
B(-4,26,-2,minecraft:warped_hyphae)
B(-4,27,-2,minecraft:warped_hyphae)
B(-4,28,-2,minecraft:warped_hyphae)
B(-4,29,-2,minecraft:warped_hyphae)
B(-4,72,-2,minecraft:warped_hyphae)
B(-4,73,-2,minecraft:warped_hyphae)
B(-4,74,-2,minecraft:warped_hyphae)
B(-4,75,-2,minecraft:warped_hyphae)
B(-4,76,-2,minecraft:warped_hyphae)
B(-4,77,-2,minecraft:warped_hyphae)
B(-4,78,-2,minecraft:warped_hyphae)
B(-4,17,-1,minecraft:warped_hyphae)
B(-4,18,-1,minecraft:warped_hyphae)
B(-4,19,-1,minecraft:warped_hyphae)
B(-4,20,-1,minecraft:warped_hyphae)
B(-4,21,-1,minecraft:warped_hyphae)
B(-4,22,-1,minecraft:warped_hyphae)
B(-4,23,-1,minecraft:warped_hyphae)
B(-4,24,-1,minecraft:warped_hyphae)
B(-4,25,-1,minecraft:warped_hyphae)
B(-4,26,-1,minecraft:warped_hyphae)
B(-4,27,-1,minecraft:warped_hyphae)
B(-4,28,-1,minecraft:warped_hyphae)
B(-4,29,-1,minecraft:warped_hyphae)
B(-4,30,-1,minecraft:warped_hyphae)
B(-4,74,-1,minecraft:warped_hyphae)
B(-4,75,-1,minecraft:warped_hyphae)
B(-4,76,-1,minecraft:warped_hyphae)
B(-4,16,0,minecraft:warped_hyphae)
B(-4,17,0,minecraft:warped_hyphae)
B(-4,18,0,minecraft:warped_hyphae)
B(-4,19,0,minecraft:warped_hyphae)
B(-4,20,0,minecraft:warped_hyphae)
B(-4,21,0,minecraft:warped_hyphae)
B(-4,22,0,minecraft:warped_hyphae)
B(-4,23,0,minecraft:warped_hyphae)
B(-4,24,0,minecraft:warped_hyphae)
B(-4,25,0,minecraft:warped_hyphae)
B(-4,26,0,minecraft:warped_hyphae)
B(-4,27,0,minecraft:warped_hyphae)
B(-4,28,0,minecraft:warped_hyphae)
B(-4,29,0,minecraft:warped_hyphae)
B(-4,30,0,minecraft:warped_hyphae)
B(-4,16,1,minecraft:warped_hyphae)
B(-4,17,1,minecraft:warped_hyphae)
B(-4,18,1,minecraft:warped_hyphae)
B(-4,19,1,minecraft:warped_hyphae)
B(-4,20,1,minecraft:warped_hyphae)
B(-4,21,1,minecraft:warped_hyphae)
B(-4,22,1,minecraft:warped_hyphae)
B(-4,23,1,minecraft:warped_hyphae)
B(-4,24,1,minecraft:warped_hyphae)
B(-4,25,1,minecraft:warped_hyphae)
B(-4,26,1,minecraft:warped_hyphae)
B(-4,27,1,minecraft:warped_hyphae)
B(-4,28,1,minecraft:warped_hyphae)
B(-4,29,1,minecraft:warped_hyphae)
B(-4,30,1,minecraft:warped_hyphae)
B(-4,16,2,minecraft:warped_hyphae)
B(-4,17,2,minecraft:warped_hyphae)
B(-4,18,2,minecraft:warped_hyphae)
B(-4,19,2,minecraft:warped_hyphae)
B(-4,20,2,minecraft:warped_hyphae)
B(-4,21,2,minecraft:warped_hyphae)
B(-4,22,2,minecraft:warped_hyphae)
B(-4,23,2,minecraft:warped_hyphae)
B(-4,24,2,minecraft:warped_hyphae)
B(-4,25,2,minecraft:warped_hyphae)
B(-4,26,2,minecraft:warped_hyphae)
B(-4,27,2,minecraft:warped_hyphae)
B(-4,28,2,minecraft:warped_hyphae)
B(-4,29,2,minecraft:warped_hyphae)
B(-4,15,3,minecraft:warped_hyphae)
B(-4,16,3,minecraft:warped_hyphae)
B(-4,17,3,minecraft:warped_hyphae)
B(-4,18,3,minecraft:warped_hyphae)
B(-4,19,3,minecraft:warped_hyphae)
B(-4,20,3,minecraft:warped_hyphae)
B(-4,21,3,minecraft:warped_hyphae)
B(-4,22,3,minecraft:warped_hyphae)
B(-4,23,3,minecraft:warped_hyphae)
B(-4,24,3,minecraft:warped_hyphae)
B(-4,25,3,minecraft:warped_hyphae)
B(-4,26,3,minecraft:warped_hyphae)
B(-4,27,3,minecraft:warped_hyphae)
B(-4,28,3,minecraft:warped_hyphae)
B(-4,29,3,minecraft:warped_hyphae)
B(-4,15,4,minecraft:warped_hyphae)
B(-4,16,4,minecraft:warped_hyphae)
B(-4,17,4,minecraft:warped_hyphae)
B(-4,18,4,minecraft:warped_hyphae)
B(-4,19,4,minecraft:warped_hyphae)
B(-4,20,4,minecraft:warped_hyphae)
B(-4,21,4,minecraft:warped_hyphae)
B(-4,22,4,minecraft:warped_hyphae)
B(-4,23,4,minecraft:warped_hyphae)
B(-4,24,4,minecraft:warped_hyphae)
B(-4,25,4,minecraft:warped_hyphae)
B(-4,26,4,minecraft:warped_hyphae)
B(-4,27,4,minecraft:warped_hyphae)
B(-4,28,4,minecraft:warped_hyphae)
B(-4,15,5,minecraft:warped_hyphae)
B(-4,16,5,minecraft:warped_hyphae)
B(-4,17,5,minecraft:warped_hyphae)
B(-4,18,5,minecraft:warped_hyphae)
B(-4,19,5,minecraft:warped_hyphae)
B(-4,20,5,minecraft:warped_hyphae)
B(-4,21,5,minecraft:warped_hyphae)
B(-4,22,5,minecraft:warped_hyphae)
B(-4,23,5,minecraft:warped_hyphae)
B(-4,24,5,minecraft:warped_hyphae)
B(-4,25,5,minecraft:warped_hyphae)
B(-4,26,5,minecraft:warped_hyphae)
B(-4,15,6,minecraft:warped_hyphae)
B(-4,16,6,minecraft:warped_hyphae)
B(-4,17,6,minecraft:warped_hyphae)
B(-4,18,6,minecraft:warped_hyphae)
B(-4,19,6,minecraft:warped_hyphae)
B(-4,20,6,minecraft:warped_hyphae)
B(-4,21,6,minecraft:warped_hyphae)
B(-4,22,6,minecraft:warped_hyphae)
B(-4,23,6,minecraft:warped_hyphae)
B(-4,24,6,minecraft:warped_hyphae)
B(-4,15,7,minecraft:warped_hyphae)
B(-4,16,7,minecraft:warped_hyphae)
B(-4,17,7,minecraft:warped_hyphae)
B(-4,18,7,minecraft:warped_hyphae)
B(-4,19,7,minecraft:warped_hyphae)
B(-4,20,7,minecraft:warped_hyphae)
B(-4,21,7,minecraft:warped_hyphae)
B(-4,22,7,minecraft:warped_hyphae)
B(-4,23,7,minecraft:warped_hyphae)
B(-4,16,8,minecraft:warped_hyphae)
B(-4,17,8,minecraft:warped_hyphae)
B(-4,18,8,minecraft:warped_hyphae)
B(-4,19,8,minecraft:warped_hyphae)
B(-4,20,8,minecraft:warped_hyphae)
B(-3,68,-7,minecraft:warped_hyphae)
B(-3,69,-7,minecraft:warped_hyphae)
B(-3,70,-7,minecraft:warped_hyphae)
B(-3,71,-7,minecraft:warped_hyphae)
B(-3,72,-7,minecraft:warped_hyphae)
B(-3,73,-7,minecraft:warped_hyphae)
B(-3,74,-7,minecraft:warped_hyphae)
B(-3,75,-7,minecraft:warped_hyphae)
B(-3,76,-7,minecraft:warped_hyphae)
B(-3,77,-7,minecraft:warped_hyphae)
B(-3,78,-7,minecraft:warped_hyphae)
B(-3,79,-7,minecraft:warped_hyphae)
B(-3,80,-7,minecraft:warped_hyphae)
B(-3,25,-6,minecraft:warped_hyphae)
B(-3,26,-6,minecraft:warped_hyphae)
B(-3,27,-6,minecraft:warped_hyphae)
B(-3,28,-6,minecraft:warped_hyphae)
B(-3,29,-6,minecraft:warped_hyphae)
B(-3,68,-6,minecraft:warped_hyphae)
B(-3,69,-6,minecraft:warped_hyphae)
B(-3,70,-6,minecraft:warped_hyphae)
B(-3,71,-6,minecraft:warped_hyphae)
B(-3,72,-6,minecraft:warped_hyphae)
B(-3,73,-6,minecraft:warped_hyphae)
B(-3,74,-6,minecraft:warped_hyphae)
B(-3,75,-6,minecraft:warped_hyphae)
B(-3,76,-6,minecraft:warped_hyphae)
B(-3,77,-6,minecraft:warped_hyphae)
B(-3,78,-6,minecraft:warped_hyphae)
B(-3,79,-6,minecraft:warped_hyphae)
B(-3,80,-6,minecraft:warped_hyphae)
B(-3,23,-5,minecraft:warped_hyphae)
B(-3,24,-5,minecraft:warped_hyphae)
B(-3,25,-5,minecraft:warped_hyphae)
B(-3,26,-5,minecraft:warped_hyphae)
B(-3,27,-5,minecraft:warped_hyphae)
B(-3,28,-5,minecraft:warped_hyphae)
B(-3,29,-5,minecraft:warped_hyphae)
B(-3,30,-5,minecraft:warped_hyphae)
B(-3,68,-5,minecraft:warped_hyphae)
B(-3,69,-5,minecraft:warped_hyphae)
B(-3,70,-5,minecraft:warped_hyphae)
B(-3,71,-5,minecraft:warped_hyphae)
B(-3,72,-5,minecraft:warped_hyphae)
B(-3,73,-5,minecraft:warped_hyphae)
B(-3,74,-5,minecraft:warped_hyphae)
B(-3,75,-5,minecraft:warped_hyphae)
B(-3,76,-5,minecraft:warped_hyphae)
B(-3,77,-5,minecraft:warped_hyphae)
B(-3,78,-5,minecraft:warped_hyphae)
B(-3,79,-5,minecraft:warped_hyphae)
B(-3,80,-5,minecraft:warped_hyphae)
B(-3,22,-4,minecraft:warped_hyphae)
B(-3,23,-4,minecraft:warped_hyphae)
B(-3,24,-4,minecraft:warped_hyphae)
B(-3,25,-4,minecraft:warped_hyphae)
B(-3,26,-4,minecraft:warped_hyphae)
B(-3,27,-4,minecraft:warped_hyphae)
B(-3,28,-4,minecraft:warped_hyphae)
B(-3,29,-4,minecraft:warped_hyphae)
B(-3,30,-4,minecraft:warped_hyphae)
B(-3,68,-4,minecraft:warped_hyphae)
B(-3,69,-4,minecraft:warped_hyphae)
B(-3,70,-4,minecraft:warped_hyphae)
B(-3,71,-4,minecraft:warped_hyphae)
B(-3,72,-4,minecraft:warped_hyphae)
B(-3,73,-4,minecraft:warped_hyphae)
B(-3,74,-4,minecraft:warped_hyphae)
B(-3,75,-4,minecraft:warped_hyphae)
B(-3,76,-4,minecraft:warped_hyphae)
B(-3,77,-4,minecraft:warped_hyphae)
B(-3,78,-4,minecraft:warped_hyphae)
B(-3,79,-4,minecraft:warped_hyphae)
B(-3,80,-4,minecraft:warped_hyphae)
B(-3,20,-3,minecraft:warped_hyphae)
B(-3,21,-3,minecraft:warped_hyphae)
B(-3,22,-3,minecraft:warped_hyphae)
B(-3,23,-3,minecraft:warped_hyphae)
B(-3,24,-3,minecraft:warped_hyphae)
B(-3,25,-3,minecraft:warped_hyphae)
B(-3,26,-3,minecraft:warped_hyphae)
B(-3,27,-3,minecraft:warped_hyphae)
B(-3,28,-3,minecraft:warped_hyphae)
B(-3,29,-3,minecraft:warped_hyphae)
B(-3,30,-3,minecraft:warped_hyphae)
B(-3,69,-3,minecraft:warped_hyphae)
B(-3,70,-3,minecraft:warped_hyphae)
B(-3,71,-3,minecraft:warped_hyphae)
B(-3,72,-3,minecraft:warped_hyphae)
B(-3,73,-3,minecraft:warped_hyphae)
B(-3,74,-3,minecraft:warped_hyphae)
B(-3,75,-3,minecraft:warped_hyphae)
B(-3,76,-3,minecraft:warped_hyphae)
B(-3,77,-3,minecraft:warped_hyphae)
B(-3,78,-3,minecraft:warped_hyphae)
B(-3,79,-3,minecraft:warped_hyphae)
B(-3,18,-2,minecraft:warped_hyphae)
B(-3,19,-2,minecraft:warped_hyphae)
B(-3,20,-2,minecraft:warped_hyphae)
B(-3,21,-2,minecraft:warped_hyphae)
B(-3,22,-2,minecraft:warped_hyphae)
B(-3,23,-2,minecraft:warped_hyphae)
B(-3,24,-2,minecraft:warped_hyphae)
B(-3,25,-2,minecraft:warped_hyphae)
B(-3,26,-2,minecraft:warped_hyphae)
B(-3,27,-2,minecraft:warped_hyphae)
B(-3,28,-2,minecraft:warped_hyphae)
B(-3,29,-2,minecraft:warped_hyphae)
B(-3,30,-2,minecraft:warped_hyphae)
B(-3,72,-2,minecraft:warped_hyphae)
B(-3,73,-2,minecraft:warped_hyphae)
B(-3,74,-2,minecraft:warped_hyphae)
B(-3,75,-2,minecraft:warped_hyphae)
B(-3,76,-2,minecraft:warped_hyphae)
B(-3,77,-2,minecraft:warped_hyphae)
B(-3,78,-2,minecraft:warped_hyphae)
B(-3,17,-1,minecraft:warped_hyphae)
B(-3,18,-1,minecraft:warped_hyphae)
B(-3,19,-1,minecraft:warped_hyphae)
B(-3,20,-1,minecraft:warped_hyphae)
B(-3,21,-1,minecraft:warped_hyphae)
B(-3,22,-1,minecraft:warped_hyphae)
B(-3,23,-1,minecraft:warped_hyphae)
B(-3,24,-1,minecraft:warped_hyphae)
B(-3,25,-1,minecraft:warped_hyphae)
B(-3,26,-1,minecraft:warped_hyphae)
B(-3,27,-1,minecraft:warped_hyphae)
B(-3,28,-1,minecraft:warped_hyphae)
B(-3,29,-1,minecraft:warped_hyphae)
B(-3,30,-1,minecraft:warped_hyphae)
B(-3,73,-1,minecraft:warped_hyphae)
B(-3,74,-1,minecraft:warped_hyphae)
B(-3,75,-1,minecraft:warped_hyphae)
B(-3,76,-1,minecraft:warped_hyphae)
B(-3,77,-1,minecraft:warped_hyphae)
B(-3,17,0,minecraft:warped_hyphae)
B(-3,18,0,minecraft:warped_hyphae)
B(-3,19,0,minecraft:warped_hyphae)
B(-3,20,0,minecraft:warped_hyphae)
B(-3,21,0,minecraft:warped_hyphae)
B(-3,22,0,minecraft:warped_hyphae)
B(-3,23,0,minecraft:warped_hyphae)
B(-3,24,0,minecraft:warped_hyphae)
B(-3,25,0,minecraft:warped_hyphae)
B(-3,26,0,minecraft:warped_hyphae)
B(-3,27,0,minecraft:warped_hyphae)
B(-3,28,0,minecraft:warped_hyphae)
B(-3,29,0,minecraft:warped_hyphae)
B(-3,30,0,minecraft:warped_hyphae)
B(-3,16,1,minecraft:warped_hyphae)
B(-3,17,1,minecraft:warped_hyphae)
B(-3,18,1,minecraft:warped_hyphae)
B(-3,19,1,minecraft:warped_hyphae)
B(-3,20,1,minecraft:warped_hyphae)
B(-3,21,1,minecraft:warped_hyphae)
B(-3,22,1,minecraft:warped_hyphae)
B(-3,23,1,minecraft:warped_hyphae)
B(-3,24,1,minecraft:warped_hyphae)
B(-3,25,1,minecraft:warped_hyphae)
B(-3,26,1,minecraft:warped_hyphae)
B(-3,27,1,minecraft:warped_hyphae)
B(-3,28,1,minecraft:warped_hyphae)
B(-3,29,1,minecraft:warped_hyphae)
B(-3,30,1,minecraft:warped_hyphae)
B(-3,16,2,minecraft:warped_hyphae)
B(-3,17,2,minecraft:warped_hyphae)
B(-3,18,2,minecraft:warped_hyphae)
B(-3,19,2,minecraft:warped_hyphae)
B(-3,20,2,minecraft:warped_hyphae)
B(-3,21,2,minecraft:warped_hyphae)
B(-3,22,2,minecraft:warped_hyphae)
B(-3,23,2,minecraft:warped_hyphae)
B(-3,24,2,minecraft:warped_hyphae)
B(-3,25,2,minecraft:warped_hyphae)
B(-3,26,2,minecraft:warped_hyphae)
B(-3,27,2,minecraft:warped_hyphae)
B(-3,28,2,minecraft:warped_hyphae)
B(-3,29,2,minecraft:warped_hyphae)
B(-3,30,2,minecraft:warped_hyphae)
B(-3,16,3,minecraft:warped_hyphae)
B(-3,17,3,minecraft:warped_hyphae)
B(-3,18,3,minecraft:warped_hyphae)
B(-3,19,3,minecraft:warped_hyphae)
B(-3,20,3,minecraft:warped_hyphae)
B(-3,21,3,minecraft:warped_hyphae)
B(-3,22,3,minecraft:warped_hyphae)
B(-3,23,3,minecraft:warped_hyphae)
B(-3,24,3,minecraft:warped_hyphae)
B(-3,25,3,minecraft:warped_hyphae)
B(-3,26,3,minecraft:warped_hyphae)
B(-3,27,3,minecraft:warped_hyphae)
B(-3,28,3,minecraft:warped_hyphae)
B(-3,29,3,minecraft:warped_hyphae)
B(-3,16,4,minecraft:warped_hyphae)
B(-3,17,4,minecraft:warped_hyphae)
B(-3,18,4,minecraft:warped_hyphae)
B(-3,19,4,minecraft:warped_hyphae)
B(-3,20,4,minecraft:warped_hyphae)
B(-3,21,4,minecraft:warped_hyphae)
B(-3,22,4,minecraft:warped_hyphae)
B(-3,23,4,minecraft:warped_hyphae)
B(-3,24,4,minecraft:warped_hyphae)
B(-3,25,4,minecraft:warped_hyphae)
B(-3,26,4,minecraft:warped_hyphae)
B(-3,27,4,minecraft:warped_hyphae)
B(-3,28,4,minecraft:warped_hyphae)
B(-3,16,5,minecraft:warped_hyphae)
B(-3,17,5,minecraft:warped_hyphae)
B(-3,18,5,minecraft:warped_hyphae)
B(-3,19,5,minecraft:warped_hyphae)
B(-3,20,5,minecraft:warped_hyphae)
B(-3,21,5,minecraft:warped_hyphae)
B(-3,22,5,minecraft:warped_hyphae)
B(-3,23,5,minecraft:warped_hyphae)
B(-3,24,5,minecraft:warped_hyphae)
B(-3,25,5,minecraft:warped_hyphae)
B(-3,26,5,minecraft:warped_hyphae)
B(-3,27,5,minecraft:warped_hyphae)
B(-3,16,6,minecraft:warped_hyphae)
B(-3,17,6,minecraft:warped_hyphae)
B(-3,18,6,minecraft:warped_hyphae)
B(-3,19,6,minecraft:warped_hyphae)
B(-3,20,6,minecraft:warped_hyphae)
B(-3,21,6,minecraft:warped_hyphae)
B(-3,22,6,minecraft:warped_hyphae)
B(-3,23,6,minecraft:warped_hyphae)
B(-3,24,6,minecraft:warped_hyphae)
B(-3,17,7,minecraft:warped_hyphae)
B(-3,18,7,minecraft:warped_hyphae)
B(-3,19,7,minecraft:warped_hyphae)
B(-3,20,7,minecraft:warped_hyphae)
B(-3,21,7,minecraft:warped_hyphae)
B(-3,22,7,minecraft:warped_hyphae)
B(-2,25,-7,minecraft:warped_hyphae)
B(-2,26,-7,minecraft:warped_hyphae)
B(-2,27,-7,minecraft:warped_hyphae)
B(-2,28,-7,minecraft:warped_hyphae)
B(-2,29,-7,minecraft:warped_hyphae)
B(-2,30,-7,minecraft:warped_hyphae)
B(-2,31,-7,minecraft:warped_hyphae)
B(-2,32,-7,minecraft:warped_hyphae)
B(-2,33,-7,minecraft:warped_hyphae)
B(-2,67,-7,minecraft:warped_hyphae)
B(-2,68,-7,minecraft:warped_hyphae)
B(-2,69,-7,minecraft:warped_hyphae)
B(-2,70,-7,minecraft:warped_hyphae)
B(-2,71,-7,minecraft:warped_hyphae)
B(-2,72,-7,minecraft:warped_hyphae)
B(-2,73,-7,minecraft:warped_hyphae)
B(-2,74,-7,minecraft:warped_hyphae)
B(-2,75,-7,minecraft:warped_hyphae)
B(-2,76,-7,minecraft:warped_hyphae)
B(-2,77,-7,minecraft:warped_hyphae)
B(-2,78,-7,minecraft:warped_hyphae)
B(-2,79,-7,minecraft:warped_hyphae)
B(-2,80,-7,minecraft:warped_hyphae)
B(-2,24,-6,minecraft:warped_hyphae)
B(-2,25,-6,minecraft:warped_hyphae)
B(-2,26,-6,minecraft:warped_hyphae)
B(-2,27,-6,minecraft:warped_hyphae)
B(-2,28,-6,minecraft:warped_hyphae)
B(-2,29,-6,minecraft:warped_hyphae)
B(-2,30,-6,minecraft:warped_hyphae)
B(-2,31,-6,minecraft:warped_hyphae)
B(-2,32,-6,minecraft:warped_hyphae)
B(-2,33,-6,minecraft:warped_hyphae)
B(-2,67,-6,minecraft:warped_hyphae)
B(-2,68,-6,minecraft:warped_hyphae)
B(-2,69,-6,minecraft:warped_hyphae)
B(-2,70,-6,minecraft:warped_hyphae)
B(-2,71,-6,minecraft:warped_hyphae)
B(-2,72,-6,minecraft:warped_hyphae)
B(-2,73,-6,minecraft:warped_hyphae)
B(-2,74,-6,minecraft:warped_hyphae)
B(-2,75,-6,minecraft:warped_hyphae)
B(-2,76,-6,minecraft:warped_hyphae)
B(-2,77,-6,minecraft:warped_hyphae)
B(-2,78,-6,minecraft:warped_hyphae)
B(-2,79,-6,minecraft:warped_hyphae)
B(-2,80,-6,minecraft:warped_hyphae)
B(-2,23,-5,minecraft:warped_hyphae)
B(-2,24,-5,minecraft:warped_hyphae)
B(-2,25,-5,minecraft:warped_hyphae)
B(-2,26,-5,minecraft:warped_hyphae)
B(-2,27,-5,minecraft:warped_hyphae)
B(-2,28,-5,minecraft:warped_hyphae)
B(-2,29,-5,minecraft:warped_hyphae)
B(-2,30,-5,minecraft:warped_hyphae)
B(-2,31,-5,minecraft:warped_hyphae)
B(-2,32,-5,minecraft:warped_hyphae)
B(-2,67,-5,minecraft:warped_hyphae)
B(-2,68,-5,minecraft:warped_hyphae)
B(-2,69,-5,minecraft:warped_hyphae)
B(-2,70,-5,minecraft:warped_hyphae)
B(-2,71,-5,minecraft:warped_hyphae)
B(-2,72,-5,minecraft:warped_hyphae)
B(-2,73,-5,minecraft:warped_hyphae)
B(-2,74,-5,minecraft:warped_hyphae)
B(-2,75,-5,minecraft:warped_hyphae)
B(-2,76,-5,minecraft:warped_hyphae)
B(-2,77,-5,minecraft:warped_hyphae)
B(-2,78,-5,minecraft:warped_hyphae)
B(-2,79,-5,minecraft:warped_hyphae)
B(-2,80,-5,minecraft:warped_hyphae)
B(-2,22,-4,minecraft:warped_hyphae)
B(-2,23,-4,minecraft:warped_hyphae)
B(-2,24,-4,minecraft:warped_hyphae)
B(-2,25,-4,minecraft:warped_hyphae)
B(-2,26,-4,minecraft:warped_hyphae)
B(-2,27,-4,minecraft:warped_hyphae)
B(-2,28,-4,minecraft:warped_hyphae)
B(-2,29,-4,minecraft:warped_hyphae)
B(-2,30,-4,minecraft:warped_hyphae)
B(-2,31,-4,minecraft:warped_hyphae)
B(-2,67,-4,minecraft:warped_hyphae)
B(-2,68,-4,minecraft:warped_hyphae)
B(-2,69,-4,minecraft:warped_hyphae)
B(-2,70,-4,minecraft:warped_hyphae)
B(-2,71,-4,minecraft:warped_hyphae)
B(-2,72,-4,minecraft:warped_hyphae)
B(-2,73,-4,minecraft:warped_hyphae)
B(-2,74,-4,minecraft:warped_hyphae)
B(-2,75,-4,minecraft:warped_hyphae)
B(-2,76,-4,minecraft:warped_hyphae)
B(-2,77,-4,minecraft:warped_hyphae)
B(-2,78,-4,minecraft:warped_hyphae)
B(-2,79,-4,minecraft:warped_hyphae)
B(-2,80,-4,minecraft:warped_hyphae)
B(-2,21,-3,minecraft:warped_hyphae)
B(-2,22,-3,minecraft:warped_hyphae)
B(-2,23,-3,minecraft:warped_hyphae)
B(-2,24,-3,minecraft:warped_hyphae)
B(-2,25,-3,minecraft:warped_hyphae)
B(-2,26,-3,minecraft:warped_hyphae)
B(-2,27,-3,minecraft:warped_hyphae)
B(-2,28,-3,minecraft:warped_hyphae)
B(-2,29,-3,minecraft:warped_hyphae)
B(-2,30,-3,minecraft:warped_hyphae)
B(-2,31,-3,minecraft:warped_hyphae)
B(-2,68,-3,minecraft:warped_hyphae)
B(-2,69,-3,minecraft:warped_hyphae)
B(-2,70,-3,minecraft:warped_hyphae)
B(-2,71,-3,minecraft:warped_hyphae)
B(-2,72,-3,minecraft:warped_hyphae)
B(-2,73,-3,minecraft:warped_hyphae)
B(-2,74,-3,minecraft:warped_hyphae)
B(-2,75,-3,minecraft:warped_hyphae)
B(-2,76,-3,minecraft:warped_hyphae)
B(-2,77,-3,minecraft:warped_hyphae)
B(-2,78,-3,minecraft:warped_hyphae)
B(-2,79,-3,minecraft:warped_hyphae)
B(-2,19,-2,minecraft:warped_hyphae)
B(-2,20,-2,minecraft:warped_hyphae)
B(-2,21,-2,minecraft:warped_hyphae)
B(-2,22,-2,minecraft:warped_hyphae)
B(-2,23,-2,minecraft:warped_hyphae)
B(-2,24,-2,minecraft:warped_hyphae)
B(-2,25,-2,minecraft:warped_hyphae)
B(-2,26,-2,minecraft:warped_hyphae)
B(-2,27,-2,minecraft:warped_hyphae)
B(-2,28,-2,minecraft:warped_hyphae)
B(-2,29,-2,minecraft:warped_hyphae)
B(-2,30,-2,minecraft:warped_hyphae)
B(-2,31,-2,minecraft:warped_hyphae)
B(-2,69,-2,minecraft:warped_hyphae)
B(-2,70,-2,minecraft:warped_hyphae)
B(-2,71,-2,minecraft:warped_hyphae)
B(-2,72,-2,minecraft:warped_hyphae)
B(-2,73,-2,minecraft:warped_hyphae)
B(-2,74,-2,minecraft:warped_hyphae)
B(-2,75,-2,minecraft:warped_hyphae)
B(-2,76,-2,minecraft:warped_hyphae)
B(-2,77,-2,minecraft:warped_hyphae)
B(-2,78,-2,minecraft:warped_hyphae)
B(-2,18,-1,minecraft:warped_hyphae)
B(-2,19,-1,minecraft:warped_hyphae)
B(-2,20,-1,minecraft:warped_hyphae)
B(-2,21,-1,minecraft:warped_hyphae)
B(-2,22,-1,minecraft:warped_hyphae)
B(-2,23,-1,minecraft:warped_hyphae)
B(-2,24,-1,minecraft:warped_hyphae)
B(-2,25,-1,minecraft:warped_hyphae)
B(-2,26,-1,minecraft:warped_hyphae)
B(-2,27,-1,minecraft:warped_hyphae)
B(-2,28,-1,minecraft:warped_hyphae)
B(-2,29,-1,minecraft:warped_hyphae)
B(-2,30,-1,minecraft:warped_hyphae)
B(-2,31,-1,minecraft:warped_hyphae)
B(-2,73,-1,minecraft:warped_hyphae)
B(-2,74,-1,minecraft:warped_hyphae)
B(-2,75,-1,minecraft:warped_hyphae)
B(-2,76,-1,minecraft:warped_hyphae)
B(-2,77,-1,minecraft:warped_hyphae)
B(-2,17,0,minecraft:warped_hyphae)
B(-2,18,0,minecraft:warped_hyphae)
B(-2,19,0,minecraft:warped_hyphae)
B(-2,20,0,minecraft:warped_hyphae)
B(-2,21,0,minecraft:warped_hyphae)
B(-2,22,0,minecraft:warped_hyphae)
B(-2,23,0,minecraft:warped_hyphae)
B(-2,24,0,minecraft:warped_hyphae)
B(-2,25,0,minecraft:warped_hyphae)
B(-2,26,0,minecraft:warped_hyphae)
B(-2,27,0,minecraft:warped_hyphae)
B(-2,28,0,minecraft:warped_hyphae)
B(-2,29,0,minecraft:warped_hyphae)
B(-2,30,0,minecraft:warped_hyphae)
B(-2,17,1,minecraft:warped_hyphae)
B(-2,18,1,minecraft:warped_hyphae)
B(-2,19,1,minecraft:warped_hyphae)
B(-2,20,1,minecraft:warped_hyphae)
B(-2,21,1,minecraft:warped_hyphae)
B(-2,22,1,minecraft:warped_hyphae)
B(-2,23,1,minecraft:warped_hyphae)
B(-2,24,1,minecraft:warped_hyphae)
B(-2,25,1,minecraft:warped_hyphae)
B(-2,26,1,minecraft:warped_hyphae)
B(-2,27,1,minecraft:warped_hyphae)
B(-2,28,1,minecraft:warped_hyphae)
B(-2,29,1,minecraft:warped_hyphae)
B(-2,30,1,minecraft:warped_hyphae)
B(-2,17,2,minecraft:warped_hyphae)
B(-2,18,2,minecraft:warped_hyphae)
B(-2,19,2,minecraft:warped_hyphae)
B(-2,20,2,minecraft:warped_hyphae)
B(-2,21,2,minecraft:warped_hyphae)
B(-2,22,2,minecraft:warped_hyphae)
B(-2,23,2,minecraft:warped_hyphae)
B(-2,24,2,minecraft:warped_hyphae)
B(-2,25,2,minecraft:warped_hyphae)
B(-2,26,2,minecraft:warped_hyphae)
B(-2,27,2,minecraft:warped_hyphae)
B(-2,28,2,minecraft:warped_hyphae)
B(-2,29,2,minecraft:warped_hyphae)
B(-2,30,2,minecraft:warped_hyphae)
B(-2,17,3,minecraft:warped_hyphae)
B(-2,18,3,minecraft:warped_hyphae)
B(-2,19,3,minecraft:warped_hyphae)
B(-2,20,3,minecraft:warped_hyphae)
B(-2,21,3,minecraft:warped_hyphae)
B(-2,22,3,minecraft:warped_hyphae)
B(-2,23,3,minecraft:warped_hyphae)
B(-2,24,3,minecraft:warped_hyphae)
B(-2,25,3,minecraft:warped_hyphae)
B(-2,26,3,minecraft:warped_hyphae)
B(-2,27,3,minecraft:warped_hyphae)
B(-2,28,3,minecraft:warped_hyphae)
B(-2,29,3,minecraft:warped_hyphae)
B(-2,17,4,minecraft:warped_hyphae)
B(-2,18,4,minecraft:warped_hyphae)
B(-2,19,4,minecraft:warped_hyphae)
B(-2,20,4,minecraft:warped_hyphae)
B(-2,21,4,minecraft:warped_hyphae)
B(-2,22,4,minecraft:warped_hyphae)
B(-2,23,4,minecraft:warped_hyphae)
B(-2,24,4,minecraft:warped_hyphae)
B(-2,25,4,minecraft:warped_hyphae)
B(-2,26,4,minecraft:warped_hyphae)
B(-2,27,4,minecraft:warped_hyphae)
B(-2,28,4,minecraft:warped_hyphae)
B(-2,18,5,minecraft:warped_hyphae)
B(-2,19,5,minecraft:warped_hyphae)
B(-2,20,5,minecraft:warped_hyphae)
B(-2,21,5,minecraft:warped_hyphae)
B(-2,22,5,minecraft:warped_hyphae)
B(-2,23,5,minecraft:warped_hyphae)
B(-2,24,5,minecraft:warped_hyphae)
B(-2,25,5,minecraft:warped_hyphae)
B(-2,26,5,minecraft:warped_hyphae)
B(-2,27,5,minecraft:warped_hyphae)
B(-2,19,6,minecraft:warped_hyphae)
B(-2,20,6,minecraft:warped_hyphae)
B(-2,21,6,minecraft:warped_hyphae)
B(-2,22,6,minecraft:warped_hyphae)
B(-2,23,6,minecraft:warped_hyphae)
B(-1,24,-7,minecraft:warped_hyphae)
B(-1,25,-7,minecraft:warped_hyphae)
B(-1,26,-7,minecraft:warped_hyphae)
B(-1,27,-7,minecraft:warped_hyphae)
B(-1,28,-7,minecraft:warped_hyphae)
B(-1,29,-7,minecraft:warped_hyphae)
B(-1,30,-7,minecraft:warped_hyphae)
B(-1,31,-7,minecraft:warped_hyphae)
B(-1,32,-7,minecraft:warped_hyphae)
B(-1,33,-7,minecraft:warped_hyphae)
B(-1,34,-7,minecraft:warped_hyphae)
B(-1,35,-7,minecraft:warped_hyphae)
B(-1,36,-7,minecraft:warped_hyphae)
B(-1,37,-7,minecraft:warped_hyphae)
B(-1,66,-7,minecraft:warped_hyphae)
B(-1,67,-7,minecraft:warped_hyphae)
B(-1,68,-7,minecraft:warped_hyphae)
B(-1,69,-7,minecraft:warped_hyphae)
B(-1,70,-7,minecraft:warped_hyphae)
B(-1,71,-7,minecraft:warped_hyphae)
B(-1,72,-7,minecraft:warped_hyphae)
B(-1,73,-7,minecraft:warped_hyphae)
B(-1,74,-7,minecraft:warped_hyphae)
B(-1,75,-7,minecraft:warped_hyphae)
B(-1,76,-7,minecraft:warped_hyphae)
B(-1,77,-7,minecraft:warped_hyphae)
B(-1,78,-7,minecraft:warped_hyphae)
B(-1,79,-7,minecraft:warped_hyphae)
B(-1,80,-7,minecraft:warped_hyphae)
B(-1,23,-6,minecraft:warped_hyphae)
B(-1,24,-6,minecraft:warped_hyphae)
B(-1,25,-6,minecraft:warped_hyphae)
B(-1,26,-6,minecraft:warped_hyphae)
B(-1,27,-6,minecraft:warped_hyphae)
B(-1,28,-6,minecraft:warped_hyphae)
B(-1,29,-6,minecraft:warped_hyphae)
B(-1,30,-6,minecraft:warped_hyphae)
B(-1,31,-6,minecraft:warped_hyphae)
B(-1,32,-6,minecraft:warped_hyphae)
B(-1,33,-6,minecraft:warped_hyphae)
B(-1,34,-6,minecraft:warped_hyphae)
B(-1,66,-6,minecraft:warped_hyphae)
B(-1,67,-6,minecraft:warped_hyphae)
B(-1,68,-6,minecraft:warped_hyphae)
B(-1,69,-6,minecraft:warped_hyphae)
B(-1,70,-6,minecraft:warped_hyphae)
B(-1,71,-6,minecraft:warped_hyphae)
B(-1,72,-6,minecraft:warped_hyphae)
B(-1,73,-6,minecraft:warped_hyphae)
B(-1,74,-6,minecraft:warped_hyphae)
B(-1,75,-6,minecraft:warped_hyphae)
B(-1,76,-6,minecraft:warped_hyphae)
B(-1,77,-6,minecraft:warped_hyphae)
B(-1,78,-6,minecraft:warped_hyphae)
B(-1,79,-6,minecraft:warped_hyphae)
B(-1,80,-6,minecraft:warped_hyphae)
B(-1,23,-5,minecraft:warped_hyphae)
B(-1,24,-5,minecraft:warped_hyphae)
B(-1,25,-5,minecraft:warped_hyphae)
B(-1,26,-5,minecraft:warped_hyphae)
B(-1,27,-5,minecraft:warped_hyphae)
B(-1,28,-5,minecraft:warped_hyphae)
B(-1,29,-5,minecraft:warped_hyphae)
B(-1,30,-5,minecraft:warped_hyphae)
B(-1,31,-5,minecraft:warped_hyphae)
B(-1,32,-5,minecraft:warped_hyphae)
B(-1,33,-5,minecraft:warped_hyphae)
B(-1,34,-5,minecraft:warped_hyphae)
B(-1,66,-5,minecraft:warped_hyphae)
B(-1,67,-5,minecraft:warped_hyphae)
B(-1,68,-5,minecraft:warped_hyphae)
B(-1,69,-5,minecraft:warped_hyphae)
B(-1,70,-5,minecraft:warped_hyphae)
B(-1,71,-5,minecraft:warped_hyphae)
B(-1,72,-5,minecraft:warped_hyphae)
B(-1,73,-5,minecraft:warped_hyphae)
B(-1,74,-5,minecraft:warped_hyphae)
B(-1,75,-5,minecraft:warped_hyphae)
B(-1,76,-5,minecraft:warped_hyphae)
B(-1,77,-5,minecraft:warped_hyphae)
B(-1,78,-5,minecraft:warped_hyphae)
B(-1,79,-5,minecraft:warped_hyphae)
B(-1,80,-5,minecraft:warped_hyphae)
B(-1,22,-4,minecraft:warped_hyphae)
B(-1,23,-4,minecraft:warped_hyphae)
B(-1,24,-4,minecraft:warped_hyphae)
B(-1,25,-4,minecraft:warped_hyphae)
B(-1,26,-4,minecraft:warped_hyphae)
B(-1,27,-4,minecraft:warped_hyphae)
B(-1,28,-4,minecraft:warped_hyphae)
B(-1,29,-4,minecraft:warped_hyphae)
B(-1,30,-4,minecraft:warped_hyphae)
B(-1,31,-4,minecraft:warped_hyphae)
B(-1,32,-4,minecraft:warped_hyphae)
B(-1,33,-4,minecraft:warped_hyphae)
B(-1,67,-4,minecraft:warped_hyphae)
B(-1,68,-4,minecraft:warped_hyphae)
B(-1,69,-4,minecraft:warped_hyphae)
B(-1,70,-4,minecraft:warped_hyphae)
B(-1,71,-4,minecraft:warped_hyphae)
B(-1,72,-4,minecraft:warped_hyphae)
B(-1,73,-4,minecraft:warped_hyphae)
B(-1,74,-4,minecraft:warped_hyphae)
B(-1,75,-4,minecraft:warped_hyphae)
B(-1,76,-4,minecraft:warped_hyphae)
B(-1,77,-4,minecraft:warped_hyphae)
B(-1,78,-4,minecraft:warped_hyphae)
B(-1,79,-4,minecraft:warped_hyphae)
B(-1,80,-4,minecraft:warped_hyphae)
B(-1,21,-3,minecraft:warped_hyphae)
B(-1,22,-3,minecraft:warped_hyphae)
B(-1,23,-3,minecraft:warped_hyphae)
B(-1,24,-3,minecraft:warped_hyphae)
B(-1,25,-3,minecraft:warped_hyphae)
B(-1,26,-3,minecraft:warped_hyphae)
B(-1,27,-3,minecraft:warped_hyphae)
B(-1,28,-3,minecraft:warped_hyphae)
B(-1,29,-3,minecraft:warped_hyphae)
B(-1,30,-3,minecraft:warped_hyphae)
B(-1,31,-3,minecraft:warped_hyphae)
B(-1,32,-3,minecraft:warped_hyphae)
B(-1,67,-3,minecraft:warped_hyphae)
B(-1,68,-3,minecraft:warped_hyphae)
B(-1,69,-3,minecraft:warped_hyphae)
B(-1,70,-3,minecraft:warped_hyphae)
B(-1,71,-3,minecraft:warped_hyphae)
B(-1,72,-3,minecraft:warped_hyphae)
B(-1,73,-3,minecraft:warped_hyphae)
B(-1,74,-3,minecraft:warped_hyphae)
B(-1,75,-3,minecraft:warped_hyphae)
B(-1,76,-3,minecraft:warped_hyphae)
B(-1,77,-3,minecraft:warped_hyphae)
B(-1,78,-3,minecraft:warped_hyphae)
B(-1,79,-3,minecraft:warped_hyphae)
B(-1,20,-2,minecraft:warped_hyphae)
B(-1,21,-2,minecraft:warped_hyphae)
B(-1,22,-2,minecraft:warped_hyphae)
B(-1,23,-2,minecraft:warped_hyphae)
B(-1,24,-2,minecraft:warped_hyphae)
B(-1,25,-2,minecraft:warped_hyphae)
B(-1,26,-2,minecraft:warped_hyphae)
B(-1,27,-2,minecraft:warped_hyphae)
B(-1,28,-2,minecraft:warped_hyphae)
B(-1,29,-2,minecraft:warped_hyphae)
B(-1,30,-2,minecraft:warped_hyphae)
B(-1,31,-2,minecraft:warped_hyphae)
B(-1,32,-2,minecraft:warped_hyphae)
B(-1,68,-2,minecraft:warped_hyphae)
B(-1,69,-2,minecraft:warped_hyphae)
B(-1,70,-2,minecraft:warped_hyphae)
B(-1,71,-2,minecraft:warped_hyphae)
B(-1,72,-2,minecraft:warped_hyphae)
B(-1,73,-2,minecraft:warped_hyphae)
B(-1,74,-2,minecraft:warped_hyphae)
B(-1,75,-2,minecraft:warped_hyphae)
B(-1,76,-2,minecraft:warped_hyphae)
B(-1,77,-2,minecraft:warped_hyphae)
B(-1,78,-2,minecraft:warped_hyphae)
B(-1,19,-1,minecraft:warped_hyphae)
B(-1,20,-1,minecraft:warped_hyphae)
B(-1,21,-1,minecraft:warped_hyphae)
B(-1,22,-1,minecraft:warped_hyphae)
B(-1,23,-1,minecraft:warped_hyphae)
B(-1,24,-1,minecraft:warped_hyphae)
B(-1,25,-1,minecraft:warped_hyphae)
B(-1,26,-1,minecraft:warped_hyphae)
B(-1,27,-1,minecraft:warped_hyphae)
B(-1,28,-1,minecraft:warped_hyphae)
B(-1,29,-1,minecraft:warped_hyphae)
B(-1,30,-1,minecraft:warped_hyphae)
B(-1,31,-1,minecraft:warped_hyphae)
B(-1,70,-1,minecraft:warped_hyphae)
B(-1,71,-1,minecraft:warped_hyphae)
B(-1,72,-1,minecraft:warped_hyphae)
B(-1,73,-1,minecraft:warped_hyphae)
B(-1,74,-1,minecraft:warped_hyphae)
B(-1,75,-1,minecraft:warped_hyphae)
B(-1,76,-1,minecraft:warped_hyphae)
B(-1,77,-1,minecraft:warped_hyphae)
B(-1,18,0,minecraft:warped_hyphae)
B(-1,19,0,minecraft:warped_hyphae)
B(-1,20,0,minecraft:warped_hyphae)
B(-1,21,0,minecraft:warped_hyphae)
B(-1,22,0,minecraft:warped_hyphae)
B(-1,23,0,minecraft:warped_hyphae)
B(-1,24,0,minecraft:warped_hyphae)
B(-1,25,0,minecraft:warped_hyphae)
B(-1,26,0,minecraft:warped_hyphae)
B(-1,27,0,minecraft:warped_hyphae)
B(-1,28,0,minecraft:warped_hyphae)
B(-1,29,0,minecraft:warped_hyphae)
B(-1,30,0,minecraft:warped_hyphae)
B(-1,31,0,minecraft:warped_hyphae)
B(-1,18,1,minecraft:warped_hyphae)
B(-1,19,1,minecraft:warped_hyphae)
B(-1,20,1,minecraft:warped_hyphae)
B(-1,21,1,minecraft:warped_hyphae)
B(-1,22,1,minecraft:warped_hyphae)
B(-1,23,1,minecraft:warped_hyphae)
B(-1,24,1,minecraft:warped_hyphae)
B(-1,25,1,minecraft:warped_hyphae)
B(-1,26,1,minecraft:warped_hyphae)
B(-1,27,1,minecraft:warped_hyphae)
B(-1,28,1,minecraft:warped_hyphae)
B(-1,29,1,minecraft:warped_hyphae)
B(-1,30,1,minecraft:warped_hyphae)
B(-1,18,2,minecraft:warped_hyphae)
B(-1,19,2,minecraft:warped_hyphae)
B(-1,20,2,minecraft:warped_hyphae)
B(-1,21,2,minecraft:warped_hyphae)
B(-1,22,2,minecraft:warped_hyphae)
B(-1,23,2,minecraft:warped_hyphae)
B(-1,24,2,minecraft:warped_hyphae)
B(-1,25,2,minecraft:warped_hyphae)
B(-1,26,2,minecraft:warped_hyphae)
B(-1,27,2,minecraft:warped_hyphae)
B(-1,28,2,minecraft:warped_hyphae)
B(-1,29,2,minecraft:warped_hyphae)
B(-1,30,2,minecraft:warped_hyphae)
B(-1,18,3,minecraft:warped_hyphae)
B(-1,19,3,minecraft:warped_hyphae)
B(-1,20,3,minecraft:warped_hyphae)
B(-1,21,3,minecraft:warped_hyphae)
B(-1,22,3,minecraft:warped_hyphae)
B(-1,23,3,minecraft:warped_hyphae)
B(-1,24,3,minecraft:warped_hyphae)
B(-1,25,3,minecraft:warped_hyphae)
B(-1,26,3,minecraft:warped_hyphae)
B(-1,27,3,minecraft:warped_hyphae)
B(-1,28,3,minecraft:warped_hyphae)
B(-1,29,3,minecraft:warped_hyphae)
B(-1,18,4,minecraft:warped_hyphae)
B(-1,19,4,minecraft:warped_hyphae)
B(-1,20,4,minecraft:warped_hyphae)
B(-1,21,4,minecraft:warped_hyphae)
B(-1,22,4,minecraft:warped_hyphae)
B(-1,23,4,minecraft:warped_hyphae)
B(-1,24,4,minecraft:warped_hyphae)
B(-1,25,4,minecraft:warped_hyphae)
B(-1,26,4,minecraft:warped_hyphae)
B(-1,27,4,minecraft:warped_hyphae)
B(-1,28,4,minecraft:warped_hyphae)
B(-1,19,5,minecraft:warped_hyphae)
B(-1,20,5,minecraft:warped_hyphae)
B(-1,21,5,minecraft:warped_hyphae)
B(-1,22,5,minecraft:warped_hyphae)
B(-1,23,5,minecraft:warped_hyphae)
B(-1,24,5,minecraft:warped_hyphae)
B(-1,25,5,minecraft:warped_hyphae)
B(-1,26,5,minecraft:warped_hyphae)
B(-1,27,5,minecraft:warped_hyphae)
B(0,24,-7,minecraft:warped_hyphae)
B(0,25,-7,minecraft:warped_hyphae)
B(0,26,-7,minecraft:warped_hyphae)
B(0,27,-7,minecraft:warped_hyphae)
B(0,28,-7,minecraft:warped_hyphae)
B(0,29,-7,minecraft:warped_hyphae)
B(0,30,-7,minecraft:warped_hyphae)
B(0,31,-7,minecraft:warped_hyphae)
B(0,32,-7,minecraft:warped_hyphae)
B(0,33,-7,minecraft:warped_hyphae)
B(0,34,-7,minecraft:warped_hyphae)
B(0,35,-7,minecraft:warped_hyphae)
B(0,36,-7,minecraft:warped_hyphae)
B(0,37,-7,minecraft:warped_hyphae)
B(0,38,-7,minecraft:warped_hyphae)
B(0,66,-7,minecraft:warped_hyphae)
B(0,67,-7,minecraft:warped_hyphae)
B(0,68,-7,minecraft:warped_hyphae)
B(0,69,-7,minecraft:warped_hyphae)
B(0,70,-7,minecraft:warped_hyphae)
B(0,71,-7,minecraft:warped_hyphae)
B(0,72,-7,minecraft:warped_hyphae)
B(0,73,-7,minecraft:warped_hyphae)
B(0,74,-7,minecraft:warped_hyphae)
B(0,75,-7,minecraft:warped_hyphae)
B(0,76,-7,minecraft:warped_hyphae)
B(0,77,-7,minecraft:warped_hyphae)
B(0,78,-7,minecraft:warped_hyphae)
B(0,79,-7,minecraft:warped_hyphae)
B(0,80,-7,minecraft:warped_hyphae)
B(0,23,-6,minecraft:warped_hyphae)
B(0,24,-6,minecraft:warped_hyphae)
B(0,25,-6,minecraft:warped_hyphae)
B(0,26,-6,minecraft:warped_hyphae)
B(0,27,-6,minecraft:warped_hyphae)
B(0,28,-6,minecraft:warped_hyphae)
B(0,29,-6,minecraft:warped_hyphae)
B(0,30,-6,minecraft:warped_hyphae)
B(0,31,-6,minecraft:warped_hyphae)
B(0,32,-6,minecraft:warped_hyphae)
B(0,33,-6,minecraft:warped_hyphae)
B(0,34,-6,minecraft:warped_hyphae)
B(0,35,-6,minecraft:warped_hyphae)
B(0,36,-6,minecraft:warped_hyphae)
B(0,37,-6,minecraft:warped_hyphae)
B(0,66,-6,minecraft:warped_hyphae)
B(0,67,-6,minecraft:warped_hyphae)
B(0,68,-6,minecraft:warped_hyphae)
B(0,69,-6,minecraft:warped_hyphae)
B(0,70,-6,minecraft:warped_hyphae)
B(0,71,-6,minecraft:warped_hyphae)
B(0,72,-6,minecraft:warped_hyphae)
B(0,73,-6,minecraft:warped_hyphae)
B(0,74,-6,minecraft:warped_hyphae)
B(0,75,-6,minecraft:warped_hyphae)
B(0,76,-6,minecraft:warped_hyphae)
B(0,77,-6,minecraft:warped_hyphae)
B(0,78,-6,minecraft:warped_hyphae)
B(0,79,-6,minecraft:warped_hyphae)
B(0,80,-6,minecraft:warped_hyphae)
B(0,22,-5,minecraft:warped_hyphae)
B(0,23,-5,minecraft:warped_hyphae)
B(0,24,-5,minecraft:warped_hyphae)
B(0,25,-5,minecraft:warped_hyphae)
B(0,26,-5,minecraft:warped_hyphae)
B(0,27,-5,minecraft:warped_hyphae)
B(0,28,-5,minecraft:warped_hyphae)
B(0,29,-5,minecraft:warped_hyphae)
B(0,30,-5,minecraft:warped_hyphae)
B(0,31,-5,minecraft:warped_hyphae)
B(0,32,-5,minecraft:warped_hyphae)
B(0,33,-5,minecraft:warped_hyphae)
B(0,34,-5,minecraft:warped_hyphae)
B(0,35,-5,minecraft:warped_hyphae)
B(0,66,-5,minecraft:warped_hyphae)
B(0,67,-5,minecraft:warped_hyphae)
B(0,68,-5,minecraft:warped_hyphae)
B(0,69,-5,minecraft:warped_hyphae)
B(0,70,-5,minecraft:warped_hyphae)
B(0,71,-5,minecraft:warped_hyphae)
B(0,72,-5,minecraft:warped_hyphae)
B(0,73,-5,minecraft:warped_hyphae)
B(0,74,-5,minecraft:warped_hyphae)
B(0,75,-5,minecraft:warped_hyphae)
B(0,76,-5,minecraft:warped_hyphae)
B(0,77,-5,minecraft:warped_hyphae)
B(0,78,-5,minecraft:warped_hyphae)
B(0,79,-5,minecraft:warped_hyphae)
B(0,80,-5,minecraft:warped_hyphae)
B(0,22,-4,minecraft:warped_hyphae)
B(0,23,-4,minecraft:warped_hyphae)
B(0,24,-4,minecraft:warped_hyphae)
B(0,25,-4,minecraft:warped_hyphae)
B(0,26,-4,minecraft:warped_hyphae)
B(0,27,-4,minecraft:warped_hyphae)
B(0,28,-4,minecraft:warped_hyphae)
B(0,29,-4,minecraft:warped_hyphae)
B(0,30,-4,minecraft:warped_hyphae)
B(0,31,-4,minecraft:warped_hyphae)
B(0,32,-4,minecraft:warped_hyphae)
B(0,33,-4,minecraft:warped_hyphae)
B(0,34,-4,minecraft:warped_hyphae)
B(0,66,-4,minecraft:warped_hyphae)
B(0,67,-4,minecraft:warped_hyphae)
B(0,68,-4,minecraft:warped_hyphae)
B(0,69,-4,minecraft:warped_hyphae)
B(0,70,-4,minecraft:warped_hyphae)
B(0,71,-4,minecraft:warped_hyphae)
B(0,72,-4,minecraft:warped_hyphae)
B(0,73,-4,minecraft:warped_hyphae)
B(0,74,-4,minecraft:warped_hyphae)
B(0,75,-4,minecraft:warped_hyphae)
B(0,76,-4,minecraft:warped_hyphae)
B(0,77,-4,minecraft:warped_hyphae)
B(0,78,-4,minecraft:warped_hyphae)
B(0,79,-4,minecraft:warped_hyphae)
B(0,21,-3,minecraft:warped_hyphae)
B(0,22,-3,minecraft:warped_hyphae)
B(0,23,-3,minecraft:warped_hyphae)
B(0,24,-3,minecraft:warped_hyphae)
B(0,25,-3,minecraft:warped_hyphae)
B(0,26,-3,minecraft:warped_hyphae)
B(0,27,-3,minecraft:warped_hyphae)
B(0,28,-3,minecraft:warped_hyphae)
B(0,29,-3,minecraft:warped_hyphae)
B(0,30,-3,minecraft:warped_hyphae)
B(0,31,-3,minecraft:warped_hyphae)
B(0,32,-3,minecraft:warped_hyphae)
B(0,33,-3,minecraft:warped_hyphae)
B(0,67,-3,minecraft:warped_hyphae)
B(0,68,-3,minecraft:warped_hyphae)
B(0,69,-3,minecraft:warped_hyphae)
B(0,70,-3,minecraft:warped_hyphae)
B(0,71,-3,minecraft:warped_hyphae)
B(0,72,-3,minecraft:warped_hyphae)
B(0,73,-3,minecraft:warped_hyphae)
B(0,74,-3,minecraft:warped_hyphae)
B(0,75,-3,minecraft:warped_hyphae)
B(0,76,-3,minecraft:warped_hyphae)
B(0,77,-3,minecraft:warped_hyphae)
B(0,78,-3,minecraft:warped_hyphae)
B(0,79,-3,minecraft:warped_hyphae)
B(0,21,-2,minecraft:warped_hyphae)
B(0,22,-2,minecraft:warped_hyphae)
B(0,23,-2,minecraft:warped_hyphae)
B(0,24,-2,minecraft:warped_hyphae)
B(0,25,-2,minecraft:warped_hyphae)
B(0,26,-2,minecraft:warped_hyphae)
B(0,27,-2,minecraft:warped_hyphae)
B(0,28,-2,minecraft:warped_hyphae)
B(0,29,-2,minecraft:warped_hyphae)
B(0,30,-2,minecraft:warped_hyphae)
B(0,31,-2,minecraft:warped_hyphae)
B(0,32,-2,minecraft:warped_hyphae)
B(0,68,-2,minecraft:warped_hyphae)
B(0,69,-2,minecraft:warped_hyphae)
B(0,70,-2,minecraft:warped_hyphae)
B(0,71,-2,minecraft:warped_hyphae)
B(0,72,-2,minecraft:warped_hyphae)
B(0,73,-2,minecraft:warped_hyphae)
B(0,74,-2,minecraft:warped_hyphae)
B(0,75,-2,minecraft:warped_hyphae)
B(0,76,-2,minecraft:warped_hyphae)
B(0,77,-2,minecraft:warped_hyphae)
B(0,78,-2,minecraft:warped_hyphae)
B(0,20,-1,minecraft:warped_hyphae)
B(0,21,-1,minecraft:warped_hyphae)
B(0,22,-1,minecraft:warped_hyphae)
B(0,23,-1,minecraft:warped_hyphae)
B(0,24,-1,minecraft:warped_hyphae)
B(0,25,-1,minecraft:warped_hyphae)
B(0,26,-1,minecraft:warped_hyphae)
B(0,27,-1,minecraft:warped_hyphae)
B(0,28,-1,minecraft:warped_hyphae)
B(0,29,-1,minecraft:warped_hyphae)
B(0,30,-1,minecraft:warped_hyphae)
B(0,31,-1,minecraft:warped_hyphae)
B(0,32,-1,minecraft:warped_hyphae)
B(0,69,-1,minecraft:warped_hyphae)
B(0,70,-1,minecraft:warped_hyphae)
B(0,71,-1,minecraft:warped_hyphae)
B(0,72,-1,minecraft:warped_hyphae)
B(0,73,-1,minecraft:warped_hyphae)
B(0,74,-1,minecraft:warped_hyphae)
B(0,75,-1,minecraft:warped_hyphae)
B(0,76,-1,minecraft:warped_hyphae)
B(0,20,0,minecraft:warped_hyphae)
B(0,21,0,minecraft:warped_hyphae)
B(0,22,0,minecraft:warped_hyphae)
B(0,23,0,minecraft:warped_hyphae)
B(0,24,0,minecraft:warped_hyphae)
B(0,25,0,minecraft:warped_hyphae)
B(0,26,0,minecraft:warped_hyphae)
B(0,27,0,minecraft:warped_hyphae)
B(0,28,0,minecraft:warped_hyphae)
B(0,29,0,minecraft:warped_hyphae)
B(0,30,0,minecraft:warped_hyphae)
B(0,31,0,minecraft:warped_hyphae)
B(0,19,1,minecraft:warped_hyphae)
B(0,20,1,minecraft:warped_hyphae)
B(0,21,1,minecraft:warped_hyphae)
B(0,22,1,minecraft:warped_hyphae)
B(0,23,1,minecraft:warped_hyphae)
B(0,24,1,minecraft:warped_hyphae)
B(0,25,1,minecraft:warped_hyphae)
B(0,26,1,minecraft:warped_hyphae)
B(0,27,1,minecraft:warped_hyphae)
B(0,28,1,minecraft:warped_hyphae)
B(0,29,1,minecraft:warped_hyphae)
B(0,30,1,minecraft:warped_hyphae)
B(0,19,2,minecraft:warped_hyphae)
B(0,20,2,minecraft:warped_hyphae)
B(0,21,2,minecraft:warped_hyphae)
B(0,22,2,minecraft:warped_hyphae)
B(0,23,2,minecraft:warped_hyphae)
B(0,24,2,minecraft:warped_hyphae)
B(0,25,2,minecraft:warped_hyphae)
B(0,26,2,minecraft:warped_hyphae)
B(0,27,2,minecraft:warped_hyphae)
B(0,28,2,minecraft:warped_hyphae)
B(0,29,2,minecraft:warped_hyphae)
B(0,19,3,minecraft:warped_hyphae)
B(0,20,3,minecraft:warped_hyphae)
B(0,21,3,minecraft:warped_hyphae)
B(0,22,3,minecraft:warped_hyphae)
B(0,23,3,minecraft:warped_hyphae)
B(0,24,3,minecraft:warped_hyphae)
B(0,25,3,minecraft:warped_hyphae)
B(0,26,3,minecraft:warped_hyphae)
B(0,27,3,minecraft:warped_hyphae)
B(0,28,3,minecraft:warped_hyphae)
B(0,29,3,minecraft:warped_hyphae)
B(0,20,4,minecraft:warped_hyphae)
B(0,21,4,minecraft:warped_hyphae)
B(0,22,4,minecraft:warped_hyphae)
B(0,23,4,minecraft:warped_hyphae)
B(0,24,4,minecraft:warped_hyphae)
B(0,25,4,minecraft:warped_hyphae)
B(0,26,4,minecraft:warped_hyphae)
B(0,27,4,minecraft:warped_hyphae)
B(0,28,4,minecraft:warped_hyphae)
B(0,24,5,minecraft:warped_hyphae)
B(0,25,5,minecraft:warped_hyphae)
B(0,26,5,minecraft:warped_hyphae)
B(1,20,-7,minecraft:warped_hyphae)
B(1,21,-7,minecraft:warped_hyphae)
B(1,22,-7,minecraft:warped_hyphae)
B(1,23,-7,minecraft:warped_hyphae)
B(1,24,-7,minecraft:warped_hyphae)
B(1,25,-7,minecraft:warped_hyphae)
B(1,26,-7,minecraft:warped_hyphae)
B(1,27,-7,minecraft:warped_hyphae)
B(1,28,-7,minecraft:warped_hyphae)
B(1,29,-7,minecraft:warped_hyphae)
B(1,30,-7,minecraft:warped_hyphae)
B(1,31,-7,minecraft:warped_hyphae)
B(1,32,-7,minecraft:warped_hyphae)
B(1,33,-7,minecraft:warped_hyphae)
B(1,34,-7,minecraft:warped_hyphae)
B(1,35,-7,minecraft:warped_hyphae)
B(1,36,-7,minecraft:warped_hyphae)
B(1,37,-7,minecraft:warped_hyphae)
B(1,38,-7,minecraft:warped_hyphae)
B(1,39,-7,minecraft:warped_hyphae)
B(1,66,-7,minecraft:warped_hyphae)
B(1,67,-7,minecraft:warped_hyphae)
B(1,68,-7,minecraft:warped_hyphae)
B(1,69,-7,minecraft:warped_hyphae)
B(1,70,-7,minecraft:warped_hyphae)
B(1,71,-7,minecraft:warped_hyphae)
B(1,72,-7,minecraft:warped_hyphae)
B(1,73,-7,minecraft:warped_hyphae)
B(1,74,-7,minecraft:warped_hyphae)
B(1,75,-7,minecraft:warped_hyphae)
B(1,76,-7,minecraft:warped_hyphae)
B(1,77,-7,minecraft:warped_hyphae)
B(1,78,-7,minecraft:warped_hyphae)
B(1,79,-7,minecraft:warped_hyphae)
B(1,19,-6,minecraft:warped_hyphae)
B(1,20,-6,minecraft:warped_hyphae)
B(1,21,-6,minecraft:warped_hyphae)
B(1,22,-6,minecraft:warped_hyphae)
B(1,23,-6,minecraft:warped_hyphae)
B(1,24,-6,minecraft:warped_hyphae)
B(1,25,-6,minecraft:warped_hyphae)
B(1,26,-6,minecraft:warped_hyphae)
B(1,27,-6,minecraft:warped_hyphae)
B(1,28,-6,minecraft:warped_hyphae)
B(1,29,-6,minecraft:warped_hyphae)
B(1,30,-6,minecraft:warped_hyphae)
B(1,31,-6,minecraft:warped_hyphae)
B(1,32,-6,minecraft:warped_hyphae)
B(1,33,-6,minecraft:warped_hyphae)
B(1,34,-6,minecraft:warped_hyphae)
B(1,35,-6,minecraft:warped_hyphae)
B(1,36,-6,minecraft:warped_hyphae)
B(1,37,-6,minecraft:warped_hyphae)
B(1,38,-6,minecraft:warped_hyphae)
B(1,66,-6,minecraft:warped_hyphae)
B(1,67,-6,minecraft:warped_hyphae)
B(1,68,-6,minecraft:warped_hyphae)
B(1,69,-6,minecraft:warped_hyphae)
B(1,70,-6,minecraft:warped_hyphae)
B(1,71,-6,minecraft:warped_hyphae)
B(1,72,-6,minecraft:warped_hyphae)
B(1,73,-6,minecraft:warped_hyphae)
B(1,74,-6,minecraft:warped_hyphae)
B(1,75,-6,minecraft:warped_hyphae)
B(1,76,-6,minecraft:warped_hyphae)
B(1,77,-6,minecraft:warped_hyphae)
B(1,78,-6,minecraft:warped_hyphae)
B(1,79,-6,minecraft:warped_hyphae)
B(1,19,-5,minecraft:warped_hyphae)
B(1,20,-5,minecraft:warped_hyphae)
B(1,21,-5,minecraft:warped_hyphae)
B(1,22,-5,minecraft:warped_hyphae)
B(1,23,-5,minecraft:warped_hyphae)
B(1,24,-5,minecraft:warped_hyphae)
B(1,25,-5,minecraft:warped_hyphae)
B(1,26,-5,minecraft:warped_hyphae)
B(1,27,-5,minecraft:warped_hyphae)
B(1,28,-5,minecraft:warped_hyphae)
B(1,29,-5,minecraft:warped_hyphae)
B(1,30,-5,minecraft:warped_hyphae)
B(1,31,-5,minecraft:warped_hyphae)
B(1,32,-5,minecraft:warped_hyphae)
B(1,33,-5,minecraft:warped_hyphae)
B(1,34,-5,minecraft:warped_hyphae)
B(1,35,-5,minecraft:warped_hyphae)
B(1,36,-5,minecraft:warped_hyphae)
B(1,66,-5,minecraft:warped_hyphae)
B(1,67,-5,minecraft:warped_hyphae)
B(1,68,-5,minecraft:warped_hyphae)
B(1,69,-5,minecraft:warped_hyphae)
B(1,70,-5,minecraft:warped_hyphae)
B(1,71,-5,minecraft:warped_hyphae)
B(1,72,-5,minecraft:warped_hyphae)
B(1,73,-5,minecraft:warped_hyphae)
B(1,74,-5,minecraft:warped_hyphae)
B(1,75,-5,minecraft:warped_hyphae)
B(1,76,-5,minecraft:warped_hyphae)
B(1,77,-5,minecraft:warped_hyphae)
B(1,78,-5,minecraft:warped_hyphae)
B(1,79,-5,minecraft:warped_hyphae)
B(1,19,-4,minecraft:warped_hyphae)
B(1,20,-4,minecraft:warped_hyphae)
B(1,21,-4,minecraft:warped_hyphae)
B(1,22,-4,minecraft:warped_hyphae)
B(1,23,-4,minecraft:warped_hyphae)
B(1,24,-4,minecraft:warped_hyphae)
B(1,25,-4,minecraft:warped_hyphae)
B(1,26,-4,minecraft:warped_hyphae)
B(1,27,-4,minecraft:warped_hyphae)
B(1,28,-4,minecraft:warped_hyphae)
B(1,29,-4,minecraft:warped_hyphae)
B(1,30,-4,minecraft:warped_hyphae)
B(1,31,-4,minecraft:warped_hyphae)
B(1,32,-4,minecraft:warped_hyphae)
B(1,33,-4,minecraft:warped_hyphae)
B(1,34,-4,minecraft:warped_hyphae)
B(1,35,-4,minecraft:warped_hyphae)
B(1,66,-4,minecraft:warped_hyphae)
B(1,67,-4,minecraft:warped_hyphae)
B(1,68,-4,minecraft:warped_hyphae)
B(1,69,-4,minecraft:warped_hyphae)
B(1,70,-4,minecraft:warped_hyphae)
B(1,71,-4,minecraft:warped_hyphae)
B(1,72,-4,minecraft:warped_hyphae)
B(1,73,-4,minecraft:warped_hyphae)
B(1,74,-4,minecraft:warped_hyphae)
B(1,75,-4,minecraft:warped_hyphae)
B(1,76,-4,minecraft:warped_hyphae)
B(1,77,-4,minecraft:warped_hyphae)
B(1,78,-4,minecraft:warped_hyphae)
B(1,79,-4,minecraft:warped_hyphae)
B(1,20,-3,minecraft:warped_hyphae)
B(1,21,-3,minecraft:warped_hyphae)
B(1,22,-3,minecraft:warped_hyphae)
B(1,23,-3,minecraft:warped_hyphae)
B(1,24,-3,minecraft:warped_hyphae)
B(1,25,-3,minecraft:warped_hyphae)
B(1,26,-3,minecraft:warped_hyphae)
B(1,27,-3,minecraft:warped_hyphae)
B(1,28,-3,minecraft:warped_hyphae)
B(1,29,-3,minecraft:warped_hyphae)
B(1,30,-3,minecraft:warped_hyphae)
B(1,31,-3,minecraft:warped_hyphae)
B(1,32,-3,minecraft:warped_hyphae)
B(1,33,-3,minecraft:warped_hyphae)
B(1,34,-3,minecraft:warped_hyphae)
B(1,67,-3,minecraft:warped_hyphae)
B(1,68,-3,minecraft:warped_hyphae)
B(1,69,-3,minecraft:warped_hyphae)
B(1,70,-3,minecraft:warped_hyphae)
B(1,71,-3,minecraft:warped_hyphae)
B(1,72,-3,minecraft:warped_hyphae)
B(1,73,-3,minecraft:warped_hyphae)
B(1,74,-3,minecraft:warped_hyphae)
B(1,75,-3,minecraft:warped_hyphae)
B(1,76,-3,minecraft:warped_hyphae)
B(1,77,-3,minecraft:warped_hyphae)
B(1,78,-3,minecraft:warped_hyphae)
B(1,21,-2,minecraft:warped_hyphae)
B(1,22,-2,minecraft:warped_hyphae)
B(1,23,-2,minecraft:warped_hyphae)
B(1,24,-2,minecraft:warped_hyphae)
B(1,25,-2,minecraft:warped_hyphae)
B(1,26,-2,minecraft:warped_hyphae)
B(1,27,-2,minecraft:warped_hyphae)
B(1,28,-2,minecraft:warped_hyphae)
B(1,29,-2,minecraft:warped_hyphae)
B(1,30,-2,minecraft:warped_hyphae)
B(1,31,-2,minecraft:warped_hyphae)
B(1,32,-2,minecraft:warped_hyphae)
B(1,68,-2,minecraft:warped_hyphae)
B(1,69,-2,minecraft:warped_hyphae)
B(1,70,-2,minecraft:warped_hyphae)
B(1,71,-2,minecraft:warped_hyphae)
B(1,72,-2,minecraft:warped_hyphae)
B(1,73,-2,minecraft:warped_hyphae)
B(1,74,-2,minecraft:warped_hyphae)
B(1,75,-2,minecraft:warped_hyphae)
B(1,76,-2,minecraft:warped_hyphae)
B(1,77,-2,minecraft:warped_hyphae)
B(1,21,-1,minecraft:warped_hyphae)
B(1,22,-1,minecraft:warped_hyphae)
B(1,23,-1,minecraft:warped_hyphae)
B(1,24,-1,minecraft:warped_hyphae)
B(1,25,-1,minecraft:warped_hyphae)
B(1,26,-1,minecraft:warped_hyphae)
B(1,27,-1,minecraft:warped_hyphae)
B(1,28,-1,minecraft:warped_hyphae)
B(1,29,-1,minecraft:warped_hyphae)
B(1,30,-1,minecraft:warped_hyphae)
B(1,31,-1,minecraft:warped_hyphae)
B(1,32,-1,minecraft:warped_hyphae)
B(1,69,-1,minecraft:warped_hyphae)
B(1,70,-1,minecraft:warped_hyphae)
B(1,71,-1,minecraft:warped_hyphae)
B(1,72,-1,minecraft:warped_hyphae)
B(1,73,-1,minecraft:warped_hyphae)
B(1,21,0,minecraft:warped_hyphae)
B(1,22,0,minecraft:warped_hyphae)
B(1,23,0,minecraft:warped_hyphae)
B(1,24,0,minecraft:warped_hyphae)
B(1,25,0,minecraft:warped_hyphae)
B(1,26,0,minecraft:warped_hyphae)
B(1,27,0,minecraft:warped_hyphae)
B(1,28,0,minecraft:warped_hyphae)
B(1,29,0,minecraft:warped_hyphae)
B(1,30,0,minecraft:warped_hyphae)
B(1,31,0,minecraft:warped_hyphae)
B(1,21,1,minecraft:warped_hyphae)
B(1,22,1,minecraft:warped_hyphae)
B(1,23,1,minecraft:warped_hyphae)
B(1,24,1,minecraft:warped_hyphae)
B(1,25,1,minecraft:warped_hyphae)
B(1,26,1,minecraft:warped_hyphae)
B(1,27,1,minecraft:warped_hyphae)
B(1,28,1,minecraft:warped_hyphae)
B(1,29,1,minecraft:warped_hyphae)
B(1,30,1,minecraft:warped_hyphae)
B(1,21,2,minecraft:warped_hyphae)
B(1,22,2,minecraft:warped_hyphae)
B(1,23,2,minecraft:warped_hyphae)
B(1,24,2,minecraft:warped_hyphae)
B(1,25,2,minecraft:warped_hyphae)
B(1,26,2,minecraft:warped_hyphae)
B(1,27,2,minecraft:warped_hyphae)
B(1,28,2,minecraft:warped_hyphae)
B(1,29,2,minecraft:warped_hyphae)
B(1,22,3,minecraft:warped_hyphae)
B(1,23,3,minecraft:warped_hyphae)
B(1,24,3,minecraft:warped_hyphae)
B(1,25,3,minecraft:warped_hyphae)
B(1,26,3,minecraft:warped_hyphae)
B(1,27,3,minecraft:warped_hyphae)
B(1,28,3,minecraft:warped_hyphae)
B(1,23,4,minecraft:warped_hyphae)
B(1,24,4,minecraft:warped_hyphae)
B(1,25,4,minecraft:warped_hyphae)
B(1,26,4,minecraft:warped_hyphae)
B(1,27,4,minecraft:warped_hyphae)
B(2,13,-7,minecraft:warped_hyphae)
B(2,14,-7,minecraft:warped_hyphae)
B(2,15,-7,minecraft:warped_hyphae)
B(2,16,-7,minecraft:warped_hyphae)
B(2,17,-7,minecraft:warped_hyphae)
B(2,18,-7,minecraft:warped_hyphae)
B(2,19,-7,minecraft:warped_hyphae)
B(2,20,-7,minecraft:warped_hyphae)
B(2,21,-7,minecraft:warped_hyphae)
B(2,22,-7,minecraft:warped_hyphae)
B(2,23,-7,minecraft:warped_hyphae)
B(2,24,-7,minecraft:warped_hyphae)
B(2,25,-7,minecraft:warped_hyphae)
B(2,26,-7,minecraft:warped_hyphae)
B(2,27,-7,minecraft:warped_hyphae)
B(2,28,-7,minecraft:warped_hyphae)
B(2,29,-7,minecraft:warped_hyphae)
B(2,30,-7,minecraft:warped_hyphae)
B(2,31,-7,minecraft:warped_hyphae)
B(2,32,-7,minecraft:warped_hyphae)
B(2,33,-7,minecraft:warped_hyphae)
B(2,34,-7,minecraft:warped_hyphae)
B(2,35,-7,minecraft:warped_hyphae)
B(2,36,-7,minecraft:warped_hyphae)
B(2,37,-7,minecraft:warped_hyphae)
B(2,38,-7,minecraft:warped_hyphae)
B(2,39,-7,minecraft:warped_hyphae)
B(2,66,-7,minecraft:warped_hyphae)
B(2,67,-7,minecraft:warped_hyphae)
B(2,68,-7,minecraft:warped_hyphae)
B(2,69,-7,minecraft:warped_hyphae)
B(2,70,-7,minecraft:warped_hyphae)
B(2,71,-7,minecraft:warped_hyphae)
B(2,72,-7,minecraft:warped_hyphae)
B(2,73,-7,minecraft:warped_hyphae)
B(2,74,-7,minecraft:warped_hyphae)
B(2,75,-7,minecraft:warped_hyphae)
B(2,76,-7,minecraft:warped_hyphae)
B(2,77,-7,minecraft:warped_hyphae)
B(2,78,-7,minecraft:warped_hyphae)
B(2,14,-6,minecraft:warped_hyphae)
B(2,15,-6,minecraft:warped_hyphae)
B(2,16,-6,minecraft:warped_hyphae)
B(2,17,-6,minecraft:warped_hyphae)
B(2,18,-6,minecraft:warped_hyphae)
B(2,19,-6,minecraft:warped_hyphae)
B(2,20,-6,minecraft:warped_hyphae)
B(2,21,-6,minecraft:warped_hyphae)
B(2,22,-6,minecraft:warped_hyphae)
B(2,23,-6,minecraft:warped_hyphae)
B(2,24,-6,minecraft:warped_hyphae)
B(2,25,-6,minecraft:warped_hyphae)
B(2,26,-6,minecraft:warped_hyphae)
B(2,27,-6,minecraft:warped_hyphae)
B(2,28,-6,minecraft:warped_hyphae)
B(2,29,-6,minecraft:warped_hyphae)
B(2,30,-6,minecraft:warped_hyphae)
B(2,31,-6,minecraft:warped_hyphae)
B(2,32,-6,minecraft:warped_hyphae)
B(2,33,-6,minecraft:warped_hyphae)
B(2,34,-6,minecraft:warped_hyphae)
B(2,35,-6,minecraft:warped_hyphae)
B(2,36,-6,minecraft:warped_hyphae)
B(2,37,-6,minecraft:warped_hyphae)
B(2,38,-6,minecraft:warped_hyphae)
B(2,66,-6,minecraft:warped_hyphae)
B(2,67,-6,minecraft:warped_hyphae)
B(2,68,-6,minecraft:warped_hyphae)
B(2,69,-6,minecraft:warped_hyphae)
B(2,70,-6,minecraft:warped_hyphae)
B(2,71,-6,minecraft:warped_hyphae)
B(2,72,-6,minecraft:warped_hyphae)
B(2,73,-6,minecraft:warped_hyphae)
B(2,74,-6,minecraft:warped_hyphae)
B(2,75,-6,minecraft:warped_hyphae)
B(2,76,-6,minecraft:warped_hyphae)
B(2,77,-6,minecraft:warped_hyphae)
B(2,78,-6,minecraft:warped_hyphae)
B(2,14,-5,minecraft:warped_hyphae)
B(2,15,-5,minecraft:warped_hyphae)
B(2,16,-5,minecraft:warped_hyphae)
B(2,17,-5,minecraft:warped_hyphae)
B(2,18,-5,minecraft:warped_hyphae)
B(2,19,-5,minecraft:warped_hyphae)
B(2,20,-5,minecraft:warped_hyphae)
B(2,21,-5,minecraft:warped_hyphae)
B(2,22,-5,minecraft:warped_hyphae)
B(2,23,-5,minecraft:warped_hyphae)
B(2,24,-5,minecraft:warped_hyphae)
B(2,25,-5,minecraft:warped_hyphae)
B(2,26,-5,minecraft:warped_hyphae)
B(2,27,-5,minecraft:warped_hyphae)
B(2,28,-5,minecraft:warped_hyphae)
B(2,29,-5,minecraft:warped_hyphae)
B(2,30,-5,minecraft:warped_hyphae)
B(2,31,-5,minecraft:warped_hyphae)
B(2,32,-5,minecraft:warped_hyphae)
B(2,33,-5,minecraft:warped_hyphae)
B(2,34,-5,minecraft:warped_hyphae)
B(2,35,-5,minecraft:warped_hyphae)
B(2,36,-5,minecraft:warped_hyphae)
B(2,37,-5,minecraft:warped_hyphae)
B(2,66,-5,minecraft:warped_hyphae)
B(2,67,-5,minecraft:warped_hyphae)
B(2,68,-5,minecraft:warped_hyphae)
B(2,69,-5,minecraft:warped_hyphae)
B(2,70,-5,minecraft:warped_hyphae)
B(2,71,-5,minecraft:warped_hyphae)
B(2,72,-5,minecraft:warped_hyphae)
B(2,73,-5,minecraft:warped_hyphae)
B(2,74,-5,minecraft:warped_hyphae)
B(2,75,-5,minecraft:warped_hyphae)
B(2,76,-5,minecraft:warped_hyphae)
B(2,77,-5,minecraft:warped_hyphae)
B(2,78,-5,minecraft:warped_hyphae)
B(2,14,-4,minecraft:warped_hyphae)
B(2,15,-4,minecraft:warped_hyphae)
B(2,16,-4,minecraft:warped_hyphae)
B(2,17,-4,minecraft:warped_hyphae)
B(2,18,-4,minecraft:warped_hyphae)
B(2,19,-4,minecraft:warped_hyphae)
B(2,20,-4,minecraft:warped_hyphae)
B(2,21,-4,minecraft:warped_hyphae)
B(2,22,-4,minecraft:warped_hyphae)
B(2,23,-4,minecraft:warped_hyphae)
B(2,24,-4,minecraft:warped_hyphae)
B(2,25,-4,minecraft:warped_hyphae)
B(2,26,-4,minecraft:warped_hyphae)
B(2,27,-4,minecraft:warped_hyphae)
B(2,28,-4,minecraft:warped_hyphae)
B(2,29,-4,minecraft:warped_hyphae)
B(2,30,-4,minecraft:warped_hyphae)
B(2,31,-4,minecraft:warped_hyphae)
B(2,32,-4,minecraft:warped_hyphae)
B(2,33,-4,minecraft:warped_hyphae)
B(2,34,-4,minecraft:warped_hyphae)
B(2,35,-4,minecraft:warped_hyphae)
B(2,66,-4,minecraft:warped_hyphae)
B(2,67,-4,minecraft:warped_hyphae)
B(2,68,-4,minecraft:warped_hyphae)
B(2,69,-4,minecraft:warped_hyphae)
B(2,70,-4,minecraft:warped_hyphae)
B(2,71,-4,minecraft:warped_hyphae)
B(2,72,-4,minecraft:warped_hyphae)
B(2,73,-4,minecraft:warped_hyphae)
B(2,74,-4,minecraft:warped_hyphae)
B(2,75,-4,minecraft:warped_hyphae)
B(2,76,-4,minecraft:warped_hyphae)
B(2,77,-4,minecraft:warped_hyphae)
B(2,78,-4,minecraft:warped_hyphae)
B(2,15,-3,minecraft:warped_hyphae)
B(2,16,-3,minecraft:warped_hyphae)
B(2,17,-3,minecraft:warped_hyphae)
B(2,18,-3,minecraft:warped_hyphae)
B(2,19,-3,minecraft:warped_hyphae)
B(2,20,-3,minecraft:warped_hyphae)
B(2,21,-3,minecraft:warped_hyphae)
B(2,22,-3,minecraft:warped_hyphae)
B(2,23,-3,minecraft:warped_hyphae)
B(2,24,-3,minecraft:warped_hyphae)
B(2,25,-3,minecraft:warped_hyphae)
B(2,26,-3,minecraft:warped_hyphae)
B(2,27,-3,minecraft:warped_hyphae)
B(2,28,-3,minecraft:warped_hyphae)
B(2,29,-3,minecraft:warped_hyphae)
B(2,30,-3,minecraft:warped_hyphae)
B(2,31,-3,minecraft:warped_hyphae)
B(2,32,-3,minecraft:warped_hyphae)
B(2,33,-3,minecraft:warped_hyphae)
B(2,34,-3,minecraft:warped_hyphae)
B(2,67,-3,minecraft:warped_hyphae)
B(2,68,-3,minecraft:warped_hyphae)
B(2,69,-3,minecraft:warped_hyphae)
B(2,70,-3,minecraft:warped_hyphae)
B(2,71,-3,minecraft:warped_hyphae)
B(2,72,-3,minecraft:warped_hyphae)
B(2,73,-3,minecraft:warped_hyphae)
B(2,74,-3,minecraft:warped_hyphae)
B(2,75,-3,minecraft:warped_hyphae)
B(2,76,-3,minecraft:warped_hyphae)
B(2,77,-3,minecraft:warped_hyphae)
B(2,19,-2,minecraft:warped_hyphae)
B(2,20,-2,minecraft:warped_hyphae)
B(2,21,-2,minecraft:warped_hyphae)
B(2,22,-2,minecraft:warped_hyphae)
B(2,23,-2,minecraft:warped_hyphae)
B(2,24,-2,minecraft:warped_hyphae)
B(2,25,-2,minecraft:warped_hyphae)
B(2,26,-2,minecraft:warped_hyphae)
B(2,27,-2,minecraft:warped_hyphae)
B(2,28,-2,minecraft:warped_hyphae)
B(2,29,-2,minecraft:warped_hyphae)
B(2,30,-2,minecraft:warped_hyphae)
B(2,31,-2,minecraft:warped_hyphae)
B(2,32,-2,minecraft:warped_hyphae)
B(2,33,-2,minecraft:warped_hyphae)
B(2,68,-2,minecraft:warped_hyphae)
B(2,69,-2,minecraft:warped_hyphae)
B(2,70,-2,minecraft:warped_hyphae)
B(2,71,-2,minecraft:warped_hyphae)
B(2,72,-2,minecraft:warped_hyphae)
B(2,73,-2,minecraft:warped_hyphae)
B(2,74,-2,minecraft:warped_hyphae)
B(2,22,-1,minecraft:warped_hyphae)
B(2,23,-1,minecraft:warped_hyphae)
B(2,24,-1,minecraft:warped_hyphae)
B(2,25,-1,minecraft:warped_hyphae)
B(2,26,-1,minecraft:warped_hyphae)
B(2,27,-1,minecraft:warped_hyphae)
B(2,28,-1,minecraft:warped_hyphae)
B(2,29,-1,minecraft:warped_hyphae)
B(2,30,-1,minecraft:warped_hyphae)
B(2,31,-1,minecraft:warped_hyphae)
B(2,32,-1,minecraft:warped_hyphae)
B(2,69,-1,minecraft:warped_hyphae)
B(2,70,-1,minecraft:warped_hyphae)
B(2,71,-1,minecraft:warped_hyphae)
B(2,72,-1,minecraft:warped_hyphae)
B(2,73,-1,minecraft:warped_hyphae)
B(2,22,0,minecraft:warped_hyphae)
B(2,23,0,minecraft:warped_hyphae)
B(2,24,0,minecraft:warped_hyphae)
B(2,25,0,minecraft:warped_hyphae)
B(2,26,0,minecraft:warped_hyphae)
B(2,27,0,minecraft:warped_hyphae)
B(2,28,0,minecraft:warped_hyphae)
B(2,29,0,minecraft:warped_hyphae)
B(2,30,0,minecraft:warped_hyphae)
B(2,31,0,minecraft:warped_hyphae)
B(2,22,1,minecraft:warped_hyphae)
B(2,23,1,minecraft:warped_hyphae)
B(2,24,1,minecraft:warped_hyphae)
B(2,25,1,minecraft:warped_hyphae)
B(2,26,1,minecraft:warped_hyphae)
B(2,27,1,minecraft:warped_hyphae)
B(2,28,1,minecraft:warped_hyphae)
B(2,29,1,minecraft:warped_hyphae)
B(2,30,1,minecraft:warped_hyphae)
B(2,22,2,minecraft:warped_hyphae)
B(2,23,2,minecraft:warped_hyphae)
B(2,24,2,minecraft:warped_hyphae)
B(2,25,2,minecraft:warped_hyphae)
B(2,26,2,minecraft:warped_hyphae)
B(2,27,2,minecraft:warped_hyphae)
B(2,28,2,minecraft:warped_hyphae)
B(2,29,2,minecraft:warped_hyphae)
B(2,23,3,minecraft:warped_hyphae)
B(2,24,3,minecraft:warped_hyphae)
B(2,25,3,minecraft:warped_hyphae)
B(2,26,3,minecraft:warped_hyphae)
B(2,27,3,minecraft:warped_hyphae)
B(3,0,-7,minecraft:warped_hyphae)
B(3,1,-7,minecraft:warped_hyphae)
B(3,2,-7,minecraft:warped_hyphae)
B(3,3,-7,minecraft:warped_hyphae)
B(3,4,-7,minecraft:warped_hyphae)
B(3,5,-7,minecraft:warped_hyphae)
B(3,6,-7,minecraft:warped_hyphae)
B(3,7,-7,minecraft:warped_hyphae)
B(3,8,-7,minecraft:warped_hyphae)
B(3,9,-7,minecraft:warped_hyphae)
B(3,10,-7,minecraft:warped_hyphae)
B(3,11,-7,minecraft:warped_hyphae)
B(3,12,-7,minecraft:warped_hyphae)
B(3,13,-7,minecraft:warped_hyphae)
B(3,14,-7,minecraft:warped_hyphae)
B(3,15,-7,minecraft:warped_hyphae)
B(3,16,-7,minecraft:warped_hyphae)
B(3,17,-7,minecraft:warped_hyphae)
B(3,18,-7,minecraft:warped_hyphae)
B(3,19,-7,minecraft:warped_hyphae)
B(3,20,-7,minecraft:warped_hyphae)
B(3,21,-7,minecraft:warped_hyphae)
B(3,22,-7,minecraft:warped_hyphae)
B(3,23,-7,minecraft:warped_hyphae)
B(3,24,-7,minecraft:warped_hyphae)
B(3,25,-7,minecraft:warped_hyphae)
B(3,26,-7,minecraft:warped_hyphae)
B(3,27,-7,minecraft:warped_hyphae)
B(3,28,-7,minecraft:warped_hyphae)
B(3,29,-7,minecraft:warped_hyphae)
B(3,30,-7,minecraft:warped_hyphae)
B(3,31,-7,minecraft:warped_hyphae)
B(3,32,-7,minecraft:warped_hyphae)
B(3,33,-7,minecraft:warped_hyphae)
B(3,34,-7,minecraft:warped_hyphae)
B(3,35,-7,minecraft:warped_hyphae)
B(3,36,-7,minecraft:warped_hyphae)
B(3,37,-7,minecraft:warped_hyphae)
B(3,38,-7,minecraft:warped_hyphae)
B(3,39,-7,minecraft:warped_hyphae)
B(3,66,-7,minecraft:warped_hyphae)
B(3,67,-7,minecraft:warped_hyphae)
B(3,68,-7,minecraft:warped_hyphae)
B(3,69,-7,minecraft:warped_hyphae)
B(3,70,-7,minecraft:warped_hyphae)
B(3,71,-7,minecraft:warped_hyphae)
B(3,72,-7,minecraft:warped_hyphae)
B(3,73,-7,minecraft:warped_hyphae)
B(3,74,-7,minecraft:warped_hyphae)
B(3,75,-7,minecraft:warped_hyphae)
B(3,76,-7,minecraft:warped_hyphae)
B(3,77,-7,minecraft:warped_hyphae)
B(3,0,-6,minecraft:warped_hyphae)
B(3,1,-6,minecraft:warped_hyphae)
B(3,2,-6,minecraft:warped_hyphae)
B(3,3,-6,minecraft:warped_hyphae)
B(3,4,-6,minecraft:warped_hyphae)
B(3,5,-6,minecraft:warped_hyphae)
B(3,6,-6,minecraft:warped_hyphae)
B(3,7,-6,minecraft:warped_hyphae)
B(3,8,-6,minecraft:warped_hyphae)
B(3,9,-6,minecraft:warped_hyphae)
B(3,10,-6,minecraft:warped_hyphae)
B(3,11,-6,minecraft:warped_hyphae)
B(3,12,-6,minecraft:warped_hyphae)
B(3,13,-6,minecraft:warped_hyphae)
B(3,14,-6,minecraft:warped_hyphae)
B(3,15,-6,minecraft:warped_hyphae)
B(3,16,-6,minecraft:warped_hyphae)
B(3,17,-6,minecraft:warped_hyphae)
B(3,18,-6,minecraft:warped_hyphae)
B(3,19,-6,minecraft:warped_hyphae)
B(3,20,-6,minecraft:warped_hyphae)
B(3,21,-6,minecraft:warped_hyphae)
B(3,22,-6,minecraft:warped_hyphae)
B(3,23,-6,minecraft:warped_hyphae)
B(3,24,-6,minecraft:warped_hyphae)
B(3,25,-6,minecraft:warped_hyphae)
B(3,26,-6,minecraft:warped_hyphae)
B(3,27,-6,minecraft:warped_hyphae)
B(3,28,-6,minecraft:warped_hyphae)
B(3,29,-6,minecraft:warped_hyphae)
B(3,30,-6,minecraft:warped_hyphae)
B(3,31,-6,minecraft:warped_hyphae)
B(3,32,-6,minecraft:warped_hyphae)
B(3,33,-6,minecraft:warped_hyphae)
B(3,34,-6,minecraft:warped_hyphae)
B(3,35,-6,minecraft:warped_hyphae)
B(3,36,-6,minecraft:warped_hyphae)
B(3,37,-6,minecraft:warped_hyphae)
B(3,38,-6,minecraft:warped_hyphae)
B(3,66,-6,minecraft:warped_hyphae)
B(3,67,-6,minecraft:warped_hyphae)
B(3,68,-6,minecraft:warped_hyphae)
B(3,69,-6,minecraft:warped_hyphae)
B(3,70,-6,minecraft:warped_hyphae)
B(3,71,-6,minecraft:warped_hyphae)
B(3,72,-6,minecraft:warped_hyphae)
B(3,73,-6,minecraft:warped_hyphae)
B(3,74,-6,minecraft:warped_hyphae)
B(3,75,-6,minecraft:warped_hyphae)
B(3,76,-6,minecraft:warped_hyphae)
B(3,77,-6,minecraft:warped_hyphae)
B(3,0,-5,minecraft:warped_hyphae)
B(3,1,-5,minecraft:warped_hyphae)
B(3,2,-5,minecraft:warped_hyphae)
B(3,5,-5,minecraft:warped_hyphae)
B(3,6,-5,minecraft:warped_hyphae)
B(3,7,-5,minecraft:warped_hyphae)
B(3,9,-5,minecraft:warped_hyphae)
B(3,10,-5,minecraft:warped_hyphae)
B(3,11,-5,minecraft:warped_hyphae)
B(3,12,-5,minecraft:warped_hyphae)
B(3,13,-5,minecraft:warped_hyphae)
B(3,14,-5,minecraft:warped_hyphae)
B(3,15,-5,minecraft:warped_hyphae)
B(3,16,-5,minecraft:warped_hyphae)
B(3,17,-5,minecraft:warped_hyphae)
B(3,18,-5,minecraft:warped_hyphae)
B(3,19,-5,minecraft:warped_hyphae)
B(3,20,-5,minecraft:warped_hyphae)
B(3,21,-5,minecraft:warped_hyphae)
B(3,22,-5,minecraft:warped_hyphae)
B(3,23,-5,minecraft:warped_hyphae)
B(3,24,-5,minecraft:warped_hyphae)
B(3,25,-5,minecraft:warped_hyphae)
B(3,26,-5,minecraft:warped_hyphae)
B(3,27,-5,minecraft:warped_hyphae)
B(3,28,-5,minecraft:warped_hyphae)
B(3,29,-5,minecraft:warped_hyphae)
B(3,30,-5,minecraft:warped_hyphae)
B(3,31,-5,minecraft:warped_hyphae)
B(3,32,-5,minecraft:warped_hyphae)
B(3,33,-5,minecraft:warped_hyphae)
B(3,34,-5,minecraft:warped_hyphae)
B(3,35,-5,minecraft:warped_hyphae)
B(3,36,-5,minecraft:warped_hyphae)
B(3,37,-5,minecraft:warped_hyphae)
B(3,66,-5,minecraft:warped_hyphae)
B(3,67,-5,minecraft:warped_hyphae)
B(3,68,-5,minecraft:warped_hyphae)
B(3,69,-5,minecraft:warped_hyphae)
B(3,70,-5,minecraft:warped_hyphae)
B(3,71,-5,minecraft:warped_hyphae)
B(3,72,-5,minecraft:warped_hyphae)
B(3,73,-5,minecraft:warped_hyphae)
B(3,74,-5,minecraft:warped_hyphae)
B(3,75,-5,minecraft:warped_hyphae)
B(3,76,-5,minecraft:warped_hyphae)
B(3,77,-5,minecraft:warped_hyphae)
B(3,10,-4,minecraft:warped_hyphae)
B(3,11,-4,minecraft:warped_hyphae)
B(3,12,-4,minecraft:warped_hyphae)
B(3,13,-4,minecraft:warped_hyphae)
B(3,14,-4,minecraft:warped_hyphae)
B(3,15,-4,minecraft:warped_hyphae)
B(3,16,-4,minecraft:warped_hyphae)
B(3,17,-4,minecraft:warped_hyphae)
B(3,18,-4,minecraft:warped_hyphae)
B(3,19,-4,minecraft:warped_hyphae)
B(3,20,-4,minecraft:warped_hyphae)
B(3,21,-4,minecraft:warped_hyphae)
B(3,22,-4,minecraft:warped_hyphae)
B(3,23,-4,minecraft:warped_hyphae)
B(3,24,-4,minecraft:warped_hyphae)
B(3,25,-4,minecraft:warped_hyphae)
B(3,26,-4,minecraft:warped_hyphae)
B(3,27,-4,minecraft:warped_hyphae)
B(3,28,-4,minecraft:warped_hyphae)
B(3,29,-4,minecraft:warped_hyphae)
B(3,30,-4,minecraft:warped_hyphae)
B(3,31,-4,minecraft:warped_hyphae)
B(3,32,-4,minecraft:warped_hyphae)
B(3,33,-4,minecraft:warped_hyphae)
B(3,34,-4,minecraft:warped_hyphae)
B(3,35,-4,minecraft:warped_hyphae)
B(3,67,-4,minecraft:warped_hyphae)
B(3,68,-4,minecraft:warped_hyphae)
B(3,69,-4,minecraft:warped_hyphae)
B(3,70,-4,minecraft:warped_hyphae)
B(3,71,-4,minecraft:warped_hyphae)
B(3,72,-4,minecraft:warped_hyphae)
B(3,73,-4,minecraft:warped_hyphae)
B(3,74,-4,minecraft:warped_hyphae)
B(3,75,-4,minecraft:warped_hyphae)
B(3,76,-4,minecraft:warped_hyphae)
B(3,13,-3,minecraft:warped_hyphae)
B(3,14,-3,minecraft:warped_hyphae)
B(3,15,-3,minecraft:warped_hyphae)
B(3,16,-3,minecraft:warped_hyphae)
B(3,17,-3,minecraft:warped_hyphae)
B(3,18,-3,minecraft:warped_hyphae)
B(3,19,-3,minecraft:warped_hyphae)
B(3,20,-3,minecraft:warped_hyphae)
B(3,21,-3,minecraft:warped_hyphae)
B(3,22,-3,minecraft:warped_hyphae)
B(3,23,-3,minecraft:warped_hyphae)
B(3,24,-3,minecraft:warped_hyphae)
B(3,25,-3,minecraft:warped_hyphae)
B(3,26,-3,minecraft:warped_hyphae)
B(3,27,-3,minecraft:warped_hyphae)
B(3,28,-3,minecraft:warped_hyphae)
B(3,29,-3,minecraft:warped_hyphae)
B(3,30,-3,minecraft:warped_hyphae)
B(3,31,-3,minecraft:warped_hyphae)
B(3,32,-3,minecraft:warped_hyphae)
B(3,33,-3,minecraft:warped_hyphae)
B(3,34,-3,minecraft:warped_hyphae)
B(3,67,-3,minecraft:warped_hyphae)
B(3,68,-3,minecraft:warped_hyphae)
B(3,69,-3,minecraft:warped_hyphae)
B(3,70,-3,minecraft:warped_hyphae)
B(3,71,-3,minecraft:warped_hyphae)
B(3,72,-3,minecraft:warped_hyphae)
B(3,73,-3,minecraft:warped_hyphae)
B(3,74,-3,minecraft:warped_hyphae)
B(3,75,-3,minecraft:warped_hyphae)
B(3,14,-2,minecraft:warped_hyphae)
B(3,15,-2,minecraft:warped_hyphae)
B(3,16,-2,minecraft:warped_hyphae)
B(3,17,-2,minecraft:warped_hyphae)
B(3,18,-2,minecraft:warped_hyphae)
B(3,19,-2,minecraft:warped_hyphae)
B(3,20,-2,minecraft:warped_hyphae)
B(3,21,-2,minecraft:warped_hyphae)
B(3,22,-2,minecraft:warped_hyphae)
B(3,23,-2,minecraft:warped_hyphae)
B(3,24,-2,minecraft:warped_hyphae)
B(3,25,-2,minecraft:warped_hyphae)
B(3,26,-2,minecraft:warped_hyphae)
B(3,27,-2,minecraft:warped_hyphae)
B(3,28,-2,minecraft:warped_hyphae)
B(3,29,-2,minecraft:warped_hyphae)
B(3,30,-2,minecraft:warped_hyphae)
B(3,31,-2,minecraft:warped_hyphae)
B(3,32,-2,minecraft:warped_hyphae)
B(3,33,-2,minecraft:warped_hyphae)
B(3,68,-2,minecraft:warped_hyphae)
B(3,69,-2,minecraft:warped_hyphae)
B(3,70,-2,minecraft:warped_hyphae)
B(3,71,-2,minecraft:warped_hyphae)
B(3,72,-2,minecraft:warped_hyphae)
B(3,73,-2,minecraft:warped_hyphae)
B(3,74,-2,minecraft:warped_hyphae)
B(3,19,-1,minecraft:warped_hyphae)
B(3,20,-1,minecraft:warped_hyphae)
B(3,21,-1,minecraft:warped_hyphae)
B(3,22,-1,minecraft:warped_hyphae)
B(3,23,-1,minecraft:warped_hyphae)
B(3,24,-1,minecraft:warped_hyphae)
B(3,25,-1,minecraft:warped_hyphae)
B(3,26,-1,minecraft:warped_hyphae)
B(3,27,-1,minecraft:warped_hyphae)
B(3,28,-1,minecraft:warped_hyphae)
B(3,29,-1,minecraft:warped_hyphae)
B(3,30,-1,minecraft:warped_hyphae)
B(3,31,-1,minecraft:warped_hyphae)
B(3,70,-1,minecraft:warped_hyphae)
B(3,71,-1,minecraft:warped_hyphae)
B(3,72,-1,minecraft:warped_hyphae)
B(3,23,0,minecraft:warped_hyphae)
B(3,24,0,minecraft:warped_hyphae)
B(3,25,0,minecraft:warped_hyphae)
B(3,26,0,minecraft:warped_hyphae)
B(3,27,0,minecraft:warped_hyphae)
B(3,28,0,minecraft:warped_hyphae)
B(3,29,0,minecraft:warped_hyphae)
B(3,30,0,minecraft:warped_hyphae)
B(3,31,0,minecraft:warped_hyphae)
B(3,23,1,minecraft:warped_hyphae)
B(3,24,1,minecraft:warped_hyphae)
B(3,25,1,minecraft:warped_hyphae)
B(3,26,1,minecraft:warped_hyphae)
B(3,27,1,minecraft:warped_hyphae)
B(3,28,1,minecraft:warped_hyphae)
B(3,29,1,minecraft:warped_hyphae)
B(3,30,1,minecraft:warped_hyphae)
B(3,24,2,minecraft:warped_hyphae)
B(3,25,2,minecraft:warped_hyphae)
B(3,26,2,minecraft:warped_hyphae)
B(3,27,2,minecraft:warped_hyphae)
B(3,28,2,minecraft:warped_hyphae)
B(4,0,-7,minecraft:warped_hyphae)
B(4,1,-7,minecraft:warped_hyphae)
B(4,2,-7,minecraft:warped_hyphae)
B(4,3,-7,minecraft:warped_hyphae)
B(4,4,-7,minecraft:warped_hyphae)
B(4,5,-7,minecraft:warped_hyphae)
B(4,6,-7,minecraft:warped_hyphae)
B(4,7,-7,minecraft:warped_hyphae)
B(4,8,-7,minecraft:warped_hyphae)
B(4,9,-7,minecraft:warped_hyphae)
B(4,10,-7,minecraft:warped_hyphae)
B(4,11,-7,minecraft:warped_hyphae)
B(4,12,-7,minecraft:warped_hyphae)
B(4,13,-7,minecraft:warped_hyphae)
B(4,14,-7,minecraft:warped_hyphae)
B(4,15,-7,minecraft:warped_hyphae)
B(4,16,-7,minecraft:warped_hyphae)
B(4,17,-7,minecraft:warped_hyphae)
B(4,18,-7,minecraft:warped_hyphae)
B(4,19,-7,minecraft:warped_hyphae)
B(4,20,-7,minecraft:warped_hyphae)
B(4,21,-7,minecraft:warped_hyphae)
B(4,22,-7,minecraft:warped_hyphae)
B(4,23,-7,minecraft:warped_hyphae)
B(4,24,-7,minecraft:warped_hyphae)
B(4,25,-7,minecraft:warped_hyphae)
B(4,26,-7,minecraft:warped_hyphae)
B(4,27,-7,minecraft:warped_hyphae)
B(4,28,-7,minecraft:warped_hyphae)
B(4,29,-7,minecraft:warped_hyphae)
B(4,30,-7,minecraft:warped_hyphae)
B(4,31,-7,minecraft:warped_hyphae)
B(4,32,-7,minecraft:warped_hyphae)
B(4,33,-7,minecraft:warped_hyphae)
B(4,34,-7,minecraft:warped_hyphae)
B(4,35,-7,minecraft:warped_hyphae)
B(4,36,-7,minecraft:warped_hyphae)
B(4,37,-7,minecraft:warped_hyphae)
B(4,38,-7,minecraft:warped_hyphae)
B(4,39,-7,minecraft:warped_hyphae)
B(4,65,-7,minecraft:warped_hyphae)
B(4,66,-7,minecraft:warped_hyphae)
B(4,67,-7,minecraft:warped_hyphae)
B(4,68,-7,minecraft:warped_hyphae)
B(4,69,-7,minecraft:warped_hyphae)
B(4,70,-7,minecraft:warped_hyphae)
B(4,71,-7,minecraft:warped_hyphae)
B(4,72,-7,minecraft:warped_hyphae)
B(4,73,-7,minecraft:warped_hyphae)
B(4,74,-7,minecraft:warped_hyphae)
B(4,75,-7,minecraft:warped_hyphae)
B(4,0,-6,minecraft:warped_hyphae)
B(4,1,-6,minecraft:warped_hyphae)
B(4,2,-6,minecraft:warped_hyphae)
B(4,3,-6,minecraft:warped_hyphae)
B(4,4,-6,minecraft:warped_hyphae)
B(4,5,-6,minecraft:warped_hyphae)
B(4,6,-6,minecraft:warped_hyphae)
B(4,7,-6,minecraft:warped_hyphae)
B(4,8,-6,minecraft:warped_hyphae)
B(4,9,-6,minecraft:warped_hyphae)
B(4,10,-6,minecraft:warped_hyphae)
B(4,11,-6,minecraft:warped_hyphae)
B(4,12,-6,minecraft:warped_hyphae)
B(4,13,-6,minecraft:warped_hyphae)
B(4,14,-6,minecraft:warped_hyphae)
B(4,15,-6,minecraft:warped_hyphae)
B(4,16,-6,minecraft:warped_hyphae)
B(4,17,-6,minecraft:warped_hyphae)
B(4,18,-6,minecraft:warped_hyphae)
B(4,19,-6,minecraft:warped_hyphae)
B(4,20,-6,minecraft:warped_hyphae)
B(4,21,-6,minecraft:warped_hyphae)
B(4,22,-6,minecraft:warped_hyphae)
B(4,23,-6,minecraft:warped_hyphae)
B(4,24,-6,minecraft:warped_hyphae)
B(4,25,-6,minecraft:warped_hyphae)
B(4,26,-6,minecraft:warped_hyphae)
B(4,27,-6,minecraft:warped_hyphae)
B(4,28,-6,minecraft:warped_hyphae)
B(4,29,-6,minecraft:warped_hyphae)
B(4,30,-6,minecraft:warped_hyphae)
B(4,31,-6,minecraft:warped_hyphae)
B(4,32,-6,minecraft:warped_hyphae)
B(4,33,-6,minecraft:warped_hyphae)
B(4,34,-6,minecraft:warped_hyphae)
B(4,35,-6,minecraft:warped_hyphae)
B(4,36,-6,minecraft:warped_hyphae)
B(4,37,-6,minecraft:warped_hyphae)
B(4,38,-6,minecraft:warped_hyphae)
B(4,65,-6,minecraft:warped_hyphae)
B(4,66,-6,minecraft:warped_hyphae)
B(4,67,-6,minecraft:warped_hyphae)
B(4,68,-6,minecraft:warped_hyphae)
B(4,69,-6,minecraft:warped_hyphae)
B(4,70,-6,minecraft:warped_hyphae)
B(4,71,-6,minecraft:warped_hyphae)
B(4,72,-6,minecraft:warped_hyphae)
B(4,73,-6,minecraft:warped_hyphae)
B(4,74,-6,minecraft:warped_hyphae)
B(4,75,-6,minecraft:warped_hyphae)
B(4,0,-5,minecraft:warped_hyphae)
B(4,1,-5,minecraft:warped_hyphae)
B(4,2,-5,minecraft:warped_hyphae)
B(4,3,-5,minecraft:warped_hyphae)
B(4,4,-5,minecraft:warped_hyphae)
B(4,5,-5,minecraft:warped_hyphae)
B(4,6,-5,minecraft:warped_hyphae)
B(4,7,-5,minecraft:warped_hyphae)
B(4,8,-5,minecraft:warped_hyphae)
B(4,9,-5,minecraft:warped_hyphae)
B(4,10,-5,minecraft:warped_hyphae)
B(4,11,-5,minecraft:warped_hyphae)
B(4,12,-5,minecraft:warped_hyphae)
B(4,13,-5,minecraft:warped_hyphae)
B(4,14,-5,minecraft:warped_hyphae)
B(4,15,-5,minecraft:warped_hyphae)
B(4,16,-5,minecraft:warped_hyphae)
B(4,17,-5,minecraft:warped_hyphae)
B(4,18,-5,minecraft:warped_hyphae)
B(4,19,-5,minecraft:warped_hyphae)
B(4,20,-5,minecraft:warped_hyphae)
B(4,21,-5,minecraft:warped_hyphae)
B(4,22,-5,minecraft:warped_hyphae)
B(4,23,-5,minecraft:warped_hyphae)
B(4,24,-5,minecraft:warped_hyphae)
B(4,25,-5,minecraft:warped_hyphae)
B(4,26,-5,minecraft:warped_hyphae)
B(4,27,-5,minecraft:warped_hyphae)
B(4,28,-5,minecraft:warped_hyphae)
B(4,29,-5,minecraft:warped_hyphae)
B(4,30,-5,minecraft:warped_hyphae)
B(4,31,-5,minecraft:warped_hyphae)
B(4,32,-5,minecraft:warped_hyphae)
B(4,33,-5,minecraft:warped_hyphae)
B(4,34,-5,minecraft:warped_hyphae)
B(4,35,-5,minecraft:warped_hyphae)
B(4,36,-5,minecraft:warped_hyphae)
B(4,37,-5,minecraft:warped_hyphae)
B(4,66,-5,minecraft:warped_hyphae)
B(4,67,-5,minecraft:warped_hyphae)
B(4,68,-5,minecraft:warped_hyphae)
B(4,69,-5,minecraft:warped_hyphae)
B(4,70,-5,minecraft:warped_hyphae)
B(4,71,-5,minecraft:warped_hyphae)
B(4,72,-5,minecraft:warped_hyphae)
B(4,73,-5,minecraft:warped_hyphae)
B(4,74,-5,minecraft:warped_hyphae)
B(4,75,-5,minecraft:warped_hyphae)
B(4,0,-4,minecraft:warped_hyphae)
B(4,1,-4,minecraft:warped_hyphae)
B(4,2,-4,minecraft:warped_hyphae)
B(4,3,-4,minecraft:warped_hyphae)
B(4,4,-4,minecraft:warped_hyphae)
B(4,5,-4,minecraft:warped_hyphae)
B(4,6,-4,minecraft:warped_hyphae)
B(4,7,-4,minecraft:warped_hyphae)
B(4,8,-4,minecraft:warped_hyphae)
B(4,9,-4,minecraft:warped_hyphae)
B(4,10,-4,minecraft:warped_hyphae)
B(4,11,-4,minecraft:warped_hyphae)
B(4,12,-4,minecraft:warped_hyphae)
B(4,13,-4,minecraft:warped_hyphae)
B(4,14,-4,minecraft:warped_hyphae)
B(4,15,-4,minecraft:warped_hyphae)
B(4,16,-4,minecraft:warped_hyphae)
B(4,17,-4,minecraft:warped_hyphae)
B(4,18,-4,minecraft:warped_hyphae)
B(4,19,-4,minecraft:warped_hyphae)
