
#######################################################################
# +-----------------------------------------------------------------+ #
# |                            BO4 object                           | #
# +-----------------------------------------------------------------+ #
#######################################################################

Author: Unknown

Description: No description given

SettingsMode: WriteWithoutComments


#######################################################################
# +-----------------------------------------------------------------+ #
# |                          Main settings                          | #
# +-----------------------------------------------------------------+ #
#######################################################################

FixedRotation: 

Frequency: 0

SpawnHeight: highestBlock

UseCenterForHighestBlock: true

##############################
# Height Limits for the BO4. #
##############################

MinHeight: 0

MaxHeight: 255

InheritBO3: 

InheritBO3Rotation: NORTH

OverrideChildSettings: true

OverrideParentHeight: false

CanOverride: false

BranchFrequency: 0

BranchFrequencyGroup: 

MustBeBelowOther: false

MustBeInside: 

CannotBeInside: 

ReplacesBO3: 

MustBeInsideWorldBorders: false

CanSpawnOnWater: true

SpawnOnWaterOnly: false

SpawnUnderWater: false

SpawnAtWaterLevel: false

HeightOffset: 0

RemoveAir: true

ReplaceAbove: 

ReplaceBelow: 

ReplaceWithBiomeBlocks: true

ReplaceWithSurfaceBlock: GRASS

ReplaceWithGroundBlock: DIRT

ReplaceWithStoneBlock: STONE

SmoothRadius: 0

SmoothHeightOffset: 0

SmoothStartTop: false

SmoothStartWood: false

SmoothingSurfaceBlock: 

SmoothingGroundBlock: 

BO3Group: 

IsSpawnPoint: false

DoReplaceBlocks: true


#######################################################################
# +-----------------------------------------------------------------+ #
# |                              Blocks                             | #
# +-----------------------------------------------------------------+ #
#######################################################################

B(-7,96,8,minecraft:nether_wart_block)
B(-7,97,8,minecraft:nether_wart_block)
B(-6,97,7,minecraft:nether_wart_block)
B(-6,98,7,minecraft:nether_wart_block)
B(-6,97,8,minecraft:nether_wart_block)
B(-5,98,6,minecraft:nether_wart_block)
B(-5,99,6,minecraft:nether_wart_block)
B(-5,98,7,minecraft:nether_wart_block)
B(-5,97,8,minecraft:nether_wart_block)
B(-5,98,8,minecraft:nether_wart_block)
B(-4,99,5,minecraft:nether_wart_block)
B(-4,100,5,minecraft:nether_wart_block)
B(-4,99,6,minecraft:nether_wart_block)
B(-4,98,7,minecraft:nether_wart_block)
B(-4,99,7,minecraft:nether_wart_block)
B(-3,100,4,minecraft:nether_wart_block)
B(-3,101,4,minecraft:nether_wart_block)
B(-3,100,5,minecraft:nether_wart_block)
B(-3,99,6,minecraft:nether_wart_block)
B(-3,100,6,minecraft:nether_wart_block)
B(-2,101,3,minecraft:nether_wart_block)
B(-2,102,3,minecraft:nether_wart_block)
B(-2,101,4,minecraft:nether_wart_block)
B(-2,100,5,minecraft:nether_wart_block)
B(-2,101,5,minecraft:nether_wart_block)
B(-1,102,2,minecraft:nether_wart_block)
B(-1,103,2,minecraft:nether_wart_block)
B(-1,102,3,minecraft:nether_wart_block)
B(-1,101,4,minecraft:nether_wart_block)
B(-1,102,4,minecraft:nether_wart_block)
B(0,103,1,minecraft:nether_wart_block)
B(0,104,1,minecraft:nether_wart_block)
B(0,103,2,minecraft:nether_wart_block)
B(0,102,3,minecraft:nether_wart_block)
B(0,103,3,minecraft:nether_wart_block)
B(1,104,0,minecraft:nether_wart_block)
B(1,105,0,minecraft:nether_wart_block)
B(1,104,1,minecraft:nether_wart_block)
B(1,103,2,minecraft:nether_wart_block)
B(1,104,2,minecraft:nether_wart_block)
B(2,105,-1,minecraft:nether_wart_block)
B(2,106,-1,minecraft:nether_wart_block)
B(2,105,0,minecraft:nether_wart_block)
B(2,104,1,minecraft:nether_wart_block)
B(2,105,1,minecraft:nether_wart_block)
B(3,106,-2,minecraft:nether_wart_block)
B(3,107,-2,minecraft:nether_wart_block)
B(3,106,-1,minecraft:nether_wart_block)
B(3,105,0,minecraft:nether_wart_block)
B(3,106,0,minecraft:nether_wart_block)
B(4,107,-3,minecraft:nether_wart_block)
B(4,108,-3,minecraft:nether_wart_block)
B(4,107,-2,minecraft:nether_wart_block)
B(4,106,-1,minecraft:nether_wart_block)
B(4,107,-1,minecraft:nether_wart_block)
B(5,108,-4,minecraft:nether_wart_block)
B(5,109,-4,minecraft:nether_wart_block)
B(5,108,-3,minecraft:nether_wart_block)
B(5,107,-2,minecraft:nether_wart_block)
B(5,108,-2,minecraft:nether_wart_block)
B(6,109,-5,minecraft:nether_wart_block)
B(6,110,-5,minecraft:nether_wart_block)
B(6,109,-4,minecraft:nether_wart_block)
B(6,108,-3,minecraft:nether_wart_block)
B(6,109,-3,minecraft:nether_wart_block)
B(7,110,-6,minecraft:nether_wart_block)
B(7,111,-6,minecraft:nether_wart_block)
B(7,110,-5,minecraft:nether_wart_block)
B(7,109,-4,minecraft:nether_wart_block)
B(7,110,-4,minecraft:nether_wart_block)

#######################################################################
# +-----------------------------------------------------------------+ #
# |                             Branches                            | #
# +-----------------------------------------------------------------+ #
#######################################################################

Branch(16,0,0,true,FleshString2_C7_R3,NORTH,100.0,0)

#######################################################################
# +-----------------------------------------------------------------+ #
# |                             Entities                            | #
# +-----------------------------------------------------------------+ #
#######################################################################

