
#######################################################################
# +-----------------------------------------------------------------+ #
# |                            BO4 object                           | #
# +-----------------------------------------------------------------+ #
#######################################################################

Author: Unknown

Description: No description given

SettingsMode: WriteWithoutComments


#######################################################################
# +-----------------------------------------------------------------+ #
# |                          Main settings                          | #
# +-----------------------------------------------------------------+ #
#######################################################################

FixedRotation: 

Frequency: 0

SpawnHeight: highestBlock

UseCenterForHighestBlock: true

##############################
# Height Limits for the BO4. #
##############################

MinHeight: 0

MaxHeight: 255

InheritBO3: 

InheritBO3Rotation: NORTH

OverrideChildSettings: true

OverrideParentHeight: false

CanOverride: false

BranchFrequency: 0

BranchFrequencyGroup: 

MustBeBelowOther: false

MustBeInside: 

CannotBeInside: 

ReplacesBO3: 

MustBeInsideWorldBorders: false

CanSpawnOnWater: true

SpawnOnWaterOnly: false

SpawnUnderWater: false

SpawnAtWaterLevel: false

HeightOffset: 0

RemoveAir: true

ReplaceAbove: 

ReplaceBelow: 

ReplaceWithBiomeBlocks: true

ReplaceWithSurfaceBlock: GRASS

ReplaceWithGroundBlock: DIRT

ReplaceWithStoneBlock: STONE

SmoothRadius: 0

SmoothHeightOffset: 0

SmoothStartTop: false

SmoothStartWood: false

SmoothingSurfaceBlock: 

SmoothingGroundBlock: 

BO3Group: 

IsSpawnPoint: false

DoReplaceBlocks: true


#######################################################################
# +-----------------------------------------------------------------+ #
# |                              Blocks                             | #
# +-----------------------------------------------------------------+ #
#######################################################################

B(-7,48,8,minecraft:nether_wart_block)
B(-7,49,8,minecraft:nether_wart_block)
B(-6,49,7,minecraft:nether_wart_block)
B(-6,50,7,minecraft:nether_wart_block)
B(-6,49,8,minecraft:nether_wart_block)
B(-5,50,6,minecraft:nether_wart_block)
B(-5,51,6,minecraft:nether_wart_block)
B(-5,50,7,minecraft:nether_wart_block)
B(-5,49,8,minecraft:nether_wart_block)
B(-5,50,8,minecraft:nether_wart_block)
B(-4,51,5,minecraft:nether_wart_block)
B(-4,52,5,minecraft:nether_wart_block)
B(-4,51,6,minecraft:nether_wart_block)
B(-4,50,7,minecraft:nether_wart_block)
B(-4,51,7,minecraft:nether_wart_block)
B(-3,52,4,minecraft:nether_wart_block)
B(-3,53,4,minecraft:nether_wart_block)
B(-3,52,5,minecraft:nether_wart_block)
B(-3,51,6,minecraft:nether_wart_block)
B(-3,52,6,minecraft:nether_wart_block)
B(-2,53,3,minecraft:nether_wart_block)
B(-2,54,3,minecraft:nether_wart_block)
B(-2,53,4,minecraft:nether_wart_block)
B(-2,52,5,minecraft:nether_wart_block)
B(-2,53,5,minecraft:nether_wart_block)
B(-1,54,2,minecraft:nether_wart_block)
B(-1,55,2,minecraft:nether_wart_block)
B(-1,54,3,minecraft:nether_wart_block)
B(-1,53,4,minecraft:nether_wart_block)
B(-1,54,4,minecraft:nether_wart_block)
B(0,55,1,minecraft:nether_wart_block)
B(0,56,1,minecraft:nether_wart_block)
B(0,55,2,minecraft:nether_wart_block)
B(0,54,3,minecraft:nether_wart_block)
B(0,55,3,minecraft:nether_wart_block)
B(1,56,0,minecraft:nether_wart_block)
B(1,57,0,minecraft:nether_wart_block)
B(1,56,1,minecraft:nether_wart_block)
B(1,55,2,minecraft:nether_wart_block)
B(1,56,2,minecraft:nether_wart_block)
B(2,57,-1,minecraft:nether_wart_block)
B(2,58,-1,minecraft:nether_wart_block)
B(2,57,0,minecraft:nether_wart_block)
B(2,56,1,minecraft:nether_wart_block)
B(2,57,1,minecraft:nether_wart_block)
B(3,58,-2,minecraft:nether_wart_block)
B(3,59,-2,minecraft:nether_wart_block)
B(3,58,-1,minecraft:nether_wart_block)
B(3,57,0,minecraft:nether_wart_block)
B(3,58,0,minecraft:nether_wart_block)
B(4,59,-3,minecraft:nether_wart_block)
B(4,60,-3,minecraft:nether_wart_block)
B(4,59,-2,minecraft:nether_wart_block)
B(4,58,-1,minecraft:nether_wart_block)
B(4,59,-1,minecraft:nether_wart_block)
B(5,60,-4,minecraft:nether_wart_block)
B(5,61,-4,minecraft:nether_wart_block)
B(5,60,-3,minecraft:nether_wart_block)
B(5,59,-2,minecraft:nether_wart_block)
B(5,60,-2,minecraft:nether_wart_block)
B(6,61,-5,minecraft:nether_wart_block)
B(6,62,-5,minecraft:nether_wart_block)
B(6,61,-4,minecraft:nether_wart_block)
B(6,60,-3,minecraft:nether_wart_block)
B(6,61,-3,minecraft:nether_wart_block)
B(7,62,-6,minecraft:nether_wart_block)
B(7,63,-6,minecraft:nether_wart_block)
B(7,62,-5,minecraft:nether_wart_block)
B(7,61,-4,minecraft:nether_wart_block)
B(7,62,-4,minecraft:nether_wart_block)

#######################################################################
# +-----------------------------------------------------------------+ #
# |                             Branches                            | #
# +-----------------------------------------------------------------+ #
#######################################################################

Branch(16,0,0,true,FleshString2_C4_R6,NORTH,100.0,0)

#######################################################################
# +-----------------------------------------------------------------+ #
# |                             Entities                            | #
# +-----------------------------------------------------------------+ #
#######################################################################

