
#######################################################################
# +-----------------------------------------------------------------+ #
# |                            BO4 object                           | #
# +-----------------------------------------------------------------+ #
#######################################################################

Author: Unknown

Description: No description given

SettingsMode: WriteWithoutComments


#######################################################################
# +-----------------------------------------------------------------+ #
# |                          Main settings                          | #
# +-----------------------------------------------------------------+ #
#######################################################################

FixedRotation: 

Frequency: 0

SpawnHeight: highestBlock

UseCenterForHighestBlock: true

##############################
# Height Limits for the BO4. #
##############################

MinHeight: 0

MaxHeight: 255

InheritBO3: 

InheritBO3Rotation: NORTH

OverrideChildSettings: true

OverrideParentHeight: false

CanOverride: false

BranchFrequency: 0

BranchFrequencyGroup: 

MustBeBelowOther: false

MustBeInside: 

CannotBeInside: 

ReplacesBO3: 

MustBeInsideWorldBorders: false

CanSpawnOnWater: true

SpawnOnWaterOnly: false

SpawnUnderWater: false

SpawnAtWaterLevel: false

HeightOffset: 0

RemoveAir: true

ReplaceAbove: 

ReplaceBelow: 

ReplaceWithBiomeBlocks: true

ReplaceWithSurfaceBlock: GRASS

ReplaceWithGroundBlock: DIRT

ReplaceWithStoneBlock: STONE

SmoothRadius: 0

SmoothHeightOffset: 0

SmoothStartTop: false

SmoothStartWood: false

SmoothingSurfaceBlock: 

SmoothingGroundBlock: 

BO3Group: 

IsSpawnPoint: false

DoReplaceBlocks: true


#######################################################################
# +-----------------------------------------------------------------+ #
# |                              Blocks                             | #
# +-----------------------------------------------------------------+ #
#######################################################################

B(-7,112,8,minecraft:nether_wart_block)
B(-7,113,8,minecraft:nether_wart_block)
B(-6,113,7,minecraft:nether_wart_block)
B(-6,114,7,minecraft:nether_wart_block)
B(-6,113,8,minecraft:nether_wart_block)
B(-5,114,6,minecraft:nether_wart_block)
B(-5,115,6,minecraft:nether_wart_block)
B(-5,114,7,minecraft:nether_wart_block)
B(-5,113,8,minecraft:nether_wart_block)
B(-5,114,8,minecraft:nether_wart_block)
B(-4,115,5,minecraft:nether_wart_block)
B(-4,116,5,minecraft:nether_wart_block)
B(-4,115,6,minecraft:nether_wart_block)
B(-4,114,7,minecraft:nether_wart_block)
B(-4,115,7,minecraft:nether_wart_block)
B(-3,116,4,minecraft:nether_wart_block)
B(-3,117,4,minecraft:nether_wart_block)
B(-3,116,5,minecraft:nether_wart_block)
B(-3,115,6,minecraft:nether_wart_block)
B(-3,116,6,minecraft:nether_wart_block)
B(-2,117,3,minecraft:nether_wart_block)
B(-2,118,3,minecraft:nether_wart_block)
B(-2,117,4,minecraft:nether_wart_block)
B(-2,116,5,minecraft:nether_wart_block)
B(-2,117,5,minecraft:nether_wart_block)
B(-1,118,2,minecraft:nether_wart_block)
B(-1,119,2,minecraft:nether_wart_block)
B(-1,118,3,minecraft:nether_wart_block)
B(-1,117,4,minecraft:nether_wart_block)
B(-1,118,4,minecraft:nether_wart_block)
B(0,119,1,minecraft:nether_wart_block)
B(0,120,1,minecraft:nether_wart_block)
B(0,119,2,minecraft:nether_wart_block)
B(0,118,3,minecraft:nether_wart_block)
B(0,119,3,minecraft:nether_wart_block)
B(1,120,0,minecraft:nether_wart_block)
B(1,121,0,minecraft:nether_wart_block)
B(1,120,1,minecraft:nether_wart_block)
B(1,119,2,minecraft:nether_wart_block)
B(1,120,2,minecraft:nether_wart_block)
B(2,121,-1,minecraft:nether_wart_block)
B(2,122,-1,minecraft:nether_wart_block)
B(2,121,0,minecraft:nether_wart_block)
B(2,120,1,minecraft:nether_wart_block)
B(2,121,1,minecraft:nether_wart_block)
B(3,122,-2,minecraft:nether_wart_block)
B(3,123,-2,minecraft:nether_wart_block)
B(3,122,-1,minecraft:nether_wart_block)
B(3,121,0,minecraft:nether_wart_block)
B(3,122,0,minecraft:nether_wart_block)
B(4,123,-3,minecraft:nether_wart_block)
B(4,124,-3,minecraft:nether_wart_block)
B(4,123,-2,minecraft:nether_wart_block)
B(4,122,-1,minecraft:nether_wart_block)
B(4,123,-1,minecraft:nether_wart_block)
B(5,124,-4,minecraft:nether_wart_block)
B(5,125,-4,minecraft:nether_wart_block)
B(5,124,-3,minecraft:nether_wart_block)
B(5,123,-2,minecraft:nether_wart_block)
B(5,124,-2,minecraft:nether_wart_block)
B(6,125,-5,minecraft:nether_wart_block)
B(6,126,-5,minecraft:nether_wart_block)
B(6,125,-4,minecraft:nether_wart_block)
B(6,124,-3,minecraft:nether_wart_block)
B(6,125,-3,minecraft:nether_wart_block)
B(7,126,-6,minecraft:nether_wart_block)
B(7,127,-6,minecraft:nether_wart_block)
B(7,126,-5,minecraft:nether_wart_block)
B(7,125,-4,minecraft:nether_wart_block)
B(7,126,-4,minecraft:nether_wart_block)

#######################################################################
# +-----------------------------------------------------------------+ #
# |                             Branches                            | #
# +-----------------------------------------------------------------+ #
#######################################################################

Branch(16,0,0,true,FleshString2_C8_R2,NORTH,100.0,0)

#######################################################################
# +-----------------------------------------------------------------+ #
# |                             Entities                            | #
# +-----------------------------------------------------------------+ #
#######################################################################

