
#######################################################################
# +-----------------------------------------------------------------+ #
# |                            BO4 object                           | #
# +-----------------------------------------------------------------+ #
#######################################################################

Author: Unknown

Description: No description given

SettingsMode: WriteWithoutComments


#######################################################################
# +-----------------------------------------------------------------+ #
# |                          Main settings                          | #
# +-----------------------------------------------------------------+ #
#######################################################################

FixedRotation: 

Frequency: 0

SpawnHeight: highestBlock

UseCenterForHighestBlock: true

##############################
# Height Limits for the BO4. #
##############################

MinHeight: 0

MaxHeight: 255

InheritBO3: 

InheritBO3Rotation: NORTH

OverrideChildSettings: true

OverrideParentHeight: false

CanOverride: false

BranchFrequency: 0

BranchFrequencyGroup: 

MustBeBelowOther: false

MustBeInside: 

CannotBeInside: 

ReplacesBO3: 

MustBeInsideWorldBorders: false

CanSpawnOnWater: true

SpawnOnWaterOnly: false

SpawnUnderWater: false

SpawnAtWaterLevel: false

HeightOffset: 0

RemoveAir: true

ReplaceAbove: 

ReplaceBelow: 

ReplaceWithBiomeBlocks: true

ReplaceWithSurfaceBlock: GRASS

ReplaceWithGroundBlock: DIRT

ReplaceWithStoneBlock: STONE

SmoothRadius: 0

SmoothHeightOffset: 0

SmoothStartTop: false

SmoothStartWood: false

SmoothingSurfaceBlock: 

SmoothingGroundBlock: 

BO3Group: 

IsSpawnPoint: false

DoReplaceBlocks: true


#######################################################################
# +-----------------------------------------------------------------+ #
# |                              Blocks                             | #
# +-----------------------------------------------------------------+ #
#######################################################################

B(-7,64,8,minecraft:nether_wart_block)
B(-7,65,8,minecraft:nether_wart_block)
B(-6,65,7,minecraft:nether_wart_block)
B(-6,66,7,minecraft:nether_wart_block)
B(-6,65,8,minecraft:nether_wart_block)
B(-5,66,6,minecraft:nether_wart_block)
B(-5,67,6,minecraft:nether_wart_block)
B(-5,66,7,minecraft:nether_wart_block)
B(-5,65,8,minecraft:nether_wart_block)
B(-5,66,8,minecraft:nether_wart_block)
B(-4,67,5,minecraft:nether_wart_block)
B(-4,68,5,minecraft:nether_wart_block)
B(-4,67,6,minecraft:nether_wart_block)
B(-4,66,7,minecraft:nether_wart_block)
B(-4,67,7,minecraft:nether_wart_block)
B(-3,68,4,minecraft:nether_wart_block)
B(-3,69,4,minecraft:nether_wart_block)
B(-3,68,5,minecraft:nether_wart_block)
B(-3,67,6,minecraft:nether_wart_block)
B(-3,68,6,minecraft:nether_wart_block)
B(-2,69,3,minecraft:nether_wart_block)
B(-2,70,3,minecraft:nether_wart_block)
B(-2,69,4,minecraft:nether_wart_block)
B(-2,68,5,minecraft:nether_wart_block)
B(-2,69,5,minecraft:nether_wart_block)
B(-1,70,2,minecraft:nether_wart_block)
B(-1,71,2,minecraft:nether_wart_block)
B(-1,70,3,minecraft:nether_wart_block)
B(-1,69,4,minecraft:nether_wart_block)
B(-1,70,4,minecraft:nether_wart_block)
B(0,71,1,minecraft:nether_wart_block)
B(0,72,1,minecraft:nether_wart_block)
B(0,71,2,minecraft:nether_wart_block)
B(0,70,3,minecraft:nether_wart_block)
B(0,71,3,minecraft:nether_wart_block)
B(1,72,0,minecraft:nether_wart_block)
B(1,73,0,minecraft:nether_wart_block)
B(1,72,1,minecraft:nether_wart_block)
B(1,71,2,minecraft:nether_wart_block)
B(1,72,2,minecraft:nether_wart_block)
B(2,73,-1,minecraft:nether_wart_block)
B(2,74,-1,minecraft:nether_wart_block)
B(2,73,0,minecraft:nether_wart_block)
B(2,72,1,minecraft:nether_wart_block)
B(2,73,1,minecraft:nether_wart_block)
B(3,74,-2,minecraft:nether_wart_block)
B(3,75,-2,minecraft:nether_wart_block)
B(3,74,-1,minecraft:nether_wart_block)
B(3,73,0,minecraft:nether_wart_block)
B(3,74,0,minecraft:nether_wart_block)
B(4,75,-3,minecraft:nether_wart_block)
B(4,76,-3,minecraft:nether_wart_block)
B(4,75,-2,minecraft:nether_wart_block)
B(4,74,-1,minecraft:nether_wart_block)
B(4,75,-1,minecraft:nether_wart_block)
B(5,76,-4,minecraft:nether_wart_block)
B(5,77,-4,minecraft:nether_wart_block)
B(5,76,-3,minecraft:nether_wart_block)
B(5,75,-2,minecraft:nether_wart_block)
B(5,76,-2,minecraft:nether_wart_block)
B(6,77,-5,minecraft:nether_wart_block)
B(6,78,-5,minecraft:nether_wart_block)
B(6,77,-4,minecraft:nether_wart_block)
B(6,76,-3,minecraft:nether_wart_block)
B(6,77,-3,minecraft:nether_wart_block)
B(7,78,-6,minecraft:nether_wart_block)
B(7,79,-6,minecraft:nether_wart_block)
B(7,78,-5,minecraft:nether_wart_block)
B(7,77,-4,minecraft:nether_wart_block)
B(7,78,-4,minecraft:nether_wart_block)

#######################################################################
# +-----------------------------------------------------------------+ #
# |                             Branches                            | #
# +-----------------------------------------------------------------+ #
#######################################################################

Branch(16,0,0,true,FleshString2_C5_R5,NORTH,100.0,0)

#######################################################################
# +-----------------------------------------------------------------+ #
# |                             Entities                            | #
# +-----------------------------------------------------------------+ #
#######################################################################

