
#######################################################################
# +-----------------------------------------------------------------+ #
# |                            BO4 object                           | #
# +-----------------------------------------------------------------+ #
#######################################################################

Author: Unknown

Description: No description given

SettingsMode: WriteWithoutComments


#######################################################################
# +-----------------------------------------------------------------+ #
# |                          Main settings                          | #
# +-----------------------------------------------------------------+ #
#######################################################################

FixedRotation: 

Frequency: 0

SpawnHeight: highestBlock

UseCenterForHighestBlock: true

##############################
# Height Limits for the BO4. #
##############################

MinHeight: 0

MaxHeight: 255

InheritBO3: 

InheritBO3Rotation: NORTH

OverrideChildSettings: true

OverrideParentHeight: false

CanOverride: false

BranchFrequency: 0

BranchFrequencyGroup: 

MustBeBelowOther: false

MustBeInside: 

CannotBeInside: 

ReplacesBO3: 

MustBeInsideWorldBorders: false

CanSpawnOnWater: true

SpawnOnWaterOnly: false

SpawnUnderWater: false

SpawnAtWaterLevel: false

HeightOffset: 0

RemoveAir: true

ReplaceAbove: 

ReplaceBelow: 

ReplaceWithBiomeBlocks: true

ReplaceWithSurfaceBlock: GRASS

ReplaceWithGroundBlock: DIRT

ReplaceWithStoneBlock: STONE

SmoothRadius: 0

SmoothHeightOffset: 0

SmoothStartTop: false

SmoothStartWood: false

SmoothingSurfaceBlock: 

SmoothingGroundBlock: 

BO3Group: 

IsSpawnPoint: false

DoReplaceBlocks: true


#######################################################################
# +-----------------------------------------------------------------+ #
# |                              Blocks                             | #
# +-----------------------------------------------------------------+ #
#######################################################################

B(-7,80,8,minecraft:nether_wart_block)
B(-7,81,8,minecraft:nether_wart_block)
B(-6,81,7,minecraft:nether_wart_block)
B(-6,82,7,minecraft:nether_wart_block)
B(-6,81,8,minecraft:nether_wart_block)
B(-5,82,6,minecraft:nether_wart_block)
B(-5,83,6,minecraft:nether_wart_block)
B(-5,82,7,minecraft:nether_wart_block)
B(-5,81,8,minecraft:nether_wart_block)
B(-5,82,8,minecraft:nether_wart_block)
B(-4,83,5,minecraft:nether_wart_block)
B(-4,84,5,minecraft:nether_wart_block)
B(-4,83,6,minecraft:nether_wart_block)
B(-4,82,7,minecraft:nether_wart_block)
B(-4,83,7,minecraft:nether_wart_block)
B(-3,84,4,minecraft:nether_wart_block)
B(-3,85,4,minecraft:nether_wart_block)
B(-3,84,5,minecraft:nether_wart_block)
B(-3,83,6,minecraft:nether_wart_block)
B(-3,84,6,minecraft:nether_wart_block)
B(-2,85,3,minecraft:nether_wart_block)
B(-2,86,3,minecraft:nether_wart_block)
B(-2,85,4,minecraft:nether_wart_block)
B(-2,84,5,minecraft:nether_wart_block)
B(-2,85,5,minecraft:nether_wart_block)
B(-1,86,2,minecraft:nether_wart_block)
B(-1,87,2,minecraft:nether_wart_block)
B(-1,86,3,minecraft:nether_wart_block)
B(-1,85,4,minecraft:nether_wart_block)
B(-1,86,4,minecraft:nether_wart_block)
B(0,87,1,minecraft:nether_wart_block)
B(0,88,1,minecraft:nether_wart_block)
B(0,87,2,minecraft:nether_wart_block)
B(0,86,3,minecraft:nether_wart_block)
B(0,87,3,minecraft:nether_wart_block)
B(1,88,0,minecraft:nether_wart_block)
B(1,89,0,minecraft:nether_wart_block)
B(1,88,1,minecraft:nether_wart_block)
B(1,87,2,minecraft:nether_wart_block)
B(1,88,2,minecraft:nether_wart_block)
B(2,89,-1,minecraft:nether_wart_block)
B(2,90,-1,minecraft:nether_wart_block)
B(2,89,0,minecraft:nether_wart_block)
B(2,88,1,minecraft:nether_wart_block)
B(2,89,1,minecraft:nether_wart_block)
B(3,90,-2,minecraft:nether_wart_block)
B(3,91,-2,minecraft:nether_wart_block)
B(3,90,-1,minecraft:nether_wart_block)
B(3,89,0,minecraft:nether_wart_block)
B(3,90,0,minecraft:nether_wart_block)
B(4,91,-3,minecraft:nether_wart_block)
B(4,92,-3,minecraft:nether_wart_block)
B(4,91,-2,minecraft:nether_wart_block)
B(4,90,-1,minecraft:nether_wart_block)
B(4,91,-1,minecraft:nether_wart_block)
B(5,92,-4,minecraft:nether_wart_block)
B(5,93,-4,minecraft:nether_wart_block)
B(5,92,-3,minecraft:nether_wart_block)
B(5,91,-2,minecraft:nether_wart_block)
B(5,92,-2,minecraft:nether_wart_block)
B(6,93,-5,minecraft:nether_wart_block)
B(6,94,-5,minecraft:nether_wart_block)
B(6,93,-4,minecraft:nether_wart_block)
B(6,92,-3,minecraft:nether_wart_block)
B(6,93,-3,minecraft:nether_wart_block)
B(7,94,-6,minecraft:nether_wart_block)
B(7,95,-6,minecraft:nether_wart_block)
B(7,94,-5,minecraft:nether_wart_block)
B(7,93,-4,minecraft:nether_wart_block)
B(7,94,-4,minecraft:nether_wart_block)

#######################################################################
# +-----------------------------------------------------------------+ #
# |                             Branches                            | #
# +-----------------------------------------------------------------+ #
#######################################################################

Branch(16,0,0,true,FleshString2_C6_R4,NORTH,100.0,0)

#######################################################################
# +-----------------------------------------------------------------+ #
# |                             Entities                            | #
# +-----------------------------------------------------------------+ #
#######################################################################

