Author: Bo3 BulkEdit

Description: Converted Schematic - Modified by Bo3BulkEdit

Version: 3

SettingsMode: WriteDisable

IsOTGPlus: true
Tree: false
Frequency: 10
Rarity: 100
RotateRandomly: true
SpawnHeight: randomY
SpawnHeightOffset: 0
SpawnHeightVariance: 0
MaxBranchDepth: 10
ExcludedBiomes: All

MinHeight: 50
MaxHeight: 65

SourceBlocks: AIR
MaxPercentageOutsideSourceBlock: 100
OutsideSourceBlock: placeAnyway

ReplaceBelow: BLACKSTONE
ReplaceWithBiomeBlocks: false
ReplaceWithGroundBlock: BLACKSTONE
ReplaceWithSurfaceBlock: BLACKSTONE
ReplaceWithStoneBlock: BLACKSTONE
SmoothRadius: 30
SmoothingSurfaceBlock: BLACKSTONE
SmoothingGroundBlock: BLACKSTONE

B(0,750,0,AIR)
B(15,750,15,AIR)
B(2,0,0,minecraft:blackstone)
B(3,0,0,minecraft:blackstone)
B(4,0,0,minecraft:blackstone)
B(5,0,0,minecraft:blackstone)
B(6,0,0,minecraft:blackstone)
B(7,0,0,minecraft:blackstone)
B(8,0,0,minecraft:blackstone)
B(9,0,0,minecraft:blackstone)
B(10,0,0,minecraft:blackstone)
B(11,0,0,minecraft:blackstone)
B(12,0,0,minecraft:blackstone)
B(13,0,0,minecraft:blackstone)
B(14,0,0,minecraft:blackstone)
B(15,0,0,minecraft:blackstone)
B(2,0,1,minecraft:blackstone)
B(3,0,1,minecraft:blackstone)
B(4,0,1,minecraft:blackstone)
B(5,0,1,minecraft:blackstone)
B(6,0,1,minecraft:blackstone)
B(7,0,1,minecraft:blackstone)
B(8,0,1,minecraft:blackstone)
B(9,0,1,minecraft:blackstone)
B(10,0,1,minecraft:blackstone)
B(11,0,1,minecraft:blackstone)
B(12,0,1,minecraft:blackstone)
B(13,0,1,minecraft:blackstone)
B(14,0,1,minecraft:blackstone)
B(15,0,1,minecraft:blackstone)
B(2,0,2,minecraft:blackstone)
B(3,0,2,minecraft:blackstone)
B(4,0,2,minecraft:blackstone)
B(5,0,2,minecraft:blackstone)
B(6,0,2,minecraft:blackstone)
B(7,0,2,minecraft:blackstone)
B(8,0,2,minecraft:blackstone)
B(9,0,2,minecraft:blackstone)
B(10,0,2,minecraft:blackstone)
B(11,0,2,minecraft:blackstone)
B(12,0,2,minecraft:blackstone)
B(13,0,2,minecraft:blackstone)
B(14,0,2,minecraft:blackstone)
B(15,0,2,minecraft:blackstone)
B(2,0,3,minecraft:blackstone)
B(3,0,3,minecraft:blackstone)
B(4,0,3,minecraft:blackstone)
B(5,0,3,minecraft:blackstone)
B(6,0,3,minecraft:blackstone)
B(7,0,3,minecraft:blackstone)
B(8,0,3,minecraft:blackstone)
B(9,0,3,minecraft:blackstone)
B(10,0,3,minecraft:blackstone)
B(11,0,3,minecraft:blackstone)
B(12,0,3,minecraft:blackstone)
B(13,0,3,minecraft:blackstone)
B(14,0,3,minecraft:blackstone)
B(15,0,3,minecraft:blackstone)
B(2,0,4,minecraft:blackstone)
B(3,0,4,minecraft:blackstone)
B(4,0,4,minecraft:blackstone)
B(5,0,4,minecraft:blackstone)
B(6,0,4,minecraft:blackstone)
B(7,0,4,minecraft:blackstone)
B(8,0,4,minecraft:blackstone)
B(9,0,4,minecraft:blackstone)
B(10,0,4,minecraft:blackstone)
B(11,0,4,minecraft:blackstone)
B(12,0,4,minecraft:blackstone)
B(13,0,4,minecraft:blackstone)
B(14,0,4,minecraft:blackstone)
B(15,0,4,minecraft:blackstone)
B(2,0,5,minecraft:blackstone)
B(3,0,5,minecraft:blackstone)
B(4,0,5,minecraft:blackstone)
B(5,0,5,minecraft:blackstone)
B(6,0,5,minecraft:blackstone)
B(7,0,5,minecraft:blackstone)
B(8,0,5,minecraft:blackstone)
B(9,0,5,minecraft:blackstone)
B(10,0,5,minecraft:blackstone)
B(11,0,5,minecraft:blackstone)
B(12,0,5,minecraft:blackstone)
B(13,0,5,minecraft:blackstone)
B(14,0,5,minecraft:blackstone)
B(15,0,5,minecraft:blackstone)
B(2,0,6,minecraft:blackstone)
B(3,0,6,minecraft:blackstone)
B(4,0,6,minecraft:blackstone)
B(5,0,6,minecraft:blackstone)
B(6,0,6,minecraft:blackstone)
B(7,0,6,minecraft:blackstone)
B(8,0,6,minecraft:blackstone)
B(9,0,6,minecraft:blackstone)
B(10,0,6,minecraft:blackstone)
B(11,0,6,minecraft:blackstone)
B(12,0,6,minecraft:blackstone)
B(13,0,6,minecraft:blackstone)
B(14,0,6,minecraft:blackstone)
B(15,0,6,minecraft:blackstone)
B(2,0,7,minecraft:blackstone)
B(3,0,7,minecraft:blackstone)
B(4,0,7,minecraft:blackstone)
B(5,0,7,minecraft:blackstone)
B(6,0,7,minecraft:blackstone)
B(7,0,7,minecraft:blackstone)
B(8,0,7,minecraft:blackstone)
B(9,0,7,minecraft:blackstone)
B(10,0,7,minecraft:blackstone)
B(11,0,7,minecraft:blackstone)
B(12,0,7,minecraft:blackstone)
B(13,0,7,minecraft:blackstone)
B(14,0,7,minecraft:blackstone)
B(15,0,7,minecraft:blackstone)
B(2,0,8,minecraft:blackstone)
B(3,0,8,minecraft:blackstone)
B(4,0,8,minecraft:blackstone)
B(5,0,8,minecraft:blackstone)
B(6,0,8,minecraft:blackstone)
B(7,0,8,minecraft:blackstone)
B(8,0,8,minecraft:blackstone)
B(9,0,8,minecraft:blackstone)
B(10,0,8,minecraft:blackstone)
B(11,0,8,minecraft:blackstone)
B(12,0,8,minecraft:blackstone)
B(13,0,8,minecraft:blackstone)
B(14,0,8,minecraft:blackstone)
B(15,0,8,minecraft:blackstone)
B(2,0,9,minecraft:blackstone)
B(3,0,9,minecraft:blackstone)
B(4,0,9,minecraft:blackstone)
B(5,0,9,minecraft:blackstone)
B(6,0,9,minecraft:blackstone)
B(7,0,9,minecraft:blackstone)
B(8,0,9,minecraft:blackstone)
B(9,0,9,minecraft:blackstone)
B(10,0,9,minecraft:blackstone)
B(11,0,9,minecraft:blackstone)
B(12,0,9,minecraft:blackstone)
B(13,0,9,minecraft:blackstone)
B(14,0,9,minecraft:blackstone)
B(15,0,9,minecraft:blackstone)
B(2,0,10,minecraft:blackstone)
B(3,0,10,minecraft:blackstone)
B(4,0,10,minecraft:blackstone)
B(5,0,10,minecraft:blackstone)
B(6,0,10,minecraft:blackstone)
B(7,0,10,minecraft:blackstone)
B(8,0,10,minecraft:blackstone)
B(9,0,10,minecraft:blackstone)
B(10,0,10,minecraft:blackstone)
B(11,0,10,minecraft:blackstone)
B(12,0,10,minecraft:blackstone)
B(13,0,10,minecraft:blackstone)
B(14,0,10,minecraft:blackstone)
B(15,0,10,minecraft:blackstone)
B(2,0,11,minecraft:blackstone)
B(3,0,11,minecraft:blackstone)
B(4,0,11,minecraft:blackstone)
B(5,0,11,minecraft:blackstone)
B(6,0,11,minecraft:blackstone)
B(7,0,11,minecraft:blackstone)
B(8,0,11,minecraft:blackstone)
B(9,0,11,minecraft:blackstone)
B(10,0,11,minecraft:blackstone)
B(11,0,11,minecraft:blackstone)
B(12,0,11,minecraft:blackstone)
B(13,0,11,minecraft:blackstone)
B(14,0,11,minecraft:blackstone)
B(15,0,11,minecraft:blackstone)
B(2,0,12,minecraft:blackstone)
B(3,0,12,minecraft:blackstone)
B(4,0,12,minecraft:blackstone)
B(5,0,12,minecraft:blackstone)
B(6,0,12,minecraft:blackstone)
B(7,0,12,minecraft:blackstone)
B(8,0,12,minecraft:blackstone)
B(9,0,12,minecraft:blackstone)
B(10,0,12,minecraft:blackstone)
B(11,0,12,minecraft:blackstone)
B(12,0,12,minecraft:blackstone)
B(13,0,12,minecraft:blackstone)
B(14,0,12,minecraft:blackstone)
B(15,0,12,minecraft:blackstone)
B(2,0,13,minecraft:blackstone)
B(3,0,13,minecraft:blackstone)
B(4,0,13,minecraft:blackstone)
B(5,0,13,minecraft:blackstone)
B(6,0,13,minecraft:blackstone)
B(7,0,13,minecraft:blackstone)
B(8,0,13,minecraft:blackstone)
B(9,0,13,minecraft:blackstone)
B(10,0,13,minecraft:blackstone)
B(11,0,13,minecraft:blackstone)
B(12,0,13,minecraft:blackstone)
B(13,0,13,minecraft:blackstone)
B(14,0,13,minecraft:blackstone)
B(15,0,13,minecraft:blackstone)
B(2,0,14,minecraft:blackstone)
B(3,0,14,minecraft:blackstone)
B(4,0,14,minecraft:blackstone)
B(5,0,14,minecraft:blackstone)
B(6,0,14,minecraft:blackstone)
B(7,0,14,minecraft:blackstone)
B(8,0,14,minecraft:blackstone)
B(9,0,14,minecraft:blackstone)
B(10,0,14,minecraft:blackstone)
B(11,0,14,minecraft:blackstone)
B(12,0,14,minecraft:blackstone)
B(13,0,14,minecraft:blackstone)
B(14,0,14,minecraft:blackstone)
B(15,0,14,minecraft:blackstone)
B(2,0,15,minecraft:blackstone)
B(3,0,15,minecraft:blackstone)
B(4,0,15,minecraft:blackstone)
B(5,0,15,minecraft:blackstone)
B(6,0,15,minecraft:blackstone)
B(7,0,15,minecraft:blackstone)
B(8,0,15,minecraft:blackstone)
B(9,0,15,minecraft:blackstone)
B(10,0,15,minecraft:blackstone)
B(11,0,15,minecraft:blackstone)
B(12,0,15,minecraft:blackstone)
B(13,0,15,minecraft:blackstone)
B(14,0,15,minecraft:blackstone)
B(15,0,15,minecraft:blackstone)
B(2,1,0,minecraft:blackstone)
B(3,1,0,minecraft:blackstone)
B(4,1,0,minecraft:blackstone)
B(5,1,0,minecraft:blackstone)
B(6,1,0,minecraft:blackstone)
B(7,1,0,minecraft:blackstone)
B(8,1,0,minecraft:blackstone)
B(9,1,0,minecraft:blackstone)
B(10,1,0,minecraft:blackstone)
B(11,1,0,minecraft:blackstone)
B(12,1,0,minecraft:blackstone)
B(13,1,0,minecraft:blackstone)
B(14,1,0,minecraft:blackstone)
B(15,1,0,minecraft:blackstone)
B(2,1,1,minecraft:blackstone)
B(3,1,1,minecraft:blackstone)
B(4,1,1,minecraft:blackstone)
B(5,1,1,minecraft:blackstone)
B(6,1,1,minecraft:blackstone)
B(7,1,1,minecraft:blackstone)
B(8,1,1,minecraft:blackstone)
B(9,1,1,minecraft:blackstone)
B(10,1,1,minecraft:blackstone)
B(11,1,1,minecraft:blackstone)
B(12,1,1,minecraft:blackstone)
B(13,1,1,minecraft:blackstone)
B(14,1,1,minecraft:blackstone)
B(15,1,1,minecraft:blackstone)
B(2,1,2,minecraft:blackstone)
B(3,1,2,minecraft:blackstone)
B(4,1,2,minecraft:blackstone)
B(5,1,2,minecraft:blackstone)
B(6,1,2,minecraft:blackstone)
B(7,1,2,minecraft:blackstone)
B(8,1,2,minecraft:blackstone)
B(9,1,2,minecraft:blackstone)
B(10,1,2,minecraft:blackstone)
B(11,1,2,minecraft:blackstone)
B(12,1,2,minecraft:blackstone)
B(13,1,2,minecraft:blackstone)
B(14,1,2,minecraft:blackstone)
B(15,1,2,minecraft:blackstone)
B(2,1,3,minecraft:blackstone)
B(3,1,3,minecraft:blackstone)
B(4,1,3,minecraft:blackstone)
B(5,1,3,minecraft:blackstone)
B(6,1,3,minecraft:blackstone)
B(7,1,3,minecraft:blackstone)
B(8,1,3,minecraft:blackstone)
B(9,1,3,minecraft:blackstone)
B(10,1,3,minecraft:blackstone)
B(11,1,3,minecraft:blackstone)
B(12,1,3,minecraft:blackstone)
B(13,1,3,minecraft:blackstone)
B(14,1,3,minecraft:blackstone)
B(15,1,3,minecraft:blackstone)
B(2,1,4,minecraft:blackstone)
B(3,1,4,minecraft:blackstone)
B(4,1,4,minecraft:blackstone)
B(5,1,4,minecraft:blackstone)
B(6,1,4,minecraft:blackstone)
B(7,1,4,minecraft:blackstone)
B(8,1,4,minecraft:blackstone)
B(9,1,4,minecraft:blackstone)
B(10,1,4,minecraft:blackstone)
B(11,1,4,minecraft:blackstone)
B(12,1,4,minecraft:blackstone)
B(13,1,4,minecraft:blackstone)
B(14,1,4,minecraft:blackstone)
B(15,1,4,minecraft:blackstone)
B(2,1,5,minecraft:blackstone)
B(3,1,5,minecraft:blackstone)
B(4,1,5,minecraft:blackstone)
B(5,1,5,minecraft:blackstone)
B(6,1,5,minecraft:blackstone)
B(7,1,5,minecraft:blackstone)
B(8,1,5,minecraft:blackstone)
B(9,1,5,minecraft:blackstone)
B(10,1,5,minecraft:blackstone)
B(11,1,5,minecraft:blackstone)
B(12,1,5,minecraft:blackstone)
B(13,1,5,minecraft:blackstone)
B(14,1,5,minecraft:blackstone)
B(15,1,5,minecraft:blackstone)
B(2,1,6,minecraft:blackstone)
B(3,1,6,minecraft:blackstone)
B(4,1,6,minecraft:blackstone)
B(5,1,6,minecraft:blackstone)
B(6,1,6,minecraft:blackstone)
B(7,1,6,minecraft:blackstone)
B(8,1,6,minecraft:blackstone)
B(9,1,6,minecraft:blackstone)
B(10,1,6,minecraft:blackstone)
B(11,1,6,minecraft:blackstone)
B(12,1,6,minecraft:blackstone)
B(13,1,6,minecraft:blackstone)
B(14,1,6,minecraft:blackstone)
B(15,1,6,minecraft:blackstone)
B(2,1,7,minecraft:blackstone)
B(3,1,7,minecraft:blackstone)
B(4,1,7,minecraft:blackstone)
B(5,1,7,minecraft:blackstone)
B(6,1,7,minecraft:blackstone)
B(7,1,7,minecraft:blackstone)
B(8,1,7,minecraft:blackstone)
B(9,1,7,minecraft:blackstone)
B(10,1,7,minecraft:blackstone)
B(11,1,7,minecraft:blackstone)
B(12,1,7,minecraft:blackstone)
B(13,1,7,minecraft:blackstone)
B(14,1,7,minecraft:blackstone)
B(15,1,7,minecraft:blackstone)
B(2,1,8,minecraft:blackstone)
B(3,1,8,minecraft:blackstone)
B(4,1,8,minecraft:blackstone)
B(5,1,8,minecraft:blackstone)
B(6,1,8,minecraft:blackstone)
B(7,1,8,minecraft:blackstone)
B(8,1,8,minecraft:blackstone)
B(9,1,8,minecraft:blackstone)
B(10,1,8,minecraft:blackstone)
B(11,1,8,minecraft:blackstone)
B(12,1,8,minecraft:blackstone)
B(13,1,8,minecraft:blackstone)
B(14,1,8,minecraft:blackstone)
B(15,1,8,minecraft:blackstone)
B(2,1,9,minecraft:blackstone)
B(3,1,9,minecraft:blackstone)
B(4,1,9,minecraft:blackstone)
B(5,1,9,minecraft:blackstone)
B(6,1,9,minecraft:blackstone)
B(7,1,9,minecraft:blackstone)
B(8,1,9,minecraft:blackstone)
B(9,1,9,minecraft:blackstone)
B(10,1,9,minecraft:blackstone)
B(11,1,9,minecraft:blackstone)
B(12,1,9,minecraft:blackstone)
B(13,1,9,minecraft:blackstone)
B(14,1,9,minecraft:blackstone)
B(15,1,9,minecraft:blackstone)
B(2,1,10,minecraft:blackstone)
B(3,1,10,minecraft:blackstone)
B(4,1,10,minecraft:blackstone)
B(5,1,10,minecraft:blackstone)
B(6,1,10,minecraft:blackstone)
B(7,1,10,minecraft:blackstone)
B(8,1,10,minecraft:blackstone)
B(9,1,10,minecraft:blackstone)
B(10,1,10,minecraft:blackstone)
B(11,1,10,minecraft:blackstone)
B(12,1,10,minecraft:blackstone)
B(13,1,10,minecraft:blackstone)
B(14,1,10,minecraft:blackstone)
B(15,1,10,minecraft:blackstone)
B(2,1,11,minecraft:blackstone)
B(3,1,11,minecraft:blackstone)
B(4,1,11,minecraft:blackstone)
B(5,1,11,minecraft:blackstone)
B(6,1,11,minecraft:blackstone)
B(7,1,11,minecraft:blackstone)
B(8,1,11,minecraft:blackstone)
B(9,1,11,minecraft:blackstone)
B(10,1,11,minecraft:blackstone)
B(11,1,11,minecraft:blackstone)
B(12,1,11,minecraft:blackstone)
B(13,1,11,minecraft:blackstone)
B(14,1,11,minecraft:blackstone)
B(15,1,11,minecraft:blackstone)
B(2,1,12,minecraft:blackstone)
B(3,1,12,minecraft:blackstone)
B(4,1,12,minecraft:blackstone)
B(5,1,12,minecraft:blackstone)
B(6,1,12,minecraft:blackstone)
B(7,1,12,minecraft:blackstone)
B(8,1,12,minecraft:blackstone)
B(9,1,12,minecraft:blackstone)
B(10,1,12,minecraft:blackstone)
B(11,1,12,minecraft:blackstone)
B(12,1,12,minecraft:blackstone)
B(13,1,12,minecraft:blackstone)
B(14,1,12,minecraft:blackstone)
B(15,1,12,minecraft:blackstone)
B(2,1,13,minecraft:blackstone)
B(3,1,13,minecraft:blackstone)
B(4,1,13,minecraft:blackstone)
B(5,1,13,minecraft:blackstone)
B(6,1,13,minecraft:blackstone)
B(7,1,13,minecraft:blackstone)
B(8,1,13,minecraft:blackstone)
B(9,1,13,minecraft:blackstone)
B(10,1,13,minecraft:blackstone)
B(11,1,13,minecraft:blackstone)
B(12,1,13,minecraft:blackstone)
B(13,1,13,minecraft:blackstone)
B(14,1,13,minecraft:blackstone)
B(15,1,13,minecraft:blackstone)
B(2,1,14,minecraft:blackstone)
B(3,1,14,minecraft:blackstone)
B(4,1,14,minecraft:blackstone)
B(5,1,14,minecraft:blackstone)
B(6,1,14,minecraft:blackstone)
B(7,1,14,minecraft:blackstone)
B(8,1,14,minecraft:blackstone)
B(9,1,14,minecraft:blackstone)
B(10,1,14,minecraft:blackstone)
B(11,1,14,minecraft:blackstone)
B(12,1,14,minecraft:blackstone)
B(13,1,14,minecraft:blackstone)
B(14,1,14,minecraft:blackstone)
B(15,1,14,minecraft:blackstone)
B(2,1,15,minecraft:blackstone)
B(3,1,15,minecraft:blackstone)
B(4,1,15,minecraft:blackstone)
B(5,1,15,minecraft:blackstone)
B(6,1,15,minecraft:blackstone)
B(7,1,15,minecraft:blackstone)
B(8,1,15,minecraft:blackstone)
B(9,1,15,minecraft:blackstone)
B(10,1,15,minecraft:blackstone)
B(11,1,15,minecraft:blackstone)
B(12,1,15,minecraft:blackstone)
B(13,1,15,minecraft:blackstone)
B(14,1,15,minecraft:blackstone)
B(15,1,15,minecraft:blackstone)
B(2,2,0,minecraft:blackstone)
B(3,2,0,minecraft:blackstone)
B(4,2,0,minecraft:blackstone)
B(5,2,0,minecraft:blackstone)
B(6,2,0,minecraft:blackstone)
B(7,2,0,minecraft:blackstone)
B(8,2,0,minecraft:blackstone)
B(9,2,0,minecraft:blackstone)
B(10,2,0,minecraft:blackstone)
B(11,2,0,minecraft:blackstone)
B(12,2,0,minecraft:blackstone)
B(13,2,0,minecraft:blackstone)
B(14,2,0,minecraft:blackstone)
B(15,2,0,minecraft:blackstone)
B(2,2,1,minecraft:blackstone)
B(3,2,1,minecraft:blackstone)
B(4,2,1,minecraft:blackstone)
B(5,2,1,minecraft:blackstone)
B(6,2,1,minecraft:blackstone)
B(7,2,1,minecraft:blackstone)
B(8,2,1,minecraft:blackstone)
B(9,2,1,minecraft:blackstone)
B(10,2,1,minecraft:blackstone)
B(11,2,1,minecraft:blackstone)
B(12,2,1,minecraft:blackstone)
B(13,2,1,minecraft:blackstone)
B(14,2,1,minecraft:blackstone)
B(15,2,1,minecraft:blackstone)
B(2,2,2,minecraft:blackstone)
B(3,2,2,minecraft:blackstone)
B(4,2,2,minecraft:blackstone)
B(5,2,2,minecraft:blackstone)
B(6,2,2,minecraft:blackstone)
B(7,2,2,minecraft:blackstone)
B(8,2,2,minecraft:blackstone)
B(9,2,2,minecraft:blackstone)
B(10,2,2,minecraft:blackstone)
B(11,2,2,minecraft:blackstone)
B(12,2,2,minecraft:blackstone)
B(13,2,2,minecraft:blackstone)
B(14,2,2,minecraft:blackstone)
B(15,2,2,minecraft:blackstone)
B(2,2,3,minecraft:blackstone)
B(3,2,3,minecraft:blackstone)
B(4,2,3,minecraft:blackstone)
B(5,2,3,minecraft:blackstone)
B(6,2,3,minecraft:blackstone)
B(7,2,3,minecraft:blackstone)
B(8,2,3,minecraft:blackstone)
B(9,2,3,minecraft:blackstone)
B(10,2,3,minecraft:blackstone)
B(11,2,3,minecraft:blackstone)
B(12,2,3,minecraft:blackstone)
B(13,2,3,minecraft:blackstone)
B(14,2,3,minecraft:blackstone)
B(15,2,3,minecraft:blackstone)
B(2,2,4,minecraft:blackstone)
B(3,2,4,minecraft:blackstone)
B(4,2,4,minecraft:blackstone)
B(5,2,4,minecraft:blackstone)
B(6,2,4,minecraft:blackstone)
B(7,2,4,minecraft:blackstone)
B(8,2,4,minecraft:blackstone)
B(9,2,4,minecraft:blackstone)
B(10,2,4,minecraft:blackstone)
B(11,2,4,minecraft:blackstone)
B(12,2,4,minecraft:blackstone)
B(13,2,4,minecraft:blackstone)
B(14,2,4,minecraft:blackstone)
B(15,2,4,minecraft:blackstone)
B(2,2,5,minecraft:blackstone)
B(3,2,5,minecraft:blackstone)
B(4,2,5,minecraft:blackstone)
B(5,2,5,minecraft:blackstone)
B(6,2,5,minecraft:blackstone)
B(7,2,5,minecraft:blackstone)
B(8,2,5,minecraft:blackstone)
B(9,2,5,minecraft:blackstone)
B(10,2,5,minecraft:blackstone)
B(11,2,5,minecraft:blackstone)
B(12,2,5,minecraft:blackstone)
B(13,2,5,minecraft:blackstone)
B(14,2,5,minecraft:blackstone)
B(15,2,5,minecraft:blackstone)
B(2,2,6,minecraft:blackstone)
B(3,2,6,minecraft:blackstone)
B(4,2,6,minecraft:blackstone)
B(5,2,6,minecraft:blackstone)
B(6,2,6,minecraft:blackstone)
B(7,2,6,minecraft:blackstone)
B(8,2,6,minecraft:blackstone)
B(9,2,6,minecraft:blackstone)
B(10,2,6,minecraft:blackstone)
B(11,2,6,minecraft:blackstone)
B(12,2,6,minecraft:blackstone)
B(13,2,6,minecraft:blackstone)
B(14,2,6,minecraft:blackstone)
B(15,2,6,minecraft:blackstone)
B(2,2,7,minecraft:blackstone)
B(3,2,7,minecraft:blackstone)
B(4,2,7,minecraft:blackstone)
B(5,2,7,minecraft:blackstone)
B(6,2,7,minecraft:blackstone)
B(7,2,7,minecraft:blackstone)
B(8,2,7,minecraft:blackstone)
B(9,2,7,minecraft:blackstone)
B(10,2,7,minecraft:blackstone)
B(11,2,7,minecraft:blackstone)
B(12,2,7,minecraft:blackstone)
B(13,2,7,minecraft:blackstone)
B(14,2,7,minecraft:blackstone)
B(15,2,7,minecraft:blackstone)
B(2,2,8,minecraft:blackstone)
B(3,2,8,minecraft:blackstone)
B(4,2,8,minecraft:blackstone)
B(5,2,8,minecraft:blackstone)
B(6,2,8,minecraft:blackstone)
B(7,2,8,minecraft:blackstone)
B(8,2,8,minecraft:blackstone)
B(9,2,8,minecraft:blackstone)
B(10,2,8,minecraft:blackstone)
B(11,2,8,minecraft:blackstone)
B(12,2,8,minecraft:blackstone)
B(13,2,8,minecraft:blackstone)
B(14,2,8,minecraft:blackstone)
B(15,2,8,minecraft:blackstone)
B(2,2,9,minecraft:blackstone)
B(3,2,9,minecraft:blackstone)
B(4,2,9,minecraft:blackstone)
B(5,2,9,minecraft:blackstone)
B(6,2,9,minecraft:blackstone)
B(7,2,9,minecraft:blackstone)
B(8,2,9,minecraft:blackstone)
B(9,2,9,minecraft:blackstone)
B(10,2,9,minecraft:blackstone)
B(11,2,9,minecraft:blackstone)
B(12,2,9,minecraft:blackstone)
B(13,2,9,minecraft:blackstone)
B(14,2,9,minecraft:blackstone)
B(15,2,9,minecraft:blackstone)
B(2,2,10,minecraft:blackstone)
B(3,2,10,minecraft:blackstone)
B(4,2,10,minecraft:blackstone)
B(5,2,10,minecraft:blackstone)
B(6,2,10,minecraft:blackstone)
B(7,2,10,minecraft:blackstone)
B(8,2,10,minecraft:blackstone)
B(9,2,10,minecraft:blackstone)
B(10,2,10,minecraft:blackstone)
B(11,2,10,minecraft:blackstone)
B(12,2,10,minecraft:blackstone)
B(13,2,10,minecraft:blackstone)
B(14,2,10,minecraft:blackstone)
B(15,2,10,minecraft:blackstone)
B(2,2,11,minecraft:blackstone)
B(4,2,11,minecraft:blackstone)
B(5,2,11,minecraft:blackstone)
B(6,2,11,minecraft:blackstone)
B(7,2,11,minecraft:blackstone)
B(8,2,11,minecraft:blackstone)
B(9,2,11,minecraft:blackstone)
B(10,2,11,minecraft:blackstone)
B(11,2,11,minecraft:blackstone)
B(12,2,11,minecraft:blackstone)
B(13,2,11,minecraft:blackstone)
B(14,2,11,minecraft:blackstone)
B(15,2,11,minecraft:blackstone)
B(2,2,12,minecraft:blackstone)
B(3,2,12,minecraft:blackstone)
B(4,2,12,minecraft:blackstone)
B(5,2,12,minecraft:blackstone)
B(6,2,12,minecraft:blackstone)
B(7,2,12,minecraft:blackstone)
B(8,2,12,minecraft:blackstone)
B(9,2,12,minecraft:blackstone)
B(10,2,12,minecraft:blackstone)
B(11,2,12,minecraft:blackstone)
B(12,2,12,minecraft:blackstone)
B(13,2,12,minecraft:blackstone)
B(14,2,12,minecraft:blackstone)
B(15,2,12,minecraft:blackstone)
B(2,2,13,minecraft:blackstone)
B(3,2,13,minecraft:blackstone)
B(4,2,13,minecraft:blackstone)
B(5,2,13,minecraft:blackstone)
B(6,2,13,minecraft:blackstone)
B(7,2,13,minecraft:blackstone)
B(8,2,13,minecraft:blackstone)
B(9,2,13,minecraft:blackstone)
B(10,2,13,minecraft:blackstone)
B(11,2,13,minecraft:blackstone)
B(12,2,13,minecraft:blackstone)
B(13,2,13,minecraft:blackstone)
B(14,2,13,minecraft:blackstone)
B(15,2,13,minecraft:blackstone)
B(2,2,14,minecraft:blackstone)
B(3,2,14,minecraft:blackstone)
B(4,2,14,minecraft:blackstone)
B(5,2,14,minecraft:blackstone)
B(6,2,14,minecraft:blackstone)
B(7,2,14,minecraft:blackstone)
B(8,2,14,minecraft:blackstone)
B(9,2,14,minecraft:blackstone)
B(10,2,14,minecraft:blackstone)
B(11,2,14,minecraft:blackstone)
B(12,2,14,minecraft:blackstone)
B(13,2,14,minecraft:blackstone)
B(14,2,14,minecraft:blackstone)
B(15,2,14,minecraft:blackstone)
B(2,2,15,minecraft:blackstone)
B(3,2,15,minecraft:blackstone)
B(4,2,15,minecraft:blackstone)
B(5,2,15,minecraft:blackstone)
B(6,2,15,minecraft:blackstone)
B(7,2,15,minecraft:blackstone)
B(8,2,15,minecraft:blackstone)
B(9,2,15,minecraft:blackstone)
B(10,2,15,minecraft:blackstone)
B(11,2,15,minecraft:blackstone)
B(12,2,15,minecraft:blackstone)
B(13,2,15,minecraft:blackstone)
B(14,2,15,minecraft:blackstone)
B(15,2,15,minecraft:blackstone)
B(2,3,0,minecraft:blackstone)
B(3,3,0,minecraft:blackstone)
B(4,3,0,minecraft:blackstone)
B(5,3,0,minecraft:blackstone)
B(6,3,0,minecraft:blackstone)
B(7,3,0,minecraft:blackstone)
B(8,3,0,minecraft:blackstone)
B(9,3,0,minecraft:blackstone)
B(10,3,0,minecraft:blackstone)
B(11,3,0,minecraft:blackstone)
B(12,3,0,minecraft:blackstone)
B(13,3,0,minecraft:blackstone)
B(14,3,0,minecraft:blackstone)
B(15,3,0,minecraft:blackstone)
B(2,3,1,minecraft:blackstone)
B(3,3,1,minecraft:blackstone)
B(4,3,1,minecraft:blackstone)
B(5,3,1,minecraft:blackstone)
B(6,3,1,minecraft:blackstone)
B(7,3,1,minecraft:blackstone)
B(8,3,1,minecraft:blackstone)
B(9,3,1,minecraft:blackstone)
B(10,3,1,minecraft:blackstone)
B(11,3,1,minecraft:blackstone)
B(12,3,1,minecraft:blackstone)
B(13,3,1,minecraft:blackstone)
B(14,3,1,minecraft:blackstone)
B(15,3,1,minecraft:blackstone)
B(2,3,2,minecraft:blackstone)
B(3,3,2,minecraft:blackstone)
B(4,3,2,minecraft:blackstone)
B(5,3,2,minecraft:blackstone)
B(6,3,2,minecraft:blackstone)
B(7,3,2,minecraft:blackstone)
B(8,3,2,minecraft:blackstone)
B(9,3,2,minecraft:blackstone)
B(10,3,2,minecraft:blackstone)
B(11,3,2,minecraft:blackstone)
B(12,3,2,minecraft:blackstone)
B(13,3,2,minecraft:blackstone)
B(14,3,2,minecraft:blackstone)
B(15,3,2,minecraft:blackstone)
B(2,3,3,minecraft:blackstone)
B(3,3,3,minecraft:blackstone)
B(4,3,3,minecraft:blackstone)
B(5,3,3,minecraft:blackstone)
B(6,3,3,minecraft:blackstone)
B(7,3,3,minecraft:blackstone)
B(8,3,3,minecraft:blackstone)
B(9,3,3,minecraft:blackstone)
B(10,3,3,minecraft:blackstone)
B(11,3,3,minecraft:blackstone)
B(12,3,3,minecraft:blackstone)
B(13,3,3,minecraft:blackstone)
B(14,3,3,minecraft:blackstone)
B(15,3,3,minecraft:blackstone)
B(2,3,4,minecraft:blackstone)
B(3,3,4,minecraft:blackstone)
B(4,3,4,minecraft:blackstone)
B(5,3,4,minecraft:blackstone)
B(6,3,4,minecraft:blackstone)
B(7,3,4,minecraft:blackstone)
B(8,3,4,minecraft:blackstone)
B(9,3,4,minecraft:blackstone)
B(10,3,4,minecraft:blackstone)
B(11,3,4,minecraft:blackstone)
B(12,3,4,minecraft:blackstone)
B(13,3,4,minecraft:blackstone)
B(14,3,4,minecraft:blackstone)
B(15,3,4,minecraft:blackstone)
B(2,3,5,minecraft:blackstone)
B(3,3,5,minecraft:blackstone)
B(4,3,5,minecraft:blackstone)
B(5,3,5,minecraft:blackstone)
B(6,3,5,minecraft:blackstone)
B(7,3,5,minecraft:blackstone)
B(8,3,5,minecraft:blackstone)
B(9,3,5,minecraft:blackstone)
B(10,3,5,minecraft:blackstone)
B(11,3,5,minecraft:blackstone)
B(12,3,5,minecraft:blackstone)
B(13,3,5,minecraft:blackstone)
B(14,3,5,minecraft:blackstone)
B(15,3,5,minecraft:blackstone)
B(2,3,6,minecraft:blackstone)
B(3,3,6,minecraft:blackstone)
B(4,3,6,minecraft:blackstone)
B(5,3,6,minecraft:blackstone)
B(6,3,6,minecraft:blackstone)
B(7,3,6,minecraft:blackstone)
B(8,3,6,minecraft:blackstone)
B(9,3,6,minecraft:blackstone)
B(10,3,6,minecraft:blackstone)
B(11,3,6,minecraft:blackstone)
B(12,3,6,minecraft:blackstone)
B(13,3,6,minecraft:blackstone)
B(14,3,6,minecraft:blackstone)
B(15,3,6,minecraft:blackstone)
B(2,3,7,minecraft:blackstone)
B(3,3,7,minecraft:blackstone)
B(4,3,7,minecraft:blackstone)
B(5,3,7,minecraft:blackstone)
B(6,3,7,minecraft:blackstone)
B(7,3,7,minecraft:blackstone)
B(8,3,7,minecraft:blackstone)
B(9,3,7,minecraft:blackstone)
B(10,3,7,minecraft:blackstone)
B(11,3,7,minecraft:blackstone)
B(12,3,7,minecraft:blackstone)
B(13,3,7,minecraft:blackstone)
B(14,3,7,minecraft:blackstone)
B(15,3,7,minecraft:blackstone)
B(2,3,8,minecraft:blackstone)
B(3,3,8,minecraft:blackstone)
B(4,3,8,minecraft:blackstone)
B(5,3,8,minecraft:blackstone)
B(6,3,8,minecraft:blackstone)
B(7,3,8,minecraft:blackstone)
B(8,3,8,minecraft:blackstone)
B(9,3,8,minecraft:blackstone)
B(10,3,8,minecraft:blackstone)
B(11,3,8,minecraft:blackstone)
B(12,3,8,minecraft:blackstone)
B(13,3,8,minecraft:blackstone)
B(14,3,8,minecraft:blackstone)
B(15,3,8,minecraft:blackstone)
B(2,3,9,minecraft:blackstone)
B(3,3,9,minecraft:blackstone)
B(4,3,9,minecraft:blackstone)
B(5,3,9,minecraft:blackstone)
B(6,3,9,minecraft:blackstone)
B(7,3,9,minecraft:blackstone)
B(8,3,9,minecraft:blackstone)
B(9,3,9,minecraft:blackstone)
B(10,3,9,minecraft:blackstone)
B(11,3,9,minecraft:blackstone)
B(12,3,9,minecraft:blackstone)
B(13,3,9,minecraft:blackstone)
B(14,3,9,minecraft:blackstone)
B(15,3,9,minecraft:blackstone)
B(4,3,10,minecraft:blackstone)
B(5,3,10,minecraft:blackstone)
B(6,3,10,minecraft:blackstone)
B(7,3,10,minecraft:blackstone)
B(8,3,10,minecraft:blackstone)
B(9,3,10,minecraft:blackstone)
B(10,3,10,minecraft:blackstone)
B(11,3,10,minecraft:blackstone)
B(12,3,10,minecraft:blackstone)
B(13,3,10,minecraft:blackstone)
B(14,3,10,minecraft:blackstone)
B(15,3,10,minecraft:blackstone)
B(4,3,11,minecraft:blackstone)
B(5,3,11,minecraft:blackstone)
B(6,3,11,minecraft:blackstone)
B(7,3,11,minecraft:blackstone)
B(8,3,11,minecraft:blackstone)
B(9,3,11,minecraft:blackstone)
B(10,3,11,minecraft:blackstone)
B(11,3,11,minecraft:blackstone)
B(12,3,11,minecraft:blackstone)
B(13,3,11,minecraft:blackstone)
B(14,3,11,minecraft:blackstone)
B(15,3,11,minecraft:blackstone)
B(4,3,12,minecraft:blackstone)
B(5,3,12,minecraft:blackstone)
B(6,3,12,minecraft:blackstone)
B(7,3,12,minecraft:blackstone)
B(8,3,12,minecraft:blackstone)
B(9,3,12,minecraft:blackstone)
B(10,3,12,minecraft:blackstone)
B(11,3,12,minecraft:blackstone)
B(12,3,12,minecraft:blackstone)
B(13,3,12,minecraft:blackstone)
B(14,3,12,minecraft:blackstone)
B(15,3,12,minecraft:blackstone)
B(3,3,13,minecraft:blackstone)
B(4,3,13,minecraft:blackstone)
B(5,3,13,minecraft:blackstone)
B(6,3,13,minecraft:blackstone)
B(7,3,13,minecraft:blackstone)
B(8,3,13,minecraft:blackstone)
B(9,3,13,minecraft:blackstone)
B(10,3,13,minecraft:blackstone)
B(11,3,13,minecraft:blackstone)
B(12,3,13,minecraft:blackstone)
B(13,3,13,minecraft:blackstone)
B(14,3,13,minecraft:blackstone)
B(15,3,13,minecraft:blackstone)
B(3,3,14,minecraft:blackstone)
B(4,3,14,minecraft:blackstone)
B(5,3,14,minecraft:blackstone)
B(6,3,14,minecraft:blackstone)
B(7,3,14,minecraft:blackstone)
B(8,3,14,minecraft:blackstone)
B(9,3,14,minecraft:blackstone)
B(10,3,14,minecraft:blackstone)
B(11,3,14,minecraft:blackstone)
B(12,3,14,minecraft:blackstone)
B(13,3,14,minecraft:blackstone)
B(14,3,14,minecraft:blackstone)
B(15,3,14,minecraft:blackstone)
B(3,3,15,minecraft:blackstone)
B(4,3,15,minecraft:blackstone)
B(5,3,15,minecraft:blackstone)
B(6,3,15,minecraft:blackstone)
B(7,3,15,minecraft:blackstone)
B(8,3,15,minecraft:blackstone)
B(9,3,15,minecraft:blackstone)
B(10,3,15,minecraft:blackstone)
B(11,3,15,minecraft:blackstone)
B(12,3,15,minecraft:blackstone)
B(13,3,15,minecraft:blackstone)
B(14,3,15,minecraft:blackstone)
B(15,3,15,minecraft:blackstone)
B(2,4,0,minecraft:blackstone)
B(3,4,0,minecraft:blackstone)
B(4,4,0,minecraft:blackstone)
B(5,4,0,minecraft:blackstone)
B(6,4,0,minecraft:blackstone)
B(7,4,0,minecraft:blackstone)
B(8,4,0,minecraft:blackstone)
B(9,4,0,minecraft:blackstone)
B(10,4,0,minecraft:blackstone)
B(11,4,0,minecraft:blackstone)
B(12,4,0,minecraft:blackstone)
B(13,4,0,minecraft:blackstone)
B(14,4,0,minecraft:blackstone)
B(15,4,0,minecraft:blackstone)
B(2,4,1,minecraft:blackstone)
B(3,4,1,minecraft:blackstone)
B(4,4,1,minecraft:blackstone)
B(5,4,1,minecraft:blackstone)
B(6,4,1,minecraft:blackstone)
B(7,4,1,minecraft:blackstone)
B(8,4,1,minecraft:blackstone)
B(9,4,1,minecraft:blackstone)
B(10,4,1,minecraft:blackstone)
B(11,4,1,minecraft:blackstone)
B(12,4,1,minecraft:blackstone)
B(13,4,1,minecraft:blackstone)
B(14,4,1,minecraft:blackstone)
B(15,4,1,minecraft:blackstone)
B(2,4,2,minecraft:blackstone)
B(3,4,2,minecraft:blackstone)
B(4,4,2,minecraft:blackstone)
B(5,4,2,minecraft:blackstone)
B(6,4,2,minecraft:blackstone)
B(7,4,2,minecraft:blackstone)
B(8,4,2,minecraft:blackstone)
B(9,4,2,minecraft:blackstone)
B(10,4,2,minecraft:blackstone)
B(11,4,2,minecraft:blackstone)
B(12,4,2,minecraft:blackstone)
B(13,4,2,minecraft:blackstone)
B(14,4,2,minecraft:blackstone)
B(15,4,2,minecraft:blackstone)
B(2,4,3,minecraft:blackstone)
B(3,4,3,minecraft:blackstone)
B(4,4,3,minecraft:blackstone)
B(5,4,3,minecraft:blackstone)
B(6,4,3,minecraft:blackstone)
B(7,4,3,minecraft:blackstone)
B(8,4,3,minecraft:blackstone)
B(9,4,3,minecraft:blackstone)
B(10,4,3,minecraft:blackstone)
B(11,4,3,minecraft:blackstone)
B(12,4,3,minecraft:blackstone)
B(13,4,3,minecraft:blackstone)
B(14,4,3,minecraft:blackstone)
B(15,4,3,minecraft:blackstone)
B(2,4,4,minecraft:blackstone)
B(3,4,4,minecraft:blackstone)
B(4,4,4,minecraft:blackstone)
B(5,4,4,minecraft:blackstone)
B(6,4,4,minecraft:blackstone)
B(7,4,4,minecraft:blackstone)
B(8,4,4,minecraft:blackstone)
B(9,4,4,minecraft:blackstone)
B(10,4,4,minecraft:blackstone)
B(11,4,4,minecraft:blackstone)
B(12,4,4,minecraft:blackstone)
B(13,4,4,minecraft:blackstone)
B(14,4,4,minecraft:blackstone)
B(15,4,4,minecraft:blackstone)
B(2,4,5,minecraft:blackstone)
B(3,4,5,minecraft:blackstone)
B(4,4,5,minecraft:blackstone)
B(5,4,5,minecraft:blackstone)
B(6,4,5,minecraft:blackstone)
B(7,4,5,minecraft:blackstone)
B(8,4,5,minecraft:blackstone)
B(9,4,5,minecraft:blackstone)
B(10,4,5,minecraft:blackstone)
B(11,4,5,minecraft:blackstone)
B(12,4,5,minecraft:blackstone)
B(13,4,5,minecraft:blackstone)
B(14,4,5,minecraft:blackstone)
B(15,4,5,minecraft:blackstone)
B(2,4,6,minecraft:blackstone)
B(3,4,6,minecraft:blackstone)
B(4,4,6,minecraft:blackstone)
B(5,4,6,minecraft:blackstone)
B(6,4,6,minecraft:blackstone)
B(7,4,6,minecraft:blackstone)
B(8,4,6,minecraft:blackstone)
B(9,4,6,minecraft:blackstone)
B(10,4,6,minecraft:blackstone)
B(11,4,6,minecraft:blackstone)
B(12,4,6,minecraft:blackstone)
B(13,4,6,minecraft:blackstone)
B(14,4,6,minecraft:blackstone)
B(15,4,6,minecraft:blackstone)
B(2,4,7,minecraft:blackstone)
B(3,4,7,minecraft:blackstone)
B(4,4,7,minecraft:blackstone)
B(5,4,7,minecraft:blackstone)
B(6,4,7,minecraft:blackstone)
B(7,4,7,minecraft:blackstone)
B(8,4,7,minecraft:blackstone)
B(9,4,7,minecraft:blackstone)
B(10,4,7,minecraft:blackstone)
B(11,4,7,minecraft:blackstone)
B(12,4,7,minecraft:blackstone)
B(13,4,7,minecraft:blackstone)
B(14,4,7,minecraft:blackstone)
B(15,4,7,minecraft:blackstone)
B(2,4,8,minecraft:blackstone)
B(3,4,8,minecraft:blackstone)
B(4,4,8,minecraft:blackstone)
B(5,4,8,minecraft:blackstone)
B(6,4,8,minecraft:blackstone)
B(7,4,8,minecraft:blackstone)
B(8,4,8,minecraft:blackstone)
B(9,4,8,minecraft:blackstone)
B(10,4,8,minecraft:blackstone)
B(11,4,8,minecraft:blackstone)
B(12,4,8,minecraft:blackstone)
B(13,4,8,minecraft:blackstone)
B(14,4,8,minecraft:blackstone)
B(15,4,8,minecraft:blackstone)
B(2,4,9,minecraft:blackstone)
B(3,4,9,minecraft:blackstone)
B(4,4,9,minecraft:blackstone)
B(5,4,9,minecraft:blackstone)
B(6,4,9,minecraft:blackstone)
B(7,4,9,minecraft:blackstone)
B(8,4,9,minecraft:blackstone)
B(9,4,9,minecraft:blackstone)
B(10,4,9,minecraft:blackstone)
B(11,4,9,minecraft:blackstone)
B(12,4,9,minecraft:blackstone)
B(13,4,9,minecraft:blackstone)
B(14,4,9,minecraft:blackstone)
B(15,4,9,minecraft:blackstone)
B(4,4,10,minecraft:blackstone)
B(5,4,10,minecraft:blackstone)
B(6,4,10,minecraft:blackstone)
B(7,4,10,minecraft:blackstone)
B(8,4,10,minecraft:blackstone)
B(9,4,10,minecraft:blackstone)
B(10,4,10,minecraft:blackstone)
B(11,4,10,minecraft:blackstone)
B(12,4,10,minecraft:blackstone)
B(13,4,10,minecraft:blackstone)
B(14,4,10,minecraft:blackstone)
B(15,4,10,minecraft:blackstone)
B(6,4,11,minecraft:blackstone)
B(7,4,11,minecraft:blackstone)
B(8,4,11,minecraft:blackstone)
B(9,4,11,minecraft:blackstone)
B(10,4,11,minecraft:blackstone)
B(11,4,11,minecraft:blackstone)
B(12,4,11,minecraft:blackstone)
B(13,4,11,minecraft:blackstone)
B(14,4,11,minecraft:blackstone)
B(15,4,11,minecraft:blackstone)
B(6,4,12,minecraft:blackstone)
B(7,4,12,minecraft:blackstone)
B(8,4,12,minecraft:blackstone)
B(9,4,12,minecraft:blackstone)
B(10,4,12,minecraft:blackstone)
B(11,4,12,minecraft:blackstone)
B(12,4,12,minecraft:blackstone)
B(13,4,12,minecraft:blackstone)
B(14,4,12,minecraft:blackstone)
B(15,4,12,minecraft:blackstone)
B(5,4,13,minecraft:blackstone)
B(6,4,13,minecraft:blackstone)
B(7,4,13,minecraft:blackstone)
B(8,4,13,minecraft:blackstone)
B(9,4,13,minecraft:blackstone)
B(10,4,13,minecraft:blackstone)
B(11,4,13,minecraft:blackstone)
B(12,4,13,minecraft:blackstone)
B(13,4,13,minecraft:blackstone)
B(14,4,13,minecraft:blackstone)
B(15,4,13,minecraft:blackstone)
B(5,4,14,minecraft:blackstone)
B(6,4,14,minecraft:blackstone)
B(7,4,14,minecraft:blackstone)
B(8,4,14,minecraft:blackstone)
B(9,4,14,minecraft:blackstone)
B(10,4,14,minecraft:blackstone)
B(11,4,14,minecraft:blackstone)
B(12,4,14,minecraft:blackstone)
B(13,4,14,minecraft:blackstone)
B(14,4,14,minecraft:blackstone)
B(15,4,14,minecraft:blackstone)
B(5,4,15,minecraft:blackstone)
B(6,4,15,minecraft:blackstone)
B(7,4,15,minecraft:blackstone)
B(8,4,15,minecraft:blackstone)
B(9,4,15,minecraft:blackstone)
B(10,4,15,minecraft:blackstone)
B(11,4,15,minecraft:blackstone)
B(12,4,15,minecraft:blackstone)
B(13,4,15,minecraft:blackstone)
B(14,4,15,minecraft:blackstone)
B(15,4,15,minecraft:blackstone)
B(8,5,0,minecraft:blackstone)
B(9,5,0,minecraft:blackstone)
B(10,5,0,minecraft:blackstone)
B(11,5,0,minecraft:blackstone)
B(12,5,0,minecraft:blackstone)
B(13,5,0,minecraft:blackstone)
B(14,5,0,minecraft:blackstone)
B(15,5,0,minecraft:blackstone)
B(3,5,1,minecraft:blackstone)
B(4,5,1,minecraft:blackstone)
B(5,5,1,minecraft:blackstone)
B(6,5,1,minecraft:blackstone)
B(7,5,1,minecraft:blackstone)
B(8,5,1,minecraft:blackstone)
B(9,5,1,minecraft:blackstone)
B(10,5,1,minecraft:blackstone)
B(11,5,1,minecraft:blackstone)
B(12,5,1,minecraft:blackstone)
B(13,5,1,minecraft:blackstone)
B(14,5,1,minecraft:blackstone)
B(15,5,1,minecraft:blackstone)
B(2,5,2,minecraft:blackstone)
B(3,5,2,minecraft:blackstone)
B(4,5,2,minecraft:blackstone)
B(5,5,2,minecraft:blackstone)
B(6,5,2,minecraft:blackstone)
B(7,5,2,minecraft:blackstone)
B(8,5,2,minecraft:blackstone)
B(9,5,2,minecraft:blackstone)
B(10,5,2,minecraft:blackstone)
B(11,5,2,minecraft:blackstone)
B(12,5,2,minecraft:blackstone)
B(13,5,2,minecraft:blackstone)
B(14,5,2,minecraft:blackstone)
B(15,5,2,minecraft:blackstone)
B(2,5,3,minecraft:blackstone)
B(3,5,3,minecraft:blackstone)
B(4,5,3,minecraft:blackstone)
B(5,5,3,minecraft:blackstone)
B(6,5,3,minecraft:blackstone)
B(7,5,3,minecraft:blackstone)
B(8,5,3,minecraft:blackstone)
B(9,5,3,minecraft:blackstone)
B(10,5,3,minecraft:blackstone)
B(11,5,3,minecraft:blackstone)
B(12,5,3,minecraft:blackstone)
B(13,5,3,minecraft:blackstone)
B(14,5,3,minecraft:blackstone)
B(15,5,3,minecraft:blackstone)
B(2,5,4,minecraft:blackstone)
B(3,5,4,minecraft:blackstone)
B(4,5,4,minecraft:blackstone)
B(5,5,4,minecraft:blackstone)
B(6,5,4,minecraft:blackstone)
B(7,5,4,minecraft:blackstone)
B(8,5,4,minecraft:blackstone)
B(9,5,4,minecraft:blackstone)
B(10,5,4,minecraft:blackstone)
B(11,5,4,minecraft:blackstone)
B(12,5,4,minecraft:blackstone)
B(13,5,4,minecraft:blackstone)
B(14,5,4,minecraft:blackstone)
B(15,5,4,minecraft:blackstone)
B(2,5,5,minecraft:blackstone)
B(3,5,5,minecraft:blackstone)
B(4,5,5,minecraft:blackstone)
B(5,5,5,minecraft:blackstone)
B(6,5,5,minecraft:blackstone)
B(7,5,5,minecraft:blackstone)
B(8,5,5,minecraft:blackstone)
B(9,5,5,minecraft:blackstone)
B(10,5,5,minecraft:blackstone)
B(11,5,5,minecraft:blackstone)
B(12,5,5,minecraft:blackstone)
B(13,5,5,minecraft:blackstone)
B(14,5,5,minecraft:blackstone)
B(15,5,5,minecraft:blackstone)
B(2,5,6,minecraft:blackstone)
B(3,5,6,minecraft:blackstone)
B(4,5,6,minecraft:blackstone)
B(5,5,6,minecraft:blackstone)
B(6,5,6,minecraft:blackstone)
B(7,5,6,minecraft:blackstone)
B(8,5,6,minecraft:blackstone)
B(9,5,6,minecraft:blackstone)
B(10,5,6,minecraft:blackstone)
B(11,5,6,minecraft:blackstone)
B(12,5,6,minecraft:blackstone)
B(13,5,6,minecraft:blackstone)
B(14,5,6,minecraft:blackstone)
B(15,5,6,minecraft:blackstone)
B(2,5,7,minecraft:blackstone)
B(3,5,7,minecraft:blackstone)
B(4,5,7,minecraft:blackstone)
B(5,5,7,minecraft:blackstone)
B(6,5,7,minecraft:blackstone)
B(7,5,7,minecraft:blackstone)
B(8,5,7,minecraft:blackstone)
B(9,5,7,minecraft:blackstone)
B(10,5,7,minecraft:blackstone)
B(11,5,7,minecraft:blackstone)
B(12,5,7,minecraft:blackstone)
B(13,5,7,minecraft:blackstone)
B(14,5,7,minecraft:blackstone)
B(15,5,7,minecraft:blackstone)
B(2,5,8,minecraft:blackstone)
B(3,5,8,minecraft:blackstone)
B(4,5,8,minecraft:blackstone)
B(5,5,8,minecraft:blackstone)
B(6,5,8,minecraft:blackstone)
B(7,5,8,minecraft:blackstone)
B(8,5,8,minecraft:blackstone)
B(9,5,8,minecraft:blackstone)
B(10,5,8,minecraft:blackstone)
B(11,5,8,minecraft:blackstone)
B(12,5,8,minecraft:blackstone)
B(13,5,8,minecraft:blackstone)
B(14,5,8,minecraft:blackstone)
B(15,5,8,minecraft:blackstone)
B(3,5,9,minecraft:blackstone)
B(4,5,9,minecraft:blackstone)
B(5,5,9,minecraft:blackstone)
B(6,5,9,minecraft:blackstone)
B(7,5,9,minecraft:blackstone)
B(8,5,9,minecraft:blackstone)
B(9,5,9,minecraft:blackstone)
B(10,5,9,minecraft:blackstone)
B(11,5,9,minecraft:blackstone)
B(12,5,9,minecraft:blackstone)
B(13,5,9,minecraft:blackstone)
B(14,5,9,minecraft:blackstone)
B(15,5,9,minecraft:blackstone)
B(8,5,10,minecraft:blackstone)
B(9,5,10,minecraft:blackstone)
B(10,5,10,minecraft:blackstone)
B(11,5,10,minecraft:blackstone)
B(12,5,10,minecraft:blackstone)
B(13,5,10,minecraft:blackstone)
B(14,5,10,minecraft:blackstone)
B(15,5,10,minecraft:blackstone)
B(8,5,11,minecraft:blackstone)
B(9,5,11,minecraft:blackstone)
B(10,5,11,minecraft:blackstone)
B(11,5,11,minecraft:blackstone)
B(12,5,11,minecraft:blackstone)
B(13,5,11,minecraft:blackstone)
B(14,5,11,minecraft:blackstone)
B(15,5,11,minecraft:blackstone)
B(8,5,12,minecraft:blackstone)
B(9,5,12,minecraft:blackstone)
B(10,5,12,minecraft:blackstone)
B(11,5,12,minecraft:blackstone)
B(12,5,12,minecraft:blackstone)
B(13,5,12,minecraft:blackstone)
B(14,5,12,minecraft:blackstone)
B(15,5,12,minecraft:blackstone)
B(8,5,13,minecraft:blackstone)
B(9,5,13,minecraft:blackstone)
B(10,5,13,minecraft:blackstone)
B(11,5,13,minecraft:blackstone)
B(12,5,13,minecraft:blackstone)
B(13,5,13,minecraft:blackstone)
B(14,5,13,minecraft:blackstone)
B(15,5,13,minecraft:blackstone)
B(8,5,14,minecraft:blackstone)
B(9,5,14,minecraft:blackstone)
B(10,5,14,minecraft:blackstone)
B(11,5,14,minecraft:blackstone)
B(12,5,14,minecraft:blackstone)
B(13,5,14,minecraft:blackstone)
B(14,5,14,minecraft:blackstone)
B(15,5,14,minecraft:blackstone)
B(8,5,15,minecraft:blackstone)
B(9,5,15,minecraft:blackstone)
B(10,5,15,minecraft:blackstone)
B(11,5,15,minecraft:blackstone)
B(12,5,15,minecraft:blackstone)
B(13,5,15,minecraft:blackstone)
B(14,5,15,minecraft:blackstone)
B(15,5,15,minecraft:blackstone)
B(9,6,0,minecraft:blackstone)
B(10,6,0,minecraft:blackstone)
B(11,6,0,minecraft:blackstone)
B(12,6,0,minecraft:blackstone)
B(13,6,0,minecraft:blackstone)
B(14,6,0,minecraft:blackstone)
B(15,6,0,minecraft:blackstone)
B(9,6,1,minecraft:blackstone)
B(10,6,1,minecraft:blackstone)
B(11,6,1,minecraft:blackstone)
B(12,6,1,minecraft:blackstone)
B(13,6,1,minecraft:blackstone)
B(14,6,1,minecraft:blackstone)
B(15,6,1,minecraft:blackstone)
B(4,6,2,minecraft:blackstone)
B(5,6,2,minecraft:blackstone)
B(6,6,2,minecraft:blackstone)
B(7,6,2,minecraft:blackstone)
B(9,6,2,minecraft:blackstone)
B(10,6,2,minecraft:blackstone)
B(11,6,2,minecraft:blackstone)
B(12,6,2,minecraft:blackstone)
B(13,6,2,minecraft:blackstone)
B(14,6,2,minecraft:blackstone)
B(15,6,2,minecraft:blackstone)
B(3,6,3,minecraft:blackstone)
B(4,6,3,minecraft:blackstone)
B(5,6,3,minecraft:blackstone)
B(6,6,3,minecraft:blackstone)
B(7,6,3,minecraft:blackstone)
B(8,6,3,minecraft:blackstone)
B(9,6,3,minecraft:blackstone)
B(10,6,3,minecraft:blackstone)
B(11,6,3,minecraft:blackstone)
B(12,6,3,minecraft:blackstone)
B(13,6,3,minecraft:blackstone)
B(14,6,3,minecraft:blackstone)
B(15,6,3,minecraft:blackstone)
B(3,6,4,minecraft:blackstone)
B(4,6,4,minecraft:blackstone)
B(5,6,4,minecraft:blackstone)
B(6,6,4,minecraft:blackstone)
B(7,6,4,minecraft:blackstone)
B(8,6,4,minecraft:blackstone)
B(10,6,4,minecraft:blackstone)
B(11,6,4,minecraft:blackstone)
B(12,6,4,minecraft:blackstone)
B(13,6,4,minecraft:blackstone)
B(14,6,4,minecraft:blackstone)
B(15,6,4,minecraft:blackstone)
B(3,6,5,minecraft:blackstone)
B(4,6,5,minecraft:blackstone)
B(5,6,5,minecraft:blackstone)
B(6,6,5,minecraft:blackstone)
B(7,6,5,minecraft:blackstone)
B(8,6,5,minecraft:blackstone)
B(9,6,5,minecraft:blackstone)
B(10,6,5,minecraft:blackstone)
B(11,6,5,minecraft:blackstone)
B(12,6,5,minecraft:blackstone)
B(13,6,5,minecraft:blackstone)
B(14,6,5,minecraft:blackstone)
B(15,6,5,minecraft:blackstone)
B(2,6,6,minecraft:blackstone)
B(3,6,6,minecraft:blackstone)
B(4,6,6,minecraft:blackstone)
B(5,6,6,minecraft:blackstone)
B(6,6,6,minecraft:blackstone)
B(7,6,6,minecraft:blackstone)
B(8,6,6,minecraft:blackstone)
B(9,6,6,minecraft:blackstone)
B(10,6,6,minecraft:blackstone)
B(11,6,6,minecraft:blackstone)
B(12,6,6,minecraft:blackstone)
B(13,6,6,minecraft:blackstone)
B(14,6,6,minecraft:blackstone)
B(15,6,6,minecraft:blackstone)
B(2,6,7,minecraft:blackstone)
B(3,6,7,minecraft:blackstone)
B(4,6,7,minecraft:blackstone)
B(5,6,7,minecraft:blackstone)
B(6,6,7,minecraft:blackstone)
B(7,6,7,minecraft:blackstone)
B(8,6,7,minecraft:blackstone)
B(9,6,7,minecraft:blackstone)
B(10,6,7,minecraft:blackstone)
B(11,6,7,minecraft:blackstone)
B(12,6,7,minecraft:blackstone)
B(13,6,7,minecraft:blackstone)
B(14,6,7,minecraft:blackstone)
B(15,6,7,minecraft:blackstone)
B(3,6,8,minecraft:blackstone)
B(4,6,8,minecraft:blackstone)
B(5,6,8,minecraft:blackstone)
B(6,6,8,minecraft:blackstone)
B(8,6,8,minecraft:blackstone)
B(9,6,8,minecraft:blackstone)
B(10,6,8,minecraft:blackstone)
B(11,6,8,minecraft:blackstone)
B(12,6,8,minecraft:blackstone)
B(13,6,8,minecraft:blackstone)
B(14,6,8,minecraft:blackstone)
B(15,6,8,minecraft:blackstone)
B(9,6,9,minecraft:blackstone)
B(10,6,9,minecraft:blackstone)
B(11,6,9,minecraft:blackstone)
B(12,6,9,minecraft:blackstone)
B(13,6,9,minecraft:blackstone)
B(14,6,9,minecraft:blackstone)
B(15,6,9,minecraft:blackstone)
B(9,6,10,minecraft:blackstone)
B(10,6,10,minecraft:blackstone)
B(11,6,10,minecraft:blackstone)
B(12,6,10,minecraft:blackstone)
B(13,6,10,minecraft:blackstone)
B(14,6,10,minecraft:blackstone)
B(15,6,10,minecraft:blackstone)
B(9,6,11,minecraft:blackstone)
B(10,6,11,minecraft:blackstone)
B(11,6,11,minecraft:blackstone)
B(12,6,11,minecraft:blackstone)
B(13,6,11,minecraft:blackstone)
B(14,6,11,minecraft:blackstone)
B(15,6,11,minecraft:blackstone)
B(9,6,12,minecraft:blackstone)
B(10,6,12,minecraft:blackstone)
B(11,6,12,minecraft:blackstone)
B(12,6,12,minecraft:blackstone)
B(13,6,12,minecraft:blackstone)
B(14,6,12,minecraft:blackstone)
B(15,6,12,minecraft:blackstone)
B(9,6,13,minecraft:blackstone)
B(10,6,13,minecraft:blackstone)
B(11,6,13,minecraft:blackstone)
B(12,6,13,minecraft:blackstone)
B(13,6,13,minecraft:blackstone)
B(14,6,13,minecraft:blackstone)
B(15,6,13,minecraft:blackstone)
B(9,6,14,minecraft:blackstone)
B(10,6,14,minecraft:blackstone)
B(11,6,14,minecraft:blackstone)
B(12,6,14,minecraft:blackstone)
B(13,6,14,minecraft:blackstone)
B(14,6,14,minecraft:blackstone)
B(15,6,14,minecraft:blackstone)
B(9,6,15,minecraft:blackstone)
B(10,6,15,minecraft:blackstone)
B(11,6,15,minecraft:blackstone)
B(12,6,15,minecraft:blackstone)
B(13,6,15,minecraft:blackstone)
B(14,6,15,minecraft:blackstone)
B(15,6,15,minecraft:blackstone)
B(10,7,0,minecraft:blackstone)
B(11,7,0,minecraft:blackstone)
B(12,7,0,minecraft:blackstone)
B(13,7,0,minecraft:blackstone)
B(14,7,0,minecraft:blackstone)
B(15,7,0,minecraft:blackstone)
B(10,7,1,minecraft:blackstone)
B(11,7,1,minecraft:blackstone)
B(12,7,1,minecraft:blackstone)
B(13,7,1,minecraft:blackstone)
B(14,7,1,minecraft:blackstone)
B(15,7,1,minecraft:blackstone)
B(10,7,2,minecraft:blackstone)
B(11,7,2,minecraft:blackstone)
B(12,7,2,minecraft:blackstone)
B(13,7,2,minecraft:blackstone)
B(14,7,2,minecraft:blackstone)
B(15,7,2,minecraft:blackstone)
B(11,7,3,minecraft:blackstone)
B(12,7,3,minecraft:blackstone)
B(13,7,3,minecraft:blackstone)
B(14,7,3,minecraft:blackstone)
B(15,7,3,minecraft:blackstone)
B(5,7,4,minecraft:blackstone)
B(6,7,4,minecraft:blackstone)
B(7,7,4,minecraft:blackstone)
B(10,7,4,minecraft:blackstone)
B(11,7,4,minecraft:blackstone)
B(12,7,4,minecraft:blackstone)
B(13,7,4,minecraft:blackstone)
B(14,7,4,minecraft:blackstone)
B(15,7,4,minecraft:blackstone)
B(5,7,5,minecraft:blackstone)
B(6,7,5,minecraft:blackstone)
B(7,7,5,minecraft:blackstone)
B(8,7,5,minecraft:blackstone)
B(9,7,5,minecraft:blackstone)
B(10,7,5,minecraft:blackstone)
B(11,7,5,minecraft:blackstone)
B(12,7,5,minecraft:blackstone)
B(13,7,5,minecraft:blackstone)
B(14,7,5,minecraft:blackstone)
B(15,7,5,minecraft:blackstone)
B(3,7,6,minecraft:blackstone)
B(4,7,6,minecraft:blackstone)
B(5,7,6,minecraft:blackstone)
B(6,7,6,minecraft:blackstone)
B(7,7,6,minecraft:blackstone)
B(8,7,6,minecraft:blackstone)
B(9,7,6,minecraft:blackstone)
B(10,7,6,minecraft:blackstone)
B(11,7,6,minecraft:blackstone)
B(12,7,6,minecraft:blackstone)
B(13,7,6,minecraft:blackstone)
B(14,7,6,minecraft:blackstone)
B(15,7,6,minecraft:blackstone)
B(4,7,7,minecraft:blackstone)
B(9,7,7,minecraft:blackstone)
B(10,7,7,minecraft:blackstone)
B(11,7,7,minecraft:blackstone)
B(12,7,7,minecraft:blackstone)
B(13,7,7,minecraft:blackstone)
B(14,7,7,minecraft:blackstone)
B(15,7,7,minecraft:blackstone)
B(9,7,8,minecraft:blackstone)
B(10,7,8,minecraft:blackstone)
B(11,7,8,minecraft:blackstone)
B(12,7,8,minecraft:blackstone)
B(13,7,8,minecraft:blackstone)
B(14,7,8,minecraft:blackstone)
B(15,7,8,minecraft:blackstone)
B(10,7,9,minecraft:blackstone)
B(11,7,9,minecraft:blackstone)
B(12,7,9,minecraft:blackstone)
B(13,7,9,minecraft:blackstone)
B(14,7,9,minecraft:blackstone)
B(15,7,9,minecraft:blackstone)
B(10,7,10,minecraft:blackstone)
B(11,7,10,minecraft:blackstone)
B(12,7,10,minecraft:blackstone)
B(13,7,10,minecraft:blackstone)
B(14,7,10,minecraft:blackstone)
B(15,7,10,minecraft:blackstone)
B(10,7,11,minecraft:blackstone)
B(11,7,11,minecraft:blackstone)
B(12,7,11,minecraft:blackstone)
B(13,7,11,minecraft:blackstone)
B(14,7,11,minecraft:blackstone)
B(15,7,11,minecraft:blackstone)
B(10,7,12,minecraft:blackstone)
B(11,7,12,minecraft:blackstone)
B(12,7,12,minecraft:blackstone)
B(13,7,12,minecraft:blackstone)
B(14,7,12,minecraft:blackstone)
B(15,7,12,minecraft:blackstone)
B(10,7,13,minecraft:blackstone)
B(11,7,13,minecraft:blackstone)
B(12,7,13,minecraft:blackstone)
B(13,7,13,minecraft:blackstone)
B(14,7,13,minecraft:blackstone)
B(15,7,13,minecraft:blackstone)
B(10,7,14,minecraft:blackstone)
B(11,7,14,minecraft:blackstone)
B(12,7,14,minecraft:blackstone)
B(13,7,14,minecraft:blackstone)
B(14,7,14,minecraft:blackstone)
B(15,7,14,minecraft:blackstone)
B(10,7,15,minecraft:blackstone)
B(11,7,15,minecraft:blackstone)
B(12,7,15,minecraft:blackstone)
B(13,7,15,minecraft:blackstone)
B(14,7,15,minecraft:blackstone)
B(15,7,15,minecraft:blackstone)
B(13,8,0,minecraft:blackstone)
B(14,8,0,minecraft:blackstone)
B(15,8,0,minecraft:blackstone)
B(13,8,1,minecraft:blackstone)
B(14,8,1,minecraft:blackstone)
B(15,8,1,minecraft:blackstone)
B(12,8,2,minecraft:blackstone)
B(13,8,2,minecraft:blackstone)
B(14,8,2,minecraft:blackstone)
B(15,8,2,minecraft:blackstone)
B(11,8,3,minecraft:blackstone)
B(12,8,3,minecraft:blackstone)
B(13,8,3,minecraft:blackstone)
B(14,8,3,minecraft:blackstone)
B(15,8,3,minecraft:blackstone)
B(10,8,4,minecraft:blackstone)
B(11,8,4,minecraft:blackstone)
B(12,8,4,minecraft:blackstone)
B(13,8,4,minecraft:blackstone)
B(14,8,4,minecraft:blackstone)
B(15,8,4,minecraft:blackstone)
B(9,8,5,minecraft:blackstone)
B(10,8,5,minecraft:blackstone)
B(11,8,5,minecraft:blackstone)
B(12,8,5,minecraft:blackstone)
B(13,8,5,minecraft:blackstone)
B(14,8,5,minecraft:blackstone)
B(15,8,5,minecraft:blackstone)
B(9,8,6,minecraft:blackstone)
B(10,8,6,minecraft:blackstone)
B(11,8,6,minecraft:blackstone)
B(12,8,6,minecraft:blackstone)
B(13,8,6,minecraft:blackstone)
B(14,8,6,minecraft:blackstone)
B(15,8,6,minecraft:blackstone)
B(10,8,7,minecraft:blackstone)
B(11,8,7,minecraft:blackstone)
B(12,8,7,minecraft:blackstone)
B(13,8,7,minecraft:blackstone)
B(14,8,7,minecraft:blackstone)
B(15,8,7,minecraft:blackstone)
B(10,8,8,minecraft:blackstone)
B(11,8,8,minecraft:blackstone)
B(12,8,8,minecraft:blackstone)
B(13,8,8,minecraft:blackstone)
B(14,8,8,minecraft:blackstone)
B(15,8,8,minecraft:blackstone)
B(10,8,9,minecraft:blackstone)
B(11,8,9,minecraft:blackstone)
B(12,8,9,minecraft:blackstone)
B(13,8,9,minecraft:blackstone)
B(14,8,9,minecraft:blackstone)
B(15,8,9,minecraft:blackstone)
B(10,8,10,minecraft:blackstone)
B(11,8,10,minecraft:blackstone)
B(12,8,10,minecraft:blackstone)
B(13,8,10,minecraft:blackstone)
B(14,8,10,minecraft:blackstone)
B(15,8,10,minecraft:blackstone)
B(10,8,11,minecraft:blackstone)
B(11,8,11,minecraft:blackstone)
B(12,8,11,minecraft:blackstone)
B(13,8,11,minecraft:blackstone)
B(14,8,11,minecraft:blackstone)
B(15,8,11,minecraft:blackstone)
B(10,8,12,minecraft:blackstone)
B(11,8,12,minecraft:blackstone)
B(12,8,12,minecraft:blackstone)
B(13,8,12,minecraft:blackstone)
B(14,8,12,minecraft:blackstone)
B(15,8,12,minecraft:blackstone)
B(10,8,13,minecraft:blackstone)
B(11,8,13,minecraft:blackstone)
B(12,8,13,minecraft:blackstone)
B(13,8,13,minecraft:blackstone)
B(14,8,13,minecraft:blackstone)
B(15,8,13,minecraft:blackstone)
B(10,8,14,minecraft:blackstone)
B(11,8,14,minecraft:blackstone)
B(12,8,14,minecraft:blackstone)
B(13,8,14,minecraft:blackstone)
B(14,8,14,minecraft:blackstone)
B(15,8,14,minecraft:blackstone)
B(10,8,15,minecraft:blackstone)
B(11,8,15,minecraft:blackstone)
B(12,8,15,minecraft:blackstone)
B(13,8,15,minecraft:blackstone)
B(14,8,15,minecraft:blackstone)
B(15,8,15,minecraft:blackstone)
B(13,9,0,minecraft:blackstone)
B(14,9,0,minecraft:blackstone)
B(15,9,0,minecraft:blackstone)
B(13,9,1,minecraft:blackstone)
B(14,9,1,minecraft:blackstone)
B(15,9,1,minecraft:blackstone)
B(12,9,2,minecraft:blackstone)
B(13,9,2,minecraft:blackstone)
B(14,9,2,minecraft:blackstone)
B(15,9,2,minecraft:blackstone)
B(11,9,3,minecraft:blackstone)
B(12,9,3,minecraft:blackstone)
B(13,9,3,minecraft:blackstone)
B(14,9,3,minecraft:blackstone)
B(15,9,3,minecraft:blackstone)
B(10,9,4,minecraft:blackstone)
B(11,9,4,minecraft:blackstone)
B(12,9,4,minecraft:blackstone)
B(13,9,4,minecraft:blackstone)
B(14,9,4,minecraft:blackstone)
B(15,9,4,minecraft:blackstone)
B(10,9,5,minecraft:blackstone)
B(11,9,5,minecraft:blackstone)
B(12,9,5,minecraft:blackstone)
B(13,9,5,minecraft:blackstone)
B(14,9,5,minecraft:blackstone)
B(15,9,5,minecraft:blackstone)
B(10,9,6,minecraft:blackstone)
B(11,9,6,minecraft:blackstone)
B(12,9,6,minecraft:blackstone)
B(13,9,6,minecraft:blackstone)
B(14,9,6,minecraft:blackstone)
B(15,9,6,minecraft:blackstone)
B(10,9,7,minecraft:blackstone)
B(11,9,7,minecraft:blackstone)
B(12,9,7,minecraft:blackstone)
B(13,9,7,minecraft:blackstone)
B(14,9,7,minecraft:blackstone)
B(15,9,7,minecraft:blackstone)
B(11,9,8,minecraft:blackstone)
B(12,9,8,minecraft:blackstone)
B(13,9,8,minecraft:blackstone)
B(14,9,8,minecraft:blackstone)
B(15,9,8,minecraft:blackstone)
B(11,9,9,minecraft:blackstone)
B(12,9,9,minecraft:blackstone)
B(13,9,9,minecraft:blackstone)
B(14,9,9,minecraft:blackstone)
B(15,9,9,minecraft:blackstone)
B(11,9,10,minecraft:blackstone)
B(12,9,10,minecraft:blackstone)
B(13,9,10,minecraft:blackstone)
B(14,9,10,minecraft:blackstone)
B(15,9,10,minecraft:blackstone)
B(11,9,11,minecraft:blackstone)
B(12,9,11,minecraft:blackstone)
B(13,9,11,minecraft:blackstone)
B(14,9,11,minecraft:blackstone)
B(15,9,11,minecraft:blackstone)
B(11,9,12,minecraft:blackstone)
B(12,9,12,minecraft:blackstone)
B(13,9,12,minecraft:blackstone)
B(14,9,12,minecraft:blackstone)
B(15,9,12,minecraft:blackstone)
B(11,9,13,minecraft:blackstone)
B(12,9,13,minecraft:blackstone)
B(13,9,13,minecraft:blackstone)
B(14,9,13,minecraft:blackstone)
B(15,9,13,minecraft:blackstone)
B(11,9,14,minecraft:blackstone)
B(12,9,14,minecraft:blackstone)
B(13,9,14,minecraft:blackstone)
B(14,9,14,minecraft:blackstone)
B(15,9,14,minecraft:blackstone)
B(11,9,15,minecraft:blackstone)
B(12,9,15,minecraft:blackstone)
B(13,9,15,minecraft:blackstone)
B(14,9,15,minecraft:blackstone)
B(15,9,15,minecraft:blackstone)
B(13,10,0,minecraft:blackstone)
B(14,10,0,minecraft:blackstone)
B(15,10,0,minecraft:blackstone)
B(13,10,1,minecraft:blackstone)
B(14,10,1,minecraft:blackstone)
B(15,10,1,minecraft:blackstone)
B(12,10,2,minecraft:blackstone)
B(13,10,2,minecraft:blackstone)
B(14,10,2,minecraft:blackstone)
B(15,10,2,minecraft:blackstone)
B(11,10,3,minecraft:blackstone)
B(12,10,3,minecraft:blackstone)
B(13,10,3,minecraft:blackstone)
B(14,10,3,minecraft:blackstone)
B(15,10,3,minecraft:blackstone)
B(11,10,4,minecraft:blackstone)
B(12,10,4,minecraft:blackstone)
B(13,10,4,minecraft:blackstone)
B(14,10,4,minecraft:blackstone)
B(15,10,4,minecraft:blackstone)
B(11,10,5,minecraft:blackstone)
B(12,10,5,minecraft:blackstone)
B(13,10,5,minecraft:blackstone)
B(14,10,5,minecraft:blackstone)
B(15,10,5,minecraft:blackstone)
B(11,10,6,minecraft:blackstone)
B(12,10,6,minecraft:blackstone)
B(13,10,6,minecraft:blackstone)
B(14,10,6,minecraft:blackstone)
B(15,10,6,minecraft:blackstone)
B(11,10,7,minecraft:blackstone)
B(12,10,7,minecraft:blackstone)
B(13,10,7,minecraft:blackstone)
B(14,10,7,minecraft:blackstone)
B(15,10,7,minecraft:blackstone)
B(11,10,8,minecraft:blackstone)
B(12,10,8,minecraft:blackstone)
B(13,10,8,minecraft:blackstone)
B(14,10,8,minecraft:blackstone)
B(15,10,8,minecraft:blackstone)
B(11,10,9,minecraft:blackstone)
B(12,10,9,minecraft:blackstone)
B(13,10,9,minecraft:blackstone)
B(14,10,9,minecraft:blackstone)
B(15,10,9,minecraft:blackstone)
B(11,10,10,minecraft:blackstone)
B(12,10,10,minecraft:blackstone)
B(13,10,10,minecraft:blackstone)
B(14,10,10,minecraft:blackstone)
B(15,10,10,minecraft:blackstone)
B(11,10,11,minecraft:blackstone)
B(12,10,11,minecraft:blackstone)
B(13,10,11,minecraft:blackstone)
B(14,10,11,minecraft:blackstone)
B(15,10,11,minecraft:blackstone)
B(11,10,12,minecraft:blackstone)
B(12,10,12,minecraft:blackstone)
B(13,10,12,minecraft:blackstone)
B(14,10,12,minecraft:blackstone)
B(15,10,12,minecraft:blackstone)
B(11,10,13,minecraft:blackstone)
B(12,10,13,minecraft:blackstone)
B(13,10,13,minecraft:blackstone)
B(14,10,13,minecraft:blackstone)
B(15,10,13,minecraft:blackstone)
B(11,10,14,minecraft:blackstone)
B(12,10,14,minecraft:blackstone)
B(13,10,14,minecraft:blackstone)
B(14,10,14,minecraft:blackstone)
B(15,10,14,minecraft:blackstone)
B(11,10,15,minecraft:blackstone)
B(12,10,15,minecraft:blackstone)
B(13,10,15,minecraft:blackstone)
B(14,10,15,minecraft:blackstone)
B(15,10,15,minecraft:blackstone)
B(14,11,0,minecraft:blackstone)
B(15,11,0,minecraft:blackstone)
B(13,11,1,minecraft:blackstone)
B(14,11,1,minecraft:blackstone)
B(15,11,1,minecraft:blackstone)
B(13,11,2,minecraft:blackstone)
B(14,11,2,minecraft:blackstone)
B(15,11,2,minecraft:blackstone)
B(12,11,3,minecraft:blackstone)
B(13,11,3,minecraft:blackstone)
B(14,11,3,minecraft:blackstone)
B(15,11,3,minecraft:blackstone)
B(11,11,4,minecraft:blackstone)
B(12,11,4,minecraft:blackstone)
B(13,11,4,minecraft:blackstone)
B(14,11,4,minecraft:blackstone)
B(15,11,4,minecraft:blackstone)
B(11,11,5,minecraft:blackstone)
B(12,11,5,minecraft:blackstone)
B(13,11,5,minecraft:blackstone)
B(14,11,5,minecraft:blackstone)
B(15,11,5,minecraft:blackstone)
B(11,11,6,minecraft:blackstone)
B(12,11,6,minecraft:blackstone)
B(13,11,6,minecraft:blackstone)
B(14,11,6,minecraft:blackstone)
B(15,11,6,minecraft:blackstone)
B(11,11,7,minecraft:blackstone)
B(12,11,7,minecraft:blackstone)
B(13,11,7,minecraft:blackstone)
B(14,11,7,minecraft:blackstone)
B(15,11,7,minecraft:blackstone)
B(11,11,8,minecraft:blackstone)
B(12,11,8,minecraft:blackstone)
B(13,11,8,minecraft:blackstone)
B(14,11,8,minecraft:blackstone)
B(15,11,8,minecraft:blackstone)
B(12,11,9,minecraft:blackstone)
B(13,11,9,minecraft:blackstone)
B(14,11,9,minecraft:blackstone)
B(15,11,9,minecraft:blackstone)
B(12,11,10,minecraft:blackstone)
B(13,11,10,minecraft:blackstone)
B(14,11,10,minecraft:blackstone)
B(15,11,10,minecraft:blackstone)
B(12,11,11,minecraft:blackstone)
B(13,11,11,minecraft:blackstone)
B(14,11,11,minecraft:blackstone)
B(15,11,11,minecraft:blackstone)
B(12,11,12,minecraft:blackstone)
B(13,11,12,minecraft:blackstone)
B(14,11,12,minecraft:blackstone)
B(15,11,12,minecraft:blackstone)
B(12,11,13,minecraft:blackstone)
B(13,11,13,minecraft:blackstone)
B(14,11,13,minecraft:blackstone)
B(15,11,13,minecraft:blackstone)
B(12,11,14,minecraft:blackstone)
B(13,11,14,minecraft:blackstone)
B(14,11,14,minecraft:blackstone)
B(15,11,14,minecraft:blackstone)
B(12,11,15,minecraft:blackstone)
B(13,11,15,minecraft:blackstone)
B(14,11,15,minecraft:blackstone)
B(15,11,15,minecraft:blackstone)
B(14,12,0,minecraft:blackstone)
B(15,12,0,minecraft:blackstone)
B(13,12,1,minecraft:blackstone)
B(14,12,1,minecraft:blackstone)
B(15,12,1,minecraft:blackstone)
B(13,12,2,minecraft:blackstone)
B(14,12,2,minecraft:blackstone)
B(15,12,2,minecraft:blackstone)
B(13,12,3,minecraft:blackstone)
B(14,12,3,minecraft:blackstone)
B(15,12,3,minecraft:blackstone)
B(12,12,4,minecraft:blackstone)
B(13,12,4,minecraft:blackstone)
B(14,12,4,minecraft:blackstone)
B(15,12,4,minecraft:blackstone)
B(12,12,5,minecraft:blackstone)
B(13,12,5,minecraft:blackstone)
B(14,12,5,minecraft:blackstone)
B(15,12,5,minecraft:blackstone)
B(12,12,6,minecraft:blackstone)
B(13,12,6,minecraft:blackstone)
B(14,12,6,minecraft:blackstone)
B(15,12,6,minecraft:blackstone)
B(12,12,7,minecraft:blackstone)
B(13,12,7,minecraft:blackstone)
B(14,12,7,minecraft:blackstone)
B(15,12,7,minecraft:blackstone)
B(12,12,8,minecraft:blackstone)
B(13,12,8,minecraft:blackstone)
B(14,12,8,minecraft:blackstone)
B(15,12,8,minecraft:blackstone)
B(12,12,9,minecraft:blackstone)
B(13,12,9,minecraft:blackstone)
B(14,12,9,minecraft:blackstone)
B(15,12,9,minecraft:blackstone)
B(12,12,10,minecraft:blackstone)
B(13,12,10,minecraft:blackstone)
B(14,12,10,minecraft:blackstone)
B(15,12,10,minecraft:blackstone)
B(12,12,11,minecraft:blackstone)
B(13,12,11,minecraft:blackstone)
B(14,12,11,minecraft:blackstone)
B(15,12,11,minecraft:blackstone)
B(12,12,12,minecraft:blackstone)
B(13,12,12,minecraft:blackstone)
B(14,12,12,minecraft:blackstone)
B(15,12,12,minecraft:blackstone)
B(12,12,13,minecraft:blackstone)
B(13,12,13,minecraft:blackstone)
B(14,12,13,minecraft:blackstone)
B(15,12,13,minecraft:blackstone)
B(12,12,14,minecraft:blackstone)
B(13,12,14,minecraft:blackstone)
B(14,12,14,minecraft:blackstone)
B(15,12,14,minecraft:blackstone)
B(12,12,15,minecraft:blackstone)
B(13,12,15,minecraft:blackstone)
B(14,12,15,minecraft:blackstone)
B(15,12,15,minecraft:blackstone)
B(14,13,0,minecraft:blackstone)
B(15,13,0,minecraft:blackstone)
B(14,13,1,minecraft:blackstone)
B(15,13,1,minecraft:blackstone)
B(14,13,2,minecraft:blackstone)
B(15,13,2,minecraft:blackstone)
B(14,13,3,minecraft:blackstone)
B(15,13,3,minecraft:blackstone)
B(13,13,4,minecraft:blackstone)
B(14,13,4,minecraft:blackstone)
B(15,13,4,minecraft:blackstone)
B(12,13,5,minecraft:blackstone)
B(13,13,5,minecraft:blackstone)
B(14,13,5,minecraft:blackstone)
B(15,13,5,minecraft:blackstone)
B(12,13,6,minecraft:blackstone)
B(13,13,6,minecraft:blackstone)
B(14,13,6,minecraft:blackstone)
B(15,13,6,minecraft:blackstone)
B(12,13,7,minecraft:blackstone)
B(13,13,7,minecraft:blackstone)
B(14,13,7,minecraft:blackstone)
B(15,13,7,minecraft:blackstone)
B(12,13,8,minecraft:blackstone)
B(13,13,8,minecraft:blackstone)
B(14,13,8,minecraft:blackstone)
B(15,13,8,minecraft:blackstone)
B(13,13,9,minecraft:blackstone)
B(14,13,9,minecraft:blackstone)
B(15,13,9,minecraft:blackstone)
B(13,13,10,minecraft:blackstone)
B(14,13,10,minecraft:blackstone)
B(15,13,10,minecraft:blackstone)
B(13,13,11,minecraft:blackstone)
B(14,13,11,minecraft:blackstone)
B(15,13,11,minecraft:blackstone)
B(13,13,12,minecraft:blackstone)
B(14,13,12,minecraft:blackstone)
B(15,13,12,minecraft:blackstone)
B(13,13,13,minecraft:blackstone)
B(14,13,13,minecraft:blackstone)
B(15,13,13,minecraft:blackstone)
B(13,13,14,minecraft:blackstone)
B(14,13,14,minecraft:blackstone)
B(15,13,14,minecraft:blackstone)
B(13,13,15,minecraft:blackstone)
B(14,13,15,minecraft:blackstone)
B(15,13,15,minecraft:blackstone)
B(15,14,0,minecraft:blackstone)
B(15,14,1,minecraft:blackstone)
B(15,14,2,minecraft:blackstone)
B(14,14,3,minecraft:blackstone)
B(15,14,3,minecraft:blackstone)
B(13,14,4,minecraft:blackstone)
B(14,14,4,minecraft:blackstone)
B(15,14,4,minecraft:blackstone)
B(13,14,5,minecraft:blackstone)
B(14,14,5,minecraft:blackstone)
B(15,14,5,minecraft:blackstone)
B(13,14,6,minecraft:blackstone)
B(14,14,6,minecraft:blackstone)
B(15,14,6,minecraft:blackstone)
B(13,14,7,minecraft:blackstone)
B(14,14,7,minecraft:blackstone)
B(15,14,7,minecraft:blackstone)
B(13,14,8,minecraft:blackstone)
B(14,14,8,minecraft:blackstone)
B(15,14,8,minecraft:blackstone)
B(13,14,9,minecraft:blackstone)
B(14,14,9,minecraft:blackstone)
B(15,14,9,minecraft:blackstone)
B(14,14,10,minecraft:blackstone)
B(15,14,10,minecraft:blackstone)
B(14,14,11,minecraft:blackstone)
B(15,14,11,minecraft:blackstone)
B(14,14,12,minecraft:blackstone)
B(15,14,12,minecraft:blackstone)
B(14,14,13,minecraft:blackstone)
B(15,14,13,minecraft:blackstone)
B(14,14,14,minecraft:blackstone)
B(15,14,14,minecraft:blackstone)
B(14,14,15,minecraft:blackstone)
B(15,14,15,minecraft:blackstone)
B(15,15,1,minecraft:blackstone)
B(15,15,2,minecraft:blackstone)
B(14,15,3,minecraft:blackstone)
B(15,15,3,minecraft:blackstone)
B(13,15,4,minecraft:blackstone)
B(14,15,4,minecraft:blackstone)
B(15,15,4,minecraft:blackstone)
B(13,15,5,minecraft:blackstone)
B(14,15,5,minecraft:blackstone)
B(15,15,5,minecraft:blackstone)
B(13,15,6,minecraft:blackstone)
B(14,15,6,minecraft:blackstone)
B(15,15,6,minecraft:blackstone)
B(14,15,7,minecraft:blackstone)
B(15,15,7,minecraft:blackstone)
B(14,15,8,minecraft:blackstone)
B(15,15,8,minecraft:blackstone)
B(14,15,9,minecraft:blackstone)
B(15,15,9,minecraft:blackstone)
B(15,15,10,minecraft:blackstone)
B(15,15,11,minecraft:blackstone)
B(15,15,12,minecraft:blackstone)
B(15,16,2,minecraft:blackstone)
B(15,16,3,minecraft:blackstone)
B(14,16,4,minecraft:blackstone)
B(15,16,4,minecraft:blackstone)
B(14,16,5,minecraft:blackstone)
B(15,16,5,minecraft:blackstone)
B(14,16,6,minecraft:blackstone)
B(15,16,6,minecraft:blackstone)
B(14,16,7,minecraft:blackstone)
B(15,16,7,minecraft:blackstone)
B(15,16,8,minecraft:blackstone)
B(15,16,9,minecraft:blackstone)
B(15,16,10,minecraft:blackstone)
B(15,16,11,minecraft:blackstone)
B(15,16,12,minecraft:blackstone)
B(15,17,4,minecraft:blackstone)
B(15,17,5,minecraft:blackstone)
B(15,17,6,minecraft:blackstone)
B(15,17,7,minecraft:blackstone)
B(15,17,8,minecraft:blackstone)
B(15,17,9,minecraft:blackstone)
B(15,17,10,minecraft:blackstone)
B(15,17,11,minecraft:blackstone)
B(15,17,12,minecraft:blackstone)
B(15,18,6,minecraft:blackstone)
B(15,18,7,minecraft:blackstone)
B(15,18,8,minecraft:blackstone)
B(15,18,9,minecraft:blackstone)
B(15,18,10,minecraft:blackstone)
B(15,18,11,minecraft:blackstone)
B(15,18,12,minecraft:blackstone)
B(15,19,7,minecraft:blackstone)
B(15,19,8,minecraft:blackstone)
B(15,19,9,minecraft:blackstone)
B(15,19,10,minecraft:blackstone)
B(15,19,11,minecraft:blackstone)
B(15,19,12,minecraft:blackstone)
B(15,20,7,minecraft:blackstone)
B(15,20,8,minecraft:blackstone)
B(15,20,9,minecraft:blackstone)
B(15,20,10,minecraft:blackstone)
B(15,20,11,minecraft:blackstone)
B(15,20,12,minecraft:blackstone)
B(15,21,7,minecraft:blackstone)
B(15,21,8,minecraft:blackstone)
B(15,21,9,minecraft:blackstone)
B(15,21,10,minecraft:blackstone)
B(15,21,11,minecraft:blackstone)
B(15,22,8,minecraft:blackstone)
B(15,22,9,minecraft:blackstone)
B(15,22,10,minecraft:blackstone)
B(15,22,11,minecraft:blackstone)
B(15,23,8,minecraft:blackstone)
B(15,23,9,minecraft:blackstone)
B(15,23,10,minecraft:blackstone)
B(15,23,11,minecraft:blackstone)
B(15,24,8,minecraft:blackstone)
B(15,24,9,minecraft:blackstone)
B(15,24,10,minecraft:blackstone)
B(15,24,11,minecraft:blackstone)
B(15,25,8,minecraft:blackstone)
B(15,25,9,minecraft:blackstone)
B(15,25,10,minecraft:blackstone)
B(15,25,11,minecraft:blackstone)
B(15,26,8,minecraft:blackstone)
B(15,26,9,minecraft:blackstone)
B(15,26,10,minecraft:blackstone)
B(15,26,11,minecraft:blackstone)
B(15,27,9,minecraft:blackstone)
B(15,27,10,minecraft:blackstone)
B(15,28,9,minecraft:blackstone)
B(15,28,10,minecraft:blackstone)

