
#######################################################################
# +-----------------------------------------------------------------+ #
# |                            BO4 object                           | #
# +-----------------------------------------------------------------+ #
#######################################################################

Author: Unknown

Description: No description given

SettingsMode: WriteWithoutComments


#######################################################################
# +-----------------------------------------------------------------+ #
# |                          Main settings                          | #
# +-----------------------------------------------------------------+ #
#######################################################################

FixedRotation: 

Frequency: 0

SpawnHeight: highestBlock

UseCenterForHighestBlock: true

##############################
# Height Limits for the BO4. #
##############################

MinHeight: 0

MaxHeight: 255

InheritBO3: 

InheritBO3Rotation: NORTH

OverrideChildSettings: true

OverrideParentHeight: false

CanOverride: false

BranchFrequency: 0

BranchFrequencyGroup: 

MustBeBelowOther: false

MustBeInside: 

CannotBeInside: 

ReplacesBO3: 

MustBeInsideWorldBorders: false

CanSpawnOnWater: true

SpawnOnWaterOnly: false

SpawnUnderWater: false

SpawnAtWaterLevel: false

HeightOffset: 0

RemoveAir: true

ReplaceAbove: 

ReplaceBelow: 

ReplaceWithBiomeBlocks: true

ReplaceWithSurfaceBlock: GRASS

ReplaceWithGroundBlock: DIRT

ReplaceWithStoneBlock: STONE

SmoothRadius: 0

SmoothHeightOffset: 0

SmoothStartTop: false

SmoothStartWood: false

SmoothingSurfaceBlock: 

SmoothingGroundBlock: 

BO3Group: 

IsSpawnPoint: false

DoReplaceBlocks: true


#######################################################################
# +-----------------------------------------------------------------+ #
# |                              Blocks                             | #
# +-----------------------------------------------------------------+ #
#######################################################################

B(-8,54,-7,minecraft:soul_sand)
B(-8,55,-7,minecraft:soul_sand)
B(-8,56,-7,minecraft:soul_sand)
B(-8,57,-7,minecraft:soul_sand)
B(-8,58,-7,minecraft:soul_sand)
B(-8,59,-7,minecraft:soul_sand)
B(-8,60,-7,minecraft:soul_sand)
B(-8,61,-7,minecraft:soul_sand)
B(-8,62,-7,minecraft:soul_sand)
B(-8,63,-7,minecraft:soul_sand)
B(-8,64,-7,minecraft:soul_sand)
B(-8,65,-7,minecraft:soul_sand)
B(-8,66,-7,minecraft:soul_sand)
B(-8,57,-6,minecraft:soul_sand)
B(-8,58,-6,minecraft:soul_sand)
B(-8,59,-6,minecraft:soul_sand)
B(-8,60,-6,minecraft:soul_sand)
B(-8,61,-6,minecraft:soul_sand)
B(-8,62,-6,minecraft:soul_sand)
B(-8,63,-6,minecraft:soul_sand)
B(-8,64,-6,minecraft:soul_sand)
B(-8,65,-6,minecraft:soul_sand)
B(-8,66,-6,minecraft:soul_sand)
B(-8,58,-5,minecraft:soul_sand)
B(-8,59,-5,minecraft:soul_sand)
B(-8,60,-5,minecraft:soul_sand)
B(-8,61,-5,minecraft:soul_sand)
B(-8,62,-5,minecraft:soul_sand)
B(-8,63,-5,minecraft:soul_sand)
B(-8,64,-5,minecraft:soul_sand)
B(-8,65,-5,minecraft:soul_sand)
B(-8,66,-5,minecraft:soul_sand)
B(-8,59,-4,minecraft:soul_sand)
B(-8,60,-4,minecraft:soul_sand)
B(-8,61,-4,minecraft:soul_sand)
B(-8,62,-4,minecraft:soul_sand)
B(-8,63,-4,minecraft:soul_sand)
B(-8,64,-4,minecraft:soul_sand)
B(-8,65,-4,minecraft:soul_sand)
B(-8,66,-4,minecraft:soul_sand)
B(-8,61,-3,minecraft:soul_sand)
B(-8,62,-3,minecraft:soul_sand)
B(-8,63,-3,minecraft:soul_sand)
B(-8,64,-3,minecraft:soul_sand)
B(-8,65,-3,minecraft:soul_sand)
B(-8,66,-3,minecraft:soul_sand)
B(-8,62,-2,minecraft:soul_sand)
B(-8,63,-2,minecraft:soul_sand)
B(-8,64,-2,minecraft:soul_sand)
B(-8,65,-2,minecraft:soul_sand)
B(-8,66,-2,minecraft:soul_sand)
B(-8,63,-1,minecraft:soul_sand)
B(-8,64,-1,minecraft:soul_sand)
B(-8,65,-1,minecraft:soul_sand)
B(-8,66,-1,minecraft:soul_sand)
B(-8,64,0,minecraft:soul_sand)
B(-8,65,0,minecraft:soul_sand)
B(-8,66,0,minecraft:soul_sand)
B(-8,65,1,minecraft:soul_sand)
B(-8,66,1,minecraft:soul_sand)
B(-8,65,2,minecraft:soul_sand)
B(-8,66,2,minecraft:soul_sand)
B(-8,66,3,minecraft:soul_sand)
B(-7,53,-7,minecraft:soul_sand)
B(-7,54,-7,minecraft:soul_sand)
B(-7,55,-7,minecraft:soul_sand)
B(-7,56,-7,minecraft:soul_sand)
B(-7,57,-7,minecraft:soul_sand)
B(-7,58,-7,minecraft:soul_sand)
B(-7,59,-7,minecraft:soul_sand)
B(-7,60,-7,minecraft:soul_sand)
B(-7,61,-7,minecraft:soul_sand)
B(-7,62,-7,minecraft:soul_sand)
B(-7,63,-7,minecraft:soul_sand)
B(-7,64,-7,minecraft:soul_sand)
B(-7,65,-7,minecraft:soul_sand)
B(-7,66,-7,minecraft:soul_sand)
B(-7,53,-6,minecraft:soul_sand)
B(-7,54,-6,minecraft:soul_sand)
B(-7,55,-6,minecraft:soul_sand)
B(-7,56,-6,minecraft:soul_sand)
B(-7,57,-6,minecraft:soul_sand)
B(-7,58,-6,minecraft:soul_sand)
B(-7,59,-6,minecraft:soul_sand)
B(-7,60,-6,minecraft:soul_sand)
B(-7,61,-6,minecraft:soul_sand)
B(-7,62,-6,minecraft:soul_sand)
B(-7,63,-6,minecraft:soul_sand)
B(-7,64,-6,minecraft:soul_sand)
B(-7,65,-6,minecraft:soul_sand)
B(-7,66,-6,minecraft:soul_sand)
B(-7,54,-5,minecraft:soul_sand)
B(-7,55,-5,minecraft:soul_sand)
B(-7,56,-5,minecraft:soul_sand)
B(-7,57,-5,minecraft:soul_sand)
B(-7,58,-5,minecraft:soul_sand)
B(-7,59,-5,minecraft:soul_sand)
B(-7,60,-5,minecraft:soul_sand)
B(-7,61,-5,minecraft:soul_sand)
B(-7,62,-5,minecraft:soul_sand)
B(-7,63,-5,minecraft:soul_sand)
B(-7,64,-5,minecraft:soul_sand)
B(-7,65,-5,minecraft:soul_sand)
B(-7,66,-5,minecraft:soul_sand)
B(-7,56,-4,minecraft:soul_sand)
B(-7,57,-4,minecraft:soul_sand)
B(-7,58,-4,minecraft:soul_sand)
B(-7,59,-4,minecraft:soul_sand)
B(-7,60,-4,minecraft:soul_sand)
B(-7,61,-4,minecraft:soul_sand)
B(-7,62,-4,minecraft:soul_sand)
B(-7,63,-4,minecraft:soul_sand)
B(-7,64,-4,minecraft:soul_sand)
B(-7,65,-4,minecraft:soul_sand)
B(-7,66,-4,minecraft:soul_sand)
B(-7,61,-3,minecraft:soul_sand)
B(-7,62,-3,minecraft:soul_sand)
B(-7,63,-3,minecraft:soul_sand)
B(-7,64,-3,minecraft:soul_sand)
B(-7,65,-3,minecraft:soul_sand)
B(-7,66,-3,minecraft:soul_sand)
B(-7,61,-2,minecraft:soul_sand)
B(-7,62,-2,minecraft:soul_sand)
B(-7,63,-2,minecraft:soul_sand)
B(-7,64,-2,minecraft:soul_sand)
B(-7,65,-2,minecraft:soul_sand)
B(-7,66,-2,minecraft:soul_sand)
B(-7,61,-1,minecraft:soul_sand)
B(-7,62,-1,minecraft:soul_sand)
B(-7,63,-1,minecraft:soul_sand)
B(-7,64,-1,minecraft:soul_sand)
B(-7,65,-1,minecraft:soul_sand)
B(-7,66,-1,minecraft:soul_sand)
B(-7,62,0,minecraft:soul_sand)
B(-7,63,0,minecraft:soul_sand)
B(-7,64,0,minecraft:soul_sand)
B(-7,65,0,minecraft:soul_sand)
B(-7,66,0,minecraft:soul_sand)
B(-7,63,1,minecraft:soul_sand)
B(-7,64,1,minecraft:soul_sand)
B(-7,65,1,minecraft:soul_sand)
B(-7,66,1,minecraft:soul_sand)
B(-7,64,2,minecraft:soul_sand)
B(-7,65,2,minecraft:soul_sand)
B(-7,66,2,minecraft:soul_sand)
B(-6,52,-7,minecraft:soul_sand)
B(-6,53,-7,minecraft:soul_sand)
B(-6,54,-7,minecraft:soul_sand)
B(-6,55,-7,minecraft:soul_sand)
B(-6,56,-7,minecraft:soul_sand)
B(-6,57,-7,minecraft:soul_sand)
B(-6,58,-7,minecraft:soul_sand)
B(-6,59,-7,minecraft:soul_sand)
B(-6,60,-7,minecraft:soul_sand)
B(-6,61,-7,minecraft:soul_sand)
B(-6,62,-7,minecraft:soul_sand)
B(-6,63,-7,minecraft:soul_sand)
B(-6,64,-7,minecraft:soul_sand)
B(-6,65,-7,minecraft:soul_sand)
B(-6,66,-7,minecraft:soul_sand)
B(-6,53,-6,minecraft:soul_sand)
B(-6,54,-6,minecraft:soul_sand)
B(-6,55,-6,minecraft:soul_sand)
B(-6,56,-6,minecraft:soul_sand)
B(-6,57,-6,minecraft:soul_sand)
B(-6,58,-6,minecraft:soul_sand)
B(-6,59,-6,minecraft:soul_sand)
B(-6,60,-6,minecraft:soul_sand)
B(-6,61,-6,minecraft:soul_sand)
B(-6,62,-6,minecraft:soul_sand)
B(-6,63,-6,minecraft:soul_sand)
B(-6,64,-6,minecraft:soul_sand)
B(-6,65,-6,minecraft:soul_sand)
B(-6,66,-6,minecraft:soul_sand)
B(-6,53,-5,minecraft:soul_sand)
B(-6,54,-5,minecraft:soul_sand)
B(-6,55,-5,minecraft:soul_sand)
B(-6,56,-5,minecraft:soul_sand)
B(-6,57,-5,minecraft:soul_sand)
B(-6,58,-5,minecraft:soul_sand)
B(-6,59,-5,minecraft:soul_sand)
B(-6,60,-5,minecraft:soul_sand)
B(-6,61,-5,minecraft:soul_sand)
B(-6,62,-5,minecraft:soul_sand)
B(-6,63,-5,minecraft:soul_sand)
B(-6,64,-5,minecraft:soul_sand)
B(-6,65,-5,minecraft:soul_sand)
B(-6,66,-5,minecraft:soul_sand)
B(-6,54,-4,minecraft:soul_sand)
B(-6,55,-4,minecraft:soul_sand)
B(-6,56,-4,minecraft:soul_sand)
B(-6,57,-4,minecraft:soul_sand)
B(-6,58,-4,minecraft:soul_sand)
B(-6,59,-4,minecraft:soul_sand)
B(-6,60,-4,minecraft:soul_sand)
B(-6,61,-4,minecraft:soul_sand)
B(-6,62,-4,minecraft:soul_sand)
B(-6,63,-4,minecraft:soul_sand)
B(-6,64,-4,minecraft:soul_sand)
B(-6,65,-4,minecraft:soul_sand)
B(-6,66,-4,minecraft:soul_sand)
B(-6,58,-3,minecraft:soul_sand)
B(-6,59,-3,minecraft:soul_sand)
B(-6,60,-3,minecraft:soul_sand)
B(-6,61,-3,minecraft:soul_sand)
B(-6,62,-3,minecraft:soul_sand)
B(-6,63,-3,minecraft:soul_sand)
B(-6,64,-3,minecraft:soul_sand)
B(-6,65,-3,minecraft:soul_sand)
B(-6,66,-3,minecraft:soul_sand)
B(-6,61,-2,minecraft:soul_sand)
B(-6,62,-2,minecraft:soul_sand)
B(-6,63,-2,minecraft:soul_sand)
B(-6,64,-2,minecraft:soul_sand)
B(-6,65,-2,minecraft:soul_sand)
B(-6,66,-2,minecraft:soul_sand)
B(-6,61,-1,minecraft:soul_sand)
B(-6,62,-1,minecraft:soul_sand)
B(-6,63,-1,minecraft:soul_sand)
B(-6,64,-1,minecraft:soul_sand)
B(-6,65,-1,minecraft:soul_sand)
B(-6,66,-1,minecraft:soul_sand)
B(-6,62,0,minecraft:soul_sand)
B(-6,63,0,minecraft:soul_sand)
B(-6,64,0,minecraft:soul_sand)
B(-6,65,0,minecraft:soul_sand)
B(-6,66,0,minecraft:soul_sand)
B(-6,63,1,minecraft:soul_sand)
B(-6,64,1,minecraft:soul_sand)
B(-6,65,1,minecraft:soul_sand)
B(-6,66,1,minecraft:soul_sand)
B(-6,65,2,minecraft:soul_sand)
B(-6,66,2,minecraft:soul_sand)
B(-6,66,3,minecraft:soul_sand)
B(-5,52,-7,minecraft:soul_sand)
B(-5,53,-7,minecraft:soul_sand)
B(-5,54,-7,minecraft:soul_sand)
B(-5,55,-7,minecraft:soul_sand)
B(-5,56,-7,minecraft:soul_sand)
B(-5,57,-7,minecraft:soul_sand)
B(-5,58,-7,minecraft:soul_sand)
B(-5,59,-7,minecraft:soul_sand)
B(-5,60,-7,minecraft:soul_sand)
B(-5,61,-7,minecraft:soul_sand)
B(-5,62,-7,minecraft:soul_sand)
B(-5,63,-7,minecraft:soul_sand)
B(-5,64,-7,minecraft:soul_sand)
B(-5,65,-7,minecraft:soul_sand)
B(-5,66,-7,minecraft:soul_sand)
B(-5,52,-6,minecraft:soul_sand)
B(-5,53,-6,minecraft:soul_sand)
B(-5,54,-6,minecraft:soul_sand)
B(-5,55,-6,minecraft:soul_sand)
B(-5,56,-6,minecraft:soul_sand)
B(-5,57,-6,minecraft:soul_sand)
B(-5,58,-6,minecraft:soul_sand)
B(-5,59,-6,minecraft:soul_sand)
B(-5,60,-6,minecraft:soul_sand)
B(-5,61,-6,minecraft:soul_sand)
B(-5,62,-6,minecraft:soul_sand)
B(-5,63,-6,minecraft:soul_sand)
B(-5,64,-6,minecraft:soul_sand)
B(-5,65,-6,minecraft:soul_sand)
B(-5,66,-6,minecraft:soul_sand)
B(-5,53,-5,minecraft:soul_sand)
B(-5,54,-5,minecraft:soul_sand)
B(-5,55,-5,minecraft:soul_sand)
B(-5,56,-5,minecraft:soul_sand)
B(-5,57,-5,minecraft:soul_sand)
B(-5,58,-5,minecraft:soul_sand)
B(-5,59,-5,minecraft:soul_sand)
B(-5,60,-5,minecraft:soul_sand)
B(-5,61,-5,minecraft:soul_sand)
B(-5,62,-5,minecraft:soul_sand)
B(-5,63,-5,minecraft:soul_sand)
B(-5,64,-5,minecraft:soul_sand)
B(-5,65,-5,minecraft:soul_sand)
B(-5,66,-5,minecraft:soul_sand)
B(-5,54,-4,minecraft:soul_sand)
B(-5,55,-4,minecraft:soul_sand)
B(-5,56,-4,minecraft:soul_sand)
B(-5,57,-4,minecraft:soul_sand)
B(-5,58,-4,minecraft:soul_sand)
B(-5,59,-4,minecraft:soul_sand)
B(-5,60,-4,minecraft:soul_sand)
B(-5,61,-4,minecraft:soul_sand)
B(-5,62,-4,minecraft:soul_sand)
B(-5,63,-4,minecraft:soul_sand)
B(-5,64,-4,minecraft:soul_sand)
B(-5,65,-4,minecraft:soul_sand)
B(-5,66,-4,minecraft:soul_sand)
B(-5,56,-3,minecraft:soul_sand)
B(-5,57,-3,minecraft:soul_sand)
B(-5,58,-3,minecraft:soul_sand)
B(-5,59,-3,minecraft:soul_sand)
B(-5,60,-3,minecraft:soul_sand)
B(-5,61,-3,minecraft:soul_sand)
B(-5,62,-3,minecraft:soul_sand)
B(-5,63,-3,minecraft:soul_sand)
B(-5,64,-3,minecraft:soul_sand)
B(-5,65,-3,minecraft:soul_sand)
B(-5,66,-3,minecraft:soul_sand)
B(-5,61,-2,minecraft:soul_sand)
B(-5,62,-2,minecraft:soul_sand)
B(-5,63,-2,minecraft:soul_sand)
B(-5,64,-2,minecraft:soul_sand)
B(-5,65,-2,minecraft:soul_sand)
B(-5,66,-2,minecraft:soul_sand)
B(-5,61,-1,minecraft:soul_sand)
B(-5,62,-1,minecraft:soul_sand)
B(-5,63,-1,minecraft:soul_sand)
B(-5,64,-1,minecraft:soul_sand)
B(-5,65,-1,minecraft:soul_sand)
B(-5,66,-1,minecraft:soul_sand)
B(-5,62,0,minecraft:soul_sand)
B(-5,63,0,minecraft:soul_sand)
B(-5,64,0,minecraft:soul_sand)
B(-5,65,0,minecraft:soul_sand)
B(-5,66,0,minecraft:soul_sand)
B(-5,63,1,minecraft:soul_sand)
B(-5,64,1,minecraft:soul_sand)
B(-5,65,1,minecraft:soul_sand)
B(-5,66,1,minecraft:soul_sand)
B(-5,65,2,minecraft:soul_sand)
B(-5,66,2,minecraft:soul_sand)
B(-5,66,3,minecraft:soul_sand)
B(-4,51,-7,minecraft:soul_sand)
B(-4,52,-7,minecraft:soul_sand)
B(-4,53,-7,minecraft:soul_sand)
B(-4,54,-7,minecraft:soul_sand)
B(-4,55,-7,minecraft:soul_sand)
B(-4,56,-7,minecraft:soul_sand)
B(-4,57,-7,minecraft:soul_sand)
B(-4,58,-7,minecraft:soul_sand)
B(-4,59,-7,minecraft:soul_sand)
B(-4,60,-7,minecraft:soul_sand)
B(-4,61,-7,minecraft:soul_sand)
B(-4,62,-7,minecraft:soul_sand)
B(-4,63,-7,minecraft:soul_sand)
B(-4,64,-7,minecraft:soul_sand)
B(-4,65,-7,minecraft:soul_sand)
B(-4,66,-7,minecraft:soul_sand)
B(-4,52,-6,minecraft:soul_sand)
B(-4,53,-6,minecraft:soul_sand)
B(-4,54,-6,minecraft:soul_sand)
B(-4,55,-6,minecraft:soul_sand)
B(-4,56,-6,minecraft:soul_sand)
B(-4,57,-6,minecraft:soul_sand)
B(-4,58,-6,minecraft:soul_sand)
B(-4,59,-6,minecraft:soul_sand)
B(-4,60,-6,minecraft:soul_sand)
B(-4,61,-6,minecraft:soul_sand)
B(-4,62,-6,minecraft:soul_sand)
B(-4,63,-6,minecraft:soul_sand)
B(-4,64,-6,minecraft:soul_sand)
B(-4,65,-6,minecraft:soul_sand)
B(-4,66,-6,minecraft:soul_sand)
B(-4,53,-5,minecraft:soul_sand)
B(-4,54,-5,minecraft:soul_sand)
B(-4,55,-5,minecraft:soul_sand)
B(-4,56,-5,minecraft:soul_sand)
B(-4,57,-5,minecraft:soul_sand)
B(-4,58,-5,minecraft:soul_sand)
B(-4,59,-5,minecraft:soul_sand)
B(-4,60,-5,minecraft:soul_sand)
B(-4,61,-5,minecraft:soul_sand)
B(-4,62,-5,minecraft:soul_sand)
B(-4,63,-5,minecraft:soul_sand)
B(-4,64,-5,minecraft:soul_sand)
B(-4,65,-5,minecraft:soul_sand)
B(-4,66,-5,minecraft:soul_sand)
B(-4,54,-4,minecraft:soul_sand)
B(-4,55,-4,minecraft:soul_sand)
B(-4,56,-4,minecraft:soul_sand)
B(-4,57,-4,minecraft:soul_sand)
B(-4,58,-4,minecraft:soul_sand)
B(-4,59,-4,minecraft:soul_sand)
B(-4,60,-4,minecraft:soul_sand)
B(-4,61,-4,minecraft:soul_sand)
B(-4,62,-4,minecraft:soul_sand)
B(-4,63,-4,minecraft:soul_sand)
B(-4,64,-4,minecraft:soul_sand)
B(-4,65,-4,minecraft:soul_sand)
B(-4,66,-4,minecraft:soul_sand)
B(-4,58,-3,minecraft:soul_sand)
B(-4,59,-3,minecraft:soul_sand)
B(-4,60,-3,minecraft:soul_sand)
B(-4,61,-3,minecraft:soul_sand)
B(-4,62,-3,minecraft:soul_sand)
B(-4,63,-3,minecraft:soul_sand)
B(-4,64,-3,minecraft:soul_sand)
B(-4,65,-3,minecraft:soul_sand)
B(-4,66,-3,minecraft:soul_sand)
B(-4,60,-2,minecraft:soul_sand)
B(-4,61,-2,minecraft:soul_sand)
B(-4,62,-2,minecraft:soul_sand)
B(-4,63,-2,minecraft:soul_sand)
B(-4,64,-2,minecraft:soul_sand)
B(-4,65,-2,minecraft:soul_sand)
B(-4,66,-2,minecraft:soul_sand)
B(-4,61,-1,minecraft:soul_sand)
B(-4,62,-1,minecraft:soul_sand)
B(-4,63,-1,minecraft:soul_sand)
B(-4,64,-1,minecraft:soul_sand)
B(-4,65,-1,minecraft:soul_sand)
B(-4,66,-1,minecraft:soul_sand)
B(-4,62,0,minecraft:soul_sand)
B(-4,63,0,minecraft:soul_sand)
B(-4,64,0,minecraft:soul_sand)
B(-4,65,0,minecraft:soul_sand)
B(-4,66,0,minecraft:soul_sand)
B(-4,63,1,minecraft:soul_sand)
B(-4,64,1,minecraft:soul_sand)
B(-4,65,1,minecraft:soul_sand)
B(-4,66,1,minecraft:soul_sand)
B(-4,64,2,minecraft:soul_sand)
B(-4,65,2,minecraft:soul_sand)
B(-4,66,2,minecraft:soul_sand)
B(-4,66,3,minecraft:soul_sand)
B(-3,50,-7,minecraft:soul_sand)
B(-3,51,-7,minecraft:soul_sand)
B(-3,52,-7,minecraft:soul_sand)
B(-3,53,-7,minecraft:soul_sand)
B(-3,54,-7,minecraft:soul_sand)
B(-3,55,-7,minecraft:soul_sand)
B(-3,56,-7,minecraft:soul_sand)
B(-3,57,-7,minecraft:soul_sand)
B(-3,58,-7,minecraft:soul_sand)
B(-3,59,-7,minecraft:soul_sand)
B(-3,60,-7,minecraft:soul_sand)
B(-3,61,-7,minecraft:soul_sand)
B(-3,62,-7,minecraft:soul_sand)
B(-3,63,-7,minecraft:soul_sand)
B(-3,64,-7,minecraft:soul_sand)
B(-3,65,-7,minecraft:soul_sand)
B(-3,66,-7,minecraft:soul_sand)
B(-3,52,-6,minecraft:soul_sand)
B(-3,53,-6,minecraft:soul_sand)
B(-3,54,-6,minecraft:soul_sand)
B(-3,55,-6,minecraft:soul_sand)
B(-3,56,-6,minecraft:soul_sand)
B(-3,57,-6,minecraft:soul_sand)
B(-3,58,-6,minecraft:soul_sand)
B(-3,59,-6,minecraft:soul_sand)
B(-3,60,-6,minecraft:soul_sand)
B(-3,61,-6,minecraft:soul_sand)
B(-3,62,-6,minecraft:soul_sand)
B(-3,63,-6,minecraft:soul_sand)
B(-3,64,-6,minecraft:soul_sand)
B(-3,65,-6,minecraft:soul_sand)
B(-3,66,-6,minecraft:soul_sand)
B(-3,53,-5,minecraft:soul_sand)
B(-3,54,-5,minecraft:soul_sand)
B(-3,55,-5,minecraft:soul_sand)
B(-3,56,-5,minecraft:soul_sand)
B(-3,57,-5,minecraft:soul_sand)
B(-3,58,-5,minecraft:soul_sand)
B(-3,59,-5,minecraft:soul_sand)
B(-3,60,-5,minecraft:soul_sand)
B(-3,61,-5,minecraft:soul_sand)
B(-3,62,-5,minecraft:soul_sand)
B(-3,63,-5,minecraft:soul_sand)
B(-3,64,-5,minecraft:soul_sand)
B(-3,65,-5,minecraft:soul_sand)
B(-3,66,-5,minecraft:soul_sand)
B(-3,55,-4,minecraft:soul_sand)
B(-3,56,-4,minecraft:soul_sand)
B(-3,57,-4,minecraft:soul_sand)
B(-3,58,-4,minecraft:soul_sand)
B(-3,59,-4,minecraft:soul_sand)
B(-3,60,-4,minecraft:soul_sand)
B(-3,61,-4,minecraft:soul_sand)
B(-3,62,-4,minecraft:soul_sand)
B(-3,63,-4,minecraft:soul_sand)
B(-3,64,-4,minecraft:soul_sand)
B(-3,65,-4,minecraft:soul_sand)
B(-3,66,-4,minecraft:soul_sand)
B(-3,58,-3,minecraft:soul_sand)
B(-3,59,-3,minecraft:soul_sand)
B(-3,60,-3,minecraft:soul_sand)
B(-3,61,-3,minecraft:soul_sand)
B(-3,62,-3,minecraft:soul_sand)
B(-3,63,-3,minecraft:soul_sand)
B(-3,64,-3,minecraft:soul_sand)
B(-3,65,-3,minecraft:soul_sand)
B(-3,66,-3,minecraft:soul_sand)
B(-3,60,-2,minecraft:soul_sand)
B(-3,61,-2,minecraft:soul_sand)
B(-3,62,-2,minecraft:soul_sand)
B(-3,63,-2,minecraft:soul_sand)
B(-3,64,-2,minecraft:soul_sand)
B(-3,65,-2,minecraft:soul_sand)
B(-3,66,-2,minecraft:soul_sand)
B(-3,60,-1,minecraft:soul_sand)
B(-3,61,-1,minecraft:soul_sand)
B(-3,62,-1,minecraft:soul_sand)
B(-3,63,-1,minecraft:soul_sand)
B(-3,64,-1,minecraft:soul_sand)
B(-3,65,-1,minecraft:soul_sand)
B(-3,66,-1,minecraft:soul_sand)
B(-3,61,0,minecraft:soul_sand)
B(-3,62,0,minecraft:soul_sand)
B(-3,63,0,minecraft:soul_sand)
B(-3,64,0,minecraft:soul_sand)
B(-3,65,0,minecraft:soul_sand)
B(-3,66,0,minecraft:soul_sand)
B(-3,62,1,minecraft:soul_sand)
B(-3,63,1,minecraft:soul_sand)
B(-3,64,1,minecraft:soul_sand)
B(-3,65,1,minecraft:soul_sand)
B(-3,66,1,minecraft:soul_sand)
B(-3,64,2,minecraft:soul_sand)
B(-3,65,2,minecraft:soul_sand)
B(-3,66,2,minecraft:soul_sand)
B(-3,65,3,minecraft:soul_sand)
B(-3,66,3,minecraft:soul_sand)
B(-3,66,4,minecraft:soul_sand)
B(-3,66,8,minecraft:soul_sand)
B(-2,50,-7,minecraft:soul_sand)
B(-2,51,-7,minecraft:soul_sand)
B(-2,52,-7,minecraft:soul_sand)
B(-2,53,-7,minecraft:soul_sand)
B(-2,54,-7,minecraft:soul_sand)
B(-2,55,-7,minecraft:soul_sand)
B(-2,56,-7,minecraft:soul_sand)
B(-2,57,-7,minecraft:soul_sand)
B(-2,58,-7,minecraft:soul_sand)
B(-2,59,-7,minecraft:soul_sand)
B(-2,60,-7,minecraft:soul_sand)
B(-2,61,-7,minecraft:soul_sand)
B(-2,62,-7,minecraft:soul_sand)
B(-2,63,-7,minecraft:soul_sand)
B(-2,64,-7,minecraft:soul_sand)
B(-2,65,-7,minecraft:soul_sand)
B(-2,66,-7,minecraft:soul_sand)
B(-2,51,-6,minecraft:soul_sand)
B(-2,52,-6,minecraft:soul_sand)
B(-2,53,-6,minecraft:soul_sand)
B(-2,54,-6,minecraft:soul_sand)
B(-2,55,-6,minecraft:soul_sand)
B(-2,56,-6,minecraft:soul_sand)
B(-2,57,-6,minecraft:soul_sand)
B(-2,58,-6,minecraft:soul_sand)
B(-2,59,-6,minecraft:soul_sand)
B(-2,60,-6,minecraft:soul_sand)
B(-2,61,-6,minecraft:soul_sand)
B(-2,62,-6,minecraft:soul_sand)
B(-2,63,-6,minecraft:soul_sand)
B(-2,64,-6,minecraft:soul_sand)
B(-2,65,-6,minecraft:soul_sand)
B(-2,66,-6,minecraft:soul_sand)
B(-2,53,-5,minecraft:soul_sand)
B(-2,54,-5,minecraft:soul_sand)
B(-2,55,-5,minecraft:soul_sand)
B(-2,56,-5,minecraft:soul_sand)
B(-2,57,-5,minecraft:soul_sand)
B(-2,58,-5,minecraft:soul_sand)
B(-2,59,-5,minecraft:soul_sand)
B(-2,60,-5,minecraft:soul_sand)
B(-2,61,-5,minecraft:soul_sand)
B(-2,62,-5,minecraft:soul_sand)
B(-2,63,-5,minecraft:soul_sand)
B(-2,64,-5,minecraft:soul_sand)
B(-2,65,-5,minecraft:soul_sand)
B(-2,66,-5,minecraft:soul_sand)
B(-2,54,-4,minecraft:soul_sand)
B(-2,55,-4,minecraft:soul_sand)
B(-2,56,-4,minecraft:soul_sand)
B(-2,57,-4,minecraft:soul_sand)
B(-2,58,-4,minecraft:soul_sand)
B(-2,59,-4,minecraft:soul_sand)
B(-2,60,-4,minecraft:soul_sand)
B(-2,61,-4,minecraft:soul_sand)
B(-2,62,-4,minecraft:soul_sand)
B(-2,63,-4,minecraft:soul_sand)
B(-2,64,-4,minecraft:soul_sand)
B(-2,65,-4,minecraft:soul_sand)
B(-2,66,-4,minecraft:soul_sand)
B(-2,58,-3,minecraft:soul_sand)
B(-2,59,-3,minecraft:soul_sand)
B(-2,60,-3,minecraft:soul_sand)
B(-2,61,-3,minecraft:soul_sand)
B(-2,62,-3,minecraft:soul_sand)
B(-2,63,-3,minecraft:soul_sand)
B(-2,64,-3,minecraft:soul_sand)
B(-2,65,-3,minecraft:soul_sand)
B(-2,66,-3,minecraft:soul_sand)
B(-2,59,-2,minecraft:soul_sand)
B(-2,60,-2,minecraft:soul_sand)
B(-2,61,-2,minecraft:soul_sand)
B(-2,62,-2,minecraft:soul_sand)
B(-2,63,-2,minecraft:soul_sand)
B(-2,64,-2,minecraft:soul_sand)
B(-2,65,-2,minecraft:soul_sand)
B(-2,66,-2,minecraft:soul_sand)
B(-2,59,-1,minecraft:soul_sand)
B(-2,60,-1,minecraft:soul_sand)
B(-2,61,-1,minecraft:soul_sand)
B(-2,62,-1,minecraft:soul_sand)
B(-2,63,-1,minecraft:soul_sand)
B(-2,64,-1,minecraft:soul_sand)
B(-2,65,-1,minecraft:soul_sand)
B(-2,66,-1,minecraft:soul_sand)
B(-2,60,0,minecraft:soul_sand)
B(-2,61,0,minecraft:soul_sand)
B(-2,62,0,minecraft:soul_sand)
B(-2,63,0,minecraft:soul_sand)
B(-2,64,0,minecraft:soul_sand)
B(-2,65,0,minecraft:soul_sand)
B(-2,66,0,minecraft:soul_sand)
B(-2,61,1,minecraft:soul_sand)
B(-2,62,1,minecraft:soul_sand)
B(-2,63,1,minecraft:soul_sand)
B(-2,64,1,minecraft:soul_sand)
B(-2,65,1,minecraft:soul_sand)
B(-2,66,1,minecraft:soul_sand)
B(-2,63,2,minecraft:soul_sand)
B(-2,64,2,minecraft:soul_sand)
B(-2,65,2,minecraft:soul_sand)
B(-2,66,2,minecraft:soul_sand)
B(-2,65,3,minecraft:soul_sand)
B(-2,66,3,minecraft:soul_sand)
B(-2,66,4,minecraft:soul_sand)
B(-2,66,5,minecraft:soul_sand)
B(-2,66,6,minecraft:soul_sand)
B(-2,66,7,minecraft:soul_sand)
B(-2,66,8,minecraft:soul_sand)
B(-1,50,-7,minecraft:soul_sand)
B(-1,51,-7,minecraft:soul_sand)
B(-1,52,-7,minecraft:soul_sand)
B(-1,53,-7,minecraft:soul_sand)
B(-1,54,-7,minecraft:soul_sand)
B(-1,55,-7,minecraft:soul_sand)
B(-1,56,-7,minecraft:soul_sand)
B(-1,57,-7,minecraft:soul_sand)
B(-1,58,-7,minecraft:soul_sand)
B(-1,59,-7,minecraft:soul_sand)
B(-1,60,-7,minecraft:soul_sand)
B(-1,61,-7,minecraft:soul_sand)
B(-1,62,-7,minecraft:soul_sand)
B(-1,63,-7,minecraft:soul_sand)
B(-1,64,-7,minecraft:soul_sand)
B(-1,65,-7,minecraft:soul_sand)
B(-1,66,-7,minecraft:soul_sand)
B(-1,51,-6,minecraft:soul_sand)
B(-1,52,-6,minecraft:soul_sand)
B(-1,53,-6,minecraft:soul_sand)
B(-1,54,-6,minecraft:soul_sand)
B(-1,55,-6,minecraft:soul_sand)
B(-1,56,-6,minecraft:soul_sand)
B(-1,57,-6,minecraft:soul_sand)
B(-1,58,-6,minecraft:soul_sand)
B(-1,59,-6,minecraft:soul_sand)
B(-1,60,-6,minecraft:soul_sand)
B(-1,61,-6,minecraft:soul_sand)
B(-1,62,-6,minecraft:soul_sand)
B(-1,63,-6,minecraft:soul_sand)
B(-1,64,-6,minecraft:soul_sand)
B(-1,65,-6,minecraft:soul_sand)
B(-1,66,-6,minecraft:soul_sand)
B(-1,54,-5,minecraft:soul_sand)
B(-1,55,-5,minecraft:soul_sand)
B(-1,56,-5,minecraft:soul_sand)
B(-1,57,-5,minecraft:soul_sand)
B(-1,58,-5,minecraft:soul_sand)
B(-1,59,-5,minecraft:soul_sand)
B(-1,60,-5,minecraft:soul_sand)
B(-1,61,-5,minecraft:soul_sand)
B(-1,62,-5,minecraft:soul_sand)
B(-1,63,-5,minecraft:soul_sand)
B(-1,64,-5,minecraft:soul_sand)
B(-1,65,-5,minecraft:soul_sand)
B(-1,66,-5,minecraft:soul_sand)
B(-1,55,-4,minecraft:soul_sand)
B(-1,56,-4,minecraft:soul_sand)
B(-1,57,-4,minecraft:soul_sand)
B(-1,58,-4,minecraft:soul_sand)
B(-1,59,-4,minecraft:soul_sand)
B(-1,60,-4,minecraft:soul_sand)
B(-1,61,-4,minecraft:soul_sand)
B(-1,62,-4,minecraft:soul_sand)
B(-1,63,-4,minecraft:soul_sand)
B(-1,64,-4,minecraft:soul_sand)
B(-1,65,-4,minecraft:soul_sand)
B(-1,66,-4,minecraft:soul_sand)
B(-1,58,-3,minecraft:soul_sand)
B(-1,59,-3,minecraft:soul_sand)
B(-1,60,-3,minecraft:soul_sand)
B(-1,61,-3,minecraft:soul_sand)
B(-1,62,-3,minecraft:soul_sand)
B(-1,63,-3,minecraft:soul_sand)
B(-1,64,-3,minecraft:soul_sand)
B(-1,65,-3,minecraft:soul_sand)
B(-1,66,-3,minecraft:soul_sand)
B(-1,58,-2,minecraft:soul_sand)
B(-1,59,-2,minecraft:soul_sand)
B(-1,60,-2,minecraft:soul_sand)
B(-1,61,-2,minecraft:soul_sand)
B(-1,62,-2,minecraft:soul_sand)
B(-1,63,-2,minecraft:soul_sand)
B(-1,64,-2,minecraft:soul_sand)
B(-1,65,-2,minecraft:soul_sand)
B(-1,66,-2,minecraft:soul_sand)
B(-1,59,-1,minecraft:soul_sand)
B(-1,60,-1,minecraft:soul_sand)
B(-1,61,-1,minecraft:soul_sand)
B(-1,62,-1,minecraft:soul_sand)
B(-1,63,-1,minecraft:soul_sand)
B(-1,64,-1,minecraft:soul_sand)
B(-1,65,-1,minecraft:soul_sand)
B(-1,66,-1,minecraft:soul_sand)
B(-1,60,0,minecraft:soul_sand)
B(-1,61,0,minecraft:soul_sand)
B(-1,62,0,minecraft:soul_sand)
B(-1,63,0,minecraft:soul_sand)
B(-1,64,0,minecraft:soul_sand)
B(-1,65,0,minecraft:soul_sand)
B(-1,66,0,minecraft:soul_sand)
B(-1,61,1,minecraft:soul_sand)
B(-1,62,1,minecraft:soul_sand)
B(-1,63,1,minecraft:soul_sand)
B(-1,64,1,minecraft:soul_sand)
B(-1,65,1,minecraft:soul_sand)
B(-1,66,1,minecraft:soul_sand)
B(-1,62,2,minecraft:soul_sand)
B(-1,63,2,minecraft:soul_sand)
B(-1,64,2,minecraft:soul_sand)
B(-1,65,2,minecraft:soul_sand)
B(-1,66,2,minecraft:soul_sand)
B(-1,64,3,minecraft:soul_sand)
B(-1,65,3,minecraft:soul_sand)
B(-1,66,3,minecraft:soul_sand)
B(-1,65,4,minecraft:soul_sand)
B(-1,66,4,minecraft:soul_sand)
B(-1,66,5,minecraft:soul_sand)
B(-1,66,6,minecraft:soul_sand)
B(-1,66,7,minecraft:soul_sand)
B(-1,65,8,minecraft:soul_sand)
B(-1,66,8,minecraft:soul_sand)
B(0,50,-7,minecraft:soul_sand)
B(0,51,-7,minecraft:soul_sand)
B(0,52,-7,minecraft:soul_sand)
B(0,53,-7,minecraft:soul_sand)
B(0,54,-7,minecraft:soul_sand)
B(0,55,-7,minecraft:soul_sand)
B(0,56,-7,minecraft:soul_sand)
B(0,57,-7,minecraft:soul_sand)
B(0,58,-7,minecraft:soul_sand)
B(0,59,-7,minecraft:soul_sand)
B(0,60,-7,minecraft:soul_sand)
B(0,61,-7,minecraft:soul_sand)
B(0,62,-7,minecraft:soul_sand)
B(0,63,-7,minecraft:soul_sand)
B(0,64,-7,minecraft:soul_sand)
B(0,65,-7,minecraft:soul_sand)
B(0,66,-7,minecraft:soul_sand)
B(0,51,-6,minecraft:soul_sand)
B(0,52,-6,minecraft:soul_sand)
B(0,53,-6,minecraft:soul_sand)
B(0,54,-6,minecraft:soul_sand)
B(0,55,-6,minecraft:soul_sand)
B(0,56,-6,minecraft:soul_sand)
B(0,57,-6,minecraft:soul_sand)
B(0,58,-6,minecraft:soul_sand)
B(0,59,-6,minecraft:soul_sand)
B(0,60,-6,minecraft:soul_sand)
B(0,61,-6,minecraft:soul_sand)
B(0,62,-6,minecraft:soul_sand)
B(0,63,-6,minecraft:soul_sand)
B(0,64,-6,minecraft:soul_sand)
B(0,65,-6,minecraft:soul_sand)
B(0,66,-6,minecraft:soul_sand)
B(0,55,-5,minecraft:soul_sand)
B(0,56,-5,minecraft:soul_sand)
B(0,57,-5,minecraft:soul_sand)
B(0,58,-5,minecraft:soul_sand)
B(0,59,-5,minecraft:soul_sand)
B(0,60,-5,minecraft:soul_sand)
B(0,61,-5,minecraft:soul_sand)
B(0,62,-5,minecraft:soul_sand)
B(0,63,-5,minecraft:soul_sand)
B(0,64,-5,minecraft:soul_sand)
B(0,65,-5,minecraft:soul_sand)
B(0,66,-5,minecraft:soul_sand)
B(0,56,-4,minecraft:soul_sand)
B(0,57,-4,minecraft:soul_sand)
B(0,58,-4,minecraft:soul_sand)
B(0,59,-4,minecraft:soul_sand)
B(0,60,-4,minecraft:soul_sand)
B(0,61,-4,minecraft:soul_sand)
B(0,62,-4,minecraft:soul_sand)
B(0,63,-4,minecraft:soul_sand)
B(0,64,-4,minecraft:soul_sand)
B(0,65,-4,minecraft:soul_sand)
B(0,66,-4,minecraft:soul_sand)
B(0,57,-3,minecraft:soul_sand)
B(0,58,-3,minecraft:soul_sand)
B(0,59,-3,minecraft:soul_sand)
B(0,60,-3,minecraft:soul_sand)
B(0,61,-3,minecraft:soul_sand)
B(0,62,-3,minecraft:soul_sand)
B(0,63,-3,minecraft:soul_sand)
B(0,64,-3,minecraft:soul_sand)
B(0,65,-3,minecraft:soul_sand)
B(0,66,-3,minecraft:soul_sand)
B(0,58,-2,minecraft:soul_sand)
B(0,59,-2,minecraft:soul_sand)
B(0,60,-2,minecraft:soul_sand)
B(0,61,-2,minecraft:soul_sand)
B(0,62,-2,minecraft:soul_sand)
B(0,63,-2,minecraft:soul_sand)
B(0,64,-2,minecraft:soul_sand)
B(0,65,-2,minecraft:soul_sand)
B(0,66,-2,minecraft:soul_sand)
B(0,59,-1,minecraft:soul_sand)
B(0,60,-1,minecraft:soul_sand)
B(0,61,-1,minecraft:soul_sand)
B(0,62,-1,minecraft:soul_sand)
B(0,63,-1,minecraft:soul_sand)
B(0,64,-1,minecraft:soul_sand)
B(0,65,-1,minecraft:soul_sand)
B(0,66,-1,minecraft:soul_sand)
B(0,59,0,minecraft:soul_sand)
B(0,60,0,minecraft:soul_sand)
B(0,61,0,minecraft:soul_sand)
B(0,62,0,minecraft:soul_sand)
B(0,63,0,minecraft:soul_sand)
B(0,64,0,minecraft:soul_sand)
B(0,65,0,minecraft:soul_sand)
B(0,66,0,minecraft:soul_sand)
B(0,60,1,minecraft:soul_sand)
B(0,61,1,minecraft:soul_sand)
B(0,62,1,minecraft:soul_sand)
B(0,63,1,minecraft:soul_sand)
B(0,64,1,minecraft:soul_sand)
B(0,65,1,minecraft:soul_sand)
B(0,66,1,minecraft:soul_sand)
B(0,61,2,minecraft:soul_sand)
B(0,62,2,minecraft:soul_sand)
B(0,63,2,minecraft:soul_sand)
B(0,64,2,minecraft:soul_sand)
B(0,65,2,minecraft:soul_sand)
B(0,66,2,minecraft:soul_sand)
B(0,63,3,minecraft:soul_sand)
B(0,64,3,minecraft:soul_sand)
B(0,65,3,minecraft:soul_sand)
B(0,66,3,minecraft:soul_sand)
B(0,64,4,minecraft:soul_sand)
B(0,65,4,minecraft:soul_sand)
B(0,66,4,minecraft:soul_sand)
B(0,65,5,minecraft:soul_sand)
B(0,66,5,minecraft:soul_sand)
B(0,65,6,minecraft:soul_sand)
B(0,66,6,minecraft:soul_sand)
B(0,65,7,minecraft:soul_sand)
B(0,66,7,minecraft:soul_sand)
B(0,65,8,minecraft:soul_sand)
B(0,66,8,minecraft:soul_sand)
B(1,50,-7,minecraft:soul_sand)
B(1,51,-7,minecraft:soul_sand)
B(1,52,-7,minecraft:soul_sand)
B(1,53,-7,minecraft:soul_sand)
B(1,54,-7,minecraft:soul_sand)
B(1,55,-7,minecraft:soul_sand)
B(1,56,-7,minecraft:soul_sand)
B(1,57,-7,minecraft:soul_sand)
B(1,58,-7,minecraft:soul_sand)
B(1,59,-7,minecraft:soul_sand)
B(1,60,-7,minecraft:soul_sand)
B(1,61,-7,minecraft:soul_sand)
B(1,62,-7,minecraft:soul_sand)
B(1,63,-7,minecraft:soul_sand)
B(1,64,-7,minecraft:soul_sand)
B(1,65,-7,minecraft:soul_sand)
B(1,66,-7,minecraft:soul_sand)
B(1,52,-6,minecraft:soul_sand)
B(1,53,-6,minecraft:soul_sand)
B(1,54,-6,minecraft:soul_sand)
B(1,55,-6,minecraft:soul_sand)
B(1,56,-6,minecraft:soul_sand)
B(1,57,-6,minecraft:soul_sand)
B(1,58,-6,minecraft:soul_sand)
B(1,59,-6,minecraft:soul_sand)
B(1,60,-6,minecraft:soul_sand)
B(1,61,-6,minecraft:soul_sand)
B(1,62,-6,minecraft:soul_sand)
B(1,63,-6,minecraft:soul_sand)
B(1,64,-6,minecraft:soul_sand)
B(1,65,-6,minecraft:soul_sand)
B(1,66,-6,minecraft:soul_sand)
B(1,54,-5,minecraft:soul_sand)
B(1,55,-5,minecraft:soul_sand)
B(1,56,-5,minecraft:soul_sand)
B(1,57,-5,minecraft:soul_sand)
B(1,58,-5,minecraft:soul_sand)
B(1,59,-5,minecraft:soul_sand)
B(1,60,-5,minecraft:soul_sand)
B(1,61,-5,minecraft:soul_sand)
B(1,62,-5,minecraft:soul_sand)
B(1,63,-5,minecraft:soul_sand)
B(1,64,-5,minecraft:soul_sand)
B(1,65,-5,minecraft:soul_sand)
B(1,66,-5,minecraft:soul_sand)
B(1,55,-4,minecraft:soul_sand)
B(1,56,-4,minecraft:soul_sand)
B(1,57,-4,minecraft:soul_sand)
B(1,58,-4,minecraft:soul_sand)
B(1,59,-4,minecraft:soul_sand)
B(1,60,-4,minecraft:soul_sand)
B(1,61,-4,minecraft:soul_sand)
B(1,62,-4,minecraft:soul_sand)
B(1,63,-4,minecraft:soul_sand)
B(1,64,-4,minecraft:soul_sand)
B(1,65,-4,minecraft:soul_sand)
B(1,66,-4,minecraft:soul_sand)
B(1,57,-3,minecraft:soul_sand)
B(1,58,-3,minecraft:soul_sand)
B(1,59,-3,minecraft:soul_sand)
B(1,60,-3,minecraft:soul_sand)
B(1,61,-3,minecraft:soul_sand)
B(1,62,-3,minecraft:soul_sand)
B(1,63,-3,minecraft:soul_sand)
B(1,64,-3,minecraft:soul_sand)
B(1,65,-3,minecraft:soul_sand)
B(1,66,-3,minecraft:soul_sand)
B(1,58,-2,minecraft:soul_sand)
B(1,59,-2,minecraft:soul_sand)
B(1,60,-2,minecraft:soul_sand)
B(1,61,-2,minecraft:soul_sand)
B(1,62,-2,minecraft:soul_sand)
B(1,63,-2,minecraft:soul_sand)
B(1,64,-2,minecraft:soul_sand)
B(1,65,-2,minecraft:soul_sand)
B(1,66,-2,minecraft:soul_sand)
B(1,59,-1,minecraft:soul_sand)
B(1,60,-1,minecraft:soul_sand)
B(1,61,-1,minecraft:soul_sand)
B(1,62,-1,minecraft:soul_sand)
B(1,63,-1,minecraft:soul_sand)
B(1,64,-1,minecraft:soul_sand)
B(1,65,-1,minecraft:soul_sand)
B(1,66,-1,minecraft:soul_sand)
B(1,59,0,minecraft:soul_sand)
B(1,60,0,minecraft:soul_sand)
B(1,61,0,minecraft:soul_sand)
B(1,62,0,minecraft:soul_sand)
B(1,63,0,minecraft:soul_sand)
B(1,64,0,minecraft:soul_sand)
B(1,65,0,minecraft:soul_sand)
B(1,66,0,minecraft:soul_sand)
B(1,60,1,minecraft:soul_sand)
B(1,61,1,minecraft:soul_sand)
B(1,62,1,minecraft:soul_sand)
B(1,63,1,minecraft:soul_sand)
B(1,64,1,minecraft:soul_sand)
B(1,65,1,minecraft:soul_sand)
B(1,66,1,minecraft:soul_sand)
B(1,61,2,minecraft:soul_sand)
B(1,62,2,minecraft:soul_sand)
B(1,63,2,minecraft:soul_sand)
B(1,64,2,minecraft:soul_sand)
B(1,65,2,minecraft:soul_sand)
B(1,66,2,minecraft:soul_sand)
B(1,62,3,minecraft:soul_sand)
B(1,63,3,minecraft:soul_sand)
B(1,64,3,minecraft:soul_sand)
B(1,65,3,minecraft:soul_sand)
B(1,66,3,minecraft:soul_sand)
B(1,63,4,minecraft:soul_sand)
B(1,64,4,minecraft:soul_sand)
B(1,65,4,minecraft:soul_sand)
B(1,66,4,minecraft:soul_sand)
B(1,64,5,minecraft:soul_sand)
B(1,65,5,minecraft:soul_sand)
B(1,66,5,minecraft:soul_sand)
B(1,64,6,minecraft:soul_sand)
B(1,65,6,minecraft:soul_sand)
B(1,66,6,minecraft:soul_sand)
B(1,64,7,minecraft:soul_sand)
B(1,65,7,minecraft:soul_sand)
B(1,66,7,minecraft:soul_sand)
B(1,64,8,minecraft:soul_sand)
B(1,65,8,minecraft:soul_sand)
B(1,66,8,minecraft:soul_sand)
B(2,51,-7,minecraft:soul_sand)
B(2,52,-7,minecraft:soul_sand)
B(2,53,-7,minecraft:soul_sand)
B(2,54,-7,minecraft:soul_sand)
B(2,55,-7,minecraft:soul_sand)
B(2,56,-7,minecraft:soul_sand)
B(2,57,-7,minecraft:soul_sand)
B(2,58,-7,minecraft:soul_sand)
B(2,59,-7,minecraft:soul_sand)
B(2,60,-7,minecraft:soul_sand)
B(2,61,-7,minecraft:soul_sand)
B(2,62,-7,minecraft:soul_sand)
B(2,63,-7,minecraft:soul_sand)
B(2,64,-7,minecraft:soul_sand)
B(2,65,-7,minecraft:soul_sand)
B(2,66,-7,minecraft:soul_sand)
B(2,53,-6,minecraft:soul_sand)
B(2,54,-6,minecraft:soul_sand)
B(2,55,-6,minecraft:soul_sand)
B(2,56,-6,minecraft:soul_sand)
B(2,57,-6,minecraft:soul_sand)
B(2,58,-6,minecraft:soul_sand)
B(2,59,-6,minecraft:soul_sand)
B(2,60,-6,minecraft:soul_sand)
B(2,61,-6,minecraft:soul_sand)
B(2,62,-6,minecraft:soul_sand)
B(2,63,-6,minecraft:soul_sand)
B(2,64,-6,minecraft:soul_sand)
B(2,65,-6,minecraft:soul_sand)
B(2,66,-6,minecraft:soul_sand)
B(2,54,-5,minecraft:soul_sand)
B(2,55,-5,minecraft:soul_sand)
B(2,56,-5,minecraft:soul_sand)
B(2,57,-5,minecraft:soul_sand)
B(2,58,-5,minecraft:soul_sand)
B(2,59,-5,minecraft:soul_sand)
B(2,60,-5,minecraft:soul_sand)
B(2,61,-5,minecraft:soul_sand)
B(2,62,-5,minecraft:soul_sand)
B(2,63,-5,minecraft:soul_sand)
B(2,64,-5,minecraft:soul_sand)
B(2,65,-5,minecraft:soul_sand)
B(2,66,-5,minecraft:soul_sand)
B(2,54,-4,minecraft:soul_sand)
B(2,55,-4,minecraft:soul_sand)
B(2,56,-4,minecraft:soul_sand)
B(2,57,-4,minecraft:soul_sand)
B(2,58,-4,minecraft:soul_sand)
B(2,59,-4,minecraft:soul_sand)
B(2,60,-4,minecraft:soul_sand)
B(2,61,-4,minecraft:soul_sand)
B(2,62,-4,minecraft:soul_sand)
B(2,63,-4,minecraft:soul_sand)
B(2,64,-4,minecraft:soul_sand)
B(2,65,-4,minecraft:soul_sand)
B(2,66,-4,minecraft:soul_sand)
B(2,57,-3,minecraft:soul_sand)
B(2,58,-3,minecraft:soul_sand)
B(2,59,-3,minecraft:soul_sand)
B(2,60,-3,minecraft:soul_sand)
B(2,61,-3,minecraft:soul_sand)
B(2,62,-3,minecraft:soul_sand)
B(2,63,-3,minecraft:soul_sand)
B(2,64,-3,minecraft:soul_sand)
B(2,65,-3,minecraft:soul_sand)
B(2,66,-3,minecraft:soul_sand)
B(2,58,-2,minecraft:soul_sand)
B(2,59,-2,minecraft:soul_sand)
B(2,60,-2,minecraft:soul_sand)
B(2,61,-2,minecraft:soul_sand)
B(2,62,-2,minecraft:soul_sand)
B(2,63,-2,minecraft:soul_sand)
B(2,64,-2,minecraft:soul_sand)
B(2,65,-2,minecraft:soul_sand)
B(2,66,-2,minecraft:soul_sand)
B(2,59,-1,minecraft:soul_sand)
B(2,60,-1,minecraft:soul_sand)
B(2,61,-1,minecraft:soul_sand)
B(2,62,-1,minecraft:soul_sand)
B(2,63,-1,minecraft:soul_sand)
B(2,64,-1,minecraft:soul_sand)
B(2,65,-1,minecraft:soul_sand)
B(2,66,-1,minecraft:soul_sand)
B(2,59,0,minecraft:soul_sand)
B(2,60,0,minecraft:soul_sand)
B(2,61,0,minecraft:soul_sand)
B(2,62,0,minecraft:soul_sand)
B(2,63,0,minecraft:soul_sand)
B(2,64,0,minecraft:soul_sand)
B(2,65,0,minecraft:soul_sand)
B(2,66,0,minecraft:soul_sand)
B(2,60,1,minecraft:soul_sand)
B(2,61,1,minecraft:soul_sand)
B(2,62,1,minecraft:soul_sand)
B(2,63,1,minecraft:soul_sand)
B(2,64,1,minecraft:soul_sand)
B(2,65,1,minecraft:soul_sand)
B(2,66,1,minecraft:soul_sand)
B(2,61,2,minecraft:soul_sand)
B(2,62,2,minecraft:soul_sand)
B(2,63,2,minecraft:soul_sand)
B(2,64,2,minecraft:soul_sand)
B(2,65,2,minecraft:soul_sand)
B(2,66,2,minecraft:soul_sand)
B(2,61,3,minecraft:soul_sand)
B(2,62,3,minecraft:soul_sand)
B(2,63,3,minecraft:soul_sand)
B(2,64,3,minecraft:soul_sand)
B(2,65,3,minecraft:soul_sand)
B(2,66,3,minecraft:soul_sand)
B(2,62,4,minecraft:soul_sand)
B(2,63,4,minecraft:soul_sand)
B(2,64,4,minecraft:soul_sand)
B(2,65,4,minecraft:soul_sand)
B(2,66,4,minecraft:soul_sand)
B(2,63,5,minecraft:soul_sand)
B(2,64,5,minecraft:soul_sand)
B(2,65,5,minecraft:soul_sand)
B(2,66,5,minecraft:soul_sand)
B(2,64,6,minecraft:soul_sand)
B(2,65,6,minecraft:soul_sand)
B(2,66,6,minecraft:soul_sand)
B(2,64,7,minecraft:soul_sand)
B(2,65,7,minecraft:soul_sand)
B(2,66,7,minecraft:soul_sand)
B(2,64,8,minecraft:soul_sand)
B(2,65,8,minecraft:soul_sand)
B(2,66,8,minecraft:soul_sand)
B(3,53,-7,minecraft:soul_sand)
B(3,54,-7,minecraft:soul_sand)
B(3,55,-7,minecraft:soul_sand)
B(3,56,-7,minecraft:soul_sand)
B(3,57,-7,minecraft:soul_sand)
B(3,58,-7,minecraft:soul_sand)
B(3,59,-7,minecraft:soul_sand)
B(3,60,-7,minecraft:soul_sand)
B(3,61,-7,minecraft:soul_sand)
B(3,62,-7,minecraft:soul_sand)
B(3,63,-7,minecraft:soul_sand)
B(3,64,-7,minecraft:soul_sand)
B(3,65,-7,minecraft:soul_sand)
B(3,66,-7,minecraft:soul_sand)
B(3,53,-6,minecraft:soul_sand)
B(3,54,-6,minecraft:soul_sand)
B(3,55,-6,minecraft:soul_sand)
B(3,56,-6,minecraft:soul_sand)
B(3,57,-6,minecraft:soul_sand)
B(3,58,-6,minecraft:soul_sand)
B(3,59,-6,minecraft:soul_sand)
B(3,60,-6,minecraft:soul_sand)
B(3,61,-6,minecraft:soul_sand)
B(3,62,-6,minecraft:soul_sand)
B(3,63,-6,minecraft:soul_sand)
B(3,64,-6,minecraft:soul_sand)
B(3,65,-6,minecraft:soul_sand)
B(3,66,-6,minecraft:soul_sand)
B(3,53,-5,minecraft:soul_sand)
B(3,54,-5,minecraft:soul_sand)
B(3,55,-5,minecraft:soul_sand)
B(3,56,-5,minecraft:soul_sand)
B(3,57,-5,minecraft:soul_sand)
B(3,58,-5,minecraft:soul_sand)
B(3,59,-5,minecraft:soul_sand)
B(3,60,-5,minecraft:soul_sand)
B(3,61,-5,minecraft:soul_sand)
B(3,62,-5,minecraft:soul_sand)
B(3,63,-5,minecraft:soul_sand)
B(3,64,-5,minecraft:soul_sand)
B(3,65,-5,minecraft:soul_sand)
B(3,66,-5,minecraft:soul_sand)
B(3,54,-4,minecraft:soul_sand)
B(3,55,-4,minecraft:soul_sand)
B(3,56,-4,minecraft:soul_sand)
B(3,57,-4,minecraft:soul_sand)
B(3,58,-4,minecraft:soul_sand)
B(3,59,-4,minecraft:soul_sand)
B(3,60,-4,minecraft:soul_sand)
B(3,61,-4,minecraft:soul_sand)
B(3,62,-4,minecraft:soul_sand)
B(3,63,-4,minecraft:soul_sand)
B(3,64,-4,minecraft:soul_sand)
B(3,65,-4,minecraft:soul_sand)
B(3,66,-4,minecraft:soul_sand)
B(3,56,-3,minecraft:soul_sand)
B(3,57,-3,minecraft:soul_sand)
B(3,58,-3,minecraft:soul_sand)
B(3,59,-3,minecraft:soul_sand)
B(3,60,-3,minecraft:soul_sand)
B(3,61,-3,minecraft:soul_sand)
B(3,62,-3,minecraft:soul_sand)
B(3,63,-3,minecraft:soul_sand)
B(3,64,-3,minecraft:soul_sand)
B(3,65,-3,minecraft:soul_sand)
B(3,66,-3,minecraft:soul_sand)
B(3,59,-2,minecraft:soul_sand)
B(3,60,-2,minecraft:soul_sand)
B(3,61,-2,minecraft:soul_sand)
B(3,62,-2,minecraft:soul_sand)
B(3,63,-2,minecraft:soul_sand)
B(3,64,-2,minecraft:soul_sand)
B(3,65,-2,minecraft:soul_sand)
B(3,66,-2,minecraft:soul_sand)
B(3,59,-1,minecraft:soul_sand)
B(3,60,-1,minecraft:soul_sand)
B(3,61,-1,minecraft:soul_sand)
B(3,62,-1,minecraft:soul_sand)
B(3,63,-1,minecraft:soul_sand)
B(3,64,-1,minecraft:soul_sand)
B(3,65,-1,minecraft:soul_sand)
B(3,66,-1,minecraft:soul_sand)
B(3,60,0,minecraft:soul_sand)
B(3,61,0,minecraft:soul_sand)
B(3,62,0,minecraft:soul_sand)
B(3,63,0,minecraft:soul_sand)
B(3,64,0,minecraft:soul_sand)
B(3,65,0,minecraft:soul_sand)
B(3,66,0,minecraft:soul_sand)
B(3,60,1,minecraft:soul_sand)
B(3,61,1,minecraft:soul_sand)
B(3,62,1,minecraft:soul_sand)
B(3,63,1,minecraft:soul_sand)
B(3,64,1,minecraft:soul_sand)
B(3,65,1,minecraft:soul_sand)
B(3,66,1,minecraft:soul_sand)
B(3,60,2,minecraft:soul_sand)
B(3,61,2,minecraft:soul_sand)
B(3,62,2,minecraft:soul_sand)
B(3,63,2,minecraft:soul_sand)
B(3,64,2,minecraft:soul_sand)
B(3,65,2,minecraft:soul_sand)
B(3,66,2,minecraft:soul_sand)
B(3,61,3,minecraft:soul_sand)
B(3,62,3,minecraft:soul_sand)
B(3,63,3,minecraft:soul_sand)
B(3,64,3,minecraft:soul_sand)
B(3,65,3,minecraft:soul_sand)
B(3,66,3,minecraft:soul_sand)
B(3,62,4,minecraft:soul_sand)
B(3,63,4,minecraft:soul_sand)
B(3,64,4,minecraft:soul_sand)
B(3,65,4,minecraft:soul_sand)
B(3,66,4,minecraft:soul_sand)
B(3,63,5,minecraft:soul_sand)
B(3,64,5,minecraft:soul_sand)
B(3,65,5,minecraft:soul_sand)
B(3,66,5,minecraft:soul_sand)
B(3,64,6,minecraft:soul_sand)
B(3,65,6,minecraft:soul_sand)
B(3,66,6,minecraft:soul_sand)
B(3,64,7,minecraft:soul_sand)
B(3,65,7,minecraft:soul_sand)
B(3,66,7,minecraft:soul_sand)
B(3,64,8,minecraft:soul_sand)
B(3,65,8,minecraft:soul_sand)
B(3,66,8,minecraft:soul_sand)
B(4,53,-7,minecraft:soul_sand)
B(4,54,-7,minecraft:soul_sand)
B(4,55,-7,minecraft:soul_sand)
B(4,56,-7,minecraft:soul_sand)
B(4,57,-7,minecraft:soul_sand)
B(4,58,-7,minecraft:soul_sand)
B(4,59,-7,minecraft:soul_sand)
B(4,60,-7,minecraft:soul_sand)
B(4,61,-7,minecraft:soul_sand)
B(4,62,-7,minecraft:soul_sand)
B(4,63,-7,minecraft:soul_sand)
B(4,64,-7,minecraft:soul_sand)
B(4,65,-7,minecraft:soul_sand)
B(4,66,-7,minecraft:soul_sand)
B(4,53,-6,minecraft:soul_sand)
B(4,54,-6,minecraft:soul_sand)
B(4,55,-6,minecraft:soul_sand)
B(4,56,-6,minecraft:soul_sand)
B(4,57,-6,minecraft:soul_sand)
B(4,58,-6,minecraft:soul_sand)
B(4,59,-6,minecraft:soul_sand)
B(4,60,-6,minecraft:soul_sand)
B(4,61,-6,minecraft:soul_sand)
B(4,62,-6,minecraft:soul_sand)
B(4,63,-6,minecraft:soul_sand)
B(4,64,-6,minecraft:soul_sand)
B(4,65,-6,minecraft:soul_sand)
B(4,66,-6,minecraft:soul_sand)
B(4,53,-5,minecraft:soul_sand)
B(4,54,-5,minecraft:soul_sand)
B(4,55,-5,minecraft:soul_sand)
B(4,56,-5,minecraft:soul_sand)
B(4,57,-5,minecraft:soul_sand)
B(4,58,-5,minecraft:soul_sand)
B(4,59,-5,minecraft:soul_sand)
B(4,60,-5,minecraft:soul_sand)
B(4,61,-5,minecraft:soul_sand)
B(4,62,-5,minecraft:soul_sand)
B(4,63,-5,minecraft:soul_sand)
B(4,64,-5,minecraft:soul_sand)
B(4,65,-5,minecraft:soul_sand)
B(4,66,-5,minecraft:soul_sand)
B(4,54,-4,minecraft:soul_sand)
B(4,55,-4,minecraft:soul_sand)
B(4,56,-4,minecraft:soul_sand)
B(4,57,-4,minecraft:soul_sand)
B(4,58,-4,minecraft:soul_sand)
B(4,59,-4,minecraft:soul_sand)
B(4,60,-4,minecraft:soul_sand)
B(4,61,-4,minecraft:soul_sand)
B(4,62,-4,minecraft:soul_sand)
B(4,63,-4,minecraft:soul_sand)
B(4,64,-4,minecraft:soul_sand)
B(4,65,-4,minecraft:soul_sand)
B(4,66,-4,minecraft:soul_sand)
B(4,56,-3,minecraft:soul_sand)
B(4,57,-3,minecraft:soul_sand)
B(4,58,-3,minecraft:soul_sand)
B(4,59,-3,minecraft:soul_sand)
B(4,60,-3,minecraft:soul_sand)
B(4,61,-3,minecraft:soul_sand)
B(4,62,-3,minecraft:soul_sand)
B(4,63,-3,minecraft:soul_sand)
B(4,64,-3,minecraft:soul_sand)
B(4,65,-3,minecraft:soul_sand)
B(4,66,-3,minecraft:soul_sand)
B(4,59,-2,minecraft:soul_sand)
B(4,60,-2,minecraft:soul_sand)
B(4,61,-2,minecraft:soul_sand)
B(4,62,-2,minecraft:soul_sand)
B(4,63,-2,minecraft:soul_sand)
B(4,64,-2,minecraft:soul_sand)
B(4,65,-2,minecraft:soul_sand)
B(4,66,-2,minecraft:soul_sand)
B(4,60,-1,minecraft:soul_sand)
B(4,61,-1,minecraft:soul_sand)
B(4,62,-1,minecraft:soul_sand)
B(4,63,-1,minecraft:soul_sand)
B(4,64,-1,minecraft:soul_sand)
B(4,65,-1,minecraft:soul_sand)
B(4,66,-1,minecraft:soul_sand)
B(4,60,0,minecraft:soul_sand)
B(4,61,0,minecraft:soul_sand)
B(4,62,0,minecraft:soul_sand)
B(4,63,0,minecraft:soul_sand)
B(4,64,0,minecraft:soul_sand)
B(4,65,0,minecraft:soul_sand)
B(4,66,0,minecraft:soul_sand)
B(4,60,1,minecraft:soul_sand)
B(4,61,1,minecraft:soul_sand)
B(4,62,1,minecraft:soul_sand)
B(4,63,1,minecraft:soul_sand)
B(4,64,1,minecraft:soul_sand)
B(4,65,1,minecraft:soul_sand)
B(4,66,1,minecraft:soul_sand)
B(4,61,2,minecraft:soul_sand)
B(4,62,2,minecraft:soul_sand)
B(4,63,2,minecraft:soul_sand)
B(4,64,2,minecraft:soul_sand)
B(4,65,2,minecraft:soul_sand)
B(4,66,2,minecraft:soul_sand)
B(4,61,3,minecraft:soul_sand)
B(4,62,3,minecraft:soul_sand)
B(4,63,3,minecraft:soul_sand)
B(4,64,3,minecraft:soul_sand)
B(4,65,3,minecraft:soul_sand)
B(4,66,3,minecraft:soul_sand)
B(4,62,4,minecraft:soul_sand)
B(4,63,4,minecraft:soul_sand)
B(4,64,4,minecraft:soul_sand)
B(4,65,4,minecraft:soul_sand)
B(4,66,4,minecraft:soul_sand)
B(4,62,5,minecraft:soul_sand)
B(4,63,5,minecraft:soul_sand)
B(4,64,5,minecraft:soul_sand)
B(4,65,5,minecraft:soul_sand)
B(4,66,5,minecraft:soul_sand)
B(4,64,6,minecraft:soul_sand)
B(4,65,6,minecraft:soul_sand)
B(4,66,6,minecraft:soul_sand)
B(4,64,7,minecraft:soul_sand)
B(4,65,7,minecraft:soul_sand)
B(4,66,7,minecraft:soul_sand)
B(4,64,8,minecraft:soul_sand)
B(4,65,8,minecraft:soul_sand)
B(4,66,8,minecraft:soul_sand)
B(5,53,-7,minecraft:soul_sand)
B(5,54,-7,minecraft:soul_sand)
B(5,55,-7,minecraft:soul_sand)
B(5,56,-7,minecraft:soul_sand)
B(5,57,-7,minecraft:soul_sand)
B(5,58,-7,minecraft:soul_sand)
B(5,59,-7,minecraft:soul_sand)
B(5,60,-7,minecraft:soul_sand)
B(5,61,-7,minecraft:soul_sand)
B(5,62,-7,minecraft:soul_sand)
B(5,63,-7,minecraft:soul_sand)
B(5,64,-7,minecraft:soul_sand)
B(5,65,-7,minecraft:soul_sand)
B(5,66,-7,minecraft:soul_sand)
B(5,53,-6,minecraft:soul_sand)
B(5,54,-6,minecraft:soul_sand)
B(5,55,-6,minecraft:soul_sand)
B(5,56,-6,minecraft:soul_sand)
B(5,57,-6,minecraft:soul_sand)
B(5,58,-6,minecraft:soul_sand)
B(5,59,-6,minecraft:soul_sand)
B(5,60,-6,minecraft:soul_sand)
B(5,61,-6,minecraft:soul_sand)
B(5,62,-6,minecraft:soul_sand)
B(5,63,-6,minecraft:soul_sand)
B(5,64,-6,minecraft:soul_sand)
B(5,65,-6,minecraft:soul_sand)
B(5,66,-6,minecraft:soul_sand)
B(5,53,-5,minecraft:soul_sand)
B(5,54,-5,minecraft:soul_sand)
B(5,55,-5,minecraft:soul_sand)
B(5,56,-5,minecraft:soul_sand)
B(5,57,-5,minecraft:soul_sand)
B(5,58,-5,minecraft:soul_sand)
B(5,59,-5,minecraft:soul_sand)
B(5,60,-5,minecraft:soul_sand)
B(5,61,-5,minecraft:soul_sand)
B(5,62,-5,minecraft:soul_sand)
B(5,63,-5,minecraft:soul_sand)
B(5,64,-5,minecraft:soul_sand)
B(5,65,-5,minecraft:soul_sand)
B(5,66,-5,minecraft:soul_sand)
B(5,54,-4,minecraft:soul_sand)
B(5,55,-4,minecraft:soul_sand)
B(5,56,-4,minecraft:soul_sand)
B(5,57,-4,minecraft:soul_sand)
B(5,58,-4,minecraft:soul_sand)
B(5,59,-4,minecraft:soul_sand)
B(5,60,-4,minecraft:soul_sand)
B(5,61,-4,minecraft:soul_sand)
B(5,62,-4,minecraft:soul_sand)
B(5,63,-4,minecraft:soul_sand)
B(5,64,-4,minecraft:soul_sand)
B(5,65,-4,minecraft:soul_sand)
B(5,66,-4,minecraft:soul_sand)
B(5,56,-3,minecraft:soul_sand)
B(5,57,-3,minecraft:soul_sand)
B(5,58,-3,minecraft:soul_sand)
B(5,59,-3,minecraft:soul_sand)
B(5,60,-3,minecraft:soul_sand)
B(5,61,-3,minecraft:soul_sand)
B(5,62,-3,minecraft:soul_sand)
B(5,63,-3,minecraft:soul_sand)
B(5,64,-3,minecraft:soul_sand)
B(5,65,-3,minecraft:soul_sand)
B(5,66,-3,minecraft:soul_sand)
B(5,56,-2,minecraft:soul_sand)
B(5,57,-2,minecraft:soul_sand)
B(5,58,-2,minecraft:soul_sand)
B(5,59,-2,minecraft:soul_sand)
B(5,60,-2,minecraft:soul_sand)
B(5,61,-2,minecraft:soul_sand)
B(5,62,-2,minecraft:soul_sand)
B(5,63,-2,minecraft:soul_sand)
B(5,64,-2,minecraft:soul_sand)
B(5,65,-2,minecraft:soul_sand)
B(5,66,-2,minecraft:soul_sand)
B(5,57,-1,minecraft:soul_sand)
B(5,58,-1,minecraft:soul_sand)
B(5,59,-1,minecraft:soul_sand)
B(5,60,-1,minecraft:soul_sand)
B(5,61,-1,minecraft:soul_sand)
B(5,62,-1,minecraft:soul_sand)
B(5,63,-1,minecraft:soul_sand)
B(5,64,-1,minecraft:soul_sand)
B(5,65,-1,minecraft:soul_sand)
B(5,66,-1,minecraft:soul_sand)
B(5,59,0,minecraft:soul_sand)
B(5,60,0,minecraft:soul_sand)
B(5,61,0,minecraft:soul_sand)
B(5,62,0,minecraft:soul_sand)
B(5,63,0,minecraft:soul_sand)
B(5,64,0,minecraft:soul_sand)
B(5,65,0,minecraft:soul_sand)
B(5,66,0,minecraft:soul_sand)
B(5,60,1,minecraft:soul_sand)
B(5,61,1,minecraft:soul_sand)
B(5,62,1,minecraft:soul_sand)
B(5,63,1,minecraft:soul_sand)
B(5,64,1,minecraft:soul_sand)
B(5,65,1,minecraft:soul_sand)
B(5,66,1,minecraft:soul_sand)
B(5,61,2,minecraft:soul_sand)
B(5,62,2,minecraft:soul_sand)
B(5,63,2,minecraft:soul_sand)
B(5,64,2,minecraft:soul_sand)
B(5,65,2,minecraft:soul_sand)
B(5,66,2,minecraft:soul_sand)
B(5,61,3,minecraft:soul_sand)
B(5,62,3,minecraft:soul_sand)
B(5,63,3,minecraft:soul_sand)
B(5,64,3,minecraft:soul_sand)
B(5,65,3,minecraft:soul_sand)
B(5,66,3,minecraft:soul_sand)
B(5,62,4,minecraft:soul_sand)
B(5,63,4,minecraft:soul_sand)
B(5,64,4,minecraft:soul_sand)
B(5,65,4,minecraft:soul_sand)
B(5,66,4,minecraft:soul_sand)
B(5,62,5,minecraft:soul_sand)
B(5,63,5,minecraft:soul_sand)
B(5,64,5,minecraft:soul_sand)
B(5,65,5,minecraft:soul_sand)
B(5,66,5,minecraft:soul_sand)
B(5,64,6,minecraft:soul_sand)
B(5,65,6,minecraft:soul_sand)
B(5,66,6,minecraft:soul_sand)
B(5,64,7,minecraft:soul_sand)
B(5,65,7,minecraft:soul_sand)
B(5,66,7,minecraft:soul_sand)
B(5,64,8,minecraft:soul_sand)
B(5,65,8,minecraft:soul_sand)
B(5,66,8,minecraft:soul_sand)
B(6,54,-7,minecraft:soul_sand)
B(6,55,-7,minecraft:soul_sand)
B(6,56,-7,minecraft:soul_sand)
B(6,57,-7,minecraft:soul_sand)
B(6,58,-7,minecraft:soul_sand)
B(6,59,-7,minecraft:soul_sand)
B(6,60,-7,minecraft:soul_sand)
B(6,61,-7,minecraft:soul_sand)
B(6,62,-7,minecraft:soul_sand)
B(6,63,-7,minecraft:soul_sand)
B(6,64,-7,minecraft:soul_sand)
B(6,65,-7,minecraft:soul_sand)
B(6,66,-7,minecraft:soul_sand)
B(6,54,-6,minecraft:soul_sand)
B(6,55,-6,minecraft:soul_sand)
B(6,56,-6,minecraft:soul_sand)
B(6,57,-6,minecraft:soul_sand)
B(6,58,-6,minecraft:soul_sand)
B(6,59,-6,minecraft:soul_sand)
B(6,60,-6,minecraft:soul_sand)
B(6,61,-6,minecraft:soul_sand)
B(6,62,-6,minecraft:soul_sand)
B(6,63,-6,minecraft:soul_sand)
B(6,64,-6,minecraft:soul_sand)
B(6,65,-6,minecraft:soul_sand)
B(6,66,-6,minecraft:soul_sand)
B(6,55,-5,minecraft:soul_sand)
B(6,56,-5,minecraft:soul_sand)
B(6,57,-5,minecraft:soul_sand)
B(6,58,-5,minecraft:soul_sand)
B(6,59,-5,minecraft:soul_sand)
B(6,60,-5,minecraft:soul_sand)
B(6,61,-5,minecraft:soul_sand)
B(6,62,-5,minecraft:soul_sand)
B(6,63,-5,minecraft:soul_sand)
B(6,64,-5,minecraft:soul_sand)
B(6,65,-5,minecraft:soul_sand)
B(6,66,-5,minecraft:soul_sand)
B(6,56,-4,minecraft:soul_sand)
B(6,57,-4,minecraft:soul_sand)
B(6,58,-4,minecraft:soul_sand)
B(6,59,-4,minecraft:soul_sand)
B(6,60,-4,minecraft:soul_sand)
B(6,61,-4,minecraft:soul_sand)
B(6,62,-4,minecraft:soul_sand)
B(6,63,-4,minecraft:soul_sand)
B(6,64,-4,minecraft:soul_sand)
B(6,65,-4,minecraft:soul_sand)
B(6,66,-4,minecraft:soul_sand)
B(6,56,-3,minecraft:soul_sand)
B(6,57,-3,minecraft:soul_sand)
B(6,58,-3,minecraft:soul_sand)
B(6,59,-3,minecraft:soul_sand)
B(6,60,-3,minecraft:soul_sand)
B(6,61,-3,minecraft:soul_sand)
B(6,62,-3,minecraft:soul_sand)
B(6,63,-3,minecraft:soul_sand)
B(6,64,-3,minecraft:soul_sand)
B(6,65,-3,minecraft:soul_sand)
B(6,66,-3,minecraft:soul_sand)
B(6,57,-2,minecraft:soul_sand)
B(6,58,-2,minecraft:soul_sand)
B(6,59,-2,minecraft:soul_sand)
B(6,60,-2,minecraft:soul_sand)
B(6,61,-2,minecraft:soul_sand)
B(6,62,-2,minecraft:soul_sand)
B(6,63,-2,minecraft:soul_sand)
B(6,64,-2,minecraft:soul_sand)
B(6,65,-2,minecraft:soul_sand)
B(6,66,-2,minecraft:soul_sand)
B(6,58,-1,minecraft:soul_sand)
B(6,59,-1,minecraft:soul_sand)
B(6,60,-1,minecraft:soul_sand)
B(6,61,-1,minecraft:soul_sand)
B(6,62,-1,minecraft:soul_sand)
B(6,63,-1,minecraft:soul_sand)
B(6,64,-1,minecraft:soul_sand)
B(6,65,-1,minecraft:soul_sand)
B(6,66,-1,minecraft:soul_sand)
B(6,59,0,minecraft:soul_sand)
B(6,60,0,minecraft:soul_sand)
B(6,61,0,minecraft:soul_sand)
B(6,62,0,minecraft:soul_sand)
B(6,63,0,minecraft:soul_sand)
B(6,64,0,minecraft:soul_sand)
B(6,65,0,minecraft:soul_sand)
B(6,66,0,minecraft:soul_sand)
B(6,60,1,minecraft:soul_sand)
B(6,61,1,minecraft:soul_sand)
B(6,62,1,minecraft:soul_sand)
B(6,63,1,minecraft:soul_sand)
B(6,64,1,minecraft:soul_sand)
B(6,65,1,minecraft:soul_sand)
B(6,66,1,minecraft:soul_sand)
B(6,61,2,minecraft:soul_sand)
B(6,62,2,minecraft:soul_sand)
B(6,63,2,minecraft:soul_sand)
B(6,64,2,minecraft:soul_sand)
B(6,65,2,minecraft:soul_sand)
B(6,66,2,minecraft:soul_sand)
B(6,62,3,minecraft:soul_sand)
B(6,63,3,minecraft:soul_sand)
B(6,64,3,minecraft:soul_sand)
B(6,65,3,minecraft:soul_sand)
B(6,66,3,minecraft:soul_sand)
B(6,62,4,minecraft:soul_sand)
B(6,63,4,minecraft:soul_sand)
B(6,64,4,minecraft:soul_sand)
B(6,65,4,minecraft:soul_sand)
B(6,66,4,minecraft:soul_sand)
B(6,63,5,minecraft:soul_sand)
B(6,64,5,minecraft:soul_sand)
B(6,65,5,minecraft:soul_sand)
B(6,66,5,minecraft:soul_sand)
B(6,64,6,minecraft:soul_sand)
B(6,65,6,minecraft:soul_sand)
B(6,66,6,minecraft:soul_sand)
B(6,65,7,minecraft:soul_sand)
B(6,66,7,minecraft:soul_sand)
B(6,65,8,minecraft:soul_sand)
B(6,66,8,minecraft:soul_sand)
B(7,54,-7,minecraft:soul_sand)
B(7,55,-7,minecraft:soul_sand)
B(7,56,-7,minecraft:soul_sand)
B(7,57,-7,minecraft:soul_sand)
B(7,58,-7,minecraft:soul_sand)
B(7,59,-7,minecraft:soul_sand)
B(7,60,-7,minecraft:soul_sand)
B(7,61,-7,minecraft:soul_sand)
B(7,62,-7,minecraft:soul_sand)
B(7,63,-7,minecraft:soul_sand)
B(7,64,-7,minecraft:soul_sand)
B(7,65,-7,minecraft:soul_sand)
B(7,66,-7,minecraft:soul_sand)
B(7,55,-6,minecraft:soul_sand)
B(7,56,-6,minecraft:soul_sand)
B(7,57,-6,minecraft:soul_sand)
B(7,58,-6,minecraft:soul_sand)
B(7,59,-6,minecraft:soul_sand)
B(7,60,-6,minecraft:soul_sand)
B(7,61,-6,minecraft:soul_sand)
B(7,62,-6,minecraft:soul_sand)
B(7,63,-6,minecraft:soul_sand)
B(7,64,-6,minecraft:soul_sand)
B(7,65,-6,minecraft:soul_sand)
B(7,66,-6,minecraft:soul_sand)
B(7,55,-5,minecraft:soul_sand)
B(7,56,-5,minecraft:soul_sand)
B(7,57,-5,minecraft:soul_sand)
B(7,58,-5,minecraft:soul_sand)
B(7,59,-5,minecraft:soul_sand)
B(7,60,-5,minecraft:soul_sand)
B(7,61,-5,minecraft:soul_sand)
B(7,62,-5,minecraft:soul_sand)
B(7,63,-5,minecraft:soul_sand)
B(7,64,-5,minecraft:soul_sand)
B(7,65,-5,minecraft:soul_sand)
B(7,66,-5,minecraft:soul_sand)
B(7,56,-4,minecraft:soul_sand)
B(7,57,-4,minecraft:soul_sand)
B(7,58,-4,minecraft:soul_sand)
B(7,59,-4,minecraft:soul_sand)
B(7,60,-4,minecraft:soul_sand)
B(7,61,-4,minecraft:soul_sand)
B(7,62,-4,minecraft:soul_sand)
B(7,63,-4,minecraft:soul_sand)
B(7,64,-4,minecraft:soul_sand)
B(7,65,-4,minecraft:soul_sand)
B(7,66,-4,minecraft:soul_sand)
B(7,57,-3,minecraft:soul_sand)
B(7,58,-3,minecraft:soul_sand)
B(7,59,-3,minecraft:soul_sand)
B(7,60,-3,minecraft:soul_sand)
B(7,61,-3,minecraft:soul_sand)
B(7,62,-3,minecraft:soul_sand)
B(7,63,-3,minecraft:soul_sand)
B(7,64,-3,minecraft:soul_sand)
B(7,65,-3,minecraft:soul_sand)
B(7,66,-3,minecraft:soul_sand)
B(7,57,-2,minecraft:soul_sand)
B(7,58,-2,minecraft:soul_sand)
B(7,59,-2,minecraft:soul_sand)
B(7,60,-2,minecraft:soul_sand)
B(7,61,-2,minecraft:soul_sand)
B(7,62,-2,minecraft:soul_sand)
B(7,63,-2,minecraft:soul_sand)
B(7,64,-2,minecraft:soul_sand)
B(7,65,-2,minecraft:soul_sand)
B(7,66,-2,minecraft:soul_sand)
B(7,58,-1,minecraft:soul_sand)
B(7,59,-1,minecraft:soul_sand)
B(7,60,-1,minecraft:soul_sand)
B(7,61,-1,minecraft:soul_sand)
B(7,62,-1,minecraft:soul_sand)
B(7,63,-1,minecraft:soul_sand)
B(7,64,-1,minecraft:soul_sand)
B(7,65,-1,minecraft:soul_sand)
B(7,66,-1,minecraft:soul_sand)
B(7,59,0,minecraft:soul_sand)
B(7,60,0,minecraft:soul_sand)
B(7,61,0,minecraft:soul_sand)
B(7,62,0,minecraft:soul_sand)
B(7,63,0,minecraft:soul_sand)
B(7,64,0,minecraft:soul_sand)
B(7,65,0,minecraft:soul_sand)
B(7,66,0,minecraft:soul_sand)
B(7,60,1,minecraft:soul_sand)
B(7,61,1,minecraft:soul_sand)
B(7,62,1,minecraft:soul_sand)
B(7,63,1,minecraft:soul_sand)
B(7,64,1,minecraft:soul_sand)
B(7,65,1,minecraft:soul_sand)
B(7,66,1,minecraft:soul_sand)
B(7,61,2,minecraft:soul_sand)
B(7,62,2,minecraft:soul_sand)
B(7,63,2,minecraft:soul_sand)
B(7,64,2,minecraft:soul_sand)
B(7,65,2,minecraft:soul_sand)
B(7,66,2,minecraft:soul_sand)
B(7,62,3,minecraft:soul_sand)
B(7,63,3,minecraft:soul_sand)
B(7,64,3,minecraft:soul_sand)
B(7,65,3,minecraft:soul_sand)
B(7,66,3,minecraft:soul_sand)
B(7,63,4,minecraft:soul_sand)
B(7,64,4,minecraft:soul_sand)
B(7,65,4,minecraft:soul_sand)
B(7,66,4,minecraft:soul_sand)
B(7,63,5,minecraft:soul_sand)
B(7,64,5,minecraft:soul_sand)
B(7,65,5,minecraft:soul_sand)
B(7,66,5,minecraft:soul_sand)
B(7,65,6,minecraft:soul_sand)
B(7,66,6,minecraft:soul_sand)
B(7,65,7,minecraft:soul_sand)
B(7,66,7,minecraft:soul_sand)
B(7,66,8,minecraft:soul_sand)

#######################################################################
# +-----------------------------------------------------------------+ #
# |                             Branches                            | #
# +-----------------------------------------------------------------+ #
#######################################################################

Branch(16,0,0,true,GiantSoulSandStalactite2_C3_R3,NORTH,100.0,0)
Branch(0,0,16,true,GiantSoulSandStalactite2_C2_R4,NORTH,100.0,0)

#######################################################################
# +-----------------------------------------------------------------+ #
# |                             Entities                            | #
# +-----------------------------------------------------------------+ #
#######################################################################

