
#######################################################################
# +-----------------------------------------------------------------+ #
# |                            BO4 object                           | #
# +-----------------------------------------------------------------+ #
#######################################################################

Author: Unknown

Description: No description given

SettingsMode: WriteWithoutComments


#######################################################################
# +-----------------------------------------------------------------+ #
# |                          Main settings                          | #
# +-----------------------------------------------------------------+ #
#######################################################################

FixedRotation: 

Frequency: 0

SpawnHeight: highestBlock

UseCenterForHighestBlock: true

##############################
# Height Limits for the BO4. #
##############################

MinHeight: 0

MaxHeight: 255

InheritBO3: 

InheritBO3Rotation: NORTH

OverrideChildSettings: true

OverrideParentHeight: false

CanOverride: false

BranchFrequency: 0

BranchFrequencyGroup: 

MustBeBelowOther: false

MustBeInside: 

CannotBeInside: 

ReplacesBO3: 

MustBeInsideWorldBorders: false

CanSpawnOnWater: true

SpawnOnWaterOnly: false

SpawnUnderWater: false

SpawnAtWaterLevel: false

HeightOffset: 0

RemoveAir: true

ReplaceAbove: 

ReplaceBelow: 

ReplaceWithBiomeBlocks: true

ReplaceWithSurfaceBlock: GRASS

ReplaceWithGroundBlock: DIRT

ReplaceWithStoneBlock: STONE

SmoothRadius: 0

SmoothHeightOffset: 0

SmoothStartTop: false

SmoothStartWood: false

SmoothingSurfaceBlock: 

SmoothingGroundBlock: 

BO3Group: 

IsSpawnPoint: false

DoReplaceBlocks: true


#######################################################################
# +-----------------------------------------------------------------+ #
# |                              Blocks                             | #
# +-----------------------------------------------------------------+ #
#######################################################################

B(-8,0,-7,minecraft:soul_sand)
B(-8,1,-7,minecraft:soul_sand)
B(-8,2,-7,minecraft:soul_sand)
B(-8,3,-7,minecraft:soul_sand)
B(-8,4,-7,minecraft:soul_sand)
B(-8,5,-7,minecraft:soul_sand)
B(-8,6,-7,minecraft:soul_sand)
B(-8,7,-7,minecraft:soul_sand)
B(-8,8,-7,minecraft:soul_sand)
B(-8,9,-7,minecraft:soul_sand)
B(-8,10,-7,minecraft:soul_sand)
B(-8,11,-7,minecraft:soul_sand)
B(-8,12,-7,minecraft:soul_sand)
B(-8,13,-7,minecraft:soul_sand)
B(-8,14,-7,minecraft:soul_sand)
B(-8,15,-7,minecraft:soul_sand)
B(-8,16,-7,minecraft:soul_sand)
B(-8,17,-7,minecraft:soul_sand)
B(-8,18,-7,minecraft:soul_sand)
B(-8,19,-7,minecraft:soul_sand)
B(-8,20,-7,minecraft:soul_sand)
B(-8,21,-7,minecraft:soul_sand)
B(-8,22,-7,minecraft:soul_sand)
B(-8,23,-7,minecraft:soul_sand)
B(-8,83,-7,minecraft:soul_sand)
B(-8,84,-7,minecraft:soul_sand)
B(-8,85,-7,minecraft:soul_sand)
B(-8,86,-7,minecraft:soul_sand)
B(-8,87,-7,minecraft:soul_sand)
B(-8,88,-7,minecraft:soul_sand)
B(-8,89,-7,minecraft:soul_sand)
B(-8,90,-7,minecraft:soul_sand)
B(-8,91,-7,minecraft:soul_sand)
B(-8,92,-7,minecraft:soul_sand)
B(-8,93,-7,minecraft:soul_sand)
B(-8,94,-7,minecraft:soul_sand)
B(-8,95,-7,minecraft:soul_sand)
B(-8,96,-7,minecraft:soul_sand)
B(-8,97,-7,minecraft:soul_sand)
B(-8,98,-7,minecraft:soul_sand)
B(-8,99,-7,minecraft:soul_sand)
B(-8,100,-7,minecraft:soul_sand)
B(-8,101,-7,minecraft:soul_sand)
B(-8,102,-7,minecraft:soul_sand)
B(-8,103,-7,minecraft:soul_sand)
B(-8,104,-7,minecraft:soul_sand)
B(-8,105,-7,minecraft:soul_sand)
B(-8,106,-7,minecraft:soul_sand)
B(-8,107,-7,minecraft:soul_sand)
B(-8,108,-7,minecraft:soul_sand)
B(-8,109,-7,minecraft:soul_sand)
B(-8,110,-7,minecraft:soul_sand)
B(-8,111,-7,minecraft:soul_sand)
B(-8,112,-7,minecraft:soul_sand)
B(-8,113,-7,minecraft:soul_sand)
B(-8,114,-7,minecraft:soul_sand)
B(-8,115,-7,minecraft:soul_sand)
B(-8,116,-7,minecraft:soul_sand)
B(-8,0,-6,minecraft:soul_sand)
B(-8,1,-6,minecraft:soul_sand)
B(-8,2,-6,minecraft:soul_sand)
B(-8,3,-6,minecraft:soul_sand)
B(-8,4,-6,minecraft:soul_sand)
B(-8,5,-6,minecraft:soul_sand)
B(-8,6,-6,minecraft:soul_sand)
B(-8,7,-6,minecraft:soul_sand)
B(-8,8,-6,minecraft:soul_sand)
B(-8,9,-6,minecraft:soul_sand)
B(-8,10,-6,minecraft:soul_sand)
B(-8,11,-6,minecraft:soul_sand)
B(-8,12,-6,minecraft:soul_sand)
B(-8,13,-6,minecraft:soul_sand)
B(-8,14,-6,minecraft:soul_sand)
B(-8,15,-6,minecraft:soul_sand)
B(-8,16,-6,minecraft:soul_sand)
B(-8,17,-6,minecraft:soul_sand)
B(-8,18,-6,minecraft:soul_sand)
B(-8,19,-6,minecraft:soul_sand)
B(-8,20,-6,minecraft:soul_sand)
B(-8,21,-6,minecraft:soul_sand)
B(-8,22,-6,minecraft:soul_sand)
B(-8,23,-6,minecraft:soul_sand)
B(-8,24,-6,minecraft:soul_sand)
B(-8,25,-6,minecraft:soul_sand)
B(-8,83,-6,minecraft:soul_sand)
B(-8,84,-6,minecraft:soul_sand)
B(-8,85,-6,minecraft:soul_sand)
B(-8,86,-6,minecraft:soul_sand)
B(-8,87,-6,minecraft:soul_sand)
B(-8,88,-6,minecraft:soul_sand)
B(-8,89,-6,minecraft:soul_sand)
B(-8,90,-6,minecraft:soul_sand)
B(-8,91,-6,minecraft:soul_sand)
B(-8,92,-6,minecraft:soul_sand)
B(-8,93,-6,minecraft:soul_sand)
B(-8,94,-6,minecraft:soul_sand)
B(-8,95,-6,minecraft:soul_sand)
B(-8,96,-6,minecraft:soul_sand)
B(-8,97,-6,minecraft:soul_sand)
B(-8,98,-6,minecraft:soul_sand)
B(-8,99,-6,minecraft:soul_sand)
B(-8,100,-6,minecraft:soul_sand)
B(-8,101,-6,minecraft:soul_sand)
B(-8,102,-6,minecraft:soul_sand)
B(-8,103,-6,minecraft:soul_sand)
B(-8,104,-6,minecraft:soul_sand)
B(-8,105,-6,minecraft:soul_sand)
B(-8,106,-6,minecraft:soul_sand)
B(-8,107,-6,minecraft:soul_sand)
B(-8,108,-6,minecraft:soul_sand)
B(-8,109,-6,minecraft:soul_sand)
B(-8,110,-6,minecraft:soul_sand)
B(-8,111,-6,minecraft:soul_sand)
B(-8,112,-6,minecraft:soul_sand)
B(-8,113,-6,minecraft:soul_sand)
B(-8,114,-6,minecraft:soul_sand)
B(-8,115,-6,minecraft:soul_sand)
B(-8,116,-6,minecraft:soul_sand)
B(-8,0,-5,minecraft:soul_sand)
B(-8,1,-5,minecraft:soul_sand)
B(-8,2,-5,minecraft:soul_sand)
B(-8,3,-5,minecraft:soul_sand)
B(-8,4,-5,minecraft:soul_sand)
B(-8,5,-5,minecraft:soul_sand)
B(-8,6,-5,minecraft:soul_sand)
B(-8,7,-5,minecraft:soul_sand)
B(-8,8,-5,minecraft:soul_sand)
B(-8,9,-5,minecraft:soul_sand)
B(-8,10,-5,minecraft:soul_sand)
B(-8,11,-5,minecraft:soul_sand)
B(-8,12,-5,minecraft:soul_sand)
B(-8,13,-5,minecraft:soul_sand)
B(-8,14,-5,minecraft:soul_sand)
B(-8,15,-5,minecraft:soul_sand)
B(-8,16,-5,minecraft:soul_sand)
B(-8,17,-5,minecraft:soul_sand)
B(-8,18,-5,minecraft:soul_sand)
B(-8,19,-5,minecraft:soul_sand)
B(-8,20,-5,minecraft:soul_sand)
B(-8,21,-5,minecraft:soul_sand)
B(-8,22,-5,minecraft:soul_sand)
B(-8,23,-5,minecraft:soul_sand)
B(-8,24,-5,minecraft:soul_sand)
B(-8,25,-5,minecraft:soul_sand)
B(-8,26,-5,minecraft:soul_sand)
B(-8,27,-5,minecraft:soul_sand)
B(-8,84,-5,minecraft:soul_sand)
B(-8,85,-5,minecraft:soul_sand)
B(-8,86,-5,minecraft:soul_sand)
B(-8,87,-5,minecraft:soul_sand)
B(-8,88,-5,minecraft:soul_sand)
B(-8,89,-5,minecraft:soul_sand)
B(-8,90,-5,minecraft:soul_sand)
B(-8,91,-5,minecraft:soul_sand)
B(-8,92,-5,minecraft:soul_sand)
B(-8,93,-5,minecraft:soul_sand)
B(-8,94,-5,minecraft:soul_sand)
B(-8,95,-5,minecraft:soul_sand)
B(-8,96,-5,minecraft:soul_sand)
B(-8,97,-5,minecraft:soul_sand)
B(-8,98,-5,minecraft:soul_sand)
B(-8,99,-5,minecraft:soul_sand)
B(-8,100,-5,minecraft:soul_sand)
B(-8,101,-5,minecraft:soul_sand)
B(-8,102,-5,minecraft:soul_sand)
B(-8,103,-5,minecraft:soul_sand)
B(-8,104,-5,minecraft:soul_sand)
B(-8,105,-5,minecraft:soul_sand)
B(-8,106,-5,minecraft:soul_sand)
B(-8,107,-5,minecraft:soul_sand)
B(-8,108,-5,minecraft:soul_sand)
B(-8,109,-5,minecraft:soul_sand)
B(-8,110,-5,minecraft:soul_sand)
B(-8,111,-5,minecraft:soul_sand)
B(-8,112,-5,minecraft:soul_sand)
B(-8,113,-5,minecraft:soul_sand)
B(-8,114,-5,minecraft:soul_sand)
B(-8,115,-5,minecraft:soul_sand)
B(-8,116,-5,minecraft:soul_sand)
B(-8,0,-4,minecraft:soul_sand)
B(-8,1,-4,minecraft:soul_sand)
B(-8,2,-4,minecraft:soul_sand)
B(-8,3,-4,minecraft:soul_sand)
B(-8,4,-4,minecraft:soul_sand)
B(-8,5,-4,minecraft:soul_sand)
B(-8,6,-4,minecraft:soul_sand)
B(-8,7,-4,minecraft:soul_sand)
B(-8,8,-4,minecraft:soul_sand)
B(-8,9,-4,minecraft:soul_sand)
B(-8,10,-4,minecraft:soul_sand)
B(-8,11,-4,minecraft:soul_sand)
B(-8,12,-4,minecraft:soul_sand)
B(-8,13,-4,minecraft:soul_sand)
B(-8,14,-4,minecraft:soul_sand)
B(-8,15,-4,minecraft:soul_sand)
B(-8,16,-4,minecraft:soul_sand)
B(-8,17,-4,minecraft:soul_sand)
B(-8,18,-4,minecraft:soul_sand)
B(-8,19,-4,minecraft:soul_sand)
B(-8,20,-4,minecraft:soul_sand)
B(-8,21,-4,minecraft:soul_sand)
B(-8,22,-4,minecraft:soul_sand)
B(-8,23,-4,minecraft:soul_sand)
B(-8,24,-4,minecraft:soul_sand)
B(-8,25,-4,minecraft:soul_sand)
B(-8,26,-4,minecraft:soul_sand)
B(-8,27,-4,minecraft:soul_sand)
B(-8,28,-4,minecraft:soul_sand)
B(-8,85,-4,minecraft:soul_sand)
B(-8,86,-4,minecraft:soul_sand)
B(-8,87,-4,minecraft:soul_sand)
B(-8,88,-4,minecraft:soul_sand)
B(-8,89,-4,minecraft:soul_sand)
B(-8,90,-4,minecraft:soul_sand)
B(-8,91,-4,minecraft:soul_sand)
B(-8,92,-4,minecraft:soul_sand)
B(-8,93,-4,minecraft:soul_sand)
B(-8,94,-4,minecraft:soul_sand)
B(-8,95,-4,minecraft:soul_sand)
B(-8,96,-4,minecraft:soul_sand)
B(-8,97,-4,minecraft:soul_sand)
B(-8,98,-4,minecraft:soul_sand)
B(-8,99,-4,minecraft:soul_sand)
B(-8,100,-4,minecraft:soul_sand)
B(-8,101,-4,minecraft:soul_sand)
B(-8,102,-4,minecraft:soul_sand)
B(-8,103,-4,minecraft:soul_sand)
B(-8,104,-4,minecraft:soul_sand)
B(-8,105,-4,minecraft:soul_sand)
B(-8,106,-4,minecraft:soul_sand)
B(-8,107,-4,minecraft:soul_sand)
B(-8,108,-4,minecraft:soul_sand)
B(-8,109,-4,minecraft:soul_sand)
B(-8,110,-4,minecraft:soul_sand)
B(-8,111,-4,minecraft:soul_sand)
B(-8,112,-4,minecraft:soul_sand)
B(-8,113,-4,minecraft:soul_sand)
B(-8,114,-4,minecraft:soul_sand)
B(-8,115,-4,minecraft:soul_sand)
B(-8,116,-4,minecraft:soul_sand)
B(-8,0,-3,minecraft:soul_sand)
B(-8,1,-3,minecraft:soul_sand)
B(-8,2,-3,minecraft:soul_sand)
B(-8,3,-3,minecraft:soul_sand)
B(-8,4,-3,minecraft:soul_sand)
B(-8,5,-3,minecraft:soul_sand)
B(-8,6,-3,minecraft:soul_sand)
B(-8,7,-3,minecraft:soul_sand)
B(-8,8,-3,minecraft:soul_sand)
B(-8,9,-3,minecraft:soul_sand)
B(-8,10,-3,minecraft:soul_sand)
B(-8,11,-3,minecraft:soul_sand)
B(-8,12,-3,minecraft:soul_sand)
B(-8,13,-3,minecraft:soul_sand)
B(-8,14,-3,minecraft:soul_sand)
B(-8,15,-3,minecraft:soul_sand)
B(-8,16,-3,minecraft:soul_sand)
B(-8,17,-3,minecraft:soul_sand)
B(-8,18,-3,minecraft:soul_sand)
B(-8,19,-3,minecraft:soul_sand)
B(-8,20,-3,minecraft:soul_sand)
B(-8,21,-3,minecraft:soul_sand)
B(-8,22,-3,minecraft:soul_sand)
B(-8,23,-3,minecraft:soul_sand)
B(-8,24,-3,minecraft:soul_sand)
B(-8,25,-3,minecraft:soul_sand)
B(-8,26,-3,minecraft:soul_sand)
B(-8,27,-3,minecraft:soul_sand)
B(-8,28,-3,minecraft:soul_sand)
B(-8,85,-3,minecraft:soul_sand)
B(-8,86,-3,minecraft:soul_sand)
B(-8,87,-3,minecraft:soul_sand)
B(-8,88,-3,minecraft:soul_sand)
B(-8,89,-3,minecraft:soul_sand)
B(-8,90,-3,minecraft:soul_sand)
B(-8,91,-3,minecraft:soul_sand)
B(-8,92,-3,minecraft:soul_sand)
B(-8,93,-3,minecraft:soul_sand)
B(-8,94,-3,minecraft:soul_sand)
B(-8,95,-3,minecraft:soul_sand)
B(-8,96,-3,minecraft:soul_sand)
B(-8,97,-3,minecraft:soul_sand)
B(-8,98,-3,minecraft:soul_sand)
B(-8,99,-3,minecraft:soul_sand)
B(-8,100,-3,minecraft:soul_sand)
B(-8,101,-3,minecraft:soul_sand)
B(-8,102,-3,minecraft:soul_sand)
B(-8,103,-3,minecraft:soul_sand)
B(-8,104,-3,minecraft:soul_sand)
B(-8,105,-3,minecraft:soul_sand)
B(-8,106,-3,minecraft:soul_sand)
B(-8,107,-3,minecraft:soul_sand)
B(-8,108,-3,minecraft:soul_sand)
B(-8,109,-3,minecraft:soul_sand)
B(-8,110,-3,minecraft:soul_sand)
B(-8,111,-3,minecraft:soul_sand)
B(-8,112,-3,minecraft:soul_sand)
B(-8,113,-3,minecraft:soul_sand)
B(-8,114,-3,minecraft:soul_sand)
B(-8,115,-3,minecraft:soul_sand)
B(-8,116,-3,minecraft:soul_sand)
B(-8,0,-2,minecraft:soul_sand)
B(-8,1,-2,minecraft:soul_sand)
B(-8,2,-2,minecraft:soul_sand)
B(-8,3,-2,minecraft:soul_sand)
B(-8,4,-2,minecraft:soul_sand)
B(-8,5,-2,minecraft:soul_sand)
B(-8,6,-2,minecraft:soul_sand)
B(-8,7,-2,minecraft:soul_sand)
B(-8,8,-2,minecraft:soul_sand)
B(-8,9,-2,minecraft:soul_sand)
B(-8,10,-2,minecraft:soul_sand)
B(-8,11,-2,minecraft:soul_sand)
B(-8,12,-2,minecraft:soul_sand)
B(-8,13,-2,minecraft:soul_sand)
B(-8,14,-2,minecraft:soul_sand)
B(-8,15,-2,minecraft:soul_sand)
B(-8,16,-2,minecraft:soul_sand)
B(-8,17,-2,minecraft:soul_sand)
B(-8,18,-2,minecraft:soul_sand)
B(-8,19,-2,minecraft:soul_sand)
B(-8,20,-2,minecraft:soul_sand)
B(-8,21,-2,minecraft:soul_sand)
B(-8,22,-2,minecraft:soul_sand)
B(-8,23,-2,minecraft:soul_sand)
B(-8,24,-2,minecraft:soul_sand)
B(-8,25,-2,minecraft:soul_sand)
B(-8,26,-2,minecraft:soul_sand)
B(-8,27,-2,minecraft:soul_sand)
B(-8,28,-2,minecraft:soul_sand)
B(-8,84,-2,minecraft:soul_sand)
B(-8,85,-2,minecraft:soul_sand)
B(-8,86,-2,minecraft:soul_sand)
B(-8,87,-2,minecraft:soul_sand)
B(-8,88,-2,minecraft:soul_sand)
B(-8,89,-2,minecraft:soul_sand)
B(-8,90,-2,minecraft:soul_sand)
B(-8,91,-2,minecraft:soul_sand)
B(-8,92,-2,minecraft:soul_sand)
B(-8,93,-2,minecraft:soul_sand)
B(-8,94,-2,minecraft:soul_sand)
B(-8,95,-2,minecraft:soul_sand)
B(-8,96,-2,minecraft:soul_sand)
B(-8,97,-2,minecraft:soul_sand)
B(-8,98,-2,minecraft:soul_sand)
B(-8,99,-2,minecraft:soul_sand)
B(-8,100,-2,minecraft:soul_sand)
B(-8,101,-2,minecraft:soul_sand)
B(-8,102,-2,minecraft:soul_sand)
B(-8,103,-2,minecraft:soul_sand)
B(-8,104,-2,minecraft:soul_sand)
B(-8,105,-2,minecraft:soul_sand)
B(-8,106,-2,minecraft:soul_sand)
B(-8,107,-2,minecraft:soul_sand)
B(-8,108,-2,minecraft:soul_sand)
B(-8,109,-2,minecraft:soul_sand)
B(-8,110,-2,minecraft:soul_sand)
B(-8,111,-2,minecraft:soul_sand)
B(-8,112,-2,minecraft:soul_sand)
B(-8,113,-2,minecraft:soul_sand)
B(-8,114,-2,minecraft:soul_sand)
B(-8,115,-2,minecraft:soul_sand)
B(-8,116,-2,minecraft:soul_sand)
B(-8,0,-1,minecraft:soul_sand)
B(-8,1,-1,minecraft:soul_sand)
B(-8,2,-1,minecraft:soul_sand)
B(-8,3,-1,minecraft:soul_sand)
B(-8,4,-1,minecraft:soul_sand)
B(-8,5,-1,minecraft:soul_sand)
B(-8,6,-1,minecraft:soul_sand)
B(-8,7,-1,minecraft:soul_sand)
B(-8,8,-1,minecraft:soul_sand)
B(-8,9,-1,minecraft:soul_sand)
B(-8,10,-1,minecraft:soul_sand)
B(-8,11,-1,minecraft:soul_sand)
B(-8,12,-1,minecraft:soul_sand)
B(-8,13,-1,minecraft:soul_sand)
B(-8,14,-1,minecraft:soul_sand)
B(-8,15,-1,minecraft:soul_sand)
B(-8,16,-1,minecraft:soul_sand)
B(-8,17,-1,minecraft:soul_sand)
B(-8,18,-1,minecraft:soul_sand)
B(-8,19,-1,minecraft:soul_sand)
B(-8,20,-1,minecraft:soul_sand)
B(-8,21,-1,minecraft:soul_sand)
B(-8,22,-1,minecraft:soul_sand)
B(-8,23,-1,minecraft:soul_sand)
B(-8,24,-1,minecraft:soul_sand)
B(-8,25,-1,minecraft:soul_sand)
B(-8,26,-1,minecraft:soul_sand)
B(-8,27,-1,minecraft:soul_sand)
B(-8,28,-1,minecraft:soul_sand)
B(-8,84,-1,minecraft:soul_sand)
B(-8,85,-1,minecraft:soul_sand)
B(-8,86,-1,minecraft:soul_sand)
B(-8,87,-1,minecraft:soul_sand)
B(-8,88,-1,minecraft:soul_sand)
B(-8,89,-1,minecraft:soul_sand)
B(-8,90,-1,minecraft:soul_sand)
B(-8,91,-1,minecraft:soul_sand)
B(-8,92,-1,minecraft:soul_sand)
B(-8,93,-1,minecraft:soul_sand)
B(-8,94,-1,minecraft:soul_sand)
B(-8,95,-1,minecraft:soul_sand)
B(-8,96,-1,minecraft:soul_sand)
B(-8,97,-1,minecraft:soul_sand)
B(-8,98,-1,minecraft:soul_sand)
B(-8,99,-1,minecraft:soul_sand)
B(-8,100,-1,minecraft:soul_sand)
B(-8,101,-1,minecraft:soul_sand)
B(-8,102,-1,minecraft:soul_sand)
B(-8,103,-1,minecraft:soul_sand)
B(-8,104,-1,minecraft:soul_sand)
B(-8,105,-1,minecraft:soul_sand)
B(-8,106,-1,minecraft:soul_sand)
B(-8,107,-1,minecraft:soul_sand)
B(-8,108,-1,minecraft:soul_sand)
B(-8,109,-1,minecraft:soul_sand)
B(-8,110,-1,minecraft:soul_sand)
B(-8,111,-1,minecraft:soul_sand)
B(-8,112,-1,minecraft:soul_sand)
B(-8,113,-1,minecraft:soul_sand)
B(-8,114,-1,minecraft:soul_sand)
B(-8,115,-1,minecraft:soul_sand)
B(-8,116,-1,minecraft:soul_sand)
B(-8,0,0,minecraft:soul_sand)
B(-8,1,0,minecraft:soul_sand)
B(-8,2,0,minecraft:soul_sand)
B(-8,3,0,minecraft:soul_sand)
B(-8,4,0,minecraft:soul_sand)
B(-8,5,0,minecraft:soul_sand)
B(-8,6,0,minecraft:soul_sand)
B(-8,7,0,minecraft:soul_sand)
B(-8,8,0,minecraft:soul_sand)
B(-8,9,0,minecraft:soul_sand)
B(-8,10,0,minecraft:soul_sand)
B(-8,11,0,minecraft:soul_sand)
B(-8,12,0,minecraft:soul_sand)
B(-8,13,0,minecraft:soul_sand)
B(-8,14,0,minecraft:soul_sand)
B(-8,15,0,minecraft:soul_sand)
B(-8,16,0,minecraft:soul_sand)
B(-8,17,0,minecraft:soul_sand)
B(-8,18,0,minecraft:soul_sand)
B(-8,19,0,minecraft:soul_sand)
B(-8,20,0,minecraft:soul_sand)
B(-8,21,0,minecraft:soul_sand)
B(-8,22,0,minecraft:soul_sand)
B(-8,23,0,minecraft:soul_sand)
B(-8,24,0,minecraft:soul_sand)
B(-8,25,0,minecraft:soul_sand)
B(-8,26,0,minecraft:soul_sand)
B(-8,27,0,minecraft:soul_sand)
B(-8,84,0,minecraft:soul_sand)
B(-8,85,0,minecraft:soul_sand)
B(-8,86,0,minecraft:soul_sand)
B(-8,87,0,minecraft:soul_sand)
B(-8,88,0,minecraft:soul_sand)
B(-8,89,0,minecraft:soul_sand)
B(-8,90,0,minecraft:soul_sand)
B(-8,91,0,minecraft:soul_sand)
B(-8,92,0,minecraft:soul_sand)
B(-8,93,0,minecraft:soul_sand)
B(-8,94,0,minecraft:soul_sand)
B(-8,95,0,minecraft:soul_sand)
B(-8,96,0,minecraft:soul_sand)
B(-8,97,0,minecraft:soul_sand)
B(-8,98,0,minecraft:soul_sand)
B(-8,99,0,minecraft:soul_sand)
B(-8,100,0,minecraft:soul_sand)
B(-8,101,0,minecraft:soul_sand)
B(-8,102,0,minecraft:soul_sand)
B(-8,103,0,minecraft:soul_sand)
B(-8,104,0,minecraft:soul_sand)
B(-8,105,0,minecraft:soul_sand)
B(-8,106,0,minecraft:soul_sand)
B(-8,107,0,minecraft:soul_sand)
B(-8,108,0,minecraft:soul_sand)
B(-8,109,0,minecraft:soul_sand)
B(-8,110,0,minecraft:soul_sand)
B(-8,111,0,minecraft:soul_sand)
B(-8,112,0,minecraft:soul_sand)
B(-8,113,0,minecraft:soul_sand)
B(-8,114,0,minecraft:soul_sand)
B(-8,115,0,minecraft:soul_sand)
B(-8,116,0,minecraft:soul_sand)
B(-8,0,1,minecraft:soul_sand)
B(-8,1,1,minecraft:soul_sand)
B(-8,2,1,minecraft:soul_sand)
B(-8,3,1,minecraft:soul_sand)
B(-8,4,1,minecraft:soul_sand)
B(-8,5,1,minecraft:soul_sand)
B(-8,6,1,minecraft:soul_sand)
B(-8,7,1,minecraft:soul_sand)
B(-8,8,1,minecraft:soul_sand)
B(-8,9,1,minecraft:soul_sand)
B(-8,10,1,minecraft:soul_sand)
B(-8,11,1,minecraft:soul_sand)
B(-8,12,1,minecraft:soul_sand)
B(-8,13,1,minecraft:soul_sand)
B(-8,14,1,minecraft:soul_sand)
B(-8,15,1,minecraft:soul_sand)
B(-8,16,1,minecraft:soul_sand)
B(-8,17,1,minecraft:soul_sand)
B(-8,18,1,minecraft:soul_sand)
B(-8,19,1,minecraft:soul_sand)
B(-8,20,1,minecraft:soul_sand)
B(-8,21,1,minecraft:soul_sand)
B(-8,22,1,minecraft:soul_sand)
B(-8,23,1,minecraft:soul_sand)
B(-8,24,1,minecraft:soul_sand)
B(-8,25,1,minecraft:soul_sand)
B(-8,26,1,minecraft:soul_sand)
B(-8,84,1,minecraft:soul_sand)
B(-8,85,1,minecraft:soul_sand)
B(-8,86,1,minecraft:soul_sand)
B(-8,87,1,minecraft:soul_sand)
B(-8,88,1,minecraft:soul_sand)
B(-8,89,1,minecraft:soul_sand)
B(-8,90,1,minecraft:soul_sand)
B(-8,91,1,minecraft:soul_sand)
B(-8,92,1,minecraft:soul_sand)
B(-8,93,1,minecraft:soul_sand)
B(-8,94,1,minecraft:soul_sand)
B(-8,95,1,minecraft:soul_sand)
B(-8,96,1,minecraft:soul_sand)
B(-8,97,1,minecraft:soul_sand)
B(-8,98,1,minecraft:soul_sand)
B(-8,99,1,minecraft:soul_sand)
B(-8,100,1,minecraft:soul_sand)
B(-8,101,1,minecraft:soul_sand)
B(-8,102,1,minecraft:soul_sand)
B(-8,103,1,minecraft:soul_sand)
B(-8,104,1,minecraft:soul_sand)
B(-8,105,1,minecraft:soul_sand)
B(-8,106,1,minecraft:soul_sand)
B(-8,107,1,minecraft:soul_sand)
B(-8,108,1,minecraft:soul_sand)
B(-8,109,1,minecraft:soul_sand)
B(-8,110,1,minecraft:soul_sand)
B(-8,111,1,minecraft:soul_sand)
B(-8,112,1,minecraft:soul_sand)
B(-8,113,1,minecraft:soul_sand)
B(-8,114,1,minecraft:soul_sand)
B(-8,115,1,minecraft:soul_sand)
B(-8,116,1,minecraft:soul_sand)
B(-8,0,2,minecraft:soul_sand)
B(-8,1,2,minecraft:soul_sand)
B(-8,2,2,minecraft:soul_sand)
B(-8,3,2,minecraft:soul_sand)
B(-8,4,2,minecraft:soul_sand)
B(-8,5,2,minecraft:soul_sand)
B(-8,6,2,minecraft:soul_sand)
B(-8,7,2,minecraft:soul_sand)
B(-8,8,2,minecraft:soul_sand)
B(-8,9,2,minecraft:soul_sand)
B(-8,10,2,minecraft:soul_sand)
B(-8,11,2,minecraft:soul_sand)
B(-8,12,2,minecraft:soul_sand)
B(-8,13,2,minecraft:soul_sand)
B(-8,14,2,minecraft:soul_sand)
B(-8,15,2,minecraft:soul_sand)
B(-8,16,2,minecraft:soul_sand)
B(-8,17,2,minecraft:soul_sand)
B(-8,18,2,minecraft:soul_sand)
B(-8,19,2,minecraft:soul_sand)
B(-8,20,2,minecraft:soul_sand)
B(-8,21,2,minecraft:soul_sand)
B(-8,22,2,minecraft:soul_sand)
B(-8,23,2,minecraft:soul_sand)
B(-8,24,2,minecraft:soul_sand)
B(-8,25,2,minecraft:soul_sand)
B(-8,84,2,minecraft:soul_sand)
B(-8,85,2,minecraft:soul_sand)
B(-8,86,2,minecraft:soul_sand)
B(-8,87,2,minecraft:soul_sand)
B(-8,88,2,minecraft:soul_sand)
B(-8,89,2,minecraft:soul_sand)
B(-8,90,2,minecraft:soul_sand)
B(-8,91,2,minecraft:soul_sand)
B(-8,92,2,minecraft:soul_sand)
B(-8,93,2,minecraft:soul_sand)
B(-8,94,2,minecraft:soul_sand)
B(-8,95,2,minecraft:soul_sand)
B(-8,96,2,minecraft:soul_sand)
B(-8,97,2,minecraft:soul_sand)
B(-8,98,2,minecraft:soul_sand)
B(-8,99,2,minecraft:soul_sand)
B(-8,100,2,minecraft:soul_sand)
B(-8,101,2,minecraft:soul_sand)
B(-8,102,2,minecraft:soul_sand)
B(-8,103,2,minecraft:soul_sand)
B(-8,104,2,minecraft:soul_sand)
B(-8,105,2,minecraft:soul_sand)
B(-8,106,2,minecraft:soul_sand)
B(-8,107,2,minecraft:soul_sand)
B(-8,108,2,minecraft:soul_sand)
B(-8,109,2,minecraft:soul_sand)
B(-8,110,2,minecraft:soul_sand)
B(-8,111,2,minecraft:soul_sand)
B(-8,112,2,minecraft:soul_sand)
B(-8,113,2,minecraft:soul_sand)
B(-8,114,2,minecraft:soul_sand)
B(-8,115,2,minecraft:soul_sand)
B(-8,116,2,minecraft:soul_sand)
B(-8,0,3,minecraft:soul_sand)
B(-8,1,3,minecraft:soul_sand)
B(-8,2,3,minecraft:soul_sand)
B(-8,3,3,minecraft:soul_sand)
B(-8,4,3,minecraft:soul_sand)
B(-8,5,3,minecraft:soul_sand)
B(-8,6,3,minecraft:soul_sand)
B(-8,7,3,minecraft:soul_sand)
B(-8,8,3,minecraft:soul_sand)
B(-8,9,3,minecraft:soul_sand)
B(-8,10,3,minecraft:soul_sand)
B(-8,11,3,minecraft:soul_sand)
B(-8,12,3,minecraft:soul_sand)
B(-8,13,3,minecraft:soul_sand)
B(-8,14,3,minecraft:soul_sand)
B(-8,15,3,minecraft:soul_sand)
B(-8,16,3,minecraft:soul_sand)
B(-8,17,3,minecraft:soul_sand)
B(-8,18,3,minecraft:soul_sand)
B(-8,19,3,minecraft:soul_sand)
B(-8,20,3,minecraft:soul_sand)
B(-8,21,3,minecraft:soul_sand)
B(-8,86,3,minecraft:soul_sand)
B(-8,87,3,minecraft:soul_sand)
B(-8,88,3,minecraft:soul_sand)
B(-8,89,3,minecraft:soul_sand)
B(-8,90,3,minecraft:soul_sand)
B(-8,91,3,minecraft:soul_sand)
B(-8,92,3,minecraft:soul_sand)
B(-8,93,3,minecraft:soul_sand)
B(-8,94,3,minecraft:soul_sand)
B(-8,95,3,minecraft:soul_sand)
B(-8,96,3,minecraft:soul_sand)
B(-8,97,3,minecraft:soul_sand)
B(-8,98,3,minecraft:soul_sand)
B(-8,99,3,minecraft:soul_sand)
B(-8,100,3,minecraft:soul_sand)
B(-8,101,3,minecraft:soul_sand)
B(-8,102,3,minecraft:soul_sand)
B(-8,103,3,minecraft:soul_sand)
B(-8,104,3,minecraft:soul_sand)
B(-8,105,3,minecraft:soul_sand)
B(-8,106,3,minecraft:soul_sand)
B(-8,107,3,minecraft:soul_sand)
B(-8,108,3,minecraft:soul_sand)
B(-8,109,3,minecraft:soul_sand)
B(-8,110,3,minecraft:soul_sand)
B(-8,111,3,minecraft:soul_sand)
B(-8,112,3,minecraft:soul_sand)
B(-8,113,3,minecraft:soul_sand)
B(-8,114,3,minecraft:soul_sand)
B(-8,115,3,minecraft:soul_sand)
B(-8,116,3,minecraft:soul_sand)
B(-8,0,4,minecraft:soul_sand)
B(-8,1,4,minecraft:soul_sand)
B(-8,2,4,minecraft:soul_sand)
B(-8,3,4,minecraft:soul_sand)
B(-8,4,4,minecraft:soul_sand)
B(-8,5,4,minecraft:soul_sand)
B(-8,6,4,minecraft:soul_sand)
B(-8,7,4,minecraft:soul_sand)
B(-8,8,4,minecraft:soul_sand)
B(-8,9,4,minecraft:soul_sand)
B(-8,10,4,minecraft:soul_sand)
B(-8,11,4,minecraft:soul_sand)
B(-8,12,4,minecraft:soul_sand)
B(-8,13,4,minecraft:soul_sand)
B(-8,14,4,minecraft:soul_sand)
B(-8,15,4,minecraft:soul_sand)
B(-8,16,4,minecraft:soul_sand)
B(-8,17,4,minecraft:soul_sand)
B(-8,18,4,minecraft:soul_sand)
B(-8,19,4,minecraft:soul_sand)
B(-8,20,4,minecraft:soul_sand)
B(-8,21,4,minecraft:soul_sand)
B(-8,87,4,minecraft:soul_sand)
B(-8,88,4,minecraft:soul_sand)
B(-8,89,4,minecraft:soul_sand)
B(-8,90,4,minecraft:soul_sand)
B(-8,91,4,minecraft:soul_sand)
B(-8,92,4,minecraft:soul_sand)
B(-8,93,4,minecraft:soul_sand)
B(-8,94,4,minecraft:soul_sand)
B(-8,95,4,minecraft:soul_sand)
B(-8,96,4,minecraft:soul_sand)
B(-8,97,4,minecraft:soul_sand)
B(-8,98,4,minecraft:soul_sand)
B(-8,99,4,minecraft:soul_sand)
B(-8,100,4,minecraft:soul_sand)
B(-8,101,4,minecraft:soul_sand)
B(-8,102,4,minecraft:soul_sand)
B(-8,103,4,minecraft:soul_sand)
B(-8,104,4,minecraft:soul_sand)
B(-8,105,4,minecraft:soul_sand)
B(-8,106,4,minecraft:soul_sand)
B(-8,107,4,minecraft:soul_sand)
B(-8,108,4,minecraft:soul_sand)
B(-8,109,4,minecraft:soul_sand)
B(-8,110,4,minecraft:soul_sand)
B(-8,111,4,minecraft:soul_sand)
B(-8,112,4,minecraft:soul_sand)
B(-8,113,4,minecraft:soul_sand)
B(-8,114,4,minecraft:soul_sand)
B(-8,115,4,minecraft:soul_sand)
B(-8,116,4,minecraft:soul_sand)
B(-8,0,5,minecraft:soul_sand)
B(-8,1,5,minecraft:soul_sand)
B(-8,2,5,minecraft:soul_sand)
B(-8,3,5,minecraft:soul_sand)
B(-8,4,5,minecraft:soul_sand)
B(-8,5,5,minecraft:soul_sand)
B(-8,6,5,minecraft:soul_sand)
B(-8,7,5,minecraft:soul_sand)
B(-8,8,5,minecraft:soul_sand)
B(-8,9,5,minecraft:soul_sand)
B(-8,10,5,minecraft:soul_sand)
B(-8,11,5,minecraft:soul_sand)
B(-8,12,5,minecraft:soul_sand)
B(-8,13,5,minecraft:soul_sand)
B(-8,14,5,minecraft:soul_sand)
B(-8,15,5,minecraft:soul_sand)
B(-8,16,5,minecraft:soul_sand)
B(-8,17,5,minecraft:soul_sand)
B(-8,18,5,minecraft:soul_sand)
B(-8,19,5,minecraft:soul_sand)
B(-8,20,5,minecraft:soul_sand)
B(-8,21,5,minecraft:soul_sand)
B(-8,90,5,minecraft:soul_sand)
B(-8,91,5,minecraft:soul_sand)
B(-8,92,5,minecraft:soul_sand)
B(-8,93,5,minecraft:soul_sand)
B(-8,94,5,minecraft:soul_sand)
B(-8,95,5,minecraft:soul_sand)
B(-8,96,5,minecraft:soul_sand)
B(-8,97,5,minecraft:soul_sand)
B(-8,98,5,minecraft:soul_sand)
B(-8,99,5,minecraft:soul_sand)
B(-8,100,5,minecraft:soul_sand)
B(-8,101,5,minecraft:soul_sand)
B(-8,102,5,minecraft:soul_sand)
B(-8,103,5,minecraft:soul_sand)
B(-8,104,5,minecraft:soul_sand)
B(-8,105,5,minecraft:soul_sand)
B(-8,106,5,minecraft:soul_sand)
B(-8,107,5,minecraft:soul_sand)
B(-8,108,5,minecraft:soul_sand)
B(-8,109,5,minecraft:soul_sand)
B(-8,110,5,minecraft:soul_sand)
B(-8,111,5,minecraft:soul_sand)
B(-8,112,5,minecraft:soul_sand)
B(-8,113,5,minecraft:soul_sand)
B(-8,114,5,minecraft:soul_sand)
B(-8,115,5,minecraft:soul_sand)
B(-8,116,5,minecraft:soul_sand)
B(-8,0,6,minecraft:soul_sand)
B(-8,1,6,minecraft:soul_sand)
B(-8,2,6,minecraft:soul_sand)
B(-8,3,6,minecraft:soul_sand)
B(-8,4,6,minecraft:soul_sand)
B(-8,5,6,minecraft:soul_sand)
B(-8,6,6,minecraft:soul_sand)
B(-8,7,6,minecraft:soul_sand)
B(-8,8,6,minecraft:soul_sand)
B(-8,9,6,minecraft:soul_sand)
B(-8,10,6,minecraft:soul_sand)
B(-8,11,6,minecraft:soul_sand)
B(-8,12,6,minecraft:soul_sand)
B(-8,13,6,minecraft:soul_sand)
B(-8,14,6,minecraft:soul_sand)
B(-8,15,6,minecraft:soul_sand)
B(-8,16,6,minecraft:soul_sand)
B(-8,17,6,minecraft:soul_sand)
B(-8,18,6,minecraft:soul_sand)
B(-8,19,6,minecraft:soul_sand)
B(-8,20,6,minecraft:soul_sand)
B(-8,21,6,minecraft:soul_sand)
B(-8,91,6,minecraft:soul_sand)
B(-8,92,6,minecraft:soul_sand)
B(-8,93,6,minecraft:soul_sand)
B(-8,94,6,minecraft:soul_sand)
B(-8,95,6,minecraft:soul_sand)
B(-8,96,6,minecraft:soul_sand)
B(-8,97,6,minecraft:soul_sand)
B(-8,98,6,minecraft:soul_sand)
B(-8,99,6,minecraft:soul_sand)
B(-8,100,6,minecraft:soul_sand)
B(-8,101,6,minecraft:soul_sand)
B(-8,102,6,minecraft:soul_sand)
B(-8,103,6,minecraft:soul_sand)
B(-8,104,6,minecraft:soul_sand)
B(-8,105,6,minecraft:soul_sand)
B(-8,106,6,minecraft:soul_sand)
B(-8,107,6,minecraft:soul_sand)
B(-8,108,6,minecraft:soul_sand)
B(-8,109,6,minecraft:soul_sand)
B(-8,110,6,minecraft:soul_sand)
B(-8,111,6,minecraft:soul_sand)
B(-8,112,6,minecraft:soul_sand)
B(-8,113,6,minecraft:soul_sand)
B(-8,114,6,minecraft:soul_sand)
B(-8,115,6,minecraft:soul_sand)
B(-8,116,6,minecraft:soul_sand)
B(-8,0,7,minecraft:soul_sand)
B(-8,1,7,minecraft:soul_sand)
B(-8,2,7,minecraft:soul_sand)
B(-8,3,7,minecraft:soul_sand)
B(-8,4,7,minecraft:soul_sand)
B(-8,5,7,minecraft:soul_sand)
B(-8,6,7,minecraft:soul_sand)
B(-8,7,7,minecraft:soul_sand)
B(-8,8,7,minecraft:soul_sand)
B(-8,9,7,minecraft:soul_sand)
B(-8,10,7,minecraft:soul_sand)
B(-8,11,7,minecraft:soul_sand)
B(-8,12,7,minecraft:soul_sand)
B(-8,13,7,minecraft:soul_sand)
B(-8,14,7,minecraft:soul_sand)
B(-8,15,7,minecraft:soul_sand)
B(-8,16,7,minecraft:soul_sand)
B(-8,17,7,minecraft:soul_sand)
B(-8,18,7,minecraft:soul_sand)
B(-8,19,7,minecraft:soul_sand)
B(-8,20,7,minecraft:soul_sand)
B(-8,21,7,minecraft:soul_sand)
B(-8,92,7,minecraft:soul_sand)
B(-8,93,7,minecraft:soul_sand)
B(-8,94,7,minecraft:soul_sand)
B(-8,95,7,minecraft:soul_sand)
B(-8,96,7,minecraft:soul_sand)
B(-8,97,7,minecraft:soul_sand)
B(-8,98,7,minecraft:soul_sand)
B(-8,99,7,minecraft:soul_sand)
B(-8,100,7,minecraft:soul_sand)
B(-8,101,7,minecraft:soul_sand)
B(-8,102,7,minecraft:soul_sand)
B(-8,103,7,minecraft:soul_sand)
B(-8,104,7,minecraft:soul_sand)
B(-8,105,7,minecraft:soul_sand)
B(-8,106,7,minecraft:soul_sand)
B(-8,107,7,minecraft:soul_sand)
B(-8,108,7,minecraft:soul_sand)
B(-8,109,7,minecraft:soul_sand)
B(-8,110,7,minecraft:soul_sand)
B(-8,111,7,minecraft:soul_sand)
B(-8,112,7,minecraft:soul_sand)
B(-8,113,7,minecraft:soul_sand)
B(-8,114,7,minecraft:soul_sand)
B(-8,115,7,minecraft:soul_sand)
B(-8,116,7,minecraft:soul_sand)
B(-8,0,8,minecraft:soul_sand)
B(-8,1,8,minecraft:soul_sand)
B(-8,2,8,minecraft:soul_sand)
B(-8,3,8,minecraft:soul_sand)
B(-8,4,8,minecraft:soul_sand)
B(-8,5,8,minecraft:soul_sand)
B(-8,6,8,minecraft:soul_sand)
B(-8,7,8,minecraft:soul_sand)
B(-8,8,8,minecraft:soul_sand)
B(-8,9,8,minecraft:soul_sand)
B(-8,10,8,minecraft:soul_sand)
B(-8,11,8,minecraft:soul_sand)
B(-8,12,8,minecraft:soul_sand)
B(-8,13,8,minecraft:soul_sand)
B(-8,14,8,minecraft:soul_sand)
B(-8,15,8,minecraft:soul_sand)
B(-8,16,8,minecraft:soul_sand)
B(-8,17,8,minecraft:soul_sand)
B(-8,18,8,minecraft:soul_sand)
B(-8,19,8,minecraft:soul_sand)
B(-8,20,8,minecraft:soul_sand)
B(-8,94,8,minecraft:soul_sand)
B(-8,95,8,minecraft:soul_sand)
B(-8,96,8,minecraft:soul_sand)
B(-8,97,8,minecraft:soul_sand)
B(-8,98,8,minecraft:soul_sand)
B(-8,99,8,minecraft:soul_sand)
B(-8,100,8,minecraft:soul_sand)
B(-8,101,8,minecraft:soul_sand)
B(-8,102,8,minecraft:soul_sand)
B(-8,103,8,minecraft:soul_sand)
B(-8,104,8,minecraft:soul_sand)
B(-8,105,8,minecraft:soul_sand)
B(-8,106,8,minecraft:soul_sand)
B(-8,107,8,minecraft:soul_sand)
B(-8,108,8,minecraft:soul_sand)
B(-8,109,8,minecraft:soul_sand)
B(-8,110,8,minecraft:soul_sand)
B(-8,111,8,minecraft:soul_sand)
B(-8,112,8,minecraft:soul_sand)
B(-8,113,8,minecraft:soul_sand)
B(-8,114,8,minecraft:soul_sand)
B(-8,115,8,minecraft:soul_sand)
B(-8,116,8,minecraft:soul_sand)
B(-7,0,-7,minecraft:soul_sand)
B(-7,1,-7,minecraft:soul_sand)
B(-7,2,-7,minecraft:soul_sand)
B(-7,3,-7,minecraft:soul_sand)
B(-7,4,-7,minecraft:soul_sand)
B(-7,5,-7,minecraft:soul_sand)
B(-7,6,-7,minecraft:soul_sand)
B(-7,7,-7,minecraft:soul_sand)
B(-7,8,-7,minecraft:soul_sand)
B(-7,9,-7,minecraft:soul_sand)
B(-7,10,-7,minecraft:soul_sand)
B(-7,11,-7,minecraft:soul_sand)
B(-7,12,-7,minecraft:soul_sand)
B(-7,13,-7,minecraft:soul_sand)
B(-7,14,-7,minecraft:soul_sand)
B(-7,15,-7,minecraft:soul_sand)
B(-7,16,-7,minecraft:soul_sand)
B(-7,17,-7,minecraft:soul_sand)
B(-7,18,-7,minecraft:soul_sand)
B(-7,19,-7,minecraft:soul_sand)
B(-7,20,-7,minecraft:soul_sand)
B(-7,21,-7,minecraft:soul_sand)
B(-7,22,-7,minecraft:soul_sand)
B(-7,23,-7,minecraft:soul_sand)
B(-7,24,-7,minecraft:soul_sand)
B(-7,25,-7,minecraft:soul_sand)
B(-7,82,-7,minecraft:soul_sand)
B(-7,83,-7,minecraft:soul_sand)
B(-7,84,-7,minecraft:soul_sand)
B(-7,85,-7,minecraft:soul_sand)
B(-7,86,-7,minecraft:soul_sand)
B(-7,87,-7,minecraft:soul_sand)
B(-7,88,-7,minecraft:soul_sand)
B(-7,89,-7,minecraft:soul_sand)
B(-7,90,-7,minecraft:soul_sand)
B(-7,91,-7,minecraft:soul_sand)
B(-7,92,-7,minecraft:soul_sand)
B(-7,93,-7,minecraft:soul_sand)
B(-7,94,-7,minecraft:soul_sand)
B(-7,95,-7,minecraft:soul_sand)
B(-7,96,-7,minecraft:soul_sand)
B(-7,97,-7,minecraft:soul_sand)
B(-7,98,-7,minecraft:soul_sand)
B(-7,99,-7,minecraft:soul_sand)
B(-7,100,-7,minecraft:soul_sand)
B(-7,101,-7,minecraft:soul_sand)
B(-7,102,-7,minecraft:soul_sand)
B(-7,103,-7,minecraft:soul_sand)
B(-7,104,-7,minecraft:soul_sand)
B(-7,105,-7,minecraft:soul_sand)
B(-7,106,-7,minecraft:soul_sand)
B(-7,107,-7,minecraft:soul_sand)
B(-7,108,-7,minecraft:soul_sand)
B(-7,109,-7,minecraft:soul_sand)
B(-7,110,-7,minecraft:soul_sand)
B(-7,111,-7,minecraft:soul_sand)
B(-7,112,-7,minecraft:soul_sand)
B(-7,113,-7,minecraft:soul_sand)
B(-7,114,-7,minecraft:soul_sand)
B(-7,115,-7,minecraft:soul_sand)
B(-7,116,-7,minecraft:soul_sand)
B(-7,0,-6,minecraft:soul_sand)
B(-7,1,-6,minecraft:soul_sand)
B(-7,2,-6,minecraft:soul_sand)
B(-7,3,-6,minecraft:soul_sand)
B(-7,4,-6,minecraft:soul_sand)
B(-7,5,-6,minecraft:soul_sand)
B(-7,6,-6,minecraft:soul_sand)
B(-7,7,-6,minecraft:soul_sand)
B(-7,8,-6,minecraft:soul_sand)
B(-7,9,-6,minecraft:soul_sand)
B(-7,10,-6,minecraft:soul_sand)
B(-7,11,-6,minecraft:soul_sand)
B(-7,12,-6,minecraft:soul_sand)
B(-7,13,-6,minecraft:soul_sand)
B(-7,14,-6,minecraft:soul_sand)
B(-7,15,-6,minecraft:soul_sand)
B(-7,16,-6,minecraft:soul_sand)
B(-7,17,-6,minecraft:soul_sand)
B(-7,18,-6,minecraft:soul_sand)
B(-7,19,-6,minecraft:soul_sand)
B(-7,20,-6,minecraft:soul_sand)
B(-7,21,-6,minecraft:soul_sand)
B(-7,22,-6,minecraft:soul_sand)
B(-7,23,-6,minecraft:soul_sand)
B(-7,24,-6,minecraft:soul_sand)
B(-7,25,-6,minecraft:soul_sand)
B(-7,26,-6,minecraft:soul_sand)
B(-7,83,-6,minecraft:soul_sand)
B(-7,84,-6,minecraft:soul_sand)
B(-7,85,-6,minecraft:soul_sand)
B(-7,86,-6,minecraft:soul_sand)
B(-7,87,-6,minecraft:soul_sand)
B(-7,88,-6,minecraft:soul_sand)
B(-7,89,-6,minecraft:soul_sand)
B(-7,90,-6,minecraft:soul_sand)
B(-7,91,-6,minecraft:soul_sand)
B(-7,92,-6,minecraft:soul_sand)
B(-7,93,-6,minecraft:soul_sand)
B(-7,94,-6,minecraft:soul_sand)
B(-7,95,-6,minecraft:soul_sand)
B(-7,96,-6,minecraft:soul_sand)
B(-7,97,-6,minecraft:soul_sand)
B(-7,98,-6,minecraft:soul_sand)
B(-7,99,-6,minecraft:soul_sand)
B(-7,100,-6,minecraft:soul_sand)
B(-7,101,-6,minecraft:soul_sand)
B(-7,102,-6,minecraft:soul_sand)
B(-7,103,-6,minecraft:soul_sand)
B(-7,104,-6,minecraft:soul_sand)
B(-7,105,-6,minecraft:soul_sand)
B(-7,106,-6,minecraft:soul_sand)
B(-7,107,-6,minecraft:soul_sand)
B(-7,108,-6,minecraft:soul_sand)
B(-7,109,-6,minecraft:soul_sand)
B(-7,110,-6,minecraft:soul_sand)
B(-7,111,-6,minecraft:soul_sand)
B(-7,112,-6,minecraft:soul_sand)
B(-7,113,-6,minecraft:soul_sand)
B(-7,114,-6,minecraft:soul_sand)
B(-7,115,-6,minecraft:soul_sand)
B(-7,116,-6,minecraft:soul_sand)
B(-7,0,-5,minecraft:soul_sand)
B(-7,1,-5,minecraft:soul_sand)
B(-7,2,-5,minecraft:soul_sand)
B(-7,3,-5,minecraft:soul_sand)
B(-7,4,-5,minecraft:soul_sand)
B(-7,5,-5,minecraft:soul_sand)
B(-7,6,-5,minecraft:soul_sand)
B(-7,7,-5,minecraft:soul_sand)
B(-7,8,-5,minecraft:soul_sand)
B(-7,9,-5,minecraft:soul_sand)
B(-7,10,-5,minecraft:soul_sand)
B(-7,11,-5,minecraft:soul_sand)
B(-7,12,-5,minecraft:soul_sand)
B(-7,13,-5,minecraft:soul_sand)
B(-7,14,-5,minecraft:soul_sand)
B(-7,15,-5,minecraft:soul_sand)
B(-7,16,-5,minecraft:soul_sand)
B(-7,17,-5,minecraft:soul_sand)
B(-7,18,-5,minecraft:soul_sand)
B(-7,19,-5,minecraft:soul_sand)
B(-7,20,-5,minecraft:soul_sand)
B(-7,21,-5,minecraft:soul_sand)
B(-7,22,-5,minecraft:soul_sand)
B(-7,23,-5,minecraft:soul_sand)
B(-7,24,-5,minecraft:soul_sand)
B(-7,25,-5,minecraft:soul_sand)
B(-7,26,-5,minecraft:soul_sand)
B(-7,27,-5,minecraft:soul_sand)
B(-7,28,-5,minecraft:soul_sand)
B(-7,83,-5,minecraft:soul_sand)
B(-7,84,-5,minecraft:soul_sand)
B(-7,85,-5,minecraft:soul_sand)
B(-7,86,-5,minecraft:soul_sand)
B(-7,87,-5,minecraft:soul_sand)
B(-7,88,-5,minecraft:soul_sand)
B(-7,89,-5,minecraft:soul_sand)
B(-7,90,-5,minecraft:soul_sand)
B(-7,91,-5,minecraft:soul_sand)
B(-7,92,-5,minecraft:soul_sand)
B(-7,93,-5,minecraft:soul_sand)
B(-7,94,-5,minecraft:soul_sand)
B(-7,95,-5,minecraft:soul_sand)
B(-7,96,-5,minecraft:soul_sand)
B(-7,97,-5,minecraft:soul_sand)
B(-7,98,-5,minecraft:soul_sand)
B(-7,99,-5,minecraft:soul_sand)
B(-7,100,-5,minecraft:soul_sand)
B(-7,101,-5,minecraft:soul_sand)
B(-7,102,-5,minecraft:soul_sand)
B(-7,103,-5,minecraft:soul_sand)
B(-7,104,-5,minecraft:soul_sand)
B(-7,105,-5,minecraft:soul_sand)
B(-7,106,-5,minecraft:soul_sand)
B(-7,107,-5,minecraft:soul_sand)
B(-7,108,-5,minecraft:soul_sand)
B(-7,109,-5,minecraft:soul_sand)
B(-7,110,-5,minecraft:soul_sand)
B(-7,111,-5,minecraft:soul_sand)
B(-7,112,-5,minecraft:soul_sand)
B(-7,113,-5,minecraft:soul_sand)
B(-7,114,-5,minecraft:soul_sand)
B(-7,115,-5,minecraft:soul_sand)
B(-7,116,-5,minecraft:soul_sand)
B(-7,0,-4,minecraft:soul_sand)
B(-7,1,-4,minecraft:soul_sand)
B(-7,2,-4,minecraft:soul_sand)
B(-7,3,-4,minecraft:soul_sand)
B(-7,4,-4,minecraft:soul_sand)
B(-7,5,-4,minecraft:soul_sand)
B(-7,6,-4,minecraft:soul_sand)
B(-7,7,-4,minecraft:soul_sand)
B(-7,8,-4,minecraft:soul_sand)
B(-7,9,-4,minecraft:soul_sand)
B(-7,10,-4,minecraft:soul_sand)
B(-7,11,-4,minecraft:soul_sand)
B(-7,12,-4,minecraft:soul_sand)
B(-7,13,-4,minecraft:soul_sand)
B(-7,14,-4,minecraft:soul_sand)
B(-7,15,-4,minecraft:soul_sand)
B(-7,16,-4,minecraft:soul_sand)
B(-7,17,-4,minecraft:soul_sand)
B(-7,18,-4,minecraft:soul_sand)
B(-7,19,-4,minecraft:soul_sand)
B(-7,20,-4,minecraft:soul_sand)
B(-7,21,-4,minecraft:soul_sand)
B(-7,22,-4,minecraft:soul_sand)
B(-7,23,-4,minecraft:soul_sand)
B(-7,24,-4,minecraft:soul_sand)
B(-7,25,-4,minecraft:soul_sand)
B(-7,26,-4,minecraft:soul_sand)
B(-7,27,-4,minecraft:soul_sand)
B(-7,28,-4,minecraft:soul_sand)
B(-7,84,-4,minecraft:soul_sand)
B(-7,85,-4,minecraft:soul_sand)
B(-7,86,-4,minecraft:soul_sand)
B(-7,87,-4,minecraft:soul_sand)
B(-7,88,-4,minecraft:soul_sand)
B(-7,89,-4,minecraft:soul_sand)
B(-7,90,-4,minecraft:soul_sand)
B(-7,91,-4,minecraft:soul_sand)
B(-7,92,-4,minecraft:soul_sand)
B(-7,93,-4,minecraft:soul_sand)
B(-7,94,-4,minecraft:soul_sand)
B(-7,95,-4,minecraft:soul_sand)
B(-7,96,-4,minecraft:soul_sand)
B(-7,97,-4,minecraft:soul_sand)
B(-7,98,-4,minecraft:soul_sand)
B(-7,99,-4,minecraft:soul_sand)
B(-7,100,-4,minecraft:soul_sand)
B(-7,101,-4,minecraft:soul_sand)
B(-7,102,-4,minecraft:soul_sand)
B(-7,103,-4,minecraft:soul_sand)
B(-7,104,-4,minecraft:soul_sand)
B(-7,105,-4,minecraft:soul_sand)
B(-7,106,-4,minecraft:soul_sand)
B(-7,107,-4,minecraft:soul_sand)
B(-7,108,-4,minecraft:soul_sand)
B(-7,109,-4,minecraft:soul_sand)
B(-7,110,-4,minecraft:soul_sand)
B(-7,111,-4,minecraft:soul_sand)
B(-7,112,-4,minecraft:soul_sand)
B(-7,113,-4,minecraft:soul_sand)
B(-7,114,-4,minecraft:soul_sand)
B(-7,115,-4,minecraft:soul_sand)
B(-7,116,-4,minecraft:soul_sand)
B(-7,0,-3,minecraft:soul_sand)
B(-7,1,-3,minecraft:soul_sand)
B(-7,2,-3,minecraft:soul_sand)
B(-7,3,-3,minecraft:soul_sand)
B(-7,4,-3,minecraft:soul_sand)
B(-7,5,-3,minecraft:soul_sand)
B(-7,6,-3,minecraft:soul_sand)
B(-7,7,-3,minecraft:soul_sand)
B(-7,8,-3,minecraft:soul_sand)
B(-7,9,-3,minecraft:soul_sand)
B(-7,10,-3,minecraft:soul_sand)
B(-7,11,-3,minecraft:soul_sand)
B(-7,12,-3,minecraft:soul_sand)
B(-7,13,-3,minecraft:soul_sand)
B(-7,14,-3,minecraft:soul_sand)
B(-7,15,-3,minecraft:soul_sand)
B(-7,16,-3,minecraft:soul_sand)
B(-7,17,-3,minecraft:soul_sand)
B(-7,18,-3,minecraft:soul_sand)
B(-7,19,-3,minecraft:soul_sand)
B(-7,20,-3,minecraft:soul_sand)
B(-7,21,-3,minecraft:soul_sand)
B(-7,22,-3,minecraft:soul_sand)
B(-7,23,-3,minecraft:soul_sand)
B(-7,24,-3,minecraft:soul_sand)
B(-7,25,-3,minecraft:soul_sand)
B(-7,26,-3,minecraft:soul_sand)
B(-7,27,-3,minecraft:soul_sand)
B(-7,28,-3,minecraft:soul_sand)
B(-7,84,-3,minecraft:soul_sand)
B(-7,85,-3,minecraft:soul_sand)
B(-7,86,-3,minecraft:soul_sand)
B(-7,87,-3,minecraft:soul_sand)
B(-7,88,-3,minecraft:soul_sand)
B(-7,89,-3,minecraft:soul_sand)
B(-7,90,-3,minecraft:soul_sand)
B(-7,91,-3,minecraft:soul_sand)
B(-7,92,-3,minecraft:soul_sand)
B(-7,93,-3,minecraft:soul_sand)
B(-7,94,-3,minecraft:soul_sand)
B(-7,95,-3,minecraft:soul_sand)
B(-7,96,-3,minecraft:soul_sand)
B(-7,97,-3,minecraft:soul_sand)
B(-7,98,-3,minecraft:soul_sand)
B(-7,99,-3,minecraft:soul_sand)
B(-7,100,-3,minecraft:soul_sand)
B(-7,101,-3,minecraft:soul_sand)
B(-7,102,-3,minecraft:soul_sand)
B(-7,103,-3,minecraft:soul_sand)
B(-7,104,-3,minecraft:soul_sand)
B(-7,105,-3,minecraft:soul_sand)
B(-7,106,-3,minecraft:soul_sand)
B(-7,107,-3,minecraft:soul_sand)
B(-7,108,-3,minecraft:soul_sand)
B(-7,109,-3,minecraft:soul_sand)
B(-7,110,-3,minecraft:soul_sand)
B(-7,111,-3,minecraft:soul_sand)
B(-7,112,-3,minecraft:soul_sand)
B(-7,113,-3,minecraft:soul_sand)
B(-7,114,-3,minecraft:soul_sand)
B(-7,115,-3,minecraft:soul_sand)
B(-7,116,-3,minecraft:soul_sand)
B(-7,0,-2,minecraft:soul_sand)
B(-7,1,-2,minecraft:soul_sand)
B(-7,2,-2,minecraft:soul_sand)
B(-7,3,-2,minecraft:soul_sand)
B(-7,4,-2,minecraft:soul_sand)
B(-7,5,-2,minecraft:soul_sand)
B(-7,6,-2,minecraft:soul_sand)
B(-7,7,-2,minecraft:soul_sand)
B(-7,8,-2,minecraft:soul_sand)
B(-7,9,-2,minecraft:soul_sand)
B(-7,10,-2,minecraft:soul_sand)
B(-7,11,-2,minecraft:soul_sand)
B(-7,12,-2,minecraft:soul_sand)
B(-7,13,-2,minecraft:soul_sand)
B(-7,14,-2,minecraft:soul_sand)
B(-7,15,-2,minecraft:soul_sand)
B(-7,16,-2,minecraft:soul_sand)
B(-7,17,-2,minecraft:soul_sand)
B(-7,18,-2,minecraft:soul_sand)
B(-7,19,-2,minecraft:soul_sand)
B(-7,20,-2,minecraft:soul_sand)
B(-7,21,-2,minecraft:soul_sand)
B(-7,22,-2,minecraft:soul_sand)
B(-7,23,-2,minecraft:soul_sand)
B(-7,24,-2,minecraft:soul_sand)
B(-7,25,-2,minecraft:soul_sand)
B(-7,26,-2,minecraft:soul_sand)
B(-7,27,-2,minecraft:soul_sand)
B(-7,28,-2,minecraft:soul_sand)
B(-7,84,-2,minecraft:soul_sand)
B(-7,85,-2,minecraft:soul_sand)
B(-7,86,-2,minecraft:soul_sand)
B(-7,87,-2,minecraft:soul_sand)
B(-7,88,-2,minecraft:soul_sand)
B(-7,89,-2,minecraft:soul_sand)
B(-7,90,-2,minecraft:soul_sand)
B(-7,91,-2,minecraft:soul_sand)
B(-7,92,-2,minecraft:soul_sand)
B(-7,93,-2,minecraft:soul_sand)
B(-7,94,-2,minecraft:soul_sand)
B(-7,95,-2,minecraft:soul_sand)
B(-7,96,-2,minecraft:soul_sand)
B(-7,97,-2,minecraft:soul_sand)
B(-7,98,-2,minecraft:soul_sand)
B(-7,99,-2,minecraft:soul_sand)
B(-7,100,-2,minecraft:soul_sand)
B(-7,101,-2,minecraft:soul_sand)
B(-7,102,-2,minecraft:soul_sand)
B(-7,103,-2,minecraft:soul_sand)
B(-7,104,-2,minecraft:soul_sand)
B(-7,105,-2,minecraft:soul_sand)
B(-7,106,-2,minecraft:soul_sand)
B(-7,107,-2,minecraft:soul_sand)
B(-7,108,-2,minecraft:soul_sand)
B(-7,109,-2,minecraft:soul_sand)
B(-7,110,-2,minecraft:soul_sand)
B(-7,111,-2,minecraft:soul_sand)
B(-7,112,-2,minecraft:soul_sand)
B(-7,113,-2,minecraft:soul_sand)
B(-7,114,-2,minecraft:soul_sand)
B(-7,115,-2,minecraft:soul_sand)
B(-7,116,-2,minecraft:soul_sand)
B(-7,0,-1,minecraft:soul_sand)
B(-7,1,-1,minecraft:soul_sand)
B(-7,2,-1,minecraft:soul_sand)
B(-7,3,-1,minecraft:soul_sand)
B(-7,4,-1,minecraft:soul_sand)
B(-7,5,-1,minecraft:soul_sand)
B(-7,6,-1,minecraft:soul_sand)
B(-7,7,-1,minecraft:soul_sand)
B(-7,8,-1,minecraft:soul_sand)
B(-7,9,-1,minecraft:soul_sand)
B(-7,10,-1,minecraft:soul_sand)
B(-7,11,-1,minecraft:soul_sand)
B(-7,12,-1,minecraft:soul_sand)
B(-7,13,-1,minecraft:soul_sand)
B(-7,14,-1,minecraft:soul_sand)
B(-7,15,-1,minecraft:soul_sand)
B(-7,16,-1,minecraft:soul_sand)
B(-7,17,-1,minecraft:soul_sand)
B(-7,18,-1,minecraft:soul_sand)
B(-7,19,-1,minecraft:soul_sand)
B(-7,20,-1,minecraft:soul_sand)
B(-7,21,-1,minecraft:soul_sand)
B(-7,22,-1,minecraft:soul_sand)
B(-7,23,-1,minecraft:soul_sand)
B(-7,24,-1,minecraft:soul_sand)
B(-7,25,-1,minecraft:soul_sand)
B(-7,26,-1,minecraft:soul_sand)
B(-7,27,-1,minecraft:soul_sand)
B(-7,28,-1,minecraft:soul_sand)
B(-7,83,-1,minecraft:soul_sand)
B(-7,84,-1,minecraft:soul_sand)
B(-7,85,-1,minecraft:soul_sand)
B(-7,86,-1,minecraft:soul_sand)
B(-7,87,-1,minecraft:soul_sand)
B(-7,88,-1,minecraft:soul_sand)
B(-7,89,-1,minecraft:soul_sand)
B(-7,90,-1,minecraft:soul_sand)
B(-7,91,-1,minecraft:soul_sand)
B(-7,92,-1,minecraft:soul_sand)
B(-7,93,-1,minecraft:soul_sand)
B(-7,94,-1,minecraft:soul_sand)
B(-7,95,-1,minecraft:soul_sand)
B(-7,96,-1,minecraft:soul_sand)
B(-7,97,-1,minecraft:soul_sand)
B(-7,98,-1,minecraft:soul_sand)
B(-7,99,-1,minecraft:soul_sand)
B(-7,100,-1,minecraft:soul_sand)
B(-7,101,-1,minecraft:soul_sand)
B(-7,102,-1,minecraft:soul_sand)
B(-7,103,-1,minecraft:soul_sand)
B(-7,104,-1,minecraft:soul_sand)
B(-7,105,-1,minecraft:soul_sand)
B(-7,106,-1,minecraft:soul_sand)
B(-7,107,-1,minecraft:soul_sand)
B(-7,108,-1,minecraft:soul_sand)
B(-7,109,-1,minecraft:soul_sand)
B(-7,110,-1,minecraft:soul_sand)
B(-7,111,-1,minecraft:soul_sand)
B(-7,112,-1,minecraft:soul_sand)
B(-7,113,-1,minecraft:soul_sand)
B(-7,114,-1,minecraft:soul_sand)
B(-7,115,-1,minecraft:soul_sand)
B(-7,116,-1,minecraft:soul_sand)
B(-7,0,0,minecraft:soul_sand)
B(-7,1,0,minecraft:soul_sand)
B(-7,2,0,minecraft:soul_sand)
B(-7,3,0,minecraft:soul_sand)
B(-7,4,0,minecraft:soul_sand)
B(-7,5,0,minecraft:soul_sand)
B(-7,6,0,minecraft:soul_sand)
B(-7,7,0,minecraft:soul_sand)
B(-7,8,0,minecraft:soul_sand)
B(-7,9,0,minecraft:soul_sand)
B(-7,10,0,minecraft:soul_sand)
B(-7,11,0,minecraft:soul_sand)
B(-7,12,0,minecraft:soul_sand)
B(-7,13,0,minecraft:soul_sand)
B(-7,14,0,minecraft:soul_sand)
B(-7,15,0,minecraft:soul_sand)
B(-7,16,0,minecraft:soul_sand)
B(-7,17,0,minecraft:soul_sand)
B(-7,18,0,minecraft:soul_sand)
B(-7,19,0,minecraft:soul_sand)
B(-7,20,0,minecraft:soul_sand)
B(-7,21,0,minecraft:soul_sand)
B(-7,22,0,minecraft:soul_sand)
B(-7,23,0,minecraft:soul_sand)
B(-7,24,0,minecraft:soul_sand)
B(-7,25,0,minecraft:soul_sand)
B(-7,26,0,minecraft:soul_sand)
B(-7,27,0,minecraft:soul_sand)
B(-7,83,0,minecraft:soul_sand)
B(-7,84,0,minecraft:soul_sand)
B(-7,85,0,minecraft:soul_sand)
B(-7,86,0,minecraft:soul_sand)
B(-7,87,0,minecraft:soul_sand)
B(-7,88,0,minecraft:soul_sand)
B(-7,89,0,minecraft:soul_sand)
B(-7,90,0,minecraft:soul_sand)
B(-7,91,0,minecraft:soul_sand)
B(-7,92,0,minecraft:soul_sand)
B(-7,93,0,minecraft:soul_sand)
B(-7,94,0,minecraft:soul_sand)
B(-7,95,0,minecraft:soul_sand)
B(-7,96,0,minecraft:soul_sand)
B(-7,97,0,minecraft:soul_sand)
B(-7,98,0,minecraft:soul_sand)
B(-7,99,0,minecraft:soul_sand)
B(-7,100,0,minecraft:soul_sand)
B(-7,101,0,minecraft:soul_sand)
B(-7,102,0,minecraft:soul_sand)
B(-7,103,0,minecraft:soul_sand)
B(-7,104,0,minecraft:soul_sand)
B(-7,105,0,minecraft:soul_sand)
B(-7,106,0,minecraft:soul_sand)
B(-7,107,0,minecraft:soul_sand)
B(-7,108,0,minecraft:soul_sand)
B(-7,109,0,minecraft:soul_sand)
B(-7,110,0,minecraft:soul_sand)
B(-7,111,0,minecraft:soul_sand)
B(-7,112,0,minecraft:soul_sand)
B(-7,113,0,minecraft:soul_sand)
B(-7,114,0,minecraft:soul_sand)
B(-7,115,0,minecraft:soul_sand)
B(-7,116,0,minecraft:soul_sand)
B(-7,0,1,minecraft:soul_sand)
B(-7,1,1,minecraft:soul_sand)
B(-7,2,1,minecraft:soul_sand)
B(-7,3,1,minecraft:soul_sand)
B(-7,4,1,minecraft:soul_sand)
B(-7,5,1,minecraft:soul_sand)
B(-7,6,1,minecraft:soul_sand)
B(-7,7,1,minecraft:soul_sand)
B(-7,8,1,minecraft:soul_sand)
B(-7,9,1,minecraft:soul_sand)
B(-7,10,1,minecraft:soul_sand)
B(-7,11,1,minecraft:soul_sand)
B(-7,12,1,minecraft:soul_sand)
B(-7,13,1,minecraft:soul_sand)
B(-7,14,1,minecraft:soul_sand)
B(-7,15,1,minecraft:soul_sand)
B(-7,16,1,minecraft:soul_sand)
B(-7,17,1,minecraft:soul_sand)
B(-7,18,1,minecraft:soul_sand)
B(-7,19,1,minecraft:soul_sand)
B(-7,20,1,minecraft:soul_sand)
B(-7,21,1,minecraft:soul_sand)
B(-7,22,1,minecraft:soul_sand)
B(-7,23,1,minecraft:soul_sand)
B(-7,24,1,minecraft:soul_sand)
B(-7,25,1,minecraft:soul_sand)
B(-7,26,1,minecraft:soul_sand)
B(-7,83,1,minecraft:soul_sand)
B(-7,84,1,minecraft:soul_sand)
B(-7,85,1,minecraft:soul_sand)
B(-7,86,1,minecraft:soul_sand)
B(-7,87,1,minecraft:soul_sand)
B(-7,88,1,minecraft:soul_sand)
B(-7,89,1,minecraft:soul_sand)
B(-7,90,1,minecraft:soul_sand)
B(-7,91,1,minecraft:soul_sand)
B(-7,92,1,minecraft:soul_sand)
B(-7,93,1,minecraft:soul_sand)
B(-7,94,1,minecraft:soul_sand)
B(-7,95,1,minecraft:soul_sand)
B(-7,96,1,minecraft:soul_sand)
B(-7,97,1,minecraft:soul_sand)
B(-7,98,1,minecraft:soul_sand)
B(-7,99,1,minecraft:soul_sand)
B(-7,100,1,minecraft:soul_sand)
B(-7,101,1,minecraft:soul_sand)
B(-7,102,1,minecraft:soul_sand)
B(-7,103,1,minecraft:soul_sand)
B(-7,104,1,minecraft:soul_sand)
B(-7,105,1,minecraft:soul_sand)
B(-7,106,1,minecraft:soul_sand)
B(-7,107,1,minecraft:soul_sand)
B(-7,108,1,minecraft:soul_sand)
B(-7,109,1,minecraft:soul_sand)
B(-7,110,1,minecraft:soul_sand)
B(-7,111,1,minecraft:soul_sand)
B(-7,112,1,minecraft:soul_sand)
B(-7,113,1,minecraft:soul_sand)
B(-7,114,1,minecraft:soul_sand)
B(-7,115,1,minecraft:soul_sand)
B(-7,116,1,minecraft:soul_sand)
B(-7,0,2,minecraft:soul_sand)
B(-7,1,2,minecraft:soul_sand)
B(-7,2,2,minecraft:soul_sand)
B(-7,3,2,minecraft:soul_sand)
B(-7,4,2,minecraft:soul_sand)
B(-7,5,2,minecraft:soul_sand)
B(-7,6,2,minecraft:soul_sand)
B(-7,7,2,minecraft:soul_sand)
B(-7,8,2,minecraft:soul_sand)
B(-7,9,2,minecraft:soul_sand)
B(-7,10,2,minecraft:soul_sand)
B(-7,11,2,minecraft:soul_sand)
B(-7,12,2,minecraft:soul_sand)
B(-7,13,2,minecraft:soul_sand)
B(-7,14,2,minecraft:soul_sand)
B(-7,15,2,minecraft:soul_sand)
B(-7,16,2,minecraft:soul_sand)
B(-7,17,2,minecraft:soul_sand)
B(-7,18,2,minecraft:soul_sand)
B(-7,19,2,minecraft:soul_sand)
B(-7,20,2,minecraft:soul_sand)
B(-7,21,2,minecraft:soul_sand)
B(-7,22,2,minecraft:soul_sand)
B(-7,23,2,minecraft:soul_sand)
B(-7,24,2,minecraft:soul_sand)
B(-7,25,2,minecraft:soul_sand)
B(-7,84,2,minecraft:soul_sand)
B(-7,85,2,minecraft:soul_sand)
B(-7,86,2,minecraft:soul_sand)
B(-7,87,2,minecraft:soul_sand)
B(-7,88,2,minecraft:soul_sand)
B(-7,89,2,minecraft:soul_sand)
B(-7,90,2,minecraft:soul_sand)
B(-7,91,2,minecraft:soul_sand)
B(-7,92,2,minecraft:soul_sand)
B(-7,93,2,minecraft:soul_sand)
B(-7,94,2,minecraft:soul_sand)
B(-7,95,2,minecraft:soul_sand)
B(-7,96,2,minecraft:soul_sand)
B(-7,97,2,minecraft:soul_sand)
B(-7,98,2,minecraft:soul_sand)
B(-7,99,2,minecraft:soul_sand)
B(-7,100,2,minecraft:soul_sand)
B(-7,101,2,minecraft:soul_sand)
B(-7,102,2,minecraft:soul_sand)
B(-7,103,2,minecraft:soul_sand)
B(-7,104,2,minecraft:soul_sand)
B(-7,105,2,minecraft:soul_sand)
B(-7,106,2,minecraft:soul_sand)
B(-7,107,2,minecraft:soul_sand)
B(-7,108,2,minecraft:soul_sand)
B(-7,109,2,minecraft:soul_sand)
B(-7,110,2,minecraft:soul_sand)
B(-7,111,2,minecraft:soul_sand)
B(-7,112,2,minecraft:soul_sand)
B(-7,113,2,minecraft:soul_sand)
B(-7,114,2,minecraft:soul_sand)
B(-7,115,2,minecraft:soul_sand)
B(-7,116,2,minecraft:soul_sand)
B(-7,0,3,minecraft:soul_sand)
B(-7,1,3,minecraft:soul_sand)
B(-7,2,3,minecraft:soul_sand)
B(-7,3,3,minecraft:soul_sand)
B(-7,4,3,minecraft:soul_sand)
B(-7,5,3,minecraft:soul_sand)
B(-7,6,3,minecraft:soul_sand)
B(-7,7,3,minecraft:soul_sand)
B(-7,8,3,minecraft:soul_sand)
B(-7,9,3,minecraft:soul_sand)
B(-7,10,3,minecraft:soul_sand)
B(-7,11,3,minecraft:soul_sand)
B(-7,12,3,minecraft:soul_sand)
B(-7,13,3,minecraft:soul_sand)
B(-7,14,3,minecraft:soul_sand)
B(-7,15,3,minecraft:soul_sand)
B(-7,16,3,minecraft:soul_sand)
B(-7,17,3,minecraft:soul_sand)
B(-7,18,3,minecraft:soul_sand)
B(-7,19,3,minecraft:soul_sand)
B(-7,20,3,minecraft:soul_sand)
B(-7,21,3,minecraft:soul_sand)
B(-7,22,3,minecraft:soul_sand)
B(-7,85,3,minecraft:soul_sand)
B(-7,86,3,minecraft:soul_sand)
B(-7,87,3,minecraft:soul_sand)
B(-7,88,3,minecraft:soul_sand)
B(-7,89,3,minecraft:soul_sand)
B(-7,90,3,minecraft:soul_sand)
B(-7,91,3,minecraft:soul_sand)
B(-7,92,3,minecraft:soul_sand)
B(-7,93,3,minecraft:soul_sand)
B(-7,94,3,minecraft:soul_sand)
B(-7,95,3,minecraft:soul_sand)
B(-7,96,3,minecraft:soul_sand)
B(-7,97,3,minecraft:soul_sand)
B(-7,98,3,minecraft:soul_sand)
B(-7,99,3,minecraft:soul_sand)
B(-7,100,3,minecraft:soul_sand)
B(-7,101,3,minecraft:soul_sand)
B(-7,102,3,minecraft:soul_sand)
B(-7,103,3,minecraft:soul_sand)
B(-7,104,3,minecraft:soul_sand)
B(-7,105,3,minecraft:soul_sand)
B(-7,106,3,minecraft:soul_sand)
B(-7,107,3,minecraft:soul_sand)
B(-7,108,3,minecraft:soul_sand)
B(-7,109,3,minecraft:soul_sand)
B(-7,110,3,minecraft:soul_sand)
B(-7,111,3,minecraft:soul_sand)
B(-7,112,3,minecraft:soul_sand)
B(-7,113,3,minecraft:soul_sand)
B(-7,114,3,minecraft:soul_sand)
B(-7,115,3,minecraft:soul_sand)
B(-7,116,3,minecraft:soul_sand)
B(-7,0,4,minecraft:soul_sand)
B(-7,1,4,minecraft:soul_sand)
B(-7,2,4,minecraft:soul_sand)
B(-7,3,4,minecraft:soul_sand)
B(-7,4,4,minecraft:soul_sand)
B(-7,5,4,minecraft:soul_sand)
B(-7,6,4,minecraft:soul_sand)
B(-7,7,4,minecraft:soul_sand)
B(-7,8,4,minecraft:soul_sand)
B(-7,9,4,minecraft:soul_sand)
B(-7,10,4,minecraft:soul_sand)
B(-7,11,4,minecraft:soul_sand)
B(-7,12,4,minecraft:soul_sand)
B(-7,13,4,minecraft:soul_sand)
B(-7,14,4,minecraft:soul_sand)
B(-7,15,4,minecraft:soul_sand)
B(-7,16,4,minecraft:soul_sand)
B(-7,17,4,minecraft:soul_sand)
B(-7,18,4,minecraft:soul_sand)
B(-7,19,4,minecraft:soul_sand)
B(-7,20,4,minecraft:soul_sand)
B(-7,21,4,minecraft:soul_sand)
B(-7,22,4,minecraft:soul_sand)
B(-7,87,4,minecraft:soul_sand)
B(-7,88,4,minecraft:soul_sand)
B(-7,89,4,minecraft:soul_sand)
B(-7,90,4,minecraft:soul_sand)
B(-7,91,4,minecraft:soul_sand)
B(-7,92,4,minecraft:soul_sand)
B(-7,93,4,minecraft:soul_sand)
B(-7,94,4,minecraft:soul_sand)
B(-7,95,4,minecraft:soul_sand)
B(-7,96,4,minecraft:soul_sand)
B(-7,97,4,minecraft:soul_sand)
B(-7,98,4,minecraft:soul_sand)
B(-7,99,4,minecraft:soul_sand)
B(-7,100,4,minecraft:soul_sand)
B(-7,101,4,minecraft:soul_sand)
B(-7,102,4,minecraft:soul_sand)
B(-7,103,4,minecraft:soul_sand)
B(-7,104,4,minecraft:soul_sand)
B(-7,105,4,minecraft:soul_sand)
B(-7,106,4,minecraft:soul_sand)
B(-7,107,4,minecraft:soul_sand)
B(-7,108,4,minecraft:soul_sand)
B(-7,109,4,minecraft:soul_sand)
B(-7,110,4,minecraft:soul_sand)
B(-7,111,4,minecraft:soul_sand)
B(-7,112,4,minecraft:soul_sand)
B(-7,113,4,minecraft:soul_sand)
B(-7,114,4,minecraft:soul_sand)
B(-7,115,4,minecraft:soul_sand)
B(-7,116,4,minecraft:soul_sand)
B(-7,0,5,minecraft:soul_sand)
B(-7,1,5,minecraft:soul_sand)
B(-7,2,5,minecraft:soul_sand)
B(-7,3,5,minecraft:soul_sand)
B(-7,4,5,minecraft:soul_sand)
B(-7,5,5,minecraft:soul_sand)
B(-7,6,5,minecraft:soul_sand)
B(-7,7,5,minecraft:soul_sand)
B(-7,8,5,minecraft:soul_sand)
B(-7,9,5,minecraft:soul_sand)
B(-7,10,5,minecraft:soul_sand)
B(-7,11,5,minecraft:soul_sand)
B(-7,12,5,minecraft:soul_sand)
B(-7,13,5,minecraft:soul_sand)
B(-7,14,5,minecraft:soul_sand)
B(-7,15,5,minecraft:soul_sand)
B(-7,16,5,minecraft:soul_sand)
B(-7,17,5,minecraft:soul_sand)
B(-7,18,5,minecraft:soul_sand)
B(-7,19,5,minecraft:soul_sand)
B(-7,20,5,minecraft:soul_sand)
B(-7,21,5,minecraft:soul_sand)
B(-7,89,5,minecraft:soul_sand)
B(-7,90,5,minecraft:soul_sand)
B(-7,91,5,minecraft:soul_sand)
B(-7,92,5,minecraft:soul_sand)
B(-7,93,5,minecraft:soul_sand)
B(-7,94,5,minecraft:soul_sand)
B(-7,95,5,minecraft:soul_sand)
B(-7,96,5,minecraft:soul_sand)
B(-7,97,5,minecraft:soul_sand)
B(-7,98,5,minecraft:soul_sand)
B(-7,99,5,minecraft:soul_sand)
B(-7,100,5,minecraft:soul_sand)
B(-7,101,5,minecraft:soul_sand)
B(-7,102,5,minecraft:soul_sand)
B(-7,103,5,minecraft:soul_sand)
B(-7,104,5,minecraft:soul_sand)
B(-7,105,5,minecraft:soul_sand)
B(-7,106,5,minecraft:soul_sand)
B(-7,107,5,minecraft:soul_sand)
B(-7,108,5,minecraft:soul_sand)
B(-7,109,5,minecraft:soul_sand)
B(-7,110,5,minecraft:soul_sand)
B(-7,111,5,minecraft:soul_sand)
B(-7,112,5,minecraft:soul_sand)
B(-7,113,5,minecraft:soul_sand)
B(-7,114,5,minecraft:soul_sand)
B(-7,115,5,minecraft:soul_sand)
B(-7,116,5,minecraft:soul_sand)
B(-7,0,6,minecraft:soul_sand)
B(-7,1,6,minecraft:soul_sand)
B(-7,2,6,minecraft:soul_sand)
B(-7,3,6,minecraft:soul_sand)
B(-7,4,6,minecraft:soul_sand)
B(-7,5,6,minecraft:soul_sand)
B(-7,6,6,minecraft:soul_sand)
B(-7,7,6,minecraft:soul_sand)
B(-7,8,6,minecraft:soul_sand)
B(-7,9,6,minecraft:soul_sand)
B(-7,10,6,minecraft:soul_sand)
B(-7,11,6,minecraft:soul_sand)
B(-7,12,6,minecraft:soul_sand)
B(-7,13,6,minecraft:soul_sand)
B(-7,14,6,minecraft:soul_sand)
B(-7,15,6,minecraft:soul_sand)
B(-7,16,6,minecraft:soul_sand)
B(-7,17,6,minecraft:soul_sand)
B(-7,18,6,minecraft:soul_sand)
B(-7,19,6,minecraft:soul_sand)
B(-7,20,6,minecraft:soul_sand)
B(-7,21,6,minecraft:soul_sand)
B(-7,90,6,minecraft:soul_sand)
B(-7,91,6,minecraft:soul_sand)
B(-7,92,6,minecraft:soul_sand)
B(-7,93,6,minecraft:soul_sand)
B(-7,94,6,minecraft:soul_sand)
B(-7,95,6,minecraft:soul_sand)
B(-7,96,6,minecraft:soul_sand)
B(-7,97,6,minecraft:soul_sand)
B(-7,98,6,minecraft:soul_sand)
B(-7,99,6,minecraft:soul_sand)
B(-7,100,6,minecraft:soul_sand)
B(-7,101,6,minecraft:soul_sand)
B(-7,102,6,minecraft:soul_sand)
B(-7,103,6,minecraft:soul_sand)
B(-7,104,6,minecraft:soul_sand)
B(-7,105,6,minecraft:soul_sand)
B(-7,106,6,minecraft:soul_sand)
B(-7,107,6,minecraft:soul_sand)
B(-7,108,6,minecraft:soul_sand)
B(-7,109,6,minecraft:soul_sand)
B(-7,110,6,minecraft:soul_sand)
B(-7,111,6,minecraft:soul_sand)
B(-7,112,6,minecraft:soul_sand)
B(-7,113,6,minecraft:soul_sand)
B(-7,114,6,minecraft:soul_sand)
B(-7,115,6,minecraft:soul_sand)
B(-7,116,6,minecraft:soul_sand)
B(-7,0,7,minecraft:soul_sand)
B(-7,1,7,minecraft:soul_sand)
B(-7,2,7,minecraft:soul_sand)
B(-7,3,7,minecraft:soul_sand)
B(-7,4,7,minecraft:soul_sand)
B(-7,5,7,minecraft:soul_sand)
B(-7,6,7,minecraft:soul_sand)
B(-7,7,7,minecraft:soul_sand)
B(-7,8,7,minecraft:soul_sand)
B(-7,9,7,minecraft:soul_sand)
B(-7,10,7,minecraft:soul_sand)
B(-7,11,7,minecraft:soul_sand)
B(-7,12,7,minecraft:soul_sand)
B(-7,13,7,minecraft:soul_sand)
B(-7,14,7,minecraft:soul_sand)
B(-7,15,7,minecraft:soul_sand)
B(-7,16,7,minecraft:soul_sand)
B(-7,17,7,minecraft:soul_sand)
B(-7,18,7,minecraft:soul_sand)
B(-7,19,7,minecraft:soul_sand)
B(-7,20,7,minecraft:soul_sand)
B(-7,21,7,minecraft:soul_sand)
B(-7,91,7,minecraft:soul_sand)
B(-7,92,7,minecraft:soul_sand)
B(-7,93,7,minecraft:soul_sand)
B(-7,94,7,minecraft:soul_sand)
B(-7,95,7,minecraft:soul_sand)
B(-7,96,7,minecraft:soul_sand)
B(-7,97,7,minecraft:soul_sand)
B(-7,98,7,minecraft:soul_sand)
B(-7,99,7,minecraft:soul_sand)
B(-7,100,7,minecraft:soul_sand)
B(-7,101,7,minecraft:soul_sand)
B(-7,102,7,minecraft:soul_sand)
B(-7,103,7,minecraft:soul_sand)
B(-7,104,7,minecraft:soul_sand)
B(-7,105,7,minecraft:soul_sand)
B(-7,106,7,minecraft:soul_sand)
B(-7,107,7,minecraft:soul_sand)
B(-7,108,7,minecraft:soul_sand)
B(-7,109,7,minecraft:soul_sand)
B(-7,110,7,minecraft:soul_sand)
B(-7,111,7,minecraft:soul_sand)
B(-7,112,7,minecraft:soul_sand)
B(-7,113,7,minecraft:soul_sand)
B(-7,114,7,minecraft:soul_sand)
B(-7,115,7,minecraft:soul_sand)
B(-7,116,7,minecraft:soul_sand)
B(-7,0,8,minecraft:soul_sand)
B(-7,1,8,minecraft:soul_sand)
B(-7,2,8,minecraft:soul_sand)
B(-7,3,8,minecraft:soul_sand)
B(-7,4,8,minecraft:soul_sand)
B(-7,5,8,minecraft:soul_sand)
B(-7,6,8,minecraft:soul_sand)
B(-7,7,8,minecraft:soul_sand)
B(-7,8,8,minecraft:soul_sand)
B(-7,9,8,minecraft:soul_sand)
B(-7,10,8,minecraft:soul_sand)
B(-7,11,8,minecraft:soul_sand)
B(-7,12,8,minecraft:soul_sand)
B(-7,13,8,minecraft:soul_sand)
B(-7,14,8,minecraft:soul_sand)
B(-7,15,8,minecraft:soul_sand)
B(-7,16,8,minecraft:soul_sand)
B(-7,17,8,minecraft:soul_sand)
B(-7,18,8,minecraft:soul_sand)
B(-7,19,8,minecraft:soul_sand)
B(-7,20,8,minecraft:soul_sand)
B(-7,93,8,minecraft:soul_sand)
B(-7,94,8,minecraft:soul_sand)
B(-7,95,8,minecraft:soul_sand)
B(-7,96,8,minecraft:soul_sand)
B(-7,97,8,minecraft:soul_sand)
B(-7,98,8,minecraft:soul_sand)
B(-7,99,8,minecraft:soul_sand)
B(-7,100,8,minecraft:soul_sand)
B(-7,101,8,minecraft:soul_sand)
B(-7,102,8,minecraft:soul_sand)
B(-7,103,8,minecraft:soul_sand)
B(-7,104,8,minecraft:soul_sand)
B(-7,105,8,minecraft:soul_sand)
B(-7,106,8,minecraft:soul_sand)
B(-7,107,8,minecraft:soul_sand)
B(-7,108,8,minecraft:soul_sand)
B(-7,109,8,minecraft:soul_sand)
B(-7,110,8,minecraft:soul_sand)
B(-7,111,8,minecraft:soul_sand)
B(-7,112,8,minecraft:soul_sand)
B(-7,113,8,minecraft:soul_sand)
B(-7,114,8,minecraft:soul_sand)
B(-7,115,8,minecraft:soul_sand)
B(-7,116,8,minecraft:soul_sand)
B(-6,0,-7,minecraft:soul_sand)
B(-6,1,-7,minecraft:soul_sand)
B(-6,2,-7,minecraft:soul_sand)
B(-6,3,-7,minecraft:soul_sand)
B(-6,4,-7,minecraft:soul_sand)
B(-6,5,-7,minecraft:soul_sand)
B(-6,6,-7,minecraft:soul_sand)
B(-6,7,-7,minecraft:soul_sand)
B(-6,8,-7,minecraft:soul_sand)
B(-6,9,-7,minecraft:soul_sand)
B(-6,10,-7,minecraft:soul_sand)
B(-6,11,-7,minecraft:soul_sand)
B(-6,12,-7,minecraft:soul_sand)
B(-6,13,-7,minecraft:soul_sand)
B(-6,14,-7,minecraft:soul_sand)
B(-6,15,-7,minecraft:soul_sand)
B(-6,16,-7,minecraft:soul_sand)
B(-6,17,-7,minecraft:soul_sand)
B(-6,18,-7,minecraft:soul_sand)
B(-6,19,-7,minecraft:soul_sand)
B(-6,20,-7,minecraft:soul_sand)
B(-6,21,-7,minecraft:soul_sand)
B(-6,22,-7,minecraft:soul_sand)
B(-6,23,-7,minecraft:soul_sand)
B(-6,24,-7,minecraft:soul_sand)
B(-6,25,-7,minecraft:soul_sand)
B(-6,26,-7,minecraft:soul_sand)
B(-6,27,-7,minecraft:soul_sand)
B(-6,28,-7,minecraft:soul_sand)
B(-6,29,-7,minecraft:soul_sand)
B(-6,83,-7,minecraft:soul_sand)
B(-6,84,-7,minecraft:soul_sand)
B(-6,85,-7,minecraft:soul_sand)
B(-6,86,-7,minecraft:soul_sand)
B(-6,87,-7,minecraft:soul_sand)
B(-6,88,-7,minecraft:soul_sand)
B(-6,89,-7,minecraft:soul_sand)
B(-6,90,-7,minecraft:soul_sand)
B(-6,91,-7,minecraft:soul_sand)
B(-6,92,-7,minecraft:soul_sand)
B(-6,93,-7,minecraft:soul_sand)
B(-6,94,-7,minecraft:soul_sand)
B(-6,95,-7,minecraft:soul_sand)
B(-6,96,-7,minecraft:soul_sand)
B(-6,97,-7,minecraft:soul_sand)
B(-6,98,-7,minecraft:soul_sand)
B(-6,99,-7,minecraft:soul_sand)
B(-6,100,-7,minecraft:soul_sand)
B(-6,101,-7,minecraft:soul_sand)
B(-6,102,-7,minecraft:soul_sand)
B(-6,103,-7,minecraft:soul_sand)
B(-6,104,-7,minecraft:soul_sand)
B(-6,105,-7,minecraft:soul_sand)
B(-6,106,-7,minecraft:soul_sand)
B(-6,107,-7,minecraft:soul_sand)
B(-6,108,-7,minecraft:soul_sand)
B(-6,109,-7,minecraft:soul_sand)
B(-6,110,-7,minecraft:soul_sand)
B(-6,111,-7,minecraft:soul_sand)
B(-6,112,-7,minecraft:soul_sand)
B(-6,113,-7,minecraft:soul_sand)
B(-6,114,-7,minecraft:soul_sand)
B(-6,115,-7,minecraft:soul_sand)
B(-6,116,-7,minecraft:soul_sand)
B(-6,0,-6,minecraft:soul_sand)
B(-6,1,-6,minecraft:soul_sand)
B(-6,2,-6,minecraft:soul_sand)
B(-6,3,-6,minecraft:soul_sand)
B(-6,4,-6,minecraft:soul_sand)
B(-6,5,-6,minecraft:soul_sand)
B(-6,6,-6,minecraft:soul_sand)
B(-6,7,-6,minecraft:soul_sand)
B(-6,8,-6,minecraft:soul_sand)
B(-6,9,-6,minecraft:soul_sand)
B(-6,10,-6,minecraft:soul_sand)
B(-6,11,-6,minecraft:soul_sand)
B(-6,12,-6,minecraft:soul_sand)
B(-6,13,-6,minecraft:soul_sand)
B(-6,14,-6,minecraft:soul_sand)
B(-6,15,-6,minecraft:soul_sand)
B(-6,16,-6,minecraft:soul_sand)
B(-6,17,-6,minecraft:soul_sand)
B(-6,18,-6,minecraft:soul_sand)
B(-6,19,-6,minecraft:soul_sand)
B(-6,20,-6,minecraft:soul_sand)
B(-6,21,-6,minecraft:soul_sand)
B(-6,22,-6,minecraft:soul_sand)
B(-6,23,-6,minecraft:soul_sand)
B(-6,24,-6,minecraft:soul_sand)
B(-6,25,-6,minecraft:soul_sand)
B(-6,26,-6,minecraft:soul_sand)
B(-6,27,-6,minecraft:soul_sand)
B(-6,28,-6,minecraft:soul_sand)
B(-6,29,-6,minecraft:soul_sand)
B(-6,30,-6,minecraft:soul_sand)
B(-6,31,-6,minecraft:soul_sand)
B(-6,32,-6,minecraft:soul_sand)
B(-6,33,-6,minecraft:soul_sand)
B(-6,34,-6,minecraft:soul_sand)
B(-6,35,-6,minecraft:soul_sand)
B(-6,36,-6,minecraft:soul_sand)
B(-6,37,-6,minecraft:soul_sand)
B(-6,38,-6,minecraft:soul_sand)
B(-6,39,-6,minecraft:soul_sand)
B(-6,40,-6,minecraft:soul_sand)
B(-6,61,-6,minecraft:soul_sand)
B(-6,62,-6,minecraft:soul_sand)
B(-6,63,-6,minecraft:soul_sand)
B(-6,82,-6,minecraft:soul_sand)
B(-6,83,-6,minecraft:soul_sand)
B(-6,84,-6,minecraft:soul_sand)
B(-6,85,-6,minecraft:soul_sand)
B(-6,86,-6,minecraft:soul_sand)
B(-6,87,-6,minecraft:soul_sand)
B(-6,88,-6,minecraft:soul_sand)
B(-6,89,-6,minecraft:soul_sand)
B(-6,90,-6,minecraft:soul_sand)
B(-6,91,-6,minecraft:soul_sand)
B(-6,92,-6,minecraft:soul_sand)
B(-6,93,-6,minecraft:soul_sand)
B(-6,94,-6,minecraft:soul_sand)
B(-6,95,-6,minecraft:soul_sand)
B(-6,96,-6,minecraft:soul_sand)
B(-6,97,-6,minecraft:soul_sand)
B(-6,98,-6,minecraft:soul_sand)
B(-6,99,-6,minecraft:soul_sand)
B(-6,100,-6,minecraft:soul_sand)
B(-6,101,-6,minecraft:soul_sand)
B(-6,102,-6,minecraft:soul_sand)
B(-6,103,-6,minecraft:soul_sand)
B(-6,104,-6,minecraft:soul_sand)
B(-6,105,-6,minecraft:soul_sand)
B(-6,106,-6,minecraft:soul_sand)
B(-6,107,-6,minecraft:soul_sand)
B(-6,108,-6,minecraft:soul_sand)
B(-6,109,-6,minecraft:soul_sand)
B(-6,110,-6,minecraft:soul_sand)
B(-6,111,-6,minecraft:soul_sand)
B(-6,112,-6,minecraft:soul_sand)
B(-6,113,-6,minecraft:soul_sand)
B(-6,114,-6,minecraft:soul_sand)
B(-6,115,-6,minecraft:soul_sand)
B(-6,116,-6,minecraft:soul_sand)
B(-6,0,-5,minecraft:soul_sand)
B(-6,1,-5,minecraft:soul_sand)
B(-6,2,-5,minecraft:soul_sand)
B(-6,3,-5,minecraft:soul_sand)
B(-6,4,-5,minecraft:soul_sand)
B(-6,5,-5,minecraft:soul_sand)
B(-6,6,-5,minecraft:soul_sand)
B(-6,7,-5,minecraft:soul_sand)
B(-6,8,-5,minecraft:soul_sand)
B(-6,9,-5,minecraft:soul_sand)
B(-6,10,-5,minecraft:soul_sand)
B(-6,11,-5,minecraft:soul_sand)
B(-6,12,-5,minecraft:soul_sand)
B(-6,13,-5,minecraft:soul_sand)
B(-6,14,-5,minecraft:soul_sand)
B(-6,15,-5,minecraft:soul_sand)
B(-6,16,-5,minecraft:soul_sand)
B(-6,17,-5,minecraft:soul_sand)
B(-6,18,-5,minecraft:soul_sand)
B(-6,19,-5,minecraft:soul_sand)
B(-6,20,-5,minecraft:soul_sand)
B(-6,21,-5,minecraft:soul_sand)
B(-6,22,-5,minecraft:soul_sand)
B(-6,23,-5,minecraft:soul_sand)
B(-6,24,-5,minecraft:soul_sand)
B(-6,25,-5,minecraft:soul_sand)
B(-6,26,-5,minecraft:soul_sand)
B(-6,27,-5,minecraft:soul_sand)
B(-6,28,-5,minecraft:soul_sand)
B(-6,29,-5,minecraft:soul_sand)
B(-6,30,-5,minecraft:soul_sand)
B(-6,31,-5,minecraft:soul_sand)
B(-6,32,-5,minecraft:soul_sand)
B(-6,33,-5,minecraft:soul_sand)
B(-6,34,-5,minecraft:soul_sand)
B(-6,35,-5,minecraft:soul_sand)
B(-6,36,-5,minecraft:soul_sand)
B(-6,37,-5,minecraft:soul_sand)
B(-6,38,-5,minecraft:soul_sand)
B(-6,39,-5,minecraft:soul_sand)
B(-6,40,-5,minecraft:soul_sand)
B(-6,41,-5,minecraft:soul_sand)
B(-6,42,-5,minecraft:soul_sand)
B(-6,43,-5,minecraft:soul_sand)
B(-6,44,-5,minecraft:soul_sand)
B(-6,45,-5,minecraft:soul_sand)
B(-6,46,-5,minecraft:soul_sand)
B(-6,47,-5,minecraft:soul_sand)
B(-6,48,-5,minecraft:soul_sand)
B(-6,49,-5,minecraft:soul_sand)
B(-6,50,-5,minecraft:soul_sand)
B(-6,51,-5,minecraft:soul_sand)
B(-6,52,-5,minecraft:soul_sand)
B(-6,60,-5,minecraft:soul_sand)
B(-6,61,-5,minecraft:soul_sand)
B(-6,62,-5,minecraft:soul_sand)
B(-6,63,-5,minecraft:soul_sand)
B(-6,64,-5,minecraft:soul_sand)
B(-6,83,-5,minecraft:soul_sand)
B(-6,84,-5,minecraft:soul_sand)
B(-6,85,-5,minecraft:soul_sand)
B(-6,86,-5,minecraft:soul_sand)
B(-6,87,-5,minecraft:soul_sand)
B(-6,88,-5,minecraft:soul_sand)
B(-6,89,-5,minecraft:soul_sand)
B(-6,90,-5,minecraft:soul_sand)
B(-6,91,-5,minecraft:soul_sand)
B(-6,92,-5,minecraft:soul_sand)
B(-6,93,-5,minecraft:soul_sand)
B(-6,94,-5,minecraft:soul_sand)
B(-6,95,-5,minecraft:soul_sand)
B(-6,96,-5,minecraft:soul_sand)
B(-6,97,-5,minecraft:soul_sand)
B(-6,98,-5,minecraft:soul_sand)
B(-6,99,-5,minecraft:soul_sand)
B(-6,100,-5,minecraft:soul_sand)
B(-6,101,-5,minecraft:soul_sand)
B(-6,102,-5,minecraft:soul_sand)
B(-6,103,-5,minecraft:soul_sand)
B(-6,104,-5,minecraft:soul_sand)
B(-6,105,-5,minecraft:soul_sand)
B(-6,106,-5,minecraft:soul_sand)
B(-6,107,-5,minecraft:soul_sand)
B(-6,108,-5,minecraft:soul_sand)
B(-6,109,-5,minecraft:soul_sand)
B(-6,110,-5,minecraft:soul_sand)
B(-6,111,-5,minecraft:soul_sand)
B(-6,112,-5,minecraft:soul_sand)
B(-6,113,-5,minecraft:soul_sand)
B(-6,114,-5,minecraft:soul_sand)
B(-6,115,-5,minecraft:soul_sand)
B(-6,116,-5,minecraft:soul_sand)
B(-6,0,-4,minecraft:soul_sand)
B(-6,1,-4,minecraft:soul_sand)
B(-6,2,-4,minecraft:soul_sand)
B(-6,3,-4,minecraft:soul_sand)
B(-6,4,-4,minecraft:soul_sand)
B(-6,5,-4,minecraft:soul_sand)
B(-6,6,-4,minecraft:soul_sand)
B(-6,7,-4,minecraft:soul_sand)
B(-6,8,-4,minecraft:soul_sand)
B(-6,9,-4,minecraft:soul_sand)
B(-6,10,-4,minecraft:soul_sand)
B(-6,11,-4,minecraft:soul_sand)
B(-6,12,-4,minecraft:soul_sand)
B(-6,13,-4,minecraft:soul_sand)
B(-6,14,-4,minecraft:soul_sand)
B(-6,15,-4,minecraft:soul_sand)
B(-6,16,-4,minecraft:soul_sand)
B(-6,17,-4,minecraft:soul_sand)
B(-6,18,-4,minecraft:soul_sand)
B(-6,19,-4,minecraft:soul_sand)
B(-6,20,-4,minecraft:soul_sand)
B(-6,21,-4,minecraft:soul_sand)
B(-6,22,-4,minecraft:soul_sand)
B(-6,23,-4,minecraft:soul_sand)
B(-6,24,-4,minecraft:soul_sand)
B(-6,25,-4,minecraft:soul_sand)
B(-6,26,-4,minecraft:soul_sand)
B(-6,27,-4,minecraft:soul_sand)
B(-6,28,-4,minecraft:soul_sand)
B(-6,29,-4,minecraft:soul_sand)
B(-6,30,-4,minecraft:soul_sand)
B(-6,31,-4,minecraft:soul_sand)
B(-6,32,-4,minecraft:soul_sand)
B(-6,33,-4,minecraft:soul_sand)
B(-6,34,-4,minecraft:soul_sand)
B(-6,35,-4,minecraft:soul_sand)
B(-6,36,-4,minecraft:soul_sand)
B(-6,37,-4,minecraft:soul_sand)
B(-6,38,-4,minecraft:soul_sand)
B(-6,39,-4,minecraft:soul_sand)
B(-6,40,-4,minecraft:soul_sand)
B(-6,41,-4,minecraft:soul_sand)
B(-6,42,-4,minecraft:soul_sand)
B(-6,43,-4,minecraft:soul_sand)
B(-6,44,-4,minecraft:soul_sand)
B(-6,45,-4,minecraft:soul_sand)
B(-6,46,-4,minecraft:soul_sand)
B(-6,47,-4,minecraft:soul_sand)
B(-6,48,-4,minecraft:soul_sand)
B(-6,49,-4,minecraft:soul_sand)
B(-6,50,-4,minecraft:soul_sand)
B(-6,51,-4,minecraft:soul_sand)
B(-6,52,-4,minecraft:soul_sand)
B(-6,53,-4,minecraft:soul_sand)
B(-6,54,-4,minecraft:soul_sand)
B(-6,60,-4,minecraft:soul_sand)
B(-6,61,-4,minecraft:soul_sand)
B(-6,62,-4,minecraft:soul_sand)
B(-6,63,-4,minecraft:soul_sand)
B(-6,64,-4,minecraft:soul_sand)
B(-6,65,-4,minecraft:soul_sand)
B(-6,84,-4,minecraft:soul_sand)
B(-6,85,-4,minecraft:soul_sand)
B(-6,86,-4,minecraft:soul_sand)
B(-6,87,-4,minecraft:soul_sand)
B(-6,88,-4,minecraft:soul_sand)
B(-6,89,-4,minecraft:soul_sand)
B(-6,90,-4,minecraft:soul_sand)
B(-6,91,-4,minecraft:soul_sand)
B(-6,92,-4,minecraft:soul_sand)
B(-6,93,-4,minecraft:soul_sand)
B(-6,94,-4,minecraft:soul_sand)
B(-6,95,-4,minecraft:soul_sand)
B(-6,96,-4,minecraft:soul_sand)
B(-6,97,-4,minecraft:soul_sand)
B(-6,98,-4,minecraft:soul_sand)
B(-6,99,-4,minecraft:soul_sand)
B(-6,100,-4,minecraft:soul_sand)
B(-6,101,-4,minecraft:soul_sand)
B(-6,102,-4,minecraft:soul_sand)
B(-6,103,-4,minecraft:soul_sand)
B(-6,104,-4,minecraft:soul_sand)
B(-6,105,-4,minecraft:soul_sand)
B(-6,106,-4,minecraft:soul_sand)
B(-6,107,-4,minecraft:soul_sand)
B(-6,108,-4,minecraft:soul_sand)
B(-6,109,-4,minecraft:soul_sand)
B(-6,110,-4,minecraft:soul_sand)
B(-6,111,-4,minecraft:soul_sand)
B(-6,112,-4,minecraft:soul_sand)
B(-6,113,-4,minecraft:soul_sand)
B(-6,114,-4,minecraft:soul_sand)
B(-6,115,-4,minecraft:soul_sand)
B(-6,116,-4,minecraft:soul_sand)
B(-6,0,-3,minecraft:soul_sand)
B(-6,1,-3,minecraft:soul_sand)
B(-6,2,-3,minecraft:soul_sand)
B(-6,3,-3,minecraft:soul_sand)
B(-6,4,-3,minecraft:soul_sand)
B(-6,5,-3,minecraft:soul_sand)
B(-6,6,-3,minecraft:soul_sand)
B(-6,7,-3,minecraft:soul_sand)
B(-6,8,-3,minecraft:soul_sand)
B(-6,9,-3,minecraft:soul_sand)
B(-6,10,-3,minecraft:soul_sand)
B(-6,11,-3,minecraft:soul_sand)
B(-6,12,-3,minecraft:soul_sand)
B(-6,13,-3,minecraft:soul_sand)
B(-6,14,-3,minecraft:soul_sand)
B(-6,15,-3,minecraft:soul_sand)
B(-6,16,-3,minecraft:soul_sand)
B(-6,17,-3,minecraft:soul_sand)
B(-6,18,-3,minecraft:soul_sand)
B(-6,19,-3,minecraft:soul_sand)
B(-6,20,-3,minecraft:soul_sand)
B(-6,21,-3,minecraft:soul_sand)
B(-6,22,-3,minecraft:soul_sand)
B(-6,23,-3,minecraft:soul_sand)
B(-6,24,-3,minecraft:soul_sand)
B(-6,25,-3,minecraft:soul_sand)
B(-6,26,-3,minecraft:soul_sand)
B(-6,27,-3,minecraft:soul_sand)
B(-6,28,-3,minecraft:soul_sand)
B(-6,29,-3,minecraft:soul_sand)
B(-6,30,-3,minecraft:soul_sand)
B(-6,31,-3,minecraft:soul_sand)
B(-6,32,-3,minecraft:soul_sand)
B(-6,33,-3,minecraft:soul_sand)
B(-6,34,-3,minecraft:soul_sand)
B(-6,35,-3,minecraft:soul_sand)
B(-6,36,-3,minecraft:soul_sand)
B(-6,37,-3,minecraft:soul_sand)
B(-6,38,-3,minecraft:soul_sand)
B(-6,39,-3,minecraft:soul_sand)
B(-6,40,-3,minecraft:soul_sand)
B(-6,41,-3,minecraft:soul_sand)
B(-6,42,-3,minecraft:soul_sand)
B(-6,43,-3,minecraft:soul_sand)
B(-6,44,-3,minecraft:soul_sand)
B(-6,45,-3,minecraft:soul_sand)
B(-6,46,-3,minecraft:soul_sand)
B(-6,47,-3,minecraft:soul_sand)
B(-6,48,-3,minecraft:soul_sand)
B(-6,49,-3,minecraft:soul_sand)
B(-6,50,-3,minecraft:soul_sand)
B(-6,51,-3,minecraft:soul_sand)
B(-6,52,-3,minecraft:soul_sand)
B(-6,53,-3,minecraft:soul_sand)
B(-6,54,-3,minecraft:soul_sand)
B(-6,55,-3,minecraft:soul_sand)
B(-6,60,-3,minecraft:soul_sand)
B(-6,61,-3,minecraft:soul_sand)
B(-6,62,-3,minecraft:soul_sand)
B(-6,63,-3,minecraft:soul_sand)
B(-6,64,-3,minecraft:soul_sand)
B(-6,65,-3,minecraft:soul_sand)
B(-6,66,-3,minecraft:soul_sand)
B(-6,84,-3,minecraft:soul_sand)
B(-6,85,-3,minecraft:soul_sand)
B(-6,86,-3,minecraft:soul_sand)
B(-6,87,-3,minecraft:soul_sand)
B(-6,88,-3,minecraft:soul_sand)
B(-6,89,-3,minecraft:soul_sand)
B(-6,90,-3,minecraft:soul_sand)
B(-6,91,-3,minecraft:soul_sand)
B(-6,92,-3,minecraft:soul_sand)
B(-6,93,-3,minecraft:soul_sand)
B(-6,94,-3,minecraft:soul_sand)
B(-6,95,-3,minecraft:soul_sand)
B(-6,96,-3,minecraft:soul_sand)
B(-6,97,-3,minecraft:soul_sand)
B(-6,98,-3,minecraft:soul_sand)
B(-6,99,-3,minecraft:soul_sand)
B(-6,100,-3,minecraft:soul_sand)
B(-6,101,-3,minecraft:soul_sand)
B(-6,102,-3,minecraft:soul_sand)
B(-6,103,-3,minecraft:soul_sand)
B(-6,104,-3,minecraft:soul_sand)
B(-6,105,-3,minecraft:soul_sand)
B(-6,106,-3,minecraft:soul_sand)
B(-6,107,-3,minecraft:soul_sand)
B(-6,108,-3,minecraft:soul_sand)
B(-6,109,-3,minecraft:soul_sand)
B(-6,110,-3,minecraft:soul_sand)
B(-6,111,-3,minecraft:soul_sand)
B(-6,112,-3,minecraft:soul_sand)
B(-6,113,-3,minecraft:soul_sand)
B(-6,114,-3,minecraft:soul_sand)
B(-6,115,-3,minecraft:soul_sand)
B(-6,116,-3,minecraft:soul_sand)
B(-6,0,-2,minecraft:soul_sand)
B(-6,1,-2,minecraft:soul_sand)
B(-6,2,-2,minecraft:soul_sand)
B(-6,3,-2,minecraft:soul_sand)
B(-6,4,-2,minecraft:soul_sand)
B(-6,5,-2,minecraft:soul_sand)
B(-6,6,-2,minecraft:soul_sand)
B(-6,7,-2,minecraft:soul_sand)
B(-6,8,-2,minecraft:soul_sand)
B(-6,9,-2,minecraft:soul_sand)
B(-6,10,-2,minecraft:soul_sand)
B(-6,11,-2,minecraft:soul_sand)
B(-6,12,-2,minecraft:soul_sand)
B(-6,13,-2,minecraft:soul_sand)
B(-6,14,-2,minecraft:soul_sand)
B(-6,15,-2,minecraft:soul_sand)
B(-6,16,-2,minecraft:soul_sand)
B(-6,17,-2,minecraft:soul_sand)
B(-6,18,-2,minecraft:soul_sand)
B(-6,19,-2,minecraft:soul_sand)
B(-6,20,-2,minecraft:soul_sand)
B(-6,21,-2,minecraft:soul_sand)
B(-6,22,-2,minecraft:soul_sand)
B(-6,23,-2,minecraft:soul_sand)
B(-6,24,-2,minecraft:soul_sand)
B(-6,25,-2,minecraft:soul_sand)
B(-6,26,-2,minecraft:soul_sand)
B(-6,27,-2,minecraft:soul_sand)
B(-6,28,-2,minecraft:soul_sand)
B(-6,29,-2,minecraft:soul_sand)
B(-6,30,-2,minecraft:soul_sand)
B(-6,31,-2,minecraft:soul_sand)
B(-6,32,-2,minecraft:soul_sand)
B(-6,33,-2,minecraft:soul_sand)
B(-6,34,-2,minecraft:soul_sand)
B(-6,35,-2,minecraft:soul_sand)
B(-6,36,-2,minecraft:soul_sand)
B(-6,37,-2,minecraft:soul_sand)
B(-6,38,-2,minecraft:soul_sand)
B(-6,39,-2,minecraft:soul_sand)
B(-6,40,-2,minecraft:soul_sand)
B(-6,41,-2,minecraft:soul_sand)
B(-6,42,-2,minecraft:soul_sand)
B(-6,43,-2,minecraft:soul_sand)
B(-6,44,-2,minecraft:soul_sand)
B(-6,45,-2,minecraft:soul_sand)
B(-6,46,-2,minecraft:soul_sand)
B(-6,47,-2,minecraft:soul_sand)
B(-6,48,-2,minecraft:soul_sand)
B(-6,49,-2,minecraft:soul_sand)
B(-6,50,-2,minecraft:soul_sand)
B(-6,62,-2,minecraft:soul_sand)
B(-6,63,-2,minecraft:soul_sand)
B(-6,64,-2,minecraft:soul_sand)
B(-6,65,-2,minecraft:soul_sand)
B(-6,83,-2,minecraft:soul_sand)
B(-6,84,-2,minecraft:soul_sand)
B(-6,85,-2,minecraft:soul_sand)
B(-6,86,-2,minecraft:soul_sand)
B(-6,87,-2,minecraft:soul_sand)
B(-6,88,-2,minecraft:soul_sand)
B(-6,89,-2,minecraft:soul_sand)
B(-6,90,-2,minecraft:soul_sand)
B(-6,91,-2,minecraft:soul_sand)
B(-6,92,-2,minecraft:soul_sand)
B(-6,93,-2,minecraft:soul_sand)
B(-6,94,-2,minecraft:soul_sand)
B(-6,95,-2,minecraft:soul_sand)
B(-6,96,-2,minecraft:soul_sand)
B(-6,97,-2,minecraft:soul_sand)
B(-6,98,-2,minecraft:soul_sand)
B(-6,99,-2,minecraft:soul_sand)
B(-6,100,-2,minecraft:soul_sand)
B(-6,101,-2,minecraft:soul_sand)
B(-6,102,-2,minecraft:soul_sand)
B(-6,103,-2,minecraft:soul_sand)
B(-6,104,-2,minecraft:soul_sand)
B(-6,105,-2,minecraft:soul_sand)
B(-6,106,-2,minecraft:soul_sand)
B(-6,107,-2,minecraft:soul_sand)
B(-6,108,-2,minecraft:soul_sand)
B(-6,109,-2,minecraft:soul_sand)
B(-6,110,-2,minecraft:soul_sand)
B(-6,111,-2,minecraft:soul_sand)
B(-6,112,-2,minecraft:soul_sand)
B(-6,113,-2,minecraft:soul_sand)
B(-6,114,-2,minecraft:soul_sand)
B(-6,115,-2,minecraft:soul_sand)
B(-6,116,-2,minecraft:soul_sand)
B(-6,0,-1,minecraft:soul_sand)
B(-6,1,-1,minecraft:soul_sand)
B(-6,2,-1,minecraft:soul_sand)
B(-6,3,-1,minecraft:soul_sand)
B(-6,4,-1,minecraft:soul_sand)
B(-6,5,-1,minecraft:soul_sand)
B(-6,6,-1,minecraft:soul_sand)
B(-6,7,-1,minecraft:soul_sand)
B(-6,8,-1,minecraft:soul_sand)
B(-6,9,-1,minecraft:soul_sand)
B(-6,10,-1,minecraft:soul_sand)
B(-6,11,-1,minecraft:soul_sand)
B(-6,12,-1,minecraft:soul_sand)
B(-6,13,-1,minecraft:soul_sand)
B(-6,14,-1,minecraft:soul_sand)
B(-6,15,-1,minecraft:soul_sand)
B(-6,16,-1,minecraft:soul_sand)
B(-6,17,-1,minecraft:soul_sand)
B(-6,18,-1,minecraft:soul_sand)
B(-6,19,-1,minecraft:soul_sand)
B(-6,20,-1,minecraft:soul_sand)
B(-6,21,-1,minecraft:soul_sand)
B(-6,22,-1,minecraft:soul_sand)
B(-6,23,-1,minecraft:soul_sand)
B(-6,24,-1,minecraft:soul_sand)
B(-6,25,-1,minecraft:soul_sand)
B(-6,26,-1,minecraft:soul_sand)
B(-6,27,-1,minecraft:soul_sand)
B(-6,28,-1,minecraft:soul_sand)
B(-6,29,-1,minecraft:soul_sand)
B(-6,30,-1,minecraft:soul_sand)
B(-6,31,-1,minecraft:soul_sand)
B(-6,32,-1,minecraft:soul_sand)
B(-6,33,-1,minecraft:soul_sand)
B(-6,34,-1,minecraft:soul_sand)
B(-6,35,-1,minecraft:soul_sand)
B(-6,36,-1,minecraft:soul_sand)
B(-6,83,-1,minecraft:soul_sand)
B(-6,84,-1,minecraft:soul_sand)
B(-6,85,-1,minecraft:soul_sand)
B(-6,86,-1,minecraft:soul_sand)
B(-6,87,-1,minecraft:soul_sand)
B(-6,88,-1,minecraft:soul_sand)
B(-6,89,-1,minecraft:soul_sand)
B(-6,90,-1,minecraft:soul_sand)
B(-6,91,-1,minecraft:soul_sand)
B(-6,92,-1,minecraft:soul_sand)
B(-6,93,-1,minecraft:soul_sand)
B(-6,94,-1,minecraft:soul_sand)
B(-6,95,-1,minecraft:soul_sand)
B(-6,96,-1,minecraft:soul_sand)
B(-6,97,-1,minecraft:soul_sand)
B(-6,98,-1,minecraft:soul_sand)
B(-6,99,-1,minecraft:soul_sand)
B(-6,100,-1,minecraft:soul_sand)
B(-6,101,-1,minecraft:soul_sand)
B(-6,102,-1,minecraft:soul_sand)
B(-6,103,-1,minecraft:soul_sand)
B(-6,104,-1,minecraft:soul_sand)
B(-6,105,-1,minecraft:soul_sand)
B(-6,106,-1,minecraft:soul_sand)
B(-6,107,-1,minecraft:soul_sand)
B(-6,108,-1,minecraft:soul_sand)
B(-6,109,-1,minecraft:soul_sand)
B(-6,110,-1,minecraft:soul_sand)
B(-6,111,-1,minecraft:soul_sand)
B(-6,112,-1,minecraft:soul_sand)
B(-6,113,-1,minecraft:soul_sand)
B(-6,114,-1,minecraft:soul_sand)
B(-6,115,-1,minecraft:soul_sand)
B(-6,116,-1,minecraft:soul_sand)
B(-6,0,0,minecraft:soul_sand)
B(-6,1,0,minecraft:soul_sand)
B(-6,2,0,minecraft:soul_sand)
B(-6,3,0,minecraft:soul_sand)
B(-6,4,0,minecraft:soul_sand)
B(-6,5,0,minecraft:soul_sand)
B(-6,6,0,minecraft:soul_sand)
B(-6,7,0,minecraft:soul_sand)
B(-6,8,0,minecraft:soul_sand)
B(-6,9,0,minecraft:soul_sand)
B(-6,10,0,minecraft:soul_sand)
B(-6,11,0,minecraft:soul_sand)
B(-6,12,0,minecraft:soul_sand)
B(-6,13,0,minecraft:soul_sand)
B(-6,14,0,minecraft:soul_sand)
B(-6,15,0,minecraft:soul_sand)
B(-6,16,0,minecraft:soul_sand)
B(-6,17,0,minecraft:soul_sand)
B(-6,18,0,minecraft:soul_sand)
B(-6,19,0,minecraft:soul_sand)
B(-6,20,0,minecraft:soul_sand)
B(-6,21,0,minecraft:soul_sand)
B(-6,22,0,minecraft:soul_sand)
B(-6,23,0,minecraft:soul_sand)
B(-6,24,0,minecraft:soul_sand)
B(-6,25,0,minecraft:soul_sand)
B(-6,26,0,minecraft:soul_sand)
B(-6,27,0,minecraft:soul_sand)
B(-6,28,0,minecraft:soul_sand)
B(-6,29,0,minecraft:soul_sand)
B(-6,30,0,minecraft:soul_sand)
B(-6,31,0,minecraft:soul_sand)
B(-6,83,0,minecraft:soul_sand)
B(-6,84,0,minecraft:soul_sand)
B(-6,85,0,minecraft:soul_sand)
B(-6,86,0,minecraft:soul_sand)
B(-6,87,0,minecraft:soul_sand)
B(-6,88,0,minecraft:soul_sand)
B(-6,89,0,minecraft:soul_sand)
B(-6,90,0,minecraft:soul_sand)
B(-6,91,0,minecraft:soul_sand)
B(-6,92,0,minecraft:soul_sand)
B(-6,93,0,minecraft:soul_sand)
B(-6,94,0,minecraft:soul_sand)
B(-6,95,0,minecraft:soul_sand)
B(-6,96,0,minecraft:soul_sand)
B(-6,97,0,minecraft:soul_sand)
B(-6,98,0,minecraft:soul_sand)
B(-6,99,0,minecraft:soul_sand)
B(-6,100,0,minecraft:soul_sand)
B(-6,101,0,minecraft:soul_sand)
B(-6,102,0,minecraft:soul_sand)
B(-6,103,0,minecraft:soul_sand)
B(-6,104,0,minecraft:soul_sand)
B(-6,105,0,minecraft:soul_sand)
B(-6,106,0,minecraft:soul_sand)
B(-6,107,0,minecraft:soul_sand)
B(-6,108,0,minecraft:soul_sand)
B(-6,109,0,minecraft:soul_sand)
B(-6,110,0,minecraft:soul_sand)
B(-6,111,0,minecraft:soul_sand)
B(-6,112,0,minecraft:soul_sand)
B(-6,113,0,minecraft:soul_sand)
B(-6,114,0,minecraft:soul_sand)
B(-6,115,0,minecraft:soul_sand)
B(-6,116,0,minecraft:soul_sand)
B(-6,0,1,minecraft:soul_sand)
B(-6,1,1,minecraft:soul_sand)
B(-6,2,1,minecraft:soul_sand)
B(-6,3,1,minecraft:soul_sand)
B(-6,4,1,minecraft:soul_sand)
B(-6,5,1,minecraft:soul_sand)
B(-6,6,1,minecraft:soul_sand)
B(-6,7,1,minecraft:soul_sand)
B(-6,8,1,minecraft:soul_sand)
B(-6,9,1,minecraft:soul_sand)
B(-6,10,1,minecraft:soul_sand)
B(-6,11,1,minecraft:soul_sand)
B(-6,12,1,minecraft:soul_sand)
B(-6,13,1,minecraft:soul_sand)
B(-6,14,1,minecraft:soul_sand)
B(-6,15,1,minecraft:soul_sand)
B(-6,16,1,minecraft:soul_sand)
B(-6,17,1,minecraft:soul_sand)
B(-6,18,1,minecraft:soul_sand)
B(-6,19,1,minecraft:soul_sand)
B(-6,20,1,minecraft:soul_sand)
B(-6,21,1,minecraft:soul_sand)
B(-6,22,1,minecraft:soul_sand)
B(-6,23,1,minecraft:soul_sand)
B(-6,24,1,minecraft:soul_sand)
B(-6,25,1,minecraft:soul_sand)
B(-6,26,1,minecraft:soul_sand)
B(-6,83,1,minecraft:soul_sand)
B(-6,84,1,minecraft:soul_sand)
B(-6,85,1,minecraft:soul_sand)
B(-6,86,1,minecraft:soul_sand)
B(-6,87,1,minecraft:soul_sand)
B(-6,88,1,minecraft:soul_sand)
B(-6,89,1,minecraft:soul_sand)
B(-6,90,1,minecraft:soul_sand)
B(-6,91,1,minecraft:soul_sand)
B(-6,92,1,minecraft:soul_sand)
B(-6,93,1,minecraft:soul_sand)
B(-6,94,1,minecraft:soul_sand)
B(-6,95,1,minecraft:soul_sand)
B(-6,96,1,minecraft:soul_sand)
B(-6,97,1,minecraft:soul_sand)
B(-6,98,1,minecraft:soul_sand)
B(-6,99,1,minecraft:soul_sand)
B(-6,100,1,minecraft:soul_sand)
B(-6,101,1,minecraft:soul_sand)
B(-6,102,1,minecraft:soul_sand)
B(-6,103,1,minecraft:soul_sand)
B(-6,104,1,minecraft:soul_sand)
B(-6,105,1,minecraft:soul_sand)
B(-6,106,1,minecraft:soul_sand)
B(-6,107,1,minecraft:soul_sand)
B(-6,108,1,minecraft:soul_sand)
B(-6,109,1,minecraft:soul_sand)
B(-6,110,1,minecraft:soul_sand)
B(-6,111,1,minecraft:soul_sand)
B(-6,112,1,minecraft:soul_sand)
B(-6,113,1,minecraft:soul_sand)
B(-6,114,1,minecraft:soul_sand)
B(-6,115,1,minecraft:soul_sand)
B(-6,116,1,minecraft:soul_sand)
B(-6,0,2,minecraft:soul_sand)
B(-6,1,2,minecraft:soul_sand)
B(-6,2,2,minecraft:soul_sand)
B(-6,3,2,minecraft:soul_sand)
B(-6,4,2,minecraft:soul_sand)
B(-6,5,2,minecraft:soul_sand)
B(-6,6,2,minecraft:soul_sand)
B(-6,7,2,minecraft:soul_sand)
B(-6,8,2,minecraft:soul_sand)
B(-6,9,2,minecraft:soul_sand)
B(-6,10,2,minecraft:soul_sand)
B(-6,11,2,minecraft:soul_sand)
B(-6,12,2,minecraft:soul_sand)
B(-6,13,2,minecraft:soul_sand)
B(-6,14,2,minecraft:soul_sand)
B(-6,15,2,minecraft:soul_sand)
B(-6,16,2,minecraft:soul_sand)
B(-6,17,2,minecraft:soul_sand)
B(-6,18,2,minecraft:soul_sand)
B(-6,19,2,minecraft:soul_sand)
B(-6,20,2,minecraft:soul_sand)
B(-6,21,2,minecraft:soul_sand)
B(-6,22,2,minecraft:soul_sand)
B(-6,23,2,minecraft:soul_sand)
B(-6,24,2,minecraft:soul_sand)
B(-6,25,2,minecraft:soul_sand)
B(-6,83,2,minecraft:soul_sand)
B(-6,84,2,minecraft:soul_sand)
B(-6,85,2,minecraft:soul_sand)
B(-6,86,2,minecraft:soul_sand)
B(-6,87,2,minecraft:soul_sand)
B(-6,88,2,minecraft:soul_sand)
B(-6,89,2,minecraft:soul_sand)
B(-6,90,2,minecraft:soul_sand)
B(-6,91,2,minecraft:soul_sand)
B(-6,92,2,minecraft:soul_sand)
B(-6,93,2,minecraft:soul_sand)
B(-6,94,2,minecraft:soul_sand)
B(-6,95,2,minecraft:soul_sand)
B(-6,96,2,minecraft:soul_sand)
B(-6,97,2,minecraft:soul_sand)
B(-6,98,2,minecraft:soul_sand)
B(-6,99,2,minecraft:soul_sand)
B(-6,100,2,minecraft:soul_sand)
B(-6,101,2,minecraft:soul_sand)
B(-6,102,2,minecraft:soul_sand)
B(-6,103,2,minecraft:soul_sand)
B(-6,104,2,minecraft:soul_sand)
B(-6,105,2,minecraft:soul_sand)
B(-6,106,2,minecraft:soul_sand)
B(-6,107,2,minecraft:soul_sand)
B(-6,108,2,minecraft:soul_sand)
B(-6,109,2,minecraft:soul_sand)
B(-6,110,2,minecraft:soul_sand)
B(-6,111,2,minecraft:soul_sand)
B(-6,112,2,minecraft:soul_sand)
B(-6,113,2,minecraft:soul_sand)
B(-6,114,2,minecraft:soul_sand)
B(-6,115,2,minecraft:soul_sand)
B(-6,116,2,minecraft:soul_sand)
B(-6,0,3,minecraft:soul_sand)
B(-6,1,3,minecraft:soul_sand)
B(-6,2,3,minecraft:soul_sand)
B(-6,3,3,minecraft:soul_sand)
B(-6,4,3,minecraft:soul_sand)
B(-6,5,3,minecraft:soul_sand)
B(-6,6,3,minecraft:soul_sand)
B(-6,7,3,minecraft:soul_sand)
B(-6,8,3,minecraft:soul_sand)
B(-6,9,3,minecraft:soul_sand)
B(-6,10,3,minecraft:soul_sand)
B(-6,11,3,minecraft:soul_sand)
B(-6,12,3,minecraft:soul_sand)
B(-6,13,3,minecraft:soul_sand)
B(-6,14,3,minecraft:soul_sand)
B(-6,15,3,minecraft:soul_sand)
B(-6,16,3,minecraft:soul_sand)
B(-6,17,3,minecraft:soul_sand)
B(-6,18,3,minecraft:soul_sand)
B(-6,19,3,minecraft:soul_sand)
B(-6,20,3,minecraft:soul_sand)
B(-6,21,3,minecraft:soul_sand)
B(-6,22,3,minecraft:soul_sand)
B(-6,23,3,minecraft:soul_sand)
B(-6,85,3,minecraft:soul_sand)
B(-6,86,3,minecraft:soul_sand)
B(-6,87,3,minecraft:soul_sand)
B(-6,88,3,minecraft:soul_sand)
B(-6,89,3,minecraft:soul_sand)
B(-6,90,3,minecraft:soul_sand)
B(-6,91,3,minecraft:soul_sand)
B(-6,92,3,minecraft:soul_sand)
B(-6,93,3,minecraft:soul_sand)
B(-6,94,3,minecraft:soul_sand)
B(-6,95,3,minecraft:soul_sand)
B(-6,96,3,minecraft:soul_sand)
B(-6,97,3,minecraft:soul_sand)
B(-6,98,3,minecraft:soul_sand)
B(-6,99,3,minecraft:soul_sand)
B(-6,100,3,minecraft:soul_sand)
B(-6,101,3,minecraft:soul_sand)
B(-6,102,3,minecraft:soul_sand)
B(-6,103,3,minecraft:soul_sand)
B(-6,104,3,minecraft:soul_sand)
B(-6,105,3,minecraft:soul_sand)
B(-6,106,3,minecraft:soul_sand)
B(-6,107,3,minecraft:soul_sand)
B(-6,108,3,minecraft:soul_sand)
B(-6,109,3,minecraft:soul_sand)
B(-6,110,3,minecraft:soul_sand)
B(-6,111,3,minecraft:soul_sand)
B(-6,112,3,minecraft:soul_sand)
B(-6,113,3,minecraft:soul_sand)
B(-6,114,3,minecraft:soul_sand)
B(-6,115,3,minecraft:soul_sand)
B(-6,116,3,minecraft:soul_sand)
B(-6,0,4,minecraft:soul_sand)
B(-6,1,4,minecraft:soul_sand)
B(-6,2,4,minecraft:soul_sand)
B(-6,3,4,minecraft:soul_sand)
B(-6,4,4,minecraft:soul_sand)
B(-6,5,4,minecraft:soul_sand)
B(-6,6,4,minecraft:soul_sand)
B(-6,7,4,minecraft:soul_sand)
B(-6,8,4,minecraft:soul_sand)
B(-6,9,4,minecraft:soul_sand)
B(-6,10,4,minecraft:soul_sand)
B(-6,11,4,minecraft:soul_sand)
B(-6,12,4,minecraft:soul_sand)
B(-6,13,4,minecraft:soul_sand)
B(-6,14,4,minecraft:soul_sand)
B(-6,15,4,minecraft:soul_sand)
B(-6,16,4,minecraft:soul_sand)
B(-6,17,4,minecraft:soul_sand)
B(-6,18,4,minecraft:soul_sand)
B(-6,19,4,minecraft:soul_sand)
B(-6,20,4,minecraft:soul_sand)
B(-6,21,4,minecraft:soul_sand)
B(-6,22,4,minecraft:soul_sand)
B(-6,23,4,minecraft:soul_sand)
B(-6,87,4,minecraft:soul_sand)
B(-6,88,4,minecraft:soul_sand)
B(-6,89,4,minecraft:soul_sand)
B(-6,90,4,minecraft:soul_sand)
B(-6,91,4,minecraft:soul_sand)
B(-6,92,4,minecraft:soul_sand)
B(-6,93,4,minecraft:soul_sand)
B(-6,94,4,minecraft:soul_sand)
B(-6,95,4,minecraft:soul_sand)
B(-6,96,4,minecraft:soul_sand)
B(-6,97,4,minecraft:soul_sand)
B(-6,98,4,minecraft:soul_sand)
B(-6,99,4,minecraft:soul_sand)
B(-6,100,4,minecraft:soul_sand)
B(-6,101,4,minecraft:soul_sand)
B(-6,102,4,minecraft:soul_sand)
B(-6,103,4,minecraft:soul_sand)
B(-6,104,4,minecraft:soul_sand)
B(-6,105,4,minecraft:soul_sand)
B(-6,106,4,minecraft:soul_sand)
B(-6,107,4,minecraft:soul_sand)
B(-6,108,4,minecraft:soul_sand)
B(-6,109,4,minecraft:soul_sand)
B(-6,110,4,minecraft:soul_sand)
B(-6,111,4,minecraft:soul_sand)
B(-6,112,4,minecraft:soul_sand)
B(-6,113,4,minecraft:soul_sand)
B(-6,114,4,minecraft:soul_sand)
B(-6,115,4,minecraft:soul_sand)
B(-6,116,4,minecraft:soul_sand)
B(-6,0,5,minecraft:soul_sand)
B(-6,1,5,minecraft:soul_sand)
B(-6,2,5,minecraft:soul_sand)
B(-6,3,5,minecraft:soul_sand)
B(-6,4,5,minecraft:soul_sand)
B(-6,5,5,minecraft:soul_sand)
B(-6,6,5,minecraft:soul_sand)
B(-6,7,5,minecraft:soul_sand)
B(-6,8,5,minecraft:soul_sand)
B(-6,9,5,minecraft:soul_sand)
B(-6,10,5,minecraft:soul_sand)
B(-6,11,5,minecraft:soul_sand)
B(-6,12,5,minecraft:soul_sand)
B(-6,13,5,minecraft:soul_sand)
B(-6,14,5,minecraft:soul_sand)
B(-6,15,5,minecraft:soul_sand)
B(-6,16,5,minecraft:soul_sand)
B(-6,17,5,minecraft:soul_sand)
B(-6,18,5,minecraft:soul_sand)
B(-6,19,5,minecraft:soul_sand)
B(-6,20,5,minecraft:soul_sand)
B(-6,21,5,minecraft:soul_sand)
B(-6,22,5,minecraft:soul_sand)
B(-6,88,5,minecraft:soul_sand)
B(-6,89,5,minecraft:soul_sand)
B(-6,90,5,minecraft:soul_sand)
B(-6,91,5,minecraft:soul_sand)
B(-6,92,5,minecraft:soul_sand)
B(-6,93,5,minecraft:soul_sand)
B(-6,94,5,minecraft:soul_sand)
B(-6,95,5,minecraft:soul_sand)
B(-6,96,5,minecraft:soul_sand)
B(-6,97,5,minecraft:soul_sand)
B(-6,98,5,minecraft:soul_sand)
B(-6,99,5,minecraft:soul_sand)
B(-6,100,5,minecraft:soul_sand)
B(-6,101,5,minecraft:soul_sand)
B(-6,102,5,minecraft:soul_sand)
B(-6,103,5,minecraft:soul_sand)
B(-6,104,5,minecraft:soul_sand)
B(-6,105,5,minecraft:soul_sand)
B(-6,106,5,minecraft:soul_sand)
B(-6,107,5,minecraft:soul_sand)
B(-6,108,5,minecraft:soul_sand)
B(-6,109,5,minecraft:soul_sand)
B(-6,110,5,minecraft:soul_sand)
B(-6,111,5,minecraft:soul_sand)
B(-6,112,5,minecraft:soul_sand)
B(-6,113,5,minecraft:soul_sand)
B(-6,114,5,minecraft:soul_sand)
B(-6,115,5,minecraft:soul_sand)
B(-6,116,5,minecraft:soul_sand)
B(-6,0,6,minecraft:soul_sand)
B(-6,1,6,minecraft:soul_sand)
B(-6,2,6,minecraft:soul_sand)
B(-6,3,6,minecraft:soul_sand)
B(-6,4,6,minecraft:soul_sand)
B(-6,5,6,minecraft:soul_sand)
B(-6,6,6,minecraft:soul_sand)
B(-6,7,6,minecraft:soul_sand)
B(-6,8,6,minecraft:soul_sand)
B(-6,9,6,minecraft:soul_sand)
B(-6,10,6,minecraft:soul_sand)
B(-6,11,6,minecraft:soul_sand)
B(-6,12,6,minecraft:soul_sand)
B(-6,13,6,minecraft:soul_sand)
B(-6,14,6,minecraft:soul_sand)
B(-6,15,6,minecraft:soul_sand)
B(-6,16,6,minecraft:soul_sand)
B(-6,17,6,minecraft:soul_sand)
B(-6,18,6,minecraft:soul_sand)
B(-6,19,6,minecraft:soul_sand)
B(-6,20,6,minecraft:soul_sand)
B(-6,21,6,minecraft:soul_sand)
B(-6,90,6,minecraft:soul_sand)
B(-6,91,6,minecraft:soul_sand)
B(-6,92,6,minecraft:soul_sand)
B(-6,93,6,minecraft:soul_sand)
B(-6,94,6,minecraft:soul_sand)
B(-6,95,6,minecraft:soul_sand)
B(-6,96,6,minecraft:soul_sand)
B(-6,97,6,minecraft:soul_sand)
B(-6,98,6,minecraft:soul_sand)
B(-6,99,6,minecraft:soul_sand)
B(-6,100,6,minecraft:soul_sand)
B(-6,101,6,minecraft:soul_sand)
B(-6,102,6,minecraft:soul_sand)
B(-6,103,6,minecraft:soul_sand)
B(-6,104,6,minecraft:soul_sand)
B(-6,105,6,minecraft:soul_sand)
B(-6,106,6,minecraft:soul_sand)
B(-6,107,6,minecraft:soul_sand)
B(-6,108,6,minecraft:soul_sand)
B(-6,109,6,minecraft:soul_sand)
B(-6,110,6,minecraft:soul_sand)
B(-6,111,6,minecraft:soul_sand)
B(-6,112,6,minecraft:soul_sand)
B(-6,113,6,minecraft:soul_sand)
B(-6,114,6,minecraft:soul_sand)
B(-6,115,6,minecraft:soul_sand)
B(-6,116,6,minecraft:soul_sand)
B(-6,0,7,minecraft:soul_sand)
B(-6,1,7,minecraft:soul_sand)
B(-6,2,7,minecraft:soul_sand)
B(-6,3,7,minecraft:soul_sand)
B(-6,4,7,minecraft:soul_sand)
B(-6,5,7,minecraft:soul_sand)
B(-6,6,7,minecraft:soul_sand)
B(-6,7,7,minecraft:soul_sand)
B(-6,8,7,minecraft:soul_sand)
B(-6,9,7,minecraft:soul_sand)
B(-6,10,7,minecraft:soul_sand)
B(-6,11,7,minecraft:soul_sand)
B(-6,12,7,minecraft:soul_sand)
B(-6,13,7,minecraft:soul_sand)
B(-6,14,7,minecraft:soul_sand)
B(-6,15,7,minecraft:soul_sand)
B(-6,16,7,minecraft:soul_sand)
B(-6,17,7,minecraft:soul_sand)
B(-6,18,7,minecraft:soul_sand)
B(-6,19,7,minecraft:soul_sand)
B(-6,20,7,minecraft:soul_sand)
B(-6,21,7,minecraft:soul_sand)
B(-6,91,7,minecraft:soul_sand)
B(-6,92,7,minecraft:soul_sand)
B(-6,93,7,minecraft:soul_sand)
B(-6,94,7,minecraft:soul_sand)
B(-6,95,7,minecraft:soul_sand)
B(-6,96,7,minecraft:soul_sand)
B(-6,97,7,minecraft:soul_sand)
B(-6,98,7,minecraft:soul_sand)
B(-6,99,7,minecraft:soul_sand)
B(-6,100,7,minecraft:soul_sand)
B(-6,101,7,minecraft:soul_sand)
B(-6,102,7,minecraft:soul_sand)
B(-6,103,7,minecraft:soul_sand)
B(-6,104,7,minecraft:soul_sand)
B(-6,105,7,minecraft:soul_sand)
B(-6,106,7,minecraft:soul_sand)
B(-6,107,7,minecraft:soul_sand)
B(-6,108,7,minecraft:soul_sand)
B(-6,109,7,minecraft:soul_sand)
B(-6,110,7,minecraft:soul_sand)
B(-6,111,7,minecraft:soul_sand)
B(-6,112,7,minecraft:soul_sand)
B(-6,113,7,minecraft:soul_sand)
B(-6,114,7,minecraft:soul_sand)
B(-6,115,7,minecraft:soul_sand)
B(-6,116,7,minecraft:soul_sand)
B(-6,0,8,minecraft:soul_sand)
B(-6,1,8,minecraft:soul_sand)
B(-6,2,8,minecraft:soul_sand)
B(-6,3,8,minecraft:soul_sand)
B(-6,4,8,minecraft:soul_sand)
B(-6,5,8,minecraft:soul_sand)
B(-6,6,8,minecraft:soul_sand)
B(-6,7,8,minecraft:soul_sand)
B(-6,8,8,minecraft:soul_sand)
B(-6,9,8,minecraft:soul_sand)
B(-6,10,8,minecraft:soul_sand)
B(-6,11,8,minecraft:soul_sand)
B(-6,12,8,minecraft:soul_sand)
B(-6,13,8,minecraft:soul_sand)
B(-6,14,8,minecraft:soul_sand)
B(-6,15,8,minecraft:soul_sand)
B(-6,16,8,minecraft:soul_sand)
B(-6,17,8,minecraft:soul_sand)
B(-6,18,8,minecraft:soul_sand)
B(-6,19,8,minecraft:soul_sand)
B(-6,20,8,minecraft:soul_sand)
B(-6,92,8,minecraft:soul_sand)
B(-6,93,8,minecraft:soul_sand)
B(-6,94,8,minecraft:soul_sand)
B(-6,95,8,minecraft:soul_sand)
B(-6,96,8,minecraft:soul_sand)
B(-6,97,8,minecraft:soul_sand)
B(-6,98,8,minecraft:soul_sand)
B(-6,99,8,minecraft:soul_sand)
B(-6,100,8,minecraft:soul_sand)
B(-6,101,8,minecraft:soul_sand)
B(-6,102,8,minecraft:soul_sand)
B(-6,103,8,minecraft:soul_sand)
B(-6,104,8,minecraft:soul_sand)
B(-6,105,8,minecraft:soul_sand)
B(-6,106,8,minecraft:soul_sand)
B(-6,107,8,minecraft:soul_sand)
B(-6,108,8,minecraft:soul_sand)
B(-6,109,8,minecraft:soul_sand)
B(-6,110,8,minecraft:soul_sand)
B(-6,111,8,minecraft:soul_sand)
B(-6,112,8,minecraft:soul_sand)
B(-6,113,8,minecraft:soul_sand)
B(-6,114,8,minecraft:soul_sand)
B(-6,115,8,minecraft:soul_sand)
B(-6,116,8,minecraft:soul_sand)
B(-5,0,-7,minecraft:soul_sand)
B(-5,1,-7,minecraft:soul_sand)
B(-5,2,-7,minecraft:soul_sand)
B(-5,3,-7,minecraft:soul_sand)
B(-5,4,-7,minecraft:soul_sand)
B(-5,5,-7,minecraft:soul_sand)
B(-5,6,-7,minecraft:soul_sand)
B(-5,7,-7,minecraft:soul_sand)
B(-5,8,-7,minecraft:soul_sand)
B(-5,9,-7,minecraft:soul_sand)
B(-5,10,-7,minecraft:soul_sand)
B(-5,11,-7,minecraft:soul_sand)
B(-5,12,-7,minecraft:soul_sand)
B(-5,13,-7,minecraft:soul_sand)
B(-5,14,-7,minecraft:soul_sand)
B(-5,15,-7,minecraft:soul_sand)
B(-5,16,-7,minecraft:soul_sand)
B(-5,17,-7,minecraft:soul_sand)
B(-5,18,-7,minecraft:soul_sand)
B(-5,19,-7,minecraft:soul_sand)
B(-5,20,-7,minecraft:soul_sand)
B(-5,21,-7,minecraft:soul_sand)
B(-5,22,-7,minecraft:soul_sand)
B(-5,23,-7,minecraft:soul_sand)
B(-5,24,-7,minecraft:soul_sand)
B(-5,25,-7,minecraft:soul_sand)
B(-5,26,-7,minecraft:soul_sand)
B(-5,27,-7,minecraft:soul_sand)
B(-5,28,-7,minecraft:soul_sand)
B(-5,29,-7,minecraft:soul_sand)
B(-5,30,-7,minecraft:soul_sand)
B(-5,31,-7,minecraft:soul_sand)
B(-5,32,-7,minecraft:soul_sand)
B(-5,33,-7,minecraft:soul_sand)
B(-5,34,-7,minecraft:soul_sand)
B(-5,35,-7,minecraft:soul_sand)
B(-5,36,-7,minecraft:soul_sand)
B(-5,37,-7,minecraft:soul_sand)
B(-5,38,-7,minecraft:soul_sand)
B(-5,39,-7,minecraft:soul_sand)
B(-5,40,-7,minecraft:soul_sand)
B(-5,41,-7,minecraft:soul_sand)
B(-5,42,-7,minecraft:soul_sand)
B(-5,43,-7,minecraft:soul_sand)
B(-5,44,-7,minecraft:soul_sand)
B(-5,45,-7,minecraft:soul_sand)
B(-5,46,-7,minecraft:soul_sand)
B(-5,47,-7,minecraft:soul_sand)
B(-5,48,-7,minecraft:soul_sand)
B(-5,49,-7,minecraft:soul_sand)
B(-5,50,-7,minecraft:soul_sand)
B(-5,51,-7,minecraft:soul_sand)
B(-5,52,-7,minecraft:soul_sand)
B(-5,53,-7,minecraft:soul_sand)
B(-5,60,-7,minecraft:soul_sand)
B(-5,61,-7,minecraft:soul_sand)
B(-5,62,-7,minecraft:soul_sand)
B(-5,63,-7,minecraft:soul_sand)
B(-5,64,-7,minecraft:soul_sand)
B(-5,71,-7,minecraft:soul_sand)
B(-5,72,-7,minecraft:soul_sand)
B(-5,73,-7,minecraft:soul_sand)
B(-5,76,-7,minecraft:soul_sand)
B(-5,77,-7,minecraft:soul_sand)
B(-5,83,-7,minecraft:soul_sand)
B(-5,84,-7,minecraft:soul_sand)
B(-5,85,-7,minecraft:soul_sand)
B(-5,86,-7,minecraft:soul_sand)
B(-5,87,-7,minecraft:soul_sand)
B(-5,88,-7,minecraft:soul_sand)
B(-5,89,-7,minecraft:soul_sand)
B(-5,90,-7,minecraft:soul_sand)
B(-5,91,-7,minecraft:soul_sand)
B(-5,92,-7,minecraft:soul_sand)
B(-5,93,-7,minecraft:soul_sand)
B(-5,94,-7,minecraft:soul_sand)
B(-5,95,-7,minecraft:soul_sand)
B(-5,96,-7,minecraft:soul_sand)
B(-5,97,-7,minecraft:soul_sand)
B(-5,98,-7,minecraft:soul_sand)
B(-5,99,-7,minecraft:soul_sand)
B(-5,100,-7,minecraft:soul_sand)
B(-5,101,-7,minecraft:soul_sand)
B(-5,102,-7,minecraft:soul_sand)
B(-5,103,-7,minecraft:soul_sand)
B(-5,104,-7,minecraft:soul_sand)
B(-5,105,-7,minecraft:soul_sand)
B(-5,106,-7,minecraft:soul_sand)
B(-5,107,-7,minecraft:soul_sand)
B(-5,108,-7,minecraft:soul_sand)
B(-5,109,-7,minecraft:soul_sand)
B(-5,110,-7,minecraft:soul_sand)
B(-5,111,-7,minecraft:soul_sand)
B(-5,112,-7,minecraft:soul_sand)
B(-5,113,-7,minecraft:soul_sand)
B(-5,114,-7,minecraft:soul_sand)
B(-5,115,-7,minecraft:soul_sand)
B(-5,116,-7,minecraft:soul_sand)
B(-5,0,-6,minecraft:soul_sand)
B(-5,1,-6,minecraft:soul_sand)
B(-5,2,-6,minecraft:soul_sand)
B(-5,3,-6,minecraft:soul_sand)
B(-5,4,-6,minecraft:soul_sand)
B(-5,5,-6,minecraft:soul_sand)
B(-5,6,-6,minecraft:soul_sand)
B(-5,7,-6,minecraft:soul_sand)
B(-5,8,-6,minecraft:soul_sand)
B(-5,9,-6,minecraft:soul_sand)
B(-5,10,-6,minecraft:soul_sand)
B(-5,11,-6,minecraft:soul_sand)
B(-5,12,-6,minecraft:soul_sand)
B(-5,13,-6,minecraft:soul_sand)
B(-5,14,-6,minecraft:soul_sand)
B(-5,15,-6,minecraft:soul_sand)
B(-5,16,-6,minecraft:soul_sand)
B(-5,17,-6,minecraft:soul_sand)
B(-5,18,-6,minecraft:soul_sand)
B(-5,19,-6,minecraft:soul_sand)
B(-5,20,-6,minecraft:soul_sand)
B(-5,21,-6,minecraft:soul_sand)
B(-5,22,-6,minecraft:soul_sand)
B(-5,23,-6,minecraft:soul_sand)
B(-5,24,-6,minecraft:soul_sand)
B(-5,25,-6,minecraft:soul_sand)
B(-5,26,-6,minecraft:soul_sand)
B(-5,27,-6,minecraft:soul_sand)
B(-5,28,-6,minecraft:soul_sand)
B(-5,29,-6,minecraft:soul_sand)
B(-5,30,-6,minecraft:soul_sand)
B(-5,31,-6,minecraft:soul_sand)
B(-5,32,-6,minecraft:soul_sand)
B(-5,33,-6,minecraft:soul_sand)
B(-5,34,-6,minecraft:soul_sand)
B(-5,35,-6,minecraft:soul_sand)
B(-5,36,-6,minecraft:soul_sand)
B(-5,37,-6,minecraft:soul_sand)
B(-5,38,-6,minecraft:soul_sand)
B(-5,39,-6,minecraft:soul_sand)
B(-5,40,-6,minecraft:soul_sand)
B(-5,41,-6,minecraft:soul_sand)
B(-5,42,-6,minecraft:soul_sand)
B(-5,43,-6,minecraft:soul_sand)
B(-5,44,-6,minecraft:soul_sand)
B(-5,45,-6,minecraft:soul_sand)
B(-5,46,-6,minecraft:soul_sand)
B(-5,47,-6,minecraft:soul_sand)
B(-5,48,-6,minecraft:soul_sand)
B(-5,49,-6,minecraft:soul_sand)
B(-5,50,-6,minecraft:soul_sand)
B(-5,51,-6,minecraft:soul_sand)
B(-5,52,-6,minecraft:soul_sand)
B(-5,53,-6,minecraft:soul_sand)
B(-5,54,-6,minecraft:soul_sand)
B(-5,55,-6,minecraft:soul_sand)
B(-5,56,-6,minecraft:soul_sand)
B(-5,59,-6,minecraft:soul_sand)
B(-5,60,-6,minecraft:soul_sand)
B(-5,61,-6,minecraft:soul_sand)
B(-5,62,-6,minecraft:soul_sand)
B(-5,63,-6,minecraft:soul_sand)
B(-5,64,-6,minecraft:soul_sand)
B(-5,65,-6,minecraft:soul_sand)
B(-5,66,-6,minecraft:soul_sand)
B(-5,70,-6,minecraft:soul_sand)
B(-5,71,-6,minecraft:soul_sand)
B(-5,72,-6,minecraft:soul_sand)
B(-5,73,-6,minecraft:soul_sand)
B(-5,74,-6,minecraft:soul_sand)
B(-5,75,-6,minecraft:soul_sand)
B(-5,76,-6,minecraft:soul_sand)
B(-5,77,-6,minecraft:soul_sand)
B(-5,78,-6,minecraft:soul_sand)
B(-5,82,-6,minecraft:soul_sand)
B(-5,83,-6,minecraft:soul_sand)
B(-5,84,-6,minecraft:soul_sand)
B(-5,85,-6,minecraft:soul_sand)
B(-5,86,-6,minecraft:soul_sand)
B(-5,87,-6,minecraft:soul_sand)
B(-5,88,-6,minecraft:soul_sand)
B(-5,89,-6,minecraft:soul_sand)
B(-5,90,-6,minecraft:soul_sand)
B(-5,91,-6,minecraft:soul_sand)
B(-5,92,-6,minecraft:soul_sand)
B(-5,93,-6,minecraft:soul_sand)
B(-5,94,-6,minecraft:soul_sand)
B(-5,95,-6,minecraft:soul_sand)
B(-5,96,-6,minecraft:soul_sand)
B(-5,97,-6,minecraft:soul_sand)
B(-5,98,-6,minecraft:soul_sand)
B(-5,99,-6,minecraft:soul_sand)
B(-5,100,-6,minecraft:soul_sand)
B(-5,101,-6,minecraft:soul_sand)
B(-5,102,-6,minecraft:soul_sand)
B(-5,103,-6,minecraft:soul_sand)
B(-5,104,-6,minecraft:soul_sand)
B(-5,105,-6,minecraft:soul_sand)
B(-5,106,-6,minecraft:soul_sand)
B(-5,107,-6,minecraft:soul_sand)
B(-5,108,-6,minecraft:soul_sand)
B(-5,109,-6,minecraft:soul_sand)
B(-5,110,-6,minecraft:soul_sand)
