
#######################################################################
# +-----------------------------------------------------------------+ #
# |                            BO4 object                           | #
# +-----------------------------------------------------------------+ #
#######################################################################

Author: Unknown

Description: No description given

SettingsMode: WriteWithoutComments


#######################################################################
# +-----------------------------------------------------------------+ #
# |                          Main settings                          | #
# +-----------------------------------------------------------------+ #
#######################################################################

FixedRotation: 

Frequency: 0

SpawnHeight: highestBlock

UseCenterForHighestBlock: true

##############################
# Height Limits for the BO4. #
##############################

MinHeight: 0

MaxHeight: 255

InheritBO3: 

InheritBO3Rotation: NORTH

OverrideChildSettings: true

OverrideParentHeight: false

CanOverride: false

BranchFrequency: 0

BranchFrequencyGroup: 

MustBeBelowOther: false

MustBeInside: 

CannotBeInside: 

ReplacesBO3: 

MustBeInsideWorldBorders: false

CanSpawnOnWater: true

SpawnOnWaterOnly: false

SpawnUnderWater: false

SpawnAtWaterLevel: false

HeightOffset: 0

RemoveAir: true

ReplaceAbove: 

ReplaceBelow: 

ReplaceWithBiomeBlocks: true

ReplaceWithSurfaceBlock: GRASS

ReplaceWithGroundBlock: DIRT

ReplaceWithStoneBlock: STONE

SmoothRadius: 0

SmoothHeightOffset: 0

SmoothStartTop: false

SmoothStartWood: false

SmoothingSurfaceBlock: 

SmoothingGroundBlock: 

BO3Group: 

IsSpawnPoint: false

DoReplaceBlocks: true


#######################################################################
# +-----------------------------------------------------------------+ #
# |                              Blocks                             | #
# +-----------------------------------------------------------------+ #
#######################################################################

B(-8,29,-7,minecraft:basalt)
B(-8,30,-7,minecraft:basalt)
B(-8,31,-7,minecraft:basalt)
B(-8,32,-7,minecraft:basalt)
B(-8,33,-7,minecraft:basalt)
B(-8,34,-7,minecraft:basalt)
B(-8,35,-7,minecraft:basalt)
B(-8,36,-7,minecraft:basalt)
B(-8,37,-7,minecraft:basalt)
B(-8,38,-7,minecraft:basalt)
B(-8,39,-7,minecraft:basalt)
B(-8,40,-7,minecraft:basalt)
B(-8,41,-7,minecraft:basalt)
B(-8,42,-7,minecraft:basalt)
B(-8,43,-7,minecraft:basalt)
B(-8,44,-7,minecraft:basalt)
B(-8,45,-7,minecraft:basalt)
B(-8,46,-7,minecraft:basalt)
B(-8,47,-7,minecraft:basalt)
B(-8,48,-7,minecraft:basalt)
B(-8,49,-7,minecraft:basalt)
B(-8,50,-7,minecraft:basalt)
B(-8,51,-7,minecraft:basalt)
B(-8,52,-7,minecraft:basalt)
B(-8,53,-7,minecraft:basalt)
B(-8,54,-7,minecraft:basalt)
B(-8,55,-7,minecraft:basalt)
B(-8,30,-6,minecraft:basalt)
B(-8,31,-6,minecraft:basalt)
B(-8,32,-6,minecraft:basalt)
B(-8,33,-6,minecraft:basalt)
B(-8,34,-6,minecraft:basalt)
B(-8,35,-6,minecraft:basalt)
B(-8,36,-6,minecraft:basalt)
B(-8,37,-6,minecraft:basalt)
B(-8,38,-6,minecraft:basalt)
B(-8,39,-6,minecraft:basalt)
B(-8,40,-6,minecraft:basalt)
B(-8,41,-6,minecraft:basalt)
B(-8,42,-6,minecraft:basalt)
B(-8,43,-6,minecraft:basalt)
B(-8,44,-6,minecraft:basalt)
B(-8,45,-6,minecraft:basalt)
B(-8,46,-6,minecraft:basalt)
B(-8,47,-6,minecraft:basalt)
B(-8,48,-6,minecraft:basalt)
B(-8,49,-6,minecraft:basalt)
B(-8,50,-6,minecraft:basalt)
B(-8,51,-6,minecraft:basalt)
B(-8,52,-6,minecraft:basalt)
B(-8,53,-6,minecraft:basalt)
B(-8,54,-6,minecraft:basalt)
B(-8,55,-6,minecraft:basalt)
B(-8,38,-5,minecraft:basalt)
B(-8,39,-5,minecraft:basalt)
B(-8,40,-5,minecraft:basalt)
B(-8,41,-5,minecraft:basalt)
B(-8,42,-5,minecraft:basalt)
B(-8,43,-5,minecraft:basalt)
B(-8,44,-5,minecraft:basalt)
B(-8,45,-5,minecraft:basalt)
B(-8,46,-5,minecraft:basalt)
B(-8,47,-5,minecraft:basalt)
B(-8,48,-5,minecraft:basalt)
B(-8,49,-5,minecraft:basalt)
B(-8,50,-5,minecraft:basalt)
B(-8,51,-5,minecraft:basalt)
B(-8,52,-5,minecraft:basalt)
B(-8,53,-5,minecraft:basalt)
B(-8,54,-5,minecraft:basalt)
B(-8,55,-5,minecraft:basalt)
B(-8,42,-4,minecraft:basalt)
B(-8,43,-4,minecraft:basalt)
B(-8,44,-4,minecraft:basalt)
B(-8,45,-4,minecraft:basalt)
B(-8,46,-4,minecraft:basalt)
B(-8,47,-4,minecraft:basalt)
B(-8,48,-4,minecraft:basalt)
B(-8,49,-4,minecraft:basalt)
B(-8,50,-4,minecraft:basalt)
B(-8,51,-4,minecraft:basalt)
B(-8,52,-4,minecraft:basalt)
B(-8,53,-4,minecraft:basalt)
B(-8,54,-4,minecraft:basalt)
B(-8,55,-4,minecraft:basalt)
B(-8,44,-3,minecraft:basalt)
B(-8,45,-3,minecraft:basalt)
B(-8,46,-3,minecraft:basalt)
B(-8,47,-3,minecraft:basalt)
B(-8,48,-3,minecraft:basalt)
B(-8,49,-3,minecraft:basalt)
B(-8,50,-3,minecraft:basalt)
B(-8,51,-3,minecraft:basalt)
B(-8,52,-3,minecraft:basalt)
B(-8,53,-3,minecraft:basalt)
B(-8,54,-3,minecraft:basalt)
B(-8,55,-3,minecraft:basalt)
B(-8,47,-2,minecraft:basalt)
B(-8,48,-2,minecraft:basalt)
B(-8,49,-2,minecraft:basalt)
B(-8,50,-2,minecraft:basalt)
B(-8,51,-2,minecraft:basalt)
B(-8,52,-2,minecraft:basalt)
B(-8,53,-2,minecraft:basalt)
B(-8,54,-2,minecraft:basalt)
B(-8,55,-2,minecraft:basalt)
B(-7,30,-7,minecraft:basalt)
B(-7,31,-7,minecraft:basalt)
B(-7,32,-7,minecraft:basalt)
B(-7,33,-7,minecraft:basalt)
B(-7,34,-7,minecraft:basalt)
B(-7,35,-7,minecraft:basalt)
B(-7,36,-7,minecraft:basalt)
B(-7,37,-7,minecraft:basalt)
B(-7,38,-7,minecraft:basalt)
B(-7,39,-7,minecraft:basalt)
B(-7,40,-7,minecraft:basalt)
B(-7,41,-7,minecraft:basalt)
B(-7,42,-7,minecraft:basalt)
B(-7,43,-7,minecraft:basalt)
B(-7,44,-7,minecraft:basalt)
B(-7,45,-7,minecraft:basalt)
B(-7,46,-7,minecraft:basalt)
B(-7,47,-7,minecraft:basalt)
B(-7,48,-7,minecraft:basalt)
B(-7,49,-7,minecraft:basalt)
B(-7,50,-7,minecraft:basalt)
B(-7,51,-7,minecraft:basalt)
B(-7,52,-7,minecraft:basalt)
B(-7,53,-7,minecraft:basalt)
B(-7,54,-7,minecraft:basalt)
B(-7,55,-7,minecraft:basalt)
B(-7,31,-6,minecraft:basalt)
B(-7,32,-6,minecraft:basalt)
B(-7,33,-6,minecraft:basalt)
B(-7,34,-6,minecraft:basalt)
B(-7,35,-6,minecraft:basalt)
B(-7,36,-6,minecraft:basalt)
B(-7,37,-6,minecraft:basalt)
B(-7,38,-6,minecraft:basalt)
B(-7,39,-6,minecraft:basalt)
B(-7,40,-6,minecraft:basalt)
B(-7,41,-6,minecraft:basalt)
B(-7,42,-6,minecraft:basalt)
B(-7,43,-6,minecraft:basalt)
B(-7,44,-6,minecraft:basalt)
B(-7,45,-6,minecraft:basalt)
B(-7,46,-6,minecraft:basalt)
B(-7,47,-6,minecraft:basalt)
B(-7,48,-6,minecraft:basalt)
B(-7,49,-6,minecraft:basalt)
B(-7,50,-6,minecraft:basalt)
B(-7,51,-6,minecraft:basalt)
B(-7,52,-6,minecraft:basalt)
B(-7,53,-6,minecraft:basalt)
B(-7,54,-6,minecraft:basalt)
B(-7,55,-6,minecraft:basalt)
B(-7,42,-5,minecraft:basalt)
B(-7,43,-5,minecraft:basalt)
B(-7,44,-5,minecraft:basalt)
B(-7,45,-5,minecraft:basalt)
B(-7,46,-5,minecraft:basalt)
B(-7,47,-5,minecraft:basalt)
B(-7,48,-5,minecraft:basalt)
B(-7,49,-5,minecraft:basalt)
B(-7,50,-5,minecraft:basalt)
B(-7,51,-5,minecraft:basalt)
B(-7,52,-5,minecraft:basalt)
B(-7,53,-5,minecraft:basalt)
B(-7,54,-5,minecraft:basalt)
B(-7,55,-5,minecraft:basalt)
B(-7,43,-4,minecraft:basalt)
B(-7,44,-4,minecraft:basalt)
B(-7,45,-4,minecraft:basalt)
B(-7,46,-4,minecraft:basalt)
B(-7,47,-4,minecraft:basalt)
B(-7,48,-4,minecraft:basalt)
B(-7,49,-4,minecraft:basalt)
B(-7,50,-4,minecraft:basalt)
B(-7,51,-4,minecraft:basalt)
B(-7,52,-4,minecraft:basalt)
B(-7,53,-4,minecraft:basalt)
B(-7,54,-4,minecraft:basalt)
B(-7,55,-4,minecraft:basalt)
B(-6,31,-7,minecraft:basalt)
B(-6,32,-7,minecraft:basalt)
B(-6,33,-7,minecraft:basalt)
B(-6,34,-7,minecraft:basalt)
B(-6,35,-7,minecraft:basalt)
B(-6,36,-7,minecraft:basalt)
B(-6,37,-7,minecraft:basalt)
B(-6,38,-7,minecraft:basalt)
B(-6,39,-7,minecraft:basalt)
B(-6,40,-7,minecraft:basalt)
B(-6,41,-7,minecraft:basalt)
B(-6,42,-7,minecraft:basalt)
B(-6,43,-7,minecraft:basalt)
B(-6,44,-7,minecraft:basalt)
B(-6,45,-7,minecraft:basalt)
B(-6,46,-7,minecraft:basalt)
B(-6,47,-7,minecraft:basalt)
B(-6,48,-7,minecraft:basalt)
B(-6,49,-7,minecraft:basalt)
B(-6,50,-7,minecraft:basalt)
B(-6,51,-7,minecraft:basalt)
B(-6,52,-7,minecraft:basalt)
B(-6,53,-7,minecraft:basalt)
B(-6,54,-7,minecraft:basalt)
B(-6,55,-7,minecraft:basalt)
B(-6,34,-6,minecraft:basalt)
B(-6,35,-6,minecraft:basalt)
B(-6,36,-6,minecraft:basalt)
B(-6,37,-6,minecraft:basalt)
B(-6,38,-6,minecraft:basalt)
B(-6,39,-6,minecraft:basalt)
B(-6,40,-6,minecraft:basalt)
B(-6,41,-6,minecraft:basalt)
B(-6,42,-6,minecraft:basalt)
B(-6,43,-6,minecraft:basalt)
B(-6,44,-6,minecraft:basalt)
B(-6,45,-6,minecraft:basalt)
B(-6,46,-6,minecraft:basalt)
B(-6,47,-6,minecraft:basalt)
B(-6,48,-6,minecraft:basalt)
B(-6,49,-6,minecraft:basalt)
B(-6,50,-6,minecraft:basalt)
B(-6,51,-6,minecraft:basalt)
B(-6,52,-6,minecraft:basalt)
B(-6,53,-6,minecraft:basalt)
B(-6,54,-6,minecraft:basalt)
B(-6,55,-6,minecraft:basalt)
B(-6,43,-5,minecraft:basalt)
B(-6,44,-5,minecraft:basalt)
B(-6,45,-5,minecraft:basalt)
B(-6,46,-5,minecraft:basalt)
B(-6,47,-5,minecraft:basalt)
B(-6,48,-5,minecraft:basalt)
B(-6,49,-5,minecraft:basalt)
B(-6,50,-5,minecraft:basalt)
B(-6,51,-5,minecraft:basalt)
B(-6,52,-5,minecraft:basalt)
B(-6,53,-5,minecraft:basalt)
B(-6,54,-5,minecraft:basalt)
B(-6,55,-5,minecraft:basalt)
B(-6,45,-4,minecraft:basalt)
B(-6,46,-4,minecraft:basalt)
B(-6,47,-4,minecraft:basalt)
B(-6,48,-4,minecraft:basalt)
B(-6,49,-4,minecraft:basalt)
B(-6,50,-4,minecraft:basalt)
B(-6,51,-4,minecraft:basalt)
B(-6,52,-4,minecraft:basalt)
B(-6,53,-4,minecraft:basalt)
B(-6,54,-4,minecraft:basalt)
B(-6,55,-4,minecraft:basalt)
B(-5,33,-7,minecraft:basalt)
B(-5,34,-7,minecraft:basalt)
B(-5,35,-7,minecraft:basalt)
B(-5,36,-7,minecraft:basalt)
B(-5,37,-7,minecraft:basalt)
B(-5,38,-7,minecraft:basalt)
B(-5,39,-7,minecraft:basalt)
B(-5,40,-7,minecraft:basalt)
B(-5,41,-7,minecraft:basalt)
B(-5,42,-7,minecraft:basalt)
B(-5,43,-7,minecraft:basalt)
B(-5,44,-7,minecraft:basalt)
B(-5,45,-7,minecraft:basalt)
B(-5,46,-7,minecraft:basalt)
B(-5,47,-7,minecraft:basalt)
B(-5,48,-7,minecraft:basalt)
B(-5,49,-7,minecraft:basalt)
B(-5,50,-7,minecraft:basalt)
B(-5,51,-7,minecraft:basalt)
B(-5,52,-7,minecraft:basalt)
B(-5,53,-7,minecraft:basalt)
B(-5,54,-7,minecraft:basalt)
B(-5,55,-7,minecraft:basalt)
B(-5,36,-6,minecraft:basalt)
B(-5,37,-6,minecraft:basalt)
B(-5,38,-6,minecraft:basalt)
B(-5,39,-6,minecraft:basalt)
B(-5,40,-6,minecraft:basalt)
B(-5,41,-6,minecraft:basalt)
B(-5,42,-6,minecraft:basalt)
B(-5,43,-6,minecraft:basalt)
B(-5,44,-6,minecraft:basalt)
B(-5,45,-6,minecraft:basalt)
B(-5,46,-6,minecraft:basalt)
B(-5,47,-6,minecraft:basalt)
B(-5,48,-6,minecraft:basalt)
B(-5,49,-6,minecraft:basalt)
B(-5,50,-6,minecraft:basalt)
B(-5,51,-6,minecraft:basalt)
B(-5,52,-6,minecraft:basalt)
B(-5,53,-6,minecraft:basalt)
B(-5,54,-6,minecraft:basalt)
B(-5,55,-6,minecraft:basalt)
B(-5,44,-5,minecraft:basalt)
B(-5,45,-5,minecraft:basalt)
B(-5,46,-5,minecraft:basalt)
B(-5,47,-5,minecraft:basalt)
B(-5,48,-5,minecraft:basalt)
B(-5,49,-5,minecraft:basalt)
B(-5,50,-5,minecraft:basalt)
B(-5,51,-5,minecraft:basalt)
B(-5,52,-5,minecraft:basalt)
B(-5,53,-5,minecraft:basalt)
B(-5,54,-5,minecraft:basalt)
B(-5,55,-5,minecraft:basalt)
B(-5,46,-4,minecraft:basalt)
B(-5,47,-4,minecraft:basalt)
B(-5,48,-4,minecraft:basalt)
B(-5,49,-4,minecraft:basalt)
B(-5,50,-4,minecraft:basalt)
B(-5,51,-4,minecraft:basalt)
B(-5,52,-4,minecraft:basalt)
B(-5,53,-4,minecraft:basalt)
B(-5,54,-4,minecraft:basalt)
B(-5,55,-4,minecraft:basalt)
B(-4,37,-7,minecraft:basalt)
B(-4,38,-7,minecraft:basalt)
B(-4,39,-7,minecraft:basalt)
B(-4,40,-7,minecraft:basalt)
B(-4,41,-7,minecraft:basalt)
B(-4,42,-7,minecraft:basalt)
B(-4,43,-7,minecraft:basalt)
B(-4,44,-7,minecraft:basalt)
B(-4,45,-7,minecraft:basalt)
B(-4,46,-7,minecraft:basalt)
B(-4,47,-7,minecraft:basalt)
B(-4,48,-7,minecraft:basalt)
B(-4,49,-7,minecraft:basalt)
B(-4,50,-7,minecraft:basalt)
B(-4,51,-7,minecraft:basalt)
B(-4,52,-7,minecraft:basalt)
B(-4,53,-7,minecraft:basalt)
B(-4,54,-7,minecraft:basalt)
B(-4,55,-7,minecraft:basalt)
B(-4,40,-6,minecraft:basalt)
B(-4,41,-6,minecraft:basalt)
B(-4,42,-6,minecraft:basalt)
B(-4,43,-6,minecraft:basalt)
B(-4,44,-6,minecraft:basalt)
B(-4,45,-6,minecraft:basalt)
B(-4,46,-6,minecraft:basalt)
B(-4,47,-6,minecraft:basalt)
B(-4,48,-6,minecraft:basalt)
B(-4,49,-6,minecraft:basalt)
B(-4,50,-6,minecraft:basalt)
B(-4,51,-6,minecraft:basalt)
B(-4,52,-6,minecraft:basalt)
B(-4,53,-6,minecraft:basalt)
B(-4,54,-6,minecraft:basalt)
B(-4,55,-6,minecraft:basalt)
B(-4,45,-5,minecraft:basalt)
B(-4,46,-5,minecraft:basalt)
B(-4,47,-5,minecraft:basalt)
B(-4,48,-5,minecraft:basalt)
B(-4,49,-5,minecraft:basalt)
B(-4,50,-5,minecraft:basalt)
B(-4,51,-5,minecraft:basalt)
B(-4,52,-5,minecraft:basalt)
B(-4,53,-5,minecraft:basalt)
B(-4,54,-5,minecraft:basalt)
B(-4,55,-5,minecraft:basalt)
B(-3,41,-7,minecraft:basalt)
B(-3,42,-7,minecraft:basalt)
B(-3,43,-7,minecraft:basalt)
B(-3,44,-7,minecraft:basalt)
B(-3,45,-7,minecraft:basalt)
B(-3,46,-7,minecraft:basalt)
B(-3,47,-7,minecraft:basalt)
B(-3,48,-7,minecraft:basalt)
B(-3,49,-7,minecraft:basalt)
B(-3,50,-7,minecraft:basalt)
B(-3,51,-7,minecraft:basalt)
B(-3,52,-7,minecraft:basalt)
B(-3,53,-7,minecraft:basalt)
B(-3,54,-7,minecraft:basalt)
B(-3,55,-7,minecraft:basalt)
B(-3,46,-6,minecraft:basalt)
B(-3,47,-6,minecraft:basalt)
B(-3,48,-6,minecraft:basalt)
B(-3,49,-6,minecraft:basalt)
B(-3,50,-6,minecraft:basalt)
B(-3,51,-6,minecraft:basalt)
B(-3,52,-6,minecraft:basalt)
B(-3,53,-6,minecraft:basalt)
B(-3,54,-6,minecraft:basalt)
B(-3,55,-6,minecraft:basalt)
B(-2,47,-7,minecraft:basalt)
B(-2,48,-7,minecraft:basalt)
B(-2,49,-7,minecraft:basalt)
B(-2,50,-7,minecraft:basalt)
B(-2,51,-7,minecraft:basalt)
B(-2,52,-7,minecraft:basalt)
B(-2,53,-7,minecraft:basalt)
B(-2,54,-7,minecraft:basalt)
B(-2,55,-7,minecraft:basalt)
B(0,52,-7,minecraft:basalt)
B(0,53,-7,minecraft:basalt)
B(0,54,-7,minecraft:basalt)
B(0,55,-7,minecraft:basalt)
B(1,55,-7,minecraft:basalt)
B(1,55,-6,minecraft:basalt)
B(1,55,-5,minecraft:basalt)
B(1,55,-4,minecraft:basalt)
B(2,54,-7,minecraft:basalt)
B(2,55,-7,minecraft:basalt)
B(2,55,-6,minecraft:basalt)
B(2,55,-5,minecraft:basalt)
B(2,55,-4,minecraft:basalt)
B(2,55,-3,minecraft:basalt)

#######################################################################
# +-----------------------------------------------------------------+ #
# |                             Branches                            | #
# +-----------------------------------------------------------------+ #
#######################################################################


#######################################################################
# +-----------------------------------------------------------------+ #
# |                             Entities                            | #
# +-----------------------------------------------------------------+ #
#######################################################################

