
#######################################################################
# +-----------------------------------------------------------------+ #
# |                            BO4 object                           | #
# +-----------------------------------------------------------------+ #
#######################################################################

Author: Unknown

Description: No description given

SettingsMode: WriteWithoutComments


#######################################################################
# +-----------------------------------------------------------------+ #
# |                          Main settings                          | #
# +-----------------------------------------------------------------+ #
#######################################################################

FixedRotation: 

Frequency: 0

SpawnHeight: highestBlock

UseCenterForHighestBlock: true

##############################
# Height Limits for the BO4. #
##############################

MinHeight: 0

MaxHeight: 255

InheritBO3: 

InheritBO3Rotation: NORTH

OverrideChildSettings: true

OverrideParentHeight: false

CanOverride: false

BranchFrequency: 0

BranchFrequencyGroup: 

MustBeBelowOther: false

MustBeInside: 

CannotBeInside: 

ReplacesBO3: 

MustBeInsideWorldBorders: false

CanSpawnOnWater: true

SpawnOnWaterOnly: false

SpawnUnderWater: false

SpawnAtWaterLevel: false

HeightOffset: 0

RemoveAir: true

ReplaceAbove: 

ReplaceBelow: 

ReplaceWithBiomeBlocks: true

ReplaceWithSurfaceBlock: GRASS

ReplaceWithGroundBlock: DIRT

ReplaceWithStoneBlock: STONE

SmoothRadius: 0

SmoothHeightOffset: 0

SmoothStartTop: false

SmoothStartWood: false

SmoothingSurfaceBlock: 

SmoothingGroundBlock: 

BO3Group: 

IsSpawnPoint: false

DoReplaceBlocks: true


#######################################################################
# +-----------------------------------------------------------------+ #
# |                              Blocks                             | #
# +-----------------------------------------------------------------+ #
#######################################################################

RandomBlock(-4,0,0,minecraft:obsidian,80,minecraft:crying_obsidian,20)
RandomBlock(-4,0,1,minecraft:obsidian,80,minecraft:crying_obsidian,20)
RandomBlock(-4,0,2,minecraft:obsidian,80,minecraft:crying_obsidian,20)
RandomBlock(-4,0,3,minecraft:obsidian,80,minecraft:crying_obsidian,20)
RandomBlock(-4,1,3,minecraft:obsidian,80,minecraft:crying_obsidian,20)
RandomBlock(-4,2,3,minecraft:obsidian,80,minecraft:crying_obsidian,20)
RandomBlock(-4,0,4,minecraft:obsidian,80,minecraft:crying_obsidian,20)
RandomBlock(-4,1,4,minecraft:obsidian,80,minecraft:crying_obsidian,20)
RandomBlock(-4,0,5,minecraft:obsidian,80,minecraft:crying_obsidian,20)
RandomBlock(-4,1,5,minecraft:obsidian,80,minecraft:crying_obsidian,20)
RandomBlock(-4,0,6,minecraft:obsidian,80,minecraft:crying_obsidian,20)
RandomBlock(-4,1,6,minecraft:obsidian,80,minecraft:crying_obsidian,20)
RandomBlock(-4,2,6,minecraft:obsidian,80,minecraft:crying_obsidian,20)
RandomBlock(-4,0,7,minecraft:obsidian,80,minecraft:crying_obsidian,20)
RandomBlock(-3,0,-4,minecraft:obsidian,80,minecraft:crying_obsidian,20)
RandomBlock(-3,0,-3,minecraft:obsidian,80,minecraft:crying_obsidian,20)
RandomBlock(-3,1,-3,minecraft:obsidian,80,minecraft:crying_obsidian,20)
RandomBlock(-3,0,-2,minecraft:obsidian,80,minecraft:crying_obsidian,20)
RandomBlock(-3,1,-2,minecraft:obsidian,80,minecraft:crying_obsidian,20)
RandomBlock(-3,0,-1,minecraft:obsidian,80,minecraft:crying_obsidian,20)
RandomBlock(-3,1,-1,minecraft:obsidian,80,minecraft:crying_obsidian,20)
RandomBlock(-3,2,-1,minecraft:obsidian,80,minecraft:crying_obsidian,20)
RandomBlock(-3,3,-1,minecraft:obsidian,80,minecraft:crying_obsidian,20)
RandomBlock(-3,4,-1,minecraft:obsidian,80,minecraft:crying_obsidian,20)
RandomBlock(-3,0,0,minecraft:obsidian,80,minecraft:crying_obsidian,20)
RandomBlock(-3,1,0,minecraft:obsidian,80,minecraft:crying_obsidian,20)
RandomBlock(-3,2,0,minecraft:obsidian,80,minecraft:crying_obsidian,20)
RandomBlock(-3,3,0,minecraft:obsidian,80,minecraft:crying_obsidian,20)
RandomBlock(-3,4,0,minecraft:obsidian,80,minecraft:crying_obsidian,20)
RandomBlock(-3,5,0,minecraft:obsidian,80,minecraft:crying_obsidian,20)
RandomBlock(-3,6,0,minecraft:obsidian,80,minecraft:crying_obsidian,20)
RandomBlock(-3,0,1,minecraft:obsidian,80,minecraft:crying_obsidian,20)
RandomBlock(-3,1,1,minecraft:obsidian,80,minecraft:crying_obsidian,20)
RandomBlock(-3,2,1,minecraft:obsidian,80,minecraft:crying_obsidian,20)
RandomBlock(-3,3,1,minecraft:obsidian,80,minecraft:crying_obsidian,20)
RandomBlock(-3,4,1,minecraft:obsidian,80,minecraft:crying_obsidian,20)
RandomBlock(-3,5,1,minecraft:obsidian,80,minecraft:crying_obsidian,20)
RandomBlock(-3,6,1,minecraft:obsidian,80,minecraft:crying_obsidian,20)
RandomBlock(-3,0,2,minecraft:obsidian,80,minecraft:crying_obsidian,20)
RandomBlock(-3,1,2,minecraft:obsidian,80,minecraft:crying_obsidian,20)
RandomBlock(-3,2,2,minecraft:obsidian,80,minecraft:crying_obsidian,20)
RandomBlock(-3,3,2,minecraft:obsidian,80,minecraft:crying_obsidian,20)
RandomBlock(-3,4,2,minecraft:obsidian,80,minecraft:crying_obsidian,20)
RandomBlock(-3,5,2,minecraft:obsidian,80,minecraft:crying_obsidian,20)
RandomBlock(-3,6,2,minecraft:obsidian,80,minecraft:crying_obsidian,20)
RandomBlock(-3,7,2,minecraft:obsidian,80,minecraft:crying_obsidian,20)
RandomBlock(-3,8,2,minecraft:obsidian,80,minecraft:crying_obsidian,20)
RandomBlock(-3,9,2,minecraft:obsidian,80,minecraft:crying_obsidian,20)
RandomBlock(-3,10,2,minecraft:obsidian,80,minecraft:crying_obsidian,20)
RandomBlock(-3,11,2,minecraft:obsidian,80,minecraft:crying_obsidian,20)
RandomBlock(-3,12,2,minecraft:obsidian,80,minecraft:crying_obsidian,20)
RandomBlock(-3,13,2,minecraft:obsidian,80,minecraft:crying_obsidian,20)
RandomBlock(-3,14,2,minecraft:obsidian,80,minecraft:crying_obsidian,20)
RandomBlock(-3,0,3,minecraft:obsidian,80,minecraft:crying_obsidian,20)
RandomBlock(-3,1,3,minecraft:obsidian,80,minecraft:crying_obsidian,20)
RandomBlock(-3,2,3,minecraft:obsidian,80,minecraft:crying_obsidian,20)
RandomBlock(-3,3,3,minecraft:obsidian,80,minecraft:crying_obsidian,20)
RandomBlock(-3,4,3,minecraft:obsidian,80,minecraft:crying_obsidian,20)
RandomBlock(-3,5,3,minecraft:obsidian,80,minecraft:crying_obsidian,20)
RandomBlock(-3,6,3,minecraft:obsidian,80,minecraft:crying_obsidian,20)
RandomBlock(-3,7,3,minecraft:obsidian,80,minecraft:crying_obsidian,20)
RandomBlock(-3,8,3,minecraft:obsidian,80,minecraft:crying_obsidian,20)
RandomBlock(-3,9,3,minecraft:obsidian,80,minecraft:crying_obsidian,20)
RandomBlock(-3,10,3,minecraft:obsidian,80,minecraft:crying_obsidian,20)
RandomBlock(-3,11,3,minecraft:obsidian,80,minecraft:crying_obsidian,20)
RandomBlock(-3,12,3,minecraft:obsidian,80,minecraft:crying_obsidian,20)
RandomBlock(-3,13,3,minecraft:obsidian,80,minecraft:crying_obsidian,20)
RandomBlock(-3,14,3,minecraft:obsidian,80,minecraft:crying_obsidian,20)
RandomBlock(-3,0,4,minecraft:obsidian,80,minecraft:crying_obsidian,20)
RandomBlock(-3,1,4,minecraft:obsidian,80,minecraft:crying_obsidian,20)
RandomBlock(-3,2,4,minecraft:obsidian,80,minecraft:crying_obsidian,20)
RandomBlock(-3,3,4,minecraft:obsidian,80,minecraft:crying_obsidian,20)
RandomBlock(-3,4,4,minecraft:obsidian,80,minecraft:crying_obsidian,20)
RandomBlock(-3,5,4,minecraft:obsidian,80,minecraft:crying_obsidian,20)
RandomBlock(-3,6,4,minecraft:obsidian,80,minecraft:crying_obsidian,20)
RandomBlock(-3,7,4,minecraft:obsidian,80,minecraft:crying_obsidian,20)
RandomBlock(-3,0,5,minecraft:obsidian,80,minecraft:crying_obsidian,20)
RandomBlock(-3,1,5,minecraft:obsidian,80,minecraft:crying_obsidian,20)
RandomBlock(-3,2,5,minecraft:obsidian,80,minecraft:crying_obsidian,20)
RandomBlock(-3,3,5,minecraft:obsidian,80,minecraft:crying_obsidian,20)
RandomBlock(-3,4,5,minecraft:obsidian,80,minecraft:crying_obsidian,20)
RandomBlock(-3,5,5,minecraft:obsidian,80,minecraft:crying_obsidian,20)
RandomBlock(-3,0,6,minecraft:obsidian,80,minecraft:crying_obsidian,20)
RandomBlock(-3,1,6,minecraft:obsidian,80,minecraft:crying_obsidian,20)
RandomBlock(-3,2,6,minecraft:obsidian,80,minecraft:crying_obsidian,20)
RandomBlock(-3,3,6,minecraft:obsidian,80,minecraft:crying_obsidian,20)
RandomBlock(-3,4,6,minecraft:obsidian,80,minecraft:crying_obsidian,20)
RandomBlock(-3,5,6,minecraft:obsidian,80,minecraft:crying_obsidian,20)
RandomBlock(-3,0,7,minecraft:obsidian,80,minecraft:crying_obsidian,20)
RandomBlock(-3,1,7,minecraft:obsidian,80,minecraft:crying_obsidian,20)
RandomBlock(-3,2,7,minecraft:obsidian,80,minecraft:crying_obsidian,20)
RandomBlock(-3,3,7,minecraft:obsidian,80,minecraft:crying_obsidian,20)
RandomBlock(-3,4,7,minecraft:obsidian,80,minecraft:crying_obsidian,20)
RandomBlock(-3,5,7,minecraft:obsidian,80,minecraft:crying_obsidian,20)
RandomBlock(-3,0,8,minecraft:obsidian,80,minecraft:crying_obsidian,20)
RandomBlock(-3,1,8,minecraft:obsidian,80,minecraft:crying_obsidian,20)
RandomBlock(-3,2,8,minecraft:obsidian,80,minecraft:crying_obsidian,20)
RandomBlock(-3,3,8,minecraft:obsidian,80,minecraft:crying_obsidian,20)
RandomBlock(-2,0,-4,minecraft:obsidian,80,minecraft:crying_obsidian,20)
RandomBlock(-2,0,-3,minecraft:obsidian,80,minecraft:crying_obsidian,20)
RandomBlock(-2,1,-3,minecraft:obsidian,80,minecraft:crying_obsidian,20)
RandomBlock(-2,0,-2,minecraft:obsidian,80,minecraft:crying_obsidian,20)
RandomBlock(-2,1,-2,minecraft:obsidian,80,minecraft:crying_obsidian,20)
RandomBlock(-2,2,-2,minecraft:obsidian,80,minecraft:crying_obsidian,20)
RandomBlock(-2,3,-2,minecraft:obsidian,80,minecraft:crying_obsidian,20)
RandomBlock(-2,4,-2,minecraft:obsidian,80,minecraft:crying_obsidian,20)
RandomBlock(-2,5,-2,minecraft:obsidian,80,minecraft:crying_obsidian,20)
RandomBlock(-2,6,-2,minecraft:obsidian,80,minecraft:crying_obsidian,20)
RandomBlock(-2,0,-1,minecraft:obsidian,80,minecraft:crying_obsidian,20)
RandomBlock(-2,1,-1,minecraft:obsidian,80,minecraft:crying_obsidian,20)
RandomBlock(-2,2,-1,minecraft:obsidian,80,minecraft:crying_obsidian,20)
RandomBlock(-2,3,-1,minecraft:obsidian,80,minecraft:crying_obsidian,20)
RandomBlock(-2,4,-1,minecraft:obsidian,80,minecraft:crying_obsidian,20)
RandomBlock(-2,5,-1,minecraft:obsidian,80,minecraft:crying_obsidian,20)
RandomBlock(-2,6,-1,minecraft:obsidian,80,minecraft:crying_obsidian,20)
RandomBlock(-2,7,-1,minecraft:obsidian,80,minecraft:crying_obsidian,20)
RandomBlock(-2,8,-1,minecraft:obsidian,80,minecraft:crying_obsidian,20)
RandomBlock(-2,0,0,minecraft:obsidian,80,minecraft:crying_obsidian,20)
RandomBlock(-2,1,0,minecraft:obsidian,80,minecraft:crying_obsidian,20)
RandomBlock(-2,2,0,minecraft:obsidian,80,minecraft:crying_obsidian,20)
RandomBlock(-2,3,0,minecraft:obsidian,80,minecraft:crying_obsidian,20)
RandomBlock(-2,4,0,minecraft:obsidian,80,minecraft:crying_obsidian,20)
RandomBlock(-2,5,0,minecraft:obsidian,80,minecraft:crying_obsidian,20)
RandomBlock(-2,6,0,minecraft:obsidian,80,minecraft:crying_obsidian,20)
RandomBlock(-2,7,0,minecraft:obsidian,80,minecraft:crying_obsidian,20)
RandomBlock(-2,8,0,minecraft:obsidian,80,minecraft:crying_obsidian,20)
RandomBlock(-2,9,0,minecraft:obsidian,80,minecraft:crying_obsidian,20)
RandomBlock(-2,0,1,minecraft:obsidian,80,minecraft:crying_obsidian,20)
RandomBlock(-2,1,1,minecraft:obsidian,80,minecraft:crying_obsidian,20)
RandomBlock(-2,2,1,minecraft:obsidian,80,minecraft:crying_obsidian,20)
RandomBlock(-2,3,1,minecraft:obsidian,80,minecraft:crying_obsidian,20)
RandomBlock(-2,4,1,minecraft:obsidian,80,minecraft:crying_obsidian,20)
RandomBlock(-2,5,1,minecraft:obsidian,80,minecraft:crying_obsidian,20)
RandomBlock(-2,6,1,minecraft:obsidian,80,minecraft:crying_obsidian,20)
RandomBlock(-2,7,1,minecraft:obsidian,80,minecraft:crying_obsidian,20)
RandomBlock(-2,8,1,minecraft:obsidian,80,minecraft:crying_obsidian,20)
RandomBlock(-2,9,1,minecraft:obsidian,80,minecraft:crying_obsidian,20)
RandomBlock(-2,10,1,minecraft:obsidian,80,minecraft:crying_obsidian,20)
RandomBlock(-2,11,1,minecraft:obsidian,80,minecraft:crying_obsidian,20)
RandomBlock(-2,12,1,minecraft:obsidian,80,minecraft:crying_obsidian,20)
RandomBlock(-2,13,1,minecraft:obsidian,80,minecraft:crying_obsidian,20)
RandomBlock(-2,14,1,minecraft:obsidian,80,minecraft:crying_obsidian,20)
RandomBlock(-2,15,1,minecraft:obsidian,80,minecraft:crying_obsidian,20)
RandomBlock(-2,16,1,minecraft:obsidian,80,minecraft:crying_obsidian,20)
RandomBlock(-2,0,2,minecraft:obsidian,80,minecraft:crying_obsidian,20)
RandomBlock(-2,1,2,minecraft:obsidian,80,minecraft:crying_obsidian,20)
RandomBlock(-2,2,2,minecraft:obsidian,80,minecraft:crying_obsidian,20)
RandomBlock(-2,3,2,minecraft:obsidian,80,minecraft:crying_obsidian,20)
RandomBlock(-2,4,2,minecraft:obsidian,80,minecraft:crying_obsidian,20)
RandomBlock(-2,5,2,minecraft:obsidian,80,minecraft:crying_obsidian,20)
RandomBlock(-2,6,2,minecraft:obsidian,80,minecraft:crying_obsidian,20)
RandomBlock(-2,7,2,minecraft:obsidian,80,minecraft:crying_obsidian,20)
RandomBlock(-2,8,2,minecraft:obsidian,80,minecraft:crying_obsidian,20)
RandomBlock(-2,9,2,minecraft:obsidian,80,minecraft:crying_obsidian,20)
RandomBlock(-2,10,2,minecraft:obsidian,80,minecraft:crying_obsidian,20)
RandomBlock(-2,11,2,minecraft:obsidian,80,minecraft:crying_obsidian,20)
RandomBlock(-2,12,2,minecraft:obsidian,80,minecraft:crying_obsidian,20)
RandomBlock(-2,13,2,minecraft:obsidian,80,minecraft:crying_obsidian,20)
RandomBlock(-2,14,2,minecraft:obsidian,80,minecraft:crying_obsidian,20)
RandomBlock(-2,15,2,minecraft:obsidian,80,minecraft:crying_obsidian,20)
RandomBlock(-2,16,2,minecraft:obsidian,80,minecraft:crying_obsidian,20)
RandomBlock(-2,17,2,minecraft:obsidian,80,minecraft:crying_obsidian,20)
RandomBlock(-2,0,3,minecraft:obsidian,80,minecraft:crying_obsidian,20)
RandomBlock(-2,1,3,minecraft:obsidian,80,minecraft:crying_obsidian,20)
RandomBlock(-2,2,3,minecraft:obsidian,80,minecraft:crying_obsidian,20)
RandomBlock(-2,3,3,minecraft:obsidian,80,minecraft:crying_obsidian,20)
RandomBlock(-2,4,3,minecraft:obsidian,80,minecraft:crying_obsidian,20)
RandomBlock(-2,5,3,minecraft:obsidian,80,minecraft:crying_obsidian,20)
RandomBlock(-2,6,3,minecraft:obsidian,80,minecraft:crying_obsidian,20)
RandomBlock(-2,7,3,minecraft:obsidian,80,minecraft:crying_obsidian,20)
RandomBlock(-2,8,3,minecraft:obsidian,80,minecraft:crying_obsidian,20)
RandomBlock(-2,9,3,minecraft:obsidian,80,minecraft:crying_obsidian,20)
RandomBlock(-2,10,3,minecraft:obsidian,80,minecraft:crying_obsidian,20)
RandomBlock(-2,11,3,minecraft:obsidian,80,minecraft:crying_obsidian,20)
RandomBlock(-2,12,3,minecraft:obsidian,80,minecraft:crying_obsidian,20)
RandomBlock(-2,13,3,minecraft:obsidian,80,minecraft:crying_obsidian,20)
RandomBlock(-2,14,3,minecraft:obsidian,80,minecraft:crying_obsidian,20)
RandomBlock(-2,15,3,minecraft:obsidian,80,minecraft:crying_obsidian,20)
RandomBlock(-2,16,3,minecraft:obsidian,80,minecraft:crying_obsidian,20)
RandomBlock(-2,17,3,minecraft:obsidian,80,minecraft:crying_obsidian,20)
RandomBlock(-2,0,4,minecraft:obsidian,80,minecraft:crying_obsidian,20)
RandomBlock(-2,1,4,minecraft:obsidian,80,minecraft:crying_obsidian,20)
RandomBlock(-2,2,4,minecraft:obsidian,80,minecraft:crying_obsidian,20)
RandomBlock(-2,3,4,minecraft:obsidian,80,minecraft:crying_obsidian,20)
RandomBlock(-2,4,4,minecraft:obsidian,80,minecraft:crying_obsidian,20)
RandomBlock(-2,5,4,minecraft:obsidian,80,minecraft:crying_obsidian,20)
RandomBlock(-2,6,4,minecraft:obsidian,80,minecraft:crying_obsidian,20)
RandomBlock(-2,7,4,minecraft:obsidian,80,minecraft:crying_obsidian,20)
RandomBlock(-2,8,4,minecraft:obsidian,80,minecraft:crying_obsidian,20)
RandomBlock(-2,9,4,minecraft:obsidian,80,minecraft:crying_obsidian,20)
RandomBlock(-2,10,4,minecraft:obsidian,80,minecraft:crying_obsidian,20)
RandomBlock(-2,11,4,minecraft:obsidian,80,minecraft:crying_obsidian,20)
RandomBlock(-2,12,4,minecraft:obsidian,80,minecraft:crying_obsidian,20)
RandomBlock(-2,13,4,minecraft:obsidian,80,minecraft:crying_obsidian,20)
RandomBlock(-2,14,4,minecraft:obsidian,80,minecraft:crying_obsidian,20)
RandomBlock(-2,15,4,minecraft:obsidian,80,minecraft:crying_obsidian,20)
RandomBlock(-2,16,4,minecraft:obsidian,80,minecraft:crying_obsidian,20)
RandomBlock(-2,0,5,minecraft:obsidian,80,minecraft:crying_obsidian,20)
RandomBlock(-2,1,5,minecraft:obsidian,80,minecraft:crying_obsidian,20)
RandomBlock(-2,2,5,minecraft:obsidian,80,minecraft:crying_obsidian,20)
RandomBlock(-2,3,5,minecraft:obsidian,80,minecraft:crying_obsidian,20)
RandomBlock(-2,4,5,minecraft:obsidian,80,minecraft:crying_obsidian,20)
RandomBlock(-2,5,5,minecraft:obsidian,80,minecraft:crying_obsidian,20)
RandomBlock(-2,6,5,minecraft:obsidian,80,minecraft:crying_obsidian,20)
RandomBlock(-2,7,5,minecraft:obsidian,80,minecraft:crying_obsidian,20)
RandomBlock(-2,8,5,minecraft:obsidian,80,minecraft:crying_obsidian,20)
RandomBlock(-2,9,5,minecraft:obsidian,80,minecraft:crying_obsidian,20)
RandomBlock(-2,10,5,minecraft:obsidian,80,minecraft:crying_obsidian,20)
RandomBlock(-2,11,5,minecraft:obsidian,80,minecraft:crying_obsidian,20)
RandomBlock(-2,12,5,minecraft:obsidian,80,minecraft:crying_obsidian,20)
RandomBlock(-2,13,5,minecraft:obsidian,80,minecraft:crying_obsidian,20)
RandomBlock(-2,14,5,minecraft:obsidian,80,minecraft:crying_obsidian,20)
RandomBlock(-2,15,5,minecraft:obsidian,80,minecraft:crying_obsidian,20)
RandomBlock(-2,16,5,minecraft:obsidian,80,minecraft:crying_obsidian,20)
RandomBlock(-2,0,6,minecraft:obsidian,80,minecraft:crying_obsidian,20)
RandomBlock(-2,1,6,minecraft:obsidian,80,minecraft:crying_obsidian,20)
RandomBlock(-2,2,6,minecraft:obsidian,80,minecraft:crying_obsidian,20)
RandomBlock(-2,3,6,minecraft:obsidian,80,minecraft:crying_obsidian,20)
RandomBlock(-2,4,6,minecraft:obsidian,80,minecraft:crying_obsidian,20)
RandomBlock(-2,5,6,minecraft:obsidian,80,minecraft:crying_obsidian,20)
RandomBlock(-2,6,6,minecraft:obsidian,80,minecraft:crying_obsidian,20)
RandomBlock(-2,7,6,minecraft:obsidian,80,minecraft:crying_obsidian,20)
RandomBlock(-2,8,6,minecraft:obsidian,80,minecraft:crying_obsidian,20)
RandomBlock(-2,9,6,minecraft:obsidian,80,minecraft:crying_obsidian,20)
RandomBlock(-2,10,6,minecraft:obsidian,80,minecraft:crying_obsidian,20)
RandomBlock(-2,11,6,minecraft:obsidian,80,minecraft:crying_obsidian,20)
RandomBlock(-2,12,6,minecraft:obsidian,80,minecraft:crying_obsidian,20)
RandomBlock(-2,13,6,minecraft:obsidian,80,minecraft:crying_obsidian,20)
RandomBlock(-2,14,6,minecraft:obsidian,80,minecraft:crying_obsidian,20)
RandomBlock(-2,15,6,minecraft:obsidian,80,minecraft:crying_obsidian,20)
RandomBlock(-2,0,7,minecraft:obsidian,80,minecraft:crying_obsidian,20)
RandomBlock(-2,1,7,minecraft:obsidian,80,minecraft:crying_obsidian,20)
RandomBlock(-2,2,7,minecraft:obsidian,80,minecraft:crying_obsidian,20)
RandomBlock(-2,3,7,minecraft:obsidian,80,minecraft:crying_obsidian,20)
RandomBlock(-2,4,7,minecraft:obsidian,80,minecraft:crying_obsidian,20)
RandomBlock(-2,5,7,minecraft:obsidian,80,minecraft:crying_obsidian,20)
RandomBlock(-2,6,7,minecraft:obsidian,80,minecraft:crying_obsidian,20)
RandomBlock(-2,7,7,minecraft:obsidian,80,minecraft:crying_obsidian,20)
RandomBlock(-2,8,7,minecraft:obsidian,80,minecraft:crying_obsidian,20)
RandomBlock(-2,9,7,minecraft:obsidian,80,minecraft:crying_obsidian,20)
RandomBlock(-2,10,7,minecraft:obsidian,80,minecraft:crying_obsidian,20)
RandomBlock(-2,11,7,minecraft:obsidian,80,minecraft:crying_obsidian,20)
RandomBlock(-2,12,7,minecraft:obsidian,80,minecraft:crying_obsidian,20)
RandomBlock(-2,13,7,minecraft:obsidian,80,minecraft:crying_obsidian,20)
RandomBlock(-2,14,7,minecraft:obsidian,80,minecraft:crying_obsidian,20)
RandomBlock(-2,0,8,minecraft:obsidian,80,minecraft:crying_obsidian,20)
RandomBlock(-2,1,8,minecraft:obsidian,80,minecraft:crying_obsidian,20)
RandomBlock(-2,2,8,minecraft:obsidian,80,minecraft:crying_obsidian,20)
RandomBlock(-2,3,8,minecraft:obsidian,80,minecraft:crying_obsidian,20)
RandomBlock(-2,4,8,minecraft:obsidian,80,minecraft:crying_obsidian,20)
RandomBlock(-2,5,8,minecraft:obsidian,80,minecraft:crying_obsidian,20)
RandomBlock(-2,6,8,minecraft:obsidian,80,minecraft:crying_obsidian,20)
RandomBlock(-2,7,8,minecraft:obsidian,80,minecraft:crying_obsidian,20)
RandomBlock(-2,8,8,minecraft:obsidian,80,minecraft:crying_obsidian,20)
RandomBlock(-2,9,8,minecraft:obsidian,80,minecraft:crying_obsidian,20)
RandomBlock(-1,0,-4,minecraft:obsidian,80,minecraft:crying_obsidian,20)
RandomBlock(-1,0,-3,minecraft:obsidian,80,minecraft:crying_obsidian,20)
RandomBlock(-1,1,-3,minecraft:obsidian,80,minecraft:crying_obsidian,20)
RandomBlock(-1,2,-3,minecraft:obsidian,80,minecraft:crying_obsidian,20)
RandomBlock(-1,3,-3,minecraft:obsidian,80,minecraft:crying_obsidian,20)
RandomBlock(-1,4,-3,minecraft:obsidian,80,minecraft:crying_obsidian,20)
RandomBlock(-1,5,-3,minecraft:obsidian,80,minecraft:crying_obsidian,20)
RandomBlock(-1,6,-3,minecraft:obsidian,80,minecraft:crying_obsidian,20)
RandomBlock(-1,7,-3,minecraft:obsidian,80,minecraft:crying_obsidian,20)
RandomBlock(-1,8,-3,minecraft:obsidian,80,minecraft:crying_obsidian,20)
RandomBlock(-1,9,-3,minecraft:obsidian,80,minecraft:crying_obsidian,20)
RandomBlock(-1,0,-2,minecraft:obsidian,80,minecraft:crying_obsidian,20)
RandomBlock(-1,1,-2,minecraft:obsidian,80,minecraft:crying_obsidian,20)
RandomBlock(-1,2,-2,minecraft:obsidian,80,minecraft:crying_obsidian,20)
RandomBlock(-1,3,-2,minecraft:obsidian,80,minecraft:crying_obsidian,20)
RandomBlock(-1,4,-2,minecraft:obsidian,80,minecraft:crying_obsidian,20)
RandomBlock(-1,5,-2,minecraft:obsidian,80,minecraft:crying_obsidian,20)
RandomBlock(-1,6,-2,minecraft:obsidian,80,minecraft:crying_obsidian,20)
RandomBlock(-1,7,-2,minecraft:obsidian,80,minecraft:crying_obsidian,20)
RandomBlock(-1,8,-2,minecraft:obsidian,80,minecraft:crying_obsidian,20)
RandomBlock(-1,9,-2,minecraft:obsidian,80,minecraft:crying_obsidian,20)
RandomBlock(-1,10,-2,minecraft:obsidian,80,minecraft:crying_obsidian,20)
RandomBlock(-1,11,-2,minecraft:obsidian,80,minecraft:crying_obsidian,20)
RandomBlock(-1,12,-2,minecraft:obsidian,80,minecraft:crying_obsidian,20)
RandomBlock(-1,13,-2,minecraft:obsidian,80,minecraft:crying_obsidian,20)
RandomBlock(-1,0,-1,minecraft:obsidian,80,minecraft:crying_obsidian,20)
RandomBlock(-1,1,-1,minecraft:obsidian,80,minecraft:crying_obsidian,20)
RandomBlock(-1,2,-1,minecraft:obsidian,80,minecraft:crying_obsidian,20)
RandomBlock(-1,3,-1,minecraft:obsidian,80,minecraft:crying_obsidian,20)
RandomBlock(-1,4,-1,minecraft:obsidian,80,minecraft:crying_obsidian,20)
RandomBlock(-1,5,-1,minecraft:obsidian,80,minecraft:crying_obsidian,20)
RandomBlock(-1,6,-1,minecraft:obsidian,80,minecraft:crying_obsidian,20)
RandomBlock(-1,7,-1,minecraft:obsidian,80,minecraft:crying_obsidian,20)
RandomBlock(-1,8,-1,minecraft:obsidian,80,minecraft:crying_obsidian,20)
RandomBlock(-1,9,-1,minecraft:obsidian,80,minecraft:crying_obsidian,20)
RandomBlock(-1,10,-1,minecraft:obsidian,80,minecraft:crying_obsidian,20)
RandomBlock(-1,11,-1,minecraft:obsidian,80,minecraft:crying_obsidian,20)
RandomBlock(-1,12,-1,minecraft:obsidian,80,minecraft:crying_obsidian,20)
RandomBlock(-1,13,-1,minecraft:obsidian,80,minecraft:crying_obsidian,20)
RandomBlock(-1,14,-1,minecraft:obsidian,80,minecraft:crying_obsidian,20)
RandomBlock(-1,15,-1,minecraft:obsidian,80,minecraft:crying_obsidian,20)
RandomBlock(-1,16,-1,minecraft:obsidian,80,minecraft:crying_obsidian,20)
RandomBlock(-1,17,-1,minecraft:obsidian,80,minecraft:crying_obsidian,20)
RandomBlock(-1,18,-1,minecraft:obsidian,80,minecraft:crying_obsidian,20)
RandomBlock(-1,19,-1,minecraft:obsidian,80,minecraft:crying_obsidian,20)
RandomBlock(-1,0,0,minecraft:obsidian,80,minecraft:crying_obsidian,20)
RandomBlock(-1,1,0,minecraft:obsidian,80,minecraft:crying_obsidian,20)
RandomBlock(-1,2,0,minecraft:obsidian,80,minecraft:crying_obsidian,20)
RandomBlock(-1,3,0,minecraft:obsidian,80,minecraft:crying_obsidian,20)
RandomBlock(-1,4,0,minecraft:obsidian,80,minecraft:crying_obsidian,20)
RandomBlock(-1,5,0,minecraft:obsidian,80,minecraft:crying_obsidian,20)
RandomBlock(-1,6,0,minecraft:obsidian,80,minecraft:crying_obsidian,20)
RandomBlock(-1,7,0,minecraft:obsidian,80,minecraft:crying_obsidian,20)
RandomBlock(-1,8,0,minecraft:obsidian,80,minecraft:crying_obsidian,20)
RandomBlock(-1,9,0,minecraft:obsidian,80,minecraft:crying_obsidian,20)
RandomBlock(-1,10,0,minecraft:obsidian,80,minecraft:crying_obsidian,20)
RandomBlock(-1,11,0,minecraft:obsidian,80,minecraft:crying_obsidian,20)
RandomBlock(-1,12,0,minecraft:obsidian,80,minecraft:crying_obsidian,20)
RandomBlock(-1,13,0,minecraft:obsidian,80,minecraft:crying_obsidian,20)
RandomBlock(-1,14,0,minecraft:obsidian,80,minecraft:crying_obsidian,20)
RandomBlock(-1,15,0,minecraft:obsidian,80,minecraft:crying_obsidian,20)
RandomBlock(-1,16,0,minecraft:obsidian,80,minecraft:crying_obsidian,20)
RandomBlock(-1,17,0,minecraft:obsidian,80,minecraft:crying_obsidian,20)
RandomBlock(-1,18,0,minecraft:obsidian,80,minecraft:crying_obsidian,20)
RandomBlock(-1,19,0,minecraft:obsidian,80,minecraft:crying_obsidian,20)
RandomBlock(-1,0,1,minecraft:obsidian,80,minecraft:crying_obsidian,20)
RandomBlock(-1,1,1,minecraft:obsidian,80,minecraft:crying_obsidian,20)
RandomBlock(-1,2,1,minecraft:obsidian,80,minecraft:crying_obsidian,20)
RandomBlock(-1,3,1,minecraft:obsidian,80,minecraft:crying_obsidian,20)
RandomBlock(-1,4,1,minecraft:obsidian,80,minecraft:crying_obsidian,20)
RandomBlock(-1,5,1,minecraft:obsidian,80,minecraft:crying_obsidian,20)
RandomBlock(-1,6,1,minecraft:obsidian,80,minecraft:crying_obsidian,20)
RandomBlock(-1,7,1,minecraft:obsidian,80,minecraft:crying_obsidian,20)
RandomBlock(-1,8,1,minecraft:obsidian,80,minecraft:crying_obsidian,20)
RandomBlock(-1,9,1,minecraft:obsidian,80,minecraft:crying_obsidian,20)
RandomBlock(-1,10,1,minecraft:obsidian,80,minecraft:crying_obsidian,20)
RandomBlock(-1,11,1,minecraft:obsidian,80,minecraft:crying_obsidian,20)
RandomBlock(-1,12,1,minecraft:obsidian,80,minecraft:crying_obsidian,20)
RandomBlock(-1,13,1,minecraft:obsidian,80,minecraft:crying_obsidian,20)
RandomBlock(-1,14,1,minecraft:obsidian,80,minecraft:crying_obsidian,20)
RandomBlock(-1,15,1,minecraft:obsidian,80,minecraft:crying_obsidian,20)
RandomBlock(-1,16,1,minecraft:obsidian,80,minecraft:crying_obsidian,20)
RandomBlock(-1,17,1,minecraft:obsidian,80,minecraft:crying_obsidian,20)
RandomBlock(-1,18,1,minecraft:obsidian,80,minecraft:crying_obsidian,20)
RandomBlock(-1,19,1,minecraft:obsidian,80,minecraft:crying_obsidian,20)
RandomBlock(-1,20,1,minecraft:obsidian,80,minecraft:crying_obsidian,20)
RandomBlock(-1,0,2,minecraft:obsidian,80,minecraft:crying_obsidian,20)
RandomBlock(-1,1,2,minecraft:obsidian,80,minecraft:crying_obsidian,20)
RandomBlock(-1,2,2,minecraft:obsidian,80,minecraft:crying_obsidian,20)
RandomBlock(-1,3,2,minecraft:obsidian,80,minecraft:crying_obsidian,20)
RandomBlock(-1,4,2,minecraft:obsidian,80,minecraft:crying_obsidian,20)
RandomBlock(-1,5,2,minecraft:obsidian,80,minecraft:crying_obsidian,20)
RandomBlock(-1,6,2,minecraft:obsidian,80,minecraft:crying_obsidian,20)
RandomBlock(-1,7,2,minecraft:obsidian,80,minecraft:crying_obsidian,20)
RandomBlock(-1,8,2,minecraft:obsidian,80,minecraft:crying_obsidian,20)
RandomBlock(-1,9,2,minecraft:obsidian,80,minecraft:crying_obsidian,20)
RandomBlock(-1,10,2,minecraft:obsidian,80,minecraft:crying_obsidian,20)
RandomBlock(-1,11,2,minecraft:obsidian,80,minecraft:crying_obsidian,20)
RandomBlock(-1,12,2,minecraft:obsidian,80,minecraft:crying_obsidian,20)
RandomBlock(-1,13,2,minecraft:obsidian,80,minecraft:crying_obsidian,20)
RandomBlock(-1,14,2,minecraft:obsidian,80,minecraft:crying_obsidian,20)
RandomBlock(-1,15,2,minecraft:obsidian,80,minecraft:crying_obsidian,20)
RandomBlock(-1,16,2,minecraft:obsidian,80,minecraft:crying_obsidian,20)
RandomBlock(-1,17,2,minecraft:obsidian,80,minecraft:crying_obsidian,20)
RandomBlock(-1,18,2,minecraft:obsidian,80,minecraft:crying_obsidian,20)
RandomBlock(-1,19,2,minecraft:obsidian,80,minecraft:crying_obsidian,20)
RandomBlock(-1,20,2,minecraft:obsidian,80,minecraft:crying_obsidian,20)
RandomBlock(-1,0,3,minecraft:obsidian,80,minecraft:crying_obsidian,20)
RandomBlock(-1,1,3,minecraft:obsidian,80,minecraft:crying_obsidian,20)
RandomBlock(-1,2,3,minecraft:obsidian,80,minecraft:crying_obsidian,20)
RandomBlock(-1,3,3,minecraft:obsidian,80,minecraft:crying_obsidian,20)
RandomBlock(-1,4,3,minecraft:obsidian,80,minecraft:crying_obsidian,20)
RandomBlock(-1,5,3,minecraft:obsidian,80,minecraft:crying_obsidian,20)
RandomBlock(-1,6,3,minecraft:obsidian,80,minecraft:crying_obsidian,20)
RandomBlock(-1,7,3,minecraft:obsidian,80,minecraft:crying_obsidian,20)
RandomBlock(-1,8,3,minecraft:obsidian,80,minecraft:crying_obsidian,20)
RandomBlock(-1,9,3,minecraft:obsidian,80,minecraft:crying_obsidian,20)
RandomBlock(-1,10,3,minecraft:obsidian,80,minecraft:crying_obsidian,20)
RandomBlock(-1,11,3,minecraft:obsidian,80,minecraft:crying_obsidian,20)
RandomBlock(-1,12,3,minecraft:obsidian,80,minecraft:crying_obsidian,20)
RandomBlock(-1,13,3,minecraft:obsidian,80,minecraft:crying_obsidian,20)
RandomBlock(-1,14,3,minecraft:obsidian,80,minecraft:crying_obsidian,20)
RandomBlock(-1,15,3,minecraft:obsidian,80,minecraft:crying_obsidian,20)
RandomBlock(-1,16,3,minecraft:obsidian,80,minecraft:crying_obsidian,20)
RandomBlock(-1,17,3,minecraft:obsidian,80,minecraft:crying_obsidian,20)
RandomBlock(-1,18,3,minecraft:obsidian,80,minecraft:crying_obsidian,20)
RandomBlock(-1,19,3,minecraft:obsidian,80,minecraft:crying_obsidian,20)
RandomBlock(-1,20,3,minecraft:obsidian,80,minecraft:crying_obsidian,20)
RandomBlock(-1,0,4,minecraft:obsidian,80,minecraft:crying_obsidian,20)
RandomBlock(-1,1,4,minecraft:obsidian,80,minecraft:crying_obsidian,20)
RandomBlock(-1,2,4,minecraft:obsidian,80,minecraft:crying_obsidian,20)
RandomBlock(-1,3,4,minecraft:obsidian,80,minecraft:crying_obsidian,20)
RandomBlock(-1,4,4,minecraft:obsidian,80,minecraft:crying_obsidian,20)
RandomBlock(-1,5,4,minecraft:obsidian,80,minecraft:crying_obsidian,20)
RandomBlock(-1,6,4,minecraft:obsidian,80,minecraft:crying_obsidian,20)
RandomBlock(-1,7,4,minecraft:obsidian,80,minecraft:crying_obsidian,20)
RandomBlock(-1,8,4,minecraft:obsidian,80,minecraft:crying_obsidian,20)
RandomBlock(-1,9,4,minecraft:obsidian,80,minecraft:crying_obsidian,20)
RandomBlock(-1,10,4,minecraft:obsidian,80,minecraft:crying_obsidian,20)
RandomBlock(-1,11,4,minecraft:obsidian,80,minecraft:crying_obsidian,20)
RandomBlock(-1,12,4,minecraft:obsidian,80,minecraft:crying_obsidian,20)
RandomBlock(-1,13,4,minecraft:obsidian,80,minecraft:crying_obsidian,20)
RandomBlock(-1,14,4,minecraft:obsidian,80,minecraft:crying_obsidian,20)
RandomBlock(-1,15,4,minecraft:obsidian,80,minecraft:crying_obsidian,20)
RandomBlock(-1,16,4,minecraft:obsidian,80,minecraft:crying_obsidian,20)
RandomBlock(-1,17,4,minecraft:obsidian,80,minecraft:crying_obsidian,20)
RandomBlock(-1,18,4,minecraft:obsidian,80,minecraft:crying_obsidian,20)
RandomBlock(-1,19,4,minecraft:obsidian,80,minecraft:crying_obsidian,20)
RandomBlock(-1,20,4,minecraft:obsidian,80,minecraft:crying_obsidian,20)
RandomBlock(-1,0,5,minecraft:obsidian,80,minecraft:crying_obsidian,20)
RandomBlock(-1,1,5,minecraft:obsidian,80,minecraft:crying_obsidian,20)
RandomBlock(-1,2,5,minecraft:obsidian,80,minecraft:crying_obsidian,20)
RandomBlock(-1,3,5,minecraft:obsidian,80,minecraft:crying_obsidian,20)
RandomBlock(-1,4,5,minecraft:obsidian,80,minecraft:crying_obsidian,20)
RandomBlock(-1,5,5,minecraft:obsidian,80,minecraft:crying_obsidian,20)
RandomBlock(-1,6,5,minecraft:obsidian,80,minecraft:crying_obsidian,20)
RandomBlock(-1,7,5,minecraft:obsidian,80,minecraft:crying_obsidian,20)
RandomBlock(-1,8,5,minecraft:obsidian,80,minecraft:crying_obsidian,20)
RandomBlock(-1,9,5,minecraft:obsidian,80,minecraft:crying_obsidian,20)
RandomBlock(-1,10,5,minecraft:obsidian,80,minecraft:crying_obsidian,20)
RandomBlock(-1,11,5,minecraft:obsidian,80,minecraft:crying_obsidian,20)
RandomBlock(-1,12,5,minecraft:obsidian,80,minecraft:crying_obsidian,20)
RandomBlock(-1,13,5,minecraft:obsidian,80,minecraft:crying_obsidian,20)
RandomBlock(-1,14,5,minecraft:obsidian,80,minecraft:crying_obsidian,20)
RandomBlock(-1,15,5,minecraft:obsidian,80,minecraft:crying_obsidian,20)
RandomBlock(-1,16,5,minecraft:obsidian,80,minecraft:crying_obsidian,20)
RandomBlock(-1,17,5,minecraft:obsidian,80,minecraft:crying_obsidian,20)
RandomBlock(-1,18,5,minecraft:obsidian,80,minecraft:crying_obsidian,20)
RandomBlock(-1,19,5,minecraft:obsidian,80,minecraft:crying_obsidian,20)
RandomBlock(-1,0,6,minecraft:obsidian,80,minecraft:crying_obsidian,20)
RandomBlock(-1,1,6,minecraft:obsidian,80,minecraft:crying_obsidian,20)
RandomBlock(-1,2,6,minecraft:obsidian,80,minecraft:crying_obsidian,20)
RandomBlock(-1,3,6,minecraft:obsidian,80,minecraft:crying_obsidian,20)
RandomBlock(-1,4,6,minecraft:obsidian,80,minecraft:crying_obsidian,20)
RandomBlock(-1,5,6,minecraft:obsidian,80,minecraft:crying_obsidian,20)
RandomBlock(-1,6,6,minecraft:obsidian,80,minecraft:crying_obsidian,20)
RandomBlock(-1,7,6,minecraft:obsidian,80,minecraft:crying_obsidian,20)
RandomBlock(-1,8,6,minecraft:obsidian,80,minecraft:crying_obsidian,20)
RandomBlock(-1,9,6,minecraft:obsidian,80,minecraft:crying_obsidian,20)
RandomBlock(-1,10,6,minecraft:obsidian,80,minecraft:crying_obsidian,20)
RandomBlock(-1,11,6,minecraft:obsidian,80,minecraft:crying_obsidian,20)
RandomBlock(-1,12,6,minecraft:obsidian,80,minecraft:crying_obsidian,20)
RandomBlock(-1,13,6,minecraft:obsidian,80,minecraft:crying_obsidian,20)
RandomBlock(-1,14,6,minecraft:obsidian,80,minecraft:crying_obsidian,20)
RandomBlock(-1,15,6,minecraft:obsidian,80,minecraft:crying_obsidian,20)
RandomBlock(-1,16,6,minecraft:obsidian,80,minecraft:crying_obsidian,20)
RandomBlock(-1,17,6,minecraft:obsidian,80,minecraft:crying_obsidian,20)
RandomBlock(-1,18,6,minecraft:obsidian,80,minecraft:crying_obsidian,20)
RandomBlock(-1,0,7,minecraft:obsidian,80,minecraft:crying_obsidian,20)
RandomBlock(-1,1,7,minecraft:obsidian,80,minecraft:crying_obsidian,20)
RandomBlock(-1,2,7,minecraft:obsidian,80,minecraft:crying_obsidian,20)
RandomBlock(-1,3,7,minecraft:obsidian,80,minecraft:crying_obsidian,20)
RandomBlock(-1,4,7,minecraft:obsidian,80,minecraft:crying_obsidian,20)
RandomBlock(-1,5,7,minecraft:obsidian,80,minecraft:crying_obsidian,20)
RandomBlock(-1,6,7,minecraft:obsidian,80,minecraft:crying_obsidian,20)
RandomBlock(-1,7,7,minecraft:obsidian,80,minecraft:crying_obsidian,20)
RandomBlock(-1,8,7,minecraft:obsidian,80,minecraft:crying_obsidian,20)
RandomBlock(-1,9,7,minecraft:obsidian,80,minecraft:crying_obsidian,20)
RandomBlock(-1,10,7,minecraft:obsidian,80,minecraft:crying_obsidian,20)
RandomBlock(-1,11,7,minecraft:obsidian,80,minecraft:crying_obsidian,20)
RandomBlock(-1,12,7,minecraft:obsidian,80,minecraft:crying_obsidian,20)
RandomBlock(-1,13,7,minecraft:obsidian,80,minecraft:crying_obsidian,20)
RandomBlock(-1,14,7,minecraft:obsidian,80,minecraft:crying_obsidian,20)
RandomBlock(-1,15,7,minecraft:obsidian,80,minecraft:crying_obsidian,20)
RandomBlock(-1,16,7,minecraft:obsidian,80,minecraft:crying_obsidian,20)
RandomBlock(-1,0,8,minecraft:obsidian,80,minecraft:crying_obsidian,20)
RandomBlock(-1,1,8,minecraft:obsidian,80,minecraft:crying_obsidian,20)
RandomBlock(-1,2,8,minecraft:obsidian,80,minecraft:crying_obsidian,20)
RandomBlock(-1,3,8,minecraft:obsidian,80,minecraft:crying_obsidian,20)
RandomBlock(-1,4,8,minecraft:obsidian,80,minecraft:crying_obsidian,20)
RandomBlock(-1,5,8,minecraft:obsidian,80,minecraft:crying_obsidian,20)
RandomBlock(-1,6,8,minecraft:obsidian,80,minecraft:crying_obsidian,20)
RandomBlock(-1,7,8,minecraft:obsidian,80,minecraft:crying_obsidian,20)
RandomBlock(-1,8,8,minecraft:obsidian,80,minecraft:crying_obsidian,20)
RandomBlock(-1,9,8,minecraft:obsidian,80,minecraft:crying_obsidian,20)
RandomBlock(-1,10,8,minecraft:obsidian,80,minecraft:crying_obsidian,20)
RandomBlock(-1,11,8,minecraft:obsidian,80,minecraft:crying_obsidian,20)
RandomBlock(-1,12,8,minecraft:obsidian,80,minecraft:crying_obsidian,20)
RandomBlock(-1,13,8,minecraft:obsidian,80,minecraft:crying_obsidian,20)
RandomBlock(-1,14,8,minecraft:obsidian,80,minecraft:crying_obsidian,20)
RandomBlock(-1,15,8,minecraft:obsidian,80,minecraft:crying_obsidian,20)
RandomBlock(0,0,-5,minecraft:obsidian,80,minecraft:crying_obsidian,20)
RandomBlock(0,1,-5,minecraft:obsidian,80,minecraft:crying_obsidian,20)
RandomBlock(0,2,-5,minecraft:obsidian,80,minecraft:crying_obsidian,20)
RandomBlock(0,0,-4,minecraft:obsidian,80,minecraft:crying_obsidian,20)
RandomBlock(0,1,-4,minecraft:obsidian,80,minecraft:crying_obsidian,20)
RandomBlock(0,2,-4,minecraft:obsidian,80,minecraft:crying_obsidian,20)
RandomBlock(0,3,-4,minecraft:obsidian,80,minecraft:crying_obsidian,20)
RandomBlock(0,4,-4,minecraft:obsidian,80,minecraft:crying_obsidian,20)
RandomBlock(0,5,-4,minecraft:obsidian,80,minecraft:crying_obsidian,20)
RandomBlock(0,6,-4,minecraft:obsidian,80,minecraft:crying_obsidian,20)
RandomBlock(0,7,-4,minecraft:obsidian,80,minecraft:crying_obsidian,20)
RandomBlock(0,8,-4,minecraft:obsidian,80,minecraft:crying_obsidian,20)
RandomBlock(0,9,-4,minecraft:obsidian,80,minecraft:crying_obsidian,20)
RandomBlock(0,10,-4,minecraft:obsidian,80,minecraft:crying_obsidian,20)
RandomBlock(0,11,-4,minecraft:obsidian,80,minecraft:crying_obsidian,20)
RandomBlock(0,12,-4,minecraft:obsidian,80,minecraft:crying_obsidian,20)
RandomBlock(0,13,-4,minecraft:obsidian,80,minecraft:crying_obsidian,20)
RandomBlock(0,0,-3,minecraft:obsidian,80,minecraft:crying_obsidian,20)
RandomBlock(0,1,-3,minecraft:obsidian,80,minecraft:crying_obsidian,20)
RandomBlock(0,2,-3,minecraft:obsidian,80,minecraft:crying_obsidian,20)
RandomBlock(0,3,-3,minecraft:obsidian,80,minecraft:crying_obsidian,20)
RandomBlock(0,4,-3,minecraft:obsidian,80,minecraft:crying_obsidian,20)
RandomBlock(0,5,-3,minecraft:obsidian,80,minecraft:crying_obsidian,20)
RandomBlock(0,6,-3,minecraft:obsidian,80,minecraft:crying_obsidian,20)
RandomBlock(0,7,-3,minecraft:obsidian,80,minecraft:crying_obsidian,20)
RandomBlock(0,8,-3,minecraft:obsidian,80,minecraft:crying_obsidian,20)
RandomBlock(0,9,-3,minecraft:obsidian,80,minecraft:crying_obsidian,20)
RandomBlock(0,10,-3,minecraft:obsidian,80,minecraft:crying_obsidian,20)
RandomBlock(0,11,-3,minecraft:obsidian,80,minecraft:crying_obsidian,20)
RandomBlock(0,12,-3,minecraft:obsidian,80,minecraft:crying_obsidian,20)
RandomBlock(0,13,-3,minecraft:obsidian,80,minecraft:crying_obsidian,20)
RandomBlock(0,14,-3,minecraft:obsidian,80,minecraft:crying_obsidian,20)
RandomBlock(0,15,-3,minecraft:obsidian,80,minecraft:crying_obsidian,20)
RandomBlock(0,16,-3,minecraft:obsidian,80,minecraft:crying_obsidian,20)
RandomBlock(0,17,-3,minecraft:obsidian,80,minecraft:crying_obsidian,20)
RandomBlock(0,18,-3,minecraft:obsidian,80,minecraft:crying_obsidian,20)
RandomBlock(0,19,-3,minecraft:obsidian,80,minecraft:crying_obsidian,20)
RandomBlock(0,0,-2,minecraft:obsidian,80,minecraft:crying_obsidian,20)
RandomBlock(0,1,-2,minecraft:obsidian,80,minecraft:crying_obsidian,20)
RandomBlock(0,2,-2,minecraft:obsidian,80,minecraft:crying_obsidian,20)
RandomBlock(0,3,-2,minecraft:obsidian,80,minecraft:crying_obsidian,20)
RandomBlock(0,4,-2,minecraft:obsidian,80,minecraft:crying_obsidian,20)
RandomBlock(0,5,-2,minecraft:obsidian,80,minecraft:crying_obsidian,20)
RandomBlock(0,6,-2,minecraft:obsidian,80,minecraft:crying_obsidian,20)
RandomBlock(0,7,-2,minecraft:obsidian,80,minecraft:crying_obsidian,20)
RandomBlock(0,8,-2,minecraft:obsidian,80,minecraft:crying_obsidian,20)
RandomBlock(0,9,-2,minecraft:obsidian,80,minecraft:crying_obsidian,20)
RandomBlock(0,10,-2,minecraft:obsidian,80,minecraft:crying_obsidian,20)
RandomBlock(0,11,-2,minecraft:obsidian,80,minecraft:crying_obsidian,20)
RandomBlock(0,12,-2,minecraft:obsidian,80,minecraft:crying_obsidian,20)
RandomBlock(0,13,-2,minecraft:obsidian,80,minecraft:crying_obsidian,20)
RandomBlock(0,14,-2,minecraft:obsidian,80,minecraft:crying_obsidian,20)
RandomBlock(0,15,-2,minecraft:obsidian,80,minecraft:crying_obsidian,20)
RandomBlock(0,16,-2,minecraft:obsidian,80,minecraft:crying_obsidian,20)
RandomBlock(0,17,-2,minecraft:obsidian,80,minecraft:crying_obsidian,20)
RandomBlock(0,18,-2,minecraft:obsidian,80,minecraft:crying_obsidian,20)
RandomBlock(0,19,-2,minecraft:obsidian,80,minecraft:crying_obsidian,20)
RandomBlock(0,20,-2,minecraft:obsidian,80,minecraft:crying_obsidian,20)
RandomBlock(0,21,-2,minecraft:obsidian,80,minecraft:crying_obsidian,20)
RandomBlock(0,22,-2,minecraft:obsidian,80,minecraft:crying_obsidian,20)
RandomBlock(0,0,-1,minecraft:obsidian,80,minecraft:crying_obsidian,20)
RandomBlock(0,1,-1,minecraft:obsidian,80,minecraft:crying_obsidian,20)
RandomBlock(0,2,-1,minecraft:obsidian,80,minecraft:crying_obsidian,20)
RandomBlock(0,3,-1,minecraft:obsidian,80,minecraft:crying_obsidian,20)
RandomBlock(0,4,-1,minecraft:obsidian,80,minecraft:crying_obsidian,20)
RandomBlock(0,5,-1,minecraft:obsidian,80,minecraft:crying_obsidian,20)
RandomBlock(0,6,-1,minecraft:obsidian,80,minecraft:crying_obsidian,20)
RandomBlock(0,7,-1,minecraft:obsidian,80,minecraft:crying_obsidian,20)
RandomBlock(0,8,-1,minecraft:obsidian,80,minecraft:crying_obsidian,20)
RandomBlock(0,9,-1,minecraft:obsidian,80,minecraft:crying_obsidian,20)
RandomBlock(0,10,-1,minecraft:obsidian,80,minecraft:crying_obsidian,20)
RandomBlock(0,11,-1,minecraft:obsidian,80,minecraft:crying_obsidian,20)
RandomBlock(0,12,-1,minecraft:obsidian,80,minecraft:crying_obsidian,20)
RandomBlock(0,13,-1,minecraft:obsidian,80,minecraft:crying_obsidian,20)
RandomBlock(0,14,-1,minecraft:obsidian,80,minecraft:crying_obsidian,20)
RandomBlock(0,15,-1,minecraft:obsidian,80,minecraft:crying_obsidian,20)
RandomBlock(0,16,-1,minecraft:obsidian,80,minecraft:crying_obsidian,20)
RandomBlock(0,17,-1,minecraft:obsidian,80,minecraft:crying_obsidian,20)
RandomBlock(0,18,-1,minecraft:obsidian,80,minecraft:crying_obsidian,20)
RandomBlock(0,19,-1,minecraft:obsidian,80,minecraft:crying_obsidian,20)
RandomBlock(0,20,-1,minecraft:obsidian,80,minecraft:crying_obsidian,20)
RandomBlock(0,21,-1,minecraft:obsidian,80,minecraft:crying_obsidian,20)
RandomBlock(0,22,-1,minecraft:obsidian,80,minecraft:crying_obsidian,20)
RandomBlock(0,0,0,minecraft:obsidian,80,minecraft:crying_obsidian,20)
RandomBlock(0,1,0,minecraft:obsidian,80,minecraft:crying_obsidian,20)
RandomBlock(0,2,0,minecraft:obsidian,80,minecraft:crying_obsidian,20)
RandomBlock(0,3,0,minecraft:obsidian,80,minecraft:crying_obsidian,20)
RandomBlock(0,4,0,minecraft:obsidian,80,minecraft:crying_obsidian,20)
RandomBlock(0,5,0,minecraft:obsidian,80,minecraft:crying_obsidian,20)
RandomBlock(0,6,0,minecraft:obsidian,80,minecraft:crying_obsidian,20)
RandomBlock(0,7,0,minecraft:obsidian,80,minecraft:crying_obsidian,20)
RandomBlock(0,8,0,minecraft:obsidian,80,minecraft:crying_obsidian,20)
RandomBlock(0,9,0,minecraft:obsidian,80,minecraft:crying_obsidian,20)
RandomBlock(0,10,0,minecraft:obsidian,80,minecraft:crying_obsidian,20)
RandomBlock(0,11,0,minecraft:obsidian,80,minecraft:crying_obsidian,20)
RandomBlock(0,12,0,minecraft:obsidian,80,minecraft:crying_obsidian,20)
RandomBlock(0,13,0,minecraft:obsidian,80,minecraft:crying_obsidian,20)
RandomBlock(0,14,0,minecraft:obsidian,80,minecraft:crying_obsidian,20)
RandomBlock(0,15,0,minecraft:obsidian,80,minecraft:crying_obsidian,20)
RandomBlock(0,16,0,minecraft:obsidian,80,minecraft:crying_obsidian,20)
RandomBlock(0,17,0,minecraft:obsidian,80,minecraft:crying_obsidian,20)
RandomBlock(0,18,0,minecraft:obsidian,80,minecraft:crying_obsidian,20)
RandomBlock(0,19,0,minecraft:obsidian,80,minecraft:crying_obsidian,20)
RandomBlock(0,20,0,minecraft:obsidian,80,minecraft:crying_obsidian,20)
RandomBlock(0,21,0,minecraft:obsidian,80,minecraft:crying_obsidian,20)
RandomBlock(0,22,0,minecraft:obsidian,80,minecraft:crying_obsidian,20)
RandomBlock(0,23,0,minecraft:obsidian,80,minecraft:crying_obsidian,20)
RandomBlock(0,0,1,minecraft:obsidian,80,minecraft:crying_obsidian,20)
RandomBlock(0,1,1,minecraft:obsidian,80,minecraft:crying_obsidian,20)
RandomBlock(0,2,1,minecraft:obsidian,80,minecraft:crying_obsidian,20)
RandomBlock(0,3,1,minecraft:obsidian,80,minecraft:crying_obsidian,20)
RandomBlock(0,4,1,minecraft:obsidian,80,minecraft:crying_obsidian,20)
RandomBlock(0,5,1,minecraft:obsidian,80,minecraft:crying_obsidian,20)
RandomBlock(0,6,1,minecraft:obsidian,80,minecraft:crying_obsidian,20)
RandomBlock(0,7,1,minecraft:obsidian,80,minecraft:crying_obsidian,20)
RandomBlock(0,8,1,minecraft:obsidian,80,minecraft:crying_obsidian,20)
RandomBlock(0,9,1,minecraft:obsidian,80,minecraft:crying_obsidian,20)
RandomBlock(0,10,1,minecraft:obsidian,80,minecraft:crying_obsidian,20)
RandomBlock(0,11,1,minecraft:obsidian,80,minecraft:crying_obsidian,20)
RandomBlock(0,12,1,minecraft:obsidian,80,minecraft:crying_obsidian,20)
RandomBlock(0,13,1,minecraft:obsidian,80,minecraft:crying_obsidian,20)
RandomBlock(0,14,1,minecraft:obsidian,80,minecraft:crying_obsidian,20)
RandomBlock(0,15,1,minecraft:obsidian,80,minecraft:crying_obsidian,20)
RandomBlock(0,16,1,minecraft:obsidian,80,minecraft:crying_obsidian,20)
RandomBlock(0,17,1,minecraft:obsidian,80,minecraft:crying_obsidian,20)
RandomBlock(0,18,1,minecraft:obsidian,80,minecraft:crying_obsidian,20)
RandomBlock(0,19,1,minecraft:obsidian,80,minecraft:crying_obsidian,20)
RandomBlock(0,20,1,minecraft:obsidian,80,minecraft:crying_obsidian,20)
RandomBlock(0,21,1,minecraft:obsidian,80,minecraft:crying_obsidian,20)
RandomBlock(0,22,1,minecraft:obsidian,80,minecraft:crying_obsidian,20)
RandomBlock(0,23,1,minecraft:obsidian,80,minecraft:crying_obsidian,20)
RandomBlock(0,0,2,minecraft:obsidian,80,minecraft:crying_obsidian,20)
RandomBlock(0,1,2,minecraft:obsidian,80,minecraft:crying_obsidian,20)
RandomBlock(0,2,2,minecraft:obsidian,80,minecraft:crying_obsidian,20)
RandomBlock(0,3,2,minecraft:obsidian,80,minecraft:crying_obsidian,20)
RandomBlock(0,4,2,minecraft:obsidian,80,minecraft:crying_obsidian,20)
RandomBlock(0,5,2,minecraft:obsidian,80,minecraft:crying_obsidian,20)
RandomBlock(0,6,2,minecraft:obsidian,80,minecraft:crying_obsidian,20)
RandomBlock(0,7,2,minecraft:obsidian,80,minecraft:crying_obsidian,20)
RandomBlock(0,8,2,minecraft:obsidian,80,minecraft:crying_obsidian,20)
RandomBlock(0,9,2,minecraft:obsidian,80,minecraft:crying_obsidian,20)
RandomBlock(0,10,2,minecraft:obsidian,80,minecraft:crying_obsidian,20)
RandomBlock(0,11,2,minecraft:obsidian,80,minecraft:crying_obsidian,20)
RandomBlock(0,12,2,minecraft:obsidian,80,minecraft:crying_obsidian,20)
RandomBlock(0,13,2,minecraft:obsidian,80,minecraft:crying_obsidian,20)
RandomBlock(0,14,2,minecraft:obsidian,80,minecraft:crying_obsidian,20)
RandomBlock(0,15,2,minecraft:obsidian,80,minecraft:crying_obsidian,20)
RandomBlock(0,16,2,minecraft:obsidian,80,minecraft:crying_obsidian,20)
RandomBlock(0,17,2,minecraft:obsidian,80,minecraft:crying_obsidian,20)
RandomBlock(0,18,2,minecraft:obsidian,80,minecraft:crying_obsidian,20)
RandomBlock(0,19,2,minecraft:obsidian,80,minecraft:crying_obsidian,20)
RandomBlock(0,20,2,minecraft:obsidian,80,minecraft:crying_obsidian,20)
RandomBlock(0,21,2,minecraft:obsidian,80,minecraft:crying_obsidian,20)
RandomBlock(0,22,2,minecraft:obsidian,80,minecraft:crying_obsidian,20)
RandomBlock(0,23,2,minecraft:obsidian,80,minecraft:crying_obsidian,20)
RandomBlock(0,0,3,minecraft:obsidian,80,minecraft:crying_obsidian,20)
RandomBlock(0,1,3,minecraft:obsidian,80,minecraft:crying_obsidian,20)
RandomBlock(0,2,3,minecraft:obsidian,80,minecraft:crying_obsidian,20)
RandomBlock(0,3,3,minecraft:obsidian,80,minecraft:crying_obsidian,20)
RandomBlock(0,4,3,minecraft:obsidian,80,minecraft:crying_obsidian,20)
RandomBlock(0,5,3,minecraft:obsidian,80,minecraft:crying_obsidian,20)
RandomBlock(0,6,3,minecraft:obsidian,80,minecraft:crying_obsidian,20)
RandomBlock(0,7,3,minecraft:obsidian,80,minecraft:crying_obsidian,20)
RandomBlock(0,8,3,minecraft:obsidian,80,minecraft:crying_obsidian,20)
RandomBlock(0,9,3,minecraft:obsidian,80,minecraft:crying_obsidian,20)
RandomBlock(0,10,3,minecraft:obsidian,80,minecraft:crying_obsidian,20)
RandomBlock(0,11,3,minecraft:obsidian,80,minecraft:crying_obsidian,20)
RandomBlock(0,12,3,minecraft:obsidian,80,minecraft:crying_obsidian,20)
RandomBlock(0,13,3,minecraft:obsidian,80,minecraft:crying_obsidian,20)
RandomBlock(0,14,3,minecraft:obsidian,80,minecraft:crying_obsidian,20)
RandomBlock(0,15,3,minecraft:obsidian,80,minecraft:crying_obsidian,20)
RandomBlock(0,16,3,minecraft:obsidian,80,minecraft:crying_obsidian,20)
RandomBlock(0,17,3,minecraft:obsidian,80,minecraft:crying_obsidian,20)
RandomBlock(0,18,3,minecraft:obsidian,80,minecraft:crying_obsidian,20)
RandomBlock(0,19,3,minecraft:obsidian,80,minecraft:crying_obsidian,20)
RandomBlock(0,20,3,minecraft:obsidian,80,minecraft:crying_obsidian,20)
RandomBlock(0,21,3,minecraft:obsidian,80,minecraft:crying_obsidian,20)
RandomBlock(0,22,3,minecraft:obsidian,80,minecraft:crying_obsidian,20)
RandomBlock(0,23,3,minecraft:obsidian,80,minecraft:crying_obsidian,20)
RandomBlock(0,0,4,minecraft:obsidian,80,minecraft:crying_obsidian,20)
RandomBlock(0,1,4,minecraft:obsidian,80,minecraft:crying_obsidian,20)
RandomBlock(0,2,4,minecraft:obsidian,80,minecraft:crying_obsidian,20)
RandomBlock(0,3,4,minecraft:obsidian,80,minecraft:crying_obsidian,20)
RandomBlock(0,4,4,minecraft:obsidian,80,minecraft:crying_obsidian,20)
RandomBlock(0,5,4,minecraft:obsidian,80,minecraft:crying_obsidian,20)
RandomBlock(0,6,4,minecraft:obsidian,80,minecraft:crying_obsidian,20)
RandomBlock(0,7,4,minecraft:obsidian,80,minecraft:crying_obsidian,20)
RandomBlock(0,8,4,minecraft:obsidian,80,minecraft:crying_obsidian,20)
RandomBlock(0,9,4,minecraft:obsidian,80,minecraft:crying_obsidian,20)
RandomBlock(0,10,4,minecraft:obsidian,80,minecraft:crying_obsidian,20)
RandomBlock(0,11,4,minecraft:obsidian,80,minecraft:crying_obsidian,20)
RandomBlock(0,12,4,minecraft:obsidian,80,minecraft:crying_obsidian,20)
RandomBlock(0,13,4,minecraft:obsidian,80,minecraft:crying_obsidian,20)
RandomBlock(0,14,4,minecraft:obsidian,80,minecraft:crying_obsidian,20)
RandomBlock(0,15,4,minecraft:obsidian,80,minecraft:crying_obsidian,20)
RandomBlock(0,16,4,minecraft:obsidian,80,minecraft:crying_obsidian,20)
RandomBlock(0,17,4,minecraft:obsidian,80,minecraft:crying_obsidian,20)
RandomBlock(0,18,4,minecraft:obsidian,80,minecraft:crying_obsidian,20)
RandomBlock(0,19,4,minecraft:obsidian,80,minecraft:crying_obsidian,20)
RandomBlock(0,20,4,minecraft:obsidian,80,minecraft:crying_obsidian,20)
RandomBlock(0,21,4,minecraft:obsidian,80,minecraft:crying_obsidian,20)
RandomBlock(0,22,4,minecraft:obsidian,80,minecraft:crying_obsidian,20)
RandomBlock(0,23,4,minecraft:obsidian,80,minecraft:crying_obsidian,20)
RandomBlock(0,0,5,minecraft:obsidian,80,minecraft:crying_obsidian,20)
RandomBlock(0,1,5,minecraft:obsidian,80,minecraft:crying_obsidian,20)
RandomBlock(0,2,5,minecraft:obsidian,80,minecraft:crying_obsidian,20)
RandomBlock(0,3,5,minecraft:obsidian,80,minecraft:crying_obsidian,20)
RandomBlock(0,4,5,minecraft:obsidian,80,minecraft:crying_obsidian,20)
RandomBlock(0,5,5,minecraft:obsidian,80,minecraft:crying_obsidian,20)
RandomBlock(0,6,5,minecraft:obsidian,80,minecraft:crying_obsidian,20)
RandomBlock(0,7,5,minecraft:obsidian,80,minecraft:crying_obsidian,20)
RandomBlock(0,8,5,minecraft:obsidian,80,minecraft:crying_obsidian,20)
RandomBlock(0,9,5,minecraft:obsidian,80,minecraft:crying_obsidian,20)
RandomBlock(0,10,5,minecraft:obsidian,80,minecraft:crying_obsidian,20)
RandomBlock(0,11,5,minecraft:obsidian,80,minecraft:crying_obsidian,20)
RandomBlock(0,12,5,minecraft:obsidian,80,minecraft:crying_obsidian,20)
RandomBlock(0,13,5,minecraft:obsidian,80,minecraft:crying_obsidian,20)
RandomBlock(0,14,5,minecraft:obsidian,80,minecraft:crying_obsidian,20)
RandomBlock(0,15,5,minecraft:obsidian,80,minecraft:crying_obsidian,20)
RandomBlock(0,16,5,minecraft:obsidian,80,minecraft:crying_obsidian,20)
RandomBlock(0,17,5,minecraft:obsidian,80,minecraft:crying_obsidian,20)
RandomBlock(0,18,5,minecraft:obsidian,80,minecraft:crying_obsidian,20)
RandomBlock(0,19,5,minecraft:obsidian,80,minecraft:crying_obsidian,20)
RandomBlock(0,20,5,minecraft:obsidian,80,minecraft:crying_obsidian,20)
RandomBlock(0,21,5,minecraft:obsidian,80,minecraft:crying_obsidian,20)
RandomBlock(0,22,5,minecraft:obsidian,80,minecraft:crying_obsidian,20)
RandomBlock(0,0,6,minecraft:obsidian,80,minecraft:crying_obsidian,20)
RandomBlock(0,1,6,minecraft:obsidian,80,minecraft:crying_obsidian,20)
RandomBlock(0,2,6,minecraft:obsidian,80,minecraft:crying_obsidian,20)
RandomBlock(0,3,6,minecraft:obsidian,80,minecraft:crying_obsidian,20)
RandomBlock(0,4,6,minecraft:obsidian,80,minecraft:crying_obsidian,20)
RandomBlock(0,5,6,minecraft:obsidian,80,minecraft:crying_obsidian,20)
RandomBlock(0,6,6,minecraft:obsidian,80,minecraft:crying_obsidian,20)
RandomBlock(0,7,6,minecraft:obsidian,80,minecraft:crying_obsidian,20)
RandomBlock(0,8,6,minecraft:obsidian,80,minecraft:crying_obsidian,20)
RandomBlock(0,9,6,minecraft:obsidian,80,minecraft:crying_obsidian,20)
RandomBlock(0,10,6,minecraft:obsidian,80,minecraft:crying_obsidian,20)
RandomBlock(0,11,6,minecraft:obsidian,80,minecraft:crying_obsidian,20)
RandomBlock(0,12,6,minecraft:obsidian,80,minecraft:crying_obsidian,20)
RandomBlock(0,13,6,minecraft:obsidian,80,minecraft:crying_obsidian,20)
RandomBlock(0,14,6,minecraft:obsidian,80,minecraft:crying_obsidian,20)
RandomBlock(0,15,6,minecraft:obsidian,80,minecraft:crying_obsidian,20)
RandomBlock(0,16,6,minecraft:obsidian,80,minecraft:crying_obsidian,20)
RandomBlock(0,17,6,minecraft:obsidian,80,minecraft:crying_obsidian,20)
RandomBlock(0,18,6,minecraft:obsidian,80,minecraft:crying_obsidian,20)
RandomBlock(0,19,6,minecraft:obsidian,80,minecraft:crying_obsidian,20)
RandomBlock(0,20,6,minecraft:obsidian,80,minecraft:crying_obsidian,20)
RandomBlock(0,0,7,minecraft:obsidian,80,minecraft:crying_obsidian,20)
RandomBlock(0,1,7,minecraft:obsidian,80,minecraft:crying_obsidian,20)
RandomBlock(0,2,7,minecraft:obsidian,80,minecraft:crying_obsidian,20)
RandomBlock(0,3,7,minecraft:obsidian,80,minecraft:crying_obsidian,20)
RandomBlock(0,4,7,minecraft:obsidian,80,minecraft:crying_obsidian,20)
RandomBlock(0,5,7,minecraft:obsidian,80,minecraft:crying_obsidian,20)
RandomBlock(0,6,7,minecraft:obsidian,80,minecraft:crying_obsidian,20)
RandomBlock(0,7,7,minecraft:obsidian,80,minecraft:crying_obsidian,20)
RandomBlock(0,8,7,minecraft:obsidian,80,minecraft:crying_obsidian,20)
RandomBlock(0,9,7,minecraft:obsidian,80,minecraft:crying_obsidian,20)
RandomBlock(0,10,7,minecraft:obsidian,80,minecraft:crying_obsidian,20)
RandomBlock(0,11,7,minecraft:obsidian,80,minecraft:crying_obsidian,20)
RandomBlock(0,12,7,minecraft:obsidian,80,minecraft:crying_obsidian,20)
RandomBlock(0,13,7,minecraft:obsidian,80,minecraft:crying_obsidian,20)
RandomBlock(0,14,7,minecraft:obsidian,80,minecraft:crying_obsidian,20)
RandomBlock(0,15,7,minecraft:obsidian,80,minecraft:crying_obsidian,20)
RandomBlock(0,16,7,minecraft:obsidian,80,minecraft:crying_obsidian,20)
RandomBlock(0,17,7,minecraft:obsidian,80,minecraft:crying_obsidian,20)
RandomBlock(0,18,7,minecraft:obsidian,80,minecraft:crying_obsidian,20)
RandomBlock(0,19,7,minecraft:obsidian,80,minecraft:crying_obsidian,20)
RandomBlock(0,0,8,minecraft:obsidian,80,minecraft:crying_obsidian,20)
RandomBlock(0,1,8,minecraft:obsidian,80,minecraft:crying_obsidian,20)
RandomBlock(0,2,8,minecraft:obsidian,80,minecraft:crying_obsidian,20)
RandomBlock(0,3,8,minecraft:obsidian,80,minecraft:crying_obsidian,20)
RandomBlock(0,4,8,minecraft:obsidian,80,minecraft:crying_obsidian,20)
RandomBlock(0,5,8,minecraft:obsidian,80,minecraft:crying_obsidian,20)
RandomBlock(0,6,8,minecraft:obsidian,80,minecraft:crying_obsidian,20)
RandomBlock(0,7,8,minecraft:obsidian,80,minecraft:crying_obsidian,20)
RandomBlock(0,8,8,minecraft:obsidian,80,minecraft:crying_obsidian,20)
RandomBlock(0,9,8,minecraft:obsidian,80,minecraft:crying_obsidian,20)
RandomBlock(0,10,8,minecraft:obsidian,80,minecraft:crying_obsidian,20)
RandomBlock(0,11,8,minecraft:obsidian,80,minecraft:crying_obsidian,20)
RandomBlock(0,12,8,minecraft:obsidian,80,minecraft:crying_obsidian,20)
RandomBlock(0,13,8,minecraft:obsidian,80,minecraft:crying_obsidian,20)
RandomBlock(0,14,8,minecraft:obsidian,80,minecraft:crying_obsidian,20)
RandomBlock(0,15,8,minecraft:obsidian,80,minecraft:crying_obsidian,20)
RandomBlock(0,16,8,minecraft:obsidian,80,minecraft:crying_obsidian,20)
RandomBlock(0,17,8,minecraft:obsidian,80,minecraft:crying_obsidian,20)
RandomBlock(1,0,-7,minecraft:obsidian,80,minecraft:crying_obsidian,20)
RandomBlock(1,0,-6,minecraft:obsidian,80,minecraft:crying_obsidian,20)
RandomBlock(1,1,-6,minecraft:obsidian,80,minecraft:crying_obsidian,20)
RandomBlock(1,2,-6,minecraft:obsidian,80,minecraft:crying_obsidian,20)
RandomBlock(1,3,-6,minecraft:obsidian,80,minecraft:crying_obsidian,20)
RandomBlock(1,4,-6,minecraft:obsidian,80,minecraft:crying_obsidian,20)
RandomBlock(1,5,-6,minecraft:obsidian,80,minecraft:crying_obsidian,20)
RandomBlock(1,0,-5,minecraft:obsidian,80,minecraft:crying_obsidian,20)
RandomBlock(1,1,-5,minecraft:obsidian,80,minecraft:crying_obsidian,20)
RandomBlock(1,2,-5,minecraft:obsidian,80,minecraft:crying_obsidian,20)
RandomBlock(1,3,-5,minecraft:obsidian,80,minecraft:crying_obsidian,20)
RandomBlock(1,4,-5,minecraft:obsidian,80,minecraft:crying_obsidian,20)
RandomBlock(1,5,-5,minecraft:obsidian,80,minecraft:crying_obsidian,20)
RandomBlock(1,6,-5,minecraft:obsidian,80,minecraft:crying_obsidian,20)
RandomBlock(1,7,-5,minecraft:obsidian,80,minecraft:crying_obsidian,20)
RandomBlock(1,8,-5,minecraft:obsidian,80,minecraft:crying_obsidian,20)
RandomBlock(1,9,-5,minecraft:obsidian,80,minecraft:crying_obsidian,20)
RandomBlock(1,10,-5,minecraft:obsidian,80,minecraft:crying_obsidian,20)
RandomBlock(1,11,-5,minecraft:obsidian,80,minecraft:crying_obsidian,20)
RandomBlock(1,0,-4,minecraft:obsidian,80,minecraft:crying_obsidian,20)
RandomBlock(1,1,-4,minecraft:obsidian,80,minecraft:crying_obsidian,20)
RandomBlock(1,2,-4,minecraft:obsidian,80,minecraft:crying_obsidian,20)
RandomBlock(1,3,-4,minecraft:obsidian,80,minecraft:crying_obsidian,20)
RandomBlock(1,4,-4,minecraft:obsidian,80,minecraft:crying_obsidian,20)
RandomBlock(1,5,-4,minecraft:obsidian,80,minecraft:crying_obsidian,20)
RandomBlock(1,6,-4,minecraft:obsidian,80,minecraft:crying_obsidian,20)
RandomBlock(1,7,-4,minecraft:obsidian,80,minecraft:crying_obsidian,20)
RandomBlock(1,8,-4,minecraft:obsidian,80,minecraft:crying_obsidian,20)
RandomBlock(1,9,-4,minecraft:obsidian,80,minecraft:crying_obsidian,20)
RandomBlock(1,10,-4,minecraft:obsidian,80,minecraft:crying_obsidian,20)
RandomBlock(1,11,-4,minecraft:obsidian,80,minecraft:crying_obsidian,20)
RandomBlock(1,12,-4,minecraft:obsidian,80,minecraft:crying_obsidian,20)
RandomBlock(1,13,-4,minecraft:obsidian,80,minecraft:crying_obsidian,20)
RandomBlock(1,14,-4,minecraft:obsidian,80,minecraft:crying_obsidian,20)
RandomBlock(1,15,-4,minecraft:obsidian,80,minecraft:crying_obsidian,20)
RandomBlock(1,16,-4,minecraft:obsidian,80,minecraft:crying_obsidian,20)
RandomBlock(1,17,-4,minecraft:obsidian,80,minecraft:crying_obsidian,20)
RandomBlock(1,18,-4,minecraft:obsidian,80,minecraft:crying_obsidian,20)
RandomBlock(1,0,-3,minecraft:obsidian,80,minecraft:crying_obsidian,20)
RandomBlock(1,1,-3,minecraft:obsidian,80,minecraft:crying_obsidian,20)
RandomBlock(1,2,-3,minecraft:obsidian,80,minecraft:crying_obsidian,20)
RandomBlock(1,3,-3,minecraft:obsidian,80,minecraft:crying_obsidian,20)
RandomBlock(1,4,-3,minecraft:obsidian,80,minecraft:crying_obsidian,20)
RandomBlock(1,5,-3,minecraft:obsidian,80,minecraft:crying_obsidian,20)
RandomBlock(1,6,-3,minecraft:obsidian,80,minecraft:crying_obsidian,20)
RandomBlock(1,7,-3,minecraft:obsidian,80,minecraft:crying_obsidian,20)
RandomBlock(1,8,-3,minecraft:obsidian,80,minecraft:crying_obsidian,20)
RandomBlock(1,9,-3,minecraft:obsidian,80,minecraft:crying_obsidian,20)
RandomBlock(1,10,-3,minecraft:obsidian,80,minecraft:crying_obsidian,20)
RandomBlock(1,11,-3,minecraft:obsidian,80,minecraft:crying_obsidian,20)
RandomBlock(1,12,-3,minecraft:obsidian,80,minecraft:crying_obsidian,20)
RandomBlock(1,13,-3,minecraft:obsidian,80,minecraft:crying_obsidian,20)
RandomBlock(1,14,-3,minecraft:obsidian,80,minecraft:crying_obsidian,20)
RandomBlock(1,15,-3,minecraft:obsidian,80,minecraft:crying_obsidian,20)
RandomBlock(1,16,-3,minecraft:obsidian,80,minecraft:crying_obsidian,20)
RandomBlock(1,17,-3,minecraft:obsidian,80,minecraft:crying_obsidian,20)
RandomBlock(1,18,-3,minecraft:obsidian,80,minecraft:crying_obsidian,20)
RandomBlock(1,19,-3,minecraft:obsidian,80,minecraft:crying_obsidian,20)
RandomBlock(1,20,-3,minecraft:obsidian,80,minecraft:crying_obsidian,20)
RandomBlock(1,21,-3,minecraft:obsidian,80,minecraft:crying_obsidian,20)
RandomBlock(1,22,-3,minecraft:obsidian,80,minecraft:crying_obsidian,20)
RandomBlock(1,23,-3,minecraft:obsidian,80,minecraft:crying_obsidian,20)
RandomBlock(1,24,-3,minecraft:obsidian,80,minecraft:crying_obsidian,20)
RandomBlock(1,25,-3,minecraft:obsidian,80,minecraft:crying_obsidian,20)
RandomBlock(1,0,-2,minecraft:obsidian,80,minecraft:crying_obsidian,20)
RandomBlock(1,1,-2,minecraft:obsidian,80,minecraft:crying_obsidian,20)
RandomBlock(1,2,-2,minecraft:obsidian,80,minecraft:crying_obsidian,20)
RandomBlock(1,3,-2,minecraft:obsidian,80,minecraft:crying_obsidian,20)
RandomBlock(1,4,-2,minecraft:obsidian,80,minecraft:crying_obsidian,20)
RandomBlock(1,5,-2,minecraft:obsidian,80,minecraft:crying_obsidian,20)
RandomBlock(1,6,-2,minecraft:obsidian,80,minecraft:crying_obsidian,20)
RandomBlock(1,7,-2,minecraft:obsidian,80,minecraft:crying_obsidian,20)
RandomBlock(1,8,-2,minecraft:obsidian,80,minecraft:crying_obsidian,20)
RandomBlock(1,9,-2,minecraft:obsidian,80,minecraft:crying_obsidian,20)
RandomBlock(1,10,-2,minecraft:obsidian,80,minecraft:crying_obsidian,20)
RandomBlock(1,11,-2,minecraft:obsidian,80,minecraft:crying_obsidian,20)
RandomBlock(1,12,-2,minecraft:obsidian,80,minecraft:crying_obsidian,20)
RandomBlock(1,13,-2,minecraft:obsidian,80,minecraft:crying_obsidian,20)
RandomBlock(1,14,-2,minecraft:obsidian,80,minecraft:crying_obsidian,20)
RandomBlock(1,15,-2,minecraft:obsidian,80,minecraft:crying_obsidian,20)
RandomBlock(1,16,-2,minecraft:obsidian,80,minecraft:crying_obsidian,20)
RandomBlock(1,17,-2,minecraft:obsidian,80,minecraft:crying_obsidian,20)
RandomBlock(1,18,-2,minecraft:obsidian,80,minecraft:crying_obsidian,20)
RandomBlock(1,19,-2,minecraft:obsidian,80,minecraft:crying_obsidian,20)
RandomBlock(1,20,-2,minecraft:obsidian,80,minecraft:crying_obsidian,20)
RandomBlock(1,21,-2,minecraft:obsidian,80,minecraft:crying_obsidian,20)
RandomBlock(1,22,-2,minecraft:obsidian,80,minecraft:crying_obsidian,20)
RandomBlock(1,23,-2,minecraft:obsidian,80,minecraft:crying_obsidian,20)
RandomBlock(1,24,-2,minecraft:obsidian,80,minecraft:crying_obsidian,20)
RandomBlock(1,25,-2,minecraft:obsidian,80,minecraft:crying_obsidian,20)
RandomBlock(1,26,-2,minecraft:obsidian,80,minecraft:crying_obsidian,20)
RandomBlock(1,0,-1,minecraft:obsidian,80,minecraft:crying_obsidian,20)
RandomBlock(1,1,-1,minecraft:obsidian,80,minecraft:crying_obsidian,20)
RandomBlock(1,2,-1,minecraft:obsidian,80,minecraft:crying_obsidian,20)
RandomBlock(1,3,-1,minecraft:obsidian,80,minecraft:crying_obsidian,20)
RandomBlock(1,4,-1,minecraft:obsidian,80,minecraft:crying_obsidian,20)
RandomBlock(1,5,-1,minecraft:obsidian,80,minecraft:crying_obsidian,20)
RandomBlock(1,6,-1,minecraft:obsidian,80,minecraft:crying_obsidian,20)
RandomBlock(1,7,-1,minecraft:obsidian,80,minecraft:crying_obsidian,20)
RandomBlock(1,8,-1,minecraft:obsidian,80,minecraft:crying_obsidian,20)
RandomBlock(1,9,-1,minecraft:obsidian,80,minecraft:crying_obsidian,20)
RandomBlock(1,10,-1,minecraft:obsidian,80,minecraft:crying_obsidian,20)
RandomBlock(1,11,-1,minecraft:obsidian,80,minecraft:crying_obsidian,20)
RandomBlock(1,12,-1,minecraft:obsidian,80,minecraft:crying_obsidian,20)
RandomBlock(1,13,-1,minecraft:obsidian,80,minecraft:crying_obsidian,20)
RandomBlock(1,14,-1,minecraft:obsidian,80,minecraft:crying_obsidian,20)
RandomBlock(1,15,-1,minecraft:obsidian,80,minecraft:crying_obsidian,20)
RandomBlock(1,16,-1,minecraft:obsidian,80,minecraft:crying_obsidian,20)
RandomBlock(1,17,-1,minecraft:obsidian,80,minecraft:crying_obsidian,20)
RandomBlock(1,18,-1,minecraft:obsidian,80,minecraft:crying_obsidian,20)
RandomBlock(1,19,-1,minecraft:obsidian,80,minecraft:crying_obsidian,20)
RandomBlock(1,20,-1,minecraft:obsidian,80,minecraft:crying_obsidian,20)
RandomBlock(1,21,-1,minecraft:obsidian,80,minecraft:crying_obsidian,20)
RandomBlock(1,22,-1,minecraft:obsidian,80,minecraft:crying_obsidian,20)
RandomBlock(1,23,-1,minecraft:obsidian,80,minecraft:crying_obsidian,20)
RandomBlock(1,24,-1,minecraft:obsidian,80,minecraft:crying_obsidian,20)
RandomBlock(1,25,-1,minecraft:obsidian,80,minecraft:crying_obsidian,20)
RandomBlock(1,0,0,minecraft:obsidian,80,minecraft:crying_obsidian,20)
RandomBlock(1,1,0,minecraft:obsidian,80,minecraft:crying_obsidian,20)
RandomBlock(1,2,0,minecraft:obsidian,80,minecraft:crying_obsidian,20)
RandomBlock(1,3,0,minecraft:obsidian,80,minecraft:crying_obsidian,20)
RandomBlock(1,4,0,minecraft:obsidian,80,minecraft:crying_obsidian,20)
RandomBlock(1,5,0,minecraft:obsidian,80,minecraft:crying_obsidian,20)
RandomBlock(1,6,0,minecraft:obsidian,80,minecraft:crying_obsidian,20)
RandomBlock(1,7,0,minecraft:obsidian,80,minecraft:crying_obsidian,20)
RandomBlock(1,8,0,minecraft:obsidian,80,minecraft:crying_obsidian,20)
RandomBlock(1,9,0,minecraft:obsidian,80,minecraft:crying_obsidian,20)
RandomBlock(1,10,0,minecraft:obsidian,80,minecraft:crying_obsidian,20)
RandomBlock(1,11,0,minecraft:obsidian,80,minecraft:crying_obsidian,20)
RandomBlock(1,12,0,minecraft:obsidian,80,minecraft:crying_obsidian,20)
RandomBlock(1,13,0,minecraft:obsidian,80,minecraft:crying_obsidian,20)
RandomBlock(1,14,0,minecraft:obsidian,80,minecraft:crying_obsidian,20)
RandomBlock(1,15,0,minecraft:obsidian,80,minecraft:crying_obsidian,20)
RandomBlock(1,16,0,minecraft:obsidian,80,minecraft:crying_obsidian,20)
RandomBlock(1,17,0,minecraft:obsidian,80,minecraft:crying_obsidian,20)
RandomBlock(1,18,0,minecraft:obsidian,80,minecraft:crying_obsidian,20)
RandomBlock(1,19,0,minecraft:obsidian,80,minecraft:crying_obsidian,20)
RandomBlock(1,20,0,minecraft:obsidian,80,minecraft:crying_obsidian,20)
RandomBlock(1,21,0,minecraft:obsidian,80,minecraft:crying_obsidian,20)
RandomBlock(1,22,0,minecraft:obsidian,80,minecraft:crying_obsidian,20)
RandomBlock(1,23,0,minecraft:obsidian,80,minecraft:crying_obsidian,20)
RandomBlock(1,24,0,minecraft:obsidian,80,minecraft:crying_obsidian,20)
RandomBlock(1,25,0,minecraft:obsidian,80,minecraft:crying_obsidian,20)
RandomBlock(1,0,1,minecraft:obsidian,80,minecraft:crying_obsidian,20)
RandomBlock(1,1,1,minecraft:obsidian,80,minecraft:crying_obsidian,20)
RandomBlock(1,2,1,minecraft:obsidian,80,minecraft:crying_obsidian,20)
RandomBlock(1,3,1,minecraft:obsidian,80,minecraft:crying_obsidian,20)
RandomBlock(1,4,1,minecraft:obsidian,80,minecraft:crying_obsidian,20)
RandomBlock(1,5,1,minecraft:obsidian,80,minecraft:crying_obsidian,20)
RandomBlock(1,6,1,minecraft:obsidian,80,minecraft:crying_obsidian,20)
RandomBlock(1,7,1,minecraft:obsidian,80,minecraft:crying_obsidian,20)
RandomBlock(1,8,1,minecraft:obsidian,80,minecraft:crying_obsidian,20)
RandomBlock(1,9,1,minecraft:obsidian,80,minecraft:crying_obsidian,20)
RandomBlock(1,10,1,minecraft:obsidian,80,minecraft:crying_obsidian,20)
RandomBlock(1,11,1,minecraft:obsidian,80,minecraft:crying_obsidian,20)
RandomBlock(1,12,1,minecraft:obsidian,80,minecraft:crying_obsidian,20)
RandomBlock(1,13,1,minecraft:obsidian,80,minecraft:crying_obsidian,20)
RandomBlock(1,14,1,minecraft:obsidian,80,minecraft:crying_obsidian,20)
RandomBlock(1,15,1,minecraft:obsidian,80,minecraft:crying_obsidian,20)
RandomBlock(1,16,1,minecraft:obsidian,80,minecraft:crying_obsidian,20)
RandomBlock(1,17,1,minecraft:obsidian,80,minecraft:crying_obsidian,20)
RandomBlock(1,18,1,minecraft:obsidian,80,minecraft:crying_obsidian,20)
RandomBlock(1,19,1,minecraft:obsidian,80,minecraft:crying_obsidian,20)
RandomBlock(1,20,1,minecraft:obsidian,80,minecraft:crying_obsidian,20)
RandomBlock(1,21,1,minecraft:obsidian,80,minecraft:crying_obsidian,20)
RandomBlock(1,22,1,minecraft:obsidian,80,minecraft:crying_obsidian,20)
RandomBlock(1,23,1,minecraft:obsidian,80,minecraft:crying_obsidian,20)
RandomBlock(1,24,1,minecraft:obsidian,80,minecraft:crying_obsidian,20)
RandomBlock(1,25,1,minecraft:obsidian,80,minecraft:crying_obsidian,20)
RandomBlock(1,26,1,minecraft:obsidian,80,minecraft:crying_obsidian,20)
RandomBlock(1,0,2,minecraft:obsidian,80,minecraft:crying_obsidian,20)
RandomBlock(1,1,2,minecraft:obsidian,80,minecraft:crying_obsidian,20)
RandomBlock(1,2,2,minecraft:obsidian,80,minecraft:crying_obsidian,20)
RandomBlock(1,3,2,minecraft:obsidian,80,minecraft:crying_obsidian,20)
RandomBlock(1,4,2,minecraft:obsidian,80,minecraft:crying_obsidian,20)
RandomBlock(1,5,2,minecraft:obsidian,80,minecraft:crying_obsidian,20)
RandomBlock(1,6,2,minecraft:obsidian,80,minecraft:crying_obsidian,20)
RandomBlock(1,7,2,minecraft:obsidian,80,minecraft:crying_obsidian,20)
RandomBlock(1,8,2,minecraft:obsidian,80,minecraft:crying_obsidian,20)
RandomBlock(1,9,2,minecraft:obsidian,80,minecraft:crying_obsidian,20)
RandomBlock(1,10,2,minecraft:obsidian,80,minecraft:crying_obsidian,20)
RandomBlock(1,11,2,minecraft:obsidian,80,minecraft:crying_obsidian,20)
RandomBlock(1,12,2,minecraft:obsidian,80,minecraft:crying_obsidian,20)
RandomBlock(1,13,2,minecraft:obsidian,80,minecraft:crying_obsidian,20)
RandomBlock(1,14,2,minecraft:obsidian,80,minecraft:crying_obsidian,20)
RandomBlock(1,15,2,minecraft:obsidian,80,minecraft:crying_obsidian,20)
RandomBlock(1,16,2,minecraft:obsidian,80,minecraft:crying_obsidian,20)
RandomBlock(1,17,2,minecraft:obsidian,80,minecraft:crying_obsidian,20)
RandomBlock(1,18,2,minecraft:obsidian,80,minecraft:crying_obsidian,20)
RandomBlock(1,19,2,minecraft:obsidian,80,minecraft:crying_obsidian,20)
RandomBlock(1,20,2,minecraft:obsidian,80,minecraft:crying_obsidian,20)
RandomBlock(1,21,2,minecraft:obsidian,80,minecraft:crying_obsidian,20)
RandomBlock(1,22,2,minecraft:obsidian,80,minecraft:crying_obsidian,20)
RandomBlock(1,23,2,minecraft:obsidian,80,minecraft:crying_obsidian,20)
RandomBlock(1,24,2,minecraft:obsidian,80,minecraft:crying_obsidian,20)
RandomBlock(1,25,2,minecraft:obsidian,80,minecraft:crying_obsidian,20)
RandomBlock(1,26,2,minecraft:obsidian,80,minecraft:crying_obsidian,20)
RandomBlock(1,0,3,minecraft:obsidian,80,minecraft:crying_obsidian,20)
RandomBlock(1,1,3,minecraft:obsidian,80,minecraft:crying_obsidian,20)
RandomBlock(1,2,3,minecraft:obsidian,80,minecraft:crying_obsidian,20)
RandomBlock(1,3,3,minecraft:obsidian,80,minecraft:crying_obsidian,20)
RandomBlock(1,4,3,minecraft:obsidian,80,minecraft:crying_obsidian,20)
RandomBlock(1,5,3,minecraft:obsidian,80,minecraft:crying_obsidian,20)
RandomBlock(1,6,3,minecraft:obsidian,80,minecraft:crying_obsidian,20)
RandomBlock(1,7,3,minecraft:obsidian,80,minecraft:crying_obsidian,20)
RandomBlock(1,8,3,minecraft:obsidian,80,minecraft:crying_obsidian,20)
RandomBlock(1,9,3,minecraft:obsidian,80,minecraft:crying_obsidian,20)
RandomBlock(1,10,3,minecraft:obsidian,80,minecraft:crying_obsidian,20)
RandomBlock(1,11,3,minecraft:obsidian,80,minecraft:crying_obsidian,20)
RandomBlock(1,12,3,minecraft:obsidian,80,minecraft:crying_obsidian,20)
RandomBlock(1,13,3,minecraft:obsidian,80,minecraft:crying_obsidian,20)
RandomBlock(1,14,3,minecraft:obsidian,80,minecraft:crying_obsidian,20)
RandomBlock(1,15,3,minecraft:obsidian,80,minecraft:crying_obsidian,20)
RandomBlock(1,16,3,minecraft:obsidian,80,minecraft:crying_obsidian,20)
RandomBlock(1,17,3,minecraft:obsidian,80,minecraft:crying_obsidian,20)
RandomBlock(1,18,3,minecraft:obsidian,80,minecraft:crying_obsidian,20)
RandomBlock(1,19,3,minecraft:obsidian,80,minecraft:crying_obsidian,20)
RandomBlock(1,20,3,minecraft:obsidian,80,minecraft:crying_obsidian,20)
RandomBlock(1,21,3,minecraft:obsidian,80,minecraft:crying_obsidian,20)
RandomBlock(1,22,3,minecraft:obsidian,80,minecraft:crying_obsidian,20)
RandomBlock(1,23,3,minecraft:obsidian,80,minecraft:crying_obsidian,20)
RandomBlock(1,24,3,minecraft:obsidian,80,minecraft:crying_obsidian,20)
RandomBlock(1,25,3,minecraft:obsidian,80,minecraft:crying_obsidian,20)
RandomBlock(1,26,3,minecraft:obsidian,80,minecraft:crying_obsidian,20)
RandomBlock(1,0,4,minecraft:obsidian,80,minecraft:crying_obsidian,20)
RandomBlock(1,1,4,minecraft:obsidian,80,minecraft:crying_obsidian,20)
RandomBlock(1,2,4,minecraft:obsidian,80,minecraft:crying_obsidian,20)
RandomBlock(1,3,4,minecraft:obsidian,80,minecraft:crying_obsidian,20)
RandomBlock(1,4,4,minecraft:obsidian,80,minecraft:crying_obsidian,20)
RandomBlock(1,5,4,minecraft:obsidian,80,minecraft:crying_obsidian,20)
RandomBlock(1,6,4,minecraft:obsidian,80,minecraft:crying_obsidian,20)
RandomBlock(1,7,4,minecraft:obsidian,80,minecraft:crying_obsidian,20)
RandomBlock(1,8,4,minecraft:obsidian,80,minecraft:crying_obsidian,20)
RandomBlock(1,9,4,minecraft:obsidian,80,minecraft:crying_obsidian,20)
RandomBlock(1,10,4,minecraft:obsidian,80,minecraft:crying_obsidian,20)
RandomBlock(1,11,4,minecraft:obsidian,80,minecraft:crying_obsidian,20)
RandomBlock(1,12,4,minecraft:obsidian,80,minecraft:crying_obsidian,20)
RandomBlock(1,13,4,minecraft:obsidian,80,minecraft:crying_obsidian,20)
RandomBlock(1,14,4,minecraft:obsidian,80,minecraft:crying_obsidian,20)
RandomBlock(1,15,4,minecraft:obsidian,80,minecraft:crying_obsidian,20)
RandomBlock(1,16,4,minecraft:obsidian,80,minecraft:crying_obsidian,20)
RandomBlock(1,17,4,minecraft:obsidian,80,minecraft:crying_obsidian,20)
RandomBlock(1,18,4,minecraft:obsidian,80,minecraft:crying_obsidian,20)
RandomBlock(1,19,4,minecraft:obsidian,80,minecraft:crying_obsidian,20)
RandomBlock(1,20,4,minecraft:obsidian,80,minecraft:crying_obsidian,20)
RandomBlock(1,21,4,minecraft:obsidian,80,minecraft:crying_obsidian,20)
RandomBlock(1,22,4,minecraft:obsidian,80,minecraft:crying_obsidian,20)
RandomBlock(1,23,4,minecraft:obsidian,80,minecraft:crying_obsidian,20)
RandomBlock(1,24,4,minecraft:obsidian,80,minecraft:crying_obsidian,20)
RandomBlock(1,25,4,minecraft:obsidian,80,minecraft:crying_obsidian,20)
RandomBlock(1,0,5,minecraft:obsidian,80,minecraft:crying_obsidian,20)
RandomBlock(1,1,5,minecraft:obsidian,80,minecraft:crying_obsidian,20)
RandomBlock(1,2,5,minecraft:obsidian,80,minecraft:crying_obsidian,20)
RandomBlock(1,3,5,minecraft:obsidian,80,minecraft:crying_obsidian,20)
RandomBlock(1,4,5,minecraft:obsidian,80,minecraft:crying_obsidian,20)
RandomBlock(1,5,5,minecraft:obsidian,80,minecraft:crying_obsidian,20)
RandomBlock(1,6,5,minecraft:obsidian,80,minecraft:crying_obsidian,20)
RandomBlock(1,7,5,minecraft:obsidian,80,minecraft:crying_obsidian,20)
RandomBlock(1,8,5,minecraft:obsidian,80,minecraft:crying_obsidian,20)
RandomBlock(1,9,5,minecraft:obsidian,80,minecraft:crying_obsidian,20)
RandomBlock(1,10,5,minecraft:obsidian,80,minecraft:crying_obsidian,20)
RandomBlock(1,11,5,minecraft:obsidian,80,minecraft:crying_obsidian,20)
RandomBlock(1,12,5,minecraft:obsidian,80,minecraft:crying_obsidian,20)
RandomBlock(1,13,5,minecraft:obsidian,80,minecraft:crying_obsidian,20)
RandomBlock(1,14,5,minecraft:obsidian,80,minecraft:crying_obsidian,20)
RandomBlock(1,15,5,minecraft:obsidian,80,minecraft:crying_obsidian,20)
RandomBlock(1,16,5,minecraft:obsidian,80,minecraft:crying_obsidian,20)
RandomBlock(1,17,5,minecraft:obsidian,80,minecraft:crying_obsidian,20)
RandomBlock(1,18,5,minecraft:obsidian,80,minecraft:crying_obsidian,20)
RandomBlock(1,19,5,minecraft:obsidian,80,minecraft:crying_obsidian,20)
RandomBlock(1,20,5,minecraft:obsidian,80,minecraft:crying_obsidian,20)
RandomBlock(1,21,5,minecraft:obsidian,80,minecraft:crying_obsidian,20)
RandomBlock(1,22,5,minecraft:obsidian,80,minecraft:crying_obsidian,20)
RandomBlock(1,23,5,minecraft:obsidian,80,minecraft:crying_obsidian,20)
RandomBlock(1,24,5,minecraft:obsidian,80,minecraft:crying_obsidian,20)
RandomBlock(1,0,6,minecraft:obsidian,80,minecraft:crying_obsidian,20)
RandomBlock(1,1,6,minecraft:obsidian,80,minecraft:crying_obsidian,20)
RandomBlock(1,2,6,minecraft:obsidian,80,minecraft:crying_obsidian,20)
RandomBlock(1,3,6,minecraft:obsidian,80,minecraft:crying_obsidian,20)
RandomBlock(1,4,6,minecraft:obsidian,80,minecraft:crying_obsidian,20)
RandomBlock(1,5,6,minecraft:obsidian,80,minecraft:crying_obsidian,20)
RandomBlock(1,6,6,minecraft:obsidian,80,minecraft:crying_obsidian,20)
RandomBlock(1,7,6,minecraft:obsidian,80,minecraft:crying_obsidian,20)
RandomBlock(1,8,6,minecraft:obsidian,80,minecraft:crying_obsidian,20)
RandomBlock(1,9,6,minecraft:obsidian,80,minecraft:crying_obsidian,20)
RandomBlock(1,10,6,minecraft:obsidian,80,minecraft:crying_obsidian,20)
RandomBlock(1,11,6,minecraft:obsidian,80,minecraft:crying_obsidian,20)
RandomBlock(1,12,6,minecraft:obsidian,80,minecraft:crying_obsidian,20)
RandomBlock(1,13,6,minecraft:obsidian,80,minecraft:crying_obsidian,20)
RandomBlock(1,14,6,minecraft:obsidian,80,minecraft:crying_obsidian,20)
RandomBlock(1,15,6,minecraft:obsidian,80,minecraft:crying_obsidian,20)
RandomBlock(1,16,6,minecraft:obsidian,80,minecraft:crying_obsidian,20)
RandomBlock(1,17,6,minecraft:obsidian,80,minecraft:crying_obsidian,20)
RandomBlock(1,18,6,minecraft:obsidian,80,minecraft:crying_obsidian,20)
RandomBlock(1,19,6,minecraft:obsidian,80,minecraft:crying_obsidian,20)
RandomBlock(1,20,6,minecraft:obsidian,80,minecraft:crying_obsidian,20)
RandomBlock(1,21,6,minecraft:obsidian,80,minecraft:crying_obsidian,20)
RandomBlock(1,22,6,minecraft:obsidian,80,minecraft:crying_obsidian,20)
RandomBlock(1,0,7,minecraft:obsidian,80,minecraft:crying_obsidian,20)
RandomBlock(1,1,7,minecraft:obsidian,80,minecraft:crying_obsidian,20)
RandomBlock(1,2,7,minecraft:obsidian,80,minecraft:crying_obsidian,20)
RandomBlock(1,3,7,minecraft:obsidian,80,minecraft:crying_obsidian,20)
RandomBlock(1,4,7,minecraft:obsidian,80,minecraft:crying_obsidian,20)
RandomBlock(1,5,7,minecraft:obsidian,80,minecraft:crying_obsidian,20)
RandomBlock(1,6,7,minecraft:obsidian,80,minecraft:crying_obsidian,20)
RandomBlock(1,7,7,minecraft:obsidian,80,minecraft:crying_obsidian,20)
RandomBlock(1,8,7,minecraft:obsidian,80,minecraft:crying_obsidian,20)
RandomBlock(1,9,7,minecraft:obsidian,80,minecraft:crying_obsidian,20)
RandomBlock(1,10,7,minecraft:obsidian,80,minecraft:crying_obsidian,20)
RandomBlock(1,11,7,minecraft:obsidian,80,minecraft:crying_obsidian,20)
RandomBlock(1,12,7,minecraft:obsidian,80,minecraft:crying_obsidian,20)
RandomBlock(1,13,7,minecraft:obsidian,80,minecraft:crying_obsidian,20)
RandomBlock(1,14,7,minecraft:obsidian,80,minecraft:crying_obsidian,20)
RandomBlock(1,15,7,minecraft:obsidian,80,minecraft:crying_obsidian,20)
RandomBlock(1,16,7,minecraft:obsidian,80,minecraft:crying_obsidian,20)
RandomBlock(1,17,7,minecraft:obsidian,80,minecraft:crying_obsidian,20)
RandomBlock(1,18,7,minecraft:obsidian,80,minecraft:crying_obsidian,20)
RandomBlock(1,19,7,minecraft:obsidian,80,minecraft:crying_obsidian,20)
RandomBlock(1,20,7,minecraft:obsidian,80,minecraft:crying_obsidian,20)
RandomBlock(1,21,7,minecraft:obsidian,80,minecraft:crying_obsidian,20)
RandomBlock(1,0,8,minecraft:obsidian,80,minecraft:crying_obsidian,20)
RandomBlock(1,1,8,minecraft:obsidian,80,minecraft:crying_obsidian,20)
RandomBlock(1,2,8,minecraft:obsidian,80,minecraft:crying_obsidian,20)
RandomBlock(1,3,8,minecraft:obsidian,80,minecraft:crying_obsidian,20)
RandomBlock(1,4,8,minecraft:obsidian,80,minecraft:crying_obsidian,20)
RandomBlock(1,5,8,minecraft:obsidian,80,minecraft:crying_obsidian,20)
RandomBlock(1,6,8,minecraft:obsidian,80,minecraft:crying_obsidian,20)
RandomBlock(1,7,8,minecraft:obsidian,80,minecraft:crying_obsidian,20)
RandomBlock(1,8,8,minecraft:obsidian,80,minecraft:crying_obsidian,20)
RandomBlock(1,9,8,minecraft:obsidian,80,minecraft:crying_obsidian,20)
RandomBlock(1,10,8,minecraft:obsidian,80,minecraft:crying_obsidian,20)
RandomBlock(1,11,8,minecraft:obsidian,80,minecraft:crying_obsidian,20)
RandomBlock(1,12,8,minecraft:obsidian,80,minecraft:crying_obsidian,20)
RandomBlock(1,13,8,minecraft:obsidian,80,minecraft:crying_obsidian,20)
RandomBlock(1,14,8,minecraft:obsidian,80,minecraft:crying_obsidian,20)
RandomBlock(1,15,8,minecraft:obsidian,80,minecraft:crying_obsidian,20)
RandomBlock(1,16,8,minecraft:obsidian,80,minecraft:crying_obsidian,20)
RandomBlock(1,17,8,minecraft:obsidian,80,minecraft:crying_obsidian,20)
RandomBlock(1,18,8,minecraft:obsidian,80,minecraft:crying_obsidian,20)
RandomBlock(1,19,8,minecraft:obsidian,80,minecraft:crying_obsidian,20)
RandomBlock(2,0,-7,minecraft:obsidian,80,minecraft:crying_obsidian,20)
RandomBlock(2,1,-7,minecraft:obsidian,80,minecraft:crying_obsidian,20)
RandomBlock(2,2,-7,minecraft:obsidian,80,minecraft:crying_obsidian,20)
RandomBlock(2,3,-7,minecraft:obsidian,80,minecraft:crying_obsidian,20)
RandomBlock(2,4,-7,minecraft:obsidian,80,minecraft:crying_obsidian,20)
RandomBlock(2,5,-7,minecraft:obsidian,80,minecraft:crying_obsidian,20)
RandomBlock(2,0,-6,minecraft:obsidian,80,minecraft:crying_obsidian,20)
RandomBlock(2,1,-6,minecraft:obsidian,80,minecraft:crying_obsidian,20)
RandomBlock(2,2,-6,minecraft:obsidian,80,minecraft:crying_obsidian,20)
RandomBlock(2,3,-6,minecraft:obsidian,80,minecraft:crying_obsidian,20)
RandomBlock(2,4,-6,minecraft:obsidian,80,minecraft:crying_obsidian,20)
RandomBlock(2,5,-6,minecraft:obsidian,80,minecraft:crying_obsidian,20)
RandomBlock(2,6,-6,minecraft:obsidian,80,minecraft:crying_obsidian,20)
RandomBlock(2,7,-6,minecraft:obsidian,80,minecraft:crying_obsidian,20)
RandomBlock(2,8,-6,minecraft:obsidian,80,minecraft:crying_obsidian,20)
RandomBlock(2,9,-6,minecraft:obsidian,80,minecraft:crying_obsidian,20)
RandomBlock(2,10,-6,minecraft:obsidian,80,minecraft:crying_obsidian,20)
RandomBlock(2,0,-5,minecraft:obsidian,80,minecraft:crying_obsidian,20)
RandomBlock(2,1,-5,minecraft:obsidian,80,minecraft:crying_obsidian,20)
RandomBlock(2,2,-5,minecraft:obsidian,80,minecraft:crying_obsidian,20)
RandomBlock(2,3,-5,minecraft:obsidian,80,minecraft:crying_obsidian,20)
RandomBlock(2,4,-5,minecraft:obsidian,80,minecraft:crying_obsidian,20)
RandomBlock(2,5,-5,minecraft:obsidian,80,minecraft:crying_obsidian,20)
RandomBlock(2,6,-5,minecraft:obsidian,80,minecraft:crying_obsidian,20)
RandomBlock(2,7,-5,minecraft:obsidian,80,minecraft:crying_obsidian,20)
RandomBlock(2,8,-5,minecraft:obsidian,80,minecraft:crying_obsidian,20)
RandomBlock(2,9,-5,minecraft:obsidian,80,minecraft:crying_obsidian,20)
RandomBlock(2,10,-5,minecraft:obsidian,80,minecraft:crying_obsidian,20)
RandomBlock(2,11,-5,minecraft:obsidian,80,minecraft:crying_obsidian,20)
RandomBlock(2,12,-5,minecraft:obsidian,80,minecraft:crying_obsidian,20)
RandomBlock(2,13,-5,minecraft:obsidian,80,minecraft:crying_obsidian,20)
RandomBlock(2,14,-5,minecraft:obsidian,80,minecraft:crying_obsidian,20)
RandomBlock(2,15,-5,minecraft:obsidian,80,minecraft:crying_obsidian,20)
RandomBlock(2,0,-4,minecraft:obsidian,80,minecraft:crying_obsidian,20)
RandomBlock(2,1,-4,minecraft:obsidian,80,minecraft:crying_obsidian,20)
RandomBlock(2,2,-4,minecraft:obsidian,80,minecraft:crying_obsidian,20)
RandomBlock(2,3,-4,minecraft:obsidian,80,minecraft:crying_obsidian,20)
RandomBlock(2,4,-4,minecraft:obsidian,80,minecraft:crying_obsidian,20)
RandomBlock(2,5,-4,minecraft:obsidian,80,minecraft:crying_obsidian,20)
RandomBlock(2,6,-4,minecraft:obsidian,80,minecraft:crying_obsidian,20)
RandomBlock(2,7,-4,minecraft:obsidian,80,minecraft:crying_obsidian,20)
RandomBlock(2,8,-4,minecraft:obsidian,80,minecraft:crying_obsidian,20)
RandomBlock(2,9,-4,minecraft:obsidian,80,minecraft:crying_obsidian,20)
RandomBlock(2,10,-4,minecraft:obsidian,80,minecraft:crying_obsidian,20)
RandomBlock(2,11,-4,minecraft:obsidian,80,minecraft:crying_obsidian,20)
RandomBlock(2,12,-4,minecraft:obsidian,80,minecraft:crying_obsidian,20)
RandomBlock(2,13,-4,minecraft:obsidian,80,minecraft:crying_obsidian,20)
RandomBlock(2,14,-4,minecraft:obsidian,80,minecraft:crying_obsidian,20)
RandomBlock(2,15,-4,minecraft:obsidian,80,minecraft:crying_obsidian,20)
RandomBlock(2,16,-4,minecraft:obsidian,80,minecraft:crying_obsidian,20)
RandomBlock(2,17,-4,minecraft:obsidian,80,minecraft:crying_obsidian,20)
RandomBlock(2,18,-4,minecraft:obsidian,80,minecraft:crying_obsidian,20)
RandomBlock(2,19,-4,minecraft:obsidian,80,minecraft:crying_obsidian,20)
RandomBlock(2,20,-4,minecraft:obsidian,80,minecraft:crying_obsidian,20)
RandomBlock(2,21,-4,minecraft:obsidian,80,minecraft:crying_obsidian,20)
RandomBlock(2,22,-4,minecraft:obsidian,80,minecraft:crying_obsidian,20)
RandomBlock(2,0,-3,minecraft:obsidian,80,minecraft:crying_obsidian,20)
RandomBlock(2,1,-3,minecraft:obsidian,80,minecraft:crying_obsidian,20)
RandomBlock(2,2,-3,minecraft:obsidian,80,minecraft:crying_obsidian,20)
RandomBlock(2,3,-3,minecraft:obsidian,80,minecraft:crying_obsidian,20)
RandomBlock(2,4,-3,minecraft:obsidian,80,minecraft:crying_obsidian,20)
RandomBlock(2,5,-3,minecraft:obsidian,80,minecraft:crying_obsidian,20)
RandomBlock(2,6,-3,minecraft:obsidian,80,minecraft:crying_obsidian,20)
RandomBlock(2,7,-3,minecraft:obsidian,80,minecraft:crying_obsidian,20)
RandomBlock(2,8,-3,minecraft:obsidian,80,minecraft:crying_obsidian,20)
RandomBlock(2,9,-3,minecraft:obsidian,80,minecraft:crying_obsidian,20)
RandomBlock(2,10,-3,minecraft:obsidian,80,minecraft:crying_obsidian,20)
RandomBlock(2,11,-3,minecraft:obsidian,80,minecraft:crying_obsidian,20)
RandomBlock(2,12,-3,minecraft:obsidian,80,minecraft:crying_obsidian,20)
RandomBlock(2,13,-3,minecraft:obsidian,80,minecraft:crying_obsidian,20)
RandomBlock(2,14,-3,minecraft:obsidian,80,minecraft:crying_obsidian,20)
RandomBlock(2,15,-3,minecraft:obsidian,80,minecraft:crying_obsidian,20)
RandomBlock(2,16,-3,minecraft:obsidian,80,minecraft:crying_obsidian,20)
RandomBlock(2,17,-3,minecraft:obsidian,80,minecraft:crying_obsidian,20)
RandomBlock(2,18,-3,minecraft:obsidian,80,minecraft:crying_obsidian,20)
RandomBlock(2,19,-3,minecraft:obsidian,80,minecraft:crying_obsidian,20)
RandomBlock(2,20,-3,minecraft:obsidian,80,minecraft:crying_obsidian,20)
RandomBlock(2,21,-3,minecraft:obsidian,80,minecraft:crying_obsidian,20)
RandomBlock(2,22,-3,minecraft:obsidian,80,minecraft:crying_obsidian,20)
RandomBlock(2,23,-3,minecraft:obsidian,80,minecraft:crying_obsidian,20)
RandomBlock(2,24,-3,minecraft:obsidian,80,minecraft:crying_obsidian,20)
RandomBlock(2,25,-3,minecraft:obsidian,80,minecraft:crying_obsidian,20)
RandomBlock(2,26,-3,minecraft:obsidian,80,minecraft:crying_obsidian,20)
RandomBlock(2,0,-2,minecraft:obsidian,80,minecraft:crying_obsidian,20)
RandomBlock(2,1,-2,minecraft:obsidian,80,minecraft:crying_obsidian,20)
RandomBlock(2,2,-2,minecraft:obsidian,80,minecraft:crying_obsidian,20)
RandomBlock(2,3,-2,minecraft:obsidian,80,minecraft:crying_obsidian,20)
RandomBlock(2,4,-2,minecraft:obsidian,80,minecraft:crying_obsidian,20)
RandomBlock(2,5,-2,minecraft:obsidian,80,minecraft:crying_obsidian,20)
RandomBlock(2,6,-2,minecraft:obsidian,80,minecraft:crying_obsidian,20)
RandomBlock(2,7,-2,minecraft:obsidian,80,minecraft:crying_obsidian,20)
RandomBlock(2,8,-2,minecraft:obsidian,80,minecraft:crying_obsidian,20)
RandomBlock(2,9,-2,minecraft:obsidian,80,minecraft:crying_obsidian,20)
RandomBlock(2,10,-2,minecraft:obsidian,80,minecraft:crying_obsidian,20)
RandomBlock(2,11,-2,minecraft:obsidian,80,minecraft:crying_obsidian,20)
RandomBlock(2,12,-2,minecraft:obsidian,80,minecraft:crying_obsidian,20)
RandomBlock(2,13,-2,minecraft:obsidian,80,minecraft:crying_obsidian,20)
RandomBlock(2,14,-2,minecraft:obsidian,80,minecraft:crying_obsidian,20)
RandomBlock(2,15,-2,minecraft:obsidian,80,minecraft:crying_obsidian,20)
RandomBlock(2,16,-2,minecraft:obsidian,80,minecraft:crying_obsidian,20)
RandomBlock(2,17,-2,minecraft:obsidian,80,minecraft:crying_obsidian,20)
RandomBlock(2,18,-2,minecraft:obsidian,80,minecraft:crying_obsidian,20)
RandomBlock(2,19,-2,minecraft:obsidian,80,minecraft:crying_obsidian,20)
RandomBlock(2,20,-2,minecraft:obsidian,80,minecraft:crying_obsidian,20)
RandomBlock(2,21,-2,minecraft:obsidian,80,minecraft:crying_obsidian,20)
RandomBlock(2,22,-2,minecraft:obsidian,80,minecraft:crying_obsidian,20)
RandomBlock(2,23,-2,minecraft:obsidian,80,minecraft:crying_obsidian,20)
RandomBlock(2,24,-2,minecraft:obsidian,80,minecraft:crying_obsidian,20)
RandomBlock(2,25,-2,minecraft:obsidian,80,minecraft:crying_obsidian,20)
RandomBlock(2,26,-2,minecraft:obsidian,80,minecraft:crying_obsidian,20)
RandomBlock(2,27,-2,minecraft:obsidian,80,minecraft:crying_obsidian,20)
RandomBlock(2,0,-1,minecraft:obsidian,80,minecraft:crying_obsidian,20)
RandomBlock(2,1,-1,minecraft:obsidian,80,minecraft:crying_obsidian,20)
RandomBlock(2,2,-1,minecraft:obsidian,80,minecraft:crying_obsidian,20)
RandomBlock(2,3,-1,minecraft:obsidian,80,minecraft:crying_obsidian,20)
RandomBlock(2,4,-1,minecraft:obsidian,80,minecraft:crying_obsidian,20)
RandomBlock(2,5,-1,minecraft:obsidian,80,minecraft:crying_obsidian,20)
RandomBlock(2,6,-1,minecraft:obsidian,80,minecraft:crying_obsidian,20)
RandomBlock(2,7,-1,minecraft:obsidian,80,minecraft:crying_obsidian,20)
RandomBlock(2,8,-1,minecraft:obsidian,80,minecraft:crying_obsidian,20)
RandomBlock(2,9,-1,minecraft:obsidian,80,minecraft:crying_obsidian,20)
RandomBlock(2,10,-1,minecraft:obsidian,80,minecraft:crying_obsidian,20)
RandomBlock(2,11,-1,minecraft:obsidian,80,minecraft:crying_obsidian,20)
RandomBlock(2,12,-1,minecraft:obsidian,80,minecraft:crying_obsidian,20)
RandomBlock(2,13,-1,minecraft:obsidian,80,minecraft:crying_obsidian,20)
RandomBlock(2,14,-1,minecraft:obsidian,80,minecraft:crying_obsidian,20)
RandomBlock(2,15,-1,minecraft:obsidian,80,minecraft:crying_obsidian,20)
RandomBlock(2,16,-1,minecraft:obsidian,80,minecraft:crying_obsidian,20)
RandomBlock(2,17,-1,minecraft:obsidian,80,minecraft:crying_obsidian,20)
RandomBlock(2,18,-1,minecraft:obsidian,80,minecraft:crying_obsidian,20)
RandomBlock(2,19,-1,minecraft:obsidian,80,minecraft:crying_obsidian,20)
RandomBlock(2,20,-1,minecraft:obsidian,80,minecraft:crying_obsidian,20)
RandomBlock(2,21,-1,minecraft:obsidian,80,minecraft:crying_obsidian,20)
RandomBlock(2,22,-1,minecraft:obsidian,80,minecraft:crying_obsidian,20)
RandomBlock(2,23,-1,minecraft:obsidian,80,minecraft:crying_obsidian,20)
RandomBlock(2,24,-1,minecraft:obsidian,80,minecraft:crying_obsidian,20)
RandomBlock(2,25,-1,minecraft:obsidian,80,minecraft:crying_obsidian,20)
RandomBlock(2,26,-1,minecraft:obsidian,80,minecraft:crying_obsidian,20)
RandomBlock(2,27,-1,minecraft:obsidian,80,minecraft:crying_obsidian,20)
RandomBlock(2,0,0,minecraft:obsidian,80,minecraft:crying_obsidian,20)
RandomBlock(2,1,0,minecraft:obsidian,80,minecraft:crying_obsidian,20)
RandomBlock(2,2,0,minecraft:obsidian,80,minecraft:crying_obsidian,20)
RandomBlock(2,3,0,minecraft:obsidian,80,minecraft:crying_obsidian,20)
RandomBlock(2,4,0,minecraft:obsidian,80,minecraft:crying_obsidian,20)
RandomBlock(2,5,0,minecraft:obsidian,80,minecraft:crying_obsidian,20)
RandomBlock(2,6,0,minecraft:obsidian,80,minecraft:crying_obsidian,20)
RandomBlock(2,7,0,minecraft:obsidian,80,minecraft:crying_obsidian,20)
RandomBlock(2,8,0,minecraft:obsidian,80,minecraft:crying_obsidian,20)
RandomBlock(2,9,0,minecraft:obsidian,80,minecraft:crying_obsidian,20)
RandomBlock(2,10,0,minecraft:obsidian,80,minecraft:crying_obsidian,20)
RandomBlock(2,11,0,minecraft:obsidian,80,minecraft:crying_obsidian,20)
RandomBlock(2,12,0,minecraft:obsidian,80,minecraft:crying_obsidian,20)
RandomBlock(2,13,0,minecraft:obsidian,80,minecraft:crying_obsidian,20)
RandomBlock(2,14,0,minecraft:obsidian,80,minecraft:crying_obsidian,20)
RandomBlock(2,15,0,minecraft:obsidian,80,minecraft:crying_obsidian,20)
RandomBlock(2,16,0,minecraft:obsidian,80,minecraft:crying_obsidian,20)
RandomBlock(2,17,0,minecraft:obsidian,80,minecraft:crying_obsidian,20)
RandomBlock(2,18,0,minecraft:obsidian,80,minecraft:crying_obsidian,20)
RandomBlock(2,19,0,minecraft:obsidian,80,minecraft:crying_obsidian,20)
RandomBlock(2,20,0,minecraft:obsidian,80,minecraft:crying_obsidian,20)
RandomBlock(2,21,0,minecraft:obsidian,80,minecraft:crying_obsidian,20)
RandomBlock(2,22,0,minecraft:obsidian,80,minecraft:crying_obsidian,20)
RandomBlock(2,23,0,minecraft:obsidian,80,minecraft:crying_obsidian,20)
RandomBlock(2,24,0,minecraft:obsidian,80,minecraft:crying_obsidian,20)
RandomBlock(2,25,0,minecraft:obsidian,80,minecraft:crying_obsidian,20)
RandomBlock(2,26,0,minecraft:obsidian,80,minecraft:crying_obsidian,20)
RandomBlock(2,27,0,minecraft:obsidian,80,minecraft:crying_obsidian,20)
RandomBlock(2,28,0,minecraft:obsidian,80,minecraft:crying_obsidian,20)
RandomBlock(2,0,1,minecraft:obsidian,80,minecraft:crying_obsidian,20)
RandomBlock(2,1,1,minecraft:obsidian,80,minecraft:crying_obsidian,20)
RandomBlock(2,2,1,minecraft:obsidian,80,minecraft:crying_obsidian,20)
RandomBlock(2,3,1,minecraft:obsidian,80,minecraft:crying_obsidian,20)
RandomBlock(2,4,1,minecraft:obsidian,80,minecraft:crying_obsidian,20)
RandomBlock(2,5,1,minecraft:obsidian,80,minecraft:crying_obsidian,20)
RandomBlock(2,6,1,minecraft:obsidian,80,minecraft:crying_obsidian,20)
RandomBlock(2,7,1,minecraft:obsidian,80,minecraft:crying_obsidian,20)
RandomBlock(2,8,1,minecraft:obsidian,80,minecraft:crying_obsidian,20)
RandomBlock(2,9,1,minecraft:obsidian,80,minecraft:crying_obsidian,20)
RandomBlock(2,10,1,minecraft:obsidian,80,minecraft:crying_obsidian,20)
RandomBlock(2,11,1,minecraft:obsidian,80,minecraft:crying_obsidian,20)
RandomBlock(2,12,1,minecraft:obsidian,80,minecraft:crying_obsidian,20)
RandomBlock(2,13,1,minecraft:obsidian,80,minecraft:crying_obsidian,20)
RandomBlock(2,14,1,minecraft:obsidian,80,minecraft:crying_obsidian,20)
RandomBlock(2,15,1,minecraft:obsidian,80,minecraft:crying_obsidian,20)
RandomBlock(2,16,1,minecraft:obsidian,80,minecraft:crying_obsidian,20)
RandomBlock(2,17,1,minecraft:obsidian,80,minecraft:crying_obsidian,20)
RandomBlock(2,18,1,minecraft:obsidian,80,minecraft:crying_obsidian,20)
RandomBlock(2,19,1,minecraft:obsidian,80,minecraft:crying_obsidian,20)
RandomBlock(2,20,1,minecraft:obsidian,80,minecraft:crying_obsidian,20)
RandomBlock(2,21,1,minecraft:obsidian,80,minecraft:crying_obsidian,20)
RandomBlock(2,22,1,minecraft:obsidian,80,minecraft:crying_obsidian,20)
RandomBlock(2,23,1,minecraft:obsidian,80,minecraft:crying_obsidian,20)
RandomBlock(2,24,1,minecraft:obsidian,80,minecraft:crying_obsidian,20)
RandomBlock(2,25,1,minecraft:obsidian,80,minecraft:crying_obsidian,20)
RandomBlock(2,26,1,minecraft:obsidian,80,minecraft:crying_obsidian,20)
RandomBlock(2,27,1,minecraft:obsidian,80,minecraft:crying_obsidian,20)
RandomBlock(2,28,1,minecraft:obsidian,80,minecraft:crying_obsidian,20)
RandomBlock(2,29,1,minecraft:obsidian,80,minecraft:crying_obsidian,20)
RandomBlock(2,30,1,minecraft:obsidian,80,minecraft:crying_obsidian,20)
RandomBlock(2,0,2,minecraft:obsidian,80,minecraft:crying_obsidian,20)
RandomBlock(2,1,2,minecraft:obsidian,80,minecraft:crying_obsidian,20)
RandomBlock(2,2,2,minecraft:obsidian,80,minecraft:crying_obsidian,20)
RandomBlock(2,3,2,minecraft:obsidian,80,minecraft:crying_obsidian,20)
RandomBlock(2,4,2,minecraft:obsidian,80,minecraft:crying_obsidian,20)
RandomBlock(2,5,2,minecraft:obsidian,80,minecraft:crying_obsidian,20)
RandomBlock(2,6,2,minecraft:obsidian,80,minecraft:crying_obsidian,20)
RandomBlock(2,7,2,minecraft:obsidian,80,minecraft:crying_obsidian,20)
RandomBlock(2,8,2,minecraft:obsidian,80,minecraft:crying_obsidian,20)
RandomBlock(2,9,2,minecraft:obsidian,80,minecraft:crying_obsidian,20)
RandomBlock(2,10,2,minecraft:obsidian,80,minecraft:crying_obsidian,20)
RandomBlock(2,11,2,minecraft:obsidian,80,minecraft:crying_obsidian,20)
RandomBlock(2,12,2,minecraft:obsidian,80,minecraft:crying_obsidian,20)
RandomBlock(2,13,2,minecraft:obsidian,80,minecraft:crying_obsidian,20)
RandomBlock(2,14,2,minecraft:obsidian,80,minecraft:crying_obsidian,20)
RandomBlock(2,15,2,minecraft:obsidian,80,minecraft:crying_obsidian,20)
RandomBlock(2,16,2,minecraft:obsidian,80,minecraft:crying_obsidian,20)
RandomBlock(2,17,2,minecraft:obsidian,80,minecraft:crying_obsidian,20)
RandomBlock(2,18,2,minecraft:obsidian,80,minecraft:crying_obsidian,20)
RandomBlock(2,19,2,minecraft:obsidian,80,minecraft:crying_obsidian,20)
RandomBlock(2,20,2,minecraft:obsidian,80,minecraft:crying_obsidian,20)
RandomBlock(2,21,2,minecraft:obsidian,80,minecraft:crying_obsidian,20)
RandomBlock(2,22,2,minecraft:obsidian,80,minecraft:crying_obsidian,20)
RandomBlock(2,23,2,minecraft:obsidian,80,minecraft:crying_obsidian,20)
RandomBlock(2,24,2,minecraft:obsidian,80,minecraft:crying_obsidian,20)
RandomBlock(2,25,2,minecraft:obsidian,80,minecraft:crying_obsidian,20)
RandomBlock(2,26,2,minecraft:obsidian,80,minecraft:crying_obsidian,20)
RandomBlock(2,27,2,minecraft:obsidian,80,minecraft:crying_obsidian,20)
RandomBlock(2,28,2,minecraft:obsidian,80,minecraft:crying_obsidian,20)
RandomBlock(2,29,2,minecraft:obsidian,80,minecraft:crying_obsidian,20)
RandomBlock(2,30,2,minecraft:obsidian,80,minecraft:crying_obsidian,20)
RandomBlock(2,31,2,minecraft:obsidian,80,minecraft:crying_obsidian,20)
RandomBlock(2,0,3,minecraft:obsidian,80,minecraft:crying_obsidian,20)
RandomBlock(2,1,3,minecraft:obsidian,80,minecraft:crying_obsidian,20)
RandomBlock(2,2,3,minecraft:obsidian,80,minecraft:crying_obsidian,20)
RandomBlock(2,3,3,minecraft:obsidian,80,minecraft:crying_obsidian,20)
RandomBlock(2,4,3,minecraft:obsidian,80,minecraft:crying_obsidian,20)
RandomBlock(2,5,3,minecraft:obsidian,80,minecraft:crying_obsidian,20)
RandomBlock(2,6,3,minecraft:obsidian,80,minecraft:crying_obsidian,20)
RandomBlock(2,7,3,minecraft:obsidian,80,minecraft:crying_obsidian,20)
RandomBlock(2,8,3,minecraft:obsidian,80,minecraft:crying_obsidian,20)
RandomBlock(2,9,3,minecraft:obsidian,80,minecraft:crying_obsidian,20)
RandomBlock(2,10,3,minecraft:obsidian,80,minecraft:crying_obsidian,20)
RandomBlock(2,11,3,minecraft:obsidian,80,minecraft:crying_obsidian,20)
RandomBlock(2,12,3,minecraft:obsidian,80,minecraft:crying_obsidian,20)
RandomBlock(2,13,3,minecraft:obsidian,80,minecraft:crying_obsidian,20)
RandomBlock(2,14,3,minecraft:obsidian,80,minecraft:crying_obsidian,20)
RandomBlock(2,15,3,minecraft:obsidian,80,minecraft:crying_obsidian,20)
RandomBlock(2,16,3,minecraft:obsidian,80,minecraft:crying_obsidian,20)
RandomBlock(2,17,3,minecraft:obsidian,80,minecraft:crying_obsidian,20)
RandomBlock(2,18,3,minecraft:obsidian,80,minecraft:crying_obsidian,20)
RandomBlock(2,19,3,minecraft:obsidian,80,minecraft:crying_obsidian,20)
RandomBlock(2,20,3,minecraft:obsidian,80,minecraft:crying_obsidian,20)
RandomBlock(2,21,3,minecraft:obsidian,80,minecraft:crying_obsidian,20)
RandomBlock(2,22,3,minecraft:obsidian,80,minecraft:crying_obsidian,20)
RandomBlock(2,23,3,minecraft:obsidian,80,minecraft:crying_obsidian,20)
RandomBlock(2,24,3,minecraft:obsidian,80,minecraft:crying_obsidian,20)
RandomBlock(2,25,3,minecraft:obsidian,80,minecraft:crying_obsidian,20)
RandomBlock(2,26,3,minecraft:obsidian,80,minecraft:crying_obsidian,20)
RandomBlock(2,27,3,minecraft:obsidian,80,minecraft:crying_obsidian,20)
RandomBlock(2,28,3,minecraft:obsidian,80,minecraft:crying_obsidian,20)
RandomBlock(2,29,3,minecraft:obsidian,80,minecraft:crying_obsidian,20)
RandomBlock(2,30,3,minecraft:obsidian,80,minecraft:crying_obsidian,20)
RandomBlock(2,31,3,minecraft:obsidian,80,minecraft:crying_obsidian,20)
RandomBlock(2,0,4,minecraft:obsidian,80,minecraft:crying_obsidian,20)
RandomBlock(2,1,4,minecraft:obsidian,80,minecraft:crying_obsidian,20)
RandomBlock(2,2,4,minecraft:obsidian,80,minecraft:crying_obsidian,20)
RandomBlock(2,3,4,minecraft:obsidian,80,minecraft:crying_obsidian,20)
RandomBlock(2,4,4,minecraft:obsidian,80,minecraft:crying_obsidian,20)
RandomBlock(2,5,4,minecraft:obsidian,80,minecraft:crying_obsidian,20)
RandomBlock(2,6,4,minecraft:obsidian,80,minecraft:crying_obsidian,20)
RandomBlock(2,7,4,minecraft:obsidian,80,minecraft:crying_obsidian,20)
RandomBlock(2,8,4,minecraft:obsidian,80,minecraft:crying_obsidian,20)
RandomBlock(2,9,4,minecraft:obsidian,80,minecraft:crying_obsidian,20)
RandomBlock(2,10,4,minecraft:obsidian,80,minecraft:crying_obsidian,20)
