
#######################################################################
# +-----------------------------------------------------------------+ #
# |                            BO4 object                           | #
# +-----------------------------------------------------------------+ #
#######################################################################

Author: Unknown

Description: No description given

SettingsMode: WriteWithoutComments


#######################################################################
# +-----------------------------------------------------------------+ #
# |                          Main settings                          | #
# +-----------------------------------------------------------------+ #
#######################################################################

FixedRotation: 

Frequency: 0

SpawnHeight: highestBlock

UseCenterForHighestBlock: true

##############################
# Height Limits for the BO4. #
##############################

MinHeight: 0

MaxHeight: 255

InheritBO3: 

InheritBO3Rotation: NORTH

OverrideChildSettings: true

OverrideParentHeight: false

CanOverride: false

BranchFrequency: 0

BranchFrequencyGroup: 

MustBeBelowOther: false

MustBeInside: 

CannotBeInside: 

ReplacesBO3: 

MustBeInsideWorldBorders: false

CanSpawnOnWater: true

SpawnOnWaterOnly: false

SpawnUnderWater: false

SpawnAtWaterLevel: false

HeightOffset: 0

RemoveAir: true

ReplaceAbove: 

ReplaceBelow: 

ReplaceWithBiomeBlocks: true

ReplaceWithSurfaceBlock: GRASS

ReplaceWithGroundBlock: DIRT

ReplaceWithStoneBlock: STONE

SmoothRadius: 0

SmoothHeightOffset: 0

SmoothStartTop: false

SmoothStartWood: false

SmoothingSurfaceBlock: 

SmoothingGroundBlock: 

BO3Group: 

IsSpawnPoint: false

DoReplaceBlocks: true


#######################################################################
# +-----------------------------------------------------------------+ #
# |                              Blocks                             | #
# +-----------------------------------------------------------------+ #
#######################################################################

B(-8,0,-4,minecraft:netherrack)
B(-8,0,-3,minecraft:netherrack)
B(-8,0,-2,minecraft:netherrack)
B(-8,1,-2,minecraft:netherrack)
B(-8,0,-1,minecraft:netherrack)
B(-8,1,-1,minecraft:netherrack)
B(-8,2,-1,minecraft:netherrack)
B(-8,0,0,minecraft:netherrack)
B(-8,1,0,minecraft:netherrack)
B(-8,2,0,minecraft:netherrack)
B(-8,3,0,minecraft:netherrack)
B(-8,0,1,minecraft:netherrack)
B(-8,1,1,minecraft:netherrack)
B(-8,2,1,minecraft:netherrack)
B(-8,3,1,minecraft:netherrack)
B(-8,0,2,minecraft:netherrack)
B(-8,1,2,minecraft:netherrack)
B(-8,2,2,minecraft:netherrack)
B(-8,3,2,minecraft:netherrack)
B(-8,4,2,minecraft:netherrack)
B(-8,0,3,minecraft:netherrack)
B(-8,1,3,minecraft:netherrack)
B(-8,2,3,minecraft:netherrack)
B(-8,3,3,minecraft:netherrack)
B(-8,4,3,minecraft:netherrack)
B(-8,5,3,minecraft:netherrack)
B(-8,0,4,minecraft:netherrack)
B(-8,1,4,minecraft:netherrack)
B(-8,2,4,minecraft:netherrack)
B(-8,3,4,minecraft:netherrack)
B(-8,4,4,minecraft:netherrack)
B(-8,5,4,minecraft:netherrack)
B(-8,6,4,minecraft:netherrack)
B(-8,7,4,minecraft:netherrack)
B(-8,0,5,minecraft:netherrack)
B(-8,1,5,minecraft:netherrack)
B(-8,2,5,minecraft:netherrack)
B(-8,3,5,minecraft:netherrack)
B(-8,4,5,minecraft:netherrack)
B(-8,5,5,minecraft:netherrack)
B(-8,6,5,minecraft:netherrack)
B(-8,7,5,minecraft:netherrack)
B(-8,8,5,minecraft:netherrack)
B(-8,9,5,minecraft:netherrack)
B(-8,10,5,minecraft:netherrack)
B(-8,0,6,minecraft:netherrack)
B(-8,1,6,minecraft:netherrack)
B(-8,2,6,minecraft:netherrack)
B(-8,3,6,minecraft:netherrack)
B(-8,4,6,minecraft:netherrack)
B(-8,5,6,minecraft:netherrack)
B(-8,6,6,minecraft:netherrack)
B(-8,7,6,minecraft:netherrack)
B(-8,8,6,minecraft:netherrack)
B(-8,9,6,minecraft:netherrack)
B(-8,10,6,minecraft:netherrack)
B(-8,11,6,minecraft:netherrack)
B(-8,12,6,minecraft:netherrack)
B(-8,13,6,minecraft:netherrack)
B(-8,0,7,minecraft:netherrack)
B(-8,1,7,minecraft:netherrack)
B(-8,2,7,minecraft:netherrack)
B(-8,3,7,minecraft:netherrack)
B(-8,4,7,minecraft:netherrack)
B(-8,5,7,minecraft:netherrack)
B(-8,6,7,minecraft:netherrack)
B(-8,7,7,minecraft:netherrack)
B(-8,8,7,minecraft:netherrack)
B(-8,9,7,minecraft:netherrack)
B(-8,10,7,minecraft:netherrack)
B(-8,11,7,minecraft:netherrack)
B(-8,12,7,minecraft:netherrack)
B(-8,13,7,minecraft:netherrack)
B(-8,14,7,minecraft:netherrack)
B(-8,15,7,minecraft:netherrack)
B(-8,0,8,minecraft:netherrack)
B(-8,1,8,minecraft:netherrack)
B(-8,2,8,minecraft:netherrack)
B(-8,3,8,minecraft:netherrack)
B(-8,4,8,minecraft:netherrack)
B(-8,5,8,minecraft:netherrack)
B(-8,6,8,minecraft:netherrack)
B(-8,7,8,minecraft:netherrack)
B(-8,8,8,minecraft:netherrack)
B(-8,9,8,minecraft:netherrack)
B(-8,10,8,minecraft:netherrack)
B(-8,11,8,minecraft:netherrack)
B(-8,12,8,minecraft:netherrack)
B(-8,13,8,minecraft:netherrack)
B(-8,14,8,minecraft:netherrack)
B(-8,15,8,minecraft:netherrack)
B(-8,16,8,minecraft:netherrack)
B(-8,17,8,minecraft:netherrack)
B(-7,0,-5,minecraft:blackstone)
B(-7,0,-4,minecraft:netherrack)
B(-7,0,-3,minecraft:blackstone)
B(-7,1,-3,minecraft:netherrack)
B(-7,0,-2,minecraft:netherrack)
B(-7,1,-2,minecraft:netherrack)
B(-7,0,-1,minecraft:netherrack)
B(-7,1,-1,minecraft:netherrack)
B(-7,2,-1,minecraft:netherrack)
B(-7,0,0,minecraft:netherrack)
B(-7,1,0,minecraft:netherrack)
B(-7,2,0,minecraft:netherrack)
B(-7,3,0,minecraft:netherrack)
B(-7,0,1,minecraft:netherrack)
B(-7,1,1,minecraft:netherrack)
B(-7,2,1,minecraft:netherrack)
B(-7,3,1,minecraft:netherrack)
B(-7,0,2,minecraft:netherrack)
B(-7,1,2,minecraft:netherrack)
B(-7,2,2,minecraft:netherrack)
B(-7,3,2,minecraft:netherrack)
B(-7,4,2,minecraft:netherrack)
B(-7,0,3,minecraft:netherrack)
B(-7,1,3,minecraft:netherrack)
B(-7,2,3,minecraft:netherrack)
B(-7,3,3,minecraft:netherrack)
B(-7,4,3,minecraft:netherrack)
B(-7,5,3,minecraft:netherrack)
B(-7,0,4,minecraft:netherrack)
B(-7,1,4,minecraft:netherrack)
B(-7,2,4,minecraft:netherrack)
B(-7,3,4,minecraft:netherrack)
B(-7,4,4,minecraft:netherrack)
B(-7,5,4,minecraft:netherrack)
B(-7,6,4,minecraft:netherrack)
B(-7,7,4,minecraft:netherrack)
B(-7,0,5,minecraft:netherrack)
B(-7,1,5,minecraft:netherrack)
B(-7,2,5,minecraft:netherrack)
B(-7,3,5,minecraft:netherrack)
B(-7,4,5,minecraft:netherrack)
B(-7,5,5,minecraft:netherrack)
B(-7,6,5,minecraft:netherrack)
B(-7,7,5,minecraft:netherrack)
B(-7,8,5,minecraft:netherrack)
B(-7,9,5,minecraft:netherrack)
B(-7,10,5,minecraft:netherrack)
B(-7,0,6,minecraft:netherrack)
B(-7,1,6,minecraft:netherrack)
B(-7,2,6,minecraft:netherrack)
B(-7,3,6,minecraft:netherrack)
B(-7,4,6,minecraft:netherrack)
B(-7,5,6,minecraft:netherrack)
B(-7,6,6,minecraft:netherrack)
B(-7,7,6,minecraft:netherrack)
B(-7,8,6,minecraft:netherrack)
B(-7,9,6,minecraft:netherrack)
B(-7,10,6,minecraft:netherrack)
B(-7,11,6,minecraft:netherrack)
B(-7,12,6,minecraft:netherrack)
B(-7,13,6,minecraft:netherrack)
B(-7,0,7,minecraft:netherrack)
B(-7,1,7,minecraft:netherrack)
B(-7,2,7,minecraft:netherrack)
B(-7,3,7,minecraft:netherrack)
B(-7,4,7,minecraft:netherrack)
B(-7,5,7,minecraft:netherrack)
B(-7,6,7,minecraft:netherrack)
B(-7,7,7,minecraft:netherrack)
B(-7,8,7,minecraft:netherrack)
B(-7,9,7,minecraft:netherrack)
B(-7,10,7,minecraft:netherrack)
B(-7,11,7,minecraft:netherrack)
B(-7,12,7,minecraft:netherrack)
B(-7,13,7,minecraft:netherrack)
B(-7,14,7,minecraft:netherrack)
B(-7,15,7,minecraft:netherrack)
B(-7,16,7,minecraft:netherrack)
B(-7,0,8,minecraft:netherrack)
B(-7,1,8,minecraft:netherrack)
B(-7,2,8,minecraft:netherrack)
B(-7,3,8,minecraft:netherrack)
B(-7,4,8,minecraft:netherrack)
B(-7,5,8,minecraft:netherrack)
B(-7,6,8,minecraft:netherrack)
B(-7,7,8,minecraft:netherrack)
B(-7,8,8,minecraft:netherrack)
B(-7,9,8,minecraft:netherrack)
B(-7,10,8,minecraft:netherrack)
B(-7,11,8,minecraft:netherrack)
B(-7,12,8,minecraft:netherrack)
B(-7,13,8,minecraft:netherrack)
B(-7,14,8,minecraft:netherrack)
B(-7,15,8,minecraft:netherrack)
B(-7,16,8,minecraft:netherrack)
B(-7,17,8,minecraft:netherrack)
B(-7,18,8,minecraft:netherrack)
B(-6,0,-7,minecraft:netherrack)
B(-6,0,-6,minecraft:netherrack)
B(-6,0,-5,minecraft:netherrack)
B(-6,0,-4,minecraft:blackstone)
B(-6,1,-4,minecraft:netherrack)
B(-6,0,-3,minecraft:netherrack)
B(-6,1,-3,minecraft:netherrack)
B(-6,0,-2,minecraft:netherrack)
B(-6,1,-2,minecraft:netherrack)
B(-6,2,-2,minecraft:netherrack)
B(-6,0,-1,minecraft:netherrack)
B(-6,1,-1,minecraft:netherrack)
B(-6,2,-1,minecraft:netherrack)
B(-6,0,0,minecraft:netherrack)
B(-6,1,0,minecraft:netherrack)
B(-6,2,0,minecraft:netherrack)
B(-6,3,0,minecraft:netherrack)
B(-6,0,1,minecraft:netherrack)
B(-6,1,1,minecraft:netherrack)
B(-6,2,1,minecraft:netherrack)
B(-6,3,1,minecraft:netherrack)
B(-6,0,2,minecraft:netherrack)
B(-6,1,2,minecraft:netherrack)
B(-6,2,2,minecraft:netherrack)
B(-6,3,2,minecraft:netherrack)
B(-6,4,2,minecraft:netherrack)
B(-6,0,3,minecraft:netherrack)
B(-6,1,3,minecraft:netherrack)
B(-6,2,3,minecraft:netherrack)
B(-6,3,3,minecraft:netherrack)
B(-6,4,3,minecraft:netherrack)
B(-6,5,3,minecraft:netherrack)
B(-6,0,4,minecraft:netherrack)
B(-6,1,4,minecraft:netherrack)
B(-6,2,4,minecraft:netherrack)
B(-6,3,4,minecraft:netherrack)
B(-6,4,4,minecraft:netherrack)
B(-6,5,4,minecraft:netherrack)
B(-6,6,4,minecraft:netherrack)
B(-6,7,4,minecraft:netherrack)
B(-6,0,5,minecraft:netherrack)
B(-6,1,5,minecraft:netherrack)
B(-6,2,5,minecraft:netherrack)
B(-6,3,5,minecraft:netherrack)
B(-6,4,5,minecraft:netherrack)
B(-6,5,5,minecraft:netherrack)
B(-6,6,5,minecraft:netherrack)
B(-6,7,5,minecraft:netherrack)
B(-6,8,5,minecraft:netherrack)
B(-6,9,5,minecraft:netherrack)
B(-6,10,5,minecraft:netherrack)
B(-6,0,6,minecraft:netherrack)
B(-6,1,6,minecraft:netherrack)
B(-6,2,6,minecraft:netherrack)
B(-6,3,6,minecraft:netherrack)
B(-6,4,6,minecraft:netherrack)
B(-6,5,6,minecraft:netherrack)
B(-6,6,6,minecraft:netherrack)
B(-6,7,6,minecraft:netherrack)
B(-6,8,6,minecraft:netherrack)
B(-6,9,6,minecraft:netherrack)
B(-6,10,6,minecraft:netherrack)
B(-6,11,6,minecraft:netherrack)
B(-6,12,6,minecraft:netherrack)
B(-6,13,6,minecraft:netherrack)
B(-6,0,7,minecraft:netherrack)
B(-6,1,7,minecraft:netherrack)
B(-6,2,7,minecraft:netherrack)
B(-6,3,7,minecraft:netherrack)
B(-6,4,7,minecraft:netherrack)
B(-6,5,7,minecraft:netherrack)
B(-6,6,7,minecraft:netherrack)
B(-6,7,7,minecraft:netherrack)
B(-6,8,7,minecraft:netherrack)
B(-6,9,7,minecraft:netherrack)
B(-6,10,7,minecraft:netherrack)
B(-6,11,7,minecraft:netherrack)
B(-6,12,7,minecraft:netherrack)
B(-6,13,7,minecraft:netherrack)
B(-6,14,7,minecraft:netherrack)
B(-6,15,7,minecraft:netherrack)
B(-6,16,7,minecraft:netherrack)
B(-6,0,8,minecraft:netherrack)
B(-6,1,8,minecraft:netherrack)
B(-6,2,8,minecraft:netherrack)
B(-6,3,8,minecraft:netherrack)
B(-6,4,8,minecraft:netherrack)
B(-6,5,8,minecraft:netherrack)
B(-6,6,8,minecraft:netherrack)
B(-6,7,8,minecraft:netherrack)
B(-6,8,8,minecraft:netherrack)
B(-6,9,8,minecraft:netherrack)
B(-6,10,8,minecraft:netherrack)
B(-6,11,8,minecraft:netherrack)
B(-6,12,8,minecraft:netherrack)
B(-6,13,8,minecraft:netherrack)
B(-6,14,8,minecraft:netherrack)
B(-6,15,8,minecraft:netherrack)
B(-6,16,8,minecraft:netherrack)
B(-6,17,8,minecraft:netherrack)
B(-6,18,8,minecraft:netherrack)
B(-5,0,-7,minecraft:netherrack)
B(-5,0,-6,minecraft:netherrack)
B(-5,0,-5,minecraft:netherrack)
B(-5,0,-4,minecraft:netherrack)
B(-5,1,-4,minecraft:netherrack)
B(-5,0,-3,minecraft:netherrack)
B(-5,1,-3,minecraft:netherrack)
B(-5,2,-3,minecraft:netherrack)
B(-5,0,-2,minecraft:netherrack)
B(-5,1,-2,minecraft:netherrack)
B(-5,2,-2,minecraft:netherrack)
B(-5,0,-1,minecraft:netherrack)
B(-5,1,-1,minecraft:netherrack)
B(-5,2,-1,minecraft:netherrack)
B(-5,0,0,minecraft:netherrack)
B(-5,1,0,minecraft:netherrack)
B(-5,2,0,minecraft:netherrack)
B(-5,3,0,minecraft:netherrack)
B(-5,0,1,minecraft:netherrack)
B(-5,1,1,minecraft:netherrack)
B(-5,2,1,minecraft:netherrack)
B(-5,3,1,minecraft:netherrack)
B(-5,0,2,minecraft:netherrack)
B(-5,1,2,minecraft:netherrack)
B(-5,2,2,minecraft:netherrack)
B(-5,3,2,minecraft:netherrack)
B(-5,4,2,minecraft:netherrack)
B(-5,0,3,minecraft:netherrack)
B(-5,1,3,minecraft:netherrack)
B(-5,2,3,minecraft:netherrack)
B(-5,3,3,minecraft:netherrack)
B(-5,4,3,minecraft:netherrack)
B(-5,5,3,minecraft:netherrack)
B(-5,0,4,minecraft:netherrack)
B(-5,1,4,minecraft:netherrack)
B(-5,2,4,minecraft:netherrack)
B(-5,3,4,minecraft:netherrack)
B(-5,4,4,minecraft:netherrack)
B(-5,5,4,minecraft:netherrack)
B(-5,6,4,minecraft:netherrack)
B(-5,7,4,minecraft:netherrack)
B(-5,0,5,minecraft:netherrack)
B(-5,1,5,minecraft:netherrack)
B(-5,2,5,minecraft:netherrack)
B(-5,3,5,minecraft:netherrack)
B(-5,4,5,minecraft:netherrack)
B(-5,5,5,minecraft:netherrack)
B(-5,6,5,minecraft:netherrack)
B(-5,7,5,minecraft:netherrack)
B(-5,8,5,minecraft:netherrack)
B(-5,9,5,minecraft:netherrack)
B(-5,10,5,minecraft:netherrack)
B(-5,0,6,minecraft:netherrack)
B(-5,1,6,minecraft:netherrack)
B(-5,2,6,minecraft:netherrack)
B(-5,3,6,minecraft:netherrack)
B(-5,4,6,minecraft:netherrack)
B(-5,5,6,minecraft:netherrack)
B(-5,6,6,minecraft:netherrack)
B(-5,7,6,minecraft:netherrack)
B(-5,8,6,minecraft:netherrack)
B(-5,9,6,minecraft:netherrack)
B(-5,10,6,minecraft:netherrack)
B(-5,11,6,minecraft:netherrack)
B(-5,12,6,minecraft:netherrack)
B(-5,13,6,minecraft:netherrack)
B(-5,0,7,minecraft:netherrack)
B(-5,1,7,minecraft:netherrack)
B(-5,2,7,minecraft:netherrack)
B(-5,3,7,minecraft:netherrack)
B(-5,4,7,minecraft:netherrack)
B(-5,5,7,minecraft:netherrack)
B(-5,6,7,minecraft:netherrack)
B(-5,7,7,minecraft:netherrack)
B(-5,8,7,minecraft:netherrack)
B(-5,9,7,minecraft:netherrack)
B(-5,10,7,minecraft:netherrack)
B(-5,11,7,minecraft:netherrack)
B(-5,12,7,minecraft:netherrack)
B(-5,13,7,minecraft:netherrack)
B(-5,14,7,minecraft:netherrack)
B(-5,15,7,minecraft:netherrack)
B(-5,16,7,minecraft:netherrack)
B(-5,0,8,minecraft:netherrack)
B(-5,1,8,minecraft:netherrack)
B(-5,2,8,minecraft:netherrack)
B(-5,3,8,minecraft:netherrack)
B(-5,4,8,minecraft:netherrack)
B(-5,5,8,minecraft:netherrack)
B(-5,6,8,minecraft:netherrack)
B(-5,7,8,minecraft:netherrack)
B(-5,8,8,minecraft:netherrack)
B(-5,9,8,minecraft:netherrack)
B(-5,10,8,minecraft:netherrack)
B(-5,11,8,minecraft:netherrack)
B(-5,12,8,minecraft:netherrack)
B(-5,13,8,minecraft:netherrack)
B(-5,14,8,minecraft:netherrack)
B(-5,15,8,minecraft:netherrack)
B(-5,16,8,minecraft:netherrack)
B(-5,17,8,minecraft:netherrack)
B(-5,18,8,minecraft:netherrack)
B(-4,0,-7,minecraft:netherrack)
B(-4,0,-6,minecraft:netherrack)
B(-4,0,-5,minecraft:netherrack)
B(-4,1,-5,minecraft:netherrack)
B(-4,0,-4,minecraft:netherrack)
B(-4,1,-4,minecraft:netherrack)
B(-4,2,-4,minecraft:netherrack)
B(-4,0,-3,minecraft:netherrack)
B(-4,1,-3,minecraft:netherrack)
B(-4,2,-3,minecraft:netherrack)
B(-4,0,-2,minecraft:netherrack)
B(-4,1,-2,minecraft:netherrack)
B(-4,2,-2,minecraft:netherrack)
B(-4,3,-2,minecraft:netherrack)
B(-4,0,-1,minecraft:netherrack)
B(-4,1,-1,minecraft:netherrack)
B(-4,2,-1,minecraft:netherrack)
B(-4,3,-1,minecraft:netherrack)
B(-4,0,0,minecraft:netherrack)
B(-4,1,0,minecraft:netherrack)
B(-4,2,0,minecraft:netherrack)
B(-4,3,0,minecraft:netherrack)
B(-4,0,1,minecraft:netherrack)
B(-4,1,1,minecraft:netherrack)
B(-4,2,1,minecraft:netherrack)
B(-4,3,1,minecraft:netherrack)
B(-4,0,2,minecraft:netherrack)
B(-4,1,2,minecraft:netherrack)
B(-4,2,2,minecraft:netherrack)
B(-4,3,2,minecraft:netherrack)
B(-4,4,2,minecraft:netherrack)
B(-4,0,3,minecraft:netherrack)
B(-4,1,3,minecraft:netherrack)
B(-4,2,3,minecraft:netherrack)
B(-4,3,3,minecraft:netherrack)
B(-4,4,3,minecraft:netherrack)
B(-4,5,3,minecraft:netherrack)
B(-4,0,4,minecraft:netherrack)
B(-4,1,4,minecraft:netherrack)
B(-4,2,4,minecraft:netherrack)
B(-4,3,4,minecraft:netherrack)
B(-4,4,4,minecraft:netherrack)
B(-4,5,4,minecraft:netherrack)
B(-4,6,4,minecraft:netherrack)
B(-4,7,4,minecraft:netherrack)
B(-4,0,5,minecraft:netherrack)
B(-4,1,5,minecraft:netherrack)
B(-4,2,5,minecraft:netherrack)
B(-4,3,5,minecraft:netherrack)
B(-4,4,5,minecraft:netherrack)
B(-4,5,5,minecraft:netherrack)
B(-4,6,5,minecraft:netherrack)
B(-4,7,5,minecraft:netherrack)
B(-4,8,5,minecraft:netherrack)
B(-4,9,5,minecraft:netherrack)
B(-4,10,5,minecraft:netherrack)
B(-4,0,6,minecraft:netherrack)
B(-4,1,6,minecraft:netherrack)
B(-4,2,6,minecraft:netherrack)
B(-4,3,6,minecraft:netherrack)
B(-4,4,6,minecraft:netherrack)
B(-4,5,6,minecraft:netherrack)
B(-4,6,6,minecraft:netherrack)
B(-4,7,6,minecraft:netherrack)
B(-4,8,6,minecraft:netherrack)
B(-4,9,6,minecraft:netherrack)
B(-4,10,6,minecraft:netherrack)
B(-4,11,6,minecraft:netherrack)
B(-4,12,6,minecraft:netherrack)
B(-4,13,6,minecraft:netherrack)
B(-4,0,7,minecraft:netherrack)
B(-4,1,7,minecraft:netherrack)
B(-4,2,7,minecraft:netherrack)
B(-4,3,7,minecraft:netherrack)
B(-4,4,7,minecraft:netherrack)
B(-4,5,7,minecraft:netherrack)
B(-4,6,7,minecraft:netherrack)
B(-4,7,7,minecraft:netherrack)
B(-4,8,7,minecraft:netherrack)
B(-4,9,7,minecraft:netherrack)
B(-4,10,7,minecraft:netherrack)
B(-4,11,7,minecraft:netherrack)
B(-4,12,7,minecraft:netherrack)
B(-4,13,7,minecraft:netherrack)
B(-4,14,7,minecraft:netherrack)
B(-4,15,7,minecraft:netherrack)
B(-4,16,7,minecraft:netherrack)
B(-4,0,8,minecraft:netherrack)
B(-4,1,8,minecraft:netherrack)
B(-4,2,8,minecraft:netherrack)
B(-4,3,8,minecraft:netherrack)
B(-4,4,8,minecraft:netherrack)
B(-4,5,8,minecraft:netherrack)
B(-4,6,8,minecraft:netherrack)
B(-4,7,8,minecraft:netherrack)
B(-4,8,8,minecraft:netherrack)
B(-4,9,8,minecraft:netherrack)
B(-4,10,8,minecraft:netherrack)
B(-4,11,8,minecraft:netherrack)
B(-4,12,8,minecraft:netherrack)
B(-4,13,8,minecraft:netherrack)
B(-4,14,8,minecraft:netherrack)
B(-4,15,8,minecraft:netherrack)
B(-4,16,8,minecraft:netherrack)
B(-4,17,8,minecraft:netherrack)
B(-4,18,8,minecraft:netherrack)
B(-3,0,-7,minecraft:netherrack)
B(-3,0,-6,minecraft:netherrack)
B(-3,1,-6,minecraft:netherrack)
B(-3,0,-5,minecraft:netherrack)
B(-3,1,-5,minecraft:netherrack)
B(-3,2,-5,minecraft:netherrack)
B(-3,0,-4,minecraft:netherrack)
B(-3,1,-4,minecraft:netherrack)
B(-3,2,-4,minecraft:netherrack)
B(-3,0,-3,minecraft:netherrack)
B(-3,1,-3,minecraft:netherrack)
B(-3,2,-3,minecraft:netherrack)
B(-3,3,-3,minecraft:netherrack)
B(-3,0,-2,minecraft:netherrack)
B(-3,1,-2,minecraft:netherrack)
B(-3,2,-2,minecraft:netherrack)
B(-3,3,-2,minecraft:netherrack)
B(-3,0,-1,minecraft:netherrack)
B(-3,1,-1,minecraft:netherrack)
B(-3,2,-1,minecraft:netherrack)
B(-3,3,-1,minecraft:netherrack)
B(-3,0,0,minecraft:netherrack)
B(-3,1,0,minecraft:netherrack)
B(-3,2,0,minecraft:netherrack)
B(-3,3,0,minecraft:netherrack)
B(-3,4,0,minecraft:netherrack)
B(-3,0,1,minecraft:netherrack)
B(-3,1,1,minecraft:netherrack)
B(-3,2,1,minecraft:netherrack)
B(-3,3,1,minecraft:netherrack)
B(-3,4,1,minecraft:netherrack)
B(-3,0,2,minecraft:netherrack)
B(-3,1,2,minecraft:netherrack)
B(-3,2,2,minecraft:netherrack)
B(-3,3,2,minecraft:netherrack)
B(-3,4,2,minecraft:netherrack)
B(-3,0,3,minecraft:netherrack)
B(-3,1,3,minecraft:netherrack)
B(-3,2,3,minecraft:netherrack)
B(-3,3,3,minecraft:netherrack)
B(-3,4,3,minecraft:netherrack)
B(-3,5,3,minecraft:netherrack)
B(-3,0,4,minecraft:netherrack)
B(-3,1,4,minecraft:netherrack)
B(-3,2,4,minecraft:netherrack)
B(-3,3,4,minecraft:netherrack)
B(-3,4,4,minecraft:netherrack)
B(-3,5,4,minecraft:netherrack)
B(-3,6,4,minecraft:netherrack)
B(-3,7,4,minecraft:netherrack)
B(-3,0,5,minecraft:netherrack)
B(-3,1,5,minecraft:netherrack)
B(-3,2,5,minecraft:netherrack)
B(-3,3,5,minecraft:netherrack)
B(-3,4,5,minecraft:netherrack)
B(-3,5,5,minecraft:netherrack)
B(-3,6,5,minecraft:netherrack)
B(-3,7,5,minecraft:netherrack)
B(-3,8,5,minecraft:netherrack)
B(-3,9,5,minecraft:netherrack)
B(-3,10,5,minecraft:netherrack)
B(-3,0,6,minecraft:netherrack)
B(-3,1,6,minecraft:netherrack)
B(-3,2,6,minecraft:netherrack)
B(-3,3,6,minecraft:netherrack)
B(-3,4,6,minecraft:netherrack)
B(-3,5,6,minecraft:netherrack)
B(-3,6,6,minecraft:netherrack)
B(-3,7,6,minecraft:netherrack)
B(-3,8,6,minecraft:netherrack)
B(-3,9,6,minecraft:netherrack)
B(-3,10,6,minecraft:netherrack)
B(-3,11,6,minecraft:netherrack)
B(-3,12,6,minecraft:netherrack)
B(-3,0,7,minecraft:netherrack)
B(-3,1,7,minecraft:netherrack)
B(-3,2,7,minecraft:netherrack)
B(-3,3,7,minecraft:netherrack)
B(-3,4,7,minecraft:netherrack)
B(-3,5,7,minecraft:netherrack)
B(-3,6,7,minecraft:netherrack)
B(-3,7,7,minecraft:netherrack)
B(-3,8,7,minecraft:netherrack)
B(-3,9,7,minecraft:netherrack)
B(-3,10,7,minecraft:netherrack)
B(-3,11,7,minecraft:netherrack)
B(-3,12,7,minecraft:netherrack)
B(-3,13,7,minecraft:netherrack)
B(-3,14,7,minecraft:netherrack)
B(-3,15,7,minecraft:netherrack)
B(-3,0,8,minecraft:netherrack)
B(-3,1,8,minecraft:netherrack)
B(-3,2,8,minecraft:netherrack)
B(-3,3,8,minecraft:netherrack)
B(-3,4,8,minecraft:netherrack)
B(-3,5,8,minecraft:netherrack)
B(-3,6,8,minecraft:netherrack)
B(-3,7,8,minecraft:netherrack)
B(-3,8,8,minecraft:netherrack)
B(-3,9,8,minecraft:netherrack)
B(-3,10,8,minecraft:netherrack)
B(-3,11,8,minecraft:netherrack)
B(-3,12,8,minecraft:netherrack)
B(-3,13,8,minecraft:netherrack)
B(-3,14,8,minecraft:netherrack)
B(-3,15,8,minecraft:netherrack)
B(-3,16,8,minecraft:netherrack)
B(-3,17,8,minecraft:netherrack)
B(-3,18,8,minecraft:netherrack)
B(-2,0,-7,minecraft:netherrack)
B(-2,0,-6,minecraft:netherrack)
B(-2,1,-6,minecraft:netherrack)
B(-2,0,-5,minecraft:netherrack)
B(-2,1,-5,minecraft:netherrack)
B(-2,2,-5,minecraft:netherrack)
B(-2,0,-4,minecraft:netherrack)
B(-2,1,-4,minecraft:netherrack)
B(-2,2,-4,minecraft:netherrack)
B(-2,0,-3,minecraft:netherrack)
B(-2,1,-3,minecraft:netherrack)
B(-2,2,-3,minecraft:netherrack)
B(-2,3,-3,minecraft:netherrack)
B(-2,0,-2,minecraft:netherrack)
B(-2,1,-2,minecraft:netherrack)
B(-2,2,-2,minecraft:netherrack)
B(-2,3,-2,minecraft:netherrack)
B(-2,0,-1,minecraft:netherrack)
B(-2,1,-1,minecraft:netherrack)
B(-2,2,-1,minecraft:netherrack)
B(-2,3,-1,minecraft:netherrack)
B(-2,4,-1,minecraft:netherrack)
B(-2,0,0,minecraft:netherrack)
B(-2,1,0,minecraft:netherrack)
B(-2,2,0,minecraft:netherrack)
B(-2,3,0,minecraft:netherrack)
B(-2,4,0,minecraft:netherrack)
B(-2,0,1,minecraft:netherrack)
B(-2,1,1,minecraft:netherrack)
B(-2,2,1,minecraft:netherrack)
B(-2,3,1,minecraft:netherrack)
B(-2,4,1,minecraft:netherrack)
B(-2,0,2,minecraft:netherrack)
B(-2,1,2,minecraft:netherrack)
B(-2,2,2,minecraft:netherrack)
B(-2,3,2,minecraft:netherrack)
B(-2,4,2,minecraft:netherrack)
B(-2,0,3,minecraft:netherrack)
B(-2,1,3,minecraft:netherrack)
B(-2,2,3,minecraft:netherrack)
B(-2,3,3,minecraft:netherrack)
B(-2,4,3,minecraft:netherrack)
B(-2,5,3,minecraft:netherrack)
B(-2,0,4,minecraft:netherrack)
B(-2,1,4,minecraft:netherrack)
B(-2,2,4,minecraft:netherrack)
B(-2,3,4,minecraft:netherrack)
B(-2,4,4,minecraft:netherrack)
B(-2,5,4,minecraft:netherrack)
B(-2,6,4,minecraft:netherrack)
B(-2,7,4,minecraft:netherrack)
B(-2,0,5,minecraft:netherrack)
B(-2,1,5,minecraft:netherrack)
B(-2,2,5,minecraft:netherrack)
B(-2,3,5,minecraft:netherrack)
B(-2,4,5,minecraft:netherrack)
B(-2,5,5,minecraft:netherrack)
B(-2,6,5,minecraft:netherrack)
B(-2,7,5,minecraft:netherrack)
B(-2,8,5,minecraft:netherrack)
B(-2,9,5,minecraft:netherrack)
B(-2,0,6,minecraft:netherrack)
B(-2,1,6,minecraft:netherrack)
B(-2,2,6,minecraft:netherrack)
B(-2,3,6,minecraft:netherrack)
B(-2,4,6,minecraft:netherrack)
B(-2,5,6,minecraft:netherrack)
B(-2,6,6,minecraft:netherrack)
B(-2,7,6,minecraft:netherrack)
B(-2,8,6,minecraft:netherrack)
B(-2,9,6,minecraft:netherrack)
B(-2,10,6,minecraft:netherrack)
B(-2,11,6,minecraft:netherrack)
B(-2,12,6,minecraft:netherrack)
B(-2,0,7,minecraft:netherrack)
B(-2,1,7,minecraft:netherrack)
B(-2,2,7,minecraft:netherrack)
B(-2,3,7,minecraft:netherrack)
B(-2,4,7,minecraft:netherrack)
B(-2,5,7,minecraft:netherrack)
B(-2,6,7,minecraft:netherrack)
B(-2,7,7,minecraft:netherrack)
B(-2,8,7,minecraft:netherrack)
B(-2,9,7,minecraft:netherrack)
B(-2,10,7,minecraft:netherrack)
B(-2,11,7,minecraft:netherrack)
B(-2,12,7,minecraft:netherrack)
B(-2,13,7,minecraft:netherrack)
B(-2,14,7,minecraft:netherrack)
B(-2,15,7,minecraft:netherrack)
B(-2,0,8,minecraft:netherrack)
B(-2,1,8,minecraft:netherrack)
B(-2,2,8,minecraft:netherrack)
B(-2,3,8,minecraft:netherrack)
B(-2,4,8,minecraft:netherrack)
B(-2,5,8,minecraft:netherrack)
B(-2,6,8,minecraft:netherrack)
B(-2,7,8,minecraft:netherrack)
B(-2,8,8,minecraft:netherrack)
B(-2,9,8,minecraft:netherrack)
B(-2,10,8,minecraft:netherrack)
B(-2,11,8,minecraft:netherrack)
B(-2,12,8,minecraft:netherrack)
B(-2,13,8,minecraft:netherrack)
B(-2,14,8,minecraft:netherrack)
B(-2,15,8,minecraft:netherrack)
B(-2,16,8,minecraft:netherrack)
B(-2,17,8,minecraft:netherrack)
B(-2,18,8,minecraft:netherrack)
B(-1,0,-7,minecraft:netherrack)
B(-1,0,-6,minecraft:netherrack)
B(-1,1,-6,minecraft:netherrack)
B(-1,0,-5,minecraft:netherrack)
B(-1,1,-5,minecraft:netherrack)
B(-1,2,-5,minecraft:netherrack)
B(-1,0,-4,minecraft:netherrack)
B(-1,1,-4,minecraft:netherrack)
B(-1,2,-4,minecraft:netherrack)
B(-1,3,-4,minecraft:netherrack)
B(-1,0,-3,minecraft:netherrack)
B(-1,1,-3,minecraft:netherrack)
B(-1,2,-3,minecraft:netherrack)
B(-1,3,-3,minecraft:netherrack)
B(-1,4,-3,minecraft:netherrack)
B(-1,0,-2,minecraft:netherrack)
B(-1,1,-2,minecraft:netherrack)
B(-1,2,-2,minecraft:netherrack)
B(-1,3,-2,minecraft:netherrack)
B(-1,4,-2,minecraft:netherrack)
B(-1,0,-1,minecraft:netherrack)
B(-1,1,-1,minecraft:netherrack)
B(-1,2,-1,minecraft:netherrack)
B(-1,3,-1,minecraft:netherrack)
B(-1,4,-1,minecraft:netherrack)
B(-1,0,0,minecraft:netherrack)
B(-1,1,0,minecraft:netherrack)
B(-1,2,0,minecraft:netherrack)
B(-1,3,0,minecraft:netherrack)
B(-1,4,0,minecraft:netherrack)
B(-1,0,1,minecraft:netherrack)
B(-1,1,1,minecraft:netherrack)
B(-1,2,1,minecraft:netherrack)
B(-1,3,1,minecraft:netherrack)
B(-1,4,1,minecraft:netherrack)
B(-1,0,2,minecraft:netherrack)
B(-1,1,2,minecraft:netherrack)
B(-1,2,2,minecraft:netherrack)
B(-1,3,2,minecraft:netherrack)
B(-1,4,2,minecraft:netherrack)
B(-1,0,3,minecraft:netherrack)
B(-1,1,3,minecraft:netherrack)
B(-1,2,3,minecraft:netherrack)
B(-1,3,3,minecraft:netherrack)
B(-1,4,3,minecraft:netherrack)
B(-1,5,3,minecraft:netherrack)
B(-1,0,4,minecraft:netherrack)
B(-1,1,4,minecraft:netherrack)
B(-1,2,4,minecraft:netherrack)
B(-1,3,4,minecraft:netherrack)
B(-1,4,4,minecraft:netherrack)
B(-1,5,4,minecraft:netherrack)
B(-1,6,4,minecraft:netherrack)
B(-1,7,4,minecraft:netherrack)
B(-1,0,5,minecraft:netherrack)
B(-1,1,5,minecraft:netherrack)
B(-1,2,5,minecraft:netherrack)
B(-1,3,5,minecraft:netherrack)
B(-1,4,5,minecraft:netherrack)
B(-1,5,5,minecraft:netherrack)
B(-1,6,5,minecraft:netherrack)
B(-1,7,5,minecraft:netherrack)
B(-1,8,5,minecraft:netherrack)
B(-1,9,5,minecraft:netherrack)
B(-1,10,5,minecraft:netherrack)
B(-1,0,6,minecraft:netherrack)
B(-1,1,6,minecraft:netherrack)
B(-1,2,6,minecraft:netherrack)
B(-1,3,6,minecraft:netherrack)
B(-1,4,6,minecraft:netherrack)
B(-1,5,6,minecraft:netherrack)
B(-1,6,6,minecraft:netherrack)
B(-1,7,6,minecraft:netherrack)
B(-1,8,6,minecraft:netherrack)
B(-1,9,6,minecraft:netherrack)
B(-1,10,6,minecraft:netherrack)
B(-1,11,6,minecraft:netherrack)
B(-1,12,6,minecraft:netherrack)
B(-1,0,7,minecraft:netherrack)
B(-1,1,7,minecraft:netherrack)
B(-1,2,7,minecraft:netherrack)
B(-1,3,7,minecraft:netherrack)
B(-1,4,7,minecraft:netherrack)
B(-1,5,7,minecraft:netherrack)
B(-1,6,7,minecraft:netherrack)
B(-1,7,7,minecraft:netherrack)
B(-1,8,7,minecraft:netherrack)
B(-1,9,7,minecraft:netherrack)
B(-1,10,7,minecraft:netherrack)
B(-1,11,7,minecraft:netherrack)
B(-1,12,7,minecraft:netherrack)
B(-1,13,7,minecraft:netherrack)
B(-1,14,7,minecraft:netherrack)
B(-1,15,7,minecraft:netherrack)
B(-1,0,8,minecraft:netherrack)
B(-1,1,8,minecraft:netherrack)
B(-1,2,8,minecraft:netherrack)
B(-1,3,8,minecraft:netherrack)
B(-1,4,8,minecraft:netherrack)
B(-1,5,8,minecraft:netherrack)
B(-1,6,8,minecraft:netherrack)
B(-1,7,8,minecraft:netherrack)
B(-1,8,8,minecraft:netherrack)
B(-1,9,8,minecraft:netherrack)
B(-1,10,8,minecraft:netherrack)
B(-1,11,8,minecraft:netherrack)
B(-1,12,8,minecraft:netherrack)
B(-1,13,8,minecraft:netherrack)
B(-1,14,8,minecraft:netherrack)
B(-1,15,8,minecraft:netherrack)
B(-1,16,8,minecraft:netherrack)
B(-1,17,8,minecraft:netherrack)
B(-1,18,8,minecraft:netherrack)
B(0,0,-7,minecraft:netherrack)
B(0,0,-6,minecraft:netherrack)
B(0,1,-6,minecraft:netherrack)
B(0,0,-5,minecraft:netherrack)
B(0,1,-5,minecraft:netherrack)
B(0,2,-5,minecraft:netherrack)
B(0,0,-4,minecraft:netherrack)
B(0,1,-4,minecraft:netherrack)
B(0,2,-4,minecraft:netherrack)
B(0,3,-4,minecraft:netherrack)
B(0,0,-3,minecraft:netherrack)
B(0,1,-3,minecraft:netherrack)
B(0,2,-3,minecraft:netherrack)
B(0,3,-3,minecraft:netherrack)
B(0,4,-3,minecraft:netherrack)
B(0,0,-2,minecraft:netherrack)
B(0,1,-2,minecraft:netherrack)
B(0,2,-2,minecraft:netherrack)
B(0,3,-2,minecraft:netherrack)
B(0,4,-2,minecraft:netherrack)
B(0,0,-1,minecraft:netherrack)
B(0,1,-1,minecraft:netherrack)
B(0,2,-1,minecraft:netherrack)
B(0,3,-1,minecraft:netherrack)
B(0,4,-1,minecraft:netherrack)
B(0,0,0,minecraft:netherrack)
B(0,1,0,minecraft:netherrack)
B(0,2,0,minecraft:netherrack)
B(0,3,0,minecraft:netherrack)
B(0,4,0,minecraft:netherrack)
B(0,0,1,minecraft:netherrack)
B(0,1,1,minecraft:netherrack)
B(0,2,1,minecraft:netherrack)
B(0,3,1,minecraft:netherrack)
B(0,4,1,minecraft:netherrack)
B(0,0,2,minecraft:netherrack)
B(0,1,2,minecraft:netherrack)
B(0,2,2,minecraft:netherrack)
B(0,3,2,minecraft:netherrack)
B(0,0,3,minecraft:netherrack)
B(0,1,3,minecraft:netherrack)
B(0,2,3,minecraft:netherrack)
B(0,0,4,minecraft:netherrack)
B(0,1,4,minecraft:netherrack)
B(0,2,4,minecraft:netherrack)
B(0,3,4,minecraft:netherrack)
B(0,4,4,minecraft:netherrack)
B(0,5,4,minecraft:netherrack)
B(0,6,4,minecraft:netherrack)
B(0,7,4,minecraft:netherrack)
B(0,8,4,minecraft:netherrack)
B(0,0,5,minecraft:netherrack)
B(0,1,5,minecraft:netherrack)
B(0,2,5,minecraft:netherrack)
B(0,3,5,minecraft:netherrack)
B(0,4,5,minecraft:netherrack)
B(0,5,5,minecraft:netherrack)
B(0,6,5,minecraft:netherrack)
B(0,7,5,minecraft:netherrack)
B(0,8,5,minecraft:netherrack)
B(0,9,5,minecraft:netherrack)
B(0,10,5,minecraft:netherrack)
B(0,0,6,minecraft:netherrack)
B(0,1,6,minecraft:netherrack)
B(0,2,6,minecraft:netherrack)
B(0,3,6,minecraft:netherrack)
B(0,4,6,minecraft:netherrack)
B(0,5,6,minecraft:netherrack)
B(0,6,6,minecraft:netherrack)
B(0,7,6,minecraft:netherrack)
B(0,8,6,minecraft:netherrack)
B(0,9,6,minecraft:netherrack)
B(0,10,6,minecraft:netherrack)
B(0,11,6,minecraft:netherrack)
B(0,12,6,minecraft:netherrack)
B(0,0,7,minecraft:netherrack)
B(0,1,7,minecraft:netherrack)
B(0,2,7,minecraft:netherrack)
B(0,3,7,minecraft:netherrack)
B(0,4,7,minecraft:netherrack)
B(0,5,7,minecraft:netherrack)
B(0,6,7,minecraft:netherrack)
B(0,7,7,minecraft:netherrack)
B(0,8,7,minecraft:netherrack)
B(0,9,7,minecraft:netherrack)
B(0,10,7,minecraft:netherrack)
B(0,11,7,minecraft:netherrack)
B(0,12,7,minecraft:netherrack)
B(0,13,7,minecraft:netherrack)
B(0,14,7,minecraft:netherrack)
B(0,0,8,minecraft:netherrack)
B(0,1,8,minecraft:netherrack)
B(0,2,8,minecraft:netherrack)
B(0,3,8,minecraft:netherrack)
B(0,4,8,minecraft:netherrack)
B(0,5,8,minecraft:netherrack)
B(0,6,8,minecraft:netherrack)
B(0,7,8,minecraft:netherrack)
B(0,8,8,minecraft:netherrack)
B(0,9,8,minecraft:netherrack)
B(0,10,8,minecraft:netherrack)
B(0,11,8,minecraft:netherrack)
B(0,12,8,minecraft:netherrack)
B(0,13,8,minecraft:netherrack)
B(0,14,8,minecraft:netherrack)
B(0,15,8,minecraft:netherrack)
B(1,0,-6,minecraft:netherrack)
B(1,0,-5,minecraft:netherrack)
B(1,1,-5,minecraft:netherrack)
B(1,2,-5,minecraft:netherrack)
B(1,0,-4,minecraft:netherrack)
B(1,1,-4,minecraft:netherrack)
B(1,2,-4,minecraft:netherrack)
B(1,3,-4,minecraft:netherrack)
B(1,0,-3,minecraft:netherrack)
B(1,1,-3,minecraft:netherrack)
B(1,2,-3,minecraft:netherrack)
B(1,3,-3,minecraft:netherrack)
B(1,0,-2,minecraft:netherrack)
B(1,1,-2,minecraft:netherrack)
B(1,2,-2,minecraft:netherrack)
B(1,3,-2,minecraft:netherrack)
B(1,4,-2,minecraft:netherrack)
B(1,0,-1,minecraft:netherrack)
B(1,1,-1,minecraft:netherrack)
B(1,2,-1,minecraft:netherrack)
B(1,3,-1,minecraft:netherrack)
B(1,4,-1,minecraft:netherrack)
B(1,0,0,minecraft:netherrack)
B(1,1,0,minecraft:netherrack)
B(1,2,0,minecraft:netherrack)
B(1,3,0,minecraft:netherrack)
B(1,4,0,minecraft:netherrack)
B(1,0,1,minecraft:netherrack)
B(1,1,1,minecraft:netherrack)
B(1,2,1,minecraft:netherrack)
B(1,3,1,minecraft:netherrack)
B(1,0,2,minecraft:netherrack)
B(1,1,2,minecraft:netherrack)
B(1,2,2,minecraft:netherrack)
B(1,3,2,minecraft:netherrack)
B(1,0,3,minecraft:netherrack)
B(1,1,3,minecraft:netherrack)
B(1,2,3,minecraft:netherrack)
B(1,0,4,minecraft:netherrack)
B(1,1,4,minecraft:netherrack)
B(1,2,4,minecraft:netherrack)
B(1,3,4,minecraft:netherrack)
B(1,4,4,minecraft:netherrack)
B(1,5,4,minecraft:netherrack)
B(1,6,4,minecraft:netherrack)
B(1,7,4,minecraft:netherrack)
B(1,0,5,minecraft:netherrack)
B(1,1,5,minecraft:netherrack)
B(1,2,5,minecraft:netherrack)
B(1,3,5,minecraft:netherrack)
B(1,4,5,minecraft:netherrack)
B(1,5,5,minecraft:netherrack)
B(1,6,5,minecraft:netherrack)
B(1,7,5,minecraft:netherrack)
B(1,8,5,minecraft:netherrack)
B(1,9,5,minecraft:netherrack)
B(1,10,5,minecraft:netherrack)
B(1,0,6,minecraft:netherrack)
B(1,1,6,minecraft:netherrack)
B(1,2,6,minecraft:netherrack)
B(1,3,6,minecraft:netherrack)
B(1,4,6,minecraft:netherrack)
B(1,5,6,minecraft:netherrack)
B(1,6,6,minecraft:netherrack)
B(1,7,6,minecraft:netherrack)
B(1,8,6,minecraft:netherrack)
B(1,9,6,minecraft:netherrack)
B(1,10,6,minecraft:netherrack)
B(1,11,6,minecraft:netherrack)
B(1,12,6,minecraft:netherrack)
B(1,0,7,minecraft:netherrack)
B(1,1,7,minecraft:netherrack)
B(1,2,7,minecraft:netherrack)
B(1,3,7,minecraft:netherrack)
B(1,4,7,minecraft:netherrack)
B(1,5,7,minecraft:netherrack)
B(1,6,7,minecraft:netherrack)
B(1,7,7,minecraft:netherrack)
B(1,8,7,minecraft:netherrack)
B(1,9,7,minecraft:netherrack)
B(1,10,7,minecraft:netherrack)
B(1,11,7,minecraft:netherrack)
B(1,12,7,minecraft:netherrack)
B(1,13,7,minecraft:netherrack)
B(1,0,8,minecraft:netherrack)
B(1,1,8,minecraft:netherrack)
B(1,2,8,minecraft:netherrack)
B(1,3,8,minecraft:netherrack)
B(1,4,8,minecraft:netherrack)
B(1,5,8,minecraft:netherrack)
B(1,6,8,minecraft:netherrack)
B(1,7,8,minecraft:netherrack)
B(1,8,8,minecraft:netherrack)
B(1,9,8,minecraft:netherrack)
B(1,10,8,minecraft:netherrack)
B(1,11,8,minecraft:netherrack)
B(1,12,8,minecraft:netherrack)
B(1,13,8,minecraft:netherrack)
B(1,14,8,minecraft:netherrack)
B(2,0,-7,minecraft:netherrack)
B(2,0,-5,minecraft:netherrack)
B(2,1,-5,minecraft:netherrack)
B(2,0,-4,minecraft:netherrack)
B(2,1,-4,minecraft:netherrack)
B(2,2,-4,minecraft:netherrack)
B(2,0,-3,minecraft:netherrack)
B(2,1,-3,minecraft:netherrack)
B(2,2,-3,minecraft:netherrack)
B(2,3,-3,minecraft:netherrack)
B(2,0,-2,minecraft:netherrack)
B(2,1,-2,minecraft:netherrack)
B(2,2,-2,minecraft:netherrack)
B(2,3,-2,minecraft:netherrack)
B(2,0,-1,minecraft:netherrack)
B(2,1,-1,minecraft:netherrack)
B(2,2,-1,minecraft:netherrack)
B(2,3,-1,minecraft:netherrack)
B(2,0,0,minecraft:netherrack)
B(2,1,0,minecraft:netherrack)
B(2,2,0,minecraft:netherrack)
B(2,3,0,minecraft:netherrack)
B(2,0,1,minecraft:netherrack)
B(2,1,1,minecraft:netherrack)
B(2,2,1,minecraft:netherrack)
B(2,3,1,minecraft:netherrack)
B(2,0,2,minecraft:netherrack)
B(2,1,2,minecraft:netherrack)
B(2,2,2,minecraft:netherrack)
B(2,3,2,minecraft:netherrack)
B(2,0,3,minecraft:netherrack)
B(2,1,3,minecraft:netherrack)
B(2,2,3,minecraft:netherrack)
B(2,3,3,minecraft:netherrack)
B(2,4,3,minecraft:netherrack)
B(2,0,4,minecraft:netherrack)
B(2,1,4,minecraft:netherrack)
B(2,2,4,minecraft:netherrack)
B(2,3,4,minecraft:netherrack)
B(2,4,4,minecraft:netherrack)
B(2,5,4,minecraft:netherrack)
B(2,0,5,minecraft:netherrack)
B(2,1,5,minecraft:netherrack)
B(2,2,5,minecraft:netherrack)
B(2,3,5,minecraft:netherrack)
B(2,4,5,minecraft:netherrack)
B(2,5,5,minecraft:netherrack)
B(2,6,5,minecraft:netherrack)
B(2,7,5,minecraft:netherrack)
B(2,8,5,minecraft:netherrack)
B(2,9,5,minecraft:netherrack)
B(2,0,6,minecraft:netherrack)
B(2,1,6,minecraft:netherrack)
B(2,2,6,minecraft:netherrack)
B(2,3,6,minecraft:netherrack)
B(2,4,6,minecraft:netherrack)
B(2,5,6,minecraft:netherrack)
B(2,6,6,minecraft:netherrack)
B(2,7,6,minecraft:netherrack)
B(2,8,6,minecraft:netherrack)
B(2,9,6,minecraft:netherrack)
B(2,10,6,minecraft:netherrack)
B(2,0,7,minecraft:netherrack)
B(2,1,7,minecraft:netherrack)
B(2,2,7,minecraft:netherrack)
B(2,3,7,minecraft:netherrack)
B(2,4,7,minecraft:netherrack)
B(2,5,7,minecraft:netherrack)
B(2,6,7,minecraft:netherrack)
B(2,7,7,minecraft:netherrack)
B(2,8,7,minecraft:netherrack)
B(2,9,7,minecraft:netherrack)
B(2,10,7,minecraft:netherrack)
B(2,11,7,minecraft:netherrack)
B(2,12,7,minecraft:netherrack)
B(2,0,8,minecraft:netherrack)
B(2,1,8,minecraft:netherrack)
B(2,2,8,minecraft:netherrack)
B(2,3,8,minecraft:netherrack)
B(2,4,8,minecraft:netherrack)
B(2,5,8,minecraft:netherrack)
B(2,6,8,minecraft:netherrack)
B(2,7,8,minecraft:netherrack)
B(2,8,8,minecraft:netherrack)
B(2,9,8,minecraft:netherrack)
B(2,10,8,minecraft:netherrack)
B(2,11,8,minecraft:netherrack)
B(2,12,8,minecraft:netherrack)
B(2,13,8,minecraft:netherrack)
B(3,0,-7,minecraft:netherrack)
B(3,0,-6,minecraft:netherrack)
B(3,0,-5,minecraft:netherrack)
B(3,0,-4,minecraft:netherrack)
B(3,1,-4,minecraft:netherrack)
B(3,0,-3,minecraft:netherrack)
B(3,1,-3,minecraft:netherrack)
B(3,0,-2,minecraft:netherrack)
B(3,1,-2,minecraft:netherrack)
B(3,2,-2,minecraft:netherrack)
B(3,0,-1,minecraft:netherrack)
B(3,1,-1,minecraft:netherrack)
B(3,2,-1,minecraft:netherrack)
B(3,0,0,minecraft:netherrack)
B(3,1,0,minecraft:netherrack)
B(3,2,0,minecraft:netherrack)
B(3,3,0,minecraft:netherrack)
B(3,0,1,minecraft:netherrack)
B(3,1,1,minecraft:netherrack)
B(3,2,1,minecraft:netherrack)
B(3,3,1,minecraft:netherrack)
B(3,0,2,minecraft:netherrack)
B(3,1,2,minecraft:netherrack)
B(3,2,2,minecraft:netherrack)
B(3,3,2,minecraft:netherrack)
B(3,4,2,minecraft:netherrack)
B(3,0,3,minecraft:netherrack)
B(3,1,3,minecraft:netherrack)
B(3,2,3,minecraft:netherrack)
B(3,3,3,minecraft:netherrack)
B(3,4,3,minecraft:netherrack)
B(3,5,3,minecraft:netherrack)
B(3,0,4,minecraft:netherrack)
B(3,1,4,minecraft:netherrack)
B(3,2,4,minecraft:netherrack)
B(3,3,4,minecraft:netherrack)
B(3,4,4,minecraft:netherrack)
B(3,5,4,minecraft:netherrack)
B(3,0,5,minecraft:netherrack)
B(3,1,5,minecraft:netherrack)
B(3,2,5,minecraft:netherrack)
B(3,3,5,minecraft:netherrack)
B(3,4,5,minecraft:netherrack)
B(3,5,5,minecraft:netherrack)
B(3,6,5,minecraft:netherrack)
B(3,7,5,minecraft:netherrack)
B(3,8,5,minecraft:netherrack)
B(3,0,6,minecraft:netherrack)
B(3,1,6,minecraft:netherrack)
B(3,2,6,minecraft:netherrack)
B(3,3,6,minecraft:netherrack)
B(3,4,6,minecraft:netherrack)
B(3,5,6,minecraft:netherrack)
B(3,6,6,minecraft:netherrack)
B(3,7,6,minecraft:netherrack)
B(3,8,6,minecraft:netherrack)
B(3,9,6,minecraft:netherrack)
B(3,0,7,minecraft:netherrack)
B(3,1,7,minecraft:netherrack)
B(3,2,7,minecraft:netherrack)
B(3,3,7,minecraft:netherrack)
B(3,4,7,minecraft:netherrack)
B(3,5,7,minecraft:netherrack)
B(3,6,7,minecraft:netherrack)
B(3,7,7,minecraft:netherrack)
B(3,8,7,minecraft:netherrack)
B(3,9,7,minecraft:netherrack)
B(3,10,7,minecraft:netherrack)
B(3,11,7,minecraft:netherrack)
B(3,0,8,minecraft:netherrack)
B(3,1,8,minecraft:netherrack)
B(3,2,8,minecraft:netherrack)
B(3,3,8,minecraft:netherrack)
B(3,4,8,minecraft:netherrack)
B(3,5,8,minecraft:netherrack)
B(3,6,8,minecraft:netherrack)
B(3,7,8,minecraft:netherrack)
B(3,8,8,minecraft:netherrack)
B(3,9,8,minecraft:netherrack)
B(3,10,8,minecraft:netherrack)
B(3,11,8,minecraft:netherrack)
B(3,12,8,minecraft:netherrack)
B(4,0,-7,minecraft:netherrack)
B(4,0,-6,minecraft:netherrack)
B(4,0,-5,minecraft:netherrack)
B(4,0,-4,minecraft:netherrack)
B(4,0,-3,minecraft:netherrack)
B(4,1,-3,minecraft:netherrack)
B(4,0,-2,minecraft:netherrack)
B(4,1,-2,minecraft:netherrack)
B(4,0,-1,minecraft:netherrack)
B(4,1,-1,minecraft:netherrack)
B(4,2,-1,minecraft:netherrack)
B(4,0,0,minecraft:netherrack)
B(4,1,0,minecraft:netherrack)
B(4,2,0,minecraft:netherrack)
B(4,3,0,minecraft:netherrack)
B(4,0,1,minecraft:netherrack)
B(4,1,1,minecraft:netherrack)
B(4,2,1,minecraft:netherrack)
B(4,3,1,minecraft:netherrack)
B(4,4,1,minecraft:netherrack)
B(4,0,2,minecraft:netherrack)
B(4,1,2,minecraft:netherrack)
B(4,2,2,minecraft:netherrack)
B(4,3,2,minecraft:netherrack)
B(4,4,2,minecraft:netherrack)
B(4,5,2,minecraft:netherrack)
B(4,0,3,minecraft:netherrack)
B(4,1,3,minecraft:netherrack)
B(4,2,3,minecraft:netherrack)
B(4,3,3,minecraft:netherrack)
B(4,4,3,minecraft:netherrack)
B(4,5,3,minecraft:netherrack)
B(4,0,4,minecraft:netherrack)
B(4,1,4,minecraft:netherrack)
B(4,2,4,minecraft:netherrack)
B(4,3,4,minecraft:netherrack)
B(4,4,4,minecraft:netherrack)
B(4,5,4,minecraft:netherrack)
B(4,6,4,minecraft:netherrack)
B(4,0,5,minecraft:netherrack)
B(4,1,5,minecraft:netherrack)
B(4,2,5,minecraft:netherrack)
B(4,3,5,minecraft:netherrack)
B(4,4,5,minecraft:netherrack)
B(4,5,5,minecraft:netherrack)
B(4,6,5,minecraft:netherrack)
B(4,7,5,minecraft:netherrack)
B(4,8,5,minecraft:netherrack)
B(4,0,6,minecraft:netherrack)
B(4,1,6,minecraft:netherrack)
B(4,2,6,minecraft:netherrack)
B(4,3,6,minecraft:netherrack)
B(4,4,6,minecraft:netherrack)
B(4,5,6,minecraft:netherrack)
B(4,6,6,minecraft:netherrack)
B(4,7,6,minecraft:netherrack)
B(4,8,6,minecraft:netherrack)
B(4,0,7,minecraft:netherrack)
B(4,1,7,minecraft:netherrack)
B(4,2,7,minecraft:netherrack)
B(4,3,7,minecraft:netherrack)
B(4,4,7,minecraft:netherrack)
B(4,5,7,minecraft:netherrack)
B(4,6,7,minecraft:netherrack)
B(4,7,7,minecraft:netherrack)
B(4,8,7,minecraft:netherrack)
B(4,9,7,minecraft:netherrack)
B(4,10,7,minecraft:netherrack)
B(4,11,7,minecraft:netherrack)
B(4,0,8,minecraft:netherrack)
B(4,1,8,minecraft:netherrack)
B(4,2,8,minecraft:netherrack)
B(4,3,8,minecraft:netherrack)
B(4,4,8,minecraft:netherrack)
B(4,5,8,minecraft:netherrack)
B(4,6,8,minecraft:netherrack)
B(4,7,8,minecraft:netherrack)
B(4,8,8,minecraft:netherrack)
B(4,9,8,minecraft:netherrack)
B(4,10,8,minecraft:netherrack)
B(4,11,8,minecraft:netherrack)
B(5,0,-7,minecraft:netherrack)
B(5,0,-6,minecraft:netherrack)
B(5,0,-5,minecraft:netherrack)
B(5,0,-4,minecraft:netherrack)
B(5,0,-3,minecraft:netherrack)
B(5,1,-3,minecraft:netherrack)
B(5,0,-2,minecraft:netherrack)
B(5,1,-2,minecraft:netherrack)
B(5,0,-1,minecraft:netherrack)
B(5,1,-1,minecraft:netherrack)
B(5,2,-1,minecraft:netherrack)
B(5,0,0,minecraft:netherrack)
B(5,1,0,minecraft:netherrack)
B(5,2,0,minecraft:netherrack)
B(5,3,0,minecraft:netherrack)
B(5,0,1,minecraft:netherrack)
B(5,1,1,minecraft:netherrack)
B(5,2,1,minecraft:netherrack)
B(5,3,1,minecraft:netherrack)
B(5,4,1,minecraft:netherrack)
B(5,0,2,minecraft:netherrack)
B(5,1,2,minecraft:netherrack)
B(5,2,2,minecraft:netherrack)
B(5,3,2,minecraft:netherrack)
B(5,4,2,minecraft:netherrack)
B(5,5,2,minecraft:netherrack)
B(5,0,3,minecraft:netherrack)
B(5,1,3,minecraft:netherrack)
B(5,2,3,minecraft:netherrack)
B(5,3,3,minecraft:netherrack)
B(5,4,3,minecraft:netherrack)
B(5,5,3,minecraft:netherrack)
B(5,0,4,minecraft:netherrack)
B(5,1,4,minecraft:netherrack)
B(5,2,4,minecraft:netherrack)
B(5,3,4,minecraft:netherrack)
B(5,4,4,minecraft:netherrack)
B(5,5,4,minecraft:netherrack)
B(5,6,4,minecraft:netherrack)
B(5,0,5,minecraft:netherrack)
B(5,1,5,minecraft:netherrack)
B(5,2,5,minecraft:netherrack)
B(5,3,5,minecraft:netherrack)
B(5,4,5,minecraft:netherrack)
B(5,5,5,minecraft:netherrack)
B(5,6,5,minecraft:netherrack)
B(5,7,5,minecraft:netherrack)
B(5,0,6,minecraft:netherrack)
B(5,1,6,minecraft:netherrack)
B(5,2,6,minecraft:netherrack)
B(5,3,6,minecraft:netherrack)
B(5,4,6,minecraft:netherrack)
B(5,5,6,minecraft:netherrack)
B(5,6,6,minecraft:netherrack)
B(5,7,6,minecraft:netherrack)
B(5,0,7,minecraft:netherrack)
B(5,1,7,minecraft:netherrack)
B(5,2,7,minecraft:netherrack)
B(5,3,7,minecraft:netherrack)
B(5,4,7,minecraft:netherrack)
B(5,5,7,minecraft:netherrack)
B(5,6,7,minecraft:netherrack)
B(5,7,7,minecraft:netherrack)
B(5,8,7,minecraft:netherrack)
B(5,0,8,minecraft:netherrack)
B(5,1,8,minecraft:netherrack)
B(5,2,8,minecraft:netherrack)
B(5,3,8,minecraft:netherrack)
B(5,4,8,minecraft:netherrack)
B(5,5,8,minecraft:netherrack)
B(5,6,8,minecraft:netherrack)
B(5,7,8,minecraft:netherrack)
B(5,8,8,minecraft:netherrack)
B(5,9,8,minecraft:netherrack)
B(5,10,8,minecraft:netherrack)
B(6,0,-7,minecraft:netherrack)
B(6,0,-6,minecraft:netherrack)
B(6,0,-5,minecraft:netherrack)
B(6,0,-4,minecraft:netherrack)
B(6,0,-3,minecraft:netherrack)
B(6,1,-3,minecraft:netherrack)
B(6,0,-2,minecraft:netherrack)
B(6,1,-2,minecraft:netherrack)
B(6,2,-2,minecraft:netherrack)
B(6,0,-1,minecraft:netherrack)
B(6,1,-1,minecraft:netherrack)
B(6,2,-1,minecraft:netherrack)
B(6,0,0,minecraft:netherrack)
B(6,1,0,minecraft:netherrack)
B(6,2,0,minecraft:netherrack)
B(6,3,0,minecraft:netherrack)
B(6,0,1,minecraft:netherrack)
B(6,1,1,minecraft:netherrack)
B(6,2,1,minecraft:netherrack)
B(6,3,1,minecraft:netherrack)
B(6,4,1,minecraft:netherrack)
B(6,0,2,minecraft:netherrack)
B(6,1,2,minecraft:netherrack)
B(6,2,2,minecraft:netherrack)
B(6,3,2,minecraft:netherrack)
B(6,4,2,minecraft:netherrack)
B(6,5,2,minecraft:netherrack)
B(6,0,3,minecraft:netherrack)
B(6,1,3,minecraft:netherrack)
B(6,2,3,minecraft:netherrack)
B(6,3,3,minecraft:netherrack)
B(6,4,3,minecraft:netherrack)
B(6,5,3,minecraft:netherrack)
B(6,0,4,minecraft:netherrack)
B(6,1,4,minecraft:netherrack)
B(6,2,4,minecraft:netherrack)
B(6,3,4,minecraft:netherrack)
B(6,4,4,minecraft:netherrack)
B(6,5,4,minecraft:netherrack)
B(6,0,5,minecraft:netherrack)
B(6,1,5,minecraft:netherrack)
B(6,2,5,minecraft:netherrack)
B(6,3,5,minecraft:netherrack)
B(6,4,5,minecraft:netherrack)
B(6,5,5,minecraft:netherrack)
B(6,6,5,minecraft:netherrack)
B(6,0,6,minecraft:netherrack)
B(6,1,6,minecraft:netherrack)
B(6,2,6,minecraft:netherrack)
B(6,3,6,minecraft:netherrack)
B(6,4,6,minecraft:netherrack)
B(6,5,6,minecraft:netherrack)
B(6,6,6,minecraft:netherrack)
B(6,7,6,minecraft:netherrack)
B(6,0,7,minecraft:netherrack)
B(6,1,7,minecraft:netherrack)
B(6,2,7,minecraft:netherrack)
B(6,3,7,minecraft:netherrack)
B(6,4,7,minecraft:netherrack)
B(6,5,7,minecraft:netherrack)
B(6,6,7,minecraft:netherrack)
B(6,7,7,minecraft:netherrack)
B(6,0,8,minecraft:netherrack)
B(6,1,8,minecraft:netherrack)
B(6,2,8,minecraft:netherrack)
B(6,3,8,minecraft:netherrack)
B(6,4,8,minecraft:netherrack)
B(6,5,8,minecraft:netherrack)
B(6,6,8,minecraft:netherrack)
B(6,7,8,minecraft:netherrack)
B(7,0,-7,minecraft:netherrack)
B(7,0,-6,minecraft:netherrack)
B(7,0,-5,minecraft:netherrack)
B(7,0,-4,minecraft:netherrack)
B(7,0,-3,minecraft:netherrack)
B(7,1,-3,minecraft:netherrack)
B(7,0,-2,minecraft:netherrack)
B(7,1,-2,minecraft:netherrack)
B(7,2,-2,minecraft:netherrack)
B(7,0,-1,minecraft:netherrack)
B(7,1,-1,minecraft:netherrack)
B(7,2,-1,minecraft:netherrack)
B(7,3,-1,minecraft:netherrack)
B(7,0,0,minecraft:netherrack)
B(7,1,0,minecraft:netherrack)
B(7,2,0,minecraft:netherrack)
B(7,3,0,minecraft:netherrack)
B(7,0,1,minecraft:netherrack)
B(7,1,1,minecraft:netherrack)
B(7,2,1,minecraft:netherrack)
B(7,3,1,minecraft:netherrack)
B(7,4,1,minecraft:netherrack)
B(7,0,2,minecraft:netherrack)
B(7,1,2,minecraft:netherrack)
B(7,2,2,minecraft:netherrack)
B(7,3,2,minecraft:netherrack)
B(7,4,2,minecraft:netherrack)
B(7,5,2,minecraft:netherrack)
B(7,0,3,minecraft:netherrack)
B(7,1,3,minecraft:netherrack)
B(7,2,3,minecraft:netherrack)
B(7,3,3,minecraft:netherrack)
B(7,4,3,minecraft:netherrack)
B(7,5,3,minecraft:netherrack)
B(7,0,4,minecraft:netherrack)
B(7,1,4,minecraft:netherrack)
B(7,2,4,minecraft:netherrack)
B(7,3,4,minecraft:netherrack)
B(7,4,4,minecraft:netherrack)
B(7,5,4,minecraft:netherrack)
B(7,0,5,minecraft:netherrack)
B(7,1,5,minecraft:netherrack)
B(7,2,5,minecraft:netherrack)
B(7,3,5,minecraft:netherrack)
B(7,4,5,minecraft:netherrack)
B(7,5,5,minecraft:netherrack)
B(7,6,5,minecraft:netherrack)
B(7,0,6,minecraft:netherrack)
B(7,1,6,minecraft:netherrack)
B(7,2,6,minecraft:netherrack)
B(7,3,6,minecraft:netherrack)
B(7,4,6,minecraft:netherrack)
B(7,5,6,minecraft:netherrack)
B(7,6,6,minecraft:netherrack)
B(7,0,7,minecraft:netherrack)
B(7,1,7,minecraft:netherrack)
B(7,2,7,minecraft:netherrack)
B(7,3,7,minecraft:netherrack)
B(7,4,7,minecraft:netherrack)
B(7,5,7,minecraft:netherrack)
B(7,6,7,minecraft:netherrack)
B(7,0,8,minecraft:netherrack)
B(7,1,8,minecraft:netherrack)
B(7,2,8,minecraft:netherrack)
B(7,3,8,minecraft:netherrack)
B(7,4,8,minecraft:netherrack)
B(7,5,8,minecraft:netherrack)
B(7,6,8,minecraft:netherrack)

#######################################################################
# +-----------------------------------------------------------------+ #
# |                             Branches                            | #
# +-----------------------------------------------------------------+ #
#######################################################################

Branch(16,0,0,true,GiantNetherrackStalacmite1_C2_R0,NORTH,100.0,0)

#######################################################################
# +-----------------------------------------------------------------+ #
# |                             Entities                            | #
# +-----------------------------------------------------------------+ #
#######################################################################

