
#######################################################################
# +-----------------------------------------------------------------+ #
# |                            BO4 object                           | #
# +-----------------------------------------------------------------+ #
#######################################################################

Author: Unknown

Description: No description given

SettingsMode: WriteWithoutComments


#######################################################################
# +-----------------------------------------------------------------+ #
# |                          Main settings                          | #
# +-----------------------------------------------------------------+ #
#######################################################################

FixedRotation: 

Frequency: 0

SpawnHeight: highestBlock

UseCenterForHighestBlock: true

##############################
# Height Limits for the BO4. #
##############################

MinHeight: 0

MaxHeight: 255

InheritBO3: 

InheritBO3Rotation: NORTH

OverrideChildSettings: true

OverrideParentHeight: false

CanOverride: false

BranchFrequency: 0

BranchFrequencyGroup: 

MustBeBelowOther: false

MustBeInside: 

CannotBeInside: 

ReplacesBO3: 

MustBeInsideWorldBorders: false

CanSpawnOnWater: true

SpawnOnWaterOnly: false

SpawnUnderWater: false

SpawnAtWaterLevel: false

HeightOffset: 0

RemoveAir: true

ReplaceAbove: 

ReplaceBelow: 

ReplaceWithBiomeBlocks: true

ReplaceWithSurfaceBlock: GRASS

ReplaceWithGroundBlock: DIRT

ReplaceWithStoneBlock: STONE

SmoothRadius: 0

SmoothHeightOffset: 0

SmoothStartTop: false

SmoothStartWood: false

SmoothingSurfaceBlock: 

SmoothingGroundBlock: 

BO3Group: 

IsSpawnPoint: false

DoReplaceBlocks: true


#######################################################################
# +-----------------------------------------------------------------+ #
# |                              Blocks                             | #
# +-----------------------------------------------------------------+ #
#######################################################################

B(-8,0,-7,minecraft:lava)
B(-8,1,-7,minecraft:lava)
B(-8,2,-7,minecraft:lava)
B(-8,3,-7,minecraft:lava)
B(-8,4,-7,minecraft:lava)
B(-8,5,-7,minecraft:lava)
B(-8,6,-7,minecraft:lava)
B(-8,7,-7,minecraft:lava)
B(-8,8,-7,minecraft:lava)
B(-8,9,-7,minecraft:lava)
B(-8,10,-7,minecraft:lava)
B(-8,11,-7,minecraft:lava)
B(-8,12,-7,minecraft:lava)
B(-8,13,-7,minecraft:lava)
B(-8,14,-7,minecraft:lava)
B(-8,15,-7,minecraft:lava)
B(-8,16,-7,minecraft:lava)
B(-8,17,-7,minecraft:lava)
B(-8,18,-7,minecraft:lava)
B(-8,19,-7,minecraft:lava)
B(-8,20,-7,minecraft:lava)
B(-8,21,-7,minecraft:lava)
B(-8,22,-7,minecraft:lava)
B(-8,23,-7,minecraft:lava)
B(-8,24,-7,minecraft:lava)
B(-8,25,-7,minecraft:lava)
B(-8,26,-7,minecraft:lava)
B(-8,27,-7,minecraft:lava)
B(-8,28,-7,minecraft:lava)
B(-8,29,-7,minecraft:lava)
B(-8,30,-7,minecraft:lava)
B(-8,31,-7,minecraft:lava)
B(-8,32,-7,minecraft:lava)
B(-8,33,-7,minecraft:lava)
B(-8,34,-7,minecraft:lava)
B(-8,35,-7,minecraft:lava)
B(-8,36,-7,minecraft:lava)
B(-8,37,-7,minecraft:lava)
B(-8,38,-7,minecraft:lava[level=8])
B(-8,39,-7,minecraft:lava[level=2])
B(-8,0,-6,minecraft:lava)
B(-8,1,-6,minecraft:lava)
B(-8,2,-6,minecraft:lava)
B(-8,3,-6,minecraft:lava)
B(-8,4,-6,minecraft:lava)
B(-8,5,-6,minecraft:lava)
B(-8,6,-6,minecraft:lava)
B(-8,7,-6,minecraft:lava)
B(-8,8,-6,minecraft:lava)
B(-8,9,-6,minecraft:lava)
B(-8,10,-6,minecraft:lava)
B(-8,11,-6,minecraft:lava)
B(-8,12,-6,minecraft:lava)
B(-8,13,-6,minecraft:lava)
B(-8,14,-6,minecraft:lava)
B(-8,15,-6,minecraft:lava)
B(-8,16,-6,minecraft:lava)
B(-8,17,-6,minecraft:lava)
B(-8,18,-6,minecraft:lava)
B(-8,19,-6,minecraft:lava)
B(-8,20,-6,minecraft:lava)
B(-8,21,-6,minecraft:lava)
B(-8,22,-6,minecraft:lava)
B(-8,23,-6,minecraft:lava)
B(-8,24,-6,minecraft:lava)
B(-8,25,-6,minecraft:lava)
B(-8,26,-6,minecraft:lava)
B(-8,27,-6,minecraft:lava)
B(-8,28,-6,minecraft:lava)
B(-8,29,-6,minecraft:lava)
B(-8,30,-6,minecraft:lava)
B(-8,31,-6,minecraft:lava)
B(-8,32,-6,minecraft:lava)
B(-8,33,-6,minecraft:lava)
B(-8,34,-6,minecraft:lava)
B(-8,35,-6,minecraft:lava)
B(-8,36,-6,minecraft:lava)
B(-8,37,-6,minecraft:lava[level=2])
B(-8,0,-5,minecraft:lava)
B(-8,1,-5,minecraft:lava)
B(-8,2,-5,minecraft:lava)
B(-8,3,-5,minecraft:lava)
B(-8,4,-5,minecraft:lava)
B(-8,5,-5,minecraft:lava)
B(-8,6,-5,minecraft:lava)
B(-8,7,-5,minecraft:lava)
B(-8,8,-5,minecraft:lava)
B(-8,9,-5,minecraft:lava)
B(-8,10,-5,minecraft:lava)
B(-8,11,-5,minecraft:lava)
B(-8,12,-5,minecraft:lava)
B(-8,13,-5,minecraft:lava)
B(-8,14,-5,minecraft:lava)
B(-8,15,-5,minecraft:lava)
B(-8,16,-5,minecraft:lava)
B(-8,17,-5,minecraft:lava)
B(-8,18,-5,minecraft:lava)
B(-8,19,-5,minecraft:lava)
B(-8,20,-5,minecraft:lava)
B(-8,21,-5,minecraft:lava)
B(-8,22,-5,minecraft:lava)
B(-8,23,-5,minecraft:lava)
B(-8,24,-5,minecraft:lava)
B(-8,25,-5,minecraft:lava)
B(-8,26,-5,minecraft:lava)
B(-8,27,-5,minecraft:lava)
B(-8,28,-5,minecraft:lava)
B(-8,29,-5,minecraft:lava[level=8])
B(-8,30,-5,minecraft:lava[level=8])
B(-8,31,-5,minecraft:lava[level=8])
B(-8,32,-5,minecraft:lava[level=8])
B(-8,33,-5,minecraft:lava[level=8])
B(-8,34,-5,minecraft:lava[level=8])
B(-8,35,-5,minecraft:lava[level=8])
B(-8,36,-5,minecraft:lava[level=2])
B(-8,0,-4,minecraft:lava)
B(-8,1,-4,minecraft:lava)
B(-8,2,-4,minecraft:lava)
B(-8,3,-4,minecraft:lava)
B(-8,4,-4,minecraft:lava)
B(-8,5,-4,minecraft:lava)
B(-8,6,-4,minecraft:lava)
B(-8,7,-4,minecraft:lava)
B(-8,8,-4,minecraft:lava)
B(-8,9,-4,minecraft:lava)
B(-8,10,-4,minecraft:lava)
B(-8,11,-4,minecraft:lava)
B(-8,12,-4,minecraft:lava)
B(-8,13,-4,minecraft:lava)
B(-8,14,-4,minecraft:lava)
B(-8,15,-4,minecraft:lava)
B(-8,16,-4,minecraft:lava)
B(-8,17,-4,minecraft:lava)
B(-8,18,-4,minecraft:lava[level=8])
B(-8,19,-4,minecraft:lava[level=8])
B(-8,20,-4,minecraft:lava[level=8])
B(-8,21,-4,minecraft:lava[level=8])
B(-8,22,-4,minecraft:lava[level=8])
B(-8,23,-4,minecraft:lava[level=8])
B(-8,24,-4,minecraft:lava[level=8])
B(-8,25,-4,minecraft:lava[level=8])
B(-8,26,-4,minecraft:lava[level=8])
B(-8,27,-4,minecraft:lava[level=8])
B(-8,28,-4,minecraft:lava[level=8])
B(-8,29,-4,minecraft:lava[level=8])
B(-8,30,-4,minecraft:lava[level=8])
B(-8,31,-4,minecraft:lava[level=8])
B(-8,32,-4,minecraft:lava[level=8])
B(-8,33,-4,minecraft:lava[level=8])
B(-8,34,-4,minecraft:lava[level=8])
B(-8,35,-4,minecraft:lava[level=2])
B(-8,0,-3,minecraft:lava)
B(-8,1,-3,minecraft:lava)
B(-8,2,-3,minecraft:lava)
B(-8,3,-3,minecraft:lava)
B(-8,4,-3,minecraft:lava)
B(-8,5,-3,minecraft:lava)
B(-8,6,-3,minecraft:lava)
B(-8,7,-3,minecraft:lava)
B(-8,8,-3,minecraft:lava[level=8])
B(-8,9,-3,minecraft:lava[level=8])
B(-8,10,-3,minecraft:lava[level=8])
B(-8,11,-3,minecraft:lava[level=8])
B(-8,12,-3,minecraft:lava[level=8])
B(-8,13,-3,minecraft:lava[level=8])
B(-8,14,-3,minecraft:lava[level=8])
B(-8,15,-3,minecraft:lava[level=8])
B(-8,16,-3,minecraft:lava[level=8])
B(-8,17,-3,minecraft:lava[level=2])
B(-8,0,-2,minecraft:lava)
B(-8,1,-2,minecraft:lava)
B(-8,2,-2,minecraft:lava)
B(-8,3,-2,minecraft:lava[level=8])
B(-8,4,-2,minecraft:lava[level=8])
B(-8,5,-2,minecraft:lava[level=8])
B(-8,6,-2,minecraft:lava[level=8])
B(-8,7,-2,minecraft:lava[level=2])
B(-8,0,-1,minecraft:lava)
B(-8,1,-1,minecraft:lava)
B(-8,2,-1,minecraft:lava)
B(-8,3,-1,minecraft:lava[level=2])
B(-8,0,0,minecraft:lava)
B(-8,1,0,minecraft:lava)
B(-8,2,0,minecraft:lava)
B(-8,3,0,minecraft:lava[level=2])
B(-8,0,1,minecraft:lava)
B(-8,1,1,minecraft:lava)
B(-8,2,1,minecraft:lava)
B(-8,0,2,minecraft:lava)
B(-8,1,2,minecraft:lava)
B(-8,2,2,minecraft:lava)
B(-8,0,3,minecraft:lava)
B(-8,1,3,minecraft:lava)
B(-8,2,3,minecraft:lava)
B(-8,3,3,minecraft:lava[level=2])
B(-8,0,4,minecraft:lava)
B(-8,1,4,minecraft:lava)
B(-8,2,4,minecraft:lava[level=8])
B(-8,3,4,minecraft:lava[level=2])
B(-8,0,5,minecraft:lava)
B(-8,1,5,minecraft:lava)
B(-8,2,5,minecraft:lava[level=2])
B(-8,0,6,minecraft:lava)
B(-8,1,6,minecraft:lava)
B(-8,2,6,minecraft:lava[level=2])
B(-8,0,7,minecraft:lava)
B(-8,1,7,minecraft:lava[level=8])
B(-8,2,7,minecraft:lava[level=2])
B(-8,0,8,minecraft:lava)
B(-8,1,8,minecraft:lava[level=2])
B(-7,0,-7,minecraft:lava)
B(-7,1,-7,minecraft:lava)
B(-7,2,-7,minecraft:lava)
B(-7,3,-7,minecraft:lava)
B(-7,4,-7,minecraft:lava)
B(-7,5,-7,minecraft:lava)
B(-7,6,-7,minecraft:lava)
B(-7,7,-7,minecraft:lava)
B(-7,8,-7,minecraft:lava)
B(-7,9,-7,minecraft:lava)
B(-7,10,-7,minecraft:lava)
B(-7,11,-7,minecraft:lava)
B(-7,12,-7,minecraft:lava)
B(-7,13,-7,minecraft:lava)
B(-7,14,-7,minecraft:lava)
B(-7,15,-7,minecraft:lava)
B(-7,16,-7,minecraft:lava)
B(-7,17,-7,minecraft:lava)
B(-7,18,-7,minecraft:lava)
B(-7,19,-7,minecraft:lava)
B(-7,20,-7,minecraft:lava)
B(-7,21,-7,minecraft:lava)
B(-7,22,-7,minecraft:lava)
B(-7,23,-7,minecraft:lava)
B(-7,24,-7,minecraft:lava)
B(-7,25,-7,minecraft:lava)
B(-7,26,-7,minecraft:lava)
B(-7,27,-7,minecraft:lava)
B(-7,28,-7,minecraft:lava)
B(-7,29,-7,minecraft:lava)
B(-7,30,-7,minecraft:lava)
B(-7,31,-7,minecraft:lava[level=8])
B(-7,32,-7,minecraft:lava[level=8])
B(-7,33,-7,minecraft:lava[level=8])
B(-7,34,-7,minecraft:lava[level=8])
B(-7,35,-7,minecraft:lava[level=8])
B(-7,36,-7,minecraft:lava[level=8])
B(-7,37,-7,minecraft:lava[level=2])
B(-7,0,-6,minecraft:lava)
B(-7,1,-6,minecraft:lava)
B(-7,2,-6,minecraft:lava)
B(-7,3,-6,minecraft:lava)
B(-7,4,-6,minecraft:lava)
B(-7,5,-6,minecraft:lava)
B(-7,6,-6,minecraft:lava)
B(-7,7,-6,minecraft:lava)
B(-7,8,-6,minecraft:lava)
B(-7,9,-6,minecraft:lava)
B(-7,10,-6,minecraft:lava)
B(-7,11,-6,minecraft:lava)
B(-7,12,-6,minecraft:lava)
B(-7,13,-6,minecraft:lava)
B(-7,14,-6,minecraft:lava)
B(-7,15,-6,minecraft:lava)
B(-7,16,-6,minecraft:lava)
B(-7,17,-6,minecraft:lava)
B(-7,18,-6,minecraft:lava)
B(-7,19,-6,minecraft:lava)
B(-7,20,-6,minecraft:lava)
B(-7,21,-6,minecraft:lava)
B(-7,22,-6,minecraft:lava)
B(-7,23,-6,minecraft:lava[level=8])
B(-7,24,-6,minecraft:lava[level=8])
B(-7,25,-6,minecraft:lava[level=8])
B(-7,26,-6,minecraft:lava[level=8])
B(-7,27,-6,minecraft:lava[level=8])
B(-7,28,-6,minecraft:lava[level=8])
B(-7,29,-6,minecraft:lava[level=8])
B(-7,30,-6,minecraft:lava[level=8])
B(-7,31,-6,minecraft:lava[level=8])
B(-7,32,-6,minecraft:lava[level=8])
B(-7,33,-6,minecraft:lava[level=8])
B(-7,34,-6,minecraft:lava[level=8])
B(-7,35,-6,minecraft:lava[level=8])
B(-7,36,-6,minecraft:lava[level=2])
B(-7,0,-5,minecraft:lava)
B(-7,1,-5,minecraft:lava)
B(-7,2,-5,minecraft:lava)
B(-7,3,-5,minecraft:lava)
B(-7,4,-5,minecraft:lava)
B(-7,5,-5,minecraft:lava)
B(-7,6,-5,minecraft:lava)
B(-7,7,-5,minecraft:lava)
B(-7,8,-5,minecraft:lava)
B(-7,9,-5,minecraft:lava)
B(-7,10,-5,minecraft:lava)
B(-7,11,-5,minecraft:lava)
B(-7,12,-5,minecraft:lava)
B(-7,13,-5,minecraft:lava)
B(-7,14,-5,minecraft:lava)
B(-7,15,-5,minecraft:lava)
B(-7,16,-5,minecraft:lava)
B(-7,17,-5,minecraft:lava)
B(-7,18,-5,minecraft:lava[level=8])
B(-7,19,-5,minecraft:lava[level=8])
B(-7,20,-5,minecraft:lava[level=8])
B(-7,21,-5,minecraft:lava[level=8])
B(-7,22,-5,minecraft:lava[level=8])
B(-7,23,-5,minecraft:lava[level=8])
B(-7,24,-5,minecraft:lava[level=8])
B(-7,25,-5,minecraft:lava[level=8])
B(-7,26,-5,minecraft:lava[level=8])
B(-7,27,-5,minecraft:lava[level=8])
B(-7,28,-5,minecraft:lava[level=2])
B(-7,0,-4,minecraft:lava)
B(-7,1,-4,minecraft:lava)
B(-7,2,-4,minecraft:lava)
B(-7,3,-4,minecraft:lava)
B(-7,4,-4,minecraft:lava)
B(-7,5,-4,minecraft:lava)
B(-7,6,-4,minecraft:lava)
B(-7,7,-4,minecraft:lava)
B(-7,8,-4,minecraft:lava)
B(-7,9,-4,minecraft:lava)
B(-7,10,-4,minecraft:lava)
B(-7,11,-4,minecraft:lava)
B(-7,12,-4,minecraft:lava)
B(-7,13,-4,minecraft:lava)
B(-7,14,-4,minecraft:lava)
B(-7,15,-4,minecraft:lava[level=8])
B(-7,16,-4,minecraft:lava[level=8])
B(-7,17,-4,minecraft:lava[level=2])
B(-7,0,-3,minecraft:lava)
B(-7,1,-3,minecraft:lava)
B(-7,2,-3,minecraft:lava)
B(-7,3,-3,minecraft:lava)
B(-7,4,-3,minecraft:lava)
B(-7,5,-3,minecraft:lava)
B(-7,6,-3,minecraft:lava[level=8])
B(-7,7,-3,minecraft:lava[level=8])
B(-7,8,-3,minecraft:lava[level=8])
B(-7,9,-3,minecraft:lava[level=8])
B(-7,10,-3,minecraft:lava[level=8])
B(-7,11,-3,minecraft:lava[level=8])
B(-7,12,-3,minecraft:lava[level=8])
B(-7,13,-3,minecraft:lava[level=8])
B(-7,14,-3,minecraft:lava[level=2])
B(-7,0,-2,minecraft:lava)
B(-7,1,-2,minecraft:lava)
B(-7,2,-2,minecraft:lava)
B(-7,3,-2,minecraft:lava)
B(-7,4,-2,minecraft:lava[level=8])
B(-7,5,-2,minecraft:lava[level=2])
B(-7,0,-1,minecraft:lava)
B(-7,1,-1,minecraft:lava)
B(-7,2,-1,minecraft:lava)
B(-7,3,-1,minecraft:lava)
B(-7,0,0,minecraft:lava)
B(-7,1,0,minecraft:lava)
B(-7,2,0,minecraft:lava)
B(-7,3,0,minecraft:lava)
B(-7,0,1,minecraft:lava)
B(-7,1,1,minecraft:lava)
B(-7,2,1,minecraft:lava)
B(-7,3,1,minecraft:lava[level=2])
B(-7,0,2,minecraft:lava)
B(-7,1,2,minecraft:lava)
B(-7,2,2,minecraft:lava)
B(-7,0,3,minecraft:lava)
B(-7,1,3,minecraft:lava)
B(-7,2,3,minecraft:lava[level=2])
B(-7,0,4,minecraft:lava)
B(-7,1,4,minecraft:lava)
B(-7,0,5,minecraft:lava)
B(-7,1,5,minecraft:lava[level=2])
B(-7,0,6,minecraft:lava)
B(-7,1,6,minecraft:lava[level=2])
B(-7,0,7,minecraft:lava)
B(-7,0,8,minecraft:lava)
B(-6,0,-7,minecraft:lava)
B(-6,1,-7,minecraft:lava)
B(-6,2,-7,minecraft:lava)
B(-6,3,-7,minecraft:lava)
B(-6,4,-7,minecraft:lava)
B(-6,5,-7,minecraft:lava)
B(-6,6,-7,minecraft:lava)
B(-6,7,-7,minecraft:lava)
B(-6,8,-7,minecraft:lava)
B(-6,9,-7,minecraft:lava)
B(-6,10,-7,minecraft:lava)
B(-6,11,-7,minecraft:lava)
B(-6,12,-7,minecraft:lava)
B(-6,13,-7,minecraft:lava)
B(-6,14,-7,minecraft:lava)
B(-6,15,-7,minecraft:lava)
B(-6,16,-7,minecraft:lava)
B(-6,17,-7,minecraft:lava)
B(-6,18,-7,minecraft:lava)
B(-6,19,-7,minecraft:lava)
B(-6,20,-7,minecraft:lava)
B(-6,21,-7,minecraft:lava)
B(-6,22,-7,minecraft:lava)
B(-6,23,-7,minecraft:lava)
B(-6,24,-7,minecraft:lava)
B(-6,25,-7,minecraft:lava)
B(-6,26,-7,minecraft:lava)
B(-6,27,-7,minecraft:lava)
B(-6,28,-7,minecraft:lava)
B(-6,29,-7,minecraft:lava[level=8])
B(-6,30,-7,minecraft:lava[level=8])
B(-6,31,-7,minecraft:lava[level=2])
B(-6,0,-6,minecraft:lava)
B(-6,1,-6,minecraft:lava)
B(-6,2,-6,minecraft:lava)
B(-6,3,-6,minecraft:lava)
B(-6,4,-6,minecraft:lava)
B(-6,5,-6,minecraft:lava)
B(-6,6,-6,minecraft:lava)
B(-6,7,-6,minecraft:lava)
B(-6,8,-6,minecraft:lava)
B(-6,9,-6,minecraft:lava)
B(-6,10,-6,minecraft:lava)
B(-6,11,-6,minecraft:lava)
B(-6,12,-6,minecraft:lava)
B(-6,13,-6,minecraft:lava)
B(-6,14,-6,minecraft:lava)
B(-6,15,-6,minecraft:lava)
B(-6,16,-6,minecraft:lava)
B(-6,17,-6,minecraft:lava)
B(-6,18,-6,minecraft:lava)
B(-6,19,-6,minecraft:lava)
B(-6,20,-6,minecraft:lava)
B(-6,21,-6,minecraft:lava)
B(-6,22,-6,minecraft:lava[level=8])
B(-6,23,-6,minecraft:lava[level=8])
B(-6,24,-6,minecraft:lava[level=8])
B(-6,25,-6,minecraft:lava[level=8])
B(-6,26,-6,minecraft:lava[level=8])
B(-6,27,-6,minecraft:lava[level=8])
B(-6,28,-6,minecraft:lava[level=2])
B(-6,0,-5,minecraft:lava)
B(-6,1,-5,minecraft:lava)
B(-6,2,-5,minecraft:lava)
B(-6,3,-5,minecraft:lava)
B(-6,4,-5,minecraft:lava)
B(-6,5,-5,minecraft:lava)
B(-6,6,-5,minecraft:lava)
B(-6,7,-5,minecraft:lava)
B(-6,8,-5,minecraft:lava)
B(-6,9,-5,minecraft:lava)
B(-6,10,-5,minecraft:lava)
B(-6,11,-5,minecraft:lava)
B(-6,12,-5,minecraft:lava)
B(-6,13,-5,minecraft:lava)
B(-6,14,-5,minecraft:lava)
B(-6,15,-5,minecraft:lava)
B(-6,16,-5,minecraft:lava[level=8])
B(-6,17,-5,minecraft:lava[level=8])
B(-6,18,-5,minecraft:lava[level=8])
B(-6,19,-5,minecraft:lava[level=8])
B(-6,20,-5,minecraft:lava[level=8])
B(-6,21,-5,minecraft:lava[level=2])
B(-6,0,-4,minecraft:lava)
B(-6,1,-4,minecraft:lava)
B(-6,2,-4,minecraft:lava)
B(-6,3,-4,minecraft:lava)
B(-6,4,-4,minecraft:lava)
B(-6,5,-4,minecraft:lava)
B(-6,6,-4,minecraft:lava)
B(-6,7,-4,minecraft:lava)
B(-6,8,-4,minecraft:lava)
B(-6,9,-4,minecraft:lava)
B(-6,10,-4,minecraft:lava)
B(-6,11,-4,minecraft:lava[level=8])
B(-6,12,-4,minecraft:lava[level=8])
B(-6,13,-4,minecraft:lava[level=8])
B(-6,14,-4,minecraft:lava[level=8])
B(-6,15,-4,minecraft:lava[level=2])
B(-6,0,-3,minecraft:lava)
B(-6,1,-3,minecraft:lava)
B(-6,2,-3,minecraft:lava)
B(-6,3,-3,minecraft:lava)
B(-6,4,-3,minecraft:lava[level=8])
B(-6,5,-3,minecraft:lava[level=8])
B(-6,6,-3,minecraft:lava[level=8])
B(-6,7,-3,minecraft:lava[level=8])
B(-6,8,-3,minecraft:lava[level=8])
B(-6,9,-3,minecraft:lava[level=8])
B(-6,10,-3,minecraft:lava[level=2])
B(-6,0,-2,minecraft:lava)
B(-6,1,-2,minecraft:lava)
B(-6,2,-2,minecraft:lava)
B(-6,3,-2,minecraft:lava)
B(-6,0,-1,minecraft:lava)
B(-6,1,-1,minecraft:lava)
B(-6,2,-1,minecraft:lava)
B(-6,3,-1,minecraft:lava)
B(-6,0,0,minecraft:lava)
B(-6,1,0,minecraft:lava)
B(-6,2,0,minecraft:lava)
B(-6,3,0,minecraft:lava)
B(-6,0,1,minecraft:lava)
B(-6,1,1,minecraft:lava)
B(-6,2,1,minecraft:lava)
B(-6,3,1,minecraft:lava[level=2])
B(-6,0,2,minecraft:lava)
B(-6,1,2,minecraft:lava)
B(-6,2,2,minecraft:lava)
B(-6,0,3,minecraft:lava)
B(-6,1,3,minecraft:lava)
B(-6,2,3,minecraft:lava[level=2])
B(-6,0,4,minecraft:lava)
B(-6,1,4,minecraft:lava[level=2])
B(-6,0,5,minecraft:lava)
B(-6,0,6,minecraft:lava[level=2])
B(-6,0,7,minecraft:lava[level=2])
B(-6,0,8,minecraft:lava[level=2])
B(-5,0,-7,minecraft:lava)
B(-5,1,-7,minecraft:lava)
B(-5,2,-7,minecraft:lava)
B(-5,3,-7,minecraft:lava)
B(-5,4,-7,minecraft:lava)
B(-5,5,-7,minecraft:lava)
B(-5,6,-7,minecraft:lava)
B(-5,7,-7,minecraft:lava)
B(-5,8,-7,minecraft:lava)
B(-5,9,-7,minecraft:lava)
B(-5,10,-7,minecraft:lava)
B(-5,11,-7,minecraft:lava)
B(-5,12,-7,minecraft:lava)
B(-5,13,-7,minecraft:lava)
B(-5,14,-7,minecraft:lava)
B(-5,15,-7,minecraft:lava)
B(-5,16,-7,minecraft:lava)
B(-5,17,-7,minecraft:lava)
B(-5,18,-7,minecraft:lava)
B(-5,19,-7,minecraft:lava)
B(-5,20,-7,minecraft:lava)
B(-5,21,-7,minecraft:lava)
B(-5,22,-7,minecraft:lava)
B(-5,23,-7,minecraft:lava)
B(-5,24,-7,minecraft:lava)
B(-5,25,-7,minecraft:lava)
B(-5,26,-7,minecraft:lava[level=8])
B(-5,27,-7,minecraft:lava[level=8])
B(-5,28,-7,minecraft:lava[level=2])
B(-5,0,-6,minecraft:lava)
B(-5,1,-6,minecraft:lava)
B(-5,2,-6,minecraft:lava)
B(-5,3,-6,minecraft:lava)
B(-5,4,-6,minecraft:lava)
B(-5,5,-6,minecraft:lava)
B(-5,6,-6,minecraft:lava)
B(-5,7,-6,minecraft:lava)
B(-5,8,-6,minecraft:lava)
B(-5,9,-6,minecraft:lava)
B(-5,10,-6,minecraft:lava)
B(-5,11,-6,minecraft:lava)
B(-5,12,-6,minecraft:lava)
B(-5,13,-6,minecraft:lava)
B(-5,14,-6,minecraft:lava)
B(-5,15,-6,minecraft:lava)
B(-5,16,-6,minecraft:lava)
B(-5,17,-6,minecraft:lava[level=8])
B(-5,18,-6,minecraft:lava[level=8])
B(-5,19,-6,minecraft:lava[level=8])
B(-5,20,-6,minecraft:lava[level=8])
B(-5,21,-6,minecraft:lava[level=8])
B(-5,22,-6,minecraft:lava[level=8])
B(-5,23,-6,minecraft:lava[level=8])
B(-5,24,-6,minecraft:lava[level=8])
B(-5,25,-6,minecraft:lava[level=2])
B(-5,0,-5,minecraft:lava)
B(-5,1,-5,minecraft:lava)
B(-5,2,-5,minecraft:lava)
B(-5,3,-5,minecraft:lava)
B(-5,4,-5,minecraft:lava)
B(-5,5,-5,minecraft:lava)
B(-5,6,-5,minecraft:lava)
B(-5,7,-5,minecraft:lava)
B(-5,8,-5,minecraft:lava)
B(-5,9,-5,minecraft:lava)
B(-5,10,-5,minecraft:lava)
B(-5,11,-5,minecraft:lava)
B(-5,12,-5,minecraft:lava[level=8])
B(-5,13,-5,minecraft:lava[level=8])
B(-5,14,-5,minecraft:lava[level=8])
B(-5,15,-5,minecraft:lava[level=8])
B(-5,16,-5,minecraft:lava[level=2])
B(-5,0,-4,minecraft:lava)
B(-5,1,-4,minecraft:lava)
B(-5,2,-4,minecraft:lava)
B(-5,3,-4,minecraft:lava[level=8])
B(-5,4,-4,minecraft:lava[level=8])
B(-5,5,-4,minecraft:lava[level=8])
B(-5,6,-4,minecraft:lava[level=8])
B(-5,7,-4,minecraft:lava[level=8])
B(-5,8,-4,minecraft:lava[level=8])
B(-5,9,-4,minecraft:lava[level=8])
B(-5,10,-4,minecraft:lava[level=8])
B(-5,11,-4,minecraft:lava[level=2])
B(-5,0,-3,minecraft:lava)
B(-5,1,-3,minecraft:lava)
B(-5,2,-3,minecraft:lava)
B(-5,3,-3,minecraft:lava)
B(-5,0,-2,minecraft:lava)
B(-5,1,-2,minecraft:lava)
B(-5,2,-2,minecraft:lava)
B(-5,3,-2,minecraft:lava)
B(-5,0,-1,minecraft:lava)
B(-5,1,-1,minecraft:lava)
B(-5,2,-1,minecraft:lava)
B(-5,3,-1,minecraft:lava)
B(-5,0,0,minecraft:lava)
B(-5,1,0,minecraft:lava)
B(-5,2,0,minecraft:lava)
B(-5,3,0,minecraft:lava[level=2])
B(-5,0,1,minecraft:lava)
B(-5,1,1,minecraft:lava)
B(-5,2,1,minecraft:lava)
B(-5,0,2,minecraft:lava)
B(-5,1,2,minecraft:lava)
B(-5,2,2,minecraft:lava[level=2])
B(-5,0,3,minecraft:lava)
B(-5,1,3,minecraft:lava[level=2])
B(-5,0,4,minecraft:lava[level=2])
B(-5,0,5,minecraft:lava[level=2])
B(-5,0,6,minecraft:lava[level=4])
B(-5,0,7,minecraft:lava[level=4])
B(-5,0,8,minecraft:lava[level=4])
B(-4,0,-7,minecraft:lava)
B(-4,1,-7,minecraft:lava)
B(-4,2,-7,minecraft:lava)
B(-4,3,-7,minecraft:lava)
B(-4,4,-7,minecraft:lava)
B(-4,5,-7,minecraft:lava)
B(-4,6,-7,minecraft:lava)
B(-4,7,-7,minecraft:lava)
B(-4,8,-7,minecraft:lava)
B(-4,9,-7,minecraft:lava)
B(-4,10,-7,minecraft:lava)
B(-4,11,-7,minecraft:lava)
B(-4,12,-7,minecraft:lava)
B(-4,13,-7,minecraft:lava)
B(-4,14,-7,minecraft:lava)
B(-4,15,-7,minecraft:lava)
B(-4,16,-7,minecraft:lava[level=8])
B(-4,17,-7,minecraft:lava[level=8])
B(-4,18,-7,minecraft:lava[level=8])
B(-4,19,-7,minecraft:lava[level=8])
B(-4,20,-7,minecraft:lava[level=8])
B(-4,21,-7,minecraft:lava[level=8])
B(-4,22,-7,minecraft:lava[level=8])
B(-4,23,-7,minecraft:lava[level=8])
B(-4,24,-7,minecraft:lava[level=8])
B(-4,25,-7,minecraft:lava[level=2])
B(-4,0,-6,minecraft:lava)
B(-4,1,-6,minecraft:lava)
B(-4,2,-6,minecraft:lava)
B(-4,3,-6,minecraft:lava)
B(-4,4,-6,minecraft:lava)
B(-4,5,-6,minecraft:lava)
B(-4,6,-6,minecraft:lava)
B(-4,7,-6,minecraft:lava)
B(-4,8,-6,minecraft:lava)
B(-4,9,-6,minecraft:lava)
B(-4,10,-6,minecraft:lava)
B(-4,11,-6,minecraft:lava[level=8])
B(-4,12,-6,minecraft:lava[level=8])
B(-4,13,-6,minecraft:lava[level=8])
B(-4,14,-6,minecraft:lava[level=8])
B(-4,15,-6,minecraft:lava[level=8])
B(-4,16,-6,minecraft:lava[level=2])
B(-4,0,-5,minecraft:lava)
B(-4,1,-5,minecraft:lava)
B(-4,2,-5,minecraft:lava[level=8])
B(-4,3,-5,minecraft:lava[level=8])
B(-4,4,-5,minecraft:lava[level=8])
B(-4,5,-5,minecraft:lava[level=8])
B(-4,6,-5,minecraft:lava[level=8])
B(-4,7,-5,minecraft:lava[level=8])
B(-4,8,-5,minecraft:lava[level=8])
B(-4,9,-5,minecraft:lava[level=8])
B(-4,10,-5,minecraft:lava[level=8])
B(-4,11,-5,minecraft:lava[level=2])
B(-4,0,-4,minecraft:lava)
B(-4,1,-4,minecraft:lava)
B(-4,2,-4,minecraft:lava)
B(-4,3,-4,minecraft:lava[level=2])
B(-4,0,-3,minecraft:lava)
B(-4,1,-3,minecraft:lava)
B(-4,2,-3,minecraft:lava)
B(-4,3,-3,minecraft:lava)
B(-4,0,-2,minecraft:lava)
B(-4,1,-2,minecraft:lava)
B(-4,2,-2,minecraft:lava)
B(-4,3,-2,minecraft:lava)
B(-4,0,-1,minecraft:lava)
B(-4,1,-1,minecraft:lava)
B(-4,2,-1,minecraft:lava)
B(-4,3,-1,minecraft:lava)
B(-4,0,0,minecraft:lava)
B(-4,1,0,minecraft:lava)
B(-4,2,0,minecraft:lava)
B(-4,3,0,minecraft:lava[level=2])
B(-4,0,1,minecraft:lava)
B(-4,1,1,minecraft:lava)
B(-4,2,1,minecraft:lava)
B(-4,0,2,minecraft:lava)
B(-4,1,2,minecraft:lava)
B(-4,2,2,minecraft:lava[level=2])
B(-4,0,3,minecraft:lava)
B(-4,1,3,minecraft:lava[level=2])
B(-4,0,4,minecraft:lava[level=2])
B(-3,0,-7,minecraft:lava)
B(-3,1,-7,minecraft:lava)
B(-3,2,-7,minecraft:lava)
B(-3,3,-7,minecraft:lava)
B(-3,4,-7,minecraft:lava)
B(-3,5,-7,minecraft:lava)
B(-3,6,-7,minecraft:lava)
B(-3,7,-7,minecraft:lava[level=8])
B(-3,8,-7,minecraft:lava[level=8])
B(-3,9,-7,minecraft:lava[level=8])
B(-3,10,-7,minecraft:lava[level=8])
B(-3,11,-7,minecraft:lava[level=8])
B(-3,12,-7,minecraft:lava[level=8])
B(-3,13,-7,minecraft:lava[level=8])
B(-3,14,-7,minecraft:lava[level=8])
B(-3,15,-7,minecraft:lava[level=2])
B(-3,0,-6,minecraft:lava)
B(-3,1,-6,minecraft:lava)
B(-3,2,-6,minecraft:lava)
B(-3,3,-6,minecraft:lava[level=8])
B(-3,4,-6,minecraft:lava[level=8])
B(-3,5,-6,minecraft:lava[level=8])
B(-3,6,-6,minecraft:lava[level=8])
B(-3,7,-6,minecraft:lava[level=8])
B(-3,8,-6,minecraft:lava[level=8])
B(-3,9,-6,minecraft:lava[level=8])
B(-3,10,-6,minecraft:lava[level=2])
B(-3,0,-5,minecraft:lava)
B(-3,1,-5,minecraft:lava)
B(-3,2,-5,minecraft:lava[level=2])
B(-3,0,-4,minecraft:lava)
B(-3,1,-4,minecraft:lava)
B(-3,2,-4,minecraft:lava)
B(-3,0,-3,minecraft:lava[level=8])
B(-3,1,-3,minecraft:lava[level=8])
B(-3,2,-3,minecraft:lava[level=8])
B(-3,3,-3,minecraft:lava[level=2])
B(-3,0,-2,minecraft:lava)
B(-3,1,-2,minecraft:lava)
B(-3,2,-2,minecraft:lava)
B(-3,3,-2,minecraft:lava[level=2])
B(-3,0,-1,minecraft:lava)
B(-3,1,-1,minecraft:lava)
B(-3,2,-1,minecraft:lava)
B(-3,3,-1,minecraft:lava[level=2])
B(-3,0,0,minecraft:lava)
B(-3,1,0,minecraft:lava)
B(-3,2,0,minecraft:lava)
B(-3,0,1,minecraft:lava)
B(-3,1,1,minecraft:lava)
B(-3,2,1,minecraft:lava[level=2])
B(-3,0,2,minecraft:lava)
B(-3,1,2,minecraft:lava[level=2])
B(-3,0,3,minecraft:lava[level=2])
B(-3,0,4,minecraft:lava[level=4])
B(-2,0,-7,minecraft:lava)
B(-2,1,-7,minecraft:lava)
B(-2,2,-7,minecraft:lava)
B(-2,3,-7,minecraft:lava)
B(-2,4,-7,minecraft:lava[level=8])
B(-2,5,-7,minecraft:lava[level=8])
B(-2,6,-7,minecraft:lava[level=2])
B(-2,0,-6,minecraft:lava)
B(-2,1,-6,minecraft:lava)
B(-2,2,-6,minecraft:lava)
B(-2,3,-6,minecraft:lava[level=2])
B(-2,0,-5,minecraft:lava)
B(-2,1,-5,minecraft:lava)
B(-2,2,-5,minecraft:lava[level=2])
B(-2,0,-4,minecraft:lava)
B(-2,1,-4,minecraft:lava)
B(-2,2,-4,minecraft:lava[level=2])
B(-2,0,-3,minecraft:lava)
B(-2,1,-3,minecraft:lava)
B(-2,2,-3,minecraft:lava)
B(-2,0,-2,minecraft:lava)
B(-2,1,-2,minecraft:lava)
B(-2,2,-2,minecraft:lava)
B(-2,0,-1,minecraft:lava)
B(-2,1,-1,minecraft:lava)
B(-2,2,-1,minecraft:lava[level=2])
B(-2,0,0,minecraft:lava)
B(-2,1,0,minecraft:lava)
B(-2,2,0,minecraft:lava[level=2])
B(-2,0,1,minecraft:lava)
B(-2,1,1,minecraft:lava[level=2])
B(-2,0,2,minecraft:lava[level=2])
B(-2,0,3,minecraft:lava[level=4])
B(-1,0,-7,minecraft:lava)
B(-1,1,-7,minecraft:lava)
B(-1,2,-7,minecraft:lava)
B(-1,3,-7,minecraft:lava[level=2])
B(-1,0,-6,minecraft:lava)
B(-1,1,-6,minecraft:lava)
B(-1,2,-6,minecraft:lava)
B(-1,0,-5,minecraft:lava)
B(-1,1,-5,minecraft:lava)
B(-1,2,-5,minecraft:lava[level=2])
B(-1,0,-4,minecraft:lava)
B(-1,1,-4,minecraft:lava[level=2])
B(-1,0,-3,minecraft:lava)
B(-1,1,-3,minecraft:lava)
B(-1,2,-3,minecraft:lava[level=2])
B(-1,0,-2,minecraft:lava)
B(-1,1,-2,minecraft:lava)
B(-1,2,-2,minecraft:lava[level=2])
B(-1,0,-1,minecraft:lava)
B(-1,1,-1,minecraft:lava)
B(-1,0,0,minecraft:lava)
B(-1,1,0,minecraft:lava[level=2])
B(-1,0,1,minecraft:lava)
B(-1,0,2,minecraft:lava[level=2])
B(-1,0,3,minecraft:lava[level=4])
B(0,0,-7,minecraft:lava)
B(0,1,-7,minecraft:lava)
B(0,2,-7,minecraft:lava)
B(0,0,-6,minecraft:lava)
B(0,1,-6,minecraft:lava)
B(0,2,-6,minecraft:lava[level=2])
B(0,0,-5,minecraft:lava)
B(0,1,-5,minecraft:lava[level=2])
B(0,0,-4,minecraft:lava)
B(0,0,-3,minecraft:lava)
B(0,1,-3,minecraft:lava[level=2])
B(0,0,-2,minecraft:lava)
B(0,1,-2,minecraft:lava[level=2])
B(0,0,-1,minecraft:lava)
B(0,1,-1,minecraft:lava[level=2])
B(0,0,0,minecraft:lava[level=2])
B(0,0,1,minecraft:lava[level=2])
B(0,0,2,minecraft:lava[level=4])
B(1,0,-7,minecraft:lava)
B(1,1,-7,minecraft:lava[level=8])
B(1,2,-7,minecraft:lava[level=2])
B(1,0,-6,minecraft:lava)
B(1,1,-6,minecraft:lava[level=2])
B(1,0,-5,minecraft:lava)
B(1,0,-4,minecraft:lava)
B(1,0,-3,minecraft:lava[level=2])
B(1,0,-2,minecraft:lava[level=2])
B(1,0,-1,minecraft:lava[level=2])
B(1,0,0,minecraft:lava[level=4])
B(1,0,1,minecraft:lava[level=4])
B(2,0,-7,minecraft:lava[level=2])
B(2,0,-6,minecraft:lava[level=2])
B(2,0,-5,minecraft:lava[level=2])
B(2,0,-2,minecraft:lava[level=4])
B(2,0,-1,minecraft:lava[level=4])
B(3,0,-7,minecraft:lava[level=4])
B(3,0,-6,minecraft:lava[level=4])
B(3,0,-5,minecraft:lava[level=4])

#######################################################################
# +-----------------------------------------------------------------+ #
# |                             Branches                            | #
# +-----------------------------------------------------------------+ #
#######################################################################


#######################################################################
# +-----------------------------------------------------------------+ #
# |                             Entities                            | #
# +-----------------------------------------------------------------+ #
#######################################################################

