
#######################################################################
# +-----------------------------------------------------------------+ #
# |                            BO4 object                           | #
# +-----------------------------------------------------------------+ #
#######################################################################

Author: Unknown

Description: No description given

SettingsMode: WriteWithoutComments


#######################################################################
# +-----------------------------------------------------------------+ #
# |                          Main settings                          | #
# +-----------------------------------------------------------------+ #
#######################################################################

FixedRotation: 

Frequency: 0

SpawnHeight: highestBlock

UseCenterForHighestBlock: true

##############################
# Height Limits for the BO4. #
##############################

MinHeight: 0

MaxHeight: 255

InheritBO3: 

InheritBO3Rotation: NORTH

OverrideChildSettings: true

OverrideParentHeight: false

CanOverride: false

BranchFrequency: 0

BranchFrequencyGroup: 

MustBeBelowOther: false

MustBeInside: 

CannotBeInside: 

ReplacesBO3: 

MustBeInsideWorldBorders: false

CanSpawnOnWater: true

SpawnOnWaterOnly: false

SpawnUnderWater: false

SpawnAtWaterLevel: false

HeightOffset: 0

RemoveAir: true

ReplaceAbove: 

ReplaceBelow: 

ReplaceWithBiomeBlocks: true

ReplaceWithSurfaceBlock: GRASS

ReplaceWithGroundBlock: DIRT

ReplaceWithStoneBlock: STONE

SmoothRadius: 0

SmoothHeightOffset: 0

SmoothStartTop: false

SmoothStartWood: false

SmoothingSurfaceBlock: 

SmoothingGroundBlock: 

BO3Group: 

IsSpawnPoint: false

DoReplaceBlocks: true


#######################################################################
# +-----------------------------------------------------------------+ #
# |                              Blocks                             | #
# +-----------------------------------------------------------------+ #
#######################################################################

B(-5,31,8,minecraft:nether_wart_block)
B(-5,32,8,minecraft:nether_wart_block)
B(-5,33,8,minecraft:nether_wart_block)
B(-5,34,8,minecraft:nether_wart_block)
B(-5,35,8,minecraft:nether_wart_block)
B(-4,32,7,minecraft:nether_wart_block)
B(-4,33,7,minecraft:nether_wart_block)
B(-4,34,7,minecraft:nether_wart_block)
B(-4,35,7,minecraft:nether_wart_block)
B(-4,36,7,minecraft:nether_wart_block)
B(-4,31,8,minecraft:nether_wart_block)
B(-4,32,8,minecraft:nether_wart_block)
B(-4,33,8,minecraft:nether_wart_block)
B(-4,34,8,minecraft:nether_wart_block)
B(-4,35,8,minecraft:nether_wart_block)
B(-4,36,8,minecraft:nether_wart_block)
B(-4,37,8,minecraft:nether_wart_block)
B(-4,38,8,minecraft:nether_wart_block)
B(-4,39,8,minecraft:nether_wart_block)
B(-3,37,5,minecraft:nether_wart_block)
B(-3,38,5,minecraft:nether_wart_block)
B(-3,39,5,minecraft:nether_wart_block)
B(-3,33,6,minecraft:nether_wart_block)
B(-3,34,6,minecraft:nether_wart_block)
B(-3,35,6,minecraft:nether_wart_block)
B(-3,36,6,minecraft:nether_wart_block)
B(-3,37,6,minecraft:nether_wart_block)
B(-3,38,6,minecraft:nether_wart_block)
B(-3,39,6,minecraft:nether_wart_block)
B(-3,32,7,minecraft:nether_wart_block)
B(-3,33,7,minecraft:nether_wart_block)
B(-3,34,7,minecraft:nether_wart_block)
B(-3,35,7,minecraft:nether_wart_block)
B(-3,36,7,minecraft:nether_wart_block)
B(-3,37,7,minecraft:nether_wart_block)
B(-3,38,7,minecraft:nether_wart_block)
B(-3,39,7,minecraft:nether_wart_block)
B(-3,31,8,minecraft:nether_wart_block)
B(-3,32,8,minecraft:nether_wart_block)
B(-3,33,8,minecraft:nether_wart_block)
B(-3,34,8,minecraft:nether_wart_block)
B(-3,35,8,minecraft:nether_wart_block)
B(-3,36,8,minecraft:nether_wart_block)
B(-3,37,8,minecraft:nether_wart_block)
B(-3,38,8,minecraft:nether_wart_block)
B(-3,39,8,minecraft:nether_wart_block)
B(-3,40,8,minecraft:nether_wart_block)
B(-3,41,8,minecraft:nether_wart_block)
B(-3,42,8,minecraft:nether_wart_block)
B(-2,36,4,minecraft:nether_wart_block)
B(-2,37,4,minecraft:nether_wart_block)
B(-2,38,4,minecraft:nether_wart_block)
B(-2,39,4,minecraft:nether_wart_block)
B(-2,40,4,minecraft:nether_wart_block)
B(-2,34,5,minecraft:nether_wart_block)
B(-2,35,5,minecraft:nether_wart_block)
B(-2,36,5,minecraft:nether_wart_block)
B(-2,37,5,minecraft:nether_wart_block)
B(-2,38,5,minecraft:nether_wart_block)
B(-2,39,5,minecraft:nether_wart_block)
B(-2,40,5,minecraft:nether_wart_block)
B(-2,33,6,minecraft:nether_wart_block)
B(-2,34,6,minecraft:nether_wart_block)
B(-2,35,6,minecraft:nether_wart_block)
B(-2,36,6,minecraft:nether_wart_block)
B(-2,37,6,minecraft:nether_wart_block)
B(-2,38,6,minecraft:nether_wart_block)
B(-2,39,6,minecraft:nether_wart_block)
B(-2,40,6,minecraft:nether_wart_block)
B(-2,32,7,minecraft:nether_wart_block)
B(-2,33,7,minecraft:nether_wart_block)
B(-2,34,7,minecraft:nether_wart_block)
B(-2,35,7,minecraft:nether_wart_block)
B(-2,36,7,minecraft:nether_wart_block)
B(-2,37,7,minecraft:nether_wart_block)
B(-2,38,7,minecraft:nether_wart_block)
B(-2,39,7,minecraft:nether_wart_block)
B(-2,40,7,minecraft:nether_wart_block)
B(-2,41,7,minecraft:nether_wart_block)
B(-2,25,8,minecraft:weeping_vines[age=5])
B(-2,26,8,minecraft:weeping_vines_plant)
B(-2,27,8,minecraft:weeping_vines_plant)
B(-2,28,8,minecraft:weeping_vines_plant)
B(-2,29,8,minecraft:weeping_vines_plant)
B(-2,30,8,minecraft:weeping_vines_plant)
B(-2,31,8,minecraft:nether_wart_block)
B(-2,32,8,minecraft:nether_wart_block)
B(-2,33,8,minecraft:nether_wart_block)
B(-2,34,8,minecraft:nether_wart_block)
B(-2,35,8,minecraft:nether_wart_block)
B(-2,36,8,minecraft:nether_wart_block)
B(-2,37,8,minecraft:nether_wart_block)
B(-2,38,8,minecraft:nether_wart_block)
B(-2,39,8,minecraft:nether_wart_block)
B(-2,40,8,minecraft:nether_wart_block)
B(-2,41,8,minecraft:nether_wart_block)
B(-2,42,8,minecraft:nether_wart_block)
B(-1,37,3,minecraft:nether_wart_block)
B(-1,38,3,minecraft:nether_wart_block)
B(-1,39,3,minecraft:nether_wart_block)
B(-1,36,4,minecraft:nether_wart_block)
B(-1,37,4,minecraft:nether_wart_block)
B(-1,38,4,minecraft:nether_wart_block)
B(-1,39,4,minecraft:nether_wart_block)
B(-1,40,4,minecraft:nether_wart_block)
B(-1,34,5,minecraft:nether_wart_block)
B(-1,35,5,minecraft:nether_wart_block)
B(-1,36,5,minecraft:nether_wart_block)
B(-1,37,5,minecraft:nether_wart_block)
B(-1,38,5,minecraft:nether_wart_block)
B(-1,39,5,minecraft:nether_wart_block)
B(-1,40,5,minecraft:nether_wart_block)
B(-1,41,5,minecraft:nether_wart_block)
B(-1,33,6,minecraft:nether_wart_block)
B(-1,34,6,minecraft:nether_wart_block)
B(-1,35,6,minecraft:nether_wart_block)
B(-1,36,6,minecraft:nether_wart_block)
B(-1,37,6,minecraft:nether_wart_block)
B(-1,38,6,minecraft:nether_wart_block)
B(-1,39,6,minecraft:nether_wart_block)
B(-1,40,6,minecraft:nether_wart_block)
B(-1,41,6,minecraft:nether_wart_block)
B(-1,42,6,minecraft:nether_wart_block)
B(-1,32,7,minecraft:nether_wart_block)
B(-1,33,7,minecraft:nether_wart_block)
B(-1,34,7,minecraft:nether_wart_block)
B(-1,35,7,minecraft:nether_wart_block)
B(-1,36,7,minecraft:nether_wart_block)
B(-1,37,7,minecraft:nether_wart_block)
B(-1,38,7,minecraft:nether_wart_block)
B(-1,39,7,minecraft:nether_wart_block)
B(-1,40,7,minecraft:nether_wart_block)
B(-1,41,7,minecraft:nether_wart_block)
B(-1,42,7,minecraft:nether_wart_block)
B(-1,31,8,minecraft:nether_wart_block)
B(-1,32,8,minecraft:nether_wart_block)
B(-1,33,8,minecraft:nether_wart_block)
B(-1,34,8,minecraft:nether_wart_block)
B(-1,35,8,minecraft:nether_wart_block)
B(-1,36,8,minecraft:nether_wart_block)
B(-1,37,8,minecraft:nether_wart_block)
B(-1,38,8,minecraft:nether_wart_block)
B(-1,39,8,minecraft:nether_wart_block)
B(-1,40,8,minecraft:nether_wart_block)
B(-1,41,8,minecraft:nether_wart_block)
B(-1,42,8,minecraft:nether_wart_block)
B(0,37,3,minecraft:nether_wart_block)
B(0,38,3,minecraft:nether_wart_block)
B(0,39,3,minecraft:nether_wart_block)
B(0,32,4,minecraft:nether_wart_block)
B(0,33,4,minecraft:nether_wart_block)
B(0,34,4,minecraft:nether_wart_block)
B(0,35,4,minecraft:nether_wart_block)
B(0,36,4,minecraft:nether_wart_block)
B(0,37,4,minecraft:nether_wart_block)
B(0,38,4,minecraft:nether_wart_block)
B(0,39,4,minecraft:nether_wart_block)
B(0,40,4,minecraft:nether_wart_block)
B(0,32,5,minecraft:nether_wart_block)
B(0,33,5,minecraft:nether_wart_block)
B(0,34,5,minecraft:nether_wart_block)
B(0,35,5,minecraft:nether_wart_block)
B(0,36,5,minecraft:nether_wart_block)
B(0,37,5,minecraft:nether_wart_block)
B(0,38,5,minecraft:nether_wart_block)
B(0,39,5,minecraft:nether_wart_block)
B(0,40,5,minecraft:nether_wart_block)
B(0,41,5,minecraft:nether_wart_block)
B(0,32,6,minecraft:nether_wart_block)
B(0,33,6,minecraft:nether_wart_block)
B(0,34,6,minecraft:nether_wart_block)
B(0,35,6,minecraft:nether_wart_block)
B(0,36,6,minecraft:nether_wart_block)
B(0,37,6,minecraft:nether_wart_block)
B(0,38,6,minecraft:nether_wart_block)
B(0,39,6,minecraft:nether_wart_block)
B(0,40,6,minecraft:nether_wart_block)
B(0,41,6,minecraft:nether_wart_block)
B(0,42,6,minecraft:nether_wart_block)
B(0,30,7,minecraft:nether_wart_block)
B(0,31,7,minecraft:nether_wart_block)
B(0,32,7,minecraft:nether_wart_block)
B(0,33,7,minecraft:nether_wart_block)
B(0,34,7,minecraft:nether_wart_block)
B(0,35,7,minecraft:nether_wart_block)
B(0,36,7,minecraft:nether_wart_block)
B(0,37,7,minecraft:nether_wart_block)
B(0,38,7,minecraft:nether_wart_block)
B(0,39,7,minecraft:nether_wart_block)
B(0,40,7,minecraft:nether_wart_block)
B(0,41,7,minecraft:nether_wart_block)
B(0,42,7,minecraft:nether_wart_block)
B(0,43,7,minecraft:nether_wart_block)
B(0,30,8,minecraft:nether_wart_block)
B(0,31,8,minecraft:nether_wart_block)
B(0,32,8,minecraft:nether_wart_block)
B(0,33,8,minecraft:nether_wart_block)
B(0,34,8,minecraft:nether_wart_block)
B(0,35,8,minecraft:nether_wart_block)
B(0,36,8,minecraft:nether_wart_block)
B(0,37,8,minecraft:nether_wart_block)
B(0,38,8,minecraft:nether_wart_block)
B(0,39,8,minecraft:nether_wart_block)
B(0,40,8,minecraft:nether_wart_block)
B(0,41,8,minecraft:nether_wart_block)
B(0,42,8,minecraft:nether_wart_block)
B(0,43,8,minecraft:nether_wart_block)
B(1,31,3,minecraft:nether_wart_block)
B(1,32,3,minecraft:nether_wart_block)
B(1,33,3,minecraft:nether_wart_block)
B(1,34,3,minecraft:nether_wart_block)
B(1,35,3,minecraft:nether_wart_block)
B(1,36,3,minecraft:nether_wart_block)
B(1,37,3,minecraft:nether_wart_block)
B(1,38,3,minecraft:nether_wart_block)
B(1,39,3,minecraft:nether_wart_block)
B(1,40,3,minecraft:nether_wart_block)
B(1,41,3,minecraft:nether_wart_block)
B(1,31,4,minecraft:nether_wart_block)
B(1,32,4,minecraft:nether_wart_block)
B(1,33,4,minecraft:nether_wart_block)
B(1,34,4,minecraft:nether_wart_block)
B(1,35,4,minecraft:nether_wart_block)
B(1,36,4,minecraft:nether_wart_block)
B(1,37,4,minecraft:nether_wart_block)
B(1,38,4,minecraft:nether_wart_block)
B(1,39,4,minecraft:nether_wart_block)
B(1,40,4,minecraft:nether_wart_block)
B(1,41,4,minecraft:nether_wart_block)
B(1,31,5,minecraft:nether_wart_block)
B(1,32,5,minecraft:nether_wart_block)
B(1,33,5,minecraft:nether_wart_block)
B(1,34,5,minecraft:nether_wart_block)
B(1,35,5,minecraft:nether_wart_block)
B(1,36,5,minecraft:nether_wart_block)
B(1,37,5,minecraft:nether_wart_block)
B(1,38,5,minecraft:nether_wart_block)
B(1,39,5,minecraft:nether_wart_block)
B(1,40,5,minecraft:nether_wart_block)
B(1,41,5,minecraft:nether_wart_block)
B(1,31,6,minecraft:nether_wart_block)
B(1,32,6,minecraft:nether_wart_block)
B(1,33,6,minecraft:nether_wart_block)
B(1,34,6,minecraft:nether_wart_block)
B(1,35,6,minecraft:nether_wart_block)
B(1,36,6,minecraft:nether_wart_block)
B(1,37,6,minecraft:nether_wart_block)
B(1,38,6,minecraft:nether_wart_block)
B(1,39,6,minecraft:nether_wart_block)
B(1,40,6,minecraft:nether_wart_block)
B(1,41,6,minecraft:nether_wart_block)
B(1,42,6,minecraft:nether_wart_block)
B(1,21,7,minecraft:weeping_vines[age=21])
B(1,22,7,minecraft:weeping_vines_plant)
B(1,23,7,minecraft:weeping_vines_plant)
B(1,24,7,minecraft:weeping_vines_plant)
B(1,25,7,minecraft:weeping_vines_plant)
B(1,26,7,minecraft:weeping_vines_plant)
B(1,27,7,minecraft:weeping_vines_plant)
B(1,28,7,minecraft:weeping_vines_plant)
B(1,29,7,minecraft:weeping_vines_plant)
B(1,30,7,minecraft:nether_wart_block)
B(1,31,7,minecraft:nether_wart_block)
B(1,32,7,minecraft:nether_wart_block)
B(1,33,7,minecraft:nether_wart_block)
B(1,34,7,minecraft:nether_wart_block)
B(1,35,7,minecraft:nether_wart_block)
B(1,36,7,minecraft:nether_wart_block)
B(1,37,7,minecraft:nether_wart_block)
B(1,38,7,minecraft:nether_wart_block)
B(1,39,7,minecraft:nether_wart_block)
B(1,40,7,minecraft:nether_wart_block)
B(1,41,7,minecraft:nether_wart_block)
B(1,42,7,minecraft:nether_wart_block)
B(1,43,7,minecraft:nether_wart_block)
B(1,18,8,minecraft:weeping_vines[age=18])
B(1,19,8,minecraft:weeping_vines_plant)
B(1,20,8,minecraft:weeping_vines_plant)
B(1,21,8,minecraft:weeping_vines_plant)
B(1,22,8,minecraft:weeping_vines_plant)
B(1,23,8,minecraft:weeping_vines_plant)
B(1,24,8,minecraft:weeping_vines_plant)
B(1,25,8,minecraft:weeping_vines_plant)
B(1,26,8,minecraft:weeping_vines_plant)
B(1,27,8,minecraft:weeping_vines_plant)
B(1,28,8,minecraft:weeping_vines_plant)
B(1,29,8,minecraft:nether_wart_block)
B(1,30,8,minecraft:nether_wart_block)
B(1,31,8,minecraft:nether_wart_block)
B(1,32,8,minecraft:nether_wart_block)
B(1,33,8,minecraft:nether_wart_block)
B(1,34,8,minecraft:nether_wart_block)
B(1,35,8,minecraft:nether_wart_block)
B(1,36,8,minecraft:nether_wart_block)
B(1,37,8,minecraft:nether_wart_block)
B(1,38,8,minecraft:nether_wart_block)
B(1,39,8,minecraft:nether_wart_block)
B(1,40,8,minecraft:nether_wart_block)
B(1,41,8,minecraft:nether_wart_block)
B(1,42,8,minecraft:nether_wart_block)
B(1,43,8,minecraft:nether_wart_block)
B(2,31,2,minecraft:nether_wart_block)
B(2,32,2,minecraft:nether_wart_block)
B(2,33,2,minecraft:nether_wart_block)
B(2,34,2,minecraft:nether_wart_block)
B(2,38,2,minecraft:nether_wart_block)
B(2,39,2,minecraft:nether_wart_block)
B(2,40,2,minecraft:nether_wart_block)
B(2,31,3,minecraft:nether_wart_block)
B(2,32,3,minecraft:nether_wart_block)
B(2,33,3,minecraft:nether_wart_block)
B(2,34,3,minecraft:nether_wart_block)
B(2,35,3,minecraft:nether_wart_block)
B(2,36,3,minecraft:nether_wart_block)
B(2,37,3,minecraft:nether_wart_block)
B(2,38,3,minecraft:nether_wart_block)
B(2,39,3,minecraft:nether_wart_block)
B(2,40,3,minecraft:nether_wart_block)
B(2,41,3,minecraft:nether_wart_block)
B(2,30,4,minecraft:nether_wart_block)
B(2,31,4,minecraft:nether_wart_block)
B(2,32,4,minecraft:nether_wart_block)
B(2,33,4,minecraft:nether_wart_block)
B(2,34,4,minecraft:nether_wart_block)
B(2,35,4,minecraft:nether_wart_block)
B(2,36,4,minecraft:nether_wart_block)
B(2,37,4,minecraft:nether_wart_block)
B(2,38,4,minecraft:nether_wart_block)
B(2,39,4,minecraft:nether_wart_block)
B(2,40,4,minecraft:nether_wart_block)
B(2,41,4,minecraft:nether_wart_block)
B(2,42,4,minecraft:nether_wart_block)
B(2,21,5,minecraft:weeping_vines[age=12])
B(2,22,5,minecraft:weeping_vines_plant)
B(2,23,5,minecraft:weeping_vines_plant)
B(2,24,5,minecraft:weeping_vines_plant)
B(2,25,5,minecraft:weeping_vines_plant)
B(2,26,5,minecraft:weeping_vines_plant)
B(2,27,5,minecraft:weeping_vines_plant)
B(2,28,5,minecraft:weeping_vines_plant)
B(2,29,5,minecraft:weeping_vines_plant)
B(2,30,5,minecraft:nether_wart_block)
B(2,31,5,minecraft:nether_wart_block)
B(2,32,5,minecraft:nether_wart_block)
B(2,33,5,minecraft:nether_wart_block)
B(2,34,5,minecraft:nether_wart_block)
B(2,35,5,minecraft:nether_wart_block)
B(2,36,5,minecraft:nether_wart_block)
B(2,37,5,minecraft:nether_wart_block)
B(2,38,5,minecraft:nether_wart_block)
B(2,39,5,minecraft:nether_wart_block)
B(2,40,5,minecraft:nether_wart_block)
B(2,41,5,minecraft:nether_wart_block)
B(2,42,5,minecraft:nether_wart_block)
B(2,30,6,minecraft:nether_wart_block)
B(2,31,6,minecraft:nether_wart_block)
B(2,32,6,minecraft:nether_wart_block)
B(2,33,6,minecraft:nether_wart_block)
B(2,34,6,minecraft:nether_wart_block)
B(2,35,6,minecraft:nether_wart_block)
B(2,36,6,minecraft:nether_wart_block)
B(2,37,6,minecraft:nether_wart_block)
B(2,38,6,minecraft:nether_wart_block)
B(2,39,6,minecraft:nether_wart_block)
B(2,40,6,minecraft:nether_wart_block)
B(2,41,6,minecraft:nether_wart_block)
B(2,42,6,minecraft:nether_wart_block)
B(2,30,7,minecraft:nether_wart_block)
B(2,31,7,minecraft:nether_wart_block)
B(2,32,7,minecraft:nether_wart_block)
B(2,33,7,minecraft:nether_wart_block)
B(2,34,7,minecraft:nether_wart_block)
B(2,35,7,minecraft:nether_wart_block)
B(2,36,7,minecraft:nether_wart_block)
B(2,37,7,minecraft:nether_wart_block)
B(2,38,7,minecraft:nether_wart_block)
B(2,39,7,minecraft:nether_wart_block)
B(2,40,7,minecraft:nether_wart_block)
B(2,41,7,minecraft:nether_wart_block)
B(2,42,7,minecraft:nether_wart_block)
B(2,43,7,minecraft:nether_wart_block)
B(2,44,7,minecraft:nether_wart_block)
B(2,29,8,minecraft:nether_wart_block)
B(2,30,8,minecraft:nether_wart_block)
B(2,31,8,minecraft:nether_wart_block)
B(2,32,8,minecraft:nether_wart_block)
B(2,33,8,minecraft:nether_wart_block)
B(2,34,8,minecraft:nether_wart_block)
B(2,35,8,minecraft:nether_wart_block)
B(2,36,8,minecraft:nether_wart_block)
B(2,37,8,minecraft:nether_wart_block)
B(2,38,8,minecraft:nether_wart_block)
B(2,39,8,minecraft:nether_wart_block)
B(2,40,8,minecraft:nether_wart_block)
B(2,41,8,minecraft:nether_wart_block)
B(2,42,8,minecraft:nether_wart_block)
B(2,43,8,minecraft:nether_wart_block)
B(2,44,8,minecraft:nether_wart_block)
B(3,30,1,minecraft:nether_wart_block)
B(3,31,1,minecraft:nether_wart_block)
B(3,32,1,minecraft:nether_wart_block)
B(3,33,1,minecraft:nether_wart_block)
B(3,34,1,minecraft:nether_wart_block)
B(3,30,2,minecraft:nether_wart_block)
B(3,31,2,minecraft:nether_wart_block)
B(3,32,2,minecraft:nether_wart_block)
B(3,33,2,minecraft:nether_wart_block)
B(3,34,2,minecraft:nether_wart_block)
B(3,38,2,minecraft:nether_wart_block)
B(3,39,2,minecraft:nether_wart_block)
B(3,40,2,minecraft:nether_wart_block)
B(3,30,3,minecraft:nether_wart_block)
B(3,31,3,minecraft:nether_wart_block)
B(3,32,3,minecraft:nether_wart_block)
B(3,33,3,minecraft:nether_wart_block)
B(3,34,3,minecraft:nether_wart_block)
B(3,35,3,minecraft:nether_wart_block)
B(3,36,3,minecraft:nether_wart_block)
B(3,37,3,minecraft:nether_wart_block)
B(3,38,3,minecraft:nether_wart_block)
B(3,39,3,minecraft:nether_wart_block)
B(3,40,3,minecraft:nether_wart_block)
B(3,41,3,minecraft:nether_wart_block)
B(3,30,4,minecraft:nether_wart_block)
B(3,31,4,minecraft:nether_wart_block)
B(3,32,4,minecraft:nether_wart_block)
B(3,33,4,minecraft:nether_wart_block)
B(3,34,4,minecraft:nether_wart_block)
B(3,35,4,minecraft:nether_wart_block)
B(3,36,4,minecraft:nether_wart_block)
B(3,37,4,minecraft:nether_wart_block)
B(3,38,4,minecraft:nether_wart_block)
B(3,39,4,minecraft:nether_wart_block)
B(3,40,4,minecraft:nether_wart_block)
B(3,41,4,minecraft:nether_wart_block)
B(3,42,4,minecraft:nether_wart_block)
B(3,30,5,minecraft:nether_wart_block)
B(3,31,5,minecraft:nether_wart_block)
B(3,32,5,minecraft:nether_wart_block)
B(3,33,5,minecraft:nether_wart_block)
B(3,34,5,minecraft:nether_wart_block)
B(3,35,5,minecraft:nether_wart_block)
B(3,36,5,minecraft:nether_wart_block)
B(3,37,5,minecraft:nether_wart_block)
B(3,38,5,minecraft:nether_wart_block)
B(3,39,5,minecraft:nether_wart_block)
B(3,40,5,minecraft:nether_wart_block)
B(3,41,5,minecraft:nether_wart_block)
B(3,42,5,minecraft:nether_wart_block)
B(3,30,6,minecraft:nether_wart_block)
B(3,31,6,minecraft:nether_wart_block)
B(3,32,6,minecraft:nether_wart_block)
B(3,33,6,minecraft:nether_wart_block)
B(3,34,6,minecraft:nether_wart_block)
B(3,35,6,minecraft:nether_wart_block)
B(3,36,6,minecraft:nether_wart_block)
B(3,37,6,minecraft:nether_wart_block)
B(3,38,6,minecraft:nether_wart_block)
B(3,39,6,minecraft:nether_wart_block)
B(3,40,6,minecraft:nether_wart_block)
B(3,41,6,minecraft:nether_wart_block)
B(3,42,6,minecraft:nether_wart_block)
B(3,43,6,minecraft:nether_wart_block)
B(3,30,7,minecraft:nether_wart_block)
B(3,31,7,minecraft:nether_wart_block)
B(3,32,7,minecraft:nether_wart_block)
B(3,33,7,minecraft:nether_wart_block)
B(3,34,7,minecraft:nether_wart_block)
B(3,35,7,minecraft:nether_wart_block)
B(3,36,7,minecraft:nether_wart_block)
B(3,37,7,minecraft:nether_wart_block)
B(3,38,7,minecraft:nether_wart_block)
B(3,39,7,minecraft:nether_wart_block)
B(3,40,7,minecraft:nether_wart_block)
B(3,41,7,minecraft:nether_wart_block)
B(3,42,7,minecraft:nether_wart_block)
B(3,43,7,minecraft:nether_wart_block)
B(3,44,7,minecraft:nether_wart_block)
B(3,29,8,minecraft:nether_wart_block)
B(3,30,8,minecraft:nether_wart_block)
B(3,31,8,minecraft:nether_wart_block)
B(3,32,8,minecraft:nether_wart_block)
B(3,33,8,minecraft:nether_wart_block)
B(3,34,8,minecraft:nether_wart_block)
B(3,35,8,minecraft:nether_wart_block)
B(3,36,8,minecraft:nether_wart_block)
B(3,37,8,minecraft:nether_wart_block)
B(3,38,8,minecraft:nether_wart_block)
B(3,39,8,minecraft:nether_wart_block)
B(3,40,8,minecraft:nether_wart_block)
B(3,41,8,minecraft:nether_wart_block)
B(3,42,8,minecraft:nether_wart_block)
B(3,43,8,minecraft:nether_wart_block)
B(3,44,8,minecraft:nether_wart_block)
B(3,45,8,minecraft:nether_wart_block)
B(4,31,0,minecraft:nether_wart_block)
B(4,32,0,minecraft:nether_wart_block)
B(4,33,0,minecraft:nether_wart_block)
B(4,30,1,minecraft:nether_wart_block)
B(4,31,1,minecraft:nether_wart_block)
B(4,32,1,minecraft:nether_wart_block)
B(4,33,1,minecraft:nether_wart_block)
B(4,34,1,minecraft:nether_wart_block)
B(4,29,2,minecraft:nether_wart_block)
B(4,30,2,minecraft:nether_wart_block)
B(4,31,2,minecraft:nether_wart_block)
B(4,32,2,minecraft:nether_wart_block)
B(4,33,2,minecraft:nether_wart_block)
B(4,34,2,minecraft:nether_wart_block)
B(4,35,2,minecraft:nether_wart_block)
B(4,38,2,minecraft:nether_wart_block)
B(4,39,2,minecraft:nether_wart_block)
B(4,40,2,minecraft:nether_wart_block)
B(4,29,3,minecraft:nether_wart_block)
B(4,30,3,minecraft:nether_wart_block)
B(4,31,3,minecraft:nether_wart_block)
B(4,32,3,minecraft:nether_wart_block)
B(4,33,3,minecraft:nether_wart_block)
B(4,34,3,minecraft:nether_wart_block)
B(4,35,3,minecraft:nether_wart_block)
B(4,36,3,minecraft:nether_wart_block)
B(4,37,3,minecraft:nether_wart_block)
B(4,38,3,minecraft:nether_wart_block)
B(4,39,3,minecraft:nether_wart_block)
B(4,40,3,minecraft:nether_wart_block)
B(4,41,3,minecraft:nether_wart_block)
B(4,29,4,minecraft:shroomlight)
B(4,30,4,minecraft:shroomlight)
B(4,31,4,minecraft:shroomlight)
B(4,32,4,minecraft:nether_wart_block)
B(4,33,4,minecraft:nether_wart_block)
B(4,34,4,minecraft:nether_wart_block)
B(4,35,4,minecraft:nether_wart_block)
B(4,36,4,minecraft:nether_wart_block)
B(4,37,4,minecraft:nether_wart_block)
B(4,38,4,minecraft:nether_wart_block)
B(4,39,4,minecraft:nether_wart_block)
B(4,40,4,minecraft:nether_wart_block)
B(4,41,4,minecraft:nether_wart_block)
B(4,42,4,minecraft:nether_wart_block)
B(4,29,5,minecraft:shroomlight)
B(4,30,5,minecraft:shroomlight)
B(4,31,5,minecraft:shroomlight)
B(4,32,5,minecraft:nether_wart_block)
B(4,33,5,minecraft:nether_wart_block)
B(4,34,5,minecraft:nether_wart_block)
B(4,35,5,minecraft:nether_wart_block)
B(4,36,5,minecraft:nether_wart_block)
B(4,37,5,minecraft:nether_wart_block)
B(4,38,5,minecraft:nether_wart_block)
B(4,39,5,minecraft:nether_wart_block)
B(4,40,5,minecraft:nether_wart_block)
B(4,41,5,minecraft:nether_wart_block)
B(4,42,5,minecraft:nether_wart_block)
B(4,29,6,minecraft:shroomlight)
B(4,30,6,minecraft:shroomlight)
B(4,31,6,minecraft:shroomlight)
B(4,32,6,minecraft:nether_wart_block)
B(4,33,6,minecraft:nether_wart_block)
B(4,34,6,minecraft:nether_wart_block)
B(4,35,6,minecraft:nether_wart_block)
B(4,36,6,minecraft:nether_wart_block)
B(4,37,6,minecraft:nether_wart_block)
B(4,38,6,minecraft:nether_wart_block)
B(4,39,6,minecraft:nether_wart_block)
B(4,40,6,minecraft:nether_wart_block)
B(4,41,6,minecraft:nether_wart_block)
B(4,42,6,minecraft:nether_wart_block)
B(4,43,6,minecraft:nether_wart_block)
B(4,30,7,minecraft:nether_wart_block)
B(4,31,7,minecraft:nether_wart_block)
B(4,32,7,minecraft:nether_wart_block)
B(4,33,7,minecraft:nether_wart_block)
B(4,34,7,minecraft:nether_wart_block)
B(4,35,7,minecraft:nether_wart_block)
B(4,36,7,minecraft:nether_wart_block)
B(4,37,7,minecraft:nether_wart_block)
B(4,38,7,minecraft:nether_wart_block)
B(4,39,7,minecraft:nether_wart_block)
B(4,40,7,minecraft:nether_wart_block)
B(4,41,7,minecraft:nether_wart_block)
B(4,42,7,minecraft:nether_wart_block)
B(4,43,7,minecraft:nether_wart_block)
B(4,44,7,minecraft:nether_wart_block)
B(4,30,8,minecraft:nether_wart_block)
B(4,31,8,minecraft:nether_wart_block)
B(4,32,8,minecraft:nether_wart_block)
B(4,33,8,minecraft:nether_wart_block)
B(4,34,8,minecraft:nether_wart_block)
B(4,35,8,minecraft:nether_wart_block)
B(4,36,8,minecraft:nether_wart_block)
B(4,37,8,minecraft:nether_wart_block)
B(4,38,8,minecraft:nether_wart_block)
B(4,39,8,minecraft:nether_wart_block)
B(4,40,8,minecraft:nether_wart_block)
B(4,41,8,minecraft:nether_wart_block)
B(4,42,8,minecraft:nether_wart_block)
B(4,43,8,minecraft:nether_wart_block)
B(4,44,8,minecraft:nether_wart_block)
B(4,45,8,minecraft:nether_wart_block)
B(5,23,0,minecraft:weeping_vines[age=18])
B(5,24,0,minecraft:weeping_vines_plant)
B(5,25,0,minecraft:weeping_vines_plant)
B(5,26,0,minecraft:weeping_vines_plant)
B(5,27,0,minecraft:weeping_vines_plant)
B(5,28,0,minecraft:weeping_vines_plant)
B(5,29,0,minecraft:weeping_vines_plant)
B(5,30,0,minecraft:weeping_vines_plant)
B(5,31,0,minecraft:nether_wart_block)
B(5,32,0,minecraft:nether_wart_block)
B(5,33,0,minecraft:nether_wart_block)
B(5,30,1,minecraft:nether_wart_block)
B(5,31,1,minecraft:nether_wart_block)
B(5,32,1,minecraft:nether_wart_block)
B(5,33,1,minecraft:nether_wart_block)
B(5,34,1,minecraft:nether_wart_block)
B(5,15,2,minecraft:weeping_vines[age=13])
B(5,16,2,minecraft:weeping_vines_plant)
B(5,17,2,minecraft:weeping_vines_plant)
B(5,18,2,minecraft:weeping_vines_plant)
B(5,19,2,minecraft:weeping_vines_plant)
B(5,20,2,minecraft:weeping_vines_plant)
B(5,21,2,minecraft:weeping_vines_plant)
B(5,22,2,minecraft:weeping_vines_plant)
B(5,23,2,minecraft:weeping_vines_plant)
B(5,24,2,minecraft:weeping_vines_plant)
B(5,25,2,minecraft:weeping_vines_plant)
B(5,26,2,minecraft:weeping_vines_plant)
B(5,27,2,minecraft:weeping_vines_plant)
B(5,28,2,minecraft:weeping_vines_plant)
B(5,29,2,minecraft:nether_wart_block)
B(5,30,2,minecraft:nether_wart_block)
B(5,31,2,minecraft:nether_wart_block)
B(5,32,2,minecraft:nether_wart_block)
B(5,33,2,minecraft:nether_wart_block)
B(5,34,2,minecraft:nether_wart_block)
B(5,35,2,minecraft:nether_wart_block)
B(5,36,2,minecraft:nether_wart_block)
B(5,37,2,minecraft:nether_wart_block)
B(5,29,3,minecraft:shroomlight)
B(5,30,3,minecraft:shroomlight)
B(5,31,3,minecraft:shroomlight)
B(5,32,3,minecraft:nether_wart_block)
B(5,33,3,minecraft:nether_wart_block)
B(5,34,3,minecraft:nether_wart_block)
B(5,35,3,minecraft:nether_wart_block)
B(5,36,3,minecraft:nether_wart_block)
B(5,37,3,minecraft:nether_wart_block)
B(5,38,3,minecraft:nether_wart_block)
B(5,39,3,minecraft:nether_wart_block)
B(5,40,3,minecraft:nether_wart_block)
B(5,41,3,minecraft:nether_wart_block)
B(5,28,4,minecraft:shroomlight)
B(5,29,4,minecraft:shroomlight)
B(5,30,4,minecraft:shroomlight)
B(5,31,4,minecraft:shroomlight)
B(5,32,4,minecraft:shroomlight)
B(5,33,4,minecraft:nether_wart_block)
B(5,34,4,minecraft:nether_wart_block)
B(5,35,4,minecraft:nether_wart_block)
B(5,36,4,minecraft:nether_wart_block)
B(5,37,4,minecraft:nether_wart_block)
B(5,38,4,minecraft:nether_wart_block)
B(5,39,4,minecraft:nether_wart_block)
B(5,40,4,minecraft:nether_wart_block)
B(5,41,4,minecraft:nether_wart_block)
B(5,28,5,minecraft:shroomlight)
B(5,29,5,minecraft:shroomlight)
B(5,30,5,minecraft:shroomlight)
B(5,31,5,minecraft:shroomlight)
B(5,32,5,minecraft:shroomlight)
B(5,33,5,minecraft:nether_wart_block)
B(5,34,5,minecraft:nether_wart_block)
B(5,35,5,minecraft:nether_wart_block)
B(5,36,5,minecraft:nether_wart_block)
B(5,37,5,minecraft:nether_wart_block)
B(5,38,5,minecraft:nether_wart_block)
B(5,39,5,minecraft:nether_wart_block)
B(5,40,5,minecraft:nether_wart_block)
B(5,41,5,minecraft:nether_wart_block)
B(5,28,6,minecraft:shroomlight)
B(5,29,6,minecraft:shroomlight)
B(5,30,6,minecraft:shroomlight)
B(5,31,6,minecraft:shroomlight)
B(5,32,6,minecraft:shroomlight)
B(5,33,6,minecraft:nether_wart_block)
B(5,34,6,minecraft:nether_wart_block)
B(5,35,6,minecraft:nether_wart_block)
B(5,36,6,minecraft:nether_wart_block)
B(5,37,6,minecraft:nether_wart_block)
B(5,38,6,minecraft:nether_wart_block)
B(5,39,6,minecraft:nether_wart_block)
B(5,40,6,minecraft:nether_wart_block)
B(5,41,6,minecraft:nether_wart_block)
B(5,42,6,minecraft:nether_wart_block)
B(5,43,6,minecraft:nether_wart_block)
B(5,29,7,minecraft:shroomlight)
B(5,30,7,minecraft:shroomlight)
B(5,31,7,minecraft:shroomlight)
B(5,32,7,minecraft:nether_wart_block)
B(5,33,7,minecraft:nether_wart_block)
B(5,34,7,minecraft:nether_wart_block)
B(5,35,7,minecraft:nether_wart_block)
B(5,36,7,minecraft:nether_wart_block)
B(5,37,7,minecraft:nether_wart_block)
B(5,38,7,minecraft:nether_wart_block)
B(5,39,7,minecraft:nether_wart_block)
B(5,40,7,minecraft:nether_wart_block)
B(5,41,7,minecraft:nether_wart_block)
B(5,42,7,minecraft:nether_wart_block)
B(5,43,7,minecraft:nether_wart_block)
B(5,44,7,minecraft:nether_wart_block)
B(5,31,8,minecraft:nether_wart_block)
B(5,32,8,minecraft:nether_wart_block)
B(5,33,8,minecraft:nether_wart_block)
B(5,34,8,minecraft:nether_wart_block)
B(5,35,8,minecraft:nether_wart_block)
B(5,36,8,minecraft:nether_wart_block)
B(5,37,8,minecraft:nether_wart_block)
B(5,38,8,minecraft:nether_wart_block)
B(5,39,8,minecraft:nether_wart_block)
B(5,40,8,minecraft:nether_wart_block)
B(5,41,8,minecraft:nether_wart_block)
B(5,42,8,minecraft:nether_wart_block)
B(5,43,8,minecraft:nether_wart_block)
B(5,44,8,minecraft:nether_wart_block)
B(5,45,8,minecraft:nether_wart_block)
B(6,31,0,minecraft:nether_wart_block)
B(6,32,0,minecraft:nether_wart_block)
B(6,33,0,minecraft:nether_wart_block)
B(6,30,1,minecraft:nether_wart_block)
B(6,31,1,minecraft:nether_wart_block)
B(6,32,1,minecraft:nether_wart_block)
B(6,33,1,minecraft:nether_wart_block)
B(6,34,1,minecraft:nether_wart_block)
B(6,35,1,minecraft:nether_wart_block)
B(6,29,2,minecraft:nether_wart_block)
B(6,30,2,minecraft:nether_wart_block)
B(6,31,2,minecraft:nether_wart_block)
B(6,32,2,minecraft:nether_wart_block)
B(6,33,2,minecraft:nether_wart_block)
B(6,34,2,minecraft:nether_wart_block)
B(6,35,2,minecraft:nether_wart_block)
B(6,36,2,minecraft:nether_wart_block)
B(6,37,2,minecraft:nether_wart_block)
B(6,29,3,minecraft:shroomlight)
B(6,30,3,minecraft:shroomlight)
B(6,31,3,minecraft:shroomlight)
B(6,32,3,minecraft:nether_wart_block)
B(6,33,3,minecraft:nether_wart_block)
B(6,34,3,minecraft:nether_wart_block)
B(6,35,3,minecraft:nether_wart_block)
B(6,36,3,minecraft:nether_wart_block)
B(6,37,3,minecraft:nether_wart_block)
B(6,38,3,minecraft:nether_wart_block)
B(6,28,4,minecraft:shroomlight)
B(6,29,4,minecraft:shroomlight)
B(6,30,4,minecraft:shroomlight)
B(6,31,4,minecraft:shroomlight)
B(6,32,4,minecraft:shroomlight)
B(6,33,4,minecraft:nether_wart_block)
B(6,34,4,minecraft:nether_wart_block)
B(6,35,4,minecraft:nether_wart_block)
B(6,36,4,minecraft:nether_wart_block)
B(6,37,4,minecraft:nether_wart_block)
B(6,38,4,minecraft:nether_wart_block)
B(6,39,4,minecraft:nether_wart_block)
B(6,40,4,minecraft:nether_wart_block)
B(6,28,5,minecraft:shroomlight)
B(6,29,5,minecraft:shroomlight)
B(6,30,5,minecraft:shroomlight)
B(6,31,5,minecraft:shroomlight)
B(6,32,5,minecraft:shroomlight)
B(6,33,5,minecraft:nether_wart_block)
B(6,34,5,minecraft:nether_wart_block)
B(6,35,5,minecraft:nether_wart_block)
B(6,36,5,minecraft:nether_wart_block)
B(6,37,5,minecraft:nether_wart_block)
B(6,38,5,minecraft:nether_wart_block)
B(6,39,5,minecraft:nether_wart_block)
B(6,40,5,minecraft:nether_wart_block)
B(6,28,6,minecraft:shroomlight)
B(6,29,6,minecraft:shroomlight)
B(6,30,6,minecraft:shroomlight)
B(6,31,6,minecraft:shroomlight)
B(6,32,6,minecraft:shroomlight)
B(6,33,6,minecraft:nether_wart_block)
B(6,34,6,minecraft:nether_wart_block)
B(6,35,6,minecraft:nether_wart_block)
B(6,36,6,minecraft:nether_wart_block)
B(6,37,6,minecraft:nether_wart_block)
B(6,38,6,minecraft:nether_wart_block)
B(6,39,6,minecraft:nether_wart_block)
B(6,40,6,minecraft:nether_wart_block)
B(6,41,6,minecraft:nether_wart_block)
B(6,42,6,minecraft:nether_wart_block)
B(6,43,6,minecraft:nether_wart_block)
B(6,29,7,minecraft:shroomlight)
B(6,30,7,minecraft:shroomlight)
B(6,31,7,minecraft:shroomlight)
B(6,32,7,minecraft:nether_wart_block)
B(6,33,7,minecraft:nether_wart_block)
B(6,34,7,minecraft:nether_wart_block)
B(6,35,7,minecraft:nether_wart_block)
B(6,36,7,minecraft:nether_wart_block)
B(6,37,7,minecraft:nether_wart_block)
B(6,38,7,minecraft:nether_wart_block)
B(6,39,7,minecraft:nether_wart_block)
B(6,40,7,minecraft:nether_wart_block)
B(6,41,7,minecraft:nether_wart_block)
B(6,42,7,minecraft:nether_wart_block)
B(6,43,7,minecraft:nether_wart_block)
B(6,44,7,minecraft:nether_wart_block)
B(6,32,8,minecraft:nether_wart_block)
B(6,33,8,minecraft:nether_wart_block)
B(6,34,8,minecraft:nether_wart_block)
B(6,35,8,minecraft:nether_wart_block)
B(6,36,8,minecraft:nether_wart_block)
B(6,37,8,minecraft:nether_wart_block)
B(6,38,8,minecraft:nether_wart_block)
B(6,39,8,minecraft:nether_wart_block)
B(6,40,8,minecraft:nether_wart_block)
B(6,41,8,minecraft:nether_wart_block)
B(6,42,8,minecraft:nether_wart_block)
B(6,43,8,minecraft:nether_wart_block)
B(6,44,8,minecraft:nether_wart_block)
B(7,0,-6,minecraft:netherrack)
B(7,0,-5,minecraft:netherrack)
B(7,0,-4,minecraft:netherrack)
B(7,0,-3,minecraft:netherrack)
B(7,0,-2,minecraft:netherrack)
B(7,1,-2,minecraft:netherrack)
B(7,0,-1,minecraft:netherrack)
B(7,1,-1,minecraft:netherrack)
B(7,0,0,minecraft:netherrack)
B(7,1,0,minecraft:netherrack)
B(7,32,0,minecraft:nether_wart_block)
B(7,33,0,minecraft:nether_wart_block)
B(7,34,0,minecraft:nether_wart_block)
B(7,35,0,minecraft:nether_wart_block)
B(7,36,0,minecraft:nether_wart_block)
B(7,0,1,minecraft:netherrack)
B(7,1,1,minecraft:netherrack)
B(7,30,1,minecraft:nether_wart_block)
B(7,31,1,minecraft:nether_wart_block)
B(7,32,1,minecraft:nether_wart_block)
B(7,33,1,minecraft:nether_wart_block)
B(7,34,1,minecraft:nether_wart_block)
B(7,35,1,minecraft:nether_wart_block)
B(7,36,1,minecraft:nether_wart_block)
B(7,0,2,minecraft:netherrack)
B(7,1,2,minecraft:netherrack)
B(7,30,2,minecraft:nether_wart_block)
B(7,31,2,minecraft:nether_wart_block)
B(7,32,2,minecraft:nether_wart_block)
B(7,33,2,minecraft:nether_wart_block)
B(7,34,2,minecraft:nether_wart_block)
B(7,35,2,minecraft:nether_wart_block)
B(7,36,2,minecraft:nether_wart_block)
B(7,37,2,minecraft:nether_wart_block)
B(7,0,3,minecraft:netherrack)
B(7,1,3,minecraft:netherrack)
B(7,29,3,minecraft:shroomlight)
B(7,30,3,minecraft:shroomlight)
B(7,31,3,minecraft:shroomlight)
B(7,32,3,minecraft:nether_wart_block)
B(7,33,3,minecraft:nether_wart_block)
B(7,34,3,minecraft:nether_wart_block)
B(7,35,3,minecraft:nether_wart_block)
B(7,36,3,minecraft:nether_wart_block)
B(7,37,3,minecraft:nether_wart_block)
B(7,38,3,minecraft:nether_wart_block)
B(7,0,4,minecraft:netherrack)
B(7,1,4,minecraft:netherrack)
B(7,28,4,minecraft:shroomlight)
B(7,29,4,minecraft:shroomlight)
B(7,30,4,minecraft:shroomlight)
B(7,31,4,minecraft:shroomlight)
B(7,32,4,minecraft:shroomlight)
B(7,33,4,minecraft:nether_wart_block)
B(7,34,4,minecraft:nether_wart_block)
B(7,35,4,minecraft:nether_wart_block)
B(7,36,4,minecraft:nether_wart_block)
B(7,37,4,minecraft:nether_wart_block)
B(7,38,4,minecraft:nether_wart_block)
B(7,39,4,minecraft:nether_wart_block)
B(7,40,4,minecraft:nether_wart_block)
B(7,0,5,minecraft:netherrack)
B(7,1,5,minecraft:netherrack)
B(7,28,5,minecraft:shroomlight)
B(7,29,5,minecraft:shroomlight)
B(7,30,5,minecraft:shroomlight)
B(7,31,5,minecraft:shroomlight)
B(7,32,5,minecraft:shroomlight)
B(7,33,5,minecraft:nether_wart_block)
B(7,34,5,minecraft:nether_wart_block)
B(7,35,5,minecraft:nether_wart_block)
B(7,36,5,minecraft:nether_wart_block)
B(7,37,5,minecraft:nether_wart_block)
B(7,38,5,minecraft:nether_wart_block)
B(7,39,5,minecraft:nether_wart_block)
B(7,40,5,minecraft:nether_wart_block)
B(7,41,5,minecraft:nether_wart_block)
B(7,42,5,minecraft:nether_wart_block)
B(7,43,5,minecraft:nether_wart_block)
B(7,44,5,minecraft:nether_wart_block)
B(7,0,6,minecraft:netherrack)
B(7,1,6,minecraft:netherrack)
B(7,28,6,minecraft:shroomlight)
B(7,29,6,minecraft:shroomlight)
B(7,30,6,minecraft:shroomlight)
B(7,31,6,minecraft:shroomlight)
B(7,32,6,minecraft:shroomlight)
B(7,33,6,minecraft:nether_wart_block)
B(7,34,6,minecraft:nether_wart_block)
B(7,35,6,minecraft:nether_wart_block)
B(7,36,6,minecraft:nether_wart_block)
B(7,37,6,minecraft:nether_wart_block)
B(7,38,6,minecraft:nether_wart_block)
B(7,39,6,minecraft:nether_wart_block)
B(7,40,6,minecraft:nether_wart_block)
B(7,41,6,minecraft:nether_wart_block)
B(7,42,6,minecraft:nether_wart_block)
B(7,43,6,minecraft:nether_wart_block)
B(7,44,6,minecraft:nether_wart_block)
B(7,0,7,minecraft:netherrack)
B(7,1,7,minecraft:netherrack)
B(7,29,7,minecraft:shroomlight)
B(7,30,7,minecraft:shroomlight)
B(7,31,7,minecraft:shroomlight)
B(7,33,7,minecraft:nether_wart_block)
B(7,34,7,minecraft:nether_wart_block)
B(7,35,7,minecraft:nether_wart_block)
B(7,36,7,minecraft:nether_wart_block)
B(7,37,7,minecraft:nether_wart_block)
B(7,38,7,minecraft:nether_wart_block)
B(7,39,7,minecraft:nether_wart_block)
B(7,40,7,minecraft:nether_wart_block)
B(7,41,7,minecraft:nether_wart_block)
B(7,42,7,minecraft:nether_wart_block)
B(7,43,7,minecraft:nether_wart_block)
B(7,44,7,minecraft:nether_wart_block)
B(7,0,8,minecraft:netherrack)
B(7,1,8,minecraft:netherrack)
B(7,33,8,minecraft:nether_wart_block)
B(7,34,8,minecraft:nether_wart_block)
B(7,35,8,minecraft:nether_wart_block)
B(7,36,8,minecraft:nether_wart_block)
B(7,37,8,minecraft:nether_wart_block)
B(7,38,8,minecraft:nether_wart_block)
B(7,39,8,minecraft:nether_wart_block)
B(7,40,8,minecraft:nether_wart_block)
B(7,41,8,minecraft:nether_wart_block)
B(7,42,8,minecraft:nether_wart_block)
B(7,43,8,minecraft:nether_wart_block)
B(7,44,8,minecraft:nether_wart_block)

#######################################################################
# +-----------------------------------------------------------------+ #
# |                             Branches                            | #
# +-----------------------------------------------------------------+ #
#######################################################################

Branch(16,0,0,true,GiantCrimsonTree1_C2_R0,NORTH,100.0,0)

#######################################################################
# +-----------------------------------------------------------------+ #
# |                             Entities                            | #
# +-----------------------------------------------------------------+ #
#######################################################################

