
#######################################################################
# +-----------------------------------------------------------------+ #
# |                            BO4 object                           | #
# +-----------------------------------------------------------------+ #
#######################################################################

Author: Unknown

Description: No description given

SettingsMode: WriteWithoutComments


#######################################################################
# +-----------------------------------------------------------------+ #
# |                          Main settings                          | #
# +-----------------------------------------------------------------+ #
#######################################################################

FixedRotation: 

Frequency: 0

SpawnHeight: highestBlock

UseCenterForHighestBlock: true

##############################
# Height Limits for the BO4. #
##############################

MinHeight: 0

MaxHeight: 255

InheritBO3: 

InheritBO3Rotation: NORTH

OverrideChildSettings: true

OverrideParentHeight: false

CanOverride: false

BranchFrequency: 0

BranchFrequencyGroup: 

MustBeBelowOther: false

MustBeInside: 

CannotBeInside: 

ReplacesBO3: 

MustBeInsideWorldBorders: false

CanSpawnOnWater: true

SpawnOnWaterOnly: false

SpawnUnderWater: false

SpawnAtWaterLevel: false

HeightOffset: 0

RemoveAir: true

ReplaceAbove: 

ReplaceBelow: 

ReplaceWithBiomeBlocks: true

ReplaceWithSurfaceBlock: GRASS

ReplaceWithGroundBlock: DIRT

ReplaceWithStoneBlock: STONE

SmoothRadius: 0

SmoothHeightOffset: 0

SmoothStartTop: false

SmoothStartWood: false

SmoothingSurfaceBlock: 

SmoothingGroundBlock: 

BO3Group: 

IsSpawnPoint: false

DoReplaceBlocks: true


#######################################################################
# +-----------------------------------------------------------------+ #
# |                              Blocks                             | #
# +-----------------------------------------------------------------+ #
#######################################################################

B(-8,24,-7,minecraft:crimson_hyphae)
B(-8,25,-7,minecraft:crimson_hyphae)
B(-8,26,-7,minecraft:crimson_hyphae)
B(-8,27,-7,minecraft:crimson_hyphae)
B(-8,28,-7,minecraft:crimson_hyphae)
B(-8,29,-7,minecraft:crimson_hyphae)
B(-8,30,-7,minecraft:crimson_hyphae)
B(-8,31,-7,minecraft:crimson_hyphae)
B(-8,32,-7,minecraft:crimson_hyphae)
B(-8,33,-7,minecraft:crimson_hyphae)
B(-8,34,-7,minecraft:nether_wart_block)
B(-8,35,-7,minecraft:nether_wart_block)
B(-8,36,-7,minecraft:nether_wart_block)
B(-8,37,-7,minecraft:nether_wart_block)
B(-8,38,-7,minecraft:nether_wart_block)
B(-8,39,-7,minecraft:nether_wart_block)
B(-8,40,-7,minecraft:nether_wart_block)
B(-8,41,-7,minecraft:nether_wart_block)
B(-8,42,-7,minecraft:nether_wart_block)
B(-8,24,-6,minecraft:crimson_hyphae)
B(-8,25,-6,minecraft:crimson_hyphae)
B(-8,26,-6,minecraft:crimson_hyphae)
B(-8,27,-6,minecraft:crimson_hyphae)
B(-8,28,-6,minecraft:crimson_hyphae)
B(-8,29,-6,minecraft:crimson_hyphae)
B(-8,30,-6,minecraft:crimson_hyphae)
B(-8,31,-6,minecraft:crimson_hyphae)
B(-8,32,-6,minecraft:crimson_hyphae)
B(-8,33,-6,minecraft:crimson_hyphae)
B(-8,34,-6,minecraft:nether_wart_block)
B(-8,35,-6,minecraft:nether_wart_block)
B(-8,36,-6,minecraft:nether_wart_block)
B(-8,37,-6,minecraft:nether_wart_block)
B(-8,38,-6,minecraft:nether_wart_block)
B(-8,39,-6,minecraft:nether_wart_block)
B(-8,40,-6,minecraft:nether_wart_block)
B(-8,41,-6,minecraft:nether_wart_block)
B(-8,42,-6,minecraft:nether_wart_block)
B(-8,24,-5,minecraft:crimson_hyphae)
B(-8,25,-5,minecraft:crimson_hyphae)
B(-8,26,-5,minecraft:crimson_hyphae)
B(-8,27,-5,minecraft:crimson_hyphae)
B(-8,28,-5,minecraft:crimson_hyphae)
B(-8,29,-5,minecraft:crimson_hyphae)
B(-8,30,-5,minecraft:crimson_hyphae)
B(-8,34,-5,minecraft:nether_wart_block)
B(-8,35,-5,minecraft:nether_wart_block)
B(-8,36,-5,minecraft:nether_wart_block)
B(-8,37,-5,minecraft:nether_wart_block)
B(-8,38,-5,minecraft:nether_wart_block)
B(-8,39,-5,minecraft:nether_wart_block)
B(-8,40,-5,minecraft:nether_wart_block)
B(-8,41,-5,minecraft:nether_wart_block)
B(-8,42,-5,minecraft:nether_wart_block)
B(-8,34,-4,minecraft:nether_wart_block)
B(-8,35,-4,minecraft:nether_wart_block)
B(-8,36,-4,minecraft:nether_wart_block)
B(-8,37,-4,minecraft:nether_wart_block)
B(-8,38,-4,minecraft:nether_wart_block)
B(-8,39,-4,minecraft:nether_wart_block)
B(-8,40,-4,minecraft:nether_wart_block)
B(-8,41,-4,minecraft:nether_wart_block)
B(-8,42,-4,minecraft:nether_wart_block)
B(-8,34,-3,minecraft:nether_wart_block)
B(-8,35,-3,minecraft:nether_wart_block)
B(-8,36,-3,minecraft:nether_wart_block)
B(-8,37,-3,minecraft:nether_wart_block)
B(-8,38,-3,minecraft:nether_wart_block)
B(-8,39,-3,minecraft:nether_wart_block)
B(-8,40,-3,minecraft:nether_wart_block)
B(-8,41,-3,minecraft:nether_wart_block)
B(-8,42,-3,minecraft:nether_wart_block)
B(-8,32,-2,minecraft:nether_wart_block)
B(-8,33,-2,minecraft:nether_wart_block)
B(-8,34,-2,minecraft:nether_wart_block)
B(-8,35,-2,minecraft:nether_wart_block)
B(-8,36,-2,minecraft:nether_wart_block)
B(-8,37,-2,minecraft:nether_wart_block)
B(-8,38,-2,minecraft:nether_wart_block)
B(-8,39,-2,minecraft:nether_wart_block)
B(-8,40,-2,minecraft:nether_wart_block)
B(-8,41,-2,minecraft:nether_wart_block)
B(-8,42,-2,minecraft:nether_wart_block)
B(-8,32,-1,minecraft:nether_wart_block)
B(-8,33,-1,minecraft:nether_wart_block)
B(-8,34,-1,minecraft:nether_wart_block)
B(-8,35,-1,minecraft:nether_wart_block)
B(-8,36,-1,minecraft:nether_wart_block)
B(-8,37,-1,minecraft:nether_wart_block)
B(-8,38,-1,minecraft:nether_wart_block)
B(-8,39,-1,minecraft:nether_wart_block)
B(-8,40,-1,minecraft:nether_wart_block)
B(-8,41,-1,minecraft:nether_wart_block)
B(-8,31,0,minecraft:nether_wart_block)
B(-8,32,0,minecraft:nether_wart_block)
B(-8,33,0,minecraft:nether_wart_block)
B(-8,34,0,minecraft:nether_wart_block)
B(-8,35,0,minecraft:nether_wart_block)
B(-8,36,0,minecraft:nether_wart_block)
B(-8,37,0,minecraft:nether_wart_block)
B(-8,38,0,minecraft:nether_wart_block)
B(-8,39,0,minecraft:nether_wart_block)
B(-8,40,0,minecraft:nether_wart_block)
B(-8,31,1,minecraft:nether_wart_block)
B(-8,32,1,minecraft:nether_wart_block)
B(-8,33,1,minecraft:nether_wart_block)
B(-8,34,1,minecraft:nether_wart_block)
B(-8,35,1,minecraft:nether_wart_block)
B(-8,36,1,minecraft:nether_wart_block)
B(-8,37,1,minecraft:nether_wart_block)
B(-8,38,1,minecraft:nether_wart_block)
B(-8,39,1,minecraft:nether_wart_block)
B(-8,40,1,minecraft:nether_wart_block)
B(-8,31,2,minecraft:nether_wart_block)
B(-8,32,2,minecraft:nether_wart_block)
B(-8,33,2,minecraft:nether_wart_block)
B(-8,34,2,minecraft:nether_wart_block)
B(-8,35,2,minecraft:nether_wart_block)
B(-8,36,2,minecraft:nether_wart_block)
B(-8,37,2,minecraft:nether_wart_block)
B(-8,38,2,minecraft:nether_wart_block)
B(-8,39,2,minecraft:nether_wart_block)
B(-8,40,2,minecraft:nether_wart_block)
B(-8,28,3,minecraft:crimson_hyphae)
B(-8,29,3,minecraft:crimson_hyphae)
B(-8,30,3,minecraft:crimson_hyphae)
B(-8,31,3,minecraft:nether_wart_block)
B(-8,32,3,minecraft:nether_wart_block)
B(-8,33,3,minecraft:nether_wart_block)
B(-8,34,3,minecraft:nether_wart_block)
B(-8,35,3,minecraft:nether_wart_block)
B(-8,36,3,minecraft:nether_wart_block)
B(-8,37,3,minecraft:nether_wart_block)
B(-8,38,3,minecraft:nether_wart_block)
B(-8,39,3,minecraft:nether_wart_block)
B(-8,40,3,minecraft:nether_wart_block)
B(-8,28,4,minecraft:crimson_hyphae)
B(-8,29,4,minecraft:crimson_hyphae)
B(-8,30,4,minecraft:nether_wart_block)
B(-8,31,4,minecraft:nether_wart_block)
B(-8,32,4,minecraft:nether_wart_block)
B(-8,33,4,minecraft:nether_wart_block)
B(-8,34,4,minecraft:nether_wart_block)
B(-8,35,4,minecraft:nether_wart_block)
B(-8,36,4,minecraft:nether_wart_block)
B(-8,37,4,minecraft:nether_wart_block)
B(-8,38,4,minecraft:nether_wart_block)
B(-8,39,4,minecraft:nether_wart_block)
B(-8,40,4,minecraft:nether_wart_block)
B(-8,28,5,minecraft:crimson_hyphae)
B(-8,29,5,minecraft:crimson_hyphae)
B(-8,30,5,minecraft:nether_wart_block)
B(-8,31,5,minecraft:nether_wart_block)
B(-8,32,5,minecraft:nether_wart_block)
B(-8,33,5,minecraft:nether_wart_block)
B(-8,34,5,minecraft:nether_wart_block)
B(-8,35,5,minecraft:nether_wart_block)
B(-8,36,5,minecraft:nether_wart_block)
B(-8,37,5,minecraft:nether_wart_block)
B(-8,38,5,minecraft:nether_wart_block)
B(-8,39,5,minecraft:nether_wart_block)
B(-8,28,6,minecraft:crimson_hyphae)
B(-8,29,6,minecraft:crimson_hyphae)
B(-8,30,6,minecraft:nether_wart_block)
B(-8,31,6,minecraft:nether_wart_block)
B(-8,32,6,minecraft:nether_wart_block)
B(-8,33,6,minecraft:nether_wart_block)
B(-8,34,6,minecraft:nether_wart_block)
B(-8,35,6,minecraft:nether_wart_block)
B(-8,36,6,minecraft:nether_wart_block)
B(-8,37,6,minecraft:nether_wart_block)
B(-8,38,6,minecraft:nether_wart_block)
B(-8,39,6,minecraft:nether_wart_block)
B(-8,28,7,minecraft:crimson_hyphae)
B(-8,29,7,minecraft:crimson_hyphae)
B(-8,30,7,minecraft:crimson_hyphae)
B(-8,31,7,minecraft:nether_wart_block)
B(-8,32,7,minecraft:nether_wart_block)
B(-8,33,7,minecraft:nether_wart_block)
B(-8,34,7,minecraft:nether_wart_block)
B(-8,35,7,minecraft:nether_wart_block)
B(-8,36,7,minecraft:nether_wart_block)
B(-8,37,7,minecraft:nether_wart_block)
B(-8,38,7,minecraft:nether_wart_block)
B(-8,39,7,minecraft:nether_wart_block)
B(-8,32,8,minecraft:nether_wart_block)
B(-8,33,8,minecraft:nether_wart_block)
B(-8,34,8,minecraft:nether_wart_block)
B(-8,35,8,minecraft:nether_wart_block)
B(-8,36,8,minecraft:nether_wart_block)
B(-8,37,8,minecraft:nether_wart_block)
B(-8,38,8,minecraft:nether_wart_block)
B(-8,39,8,minecraft:nether_wart_block)
B(-7,25,-7,minecraft:crimson_hyphae)
B(-7,26,-7,minecraft:crimson_hyphae)
B(-7,27,-7,minecraft:crimson_hyphae)
B(-7,28,-7,minecraft:crimson_hyphae)
B(-7,29,-7,minecraft:crimson_hyphae)
B(-7,30,-7,minecraft:crimson_hyphae)
B(-7,31,-7,minecraft:crimson_hyphae)
B(-7,32,-7,minecraft:crimson_hyphae)
B(-7,33,-7,minecraft:nether_wart_block)
B(-7,34,-7,minecraft:nether_wart_block)
B(-7,35,-7,minecraft:nether_wart_block)
B(-7,36,-7,minecraft:nether_wart_block)
B(-7,37,-7,minecraft:nether_wart_block)
B(-7,38,-7,minecraft:nether_wart_block)
B(-7,39,-7,minecraft:nether_wart_block)
B(-7,40,-7,minecraft:nether_wart_block)
B(-7,41,-7,minecraft:nether_wart_block)
B(-7,42,-7,minecraft:nether_wart_block)
B(-7,25,-6,minecraft:crimson_hyphae)
B(-7,26,-6,minecraft:crimson_hyphae)
B(-7,27,-6,minecraft:crimson_hyphae)
B(-7,28,-6,minecraft:crimson_hyphae)
B(-7,29,-6,minecraft:crimson_hyphae)
B(-7,30,-6,minecraft:crimson_hyphae)
B(-7,31,-6,minecraft:crimson_hyphae)
B(-7,32,-6,minecraft:crimson_hyphae)
B(-7,33,-6,minecraft:nether_wart_block)
B(-7,34,-6,minecraft:nether_wart_block)
B(-7,35,-6,minecraft:nether_wart_block)
B(-7,36,-6,minecraft:nether_wart_block)
B(-7,37,-6,minecraft:nether_wart_block)
B(-7,38,-6,minecraft:nether_wart_block)
B(-7,39,-6,minecraft:nether_wart_block)
B(-7,40,-6,minecraft:nether_wart_block)
B(-7,41,-6,minecraft:nether_wart_block)
B(-7,42,-6,minecraft:nether_wart_block)
B(-7,33,-5,minecraft:nether_wart_block)
B(-7,34,-5,minecraft:nether_wart_block)
B(-7,35,-5,minecraft:nether_wart_block)
B(-7,36,-5,minecraft:nether_wart_block)
B(-7,37,-5,minecraft:nether_wart_block)
B(-7,38,-5,minecraft:nether_wart_block)
B(-7,39,-5,minecraft:nether_wart_block)
B(-7,40,-5,minecraft:nether_wart_block)
B(-7,41,-5,minecraft:nether_wart_block)
B(-7,42,-5,minecraft:nether_wart_block)
B(-7,33,-4,minecraft:nether_wart_block)
B(-7,34,-4,minecraft:nether_wart_block)
B(-7,35,-4,minecraft:nether_wart_block)
B(-7,36,-4,minecraft:nether_wart_block)
B(-7,37,-4,minecraft:nether_wart_block)
B(-7,38,-4,minecraft:nether_wart_block)
B(-7,39,-4,minecraft:nether_wart_block)
B(-7,40,-4,minecraft:nether_wart_block)
B(-7,41,-4,minecraft:nether_wart_block)
B(-7,31,-3,minecraft:nether_wart_block)
B(-7,32,-3,minecraft:nether_wart_block)
B(-7,33,-3,minecraft:nether_wart_block)
B(-7,34,-3,minecraft:nether_wart_block)
B(-7,35,-3,minecraft:nether_wart_block)
B(-7,36,-3,minecraft:nether_wart_block)
B(-7,37,-3,minecraft:nether_wart_block)
B(-7,38,-3,minecraft:nether_wart_block)
B(-7,39,-3,minecraft:nether_wart_block)
B(-7,40,-3,minecraft:nether_wart_block)
B(-7,41,-3,minecraft:nether_wart_block)
B(-7,31,-2,minecraft:nether_wart_block)
B(-7,32,-2,minecraft:nether_wart_block)
B(-7,33,-2,minecraft:nether_wart_block)
B(-7,34,-2,minecraft:nether_wart_block)
B(-7,35,-2,minecraft:nether_wart_block)
B(-7,36,-2,minecraft:nether_wart_block)
B(-7,37,-2,minecraft:nether_wart_block)
B(-7,38,-2,minecraft:nether_wart_block)
B(-7,39,-2,minecraft:nether_wart_block)
B(-7,40,-2,minecraft:nether_wart_block)
B(-7,41,-2,minecraft:nether_wart_block)
B(-7,31,-1,minecraft:nether_wart_block)
B(-7,32,-1,minecraft:nether_wart_block)
B(-7,33,-1,minecraft:nether_wart_block)
B(-7,34,-1,minecraft:nether_wart_block)
B(-7,35,-1,minecraft:nether_wart_block)
B(-7,36,-1,minecraft:nether_wart_block)
B(-7,37,-1,minecraft:nether_wart_block)
B(-7,38,-1,minecraft:nether_wart_block)
B(-7,39,-1,minecraft:nether_wart_block)
B(-7,40,-1,minecraft:nether_wart_block)
B(-7,41,-1,minecraft:nether_wart_block)
B(-7,31,0,minecraft:nether_wart_block)
B(-7,32,0,minecraft:nether_wart_block)
B(-7,33,0,minecraft:nether_wart_block)
B(-7,34,0,minecraft:nether_wart_block)
B(-7,35,0,minecraft:nether_wart_block)
B(-7,36,0,minecraft:nether_wart_block)
B(-7,37,0,minecraft:nether_wart_block)
B(-7,38,0,minecraft:nether_wart_block)
B(-7,31,1,minecraft:nether_wart_block)
B(-7,32,1,minecraft:nether_wart_block)
B(-7,33,1,minecraft:nether_wart_block)
B(-7,34,1,minecraft:nether_wart_block)
B(-7,35,1,minecraft:nether_wart_block)
B(-7,36,1,minecraft:nether_wart_block)
B(-7,37,1,minecraft:nether_wart_block)
B(-7,38,1,minecraft:nether_wart_block)
B(-7,39,1,minecraft:nether_wart_block)
B(-7,31,2,minecraft:nether_wart_block)
B(-7,32,2,minecraft:nether_wart_block)
B(-7,33,2,minecraft:nether_wart_block)
B(-7,34,2,minecraft:nether_wart_block)
B(-7,35,2,minecraft:nether_wart_block)
B(-7,36,2,minecraft:nether_wart_block)
B(-7,37,2,minecraft:nether_wart_block)
B(-7,38,2,minecraft:nether_wart_block)
B(-7,39,2,minecraft:nether_wart_block)
B(-7,31,3,minecraft:nether_wart_block)
B(-7,32,3,minecraft:nether_wart_block)
B(-7,33,3,minecraft:nether_wart_block)
B(-7,34,3,minecraft:nether_wart_block)
B(-7,35,3,minecraft:nether_wart_block)
B(-7,36,3,minecraft:nether_wart_block)
B(-7,37,3,minecraft:nether_wart_block)
B(-7,38,3,minecraft:nether_wart_block)
B(-7,39,3,minecraft:nether_wart_block)
B(-7,29,4,minecraft:crimson_hyphae)
B(-7,30,4,minecraft:nether_wart_block)
B(-7,31,4,minecraft:nether_wart_block)
B(-7,32,4,minecraft:nether_wart_block)
B(-7,33,4,minecraft:nether_wart_block)
B(-7,34,4,minecraft:nether_wart_block)
B(-7,35,4,minecraft:nether_wart_block)
B(-7,36,4,minecraft:nether_wart_block)
B(-7,37,4,minecraft:nether_wart_block)
B(-7,38,4,minecraft:nether_wart_block)
B(-7,29,5,minecraft:crimson_hyphae)
B(-7,30,5,minecraft:nether_wart_block)
B(-7,31,5,minecraft:nether_wart_block)
B(-7,32,5,minecraft:nether_wart_block)
B(-7,33,5,minecraft:nether_wart_block)
B(-7,34,5,minecraft:nether_wart_block)
B(-7,35,5,minecraft:nether_wart_block)
B(-7,36,5,minecraft:nether_wart_block)
B(-7,37,5,minecraft:nether_wart_block)
B(-7,38,5,minecraft:nether_wart_block)
B(-7,29,6,minecraft:crimson_hyphae)
B(-7,30,6,minecraft:nether_wart_block)
B(-7,31,6,minecraft:nether_wart_block)
B(-7,32,6,minecraft:nether_wart_block)
B(-7,33,6,minecraft:nether_wart_block)
B(-7,34,6,minecraft:nether_wart_block)
B(-7,35,6,minecraft:nether_wart_block)
B(-7,36,6,minecraft:nether_wart_block)
B(-7,37,6,minecraft:nether_wart_block)
B(-7,38,6,minecraft:nether_wart_block)
B(-7,31,7,minecraft:nether_wart_block)
B(-7,32,7,minecraft:nether_wart_block)
B(-7,33,7,minecraft:nether_wart_block)
B(-7,34,7,minecraft:nether_wart_block)
B(-7,35,7,minecraft:nether_wart_block)
B(-7,36,7,minecraft:nether_wart_block)
B(-7,37,7,minecraft:nether_wart_block)
B(-7,38,7,minecraft:nether_wart_block)
B(-7,32,8,minecraft:nether_wart_block)
B(-7,33,8,minecraft:nether_wart_block)
B(-7,34,8,minecraft:nether_wart_block)
B(-7,35,8,minecraft:nether_wart_block)
B(-7,36,8,minecraft:nether_wart_block)
B(-7,37,8,minecraft:nether_wart_block)
B(-7,38,8,minecraft:nether_wart_block)
B(-6,28,-7,minecraft:crimson_hyphae)
B(-6,29,-7,minecraft:crimson_hyphae)
B(-6,30,-7,minecraft:crimson_hyphae)
B(-6,31,-7,minecraft:crimson_hyphae)
B(-6,32,-7,minecraft:nether_wart_block)
B(-6,33,-7,minecraft:nether_wart_block)
B(-6,34,-7,minecraft:nether_wart_block)
B(-6,35,-7,minecraft:nether_wart_block)
B(-6,36,-7,minecraft:nether_wart_block)
B(-6,37,-7,minecraft:nether_wart_block)
B(-6,38,-7,minecraft:nether_wart_block)
B(-6,39,-7,minecraft:nether_wart_block)
B(-6,40,-7,minecraft:nether_wart_block)
B(-6,41,-7,minecraft:nether_wart_block)
B(-6,32,-6,minecraft:nether_wart_block)
B(-6,33,-6,minecraft:nether_wart_block)
B(-6,34,-6,minecraft:nether_wart_block)
B(-6,35,-6,minecraft:nether_wart_block)
B(-6,36,-6,minecraft:nether_wart_block)
B(-6,37,-6,minecraft:nether_wart_block)
B(-6,38,-6,minecraft:nether_wart_block)
B(-6,39,-6,minecraft:nether_wart_block)
B(-6,40,-6,minecraft:nether_wart_block)
B(-6,41,-6,minecraft:nether_wart_block)
B(-6,32,-5,minecraft:nether_wart_block)
B(-6,33,-5,minecraft:nether_wart_block)
B(-6,34,-5,minecraft:nether_wart_block)
B(-6,35,-5,minecraft:nether_wart_block)
B(-6,36,-5,minecraft:nether_wart_block)
B(-6,37,-5,minecraft:nether_wart_block)
B(-6,38,-5,minecraft:nether_wart_block)
B(-6,39,-5,minecraft:nether_wart_block)
B(-6,40,-5,minecraft:nether_wart_block)
B(-6,41,-5,minecraft:nether_wart_block)
B(-6,32,-4,minecraft:nether_wart_block)
B(-6,33,-4,minecraft:nether_wart_block)
B(-6,34,-4,minecraft:nether_wart_block)
B(-6,35,-4,minecraft:nether_wart_block)
B(-6,36,-4,minecraft:nether_wart_block)
B(-6,37,-4,minecraft:nether_wart_block)
B(-6,38,-4,minecraft:nether_wart_block)
B(-6,39,-4,minecraft:nether_wart_block)
B(-6,40,-4,minecraft:nether_wart_block)
B(-6,41,-4,minecraft:nether_wart_block)
B(-6,31,-3,minecraft:nether_wart_block)
B(-6,32,-3,minecraft:nether_wart_block)
B(-6,33,-3,minecraft:nether_wart_block)
B(-6,34,-3,minecraft:nether_wart_block)
B(-6,35,-3,minecraft:nether_wart_block)
B(-6,36,-3,minecraft:nether_wart_block)
B(-6,37,-3,minecraft:nether_wart_block)
B(-6,38,-3,minecraft:nether_wart_block)
B(-6,39,-3,minecraft:nether_wart_block)
B(-6,40,-3,minecraft:nether_wart_block)
B(-6,30,-2,minecraft:nether_wart_block)
B(-6,31,-2,minecraft:nether_wart_block)
B(-6,32,-2,minecraft:nether_wart_block)
B(-6,33,-2,minecraft:nether_wart_block)
B(-6,34,-2,minecraft:nether_wart_block)
B(-6,35,-2,minecraft:nether_wart_block)
B(-6,36,-2,minecraft:nether_wart_block)
B(-6,37,-2,minecraft:nether_wart_block)
B(-6,38,-2,minecraft:nether_wart_block)
B(-6,39,-2,minecraft:nether_wart_block)
B(-6,40,-2,minecraft:nether_wart_block)
B(-6,30,-1,minecraft:nether_wart_block)
B(-6,31,-1,minecraft:nether_wart_block)
B(-6,32,-1,minecraft:nether_wart_block)
B(-6,33,-1,minecraft:nether_wart_block)
B(-6,34,-1,minecraft:nether_wart_block)
B(-6,35,-1,minecraft:nether_wart_block)
B(-6,36,-1,minecraft:nether_wart_block)
B(-6,37,-1,minecraft:nether_wart_block)
B(-6,38,-1,minecraft:nether_wart_block)
B(-6,39,-1,minecraft:nether_wart_block)
B(-6,30,0,minecraft:shroomlight)
B(-6,31,0,minecraft:shroomlight)
B(-6,32,0,minecraft:shroomlight)
B(-6,33,0,minecraft:nether_wart_block)
B(-6,34,0,minecraft:nether_wart_block)
B(-6,35,0,minecraft:nether_wart_block)
B(-6,36,0,minecraft:nether_wart_block)
B(-6,37,0,minecraft:nether_wart_block)
B(-6,38,0,minecraft:nether_wart_block)
B(-6,30,1,minecraft:shroomlight)
B(-6,31,1,minecraft:shroomlight)
B(-6,32,1,minecraft:shroomlight)
B(-6,33,1,minecraft:nether_wart_block)
B(-6,34,1,minecraft:nether_wart_block)
B(-6,35,1,minecraft:nether_wart_block)
B(-6,36,1,minecraft:nether_wart_block)
B(-6,37,1,minecraft:nether_wart_block)
B(-6,30,2,minecraft:shroomlight)
B(-6,31,2,minecraft:shroomlight)
B(-6,32,2,minecraft:shroomlight)
B(-6,33,2,minecraft:nether_wart_block)
B(-6,34,2,minecraft:nether_wart_block)
B(-6,35,2,minecraft:nether_wart_block)
B(-6,36,2,minecraft:nether_wart_block)
B(-6,37,2,minecraft:nether_wart_block)
B(-6,31,3,minecraft:nether_wart_block)
B(-6,32,3,minecraft:nether_wart_block)
B(-6,33,3,minecraft:nether_wart_block)
B(-6,34,3,minecraft:nether_wart_block)
B(-6,35,3,minecraft:nether_wart_block)
B(-6,36,3,minecraft:nether_wart_block)
B(-6,37,3,minecraft:nether_wart_block)
B(-6,30,4,minecraft:nether_wart_block)
B(-6,31,4,minecraft:nether_wart_block)
B(-6,32,4,minecraft:nether_wart_block)
B(-6,33,4,minecraft:nether_wart_block)
B(-6,34,4,minecraft:nether_wart_block)
B(-6,35,4,minecraft:nether_wart_block)
B(-6,36,4,minecraft:nether_wart_block)
B(-6,37,4,minecraft:nether_wart_block)
B(-6,30,5,minecraft:nether_wart_block)
B(-6,31,5,minecraft:nether_wart_block)
B(-6,32,5,minecraft:nether_wart_block)
B(-6,33,5,minecraft:nether_wart_block)
B(-6,34,5,minecraft:nether_wart_block)
B(-6,35,5,minecraft:nether_wart_block)
B(-6,36,5,minecraft:nether_wart_block)
B(-6,37,5,minecraft:nether_wart_block)
B(-6,30,6,minecraft:nether_wart_block)
B(-6,31,6,minecraft:nether_wart_block)
B(-6,32,6,minecraft:nether_wart_block)
B(-6,33,6,minecraft:nether_wart_block)
B(-6,34,6,minecraft:nether_wart_block)
B(-6,35,6,minecraft:nether_wart_block)
B(-6,36,6,minecraft:nether_wart_block)
B(-6,37,6,minecraft:nether_wart_block)
B(-6,31,7,minecraft:nether_wart_block)
B(-6,32,7,minecraft:nether_wart_block)
B(-6,33,7,minecraft:nether_wart_block)
B(-6,34,7,minecraft:nether_wart_block)
B(-6,35,7,minecraft:nether_wart_block)
B(-6,36,7,minecraft:nether_wart_block)
B(-6,37,7,minecraft:nether_wart_block)
B(-6,31,8,minecraft:nether_wart_block)
B(-6,32,8,minecraft:nether_wart_block)
B(-6,33,8,minecraft:nether_wart_block)
B(-6,34,8,minecraft:nether_wart_block)
B(-6,35,8,minecraft:nether_wart_block)
B(-6,36,8,minecraft:nether_wart_block)
B(-6,37,8,minecraft:nether_wart_block)
B(-5,23,-7,minecraft:weeping_vines[age=10])
B(-5,24,-7,minecraft:weeping_vines_plant)
B(-5,25,-7,minecraft:weeping_vines_plant)
B(-5,26,-7,minecraft:weeping_vines_plant)
B(-5,27,-7,minecraft:weeping_vines_plant)
B(-5,28,-7,minecraft:weeping_vines_plant)
B(-5,29,-7,minecraft:weeping_vines_plant)
B(-5,30,-7,minecraft:weeping_vines_plant)
B(-5,31,-7,minecraft:weeping_vines_plant)
B(-5,32,-7,minecraft:nether_wart_block)
B(-5,33,-7,minecraft:nether_wart_block)
B(-5,34,-7,minecraft:nether_wart_block)
B(-5,35,-7,minecraft:nether_wart_block)
B(-5,36,-7,minecraft:nether_wart_block)
B(-5,37,-7,minecraft:nether_wart_block)
B(-5,38,-7,minecraft:nether_wart_block)
B(-5,39,-7,minecraft:nether_wart_block)
B(-5,40,-7,minecraft:nether_wart_block)
B(-5,32,-6,minecraft:nether_wart_block)
B(-5,33,-6,minecraft:nether_wart_block)
B(-5,34,-6,minecraft:nether_wart_block)
B(-5,35,-6,minecraft:nether_wart_block)
B(-5,36,-6,minecraft:nether_wart_block)
B(-5,37,-6,minecraft:nether_wart_block)
B(-5,38,-6,minecraft:nether_wart_block)
B(-5,39,-6,minecraft:nether_wart_block)
B(-5,40,-6,minecraft:nether_wart_block)
B(-5,14,-5,minecraft:weeping_vines[age=23])
B(-5,15,-5,minecraft:weeping_vines_plant)
B(-5,16,-5,minecraft:weeping_vines_plant)
B(-5,17,-5,minecraft:weeping_vines_plant)
B(-5,18,-5,minecraft:weeping_vines_plant)
B(-5,19,-5,minecraft:weeping_vines_plant)
B(-5,20,-5,minecraft:weeping_vines_plant)
B(-5,21,-5,minecraft:weeping_vines_plant)
B(-5,22,-5,minecraft:weeping_vines_plant)
B(-5,23,-5,minecraft:weeping_vines_plant)
B(-5,24,-5,minecraft:weeping_vines_plant)
B(-5,25,-5,minecraft:weeping_vines_plant)
B(-5,26,-5,minecraft:weeping_vines_plant)
B(-5,27,-5,minecraft:weeping_vines_plant)
B(-5,28,-5,minecraft:weeping_vines_plant)
B(-5,29,-5,minecraft:weeping_vines_plant)
B(-5,30,-5,minecraft:weeping_vines_plant)
B(-5,31,-5,minecraft:weeping_vines_plant)
B(-5,32,-5,minecraft:nether_wart_block)
B(-5,33,-5,minecraft:nether_wart_block)
B(-5,34,-5,minecraft:nether_wart_block)
B(-5,35,-5,minecraft:nether_wart_block)
B(-5,36,-5,minecraft:nether_wart_block)
B(-5,37,-5,minecraft:nether_wart_block)
B(-5,38,-5,minecraft:nether_wart_block)
B(-5,39,-5,minecraft:nether_wart_block)
B(-5,40,-5,minecraft:nether_wart_block)
B(-5,32,-4,minecraft:nether_wart_block)
B(-5,33,-4,minecraft:nether_wart_block)
B(-5,34,-4,minecraft:nether_wart_block)
B(-5,35,-4,minecraft:nether_wart_block)
B(-5,36,-4,minecraft:nether_wart_block)
B(-5,37,-4,minecraft:nether_wart_block)
B(-5,38,-4,minecraft:nether_wart_block)
B(-5,39,-4,minecraft:nether_wart_block)
B(-5,31,-3,minecraft:nether_wart_block)
B(-5,32,-3,minecraft:nether_wart_block)
B(-5,33,-3,minecraft:nether_wart_block)
B(-5,34,-3,minecraft:nether_wart_block)
B(-5,35,-3,minecraft:nether_wart_block)
B(-5,36,-3,minecraft:nether_wart_block)
B(-5,37,-3,minecraft:nether_wart_block)
B(-5,38,-3,minecraft:nether_wart_block)
B(-5,39,-3,minecraft:nether_wart_block)
B(-5,30,-2,minecraft:nether_wart_block)
B(-5,31,-2,minecraft:nether_wart_block)
B(-5,32,-2,minecraft:nether_wart_block)
B(-5,33,-2,minecraft:nether_wart_block)
B(-5,34,-2,minecraft:nether_wart_block)
B(-5,35,-2,minecraft:nether_wart_block)
B(-5,36,-2,minecraft:nether_wart_block)
B(-5,37,-2,minecraft:nether_wart_block)
B(-5,38,-2,minecraft:nether_wart_block)
B(-5,39,-2,minecraft:nether_wart_block)
B(-5,30,-1,minecraft:shroomlight)
B(-5,31,-1,minecraft:shroomlight)
B(-5,32,-1,minecraft:shroomlight)
B(-5,33,-1,minecraft:nether_wart_block)
B(-5,34,-1,minecraft:nether_wart_block)
B(-5,35,-1,minecraft:nether_wart_block)
B(-5,36,-1,minecraft:nether_wart_block)
B(-5,37,-1,minecraft:nether_wart_block)
B(-5,38,-1,minecraft:nether_wart_block)
B(-5,39,-1,minecraft:nether_wart_block)
B(-5,29,0,minecraft:shroomlight)
B(-5,30,0,minecraft:shroomlight)
B(-5,31,0,minecraft:shroomlight)
B(-5,32,0,minecraft:shroomlight)
B(-5,33,0,minecraft:shroomlight)
B(-5,34,0,minecraft:nether_wart_block)
B(-5,35,0,minecraft:nether_wart_block)
B(-5,36,0,minecraft:nether_wart_block)
B(-5,37,0,minecraft:nether_wart_block)
B(-5,29,1,minecraft:shroomlight)
B(-5,30,1,minecraft:shroomlight)
B(-5,31,1,minecraft:shroomlight)
B(-5,32,1,minecraft:shroomlight)
B(-5,33,1,minecraft:shroomlight)
B(-5,34,1,minecraft:nether_wart_block)
B(-5,35,1,minecraft:nether_wart_block)
B(-5,36,1,minecraft:nether_wart_block)
B(-5,37,1,minecraft:nether_wart_block)
B(-5,38,1,minecraft:nether_wart_block)
B(-5,29,2,minecraft:shroomlight)
B(-5,30,2,minecraft:shroomlight)
B(-5,31,2,minecraft:shroomlight)
B(-5,32,2,minecraft:shroomlight)
B(-5,33,2,minecraft:shroomlight)
B(-5,34,2,minecraft:nether_wart_block)
B(-5,35,2,minecraft:nether_wart_block)
B(-5,36,2,minecraft:nether_wart_block)
B(-5,37,2,minecraft:nether_wart_block)
B(-5,38,2,minecraft:nether_wart_block)
B(-5,30,3,minecraft:shroomlight)
B(-5,31,3,minecraft:shroomlight)
B(-5,32,3,minecraft:shroomlight)
B(-5,33,3,minecraft:nether_wart_block)
B(-5,34,3,minecraft:nether_wart_block)
B(-5,35,3,minecraft:nether_wart_block)
B(-5,36,3,minecraft:nether_wart_block)
B(-5,37,3,minecraft:nether_wart_block)
B(-5,38,3,minecraft:nether_wart_block)
B(-5,31,4,minecraft:nether_wart_block)
B(-5,32,4,minecraft:nether_wart_block)
B(-5,33,4,minecraft:nether_wart_block)
B(-5,34,4,minecraft:nether_wart_block)
B(-5,35,4,minecraft:nether_wart_block)
B(-5,36,4,minecraft:nether_wart_block)
B(-5,37,4,minecraft:nether_wart_block)
B(-5,30,5,minecraft:nether_wart_block)
B(-5,31,5,minecraft:nether_wart_block)
B(-5,32,5,minecraft:nether_wart_block)
B(-5,33,5,minecraft:nether_wart_block)
B(-5,34,5,minecraft:nether_wart_block)
B(-5,35,5,minecraft:nether_wart_block)
B(-5,36,5,minecraft:nether_wart_block)
B(-5,30,6,minecraft:nether_wart_block)
B(-5,31,6,minecraft:nether_wart_block)
B(-5,32,6,minecraft:nether_wart_block)
B(-5,33,6,minecraft:nether_wart_block)
B(-5,34,6,minecraft:nether_wart_block)
B(-5,35,6,minecraft:nether_wart_block)
B(-5,36,6,minecraft:nether_wart_block)
B(-5,30,7,minecraft:nether_wart_block)
B(-5,31,7,minecraft:nether_wart_block)
B(-5,32,7,minecraft:nether_wart_block)
B(-5,33,7,minecraft:nether_wart_block)
B(-5,34,7,minecraft:nether_wart_block)
B(-5,35,7,minecraft:nether_wart_block)
B(-5,36,7,minecraft:nether_wart_block)
B(-5,30,8,minecraft:nether_wart_block)
B(-5,31,8,minecraft:nether_wart_block)
B(-5,32,8,minecraft:nether_wart_block)
B(-5,33,8,minecraft:nether_wart_block)
B(-5,34,8,minecraft:nether_wart_block)
B(-5,35,8,minecraft:nether_wart_block)
B(-5,36,8,minecraft:nether_wart_block)
B(-4,32,-7,minecraft:nether_wart_block)
B(-4,33,-7,minecraft:nether_wart_block)
B(-4,34,-7,minecraft:nether_wart_block)
B(-4,35,-7,minecraft:nether_wart_block)
B(-4,36,-7,minecraft:nether_wart_block)
B(-4,37,-7,minecraft:nether_wart_block)
B(-4,38,-7,minecraft:nether_wart_block)
B(-4,32,-6,minecraft:nether_wart_block)
B(-4,33,-6,minecraft:nether_wart_block)
B(-4,34,-6,minecraft:nether_wart_block)
B(-4,35,-6,minecraft:nether_wart_block)
B(-4,36,-6,minecraft:nether_wart_block)
B(-4,37,-6,minecraft:nether_wart_block)
B(-4,38,-6,minecraft:nether_wart_block)
B(-4,20,-5,minecraft:weeping_vines[age=12])
B(-4,21,-5,minecraft:weeping_vines_plant)
B(-4,22,-5,minecraft:weeping_vines_plant)
B(-4,23,-5,minecraft:weeping_vines_plant)
B(-4,24,-5,minecraft:weeping_vines_plant)
B(-4,25,-5,minecraft:weeping_vines_plant)
B(-4,26,-5,minecraft:weeping_vines_plant)
B(-4,27,-5,minecraft:weeping_vines_plant)
B(-4,28,-5,minecraft:weeping_vines_plant)
B(-4,29,-5,minecraft:weeping_vines_plant)
B(-4,30,-5,minecraft:weeping_vines_plant)
B(-4,31,-5,minecraft:weeping_vines_plant)
B(-4,32,-5,minecraft:nether_wart_block)
B(-4,33,-5,minecraft:nether_wart_block)
B(-4,34,-5,minecraft:nether_wart_block)
B(-4,35,-5,minecraft:nether_wart_block)
B(-4,36,-5,minecraft:nether_wart_block)
B(-4,37,-5,minecraft:nether_wart_block)
B(-4,38,-5,minecraft:nether_wart_block)
B(-4,32,-4,minecraft:nether_wart_block)
B(-4,33,-4,minecraft:nether_wart_block)
B(-4,34,-4,minecraft:nether_wart_block)
B(-4,35,-4,minecraft:nether_wart_block)
B(-4,36,-4,minecraft:nether_wart_block)
B(-4,37,-4,minecraft:nether_wart_block)
B(-4,38,-4,minecraft:nether_wart_block)
B(-4,22,-3,minecraft:weeping_vines[age=16])
B(-4,23,-3,minecraft:weeping_vines_plant)
B(-4,24,-3,minecraft:weeping_vines_plant)
B(-4,25,-3,minecraft:weeping_vines_plant)
B(-4,26,-3,minecraft:weeping_vines_plant)
B(-4,27,-3,minecraft:weeping_vines_plant)
B(-4,28,-3,minecraft:weeping_vines_plant)
B(-4,29,-3,minecraft:weeping_vines_plant)
B(-4,30,-3,minecraft:weeping_vines_plant)
B(-4,31,-3,minecraft:nether_wart_block)
B(-4,32,-3,minecraft:nether_wart_block)
B(-4,33,-3,minecraft:nether_wart_block)
B(-4,34,-3,minecraft:nether_wart_block)
B(-4,35,-3,minecraft:nether_wart_block)
B(-4,36,-3,minecraft:nether_wart_block)
B(-4,37,-3,minecraft:nether_wart_block)
B(-4,38,-3,minecraft:nether_wart_block)
B(-4,30,-2,minecraft:nether_wart_block)
B(-4,31,-2,minecraft:nether_wart_block)
B(-4,32,-2,minecraft:nether_wart_block)
B(-4,33,-2,minecraft:nether_wart_block)
B(-4,34,-2,minecraft:nether_wart_block)
B(-4,35,-2,minecraft:nether_wart_block)
B(-4,36,-2,minecraft:nether_wart_block)
B(-4,37,-2,minecraft:nether_wart_block)
B(-4,38,-2,minecraft:nether_wart_block)
B(-4,30,-1,minecraft:shroomlight)
B(-4,31,-1,minecraft:shroomlight)
B(-4,32,-1,minecraft:shroomlight)
B(-4,33,-1,minecraft:nether_wart_block)
B(-4,34,-1,minecraft:nether_wart_block)
B(-4,35,-1,minecraft:nether_wart_block)
B(-4,36,-1,minecraft:nether_wart_block)
B(-4,29,0,minecraft:shroomlight)
B(-4,30,0,minecraft:shroomlight)
B(-4,31,0,minecraft:shroomlight)
B(-4,32,0,minecraft:shroomlight)
B(-4,33,0,minecraft:shroomlight)
B(-4,34,0,minecraft:nether_wart_block)
B(-4,35,0,minecraft:nether_wart_block)
B(-4,36,0,minecraft:nether_wart_block)
B(-4,37,0,minecraft:nether_wart_block)
B(-4,29,1,minecraft:shroomlight)
B(-4,30,1,minecraft:shroomlight)
B(-4,31,1,minecraft:shroomlight)
B(-4,32,1,minecraft:shroomlight)
B(-4,33,1,minecraft:shroomlight)
B(-4,34,1,minecraft:nether_wart_block)
B(-4,35,1,minecraft:nether_wart_block)
B(-4,36,1,minecraft:nether_wart_block)
B(-4,37,1,minecraft:nether_wart_block)
B(-4,38,1,minecraft:nether_wart_block)
B(-4,29,2,minecraft:shroomlight)
B(-4,30,2,minecraft:shroomlight)
B(-4,31,2,minecraft:shroomlight)
B(-4,32,2,minecraft:shroomlight)
B(-4,33,2,minecraft:shroomlight)
B(-4,34,2,minecraft:nether_wart_block)
B(-4,35,2,minecraft:nether_wart_block)
B(-4,36,2,minecraft:nether_wart_block)
B(-4,37,2,minecraft:nether_wart_block)
B(-4,38,2,minecraft:nether_wart_block)
B(-4,30,3,minecraft:shroomlight)
B(-4,31,3,minecraft:shroomlight)
B(-4,32,3,minecraft:shroomlight)
B(-4,33,3,minecraft:nether_wart_block)
B(-4,34,3,minecraft:nether_wart_block)
B(-4,35,3,minecraft:nether_wart_block)
B(-4,36,3,minecraft:nether_wart_block)
B(-4,37,3,minecraft:nether_wart_block)
B(-4,38,3,minecraft:nether_wart_block)
B(-4,31,4,minecraft:nether_wart_block)
B(-4,32,4,minecraft:nether_wart_block)
B(-4,33,4,minecraft:nether_wart_block)
B(-4,34,4,minecraft:nether_wart_block)
B(-4,35,4,minecraft:nether_wart_block)
B(-4,36,4,minecraft:nether_wart_block)
B(-4,37,4,minecraft:nether_wart_block)
B(-4,29,5,minecraft:nether_wart_block)
B(-4,30,5,minecraft:nether_wart_block)
B(-4,31,5,minecraft:nether_wart_block)
B(-4,32,5,minecraft:nether_wart_block)
B(-4,33,5,minecraft:nether_wart_block)
B(-4,34,5,minecraft:nether_wart_block)
B(-4,35,5,minecraft:nether_wart_block)
B(-4,36,5,minecraft:nether_wart_block)
B(-4,29,6,minecraft:nether_wart_block)
B(-4,30,6,minecraft:nether_wart_block)
B(-4,31,6,minecraft:nether_wart_block)
B(-4,32,6,minecraft:nether_wart_block)
B(-4,33,6,minecraft:nether_wart_block)
B(-4,34,6,minecraft:nether_wart_block)
B(-4,35,6,minecraft:nether_wart_block)
B(-4,36,6,minecraft:nether_wart_block)
B(-4,29,7,minecraft:nether_wart_block)
B(-4,30,7,minecraft:nether_wart_block)
B(-4,31,7,minecraft:nether_wart_block)
B(-4,32,7,minecraft:nether_wart_block)
B(-4,33,7,minecraft:nether_wart_block)
B(-4,34,7,minecraft:nether_wart_block)
B(-4,35,7,minecraft:nether_wart_block)
B(-4,36,7,minecraft:nether_wart_block)
B(-4,29,8,minecraft:nether_wart_block)
B(-4,30,8,minecraft:nether_wart_block)
B(-4,31,8,minecraft:nether_wart_block)
B(-4,32,8,minecraft:nether_wart_block)
B(-4,33,8,minecraft:nether_wart_block)
B(-4,34,8,minecraft:nether_wart_block)
B(-4,35,8,minecraft:nether_wart_block)
B(-3,33,-7,minecraft:nether_wart_block)
B(-3,34,-7,minecraft:nether_wart_block)
B(-3,35,-7,minecraft:nether_wart_block)
B(-3,36,-7,minecraft:nether_wart_block)
B(-3,37,-7,minecraft:nether_wart_block)
B(-3,38,-7,minecraft:nether_wart_block)
B(-3,33,-6,minecraft:nether_wart_block)
B(-3,34,-6,minecraft:nether_wart_block)
B(-3,35,-6,minecraft:nether_wart_block)
B(-3,36,-6,minecraft:nether_wart_block)
B(-3,37,-6,minecraft:nether_wart_block)
B(-3,33,-5,minecraft:nether_wart_block)
B(-3,34,-5,minecraft:nether_wart_block)
B(-3,35,-5,minecraft:nether_wart_block)
B(-3,36,-5,minecraft:nether_wart_block)
B(-3,37,-5,minecraft:nether_wart_block)
B(-3,33,-4,minecraft:nether_wart_block)
B(-3,34,-4,minecraft:nether_wart_block)
B(-3,35,-4,minecraft:nether_wart_block)
B(-3,36,-4,minecraft:nether_wart_block)
B(-3,37,-4,minecraft:nether_wart_block)
B(-3,31,-3,minecraft:nether_wart_block)
B(-3,32,-3,minecraft:nether_wart_block)
B(-3,33,-3,minecraft:nether_wart_block)
B(-3,34,-3,minecraft:nether_wart_block)
B(-3,35,-3,minecraft:nether_wart_block)
B(-3,31,-2,minecraft:nether_wart_block)
B(-3,32,-2,minecraft:nether_wart_block)
B(-3,33,-2,minecraft:nether_wart_block)
B(-3,34,-2,minecraft:nether_wart_block)
B(-3,35,-2,minecraft:nether_wart_block)
B(-3,30,-1,minecraft:shroomlight)
B(-3,31,-1,minecraft:shroomlight)
B(-3,32,-1,minecraft:shroomlight)
B(-3,33,-1,minecraft:nether_wart_block)
B(-3,34,-1,minecraft:nether_wart_block)
B(-3,35,-1,minecraft:nether_wart_block)
B(-3,36,-1,minecraft:nether_wart_block)
B(-3,29,0,minecraft:shroomlight)
B(-3,30,0,minecraft:shroomlight)
B(-3,31,0,minecraft:shroomlight)
B(-3,32,0,minecraft:shroomlight)
B(-3,33,0,minecraft:shroomlight)
B(-3,34,0,minecraft:nether_wart_block)
B(-3,35,0,minecraft:nether_wart_block)
B(-3,36,0,minecraft:nether_wart_block)
B(-3,37,0,minecraft:nether_wart_block)
B(-3,29,1,minecraft:shroomlight)
B(-3,30,1,minecraft:shroomlight)
B(-3,31,1,minecraft:shroomlight)
B(-3,32,1,minecraft:shroomlight)
B(-3,33,1,minecraft:shroomlight)
B(-3,34,1,minecraft:nether_wart_block)
B(-3,35,1,minecraft:nether_wart_block)
B(-3,36,1,minecraft:nether_wart_block)
B(-3,37,1,minecraft:nether_wart_block)
B(-3,38,1,minecraft:nether_wart_block)
B(-3,29,2,minecraft:shroomlight)
B(-3,30,2,minecraft:shroomlight)
B(-3,31,2,minecraft:shroomlight)
B(-3,32,2,minecraft:shroomlight)
B(-3,33,2,minecraft:shroomlight)
B(-3,34,2,minecraft:nether_wart_block)
B(-3,35,2,minecraft:nether_wart_block)
B(-3,36,2,minecraft:nether_wart_block)
B(-3,37,2,minecraft:nether_wart_block)
B(-3,38,2,minecraft:nether_wart_block)
B(-3,30,3,minecraft:shroomlight)
B(-3,31,3,minecraft:shroomlight)
B(-3,32,3,minecraft:shroomlight)
B(-3,33,3,minecraft:nether_wart_block)
B(-3,34,3,minecraft:nether_wart_block)
B(-3,35,3,minecraft:nether_wart_block)
B(-3,36,3,minecraft:nether_wart_block)
B(-3,37,3,minecraft:nether_wart_block)
B(-3,38,3,minecraft:nether_wart_block)
B(-3,30,4,minecraft:nether_wart_block)
B(-3,31,4,minecraft:nether_wart_block)
B(-3,32,4,minecraft:nether_wart_block)
B(-3,33,4,minecraft:nether_wart_block)
B(-3,34,4,minecraft:nether_wart_block)
B(-3,35,4,minecraft:nether_wart_block)
B(-3,36,4,minecraft:nether_wart_block)
B(-3,37,4,minecraft:nether_wart_block)
B(-3,29,5,minecraft:nether_wart_block)
B(-3,30,5,minecraft:nether_wart_block)
B(-3,31,5,minecraft:nether_wart_block)
B(-3,32,5,minecraft:nether_wart_block)
B(-3,33,5,minecraft:nether_wart_block)
B(-3,34,5,minecraft:nether_wart_block)
B(-3,35,5,minecraft:nether_wart_block)
B(-3,36,5,minecraft:nether_wart_block)
B(-3,28,6,minecraft:nether_wart_block)
B(-3,29,6,minecraft:nether_wart_block)
B(-3,30,6,minecraft:nether_wart_block)
B(-3,31,6,minecraft:nether_wart_block)
B(-3,32,6,minecraft:nether_wart_block)
B(-3,33,6,minecraft:nether_wart_block)
B(-3,34,6,minecraft:nether_wart_block)
B(-3,35,6,minecraft:nether_wart_block)
B(-3,36,6,minecraft:nether_wart_block)
B(-3,28,7,minecraft:nether_wart_block)
B(-3,29,7,minecraft:nether_wart_block)
B(-3,30,7,minecraft:nether_wart_block)
B(-3,31,7,minecraft:nether_wart_block)
B(-3,32,7,minecraft:nether_wart_block)
B(-3,33,7,minecraft:nether_wart_block)
B(-3,34,7,minecraft:nether_wart_block)
B(-3,35,7,minecraft:nether_wart_block)
B(-3,36,7,minecraft:nether_wart_block)
B(-3,28,8,minecraft:nether_wart_block)
B(-3,29,8,minecraft:nether_wart_block)
B(-3,30,8,minecraft:nether_wart_block)
B(-3,31,8,minecraft:nether_wart_block)
B(-3,32,8,minecraft:nether_wart_block)
B(-3,33,8,minecraft:nether_wart_block)
B(-3,34,8,minecraft:nether_wart_block)
B(-3,35,8,minecraft:nether_wart_block)
B(-2,34,-7,minecraft:nether_wart_block)
B(-2,35,-7,minecraft:nether_wart_block)
B(-2,36,-7,minecraft:nether_wart_block)
B(-2,34,-6,minecraft:nether_wart_block)
B(-2,35,-6,minecraft:nether_wart_block)
B(-2,36,-6,minecraft:nether_wart_block)
B(-2,34,-5,minecraft:nether_wart_block)
B(-2,35,-5,minecraft:nether_wart_block)
B(-2,36,-5,minecraft:nether_wart_block)
B(-2,32,-2,minecraft:nether_wart_block)
B(-2,33,-2,minecraft:nether_wart_block)
B(-2,34,-2,minecraft:nether_wart_block)
B(-2,32,-1,minecraft:nether_wart_block)
B(-2,33,-1,minecraft:nether_wart_block)
B(-2,34,-1,minecraft:nether_wart_block)
B(-2,30,0,minecraft:shroomlight)
B(-2,31,0,minecraft:shroomlight)
B(-2,32,0,minecraft:shroomlight)
B(-2,33,0,minecraft:nether_wart_block)
B(-2,34,0,minecraft:nether_wart_block)
B(-2,35,0,minecraft:nether_wart_block)
B(-2,36,0,minecraft:nether_wart_block)
B(-2,37,0,minecraft:nether_wart_block)
B(-2,30,1,minecraft:shroomlight)
B(-2,31,1,minecraft:shroomlight)
B(-2,32,1,minecraft:shroomlight)
B(-2,33,1,minecraft:nether_wart_block)
B(-2,34,1,minecraft:nether_wart_block)
B(-2,35,1,minecraft:nether_wart_block)
B(-2,36,1,minecraft:nether_wart_block)
B(-2,37,1,minecraft:nether_wart_block)
B(-2,30,2,minecraft:shroomlight)
B(-2,31,2,minecraft:shroomlight)
B(-2,32,2,minecraft:shroomlight)
B(-2,33,2,minecraft:nether_wart_block)
B(-2,34,2,minecraft:nether_wart_block)
B(-2,35,2,minecraft:nether_wart_block)
B(-2,36,2,minecraft:nether_wart_block)
B(-2,37,2,minecraft:nether_wart_block)
B(-2,33,3,minecraft:nether_wart_block)
B(-2,34,3,minecraft:nether_wart_block)
B(-2,35,3,minecraft:nether_wart_block)
B(-2,36,3,minecraft:nether_wart_block)
B(-2,37,3,minecraft:nether_wart_block)
B(-2,19,4,minecraft:weeping_vines[age=21])
B(-2,20,4,minecraft:weeping_vines_plant)
B(-2,21,4,minecraft:weeping_vines_plant)
B(-2,22,4,minecraft:weeping_vines_plant)
B(-2,23,4,minecraft:weeping_vines_plant)
B(-2,24,4,minecraft:weeping_vines_plant)
B(-2,25,4,minecraft:weeping_vines_plant)
B(-2,26,4,minecraft:weeping_vines_plant)
B(-2,27,4,minecraft:weeping_vines_plant)
B(-2,28,4,minecraft:weeping_vines_plant)
B(-2,29,4,minecraft:weeping_vines_plant)
B(-2,30,4,minecraft:nether_wart_block)
B(-2,31,4,minecraft:nether_wart_block)
B(-2,32,4,minecraft:nether_wart_block)
B(-2,33,4,minecraft:nether_wart_block)
B(-2,34,4,minecraft:nether_wart_block)
B(-2,35,4,minecraft:nether_wart_block)
B(-2,36,4,minecraft:nether_wart_block)
B(-2,37,4,minecraft:nether_wart_block)
B(-2,29,5,minecraft:nether_wart_block)
B(-2,30,5,minecraft:nether_wart_block)
B(-2,31,5,minecraft:nether_wart_block)
B(-2,32,5,minecraft:nether_wart_block)
B(-2,33,5,minecraft:nether_wart_block)
B(-2,34,5,minecraft:nether_wart_block)
B(-2,35,5,minecraft:nether_wart_block)
B(-2,28,6,minecraft:nether_wart_block)
B(-2,29,6,minecraft:nether_wart_block)
B(-2,30,6,minecraft:nether_wart_block)
B(-2,31,6,minecraft:nether_wart_block)
B(-2,32,6,minecraft:nether_wart_block)
B(-2,33,6,minecraft:nether_wart_block)
B(-2,34,6,minecraft:nether_wart_block)
B(-2,35,6,minecraft:nether_wart_block)
B(-2,28,7,minecraft:nether_wart_block)
B(-2,29,7,minecraft:nether_wart_block)
B(-2,30,7,minecraft:nether_wart_block)
B(-2,31,7,minecraft:nether_wart_block)
B(-2,32,7,minecraft:nether_wart_block)
B(-2,33,7,minecraft:nether_wart_block)
B(-2,34,7,minecraft:nether_wart_block)
B(-2,35,7,minecraft:nether_wart_block)
B(-2,28,8,minecraft:nether_wart_block)
B(-2,29,8,minecraft:nether_wart_block)
B(-2,30,8,minecraft:nether_wart_block)
B(-2,31,8,minecraft:nether_wart_block)
B(-2,32,8,minecraft:nether_wart_block)
B(-2,33,8,minecraft:nether_wart_block)
B(-2,34,8,minecraft:nether_wart_block)
B(-2,35,8,minecraft:nether_wart_block)
B(-1,34,1,minecraft:nether_wart_block)
B(-1,35,1,minecraft:nether_wart_block)
B(-1,36,1,minecraft:nether_wart_block)
B(-1,34,2,minecraft:nether_wart_block)
B(-1,35,2,minecraft:nether_wart_block)
B(-1,36,2,minecraft:nether_wart_block)
B(-1,34,3,minecraft:nether_wart_block)
B(-1,35,3,minecraft:nether_wart_block)
B(-1,36,3,minecraft:nether_wart_block)
B(-1,30,4,minecraft:nether_wart_block)
B(-1,31,4,minecraft:nether_wart_block)
B(-1,32,4,minecraft:nether_wart_block)
B(-1,29,5,minecraft:nether_wart_block)
B(-1,30,5,minecraft:nether_wart_block)
B(-1,31,5,minecraft:nether_wart_block)
B(-1,32,5,minecraft:nether_wart_block)
B(-1,33,5,minecraft:nether_wart_block)
B(-1,34,5,minecraft:nether_wart_block)
B(-1,28,6,minecraft:nether_wart_block)
B(-1,29,6,minecraft:nether_wart_block)
B(-1,30,6,minecraft:nether_wart_block)
B(-1,31,6,minecraft:nether_wart_block)
B(-1,32,6,minecraft:nether_wart_block)
B(-1,33,6,minecraft:nether_wart_block)
B(-1,34,6,minecraft:nether_wart_block)
B(-1,28,7,minecraft:nether_wart_block)
B(-1,29,7,minecraft:nether_wart_block)
B(-1,30,7,minecraft:nether_wart_block)
B(-1,31,7,minecraft:nether_wart_block)
B(-1,32,7,minecraft:nether_wart_block)
B(-1,33,7,minecraft:nether_wart_block)
B(-1,34,7,minecraft:nether_wart_block)
B(-1,15,8,minecraft:weeping_vines[age=14])
B(-1,16,8,minecraft:weeping_vines_plant)
B(-1,17,8,minecraft:weeping_vines_plant)
B(-1,18,8,minecraft:weeping_vines_plant)
B(-1,19,8,minecraft:weeping_vines_plant)
B(-1,20,8,minecraft:weeping_vines_plant)
B(-1,21,8,minecraft:weeping_vines_plant)
B(-1,22,8,minecraft:weeping_vines_plant)
B(-1,23,8,minecraft:weeping_vines_plant)
B(-1,24,8,minecraft:weeping_vines_plant)
B(-1,25,8,minecraft:weeping_vines_plant)
B(-1,26,8,minecraft:weeping_vines_plant)
B(-1,27,8,minecraft:weeping_vines_plant)
B(-1,28,8,minecraft:nether_wart_block)
B(-1,29,8,minecraft:nether_wart_block)
B(-1,30,8,minecraft:nether_wart_block)
B(-1,31,8,minecraft:nether_wart_block)
B(-1,32,8,minecraft:nether_wart_block)
B(-1,33,8,minecraft:nether_wart_block)
B(-1,34,8,minecraft:nether_wart_block)
B(0,29,5,minecraft:nether_wart_block)
B(0,30,5,minecraft:nether_wart_block)
B(0,31,5,minecraft:nether_wart_block)
B(0,32,5,minecraft:nether_wart_block)
B(0,33,5,minecraft:nether_wart_block)
B(0,29,6,minecraft:nether_wart_block)
B(0,30,6,minecraft:nether_wart_block)
B(0,31,6,minecraft:nether_wart_block)
B(0,32,6,minecraft:nether_wart_block)
B(0,33,6,minecraft:nether_wart_block)
B(0,29,7,minecraft:nether_wart_block)
B(0,30,7,minecraft:nether_wart_block)
B(0,31,7,minecraft:nether_wart_block)
B(0,32,7,minecraft:nether_wart_block)
B(0,33,7,minecraft:nether_wart_block)
B(0,29,8,minecraft:nether_wart_block)
B(0,30,8,minecraft:nether_wart_block)
B(0,31,8,minecraft:nether_wart_block)
B(0,32,8,minecraft:nether_wart_block)
B(0,33,8,minecraft:nether_wart_block)
B(1,30,6,minecraft:nether_wart_block)
B(1,31,6,minecraft:nether_wart_block)
B(1,32,6,minecraft:nether_wart_block)
B(1,30,7,minecraft:nether_wart_block)
B(1,31,7,minecraft:nether_wart_block)
B(1,32,7,minecraft:nether_wart_block)
B(1,30,8,minecraft:nether_wart_block)
B(1,31,8,minecraft:nether_wart_block)
B(1,32,8,minecraft:nether_wart_block)
B(4,0,5,minecraft:netherrack)
B(4,0,6,minecraft:netherrack)
B(4,0,7,minecraft:netherrack)
B(4,0,8,minecraft:netherrack)

#######################################################################
# +-----------------------------------------------------------------+ #
# |                             Branches                            | #
# +-----------------------------------------------------------------+ #
#######################################################################


#######################################################################
# +-----------------------------------------------------------------+ #
# |                             Entities                            | #
# +-----------------------------------------------------------------+ #
#######################################################################

