
#######################################################################
# +-----------------------------------------------------------------+ #
# |                            BO4 object                           | #
# +-----------------------------------------------------------------+ #
#######################################################################

Author: Unknown

Description: No description given

SettingsMode: WriteWithoutComments


#######################################################################
# +-----------------------------------------------------------------+ #
# |                          Main settings                          | #
# +-----------------------------------------------------------------+ #
#######################################################################

FixedRotation: 

Frequency: 0

SpawnHeight: highestBlock

UseCenterForHighestBlock: true

##############################
# Height Limits for the BO4. #
##############################

MinHeight: 0

MaxHeight: 255

InheritBO3: 

InheritBO3Rotation: NORTH

OverrideChildSettings: true

OverrideParentHeight: false

CanOverride: false

BranchFrequency: 0

BranchFrequencyGroup: 

MustBeBelowOther: false

MustBeInside: 

CannotBeInside: 

ReplacesBO3: 

MustBeInsideWorldBorders: false

CanSpawnOnWater: true

SpawnOnWaterOnly: false

SpawnUnderWater: false

SpawnAtWaterLevel: false

HeightOffset: 0

RemoveAir: true

ReplaceAbove: 

ReplaceBelow: 

ReplaceWithBiomeBlocks: true

ReplaceWithSurfaceBlock: GRASS

ReplaceWithGroundBlock: DIRT

ReplaceWithStoneBlock: STONE

SmoothRadius: 0

SmoothHeightOffset: 0

SmoothStartTop: false

SmoothStartWood: false

SmoothingSurfaceBlock: 

SmoothingGroundBlock: 

BO3Group: 

IsSpawnPoint: false

DoReplaceBlocks: true


#######################################################################
# +-----------------------------------------------------------------+ #
# |                              Blocks                             | #
# +-----------------------------------------------------------------+ #
#######################################################################

B(-8,39,-7,minecraft:nether_wart_block)
B(-8,40,-7,minecraft:nether_wart_block)
B(-8,41,-7,minecraft:nether_wart_block)
B(-8,42,-7,minecraft:nether_wart_block)
B(-8,43,-7,minecraft:nether_wart_block)
B(-8,44,-7,minecraft:nether_wart_block)
B(-8,45,-7,minecraft:nether_wart_block)
B(-8,46,-7,minecraft:nether_wart_block)
B(-8,47,-7,minecraft:nether_wart_block)
B(-8,48,-7,minecraft:nether_wart_block)
B(-8,39,-6,minecraft:nether_wart_block)
B(-8,40,-6,minecraft:nether_wart_block)
B(-8,41,-6,minecraft:nether_wart_block)
B(-8,42,-6,minecraft:nether_wart_block)
B(-8,43,-6,minecraft:nether_wart_block)
B(-8,44,-6,minecraft:nether_wart_block)
B(-8,45,-6,minecraft:nether_wart_block)
B(-8,46,-6,minecraft:nether_wart_block)
B(-8,47,-6,minecraft:nether_wart_block)
B(-8,48,-6,minecraft:nether_wart_block)
B(-8,34,-5,minecraft:crimson_hyphae)
B(-8,35,-5,minecraft:crimson_hyphae)
B(-8,36,-5,minecraft:nether_wart_block)
B(-8,37,-5,minecraft:nether_wart_block)
B(-8,38,-5,minecraft:nether_wart_block)
B(-8,39,-5,minecraft:nether_wart_block)
B(-8,40,-5,minecraft:nether_wart_block)
B(-8,41,-5,minecraft:nether_wart_block)
B(-8,42,-5,minecraft:nether_wart_block)
B(-8,43,-5,minecraft:nether_wart_block)
B(-8,44,-5,minecraft:nether_wart_block)
B(-8,45,-5,minecraft:nether_wart_block)
B(-8,46,-5,minecraft:nether_wart_block)
B(-8,47,-5,minecraft:nether_wart_block)
B(-8,34,-4,minecraft:crimson_hyphae)
B(-8,35,-4,minecraft:nether_wart_block)
B(-8,36,-4,minecraft:nether_wart_block)
B(-8,37,-4,minecraft:nether_wart_block)
B(-8,38,-4,minecraft:nether_wart_block)
B(-8,39,-4,minecraft:nether_wart_block)
B(-8,40,-4,minecraft:nether_wart_block)
B(-8,41,-4,minecraft:nether_wart_block)
B(-8,42,-4,minecraft:nether_wart_block)
B(-8,43,-4,minecraft:nether_wart_block)
B(-8,44,-4,minecraft:nether_wart_block)
B(-8,45,-4,minecraft:nether_wart_block)
B(-8,46,-4,minecraft:nether_wart_block)
B(-8,34,-3,minecraft:nether_wart_block)
B(-8,35,-3,minecraft:nether_wart_block)
B(-8,36,-3,minecraft:nether_wart_block)
B(-8,37,-3,minecraft:nether_wart_block)
B(-8,38,-3,minecraft:nether_wart_block)
B(-8,39,-3,minecraft:nether_wart_block)
B(-8,40,-3,minecraft:nether_wart_block)
B(-8,41,-3,minecraft:nether_wart_block)
B(-8,42,-3,minecraft:nether_wart_block)
B(-8,43,-3,minecraft:nether_wart_block)
B(-8,44,-3,minecraft:nether_wart_block)
B(-8,45,-3,minecraft:nether_wart_block)
B(-8,34,-2,minecraft:nether_wart_block)
B(-8,35,-2,minecraft:nether_wart_block)
B(-8,36,-2,minecraft:nether_wart_block)
B(-8,37,-2,minecraft:nether_wart_block)
B(-8,38,-2,minecraft:nether_wart_block)
B(-8,39,-2,minecraft:nether_wart_block)
B(-8,40,-2,minecraft:nether_wart_block)
B(-8,41,-2,minecraft:nether_wart_block)
B(-8,42,-2,minecraft:nether_wart_block)
B(-8,43,-2,minecraft:nether_wart_block)
B(-8,44,-2,minecraft:nether_wart_block)
B(-8,45,-2,minecraft:nether_wart_block)
B(-8,32,-1,minecraft:nether_wart_block)
B(-8,33,-1,minecraft:nether_wart_block)
B(-8,34,-1,minecraft:nether_wart_block)
B(-8,35,-1,minecraft:nether_wart_block)
B(-8,36,-1,minecraft:nether_wart_block)
B(-8,37,-1,minecraft:nether_wart_block)
B(-8,38,-1,minecraft:nether_wart_block)
B(-8,39,-1,minecraft:nether_wart_block)
B(-8,40,-1,minecraft:nether_wart_block)
B(-8,41,-1,minecraft:nether_wart_block)
B(-8,42,-1,minecraft:nether_wart_block)
B(-8,43,-1,minecraft:nether_wart_block)
B(-8,44,-1,minecraft:nether_wart_block)
B(-8,45,-1,minecraft:nether_wart_block)
B(-8,29,0,minecraft:nether_wart_block)
B(-8,30,0,minecraft:nether_wart_block)
B(-8,31,0,minecraft:nether_wart_block)
B(-8,32,0,minecraft:nether_wart_block)
B(-8,33,0,minecraft:nether_wart_block)
B(-8,34,0,minecraft:nether_wart_block)
B(-8,35,0,minecraft:nether_wart_block)
B(-8,36,0,minecraft:nether_wart_block)
B(-8,37,0,minecraft:nether_wart_block)
B(-8,38,0,minecraft:nether_wart_block)
B(-8,39,0,minecraft:nether_wart_block)
B(-8,40,0,minecraft:nether_wart_block)
B(-8,41,0,minecraft:nether_wart_block)
B(-8,42,0,minecraft:nether_wart_block)
B(-8,43,0,minecraft:nether_wart_block)
B(-8,44,0,minecraft:nether_wart_block)
B(-8,45,0,minecraft:nether_wart_block)
B(-8,28,1,minecraft:nether_wart_block)
B(-8,29,1,minecraft:nether_wart_block)
B(-8,30,1,minecraft:nether_wart_block)
B(-8,31,1,minecraft:nether_wart_block)
B(-8,32,1,minecraft:nether_wart_block)
B(-8,33,1,minecraft:nether_wart_block)
B(-8,34,1,minecraft:nether_wart_block)
B(-8,35,1,minecraft:nether_wart_block)
B(-8,36,1,minecraft:nether_wart_block)
B(-8,37,1,minecraft:nether_wart_block)
B(-8,38,1,minecraft:nether_wart_block)
B(-8,39,1,minecraft:nether_wart_block)
B(-8,40,1,minecraft:nether_wart_block)
B(-8,41,1,minecraft:nether_wart_block)
B(-8,42,1,minecraft:nether_wart_block)
B(-8,43,1,minecraft:nether_wart_block)
B(-8,44,1,minecraft:nether_wart_block)
B(-8,27,2,minecraft:nether_wart_block)
B(-8,28,2,minecraft:nether_wart_block)
B(-8,29,2,minecraft:nether_wart_block)
B(-8,30,2,minecraft:nether_wart_block)
B(-8,31,2,minecraft:nether_wart_block)
B(-8,32,2,minecraft:nether_wart_block)
B(-8,33,2,minecraft:nether_wart_block)
B(-8,34,2,minecraft:nether_wart_block)
B(-8,35,2,minecraft:nether_wart_block)
B(-8,36,2,minecraft:nether_wart_block)
B(-8,37,2,minecraft:nether_wart_block)
B(-8,38,2,minecraft:nether_wart_block)
B(-8,39,2,minecraft:nether_wart_block)
B(-8,40,2,minecraft:nether_wart_block)
B(-8,41,2,minecraft:nether_wart_block)
B(-8,42,2,minecraft:nether_wart_block)
B(-8,43,2,minecraft:nether_wart_block)
B(-8,44,2,minecraft:nether_wart_block)
B(-8,27,3,minecraft:nether_wart_block)
B(-8,28,3,minecraft:nether_wart_block)
B(-8,29,3,minecraft:nether_wart_block)
B(-8,30,3,minecraft:nether_wart_block)
B(-8,31,3,minecraft:nether_wart_block)
B(-8,32,3,minecraft:nether_wart_block)
B(-8,33,3,minecraft:nether_wart_block)
B(-8,34,3,minecraft:nether_wart_block)
B(-8,35,3,minecraft:nether_wart_block)
B(-8,36,3,minecraft:nether_wart_block)
B(-8,37,3,minecraft:nether_wart_block)
B(-8,38,3,minecraft:nether_wart_block)
B(-8,39,3,minecraft:nether_wart_block)
B(-8,40,3,minecraft:nether_wart_block)
B(-8,41,3,minecraft:nether_wart_block)
B(-8,42,3,minecraft:nether_wart_block)
B(-8,43,3,minecraft:nether_wart_block)
B(-8,44,3,minecraft:nether_wart_block)
B(-8,27,4,minecraft:nether_wart_block)
B(-8,28,4,minecraft:nether_wart_block)
B(-8,29,4,minecraft:nether_wart_block)
B(-8,30,4,minecraft:nether_wart_block)
B(-8,31,4,minecraft:nether_wart_block)
B(-8,32,4,minecraft:nether_wart_block)
B(-8,33,4,minecraft:nether_wart_block)
B(-8,34,4,minecraft:nether_wart_block)
B(-8,35,4,minecraft:nether_wart_block)
B(-8,36,4,minecraft:nether_wart_block)
B(-8,37,4,minecraft:nether_wart_block)
B(-8,38,4,minecraft:nether_wart_block)
B(-8,39,4,minecraft:nether_wart_block)
B(-8,40,4,minecraft:nether_wart_block)
B(-8,41,4,minecraft:nether_wart_block)
B(-8,42,4,minecraft:nether_wart_block)
B(-8,43,4,minecraft:nether_wart_block)
B(-8,44,4,minecraft:nether_wart_block)
B(-8,28,5,minecraft:nether_wart_block)
B(-8,29,5,minecraft:nether_wart_block)
B(-8,30,5,minecraft:nether_wart_block)
B(-8,31,5,minecraft:nether_wart_block)
B(-8,32,5,minecraft:nether_wart_block)
B(-8,33,5,minecraft:nether_wart_block)
B(-8,34,5,minecraft:nether_wart_block)
B(-8,35,5,minecraft:nether_wart_block)
B(-8,36,5,minecraft:nether_wart_block)
B(-8,37,5,minecraft:nether_wart_block)
B(-8,38,5,minecraft:nether_wart_block)
B(-8,39,5,minecraft:nether_wart_block)
B(-8,40,5,minecraft:nether_wart_block)
B(-8,41,5,minecraft:nether_wart_block)
B(-8,42,5,minecraft:nether_wart_block)
B(-8,43,5,minecraft:nether_wart_block)
B(-8,29,6,minecraft:nether_wart_block)
B(-8,30,6,minecraft:nether_wart_block)
B(-8,31,6,minecraft:nether_wart_block)
B(-8,40,6,minecraft:nether_wart_block)
B(-8,41,6,minecraft:nether_wart_block)
B(-8,42,6,minecraft:nether_wart_block)
B(-7,31,-7,minecraft:crimson_hyphae)
B(-7,32,-7,minecraft:crimson_hyphae)
B(-7,33,-7,minecraft:crimson_hyphae)
B(-7,40,-7,minecraft:nether_wart_block)
B(-7,41,-7,minecraft:nether_wart_block)
B(-7,42,-7,minecraft:nether_wart_block)
B(-7,43,-7,minecraft:nether_wart_block)
B(-7,44,-7,minecraft:nether_wart_block)
B(-7,45,-7,minecraft:nether_wart_block)
B(-7,46,-7,minecraft:nether_wart_block)
B(-7,47,-7,minecraft:nether_wart_block)
B(-7,48,-7,minecraft:nether_wart_block)
B(-7,31,-6,minecraft:crimson_hyphae)
B(-7,32,-6,minecraft:crimson_hyphae)
B(-7,33,-6,minecraft:crimson_hyphae)
B(-7,34,-6,minecraft:crimson_hyphae)
B(-7,35,-6,minecraft:crimson_hyphae)
B(-7,36,-6,minecraft:crimson_hyphae)
B(-7,37,-6,minecraft:crimson_hyphae)
B(-7,39,-6,minecraft:nether_wart_block)
B(-7,40,-6,minecraft:nether_wart_block)
B(-7,41,-6,minecraft:nether_wart_block)
B(-7,42,-6,minecraft:nether_wart_block)
B(-7,43,-6,minecraft:nether_wart_block)
B(-7,44,-6,minecraft:nether_wart_block)
B(-7,45,-6,minecraft:nether_wart_block)
B(-7,46,-6,minecraft:nether_wart_block)
B(-7,47,-6,minecraft:nether_wart_block)
B(-7,33,-5,minecraft:crimson_hyphae)
B(-7,34,-5,minecraft:crimson_hyphae)
B(-7,35,-5,minecraft:crimson_hyphae)
B(-7,36,-5,minecraft:crimson_hyphae)
B(-7,37,-5,minecraft:crimson_hyphae)
B(-7,38,-5,minecraft:nether_wart_block)
B(-7,39,-5,minecraft:nether_wart_block)
B(-7,40,-5,minecraft:nether_wart_block)
B(-7,41,-5,minecraft:nether_wart_block)
B(-7,42,-5,minecraft:nether_wart_block)
B(-7,43,-5,minecraft:nether_wart_block)
B(-7,44,-5,minecraft:nether_wart_block)
B(-7,45,-5,minecraft:nether_wart_block)
B(-7,46,-5,minecraft:nether_wart_block)
B(-7,47,-5,minecraft:nether_wart_block)
B(-7,33,-4,minecraft:crimson_hyphae)
B(-7,34,-4,minecraft:crimson_hyphae)
B(-7,35,-4,minecraft:nether_wart_block)
B(-7,36,-4,minecraft:nether_wart_block)
B(-7,37,-4,minecraft:nether_wart_block)
B(-7,38,-4,minecraft:nether_wart_block)
B(-7,39,-4,minecraft:nether_wart_block)
B(-7,40,-4,minecraft:nether_wart_block)
B(-7,41,-4,minecraft:nether_wart_block)
B(-7,42,-4,minecraft:nether_wart_block)
B(-7,43,-4,minecraft:nether_wart_block)
B(-7,44,-4,minecraft:nether_wart_block)
B(-7,45,-4,minecraft:nether_wart_block)
B(-7,33,-3,minecraft:crimson_hyphae)
B(-7,34,-3,minecraft:crimson_hyphae)
B(-7,35,-3,minecraft:nether_wart_block)
B(-7,36,-3,minecraft:nether_wart_block)
B(-7,37,-3,minecraft:nether_wart_block)
B(-7,38,-3,minecraft:nether_wart_block)
B(-7,39,-3,minecraft:nether_wart_block)
B(-7,40,-3,minecraft:nether_wart_block)
B(-7,41,-3,minecraft:nether_wart_block)
B(-7,42,-3,minecraft:nether_wart_block)
B(-7,43,-3,minecraft:nether_wart_block)
B(-7,44,-3,minecraft:nether_wart_block)
B(-7,45,-3,minecraft:nether_wart_block)
B(-7,46,-3,minecraft:nether_wart_block)
B(-7,33,-2,minecraft:crimson_hyphae)
B(-7,34,-2,minecraft:crimson_hyphae)
B(-7,35,-2,minecraft:nether_wart_block)
B(-7,36,-2,minecraft:nether_wart_block)
B(-7,37,-2,minecraft:nether_wart_block)
B(-7,38,-2,minecraft:nether_wart_block)
B(-7,39,-2,minecraft:nether_wart_block)
B(-7,40,-2,minecraft:nether_wart_block)
B(-7,41,-2,minecraft:nether_wart_block)
B(-7,42,-2,minecraft:nether_wart_block)
B(-7,43,-2,minecraft:nether_wart_block)
B(-7,44,-2,minecraft:nether_wart_block)
B(-7,45,-2,minecraft:nether_wart_block)
B(-7,46,-2,minecraft:nether_wart_block)
B(-7,32,-1,minecraft:nether_wart_block)
B(-7,33,-1,minecraft:nether_wart_block)
B(-7,34,-1,minecraft:nether_wart_block)
B(-7,35,-1,minecraft:nether_wart_block)
B(-7,36,-1,minecraft:nether_wart_block)
B(-7,37,-1,minecraft:nether_wart_block)
B(-7,38,-1,minecraft:nether_wart_block)
B(-7,39,-1,minecraft:nether_wart_block)
B(-7,40,-1,minecraft:nether_wart_block)
B(-7,41,-1,minecraft:nether_wart_block)
B(-7,42,-1,minecraft:nether_wart_block)
B(-7,43,-1,minecraft:nether_wart_block)
B(-7,44,-1,minecraft:nether_wart_block)
B(-7,45,-1,minecraft:nether_wart_block)
B(-7,46,-1,minecraft:nether_wart_block)
B(-7,27,0,minecraft:weeping_vines[age=24])
B(-7,28,0,minecraft:weeping_vines_plant)
B(-7,29,0,minecraft:nether_wart_block)
B(-7,30,0,minecraft:nether_wart_block)
B(-7,31,0,minecraft:nether_wart_block)
B(-7,32,0,minecraft:nether_wart_block)
B(-7,33,0,minecraft:nether_wart_block)
B(-7,34,0,minecraft:nether_wart_block)
B(-7,35,0,minecraft:nether_wart_block)
B(-7,36,0,minecraft:nether_wart_block)
B(-7,37,0,minecraft:nether_wart_block)
B(-7,38,0,minecraft:nether_wart_block)
B(-7,39,0,minecraft:nether_wart_block)
B(-7,40,0,minecraft:nether_wart_block)
B(-7,41,0,minecraft:nether_wart_block)
B(-7,42,0,minecraft:nether_wart_block)
B(-7,43,0,minecraft:nether_wart_block)
B(-7,44,0,minecraft:nether_wart_block)
B(-7,45,0,minecraft:nether_wart_block)
B(-7,28,1,minecraft:nether_wart_block)
B(-7,29,1,minecraft:nether_wart_block)
B(-7,30,1,minecraft:nether_wart_block)
B(-7,31,1,minecraft:nether_wart_block)
B(-7,32,1,minecraft:nether_wart_block)
B(-7,33,1,minecraft:nether_wart_block)
B(-7,34,1,minecraft:nether_wart_block)
B(-7,35,1,minecraft:nether_wart_block)
B(-7,36,1,minecraft:nether_wart_block)
B(-7,37,1,minecraft:nether_wart_block)
B(-7,38,1,minecraft:nether_wart_block)
B(-7,39,1,minecraft:nether_wart_block)
B(-7,40,1,minecraft:nether_wart_block)
B(-7,41,1,minecraft:nether_wart_block)
B(-7,42,1,minecraft:nether_wart_block)
B(-7,43,1,minecraft:nether_wart_block)
B(-7,44,1,minecraft:nether_wart_block)
B(-7,27,2,minecraft:nether_wart_block)
B(-7,28,2,minecraft:nether_wart_block)
B(-7,29,2,minecraft:nether_wart_block)
B(-7,30,2,minecraft:nether_wart_block)
B(-7,31,2,minecraft:nether_wart_block)
B(-7,32,2,minecraft:nether_wart_block)
B(-7,33,2,minecraft:nether_wart_block)
B(-7,34,2,minecraft:nether_wart_block)
B(-7,35,2,minecraft:nether_wart_block)
B(-7,36,2,minecraft:nether_wart_block)
B(-7,37,2,minecraft:nether_wart_block)
B(-7,38,2,minecraft:nether_wart_block)
B(-7,39,2,minecraft:nether_wart_block)
B(-7,40,2,minecraft:nether_wart_block)
B(-7,41,2,minecraft:nether_wart_block)
B(-7,42,2,minecraft:nether_wart_block)
B(-7,43,2,minecraft:nether_wart_block)
B(-7,44,2,minecraft:nether_wart_block)
B(-7,23,3,minecraft:weeping_vines[age=25])
B(-7,24,3,minecraft:weeping_vines_plant)
B(-7,25,3,minecraft:weeping_vines_plant)
B(-7,26,3,minecraft:weeping_vines_plant)
B(-7,27,3,minecraft:nether_wart_block)
B(-7,28,3,minecraft:nether_wart_block)
B(-7,29,3,minecraft:nether_wart_block)
B(-7,30,3,minecraft:nether_wart_block)
B(-7,31,3,minecraft:nether_wart_block)
B(-7,32,3,minecraft:nether_wart_block)
B(-7,33,3,minecraft:nether_wart_block)
B(-7,34,3,minecraft:nether_wart_block)
B(-7,35,3,minecraft:nether_wart_block)
B(-7,36,3,minecraft:nether_wart_block)
B(-7,37,3,minecraft:nether_wart_block)
B(-7,38,3,minecraft:nether_wart_block)
B(-7,39,3,minecraft:nether_wart_block)
B(-7,40,3,minecraft:nether_wart_block)
B(-7,41,3,minecraft:nether_wart_block)
B(-7,42,3,minecraft:nether_wart_block)
B(-7,43,3,minecraft:nether_wart_block)
B(-7,44,3,minecraft:nether_wart_block)
B(-7,27,4,minecraft:nether_wart_block)
B(-7,28,4,minecraft:nether_wart_block)
B(-7,29,4,minecraft:nether_wart_block)
B(-7,30,4,minecraft:nether_wart_block)
B(-7,31,4,minecraft:nether_wart_block)
B(-7,32,4,minecraft:nether_wart_block)
B(-7,33,4,minecraft:nether_wart_block)
B(-7,34,4,minecraft:nether_wart_block)
B(-7,35,4,minecraft:nether_wart_block)
B(-7,36,4,minecraft:nether_wart_block)
B(-7,37,4,minecraft:nether_wart_block)
B(-7,38,4,minecraft:nether_wart_block)
B(-7,39,4,minecraft:nether_wart_block)
B(-7,40,4,minecraft:nether_wart_block)
B(-7,41,4,minecraft:nether_wart_block)
B(-7,42,4,minecraft:nether_wart_block)
B(-7,43,4,minecraft:nether_wart_block)
B(-7,44,4,minecraft:nether_wart_block)
B(-7,28,5,minecraft:nether_wart_block)
B(-7,29,5,minecraft:nether_wart_block)
B(-7,30,5,minecraft:nether_wart_block)
B(-7,31,5,minecraft:nether_wart_block)
B(-7,32,5,minecraft:nether_wart_block)
B(-7,33,5,minecraft:nether_wart_block)
B(-7,34,5,minecraft:nether_wart_block)
B(-7,35,5,minecraft:nether_wart_block)
B(-7,36,5,minecraft:nether_wart_block)
B(-7,37,5,minecraft:nether_wart_block)
B(-7,38,5,minecraft:nether_wart_block)
B(-7,39,5,minecraft:nether_wart_block)
B(-7,40,5,minecraft:nether_wart_block)
B(-7,41,5,minecraft:nether_wart_block)
B(-7,42,5,minecraft:nether_wart_block)
B(-7,43,5,minecraft:nether_wart_block)
B(-7,27,6,minecraft:nether_wart_block)
B(-7,28,6,minecraft:nether_wart_block)
B(-7,29,6,minecraft:nether_wart_block)
B(-7,30,6,minecraft:nether_wart_block)
B(-7,31,6,minecraft:nether_wart_block)
B(-7,33,6,minecraft:nether_wart_block)
B(-7,34,6,minecraft:nether_wart_block)
B(-7,35,6,minecraft:nether_wart_block)
B(-7,37,6,minecraft:nether_wart_block)
B(-7,38,6,minecraft:nether_wart_block)
B(-7,39,6,minecraft:nether_wart_block)
B(-7,40,6,minecraft:nether_wart_block)
B(-7,41,6,minecraft:nether_wart_block)
B(-7,42,6,minecraft:nether_wart_block)
B(-7,27,7,minecraft:nether_wart_block)
B(-7,28,7,minecraft:nether_wart_block)
B(-7,29,7,minecraft:nether_wart_block)
B(-7,27,8,minecraft:nether_wart_block)
B(-7,28,8,minecraft:nether_wart_block)
B(-7,29,8,minecraft:nether_wart_block)
B(-6,30,-7,minecraft:crimson_hyphae)
B(-6,31,-7,minecraft:crimson_hyphae)
B(-6,32,-7,minecraft:crimson_hyphae)
B(-6,33,-7,minecraft:crimson_hyphae)
B(-6,34,-7,minecraft:crimson_hyphae)
B(-6,35,-7,minecraft:crimson_hyphae)
B(-6,36,-7,minecraft:crimson_hyphae)
B(-6,42,-7,minecraft:nether_wart_block)
B(-6,43,-7,minecraft:nether_wart_block)
B(-6,44,-7,minecraft:nether_wart_block)
B(-6,45,-7,minecraft:nether_wart_block)
B(-6,46,-7,minecraft:nether_wart_block)
B(-6,47,-7,minecraft:nether_wart_block)
B(-6,48,-7,minecraft:nether_wart_block)
B(-6,30,-6,minecraft:crimson_hyphae)
B(-6,31,-6,minecraft:crimson_hyphae)
B(-6,32,-6,minecraft:crimson_hyphae)
B(-6,33,-6,minecraft:crimson_hyphae)
B(-6,34,-6,minecraft:crimson_hyphae)
B(-6,35,-6,minecraft:crimson_hyphae)
B(-6,36,-6,minecraft:crimson_hyphae)
B(-6,37,-6,minecraft:crimson_hyphae)
B(-6,43,-6,minecraft:nether_wart_block)
B(-6,44,-6,minecraft:nether_wart_block)
B(-6,45,-6,minecraft:nether_wart_block)
B(-6,46,-6,minecraft:nether_wart_block)
B(-6,47,-6,minecraft:nether_wart_block)
B(-6,30,-5,minecraft:crimson_hyphae)
B(-6,31,-5,minecraft:crimson_hyphae)
B(-6,32,-5,minecraft:crimson_hyphae)
B(-6,33,-5,minecraft:crimson_hyphae)
B(-6,34,-5,minecraft:crimson_hyphae)
B(-6,35,-5,minecraft:crimson_hyphae)
B(-6,36,-5,minecraft:crimson_hyphae)
B(-6,37,-5,minecraft:crimson_hyphae)
B(-6,38,-5,minecraft:nether_wart_block)
B(-6,39,-5,minecraft:nether_wart_block)
B(-6,40,-5,minecraft:nether_wart_block)
B(-6,41,-5,minecraft:nether_wart_block)
B(-6,42,-5,minecraft:nether_wart_block)
B(-6,43,-5,minecraft:nether_wart_block)
B(-6,44,-5,minecraft:nether_wart_block)
B(-6,45,-5,minecraft:nether_wart_block)
B(-6,46,-5,minecraft:nether_wart_block)
B(-6,32,-4,minecraft:crimson_hyphae)
B(-6,33,-4,minecraft:crimson_hyphae)
B(-6,34,-4,minecraft:crimson_hyphae)
B(-6,35,-4,minecraft:crimson_hyphae)
B(-6,36,-4,minecraft:crimson_hyphae)
B(-6,37,-4,minecraft:nether_wart_block)
B(-6,38,-4,minecraft:nether_wart_block)
B(-6,39,-4,minecraft:nether_wart_block)
B(-6,40,-4,minecraft:nether_wart_block)
B(-6,41,-4,minecraft:nether_wart_block)
B(-6,42,-4,minecraft:nether_wart_block)
B(-6,43,-4,minecraft:nether_wart_block)
B(-6,44,-4,minecraft:nether_wart_block)
B(-6,45,-4,minecraft:nether_wart_block)
B(-6,32,-3,minecraft:crimson_hyphae)
B(-6,33,-3,minecraft:crimson_hyphae)
B(-6,34,-3,minecraft:crimson_hyphae)
B(-6,35,-3,minecraft:crimson_hyphae)
B(-6,36,-3,minecraft:nether_wart_block)
B(-6,37,-3,minecraft:nether_wart_block)
B(-6,38,-3,minecraft:nether_wart_block)
B(-6,39,-3,minecraft:nether_wart_block)
B(-6,40,-3,minecraft:nether_wart_block)
B(-6,41,-3,minecraft:nether_wart_block)
B(-6,42,-3,minecraft:nether_wart_block)
B(-6,43,-3,minecraft:nether_wart_block)
B(-6,44,-3,minecraft:nether_wart_block)
B(-6,45,-3,minecraft:nether_wart_block)
B(-6,46,-3,minecraft:nether_wart_block)
B(-6,33,-2,minecraft:crimson_hyphae)
B(-6,34,-2,minecraft:crimson_hyphae)
B(-6,35,-2,minecraft:nether_wart_block)
B(-6,36,-2,minecraft:nether_wart_block)
B(-6,37,-2,minecraft:nether_wart_block)
B(-6,38,-2,minecraft:nether_wart_block)
B(-6,39,-2,minecraft:nether_wart_block)
B(-6,40,-2,minecraft:nether_wart_block)
B(-6,41,-2,minecraft:nether_wart_block)
B(-6,42,-2,minecraft:nether_wart_block)
B(-6,43,-2,minecraft:nether_wart_block)
B(-6,44,-2,minecraft:nether_wart_block)
B(-6,45,-2,minecraft:nether_wart_block)
B(-6,46,-2,minecraft:nether_wart_block)
B(-6,32,-1,minecraft:nether_wart_block)
B(-6,33,-1,minecraft:nether_wart_block)
B(-6,34,-1,minecraft:nether_wart_block)
B(-6,35,-1,minecraft:nether_wart_block)
B(-6,36,-1,minecraft:nether_wart_block)
B(-6,37,-1,minecraft:nether_wart_block)
B(-6,38,-1,minecraft:nether_wart_block)
B(-6,39,-1,minecraft:nether_wart_block)
B(-6,40,-1,minecraft:nether_wart_block)
B(-6,41,-1,minecraft:nether_wart_block)
B(-6,42,-1,minecraft:nether_wart_block)
B(-6,43,-1,minecraft:nether_wart_block)
B(-6,44,-1,minecraft:nether_wart_block)
B(-6,45,-1,minecraft:nether_wart_block)
B(-6,46,-1,minecraft:nether_wart_block)
B(-6,29,0,minecraft:nether_wart_block)
B(-6,30,0,minecraft:nether_wart_block)
B(-6,31,0,minecraft:nether_wart_block)
B(-6,32,0,minecraft:nether_wart_block)
B(-6,33,0,minecraft:nether_wart_block)
B(-6,34,0,minecraft:nether_wart_block)
B(-6,35,0,minecraft:nether_wart_block)
B(-6,36,0,minecraft:nether_wart_block)
B(-6,37,0,minecraft:nether_wart_block)
B(-6,38,0,minecraft:nether_wart_block)
B(-6,39,0,minecraft:nether_wart_block)
B(-6,40,0,minecraft:nether_wart_block)
B(-6,41,0,minecraft:nether_wart_block)
B(-6,42,0,minecraft:nether_wart_block)
B(-6,43,0,minecraft:nether_wart_block)
B(-6,44,0,minecraft:nether_wart_block)
B(-6,45,0,minecraft:nether_wart_block)
B(-6,28,1,minecraft:nether_wart_block)
B(-6,29,1,minecraft:nether_wart_block)
B(-6,30,1,minecraft:nether_wart_block)
B(-6,31,1,minecraft:nether_wart_block)
B(-6,32,1,minecraft:nether_wart_block)
B(-6,33,1,minecraft:nether_wart_block)
B(-6,34,1,minecraft:nether_wart_block)
B(-6,35,1,minecraft:nether_wart_block)
B(-6,36,1,minecraft:nether_wart_block)
B(-6,37,1,minecraft:nether_wart_block)
B(-6,38,1,minecraft:nether_wart_block)
B(-6,39,1,minecraft:nether_wart_block)
B(-6,40,1,minecraft:nether_wart_block)
B(-6,41,1,minecraft:nether_wart_block)
B(-6,42,1,minecraft:nether_wart_block)
B(-6,43,1,minecraft:nether_wart_block)
B(-6,44,1,minecraft:nether_wart_block)
B(-6,20,2,minecraft:weeping_vines[age=16])
B(-6,21,2,minecraft:weeping_vines_plant)
B(-6,22,2,minecraft:weeping_vines_plant)
B(-6,23,2,minecraft:weeping_vines_plant)
B(-6,24,2,minecraft:weeping_vines_plant)
B(-6,25,2,minecraft:weeping_vines_plant)
B(-6,26,2,minecraft:weeping_vines_plant)
B(-6,27,2,minecraft:nether_wart_block)
B(-6,28,2,minecraft:nether_wart_block)
B(-6,29,2,minecraft:nether_wart_block)
B(-6,30,2,minecraft:nether_wart_block)
B(-6,31,2,minecraft:nether_wart_block)
B(-6,32,2,minecraft:nether_wart_block)
B(-6,33,2,minecraft:nether_wart_block)
B(-6,34,2,minecraft:nether_wart_block)
B(-6,35,2,minecraft:nether_wart_block)
B(-6,36,2,minecraft:nether_wart_block)
B(-6,37,2,minecraft:nether_wart_block)
B(-6,38,2,minecraft:nether_wart_block)
B(-6,39,2,minecraft:nether_wart_block)
B(-6,40,2,minecraft:nether_wart_block)
B(-6,41,2,minecraft:nether_wart_block)
B(-6,42,2,minecraft:nether_wart_block)
B(-6,43,2,minecraft:nether_wart_block)
B(-6,44,2,minecraft:nether_wart_block)
B(-6,27,3,minecraft:nether_wart_block)
B(-6,28,3,minecraft:nether_wart_block)
B(-6,29,3,minecraft:nether_wart_block)
B(-6,30,3,minecraft:nether_wart_block)
B(-6,31,3,minecraft:nether_wart_block)
B(-6,32,3,minecraft:nether_wart_block)
B(-6,33,3,minecraft:nether_wart_block)
B(-6,34,3,minecraft:nether_wart_block)
B(-6,35,3,minecraft:nether_wart_block)
B(-6,36,3,minecraft:nether_wart_block)
B(-6,37,3,minecraft:nether_wart_block)
B(-6,38,3,minecraft:nether_wart_block)
B(-6,39,3,minecraft:nether_wart_block)
B(-6,40,3,minecraft:nether_wart_block)
B(-6,41,3,minecraft:nether_wart_block)
B(-6,42,3,minecraft:nether_wart_block)
B(-6,43,3,minecraft:nether_wart_block)
B(-6,27,4,minecraft:nether_wart_block)
B(-6,28,4,minecraft:nether_wart_block)
B(-6,29,4,minecraft:nether_wart_block)
B(-6,30,4,minecraft:nether_wart_block)
B(-6,31,4,minecraft:nether_wart_block)
B(-6,32,4,minecraft:nether_wart_block)
B(-6,33,4,minecraft:nether_wart_block)
B(-6,34,4,minecraft:nether_wart_block)
B(-6,35,4,minecraft:nether_wart_block)
B(-6,36,4,minecraft:nether_wart_block)
B(-6,37,4,minecraft:nether_wart_block)
B(-6,38,4,minecraft:nether_wart_block)
B(-6,39,4,minecraft:nether_wart_block)
B(-6,40,4,minecraft:nether_wart_block)
B(-6,41,4,minecraft:nether_wart_block)
B(-6,42,4,minecraft:nether_wart_block)
B(-6,43,4,minecraft:nether_wart_block)
B(-6,26,5,minecraft:nether_wart_block)
B(-6,27,5,minecraft:nether_wart_block)
B(-6,28,5,minecraft:nether_wart_block)
B(-6,29,5,minecraft:nether_wart_block)
B(-6,30,5,minecraft:nether_wart_block)
B(-6,31,5,minecraft:nether_wart_block)
B(-6,32,5,minecraft:nether_wart_block)
B(-6,33,5,minecraft:nether_wart_block)
B(-6,34,5,minecraft:nether_wart_block)
B(-6,35,5,minecraft:nether_wart_block)
B(-6,36,5,minecraft:nether_wart_block)
B(-6,37,5,minecraft:nether_wart_block)
B(-6,38,5,minecraft:nether_wart_block)
B(-6,39,5,minecraft:nether_wart_block)
B(-6,40,5,minecraft:nether_wart_block)
B(-6,41,5,minecraft:nether_wart_block)
B(-6,42,5,minecraft:nether_wart_block)
B(-6,43,5,minecraft:nether_wart_block)
B(-6,24,6,minecraft:nether_wart_block)
B(-6,25,6,minecraft:nether_wart_block)
B(-6,26,6,minecraft:nether_wart_block)
B(-6,27,6,minecraft:nether_wart_block)
B(-6,28,6,minecraft:nether_wart_block)
B(-6,29,6,minecraft:nether_wart_block)
B(-6,30,6,minecraft:nether_wart_block)
B(-6,31,6,minecraft:nether_wart_block)
B(-6,32,6,minecraft:nether_wart_block)
B(-6,33,6,minecraft:nether_wart_block)
B(-6,34,6,minecraft:nether_wart_block)
B(-6,35,6,minecraft:nether_wart_block)
B(-6,36,6,minecraft:nether_wart_block)
B(-6,37,6,minecraft:nether_wart_block)
B(-6,38,6,minecraft:nether_wart_block)
B(-6,39,6,minecraft:nether_wart_block)
B(-6,21,7,minecraft:nether_wart_block)
B(-6,22,7,minecraft:nether_wart_block)
B(-6,23,7,minecraft:nether_wart_block)
B(-6,24,7,minecraft:nether_wart_block)
B(-6,25,7,minecraft:nether_wart_block)
B(-6,26,7,minecraft:nether_wart_block)
B(-6,27,7,minecraft:nether_wart_block)
B(-6,28,7,minecraft:nether_wart_block)
B(-6,29,7,minecraft:nether_wart_block)
B(-6,30,7,minecraft:nether_wart_block)
B(-6,31,7,minecraft:nether_wart_block)
B(-6,32,7,minecraft:nether_wart_block)
B(-6,33,7,minecraft:nether_wart_block)
B(-6,34,7,minecraft:nether_wart_block)
B(-6,35,7,minecraft:nether_wart_block)
B(-6,36,7,minecraft:nether_wart_block)
B(-6,21,8,minecraft:nether_wart_block)
B(-6,22,8,minecraft:nether_wart_block)
B(-6,23,8,minecraft:nether_wart_block)
B(-6,24,8,minecraft:nether_wart_block)
B(-6,25,8,minecraft:nether_wart_block)
B(-6,26,8,minecraft:nether_wart_block)
B(-6,27,8,minecraft:nether_wart_block)
B(-6,28,8,minecraft:nether_wart_block)
B(-6,29,8,minecraft:nether_wart_block)
B(-6,30,8,minecraft:nether_wart_block)
B(-5,28,-7,minecraft:crimson_hyphae)
B(-5,29,-7,minecraft:crimson_hyphae)
B(-5,30,-7,minecraft:crimson_hyphae)
B(-5,31,-7,minecraft:crimson_hyphae)
B(-5,32,-7,minecraft:crimson_hyphae)
B(-5,33,-7,minecraft:crimson_hyphae)
B(-5,34,-7,minecraft:crimson_hyphae)
B(-5,35,-7,minecraft:crimson_hyphae)
B(-5,36,-7,minecraft:crimson_hyphae)
B(-5,42,-7,minecraft:nether_wart_block)
B(-5,43,-7,minecraft:nether_wart_block)
B(-5,44,-7,minecraft:nether_wart_block)
B(-5,45,-7,minecraft:nether_wart_block)
B(-5,46,-7,minecraft:nether_wart_block)
B(-5,47,-7,minecraft:nether_wart_block)
B(-5,48,-7,minecraft:nether_wart_block)
B(-5,29,-6,minecraft:crimson_hyphae)
B(-5,30,-6,minecraft:crimson_hyphae)
B(-5,31,-6,minecraft:crimson_hyphae)
B(-5,32,-6,minecraft:crimson_hyphae)
B(-5,33,-6,minecraft:crimson_hyphae)
B(-5,34,-6,minecraft:crimson_hyphae)
B(-5,35,-6,minecraft:crimson_hyphae)
B(-5,36,-6,minecraft:crimson_hyphae)
B(-5,37,-6,minecraft:crimson_hyphae)
B(-5,43,-6,minecraft:nether_wart_block)
B(-5,44,-6,minecraft:nether_wart_block)
B(-5,45,-6,minecraft:nether_wart_block)
B(-5,46,-6,minecraft:nether_wart_block)
B(-5,47,-6,minecraft:nether_wart_block)
B(-5,30,-5,minecraft:crimson_hyphae)
B(-5,31,-5,minecraft:crimson_hyphae)
B(-5,32,-5,minecraft:crimson_hyphae)
B(-5,33,-5,minecraft:crimson_hyphae)
B(-5,34,-5,minecraft:crimson_hyphae)
B(-5,35,-5,minecraft:crimson_hyphae)
B(-5,36,-5,minecraft:crimson_hyphae)
B(-5,37,-5,minecraft:crimson_hyphae)
B(-5,38,-5,minecraft:crimson_hyphae)
B(-5,40,-5,minecraft:nether_wart_block)
B(-5,41,-5,minecraft:nether_wart_block)
B(-5,42,-5,minecraft:nether_wart_block)
B(-5,43,-5,minecraft:nether_wart_block)
B(-5,44,-5,minecraft:nether_wart_block)
B(-5,45,-5,minecraft:nether_wart_block)
B(-5,46,-5,minecraft:nether_wart_block)
B(-5,31,-4,minecraft:crimson_hyphae)
B(-5,32,-4,minecraft:crimson_hyphae)
B(-5,33,-4,minecraft:crimson_hyphae)
B(-5,34,-4,minecraft:crimson_hyphae)
B(-5,35,-4,minecraft:crimson_hyphae)
B(-5,36,-4,minecraft:crimson_hyphae)
B(-5,37,-4,minecraft:nether_wart_block)
B(-5,38,-4,minecraft:nether_wart_block)
B(-5,39,-4,minecraft:nether_wart_block)
B(-5,40,-4,minecraft:nether_wart_block)
B(-5,41,-4,minecraft:nether_wart_block)
B(-5,42,-4,minecraft:nether_wart_block)
B(-5,43,-4,minecraft:nether_wart_block)
B(-5,44,-4,minecraft:nether_wart_block)
B(-5,45,-4,minecraft:nether_wart_block)
B(-5,32,-3,minecraft:crimson_hyphae)
B(-5,33,-3,minecraft:crimson_hyphae)
B(-5,34,-3,minecraft:crimson_hyphae)
B(-5,35,-3,minecraft:crimson_hyphae)
B(-5,36,-3,minecraft:nether_wart_block)
B(-5,37,-3,minecraft:nether_wart_block)
B(-5,38,-3,minecraft:nether_wart_block)
B(-5,39,-3,minecraft:nether_wart_block)
B(-5,40,-3,minecraft:nether_wart_block)
B(-5,41,-3,minecraft:nether_wart_block)
B(-5,42,-3,minecraft:nether_wart_block)
B(-5,43,-3,minecraft:nether_wart_block)
B(-5,44,-3,minecraft:nether_wart_block)
B(-5,45,-3,minecraft:nether_wart_block)
B(-5,46,-3,minecraft:nether_wart_block)
B(-5,33,-2,minecraft:nether_wart_block)
B(-5,34,-2,minecraft:nether_wart_block)
B(-5,35,-2,minecraft:nether_wart_block)
B(-5,36,-2,minecraft:nether_wart_block)
B(-5,37,-2,minecraft:nether_wart_block)
B(-5,38,-2,minecraft:nether_wart_block)
B(-5,39,-2,minecraft:nether_wart_block)
B(-5,40,-2,minecraft:nether_wart_block)
B(-5,41,-2,minecraft:nether_wart_block)
B(-5,42,-2,minecraft:nether_wart_block)
B(-5,43,-2,minecraft:nether_wart_block)
B(-5,44,-2,minecraft:nether_wart_block)
B(-5,45,-2,minecraft:nether_wart_block)
B(-5,46,-2,minecraft:nether_wart_block)
B(-5,32,-1,minecraft:nether_wart_block)
B(-5,33,-1,minecraft:nether_wart_block)
B(-5,34,-1,minecraft:nether_wart_block)
B(-5,35,-1,minecraft:nether_wart_block)
B(-5,36,-1,minecraft:nether_wart_block)
B(-5,37,-1,minecraft:nether_wart_block)
B(-5,38,-1,minecraft:nether_wart_block)
B(-5,39,-1,minecraft:nether_wart_block)
B(-5,40,-1,minecraft:nether_wart_block)
B(-5,41,-1,minecraft:nether_wart_block)
B(-5,42,-1,minecraft:nether_wart_block)
B(-5,43,-1,minecraft:nether_wart_block)
B(-5,44,-1,minecraft:nether_wart_block)
B(-5,45,-1,minecraft:nether_wart_block)
B(-5,46,-1,minecraft:nether_wart_block)
B(-5,29,0,minecraft:nether_wart_block)
B(-5,30,0,minecraft:nether_wart_block)
B(-5,31,0,minecraft:nether_wart_block)
B(-5,32,0,minecraft:nether_wart_block)
B(-5,33,0,minecraft:nether_wart_block)
B(-5,34,0,minecraft:nether_wart_block)
B(-5,35,0,minecraft:nether_wart_block)
B(-5,36,0,minecraft:nether_wart_block)
B(-5,37,0,minecraft:nether_wart_block)
B(-5,38,0,minecraft:nether_wart_block)
B(-5,39,0,minecraft:nether_wart_block)
B(-5,40,0,minecraft:nether_wart_block)
B(-5,41,0,minecraft:nether_wart_block)
B(-5,42,0,minecraft:nether_wart_block)
B(-5,43,0,minecraft:nether_wart_block)
B(-5,44,0,minecraft:nether_wart_block)
B(-5,45,0,minecraft:nether_wart_block)
B(-5,28,1,minecraft:nether_wart_block)
B(-5,29,1,minecraft:nether_wart_block)
B(-5,30,1,minecraft:nether_wart_block)
B(-5,31,1,minecraft:nether_wart_block)
B(-5,32,1,minecraft:nether_wart_block)
B(-5,33,1,minecraft:nether_wart_block)
B(-5,34,1,minecraft:nether_wart_block)
B(-5,35,1,minecraft:nether_wart_block)
B(-5,36,1,minecraft:nether_wart_block)
B(-5,37,1,minecraft:nether_wart_block)
B(-5,38,1,minecraft:nether_wart_block)
B(-5,39,1,minecraft:nether_wart_block)
B(-5,40,1,minecraft:nether_wart_block)
B(-5,41,1,minecraft:nether_wart_block)
B(-5,42,1,minecraft:nether_wart_block)
B(-5,43,1,minecraft:nether_wart_block)
B(-5,44,1,minecraft:nether_wart_block)
B(-5,28,2,minecraft:nether_wart_block)
B(-5,29,2,minecraft:nether_wart_block)
B(-5,30,2,minecraft:nether_wart_block)
B(-5,31,2,minecraft:nether_wart_block)
B(-5,32,2,minecraft:nether_wart_block)
B(-5,33,2,minecraft:nether_wart_block)
B(-5,34,2,minecraft:nether_wart_block)
B(-5,35,2,minecraft:nether_wart_block)
B(-5,36,2,minecraft:nether_wart_block)
B(-5,37,2,minecraft:nether_wart_block)
B(-5,38,2,minecraft:nether_wart_block)
B(-5,39,2,minecraft:nether_wart_block)
B(-5,40,2,minecraft:nether_wart_block)
B(-5,41,2,minecraft:nether_wart_block)
B(-5,42,2,minecraft:nether_wart_block)
B(-5,43,2,minecraft:nether_wart_block)
B(-5,44,2,minecraft:nether_wart_block)
B(-5,28,3,minecraft:nether_wart_block)
B(-5,29,3,minecraft:nether_wart_block)
B(-5,30,3,minecraft:nether_wart_block)
B(-5,31,3,minecraft:nether_wart_block)
B(-5,32,3,minecraft:nether_wart_block)
B(-5,33,3,minecraft:nether_wart_block)
B(-5,34,3,minecraft:nether_wart_block)
B(-5,35,3,minecraft:nether_wart_block)
B(-5,36,3,minecraft:nether_wart_block)
B(-5,37,3,minecraft:nether_wart_block)
B(-5,38,3,minecraft:nether_wart_block)
B(-5,39,3,minecraft:nether_wart_block)
B(-5,40,3,minecraft:nether_wart_block)
B(-5,41,3,minecraft:nether_wart_block)
B(-5,42,3,minecraft:nether_wart_block)
B(-5,43,3,minecraft:nether_wart_block)
B(-5,27,4,minecraft:nether_wart_block)
B(-5,28,4,minecraft:nether_wart_block)
B(-5,29,4,minecraft:nether_wart_block)
B(-5,30,4,minecraft:nether_wart_block)
B(-5,31,4,minecraft:nether_wart_block)
B(-5,32,4,minecraft:nether_wart_block)
B(-5,33,4,minecraft:nether_wart_block)
B(-5,34,4,minecraft:nether_wart_block)
B(-5,35,4,minecraft:nether_wart_block)
B(-5,36,4,minecraft:nether_wart_block)
B(-5,37,4,minecraft:nether_wart_block)
B(-5,38,4,minecraft:nether_wart_block)
B(-5,39,4,minecraft:nether_wart_block)
B(-5,40,4,minecraft:nether_wart_block)
B(-5,41,4,minecraft:nether_wart_block)
B(-5,42,4,minecraft:nether_wart_block)
B(-5,23,5,minecraft:nether_wart_block)
B(-5,24,5,minecraft:nether_wart_block)
B(-5,25,5,minecraft:nether_wart_block)
B(-5,26,5,minecraft:nether_wart_block)
B(-5,27,5,minecraft:nether_wart_block)
B(-5,28,5,minecraft:nether_wart_block)
B(-5,29,5,minecraft:nether_wart_block)
B(-5,30,5,minecraft:nether_wart_block)
B(-5,31,5,minecraft:nether_wart_block)
B(-5,32,5,minecraft:nether_wart_block)
B(-5,33,5,minecraft:nether_wart_block)
B(-5,34,5,minecraft:nether_wart_block)
B(-5,35,5,minecraft:nether_wart_block)
B(-5,36,5,minecraft:nether_wart_block)
B(-5,37,5,minecraft:nether_wart_block)
B(-5,38,5,minecraft:nether_wart_block)
B(-5,39,5,minecraft:nether_wart_block)
B(-5,40,5,minecraft:nether_wart_block)
B(-5,20,6,minecraft:nether_wart_block)
B(-5,21,6,minecraft:nether_wart_block)
B(-5,22,6,minecraft:nether_wart_block)
B(-5,23,6,minecraft:nether_wart_block)
B(-5,24,6,minecraft:nether_wart_block)
B(-5,25,6,minecraft:nether_wart_block)
B(-5,26,6,minecraft:nether_wart_block)
B(-5,27,6,minecraft:nether_wart_block)
B(-5,28,6,minecraft:nether_wart_block)
B(-5,29,6,minecraft:nether_wart_block)
B(-5,30,6,minecraft:nether_wart_block)
B(-5,31,6,minecraft:nether_wart_block)
B(-5,32,6,minecraft:nether_wart_block)
B(-5,33,6,minecraft:nether_wart_block)
B(-5,34,6,minecraft:nether_wart_block)
B(-5,35,6,minecraft:nether_wart_block)
B(-5,36,6,minecraft:nether_wart_block)
B(-5,37,6,minecraft:nether_wart_block)
B(-5,38,6,minecraft:nether_wart_block)
B(-5,39,6,minecraft:nether_wart_block)
B(-5,14,7,minecraft:weeping_vines[age=25])
B(-5,15,7,minecraft:weeping_vines_plant)
B(-5,16,7,minecraft:weeping_vines_plant)
B(-5,17,7,minecraft:weeping_vines_plant)
B(-5,18,7,minecraft:weeping_vines_plant)
B(-5,19,7,minecraft:weeping_vines_plant)
B(-5,20,7,minecraft:nether_wart_block)
B(-5,21,7,minecraft:nether_wart_block)
B(-5,22,7,minecraft:nether_wart_block)
B(-5,23,7,minecraft:nether_wart_block)
B(-5,24,7,minecraft:nether_wart_block)
B(-5,25,7,minecraft:nether_wart_block)
B(-5,26,7,minecraft:nether_wart_block)
B(-5,27,7,minecraft:nether_wart_block)
B(-5,28,7,minecraft:nether_wart_block)
B(-5,29,7,minecraft:nether_wart_block)
B(-5,30,7,minecraft:nether_wart_block)
B(-5,31,7,minecraft:nether_wart_block)
B(-5,32,7,minecraft:nether_wart_block)
B(-5,33,7,minecraft:nether_wart_block)
B(-5,34,7,minecraft:nether_wart_block)
B(-5,35,7,minecraft:nether_wart_block)
B(-5,36,7,minecraft:nether_wart_block)
B(-5,20,8,minecraft:nether_wart_block)
B(-5,21,8,minecraft:nether_wart_block)
B(-5,22,8,minecraft:nether_wart_block)
B(-5,23,8,minecraft:nether_wart_block)
B(-5,24,8,minecraft:nether_wart_block)
B(-5,25,8,minecraft:nether_wart_block)
B(-5,26,8,minecraft:nether_wart_block)
B(-5,27,8,minecraft:nether_wart_block)
B(-5,28,8,minecraft:nether_wart_block)
B(-5,29,8,minecraft:nether_wart_block)
B(-5,30,8,minecraft:nether_wart_block)
B(-5,31,8,minecraft:nether_wart_block)
B(-5,32,8,minecraft:nether_wart_block)
B(-5,33,8,minecraft:nether_wart_block)
B(-5,34,8,minecraft:nether_wart_block)
B(-5,35,8,minecraft:nether_wart_block)
B(-4,28,-7,minecraft:crimson_hyphae)
B(-4,29,-7,minecraft:crimson_hyphae)
B(-4,30,-7,minecraft:crimson_hyphae)
B(-4,31,-7,minecraft:crimson_hyphae)
B(-4,32,-7,minecraft:crimson_hyphae)
B(-4,33,-7,minecraft:crimson_hyphae)
B(-4,34,-7,minecraft:crimson_hyphae)
B(-4,35,-7,minecraft:crimson_hyphae)
B(-4,36,-7,minecraft:crimson_hyphae)
B(-4,43,-7,minecraft:nether_wart_block)
B(-4,44,-7,minecraft:nether_wart_block)
B(-4,45,-7,minecraft:nether_wart_block)
B(-4,46,-7,minecraft:nether_wart_block)
B(-4,47,-7,minecraft:nether_wart_block)
B(-4,29,-6,minecraft:crimson_hyphae)
B(-4,30,-6,minecraft:crimson_hyphae)
B(-4,31,-6,minecraft:crimson_hyphae)
B(-4,32,-6,minecraft:crimson_hyphae)
B(-4,33,-6,minecraft:crimson_hyphae)
B(-4,34,-6,minecraft:crimson_hyphae)
B(-4,35,-6,minecraft:crimson_hyphae)
B(-4,36,-6,minecraft:crimson_hyphae)
B(-4,37,-6,minecraft:crimson_hyphae)
B(-4,41,-6,minecraft:nether_wart_block)
B(-4,42,-6,minecraft:nether_wart_block)
B(-4,43,-6,minecraft:nether_wart_block)
B(-4,44,-6,minecraft:nether_wart_block)
B(-4,45,-6,minecraft:nether_wart_block)
B(-4,46,-6,minecraft:nether_wart_block)
B(-4,47,-6,minecraft:nether_wart_block)
B(-4,30,-5,minecraft:crimson_hyphae)
B(-4,31,-5,minecraft:crimson_hyphae)
B(-4,32,-5,minecraft:crimson_hyphae)
B(-4,33,-5,minecraft:crimson_hyphae)
B(-4,34,-5,minecraft:crimson_hyphae)
B(-4,35,-5,minecraft:crimson_hyphae)
B(-4,36,-5,minecraft:crimson_hyphae)
B(-4,37,-5,minecraft:crimson_hyphae)
B(-4,38,-5,minecraft:crimson_hyphae)
B(-4,40,-5,minecraft:nether_wart_block)
B(-4,41,-5,minecraft:nether_wart_block)
B(-4,42,-5,minecraft:nether_wart_block)
B(-4,43,-5,minecraft:nether_wart_block)
B(-4,44,-5,minecraft:nether_wart_block)
B(-4,31,-4,minecraft:crimson_hyphae)
B(-4,32,-4,minecraft:crimson_hyphae)
B(-4,33,-4,minecraft:crimson_hyphae)
B(-4,34,-4,minecraft:crimson_hyphae)
B(-4,35,-4,minecraft:crimson_hyphae)
B(-4,36,-4,minecraft:crimson_hyphae)
B(-4,37,-4,minecraft:crimson_hyphae)
B(-4,38,-4,minecraft:crimson_hyphae)
B(-4,39,-4,minecraft:nether_wart_block)
B(-4,40,-4,minecraft:nether_wart_block)
B(-4,41,-4,minecraft:nether_wart_block)
B(-4,42,-4,minecraft:nether_wart_block)
B(-4,43,-4,minecraft:nether_wart_block)
B(-4,44,-4,minecraft:nether_wart_block)
B(-4,45,-4,minecraft:nether_wart_block)
B(-4,32,-3,minecraft:crimson_hyphae)
B(-4,33,-3,minecraft:crimson_hyphae)
B(-4,34,-3,minecraft:crimson_hyphae)
B(-4,35,-3,minecraft:crimson_hyphae)
B(-4,36,-3,minecraft:nether_wart_block)
B(-4,37,-3,minecraft:nether_wart_block)
B(-4,38,-3,minecraft:nether_wart_block)
B(-4,39,-3,minecraft:nether_wart_block)
B(-4,40,-3,minecraft:nether_wart_block)
B(-4,41,-3,minecraft:nether_wart_block)
B(-4,42,-3,minecraft:nether_wart_block)
B(-4,43,-3,minecraft:nether_wart_block)
B(-4,44,-3,minecraft:nether_wart_block)
B(-4,45,-3,minecraft:nether_wart_block)
B(-4,33,-2,minecraft:nether_wart_block)
B(-4,34,-2,minecraft:nether_wart_block)
B(-4,35,-2,minecraft:nether_wart_block)
B(-4,36,-2,minecraft:nether_wart_block)
B(-4,37,-2,minecraft:nether_wart_block)
B(-4,38,-2,minecraft:nether_wart_block)
B(-4,39,-2,minecraft:nether_wart_block)
B(-4,40,-2,minecraft:nether_wart_block)
B(-4,41,-2,minecraft:nether_wart_block)
B(-4,42,-2,minecraft:nether_wart_block)
B(-4,43,-2,minecraft:nether_wart_block)
B(-4,44,-2,minecraft:nether_wart_block)
B(-4,45,-2,minecraft:nether_wart_block)
B(-4,30,-1,minecraft:nether_wart_block)
B(-4,31,-1,minecraft:nether_wart_block)
B(-4,32,-1,minecraft:nether_wart_block)
B(-4,33,-1,minecraft:nether_wart_block)
B(-4,34,-1,minecraft:nether_wart_block)
B(-4,35,-1,minecraft:nether_wart_block)
B(-4,36,-1,minecraft:nether_wart_block)
B(-4,37,-1,minecraft:nether_wart_block)
B(-4,38,-1,minecraft:nether_wart_block)
B(-4,39,-1,minecraft:nether_wart_block)
B(-4,40,-1,minecraft:nether_wart_block)
B(-4,41,-1,minecraft:nether_wart_block)
B(-4,42,-1,minecraft:nether_wart_block)
B(-4,43,-1,minecraft:nether_wart_block)
B(-4,44,-1,minecraft:nether_wart_block)
B(-4,45,-1,minecraft:nether_wart_block)
B(-4,29,0,minecraft:nether_wart_block)
B(-4,30,0,minecraft:nether_wart_block)
B(-4,31,0,minecraft:nether_wart_block)
B(-4,32,0,minecraft:nether_wart_block)
B(-4,33,0,minecraft:nether_wart_block)
B(-4,34,0,minecraft:nether_wart_block)
B(-4,35,0,minecraft:nether_wart_block)
B(-4,36,0,minecraft:nether_wart_block)
B(-4,37,0,minecraft:nether_wart_block)
B(-4,38,0,minecraft:nether_wart_block)
B(-4,39,0,minecraft:nether_wart_block)
B(-4,40,0,minecraft:nether_wart_block)
B(-4,41,0,minecraft:nether_wart_block)
B(-4,42,0,minecraft:nether_wart_block)
B(-4,43,0,minecraft:nether_wart_block)
B(-4,44,0,minecraft:nether_wart_block)
B(-4,45,0,minecraft:nether_wart_block)
B(-4,28,1,minecraft:nether_wart_block)
B(-4,29,1,minecraft:nether_wart_block)
B(-4,30,1,minecraft:nether_wart_block)
B(-4,31,1,minecraft:nether_wart_block)
B(-4,32,1,minecraft:nether_wart_block)
B(-4,33,1,minecraft:nether_wart_block)
B(-4,34,1,minecraft:nether_wart_block)
B(-4,35,1,minecraft:nether_wart_block)
B(-4,36,1,minecraft:nether_wart_block)
B(-4,37,1,minecraft:nether_wart_block)
B(-4,38,1,minecraft:nether_wart_block)
B(-4,39,1,minecraft:nether_wart_block)
B(-4,40,1,minecraft:nether_wart_block)
B(-4,41,1,minecraft:nether_wart_block)
B(-4,42,1,minecraft:nether_wart_block)
B(-4,43,1,minecraft:nether_wart_block)
B(-4,44,1,minecraft:nether_wart_block)
B(-4,28,2,minecraft:nether_wart_block)
B(-4,29,2,minecraft:nether_wart_block)
B(-4,30,2,minecraft:nether_wart_block)
B(-4,31,2,minecraft:nether_wart_block)
B(-4,32,2,minecraft:nether_wart_block)
B(-4,33,2,minecraft:nether_wart_block)
B(-4,34,2,minecraft:nether_wart_block)
B(-4,35,2,minecraft:nether_wart_block)
B(-4,36,2,minecraft:nether_wart_block)
B(-4,37,2,minecraft:nether_wart_block)
B(-4,38,2,minecraft:nether_wart_block)
B(-4,39,2,minecraft:nether_wart_block)
B(-4,40,2,minecraft:nether_wart_block)
B(-4,41,2,minecraft:nether_wart_block)
B(-4,42,2,minecraft:nether_wart_block)
B(-4,43,2,minecraft:nether_wart_block)
B(-4,44,2,minecraft:nether_wart_block)
B(-4,28,3,minecraft:nether_wart_block)
B(-4,29,3,minecraft:nether_wart_block)
B(-4,30,3,minecraft:nether_wart_block)
B(-4,31,3,minecraft:nether_wart_block)
B(-4,32,3,minecraft:nether_wart_block)
B(-4,33,3,minecraft:nether_wart_block)
B(-4,34,3,minecraft:nether_wart_block)
B(-4,35,3,minecraft:nether_wart_block)
B(-4,36,3,minecraft:nether_wart_block)
B(-4,37,3,minecraft:nether_wart_block)
B(-4,38,3,minecraft:nether_wart_block)
B(-4,39,3,minecraft:nether_wart_block)
B(-4,40,3,minecraft:nether_wart_block)
B(-4,41,3,minecraft:nether_wart_block)
B(-4,42,3,minecraft:nether_wart_block)
B(-4,43,3,minecraft:nether_wart_block)
B(-4,24,4,minecraft:nether_wart_block)
B(-4,25,4,minecraft:nether_wart_block)
B(-4,26,4,minecraft:nether_wart_block)
B(-4,27,4,minecraft:nether_wart_block)
B(-4,28,4,minecraft:nether_wart_block)
B(-4,29,4,minecraft:nether_wart_block)
B(-4,30,4,minecraft:nether_wart_block)
B(-4,31,4,minecraft:nether_wart_block)
B(-4,32,4,minecraft:nether_wart_block)
B(-4,33,4,minecraft:nether_wart_block)
B(-4,34,4,minecraft:nether_wart_block)
B(-4,35,4,minecraft:nether_wart_block)
B(-4,36,4,minecraft:nether_wart_block)
B(-4,37,4,minecraft:nether_wart_block)
B(-4,38,4,minecraft:nether_wart_block)
B(-4,39,4,minecraft:nether_wart_block)
B(-4,40,4,minecraft:nether_wart_block)
B(-4,41,4,minecraft:nether_wart_block)
B(-4,42,4,minecraft:nether_wart_block)
B(-4,21,5,minecraft:nether_wart_block)
B(-4,22,5,minecraft:nether_wart_block)
B(-4,23,5,minecraft:nether_wart_block)
B(-4,24,5,minecraft:nether_wart_block)
B(-4,25,5,minecraft:nether_wart_block)
B(-4,26,5,minecraft:nether_wart_block)
B(-4,27,5,minecraft:nether_wart_block)
B(-4,28,5,minecraft:nether_wart_block)
B(-4,29,5,minecraft:nether_wart_block)
B(-4,30,5,minecraft:nether_wart_block)
B(-4,31,5,minecraft:nether_wart_block)
B(-4,32,5,minecraft:nether_wart_block)
B(-4,33,5,minecraft:nether_wart_block)
B(-4,34,5,minecraft:nether_wart_block)
B(-4,35,5,minecraft:nether_wart_block)
B(-4,36,5,minecraft:nether_wart_block)
B(-4,37,5,minecraft:nether_wart_block)
B(-4,38,5,minecraft:nether_wart_block)
B(-4,39,5,minecraft:nether_wart_block)
B(-4,40,5,minecraft:nether_wart_block)
B(-4,41,5,minecraft:nether_wart_block)
B(-4,42,5,minecraft:nether_wart_block)
B(-4,20,6,minecraft:nether_wart_block)
B(-4,21,6,minecraft:nether_wart_block)
B(-4,22,6,minecraft:nether_wart_block)
B(-4,23,6,minecraft:nether_wart_block)
B(-4,24,6,minecraft:nether_wart_block)
B(-4,25,6,minecraft:nether_wart_block)
B(-4,26,6,minecraft:nether_wart_block)
B(-4,27,6,minecraft:nether_wart_block)
B(-4,28,6,minecraft:nether_wart_block)
B(-4,29,6,minecraft:nether_wart_block)
B(-4,30,6,minecraft:nether_wart_block)
B(-4,31,6,minecraft:nether_wart_block)
B(-4,32,6,minecraft:nether_wart_block)
B(-4,33,6,minecraft:nether_wart_block)
B(-4,34,6,minecraft:nether_wart_block)
B(-4,35,6,minecraft:nether_wart_block)
B(-4,36,6,minecraft:nether_wart_block)
B(-4,37,6,minecraft:nether_wart_block)
B(-4,19,7,minecraft:nether_wart_block)
B(-4,20,7,minecraft:nether_wart_block)
B(-4,21,7,minecraft:nether_wart_block)
B(-4,22,7,minecraft:nether_wart_block)
B(-4,23,7,minecraft:nether_wart_block)
B(-4,24,7,minecraft:nether_wart_block)
B(-4,25,7,minecraft:nether_wart_block)
B(-4,26,7,minecraft:nether_wart_block)
B(-4,27,7,minecraft:nether_wart_block)
B(-4,28,7,minecraft:nether_wart_block)
B(-4,29,7,minecraft:nether_wart_block)
B(-4,30,7,minecraft:nether_wart_block)
B(-4,31,7,minecraft:nether_wart_block)
B(-4,32,7,minecraft:nether_wart_block)
B(-4,33,7,minecraft:nether_wart_block)
B(-4,34,7,minecraft:nether_wart_block)
B(-4,35,7,minecraft:nether_wart_block)
B(-4,36,7,minecraft:nether_wart_block)
B(-4,19,8,minecraft:nether_wart_block)
B(-4,20,8,minecraft:nether_wart_block)
B(-4,21,8,minecraft:nether_wart_block)
B(-4,22,8,minecraft:nether_wart_block)
B(-4,23,8,minecraft:nether_wart_block)
B(-4,24,8,minecraft:nether_wart_block)
B(-4,25,8,minecraft:nether_wart_block)
B(-4,26,8,minecraft:nether_wart_block)
B(-4,27,8,minecraft:nether_wart_block)
B(-4,28,8,minecraft:nether_wart_block)
B(-4,29,8,minecraft:nether_wart_block)
B(-4,30,8,minecraft:nether_wart_block)
B(-4,31,8,minecraft:nether_wart_block)
B(-4,32,8,minecraft:nether_wart_block)
B(-4,33,8,minecraft:nether_wart_block)
B(-4,34,8,minecraft:nether_wart_block)
B(-4,35,8,minecraft:nether_wart_block)
B(-3,28,-7,minecraft:crimson_hyphae)
B(-3,29,-7,minecraft:crimson_hyphae)
B(-3,30,-7,minecraft:crimson_hyphae)
B(-3,31,-7,minecraft:crimson_hyphae)
B(-3,32,-7,minecraft:crimson_hyphae)
B(-3,33,-7,minecraft:crimson_hyphae)
B(-3,34,-7,minecraft:crimson_hyphae)
B(-3,35,-7,minecraft:crimson_hyphae)
B(-3,36,-7,minecraft:crimson_hyphae)
B(-3,42,-7,minecraft:nether_wart_block)
B(-3,43,-7,minecraft:nether_wart_block)
B(-3,44,-7,minecraft:nether_wart_block)
B(-3,45,-7,minecraft:nether_wart_block)
B(-3,46,-7,minecraft:nether_wart_block)
B(-3,47,-7,minecraft:nether_wart_block)
B(-3,48,-7,minecraft:nether_wart_block)
B(-3,29,-6,minecraft:crimson_hyphae)
B(-3,30,-6,minecraft:crimson_hyphae)
B(-3,31,-6,minecraft:crimson_hyphae)
B(-3,32,-6,minecraft:crimson_hyphae)
B(-3,33,-6,minecraft:crimson_hyphae)
B(-3,34,-6,minecraft:crimson_hyphae)
B(-3,35,-6,minecraft:crimson_hyphae)
B(-3,36,-6,minecraft:crimson_hyphae)
B(-3,37,-6,minecraft:crimson_hyphae)
B(-3,41,-6,minecraft:nether_wart_block)
B(-3,42,-6,minecraft:nether_wart_block)
B(-3,43,-6,minecraft:nether_wart_block)
B(-3,44,-6,minecraft:nether_wart_block)
B(-3,45,-6,minecraft:nether_wart_block)
B(-3,46,-6,minecraft:nether_wart_block)
B(-3,47,-6,minecraft:nether_wart_block)
B(-3,30,-5,minecraft:crimson_hyphae)
B(-3,31,-5,minecraft:crimson_hyphae)
B(-3,32,-5,minecraft:crimson_hyphae)
B(-3,33,-5,minecraft:crimson_hyphae)
B(-3,34,-5,minecraft:crimson_hyphae)
B(-3,35,-5,minecraft:crimson_hyphae)
B(-3,36,-5,minecraft:crimson_hyphae)
B(-3,37,-5,minecraft:crimson_hyphae)
B(-3,40,-5,minecraft:nether_wart_block)
B(-3,41,-5,minecraft:nether_wart_block)
B(-3,42,-5,minecraft:nether_wart_block)
B(-3,43,-5,minecraft:nether_wart_block)
B(-3,44,-5,minecraft:nether_wart_block)
B(-3,45,-5,minecraft:nether_wart_block)
B(-3,46,-5,minecraft:nether_wart_block)
B(-3,31,-4,minecraft:crimson_hyphae)
B(-3,32,-4,minecraft:crimson_hyphae)
B(-3,33,-4,minecraft:crimson_hyphae)
B(-3,34,-4,minecraft:crimson_hyphae)
B(-3,35,-4,minecraft:crimson_hyphae)
B(-3,36,-4,minecraft:crimson_hyphae)
B(-3,37,-4,minecraft:crimson_hyphae)
B(-3,39,-4,minecraft:nether_wart_block)
B(-3,40,-4,minecraft:nether_wart_block)
B(-3,41,-4,minecraft:nether_wart_block)
B(-3,42,-4,minecraft:nether_wart_block)
B(-3,43,-4,minecraft:nether_wart_block)
B(-3,44,-4,minecraft:nether_wart_block)
B(-3,45,-4,minecraft:nether_wart_block)
B(-3,32,-3,minecraft:crimson_hyphae)
B(-3,33,-3,minecraft:crimson_hyphae)
B(-3,34,-3,minecraft:crimson_hyphae)
B(-3,35,-3,minecraft:crimson_hyphae)
B(-3,36,-3,minecraft:crimson_hyphae)
B(-3,37,-3,minecraft:crimson_hyphae)
B(-3,39,-3,minecraft:nether_wart_block)
B(-3,40,-3,minecraft:nether_wart_block)
B(-3,41,-3,minecraft:nether_wart_block)
B(-3,42,-3,minecraft:nether_wart_block)
B(-3,43,-3,minecraft:nether_wart_block)
B(-3,44,-3,minecraft:nether_wart_block)
B(-3,45,-3,minecraft:nether_wart_block)
B(-3,33,-2,minecraft:nether_wart_block)
B(-3,34,-2,minecraft:nether_wart_block)
B(-3,35,-2,minecraft:nether_wart_block)
B(-3,36,-2,minecraft:nether_wart_block)
B(-3,37,-2,minecraft:nether_wart_block)
B(-3,38,-2,minecraft:nether_wart_block)
B(-3,39,-2,minecraft:nether_wart_block)
B(-3,40,-2,minecraft:nether_wart_block)
B(-3,41,-2,minecraft:nether_wart_block)
B(-3,42,-2,minecraft:nether_wart_block)
B(-3,43,-2,minecraft:nether_wart_block)
B(-3,44,-2,minecraft:nether_wart_block)
B(-3,45,-2,minecraft:nether_wart_block)
B(-3,30,-1,minecraft:nether_wart_block)
B(-3,31,-1,minecraft:nether_wart_block)
B(-3,32,-1,minecraft:nether_wart_block)
B(-3,33,-1,minecraft:nether_wart_block)
B(-3,34,-1,minecraft:nether_wart_block)
B(-3,35,-1,minecraft:nether_wart_block)
B(-3,36,-1,minecraft:nether_wart_block)
B(-3,37,-1,minecraft:nether_wart_block)
B(-3,38,-1,minecraft:nether_wart_block)
B(-3,39,-1,minecraft:nether_wart_block)
B(-3,40,-1,minecraft:nether_wart_block)
B(-3,41,-1,minecraft:nether_wart_block)
B(-3,42,-1,minecraft:nether_wart_block)
B(-3,43,-1,minecraft:nether_wart_block)
B(-3,44,-1,minecraft:nether_wart_block)
B(-3,45,-1,minecraft:nether_wart_block)
B(-3,29,0,minecraft:nether_wart_block)
B(-3,30,0,minecraft:nether_wart_block)
B(-3,31,0,minecraft:nether_wart_block)
B(-3,32,0,minecraft:nether_wart_block)
B(-3,33,0,minecraft:nether_wart_block)
B(-3,34,0,minecraft:nether_wart_block)
B(-3,35,0,minecraft:nether_wart_block)
B(-3,36,0,minecraft:nether_wart_block)
B(-3,37,0,minecraft:nether_wart_block)
B(-3,38,0,minecraft:nether_wart_block)
B(-3,39,0,minecraft:nether_wart_block)
B(-3,40,0,minecraft:nether_wart_block)
B(-3,41,0,minecraft:nether_wart_block)
B(-3,42,0,minecraft:nether_wart_block)
B(-3,43,0,minecraft:nether_wart_block)
B(-3,44,0,minecraft:nether_wart_block)
B(-3,45,0,minecraft:nether_wart_block)
B(-3,28,1,minecraft:nether_wart_block)
B(-3,29,1,minecraft:nether_wart_block)
B(-3,30,1,minecraft:nether_wart_block)
B(-3,31,1,minecraft:nether_wart_block)
B(-3,32,1,minecraft:nether_wart_block)
B(-3,33,1,minecraft:nether_wart_block)
B(-3,34,1,minecraft:nether_wart_block)
B(-3,35,1,minecraft:nether_wart_block)
B(-3,36,1,minecraft:nether_wart_block)
B(-3,37,1,minecraft:nether_wart_block)
B(-3,38,1,minecraft:nether_wart_block)
B(-3,39,1,minecraft:nether_wart_block)
B(-3,40,1,minecraft:nether_wart_block)
B(-3,41,1,minecraft:nether_wart_block)
B(-3,42,1,minecraft:nether_wart_block)
B(-3,43,1,minecraft:nether_wart_block)
B(-3,44,1,minecraft:nether_wart_block)
B(-3,45,1,minecraft:nether_wart_block)
B(-3,28,2,minecraft:nether_wart_block)
B(-3,29,2,minecraft:nether_wart_block)
B(-3,30,2,minecraft:nether_wart_block)
B(-3,31,2,minecraft:nether_wart_block)
B(-3,32,2,minecraft:nether_wart_block)
B(-3,33,2,minecraft:nether_wart_block)
B(-3,34,2,minecraft:nether_wart_block)
B(-3,35,2,minecraft:nether_wart_block)
B(-3,36,2,minecraft:nether_wart_block)
B(-3,37,2,minecraft:nether_wart_block)
B(-3,38,2,minecraft:nether_wart_block)
B(-3,39,2,minecraft:nether_wart_block)
B(-3,40,2,minecraft:nether_wart_block)
B(-3,41,2,minecraft:nether_wart_block)
B(-3,42,2,minecraft:nether_wart_block)
B(-3,43,2,minecraft:nether_wart_block)
B(-3,28,3,minecraft:nether_wart_block)
B(-3,29,3,minecraft:nether_wart_block)
B(-3,30,3,minecraft:nether_wart_block)
B(-3,31,3,minecraft:nether_wart_block)
B(-3,32,3,minecraft:nether_wart_block)
B(-3,33,3,minecraft:nether_wart_block)
B(-3,34,3,minecraft:nether_wart_block)
B(-3,35,3,minecraft:nether_wart_block)
B(-3,36,3,minecraft:nether_wart_block)
B(-3,37,3,minecraft:nether_wart_block)
B(-3,38,3,minecraft:nether_wart_block)
B(-3,39,3,minecraft:nether_wart_block)
B(-3,40,3,minecraft:nether_wart_block)
B(-3,41,3,minecraft:nether_wart_block)
B(-3,42,3,minecraft:nether_wart_block)
B(-3,43,3,minecraft:nether_wart_block)
B(-3,24,4,minecraft:nether_wart_block)
B(-3,25,4,minecraft:nether_wart_block)
B(-3,26,4,minecraft:nether_wart_block)
B(-3,27,4,minecraft:nether_wart_block)
B(-3,28,4,minecraft:nether_wart_block)
B(-3,29,4,minecraft:nether_wart_block)
B(-3,30,4,minecraft:nether_wart_block)
B(-3,31,4,minecraft:nether_wart_block)
B(-3,32,4,minecraft:nether_wart_block)
B(-3,33,4,minecraft:nether_wart_block)
B(-3,34,4,minecraft:nether_wart_block)
B(-3,35,4,minecraft:nether_wart_block)
B(-3,36,4,minecraft:nether_wart_block)
B(-3,37,4,minecraft:nether_wart_block)
B(-3,38,4,minecraft:nether_wart_block)
B(-3,39,4,minecraft:nether_wart_block)
B(-3,40,4,minecraft:nether_wart_block)
B(-3,41,4,minecraft:nether_wart_block)
B(-3,42,4,minecraft:nether_wart_block)
B(-3,43,4,minecraft:nether_wart_block)
B(-3,21,5,minecraft:nether_wart_block)
B(-3,22,5,minecraft:nether_wart_block)
B(-3,23,5,minecraft:nether_wart_block)
B(-3,24,5,minecraft:nether_wart_block)
B(-3,25,5,minecraft:nether_wart_block)
B(-3,26,5,minecraft:nether_wart_block)
B(-3,27,5,minecraft:nether_wart_block)
B(-3,28,5,minecraft:nether_wart_block)
B(-3,29,5,minecraft:nether_wart_block)
B(-3,30,5,minecraft:nether_wart_block)
B(-3,31,5,minecraft:nether_wart_block)
B(-3,32,5,minecraft:nether_wart_block)
B(-3,33,5,minecraft:nether_wart_block)
B(-3,34,5,minecraft:nether_wart_block)
B(-3,35,5,minecraft:nether_wart_block)
B(-3,36,5,minecraft:nether_wart_block)
B(-3,37,5,minecraft:nether_wart_block)
B(-3,38,5,minecraft:nether_wart_block)
B(-3,39,5,minecraft:nether_wart_block)
B(-3,40,5,minecraft:nether_wart_block)
B(-3,41,5,minecraft:nether_wart_block)
B(-3,42,5,minecraft:nether_wart_block)
B(-3,43,5,minecraft:nether_wart_block)
B(-3,20,6,minecraft:nether_wart_block)
B(-3,21,6,minecraft:nether_wart_block)
B(-3,22,6,minecraft:nether_wart_block)
B(-3,23,6,minecraft:nether_wart_block)
B(-3,24,6,minecraft:nether_wart_block)
B(-3,25,6,minecraft:nether_wart_block)
B(-3,26,6,minecraft:nether_wart_block)
B(-3,27,6,minecraft:nether_wart_block)
B(-3,28,6,minecraft:nether_wart_block)
B(-3,29,6,minecraft:nether_wart_block)
B(-3,30,6,minecraft:nether_wart_block)
B(-3,31,6,minecraft:nether_wart_block)
B(-3,32,6,minecraft:nether_wart_block)
B(-3,33,6,minecraft:nether_wart_block)
B(-3,34,6,minecraft:nether_wart_block)
B(-3,35,6,minecraft:nether_wart_block)
B(-3,36,6,minecraft:nether_wart_block)
B(-3,37,6,minecraft:nether_wart_block)
B(-3,39,6,minecraft:nether_wart_block)
B(-3,40,6,minecraft:nether_wart_block)
B(-3,41,6,minecraft:nether_wart_block)
B(-3,42,6,minecraft:nether_wart_block)
B(-3,43,6,minecraft:nether_wart_block)
B(-3,19,7,minecraft:nether_wart_block)
B(-3,20,7,minecraft:nether_wart_block)
B(-3,21,7,minecraft:nether_wart_block)
B(-3,22,7,minecraft:nether_wart_block)
B(-3,23,7,minecraft:nether_wart_block)
B(-3,24,7,minecraft:nether_wart_block)
B(-3,25,7,minecraft:nether_wart_block)
B(-3,26,7,minecraft:nether_wart_block)
B(-3,27,7,minecraft:nether_wart_block)
B(-3,28,7,minecraft:nether_wart_block)
B(-3,29,7,minecraft:nether_wart_block)
B(-3,30,7,minecraft:nether_wart_block)
B(-3,31,7,minecraft:nether_wart_block)
B(-3,32,7,minecraft:nether_wart_block)
B(-3,33,7,minecraft:nether_wart_block)
B(-3,34,7,minecraft:nether_wart_block)
B(-3,35,7,minecraft:nether_wart_block)
B(-3,36,7,minecraft:nether_wart_block)
B(-3,19,8,minecraft:nether_wart_block)
B(-3,20,8,minecraft:nether_wart_block)
B(-3,21,8,minecraft:nether_wart_block)
B(-3,22,8,minecraft:nether_wart_block)
B(-3,23,8,minecraft:nether_wart_block)
B(-3,24,8,minecraft:nether_wart_block)
B(-3,25,8,minecraft:nether_wart_block)
B(-3,26,8,minecraft:nether_wart_block)
B(-3,27,8,minecraft:nether_wart_block)
B(-3,28,8,minecraft:nether_wart_block)
B(-3,29,8,minecraft:nether_wart_block)
B(-3,30,8,minecraft:nether_wart_block)
B(-3,31,8,minecraft:nether_wart_block)
B(-3,32,8,minecraft:nether_wart_block)
B(-3,33,8,minecraft:nether_wart_block)
B(-3,34,8,minecraft:nether_wart_block)
B(-3,35,8,minecraft:nether_wart_block)
B(-3,36,8,minecraft:nether_wart_block)
B(-2,28,-7,minecraft:crimson_hyphae)
B(-2,29,-7,minecraft:crimson_hyphae)
B(-2,30,-7,minecraft:crimson_hyphae)
B(-2,31,-7,minecraft:crimson_hyphae)
B(-2,32,-7,minecraft:crimson_hyphae)
B(-2,33,-7,minecraft:crimson_hyphae)
B(-2,34,-7,minecraft:crimson_hyphae)
B(-2,35,-7,minecraft:crimson_hyphae)
B(-2,36,-7,minecraft:crimson_hyphae)
B(-2,42,-7,minecraft:nether_wart_block)
B(-2,43,-7,minecraft:nether_wart_block)
B(-2,44,-7,minecraft:nether_wart_block)
B(-2,45,-7,minecraft:nether_wart_block)
B(-2,46,-7,minecraft:nether_wart_block)
B(-2,47,-7,minecraft:nether_wart_block)
B(-2,48,-7,minecraft:nether_wart_block)
B(-2,29,-6,minecraft:crimson_hyphae)
B(-2,30,-6,minecraft:crimson_hyphae)
B(-2,31,-6,minecraft:crimson_hyphae)
B(-2,32,-6,minecraft:crimson_hyphae)
B(-2,33,-6,minecraft:crimson_hyphae)
B(-2,34,-6,minecraft:crimson_hyphae)
B(-2,35,-6,minecraft:crimson_hyphae)
B(-2,36,-6,minecraft:crimson_hyphae)
B(-2,41,-6,minecraft:nether_wart_block)
B(-2,42,-6,minecraft:nether_wart_block)
B(-2,43,-6,minecraft:nether_wart_block)
B(-2,44,-6,minecraft:nether_wart_block)
B(-2,45,-6,minecraft:nether_wart_block)
B(-2,46,-6,minecraft:nether_wart_block)
B(-2,47,-6,minecraft:nether_wart_block)
B(-2,30,-5,minecraft:crimson_hyphae)
B(-2,31,-5,minecraft:crimson_hyphae)
B(-2,32,-5,minecraft:crimson_hyphae)
B(-2,33,-5,minecraft:crimson_hyphae)
B(-2,34,-5,minecraft:crimson_hyphae)
B(-2,35,-5,minecraft:crimson_hyphae)
B(-2,36,-5,minecraft:crimson_hyphae)
B(-2,40,-5,minecraft:nether_wart_block)
B(-2,41,-5,minecraft:nether_wart_block)
B(-2,42,-5,minecraft:nether_wart_block)
B(-2,43,-5,minecraft:nether_wart_block)
B(-2,44,-5,minecraft:nether_wart_block)
B(-2,45,-5,minecraft:nether_wart_block)
B(-2,46,-5,minecraft:nether_wart_block)
B(-2,47,-5,minecraft:nether_wart_block)
B(-2,32,-4,minecraft:crimson_hyphae)
B(-2,33,-4,minecraft:crimson_hyphae)
B(-2,34,-4,minecraft:crimson_hyphae)
B(-2,35,-4,minecraft:crimson_hyphae)
B(-2,36,-4,minecraft:crimson_hyphae)
B(-2,39,-4,minecraft:nether_wart_block)
B(-2,40,-4,minecraft:nether_wart_block)
B(-2,41,-4,minecraft:nether_wart_block)
B(-2,42,-4,minecraft:nether_wart_block)
B(-2,43,-4,minecraft:nether_wart_block)
B(-2,44,-4,minecraft:nether_wart_block)
B(-2,45,-4,minecraft:nether_wart_block)
B(-2,46,-4,minecraft:nether_wart_block)
B(-2,47,-4,minecraft:nether_wart_block)
B(-2,32,-3,minecraft:crimson_hyphae)
B(-2,33,-3,minecraft:crimson_hyphae)
B(-2,34,-3,minecraft:crimson_hyphae)
B(-2,35,-3,minecraft:crimson_hyphae)
B(-2,36,-3,minecraft:crimson_hyphae)
B(-2,39,-3,minecraft:nether_wart_block)
B(-2,40,-3,minecraft:nether_wart_block)
B(-2,41,-3,minecraft:nether_wart_block)
B(-2,42,-3,minecraft:nether_wart_block)
B(-2,43,-3,minecraft:nether_wart_block)
B(-2,44,-3,minecraft:nether_wart_block)
B(-2,45,-3,minecraft:nether_wart_block)
B(-2,39,-2,minecraft:nether_wart_block)
B(-2,40,-2,minecraft:nether_wart_block)
B(-2,41,-2,minecraft:nether_wart_block)
B(-2,42,-2,minecraft:nether_wart_block)
B(-2,43,-2,minecraft:nether_wart_block)
B(-2,44,-2,minecraft:nether_wart_block)
B(-2,45,-2,minecraft:nether_wart_block)
B(-2,46,-2,minecraft:nether_wart_block)
B(-2,30,-1,minecraft:nether_wart_block)
B(-2,31,-1,minecraft:nether_wart_block)
B(-2,32,-1,minecraft:nether_wart_block)
B(-2,33,-1,minecraft:nether_wart_block)
B(-2,34,-1,minecraft:nether_wart_block)
B(-2,35,-1,minecraft:nether_wart_block)
B(-2,36,-1,minecraft:nether_wart_block)
B(-2,37,-1,minecraft:nether_wart_block)
B(-2,38,-1,minecraft:nether_wart_block)
B(-2,39,-1,minecraft:nether_wart_block)
B(-2,40,-1,minecraft:nether_wart_block)
B(-2,41,-1,minecraft:nether_wart_block)
B(-2,42,-1,minecraft:nether_wart_block)
B(-2,43,-1,minecraft:nether_wart_block)
B(-2,44,-1,minecraft:nether_wart_block)
B(-2,45,-1,minecraft:nether_wart_block)
B(-2,46,-1,minecraft:nether_wart_block)
B(-2,29,0,minecraft:nether_wart_block)
B(-2,30,0,minecraft:nether_wart_block)
B(-2,31,0,minecraft:nether_wart_block)
B(-2,32,0,minecraft:nether_wart_block)
B(-2,33,0,minecraft:nether_wart_block)
B(-2,34,0,minecraft:nether_wart_block)
B(-2,35,0,minecraft:nether_wart_block)
B(-2,36,0,minecraft:nether_wart_block)
B(-2,37,0,minecraft:nether_wart_block)
B(-2,38,0,minecraft:nether_wart_block)
B(-2,39,0,minecraft:nether_wart_block)
B(-2,40,0,minecraft:nether_wart_block)
B(-2,41,0,minecraft:nether_wart_block)
B(-2,42,0,minecraft:nether_wart_block)
B(-2,43,0,minecraft:nether_wart_block)
B(-2,44,0,minecraft:nether_wart_block)
B(-2,45,0,minecraft:nether_wart_block)
B(-2,46,0,minecraft:nether_wart_block)
B(-2,28,1,minecraft:nether_wart_block)
B(-2,29,1,minecraft:nether_wart_block)
B(-2,30,1,minecraft:nether_wart_block)
B(-2,31,1,minecraft:nether_wart_block)
B(-2,32,1,minecraft:nether_wart_block)
B(-2,33,1,minecraft:nether_wart_block)
B(-2,34,1,minecraft:nether_wart_block)
B(-2,35,1,minecraft:nether_wart_block)
B(-2,36,1,minecraft:nether_wart_block)
B(-2,37,1,minecraft:nether_wart_block)
B(-2,38,1,minecraft:nether_wart_block)
B(-2,39,1,minecraft:nether_wart_block)
B(-2,40,1,minecraft:nether_wart_block)
B(-2,41,1,minecraft:nether_wart_block)
B(-2,42,1,minecraft:nether_wart_block)
B(-2,43,1,minecraft:nether_wart_block)
B(-2,44,1,minecraft:nether_wart_block)
B(-2,45,1,minecraft:nether_wart_block)
B(-2,28,2,minecraft:nether_wart_block)
B(-2,29,2,minecraft:nether_wart_block)
B(-2,30,2,minecraft:nether_wart_block)
B(-2,31,2,minecraft:nether_wart_block)
B(-2,32,2,minecraft:nether_wart_block)
B(-2,33,2,minecraft:nether_wart_block)
B(-2,34,2,minecraft:nether_wart_block)
B(-2,35,2,minecraft:nether_wart_block)
B(-2,36,2,minecraft:nether_wart_block)
B(-2,37,2,minecraft:nether_wart_block)
B(-2,38,2,minecraft:nether_wart_block)
B(-2,39,2,minecraft:nether_wart_block)
B(-2,40,2,minecraft:nether_wart_block)
B(-2,41,2,minecraft:nether_wart_block)
B(-2,42,2,minecraft:nether_wart_block)
B(-2,43,2,minecraft:nether_wart_block)
B(-2,44,2,minecraft:nether_wart_block)
B(-2,28,3,minecraft:nether_wart_block)
B(-2,29,3,minecraft:nether_wart_block)
B(-2,30,3,minecraft:nether_wart_block)
B(-2,31,3,minecraft:nether_wart_block)
B(-2,32,3,minecraft:nether_wart_block)
B(-2,33,3,minecraft:nether_wart_block)
B(-2,34,3,minecraft:nether_wart_block)
B(-2,35,3,minecraft:nether_wart_block)
B(-2,36,3,minecraft:nether_wart_block)
B(-2,37,3,minecraft:nether_wart_block)
B(-2,38,3,minecraft:nether_wart_block)
B(-2,39,3,minecraft:nether_wart_block)
B(-2,40,3,minecraft:nether_wart_block)
B(-2,41,3,minecraft:nether_wart_block)
B(-2,42,3,minecraft:nether_wart_block)
B(-2,43,3,minecraft:nether_wart_block)
B(-2,44,3,minecraft:nether_wart_block)
B(-2,24,4,minecraft:nether_wart_block)
B(-2,25,4,minecraft:nether_wart_block)
B(-2,26,4,minecraft:nether_wart_block)
B(-2,29,4,minecraft:nether_wart_block)
B(-2,30,4,minecraft:nether_wart_block)
B(-2,31,4,minecraft:nether_wart_block)
B(-2,32,4,minecraft:nether_wart_block)
B(-2,33,4,minecraft:nether_wart_block)
B(-2,34,4,minecraft:nether_wart_block)
B(-2,35,4,minecraft:nether_wart_block)
B(-2,36,4,minecraft:nether_wart_block)
B(-2,37,4,minecraft:nether_wart_block)
B(-2,38,4,minecraft:nether_wart_block)
B(-2,39,4,minecraft:nether_wart_block)
B(-2,40,4,minecraft:nether_wart_block)
B(-2,41,4,minecraft:nether_wart_block)
B(-2,42,4,minecraft:nether_wart_block)
B(-2,43,4,minecraft:nether_wart_block)
B(-2,44,4,minecraft:nether_wart_block)
B(-2,21,5,minecraft:nether_wart_block)
B(-2,22,5,minecraft:nether_wart_block)
B(-2,23,5,minecraft:nether_wart_block)
B(-2,24,5,minecraft:nether_wart_block)
B(-2,25,5,minecraft:nether_wart_block)
B(-2,26,5,minecraft:nether_wart_block)
B(-2,27,5,minecraft:nether_wart_block)
B(-2,28,5,minecraft:nether_wart_block)
B(-2,29,5,minecraft:nether_wart_block)
B(-2,30,5,minecraft:nether_wart_block)
B(-2,31,5,minecraft:nether_wart_block)
B(-2,32,5,minecraft:nether_wart_block)
B(-2,33,5,minecraft:nether_wart_block)
B(-2,34,5,minecraft:nether_wart_block)
B(-2,35,5,minecraft:nether_wart_block)
B(-2,36,5,minecraft:nether_wart_block)
B(-2,37,5,minecraft:nether_wart_block)
B(-2,38,5,minecraft:nether_wart_block)
B(-2,39,5,minecraft:nether_wart_block)
B(-2,40,5,minecraft:nether_wart_block)
B(-2,41,5,minecraft:nether_wart_block)
B(-2,42,5,minecraft:nether_wart_block)
B(-2,43,5,minecraft:nether_wart_block)
B(-2,44,5,minecraft:nether_wart_block)
B(-2,20,6,minecraft:nether_wart_block)
B(-2,21,6,minecraft:nether_wart_block)
B(-2,22,6,minecraft:nether_wart_block)
B(-2,23,6,minecraft:nether_wart_block)
B(-2,24,6,minecraft:nether_wart_block)
B(-2,25,6,minecraft:nether_wart_block)
B(-2,26,6,minecraft:nether_wart_block)
B(-2,27,6,minecraft:nether_wart_block)
B(-2,28,6,minecraft:nether_wart_block)
B(-2,29,6,minecraft:nether_wart_block)
B(-2,30,6,minecraft:nether_wart_block)
B(-2,31,6,minecraft:nether_wart_block)
B(-2,32,6,minecraft:nether_wart_block)
B(-2,33,6,minecraft:nether_wart_block)
B(-2,34,6,minecraft:nether_wart_block)
B(-2,35,6,minecraft:nether_wart_block)
B(-2,36,6,minecraft:nether_wart_block)
B(-2,37,6,minecraft:nether_wart_block)
B(-2,39,6,minecraft:nether_wart_block)
B(-2,40,6,minecraft:nether_wart_block)
B(-2,41,6,minecraft:nether_wart_block)
B(-2,42,6,minecraft:nether_wart_block)
B(-2,43,6,minecraft:nether_wart_block)
B(-2,19,7,minecraft:nether_wart_block)
B(-2,20,7,minecraft:nether_wart_block)
B(-2,21,7,minecraft:nether_wart_block)
B(-2,22,7,minecraft:nether_wart_block)
B(-2,23,7,minecraft:nether_wart_block)
B(-2,24,7,minecraft:nether_wart_block)
B(-2,25,7,minecraft:nether_wart_block)
B(-2,26,7,minecraft:nether_wart_block)
B(-2,27,7,minecraft:nether_wart_block)
B(-2,28,7,minecraft:nether_wart_block)
B(-2,29,7,minecraft:nether_wart_block)
B(-2,30,7,minecraft:nether_wart_block)
B(-2,31,7,minecraft:nether_wart_block)
B(-2,32,7,minecraft:nether_wart_block)
B(-2,33,7,minecraft:nether_wart_block)
B(-2,34,7,minecraft:nether_wart_block)
B(-2,35,7,minecraft:nether_wart_block)
B(-2,36,7,minecraft:nether_wart_block)
B(-2,37,7,minecraft:nether_wart_block)
B(-2,40,7,minecraft:nether_wart_block)
B(-2,41,7,minecraft:nether_wart_block)
B(-2,42,7,minecraft:nether_wart_block)
B(-2,19,8,minecraft:nether_wart_block)
B(-2,20,8,minecraft:nether_wart_block)
B(-2,21,8,minecraft:nether_wart_block)
B(-2,22,8,minecraft:nether_wart_block)
B(-2,23,8,minecraft:nether_wart_block)
B(-2,24,8,minecraft:nether_wart_block)
B(-2,25,8,minecraft:nether_wart_block)
B(-2,26,8,minecraft:nether_wart_block)
B(-2,27,8,minecraft:nether_wart_block)
B(-2,28,8,minecraft:nether_wart_block)
B(-2,29,8,minecraft:nether_wart_block)
B(-2,30,8,minecraft:nether_wart_block)
B(-2,31,8,minecraft:nether_wart_block)
B(-2,32,8,minecraft:nether_wart_block)
B(-2,33,8,minecraft:nether_wart_block)
B(-2,34,8,minecraft:nether_wart_block)
B(-2,35,8,minecraft:nether_wart_block)
B(-2,36,8,minecraft:nether_wart_block)
B(-1,28,-7,minecraft:crimson_hyphae)
B(-1,29,-7,minecraft:crimson_hyphae)
B(-1,30,-7,minecraft:crimson_hyphae)
B(-1,31,-7,minecraft:crimson_hyphae)
B(-1,32,-7,minecraft:crimson_hyphae)
B(-1,33,-7,minecraft:crimson_hyphae)
B(-1,42,-7,minecraft:nether_wart_block)
B(-1,43,-7,minecraft:nether_wart_block)
B(-1,44,-7,minecraft:nether_wart_block)
B(-1,45,-7,minecraft:nether_wart_block)
B(-1,46,-7,minecraft:nether_wart_block)
B(-1,47,-7,minecraft:nether_wart_block)
B(-1,48,-7,minecraft:nether_wart_block)
B(-1,31,-6,minecraft:crimson_hyphae)
B(-1,32,-6,minecraft:crimson_hyphae)
B(-1,33,-6,minecraft:crimson_hyphae)
B(-1,34,-6,minecraft:crimson_hyphae)
B(-1,35,-6,minecraft:crimson_hyphae)
B(-1,42,-6,minecraft:nether_wart_block)
B(-1,43,-6,minecraft:nether_wart_block)
B(-1,44,-6,minecraft:nether_wart_block)
B(-1,45,-6,minecraft:nether_wart_block)
B(-1,46,-6,minecraft:nether_wart_block)
B(-1,47,-6,minecraft:nether_wart_block)
B(-1,48,-6,minecraft:nether_wart_block)
B(-1,33,-5,minecraft:crimson_hyphae)
B(-1,34,-5,minecraft:crimson_hyphae)
B(-1,35,-5,minecraft:crimson_hyphae)
B(-1,40,-5,minecraft:nether_wart_block)
B(-1,41,-5,minecraft:nether_wart_block)
B(-1,42,-5,minecraft:nether_wart_block)
B(-1,43,-5,minecraft:nether_wart_block)
B(-1,44,-5,minecraft:nether_wart_block)
B(-1,45,-5,minecraft:nether_wart_block)
B(-1,46,-5,minecraft:nether_wart_block)
B(-1,47,-5,minecraft:nether_wart_block)
B(-1,48,-5,minecraft:nether_wart_block)
B(-1,33,-4,minecraft:crimson_hyphae)
B(-1,34,-4,minecraft:crimson_hyphae)
B(-1,35,-4,minecraft:crimson_hyphae)
B(-1,40,-4,minecraft:nether_wart_block)
B(-1,41,-4,minecraft:nether_wart_block)
B(-1,42,-4,minecraft:nether_wart_block)
B(-1,43,-4,minecraft:nether_wart_block)
B(-1,44,-4,minecraft:nether_wart_block)
B(-1,45,-4,minecraft:nether_wart_block)
B(-1,46,-4,minecraft:nether_wart_block)
B(-1,47,-4,minecraft:nether_wart_block)
B(-1,40,-3,minecraft:nether_wart_block)
B(-1,41,-3,minecraft:nether_wart_block)
B(-1,42,-3,minecraft:nether_wart_block)
B(-1,43,-3,minecraft:nether_wart_block)
B(-1,44,-3,minecraft:nether_wart_block)
B(-1,45,-3,minecraft:nether_wart_block)
B(-1,46,-3,minecraft:nether_wart_block)
B(-1,40,-2,minecraft:nether_wart_block)
B(-1,41,-2,minecraft:nether_wart_block)
B(-1,42,-2,minecraft:nether_wart_block)
B(-1,43,-2,minecraft:nether_wart_block)
B(-1,44,-2,minecraft:nether_wart_block)
B(-1,45,-2,minecraft:nether_wart_block)
B(-1,46,-2,minecraft:nether_wart_block)
B(-1,40,-1,minecraft:nether_wart_block)
B(-1,41,-1,minecraft:nether_wart_block)
B(-1,42,-1,minecraft:nether_wart_block)
B(-1,43,-1,minecraft:nether_wart_block)
B(-1,44,-1,minecraft:nether_wart_block)
B(-1,45,-1,minecraft:nether_wart_block)
B(-1,46,-1,minecraft:nether_wart_block)
B(-1,29,0,minecraft:nether_wart_block)
B(-1,30,0,minecraft:nether_wart_block)
B(-1,31,0,minecraft:nether_wart_block)
B(-1,32,0,minecraft:nether_wart_block)
B(-1,33,0,minecraft:nether_wart_block)
B(-1,34,0,minecraft:nether_wart_block)
B(-1,35,0,minecraft:nether_wart_block)
B(-1,36,0,minecraft:nether_wart_block)
B(-1,37,0,minecraft:nether_wart_block)
B(-1,38,0,minecraft:nether_wart_block)
B(-1,39,0,minecraft:nether_wart_block)
B(-1,40,0,minecraft:nether_wart_block)
B(-1,41,0,minecraft:nether_wart_block)
B(-1,42,0,minecraft:nether_wart_block)
B(-1,43,0,minecraft:nether_wart_block)
B(-1,44,0,minecraft:nether_wart_block)
B(-1,45,0,minecraft:nether_wart_block)
B(-1,46,0,minecraft:nether_wart_block)
B(-1,29,1,minecraft:nether_wart_block)
B(-1,30,1,minecraft:nether_wart_block)
B(-1,31,1,minecraft:nether_wart_block)
B(-1,32,1,minecraft:nether_wart_block)
B(-1,33,1,minecraft:nether_wart_block)
B(-1,34,1,minecraft:nether_wart_block)
B(-1,35,1,minecraft:nether_wart_block)
B(-1,36,1,minecraft:nether_wart_block)
B(-1,37,1,minecraft:nether_wart_block)
B(-1,38,1,minecraft:nether_wart_block)
B(-1,39,1,minecraft:nether_wart_block)
B(-1,40,1,minecraft:nether_wart_block)
B(-1,41,1,minecraft:nether_wart_block)
B(-1,42,1,minecraft:nether_wart_block)
B(-1,43,1,minecraft:nether_wart_block)
B(-1,44,1,minecraft:nether_wart_block)
B(-1,45,1,minecraft:nether_wart_block)
B(-1,29,2,minecraft:nether_wart_block)
B(-1,30,2,minecraft:nether_wart_block)
B(-1,31,2,minecraft:nether_wart_block)
B(-1,32,2,minecraft:nether_wart_block)
B(-1,33,2,minecraft:nether_wart_block)
B(-1,34,2,minecraft:nether_wart_block)
B(-1,35,2,minecraft:nether_wart_block)
B(-1,36,2,minecraft:nether_wart_block)
B(-1,37,2,minecraft:nether_wart_block)
B(-1,38,2,minecraft:nether_wart_block)
B(-1,39,2,minecraft:nether_wart_block)
B(-1,40,2,minecraft:nether_wart_block)
B(-1,41,2,minecraft:nether_wart_block)
B(-1,42,2,minecraft:nether_wart_block)
B(-1,43,2,minecraft:nether_wart_block)
B(-1,44,2,minecraft:nether_wart_block)
B(-1,29,3,minecraft:nether_wart_block)
B(-1,30,3,minecraft:nether_wart_block)
B(-1,31,3,minecraft:nether_wart_block)
B(-1,32,3,minecraft:nether_wart_block)
B(-1,33,3,minecraft:nether_wart_block)
B(-1,34,3,minecraft:nether_wart_block)
B(-1,35,3,minecraft:nether_wart_block)
B(-1,36,3,minecraft:nether_wart_block)
B(-1,37,3,minecraft:nether_wart_block)
B(-1,38,3,minecraft:nether_wart_block)
B(-1,39,3,minecraft:nether_wart_block)
B(-1,40,3,minecraft:nether_wart_block)
B(-1,41,3,minecraft:nether_wart_block)
B(-1,42,3,minecraft:nether_wart_block)
B(-1,43,3,minecraft:nether_wart_block)
B(-1,44,3,minecraft:nether_wart_block)
B(-1,29,4,minecraft:nether_wart_block)
B(-1,30,4,minecraft:nether_wart_block)
B(-1,31,4,minecraft:nether_wart_block)
B(-1,32,4,minecraft:nether_wart_block)
B(-1,33,4,minecraft:nether_wart_block)
B(-1,34,4,minecraft:nether_wart_block)
B(-1,35,4,minecraft:nether_wart_block)
B(-1,36,4,minecraft:nether_wart_block)
B(-1,37,4,minecraft:nether_wart_block)
B(-1,38,4,minecraft:nether_wart_block)
B(-1,39,4,minecraft:nether_wart_block)
B(-1,40,4,minecraft:nether_wart_block)
B(-1,41,4,minecraft:nether_wart_block)
B(-1,42,4,minecraft:nether_wart_block)
B(-1,43,4,minecraft:nether_wart_block)
B(-1,44,4,minecraft:nether_wart_block)
B(-1,23,5,minecraft:nether_wart_block)
B(-1,24,5,minecraft:nether_wart_block)
B(-1,25,5,minecraft:nether_wart_block)
B(-1,26,5,minecraft:nether_wart_block)
B(-1,27,5,minecraft:nether_wart_block)
B(-1,29,5,minecraft:nether_wart_block)
B(-1,30,5,minecraft:nether_wart_block)
B(-1,31,5,minecraft:nether_wart_block)
B(-1,32,5,minecraft:nether_wart_block)
B(-1,33,5,minecraft:nether_wart_block)
B(-1,34,5,minecraft:nether_wart_block)
B(-1,35,5,minecraft:nether_wart_block)
B(-1,36,5,minecraft:nether_wart_block)
B(-1,37,5,minecraft:nether_wart_block)
B(-1,38,5,minecraft:nether_wart_block)
B(-1,39,5,minecraft:nether_wart_block)
B(-1,40,5,minecraft:nether_wart_block)
B(-1,41,5,minecraft:nether_wart_block)
B(-1,42,5,minecraft:nether_wart_block)
B(-1,43,5,minecraft:nether_wart_block)
B(-1,44,5,minecraft:nether_wart_block)
B(-1,20,6,minecraft:nether_wart_block)
B(-1,21,6,minecraft:nether_wart_block)
B(-1,22,6,minecraft:nether_wart_block)
B(-1,23,6,minecraft:nether_wart_block)
B(-1,24,6,minecraft:nether_wart_block)
B(-1,25,6,minecraft:nether_wart_block)
B(-1,26,6,minecraft:nether_wart_block)
B(-1,27,6,minecraft:nether_wart_block)
B(-1,28,6,minecraft:nether_wart_block)
B(-1,29,6,minecraft:nether_wart_block)
B(-1,30,6,minecraft:nether_wart_block)
B(-1,31,6,minecraft:nether_wart_block)
B(-1,32,6,minecraft:nether_wart_block)
B(-1,33,6,minecraft:nether_wart_block)
B(-1,34,6,minecraft:nether_wart_block)
B(-1,35,6,minecraft:nether_wart_block)
B(-1,36,6,minecraft:nether_wart_block)
B(-1,37,6,minecraft:nether_wart_block)
B(-1,39,6,minecraft:nether_wart_block)
B(-1,40,6,minecraft:nether_wart_block)
B(-1,41,6,minecraft:nether_wart_block)
B(-1,42,6,minecraft:nether_wart_block)
B(-1,43,6,minecraft:nether_wart_block)
B(-1,20,7,minecraft:nether_wart_block)
B(-1,21,7,minecraft:nether_wart_block)
B(-1,22,7,minecraft:nether_wart_block)
B(-1,23,7,minecraft:nether_wart_block)
B(-1,24,7,minecraft:nether_wart_block)
B(-1,25,7,minecraft:nether_wart_block)
B(-1,26,7,minecraft:nether_wart_block)
B(-1,27,7,minecraft:nether_wart_block)
B(-1,28,7,minecraft:nether_wart_block)
B(-1,29,7,minecraft:nether_wart_block)
B(-1,30,7,minecraft:nether_wart_block)
B(-1,31,7,minecraft:nether_wart_block)
B(-1,32,7,minecraft:nether_wart_block)
B(-1,33,7,minecraft:nether_wart_block)
B(-1,34,7,minecraft:nether_wart_block)
B(-1,35,7,minecraft:nether_wart_block)
B(-1,36,7,minecraft:nether_wart_block)
B(-1,37,7,minecraft:nether_wart_block)
B(-1,40,7,minecraft:nether_wart_block)
B(-1,41,7,minecraft:nether_wart_block)
B(-1,42,7,minecraft:nether_wart_block)
B(-1,20,8,minecraft:nether_wart_block)
B(-1,21,8,minecraft:nether_wart_block)
B(-1,22,8,minecraft:nether_wart_block)
B(-1,23,8,minecraft:nether_wart_block)
B(-1,24,8,minecraft:nether_wart_block)
B(-1,25,8,minecraft:nether_wart_block)
B(-1,26,8,minecraft:nether_wart_block)
B(-1,27,8,minecraft:nether_wart_block)
B(-1,28,8,minecraft:nether_wart_block)
B(-1,29,8,minecraft:nether_wart_block)
B(-1,30,8,minecraft:nether_wart_block)
B(-1,31,8,minecraft:nether_wart_block)
B(-1,32,8,minecraft:nether_wart_block)
B(-1,33,8,minecraft:nether_wart_block)
B(-1,34,8,minecraft:nether_wart_block)
B(-1,35,8,minecraft:nether_wart_block)
B(-1,36,8,minecraft:nether_wart_block)
B(-1,37,8,minecraft:nether_wart_block)
B(0,42,-7,minecraft:nether_wart_block)
B(0,43,-7,minecraft:nether_wart_block)
B(0,44,-7,minecraft:nether_wart_block)
B(0,45,-7,minecraft:nether_wart_block)
B(0,46,-7,minecraft:nether_wart_block)
B(0,47,-7,minecraft:nether_wart_block)
B(0,48,-7,minecraft:nether_wart_block)
B(0,42,-6,minecraft:nether_wart_block)
B(0,43,-6,minecraft:nether_wart_block)
B(0,44,-6,minecraft:nether_wart_block)
B(0,45,-6,minecraft:nether_wart_block)
B(0,46,-6,minecraft:nether_wart_block)
B(0,47,-6,minecraft:nether_wart_block)
B(0,48,-6,minecraft:nether_wart_block)
B(0,42,-5,minecraft:nether_wart_block)
B(0,43,-5,minecraft:nether_wart_block)
B(0,44,-5,minecraft:nether_wart_block)
B(0,45,-5,minecraft:nether_wart_block)
B(0,46,-5,minecraft:nether_wart_block)
B(0,47,-5,minecraft:nether_wart_block)
B(0,48,-5,minecraft:nether_wart_block)
B(0,41,-4,minecraft:nether_wart_block)
B(0,42,-4,minecraft:nether_wart_block)
B(0,43,-4,minecraft:nether_wart_block)
B(0,44,-4,minecraft:nether_wart_block)
B(0,45,-4,minecraft:nether_wart_block)
B(0,46,-4,minecraft:nether_wart_block)
B(0,47,-4,minecraft:nether_wart_block)
B(0,41,-3,minecraft:nether_wart_block)
B(0,42,-3,minecraft:nether_wart_block)
B(0,43,-3,minecraft:nether_wart_block)
B(0,44,-3,minecraft:nether_wart_block)
B(0,45,-3,minecraft:nether_wart_block)
B(0,46,-3,minecraft:nether_wart_block)
B(0,40,-2,minecraft:nether_wart_block)
B(0,41,-2,minecraft:nether_wart_block)
B(0,42,-2,minecraft:nether_wart_block)
B(0,43,-2,minecraft:nether_wart_block)
B(0,44,-2,minecraft:nether_wart_block)
B(0,45,-2,minecraft:nether_wart_block)
B(0,46,-2,minecraft:nether_wart_block)
B(0,40,-1,minecraft:nether_wart_block)
B(0,41,-1,minecraft:nether_wart_block)
B(0,42,-1,minecraft:nether_wart_block)
B(0,43,-1,minecraft:nether_wart_block)
B(0,44,-1,minecraft:nether_wart_block)
B(0,45,-1,minecraft:nether_wart_block)
B(0,46,-1,minecraft:nether_wart_block)
B(0,40,0,minecraft:nether_wart_block)
B(0,41,0,minecraft:nether_wart_block)
B(0,42,0,minecraft:nether_wart_block)
B(0,43,0,minecraft:nether_wart_block)
B(0,44,0,minecraft:nether_wart_block)
B(0,45,0,minecraft:nether_wart_block)
B(0,46,0,minecraft:nether_wart_block)
B(0,30,1,minecraft:nether_wart_block)
B(0,31,1,minecraft:nether_wart_block)
B(0,32,1,minecraft:nether_wart_block)
B(0,34,1,minecraft:nether_wart_block)
B(0,35,1,minecraft:nether_wart_block)
B(0,36,1,minecraft:nether_wart_block)
B(0,37,1,minecraft:nether_wart_block)
B(0,38,1,minecraft:nether_wart_block)
B(0,39,1,minecraft:nether_wart_block)
B(0,40,1,minecraft:nether_wart_block)
B(0,41,1,minecraft:nether_wart_block)
B(0,42,1,minecraft:nether_wart_block)
B(0,43,1,minecraft:nether_wart_block)
B(0,44,1,minecraft:nether_wart_block)
B(0,45,1,minecraft:nether_wart_block)
B(0,30,2,minecraft:nether_wart_block)
B(0,31,2,minecraft:nether_wart_block)
B(0,32,2,minecraft:nether_wart_block)
B(0,34,2,minecraft:nether_wart_block)
B(0,35,2,minecraft:nether_wart_block)
B(0,36,2,minecraft:nether_wart_block)
B(0,37,2,minecraft:nether_wart_block)
B(0,38,2,minecraft:nether_wart_block)
B(0,39,2,minecraft:nether_wart_block)
B(0,40,2,minecraft:nether_wart_block)
B(0,41,2,minecraft:nether_wart_block)
B(0,42,2,minecraft:nether_wart_block)
B(0,43,2,minecraft:nether_wart_block)
B(0,44,2,minecraft:nether_wart_block)
B(0,30,3,minecraft:nether_wart_block)
B(0,31,3,minecraft:nether_wart_block)
B(0,32,3,minecraft:nether_wart_block)
B(0,33,3,minecraft:nether_wart_block)
B(0,34,3,minecraft:nether_wart_block)
B(0,35,3,minecraft:nether_wart_block)
B(0,36,3,minecraft:nether_wart_block)
B(0,37,3,minecraft:nether_wart_block)
B(0,38,3,minecraft:nether_wart_block)
B(0,39,3,minecraft:nether_wart_block)
B(0,40,3,minecraft:nether_wart_block)
B(0,41,3,minecraft:nether_wart_block)
B(0,42,3,minecraft:nether_wart_block)
B(0,43,3,minecraft:nether_wart_block)
B(0,44,3,minecraft:nether_wart_block)
B(0,31,4,minecraft:nether_wart_block)
B(0,32,4,minecraft:nether_wart_block)
B(0,33,4,minecraft:nether_wart_block)
B(0,34,4,minecraft:nether_wart_block)
B(0,35,4,minecraft:nether_wart_block)
B(0,36,4,minecraft:nether_wart_block)
B(0,37,4,minecraft:nether_wart_block)
B(0,38,4,minecraft:nether_wart_block)
B(0,39,4,minecraft:nether_wart_block)
B(0,40,4,minecraft:nether_wart_block)
B(0,41,4,minecraft:nether_wart_block)
B(0,42,4,minecraft:nether_wart_block)
B(0,43,4,minecraft:nether_wart_block)
B(0,44,4,minecraft:nether_wart_block)
B(0,30,5,minecraft:nether_wart_block)
B(0,31,5,minecraft:nether_wart_block)
B(0,32,5,minecraft:nether_wart_block)
B(0,33,5,minecraft:nether_wart_block)
B(0,34,5,minecraft:nether_wart_block)
B(0,35,5,minecraft:nether_wart_block)
B(0,36,5,minecraft:nether_wart_block)
B(0,37,5,minecraft:nether_wart_block)
B(0,38,5,minecraft:nether_wart_block)
B(0,39,5,minecraft:nether_wart_block)
B(0,40,5,minecraft:nether_wart_block)
B(0,41,5,minecraft:nether_wart_block)
B(0,42,5,minecraft:nether_wart_block)
B(0,43,5,minecraft:nether_wart_block)
B(0,44,5,minecraft:nether_wart_block)
B(0,24,6,minecraft:nether_wart_block)
B(0,25,6,minecraft:nether_wart_block)
B(0,26,6,minecraft:nether_wart_block)
B(0,29,6,minecraft:nether_wart_block)
B(0,30,6,minecraft:nether_wart_block)
B(0,31,6,minecraft:nether_wart_block)
B(0,32,6,minecraft:nether_wart_block)
B(0,33,6,minecraft:nether_wart_block)
B(0,34,6,minecraft:nether_wart_block)
B(0,35,6,minecraft:nether_wart_block)
B(0,36,6,minecraft:nether_wart_block)
B(0,37,6,minecraft:nether_wart_block)
B(0,38,6,minecraft:nether_wart_block)
B(0,39,6,minecraft:nether_wart_block)
B(0,40,6,minecraft:nether_wart_block)
B(0,41,6,minecraft:nether_wart_block)
B(0,42,6,minecraft:nether_wart_block)
B(0,43,6,minecraft:nether_wart_block)
B(0,21,7,minecraft:nether_wart_block)
B(0,22,7,minecraft:nether_wart_block)
B(0,23,7,minecraft:nether_wart_block)
B(0,24,7,minecraft:nether_wart_block)
B(0,25,7,minecraft:nether_wart_block)
B(0,26,7,minecraft:nether_wart_block)
B(0,29,7,minecraft:nether_wart_block)
B(0,30,7,minecraft:nether_wart_block)
B(0,31,7,minecraft:nether_wart_block)
B(0,32,7,minecraft:nether_wart_block)
B(0,33,7,minecraft:nether_wart_block)
B(0,34,7,minecraft:nether_wart_block)
B(0,35,7,minecraft:nether_wart_block)
B(0,36,7,minecraft:nether_wart_block)
B(0,37,7,minecraft:nether_wart_block)
B(0,38,7,minecraft:nether_wart_block)
B(0,40,7,minecraft:nether_wart_block)
B(0,41,7,minecraft:nether_wart_block)
B(0,42,7,minecraft:nether_wart_block)
B(0,21,8,minecraft:nether_wart_block)
B(0,22,8,minecraft:nether_wart_block)
B(0,23,8,minecraft:nether_wart_block)
B(0,24,8,minecraft:nether_wart_block)
B(0,25,8,minecraft:nether_wart_block)
B(0,26,8,minecraft:nether_wart_block)
B(0,29,8,minecraft:nether_wart_block)
B(0,30,8,minecraft:nether_wart_block)
B(0,31,8,minecraft:nether_wart_block)
B(0,32,8,minecraft:nether_wart_block)
B(0,33,8,minecraft:nether_wart_block)
B(0,34,8,minecraft:nether_wart_block)
B(0,35,8,minecraft:nether_wart_block)
B(0,36,8,minecraft:nether_wart_block)
B(0,37,8,minecraft:nether_wart_block)
B(0,38,8,minecraft:nether_wart_block)
B(1,42,-7,minecraft:nether_wart_block)
B(1,43,-7,minecraft:nether_wart_block)
B(1,44,-7,minecraft:nether_wart_block)
B(1,45,-7,minecraft:nether_wart_block)
B(1,46,-7,minecraft:nether_wart_block)
B(1,47,-7,minecraft:nether_wart_block)
B(1,48,-7,minecraft:nether_wart_block)
B(1,42,-6,minecraft:nether_wart_block)
B(1,43,-6,minecraft:nether_wart_block)
B(1,44,-6,minecraft:nether_wart_block)
B(1,45,-6,minecraft:nether_wart_block)
B(1,46,-6,minecraft:nether_wart_block)
B(1,47,-6,minecraft:nether_wart_block)
B(1,48,-6,minecraft:nether_wart_block)
B(1,42,-5,minecraft:nether_wart_block)
B(1,43,-5,minecraft:nether_wart_block)
B(1,44,-5,minecraft:nether_wart_block)
B(1,45,-5,minecraft:nether_wart_block)
B(1,46,-5,minecraft:nether_wart_block)
B(1,47,-5,minecraft:nether_wart_block)
B(1,48,-5,minecraft:nether_wart_block)
B(1,42,-4,minecraft:nether_wart_block)
B(1,43,-4,minecraft:nether_wart_block)
B(1,44,-4,minecraft:nether_wart_block)
B(1,45,-4,minecraft:nether_wart_block)
B(1,46,-4,minecraft:nether_wart_block)
B(1,47,-4,minecraft:nether_wart_block)
B(1,41,-3,minecraft:nether_wart_block)
B(1,42,-3,minecraft:nether_wart_block)
B(1,43,-3,minecraft:nether_wart_block)
B(1,44,-3,minecraft:nether_wart_block)
B(1,45,-3,minecraft:nether_wart_block)
B(1,46,-3,minecraft:nether_wart_block)
B(1,47,-3,minecraft:nether_wart_block)
B(1,39,-2,minecraft:shroomlight)
B(1,40,-2,minecraft:shroomlight)
B(1,41,-2,minecraft:shroomlight)
B(1,42,-2,minecraft:nether_wart_block)
B(1,43,-2,minecraft:nether_wart_block)
B(1,44,-2,minecraft:nether_wart_block)
B(1,45,-2,minecraft:nether_wart_block)
B(1,46,-2,minecraft:nether_wart_block)
B(1,47,-2,minecraft:nether_wart_block)
B(1,39,-1,minecraft:shroomlight)
B(1,40,-1,minecraft:shroomlight)
B(1,41,-1,minecraft:shroomlight)
B(1,42,-1,minecraft:nether_wart_block)
B(1,43,-1,minecraft:nether_wart_block)
B(1,44,-1,minecraft:nether_wart_block)
B(1,45,-1,minecraft:nether_wart_block)
B(1,46,-1,minecraft:nether_wart_block)
B(1,47,-1,minecraft:nether_wart_block)
B(1,39,0,minecraft:shroomlight)
B(1,40,0,minecraft:shroomlight)
B(1,41,0,minecraft:shroomlight)
B(1,42,0,minecraft:nether_wart_block)
B(1,43,0,minecraft:nether_wart_block)
B(1,44,0,minecraft:nether_wart_block)
B(1,45,0,minecraft:nether_wart_block)
B(1,46,0,minecraft:nether_wart_block)
B(1,40,1,minecraft:nether_wart_block)
B(1,41,1,minecraft:nether_wart_block)
B(1,42,1,minecraft:nether_wart_block)
B(1,43,1,minecraft:nether_wart_block)
B(1,44,1,minecraft:nether_wart_block)
B(1,45,1,minecraft:nether_wart_block)
B(1,35,2,minecraft:nether_wart_block)
B(1,36,2,minecraft:nether_wart_block)
B(1,37,2,minecraft:nether_wart_block)
B(1,39,2,minecraft:nether_wart_block)
B(1,40,2,minecraft:nether_wart_block)
B(1,41,2,minecraft:nether_wart_block)
B(1,42,2,minecraft:nether_wart_block)
B(1,43,2,minecraft:nether_wart_block)
B(1,44,2,minecraft:nether_wart_block)
B(1,35,3,minecraft:nether_wart_block)
B(1,36,3,minecraft:nether_wart_block)
B(1,37,3,minecraft:nether_wart_block)
B(1,38,3,minecraft:nether_wart_block)
B(1,39,3,minecraft:nether_wart_block)
B(1,40,3,minecraft:nether_wart_block)
B(1,41,3,minecraft:nether_wart_block)
B(1,42,3,minecraft:nether_wart_block)
B(1,43,3,minecraft:nether_wart_block)
B(1,44,3,minecraft:nether_wart_block)
B(1,31,4,minecraft:nether_wart_block)
B(1,32,4,minecraft:nether_wart_block)
B(1,33,4,minecraft:nether_wart_block)
B(1,34,4,minecraft:nether_wart_block)
B(1,35,4,minecraft:nether_wart_block)
B(1,36,4,minecraft:nether_wart_block)
B(1,37,4,minecraft:nether_wart_block)
B(1,38,4,minecraft:nether_wart_block)
B(1,39,4,minecraft:nether_wart_block)
B(1,40,4,minecraft:nether_wart_block)
B(1,41,4,minecraft:nether_wart_block)
B(1,42,4,minecraft:nether_wart_block)
B(1,43,4,minecraft:nether_wart_block)
B(1,30,5,minecraft:nether_wart_block)
B(1,31,5,minecraft:nether_wart_block)
B(1,32,5,minecraft:nether_wart_block)
B(1,33,5,minecraft:nether_wart_block)
B(1,34,5,minecraft:nether_wart_block)
B(1,35,5,minecraft:nether_wart_block)
B(1,36,5,minecraft:nether_wart_block)
B(1,37,5,minecraft:nether_wart_block)
B(1,38,5,minecraft:nether_wart_block)
B(1,39,5,minecraft:nether_wart_block)
B(1,40,5,minecraft:nether_wart_block)
B(1,41,5,minecraft:nether_wart_block)
B(1,42,5,minecraft:nether_wart_block)
B(1,43,5,minecraft:nether_wart_block)
B(1,29,6,minecraft:nether_wart_block)
B(1,30,6,minecraft:nether_wart_block)
B(1,31,6,minecraft:nether_wart_block)
B(1,32,6,minecraft:nether_wart_block)
B(1,33,6,minecraft:nether_wart_block)
B(1,34,6,minecraft:nether_wart_block)
B(1,35,6,minecraft:nether_wart_block)
B(1,36,6,minecraft:nether_wart_block)
B(1,37,6,minecraft:nether_wart_block)
B(1,38,6,minecraft:nether_wart_block)
B(1,39,6,minecraft:nether_wart_block)
B(1,40,6,minecraft:nether_wart_block)
B(1,41,6,minecraft:nether_wart_block)
B(1,42,6,minecraft:nether_wart_block)
B(1,43,6,minecraft:nether_wart_block)
B(1,29,7,minecraft:nether_wart_block)
B(1,30,7,minecraft:nether_wart_block)
B(1,31,7,minecraft:nether_wart_block)
B(1,32,7,minecraft:nether_wart_block)
B(1,33,7,minecraft:nether_wart_block)
B(1,34,7,minecraft:nether_wart_block)
B(1,35,7,minecraft:nether_wart_block)
B(1,36,7,minecraft:nether_wart_block)
B(1,37,7,minecraft:nether_wart_block)
B(1,38,7,minecraft:nether_wart_block)
B(1,39,7,minecraft:nether_wart_block)
B(1,40,7,minecraft:nether_wart_block)
B(1,29,8,minecraft:nether_wart_block)
B(1,30,8,minecraft:nether_wart_block)
B(1,31,8,minecraft:nether_wart_block)
B(1,32,8,minecraft:nether_wart_block)
B(1,33,8,minecraft:nether_wart_block)
B(1,34,8,minecraft:nether_wart_block)
B(1,35,8,minecraft:nether_wart_block)
B(1,36,8,minecraft:nether_wart_block)
B(1,37,8,minecraft:nether_wart_block)
B(1,38,8,minecraft:nether_wart_block)
B(1,39,8,minecraft:nether_wart_block)
B(2,43,-7,minecraft:nether_wart_block)
B(2,44,-7,minecraft:nether_wart_block)
B(2,45,-7,minecraft:nether_wart_block)
B(2,46,-7,minecraft:nether_wart_block)
B(2,47,-7,minecraft:nether_wart_block)
B(2,48,-7,minecraft:nether_wart_block)
B(2,49,-7,minecraft:nether_wart_block)
B(2,43,-6,minecraft:nether_wart_block)
B(2,44,-6,minecraft:nether_wart_block)
B(2,45,-6,minecraft:nether_wart_block)
B(2,46,-6,minecraft:nether_wart_block)
B(2,47,-6,minecraft:nether_wart_block)
B(2,48,-6,minecraft:nether_wart_block)
B(2,49,-6,minecraft:nether_wart_block)
B(2,43,-5,minecraft:nether_wart_block)
B(2,44,-5,minecraft:nether_wart_block)
B(2,45,-5,minecraft:nether_wart_block)
B(2,46,-5,minecraft:nether_wart_block)
B(2,47,-5,minecraft:nether_wart_block)
B(2,48,-5,minecraft:nether_wart_block)
B(2,0,-4,minecraft:netherrack)
B(2,42,-4,minecraft:nether_wart_block)
B(2,43,-4,minecraft:nether_wart_block)
B(2,44,-4,minecraft:nether_wart_block)
B(2,45,-4,minecraft:nether_wart_block)
B(2,46,-4,minecraft:nether_wart_block)
B(2,47,-4,minecraft:nether_wart_block)
B(2,0,-3,minecraft:netherrack)
B(2,1,-3,minecraft:netherrack)
B(2,39,-3,minecraft:shroomlight)
B(2,40,-3,minecraft:shroomlight)
B(2,41,-3,minecraft:shroomlight)
B(2,42,-3,minecraft:nether_wart_block)
B(2,43,-3,minecraft:nether_wart_block)
B(2,44,-3,minecraft:nether_wart_block)
B(2,45,-3,minecraft:nether_wart_block)
B(2,46,-3,minecraft:nether_wart_block)
B(2,47,-3,minecraft:nether_wart_block)
B(2,0,-2,minecraft:netherrack)
B(2,38,-2,minecraft:shroomlight)
B(2,39,-2,minecraft:shroomlight)
B(2,40,-2,minecraft:shroomlight)
B(2,41,-2,minecraft:shroomlight)
B(2,42,-2,minecraft:shroomlight)
B(2,43,-2,minecraft:nether_wart_block)
B(2,44,-2,minecraft:nether_wart_block)
B(2,45,-2,minecraft:nether_wart_block)
B(2,46,-2,minecraft:nether_wart_block)
B(2,47,-2,minecraft:nether_wart_block)
B(2,38,-1,minecraft:shroomlight)
B(2,39,-1,minecraft:shroomlight)
B(2,40,-1,minecraft:shroomlight)
B(2,41,-1,minecraft:shroomlight)
B(2,42,-1,minecraft:shroomlight)
B(2,43,-1,minecraft:nether_wart_block)
B(2,44,-1,minecraft:nether_wart_block)
B(2,45,-1,minecraft:nether_wart_block)
B(2,46,-1,minecraft:nether_wart_block)
B(2,47,-1,minecraft:nether_wart_block)
B(2,38,0,minecraft:shroomlight)
B(2,39,0,minecraft:shroomlight)
B(2,40,0,minecraft:shroomlight)
B(2,41,0,minecraft:shroomlight)
B(2,42,0,minecraft:shroomlight)
B(2,43,0,minecraft:nether_wart_block)
B(2,44,0,minecraft:nether_wart_block)
B(2,45,0,minecraft:nether_wart_block)
B(2,46,0,minecraft:nether_wart_block)
B(2,39,1,minecraft:shroomlight)
B(2,40,1,minecraft:shroomlight)
B(2,41,1,minecraft:shroomlight)
B(2,42,1,minecraft:nether_wart_block)
B(2,43,1,minecraft:nether_wart_block)
B(2,44,1,minecraft:nether_wart_block)
B(2,45,1,minecraft:nether_wart_block)
B(2,37,2,minecraft:nether_wart_block)
B(2,38,2,minecraft:nether_wart_block)
B(2,39,2,minecraft:nether_wart_block)
B(2,40,2,minecraft:nether_wart_block)
B(2,41,2,minecraft:nether_wart_block)
B(2,42,2,minecraft:nether_wart_block)
B(2,43,2,minecraft:nether_wart_block)
B(2,44,2,minecraft:nether_wart_block)
B(2,45,2,minecraft:nether_wart_block)
B(2,36,3,minecraft:nether_wart_block)
B(2,37,3,minecraft:nether_wart_block)
B(2,38,3,minecraft:nether_wart_block)
B(2,39,3,minecraft:nether_wart_block)
B(2,40,3,minecraft:nether_wart_block)
B(2,41,3,minecraft:nether_wart_block)
B(2,42,3,minecraft:nether_wart_block)
B(2,43,3,minecraft:nether_wart_block)
B(2,44,3,minecraft:nether_wart_block)
B(2,35,4,minecraft:nether_wart_block)
B(2,36,4,minecraft:nether_wart_block)
B(2,37,4,minecraft:nether_wart_block)
B(2,38,4,minecraft:nether_wart_block)
B(2,39,4,minecraft:nether_wart_block)
B(2,40,4,minecraft:nether_wart_block)
B(2,41,4,minecraft:nether_wart_block)
B(2,42,4,minecraft:nether_wart_block)
B(2,43,4,minecraft:nether_wart_block)
B(2,44,4,minecraft:nether_wart_block)
B(2,30,5,minecraft:nether_wart_block)
B(2,31,5,minecraft:nether_wart_block)
B(2,32,5,minecraft:nether_wart_block)
B(2,33,5,minecraft:nether_wart_block)
B(2,34,5,minecraft:nether_wart_block)
B(2,35,5,minecraft:nether_wart_block)
B(2,36,5,minecraft:nether_wart_block)
B(2,37,5,minecraft:nether_wart_block)
B(2,38,5,minecraft:nether_wart_block)
B(2,39,5,minecraft:nether_wart_block)
B(2,40,5,minecraft:nether_wart_block)
B(2,41,5,minecraft:nether_wart_block)
B(2,42,5,minecraft:nether_wart_block)
B(2,43,5,minecraft:nether_wart_block)
B(2,44,5,minecraft:nether_wart_block)
B(2,29,6,minecraft:nether_wart_block)
B(2,30,6,minecraft:nether_wart_block)
B(2,31,6,minecraft:nether_wart_block)
B(2,32,6,minecraft:nether_wart_block)
B(2,33,6,minecraft:nether_wart_block)
B(2,34,6,minecraft:nether_wart_block)
B(2,35,6,minecraft:nether_wart_block)
B(2,36,6,minecraft:nether_wart_block)
B(2,37,6,minecraft:nether_wart_block)
B(2,38,6,minecraft:nether_wart_block)
B(2,39,6,minecraft:nether_wart_block)
B(2,40,6,minecraft:nether_wart_block)
B(2,41,6,minecraft:nether_wart_block)
B(2,42,6,minecraft:nether_wart_block)
B(2,43,6,minecraft:nether_wart_block)
B(2,28,7,minecraft:nether_wart_block)
B(2,29,7,minecraft:nether_wart_block)
B(2,30,7,minecraft:nether_wart_block)
B(2,31,7,minecraft:nether_wart_block)
B(2,32,7,minecraft:nether_wart_block)
B(2,33,7,minecraft:nether_wart_block)
B(2,34,7,minecraft:nether_wart_block)
B(2,35,7,minecraft:nether_wart_block)
B(2,36,7,minecraft:nether_wart_block)
B(2,37,7,minecraft:nether_wart_block)
B(2,38,7,minecraft:nether_wart_block)
B(2,39,7,minecraft:nether_wart_block)
B(2,40,7,minecraft:nether_wart_block)
B(2,41,7,minecraft:nether_wart_block)
B(2,42,7,minecraft:nether_wart_block)
B(2,28,8,minecraft:nether_wart_block)
B(2,29,8,minecraft:nether_wart_block)
B(2,30,8,minecraft:nether_wart_block)
B(2,31,8,minecraft:nether_wart_block)
B(2,32,8,minecraft:nether_wart_block)
B(2,33,8,minecraft:nether_wart_block)
B(2,34,8,minecraft:nether_wart_block)
B(2,35,8,minecraft:nether_wart_block)
B(2,36,8,minecraft:nether_wart_block)
B(2,37,8,minecraft:nether_wart_block)
B(2,38,8,minecraft:nether_wart_block)
B(2,39,8,minecraft:nether_wart_block)
B(3,43,-7,minecraft:nether_wart_block)
B(3,44,-7,minecraft:nether_wart_block)
B(3,45,-7,minecraft:nether_wart_block)
B(3,46,-7,minecraft:nether_wart_block)
B(3,47,-7,minecraft:nether_wart_block)
B(3,48,-7,minecraft:nether_wart_block)
B(3,49,-7,minecraft:nether_wart_block)
B(3,43,-6,minecraft:nether_wart_block)
B(3,44,-6,minecraft:nether_wart_block)
B(3,45,-6,minecraft:nether_wart_block)
B(3,46,-6,minecraft:nether_wart_block)
B(3,47,-6,minecraft:nether_wart_block)
B(3,48,-6,minecraft:nether_wart_block)
B(3,49,-6,minecraft:nether_wart_block)
B(3,0,-5,minecraft:netherrack)
B(3,43,-5,minecraft:nether_wart_block)
B(3,44,-5,minecraft:nether_wart_block)
B(3,45,-5,minecraft:nether_wart_block)
B(3,46,-5,minecraft:nether_wart_block)
B(3,47,-5,minecraft:nether_wart_block)
B(3,48,-5,minecraft:nether_wart_block)
B(3,0,-4,minecraft:netherrack)
B(3,1,-4,minecraft:netherrack)
B(3,42,-4,minecraft:nether_wart_block)
B(3,43,-4,minecraft:nether_wart_block)
B(3,44,-4,minecraft:nether_wart_block)
B(3,45,-4,minecraft:nether_wart_block)
B(3,46,-4,minecraft:nether_wart_block)
B(3,47,-4,minecraft:nether_wart_block)
B(3,0,-3,minecraft:netherrack)
B(3,1,-3,minecraft:netherrack)
B(3,39,-3,minecraft:shroomlight)
B(3,40,-3,minecraft:shroomlight)
B(3,41,-3,minecraft:shroomlight)
B(3,42,-3,minecraft:nether_wart_block)
B(3,43,-3,minecraft:nether_wart_block)
B(3,44,-3,minecraft:nether_wart_block)
B(3,45,-3,minecraft:nether_wart_block)
B(3,46,-3,minecraft:nether_wart_block)
B(3,47,-3,minecraft:nether_wart_block)
B(3,0,-2,minecraft:netherrack)
B(3,1,-2,minecraft:netherrack)
B(3,38,-2,minecraft:shroomlight)
B(3,39,-2,minecraft:shroomlight)
