
#######################################################################
# +-----------------------------------------------------------------+ #
# |                            BO4 object                           | #
# +-----------------------------------------------------------------+ #
#######################################################################

Author: Unknown

Description: No description given

SettingsMode: WriteWithoutComments


#######################################################################
# +-----------------------------------------------------------------+ #
# |                          Main settings                          | #
# +-----------------------------------------------------------------+ #
#######################################################################

FixedRotation: 

Frequency: 0

SpawnHeight: highestBlock

UseCenterForHighestBlock: true

##############################
# Height Limits for the BO4. #
##############################

MinHeight: 0

MaxHeight: 255

InheritBO3: 

InheritBO3Rotation: NORTH

OverrideChildSettings: true

OverrideParentHeight: false

CanOverride: false

BranchFrequency: 0

BranchFrequencyGroup: 

MustBeBelowOther: false

MustBeInside: 

CannotBeInside: 

ReplacesBO3: 

MustBeInsideWorldBorders: false

CanSpawnOnWater: true

SpawnOnWaterOnly: false

SpawnUnderWater: false

SpawnAtWaterLevel: false

HeightOffset: 0

RemoveAir: true

ReplaceAbove: 

ReplaceBelow: 

ReplaceWithBiomeBlocks: true

ReplaceWithSurfaceBlock: GRASS

ReplaceWithGroundBlock: DIRT

ReplaceWithStoneBlock: STONE

SmoothRadius: 0

SmoothHeightOffset: 0

SmoothStartTop: false

SmoothStartWood: false

SmoothingSurfaceBlock: 

SmoothingGroundBlock: 

BO3Group: 

IsSpawnPoint: false

DoReplaceBlocks: true


#######################################################################
# +-----------------------------------------------------------------+ #
# |                              Blocks                             | #
# +-----------------------------------------------------------------+ #
#######################################################################

B(-8,34,-1,minecraft:nether_wart_block)
B(-8,35,-1,minecraft:nether_wart_block)
B(-8,36,-1,minecraft:nether_wart_block)
B(-8,33,0,minecraft:nether_wart_block)
B(-8,34,0,minecraft:nether_wart_block)
B(-8,35,0,minecraft:nether_wart_block)
B(-8,36,0,minecraft:nether_wart_block)
B(-8,37,0,minecraft:nether_wart_block)
B(-8,32,1,minecraft:nether_wart_block)
B(-8,33,1,minecraft:nether_wart_block)
B(-8,34,1,minecraft:nether_wart_block)
B(-8,35,1,minecraft:nether_wart_block)
B(-8,36,1,minecraft:nether_wart_block)
B(-8,37,1,minecraft:nether_wart_block)
B(-8,38,1,minecraft:nether_wart_block)
B(-8,23,2,minecraft:weeping_vines[age=25])
B(-8,24,2,minecraft:weeping_vines_plant)
B(-8,25,2,minecraft:weeping_vines_plant)
B(-8,26,2,minecraft:weeping_vines_plant)
B(-8,27,2,minecraft:weeping_vines_plant)
B(-8,28,2,minecraft:weeping_vines_plant)
B(-8,29,2,minecraft:weeping_vines_plant)
B(-8,30,2,minecraft:weeping_vines_plant)
B(-8,31,2,minecraft:weeping_vines_plant)
B(-8,32,2,minecraft:nether_wart_block)
B(-8,33,2,minecraft:nether_wart_block)
B(-8,34,2,minecraft:nether_wart_block)
B(-8,35,2,minecraft:nether_wart_block)
B(-8,36,2,minecraft:nether_wart_block)
B(-8,37,2,minecraft:nether_wart_block)
B(-8,38,2,minecraft:nether_wart_block)
B(-8,39,2,minecraft:nether_wart_block)
B(-8,40,2,minecraft:nether_wart_block)
B(-8,31,3,minecraft:nether_wart_block)
B(-8,32,3,minecraft:nether_wart_block)
B(-8,33,3,minecraft:nether_wart_block)
B(-8,34,3,minecraft:nether_wart_block)
B(-8,35,3,minecraft:nether_wart_block)
B(-8,36,3,minecraft:nether_wart_block)
B(-8,37,3,minecraft:nether_wart_block)
B(-8,38,3,minecraft:nether_wart_block)
B(-8,39,3,minecraft:nether_wart_block)
B(-8,40,3,minecraft:nether_wart_block)
B(-8,41,3,minecraft:nether_wart_block)
B(-8,31,4,minecraft:nether_wart_block)
B(-8,32,4,minecraft:nether_wart_block)
B(-8,33,4,minecraft:nether_wart_block)
B(-8,34,4,minecraft:nether_wart_block)
B(-8,35,4,minecraft:nether_wart_block)
B(-8,36,4,minecraft:nether_wart_block)
B(-8,37,4,minecraft:nether_wart_block)
B(-8,38,4,minecraft:nether_wart_block)
B(-8,39,4,minecraft:nether_wart_block)
B(-8,40,4,minecraft:nether_wart_block)
B(-8,41,4,minecraft:nether_wart_block)
B(-8,28,5,minecraft:crimson_hyphae)
B(-8,29,5,minecraft:crimson_hyphae)
B(-8,30,5,minecraft:crimson_hyphae)
B(-8,31,5,minecraft:nether_wart_block)
B(-8,32,5,minecraft:nether_wart_block)
B(-8,33,5,minecraft:nether_wart_block)
B(-8,34,5,minecraft:nether_wart_block)
B(-8,35,5,minecraft:nether_wart_block)
B(-8,36,5,minecraft:nether_wart_block)
B(-8,37,5,minecraft:nether_wart_block)
B(-8,38,5,minecraft:nether_wart_block)
B(-8,39,5,minecraft:nether_wart_block)
B(-8,40,5,minecraft:nether_wart_block)
B(-8,41,5,minecraft:nether_wart_block)
B(-8,27,6,minecraft:crimson_hyphae)
B(-8,28,6,minecraft:crimson_hyphae)
B(-8,29,6,minecraft:crimson_hyphae)
B(-8,30,6,minecraft:crimson_hyphae)
B(-8,31,6,minecraft:nether_wart_block)
B(-8,32,6,minecraft:nether_wart_block)
B(-8,33,6,minecraft:nether_wart_block)
B(-8,34,6,minecraft:nether_wart_block)
B(-8,35,6,minecraft:nether_wart_block)
B(-8,36,6,minecraft:nether_wart_block)
B(-8,37,6,minecraft:nether_wart_block)
B(-8,38,6,minecraft:nether_wart_block)
B(-8,39,6,minecraft:nether_wart_block)
B(-8,40,6,minecraft:nether_wart_block)
B(-8,41,6,minecraft:nether_wart_block)
B(-8,24,7,minecraft:crimson_hyphae)
B(-8,25,7,minecraft:crimson_hyphae)
B(-8,26,7,minecraft:crimson_hyphae)
B(-8,27,7,minecraft:crimson_hyphae)
B(-8,28,7,minecraft:crimson_hyphae)
B(-8,29,7,minecraft:crimson_hyphae)
B(-8,30,7,minecraft:crimson_hyphae)
B(-8,31,7,minecraft:nether_wart_block)
B(-8,32,7,minecraft:nether_wart_block)
B(-8,33,7,minecraft:nether_wart_block)
B(-8,34,7,minecraft:nether_wart_block)
B(-8,35,7,minecraft:nether_wart_block)
B(-8,36,7,minecraft:nether_wart_block)
B(-8,37,7,minecraft:nether_wart_block)
B(-8,38,7,minecraft:nether_wart_block)
B(-8,39,7,minecraft:nether_wart_block)
B(-8,40,7,minecraft:nether_wart_block)
B(-8,41,7,minecraft:nether_wart_block)
B(-8,24,8,minecraft:crimson_hyphae)
B(-8,25,8,minecraft:crimson_hyphae)
B(-8,26,8,minecraft:crimson_hyphae)
B(-8,27,8,minecraft:crimson_hyphae)
B(-8,28,8,minecraft:crimson_hyphae)
B(-8,29,8,minecraft:crimson_hyphae)
B(-8,30,8,minecraft:crimson_hyphae)
B(-8,31,8,minecraft:crimson_hyphae)
B(-8,32,8,minecraft:crimson_hyphae)
B(-8,33,8,minecraft:crimson_hyphae)
B(-8,34,8,minecraft:crimson_hyphae)
B(-8,35,8,minecraft:nether_wart_block)
B(-8,36,8,minecraft:nether_wart_block)
B(-8,37,8,minecraft:nether_wart_block)
B(-8,38,8,minecraft:nether_wart_block)
B(-8,39,8,minecraft:nether_wart_block)
B(-8,40,8,minecraft:nether_wart_block)
B(-8,41,8,minecraft:nether_wart_block)
B(-7,34,-1,minecraft:nether_wart_block)
B(-7,35,-1,minecraft:nether_wart_block)
B(-7,36,-1,minecraft:nether_wart_block)
B(-7,33,0,minecraft:nether_wart_block)
B(-7,34,0,minecraft:nether_wart_block)
B(-7,35,0,minecraft:nether_wart_block)
B(-7,36,0,minecraft:nether_wart_block)
B(-7,37,0,minecraft:nether_wart_block)
B(-7,32,1,minecraft:nether_wart_block)
B(-7,33,1,minecraft:nether_wart_block)
B(-7,34,1,minecraft:nether_wart_block)
B(-7,35,1,minecraft:nether_wart_block)
B(-7,36,1,minecraft:nether_wart_block)
B(-7,37,1,minecraft:nether_wart_block)
B(-7,38,1,minecraft:nether_wart_block)
B(-7,39,1,minecraft:nether_wart_block)
B(-7,32,2,minecraft:nether_wart_block)
B(-7,33,2,minecraft:nether_wart_block)
B(-7,34,2,minecraft:nether_wart_block)
B(-7,35,2,minecraft:nether_wart_block)
B(-7,36,2,minecraft:nether_wart_block)
B(-7,37,2,minecraft:nether_wart_block)
B(-7,38,2,minecraft:nether_wart_block)
B(-7,39,2,minecraft:nether_wart_block)
B(-7,40,2,minecraft:nether_wart_block)
B(-7,32,3,minecraft:nether_wart_block)
B(-7,33,3,minecraft:nether_wart_block)
B(-7,34,3,minecraft:nether_wart_block)
B(-7,35,3,minecraft:nether_wart_block)
B(-7,36,3,minecraft:nether_wart_block)
B(-7,37,3,minecraft:nether_wart_block)
B(-7,38,3,minecraft:nether_wart_block)
B(-7,39,3,minecraft:nether_wart_block)
B(-7,40,3,minecraft:nether_wart_block)
B(-7,41,3,minecraft:nether_wart_block)
B(-7,31,4,minecraft:crimson_hyphae)
B(-7,32,4,minecraft:nether_wart_block)
B(-7,33,4,minecraft:nether_wart_block)
B(-7,34,4,minecraft:nether_wart_block)
B(-7,35,4,minecraft:nether_wart_block)
B(-7,36,4,minecraft:nether_wart_block)
B(-7,37,4,minecraft:nether_wart_block)
B(-7,38,4,minecraft:nether_wart_block)
B(-7,39,4,minecraft:nether_wart_block)
B(-7,40,4,minecraft:nether_wart_block)
B(-7,41,4,minecraft:nether_wart_block)
B(-7,30,5,minecraft:crimson_hyphae)
B(-7,31,5,minecraft:crimson_hyphae)
B(-7,32,5,minecraft:nether_wart_block)
B(-7,33,5,minecraft:nether_wart_block)
B(-7,34,5,minecraft:nether_wart_block)
B(-7,35,5,minecraft:nether_wart_block)
B(-7,36,5,minecraft:nether_wart_block)
B(-7,37,5,minecraft:nether_wart_block)
B(-7,38,5,minecraft:nether_wart_block)
B(-7,39,5,minecraft:nether_wart_block)
B(-7,40,5,minecraft:nether_wart_block)
B(-7,41,5,minecraft:nether_wart_block)
B(-7,27,6,minecraft:crimson_hyphae)
B(-7,28,6,minecraft:crimson_hyphae)
B(-7,29,6,minecraft:crimson_hyphae)
B(-7,30,6,minecraft:crimson_hyphae)
B(-7,31,6,minecraft:crimson_hyphae)
B(-7,32,6,minecraft:nether_wart_block)
B(-7,33,6,minecraft:nether_wart_block)
B(-7,34,6,minecraft:nether_wart_block)
B(-7,35,6,minecraft:nether_wart_block)
B(-7,36,6,minecraft:nether_wart_block)
B(-7,37,6,minecraft:nether_wart_block)
B(-7,38,6,minecraft:nether_wart_block)
B(-7,39,6,minecraft:nether_wart_block)
B(-7,40,6,minecraft:nether_wart_block)
B(-7,27,7,minecraft:crimson_hyphae)
B(-7,28,7,minecraft:crimson_hyphae)
B(-7,29,7,minecraft:crimson_hyphae)
B(-7,30,7,minecraft:crimson_hyphae)
B(-7,31,7,minecraft:crimson_hyphae)
B(-7,32,7,minecraft:crimson_hyphae)
B(-7,33,7,minecraft:crimson_hyphae)
B(-7,34,7,minecraft:nether_wart_block)
B(-7,35,7,minecraft:nether_wart_block)
B(-7,36,7,minecraft:nether_wart_block)
B(-7,37,7,minecraft:nether_wart_block)
B(-7,38,7,minecraft:nether_wart_block)
B(-7,39,7,minecraft:nether_wart_block)
B(-7,40,7,minecraft:nether_wart_block)
B(-7,25,8,minecraft:crimson_hyphae)
B(-7,26,8,minecraft:crimson_hyphae)
B(-7,27,8,minecraft:crimson_hyphae)
B(-7,28,8,minecraft:crimson_hyphae)
B(-7,29,8,minecraft:crimson_hyphae)
B(-7,30,8,minecraft:crimson_hyphae)
B(-7,31,8,minecraft:crimson_hyphae)
B(-7,32,8,minecraft:crimson_hyphae)
B(-7,33,8,minecraft:nether_wart_block)
B(-7,34,8,minecraft:nether_wart_block)
B(-7,35,8,minecraft:nether_wart_block)
B(-7,36,8,minecraft:nether_wart_block)
B(-7,37,8,minecraft:nether_wart_block)
B(-7,38,8,minecraft:nether_wart_block)
B(-7,39,8,minecraft:nether_wart_block)
B(-7,40,8,minecraft:nether_wart_block)
B(-7,41,8,minecraft:nether_wart_block)
B(-6,33,0,minecraft:nether_wart_block)
B(-6,34,0,minecraft:nether_wart_block)
B(-6,35,0,minecraft:nether_wart_block)
B(-6,36,0,minecraft:nether_wart_block)
B(-6,37,0,minecraft:nether_wart_block)
B(-6,33,1,minecraft:nether_wart_block)
B(-6,34,1,minecraft:nether_wart_block)
B(-6,35,1,minecraft:nether_wart_block)
B(-6,36,1,minecraft:nether_wart_block)
B(-6,37,1,minecraft:nether_wart_block)
B(-6,38,1,minecraft:nether_wart_block)
B(-6,39,1,minecraft:nether_wart_block)
B(-6,30,2,minecraft:shroomlight)
B(-6,31,2,minecraft:shroomlight)
B(-6,32,2,minecraft:shroomlight)
B(-6,33,2,minecraft:nether_wart_block)
B(-6,34,2,minecraft:nether_wart_block)
B(-6,35,2,minecraft:nether_wart_block)
B(-6,36,2,minecraft:nether_wart_block)
B(-6,37,2,minecraft:nether_wart_block)
B(-6,38,2,minecraft:nether_wart_block)
B(-6,39,2,minecraft:nether_wart_block)
B(-6,40,2,minecraft:nether_wart_block)
B(-6,30,3,minecraft:shroomlight)
B(-6,31,3,minecraft:shroomlight)
B(-6,32,3,minecraft:shroomlight)
B(-6,33,3,minecraft:nether_wart_block)
B(-6,34,3,minecraft:nether_wart_block)
B(-6,35,3,minecraft:nether_wart_block)
B(-6,36,3,minecraft:nether_wart_block)
B(-6,37,3,minecraft:nether_wart_block)
B(-6,38,3,minecraft:nether_wart_block)
B(-6,39,3,minecraft:nether_wart_block)
B(-6,40,3,minecraft:nether_wart_block)
B(-6,41,3,minecraft:nether_wart_block)
B(-6,30,4,minecraft:shroomlight)
B(-6,31,4,minecraft:shroomlight)
B(-6,32,4,minecraft:shroomlight)
B(-6,33,4,minecraft:nether_wart_block)
B(-6,34,4,minecraft:nether_wart_block)
B(-6,35,4,minecraft:nether_wart_block)
B(-6,36,4,minecraft:nether_wart_block)
B(-6,37,4,minecraft:nether_wart_block)
B(-6,38,4,minecraft:nether_wart_block)
B(-6,39,4,minecraft:nether_wart_block)
B(-6,40,4,minecraft:nether_wart_block)
B(-6,41,4,minecraft:nether_wart_block)
B(-6,30,5,minecraft:crimson_hyphae)
B(-6,31,5,minecraft:crimson_hyphae)
B(-6,32,5,minecraft:nether_wart_block)
B(-6,33,5,minecraft:nether_wart_block)
B(-6,34,5,minecraft:nether_wart_block)
B(-6,35,5,minecraft:nether_wart_block)
B(-6,36,5,minecraft:nether_wart_block)
B(-6,37,5,minecraft:nether_wart_block)
B(-6,38,5,minecraft:nether_wart_block)
B(-6,39,5,minecraft:nether_wart_block)
B(-6,40,5,minecraft:nether_wart_block)
B(-6,41,5,minecraft:nether_wart_block)
B(-6,30,6,minecraft:crimson_hyphae)
B(-6,31,6,minecraft:crimson_hyphae)
B(-6,32,6,minecraft:nether_wart_block)
B(-6,33,6,minecraft:nether_wart_block)
B(-6,34,6,minecraft:nether_wart_block)
B(-6,35,6,minecraft:nether_wart_block)
B(-6,36,6,minecraft:nether_wart_block)
B(-6,37,6,minecraft:nether_wart_block)
B(-6,38,6,minecraft:nether_wart_block)
B(-6,39,6,minecraft:nether_wart_block)
B(-6,40,6,minecraft:nether_wart_block)
B(-6,28,7,minecraft:crimson_hyphae)
B(-6,29,7,minecraft:crimson_hyphae)
B(-6,30,7,minecraft:crimson_hyphae)
B(-6,31,7,minecraft:crimson_hyphae)
B(-6,32,7,minecraft:crimson_hyphae)
B(-6,33,7,minecraft:nether_wart_block)
B(-6,34,7,minecraft:nether_wart_block)
B(-6,35,7,minecraft:nether_wart_block)
B(-6,36,7,minecraft:nether_wart_block)
B(-6,37,7,minecraft:nether_wart_block)
B(-6,38,7,minecraft:nether_wart_block)
B(-6,39,7,minecraft:nether_wart_block)
B(-6,28,8,minecraft:crimson_hyphae)
B(-6,29,8,minecraft:crimson_hyphae)
B(-6,30,8,minecraft:crimson_hyphae)
B(-6,31,8,minecraft:crimson_hyphae)
B(-6,32,8,minecraft:crimson_hyphae)
B(-6,33,8,minecraft:nether_wart_block)
B(-6,34,8,minecraft:nether_wart_block)
B(-6,35,8,minecraft:nether_wart_block)
B(-6,36,8,minecraft:nether_wart_block)
B(-6,37,8,minecraft:nether_wart_block)
B(-6,38,8,minecraft:nether_wart_block)
B(-6,39,8,minecraft:nether_wart_block)
B(-6,40,8,minecraft:nether_wart_block)
B(-6,41,8,minecraft:nether_wart_block)
B(-5,30,1,minecraft:shroomlight)
B(-5,31,1,minecraft:shroomlight)
B(-5,32,1,minecraft:shroomlight)
B(-5,34,1,minecraft:nether_wart_block)
B(-5,35,1,minecraft:nether_wart_block)
B(-5,36,1,minecraft:nether_wart_block)
B(-5,37,1,minecraft:nether_wart_block)
B(-5,38,1,minecraft:nether_wart_block)
B(-5,39,1,minecraft:nether_wart_block)
B(-5,29,2,minecraft:shroomlight)
B(-5,30,2,minecraft:shroomlight)
B(-5,31,2,minecraft:shroomlight)
B(-5,32,2,minecraft:shroomlight)
B(-5,33,2,minecraft:shroomlight)
B(-5,34,2,minecraft:nether_wart_block)
B(-5,35,2,minecraft:nether_wart_block)
B(-5,36,2,minecraft:nether_wart_block)
B(-5,37,2,minecraft:nether_wart_block)
B(-5,38,2,minecraft:nether_wart_block)
B(-5,39,2,minecraft:nether_wart_block)
B(-5,40,2,minecraft:nether_wart_block)
B(-5,29,3,minecraft:shroomlight)
B(-5,30,3,minecraft:shroomlight)
B(-5,31,3,minecraft:shroomlight)
B(-5,32,3,minecraft:shroomlight)
B(-5,33,3,minecraft:shroomlight)
B(-5,34,3,minecraft:nether_wart_block)
B(-5,35,3,minecraft:nether_wart_block)
B(-5,36,3,minecraft:nether_wart_block)
B(-5,37,3,minecraft:nether_wart_block)
B(-5,38,3,minecraft:nether_wart_block)
B(-5,39,3,minecraft:nether_wart_block)
B(-5,40,3,minecraft:nether_wart_block)
B(-5,41,3,minecraft:nether_wart_block)
B(-5,29,4,minecraft:shroomlight)
B(-5,30,4,minecraft:shroomlight)
B(-5,31,4,minecraft:shroomlight)
B(-5,32,4,minecraft:shroomlight)
B(-5,33,4,minecraft:shroomlight)
B(-5,34,4,minecraft:nether_wart_block)
B(-5,35,4,minecraft:nether_wart_block)
B(-5,36,4,minecraft:nether_wart_block)
B(-5,37,4,minecraft:nether_wart_block)
B(-5,38,4,minecraft:nether_wart_block)
B(-5,39,4,minecraft:nether_wart_block)
B(-5,40,4,minecraft:nether_wart_block)
B(-5,41,4,minecraft:nether_wart_block)
B(-5,30,5,minecraft:shroomlight)
B(-5,31,5,minecraft:shroomlight)
B(-5,32,5,minecraft:shroomlight)
B(-5,33,5,minecraft:nether_wart_block)
B(-5,34,5,minecraft:nether_wart_block)
B(-5,35,5,minecraft:nether_wart_block)
B(-5,36,5,minecraft:nether_wart_block)
B(-5,37,5,minecraft:nether_wart_block)
B(-5,38,5,minecraft:nether_wart_block)
B(-5,39,5,minecraft:nether_wart_block)
B(-5,40,5,minecraft:nether_wart_block)
B(-5,41,5,minecraft:nether_wart_block)
B(-5,31,6,minecraft:nether_wart_block)
B(-5,32,6,minecraft:nether_wart_block)
B(-5,33,6,minecraft:nether_wart_block)
B(-5,34,6,minecraft:nether_wart_block)
B(-5,35,6,minecraft:nether_wart_block)
B(-5,36,6,minecraft:nether_wart_block)
B(-5,37,6,minecraft:nether_wart_block)
B(-5,38,6,minecraft:nether_wart_block)
B(-5,39,6,minecraft:nether_wart_block)
B(-5,40,6,minecraft:nether_wart_block)
B(-5,31,7,minecraft:nether_wart_block)
B(-5,32,7,minecraft:nether_wart_block)
B(-5,33,7,minecraft:nether_wart_block)
B(-5,34,7,minecraft:nether_wart_block)
B(-5,35,7,minecraft:nether_wart_block)
B(-5,36,7,minecraft:nether_wart_block)
B(-5,37,7,minecraft:nether_wart_block)
B(-5,38,7,minecraft:nether_wart_block)
B(-5,39,7,minecraft:nether_wart_block)
B(-5,31,8,minecraft:crimson_hyphae)
B(-5,32,8,minecraft:crimson_hyphae)
B(-5,33,8,minecraft:nether_wart_block)
B(-5,34,8,minecraft:nether_wart_block)
B(-5,35,8,minecraft:nether_wart_block)
B(-5,36,8,minecraft:nether_wart_block)
B(-5,37,8,minecraft:nether_wart_block)
B(-5,38,8,minecraft:nether_wart_block)
B(-5,39,8,minecraft:nether_wart_block)
B(-4,30,1,minecraft:shroomlight)
B(-4,31,1,minecraft:shroomlight)
B(-4,32,1,minecraft:shroomlight)
B(-4,34,1,minecraft:nether_wart_block)
B(-4,35,1,minecraft:nether_wart_block)
B(-4,36,1,minecraft:nether_wart_block)
B(-4,29,2,minecraft:shroomlight)
B(-4,30,2,minecraft:shroomlight)
B(-4,31,2,minecraft:shroomlight)
B(-4,32,2,minecraft:shroomlight)
B(-4,33,2,minecraft:shroomlight)
B(-4,34,2,minecraft:nether_wart_block)
B(-4,35,2,minecraft:nether_wart_block)
B(-4,36,2,minecraft:nether_wart_block)
B(-4,37,2,minecraft:nether_wart_block)
B(-4,38,2,minecraft:nether_wart_block)
B(-4,39,2,minecraft:nether_wart_block)
B(-4,40,2,minecraft:nether_wart_block)
B(-4,29,3,minecraft:shroomlight)
B(-4,30,3,minecraft:shroomlight)
B(-4,31,3,minecraft:shroomlight)
B(-4,32,3,minecraft:shroomlight)
B(-4,33,3,minecraft:shroomlight)
B(-4,34,3,minecraft:nether_wart_block)
B(-4,35,3,minecraft:nether_wart_block)
B(-4,36,3,minecraft:nether_wart_block)
B(-4,37,3,minecraft:nether_wart_block)
B(-4,38,3,minecraft:nether_wart_block)
B(-4,39,3,minecraft:nether_wart_block)
B(-4,40,3,minecraft:nether_wart_block)
B(-4,29,4,minecraft:shroomlight)
B(-4,30,4,minecraft:shroomlight)
B(-4,31,4,minecraft:shroomlight)
B(-4,32,4,minecraft:shroomlight)
B(-4,33,4,minecraft:shroomlight)
B(-4,34,4,minecraft:nether_wart_block)
B(-4,35,4,minecraft:nether_wart_block)
B(-4,36,4,minecraft:nether_wart_block)
B(-4,37,4,minecraft:nether_wart_block)
B(-4,38,4,minecraft:nether_wart_block)
B(-4,39,4,minecraft:nether_wart_block)
B(-4,40,4,minecraft:nether_wart_block)
B(-4,30,5,minecraft:shroomlight)
B(-4,31,5,minecraft:shroomlight)
B(-4,32,5,minecraft:shroomlight)
B(-4,33,5,minecraft:nether_wart_block)
B(-4,34,5,minecraft:nether_wart_block)
B(-4,35,5,minecraft:nether_wart_block)
B(-4,36,5,minecraft:nether_wart_block)
B(-4,37,5,minecraft:nether_wart_block)
B(-4,38,5,minecraft:nether_wart_block)
B(-4,39,5,minecraft:nether_wart_block)
B(-4,40,5,minecraft:nether_wart_block)
B(-4,30,6,minecraft:nether_wart_block)
B(-4,31,6,minecraft:nether_wart_block)
B(-4,32,6,minecraft:nether_wart_block)
B(-4,33,6,minecraft:nether_wart_block)
B(-4,34,6,minecraft:nether_wart_block)
B(-4,35,6,minecraft:nether_wart_block)
B(-4,36,6,minecraft:nether_wart_block)
B(-4,37,6,minecraft:nether_wart_block)
B(-4,38,6,minecraft:nether_wart_block)
B(-4,39,6,minecraft:nether_wart_block)
B(-4,40,6,minecraft:nether_wart_block)
B(-4,31,7,minecraft:nether_wart_block)
B(-4,32,7,minecraft:nether_wart_block)
B(-4,33,7,minecraft:nether_wart_block)
B(-4,34,7,minecraft:nether_wart_block)
B(-4,35,7,minecraft:nether_wart_block)
B(-4,36,7,minecraft:nether_wart_block)
B(-4,37,7,minecraft:nether_wart_block)
B(-4,38,7,minecraft:nether_wart_block)
B(-4,39,7,minecraft:nether_wart_block)
B(-4,32,8,minecraft:nether_wart_block)
B(-4,33,8,minecraft:nether_wart_block)
B(-4,34,8,minecraft:nether_wart_block)
B(-4,35,8,minecraft:nether_wart_block)
B(-4,36,8,minecraft:nether_wart_block)
B(-4,37,8,minecraft:nether_wart_block)
B(-4,38,8,minecraft:nether_wart_block)
B(-4,39,8,minecraft:nether_wart_block)
B(-3,30,1,minecraft:shroomlight)
B(-3,31,1,minecraft:shroomlight)
B(-3,32,1,minecraft:shroomlight)
B(-3,29,2,minecraft:shroomlight)
B(-3,30,2,minecraft:shroomlight)
B(-3,31,2,minecraft:shroomlight)
B(-3,32,2,minecraft:shroomlight)
B(-3,33,2,minecraft:shroomlight)
B(-3,34,2,minecraft:nether_wart_block)
B(-3,35,2,minecraft:nether_wart_block)
B(-3,36,2,minecraft:nether_wart_block)
B(-3,37,2,minecraft:nether_wart_block)
B(-3,29,3,minecraft:shroomlight)
B(-3,30,3,minecraft:shroomlight)
B(-3,31,3,minecraft:shroomlight)
B(-3,32,3,minecraft:shroomlight)
B(-3,33,3,minecraft:shroomlight)
B(-3,34,3,minecraft:nether_wart_block)
B(-3,35,3,minecraft:nether_wart_block)
B(-3,36,3,minecraft:nether_wart_block)
B(-3,37,3,minecraft:nether_wart_block)
B(-3,38,3,minecraft:nether_wart_block)
B(-3,39,3,minecraft:nether_wart_block)
B(-3,29,4,minecraft:shroomlight)
B(-3,30,4,minecraft:shroomlight)
B(-3,31,4,minecraft:shroomlight)
B(-3,32,4,minecraft:shroomlight)
B(-3,33,4,minecraft:shroomlight)
B(-3,34,4,minecraft:nether_wart_block)
B(-3,35,4,minecraft:nether_wart_block)
B(-3,36,4,minecraft:nether_wart_block)
B(-3,37,4,minecraft:nether_wart_block)
B(-3,38,4,minecraft:nether_wart_block)
B(-3,39,4,minecraft:nether_wart_block)
B(-3,30,5,minecraft:shroomlight)
B(-3,31,5,minecraft:shroomlight)
B(-3,32,5,minecraft:shroomlight)
B(-3,33,5,minecraft:nether_wart_block)
B(-3,34,5,minecraft:nether_wart_block)
B(-3,35,5,minecraft:nether_wart_block)
B(-3,36,5,minecraft:nether_wart_block)
B(-3,37,5,minecraft:nether_wart_block)
B(-3,38,5,minecraft:nether_wart_block)
B(-3,39,5,minecraft:nether_wart_block)
B(-3,30,6,minecraft:nether_wart_block)
B(-3,31,6,minecraft:nether_wart_block)
B(-3,32,6,minecraft:nether_wart_block)
B(-3,33,6,minecraft:nether_wart_block)
B(-3,34,6,minecraft:nether_wart_block)
B(-3,35,6,minecraft:nether_wart_block)
B(-3,36,6,minecraft:nether_wart_block)
B(-3,37,6,minecraft:nether_wart_block)
B(-3,38,6,minecraft:nether_wart_block)
B(-3,31,7,minecraft:nether_wart_block)
B(-3,32,7,minecraft:nether_wart_block)
B(-3,33,7,minecraft:nether_wart_block)
B(-3,34,7,minecraft:nether_wart_block)
B(-3,35,7,minecraft:nether_wart_block)
B(-3,36,7,minecraft:nether_wart_block)
B(-3,37,7,minecraft:nether_wart_block)
B(-3,38,7,minecraft:nether_wart_block)
B(-3,32,8,minecraft:nether_wart_block)
B(-3,33,8,minecraft:nether_wart_block)
B(-3,34,8,minecraft:nether_wart_block)
B(-3,35,8,minecraft:nether_wart_block)
B(-3,36,8,minecraft:nether_wart_block)
B(-3,37,8,minecraft:nether_wart_block)
B(-3,38,8,minecraft:nether_wart_block)
B(-2,30,2,minecraft:shroomlight)
B(-2,31,2,minecraft:shroomlight)
B(-2,32,2,minecraft:shroomlight)
B(-2,33,2,minecraft:nether_wart_block)
B(-2,34,2,minecraft:nether_wart_block)
B(-2,30,3,minecraft:shroomlight)
B(-2,31,3,minecraft:shroomlight)
B(-2,32,3,minecraft:shroomlight)
B(-2,33,3,minecraft:nether_wart_block)
B(-2,34,3,minecraft:nether_wart_block)
B(-2,35,3,minecraft:nether_wart_block)
B(-2,36,3,minecraft:nether_wart_block)
B(-2,30,4,minecraft:shroomlight)
B(-2,31,4,minecraft:shroomlight)
B(-2,32,4,minecraft:shroomlight)
B(-2,33,4,minecraft:nether_wart_block)
B(-2,34,4,minecraft:nether_wart_block)
B(-2,35,4,minecraft:nether_wart_block)
B(-2,36,4,minecraft:nether_wart_block)
B(-2,30,5,minecraft:nether_wart_block)
B(-2,31,5,minecraft:nether_wart_block)
B(-2,32,5,minecraft:nether_wart_block)
B(-2,33,5,minecraft:nether_wart_block)
B(-2,34,5,minecraft:nether_wart_block)
B(-2,35,5,minecraft:nether_wart_block)
B(-2,36,5,minecraft:nether_wart_block)
B(-2,16,6,minecraft:weeping_vines[age=20])
B(-2,17,6,minecraft:weeping_vines_plant)
B(-2,18,6,minecraft:weeping_vines_plant)
B(-2,19,6,minecraft:weeping_vines_plant)
B(-2,20,6,minecraft:weeping_vines_plant)
B(-2,21,6,minecraft:weeping_vines_plant)
B(-2,22,6,minecraft:weeping_vines_plant)
B(-2,23,6,minecraft:weeping_vines_plant)
B(-2,24,6,minecraft:weeping_vines_plant)
B(-2,25,6,minecraft:weeping_vines_plant)
B(-2,26,6,minecraft:weeping_vines_plant)
B(-2,27,6,minecraft:weeping_vines_plant)
B(-2,28,6,minecraft:weeping_vines_plant)
B(-2,29,6,minecraft:weeping_vines_plant)
B(-2,30,6,minecraft:nether_wart_block)
B(-2,31,6,minecraft:nether_wart_block)
B(-2,32,6,minecraft:nether_wart_block)
B(-2,33,6,minecraft:nether_wart_block)
B(-2,34,6,minecraft:nether_wart_block)
B(-2,35,6,minecraft:nether_wart_block)
B(-2,36,6,minecraft:nether_wart_block)
B(-2,37,6,minecraft:nether_wart_block)
B(-2,31,7,minecraft:nether_wart_block)
B(-2,32,7,minecraft:nether_wart_block)
B(-2,33,7,minecraft:nether_wart_block)
B(-2,34,7,minecraft:nether_wart_block)
B(-2,35,7,minecraft:nether_wart_block)
B(-2,36,7,minecraft:nether_wart_block)
B(-2,37,7,minecraft:nether_wart_block)
B(-2,32,8,minecraft:nether_wart_block)
B(-2,33,8,minecraft:nether_wart_block)
B(-2,34,8,minecraft:nether_wart_block)
B(-2,35,8,minecraft:nether_wart_block)
B(-2,36,8,minecraft:nether_wart_block)
B(-2,37,8,minecraft:nether_wart_block)
B(-1,31,3,minecraft:nether_wart_block)
B(-1,32,3,minecraft:nether_wart_block)
B(-1,33,3,minecraft:nether_wart_block)
B(-1,34,3,minecraft:nether_wart_block)
B(-1,35,3,minecraft:nether_wart_block)
B(-1,31,4,minecraft:nether_wart_block)
B(-1,32,4,minecraft:nether_wart_block)
B(-1,33,4,minecraft:nether_wart_block)
B(-1,34,4,minecraft:nether_wart_block)
B(-1,35,4,minecraft:nether_wart_block)
B(-1,31,5,minecraft:nether_wart_block)
B(-1,32,5,minecraft:nether_wart_block)
B(-1,33,5,minecraft:nether_wart_block)
B(-1,34,5,minecraft:nether_wart_block)
B(-1,35,5,minecraft:nether_wart_block)
B(-1,31,6,minecraft:nether_wart_block)
B(-1,32,6,minecraft:nether_wart_block)
B(-1,33,6,minecraft:nether_wart_block)
B(-1,34,6,minecraft:nether_wart_block)
B(-1,35,6,minecraft:nether_wart_block)
B(-1,31,7,minecraft:nether_wart_block)
B(-1,32,7,minecraft:nether_wart_block)
B(-1,33,7,minecraft:nether_wart_block)
B(-1,34,7,minecraft:nether_wart_block)
B(-1,35,7,minecraft:nether_wart_block)
B(0,32,4,minecraft:nether_wart_block)
B(0,33,4,minecraft:nether_wart_block)
B(0,34,4,minecraft:nether_wart_block)
B(0,32,5,minecraft:nether_wart_block)
B(0,33,5,minecraft:nether_wart_block)
B(0,34,5,minecraft:nether_wart_block)
B(0,32,6,minecraft:nether_wart_block)
B(0,33,6,minecraft:nether_wart_block)
B(0,34,6,minecraft:nether_wart_block)

#######################################################################
# +-----------------------------------------------------------------+ #
# |                             Branches                            | #
# +-----------------------------------------------------------------+ #
#######################################################################


#######################################################################
# +-----------------------------------------------------------------+ #
# |                             Entities                            | #
# +-----------------------------------------------------------------+ #
#######################################################################

