#######################################################################
# +-----------------------------------------------------------------+ #
# |                            BO3 object                           | #
# +-----------------------------------------------------------------+ #
#######################################################################

Author: Bo3 BulkEdit

Description: Converted Schematic - Modified by Bo3BulkEdit

Version: 3

SettingsMode: WriteDisable

#######################################################################
# +-----------------------------------------------------------------+ #
# |                          Main settings                          | #
# +-----------------------------------------------------------------+ #
#######################################################################

IsOTGPlus: true
Tree: true
Frequency: 10
Rarity: 100
RotateRandomly: true
SpawnHeight: randomY
SpawnHeightOffset: 0
SpawnHeightVariance: 0
MaxBranchDepth: 10
ExcludedBiomes: All

##############################
# Height Limits for the BO3. #
##############################

MinHeight: 50
MaxHeight: 65

#######################################################################
# +-----------------------------------------------------------------+ #
# |                      Source block settings                      | #
# +-----------------------------------------------------------------+ #
#######################################################################

SourceBlocks: AIR
MaxPercentageOutsideSourceBlock: 100
OutsideSourceBlock: placeAnyway

#######################################################################
# +-----------------------------------------------------------------+ #
# |                               OTG+                              | #
# +-----------------------------------------------------------------+ #
#######################################################################

RemoveAir: true
ReplaceBelow: OBSIDIAN
ReplaceWithBiomeBlocks: false
ReplaceWithGroundBlock: OBSIDIAN
ReplaceWithSurfaceBlock: OBSIDIAN
ReplaceWithStoneBlock: OBSIDIAN
SmoothRadius: 30
SmoothingSurfaceBlock: OBSIDIAN
SmoothingGroundBlock: OBSIDIAN

#######################################################################
# +-----------------------------------------------------------------+ #
# |                              Blocks                             | #
# +-----------------------------------------------------------------+ #
#######################################################################

RB(0,0,0,minecraft:crying_obsidian,20,minecraft:obsidian,100)
RB(1,0,0,minecraft:crying_obsidian,20,minecraft:obsidian,100)
RB(2,0,0,minecraft:crying_obsidian,20,minecraft:obsidian,100)
RB(3,0,0,minecraft:crying_obsidian,20,minecraft:obsidian,100)
RB(4,0,0,minecraft:crying_obsidian,20,minecraft:obsidian,100)
RB(0,0,1,minecraft:crying_obsidian,20,minecraft:obsidian,100)
RB(1,0,1,minecraft:crying_obsidian,20,minecraft:obsidian,100)
RB(2,0,1,minecraft:crying_obsidian,20,minecraft:obsidian,100)
RB(3,0,1,minecraft:crying_obsidian,20,minecraft:obsidian,100)
RB(0,0,2,minecraft:crying_obsidian,20,minecraft:obsidian,100)
RB(1,0,2,minecraft:crying_obsidian,20,minecraft:obsidian,100)
RB(2,0,2,minecraft:crying_obsidian,20,minecraft:obsidian,100)
RB(3,0,2,minecraft:crying_obsidian,20,minecraft:obsidian,100)
RB(0,0,3,minecraft:crying_obsidian,20,minecraft:obsidian,100)
RB(1,0,3,minecraft:crying_obsidian,20,minecraft:obsidian,100)
RB(2,0,3,minecraft:crying_obsidian,20,minecraft:obsidian,100)
RB(3,0,3,minecraft:crying_obsidian,20,minecraft:obsidian,100)
RB(0,0,4,minecraft:crying_obsidian,20,minecraft:obsidian,100)
RB(1,0,4,minecraft:crying_obsidian,20,minecraft:obsidian,100)
RB(2,0,4,minecraft:crying_obsidian,20,minecraft:obsidian,100)
RB(3,0,4,minecraft:crying_obsidian,20,minecraft:obsidian,100)
RB(0,0,5,minecraft:crying_obsidian,20,minecraft:obsidian,100)
RB(1,0,5,minecraft:crying_obsidian,20,minecraft:obsidian,100)
RB(2,0,5,minecraft:crying_obsidian,20,minecraft:obsidian,100)
RB(0,0,6,minecraft:crying_obsidian,20,minecraft:obsidian,100)
RB(1,0,6,minecraft:crying_obsidian,20,minecraft:obsidian,100)
RB(0,0,7,minecraft:crying_obsidian,20,minecraft:obsidian,100)
RB(1,0,7,minecraft:crying_obsidian,20,minecraft:obsidian,100)
RB(0,0,8,minecraft:crying_obsidian,20,minecraft:obsidian,100)
RB(1,0,8,minecraft:crying_obsidian,20,minecraft:obsidian,100)
RB(0,0,9,minecraft:crying_obsidian,20,minecraft:obsidian,100)
RB(1,0,9,minecraft:crying_obsidian,20,minecraft:obsidian,100)
RB(0,0,10,minecraft:crying_obsidian,20,minecraft:obsidian,100)
RB(0,0,12,minecraft:crying_obsidian,20,minecraft:obsidian,100)
RB(0,0,13,minecraft:crying_obsidian,20,minecraft:obsidian,100)
RB(0,0,14,minecraft:crying_obsidian,20,minecraft:obsidian,100)
RB(0,1,0,minecraft:crying_obsidian,20,minecraft:obsidian,100)
RB(1,1,0,minecraft:crying_obsidian,20,minecraft:obsidian,100)
RB(2,1,0,minecraft:crying_obsidian,20,minecraft:obsidian,100)
RB(3,1,0,minecraft:crying_obsidian,20,minecraft:obsidian,100)
RB(4,1,0,minecraft:crying_obsidian,20,minecraft:obsidian,100)
RB(0,1,1,minecraft:crying_obsidian,20,minecraft:obsidian,100)
RB(1,1,1,minecraft:crying_obsidian,20,minecraft:obsidian,100)
RB(2,1,1,minecraft:crying_obsidian,20,minecraft:obsidian,100)
RB(3,1,1,minecraft:crying_obsidian,20,minecraft:obsidian,100)
RB(0,1,2,minecraft:crying_obsidian,20,minecraft:obsidian,100)
RB(1,1,2,minecraft:crying_obsidian,20,minecraft:obsidian,100)
RB(2,1,2,minecraft:crying_obsidian,20,minecraft:obsidian,100)
RB(3,1,2,minecraft:crying_obsidian,20,minecraft:obsidian,100)
RB(0,1,3,minecraft:crying_obsidian,20,minecraft:obsidian,100)
RB(1,1,3,minecraft:crying_obsidian,20,minecraft:obsidian,100)
RB(2,1,3,minecraft:crying_obsidian,20,minecraft:obsidian,100)
RB(3,1,3,minecraft:crying_obsidian,20,minecraft:obsidian,100)
RB(0,1,4,minecraft:crying_obsidian,20,minecraft:obsidian,100)
RB(1,1,4,minecraft:crying_obsidian,20,minecraft:obsidian,100)
RB(2,1,4,minecraft:crying_obsidian,20,minecraft:obsidian,100)
RB(3,1,4,minecraft:crying_obsidian,20,minecraft:obsidian,100)
RB(0,1,5,minecraft:crying_obsidian,20,minecraft:obsidian,100)
RB(1,1,5,minecraft:crying_obsidian,20,minecraft:obsidian,100)
RB(2,1,5,minecraft:crying_obsidian,20,minecraft:obsidian,100)
RB(0,1,6,minecraft:crying_obsidian,20,minecraft:obsidian,100)
RB(1,1,6,minecraft:crying_obsidian,20,minecraft:obsidian,100)
RB(0,1,7,minecraft:crying_obsidian,20,minecraft:obsidian,100)
RB(1,1,7,minecraft:crying_obsidian,20,minecraft:obsidian,100)
RB(0,1,8,minecraft:crying_obsidian,20,minecraft:obsidian,100)
RB(1,1,8,minecraft:crying_obsidian,20,minecraft:obsidian,100)
RB(0,1,9,minecraft:crying_obsidian,20,minecraft:obsidian,100)
RB(1,1,9,minecraft:crying_obsidian,20,minecraft:obsidian,100)
RB(0,1,10,minecraft:crying_obsidian,20,minecraft:obsidian,100)
RB(0,2,0,minecraft:crying_obsidian,20,minecraft:obsidian,100)
RB(1,2,0,minecraft:crying_obsidian,20,minecraft:obsidian,100)
RB(2,2,0,minecraft:crying_obsidian,20,minecraft:obsidian,100)
RB(3,2,0,minecraft:crying_obsidian,20,minecraft:obsidian,100)
RB(0,2,1,minecraft:crying_obsidian,20,minecraft:obsidian,100)
RB(1,2,1,minecraft:crying_obsidian,20,minecraft:obsidian,100)
RB(2,2,1,minecraft:crying_obsidian,20,minecraft:obsidian,100)
RB(3,2,1,minecraft:crying_obsidian,20,minecraft:obsidian,100)
RB(0,2,2,minecraft:crying_obsidian,20,minecraft:obsidian,100)
RB(1,2,2,minecraft:crying_obsidian,20,minecraft:obsidian,100)
RB(2,2,2,minecraft:crying_obsidian,20,minecraft:obsidian,100)
RB(3,2,2,minecraft:crying_obsidian,20,minecraft:obsidian,100)
RB(0,2,3,minecraft:crying_obsidian,20,minecraft:obsidian,100)
RB(1,2,3,minecraft:crying_obsidian,20,minecraft:obsidian,100)
RB(2,2,3,minecraft:crying_obsidian,20,minecraft:obsidian,100)
RB(3,2,3,minecraft:crying_obsidian,20,minecraft:obsidian,100)
RB(0,2,4,minecraft:crying_obsidian,20,minecraft:obsidian,100)
RB(1,2,4,minecraft:crying_obsidian,20,minecraft:obsidian,100)
RB(2,2,4,minecraft:crying_obsidian,20,minecraft:obsidian,100)
RB(3,2,4,minecraft:crying_obsidian,20,minecraft:obsidian,100)
RB(0,2,5,minecraft:crying_obsidian,20,minecraft:obsidian,100)
RB(1,2,5,minecraft:crying_obsidian,20,minecraft:obsidian,100)
RB(2,2,5,minecraft:crying_obsidian,20,minecraft:obsidian,100)
RB(0,2,6,minecraft:crying_obsidian,20,minecraft:obsidian,100)
RB(1,2,6,minecraft:crying_obsidian,20,minecraft:obsidian,100)
RB(0,2,7,minecraft:crying_obsidian,20,minecraft:obsidian,100)
RB(1,2,7,minecraft:crying_obsidian,20,minecraft:obsidian,100)
RB(0,2,8,minecraft:crying_obsidian,20,minecraft:obsidian,100)
RB(1,2,8,minecraft:crying_obsidian,20,minecraft:obsidian,100)
RB(0,2,9,minecraft:crying_obsidian,20,minecraft:obsidian,100)
RB(0,2,10,minecraft:crying_obsidian,20,minecraft:obsidian,100)
RB(0,3,0,minecraft:crying_obsidian,20,minecraft:obsidian,100)
RB(1,3,0,minecraft:crying_obsidian,20,minecraft:obsidian,100)
RB(2,3,0,minecraft:crying_obsidian,20,minecraft:obsidian,100)
RB(3,3,0,minecraft:crying_obsidian,20,minecraft:obsidian,100)
RB(0,3,1,minecraft:crying_obsidian,20,minecraft:obsidian,100)
RB(1,3,1,minecraft:crying_obsidian,20,minecraft:obsidian,100)
RB(2,3,1,minecraft:crying_obsidian,20,minecraft:obsidian,100)
RB(3,3,1,minecraft:crying_obsidian,20,minecraft:obsidian,100)
RB(0,3,2,minecraft:crying_obsidian,20,minecraft:obsidian,100)
RB(1,3,2,minecraft:crying_obsidian,20,minecraft:obsidian,100)
RB(2,3,2,minecraft:crying_obsidian,20,minecraft:obsidian,100)
RB(3,3,2,minecraft:crying_obsidian,20,minecraft:obsidian,100)
RB(0,3,3,minecraft:crying_obsidian,20,minecraft:obsidian,100)
RB(1,3,3,minecraft:crying_obsidian,20,minecraft:obsidian,100)
RB(2,3,3,minecraft:crying_obsidian,20,minecraft:obsidian,100)
RB(3,3,3,minecraft:crying_obsidian,20,minecraft:obsidian,100)
RB(0,3,4,minecraft:crying_obsidian,20,minecraft:obsidian,100)
RB(1,3,4,minecraft:crying_obsidian,20,minecraft:obsidian,100)
RB(2,3,4,minecraft:crying_obsidian,20,minecraft:obsidian,100)
RB(3,3,4,minecraft:crying_obsidian,20,minecraft:obsidian,100)
RB(0,3,5,minecraft:crying_obsidian,20,minecraft:obsidian,100)
RB(1,3,5,minecraft:crying_obsidian,20,minecraft:obsidian,100)
RB(2,3,5,minecraft:crying_obsidian,20,minecraft:obsidian,100)
RB(0,3,6,minecraft:crying_obsidian,20,minecraft:obsidian,100)
RB(1,3,6,minecraft:crying_obsidian,20,minecraft:obsidian,100)
RB(0,3,7,minecraft:crying_obsidian,20,minecraft:obsidian,100)
RB(1,3,7,minecraft:crying_obsidian,20,minecraft:obsidian,100)
RB(0,3,8,minecraft:crying_obsidian,20,minecraft:obsidian,100)
RB(1,3,8,minecraft:crying_obsidian,20,minecraft:obsidian,100)
RB(0,3,9,minecraft:crying_obsidian,20,minecraft:obsidian,100)
RB(0,3,10,minecraft:crying_obsidian,20,minecraft:obsidian,100)
RB(0,4,0,minecraft:crying_obsidian,20,minecraft:obsidian,100)
RB(1,4,0,minecraft:crying_obsidian,20,minecraft:obsidian,100)
RB(2,4,0,minecraft:crying_obsidian,20,minecraft:obsidian,100)
RB(0,4,1,minecraft:crying_obsidian,20,minecraft:obsidian,100)
RB(1,4,1,minecraft:crying_obsidian,20,minecraft:obsidian,100)
RB(2,4,1,minecraft:crying_obsidian,20,minecraft:obsidian,100)
RB(3,4,1,minecraft:crying_obsidian,20,minecraft:obsidian,100)
RB(0,4,2,minecraft:crying_obsidian,20,minecraft:obsidian,100)
RB(1,4,2,minecraft:crying_obsidian,20,minecraft:obsidian,100)
RB(2,4,2,minecraft:crying_obsidian,20,minecraft:obsidian,100)
RB(3,4,2,minecraft:crying_obsidian,20,minecraft:obsidian,100)
RB(0,4,3,minecraft:crying_obsidian,20,minecraft:obsidian,100)
RB(1,4,3,minecraft:crying_obsidian,20,minecraft:obsidian,100)
RB(2,4,3,minecraft:crying_obsidian,20,minecraft:obsidian,100)
RB(3,4,3,minecraft:crying_obsidian,20,minecraft:obsidian,100)
RB(0,4,4,minecraft:crying_obsidian,20,minecraft:obsidian,100)
RB(1,4,4,minecraft:crying_obsidian,20,minecraft:obsidian,100)
RB(2,4,4,minecraft:crying_obsidian,20,minecraft:obsidian,100)
RB(3,4,4,minecraft:crying_obsidian,20,minecraft:obsidian,100)
RB(0,4,5,minecraft:crying_obsidian,20,minecraft:obsidian,100)
RB(1,4,5,minecraft:crying_obsidian,20,minecraft:obsidian,100)
RB(2,4,5,minecraft:crying_obsidian,20,minecraft:obsidian,100)
RB(0,4,6,minecraft:crying_obsidian,20,minecraft:obsidian,100)
RB(1,4,6,minecraft:crying_obsidian,20,minecraft:obsidian,100)
RB(0,4,7,minecraft:crying_obsidian,20,minecraft:obsidian,100)
RB(0,4,8,minecraft:crying_obsidian,20,minecraft:obsidian,100)
RB(0,4,9,minecraft:crying_obsidian,20,minecraft:obsidian,100)
RB(0,5,0,minecraft:crying_obsidian,20,minecraft:obsidian,100)
RB(1,5,0,minecraft:crying_obsidian,20,minecraft:obsidian,100)
RB(0,5,1,minecraft:crying_obsidian,20,minecraft:obsidian,100)
RB(1,5,1,minecraft:crying_obsidian,20,minecraft:obsidian,100)
RB(2,5,1,minecraft:crying_obsidian,20,minecraft:obsidian,100)
RB(0,5,2,minecraft:crying_obsidian,20,minecraft:obsidian,100)
RB(1,5,2,minecraft:crying_obsidian,20,minecraft:obsidian,100)
RB(2,5,2,minecraft:crying_obsidian,20,minecraft:obsidian,100)
RB(0,5,3,minecraft:crying_obsidian,20,minecraft:obsidian,100)
RB(1,5,3,minecraft:crying_obsidian,20,minecraft:obsidian,100)
RB(2,5,3,minecraft:crying_obsidian,20,minecraft:obsidian,100)
RB(0,5,4,minecraft:crying_obsidian,20,minecraft:obsidian,100)
RB(1,5,4,minecraft:crying_obsidian,20,minecraft:obsidian,100)
RB(2,5,4,minecraft:crying_obsidian,20,minecraft:obsidian,100)
RB(0,5,5,minecraft:crying_obsidian,20,minecraft:obsidian,100)
RB(1,5,5,minecraft:crying_obsidian,20,minecraft:obsidian,100)
RB(0,5,6,minecraft:crying_obsidian,20,minecraft:obsidian,100)
RB(1,5,6,minecraft:crying_obsidian,20,minecraft:obsidian,100)
RB(0,6,0,minecraft:crying_obsidian,20,minecraft:obsidian,100)
RB(0,6,1,minecraft:crying_obsidian,20,minecraft:obsidian,100)
RB(0,6,2,minecraft:crying_obsidian,20,minecraft:obsidian,100)
RB(1,6,2,minecraft:crying_obsidian,20,minecraft:obsidian,100)
RB(0,6,3,minecraft:crying_obsidian,20,minecraft:obsidian,100)
RB(1,6,3,minecraft:crying_obsidian,20,minecraft:obsidian,100)
RB(0,6,4,minecraft:crying_obsidian,20,minecraft:obsidian,100)
RB(1,6,4,minecraft:crying_obsidian,20,minecraft:obsidian,100)
RB(0,6,5,minecraft:crying_obsidian,20,minecraft:obsidian,100)
RB(1,6,5,minecraft:crying_obsidian,20,minecraft:obsidian,100)
RB(0,6,6,minecraft:crying_obsidian,20,minecraft:obsidian,100)
RB(0,7,4,minecraft:crying_obsidian,20,minecraft:obsidian,100)
RB(0,7,5,minecraft:crying_obsidian,20,minecraft:obsidian,100)
B(3,9,4,minecraft:melon)
B(1,9,5,minecraft:melon)
B(6,11,7,minecraft:melon)

