
#######################################################################
# +-----------------------------------------------------------------+ #
# |                            BO4 object                           | #
# +-----------------------------------------------------------------+ #
#######################################################################

Author: Unknown

Description: No description given

SettingsMode: WriteWithoutComments


#######################################################################
# +-----------------------------------------------------------------+ #
# |                          Main settings                          | #
# +-----------------------------------------------------------------+ #
#######################################################################

FixedRotation: 

Frequency: 0

SpawnHeight: highestBlock

UseCenterForHighestBlock: true

##############################
# Height Limits for the BO4. #
##############################

MinHeight: 0

MaxHeight: 255

InheritBO3: 

InheritBO3Rotation: NORTH

OverrideChildSettings: true

OverrideParentHeight: false

CanOverride: false

BranchFrequency: 0

BranchFrequencyGroup: 

MustBeBelowOther: false

MustBeInside: 

CannotBeInside: 

ReplacesBO3: 

MustBeInsideWorldBorders: false

CanSpawnOnWater: true

SpawnOnWaterOnly: false

SpawnUnderWater: false

SpawnAtWaterLevel: false

HeightOffset: 0

RemoveAir: true

ReplaceAbove: 

ReplaceBelow: 

ReplaceWithBiomeBlocks: true

ReplaceWithSurfaceBlock: GRASS

ReplaceWithGroundBlock: DIRT

ReplaceWithStoneBlock: STONE

SmoothRadius: 0

SmoothHeightOffset: 0

SmoothStartTop: false

SmoothStartWood: false

SmoothingSurfaceBlock: 

SmoothingGroundBlock: 

BO3Group: 

IsSpawnPoint: false

DoReplaceBlocks: true


#######################################################################
# +-----------------------------------------------------------------+ #
# |                              Blocks                             | #
# +-----------------------------------------------------------------+ #
#######################################################################

B(-8,90,1,minecraft:basalt)
B(-8,90,2,minecraft:basalt)
B(-8,90,3,minecraft:basalt)
B(-7,90,1,minecraft:basalt)
B(-7,90,2,minecraft:basalt)
B(-7,90,3,minecraft:basalt)
B(-6,90,0,minecraft:basalt)
B(-6,90,1,minecraft:basalt)
B(-6,90,2,minecraft:basalt)
B(-6,90,3,minecraft:basalt)
B(-5,90,0,minecraft:basalt)
B(-5,90,1,minecraft:basalt)
B(-5,90,2,minecraft:basalt)
B(-5,90,3,minecraft:basalt)
B(-4,88,-7,minecraft:basalt)
B(-4,89,-7,minecraft:basalt)
B(-4,90,-7,minecraft:basalt)
B(-4,90,0,minecraft:basalt)
B(-4,90,1,minecraft:basalt)
B(-4,90,2,minecraft:basalt)
B(-4,90,3,minecraft:basalt)
B(-3,79,-7,minecraft:basalt)
B(-3,80,-7,minecraft:basalt)
B(-3,81,-7,minecraft:basalt)
B(-3,82,-7,minecraft:basalt)
B(-3,83,-7,minecraft:basalt)
B(-3,84,-7,minecraft:basalt)
B(-3,85,-7,minecraft:basalt)
B(-3,86,-7,minecraft:basalt)
B(-3,87,-7,minecraft:basalt)
B(-3,88,-7,minecraft:basalt)
B(-3,89,-7,minecraft:basalt)
B(-3,90,-7,minecraft:basalt)
B(-3,80,-6,minecraft:basalt)
B(-3,81,-6,minecraft:basalt)
B(-3,82,-6,minecraft:basalt)
B(-3,83,-6,minecraft:basalt)
B(-3,84,-6,minecraft:basalt)
B(-3,85,-6,minecraft:basalt)
B(-3,86,-6,minecraft:basalt)
B(-3,87,-6,minecraft:basalt)
B(-3,88,-6,minecraft:basalt)
B(-3,89,-6,minecraft:basalt)
B(-3,90,-6,minecraft:basalt)
B(-3,88,-5,minecraft:basalt)
B(-3,89,-5,minecraft:basalt)
B(-3,90,-5,minecraft:basalt)
B(-3,90,-1,minecraft:basalt)
B(-3,90,0,minecraft:basalt)
B(-3,90,1,minecraft:basalt)
B(-3,90,2,minecraft:basalt)
B(-3,90,3,minecraft:basalt)
B(-2,69,-7,minecraft:basalt)
B(-2,70,-7,minecraft:basalt)
B(-2,71,-7,minecraft:basalt)
B(-2,72,-7,minecraft:basalt)
B(-2,73,-7,minecraft:basalt)
B(-2,74,-7,minecraft:basalt)
B(-2,75,-7,minecraft:basalt)
B(-2,76,-7,minecraft:basalt)
B(-2,77,-7,minecraft:basalt)
B(-2,78,-7,minecraft:basalt)
B(-2,79,-7,minecraft:basalt)
B(-2,80,-7,minecraft:basalt)
B(-2,81,-7,minecraft:basalt)
B(-2,82,-7,minecraft:basalt)
B(-2,83,-7,minecraft:basalt)
B(-2,84,-7,minecraft:basalt)
B(-2,85,-7,minecraft:basalt)
B(-2,86,-7,minecraft:basalt)
B(-2,87,-7,minecraft:basalt)
B(-2,88,-7,minecraft:basalt)
B(-2,89,-7,minecraft:basalt)
B(-2,90,-7,minecraft:blackstone)
B(-2,69,-6,minecraft:basalt)
B(-2,70,-6,minecraft:basalt)
B(-2,71,-6,minecraft:basalt)
B(-2,72,-6,minecraft:basalt)
B(-2,73,-6,minecraft:basalt)
B(-2,74,-6,minecraft:basalt)
B(-2,75,-6,minecraft:basalt)
B(-2,76,-6,minecraft:basalt)
B(-2,77,-6,minecraft:basalt)
B(-2,78,-6,minecraft:basalt)
B(-2,79,-6,minecraft:basalt)
B(-2,80,-6,minecraft:basalt)
B(-2,81,-6,minecraft:basalt)
B(-2,82,-6,minecraft:basalt)
B(-2,83,-6,minecraft:basalt)
B(-2,84,-6,minecraft:basalt)
B(-2,85,-6,minecraft:basalt)
B(-2,86,-6,minecraft:basalt)
B(-2,87,-6,minecraft:basalt)
B(-2,88,-6,minecraft:basalt)
B(-2,89,-6,minecraft:basalt)
B(-2,90,-6,minecraft:basalt)
B(-2,71,-5,minecraft:basalt)
B(-2,72,-5,minecraft:basalt)
B(-2,73,-5,minecraft:basalt)
B(-2,74,-5,minecraft:basalt)
B(-2,75,-5,minecraft:basalt)
B(-2,76,-5,minecraft:basalt)
B(-2,77,-5,minecraft:basalt)
B(-2,78,-5,minecraft:basalt)
B(-2,79,-5,minecraft:basalt)
B(-2,80,-5,minecraft:basalt)
B(-2,81,-5,minecraft:basalt)
B(-2,82,-5,minecraft:basalt)
B(-2,83,-5,minecraft:basalt)
B(-2,84,-5,minecraft:basalt)
B(-2,85,-5,minecraft:basalt)
B(-2,86,-5,minecraft:basalt)
B(-2,87,-5,minecraft:basalt)
B(-2,88,-5,minecraft:basalt)
B(-2,89,-5,minecraft:basalt)
B(-2,90,-5,minecraft:basalt)
B(-2,81,-4,minecraft:basalt)
B(-2,82,-4,minecraft:basalt)
B(-2,83,-4,minecraft:basalt)
B(-2,84,-4,minecraft:basalt)
B(-2,85,-4,minecraft:basalt)
B(-2,86,-4,minecraft:basalt)
B(-2,87,-4,minecraft:basalt)
B(-2,88,-4,minecraft:basalt)
B(-2,89,-4,minecraft:basalt)
B(-2,90,-4,minecraft:basalt)
B(-2,88,-3,minecraft:basalt)
B(-2,89,-3,minecraft:basalt)
B(-2,90,-3,minecraft:basalt)
B(-2,90,-2,minecraft:basalt)
B(-2,90,-1,minecraft:basalt)
B(-2,90,0,minecraft:basalt)
B(-2,90,1,minecraft:basalt)
B(-2,89,2,minecraft:basalt)
B(-2,90,2,minecraft:blackstone)
B(-2,89,3,minecraft:basalt)
B(-2,90,3,minecraft:blackstone)
B(-1,61,-7,minecraft:basalt)
B(-1,62,-7,minecraft:basalt)
B(-1,63,-7,minecraft:basalt)
B(-1,64,-7,minecraft:basalt)
B(-1,65,-7,minecraft:basalt)
B(-1,66,-7,minecraft:basalt)
B(-1,67,-7,minecraft:basalt)
B(-1,68,-7,minecraft:basalt)
B(-1,69,-7,minecraft:basalt)
B(-1,70,-7,minecraft:basalt)
B(-1,71,-7,minecraft:basalt)
B(-1,72,-7,minecraft:basalt)
B(-1,73,-7,minecraft:basalt)
B(-1,74,-7,minecraft:basalt)
B(-1,75,-7,minecraft:basalt)
B(-1,76,-7,minecraft:basalt)
B(-1,77,-7,minecraft:basalt)
B(-1,78,-7,minecraft:basalt)
B(-1,79,-7,minecraft:basalt)
B(-1,80,-7,minecraft:basalt)
B(-1,81,-7,minecraft:basalt)
B(-1,82,-7,minecraft:basalt)
B(-1,83,-7,minecraft:basalt)
B(-1,84,-7,minecraft:basalt)
B(-1,85,-7,minecraft:basalt)
B(-1,86,-7,minecraft:basalt)
B(-1,87,-7,minecraft:basalt)
B(-1,88,-7,minecraft:basalt)
B(-1,89,-7,minecraft:basalt)
B(-1,90,-7,minecraft:blackstone)
B(-1,67,-6,minecraft:basalt)
B(-1,68,-6,minecraft:basalt)
B(-1,69,-6,minecraft:basalt)
B(-1,70,-6,minecraft:basalt)
B(-1,71,-6,minecraft:basalt)
B(-1,72,-6,minecraft:basalt)
B(-1,73,-6,minecraft:basalt)
B(-1,74,-6,minecraft:basalt)
B(-1,75,-6,minecraft:basalt)
B(-1,76,-6,minecraft:basalt)
B(-1,77,-6,minecraft:basalt)
B(-1,78,-6,minecraft:basalt)
B(-1,79,-6,minecraft:basalt)
B(-1,80,-6,minecraft:basalt)
B(-1,81,-6,minecraft:basalt)
B(-1,82,-6,minecraft:basalt)
B(-1,83,-6,minecraft:basalt)
B(-1,84,-6,minecraft:basalt)
B(-1,85,-6,minecraft:basalt)
B(-1,86,-6,minecraft:basalt)
B(-1,87,-6,minecraft:basalt)
B(-1,88,-6,minecraft:basalt)
B(-1,89,-6,minecraft:basalt)
B(-1,90,-6,minecraft:basalt)
B(-1,68,-5,minecraft:basalt)
B(-1,69,-5,minecraft:basalt)
B(-1,70,-5,minecraft:basalt)
B(-1,71,-5,minecraft:basalt)
B(-1,72,-5,minecraft:basalt)
B(-1,73,-5,minecraft:basalt)
B(-1,74,-5,minecraft:basalt)
B(-1,75,-5,minecraft:basalt)
B(-1,76,-5,minecraft:basalt)
B(-1,77,-5,minecraft:basalt)
B(-1,78,-5,minecraft:basalt)
B(-1,79,-5,minecraft:basalt)
B(-1,80,-5,minecraft:basalt)
B(-1,81,-5,minecraft:basalt)
B(-1,82,-5,minecraft:basalt)
B(-1,83,-5,minecraft:basalt)
B(-1,84,-5,minecraft:basalt)
B(-1,85,-5,minecraft:basalt)
B(-1,86,-5,minecraft:basalt)
B(-1,87,-5,minecraft:basalt)
B(-1,88,-5,minecraft:basalt)
B(-1,89,-5,minecraft:basalt)
B(-1,90,-5,minecraft:basalt)
B(-1,71,-4,minecraft:basalt)
B(-1,72,-4,minecraft:basalt)
B(-1,73,-4,minecraft:basalt)
B(-1,74,-4,minecraft:basalt)
B(-1,75,-4,minecraft:basalt)
B(-1,76,-4,minecraft:basalt)
B(-1,77,-4,minecraft:basalt)
B(-1,78,-4,minecraft:basalt)
B(-1,79,-4,minecraft:basalt)
B(-1,80,-4,minecraft:basalt)
B(-1,81,-4,minecraft:basalt)
B(-1,82,-4,minecraft:basalt)
B(-1,83,-4,minecraft:basalt)
B(-1,84,-4,minecraft:basalt)
B(-1,85,-4,minecraft:basalt)
B(-1,86,-4,minecraft:basalt)
B(-1,87,-4,minecraft:basalt)
B(-1,88,-4,minecraft:basalt)
B(-1,89,-4,minecraft:basalt)
B(-1,90,-4,minecraft:basalt)
B(-1,78,-3,minecraft:basalt)
B(-1,79,-3,minecraft:basalt)
B(-1,80,-3,minecraft:basalt)
B(-1,81,-3,minecraft:basalt)
B(-1,82,-3,minecraft:basalt)
B(-1,83,-3,minecraft:basalt)
B(-1,84,-3,minecraft:basalt)
B(-1,85,-3,minecraft:basalt)
B(-1,86,-3,minecraft:basalt)
B(-1,87,-3,minecraft:basalt)
B(-1,88,-3,minecraft:basalt)
B(-1,89,-3,minecraft:basalt)
B(-1,90,-3,minecraft:basalt)
B(-1,85,-2,minecraft:basalt)
B(-1,86,-2,minecraft:basalt)
B(-1,87,-2,minecraft:basalt)
B(-1,88,-2,minecraft:basalt)
B(-1,89,-2,minecraft:basalt)
B(-1,90,-2,minecraft:basalt)
B(-1,90,-1,minecraft:basalt)
B(-1,90,0,minecraft:basalt)
B(-1,89,1,minecraft:basalt)
B(-1,90,1,minecraft:blackstone)
B(-1,89,2,minecraft:basalt)
B(-1,90,2,minecraft:blackstone)
B(-1,89,3,minecraft:basalt)
B(-1,90,3,minecraft:blackstone)
B(0,57,-7,minecraft:basalt)
B(0,58,-7,minecraft:basalt)
B(0,59,-7,minecraft:basalt)
B(0,60,-7,minecraft:basalt)
B(0,61,-7,minecraft:basalt)
B(0,62,-7,minecraft:basalt)
B(0,63,-7,minecraft:basalt)
B(0,64,-7,minecraft:basalt)
B(0,65,-7,minecraft:basalt)
B(0,66,-7,minecraft:basalt)
B(0,67,-7,minecraft:basalt)
B(0,68,-7,minecraft:basalt)
B(0,69,-7,minecraft:basalt)
B(0,70,-7,minecraft:basalt)
B(0,71,-7,minecraft:basalt)
B(0,72,-7,minecraft:basalt)
B(0,73,-7,minecraft:basalt)
B(0,74,-7,minecraft:basalt)
B(0,75,-7,minecraft:basalt)
B(0,76,-7,minecraft:basalt)
B(0,77,-7,minecraft:basalt)
B(0,78,-7,minecraft:basalt)
B(0,79,-7,minecraft:basalt)
B(0,80,-7,minecraft:basalt)
B(0,81,-7,minecraft:basalt)
B(0,82,-7,minecraft:basalt)
B(0,83,-7,minecraft:basalt)
B(0,84,-7,minecraft:basalt)
B(0,85,-7,minecraft:basalt)
B(0,86,-7,minecraft:basalt)
B(0,87,-7,minecraft:basalt)
B(0,88,-7,minecraft:basalt)
B(0,89,-7,minecraft:basalt)
B(0,90,-7,minecraft:basalt)
B(0,61,-6,minecraft:basalt)
B(0,62,-6,minecraft:basalt)
B(0,63,-6,minecraft:basalt)
B(0,64,-6,minecraft:basalt)
B(0,65,-6,minecraft:basalt)
B(0,66,-6,minecraft:basalt)
B(0,67,-6,minecraft:basalt)
B(0,68,-6,minecraft:basalt)
B(0,69,-6,minecraft:basalt)
B(0,70,-6,minecraft:basalt)
B(0,71,-6,minecraft:basalt)
B(0,72,-6,minecraft:basalt)
B(0,73,-6,minecraft:basalt)
B(0,74,-6,minecraft:basalt)
B(0,75,-6,minecraft:basalt)
B(0,76,-6,minecraft:basalt)
B(0,77,-6,minecraft:basalt)
B(0,78,-6,minecraft:basalt)
B(0,79,-6,minecraft:basalt)
B(0,80,-6,minecraft:basalt)
B(0,81,-6,minecraft:basalt)
B(0,82,-6,minecraft:basalt)
B(0,83,-6,minecraft:basalt)
B(0,84,-6,minecraft:basalt)
B(0,85,-6,minecraft:basalt)
B(0,86,-6,minecraft:basalt)
B(0,87,-6,minecraft:basalt)
B(0,88,-6,minecraft:basalt)
B(0,89,-6,minecraft:basalt)
B(0,90,-6,minecraft:basalt)
B(0,66,-5,minecraft:basalt)
B(0,67,-5,minecraft:basalt)
B(0,68,-5,minecraft:basalt)
B(0,69,-5,minecraft:basalt)
B(0,70,-5,minecraft:basalt)
B(0,71,-5,minecraft:basalt)
B(0,72,-5,minecraft:basalt)
B(0,73,-5,minecraft:basalt)
B(0,74,-5,minecraft:basalt)
B(0,75,-5,minecraft:basalt)
B(0,76,-5,minecraft:basalt)
B(0,77,-5,minecraft:basalt)
B(0,78,-5,minecraft:basalt)
B(0,79,-5,minecraft:basalt)
B(0,80,-5,minecraft:basalt)
B(0,81,-5,minecraft:basalt)
B(0,82,-5,minecraft:basalt)
B(0,83,-5,minecraft:basalt)
B(0,84,-5,minecraft:basalt)
B(0,85,-5,minecraft:basalt)
B(0,86,-5,minecraft:basalt)
B(0,87,-5,minecraft:basalt)
B(0,88,-5,minecraft:basalt)
B(0,89,-5,minecraft:basalt)
B(0,90,-5,minecraft:basalt)
B(0,67,-4,minecraft:basalt)
B(0,68,-4,minecraft:basalt)
B(0,69,-4,minecraft:basalt)
B(0,70,-4,minecraft:basalt)
B(0,71,-4,minecraft:basalt)
B(0,72,-4,minecraft:basalt)
B(0,73,-4,minecraft:basalt)
B(0,74,-4,minecraft:basalt)
B(0,75,-4,minecraft:basalt)
B(0,76,-4,minecraft:basalt)
B(0,77,-4,minecraft:basalt)
B(0,78,-4,minecraft:basalt)
B(0,79,-4,minecraft:basalt)
B(0,80,-4,minecraft:basalt)
B(0,81,-4,minecraft:basalt)
B(0,82,-4,minecraft:basalt)
B(0,83,-4,minecraft:basalt)
B(0,84,-4,minecraft:basalt)
B(0,85,-4,minecraft:basalt)
B(0,86,-4,minecraft:basalt)
B(0,87,-4,minecraft:basalt)
B(0,88,-4,minecraft:basalt)
B(0,89,-4,minecraft:basalt)
B(0,90,-4,minecraft:basalt)
B(0,71,-3,minecraft:basalt)
B(0,72,-3,minecraft:basalt)
B(0,73,-3,minecraft:basalt)
B(0,74,-3,minecraft:basalt)
B(0,75,-3,minecraft:basalt)
B(0,76,-3,minecraft:basalt)
B(0,77,-3,minecraft:basalt)
B(0,78,-3,minecraft:basalt)
B(0,79,-3,minecraft:basalt)
B(0,80,-3,minecraft:basalt)
B(0,81,-3,minecraft:basalt)
B(0,82,-3,minecraft:basalt)
B(0,83,-3,minecraft:basalt)
B(0,84,-3,minecraft:basalt)
B(0,85,-3,minecraft:basalt)
B(0,86,-3,minecraft:basalt)
B(0,87,-3,minecraft:basalt)
B(0,88,-3,minecraft:basalt)
B(0,89,-3,minecraft:basalt)
B(0,90,-3,minecraft:basalt)
B(0,80,-2,minecraft:basalt)
B(0,81,-2,minecraft:basalt)
B(0,82,-2,minecraft:basalt)
B(0,83,-2,minecraft:basalt)
B(0,84,-2,minecraft:basalt)
B(0,85,-2,minecraft:basalt)
B(0,86,-2,minecraft:basalt)
B(0,87,-2,minecraft:basalt)
B(0,88,-2,minecraft:basalt)
B(0,89,-2,minecraft:basalt)
B(0,90,-2,minecraft:basalt)
B(0,85,-1,minecraft:basalt)
B(0,86,-1,minecraft:basalt)
B(0,87,-1,minecraft:basalt)
B(0,88,-1,minecraft:basalt)
B(0,89,-1,minecraft:basalt)
B(0,90,-1,minecraft:basalt)
B(0,89,0,minecraft:basalt)
B(0,90,0,minecraft:blackstone)
B(0,89,1,minecraft:basalt)
B(0,90,1,minecraft:blackstone)
B(0,89,2,minecraft:basalt)
B(0,90,2,minecraft:blackstone)
B(0,89,3,minecraft:basalt)
B(0,90,3,minecraft:blackstone)
B(1,41,-7,minecraft:basalt)
B(1,42,-7,minecraft:basalt)
B(1,43,-7,minecraft:basalt)
B(1,44,-7,minecraft:basalt)
B(1,45,-7,minecraft:basalt)
B(1,46,-7,minecraft:basalt)
B(1,47,-7,minecraft:basalt)
B(1,48,-7,minecraft:basalt)
B(1,49,-7,minecraft:basalt)
B(1,50,-7,minecraft:basalt)
B(1,51,-7,minecraft:basalt)
B(1,52,-7,minecraft:basalt)
B(1,53,-7,minecraft:basalt)
B(1,54,-7,minecraft:basalt)
B(1,55,-7,minecraft:basalt)
B(1,56,-7,minecraft:basalt)
B(1,57,-7,minecraft:basalt)
B(1,58,-7,minecraft:basalt)
B(1,59,-7,minecraft:basalt)
B(1,60,-7,minecraft:basalt)
B(1,61,-7,minecraft:basalt)
B(1,62,-7,minecraft:basalt)
B(1,63,-7,minecraft:basalt)
B(1,64,-7,minecraft:basalt)
B(1,65,-7,minecraft:basalt)
B(1,66,-7,minecraft:basalt)
B(1,67,-7,minecraft:basalt)
B(1,68,-7,minecraft:basalt)
B(1,69,-7,minecraft:basalt)
B(1,70,-7,minecraft:basalt)
B(1,71,-7,minecraft:basalt)
B(1,72,-7,minecraft:basalt)
B(1,73,-7,minecraft:basalt)
B(1,74,-7,minecraft:basalt)
B(1,75,-7,minecraft:basalt)
B(1,76,-7,minecraft:basalt)
B(1,77,-7,minecraft:basalt)
B(1,78,-7,minecraft:basalt)
B(1,79,-7,minecraft:basalt)
B(1,80,-7,minecraft:basalt)
B(1,81,-7,minecraft:basalt)
B(1,82,-7,minecraft:basalt)
B(1,83,-7,minecraft:basalt)
B(1,84,-7,minecraft:basalt)
B(1,85,-7,minecraft:basalt)
B(1,86,-7,minecraft:basalt)
B(1,87,-7,minecraft:basalt)
B(1,88,-7,minecraft:basalt)
B(1,89,-7,minecraft:basalt)
B(1,90,-7,minecraft:basalt)
B(1,60,-6,minecraft:basalt)
B(1,61,-6,minecraft:basalt)
B(1,62,-6,minecraft:basalt)
B(1,63,-6,minecraft:basalt)
B(1,64,-6,minecraft:basalt)
B(1,65,-6,minecraft:basalt)
B(1,66,-6,minecraft:basalt)
B(1,67,-6,minecraft:basalt)
B(1,68,-6,minecraft:basalt)
B(1,69,-6,minecraft:basalt)
B(1,70,-6,minecraft:basalt)
B(1,71,-6,minecraft:basalt)
B(1,72,-6,minecraft:basalt)
B(1,73,-6,minecraft:basalt)
B(1,74,-6,minecraft:basalt)
B(1,75,-6,minecraft:basalt)
B(1,76,-6,minecraft:basalt)
B(1,77,-6,minecraft:basalt)
B(1,78,-6,minecraft:basalt)
B(1,79,-6,minecraft:basalt)
B(1,80,-6,minecraft:basalt)
B(1,81,-6,minecraft:basalt)
B(1,82,-6,minecraft:basalt)
B(1,83,-6,minecraft:basalt)
B(1,84,-6,minecraft:basalt)
B(1,85,-6,minecraft:basalt)
B(1,86,-6,minecraft:basalt)
B(1,87,-6,minecraft:basalt)
B(1,88,-6,minecraft:basalt)
B(1,89,-6,minecraft:basalt)
B(1,90,-6,minecraft:basalt)
B(1,63,-5,minecraft:basalt)
B(1,64,-5,minecraft:basalt)
B(1,65,-5,minecraft:basalt)
B(1,66,-5,minecraft:basalt)
B(1,67,-5,minecraft:basalt)
B(1,68,-5,minecraft:basalt)
B(1,69,-5,minecraft:basalt)
B(1,70,-5,minecraft:basalt)
B(1,71,-5,minecraft:basalt)
B(1,72,-5,minecraft:basalt)
B(1,73,-5,minecraft:basalt)
B(1,74,-5,minecraft:basalt)
B(1,75,-5,minecraft:basalt)
B(1,76,-5,minecraft:basalt)
B(1,77,-5,minecraft:basalt)
B(1,78,-5,minecraft:basalt)
B(1,79,-5,minecraft:basalt)
B(1,80,-5,minecraft:basalt)
B(1,81,-5,minecraft:basalt)
B(1,82,-5,minecraft:basalt)
B(1,83,-5,minecraft:basalt)
B(1,84,-5,minecraft:basalt)
B(1,85,-5,minecraft:basalt)
B(1,86,-5,minecraft:basalt)
B(1,87,-5,minecraft:basalt)
B(1,88,-5,minecraft:basalt)
B(1,89,-5,minecraft:basalt)
B(1,90,-5,minecraft:basalt)
B(1,67,-4,minecraft:basalt)
B(1,68,-4,minecraft:basalt)
B(1,69,-4,minecraft:basalt)
B(1,70,-4,minecraft:basalt)
B(1,71,-4,minecraft:basalt)
B(1,72,-4,minecraft:basalt)
B(1,73,-4,minecraft:basalt)
B(1,74,-4,minecraft:basalt)
B(1,75,-4,minecraft:basalt)
B(1,76,-4,minecraft:basalt)
B(1,77,-4,minecraft:basalt)
B(1,78,-4,minecraft:basalt)
B(1,79,-4,minecraft:basalt)
B(1,80,-4,minecraft:basalt)
B(1,81,-4,minecraft:basalt)
B(1,82,-4,minecraft:basalt)
B(1,83,-4,minecraft:basalt)
B(1,84,-4,minecraft:basalt)
B(1,85,-4,minecraft:basalt)
B(1,86,-4,minecraft:basalt)
B(1,87,-4,minecraft:basalt)
B(1,88,-4,minecraft:basalt)
B(1,89,-4,minecraft:basalt)
B(1,90,-4,minecraft:basalt)
B(1,71,-3,minecraft:basalt)
B(1,72,-3,minecraft:basalt)
B(1,73,-3,minecraft:basalt)
B(1,74,-3,minecraft:basalt)
B(1,75,-3,minecraft:basalt)
B(1,76,-3,minecraft:basalt)
B(1,77,-3,minecraft:basalt)
B(1,78,-3,minecraft:basalt)
B(1,79,-3,minecraft:basalt)
B(1,80,-3,minecraft:basalt)
B(1,81,-3,minecraft:basalt)
B(1,82,-3,minecraft:basalt)
B(1,83,-3,minecraft:basalt)
B(1,84,-3,minecraft:basalt)
B(1,85,-3,minecraft:basalt)
B(1,86,-3,minecraft:basalt)
B(1,87,-3,minecraft:basalt)
B(1,88,-3,minecraft:basalt)
B(1,89,-3,minecraft:basalt)
B(1,90,-3,minecraft:basalt)
B(1,73,-2,minecraft:basalt)
B(1,74,-2,minecraft:basalt)
B(1,75,-2,minecraft:basalt)
B(1,76,-2,minecraft:basalt)
B(1,77,-2,minecraft:basalt)
B(1,78,-2,minecraft:basalt)
B(1,79,-2,minecraft:basalt)
B(1,80,-2,minecraft:basalt)
B(1,81,-2,minecraft:basalt)
B(1,82,-2,minecraft:basalt)
B(1,83,-2,minecraft:basalt)
B(1,84,-2,minecraft:basalt)
B(1,85,-2,minecraft:basalt)
B(1,86,-2,minecraft:basalt)
B(1,87,-2,minecraft:basalt)
B(1,88,-2,minecraft:basalt)
B(1,89,-2,minecraft:basalt)
B(1,90,-2,minecraft:basalt)
B(1,82,-1,minecraft:basalt)
B(1,83,-1,minecraft:basalt)
B(1,84,-1,minecraft:basalt)
B(1,85,-1,minecraft:basalt)
B(1,86,-1,minecraft:basalt)
B(1,87,-1,minecraft:basalt)
B(1,88,-1,minecraft:basalt)
B(1,89,-1,minecraft:basalt)
B(1,90,-1,minecraft:blackstone)
B(1,86,0,minecraft:basalt)
B(1,87,0,minecraft:basalt)
B(1,88,0,minecraft:basalt)
B(1,89,0,minecraft:basalt)
B(1,90,0,minecraft:blackstone)
B(1,89,1,minecraft:basalt)
B(1,90,1,minecraft:blackstone)
B(1,89,2,minecraft:basalt)
B(1,90,2,minecraft:blackstone)
B(1,88,3,minecraft:basalt)
B(1,89,3,minecraft:blackstone)
B(1,90,3,minecraft:blackstone)
B(2,35,-7,minecraft:basalt)
B(2,36,-7,minecraft:basalt)
B(2,37,-7,minecraft:basalt)
B(2,38,-7,minecraft:basalt)
B(2,39,-7,minecraft:basalt)
B(2,40,-7,minecraft:basalt)
B(2,41,-7,minecraft:basalt)
B(2,42,-7,minecraft:basalt)
B(2,43,-7,minecraft:basalt)
B(2,44,-7,minecraft:basalt)
B(2,45,-7,minecraft:basalt)
B(2,46,-7,minecraft:basalt)
B(2,47,-7,minecraft:basalt)
B(2,48,-7,minecraft:basalt)
B(2,49,-7,minecraft:basalt)
B(2,50,-7,minecraft:basalt)
B(2,51,-7,minecraft:basalt)
B(2,52,-7,minecraft:basalt)
B(2,53,-7,minecraft:basalt)
B(2,54,-7,minecraft:basalt)
B(2,55,-7,minecraft:basalt)
B(2,56,-7,minecraft:basalt)
B(2,57,-7,minecraft:basalt)
B(2,58,-7,minecraft:basalt)
B(2,59,-7,minecraft:basalt)
B(2,60,-7,minecraft:basalt)
B(2,61,-7,minecraft:basalt)
B(2,62,-7,minecraft:basalt)
B(2,63,-7,minecraft:basalt)
B(2,64,-7,minecraft:basalt)
B(2,65,-7,minecraft:basalt)
B(2,66,-7,minecraft:basalt)
B(2,67,-7,minecraft:basalt)
B(2,68,-7,minecraft:basalt)
B(2,69,-7,minecraft:basalt)
B(2,70,-7,minecraft:basalt)
B(2,71,-7,minecraft:basalt)
B(2,72,-7,minecraft:basalt)
B(2,73,-7,minecraft:basalt)
B(2,74,-7,minecraft:basalt)
B(2,75,-7,minecraft:basalt)
B(2,76,-7,minecraft:basalt)
B(2,77,-7,minecraft:basalt)
B(2,78,-7,minecraft:basalt)
B(2,79,-7,minecraft:basalt)
B(2,80,-7,minecraft:basalt)
B(2,81,-7,minecraft:basalt)
B(2,82,-7,minecraft:basalt)
B(2,83,-7,minecraft:basalt)
B(2,84,-7,minecraft:basalt)
B(2,85,-7,minecraft:basalt)
B(2,86,-7,minecraft:basalt)
B(2,87,-7,minecraft:basalt)
B(2,88,-7,minecraft:basalt)
B(2,89,-7,minecraft:basalt)
B(2,90,-7,minecraft:basalt)
B(2,54,-6,minecraft:basalt)
B(2,55,-6,minecraft:basalt)
B(2,56,-6,minecraft:basalt)
B(2,57,-6,minecraft:basalt)
B(2,58,-6,minecraft:basalt)
B(2,59,-6,minecraft:basalt)
B(2,60,-6,minecraft:basalt)
B(2,61,-6,minecraft:basalt)
B(2,62,-6,minecraft:basalt)
B(2,63,-6,minecraft:basalt)
B(2,64,-6,minecraft:basalt)
B(2,65,-6,minecraft:basalt)
B(2,66,-6,minecraft:basalt)
B(2,67,-6,minecraft:basalt)
B(2,68,-6,minecraft:basalt)
B(2,69,-6,minecraft:basalt)
B(2,70,-6,minecraft:basalt)
B(2,71,-6,minecraft:basalt)
B(2,72,-6,minecraft:basalt)
B(2,73,-6,minecraft:basalt)
B(2,74,-6,minecraft:basalt)
B(2,75,-6,minecraft:basalt)
B(2,76,-6,minecraft:basalt)
B(2,77,-6,minecraft:basalt)
B(2,78,-6,minecraft:basalt)
B(2,79,-6,minecraft:basalt)
B(2,80,-6,minecraft:basalt)
B(2,81,-6,minecraft:basalt)
B(2,82,-6,minecraft:basalt)
B(2,83,-6,minecraft:basalt)
B(2,84,-6,minecraft:basalt)
B(2,85,-6,minecraft:basalt)
B(2,86,-6,minecraft:basalt)
B(2,87,-6,minecraft:basalt)
B(2,88,-6,minecraft:basalt)
B(2,89,-6,minecraft:basalt)
B(2,90,-6,minecraft:basalt)
B(2,61,-5,minecraft:basalt)
B(2,62,-5,minecraft:basalt)
B(2,63,-5,minecraft:basalt)
B(2,64,-5,minecraft:basalt)
B(2,65,-5,minecraft:basalt)
B(2,66,-5,minecraft:basalt)
B(2,67,-5,minecraft:basalt)
B(2,68,-5,minecraft:basalt)
B(2,69,-5,minecraft:basalt)
B(2,70,-5,minecraft:basalt)
B(2,71,-5,minecraft:basalt)
B(2,72,-5,minecraft:basalt)
B(2,73,-5,minecraft:basalt)
B(2,74,-5,minecraft:basalt)
B(2,75,-5,minecraft:basalt)
B(2,76,-5,minecraft:basalt)
B(2,77,-5,minecraft:basalt)
B(2,78,-5,minecraft:basalt)
B(2,79,-5,minecraft:basalt)
B(2,80,-5,minecraft:basalt)
B(2,81,-5,minecraft:basalt)
B(2,82,-5,minecraft:basalt)
B(2,83,-5,minecraft:basalt)
B(2,84,-5,minecraft:basalt)
B(2,85,-5,minecraft:basalt)
B(2,86,-5,minecraft:basalt)
B(2,87,-5,minecraft:basalt)
B(2,88,-5,minecraft:basalt)
B(2,89,-5,minecraft:basalt)
B(2,90,-5,minecraft:basalt)
B(2,67,-4,minecraft:basalt)
B(2,68,-4,minecraft:basalt)
B(2,69,-4,minecraft:basalt)
B(2,70,-4,minecraft:basalt)
B(2,71,-4,minecraft:basalt)
B(2,72,-4,minecraft:basalt)
B(2,73,-4,minecraft:basalt)
B(2,74,-4,minecraft:basalt)
B(2,75,-4,minecraft:basalt)
B(2,76,-4,minecraft:basalt)
B(2,77,-4,minecraft:basalt)
B(2,78,-4,minecraft:basalt)
B(2,79,-4,minecraft:basalt)
B(2,80,-4,minecraft:basalt)
B(2,81,-4,minecraft:basalt)
B(2,82,-4,minecraft:basalt)
B(2,83,-4,minecraft:basalt)
B(2,84,-4,minecraft:basalt)
B(2,85,-4,minecraft:basalt)
B(2,86,-4,minecraft:basalt)
B(2,87,-4,minecraft:basalt)
B(2,88,-4,minecraft:basalt)
B(2,89,-4,minecraft:basalt)
B(2,90,-4,minecraft:basalt)
B(2,71,-3,minecraft:basalt)
B(2,72,-3,minecraft:basalt)
B(2,73,-3,minecraft:basalt)
B(2,74,-3,minecraft:basalt)
B(2,75,-3,minecraft:basalt)
B(2,76,-3,minecraft:basalt)
B(2,77,-3,minecraft:basalt)
B(2,78,-3,minecraft:basalt)
B(2,79,-3,minecraft:basalt)
B(2,80,-3,minecraft:basalt)
B(2,81,-3,minecraft:basalt)
B(2,82,-3,minecraft:basalt)
B(2,83,-3,minecraft:basalt)
B(2,84,-3,minecraft:basalt)
B(2,85,-3,minecraft:basalt)
B(2,86,-3,minecraft:basalt)
B(2,87,-3,minecraft:basalt)
B(2,88,-3,minecraft:basalt)
B(2,89,-3,minecraft:basalt)
B(2,90,-3,minecraft:basalt)
B(2,72,-2,minecraft:basalt)
B(2,73,-2,minecraft:basalt)
B(2,74,-2,minecraft:basalt)
B(2,75,-2,minecraft:basalt)
B(2,76,-2,minecraft:basalt)
B(2,77,-2,minecraft:basalt)
B(2,78,-2,minecraft:basalt)
B(2,79,-2,minecraft:basalt)
B(2,80,-2,minecraft:basalt)
B(2,81,-2,minecraft:basalt)
B(2,82,-2,minecraft:basalt)
B(2,83,-2,minecraft:basalt)
B(2,84,-2,minecraft:basalt)
B(2,85,-2,minecraft:basalt)
B(2,86,-2,minecraft:basalt)
B(2,87,-2,minecraft:basalt)
B(2,88,-2,minecraft:basalt)
B(2,89,-2,minecraft:basalt)
B(2,90,-2,minecraft:basalt)
B(2,81,-1,minecraft:basalt)
B(2,82,-1,minecraft:basalt)
B(2,83,-1,minecraft:basalt)
B(2,84,-1,minecraft:basalt)
B(2,85,-1,minecraft:basalt)
B(2,86,-1,minecraft:basalt)
B(2,87,-1,minecraft:basalt)
B(2,88,-1,minecraft:basalt)
B(2,89,-1,minecraft:basalt)
B(2,90,-1,minecraft:basalt)
B(2,84,0,minecraft:basalt)
B(2,85,0,minecraft:basalt)
B(2,86,0,minecraft:basalt)
B(2,87,0,minecraft:basalt)
B(2,88,0,minecraft:basalt)
B(2,89,0,minecraft:basalt)
B(2,90,0,minecraft:blackstone)
B(2,89,1,minecraft:basalt)
B(2,90,1,minecraft:blackstone)
B(2,89,2,minecraft:basalt)
B(2,90,2,minecraft:blackstone)
B(2,88,3,minecraft:basalt)
B(2,89,3,minecraft:blackstone)
B(2,90,3,minecraft:blackstone)
B(3,35,-7,minecraft:basalt)
B(3,36,-7,minecraft:basalt)
B(3,37,-7,minecraft:basalt)
B(3,38,-7,minecraft:basalt)
B(3,39,-7,minecraft:basalt)
B(3,40,-7,minecraft:basalt)
B(3,41,-7,minecraft:basalt)
B(3,42,-7,minecraft:basalt)
B(3,43,-7,minecraft:basalt)
B(3,44,-7,minecraft:basalt)
B(3,45,-7,minecraft:basalt)
B(3,46,-7,minecraft:basalt)
B(3,47,-7,minecraft:basalt)
B(3,48,-7,minecraft:basalt)
B(3,49,-7,minecraft:basalt)
B(3,50,-7,minecraft:basalt)
B(3,51,-7,minecraft:basalt)
B(3,52,-7,minecraft:basalt)
B(3,53,-7,minecraft:basalt)
B(3,54,-7,minecraft:basalt)
B(3,55,-7,minecraft:basalt)
B(3,56,-7,minecraft:basalt)
B(3,57,-7,minecraft:basalt)
B(3,58,-7,minecraft:basalt)
B(3,59,-7,minecraft:basalt)
B(3,60,-7,minecraft:basalt)
B(3,61,-7,minecraft:basalt)
B(3,62,-7,minecraft:basalt)
B(3,63,-7,minecraft:basalt)
B(3,64,-7,minecraft:basalt)
B(3,65,-7,minecraft:basalt)
B(3,66,-7,minecraft:basalt)
B(3,67,-7,minecraft:basalt)
B(3,68,-7,minecraft:basalt)
B(3,69,-7,minecraft:basalt)
B(3,70,-7,minecraft:basalt)
B(3,71,-7,minecraft:basalt)
B(3,72,-7,minecraft:basalt)
B(3,73,-7,minecraft:basalt)
B(3,74,-7,minecraft:basalt)
B(3,75,-7,minecraft:basalt)
B(3,76,-7,minecraft:basalt)
B(3,77,-7,minecraft:basalt)
B(3,78,-7,minecraft:basalt)
B(3,79,-7,minecraft:basalt)
B(3,80,-7,minecraft:basalt)
B(3,81,-7,minecraft:basalt)
B(3,82,-7,minecraft:basalt)
B(3,83,-7,minecraft:basalt)
B(3,84,-7,minecraft:basalt)
B(3,85,-7,minecraft:basalt)
B(3,86,-7,minecraft:basalt)
B(3,87,-7,minecraft:basalt)
B(3,88,-7,minecraft:basalt)
B(3,89,-7,minecraft:basalt)
B(3,90,-7,minecraft:basalt)
B(3,50,-6,minecraft:basalt)
B(3,51,-6,minecraft:basalt)
B(3,52,-6,minecraft:basalt)
B(3,53,-6,minecraft:basalt)
B(3,54,-6,minecraft:basalt)
B(3,55,-6,minecraft:basalt)
B(3,56,-6,minecraft:basalt)
B(3,57,-6,minecraft:basalt)
B(3,58,-6,minecraft:basalt)
B(3,59,-6,minecraft:basalt)
B(3,60,-6,minecraft:basalt)
B(3,61,-6,minecraft:basalt)
B(3,62,-6,minecraft:basalt)
B(3,63,-6,minecraft:basalt)
B(3,64,-6,minecraft:basalt)
B(3,65,-6,minecraft:basalt)
B(3,66,-6,minecraft:basalt)
B(3,67,-6,minecraft:basalt)
B(3,68,-6,minecraft:basalt)
B(3,69,-6,minecraft:basalt)
B(3,70,-6,minecraft:basalt)
B(3,71,-6,minecraft:basalt)
B(3,72,-6,minecraft:basalt)
B(3,73,-6,minecraft:basalt)
B(3,74,-6,minecraft:basalt)
B(3,75,-6,minecraft:basalt)
B(3,76,-6,minecraft:basalt)
B(3,77,-6,minecraft:basalt)
B(3,78,-6,minecraft:basalt)
B(3,79,-6,minecraft:basalt)
B(3,80,-6,minecraft:basalt)
B(3,81,-6,minecraft:basalt)
B(3,82,-6,minecraft:basalt)
B(3,83,-6,minecraft:basalt)
B(3,84,-6,minecraft:basalt)
B(3,85,-6,minecraft:basalt)
B(3,86,-6,minecraft:basalt)
B(3,87,-6,minecraft:basalt)
B(3,88,-6,minecraft:basalt)
B(3,89,-6,minecraft:basalt)
B(3,90,-6,minecraft:basalt)
B(3,61,-5,minecraft:basalt)
B(3,62,-5,minecraft:basalt)
B(3,63,-5,minecraft:basalt)
B(3,64,-5,minecraft:basalt)
B(3,65,-5,minecraft:basalt)
B(3,66,-5,minecraft:basalt)
B(3,67,-5,minecraft:basalt)
B(3,68,-5,minecraft:basalt)
B(3,69,-5,minecraft:basalt)
B(3,70,-5,minecraft:basalt)
B(3,71,-5,minecraft:basalt)
B(3,72,-5,minecraft:basalt)
B(3,73,-5,minecraft:basalt)
B(3,74,-5,minecraft:basalt)
B(3,75,-5,minecraft:basalt)
B(3,76,-5,minecraft:basalt)
B(3,77,-5,minecraft:basalt)
B(3,78,-5,minecraft:basalt)
B(3,79,-5,minecraft:basalt)
B(3,80,-5,minecraft:basalt)
B(3,81,-5,minecraft:basalt)
B(3,82,-5,minecraft:basalt)
B(3,83,-5,minecraft:basalt)
B(3,84,-5,minecraft:basalt)
B(3,85,-5,minecraft:basalt)
B(3,86,-5,minecraft:basalt)
B(3,87,-5,minecraft:basalt)
B(3,88,-5,minecraft:basalt)
B(3,89,-5,minecraft:basalt)
B(3,90,-5,minecraft:basalt)
B(3,68,-4,minecraft:basalt)
B(3,69,-4,minecraft:basalt)
B(3,70,-4,minecraft:basalt)
B(3,71,-4,minecraft:basalt)
B(3,72,-4,minecraft:basalt)
B(3,73,-4,minecraft:basalt)
B(3,74,-4,minecraft:basalt)
B(3,75,-4,minecraft:basalt)
B(3,76,-4,minecraft:basalt)
B(3,77,-4,minecraft:basalt)
B(3,78,-4,minecraft:basalt)
B(3,79,-4,minecraft:basalt)
B(3,80,-4,minecraft:basalt)
B(3,81,-4,minecraft:basalt)
B(3,82,-4,minecraft:basalt)
B(3,83,-4,minecraft:basalt)
B(3,84,-4,minecraft:basalt)
B(3,85,-4,minecraft:basalt)
B(3,86,-4,minecraft:basalt)
B(3,87,-4,minecraft:basalt)
B(3,88,-4,minecraft:basalt)
B(3,89,-4,minecraft:basalt)
B(3,90,-4,minecraft:basalt)
B(3,71,-3,minecraft:basalt)
B(3,72,-3,minecraft:basalt)
B(3,73,-3,minecraft:basalt)
B(3,74,-3,minecraft:basalt)
B(3,75,-3,minecraft:basalt)
B(3,76,-3,minecraft:basalt)
B(3,77,-3,minecraft:basalt)
B(3,78,-3,minecraft:basalt)
B(3,79,-3,minecraft:basalt)
B(3,80,-3,minecraft:basalt)
B(3,81,-3,minecraft:basalt)
B(3,82,-3,minecraft:basalt)
B(3,83,-3,minecraft:basalt)
B(3,84,-3,minecraft:basalt)
B(3,85,-3,minecraft:basalt)
B(3,86,-3,minecraft:basalt)
B(3,87,-3,minecraft:basalt)
B(3,88,-3,minecraft:basalt)
B(3,89,-3,minecraft:basalt)
B(3,90,-3,minecraft:basalt)
B(3,72,-2,minecraft:basalt)
B(3,73,-2,minecraft:basalt)
B(3,74,-2,minecraft:basalt)
B(3,75,-2,minecraft:basalt)
B(3,76,-2,minecraft:basalt)
B(3,77,-2,minecraft:basalt)
B(3,78,-2,minecraft:basalt)
B(3,79,-2,minecraft:basalt)
B(3,80,-2,minecraft:basalt)
B(3,81,-2,minecraft:basalt)
B(3,82,-2,minecraft:basalt)
B(3,83,-2,minecraft:basalt)
B(3,84,-2,minecraft:basalt)
B(3,85,-2,minecraft:basalt)
B(3,86,-2,minecraft:basalt)
B(3,87,-2,minecraft:basalt)
B(3,88,-2,minecraft:basalt)
B(3,89,-2,minecraft:basalt)
B(3,90,-2,minecraft:basalt)
B(3,81,-1,minecraft:basalt)
B(3,82,-1,minecraft:basalt)
B(3,83,-1,minecraft:basalt)
B(3,84,-1,minecraft:basalt)
B(3,85,-1,minecraft:basalt)
B(3,86,-1,minecraft:basalt)
B(3,87,-1,minecraft:basalt)
B(3,88,-1,minecraft:basalt)
B(3,89,-1,minecraft:basalt)
B(3,90,-1,minecraft:basalt)
B(3,83,0,minecraft:basalt)
B(3,84,0,minecraft:basalt)
B(3,85,0,minecraft:basalt)
B(3,86,0,minecraft:basalt)
B(3,87,0,minecraft:basalt)
B(3,88,0,minecraft:basalt)
B(3,89,0,minecraft:basalt)
B(3,90,0,minecraft:basalt)
B(3,89,1,minecraft:basalt)
B(3,90,1,minecraft:blackstone)
B(3,89,2,minecraft:basalt)
B(3,90,2,minecraft:blackstone)
B(3,88,3,minecraft:basalt)
B(3,89,3,minecraft:blackstone)
B(3,90,3,minecraft:blackstone)
B(4,36,-7,minecraft:basalt)
B(4,37,-7,minecraft:basalt)
B(4,38,-7,minecraft:basalt)
B(4,39,-7,minecraft:basalt)
B(4,40,-7,minecraft:basalt)
B(4,41,-7,minecraft:basalt)
B(4,42,-7,minecraft:basalt)
B(4,43,-7,minecraft:basalt)
B(4,44,-7,minecraft:basalt)
B(4,45,-7,minecraft:basalt)
B(4,46,-7,minecraft:basalt)
B(4,47,-7,minecraft:basalt)
B(4,48,-7,minecraft:basalt)
B(4,49,-7,minecraft:basalt)
B(4,50,-7,minecraft:basalt)
B(4,51,-7,minecraft:basalt)
B(4,52,-7,minecraft:basalt)
B(4,53,-7,minecraft:basalt)
B(4,54,-7,minecraft:basalt)
B(4,55,-7,minecraft:basalt)
B(4,56,-7,minecraft:basalt)
B(4,57,-7,minecraft:basalt)
B(4,58,-7,minecraft:basalt)
B(4,59,-7,minecraft:basalt)
B(4,60,-7,minecraft:basalt)
B(4,61,-7,minecraft:basalt)
B(4,62,-7,minecraft:basalt)
B(4,63,-7,minecraft:basalt)
B(4,64,-7,minecraft:basalt)
B(4,65,-7,minecraft:basalt)
B(4,66,-7,minecraft:basalt)
B(4,67,-7,minecraft:basalt)
B(4,68,-7,minecraft:basalt)
B(4,69,-7,minecraft:basalt)
B(4,70,-7,minecraft:basalt)
B(4,71,-7,minecraft:basalt)
B(4,72,-7,minecraft:basalt)
B(4,73,-7,minecraft:basalt)
B(4,74,-7,minecraft:basalt)
B(4,75,-7,minecraft:basalt)
B(4,76,-7,minecraft:basalt)
B(4,77,-7,minecraft:basalt)
B(4,78,-7,minecraft:basalt)
B(4,79,-7,minecraft:basalt)
B(4,80,-7,minecraft:basalt)
B(4,81,-7,minecraft:basalt)
B(4,82,-7,minecraft:basalt)
B(4,83,-7,minecraft:basalt)
B(4,84,-7,minecraft:basalt)
B(4,85,-7,minecraft:basalt)
B(4,86,-7,minecraft:basalt)
B(4,87,-7,minecraft:basalt)
B(4,88,-7,minecraft:basalt)
B(4,89,-7,minecraft:basalt)
B(4,90,-7,minecraft:basalt)
B(4,50,-6,minecraft:basalt)
B(4,51,-6,minecraft:basalt)
B(4,52,-6,minecraft:basalt)
B(4,53,-6,minecraft:basalt)
B(4,54,-6,minecraft:basalt)
B(4,55,-6,minecraft:basalt)
B(4,56,-6,minecraft:basalt)
B(4,57,-6,minecraft:basalt)
B(4,58,-6,minecraft:basalt)
B(4,59,-6,minecraft:basalt)
B(4,60,-6,minecraft:basalt)
B(4,61,-6,minecraft:basalt)
B(4,62,-6,minecraft:basalt)
B(4,63,-6,minecraft:basalt)
B(4,64,-6,minecraft:basalt)
B(4,65,-6,minecraft:basalt)
B(4,66,-6,minecraft:basalt)
B(4,67,-6,minecraft:basalt)
B(4,68,-6,minecraft:basalt)
B(4,69,-6,minecraft:basalt)
B(4,70,-6,minecraft:basalt)
B(4,71,-6,minecraft:basalt)
B(4,72,-6,minecraft:basalt)
B(4,73,-6,minecraft:basalt)
B(4,74,-6,minecraft:basalt)
B(4,75,-6,minecraft:basalt)
B(4,76,-6,minecraft:basalt)
B(4,77,-6,minecraft:basalt)
B(4,78,-6,minecraft:basalt)
B(4,79,-6,minecraft:basalt)
B(4,80,-6,minecraft:basalt)
B(4,81,-6,minecraft:basalt)
B(4,82,-6,minecraft:basalt)
B(4,83,-6,minecraft:basalt)
B(4,84,-6,minecraft:basalt)
B(4,85,-6,minecraft:basalt)
B(4,86,-6,minecraft:basalt)
B(4,87,-6,minecraft:basalt)
B(4,88,-6,minecraft:basalt)
B(4,89,-6,minecraft:basalt)
B(4,90,-6,minecraft:basalt)
B(4,62,-5,minecraft:basalt)
B(4,63,-5,minecraft:basalt)
B(4,64,-5,minecraft:basalt)
B(4,65,-5,minecraft:basalt)
B(4,66,-5,minecraft:basalt)
B(4,67,-5,minecraft:basalt)
B(4,68,-5,minecraft:basalt)
B(4,69,-5,minecraft:basalt)
B(4,70,-5,minecraft:basalt)
B(4,71,-5,minecraft:basalt)
B(4,72,-5,minecraft:basalt)
B(4,73,-5,minecraft:basalt)
B(4,74,-5,minecraft:basalt)
B(4,75,-5,minecraft:basalt)
B(4,76,-5,minecraft:basalt)
B(4,77,-5,minecraft:basalt)
B(4,78,-5,minecraft:basalt)
B(4,79,-5,minecraft:basalt)
B(4,80,-5,minecraft:basalt)
B(4,81,-5,minecraft:basalt)
B(4,82,-5,minecraft:basalt)
B(4,83,-5,minecraft:basalt)
B(4,84,-5,minecraft:basalt)
B(4,85,-5,minecraft:basalt)
B(4,86,-5,minecraft:basalt)
B(4,87,-5,minecraft:basalt)
B(4,88,-5,minecraft:basalt)
B(4,89,-5,minecraft:basalt)
B(4,90,-5,minecraft:basalt)
B(4,70,-4,minecraft:basalt)
B(4,71,-4,minecraft:basalt)
B(4,72,-4,minecraft:basalt)
B(4,73,-4,minecraft:basalt)
B(4,74,-4,minecraft:basalt)
B(4,75,-4,minecraft:basalt)
B(4,76,-4,minecraft:basalt)
B(4,77,-4,minecraft:basalt)
B(4,78,-4,minecraft:basalt)
B(4,79,-4,minecraft:basalt)
B(4,80,-4,minecraft:basalt)
B(4,81,-4,minecraft:basalt)
B(4,82,-4,minecraft:basalt)
B(4,83,-4,minecraft:basalt)
B(4,84,-4,minecraft:basalt)
B(4,85,-4,minecraft:basalt)
B(4,86,-4,minecraft:basalt)
B(4,87,-4,minecraft:basalt)
B(4,88,-4,minecraft:basalt)
B(4,89,-4,minecraft:basalt)
B(4,90,-4,minecraft:basalt)
B(4,71,-3,minecraft:basalt)
B(4,72,-3,minecraft:basalt)
B(4,73,-3,minecraft:basalt)
B(4,74,-3,minecraft:basalt)
B(4,75,-3,minecraft:basalt)
B(4,76,-3,minecraft:basalt)
B(4,77,-3,minecraft:basalt)
B(4,78,-3,minecraft:basalt)
B(4,79,-3,minecraft:basalt)
B(4,80,-3,minecraft:basalt)
B(4,81,-3,minecraft:basalt)
B(4,82,-3,minecraft:basalt)
B(4,83,-3,minecraft:basalt)
B(4,84,-3,minecraft:basalt)
B(4,85,-3,minecraft:basalt)
B(4,86,-3,minecraft:basalt)
B(4,87,-3,minecraft:basalt)
B(4,88,-3,minecraft:basalt)
B(4,89,-3,minecraft:basalt)
B(4,90,-3,minecraft:basalt)
B(4,74,-2,minecraft:basalt)
B(4,75,-2,minecraft:basalt)
B(4,76,-2,minecraft:basalt)
B(4,77,-2,minecraft:basalt)
B(4,78,-2,minecraft:basalt)
B(4,79,-2,minecraft:basalt)
B(4,80,-2,minecraft:basalt)
B(4,81,-2,minecraft:basalt)
B(4,82,-2,minecraft:basalt)
B(4,83,-2,minecraft:basalt)
B(4,84,-2,minecraft:basalt)
B(4,85,-2,minecraft:basalt)
B(4,86,-2,minecraft:basalt)
B(4,87,-2,minecraft:basalt)
B(4,88,-2,minecraft:basalt)
B(4,89,-2,minecraft:basalt)
B(4,90,-2,minecraft:basalt)
B(4,81,-1,minecraft:basalt)
B(4,82,-1,minecraft:basalt)
B(4,83,-1,minecraft:basalt)
B(4,84,-1,minecraft:basalt)
B(4,85,-1,minecraft:basalt)
B(4,86,-1,minecraft:basalt)
B(4,87,-1,minecraft:basalt)
B(4,88,-1,minecraft:basalt)
B(4,89,-1,minecraft:basalt)
B(4,90,-1,minecraft:basalt)
B(4,82,0,minecraft:basalt)
B(4,83,0,minecraft:basalt)
B(4,84,0,minecraft:basalt)
B(4,85,0,minecraft:basalt)
B(4,86,0,minecraft:basalt)
B(4,87,0,minecraft:basalt)
B(4,88,0,minecraft:basalt)
B(4,89,0,minecraft:basalt)
B(4,90,0,minecraft:basalt)
B(4,89,1,minecraft:basalt)
B(4,90,1,minecraft:blackstone)
B(4,88,2,minecraft:basalt)
B(4,89,2,minecraft:blackstone)
B(4,90,2,minecraft:blackstone)
B(4,88,3,minecraft:basalt)
B(4,89,3,minecraft:blackstone)
B(4,90,3,minecraft:blackstone)
B(5,39,-7,minecraft:basalt)
B(5,40,-7,minecraft:basalt)
B(5,41,-7,minecraft:basalt)
B(5,42,-7,minecraft:basalt)
B(5,43,-7,minecraft:basalt)
B(5,44,-7,minecraft:basalt)
B(5,45,-7,minecraft:basalt)
B(5,46,-7,minecraft:basalt)
B(5,47,-7,minecraft:basalt)
B(5,48,-7,minecraft:basalt)
B(5,49,-7,minecraft:basalt)
B(5,50,-7,minecraft:basalt)
B(5,51,-7,minecraft:basalt)
B(5,52,-7,minecraft:basalt)
B(5,53,-7,minecraft:basalt)
B(5,54,-7,minecraft:basalt)
B(5,55,-7,minecraft:basalt)
B(5,56,-7,minecraft:basalt)
B(5,57,-7,minecraft:basalt)
B(5,58,-7,minecraft:basalt)
B(5,59,-7,minecraft:basalt)
B(5,60,-7,minecraft:basalt)
B(5,61,-7,minecraft:basalt)
B(5,62,-7,minecraft:basalt)
B(5,63,-7,minecraft:basalt)
B(5,64,-7,minecraft:basalt)
B(5,65,-7,minecraft:basalt)
B(5,66,-7,minecraft:basalt)
B(5,67,-7,minecraft:basalt)
B(5,68,-7,minecraft:basalt)
B(5,69,-7,minecraft:basalt)
B(5,70,-7,minecraft:basalt)
B(5,71,-7,minecraft:basalt)
B(5,72,-7,minecraft:basalt)
B(5,73,-7,minecraft:basalt)
B(5,74,-7,minecraft:basalt)
B(5,75,-7,minecraft:basalt)
B(5,76,-7,minecraft:basalt)
B(5,77,-7,minecraft:basalt)
B(5,78,-7,minecraft:basalt)
B(5,79,-7,minecraft:basalt)
B(5,80,-7,minecraft:basalt)
B(5,81,-7,minecraft:basalt)
B(5,82,-7,minecraft:basalt)
B(5,83,-7,minecraft:basalt)
B(5,84,-7,minecraft:basalt)
B(5,85,-7,minecraft:basalt)
B(5,86,-7,minecraft:basalt)
B(5,87,-7,minecraft:basalt)
B(5,88,-7,minecraft:basalt)
B(5,89,-7,minecraft:basalt)
B(5,90,-7,minecraft:basalt)
B(5,50,-6,minecraft:basalt)
B(5,51,-6,minecraft:basalt)
B(5,52,-6,minecraft:basalt)
B(5,53,-6,minecraft:basalt)
B(5,54,-6,minecraft:basalt)
B(5,55,-6,minecraft:basalt)
B(5,56,-6,minecraft:basalt)
B(5,57,-6,minecraft:basalt)
B(5,58,-6,minecraft:basalt)
B(5,59,-6,minecraft:basalt)
B(5,60,-6,minecraft:basalt)
B(5,61,-6,minecraft:basalt)
B(5,62,-6,minecraft:basalt)
B(5,63,-6,minecraft:basalt)
B(5,64,-6,minecraft:basalt)
B(5,65,-6,minecraft:basalt)
B(5,66,-6,minecraft:basalt)
B(5,67,-6,minecraft:basalt)
B(5,68,-6,minecraft:basalt)
B(5,69,-6,minecraft:basalt)
B(5,70,-6,minecraft:basalt)
B(5,71,-6,minecraft:basalt)
B(5,72,-6,minecraft:basalt)
B(5,73,-6,minecraft:basalt)
B(5,74,-6,minecraft:basalt)
B(5,75,-6,minecraft:basalt)
B(5,76,-6,minecraft:basalt)
B(5,77,-6,minecraft:basalt)
B(5,78,-6,minecraft:basalt)
B(5,79,-6,minecraft:basalt)
B(5,80,-6,minecraft:basalt)
B(5,81,-6,minecraft:basalt)
B(5,82,-6,minecraft:basalt)
B(5,83,-6,minecraft:basalt)
B(5,84,-6,minecraft:basalt)
B(5,85,-6,minecraft:basalt)
B(5,86,-6,minecraft:basalt)
B(5,87,-6,minecraft:basalt)
B(5,88,-6,minecraft:basalt)
B(5,89,-6,minecraft:basalt)
B(5,90,-6,minecraft:basalt)
B(5,67,-5,minecraft:basalt)
B(5,68,-5,minecraft:basalt)
B(5,69,-5,minecraft:basalt)
B(5,70,-5,minecraft:basalt)
B(5,71,-5,minecraft:basalt)
B(5,72,-5,minecraft:basalt)
B(5,73,-5,minecraft:basalt)
B(5,74,-5,minecraft:basalt)
B(5,75,-5,minecraft:basalt)
B(5,76,-5,minecraft:basalt)
B(5,77,-5,minecraft:basalt)
B(5,78,-5,minecraft:basalt)
B(5,79,-5,minecraft:basalt)
B(5,80,-5,minecraft:basalt)
B(5,81,-5,minecraft:basalt)
B(5,82,-5,minecraft:basalt)
B(5,83,-5,minecraft:basalt)
B(5,84,-5,minecraft:basalt)
B(5,85,-5,minecraft:basalt)
B(5,86,-5,minecraft:basalt)
B(5,87,-5,minecraft:basalt)
B(5,88,-5,minecraft:basalt)
B(5,89,-5,minecraft:basalt)
B(5,90,-5,minecraft:basalt)
B(5,71,-4,minecraft:basalt)
B(5,72,-4,minecraft:basalt)
B(5,73,-4,minecraft:basalt)
B(5,74,-4,minecraft:basalt)
B(5,75,-4,minecraft:basalt)
B(5,76,-4,minecraft:basalt)
B(5,77,-4,minecraft:basalt)
B(5,78,-4,minecraft:basalt)
B(5,79,-4,minecraft:basalt)
B(5,80,-4,minecraft:basalt)
B(5,81,-4,minecraft:basalt)
B(5,82,-4,minecraft:basalt)
B(5,83,-4,minecraft:basalt)
B(5,84,-4,minecraft:basalt)
B(5,85,-4,minecraft:basalt)
B(5,86,-4,minecraft:basalt)
B(5,87,-4,minecraft:basalt)
B(5,88,-4,minecraft:basalt)
B(5,89,-4,minecraft:basalt)
B(5,90,-4,minecraft:basalt)
B(5,72,-3,minecraft:basalt)
B(5,73,-3,minecraft:basalt)
B(5,74,-3,minecraft:basalt)
B(5,75,-3,minecraft:basalt)
B(5,76,-3,minecraft:basalt)
B(5,77,-3,minecraft:basalt)
B(5,78,-3,minecraft:basalt)
B(5,79,-3,minecraft:basalt)
B(5,80,-3,minecraft:basalt)
B(5,81,-3,minecraft:basalt)
B(5,82,-3,minecraft:basalt)
B(5,83,-3,minecraft:basalt)
B(5,84,-3,minecraft:basalt)
B(5,85,-3,minecraft:basalt)
B(5,86,-3,minecraft:basalt)
B(5,87,-3,minecraft:basalt)
B(5,88,-3,minecraft:basalt)
B(5,89,-3,minecraft:basalt)
B(5,90,-3,minecraft:basalt)
B(5,78,-2,minecraft:basalt)
B(5,79,-2,minecraft:basalt)
B(5,80,-2,minecraft:basalt)
B(5,81,-2,minecraft:basalt)
B(5,82,-2,minecraft:basalt)
B(5,83,-2,minecraft:basalt)
B(5,84,-2,minecraft:basalt)
B(5,85,-2,minecraft:basalt)
B(5,86,-2,minecraft:basalt)
B(5,87,-2,minecraft:basalt)
B(5,88,-2,minecraft:basalt)
B(5,89,-2,minecraft:basalt)
B(5,90,-2,minecraft:basalt)
B(5,81,-1,minecraft:basalt)
B(5,82,-1,minecraft:basalt)
B(5,83,-1,minecraft:basalt)
B(5,84,-1,minecraft:basalt)
B(5,85,-1,minecraft:basalt)
B(5,86,-1,minecraft:basalt)
B(5,87,-1,minecraft:basalt)
B(5,88,-1,minecraft:basalt)
B(5,89,-1,minecraft:basalt)
B(5,90,-1,minecraft:basalt)
B(5,84,0,minecraft:basalt)
B(5,85,0,minecraft:basalt)
B(5,86,0,minecraft:basalt)
B(5,87,0,minecraft:basalt)
B(5,88,0,minecraft:basalt)
B(5,89,0,minecraft:basalt)
B(5,90,0,minecraft:basalt)
B(5,88,1,minecraft:basalt)
B(5,89,1,minecraft:blackstone)
B(5,90,1,minecraft:blackstone)
B(5,88,2,minecraft:basalt)
B(5,89,2,minecraft:blackstone)
B(5,90,2,minecraft:blackstone)
B(5,89,3,minecraft:basalt)
B(5,90,3,minecraft:blackstone)
B(6,47,-7,minecraft:basalt)
B(6,48,-7,minecraft:basalt)
B(6,49,-7,minecraft:basalt)
B(6,50,-7,minecraft:basalt)
B(6,51,-7,minecraft:basalt)
B(6,52,-7,minecraft:basalt)
B(6,53,-7,minecraft:basalt)
B(6,54,-7,minecraft:basalt)
B(6,55,-7,minecraft:basalt)
B(6,56,-7,minecraft:basalt)
B(6,57,-7,minecraft:basalt)
B(6,58,-7,minecraft:basalt)
B(6,59,-7,minecraft:basalt)
B(6,60,-7,minecraft:basalt)
B(6,61,-7,minecraft:basalt)
B(6,62,-7,minecraft:basalt)
B(6,63,-7,minecraft:basalt)
B(6,64,-7,minecraft:basalt)
B(6,65,-7,minecraft:basalt)
B(6,66,-7,minecraft:basalt)
B(6,67,-7,minecraft:basalt)
B(6,68,-7,minecraft:basalt)
B(6,69,-7,minecraft:basalt)
B(6,70,-7,minecraft:basalt)
B(6,71,-7,minecraft:basalt)
B(6,72,-7,minecraft:basalt)
B(6,73,-7,minecraft:basalt)
B(6,74,-7,minecraft:basalt)
B(6,75,-7,minecraft:basalt)
B(6,76,-7,minecraft:basalt)
B(6,77,-7,minecraft:basalt)
B(6,78,-7,minecraft:basalt)
B(6,79,-7,minecraft:basalt)
B(6,80,-7,minecraft:basalt)
B(6,81,-7,minecraft:basalt)
B(6,82,-7,minecraft:basalt)
B(6,83,-7,minecraft:basalt)
B(6,84,-7,minecraft:basalt)
B(6,85,-7,minecraft:basalt)
B(6,86,-7,minecraft:basalt)
B(6,87,-7,minecraft:basalt)
B(6,88,-7,minecraft:basalt)
B(6,89,-7,minecraft:basalt)
B(6,90,-7,minecraft:basalt)
B(6,55,-6,minecraft:basalt)
B(6,56,-6,minecraft:basalt)
B(6,57,-6,minecraft:basalt)
B(6,58,-6,minecraft:basalt)
B(6,59,-6,minecraft:basalt)
B(6,60,-6,minecraft:basalt)
B(6,61,-6,minecraft:basalt)
B(6,62,-6,minecraft:basalt)
B(6,63,-6,minecraft:basalt)
B(6,64,-6,minecraft:basalt)
B(6,65,-6,minecraft:basalt)
B(6,66,-6,minecraft:basalt)
B(6,67,-6,minecraft:basalt)
B(6,68,-6,minecraft:basalt)
B(6,69,-6,minecraft:basalt)
B(6,70,-6,minecraft:basalt)
B(6,71,-6,minecraft:basalt)
B(6,72,-6,minecraft:basalt)
B(6,73,-6,minecraft:basalt)
B(6,74,-6,minecraft:basalt)
B(6,75,-6,minecraft:basalt)
B(6,76,-6,minecraft:basalt)
B(6,77,-6,minecraft:basalt)
B(6,78,-6,minecraft:basalt)
B(6,79,-6,minecraft:basalt)
B(6,80,-6,minecraft:basalt)
B(6,81,-6,minecraft:basalt)
B(6,82,-6,minecraft:basalt)
B(6,83,-6,minecraft:basalt)
B(6,84,-6,minecraft:basalt)
B(6,85,-6,minecraft:basalt)
B(6,86,-6,minecraft:basalt)
B(6,87,-6,minecraft:basalt)
B(6,88,-6,minecraft:basalt)
B(6,89,-6,minecraft:basalt)
B(6,90,-6,minecraft:basalt)
B(6,61,-5,minecraft:basalt)
B(6,62,-5,minecraft:basalt)
B(6,63,-5,minecraft:basalt)
B(6,64,-5,minecraft:basalt)
B(6,65,-5,minecraft:basalt)
B(6,66,-5,minecraft:basalt)
B(6,67,-5,minecraft:basalt)
B(6,68,-5,minecraft:basalt)
B(6,69,-5,minecraft:basalt)
B(6,70,-5,minecraft:basalt)
B(6,71,-5,minecraft:basalt)
B(6,72,-5,minecraft:basalt)
B(6,73,-5,minecraft:basalt)
B(6,74,-5,minecraft:basalt)
B(6,75,-5,minecraft:basalt)
B(6,76,-5,minecraft:basalt)
B(6,77,-5,minecraft:basalt)
B(6,78,-5,minecraft:basalt)
B(6,79,-5,minecraft:basalt)
B(6,80,-5,minecraft:basalt)
B(6,81,-5,minecraft:basalt)
B(6,82,-5,minecraft:basalt)
B(6,83,-5,minecraft:basalt)
B(6,84,-5,minecraft:basalt)
B(6,85,-5,minecraft:basalt)
B(6,86,-5,minecraft:basalt)
B(6,87,-5,minecraft:basalt)
B(6,88,-5,minecraft:basalt)
B(6,89,-5,minecraft:basalt)
B(6,90,-5,minecraft:basalt)
B(6,72,-4,minecraft:basalt)
B(6,73,-4,minecraft:basalt)
B(6,74,-4,minecraft:basalt)
B(6,75,-4,minecraft:basalt)
B(6,76,-4,minecraft:basalt)
B(6,77,-4,minecraft:basalt)
B(6,78,-4,minecraft:basalt)
B(6,79,-4,minecraft:basalt)
B(6,80,-4,minecraft:basalt)
B(6,81,-4,minecraft:basalt)
B(6,82,-4,minecraft:basalt)
B(6,83,-4,minecraft:basalt)
B(6,84,-4,minecraft:basalt)
B(6,85,-4,minecraft:basalt)
B(6,86,-4,minecraft:basalt)
B(6,87,-4,minecraft:basalt)
B(6,88,-4,minecraft:basalt)
B(6,89,-4,minecraft:basalt)
B(6,90,-4,minecraft:basalt)
B(6,77,-3,minecraft:basalt)
B(6,78,-3,minecraft:basalt)
B(6,79,-3,minecraft:basalt)
B(6,80,-3,minecraft:basalt)
B(6,81,-3,minecraft:basalt)
B(6,82,-3,minecraft:basalt)
B(6,83,-3,minecraft:basalt)
B(6,84,-3,minecraft:basalt)
B(6,85,-3,minecraft:basalt)
B(6,86,-3,minecraft:basalt)
B(6,87,-3,minecraft:basalt)
B(6,88,-3,minecraft:basalt)
B(6,89,-3,minecraft:basalt)
B(6,90,-3,minecraft:basalt)
B(6,81,-2,minecraft:basalt)
B(6,82,-2,minecraft:basalt)
B(6,83,-2,minecraft:basalt)
B(6,84,-2,minecraft:basalt)
B(6,85,-2,minecraft:basalt)
B(6,86,-2,minecraft:basalt)
B(6,87,-2,minecraft:basalt)
B(6,88,-2,minecraft:basalt)
B(6,89,-2,minecraft:basalt)
B(6,90,-2,minecraft:basalt)
B(6,82,-1,minecraft:basalt)
B(6,83,-1,minecraft:basalt)
B(6,84,-1,minecraft:basalt)
B(6,85,-1,minecraft:basalt)
B(6,86,-1,minecraft:basalt)
B(6,87,-1,minecraft:basalt)
B(6,88,-1,minecraft:basalt)
B(6,89,-1,minecraft:basalt)
B(6,90,-1,minecraft:basalt)
B(6,87,0,minecraft:basalt)
B(6,88,0,minecraft:basalt)
B(6,89,0,minecraft:basalt)
B(6,90,0,minecraft:basalt)
B(6,88,1,minecraft:basalt)
B(6,89,1,minecraft:blackstone)
B(6,90,1,minecraft:blackstone)
B(6,88,2,minecraft:basalt)
B(6,89,2,minecraft:blackstone)
B(6,90,2,minecraft:blackstone)
B(6,89,3,minecraft:basalt)
B(6,90,3,minecraft:blackstone)
B(7,54,-7,minecraft:basalt)
B(7,55,-7,minecraft:basalt)
B(7,56,-7,minecraft:basalt)
B(7,57,-7,minecraft:basalt)
B(7,58,-7,minecraft:basalt)
B(7,59,-7,minecraft:basalt)
B(7,60,-7,minecraft:basalt)
B(7,61,-7,minecraft:basalt)
B(7,62,-7,minecraft:basalt)
B(7,63,-7,minecraft:basalt)
B(7,64,-7,minecraft:basalt)
B(7,65,-7,minecraft:basalt)
B(7,66,-7,minecraft:basalt)
B(7,67,-7,minecraft:basalt)
B(7,68,-7,minecraft:basalt)
B(7,69,-7,minecraft:basalt)
B(7,70,-7,minecraft:basalt)
B(7,71,-7,minecraft:basalt)
B(7,72,-7,minecraft:basalt)
B(7,73,-7,minecraft:basalt)
B(7,74,-7,minecraft:basalt)
B(7,75,-7,minecraft:basalt)
B(7,76,-7,minecraft:basalt)
B(7,77,-7,minecraft:basalt)
B(7,78,-7,minecraft:basalt)
B(7,79,-7,minecraft:basalt)
B(7,80,-7,minecraft:basalt)
B(7,81,-7,minecraft:basalt)
B(7,82,-7,minecraft:basalt)
B(7,83,-7,minecraft:basalt)
B(7,84,-7,minecraft:basalt)
B(7,85,-7,minecraft:basalt)
B(7,86,-7,minecraft:basalt)
B(7,87,-7,minecraft:basalt)
B(7,88,-7,minecraft:basalt)
B(7,89,-7,minecraft:basalt)
B(7,90,-7,minecraft:basalt)
B(7,58,-6,minecraft:basalt)
B(7,59,-6,minecraft:basalt)
B(7,60,-6,minecraft:basalt)
B(7,61,-6,minecraft:basalt)
B(7,62,-6,minecraft:basalt)
B(7,63,-6,minecraft:basalt)
B(7,64,-6,minecraft:basalt)
B(7,65,-6,minecraft:basalt)
B(7,66,-6,minecraft:basalt)
B(7,67,-6,minecraft:basalt)
B(7,68,-6,minecraft:basalt)
B(7,69,-6,minecraft:basalt)
B(7,70,-6,minecraft:basalt)
B(7,71,-6,minecraft:basalt)
B(7,72,-6,minecraft:basalt)
B(7,73,-6,minecraft:basalt)
B(7,74,-6,minecraft:basalt)
B(7,75,-6,minecraft:basalt)
B(7,76,-6,minecraft:basalt)
B(7,77,-6,minecraft:basalt)
B(7,78,-6,minecraft:basalt)
B(7,79,-6,minecraft:basalt)
B(7,80,-6,minecraft:basalt)
B(7,81,-6,minecraft:basalt)
B(7,82,-6,minecraft:basalt)
B(7,83,-6,minecraft:basalt)
B(7,84,-6,minecraft:basalt)
B(7,85,-6,minecraft:basalt)
B(7,86,-6,minecraft:basalt)
B(7,87,-6,minecraft:basalt)
B(7,88,-6,minecraft:basalt)
B(7,89,-6,minecraft:basalt)
B(7,90,-6,minecraft:basalt)
B(7,61,-5,minecraft:basalt)
B(7,62,-5,minecraft:basalt)
B(7,63,-5,minecraft:basalt)
B(7,64,-5,minecraft:basalt)
B(7,65,-5,minecraft:basalt)
B(7,66,-5,minecraft:basalt)
B(7,67,-5,minecraft:basalt)
B(7,68,-5,minecraft:basalt)
B(7,69,-5,minecraft:basalt)
B(7,70,-5,minecraft:basalt)
B(7,71,-5,minecraft:basalt)
B(7,72,-5,minecraft:basalt)
B(7,73,-5,minecraft:basalt)
B(7,74,-5,minecraft:basalt)
B(7,75,-5,minecraft:basalt)
B(7,76,-5,minecraft:basalt)
B(7,77,-5,minecraft:basalt)
B(7,78,-5,minecraft:basalt)
B(7,79,-5,minecraft:basalt)
B(7,80,-5,minecraft:basalt)
B(7,81,-5,minecraft:basalt)
B(7,82,-5,minecraft:basalt)
B(7,83,-5,minecraft:basalt)
B(7,84,-5,minecraft:basalt)
B(7,85,-5,minecraft:basalt)
B(7,86,-5,minecraft:basalt)
B(7,87,-5,minecraft:basalt)
B(7,88,-5,minecraft:basalt)
B(7,89,-5,minecraft:basalt)
B(7,90,-5,minecraft:basalt)
B(7,67,-4,minecraft:basalt)
B(7,68,-4,minecraft:basalt)
B(7,69,-4,minecraft:basalt)
B(7,70,-4,minecraft:basalt)
B(7,71,-4,minecraft:basalt)
B(7,72,-4,minecraft:basalt)
B(7,73,-4,minecraft:basalt)
B(7,74,-4,minecraft:basalt)
B(7,75,-4,minecraft:basalt)
B(7,76,-4,minecraft:basalt)
B(7,77,-4,minecraft:basalt)
B(7,78,-4,minecraft:basalt)
B(7,79,-4,minecraft:basalt)
B(7,80,-4,minecraft:basalt)
B(7,81,-4,minecraft:basalt)
B(7,82,-4,minecraft:basalt)
B(7,83,-4,minecraft:basalt)
B(7,84,-4,minecraft:basalt)
B(7,85,-4,minecraft:basalt)
B(7,86,-4,minecraft:basalt)
B(7,87,-4,minecraft:basalt)
B(7,88,-4,minecraft:basalt)
B(7,89,-4,minecraft:basalt)
B(7,90,-4,minecraft:basalt)
B(7,81,-3,minecraft:basalt)
B(7,82,-3,minecraft:basalt)
B(7,83,-3,minecraft:basalt)
B(7,84,-3,minecraft:basalt)
B(7,85,-3,minecraft:basalt)
B(7,86,-3,minecraft:basalt)
B(7,87,-3,minecraft:basalt)
B(7,88,-3,minecraft:basalt)
B(7,89,-3,minecraft:basalt)
B(7,90,-3,minecraft:basalt)
B(7,82,-2,minecraft:basalt)
B(7,83,-2,minecraft:basalt)
B(7,84,-2,minecraft:basalt)
B(7,85,-2,minecraft:basalt)
B(7,86,-2,minecraft:basalt)
B(7,87,-2,minecraft:basalt)
B(7,88,-2,minecraft:basalt)
B(7,89,-2,minecraft:basalt)
B(7,90,-2,minecraft:basalt)
B(7,86,-1,minecraft:basalt)
B(7,87,-1,minecraft:basalt)
B(7,88,-1,minecraft:basalt)
B(7,89,-1,minecraft:basalt)
B(7,90,-1,minecraft:basalt)
B(7,88,0,minecraft:basalt)
B(7,89,0,minecraft:basalt)
B(7,90,0,minecraft:basalt)
B(7,88,1,minecraft:basalt)
B(7,89,1,minecraft:blackstone)
B(7,90,1,minecraft:blackstone)
B(7,89,2,minecraft:basalt)
B(7,90,2,minecraft:blackstone)
B(7,89,3,minecraft:basalt)
B(7,90,3,minecraft:blackstone)

#######################################################################
# +-----------------------------------------------------------------+ #
# |                             Branches                            | #
# +-----------------------------------------------------------------+ #
#######################################################################

Branch(16,0,0,true,UpsideDownBasaltWall1_C1_R9,NORTH,100.0,0)

#######################################################################
# +-----------------------------------------------------------------+ #
# |                             Entities                            | #
# +-----------------------------------------------------------------+ #
#######################################################################

