
#######################################################################
# +-----------------------------------------------------------------+ #
# |                            BO4 object                           | #
# +-----------------------------------------------------------------+ #
#######################################################################

Author: Unknown

Description: No description given

SettingsMode: WriteWithoutComments


#######################################################################
# +-----------------------------------------------------------------+ #
# |                          Main settings                          | #
# +-----------------------------------------------------------------+ #
#######################################################################

FixedRotation: 

Frequency: 0

SpawnHeight: highestBlock

UseCenterForHighestBlock: true

##############################
# Height Limits for the BO4. #
##############################

MinHeight: 0

MaxHeight: 255

InheritBO3: 

InheritBO3Rotation: NORTH

OverrideChildSettings: true

OverrideParentHeight: false

CanOverride: false

BranchFrequency: 0

BranchFrequencyGroup: 

MustBeBelowOther: false

MustBeInside: 

CannotBeInside: 

ReplacesBO3: 

MustBeInsideWorldBorders: false

CanSpawnOnWater: true

SpawnOnWaterOnly: false

SpawnUnderWater: false

SpawnAtWaterLevel: false

HeightOffset: 0

RemoveAir: true

ReplaceAbove: 

ReplaceBelow: 

ReplaceWithBiomeBlocks: true

ReplaceWithSurfaceBlock: GRASS

ReplaceWithGroundBlock: DIRT

ReplaceWithStoneBlock: STONE

SmoothRadius: 0

SmoothHeightOffset: 0

SmoothStartTop: false

SmoothStartWood: false

SmoothingSurfaceBlock: 

SmoothingGroundBlock: 

BO3Group: 

IsSpawnPoint: false

DoReplaceBlocks: true


#######################################################################
# +-----------------------------------------------------------------+ #
# |                              Blocks                             | #
# +-----------------------------------------------------------------+ #
#######################################################################

B(-8,0,-7,minecraft:netherrack)
B(-8,1,-7,minecraft:netherrack)
B(-8,2,-7,minecraft:soul_soil)
B(-8,3,-7,minecraft:soul_soil)
B(-8,4,-7,minecraft:soul_soil)
B(-8,5,-7,minecraft:soul_soil)
B(-8,6,-7,minecraft:soul_sand)
B(-8,96,-7,minecraft:soul_sand)
B(-8,97,-7,minecraft:soul_sand)
B(-8,98,-7,minecraft:soul_sand)
B(-8,99,-7,minecraft:soul_sand)
B(-8,100,-7,minecraft:soul_sand)
B(-8,101,-7,minecraft:soul_sand)
B(-8,102,-7,minecraft:soul_sand)
B(-8,103,-7,minecraft:soul_sand)
B(-8,104,-7,minecraft:soul_sand)
B(-8,105,-7,minecraft:soul_sand)
B(-8,106,-7,minecraft:soul_sand)
B(-8,107,-7,minecraft:soul_sand)
B(-8,108,-7,minecraft:soul_sand)
B(-8,109,-7,minecraft:soul_sand)
B(-8,110,-7,minecraft:soul_sand)
B(-8,111,-7,minecraft:soul_sand)
B(-8,0,-6,minecraft:netherrack)
B(-8,1,-6,minecraft:netherrack)
B(-8,2,-6,minecraft:soul_soil)
B(-8,3,-6,minecraft:soul_soil)
B(-8,4,-6,minecraft:soul_soil)
B(-8,5,-6,minecraft:soul_soil)
B(-8,6,-6,minecraft:soul_sand)
B(-8,95,-6,minecraft:soul_sand)
B(-8,96,-6,minecraft:soul_sand)
B(-8,97,-6,minecraft:soul_sand)
B(-8,98,-6,minecraft:soul_sand)
B(-8,99,-6,minecraft:soul_sand)
B(-8,100,-6,minecraft:soul_sand)
B(-8,101,-6,minecraft:soul_sand)
B(-8,102,-6,minecraft:soul_sand)
B(-8,103,-6,minecraft:soul_sand)
B(-8,104,-6,minecraft:soul_sand)
B(-8,105,-6,minecraft:soul_sand)
B(-8,106,-6,minecraft:soul_sand)
B(-8,107,-6,minecraft:soul_sand)
B(-8,108,-6,minecraft:soul_sand)
B(-8,109,-6,minecraft:soul_sand)
B(-8,110,-6,minecraft:soul_sand)
B(-8,111,-6,minecraft:soul_sand)
B(-8,0,-5,minecraft:netherrack)
B(-8,1,-5,minecraft:netherrack)
B(-8,2,-5,minecraft:soul_soil)
B(-8,3,-5,minecraft:soul_soil)
B(-8,4,-5,minecraft:soul_soil)
B(-8,5,-5,minecraft:soul_sand)
B(-8,95,-5,minecraft:soul_sand)
B(-8,96,-5,minecraft:soul_sand)
B(-8,97,-5,minecraft:soul_sand)
B(-8,98,-5,minecraft:soul_sand)
B(-8,99,-5,minecraft:soul_sand)
B(-8,100,-5,minecraft:soul_sand)
B(-8,101,-5,minecraft:soul_sand)
B(-8,102,-5,minecraft:soul_sand)
B(-8,103,-5,minecraft:soul_sand)
B(-8,104,-5,minecraft:soul_sand)
B(-8,105,-5,minecraft:soul_sand)
B(-8,106,-5,minecraft:soul_sand)
B(-8,107,-5,minecraft:soul_sand)
B(-8,108,-5,minecraft:soul_sand)
B(-8,109,-5,minecraft:soul_sand)
B(-8,110,-5,minecraft:soul_sand)
B(-8,111,-5,minecraft:soul_sand)
B(-8,0,-4,minecraft:netherrack)
B(-8,1,-4,minecraft:netherrack)
B(-8,2,-4,minecraft:netherrack)
B(-8,3,-4,minecraft:soul_soil)
B(-8,4,-4,minecraft:soul_soil)
B(-8,5,-4,minecraft:soul_soil)
B(-8,6,-4,minecraft:soul_sand)
B(-8,94,-4,minecraft:soul_sand)
B(-8,95,-4,minecraft:soul_sand)
B(-8,96,-4,minecraft:soul_sand)
B(-8,97,-4,minecraft:soul_sand)
B(-8,98,-4,minecraft:soul_sand)
B(-8,99,-4,minecraft:soul_sand)
B(-8,100,-4,minecraft:soul_sand)
B(-8,101,-4,minecraft:soul_sand)
B(-8,102,-4,minecraft:soul_sand)
B(-8,103,-4,minecraft:soul_sand)
B(-8,104,-4,minecraft:soul_sand)
B(-8,105,-4,minecraft:soul_sand)
B(-8,106,-4,minecraft:soul_sand)
B(-8,107,-4,minecraft:soul_sand)
B(-8,108,-4,minecraft:soul_sand)
B(-8,109,-4,minecraft:soul_sand)
B(-8,110,-4,minecraft:soul_sand)
B(-8,111,-4,minecraft:soul_sand)
B(-8,0,-3,minecraft:netherrack)
B(-8,1,-3,minecraft:netherrack)
B(-8,2,-3,minecraft:soul_sand)
B(-8,3,-3,minecraft:soul_sand)
B(-8,4,-3,minecraft:soul_sand)
B(-8,5,-3,minecraft:soul_sand)
B(-8,6,-3,minecraft:soul_sand)
B(-8,97,-3,minecraft:soul_sand)
B(-8,98,-3,minecraft:soul_sand)
B(-8,99,-3,minecraft:soul_sand)
B(-8,100,-3,minecraft:soul_sand)
B(-8,101,-3,minecraft:soul_sand)
B(-8,102,-3,minecraft:soul_sand)
B(-8,103,-3,minecraft:soul_sand)
B(-8,104,-3,minecraft:soul_sand)
B(-8,105,-3,minecraft:soul_sand)
B(-8,106,-3,minecraft:soul_sand)
B(-8,107,-3,minecraft:soul_sand)
B(-8,108,-3,minecraft:soul_sand)
B(-8,109,-3,minecraft:soul_sand)
B(-8,110,-3,minecraft:soul_sand)
B(-8,111,-3,minecraft:soul_sand)
B(-8,0,-2,minecraft:soul_sand)
B(-8,1,-2,minecraft:soul_sand)
B(-8,2,-2,minecraft:soul_sand)
B(-8,3,-2,minecraft:soul_sand)
B(-8,4,-2,minecraft:soul_sand)
B(-8,5,-2,minecraft:soul_sand)
B(-8,6,-2,minecraft:soul_sand)
B(-8,100,-2,minecraft:soul_sand)
B(-8,101,-2,minecraft:soul_sand)
B(-8,102,-2,minecraft:soul_sand)
B(-8,103,-2,minecraft:soul_sand)
B(-8,104,-2,minecraft:soul_sand)
B(-8,105,-2,minecraft:soul_sand)
B(-8,106,-2,minecraft:soul_sand)
B(-8,107,-2,minecraft:soul_sand)
B(-8,108,-2,minecraft:soul_sand)
B(-8,109,-2,minecraft:soul_sand)
B(-8,110,-2,minecraft:soul_sand)
B(-8,111,-2,minecraft:soul_sand)
B(-8,0,-1,minecraft:soul_sand)
B(-8,1,-1,minecraft:soul_sand)
B(-8,2,-1,minecraft:soul_sand)
B(-8,3,-1,minecraft:soul_sand)
B(-8,4,-1,minecraft:soul_sand)
B(-8,5,-1,minecraft:soul_sand)
B(-8,6,-1,minecraft:soul_sand)
B(-8,7,-1,minecraft:soul_sand)
B(-8,102,-1,minecraft:soul_sand)
B(-8,103,-1,minecraft:soul_sand)
B(-8,104,-1,minecraft:soul_sand)
B(-8,105,-1,minecraft:soul_sand)
B(-8,106,-1,minecraft:soul_sand)
B(-8,107,-1,minecraft:soul_sand)
B(-8,108,-1,minecraft:soul_sand)
B(-8,109,-1,minecraft:soul_sand)
B(-8,110,-1,minecraft:soul_sand)
B(-8,111,-1,minecraft:soul_sand)
B(-8,0,0,minecraft:soul_sand)
B(-8,1,0,minecraft:soul_sand)
B(-8,2,0,minecraft:soul_sand)
B(-8,3,0,minecraft:soul_sand)
B(-8,4,0,minecraft:soul_sand)
B(-8,5,0,minecraft:soul_sand)
B(-8,6,0,minecraft:soul_sand)
B(-8,105,0,minecraft:soul_sand)
B(-8,106,0,minecraft:soul_sand)
B(-8,107,0,minecraft:soul_sand)
B(-8,108,0,minecraft:soul_sand)
B(-8,109,0,minecraft:soul_sand)
B(-8,110,0,minecraft:soul_sand)
B(-8,111,0,minecraft:soul_sand)
B(-8,0,1,minecraft:soul_sand)
B(-8,1,1,minecraft:soul_sand)
B(-8,2,1,minecraft:soul_sand)
B(-8,3,1,minecraft:soul_sand)
B(-8,4,1,minecraft:soul_sand)
B(-8,5,1,minecraft:soul_sand)
B(-8,6,1,minecraft:soul_sand)
B(-8,104,1,minecraft:soul_sand)
B(-8,105,1,minecraft:soul_sand)
B(-8,106,1,minecraft:soul_sand)
B(-8,107,1,minecraft:soul_sand)
B(-8,108,1,minecraft:soul_sand)
B(-8,109,1,minecraft:soul_sand)
B(-8,110,1,minecraft:soul_sand)
B(-8,111,1,minecraft:soul_sand)
B(-8,0,2,minecraft:soul_sand)
B(-8,1,2,minecraft:soul_sand)
B(-8,2,2,minecraft:soul_sand)
B(-8,3,2,minecraft:soul_sand)
B(-8,4,2,minecraft:soul_sand)
B(-8,5,2,minecraft:soul_sand)
B(-8,6,2,minecraft:soul_sand)
B(-8,103,2,minecraft:soul_sand)
B(-8,104,2,minecraft:soul_sand)
B(-8,105,2,minecraft:soul_sand)
B(-8,106,2,minecraft:soul_sand)
B(-8,107,2,minecraft:soul_sand)
B(-8,108,2,minecraft:soul_sand)
B(-8,109,2,minecraft:soul_sand)
B(-8,110,2,minecraft:soul_sand)
B(-8,111,2,minecraft:soul_sand)
B(-8,0,3,minecraft:soul_sand)
B(-8,1,3,minecraft:soul_sand)
B(-8,2,3,minecraft:soul_sand)
B(-8,3,3,minecraft:soul_sand)
B(-8,4,3,minecraft:soul_sand)
B(-8,5,3,minecraft:soul_sand)
B(-8,6,3,minecraft:soul_sand)
B(-8,102,3,minecraft:soul_sand)
B(-8,103,3,minecraft:soul_sand)
B(-8,104,3,minecraft:soul_sand)
B(-8,105,3,minecraft:soul_sand)
B(-8,106,3,minecraft:soul_sand)
B(-8,107,3,minecraft:soul_sand)
B(-8,108,3,minecraft:soul_sand)
B(-8,109,3,minecraft:soul_sand)
B(-8,110,3,minecraft:soul_sand)
B(-8,111,3,minecraft:soul_sand)
B(-8,0,4,minecraft:soul_sand)
B(-8,1,4,minecraft:soul_sand)
B(-8,2,4,minecraft:soul_sand)
B(-8,3,4,minecraft:soul_sand)
B(-8,4,4,minecraft:soul_sand)
B(-8,5,4,minecraft:soul_sand)
B(-8,6,4,minecraft:soul_sand)
B(-8,101,4,minecraft:soul_sand)
B(-8,102,4,minecraft:soul_sand)
B(-8,103,4,minecraft:soul_sand)
B(-8,104,4,minecraft:soul_sand)
B(-8,105,4,minecraft:soul_sand)
B(-8,106,4,minecraft:soul_sand)
B(-8,107,4,minecraft:soul_sand)
B(-8,108,4,minecraft:soul_sand)
B(-8,109,4,minecraft:soul_sand)
B(-8,110,4,minecraft:soul_sand)
B(-8,111,4,minecraft:soul_sand)
B(-8,0,5,minecraft:netherrack)
B(-8,1,5,minecraft:netherrack)
B(-8,2,5,minecraft:soul_sand)
B(-8,3,5,minecraft:soul_sand)
B(-8,4,5,minecraft:soul_sand)
B(-8,5,5,minecraft:soul_sand)
B(-8,6,5,minecraft:soul_sand)
B(-8,7,5,minecraft:soul_sand)
B(-8,100,5,minecraft:soul_sand)
B(-8,101,5,minecraft:soul_sand)
B(-8,102,5,minecraft:soul_sand)
B(-8,103,5,minecraft:soul_sand)
B(-8,104,5,minecraft:soul_sand)
B(-8,105,5,minecraft:soul_sand)
B(-8,106,5,minecraft:soul_sand)
B(-8,107,5,minecraft:soul_sand)
B(-8,108,5,minecraft:soul_sand)
B(-8,109,5,minecraft:soul_sand)
B(-8,110,5,minecraft:soul_sand)
B(-8,111,5,minecraft:soul_sand)
B(-8,0,6,minecraft:netherrack)
B(-8,1,6,minecraft:netherrack)
B(-8,2,6,minecraft:soul_soil)
B(-8,3,6,minecraft:soul_sand)
B(-8,4,6,minecraft:soul_sand)
B(-8,5,6,minecraft:soul_sand)
B(-8,6,6,minecraft:soul_sand)
B(-8,7,6,minecraft:soul_sand)
B(-8,100,6,minecraft:soul_sand)
B(-8,101,6,minecraft:soul_sand)
B(-8,102,6,minecraft:soul_sand)
B(-8,103,6,minecraft:soul_sand)
B(-8,104,6,minecraft:soul_sand)
B(-8,105,6,minecraft:soul_sand)
B(-8,106,6,minecraft:soul_sand)
B(-8,107,6,minecraft:soul_sand)
B(-8,108,6,minecraft:soul_sand)
B(-8,109,6,minecraft:soul_sand)
B(-8,110,6,minecraft:soul_sand)
B(-8,111,6,minecraft:soul_sand)
B(-8,0,7,minecraft:netherrack)
B(-8,1,7,minecraft:netherrack)
B(-8,2,7,minecraft:soul_soil)
B(-8,3,7,minecraft:soul_sand)
B(-8,4,7,minecraft:soul_sand)
B(-8,5,7,minecraft:soul_sand)
B(-8,6,7,minecraft:soul_sand)
B(-8,7,7,minecraft:soul_sand)
B(-8,8,7,minecraft:soul_sand)
B(-8,100,7,minecraft:soul_sand)
B(-8,101,7,minecraft:soul_sand)
B(-8,102,7,minecraft:soul_sand)
B(-8,103,7,minecraft:soul_sand)
B(-8,104,7,minecraft:soul_sand)
B(-8,105,7,minecraft:soul_sand)
B(-8,106,7,minecraft:soul_sand)
B(-8,107,7,minecraft:soul_sand)
B(-8,108,7,minecraft:soul_sand)
B(-8,109,7,minecraft:soul_sand)
B(-8,110,7,minecraft:soul_sand)
B(-8,111,7,minecraft:soul_sand)
B(-8,0,8,minecraft:netherrack)
B(-8,1,8,minecraft:netherrack)
B(-8,2,8,minecraft:soul_sand)
B(-8,3,8,minecraft:soul_sand)
B(-8,4,8,minecraft:soul_sand)
B(-8,5,8,minecraft:soul_sand)
B(-8,6,8,minecraft:soul_sand)
B(-8,7,8,minecraft:soul_sand)
B(-8,8,8,minecraft:soul_sand)
B(-8,9,8,minecraft:soul_sand)
B(-8,100,8,minecraft:soul_sand)
B(-8,101,8,minecraft:soul_sand)
B(-8,102,8,minecraft:soul_sand)
B(-8,103,8,minecraft:soul_sand)
B(-8,104,8,minecraft:soul_sand)
B(-8,105,8,minecraft:soul_sand)
B(-8,106,8,minecraft:soul_sand)
B(-8,107,8,minecraft:soul_sand)
B(-8,108,8,minecraft:soul_sand)
B(-8,109,8,minecraft:soul_sand)
B(-8,110,8,minecraft:soul_sand)
B(-8,111,8,minecraft:soul_sand)
B(-7,0,-7,minecraft:netherrack)
B(-7,1,-7,minecraft:netherrack)
B(-7,2,-7,minecraft:soul_soil)
B(-7,3,-7,minecraft:soul_soil)
B(-7,4,-7,minecraft:soul_soil)
B(-7,5,-7,minecraft:soul_soil)
B(-7,6,-7,minecraft:soul_sand)
B(-7,98,-7,minecraft:soul_sand)
B(-7,99,-7,minecraft:soul_sand)
B(-7,100,-7,minecraft:soul_sand)
B(-7,101,-7,minecraft:soul_sand)
B(-7,102,-7,minecraft:soul_sand)
B(-7,103,-7,minecraft:soul_sand)
B(-7,104,-7,minecraft:soul_sand)
B(-7,105,-7,minecraft:soul_sand)
B(-7,106,-7,minecraft:soul_sand)
B(-7,107,-7,minecraft:soul_sand)
B(-7,108,-7,minecraft:soul_sand)
B(-7,109,-7,minecraft:soul_sand)
B(-7,110,-7,minecraft:soul_sand)
B(-7,111,-7,minecraft:soul_sand)
B(-7,0,-6,minecraft:netherrack)
B(-7,1,-6,minecraft:netherrack)
B(-7,2,-6,minecraft:soul_soil)
B(-7,3,-6,minecraft:soul_soil)
B(-7,4,-6,minecraft:soul_soil)
B(-7,5,-6,minecraft:soul_soil)
B(-7,6,-6,minecraft:soul_sand)
B(-7,97,-6,minecraft:soul_sand)
B(-7,98,-6,minecraft:soul_sand)
B(-7,99,-6,minecraft:soul_sand)
B(-7,100,-6,minecraft:soul_sand)
B(-7,101,-6,minecraft:soul_sand)
B(-7,102,-6,minecraft:soul_sand)
B(-7,103,-6,minecraft:soul_sand)
B(-7,104,-6,minecraft:soul_sand)
B(-7,105,-6,minecraft:soul_sand)
B(-7,106,-6,minecraft:soul_sand)
B(-7,107,-6,minecraft:soul_sand)
B(-7,108,-6,minecraft:soul_sand)
B(-7,109,-6,minecraft:soul_sand)
B(-7,110,-6,minecraft:soul_sand)
B(-7,111,-6,minecraft:soul_sand)
B(-7,0,-5,minecraft:netherrack)
B(-7,1,-5,minecraft:netherrack)
B(-7,2,-5,minecraft:soul_soil)
B(-7,3,-5,minecraft:soul_soil)
B(-7,4,-5,minecraft:soul_soil)
B(-7,5,-5,minecraft:soul_sand)
B(-7,96,-5,minecraft:soul_sand)
B(-7,97,-5,minecraft:soul_sand)
B(-7,98,-5,minecraft:soul_sand)
B(-7,99,-5,minecraft:soul_sand)
B(-7,100,-5,minecraft:soul_sand)
B(-7,101,-5,minecraft:soul_sand)
B(-7,102,-5,minecraft:soul_sand)
B(-7,103,-5,minecraft:soul_sand)
B(-7,104,-5,minecraft:soul_sand)
B(-7,105,-5,minecraft:soul_sand)
B(-7,106,-5,minecraft:soul_sand)
B(-7,107,-5,minecraft:soul_sand)
B(-7,108,-5,minecraft:soul_sand)
B(-7,109,-5,minecraft:soul_sand)
B(-7,110,-5,minecraft:soul_sand)
B(-7,111,-5,minecraft:soul_sand)
B(-7,0,-4,minecraft:netherrack)
B(-7,1,-4,minecraft:netherrack)
B(-7,2,-4,minecraft:netherrack)
B(-7,3,-4,minecraft:soul_soil)
B(-7,4,-4,minecraft:soul_soil)
B(-7,5,-4,minecraft:soul_soil)
B(-7,6,-4,minecraft:soul_sand)
B(-7,95,-4,minecraft:soul_sand)
B(-7,96,-4,minecraft:soul_sand)
B(-7,97,-4,minecraft:soul_sand)
B(-7,98,-4,minecraft:soul_sand)
B(-7,99,-4,minecraft:soul_sand)
B(-7,100,-4,minecraft:soul_sand)
B(-7,101,-4,minecraft:soul_sand)
B(-7,102,-4,minecraft:soul_sand)
B(-7,103,-4,minecraft:soul_sand)
B(-7,104,-4,minecraft:soul_sand)
B(-7,105,-4,minecraft:soul_sand)
B(-7,106,-4,minecraft:soul_sand)
B(-7,107,-4,minecraft:soul_sand)
B(-7,108,-4,minecraft:soul_sand)
B(-7,109,-4,minecraft:soul_sand)
B(-7,110,-4,minecraft:soul_sand)
B(-7,111,-4,minecraft:soul_sand)
B(-7,0,-3,minecraft:netherrack)
B(-7,1,-3,minecraft:netherrack)
B(-7,2,-3,minecraft:netherrack)
B(-7,3,-3,minecraft:soul_soil)
B(-7,4,-3,minecraft:soul_soil)
B(-7,5,-3,minecraft:soul_soil)
B(-7,6,-3,minecraft:soul_sand)
B(-7,97,-3,minecraft:soul_sand)
B(-7,98,-3,minecraft:soul_sand)
B(-7,99,-3,minecraft:soul_sand)
B(-7,100,-3,minecraft:soul_sand)
B(-7,101,-3,minecraft:soul_sand)
B(-7,102,-3,minecraft:soul_sand)
B(-7,103,-3,minecraft:soul_sand)
B(-7,104,-3,minecraft:soul_sand)
B(-7,105,-3,minecraft:soul_sand)
B(-7,106,-3,minecraft:soul_sand)
B(-7,107,-3,minecraft:soul_sand)
B(-7,108,-3,minecraft:soul_sand)
B(-7,109,-3,minecraft:soul_sand)
B(-7,110,-3,minecraft:soul_sand)
B(-7,111,-3,minecraft:soul_sand)
B(-7,0,-2,minecraft:netherrack)
B(-7,1,-2,minecraft:netherrack)
B(-7,2,-2,minecraft:soul_sand)
B(-7,3,-2,minecraft:soul_sand)
B(-7,4,-2,minecraft:soul_sand)
B(-7,5,-2,minecraft:soul_sand)
B(-7,6,-2,minecraft:soul_sand)
B(-7,99,-2,minecraft:soul_sand)
B(-7,100,-2,minecraft:soul_sand)
B(-7,101,-2,minecraft:soul_sand)
B(-7,102,-2,minecraft:soul_sand)
B(-7,103,-2,minecraft:soul_sand)
B(-7,104,-2,minecraft:soul_sand)
B(-7,105,-2,minecraft:soul_sand)
B(-7,106,-2,minecraft:soul_sand)
B(-7,107,-2,minecraft:soul_sand)
B(-7,108,-2,minecraft:soul_sand)
B(-7,109,-2,minecraft:soul_sand)
B(-7,110,-2,minecraft:soul_sand)
B(-7,111,-2,minecraft:soul_sand)
B(-7,0,-1,minecraft:soul_sand)
B(-7,1,-1,minecraft:soul_sand)
B(-7,2,-1,minecraft:soul_sand)
B(-7,3,-1,minecraft:soul_sand)
B(-7,4,-1,minecraft:soul_sand)
B(-7,5,-1,minecraft:soul_sand)
B(-7,6,-1,minecraft:soul_sand)
B(-7,101,-1,minecraft:soul_sand)
B(-7,102,-1,minecraft:soul_sand)
B(-7,103,-1,minecraft:soul_sand)
B(-7,104,-1,minecraft:soul_sand)
B(-7,105,-1,minecraft:soul_sand)
B(-7,106,-1,minecraft:soul_sand)
B(-7,107,-1,minecraft:soul_sand)
B(-7,108,-1,minecraft:soul_sand)
B(-7,109,-1,minecraft:soul_sand)
B(-7,110,-1,minecraft:soul_sand)
B(-7,111,-1,minecraft:soul_sand)
B(-7,0,0,minecraft:soul_sand)
B(-7,1,0,minecraft:soul_sand)
B(-7,2,0,minecraft:soul_sand)
B(-7,3,0,minecraft:soul_sand)
B(-7,4,0,minecraft:soul_sand)
B(-7,5,0,minecraft:soul_sand)
B(-7,6,0,minecraft:soul_sand)
B(-7,102,0,minecraft:soul_sand)
B(-7,103,0,minecraft:soul_sand)
B(-7,104,0,minecraft:soul_sand)
B(-7,105,0,minecraft:soul_sand)
B(-7,106,0,minecraft:soul_sand)
B(-7,107,0,minecraft:soul_sand)
B(-7,108,0,minecraft:soul_sand)
B(-7,109,0,minecraft:soul_sand)
B(-7,110,0,minecraft:soul_sand)
B(-7,111,0,minecraft:soul_sand)
B(-7,0,1,minecraft:soul_sand)
B(-7,1,1,minecraft:soul_sand)
B(-7,2,1,minecraft:soul_sand)
B(-7,3,1,minecraft:soul_sand)
B(-7,4,1,minecraft:soul_sand)
B(-7,5,1,minecraft:soul_sand)
B(-7,6,1,minecraft:soul_sand)
B(-7,102,1,minecraft:soul_sand)
B(-7,103,1,minecraft:soul_sand)
B(-7,104,1,minecraft:soul_sand)
B(-7,105,1,minecraft:soul_sand)
B(-7,106,1,minecraft:soul_sand)
B(-7,107,1,minecraft:soul_sand)
B(-7,108,1,minecraft:soul_sand)
B(-7,109,1,minecraft:soul_sand)
B(-7,110,1,minecraft:soul_sand)
B(-7,111,1,minecraft:soul_sand)
B(-7,0,2,minecraft:soul_sand)
B(-7,1,2,minecraft:soul_sand)
B(-7,2,2,minecraft:soul_sand)
B(-7,3,2,minecraft:soul_sand)
B(-7,4,2,minecraft:soul_sand)
B(-7,5,2,minecraft:soul_sand)
B(-7,102,2,minecraft:soul_sand)
B(-7,103,2,minecraft:soul_sand)
B(-7,104,2,minecraft:soul_sand)
B(-7,105,2,minecraft:soul_sand)
B(-7,106,2,minecraft:soul_sand)
B(-7,107,2,minecraft:soul_sand)
B(-7,108,2,minecraft:soul_sand)
B(-7,109,2,minecraft:soul_sand)
B(-7,110,2,minecraft:soul_sand)
B(-7,111,2,minecraft:soul_sand)
B(-7,0,3,minecraft:soul_sand)
B(-7,1,3,minecraft:soul_sand)
B(-7,2,3,minecraft:soul_sand)
B(-7,3,3,minecraft:soul_sand)
B(-7,4,3,minecraft:soul_sand)
B(-7,5,3,minecraft:soul_sand)
B(-7,101,3,minecraft:soul_sand)
B(-7,102,3,minecraft:soul_sand)
B(-7,103,3,minecraft:soul_sand)
B(-7,104,3,minecraft:soul_sand)
B(-7,105,3,minecraft:soul_sand)
B(-7,106,3,minecraft:soul_sand)
B(-7,107,3,minecraft:soul_sand)
B(-7,108,3,minecraft:soul_sand)
B(-7,109,3,minecraft:soul_sand)
B(-7,110,3,minecraft:soul_sand)
B(-7,111,3,minecraft:soul_sand)
B(-7,0,4,minecraft:netherrack)
B(-7,1,4,minecraft:soul_sand)
B(-7,2,4,minecraft:soul_sand)
B(-7,3,4,minecraft:soul_sand)
B(-7,4,4,minecraft:soul_sand)
B(-7,5,4,minecraft:soul_sand)
B(-7,6,4,minecraft:soul_sand)
B(-7,101,4,minecraft:soul_sand)
B(-7,102,4,minecraft:soul_sand)
B(-7,103,4,minecraft:soul_sand)
B(-7,104,4,minecraft:soul_sand)
B(-7,105,4,minecraft:soul_sand)
B(-7,106,4,minecraft:soul_sand)
B(-7,107,4,minecraft:soul_sand)
B(-7,108,4,minecraft:soul_sand)
B(-7,109,4,minecraft:soul_sand)
B(-7,110,4,minecraft:soul_sand)
B(-7,111,4,minecraft:soul_sand)
B(-7,0,5,minecraft:netherrack)
B(-7,1,5,minecraft:netherrack)
B(-7,2,5,minecraft:netherrack)
B(-7,3,5,minecraft:netherrack)
B(-7,4,5,minecraft:soul_soil)
B(-7,100,5,minecraft:soul_sand)
B(-7,101,5,minecraft:soul_sand)
B(-7,102,5,minecraft:soul_sand)
B(-7,103,5,minecraft:soul_sand)
B(-7,104,5,minecraft:soul_sand)
B(-7,105,5,minecraft:soul_sand)
B(-7,106,5,minecraft:soul_sand)
B(-7,107,5,minecraft:soul_sand)
B(-7,108,5,minecraft:soul_sand)
B(-7,109,5,minecraft:soul_sand)
B(-7,110,5,minecraft:soul_sand)
B(-7,111,5,minecraft:soul_sand)
B(-7,0,6,minecraft:netherrack)
B(-7,1,6,minecraft:netherrack)
B(-7,2,6,minecraft:netherrack)
B(-7,3,6,minecraft:netherrack)
B(-7,4,6,minecraft:soul_soil)
B(-7,100,6,minecraft:soul_sand)
B(-7,101,6,minecraft:soul_sand)
B(-7,102,6,minecraft:soul_sand)
B(-7,103,6,minecraft:soul_sand)
B(-7,104,6,minecraft:soul_sand)
B(-7,105,6,minecraft:soul_sand)
B(-7,106,6,minecraft:soul_sand)
B(-7,107,6,minecraft:soul_sand)
B(-7,108,6,minecraft:soul_sand)
B(-7,109,6,minecraft:soul_sand)
B(-7,110,6,minecraft:soul_sand)
B(-7,111,6,minecraft:soul_sand)
B(-7,0,7,minecraft:netherrack)
B(-7,1,7,minecraft:netherrack)
B(-7,2,7,minecraft:netherrack)
B(-7,3,7,minecraft:soul_sand)
B(-7,4,7,minecraft:soul_sand)
B(-7,5,7,minecraft:soul_sand)
B(-7,6,7,minecraft:soul_sand)
B(-7,7,7,minecraft:soul_sand)
B(-7,99,7,minecraft:soul_sand)
B(-7,100,7,minecraft:soul_sand)
B(-7,101,7,minecraft:soul_sand)
B(-7,102,7,minecraft:soul_sand)
B(-7,103,7,minecraft:soul_sand)
B(-7,104,7,minecraft:soul_sand)
B(-7,105,7,minecraft:soul_sand)
B(-7,106,7,minecraft:soul_sand)
B(-7,107,7,minecraft:soul_sand)
B(-7,108,7,minecraft:soul_sand)
B(-7,109,7,minecraft:soul_sand)
B(-7,110,7,minecraft:soul_sand)
B(-7,111,7,minecraft:soul_sand)
B(-7,0,8,minecraft:netherrack)
B(-7,1,8,minecraft:netherrack)
B(-7,2,8,minecraft:netherrack)
B(-7,3,8,minecraft:soul_sand)
B(-7,4,8,minecraft:soul_sand)
B(-7,5,8,minecraft:soul_sand)
B(-7,6,8,minecraft:soul_sand)
B(-7,7,8,minecraft:soul_sand)
B(-7,8,8,minecraft:soul_sand)
B(-7,98,8,minecraft:soul_sand)
B(-7,99,8,minecraft:soul_sand)
B(-7,100,8,minecraft:soul_sand)
B(-7,101,8,minecraft:soul_sand)
B(-7,102,8,minecraft:soul_sand)
B(-7,103,8,minecraft:soul_sand)
B(-7,104,8,minecraft:soul_sand)
B(-7,105,8,minecraft:soul_sand)
B(-7,106,8,minecraft:soul_sand)
B(-7,107,8,minecraft:soul_sand)
B(-7,108,8,minecraft:soul_sand)
B(-7,109,8,minecraft:soul_sand)
B(-7,110,8,minecraft:soul_sand)
B(-7,111,8,minecraft:soul_sand)
B(-6,0,-7,minecraft:netherrack)
B(-6,1,-7,minecraft:netherrack)
B(-6,2,-7,minecraft:soul_soil)
B(-6,3,-7,minecraft:soul_soil)
B(-6,4,-7,minecraft:soul_sand)
B(-6,6,-7,minecraft:bone_block[axis=x])
B(-6,99,-7,minecraft:soul_sand)
B(-6,100,-7,minecraft:soul_sand)
B(-6,101,-7,minecraft:soul_sand)
B(-6,102,-7,minecraft:soul_sand)
B(-6,103,-7,minecraft:soul_sand)
B(-6,104,-7,minecraft:soul_sand)
B(-6,105,-7,minecraft:soul_sand)
B(-6,106,-7,minecraft:soul_sand)
B(-6,107,-7,minecraft:soul_sand)
B(-6,108,-7,minecraft:soul_sand)
B(-6,109,-7,minecraft:soul_sand)
B(-6,110,-7,minecraft:soul_sand)
B(-6,111,-7,minecraft:soul_sand)
B(-6,0,-6,minecraft:netherrack)
B(-6,1,-6,minecraft:netherrack)
B(-6,2,-6,minecraft:soul_soil)
B(-6,3,-6,minecraft:soul_soil)
B(-6,4,-6,minecraft:soul_soil)
B(-6,5,-6,minecraft:soul_soil)
B(-6,6,-6,minecraft:soul_sand)
B(-6,98,-6,minecraft:soul_sand)
B(-6,99,-6,minecraft:soul_sand)
B(-6,100,-6,minecraft:soul_sand)
B(-6,101,-6,minecraft:soul_sand)
B(-6,102,-6,minecraft:soul_sand)
B(-6,103,-6,minecraft:soul_sand)
B(-6,104,-6,minecraft:soul_sand)
B(-6,105,-6,minecraft:soul_sand)
B(-6,106,-6,minecraft:soul_sand)
B(-6,107,-6,minecraft:soul_sand)
B(-6,108,-6,minecraft:soul_sand)
B(-6,109,-6,minecraft:soul_sand)
B(-6,110,-6,minecraft:soul_sand)
B(-6,111,-6,minecraft:soul_sand)
B(-6,0,-5,minecraft:netherrack)
B(-6,1,-5,minecraft:netherrack)
B(-6,2,-5,minecraft:soul_soil)
B(-6,3,-5,minecraft:soul_soil)
B(-6,4,-5,minecraft:soul_soil)
B(-6,5,-5,minecraft:soul_sand)
B(-6,97,-5,minecraft:soul_sand)
B(-6,98,-5,minecraft:soul_sand)
B(-6,99,-5,minecraft:soul_sand)
B(-6,100,-5,minecraft:soul_sand)
B(-6,101,-5,minecraft:soul_sand)
B(-6,102,-5,minecraft:soul_sand)
B(-6,103,-5,minecraft:soul_sand)
B(-6,104,-5,minecraft:soul_sand)
B(-6,105,-5,minecraft:soul_sand)
B(-6,106,-5,minecraft:soul_sand)
B(-6,107,-5,minecraft:soul_sand)
B(-6,108,-5,minecraft:soul_sand)
B(-6,109,-5,minecraft:soul_sand)
B(-6,110,-5,minecraft:soul_sand)
B(-6,111,-5,minecraft:soul_sand)
B(-6,0,-4,minecraft:netherrack)
B(-6,1,-4,minecraft:netherrack)
B(-6,2,-4,minecraft:netherrack)
B(-6,3,-4,minecraft:soul_soil)
B(-6,4,-4,minecraft:soul_soil)
B(-6,5,-4,minecraft:soul_soil)
B(-6,6,-4,minecraft:soul_sand)
B(-6,96,-4,minecraft:soul_sand)
B(-6,97,-4,minecraft:soul_sand)
B(-6,98,-4,minecraft:soul_sand)
B(-6,99,-4,minecraft:soul_sand)
B(-6,100,-4,minecraft:soul_sand)
B(-6,101,-4,minecraft:soul_sand)
B(-6,102,-4,minecraft:soul_sand)
B(-6,103,-4,minecraft:soul_sand)
B(-6,104,-4,minecraft:soul_sand)
B(-6,105,-4,minecraft:soul_sand)
B(-6,106,-4,minecraft:soul_sand)
B(-6,107,-4,minecraft:soul_sand)
B(-6,108,-4,minecraft:soul_sand)
B(-6,109,-4,minecraft:soul_sand)
B(-6,110,-4,minecraft:soul_sand)
B(-6,111,-4,minecraft:soul_sand)
B(-6,0,-3,minecraft:netherrack)
B(-6,1,-3,minecraft:netherrack)
B(-6,2,-3,minecraft:soul_soil)
B(-6,3,-3,minecraft:soul_sand)
B(-6,6,-3,minecraft:bone_block[axis=x])
B(-6,97,-3,minecraft:soul_sand)
B(-6,98,-3,minecraft:soul_sand)
B(-6,99,-3,minecraft:soul_sand)
B(-6,100,-3,minecraft:soul_sand)
B(-6,101,-3,minecraft:soul_sand)
B(-6,102,-3,minecraft:soul_sand)
B(-6,103,-3,minecraft:soul_sand)
B(-6,104,-3,minecraft:soul_sand)
B(-6,105,-3,minecraft:soul_sand)
B(-6,106,-3,minecraft:soul_sand)
B(-6,107,-3,minecraft:soul_sand)
B(-6,108,-3,minecraft:soul_sand)
B(-6,109,-3,minecraft:soul_sand)
B(-6,110,-3,minecraft:soul_sand)
B(-6,111,-3,minecraft:soul_sand)
B(-6,0,-2,minecraft:netherrack)
B(-6,1,-2,minecraft:netherrack)
B(-6,2,-2,minecraft:netherrack)
B(-6,3,-2,minecraft:soul_soil)
B(-6,4,-2,minecraft:soul_soil)
B(-6,5,-2,minecraft:soul_soil)
B(-6,6,-2,minecraft:soul_sand)
B(-6,98,-2,minecraft:soul_sand)
B(-6,99,-2,minecraft:soul_sand)
B(-6,100,-2,minecraft:soul_sand)
B(-6,101,-2,minecraft:soul_sand)
B(-6,102,-2,minecraft:soul_sand)
B(-6,103,-2,minecraft:soul_sand)
B(-6,104,-2,minecraft:soul_sand)
B(-6,105,-2,minecraft:soul_sand)
B(-6,106,-2,minecraft:soul_sand)
B(-6,107,-2,minecraft:soul_sand)
B(-6,108,-2,minecraft:soul_sand)
B(-6,109,-2,minecraft:soul_sand)
B(-6,110,-2,minecraft:soul_sand)
B(-6,111,-2,minecraft:soul_sand)
B(-6,0,-1,minecraft:netherrack)
B(-6,1,-1,minecraft:netherrack)
B(-6,2,-1,minecraft:soul_sand)
B(-6,3,-1,minecraft:soul_sand)
B(-6,4,-1,minecraft:soul_sand)
B(-6,5,-1,minecraft:soul_sand)
B(-6,99,-1,minecraft:soul_sand)
B(-6,100,-1,minecraft:soul_sand)
B(-6,101,-1,minecraft:soul_sand)
B(-6,102,-1,minecraft:soul_sand)
B(-6,103,-1,minecraft:soul_sand)
B(-6,104,-1,minecraft:soul_sand)
B(-6,105,-1,minecraft:soul_sand)
B(-6,106,-1,minecraft:soul_sand)
B(-6,107,-1,minecraft:soul_sand)
B(-6,108,-1,minecraft:soul_sand)
B(-6,109,-1,minecraft:soul_sand)
B(-6,110,-1,minecraft:soul_sand)
B(-6,111,-1,minecraft:soul_sand)
B(-6,0,0,minecraft:netherrack)
B(-6,1,0,minecraft:soul_sand)
B(-6,2,0,minecraft:soul_sand)
B(-6,3,0,minecraft:soul_sand)
B(-6,4,0,minecraft:soul_sand)
B(-6,5,0,minecraft:soul_sand)
B(-6,100,0,minecraft:soul_sand)
B(-6,101,0,minecraft:soul_sand)
B(-6,102,0,minecraft:soul_sand)
B(-6,103,0,minecraft:soul_sand)
B(-6,104,0,minecraft:soul_sand)
B(-6,105,0,minecraft:soul_sand)
B(-6,106,0,minecraft:soul_sand)
B(-6,107,0,minecraft:soul_sand)
B(-6,108,0,minecraft:soul_sand)
B(-6,109,0,minecraft:soul_sand)
B(-6,110,0,minecraft:soul_sand)
B(-6,111,0,minecraft:soul_sand)
B(-6,0,1,minecraft:netherrack)
B(-6,1,1,minecraft:soul_sand)
B(-6,2,1,minecraft:soul_sand)
B(-6,3,1,minecraft:soul_sand)
B(-6,4,1,minecraft:soul_sand)
B(-6,5,1,minecraft:soul_sand)
B(-6,100,1,minecraft:soul_sand)
B(-6,101,1,minecraft:soul_sand)
B(-6,102,1,minecraft:soul_sand)
B(-6,103,1,minecraft:soul_sand)
B(-6,104,1,minecraft:soul_sand)
B(-6,105,1,minecraft:soul_sand)
B(-6,106,1,minecraft:soul_sand)
B(-6,107,1,minecraft:soul_sand)
B(-6,108,1,minecraft:soul_sand)
B(-6,109,1,minecraft:soul_sand)
B(-6,110,1,minecraft:soul_sand)
B(-6,111,1,minecraft:soul_sand)
B(-6,0,2,minecraft:netherrack)
B(-6,1,2,minecraft:soul_sand)
B(-6,2,2,minecraft:soul_sand)
B(-6,3,2,minecraft:soul_sand)
B(-6,4,2,minecraft:soul_sand)
B(-6,100,2,minecraft:soul_sand)
B(-6,101,2,minecraft:soul_sand)
B(-6,102,2,minecraft:soul_sand)
B(-6,103,2,minecraft:soul_sand)
B(-6,104,2,minecraft:soul_sand)
B(-6,105,2,minecraft:soul_sand)
B(-6,106,2,minecraft:soul_sand)
B(-6,107,2,minecraft:soul_sand)
B(-6,108,2,minecraft:soul_sand)
B(-6,109,2,minecraft:soul_sand)
B(-6,110,2,minecraft:soul_sand)
B(-6,111,2,minecraft:soul_sand)
B(-6,0,3,minecraft:netherrack)
B(-6,1,3,minecraft:netherrack)
B(-6,2,3,minecraft:soul_sand)
B(-6,3,3,minecraft:soul_sand)
B(-6,4,3,minecraft:soul_sand)
B(-6,100,3,minecraft:soul_sand)
B(-6,101,3,minecraft:soul_sand)
B(-6,102,3,minecraft:soul_sand)
B(-6,103,3,minecraft:soul_sand)
B(-6,104,3,minecraft:soul_sand)
B(-6,105,3,minecraft:soul_sand)
B(-6,106,3,minecraft:soul_sand)
B(-6,107,3,minecraft:soul_sand)
B(-6,108,3,minecraft:soul_sand)
B(-6,109,3,minecraft:soul_sand)
B(-6,110,3,minecraft:soul_sand)
B(-6,111,3,minecraft:soul_sand)
B(-6,0,4,minecraft:netherrack)
B(-6,1,4,minecraft:netherrack)
B(-6,2,4,minecraft:netherrack)
B(-6,3,4,minecraft:soul_soil)
B(-6,100,4,minecraft:soul_sand)
B(-6,101,4,minecraft:soul_sand)
B(-6,102,4,minecraft:soul_sand)
B(-6,103,4,minecraft:soul_sand)
B(-6,104,4,minecraft:soul_sand)
B(-6,105,4,minecraft:soul_sand)
B(-6,106,4,minecraft:soul_sand)
B(-6,107,4,minecraft:soul_sand)
B(-6,108,4,minecraft:soul_sand)
B(-6,109,4,minecraft:soul_sand)
B(-6,110,4,minecraft:soul_sand)
B(-6,111,4,minecraft:soul_sand)
B(-6,0,5,minecraft:netherrack)
B(-6,1,5,minecraft:netherrack)
B(-6,2,5,minecraft:netherrack)
B(-6,3,5,minecraft:soul_soil)
B(-6,100,5,minecraft:soul_sand)
B(-6,101,5,minecraft:soul_sand)
B(-6,102,5,minecraft:soul_sand)
B(-6,103,5,minecraft:soul_sand)
B(-6,104,5,minecraft:soul_sand)
B(-6,105,5,minecraft:soul_sand)
B(-6,106,5,minecraft:soul_sand)
B(-6,107,5,minecraft:soul_sand)
B(-6,108,5,minecraft:soul_sand)
B(-6,109,5,minecraft:soul_sand)
B(-6,110,5,minecraft:soul_sand)
B(-6,111,5,minecraft:soul_sand)
B(-6,0,6,minecraft:netherrack)
B(-6,1,6,minecraft:netherrack)
B(-6,2,6,minecraft:netherrack)
B(-6,3,6,minecraft:netherrack)
B(-6,99,6,minecraft:soul_sand)
B(-6,100,6,minecraft:soul_sand)
B(-6,101,6,minecraft:soul_sand)
B(-6,102,6,minecraft:soul_sand)
B(-6,103,6,minecraft:soul_sand)
B(-6,104,6,minecraft:soul_sand)
B(-6,105,6,minecraft:soul_sand)
B(-6,106,6,minecraft:soul_sand)
B(-6,107,6,minecraft:soul_sand)
B(-6,108,6,minecraft:soul_sand)
B(-6,109,6,minecraft:soul_sand)
B(-6,110,6,minecraft:soul_sand)
B(-6,111,6,minecraft:soul_sand)
B(-6,0,7,minecraft:netherrack)
B(-6,1,7,minecraft:netherrack)
B(-6,2,7,minecraft:netherrack)
B(-6,3,7,minecraft:lava)
B(-6,98,7,minecraft:soul_sand)
B(-6,99,7,minecraft:soul_sand)
B(-6,100,7,minecraft:soul_sand)
B(-6,101,7,minecraft:soul_sand)
B(-6,102,7,minecraft:soul_sand)
B(-6,103,7,minecraft:soul_sand)
B(-6,104,7,minecraft:soul_sand)
B(-6,105,7,minecraft:soul_sand)
B(-6,106,7,minecraft:soul_sand)
B(-6,107,7,minecraft:soul_sand)
B(-6,108,7,minecraft:soul_sand)
B(-6,109,7,minecraft:soul_sand)
B(-6,110,7,minecraft:soul_sand)
B(-6,111,7,minecraft:soul_sand)
B(-6,0,8,minecraft:netherrack)
B(-6,1,8,minecraft:netherrack)
B(-6,2,8,minecraft:netherrack)
B(-6,3,8,minecraft:soul_sand)
B(-6,4,8,minecraft:soul_sand)
B(-6,5,8,minecraft:soul_sand)
B(-6,6,8,minecraft:soul_sand)
B(-6,7,8,minecraft:soul_sand)
B(-6,97,8,minecraft:soul_sand)
B(-6,98,8,minecraft:soul_sand)
B(-6,99,8,minecraft:soul_sand)
B(-6,100,8,minecraft:soul_sand)
B(-6,101,8,minecraft:soul_sand)
B(-6,102,8,minecraft:soul_sand)
B(-6,103,8,minecraft:soul_sand)
B(-6,104,8,minecraft:soul_sand)
B(-6,105,8,minecraft:soul_sand)
B(-6,106,8,minecraft:soul_sand)
B(-6,107,8,minecraft:soul_sand)
B(-6,108,8,minecraft:soul_sand)
B(-6,109,8,minecraft:soul_sand)
B(-6,110,8,minecraft:soul_sand)
B(-6,111,8,minecraft:soul_sand)
B(-5,0,-7,minecraft:netherrack)
B(-5,1,-7,minecraft:netherrack)
B(-5,2,-7,minecraft:soul_soil)
B(-5,3,-7,minecraft:soul_soil)
B(-5,4,-7,minecraft:soul_soil)
B(-5,5,-7,minecraft:soul_sand)
B(-5,11,-7,minecraft:bone_block[axis=x])
B(-5,101,-7,minecraft:soul_sand)
B(-5,102,-7,minecraft:soul_sand)
B(-5,103,-7,minecraft:soul_sand)
B(-5,104,-7,minecraft:soul_sand)
B(-5,105,-7,minecraft:soul_sand)
B(-5,106,-7,minecraft:soul_sand)
B(-5,107,-7,minecraft:soul_sand)
B(-5,108,-7,minecraft:soul_sand)
B(-5,109,-7,minecraft:soul_sand)
B(-5,110,-7,minecraft:soul_sand)
B(-5,111,-7,minecraft:soul_sand)
B(-5,0,-6,minecraft:netherrack)
B(-5,1,-6,minecraft:netherrack)
B(-5,2,-6,minecraft:soul_soil)
B(-5,3,-6,minecraft:soul_soil)
B(-5,4,-6,minecraft:soul_soil)
B(-5,5,-6,minecraft:soul_sand)
B(-5,100,-6,minecraft:soul_sand)
B(-5,101,-6,minecraft:soul_sand)
B(-5,102,-6,minecraft:soul_sand)
B(-5,103,-6,minecraft:soul_sand)
B(-5,104,-6,minecraft:soul_sand)
B(-5,105,-6,minecraft:soul_sand)
B(-5,106,-6,minecraft:soul_sand)
B(-5,107,-6,minecraft:soul_sand)
B(-5,108,-6,minecraft:soul_sand)
B(-5,109,-6,minecraft:soul_sand)
B(-5,110,-6,minecraft:soul_sand)
B(-5,111,-6,minecraft:soul_sand)
B(-5,0,-5,minecraft:netherrack)
B(-5,1,-5,minecraft:netherrack)
B(-5,2,-5,minecraft:soul_soil)
B(-5,3,-5,minecraft:soul_soil)
B(-5,4,-5,minecraft:soul_soil)
B(-5,5,-5,minecraft:soul_sand)
B(-5,99,-5,minecraft:soul_sand)
B(-5,100,-5,minecraft:soul_sand)
B(-5,101,-5,minecraft:soul_sand)
B(-5,102,-5,minecraft:soul_sand)
B(-5,103,-5,minecraft:soul_sand)
B(-5,104,-5,minecraft:soul_sand)
B(-5,105,-5,minecraft:soul_sand)
B(-5,106,-5,minecraft:soul_sand)
B(-5,107,-5,minecraft:soul_sand)
B(-5,108,-5,minecraft:soul_sand)
B(-5,109,-5,minecraft:soul_sand)
B(-5,110,-5,minecraft:soul_sand)
B(-5,111,-5,minecraft:soul_sand)
B(-5,0,-4,minecraft:netherrack)
B(-5,1,-4,minecraft:netherrack)
B(-5,2,-4,minecraft:netherrack)
B(-5,3,-4,minecraft:soul_soil)
B(-5,4,-4,minecraft:soul_soil)
B(-5,5,-4,minecraft:soul_soil)
B(-5,6,-4,minecraft:soul_sand)
B(-5,98,-4,minecraft:soul_sand)
B(-5,99,-4,minecraft:soul_sand)
B(-5,100,-4,minecraft:soul_sand)
B(-5,101,-4,minecraft:soul_sand)
B(-5,102,-4,minecraft:soul_sand)
B(-5,103,-4,minecraft:soul_sand)
B(-5,104,-4,minecraft:soul_sand)
B(-5,105,-4,minecraft:soul_sand)
B(-5,106,-4,minecraft:soul_sand)
B(-5,107,-4,minecraft:soul_sand)
B(-5,108,-4,minecraft:soul_sand)
B(-5,109,-4,minecraft:soul_sand)
B(-5,110,-4,minecraft:soul_sand)
B(-5,111,-4,minecraft:soul_sand)
B(-5,0,-3,minecraft:netherrack)
B(-5,1,-3,minecraft:netherrack)
B(-5,2,-3,minecraft:soul_soil)
B(-5,3,-3,minecraft:soul_sand)
B(-5,6,-3,minecraft:bone_block[axis=x])
B(-5,98,-3,minecraft:soul_sand)
B(-5,99,-3,minecraft:soul_sand)
B(-5,100,-3,minecraft:soul_sand)
B(-5,101,-3,minecraft:soul_sand)
B(-5,102,-3,minecraft:soul_sand)
B(-5,103,-3,minecraft:soul_sand)
B(-5,104,-3,minecraft:soul_sand)
B(-5,105,-3,minecraft:soul_sand)
B(-5,106,-3,minecraft:soul_sand)
B(-5,107,-3,minecraft:soul_sand)
B(-5,108,-3,minecraft:soul_sand)
B(-5,109,-3,minecraft:soul_sand)
B(-5,110,-3,minecraft:soul_sand)
B(-5,111,-3,minecraft:soul_sand)
B(-5,0,-2,minecraft:netherrack)
B(-5,1,-2,minecraft:netherrack)
B(-5,2,-2,minecraft:netherrack)
B(-5,3,-2,minecraft:soul_soil)
B(-5,4,-2,minecraft:soul_soil)
B(-5,5,-2,minecraft:soul_soil)
B(-5,6,-2,minecraft:soul_sand)
B(-5,98,-2,minecraft:soul_sand)
B(-5,99,-2,minecraft:soul_sand)
B(-5,100,-2,minecraft:soul_sand)
B(-5,101,-2,minecraft:soul_sand)
B(-5,102,-2,minecraft:soul_sand)
B(-5,103,-2,minecraft:soul_sand)
B(-5,104,-2,minecraft:soul_sand)
B(-5,105,-2,minecraft:soul_sand)
B(-5,106,-2,minecraft:soul_sand)
B(-5,107,-2,minecraft:soul_sand)
B(-5,108,-2,minecraft:soul_sand)
B(-5,109,-2,minecraft:soul_sand)
B(-5,110,-2,minecraft:soul_sand)
B(-5,111,-2,minecraft:soul_sand)
B(-5,0,-1,minecraft:netherrack)
B(-5,1,-1,minecraft:netherrack)
B(-5,2,-1,minecraft:soul_soil)
B(-5,3,-1,minecraft:soul_soil)
B(-5,4,-1,minecraft:soul_soil)
B(-5,5,-1,minecraft:soul_sand)
B(-5,98,-1,minecraft:soul_sand)
B(-5,99,-1,minecraft:soul_sand)
B(-5,100,-1,minecraft:soul_sand)
B(-5,101,-1,minecraft:soul_sand)
B(-5,102,-1,minecraft:soul_sand)
B(-5,103,-1,minecraft:soul_sand)
B(-5,104,-1,minecraft:soul_sand)
B(-5,105,-1,minecraft:soul_sand)
B(-5,106,-1,minecraft:soul_sand)
B(-5,107,-1,minecraft:soul_sand)
B(-5,108,-1,minecraft:soul_sand)
B(-5,109,-1,minecraft:soul_sand)
B(-5,110,-1,minecraft:soul_sand)
B(-5,111,-1,minecraft:soul_sand)
B(-5,0,0,minecraft:netherrack)
B(-5,1,0,minecraft:netherrack)
B(-5,2,0,minecraft:soul_soil)
B(-5,3,0,minecraft:soul_soil)
B(-5,4,0,minecraft:soul_sand)
B(-5,98,0,minecraft:soul_sand)
B(-5,99,0,minecraft:soul_sand)
B(-5,100,0,minecraft:soul_sand)
B(-5,101,0,minecraft:soul_sand)
B(-5,102,0,minecraft:soul_sand)
B(-5,103,0,minecraft:soul_sand)
B(-5,104,0,minecraft:soul_sand)
B(-5,105,0,minecraft:soul_sand)
B(-5,106,0,minecraft:soul_sand)
B(-5,107,0,minecraft:soul_sand)
B(-5,108,0,minecraft:soul_sand)
B(-5,109,0,minecraft:soul_sand)
B(-5,110,0,minecraft:soul_sand)
B(-5,111,0,minecraft:soul_sand)
B(-5,0,1,minecraft:netherrack)
B(-5,1,1,minecraft:netherrack)
B(-5,2,1,minecraft:netherrack)
B(-5,3,1,minecraft:netherrack)
B(-5,4,1,minecraft:soul_soil)
B(-5,98,1,minecraft:soul_sand)
B(-5,99,1,minecraft:soul_sand)
B(-5,100,1,minecraft:soul_sand)
B(-5,101,1,minecraft:soul_sand)
B(-5,102,1,minecraft:soul_sand)
B(-5,103,1,minecraft:soul_sand)
B(-5,104,1,minecraft:soul_sand)
B(-5,105,1,minecraft:soul_sand)
B(-5,106,1,minecraft:soul_sand)
B(-5,107,1,minecraft:soul_sand)
B(-5,108,1,minecraft:soul_sand)
B(-5,109,1,minecraft:soul_sand)
B(-5,110,1,minecraft:soul_sand)
B(-5,111,1,minecraft:soul_sand)
B(-5,0,2,minecraft:netherrack)
B(-5,1,2,minecraft:netherrack)
B(-5,2,2,minecraft:netherrack)
B(-5,3,2,minecraft:netherrack)
B(-5,99,2,minecraft:soul_sand)
B(-5,100,2,minecraft:soul_sand)
B(-5,101,2,minecraft:soul_sand)
B(-5,102,2,minecraft:soul_sand)
B(-5,103,2,minecraft:soul_sand)
B(-5,104,2,minecraft:soul_sand)
B(-5,105,2,minecraft:soul_sand)
B(-5,106,2,minecraft:soul_sand)
B(-5,107,2,minecraft:soul_sand)
B(-5,108,2,minecraft:soul_sand)
B(-5,109,2,minecraft:soul_sand)
B(-5,110,2,minecraft:soul_sand)
B(-5,111,2,minecraft:soul_sand)
B(-5,0,3,minecraft:netherrack)
B(-5,1,3,minecraft:netherrack)
B(-5,2,3,minecraft:netherrack)
B(-5,3,3,minecraft:netherrack)
B(-5,99,3,minecraft:soul_sand)
B(-5,100,3,minecraft:soul_sand)
B(-5,101,3,minecraft:soul_sand)
B(-5,102,3,minecraft:soul_sand)
B(-5,103,3,minecraft:soul_sand)
B(-5,104,3,minecraft:soul_sand)
B(-5,105,3,minecraft:soul_sand)
B(-5,106,3,minecraft:soul_sand)
B(-5,107,3,minecraft:soul_sand)
B(-5,108,3,minecraft:soul_sand)
B(-5,109,3,minecraft:soul_sand)
B(-5,110,3,minecraft:soul_sand)
B(-5,111,3,minecraft:soul_sand)
B(-5,0,4,minecraft:netherrack)
B(-5,1,4,minecraft:netherrack)
B(-5,2,4,minecraft:netherrack)
B(-5,3,4,minecraft:netherrack)
B(-5,100,4,minecraft:soul_sand)
B(-5,101,4,minecraft:soul_sand)
B(-5,102,4,minecraft:soul_sand)
B(-5,103,4,minecraft:soul_sand)
B(-5,104,4,minecraft:soul_sand)
B(-5,105,4,minecraft:soul_sand)
B(-5,106,4,minecraft:soul_sand)
B(-5,107,4,minecraft:soul_sand)
B(-5,108,4,minecraft:soul_sand)
B(-5,109,4,minecraft:soul_sand)
B(-5,110,4,minecraft:soul_sand)
B(-5,111,4,minecraft:soul_sand)
B(-5,0,5,minecraft:netherrack)
B(-5,1,5,minecraft:netherrack)
B(-5,2,5,minecraft:netherrack)
B(-5,3,5,minecraft:lava)
B(-5,99,5,minecraft:soul_sand)
B(-5,100,5,minecraft:soul_sand)
B(-5,101,5,minecraft:soul_sand)
B(-5,102,5,minecraft:soul_sand)
B(-5,103,5,minecraft:soul_sand)
B(-5,104,5,minecraft:soul_sand)
B(-5,105,5,minecraft:soul_sand)
B(-5,106,5,minecraft:soul_sand)
B(-5,107,5,minecraft:soul_sand)
B(-5,108,5,minecraft:soul_sand)
B(-5,109,5,minecraft:soul_sand)
B(-5,110,5,minecraft:soul_sand)
B(-5,111,5,minecraft:soul_sand)
B(-5,0,6,minecraft:netherrack)
B(-5,1,6,minecraft:netherrack)
B(-5,2,6,minecraft:netherrack)
B(-5,3,6,minecraft:lava)
B(-5,98,6,minecraft:soul_sand)
B(-5,99,6,minecraft:soul_sand)
B(-5,100,6,minecraft:soul_sand)
B(-5,101,6,minecraft:soul_sand)
B(-5,102,6,minecraft:soul_sand)
B(-5,103,6,minecraft:soul_sand)
B(-5,104,6,minecraft:soul_sand)
B(-5,105,6,minecraft:soul_sand)
B(-5,106,6,minecraft:soul_sand)
B(-5,107,6,minecraft:soul_sand)
B(-5,108,6,minecraft:soul_sand)
B(-5,109,6,minecraft:soul_sand)
B(-5,110,6,minecraft:soul_sand)
B(-5,111,6,minecraft:soul_sand)
B(-5,0,7,minecraft:netherrack)
B(-5,1,7,minecraft:netherrack)
B(-5,2,7,minecraft:netherrack)
B(-5,3,7,minecraft:lava)
B(-5,97,7,minecraft:soul_sand)
B(-5,98,7,minecraft:soul_sand)
B(-5,99,7,minecraft:soul_sand)
B(-5,100,7,minecraft:soul_sand)
B(-5,101,7,minecraft:soul_sand)
B(-5,102,7,minecraft:soul_sand)
B(-5,103,7,minecraft:soul_sand)
B(-5,104,7,minecraft:soul_sand)
B(-5,105,7,minecraft:soul_sand)
B(-5,106,7,minecraft:soul_sand)
B(-5,107,7,minecraft:soul_sand)
B(-5,108,7,minecraft:soul_sand)
B(-5,109,7,minecraft:soul_sand)
B(-5,110,7,minecraft:soul_sand)
B(-5,111,7,minecraft:soul_sand)
B(-5,0,8,minecraft:netherrack)
B(-5,1,8,minecraft:netherrack)
B(-5,2,8,minecraft:netherrack)
B(-5,3,8,minecraft:lava)
B(-5,96,8,minecraft:soul_sand)
B(-5,97,8,minecraft:soul_sand)
B(-5,98,8,minecraft:soul_sand)
B(-5,99,8,minecraft:soul_sand)
B(-5,100,8,minecraft:soul_sand)
B(-5,101,8,minecraft:soul_sand)
B(-5,102,8,minecraft:soul_sand)
B(-5,103,8,minecraft:soul_sand)
B(-5,104,8,minecraft:soul_sand)
B(-5,105,8,minecraft:soul_sand)
B(-5,106,8,minecraft:soul_sand)
B(-5,107,8,minecraft:soul_sand)
B(-5,108,8,minecraft:soul_sand)
B(-5,109,8,minecraft:soul_sand)
B(-5,110,8,minecraft:soul_sand)
B(-5,111,8,minecraft:soul_sand)
B(-4,0,-7,minecraft:netherrack)
B(-4,1,-7,minecraft:netherrack)
B(-4,2,-7,minecraft:soul_soil)
B(-4,3,-7,minecraft:soul_soil)
B(-4,4,-7,minecraft:soul_soil)
B(-4,5,-7,minecraft:soul_sand)
B(-4,11,-7,minecraft:bone_block[axis=x])
B(-4,102,-7,minecraft:soul_sand)
B(-4,103,-7,minecraft:soul_sand)
B(-4,104,-7,minecraft:soul_sand)
B(-4,105,-7,minecraft:soul_sand)
B(-4,106,-7,minecraft:soul_sand)
B(-4,107,-7,minecraft:soul_sand)
B(-4,108,-7,minecraft:soul_sand)
B(-4,109,-7,minecraft:soul_sand)
B(-4,110,-7,minecraft:soul_sand)
B(-4,111,-7,minecraft:soul_sand)
B(-4,0,-6,minecraft:netherrack)
B(-4,1,-6,minecraft:netherrack)
B(-4,2,-6,minecraft:soul_soil)
B(-4,3,-6,minecraft:soul_soil)
B(-4,4,-6,minecraft:soul_soil)
B(-4,5,-6,minecraft:soul_sand)
B(-4,101,-6,minecraft:soul_sand)
B(-4,102,-6,minecraft:soul_sand)
B(-4,103,-6,minecraft:soul_sand)
B(-4,104,-6,minecraft:soul_sand)
B(-4,105,-6,minecraft:soul_sand)
B(-4,106,-6,minecraft:soul_sand)
B(-4,107,-6,minecraft:soul_sand)
B(-4,108,-6,minecraft:soul_sand)
B(-4,109,-6,minecraft:soul_sand)
B(-4,110,-6,minecraft:soul_sand)
B(-4,111,-6,minecraft:soul_sand)
B(-4,0,-5,minecraft:netherrack)
B(-4,1,-5,minecraft:netherrack)
B(-4,2,-5,minecraft:soul_soil)
B(-4,3,-5,minecraft:soul_soil)
B(-4,4,-5,minecraft:soul_soil)
B(-4,5,-5,minecraft:soul_sand)
B(-4,100,-5,minecraft:soul_sand)
B(-4,101,-5,minecraft:soul_sand)
B(-4,102,-5,minecraft:soul_sand)
B(-4,103,-5,minecraft:soul_sand)
B(-4,104,-5,minecraft:soul_sand)
B(-4,105,-5,minecraft:soul_sand)
B(-4,106,-5,minecraft:soul_sand)
B(-4,107,-5,minecraft:soul_sand)
B(-4,108,-5,minecraft:soul_sand)
B(-4,109,-5,minecraft:soul_sand)
B(-4,110,-5,minecraft:soul_sand)
B(-4,111,-5,minecraft:soul_sand)
B(-4,0,-4,minecraft:netherrack)
B(-4,1,-4,minecraft:netherrack)
B(-4,2,-4,minecraft:netherrack)
B(-4,3,-4,minecraft:soul_soil)
B(-4,4,-4,minecraft:soul_soil)
B(-4,5,-4,minecraft:soul_soil)
B(-4,6,-4,minecraft:soul_sand)
B(-4,99,-4,minecraft:soul_sand)
B(-4,100,-4,minecraft:soul_sand)
B(-4,101,-4,minecraft:soul_sand)
B(-4,102,-4,minecraft:soul_sand)
B(-4,103,-4,minecraft:soul_sand)
B(-4,104,-4,minecraft:soul_sand)
B(-4,105,-4,minecraft:soul_sand)
B(-4,106,-4,minecraft:soul_sand)
B(-4,107,-4,minecraft:soul_sand)
B(-4,108,-4,minecraft:soul_sand)
B(-4,109,-4,minecraft:soul_sand)
B(-4,110,-4,minecraft:soul_sand)
B(-4,111,-4,minecraft:soul_sand)
B(-4,0,-3,minecraft:netherrack)
B(-4,1,-3,minecraft:netherrack)
B(-4,2,-3,minecraft:soul_soil)
B(-4,3,-3,minecraft:soul_soil)
B(-4,4,-3,minecraft:bone_block)
B(-4,5,-3,minecraft:bone_block)
B(-4,6,-3,minecraft:bone_block)
B(-4,99,-3,minecraft:soul_sand)
B(-4,100,-3,minecraft:soul_sand)
B(-4,101,-3,minecraft:soul_sand)
B(-4,102,-3,minecraft:soul_sand)
B(-4,103,-3,minecraft:soul_sand)
B(-4,104,-3,minecraft:soul_sand)
B(-4,105,-3,minecraft:soul_sand)
B(-4,106,-3,minecraft:soul_sand)
B(-4,107,-3,minecraft:soul_sand)
B(-4,108,-3,minecraft:soul_sand)
B(-4,109,-3,minecraft:soul_sand)
B(-4,110,-3,minecraft:soul_sand)
B(-4,111,-3,minecraft:soul_sand)
B(-4,0,-2,minecraft:netherrack)
B(-4,1,-2,minecraft:netherrack)
B(-4,2,-2,minecraft:soul_soil)
B(-4,3,-2,minecraft:soul_soil)
B(-4,4,-2,minecraft:soul_soil)
B(-4,5,-2,minecraft:soul_sand)
B(-4,99,-2,minecraft:soul_sand)
B(-4,100,-2,minecraft:soul_sand)
B(-4,101,-2,minecraft:soul_sand)
B(-4,102,-2,minecraft:soul_sand)
B(-4,103,-2,minecraft:soul_sand)
B(-4,104,-2,minecraft:soul_sand)
B(-4,105,-2,minecraft:soul_sand)
B(-4,106,-2,minecraft:soul_sand)
B(-4,107,-2,minecraft:soul_sand)
B(-4,108,-2,minecraft:soul_sand)
B(-4,109,-2,minecraft:soul_sand)
B(-4,110,-2,minecraft:soul_sand)
B(-4,111,-2,minecraft:soul_sand)
B(-4,0,-1,minecraft:netherrack)
B(-4,1,-1,minecraft:netherrack)
B(-4,2,-1,minecraft:soul_soil)
B(-4,3,-1,minecraft:soul_soil)
B(-4,4,-1,minecraft:soul_soil)
B(-4,5,-1,minecraft:soul_sand)
B(-4,99,-1,minecraft:soul_sand)
B(-4,100,-1,minecraft:soul_sand)
B(-4,101,-1,minecraft:soul_sand)
B(-4,102,-1,minecraft:soul_sand)
B(-4,103,-1,minecraft:soul_sand)
B(-4,104,-1,minecraft:soul_sand)
B(-4,105,-1,minecraft:soul_sand)
B(-4,106,-1,minecraft:soul_sand)
B(-4,107,-1,minecraft:soul_sand)
B(-4,108,-1,minecraft:soul_sand)
B(-4,109,-1,minecraft:soul_sand)
B(-4,110,-1,minecraft:soul_sand)
B(-4,111,-1,minecraft:soul_sand)
B(-4,0,0,minecraft:netherrack)
B(-4,1,0,minecraft:netherrack)
B(-4,2,0,minecraft:soul_soil)
B(-4,3,0,minecraft:soul_soil)
B(-4,4,0,minecraft:soul_sand)
B(-4,99,0,minecraft:soul_sand)
B(-4,100,0,minecraft:soul_sand)
B(-4,101,0,minecraft:soul_sand)
B(-4,102,0,minecraft:soul_sand)
B(-4,103,0,minecraft:soul_sand)
B(-4,104,0,minecraft:soul_sand)
B(-4,105,0,minecraft:soul_sand)
B(-4,106,0,minecraft:soul_sand)
B(-4,107,0,minecraft:soul_sand)
B(-4,108,0,minecraft:soul_sand)
B(-4,109,0,minecraft:soul_sand)
B(-4,110,0,minecraft:soul_sand)
B(-4,111,0,minecraft:soul_sand)
B(-4,0,1,minecraft:netherrack)
B(-4,1,1,minecraft:netherrack)
B(-4,2,1,minecraft:netherrack)
B(-4,3,1,minecraft:soul_soil)
B(-4,99,1,minecraft:soul_sand)
B(-4,100,1,minecraft:soul_sand)
B(-4,101,1,minecraft:soul_sand)
B(-4,102,1,minecraft:soul_sand)
B(-4,103,1,minecraft:soul_sand)
B(-4,104,1,minecraft:soul_sand)
B(-4,105,1,minecraft:soul_sand)
B(-4,106,1,minecraft:soul_sand)
B(-4,107,1,minecraft:soul_sand)
B(-4,108,1,minecraft:soul_sand)
B(-4,109,1,minecraft:soul_sand)
B(-4,110,1,minecraft:soul_sand)
B(-4,111,1,minecraft:soul_sand)
B(-4,0,2,minecraft:netherrack)
B(-4,1,2,minecraft:netherrack)
B(-4,2,2,minecraft:netherrack)
B(-4,3,2,minecraft:netherrack)
B(-4,100,2,minecraft:soul_sand)
B(-4,101,2,minecraft:soul_sand)
B(-4,102,2,minecraft:soul_sand)
B(-4,103,2,minecraft:soul_sand)
B(-4,104,2,minecraft:soul_sand)
B(-4,105,2,minecraft:soul_sand)
B(-4,106,2,minecraft:soul_sand)
B(-4,107,2,minecraft:soul_sand)
B(-4,108,2,minecraft:soul_sand)
B(-4,109,2,minecraft:soul_sand)
B(-4,110,2,minecraft:soul_sand)
B(-4,111,2,minecraft:soul_sand)
B(-4,0,3,minecraft:netherrack)
B(-4,1,3,minecraft:netherrack)
B(-4,2,3,minecraft:netherrack)
B(-4,3,3,minecraft:lava)
B(-4,100,3,minecraft:soul_sand)
B(-4,101,3,minecraft:soul_sand)
B(-4,102,3,minecraft:soul_sand)
B(-4,103,3,minecraft:soul_sand)
B(-4,104,3,minecraft:soul_sand)
B(-4,105,3,minecraft:soul_sand)
B(-4,106,3,minecraft:soul_sand)
B(-4,107,3,minecraft:soul_sand)
B(-4,108,3,minecraft:soul_sand)
B(-4,109,3,minecraft:soul_sand)
B(-4,110,3,minecraft:soul_sand)
B(-4,111,3,minecraft:soul_sand)
B(-4,0,4,minecraft:netherrack)
B(-4,1,4,minecraft:netherrack)
B(-4,2,4,minecraft:netherrack)
B(-4,3,4,minecraft:lava)
B(-4,100,4,minecraft:soul_sand)
B(-4,101,4,minecraft:soul_sand)
B(-4,102,4,minecraft:soul_sand)
B(-4,103,4,minecraft:soul_sand)
B(-4,104,4,minecraft:soul_sand)
B(-4,105,4,minecraft:soul_sand)
B(-4,106,4,minecraft:soul_sand)
B(-4,107,4,minecraft:soul_sand)
B(-4,108,4,minecraft:soul_sand)
B(-4,109,4,minecraft:soul_sand)
B(-4,110,4,minecraft:soul_sand)
B(-4,111,4,minecraft:soul_sand)
B(-4,0,5,minecraft:netherrack)
B(-4,1,5,minecraft:netherrack)
B(-4,2,5,minecraft:netherrack)
B(-4,3,5,minecraft:lava)
B(-4,100,5,minecraft:soul_sand)
B(-4,101,5,minecraft:soul_sand)
B(-4,102,5,minecraft:soul_sand)
B(-4,103,5,minecraft:soul_sand)
B(-4,104,5,minecraft:soul_sand)
B(-4,105,5,minecraft:soul_sand)
B(-4,106,5,minecraft:soul_sand)
B(-4,107,5,minecraft:soul_sand)
B(-4,108,5,minecraft:soul_sand)
B(-4,109,5,minecraft:soul_sand)
B(-4,110,5,minecraft:soul_sand)
B(-4,111,5,minecraft:soul_sand)
B(-4,0,6,minecraft:netherrack)
B(-4,1,6,minecraft:netherrack)
B(-4,2,6,minecraft:netherrack)
B(-4,3,6,minecraft:lava)
B(-4,99,6,minecraft:soul_sand)
B(-4,100,6,minecraft:soul_sand)
B(-4,101,6,minecraft:soul_sand)
B(-4,102,6,minecraft:soul_sand)
B(-4,103,6,minecraft:soul_sand)
B(-4,104,6,minecraft:soul_sand)
B(-4,105,6,minecraft:soul_sand)
B(-4,106,6,minecraft:soul_sand)
B(-4,107,6,minecraft:soul_sand)
B(-4,108,6,minecraft:soul_sand)
B(-4,109,6,minecraft:soul_sand)
B(-4,110,6,minecraft:soul_sand)
B(-4,111,6,minecraft:soul_sand)
B(-4,0,7,minecraft:netherrack)
B(-4,1,7,minecraft:netherrack)
B(-4,2,7,minecraft:netherrack)
B(-4,3,7,minecraft:lava)
B(-4,98,7,minecraft:soul_sand)
B(-4,99,7,minecraft:soul_sand)
B(-4,100,7,minecraft:soul_sand)
B(-4,101,7,minecraft:soul_sand)
B(-4,102,7,minecraft:soul_sand)
B(-4,103,7,minecraft:soul_sand)
B(-4,104,7,minecraft:soul_sand)
B(-4,105,7,minecraft:soul_sand)
B(-4,106,7,minecraft:soul_sand)
B(-4,107,7,minecraft:soul_sand)
B(-4,108,7,minecraft:soul_sand)
B(-4,109,7,minecraft:soul_sand)
B(-4,110,7,minecraft:soul_sand)
B(-4,111,7,minecraft:soul_sand)
B(-4,0,8,minecraft:netherrack)
B(-4,1,8,minecraft:netherrack)
B(-4,2,8,minecraft:netherrack)
B(-4,3,8,minecraft:lava)
B(-4,97,8,minecraft:soul_sand)
B(-4,98,8,minecraft:soul_sand)
B(-4,99,8,minecraft:soul_sand)
B(-4,100,8,minecraft:soul_sand)
B(-4,101,8,minecraft:soul_sand)
B(-4,102,8,minecraft:soul_sand)
B(-4,103,8,minecraft:soul_sand)
B(-4,104,8,minecraft:soul_sand)
B(-4,105,8,minecraft:soul_sand)
B(-4,106,8,minecraft:soul_sand)
B(-4,107,8,minecraft:soul_sand)
B(-4,108,8,minecraft:soul_sand)
B(-4,109,8,minecraft:soul_sand)
B(-4,110,8,minecraft:soul_sand)
B(-4,111,8,minecraft:soul_sand)
B(-3,0,-7,minecraft:netherrack)
B(-3,1,-7,minecraft:netherrack)
B(-3,2,-7,minecraft:soul_soil)
B(-3,3,-7,minecraft:soul_soil)
B(-3,4,-7,minecraft:soul_soil)
B(-3,5,-7,minecraft:soul_sand)
B(-3,6,-7,minecraft:bone_block)
B(-3,7,-7,minecraft:bone_block)
B(-3,8,-7,minecraft:bone_block)
B(-3,9,-7,minecraft:bone_block)
B(-3,10,-7,minecraft:bone_block)
B(-3,103,-7,minecraft:soul_sand)
B(-3,104,-7,minecraft:soul_sand)
B(-3,105,-7,minecraft:soul_sand)
B(-3,106,-7,minecraft:soul_sand)
B(-3,107,-7,minecraft:soul_sand)
B(-3,108,-7,minecraft:soul_sand)
B(-3,109,-7,minecraft:soul_sand)
B(-3,110,-7,minecraft:soul_sand)
B(-3,111,-7,minecraft:soul_sand)
B(-3,0,-6,minecraft:netherrack)
B(-3,1,-6,minecraft:netherrack)
B(-3,2,-6,minecraft:soul_soil)
B(-3,3,-6,minecraft:soul_soil)
B(-3,4,-6,minecraft:soul_soil)
B(-3,5,-6,minecraft:soul_sand)
B(-3,102,-6,minecraft:soul_sand)
B(-3,103,-6,minecraft:soul_sand)
B(-3,104,-6,minecraft:soul_sand)
B(-3,105,-6,minecraft:soul_sand)
B(-3,106,-6,minecraft:soul_sand)
B(-3,107,-6,minecraft:soul_sand)
B(-3,108,-6,minecraft:soul_sand)
B(-3,109,-6,minecraft:soul_sand)
B(-3,110,-6,minecraft:soul_sand)
B(-3,111,-6,minecraft:soul_sand)
B(-3,0,-5,minecraft:netherrack)
B(-3,1,-5,minecraft:netherrack)
B(-3,2,-5,minecraft:soul_soil)
B(-3,3,-5,minecraft:soul_soil)
B(-3,4,-5,minecraft:soul_soil)
B(-3,5,-5,minecraft:soul_sand)
B(-3,6,-5,minecraft:bone_block)
B(-3,7,-5,minecraft:bone_block)
B(-3,8,-5,minecraft:bone_block)
B(-3,9,-5,minecraft:bone_block)
B(-3,101,-5,minecraft:soul_sand)
B(-3,102,-5,minecraft:soul_sand)
B(-3,103,-5,minecraft:soul_sand)
B(-3,104,-5,minecraft:soul_sand)
B(-3,105,-5,minecraft:soul_sand)
B(-3,106,-5,minecraft:soul_sand)
B(-3,107,-5,minecraft:soul_sand)
B(-3,108,-5,minecraft:soul_sand)
B(-3,109,-5,minecraft:soul_sand)
B(-3,110,-5,minecraft:soul_sand)
B(-3,111,-5,minecraft:soul_sand)
B(-3,0,-4,minecraft:netherrack)
B(-3,1,-4,minecraft:netherrack)
B(-3,2,-4,minecraft:soul_soil)
B(-3,3,-4,minecraft:soul_soil)
B(-3,4,-4,minecraft:soul_soil)
B(-3,5,-4,minecraft:soul_sand)
B(-3,101,-4,minecraft:soul_sand)
B(-3,102,-4,minecraft:soul_sand)
B(-3,103,-4,minecraft:soul_sand)
B(-3,104,-4,minecraft:soul_sand)
B(-3,105,-4,minecraft:soul_sand)
B(-3,106,-4,minecraft:soul_sand)
B(-3,107,-4,minecraft:soul_sand)
B(-3,108,-4,minecraft:soul_sand)
B(-3,109,-4,minecraft:soul_sand)
B(-3,110,-4,minecraft:soul_sand)
B(-3,111,-4,minecraft:soul_sand)
B(-3,0,-3,minecraft:netherrack)
B(-3,1,-3,minecraft:netherrack)
B(-3,2,-3,minecraft:soul_soil)
B(-3,3,-3,minecraft:soul_soil)
B(-3,4,-3,minecraft:soul_soil)
B(-3,5,-3,minecraft:soul_sand)
B(-3,100,-3,minecraft:soul_sand)
B(-3,101,-3,minecraft:soul_sand)
B(-3,102,-3,minecraft:soul_sand)
B(-3,103,-3,minecraft:soul_sand)
B(-3,104,-3,minecraft:soul_sand)
B(-3,105,-3,minecraft:soul_sand)
B(-3,106,-3,minecraft:soul_sand)
B(-3,107,-3,minecraft:soul_sand)
B(-3,108,-3,minecraft:soul_sand)
B(-3,109,-3,minecraft:soul_sand)
B(-3,110,-3,minecraft:soul_sand)
B(-3,111,-3,minecraft:soul_sand)
B(-3,0,-2,minecraft:netherrack)
B(-3,1,-2,minecraft:netherrack)
B(-3,2,-2,minecraft:soul_soil)
B(-3,3,-2,minecraft:soul_soil)
B(-3,4,-2,minecraft:soul_soil)
B(-3,5,-2,minecraft:soul_sand)
B(-3,100,-2,minecraft:soul_sand)
B(-3,101,-2,minecraft:soul_sand)
B(-3,102,-2,minecraft:soul_sand)
B(-3,103,-2,minecraft:soul_sand)
B(-3,104,-2,minecraft:soul_sand)
B(-3,105,-2,minecraft:soul_sand)
B(-3,106,-2,minecraft:soul_sand)
B(-3,107,-2,minecraft:soul_sand)
B(-3,108,-2,minecraft:soul_sand)
B(-3,109,-2,minecraft:soul_sand)
B(-3,110,-2,minecraft:soul_sand)
B(-3,111,-2,minecraft:soul_sand)
B(-3,0,-1,minecraft:netherrack)
B(-3,1,-1,minecraft:netherrack)
B(-3,2,-1,minecraft:soul_soil)
B(-3,3,-1,minecraft:soul_soil)
B(-3,4,-1,minecraft:soul_soil)
B(-3,5,-1,minecraft:soul_sand)
B(-3,100,-1,minecraft:soul_sand)
B(-3,101,-1,minecraft:soul_sand)
B(-3,102,-1,minecraft:soul_sand)
B(-3,103,-1,minecraft:soul_sand)
B(-3,104,-1,minecraft:soul_sand)
B(-3,105,-1,minecraft:soul_sand)
B(-3,106,-1,minecraft:soul_sand)
B(-3,107,-1,minecraft:soul_sand)
B(-3,108,-1,minecraft:soul_sand)
B(-3,109,-1,minecraft:soul_sand)
B(-3,110,-1,minecraft:soul_sand)
B(-3,111,-1,minecraft:soul_sand)
B(-3,0,0,minecraft:netherrack)
B(-3,1,0,minecraft:netherrack)
B(-3,2,0,minecraft:soul_soil)
B(-3,3,0,minecraft:soul_soil)
B(-3,4,0,minecraft:soul_sand)
B(-3,100,0,minecraft:soul_sand)
B(-3,101,0,minecraft:soul_sand)
B(-3,102,0,minecraft:soul_sand)
B(-3,103,0,minecraft:soul_sand)
B(-3,104,0,minecraft:soul_sand)
B(-3,105,0,minecraft:soul_sand)
B(-3,106,0,minecraft:soul_sand)
B(-3,107,0,minecraft:soul_sand)
B(-3,108,0,minecraft:soul_sand)
B(-3,109,0,minecraft:soul_sand)
B(-3,110,0,minecraft:soul_sand)
B(-3,111,0,minecraft:soul_sand)
B(-3,0,1,minecraft:netherrack)
B(-3,1,1,minecraft:netherrack)
B(-3,2,1,minecraft:netherrack)
B(-3,3,1,minecraft:soul_soil)
B(-3,100,1,minecraft:soul_sand)
B(-3,101,1,minecraft:soul_sand)
B(-3,102,1,minecraft:soul_sand)
B(-3,103,1,minecraft:soul_sand)
B(-3,104,1,minecraft:soul_sand)
B(-3,105,1,minecraft:soul_sand)
B(-3,106,1,minecraft:soul_sand)
B(-3,107,1,minecraft:soul_sand)
B(-3,108,1,minecraft:soul_sand)
B(-3,109,1,minecraft:soul_sand)
B(-3,110,1,minecraft:soul_sand)
B(-3,111,1,minecraft:soul_sand)
B(-3,0,2,minecraft:netherrack)
B(-3,1,2,minecraft:netherrack)
B(-3,2,2,minecraft:netherrack)
B(-3,3,2,minecraft:lava)
B(-3,101,2,minecraft:soul_sand)
B(-3,102,2,minecraft:soul_sand)
B(-3,103,2,minecraft:soul_sand)
B(-3,104,2,minecraft:soul_sand)
B(-3,105,2,minecraft:soul_sand)
B(-3,106,2,minecraft:soul_sand)
B(-3,107,2,minecraft:soul_sand)
B(-3,108,2,minecraft:soul_sand)
B(-3,109,2,minecraft:soul_sand)
B(-3,110,2,minecraft:soul_sand)
B(-3,111,2,minecraft:soul_sand)
B(-3,0,3,minecraft:netherrack)
B(-3,1,3,minecraft:netherrack)
B(-3,2,3,minecraft:netherrack)
B(-3,3,3,minecraft:lava)
B(-3,101,3,minecraft:soul_sand)
B(-3,102,3,minecraft:soul_sand)
B(-3,103,3,minecraft:soul_sand)
B(-3,104,3,minecraft:soul_sand)
B(-3,105,3,minecraft:soul_sand)
B(-3,106,3,minecraft:soul_sand)
B(-3,107,3,minecraft:soul_sand)
B(-3,108,3,minecraft:soul_sand)
B(-3,109,3,minecraft:soul_sand)
B(-3,110,3,minecraft:soul_sand)
B(-3,111,3,minecraft:soul_sand)
B(-3,0,4,minecraft:netherrack)
B(-3,1,4,minecraft:netherrack)
B(-3,2,4,minecraft:soul_soil)
B(-3,3,4,minecraft:lava)
B(-3,101,4,minecraft:soul_sand)
B(-3,102,4,minecraft:soul_sand)
B(-3,103,4,minecraft:soul_sand)
B(-3,104,4,minecraft:soul_sand)
B(-3,105,4,minecraft:soul_sand)
B(-3,106,4,minecraft:soul_sand)
B(-3,107,4,minecraft:soul_sand)
B(-3,108,4,minecraft:soul_sand)
B(-3,109,4,minecraft:soul_sand)
B(-3,110,4,minecraft:soul_sand)
B(-3,111,4,minecraft:soul_sand)
B(-3,0,5,minecraft:netherrack)
B(-3,1,5,minecraft:netherrack)
B(-3,2,5,minecraft:netherrack)
B(-3,3,5,minecraft:lava)
B(-3,100,5,minecraft:soul_sand)
B(-3,101,5,minecraft:soul_sand)
B(-3,102,5,minecraft:soul_sand)
B(-3,103,5,minecraft:soul_sand)
B(-3,104,5,minecraft:soul_sand)
B(-3,105,5,minecraft:soul_sand)
B(-3,106,5,minecraft:soul_sand)
B(-3,107,5,minecraft:soul_sand)
B(-3,108,5,minecraft:soul_sand)
B(-3,109,5,minecraft:soul_sand)
B(-3,110,5,minecraft:soul_sand)
B(-3,111,5,minecraft:soul_sand)
B(-3,0,6,minecraft:netherrack)
B(-3,1,6,minecraft:netherrack)
B(-3,2,6,minecraft:netherrack)
B(-3,3,6,minecraft:lava)
B(-3,100,6,minecraft:soul_sand)
B(-3,101,6,minecraft:soul_sand)
B(-3,102,6,minecraft:soul_sand)
B(-3,103,6,minecraft:soul_sand)
B(-3,104,6,minecraft:soul_sand)
B(-3,105,6,minecraft:soul_sand)
B(-3,106,6,minecraft:soul_sand)
B(-3,107,6,minecraft:soul_sand)
B(-3,108,6,minecraft:soul_sand)
B(-3,109,6,minecraft:soul_sand)
B(-3,110,6,minecraft:soul_sand)
B(-3,111,6,minecraft:soul_sand)
B(-3,0,7,minecraft:netherrack)
B(-3,1,7,minecraft:netherrack)
B(-3,2,7,minecraft:netherrack)
B(-3,3,7,minecraft:lava)
B(-3,99,7,minecraft:soul_sand)
B(-3,100,7,minecraft:soul_sand)
B(-3,101,7,minecraft:soul_sand)
B(-3,102,7,minecraft:soul_sand)
B(-3,103,7,minecraft:soul_sand)
B(-3,104,7,minecraft:soul_sand)
B(-3,105,7,minecraft:soul_sand)
B(-3,106,7,minecraft:soul_sand)
B(-3,107,7,minecraft:soul_sand)
B(-3,108,7,minecraft:soul_sand)
B(-3,109,7,minecraft:soul_sand)
B(-3,110,7,minecraft:soul_sand)
B(-3,111,7,minecraft:soul_sand)
B(-3,0,8,minecraft:netherrack)
B(-3,1,8,minecraft:netherrack)
B(-3,2,8,minecraft:netherrack)
B(-3,3,8,minecraft:soul_soil)
B(-3,98,8,minecraft:soul_sand)
B(-3,99,8,minecraft:soul_sand)
B(-3,100,8,minecraft:soul_sand)
B(-3,101,8,minecraft:soul_sand)
B(-3,102,8,minecraft:soul_sand)
B(-3,103,8,minecraft:soul_sand)
B(-3,104,8,minecraft:soul_sand)
B(-3,105,8,minecraft:soul_sand)
B(-3,106,8,minecraft:soul_sand)
B(-3,107,8,minecraft:soul_sand)
B(-3,108,8,minecraft:soul_sand)
B(-3,109,8,minecraft:soul_sand)
B(-3,110,8,minecraft:soul_sand)
B(-3,111,8,minecraft:soul_sand)
B(-2,0,-7,minecraft:netherrack)
B(-2,1,-7,minecraft:netherrack)
B(-2,2,-7,minecraft:soul_soil)
B(-2,3,-7,minecraft:soul_soil)
B(-2,4,-7,minecraft:soul_soil)
B(-2,5,-7,minecraft:soul_sand)
B(-2,104,-7,minecraft:soul_sand)
B(-2,105,-7,minecraft:soul_sand)
B(-2,106,-7,minecraft:soul_sand)
B(-2,107,-7,minecraft:soul_sand)
B(-2,108,-7,minecraft:soul_sand)
B(-2,109,-7,minecraft:soul_sand)
B(-2,110,-7,minecraft:soul_sand)
B(-2,111,-7,minecraft:soul_sand)
B(-2,0,-6,minecraft:netherrack)
B(-2,1,-6,minecraft:netherrack)
B(-2,2,-6,minecraft:soul_soil)
B(-2,3,-6,minecraft:soul_soil)
B(-2,4,-6,minecraft:soul_soil)
B(-2,5,-6,minecraft:soul_sand)
B(-2,103,-6,minecraft:soul_sand)
B(-2,104,-6,minecraft:soul_sand)
B(-2,105,-6,minecraft:soul_sand)
B(-2,106,-6,minecraft:soul_sand)
B(-2,107,-6,minecraft:soul_sand)
B(-2,108,-6,minecraft:soul_sand)
B(-2,109,-6,minecraft:soul_sand)
B(-2,110,-6,minecraft:soul_sand)
B(-2,111,-6,minecraft:soul_sand)
B(-2,0,-5,minecraft:netherrack)
B(-2,1,-5,minecraft:netherrack)
B(-2,2,-5,minecraft:soul_soil)
B(-2,3,-5,minecraft:soul_soil)
B(-2,4,-5,minecraft:soul_soil)
B(-2,5,-5,minecraft:soul_sand)
B(-2,103,-5,minecraft:soul_sand)
B(-2,104,-5,minecraft:soul_sand)
B(-2,105,-5,minecraft:soul_sand)
B(-2,106,-5,minecraft:soul_sand)
B(-2,107,-5,minecraft:soul_sand)
B(-2,108,-5,minecraft:soul_sand)
B(-2,109,-5,minecraft:soul_sand)
B(-2,110,-5,minecraft:soul_sand)
B(-2,111,-5,minecraft:soul_sand)
B(-2,0,-4,minecraft:netherrack)
B(-2,1,-4,minecraft:netherrack)
B(-2,2,-4,minecraft:soul_soil)
B(-2,3,-4,minecraft:soul_soil)
B(-2,4,-4,minecraft:soul_soil)
B(-2,5,-4,minecraft:soul_sand)
B(-2,102,-4,minecraft:soul_sand)
B(-2,103,-4,minecraft:soul_sand)
B(-2,104,-4,minecraft:soul_sand)
B(-2,105,-4,minecraft:soul_sand)
B(-2,106,-4,minecraft:soul_sand)
B(-2,107,-4,minecraft:soul_sand)
B(-2,108,-4,minecraft:soul_sand)
B(-2,109,-4,minecraft:soul_sand)
B(-2,110,-4,minecraft:soul_sand)
B(-2,111,-4,minecraft:soul_sand)
B(-2,0,-3,minecraft:netherrack)
B(-2,1,-3,minecraft:netherrack)
B(-2,2,-3,minecraft:soul_soil)
B(-2,3,-3,minecraft:soul_soil)
B(-2,4,-3,minecraft:soul_soil)
B(-2,5,-3,minecraft:soul_sand)
B(-2,102,-3,minecraft:soul_sand)
B(-2,103,-3,minecraft:soul_sand)
B(-2,104,-3,minecraft:soul_sand)
B(-2,105,-3,minecraft:soul_sand)
B(-2,106,-3,minecraft:soul_sand)
B(-2,107,-3,minecraft:soul_sand)
B(-2,108,-3,minecraft:soul_sand)
B(-2,109,-3,minecraft:soul_sand)
B(-2,110,-3,minecraft:soul_sand)
B(-2,111,-3,minecraft:soul_sand)
B(-2,0,-2,minecraft:netherrack)
B(-2,1,-2,minecraft:netherrack)
B(-2,2,-2,minecraft:soul_soil)
B(-2,3,-2,minecraft:soul_soil)
B(-2,4,-2,minecraft:soul_soil)
B(-2,5,-2,minecraft:soul_sand)
B(-2,102,-2,minecraft:soul_sand)
B(-2,103,-2,minecraft:soul_sand)
B(-2,104,-2,minecraft:soul_sand)
B(-2,105,-2,minecraft:soul_sand)
B(-2,106,-2,minecraft:soul_sand)
B(-2,107,-2,minecraft:soul_sand)
B(-2,108,-2,minecraft:soul_sand)
B(-2,109,-2,minecraft:soul_sand)
B(-2,110,-2,minecraft:soul_sand)
B(-2,111,-2,minecraft:soul_sand)
B(-2,0,-1,minecraft:netherrack)
B(-2,1,-1,minecraft:netherrack)
B(-2,2,-1,minecraft:soul_soil)
B(-2,3,-1,minecraft:soul_soil)
B(-2,4,-1,minecraft:soul_soil)
B(-2,5,-1,minecraft:soul_sand)
B(-2,102,-1,minecraft:soul_sand)
B(-2,103,-1,minecraft:soul_sand)
B(-2,104,-1,minecraft:soul_sand)
B(-2,105,-1,minecraft:soul_sand)
B(-2,106,-1,minecraft:soul_sand)
B(-2,107,-1,minecraft:soul_sand)
B(-2,108,-1,minecraft:soul_sand)
B(-2,109,-1,minecraft:soul_sand)
B(-2,110,-1,minecraft:soul_sand)
B(-2,111,-1,minecraft:soul_sand)
B(-2,0,0,minecraft:netherrack)
B(-2,1,0,minecraft:netherrack)
B(-2,2,0,minecraft:soul_soil)
B(-2,3,0,minecraft:soul_soil)
B(-2,4,0,minecraft:soul_sand)
B(-2,101,0,minecraft:soul_sand)
B(-2,102,0,minecraft:soul_sand)
B(-2,103,0,minecraft:soul_sand)
B(-2,104,0,minecraft:soul_sand)
B(-2,105,0,minecraft:soul_sand)
B(-2,106,0,minecraft:soul_sand)
B(-2,107,0,minecraft:soul_sand)
B(-2,108,0,minecraft:soul_sand)
B(-2,109,0,minecraft:soul_sand)
B(-2,110,0,minecraft:soul_sand)
B(-2,111,0,minecraft:soul_sand)
B(-2,0,1,minecraft:netherrack)
B(-2,1,1,minecraft:netherrack)
B(-2,2,1,minecraft:netherrack)
B(-2,3,1,minecraft:soul_soil)
B(-2,102,1,minecraft:soul_sand)
B(-2,103,1,minecraft:soul_sand)
B(-2,104,1,minecraft:soul_sand)
B(-2,105,1,minecraft:soul_sand)
B(-2,106,1,minecraft:soul_sand)
B(-2,107,1,minecraft:soul_sand)
B(-2,108,1,minecraft:soul_sand)
B(-2,109,1,minecraft:soul_sand)
B(-2,110,1,minecraft:soul_sand)
B(-2,111,1,minecraft:soul_sand)
B(-2,0,2,minecraft:netherrack)
B(-2,1,2,minecraft:netherrack)
B(-2,2,2,minecraft:netherrack)
B(-2,3,2,minecraft:lava)
B(-2,102,2,minecraft:soul_sand)
B(-2,103,2,minecraft:soul_sand)
B(-2,104,2,minecraft:soul_sand)
B(-2,105,2,minecraft:soul_sand)
B(-2,106,2,minecraft:soul_sand)
B(-2,107,2,minecraft:soul_sand)
B(-2,108,2,minecraft:soul_sand)
B(-2,109,2,minecraft:soul_sand)
B(-2,110,2,minecraft:soul_sand)
B(-2,111,2,minecraft:soul_sand)
B(-2,0,3,minecraft:netherrack)
B(-2,1,3,minecraft:netherrack)
B(-2,2,3,minecraft:soul_soil)
B(-2,3,3,minecraft:lava)
B(-2,102,3,minecraft:soul_sand)
B(-2,103,3,minecraft:soul_sand)
B(-2,104,3,minecraft:soul_sand)
B(-2,105,3,minecraft:soul_sand)
B(-2,106,3,minecraft:soul_sand)
B(-2,107,3,minecraft:soul_sand)
B(-2,108,3,minecraft:soul_sand)
B(-2,109,3,minecraft:soul_sand)
B(-2,110,3,minecraft:soul_sand)
B(-2,111,3,minecraft:soul_sand)
B(-2,0,4,minecraft:netherrack)
B(-2,1,4,minecraft:soul_soil)
B(-2,2,4,minecraft:lava)
B(-2,3,4,minecraft:lava)
B(-2,102,4,minecraft:soul_sand)
B(-2,103,4,minecraft:soul_sand)
B(-2,104,4,minecraft:soul_sand)
B(-2,105,4,minecraft:soul_sand)
B(-2,106,4,minecraft:soul_sand)
B(-2,107,4,minecraft:soul_sand)
B(-2,108,4,minecraft:soul_sand)
B(-2,109,4,minecraft:soul_sand)
B(-2,110,4,minecraft:soul_sand)
B(-2,111,4,minecraft:soul_sand)
B(-2,0,5,minecraft:netherrack)
B(-2,1,5,minecraft:netherrack)
B(-2,2,5,minecraft:lava)
B(-2,3,5,minecraft:lava)
B(-2,101,5,minecraft:soul_sand)
B(-2,102,5,minecraft:soul_sand)
B(-2,103,5,minecraft:soul_sand)
B(-2,104,5,minecraft:soul_sand)
B(-2,105,5,minecraft:soul_sand)
B(-2,106,5,minecraft:soul_sand)
B(-2,107,5,minecraft:soul_sand)
B(-2,108,5,minecraft:soul_sand)
B(-2,109,5,minecraft:soul_sand)
B(-2,110,5,minecraft:soul_sand)
B(-2,111,5,minecraft:soul_sand)
B(-2,0,6,minecraft:netherrack)
B(-2,1,6,minecraft:netherrack)
B(-2,2,6,minecraft:soul_soil)
B(-2,3,6,minecraft:lava)
B(-2,101,6,minecraft:soul_sand)
B(-2,102,6,minecraft:soul_sand)
B(-2,103,6,minecraft:soul_sand)
B(-2,104,6,minecraft:soul_sand)
B(-2,105,6,minecraft:soul_sand)
B(-2,106,6,minecraft:soul_sand)
B(-2,107,6,minecraft:soul_sand)
B(-2,108,6,minecraft:soul_sand)
B(-2,109,6,minecraft:soul_sand)
B(-2,110,6,minecraft:soul_sand)
B(-2,111,6,minecraft:soul_sand)
B(-2,0,7,minecraft:netherrack)
B(-2,1,7,minecraft:netherrack)
B(-2,2,7,minecraft:netherrack)
B(-2,3,7,minecraft:soul_soil)
B(-2,6,7,minecraft:soul_sand)
B(-2,100,7,minecraft:soul_sand)
B(-2,101,7,minecraft:soul_sand)
B(-2,102,7,minecraft:soul_sand)
B(-2,103,7,minecraft:soul_sand)
B(-2,104,7,minecraft:soul_sand)
B(-2,105,7,minecraft:soul_sand)
B(-2,106,7,minecraft:soul_sand)
B(-2,107,7,minecraft:soul_sand)
B(-2,108,7,minecraft:soul_sand)
B(-2,109,7,minecraft:soul_sand)
B(-2,110,7,minecraft:soul_sand)
B(-2,111,7,minecraft:soul_sand)
B(-2,0,8,minecraft:netherrack)
B(-2,1,8,minecraft:netherrack)
B(-2,2,8,minecraft:netherrack)
B(-2,3,8,minecraft:soul_soil)
B(-2,4,8,minecraft:soul_soil)
B(-2,5,8,minecraft:soul_soil)
B(-2,6,8,minecraft:soul_sand)
B(-2,99,8,minecraft:soul_sand)
B(-2,100,8,minecraft:soul_sand)
B(-2,101,8,minecraft:soul_sand)
B(-2,102,8,minecraft:soul_sand)
B(-2,103,8,minecraft:soul_sand)
B(-2,104,8,minecraft:soul_sand)
B(-2,105,8,minecraft:soul_sand)
B(-2,106,8,minecraft:soul_sand)
B(-2,107,8,minecraft:soul_sand)
B(-2,108,8,minecraft:soul_sand)
B(-2,109,8,minecraft:soul_sand)
B(-2,110,8,minecraft:soul_sand)
B(-2,111,8,minecraft:soul_sand)
B(-1,0,-7,minecraft:netherrack)
B(-1,1,-7,minecraft:netherrack)
B(-1,2,-7,minecraft:soul_soil)
B(-1,3,-7,minecraft:soul_soil)
B(-1,4,-7,minecraft:soul_soil)
B(-1,5,-7,minecraft:soul_sand)
B(-1,105,-7,minecraft:soul_sand)
B(-1,106,-7,minecraft:soul_sand)
B(-1,107,-7,minecraft:soul_sand)
B(-1,108,-7,minecraft:soul_sand)
B(-1,109,-7,minecraft:soul_sand)
B(-1,110,-7,minecraft:soul_sand)
B(-1,111,-7,minecraft:soul_sand)
B(-1,0,-6,minecraft:netherrack)
B(-1,1,-6,minecraft:netherrack)
B(-1,2,-6,minecraft:soul_soil)
B(-1,3,-6,minecraft:soul_soil)
B(-1,4,-6,minecraft:soul_soil)
B(-1,5,-6,minecraft:soul_sand)
B(-1,104,-6,minecraft:soul_sand)
B(-1,105,-6,minecraft:soul_sand)
B(-1,106,-6,minecraft:soul_sand)
B(-1,107,-6,minecraft:soul_sand)
B(-1,108,-6,minecraft:soul_sand)
B(-1,109,-6,minecraft:soul_sand)
B(-1,110,-6,minecraft:soul_sand)
B(-1,111,-6,minecraft:soul_sand)
B(-1,0,-5,minecraft:netherrack)
B(-1,1,-5,minecraft:netherrack)
B(-1,2,-5,minecraft:soul_soil)
B(-1,3,-5,minecraft:soul_soil)
B(-1,4,-5,minecraft:soul_soil)
B(-1,5,-5,minecraft:soul_sand)
B(-1,104,-5,minecraft:soul_sand)
B(-1,105,-5,minecraft:soul_sand)
B(-1,106,-5,minecraft:soul_sand)
B(-1,107,-5,minecraft:soul_sand)
B(-1,108,-5,minecraft:soul_sand)
B(-1,109,-5,minecraft:soul_sand)
B(-1,110,-5,minecraft:soul_sand)
B(-1,111,-5,minecraft:soul_sand)
B(-1,0,-4,minecraft:netherrack)
B(-1,1,-4,minecraft:netherrack)
B(-1,2,-4,minecraft:soul_soil)
B(-1,3,-4,minecraft:soul_soil)
B(-1,4,-4,minecraft:soul_soil)
B(-1,5,-4,minecraft:soul_sand)
B(-1,104,-4,minecraft:soul_sand)
B(-1,105,-4,minecraft:soul_sand)
B(-1,106,-4,minecraft:soul_sand)
B(-1,107,-4,minecraft:soul_sand)
B(-1,108,-4,minecraft:soul_sand)
B(-1,109,-4,minecraft:soul_sand)
B(-1,110,-4,minecraft:soul_sand)
B(-1,111,-4,minecraft:soul_sand)
B(-1,0,-3,minecraft:netherrack)
B(-1,1,-3,minecraft:netherrack)
B(-1,2,-3,minecraft:soul_soil)
B(-1,3,-3,minecraft:soul_soil)
B(-1,4,-3,minecraft:soul_soil)
B(-1,5,-3,minecraft:soul_sand)
B(-1,103,-3,minecraft:soul_sand)
B(-1,104,-3,minecraft:soul_sand)
B(-1,105,-3,minecraft:soul_sand)
B(-1,106,-3,minecraft:soul_sand)
B(-1,107,-3,minecraft:soul_sand)
B(-1,108,-3,minecraft:soul_sand)
B(-1,109,-3,minecraft:soul_sand)
B(-1,110,-3,minecraft:soul_sand)
B(-1,111,-3,minecraft:soul_sand)
B(-1,0,-2,minecraft:netherrack)
B(-1,1,-2,minecraft:netherrack)
B(-1,2,-2,minecraft:soul_soil)
B(-1,3,-2,minecraft:soul_soil)
B(-1,4,-2,minecraft:soul_soil)
B(-1,5,-2,minecraft:soul_sand)
B(-1,103,-2,minecraft:soul_sand)
B(-1,104,-2,minecraft:soul_sand)
B(-1,105,-2,minecraft:soul_sand)
B(-1,106,-2,minecraft:soul_sand)
B(-1,107,-2,minecraft:soul_sand)
B(-1,108,-2,minecraft:soul_sand)
B(-1,109,-2,minecraft:soul_sand)
B(-1,110,-2,minecraft:soul_sand)
B(-1,111,-2,minecraft:soul_sand)
B(-1,0,-1,minecraft:netherrack)
B(-1,1,-1,minecraft:netherrack)
B(-1,2,-1,minecraft:soul_soil)
B(-1,3,-1,minecraft:soul_soil)
B(-1,4,-1,minecraft:soul_soil)
B(-1,5,-1,minecraft:soul_sand)
B(-1,103,-1,minecraft:soul_sand)
B(-1,104,-1,minecraft:soul_sand)
B(-1,105,-1,minecraft:soul_sand)
B(-1,106,-1,minecraft:soul_sand)
B(-1,107,-1,minecraft:soul_sand)
B(-1,108,-1,minecraft:soul_sand)
B(-1,109,-1,minecraft:soul_sand)
B(-1,110,-1,minecraft:soul_sand)
B(-1,111,-1,minecraft:soul_sand)
B(-1,0,0,minecraft:netherrack)
B(-1,1,0,minecraft:netherrack)
B(-1,2,0,minecraft:soul_soil)
B(-1,3,0,minecraft:soul_soil)
B(-1,4,0,minecraft:soul_sand)
B(-1,103,0,minecraft:soul_sand)
B(-1,104,0,minecraft:soul_sand)
B(-1,105,0,minecraft:soul_sand)
B(-1,106,0,minecraft:soul_sand)
B(-1,107,0,minecraft:soul_sand)
B(-1,108,0,minecraft:soul_sand)
B(-1,109,0,minecraft:soul_sand)
B(-1,110,0,minecraft:soul_sand)
B(-1,111,0,minecraft:soul_sand)
B(-1,0,1,minecraft:netherrack)
B(-1,1,1,minecraft:netherrack)
B(-1,2,1,minecraft:soul_soil)
B(-1,3,1,minecraft:soul_sand)
B(-1,103,1,minecraft:soul_sand)
B(-1,104,1,minecraft:soul_sand)
B(-1,105,1,minecraft:soul_sand)
B(-1,106,1,minecraft:soul_sand)
B(-1,107,1,minecraft:soul_sand)
B(-1,108,1,minecraft:soul_sand)
B(-1,109,1,minecraft:soul_sand)
B(-1,110,1,minecraft:soul_sand)
B(-1,111,1,minecraft:soul_sand)
B(-1,0,2,minecraft:netherrack)
B(-1,1,2,minecraft:netherrack)
B(-1,2,2,minecraft:soul_soil)
B(-1,3,2,minecraft:lava)
B(-1,103,2,minecraft:soul_sand)
B(-1,104,2,minecraft:soul_sand)
B(-1,105,2,minecraft:soul_sand)
B(-1,106,2,minecraft:soul_sand)
B(-1,107,2,minecraft:soul_sand)
B(-1,108,2,minecraft:soul_sand)
B(-1,109,2,minecraft:soul_sand)
B(-1,110,2,minecraft:soul_sand)
B(-1,111,2,minecraft:soul_sand)
B(-1,0,3,minecraft:netherrack)
B(-1,1,3,minecraft:soul_soil)
B(-1,2,3,minecraft:lava)
B(-1,3,3,minecraft:lava)
B(-1,102,3,minecraft:soul_sand)
B(-1,103,3,minecraft:soul_sand)
B(-1,104,3,minecraft:soul_sand)
B(-1,105,3,minecraft:soul_sand)
B(-1,106,3,minecraft:soul_sand)
B(-1,107,3,minecraft:soul_sand)
B(-1,108,3,minecraft:soul_sand)
B(-1,109,3,minecraft:soul_sand)
B(-1,110,3,minecraft:soul_sand)
B(-1,111,3,minecraft:soul_sand)
B(-1,0,4,minecraft:netherrack)
B(-1,1,4,minecraft:soul_soil)
B(-1,2,4,minecraft:lava)
B(-1,3,4,minecraft:lava)
B(-1,102,4,minecraft:soul_sand)
B(-1,103,4,minecraft:soul_sand)
B(-1,104,4,minecraft:soul_sand)
B(-1,105,4,minecraft:soul_sand)
B(-1,106,4,minecraft:soul_sand)
B(-1,107,4,minecraft:soul_sand)
B(-1,108,4,minecraft:soul_sand)
B(-1,109,4,minecraft:soul_sand)
B(-1,110,4,minecraft:soul_sand)
B(-1,111,4,minecraft:soul_sand)
B(-1,0,5,minecraft:netherrack)
B(-1,1,5,minecraft:soul_soil)
B(-1,2,5,minecraft:soul_soil)
B(-1,3,5,minecraft:lava)
B(-1,102,5,minecraft:soul_sand)
B(-1,103,5,minecraft:soul_sand)
B(-1,104,5,minecraft:soul_sand)
B(-1,105,5,minecraft:soul_sand)
B(-1,106,5,minecraft:soul_sand)
B(-1,107,5,minecraft:soul_sand)
B(-1,108,5,minecraft:soul_sand)
B(-1,109,5,minecraft:soul_sand)
B(-1,110,5,minecraft:soul_sand)
B(-1,111,5,minecraft:soul_sand)
B(-1,0,6,minecraft:netherrack)
B(-1,1,6,minecraft:netherrack)
B(-1,2,6,minecraft:soul_soil)
B(-1,3,6,minecraft:lava)
B(-1,101,6,minecraft:soul_sand)
B(-1,102,6,minecraft:soul_sand)
B(-1,103,6,minecraft:soul_sand)
B(-1,104,6,minecraft:soul_sand)
B(-1,105,6,minecraft:soul_sand)
B(-1,106,6,minecraft:soul_sand)
B(-1,107,6,minecraft:soul_sand)
B(-1,108,6,minecraft:soul_sand)
B(-1,109,6,minecraft:soul_sand)
B(-1,110,6,minecraft:soul_sand)
B(-1,111,6,minecraft:soul_sand)
B(-1,0,7,minecraft:netherrack)
B(-1,1,7,minecraft:netherrack)
B(-1,2,7,minecraft:soul_soil)
B(-1,3,7,minecraft:soul_soil)
B(-1,4,7,minecraft:soul_soil)
B(-1,5,7,minecraft:soul_sand)
B(-1,101,7,minecraft:soul_sand)
B(-1,102,7,minecraft:soul_sand)
B(-1,103,7,minecraft:soul_sand)
B(-1,104,7,minecraft:soul_sand)
B(-1,105,7,minecraft:soul_sand)
B(-1,106,7,minecraft:soul_sand)
B(-1,107,7,minecraft:soul_sand)
B(-1,108,7,minecraft:soul_sand)
B(-1,109,7,minecraft:soul_sand)
B(-1,110,7,minecraft:soul_sand)
B(-1,111,7,minecraft:soul_sand)
B(-1,0,8,minecraft:netherrack)
B(-1,1,8,minecraft:netherrack)
B(-1,2,8,minecraft:netherrack)
B(-1,3,8,minecraft:soul_soil)
B(-1,4,8,minecraft:soul_soil)
B(-1,5,8,minecraft:soul_soil)
B(-1,6,8,minecraft:soul_sand)
B(-1,100,8,minecraft:soul_sand)
B(-1,101,8,minecraft:soul_sand)
B(-1,102,8,minecraft:soul_sand)
B(-1,103,8,minecraft:soul_sand)
B(-1,104,8,minecraft:soul_sand)
B(-1,105,8,minecraft:soul_sand)
B(-1,106,8,minecraft:soul_sand)
B(-1,107,8,minecraft:soul_sand)
B(-1,108,8,minecraft:soul_sand)
B(-1,109,8,minecraft:soul_sand)
B(-1,110,8,minecraft:soul_sand)
B(-1,111,8,minecraft:soul_sand)
B(0,0,-7,minecraft:netherrack)
B(0,1,-7,minecraft:netherrack)
B(0,2,-7,minecraft:soul_soil)
B(0,3,-7,minecraft:soul_soil)
B(0,4,-7,minecraft:soul_soil)
B(0,5,-7,minecraft:soul_sand)
B(0,104,-7,minecraft:soul_sand)
B(0,105,-7,minecraft:soul_sand)
B(0,106,-7,minecraft:soul_sand)
B(0,107,-7,minecraft:soul_sand)
B(0,108,-7,minecraft:soul_sand)
B(0,109,-7,minecraft:soul_sand)
B(0,110,-7,minecraft:soul_sand)
B(0,111,-7,minecraft:soul_sand)
B(0,0,-6,minecraft:netherrack)
B(0,1,-6,minecraft:netherrack)
B(0,2,-6,minecraft:soul_soil)
B(0,3,-6,minecraft:soul_soil)
B(0,4,-6,minecraft:soul_soil)
B(0,5,-6,minecraft:soul_sand)
B(0,104,-6,minecraft:soul_sand)
B(0,105,-6,minecraft:soul_sand)
B(0,106,-6,minecraft:soul_sand)
B(0,107,-6,minecraft:soul_sand)
B(0,108,-6,minecraft:soul_sand)
B(0,109,-6,minecraft:soul_sand)
B(0,110,-6,minecraft:soul_sand)
B(0,111,-6,minecraft:soul_sand)
B(0,0,-5,minecraft:netherrack)
B(0,1,-5,minecraft:netherrack)
B(0,2,-5,minecraft:soul_soil)
B(0,3,-5,minecraft:soul_soil)
B(0,4,-5,minecraft:soul_soil)
B(0,5,-5,minecraft:soul_sand)
B(0,104,-5,minecraft:soul_sand)
B(0,105,-5,minecraft:soul_sand)
B(0,106,-5,minecraft:soul_sand)
B(0,107,-5,minecraft:soul_sand)
B(0,108,-5,minecraft:soul_sand)
B(0,109,-5,minecraft:soul_sand)
B(0,110,-5,minecraft:soul_sand)
B(0,111,-5,minecraft:soul_sand)
B(0,0,-4,minecraft:netherrack)
B(0,1,-4,minecraft:netherrack)
B(0,2,-4,minecraft:soul_soil)
B(0,3,-4,minecraft:soul_soil)
B(0,4,-4,minecraft:soul_soil)
B(0,5,-4,minecraft:soul_sand)
B(0,104,-4,minecraft:soul_sand)
B(0,105,-4,minecraft:soul_sand)
B(0,106,-4,minecraft:soul_sand)
B(0,107,-4,minecraft:soul_sand)
B(0,108,-4,minecraft:soul_sand)
B(0,109,-4,minecraft:soul_sand)
B(0,110,-4,minecraft:soul_sand)
B(0,111,-4,minecraft:soul_sand)
B(0,0,-3,minecraft:netherrack)
B(0,1,-3,minecraft:netherrack)
B(0,2,-3,minecraft:soul_soil)
B(0,3,-3,minecraft:soul_soil)
B(0,4,-3,minecraft:soul_soil)
B(0,5,-3,minecraft:soul_sand)
B(0,104,-3,minecraft:soul_sand)
B(0,105,-3,minecraft:soul_sand)
B(0,106,-3,minecraft:soul_sand)
B(0,107,-3,minecraft:soul_sand)
B(0,108,-3,minecraft:soul_sand)
B(0,109,-3,minecraft:soul_sand)
B(0,110,-3,minecraft:soul_sand)
B(0,111,-3,minecraft:soul_sand)
B(0,0,-2,minecraft:netherrack)
B(0,1,-2,minecraft:netherrack)
B(0,2,-2,minecraft:soul_soil)
B(0,3,-2,minecraft:soul_soil)
B(0,4,-2,minecraft:soul_soil)
B(0,5,-2,minecraft:soul_sand)
B(0,104,-2,minecraft:soul_sand)
B(0,105,-2,minecraft:soul_sand)
B(0,106,-2,minecraft:soul_sand)
B(0,107,-2,minecraft:soul_sand)
B(0,108,-2,minecraft:soul_sand)
B(0,109,-2,minecraft:soul_sand)
B(0,110,-2,minecraft:soul_sand)
B(0,111,-2,minecraft:soul_sand)
B(0,0,-1,minecraft:netherrack)
B(0,1,-1,minecraft:netherrack)
B(0,2,-1,minecraft:soul_soil)
B(0,3,-1,minecraft:soul_soil)
B(0,4,-1,minecraft:soul_soil)
B(0,5,-1,minecraft:soul_sand)
B(0,104,-1,minecraft:soul_sand)
B(0,105,-1,minecraft:soul_sand)
B(0,106,-1,minecraft:soul_sand)
B(0,107,-1,minecraft:soul_sand)
B(0,108,-1,minecraft:soul_sand)
B(0,109,-1,minecraft:soul_sand)
B(0,110,-1,minecraft:soul_sand)
B(0,111,-1,minecraft:soul_sand)
B(0,0,0,minecraft:netherrack)
B(0,1,0,minecraft:netherrack)
B(0,2,0,minecraft:soul_soil)
B(0,3,0,minecraft:soul_soil)
B(0,4,0,minecraft:soul_soil)
B(0,5,0,minecraft:soul_sand)
B(0,104,0,minecraft:soul_sand)
B(0,105,0,minecraft:soul_sand)
B(0,106,0,minecraft:soul_sand)
B(0,107,0,minecraft:soul_sand)
B(0,108,0,minecraft:soul_sand)
B(0,109,0,minecraft:soul_sand)
B(0,110,0,minecraft:soul_sand)
B(0,111,0,minecraft:soul_sand)
B(0,0,1,minecraft:netherrack)
B(0,1,1,minecraft:soul_soil)
B(0,2,1,minecraft:soul_soil)
B(0,3,1,minecraft:soul_soil)
B(0,4,1,minecraft:soul_sand)
B(0,104,1,minecraft:soul_sand)
B(0,105,1,minecraft:soul_sand)
B(0,106,1,minecraft:soul_sand)
B(0,107,1,minecraft:soul_sand)
B(0,108,1,minecraft:soul_sand)
B(0,109,1,minecraft:soul_sand)
B(0,110,1,minecraft:soul_sand)
B(0,111,1,minecraft:soul_sand)
B(0,0,2,minecraft:netherrack)
B(0,1,2,minecraft:soul_soil)
B(0,2,2,minecraft:soul_soil)
B(0,3,2,minecraft:lava)
B(0,104,2,minecraft:soul_sand)
B(0,105,2,minecraft:soul_sand)
B(0,106,2,minecraft:soul_sand)
B(0,107,2,minecraft:soul_sand)
B(0,108,2,minecraft:soul_sand)
B(0,109,2,minecraft:soul_sand)
B(0,110,2,minecraft:soul_sand)
B(0,111,2,minecraft:soul_sand)
B(0,0,3,minecraft:netherrack)
B(0,1,3,minecraft:soul_soil)
B(0,2,3,minecraft:soul_soil)
B(0,3,3,minecraft:lava)
B(0,104,3,minecraft:soul_sand)
B(0,105,3,minecraft:soul_sand)
B(0,106,3,minecraft:soul_sand)
B(0,107,3,minecraft:soul_sand)
B(0,108,3,minecraft:soul_sand)
B(0,109,3,minecraft:soul_sand)
B(0,110,3,minecraft:soul_sand)
B(0,111,3,minecraft:soul_sand)
B(0,0,4,minecraft:soul_soil)
B(0,1,4,minecraft:soul_soil)
B(0,2,4,minecraft:soul_soil)
B(0,3,4,minecraft:lava)
B(0,103,4,minecraft:soul_sand)
B(0,104,4,minecraft:soul_sand)
B(0,105,4,minecraft:soul_sand)
B(0,106,4,minecraft:soul_sand)
B(0,107,4,minecraft:soul_sand)
B(0,108,4,minecraft:soul_sand)
B(0,109,4,minecraft:soul_sand)
B(0,110,4,minecraft:soul_sand)
B(0,111,4,minecraft:soul_sand)
B(0,0,5,minecraft:netherrack)
B(0,1,5,minecraft:soul_soil)
B(0,2,5,minecraft:soul_soil)
B(0,3,5,minecraft:soul_soil)
B(0,103,5,minecraft:soul_sand)
B(0,104,5,minecraft:soul_sand)
B(0,105,5,minecraft:soul_sand)
B(0,106,5,minecraft:soul_sand)
B(0,107,5,minecraft:soul_sand)
B(0,108,5,minecraft:soul_sand)
B(0,109,5,minecraft:soul_sand)
B(0,110,5,minecraft:soul_sand)
B(0,111,5,minecraft:soul_sand)
B(0,0,6,minecraft:netherrack)
B(0,1,6,minecraft:soul_soil)
B(0,2,6,minecraft:soul_soil)
B(0,3,6,minecraft:soul_soil)
B(0,102,6,minecraft:soul_sand)
B(0,103,6,minecraft:soul_sand)
B(0,104,6,minecraft:soul_sand)
B(0,105,6,minecraft:soul_sand)
B(0,106,6,minecraft:soul_sand)
B(0,107,6,minecraft:soul_sand)
B(0,108,6,minecraft:soul_sand)
B(0,109,6,minecraft:soul_sand)
B(0,110,6,minecraft:soul_sand)
B(0,111,6,minecraft:soul_sand)
B(0,0,7,minecraft:netherrack)
B(0,1,7,minecraft:netherrack)
B(0,2,7,minecraft:soul_soil)
B(0,3,7,minecraft:soul_soil)
B(0,4,7,minecraft:soul_soil)
B(0,5,7,minecraft:soul_sand)
B(0,101,7,minecraft:soul_sand)
B(0,102,7,minecraft:soul_sand)
B(0,103,7,minecraft:soul_sand)
B(0,104,7,minecraft:soul_sand)
B(0,105,7,minecraft:soul_sand)
B(0,106,7,minecraft:soul_sand)
B(0,107,7,minecraft:soul_sand)
B(0,108,7,minecraft:soul_sand)
B(0,109,7,minecraft:soul_sand)
B(0,110,7,minecraft:soul_sand)
B(0,111,7,minecraft:soul_sand)
B(0,0,8,minecraft:netherrack)
B(0,1,8,minecraft:netherrack)
B(0,2,8,minecraft:soul_soil)
B(0,3,8,minecraft:soul_soil)
B(0,4,8,minecraft:soul_soil)
B(0,5,8,minecraft:soul_sand)
B(0,101,8,minecraft:soul_sand)
B(0,102,8,minecraft:soul_sand)
B(0,103,8,minecraft:soul_sand)
B(0,104,8,minecraft:soul_sand)
B(0,105,8,minecraft:soul_sand)
B(0,106,8,minecraft:soul_sand)
B(0,107,8,minecraft:soul_sand)
B(0,108,8,minecraft:soul_sand)
B(0,109,8,minecraft:soul_sand)
B(0,110,8,minecraft:soul_sand)
B(0,111,8,minecraft:soul_sand)

#######################################################################
# +-----------------------------------------------------------------+ #
# |                             Branches                            | #
# +-----------------------------------------------------------------+ #
#######################################################################


#######################################################################
# +-----------------------------------------------------------------+ #
# |                             Entities                            | #
# +-----------------------------------------------------------------+ #
#######################################################################

