
#######################################################################
# +-----------------------------------------------------------------+ #
# |                            BO4 object                           | #
# +-----------------------------------------------------------------+ #
#######################################################################

Author: Unknown

Description: No description given

SettingsMode: WriteWithoutComments


#######################################################################
# +-----------------------------------------------------------------+ #
# |                          Main settings                          | #
# +-----------------------------------------------------------------+ #
#######################################################################

FixedRotation: 

Frequency: 0

SpawnHeight: highestBlock

UseCenterForHighestBlock: true

##############################
# Height Limits for the BO4. #
##############################

MinHeight: 0

MaxHeight: 255

InheritBO3: 

InheritBO3Rotation: NORTH

OverrideChildSettings: true

OverrideParentHeight: false

CanOverride: false

BranchFrequency: 0

BranchFrequencyGroup: 

MustBeBelowOther: false

MustBeInside: 

CannotBeInside: 

ReplacesBO3: 

MustBeInsideWorldBorders: false

CanSpawnOnWater: true

SpawnOnWaterOnly: false

SpawnUnderWater: false

SpawnAtWaterLevel: false

HeightOffset: 0

RemoveAir: true

ReplaceAbove: 

ReplaceBelow: 

ReplaceWithBiomeBlocks: true

ReplaceWithSurfaceBlock: GRASS

ReplaceWithGroundBlock: DIRT

ReplaceWithStoneBlock: STONE

SmoothRadius: 0

SmoothHeightOffset: 0

SmoothStartTop: false

SmoothStartWood: false

SmoothingSurfaceBlock: 

SmoothingGroundBlock: 

BO3Group: 

IsSpawnPoint: false

DoReplaceBlocks: true


#######################################################################
# +-----------------------------------------------------------------+ #
# |                              Blocks                             | #
# +-----------------------------------------------------------------+ #
#######################################################################

B(-6,90,4,minecraft:netherrack)
B(-6,90,5,minecraft:netherrack)
B(-6,90,6,minecraft:netherrack)
B(-6,90,7,minecraft:netherrack)
B(-6,90,8,minecraft:netherrack)
B(-5,89,4,minecraft:netherrack)
B(-5,90,4,minecraft:blackstone)
B(-5,89,5,minecraft:netherrack)
B(-5,90,5,minecraft:blackstone)
B(-5,90,6,minecraft:netherrack)
B(-5,90,7,minecraft:netherrack)
B(-5,90,8,minecraft:netherrack)
B(-4,89,-7,minecraft:netherrack)
B(-4,90,-7,minecraft:netherrack)
B(-4,89,-6,minecraft:netherrack)
B(-4,90,-6,minecraft:netherrack)
B(-4,89,-5,minecraft:netherrack)
B(-4,90,-5,minecraft:netherrack)
B(-4,90,-4,minecraft:netherrack)
B(-4,82,-3,minecraft:netherrack)
B(-4,83,-3,minecraft:netherrack)
B(-4,84,-3,minecraft:netherrack)
B(-4,85,-3,minecraft:netherrack)
B(-4,86,-3,minecraft:netherrack)
B(-4,87,-3,minecraft:netherrack)
B(-4,88,-3,minecraft:netherrack)
B(-4,89,-3,minecraft:netherrack)
B(-4,90,-3,minecraft:netherrack)
B(-4,74,-2,minecraft:netherrack)
B(-4,75,-2,minecraft:netherrack)
B(-4,76,-2,minecraft:netherrack)
B(-4,77,-2,minecraft:netherrack)
B(-4,78,-2,minecraft:netherrack)
B(-4,79,-2,minecraft:netherrack)
B(-4,80,-2,minecraft:netherrack)
B(-4,81,-2,minecraft:netherrack)
B(-4,82,-2,minecraft:netherrack)
B(-4,83,-2,minecraft:netherrack)
B(-4,84,-2,minecraft:netherrack)
B(-4,85,-2,minecraft:netherrack)
B(-4,86,-2,minecraft:netherrack)
B(-4,87,-2,minecraft:netherrack)
B(-4,88,-2,minecraft:netherrack)
B(-4,89,-2,minecraft:netherrack)
B(-4,90,-2,minecraft:netherrack)
B(-4,71,-1,minecraft:netherrack)
B(-4,72,-1,minecraft:netherrack)
B(-4,73,-1,minecraft:netherrack)
B(-4,74,-1,minecraft:netherrack)
B(-4,75,-1,minecraft:netherrack)
B(-4,76,-1,minecraft:netherrack)
B(-4,77,-1,minecraft:netherrack)
B(-4,78,-1,minecraft:netherrack)
B(-4,79,-1,minecraft:netherrack)
B(-4,80,-1,minecraft:netherrack)
B(-4,81,-1,minecraft:netherrack)
B(-4,82,-1,minecraft:netherrack)
B(-4,83,-1,minecraft:netherrack)
B(-4,84,-1,minecraft:netherrack)
B(-4,85,-1,minecraft:netherrack)
B(-4,86,-1,minecraft:netherrack)
B(-4,87,-1,minecraft:netherrack)
B(-4,88,-1,minecraft:netherrack)
B(-4,89,-1,minecraft:netherrack)
B(-4,90,-1,minecraft:netherrack)
B(-4,69,0,minecraft:netherrack)
B(-4,70,0,minecraft:netherrack)
B(-4,71,0,minecraft:netherrack)
B(-4,72,0,minecraft:netherrack)
B(-4,73,0,minecraft:netherrack)
B(-4,74,0,minecraft:netherrack)
B(-4,75,0,minecraft:netherrack)
B(-4,76,0,minecraft:netherrack)
B(-4,77,0,minecraft:netherrack)
B(-4,78,0,minecraft:netherrack)
B(-4,79,0,minecraft:netherrack)
B(-4,80,0,minecraft:netherrack)
B(-4,81,0,minecraft:netherrack)
B(-4,82,0,minecraft:netherrack)
B(-4,83,0,minecraft:netherrack)
B(-4,84,0,minecraft:netherrack)
B(-4,85,0,minecraft:netherrack)
B(-4,86,0,minecraft:netherrack)
B(-4,87,0,minecraft:netherrack)
B(-4,88,0,minecraft:netherrack)
B(-4,89,0,minecraft:netherrack)
B(-4,90,0,minecraft:netherrack)
B(-4,77,1,minecraft:netherrack)
B(-4,78,1,minecraft:netherrack)
B(-4,79,1,minecraft:netherrack)
B(-4,80,1,minecraft:netherrack)
B(-4,81,1,minecraft:netherrack)
B(-4,82,1,minecraft:netherrack)
B(-4,83,1,minecraft:netherrack)
B(-4,84,1,minecraft:netherrack)
B(-4,85,1,minecraft:netherrack)
B(-4,86,1,minecraft:netherrack)
B(-4,87,1,minecraft:netherrack)
B(-4,88,1,minecraft:netherrack)
B(-4,89,1,minecraft:netherrack)
B(-4,90,1,minecraft:netherrack)
B(-4,89,2,minecraft:netherrack)
B(-4,90,2,minecraft:netherrack)
B(-4,90,3,minecraft:netherrack)
B(-4,89,4,minecraft:netherrack)
B(-4,90,4,minecraft:blackstone)
B(-4,89,5,minecraft:netherrack)
B(-4,90,5,minecraft:blackstone)
B(-4,89,6,minecraft:netherrack)
B(-4,90,6,minecraft:blackstone)
B(-4,89,7,minecraft:netherrack)
B(-4,90,7,minecraft:blackstone)
B(-4,89,8,minecraft:netherrack)
B(-4,90,8,minecraft:blackstone)
B(-3,80,-7,minecraft:netherrack)
B(-3,81,-7,minecraft:netherrack)
B(-3,82,-7,minecraft:netherrack)
B(-3,83,-7,minecraft:netherrack)
B(-3,84,-7,minecraft:netherrack)
B(-3,85,-7,minecraft:netherrack)
B(-3,86,-7,minecraft:netherrack)
B(-3,87,-7,minecraft:netherrack)
B(-3,88,-7,minecraft:netherrack)
B(-3,89,-7,minecraft:netherrack)
B(-3,90,-7,minecraft:netherrack)
B(-3,78,-6,minecraft:netherrack)
B(-3,79,-6,minecraft:netherrack)
B(-3,80,-6,minecraft:netherrack)
B(-3,81,-6,minecraft:netherrack)
B(-3,82,-6,minecraft:netherrack)
B(-3,83,-6,minecraft:netherrack)
B(-3,84,-6,minecraft:netherrack)
B(-3,85,-6,minecraft:netherrack)
B(-3,86,-6,minecraft:netherrack)
B(-3,87,-6,minecraft:netherrack)
B(-3,88,-6,minecraft:netherrack)
B(-3,89,-6,minecraft:netherrack)
B(-3,90,-6,minecraft:netherrack)
B(-3,78,-5,minecraft:netherrack)
B(-3,79,-5,minecraft:netherrack)
B(-3,80,-5,minecraft:netherrack)
B(-3,81,-5,minecraft:netherrack)
B(-3,82,-5,minecraft:netherrack)
B(-3,83,-5,minecraft:netherrack)
B(-3,84,-5,minecraft:netherrack)
B(-3,85,-5,minecraft:netherrack)
B(-3,86,-5,minecraft:netherrack)
B(-3,87,-5,minecraft:netherrack)
B(-3,88,-5,minecraft:netherrack)
B(-3,89,-5,minecraft:netherrack)
B(-3,90,-5,minecraft:netherrack)
B(-3,61,-4,minecraft:netherrack)
B(-3,62,-4,minecraft:netherrack)
B(-3,63,-4,minecraft:netherrack)
B(-3,64,-4,minecraft:netherrack)
B(-3,65,-4,minecraft:netherrack)
B(-3,66,-4,minecraft:netherrack)
B(-3,67,-4,minecraft:netherrack)
B(-3,68,-4,minecraft:netherrack)
B(-3,69,-4,minecraft:netherrack)
B(-3,70,-4,minecraft:netherrack)
B(-3,71,-4,minecraft:netherrack)
B(-3,72,-4,minecraft:netherrack)
B(-3,73,-4,minecraft:netherrack)
B(-3,74,-4,minecraft:netherrack)
B(-3,75,-4,minecraft:netherrack)
B(-3,76,-4,minecraft:netherrack)
B(-3,77,-4,minecraft:netherrack)
B(-3,78,-4,minecraft:netherrack)
B(-3,79,-4,minecraft:netherrack)
B(-3,80,-4,minecraft:netherrack)
B(-3,81,-4,minecraft:netherrack)
B(-3,82,-4,minecraft:netherrack)
B(-3,83,-4,minecraft:netherrack)
B(-3,84,-4,minecraft:netherrack)
B(-3,85,-4,minecraft:netherrack)
B(-3,86,-4,minecraft:netherrack)
B(-3,87,-4,minecraft:netherrack)
B(-3,88,-4,minecraft:netherrack)
B(-3,89,-4,minecraft:netherrack)
B(-3,90,-4,minecraft:netherrack)
B(-3,62,-3,minecraft:netherrack)
B(-3,63,-3,minecraft:netherrack)
B(-3,64,-3,minecraft:netherrack)
B(-3,65,-3,minecraft:netherrack)
B(-3,66,-3,minecraft:netherrack)
B(-3,67,-3,minecraft:netherrack)
B(-3,68,-3,minecraft:netherrack)
B(-3,69,-3,minecraft:netherrack)
B(-3,70,-3,minecraft:netherrack)
B(-3,71,-3,minecraft:netherrack)
B(-3,72,-3,minecraft:netherrack)
B(-3,73,-3,minecraft:netherrack)
B(-3,74,-3,minecraft:netherrack)
B(-3,75,-3,minecraft:netherrack)
B(-3,76,-3,minecraft:netherrack)
B(-3,77,-3,minecraft:netherrack)
B(-3,78,-3,minecraft:netherrack)
B(-3,79,-3,minecraft:netherrack)
B(-3,80,-3,minecraft:netherrack)
B(-3,81,-3,minecraft:netherrack)
B(-3,82,-3,minecraft:netherrack)
B(-3,83,-3,minecraft:netherrack)
B(-3,84,-3,minecraft:netherrack)
B(-3,85,-3,minecraft:netherrack)
B(-3,86,-3,minecraft:netherrack)
B(-3,87,-3,minecraft:netherrack)
B(-3,88,-3,minecraft:netherrack)
B(-3,89,-3,minecraft:netherrack)
B(-3,90,-3,minecraft:netherrack)
B(-3,64,-2,minecraft:netherrack)
B(-3,65,-2,minecraft:netherrack)
B(-3,66,-2,minecraft:netherrack)
B(-3,67,-2,minecraft:netherrack)
B(-3,68,-2,minecraft:netherrack)
B(-3,69,-2,minecraft:netherrack)
B(-3,70,-2,minecraft:netherrack)
B(-3,71,-2,minecraft:netherrack)
B(-3,72,-2,minecraft:netherrack)
B(-3,73,-2,minecraft:netherrack)
B(-3,74,-2,minecraft:netherrack)
B(-3,75,-2,minecraft:netherrack)
B(-3,76,-2,minecraft:netherrack)
B(-3,77,-2,minecraft:netherrack)
B(-3,78,-2,minecraft:netherrack)
B(-3,79,-2,minecraft:netherrack)
B(-3,80,-2,minecraft:netherrack)
B(-3,81,-2,minecraft:netherrack)
B(-3,82,-2,minecraft:netherrack)
B(-3,83,-2,minecraft:netherrack)
B(-3,84,-2,minecraft:netherrack)
B(-3,85,-2,minecraft:netherrack)
B(-3,86,-2,minecraft:netherrack)
B(-3,87,-2,minecraft:netherrack)
B(-3,88,-2,minecraft:netherrack)
B(-3,89,-2,minecraft:netherrack)
B(-3,90,-2,minecraft:netherrack)
B(-3,64,-1,minecraft:netherrack)
B(-3,65,-1,minecraft:netherrack)
B(-3,66,-1,minecraft:netherrack)
B(-3,67,-1,minecraft:netherrack)
B(-3,68,-1,minecraft:netherrack)
B(-3,69,-1,minecraft:netherrack)
B(-3,70,-1,minecraft:netherrack)
B(-3,71,-1,minecraft:netherrack)
B(-3,72,-1,minecraft:netherrack)
B(-3,73,-1,minecraft:netherrack)
B(-3,74,-1,minecraft:netherrack)
B(-3,75,-1,minecraft:netherrack)
B(-3,76,-1,minecraft:netherrack)
B(-3,77,-1,minecraft:netherrack)
B(-3,78,-1,minecraft:netherrack)
B(-3,79,-1,minecraft:netherrack)
B(-3,80,-1,minecraft:netherrack)
B(-3,81,-1,minecraft:netherrack)
B(-3,82,-1,minecraft:netherrack)
B(-3,83,-1,minecraft:netherrack)
B(-3,84,-1,minecraft:netherrack)
B(-3,85,-1,minecraft:netherrack)
B(-3,86,-1,minecraft:netherrack)
B(-3,87,-1,minecraft:netherrack)
B(-3,88,-1,minecraft:netherrack)
B(-3,89,-1,minecraft:netherrack)
B(-3,90,-1,minecraft:netherrack)
B(-3,61,0,minecraft:netherrack)
B(-3,62,0,minecraft:netherrack)
B(-3,63,0,minecraft:netherrack)
B(-3,64,0,minecraft:netherrack)
B(-3,65,0,minecraft:netherrack)
B(-3,66,0,minecraft:netherrack)
B(-3,67,0,minecraft:netherrack)
B(-3,68,0,minecraft:netherrack)
B(-3,69,0,minecraft:netherrack)
B(-3,70,0,minecraft:netherrack)
B(-3,71,0,minecraft:netherrack)
B(-3,72,0,minecraft:netherrack)
B(-3,73,0,minecraft:netherrack)
B(-3,74,0,minecraft:netherrack)
B(-3,75,0,minecraft:netherrack)
B(-3,76,0,minecraft:netherrack)
B(-3,77,0,minecraft:netherrack)
B(-3,78,0,minecraft:netherrack)
B(-3,79,0,minecraft:netherrack)
B(-3,80,0,minecraft:netherrack)
B(-3,81,0,minecraft:netherrack)
B(-3,82,0,minecraft:netherrack)
B(-3,83,0,minecraft:netherrack)
B(-3,84,0,minecraft:netherrack)
B(-3,85,0,minecraft:netherrack)
B(-3,86,0,minecraft:netherrack)
B(-3,87,0,minecraft:netherrack)
B(-3,88,0,minecraft:netherrack)
B(-3,89,0,minecraft:netherrack)
B(-3,90,0,minecraft:netherrack)
B(-3,57,1,minecraft:netherrack)
B(-3,58,1,minecraft:netherrack)
B(-3,59,1,minecraft:netherrack)
B(-3,60,1,minecraft:netherrack)
B(-3,61,1,minecraft:netherrack)
B(-3,62,1,minecraft:netherrack)
B(-3,63,1,minecraft:netherrack)
B(-3,64,1,minecraft:netherrack)
B(-3,65,1,minecraft:netherrack)
B(-3,66,1,minecraft:netherrack)
B(-3,67,1,minecraft:netherrack)
B(-3,68,1,minecraft:netherrack)
B(-3,69,1,minecraft:netherrack)
B(-3,70,1,minecraft:netherrack)
B(-3,71,1,minecraft:netherrack)
B(-3,72,1,minecraft:netherrack)
B(-3,73,1,minecraft:netherrack)
B(-3,74,1,minecraft:netherrack)
B(-3,75,1,minecraft:netherrack)
B(-3,76,1,minecraft:netherrack)
B(-3,77,1,minecraft:netherrack)
B(-3,78,1,minecraft:netherrack)
B(-3,79,1,minecraft:netherrack)
B(-3,80,1,minecraft:netherrack)
B(-3,81,1,minecraft:netherrack)
B(-3,82,1,minecraft:netherrack)
B(-3,83,1,minecraft:netherrack)
B(-3,84,1,minecraft:netherrack)
B(-3,85,1,minecraft:netherrack)
B(-3,86,1,minecraft:netherrack)
B(-3,87,1,minecraft:netherrack)
B(-3,88,1,minecraft:netherrack)
B(-3,89,1,minecraft:netherrack)
B(-3,90,1,minecraft:netherrack)
B(-3,59,2,minecraft:netherrack)
B(-3,60,2,minecraft:netherrack)
B(-3,61,2,minecraft:netherrack)
B(-3,62,2,minecraft:netherrack)
B(-3,63,2,minecraft:netherrack)
B(-3,64,2,minecraft:netherrack)
B(-3,65,2,minecraft:netherrack)
B(-3,66,2,minecraft:netherrack)
B(-3,67,2,minecraft:netherrack)
B(-3,68,2,minecraft:netherrack)
B(-3,69,2,minecraft:netherrack)
B(-3,70,2,minecraft:netherrack)
B(-3,71,2,minecraft:netherrack)
B(-3,72,2,minecraft:netherrack)
B(-3,73,2,minecraft:netherrack)
B(-3,74,2,minecraft:netherrack)
B(-3,75,2,minecraft:netherrack)
B(-3,76,2,minecraft:netherrack)
B(-3,77,2,minecraft:netherrack)
B(-3,78,2,minecraft:netherrack)
B(-3,79,2,minecraft:netherrack)
B(-3,80,2,minecraft:netherrack)
B(-3,81,2,minecraft:netherrack)
B(-3,82,2,minecraft:netherrack)
B(-3,83,2,minecraft:netherrack)
B(-3,84,2,minecraft:netherrack)
B(-3,85,2,minecraft:netherrack)
B(-3,86,2,minecraft:netherrack)
B(-3,87,2,minecraft:netherrack)
B(-3,88,2,minecraft:netherrack)
B(-3,89,2,minecraft:netherrack)
B(-3,90,2,minecraft:netherrack)
B(-3,78,3,minecraft:netherrack)
B(-3,79,3,minecraft:netherrack)
B(-3,80,3,minecraft:netherrack)
B(-3,81,3,minecraft:netherrack)
B(-3,82,3,minecraft:netherrack)
B(-3,83,3,minecraft:netherrack)
B(-3,84,3,minecraft:netherrack)
B(-3,85,3,minecraft:netherrack)
B(-3,86,3,minecraft:netherrack)
B(-3,87,3,minecraft:netherrack)
B(-3,88,3,minecraft:netherrack)
B(-3,89,3,minecraft:netherrack)
B(-3,90,3,minecraft:netherrack)
B(-3,82,4,minecraft:netherrack)
B(-3,83,4,minecraft:netherrack)
B(-3,84,4,minecraft:netherrack)
B(-3,85,4,minecraft:netherrack)
B(-3,86,4,minecraft:netherrack)
B(-3,87,4,minecraft:netherrack)
B(-3,88,4,minecraft:netherrack)
B(-3,89,4,minecraft:netherrack)
B(-3,90,4,minecraft:netherrack)
B(-3,85,5,minecraft:netherrack)
B(-3,86,5,minecraft:netherrack)
B(-3,87,5,minecraft:netherrack)
B(-3,88,5,minecraft:netherrack)
B(-3,89,5,minecraft:blackstone)
B(-3,90,5,minecraft:blackstone)
B(-3,85,6,minecraft:netherrack)
B(-3,86,6,minecraft:netherrack)
B(-3,87,6,minecraft:netherrack)
B(-3,88,6,minecraft:netherrack)
B(-3,89,6,minecraft:blackstone)
B(-3,90,6,minecraft:blackstone)
B(-3,81,7,minecraft:netherrack)
B(-3,82,7,minecraft:netherrack)
B(-3,83,7,minecraft:netherrack)
B(-3,84,7,minecraft:netherrack)
B(-3,85,7,minecraft:netherrack)
B(-3,86,7,minecraft:netherrack)
B(-3,87,7,minecraft:netherrack)
B(-3,88,7,minecraft:netherrack)
B(-3,89,7,minecraft:netherrack)
B(-3,90,7,minecraft:blackstone)
B(-3,80,8,minecraft:netherrack)
B(-3,81,8,minecraft:netherrack)
B(-3,82,8,minecraft:netherrack)
B(-3,83,8,minecraft:netherrack)
B(-3,84,8,minecraft:netherrack)
B(-3,85,8,minecraft:netherrack)
B(-3,86,8,minecraft:netherrack)
B(-3,87,8,minecraft:netherrack)
B(-3,88,8,minecraft:netherrack)
B(-3,89,8,minecraft:netherrack)
B(-3,90,8,minecraft:blackstone)
B(-2,59,-7,minecraft:netherrack)
B(-2,60,-7,minecraft:netherrack)
B(-2,61,-7,minecraft:netherrack)
B(-2,62,-7,minecraft:netherrack)
B(-2,63,-7,minecraft:netherrack)
B(-2,64,-7,minecraft:netherrack)
B(-2,65,-7,minecraft:netherrack)
B(-2,66,-7,minecraft:netherrack)
B(-2,67,-7,minecraft:netherrack)
B(-2,68,-7,minecraft:netherrack)
B(-2,69,-7,minecraft:netherrack)
B(-2,70,-7,minecraft:netherrack)
B(-2,71,-7,minecraft:netherrack)
B(-2,72,-7,minecraft:netherrack)
B(-2,73,-7,minecraft:netherrack)
B(-2,74,-7,minecraft:netherrack)
B(-2,75,-7,minecraft:netherrack)
B(-2,76,-7,minecraft:netherrack)
B(-2,77,-7,minecraft:netherrack)
B(-2,78,-7,minecraft:netherrack)
B(-2,79,-7,minecraft:netherrack)
B(-2,80,-7,minecraft:netherrack)
B(-2,81,-7,minecraft:netherrack)
B(-2,82,-7,minecraft:netherrack)
B(-2,83,-7,minecraft:netherrack)
B(-2,84,-7,minecraft:netherrack)
B(-2,85,-7,minecraft:netherrack)
B(-2,86,-7,minecraft:netherrack)
B(-2,87,-7,minecraft:netherrack)
B(-2,88,-7,minecraft:netherrack)
B(-2,89,-7,minecraft:netherrack)
B(-2,90,-7,minecraft:netherrack)
B(-2,59,-6,minecraft:netherrack)
B(-2,60,-6,minecraft:netherrack)
B(-2,61,-6,minecraft:netherrack)
B(-2,62,-6,minecraft:netherrack)
B(-2,63,-6,minecraft:netherrack)
B(-2,64,-6,minecraft:netherrack)
B(-2,65,-6,minecraft:netherrack)
B(-2,66,-6,minecraft:netherrack)
B(-2,67,-6,minecraft:netherrack)
B(-2,68,-6,minecraft:netherrack)
B(-2,69,-6,minecraft:netherrack)
B(-2,70,-6,minecraft:netherrack)
B(-2,71,-6,minecraft:netherrack)
B(-2,72,-6,minecraft:netherrack)
B(-2,73,-6,minecraft:netherrack)
B(-2,74,-6,minecraft:netherrack)
B(-2,75,-6,minecraft:netherrack)
B(-2,76,-6,minecraft:netherrack)
B(-2,77,-6,minecraft:netherrack)
B(-2,78,-6,minecraft:netherrack)
B(-2,79,-6,minecraft:netherrack)
B(-2,80,-6,minecraft:netherrack)
B(-2,81,-6,minecraft:netherrack)
B(-2,82,-6,minecraft:netherrack)
B(-2,83,-6,minecraft:netherrack)
B(-2,84,-6,minecraft:netherrack)
B(-2,85,-6,minecraft:netherrack)
B(-2,86,-6,minecraft:netherrack)
B(-2,87,-6,minecraft:netherrack)
B(-2,88,-6,minecraft:netherrack)
B(-2,89,-6,minecraft:netherrack)
B(-2,90,-6,minecraft:netherrack)
B(-2,43,-5,minecraft:netherrack)
B(-2,44,-5,minecraft:netherrack)
B(-2,45,-5,minecraft:netherrack)
B(-2,46,-5,minecraft:netherrack)
B(-2,47,-5,minecraft:netherrack)
B(-2,48,-5,minecraft:netherrack)
B(-2,49,-5,minecraft:netherrack)
B(-2,50,-5,minecraft:netherrack)
B(-2,51,-5,minecraft:netherrack)
B(-2,52,-5,minecraft:netherrack)
B(-2,53,-5,minecraft:netherrack)
B(-2,54,-5,minecraft:netherrack)
B(-2,55,-5,minecraft:netherrack)
B(-2,56,-5,minecraft:netherrack)
B(-2,57,-5,minecraft:netherrack)
B(-2,58,-5,minecraft:netherrack)
B(-2,59,-5,minecraft:netherrack)
B(-2,60,-5,minecraft:netherrack)
B(-2,61,-5,minecraft:netherrack)
B(-2,62,-5,minecraft:netherrack)
B(-2,63,-5,minecraft:netherrack)
B(-2,64,-5,minecraft:netherrack)
B(-2,65,-5,minecraft:netherrack)
B(-2,66,-5,minecraft:netherrack)
B(-2,67,-5,minecraft:netherrack)
B(-2,68,-5,minecraft:netherrack)
B(-2,69,-5,minecraft:netherrack)
B(-2,70,-5,minecraft:netherrack)
B(-2,71,-5,minecraft:netherrack)
B(-2,72,-5,minecraft:netherrack)
B(-2,73,-5,minecraft:netherrack)
B(-2,74,-5,minecraft:netherrack)
B(-2,75,-5,minecraft:netherrack)
B(-2,76,-5,minecraft:netherrack)
B(-2,77,-5,minecraft:netherrack)
B(-2,78,-5,minecraft:netherrack)
B(-2,79,-5,minecraft:netherrack)
B(-2,80,-5,minecraft:netherrack)
B(-2,81,-5,minecraft:netherrack)
B(-2,82,-5,minecraft:netherrack)
B(-2,83,-5,minecraft:netherrack)
B(-2,84,-5,minecraft:netherrack)
B(-2,85,-5,minecraft:netherrack)
B(-2,86,-5,minecraft:netherrack)
B(-2,87,-5,minecraft:netherrack)
B(-2,88,-5,minecraft:netherrack)
B(-2,89,-5,minecraft:netherrack)
B(-2,90,-5,minecraft:netherrack)
B(-2,49,-4,minecraft:netherrack)
B(-2,50,-4,minecraft:netherrack)
B(-2,51,-4,minecraft:netherrack)
B(-2,52,-4,minecraft:netherrack)
B(-2,53,-4,minecraft:netherrack)
B(-2,54,-4,minecraft:netherrack)
B(-2,55,-4,minecraft:netherrack)
B(-2,56,-4,minecraft:netherrack)
B(-2,57,-4,minecraft:netherrack)
B(-2,58,-4,minecraft:netherrack)
B(-2,59,-4,minecraft:netherrack)
B(-2,60,-4,minecraft:netherrack)
B(-2,61,-4,minecraft:netherrack)
B(-2,62,-4,minecraft:netherrack)
B(-2,63,-4,minecraft:netherrack)
B(-2,64,-4,minecraft:netherrack)
B(-2,65,-4,minecraft:netherrack)
B(-2,66,-4,minecraft:netherrack)
B(-2,67,-4,minecraft:netherrack)
B(-2,68,-4,minecraft:netherrack)
B(-2,69,-4,minecraft:netherrack)
B(-2,70,-4,minecraft:netherrack)
B(-2,71,-4,minecraft:netherrack)
B(-2,72,-4,minecraft:netherrack)
B(-2,73,-4,minecraft:netherrack)
B(-2,74,-4,minecraft:netherrack)
B(-2,75,-4,minecraft:netherrack)
B(-2,76,-4,minecraft:netherrack)
B(-2,77,-4,minecraft:netherrack)
B(-2,78,-4,minecraft:netherrack)
B(-2,79,-4,minecraft:netherrack)
B(-2,80,-4,minecraft:netherrack)
B(-2,81,-4,minecraft:netherrack)
B(-2,82,-4,minecraft:netherrack)
B(-2,83,-4,minecraft:netherrack)
B(-2,84,-4,minecraft:netherrack)
B(-2,85,-4,minecraft:netherrack)
B(-2,86,-4,minecraft:netherrack)
B(-2,87,-4,minecraft:netherrack)
B(-2,88,-4,minecraft:netherrack)
B(-2,89,-4,minecraft:netherrack)
B(-2,90,-4,minecraft:netherrack)
B(-2,56,-3,minecraft:netherrack)
B(-2,57,-3,minecraft:netherrack)
B(-2,58,-3,minecraft:netherrack)
B(-2,59,-3,minecraft:netherrack)
B(-2,60,-3,minecraft:netherrack)
B(-2,61,-3,minecraft:netherrack)
B(-2,62,-3,minecraft:netherrack)
B(-2,63,-3,minecraft:netherrack)
B(-2,64,-3,minecraft:netherrack)
B(-2,65,-3,minecraft:netherrack)
B(-2,66,-3,minecraft:netherrack)
B(-2,67,-3,minecraft:netherrack)
B(-2,68,-3,minecraft:netherrack)
B(-2,69,-3,minecraft:netherrack)
B(-2,70,-3,minecraft:netherrack)
B(-2,71,-3,minecraft:netherrack)
B(-2,72,-3,minecraft:netherrack)
B(-2,73,-3,minecraft:netherrack)
B(-2,74,-3,minecraft:netherrack)
B(-2,75,-3,minecraft:netherrack)
B(-2,76,-3,minecraft:netherrack)
B(-2,77,-3,minecraft:netherrack)
B(-2,78,-3,minecraft:netherrack)
B(-2,79,-3,minecraft:netherrack)
B(-2,80,-3,minecraft:netherrack)
B(-2,81,-3,minecraft:netherrack)
B(-2,82,-3,minecraft:netherrack)
B(-2,83,-3,minecraft:netherrack)
B(-2,84,-3,minecraft:netherrack)
B(-2,85,-3,minecraft:netherrack)
B(-2,86,-3,minecraft:netherrack)
B(-2,87,-3,minecraft:netherrack)
B(-2,88,-3,minecraft:netherrack)
B(-2,89,-3,minecraft:netherrack)
B(-2,90,-3,minecraft:netherrack)
B(-2,61,-2,minecraft:netherrack)
B(-2,62,-2,minecraft:netherrack)
B(-2,63,-2,minecraft:netherrack)
B(-2,64,-2,minecraft:netherrack)
B(-2,65,-2,minecraft:netherrack)
B(-2,66,-2,minecraft:netherrack)
B(-2,67,-2,minecraft:netherrack)
B(-2,68,-2,minecraft:netherrack)
B(-2,69,-2,minecraft:netherrack)
B(-2,70,-2,minecraft:netherrack)
B(-2,71,-2,minecraft:netherrack)
B(-2,72,-2,minecraft:netherrack)
B(-2,73,-2,minecraft:netherrack)
B(-2,74,-2,minecraft:netherrack)
B(-2,75,-2,minecraft:netherrack)
B(-2,76,-2,minecraft:netherrack)
B(-2,77,-2,minecraft:netherrack)
B(-2,78,-2,minecraft:netherrack)
B(-2,79,-2,minecraft:netherrack)
B(-2,80,-2,minecraft:netherrack)
B(-2,81,-2,minecraft:netherrack)
B(-2,82,-2,minecraft:netherrack)
B(-2,83,-2,minecraft:netherrack)
B(-2,84,-2,minecraft:netherrack)
B(-2,85,-2,minecraft:netherrack)
B(-2,86,-2,minecraft:netherrack)
B(-2,87,-2,minecraft:netherrack)
B(-2,88,-2,minecraft:netherrack)
B(-2,89,-2,minecraft:netherrack)
B(-2,90,-2,minecraft:netherrack)
B(-2,58,-1,minecraft:netherrack)
B(-2,59,-1,minecraft:netherrack)
B(-2,60,-1,minecraft:netherrack)
B(-2,61,-1,minecraft:netherrack)
B(-2,62,-1,minecraft:netherrack)
B(-2,63,-1,minecraft:netherrack)
B(-2,64,-1,minecraft:netherrack)
B(-2,65,-1,minecraft:netherrack)
B(-2,66,-1,minecraft:netherrack)
B(-2,67,-1,minecraft:netherrack)
B(-2,68,-1,minecraft:netherrack)
B(-2,69,-1,minecraft:netherrack)
B(-2,70,-1,minecraft:netherrack)
B(-2,71,-1,minecraft:netherrack)
B(-2,72,-1,minecraft:netherrack)
B(-2,73,-1,minecraft:netherrack)
B(-2,74,-1,minecraft:netherrack)
B(-2,75,-1,minecraft:netherrack)
B(-2,76,-1,minecraft:netherrack)
B(-2,77,-1,minecraft:netherrack)
B(-2,78,-1,minecraft:netherrack)
B(-2,79,-1,minecraft:netherrack)
B(-2,80,-1,minecraft:netherrack)
B(-2,81,-1,minecraft:netherrack)
B(-2,82,-1,minecraft:netherrack)
B(-2,83,-1,minecraft:netherrack)
B(-2,84,-1,minecraft:netherrack)
B(-2,85,-1,minecraft:netherrack)
B(-2,86,-1,minecraft:netherrack)
B(-2,87,-1,minecraft:netherrack)
B(-2,88,-1,minecraft:netherrack)
B(-2,89,-1,minecraft:netherrack)
B(-2,90,-1,minecraft:netherrack)
B(-2,49,0,minecraft:netherrack)
B(-2,50,0,minecraft:netherrack)
B(-2,51,0,minecraft:netherrack)
B(-2,52,0,minecraft:netherrack)
B(-2,53,0,minecraft:netherrack)
B(-2,54,0,minecraft:netherrack)
B(-2,55,0,minecraft:netherrack)
B(-2,56,0,minecraft:netherrack)
B(-2,57,0,minecraft:netherrack)
B(-2,58,0,minecraft:netherrack)
B(-2,59,0,minecraft:netherrack)
B(-2,60,0,minecraft:netherrack)
B(-2,61,0,minecraft:netherrack)
B(-2,62,0,minecraft:netherrack)
B(-2,63,0,minecraft:netherrack)
B(-2,64,0,minecraft:netherrack)
B(-2,65,0,minecraft:netherrack)
B(-2,66,0,minecraft:netherrack)
B(-2,67,0,minecraft:netherrack)
B(-2,68,0,minecraft:netherrack)
B(-2,69,0,minecraft:netherrack)
B(-2,70,0,minecraft:netherrack)
B(-2,71,0,minecraft:netherrack)
B(-2,72,0,minecraft:netherrack)
B(-2,73,0,minecraft:netherrack)
B(-2,74,0,minecraft:netherrack)
B(-2,75,0,minecraft:netherrack)
B(-2,76,0,minecraft:netherrack)
B(-2,77,0,minecraft:netherrack)
B(-2,78,0,minecraft:netherrack)
B(-2,79,0,minecraft:netherrack)
B(-2,80,0,minecraft:netherrack)
B(-2,81,0,minecraft:netherrack)
B(-2,82,0,minecraft:netherrack)
B(-2,83,0,minecraft:netherrack)
B(-2,84,0,minecraft:netherrack)
B(-2,85,0,minecraft:netherrack)
B(-2,86,0,minecraft:netherrack)
B(-2,87,0,minecraft:netherrack)
B(-2,88,0,minecraft:netherrack)
B(-2,89,0,minecraft:netherrack)
B(-2,90,0,minecraft:netherrack)
B(-2,46,1,minecraft:netherrack)
B(-2,47,1,minecraft:netherrack)
B(-2,48,1,minecraft:netherrack)
B(-2,49,1,minecraft:netherrack)
B(-2,50,1,minecraft:netherrack)
B(-2,51,1,minecraft:netherrack)
B(-2,52,1,minecraft:netherrack)
B(-2,53,1,minecraft:netherrack)
B(-2,54,1,minecraft:netherrack)
B(-2,55,1,minecraft:netherrack)
B(-2,56,1,minecraft:netherrack)
B(-2,57,1,minecraft:netherrack)
B(-2,58,1,minecraft:netherrack)
B(-2,59,1,minecraft:netherrack)
B(-2,60,1,minecraft:netherrack)
B(-2,61,1,minecraft:netherrack)
B(-2,62,1,minecraft:netherrack)
B(-2,63,1,minecraft:netherrack)
B(-2,64,1,minecraft:netherrack)
B(-2,65,1,minecraft:netherrack)
B(-2,66,1,minecraft:netherrack)
B(-2,67,1,minecraft:netherrack)
B(-2,68,1,minecraft:netherrack)
B(-2,69,1,minecraft:netherrack)
B(-2,70,1,minecraft:netherrack)
B(-2,71,1,minecraft:netherrack)
B(-2,72,1,minecraft:netherrack)
B(-2,73,1,minecraft:netherrack)
B(-2,74,1,minecraft:netherrack)
B(-2,75,1,minecraft:netherrack)
B(-2,76,1,minecraft:netherrack)
B(-2,77,1,minecraft:netherrack)
B(-2,78,1,minecraft:netherrack)
B(-2,79,1,minecraft:netherrack)
B(-2,80,1,minecraft:netherrack)
B(-2,81,1,minecraft:netherrack)
B(-2,82,1,minecraft:netherrack)
B(-2,83,1,minecraft:netherrack)
B(-2,84,1,minecraft:netherrack)
B(-2,85,1,minecraft:netherrack)
B(-2,86,1,minecraft:netherrack)
B(-2,87,1,minecraft:netherrack)
B(-2,88,1,minecraft:netherrack)
B(-2,89,1,minecraft:netherrack)
B(-2,90,1,minecraft:netherrack)
B(-2,46,2,minecraft:netherrack)
B(-2,47,2,minecraft:netherrack)
B(-2,48,2,minecraft:netherrack)
B(-2,49,2,minecraft:netherrack)
B(-2,50,2,minecraft:netherrack)
B(-2,51,2,minecraft:netherrack)
B(-2,52,2,minecraft:netherrack)
B(-2,53,2,minecraft:netherrack)
B(-2,54,2,minecraft:netherrack)
B(-2,55,2,minecraft:netherrack)
B(-2,56,2,minecraft:netherrack)
B(-2,57,2,minecraft:netherrack)
B(-2,58,2,minecraft:netherrack)
B(-2,59,2,minecraft:netherrack)
B(-2,60,2,minecraft:netherrack)
B(-2,61,2,minecraft:netherrack)
B(-2,62,2,minecraft:netherrack)
B(-2,63,2,minecraft:netherrack)
B(-2,64,2,minecraft:netherrack)
B(-2,65,2,minecraft:netherrack)
B(-2,66,2,minecraft:netherrack)
B(-2,67,2,minecraft:netherrack)
B(-2,68,2,minecraft:netherrack)
B(-2,69,2,minecraft:netherrack)
B(-2,70,2,minecraft:netherrack)
B(-2,71,2,minecraft:netherrack)
B(-2,72,2,minecraft:netherrack)
B(-2,73,2,minecraft:netherrack)
B(-2,74,2,minecraft:netherrack)
B(-2,75,2,minecraft:netherrack)
B(-2,76,2,minecraft:netherrack)
B(-2,77,2,minecraft:netherrack)
B(-2,78,2,minecraft:netherrack)
B(-2,79,2,minecraft:netherrack)
B(-2,80,2,minecraft:netherrack)
B(-2,81,2,minecraft:netherrack)
B(-2,82,2,minecraft:netherrack)
B(-2,83,2,minecraft:netherrack)
B(-2,84,2,minecraft:netherrack)
B(-2,85,2,minecraft:netherrack)
B(-2,86,2,minecraft:netherrack)
B(-2,87,2,minecraft:netherrack)
B(-2,88,2,minecraft:netherrack)
B(-2,89,2,minecraft:netherrack)
B(-2,90,2,minecraft:netherrack)
B(-2,48,3,minecraft:netherrack)
B(-2,49,3,minecraft:netherrack)
B(-2,50,3,minecraft:netherrack)
B(-2,51,3,minecraft:netherrack)
B(-2,52,3,minecraft:netherrack)
B(-2,53,3,minecraft:netherrack)
B(-2,54,3,minecraft:netherrack)
B(-2,55,3,minecraft:netherrack)
B(-2,56,3,minecraft:netherrack)
B(-2,57,3,minecraft:netherrack)
B(-2,58,3,minecraft:netherrack)
B(-2,59,3,minecraft:netherrack)
B(-2,60,3,minecraft:netherrack)
B(-2,61,3,minecraft:netherrack)
B(-2,62,3,minecraft:netherrack)
B(-2,63,3,minecraft:netherrack)
B(-2,64,3,minecraft:netherrack)
B(-2,65,3,minecraft:netherrack)
B(-2,66,3,minecraft:netherrack)
B(-2,67,3,minecraft:netherrack)
B(-2,68,3,minecraft:netherrack)
B(-2,69,3,minecraft:netherrack)
B(-2,70,3,minecraft:netherrack)
B(-2,71,3,minecraft:netherrack)
B(-2,72,3,minecraft:netherrack)
B(-2,73,3,minecraft:netherrack)
B(-2,74,3,minecraft:netherrack)
B(-2,75,3,minecraft:netherrack)
B(-2,76,3,minecraft:netherrack)
B(-2,77,3,minecraft:netherrack)
B(-2,78,3,minecraft:netherrack)
B(-2,79,3,minecraft:netherrack)
B(-2,80,3,minecraft:netherrack)
B(-2,81,3,minecraft:netherrack)
B(-2,82,3,minecraft:netherrack)
B(-2,83,3,minecraft:netherrack)
B(-2,84,3,minecraft:netherrack)
B(-2,85,3,minecraft:netherrack)
B(-2,86,3,minecraft:netherrack)
B(-2,87,3,minecraft:netherrack)
B(-2,88,3,minecraft:netherrack)
B(-2,89,3,minecraft:netherrack)
B(-2,90,3,minecraft:netherrack)
B(-2,69,4,minecraft:netherrack)
B(-2,70,4,minecraft:netherrack)
B(-2,71,4,minecraft:netherrack)
B(-2,72,4,minecraft:netherrack)
B(-2,73,4,minecraft:netherrack)
B(-2,74,4,minecraft:netherrack)
B(-2,75,4,minecraft:netherrack)
B(-2,76,4,minecraft:netherrack)
B(-2,77,4,minecraft:netherrack)
B(-2,78,4,minecraft:netherrack)
B(-2,79,4,minecraft:netherrack)
B(-2,80,4,minecraft:netherrack)
B(-2,81,4,minecraft:netherrack)
B(-2,82,4,minecraft:netherrack)
B(-2,83,4,minecraft:netherrack)
B(-2,84,4,minecraft:netherrack)
B(-2,85,4,minecraft:netherrack)
B(-2,86,4,minecraft:netherrack)
B(-2,87,4,minecraft:netherrack)
B(-2,88,4,minecraft:netherrack)
B(-2,89,4,minecraft:netherrack)
B(-2,90,4,minecraft:netherrack)
B(-2,72,5,minecraft:netherrack)
B(-2,73,5,minecraft:netherrack)
B(-2,74,5,minecraft:netherrack)
B(-2,75,5,minecraft:netherrack)
B(-2,76,5,minecraft:netherrack)
B(-2,77,5,minecraft:netherrack)
B(-2,78,5,minecraft:netherrack)
B(-2,79,5,minecraft:netherrack)
B(-2,80,5,minecraft:netherrack)
B(-2,81,5,minecraft:netherrack)
B(-2,82,5,minecraft:netherrack)
B(-2,83,5,minecraft:netherrack)
B(-2,84,5,minecraft:netherrack)
B(-2,85,5,minecraft:netherrack)
B(-2,86,5,minecraft:netherrack)
B(-2,87,5,minecraft:netherrack)
B(-2,88,5,minecraft:netherrack)
B(-2,89,5,minecraft:netherrack)
B(-2,90,5,minecraft:netherrack)
B(-2,70,6,minecraft:netherrack)
B(-2,71,6,minecraft:netherrack)
B(-2,72,6,minecraft:netherrack)
B(-2,73,6,minecraft:netherrack)
B(-2,74,6,minecraft:netherrack)
B(-2,75,6,minecraft:netherrack)
B(-2,76,6,minecraft:netherrack)
B(-2,77,6,minecraft:netherrack)
B(-2,78,6,minecraft:netherrack)
B(-2,79,6,minecraft:netherrack)
B(-2,80,6,minecraft:netherrack)
B(-2,81,6,minecraft:netherrack)
B(-2,82,6,minecraft:netherrack)
B(-2,83,6,minecraft:netherrack)
B(-2,84,6,minecraft:netherrack)
B(-2,85,6,minecraft:netherrack)
B(-2,86,6,minecraft:netherrack)
B(-2,87,6,minecraft:netherrack)
B(-2,88,6,minecraft:netherrack)
B(-2,89,6,minecraft:netherrack)
B(-2,90,6,minecraft:blackstone)
B(-2,73,7,minecraft:netherrack)
B(-2,74,7,minecraft:netherrack)
B(-2,75,7,minecraft:netherrack)
B(-2,76,7,minecraft:netherrack)
B(-2,77,7,minecraft:netherrack)
B(-2,78,7,minecraft:netherrack)
B(-2,79,7,minecraft:netherrack)
B(-2,80,7,minecraft:netherrack)
B(-2,81,7,minecraft:netherrack)
B(-2,82,7,minecraft:netherrack)
B(-2,83,7,minecraft:netherrack)
B(-2,84,7,minecraft:netherrack)
B(-2,85,7,minecraft:netherrack)
B(-2,86,7,minecraft:netherrack)
B(-2,87,7,minecraft:netherrack)
B(-2,88,7,minecraft:netherrack)
B(-2,89,7,minecraft:netherrack)
B(-2,90,7,minecraft:netherrack)
B(-2,70,8,minecraft:netherrack)
B(-2,71,8,minecraft:netherrack)
B(-2,72,8,minecraft:netherrack)
B(-2,73,8,minecraft:netherrack)
B(-2,74,8,minecraft:netherrack)
B(-2,75,8,minecraft:netherrack)
B(-2,76,8,minecraft:netherrack)
B(-2,77,8,minecraft:netherrack)
B(-2,78,8,minecraft:netherrack)
B(-2,79,8,minecraft:netherrack)
B(-2,80,8,minecraft:netherrack)
B(-2,81,8,minecraft:netherrack)
B(-2,82,8,minecraft:netherrack)
B(-2,83,8,minecraft:netherrack)
B(-2,84,8,minecraft:netherrack)
B(-2,85,8,minecraft:netherrack)
B(-2,86,8,minecraft:netherrack)
B(-2,87,8,minecraft:netherrack)
B(-2,88,8,minecraft:netherrack)
B(-2,89,8,minecraft:netherrack)
B(-2,90,8,minecraft:netherrack)
B(-1,45,-7,minecraft:netherrack)
B(-1,46,-7,minecraft:netherrack)
B(-1,47,-7,minecraft:netherrack)
B(-1,48,-7,minecraft:netherrack)
B(-1,49,-7,minecraft:netherrack)
B(-1,50,-7,minecraft:netherrack)
B(-1,51,-7,minecraft:netherrack)
B(-1,52,-7,minecraft:netherrack)
B(-1,53,-7,minecraft:netherrack)
B(-1,54,-7,minecraft:netherrack)
B(-1,55,-7,minecraft:netherrack)
B(-1,56,-7,minecraft:netherrack)
B(-1,57,-7,minecraft:netherrack)
B(-1,58,-7,minecraft:netherrack)
B(-1,59,-7,minecraft:netherrack)
B(-1,60,-7,minecraft:netherrack)
B(-1,61,-7,minecraft:netherrack)
B(-1,62,-7,minecraft:netherrack)
B(-1,63,-7,minecraft:netherrack)
B(-1,64,-7,minecraft:netherrack)
B(-1,65,-7,minecraft:netherrack)
B(-1,66,-7,minecraft:netherrack)
B(-1,67,-7,minecraft:netherrack)
B(-1,68,-7,minecraft:netherrack)
B(-1,69,-7,minecraft:netherrack)
B(-1,70,-7,minecraft:netherrack)
B(-1,71,-7,minecraft:netherrack)
B(-1,72,-7,minecraft:netherrack)
B(-1,73,-7,minecraft:netherrack)
B(-1,74,-7,minecraft:netherrack)
B(-1,75,-7,minecraft:netherrack)
B(-1,76,-7,minecraft:netherrack)
B(-1,77,-7,minecraft:netherrack)
B(-1,78,-7,minecraft:netherrack)
B(-1,79,-7,minecraft:netherrack)
B(-1,80,-7,minecraft:netherrack)
B(-1,81,-7,minecraft:netherrack)
B(-1,82,-7,minecraft:netherrack)
B(-1,83,-7,minecraft:netherrack)
B(-1,84,-7,minecraft:netherrack)
B(-1,85,-7,minecraft:netherrack)
B(-1,86,-7,minecraft:netherrack)
B(-1,87,-7,minecraft:netherrack)
B(-1,88,-7,minecraft:netherrack)
B(-1,89,-7,minecraft:netherrack)
B(-1,90,-7,minecraft:netherrack)
B(-1,33,-6,minecraft:netherrack)
B(-1,34,-6,minecraft:netherrack)
B(-1,35,-6,minecraft:netherrack)
B(-1,36,-6,minecraft:netherrack)
B(-1,37,-6,minecraft:netherrack)
B(-1,38,-6,minecraft:netherrack)
B(-1,39,-6,minecraft:netherrack)
B(-1,40,-6,minecraft:netherrack)
B(-1,41,-6,minecraft:netherrack)
B(-1,42,-6,minecraft:netherrack)
B(-1,43,-6,minecraft:netherrack)
B(-1,44,-6,minecraft:netherrack)
B(-1,45,-6,minecraft:netherrack)
B(-1,46,-6,minecraft:netherrack)
B(-1,47,-6,minecraft:netherrack)
B(-1,48,-6,minecraft:netherrack)
B(-1,49,-6,minecraft:netherrack)
B(-1,50,-6,minecraft:netherrack)
B(-1,51,-6,minecraft:netherrack)
B(-1,52,-6,minecraft:netherrack)
B(-1,53,-6,minecraft:netherrack)
B(-1,54,-6,minecraft:netherrack)
B(-1,55,-6,minecraft:netherrack)
B(-1,56,-6,minecraft:netherrack)
B(-1,57,-6,minecraft:netherrack)
B(-1,58,-6,minecraft:netherrack)
B(-1,59,-6,minecraft:netherrack)
B(-1,60,-6,minecraft:netherrack)
B(-1,61,-6,minecraft:netherrack)
B(-1,62,-6,minecraft:netherrack)
B(-1,63,-6,minecraft:netherrack)
B(-1,64,-6,minecraft:netherrack)
B(-1,65,-6,minecraft:netherrack)
B(-1,66,-6,minecraft:netherrack)
B(-1,67,-6,minecraft:netherrack)
B(-1,68,-6,minecraft:netherrack)
B(-1,69,-6,minecraft:netherrack)
B(-1,70,-6,minecraft:netherrack)
B(-1,71,-6,minecraft:netherrack)
B(-1,72,-6,minecraft:netherrack)
B(-1,73,-6,minecraft:netherrack)
B(-1,74,-6,minecraft:netherrack)
B(-1,75,-6,minecraft:netherrack)
B(-1,76,-6,minecraft:netherrack)
B(-1,77,-6,minecraft:netherrack)
B(-1,78,-6,minecraft:netherrack)
B(-1,79,-6,minecraft:netherrack)
B(-1,80,-6,minecraft:netherrack)
B(-1,81,-6,minecraft:netherrack)
B(-1,82,-6,minecraft:netherrack)
B(-1,83,-6,minecraft:netherrack)
B(-1,84,-6,minecraft:netherrack)
B(-1,85,-6,minecraft:netherrack)
B(-1,86,-6,minecraft:netherrack)
B(-1,87,-6,minecraft:netherrack)
B(-1,88,-6,minecraft:netherrack)
B(-1,89,-6,minecraft:netherrack)
B(-1,90,-6,minecraft:netherrack)
B(-1,30,-5,minecraft:netherrack)
B(-1,31,-5,minecraft:netherrack)
B(-1,32,-5,minecraft:netherrack)
B(-1,33,-5,minecraft:netherrack)
B(-1,34,-5,minecraft:netherrack)
B(-1,35,-5,minecraft:netherrack)
B(-1,36,-5,minecraft:netherrack)
B(-1,37,-5,minecraft:netherrack)
B(-1,38,-5,minecraft:netherrack)
B(-1,39,-5,minecraft:netherrack)
B(-1,40,-5,minecraft:netherrack)
B(-1,41,-5,minecraft:netherrack)
B(-1,42,-5,minecraft:netherrack)
B(-1,43,-5,minecraft:netherrack)
B(-1,44,-5,minecraft:netherrack)
B(-1,45,-5,minecraft:netherrack)
B(-1,46,-5,minecraft:netherrack)
B(-1,47,-5,minecraft:netherrack)
B(-1,48,-5,minecraft:netherrack)
B(-1,49,-5,minecraft:netherrack)
B(-1,50,-5,minecraft:netherrack)
B(-1,51,-5,minecraft:netherrack)
B(-1,52,-5,minecraft:netherrack)
B(-1,53,-5,minecraft:netherrack)
B(-1,54,-5,minecraft:netherrack)
B(-1,55,-5,minecraft:netherrack)
B(-1,56,-5,minecraft:netherrack)
B(-1,57,-5,minecraft:netherrack)
B(-1,58,-5,minecraft:netherrack)
B(-1,59,-5,minecraft:netherrack)
B(-1,60,-5,minecraft:netherrack)
B(-1,61,-5,minecraft:netherrack)
B(-1,62,-5,minecraft:netherrack)
B(-1,63,-5,minecraft:netherrack)
B(-1,64,-5,minecraft:netherrack)
B(-1,65,-5,minecraft:netherrack)
B(-1,66,-5,minecraft:netherrack)
B(-1,67,-5,minecraft:netherrack)
B(-1,68,-5,minecraft:netherrack)
B(-1,69,-5,minecraft:netherrack)
B(-1,70,-5,minecraft:netherrack)
B(-1,71,-5,minecraft:netherrack)
B(-1,72,-5,minecraft:netherrack)
B(-1,73,-5,minecraft:netherrack)
B(-1,74,-5,minecraft:netherrack)
B(-1,75,-5,minecraft:netherrack)
B(-1,76,-5,minecraft:netherrack)
B(-1,77,-5,minecraft:netherrack)
B(-1,78,-5,minecraft:netherrack)
B(-1,79,-5,minecraft:netherrack)
B(-1,80,-5,minecraft:netherrack)
B(-1,81,-5,minecraft:netherrack)
B(-1,82,-5,minecraft:netherrack)
B(-1,83,-5,minecraft:netherrack)
B(-1,84,-5,minecraft:netherrack)
B(-1,85,-5,minecraft:netherrack)
B(-1,86,-5,minecraft:netherrack)
B(-1,87,-5,minecraft:netherrack)
B(-1,88,-5,minecraft:netherrack)
B(-1,89,-5,minecraft:netherrack)
B(-1,90,-5,minecraft:netherrack)
B(-1,32,-4,minecraft:netherrack)
B(-1,33,-4,minecraft:netherrack)
B(-1,34,-4,minecraft:netherrack)
B(-1,35,-4,minecraft:netherrack)
B(-1,36,-4,minecraft:netherrack)
B(-1,37,-4,minecraft:netherrack)
B(-1,38,-4,minecraft:netherrack)
B(-1,39,-4,minecraft:netherrack)
B(-1,40,-4,minecraft:netherrack)
B(-1,41,-4,minecraft:netherrack)
B(-1,42,-4,minecraft:netherrack)
B(-1,43,-4,minecraft:netherrack)
B(-1,44,-4,minecraft:netherrack)
B(-1,45,-4,minecraft:netherrack)
B(-1,46,-4,minecraft:netherrack)
B(-1,47,-4,minecraft:netherrack)
B(-1,48,-4,minecraft:netherrack)
B(-1,49,-4,minecraft:netherrack)
B(-1,50,-4,minecraft:netherrack)
B(-1,51,-4,minecraft:netherrack)
B(-1,52,-4,minecraft:netherrack)
B(-1,53,-4,minecraft:netherrack)
B(-1,54,-4,minecraft:netherrack)
B(-1,55,-4,minecraft:netherrack)
B(-1,56,-4,minecraft:netherrack)
B(-1,57,-4,minecraft:netherrack)
B(-1,58,-4,minecraft:netherrack)
B(-1,59,-4,minecraft:netherrack)
B(-1,60,-4,minecraft:netherrack)
B(-1,61,-4,minecraft:netherrack)
B(-1,62,-4,minecraft:netherrack)
B(-1,63,-4,minecraft:netherrack)
B(-1,64,-4,minecraft:netherrack)
B(-1,65,-4,minecraft:netherrack)
B(-1,66,-4,minecraft:netherrack)
B(-1,67,-4,minecraft:netherrack)
B(-1,68,-4,minecraft:netherrack)
B(-1,69,-4,minecraft:netherrack)
B(-1,70,-4,minecraft:netherrack)
B(-1,71,-4,minecraft:netherrack)
B(-1,72,-4,minecraft:netherrack)
B(-1,73,-4,minecraft:netherrack)
B(-1,74,-4,minecraft:netherrack)
B(-1,75,-4,minecraft:netherrack)
B(-1,76,-4,minecraft:netherrack)
B(-1,77,-4,minecraft:netherrack)
B(-1,78,-4,minecraft:netherrack)
B(-1,79,-4,minecraft:netherrack)
B(-1,80,-4,minecraft:netherrack)
B(-1,81,-4,minecraft:netherrack)
B(-1,82,-4,minecraft:netherrack)
B(-1,83,-4,minecraft:netherrack)
B(-1,84,-4,minecraft:netherrack)
B(-1,85,-4,minecraft:netherrack)
B(-1,86,-4,minecraft:netherrack)
B(-1,87,-4,minecraft:netherrack)
B(-1,88,-4,minecraft:netherrack)
B(-1,89,-4,minecraft:netherrack)
B(-1,90,-4,minecraft:netherrack)
B(-1,43,-3,minecraft:netherrack)
B(-1,44,-3,minecraft:netherrack)
B(-1,45,-3,minecraft:netherrack)
B(-1,46,-3,minecraft:netherrack)
B(-1,47,-3,minecraft:netherrack)
B(-1,48,-3,minecraft:netherrack)
B(-1,49,-3,minecraft:netherrack)
B(-1,50,-3,minecraft:netherrack)
B(-1,51,-3,minecraft:netherrack)
B(-1,52,-3,minecraft:netherrack)
B(-1,53,-3,minecraft:netherrack)
B(-1,54,-3,minecraft:netherrack)
B(-1,55,-3,minecraft:netherrack)
B(-1,56,-3,minecraft:netherrack)
B(-1,57,-3,minecraft:netherrack)
B(-1,58,-3,minecraft:netherrack)
B(-1,59,-3,minecraft:netherrack)
B(-1,60,-3,minecraft:netherrack)
B(-1,61,-3,minecraft:netherrack)
B(-1,62,-3,minecraft:netherrack)
B(-1,63,-3,minecraft:netherrack)
B(-1,64,-3,minecraft:netherrack)
B(-1,65,-3,minecraft:netherrack)
B(-1,66,-3,minecraft:netherrack)
B(-1,67,-3,minecraft:netherrack)
B(-1,68,-3,minecraft:netherrack)
B(-1,69,-3,minecraft:netherrack)
B(-1,70,-3,minecraft:netherrack)
B(-1,71,-3,minecraft:netherrack)
B(-1,72,-3,minecraft:netherrack)
B(-1,73,-3,minecraft:netherrack)
B(-1,74,-3,minecraft:netherrack)
B(-1,75,-3,minecraft:netherrack)
B(-1,76,-3,minecraft:netherrack)
B(-1,77,-3,minecraft:netherrack)
B(-1,78,-3,minecraft:netherrack)
B(-1,79,-3,minecraft:netherrack)
B(-1,80,-3,minecraft:netherrack)
B(-1,81,-3,minecraft:netherrack)
B(-1,82,-3,minecraft:netherrack)
B(-1,83,-3,minecraft:netherrack)
B(-1,84,-3,minecraft:netherrack)
B(-1,85,-3,minecraft:netherrack)
B(-1,86,-3,minecraft:netherrack)
B(-1,87,-3,minecraft:netherrack)
B(-1,88,-3,minecraft:netherrack)
B(-1,89,-3,minecraft:netherrack)
B(-1,90,-3,minecraft:netherrack)
B(-1,56,-2,minecraft:netherrack)
B(-1,57,-2,minecraft:netherrack)
B(-1,58,-2,minecraft:netherrack)
B(-1,59,-2,minecraft:netherrack)
B(-1,60,-2,minecraft:netherrack)
B(-1,61,-2,minecraft:netherrack)
B(-1,62,-2,minecraft:netherrack)
B(-1,63,-2,minecraft:netherrack)
B(-1,64,-2,minecraft:netherrack)
B(-1,65,-2,minecraft:netherrack)
B(-1,66,-2,minecraft:netherrack)
B(-1,67,-2,minecraft:netherrack)
B(-1,68,-2,minecraft:netherrack)
B(-1,69,-2,minecraft:netherrack)
B(-1,70,-2,minecraft:netherrack)
B(-1,71,-2,minecraft:netherrack)
B(-1,72,-2,minecraft:netherrack)
B(-1,73,-2,minecraft:netherrack)
B(-1,74,-2,minecraft:netherrack)
B(-1,75,-2,minecraft:netherrack)
B(-1,76,-2,minecraft:netherrack)
B(-1,77,-2,minecraft:netherrack)
B(-1,78,-2,minecraft:netherrack)
B(-1,79,-2,minecraft:netherrack)
B(-1,80,-2,minecraft:netherrack)
B(-1,81,-2,minecraft:netherrack)
B(-1,82,-2,minecraft:netherrack)
B(-1,83,-2,minecraft:netherrack)
B(-1,84,-2,minecraft:netherrack)
B(-1,85,-2,minecraft:netherrack)
B(-1,86,-2,minecraft:netherrack)
B(-1,87,-2,minecraft:netherrack)
B(-1,88,-2,minecraft:netherrack)
B(-1,89,-2,minecraft:netherrack)
B(-1,90,-2,minecraft:netherrack)
B(-1,46,-1,minecraft:netherrack)
B(-1,47,-1,minecraft:netherrack)
B(-1,48,-1,minecraft:netherrack)
B(-1,49,-1,minecraft:netherrack)
B(-1,50,-1,minecraft:netherrack)
B(-1,51,-1,minecraft:netherrack)
B(-1,52,-1,minecraft:netherrack)
B(-1,53,-1,minecraft:netherrack)
B(-1,54,-1,minecraft:netherrack)
B(-1,55,-1,minecraft:netherrack)
B(-1,56,-1,minecraft:netherrack)
B(-1,57,-1,minecraft:netherrack)
B(-1,58,-1,minecraft:netherrack)
B(-1,59,-1,minecraft:netherrack)
B(-1,60,-1,minecraft:netherrack)
B(-1,61,-1,minecraft:netherrack)
B(-1,62,-1,minecraft:netherrack)
B(-1,63,-1,minecraft:netherrack)
B(-1,64,-1,minecraft:netherrack)
B(-1,65,-1,minecraft:netherrack)
B(-1,66,-1,minecraft:netherrack)
B(-1,67,-1,minecraft:netherrack)
B(-1,68,-1,minecraft:netherrack)
B(-1,69,-1,minecraft:netherrack)
B(-1,70,-1,minecraft:netherrack)
B(-1,71,-1,minecraft:netherrack)
B(-1,72,-1,minecraft:netherrack)
B(-1,73,-1,minecraft:netherrack)
B(-1,74,-1,minecraft:netherrack)
B(-1,75,-1,minecraft:netherrack)
B(-1,76,-1,minecraft:netherrack)
B(-1,77,-1,minecraft:netherrack)
B(-1,78,-1,minecraft:netherrack)
B(-1,79,-1,minecraft:netherrack)
B(-1,80,-1,minecraft:netherrack)
B(-1,81,-1,minecraft:netherrack)
B(-1,82,-1,minecraft:netherrack)
B(-1,83,-1,minecraft:netherrack)
B(-1,84,-1,minecraft:netherrack)
B(-1,85,-1,minecraft:netherrack)
B(-1,86,-1,minecraft:netherrack)
B(-1,87,-1,minecraft:netherrack)
B(-1,88,-1,minecraft:netherrack)
B(-1,89,-1,minecraft:netherrack)
B(-1,90,-1,minecraft:netherrack)
B(-1,42,0,minecraft:netherrack)
B(-1,43,0,minecraft:netherrack)
B(-1,44,0,minecraft:netherrack)
B(-1,45,0,minecraft:netherrack)
B(-1,46,0,minecraft:netherrack)
B(-1,47,0,minecraft:netherrack)
B(-1,48,0,minecraft:netherrack)
B(-1,49,0,minecraft:netherrack)
B(-1,50,0,minecraft:netherrack)
B(-1,51,0,minecraft:netherrack)
B(-1,52,0,minecraft:netherrack)
B(-1,53,0,minecraft:netherrack)
B(-1,54,0,minecraft:netherrack)
B(-1,55,0,minecraft:netherrack)
B(-1,56,0,minecraft:netherrack)
B(-1,57,0,minecraft:netherrack)
B(-1,58,0,minecraft:netherrack)
B(-1,59,0,minecraft:netherrack)
B(-1,60,0,minecraft:netherrack)
B(-1,61,0,minecraft:netherrack)
B(-1,62,0,minecraft:netherrack)
B(-1,63,0,minecraft:netherrack)
B(-1,64,0,minecraft:netherrack)
B(-1,65,0,minecraft:netherrack)
B(-1,66,0,minecraft:netherrack)
B(-1,67,0,minecraft:netherrack)
B(-1,68,0,minecraft:netherrack)
B(-1,69,0,minecraft:netherrack)
B(-1,70,0,minecraft:netherrack)
B(-1,71,0,minecraft:netherrack)
B(-1,72,0,minecraft:netherrack)
B(-1,73,0,minecraft:netherrack)
B(-1,74,0,minecraft:netherrack)
B(-1,75,0,minecraft:netherrack)
B(-1,76,0,minecraft:netherrack)
B(-1,77,0,minecraft:netherrack)
B(-1,78,0,minecraft:netherrack)
B(-1,79,0,minecraft:netherrack)
B(-1,80,0,minecraft:netherrack)
B(-1,81,0,minecraft:netherrack)
B(-1,82,0,minecraft:netherrack)
B(-1,83,0,minecraft:netherrack)
B(-1,84,0,minecraft:netherrack)
B(-1,85,0,minecraft:netherrack)
B(-1,86,0,minecraft:netherrack)
B(-1,87,0,minecraft:netherrack)
B(-1,88,0,minecraft:netherrack)
B(-1,89,0,minecraft:netherrack)
B(-1,90,0,minecraft:netherrack)
B(-1,41,1,minecraft:netherrack)
B(-1,42,1,minecraft:netherrack)
B(-1,43,1,minecraft:netherrack)
B(-1,44,1,minecraft:netherrack)
B(-1,45,1,minecraft:netherrack)
B(-1,46,1,minecraft:netherrack)
B(-1,47,1,minecraft:netherrack)
B(-1,48,1,minecraft:netherrack)
B(-1,49,1,minecraft:netherrack)
B(-1,50,1,minecraft:netherrack)
B(-1,51,1,minecraft:netherrack)
B(-1,52,1,minecraft:netherrack)
B(-1,53,1,minecraft:netherrack)
B(-1,54,1,minecraft:netherrack)
B(-1,55,1,minecraft:netherrack)
B(-1,56,1,minecraft:netherrack)
B(-1,57,1,minecraft:netherrack)
B(-1,58,1,minecraft:netherrack)
B(-1,59,1,minecraft:netherrack)
B(-1,60,1,minecraft:netherrack)
B(-1,61,1,minecraft:netherrack)
B(-1,62,1,minecraft:netherrack)
B(-1,63,1,minecraft:netherrack)
B(-1,64,1,minecraft:netherrack)
B(-1,65,1,minecraft:netherrack)
B(-1,66,1,minecraft:netherrack)
B(-1,67,1,minecraft:netherrack)
B(-1,68,1,minecraft:netherrack)
B(-1,69,1,minecraft:netherrack)
B(-1,70,1,minecraft:netherrack)
B(-1,71,1,minecraft:netherrack)
B(-1,72,1,minecraft:netherrack)
B(-1,73,1,minecraft:netherrack)
B(-1,74,1,minecraft:netherrack)
B(-1,75,1,minecraft:netherrack)
B(-1,76,1,minecraft:netherrack)
B(-1,77,1,minecraft:netherrack)
B(-1,78,1,minecraft:netherrack)
B(-1,79,1,minecraft:netherrack)
B(-1,80,1,minecraft:netherrack)
B(-1,81,1,minecraft:netherrack)
B(-1,82,1,minecraft:netherrack)
B(-1,83,1,minecraft:netherrack)
B(-1,84,1,minecraft:netherrack)
B(-1,85,1,minecraft:netherrack)
B(-1,86,1,minecraft:netherrack)
B(-1,87,1,minecraft:netherrack)
B(-1,88,1,minecraft:netherrack)
B(-1,89,1,minecraft:netherrack)
B(-1,90,1,minecraft:netherrack)
B(-1,41,2,minecraft:netherrack)
B(-1,42,2,minecraft:netherrack)
B(-1,43,2,minecraft:netherrack)
B(-1,44,2,minecraft:netherrack)
B(-1,45,2,minecraft:netherrack)
B(-1,46,2,minecraft:netherrack)
B(-1,47,2,minecraft:netherrack)
B(-1,48,2,minecraft:netherrack)
B(-1,49,2,minecraft:netherrack)
B(-1,50,2,minecraft:netherrack)
B(-1,51,2,minecraft:netherrack)
B(-1,52,2,minecraft:netherrack)
B(-1,53,2,minecraft:netherrack)
B(-1,54,2,minecraft:netherrack)
B(-1,55,2,minecraft:netherrack)
B(-1,56,2,minecraft:netherrack)
B(-1,57,2,minecraft:netherrack)
B(-1,58,2,minecraft:netherrack)
B(-1,59,2,minecraft:netherrack)
B(-1,60,2,minecraft:netherrack)
B(-1,61,2,minecraft:netherrack)
B(-1,62,2,minecraft:netherrack)
B(-1,63,2,minecraft:netherrack)
B(-1,64,2,minecraft:netherrack)
B(-1,65,2,minecraft:netherrack)
B(-1,66,2,minecraft:netherrack)
B(-1,67,2,minecraft:netherrack)
B(-1,68,2,minecraft:netherrack)
B(-1,69,2,minecraft:netherrack)
B(-1,70,2,minecraft:netherrack)
B(-1,71,2,minecraft:netherrack)
B(-1,72,2,minecraft:netherrack)
B(-1,73,2,minecraft:netherrack)
B(-1,74,2,minecraft:netherrack)
B(-1,75,2,minecraft:netherrack)
B(-1,76,2,minecraft:netherrack)
B(-1,77,2,minecraft:netherrack)
B(-1,78,2,minecraft:netherrack)
B(-1,79,2,minecraft:netherrack)
B(-1,80,2,minecraft:netherrack)
B(-1,81,2,minecraft:netherrack)
B(-1,82,2,minecraft:netherrack)
B(-1,83,2,minecraft:netherrack)
B(-1,84,2,minecraft:netherrack)
B(-1,85,2,minecraft:netherrack)
B(-1,86,2,minecraft:netherrack)
B(-1,87,2,minecraft:netherrack)
B(-1,88,2,minecraft:netherrack)
B(-1,89,2,minecraft:netherrack)
B(-1,90,2,minecraft:netherrack)
B(-1,41,3,minecraft:netherrack)
B(-1,42,3,minecraft:netherrack)
B(-1,43,3,minecraft:netherrack)
B(-1,44,3,minecraft:netherrack)
B(-1,45,3,minecraft:netherrack)
B(-1,46,3,minecraft:netherrack)
B(-1,47,3,minecraft:netherrack)
B(-1,48,3,minecraft:netherrack)
B(-1,49,3,minecraft:netherrack)
B(-1,50,3,minecraft:netherrack)
B(-1,51,3,minecraft:netherrack)
B(-1,52,3,minecraft:netherrack)
B(-1,53,3,minecraft:netherrack)
B(-1,54,3,minecraft:netherrack)
B(-1,55,3,minecraft:netherrack)
B(-1,56,3,minecraft:netherrack)
B(-1,57,3,minecraft:netherrack)
B(-1,58,3,minecraft:netherrack)
B(-1,59,3,minecraft:netherrack)
B(-1,60,3,minecraft:netherrack)
B(-1,61,3,minecraft:netherrack)
B(-1,62,3,minecraft:netherrack)
B(-1,63,3,minecraft:netherrack)
B(-1,64,3,minecraft:netherrack)
B(-1,65,3,minecraft:netherrack)
B(-1,66,3,minecraft:netherrack)
B(-1,67,3,minecraft:netherrack)
B(-1,68,3,minecraft:netherrack)
B(-1,69,3,minecraft:netherrack)
B(-1,70,3,minecraft:netherrack)
B(-1,71,3,minecraft:netherrack)
B(-1,72,3,minecraft:netherrack)
B(-1,73,3,minecraft:netherrack)
B(-1,74,3,minecraft:netherrack)
B(-1,75,3,minecraft:netherrack)
B(-1,76,3,minecraft:netherrack)
B(-1,77,3,minecraft:netherrack)
B(-1,78,3,minecraft:netherrack)
B(-1,79,3,minecraft:netherrack)
B(-1,80,3,minecraft:netherrack)
B(-1,81,3,minecraft:netherrack)
B(-1,82,3,minecraft:netherrack)
B(-1,83,3,minecraft:netherrack)
B(-1,84,3,minecraft:netherrack)
B(-1,85,3,minecraft:netherrack)
B(-1,86,3,minecraft:netherrack)
B(-1,87,3,minecraft:netherrack)
B(-1,88,3,minecraft:netherrack)
B(-1,89,3,minecraft:netherrack)
B(-1,90,3,minecraft:netherrack)
B(-1,48,4,minecraft:netherrack)
B(-1,49,4,minecraft:netherrack)
B(-1,50,4,minecraft:netherrack)
B(-1,51,4,minecraft:netherrack)
B(-1,52,4,minecraft:netherrack)
B(-1,53,4,minecraft:netherrack)
B(-1,54,4,minecraft:netherrack)
B(-1,55,4,minecraft:netherrack)
B(-1,56,4,minecraft:netherrack)
B(-1,57,4,minecraft:netherrack)
B(-1,58,4,minecraft:netherrack)
B(-1,59,4,minecraft:netherrack)
B(-1,60,4,minecraft:netherrack)
B(-1,61,4,minecraft:netherrack)
B(-1,62,4,minecraft:netherrack)
B(-1,63,4,minecraft:netherrack)
B(-1,64,4,minecraft:netherrack)
B(-1,65,4,minecraft:netherrack)
B(-1,66,4,minecraft:netherrack)
B(-1,67,4,minecraft:netherrack)
B(-1,68,4,minecraft:netherrack)
B(-1,69,4,minecraft:netherrack)
B(-1,70,4,minecraft:netherrack)
B(-1,71,4,minecraft:netherrack)
B(-1,72,4,minecraft:netherrack)
B(-1,73,4,minecraft:netherrack)
B(-1,74,4,minecraft:netherrack)
B(-1,75,4,minecraft:netherrack)
B(-1,76,4,minecraft:netherrack)
B(-1,77,4,minecraft:netherrack)
B(-1,78,4,minecraft:netherrack)
B(-1,79,4,minecraft:netherrack)
B(-1,80,4,minecraft:netherrack)
B(-1,81,4,minecraft:netherrack)
B(-1,82,4,minecraft:netherrack)
B(-1,83,4,minecraft:netherrack)
B(-1,84,4,minecraft:netherrack)
B(-1,85,4,minecraft:netherrack)
B(-1,86,4,minecraft:netherrack)
B(-1,87,4,minecraft:netherrack)
B(-1,88,4,minecraft:netherrack)
B(-1,89,4,minecraft:netherrack)
B(-1,90,4,minecraft:netherrack)
B(-1,52,5,minecraft:netherrack)
B(-1,53,5,minecraft:netherrack)
B(-1,54,5,minecraft:netherrack)
B(-1,55,5,minecraft:netherrack)
B(-1,56,5,minecraft:netherrack)
B(-1,57,5,minecraft:netherrack)
B(-1,58,5,minecraft:netherrack)
B(-1,59,5,minecraft:netherrack)
B(-1,60,5,minecraft:netherrack)
B(-1,61,5,minecraft:netherrack)
B(-1,62,5,minecraft:netherrack)
B(-1,63,5,minecraft:netherrack)
B(-1,64,5,minecraft:netherrack)
B(-1,65,5,minecraft:netherrack)
B(-1,66,5,minecraft:netherrack)
B(-1,67,5,minecraft:netherrack)
B(-1,68,5,minecraft:netherrack)
B(-1,69,5,minecraft:netherrack)
B(-1,70,5,minecraft:netherrack)
B(-1,71,5,minecraft:netherrack)
B(-1,72,5,minecraft:netherrack)
B(-1,73,5,minecraft:netherrack)
B(-1,74,5,minecraft:netherrack)
B(-1,75,5,minecraft:netherrack)
B(-1,76,5,minecraft:netherrack)
B(-1,77,5,minecraft:netherrack)
B(-1,78,5,minecraft:netherrack)
B(-1,79,5,minecraft:netherrack)
B(-1,80,5,minecraft:netherrack)
B(-1,81,5,minecraft:netherrack)
B(-1,82,5,minecraft:netherrack)
B(-1,83,5,minecraft:netherrack)
B(-1,84,5,minecraft:netherrack)
B(-1,85,5,minecraft:netherrack)
B(-1,86,5,minecraft:netherrack)
B(-1,87,5,minecraft:netherrack)
B(-1,88,5,minecraft:netherrack)
B(-1,89,5,minecraft:netherrack)
B(-1,90,5,minecraft:netherrack)
B(-1,60,6,minecraft:netherrack)
B(-1,61,6,minecraft:netherrack)
B(-1,62,6,minecraft:netherrack)
B(-1,63,6,minecraft:netherrack)
B(-1,64,6,minecraft:netherrack)
B(-1,65,6,minecraft:netherrack)
B(-1,66,6,minecraft:netherrack)
B(-1,67,6,minecraft:netherrack)
B(-1,68,6,minecraft:netherrack)
B(-1,69,6,minecraft:netherrack)
B(-1,70,6,minecraft:netherrack)
B(-1,71,6,minecraft:netherrack)
B(-1,72,6,minecraft:netherrack)
B(-1,73,6,minecraft:netherrack)
B(-1,74,6,minecraft:netherrack)
B(-1,75,6,minecraft:netherrack)
B(-1,76,6,minecraft:netherrack)
B(-1,77,6,minecraft:netherrack)
B(-1,78,6,minecraft:netherrack)
B(-1,79,6,minecraft:netherrack)
B(-1,80,6,minecraft:netherrack)
B(-1,81,6,minecraft:netherrack)
B(-1,82,6,minecraft:netherrack)
B(-1,83,6,minecraft:netherrack)
B(-1,84,6,minecraft:netherrack)
B(-1,85,6,minecraft:netherrack)
B(-1,86,6,minecraft:netherrack)
B(-1,87,6,minecraft:netherrack)
B(-1,88,6,minecraft:netherrack)
B(-1,89,6,minecraft:netherrack)
B(-1,90,6,minecraft:netherrack)
B(-1,61,7,minecraft:netherrack)
B(-1,62,7,minecraft:netherrack)
B(-1,63,7,minecraft:netherrack)
B(-1,64,7,minecraft:netherrack)
B(-1,65,7,minecraft:netherrack)
B(-1,66,7,minecraft:netherrack)
B(-1,67,7,minecraft:netherrack)
B(-1,68,7,minecraft:netherrack)
B(-1,69,7,minecraft:netherrack)
B(-1,70,7,minecraft:netherrack)
B(-1,71,7,minecraft:netherrack)
B(-1,72,7,minecraft:netherrack)
B(-1,73,7,minecraft:netherrack)
B(-1,74,7,minecraft:netherrack)
B(-1,75,7,minecraft:netherrack)
B(-1,76,7,minecraft:netherrack)
B(-1,77,7,minecraft:netherrack)
B(-1,78,7,minecraft:netherrack)
B(-1,79,7,minecraft:netherrack)
B(-1,80,7,minecraft:netherrack)
B(-1,81,7,minecraft:netherrack)
B(-1,82,7,minecraft:netherrack)
B(-1,83,7,minecraft:netherrack)
B(-1,84,7,minecraft:netherrack)
B(-1,85,7,minecraft:netherrack)
B(-1,86,7,minecraft:netherrack)
B(-1,87,7,minecraft:netherrack)
B(-1,88,7,minecraft:netherrack)
B(-1,89,7,minecraft:netherrack)
B(-1,90,7,minecraft:netherrack)
B(-1,62,8,minecraft:netherrack)
B(-1,63,8,minecraft:netherrack)
B(-1,64,8,minecraft:netherrack)
B(-1,65,8,minecraft:netherrack)
B(-1,66,8,minecraft:netherrack)
B(-1,67,8,minecraft:netherrack)
B(-1,68,8,minecraft:netherrack)
B(-1,69,8,minecraft:netherrack)
B(-1,70,8,minecraft:netherrack)
B(-1,71,8,minecraft:netherrack)
B(-1,72,8,minecraft:netherrack)
B(-1,73,8,minecraft:netherrack)
B(-1,74,8,minecraft:netherrack)
B(-1,75,8,minecraft:netherrack)
B(-1,76,8,minecraft:netherrack)
B(-1,77,8,minecraft:netherrack)
B(-1,78,8,minecraft:netherrack)
B(-1,79,8,minecraft:netherrack)
B(-1,80,8,minecraft:netherrack)
B(-1,81,8,minecraft:netherrack)
B(-1,82,8,minecraft:netherrack)
B(-1,83,8,minecraft:netherrack)
B(-1,84,8,minecraft:netherrack)
B(-1,85,8,minecraft:netherrack)
B(-1,86,8,minecraft:netherrack)
B(-1,87,8,minecraft:netherrack)
B(-1,88,8,minecraft:netherrack)
B(-1,89,8,minecraft:netherrack)
B(-1,90,8,minecraft:netherrack)
B(0,34,-7,minecraft:netherrack)
B(0,35,-7,minecraft:netherrack)
B(0,36,-7,minecraft:netherrack)
B(0,37,-7,minecraft:netherrack)
B(0,38,-7,minecraft:netherrack)
B(0,39,-7,minecraft:netherrack)
B(0,40,-7,minecraft:netherrack)
B(0,41,-7,minecraft:netherrack)
B(0,42,-7,minecraft:netherrack)
B(0,43,-7,minecraft:netherrack)
B(0,44,-7,minecraft:netherrack)
B(0,45,-7,minecraft:netherrack)
B(0,46,-7,minecraft:netherrack)
B(0,47,-7,minecraft:netherrack)
B(0,48,-7,minecraft:netherrack)
B(0,49,-7,minecraft:netherrack)
B(0,50,-7,minecraft:netherrack)
B(0,51,-7,minecraft:netherrack)
B(0,52,-7,minecraft:netherrack)
B(0,53,-7,minecraft:netherrack)
B(0,54,-7,minecraft:netherrack)
B(0,55,-7,minecraft:netherrack)
B(0,56,-7,minecraft:netherrack)
B(0,57,-7,minecraft:netherrack)
B(0,58,-7,minecraft:netherrack)
B(0,59,-7,minecraft:netherrack)
B(0,60,-7,minecraft:netherrack)
B(0,61,-7,minecraft:netherrack)
B(0,62,-7,minecraft:netherrack)
B(0,63,-7,minecraft:netherrack)
B(0,64,-7,minecraft:netherrack)
B(0,65,-7,minecraft:netherrack)
B(0,66,-7,minecraft:netherrack)
B(0,67,-7,minecraft:netherrack)
B(0,68,-7,minecraft:netherrack)
B(0,69,-7,minecraft:netherrack)
B(0,70,-7,minecraft:netherrack)
B(0,71,-7,minecraft:netherrack)
B(0,72,-7,minecraft:netherrack)
B(0,73,-7,minecraft:netherrack)
B(0,74,-7,minecraft:netherrack)
B(0,75,-7,minecraft:netherrack)
B(0,76,-7,minecraft:netherrack)
B(0,77,-7,minecraft:netherrack)
B(0,78,-7,minecraft:netherrack)
B(0,79,-7,minecraft:netherrack)
B(0,80,-7,minecraft:netherrack)
B(0,81,-7,minecraft:netherrack)
B(0,82,-7,minecraft:netherrack)
B(0,83,-7,minecraft:netherrack)
B(0,84,-7,minecraft:netherrack)
B(0,85,-7,minecraft:netherrack)
B(0,86,-7,minecraft:netherrack)
B(0,87,-7,minecraft:netherrack)
B(0,88,-7,minecraft:netherrack)
B(0,89,-7,minecraft:netherrack)
B(0,90,-7,minecraft:netherrack)
B(0,29,-6,minecraft:netherrack)
B(0,30,-6,minecraft:netherrack)
B(0,31,-6,minecraft:netherrack)
B(0,32,-6,minecraft:netherrack)
B(0,33,-6,minecraft:netherrack)
B(0,34,-6,minecraft:netherrack)
B(0,35,-6,minecraft:netherrack)
B(0,36,-6,minecraft:netherrack)
B(0,37,-6,minecraft:netherrack)
B(0,38,-6,minecraft:netherrack)
B(0,39,-6,minecraft:netherrack)
B(0,40,-6,minecraft:netherrack)
B(0,41,-6,minecraft:netherrack)
B(0,42,-6,minecraft:netherrack)
B(0,43,-6,minecraft:netherrack)
B(0,44,-6,minecraft:netherrack)
B(0,45,-6,minecraft:netherrack)
B(0,46,-6,minecraft:netherrack)
B(0,47,-6,minecraft:netherrack)
B(0,48,-6,minecraft:netherrack)
B(0,49,-6,minecraft:netherrack)
B(0,50,-6,minecraft:netherrack)
B(0,51,-6,minecraft:netherrack)
B(0,52,-6,minecraft:netherrack)
B(0,53,-6,minecraft:netherrack)
B(0,54,-6,minecraft:netherrack)
B(0,55,-6,minecraft:netherrack)
B(0,56,-6,minecraft:netherrack)
B(0,57,-6,minecraft:netherrack)
B(0,58,-6,minecraft:netherrack)
B(0,59,-6,minecraft:netherrack)
B(0,60,-6,minecraft:netherrack)
B(0,61,-6,minecraft:netherrack)
B(0,62,-6,minecraft:netherrack)
B(0,63,-6,minecraft:netherrack)
B(0,64,-6,minecraft:netherrack)
B(0,65,-6,minecraft:netherrack)
B(0,66,-6,minecraft:netherrack)
B(0,67,-6,minecraft:netherrack)
B(0,68,-6,minecraft:netherrack)
B(0,69,-6,minecraft:netherrack)
B(0,70,-6,minecraft:netherrack)
B(0,71,-6,minecraft:netherrack)
B(0,72,-6,minecraft:netherrack)
B(0,73,-6,minecraft:netherrack)
B(0,74,-6,minecraft:netherrack)
B(0,75,-6,minecraft:netherrack)
B(0,76,-6,minecraft:netherrack)
B(0,77,-6,minecraft:netherrack)
B(0,78,-6,minecraft:netherrack)
B(0,79,-6,minecraft:netherrack)
B(0,80,-6,minecraft:netherrack)
B(0,81,-6,minecraft:netherrack)
B(0,82,-6,minecraft:netherrack)
B(0,83,-6,minecraft:netherrack)
B(0,84,-6,minecraft:netherrack)
B(0,85,-6,minecraft:netherrack)
B(0,86,-6,minecraft:netherrack)
B(0,87,-6,minecraft:netherrack)
B(0,88,-6,minecraft:netherrack)
B(0,89,-6,minecraft:netherrack)
B(0,90,-6,minecraft:netherrack)
B(0,29,-5,minecraft:netherrack)
B(0,30,-5,minecraft:netherrack)
B(0,31,-5,minecraft:netherrack)
B(0,32,-5,minecraft:netherrack)
B(0,33,-5,minecraft:netherrack)
B(0,34,-5,minecraft:netherrack)
B(0,35,-5,minecraft:netherrack)
B(0,36,-5,minecraft:netherrack)
B(0,37,-5,minecraft:netherrack)
B(0,38,-5,minecraft:netherrack)
B(0,39,-5,minecraft:netherrack)
B(0,40,-5,minecraft:netherrack)
B(0,41,-5,minecraft:netherrack)
B(0,42,-5,minecraft:netherrack)
B(0,43,-5,minecraft:netherrack)
B(0,44,-5,minecraft:netherrack)
B(0,45,-5,minecraft:netherrack)
B(0,46,-5,minecraft:netherrack)
B(0,47,-5,minecraft:netherrack)
B(0,48,-5,minecraft:netherrack)
B(0,49,-5,minecraft:netherrack)
B(0,50,-5,minecraft:netherrack)
B(0,51,-5,minecraft:netherrack)
B(0,52,-5,minecraft:netherrack)
B(0,53,-5,minecraft:netherrack)
B(0,54,-5,minecraft:netherrack)
B(0,55,-5,minecraft:netherrack)
B(0,56,-5,minecraft:netherrack)
B(0,57,-5,minecraft:netherrack)
B(0,58,-5,minecraft:netherrack)
B(0,59,-5,minecraft:netherrack)
B(0,60,-5,minecraft:netherrack)
B(0,61,-5,minecraft:netherrack)
B(0,62,-5,minecraft:netherrack)
B(0,63,-5,minecraft:netherrack)
B(0,64,-5,minecraft:netherrack)
B(0,65,-5,minecraft:netherrack)
B(0,66,-5,minecraft:netherrack)
B(0,67,-5,minecraft:netherrack)
B(0,68,-5,minecraft:netherrack)
B(0,69,-5,minecraft:netherrack)
B(0,70,-5,minecraft:netherrack)
B(0,71,-5,minecraft:netherrack)
B(0,72,-5,minecraft:netherrack)
B(0,73,-5,minecraft:netherrack)
B(0,74,-5,minecraft:netherrack)
B(0,75,-5,minecraft:netherrack)
B(0,76,-5,minecraft:netherrack)
B(0,77,-5,minecraft:netherrack)
B(0,78,-5,minecraft:netherrack)
B(0,79,-5,minecraft:netherrack)
B(0,80,-5,minecraft:netherrack)
B(0,81,-5,minecraft:netherrack)
B(0,82,-5,minecraft:netherrack)
B(0,83,-5,minecraft:netherrack)
B(0,84,-5,minecraft:netherrack)
B(0,85,-5,minecraft:netherrack)
B(0,86,-5,minecraft:netherrack)
B(0,87,-5,minecraft:netherrack)
B(0,88,-5,minecraft:netherrack)
B(0,89,-5,minecraft:netherrack)
B(0,90,-5,minecraft:netherrack)
B(0,30,-4,minecraft:netherrack)
B(0,31,-4,minecraft:netherrack)
B(0,32,-4,minecraft:netherrack)
B(0,33,-4,minecraft:netherrack)
B(0,34,-4,minecraft:netherrack)
B(0,35,-4,minecraft:netherrack)
B(0,36,-4,minecraft:netherrack)
B(0,37,-4,minecraft:netherrack)
B(0,38,-4,minecraft:netherrack)
B(0,39,-4,minecraft:netherrack)
B(0,40,-4,minecraft:netherrack)
B(0,41,-4,minecraft:netherrack)
B(0,42,-4,minecraft:netherrack)
B(0,43,-4,minecraft:netherrack)
B(0,44,-4,minecraft:netherrack)
B(0,45,-4,minecraft:netherrack)
B(0,46,-4,minecraft:netherrack)
B(0,47,-4,minecraft:netherrack)
B(0,48,-4,minecraft:netherrack)
B(0,49,-4,minecraft:netherrack)
B(0,50,-4,minecraft:netherrack)
B(0,51,-4,minecraft:netherrack)
B(0,52,-4,minecraft:netherrack)
B(0,53,-4,minecraft:netherrack)
B(0,54,-4,minecraft:netherrack)
B(0,55,-4,minecraft:netherrack)
B(0,56,-4,minecraft:netherrack)
B(0,57,-4,minecraft:netherrack)
B(0,58,-4,minecraft:netherrack)
B(0,59,-4,minecraft:netherrack)
B(0,60,-4,minecraft:netherrack)
B(0,61,-4,minecraft:netherrack)
B(0,62,-4,minecraft:netherrack)
B(0,63,-4,minecraft:netherrack)
B(0,64,-4,minecraft:netherrack)
B(0,65,-4,minecraft:netherrack)
B(0,66,-4,minecraft:netherrack)
B(0,67,-4,minecraft:netherrack)
B(0,68,-4,minecraft:netherrack)
B(0,69,-4,minecraft:netherrack)
B(0,70,-4,minecraft:netherrack)
B(0,71,-4,minecraft:netherrack)
B(0,72,-4,minecraft:netherrack)
B(0,73,-4,minecraft:netherrack)
B(0,74,-4,minecraft:netherrack)
B(0,75,-4,minecraft:netherrack)
B(0,76,-4,minecraft:netherrack)
B(0,77,-4,minecraft:netherrack)
B(0,78,-4,minecraft:netherrack)
B(0,79,-4,minecraft:netherrack)
B(0,80,-4,minecraft:netherrack)
B(0,81,-4,minecraft:netherrack)
B(0,82,-4,minecraft:netherrack)
B(0,83,-4,minecraft:netherrack)
B(0,84,-4,minecraft:netherrack)
B(0,85,-4,minecraft:netherrack)
B(0,86,-4,minecraft:netherrack)
B(0,87,-4,minecraft:netherrack)
B(0,88,-4,minecraft:netherrack)
B(0,89,-4,minecraft:netherrack)
B(0,90,-4,minecraft:netherrack)
B(0,31,-3,minecraft:netherrack)
B(0,32,-3,minecraft:netherrack)
B(0,33,-3,minecraft:netherrack)
B(0,34,-3,minecraft:netherrack)
B(0,35,-3,minecraft:netherrack)
B(0,36,-3,minecraft:netherrack)
B(0,37,-3,minecraft:netherrack)
B(0,38,-3,minecraft:netherrack)
B(0,39,-3,minecraft:netherrack)
B(0,40,-3,minecraft:netherrack)
B(0,41,-3,minecraft:netherrack)
B(0,42,-3,minecraft:netherrack)
B(0,43,-3,minecraft:netherrack)
B(0,44,-3,minecraft:netherrack)
B(0,45,-3,minecraft:netherrack)
B(0,46,-3,minecraft:netherrack)
B(0,47,-3,minecraft:netherrack)
B(0,48,-3,minecraft:netherrack)
B(0,49,-3,minecraft:netherrack)
B(0,50,-3,minecraft:netherrack)
B(0,51,-3,minecraft:netherrack)
B(0,52,-3,minecraft:netherrack)
B(0,53,-3,minecraft:netherrack)
B(0,54,-3,minecraft:netherrack)
B(0,55,-3,minecraft:netherrack)
B(0,56,-3,minecraft:netherrack)
B(0,57,-3,minecraft:netherrack)
B(0,58,-3,minecraft:netherrack)
B(0,59,-3,minecraft:netherrack)
B(0,60,-3,minecraft:netherrack)
B(0,61,-3,minecraft:netherrack)
B(0,62,-3,minecraft:netherrack)
B(0,63,-3,minecraft:netherrack)
B(0,64,-3,minecraft:netherrack)
B(0,65,-3,minecraft:netherrack)
B(0,66,-3,minecraft:netherrack)
B(0,67,-3,minecraft:netherrack)
B(0,68,-3,minecraft:netherrack)
B(0,69,-3,minecraft:netherrack)
B(0,70,-3,minecraft:netherrack)
B(0,71,-3,minecraft:netherrack)
B(0,72,-3,minecraft:netherrack)
B(0,73,-3,minecraft:netherrack)
B(0,74,-3,minecraft:netherrack)
B(0,75,-3,minecraft:netherrack)
B(0,76,-3,minecraft:netherrack)
B(0,77,-3,minecraft:netherrack)
B(0,78,-3,minecraft:netherrack)
B(0,79,-3,minecraft:netherrack)
B(0,80,-3,minecraft:netherrack)
B(0,81,-3,minecraft:netherrack)
B(0,82,-3,minecraft:netherrack)
B(0,83,-3,minecraft:netherrack)
B(0,84,-3,minecraft:netherrack)
B(0,85,-3,minecraft:netherrack)
B(0,86,-3,minecraft:netherrack)
B(0,87,-3,minecraft:netherrack)
B(0,88,-3,minecraft:netherrack)
B(0,89,-3,minecraft:netherrack)
B(0,90,-3,minecraft:netherrack)
B(0,41,-2,minecraft:netherrack)
B(0,42,-2,minecraft:netherrack)
B(0,43,-2,minecraft:netherrack)
B(0,44,-2,minecraft:netherrack)
B(0,45,-2,minecraft:netherrack)
B(0,46,-2,minecraft:netherrack)
B(0,47,-2,minecraft:netherrack)
B(0,48,-2,minecraft:netherrack)
B(0,49,-2,minecraft:netherrack)
B(0,50,-2,minecraft:netherrack)
B(0,51,-2,minecraft:netherrack)
B(0,52,-2,minecraft:netherrack)
B(0,53,-2,minecraft:netherrack)
B(0,54,-2,minecraft:netherrack)
B(0,55,-2,minecraft:netherrack)
B(0,56,-2,minecraft:netherrack)
B(0,57,-2,minecraft:netherrack)
B(0,58,-2,minecraft:netherrack)
B(0,59,-2,minecraft:netherrack)
B(0,60,-2,minecraft:netherrack)
B(0,61,-2,minecraft:netherrack)
B(0,62,-2,minecraft:netherrack)
B(0,63,-2,minecraft:netherrack)
B(0,64,-2,minecraft:netherrack)
B(0,65,-2,minecraft:netherrack)
B(0,66,-2,minecraft:netherrack)
B(0,67,-2,minecraft:netherrack)
B(0,68,-2,minecraft:netherrack)
B(0,69,-2,minecraft:netherrack)
B(0,70,-2,minecraft:netherrack)
B(0,71,-2,minecraft:netherrack)
B(0,72,-2,minecraft:netherrack)
B(0,73,-2,minecraft:netherrack)
B(0,74,-2,minecraft:netherrack)
B(0,75,-2,minecraft:netherrack)
B(0,76,-2,minecraft:netherrack)
B(0,77,-2,minecraft:netherrack)
B(0,78,-2,minecraft:netherrack)
B(0,79,-2,minecraft:netherrack)
B(0,80,-2,minecraft:netherrack)
B(0,81,-2,minecraft:netherrack)
B(0,82,-2,minecraft:netherrack)
B(0,83,-2,minecraft:netherrack)
B(0,84,-2,minecraft:netherrack)
B(0,85,-2,minecraft:netherrack)
B(0,86,-2,minecraft:netherrack)
B(0,87,-2,minecraft:netherrack)
B(0,88,-2,minecraft:netherrack)
B(0,89,-2,minecraft:netherrack)
B(0,90,-2,minecraft:netherrack)
B(0,38,-1,minecraft:netherrack)
B(0,39,-1,minecraft:netherrack)
B(0,40,-1,minecraft:netherrack)
B(0,41,-1,minecraft:netherrack)
B(0,42,-1,minecraft:netherrack)
B(0,43,-1,minecraft:netherrack)
B(0,44,-1,minecraft:netherrack)
B(0,45,-1,minecraft:netherrack)
B(0,46,-1,minecraft:netherrack)
B(0,47,-1,minecraft:netherrack)
B(0,48,-1,minecraft:netherrack)
B(0,49,-1,minecraft:netherrack)
B(0,50,-1,minecraft:netherrack)
B(0,51,-1,minecraft:netherrack)
B(0,52,-1,minecraft:netherrack)
B(0,53,-1,minecraft:netherrack)
B(0,54,-1,minecraft:netherrack)
B(0,55,-1,minecraft:netherrack)
B(0,56,-1,minecraft:netherrack)
B(0,57,-1,minecraft:netherrack)
B(0,58,-1,minecraft:netherrack)
B(0,59,-1,minecraft:netherrack)
B(0,60,-1,minecraft:netherrack)
B(0,61,-1,minecraft:netherrack)
B(0,62,-1,minecraft:netherrack)
B(0,63,-1,minecraft:netherrack)
B(0,64,-1,minecraft:netherrack)
B(0,65,-1,minecraft:netherrack)
B(0,66,-1,minecraft:netherrack)
B(0,67,-1,minecraft:netherrack)
B(0,68,-1,minecraft:netherrack)
B(0,69,-1,minecraft:netherrack)
B(0,70,-1,minecraft:netherrack)
B(0,71,-1,minecraft:netherrack)
B(0,72,-1,minecraft:netherrack)
B(0,73,-1,minecraft:netherrack)
B(0,74,-1,minecraft:netherrack)
B(0,75,-1,minecraft:netherrack)
B(0,76,-1,minecraft:netherrack)
B(0,77,-1,minecraft:netherrack)
B(0,78,-1,minecraft:netherrack)
B(0,79,-1,minecraft:netherrack)
B(0,80,-1,minecraft:netherrack)
B(0,81,-1,minecraft:netherrack)
B(0,82,-1,minecraft:netherrack)
B(0,83,-1,minecraft:netherrack)
B(0,84,-1,minecraft:netherrack)
B(0,85,-1,minecraft:netherrack)
B(0,86,-1,minecraft:netherrack)
B(0,87,-1,minecraft:netherrack)
B(0,88,-1,minecraft:netherrack)
B(0,89,-1,minecraft:netherrack)
B(0,90,-1,minecraft:netherrack)
B(0,36,0,minecraft:netherrack)
B(0,37,0,minecraft:netherrack)
B(0,38,0,minecraft:netherrack)
B(0,39,0,minecraft:netherrack)
B(0,40,0,minecraft:netherrack)
B(0,41,0,minecraft:netherrack)
B(0,42,0,minecraft:netherrack)
B(0,43,0,minecraft:netherrack)
B(0,44,0,minecraft:netherrack)
B(0,45,0,minecraft:netherrack)
B(0,46,0,minecraft:netherrack)
B(0,47,0,minecraft:netherrack)
B(0,48,0,minecraft:netherrack)
B(0,49,0,minecraft:netherrack)
B(0,50,0,minecraft:netherrack)
B(0,51,0,minecraft:netherrack)
B(0,52,0,minecraft:netherrack)
B(0,53,0,minecraft:netherrack)
B(0,54,0,minecraft:netherrack)
B(0,55,0,minecraft:netherrack)
B(0,56,0,minecraft:netherrack)
B(0,57,0,minecraft:netherrack)
B(0,58,0,minecraft:netherrack)
B(0,59,0,minecraft:netherrack)
B(0,60,0,minecraft:netherrack)
B(0,61,0,minecraft:netherrack)
B(0,62,0,minecraft:netherrack)
B(0,63,0,minecraft:netherrack)
B(0,64,0,minecraft:netherrack)
B(0,65,0,minecraft:netherrack)
B(0,66,0,minecraft:netherrack)
B(0,67,0,minecraft:netherrack)
B(0,68,0,minecraft:netherrack)
B(0,69,0,minecraft:netherrack)
B(0,70,0,minecraft:netherrack)
B(0,71,0,minecraft:netherrack)
B(0,72,0,minecraft:netherrack)
B(0,73,0,minecraft:netherrack)
B(0,74,0,minecraft:netherrack)
B(0,75,0,minecraft:netherrack)
B(0,76,0,minecraft:netherrack)
B(0,77,0,minecraft:netherrack)
B(0,78,0,minecraft:netherrack)
B(0,79,0,minecraft:netherrack)
B(0,80,0,minecraft:netherrack)
B(0,81,0,minecraft:netherrack)
B(0,82,0,minecraft:netherrack)
B(0,83,0,minecraft:netherrack)
B(0,84,0,minecraft:netherrack)
B(0,85,0,minecraft:netherrack)
B(0,86,0,minecraft:netherrack)
B(0,87,0,minecraft:netherrack)
B(0,88,0,minecraft:netherrack)
B(0,89,0,minecraft:netherrack)
B(0,90,0,minecraft:netherrack)
B(0,36,1,minecraft:netherrack)
B(0,37,1,minecraft:netherrack)
B(0,38,1,minecraft:netherrack)
B(0,39,1,minecraft:netherrack)
B(0,40,1,minecraft:netherrack)
B(0,41,1,minecraft:netherrack)
B(0,42,1,minecraft:netherrack)
B(0,43,1,minecraft:netherrack)
B(0,44,1,minecraft:netherrack)
B(0,45,1,minecraft:netherrack)
B(0,46,1,minecraft:netherrack)
B(0,47,1,minecraft:netherrack)
B(0,48,1,minecraft:netherrack)
B(0,49,1,minecraft:netherrack)
B(0,50,1,minecraft:netherrack)
B(0,51,1,minecraft:netherrack)
B(0,52,1,minecraft:netherrack)
B(0,53,1,minecraft:netherrack)
B(0,54,1,minecraft:netherrack)
B(0,55,1,minecraft:netherrack)
B(0,56,1,minecraft:netherrack)
B(0,57,1,minecraft:netherrack)
B(0,58,1,minecraft:netherrack)
B(0,59,1,minecraft:netherrack)
B(0,60,1,minecraft:netherrack)
B(0,61,1,minecraft:netherrack)
B(0,62,1,minecraft:netherrack)
B(0,63,1,minecraft:netherrack)
B(0,64,1,minecraft:netherrack)
B(0,65,1,minecraft:netherrack)
B(0,66,1,minecraft:netherrack)
B(0,67,1,minecraft:netherrack)
B(0,68,1,minecraft:netherrack)
B(0,69,1,minecraft:netherrack)
B(0,70,1,minecraft:netherrack)
B(0,71,1,minecraft:netherrack)
B(0,72,1,minecraft:netherrack)
B(0,73,1,minecraft:netherrack)
B(0,74,1,minecraft:netherrack)
B(0,75,1,minecraft:netherrack)
B(0,76,1,minecraft:netherrack)
B(0,77,1,minecraft:netherrack)
B(0,78,1,minecraft:netherrack)
B(0,79,1,minecraft:netherrack)
B(0,80,1,minecraft:netherrack)
B(0,81,1,minecraft:netherrack)
B(0,82,1,minecraft:netherrack)
B(0,83,1,minecraft:netherrack)
B(0,84,1,minecraft:netherrack)
B(0,85,1,minecraft:netherrack)
B(0,86,1,minecraft:netherrack)
B(0,87,1,minecraft:netherrack)
B(0,88,1,minecraft:netherrack)
B(0,89,1,minecraft:netherrack)
B(0,90,1,minecraft:netherrack)
B(0,36,2,minecraft:netherrack)
B(0,37,2,minecraft:netherrack)
B(0,38,2,minecraft:netherrack)
B(0,39,2,minecraft:netherrack)
B(0,40,2,minecraft:netherrack)
B(0,41,2,minecraft:netherrack)
B(0,42,2,minecraft:netherrack)
B(0,43,2,minecraft:netherrack)
B(0,44,2,minecraft:netherrack)
B(0,45,2,minecraft:netherrack)
B(0,46,2,minecraft:netherrack)
B(0,47,2,minecraft:netherrack)
B(0,48,2,minecraft:netherrack)
B(0,49,2,minecraft:netherrack)
B(0,50,2,minecraft:netherrack)
B(0,51,2,minecraft:netherrack)
B(0,52,2,minecraft:netherrack)
B(0,53,2,minecraft:netherrack)
B(0,54,2,minecraft:netherrack)
B(0,55,2,minecraft:netherrack)
B(0,56,2,minecraft:netherrack)
B(0,57,2,minecraft:netherrack)
B(0,58,2,minecraft:netherrack)
B(0,59,2,minecraft:netherrack)
B(0,60,2,minecraft:netherrack)
B(0,61,2,minecraft:netherrack)
B(0,62,2,minecraft:netherrack)
B(0,63,2,minecraft:netherrack)
B(0,64,2,minecraft:netherrack)
B(0,65,2,minecraft:netherrack)
B(0,66,2,minecraft:netherrack)
B(0,67,2,minecraft:netherrack)
B(0,68,2,minecraft:netherrack)
B(0,69,2,minecraft:netherrack)
B(0,70,2,minecraft:netherrack)
B(0,71,2,minecraft:netherrack)
B(0,72,2,minecraft:netherrack)
B(0,73,2,minecraft:netherrack)
B(0,74,2,minecraft:netherrack)
B(0,75,2,minecraft:netherrack)
B(0,76,2,minecraft:netherrack)
B(0,77,2,minecraft:netherrack)
B(0,78,2,minecraft:netherrack)
B(0,79,2,minecraft:netherrack)
B(0,80,2,minecraft:netherrack)
B(0,81,2,minecraft:netherrack)
B(0,82,2,minecraft:netherrack)
B(0,83,2,minecraft:netherrack)
B(0,84,2,minecraft:netherrack)
B(0,85,2,minecraft:netherrack)
B(0,86,2,minecraft:netherrack)
B(0,87,2,minecraft:netherrack)
B(0,88,2,minecraft:netherrack)
B(0,89,2,minecraft:netherrack)
B(0,90,2,minecraft:netherrack)
B(0,37,3,minecraft:netherrack)
B(0,38,3,minecraft:netherrack)
B(0,39,3,minecraft:netherrack)
B(0,40,3,minecraft:netherrack)
B(0,41,3,minecraft:netherrack)
B(0,42,3,minecraft:netherrack)
B(0,43,3,minecraft:netherrack)
B(0,44,3,minecraft:netherrack)
B(0,45,3,minecraft:netherrack)
B(0,46,3,minecraft:netherrack)
B(0,47,3,minecraft:netherrack)
B(0,48,3,minecraft:netherrack)
B(0,49,3,minecraft:netherrack)
B(0,50,3,minecraft:netherrack)
B(0,51,3,minecraft:netherrack)
B(0,52,3,minecraft:netherrack)
B(0,53,3,minecraft:netherrack)
B(0,54,3,minecraft:netherrack)
B(0,55,3,minecraft:netherrack)
B(0,56,3,minecraft:netherrack)
B(0,57,3,minecraft:netherrack)
B(0,58,3,minecraft:netherrack)
B(0,59,3,minecraft:netherrack)
B(0,60,3,minecraft:netherrack)
B(0,61,3,minecraft:netherrack)
B(0,62,3,minecraft:netherrack)
B(0,63,3,minecraft:netherrack)
B(0,64,3,minecraft:netherrack)
B(0,65,3,minecraft:netherrack)
B(0,66,3,minecraft:netherrack)
B(0,67,3,minecraft:netherrack)
B(0,68,3,minecraft:netherrack)
B(0,69,3,minecraft:netherrack)
B(0,70,3,minecraft:netherrack)
B(0,71,3,minecraft:netherrack)
B(0,72,3,minecraft:netherrack)
B(0,73,3,minecraft:netherrack)
B(0,74,3,minecraft:netherrack)
B(0,75,3,minecraft:netherrack)
B(0,76,3,minecraft:netherrack)
B(0,77,3,minecraft:netherrack)
B(0,78,3,minecraft:netherrack)
B(0,79,3,minecraft:netherrack)
B(0,80,3,minecraft:netherrack)
B(0,81,3,minecraft:netherrack)
B(0,82,3,minecraft:netherrack)
B(0,83,3,minecraft:netherrack)
B(0,84,3,minecraft:netherrack)
B(0,85,3,minecraft:netherrack)
B(0,86,3,minecraft:netherrack)
B(0,87,3,minecraft:netherrack)
B(0,88,3,minecraft:netherrack)
B(0,89,3,minecraft:netherrack)
B(0,90,3,minecraft:netherrack)
B(0,40,4,minecraft:netherrack)
B(0,41,4,minecraft:netherrack)
B(0,42,4,minecraft:netherrack)
B(0,43,4,minecraft:netherrack)
B(0,44,4,minecraft:netherrack)
B(0,45,4,minecraft:netherrack)
B(0,46,4,minecraft:netherrack)
B(0,47,4,minecraft:netherrack)
B(0,48,4,minecraft:netherrack)
B(0,49,4,minecraft:netherrack)
B(0,50,4,minecraft:netherrack)
B(0,51,4,minecraft:netherrack)
B(0,52,4,minecraft:netherrack)
B(0,53,4,minecraft:netherrack)
B(0,54,4,minecraft:netherrack)
B(0,55,4,minecraft:netherrack)
B(0,56,4,minecraft:netherrack)
B(0,57,4,minecraft:netherrack)
B(0,58,4,minecraft:netherrack)
B(0,59,4,minecraft:netherrack)
B(0,60,4,minecraft:netherrack)
B(0,61,4,minecraft:netherrack)
B(0,62,4,minecraft:netherrack)
B(0,63,4,minecraft:netherrack)
B(0,64,4,minecraft:netherrack)
B(0,65,4,minecraft:netherrack)
B(0,66,4,minecraft:netherrack)
B(0,67,4,minecraft:netherrack)
B(0,68,4,minecraft:netherrack)
B(0,69,4,minecraft:netherrack)
B(0,70,4,minecraft:netherrack)
B(0,71,4,minecraft:netherrack)
B(0,72,4,minecraft:netherrack)
B(0,73,4,minecraft:netherrack)
B(0,74,4,minecraft:netherrack)
B(0,75,4,minecraft:netherrack)
B(0,76,4,minecraft:netherrack)
B(0,77,4,minecraft:netherrack)
B(0,78,4,minecraft:netherrack)
B(0,79,4,minecraft:netherrack)
B(0,80,4,minecraft:netherrack)
B(0,81,4,minecraft:netherrack)
B(0,82,4,minecraft:netherrack)
B(0,83,4,minecraft:netherrack)
B(0,84,4,minecraft:netherrack)
B(0,85,4,minecraft:netherrack)
B(0,86,4,minecraft:netherrack)
B(0,87,4,minecraft:netherrack)
B(0,88,4,minecraft:netherrack)
B(0,89,4,minecraft:netherrack)
B(0,90,4,minecraft:netherrack)
B(0,44,5,minecraft:netherrack)
B(0,45,5,minecraft:netherrack)
B(0,46,5,minecraft:netherrack)
B(0,47,5,minecraft:netherrack)
B(0,48,5,minecraft:netherrack)
B(0,49,5,minecraft:netherrack)
B(0,50,5,minecraft:netherrack)
B(0,51,5,minecraft:netherrack)
B(0,52,5,minecraft:netherrack)
B(0,53,5,minecraft:netherrack)
B(0,54,5,minecraft:netherrack)
B(0,55,5,minecraft:netherrack)
B(0,56,5,minecraft:netherrack)
B(0,57,5,minecraft:netherrack)
B(0,58,5,minecraft:netherrack)
B(0,59,5,minecraft:netherrack)
B(0,60,5,minecraft:netherrack)
B(0,61,5,minecraft:netherrack)
B(0,62,5,minecraft:netherrack)
B(0,63,5,minecraft:netherrack)
B(0,64,5,minecraft:netherrack)
B(0,65,5,minecraft:netherrack)
B(0,66,5,minecraft:netherrack)
B(0,67,5,minecraft:netherrack)
B(0,68,5,minecraft:netherrack)
B(0,69,5,minecraft:netherrack)
B(0,70,5,minecraft:netherrack)
B(0,71,5,minecraft:netherrack)
B(0,72,5,minecraft:netherrack)
B(0,73,5,minecraft:netherrack)
B(0,74,5,minecraft:netherrack)
B(0,75,5,minecraft:netherrack)
B(0,76,5,minecraft:netherrack)
B(0,77,5,minecraft:netherrack)
B(0,78,5,minecraft:netherrack)
B(0,79,5,minecraft:netherrack)
B(0,80,5,minecraft:netherrack)
B(0,81,5,minecraft:netherrack)
B(0,82,5,minecraft:netherrack)
B(0,83,5,minecraft:netherrack)
B(0,84,5,minecraft:netherrack)
B(0,85,5,minecraft:netherrack)
B(0,86,5,minecraft:netherrack)
B(0,87,5,minecraft:netherrack)
B(0,88,5,minecraft:netherrack)
B(0,89,5,minecraft:netherrack)
B(0,90,5,minecraft:netherrack)
B(0,46,6,minecraft:netherrack)
B(0,47,6,minecraft:netherrack)
B(0,48,6,minecraft:netherrack)
B(0,49,6,minecraft:netherrack)
B(0,50,6,minecraft:netherrack)
B(0,51,6,minecraft:netherrack)
B(0,52,6,minecraft:netherrack)
B(0,53,6,minecraft:netherrack)
B(0,54,6,minecraft:netherrack)
B(0,55,6,minecraft:netherrack)
B(0,56,6,minecraft:netherrack)
B(0,57,6,minecraft:netherrack)
B(0,58,6,minecraft:netherrack)
B(0,59,6,minecraft:netherrack)
B(0,60,6,minecraft:netherrack)
B(0,61,6,minecraft:netherrack)
B(0,62,6,minecraft:netherrack)
B(0,63,6,minecraft:netherrack)
B(0,64,6,minecraft:netherrack)
B(0,65,6,minecraft:netherrack)
B(0,66,6,minecraft:netherrack)
B(0,67,6,minecraft:netherrack)
B(0,68,6,minecraft:netherrack)
B(0,69,6,minecraft:netherrack)
B(0,70,6,minecraft:netherrack)
B(0,71,6,minecraft:netherrack)
B(0,72,6,minecraft:netherrack)
B(0,73,6,minecraft:netherrack)
B(0,74,6,minecraft:netherrack)
B(0,75,6,minecraft:netherrack)
B(0,76,6,minecraft:netherrack)
B(0,77,6,minecraft:netherrack)
B(0,78,6,minecraft:netherrack)
B(0,79,6,minecraft:netherrack)
B(0,80,6,minecraft:netherrack)
B(0,81,6,minecraft:netherrack)
B(0,82,6,minecraft:netherrack)
B(0,83,6,minecraft:netherrack)
B(0,84,6,minecraft:netherrack)
B(0,85,6,minecraft:netherrack)
B(0,86,6,minecraft:netherrack)
B(0,87,6,minecraft:netherrack)
B(0,88,6,minecraft:netherrack)
B(0,89,6,minecraft:netherrack)
B(0,90,6,minecraft:netherrack)
B(0,57,7,minecraft:netherrack)
B(0,58,7,minecraft:netherrack)
B(0,59,7,minecraft:netherrack)
B(0,60,7,minecraft:netherrack)
B(0,61,7,minecraft:netherrack)
B(0,62,7,minecraft:netherrack)
B(0,63,7,minecraft:netherrack)
B(0,64,7,minecraft:netherrack)
B(0,65,7,minecraft:netherrack)
B(0,66,7,minecraft:netherrack)
B(0,67,7,minecraft:netherrack)
B(0,68,7,minecraft:netherrack)
B(0,69,7,minecraft:netherrack)
B(0,70,7,minecraft:netherrack)
B(0,71,7,minecraft:netherrack)
B(0,72,7,minecraft:netherrack)
B(0,73,7,minecraft:netherrack)
B(0,74,7,minecraft:netherrack)
B(0,75,7,minecraft:netherrack)
B(0,76,7,minecraft:netherrack)
B(0,77,7,minecraft:netherrack)
B(0,78,7,minecraft:netherrack)
B(0,79,7,minecraft:netherrack)
B(0,80,7,minecraft:netherrack)
B(0,81,7,minecraft:netherrack)
B(0,82,7,minecraft:netherrack)
B(0,83,7,minecraft:netherrack)
B(0,84,7,minecraft:netherrack)
B(0,85,7,minecraft:netherrack)
B(0,86,7,minecraft:netherrack)
B(0,87,7,minecraft:netherrack)
B(0,88,7,minecraft:netherrack)
B(0,89,7,minecraft:netherrack)
B(0,90,7,minecraft:netherrack)
B(0,51,8,minecraft:netherrack)
B(0,52,8,minecraft:netherrack)
B(0,53,8,minecraft:netherrack)
B(0,54,8,minecraft:netherrack)
B(0,55,8,minecraft:netherrack)
B(0,56,8,minecraft:netherrack)
B(0,57,8,minecraft:netherrack)
B(0,58,8,minecraft:netherrack)
B(0,59,8,minecraft:netherrack)
B(0,60,8,minecraft:netherrack)
B(0,61,8,minecraft:netherrack)
B(0,62,8,minecraft:netherrack)
B(0,63,8,minecraft:netherrack)
B(0,64,8,minecraft:netherrack)
B(0,65,8,minecraft:netherrack)
B(0,66,8,minecraft:netherrack)
B(0,67,8,minecraft:netherrack)
B(0,68,8,minecraft:netherrack)
B(0,69,8,minecraft:netherrack)
B(0,70,8,minecraft:netherrack)
B(0,71,8,minecraft:netherrack)
B(0,72,8,minecraft:netherrack)
B(0,73,8,minecraft:netherrack)
B(0,74,8,minecraft:netherrack)
B(0,75,8,minecraft:netherrack)
B(0,76,8,minecraft:netherrack)
B(0,77,8,minecraft:netherrack)
B(0,78,8,minecraft:netherrack)
B(0,79,8,minecraft:netherrack)
B(0,80,8,minecraft:netherrack)
B(0,81,8,minecraft:netherrack)
B(0,82,8,minecraft:netherrack)
B(0,83,8,minecraft:netherrack)
B(0,84,8,minecraft:netherrack)
B(0,85,8,minecraft:netherrack)
B(0,86,8,minecraft:netherrack)
B(0,87,8,minecraft:netherrack)
B(0,88,8,minecraft:netherrack)
B(0,89,8,minecraft:netherrack)
B(0,90,8,minecraft:netherrack)
B(1,28,-7,minecraft:netherrack)
B(1,29,-7,minecraft:netherrack)
B(1,30,-7,minecraft:netherrack)
B(1,31,-7,minecraft:netherrack)
B(1,32,-7,minecraft:netherrack)
B(1,33,-7,minecraft:netherrack)
B(1,34,-7,minecraft:netherrack)
B(1,35,-7,minecraft:netherrack)
B(1,36,-7,minecraft:netherrack)
B(1,37,-7,minecraft:netherrack)
B(1,38,-7,minecraft:netherrack)
B(1,39,-7,minecraft:netherrack)
B(1,40,-7,minecraft:netherrack)
B(1,41,-7,minecraft:netherrack)
B(1,42,-7,minecraft:netherrack)
B(1,43,-7,minecraft:netherrack)
B(1,44,-7,minecraft:netherrack)
B(1,45,-7,minecraft:netherrack)
B(1,46,-7,minecraft:netherrack)
B(1,47,-7,minecraft:netherrack)
B(1,48,-7,minecraft:netherrack)
B(1,49,-7,minecraft:netherrack)
B(1,50,-7,minecraft:netherrack)
B(1,51,-7,minecraft:netherrack)
B(1,52,-7,minecraft:netherrack)
B(1,53,-7,minecraft:netherrack)
B(1,54,-7,minecraft:netherrack)
B(1,55,-7,minecraft:netherrack)
B(1,56,-7,minecraft:netherrack)
B(1,57,-7,minecraft:netherrack)
B(1,58,-7,minecraft:netherrack)
B(1,59,-7,minecraft:netherrack)
B(1,60,-7,minecraft:netherrack)
B(1,61,-7,minecraft:netherrack)
B(1,62,-7,minecraft:netherrack)
B(1,63,-7,minecraft:netherrack)
B(1,64,-7,minecraft:netherrack)
B(1,65,-7,minecraft:netherrack)
B(1,66,-7,minecraft:netherrack)
B(1,67,-7,minecraft:netherrack)
B(1,68,-7,minecraft:netherrack)
B(1,69,-7,minecraft:netherrack)
B(1,70,-7,minecraft:netherrack)
B(1,71,-7,minecraft:netherrack)
B(1,72,-7,minecraft:netherrack)
B(1,73,-7,minecraft:netherrack)
B(1,74,-7,minecraft:netherrack)
B(1,75,-7,minecraft:netherrack)
B(1,76,-7,minecraft:netherrack)
B(1,77,-7,minecraft:netherrack)
B(1,78,-7,minecraft:netherrack)
B(1,79,-7,minecraft:netherrack)
B(1,80,-7,minecraft:netherrack)
B(1,81,-7,minecraft:netherrack)
B(1,82,-7,minecraft:netherrack)
B(1,83,-7,minecraft:netherrack)
B(1,84,-7,minecraft:netherrack)
B(1,85,-7,minecraft:netherrack)
B(1,86,-7,minecraft:netherrack)
B(1,87,-7,minecraft:netherrack)
B(1,88,-7,minecraft:netherrack)
B(1,89,-7,minecraft:netherrack)
B(1,90,-7,minecraft:netherrack)
B(1,28,-6,minecraft:netherrack)
B(1,29,-6,minecraft:netherrack)
B(1,30,-6,minecraft:netherrack)
B(1,31,-6,minecraft:netherrack)
B(1,32,-6,minecraft:netherrack)
B(1,33,-6,minecraft:netherrack)
B(1,34,-6,minecraft:netherrack)
B(1,35,-6,minecraft:netherrack)
B(1,36,-6,minecraft:netherrack)
B(1,37,-6,minecraft:netherrack)
B(1,38,-6,minecraft:netherrack)
B(1,39,-6,minecraft:netherrack)
B(1,40,-6,minecraft:netherrack)
B(1,41,-6,minecraft:netherrack)
B(1,42,-6,minecraft:netherrack)
B(1,43,-6,minecraft:netherrack)
B(1,44,-6,minecraft:netherrack)
B(1,45,-6,minecraft:netherrack)
B(1,46,-6,minecraft:netherrack)
B(1,47,-6,minecraft:netherrack)
B(1,48,-6,minecraft:netherrack)
B(1,49,-6,minecraft:netherrack)
B(1,50,-6,minecraft:netherrack)
B(1,51,-6,minecraft:netherrack)
B(1,52,-6,minecraft:netherrack)
B(1,53,-6,minecraft:netherrack)
B(1,54,-6,minecraft:netherrack)
B(1,55,-6,minecraft:netherrack)
B(1,56,-6,minecraft:netherrack)
B(1,57,-6,minecraft:netherrack)
B(1,58,-6,minecraft:netherrack)
B(1,59,-6,minecraft:netherrack)
B(1,60,-6,minecraft:netherrack)
B(1,61,-6,minecraft:netherrack)
B(1,62,-6,minecraft:netherrack)
B(1,63,-6,minecraft:netherrack)
B(1,64,-6,minecraft:netherrack)
B(1,65,-6,minecraft:netherrack)
B(1,66,-6,minecraft:netherrack)
B(1,67,-6,minecraft:netherrack)
B(1,68,-6,minecraft:netherrack)
B(1,69,-6,minecraft:netherrack)
B(1,70,-6,minecraft:netherrack)
B(1,71,-6,minecraft:netherrack)
B(1,72,-6,minecraft:netherrack)
B(1,73,-6,minecraft:netherrack)
B(1,74,-6,minecraft:netherrack)
B(1,75,-6,minecraft:netherrack)
B(1,76,-6,minecraft:netherrack)
B(1,77,-6,minecraft:netherrack)
B(1,78,-6,minecraft:netherrack)
B(1,79,-6,minecraft:netherrack)
B(1,80,-6,minecraft:netherrack)
B(1,81,-6,minecraft:netherrack)
B(1,82,-6,minecraft:netherrack)
B(1,83,-6,minecraft:netherrack)
B(1,84,-6,minecraft:netherrack)
B(1,85,-6,minecraft:netherrack)
B(1,86,-6,minecraft:netherrack)
B(1,87,-6,minecraft:netherrack)
B(1,88,-6,minecraft:netherrack)
B(1,89,-6,minecraft:netherrack)
B(1,90,-6,minecraft:netherrack)
B(1,29,-5,minecraft:netherrack)
B(1,30,-5,minecraft:netherrack)
B(1,31,-5,minecraft:netherrack)
B(1,32,-5,minecraft:netherrack)
B(1,33,-5,minecraft:netherrack)
B(1,34,-5,minecraft:netherrack)
B(1,35,-5,minecraft:netherrack)
B(1,36,-5,minecraft:netherrack)
B(1,37,-5,minecraft:netherrack)
B(1,38,-5,minecraft:netherrack)
B(1,39,-5,minecraft:netherrack)
B(1,40,-5,minecraft:netherrack)
B(1,41,-5,minecraft:netherrack)
B(1,42,-5,minecraft:netherrack)
B(1,43,-5,minecraft:netherrack)
B(1,44,-5,minecraft:netherrack)
B(1,45,-5,minecraft:netherrack)
B(1,46,-5,minecraft:netherrack)
B(1,47,-5,minecraft:netherrack)
B(1,48,-5,minecraft:netherrack)
B(1,49,-5,minecraft:netherrack)
B(1,50,-5,minecraft:netherrack)
B(1,51,-5,minecraft:netherrack)
B(1,52,-5,minecraft:netherrack)
B(1,53,-5,minecraft:netherrack)
B(1,54,-5,minecraft:netherrack)
B(1,55,-5,minecraft:netherrack)
B(1,56,-5,minecraft:netherrack)
B(1,57,-5,minecraft:netherrack)
B(1,58,-5,minecraft:netherrack)
B(1,59,-5,minecraft:netherrack)
B(1,60,-5,minecraft:netherrack)
B(1,61,-5,minecraft:netherrack)
B(1,62,-5,minecraft:netherrack)
B(1,63,-5,minecraft:netherrack)
B(1,64,-5,minecraft:netherrack)
B(1,65,-5,minecraft:netherrack)
B(1,66,-5,minecraft:netherrack)
B(1,67,-5,minecraft:netherrack)
B(1,68,-5,minecraft:netherrack)
B(1,69,-5,minecraft:netherrack)
B(1,70,-5,minecraft:netherrack)
B(1,71,-5,minecraft:netherrack)
B(1,72,-5,minecraft:netherrack)
B(1,73,-5,minecraft:netherrack)
B(1,74,-5,minecraft:netherrack)
B(1,75,-5,minecraft:netherrack)
B(1,76,-5,minecraft:netherrack)
B(1,77,-5,minecraft:netherrack)
B(1,78,-5,minecraft:netherrack)
B(1,79,-5,minecraft:netherrack)
B(1,80,-5,minecraft:netherrack)
B(1,81,-5,minecraft:netherrack)
B(1,82,-5,minecraft:netherrack)
B(1,83,-5,minecraft:netherrack)
B(1,84,-5,minecraft:netherrack)
B(1,85,-5,minecraft:netherrack)
B(1,86,-5,minecraft:netherrack)
B(1,87,-5,minecraft:netherrack)
B(1,88,-5,minecraft:netherrack)
B(1,89,-5,minecraft:netherrack)
B(1,90,-5,minecraft:netherrack)
B(1,29,-4,minecraft:netherrack)
B(1,30,-4,minecraft:netherrack)
B(1,31,-4,minecraft:netherrack)
B(1,32,-4,minecraft:netherrack)
B(1,33,-4,minecraft:netherrack)
B(1,34,-4,minecraft:netherrack)
B(1,35,-4,minecraft:netherrack)
B(1,36,-4,minecraft:netherrack)
B(1,37,-4,minecraft:netherrack)
B(1,38,-4,minecraft:netherrack)
B(1,39,-4,minecraft:netherrack)
B(1,40,-4,minecraft:netherrack)
B(1,41,-4,minecraft:netherrack)
B(1,42,-4,minecraft:netherrack)
B(1,43,-4,minecraft:netherrack)
B(1,44,-4,minecraft:netherrack)
B(1,45,-4,minecraft:netherrack)
B(1,46,-4,minecraft:netherrack)
B(1,47,-4,minecraft:netherrack)
B(1,48,-4,minecraft:netherrack)
B(1,49,-4,minecraft:netherrack)
B(1,50,-4,minecraft:netherrack)
B(1,51,-4,minecraft:netherrack)
B(1,52,-4,minecraft:netherrack)
B(1,53,-4,minecraft:netherrack)
B(1,54,-4,minecraft:netherrack)
B(1,55,-4,minecraft:netherrack)
B(1,56,-4,minecraft:netherrack)
B(1,57,-4,minecraft:netherrack)
B(1,58,-4,minecraft:netherrack)
B(1,59,-4,minecraft:netherrack)
B(1,60,-4,minecraft:netherrack)
B(1,61,-4,minecraft:netherrack)
B(1,62,-4,minecraft:netherrack)
B(1,63,-4,minecraft:netherrack)
B(1,64,-4,minecraft:netherrack)
B(1,65,-4,minecraft:netherrack)
B(1,66,-4,minecraft:netherrack)
B(1,67,-4,minecraft:netherrack)
B(1,68,-4,minecraft:netherrack)
B(1,69,-4,minecraft:netherrack)
B(1,70,-4,minecraft:netherrack)
B(1,71,-4,minecraft:netherrack)
B(1,72,-4,minecraft:netherrack)
B(1,73,-4,minecraft:netherrack)
B(1,74,-4,minecraft:netherrack)
B(1,75,-4,minecraft:netherrack)
B(1,76,-4,minecraft:netherrack)
B(1,77,-4,minecraft:netherrack)
B(1,78,-4,minecraft:netherrack)
B(1,79,-4,minecraft:netherrack)
B(1,80,-4,minecraft:netherrack)
B(1,81,-4,minecraft:netherrack)
B(1,82,-4,minecraft:netherrack)
B(1,83,-4,minecraft:netherrack)
B(1,84,-4,minecraft:netherrack)
B(1,85,-4,minecraft:netherrack)
B(1,86,-4,minecraft:netherrack)
B(1,87,-4,minecraft:netherrack)
B(1,88,-4,minecraft:netherrack)
B(1,89,-4,minecraft:netherrack)
B(1,90,-4,minecraft:netherrack)
B(1,30,-3,minecraft:netherrack)
B(1,31,-3,minecraft:netherrack)
B(1,32,-3,minecraft:netherrack)
B(1,33,-3,minecraft:netherrack)
B(1,34,-3,minecraft:netherrack)
B(1,35,-3,minecraft:netherrack)
B(1,36,-3,minecraft:netherrack)
B(1,37,-3,minecraft:netherrack)
B(1,38,-3,minecraft:netherrack)
B(1,39,-3,minecraft:netherrack)
B(1,40,-3,minecraft:netherrack)
B(1,41,-3,minecraft:netherrack)
B(1,42,-3,minecraft:netherrack)
B(1,43,-3,minecraft:netherrack)
B(1,44,-3,minecraft:netherrack)
B(1,45,-3,minecraft:netherrack)
B(1,46,-3,minecraft:netherrack)
B(1,47,-3,minecraft:netherrack)
B(1,48,-3,minecraft:netherrack)
B(1,49,-3,minecraft:netherrack)
B(1,50,-3,minecraft:netherrack)
B(1,51,-3,minecraft:netherrack)
B(1,52,-3,minecraft:netherrack)
B(1,53,-3,minecraft:netherrack)
B(1,54,-3,minecraft:netherrack)
B(1,55,-3,minecraft:netherrack)
B(1,56,-3,minecraft:netherrack)
B(1,57,-3,minecraft:netherrack)
B(1,58,-3,minecraft:netherrack)
B(1,59,-3,minecraft:netherrack)
B(1,60,-3,minecraft:netherrack)
B(1,61,-3,minecraft:netherrack)
B(1,62,-3,minecraft:netherrack)
B(1,63,-3,minecraft:netherrack)
B(1,64,-3,minecraft:netherrack)
B(1,65,-3,minecraft:netherrack)
B(1,66,-3,minecraft:netherrack)
B(1,67,-3,minecraft:netherrack)
B(1,68,-3,minecraft:netherrack)
B(1,69,-3,minecraft:netherrack)
B(1,70,-3,minecraft:netherrack)
B(1,71,-3,minecraft:netherrack)
B(1,72,-3,minecraft:netherrack)
B(1,73,-3,minecraft:netherrack)
B(1,74,-3,minecraft:netherrack)
B(1,75,-3,minecraft:netherrack)
B(1,76,-3,minecraft:netherrack)
B(1,77,-3,minecraft:netherrack)
B(1,78,-3,minecraft:netherrack)
B(1,79,-3,minecraft:netherrack)
B(1,80,-3,minecraft:netherrack)
B(1,81,-3,minecraft:netherrack)
B(1,82,-3,minecraft:netherrack)
B(1,83,-3,minecraft:netherrack)
B(1,84,-3,minecraft:netherrack)
B(1,85,-3,minecraft:netherrack)
B(1,86,-3,minecraft:netherrack)
B(1,87,-3,minecraft:netherrack)
B(1,88,-3,minecraft:netherrack)
B(1,89,-3,minecraft:netherrack)
B(1,90,-3,minecraft:netherrack)
B(1,32,-2,minecraft:netherrack)
B(1,33,-2,minecraft:netherrack)
B(1,34,-2,minecraft:netherrack)
B(1,35,-2,minecraft:netherrack)
B(1,36,-2,minecraft:netherrack)
B(1,37,-2,minecraft:netherrack)
B(1,38,-2,minecraft:netherrack)
B(1,39,-2,minecraft:netherrack)
B(1,40,-2,minecraft:netherrack)
B(1,41,-2,minecraft:netherrack)
B(1,42,-2,minecraft:netherrack)
B(1,43,-2,minecraft:netherrack)
B(1,44,-2,minecraft:netherrack)
B(1,45,-2,minecraft:netherrack)
B(1,46,-2,minecraft:netherrack)
B(1,47,-2,minecraft:netherrack)
B(1,48,-2,minecraft:netherrack)
B(1,49,-2,minecraft:netherrack)
B(1,50,-2,minecraft:netherrack)
B(1,51,-2,minecraft:netherrack)
B(1,52,-2,minecraft:netherrack)
B(1,53,-2,minecraft:netherrack)
B(1,54,-2,minecraft:netherrack)
B(1,55,-2,minecraft:netherrack)
B(1,56,-2,minecraft:netherrack)
B(1,57,-2,minecraft:netherrack)
B(1,58,-2,minecraft:netherrack)
B(1,59,-2,minecraft:netherrack)
B(1,60,-2,minecraft:netherrack)
B(1,61,-2,minecraft:netherrack)
B(1,62,-2,minecraft:netherrack)
B(1,63,-2,minecraft:netherrack)
B(1,64,-2,minecraft:netherrack)
B(1,65,-2,minecraft:netherrack)
B(1,66,-2,minecraft:netherrack)
B(1,67,-2,minecraft:netherrack)
B(1,68,-2,minecraft:netherrack)
B(1,69,-2,minecraft:netherrack)
B(1,70,-2,minecraft:netherrack)
B(1,71,-2,minecraft:netherrack)
B(1,72,-2,minecraft:netherrack)
B(1,73,-2,minecraft:netherrack)
B(1,74,-2,minecraft:netherrack)
B(1,75,-2,minecraft:netherrack)
B(1,76,-2,minecraft:netherrack)
B(1,77,-2,minecraft:netherrack)
B(1,78,-2,minecraft:netherrack)
B(1,79,-2,minecraft:netherrack)
B(1,80,-2,minecraft:netherrack)
B(1,81,-2,minecraft:netherrack)
B(1,82,-2,minecraft:netherrack)
B(1,83,-2,minecraft:netherrack)
B(1,84,-2,minecraft:netherrack)
B(1,85,-2,minecraft:netherrack)
B(1,86,-2,minecraft:netherrack)
B(1,87,-2,minecraft:netherrack)
B(1,88,-2,minecraft:netherrack)
B(1,89,-2,minecraft:netherrack)
B(1,90,-2,minecraft:netherrack)
B(1,35,-1,minecraft:netherrack)
B(1,36,-1,minecraft:netherrack)
B(1,37,-1,minecraft:netherrack)
B(1,38,-1,minecraft:netherrack)
B(1,39,-1,minecraft:netherrack)
B(1,40,-1,minecraft:netherrack)
B(1,41,-1,minecraft:netherrack)
B(1,42,-1,minecraft:netherrack)
B(1,43,-1,minecraft:netherrack)
B(1,44,-1,minecraft:netherrack)
B(1,45,-1,minecraft:netherrack)
B(1,46,-1,minecraft:netherrack)
B(1,47,-1,minecraft:netherrack)
B(1,48,-1,minecraft:netherrack)
B(1,49,-1,minecraft:netherrack)
B(1,50,-1,minecraft:netherrack)
B(1,51,-1,minecraft:netherrack)
B(1,52,-1,minecraft:netherrack)
B(1,53,-1,minecraft:netherrack)
B(1,54,-1,minecraft:netherrack)
B(1,55,-1,minecraft:netherrack)
B(1,56,-1,minecraft:netherrack)
B(1,57,-1,minecraft:netherrack)
B(1,58,-1,minecraft:netherrack)
B(1,59,-1,minecraft:netherrack)
B(1,60,-1,minecraft:netherrack)
B(1,61,-1,minecraft:netherrack)
B(1,62,-1,minecraft:netherrack)
B(1,63,-1,minecraft:netherrack)
B(1,64,-1,minecraft:netherrack)
B(1,65,-1,minecraft:netherrack)
B(1,66,-1,minecraft:netherrack)
B(1,67,-1,minecraft:netherrack)
B(1,68,-1,minecraft:netherrack)
B(1,69,-1,minecraft:netherrack)
B(1,70,-1,minecraft:netherrack)
B(1,71,-1,minecraft:netherrack)
B(1,72,-1,minecraft:netherrack)
B(1,73,-1,minecraft:netherrack)
B(1,74,-1,minecraft:netherrack)
B(1,75,-1,minecraft:netherrack)
B(1,76,-1,minecraft:netherrack)
B(1,77,-1,minecraft:netherrack)
B(1,78,-1,minecraft:netherrack)
B(1,79,-1,minecraft:netherrack)
B(1,80,-1,minecraft:netherrack)
B(1,81,-1,minecraft:netherrack)
B(1,82,-1,minecraft:netherrack)
B(1,83,-1,minecraft:netherrack)
B(1,84,-1,minecraft:netherrack)
B(1,85,-1,minecraft:netherrack)
B(1,86,-1,minecraft:netherrack)
B(1,87,-1,minecraft:netherrack)
B(1,88,-1,minecraft:netherrack)
B(1,89,-1,minecraft:netherrack)
B(1,90,-1,minecraft:netherrack)
B(1,35,0,minecraft:netherrack)
B(1,36,0,minecraft:netherrack)
B(1,37,0,minecraft:netherrack)
B(1,38,0,minecraft:netherrack)
B(1,39,0,minecraft:netherrack)
B(1,40,0,minecraft:netherrack)
B(1,41,0,minecraft:netherrack)
B(1,42,0,minecraft:netherrack)
B(1,43,0,minecraft:netherrack)
B(1,44,0,minecraft:netherrack)
B(1,45,0,minecraft:netherrack)
B(1,46,0,minecraft:netherrack)
B(1,47,0,minecraft:netherrack)
B(1,48,0,minecraft:netherrack)
B(1,49,0,minecraft:netherrack)
B(1,50,0,minecraft:netherrack)
B(1,51,0,minecraft:netherrack)
B(1,52,0,minecraft:netherrack)
B(1,53,0,minecraft:netherrack)
B(1,54,0,minecraft:netherrack)
B(1,55,0,minecraft:netherrack)
B(1,56,0,minecraft:netherrack)
B(1,57,0,minecraft:netherrack)
B(1,58,0,minecraft:netherrack)
B(1,59,0,minecraft:netherrack)
B(1,60,0,minecraft:netherrack)
B(1,61,0,minecraft:netherrack)
B(1,62,0,minecraft:netherrack)
B(1,63,0,minecraft:netherrack)
B(1,64,0,minecraft:netherrack)
B(1,65,0,minecraft:netherrack)
B(1,66,0,minecraft:netherrack)
B(1,67,0,minecraft:netherrack)
B(1,68,0,minecraft:netherrack)
B(1,69,0,minecraft:netherrack)
B(1,70,0,minecraft:netherrack)
B(1,71,0,minecraft:netherrack)
B(1,72,0,minecraft:netherrack)
B(1,73,0,minecraft:netherrack)
B(1,74,0,minecraft:netherrack)
B(1,75,0,minecraft:netherrack)
B(1,76,0,minecraft:netherrack)
B(1,77,0,minecraft:netherrack)
B(1,78,0,minecraft:netherrack)
B(1,79,0,minecraft:netherrack)
B(1,80,0,minecraft:netherrack)
B(1,81,0,minecraft:netherrack)
B(1,82,0,minecraft:netherrack)
B(1,83,0,minecraft:netherrack)
B(1,84,0,minecraft:netherrack)
B(1,85,0,minecraft:netherrack)
B(1,86,0,minecraft:netherrack)
B(1,87,0,minecraft:netherrack)
B(1,88,0,minecraft:netherrack)
B(1,89,0,minecraft:netherrack)
B(1,90,0,minecraft:netherrack)
B(1,35,1,minecraft:netherrack)
B(1,36,1,minecraft:netherrack)
B(1,37,1,minecraft:netherrack)
B(1,38,1,minecraft:netherrack)
B(1,39,1,minecraft:netherrack)
B(1,40,1,minecraft:netherrack)
B(1,41,1,minecraft:netherrack)
B(1,42,1,minecraft:netherrack)
B(1,43,1,minecraft:netherrack)
B(1,44,1,minecraft:netherrack)
B(1,45,1,minecraft:netherrack)
B(1,46,1,minecraft:netherrack)
B(1,47,1,minecraft:netherrack)
B(1,48,1,minecraft:netherrack)
B(1,49,1,minecraft:netherrack)
B(1,50,1,minecraft:netherrack)
B(1,51,1,minecraft:netherrack)
B(1,52,1,minecraft:netherrack)
B(1,53,1,minecraft:netherrack)
B(1,54,1,minecraft:netherrack)
B(1,55,1,minecraft:netherrack)
B(1,56,1,minecraft:netherrack)
B(1,57,1,minecraft:netherrack)
B(1,58,1,minecraft:netherrack)
B(1,59,1,minecraft:netherrack)
B(1,60,1,minecraft:netherrack)
B(1,61,1,minecraft:netherrack)
B(1,62,1,minecraft:netherrack)
B(1,63,1,minecraft:netherrack)
B(1,64,1,minecraft:netherrack)
B(1,65,1,minecraft:netherrack)
B(1,66,1,minecraft:netherrack)
B(1,67,1,minecraft:netherrack)
B(1,68,1,minecraft:netherrack)
B(1,69,1,minecraft:netherrack)
B(1,70,1,minecraft:netherrack)
B(1,71,1,minecraft:netherrack)
B(1,72,1,minecraft:netherrack)
B(1,73,1,minecraft:netherrack)
B(1,74,1,minecraft:netherrack)
B(1,75,1,minecraft:netherrack)
B(1,76,1,minecraft:netherrack)
B(1,77,1,minecraft:netherrack)
B(1,78,1,minecraft:netherrack)
B(1,79,1,minecraft:netherrack)
B(1,80,1,minecraft:netherrack)
B(1,81,1,minecraft:netherrack)
B(1,82,1,minecraft:netherrack)
B(1,83,1,minecraft:netherrack)
B(1,84,1,minecraft:netherrack)
B(1,85,1,minecraft:netherrack)
B(1,86,1,minecraft:netherrack)
B(1,87,1,minecraft:netherrack)
B(1,88,1,minecraft:netherrack)
B(1,89,1,minecraft:netherrack)
B(1,90,1,minecraft:netherrack)
B(1,35,2,minecraft:netherrack)
B(1,36,2,minecraft:netherrack)
B(1,37,2,minecraft:netherrack)
B(1,38,2,minecraft:netherrack)
B(1,39,2,minecraft:netherrack)
