
#######################################################################
# +-----------------------------------------------------------------+ #
# |                            BO4 object                           | #
# +-----------------------------------------------------------------+ #
#######################################################################

Author: Unknown

Description: No description given

SettingsMode: WriteWithoutComments


#######################################################################
# +-----------------------------------------------------------------+ #
# |                          Main settings                          | #
# +-----------------------------------------------------------------+ #
#######################################################################

FixedRotation: 

Frequency: 0

SpawnHeight: highestBlock

UseCenterForHighestBlock: true

##############################
# Height Limits for the BO4. #
##############################

MinHeight: 0

MaxHeight: 255

InheritBO3: 

InheritBO3Rotation: NORTH

OverrideChildSettings: true

OverrideParentHeight: false

CanOverride: false

BranchFrequency: 0

BranchFrequencyGroup: 

MustBeBelowOther: false

MustBeInside: 

CannotBeInside: 

ReplacesBO3: 

MustBeInsideWorldBorders: false

CanSpawnOnWater: true

SpawnOnWaterOnly: false

SpawnUnderWater: false

SpawnAtWaterLevel: false

HeightOffset: 0

RemoveAir: true

ReplaceAbove: 

ReplaceBelow: 

ReplaceWithBiomeBlocks: true

ReplaceWithSurfaceBlock: GRASS

ReplaceWithGroundBlock: DIRT

ReplaceWithStoneBlock: STONE

SmoothRadius: 0

SmoothHeightOffset: 0

SmoothStartTop: false

SmoothStartWood: false

SmoothingSurfaceBlock: 

SmoothingGroundBlock: 

BO3Group: 

IsSpawnPoint: false

DoReplaceBlocks: true


#######################################################################
# +-----------------------------------------------------------------+ #
# |                              Blocks                             | #
# +-----------------------------------------------------------------+ #
#######################################################################

B(-8,27,-7,minecraft:netherrack)
B(-8,28,-7,minecraft:netherrack)
B(-8,29,-7,minecraft:netherrack)
B(-8,30,-7,minecraft:netherrack)
B(-8,31,-7,minecraft:netherrack)
B(-8,32,-7,minecraft:netherrack)
B(-8,33,-7,minecraft:netherrack)
B(-8,34,-7,minecraft:netherrack)
B(-8,35,-7,minecraft:netherrack)
B(-8,36,-7,minecraft:netherrack)
B(-8,37,-7,minecraft:netherrack)
B(-8,38,-7,minecraft:netherrack)
B(-8,39,-7,minecraft:netherrack)
B(-8,40,-7,minecraft:netherrack)
B(-8,41,-7,minecraft:netherrack)
B(-8,42,-7,minecraft:netherrack)
B(-8,43,-7,minecraft:netherrack)
B(-8,44,-7,minecraft:netherrack)
B(-8,45,-7,minecraft:netherrack)
B(-8,46,-7,minecraft:netherrack)
B(-8,47,-7,minecraft:netherrack)
B(-8,48,-7,minecraft:netherrack)
B(-8,49,-7,minecraft:netherrack)
B(-8,50,-7,minecraft:netherrack)
B(-8,51,-7,minecraft:netherrack)
B(-8,52,-7,minecraft:netherrack)
B(-8,53,-7,minecraft:netherrack)
B(-8,54,-7,minecraft:netherrack)
B(-8,55,-7,minecraft:netherrack)
B(-8,56,-7,minecraft:netherrack)
B(-8,57,-7,minecraft:netherrack)
B(-8,58,-7,minecraft:netherrack)
B(-8,59,-7,minecraft:netherrack)
B(-8,60,-7,minecraft:netherrack)
B(-8,61,-7,minecraft:netherrack)
B(-8,62,-7,minecraft:netherrack)
B(-8,63,-7,minecraft:netherrack)
B(-8,64,-7,minecraft:netherrack)
B(-8,65,-7,minecraft:netherrack)
B(-8,66,-7,minecraft:netherrack)
B(-8,67,-7,minecraft:netherrack)
B(-8,68,-7,minecraft:netherrack)
B(-8,69,-7,minecraft:netherrack)
B(-8,70,-7,minecraft:netherrack)
B(-8,71,-7,minecraft:netherrack)
B(-8,72,-7,minecraft:netherrack)
B(-8,73,-7,minecraft:netherrack)
B(-8,74,-7,minecraft:netherrack)
B(-8,75,-7,minecraft:netherrack)
B(-8,76,-7,minecraft:netherrack)
B(-8,77,-7,minecraft:netherrack)
B(-8,78,-7,minecraft:netherrack)
B(-8,79,-7,minecraft:netherrack)
B(-8,80,-7,minecraft:netherrack)
B(-8,81,-7,minecraft:netherrack)
B(-8,82,-7,minecraft:netherrack)
B(-8,83,-7,minecraft:netherrack)
B(-8,84,-7,minecraft:netherrack)
B(-8,85,-7,minecraft:netherrack)
B(-8,86,-7,minecraft:netherrack)
B(-8,87,-7,minecraft:netherrack)
B(-8,88,-7,minecraft:netherrack)
B(-8,89,-7,minecraft:netherrack)
B(-8,90,-7,minecraft:netherrack)
B(-8,27,-6,minecraft:netherrack)
B(-8,28,-6,minecraft:netherrack)
B(-8,29,-6,minecraft:netherrack)
B(-8,30,-6,minecraft:netherrack)
B(-8,31,-6,minecraft:netherrack)
B(-8,32,-6,minecraft:netherrack)
B(-8,33,-6,minecraft:netherrack)
B(-8,34,-6,minecraft:netherrack)
B(-8,35,-6,minecraft:netherrack)
B(-8,36,-6,minecraft:netherrack)
B(-8,37,-6,minecraft:netherrack)
B(-8,38,-6,minecraft:netherrack)
B(-8,39,-6,minecraft:netherrack)
B(-8,40,-6,minecraft:netherrack)
B(-8,41,-6,minecraft:netherrack)
B(-8,42,-6,minecraft:netherrack)
B(-8,43,-6,minecraft:netherrack)
B(-8,44,-6,minecraft:netherrack)
B(-8,45,-6,minecraft:netherrack)
B(-8,46,-6,minecraft:netherrack)
B(-8,47,-6,minecraft:netherrack)
B(-8,48,-6,minecraft:netherrack)
B(-8,49,-6,minecraft:netherrack)
B(-8,50,-6,minecraft:netherrack)
B(-8,51,-6,minecraft:netherrack)
B(-8,52,-6,minecraft:netherrack)
B(-8,53,-6,minecraft:netherrack)
B(-8,54,-6,minecraft:netherrack)
B(-8,55,-6,minecraft:netherrack)
B(-8,56,-6,minecraft:netherrack)
B(-8,57,-6,minecraft:netherrack)
B(-8,58,-6,minecraft:netherrack)
B(-8,59,-6,minecraft:netherrack)
B(-8,60,-6,minecraft:netherrack)
B(-8,61,-6,minecraft:netherrack)
B(-8,62,-6,minecraft:netherrack)
B(-8,63,-6,minecraft:netherrack)
B(-8,64,-6,minecraft:netherrack)
B(-8,65,-6,minecraft:netherrack)
B(-8,66,-6,minecraft:netherrack)
B(-8,67,-6,minecraft:netherrack)
B(-8,68,-6,minecraft:netherrack)
B(-8,69,-6,minecraft:netherrack)
B(-8,70,-6,minecraft:netherrack)
B(-8,71,-6,minecraft:netherrack)
B(-8,72,-6,minecraft:netherrack)
B(-8,73,-6,minecraft:netherrack)
B(-8,74,-6,minecraft:netherrack)
B(-8,75,-6,minecraft:netherrack)
B(-8,76,-6,minecraft:netherrack)
B(-8,77,-6,minecraft:netherrack)
B(-8,78,-6,minecraft:netherrack)
B(-8,79,-6,minecraft:netherrack)
B(-8,80,-6,minecraft:netherrack)
B(-8,81,-6,minecraft:netherrack)
B(-8,82,-6,minecraft:netherrack)
B(-8,83,-6,minecraft:netherrack)
B(-8,84,-6,minecraft:netherrack)
B(-8,85,-6,minecraft:netherrack)
B(-8,86,-6,minecraft:netherrack)
B(-8,87,-6,minecraft:netherrack)
B(-8,88,-6,minecraft:netherrack)
B(-8,89,-6,minecraft:netherrack)
B(-8,90,-6,minecraft:netherrack)
B(-8,27,-5,minecraft:netherrack)
B(-8,28,-5,minecraft:netherrack)
B(-8,29,-5,minecraft:netherrack)
B(-8,30,-5,minecraft:netherrack)
B(-8,31,-5,minecraft:netherrack)
B(-8,32,-5,minecraft:netherrack)
B(-8,33,-5,minecraft:netherrack)
B(-8,34,-5,minecraft:netherrack)
B(-8,35,-5,minecraft:netherrack)
B(-8,36,-5,minecraft:netherrack)
B(-8,37,-5,minecraft:netherrack)
B(-8,38,-5,minecraft:netherrack)
B(-8,39,-5,minecraft:netherrack)
B(-8,40,-5,minecraft:netherrack)
B(-8,41,-5,minecraft:netherrack)
B(-8,42,-5,minecraft:netherrack)
B(-8,43,-5,minecraft:netherrack)
B(-8,44,-5,minecraft:netherrack)
B(-8,45,-5,minecraft:netherrack)
B(-8,46,-5,minecraft:netherrack)
B(-8,47,-5,minecraft:netherrack)
B(-8,48,-5,minecraft:netherrack)
B(-8,49,-5,minecraft:netherrack)
B(-8,50,-5,minecraft:netherrack)
B(-8,51,-5,minecraft:netherrack)
B(-8,52,-5,minecraft:netherrack)
B(-8,53,-5,minecraft:netherrack)
B(-8,54,-5,minecraft:netherrack)
B(-8,55,-5,minecraft:netherrack)
B(-8,56,-5,minecraft:netherrack)
B(-8,57,-5,minecraft:netherrack)
B(-8,58,-5,minecraft:netherrack)
B(-8,59,-5,minecraft:netherrack)
B(-8,60,-5,minecraft:netherrack)
B(-8,61,-5,minecraft:netherrack)
B(-8,62,-5,minecraft:netherrack)
B(-8,63,-5,minecraft:netherrack)
B(-8,64,-5,minecraft:netherrack)
B(-8,65,-5,minecraft:netherrack)
B(-8,66,-5,minecraft:netherrack)
B(-8,67,-5,minecraft:netherrack)
B(-8,68,-5,minecraft:netherrack)
B(-8,69,-5,minecraft:netherrack)
B(-8,70,-5,minecraft:netherrack)
B(-8,71,-5,minecraft:netherrack)
B(-8,72,-5,minecraft:netherrack)
B(-8,73,-5,minecraft:netherrack)
B(-8,74,-5,minecraft:netherrack)
B(-8,75,-5,minecraft:netherrack)
B(-8,76,-5,minecraft:netherrack)
B(-8,77,-5,minecraft:netherrack)
B(-8,78,-5,minecraft:netherrack)
B(-8,79,-5,minecraft:netherrack)
B(-8,80,-5,minecraft:netherrack)
B(-8,81,-5,minecraft:netherrack)
B(-8,82,-5,minecraft:netherrack)
B(-8,83,-5,minecraft:netherrack)
B(-8,84,-5,minecraft:netherrack)
B(-8,85,-5,minecraft:netherrack)
B(-8,86,-5,minecraft:netherrack)
B(-8,87,-5,minecraft:netherrack)
B(-8,88,-5,minecraft:netherrack)
B(-8,89,-5,minecraft:netherrack)
B(-8,90,-5,minecraft:netherrack)
B(-8,27,-4,minecraft:netherrack)
B(-8,28,-4,minecraft:netherrack)
B(-8,29,-4,minecraft:netherrack)
B(-8,30,-4,minecraft:netherrack)
B(-8,31,-4,minecraft:netherrack)
B(-8,32,-4,minecraft:netherrack)
B(-8,33,-4,minecraft:netherrack)
B(-8,34,-4,minecraft:netherrack)
B(-8,35,-4,minecraft:netherrack)
B(-8,36,-4,minecraft:netherrack)
B(-8,37,-4,minecraft:netherrack)
B(-8,38,-4,minecraft:netherrack)
B(-8,39,-4,minecraft:netherrack)
B(-8,40,-4,minecraft:netherrack)
B(-8,41,-4,minecraft:netherrack)
B(-8,42,-4,minecraft:netherrack)
B(-8,43,-4,minecraft:netherrack)
B(-8,44,-4,minecraft:netherrack)
B(-8,45,-4,minecraft:netherrack)
B(-8,46,-4,minecraft:netherrack)
B(-8,47,-4,minecraft:netherrack)
B(-8,48,-4,minecraft:netherrack)
B(-8,49,-4,minecraft:netherrack)
B(-8,50,-4,minecraft:netherrack)
B(-8,51,-4,minecraft:netherrack)
B(-8,52,-4,minecraft:netherrack)
B(-8,53,-4,minecraft:netherrack)
B(-8,54,-4,minecraft:netherrack)
B(-8,55,-4,minecraft:netherrack)
B(-8,56,-4,minecraft:netherrack)
B(-8,57,-4,minecraft:netherrack)
B(-8,58,-4,minecraft:netherrack)
B(-8,59,-4,minecraft:netherrack)
B(-8,60,-4,minecraft:netherrack)
B(-8,61,-4,minecraft:netherrack)
B(-8,62,-4,minecraft:netherrack)
B(-8,63,-4,minecraft:netherrack)
B(-8,64,-4,minecraft:netherrack)
B(-8,65,-4,minecraft:netherrack)
B(-8,66,-4,minecraft:netherrack)
B(-8,67,-4,minecraft:netherrack)
B(-8,68,-4,minecraft:netherrack)
B(-8,69,-4,minecraft:netherrack)
B(-8,70,-4,minecraft:netherrack)
B(-8,71,-4,minecraft:netherrack)
B(-8,72,-4,minecraft:netherrack)
B(-8,73,-4,minecraft:netherrack)
B(-8,74,-4,minecraft:netherrack)
B(-8,75,-4,minecraft:netherrack)
B(-8,76,-4,minecraft:netherrack)
B(-8,77,-4,minecraft:netherrack)
B(-8,78,-4,minecraft:netherrack)
B(-8,79,-4,minecraft:netherrack)
B(-8,80,-4,minecraft:netherrack)
B(-8,81,-4,minecraft:netherrack)
B(-8,82,-4,minecraft:netherrack)
B(-8,83,-4,minecraft:netherrack)
B(-8,84,-4,minecraft:netherrack)
B(-8,85,-4,minecraft:netherrack)
B(-8,86,-4,minecraft:netherrack)
B(-8,87,-4,minecraft:netherrack)
B(-8,88,-4,minecraft:netherrack)
B(-8,89,-4,minecraft:netherrack)
B(-8,90,-4,minecraft:netherrack)
B(-8,28,-3,minecraft:netherrack)
B(-8,29,-3,minecraft:netherrack)
B(-8,30,-3,minecraft:netherrack)
B(-8,31,-3,minecraft:netherrack)
B(-8,32,-3,minecraft:netherrack)
B(-8,33,-3,minecraft:netherrack)
B(-8,34,-3,minecraft:netherrack)
B(-8,35,-3,minecraft:netherrack)
B(-8,36,-3,minecraft:netherrack)
B(-8,37,-3,minecraft:netherrack)
B(-8,38,-3,minecraft:netherrack)
B(-8,39,-3,minecraft:netherrack)
B(-8,40,-3,minecraft:netherrack)
B(-8,41,-3,minecraft:netherrack)
B(-8,42,-3,minecraft:netherrack)
B(-8,43,-3,minecraft:netherrack)
B(-8,44,-3,minecraft:netherrack)
B(-8,45,-3,minecraft:netherrack)
B(-8,46,-3,minecraft:netherrack)
B(-8,47,-3,minecraft:netherrack)
B(-8,48,-3,minecraft:netherrack)
B(-8,49,-3,minecraft:netherrack)
B(-8,50,-3,minecraft:netherrack)
B(-8,51,-3,minecraft:netherrack)
B(-8,52,-3,minecraft:netherrack)
B(-8,53,-3,minecraft:netherrack)
B(-8,54,-3,minecraft:netherrack)
B(-8,55,-3,minecraft:netherrack)
B(-8,56,-3,minecraft:netherrack)
B(-8,57,-3,minecraft:netherrack)
B(-8,58,-3,minecraft:netherrack)
B(-8,59,-3,minecraft:netherrack)
B(-8,60,-3,minecraft:netherrack)
B(-8,61,-3,minecraft:netherrack)
B(-8,62,-3,minecraft:netherrack)
B(-8,63,-3,minecraft:netherrack)
B(-8,64,-3,minecraft:netherrack)
B(-8,65,-3,minecraft:netherrack)
B(-8,66,-3,minecraft:netherrack)
B(-8,67,-3,minecraft:netherrack)
B(-8,68,-3,minecraft:netherrack)
B(-8,69,-3,minecraft:netherrack)
B(-8,70,-3,minecraft:netherrack)
B(-8,71,-3,minecraft:netherrack)
B(-8,72,-3,minecraft:netherrack)
B(-8,73,-3,minecraft:netherrack)
B(-8,74,-3,minecraft:netherrack)
B(-8,75,-3,minecraft:netherrack)
B(-8,76,-3,minecraft:netherrack)
B(-8,77,-3,minecraft:netherrack)
B(-8,78,-3,minecraft:netherrack)
B(-8,79,-3,minecraft:netherrack)
B(-8,80,-3,minecraft:netherrack)
B(-8,81,-3,minecraft:netherrack)
B(-8,82,-3,minecraft:netherrack)
B(-8,83,-3,minecraft:netherrack)
B(-8,84,-3,minecraft:netherrack)
B(-8,85,-3,minecraft:netherrack)
B(-8,86,-3,minecraft:netherrack)
B(-8,87,-3,minecraft:netherrack)
B(-8,88,-3,minecraft:netherrack)
B(-8,89,-3,minecraft:netherrack)
B(-8,90,-3,minecraft:netherrack)
B(-8,20,-2,minecraft:netherrack)
B(-8,21,-2,minecraft:netherrack)
B(-8,22,-2,minecraft:netherrack)
B(-8,23,-2,minecraft:netherrack)
B(-8,24,-2,minecraft:netherrack)
B(-8,25,-2,minecraft:netherrack)
B(-8,26,-2,minecraft:netherrack)
B(-8,27,-2,minecraft:netherrack)
B(-8,28,-2,minecraft:netherrack)
B(-8,29,-2,minecraft:netherrack)
B(-8,30,-2,minecraft:netherrack)
B(-8,31,-2,minecraft:netherrack)
B(-8,32,-2,minecraft:netherrack)
B(-8,33,-2,minecraft:netherrack)
B(-8,34,-2,minecraft:netherrack)
B(-8,35,-2,minecraft:netherrack)
B(-8,36,-2,minecraft:netherrack)
B(-8,37,-2,minecraft:netherrack)
B(-8,38,-2,minecraft:netherrack)
B(-8,39,-2,minecraft:netherrack)
B(-8,40,-2,minecraft:netherrack)
B(-8,41,-2,minecraft:netherrack)
B(-8,42,-2,minecraft:netherrack)
B(-8,43,-2,minecraft:netherrack)
B(-8,44,-2,minecraft:netherrack)
B(-8,45,-2,minecraft:netherrack)
B(-8,46,-2,minecraft:netherrack)
B(-8,47,-2,minecraft:netherrack)
B(-8,48,-2,minecraft:netherrack)
B(-8,49,-2,minecraft:netherrack)
B(-8,50,-2,minecraft:netherrack)
B(-8,51,-2,minecraft:netherrack)
B(-8,52,-2,minecraft:netherrack)
B(-8,53,-2,minecraft:netherrack)
B(-8,54,-2,minecraft:netherrack)
B(-8,55,-2,minecraft:netherrack)
B(-8,56,-2,minecraft:netherrack)
B(-8,57,-2,minecraft:netherrack)
B(-8,58,-2,minecraft:netherrack)
B(-8,59,-2,minecraft:netherrack)
B(-8,60,-2,minecraft:netherrack)
B(-8,61,-2,minecraft:netherrack)
B(-8,62,-2,minecraft:netherrack)
B(-8,63,-2,minecraft:netherrack)
B(-8,64,-2,minecraft:netherrack)
B(-8,65,-2,minecraft:netherrack)
B(-8,66,-2,minecraft:netherrack)
B(-8,67,-2,minecraft:netherrack)
B(-8,68,-2,minecraft:netherrack)
B(-8,69,-2,minecraft:netherrack)
B(-8,70,-2,minecraft:netherrack)
B(-8,71,-2,minecraft:netherrack)
B(-8,72,-2,minecraft:netherrack)
B(-8,73,-2,minecraft:netherrack)
B(-8,74,-2,minecraft:netherrack)
B(-8,75,-2,minecraft:netherrack)
B(-8,76,-2,minecraft:netherrack)
B(-8,77,-2,minecraft:netherrack)
B(-8,78,-2,minecraft:netherrack)
B(-8,79,-2,minecraft:netherrack)
B(-8,80,-2,minecraft:netherrack)
B(-8,81,-2,minecraft:netherrack)
B(-8,82,-2,minecraft:netherrack)
B(-8,83,-2,minecraft:netherrack)
B(-8,84,-2,minecraft:netherrack)
B(-8,85,-2,minecraft:netherrack)
B(-8,86,-2,minecraft:netherrack)
B(-8,87,-2,minecraft:netherrack)
B(-8,88,-2,minecraft:netherrack)
B(-8,89,-2,minecraft:netherrack)
B(-8,90,-2,minecraft:netherrack)
B(-8,19,-1,minecraft:netherrack)
B(-8,20,-1,minecraft:netherrack)
B(-8,21,-1,minecraft:netherrack)
B(-8,22,-1,minecraft:netherrack)
B(-8,23,-1,minecraft:netherrack)
B(-8,24,-1,minecraft:netherrack)
B(-8,25,-1,minecraft:netherrack)
B(-8,26,-1,minecraft:netherrack)
B(-8,27,-1,minecraft:netherrack)
B(-8,28,-1,minecraft:netherrack)
B(-8,29,-1,minecraft:netherrack)
B(-8,30,-1,minecraft:netherrack)
B(-8,31,-1,minecraft:netherrack)
B(-8,32,-1,minecraft:netherrack)
B(-8,33,-1,minecraft:netherrack)
B(-8,34,-1,minecraft:netherrack)
B(-8,35,-1,minecraft:netherrack)
B(-8,36,-1,minecraft:netherrack)
B(-8,37,-1,minecraft:netherrack)
B(-8,38,-1,minecraft:netherrack)
B(-8,39,-1,minecraft:netherrack)
B(-8,40,-1,minecraft:netherrack)
B(-8,41,-1,minecraft:netherrack)
B(-8,42,-1,minecraft:netherrack)
B(-8,43,-1,minecraft:netherrack)
B(-8,44,-1,minecraft:netherrack)
B(-8,45,-1,minecraft:netherrack)
B(-8,46,-1,minecraft:netherrack)
B(-8,47,-1,minecraft:netherrack)
B(-8,48,-1,minecraft:netherrack)
B(-8,49,-1,minecraft:netherrack)
B(-8,50,-1,minecraft:netherrack)
B(-8,51,-1,minecraft:netherrack)
B(-8,52,-1,minecraft:netherrack)
B(-8,53,-1,minecraft:netherrack)
B(-8,54,-1,minecraft:netherrack)
B(-8,55,-1,minecraft:netherrack)
B(-8,56,-1,minecraft:netherrack)
B(-8,57,-1,minecraft:netherrack)
B(-8,58,-1,minecraft:netherrack)
B(-8,59,-1,minecraft:netherrack)
B(-8,60,-1,minecraft:netherrack)
B(-8,61,-1,minecraft:netherrack)
B(-8,62,-1,minecraft:netherrack)
B(-8,63,-1,minecraft:netherrack)
B(-8,64,-1,minecraft:netherrack)
B(-8,65,-1,minecraft:netherrack)
B(-8,66,-1,minecraft:netherrack)
B(-8,67,-1,minecraft:netherrack)
B(-8,68,-1,minecraft:netherrack)
B(-8,69,-1,minecraft:netherrack)
B(-8,70,-1,minecraft:netherrack)
B(-8,71,-1,minecraft:netherrack)
B(-8,72,-1,minecraft:netherrack)
B(-8,73,-1,minecraft:netherrack)
B(-8,74,-1,minecraft:netherrack)
B(-8,75,-1,minecraft:netherrack)
B(-8,76,-1,minecraft:netherrack)
B(-8,77,-1,minecraft:netherrack)
B(-8,78,-1,minecraft:netherrack)
B(-8,79,-1,minecraft:netherrack)
B(-8,80,-1,minecraft:netherrack)
B(-8,81,-1,minecraft:netherrack)
B(-8,82,-1,minecraft:netherrack)
B(-8,83,-1,minecraft:netherrack)
B(-8,84,-1,minecraft:netherrack)
B(-8,85,-1,minecraft:netherrack)
B(-8,86,-1,minecraft:netherrack)
B(-8,87,-1,minecraft:netherrack)
B(-8,88,-1,minecraft:netherrack)
B(-8,89,-1,minecraft:netherrack)
B(-8,90,-1,minecraft:netherrack)
B(-8,20,0,minecraft:netherrack)
B(-8,21,0,minecraft:netherrack)
B(-8,22,0,minecraft:netherrack)
B(-8,23,0,minecraft:netherrack)
B(-8,24,0,minecraft:netherrack)
B(-8,25,0,minecraft:netherrack)
B(-8,26,0,minecraft:netherrack)
B(-8,27,0,minecraft:netherrack)
B(-8,28,0,minecraft:netherrack)
B(-8,29,0,minecraft:netherrack)
B(-8,30,0,minecraft:netherrack)
B(-8,31,0,minecraft:netherrack)
B(-8,32,0,minecraft:netherrack)
B(-8,33,0,minecraft:netherrack)
B(-8,34,0,minecraft:netherrack)
B(-8,35,0,minecraft:netherrack)
B(-8,36,0,minecraft:netherrack)
B(-8,37,0,minecraft:netherrack)
B(-8,38,0,minecraft:netherrack)
B(-8,39,0,minecraft:netherrack)
B(-8,40,0,minecraft:netherrack)
B(-8,41,0,minecraft:netherrack)
B(-8,42,0,minecraft:netherrack)
B(-8,43,0,minecraft:netherrack)
B(-8,44,0,minecraft:netherrack)
B(-8,45,0,minecraft:netherrack)
B(-8,46,0,minecraft:netherrack)
B(-8,47,0,minecraft:netherrack)
B(-8,48,0,minecraft:netherrack)
B(-8,49,0,minecraft:netherrack)
B(-8,50,0,minecraft:netherrack)
B(-8,51,0,minecraft:netherrack)
B(-8,52,0,minecraft:netherrack)
B(-8,53,0,minecraft:netherrack)
B(-8,54,0,minecraft:netherrack)
B(-8,55,0,minecraft:netherrack)
B(-8,56,0,minecraft:netherrack)
B(-8,57,0,minecraft:netherrack)
B(-8,58,0,minecraft:netherrack)
B(-8,59,0,minecraft:netherrack)
B(-8,60,0,minecraft:netherrack)
B(-8,61,0,minecraft:netherrack)
B(-8,62,0,minecraft:netherrack)
B(-8,63,0,minecraft:netherrack)
B(-8,64,0,minecraft:netherrack)
B(-8,65,0,minecraft:netherrack)
B(-8,66,0,minecraft:netherrack)
B(-8,67,0,minecraft:netherrack)
B(-8,68,0,minecraft:netherrack)
B(-8,69,0,minecraft:netherrack)
B(-8,70,0,minecraft:netherrack)
B(-8,71,0,minecraft:netherrack)
B(-8,72,0,minecraft:netherrack)
B(-8,73,0,minecraft:netherrack)
B(-8,74,0,minecraft:netherrack)
B(-8,75,0,minecraft:netherrack)
B(-8,76,0,minecraft:netherrack)
B(-8,77,0,minecraft:netherrack)
B(-8,78,0,minecraft:netherrack)
B(-8,79,0,minecraft:netherrack)
B(-8,80,0,minecraft:netherrack)
B(-8,81,0,minecraft:netherrack)
B(-8,82,0,minecraft:netherrack)
B(-8,83,0,minecraft:netherrack)
B(-8,84,0,minecraft:netherrack)
B(-8,85,0,minecraft:netherrack)
B(-8,86,0,minecraft:netherrack)
B(-8,87,0,minecraft:netherrack)
B(-8,88,0,minecraft:netherrack)
B(-8,89,0,minecraft:netherrack)
B(-8,90,0,minecraft:blackstone)
B(-8,22,1,minecraft:netherrack)
B(-8,23,1,minecraft:netherrack)
B(-8,24,1,minecraft:netherrack)
B(-8,25,1,minecraft:netherrack)
B(-8,26,1,minecraft:netherrack)
B(-8,27,1,minecraft:netherrack)
B(-8,28,1,minecraft:netherrack)
B(-8,29,1,minecraft:netherrack)
B(-8,30,1,minecraft:netherrack)
B(-8,31,1,minecraft:netherrack)
B(-8,32,1,minecraft:netherrack)
B(-8,33,1,minecraft:netherrack)
B(-8,34,1,minecraft:netherrack)
B(-8,35,1,minecraft:netherrack)
B(-8,36,1,minecraft:netherrack)
B(-8,37,1,minecraft:netherrack)
B(-8,38,1,minecraft:netherrack)
B(-8,39,1,minecraft:netherrack)
B(-8,40,1,minecraft:netherrack)
B(-8,41,1,minecraft:netherrack)
B(-8,42,1,minecraft:netherrack)
B(-8,43,1,minecraft:netherrack)
B(-8,44,1,minecraft:netherrack)
B(-8,45,1,minecraft:netherrack)
B(-8,46,1,minecraft:netherrack)
B(-8,47,1,minecraft:netherrack)
B(-8,48,1,minecraft:netherrack)
B(-8,49,1,minecraft:netherrack)
B(-8,50,1,minecraft:netherrack)
B(-8,51,1,minecraft:netherrack)
B(-8,52,1,minecraft:netherrack)
B(-8,53,1,minecraft:netherrack)
B(-8,54,1,minecraft:netherrack)
B(-8,55,1,minecraft:netherrack)
B(-8,56,1,minecraft:netherrack)
B(-8,57,1,minecraft:netherrack)
B(-8,58,1,minecraft:netherrack)
B(-8,59,1,minecraft:netherrack)
B(-8,60,1,minecraft:netherrack)
B(-8,61,1,minecraft:netherrack)
B(-8,62,1,minecraft:netherrack)
B(-8,63,1,minecraft:netherrack)
B(-8,64,1,minecraft:netherrack)
B(-8,65,1,minecraft:netherrack)
B(-8,66,1,minecraft:netherrack)
B(-8,67,1,minecraft:netherrack)
B(-8,68,1,minecraft:netherrack)
B(-8,69,1,minecraft:netherrack)
B(-8,70,1,minecraft:netherrack)
B(-8,71,1,minecraft:netherrack)
B(-8,72,1,minecraft:netherrack)
B(-8,73,1,minecraft:netherrack)
B(-8,74,1,minecraft:netherrack)
B(-8,75,1,minecraft:netherrack)
B(-8,76,1,minecraft:netherrack)
B(-8,77,1,minecraft:netherrack)
B(-8,78,1,minecraft:netherrack)
B(-8,79,1,minecraft:netherrack)
B(-8,80,1,minecraft:netherrack)
B(-8,81,1,minecraft:netherrack)
B(-8,82,1,minecraft:netherrack)
B(-8,83,1,minecraft:netherrack)
B(-8,84,1,minecraft:netherrack)
B(-8,85,1,minecraft:netherrack)
B(-8,86,1,minecraft:netherrack)
B(-8,87,1,minecraft:netherrack)
B(-8,88,1,minecraft:netherrack)
B(-8,89,1,minecraft:netherrack)
B(-8,90,1,minecraft:netherrack)
B(-8,18,2,minecraft:netherrack)
B(-8,19,2,minecraft:netherrack)
B(-8,20,2,minecraft:netherrack)
B(-8,21,2,minecraft:netherrack)
B(-8,22,2,minecraft:netherrack)
B(-8,23,2,minecraft:netherrack)
B(-8,24,2,minecraft:netherrack)
B(-8,25,2,minecraft:netherrack)
B(-8,26,2,minecraft:netherrack)
B(-8,27,2,minecraft:netherrack)
B(-8,28,2,minecraft:netherrack)
B(-8,29,2,minecraft:netherrack)
B(-8,30,2,minecraft:netherrack)
B(-8,31,2,minecraft:netherrack)
B(-8,32,2,minecraft:netherrack)
B(-8,33,2,minecraft:netherrack)
B(-8,34,2,minecraft:netherrack)
B(-8,35,2,minecraft:netherrack)
B(-8,36,2,minecraft:netherrack)
B(-8,37,2,minecraft:netherrack)
B(-8,38,2,minecraft:netherrack)
B(-8,39,2,minecraft:netherrack)
B(-8,40,2,minecraft:netherrack)
B(-8,41,2,minecraft:netherrack)
B(-8,42,2,minecraft:netherrack)
B(-8,43,2,minecraft:netherrack)
B(-8,44,2,minecraft:netherrack)
B(-8,45,2,minecraft:netherrack)
B(-8,46,2,minecraft:netherrack)
B(-8,47,2,minecraft:netherrack)
B(-8,48,2,minecraft:netherrack)
B(-8,49,2,minecraft:netherrack)
B(-8,50,2,minecraft:netherrack)
B(-8,51,2,minecraft:netherrack)
B(-8,52,2,minecraft:netherrack)
B(-8,53,2,minecraft:netherrack)
B(-8,54,2,minecraft:netherrack)
B(-8,55,2,minecraft:netherrack)
B(-8,56,2,minecraft:netherrack)
B(-8,57,2,minecraft:netherrack)
B(-8,58,2,minecraft:netherrack)
B(-8,59,2,minecraft:netherrack)
B(-8,60,2,minecraft:netherrack)
B(-8,61,2,minecraft:netherrack)
B(-8,62,2,minecraft:netherrack)
B(-8,63,2,minecraft:netherrack)
B(-8,64,2,minecraft:netherrack)
B(-8,65,2,minecraft:netherrack)
B(-8,66,2,minecraft:netherrack)
B(-8,67,2,minecraft:netherrack)
B(-8,68,2,minecraft:netherrack)
B(-8,69,2,minecraft:netherrack)
B(-8,70,2,minecraft:netherrack)
B(-8,71,2,minecraft:netherrack)
B(-8,72,2,minecraft:netherrack)
B(-8,73,2,minecraft:netherrack)
B(-8,74,2,minecraft:netherrack)
B(-8,75,2,minecraft:netherrack)
B(-8,76,2,minecraft:netherrack)
B(-8,77,2,minecraft:netherrack)
B(-8,78,2,minecraft:netherrack)
B(-8,79,2,minecraft:netherrack)
B(-8,80,2,minecraft:netherrack)
B(-8,81,2,minecraft:netherrack)
B(-8,82,2,minecraft:netherrack)
B(-8,83,2,minecraft:netherrack)
B(-8,84,2,minecraft:netherrack)
B(-8,85,2,minecraft:netherrack)
B(-8,86,2,minecraft:netherrack)
B(-8,87,2,minecraft:netherrack)
B(-8,88,2,minecraft:netherrack)
B(-8,89,2,minecraft:netherrack)
B(-8,90,2,minecraft:netherrack)
B(-8,18,3,minecraft:netherrack)
B(-8,19,3,minecraft:netherrack)
B(-8,20,3,minecraft:netherrack)
B(-8,21,3,minecraft:netherrack)
B(-8,22,3,minecraft:netherrack)
B(-8,23,3,minecraft:netherrack)
B(-8,24,3,minecraft:netherrack)
B(-8,25,3,minecraft:netherrack)
B(-8,26,3,minecraft:netherrack)
B(-8,27,3,minecraft:netherrack)
B(-8,28,3,minecraft:netherrack)
B(-8,29,3,minecraft:netherrack)
B(-8,30,3,minecraft:netherrack)
B(-8,31,3,minecraft:netherrack)
B(-8,32,3,minecraft:netherrack)
B(-8,33,3,minecraft:netherrack)
B(-8,34,3,minecraft:netherrack)
B(-8,35,3,minecraft:netherrack)
B(-8,36,3,minecraft:netherrack)
B(-8,37,3,minecraft:netherrack)
B(-8,38,3,minecraft:netherrack)
B(-8,39,3,minecraft:netherrack)
B(-8,40,3,minecraft:netherrack)
B(-8,41,3,minecraft:netherrack)
B(-8,42,3,minecraft:netherrack)
B(-8,43,3,minecraft:netherrack)
B(-8,44,3,minecraft:netherrack)
B(-8,45,3,minecraft:netherrack)
B(-8,46,3,minecraft:netherrack)
B(-8,47,3,minecraft:netherrack)
B(-8,48,3,minecraft:netherrack)
B(-8,49,3,minecraft:netherrack)
B(-8,50,3,minecraft:netherrack)
B(-8,51,3,minecraft:netherrack)
B(-8,52,3,minecraft:netherrack)
B(-8,53,3,minecraft:netherrack)
B(-8,54,3,minecraft:netherrack)
B(-8,55,3,minecraft:netherrack)
B(-8,56,3,minecraft:netherrack)
B(-8,57,3,minecraft:netherrack)
B(-8,58,3,minecraft:netherrack)
B(-8,59,3,minecraft:netherrack)
B(-8,60,3,minecraft:netherrack)
B(-8,61,3,minecraft:netherrack)
B(-8,62,3,minecraft:netherrack)
B(-8,63,3,minecraft:netherrack)
B(-8,64,3,minecraft:netherrack)
B(-8,65,3,minecraft:netherrack)
B(-8,66,3,minecraft:netherrack)
B(-8,67,3,minecraft:netherrack)
B(-8,68,3,minecraft:netherrack)
B(-8,69,3,minecraft:netherrack)
B(-8,70,3,minecraft:netherrack)
B(-8,71,3,minecraft:netherrack)
B(-8,72,3,minecraft:netherrack)
B(-8,73,3,minecraft:netherrack)
B(-8,74,3,minecraft:netherrack)
B(-8,75,3,minecraft:netherrack)
B(-8,76,3,minecraft:netherrack)
B(-8,77,3,minecraft:netherrack)
B(-8,78,3,minecraft:netherrack)
B(-8,79,3,minecraft:netherrack)
B(-8,80,3,minecraft:netherrack)
B(-8,81,3,minecraft:netherrack)
B(-8,82,3,minecraft:netherrack)
B(-8,83,3,minecraft:netherrack)
B(-8,84,3,minecraft:netherrack)
B(-8,85,3,minecraft:netherrack)
B(-8,86,3,minecraft:netherrack)
B(-8,87,3,minecraft:netherrack)
B(-8,88,3,minecraft:netherrack)
B(-8,89,3,minecraft:netherrack)
B(-8,90,3,minecraft:netherrack)
B(-8,19,4,minecraft:netherrack)
B(-8,20,4,minecraft:netherrack)
B(-8,21,4,minecraft:netherrack)
B(-8,22,4,minecraft:netherrack)
B(-8,23,4,minecraft:netherrack)
B(-8,24,4,minecraft:netherrack)
B(-8,25,4,minecraft:netherrack)
B(-8,26,4,minecraft:netherrack)
B(-8,27,4,minecraft:netherrack)
B(-8,28,4,minecraft:netherrack)
B(-8,29,4,minecraft:netherrack)
B(-8,30,4,minecraft:netherrack)
B(-8,31,4,minecraft:netherrack)
B(-8,32,4,minecraft:netherrack)
B(-8,33,4,minecraft:netherrack)
B(-8,34,4,minecraft:netherrack)
B(-8,35,4,minecraft:netherrack)
B(-8,36,4,minecraft:netherrack)
B(-8,37,4,minecraft:netherrack)
B(-8,38,4,minecraft:netherrack)
B(-8,39,4,minecraft:netherrack)
B(-8,40,4,minecraft:netherrack)
B(-8,41,4,minecraft:netherrack)
B(-8,42,4,minecraft:netherrack)
B(-8,43,4,minecraft:netherrack)
B(-8,44,4,minecraft:netherrack)
B(-8,45,4,minecraft:netherrack)
B(-8,46,4,minecraft:netherrack)
B(-8,47,4,minecraft:netherrack)
B(-8,48,4,minecraft:netherrack)
B(-8,49,4,minecraft:netherrack)
B(-8,50,4,minecraft:netherrack)
B(-8,51,4,minecraft:netherrack)
B(-8,52,4,minecraft:netherrack)
B(-8,53,4,minecraft:netherrack)
B(-8,54,4,minecraft:netherrack)
B(-8,55,4,minecraft:netherrack)
B(-8,56,4,minecraft:netherrack)
B(-8,57,4,minecraft:netherrack)
B(-8,58,4,minecraft:netherrack)
B(-8,59,4,minecraft:netherrack)
B(-8,60,4,minecraft:netherrack)
B(-8,61,4,minecraft:netherrack)
B(-8,62,4,minecraft:netherrack)
B(-8,63,4,minecraft:netherrack)
B(-8,64,4,minecraft:netherrack)
B(-8,65,4,minecraft:netherrack)
B(-8,66,4,minecraft:netherrack)
B(-8,67,4,minecraft:netherrack)
B(-8,68,4,minecraft:netherrack)
B(-8,69,4,minecraft:netherrack)
B(-8,70,4,minecraft:netherrack)
B(-8,71,4,minecraft:netherrack)
B(-8,72,4,minecraft:netherrack)
B(-8,73,4,minecraft:netherrack)
B(-8,74,4,minecraft:netherrack)
B(-8,75,4,minecraft:netherrack)
B(-8,76,4,minecraft:netherrack)
B(-8,77,4,minecraft:netherrack)
B(-8,78,4,minecraft:netherrack)
B(-8,79,4,minecraft:netherrack)
B(-8,80,4,minecraft:netherrack)
B(-8,81,4,minecraft:netherrack)
B(-8,82,4,minecraft:netherrack)
B(-8,83,4,minecraft:netherrack)
B(-8,84,4,minecraft:netherrack)
B(-8,85,4,minecraft:netherrack)
B(-8,86,4,minecraft:netherrack)
B(-8,87,4,minecraft:netherrack)
B(-8,88,4,minecraft:netherrack)
B(-8,89,4,minecraft:netherrack)
B(-8,90,4,minecraft:netherrack)
B(-8,19,5,minecraft:netherrack)
B(-8,20,5,minecraft:netherrack)
B(-8,21,5,minecraft:netherrack)
B(-8,22,5,minecraft:netherrack)
B(-8,23,5,minecraft:netherrack)
B(-8,24,5,minecraft:netherrack)
B(-8,25,5,minecraft:netherrack)
B(-8,26,5,minecraft:netherrack)
B(-8,27,5,minecraft:netherrack)
B(-8,28,5,minecraft:netherrack)
B(-8,29,5,minecraft:netherrack)
B(-8,30,5,minecraft:netherrack)
B(-8,31,5,minecraft:netherrack)
B(-8,32,5,minecraft:netherrack)
B(-8,33,5,minecraft:netherrack)
B(-8,34,5,minecraft:netherrack)
B(-8,35,5,minecraft:netherrack)
B(-8,36,5,minecraft:netherrack)
B(-8,37,5,minecraft:netherrack)
B(-8,38,5,minecraft:netherrack)
B(-8,39,5,minecraft:netherrack)
B(-8,40,5,minecraft:netherrack)
B(-8,41,5,minecraft:netherrack)
B(-8,42,5,minecraft:netherrack)
B(-8,43,5,minecraft:netherrack)
B(-8,44,5,minecraft:netherrack)
B(-8,45,5,minecraft:netherrack)
B(-8,46,5,minecraft:netherrack)
B(-8,47,5,minecraft:netherrack)
B(-8,48,5,minecraft:netherrack)
B(-8,49,5,minecraft:netherrack)
B(-8,50,5,minecraft:netherrack)
B(-8,51,5,minecraft:netherrack)
B(-8,52,5,minecraft:netherrack)
B(-8,53,5,minecraft:netherrack)
B(-8,54,5,minecraft:netherrack)
B(-8,55,5,minecraft:netherrack)
B(-8,56,5,minecraft:netherrack)
B(-8,57,5,minecraft:netherrack)
B(-8,58,5,minecraft:netherrack)
B(-8,59,5,minecraft:netherrack)
B(-8,60,5,minecraft:netherrack)
B(-8,61,5,minecraft:netherrack)
B(-8,62,5,minecraft:netherrack)
B(-8,63,5,minecraft:netherrack)
B(-8,64,5,minecraft:netherrack)
B(-8,65,5,minecraft:netherrack)
B(-8,66,5,minecraft:netherrack)
B(-8,67,5,minecraft:netherrack)
B(-8,68,5,minecraft:netherrack)
B(-8,69,5,minecraft:netherrack)
B(-8,70,5,minecraft:netherrack)
B(-8,71,5,minecraft:netherrack)
B(-8,72,5,minecraft:netherrack)
B(-8,73,5,minecraft:netherrack)
B(-8,74,5,minecraft:netherrack)
B(-8,75,5,minecraft:netherrack)
B(-8,76,5,minecraft:netherrack)
B(-8,77,5,minecraft:netherrack)
B(-8,78,5,minecraft:netherrack)
B(-8,79,5,minecraft:netherrack)
B(-8,80,5,minecraft:netherrack)
B(-8,81,5,minecraft:netherrack)
B(-8,82,5,minecraft:netherrack)
B(-8,83,5,minecraft:netherrack)
B(-8,84,5,minecraft:netherrack)
B(-8,85,5,minecraft:netherrack)
B(-8,86,5,minecraft:netherrack)
B(-8,87,5,minecraft:netherrack)
B(-8,88,5,minecraft:netherrack)
B(-8,89,5,minecraft:netherrack)
B(-8,90,5,minecraft:netherrack)
B(-8,20,6,minecraft:netherrack)
B(-8,21,6,minecraft:netherrack)
B(-8,22,6,minecraft:netherrack)
B(-8,23,6,minecraft:netherrack)
B(-8,24,6,minecraft:netherrack)
B(-8,25,6,minecraft:netherrack)
B(-8,26,6,minecraft:netherrack)
B(-8,27,6,minecraft:netherrack)
B(-8,28,6,minecraft:netherrack)
B(-8,29,6,minecraft:netherrack)
B(-8,30,6,minecraft:netherrack)
B(-8,31,6,minecraft:netherrack)
B(-8,32,6,minecraft:netherrack)
B(-8,33,6,minecraft:netherrack)
B(-8,34,6,minecraft:netherrack)
B(-8,35,6,minecraft:netherrack)
B(-8,36,6,minecraft:netherrack)
B(-8,37,6,minecraft:netherrack)
B(-8,38,6,minecraft:netherrack)
B(-8,39,6,minecraft:netherrack)
B(-8,40,6,minecraft:netherrack)
B(-8,41,6,minecraft:netherrack)
B(-8,42,6,minecraft:netherrack)
B(-8,43,6,minecraft:netherrack)
B(-8,44,6,minecraft:netherrack)
B(-8,45,6,minecraft:netherrack)
B(-8,46,6,minecraft:netherrack)
B(-8,47,6,minecraft:netherrack)
B(-8,48,6,minecraft:netherrack)
B(-8,49,6,minecraft:netherrack)
B(-8,50,6,minecraft:netherrack)
B(-8,51,6,minecraft:netherrack)
B(-8,52,6,minecraft:netherrack)
B(-8,53,6,minecraft:netherrack)
B(-8,54,6,minecraft:netherrack)
B(-8,55,6,minecraft:netherrack)
B(-8,56,6,minecraft:netherrack)
B(-8,57,6,minecraft:netherrack)
B(-8,58,6,minecraft:netherrack)
B(-8,59,6,minecraft:netherrack)
B(-8,60,6,minecraft:netherrack)
B(-8,61,6,minecraft:netherrack)
B(-8,62,6,minecraft:netherrack)
B(-8,63,6,minecraft:netherrack)
B(-8,64,6,minecraft:netherrack)
B(-8,65,6,minecraft:netherrack)
B(-8,66,6,minecraft:netherrack)
B(-8,67,6,minecraft:netherrack)
B(-8,68,6,minecraft:netherrack)
B(-8,69,6,minecraft:netherrack)
B(-8,70,6,minecraft:netherrack)
B(-8,71,6,minecraft:netherrack)
B(-8,72,6,minecraft:netherrack)
B(-8,73,6,minecraft:netherrack)
B(-8,74,6,minecraft:netherrack)
B(-8,75,6,minecraft:netherrack)
B(-8,76,6,minecraft:netherrack)
B(-8,77,6,minecraft:netherrack)
B(-8,78,6,minecraft:netherrack)
B(-8,79,6,minecraft:netherrack)
B(-8,80,6,minecraft:netherrack)
B(-8,81,6,minecraft:netherrack)
B(-8,82,6,minecraft:netherrack)
B(-8,83,6,minecraft:netherrack)
B(-8,84,6,minecraft:netherrack)
B(-8,85,6,minecraft:netherrack)
B(-8,86,6,minecraft:netherrack)
B(-8,87,6,minecraft:netherrack)
B(-8,88,6,minecraft:netherrack)
B(-8,89,6,minecraft:netherrack)
B(-8,90,6,minecraft:netherrack)
B(-8,22,7,minecraft:netherrack)
B(-8,23,7,minecraft:netherrack)
B(-8,24,7,minecraft:netherrack)
B(-8,25,7,minecraft:netherrack)
B(-8,26,7,minecraft:netherrack)
B(-8,27,7,minecraft:netherrack)
B(-8,28,7,minecraft:netherrack)
B(-8,29,7,minecraft:netherrack)
B(-8,30,7,minecraft:netherrack)
B(-8,31,7,minecraft:netherrack)
B(-8,32,7,minecraft:netherrack)
B(-8,33,7,minecraft:netherrack)
B(-8,34,7,minecraft:netherrack)
B(-8,35,7,minecraft:netherrack)
B(-8,36,7,minecraft:netherrack)
B(-8,37,7,minecraft:netherrack)
B(-8,38,7,minecraft:netherrack)
B(-8,39,7,minecraft:netherrack)
B(-8,40,7,minecraft:netherrack)
B(-8,41,7,minecraft:netherrack)
B(-8,42,7,minecraft:netherrack)
B(-8,43,7,minecraft:netherrack)
B(-8,44,7,minecraft:netherrack)
B(-8,45,7,minecraft:netherrack)
B(-8,46,7,minecraft:netherrack)
B(-8,47,7,minecraft:netherrack)
B(-8,48,7,minecraft:netherrack)
B(-8,49,7,minecraft:netherrack)
B(-8,50,7,minecraft:netherrack)
B(-8,51,7,minecraft:netherrack)
B(-8,52,7,minecraft:netherrack)
B(-8,53,7,minecraft:netherrack)
B(-8,54,7,minecraft:netherrack)
B(-8,55,7,minecraft:netherrack)
B(-8,56,7,minecraft:netherrack)
B(-8,57,7,minecraft:netherrack)
B(-8,58,7,minecraft:netherrack)
B(-8,59,7,minecraft:netherrack)
B(-8,60,7,minecraft:netherrack)
B(-8,61,7,minecraft:netherrack)
B(-8,62,7,minecraft:netherrack)
B(-8,63,7,minecraft:netherrack)
B(-8,64,7,minecraft:netherrack)
B(-8,65,7,minecraft:netherrack)
B(-8,66,7,minecraft:netherrack)
B(-8,67,7,minecraft:netherrack)
B(-8,68,7,minecraft:netherrack)
B(-8,69,7,minecraft:netherrack)
B(-8,70,7,minecraft:netherrack)
B(-8,71,7,minecraft:netherrack)
B(-8,72,7,minecraft:netherrack)
B(-8,73,7,minecraft:netherrack)
B(-8,74,7,minecraft:netherrack)
B(-8,75,7,minecraft:netherrack)
B(-8,76,7,minecraft:netherrack)
B(-8,77,7,minecraft:netherrack)
B(-8,78,7,minecraft:netherrack)
B(-8,79,7,minecraft:netherrack)
B(-8,80,7,minecraft:netherrack)
B(-8,81,7,minecraft:netherrack)
B(-8,82,7,minecraft:netherrack)
B(-8,83,7,minecraft:netherrack)
B(-8,84,7,minecraft:netherrack)
B(-8,85,7,minecraft:netherrack)
B(-8,86,7,minecraft:netherrack)
B(-8,87,7,minecraft:netherrack)
B(-8,88,7,minecraft:netherrack)
B(-8,89,7,minecraft:netherrack)
B(-8,90,7,minecraft:netherrack)
B(-8,26,8,minecraft:netherrack)
B(-8,27,8,minecraft:netherrack)
B(-8,28,8,minecraft:netherrack)
B(-8,29,8,minecraft:netherrack)
B(-8,30,8,minecraft:netherrack)
B(-8,31,8,minecraft:netherrack)
B(-8,32,8,minecraft:netherrack)
B(-8,33,8,minecraft:netherrack)
B(-8,34,8,minecraft:netherrack)
B(-8,35,8,minecraft:netherrack)
B(-8,36,8,minecraft:netherrack)
B(-8,37,8,minecraft:netherrack)
B(-8,38,8,minecraft:netherrack)
B(-8,39,8,minecraft:netherrack)
B(-8,40,8,minecraft:netherrack)
B(-8,41,8,minecraft:netherrack)
B(-8,42,8,minecraft:netherrack)
B(-8,43,8,minecraft:netherrack)
B(-8,44,8,minecraft:netherrack)
B(-8,45,8,minecraft:netherrack)
B(-8,46,8,minecraft:netherrack)
B(-8,47,8,minecraft:netherrack)
B(-8,48,8,minecraft:netherrack)
B(-8,49,8,minecraft:netherrack)
B(-8,50,8,minecraft:netherrack)
B(-8,51,8,minecraft:netherrack)
B(-8,52,8,minecraft:netherrack)
B(-8,53,8,minecraft:netherrack)
B(-8,54,8,minecraft:netherrack)
B(-8,55,8,minecraft:netherrack)
B(-8,56,8,minecraft:netherrack)
B(-8,57,8,minecraft:netherrack)
B(-8,58,8,minecraft:netherrack)
B(-8,59,8,minecraft:netherrack)
B(-8,60,8,minecraft:netherrack)
B(-8,61,8,minecraft:netherrack)
B(-8,62,8,minecraft:netherrack)
B(-8,63,8,minecraft:netherrack)
B(-8,64,8,minecraft:netherrack)
B(-8,65,8,minecraft:netherrack)
B(-8,66,8,minecraft:netherrack)
B(-8,67,8,minecraft:netherrack)
B(-8,68,8,minecraft:netherrack)
B(-8,69,8,minecraft:netherrack)
B(-8,70,8,minecraft:netherrack)
B(-8,71,8,minecraft:netherrack)
B(-8,72,8,minecraft:netherrack)
B(-8,73,8,minecraft:netherrack)
B(-8,74,8,minecraft:netherrack)
B(-8,75,8,minecraft:netherrack)
B(-8,76,8,minecraft:netherrack)
B(-8,77,8,minecraft:netherrack)
B(-8,78,8,minecraft:netherrack)
B(-8,79,8,minecraft:netherrack)
B(-8,80,8,minecraft:netherrack)
B(-8,81,8,minecraft:netherrack)
B(-8,82,8,minecraft:netherrack)
B(-8,83,8,minecraft:netherrack)
B(-8,84,8,minecraft:netherrack)
B(-8,85,8,minecraft:netherrack)
B(-8,86,8,minecraft:netherrack)
B(-8,87,8,minecraft:netherrack)
B(-8,88,8,minecraft:netherrack)
B(-8,89,8,minecraft:netherrack)
B(-8,90,8,minecraft:blackstone)
B(-7,27,-7,minecraft:netherrack)
B(-7,28,-7,minecraft:netherrack)
B(-7,29,-7,minecraft:netherrack)
B(-7,30,-7,minecraft:netherrack)
B(-7,31,-7,minecraft:netherrack)
B(-7,32,-7,minecraft:netherrack)
B(-7,33,-7,minecraft:netherrack)
B(-7,34,-7,minecraft:netherrack)
B(-7,35,-7,minecraft:netherrack)
B(-7,36,-7,minecraft:netherrack)
B(-7,37,-7,minecraft:netherrack)
B(-7,38,-7,minecraft:netherrack)
B(-7,39,-7,minecraft:netherrack)
B(-7,40,-7,minecraft:netherrack)
B(-7,41,-7,minecraft:netherrack)
B(-7,42,-7,minecraft:netherrack)
B(-7,43,-7,minecraft:netherrack)
B(-7,44,-7,minecraft:netherrack)
B(-7,45,-7,minecraft:netherrack)
B(-7,46,-7,minecraft:netherrack)
B(-7,47,-7,minecraft:netherrack)
B(-7,48,-7,minecraft:netherrack)
B(-7,49,-7,minecraft:netherrack)
B(-7,50,-7,minecraft:netherrack)
B(-7,51,-7,minecraft:netherrack)
B(-7,52,-7,minecraft:netherrack)
B(-7,53,-7,minecraft:netherrack)
B(-7,54,-7,minecraft:netherrack)
B(-7,55,-7,minecraft:netherrack)
B(-7,56,-7,minecraft:netherrack)
B(-7,57,-7,minecraft:netherrack)
B(-7,58,-7,minecraft:netherrack)
B(-7,59,-7,minecraft:netherrack)
B(-7,60,-7,minecraft:netherrack)
B(-7,61,-7,minecraft:netherrack)
B(-7,62,-7,minecraft:netherrack)
B(-7,63,-7,minecraft:netherrack)
B(-7,64,-7,minecraft:netherrack)
B(-7,65,-7,minecraft:netherrack)
B(-7,66,-7,minecraft:netherrack)
B(-7,67,-7,minecraft:netherrack)
B(-7,68,-7,minecraft:netherrack)
B(-7,69,-7,minecraft:netherrack)
B(-7,70,-7,minecraft:netherrack)
B(-7,71,-7,minecraft:netherrack)
B(-7,72,-7,minecraft:netherrack)
B(-7,73,-7,minecraft:netherrack)
B(-7,74,-7,minecraft:netherrack)
B(-7,75,-7,minecraft:netherrack)
B(-7,76,-7,minecraft:netherrack)
B(-7,77,-7,minecraft:netherrack)
B(-7,78,-7,minecraft:netherrack)
B(-7,79,-7,minecraft:netherrack)
B(-7,80,-7,minecraft:netherrack)
B(-7,81,-7,minecraft:netherrack)
B(-7,82,-7,minecraft:netherrack)
B(-7,83,-7,minecraft:netherrack)
B(-7,84,-7,minecraft:netherrack)
B(-7,85,-7,minecraft:netherrack)
B(-7,86,-7,minecraft:netherrack)
B(-7,87,-7,minecraft:netherrack)
B(-7,88,-7,minecraft:netherrack)
B(-7,89,-7,minecraft:netherrack)
B(-7,90,-7,minecraft:netherrack)
B(-7,27,-6,minecraft:netherrack)
B(-7,28,-6,minecraft:netherrack)
B(-7,29,-6,minecraft:netherrack)
B(-7,30,-6,minecraft:netherrack)
B(-7,31,-6,minecraft:netherrack)
B(-7,32,-6,minecraft:netherrack)
B(-7,33,-6,minecraft:netherrack)
B(-7,34,-6,minecraft:netherrack)
B(-7,35,-6,minecraft:netherrack)
B(-7,36,-6,minecraft:netherrack)
B(-7,37,-6,minecraft:netherrack)
B(-7,38,-6,minecraft:netherrack)
B(-7,39,-6,minecraft:netherrack)
B(-7,40,-6,minecraft:netherrack)
B(-7,41,-6,minecraft:netherrack)
B(-7,42,-6,minecraft:netherrack)
B(-7,43,-6,minecraft:netherrack)
B(-7,44,-6,minecraft:netherrack)
B(-7,45,-6,minecraft:netherrack)
B(-7,46,-6,minecraft:netherrack)
B(-7,47,-6,minecraft:netherrack)
B(-7,48,-6,minecraft:netherrack)
B(-7,49,-6,minecraft:netherrack)
B(-7,50,-6,minecraft:netherrack)
B(-7,51,-6,minecraft:netherrack)
B(-7,52,-6,minecraft:netherrack)
B(-7,53,-6,minecraft:netherrack)
B(-7,54,-6,minecraft:netherrack)
B(-7,55,-6,minecraft:netherrack)
B(-7,56,-6,minecraft:netherrack)
B(-7,57,-6,minecraft:netherrack)
B(-7,58,-6,minecraft:netherrack)
B(-7,59,-6,minecraft:netherrack)
B(-7,60,-6,minecraft:netherrack)
B(-7,61,-6,minecraft:netherrack)
B(-7,62,-6,minecraft:netherrack)
B(-7,63,-6,minecraft:netherrack)
B(-7,64,-6,minecraft:netherrack)
B(-7,65,-6,minecraft:netherrack)
B(-7,66,-6,minecraft:netherrack)
B(-7,67,-6,minecraft:netherrack)
B(-7,68,-6,minecraft:netherrack)
B(-7,69,-6,minecraft:netherrack)
B(-7,70,-6,minecraft:netherrack)
B(-7,71,-6,minecraft:netherrack)
B(-7,72,-6,minecraft:netherrack)
B(-7,73,-6,minecraft:netherrack)
B(-7,74,-6,minecraft:netherrack)
B(-7,75,-6,minecraft:netherrack)
B(-7,76,-6,minecraft:netherrack)
B(-7,77,-6,minecraft:netherrack)
B(-7,78,-6,minecraft:netherrack)
B(-7,79,-6,minecraft:netherrack)
B(-7,80,-6,minecraft:netherrack)
B(-7,81,-6,minecraft:netherrack)
B(-7,82,-6,minecraft:netherrack)
B(-7,83,-6,minecraft:netherrack)
B(-7,84,-6,minecraft:netherrack)
B(-7,85,-6,minecraft:netherrack)
B(-7,86,-6,minecraft:netherrack)
B(-7,87,-6,minecraft:netherrack)
B(-7,88,-6,minecraft:netherrack)
B(-7,89,-6,minecraft:netherrack)
B(-7,90,-6,minecraft:netherrack)
B(-7,27,-5,minecraft:netherrack)
B(-7,28,-5,minecraft:netherrack)
B(-7,29,-5,minecraft:netherrack)
B(-7,30,-5,minecraft:netherrack)
B(-7,31,-5,minecraft:netherrack)
B(-7,32,-5,minecraft:netherrack)
B(-7,33,-5,minecraft:netherrack)
B(-7,34,-5,minecraft:netherrack)
B(-7,35,-5,minecraft:netherrack)
B(-7,36,-5,minecraft:netherrack)
B(-7,37,-5,minecraft:netherrack)
B(-7,38,-5,minecraft:netherrack)
B(-7,39,-5,minecraft:netherrack)
B(-7,40,-5,minecraft:netherrack)
B(-7,41,-5,minecraft:netherrack)
B(-7,42,-5,minecraft:netherrack)
B(-7,43,-5,minecraft:netherrack)
B(-7,44,-5,minecraft:netherrack)
B(-7,45,-5,minecraft:netherrack)
B(-7,46,-5,minecraft:netherrack)
B(-7,47,-5,minecraft:netherrack)
B(-7,48,-5,minecraft:netherrack)
B(-7,49,-5,minecraft:netherrack)
B(-7,50,-5,minecraft:netherrack)
B(-7,51,-5,minecraft:netherrack)
B(-7,52,-5,minecraft:netherrack)
B(-7,53,-5,minecraft:netherrack)
B(-7,54,-5,minecraft:netherrack)
B(-7,55,-5,minecraft:netherrack)
B(-7,56,-5,minecraft:netherrack)
B(-7,57,-5,minecraft:netherrack)
B(-7,58,-5,minecraft:netherrack)
B(-7,59,-5,minecraft:netherrack)
B(-7,60,-5,minecraft:netherrack)
B(-7,61,-5,minecraft:netherrack)
B(-7,62,-5,minecraft:netherrack)
B(-7,63,-5,minecraft:netherrack)
B(-7,64,-5,minecraft:netherrack)
B(-7,65,-5,minecraft:netherrack)
B(-7,66,-5,minecraft:netherrack)
B(-7,67,-5,minecraft:netherrack)
B(-7,68,-5,minecraft:netherrack)
B(-7,69,-5,minecraft:netherrack)
B(-7,70,-5,minecraft:netherrack)
B(-7,71,-5,minecraft:netherrack)
B(-7,72,-5,minecraft:netherrack)
B(-7,73,-5,minecraft:netherrack)
B(-7,74,-5,minecraft:netherrack)
B(-7,75,-5,minecraft:netherrack)
B(-7,76,-5,minecraft:netherrack)
B(-7,77,-5,minecraft:netherrack)
B(-7,78,-5,minecraft:netherrack)
B(-7,79,-5,minecraft:netherrack)
B(-7,80,-5,minecraft:netherrack)
B(-7,81,-5,minecraft:netherrack)
B(-7,82,-5,minecraft:netherrack)
B(-7,83,-5,minecraft:netherrack)
B(-7,84,-5,minecraft:netherrack)
B(-7,85,-5,minecraft:netherrack)
B(-7,86,-5,minecraft:netherrack)
B(-7,87,-5,minecraft:netherrack)
B(-7,88,-5,minecraft:netherrack)
B(-7,89,-5,minecraft:netherrack)
B(-7,90,-5,minecraft:netherrack)
B(-7,28,-4,minecraft:netherrack)
B(-7,29,-4,minecraft:netherrack)
B(-7,30,-4,minecraft:netherrack)
B(-7,31,-4,minecraft:netherrack)
B(-7,32,-4,minecraft:netherrack)
B(-7,33,-4,minecraft:netherrack)
B(-7,34,-4,minecraft:netherrack)
B(-7,35,-4,minecraft:netherrack)
B(-7,36,-4,minecraft:netherrack)
B(-7,37,-4,minecraft:netherrack)
B(-7,38,-4,minecraft:netherrack)
B(-7,39,-4,minecraft:netherrack)
B(-7,40,-4,minecraft:netherrack)
B(-7,41,-4,minecraft:netherrack)
B(-7,42,-4,minecraft:netherrack)
B(-7,43,-4,minecraft:netherrack)
B(-7,44,-4,minecraft:netherrack)
B(-7,45,-4,minecraft:netherrack)
B(-7,46,-4,minecraft:netherrack)
B(-7,47,-4,minecraft:netherrack)
B(-7,48,-4,minecraft:netherrack)
B(-7,49,-4,minecraft:netherrack)
B(-7,50,-4,minecraft:netherrack)
B(-7,51,-4,minecraft:netherrack)
B(-7,52,-4,minecraft:netherrack)
B(-7,53,-4,minecraft:netherrack)
B(-7,54,-4,minecraft:netherrack)
B(-7,55,-4,minecraft:netherrack)
B(-7,56,-4,minecraft:netherrack)
B(-7,57,-4,minecraft:netherrack)
B(-7,58,-4,minecraft:netherrack)
B(-7,59,-4,minecraft:netherrack)
B(-7,60,-4,minecraft:netherrack)
B(-7,61,-4,minecraft:netherrack)
B(-7,62,-4,minecraft:netherrack)
B(-7,63,-4,minecraft:netherrack)
B(-7,64,-4,minecraft:netherrack)
B(-7,65,-4,minecraft:netherrack)
B(-7,66,-4,minecraft:netherrack)
B(-7,67,-4,minecraft:netherrack)
B(-7,68,-4,minecraft:netherrack)
B(-7,69,-4,minecraft:netherrack)
B(-7,70,-4,minecraft:netherrack)
B(-7,71,-4,minecraft:netherrack)
B(-7,72,-4,minecraft:netherrack)
B(-7,73,-4,minecraft:netherrack)
B(-7,74,-4,minecraft:netherrack)
B(-7,75,-4,minecraft:netherrack)
B(-7,76,-4,minecraft:netherrack)
B(-7,77,-4,minecraft:netherrack)
B(-7,78,-4,minecraft:netherrack)
B(-7,79,-4,minecraft:netherrack)
B(-7,80,-4,minecraft:netherrack)
B(-7,81,-4,minecraft:netherrack)
B(-7,82,-4,minecraft:netherrack)
B(-7,83,-4,minecraft:netherrack)
B(-7,84,-4,minecraft:netherrack)
B(-7,85,-4,minecraft:netherrack)
B(-7,86,-4,minecraft:netherrack)
B(-7,87,-4,minecraft:netherrack)
B(-7,88,-4,minecraft:netherrack)
B(-7,89,-4,minecraft:netherrack)
B(-7,90,-4,minecraft:netherrack)
B(-7,28,-3,minecraft:netherrack)
B(-7,29,-3,minecraft:netherrack)
B(-7,30,-3,minecraft:netherrack)
B(-7,31,-3,minecraft:netherrack)
B(-7,32,-3,minecraft:netherrack)
B(-7,33,-3,minecraft:netherrack)
B(-7,34,-3,minecraft:netherrack)
B(-7,35,-3,minecraft:netherrack)
B(-7,36,-3,minecraft:netherrack)
B(-7,37,-3,minecraft:netherrack)
B(-7,38,-3,minecraft:netherrack)
B(-7,39,-3,minecraft:netherrack)
B(-7,40,-3,minecraft:netherrack)
B(-7,41,-3,minecraft:netherrack)
B(-7,42,-3,minecraft:netherrack)
B(-7,43,-3,minecraft:netherrack)
B(-7,44,-3,minecraft:netherrack)
B(-7,45,-3,minecraft:netherrack)
B(-7,46,-3,minecraft:netherrack)
B(-7,47,-3,minecraft:netherrack)
B(-7,48,-3,minecraft:netherrack)
B(-7,49,-3,minecraft:netherrack)
B(-7,50,-3,minecraft:netherrack)
B(-7,51,-3,minecraft:netherrack)
B(-7,52,-3,minecraft:netherrack)
B(-7,53,-3,minecraft:netherrack)
B(-7,54,-3,minecraft:netherrack)
B(-7,55,-3,minecraft:netherrack)
B(-7,56,-3,minecraft:netherrack)
B(-7,57,-3,minecraft:netherrack)
B(-7,58,-3,minecraft:netherrack)
B(-7,59,-3,minecraft:netherrack)
B(-7,60,-3,minecraft:netherrack)
B(-7,61,-3,minecraft:netherrack)
B(-7,62,-3,minecraft:netherrack)
B(-7,63,-3,minecraft:netherrack)
B(-7,64,-3,minecraft:netherrack)
B(-7,65,-3,minecraft:netherrack)
B(-7,66,-3,minecraft:netherrack)
B(-7,67,-3,minecraft:netherrack)
B(-7,68,-3,minecraft:netherrack)
B(-7,69,-3,minecraft:netherrack)
B(-7,70,-3,minecraft:netherrack)
B(-7,71,-3,minecraft:netherrack)
B(-7,72,-3,minecraft:netherrack)
B(-7,73,-3,minecraft:netherrack)
B(-7,74,-3,minecraft:netherrack)
B(-7,75,-3,minecraft:netherrack)
B(-7,76,-3,minecraft:netherrack)
B(-7,77,-3,minecraft:netherrack)
B(-7,78,-3,minecraft:netherrack)
B(-7,79,-3,minecraft:netherrack)
B(-7,80,-3,minecraft:netherrack)
B(-7,81,-3,minecraft:netherrack)
B(-7,82,-3,minecraft:netherrack)
B(-7,83,-3,minecraft:netherrack)
B(-7,84,-3,minecraft:netherrack)
B(-7,85,-3,minecraft:netherrack)
B(-7,86,-3,minecraft:netherrack)
B(-7,87,-3,minecraft:netherrack)
B(-7,88,-3,minecraft:netherrack)
B(-7,89,-3,minecraft:netherrack)
B(-7,90,-3,minecraft:netherrack)
B(-7,27,-2,minecraft:netherrack)
B(-7,28,-2,minecraft:netherrack)
B(-7,29,-2,minecraft:netherrack)
B(-7,30,-2,minecraft:netherrack)
B(-7,31,-2,minecraft:netherrack)
B(-7,32,-2,minecraft:netherrack)
B(-7,33,-2,minecraft:netherrack)
B(-7,34,-2,minecraft:netherrack)
B(-7,35,-2,minecraft:netherrack)
B(-7,36,-2,minecraft:netherrack)
B(-7,37,-2,minecraft:netherrack)
B(-7,38,-2,minecraft:netherrack)
B(-7,39,-2,minecraft:netherrack)
B(-7,40,-2,minecraft:netherrack)
B(-7,41,-2,minecraft:netherrack)
B(-7,42,-2,minecraft:netherrack)
B(-7,43,-2,minecraft:netherrack)
B(-7,44,-2,minecraft:netherrack)
B(-7,45,-2,minecraft:netherrack)
B(-7,46,-2,minecraft:netherrack)
B(-7,47,-2,minecraft:netherrack)
B(-7,48,-2,minecraft:netherrack)
B(-7,49,-2,minecraft:netherrack)
B(-7,50,-2,minecraft:netherrack)
B(-7,51,-2,minecraft:netherrack)
B(-7,52,-2,minecraft:netherrack)
B(-7,53,-2,minecraft:netherrack)
B(-7,54,-2,minecraft:netherrack)
B(-7,55,-2,minecraft:netherrack)
B(-7,56,-2,minecraft:netherrack)
B(-7,57,-2,minecraft:netherrack)
B(-7,58,-2,minecraft:netherrack)
B(-7,59,-2,minecraft:netherrack)
B(-7,60,-2,minecraft:netherrack)
B(-7,61,-2,minecraft:netherrack)
B(-7,62,-2,minecraft:netherrack)
B(-7,63,-2,minecraft:netherrack)
B(-7,64,-2,minecraft:netherrack)
B(-7,65,-2,minecraft:netherrack)
B(-7,66,-2,minecraft:netherrack)
B(-7,67,-2,minecraft:netherrack)
B(-7,68,-2,minecraft:netherrack)
B(-7,69,-2,minecraft:netherrack)
B(-7,70,-2,minecraft:netherrack)
B(-7,71,-2,minecraft:netherrack)
B(-7,72,-2,minecraft:netherrack)
B(-7,73,-2,minecraft:netherrack)
B(-7,74,-2,minecraft:netherrack)
B(-7,75,-2,minecraft:netherrack)
B(-7,76,-2,minecraft:netherrack)
B(-7,77,-2,minecraft:netherrack)
B(-7,78,-2,minecraft:netherrack)
B(-7,79,-2,minecraft:netherrack)
B(-7,80,-2,minecraft:netherrack)
B(-7,81,-2,minecraft:netherrack)
B(-7,82,-2,minecraft:netherrack)
B(-7,83,-2,minecraft:netherrack)
B(-7,84,-2,minecraft:netherrack)
B(-7,85,-2,minecraft:netherrack)
B(-7,86,-2,minecraft:netherrack)
B(-7,87,-2,minecraft:netherrack)
B(-7,88,-2,minecraft:netherrack)
B(-7,89,-2,minecraft:netherrack)
B(-7,90,-2,minecraft:netherrack)
B(-7,29,-1,minecraft:netherrack)
B(-7,30,-1,minecraft:netherrack)
B(-7,31,-1,minecraft:netherrack)
B(-7,32,-1,minecraft:netherrack)
B(-7,33,-1,minecraft:netherrack)
B(-7,34,-1,minecraft:netherrack)
B(-7,35,-1,minecraft:netherrack)
B(-7,36,-1,minecraft:netherrack)
B(-7,37,-1,minecraft:netherrack)
B(-7,38,-1,minecraft:netherrack)
B(-7,39,-1,minecraft:netherrack)
B(-7,40,-1,minecraft:netherrack)
B(-7,41,-1,minecraft:netherrack)
B(-7,42,-1,minecraft:netherrack)
B(-7,43,-1,minecraft:netherrack)
B(-7,44,-1,minecraft:netherrack)
B(-7,45,-1,minecraft:netherrack)
B(-7,46,-1,minecraft:netherrack)
B(-7,47,-1,minecraft:netherrack)
B(-7,48,-1,minecraft:netherrack)
B(-7,49,-1,minecraft:netherrack)
B(-7,50,-1,minecraft:netherrack)
B(-7,51,-1,minecraft:netherrack)
B(-7,52,-1,minecraft:netherrack)
B(-7,53,-1,minecraft:netherrack)
B(-7,54,-1,minecraft:netherrack)
B(-7,55,-1,minecraft:netherrack)
B(-7,56,-1,minecraft:netherrack)
B(-7,57,-1,minecraft:netherrack)
B(-7,58,-1,minecraft:netherrack)
B(-7,59,-1,minecraft:netherrack)
B(-7,60,-1,minecraft:netherrack)
B(-7,61,-1,minecraft:netherrack)
B(-7,62,-1,minecraft:netherrack)
B(-7,63,-1,minecraft:netherrack)
B(-7,64,-1,minecraft:netherrack)
B(-7,65,-1,minecraft:netherrack)
B(-7,66,-1,minecraft:netherrack)
B(-7,67,-1,minecraft:netherrack)
B(-7,68,-1,minecraft:netherrack)
B(-7,69,-1,minecraft:netherrack)
B(-7,70,-1,minecraft:netherrack)
B(-7,71,-1,minecraft:netherrack)
B(-7,72,-1,minecraft:netherrack)
B(-7,73,-1,minecraft:netherrack)
B(-7,74,-1,minecraft:netherrack)
B(-7,75,-1,minecraft:netherrack)
B(-7,76,-1,minecraft:netherrack)
B(-7,77,-1,minecraft:netherrack)
B(-7,78,-1,minecraft:netherrack)
B(-7,79,-1,minecraft:netherrack)
B(-7,80,-1,minecraft:netherrack)
B(-7,81,-1,minecraft:netherrack)
B(-7,82,-1,minecraft:netherrack)
B(-7,83,-1,minecraft:netherrack)
B(-7,84,-1,minecraft:netherrack)
B(-7,85,-1,minecraft:netherrack)
B(-7,86,-1,minecraft:netherrack)
B(-7,87,-1,minecraft:netherrack)
B(-7,88,-1,minecraft:netherrack)
B(-7,89,-1,minecraft:netherrack)
B(-7,90,-1,minecraft:blackstone)
B(-7,31,0,minecraft:netherrack)
B(-7,32,0,minecraft:netherrack)
B(-7,33,0,minecraft:netherrack)
B(-7,34,0,minecraft:netherrack)
B(-7,35,0,minecraft:netherrack)
B(-7,36,0,minecraft:netherrack)
B(-7,37,0,minecraft:netherrack)
B(-7,38,0,minecraft:netherrack)
B(-7,39,0,minecraft:netherrack)
B(-7,40,0,minecraft:netherrack)
B(-7,41,0,minecraft:netherrack)
B(-7,42,0,minecraft:netherrack)
B(-7,43,0,minecraft:netherrack)
B(-7,44,0,minecraft:netherrack)
B(-7,45,0,minecraft:netherrack)
B(-7,46,0,minecraft:netherrack)
B(-7,47,0,minecraft:netherrack)
B(-7,48,0,minecraft:netherrack)
B(-7,49,0,minecraft:netherrack)
B(-7,50,0,minecraft:netherrack)
B(-7,51,0,minecraft:netherrack)
B(-7,52,0,minecraft:netherrack)
B(-7,53,0,minecraft:netherrack)
B(-7,54,0,minecraft:netherrack)
B(-7,55,0,minecraft:netherrack)
B(-7,56,0,minecraft:netherrack)
B(-7,57,0,minecraft:netherrack)
B(-7,58,0,minecraft:netherrack)
B(-7,59,0,minecraft:netherrack)
B(-7,60,0,minecraft:netherrack)
B(-7,61,0,minecraft:netherrack)
B(-7,62,0,minecraft:netherrack)
B(-7,63,0,minecraft:netherrack)
B(-7,64,0,minecraft:netherrack)
B(-7,65,0,minecraft:netherrack)
B(-7,66,0,minecraft:netherrack)
B(-7,67,0,minecraft:netherrack)
B(-7,68,0,minecraft:netherrack)
B(-7,69,0,minecraft:netherrack)
B(-7,70,0,minecraft:netherrack)
B(-7,71,0,minecraft:netherrack)
B(-7,72,0,minecraft:netherrack)
B(-7,73,0,minecraft:netherrack)
B(-7,74,0,minecraft:netherrack)
B(-7,75,0,minecraft:netherrack)
B(-7,76,0,minecraft:netherrack)
B(-7,77,0,minecraft:netherrack)
B(-7,78,0,minecraft:netherrack)
B(-7,79,0,minecraft:netherrack)
B(-7,80,0,minecraft:netherrack)
B(-7,81,0,minecraft:netherrack)
B(-7,82,0,minecraft:netherrack)
B(-7,83,0,minecraft:netherrack)
B(-7,84,0,minecraft:netherrack)
B(-7,85,0,minecraft:netherrack)
B(-7,86,0,minecraft:netherrack)
B(-7,87,0,minecraft:netherrack)
B(-7,88,0,minecraft:blackstone)
B(-7,89,0,minecraft:blackstone)
B(-7,90,0,minecraft:blackstone)
B(-7,32,1,minecraft:netherrack)
B(-7,33,1,minecraft:netherrack)
B(-7,34,1,minecraft:netherrack)
B(-7,35,1,minecraft:netherrack)
B(-7,36,1,minecraft:netherrack)
B(-7,37,1,minecraft:netherrack)
B(-7,38,1,minecraft:netherrack)
B(-7,39,1,minecraft:netherrack)
B(-7,40,1,minecraft:netherrack)
B(-7,41,1,minecraft:netherrack)
B(-7,42,1,minecraft:netherrack)
B(-7,43,1,minecraft:netherrack)
B(-7,44,1,minecraft:netherrack)
B(-7,45,1,minecraft:netherrack)
B(-7,46,1,minecraft:netherrack)
B(-7,47,1,minecraft:netherrack)
B(-7,48,1,minecraft:netherrack)
B(-7,49,1,minecraft:netherrack)
B(-7,50,1,minecraft:netherrack)
B(-7,51,1,minecraft:netherrack)
B(-7,52,1,minecraft:netherrack)
B(-7,53,1,minecraft:netherrack)
B(-7,54,1,minecraft:netherrack)
B(-7,55,1,minecraft:netherrack)
B(-7,56,1,minecraft:netherrack)
B(-7,57,1,minecraft:netherrack)
B(-7,58,1,minecraft:netherrack)
B(-7,59,1,minecraft:netherrack)
B(-7,60,1,minecraft:netherrack)
B(-7,61,1,minecraft:netherrack)
B(-7,62,1,minecraft:netherrack)
B(-7,63,1,minecraft:netherrack)
B(-7,64,1,minecraft:netherrack)
B(-7,65,1,minecraft:netherrack)
B(-7,66,1,minecraft:netherrack)
B(-7,67,1,minecraft:netherrack)
B(-7,68,1,minecraft:netherrack)
B(-7,69,1,minecraft:netherrack)
B(-7,70,1,minecraft:netherrack)
B(-7,71,1,minecraft:netherrack)
B(-7,72,1,minecraft:netherrack)
B(-7,73,1,minecraft:netherrack)
B(-7,74,1,minecraft:netherrack)
B(-7,75,1,minecraft:netherrack)
B(-7,76,1,minecraft:netherrack)
B(-7,77,1,minecraft:netherrack)
B(-7,78,1,minecraft:netherrack)
B(-7,79,1,minecraft:netherrack)
B(-7,80,1,minecraft:netherrack)
B(-7,81,1,minecraft:netherrack)
B(-7,82,1,minecraft:netherrack)
B(-7,83,1,minecraft:netherrack)
B(-7,84,1,minecraft:netherrack)
B(-7,85,1,minecraft:netherrack)
B(-7,86,1,minecraft:netherrack)
B(-7,87,1,minecraft:netherrack)
B(-7,88,1,minecraft:netherrack)
B(-7,89,1,minecraft:netherrack)
B(-7,90,1,minecraft:blackstone)
B(-7,36,2,minecraft:netherrack)
B(-7,37,2,minecraft:netherrack)
B(-7,38,2,minecraft:netherrack)
B(-7,39,2,minecraft:netherrack)
B(-7,40,2,minecraft:netherrack)
B(-7,41,2,minecraft:netherrack)
B(-7,42,2,minecraft:netherrack)
B(-7,43,2,minecraft:netherrack)
B(-7,44,2,minecraft:netherrack)
B(-7,45,2,minecraft:netherrack)
B(-7,46,2,minecraft:netherrack)
B(-7,47,2,minecraft:netherrack)
B(-7,48,2,minecraft:netherrack)
B(-7,49,2,minecraft:netherrack)
B(-7,50,2,minecraft:netherrack)
B(-7,51,2,minecraft:netherrack)
B(-7,52,2,minecraft:netherrack)
B(-7,53,2,minecraft:netherrack)
B(-7,54,2,minecraft:netherrack)
B(-7,55,2,minecraft:netherrack)
B(-7,56,2,minecraft:netherrack)
B(-7,57,2,minecraft:netherrack)
B(-7,58,2,minecraft:netherrack)
B(-7,59,2,minecraft:netherrack)
B(-7,60,2,minecraft:netherrack)
B(-7,61,2,minecraft:netherrack)
B(-7,62,2,minecraft:netherrack)
B(-7,63,2,minecraft:netherrack)
B(-7,64,2,minecraft:netherrack)
B(-7,65,2,minecraft:netherrack)
B(-7,66,2,minecraft:netherrack)
B(-7,67,2,minecraft:netherrack)
B(-7,68,2,minecraft:netherrack)
B(-7,69,2,minecraft:netherrack)
B(-7,70,2,minecraft:netherrack)
B(-7,71,2,minecraft:netherrack)
B(-7,72,2,minecraft:netherrack)
B(-7,73,2,minecraft:netherrack)
B(-7,74,2,minecraft:netherrack)
B(-7,75,2,minecraft:netherrack)
B(-7,76,2,minecraft:netherrack)
B(-7,77,2,minecraft:netherrack)
B(-7,78,2,minecraft:netherrack)
B(-7,79,2,minecraft:netherrack)
B(-7,80,2,minecraft:netherrack)
B(-7,81,2,minecraft:netherrack)
B(-7,82,2,minecraft:netherrack)
B(-7,83,2,minecraft:netherrack)
B(-7,84,2,minecraft:netherrack)
B(-7,85,2,minecraft:netherrack)
B(-7,86,2,minecraft:netherrack)
B(-7,87,2,minecraft:netherrack)
B(-7,88,2,minecraft:netherrack)
B(-7,89,2,minecraft:netherrack)
B(-7,90,2,minecraft:netherrack)
B(-7,23,3,minecraft:netherrack)
B(-7,24,3,minecraft:netherrack)
B(-7,25,3,minecraft:netherrack)
B(-7,26,3,minecraft:netherrack)
B(-7,27,3,minecraft:netherrack)
B(-7,28,3,minecraft:netherrack)
B(-7,29,3,minecraft:netherrack)
B(-7,30,3,minecraft:netherrack)
B(-7,31,3,minecraft:netherrack)
B(-7,32,3,minecraft:netherrack)
B(-7,33,3,minecraft:netherrack)
B(-7,34,3,minecraft:netherrack)
B(-7,35,3,minecraft:netherrack)
B(-7,36,3,minecraft:netherrack)
B(-7,37,3,minecraft:netherrack)
B(-7,38,3,minecraft:netherrack)
B(-7,39,3,minecraft:netherrack)
B(-7,40,3,minecraft:netherrack)
B(-7,41,3,minecraft:netherrack)
B(-7,42,3,minecraft:netherrack)
B(-7,43,3,minecraft:netherrack)
B(-7,44,3,minecraft:netherrack)
B(-7,45,3,minecraft:netherrack)
B(-7,46,3,minecraft:netherrack)
B(-7,47,3,minecraft:netherrack)
B(-7,48,3,minecraft:netherrack)
B(-7,49,3,minecraft:netherrack)
B(-7,50,3,minecraft:netherrack)
B(-7,51,3,minecraft:netherrack)
B(-7,52,3,minecraft:netherrack)
B(-7,53,3,minecraft:netherrack)
B(-7,54,3,minecraft:netherrack)
B(-7,55,3,minecraft:netherrack)
B(-7,56,3,minecraft:netherrack)
B(-7,57,3,minecraft:netherrack)
B(-7,58,3,minecraft:netherrack)
B(-7,59,3,minecraft:netherrack)
B(-7,60,3,minecraft:netherrack)
B(-7,61,3,minecraft:netherrack)
B(-7,62,3,minecraft:netherrack)
B(-7,63,3,minecraft:netherrack)
B(-7,64,3,minecraft:netherrack)
B(-7,65,3,minecraft:netherrack)
B(-7,66,3,minecraft:netherrack)
B(-7,67,3,minecraft:netherrack)
B(-7,68,3,minecraft:netherrack)
B(-7,69,3,minecraft:netherrack)
B(-7,70,3,minecraft:netherrack)
B(-7,71,3,minecraft:netherrack)
B(-7,72,3,minecraft:netherrack)
B(-7,73,3,minecraft:netherrack)
B(-7,74,3,minecraft:netherrack)
B(-7,75,3,minecraft:netherrack)
B(-7,76,3,minecraft:netherrack)
B(-7,77,3,minecraft:netherrack)
B(-7,78,3,minecraft:netherrack)
B(-7,79,3,minecraft:netherrack)
B(-7,80,3,minecraft:netherrack)
B(-7,81,3,minecraft:netherrack)
B(-7,82,3,minecraft:netherrack)
B(-7,83,3,minecraft:netherrack)
B(-7,84,3,minecraft:netherrack)
B(-7,85,3,minecraft:netherrack)
B(-7,86,3,minecraft:netherrack)
B(-7,87,3,minecraft:netherrack)
B(-7,88,3,minecraft:netherrack)
B(-7,89,3,minecraft:netherrack)
B(-7,90,3,minecraft:netherrack)
B(-7,19,4,minecraft:netherrack)
B(-7,20,4,minecraft:netherrack)
B(-7,21,4,minecraft:netherrack)
B(-7,22,4,minecraft:netherrack)
B(-7,23,4,minecraft:netherrack)
B(-7,24,4,minecraft:netherrack)
B(-7,25,4,minecraft:netherrack)
B(-7,26,4,minecraft:netherrack)
B(-7,27,4,minecraft:netherrack)
B(-7,28,4,minecraft:netherrack)
B(-7,29,4,minecraft:netherrack)
B(-7,30,4,minecraft:netherrack)
B(-7,31,4,minecraft:netherrack)
B(-7,32,4,minecraft:netherrack)
B(-7,33,4,minecraft:netherrack)
B(-7,34,4,minecraft:netherrack)
B(-7,35,4,minecraft:netherrack)
B(-7,36,4,minecraft:netherrack)
B(-7,37,4,minecraft:netherrack)
B(-7,38,4,minecraft:netherrack)
B(-7,39,4,minecraft:netherrack)
B(-7,40,4,minecraft:netherrack)
B(-7,41,4,minecraft:netherrack)
B(-7,42,4,minecraft:netherrack)
B(-7,43,4,minecraft:netherrack)
B(-7,44,4,minecraft:netherrack)
B(-7,45,4,minecraft:netherrack)
B(-7,46,4,minecraft:netherrack)
B(-7,47,4,minecraft:netherrack)
B(-7,48,4,minecraft:netherrack)
B(-7,49,4,minecraft:netherrack)
B(-7,50,4,minecraft:netherrack)
B(-7,51,4,minecraft:netherrack)
B(-7,52,4,minecraft:netherrack)
B(-7,53,4,minecraft:netherrack)
B(-7,54,4,minecraft:netherrack)
B(-7,55,4,minecraft:netherrack)
B(-7,56,4,minecraft:netherrack)
B(-7,57,4,minecraft:netherrack)
B(-7,58,4,minecraft:netherrack)
B(-7,59,4,minecraft:netherrack)
B(-7,60,4,minecraft:netherrack)
B(-7,61,4,minecraft:netherrack)
B(-7,62,4,minecraft:netherrack)
B(-7,63,4,minecraft:netherrack)
B(-7,64,4,minecraft:netherrack)
B(-7,65,4,minecraft:netherrack)
B(-7,66,4,minecraft:netherrack)
B(-7,67,4,minecraft:netherrack)
B(-7,68,4,minecraft:netherrack)
B(-7,69,4,minecraft:netherrack)
B(-7,70,4,minecraft:netherrack)
B(-7,71,4,minecraft:netherrack)
B(-7,72,4,minecraft:netherrack)
B(-7,73,4,minecraft:netherrack)
B(-7,74,4,minecraft:netherrack)
B(-7,75,4,minecraft:netherrack)
B(-7,76,4,minecraft:netherrack)
B(-7,77,4,minecraft:netherrack)
B(-7,78,4,minecraft:netherrack)
B(-7,79,4,minecraft:netherrack)
B(-7,80,4,minecraft:netherrack)
B(-7,81,4,minecraft:netherrack)
B(-7,82,4,minecraft:netherrack)
B(-7,83,4,minecraft:netherrack)
B(-7,84,4,minecraft:netherrack)
B(-7,85,4,minecraft:netherrack)
B(-7,86,4,minecraft:netherrack)
B(-7,87,4,minecraft:netherrack)
B(-7,88,4,minecraft:netherrack)
B(-7,89,4,minecraft:netherrack)
B(-7,90,4,minecraft:netherrack)
B(-7,20,5,minecraft:netherrack)
B(-7,21,5,minecraft:netherrack)
B(-7,22,5,minecraft:netherrack)
B(-7,23,5,minecraft:netherrack)
B(-7,24,5,minecraft:netherrack)
B(-7,25,5,minecraft:netherrack)
B(-7,26,5,minecraft:netherrack)
B(-7,27,5,minecraft:netherrack)
B(-7,28,5,minecraft:netherrack)
B(-7,29,5,minecraft:netherrack)
B(-7,30,5,minecraft:netherrack)
B(-7,31,5,minecraft:netherrack)
B(-7,32,5,minecraft:netherrack)
B(-7,33,5,minecraft:netherrack)
B(-7,34,5,minecraft:netherrack)
B(-7,35,5,minecraft:netherrack)
B(-7,36,5,minecraft:netherrack)
B(-7,37,5,minecraft:netherrack)
B(-7,38,5,minecraft:netherrack)
B(-7,39,5,minecraft:netherrack)
B(-7,40,5,minecraft:netherrack)
B(-7,41,5,minecraft:netherrack)
B(-7,42,5,minecraft:netherrack)
B(-7,43,5,minecraft:netherrack)
B(-7,44,5,minecraft:netherrack)
B(-7,45,5,minecraft:netherrack)
B(-7,46,5,minecraft:netherrack)
B(-7,47,5,minecraft:netherrack)
B(-7,48,5,minecraft:netherrack)
B(-7,49,5,minecraft:netherrack)
B(-7,50,5,minecraft:netherrack)
B(-7,51,5,minecraft:netherrack)
B(-7,52,5,minecraft:netherrack)
B(-7,53,5,minecraft:netherrack)
B(-7,54,5,minecraft:netherrack)
B(-7,55,5,minecraft:netherrack)
B(-7,56,5,minecraft:netherrack)
B(-7,57,5,minecraft:netherrack)
B(-7,58,5,minecraft:netherrack)
B(-7,59,5,minecraft:netherrack)
B(-7,60,5,minecraft:netherrack)
B(-7,61,5,minecraft:netherrack)
B(-7,62,5,minecraft:netherrack)
B(-7,63,5,minecraft:netherrack)
B(-7,64,5,minecraft:netherrack)
B(-7,65,5,minecraft:netherrack)
B(-7,66,5,minecraft:netherrack)
B(-7,67,5,minecraft:netherrack)
B(-7,68,5,minecraft:netherrack)
B(-7,69,5,minecraft:netherrack)
B(-7,70,5,minecraft:netherrack)
B(-7,71,5,minecraft:netherrack)
B(-7,72,5,minecraft:netherrack)
B(-7,73,5,minecraft:netherrack)
B(-7,74,5,minecraft:netherrack)
B(-7,75,5,minecraft:netherrack)
B(-7,76,5,minecraft:netherrack)
B(-7,77,5,minecraft:netherrack)
B(-7,78,5,minecraft:netherrack)
B(-7,79,5,minecraft:netherrack)
B(-7,80,5,minecraft:netherrack)
B(-7,81,5,minecraft:netherrack)
B(-7,82,5,minecraft:netherrack)
B(-7,83,5,minecraft:netherrack)
B(-7,84,5,minecraft:netherrack)
B(-7,85,5,minecraft:netherrack)
B(-7,86,5,minecraft:netherrack)
B(-7,87,5,minecraft:netherrack)
B(-7,88,5,minecraft:netherrack)
B(-7,89,5,minecraft:netherrack)
B(-7,90,5,minecraft:netherrack)
B(-7,21,6,minecraft:netherrack)
B(-7,22,6,minecraft:netherrack)
B(-7,23,6,minecraft:netherrack)
B(-7,24,6,minecraft:netherrack)
B(-7,25,6,minecraft:netherrack)
B(-7,26,6,minecraft:netherrack)
B(-7,27,6,minecraft:netherrack)
B(-7,28,6,minecraft:netherrack)
B(-7,29,6,minecraft:netherrack)
B(-7,30,6,minecraft:netherrack)
B(-7,31,6,minecraft:netherrack)
B(-7,32,6,minecraft:netherrack)
B(-7,33,6,minecraft:netherrack)
B(-7,34,6,minecraft:netherrack)
B(-7,35,6,minecraft:netherrack)
B(-7,36,6,minecraft:netherrack)
B(-7,37,6,minecraft:netherrack)
B(-7,38,6,minecraft:netherrack)
B(-7,39,6,minecraft:netherrack)
B(-7,40,6,minecraft:netherrack)
B(-7,41,6,minecraft:netherrack)
B(-7,42,6,minecraft:netherrack)
B(-7,43,6,minecraft:netherrack)
B(-7,44,6,minecraft:netherrack)
B(-7,45,6,minecraft:netherrack)
B(-7,46,6,minecraft:netherrack)
B(-7,47,6,minecraft:netherrack)
B(-7,48,6,minecraft:netherrack)
B(-7,49,6,minecraft:netherrack)
B(-7,50,6,minecraft:netherrack)
B(-7,51,6,minecraft:netherrack)
B(-7,52,6,minecraft:netherrack)
B(-7,53,6,minecraft:netherrack)
B(-7,54,6,minecraft:netherrack)
B(-7,55,6,minecraft:netherrack)
B(-7,56,6,minecraft:netherrack)
B(-7,57,6,minecraft:netherrack)
B(-7,58,6,minecraft:netherrack)
B(-7,59,6,minecraft:netherrack)
B(-7,60,6,minecraft:netherrack)
B(-7,61,6,minecraft:netherrack)
B(-7,62,6,minecraft:netherrack)
B(-7,63,6,minecraft:netherrack)
B(-7,64,6,minecraft:netherrack)
B(-7,65,6,minecraft:netherrack)
B(-7,66,6,minecraft:netherrack)
B(-7,67,6,minecraft:netherrack)
B(-7,68,6,minecraft:netherrack)
B(-7,69,6,minecraft:netherrack)
B(-7,70,6,minecraft:netherrack)
B(-7,71,6,minecraft:netherrack)
B(-7,72,6,minecraft:netherrack)
B(-7,73,6,minecraft:netherrack)
B(-7,74,6,minecraft:netherrack)
B(-7,75,6,minecraft:netherrack)
B(-7,76,6,minecraft:netherrack)
B(-7,77,6,minecraft:netherrack)
B(-7,78,6,minecraft:netherrack)
B(-7,79,6,minecraft:netherrack)
B(-7,80,6,minecraft:netherrack)
B(-7,81,6,minecraft:netherrack)
B(-7,82,6,minecraft:netherrack)
B(-7,83,6,minecraft:netherrack)
B(-7,84,6,minecraft:netherrack)
B(-7,85,6,minecraft:netherrack)
B(-7,86,6,minecraft:netherrack)
B(-7,87,6,minecraft:netherrack)
B(-7,88,6,minecraft:netherrack)
B(-7,89,6,minecraft:netherrack)
B(-7,90,6,minecraft:netherrack)
B(-7,39,7,minecraft:netherrack)
B(-7,40,7,minecraft:netherrack)
B(-7,41,7,minecraft:netherrack)
B(-7,42,7,minecraft:netherrack)
B(-7,43,7,minecraft:netherrack)
B(-7,44,7,minecraft:netherrack)
B(-7,45,7,minecraft:netherrack)
B(-7,46,7,minecraft:netherrack)
B(-7,47,7,minecraft:netherrack)
B(-7,48,7,minecraft:netherrack)
B(-7,49,7,minecraft:netherrack)
B(-7,50,7,minecraft:netherrack)
B(-7,51,7,minecraft:netherrack)
B(-7,52,7,minecraft:netherrack)
B(-7,53,7,minecraft:netherrack)
B(-7,54,7,minecraft:netherrack)
B(-7,55,7,minecraft:netherrack)
B(-7,56,7,minecraft:netherrack)
B(-7,57,7,minecraft:netherrack)
B(-7,58,7,minecraft:netherrack)
B(-7,59,7,minecraft:netherrack)
B(-7,60,7,minecraft:netherrack)
B(-7,61,7,minecraft:netherrack)
B(-7,62,7,minecraft:netherrack)
B(-7,63,7,minecraft:netherrack)
B(-7,64,7,minecraft:netherrack)
B(-7,65,7,minecraft:netherrack)
B(-7,66,7,minecraft:netherrack)
B(-7,67,7,minecraft:netherrack)
B(-7,68,7,minecraft:netherrack)
B(-7,69,7,minecraft:netherrack)
B(-7,70,7,minecraft:netherrack)
B(-7,71,7,minecraft:netherrack)
B(-7,72,7,minecraft:netherrack)
B(-7,73,7,minecraft:netherrack)
B(-7,74,7,minecraft:netherrack)
B(-7,75,7,minecraft:netherrack)
B(-7,76,7,minecraft:netherrack)
B(-7,77,7,minecraft:netherrack)
B(-7,78,7,minecraft:netherrack)
B(-7,79,7,minecraft:netherrack)
B(-7,80,7,minecraft:netherrack)
B(-7,81,7,minecraft:netherrack)
B(-7,82,7,minecraft:netherrack)
B(-7,83,7,minecraft:netherrack)
B(-7,84,7,minecraft:netherrack)
B(-7,85,7,minecraft:netherrack)
B(-7,86,7,minecraft:netherrack)
B(-7,87,7,minecraft:netherrack)
B(-7,88,7,minecraft:netherrack)
B(-7,89,7,minecraft:netherrack)
B(-7,90,7,minecraft:blackstone)
B(-7,67,8,minecraft:netherrack)
B(-7,68,8,minecraft:netherrack)
B(-7,69,8,minecraft:netherrack)
B(-7,70,8,minecraft:netherrack)
B(-7,71,8,minecraft:netherrack)
B(-7,72,8,minecraft:netherrack)
B(-7,73,8,minecraft:netherrack)
B(-7,74,8,minecraft:netherrack)
B(-7,75,8,minecraft:netherrack)
B(-7,76,8,minecraft:netherrack)
B(-7,77,8,minecraft:netherrack)
B(-7,78,8,minecraft:netherrack)
B(-7,79,8,minecraft:netherrack)
B(-7,80,8,minecraft:netherrack)
B(-7,81,8,minecraft:netherrack)
B(-7,82,8,minecraft:netherrack)
B(-7,83,8,minecraft:netherrack)
B(-7,84,8,minecraft:netherrack)
B(-7,85,8,minecraft:netherrack)
B(-7,86,8,minecraft:netherrack)
B(-7,87,8,minecraft:netherrack)
B(-7,88,8,minecraft:netherrack)
B(-7,89,8,minecraft:netherrack)
B(-7,90,8,minecraft:blackstone)
B(-6,28,-7,minecraft:netherrack)
B(-6,29,-7,minecraft:netherrack)
B(-6,30,-7,minecraft:netherrack)
B(-6,31,-7,minecraft:netherrack)
B(-6,32,-7,minecraft:netherrack)
B(-6,33,-7,minecraft:netherrack)
B(-6,34,-7,minecraft:netherrack)
B(-6,35,-7,minecraft:netherrack)
B(-6,36,-7,minecraft:netherrack)
B(-6,37,-7,minecraft:netherrack)
B(-6,38,-7,minecraft:netherrack)
B(-6,39,-7,minecraft:netherrack)
B(-6,40,-7,minecraft:netherrack)
B(-6,41,-7,minecraft:netherrack)
B(-6,42,-7,minecraft:netherrack)
B(-6,43,-7,minecraft:netherrack)
B(-6,44,-7,minecraft:netherrack)
B(-6,45,-7,minecraft:netherrack)
B(-6,46,-7,minecraft:netherrack)
B(-6,47,-7,minecraft:netherrack)
B(-6,48,-7,minecraft:netherrack)
B(-6,49,-7,minecraft:netherrack)
B(-6,50,-7,minecraft:netherrack)
B(-6,51,-7,minecraft:netherrack)
B(-6,52,-7,minecraft:netherrack)
B(-6,53,-7,minecraft:netherrack)
B(-6,54,-7,minecraft:netherrack)
B(-6,55,-7,minecraft:netherrack)
B(-6,56,-7,minecraft:netherrack)
B(-6,57,-7,minecraft:netherrack)
B(-6,58,-7,minecraft:netherrack)
B(-6,59,-7,minecraft:netherrack)
B(-6,60,-7,minecraft:netherrack)
B(-6,61,-7,minecraft:netherrack)
B(-6,62,-7,minecraft:netherrack)
B(-6,63,-7,minecraft:netherrack)
B(-6,64,-7,minecraft:netherrack)
B(-6,65,-7,minecraft:netherrack)
B(-6,66,-7,minecraft:netherrack)
B(-6,67,-7,minecraft:netherrack)
B(-6,68,-7,minecraft:netherrack)
B(-6,69,-7,minecraft:netherrack)
B(-6,70,-7,minecraft:netherrack)
B(-6,71,-7,minecraft:netherrack)
B(-6,72,-7,minecraft:netherrack)
B(-6,73,-7,minecraft:netherrack)
B(-6,74,-7,minecraft:netherrack)
B(-6,75,-7,minecraft:netherrack)
B(-6,76,-7,minecraft:netherrack)
B(-6,77,-7,minecraft:netherrack)
B(-6,78,-7,minecraft:netherrack)
B(-6,79,-7,minecraft:netherrack)
B(-6,80,-7,minecraft:netherrack)
B(-6,81,-7,minecraft:netherrack)
B(-6,82,-7,minecraft:netherrack)
B(-6,83,-7,minecraft:netherrack)
B(-6,84,-7,minecraft:netherrack)
B(-6,85,-7,minecraft:netherrack)
B(-6,86,-7,minecraft:netherrack)
B(-6,87,-7,minecraft:netherrack)
B(-6,88,-7,minecraft:netherrack)
B(-6,89,-7,minecraft:netherrack)
B(-6,90,-7,minecraft:blackstone)
B(-6,28,-6,minecraft:netherrack)
B(-6,29,-6,minecraft:netherrack)
B(-6,30,-6,minecraft:netherrack)
B(-6,31,-6,minecraft:netherrack)
B(-6,32,-6,minecraft:netherrack)
B(-6,33,-6,minecraft:netherrack)
B(-6,34,-6,minecraft:netherrack)
B(-6,35,-6,minecraft:netherrack)
B(-6,36,-6,minecraft:netherrack)
B(-6,37,-6,minecraft:netherrack)
B(-6,38,-6,minecraft:netherrack)
B(-6,39,-6,minecraft:netherrack)
B(-6,40,-6,minecraft:netherrack)
B(-6,41,-6,minecraft:netherrack)
B(-6,42,-6,minecraft:netherrack)
B(-6,43,-6,minecraft:netherrack)
B(-6,44,-6,minecraft:netherrack)
B(-6,45,-6,minecraft:netherrack)
B(-6,46,-6,minecraft:netherrack)
B(-6,47,-6,minecraft:netherrack)
B(-6,48,-6,minecraft:netherrack)
B(-6,49,-6,minecraft:netherrack)
B(-6,50,-6,minecraft:netherrack)
B(-6,51,-6,minecraft:netherrack)
B(-6,52,-6,minecraft:netherrack)
B(-6,53,-6,minecraft:netherrack)
B(-6,54,-6,minecraft:netherrack)
B(-6,55,-6,minecraft:netherrack)
B(-6,56,-6,minecraft:netherrack)
B(-6,57,-6,minecraft:netherrack)
B(-6,58,-6,minecraft:netherrack)
B(-6,59,-6,minecraft:netherrack)
B(-6,60,-6,minecraft:netherrack)
B(-6,61,-6,minecraft:netherrack)
B(-6,62,-6,minecraft:netherrack)
B(-6,63,-6,minecraft:netherrack)
B(-6,64,-6,minecraft:netherrack)
B(-6,65,-6,minecraft:netherrack)
B(-6,66,-6,minecraft:netherrack)
B(-6,67,-6,minecraft:netherrack)
B(-6,68,-6,minecraft:netherrack)
B(-6,69,-6,minecraft:netherrack)
B(-6,70,-6,minecraft:netherrack)
B(-6,71,-6,minecraft:netherrack)
B(-6,72,-6,minecraft:netherrack)
B(-6,73,-6,minecraft:netherrack)
B(-6,74,-6,minecraft:netherrack)
B(-6,75,-6,minecraft:netherrack)
B(-6,76,-6,minecraft:netherrack)
B(-6,77,-6,minecraft:netherrack)
B(-6,78,-6,minecraft:netherrack)
B(-6,79,-6,minecraft:netherrack)
B(-6,80,-6,minecraft:netherrack)
B(-6,81,-6,minecraft:netherrack)
B(-6,82,-6,minecraft:netherrack)
B(-6,83,-6,minecraft:netherrack)
B(-6,84,-6,minecraft:netherrack)
B(-6,85,-6,minecraft:netherrack)
B(-6,86,-6,minecraft:netherrack)
B(-6,87,-6,minecraft:netherrack)
B(-6,88,-6,minecraft:netherrack)
B(-6,89,-6,minecraft:blackstone)
B(-6,90,-6,minecraft:blackstone)
B(-6,28,-5,minecraft:netherrack)
B(-6,29,-5,minecraft:netherrack)
B(-6,30,-5,minecraft:netherrack)
B(-6,31,-5,minecraft:netherrack)
B(-6,32,-5,minecraft:netherrack)
B(-6,33,-5,minecraft:netherrack)
B(-6,34,-5,minecraft:netherrack)
B(-6,35,-5,minecraft:netherrack)
B(-6,36,-5,minecraft:netherrack)
B(-6,37,-5,minecraft:netherrack)
B(-6,38,-5,minecraft:netherrack)
B(-6,39,-5,minecraft:netherrack)
B(-6,40,-5,minecraft:netherrack)
B(-6,41,-5,minecraft:netherrack)
B(-6,42,-5,minecraft:netherrack)
B(-6,43,-5,minecraft:netherrack)
B(-6,44,-5,minecraft:netherrack)
B(-6,45,-5,minecraft:netherrack)
B(-6,46,-5,minecraft:netherrack)
B(-6,47,-5,minecraft:netherrack)
B(-6,48,-5,minecraft:netherrack)
B(-6,49,-5,minecraft:netherrack)
B(-6,50,-5,minecraft:netherrack)
B(-6,51,-5,minecraft:netherrack)
B(-6,52,-5,minecraft:netherrack)
B(-6,53,-5,minecraft:netherrack)
B(-6,54,-5,minecraft:netherrack)
B(-6,55,-5,minecraft:netherrack)
B(-6,56,-5,minecraft:netherrack)
B(-6,57,-5,minecraft:netherrack)
B(-6,58,-5,minecraft:netherrack)
B(-6,59,-5,minecraft:netherrack)
B(-6,60,-5,minecraft:netherrack)
B(-6,61,-5,minecraft:netherrack)
B(-6,62,-5,minecraft:netherrack)
B(-6,63,-5,minecraft:netherrack)
B(-6,64,-5,minecraft:netherrack)
B(-6,65,-5,minecraft:netherrack)
B(-6,66,-5,minecraft:netherrack)
B(-6,67,-5,minecraft:netherrack)
B(-6,68,-5,minecraft:netherrack)
B(-6,69,-5,minecraft:netherrack)
B(-6,70,-5,minecraft:netherrack)
B(-6,71,-5,minecraft:netherrack)
B(-6,72,-5,minecraft:netherrack)
B(-6,73,-5,minecraft:netherrack)
B(-6,74,-5,minecraft:netherrack)
B(-6,75,-5,minecraft:netherrack)
B(-6,76,-5,minecraft:netherrack)
B(-6,77,-5,minecraft:netherrack)
B(-6,78,-5,minecraft:netherrack)
B(-6,79,-5,minecraft:netherrack)
B(-6,80,-5,minecraft:netherrack)
B(-6,81,-5,minecraft:netherrack)
B(-6,82,-5,minecraft:netherrack)
B(-6,83,-5,minecraft:netherrack)
B(-6,84,-5,minecraft:netherrack)
B(-6,85,-5,minecraft:netherrack)
B(-6,86,-5,minecraft:netherrack)
B(-6,87,-5,minecraft:netherrack)
B(-6,88,-5,minecraft:netherrack)
B(-6,89,-5,minecraft:netherrack)
B(-6,90,-5,minecraft:blackstone)
B(-6,28,-4,minecraft:netherrack)
B(-6,29,-4,minecraft:netherrack)
B(-6,30,-4,minecraft:netherrack)
B(-6,31,-4,minecraft:netherrack)
B(-6,32,-4,minecraft:netherrack)
B(-6,33,-4,minecraft:netherrack)
B(-6,34,-4,minecraft:netherrack)
B(-6,35,-4,minecraft:netherrack)
B(-6,36,-4,minecraft:netherrack)
B(-6,37,-4,minecraft:netherrack)
B(-6,38,-4,minecraft:netherrack)
B(-6,39,-4,minecraft:netherrack)
B(-6,40,-4,minecraft:netherrack)
B(-6,41,-4,minecraft:netherrack)
B(-6,42,-4,minecraft:netherrack)
B(-6,43,-4,minecraft:netherrack)
B(-6,44,-4,minecraft:netherrack)
B(-6,45,-4,minecraft:netherrack)
B(-6,46,-4,minecraft:netherrack)
B(-6,47,-4,minecraft:netherrack)
B(-6,48,-4,minecraft:netherrack)
B(-6,49,-4,minecraft:netherrack)
B(-6,50,-4,minecraft:netherrack)
B(-6,51,-4,minecraft:netherrack)
B(-6,52,-4,minecraft:netherrack)
B(-6,53,-4,minecraft:netherrack)
B(-6,54,-4,minecraft:netherrack)
B(-6,55,-4,minecraft:netherrack)
B(-6,56,-4,minecraft:netherrack)
B(-6,57,-4,minecraft:netherrack)
B(-6,58,-4,minecraft:netherrack)
B(-6,59,-4,minecraft:netherrack)
B(-6,60,-4,minecraft:netherrack)
B(-6,61,-4,minecraft:netherrack)
B(-6,62,-4,minecraft:netherrack)
B(-6,63,-4,minecraft:netherrack)
B(-6,64,-4,minecraft:netherrack)
B(-6,65,-4,minecraft:netherrack)
B(-6,66,-4,minecraft:netherrack)
B(-6,67,-4,minecraft:netherrack)
B(-6,68,-4,minecraft:netherrack)
B(-6,69,-4,minecraft:netherrack)
B(-6,70,-4,minecraft:netherrack)
B(-6,71,-4,minecraft:netherrack)
B(-6,72,-4,minecraft:netherrack)
B(-6,73,-4,minecraft:netherrack)
B(-6,74,-4,minecraft:netherrack)
B(-6,75,-4,minecraft:netherrack)
B(-6,76,-4,minecraft:netherrack)
B(-6,77,-4,minecraft:netherrack)
B(-6,78,-4,minecraft:netherrack)
B(-6,79,-4,minecraft:netherrack)
B(-6,80,-4,minecraft:netherrack)
B(-6,81,-4,minecraft:netherrack)
B(-6,82,-4,minecraft:netherrack)
B(-6,83,-4,minecraft:netherrack)
B(-6,84,-4,minecraft:netherrack)
B(-6,85,-4,minecraft:netherrack)
B(-6,86,-4,minecraft:netherrack)
B(-6,87,-4,minecraft:netherrack)
B(-6,88,-4,minecraft:netherrack)
B(-6,89,-4,minecraft:netherrack)
B(-6,90,-4,minecraft:blackstone)
B(-6,37,-3,minecraft:netherrack)
B(-6,38,-3,minecraft:netherrack)
B(-6,39,-3,minecraft:netherrack)
B(-6,40,-3,minecraft:netherrack)
B(-6,41,-3,minecraft:netherrack)
B(-6,42,-3,minecraft:netherrack)
B(-6,43,-3,minecraft:netherrack)
B(-6,44,-3,minecraft:netherrack)
B(-6,45,-3,minecraft:netherrack)
B(-6,46,-3,minecraft:netherrack)
B(-6,47,-3,minecraft:netherrack)
B(-6,48,-3,minecraft:netherrack)
B(-6,49,-3,minecraft:netherrack)
B(-6,50,-3,minecraft:netherrack)
B(-6,51,-3,minecraft:netherrack)
B(-6,52,-3,minecraft:netherrack)
B(-6,53,-3,minecraft:netherrack)
B(-6,54,-3,minecraft:netherrack)
B(-6,55,-3,minecraft:netherrack)
B(-6,56,-3,minecraft:netherrack)
B(-6,57,-3,minecraft:netherrack)
B(-6,58,-3,minecraft:netherrack)
B(-6,59,-3,minecraft:netherrack)
B(-6,60,-3,minecraft:netherrack)
B(-6,61,-3,minecraft:netherrack)
B(-6,62,-3,minecraft:netherrack)
B(-6,63,-3,minecraft:netherrack)
B(-6,64,-3,minecraft:netherrack)
B(-6,65,-3,minecraft:netherrack)
B(-6,66,-3,minecraft:netherrack)
B(-6,67,-3,minecraft:netherrack)
B(-6,68,-3,minecraft:netherrack)
B(-6,69,-3,minecraft:netherrack)
B(-6,70,-3,minecraft:netherrack)
B(-6,71,-3,minecraft:netherrack)
B(-6,72,-3,minecraft:netherrack)
B(-6,73,-3,minecraft:netherrack)
B(-6,74,-3,minecraft:netherrack)
B(-6,75,-3,minecraft:netherrack)
B(-6,76,-3,minecraft:netherrack)
B(-6,77,-3,minecraft:netherrack)
B(-6,78,-3,minecraft:netherrack)
B(-6,79,-3,minecraft:netherrack)
B(-6,80,-3,minecraft:netherrack)
B(-6,81,-3,minecraft:netherrack)
B(-6,82,-3,minecraft:netherrack)
B(-6,83,-3,minecraft:netherrack)
B(-6,84,-3,minecraft:netherrack)
B(-6,85,-3,minecraft:netherrack)
B(-6,86,-3,minecraft:netherrack)
B(-6,87,-3,minecraft:netherrack)
B(-6,88,-3,minecraft:netherrack)
B(-6,89,-3,minecraft:netherrack)
B(-6,90,-3,minecraft:blackstone)
B(-6,53,-2,minecraft:netherrack)
B(-6,54,-2,minecraft:netherrack)
B(-6,55,-2,minecraft:netherrack)
B(-6,56,-2,minecraft:netherrack)
B(-6,57,-2,minecraft:netherrack)
B(-6,58,-2,minecraft:netherrack)
B(-6,59,-2,minecraft:netherrack)
B(-6,60,-2,minecraft:netherrack)
B(-6,61,-2,minecraft:netherrack)
B(-6,62,-2,minecraft:netherrack)
B(-6,63,-2,minecraft:netherrack)
B(-6,64,-2,minecraft:netherrack)
B(-6,65,-2,minecraft:netherrack)
B(-6,66,-2,minecraft:netherrack)
B(-6,67,-2,minecraft:netherrack)
B(-6,68,-2,minecraft:netherrack)
B(-6,69,-2,minecraft:netherrack)
B(-6,70,-2,minecraft:netherrack)
B(-6,71,-2,minecraft:netherrack)
B(-6,72,-2,minecraft:netherrack)
B(-6,73,-2,minecraft:netherrack)
B(-6,74,-2,minecraft:netherrack)
B(-6,75,-2,minecraft:netherrack)
B(-6,76,-2,minecraft:netherrack)
B(-6,77,-2,minecraft:netherrack)
B(-6,78,-2,minecraft:netherrack)
B(-6,79,-2,minecraft:netherrack)
B(-6,80,-2,minecraft:netherrack)
B(-6,81,-2,minecraft:netherrack)
B(-6,82,-2,minecraft:netherrack)
B(-6,83,-2,minecraft:netherrack)
B(-6,84,-2,minecraft:netherrack)
B(-6,85,-2,minecraft:netherrack)
B(-6,86,-2,minecraft:netherrack)
B(-6,87,-2,minecraft:netherrack)
B(-6,88,-2,minecraft:netherrack)
B(-6,89,-2,minecraft:blackstone)
B(-6,90,-2,minecraft:blackstone)
B(-6,47,-1,minecraft:netherrack)
B(-6,48,-1,minecraft:netherrack)
B(-6,49,-1,minecraft:netherrack)
B(-6,50,-1,minecraft:netherrack)
B(-6,51,-1,minecraft:netherrack)
B(-6,52,-1,minecraft:netherrack)
B(-6,53,-1,minecraft:netherrack)
B(-6,54,-1,minecraft:netherrack)
B(-6,55,-1,minecraft:netherrack)
B(-6,56,-1,minecraft:netherrack)
B(-6,57,-1,minecraft:netherrack)
B(-6,58,-1,minecraft:netherrack)
B(-6,59,-1,minecraft:netherrack)
B(-6,60,-1,minecraft:netherrack)
B(-6,61,-1,minecraft:netherrack)
B(-6,62,-1,minecraft:netherrack)
B(-6,63,-1,minecraft:netherrack)
B(-6,64,-1,minecraft:netherrack)
B(-6,65,-1,minecraft:netherrack)
B(-6,66,-1,minecraft:netherrack)
B(-6,67,-1,minecraft:netherrack)
B(-6,68,-1,minecraft:netherrack)
B(-6,69,-1,minecraft:netherrack)
B(-6,70,-1,minecraft:netherrack)
B(-6,71,-1,minecraft:netherrack)
B(-6,72,-1,minecraft:netherrack)
B(-6,73,-1,minecraft:netherrack)
B(-6,74,-1,minecraft:netherrack)
B(-6,75,-1,minecraft:netherrack)
B(-6,76,-1,minecraft:netherrack)
B(-6,77,-1,minecraft:netherrack)
B(-6,78,-1,minecraft:netherrack)
B(-6,79,-1,minecraft:netherrack)
B(-6,80,-1,minecraft:netherrack)
B(-6,81,-1,minecraft:netherrack)
B(-6,82,-1,minecraft:netherrack)
B(-6,83,-1,minecraft:netherrack)
B(-6,84,-1,minecraft:netherrack)
B(-6,85,-1,minecraft:netherrack)
B(-6,86,-1,minecraft:netherrack)
B(-6,87,-1,minecraft:netherrack)
B(-6,88,-1,minecraft:blackstone)
B(-6,89,-1,minecraft:blackstone)
B(-6,90,-1,minecraft:blackstone)
B(-6,39,0,minecraft:netherrack)
B(-6,40,0,minecraft:netherrack)
B(-6,41,0,minecraft:netherrack)
B(-6,42,0,minecraft:netherrack)
B(-6,43,0,minecraft:netherrack)
B(-6,44,0,minecraft:netherrack)
B(-6,45,0,minecraft:netherrack)
B(-6,46,0,minecraft:netherrack)
B(-6,47,0,minecraft:netherrack)
B(-6,48,0,minecraft:netherrack)
B(-6,49,0,minecraft:netherrack)
B(-6,50,0,minecraft:netherrack)
B(-6,51,0,minecraft:netherrack)
B(-6,52,0,minecraft:netherrack)
B(-6,53,0,minecraft:netherrack)
B(-6,54,0,minecraft:netherrack)
B(-6,55,0,minecraft:netherrack)
B(-6,56,0,minecraft:netherrack)
B(-6,57,0,minecraft:netherrack)
B(-6,58,0,minecraft:netherrack)
B(-6,59,0,minecraft:netherrack)
B(-6,60,0,minecraft:netherrack)
B(-6,61,0,minecraft:netherrack)
B(-6,62,0,minecraft:netherrack)
B(-6,63,0,minecraft:netherrack)
B(-6,64,0,minecraft:netherrack)
B(-6,65,0,minecraft:netherrack)
B(-6,66,0,minecraft:netherrack)
B(-6,67,0,minecraft:netherrack)
B(-6,68,0,minecraft:netherrack)
B(-6,69,0,minecraft:netherrack)
B(-6,70,0,minecraft:netherrack)
B(-6,71,0,minecraft:netherrack)
B(-6,72,0,minecraft:netherrack)
B(-6,73,0,minecraft:netherrack)
B(-6,74,0,minecraft:netherrack)
B(-6,75,0,minecraft:netherrack)
B(-6,76,0,minecraft:netherrack)
B(-6,77,0,minecraft:netherrack)
B(-6,78,0,minecraft:netherrack)
B(-6,79,0,minecraft:netherrack)
B(-6,80,0,minecraft:netherrack)
B(-6,81,0,minecraft:netherrack)
B(-6,82,0,minecraft:netherrack)
B(-6,83,0,minecraft:netherrack)
B(-6,84,0,minecraft:netherrack)
B(-6,85,0,minecraft:netherrack)
B(-6,86,0,minecraft:netherrack)
B(-6,87,0,minecraft:netherrack)
B(-6,88,0,minecraft:blackstone)
B(-6,89,0,minecraft:blackstone)
B(-6,90,0,minecraft:blackstone)
B(-6,39,1,minecraft:netherrack)
B(-6,40,1,minecraft:netherrack)
B(-6,41,1,minecraft:netherrack)
B(-6,42,1,minecraft:netherrack)
B(-6,43,1,minecraft:netherrack)
B(-6,44,1,minecraft:netherrack)
B(-6,45,1,minecraft:netherrack)
B(-6,46,1,minecraft:netherrack)
B(-6,47,1,minecraft:netherrack)
B(-6,48,1,minecraft:netherrack)
B(-6,49,1,minecraft:netherrack)
B(-6,50,1,minecraft:netherrack)
B(-6,51,1,minecraft:netherrack)
B(-6,52,1,minecraft:netherrack)
B(-6,53,1,minecraft:netherrack)
B(-6,54,1,minecraft:netherrack)
B(-6,55,1,minecraft:netherrack)
B(-6,56,1,minecraft:netherrack)
B(-6,57,1,minecraft:netherrack)
B(-6,58,1,minecraft:netherrack)
B(-6,59,1,minecraft:netherrack)
B(-6,60,1,minecraft:netherrack)
B(-6,61,1,minecraft:netherrack)
B(-6,62,1,minecraft:netherrack)
B(-6,63,1,minecraft:netherrack)
B(-6,64,1,minecraft:netherrack)
B(-6,65,1,minecraft:netherrack)
B(-6,66,1,minecraft:netherrack)
B(-6,67,1,minecraft:netherrack)
B(-6,68,1,minecraft:netherrack)
B(-6,69,1,minecraft:netherrack)
B(-6,70,1,minecraft:netherrack)
B(-6,71,1,minecraft:netherrack)
B(-6,72,1,minecraft:netherrack)
B(-6,73,1,minecraft:netherrack)
B(-6,74,1,minecraft:netherrack)
B(-6,75,1,minecraft:netherrack)
B(-6,76,1,minecraft:netherrack)
B(-6,77,1,minecraft:netherrack)
B(-6,78,1,minecraft:netherrack)
B(-6,79,1,minecraft:netherrack)
B(-6,80,1,minecraft:netherrack)
B(-6,81,1,minecraft:netherrack)
B(-6,82,1,minecraft:netherrack)
B(-6,83,1,minecraft:netherrack)
B(-6,84,1,minecraft:netherrack)
B(-6,85,1,minecraft:netherrack)
B(-6,86,1,minecraft:netherrack)
B(-6,87,1,minecraft:netherrack)
B(-6,88,1,minecraft:blackstone)
B(-6,89,1,minecraft:blackstone)
B(-6,90,1,minecraft:blackstone)
B(-6,41,2,minecraft:netherrack)
B(-6,42,2,minecraft:netherrack)
B(-6,43,2,minecraft:netherrack)
B(-6,44,2,minecraft:netherrack)
B(-6,45,2,minecraft:netherrack)
B(-6,46,2,minecraft:netherrack)
B(-6,47,2,minecraft:netherrack)
B(-6,48,2,minecraft:netherrack)
B(-6,49,2,minecraft:netherrack)
B(-6,50,2,minecraft:netherrack)
B(-6,51,2,minecraft:netherrack)
B(-6,52,2,minecraft:netherrack)
B(-6,53,2,minecraft:netherrack)
B(-6,54,2,minecraft:netherrack)
B(-6,55,2,minecraft:netherrack)
B(-6,56,2,minecraft:netherrack)
B(-6,57,2,minecraft:netherrack)
B(-6,58,2,minecraft:netherrack)
B(-6,59,2,minecraft:netherrack)
B(-6,60,2,minecraft:netherrack)
B(-6,61,2,minecraft:netherrack)
B(-6,62,2,minecraft:netherrack)
B(-6,63,2,minecraft:netherrack)
B(-6,64,2,minecraft:netherrack)
B(-6,65,2,minecraft:netherrack)
B(-6,66,2,minecraft:netherrack)
B(-6,67,2,minecraft:netherrack)
B(-6,68,2,minecraft:netherrack)
B(-6,69,2,minecraft:netherrack)
B(-6,70,2,minecraft:netherrack)
B(-6,71,2,minecraft:netherrack)
B(-6,72,2,minecraft:netherrack)
B(-6,73,2,minecraft:netherrack)
B(-6,74,2,minecraft:netherrack)
B(-6,75,2,minecraft:netherrack)
B(-6,76,2,minecraft:netherrack)
B(-6,77,2,minecraft:netherrack)
B(-6,78,2,minecraft:netherrack)
B(-6,79,2,minecraft:netherrack)
B(-6,80,2,minecraft:netherrack)
B(-6,81,2,minecraft:netherrack)
B(-6,82,2,minecraft:netherrack)
B(-6,83,2,minecraft:netherrack)
B(-6,84,2,minecraft:netherrack)
B(-6,85,2,minecraft:netherrack)
B(-6,86,2,minecraft:netherrack)
B(-6,87,2,minecraft:netherrack)
B(-6,88,2,minecraft:netherrack)
B(-6,89,2,minecraft:blackstone)
B(-6,90,2,minecraft:blackstone)
B(-6,40,3,minecraft:netherrack)
B(-6,41,3,minecraft:netherrack)
B(-6,42,3,minecraft:netherrack)
B(-6,43,3,minecraft:netherrack)
B(-6,44,3,minecraft:netherrack)
B(-6,45,3,minecraft:netherrack)
B(-6,46,3,minecraft:netherrack)
B(-6,47,3,minecraft:netherrack)
B(-6,48,3,minecraft:netherrack)
B(-6,49,3,minecraft:netherrack)
B(-6,50,3,minecraft:netherrack)
B(-6,51,3,minecraft:netherrack)
B(-6,52,3,minecraft:netherrack)
B(-6,53,3,minecraft:netherrack)
B(-6,54,3,minecraft:netherrack)
B(-6,55,3,minecraft:netherrack)
B(-6,56,3,minecraft:netherrack)
B(-6,57,3,minecraft:netherrack)
B(-6,58,3,minecraft:netherrack)
B(-6,59,3,minecraft:netherrack)
B(-6,60,3,minecraft:netherrack)
B(-6,61,3,minecraft:netherrack)
B(-6,62,3,minecraft:netherrack)
B(-6,63,3,minecraft:netherrack)
B(-6,64,3,minecraft:netherrack)
B(-6,65,3,minecraft:netherrack)
B(-6,66,3,minecraft:netherrack)
B(-6,67,3,minecraft:netherrack)
B(-6,68,3,minecraft:netherrack)
B(-6,69,3,minecraft:netherrack)
B(-6,70,3,minecraft:netherrack)
B(-6,71,3,minecraft:netherrack)
B(-6,72,3,minecraft:netherrack)
B(-6,73,3,minecraft:netherrack)
B(-6,74,3,minecraft:netherrack)
B(-6,75,3,minecraft:netherrack)
B(-6,76,3,minecraft:netherrack)
B(-6,77,3,minecraft:netherrack)
B(-6,78,3,minecraft:netherrack)
B(-6,79,3,minecraft:netherrack)
B(-6,80,3,minecraft:netherrack)
B(-6,81,3,minecraft:netherrack)
B(-6,82,3,minecraft:netherrack)
B(-6,83,3,minecraft:netherrack)
B(-6,84,3,minecraft:netherrack)
B(-6,85,3,minecraft:netherrack)
B(-6,86,3,minecraft:netherrack)
B(-6,87,3,minecraft:netherrack)
B(-6,88,3,minecraft:netherrack)
B(-6,89,3,minecraft:netherrack)
B(-6,90,3,minecraft:blackstone)
B(-6,43,4,minecraft:netherrack)
B(-6,44,4,minecraft:netherrack)
B(-6,45,4,minecraft:netherrack)
B(-6,46,4,minecraft:netherrack)
B(-6,47,4,minecraft:netherrack)
B(-6,48,4,minecraft:netherrack)
B(-6,49,4,minecraft:netherrack)
B(-6,50,4,minecraft:netherrack)
B(-6,51,4,minecraft:netherrack)
B(-6,52,4,minecraft:netherrack)
B(-6,53,4,minecraft:netherrack)
B(-6,54,4,minecraft:netherrack)
B(-6,55,4,minecraft:netherrack)
B(-6,56,4,minecraft:netherrack)
B(-6,57,4,minecraft:netherrack)
B(-6,58,4,minecraft:netherrack)
B(-6,59,4,minecraft:netherrack)
B(-6,60,4,minecraft:netherrack)
B(-6,61,4,minecraft:netherrack)
B(-6,62,4,minecraft:netherrack)
B(-6,63,4,minecraft:netherrack)
B(-6,64,4,minecraft:netherrack)
B(-6,65,4,minecraft:netherrack)
B(-6,66,4,minecraft:netherrack)
B(-6,67,4,minecraft:netherrack)
B(-6,68,4,minecraft:netherrack)
B(-6,69,4,minecraft:netherrack)
B(-6,70,4,minecraft:netherrack)
B(-6,71,4,minecraft:netherrack)
B(-6,72,4,minecraft:netherrack)
B(-6,73,4,minecraft:netherrack)
B(-6,74,4,minecraft:netherrack)
B(-6,75,4,minecraft:netherrack)
B(-6,76,4,minecraft:netherrack)
B(-6,77,4,minecraft:netherrack)
B(-6,78,4,minecraft:netherrack)
B(-6,79,4,minecraft:netherrack)
B(-6,80,4,minecraft:netherrack)
B(-6,81,4,minecraft:netherrack)
B(-6,82,4,minecraft:netherrack)
B(-6,83,4,minecraft:netherrack)
B(-6,84,4,minecraft:netherrack)
B(-6,85,4,minecraft:netherrack)
B(-6,86,4,minecraft:netherrack)
B(-6,87,4,minecraft:netherrack)
B(-6,88,4,minecraft:netherrack)
B(-6,89,4,minecraft:netherrack)
B(-6,90,4,minecraft:blackstone)
B(-6,47,5,minecraft:netherrack)
B(-6,48,5,minecraft:netherrack)
B(-6,49,5,minecraft:netherrack)
B(-6,50,5,minecraft:netherrack)
B(-6,51,5,minecraft:netherrack)
B(-6,52,5,minecraft:netherrack)
B(-6,53,5,minecraft:netherrack)
B(-6,54,5,minecraft:netherrack)
B(-6,55,5,minecraft:netherrack)
B(-6,56,5,minecraft:netherrack)
B(-6,57,5,minecraft:netherrack)
B(-6,58,5,minecraft:netherrack)
B(-6,59,5,minecraft:netherrack)
B(-6,60,5,minecraft:netherrack)
B(-6,61,5,minecraft:netherrack)
B(-6,62,5,minecraft:netherrack)
B(-6,63,5,minecraft:netherrack)
B(-6,64,5,minecraft:netherrack)
B(-6,65,5,minecraft:netherrack)
B(-6,66,5,minecraft:netherrack)
B(-6,67,5,minecraft:netherrack)
B(-6,68,5,minecraft:netherrack)
B(-6,69,5,minecraft:netherrack)
B(-6,70,5,minecraft:netherrack)
B(-6,71,5,minecraft:netherrack)
B(-6,72,5,minecraft:netherrack)
B(-6,73,5,minecraft:netherrack)
B(-6,74,5,minecraft:netherrack)
B(-6,75,5,minecraft:netherrack)
B(-6,76,5,minecraft:netherrack)
B(-6,77,5,minecraft:netherrack)
B(-6,78,5,minecraft:netherrack)
B(-6,79,5,minecraft:netherrack)
B(-6,80,5,minecraft:netherrack)
B(-6,81,5,minecraft:netherrack)
B(-6,82,5,minecraft:netherrack)
B(-6,83,5,minecraft:netherrack)
B(-6,84,5,minecraft:netherrack)
B(-6,85,5,minecraft:netherrack)
B(-6,86,5,minecraft:netherrack)
B(-6,87,5,minecraft:netherrack)
B(-6,88,5,minecraft:netherrack)
B(-6,89,5,minecraft:netherrack)
B(-6,90,5,minecraft:blackstone)
B(-6,57,6,minecraft:netherrack)
B(-6,58,6,minecraft:netherrack)
B(-6,59,6,minecraft:netherrack)
B(-6,60,6,minecraft:netherrack)
B(-6,61,6,minecraft:netherrack)
B(-6,62,6,minecraft:netherrack)
B(-6,63,6,minecraft:netherrack)
B(-6,64,6,minecraft:netherrack)
B(-6,65,6,minecraft:netherrack)
B(-6,66,6,minecraft:netherrack)
B(-6,67,6,minecraft:netherrack)
B(-6,68,6,minecraft:netherrack)
B(-6,69,6,minecraft:netherrack)
B(-6,70,6,minecraft:netherrack)
B(-6,71,6,minecraft:netherrack)
B(-6,72,6,minecraft:netherrack)
B(-6,73,6,minecraft:netherrack)
B(-6,74,6,minecraft:netherrack)
B(-6,75,6,minecraft:netherrack)
B(-6,76,6,minecraft:netherrack)
B(-6,77,6,minecraft:netherrack)
B(-6,78,6,minecraft:netherrack)
B(-6,79,6,minecraft:netherrack)
B(-6,80,6,minecraft:netherrack)
B(-6,81,6,minecraft:netherrack)
B(-6,82,6,minecraft:netherrack)
B(-6,83,6,minecraft:netherrack)
B(-6,84,6,minecraft:netherrack)
B(-6,85,6,minecraft:netherrack)
B(-6,86,6,minecraft:netherrack)
B(-6,87,6,minecraft:netherrack)
B(-6,88,6,minecraft:netherrack)
B(-6,89,6,minecraft:blackstone)
B(-6,90,6,minecraft:blackstone)
B(-6,68,7,minecraft:netherrack)
B(-6,69,7,minecraft:netherrack)
B(-6,70,7,minecraft:netherrack)
B(-6,71,7,minecraft:netherrack)
B(-6,72,7,minecraft:netherrack)
B(-6,73,7,minecraft:netherrack)
B(-6,74,7,minecraft:netherrack)
B(-6,75,7,minecraft:netherrack)
B(-6,76,7,minecraft:netherrack)
B(-6,77,7,minecraft:netherrack)
B(-6,78,7,minecraft:netherrack)
B(-6,79,7,minecraft:netherrack)
B(-6,80,7,minecraft:netherrack)
B(-6,81,7,minecraft:netherrack)
B(-6,82,7,minecraft:netherrack)
B(-6,83,7,minecraft:netherrack)
B(-6,84,7,minecraft:netherrack)
B(-6,85,7,minecraft:netherrack)
B(-6,86,7,minecraft:netherrack)
B(-6,87,7,minecraft:netherrack)
B(-6,88,7,minecraft:netherrack)
B(-6,89,7,minecraft:netherrack)
B(-6,90,7,minecraft:blackstone)
B(-6,85,8,minecraft:netherrack)
B(-6,86,8,minecraft:netherrack)
B(-6,87,8,minecraft:netherrack)
B(-6,88,8,minecraft:netherrack)
B(-6,89,8,minecraft:netherrack)
B(-6,90,8,minecraft:netherrack)
B(-5,51,-7,minecraft:netherrack)
B(-5,52,-7,minecraft:netherrack)
B(-5,53,-7,minecraft:netherrack)
B(-5,54,-7,minecraft:netherrack)
B(-5,55,-7,minecraft:netherrack)
B(-5,56,-7,minecraft:netherrack)
B(-5,57,-7,minecraft:netherrack)
B(-5,58,-7,minecraft:netherrack)
B(-5,59,-7,minecraft:netherrack)
B(-5,60,-7,minecraft:netherrack)
B(-5,61,-7,minecraft:netherrack)
B(-5,62,-7,minecraft:netherrack)
B(-5,63,-7,minecraft:netherrack)
B(-5,64,-7,minecraft:netherrack)
B(-5,65,-7,minecraft:netherrack)
B(-5,66,-7,minecraft:netherrack)
B(-5,67,-7,minecraft:netherrack)
B(-5,68,-7,minecraft:netherrack)
B(-5,69,-7,minecraft:netherrack)
B(-5,70,-7,minecraft:netherrack)
B(-5,71,-7,minecraft:netherrack)
B(-5,72,-7,minecraft:netherrack)
B(-5,73,-7,minecraft:netherrack)
B(-5,74,-7,minecraft:netherrack)
B(-5,75,-7,minecraft:netherrack)
B(-5,76,-7,minecraft:netherrack)
B(-5,77,-7,minecraft:netherrack)
B(-5,78,-7,minecraft:netherrack)
B(-5,79,-7,minecraft:netherrack)
B(-5,80,-7,minecraft:netherrack)
B(-5,81,-7,minecraft:netherrack)
B(-5,82,-7,minecraft:netherrack)
B(-5,83,-7,minecraft:netherrack)
B(-5,84,-7,minecraft:netherrack)
B(-5,85,-7,minecraft:netherrack)
B(-5,86,-7,minecraft:netherrack)
B(-5,87,-7,minecraft:netherrack)
B(-5,88,-7,minecraft:blackstone)
B(-5,89,-7,minecraft:blackstone)
B(-5,90,-7,minecraft:blackstone)
B(-5,48,-6,minecraft:netherrack)
B(-5,49,-6,minecraft:netherrack)
B(-5,50,-6,minecraft:netherrack)
B(-5,51,-6,minecraft:netherrack)
B(-5,52,-6,minecraft:netherrack)
B(-5,53,-6,minecraft:netherrack)
B(-5,54,-6,minecraft:netherrack)
B(-5,55,-6,minecraft:netherrack)
B(-5,56,-6,minecraft:netherrack)
B(-5,57,-6,minecraft:netherrack)
B(-5,58,-6,minecraft:netherrack)
B(-5,59,-6,minecraft:netherrack)
B(-5,60,-6,minecraft:netherrack)
B(-5,61,-6,minecraft:netherrack)
B(-5,62,-6,minecraft:netherrack)
B(-5,63,-6,minecraft:netherrack)
B(-5,64,-6,minecraft:netherrack)
B(-5,65,-6,minecraft:netherrack)
B(-5,66,-6,minecraft:netherrack)
B(-5,67,-6,minecraft:netherrack)
B(-5,68,-6,minecraft:netherrack)
B(-5,69,-6,minecraft:netherrack)
B(-5,70,-6,minecraft:netherrack)
B(-5,71,-6,minecraft:netherrack)
B(-5,72,-6,minecraft:netherrack)
B(-5,73,-6,minecraft:netherrack)
B(-5,74,-6,minecraft:netherrack)
B(-5,75,-6,minecraft:netherrack)
B(-5,76,-6,minecraft:netherrack)
B(-5,77,-6,minecraft:netherrack)
B(-5,78,-6,minecraft:netherrack)
B(-5,79,-6,minecraft:netherrack)
B(-5,80,-6,minecraft:netherrack)
B(-5,81,-6,minecraft:netherrack)
B(-5,82,-6,minecraft:netherrack)
B(-5,83,-6,minecraft:netherrack)
B(-5,84,-6,minecraft:netherrack)
B(-5,85,-6,minecraft:netherrack)
B(-5,86,-6,minecraft:netherrack)
B(-5,87,-6,minecraft:netherrack)
B(-5,88,-6,minecraft:blackstone)
B(-5,89,-6,minecraft:blackstone)
B(-5,90,-6,minecraft:blackstone)
B(-5,48,-5,minecraft:netherrack)
B(-5,49,-5,minecraft:netherrack)
B(-5,50,-5,minecraft:netherrack)
B(-5,51,-5,minecraft:netherrack)
B(-5,52,-5,minecraft:netherrack)
B(-5,53,-5,minecraft:netherrack)
B(-5,54,-5,minecraft:netherrack)
B(-5,55,-5,minecraft:netherrack)
B(-5,56,-5,minecraft:netherrack)
B(-5,57,-5,minecraft:netherrack)
B(-5,58,-5,minecraft:netherrack)
B(-5,59,-5,minecraft:netherrack)
B(-5,60,-5,minecraft:netherrack)
B(-5,61,-5,minecraft:netherrack)
B(-5,62,-5,minecraft:netherrack)
B(-5,63,-5,minecraft:netherrack)
B(-5,64,-5,minecraft:netherrack)
B(-5,65,-5,minecraft:netherrack)
B(-5,66,-5,minecraft:netherrack)
B(-5,67,-5,minecraft:netherrack)
B(-5,68,-5,minecraft:netherrack)
B(-5,69,-5,minecraft:netherrack)
B(-5,70,-5,minecraft:netherrack)
B(-5,71,-5,minecraft:netherrack)
B(-5,72,-5,minecraft:netherrack)
B(-5,73,-5,minecraft:netherrack)
B(-5,74,-5,minecraft:netherrack)
B(-5,75,-5,minecraft:netherrack)
B(-5,76,-5,minecraft:netherrack)
B(-5,77,-5,minecraft:netherrack)
B(-5,78,-5,minecraft:netherrack)
B(-5,79,-5,minecraft:netherrack)
B(-5,80,-5,minecraft:netherrack)
B(-5,81,-5,minecraft:netherrack)
B(-5,82,-5,minecraft:netherrack)
B(-5,83,-5,minecraft:netherrack)
B(-5,84,-5,minecraft:netherrack)
B(-5,85,-5,minecraft:netherrack)
B(-5,86,-5,minecraft:netherrack)
B(-5,87,-5,minecraft:netherrack)
B(-5,88,-5,minecraft:blackstone)
B(-5,89,-5,minecraft:blackstone)
B(-5,90,-5,minecraft:blackstone)
B(-5,49,-4,minecraft:netherrack)
B(-5,50,-4,minecraft:netherrack)
B(-5,51,-4,minecraft:netherrack)
B(-5,52,-4,minecraft:netherrack)
B(-5,53,-4,minecraft:netherrack)
B(-5,54,-4,minecraft:netherrack)
B(-5,55,-4,minecraft:netherrack)
B(-5,56,-4,minecraft:netherrack)
B(-5,57,-4,minecraft:netherrack)
B(-5,58,-4,minecraft:netherrack)
B(-5,59,-4,minecraft:netherrack)
B(-5,60,-4,minecraft:netherrack)
B(-5,61,-4,minecraft:netherrack)
B(-5,62,-4,minecraft:netherrack)
B(-5,63,-4,minecraft:netherrack)
B(-5,64,-4,minecraft:netherrack)
B(-5,65,-4,minecraft:netherrack)
B(-5,66,-4,minecraft:netherrack)
B(-5,67,-4,minecraft:netherrack)
B(-5,68,-4,minecraft:netherrack)
B(-5,69,-4,minecraft:netherrack)
B(-5,70,-4,minecraft:netherrack)
B(-5,71,-4,minecraft:netherrack)
B(-5,72,-4,minecraft:netherrack)
B(-5,73,-4,minecraft:netherrack)
B(-5,74,-4,minecraft:netherrack)
B(-5,75,-4,minecraft:netherrack)
B(-5,76,-4,minecraft:netherrack)
B(-5,77,-4,minecraft:netherrack)
B(-5,78,-4,minecraft:netherrack)
B(-5,79,-4,minecraft:netherrack)
B(-5,80,-4,minecraft:netherrack)
B(-5,81,-4,minecraft:netherrack)
B(-5,82,-4,minecraft:netherrack)
B(-5,83,-4,minecraft:netherrack)
B(-5,84,-4,minecraft:netherrack)
B(-5,85,-4,minecraft:netherrack)
B(-5,86,-4,minecraft:netherrack)
B(-5,87,-4,minecraft:netherrack)
B(-5,88,-4,minecraft:blackstone)
B(-5,89,-4,minecraft:blackstone)
B(-5,90,-4,minecraft:blackstone)
B(-5,56,-3,minecraft:netherrack)
B(-5,57,-3,minecraft:netherrack)
B(-5,58,-3,minecraft:netherrack)
B(-5,59,-3,minecraft:netherrack)
B(-5,60,-3,minecraft:netherrack)
B(-5,61,-3,minecraft:netherrack)
B(-5,62,-3,minecraft:netherrack)
B(-5,63,-3,minecraft:netherrack)
B(-5,64,-3,minecraft:netherrack)
B(-5,65,-3,minecraft:netherrack)
B(-5,66,-3,minecraft:netherrack)
B(-5,67,-3,minecraft:netherrack)
B(-5,68,-3,minecraft:netherrack)
B(-5,69,-3,minecraft:netherrack)
B(-5,70,-3,minecraft:netherrack)
B(-5,71,-3,minecraft:netherrack)
B(-5,72,-3,minecraft:netherrack)
B(-5,73,-3,minecraft:netherrack)
B(-5,74,-3,minecraft:netherrack)
B(-5,75,-3,minecraft:netherrack)
B(-5,76,-3,minecraft:netherrack)
B(-5,77,-3,minecraft:netherrack)
B(-5,78,-3,minecraft:netherrack)
