Author: Bo3 BulkEdit

Description: Converted Schematic - Modified by Bo3BulkEdit

Version: 3

SettingsMode: WriteDisable

IsOTGPlus: true
Tree: false
Frequency: 10
Rarity: 100
RotateRandomly: true
SpawnHeight: randomY
SpawnHeightOffset: 0
SpawnHeightVariance: 0
MaxBranchDepth: 10
ExcludedBiomes: All

MinHeight: 50
MaxHeight: 65

SourceBlocks: AIR
MaxPercentageOutsideSourceBlock: 100
OutsideSourceBlock: placeAnyway

ReplaceBelow: BLACKSTONE
ReplaceWithBiomeBlocks: false
ReplaceWithGroundBlock: BLACKSTONE
ReplaceWithSurfaceBlock: BLACKSTONE
ReplaceWithStoneBlock: BLACKSTONE
SmoothRadius: 30
SmoothingSurfaceBlock: BLACKSTONE
SmoothingGroundBlock: BLACKSTONE

B(0,750,0,AIR)
B(15,750,15,AIR)
B(15,0,7,minecraft:blackstone)
B(12,0,8,minecraft:blackstone)
B(13,0,8,minecraft:blackstone)
B(14,0,8,minecraft:blackstone)
B(15,0,8,minecraft:blackstone)
B(11,0,9,minecraft:blackstone)
B(12,0,9,minecraft:blackstone)
B(13,0,9,minecraft:blackstone)
B(14,0,9,minecraft:blackstone)
B(15,0,9,minecraft:blackstone)
B(10,0,10,minecraft:blackstone)
B(11,0,10,minecraft:blackstone)
B(12,0,10,minecraft:blackstone)
B(13,0,10,minecraft:blackstone)
B(14,0,10,minecraft:blackstone)
B(15,0,10,minecraft:blackstone)
B(10,0,11,minecraft:blackstone)
B(11,0,11,minecraft:blackstone)
B(12,0,11,minecraft:blackstone)
B(13,0,11,minecraft:blackstone)
B(14,0,11,minecraft:blackstone)
B(15,0,11,minecraft:blackstone)
B(9,0,12,minecraft:blackstone)
B(10,0,12,minecraft:blackstone)
B(11,0,12,minecraft:blackstone)
B(12,0,12,minecraft:blackstone)
B(13,0,12,minecraft:blackstone)
B(14,0,12,minecraft:blackstone)
B(15,0,12,minecraft:blackstone)
B(10,0,13,minecraft:blackstone)
B(11,0,13,minecraft:blackstone)
B(12,0,13,minecraft:blackstone)
B(13,0,13,minecraft:blackstone)
B(14,0,13,minecraft:blackstone)
B(15,0,13,minecraft:blackstone)
B(10,0,14,minecraft:blackstone)
B(11,0,14,minecraft:blackstone)
B(12,0,14,minecraft:blackstone)
B(13,0,14,minecraft:blackstone)
B(14,0,14,minecraft:blackstone)
B(15,0,14,minecraft:blackstone)
B(10,0,15,minecraft:blackstone)
B(11,0,15,minecraft:blackstone)
B(12,0,15,minecraft:blackstone)
B(13,0,15,minecraft:blackstone)
B(14,0,15,minecraft:blackstone)
B(15,0,15,minecraft:blackstone)
B(13,1,8,minecraft:blackstone)
B(14,1,8,minecraft:blackstone)
B(15,1,8,minecraft:blackstone)
B(12,1,9,minecraft:blackstone)
B(13,1,9,minecraft:blackstone)
B(14,1,9,minecraft:blackstone)
B(15,1,9,minecraft:blackstone)
B(11,1,10,minecraft:blackstone)
B(12,1,10,minecraft:blackstone)
B(13,1,10,minecraft:blackstone)
B(14,1,10,minecraft:blackstone)
B(15,1,10,minecraft:blackstone)
B(10,1,11,minecraft:blackstone)
B(11,1,11,minecraft:blackstone)
B(12,1,11,minecraft:blackstone)
B(13,1,11,minecraft:blackstone)
B(14,1,11,minecraft:blackstone)
B(15,1,11,minecraft:blackstone)
B(10,1,12,minecraft:blackstone)
B(11,1,12,minecraft:blackstone)
B(12,1,12,minecraft:blackstone)
B(13,1,12,minecraft:blackstone)
B(14,1,12,minecraft:blackstone)
B(15,1,12,minecraft:blackstone)
B(10,1,13,minecraft:blackstone)
B(11,1,13,minecraft:blackstone)
B(12,1,13,minecraft:blackstone)
B(13,1,13,minecraft:blackstone)
B(14,1,13,minecraft:blackstone)
B(15,1,13,minecraft:blackstone)
B(10,1,14,minecraft:blackstone)
B(11,1,14,minecraft:blackstone)
B(12,1,14,minecraft:blackstone)
B(13,1,14,minecraft:blackstone)
B(14,1,14,minecraft:blackstone)
B(15,1,14,minecraft:blackstone)
B(10,1,15,minecraft:blackstone)
B(11,1,15,minecraft:blackstone)
B(12,1,15,minecraft:blackstone)
B(13,1,15,minecraft:blackstone)
B(14,1,15,minecraft:blackstone)
B(15,1,15,minecraft:blackstone)
B(14,2,8,minecraft:blackstone)
B(15,2,8,minecraft:blackstone)
B(12,2,9,minecraft:blackstone)
B(13,2,9,minecraft:blackstone)
B(14,2,9,minecraft:blackstone)
B(15,2,9,minecraft:blackstone)
B(11,2,10,minecraft:blackstone)
B(12,2,10,minecraft:blackstone)
B(13,2,10,minecraft:blackstone)
B(14,2,10,minecraft:blackstone)
B(15,2,10,minecraft:blackstone)
B(11,2,11,minecraft:blackstone)
B(12,2,11,minecraft:blackstone)
B(13,2,11,minecraft:blackstone)
B(14,2,11,minecraft:blackstone)
B(15,2,11,minecraft:blackstone)
B(10,2,12,minecraft:blackstone)
B(11,2,12,minecraft:blackstone)
B(12,2,12,minecraft:blackstone)
B(13,2,12,minecraft:blackstone)
B(14,2,12,minecraft:blackstone)
B(15,2,12,minecraft:blackstone)
B(10,2,13,minecraft:blackstone)
B(11,2,13,minecraft:blackstone)
B(12,2,13,minecraft:blackstone)
B(13,2,13,minecraft:blackstone)
B(14,2,13,minecraft:blackstone)
B(15,2,13,minecraft:blackstone)
B(10,2,14,minecraft:blackstone)
B(11,2,14,minecraft:blackstone)
B(12,2,14,minecraft:blackstone)
B(13,2,14,minecraft:blackstone)
B(14,2,14,minecraft:blackstone)
B(15,2,14,minecraft:blackstone)
B(10,2,15,minecraft:blackstone)
B(11,2,15,minecraft:blackstone)
B(12,2,15,minecraft:blackstone)
B(13,2,15,minecraft:blackstone)
B(14,2,15,minecraft:blackstone)
B(15,2,15,minecraft:blackstone)
B(14,3,8,minecraft:blackstone)
B(15,3,8,minecraft:blackstone)
B(13,3,9,minecraft:blackstone)
B(14,3,9,minecraft:blackstone)
B(15,3,9,minecraft:blackstone)
B(12,3,10,minecraft:blackstone)
B(13,3,10,minecraft:blackstone)
B(14,3,10,minecraft:blackstone)
B(15,3,10,minecraft:blackstone)
B(11,3,11,minecraft:blackstone)
B(12,3,11,minecraft:blackstone)
B(13,3,11,minecraft:blackstone)
B(14,3,11,minecraft:blackstone)
B(15,3,11,minecraft:blackstone)
B(11,3,12,minecraft:blackstone)
B(12,3,12,minecraft:blackstone)
B(13,3,12,minecraft:blackstone)
B(14,3,12,minecraft:blackstone)
B(15,3,12,minecraft:blackstone)
B(10,3,13,minecraft:blackstone)
B(11,3,13,minecraft:blackstone)
B(12,3,13,minecraft:blackstone)
B(13,3,13,minecraft:blackstone)
B(14,3,13,minecraft:blackstone)
B(15,3,13,minecraft:blackstone)
B(10,3,14,minecraft:blackstone)
B(11,3,14,minecraft:blackstone)
B(12,3,14,minecraft:blackstone)
B(13,3,14,minecraft:blackstone)
B(14,3,14,minecraft:blackstone)
B(15,3,14,minecraft:blackstone)
B(10,3,15,minecraft:blackstone)
B(11,3,15,minecraft:blackstone)
B(12,3,15,minecraft:blackstone)
B(13,3,15,minecraft:blackstone)
B(14,3,15,minecraft:blackstone)
B(15,3,15,minecraft:blackstone)
B(13,4,9,minecraft:blackstone)
B(14,4,9,minecraft:blackstone)
B(15,4,9,minecraft:blackstone)
B(12,4,10,minecraft:blackstone)
B(13,4,10,minecraft:blackstone)
B(14,4,10,minecraft:blackstone)
B(15,4,10,minecraft:blackstone)
B(12,4,11,minecraft:blackstone)
B(13,4,11,minecraft:blackstone)
B(14,4,11,minecraft:blackstone)
B(15,4,11,minecraft:blackstone)
B(11,4,12,minecraft:blackstone)
B(12,4,12,minecraft:blackstone)
B(13,4,12,minecraft:blackstone)
B(14,4,12,minecraft:blackstone)
B(15,4,12,minecraft:blackstone)
B(10,4,13,minecraft:blackstone)
B(11,4,13,minecraft:blackstone)
B(12,4,13,minecraft:blackstone)
B(13,4,13,minecraft:blackstone)
B(14,4,13,minecraft:blackstone)
B(15,4,13,minecraft:blackstone)
B(10,4,14,minecraft:blackstone)
B(11,4,14,minecraft:blackstone)
B(12,4,14,minecraft:blackstone)
B(13,4,14,minecraft:blackstone)
B(14,4,14,minecraft:blackstone)
B(15,4,14,minecraft:blackstone)
B(10,4,15,minecraft:blackstone)
B(11,4,15,minecraft:blackstone)
B(12,4,15,minecraft:blackstone)
B(13,4,15,minecraft:blackstone)
B(14,4,15,minecraft:blackstone)
B(15,4,15,minecraft:blackstone)
B(14,5,9,minecraft:blackstone)
B(15,5,9,minecraft:blackstone)
B(13,5,10,minecraft:blackstone)
B(14,5,10,minecraft:blackstone)
B(15,5,10,minecraft:blackstone)
B(12,5,11,minecraft:blackstone)
B(13,5,11,minecraft:blackstone)
B(14,5,11,minecraft:blackstone)
B(15,5,11,minecraft:blackstone)
B(12,5,12,minecraft:blackstone)
B(13,5,12,minecraft:blackstone)
B(14,5,12,minecraft:blackstone)
B(15,5,12,minecraft:blackstone)
B(10,5,13,minecraft:blackstone)
B(11,5,13,minecraft:blackstone)
B(12,5,13,minecraft:blackstone)
B(13,5,13,minecraft:blackstone)
B(14,5,13,minecraft:blackstone)
B(15,5,13,minecraft:blackstone)
B(10,5,14,minecraft:blackstone)
B(11,5,14,minecraft:blackstone)
B(12,5,14,minecraft:blackstone)
B(13,5,14,minecraft:blackstone)
B(14,5,14,minecraft:blackstone)
B(15,5,14,minecraft:blackstone)
B(10,5,15,minecraft:blackstone)
B(11,5,15,minecraft:blackstone)
B(12,5,15,minecraft:blackstone)
B(13,5,15,minecraft:blackstone)
B(14,5,15,minecraft:blackstone)
B(15,5,15,minecraft:blackstone)
B(15,6,9,minecraft:blackstone)
B(13,6,10,minecraft:blackstone)
B(14,6,10,minecraft:blackstone)
B(15,6,10,minecraft:blackstone)
B(12,6,11,minecraft:blackstone)
B(13,6,11,minecraft:blackstone)
B(14,6,11,minecraft:blackstone)
B(15,6,11,minecraft:blackstone)
B(12,6,12,minecraft:blackstone)
B(13,6,12,minecraft:blackstone)
B(14,6,12,minecraft:blackstone)
B(15,6,12,minecraft:blackstone)
B(10,6,13,minecraft:blackstone)
B(11,6,13,minecraft:blackstone)
B(12,6,13,minecraft:blackstone)
B(13,6,13,minecraft:blackstone)
B(14,6,13,minecraft:blackstone)
B(15,6,13,minecraft:blackstone)
B(10,6,14,minecraft:blackstone)
B(11,6,14,minecraft:blackstone)
B(12,6,14,minecraft:blackstone)
B(13,6,14,minecraft:blackstone)
B(14,6,14,minecraft:blackstone)
B(15,6,14,minecraft:blackstone)
B(10,6,15,minecraft:blackstone)
B(11,6,15,minecraft:blackstone)
B(12,6,15,minecraft:blackstone)
B(13,6,15,minecraft:blackstone)
B(14,6,15,minecraft:blackstone)
B(15,6,15,minecraft:blackstone)
B(14,7,10,minecraft:blackstone)
B(15,7,10,minecraft:blackstone)
B(13,7,11,minecraft:blackstone)
B(14,7,11,minecraft:blackstone)
B(15,7,11,minecraft:blackstone)
B(13,7,12,minecraft:blackstone)
B(14,7,12,minecraft:blackstone)
B(15,7,12,minecraft:blackstone)
B(11,7,13,minecraft:blackstone)
B(12,7,13,minecraft:blackstone)
B(13,7,13,minecraft:blackstone)
B(14,7,13,minecraft:blackstone)
B(15,7,13,minecraft:blackstone)
B(10,7,14,minecraft:blackstone)
B(11,7,14,minecraft:blackstone)
B(12,7,14,minecraft:blackstone)
B(13,7,14,minecraft:blackstone)
B(14,7,14,minecraft:blackstone)
B(15,7,14,minecraft:blackstone)
B(10,7,15,minecraft:blackstone)
B(11,7,15,minecraft:blackstone)
B(12,7,15,minecraft:blackstone)
B(13,7,15,minecraft:blackstone)
B(14,7,15,minecraft:blackstone)
B(15,7,15,minecraft:blackstone)
B(14,8,10,minecraft:blackstone)
B(15,8,10,minecraft:blackstone)
B(13,8,11,minecraft:blackstone)
B(14,8,11,minecraft:blackstone)
B(15,8,11,minecraft:blackstone)
B(13,8,12,minecraft:blackstone)
B(14,8,12,minecraft:blackstone)
B(15,8,12,minecraft:blackstone)
B(11,8,13,minecraft:blackstone)
B(12,8,13,minecraft:blackstone)
B(13,8,13,minecraft:blackstone)
B(14,8,13,minecraft:blackstone)
B(15,8,13,minecraft:blackstone)
B(10,8,14,minecraft:blackstone)
B(11,8,14,minecraft:blackstone)
B(12,8,14,minecraft:blackstone)
B(13,8,14,minecraft:blackstone)
B(14,8,14,minecraft:blackstone)
B(15,8,14,minecraft:blackstone)
B(10,8,15,minecraft:blackstone)
B(11,8,15,minecraft:blackstone)
B(12,8,15,minecraft:blackstone)
B(13,8,15,minecraft:blackstone)
B(14,8,15,minecraft:blackstone)
B(15,8,15,minecraft:blackstone)
B(15,9,10,minecraft:blackstone)
B(14,9,11,minecraft:blackstone)
B(15,9,11,minecraft:blackstone)
B(13,9,12,minecraft:blackstone)
B(14,9,12,minecraft:blackstone)
B(15,9,12,minecraft:blackstone)
B(11,9,13,minecraft:blackstone)
B(12,9,13,minecraft:blackstone)
B(13,9,13,minecraft:blackstone)
B(14,9,13,minecraft:blackstone)
B(15,9,13,minecraft:blackstone)
B(11,9,14,minecraft:blackstone)
B(12,9,14,minecraft:blackstone)
B(13,9,14,minecraft:blackstone)
B(14,9,14,minecraft:blackstone)
B(15,9,14,minecraft:blackstone)
B(10,9,15,minecraft:blackstone)
B(11,9,15,minecraft:blackstone)
B(12,9,15,minecraft:blackstone)
B(13,9,15,minecraft:blackstone)
B(14,9,15,minecraft:blackstone)
B(15,9,15,minecraft:blackstone)
B(15,10,10,minecraft:blackstone)
B(14,10,11,minecraft:blackstone)
B(15,10,11,minecraft:blackstone)
B(13,10,12,minecraft:blackstone)
B(14,10,12,minecraft:blackstone)
B(15,10,12,minecraft:blackstone)
B(12,10,13,minecraft:blackstone)
B(13,10,13,minecraft:blackstone)
B(14,10,13,minecraft:blackstone)
B(15,10,13,minecraft:blackstone)
B(11,10,14,minecraft:blackstone)
B(12,10,14,minecraft:blackstone)
B(13,10,14,minecraft:blackstone)
B(14,10,14,minecraft:blackstone)
B(15,10,14,minecraft:blackstone)
B(11,10,15,minecraft:blackstone)
B(12,10,15,minecraft:blackstone)
B(13,10,15,minecraft:blackstone)
B(14,10,15,minecraft:blackstone)
B(15,10,15,minecraft:blackstone)
B(14,11,11,minecraft:blackstone)
B(15,11,11,minecraft:blackstone)
B(14,11,12,minecraft:blackstone)
B(15,11,12,minecraft:blackstone)
B(12,11,13,minecraft:blackstone)
B(13,11,13,minecraft:blackstone)
B(14,11,13,minecraft:blackstone)
B(15,11,13,minecraft:blackstone)
B(11,11,14,minecraft:blackstone)
B(12,11,14,minecraft:blackstone)
B(13,11,14,minecraft:blackstone)
B(14,11,14,minecraft:blackstone)
B(15,11,14,minecraft:blackstone)
B(11,11,15,minecraft:blackstone)
B(12,11,15,minecraft:blackstone)
B(13,11,15,minecraft:blackstone)
B(14,11,15,minecraft:blackstone)
B(15,11,15,minecraft:blackstone)
B(14,12,11,minecraft:blackstone)
B(15,12,11,minecraft:blackstone)
B(14,12,12,minecraft:blackstone)
B(15,12,12,minecraft:blackstone)
B(12,12,13,minecraft:blackstone)
B(13,12,13,minecraft:blackstone)
B(14,12,13,minecraft:blackstone)
B(15,12,13,minecraft:blackstone)
B(11,12,14,minecraft:blackstone)
B(12,12,14,minecraft:blackstone)
B(13,12,14,minecraft:blackstone)
B(14,12,14,minecraft:blackstone)
B(15,12,14,minecraft:blackstone)
B(11,12,15,minecraft:blackstone)
B(12,12,15,minecraft:blackstone)
B(13,12,15,minecraft:blackstone)
B(14,12,15,minecraft:blackstone)
B(15,12,15,minecraft:blackstone)
B(14,13,11,minecraft:blackstone)
B(15,13,11,minecraft:blackstone)
B(14,13,12,minecraft:blackstone)
B(15,13,12,minecraft:blackstone)
B(12,13,13,minecraft:blackstone)
B(13,13,13,minecraft:blackstone)
B(14,13,13,minecraft:blackstone)
B(15,13,13,minecraft:blackstone)
B(11,13,14,minecraft:blackstone)
B(12,13,14,minecraft:blackstone)
B(13,13,14,minecraft:blackstone)
B(14,13,14,minecraft:blackstone)
B(15,13,14,minecraft:blackstone)
B(11,13,15,minecraft:blackstone)
B(12,13,15,minecraft:blackstone)
B(13,13,15,minecraft:blackstone)
B(14,13,15,minecraft:blackstone)
B(15,13,15,minecraft:blackstone)
B(15,14,11,minecraft:blackstone)
B(14,14,12,minecraft:blackstone)
B(15,14,12,minecraft:blackstone)
B(13,14,13,minecraft:blackstone)
B(14,14,13,minecraft:blackstone)
B(15,14,13,minecraft:blackstone)
B(12,14,14,minecraft:blackstone)
B(13,14,14,minecraft:blackstone)
B(14,14,14,minecraft:blackstone)
B(15,14,14,minecraft:blackstone)
B(11,14,15,minecraft:blackstone)
B(12,14,15,minecraft:blackstone)
B(13,14,15,minecraft:blackstone)
B(14,14,15,minecraft:blackstone)
B(15,14,15,minecraft:blackstone)
B(15,15,12,minecraft:blackstone)
B(14,15,13,minecraft:blackstone)
B(15,15,13,minecraft:blackstone)
B(13,15,14,minecraft:blackstone)
B(14,15,14,minecraft:blackstone)
B(15,15,14,minecraft:blackstone)
B(12,15,15,minecraft:blackstone)
B(13,15,15,minecraft:blackstone)
B(14,15,15,minecraft:blackstone)
B(15,15,15,minecraft:blackstone)
B(14,16,13,minecraft:blackstone)
B(15,16,13,minecraft:blackstone)
B(13,16,14,minecraft:blackstone)
B(14,16,14,minecraft:blackstone)
B(15,16,14,minecraft:blackstone)
B(13,16,15,minecraft:blackstone)
B(14,16,15,minecraft:blackstone)
B(15,16,15,minecraft:blackstone)
B(15,17,13,minecraft:blackstone)
B(14,17,14,minecraft:blackstone)
B(15,17,14,minecraft:blackstone)
B(13,17,15,minecraft:blackstone)
B(14,17,15,minecraft:blackstone)
B(15,17,15,minecraft:blackstone)
B(15,18,14,minecraft:blackstone)
B(14,18,15,minecraft:blackstone)
B(15,18,15,minecraft:blackstone)
B(15,19,14,minecraft:blackstone)
B(14,19,15,minecraft:blackstone)
B(15,19,15,minecraft:blackstone)
B(15,20,15,minecraft:blackstone)

BR(16,0,0,true,GiantBlackstoneStalacmite4_1x0,NORTH,100,0)
