
#######################################################################
# +-----------------------------------------------------------------+ #
# |                            BO4 object                           | #
# +-----------------------------------------------------------------+ #
#######################################################################

Author: Unknown

Description: No description given

SettingsMode: WriteWithoutComments


#######################################################################
# +-----------------------------------------------------------------+ #
# |                          Main settings                          | #
# +-----------------------------------------------------------------+ #
#######################################################################

FixedRotation: 

Frequency: 0

SpawnHeight: highestBlock

UseCenterForHighestBlock: true

##############################
# Height Limits for the BO4. #
##############################

MinHeight: 0

MaxHeight: 255

InheritBO3: 

InheritBO3Rotation: NORTH

OverrideChildSettings: true

OverrideParentHeight: false

CanOverride: false

BranchFrequency: 0

BranchFrequencyGroup: 

MustBeBelowOther: false

MustBeInside: 

CannotBeInside: 

ReplacesBO3: 

MustBeInsideWorldBorders: false

CanSpawnOnWater: true

SpawnOnWaterOnly: false

SpawnUnderWater: false

SpawnAtWaterLevel: false

HeightOffset: 0

RemoveAir: true

ReplaceAbove: 

ReplaceBelow: 

ReplaceWithBiomeBlocks: true

ReplaceWithSurfaceBlock: GRASS

ReplaceWithGroundBlock: DIRT

ReplaceWithStoneBlock: STONE

SmoothRadius: 0

SmoothHeightOffset: 0

SmoothStartTop: false

SmoothStartWood: false

SmoothingSurfaceBlock: 

SmoothingGroundBlock: 

BO3Group: 

IsSpawnPoint: false

DoReplaceBlocks: true


#######################################################################
# +-----------------------------------------------------------------+ #
# |                              Blocks                             | #
# +-----------------------------------------------------------------+ #
#######################################################################

B(-1,0,2,minecraft:netherrack)
B(0,0,0,minecraft:netherrack)
B(0,0,1,minecraft:netherrack)
B(0,0,2,minecraft:netherrack)
B(1,0,-3,minecraft:netherrack)
B(1,0,-2,minecraft:netherrack)
B(1,0,-1,minecraft:netherrack)
B(1,0,0,minecraft:netherrack)
B(1,0,1,minecraft:netherrack)
B(1,0,2,minecraft:soul_soil)
B(1,1,2,minecraft:netherrack)
B(2,0,-3,minecraft:netherrack)
B(2,0,-2,minecraft:soul_soil)
B(2,1,-2,minecraft:netherrack)
B(2,0,-1,minecraft:soul_soil)
B(2,1,-1,minecraft:netherrack)
B(2,0,0,minecraft:soul_soil)
B(2,1,0,minecraft:netherrack)
B(2,0,1,minecraft:soul_soil)
B(2,1,1,minecraft:netherrack)
B(2,0,2,minecraft:soul_soil)
B(2,1,2,minecraft:netherrack)
B(2,0,3,minecraft:netherrack)
B(3,0,-4,minecraft:netherrack)
B(3,0,-3,minecraft:soul_soil)
B(3,1,-3,minecraft:netherrack)
B(3,0,-2,minecraft:soul_soil)
B(3,1,-2,minecraft:soul_soil)
B(3,2,-2,minecraft:netherrack)
B(3,0,-1,minecraft:soul_soil)
B(3,1,-1,minecraft:soul_soil)
B(3,2,-1,minecraft:netherrack)
B(3,0,0,minecraft:soul_soil)
B(3,1,0,minecraft:netherrack)
B(3,0,1,minecraft:soul_soil)
B(3,1,1,minecraft:netherrack)
B(3,0,2,minecraft:soul_soil)
B(3,1,2,minecraft:netherrack)
B(3,0,3,minecraft:netherrack)
B(4,0,-5,minecraft:netherrack)
B(4,0,-4,minecraft:soul_soil)
B(4,1,-4,minecraft:netherrack)
B(4,0,-3,minecraft:soul_soil)
B(4,1,-3,minecraft:soul_soil)
B(4,2,-3,minecraft:netherrack)
B(4,0,-2,minecraft:soul_soil)
B(4,1,-2,minecraft:soul_soil)
B(4,2,-2,minecraft:netherrack)
B(4,0,-1,minecraft:soul_soil)
B(4,1,-1,minecraft:soul_soil)
B(4,2,-1,minecraft:netherrack)
B(4,0,0,minecraft:soul_soil)
B(4,1,0,minecraft:soul_soil)
B(4,2,0,minecraft:netherrack)
B(4,0,1,minecraft:soul_soil)
B(4,1,1,minecraft:netherrack)
B(4,0,2,minecraft:soul_soil)
B(4,1,2,minecraft:netherrack)
B(4,0,3,minecraft:netherrack)
B(5,0,-6,minecraft:netherrack)
B(5,0,-5,minecraft:soul_soil)
B(5,1,-5,minecraft:netherrack)
B(5,0,-4,minecraft:soul_soil)
B(5,1,-4,minecraft:netherrack)
B(5,0,-3,minecraft:soul_soil)
B(5,1,-3,minecraft:soul_soil)
B(5,2,-3,minecraft:netherrack)
B(5,0,-2,minecraft:netherrack)
B(5,1,-2,minecraft:soul_soil)
B(5,2,-2,minecraft:soul_soil)
B(5,3,-2,minecraft:netherrack)
B(5,0,-1,minecraft:netherrack)
B(5,1,-1,minecraft:soul_soil)
B(5,2,-1,minecraft:soul_soil)
B(5,3,-1,minecraft:netherrack)
B(5,0,0,minecraft:soul_soil)
B(5,1,0,minecraft:soul_soil)
B(5,2,0,minecraft:netherrack)
B(5,0,1,minecraft:soul_soil)
B(5,1,1,minecraft:soul_soil)
B(5,2,1,minecraft:netherrack)
B(5,0,2,minecraft:soul_soil)
B(5,1,2,minecraft:netherrack)
B(5,0,3,minecraft:netherrack)
B(6,0,-7,minecraft:netherrack)
B(6,0,-6,minecraft:soul_soil)
B(6,1,-6,minecraft:netherrack)
B(6,0,-5,minecraft:soul_soil)
B(6,1,-5,minecraft:netherrack)
B(6,0,-4,minecraft:soul_soil)
B(6,1,-4,minecraft:soul_soil)
B(6,2,-4,minecraft:netherrack)
B(6,0,-3,minecraft:netherrack)
B(6,1,-3,minecraft:soul_soil)
B(6,2,-3,minecraft:soul_soil)
B(6,3,-3,minecraft:netherrack)
B(6,0,-2,minecraft:netherrack)
B(6,1,-2,minecraft:soul_soil)
B(6,2,-2,minecraft:soul_soil)
B(6,3,-2,minecraft:netherrack)
B(6,0,-1,minecraft:netherrack)
B(6,1,-1,minecraft:soul_soil)
B(6,2,-1,minecraft:soul_soil)
B(6,3,-1,minecraft:netherrack)
B(6,0,0,minecraft:soul_soil)
B(6,1,0,minecraft:soul_soil)
B(6,2,0,minecraft:netherrack)
B(6,0,1,minecraft:soul_soil)
B(6,1,1,minecraft:soul_soil)
B(6,2,1,minecraft:netherrack)
B(6,0,2,minecraft:soul_soil)
B(6,1,2,minecraft:netherrack)
B(6,0,3,minecraft:soul_soil)
B(6,1,3,minecraft:netherrack)
B(7,0,-6,minecraft:netherrack)
B(7,0,-5,minecraft:soul_soil)
B(7,1,-5,minecraft:netherrack)
B(7,0,-4,minecraft:soul_soil)
B(7,1,-4,minecraft:netherrack)
B(7,0,-3,minecraft:soul_soil)
B(7,1,-3,minecraft:soul_soil)
B(7,2,-3,minecraft:netherrack)
B(7,0,-2,minecraft:netherrack)
B(7,1,-2,minecraft:soul_soil)
B(7,2,-2,minecraft:soul_soil)
B(7,3,-2,minecraft:netherrack)
B(7,0,-1,minecraft:soul_soil)
B(7,1,-1,minecraft:soul_soil)
B(7,2,-1,minecraft:netherrack)
B(7,0,0,minecraft:soul_soil)
B(7,1,0,minecraft:soul_soil)
B(7,2,0,minecraft:netherrack)
B(7,0,1,minecraft:soul_soil)
B(7,1,1,minecraft:netherrack)
B(7,0,2,minecraft:netherrack)
B(7,0,3,minecraft:netherrack)

#######################################################################
# +-----------------------------------------------------------------+ #
# |                             Branches                            | #
# +-----------------------------------------------------------------+ #
#######################################################################

Branch(16,0,0,true,NetherrackWall2_C3_R6,NORTH,100.0,0)

#######################################################################
# +-----------------------------------------------------------------+ #
# |                             Entities                            | #
# +-----------------------------------------------------------------+ #
#######################################################################

