
#######################################################################
# +-----------------------------------------------------------------+ #
# |                            BO4 object                           | #
# +-----------------------------------------------------------------+ #
#######################################################################

Author: Unknown

Description: No description given

SettingsMode: WriteWithoutComments


#######################################################################
# +-----------------------------------------------------------------+ #
# |                          Main settings                          | #
# +-----------------------------------------------------------------+ #
#######################################################################

FixedRotation: 

Frequency: 0

SpawnHeight: highestBlock

UseCenterForHighestBlock: true

##############################
# Height Limits for the BO4. #
##############################

MinHeight: 0

MaxHeight: 255

InheritBO3: 

InheritBO3Rotation: NORTH

OverrideChildSettings: true

OverrideParentHeight: false

CanOverride: false

BranchFrequency: 0

BranchFrequencyGroup: 

MustBeBelowOther: false

MustBeInside: 

CannotBeInside: 

ReplacesBO3: 

MustBeInsideWorldBorders: false

CanSpawnOnWater: true

SpawnOnWaterOnly: false

SpawnUnderWater: false

SpawnAtWaterLevel: false

HeightOffset: 0

RemoveAir: true

ReplaceAbove: 

ReplaceBelow: 

ReplaceWithBiomeBlocks: true

ReplaceWithSurfaceBlock: GRASS

ReplaceWithGroundBlock: DIRT

ReplaceWithStoneBlock: STONE

SmoothRadius: 0

SmoothHeightOffset: 0

SmoothStartTop: false

SmoothStartWood: false

SmoothingSurfaceBlock: 

SmoothingGroundBlock: 

BO3Group: 

IsSpawnPoint: false

DoReplaceBlocks: true


#######################################################################
# +-----------------------------------------------------------------+ #
# |                              Blocks                             | #
# +-----------------------------------------------------------------+ #
#######################################################################

B(-8,0,-7,minecraft:netherrack)
B(-8,1,-7,minecraft:netherrack)
B(-8,2,-7,minecraft:netherrack)
B(-8,3,-7,minecraft:netherrack)
B(-8,4,-7,minecraft:netherrack)
B(-8,5,-7,minecraft:netherrack)
B(-8,6,-7,minecraft:netherrack)
B(-8,7,-7,minecraft:netherrack)
B(-8,8,-7,minecraft:netherrack)
B(-8,9,-7,minecraft:netherrack)
B(-8,10,-7,minecraft:netherrack)
B(-8,11,-7,minecraft:netherrack)
B(-8,12,-7,minecraft:netherrack)
B(-8,13,-7,minecraft:netherrack)
B(-8,14,-7,minecraft:netherrack)
B(-8,15,-7,minecraft:netherrack)
B(-8,16,-7,minecraft:netherrack)
B(-8,17,-7,minecraft:netherrack)
B(-8,18,-7,minecraft:netherrack)
B(-8,19,-7,minecraft:netherrack)
B(-8,20,-7,minecraft:netherrack)
B(-8,21,-7,minecraft:netherrack)
B(-8,22,-7,minecraft:netherrack)
B(-8,23,-7,minecraft:netherrack)
B(-8,24,-7,minecraft:netherrack)
B(-8,25,-7,minecraft:netherrack)
B(-8,26,-7,minecraft:netherrack)
B(-8,27,-7,minecraft:netherrack)
B(-8,28,-7,minecraft:netherrack)
B(-8,29,-7,minecraft:netherrack)
B(-8,30,-7,minecraft:netherrack)
B(-8,31,-7,minecraft:netherrack)
B(-8,32,-7,minecraft:netherrack)
B(-8,33,-7,minecraft:netherrack)
B(-8,34,-7,minecraft:netherrack)
B(-8,35,-7,minecraft:netherrack)
B(-8,36,-7,minecraft:netherrack)
B(-8,37,-7,minecraft:netherrack)
B(-8,38,-7,minecraft:netherrack)
B(-8,39,-7,minecraft:netherrack)
B(-8,40,-7,minecraft:netherrack)
B(-8,41,-7,minecraft:netherrack)
B(-8,42,-7,minecraft:netherrack)
B(-8,43,-7,minecraft:netherrack)
B(-8,44,-7,minecraft:netherrack)
B(-8,45,-7,minecraft:netherrack)
B(-8,46,-7,minecraft:netherrack)
B(-8,47,-7,minecraft:netherrack)
B(-8,48,-7,minecraft:netherrack)
B(-8,49,-7,minecraft:netherrack)
B(-8,50,-7,minecraft:netherrack)
B(-8,51,-7,minecraft:netherrack)
B(-8,52,-7,minecraft:netherrack)
B(-8,53,-7,minecraft:netherrack)
B(-8,54,-7,minecraft:netherrack)
B(-8,55,-7,minecraft:netherrack)
B(-8,56,-7,minecraft:netherrack)
B(-8,0,-6,minecraft:netherrack)
B(-8,1,-6,minecraft:netherrack)
B(-8,2,-6,minecraft:netherrack)
B(-8,3,-6,minecraft:netherrack)
B(-8,4,-6,minecraft:netherrack)
B(-8,5,-6,minecraft:netherrack)
B(-8,6,-6,minecraft:netherrack)
B(-8,7,-6,minecraft:netherrack)
B(-8,8,-6,minecraft:netherrack)
B(-8,9,-6,minecraft:netherrack)
B(-8,10,-6,minecraft:netherrack)
B(-8,11,-6,minecraft:netherrack)
B(-8,12,-6,minecraft:netherrack)
B(-8,13,-6,minecraft:netherrack)
B(-8,14,-6,minecraft:netherrack)
B(-8,15,-6,minecraft:netherrack)
B(-8,16,-6,minecraft:netherrack)
B(-8,17,-6,minecraft:netherrack)
B(-8,18,-6,minecraft:netherrack)
B(-8,19,-6,minecraft:netherrack)
B(-8,20,-6,minecraft:netherrack)
B(-8,21,-6,minecraft:netherrack)
B(-8,22,-6,minecraft:netherrack)
B(-8,23,-6,minecraft:netherrack)
B(-8,24,-6,minecraft:netherrack)
B(-8,25,-6,minecraft:netherrack)
B(-8,26,-6,minecraft:netherrack)
B(-8,27,-6,minecraft:netherrack)
B(-8,28,-6,minecraft:netherrack)
B(-8,29,-6,minecraft:netherrack)
B(-8,30,-6,minecraft:netherrack)
B(-8,31,-6,minecraft:netherrack)
B(-8,32,-6,minecraft:netherrack)
B(-8,33,-6,minecraft:netherrack)
B(-8,34,-6,minecraft:netherrack)
B(-8,35,-6,minecraft:netherrack)
B(-8,36,-6,minecraft:netherrack)
B(-8,37,-6,minecraft:netherrack)
B(-8,38,-6,minecraft:netherrack)
B(-8,39,-6,minecraft:netherrack)
B(-8,40,-6,minecraft:netherrack)
B(-8,41,-6,minecraft:netherrack)
B(-8,42,-6,minecraft:netherrack)
B(-8,43,-6,minecraft:netherrack)
B(-8,44,-6,minecraft:netherrack)
B(-8,45,-6,minecraft:netherrack)
B(-8,46,-6,minecraft:netherrack)
B(-8,47,-6,minecraft:netherrack)
B(-8,48,-6,minecraft:netherrack)
B(-8,49,-6,minecraft:netherrack)
B(-8,0,-5,minecraft:netherrack)
B(-8,1,-5,minecraft:netherrack)
B(-8,2,-5,minecraft:netherrack)
B(-8,3,-5,minecraft:netherrack)
B(-8,4,-5,minecraft:netherrack)
B(-8,5,-5,minecraft:netherrack)
B(-8,6,-5,minecraft:netherrack)
B(-8,7,-5,minecraft:netherrack)
B(-8,8,-5,minecraft:netherrack)
B(-8,9,-5,minecraft:netherrack)
B(-8,10,-5,minecraft:netherrack)
B(-8,11,-5,minecraft:netherrack)
B(-8,12,-5,minecraft:netherrack)
B(-8,13,-5,minecraft:netherrack)
B(-8,14,-5,minecraft:netherrack)
B(-8,15,-5,minecraft:netherrack)
B(-8,16,-5,minecraft:netherrack)
B(-8,17,-5,minecraft:netherrack)
B(-8,18,-5,minecraft:netherrack)
B(-8,19,-5,minecraft:netherrack)
B(-8,20,-5,minecraft:netherrack)
B(-8,21,-5,minecraft:netherrack)
B(-8,22,-5,minecraft:netherrack)
B(-8,23,-5,minecraft:netherrack)
B(-8,24,-5,minecraft:netherrack)
B(-8,25,-5,minecraft:netherrack)
B(-8,26,-5,minecraft:netherrack)
B(-8,27,-5,minecraft:netherrack)
B(-8,28,-5,minecraft:netherrack)
B(-8,29,-5,minecraft:netherrack)
B(-8,30,-5,minecraft:netherrack)
B(-8,31,-5,minecraft:netherrack)
B(-8,0,-4,minecraft:netherrack)
B(-8,1,-4,minecraft:soul_soil)
B(-8,2,-4,minecraft:soul_soil)
B(-8,3,-4,minecraft:netherrack)
B(-8,0,-3,minecraft:netherrack)
B(-8,1,-3,minecraft:netherrack)
B(-8,2,-3,minecraft:soul_soil)
B(-8,3,-3,minecraft:soul_soil)
B(-8,4,-3,minecraft:netherrack)
B(-8,0,-2,minecraft:netherrack)
B(-8,1,-2,minecraft:netherrack)
B(-8,2,-2,minecraft:netherrack)
B(-8,3,-2,minecraft:soul_soil)
B(-8,4,-2,minecraft:soul_soil)
B(-8,5,-2,minecraft:netherrack)
B(-8,0,-1,minecraft:netherrack)
B(-8,1,-1,minecraft:netherrack)
B(-8,2,-1,minecraft:netherrack)
B(-8,3,-1,minecraft:soul_soil)
B(-8,4,-1,minecraft:soul_soil)
B(-8,5,-1,minecraft:netherrack)
B(-8,0,0,minecraft:netherrack)
B(-8,1,0,minecraft:netherrack)
B(-8,2,0,minecraft:netherrack)
B(-8,3,0,minecraft:soul_soil)
B(-8,4,0,minecraft:soul_soil)
B(-8,5,0,minecraft:netherrack)
B(-8,0,1,minecraft:netherrack)
B(-8,1,1,minecraft:netherrack)
B(-8,2,1,minecraft:netherrack)
B(-8,3,1,minecraft:soul_soil)
B(-8,4,1,minecraft:soul_soil)
B(-8,5,1,minecraft:netherrack)
B(-8,0,2,minecraft:netherrack)
B(-8,1,2,minecraft:netherrack)
B(-8,2,2,minecraft:netherrack)
B(-8,3,2,minecraft:soul_soil)
B(-8,4,2,minecraft:soul_soil)
B(-8,5,2,minecraft:netherrack)
B(-8,0,3,minecraft:netherrack)
B(-8,1,3,minecraft:netherrack)
B(-8,2,3,minecraft:netherrack)
B(-8,3,3,minecraft:soul_soil)
B(-8,4,3,minecraft:soul_soil)
B(-8,5,3,minecraft:netherrack)
B(-8,0,4,minecraft:netherrack)
B(-8,1,4,minecraft:netherrack)
B(-8,2,4,minecraft:netherrack)
B(-8,3,4,minecraft:soul_soil)
B(-8,4,4,minecraft:soul_soil)
B(-8,5,4,minecraft:netherrack)
B(-8,0,5,minecraft:netherrack)
B(-8,1,5,minecraft:nether_quartz_ore)
B(-8,2,5,minecraft:soul_soil)
B(-8,3,5,minecraft:soul_soil)
B(-8,4,5,minecraft:netherrack)
B(-8,0,6,minecraft:netherrack)
B(-8,1,6,minecraft:nether_quartz_ore)
B(-8,2,6,minecraft:soul_soil)
B(-8,3,6,minecraft:soul_soil)
B(-8,4,6,minecraft:netherrack)
B(-8,0,7,minecraft:netherrack)
B(-8,1,7,minecraft:soul_soil)
B(-8,2,7,minecraft:soul_soil)
B(-8,3,7,minecraft:netherrack)
B(-8,0,8,minecraft:netherrack)
B(-8,1,8,minecraft:soul_soil)
B(-8,2,8,minecraft:soul_soil)
B(-8,3,8,minecraft:netherrack)
B(-7,0,-7,minecraft:netherrack)
B(-7,1,-7,minecraft:netherrack)
B(-7,2,-7,minecraft:netherrack)
B(-7,3,-7,minecraft:netherrack)
B(-7,4,-7,minecraft:netherrack)
B(-7,5,-7,minecraft:netherrack)
B(-7,6,-7,minecraft:netherrack)
B(-7,7,-7,minecraft:netherrack)
B(-7,8,-7,minecraft:netherrack)
B(-7,9,-7,minecraft:netherrack)
B(-7,10,-7,minecraft:netherrack)
B(-7,11,-7,minecraft:netherrack)
B(-7,12,-7,minecraft:netherrack)
B(-7,13,-7,minecraft:netherrack)
B(-7,14,-7,minecraft:netherrack)
B(-7,15,-7,minecraft:netherrack)
B(-7,16,-7,minecraft:netherrack)
B(-7,17,-7,minecraft:netherrack)
B(-7,18,-7,minecraft:netherrack)
B(-7,19,-7,minecraft:netherrack)
B(-7,20,-7,minecraft:netherrack)
B(-7,21,-7,minecraft:netherrack)
B(-7,22,-7,minecraft:netherrack)
B(-7,23,-7,minecraft:netherrack)
B(-7,24,-7,minecraft:netherrack)
B(-7,25,-7,minecraft:netherrack)
B(-7,26,-7,minecraft:netherrack)
B(-7,27,-7,minecraft:netherrack)
B(-7,28,-7,minecraft:netherrack)
B(-7,29,-7,minecraft:netherrack)
B(-7,30,-7,minecraft:netherrack)
B(-7,31,-7,minecraft:netherrack)
B(-7,32,-7,minecraft:netherrack)
B(-7,33,-7,minecraft:netherrack)
B(-7,34,-7,minecraft:netherrack)
B(-7,35,-7,minecraft:netherrack)
B(-7,36,-7,minecraft:netherrack)
B(-7,37,-7,minecraft:netherrack)
B(-7,38,-7,minecraft:netherrack)
B(-7,39,-7,minecraft:netherrack)
B(-7,40,-7,minecraft:netherrack)
B(-7,41,-7,minecraft:netherrack)
B(-7,42,-7,minecraft:netherrack)
B(-7,43,-7,minecraft:netherrack)
B(-7,44,-7,minecraft:netherrack)
B(-7,45,-7,minecraft:netherrack)
B(-7,46,-7,minecraft:netherrack)
B(-7,47,-7,minecraft:netherrack)
B(-7,48,-7,minecraft:netherrack)
B(-7,49,-7,minecraft:netherrack)
B(-7,50,-7,minecraft:netherrack)
B(-7,51,-7,minecraft:netherrack)
B(-7,52,-7,minecraft:netherrack)
B(-7,53,-7,minecraft:netherrack)
B(-7,54,-7,minecraft:netherrack)
B(-7,55,-7,minecraft:netherrack)
B(-7,56,-7,minecraft:netherrack)
B(-7,0,-6,minecraft:netherrack)
B(-7,1,-6,minecraft:netherrack)
B(-7,2,-6,minecraft:netherrack)
B(-7,3,-6,minecraft:netherrack)
B(-7,4,-6,minecraft:netherrack)
B(-7,5,-6,minecraft:netherrack)
B(-7,6,-6,minecraft:netherrack)
B(-7,7,-6,minecraft:netherrack)
B(-7,8,-6,minecraft:netherrack)
B(-7,9,-6,minecraft:netherrack)
B(-7,10,-6,minecraft:netherrack)
B(-7,11,-6,minecraft:netherrack)
B(-7,12,-6,minecraft:netherrack)
B(-7,13,-6,minecraft:netherrack)
B(-7,14,-6,minecraft:netherrack)
B(-7,15,-6,minecraft:netherrack)
B(-7,16,-6,minecraft:netherrack)
B(-7,17,-6,minecraft:netherrack)
B(-7,18,-6,minecraft:netherrack)
B(-7,19,-6,minecraft:netherrack)
B(-7,20,-6,minecraft:netherrack)
B(-7,21,-6,minecraft:netherrack)
B(-7,22,-6,minecraft:netherrack)
B(-7,23,-6,minecraft:netherrack)
B(-7,24,-6,minecraft:netherrack)
B(-7,25,-6,minecraft:netherrack)
B(-7,26,-6,minecraft:netherrack)
B(-7,27,-6,minecraft:netherrack)
B(-7,28,-6,minecraft:netherrack)
B(-7,29,-6,minecraft:netherrack)
B(-7,30,-6,minecraft:netherrack)
B(-7,31,-6,minecraft:netherrack)
B(-7,32,-6,minecraft:netherrack)
B(-7,33,-6,minecraft:netherrack)
B(-7,34,-6,minecraft:netherrack)
B(-7,35,-6,minecraft:netherrack)
B(-7,36,-6,minecraft:netherrack)
B(-7,37,-6,minecraft:netherrack)
B(-7,38,-6,minecraft:netherrack)
B(-7,39,-6,minecraft:netherrack)
B(-7,40,-6,minecraft:netherrack)
B(-7,41,-6,minecraft:netherrack)
B(-7,42,-6,minecraft:netherrack)
B(-7,43,-6,minecraft:netherrack)
B(-7,44,-6,minecraft:netherrack)
B(-7,45,-6,minecraft:netherrack)
B(-7,46,-6,minecraft:netherrack)
B(-7,47,-6,minecraft:netherrack)
B(-7,48,-6,minecraft:netherrack)
B(-7,49,-6,minecraft:netherrack)
B(-7,50,-6,minecraft:netherrack)
B(-7,51,-6,minecraft:netherrack)
B(-7,52,-6,minecraft:netherrack)
B(-7,53,-6,minecraft:netherrack)
B(-7,54,-6,minecraft:netherrack)
B(-7,55,-6,minecraft:netherrack)
B(-7,0,-5,minecraft:netherrack)
B(-7,1,-5,minecraft:netherrack)
B(-7,2,-5,minecraft:netherrack)
B(-7,3,-5,minecraft:netherrack)
B(-7,4,-5,minecraft:netherrack)
B(-7,5,-5,minecraft:netherrack)
B(-7,6,-5,minecraft:netherrack)
B(-7,7,-5,minecraft:netherrack)
B(-7,8,-5,minecraft:netherrack)
B(-7,9,-5,minecraft:netherrack)
B(-7,10,-5,minecraft:netherrack)
B(-7,11,-5,minecraft:netherrack)
B(-7,12,-5,minecraft:netherrack)
B(-7,13,-5,minecraft:netherrack)
B(-7,14,-5,minecraft:netherrack)
B(-7,15,-5,minecraft:netherrack)
B(-7,16,-5,minecraft:netherrack)
B(-7,17,-5,minecraft:netherrack)
B(-7,18,-5,minecraft:netherrack)
B(-7,19,-5,minecraft:netherrack)
B(-7,20,-5,minecraft:netherrack)
B(-7,21,-5,minecraft:netherrack)
B(-7,22,-5,minecraft:netherrack)
B(-7,23,-5,minecraft:netherrack)
B(-7,24,-5,minecraft:netherrack)
B(-7,25,-5,minecraft:netherrack)
B(-7,26,-5,minecraft:netherrack)
B(-7,27,-5,minecraft:netherrack)
B(-7,28,-5,minecraft:netherrack)
B(-7,29,-5,minecraft:netherrack)
B(-7,30,-5,minecraft:netherrack)
B(-7,31,-5,minecraft:netherrack)
B(-7,32,-5,minecraft:netherrack)
B(-7,33,-5,minecraft:netherrack)
B(-7,34,-5,minecraft:netherrack)
B(-7,35,-5,minecraft:netherrack)
B(-7,36,-5,minecraft:netherrack)
B(-7,37,-5,minecraft:netherrack)
B(-7,38,-5,minecraft:netherrack)
B(-7,39,-5,minecraft:netherrack)
B(-7,40,-5,minecraft:netherrack)
B(-7,41,-5,minecraft:netherrack)
B(-7,42,-5,minecraft:netherrack)
B(-7,43,-5,minecraft:netherrack)
B(-7,44,-5,minecraft:netherrack)
B(-7,45,-5,minecraft:netherrack)
B(-7,46,-5,minecraft:netherrack)
B(-7,0,-4,minecraft:netherrack)
B(-7,1,-4,minecraft:netherrack)
B(-7,2,-4,minecraft:netherrack)
B(-7,3,-4,minecraft:netherrack)
B(-7,4,-4,minecraft:netherrack)
B(-7,5,-4,minecraft:netherrack)
B(-7,6,-4,minecraft:netherrack)
B(-7,7,-4,minecraft:netherrack)
B(-7,8,-4,minecraft:netherrack)
B(-7,9,-4,minecraft:netherrack)
B(-7,10,-4,minecraft:netherrack)
B(-7,11,-4,minecraft:netherrack)
B(-7,12,-4,minecraft:netherrack)
B(-7,13,-4,minecraft:netherrack)
B(-7,14,-4,minecraft:netherrack)
B(-7,15,-4,minecraft:netherrack)
B(-7,16,-4,minecraft:netherrack)
B(-7,17,-4,minecraft:netherrack)
B(-7,18,-4,minecraft:netherrack)
B(-7,19,-4,minecraft:netherrack)
B(-7,20,-4,minecraft:netherrack)
B(-7,21,-4,minecraft:netherrack)
B(-7,22,-4,minecraft:netherrack)
B(-7,23,-4,minecraft:netherrack)
B(-7,24,-4,minecraft:netherrack)
B(-7,25,-4,minecraft:netherrack)
B(-7,26,-4,minecraft:netherrack)
B(-7,0,-3,minecraft:netherrack)
B(-7,1,-3,minecraft:netherrack)
B(-7,2,-3,minecraft:soul_soil)
B(-7,3,-3,minecraft:soul_soil)
B(-7,4,-3,minecraft:netherrack)
B(-7,0,-2,minecraft:netherrack)
B(-7,1,-2,minecraft:netherrack)
B(-7,2,-2,minecraft:netherrack)
B(-7,3,-2,minecraft:soul_soil)
B(-7,4,-2,minecraft:soul_soil)
B(-7,5,-2,minecraft:netherrack)
B(-7,0,-1,minecraft:netherrack)
B(-7,1,-1,minecraft:netherrack)
B(-7,2,-1,minecraft:netherrack)
B(-7,3,-1,minecraft:soul_soil)
B(-7,4,-1,minecraft:soul_soil)
B(-7,5,-1,minecraft:netherrack)
B(-7,0,0,minecraft:netherrack)
B(-7,1,0,minecraft:netherrack)
B(-7,2,0,minecraft:netherrack)
B(-7,3,0,minecraft:soul_soil)
B(-7,4,0,minecraft:soul_soil)
B(-7,5,0,minecraft:netherrack)
B(-7,0,1,minecraft:netherrack)
B(-7,1,1,minecraft:netherrack)
B(-7,2,1,minecraft:netherrack)
B(-7,3,1,minecraft:soul_soil)
B(-7,4,1,minecraft:soul_soil)
B(-7,5,1,minecraft:netherrack)
B(-7,0,2,minecraft:netherrack)
B(-7,1,2,minecraft:netherrack)
B(-7,2,2,minecraft:netherrack)
B(-7,3,2,minecraft:soul_soil)
B(-7,4,2,minecraft:soul_soil)
B(-7,5,2,minecraft:netherrack)
B(-7,0,3,minecraft:netherrack)
B(-7,1,3,minecraft:netherrack)
B(-7,2,3,minecraft:netherrack)
B(-7,3,3,minecraft:soul_soil)
B(-7,4,3,minecraft:soul_soil)
B(-7,5,3,minecraft:netherrack)
B(-7,0,4,minecraft:netherrack)
B(-7,1,4,minecraft:netherrack)
B(-7,2,4,minecraft:netherrack)
B(-7,3,4,minecraft:soul_soil)
B(-7,4,4,minecraft:soul_soil)
B(-7,5,4,minecraft:netherrack)
B(-7,0,5,minecraft:netherrack)
B(-7,1,5,minecraft:netherrack)
B(-7,2,5,minecraft:netherrack)
B(-7,3,5,minecraft:soul_soil)
B(-7,4,5,minecraft:netherrack)
B(-7,0,6,minecraft:netherrack)
B(-7,1,6,minecraft:soul_soil)
B(-7,2,6,minecraft:soul_soil)
B(-7,3,6,minecraft:netherrack)
B(-7,0,7,minecraft:netherrack)
B(-7,1,7,minecraft:netherrack)
B(-7,2,7,minecraft:soul_soil)
B(-7,3,7,minecraft:netherrack)
B(-7,0,8,minecraft:netherrack)
B(-7,1,8,minecraft:soul_soil)
B(-7,2,8,minecraft:soul_soil)
B(-7,3,8,minecraft:netherrack)
B(-6,0,-7,minecraft:netherrack)
B(-6,1,-7,minecraft:netherrack)
B(-6,2,-7,minecraft:netherrack)
B(-6,3,-7,minecraft:netherrack)
B(-6,4,-7,minecraft:netherrack)
B(-6,5,-7,minecraft:netherrack)
B(-6,6,-7,minecraft:netherrack)
B(-6,7,-7,minecraft:netherrack)
B(-6,8,-7,minecraft:netherrack)
B(-6,9,-7,minecraft:netherrack)
B(-6,10,-7,minecraft:netherrack)
B(-6,11,-7,minecraft:netherrack)
B(-6,12,-7,minecraft:netherrack)
B(-6,13,-7,minecraft:netherrack)
B(-6,14,-7,minecraft:netherrack)
B(-6,15,-7,minecraft:netherrack)
B(-6,16,-7,minecraft:netherrack)
B(-6,17,-7,minecraft:netherrack)
B(-6,18,-7,minecraft:netherrack)
B(-6,19,-7,minecraft:netherrack)
B(-6,20,-7,minecraft:netherrack)
B(-6,21,-7,minecraft:netherrack)
B(-6,22,-7,minecraft:netherrack)
B(-6,23,-7,minecraft:netherrack)
B(-6,24,-7,minecraft:netherrack)
B(-6,25,-7,minecraft:netherrack)
B(-6,26,-7,minecraft:netherrack)
B(-6,27,-7,minecraft:netherrack)
B(-6,28,-7,minecraft:netherrack)
B(-6,29,-7,minecraft:netherrack)
B(-6,30,-7,minecraft:netherrack)
B(-6,31,-7,minecraft:netherrack)
B(-6,32,-7,minecraft:netherrack)
B(-6,33,-7,minecraft:netherrack)
B(-6,34,-7,minecraft:netherrack)
B(-6,35,-7,minecraft:netherrack)
B(-6,36,-7,minecraft:netherrack)
B(-6,37,-7,minecraft:netherrack)
B(-6,38,-7,minecraft:netherrack)
B(-6,39,-7,minecraft:netherrack)
B(-6,40,-7,minecraft:netherrack)
B(-6,41,-7,minecraft:netherrack)
B(-6,42,-7,minecraft:netherrack)
B(-6,43,-7,minecraft:netherrack)
B(-6,44,-7,minecraft:netherrack)
B(-6,45,-7,minecraft:netherrack)
B(-6,46,-7,minecraft:netherrack)
B(-6,47,-7,minecraft:netherrack)
B(-6,48,-7,minecraft:netherrack)
B(-6,49,-7,minecraft:netherrack)
B(-6,50,-7,minecraft:netherrack)
B(-6,51,-7,minecraft:netherrack)
B(-6,52,-7,minecraft:netherrack)
B(-6,53,-7,minecraft:netherrack)
B(-6,54,-7,minecraft:netherrack)
B(-6,55,-7,minecraft:netherrack)
B(-6,56,-7,minecraft:netherrack)
B(-6,0,-6,minecraft:netherrack)
B(-6,1,-6,minecraft:netherrack)
B(-6,2,-6,minecraft:netherrack)
B(-6,3,-6,minecraft:netherrack)
B(-6,4,-6,minecraft:netherrack)
B(-6,5,-6,minecraft:netherrack)
B(-6,6,-6,minecraft:netherrack)
B(-6,7,-6,minecraft:netherrack)
B(-6,8,-6,minecraft:netherrack)
B(-6,9,-6,minecraft:netherrack)
B(-6,10,-6,minecraft:netherrack)
B(-6,11,-6,minecraft:netherrack)
B(-6,12,-6,minecraft:netherrack)
B(-6,13,-6,minecraft:netherrack)
B(-6,14,-6,minecraft:netherrack)
B(-6,15,-6,minecraft:netherrack)
B(-6,16,-6,minecraft:netherrack)
B(-6,17,-6,minecraft:netherrack)
B(-6,18,-6,minecraft:netherrack)
B(-6,19,-6,minecraft:netherrack)
B(-6,20,-6,minecraft:netherrack)
B(-6,21,-6,minecraft:netherrack)
B(-6,22,-6,minecraft:netherrack)
B(-6,23,-6,minecraft:netherrack)
B(-6,24,-6,minecraft:netherrack)
B(-6,25,-6,minecraft:netherrack)
B(-6,26,-6,minecraft:netherrack)
B(-6,27,-6,minecraft:netherrack)
B(-6,28,-6,minecraft:netherrack)
B(-6,29,-6,minecraft:netherrack)
B(-6,30,-6,minecraft:netherrack)
B(-6,31,-6,minecraft:netherrack)
B(-6,32,-6,minecraft:netherrack)
B(-6,33,-6,minecraft:netherrack)
B(-6,34,-6,minecraft:netherrack)
B(-6,35,-6,minecraft:netherrack)
B(-6,36,-6,minecraft:netherrack)
B(-6,37,-6,minecraft:netherrack)
B(-6,38,-6,minecraft:netherrack)
B(-6,39,-6,minecraft:netherrack)
B(-6,40,-6,minecraft:netherrack)
B(-6,41,-6,minecraft:netherrack)
B(-6,42,-6,minecraft:netherrack)
B(-6,43,-6,minecraft:netherrack)
B(-6,44,-6,minecraft:netherrack)
B(-6,45,-6,minecraft:netherrack)
B(-6,46,-6,minecraft:netherrack)
B(-6,47,-6,minecraft:netherrack)
B(-6,48,-6,minecraft:netherrack)
B(-6,49,-6,minecraft:netherrack)
B(-6,50,-6,minecraft:netherrack)
B(-6,51,-6,minecraft:netherrack)
B(-6,52,-6,minecraft:netherrack)
B(-6,53,-6,minecraft:netherrack)
B(-6,54,-6,minecraft:netherrack)
B(-6,55,-6,minecraft:netherrack)
B(-6,0,-5,minecraft:netherrack)
B(-6,1,-5,minecraft:netherrack)
B(-6,2,-5,minecraft:netherrack)
B(-6,3,-5,minecraft:netherrack)
B(-6,4,-5,minecraft:netherrack)
B(-6,5,-5,minecraft:netherrack)
B(-6,6,-5,minecraft:netherrack)
B(-6,7,-5,minecraft:netherrack)
B(-6,8,-5,minecraft:netherrack)
B(-6,9,-5,minecraft:netherrack)
B(-6,10,-5,minecraft:netherrack)
B(-6,11,-5,minecraft:netherrack)
B(-6,12,-5,minecraft:netherrack)
B(-6,13,-5,minecraft:netherrack)
B(-6,14,-5,minecraft:netherrack)
B(-6,15,-5,minecraft:netherrack)
B(-6,16,-5,minecraft:netherrack)
B(-6,17,-5,minecraft:netherrack)
B(-6,18,-5,minecraft:netherrack)
B(-6,19,-5,minecraft:netherrack)
B(-6,20,-5,minecraft:netherrack)
B(-6,21,-5,minecraft:netherrack)
B(-6,22,-5,minecraft:netherrack)
B(-6,23,-5,minecraft:netherrack)
B(-6,24,-5,minecraft:netherrack)
B(-6,25,-5,minecraft:netherrack)
B(-6,26,-5,minecraft:netherrack)
B(-6,27,-5,minecraft:netherrack)
B(-6,28,-5,minecraft:netherrack)
B(-6,29,-5,minecraft:netherrack)
B(-6,30,-5,minecraft:netherrack)
B(-6,31,-5,minecraft:netherrack)
B(-6,32,-5,minecraft:netherrack)
B(-6,33,-5,minecraft:netherrack)
B(-6,34,-5,minecraft:netherrack)
B(-6,35,-5,minecraft:netherrack)
B(-6,36,-5,minecraft:netherrack)
B(-6,37,-5,minecraft:netherrack)
B(-6,38,-5,minecraft:netherrack)
B(-6,39,-5,minecraft:netherrack)
B(-6,40,-5,minecraft:netherrack)
B(-6,41,-5,minecraft:netherrack)
B(-6,42,-5,minecraft:netherrack)
B(-6,43,-5,minecraft:netherrack)
B(-6,44,-5,minecraft:netherrack)
B(-6,45,-5,minecraft:netherrack)
B(-6,46,-5,minecraft:netherrack)
B(-6,47,-5,minecraft:netherrack)
B(-6,48,-5,minecraft:netherrack)
B(-6,49,-5,minecraft:netherrack)
B(-6,50,-5,minecraft:netherrack)
B(-6,51,-5,minecraft:netherrack)
B(-6,52,-5,minecraft:netherrack)
B(-6,53,-5,minecraft:netherrack)
B(-6,54,-5,minecraft:netherrack)
B(-6,0,-4,minecraft:netherrack)
B(-6,1,-4,minecraft:netherrack)
B(-6,2,-4,minecraft:netherrack)
B(-6,3,-4,minecraft:netherrack)
B(-6,4,-4,minecraft:netherrack)
B(-6,5,-4,minecraft:netherrack)
B(-6,6,-4,minecraft:netherrack)
B(-6,7,-4,minecraft:netherrack)
B(-6,8,-4,minecraft:netherrack)
B(-6,9,-4,minecraft:netherrack)
B(-6,10,-4,minecraft:netherrack)
B(-6,11,-4,minecraft:netherrack)
B(-6,12,-4,minecraft:netherrack)
B(-6,13,-4,minecraft:netherrack)
B(-6,14,-4,minecraft:netherrack)
B(-6,15,-4,minecraft:netherrack)
B(-6,16,-4,minecraft:netherrack)
B(-6,17,-4,minecraft:netherrack)
B(-6,18,-4,minecraft:netherrack)
B(-6,19,-4,minecraft:netherrack)
B(-6,20,-4,minecraft:netherrack)
B(-6,21,-4,minecraft:netherrack)
B(-6,22,-4,minecraft:netherrack)
B(-6,23,-4,minecraft:netherrack)
B(-6,24,-4,minecraft:netherrack)
B(-6,25,-4,minecraft:netherrack)
B(-6,26,-4,minecraft:netherrack)
B(-6,27,-4,minecraft:netherrack)
B(-6,28,-4,minecraft:netherrack)
B(-6,29,-4,minecraft:netherrack)
B(-6,30,-4,minecraft:netherrack)
B(-6,31,-4,minecraft:netherrack)
B(-6,32,-4,minecraft:netherrack)
B(-6,33,-4,minecraft:netherrack)
B(-6,34,-4,minecraft:netherrack)
B(-6,35,-4,minecraft:netherrack)
B(-6,36,-4,minecraft:netherrack)
B(-6,37,-4,minecraft:netherrack)
B(-6,38,-4,minecraft:netherrack)
B(-6,39,-4,minecraft:netherrack)
B(-6,40,-4,minecraft:netherrack)
B(-6,41,-4,minecraft:netherrack)
B(-6,42,-4,minecraft:netherrack)
B(-6,43,-4,minecraft:netherrack)
B(-6,44,-4,minecraft:netherrack)
B(-6,45,-4,minecraft:netherrack)
B(-6,46,-4,minecraft:netherrack)
B(-6,47,-4,minecraft:netherrack)
B(-6,48,-4,minecraft:netherrack)
B(-6,49,-4,minecraft:netherrack)
B(-6,50,-4,minecraft:netherrack)
B(-6,0,-3,minecraft:netherrack)
B(-6,1,-3,minecraft:netherrack)
B(-6,2,-3,minecraft:soul_soil)
B(-6,3,-3,minecraft:soul_soil)
B(-6,4,-3,minecraft:netherrack)
B(-6,5,-3,minecraft:netherrack)
B(-6,6,-3,minecraft:netherrack)
B(-6,7,-3,minecraft:netherrack)
B(-6,8,-3,minecraft:netherrack)
B(-6,9,-3,minecraft:netherrack)
B(-6,10,-3,minecraft:netherrack)
B(-6,11,-3,minecraft:netherrack)
B(-6,12,-3,minecraft:netherrack)
B(-6,13,-3,minecraft:netherrack)
B(-6,14,-3,minecraft:netherrack)
B(-6,15,-3,minecraft:netherrack)
B(-6,16,-3,minecraft:netherrack)
B(-6,17,-3,minecraft:netherrack)
B(-6,18,-3,minecraft:netherrack)
B(-6,19,-3,minecraft:netherrack)
B(-6,20,-3,minecraft:netherrack)
B(-6,21,-3,minecraft:netherrack)
B(-6,22,-3,minecraft:netherrack)
B(-6,23,-3,minecraft:netherrack)
B(-6,24,-3,minecraft:netherrack)
B(-6,25,-3,minecraft:netherrack)
B(-6,26,-3,minecraft:netherrack)
B(-6,27,-3,minecraft:netherrack)
B(-6,28,-3,minecraft:netherrack)
B(-6,29,-3,minecraft:netherrack)
B(-6,0,-2,minecraft:netherrack)
B(-6,1,-2,minecraft:netherrack)
B(-6,2,-2,minecraft:netherrack)
B(-6,3,-2,minecraft:soul_soil)
B(-6,4,-2,minecraft:soul_soil)
B(-6,5,-2,minecraft:netherrack)
B(-6,0,-1,minecraft:netherrack)
B(-6,1,-1,minecraft:netherrack)
B(-6,2,-1,minecraft:netherrack)
B(-6,3,-1,minecraft:soul_soil)
B(-6,4,-1,minecraft:soul_soil)
B(-6,5,-1,minecraft:netherrack)
B(-6,0,0,minecraft:netherrack)
B(-6,1,0,minecraft:netherrack)
B(-6,2,0,minecraft:netherrack)
B(-6,3,0,minecraft:soul_soil)
B(-6,4,0,minecraft:soul_soil)
B(-6,5,0,minecraft:netherrack)
B(-6,0,1,minecraft:netherrack)
B(-6,1,1,minecraft:netherrack)
B(-6,2,1,minecraft:netherrack)
B(-6,3,1,minecraft:soul_soil)
B(-6,4,1,minecraft:soul_soil)
B(-6,5,1,minecraft:netherrack)
B(-6,0,2,minecraft:netherrack)
B(-6,1,2,minecraft:netherrack)
B(-6,2,2,minecraft:netherrack)
B(-6,3,2,minecraft:soul_soil)
B(-6,4,2,minecraft:soul_soil)
B(-6,5,2,minecraft:netherrack)
B(-6,0,3,minecraft:netherrack)
B(-6,1,3,minecraft:netherrack)
B(-6,2,3,minecraft:netherrack)
B(-6,3,3,minecraft:soul_soil)
B(-6,4,3,minecraft:soul_soil)
B(-6,5,3,minecraft:netherrack)
B(-6,0,4,minecraft:netherrack)
B(-6,1,4,minecraft:netherrack)
B(-6,2,4,minecraft:soul_soil)
B(-6,3,4,minecraft:soul_soil)
B(-6,4,4,minecraft:netherrack)
B(-6,0,5,minecraft:netherrack)
B(-6,1,5,minecraft:netherrack)
B(-6,2,5,minecraft:soul_soil)
B(-6,3,5,minecraft:soul_soil)
B(-6,4,5,minecraft:netherrack)
B(-6,0,6,minecraft:netherrack)
B(-6,1,6,minecraft:soul_soil)
B(-6,2,6,minecraft:soul_soil)
B(-6,3,6,minecraft:netherrack)
B(-6,0,7,minecraft:netherrack)
B(-6,1,7,minecraft:netherrack)
B(-6,2,7,minecraft:soul_soil)
B(-6,3,7,minecraft:netherrack)
B(-6,0,8,minecraft:netherrack)
B(-6,1,8,minecraft:netherrack)
B(-6,2,8,minecraft:soul_soil)
B(-6,3,8,minecraft:netherrack)
B(-5,0,-7,minecraft:netherrack)
B(-5,1,-7,minecraft:netherrack)
B(-5,2,-7,minecraft:netherrack)
B(-5,3,-7,minecraft:netherrack)
B(-5,4,-7,minecraft:netherrack)
B(-5,5,-7,minecraft:netherrack)
B(-5,6,-7,minecraft:netherrack)
B(-5,7,-7,minecraft:netherrack)
B(-5,8,-7,minecraft:netherrack)
B(-5,9,-7,minecraft:netherrack)
B(-5,10,-7,minecraft:netherrack)
B(-5,11,-7,minecraft:netherrack)
B(-5,12,-7,minecraft:netherrack)
B(-5,13,-7,minecraft:netherrack)
B(-5,14,-7,minecraft:netherrack)
B(-5,15,-7,minecraft:netherrack)
B(-5,16,-7,minecraft:netherrack)
B(-5,17,-7,minecraft:netherrack)
B(-5,18,-7,minecraft:netherrack)
B(-5,19,-7,minecraft:netherrack)
B(-5,20,-7,minecraft:netherrack)
B(-5,21,-7,minecraft:netherrack)
B(-5,22,-7,minecraft:netherrack)
B(-5,23,-7,minecraft:netherrack)
B(-5,24,-7,minecraft:netherrack)
B(-5,25,-7,minecraft:netherrack)
B(-5,26,-7,minecraft:netherrack)
B(-5,27,-7,minecraft:netherrack)
B(-5,28,-7,minecraft:netherrack)
B(-5,29,-7,minecraft:netherrack)
B(-5,30,-7,minecraft:netherrack)
B(-5,31,-7,minecraft:netherrack)
B(-5,32,-7,minecraft:netherrack)
B(-5,33,-7,minecraft:netherrack)
B(-5,34,-7,minecraft:netherrack)
B(-5,35,-7,minecraft:netherrack)
B(-5,36,-7,minecraft:netherrack)
B(-5,37,-7,minecraft:netherrack)
B(-5,38,-7,minecraft:netherrack)
B(-5,39,-7,minecraft:netherrack)
B(-5,40,-7,minecraft:netherrack)
B(-5,41,-7,minecraft:netherrack)
B(-5,42,-7,minecraft:netherrack)
B(-5,43,-7,minecraft:netherrack)
B(-5,44,-7,minecraft:netherrack)
B(-5,45,-7,minecraft:netherrack)
B(-5,46,-7,minecraft:netherrack)
B(-5,47,-7,minecraft:netherrack)
B(-5,48,-7,minecraft:netherrack)
B(-5,49,-7,minecraft:netherrack)
B(-5,50,-7,minecraft:netherrack)
B(-5,51,-7,minecraft:netherrack)
B(-5,52,-7,minecraft:netherrack)
B(-5,53,-7,minecraft:netherrack)
B(-5,54,-7,minecraft:netherrack)
B(-5,55,-7,minecraft:netherrack)
B(-5,56,-7,minecraft:netherrack)
B(-5,0,-6,minecraft:netherrack)
B(-5,1,-6,minecraft:netherrack)
B(-5,2,-6,minecraft:netherrack)
B(-5,3,-6,minecraft:netherrack)
B(-5,4,-6,minecraft:netherrack)
B(-5,5,-6,minecraft:netherrack)
B(-5,6,-6,minecraft:netherrack)
B(-5,7,-6,minecraft:netherrack)
B(-5,8,-6,minecraft:netherrack)
B(-5,9,-6,minecraft:netherrack)
B(-5,10,-6,minecraft:netherrack)
B(-5,11,-6,minecraft:netherrack)
B(-5,12,-6,minecraft:netherrack)
B(-5,13,-6,minecraft:netherrack)
B(-5,14,-6,minecraft:netherrack)
B(-5,15,-6,minecraft:netherrack)
B(-5,16,-6,minecraft:netherrack)
B(-5,17,-6,minecraft:netherrack)
B(-5,18,-6,minecraft:netherrack)
B(-5,19,-6,minecraft:netherrack)
B(-5,20,-6,minecraft:netherrack)
B(-5,21,-6,minecraft:netherrack)
B(-5,22,-6,minecraft:netherrack)
B(-5,23,-6,minecraft:netherrack)
B(-5,24,-6,minecraft:netherrack)
B(-5,25,-6,minecraft:netherrack)
B(-5,26,-6,minecraft:netherrack)
B(-5,27,-6,minecraft:netherrack)
B(-5,28,-6,minecraft:netherrack)
B(-5,29,-6,minecraft:netherrack)
B(-5,30,-6,minecraft:netherrack)
B(-5,31,-6,minecraft:netherrack)
B(-5,32,-6,minecraft:netherrack)
B(-5,33,-6,minecraft:netherrack)
B(-5,34,-6,minecraft:netherrack)
B(-5,35,-6,minecraft:netherrack)
B(-5,36,-6,minecraft:netherrack)
B(-5,37,-6,minecraft:netherrack)
B(-5,38,-6,minecraft:netherrack)
B(-5,39,-6,minecraft:netherrack)
B(-5,40,-6,minecraft:netherrack)
B(-5,41,-6,minecraft:netherrack)
B(-5,42,-6,minecraft:netherrack)
B(-5,43,-6,minecraft:netherrack)
B(-5,44,-6,minecraft:netherrack)
B(-5,45,-6,minecraft:netherrack)
B(-5,46,-6,minecraft:netherrack)
B(-5,47,-6,minecraft:netherrack)
B(-5,48,-6,minecraft:netherrack)
B(-5,49,-6,minecraft:netherrack)
B(-5,50,-6,minecraft:netherrack)
B(-5,51,-6,minecraft:netherrack)
B(-5,52,-6,minecraft:netherrack)
B(-5,53,-6,minecraft:netherrack)
B(-5,54,-6,minecraft:netherrack)
B(-5,55,-6,minecraft:netherrack)
B(-5,56,-6,minecraft:netherrack)
B(-5,0,-5,minecraft:netherrack)
B(-5,1,-5,minecraft:netherrack)
B(-5,2,-5,minecraft:netherrack)
B(-5,3,-5,minecraft:netherrack)
B(-5,4,-5,minecraft:netherrack)
B(-5,5,-5,minecraft:netherrack)
B(-5,6,-5,minecraft:netherrack)
B(-5,7,-5,minecraft:netherrack)
B(-5,8,-5,minecraft:netherrack)
B(-5,9,-5,minecraft:netherrack)
B(-5,10,-5,minecraft:netherrack)
B(-5,11,-5,minecraft:netherrack)
B(-5,12,-5,minecraft:netherrack)
B(-5,13,-5,minecraft:netherrack)
B(-5,14,-5,minecraft:netherrack)
B(-5,15,-5,minecraft:netherrack)
B(-5,16,-5,minecraft:netherrack)
B(-5,17,-5,minecraft:netherrack)
B(-5,18,-5,minecraft:netherrack)
B(-5,19,-5,minecraft:netherrack)
B(-5,20,-5,minecraft:netherrack)
B(-5,21,-5,minecraft:netherrack)
B(-5,22,-5,minecraft:netherrack)
B(-5,23,-5,minecraft:netherrack)
B(-5,24,-5,minecraft:netherrack)
B(-5,25,-5,minecraft:netherrack)
B(-5,26,-5,minecraft:netherrack)
B(-5,27,-5,minecraft:netherrack)
B(-5,28,-5,minecraft:netherrack)
B(-5,29,-5,minecraft:netherrack)
B(-5,30,-5,minecraft:netherrack)
B(-5,31,-5,minecraft:netherrack)
B(-5,32,-5,minecraft:netherrack)
B(-5,33,-5,minecraft:netherrack)
B(-5,34,-5,minecraft:netherrack)
B(-5,35,-5,minecraft:netherrack)
B(-5,36,-5,minecraft:netherrack)
B(-5,37,-5,minecraft:netherrack)
B(-5,38,-5,minecraft:netherrack)
B(-5,39,-5,minecraft:netherrack)
B(-5,40,-5,minecraft:netherrack)
B(-5,41,-5,minecraft:netherrack)
B(-5,42,-5,minecraft:netherrack)
B(-5,43,-5,minecraft:netherrack)
B(-5,44,-5,minecraft:netherrack)
B(-5,45,-5,minecraft:netherrack)
B(-5,46,-5,minecraft:netherrack)
B(-5,47,-5,minecraft:netherrack)
B(-5,48,-5,minecraft:netherrack)
B(-5,49,-5,minecraft:netherrack)
B(-5,50,-5,minecraft:netherrack)
B(-5,51,-5,minecraft:netherrack)
B(-5,52,-5,minecraft:netherrack)
B(-5,53,-5,minecraft:netherrack)
B(-5,54,-5,minecraft:netherrack)
B(-5,55,-5,minecraft:netherrack)
B(-5,56,-5,minecraft:netherrack)
B(-5,0,-4,minecraft:netherrack)
B(-5,1,-4,minecraft:netherrack)
B(-5,2,-4,minecraft:netherrack)
B(-5,3,-4,minecraft:netherrack)
B(-5,4,-4,minecraft:netherrack)
B(-5,5,-4,minecraft:netherrack)
B(-5,6,-4,minecraft:netherrack)
B(-5,7,-4,minecraft:netherrack)
B(-5,8,-4,minecraft:netherrack)
B(-5,9,-4,minecraft:netherrack)
B(-5,10,-4,minecraft:netherrack)
B(-5,11,-4,minecraft:netherrack)
B(-5,12,-4,minecraft:netherrack)
B(-5,13,-4,minecraft:netherrack)
B(-5,14,-4,minecraft:netherrack)
B(-5,15,-4,minecraft:netherrack)
B(-5,16,-4,minecraft:netherrack)
B(-5,17,-4,minecraft:netherrack)
B(-5,18,-4,minecraft:netherrack)
B(-5,19,-4,minecraft:netherrack)
B(-5,20,-4,minecraft:netherrack)
B(-5,21,-4,minecraft:netherrack)
B(-5,22,-4,minecraft:netherrack)
B(-5,23,-4,minecraft:netherrack)
B(-5,24,-4,minecraft:netherrack)
B(-5,25,-4,minecraft:netherrack)
B(-5,26,-4,minecraft:netherrack)
B(-5,27,-4,minecraft:netherrack)
B(-5,28,-4,minecraft:netherrack)
B(-5,29,-4,minecraft:netherrack)
B(-5,30,-4,minecraft:netherrack)
B(-5,31,-4,minecraft:netherrack)
B(-5,32,-4,minecraft:netherrack)
B(-5,33,-4,minecraft:netherrack)
B(-5,34,-4,minecraft:netherrack)
B(-5,35,-4,minecraft:netherrack)
B(-5,36,-4,minecraft:netherrack)
B(-5,37,-4,minecraft:netherrack)
B(-5,38,-4,minecraft:netherrack)
B(-5,39,-4,minecraft:netherrack)
B(-5,40,-4,minecraft:netherrack)
B(-5,41,-4,minecraft:netherrack)
B(-5,42,-4,minecraft:netherrack)
B(-5,43,-4,minecraft:netherrack)
B(-5,44,-4,minecraft:netherrack)
B(-5,45,-4,minecraft:netherrack)
B(-5,46,-4,minecraft:netherrack)
B(-5,47,-4,minecraft:netherrack)
B(-5,48,-4,minecraft:netherrack)
B(-5,49,-4,minecraft:netherrack)
B(-5,50,-4,minecraft:netherrack)
B(-5,51,-4,minecraft:netherrack)
B(-5,52,-4,minecraft:netherrack)
B(-5,53,-4,minecraft:netherrack)
B(-5,54,-4,minecraft:netherrack)
B(-5,55,-4,minecraft:netherrack)
B(-5,56,-4,minecraft:netherrack)
B(-5,0,-3,minecraft:netherrack)
B(-5,1,-3,minecraft:soul_soil)
B(-5,2,-3,minecraft:soul_soil)
B(-5,3,-3,minecraft:netherrack)
B(-5,4,-3,minecraft:netherrack)
B(-5,5,-3,minecraft:netherrack)
B(-5,6,-3,minecraft:netherrack)
B(-5,7,-3,minecraft:netherrack)
B(-5,8,-3,minecraft:netherrack)
B(-5,9,-3,minecraft:netherrack)
B(-5,10,-3,minecraft:netherrack)
B(-5,11,-3,minecraft:netherrack)
B(-5,12,-3,minecraft:netherrack)
B(-5,13,-3,minecraft:netherrack)
B(-5,14,-3,minecraft:netherrack)
B(-5,15,-3,minecraft:netherrack)
B(-5,16,-3,minecraft:netherrack)
B(-5,17,-3,minecraft:netherrack)
B(-5,18,-3,minecraft:netherrack)
B(-5,19,-3,minecraft:netherrack)
B(-5,20,-3,minecraft:netherrack)
B(-5,21,-3,minecraft:netherrack)
B(-5,22,-3,minecraft:netherrack)
B(-5,23,-3,minecraft:netherrack)
B(-5,24,-3,minecraft:netherrack)
B(-5,25,-3,minecraft:netherrack)
B(-5,26,-3,minecraft:netherrack)
B(-5,27,-3,minecraft:netherrack)
B(-5,28,-3,minecraft:netherrack)
B(-5,29,-3,minecraft:netherrack)
B(-5,30,-3,minecraft:netherrack)
B(-5,31,-3,minecraft:netherrack)
B(-5,32,-3,minecraft:netherrack)
B(-5,33,-3,minecraft:netherrack)
B(-5,34,-3,minecraft:netherrack)
B(-5,35,-3,minecraft:netherrack)
B(-5,36,-3,minecraft:netherrack)
B(-5,37,-3,minecraft:netherrack)
B(-5,38,-3,minecraft:netherrack)
B(-5,39,-3,minecraft:netherrack)
B(-5,40,-3,minecraft:netherrack)
B(-5,41,-3,minecraft:netherrack)
B(-5,42,-3,minecraft:netherrack)
B(-5,43,-3,minecraft:netherrack)
B(-5,44,-3,minecraft:netherrack)
B(-5,45,-3,minecraft:netherrack)
B(-5,46,-3,minecraft:netherrack)
B(-5,47,-3,minecraft:netherrack)
B(-5,48,-3,minecraft:netherrack)
B(-5,49,-3,minecraft:netherrack)
B(-5,50,-3,minecraft:netherrack)
B(-5,51,-3,minecraft:netherrack)
B(-5,52,-3,minecraft:netherrack)
B(-5,53,-3,minecraft:netherrack)
B(-5,54,-3,minecraft:netherrack)
B(-5,0,-2,minecraft:netherrack)
B(-5,1,-2,minecraft:netherrack)
B(-5,2,-2,minecraft:soul_soil)
B(-5,3,-2,minecraft:soul_soil)
B(-5,4,-2,minecraft:netherrack)
B(-5,0,-1,minecraft:netherrack)
B(-5,1,-1,minecraft:netherrack)
B(-5,2,-1,minecraft:soul_soil)
B(-5,3,-1,minecraft:soul_soil)
B(-5,4,-1,minecraft:netherrack)
B(-5,0,0,minecraft:netherrack)
B(-5,1,0,minecraft:netherrack)
B(-5,2,0,minecraft:soul_soil)
B(-5,3,0,minecraft:soul_soil)
B(-5,4,0,minecraft:netherrack)
B(-5,0,1,minecraft:netherrack)
B(-5,1,1,minecraft:netherrack)
B(-5,2,1,minecraft:netherrack)
B(-5,3,1,minecraft:soul_soil)
B(-5,4,1,minecraft:soul_soil)
B(-5,5,1,minecraft:netherrack)
B(-5,0,2,minecraft:netherrack)
B(-5,1,2,minecraft:netherrack)
B(-5,2,2,minecraft:netherrack)
B(-5,3,2,minecraft:soul_soil)
B(-5,4,2,minecraft:soul_soil)
B(-5,5,2,minecraft:netherrack)
B(-5,0,3,minecraft:netherrack)
B(-5,1,3,minecraft:netherrack)
B(-5,2,3,minecraft:soul_soil)
B(-5,3,3,minecraft:soul_soil)
B(-5,4,3,minecraft:netherrack)
B(-5,0,4,minecraft:netherrack)
B(-5,1,4,minecraft:netherrack)
B(-5,2,4,minecraft:soul_soil)
B(-5,3,4,minecraft:soul_soil)
B(-5,4,4,minecraft:netherrack)
B(-5,0,5,minecraft:netherrack)
B(-5,1,5,minecraft:soul_soil)
B(-5,2,5,minecraft:soul_soil)
B(-5,3,5,minecraft:netherrack)
B(-5,0,6,minecraft:netherrack)
B(-5,1,6,minecraft:soul_soil)
B(-5,2,6,minecraft:soul_soil)
B(-5,3,6,minecraft:netherrack)
B(-5,0,7,minecraft:netherrack)
B(-5,1,7,minecraft:netherrack)
B(-5,2,7,minecraft:soul_soil)
B(-5,3,7,minecraft:netherrack)
B(-5,0,8,minecraft:netherrack)
B(-5,1,8,minecraft:soul_soil)
B(-5,2,8,minecraft:netherrack)
B(-4,0,-7,minecraft:netherrack)
B(-4,1,-7,minecraft:netherrack)
B(-4,2,-7,minecraft:netherrack)
B(-4,3,-7,minecraft:netherrack)
B(-4,4,-7,minecraft:netherrack)
B(-4,5,-7,minecraft:netherrack)
B(-4,6,-7,minecraft:netherrack)
B(-4,7,-7,minecraft:netherrack)
B(-4,8,-7,minecraft:netherrack)
B(-4,9,-7,minecraft:netherrack)
B(-4,10,-7,minecraft:netherrack)
B(-4,11,-7,minecraft:netherrack)
B(-4,12,-7,minecraft:netherrack)
B(-4,13,-7,minecraft:netherrack)
B(-4,14,-7,minecraft:netherrack)
B(-4,15,-7,minecraft:netherrack)
B(-4,16,-7,minecraft:netherrack)
B(-4,17,-7,minecraft:netherrack)
B(-4,18,-7,minecraft:netherrack)
B(-4,19,-7,minecraft:netherrack)
B(-4,20,-7,minecraft:netherrack)
B(-4,21,-7,minecraft:netherrack)
B(-4,22,-7,minecraft:netherrack)
B(-4,23,-7,minecraft:netherrack)
B(-4,24,-7,minecraft:netherrack)
B(-4,25,-7,minecraft:netherrack)
B(-4,26,-7,minecraft:netherrack)
B(-4,27,-7,minecraft:netherrack)
B(-4,28,-7,minecraft:netherrack)
B(-4,29,-7,minecraft:netherrack)
B(-4,30,-7,minecraft:netherrack)
B(-4,31,-7,minecraft:netherrack)
B(-4,32,-7,minecraft:netherrack)
B(-4,33,-7,minecraft:netherrack)
B(-4,34,-7,minecraft:netherrack)
B(-4,35,-7,minecraft:netherrack)
B(-4,36,-7,minecraft:netherrack)
B(-4,37,-7,minecraft:netherrack)
B(-4,38,-7,minecraft:netherrack)
B(-4,39,-7,minecraft:netherrack)
B(-4,40,-7,minecraft:netherrack)
B(-4,41,-7,minecraft:netherrack)
B(-4,42,-7,minecraft:netherrack)
B(-4,43,-7,minecraft:netherrack)
B(-4,44,-7,minecraft:netherrack)
B(-4,45,-7,minecraft:netherrack)
B(-4,46,-7,minecraft:netherrack)
B(-4,47,-7,minecraft:netherrack)
B(-4,48,-7,minecraft:netherrack)
B(-4,49,-7,minecraft:netherrack)
B(-4,50,-7,minecraft:netherrack)
B(-4,51,-7,minecraft:netherrack)
B(-4,52,-7,minecraft:netherrack)
B(-4,53,-7,minecraft:netherrack)
B(-4,54,-7,minecraft:netherrack)
B(-4,55,-7,minecraft:netherrack)
B(-4,56,-7,minecraft:netherrack)
B(-4,0,-6,minecraft:netherrack)
B(-4,1,-6,minecraft:netherrack)
B(-4,2,-6,minecraft:netherrack)
B(-4,3,-6,minecraft:netherrack)
B(-4,4,-6,minecraft:netherrack)
B(-4,5,-6,minecraft:netherrack)
B(-4,6,-6,minecraft:netherrack)
B(-4,7,-6,minecraft:netherrack)
B(-4,8,-6,minecraft:netherrack)
B(-4,9,-6,minecraft:netherrack)
B(-4,10,-6,minecraft:netherrack)
B(-4,11,-6,minecraft:netherrack)
B(-4,12,-6,minecraft:netherrack)
B(-4,13,-6,minecraft:netherrack)
B(-4,14,-6,minecraft:netherrack)
B(-4,15,-6,minecraft:netherrack)
B(-4,16,-6,minecraft:netherrack)
B(-4,17,-6,minecraft:netherrack)
B(-4,18,-6,minecraft:netherrack)
B(-4,19,-6,minecraft:netherrack)
B(-4,20,-6,minecraft:netherrack)
B(-4,21,-6,minecraft:netherrack)
B(-4,22,-6,minecraft:netherrack)
B(-4,23,-6,minecraft:netherrack)
B(-4,24,-6,minecraft:netherrack)
B(-4,25,-6,minecraft:netherrack)
B(-4,26,-6,minecraft:netherrack)
B(-4,27,-6,minecraft:netherrack)
B(-4,28,-6,minecraft:netherrack)
B(-4,29,-6,minecraft:netherrack)
B(-4,30,-6,minecraft:netherrack)
B(-4,31,-6,minecraft:netherrack)
B(-4,32,-6,minecraft:netherrack)
B(-4,33,-6,minecraft:netherrack)
B(-4,34,-6,minecraft:netherrack)
B(-4,35,-6,minecraft:netherrack)
B(-4,36,-6,minecraft:netherrack)
B(-4,37,-6,minecraft:netherrack)
B(-4,38,-6,minecraft:netherrack)
B(-4,39,-6,minecraft:netherrack)
B(-4,40,-6,minecraft:netherrack)
B(-4,41,-6,minecraft:netherrack)
B(-4,42,-6,minecraft:netherrack)
B(-4,43,-6,minecraft:netherrack)
B(-4,44,-6,minecraft:netherrack)
B(-4,45,-6,minecraft:netherrack)
B(-4,46,-6,minecraft:netherrack)
B(-4,47,-6,minecraft:netherrack)
B(-4,48,-6,minecraft:netherrack)
B(-4,49,-6,minecraft:netherrack)
B(-4,50,-6,minecraft:netherrack)
B(-4,51,-6,minecraft:netherrack)
B(-4,52,-6,minecraft:netherrack)
B(-4,53,-6,minecraft:netherrack)
B(-4,54,-6,minecraft:netherrack)
B(-4,55,-6,minecraft:netherrack)
B(-4,56,-6,minecraft:netherrack)
B(-4,0,-5,minecraft:netherrack)
B(-4,1,-5,minecraft:netherrack)
B(-4,2,-5,minecraft:netherrack)
B(-4,3,-5,minecraft:netherrack)
B(-4,4,-5,minecraft:netherrack)
B(-4,5,-5,minecraft:netherrack)
B(-4,6,-5,minecraft:netherrack)
B(-4,7,-5,minecraft:netherrack)
B(-4,8,-5,minecraft:netherrack)
B(-4,9,-5,minecraft:netherrack)
B(-4,10,-5,minecraft:netherrack)
B(-4,11,-5,minecraft:netherrack)
B(-4,12,-5,minecraft:netherrack)
B(-4,13,-5,minecraft:netherrack)
B(-4,14,-5,minecraft:netherrack)
B(-4,15,-5,minecraft:netherrack)
B(-4,16,-5,minecraft:netherrack)
B(-4,17,-5,minecraft:netherrack)
B(-4,18,-5,minecraft:netherrack)
B(-4,19,-5,minecraft:netherrack)
B(-4,20,-5,minecraft:netherrack)
B(-4,21,-5,minecraft:netherrack)
B(-4,22,-5,minecraft:netherrack)
B(-4,23,-5,minecraft:netherrack)
B(-4,24,-5,minecraft:netherrack)
B(-4,25,-5,minecraft:netherrack)
B(-4,26,-5,minecraft:netherrack)
B(-4,27,-5,minecraft:netherrack)
B(-4,28,-5,minecraft:netherrack)
B(-4,29,-5,minecraft:netherrack)
B(-4,30,-5,minecraft:netherrack)
B(-4,31,-5,minecraft:netherrack)
B(-4,32,-5,minecraft:netherrack)
B(-4,33,-5,minecraft:netherrack)
B(-4,34,-5,minecraft:netherrack)
B(-4,35,-5,minecraft:netherrack)
B(-4,36,-5,minecraft:netherrack)
B(-4,37,-5,minecraft:netherrack)
B(-4,38,-5,minecraft:netherrack)
B(-4,39,-5,minecraft:netherrack)
B(-4,40,-5,minecraft:netherrack)
B(-4,41,-5,minecraft:netherrack)
B(-4,42,-5,minecraft:netherrack)
B(-4,43,-5,minecraft:netherrack)
B(-4,44,-5,minecraft:netherrack)
B(-4,45,-5,minecraft:netherrack)
B(-4,46,-5,minecraft:netherrack)
B(-4,47,-5,minecraft:netherrack)
B(-4,48,-5,minecraft:netherrack)
B(-4,49,-5,minecraft:netherrack)
B(-4,50,-5,minecraft:netherrack)
B(-4,51,-5,minecraft:netherrack)
B(-4,52,-5,minecraft:netherrack)
B(-4,53,-5,minecraft:netherrack)
B(-4,54,-5,minecraft:netherrack)
B(-4,55,-5,minecraft:netherrack)
B(-4,56,-5,minecraft:netherrack)
B(-4,57,-5,minecraft:netherrack)
B(-4,0,-4,minecraft:netherrack)
B(-4,1,-4,minecraft:netherrack)
B(-4,2,-4,minecraft:netherrack)
B(-4,3,-4,minecraft:netherrack)
B(-4,4,-4,minecraft:netherrack)
B(-4,5,-4,minecraft:netherrack)
B(-4,6,-4,minecraft:netherrack)
B(-4,7,-4,minecraft:netherrack)
B(-4,8,-4,minecraft:netherrack)
B(-4,9,-4,minecraft:netherrack)
B(-4,10,-4,minecraft:netherrack)
B(-4,11,-4,minecraft:netherrack)
B(-4,12,-4,minecraft:netherrack)
B(-4,13,-4,minecraft:netherrack)
B(-4,14,-4,minecraft:netherrack)
B(-4,15,-4,minecraft:netherrack)
B(-4,16,-4,minecraft:netherrack)
B(-4,17,-4,minecraft:netherrack)
B(-4,18,-4,minecraft:netherrack)
B(-4,19,-4,minecraft:netherrack)
B(-4,20,-4,minecraft:netherrack)
B(-4,21,-4,minecraft:netherrack)
B(-4,22,-4,minecraft:netherrack)
B(-4,23,-4,minecraft:netherrack)
B(-4,24,-4,minecraft:netherrack)
B(-4,25,-4,minecraft:netherrack)
B(-4,26,-4,minecraft:netherrack)
B(-4,27,-4,minecraft:netherrack)
B(-4,28,-4,minecraft:netherrack)
B(-4,29,-4,minecraft:netherrack)
B(-4,30,-4,minecraft:netherrack)
B(-4,31,-4,minecraft:netherrack)
B(-4,32,-4,minecraft:netherrack)
B(-4,33,-4,minecraft:netherrack)
B(-4,34,-4,minecraft:netherrack)
B(-4,35,-4,minecraft:netherrack)
B(-4,36,-4,minecraft:netherrack)
B(-4,37,-4,minecraft:netherrack)
B(-4,38,-4,minecraft:netherrack)
B(-4,39,-4,minecraft:netherrack)
B(-4,40,-4,minecraft:netherrack)
B(-4,41,-4,minecraft:netherrack)
B(-4,42,-4,minecraft:netherrack)
B(-4,43,-4,minecraft:netherrack)
B(-4,44,-4,minecraft:netherrack)
B(-4,45,-4,minecraft:netherrack)
B(-4,46,-4,minecraft:netherrack)
B(-4,47,-4,minecraft:netherrack)
B(-4,48,-4,minecraft:netherrack)
B(-4,49,-4,minecraft:netherrack)
B(-4,50,-4,minecraft:netherrack)
B(-4,51,-4,minecraft:netherrack)
B(-4,52,-4,minecraft:netherrack)
B(-4,53,-4,minecraft:netherrack)
B(-4,54,-4,minecraft:netherrack)
B(-4,55,-4,minecraft:netherrack)
B(-4,56,-4,minecraft:netherrack)
B(-4,57,-4,minecraft:netherrack)
B(-4,0,-3,minecraft:netherrack)
B(-4,1,-3,minecraft:netherrack)
B(-4,2,-3,minecraft:soul_soil)
B(-4,3,-3,minecraft:netherrack)
B(-4,4,-3,minecraft:netherrack)
B(-4,5,-3,minecraft:netherrack)
B(-4,6,-3,minecraft:netherrack)
B(-4,7,-3,minecraft:netherrack)
B(-4,8,-3,minecraft:netherrack)
B(-4,9,-3,minecraft:netherrack)
B(-4,10,-3,minecraft:netherrack)
B(-4,11,-3,minecraft:netherrack)
B(-4,12,-3,minecraft:netherrack)
B(-4,13,-3,minecraft:netherrack)
B(-4,14,-3,minecraft:netherrack)
B(-4,15,-3,minecraft:netherrack)
B(-4,16,-3,minecraft:netherrack)
B(-4,17,-3,minecraft:netherrack)
B(-4,18,-3,minecraft:netherrack)
B(-4,19,-3,minecraft:netherrack)
B(-4,20,-3,minecraft:netherrack)
B(-4,21,-3,minecraft:netherrack)
B(-4,22,-3,minecraft:netherrack)
B(-4,23,-3,minecraft:netherrack)
B(-4,24,-3,minecraft:netherrack)
B(-4,25,-3,minecraft:netherrack)
B(-4,26,-3,minecraft:netherrack)
B(-4,27,-3,minecraft:netherrack)
B(-4,28,-3,minecraft:netherrack)
B(-4,29,-3,minecraft:netherrack)
B(-4,30,-3,minecraft:netherrack)
B(-4,31,-3,minecraft:netherrack)
B(-4,32,-3,minecraft:netherrack)
B(-4,33,-3,minecraft:netherrack)
B(-4,34,-3,minecraft:netherrack)
B(-4,35,-3,minecraft:netherrack)
B(-4,36,-3,minecraft:netherrack)
B(-4,37,-3,minecraft:netherrack)
B(-4,38,-3,minecraft:netherrack)
B(-4,39,-3,minecraft:netherrack)
B(-4,40,-3,minecraft:netherrack)
B(-4,41,-3,minecraft:netherrack)
B(-4,42,-3,minecraft:netherrack)
B(-4,43,-3,minecraft:netherrack)
B(-4,44,-3,minecraft:netherrack)
B(-4,45,-3,minecraft:netherrack)
B(-4,46,-3,minecraft:netherrack)
B(-4,47,-3,minecraft:netherrack)
B(-4,48,-3,minecraft:netherrack)
B(-4,49,-3,minecraft:netherrack)
B(-4,50,-3,minecraft:netherrack)
B(-4,51,-3,minecraft:netherrack)
B(-4,52,-3,minecraft:netherrack)
B(-4,53,-3,minecraft:netherrack)
B(-4,54,-3,minecraft:netherrack)
B(-4,55,-3,minecraft:netherrack)
B(-4,56,-3,minecraft:netherrack)
B(-4,57,-3,minecraft:netherrack)
B(-4,0,-2,minecraft:netherrack)
B(-4,1,-2,minecraft:soul_soil)
B(-4,2,-2,minecraft:soul_soil)
B(-4,3,-2,minecraft:netherrack)
B(-4,0,-1,minecraft:netherrack)
B(-4,1,-1,minecraft:soul_soil)
B(-4,2,-1,minecraft:soul_soil)
B(-4,3,-1,minecraft:netherrack)
B(-4,0,0,minecraft:netherrack)
B(-4,1,0,minecraft:netherrack)
B(-4,2,0,minecraft:soul_soil)
B(-4,3,0,minecraft:soul_soil)
B(-4,4,0,minecraft:netherrack)
B(-4,0,1,minecraft:netherrack)
B(-4,1,1,minecraft:netherrack)
B(-4,2,1,minecraft:soul_soil)
B(-4,3,1,minecraft:soul_soil)
B(-4,4,1,minecraft:netherrack)
B(-4,0,2,minecraft:netherrack)
B(-4,1,2,minecraft:netherrack)
B(-4,2,2,minecraft:soul_soil)
B(-4,3,2,minecraft:soul_soil)
B(-4,4,2,minecraft:netherrack)
B(-4,0,3,minecraft:netherrack)
B(-4,1,3,minecraft:netherrack)
B(-4,2,3,minecraft:soul_soil)
B(-4,3,3,minecraft:soul_soil)
B(-4,4,3,minecraft:netherrack)
B(-4,0,4,minecraft:netherrack)
B(-4,1,4,minecraft:soul_soil)
B(-4,2,4,minecraft:soul_soil)
B(-4,3,4,minecraft:netherrack)
B(-4,0,5,minecraft:netherrack)
B(-4,1,5,minecraft:soul_soil)
B(-4,2,5,minecraft:soul_soil)
B(-4,3,5,minecraft:netherrack)
B(-4,0,6,minecraft:soul_soil)
B(-4,1,6,minecraft:soul_soil)
B(-4,2,6,minecraft:netherrack)
B(-4,0,7,minecraft:soul_soil)
B(-4,1,7,minecraft:soul_soil)
B(-4,2,7,minecraft:netherrack)
B(-4,0,8,minecraft:soul_soil)
B(-4,1,8,minecraft:soul_soil)
B(-4,2,8,minecraft:netherrack)
B(-3,0,-7,minecraft:netherrack)
B(-3,1,-7,minecraft:netherrack)
B(-3,2,-7,minecraft:netherrack)
B(-3,3,-7,minecraft:netherrack)
B(-3,4,-7,minecraft:netherrack)
B(-3,5,-7,minecraft:netherrack)
B(-3,6,-7,minecraft:netherrack)
B(-3,7,-7,minecraft:netherrack)
B(-3,8,-7,minecraft:netherrack)
B(-3,9,-7,minecraft:netherrack)
B(-3,10,-7,minecraft:netherrack)
B(-3,11,-7,minecraft:netherrack)
B(-3,12,-7,minecraft:netherrack)
B(-3,13,-7,minecraft:netherrack)
B(-3,14,-7,minecraft:netherrack)
B(-3,15,-7,minecraft:netherrack)
B(-3,16,-7,minecraft:netherrack)
B(-3,17,-7,minecraft:netherrack)
B(-3,18,-7,minecraft:netherrack)
B(-3,19,-7,minecraft:netherrack)
B(-3,20,-7,minecraft:netherrack)
B(-3,21,-7,minecraft:netherrack)
B(-3,22,-7,minecraft:netherrack)
B(-3,23,-7,minecraft:netherrack)
B(-3,24,-7,minecraft:netherrack)
B(-3,25,-7,minecraft:netherrack)
B(-3,26,-7,minecraft:netherrack)
B(-3,27,-7,minecraft:netherrack)
B(-3,28,-7,minecraft:netherrack)
B(-3,29,-7,minecraft:netherrack)
B(-3,30,-7,minecraft:netherrack)
B(-3,31,-7,minecraft:netherrack)
B(-3,32,-7,minecraft:netherrack)
B(-3,33,-7,minecraft:netherrack)
B(-3,34,-7,minecraft:netherrack)
B(-3,35,-7,minecraft:netherrack)
B(-3,36,-7,minecraft:netherrack)
B(-3,37,-7,minecraft:netherrack)
B(-3,38,-7,minecraft:netherrack)
B(-3,39,-7,minecraft:netherrack)
B(-3,40,-7,minecraft:netherrack)
B(-3,41,-7,minecraft:netherrack)
B(-3,42,-7,minecraft:netherrack)
B(-3,43,-7,minecraft:netherrack)
B(-3,44,-7,minecraft:netherrack)
B(-3,45,-7,minecraft:netherrack)
B(-3,46,-7,minecraft:netherrack)
B(-3,47,-7,minecraft:netherrack)
B(-3,48,-7,minecraft:netherrack)
B(-3,49,-7,minecraft:netherrack)
B(-3,50,-7,minecraft:netherrack)
B(-3,51,-7,minecraft:netherrack)
B(-3,52,-7,minecraft:netherrack)
B(-3,53,-7,minecraft:netherrack)
B(-3,54,-7,minecraft:netherrack)
B(-3,55,-7,minecraft:netherrack)
B(-3,56,-7,minecraft:netherrack)
B(-3,0,-6,minecraft:netherrack)
B(-3,1,-6,minecraft:netherrack)
B(-3,2,-6,minecraft:netherrack)
B(-3,3,-6,minecraft:netherrack)
B(-3,4,-6,minecraft:netherrack)
B(-3,5,-6,minecraft:netherrack)
B(-3,6,-6,minecraft:netherrack)
B(-3,7,-6,minecraft:netherrack)
B(-3,8,-6,minecraft:netherrack)
B(-3,9,-6,minecraft:netherrack)
B(-3,10,-6,minecraft:netherrack)
B(-3,11,-6,minecraft:netherrack)
B(-3,12,-6,minecraft:netherrack)
B(-3,13,-6,minecraft:netherrack)
B(-3,14,-6,minecraft:netherrack)
B(-3,15,-6,minecraft:netherrack)
B(-3,16,-6,minecraft:netherrack)
B(-3,17,-6,minecraft:netherrack)
B(-3,18,-6,minecraft:netherrack)
B(-3,19,-6,minecraft:netherrack)
B(-3,20,-6,minecraft:netherrack)
B(-3,21,-6,minecraft:netherrack)
B(-3,22,-6,minecraft:netherrack)
B(-3,23,-6,minecraft:netherrack)
B(-3,24,-6,minecraft:netherrack)
B(-3,25,-6,minecraft:netherrack)
B(-3,26,-6,minecraft:netherrack)
B(-3,27,-6,minecraft:netherrack)
B(-3,28,-6,minecraft:netherrack)
B(-3,29,-6,minecraft:netherrack)
B(-3,30,-6,minecraft:netherrack)
B(-3,31,-6,minecraft:netherrack)
B(-3,32,-6,minecraft:netherrack)
B(-3,33,-6,minecraft:netherrack)
B(-3,34,-6,minecraft:netherrack)
B(-3,35,-6,minecraft:netherrack)
B(-3,36,-6,minecraft:netherrack)
B(-3,37,-6,minecraft:netherrack)
B(-3,38,-6,minecraft:netherrack)
B(-3,39,-6,minecraft:netherrack)
B(-3,40,-6,minecraft:netherrack)
B(-3,41,-6,minecraft:netherrack)
B(-3,42,-6,minecraft:netherrack)
B(-3,43,-6,minecraft:netherrack)
B(-3,44,-6,minecraft:netherrack)
B(-3,45,-6,minecraft:netherrack)
B(-3,46,-6,minecraft:netherrack)
B(-3,47,-6,minecraft:netherrack)
B(-3,48,-6,minecraft:netherrack)
B(-3,49,-6,minecraft:netherrack)
B(-3,50,-6,minecraft:netherrack)
B(-3,51,-6,minecraft:netherrack)
B(-3,52,-6,minecraft:netherrack)
B(-3,53,-6,minecraft:netherrack)
B(-3,54,-6,minecraft:netherrack)
B(-3,55,-6,minecraft:netherrack)
B(-3,56,-6,minecraft:netherrack)
B(-3,57,-6,minecraft:netherrack)
B(-3,58,-6,minecraft:netherrack)
B(-3,59,-6,minecraft:netherrack)
B(-3,0,-5,minecraft:netherrack)
B(-3,1,-5,minecraft:netherrack)
B(-3,2,-5,minecraft:netherrack)
B(-3,3,-5,minecraft:netherrack)
B(-3,4,-5,minecraft:netherrack)
B(-3,5,-5,minecraft:netherrack)
B(-3,6,-5,minecraft:netherrack)
B(-3,7,-5,minecraft:netherrack)
B(-3,8,-5,minecraft:netherrack)
B(-3,9,-5,minecraft:netherrack)
B(-3,10,-5,minecraft:netherrack)
B(-3,11,-5,minecraft:netherrack)
B(-3,12,-5,minecraft:netherrack)
B(-3,13,-5,minecraft:netherrack)
B(-3,14,-5,minecraft:netherrack)
B(-3,15,-5,minecraft:netherrack)
B(-3,16,-5,minecraft:netherrack)
B(-3,17,-5,minecraft:netherrack)
B(-3,18,-5,minecraft:netherrack)
B(-3,19,-5,minecraft:netherrack)
B(-3,20,-5,minecraft:netherrack)
B(-3,21,-5,minecraft:netherrack)
B(-3,22,-5,minecraft:netherrack)
B(-3,23,-5,minecraft:netherrack)
B(-3,24,-5,minecraft:netherrack)
B(-3,25,-5,minecraft:netherrack)
B(-3,26,-5,minecraft:netherrack)
B(-3,27,-5,minecraft:netherrack)
B(-3,28,-5,minecraft:netherrack)
B(-3,29,-5,minecraft:netherrack)
B(-3,30,-5,minecraft:netherrack)
B(-3,31,-5,minecraft:netherrack)
B(-3,32,-5,minecraft:netherrack)
B(-3,33,-5,minecraft:netherrack)
B(-3,34,-5,minecraft:netherrack)
B(-3,35,-5,minecraft:netherrack)
B(-3,36,-5,minecraft:netherrack)
B(-3,37,-5,minecraft:netherrack)
B(-3,38,-5,minecraft:netherrack)
B(-3,39,-5,minecraft:netherrack)
B(-3,40,-5,minecraft:netherrack)
B(-3,41,-5,minecraft:netherrack)
B(-3,42,-5,minecraft:netherrack)
B(-3,43,-5,minecraft:netherrack)
B(-3,44,-5,minecraft:netherrack)
B(-3,45,-5,minecraft:netherrack)
B(-3,46,-5,minecraft:netherrack)
B(-3,47,-5,minecraft:netherrack)
B(-3,48,-5,minecraft:netherrack)
B(-3,49,-5,minecraft:netherrack)
B(-3,50,-5,minecraft:netherrack)
B(-3,51,-5,minecraft:netherrack)
B(-3,52,-5,minecraft:netherrack)
B(-3,53,-5,minecraft:netherrack)
B(-3,54,-5,minecraft:netherrack)
B(-3,55,-5,minecraft:netherrack)
B(-3,56,-5,minecraft:netherrack)
B(-3,57,-5,minecraft:netherrack)
B(-3,58,-5,minecraft:netherrack)
B(-3,59,-5,minecraft:netherrack)
B(-3,0,-4,minecraft:netherrack)
B(-3,1,-4,minecraft:netherrack)
B(-3,2,-4,minecraft:netherrack)
B(-3,3,-4,minecraft:netherrack)
B(-3,4,-4,minecraft:netherrack)
B(-3,5,-4,minecraft:netherrack)
B(-3,6,-4,minecraft:netherrack)
B(-3,7,-4,minecraft:netherrack)
B(-3,8,-4,minecraft:netherrack)
B(-3,9,-4,minecraft:netherrack)
B(-3,10,-4,minecraft:netherrack)
B(-3,11,-4,minecraft:netherrack)
B(-3,12,-4,minecraft:netherrack)
B(-3,13,-4,minecraft:netherrack)
B(-3,14,-4,minecraft:netherrack)
B(-3,15,-4,minecraft:netherrack)
B(-3,16,-4,minecraft:netherrack)
B(-3,17,-4,minecraft:netherrack)
B(-3,18,-4,minecraft:netherrack)
B(-3,19,-4,minecraft:netherrack)
B(-3,20,-4,minecraft:netherrack)
B(-3,21,-4,minecraft:netherrack)
B(-3,22,-4,minecraft:netherrack)
B(-3,23,-4,minecraft:netherrack)
B(-3,24,-4,minecraft:netherrack)
B(-3,25,-4,minecraft:netherrack)
B(-3,26,-4,minecraft:netherrack)
B(-3,27,-4,minecraft:netherrack)
B(-3,28,-4,minecraft:netherrack)
B(-3,29,-4,minecraft:netherrack)
B(-3,30,-4,minecraft:netherrack)
B(-3,31,-4,minecraft:netherrack)
B(-3,32,-4,minecraft:netherrack)
B(-3,33,-4,minecraft:netherrack)
B(-3,34,-4,minecraft:netherrack)
B(-3,35,-4,minecraft:netherrack)
B(-3,36,-4,minecraft:netherrack)
B(-3,37,-4,minecraft:netherrack)
B(-3,38,-4,minecraft:netherrack)
B(-3,39,-4,minecraft:netherrack)
B(-3,40,-4,minecraft:netherrack)
B(-3,41,-4,minecraft:netherrack)
B(-3,42,-4,minecraft:netherrack)
B(-3,43,-4,minecraft:netherrack)
B(-3,44,-4,minecraft:netherrack)
B(-3,45,-4,minecraft:netherrack)
B(-3,46,-4,minecraft:netherrack)
B(-3,47,-4,minecraft:netherrack)
B(-3,48,-4,minecraft:netherrack)
B(-3,49,-4,minecraft:netherrack)
B(-3,50,-4,minecraft:netherrack)
B(-3,51,-4,minecraft:netherrack)
B(-3,52,-4,minecraft:netherrack)
B(-3,53,-4,minecraft:netherrack)
B(-3,54,-4,minecraft:netherrack)
B(-3,55,-4,minecraft:netherrack)
B(-3,56,-4,minecraft:netherrack)
B(-3,57,-4,minecraft:netherrack)
B(-3,58,-4,minecraft:netherrack)
B(-3,59,-4,minecraft:netherrack)
B(-3,0,-3,minecraft:netherrack)
B(-3,1,-3,minecraft:netherrack)
B(-3,2,-3,minecraft:netherrack)
B(-3,3,-3,minecraft:netherrack)
B(-3,4,-3,minecraft:netherrack)
B(-3,5,-3,minecraft:netherrack)
B(-3,6,-3,minecraft:netherrack)
B(-3,7,-3,minecraft:netherrack)
B(-3,8,-3,minecraft:netherrack)
B(-3,9,-3,minecraft:netherrack)
B(-3,10,-3,minecraft:netherrack)
B(-3,11,-3,minecraft:netherrack)
B(-3,12,-3,minecraft:netherrack)
B(-3,13,-3,minecraft:netherrack)
B(-3,14,-3,minecraft:netherrack)
B(-3,15,-3,minecraft:netherrack)
B(-3,16,-3,minecraft:netherrack)
B(-3,17,-3,minecraft:netherrack)
B(-3,18,-3,minecraft:netherrack)
B(-3,19,-3,minecraft:netherrack)
B(-3,20,-3,minecraft:netherrack)
B(-3,21,-3,minecraft:netherrack)
B(-3,22,-3,minecraft:netherrack)
B(-3,23,-3,minecraft:netherrack)
B(-3,24,-3,minecraft:netherrack)
B(-3,25,-3,minecraft:netherrack)
B(-3,26,-3,minecraft:netherrack)
B(-3,27,-3,minecraft:netherrack)
B(-3,28,-3,minecraft:netherrack)
B(-3,29,-3,minecraft:netherrack)
B(-3,30,-3,minecraft:netherrack)
B(-3,31,-3,minecraft:netherrack)
B(-3,32,-3,minecraft:netherrack)
B(-3,33,-3,minecraft:netherrack)
B(-3,34,-3,minecraft:netherrack)
B(-3,35,-3,minecraft:netherrack)
B(-3,36,-3,minecraft:netherrack)
B(-3,37,-3,minecraft:netherrack)
B(-3,38,-3,minecraft:netherrack)
B(-3,39,-3,minecraft:netherrack)
B(-3,40,-3,minecraft:netherrack)
B(-3,41,-3,minecraft:netherrack)
B(-3,42,-3,minecraft:netherrack)
B(-3,43,-3,minecraft:netherrack)
B(-3,44,-3,minecraft:netherrack)
B(-3,45,-3,minecraft:netherrack)
B(-3,46,-3,minecraft:netherrack)
B(-3,47,-3,minecraft:netherrack)
B(-3,48,-3,minecraft:netherrack)
B(-3,49,-3,minecraft:netherrack)
B(-3,50,-3,minecraft:netherrack)
B(-3,51,-3,minecraft:netherrack)
B(-3,52,-3,minecraft:netherrack)
B(-3,53,-3,minecraft:netherrack)
B(-3,54,-3,minecraft:netherrack)
B(-3,55,-3,minecraft:netherrack)
B(-3,56,-3,minecraft:netherrack)
B(-3,57,-3,minecraft:netherrack)
B(-3,58,-3,minecraft:netherrack)
B(-3,59,-3,minecraft:netherrack)
B(-3,0,-2,minecraft:netherrack)
B(-3,1,-2,minecraft:netherrack)
B(-3,2,-2,minecraft:netherrack)
B(-3,3,-2,minecraft:netherrack)
B(-3,4,-2,minecraft:netherrack)
B(-3,5,-2,minecraft:netherrack)
B(-3,6,-2,minecraft:netherrack)
B(-3,7,-2,minecraft:netherrack)
B(-3,8,-2,minecraft:netherrack)
B(-3,9,-2,minecraft:netherrack)
B(-3,10,-2,minecraft:netherrack)
B(-3,11,-2,minecraft:netherrack)
B(-3,12,-2,minecraft:netherrack)
B(-3,13,-2,minecraft:netherrack)
B(-3,14,-2,minecraft:netherrack)
B(-3,15,-2,minecraft:netherrack)
B(-3,16,-2,minecraft:netherrack)
B(-3,17,-2,minecraft:netherrack)
B(-3,18,-2,minecraft:netherrack)
B(-3,19,-2,minecraft:netherrack)
B(-3,20,-2,minecraft:netherrack)
B(-3,21,-2,minecraft:netherrack)
B(-3,22,-2,minecraft:netherrack)
B(-3,23,-2,minecraft:netherrack)
B(-3,24,-2,minecraft:netherrack)
B(-3,25,-2,minecraft:netherrack)
B(-3,26,-2,minecraft:netherrack)
B(-3,27,-2,minecraft:netherrack)
B(-3,28,-2,minecraft:netherrack)
B(-3,29,-2,minecraft:netherrack)
B(-3,30,-2,minecraft:netherrack)
B(-3,31,-2,minecraft:netherrack)
B(-3,32,-2,minecraft:netherrack)
B(-3,33,-2,minecraft:netherrack)
B(-3,34,-2,minecraft:netherrack)
B(-3,35,-2,minecraft:netherrack)
B(-3,36,-2,minecraft:netherrack)
B(-3,37,-2,minecraft:netherrack)
B(-3,38,-2,minecraft:netherrack)
B(-3,39,-2,minecraft:netherrack)
B(-3,40,-2,minecraft:netherrack)
B(-3,41,-2,minecraft:netherrack)
B(-3,42,-2,minecraft:netherrack)
B(-3,43,-2,minecraft:netherrack)
B(-3,44,-2,minecraft:netherrack)
B(-3,45,-2,minecraft:netherrack)
B(-3,46,-2,minecraft:netherrack)
B(-3,47,-2,minecraft:netherrack)
B(-3,48,-2,minecraft:netherrack)
B(-3,49,-2,minecraft:netherrack)
B(-3,50,-2,minecraft:netherrack)
B(-3,51,-2,minecraft:netherrack)
B(-3,52,-2,minecraft:netherrack)
B(-3,53,-2,minecraft:netherrack)
B(-3,54,-2,minecraft:netherrack)
B(-3,55,-2,minecraft:netherrack)
B(-3,56,-2,minecraft:netherrack)
B(-3,57,-2,minecraft:netherrack)
B(-3,58,-2,minecraft:netherrack)
B(-3,59,-2,minecraft:netherrack)
B(-3,0,-1,minecraft:netherrack)
B(-3,1,-1,minecraft:soul_soil)
B(-3,2,-1,minecraft:soul_soil)
B(-3,3,-1,minecraft:netherrack)
B(-3,0,0,minecraft:netherrack)
B(-3,1,0,minecraft:soul_soil)
B(-3,2,0,minecraft:soul_soil)
B(-3,3,0,minecraft:netherrack)
B(-3,0,1,minecraft:netherrack)
B(-3,1,1,minecraft:soul_soil)
B(-3,2,1,minecraft:soul_soil)
B(-3,3,1,minecraft:netherrack)
B(-3,0,2,minecraft:netherrack)
B(-3,1,2,minecraft:netherrack)
B(-3,2,2,minecraft:soul_soil)
B(-3,3,2,minecraft:soul_soil)
B(-3,4,2,minecraft:netherrack)
B(-3,0,3,minecraft:netherrack)
B(-3,1,3,minecraft:soul_soil)
B(-3,2,3,minecraft:soul_soil)
B(-3,3,3,minecraft:netherrack)
B(-3,0,4,minecraft:netherrack)
B(-3,1,4,minecraft:soul_soil)
B(-3,2,4,minecraft:soul_soil)
B(-3,3,4,minecraft:netherrack)
B(-3,0,5,minecraft:soul_soil)
B(-3,1,5,minecraft:soul_soil)
B(-3,2,5,minecraft:netherrack)
B(-3,0,6,minecraft:soul_soil)
B(-3,1,6,minecraft:soul_soil)
B(-3,2,6,minecraft:netherrack)
B(-3,0,7,minecraft:soul_soil)
B(-3,1,7,minecraft:soul_soil)
B(-3,2,7,minecraft:netherrack)
B(-3,0,8,minecraft:soul_soil)
B(-3,1,8,minecraft:soul_soil)
B(-3,2,8,minecraft:netherrack)
B(-2,0,-7,minecraft:netherrack)
B(-2,1,-7,minecraft:netherrack)
B(-2,2,-7,minecraft:netherrack)
B(-2,3,-7,minecraft:netherrack)
B(-2,4,-7,minecraft:netherrack)
B(-2,5,-7,minecraft:netherrack)
B(-2,6,-7,minecraft:netherrack)
B(-2,7,-7,minecraft:netherrack)
B(-2,8,-7,minecraft:netherrack)
B(-2,9,-7,minecraft:netherrack)
B(-2,10,-7,minecraft:netherrack)
B(-2,11,-7,minecraft:netherrack)
B(-2,12,-7,minecraft:netherrack)
B(-2,13,-7,minecraft:netherrack)
B(-2,14,-7,minecraft:netherrack)
B(-2,15,-7,minecraft:netherrack)
B(-2,16,-7,minecraft:netherrack)
B(-2,17,-7,minecraft:netherrack)
B(-2,18,-7,minecraft:netherrack)
B(-2,19,-7,minecraft:netherrack)
B(-2,20,-7,minecraft:netherrack)
B(-2,21,-7,minecraft:netherrack)
B(-2,22,-7,minecraft:netherrack)
B(-2,23,-7,minecraft:netherrack)
B(-2,24,-7,minecraft:netherrack)
B(-2,25,-7,minecraft:netherrack)
B(-2,26,-7,minecraft:netherrack)
B(-2,27,-7,minecraft:netherrack)
B(-2,28,-7,minecraft:netherrack)
B(-2,29,-7,minecraft:netherrack)
B(-2,30,-7,minecraft:netherrack)
B(-2,31,-7,minecraft:netherrack)
B(-2,32,-7,minecraft:netherrack)
B(-2,33,-7,minecraft:netherrack)
B(-2,34,-7,minecraft:netherrack)
B(-2,35,-7,minecraft:netherrack)
B(-2,36,-7,minecraft:netherrack)
B(-2,37,-7,minecraft:netherrack)
B(-2,38,-7,minecraft:netherrack)
B(-2,39,-7,minecraft:netherrack)
B(-2,40,-7,minecraft:netherrack)
B(-2,41,-7,minecraft:netherrack)
B(-2,42,-7,minecraft:netherrack)
B(-2,43,-7,minecraft:netherrack)
B(-2,44,-7,minecraft:netherrack)
B(-2,45,-7,minecraft:netherrack)
B(-2,46,-7,minecraft:netherrack)
B(-2,47,-7,minecraft:netherrack)
B(-2,48,-7,minecraft:netherrack)
B(-2,49,-7,minecraft:netherrack)
B(-2,50,-7,minecraft:netherrack)
B(-2,51,-7,minecraft:netherrack)
B(-2,52,-7,minecraft:netherrack)
B(-2,53,-7,minecraft:netherrack)
B(-2,54,-7,minecraft:netherrack)
B(-2,55,-7,minecraft:netherrack)
B(-2,56,-7,minecraft:netherrack)
B(-2,57,-7,minecraft:netherrack)
B(-2,58,-7,minecraft:netherrack)
B(-2,59,-7,minecraft:netherrack)
B(-2,0,-6,minecraft:netherrack)
B(-2,1,-6,minecraft:netherrack)
B(-2,2,-6,minecraft:netherrack)
B(-2,3,-6,minecraft:netherrack)
B(-2,4,-6,minecraft:netherrack)
B(-2,5,-6,minecraft:netherrack)
B(-2,6,-6,minecraft:netherrack)
B(-2,7,-6,minecraft:netherrack)
B(-2,8,-6,minecraft:netherrack)
B(-2,9,-6,minecraft:netherrack)
B(-2,10,-6,minecraft:netherrack)
B(-2,11,-6,minecraft:netherrack)
B(-2,12,-6,minecraft:netherrack)
B(-2,13,-6,minecraft:netherrack)
B(-2,14,-6,minecraft:netherrack)
B(-2,15,-6,minecraft:netherrack)
B(-2,16,-6,minecraft:netherrack)
B(-2,17,-6,minecraft:netherrack)
B(-2,18,-6,minecraft:netherrack)
B(-2,19,-6,minecraft:netherrack)
B(-2,20,-6,minecraft:netherrack)
B(-2,21,-6,minecraft:netherrack)
B(-2,22,-6,minecraft:netherrack)
B(-2,23,-6,minecraft:netherrack)
B(-2,24,-6,minecraft:netherrack)
B(-2,25,-6,minecraft:netherrack)
B(-2,26,-6,minecraft:netherrack)
B(-2,27,-6,minecraft:netherrack)
B(-2,28,-6,minecraft:netherrack)
B(-2,29,-6,minecraft:netherrack)
B(-2,30,-6,minecraft:netherrack)
B(-2,31,-6,minecraft:netherrack)
B(-2,32,-6,minecraft:netherrack)
B(-2,33,-6,minecraft:netherrack)
B(-2,34,-6,minecraft:netherrack)
B(-2,35,-6,minecraft:netherrack)
B(-2,36,-6,minecraft:netherrack)
B(-2,37,-6,minecraft:netherrack)
B(-2,38,-6,minecraft:netherrack)
B(-2,39,-6,minecraft:netherrack)
B(-2,40,-6,minecraft:netherrack)
B(-2,41,-6,minecraft:netherrack)
B(-2,42,-6,minecraft:netherrack)
B(-2,43,-6,minecraft:netherrack)
B(-2,44,-6,minecraft:netherrack)
B(-2,45,-6,minecraft:netherrack)
B(-2,46,-6,minecraft:netherrack)
B(-2,47,-6,minecraft:netherrack)
B(-2,48,-6,minecraft:netherrack)
B(-2,49,-6,minecraft:netherrack)
B(-2,50,-6,minecraft:netherrack)
B(-2,51,-6,minecraft:netherrack)
B(-2,52,-6,minecraft:netherrack)
B(-2,53,-6,minecraft:netherrack)
B(-2,54,-6,minecraft:netherrack)
B(-2,55,-6,minecraft:netherrack)
B(-2,56,-6,minecraft:netherrack)
B(-2,57,-6,minecraft:netherrack)
B(-2,58,-6,minecraft:netherrack)
B(-2,59,-6,minecraft:netherrack)
B(-2,60,-6,minecraft:netherrack)
B(-2,0,-5,minecraft:netherrack)
B(-2,1,-5,minecraft:netherrack)
B(-2,2,-5,minecraft:netherrack)
B(-2,3,-5,minecraft:netherrack)
B(-2,4,-5,minecraft:netherrack)
B(-2,5,-5,minecraft:netherrack)
B(-2,6,-5,minecraft:netherrack)
B(-2,7,-5,minecraft:netherrack)
B(-2,8,-5,minecraft:netherrack)
B(-2,9,-5,minecraft:netherrack)
B(-2,10,-5,minecraft:netherrack)
B(-2,11,-5,minecraft:netherrack)
B(-2,12,-5,minecraft:netherrack)
B(-2,13,-5,minecraft:netherrack)
B(-2,14,-5,minecraft:netherrack)
B(-2,15,-5,minecraft:netherrack)
B(-2,16,-5,minecraft:netherrack)
B(-2,17,-5,minecraft:netherrack)
B(-2,18,-5,minecraft:netherrack)
B(-2,19,-5,minecraft:netherrack)
B(-2,20,-5,minecraft:netherrack)
B(-2,21,-5,minecraft:netherrack)
B(-2,22,-5,minecraft:netherrack)
B(-2,23,-5,minecraft:netherrack)
B(-2,24,-5,minecraft:netherrack)
B(-2,25,-5,minecraft:netherrack)
B(-2,26,-5,minecraft:netherrack)
B(-2,27,-5,minecraft:netherrack)
B(-2,28,-5,minecraft:netherrack)
B(-2,29,-5,minecraft:netherrack)
B(-2,30,-5,minecraft:netherrack)
B(-2,31,-5,minecraft:netherrack)
B(-2,32,-5,minecraft:netherrack)
B(-2,33,-5,minecraft:netherrack)
B(-2,34,-5,minecraft:netherrack)
B(-2,35,-5,minecraft:netherrack)
B(-2,36,-5,minecraft:netherrack)
B(-2,37,-5,minecraft:netherrack)
B(-2,38,-5,minecraft:netherrack)
B(-2,39,-5,minecraft:netherrack)
B(-2,40,-5,minecraft:netherrack)
B(-2,41,-5,minecraft:netherrack)
B(-2,42,-5,minecraft:netherrack)
B(-2,43,-5,minecraft:netherrack)
B(-2,44,-5,minecraft:netherrack)
B(-2,45,-5,minecraft:netherrack)
B(-2,46,-5,minecraft:netherrack)
B(-2,47,-5,minecraft:netherrack)
B(-2,48,-5,minecraft:netherrack)
B(-2,49,-5,minecraft:netherrack)
B(-2,50,-5,minecraft:netherrack)
B(-2,51,-5,minecraft:netherrack)
B(-2,52,-5,minecraft:netherrack)
B(-2,53,-5,minecraft:netherrack)
B(-2,54,-5,minecraft:netherrack)
B(-2,55,-5,minecraft:netherrack)
B(-2,56,-5,minecraft:netherrack)
B(-2,57,-5,minecraft:netherrack)
B(-2,58,-5,minecraft:netherrack)
B(-2,59,-5,minecraft:netherrack)
B(-2,60,-5,minecraft:netherrack)
B(-2,0,-4,minecraft:netherrack)
B(-2,1,-4,minecraft:netherrack)
B(-2,2,-4,minecraft:netherrack)
B(-2,3,-4,minecraft:netherrack)
B(-2,4,-4,minecraft:netherrack)
B(-2,5,-4,minecraft:netherrack)
B(-2,6,-4,minecraft:netherrack)
B(-2,7,-4,minecraft:netherrack)
B(-2,8,-4,minecraft:netherrack)
B(-2,9,-4,minecraft:netherrack)
B(-2,10,-4,minecraft:netherrack)
B(-2,11,-4,minecraft:netherrack)
B(-2,12,-4,minecraft:netherrack)
B(-2,13,-4,minecraft:netherrack)
B(-2,14,-4,minecraft:netherrack)
B(-2,15,-4,minecraft:netherrack)
B(-2,16,-4,minecraft:netherrack)
B(-2,17,-4,minecraft:netherrack)
B(-2,18,-4,minecraft:netherrack)
B(-2,19,-4,minecraft:netherrack)
B(-2,20,-4,minecraft:netherrack)
B(-2,21,-4,minecraft:netherrack)
B(-2,22,-4,minecraft:netherrack)
B(-2,23,-4,minecraft:netherrack)
B(-2,24,-4,minecraft:netherrack)
B(-2,25,-4,minecraft:netherrack)
B(-2,26,-4,minecraft:netherrack)
B(-2,27,-4,minecraft:netherrack)
B(-2,28,-4,minecraft:netherrack)
B(-2,29,-4,minecraft:netherrack)
B(-2,30,-4,minecraft:netherrack)
B(-2,31,-4,minecraft:netherrack)
B(-2,32,-4,minecraft:netherrack)
B(-2,33,-4,minecraft:netherrack)
B(-2,34,-4,minecraft:netherrack)
B(-2,35,-4,minecraft:netherrack)
B(-2,36,-4,minecraft:netherrack)
B(-2,37,-4,minecraft:netherrack)
B(-2,38,-4,minecraft:netherrack)
B(-2,39,-4,minecraft:netherrack)
B(-2,40,-4,minecraft:netherrack)
B(-2,41,-4,minecraft:netherrack)
B(-2,42,-4,minecraft:netherrack)
B(-2,43,-4,minecraft:netherrack)
B(-2,44,-4,minecraft:netherrack)
B(-2,45,-4,minecraft:netherrack)
B(-2,46,-4,minecraft:netherrack)
B(-2,47,-4,minecraft:netherrack)
B(-2,48,-4,minecraft:netherrack)
B(-2,49,-4,minecraft:netherrack)
B(-2,50,-4,minecraft:netherrack)
B(-2,51,-4,minecraft:netherrack)
B(-2,52,-4,minecraft:netherrack)
B(-2,53,-4,minecraft:netherrack)
B(-2,54,-4,minecraft:netherrack)
B(-2,55,-4,minecraft:netherrack)
B(-2,56,-4,minecraft:netherrack)
B(-2,57,-4,minecraft:netherrack)
B(-2,58,-4,minecraft:netherrack)
B(-2,59,-4,minecraft:netherrack)
B(-2,60,-4,minecraft:netherrack)
B(-2,0,-3,minecraft:netherrack)
B(-2,1,-3,minecraft:netherrack)
B(-2,2,-3,minecraft:netherrack)
B(-2,3,-3,minecraft:netherrack)
B(-2,4,-3,minecraft:netherrack)
B(-2,5,-3,minecraft:netherrack)
B(-2,6,-3,minecraft:netherrack)
B(-2,7,-3,minecraft:netherrack)
B(-2,8,-3,minecraft:netherrack)
B(-2,9,-3,minecraft:netherrack)
B(-2,10,-3,minecraft:netherrack)
B(-2,11,-3,minecraft:netherrack)
B(-2,12,-3,minecraft:netherrack)
B(-2,13,-3,minecraft:netherrack)
B(-2,14,-3,minecraft:netherrack)
B(-2,15,-3,minecraft:netherrack)
B(-2,16,-3,minecraft:netherrack)
B(-2,17,-3,minecraft:netherrack)
B(-2,18,-3,minecraft:netherrack)
B(-2,19,-3,minecraft:netherrack)
B(-2,20,-3,minecraft:netherrack)
B(-2,21,-3,minecraft:netherrack)
B(-2,22,-3,minecraft:netherrack)
B(-2,23,-3,minecraft:netherrack)
B(-2,24,-3,minecraft:netherrack)
B(-2,25,-3,minecraft:netherrack)
B(-2,26,-3,minecraft:netherrack)
B(-2,27,-3,minecraft:netherrack)
B(-2,28,-3,minecraft:netherrack)
B(-2,29,-3,minecraft:netherrack)
B(-2,30,-3,minecraft:netherrack)
B(-2,31,-3,minecraft:netherrack)
B(-2,32,-3,minecraft:netherrack)
B(-2,33,-3,minecraft:netherrack)
B(-2,34,-3,minecraft:netherrack)
B(-2,35,-3,minecraft:netherrack)
B(-2,36,-3,minecraft:netherrack)
B(-2,37,-3,minecraft:netherrack)
B(-2,38,-3,minecraft:netherrack)
B(-2,39,-3,minecraft:netherrack)
B(-2,40,-3,minecraft:netherrack)
B(-2,41,-3,minecraft:netherrack)
B(-2,42,-3,minecraft:netherrack)
B(-2,43,-3,minecraft:netherrack)
B(-2,44,-3,minecraft:netherrack)
B(-2,45,-3,minecraft:netherrack)
B(-2,46,-3,minecraft:netherrack)
B(-2,47,-3,minecraft:netherrack)
B(-2,48,-3,minecraft:netherrack)
B(-2,49,-3,minecraft:netherrack)
B(-2,50,-3,minecraft:netherrack)
B(-2,51,-3,minecraft:netherrack)
B(-2,52,-3,minecraft:netherrack)
B(-2,53,-3,minecraft:netherrack)
B(-2,54,-3,minecraft:netherrack)
B(-2,55,-3,minecraft:netherrack)
B(-2,56,-3,minecraft:netherrack)
B(-2,57,-3,minecraft:netherrack)
B(-2,58,-3,minecraft:netherrack)
B(-2,59,-3,minecraft:netherrack)
B(-2,60,-3,minecraft:netherrack)
B(-2,0,-2,minecraft:netherrack)
B(-2,1,-2,minecraft:netherrack)
B(-2,2,-2,minecraft:netherrack)
B(-2,3,-2,minecraft:netherrack)
B(-2,4,-2,minecraft:netherrack)
B(-2,5,-2,minecraft:netherrack)
B(-2,6,-2,minecraft:netherrack)
B(-2,7,-2,minecraft:netherrack)
B(-2,8,-2,minecraft:netherrack)
B(-2,9,-2,minecraft:netherrack)
B(-2,10,-2,minecraft:netherrack)
B(-2,11,-2,minecraft:netherrack)
B(-2,12,-2,minecraft:netherrack)
B(-2,13,-2,minecraft:netherrack)
B(-2,14,-2,minecraft:netherrack)
B(-2,15,-2,minecraft:netherrack)
B(-2,16,-2,minecraft:netherrack)
B(-2,17,-2,minecraft:netherrack)
B(-2,18,-2,minecraft:netherrack)
B(-2,19,-2,minecraft:netherrack)
B(-2,20,-2,minecraft:netherrack)
B(-2,21,-2,minecraft:netherrack)
B(-2,22,-2,minecraft:netherrack)
B(-2,23,-2,minecraft:netherrack)
B(-2,24,-2,minecraft:netherrack)
B(-2,25,-2,minecraft:netherrack)
B(-2,26,-2,minecraft:netherrack)
B(-2,27,-2,minecraft:netherrack)
B(-2,28,-2,minecraft:netherrack)
B(-2,29,-2,minecraft:netherrack)
B(-2,30,-2,minecraft:netherrack)
B(-2,31,-2,minecraft:netherrack)
B(-2,32,-2,minecraft:netherrack)
B(-2,33,-2,minecraft:netherrack)
B(-2,34,-2,minecraft:netherrack)
B(-2,35,-2,minecraft:netherrack)
B(-2,36,-2,minecraft:netherrack)
B(-2,37,-2,minecraft:netherrack)
B(-2,38,-2,minecraft:netherrack)
B(-2,39,-2,minecraft:netherrack)
B(-2,40,-2,minecraft:netherrack)
B(-2,41,-2,minecraft:netherrack)
B(-2,42,-2,minecraft:netherrack)
B(-2,43,-2,minecraft:netherrack)
B(-2,44,-2,minecraft:netherrack)
B(-2,45,-2,minecraft:netherrack)
B(-2,46,-2,minecraft:netherrack)
B(-2,47,-2,minecraft:netherrack)
B(-2,48,-2,minecraft:netherrack)
B(-2,49,-2,minecraft:netherrack)
B(-2,50,-2,minecraft:netherrack)
B(-2,51,-2,minecraft:netherrack)
B(-2,52,-2,minecraft:netherrack)
B(-2,53,-2,minecraft:netherrack)
B(-2,54,-2,minecraft:netherrack)
B(-2,55,-2,minecraft:netherrack)
B(-2,56,-2,minecraft:netherrack)
B(-2,57,-2,minecraft:netherrack)
B(-2,58,-2,minecraft:netherrack)
B(-2,59,-2,minecraft:netherrack)
B(-2,60,-2,minecraft:netherrack)
B(-2,0,-1,minecraft:netherrack)
B(-2,1,-1,minecraft:netherrack)
B(-2,2,-1,minecraft:netherrack)
B(-2,3,-1,minecraft:netherrack)
B(-2,4,-1,minecraft:netherrack)
B(-2,5,-1,minecraft:netherrack)
B(-2,6,-1,minecraft:netherrack)
B(-2,7,-1,minecraft:netherrack)
B(-2,8,-1,minecraft:netherrack)
B(-2,9,-1,minecraft:netherrack)
B(-2,10,-1,minecraft:netherrack)
B(-2,11,-1,minecraft:netherrack)
B(-2,12,-1,minecraft:netherrack)
B(-2,13,-1,minecraft:netherrack)
B(-2,14,-1,minecraft:netherrack)
B(-2,15,-1,minecraft:netherrack)
B(-2,16,-1,minecraft:netherrack)
B(-2,17,-1,minecraft:netherrack)
B(-2,18,-1,minecraft:netherrack)
B(-2,19,-1,minecraft:netherrack)
B(-2,20,-1,minecraft:netherrack)
B(-2,21,-1,minecraft:netherrack)
B(-2,22,-1,minecraft:netherrack)
B(-2,23,-1,minecraft:netherrack)
B(-2,24,-1,minecraft:netherrack)
B(-2,25,-1,minecraft:netherrack)
B(-2,26,-1,minecraft:netherrack)
B(-2,27,-1,minecraft:netherrack)
B(-2,28,-1,minecraft:netherrack)
B(-2,29,-1,minecraft:netherrack)
B(-2,30,-1,minecraft:netherrack)
B(-2,31,-1,minecraft:netherrack)
B(-2,32,-1,minecraft:netherrack)
B(-2,33,-1,minecraft:netherrack)
B(-2,34,-1,minecraft:netherrack)
B(-2,35,-1,minecraft:netherrack)
B(-2,36,-1,minecraft:netherrack)
B(-2,37,-1,minecraft:netherrack)
B(-2,38,-1,minecraft:netherrack)
B(-2,39,-1,minecraft:netherrack)
B(-2,40,-1,minecraft:netherrack)
B(-2,41,-1,minecraft:netherrack)
B(-2,42,-1,minecraft:netherrack)
B(-2,43,-1,minecraft:netherrack)
B(-2,44,-1,minecraft:netherrack)
B(-2,45,-1,minecraft:netherrack)
B(-2,46,-1,minecraft:netherrack)
B(-2,47,-1,minecraft:netherrack)
B(-2,48,-1,minecraft:netherrack)
B(-2,49,-1,minecraft:netherrack)
B(-2,50,-1,minecraft:netherrack)
B(-2,51,-1,minecraft:netherrack)
B(-2,52,-1,minecraft:netherrack)
B(-2,53,-1,minecraft:netherrack)
B(-2,54,-1,minecraft:netherrack)
B(-2,55,-1,minecraft:netherrack)
B(-2,56,-1,minecraft:netherrack)
B(-2,57,-1,minecraft:netherrack)
B(-2,58,-1,minecraft:netherrack)
B(-2,59,-1,minecraft:netherrack)
B(-2,0,0,minecraft:soul_soil)
B(-2,1,0,minecraft:soul_soil)
B(-2,2,0,minecraft:netherrack)
B(-2,0,1,minecraft:netherrack)
B(-2,1,1,minecraft:soul_soil)
B(-2,2,1,minecraft:soul_soil)
B(-2,3,1,minecraft:netherrack)
B(-2,0,2,minecraft:netherrack)
B(-2,1,2,minecraft:soul_soil)
B(-2,2,2,minecraft:soul_soil)
B(-2,3,2,minecraft:netherrack)
B(-2,0,3,minecraft:netherrack)
B(-2,1,3,minecraft:soul_soil)
B(-2,2,3,minecraft:soul_soil)
B(-2,3,3,minecraft:netherrack)
B(-2,0,4,minecraft:soul_soil)
B(-2,1,4,minecraft:soul_soil)
B(-2,2,4,minecraft:netherrack)
B(-2,0,5,minecraft:soul_soil)
B(-2,1,5,minecraft:soul_soil)
B(-2,2,5,minecraft:netherrack)
B(-2,0,6,minecraft:soul_soil)
B(-2,1,6,minecraft:soul_soil)
B(-2,2,6,minecraft:netherrack)
B(-2,0,7,minecraft:soul_soil)
B(-2,1,7,minecraft:netherrack)
B(-2,0,8,minecraft:soul_soil)
B(-2,1,8,minecraft:netherrack)
B(-1,0,-7,minecraft:netherrack)
B(-1,1,-7,minecraft:netherrack)
B(-1,2,-7,minecraft:netherrack)
B(-1,3,-7,minecraft:netherrack)
B(-1,4,-7,minecraft:netherrack)
B(-1,5,-7,minecraft:netherrack)
B(-1,6,-7,minecraft:netherrack)
B(-1,7,-7,minecraft:netherrack)
B(-1,8,-7,minecraft:netherrack)
B(-1,9,-7,minecraft:netherrack)
B(-1,10,-7,minecraft:netherrack)
B(-1,11,-7,minecraft:netherrack)
B(-1,12,-7,minecraft:netherrack)
B(-1,13,-7,minecraft:netherrack)
B(-1,14,-7,minecraft:netherrack)
B(-1,15,-7,minecraft:netherrack)
B(-1,16,-7,minecraft:netherrack)
B(-1,17,-7,minecraft:netherrack)
B(-1,18,-7,minecraft:netherrack)
B(-1,19,-7,minecraft:netherrack)
B(-1,20,-7,minecraft:netherrack)
B(-1,21,-7,minecraft:netherrack)
B(-1,22,-7,minecraft:netherrack)
B(-1,23,-7,minecraft:netherrack)
B(-1,24,-7,minecraft:netherrack)
B(-1,25,-7,minecraft:netherrack)
B(-1,26,-7,minecraft:netherrack)
B(-1,27,-7,minecraft:netherrack)
B(-1,28,-7,minecraft:netherrack)
B(-1,29,-7,minecraft:netherrack)
B(-1,30,-7,minecraft:netherrack)
B(-1,31,-7,minecraft:netherrack)
B(-1,32,-7,minecraft:netherrack)
B(-1,33,-7,minecraft:netherrack)
B(-1,34,-7,minecraft:netherrack)
B(-1,35,-7,minecraft:netherrack)
B(-1,36,-7,minecraft:netherrack)
B(-1,37,-7,minecraft:netherrack)
B(-1,38,-7,minecraft:netherrack)
B(-1,39,-7,minecraft:netherrack)
B(-1,40,-7,minecraft:netherrack)
B(-1,41,-7,minecraft:netherrack)
B(-1,42,-7,minecraft:netherrack)
B(-1,43,-7,minecraft:netherrack)
B(-1,44,-7,minecraft:netherrack)
B(-1,45,-7,minecraft:netherrack)
B(-1,46,-7,minecraft:netherrack)
B(-1,47,-7,minecraft:netherrack)
B(-1,48,-7,minecraft:netherrack)
B(-1,49,-7,minecraft:netherrack)
B(-1,50,-7,minecraft:netherrack)
B(-1,51,-7,minecraft:netherrack)
B(-1,52,-7,minecraft:netherrack)
B(-1,53,-7,minecraft:netherrack)
B(-1,54,-7,minecraft:netherrack)
B(-1,55,-7,minecraft:netherrack)
B(-1,56,-7,minecraft:netherrack)
B(-1,57,-7,minecraft:netherrack)
B(-1,58,-7,minecraft:netherrack)
B(-1,59,-7,minecraft:netherrack)
B(-1,60,-7,minecraft:netherrack)
B(-1,0,-6,minecraft:netherrack)
B(-1,1,-6,minecraft:netherrack)
B(-1,2,-6,minecraft:netherrack)
B(-1,3,-6,minecraft:netherrack)
B(-1,4,-6,minecraft:netherrack)
B(-1,5,-6,minecraft:netherrack)
B(-1,6,-6,minecraft:netherrack)
B(-1,7,-6,minecraft:netherrack)
B(-1,8,-6,minecraft:netherrack)
B(-1,9,-6,minecraft:netherrack)
B(-1,10,-6,minecraft:netherrack)
B(-1,11,-6,minecraft:netherrack)
B(-1,12,-6,minecraft:netherrack)
B(-1,13,-6,minecraft:netherrack)
B(-1,14,-6,minecraft:netherrack)
B(-1,15,-6,minecraft:netherrack)
B(-1,16,-6,minecraft:netherrack)
B(-1,17,-6,minecraft:netherrack)
B(-1,18,-6,minecraft:netherrack)
B(-1,19,-6,minecraft:netherrack)
B(-1,20,-6,minecraft:netherrack)
B(-1,21,-6,minecraft:netherrack)
B(-1,22,-6,minecraft:netherrack)
B(-1,23,-6,minecraft:netherrack)
B(-1,24,-6,minecraft:netherrack)
B(-1,25,-6,minecraft:netherrack)
B(-1,26,-6,minecraft:netherrack)
B(-1,27,-6,minecraft:netherrack)
B(-1,28,-6,minecraft:netherrack)
B(-1,29,-6,minecraft:netherrack)
B(-1,30,-6,minecraft:netherrack)
B(-1,31,-6,minecraft:netherrack)
B(-1,32,-6,minecraft:netherrack)
B(-1,33,-6,minecraft:netherrack)
B(-1,34,-6,minecraft:netherrack)
B(-1,35,-6,minecraft:netherrack)
B(-1,36,-6,minecraft:netherrack)
B(-1,37,-6,minecraft:netherrack)
B(-1,38,-6,minecraft:netherrack)
B(-1,39,-6,minecraft:netherrack)
B(-1,40,-6,minecraft:netherrack)
B(-1,41,-6,minecraft:netherrack)
B(-1,42,-6,minecraft:netherrack)
B(-1,43,-6,minecraft:netherrack)
B(-1,44,-6,minecraft:netherrack)
B(-1,45,-6,minecraft:netherrack)
B(-1,46,-6,minecraft:netherrack)
B(-1,47,-6,minecraft:netherrack)
B(-1,48,-6,minecraft:netherrack)
B(-1,49,-6,minecraft:netherrack)
B(-1,50,-6,minecraft:netherrack)
B(-1,51,-6,minecraft:netherrack)
B(-1,52,-6,minecraft:netherrack)
B(-1,53,-6,minecraft:netherrack)
B(-1,54,-6,minecraft:netherrack)
B(-1,55,-6,minecraft:netherrack)
B(-1,56,-6,minecraft:netherrack)
B(-1,57,-6,minecraft:netherrack)
B(-1,58,-6,minecraft:netherrack)
B(-1,59,-6,minecraft:netherrack)
B(-1,60,-6,minecraft:netherrack)
B(-1,0,-5,minecraft:netherrack)
B(-1,1,-5,minecraft:netherrack)
B(-1,2,-5,minecraft:netherrack)
B(-1,3,-5,minecraft:netherrack)
B(-1,4,-5,minecraft:netherrack)
B(-1,5,-5,minecraft:netherrack)
B(-1,6,-5,minecraft:netherrack)
B(-1,7,-5,minecraft:netherrack)
B(-1,8,-5,minecraft:netherrack)
B(-1,9,-5,minecraft:netherrack)
B(-1,10,-5,minecraft:netherrack)
B(-1,11,-5,minecraft:netherrack)
B(-1,12,-5,minecraft:netherrack)
B(-1,13,-5,minecraft:netherrack)
B(-1,14,-5,minecraft:netherrack)
B(-1,15,-5,minecraft:netherrack)
B(-1,16,-5,minecraft:netherrack)
B(-1,17,-5,minecraft:netherrack)
B(-1,18,-5,minecraft:netherrack)
B(-1,19,-5,minecraft:netherrack)
B(-1,20,-5,minecraft:netherrack)
B(-1,21,-5,minecraft:netherrack)
B(-1,22,-5,minecraft:netherrack)
B(-1,23,-5,minecraft:netherrack)
B(-1,24,-5,minecraft:netherrack)
B(-1,25,-5,minecraft:netherrack)
B(-1,26,-5,minecraft:netherrack)
B(-1,27,-5,minecraft:netherrack)
B(-1,28,-5,minecraft:netherrack)
B(-1,29,-5,minecraft:netherrack)
B(-1,30,-5,minecraft:netherrack)
B(-1,31,-5,minecraft:netherrack)
B(-1,32,-5,minecraft:netherrack)
B(-1,33,-5,minecraft:netherrack)
B(-1,34,-5,minecraft:netherrack)
B(-1,35,-5,minecraft:netherrack)
B(-1,36,-5,minecraft:netherrack)
B(-1,37,-5,minecraft:netherrack)
B(-1,38,-5,minecraft:netherrack)
B(-1,39,-5,minecraft:netherrack)
B(-1,40,-5,minecraft:netherrack)
B(-1,41,-5,minecraft:netherrack)
B(-1,42,-5,minecraft:netherrack)
B(-1,43,-5,minecraft:netherrack)
B(-1,44,-5,minecraft:netherrack)
B(-1,45,-5,minecraft:netherrack)
B(-1,46,-5,minecraft:netherrack)
B(-1,47,-5,minecraft:netherrack)
B(-1,48,-5,minecraft:netherrack)
B(-1,49,-5,minecraft:netherrack)
B(-1,50,-5,minecraft:netherrack)
B(-1,51,-5,minecraft:netherrack)
B(-1,52,-5,minecraft:netherrack)
B(-1,53,-5,minecraft:netherrack)
B(-1,54,-5,minecraft:netherrack)
B(-1,55,-5,minecraft:netherrack)
B(-1,56,-5,minecraft:netherrack)
B(-1,57,-5,minecraft:netherrack)
B(-1,58,-5,minecraft:netherrack)
B(-1,59,-5,minecraft:netherrack)
B(-1,60,-5,minecraft:netherrack)
B(-1,61,-5,minecraft:netherrack)
B(-1,0,-4,minecraft:netherrack)
B(-1,1,-4,minecraft:netherrack)
B(-1,2,-4,minecraft:netherrack)
B(-1,3,-4,minecraft:netherrack)
B(-1,4,-4,minecraft:netherrack)
B(-1,5,-4,minecraft:netherrack)
B(-1,6,-4,minecraft:netherrack)
B(-1,7,-4,minecraft:netherrack)
B(-1,8,-4,minecraft:netherrack)
B(-1,9,-4,minecraft:netherrack)
B(-1,10,-4,minecraft:netherrack)
B(-1,11,-4,minecraft:netherrack)
B(-1,12,-4,minecraft:netherrack)
B(-1,13,-4,minecraft:netherrack)
B(-1,14,-4,minecraft:netherrack)
B(-1,15,-4,minecraft:netherrack)
B(-1,16,-4,minecraft:netherrack)
B(-1,17,-4,minecraft:netherrack)
B(-1,18,-4,minecraft:netherrack)
B(-1,19,-4,minecraft:netherrack)
B(-1,20,-4,minecraft:netherrack)
B(-1,21,-4,minecraft:netherrack)
B(-1,22,-4,minecraft:netherrack)
B(-1,23,-4,minecraft:netherrack)
B(-1,24,-4,minecraft:netherrack)
B(-1,25,-4,minecraft:netherrack)
B(-1,26,-4,minecraft:netherrack)
B(-1,27,-4,minecraft:netherrack)
B(-1,28,-4,minecraft:netherrack)
B(-1,29,-4,minecraft:netherrack)
B(-1,30,-4,minecraft:netherrack)
B(-1,31,-4,minecraft:netherrack)
B(-1,32,-4,minecraft:netherrack)
B(-1,33,-4,minecraft:netherrack)
B(-1,34,-4,minecraft:netherrack)
B(-1,35,-4,minecraft:netherrack)
B(-1,36,-4,minecraft:netherrack)
B(-1,37,-4,minecraft:netherrack)
B(-1,38,-4,minecraft:netherrack)
B(-1,39,-4,minecraft:netherrack)
B(-1,40,-4,minecraft:netherrack)
B(-1,41,-4,minecraft:netherrack)
B(-1,42,-4,minecraft:netherrack)
B(-1,43,-4,minecraft:netherrack)
B(-1,44,-4,minecraft:netherrack)
B(-1,45,-4,minecraft:netherrack)
B(-1,46,-4,minecraft:netherrack)
B(-1,47,-4,minecraft:netherrack)
B(-1,48,-4,minecraft:netherrack)
B(-1,49,-4,minecraft:netherrack)
B(-1,50,-4,minecraft:netherrack)
B(-1,51,-4,minecraft:netherrack)
B(-1,52,-4,minecraft:netherrack)
B(-1,53,-4,minecraft:netherrack)
B(-1,54,-4,minecraft:netherrack)
B(-1,55,-4,minecraft:netherrack)
B(-1,56,-4,minecraft:netherrack)
B(-1,57,-4,minecraft:netherrack)
B(-1,58,-4,minecraft:netherrack)
B(-1,59,-4,minecraft:netherrack)
B(-1,60,-4,minecraft:netherrack)
B(-1,61,-4,minecraft:netherrack)
B(-1,0,-3,minecraft:netherrack)
B(-1,1,-3,minecraft:netherrack)
B(-1,2,-3,minecraft:netherrack)
B(-1,3,-3,minecraft:netherrack)
B(-1,4,-3,minecraft:netherrack)
B(-1,5,-3,minecraft:netherrack)
B(-1,6,-3,minecraft:netherrack)
B(-1,7,-3,minecraft:netherrack)
B(-1,8,-3,minecraft:netherrack)
B(-1,9,-3,minecraft:netherrack)
B(-1,10,-3,minecraft:netherrack)
B(-1,11,-3,minecraft:netherrack)
B(-1,12,-3,minecraft:netherrack)
B(-1,13,-3,minecraft:netherrack)
B(-1,14,-3,minecraft:netherrack)
B(-1,15,-3,minecraft:netherrack)
B(-1,16,-3,minecraft:netherrack)
B(-1,17,-3,minecraft:netherrack)
B(-1,18,-3,minecraft:netherrack)
B(-1,19,-3,minecraft:netherrack)
B(-1,20,-3,minecraft:netherrack)
B(-1,21,-3,minecraft:netherrack)
B(-1,22,-3,minecraft:netherrack)
B(-1,23,-3,minecraft:netherrack)
B(-1,24,-3,minecraft:netherrack)
B(-1,25,-3,minecraft:netherrack)
B(-1,26,-3,minecraft:netherrack)
B(-1,27,-3,minecraft:netherrack)
B(-1,28,-3,minecraft:netherrack)
B(-1,29,-3,minecraft:netherrack)
B(-1,30,-3,minecraft:netherrack)
B(-1,31,-3,minecraft:netherrack)
B(-1,32,-3,minecraft:netherrack)
B(-1,33,-3,minecraft:netherrack)
B(-1,34,-3,minecraft:netherrack)
B(-1,35,-3,minecraft:netherrack)
B(-1,36,-3,minecraft:netherrack)
B(-1,37,-3,minecraft:netherrack)
B(-1,38,-3,minecraft:netherrack)
B(-1,39,-3,minecraft:netherrack)
B(-1,40,-3,minecraft:netherrack)
B(-1,41,-3,minecraft:netherrack)
B(-1,42,-3,minecraft:netherrack)
B(-1,43,-3,minecraft:netherrack)
B(-1,44,-3,minecraft:netherrack)
B(-1,45,-3,minecraft:netherrack)
B(-1,46,-3,minecraft:netherrack)
B(-1,47,-3,minecraft:netherrack)
B(-1,48,-3,minecraft:netherrack)
B(-1,49,-3,minecraft:netherrack)
B(-1,50,-3,minecraft:netherrack)
B(-1,51,-3,minecraft:netherrack)
B(-1,52,-3,minecraft:netherrack)
B(-1,53,-3,minecraft:netherrack)
B(-1,54,-3,minecraft:netherrack)
B(-1,55,-3,minecraft:netherrack)
B(-1,56,-3,minecraft:netherrack)
B(-1,57,-3,minecraft:netherrack)
B(-1,58,-3,minecraft:netherrack)
B(-1,59,-3,minecraft:netherrack)
B(-1,60,-3,minecraft:netherrack)
B(-1,61,-3,minecraft:netherrack)
B(-1,0,-2,minecraft:netherrack)
B(-1,1,-2,minecraft:netherrack)
B(-1,2,-2,minecraft:netherrack)
B(-1,3,-2,minecraft:netherrack)
B(-1,4,-2,minecraft:netherrack)
B(-1,5,-2,minecraft:netherrack)
B(-1,6,-2,minecraft:netherrack)
B(-1,7,-2,minecraft:netherrack)
B(-1,8,-2,minecraft:netherrack)
B(-1,9,-2,minecraft:netherrack)
B(-1,10,-2,minecraft:netherrack)
B(-1,11,-2,minecraft:netherrack)
B(-1,12,-2,minecraft:netherrack)
B(-1,13,-2,minecraft:netherrack)
B(-1,14,-2,minecraft:netherrack)
B(-1,15,-2,minecraft:netherrack)
B(-1,16,-2,minecraft:netherrack)
B(-1,17,-2,minecraft:netherrack)
B(-1,18,-2,minecraft:netherrack)
B(-1,19,-2,minecraft:netherrack)
B(-1,20,-2,minecraft:netherrack)
B(-1,21,-2,minecraft:netherrack)
B(-1,22,-2,minecraft:netherrack)
B(-1,23,-2,minecraft:netherrack)
B(-1,24,-2,minecraft:netherrack)
B(-1,25,-2,minecraft:netherrack)
B(-1,26,-2,minecraft:netherrack)
B(-1,27,-2,minecraft:netherrack)
B(-1,28,-2,minecraft:netherrack)
B(-1,29,-2,minecraft:netherrack)
B(-1,30,-2,minecraft:netherrack)
B(-1,31,-2,minecraft:netherrack)
B(-1,32,-2,minecraft:netherrack)
B(-1,33,-2,minecraft:netherrack)
B(-1,34,-2,minecraft:netherrack)
B(-1,35,-2,minecraft:netherrack)
B(-1,36,-2,minecraft:netherrack)
B(-1,37,-2,minecraft:netherrack)
B(-1,38,-2,minecraft:netherrack)
B(-1,39,-2,minecraft:netherrack)
B(-1,40,-2,minecraft:netherrack)
B(-1,41,-2,minecraft:netherrack)
B(-1,42,-2,minecraft:netherrack)
B(-1,43,-2,minecraft:netherrack)
B(-1,44,-2,minecraft:netherrack)
B(-1,45,-2,minecraft:netherrack)
B(-1,46,-2,minecraft:netherrack)
B(-1,47,-2,minecraft:netherrack)
B(-1,48,-2,minecraft:netherrack)
B(-1,49,-2,minecraft:netherrack)
B(-1,50,-2,minecraft:netherrack)
B(-1,51,-2,minecraft:netherrack)
B(-1,52,-2,minecraft:netherrack)
B(-1,53,-2,minecraft:netherrack)
B(-1,54,-2,minecraft:netherrack)
B(-1,55,-2,minecraft:netherrack)
B(-1,56,-2,minecraft:netherrack)
B(-1,57,-2,minecraft:netherrack)
B(-1,58,-2,minecraft:netherrack)
B(-1,59,-2,minecraft:netherrack)
B(-1,60,-2,minecraft:netherrack)
B(-1,0,-1,minecraft:netherrack)
B(-1,1,-1,minecraft:netherrack)
B(-1,2,-1,minecraft:netherrack)
B(-1,3,-1,minecraft:netherrack)
B(-1,4,-1,minecraft:netherrack)
B(-1,5,-1,minecraft:netherrack)
B(-1,6,-1,minecraft:netherrack)
B(-1,7,-1,minecraft:netherrack)
B(-1,8,-1,minecraft:netherrack)
B(-1,9,-1,minecraft:netherrack)
B(-1,10,-1,minecraft:netherrack)
B(-1,11,-1,minecraft:netherrack)
B(-1,12,-1,minecraft:netherrack)
B(-1,13,-1,minecraft:netherrack)
B(-1,14,-1,minecraft:netherrack)
B(-1,15,-1,minecraft:netherrack)
B(-1,16,-1,minecraft:netherrack)
B(-1,17,-1,minecraft:netherrack)
B(-1,18,-1,minecraft:netherrack)
B(-1,19,-1,minecraft:netherrack)
B(-1,20,-1,minecraft:netherrack)
B(-1,21,-1,minecraft:netherrack)
B(-1,22,-1,minecraft:netherrack)
B(-1,23,-1,minecraft:netherrack)
B(-1,24,-1,minecraft:netherrack)
B(-1,25,-1,minecraft:netherrack)
B(-1,26,-1,minecraft:netherrack)
B(-1,27,-1,minecraft:netherrack)
B(-1,28,-1,minecraft:netherrack)
B(-1,29,-1,minecraft:netherrack)
B(-1,30,-1,minecraft:netherrack)
B(-1,31,-1,minecraft:netherrack)
B(-1,32,-1,minecraft:netherrack)
B(-1,33,-1,minecraft:netherrack)
B(-1,34,-1,minecraft:netherrack)
B(-1,35,-1,minecraft:netherrack)
B(-1,36,-1,minecraft:netherrack)
B(-1,37,-1,minecraft:netherrack)
B(-1,38,-1,minecraft:netherrack)
B(-1,39,-1,minecraft:netherrack)
B(-1,40,-1,minecraft:netherrack)
B(-1,41,-1,minecraft:netherrack)
B(-1,42,-1,minecraft:netherrack)
B(-1,43,-1,minecraft:netherrack)
B(-1,44,-1,minecraft:netherrack)
B(-1,45,-1,minecraft:netherrack)
B(-1,46,-1,minecraft:netherrack)
B(-1,47,-1,minecraft:netherrack)
B(-1,48,-1,minecraft:netherrack)
B(-1,49,-1,minecraft:netherrack)
B(-1,50,-1,minecraft:netherrack)
B(-1,51,-1,minecraft:netherrack)
B(-1,52,-1,minecraft:netherrack)
B(-1,53,-1,minecraft:netherrack)
B(-1,54,-1,minecraft:netherrack)
B(-1,55,-1,minecraft:netherrack)
B(-1,56,-1,minecraft:netherrack)
B(-1,57,-1,minecraft:netherrack)
B(-1,58,-1,minecraft:netherrack)
B(-1,59,-1,minecraft:netherrack)
B(-1,60,-1,minecraft:netherrack)
B(-1,0,0,minecraft:netherrack)
B(-1,1,0,minecraft:netherrack)
B(-1,2,0,minecraft:netherrack)
B(-1,0,1,minecraft:soul_soil)
B(-1,1,1,minecraft:soul_soil)
B(-1,2,1,minecraft:netherrack)
B(-1,0,2,minecraft:soul_soil)
B(-1,1,2,minecraft:soul_soil)
B(-1,2,2,minecraft:netherrack)
B(-1,0,3,minecraft:soul_soil)
B(-1,1,3,minecraft:soul_soil)
B(-1,2,3,minecraft:netherrack)
B(-1,0,4,minecraft:soul_soil)
B(-1,1,4,minecraft:soul_soil)
B(-1,2,4,minecraft:netherrack)
B(-1,0,5,minecraft:soul_soil)
B(-1,1,5,minecraft:netherrack)
B(-1,0,6,minecraft:soul_soil)
B(-1,1,6,minecraft:netherrack)
B(-1,0,7,minecraft:soul_soil)
B(-1,1,7,minecraft:netherrack)
B(-1,0,8,minecraft:soul_soil)
B(-1,1,8,minecraft:netherrack)
B(0,0,-7,minecraft:netherrack)
B(0,1,-7,minecraft:netherrack)
B(0,2,-7,minecraft:netherrack)
B(0,3,-7,minecraft:netherrack)
B(0,4,-7,minecraft:netherrack)
B(0,5,-7,minecraft:netherrack)
B(0,6,-7,minecraft:netherrack)
B(0,7,-7,minecraft:netherrack)
B(0,8,-7,minecraft:netherrack)
B(0,9,-7,minecraft:netherrack)
B(0,10,-7,minecraft:netherrack)
B(0,11,-7,minecraft:netherrack)
B(0,12,-7,minecraft:netherrack)
B(0,13,-7,minecraft:netherrack)
B(0,14,-7,minecraft:netherrack)
B(0,15,-7,minecraft:netherrack)
B(0,16,-7,minecraft:netherrack)
B(0,17,-7,minecraft:netherrack)
B(0,18,-7,minecraft:netherrack)
B(0,19,-7,minecraft:netherrack)
B(0,20,-7,minecraft:netherrack)
B(0,21,-7,minecraft:netherrack)
B(0,22,-7,minecraft:netherrack)
B(0,23,-7,minecraft:netherrack)
B(0,24,-7,minecraft:netherrack)
B(0,25,-7,minecraft:netherrack)
B(0,26,-7,minecraft:netherrack)
B(0,27,-7,minecraft:netherrack)
B(0,28,-7,minecraft:netherrack)
B(0,29,-7,minecraft:netherrack)
B(0,30,-7,minecraft:netherrack)
B(0,31,-7,minecraft:netherrack)
B(0,32,-7,minecraft:netherrack)
B(0,33,-7,minecraft:netherrack)
B(0,34,-7,minecraft:netherrack)
B(0,35,-7,minecraft:netherrack)
B(0,36,-7,minecraft:netherrack)
B(0,37,-7,minecraft:netherrack)
B(0,38,-7,minecraft:netherrack)
B(0,39,-7,minecraft:netherrack)
B(0,40,-7,minecraft:netherrack)
B(0,41,-7,minecraft:netherrack)
B(0,42,-7,minecraft:netherrack)
B(0,43,-7,minecraft:netherrack)
B(0,44,-7,minecraft:netherrack)
B(0,45,-7,minecraft:netherrack)
B(0,46,-7,minecraft:netherrack)
B(0,47,-7,minecraft:netherrack)
B(0,48,-7,minecraft:netherrack)
B(0,49,-7,minecraft:netherrack)
B(0,50,-7,minecraft:netherrack)
B(0,51,-7,minecraft:netherrack)
B(0,52,-7,minecraft:netherrack)
B(0,53,-7,minecraft:netherrack)
B(0,54,-7,minecraft:netherrack)
B(0,55,-7,minecraft:netherrack)
B(0,56,-7,minecraft:netherrack)
B(0,57,-7,minecraft:netherrack)
B(0,58,-7,minecraft:netherrack)
B(0,59,-7,minecraft:netherrack)
B(0,60,-7,minecraft:netherrack)
B(0,0,-6,minecraft:netherrack)
B(0,1,-6,minecraft:netherrack)
B(0,2,-6,minecraft:netherrack)
B(0,3,-6,minecraft:netherrack)
B(0,4,-6,minecraft:netherrack)
B(0,5,-6,minecraft:netherrack)
B(0,6,-6,minecraft:netherrack)
B(0,7,-6,minecraft:netherrack)
B(0,8,-6,minecraft:netherrack)
B(0,9,-6,minecraft:netherrack)
B(0,10,-6,minecraft:netherrack)
B(0,11,-6,minecraft:netherrack)
B(0,12,-6,minecraft:netherrack)
B(0,13,-6,minecraft:netherrack)
B(0,14,-6,minecraft:netherrack)
B(0,15,-6,minecraft:netherrack)
B(0,16,-6,minecraft:netherrack)
B(0,17,-6,minecraft:netherrack)
B(0,18,-6,minecraft:netherrack)
B(0,19,-6,minecraft:netherrack)
B(0,20,-6,minecraft:netherrack)
B(0,21,-6,minecraft:netherrack)
B(0,22,-6,minecraft:netherrack)
B(0,23,-6,minecraft:netherrack)
B(0,24,-6,minecraft:netherrack)
B(0,25,-6,minecraft:netherrack)
B(0,26,-6,minecraft:netherrack)
B(0,27,-6,minecraft:netherrack)
B(0,28,-6,minecraft:netherrack)
B(0,29,-6,minecraft:netherrack)
B(0,30,-6,minecraft:netherrack)
B(0,31,-6,minecraft:netherrack)
B(0,32,-6,minecraft:netherrack)
B(0,33,-6,minecraft:netherrack)
B(0,34,-6,minecraft:netherrack)
B(0,35,-6,minecraft:netherrack)
B(0,36,-6,minecraft:netherrack)
B(0,37,-6,minecraft:netherrack)
B(0,38,-6,minecraft:netherrack)
B(0,39,-6,minecraft:netherrack)
B(0,40,-6,minecraft:netherrack)
B(0,41,-6,minecraft:netherrack)
B(0,42,-6,minecraft:netherrack)
B(0,43,-6,minecraft:netherrack)
B(0,44,-6,minecraft:netherrack)
B(0,45,-6,minecraft:netherrack)
B(0,46,-6,minecraft:netherrack)
B(0,47,-6,minecraft:netherrack)
B(0,48,-6,minecraft:netherrack)
B(0,49,-6,minecraft:netherrack)
B(0,50,-6,minecraft:netherrack)
B(0,51,-6,minecraft:netherrack)
B(0,52,-6,minecraft:netherrack)
B(0,53,-6,minecraft:netherrack)
B(0,54,-6,minecraft:netherrack)
B(0,55,-6,minecraft:netherrack)
B(0,56,-6,minecraft:netherrack)
B(0,57,-6,minecraft:netherrack)
B(0,58,-6,minecraft:netherrack)
B(0,59,-6,minecraft:netherrack)
B(0,60,-6,minecraft:netherrack)
B(0,61,-6,minecraft:netherrack)
B(0,0,-5,minecraft:netherrack)
B(0,1,-5,minecraft:netherrack)
B(0,2,-5,minecraft:netherrack)
B(0,3,-5,minecraft:netherrack)
B(0,4,-5,minecraft:netherrack)
B(0,5,-5,minecraft:netherrack)
B(0,6,-5,minecraft:netherrack)
B(0,7,-5,minecraft:netherrack)
B(0,8,-5,minecraft:netherrack)
B(0,9,-5,minecraft:netherrack)
B(0,10,-5,minecraft:netherrack)
B(0,11,-5,minecraft:netherrack)
B(0,12,-5,minecraft:netherrack)
B(0,13,-5,minecraft:netherrack)
B(0,14,-5,minecraft:netherrack)
B(0,15,-5,minecraft:netherrack)
B(0,16,-5,minecraft:netherrack)
B(0,17,-5,minecraft:netherrack)
B(0,18,-5,minecraft:netherrack)
B(0,19,-5,minecraft:netherrack)
B(0,20,-5,minecraft:netherrack)
B(0,21,-5,minecraft:netherrack)
B(0,22,-5,minecraft:netherrack)
B(0,23,-5,minecraft:netherrack)
B(0,24,-5,minecraft:netherrack)
B(0,25,-5,minecraft:netherrack)
B(0,26,-5,minecraft:netherrack)
B(0,27,-5,minecraft:netherrack)
B(0,28,-5,minecraft:netherrack)
B(0,29,-5,minecraft:netherrack)
B(0,30,-5,minecraft:netherrack)
B(0,31,-5,minecraft:netherrack)
B(0,32,-5,minecraft:netherrack)
B(0,33,-5,minecraft:netherrack)
B(0,34,-5,minecraft:netherrack)
B(0,35,-5,minecraft:netherrack)
B(0,36,-5,minecraft:netherrack)
B(0,37,-5,minecraft:netherrack)
B(0,38,-5,minecraft:netherrack)
B(0,39,-5,minecraft:netherrack)
B(0,40,-5,minecraft:netherrack)
B(0,41,-5,minecraft:netherrack)
B(0,42,-5,minecraft:netherrack)
B(0,43,-5,minecraft:netherrack)
B(0,44,-5,minecraft:netherrack)
B(0,45,-5,minecraft:netherrack)
B(0,46,-5,minecraft:netherrack)
B(0,47,-5,minecraft:netherrack)
B(0,48,-5,minecraft:netherrack)
B(0,49,-5,minecraft:netherrack)
B(0,50,-5,minecraft:netherrack)
B(0,51,-5,minecraft:netherrack)
B(0,52,-5,minecraft:netherrack)
B(0,53,-5,minecraft:netherrack)
B(0,54,-5,minecraft:netherrack)
B(0,55,-5,minecraft:netherrack)
B(0,56,-5,minecraft:netherrack)
B(0,57,-5,minecraft:netherrack)
B(0,58,-5,minecraft:netherrack)
B(0,59,-5,minecraft:netherrack)
B(0,60,-5,minecraft:netherrack)
B(0,61,-5,minecraft:netherrack)
B(0,0,-4,minecraft:netherrack)
B(0,1,-4,minecraft:netherrack)
B(0,2,-4,minecraft:netherrack)
B(0,3,-4,minecraft:netherrack)
B(0,4,-4,minecraft:netherrack)
B(0,5,-4,minecraft:netherrack)
B(0,6,-4,minecraft:netherrack)
B(0,7,-4,minecraft:netherrack)
B(0,8,-4,minecraft:netherrack)
B(0,9,-4,minecraft:netherrack)
B(0,10,-4,minecraft:netherrack)
B(0,11,-4,minecraft:netherrack)
B(0,12,-4,minecraft:netherrack)
B(0,13,-4,minecraft:netherrack)
B(0,14,-4,minecraft:netherrack)
B(0,15,-4,minecraft:netherrack)
B(0,16,-4,minecraft:netherrack)
B(0,17,-4,minecraft:netherrack)
B(0,18,-4,minecraft:netherrack)
B(0,19,-4,minecraft:netherrack)
B(0,20,-4,minecraft:netherrack)
B(0,21,-4,minecraft:netherrack)
B(0,22,-4,minecraft:netherrack)
B(0,23,-4,minecraft:netherrack)
B(0,24,-4,minecraft:netherrack)
B(0,25,-4,minecraft:netherrack)
B(0,26,-4,minecraft:netherrack)
B(0,27,-4,minecraft:netherrack)
B(0,28,-4,minecraft:netherrack)
B(0,29,-4,minecraft:netherrack)
B(0,30,-4,minecraft:netherrack)
B(0,31,-4,minecraft:netherrack)
B(0,32,-4,minecraft:netherrack)
B(0,33,-4,minecraft:netherrack)
B(0,34,-4,minecraft:netherrack)
B(0,35,-4,minecraft:netherrack)
B(0,36,-4,minecraft:netherrack)
B(0,37,-4,minecraft:netherrack)
B(0,38,-4,minecraft:netherrack)
B(0,39,-4,minecraft:netherrack)
B(0,40,-4,minecraft:netherrack)
B(0,41,-4,minecraft:netherrack)
B(0,42,-4,minecraft:netherrack)
B(0,43,-4,minecraft:netherrack)
B(0,44,-4,minecraft:netherrack)
B(0,45,-4,minecraft:netherrack)
B(0,46,-4,minecraft:netherrack)
B(0,47,-4,minecraft:netherrack)
B(0,48,-4,minecraft:netherrack)
B(0,49,-4,minecraft:netherrack)
B(0,50,-4,minecraft:netherrack)
B(0,51,-4,minecraft:netherrack)
B(0,52,-4,minecraft:netherrack)
B(0,53,-4,minecraft:netherrack)
B(0,54,-4,minecraft:netherrack)
B(0,55,-4,minecraft:netherrack)
B(0,56,-4,minecraft:netherrack)
B(0,57,-4,minecraft:netherrack)
B(0,58,-4,minecraft:netherrack)
B(0,59,-4,minecraft:netherrack)
B(0,60,-4,minecraft:netherrack)
B(0,61,-4,minecraft:netherrack)
B(0,0,-3,minecraft:netherrack)
B(0,1,-3,minecraft:netherrack)
B(0,2,-3,minecraft:netherrack)
B(0,3,-3,minecraft:netherrack)
B(0,4,-3,minecraft:netherrack)
B(0,5,-3,minecraft:netherrack)
B(0,6,-3,minecraft:netherrack)
B(0,7,-3,minecraft:netherrack)
B(0,8,-3,minecraft:netherrack)
B(0,9,-3,minecraft:netherrack)
B(0,10,-3,minecraft:netherrack)
B(0,11,-3,minecraft:netherrack)
B(0,12,-3,minecraft:netherrack)
B(0,13,-3,minecraft:netherrack)
B(0,14,-3,minecraft:netherrack)
B(0,15,-3,minecraft:netherrack)
B(0,16,-3,minecraft:netherrack)
B(0,17,-3,minecraft:netherrack)
B(0,18,-3,minecraft:netherrack)
B(0,19,-3,minecraft:netherrack)
B(0,20,-3,minecraft:netherrack)
B(0,21,-3,minecraft:netherrack)
B(0,22,-3,minecraft:netherrack)
B(0,23,-3,minecraft:netherrack)
B(0,24,-3,minecraft:netherrack)
B(0,25,-3,minecraft:netherrack)
B(0,26,-3,minecraft:netherrack)
B(0,27,-3,minecraft:netherrack)
B(0,28,-3,minecraft:netherrack)
B(0,29,-3,minecraft:netherrack)
B(0,30,-3,minecraft:netherrack)
B(0,31,-3,minecraft:netherrack)
