
#######################################################################
# +-----------------------------------------------------------------+ #
# |                            BO4 object                           | #
# +-----------------------------------------------------------------+ #
#######################################################################

Author: Unknown

Description: No description given

SettingsMode: WriteWithoutComments


#######################################################################
# +-----------------------------------------------------------------+ #
# |                          Main settings                          | #
# +-----------------------------------------------------------------+ #
#######################################################################

FixedRotation: 

Frequency: 0

SpawnHeight: highestBlock

UseCenterForHighestBlock: true

##############################
# Height Limits for the BO4. #
##############################

MinHeight: 0

MaxHeight: 255

InheritBO3: 

InheritBO3Rotation: NORTH

OverrideChildSettings: true

OverrideParentHeight: false

CanOverride: false

BranchFrequency: 0

BranchFrequencyGroup: 

MustBeBelowOther: false

MustBeInside: 

CannotBeInside: 

ReplacesBO3: 

MustBeInsideWorldBorders: false

CanSpawnOnWater: true

SpawnOnWaterOnly: false

SpawnUnderWater: false

SpawnAtWaterLevel: false

HeightOffset: 0

RemoveAir: true

ReplaceAbove: 

ReplaceBelow: 

ReplaceWithBiomeBlocks: true

ReplaceWithSurfaceBlock: GRASS

ReplaceWithGroundBlock: DIRT

ReplaceWithStoneBlock: STONE

SmoothRadius: 0

SmoothHeightOffset: 0

SmoothStartTop: false

SmoothStartWood: false

SmoothingSurfaceBlock: 

SmoothingGroundBlock: 

BO3Group: 

IsSpawnPoint: false

DoReplaceBlocks: true


#######################################################################
# +-----------------------------------------------------------------+ #
# |                              Blocks                             | #
# +-----------------------------------------------------------------+ #
#######################################################################

B(-8,0,-7,minecraft:soul_soil)
B(-8,1,-7,minecraft:soul_soil)
B(-8,2,-7,minecraft:netherrack)
B(-8,0,-6,minecraft:soul_soil)
B(-8,1,-6,minecraft:soul_soil)
B(-8,2,-6,minecraft:soul_soil)
B(-8,3,-6,minecraft:netherrack)
B(-8,0,-5,minecraft:soul_soil)
B(-8,1,-5,minecraft:soul_soil)
B(-8,2,-5,minecraft:netherrack)
B(-8,0,-4,minecraft:soul_soil)
B(-8,1,-4,minecraft:soul_soil)
B(-8,2,-4,minecraft:netherrack)
B(-8,0,-3,minecraft:soul_soil)
B(-8,1,-3,minecraft:soul_soil)
B(-8,2,-3,minecraft:netherrack)
B(-8,0,-2,minecraft:soul_soil)
B(-8,1,-2,minecraft:soul_soil)
B(-8,2,-2,minecraft:netherrack)
B(-8,0,-1,minecraft:soul_soil)
B(-8,1,-1,minecraft:soul_soil)
B(-8,2,-1,minecraft:soul_soil)
B(-8,3,-1,minecraft:netherrack)
B(-8,0,0,minecraft:soul_soil)
B(-8,1,0,minecraft:soul_soil)
B(-8,2,0,minecraft:soul_soil)
B(-8,3,0,minecraft:netherrack)
B(-8,0,1,minecraft:netherrack)
B(-8,1,1,minecraft:soul_soil)
B(-8,2,1,minecraft:soul_soil)
B(-8,3,1,minecraft:soul_soil)
B(-8,4,1,minecraft:netherrack)
B(-8,0,2,minecraft:netherrack)
B(-8,1,2,minecraft:soul_soil)
B(-8,2,2,minecraft:soul_soil)
B(-8,3,2,minecraft:soul_soil)
B(-8,4,2,minecraft:netherrack)
B(-8,0,3,minecraft:netherrack)
B(-8,1,3,minecraft:netherrack)
B(-8,2,3,minecraft:soul_soil)
B(-8,3,3,minecraft:soul_soil)
B(-8,4,3,minecraft:soul_soil)
B(-8,5,3,minecraft:netherrack)
B(-8,0,4,minecraft:netherrack)
B(-8,1,4,minecraft:netherrack)
B(-8,2,4,minecraft:soul_soil)
B(-8,3,4,minecraft:soul_soil)
B(-8,4,4,minecraft:soul_soil)
B(-8,5,4,minecraft:netherrack)
B(-8,0,5,minecraft:netherrack)
B(-8,1,5,minecraft:netherrack)
B(-8,2,5,minecraft:soul_soil)
B(-8,3,5,minecraft:soul_soil)
B(-8,4,5,minecraft:soul_soil)
B(-8,5,5,minecraft:netherrack)
B(-8,0,6,minecraft:netherrack)
B(-8,1,6,minecraft:netherrack)
B(-8,2,6,minecraft:netherrack)
B(-8,3,6,minecraft:soul_soil)
B(-8,4,6,minecraft:soul_soil)
B(-8,5,6,minecraft:netherrack)
B(-8,0,7,minecraft:netherrack)
B(-8,1,7,minecraft:netherrack)
B(-8,2,7,minecraft:soul_soil)
B(-8,3,7,minecraft:soul_soil)
B(-8,4,7,minecraft:soul_soil)
B(-8,5,7,minecraft:netherrack)
B(-8,0,8,minecraft:netherrack)
B(-8,1,8,minecraft:netherrack)
B(-8,2,8,minecraft:netherrack)
B(-8,3,8,minecraft:soul_soil)
B(-8,4,8,minecraft:soul_soil)
B(-8,5,8,minecraft:netherrack)
B(-7,0,-7,minecraft:soul_soil)
B(-7,1,-7,minecraft:soul_soil)
B(-7,2,-7,minecraft:netherrack)
B(-7,0,-6,minecraft:soul_soil)
B(-7,1,-6,minecraft:soul_soil)
B(-7,2,-6,minecraft:soul_soil)
B(-7,3,-6,minecraft:netherrack)
B(-7,0,-5,minecraft:soul_soil)
B(-7,1,-5,minecraft:soul_soil)
B(-7,2,-5,minecraft:netherrack)
B(-7,0,-4,minecraft:soul_soil)
B(-7,1,-4,minecraft:soul_soil)
B(-7,2,-4,minecraft:netherrack)
B(-7,0,-3,minecraft:soul_soil)
B(-7,1,-3,minecraft:soul_soil)
B(-7,2,-3,minecraft:netherrack)
B(-7,0,-2,minecraft:soul_soil)
B(-7,1,-2,minecraft:soul_soil)
B(-7,2,-2,minecraft:netherrack)
B(-7,0,-1,minecraft:soul_soil)
B(-7,1,-1,minecraft:soul_soil)
B(-7,2,-1,minecraft:netherrack)
B(-7,0,0,minecraft:soul_soil)
B(-7,1,0,minecraft:soul_soil)
B(-7,2,0,minecraft:netherrack)
B(-7,0,1,minecraft:soul_soil)
B(-7,1,1,minecraft:soul_soil)
B(-7,2,1,minecraft:soul_soil)
B(-7,3,1,minecraft:netherrack)
B(-7,0,2,minecraft:soul_soil)
B(-7,1,2,minecraft:soul_soil)
B(-7,2,2,minecraft:soul_soil)
B(-7,3,2,minecraft:netherrack)
B(-7,0,3,minecraft:netherrack)
B(-7,1,3,minecraft:soul_soil)
B(-7,2,3,minecraft:soul_soil)
B(-7,3,3,minecraft:soul_soil)
B(-7,4,3,minecraft:netherrack)
B(-7,0,4,minecraft:netherrack)
B(-7,1,4,minecraft:netherrack)
B(-7,2,4,minecraft:soul_soil)
B(-7,3,4,minecraft:soul_soil)
B(-7,4,4,minecraft:soul_soil)
B(-7,5,4,minecraft:netherrack)
B(-7,0,5,minecraft:netherrack)
B(-7,1,5,minecraft:netherrack)
B(-7,2,5,minecraft:soul_soil)
B(-7,3,5,minecraft:soul_soil)
B(-7,4,5,minecraft:soul_soil)
B(-7,5,5,minecraft:netherrack)
B(-7,0,6,minecraft:netherrack)
B(-7,1,6,minecraft:netherrack)
B(-7,2,6,minecraft:soul_soil)
B(-7,3,6,minecraft:soul_soil)
B(-7,4,6,minecraft:soul_soil)
B(-7,5,6,minecraft:netherrack)
B(-7,0,7,minecraft:netherrack)
B(-7,1,7,minecraft:netherrack)
B(-7,2,7,minecraft:soul_soil)
B(-7,3,7,minecraft:soul_soil)
B(-7,4,7,minecraft:soul_soil)
B(-7,5,7,minecraft:netherrack)
B(-7,0,8,minecraft:netherrack)
B(-7,1,8,minecraft:netherrack)
B(-7,2,8,minecraft:netherrack)
B(-7,3,8,minecraft:soul_soil)
B(-7,4,8,minecraft:soul_soil)
B(-7,5,8,minecraft:netherrack)
B(-6,0,-7,minecraft:soul_soil)
B(-6,1,-7,minecraft:soul_soil)
B(-6,2,-7,minecraft:netherrack)
B(-6,0,-6,minecraft:soul_soil)
B(-6,1,-6,minecraft:soul_soil)
B(-6,2,-6,minecraft:soul_soil)
B(-6,3,-6,minecraft:netherrack)
B(-6,0,-5,minecraft:soul_soil)
B(-6,1,-5,minecraft:soul_soil)
B(-6,2,-5,minecraft:soul_soil)
B(-6,3,-5,minecraft:netherrack)
B(-6,0,-4,minecraft:soul_soil)
B(-6,1,-4,minecraft:soul_soil)
B(-6,2,-4,minecraft:netherrack)
B(-6,0,-3,minecraft:soul_soil)
B(-6,1,-3,minecraft:soul_soil)
B(-6,2,-3,minecraft:netherrack)
B(-6,0,-2,minecraft:soul_soil)
B(-6,1,-2,minecraft:netherrack)
B(-6,0,-1,minecraft:soul_soil)
B(-6,1,-1,minecraft:netherrack)
B(-6,0,0,minecraft:soul_soil)
B(-6,1,0,minecraft:netherrack)
B(-6,0,1,minecraft:soul_soil)
B(-6,1,1,minecraft:netherrack)
B(-6,0,2,minecraft:soul_soil)
B(-6,1,2,minecraft:netherrack)
B(-6,0,3,minecraft:soul_soil)
B(-6,1,3,minecraft:soul_soil)
B(-6,2,3,minecraft:soul_soil)
B(-6,3,3,minecraft:netherrack)
B(-6,0,4,minecraft:netherrack)
B(-6,1,4,minecraft:soul_soil)
B(-6,2,4,minecraft:soul_soil)
B(-6,3,4,minecraft:soul_soil)
B(-6,4,4,minecraft:netherrack)
B(-6,0,5,minecraft:netherrack)
B(-6,1,5,minecraft:netherrack)
B(-6,2,5,minecraft:soul_soil)
B(-6,3,5,minecraft:soul_soil)
B(-6,4,5,minecraft:soul_soil)
B(-6,5,5,minecraft:netherrack)
B(-6,0,6,minecraft:netherrack)
B(-6,1,6,minecraft:netherrack)
B(-6,2,6,minecraft:soul_soil)
B(-6,3,6,minecraft:soul_soil)
B(-6,4,6,minecraft:soul_soil)
B(-6,5,6,minecraft:netherrack)
B(-6,0,7,minecraft:netherrack)
B(-6,1,7,minecraft:netherrack)
B(-6,2,7,minecraft:soul_soil)
B(-6,3,7,minecraft:soul_soil)
B(-6,4,7,minecraft:soul_soil)
B(-6,5,7,minecraft:netherrack)
B(-6,0,8,minecraft:netherrack)
B(-6,1,8,minecraft:netherrack)
B(-6,2,8,minecraft:soul_soil)
B(-6,3,8,minecraft:soul_soil)
B(-6,4,8,minecraft:soul_soil)
B(-6,5,8,minecraft:netherrack)
B(-5,0,-7,minecraft:soul_soil)
B(-5,1,-7,minecraft:soul_soil)
B(-5,2,-7,minecraft:netherrack)
B(-5,0,-6,minecraft:soul_soil)
B(-5,1,-6,minecraft:soul_soil)
B(-5,2,-6,minecraft:netherrack)
B(-5,0,-5,minecraft:soul_soil)
B(-5,1,-5,minecraft:soul_soil)
B(-5,2,-5,minecraft:netherrack)
B(-5,0,-4,minecraft:soul_soil)
B(-5,1,-4,minecraft:soul_soil)
B(-5,2,-4,minecraft:netherrack)
B(-5,0,-3,minecraft:soul_soil)
B(-5,1,-3,minecraft:netherrack)
B(-5,0,-2,minecraft:soul_soil)
B(-5,1,-2,minecraft:netherrack)
B(-5,0,-1,minecraft:soul_soil)
B(-5,1,-1,minecraft:netherrack)
B(-5,0,0,minecraft:soul_soil)
B(-5,1,0,minecraft:netherrack)
B(-5,0,1,minecraft:soul_soil)
B(-5,1,1,minecraft:netherrack)
B(-5,0,2,minecraft:soul_soil)
B(-5,1,2,minecraft:netherrack)
B(-5,0,3,minecraft:soul_soil)
B(-5,1,3,minecraft:soul_soil)
B(-5,2,3,minecraft:netherrack)
B(-5,0,4,minecraft:soul_soil)
B(-5,1,4,minecraft:soul_soil)
B(-5,2,4,minecraft:soul_soil)
B(-5,3,4,minecraft:netherrack)
B(-5,0,5,minecraft:netherrack)
B(-5,1,5,minecraft:soul_soil)
B(-5,2,5,minecraft:soul_soil)
B(-5,3,5,minecraft:soul_soil)
B(-5,4,5,minecraft:netherrack)
B(-5,0,6,minecraft:netherrack)
B(-5,1,6,minecraft:netherrack)
B(-5,2,6,minecraft:soul_soil)
B(-5,3,6,minecraft:soul_soil)
B(-5,4,6,minecraft:soul_soil)
B(-5,5,6,minecraft:netherrack)
B(-5,0,7,minecraft:netherrack)
B(-5,1,7,minecraft:netherrack)
B(-5,2,7,minecraft:soul_soil)
B(-5,3,7,minecraft:soul_soil)
B(-5,4,7,minecraft:soul_soil)
B(-5,5,7,minecraft:netherrack)
B(-5,0,8,minecraft:netherrack)
B(-5,1,8,minecraft:soul_soil)
B(-5,2,8,minecraft:soul_soil)
B(-5,3,8,minecraft:soul_soil)
B(-5,4,8,minecraft:netherrack)
B(-4,0,-7,minecraft:soul_soil)
B(-4,1,-7,minecraft:soul_soil)
B(-4,2,-7,minecraft:netherrack)
B(-4,0,-6,minecraft:soul_soil)
B(-4,1,-6,minecraft:soul_soil)
B(-4,2,-6,minecraft:netherrack)
B(-4,0,-5,minecraft:soul_soil)
B(-4,1,-5,minecraft:soul_soil)
B(-4,2,-5,minecraft:netherrack)
B(-4,0,-4,minecraft:soul_soil)
B(-4,1,-4,minecraft:netherrack)
B(-4,0,-3,minecraft:soul_soil)
B(-4,1,-3,minecraft:netherrack)
B(-4,0,-2,minecraft:netherrack)
B(-4,0,-1,minecraft:netherrack)
B(-4,0,0,minecraft:soul_soil)
B(-4,1,0,minecraft:netherrack)
B(-4,0,1,minecraft:soul_soil)
B(-4,1,1,minecraft:netherrack)
B(-4,0,2,minecraft:soul_soil)
B(-4,1,2,minecraft:netherrack)
B(-4,0,3,minecraft:soul_soil)
B(-4,1,3,minecraft:netherrack)
B(-4,0,4,minecraft:soul_soil)
B(-4,1,4,minecraft:soul_soil)
B(-4,2,4,minecraft:netherrack)
B(-4,0,5,minecraft:soul_soil)
B(-4,1,5,minecraft:soul_soil)
B(-4,2,5,minecraft:soul_soil)
B(-4,3,5,minecraft:netherrack)
B(-4,0,6,minecraft:netherrack)
B(-4,1,6,minecraft:soul_soil)
B(-4,2,6,minecraft:soul_soil)
B(-4,3,6,minecraft:soul_soil)
B(-4,4,6,minecraft:netherrack)
B(-4,0,7,minecraft:soul_soil)
B(-4,1,7,minecraft:soul_soil)
B(-4,2,7,minecraft:soul_soil)
B(-4,3,7,minecraft:netherrack)
B(-4,0,8,minecraft:soul_soil)
B(-4,1,8,minecraft:soul_soil)
B(-4,2,8,minecraft:soul_soil)
B(-4,3,8,minecraft:netherrack)
B(-3,0,-7,minecraft:soul_soil)
B(-3,1,-7,minecraft:soul_soil)
B(-3,2,-7,minecraft:netherrack)
B(-3,0,-6,minecraft:soul_soil)
B(-3,1,-6,minecraft:soul_soil)
B(-3,2,-6,minecraft:netherrack)
B(-3,0,-5,minecraft:soul_soil)
B(-3,1,-5,minecraft:netherrack)
B(-3,0,-4,minecraft:soul_soil)
B(-3,1,-4,minecraft:netherrack)
B(-3,0,-3,minecraft:netherrack)
B(-3,0,-2,minecraft:netherrack)
B(-3,0,-1,minecraft:netherrack)
B(-3,0,0,minecraft:netherrack)
B(-3,0,1,minecraft:netherrack)
B(-3,0,2,minecraft:netherrack)
B(-3,0,3,minecraft:soul_soil)
B(-3,1,3,minecraft:netherrack)
B(-3,0,4,minecraft:soul_soil)
B(-3,1,4,minecraft:netherrack)
B(-3,0,5,minecraft:soul_soil)
B(-3,1,5,minecraft:soul_soil)
B(-3,2,5,minecraft:netherrack)
B(-3,0,6,minecraft:soul_soil)
B(-3,1,6,minecraft:soul_soil)
B(-3,2,6,minecraft:netherrack)
B(-3,0,7,minecraft:soul_soil)
B(-3,1,7,minecraft:soul_soil)
B(-3,2,7,minecraft:netherrack)
B(-3,0,8,minecraft:soul_soil)
B(-3,1,8,minecraft:soul_soil)
B(-3,2,8,minecraft:netherrack)
B(-2,0,-7,minecraft:soul_soil)
B(-2,1,-7,minecraft:soul_soil)
B(-2,2,-7,minecraft:netherrack)
B(-2,0,-6,minecraft:soul_soil)
B(-2,1,-6,minecraft:netherrack)
B(-2,0,-5,minecraft:soul_soil)
B(-2,1,-5,minecraft:netherrack)
B(-2,0,-4,minecraft:netherrack)
B(-2,0,-3,minecraft:netherrack)
B(-2,0,0,minecraft:netherrack)
B(-2,0,1,minecraft:netherrack)
B(-2,0,2,minecraft:netherrack)
B(-2,0,3,minecraft:netherrack)
B(-2,0,4,minecraft:netherrack)
B(-2,0,5,minecraft:netherrack)
B(-2,0,6,minecraft:netherrack)
B(-2,0,7,minecraft:soul_soil)
B(-2,1,7,minecraft:netherrack)
B(-2,0,8,minecraft:soul_soil)
B(-2,1,8,minecraft:netherrack)
B(-1,0,-7,minecraft:soul_soil)
B(-1,1,-7,minecraft:netherrack)
B(-1,0,-6,minecraft:soul_soil)
B(-1,1,-6,minecraft:netherrack)
B(-1,0,-5,minecraft:soul_soil)
B(-1,1,-5,minecraft:netherrack)
B(-1,0,-4,minecraft:netherrack)
B(-1,0,1,minecraft:netherrack)
B(-1,0,2,minecraft:netherrack)
B(-1,0,3,minecraft:netherrack)
B(-1,0,4,minecraft:soul_soil)
B(-1,1,4,minecraft:netherrack)
B(-1,0,5,minecraft:soul_soil)
B(-1,1,5,minecraft:netherrack)
B(-1,0,6,minecraft:soul_soil)
B(-1,1,6,minecraft:netherrack)
B(-1,0,7,minecraft:soul_soil)
B(-1,1,7,minecraft:soul_soil)
B(-1,2,7,minecraft:netherrack)
B(-1,0,8,minecraft:soul_soil)
B(-1,1,8,minecraft:soul_soil)
B(-1,2,8,minecraft:netherrack)
B(0,0,-7,minecraft:soul_soil)
B(0,1,-7,minecraft:netherrack)
B(0,0,-6,minecraft:soul_soil)
B(0,1,-6,minecraft:netherrack)
B(0,0,-5,minecraft:netherrack)
B(0,0,-4,minecraft:netherrack)
B(0,0,2,minecraft:netherrack)
B(0,0,3,minecraft:netherrack)
B(0,0,4,minecraft:soul_soil)
B(0,1,4,minecraft:netherrack)
B(0,0,5,minecraft:soul_soil)
B(0,1,5,minecraft:soul_soil)
B(0,2,5,minecraft:netherrack)
B(0,0,6,minecraft:soul_soil)
B(0,1,6,minecraft:soul_soil)
B(0,2,6,minecraft:soul_soil)
B(0,3,6,minecraft:netherrack)
B(0,0,7,minecraft:soul_soil)
B(0,1,7,minecraft:soul_soil)
B(0,2,7,minecraft:soul_soil)
B(0,3,7,minecraft:netherrack)
B(0,0,8,minecraft:soul_soil)
B(0,1,8,minecraft:soul_soil)
B(0,2,8,minecraft:soul_soil)
B(0,3,8,minecraft:netherrack)
B(1,0,-7,minecraft:soul_soil)
B(1,1,-7,minecraft:netherrack)
B(1,0,-6,minecraft:soul_soil)
B(1,1,-6,minecraft:netherrack)
B(1,0,-5,minecraft:netherrack)
B(1,0,2,minecraft:netherrack)
B(1,0,3,minecraft:soul_soil)
B(1,1,3,minecraft:netherrack)
B(1,0,4,minecraft:soul_soil)
B(1,1,4,minecraft:soul_soil)
B(1,2,4,minecraft:netherrack)
B(1,0,5,minecraft:soul_soil)
B(1,1,5,minecraft:soul_soil)
B(1,2,5,minecraft:soul_soil)
B(1,3,5,minecraft:netherrack)
B(1,0,6,minecraft:netherrack)
B(1,1,6,minecraft:soul_soil)
B(1,2,6,minecraft:soul_soil)
B(1,3,6,minecraft:soul_soil)
B(1,4,6,minecraft:netherrack)
B(1,0,7,minecraft:netherrack)
B(1,1,7,minecraft:soul_soil)
B(1,2,7,minecraft:soul_soil)
B(1,3,7,minecraft:soul_soil)
B(1,4,7,minecraft:netherrack)
B(1,0,8,minecraft:soul_soil)
B(1,1,8,minecraft:soul_soil)
B(1,2,8,minecraft:soul_soil)
B(1,3,8,minecraft:netherrack)
B(2,0,-7,minecraft:soul_soil)
B(2,1,-7,minecraft:netherrack)
B(2,0,-6,minecraft:soul_soil)
B(2,1,-6,minecraft:netherrack)
B(2,0,-5,minecraft:netherrack)
B(2,0,3,minecraft:soul_soil)
B(2,1,3,minecraft:netherrack)
B(2,0,4,minecraft:soul_soil)
B(2,1,4,minecraft:soul_soil)
B(2,2,4,minecraft:netherrack)
B(2,0,5,minecraft:soul_soil)
B(2,1,5,minecraft:soul_soil)
B(2,2,5,minecraft:soul_soil)
B(2,3,5,minecraft:netherrack)
B(2,0,6,minecraft:netherrack)
B(2,1,6,minecraft:netherrack)
B(2,2,6,minecraft:soul_soil)
B(2,3,6,minecraft:soul_soil)
B(2,4,6,minecraft:soul_soil)
B(2,5,6,minecraft:netherrack)
B(2,0,7,minecraft:soul_soil)
B(2,1,7,minecraft:soul_soil)
B(2,2,7,minecraft:soul_soil)
B(2,3,7,minecraft:soul_soil)
B(2,4,7,minecraft:netherrack)
B(2,0,8,minecraft:netherrack)
B(2,1,8,minecraft:soul_soil)
B(2,2,8,minecraft:soul_soil)
B(2,3,8,minecraft:soul_soil)
B(2,4,8,minecraft:netherrack)
B(3,0,-7,minecraft:soul_soil)
B(3,1,-7,minecraft:soul_soil)
B(3,2,-7,minecraft:netherrack)
B(3,0,-6,minecraft:soul_soil)
B(3,1,-6,minecraft:soul_soil)
B(3,2,-6,minecraft:netherrack)
B(3,0,-5,minecraft:soul_soil)
B(3,1,-5,minecraft:netherrack)
B(3,0,-4,minecraft:netherrack)
B(3,0,-3,minecraft:netherrack)
B(3,0,-1,minecraft:netherrack)
B(3,0,0,minecraft:netherrack)
B(3,0,1,minecraft:netherrack)
B(3,0,2,minecraft:netherrack)
B(3,0,3,minecraft:soul_soil)
B(3,1,3,minecraft:netherrack)
B(3,0,4,minecraft:soul_soil)
B(3,1,4,minecraft:soul_soil)
B(3,2,4,minecraft:netherrack)
B(3,0,5,minecraft:soul_soil)
B(3,1,5,minecraft:soul_soil)
B(3,2,5,minecraft:soul_soil)
B(3,3,5,minecraft:netherrack)
B(3,0,6,minecraft:netherrack)
B(3,1,6,minecraft:soul_soil)
B(3,2,6,minecraft:soul_soil)
B(3,3,6,minecraft:soul_soil)
B(3,4,6,minecraft:netherrack)
B(3,0,7,minecraft:soul_soil)
B(3,1,7,minecraft:soul_soil)
B(3,2,7,minecraft:soul_soil)
B(3,3,7,minecraft:soul_soil)
B(3,4,7,minecraft:netherrack)
B(3,0,8,minecraft:soul_soil)
B(3,1,8,minecraft:soul_soil)
B(3,2,8,minecraft:soul_soil)
B(3,3,8,minecraft:soul_soil)
B(3,4,8,minecraft:netherrack)
B(4,0,-7,minecraft:soul_soil)
B(4,1,-7,minecraft:soul_soil)
B(4,2,-7,minecraft:netherrack)
B(4,0,-6,minecraft:soul_soil)
B(4,1,-6,minecraft:soul_soil)
B(4,2,-6,minecraft:soul_soil)
B(4,3,-6,minecraft:netherrack)
B(4,0,-5,minecraft:soul_soil)
B(4,1,-5,minecraft:soul_soil)
B(4,2,-5,minecraft:netherrack)
B(4,0,-4,minecraft:soul_soil)
B(4,1,-4,minecraft:soul_soil)
B(4,2,-4,minecraft:netherrack)
B(4,0,-3,minecraft:soul_soil)
B(4,1,-3,minecraft:netherrack)
B(4,0,-2,minecraft:soul_soil)
B(4,1,-2,minecraft:netherrack)
B(4,0,-1,minecraft:soul_soil)
B(4,1,-1,minecraft:netherrack)
B(4,0,0,minecraft:soul_soil)
B(4,1,0,minecraft:netherrack)
B(4,0,1,minecraft:soul_soil)
B(4,1,1,minecraft:netherrack)
B(4,0,2,minecraft:soul_soil)
B(4,1,2,minecraft:netherrack)
B(4,0,3,minecraft:soul_soil)
B(4,1,3,minecraft:soul_soil)
B(4,2,3,minecraft:netherrack)
B(4,0,4,minecraft:soul_soil)
B(4,1,4,minecraft:soul_soil)
B(4,2,4,minecraft:soul_soil)
B(4,3,4,minecraft:netherrack)
B(4,0,5,minecraft:soul_soil)
B(4,1,5,minecraft:soul_soil)
B(4,2,5,minecraft:soul_soil)
B(4,3,5,minecraft:netherrack)
B(4,0,6,minecraft:soul_soil)
B(4,1,6,minecraft:soul_soil)
B(4,2,6,minecraft:soul_soil)
B(4,3,6,minecraft:soul_soil)
B(4,4,6,minecraft:netherrack)
B(4,0,7,minecraft:soul_soil)
B(4,1,7,minecraft:soul_soil)
B(4,2,7,minecraft:soul_soil)
B(4,3,7,minecraft:soul_soil)
B(4,4,7,minecraft:netherrack)
B(4,0,8,minecraft:soul_soil)
B(4,1,8,minecraft:soul_soil)
B(4,2,8,minecraft:soul_soil)
B(4,3,8,minecraft:netherrack)
B(5,0,-7,minecraft:soul_soil)
B(5,1,-7,minecraft:soul_soil)
B(5,2,-7,minecraft:soul_soil)
B(5,3,-7,minecraft:netherrack)
B(5,0,-6,minecraft:netherrack)
B(5,1,-6,minecraft:soul_soil)
B(5,2,-6,minecraft:soul_soil)
B(5,3,-6,minecraft:soul_soil)
B(5,4,-6,minecraft:netherrack)
B(5,0,-5,minecraft:soul_soil)
B(5,1,-5,minecraft:soul_soil)
B(5,2,-5,minecraft:soul_soil)
B(5,3,-5,minecraft:netherrack)
B(5,0,-4,minecraft:soul_soil)
B(5,1,-4,minecraft:soul_soil)
B(5,2,-4,minecraft:soul_soil)
B(5,3,-4,minecraft:netherrack)
B(5,0,-3,minecraft:soul_soil)
B(5,1,-3,minecraft:soul_soil)
B(5,2,-3,minecraft:soul_soil)
B(5,3,-3,minecraft:netherrack)
B(5,0,-2,minecraft:soul_soil)
B(5,1,-2,minecraft:soul_soil)
B(5,2,-2,minecraft:netherrack)
B(5,0,-1,minecraft:soul_soil)
B(5,1,-1,minecraft:soul_soil)
B(5,2,-1,minecraft:netherrack)
B(5,0,0,minecraft:soul_soil)
B(5,1,0,minecraft:soul_soil)
B(5,2,0,minecraft:netherrack)
B(5,0,1,minecraft:soul_soil)
B(5,1,1,minecraft:soul_soil)
B(5,2,1,minecraft:netherrack)
B(5,0,2,minecraft:soul_soil)
B(5,1,2,minecraft:soul_soil)
B(5,2,2,minecraft:netherrack)
B(5,0,3,minecraft:soul_soil)
B(5,1,3,minecraft:soul_soil)
B(5,2,3,minecraft:soul_soil)
B(5,3,3,minecraft:netherrack)
B(5,0,4,minecraft:soul_soil)
B(5,1,4,minecraft:soul_soil)
B(5,2,4,minecraft:soul_soil)
B(5,3,4,minecraft:netherrack)
B(5,0,5,minecraft:soul_soil)
B(5,1,5,minecraft:soul_soil)
B(5,2,5,minecraft:soul_soil)
B(5,3,5,minecraft:netherrack)
B(5,0,6,minecraft:soul_soil)
B(5,1,6,minecraft:soul_soil)
B(5,2,6,minecraft:soul_soil)
B(5,3,6,minecraft:netherrack)
B(5,0,7,minecraft:soul_soil)
B(5,1,7,minecraft:soul_soil)
B(5,2,7,minecraft:soul_soil)
B(5,3,7,minecraft:netherrack)
B(5,0,8,minecraft:soul_soil)
B(5,1,8,minecraft:soul_soil)
B(5,2,8,minecraft:soul_soil)
B(5,3,8,minecraft:netherrack)
B(6,0,-7,minecraft:netherrack)
B(6,1,-7,minecraft:soul_soil)
B(6,2,-7,minecraft:soul_soil)
B(6,3,-7,minecraft:soul_soil)
B(6,4,-7,minecraft:netherrack)
B(6,0,-6,minecraft:netherrack)
B(6,1,-6,minecraft:netherrack)
B(6,2,-6,minecraft:soul_soil)
B(6,3,-6,minecraft:soul_soil)
B(6,4,-6,minecraft:soul_soil)
B(6,5,-6,minecraft:netherrack)
B(6,0,-5,minecraft:netherrack)
B(6,1,-5,minecraft:soul_soil)
B(6,2,-5,minecraft:soul_soil)
B(6,3,-5,minecraft:soul_soil)
B(6,4,-5,minecraft:netherrack)
B(6,0,-4,minecraft:netherrack)
B(6,1,-4,minecraft:soul_soil)
B(6,2,-4,minecraft:soul_soil)
B(6,3,-4,minecraft:soul_soil)
B(6,4,-4,minecraft:netherrack)
B(6,0,-3,minecraft:netherrack)
B(6,1,-3,minecraft:soul_soil)
B(6,2,-3,minecraft:soul_soil)
B(6,3,-3,minecraft:soul_soil)
B(6,4,-3,minecraft:netherrack)
B(6,0,-2,minecraft:netherrack)
B(6,1,-2,minecraft:soul_soil)
B(6,2,-2,minecraft:soul_soil)
B(6,3,-2,minecraft:soul_soil)
B(6,4,-2,minecraft:netherrack)
B(6,0,-1,minecraft:netherrack)
B(6,1,-1,minecraft:soul_soil)
B(6,2,-1,minecraft:soul_soil)
B(6,3,-1,minecraft:soul_soil)
B(6,4,-1,minecraft:netherrack)
B(6,0,0,minecraft:netherrack)
B(6,1,0,minecraft:soul_soil)
B(6,2,0,minecraft:soul_soil)
B(6,3,0,minecraft:soul_soil)
B(6,4,0,minecraft:netherrack)
B(6,0,1,minecraft:netherrack)
B(6,1,1,minecraft:soul_soil)
B(6,2,1,minecraft:soul_soil)
B(6,3,1,minecraft:soul_soil)
B(6,4,1,minecraft:netherrack)
B(6,0,2,minecraft:netherrack)
B(6,1,2,minecraft:soul_soil)
B(6,2,2,minecraft:soul_soil)
B(6,3,2,minecraft:soul_soil)
B(6,4,2,minecraft:netherrack)
B(6,0,3,minecraft:soul_soil)
B(6,1,3,minecraft:soul_soil)
B(6,2,3,minecraft:soul_soil)
B(6,3,3,minecraft:netherrack)
B(6,0,4,minecraft:soul_soil)
B(6,1,4,minecraft:soul_soil)
B(6,2,4,minecraft:soul_soil)
B(6,3,4,minecraft:netherrack)
B(6,0,5,minecraft:soul_soil)
B(6,1,5,minecraft:soul_soil)
B(6,2,5,minecraft:soul_soil)
B(6,3,5,minecraft:netherrack)
B(6,0,6,minecraft:soul_soil)
B(6,1,6,minecraft:soul_soil)
B(6,2,6,minecraft:soul_soil)
B(6,3,6,minecraft:netherrack)
B(6,0,7,minecraft:soul_soil)
B(6,1,7,minecraft:soul_soil)
B(6,2,7,minecraft:soul_soil)
B(6,3,7,minecraft:netherrack)
B(6,0,8,minecraft:soul_soil)
B(6,1,8,minecraft:soul_soil)
B(6,2,8,minecraft:soul_soil)
B(6,3,8,minecraft:netherrack)
B(7,0,-7,minecraft:netherrack)
B(7,1,-7,minecraft:soul_soil)
B(7,2,-7,minecraft:soul_soil)
B(7,3,-7,minecraft:soul_soil)
B(7,4,-7,minecraft:netherrack)
B(7,0,-6,minecraft:netherrack)
B(7,1,-6,minecraft:netherrack)
B(7,2,-6,minecraft:soul_soil)
B(7,3,-6,minecraft:soul_soil)
B(7,4,-6,minecraft:soul_soil)
B(7,5,-6,minecraft:netherrack)
B(7,0,-5,minecraft:netherrack)
B(7,1,-5,minecraft:netherrack)
B(7,2,-5,minecraft:soul_soil)
B(7,3,-5,minecraft:soul_soil)
B(7,4,-5,minecraft:soul_soil)
B(7,5,-5,minecraft:netherrack)
B(7,0,-4,minecraft:netherrack)
B(7,1,-4,minecraft:soul_soil)
B(7,2,-4,minecraft:soul_soil)
B(7,3,-4,minecraft:soul_soil)
B(7,4,-4,minecraft:netherrack)
B(7,0,-3,minecraft:netherrack)
B(7,1,-3,minecraft:soul_soil)
B(7,2,-3,minecraft:soul_soil)
B(7,3,-3,minecraft:soul_soil)
B(7,4,-3,minecraft:netherrack)
B(7,0,-2,minecraft:netherrack)
B(7,1,-2,minecraft:soul_soil)
B(7,2,-2,minecraft:soul_soil)
B(7,3,-2,minecraft:soul_soil)
B(7,4,-2,minecraft:netherrack)
B(7,0,-1,minecraft:netherrack)
B(7,1,-1,minecraft:soul_soil)
B(7,2,-1,minecraft:soul_soil)
B(7,3,-1,minecraft:soul_soil)
B(7,4,-1,minecraft:netherrack)
B(7,0,0,minecraft:netherrack)
B(7,1,0,minecraft:soul_soil)
B(7,2,0,minecraft:soul_soil)
B(7,3,0,minecraft:soul_soil)
B(7,4,0,minecraft:netherrack)
B(7,0,1,minecraft:netherrack)
B(7,1,1,minecraft:soul_soil)
B(7,2,1,minecraft:soul_soil)
B(7,3,1,minecraft:soul_soil)
B(7,4,1,minecraft:netherrack)
B(7,0,2,minecraft:soul_soil)
B(7,1,2,minecraft:soul_soil)
B(7,2,2,minecraft:soul_soil)
B(7,3,2,minecraft:netherrack)
B(7,0,3,minecraft:soul_soil)
B(7,1,3,minecraft:soul_soil)
B(7,2,3,minecraft:soul_soil)
B(7,3,3,minecraft:netherrack)
B(7,0,4,minecraft:soul_soil)
B(7,1,4,minecraft:soul_soil)
B(7,2,4,minecraft:soul_soil)
B(7,3,4,minecraft:netherrack)
B(7,0,5,minecraft:soul_soil)
B(7,1,5,minecraft:soul_soil)
B(7,2,5,minecraft:soul_soil)
B(7,3,5,minecraft:netherrack)
B(7,0,6,minecraft:soul_soil)
B(7,1,6,minecraft:soul_soil)
B(7,2,6,minecraft:netherrack)
B(7,0,7,minecraft:soul_soil)
B(7,1,7,minecraft:soul_soil)
B(7,2,7,minecraft:netherrack)
B(7,0,8,minecraft:soul_soil)
B(7,1,8,minecraft:soul_soil)
B(7,2,8,minecraft:netherrack)

#######################################################################
# +-----------------------------------------------------------------+ #
# |                             Branches                            | #
# +-----------------------------------------------------------------+ #
#######################################################################

Branch(16,0,0,true,NetherrackWall2_C4_R2,NORTH,100.0,0)

#######################################################################
# +-----------------------------------------------------------------+ #
# |                             Entities                            | #
# +-----------------------------------------------------------------+ #
#######################################################################

