
#######################################################################
# +-----------------------------------------------------------------+ #
# |                            BO4 object                           | #
# +-----------------------------------------------------------------+ #
#######################################################################

Author: Unknown

Description: No description given

SettingsMode: WriteWithoutComments


#######################################################################
# +-----------------------------------------------------------------+ #
# |                          Main settings                          | #
# +-----------------------------------------------------------------+ #
#######################################################################

FixedRotation: 

Frequency: 0

SpawnHeight: highestBlock

UseCenterForHighestBlock: true

##############################
# Height Limits for the BO4. #
##############################

MinHeight: 0

MaxHeight: 255

InheritBO3: 

InheritBO3Rotation: NORTH

OverrideChildSettings: true

OverrideParentHeight: false

CanOverride: false

BranchFrequency: 0

BranchFrequencyGroup: 

MustBeBelowOther: false

MustBeInside: 

CannotBeInside: 

ReplacesBO3: 

MustBeInsideWorldBorders: false

CanSpawnOnWater: true

SpawnOnWaterOnly: false

SpawnUnderWater: false

SpawnAtWaterLevel: false

HeightOffset: 0

RemoveAir: true

ReplaceAbove: 

ReplaceBelow: 

ReplaceWithBiomeBlocks: true

ReplaceWithSurfaceBlock: GRASS

ReplaceWithGroundBlock: DIRT

ReplaceWithStoneBlock: STONE

SmoothRadius: 0

SmoothHeightOffset: 0

SmoothStartTop: false

SmoothStartWood: false

SmoothingSurfaceBlock: 

SmoothingGroundBlock: 

BO3Group: 

IsSpawnPoint: false

DoReplaceBlocks: true


#######################################################################
# +-----------------------------------------------------------------+ #
# |                              Blocks                             | #
# +-----------------------------------------------------------------+ #
#######################################################################

B(-8,53,-7,minecraft:basalt)
B(-8,54,-7,minecraft:basalt)
B(-8,55,-7,minecraft:basalt)
B(-8,56,-7,minecraft:basalt)
B(-8,57,-7,minecraft:basalt)
B(-8,58,-7,minecraft:basalt)
B(-8,59,-7,minecraft:basalt)
B(-8,60,-7,minecraft:basalt)
B(-8,61,-7,minecraft:basalt)
B(-8,62,-7,minecraft:basalt)
B(-8,63,-7,minecraft:basalt)
B(-8,64,-7,minecraft:basalt)
B(-8,65,-7,minecraft:basalt)
B(-8,66,-7,minecraft:basalt)
B(-8,54,-6,minecraft:basalt)
B(-8,55,-6,minecraft:basalt)
B(-8,56,-6,minecraft:basalt)
B(-8,57,-6,minecraft:basalt)
B(-8,58,-6,minecraft:basalt)
B(-8,59,-6,minecraft:basalt)
B(-8,60,-6,minecraft:basalt)
B(-8,61,-6,minecraft:basalt)
B(-8,62,-6,minecraft:basalt)
B(-8,63,-6,minecraft:basalt)
B(-8,64,-6,minecraft:basalt)
B(-8,65,-6,minecraft:basalt)
B(-8,66,-6,minecraft:basalt)
B(-8,54,-5,minecraft:basalt)
B(-8,55,-5,minecraft:basalt)
B(-8,56,-5,minecraft:basalt)
B(-8,57,-5,minecraft:basalt)
B(-8,58,-5,minecraft:basalt)
B(-8,59,-5,minecraft:basalt)
B(-8,60,-5,minecraft:basalt)
B(-8,61,-5,minecraft:basalt)
B(-8,62,-5,minecraft:basalt)
B(-8,63,-5,minecraft:basalt)
B(-8,64,-5,minecraft:basalt)
B(-8,65,-5,minecraft:basalt)
B(-8,66,-5,minecraft:basalt)
B(-8,54,-4,minecraft:basalt)
B(-8,55,-4,minecraft:basalt)
B(-8,56,-4,minecraft:basalt)
B(-8,57,-4,minecraft:basalt)
B(-8,58,-4,minecraft:basalt)
B(-8,59,-4,minecraft:basalt)
B(-8,60,-4,minecraft:basalt)
B(-8,61,-4,minecraft:basalt)
B(-8,62,-4,minecraft:basalt)
B(-8,63,-4,minecraft:basalt)
B(-8,64,-4,minecraft:basalt)
B(-8,65,-4,minecraft:basalt)
B(-8,66,-4,minecraft:basalt)
B(-8,54,-3,minecraft:basalt)
B(-8,55,-3,minecraft:basalt)
B(-8,56,-3,minecraft:basalt)
B(-8,57,-3,minecraft:basalt)
B(-8,58,-3,minecraft:basalt)
B(-8,59,-3,minecraft:basalt)
B(-8,60,-3,minecraft:basalt)
B(-8,61,-3,minecraft:basalt)
B(-8,62,-3,minecraft:basalt)
B(-8,63,-3,minecraft:basalt)
B(-8,64,-3,minecraft:basalt)
B(-8,65,-3,minecraft:basalt)
B(-8,66,-3,minecraft:basalt)
B(-8,54,-2,minecraft:basalt)
B(-8,55,-2,minecraft:basalt)
B(-8,56,-2,minecraft:basalt)
B(-8,57,-2,minecraft:basalt)
B(-8,58,-2,minecraft:basalt)
B(-8,59,-2,minecraft:basalt)
B(-8,60,-2,minecraft:basalt)
B(-8,61,-2,minecraft:basalt)
B(-8,62,-2,minecraft:basalt)
B(-8,63,-2,minecraft:basalt)
B(-8,64,-2,minecraft:basalt)
B(-8,65,-2,minecraft:basalt)
B(-8,66,-2,minecraft:basalt)
B(-8,55,-1,minecraft:basalt)
B(-8,56,-1,minecraft:basalt)
B(-8,57,-1,minecraft:basalt)
B(-8,58,-1,minecraft:basalt)
B(-8,59,-1,minecraft:basalt)
B(-8,60,-1,minecraft:basalt)
B(-8,61,-1,minecraft:basalt)
B(-8,62,-1,minecraft:basalt)
B(-8,63,-1,minecraft:basalt)
B(-8,64,-1,minecraft:basalt)
B(-8,65,-1,minecraft:basalt)
B(-8,66,-1,minecraft:basalt)
B(-8,55,0,minecraft:basalt)
B(-8,56,0,minecraft:basalt)
B(-8,57,0,minecraft:basalt)
B(-8,58,0,minecraft:basalt)
B(-8,59,0,minecraft:basalt)
B(-8,60,0,minecraft:basalt)
B(-8,61,0,minecraft:basalt)
B(-8,62,0,minecraft:basalt)
B(-8,63,0,minecraft:basalt)
B(-8,64,0,minecraft:basalt)
B(-8,65,0,minecraft:basalt)
B(-8,66,0,minecraft:basalt)
B(-8,56,1,minecraft:basalt)
B(-8,57,1,minecraft:basalt)
B(-8,58,1,minecraft:basalt)
B(-8,59,1,minecraft:basalt)
B(-8,60,1,minecraft:basalt)
B(-8,61,1,minecraft:basalt)
B(-8,62,1,minecraft:basalt)
B(-8,63,1,minecraft:basalt)
B(-8,64,1,minecraft:basalt)
B(-8,65,1,minecraft:basalt)
B(-8,66,1,minecraft:basalt)
B(-8,57,2,minecraft:basalt)
B(-8,58,2,minecraft:basalt)
B(-8,59,2,minecraft:basalt)
B(-8,60,2,minecraft:basalt)
B(-8,61,2,minecraft:basalt)
B(-8,62,2,minecraft:basalt)
B(-8,63,2,minecraft:basalt)
B(-8,64,2,minecraft:basalt)
B(-8,65,2,minecraft:basalt)
B(-8,66,2,minecraft:basalt)
B(-8,58,3,minecraft:basalt)
B(-8,59,3,minecraft:basalt)
B(-8,60,3,minecraft:basalt)
B(-8,61,3,minecraft:basalt)
B(-8,62,3,minecraft:basalt)
B(-8,63,3,minecraft:basalt)
B(-8,64,3,minecraft:basalt)
B(-8,65,3,minecraft:basalt)
B(-8,66,3,minecraft:basalt)
B(-8,59,4,minecraft:basalt)
B(-8,60,4,minecraft:basalt)
B(-8,61,4,minecraft:basalt)
B(-8,62,4,minecraft:basalt)
B(-8,63,4,minecraft:basalt)
B(-8,64,4,minecraft:basalt)
B(-8,65,4,minecraft:basalt)
B(-8,66,4,minecraft:basalt)
B(-8,64,5,minecraft:basalt)
B(-8,65,5,minecraft:basalt)
B(-8,66,5,minecraft:basalt)
B(-8,64,6,minecraft:basalt)
B(-8,65,6,minecraft:basalt)
B(-8,66,6,minecraft:basalt)
B(-8,62,7,minecraft:basalt)
B(-8,63,7,minecraft:basalt)
B(-8,64,7,minecraft:basalt)
B(-8,65,7,minecraft:basalt)
B(-8,66,7,minecraft:basalt)
B(-8,62,8,minecraft:basalt)
B(-8,63,8,minecraft:basalt)
B(-8,64,8,minecraft:basalt)
B(-8,65,8,minecraft:basalt)
B(-8,66,8,minecraft:basalt)
B(-7,53,-7,minecraft:basalt)
B(-7,54,-7,minecraft:basalt)
B(-7,55,-7,minecraft:basalt)
B(-7,56,-7,minecraft:basalt)
B(-7,57,-7,minecraft:basalt)
B(-7,58,-7,minecraft:basalt)
B(-7,59,-7,minecraft:basalt)
B(-7,60,-7,minecraft:basalt)
B(-7,61,-7,minecraft:basalt)
B(-7,62,-7,minecraft:basalt)
B(-7,63,-7,minecraft:basalt)
B(-7,64,-7,minecraft:basalt)
B(-7,65,-7,minecraft:basalt)
B(-7,66,-7,minecraft:basalt)
B(-7,53,-6,minecraft:basalt)
B(-7,54,-6,minecraft:basalt)
B(-7,55,-6,minecraft:basalt)
B(-7,56,-6,minecraft:basalt)
B(-7,57,-6,minecraft:basalt)
B(-7,58,-6,minecraft:basalt)
B(-7,59,-6,minecraft:basalt)
B(-7,60,-6,minecraft:basalt)
B(-7,61,-6,minecraft:basalt)
B(-7,62,-6,minecraft:basalt)
B(-7,63,-6,minecraft:basalt)
B(-7,64,-6,minecraft:basalt)
B(-7,65,-6,minecraft:basalt)
B(-7,66,-6,minecraft:basalt)
B(-7,53,-5,minecraft:basalt)
B(-7,54,-5,minecraft:basalt)
B(-7,55,-5,minecraft:basalt)
B(-7,56,-5,minecraft:basalt)
B(-7,57,-5,minecraft:basalt)
B(-7,58,-5,minecraft:basalt)
B(-7,59,-5,minecraft:basalt)
B(-7,60,-5,minecraft:basalt)
B(-7,61,-5,minecraft:basalt)
B(-7,62,-5,minecraft:basalt)
B(-7,63,-5,minecraft:basalt)
B(-7,64,-5,minecraft:basalt)
B(-7,65,-5,minecraft:basalt)
B(-7,66,-5,minecraft:basalt)
B(-7,54,-4,minecraft:basalt)
B(-7,55,-4,minecraft:basalt)
B(-7,56,-4,minecraft:basalt)
B(-7,57,-4,minecraft:basalt)
B(-7,58,-4,minecraft:basalt)
B(-7,59,-4,minecraft:basalt)
B(-7,60,-4,minecraft:basalt)
B(-7,61,-4,minecraft:basalt)
B(-7,62,-4,minecraft:basalt)
B(-7,63,-4,minecraft:basalt)
B(-7,64,-4,minecraft:basalt)
B(-7,65,-4,minecraft:basalt)
B(-7,66,-4,minecraft:basalt)
B(-7,54,-3,minecraft:basalt)
B(-7,55,-3,minecraft:basalt)
B(-7,56,-3,minecraft:basalt)
B(-7,57,-3,minecraft:basalt)
B(-7,58,-3,minecraft:basalt)
B(-7,59,-3,minecraft:basalt)
B(-7,60,-3,minecraft:basalt)
B(-7,61,-3,minecraft:basalt)
B(-7,62,-3,minecraft:basalt)
B(-7,63,-3,minecraft:basalt)
B(-7,64,-3,minecraft:basalt)
B(-7,65,-3,minecraft:basalt)
B(-7,66,-3,minecraft:basalt)
B(-7,54,-2,minecraft:basalt)
B(-7,55,-2,minecraft:basalt)
B(-7,56,-2,minecraft:basalt)
B(-7,57,-2,minecraft:basalt)
B(-7,58,-2,minecraft:basalt)
B(-7,59,-2,minecraft:basalt)
B(-7,60,-2,minecraft:basalt)
B(-7,61,-2,minecraft:basalt)
B(-7,62,-2,minecraft:basalt)
B(-7,63,-2,minecraft:basalt)
B(-7,64,-2,minecraft:basalt)
B(-7,65,-2,minecraft:basalt)
B(-7,66,-2,minecraft:basalt)
B(-7,54,-1,minecraft:basalt)
B(-7,55,-1,minecraft:basalt)
B(-7,56,-1,minecraft:basalt)
B(-7,57,-1,minecraft:basalt)
B(-7,58,-1,minecraft:basalt)
B(-7,59,-1,minecraft:basalt)
B(-7,60,-1,minecraft:basalt)
B(-7,61,-1,minecraft:basalt)
B(-7,62,-1,minecraft:basalt)
B(-7,63,-1,minecraft:basalt)
B(-7,64,-1,minecraft:basalt)
B(-7,65,-1,minecraft:basalt)
B(-7,66,-1,minecraft:basalt)
B(-7,55,0,minecraft:basalt)
B(-7,56,0,minecraft:basalt)
B(-7,57,0,minecraft:basalt)
B(-7,58,0,minecraft:basalt)
B(-7,59,0,minecraft:basalt)
B(-7,60,0,minecraft:basalt)
B(-7,61,0,minecraft:basalt)
B(-7,62,0,minecraft:basalt)
B(-7,63,0,minecraft:basalt)
B(-7,64,0,minecraft:basalt)
B(-7,65,0,minecraft:basalt)
B(-7,66,0,minecraft:basalt)
B(-7,56,1,minecraft:basalt)
B(-7,57,1,minecraft:basalt)
B(-7,58,1,minecraft:basalt)
B(-7,59,1,minecraft:basalt)
B(-7,60,1,minecraft:basalt)
B(-7,61,1,minecraft:basalt)
B(-7,62,1,minecraft:basalt)
B(-7,63,1,minecraft:basalt)
B(-7,64,1,minecraft:basalt)
B(-7,65,1,minecraft:basalt)
B(-7,66,1,minecraft:basalt)
B(-7,57,2,minecraft:basalt)
B(-7,58,2,minecraft:basalt)
B(-7,59,2,minecraft:basalt)
B(-7,60,2,minecraft:basalt)
B(-7,61,2,minecraft:basalt)
B(-7,62,2,minecraft:basalt)
B(-7,63,2,minecraft:basalt)
B(-7,64,2,minecraft:basalt)
B(-7,65,2,minecraft:basalt)
B(-7,66,2,minecraft:basalt)
B(-7,57,3,minecraft:basalt)
B(-7,58,3,minecraft:basalt)
B(-7,59,3,minecraft:basalt)
B(-7,60,3,minecraft:basalt)
B(-7,61,3,minecraft:basalt)
B(-7,62,3,minecraft:basalt)
B(-7,63,3,minecraft:basalt)
B(-7,64,3,minecraft:basalt)
B(-7,65,3,minecraft:basalt)
B(-7,66,3,minecraft:basalt)
B(-7,59,4,minecraft:basalt)
B(-7,60,4,minecraft:basalt)
B(-7,61,4,minecraft:basalt)
B(-7,62,4,minecraft:basalt)
B(-7,63,4,minecraft:basalt)
B(-7,64,4,minecraft:basalt)
B(-7,65,4,minecraft:basalt)
B(-7,66,4,minecraft:basalt)
B(-7,65,5,minecraft:basalt)
B(-7,66,5,minecraft:basalt)
B(-7,64,6,minecraft:basalt)
B(-7,65,6,minecraft:basalt)
B(-7,66,6,minecraft:basalt)
B(-7,61,7,minecraft:basalt)
B(-7,62,7,minecraft:basalt)
B(-7,63,7,minecraft:basalt)
B(-7,64,7,minecraft:basalt)
B(-7,65,7,minecraft:basalt)
B(-7,66,7,minecraft:basalt)
B(-7,62,8,minecraft:basalt)
B(-7,63,8,minecraft:basalt)
B(-7,64,8,minecraft:basalt)
B(-7,65,8,minecraft:basalt)
B(-7,66,8,minecraft:basalt)
B(-6,52,-7,minecraft:basalt)
B(-6,53,-7,minecraft:basalt)
B(-6,54,-7,minecraft:basalt)
B(-6,55,-7,minecraft:basalt)
B(-6,56,-7,minecraft:basalt)
B(-6,57,-7,minecraft:basalt)
B(-6,58,-7,minecraft:basalt)
B(-6,59,-7,minecraft:basalt)
B(-6,60,-7,minecraft:basalt)
B(-6,61,-7,minecraft:basalt)
B(-6,62,-7,minecraft:basalt)
B(-6,63,-7,minecraft:basalt)
B(-6,64,-7,minecraft:basalt)
B(-6,65,-7,minecraft:basalt)
B(-6,66,-7,minecraft:basalt)
B(-6,52,-6,minecraft:basalt)
B(-6,53,-6,minecraft:basalt)
B(-6,54,-6,minecraft:basalt)
B(-6,55,-6,minecraft:basalt)
B(-6,56,-6,minecraft:basalt)
B(-6,57,-6,minecraft:basalt)
B(-6,58,-6,minecraft:basalt)
B(-6,59,-6,minecraft:basalt)
B(-6,60,-6,minecraft:basalt)
B(-6,61,-6,minecraft:basalt)
B(-6,62,-6,minecraft:basalt)
B(-6,63,-6,minecraft:basalt)
B(-6,64,-6,minecraft:basalt)
B(-6,65,-6,minecraft:basalt)
B(-6,66,-6,minecraft:basalt)
B(-6,53,-5,minecraft:basalt)
B(-6,54,-5,minecraft:basalt)
B(-6,55,-5,minecraft:basalt)
B(-6,56,-5,minecraft:basalt)
B(-6,57,-5,minecraft:basalt)
B(-6,58,-5,minecraft:basalt)
B(-6,59,-5,minecraft:basalt)
B(-6,60,-5,minecraft:basalt)
B(-6,61,-5,minecraft:basalt)
B(-6,62,-5,minecraft:basalt)
B(-6,63,-5,minecraft:basalt)
B(-6,64,-5,minecraft:basalt)
B(-6,65,-5,minecraft:basalt)
B(-6,66,-5,minecraft:basalt)
B(-6,53,-4,minecraft:basalt)
B(-6,54,-4,minecraft:basalt)
B(-6,55,-4,minecraft:basalt)
B(-6,56,-4,minecraft:basalt)
B(-6,57,-4,minecraft:basalt)
B(-6,58,-4,minecraft:basalt)
B(-6,59,-4,minecraft:basalt)
B(-6,60,-4,minecraft:basalt)
B(-6,61,-4,minecraft:basalt)
B(-6,62,-4,minecraft:basalt)
B(-6,63,-4,minecraft:basalt)
B(-6,64,-4,minecraft:basalt)
B(-6,65,-4,minecraft:basalt)
B(-6,66,-4,minecraft:basalt)
B(-6,54,-3,minecraft:basalt)
B(-6,55,-3,minecraft:basalt)
B(-6,56,-3,minecraft:basalt)
B(-6,57,-3,minecraft:basalt)
B(-6,58,-3,minecraft:basalt)
B(-6,59,-3,minecraft:basalt)
B(-6,60,-3,minecraft:basalt)
B(-6,61,-3,minecraft:basalt)
B(-6,62,-3,minecraft:basalt)
B(-6,63,-3,minecraft:basalt)
B(-6,64,-3,minecraft:basalt)
B(-6,65,-3,minecraft:basalt)
B(-6,66,-3,minecraft:basalt)
B(-6,54,-2,minecraft:basalt)
B(-6,55,-2,minecraft:basalt)
B(-6,56,-2,minecraft:basalt)
B(-6,57,-2,minecraft:basalt)
B(-6,58,-2,minecraft:basalt)
B(-6,59,-2,minecraft:basalt)
B(-6,60,-2,minecraft:basalt)
B(-6,61,-2,minecraft:basalt)
B(-6,62,-2,minecraft:basalt)
B(-6,63,-2,minecraft:basalt)
B(-6,64,-2,minecraft:basalt)
B(-6,65,-2,minecraft:basalt)
B(-6,66,-2,minecraft:basalt)
B(-6,54,-1,minecraft:basalt)
B(-6,55,-1,minecraft:basalt)
B(-6,56,-1,minecraft:basalt)
B(-6,57,-1,minecraft:basalt)
B(-6,58,-1,minecraft:basalt)
B(-6,59,-1,minecraft:basalt)
B(-6,60,-1,minecraft:basalt)
B(-6,61,-1,minecraft:basalt)
B(-6,62,-1,minecraft:basalt)
B(-6,63,-1,minecraft:basalt)
B(-6,64,-1,minecraft:basalt)
B(-6,65,-1,minecraft:basalt)
B(-6,66,-1,minecraft:basalt)
B(-6,54,0,minecraft:basalt)
B(-6,55,0,minecraft:basalt)
B(-6,56,0,minecraft:basalt)
B(-6,57,0,minecraft:basalt)
B(-6,58,0,minecraft:basalt)
B(-6,59,0,minecraft:basalt)
B(-6,60,0,minecraft:basalt)
B(-6,61,0,minecraft:basalt)
B(-6,62,0,minecraft:basalt)
B(-6,63,0,minecraft:basalt)
B(-6,64,0,minecraft:basalt)
B(-6,65,0,minecraft:basalt)
B(-6,66,0,minecraft:basalt)
B(-6,56,1,minecraft:basalt)
B(-6,57,1,minecraft:basalt)
B(-6,58,1,minecraft:basalt)
B(-6,59,1,minecraft:basalt)
B(-6,60,1,minecraft:basalt)
B(-6,61,1,minecraft:basalt)
B(-6,62,1,minecraft:basalt)
B(-6,63,1,minecraft:basalt)
B(-6,64,1,minecraft:basalt)
B(-6,65,1,minecraft:basalt)
B(-6,66,1,minecraft:basalt)
B(-6,56,2,minecraft:basalt)
B(-6,57,2,minecraft:basalt)
B(-6,58,2,minecraft:basalt)
B(-6,59,2,minecraft:basalt)
B(-6,60,2,minecraft:basalt)
B(-6,61,2,minecraft:basalt)
B(-6,62,2,minecraft:basalt)
B(-6,63,2,minecraft:basalt)
B(-6,64,2,minecraft:basalt)
B(-6,65,2,minecraft:basalt)
B(-6,66,2,minecraft:basalt)
B(-6,57,3,minecraft:basalt)
B(-6,58,3,minecraft:basalt)
B(-6,59,3,minecraft:basalt)
B(-6,60,3,minecraft:basalt)
B(-6,61,3,minecraft:basalt)
B(-6,62,3,minecraft:basalt)
B(-6,63,3,minecraft:basalt)
B(-6,64,3,minecraft:basalt)
B(-6,65,3,minecraft:basalt)
B(-6,66,3,minecraft:basalt)
B(-6,58,4,minecraft:basalt)
B(-6,59,4,minecraft:basalt)
B(-6,60,4,minecraft:basalt)
B(-6,61,4,minecraft:basalt)
B(-6,62,4,minecraft:basalt)
B(-6,63,4,minecraft:basalt)
B(-6,64,4,minecraft:basalt)
B(-6,65,4,minecraft:basalt)
B(-6,66,4,minecraft:basalt)
B(-6,59,5,minecraft:basalt)
B(-6,60,5,minecraft:basalt)
B(-6,61,5,minecraft:basalt)
B(-6,62,5,minecraft:basalt)
B(-6,63,5,minecraft:basalt)
B(-6,64,5,minecraft:basalt)
B(-6,65,5,minecraft:basalt)
B(-6,66,5,minecraft:basalt)
B(-6,60,6,minecraft:basalt)
B(-6,61,6,minecraft:basalt)
B(-6,62,6,minecraft:basalt)
B(-6,63,6,minecraft:basalt)
B(-6,64,6,minecraft:basalt)
B(-6,65,6,minecraft:basalt)
B(-6,66,6,minecraft:basalt)
B(-6,60,7,minecraft:basalt)
B(-6,61,7,minecraft:basalt)
B(-6,62,7,minecraft:basalt)
B(-6,63,7,minecraft:basalt)
B(-6,64,7,minecraft:basalt)
B(-6,65,7,minecraft:basalt)
B(-6,66,7,minecraft:basalt)
B(-6,61,8,minecraft:basalt)
B(-6,62,8,minecraft:basalt)
B(-6,63,8,minecraft:basalt)
B(-6,64,8,minecraft:basalt)
B(-6,65,8,minecraft:basalt)
B(-6,66,8,minecraft:basalt)
B(-5,52,-7,minecraft:basalt)
B(-5,53,-7,minecraft:basalt)
B(-5,54,-7,minecraft:basalt)
B(-5,55,-7,minecraft:basalt)
B(-5,56,-7,minecraft:basalt)
B(-5,57,-7,minecraft:basalt)
B(-5,58,-7,minecraft:basalt)
B(-5,59,-7,minecraft:basalt)
B(-5,60,-7,minecraft:basalt)
B(-5,61,-7,minecraft:basalt)
B(-5,62,-7,minecraft:basalt)
B(-5,63,-7,minecraft:basalt)
B(-5,64,-7,minecraft:basalt)
B(-5,65,-7,minecraft:basalt)
B(-5,66,-7,minecraft:basalt)
B(-5,52,-6,minecraft:basalt)
B(-5,53,-6,minecraft:basalt)
B(-5,54,-6,minecraft:basalt)
B(-5,55,-6,minecraft:basalt)
B(-5,56,-6,minecraft:basalt)
B(-5,57,-6,minecraft:basalt)
B(-5,58,-6,minecraft:basalt)
B(-5,59,-6,minecraft:basalt)
B(-5,60,-6,minecraft:basalt)
B(-5,61,-6,minecraft:basalt)
B(-5,62,-6,minecraft:basalt)
B(-5,63,-6,minecraft:basalt)
B(-5,64,-6,minecraft:basalt)
B(-5,65,-6,minecraft:basalt)
B(-5,66,-6,minecraft:basalt)
B(-5,52,-5,minecraft:basalt)
B(-5,53,-5,minecraft:basalt)
B(-5,54,-5,minecraft:basalt)
B(-5,55,-5,minecraft:basalt)
B(-5,56,-5,minecraft:basalt)
B(-5,57,-5,minecraft:basalt)
B(-5,58,-5,minecraft:basalt)
B(-5,59,-5,minecraft:basalt)
B(-5,60,-5,minecraft:basalt)
B(-5,61,-5,minecraft:basalt)
B(-5,62,-5,minecraft:basalt)
B(-5,63,-5,minecraft:basalt)
B(-5,64,-5,minecraft:basalt)
B(-5,65,-5,minecraft:basalt)
B(-5,66,-5,minecraft:basalt)
B(-5,53,-4,minecraft:basalt)
B(-5,54,-4,minecraft:basalt)
B(-5,55,-4,minecraft:basalt)
B(-5,56,-4,minecraft:basalt)
B(-5,57,-4,minecraft:basalt)
B(-5,58,-4,minecraft:basalt)
B(-5,59,-4,minecraft:basalt)
B(-5,60,-4,minecraft:basalt)
B(-5,61,-4,minecraft:basalt)
B(-5,62,-4,minecraft:basalt)
B(-5,63,-4,minecraft:basalt)
B(-5,64,-4,minecraft:basalt)
B(-5,65,-4,minecraft:basalt)
B(-5,66,-4,minecraft:basalt)
B(-5,54,-3,minecraft:basalt)
B(-5,55,-3,minecraft:basalt)
B(-5,56,-3,minecraft:basalt)
B(-5,57,-3,minecraft:basalt)
B(-5,58,-3,minecraft:basalt)
B(-5,59,-3,minecraft:basalt)
B(-5,60,-3,minecraft:basalt)
B(-5,61,-3,minecraft:basalt)
B(-5,62,-3,minecraft:basalt)
B(-5,63,-3,minecraft:basalt)
B(-5,64,-3,minecraft:basalt)
B(-5,65,-3,minecraft:basalt)
B(-5,66,-3,minecraft:basalt)
B(-5,54,-2,minecraft:basalt)
B(-5,55,-2,minecraft:basalt)
B(-5,56,-2,minecraft:basalt)
B(-5,57,-2,minecraft:basalt)
B(-5,58,-2,minecraft:basalt)
B(-5,59,-2,minecraft:basalt)
B(-5,60,-2,minecraft:basalt)
B(-5,61,-2,minecraft:basalt)
B(-5,62,-2,minecraft:basalt)
B(-5,63,-2,minecraft:basalt)
B(-5,64,-2,minecraft:basalt)
B(-5,65,-2,minecraft:basalt)
B(-5,66,-2,minecraft:basalt)
B(-5,54,-1,minecraft:basalt)
B(-5,55,-1,minecraft:basalt)
B(-5,56,-1,minecraft:basalt)
B(-5,57,-1,minecraft:basalt)
B(-5,58,-1,minecraft:basalt)
B(-5,59,-1,minecraft:basalt)
B(-5,60,-1,minecraft:basalt)
B(-5,61,-1,minecraft:basalt)
B(-5,62,-1,minecraft:basalt)
B(-5,63,-1,minecraft:basalt)
B(-5,64,-1,minecraft:basalt)
B(-5,65,-1,minecraft:basalt)
B(-5,66,-1,minecraft:basalt)
B(-5,54,0,minecraft:basalt)
B(-5,55,0,minecraft:basalt)
B(-5,56,0,minecraft:basalt)
B(-5,57,0,minecraft:basalt)
B(-5,58,0,minecraft:basalt)
B(-5,59,0,minecraft:basalt)
B(-5,60,0,minecraft:basalt)
B(-5,61,0,minecraft:basalt)
B(-5,62,0,minecraft:basalt)
B(-5,63,0,minecraft:basalt)
B(-5,64,0,minecraft:basalt)
B(-5,65,0,minecraft:basalt)
B(-5,66,0,minecraft:basalt)
B(-5,55,1,minecraft:basalt)
B(-5,56,1,minecraft:basalt)
B(-5,57,1,minecraft:basalt)
B(-5,58,1,minecraft:basalt)
B(-5,59,1,minecraft:basalt)
B(-5,60,1,minecraft:basalt)
B(-5,61,1,minecraft:basalt)
B(-5,62,1,minecraft:basalt)
B(-5,63,1,minecraft:basalt)
B(-5,64,1,minecraft:basalt)
B(-5,65,1,minecraft:basalt)
B(-5,66,1,minecraft:basalt)
B(-5,56,2,minecraft:basalt)
B(-5,57,2,minecraft:basalt)
B(-5,58,2,minecraft:basalt)
B(-5,59,2,minecraft:basalt)
B(-5,60,2,minecraft:basalt)
B(-5,61,2,minecraft:basalt)
B(-5,62,2,minecraft:basalt)
B(-5,63,2,minecraft:basalt)
B(-5,64,2,minecraft:basalt)
B(-5,65,2,minecraft:basalt)
B(-5,66,2,minecraft:basalt)
B(-5,56,3,minecraft:basalt)
B(-5,57,3,minecraft:basalt)
B(-5,58,3,minecraft:basalt)
B(-5,59,3,minecraft:basalt)
B(-5,60,3,minecraft:basalt)
B(-5,61,3,minecraft:basalt)
B(-5,62,3,minecraft:basalt)
B(-5,63,3,minecraft:basalt)
B(-5,64,3,minecraft:basalt)
B(-5,65,3,minecraft:basalt)
B(-5,66,3,minecraft:basalt)
B(-5,57,4,minecraft:basalt)
B(-5,58,4,minecraft:basalt)
B(-5,59,4,minecraft:basalt)
B(-5,60,4,minecraft:basalt)
B(-5,61,4,minecraft:basalt)
B(-5,62,4,minecraft:basalt)
B(-5,63,4,minecraft:basalt)
B(-5,64,4,minecraft:basalt)
B(-5,65,4,minecraft:basalt)
B(-5,66,4,minecraft:basalt)
B(-5,57,5,minecraft:basalt)
B(-5,58,5,minecraft:basalt)
B(-5,59,5,minecraft:basalt)
B(-5,60,5,minecraft:basalt)
B(-5,61,5,minecraft:basalt)
B(-5,62,5,minecraft:basalt)
B(-5,63,5,minecraft:basalt)
B(-5,64,5,minecraft:basalt)
B(-5,65,5,minecraft:basalt)
B(-5,66,5,minecraft:basalt)
B(-5,58,6,minecraft:basalt)
B(-5,59,6,minecraft:basalt)
B(-5,60,6,minecraft:basalt)
B(-5,61,6,minecraft:basalt)
B(-5,62,6,minecraft:basalt)
B(-5,63,6,minecraft:basalt)
B(-5,64,6,minecraft:basalt)
B(-5,65,6,minecraft:basalt)
B(-5,66,6,minecraft:basalt)
B(-5,59,7,minecraft:basalt)
B(-5,60,7,minecraft:basalt)
B(-5,61,7,minecraft:basalt)
B(-5,62,7,minecraft:basalt)
B(-5,63,7,minecraft:basalt)
B(-5,64,7,minecraft:basalt)
B(-5,65,7,minecraft:basalt)
B(-5,66,7,minecraft:basalt)
B(-5,60,8,minecraft:basalt)
B(-5,61,8,minecraft:basalt)
B(-5,62,8,minecraft:basalt)
B(-5,63,8,minecraft:basalt)
B(-5,64,8,minecraft:basalt)
B(-5,65,8,minecraft:basalt)
B(-5,66,8,minecraft:basalt)
B(-4,52,-7,minecraft:basalt)
B(-4,53,-7,minecraft:basalt)
B(-4,54,-7,minecraft:basalt)
B(-4,55,-7,minecraft:basalt)
B(-4,56,-7,minecraft:basalt)
B(-4,57,-7,minecraft:basalt)
B(-4,58,-7,minecraft:basalt)
B(-4,59,-7,minecraft:basalt)
B(-4,60,-7,minecraft:basalt)
B(-4,61,-7,minecraft:basalt)
B(-4,62,-7,minecraft:basalt)
B(-4,63,-7,minecraft:basalt)
B(-4,64,-7,minecraft:basalt)
B(-4,65,-7,minecraft:basalt)
B(-4,66,-7,minecraft:basalt)
B(-4,52,-6,minecraft:basalt)
B(-4,53,-6,minecraft:basalt)
B(-4,54,-6,minecraft:basalt)
B(-4,55,-6,minecraft:basalt)
B(-4,56,-6,minecraft:basalt)
B(-4,57,-6,minecraft:basalt)
B(-4,58,-6,minecraft:basalt)
B(-4,59,-6,minecraft:basalt)
B(-4,60,-6,minecraft:basalt)
B(-4,61,-6,minecraft:basalt)
B(-4,62,-6,minecraft:basalt)
B(-4,63,-6,minecraft:basalt)
B(-4,64,-6,minecraft:basalt)
B(-4,65,-6,minecraft:basalt)
B(-4,66,-6,minecraft:basalt)
B(-4,52,-5,minecraft:basalt)
B(-4,53,-5,minecraft:basalt)
B(-4,54,-5,minecraft:basalt)
B(-4,55,-5,minecraft:basalt)
B(-4,56,-5,minecraft:basalt)
B(-4,57,-5,minecraft:basalt)
B(-4,58,-5,minecraft:basalt)
B(-4,59,-5,minecraft:basalt)
B(-4,60,-5,minecraft:basalt)
B(-4,61,-5,minecraft:basalt)
B(-4,62,-5,minecraft:basalt)
B(-4,63,-5,minecraft:basalt)
B(-4,64,-5,minecraft:basalt)
B(-4,65,-5,minecraft:basalt)
B(-4,66,-5,minecraft:basalt)
B(-4,53,-4,minecraft:basalt)
B(-4,54,-4,minecraft:basalt)
B(-4,55,-4,minecraft:basalt)
B(-4,56,-4,minecraft:basalt)
B(-4,57,-4,minecraft:basalt)
B(-4,58,-4,minecraft:basalt)
B(-4,59,-4,minecraft:basalt)
B(-4,60,-4,minecraft:basalt)
B(-4,61,-4,minecraft:basalt)
B(-4,62,-4,minecraft:basalt)
B(-4,63,-4,minecraft:basalt)
B(-4,64,-4,minecraft:basalt)
B(-4,65,-4,minecraft:basalt)
B(-4,66,-4,minecraft:basalt)
B(-4,54,-3,minecraft:basalt)
B(-4,55,-3,minecraft:basalt)
B(-4,56,-3,minecraft:basalt)
B(-4,57,-3,minecraft:basalt)
B(-4,58,-3,minecraft:basalt)
B(-4,59,-3,minecraft:basalt)
B(-4,60,-3,minecraft:basalt)
B(-4,61,-3,minecraft:basalt)
B(-4,62,-3,minecraft:basalt)
B(-4,63,-3,minecraft:basalt)
B(-4,64,-3,minecraft:basalt)
B(-4,65,-3,minecraft:basalt)
B(-4,66,-3,minecraft:basalt)
B(-4,55,-2,minecraft:basalt)
B(-4,56,-2,minecraft:basalt)
B(-4,57,-2,minecraft:basalt)
B(-4,58,-2,minecraft:basalt)
B(-4,59,-2,minecraft:basalt)
B(-4,60,-2,minecraft:basalt)
B(-4,61,-2,minecraft:basalt)
B(-4,62,-2,minecraft:basalt)
B(-4,63,-2,minecraft:basalt)
B(-4,64,-2,minecraft:basalt)
B(-4,65,-2,minecraft:basalt)
B(-4,66,-2,minecraft:basalt)
B(-4,55,-1,minecraft:basalt)
B(-4,56,-1,minecraft:basalt)
B(-4,57,-1,minecraft:basalt)
B(-4,58,-1,minecraft:basalt)
B(-4,59,-1,minecraft:basalt)
B(-4,60,-1,minecraft:basalt)
B(-4,61,-1,minecraft:basalt)
B(-4,62,-1,minecraft:basalt)
B(-4,63,-1,minecraft:basalt)
B(-4,64,-1,minecraft:basalt)
B(-4,65,-1,minecraft:basalt)
B(-4,66,-1,minecraft:basalt)
B(-4,55,0,minecraft:basalt)
B(-4,56,0,minecraft:basalt)
B(-4,57,0,minecraft:basalt)
B(-4,58,0,minecraft:basalt)
B(-4,59,0,minecraft:basalt)
B(-4,60,0,minecraft:basalt)
B(-4,61,0,minecraft:basalt)
B(-4,62,0,minecraft:basalt)
B(-4,63,0,minecraft:basalt)
B(-4,64,0,minecraft:basalt)
B(-4,65,0,minecraft:basalt)
B(-4,66,0,minecraft:basalt)
B(-4,55,1,minecraft:basalt)
B(-4,56,1,minecraft:basalt)
B(-4,57,1,minecraft:basalt)
B(-4,58,1,minecraft:basalt)
B(-4,59,1,minecraft:basalt)
B(-4,60,1,minecraft:basalt)
B(-4,61,1,minecraft:basalt)
B(-4,62,1,minecraft:basalt)
B(-4,63,1,minecraft:basalt)
B(-4,64,1,minecraft:basalt)
B(-4,65,1,minecraft:basalt)
B(-4,66,1,minecraft:basalt)
B(-4,55,2,minecraft:basalt)
B(-4,56,2,minecraft:basalt)
B(-4,57,2,minecraft:basalt)
B(-4,58,2,minecraft:basalt)
B(-4,59,2,minecraft:basalt)
B(-4,60,2,minecraft:basalt)
B(-4,61,2,minecraft:basalt)
B(-4,62,2,minecraft:basalt)
B(-4,63,2,minecraft:basalt)
B(-4,64,2,minecraft:basalt)
B(-4,65,2,minecraft:basalt)
B(-4,66,2,minecraft:basalt)
B(-4,55,3,minecraft:basalt)
B(-4,56,3,minecraft:basalt)
B(-4,57,3,minecraft:basalt)
B(-4,58,3,minecraft:basalt)
B(-4,59,3,minecraft:basalt)
B(-4,60,3,minecraft:basalt)
B(-4,61,3,minecraft:basalt)
B(-4,62,3,minecraft:basalt)
B(-4,63,3,minecraft:basalt)
B(-4,64,3,minecraft:basalt)
B(-4,65,3,minecraft:basalt)
B(-4,66,3,minecraft:basalt)
B(-4,56,4,minecraft:basalt)
B(-4,57,4,minecraft:basalt)
B(-4,58,4,minecraft:basalt)
B(-4,59,4,minecraft:basalt)
B(-4,60,4,minecraft:basalt)
B(-4,61,4,minecraft:basalt)
B(-4,62,4,minecraft:basalt)
B(-4,63,4,minecraft:basalt)
B(-4,64,4,minecraft:basalt)
B(-4,65,4,minecraft:basalt)
B(-4,66,4,minecraft:basalt)
B(-4,56,5,minecraft:basalt)
B(-4,57,5,minecraft:basalt)
B(-4,58,5,minecraft:basalt)
B(-4,59,5,minecraft:basalt)
B(-4,60,5,minecraft:basalt)
B(-4,61,5,minecraft:basalt)
B(-4,62,5,minecraft:basalt)
B(-4,63,5,minecraft:basalt)
B(-4,64,5,minecraft:basalt)
B(-4,65,5,minecraft:basalt)
B(-4,66,5,minecraft:basalt)
B(-4,57,6,minecraft:basalt)
B(-4,58,6,minecraft:basalt)
B(-4,59,6,minecraft:basalt)
B(-4,60,6,minecraft:basalt)
B(-4,61,6,minecraft:basalt)
B(-4,62,6,minecraft:basalt)
B(-4,63,6,minecraft:basalt)
B(-4,64,6,minecraft:basalt)
B(-4,65,6,minecraft:basalt)
B(-4,66,6,minecraft:basalt)
B(-4,58,7,minecraft:basalt)
B(-4,59,7,minecraft:basalt)
B(-4,60,7,minecraft:basalt)
B(-4,61,7,minecraft:basalt)
B(-4,62,7,minecraft:basalt)
B(-4,63,7,minecraft:basalt)
B(-4,64,7,minecraft:basalt)
B(-4,65,7,minecraft:basalt)
B(-4,66,7,minecraft:basalt)
B(-4,58,8,minecraft:basalt)
B(-4,59,8,minecraft:basalt)
B(-4,60,8,minecraft:basalt)
B(-4,61,8,minecraft:basalt)
B(-4,62,8,minecraft:basalt)
B(-4,63,8,minecraft:basalt)
B(-4,64,8,minecraft:basalt)
B(-4,65,8,minecraft:basalt)
B(-4,66,8,minecraft:basalt)
B(-3,51,-7,minecraft:basalt)
B(-3,52,-7,minecraft:basalt)
B(-3,53,-7,minecraft:basalt)
B(-3,54,-7,minecraft:basalt)
B(-3,55,-7,minecraft:basalt)
B(-3,56,-7,minecraft:basalt)
B(-3,57,-7,minecraft:basalt)
B(-3,58,-7,minecraft:basalt)
B(-3,59,-7,minecraft:basalt)
B(-3,60,-7,minecraft:basalt)
B(-3,61,-7,minecraft:basalt)
B(-3,62,-7,minecraft:basalt)
B(-3,63,-7,minecraft:basalt)
B(-3,64,-7,minecraft:basalt)
B(-3,65,-7,minecraft:basalt)
B(-3,66,-7,minecraft:basalt)
B(-3,51,-6,minecraft:basalt)
B(-3,52,-6,minecraft:basalt)
B(-3,53,-6,minecraft:basalt)
B(-3,54,-6,minecraft:basalt)
B(-3,55,-6,minecraft:basalt)
B(-3,56,-6,minecraft:basalt)
B(-3,57,-6,minecraft:basalt)
B(-3,58,-6,minecraft:basalt)
B(-3,59,-6,minecraft:basalt)
B(-3,60,-6,minecraft:basalt)
B(-3,61,-6,minecraft:basalt)
B(-3,62,-6,minecraft:basalt)
B(-3,63,-6,minecraft:basalt)
B(-3,64,-6,minecraft:basalt)
B(-3,65,-6,minecraft:basalt)
B(-3,66,-6,minecraft:basalt)
B(-3,51,-5,minecraft:basalt)
B(-3,52,-5,minecraft:basalt)
B(-3,53,-5,minecraft:basalt)
B(-3,54,-5,minecraft:basalt)
B(-3,55,-5,minecraft:basalt)
B(-3,56,-5,minecraft:basalt)
B(-3,57,-5,minecraft:basalt)
B(-3,58,-5,minecraft:basalt)
B(-3,59,-5,minecraft:basalt)
B(-3,60,-5,minecraft:basalt)
B(-3,61,-5,minecraft:basalt)
B(-3,62,-5,minecraft:basalt)
B(-3,63,-5,minecraft:basalt)
B(-3,64,-5,minecraft:basalt)
B(-3,65,-5,minecraft:basalt)
B(-3,66,-5,minecraft:basalt)
B(-3,51,-4,minecraft:basalt)
B(-3,52,-4,minecraft:basalt)
B(-3,53,-4,minecraft:basalt)
B(-3,54,-4,minecraft:basalt)
B(-3,55,-4,minecraft:basalt)
B(-3,56,-4,minecraft:basalt)
B(-3,57,-4,minecraft:basalt)
B(-3,58,-4,minecraft:basalt)
B(-3,59,-4,minecraft:basalt)
B(-3,60,-4,minecraft:basalt)
B(-3,61,-4,minecraft:basalt)
B(-3,62,-4,minecraft:basalt)
B(-3,63,-4,minecraft:basalt)
B(-3,64,-4,minecraft:basalt)
B(-3,65,-4,minecraft:basalt)
B(-3,66,-4,minecraft:basalt)
B(-3,52,-3,minecraft:basalt)
B(-3,53,-3,minecraft:basalt)
B(-3,54,-3,minecraft:basalt)
B(-3,55,-3,minecraft:basalt)
B(-3,56,-3,minecraft:basalt)
B(-3,57,-3,minecraft:basalt)
B(-3,58,-3,minecraft:basalt)
B(-3,59,-3,minecraft:basalt)
B(-3,60,-3,minecraft:basalt)
B(-3,61,-3,minecraft:basalt)
B(-3,62,-3,minecraft:basalt)
B(-3,63,-3,minecraft:basalt)
B(-3,64,-3,minecraft:basalt)
B(-3,65,-3,minecraft:basalt)
B(-3,66,-3,minecraft:basalt)
B(-3,54,-2,minecraft:basalt)
B(-3,55,-2,minecraft:basalt)
B(-3,56,-2,minecraft:basalt)
B(-3,57,-2,minecraft:basalt)
B(-3,58,-2,minecraft:basalt)
B(-3,59,-2,minecraft:basalt)
B(-3,60,-2,minecraft:basalt)
B(-3,61,-2,minecraft:basalt)
B(-3,62,-2,minecraft:basalt)
B(-3,63,-2,minecraft:basalt)
B(-3,64,-2,minecraft:basalt)
B(-3,65,-2,minecraft:basalt)
B(-3,66,-2,minecraft:basalt)
B(-3,54,-1,minecraft:basalt)
B(-3,55,-1,minecraft:basalt)
B(-3,56,-1,minecraft:basalt)
B(-3,57,-1,minecraft:basalt)
B(-3,58,-1,minecraft:basalt)
B(-3,59,-1,minecraft:basalt)
B(-3,60,-1,minecraft:basalt)
B(-3,61,-1,minecraft:basalt)
B(-3,62,-1,minecraft:basalt)
B(-3,63,-1,minecraft:basalt)
B(-3,64,-1,minecraft:basalt)
B(-3,65,-1,minecraft:basalt)
B(-3,66,-1,minecraft:basalt)
B(-3,55,0,minecraft:basalt)
B(-3,56,0,minecraft:basalt)
B(-3,57,0,minecraft:basalt)
B(-3,58,0,minecraft:basalt)
B(-3,59,0,minecraft:basalt)
B(-3,60,0,minecraft:basalt)
B(-3,61,0,minecraft:basalt)
B(-3,62,0,minecraft:basalt)
B(-3,63,0,minecraft:basalt)
B(-3,64,0,minecraft:basalt)
B(-3,65,0,minecraft:basalt)
B(-3,66,0,minecraft:basalt)
B(-3,55,1,minecraft:basalt)
B(-3,56,1,minecraft:basalt)
B(-3,57,1,minecraft:basalt)
B(-3,58,1,minecraft:basalt)
B(-3,59,1,minecraft:basalt)
B(-3,60,1,minecraft:basalt)
B(-3,61,1,minecraft:basalt)
B(-3,62,1,minecraft:basalt)
B(-3,63,1,minecraft:basalt)
B(-3,64,1,minecraft:basalt)
B(-3,65,1,minecraft:basalt)
B(-3,66,1,minecraft:basalt)
B(-3,55,2,minecraft:basalt)
B(-3,56,2,minecraft:basalt)
B(-3,57,2,minecraft:basalt)
B(-3,58,2,minecraft:basalt)
B(-3,59,2,minecraft:basalt)
B(-3,60,2,minecraft:basalt)
B(-3,61,2,minecraft:basalt)
B(-3,62,2,minecraft:basalt)
B(-3,63,2,minecraft:basalt)
B(-3,64,2,minecraft:basalt)
B(-3,65,2,minecraft:basalt)
B(-3,66,2,minecraft:basalt)
B(-3,55,3,minecraft:basalt)
B(-3,56,3,minecraft:basalt)
B(-3,57,3,minecraft:basalt)
B(-3,58,3,minecraft:basalt)
B(-3,59,3,minecraft:basalt)
B(-3,60,3,minecraft:basalt)
B(-3,61,3,minecraft:basalt)
B(-3,62,3,minecraft:basalt)
B(-3,63,3,minecraft:basalt)
B(-3,64,3,minecraft:basalt)
B(-3,65,3,minecraft:basalt)
B(-3,66,3,minecraft:basalt)
B(-3,55,4,minecraft:basalt)
B(-3,56,4,minecraft:basalt)
B(-3,57,4,minecraft:basalt)
B(-3,58,4,minecraft:basalt)
B(-3,59,4,minecraft:basalt)
B(-3,60,4,minecraft:basalt)
B(-3,61,4,minecraft:basalt)
B(-3,62,4,minecraft:basalt)
B(-3,63,4,minecraft:basalt)
B(-3,64,4,minecraft:basalt)
B(-3,65,4,minecraft:basalt)
B(-3,66,4,minecraft:basalt)
B(-3,55,5,minecraft:basalt)
B(-3,56,5,minecraft:basalt)
B(-3,57,5,minecraft:basalt)
B(-3,58,5,minecraft:basalt)
B(-3,59,5,minecraft:basalt)
B(-3,60,5,minecraft:basalt)
B(-3,61,5,minecraft:basalt)
B(-3,62,5,minecraft:basalt)
B(-3,63,5,minecraft:basalt)
B(-3,64,5,minecraft:basalt)
B(-3,65,5,minecraft:basalt)
B(-3,66,5,minecraft:basalt)
B(-3,56,6,minecraft:basalt)
B(-3,57,6,minecraft:basalt)
B(-3,58,6,minecraft:basalt)
B(-3,59,6,minecraft:basalt)
B(-3,60,6,minecraft:basalt)
B(-3,61,6,minecraft:basalt)
B(-3,62,6,minecraft:basalt)
B(-3,63,6,minecraft:basalt)
B(-3,64,6,minecraft:basalt)
B(-3,65,6,minecraft:basalt)
B(-3,66,6,minecraft:basalt)
B(-3,57,7,minecraft:basalt)
B(-3,58,7,minecraft:basalt)
B(-3,59,7,minecraft:basalt)
B(-3,60,7,minecraft:basalt)
B(-3,61,7,minecraft:basalt)
B(-3,62,7,minecraft:basalt)
B(-3,63,7,minecraft:basalt)
B(-3,64,7,minecraft:basalt)
B(-3,65,7,minecraft:basalt)
B(-3,66,7,minecraft:basalt)
B(-3,57,8,minecraft:basalt)
B(-3,58,8,minecraft:basalt)
B(-3,59,8,minecraft:basalt)
B(-3,60,8,minecraft:basalt)
B(-3,61,8,minecraft:basalt)
B(-3,62,8,minecraft:basalt)
B(-3,63,8,minecraft:basalt)
B(-3,64,8,minecraft:basalt)
B(-3,65,8,minecraft:basalt)
B(-3,66,8,minecraft:basalt)
B(-2,50,-7,minecraft:basalt)
B(-2,51,-7,minecraft:basalt)
B(-2,52,-7,minecraft:basalt)
B(-2,53,-7,minecraft:basalt)
B(-2,54,-7,minecraft:basalt)
B(-2,55,-7,minecraft:basalt)
B(-2,56,-7,minecraft:basalt)
B(-2,57,-7,minecraft:basalt)
B(-2,58,-7,minecraft:basalt)
B(-2,59,-7,minecraft:basalt)
B(-2,60,-7,minecraft:basalt)
B(-2,61,-7,minecraft:basalt)
B(-2,62,-7,minecraft:basalt)
B(-2,63,-7,minecraft:basalt)
B(-2,64,-7,minecraft:basalt)
B(-2,65,-7,minecraft:basalt)
B(-2,66,-7,minecraft:basalt)
B(-2,50,-6,minecraft:basalt)
B(-2,51,-6,minecraft:basalt)
B(-2,52,-6,minecraft:basalt)
B(-2,53,-6,minecraft:basalt)
B(-2,54,-6,minecraft:basalt)
B(-2,55,-6,minecraft:basalt)
B(-2,56,-6,minecraft:basalt)
B(-2,57,-6,minecraft:basalt)
B(-2,58,-6,minecraft:basalt)
B(-2,59,-6,minecraft:basalt)
B(-2,60,-6,minecraft:basalt)
B(-2,61,-6,minecraft:basalt)
B(-2,62,-6,minecraft:basalt)
B(-2,63,-6,minecraft:basalt)
B(-2,64,-6,minecraft:basalt)
B(-2,65,-6,minecraft:basalt)
B(-2,66,-6,minecraft:basalt)
B(-2,50,-5,minecraft:basalt)
B(-2,51,-5,minecraft:basalt)
B(-2,52,-5,minecraft:basalt)
B(-2,53,-5,minecraft:basalt)
B(-2,54,-5,minecraft:basalt)
B(-2,55,-5,minecraft:basalt)
B(-2,56,-5,minecraft:basalt)
B(-2,57,-5,minecraft:basalt)
B(-2,58,-5,minecraft:basalt)
B(-2,59,-5,minecraft:basalt)
B(-2,60,-5,minecraft:basalt)
B(-2,61,-5,minecraft:basalt)
B(-2,62,-5,minecraft:basalt)
B(-2,63,-5,minecraft:basalt)
B(-2,64,-5,minecraft:basalt)
B(-2,65,-5,minecraft:basalt)
B(-2,66,-5,minecraft:basalt)
B(-2,50,-4,minecraft:basalt)
B(-2,51,-4,minecraft:basalt)
B(-2,52,-4,minecraft:basalt)
B(-2,53,-4,minecraft:basalt)
B(-2,54,-4,minecraft:basalt)
B(-2,55,-4,minecraft:basalt)
B(-2,56,-4,minecraft:basalt)
B(-2,57,-4,minecraft:basalt)
B(-2,58,-4,minecraft:basalt)
B(-2,59,-4,minecraft:basalt)
B(-2,60,-4,minecraft:basalt)
B(-2,61,-4,minecraft:basalt)
B(-2,62,-4,minecraft:basalt)
B(-2,63,-4,minecraft:basalt)
B(-2,64,-4,minecraft:basalt)
B(-2,65,-4,minecraft:basalt)
B(-2,66,-4,minecraft:basalt)
B(-2,51,-3,minecraft:basalt)
B(-2,52,-3,minecraft:basalt)
B(-2,53,-3,minecraft:basalt)
B(-2,54,-3,minecraft:basalt)
B(-2,55,-3,minecraft:basalt)
B(-2,56,-3,minecraft:basalt)
B(-2,57,-3,minecraft:basalt)
B(-2,58,-3,minecraft:basalt)
B(-2,59,-3,minecraft:basalt)
B(-2,60,-3,minecraft:basalt)
B(-2,61,-3,minecraft:basalt)
B(-2,62,-3,minecraft:basalt)
B(-2,63,-3,minecraft:basalt)
B(-2,64,-3,minecraft:basalt)
B(-2,65,-3,minecraft:basalt)
B(-2,66,-3,minecraft:basalt)
B(-2,52,-2,minecraft:basalt)
B(-2,53,-2,minecraft:basalt)
B(-2,54,-2,minecraft:basalt)
B(-2,55,-2,minecraft:basalt)
B(-2,56,-2,minecraft:basalt)
B(-2,57,-2,minecraft:basalt)
B(-2,58,-2,minecraft:basalt)
B(-2,59,-2,minecraft:basalt)
B(-2,60,-2,minecraft:basalt)
B(-2,61,-2,minecraft:basalt)
B(-2,62,-2,minecraft:basalt)
B(-2,63,-2,minecraft:basalt)
B(-2,64,-2,minecraft:basalt)
B(-2,65,-2,minecraft:basalt)
B(-2,66,-2,minecraft:basalt)
B(-2,54,-1,minecraft:basalt)
B(-2,55,-1,minecraft:basalt)
B(-2,56,-1,minecraft:basalt)
B(-2,57,-1,minecraft:basalt)
B(-2,58,-1,minecraft:basalt)
B(-2,59,-1,minecraft:basalt)
B(-2,60,-1,minecraft:basalt)
B(-2,61,-1,minecraft:basalt)
B(-2,62,-1,minecraft:basalt)
B(-2,63,-1,minecraft:basalt)
B(-2,64,-1,minecraft:basalt)
B(-2,65,-1,minecraft:basalt)
B(-2,66,-1,minecraft:basalt)
B(-2,54,0,minecraft:basalt)
B(-2,55,0,minecraft:basalt)
B(-2,56,0,minecraft:basalt)
B(-2,57,0,minecraft:basalt)
B(-2,58,0,minecraft:basalt)
B(-2,59,0,minecraft:basalt)
B(-2,60,0,minecraft:basalt)
B(-2,61,0,minecraft:basalt)
B(-2,62,0,minecraft:basalt)
B(-2,63,0,minecraft:basalt)
B(-2,64,0,minecraft:basalt)
B(-2,65,0,minecraft:basalt)
B(-2,66,0,minecraft:basalt)
B(-2,55,1,minecraft:basalt)
B(-2,56,1,minecraft:basalt)
B(-2,57,1,minecraft:basalt)
B(-2,58,1,minecraft:basalt)
B(-2,59,1,minecraft:basalt)
B(-2,60,1,minecraft:basalt)
B(-2,61,1,minecraft:basalt)
B(-2,62,1,minecraft:basalt)
B(-2,63,1,minecraft:basalt)
B(-2,64,1,minecraft:basalt)
B(-2,65,1,minecraft:basalt)
B(-2,66,1,minecraft:basalt)
B(-2,54,2,minecraft:basalt)
B(-2,55,2,minecraft:basalt)
B(-2,56,2,minecraft:basalt)
B(-2,57,2,minecraft:basalt)
B(-2,58,2,minecraft:basalt)
B(-2,59,2,minecraft:basalt)
B(-2,60,2,minecraft:basalt)
B(-2,61,2,minecraft:basalt)
B(-2,62,2,minecraft:basalt)
B(-2,63,2,minecraft:basalt)
B(-2,64,2,minecraft:basalt)
B(-2,65,2,minecraft:basalt)
B(-2,66,2,minecraft:basalt)
B(-2,54,3,minecraft:basalt)
B(-2,55,3,minecraft:basalt)
B(-2,56,3,minecraft:basalt)
B(-2,57,3,minecraft:basalt)
B(-2,58,3,minecraft:basalt)
B(-2,59,3,minecraft:basalt)
B(-2,60,3,minecraft:basalt)
B(-2,61,3,minecraft:basalt)
B(-2,62,3,minecraft:basalt)
B(-2,63,3,minecraft:basalt)
B(-2,64,3,minecraft:basalt)
B(-2,65,3,minecraft:basalt)
B(-2,66,3,minecraft:basalt)
B(-2,55,4,minecraft:basalt)
B(-2,56,4,minecraft:basalt)
B(-2,57,4,minecraft:basalt)
B(-2,58,4,minecraft:basalt)
B(-2,59,4,minecraft:basalt)
B(-2,60,4,minecraft:basalt)
B(-2,61,4,minecraft:basalt)
B(-2,62,4,minecraft:basalt)
B(-2,63,4,minecraft:basalt)
B(-2,64,4,minecraft:basalt)
B(-2,65,4,minecraft:basalt)
B(-2,66,4,minecraft:basalt)
B(-2,55,5,minecraft:basalt)
B(-2,56,5,minecraft:basalt)
B(-2,57,5,minecraft:basalt)
B(-2,58,5,minecraft:basalt)
B(-2,59,5,minecraft:basalt)
B(-2,60,5,minecraft:basalt)
B(-2,61,5,minecraft:basalt)
B(-2,62,5,minecraft:basalt)
B(-2,63,5,minecraft:basalt)
B(-2,64,5,minecraft:basalt)
B(-2,65,5,minecraft:basalt)
B(-2,66,5,minecraft:basalt)
B(-2,55,6,minecraft:basalt)
B(-2,56,6,minecraft:basalt)
B(-2,57,6,minecraft:basalt)
B(-2,58,6,minecraft:basalt)
B(-2,59,6,minecraft:basalt)
B(-2,60,6,minecraft:basalt)
B(-2,61,6,minecraft:basalt)
B(-2,62,6,minecraft:basalt)
B(-2,63,6,minecraft:basalt)
B(-2,64,6,minecraft:basalt)
B(-2,65,6,minecraft:basalt)
B(-2,66,6,minecraft:basalt)
B(-2,56,7,minecraft:basalt)
B(-2,57,7,minecraft:basalt)
B(-2,58,7,minecraft:basalt)
B(-2,59,7,minecraft:basalt)
B(-2,60,7,minecraft:basalt)
B(-2,61,7,minecraft:basalt)
B(-2,62,7,minecraft:basalt)
B(-2,63,7,minecraft:basalt)
B(-2,64,7,minecraft:basalt)
B(-2,65,7,minecraft:basalt)
B(-2,66,7,minecraft:basalt)
B(-2,57,8,minecraft:basalt)
B(-2,58,8,minecraft:basalt)
B(-2,59,8,minecraft:basalt)
B(-2,60,8,minecraft:basalt)
B(-2,61,8,minecraft:basalt)
B(-2,62,8,minecraft:basalt)
B(-2,63,8,minecraft:basalt)
B(-2,64,8,minecraft:basalt)
B(-2,65,8,minecraft:basalt)
B(-2,66,8,minecraft:basalt)
B(-1,49,-7,minecraft:basalt)
B(-1,50,-7,minecraft:basalt)
B(-1,51,-7,minecraft:basalt)
B(-1,52,-7,minecraft:basalt)
B(-1,53,-7,minecraft:basalt)
B(-1,54,-7,minecraft:basalt)
B(-1,55,-7,minecraft:basalt)
B(-1,56,-7,minecraft:basalt)
B(-1,57,-7,minecraft:basalt)
B(-1,58,-7,minecraft:basalt)
B(-1,59,-7,minecraft:basalt)
B(-1,60,-7,minecraft:basalt)
B(-1,61,-7,minecraft:basalt)
B(-1,62,-7,minecraft:basalt)
B(-1,63,-7,minecraft:basalt)
B(-1,64,-7,minecraft:basalt)
B(-1,65,-7,minecraft:basalt)
B(-1,66,-7,minecraft:basalt)
B(-1,46,-6,minecraft:basalt)
B(-1,47,-6,minecraft:basalt)
B(-1,48,-6,minecraft:basalt)
B(-1,49,-6,minecraft:basalt)
B(-1,50,-6,minecraft:basalt)
B(-1,51,-6,minecraft:basalt)
B(-1,52,-6,minecraft:basalt)
B(-1,53,-6,minecraft:basalt)
B(-1,54,-6,minecraft:basalt)
B(-1,55,-6,minecraft:basalt)
B(-1,56,-6,minecraft:basalt)
B(-1,57,-6,minecraft:basalt)
B(-1,58,-6,minecraft:basalt)
B(-1,59,-6,minecraft:basalt)
B(-1,60,-6,minecraft:basalt)
B(-1,61,-6,minecraft:basalt)
B(-1,62,-6,minecraft:basalt)
B(-1,63,-6,minecraft:basalt)
B(-1,64,-6,minecraft:basalt)
B(-1,65,-6,minecraft:basalt)
B(-1,66,-6,minecraft:basalt)
B(-1,44,-5,minecraft:basalt)
B(-1,45,-5,minecraft:basalt)
B(-1,46,-5,minecraft:basalt)
B(-1,47,-5,minecraft:basalt)
B(-1,48,-5,minecraft:basalt)
B(-1,49,-5,minecraft:basalt)
B(-1,50,-5,minecraft:basalt)
B(-1,51,-5,minecraft:basalt)
B(-1,52,-5,minecraft:basalt)
B(-1,53,-5,minecraft:basalt)
B(-1,54,-5,minecraft:basalt)
B(-1,55,-5,minecraft:basalt)
B(-1,56,-5,minecraft:basalt)
B(-1,57,-5,minecraft:basalt)
B(-1,58,-5,minecraft:basalt)
B(-1,59,-5,minecraft:basalt)
B(-1,60,-5,minecraft:basalt)
B(-1,61,-5,minecraft:basalt)
B(-1,62,-5,minecraft:basalt)
B(-1,63,-5,minecraft:basalt)
B(-1,64,-5,minecraft:basalt)
B(-1,65,-5,minecraft:basalt)
B(-1,66,-5,minecraft:basalt)
B(-1,45,-4,minecraft:basalt)
B(-1,46,-4,minecraft:basalt)
B(-1,47,-4,minecraft:basalt)
B(-1,48,-4,minecraft:basalt)
B(-1,49,-4,minecraft:basalt)
B(-1,50,-4,minecraft:basalt)
B(-1,51,-4,minecraft:basalt)
B(-1,52,-4,minecraft:basalt)
B(-1,53,-4,minecraft:basalt)
B(-1,54,-4,minecraft:basalt)
B(-1,55,-4,minecraft:basalt)
B(-1,56,-4,minecraft:basalt)
B(-1,57,-4,minecraft:basalt)
B(-1,58,-4,minecraft:basalt)
B(-1,59,-4,minecraft:basalt)
B(-1,60,-4,minecraft:basalt)
B(-1,61,-4,minecraft:basalt)
B(-1,62,-4,minecraft:basalt)
B(-1,63,-4,minecraft:basalt)
B(-1,64,-4,minecraft:basalt)
B(-1,65,-4,minecraft:basalt)
B(-1,66,-4,minecraft:basalt)
B(-1,45,-3,minecraft:basalt)
B(-1,46,-3,minecraft:basalt)
B(-1,47,-3,minecraft:basalt)
B(-1,48,-3,minecraft:basalt)
B(-1,49,-3,minecraft:basalt)
B(-1,50,-3,minecraft:basalt)
B(-1,51,-3,minecraft:basalt)
B(-1,52,-3,minecraft:basalt)
B(-1,53,-3,minecraft:basalt)
B(-1,54,-3,minecraft:basalt)
B(-1,55,-3,minecraft:basalt)
B(-1,56,-3,minecraft:basalt)
B(-1,57,-3,minecraft:basalt)
B(-1,58,-3,minecraft:basalt)
B(-1,59,-3,minecraft:basalt)
B(-1,60,-3,minecraft:basalt)
B(-1,61,-3,minecraft:basalt)
B(-1,62,-3,minecraft:basalt)
B(-1,63,-3,minecraft:basalt)
B(-1,64,-3,minecraft:basalt)
B(-1,65,-3,minecraft:basalt)
B(-1,66,-3,minecraft:basalt)
B(-1,48,-2,minecraft:basalt)
B(-1,49,-2,minecraft:basalt)
B(-1,50,-2,minecraft:basalt)
B(-1,51,-2,minecraft:basalt)
B(-1,52,-2,minecraft:basalt)
B(-1,53,-2,minecraft:basalt)
B(-1,54,-2,minecraft:basalt)
B(-1,55,-2,minecraft:basalt)
B(-1,56,-2,minecraft:basalt)
B(-1,57,-2,minecraft:basalt)
B(-1,58,-2,minecraft:basalt)
B(-1,59,-2,minecraft:basalt)
B(-1,60,-2,minecraft:basalt)
B(-1,61,-2,minecraft:basalt)
B(-1,62,-2,minecraft:basalt)
B(-1,63,-2,minecraft:basalt)
B(-1,64,-2,minecraft:basalt)
B(-1,65,-2,minecraft:basalt)
B(-1,66,-2,minecraft:basalt)
B(-1,53,-1,minecraft:basalt)
B(-1,54,-1,minecraft:basalt)
B(-1,55,-1,minecraft:basalt)
B(-1,56,-1,minecraft:basalt)
B(-1,57,-1,minecraft:basalt)
B(-1,58,-1,minecraft:basalt)
B(-1,59,-1,minecraft:basalt)
B(-1,60,-1,minecraft:basalt)
B(-1,61,-1,minecraft:basalt)
B(-1,62,-1,minecraft:basalt)
B(-1,63,-1,minecraft:basalt)
B(-1,64,-1,minecraft:basalt)
B(-1,65,-1,minecraft:basalt)
B(-1,66,-1,minecraft:basalt)
B(-1,54,0,minecraft:basalt)
B(-1,55,0,minecraft:basalt)
B(-1,56,0,minecraft:basalt)
B(-1,57,0,minecraft:basalt)
B(-1,58,0,minecraft:basalt)
B(-1,59,0,minecraft:basalt)
B(-1,60,0,minecraft:basalt)
B(-1,61,0,minecraft:basalt)
B(-1,62,0,minecraft:basalt)
B(-1,63,0,minecraft:basalt)
B(-1,64,0,minecraft:basalt)
B(-1,65,0,minecraft:basalt)
B(-1,66,0,minecraft:basalt)
B(-1,55,1,minecraft:basalt)
B(-1,56,1,minecraft:basalt)
B(-1,57,1,minecraft:basalt)
B(-1,58,1,minecraft:basalt)
B(-1,59,1,minecraft:basalt)
B(-1,60,1,minecraft:basalt)
B(-1,61,1,minecraft:basalt)
B(-1,62,1,minecraft:basalt)
B(-1,63,1,minecraft:basalt)
B(-1,64,1,minecraft:basalt)
B(-1,65,1,minecraft:basalt)
B(-1,66,1,minecraft:basalt)
B(-1,54,2,minecraft:basalt)
B(-1,55,2,minecraft:basalt)
B(-1,56,2,minecraft:basalt)
B(-1,57,2,minecraft:basalt)
B(-1,58,2,minecraft:basalt)
B(-1,59,2,minecraft:basalt)
B(-1,60,2,minecraft:basalt)
B(-1,61,2,minecraft:basalt)
B(-1,62,2,minecraft:basalt)
B(-1,63,2,minecraft:basalt)
B(-1,64,2,minecraft:basalt)
B(-1,65,2,minecraft:basalt)
B(-1,66,2,minecraft:basalt)
B(-1,54,3,minecraft:basalt)
B(-1,55,3,minecraft:basalt)
B(-1,56,3,minecraft:basalt)
B(-1,57,3,minecraft:basalt)
B(-1,58,3,minecraft:basalt)
B(-1,59,3,minecraft:basalt)
B(-1,60,3,minecraft:basalt)
B(-1,61,3,minecraft:basalt)
B(-1,62,3,minecraft:basalt)
B(-1,63,3,minecraft:basalt)
B(-1,64,3,minecraft:basalt)
B(-1,65,3,minecraft:basalt)
B(-1,66,3,minecraft:basalt)
B(-1,54,4,minecraft:basalt)
B(-1,55,4,minecraft:basalt)
B(-1,56,4,minecraft:basalt)
B(-1,57,4,minecraft:basalt)
B(-1,58,4,minecraft:basalt)
B(-1,59,4,minecraft:basalt)
B(-1,60,4,minecraft:basalt)
B(-1,61,4,minecraft:basalt)
B(-1,62,4,minecraft:basalt)
B(-1,63,4,minecraft:basalt)
B(-1,64,4,minecraft:basalt)
B(-1,65,4,minecraft:basalt)
B(-1,66,4,minecraft:basalt)
B(-1,54,5,minecraft:basalt)
B(-1,55,5,minecraft:basalt)
B(-1,56,5,minecraft:basalt)
B(-1,57,5,minecraft:basalt)
B(-1,58,5,minecraft:basalt)
B(-1,59,5,minecraft:basalt)
B(-1,60,5,minecraft:basalt)
B(-1,61,5,minecraft:basalt)
B(-1,62,5,minecraft:basalt)
B(-1,63,5,minecraft:basalt)
B(-1,64,5,minecraft:basalt)
B(-1,65,5,minecraft:basalt)
B(-1,66,5,minecraft:basalt)
B(-1,55,6,minecraft:basalt)
B(-1,56,6,minecraft:basalt)
B(-1,57,6,minecraft:basalt)
B(-1,58,6,minecraft:basalt)
B(-1,59,6,minecraft:basalt)
B(-1,60,6,minecraft:basalt)
B(-1,61,6,minecraft:basalt)
B(-1,62,6,minecraft:basalt)
B(-1,63,6,minecraft:basalt)
B(-1,64,6,minecraft:basalt)
B(-1,65,6,minecraft:basalt)
B(-1,66,6,minecraft:basalt)
B(-1,56,7,minecraft:basalt)
B(-1,57,7,minecraft:basalt)
B(-1,58,7,minecraft:basalt)
B(-1,59,7,minecraft:basalt)
B(-1,60,7,minecraft:basalt)
B(-1,61,7,minecraft:basalt)
B(-1,62,7,minecraft:basalt)
B(-1,63,7,minecraft:basalt)
B(-1,64,7,minecraft:basalt)
B(-1,65,7,minecraft:basalt)
B(-1,66,7,minecraft:basalt)
B(-1,56,8,minecraft:basalt)
B(-1,57,8,minecraft:basalt)
B(-1,58,8,minecraft:basalt)
B(-1,59,8,minecraft:basalt)
B(-1,60,8,minecraft:basalt)
B(-1,61,8,minecraft:basalt)
B(-1,62,8,minecraft:basalt)
B(-1,63,8,minecraft:basalt)
B(-1,64,8,minecraft:basalt)
B(-1,65,8,minecraft:basalt)
B(-1,66,8,minecraft:basalt)
B(0,39,-7,minecraft:basalt)
B(0,40,-7,minecraft:basalt)
B(0,41,-7,minecraft:basalt)
B(0,42,-7,minecraft:basalt)
B(0,43,-7,minecraft:basalt)
B(0,44,-7,minecraft:basalt)
B(0,45,-7,minecraft:basalt)
B(0,46,-7,minecraft:basalt)
B(0,47,-7,minecraft:basalt)
B(0,48,-7,minecraft:basalt)
B(0,49,-7,minecraft:basalt)
B(0,50,-7,minecraft:basalt)
B(0,51,-7,minecraft:basalt)
B(0,52,-7,minecraft:basalt)
B(0,53,-7,minecraft:basalt)
B(0,54,-7,minecraft:basalt)
B(0,55,-7,minecraft:basalt)
B(0,56,-7,minecraft:basalt)
B(0,57,-7,minecraft:basalt)
B(0,58,-7,minecraft:basalt)
B(0,59,-7,minecraft:basalt)
B(0,60,-7,minecraft:basalt)
B(0,61,-7,minecraft:basalt)
B(0,62,-7,minecraft:basalt)
B(0,63,-7,minecraft:basalt)
B(0,64,-7,minecraft:basalt)
B(0,65,-7,minecraft:basalt)
B(0,66,-7,minecraft:basalt)
B(0,32,-6,minecraft:basalt)
B(0,33,-6,minecraft:basalt)
B(0,34,-6,minecraft:basalt)
B(0,35,-6,minecraft:basalt)
B(0,36,-6,minecraft:basalt)
B(0,37,-6,minecraft:basalt)
B(0,38,-6,minecraft:basalt)
B(0,39,-6,minecraft:basalt)
B(0,40,-6,minecraft:basalt)
B(0,41,-6,minecraft:basalt)
B(0,42,-6,minecraft:basalt)
B(0,43,-6,minecraft:basalt)
B(0,44,-6,minecraft:basalt)
B(0,45,-6,minecraft:basalt)
B(0,46,-6,minecraft:basalt)
B(0,47,-6,minecraft:basalt)
B(0,48,-6,minecraft:basalt)
B(0,49,-6,minecraft:basalt)
B(0,50,-6,minecraft:basalt)
B(0,51,-6,minecraft:basalt)
B(0,52,-6,minecraft:basalt)
B(0,53,-6,minecraft:basalt)
B(0,54,-6,minecraft:basalt)
B(0,55,-6,minecraft:basalt)
B(0,56,-6,minecraft:basalt)
B(0,57,-6,minecraft:basalt)
B(0,58,-6,minecraft:basalt)
B(0,59,-6,minecraft:basalt)
B(0,60,-6,minecraft:basalt)
B(0,61,-6,minecraft:basalt)
B(0,62,-6,minecraft:basalt)
B(0,63,-6,minecraft:basalt)
B(0,64,-6,minecraft:basalt)
B(0,65,-6,minecraft:basalt)
B(0,66,-6,minecraft:basalt)
B(0,31,-5,minecraft:basalt)
B(0,32,-5,minecraft:basalt)
B(0,33,-5,minecraft:basalt)
B(0,34,-5,minecraft:basalt)
B(0,35,-5,minecraft:basalt)
B(0,36,-5,minecraft:basalt)
B(0,37,-5,minecraft:basalt)
B(0,38,-5,minecraft:basalt)
B(0,39,-5,minecraft:basalt)
B(0,40,-5,minecraft:basalt)
B(0,41,-5,minecraft:basalt)
B(0,42,-5,minecraft:basalt)
B(0,43,-5,minecraft:basalt)
B(0,44,-5,minecraft:basalt)
B(0,45,-5,minecraft:basalt)
B(0,46,-5,minecraft:basalt)
B(0,47,-5,minecraft:basalt)
B(0,48,-5,minecraft:basalt)
B(0,49,-5,minecraft:basalt)
B(0,50,-5,minecraft:basalt)
B(0,51,-5,minecraft:basalt)
B(0,52,-5,minecraft:basalt)
B(0,53,-5,minecraft:basalt)
B(0,54,-5,minecraft:basalt)
B(0,55,-5,minecraft:basalt)
B(0,56,-5,minecraft:basalt)
B(0,57,-5,minecraft:basalt)
B(0,58,-5,minecraft:basalt)
B(0,59,-5,minecraft:basalt)
B(0,60,-5,minecraft:basalt)
B(0,61,-5,minecraft:basalt)
B(0,62,-5,minecraft:basalt)
B(0,63,-5,minecraft:basalt)
B(0,64,-5,minecraft:basalt)
B(0,65,-5,minecraft:basalt)
B(0,66,-5,minecraft:basalt)
B(0,34,-4,minecraft:basalt)
B(0,35,-4,minecraft:basalt)
B(0,36,-4,minecraft:basalt)
B(0,37,-4,minecraft:basalt)
B(0,38,-4,minecraft:basalt)
B(0,39,-4,minecraft:basalt)
B(0,40,-4,minecraft:basalt)
B(0,41,-4,minecraft:basalt)
B(0,42,-4,minecraft:basalt)
B(0,43,-4,minecraft:basalt)
B(0,44,-4,minecraft:basalt)
B(0,45,-4,minecraft:basalt)
B(0,46,-4,minecraft:basalt)
B(0,47,-4,minecraft:basalt)
B(0,48,-4,minecraft:basalt)
B(0,49,-4,minecraft:basalt)
B(0,50,-4,minecraft:basalt)
B(0,51,-4,minecraft:basalt)
B(0,52,-4,minecraft:basalt)
B(0,53,-4,minecraft:basalt)
B(0,54,-4,minecraft:basalt)
B(0,55,-4,minecraft:basalt)
B(0,56,-4,minecraft:basalt)
B(0,57,-4,minecraft:basalt)
B(0,58,-4,minecraft:basalt)
B(0,59,-4,minecraft:basalt)
B(0,60,-4,minecraft:basalt)
B(0,61,-4,minecraft:basalt)
B(0,62,-4,minecraft:basalt)
B(0,63,-4,minecraft:basalt)
B(0,64,-4,minecraft:basalt)
B(0,65,-4,minecraft:basalt)
B(0,66,-4,minecraft:basalt)
B(0,34,-3,minecraft:basalt)
B(0,35,-3,minecraft:basalt)
B(0,36,-3,minecraft:basalt)
B(0,37,-3,minecraft:basalt)
B(0,38,-3,minecraft:basalt)
B(0,39,-3,minecraft:basalt)
B(0,40,-3,minecraft:basalt)
B(0,41,-3,minecraft:basalt)
B(0,42,-3,minecraft:basalt)
B(0,43,-3,minecraft:basalt)
B(0,44,-3,minecraft:basalt)
B(0,45,-3,minecraft:basalt)
B(0,46,-3,minecraft:basalt)
B(0,47,-3,minecraft:basalt)
B(0,48,-3,minecraft:basalt)
B(0,49,-3,minecraft:basalt)
B(0,50,-3,minecraft:basalt)
B(0,51,-3,minecraft:basalt)
B(0,52,-3,minecraft:basalt)
B(0,53,-3,minecraft:basalt)
B(0,54,-3,minecraft:basalt)
B(0,55,-3,minecraft:basalt)
B(0,56,-3,minecraft:basalt)
B(0,57,-3,minecraft:basalt)
B(0,58,-3,minecraft:basalt)
B(0,59,-3,minecraft:basalt)
B(0,60,-3,minecraft:basalt)
B(0,61,-3,minecraft:basalt)
B(0,62,-3,minecraft:basalt)
B(0,63,-3,minecraft:basalt)
B(0,64,-3,minecraft:basalt)
B(0,65,-3,minecraft:basalt)
B(0,66,-3,minecraft:basalt)
B(0,38,-2,minecraft:basalt)
B(0,39,-2,minecraft:basalt)
B(0,40,-2,minecraft:basalt)
B(0,41,-2,minecraft:basalt)
B(0,42,-2,minecraft:basalt)
B(0,43,-2,minecraft:basalt)
B(0,44,-2,minecraft:basalt)
B(0,45,-2,minecraft:basalt)
B(0,46,-2,minecraft:basalt)
B(0,47,-2,minecraft:basalt)
B(0,48,-2,minecraft:basalt)
B(0,49,-2,minecraft:basalt)
B(0,50,-2,minecraft:basalt)
B(0,51,-2,minecraft:basalt)
B(0,52,-2,minecraft:basalt)
B(0,53,-2,minecraft:basalt)
B(0,54,-2,minecraft:basalt)
B(0,55,-2,minecraft:basalt)
B(0,56,-2,minecraft:basalt)
B(0,57,-2,minecraft:basalt)
B(0,58,-2,minecraft:basalt)
B(0,59,-2,minecraft:basalt)
B(0,60,-2,minecraft:basalt)
B(0,61,-2,minecraft:basalt)
B(0,62,-2,minecraft:basalt)
B(0,63,-2,minecraft:basalt)
B(0,64,-2,minecraft:basalt)
B(0,65,-2,minecraft:basalt)
B(0,66,-2,minecraft:basalt)
B(0,47,-1,minecraft:basalt)
B(0,48,-1,minecraft:basalt)
B(0,49,-1,minecraft:basalt)
B(0,50,-1,minecraft:basalt)
B(0,51,-1,minecraft:basalt)
B(0,52,-1,minecraft:basalt)
B(0,53,-1,minecraft:basalt)
B(0,54,-1,minecraft:basalt)
B(0,55,-1,minecraft:basalt)
B(0,56,-1,minecraft:basalt)
B(0,57,-1,minecraft:basalt)
B(0,58,-1,minecraft:basalt)
B(0,59,-1,minecraft:basalt)
B(0,60,-1,minecraft:basalt)
B(0,61,-1,minecraft:basalt)
B(0,62,-1,minecraft:basalt)
B(0,63,-1,minecraft:basalt)
B(0,64,-1,minecraft:basalt)
B(0,65,-1,minecraft:basalt)
B(0,66,-1,minecraft:basalt)
B(0,54,0,minecraft:basalt)
B(0,55,0,minecraft:basalt)
B(0,56,0,minecraft:basalt)
B(0,57,0,minecraft:basalt)
B(0,58,0,minecraft:basalt)
B(0,59,0,minecraft:basalt)
B(0,60,0,minecraft:basalt)
B(0,61,0,minecraft:basalt)
B(0,62,0,minecraft:basalt)
B(0,63,0,minecraft:basalt)
B(0,64,0,minecraft:basalt)
B(0,65,0,minecraft:basalt)
B(0,66,0,minecraft:basalt)
B(0,55,1,minecraft:basalt)
B(0,56,1,minecraft:basalt)
B(0,57,1,minecraft:basalt)
B(0,58,1,minecraft:basalt)
B(0,59,1,minecraft:basalt)
B(0,60,1,minecraft:basalt)
B(0,61,1,minecraft:basalt)
B(0,62,1,minecraft:basalt)
B(0,63,1,minecraft:basalt)
B(0,64,1,minecraft:basalt)
B(0,65,1,minecraft:basalt)
B(0,66,1,minecraft:basalt)
B(0,54,2,minecraft:basalt)
B(0,55,2,minecraft:basalt)
B(0,56,2,minecraft:basalt)
B(0,57,2,minecraft:basalt)
B(0,58,2,minecraft:basalt)
B(0,59,2,minecraft:basalt)
B(0,60,2,minecraft:basalt)
B(0,61,2,minecraft:basalt)
B(0,62,2,minecraft:basalt)
B(0,63,2,minecraft:basalt)
B(0,64,2,minecraft:basalt)
B(0,65,2,minecraft:basalt)
B(0,66,2,minecraft:basalt)
B(0,54,3,minecraft:basalt)
B(0,55,3,minecraft:basalt)
B(0,56,3,minecraft:basalt)
B(0,57,3,minecraft:basalt)
B(0,58,3,minecraft:basalt)
B(0,59,3,minecraft:basalt)
B(0,60,3,minecraft:basalt)
B(0,61,3,minecraft:basalt)
B(0,62,3,minecraft:basalt)
B(0,63,3,minecraft:basalt)
B(0,64,3,minecraft:basalt)
B(0,65,3,minecraft:basalt)
B(0,66,3,minecraft:basalt)
B(0,54,4,minecraft:basalt)
B(0,55,4,minecraft:basalt)
B(0,56,4,minecraft:basalt)
B(0,57,4,minecraft:basalt)
B(0,58,4,minecraft:basalt)
B(0,59,4,minecraft:basalt)
B(0,60,4,minecraft:basalt)
B(0,61,4,minecraft:basalt)
B(0,62,4,minecraft:basalt)
B(0,63,4,minecraft:basalt)
B(0,64,4,minecraft:basalt)
B(0,65,4,minecraft:basalt)
B(0,66,4,minecraft:basalt)
B(0,54,5,minecraft:basalt)
B(0,55,5,minecraft:basalt)
B(0,56,5,minecraft:basalt)
B(0,57,5,minecraft:basalt)
B(0,58,5,minecraft:basalt)
B(0,59,5,minecraft:basalt)
B(0,60,5,minecraft:basalt)
B(0,61,5,minecraft:basalt)
B(0,62,5,minecraft:basalt)
B(0,63,5,minecraft:basalt)
B(0,64,5,minecraft:basalt)
B(0,65,5,minecraft:basalt)
B(0,66,5,minecraft:basalt)
B(0,55,6,minecraft:basalt)
B(0,56,6,minecraft:basalt)
B(0,57,6,minecraft:basalt)
B(0,58,6,minecraft:basalt)
B(0,59,6,minecraft:basalt)
B(0,60,6,minecraft:basalt)
B(0,61,6,minecraft:basalt)
B(0,62,6,minecraft:basalt)
B(0,63,6,minecraft:basalt)
B(0,64,6,minecraft:basalt)
B(0,65,6,minecraft:basalt)
B(0,66,6,minecraft:basalt)
B(0,55,7,minecraft:basalt)
B(0,56,7,minecraft:basalt)
B(0,57,7,minecraft:basalt)
B(0,58,7,minecraft:basalt)
B(0,59,7,minecraft:basalt)
B(0,60,7,minecraft:basalt)
B(0,61,7,minecraft:basalt)
B(0,62,7,minecraft:basalt)
B(0,63,7,minecraft:basalt)
B(0,64,7,minecraft:basalt)
B(0,65,7,minecraft:basalt)
B(0,66,7,minecraft:basalt)
B(0,56,8,minecraft:basalt)
B(0,57,8,minecraft:basalt)
B(0,58,8,minecraft:basalt)
B(0,59,8,minecraft:basalt)
B(0,60,8,minecraft:basalt)
B(0,61,8,minecraft:basalt)
B(0,62,8,minecraft:basalt)
B(0,63,8,minecraft:basalt)
B(0,64,8,minecraft:basalt)
B(0,65,8,minecraft:basalt)
B(0,66,8,minecraft:basalt)
B(1,27,-7,minecraft:basalt)
B(1,28,-7,minecraft:basalt)
B(1,29,-7,minecraft:basalt)
B(1,30,-7,minecraft:basalt)
B(1,31,-7,minecraft:basalt)
B(1,32,-7,minecraft:basalt)
B(1,33,-7,minecraft:basalt)
B(1,34,-7,minecraft:basalt)
B(1,35,-7,minecraft:basalt)
B(1,36,-7,minecraft:basalt)
B(1,37,-7,minecraft:basalt)
B(1,38,-7,minecraft:basalt)
B(1,39,-7,minecraft:basalt)
B(1,40,-7,minecraft:basalt)
B(1,41,-7,minecraft:basalt)
B(1,42,-7,minecraft:basalt)
B(1,43,-7,minecraft:basalt)
B(1,44,-7,minecraft:basalt)
B(1,45,-7,minecraft:basalt)
B(1,46,-7,minecraft:basalt)
B(1,47,-7,minecraft:basalt)
B(1,48,-7,minecraft:basalt)
B(1,49,-7,minecraft:basalt)
B(1,50,-7,minecraft:basalt)
B(1,51,-7,minecraft:basalt)
B(1,52,-7,minecraft:basalt)
B(1,53,-7,minecraft:basalt)
B(1,54,-7,minecraft:basalt)
B(1,55,-7,minecraft:basalt)
B(1,56,-7,minecraft:basalt)
B(1,57,-7,minecraft:basalt)
B(1,58,-7,minecraft:basalt)
B(1,59,-7,minecraft:basalt)
B(1,60,-7,minecraft:basalt)
B(1,61,-7,minecraft:basalt)
B(1,62,-7,minecraft:basalt)
B(1,63,-7,minecraft:basalt)
B(1,64,-7,minecraft:basalt)
B(1,65,-7,minecraft:basalt)
B(1,66,-7,minecraft:basalt)
B(1,22,-6,minecraft:basalt)
B(1,23,-6,minecraft:basalt)
B(1,24,-6,minecraft:basalt)
B(1,25,-6,minecraft:basalt)
B(1,26,-6,minecraft:basalt)
B(1,27,-6,minecraft:basalt)
B(1,28,-6,minecraft:basalt)
B(1,29,-6,minecraft:basalt)
B(1,30,-6,minecraft:basalt)
B(1,31,-6,minecraft:basalt)
B(1,32,-6,minecraft:basalt)
B(1,33,-6,minecraft:basalt)
B(1,34,-6,minecraft:basalt)
B(1,35,-6,minecraft:basalt)
B(1,36,-6,minecraft:basalt)
B(1,37,-6,minecraft:basalt)
B(1,38,-6,minecraft:basalt)
B(1,39,-6,minecraft:basalt)
B(1,40,-6,minecraft:basalt)
B(1,41,-6,minecraft:basalt)
B(1,42,-6,minecraft:basalt)
B(1,43,-6,minecraft:basalt)
B(1,44,-6,minecraft:basalt)
B(1,45,-6,minecraft:basalt)
B(1,46,-6,minecraft:basalt)
B(1,47,-6,minecraft:basalt)
B(1,48,-6,minecraft:basalt)
B(1,49,-6,minecraft:basalt)
B(1,50,-6,minecraft:basalt)
B(1,51,-6,minecraft:basalt)
B(1,52,-6,minecraft:basalt)
B(1,53,-6,minecraft:basalt)
B(1,54,-6,minecraft:basalt)
B(1,55,-6,minecraft:basalt)
B(1,56,-6,minecraft:basalt)
B(1,57,-6,minecraft:basalt)
B(1,58,-6,minecraft:basalt)
B(1,59,-6,minecraft:basalt)
B(1,60,-6,minecraft:basalt)
B(1,61,-6,minecraft:basalt)
B(1,62,-6,minecraft:basalt)
B(1,63,-6,minecraft:basalt)
B(1,64,-6,minecraft:basalt)
B(1,65,-6,minecraft:basalt)
B(1,66,-6,minecraft:basalt)
B(1,22,-5,minecraft:basalt)
B(1,23,-5,minecraft:basalt)
B(1,24,-5,minecraft:basalt)
B(1,25,-5,minecraft:basalt)
B(1,26,-5,minecraft:basalt)
B(1,27,-5,minecraft:basalt)
B(1,28,-5,minecraft:basalt)
B(1,29,-5,minecraft:basalt)
B(1,30,-5,minecraft:basalt)
B(1,31,-5,minecraft:basalt)
B(1,32,-5,minecraft:basalt)
B(1,33,-5,minecraft:basalt)
B(1,34,-5,minecraft:basalt)
B(1,35,-5,minecraft:basalt)
B(1,36,-5,minecraft:basalt)
B(1,37,-5,minecraft:basalt)
B(1,38,-5,minecraft:basalt)
B(1,39,-5,minecraft:basalt)
B(1,40,-5,minecraft:basalt)
B(1,41,-5,minecraft:basalt)
B(1,42,-5,minecraft:basalt)
B(1,43,-5,minecraft:basalt)
B(1,44,-5,minecraft:basalt)
B(1,45,-5,minecraft:basalt)
B(1,46,-5,minecraft:basalt)
B(1,47,-5,minecraft:basalt)
B(1,48,-5,minecraft:basalt)
B(1,49,-5,minecraft:basalt)
B(1,50,-5,minecraft:basalt)
B(1,51,-5,minecraft:basalt)
B(1,52,-5,minecraft:basalt)
B(1,53,-5,minecraft:basalt)
B(1,54,-5,minecraft:basalt)
B(1,55,-5,minecraft:basalt)
B(1,56,-5,minecraft:basalt)
B(1,57,-5,minecraft:basalt)
B(1,58,-5,minecraft:basalt)
B(1,59,-5,minecraft:basalt)
B(1,60,-5,minecraft:basalt)
B(1,61,-5,minecraft:basalt)
B(1,62,-5,minecraft:basalt)
B(1,63,-5,minecraft:basalt)
B(1,64,-5,minecraft:basalt)
B(1,65,-5,minecraft:basalt)
B(1,66,-5,minecraft:basalt)
B(1,22,-4,minecraft:basalt)
B(1,23,-4,minecraft:basalt)
B(1,24,-4,minecraft:basalt)
B(1,25,-4,minecraft:basalt)
B(1,26,-4,minecraft:basalt)
B(1,27,-4,minecraft:basalt)
B(1,28,-4,minecraft:basalt)
B(1,29,-4,minecraft:basalt)
B(1,30,-4,minecraft:basalt)
B(1,31,-4,minecraft:basalt)
B(1,32,-4,minecraft:basalt)
B(1,33,-4,minecraft:basalt)
B(1,34,-4,minecraft:basalt)
B(1,35,-4,minecraft:basalt)
B(1,36,-4,minecraft:basalt)
B(1,37,-4,minecraft:basalt)
B(1,38,-4,minecraft:basalt)
B(1,39,-4,minecraft:basalt)
B(1,40,-4,minecraft:basalt)
B(1,41,-4,minecraft:basalt)
B(1,42,-4,minecraft:basalt)
B(1,43,-4,minecraft:basalt)
B(1,44,-4,minecraft:basalt)
B(1,45,-4,minecraft:basalt)
B(1,46,-4,minecraft:basalt)
B(1,47,-4,minecraft:basalt)
B(1,48,-4,minecraft:basalt)
B(1,49,-4,minecraft:basalt)
B(1,50,-4,minecraft:basalt)
B(1,51,-4,minecraft:basalt)
B(1,52,-4,minecraft:basalt)
B(1,53,-4,minecraft:basalt)
B(1,54,-4,minecraft:basalt)
B(1,55,-4,minecraft:basalt)
B(1,56,-4,minecraft:basalt)
B(1,57,-4,minecraft:basalt)
B(1,58,-4,minecraft:basalt)
B(1,59,-4,minecraft:basalt)
B(1,60,-4,minecraft:basalt)
B(1,61,-4,minecraft:basalt)
B(1,62,-4,minecraft:basalt)
B(1,63,-4,minecraft:basalt)
B(1,64,-4,minecraft:basalt)
B(1,65,-4,minecraft:basalt)
B(1,66,-4,minecraft:basalt)
B(1,29,-3,minecraft:basalt)
B(1,30,-3,minecraft:basalt)
B(1,31,-3,minecraft:basalt)
B(1,32,-3,minecraft:basalt)
B(1,33,-3,minecraft:basalt)
B(1,34,-3,minecraft:basalt)
B(1,35,-3,minecraft:basalt)
B(1,36,-3,minecraft:basalt)
B(1,37,-3,minecraft:basalt)
B(1,38,-3,minecraft:basalt)
B(1,39,-3,minecraft:basalt)
B(1,40,-3,minecraft:basalt)
B(1,41,-3,minecraft:basalt)
B(1,42,-3,minecraft:basalt)
B(1,43,-3,minecraft:basalt)
B(1,44,-3,minecraft:basalt)
B(1,45,-3,minecraft:basalt)
B(1,46,-3,minecraft:basalt)
B(1,47,-3,minecraft:basalt)
B(1,48,-3,minecraft:basalt)
B(1,49,-3,minecraft:basalt)
B(1,50,-3,minecraft:basalt)
B(1,51,-3,minecraft:basalt)
B(1,52,-3,minecraft:basalt)
B(1,53,-3,minecraft:basalt)
B(1,54,-3,minecraft:basalt)
B(1,55,-3,minecraft:basalt)
B(1,56,-3,minecraft:basalt)
B(1,57,-3,minecraft:basalt)
B(1,58,-3,minecraft:basalt)
B(1,59,-3,minecraft:basalt)
B(1,60,-3,minecraft:basalt)
B(1,61,-3,minecraft:basalt)
B(1,62,-3,minecraft:basalt)
B(1,63,-3,minecraft:basalt)
B(1,64,-3,minecraft:basalt)
B(1,65,-3,minecraft:basalt)
B(1,66,-3,minecraft:basalt)
B(1,26,-2,minecraft:basalt)
B(1,27,-2,minecraft:basalt)
B(1,28,-2,minecraft:basalt)
B(1,29,-2,minecraft:basalt)
B(1,30,-2,minecraft:basalt)
B(1,31,-2,minecraft:basalt)
B(1,32,-2,minecraft:basalt)
B(1,33,-2,minecraft:basalt)
B(1,34,-2,minecraft:basalt)
B(1,35,-2,minecraft:basalt)
B(1,36,-2,minecraft:basalt)
B(1,37,-2,minecraft:basalt)
B(1,38,-2,minecraft:basalt)
B(1,39,-2,minecraft:basalt)
B(1,40,-2,minecraft:basalt)
B(1,41,-2,minecraft:basalt)
B(1,42,-2,minecraft:basalt)
B(1,43,-2,minecraft:basalt)
B(1,44,-2,minecraft:basalt)
B(1,45,-2,minecraft:basalt)
B(1,46,-2,minecraft:basalt)
B(1,47,-2,minecraft:basalt)
B(1,48,-2,minecraft:basalt)
B(1,49,-2,minecraft:basalt)
B(1,50,-2,minecraft:basalt)
B(1,51,-2,minecraft:basalt)
B(1,52,-2,minecraft:basalt)
B(1,53,-2,minecraft:basalt)
B(1,54,-2,minecraft:basalt)
B(1,55,-2,minecraft:basalt)
B(1,56,-2,minecraft:basalt)
B(1,57,-2,minecraft:basalt)
B(1,58,-2,minecraft:basalt)
B(1,59,-2,minecraft:basalt)
B(1,60,-2,minecraft:basalt)
B(1,61,-2,minecraft:basalt)
B(1,62,-2,minecraft:basalt)
B(1,63,-2,minecraft:basalt)
B(1,64,-2,minecraft:basalt)
B(1,65,-2,minecraft:basalt)
B(1,66,-2,minecraft:basalt)
B(1,30,-1,minecraft:basalt)
B(1,31,-1,minecraft:basalt)
B(1,32,-1,minecraft:basalt)
B(1,33,-1,minecraft:basalt)
B(1,34,-1,minecraft:basalt)
B(1,35,-1,minecraft:basalt)
B(1,36,-1,minecraft:basalt)
B(1,37,-1,minecraft:basalt)
B(1,38,-1,minecraft:basalt)
B(1,39,-1,minecraft:basalt)
B(1,40,-1,minecraft:basalt)
B(1,41,-1,minecraft:basalt)
B(1,42,-1,minecraft:basalt)
B(1,43,-1,minecraft:basalt)
B(1,44,-1,minecraft:basalt)
B(1,45,-1,minecraft:basalt)
B(1,46,-1,minecraft:basalt)
B(1,47,-1,minecraft:basalt)
B(1,48,-1,minecraft:basalt)
B(1,49,-1,minecraft:basalt)
B(1,50,-1,minecraft:basalt)
B(1,51,-1,minecraft:basalt)
B(1,52,-1,minecraft:basalt)
B(1,53,-1,minecraft:basalt)
B(1,54,-1,minecraft:basalt)
B(1,55,-1,minecraft:basalt)
B(1,56,-1,minecraft:basalt)
B(1,57,-1,minecraft:basalt)
B(1,58,-1,minecraft:basalt)
B(1,59,-1,minecraft:basalt)
B(1,60,-1,minecraft:basalt)
B(1,61,-1,minecraft:basalt)
B(1,62,-1,minecraft:basalt)
B(1,63,-1,minecraft:basalt)
B(1,64,-1,minecraft:basalt)
B(1,65,-1,minecraft:basalt)
B(1,66,-1,minecraft:basalt)
B(1,44,0,minecraft:basalt)
B(1,45,0,minecraft:basalt)
B(1,46,0,minecraft:basalt)
B(1,47,0,minecraft:basalt)
B(1,48,0,minecraft:basalt)
B(1,49,0,minecraft:basalt)
B(1,50,0,minecraft:basalt)
B(1,51,0,minecraft:basalt)
B(1,52,0,minecraft:basalt)
B(1,53,0,minecraft:basalt)
B(1,54,0,minecraft:basalt)
B(1,55,0,minecraft:basalt)
B(1,56,0,minecraft:basalt)
B(1,57,0,minecraft:basalt)
B(1,58,0,minecraft:basalt)
B(1,59,0,minecraft:basalt)
B(1,60,0,minecraft:basalt)
B(1,61,0,minecraft:basalt)
B(1,62,0,minecraft:basalt)
B(1,63,0,minecraft:basalt)
B(1,64,0,minecraft:basalt)
B(1,65,0,minecraft:basalt)
B(1,66,0,minecraft:basalt)
B(1,50,1,minecraft:basalt)
B(1,51,1,minecraft:basalt)
B(1,52,1,minecraft:basalt)
B(1,53,1,minecraft:basalt)
B(1,54,1,minecraft:basalt)
B(1,55,1,minecraft:basalt)
B(1,56,1,minecraft:basalt)
B(1,57,1,minecraft:basalt)
B(1,58,1,minecraft:basalt)
B(1,59,1,minecraft:basalt)
B(1,60,1,minecraft:basalt)
B(1,61,1,minecraft:basalt)
B(1,62,1,minecraft:basalt)
B(1,63,1,minecraft:basalt)
B(1,64,1,minecraft:basalt)
B(1,65,1,minecraft:basalt)
B(1,66,1,minecraft:basalt)
B(1,52,2,minecraft:basalt)
B(1,53,2,minecraft:basalt)
B(1,54,2,minecraft:basalt)
B(1,55,2,minecraft:basalt)
B(1,56,2,minecraft:basalt)
B(1,57,2,minecraft:basalt)
B(1,58,2,minecraft:basalt)
B(1,59,2,minecraft:basalt)
B(1,60,2,minecraft:basalt)
B(1,61,2,minecraft:basalt)
B(1,62,2,minecraft:basalt)
B(1,63,2,minecraft:basalt)
B(1,64,2,minecraft:basalt)
B(1,65,2,minecraft:basalt)
B(1,66,2,minecraft:basalt)
B(1,54,3,minecraft:basalt)
B(1,55,3,minecraft:basalt)
B(1,56,3,minecraft:basalt)
B(1,57,3,minecraft:basalt)
B(1,58,3,minecraft:basalt)
B(1,59,3,minecraft:basalt)
B(1,60,3,minecraft:basalt)
B(1,61,3,minecraft:basalt)
B(1,62,3,minecraft:basalt)
B(1,63,3,minecraft:basalt)
B(1,64,3,minecraft:basalt)
B(1,65,3,minecraft:basalt)
B(1,66,3,minecraft:basalt)
B(1,54,4,minecraft:basalt)
B(1,55,4,minecraft:basalt)
B(1,56,4,minecraft:basalt)
B(1,57,4,minecraft:basalt)
B(1,58,4,minecraft:basalt)
B(1,59,4,minecraft:basalt)
B(1,60,4,minecraft:basalt)
B(1,61,4,minecraft:basalt)
B(1,62,4,minecraft:basalt)
B(1,63,4,minecraft:basalt)
B(1,64,4,minecraft:basalt)
B(1,65,4,minecraft:basalt)
B(1,66,4,minecraft:basalt)
B(1,54,5,minecraft:basalt)
B(1,55,5,minecraft:basalt)
B(1,56,5,minecraft:basalt)
B(1,57,5,minecraft:basalt)
B(1,58,5,minecraft:basalt)
B(1,59,5,minecraft:basalt)
B(1,60,5,minecraft:basalt)
B(1,61,5,minecraft:basalt)
B(1,62,5,minecraft:basalt)
B(1,63,5,minecraft:basalt)
B(1,64,5,minecraft:basalt)
B(1,65,5,minecraft:basalt)
B(1,66,5,minecraft:basalt)
B(1,55,7,minecraft:basalt)
B(1,56,7,minecraft:basalt)
B(1,57,7,minecraft:basalt)
B(1,58,7,minecraft:basalt)
B(1,59,7,minecraft:basalt)
B(1,60,7,minecraft:basalt)
B(1,61,7,minecraft:basalt)
B(1,62,7,minecraft:basalt)
B(1,63,7,minecraft:basalt)
B(1,64,7,minecraft:basalt)
B(1,65,7,minecraft:basalt)
B(1,66,7,minecraft:basalt)
B(1,56,8,minecraft:basalt)
B(1,57,8,minecraft:basalt)
B(1,58,8,minecraft:basalt)
B(1,59,8,minecraft:basalt)
B(1,60,8,minecraft:basalt)
B(1,61,8,minecraft:basalt)
B(1,62,8,minecraft:basalt)
B(1,63,8,minecraft:basalt)
B(1,64,8,minecraft:basalt)
B(1,65,8,minecraft:basalt)
B(1,66,8,minecraft:basalt)
B(2,21,-7,minecraft:basalt)
B(2,22,-7,minecraft:basalt)
B(2,23,-7,minecraft:basalt)
B(2,24,-7,minecraft:basalt)
B(2,25,-7,minecraft:basalt)
B(2,26,-7,minecraft:basalt)
B(2,27,-7,minecraft:basalt)
B(2,28,-7,minecraft:basalt)
B(2,29,-7,minecraft:basalt)
B(2,30,-7,minecraft:basalt)
B(2,31,-7,minecraft:basalt)
B(2,32,-7,minecraft:basalt)
B(2,33,-7,minecraft:basalt)
B(2,34,-7,minecraft:basalt)
B(2,35,-7,minecraft:basalt)
B(2,36,-7,minecraft:basalt)
B(2,37,-7,minecraft:basalt)
B(2,38,-7,minecraft:basalt)
B(2,39,-7,minecraft:basalt)
B(2,40,-7,minecraft:basalt)
B(2,41,-7,minecraft:basalt)
B(2,42,-7,minecraft:basalt)
B(2,43,-7,minecraft:basalt)
B(2,44,-7,minecraft:basalt)
B(2,45,-7,minecraft:basalt)
B(2,46,-7,minecraft:basalt)
B(2,47,-7,minecraft:basalt)
B(2,48,-7,minecraft:basalt)
B(2,49,-7,minecraft:basalt)
B(2,50,-7,minecraft:basalt)
B(2,51,-7,minecraft:basalt)
B(2,52,-7,minecraft:basalt)
B(2,53,-7,minecraft:basalt)
B(2,54,-7,minecraft:basalt)
B(2,55,-7,minecraft:basalt)
B(2,56,-7,minecraft:basalt)
B(2,57,-7,minecraft:basalt)
B(2,58,-7,minecraft:basalt)
B(2,59,-7,minecraft:basalt)
B(2,60,-7,minecraft:basalt)
B(2,61,-7,minecraft:basalt)
B(2,62,-7,minecraft:basalt)
B(2,63,-7,minecraft:basalt)
B(2,64,-7,minecraft:basalt)
B(2,65,-7,minecraft:basalt)
B(2,66,-7,minecraft:basalt)
B(2,20,-6,minecraft:basalt)
B(2,21,-6,minecraft:basalt)
B(2,22,-6,minecraft:basalt)
B(2,23,-6,minecraft:basalt)
B(2,24,-6,minecraft:basalt)
B(2,25,-6,minecraft:basalt)
B(2,26,-6,minecraft:basalt)
B(2,27,-6,minecraft:basalt)
B(2,28,-6,minecraft:basalt)
B(2,29,-6,minecraft:basalt)
B(2,30,-6,minecraft:basalt)
B(2,31,-6,minecraft:basalt)
B(2,32,-6,minecraft:basalt)
B(2,33,-6,minecraft:basalt)
B(2,34,-6,minecraft:basalt)
B(2,35,-6,minecraft:basalt)
B(2,36,-6,minecraft:basalt)
B(2,37,-6,minecraft:basalt)
B(2,38,-6,minecraft:basalt)
B(2,39,-6,minecraft:basalt)
B(2,40,-6,minecraft:basalt)
B(2,41,-6,minecraft:basalt)
B(2,42,-6,minecraft:basalt)
B(2,43,-6,minecraft:basalt)
B(2,44,-6,minecraft:basalt)
B(2,45,-6,minecraft:basalt)
B(2,46,-6,minecraft:basalt)
B(2,47,-6,minecraft:basalt)
B(2,48,-6,minecraft:basalt)
B(2,49,-6,minecraft:basalt)
B(2,50,-6,minecraft:basalt)
B(2,51,-6,minecraft:basalt)
B(2,52,-6,minecraft:basalt)
B(2,53,-6,minecraft:basalt)
B(2,54,-6,minecraft:basalt)
B(2,55,-6,minecraft:basalt)
B(2,56,-6,minecraft:basalt)
B(2,57,-6,minecraft:basalt)
B(2,58,-6,minecraft:basalt)
B(2,59,-6,minecraft:basalt)
B(2,60,-6,minecraft:basalt)
B(2,61,-6,minecraft:basalt)
B(2,62,-6,minecraft:basalt)
B(2,63,-6,minecraft:basalt)
B(2,64,-6,minecraft:basalt)
B(2,65,-6,minecraft:basalt)
B(2,66,-6,minecraft:basalt)
B(2,20,-5,minecraft:basalt)
B(2,21,-5,minecraft:basalt)
B(2,22,-5,minecraft:basalt)
B(2,23,-5,minecraft:basalt)
B(2,24,-5,minecraft:basalt)
B(2,25,-5,minecraft:basalt)
B(2,26,-5,minecraft:basalt)
B(2,27,-5,minecraft:basalt)
B(2,28,-5,minecraft:basalt)
B(2,29,-5,minecraft:basalt)
B(2,30,-5,minecraft:basalt)
B(2,31,-5,minecraft:basalt)
B(2,32,-5,minecraft:basalt)
B(2,33,-5,minecraft:basalt)
B(2,34,-5,minecraft:basalt)
B(2,35,-5,minecraft:basalt)
B(2,36,-5,minecraft:basalt)
B(2,37,-5,minecraft:basalt)
B(2,38,-5,minecraft:basalt)
B(2,39,-5,minecraft:basalt)
B(2,40,-5,minecraft:basalt)
B(2,41,-5,minecraft:basalt)
B(2,42,-5,minecraft:basalt)
B(2,43,-5,minecraft:basalt)
B(2,44,-5,minecraft:basalt)
B(2,45,-5,minecraft:basalt)
B(2,46,-5,minecraft:basalt)
B(2,47,-5,minecraft:basalt)
B(2,48,-5,minecraft:basalt)
B(2,49,-5,minecraft:basalt)
B(2,50,-5,minecraft:basalt)
B(2,51,-5,minecraft:basalt)
B(2,52,-5,minecraft:basalt)
B(2,53,-5,minecraft:basalt)
B(2,54,-5,minecraft:basalt)
B(2,55,-5,minecraft:basalt)
B(2,56,-5,minecraft:basalt)
B(2,57,-5,minecraft:basalt)
B(2,58,-5,minecraft:basalt)
B(2,59,-5,minecraft:basalt)
B(2,60,-5,minecraft:basalt)
B(2,61,-5,minecraft:basalt)
B(2,62,-5,minecraft:basalt)
B(2,63,-5,minecraft:basalt)
B(2,64,-5,minecraft:basalt)
B(2,65,-5,minecraft:basalt)
B(2,66,-5,minecraft:basalt)
B(2,20,-4,minecraft:basalt)
B(2,21,-4,minecraft:basalt)
B(2,22,-4,minecraft:basalt)
B(2,23,-4,minecraft:basalt)
B(2,24,-4,minecraft:basalt)
B(2,25,-4,minecraft:basalt)
B(2,26,-4,minecraft:basalt)
B(2,27,-4,minecraft:basalt)
B(2,28,-4,minecraft:basalt)
B(2,29,-4,minecraft:basalt)
B(2,30,-4,minecraft:basalt)
B(2,31,-4,minecraft:basalt)
B(2,32,-4,minecraft:basalt)
B(2,33,-4,minecraft:basalt)
B(2,34,-4,minecraft:basalt)
B(2,35,-4,minecraft:basalt)
B(2,36,-4,minecraft:basalt)
B(2,37,-4,minecraft:basalt)
B(2,38,-4,minecraft:basalt)
B(2,39,-4,minecraft:basalt)
B(2,40,-4,minecraft:basalt)
B(2,41,-4,minecraft:basalt)
B(2,42,-4,minecraft:basalt)
B(2,43,-4,minecraft:basalt)
B(2,44,-4,minecraft:basalt)
B(2,45,-4,minecraft:basalt)
B(2,46,-4,minecraft:basalt)
B(2,47,-4,minecraft:basalt)
B(2,48,-4,minecraft:basalt)
B(2,49,-4,minecraft:basalt)
B(2,50,-4,minecraft:basalt)
B(2,51,-4,minecraft:basalt)
B(2,52,-4,minecraft:basalt)
B(2,53,-4,minecraft:basalt)
B(2,54,-4,minecraft:basalt)
B(2,55,-4,minecraft:basalt)
B(2,56,-4,minecraft:basalt)
B(2,57,-4,minecraft:basalt)
B(2,58,-4,minecraft:basalt)
B(2,59,-4,minecraft:basalt)
B(2,60,-4,minecraft:basalt)
B(2,61,-4,minecraft:basalt)
B(2,62,-4,minecraft:basalt)
B(2,63,-4,minecraft:basalt)
B(2,64,-4,minecraft:basalt)
B(2,65,-4,minecraft:basalt)
B(2,66,-4,minecraft:basalt)
B(2,20,-3,minecraft:basalt)
B(2,21,-3,minecraft:basalt)
B(2,22,-3,minecraft:basalt)
B(2,23,-3,minecraft:basalt)
B(2,24,-3,minecraft:basalt)
B(2,25,-3,minecraft:basalt)
B(2,26,-3,minecraft:basalt)
B(2,27,-3,minecraft:basalt)
B(2,28,-3,minecraft:basalt)
B(2,29,-3,minecraft:basalt)
B(2,30,-3,minecraft:basalt)
B(2,31,-3,minecraft:basalt)
B(2,32,-3,minecraft:basalt)
B(2,33,-3,minecraft:basalt)
B(2,34,-3,minecraft:basalt)
B(2,35,-3,minecraft:basalt)
B(2,36,-3,minecraft:basalt)
B(2,37,-3,minecraft:basalt)
B(2,38,-3,minecraft:basalt)
B(2,39,-3,minecraft:basalt)
B(2,40,-3,minecraft:basalt)
B(2,41,-3,minecraft:basalt)
B(2,42,-3,minecraft:basalt)
B(2,43,-3,minecraft:basalt)
B(2,44,-3,minecraft:basalt)
B(2,45,-3,minecraft:basalt)
B(2,46,-3,minecraft:basalt)
B(2,47,-3,minecraft:basalt)
B(2,48,-3,minecraft:basalt)
B(2,49,-3,minecraft:basalt)
B(2,50,-3,minecraft:basalt)
B(2,51,-3,minecraft:basalt)
B(2,52,-3,minecraft:basalt)
B(2,53,-3,minecraft:basalt)
B(2,54,-3,minecraft:basalt)
B(2,55,-3,minecraft:basalt)
B(2,56,-3,minecraft:basalt)
B(2,57,-3,minecraft:basalt)
B(2,58,-3,minecraft:basalt)
B(2,59,-3,minecraft:basalt)
B(2,60,-3,minecraft:basalt)
B(2,61,-3,minecraft:basalt)
B(2,62,-3,minecraft:basalt)
B(2,63,-3,minecraft:basalt)
B(2,64,-3,minecraft:basalt)
B(2,65,-3,minecraft:basalt)
B(2,66,-3,minecraft:basalt)
B(2,21,-2,minecraft:basalt)
B(2,22,-2,minecraft:basalt)
B(2,23,-2,minecraft:basalt)
B(2,24,-2,minecraft:basalt)
B(2,25,-2,minecraft:basalt)
B(2,26,-2,minecraft:basalt)
B(2,27,-2,minecraft:basalt)
B(2,28,-2,minecraft:basalt)
B(2,29,-2,minecraft:basalt)
B(2,30,-2,minecraft:basalt)
B(2,31,-2,minecraft:basalt)
B(2,32,-2,minecraft:basalt)
B(2,33,-2,minecraft:basalt)
B(2,34,-2,minecraft:basalt)
B(2,35,-2,minecraft:basalt)
B(2,36,-2,minecraft:basalt)
B(2,37,-2,minecraft:basalt)
B(2,38,-2,minecraft:basalt)
B(2,39,-2,minecraft:basalt)
B(2,40,-2,minecraft:basalt)
B(2,41,-2,minecraft:basalt)
B(2,42,-2,minecraft:basalt)
B(2,43,-2,minecraft:basalt)
B(2,44,-2,minecraft:basalt)
B(2,45,-2,minecraft:basalt)
B(2,46,-2,minecraft:basalt)
B(2,47,-2,minecraft:basalt)
B(2,48,-2,minecraft:basalt)
B(2,49,-2,minecraft:basalt)
B(2,50,-2,minecraft:basalt)
B(2,51,-2,minecraft:basalt)
B(2,52,-2,minecraft:basalt)
B(2,53,-2,minecraft:basalt)
B(2,54,-2,minecraft:basalt)
B(2,55,-2,minecraft:basalt)
B(2,56,-2,minecraft:basalt)
B(2,57,-2,minecraft:basalt)
B(2,58,-2,minecraft:basalt)
B(2,59,-2,minecraft:basalt)
B(2,60,-2,minecraft:basalt)
B(2,61,-2,minecraft:basalt)
B(2,62,-2,minecraft:basalt)
B(2,63,-2,minecraft:basalt)
B(2,64,-2,minecraft:basalt)
B(2,65,-2,minecraft:basalt)
B(2,66,-2,minecraft:basalt)
B(2,22,-1,minecraft:basalt)
B(2,23,-1,minecraft:basalt)
B(2,24,-1,minecraft:basalt)
B(2,25,-1,minecraft:basalt)
B(2,26,-1,minecraft:basalt)
B(2,27,-1,minecraft:basalt)
B(2,28,-1,minecraft:basalt)
B(2,29,-1,minecraft:basalt)
B(2,30,-1,minecraft:basalt)
B(2,31,-1,minecraft:basalt)
B(2,32,-1,minecraft:basalt)
B(2,33,-1,minecraft:basalt)
B(2,34,-1,minecraft:basalt)
B(2,35,-1,minecraft:basalt)
B(2,36,-1,minecraft:basalt)
B(2,37,-1,minecraft:basalt)
B(2,38,-1,minecraft:basalt)
B(2,39,-1,minecraft:basalt)
B(2,40,-1,minecraft:basalt)
B(2,41,-1,minecraft:basalt)
B(2,42,-1,minecraft:basalt)
B(2,43,-1,minecraft:basalt)
B(2,44,-1,minecraft:basalt)
B(2,45,-1,minecraft:basalt)
B(2,46,-1,minecraft:basalt)
B(2,47,-1,minecraft:basalt)
B(2,48,-1,minecraft:basalt)
B(2,49,-1,minecraft:basalt)
B(2,50,-1,minecraft:basalt)
B(2,51,-1,minecraft:basalt)
B(2,52,-1,minecraft:basalt)
B(2,53,-1,minecraft:basalt)
B(2,54,-1,minecraft:basalt)
B(2,55,-1,minecraft:basalt)
B(2,56,-1,minecraft:basalt)
B(2,57,-1,minecraft:basalt)
B(2,58,-1,minecraft:basalt)
B(2,59,-1,minecraft:basalt)
B(2,60,-1,minecraft:basalt)
B(2,61,-1,minecraft:basalt)
B(2,62,-1,minecraft:basalt)
B(2,63,-1,minecraft:basalt)
B(2,64,-1,minecraft:basalt)
B(2,65,-1,minecraft:basalt)
B(2,66,-1,minecraft:basalt)
B(2,22,0,minecraft:basalt)
B(2,23,0,minecraft:basalt)
B(2,24,0,minecraft:basalt)
B(2,25,0,minecraft:basalt)
B(2,26,0,minecraft:basalt)
B(2,27,0,minecraft:basalt)
B(2,28,0,minecraft:basalt)
B(2,29,0,minecraft:basalt)
B(2,30,0,minecraft:basalt)
B(2,31,0,minecraft:basalt)
B(2,32,0,minecraft:basalt)
B(2,33,0,minecraft:basalt)
B(2,34,0,minecraft:basalt)
B(2,35,0,minecraft:basalt)
B(2,36,0,minecraft:basalt)
B(2,37,0,minecraft:basalt)
B(2,38,0,minecraft:basalt)
B(2,39,0,minecraft:basalt)
B(2,40,0,minecraft:basalt)
B(2,41,0,minecraft:basalt)
B(2,42,0,minecraft:basalt)
B(2,43,0,minecraft:basalt)
B(2,44,0,minecraft:basalt)
B(2,45,0,minecraft:basalt)
B(2,46,0,minecraft:basalt)
B(2,47,0,minecraft:basalt)
B(2,48,0,minecraft:basalt)
B(2,49,0,minecraft:basalt)
B(2,50,0,minecraft:basalt)
B(2,51,0,minecraft:basalt)
B(2,52,0,minecraft:basalt)
B(2,53,0,minecraft:basalt)
B(2,54,0,minecraft:basalt)
B(2,55,0,minecraft:basalt)
B(2,56,0,minecraft:basalt)
B(2,57,0,minecraft:basalt)
B(2,58,0,minecraft:basalt)
B(2,59,0,minecraft:basalt)
B(2,60,0,minecraft:basalt)
B(2,61,0,minecraft:basalt)
B(2,62,0,minecraft:basalt)
B(2,63,0,minecraft:basalt)
B(2,64,0,minecraft:basalt)
B(2,65,0,minecraft:basalt)
B(2,66,0,minecraft:basalt)
B(2,40,1,minecraft:basalt)
B(2,41,1,minecraft:basalt)
B(2,42,1,minecraft:basalt)
B(2,43,1,minecraft:basalt)
B(2,44,1,minecraft:basalt)
B(2,45,1,minecraft:basalt)
B(2,46,1,minecraft:basalt)
B(2,47,1,minecraft:basalt)
B(2,48,1,minecraft:basalt)
B(2,49,1,minecraft:basalt)
B(2,50,1,minecraft:basalt)
B(2,51,1,minecraft:basalt)
B(2,52,1,minecraft:basalt)
B(2,53,1,minecraft:basalt)
B(2,54,1,minecraft:basalt)
B(2,55,1,minecraft:basalt)
B(2,56,1,minecraft:basalt)
B(2,57,1,minecraft:basalt)
B(2,58,1,minecraft:basalt)
B(2,59,1,minecraft:basalt)
B(2,60,1,minecraft:basalt)
B(2,61,1,minecraft:basalt)
B(2,62,1,minecraft:basalt)
B(2,63,1,minecraft:basalt)
B(2,64,1,minecraft:basalt)
B(2,65,1,minecraft:basalt)
B(2,66,1,minecraft:basalt)
B(2,43,2,minecraft:basalt)
B(2,44,2,minecraft:basalt)
B(2,45,2,minecraft:basalt)
B(2,46,2,minecraft:basalt)
B(2,47,2,minecraft:basalt)
B(2,48,2,minecraft:basalt)
B(2,49,2,minecraft:basalt)
B(2,50,2,minecraft:basalt)
B(2,51,2,minecraft:basalt)
B(2,52,2,minecraft:basalt)
B(2,53,2,minecraft:basalt)
B(2,54,2,minecraft:basalt)
B(2,55,2,minecraft:basalt)
B(2,56,2,minecraft:basalt)
B(2,57,2,minecraft:basalt)
B(2,58,2,minecraft:basalt)
B(2,59,2,minecraft:basalt)
B(2,60,2,minecraft:basalt)
B(2,61,2,minecraft:basalt)
B(2,62,2,minecraft:basalt)
B(2,63,2,minecraft:basalt)
B(2,64,2,minecraft:basalt)
B(2,65,2,minecraft:basalt)
B(2,66,2,minecraft:basalt)
B(2,47,3,minecraft:basalt)
B(2,48,3,minecraft:basalt)
B(2,49,3,minecraft:basalt)
B(2,50,3,minecraft:basalt)
B(2,51,3,minecraft:basalt)
B(2,52,3,minecraft:basalt)
B(2,53,3,minecraft:basalt)
B(2,54,3,minecraft:basalt)
B(2,55,3,minecraft:basalt)
B(2,56,3,minecraft:basalt)
B(2,57,3,minecraft:basalt)
B(2,58,3,minecraft:basalt)
B(2,59,3,minecraft:basalt)
B(2,60,3,minecraft:basalt)
B(2,61,3,minecraft:basalt)
B(2,62,3,minecraft:basalt)
B(2,63,3,minecraft:basalt)
B(2,64,3,minecraft:basalt)
B(2,65,3,minecraft:basalt)
B(2,66,3,minecraft:basalt)
B(2,55,4,minecraft:basalt)
B(2,56,4,minecraft:basalt)
B(2,57,4,minecraft:basalt)
B(2,58,4,minecraft:basalt)
B(2,59,4,minecraft:basalt)
B(2,60,4,minecraft:basalt)
B(2,61,4,minecraft:basalt)
B(2,62,4,minecraft:basalt)
B(2,63,4,minecraft:basalt)
B(2,64,4,minecraft:basalt)
B(2,65,4,minecraft:basalt)
B(2,66,4,minecraft:basalt)
B(2,55,5,minecraft:basalt)
B(2,56,5,minecraft:basalt)
B(2,57,5,minecraft:basalt)
B(2,58,5,minecraft:basalt)
B(2,59,5,minecraft:basalt)
B(2,60,5,minecraft:basalt)
B(2,61,5,minecraft:basalt)
B(2,62,5,minecraft:basalt)
B(2,63,5,minecraft:basalt)
B(2,64,5,minecraft:basalt)
B(2,65,5,minecraft:basalt)
B(2,66,5,minecraft:basalt)
B(2,55,6,minecraft:basalt)
B(2,56,6,minecraft:basalt)
B(2,57,6,minecraft:basalt)
B(2,58,6,minecraft:basalt)
B(2,59,6,minecraft:basalt)
B(2,60,6,minecraft:basalt)
B(2,61,6,minecraft:basalt)
B(2,62,6,minecraft:basalt)
B(2,63,6,minecraft:basalt)
B(2,64,6,minecraft:basalt)
B(2,65,6,minecraft:basalt)
B(2,66,6,minecraft:basalt)
B(2,56,7,minecraft:basalt)
B(2,57,7,minecraft:basalt)
B(2,58,7,minecraft:basalt)
B(2,59,7,minecraft:basalt)
B(2,60,7,minecraft:basalt)
B(2,61,7,minecraft:basalt)
B(2,62,7,minecraft:basalt)
B(2,63,7,minecraft:basalt)
B(2,64,7,minecraft:basalt)
B(2,65,7,minecraft:basalt)
B(2,66,7,minecraft:basalt)
B(2,57,8,minecraft:basalt)
B(2,58,8,minecraft:basalt)
B(2,59,8,minecraft:basalt)
B(2,60,8,minecraft:basalt)
B(2,61,8,minecraft:basalt)
B(2,62,8,minecraft:basalt)
B(2,63,8,minecraft:basalt)
B(2,64,8,minecraft:basalt)
B(2,65,8,minecraft:basalt)
B(2,66,8,minecraft:basalt)
B(3,20,-7,minecraft:basalt)
B(3,21,-7,minecraft:basalt)
B(3,22,-7,minecraft:basalt)
B(3,23,-7,minecraft:basalt)
B(3,24,-7,minecraft:basalt)
B(3,25,-7,minecraft:basalt)
B(3,26,-7,minecraft:basalt)
B(3,27,-7,minecraft:basalt)
B(3,28,-7,minecraft:basalt)
B(3,29,-7,minecraft:basalt)
B(3,30,-7,minecraft:basalt)
B(3,31,-7,minecraft:basalt)
B(3,32,-7,minecraft:basalt)
B(3,33,-7,minecraft:basalt)
B(3,34,-7,minecraft:basalt)
B(3,35,-7,minecraft:basalt)
B(3,36,-7,minecraft:basalt)
B(3,37,-7,minecraft:basalt)
B(3,38,-7,minecraft:basalt)
B(3,39,-7,minecraft:basalt)
B(3,40,-7,minecraft:basalt)
B(3,41,-7,minecraft:basalt)
B(3,42,-7,minecraft:basalt)
B(3,43,-7,minecraft:basalt)
B(3,44,-7,minecraft:basalt)
B(3,45,-7,minecraft:basalt)
B(3,46,-7,minecraft:basalt)
B(3,47,-7,minecraft:basalt)
B(3,48,-7,minecraft:basalt)
B(3,49,-7,minecraft:basalt)
B(3,50,-7,minecraft:basalt)
B(3,51,-7,minecraft:basalt)
B(3,52,-7,minecraft:basalt)
B(3,53,-7,minecraft:basalt)
B(3,54,-7,minecraft:basalt)
B(3,55,-7,minecraft:basalt)
B(3,56,-7,minecraft:basalt)
B(3,57,-7,minecraft:basalt)
B(3,58,-7,minecraft:basalt)
B(3,59,-7,minecraft:basalt)
B(3,60,-7,minecraft:basalt)
B(3,61,-7,minecraft:basalt)
B(3,62,-7,minecraft:basalt)
B(3,63,-7,minecraft:basalt)
B(3,64,-7,minecraft:basalt)
B(3,65,-7,minecraft:basalt)
B(3,66,-7,minecraft:basalt)
B(3,19,-6,minecraft:basalt)
B(3,20,-6,minecraft:basalt)
B(3,21,-6,minecraft:basalt)
B(3,22,-6,minecraft:basalt)
B(3,23,-6,minecraft:basalt)
B(3,24,-6,minecraft:basalt)
B(3,25,-6,minecraft:basalt)
B(3,26,-6,minecraft:basalt)
B(3,27,-6,minecraft:basalt)
B(3,28,-6,minecraft:basalt)
B(3,29,-6,minecraft:basalt)
B(3,30,-6,minecraft:basalt)
B(3,31,-6,minecraft:basalt)
B(3,32,-6,minecraft:basalt)
B(3,33,-6,minecraft:basalt)
B(3,34,-6,minecraft:basalt)
B(3,35,-6,minecraft:basalt)
B(3,36,-6,minecraft:basalt)
B(3,37,-6,minecraft:basalt)
B(3,38,-6,minecraft:basalt)
B(3,39,-6,minecraft:basalt)
B(3,40,-6,minecraft:basalt)
B(3,41,-6,minecraft:basalt)
B(3,42,-6,minecraft:basalt)
B(3,43,-6,minecraft:basalt)
B(3,44,-6,minecraft:basalt)
B(3,45,-6,minecraft:basalt)
B(3,46,-6,minecraft:basalt)
B(3,47,-6,minecraft:basalt)
B(3,48,-6,minecraft:basalt)
B(3,49,-6,minecraft:basalt)
B(3,50,-6,minecraft:basalt)
B(3,51,-6,minecraft:basalt)
B(3,52,-6,minecraft:basalt)
B(3,53,-6,minecraft:basalt)
B(3,54,-6,minecraft:basalt)
B(3,55,-6,minecraft:basalt)
B(3,56,-6,minecraft:basalt)
B(3,57,-6,minecraft:basalt)
B(3,58,-6,minecraft:basalt)
B(3,59,-6,minecraft:basalt)
B(3,60,-6,minecraft:basalt)
B(3,61,-6,minecraft:basalt)
B(3,62,-6,minecraft:basalt)
B(3,63,-6,minecraft:basalt)
B(3,64,-6,minecraft:basalt)
B(3,65,-6,minecraft:basalt)
B(3,66,-6,minecraft:basalt)
B(3,18,-5,minecraft:basalt)
B(3,19,-5,minecraft:basalt)
B(3,20,-5,minecraft:basalt)
B(3,21,-5,minecraft:basalt)
B(3,22,-5,minecraft:basalt)
B(3,23,-5,minecraft:basalt)
B(3,24,-5,minecraft:basalt)
B(3,25,-5,minecraft:basalt)
B(3,26,-5,minecraft:basalt)
B(3,27,-5,minecraft:basalt)
B(3,28,-5,minecraft:basalt)
B(3,29,-5,minecraft:basalt)
B(3,30,-5,minecraft:basalt)
B(3,31,-5,minecraft:basalt)
B(3,32,-5,minecraft:basalt)
B(3,33,-5,minecraft:basalt)
B(3,34,-5,minecraft:basalt)
B(3,35,-5,minecraft:basalt)
B(3,36,-5,minecraft:basalt)
B(3,37,-5,minecraft:basalt)
B(3,38,-5,minecraft:basalt)
B(3,39,-5,minecraft:basalt)
B(3,40,-5,minecraft:basalt)
B(3,41,-5,minecraft:basalt)
B(3,42,-5,minecraft:basalt)
B(3,43,-5,minecraft:basalt)
B(3,44,-5,minecraft:basalt)
B(3,45,-5,minecraft:basalt)
B(3,46,-5,minecraft:basalt)
B(3,47,-5,minecraft:basalt)
B(3,48,-5,minecraft:basalt)
B(3,49,-5,minecraft:basalt)
B(3,50,-5,minecraft:basalt)
B(3,51,-5,minecraft:basalt)
B(3,52,-5,minecraft:basalt)
B(3,53,-5,minecraft:basalt)
B(3,54,-5,minecraft:basalt)
B(3,55,-5,minecraft:basalt)
B(3,56,-5,minecraft:basalt)
B(3,57,-5,minecraft:basalt)
B(3,58,-5,minecraft:basalt)
B(3,59,-5,minecraft:basalt)
B(3,60,-5,minecraft:basalt)
B(3,61,-5,minecraft:basalt)
B(3,62,-5,minecraft:basalt)
B(3,63,-5,minecraft:basalt)
B(3,64,-5,minecraft:basalt)
B(3,65,-5,minecraft:basalt)
B(3,66,-5,minecraft:basalt)
B(3,18,-4,minecraft:basalt)
B(3,19,-4,minecraft:basalt)
B(3,20,-4,minecraft:basalt)
B(3,21,-4,minecraft:basalt)
B(3,22,-4,minecraft:basalt)
B(3,23,-4,minecraft:basalt)
B(3,24,-4,minecraft:basalt)
B(3,25,-4,minecraft:basalt)
B(3,26,-4,minecraft:basalt)
B(3,27,-4,minecraft:basalt)
B(3,28,-4,minecraft:basalt)
B(3,29,-4,minecraft:basalt)
B(3,30,-4,minecraft:basalt)
B(3,31,-4,minecraft:basalt)
B(3,32,-4,minecraft:basalt)
B(3,33,-4,minecraft:basalt)
B(3,34,-4,minecraft:basalt)
B(3,35,-4,minecraft:basalt)
B(3,36,-4,minecraft:basalt)
B(3,37,-4,minecraft:basalt)
B(3,38,-4,minecraft:basalt)
B(3,39,-4,minecraft:basalt)
B(3,40,-4,minecraft:basalt)
B(3,41,-4,minecraft:basalt)
B(3,42,-4,minecraft:basalt)
B(3,43,-4,minecraft:basalt)
B(3,44,-4,minecraft:basalt)
B(3,45,-4,minecraft:basalt)
B(3,46,-4,minecraft:basalt)
B(3,47,-4,minecraft:basalt)
B(3,48,-4,minecraft:basalt)
B(3,49,-4,minecraft:basalt)
B(3,50,-4,minecraft:basalt)
B(3,51,-4,minecraft:basalt)
B(3,52,-4,minecraft:basalt)
B(3,53,-4,minecraft:basalt)
B(3,54,-4,minecraft:basalt)
B(3,55,-4,minecraft:basalt)
B(3,56,-4,minecraft:basalt)
B(3,57,-4,minecraft:basalt)
B(3,58,-4,minecraft:basalt)
B(3,59,-4,minecraft:basalt)
B(3,60,-4,minecraft:basalt)
B(3,61,-4,minecraft:basalt)
B(3,62,-4,minecraft:basalt)
B(3,63,-4,minecraft:basalt)
B(3,64,-4,minecraft:basalt)
B(3,65,-4,minecraft:basalt)
B(3,66,-4,minecraft:basalt)
B(3,18,-3,minecraft:basalt)
B(3,19,-3,minecraft:basalt)
B(3,20,-3,minecraft:basalt)
B(3,21,-3,minecraft:basalt)
B(3,22,-3,minecraft:basalt)
B(3,23,-3,minecraft:basalt)
B(3,24,-3,minecraft:basalt)
B(3,25,-3,minecraft:basalt)
B(3,26,-3,minecraft:basalt)
B(3,27,-3,minecraft:basalt)
B(3,28,-3,minecraft:basalt)
B(3,29,-3,minecraft:basalt)
B(3,30,-3,minecraft:basalt)
B(3,31,-3,minecraft:basalt)
B(3,32,-3,minecraft:basalt)
B(3,33,-3,minecraft:basalt)
B(3,34,-3,minecraft:basalt)
B(3,35,-3,minecraft:basalt)
B(3,36,-3,minecraft:basalt)
B(3,37,-3,minecraft:basalt)
B(3,38,-3,minecraft:basalt)
B(3,39,-3,minecraft:basalt)
B(3,40,-3,minecraft:basalt)
B(3,41,-3,minecraft:basalt)
B(3,42,-3,minecraft:basalt)
B(3,43,-3,minecraft:basalt)
B(3,44,-3,minecraft:basalt)
B(3,45,-3,minecraft:basalt)
B(3,46,-3,minecraft:basalt)
B(3,47,-3,minecraft:basalt)
B(3,48,-3,minecraft:basalt)
B(3,49,-3,minecraft:basalt)
B(3,50,-3,minecraft:basalt)
B(3,51,-3,minecraft:basalt)
B(3,52,-3,minecraft:basalt)
B(3,53,-3,minecraft:basalt)
B(3,54,-3,minecraft:basalt)
B(3,55,-3,minecraft:basalt)
B(3,56,-3,minecraft:basalt)
B(3,57,-3,minecraft:basalt)
B(3,58,-3,minecraft:basalt)
B(3,59,-3,minecraft:basalt)
B(3,60,-3,minecraft:basalt)
B(3,61,-3,minecraft:basalt)
B(3,62,-3,minecraft:basalt)
B(3,63,-3,minecraft:basalt)
B(3,64,-3,minecraft:basalt)
B(3,65,-3,minecraft:basalt)
B(3,66,-3,minecraft:basalt)
B(3,19,-2,minecraft:basalt)
B(3,20,-2,minecraft:basalt)
B(3,21,-2,minecraft:basalt)
B(3,22,-2,minecraft:basalt)
B(3,23,-2,minecraft:basalt)
B(3,24,-2,minecraft:basalt)
B(3,25,-2,minecraft:basalt)
B(3,26,-2,minecraft:basalt)
B(3,27,-2,minecraft:basalt)
B(3,28,-2,minecraft:basalt)
B(3,29,-2,minecraft:basalt)
B(3,30,-2,minecraft:basalt)
B(3,31,-2,minecraft:basalt)
B(3,32,-2,minecraft:basalt)
B(3,33,-2,minecraft:basalt)
B(3,34,-2,minecraft:basalt)
B(3,35,-2,minecraft:basalt)
B(3,36,-2,minecraft:basalt)
B(3,37,-2,minecraft:basalt)
B(3,38,-2,minecraft:basalt)
B(3,39,-2,minecraft:basalt)
B(3,40,-2,minecraft:basalt)
B(3,41,-2,minecraft:basalt)
B(3,42,-2,minecraft:basalt)
B(3,43,-2,minecraft:basalt)
B(3,44,-2,minecraft:basalt)
B(3,45,-2,minecraft:basalt)
B(3,46,-2,minecraft:basalt)
B(3,47,-2,minecraft:basalt)
B(3,48,-2,minecraft:basalt)
B(3,49,-2,minecraft:basalt)
B(3,50,-2,minecraft:basalt)
B(3,51,-2,minecraft:basalt)
B(3,52,-2,minecraft:basalt)
B(3,53,-2,minecraft:basalt)
B(3,54,-2,minecraft:basalt)
B(3,55,-2,minecraft:basalt)
B(3,56,-2,minecraft:basalt)
B(3,57,-2,minecraft:basalt)
B(3,58,-2,minecraft:basalt)
B(3,59,-2,minecraft:basalt)
B(3,60,-2,minecraft:basalt)
B(3,61,-2,minecraft:basalt)
B(3,62,-2,minecraft:basalt)
B(3,63,-2,minecraft:basalt)
B(3,64,-2,minecraft:basalt)
B(3,65,-2,minecraft:basalt)
B(3,66,-2,minecraft:basalt)
B(3,20,-1,minecraft:basalt)
B(3,21,-1,minecraft:basalt)
B(3,22,-1,minecraft:basalt)
B(3,23,-1,minecraft:basalt)
B(3,24,-1,minecraft:basalt)
B(3,25,-1,minecraft:basalt)
B(3,26,-1,minecraft:basalt)
B(3,27,-1,minecraft:basalt)
B(3,28,-1,minecraft:basalt)
B(3,29,-1,minecraft:basalt)
B(3,30,-1,minecraft:basalt)
B(3,31,-1,minecraft:basalt)
B(3,32,-1,minecraft:basalt)
B(3,33,-1,minecraft:basalt)
B(3,34,-1,minecraft:basalt)
B(3,35,-1,minecraft:basalt)
B(3,36,-1,minecraft:basalt)
B(3,37,-1,minecraft:basalt)
B(3,38,-1,minecraft:basalt)
B(3,39,-1,minecraft:basalt)
B(3,40,-1,minecraft:basalt)
B(3,41,-1,minecraft:basalt)
B(3,42,-1,minecraft:basalt)
B(3,43,-1,minecraft:basalt)
B(3,44,-1,minecraft:basalt)
B(3,45,-1,minecraft:basalt)
B(3,46,-1,minecraft:basalt)
B(3,47,-1,minecraft:basalt)
B(3,48,-1,minecraft:basalt)
B(3,49,-1,minecraft:basalt)
B(3,50,-1,minecraft:basalt)
B(3,51,-1,minecraft:basalt)
B(3,52,-1,minecraft:basalt)
B(3,53,-1,minecraft:basalt)
B(3,54,-1,minecraft:basalt)
B(3,55,-1,minecraft:basalt)
B(3,56,-1,minecraft:basalt)
B(3,57,-1,minecraft:basalt)
B(3,58,-1,minecraft:basalt)
B(3,59,-1,minecraft:basalt)
B(3,60,-1,minecraft:basalt)
B(3,61,-1,minecraft:basalt)
B(3,62,-1,minecraft:basalt)
B(3,63,-1,minecraft:basalt)
B(3,64,-1,minecraft:basalt)
B(3,65,-1,minecraft:basalt)
B(3,66,-1,minecraft:basalt)
B(3,21,0,minecraft:basalt)
B(3,22,0,minecraft:basalt)
B(3,23,0,minecraft:basalt)
B(3,24,0,minecraft:basalt)
B(3,25,0,minecraft:basalt)
B(3,26,0,minecraft:basalt)
B(3,27,0,minecraft:basalt)
B(3,28,0,minecraft:basalt)
B(3,29,0,minecraft:basalt)
B(3,30,0,minecraft:basalt)
B(3,31,0,minecraft:basalt)
B(3,32,0,minecraft:basalt)
B(3,33,0,minecraft:basalt)
B(3,34,0,minecraft:basalt)
B(3,35,0,minecraft:basalt)
B(3,36,0,minecraft:basalt)
B(3,37,0,minecraft:basalt)
B(3,38,0,minecraft:basalt)
B(3,39,0,minecraft:basalt)
B(3,40,0,minecraft:basalt)
B(3,41,0,minecraft:basalt)
B(3,42,0,minecraft:basalt)
B(3,43,0,minecraft:basalt)
B(3,44,0,minecraft:basalt)
B(3,45,0,minecraft:basalt)
B(3,46,0,minecraft:basalt)
B(3,47,0,minecraft:basalt)
B(3,48,0,minecraft:basalt)
B(3,49,0,minecraft:basalt)
B(3,50,0,minecraft:basalt)
B(3,51,0,minecraft:basalt)
B(3,52,0,minecraft:basalt)
B(3,53,0,minecraft:basalt)
B(3,54,0,minecraft:basalt)
B(3,55,0,minecraft:basalt)
B(3,56,0,minecraft:basalt)
B(3,57,0,minecraft:basalt)
B(3,58,0,minecraft:basalt)
B(3,59,0,minecraft:basalt)
B(3,60,0,minecraft:basalt)
B(3,61,0,minecraft:basalt)
B(3,62,0,minecraft:basalt)
B(3,63,0,minecraft:basalt)
B(3,64,0,minecraft:basalt)
B(3,65,0,minecraft:basalt)
B(3,66,0,minecraft:basalt)
B(3,29,1,minecraft:basalt)
B(3,30,1,minecraft:basalt)
B(3,31,1,minecraft:basalt)
B(3,32,1,minecraft:basalt)
B(3,33,1,minecraft:basalt)
B(3,34,1,minecraft:basalt)
B(3,35,1,minecraft:basalt)
B(3,36,1,minecraft:basalt)
B(3,37,1,minecraft:basalt)
B(3,38,1,minecraft:basalt)
B(3,39,1,minecraft:basalt)
B(3,40,1,minecraft:basalt)
B(3,41,1,minecraft:basalt)
B(3,42,1,minecraft:basalt)
B(3,43,1,minecraft:basalt)
B(3,44,1,minecraft:basalt)
B(3,45,1,minecraft:basalt)
B(3,46,1,minecraft:basalt)
B(3,47,1,minecraft:basalt)
B(3,48,1,minecraft:basalt)
B(3,49,1,minecraft:basalt)
B(3,50,1,minecraft:basalt)
B(3,51,1,minecraft:basalt)
B(3,52,1,minecraft:basalt)
B(3,53,1,minecraft:basalt)
B(3,54,1,minecraft:basalt)
B(3,55,1,minecraft:basalt)
B(3,56,1,minecraft:basalt)
B(3,57,1,minecraft:basalt)
B(3,58,1,minecraft:basalt)
B(3,59,1,minecraft:basalt)
B(3,60,1,minecraft:basalt)
B(3,61,1,minecraft:basalt)
B(3,62,1,minecraft:basalt)
B(3,63,1,minecraft:basalt)
B(3,64,1,minecraft:basalt)
B(3,65,1,minecraft:basalt)
B(3,66,1,minecraft:basalt)
B(3,40,2,minecraft:basalt)
B(3,41,2,minecraft:basalt)
B(3,42,2,minecraft:basalt)
B(3,43,2,minecraft:basalt)
B(3,44,2,minecraft:basalt)
B(3,45,2,minecraft:basalt)
B(3,46,2,minecraft:basalt)
B(3,47,2,minecraft:basalt)
B(3,48,2,minecraft:basalt)
B(3,49,2,minecraft:basalt)
B(3,50,2,minecraft:basalt)
B(3,51,2,minecraft:basalt)
B(3,52,2,minecraft:basalt)
B(3,53,2,minecraft:basalt)
B(3,54,2,minecraft:basalt)
B(3,55,2,minecraft:basalt)
B(3,56,2,minecraft:basalt)
B(3,57,2,minecraft:basalt)
B(3,58,2,minecraft:basalt)
B(3,59,2,minecraft:basalt)
B(3,60,2,minecraft:basalt)
B(3,61,2,minecraft:basalt)
B(3,62,2,minecraft:basalt)
B(3,63,2,minecraft:basalt)
B(3,64,2,minecraft:basalt)
B(3,65,2,minecraft:basalt)
B(3,66,2,minecraft:basalt)
B(3,42,3,minecraft:basalt)
B(3,43,3,minecraft:basalt)
B(3,44,3,minecraft:basalt)
B(3,45,3,minecraft:basalt)
B(3,46,3,minecraft:basalt)
B(3,47,3,minecraft:basalt)
B(3,48,3,minecraft:basalt)
B(3,49,3,minecraft:basalt)
B(3,50,3,minecraft:basalt)
B(3,51,3,minecraft:basalt)
B(3,52,3,minecraft:basalt)
B(3,53,3,minecraft:basalt)
B(3,54,3,minecraft:basalt)
B(3,55,3,minecraft:basalt)
B(3,56,3,minecraft:basalt)
B(3,57,3,minecraft:basalt)
B(3,58,3,minecraft:basalt)
B(3,59,3,minecraft:basalt)
B(3,60,3,minecraft:basalt)
B(3,61,3,minecraft:basalt)
B(3,62,3,minecraft:basalt)
B(3,63,3,minecraft:basalt)
B(3,64,3,minecraft:basalt)
B(3,65,3,minecraft:basalt)
B(3,66,3,minecraft:basalt)
B(3,46,4,minecraft:basalt)
B(3,47,4,minecraft:basalt)
B(3,48,4,minecraft:basalt)
B(3,49,4,minecraft:basalt)
B(3,50,4,minecraft:basalt)
B(3,51,4,minecraft:basalt)
B(3,52,4,minecraft:basalt)
B(3,53,4,minecraft:basalt)
B(3,54,4,minecraft:basalt)
B(3,55,4,minecraft:basalt)
B(3,56,4,minecraft:basalt)
B(3,57,4,minecraft:basalt)
B(3,58,4,minecraft:basalt)
B(3,59,4,minecraft:basalt)
B(3,60,4,minecraft:basalt)
B(3,61,4,minecraft:basalt)
B(3,62,4,minecraft:basalt)
B(3,63,4,minecraft:basalt)
B(3,64,4,minecraft:basalt)
B(3,65,4,minecraft:basalt)
B(3,66,4,minecraft:basalt)
B(3,56,5,minecraft:basalt)
B(3,57,5,minecraft:basalt)
B(3,58,5,minecraft:basalt)
B(3,59,5,minecraft:basalt)
B(3,60,5,minecraft:basalt)
B(3,61,5,minecraft:basalt)
B(3,62,5,minecraft:basalt)
B(3,63,5,minecraft:basalt)
B(3,64,5,minecraft:basalt)
B(3,65,5,minecraft:basalt)
B(3,66,5,minecraft:basalt)
B(3,56,6,minecraft:basalt)
B(3,57,6,minecraft:basalt)
B(3,58,6,minecraft:basalt)
B(3,59,6,minecraft:basalt)
B(3,60,6,minecraft:basalt)
B(3,61,6,minecraft:basalt)
B(3,62,6,minecraft:basalt)
B(3,63,6,minecraft:basalt)
B(3,64,6,minecraft:basalt)
B(3,65,6,minecraft:basalt)
B(3,66,6,minecraft:basalt)
B(3,56,7,minecraft:basalt)
B(3,57,7,minecraft:basalt)
B(3,58,7,minecraft:basalt)
B(3,59,7,minecraft:basalt)
B(3,60,7,minecraft:basalt)
B(3,61,7,minecraft:basalt)
B(3,62,7,minecraft:basalt)
B(3,63,7,minecraft:basalt)
B(3,64,7,minecraft:basalt)
B(3,65,7,minecraft:basalt)
B(3,66,7,minecraft:basalt)
B(3,56,8,minecraft:basalt)
B(3,57,8,minecraft:basalt)
B(3,58,8,minecraft:basalt)
B(3,59,8,minecraft:basalt)
B(3,60,8,minecraft:basalt)
B(3,61,8,minecraft:basalt)
B(3,62,8,minecraft:basalt)
B(3,63,8,minecraft:basalt)
B(3,64,8,minecraft:basalt)
B(3,65,8,minecraft:basalt)
B(3,66,8,minecraft:basalt)
B(4,19,-7,minecraft:basalt)
B(4,20,-7,minecraft:basalt)
B(4,21,-7,minecraft:basalt)
B(4,22,-7,minecraft:basalt)
B(4,23,-7,minecraft:basalt)
B(4,24,-7,minecraft:basalt)
B(4,25,-7,minecraft:basalt)
B(4,26,-7,minecraft:basalt)
B(4,27,-7,minecraft:basalt)
B(4,28,-7,minecraft:basalt)
B(4,29,-7,minecraft:basalt)
B(4,30,-7,minecraft:basalt)
B(4,31,-7,minecraft:basalt)
B(4,32,-7,minecraft:basalt)
B(4,33,-7,minecraft:basalt)
B(4,34,-7,minecraft:basalt)
B(4,35,-7,minecraft:basalt)
B(4,36,-7,minecraft:basalt)
B(4,37,-7,minecraft:basalt)
B(4,38,-7,minecraft:basalt)
B(4,39,-7,minecraft:basalt)
B(4,40,-7,minecraft:basalt)
B(4,41,-7,minecraft:basalt)
B(4,42,-7,minecraft:basalt)
B(4,43,-7,minecraft:basalt)
B(4,44,-7,minecraft:basalt)
B(4,45,-7,minecraft:basalt)
B(4,46,-7,minecraft:basalt)
B(4,47,-7,minecraft:basalt)
B(4,48,-7,minecraft:basalt)
B(4,49,-7,minecraft:basalt)
B(4,50,-7,minecraft:basalt)
B(4,51,-7,minecraft:basalt)
B(4,52,-7,minecraft:basalt)
B(4,53,-7,minecraft:basalt)
B(4,54,-7,minecraft:basalt)
B(4,55,-7,minecraft:basalt)
B(4,56,-7,minecraft:basalt)
B(4,57,-7,minecraft:basalt)
B(4,58,-7,minecraft:basalt)
B(4,59,-7,minecraft:basalt)
B(4,60,-7,minecraft:basalt)
B(4,61,-7,minecraft:basalt)
B(4,62,-7,minecraft:basalt)
B(4,63,-7,minecraft:basalt)
B(4,64,-7,minecraft:basalt)
B(4,65,-7,minecraft:basalt)
B(4,66,-7,minecraft:basalt)
B(4,17,-6,minecraft:basalt)
B(4,18,-6,minecraft:basalt)
B(4,19,-6,minecraft:basalt)
B(4,20,-6,minecraft:basalt)
B(4,21,-6,minecraft:basalt)
B(4,22,-6,minecraft:basalt)
B(4,23,-6,minecraft:basalt)
B(4,24,-6,minecraft:basalt)
B(4,25,-6,minecraft:basalt)
B(4,26,-6,minecraft:basalt)
B(4,27,-6,minecraft:basalt)
B(4,28,-6,minecraft:basalt)
B(4,29,-6,minecraft:basalt)
B(4,30,-6,minecraft:basalt)
B(4,31,-6,minecraft:basalt)
B(4,32,-6,minecraft:basalt)
B(4,33,-6,minecraft:basalt)
B(4,34,-6,minecraft:basalt)
B(4,35,-6,minecraft:basalt)
B(4,36,-6,minecraft:basalt)
B(4,37,-6,minecraft:basalt)
B(4,38,-6,minecraft:basalt)
B(4,39,-6,minecraft:basalt)
B(4,40,-6,minecraft:basalt)
B(4,41,-6,minecraft:basalt)
B(4,42,-6,minecraft:basalt)
B(4,43,-6,minecraft:basalt)
B(4,44,-6,minecraft:basalt)
B(4,45,-6,minecraft:basalt)
B(4,46,-6,minecraft:basalt)
B(4,47,-6,minecraft:basalt)
B(4,48,-6,minecraft:basalt)
B(4,49,-6,minecraft:basalt)
B(4,50,-6,minecraft:basalt)
B(4,51,-6,minecraft:basalt)
B(4,52,-6,minecraft:basalt)
B(4,53,-6,minecraft:basalt)
B(4,54,-6,minecraft:basalt)
B(4,55,-6,minecraft:basalt)
B(4,56,-6,minecraft:basalt)
B(4,57,-6,minecraft:basalt)
B(4,58,-6,minecraft:basalt)
B(4,59,-6,minecraft:basalt)
B(4,60,-6,minecraft:basalt)
B(4,61,-6,minecraft:basalt)
B(4,62,-6,minecraft:basalt)
B(4,63,-6,minecraft:basalt)
B(4,64,-6,minecraft:basalt)
B(4,65,-6,minecraft:basalt)
B(4,66,-6,minecraft:basalt)
B(4,16,-5,minecraft:basalt)
B(4,17,-5,minecraft:basalt)
B(4,18,-5,minecraft:basalt)
B(4,19,-5,minecraft:basalt)
B(4,20,-5,minecraft:basalt)
B(4,21,-5,minecraft:basalt)
B(4,22,-5,minecraft:basalt)
B(4,23,-5,minecraft:basalt)
B(4,24,-5,minecraft:basalt)
B(4,25,-5,minecraft:basalt)
B(4,26,-5,minecraft:basalt)
B(4,27,-5,minecraft:basalt)
B(4,28,-5,minecraft:basalt)
B(4,29,-5,minecraft:basalt)
B(4,30,-5,minecraft:basalt)
B(4,31,-5,minecraft:basalt)
B(4,32,-5,minecraft:basalt)
B(4,33,-5,minecraft:basalt)
B(4,34,-5,minecraft:basalt)
B(4,35,-5,minecraft:basalt)
B(4,36,-5,minecraft:basalt)
B(4,37,-5,minecraft:basalt)
B(4,38,-5,minecraft:basalt)
B(4,39,-5,minecraft:basalt)
B(4,40,-5,minecraft:basalt)
B(4,41,-5,minecraft:basalt)
B(4,42,-5,minecraft:basalt)
B(4,43,-5,minecraft:basalt)
B(4,44,-5,minecraft:basalt)
B(4,45,-5,minecraft:basalt)
B(4,46,-5,minecraft:basalt)
B(4,47,-5,minecraft:basalt)
B(4,48,-5,minecraft:basalt)
B(4,49,-5,minecraft:basalt)
B(4,50,-5,minecraft:basalt)
B(4,51,-5,minecraft:basalt)
B(4,52,-5,minecraft:basalt)
B(4,53,-5,minecraft:basalt)
B(4,54,-5,minecraft:basalt)
B(4,55,-5,minecraft:basalt)
B(4,56,-5,minecraft:basalt)
B(4,57,-5,minecraft:basalt)
B(4,58,-5,minecraft:basalt)
B(4,59,-5,minecraft:basalt)
B(4,60,-5,minecraft:basalt)
B(4,61,-5,minecraft:basalt)
B(4,62,-5,minecraft:basalt)
B(4,63,-5,minecraft:basalt)
B(4,64,-5,minecraft:basalt)
B(4,65,-5,minecraft:basalt)
B(4,66,-5,minecraft:basalt)
B(4,16,-4,minecraft:basalt)
B(4,17,-4,minecraft:basalt)
B(4,18,-4,minecraft:basalt)
B(4,19,-4,minecraft:basalt)
B(4,20,-4,minecraft:basalt)
B(4,21,-4,minecraft:basalt)
B(4,22,-4,minecraft:basalt)
B(4,23,-4,minecraft:basalt)
B(4,24,-4,minecraft:basalt)
