
#######################################################################
# +-----------------------------------------------------------------+ #
# |                            BO4 object                           | #
# +-----------------------------------------------------------------+ #
#######################################################################

Author: Unknown

Description: No description given

SettingsMode: WriteWithoutComments


#######################################################################
# +-----------------------------------------------------------------+ #
# |                          Main settings                          | #
# +-----------------------------------------------------------------+ #
#######################################################################

FixedRotation: 

Frequency: 0

SpawnHeight: highestBlock

UseCenterForHighestBlock: true

##############################
# Height Limits for the BO4. #
##############################

MinHeight: 0

MaxHeight: 255

InheritBO3: 

InheritBO3Rotation: NORTH

OverrideChildSettings: true

OverrideParentHeight: false

CanOverride: false

BranchFrequency: 0

BranchFrequencyGroup: 

MustBeBelowOther: false

MustBeInside: 

CannotBeInside: 

ReplacesBO3: 

MustBeInsideWorldBorders: false

CanSpawnOnWater: true

SpawnOnWaterOnly: false

SpawnUnderWater: false

SpawnAtWaterLevel: false

HeightOffset: 0

RemoveAir: true

ReplaceAbove: 

ReplaceBelow: 

ReplaceWithBiomeBlocks: true

ReplaceWithSurfaceBlock: GRASS

ReplaceWithGroundBlock: DIRT

ReplaceWithStoneBlock: STONE

SmoothRadius: 0

SmoothHeightOffset: 0

SmoothStartTop: false

SmoothStartWood: false

SmoothingSurfaceBlock: 

SmoothingGroundBlock: 

BO3Group: 

IsSpawnPoint: false

DoReplaceBlocks: true


#######################################################################
# +-----------------------------------------------------------------+ #
# |                              Blocks                             | #
# +-----------------------------------------------------------------+ #
#######################################################################

B(-8,0,-7,minecraft:netherrack)
B(-8,1,-7,minecraft:netherrack)
B(-8,2,-7,minecraft:netherrack)
B(-8,3,-7,minecraft:netherrack)
B(-8,4,-7,minecraft:netherrack)
B(-8,5,-7,minecraft:netherrack)
B(-8,6,-7,minecraft:netherrack)
B(-8,7,-7,minecraft:netherrack)
B(-8,8,-7,minecraft:netherrack)
B(-8,9,-7,minecraft:netherrack)
B(-8,10,-7,minecraft:netherrack)
B(-8,11,-7,minecraft:netherrack)
B(-8,12,-7,minecraft:netherrack)
B(-8,13,-7,minecraft:netherrack)
B(-8,14,-7,minecraft:netherrack)
B(-8,15,-7,minecraft:netherrack)
B(-8,16,-7,minecraft:netherrack)
B(-8,17,-7,minecraft:netherrack)
B(-8,18,-7,minecraft:netherrack)
B(-8,19,-7,minecraft:netherrack)
B(-8,20,-7,minecraft:netherrack)
B(-8,21,-7,minecraft:netherrack)
B(-8,22,-7,minecraft:netherrack)
B(-8,23,-7,minecraft:netherrack)
B(-8,24,-7,minecraft:netherrack)
B(-8,25,-7,minecraft:netherrack)
B(-8,26,-7,minecraft:netherrack)
B(-8,27,-7,minecraft:netherrack)
B(-8,28,-7,minecraft:netherrack)
B(-8,29,-7,minecraft:netherrack)
B(-8,30,-7,minecraft:netherrack)
B(-8,31,-7,minecraft:netherrack)
B(-8,32,-7,minecraft:netherrack)
B(-8,33,-7,minecraft:netherrack)
B(-8,0,-6,minecraft:netherrack)
B(-8,1,-6,minecraft:netherrack)
B(-8,2,-6,minecraft:netherrack)
B(-8,3,-6,minecraft:netherrack)
B(-8,4,-6,minecraft:netherrack)
B(-8,5,-6,minecraft:netherrack)
B(-8,6,-6,minecraft:netherrack)
B(-8,7,-6,minecraft:netherrack)
B(-8,8,-6,minecraft:netherrack)
B(-8,9,-6,minecraft:netherrack)
B(-8,10,-6,minecraft:netherrack)
B(-8,11,-6,minecraft:netherrack)
B(-8,12,-6,minecraft:netherrack)
B(-8,13,-6,minecraft:netherrack)
B(-8,14,-6,minecraft:netherrack)
B(-8,15,-6,minecraft:netherrack)
B(-8,16,-6,minecraft:netherrack)
B(-8,17,-6,minecraft:netherrack)
B(-8,18,-6,minecraft:netherrack)
B(-8,19,-6,minecraft:netherrack)
B(-8,20,-6,minecraft:netherrack)
B(-8,21,-6,minecraft:netherrack)
B(-8,22,-6,minecraft:netherrack)
B(-8,23,-6,minecraft:netherrack)
B(-8,24,-6,minecraft:netherrack)
B(-8,25,-6,minecraft:netherrack)
B(-8,26,-6,minecraft:netherrack)
B(-8,27,-6,minecraft:netherrack)
B(-8,28,-6,minecraft:netherrack)
B(-8,29,-6,minecraft:netherrack)
B(-8,30,-6,minecraft:netherrack)
B(-8,31,-6,minecraft:netherrack)
B(-8,32,-6,minecraft:netherrack)
B(-8,33,-6,minecraft:netherrack)
B(-8,0,-5,minecraft:netherrack)
B(-8,1,-5,minecraft:netherrack)
B(-8,2,-5,minecraft:netherrack)
B(-8,3,-5,minecraft:netherrack)
B(-8,4,-5,minecraft:netherrack)
B(-8,5,-5,minecraft:netherrack)
B(-8,6,-5,minecraft:netherrack)
B(-8,7,-5,minecraft:netherrack)
B(-8,8,-5,minecraft:netherrack)
B(-8,9,-5,minecraft:netherrack)
B(-8,10,-5,minecraft:netherrack)
B(-8,11,-5,minecraft:netherrack)
B(-8,12,-5,minecraft:netherrack)
B(-8,13,-5,minecraft:netherrack)
B(-8,14,-5,minecraft:netherrack)
B(-8,15,-5,minecraft:netherrack)
B(-8,16,-5,minecraft:netherrack)
B(-8,17,-5,minecraft:netherrack)
B(-8,18,-5,minecraft:netherrack)
B(-8,19,-5,minecraft:netherrack)
B(-8,20,-5,minecraft:netherrack)
B(-8,21,-5,minecraft:netherrack)
B(-8,22,-5,minecraft:netherrack)
B(-8,23,-5,minecraft:netherrack)
B(-8,24,-5,minecraft:netherrack)
B(-8,25,-5,minecraft:netherrack)
B(-8,26,-5,minecraft:netherrack)
B(-8,27,-5,minecraft:netherrack)
B(-8,28,-5,minecraft:netherrack)
B(-8,29,-5,minecraft:netherrack)
B(-8,30,-5,minecraft:netherrack)
B(-8,31,-5,minecraft:netherrack)
B(-8,32,-5,minecraft:netherrack)
B(-8,33,-5,minecraft:netherrack)
B(-8,34,-5,minecraft:netherrack)
B(-8,35,-5,minecraft:netherrack)
B(-8,0,-4,minecraft:netherrack)
B(-8,1,-4,minecraft:netherrack)
B(-8,2,-4,minecraft:netherrack)
B(-8,3,-4,minecraft:netherrack)
B(-8,4,-4,minecraft:netherrack)
B(-8,5,-4,minecraft:netherrack)
B(-8,6,-4,minecraft:netherrack)
B(-8,7,-4,minecraft:netherrack)
B(-8,8,-4,minecraft:netherrack)
B(-8,9,-4,minecraft:netherrack)
B(-8,10,-4,minecraft:netherrack)
B(-8,11,-4,minecraft:netherrack)
B(-8,12,-4,minecraft:netherrack)
B(-8,13,-4,minecraft:netherrack)
B(-8,14,-4,minecraft:netherrack)
B(-8,15,-4,minecraft:netherrack)
B(-8,16,-4,minecraft:netherrack)
B(-8,17,-4,minecraft:netherrack)
B(-8,18,-4,minecraft:netherrack)
B(-8,19,-4,minecraft:netherrack)
B(-8,20,-4,minecraft:netherrack)
B(-8,21,-4,minecraft:netherrack)
B(-8,22,-4,minecraft:netherrack)
B(-8,23,-4,minecraft:netherrack)
B(-8,24,-4,minecraft:netherrack)
B(-8,25,-4,minecraft:netherrack)
B(-8,26,-4,minecraft:netherrack)
B(-8,27,-4,minecraft:netherrack)
B(-8,28,-4,minecraft:netherrack)
B(-8,29,-4,minecraft:netherrack)
B(-8,30,-4,minecraft:netherrack)
B(-8,31,-4,minecraft:netherrack)
B(-8,32,-4,minecraft:netherrack)
B(-8,33,-4,minecraft:netherrack)
B(-8,34,-4,minecraft:netherrack)
B(-8,35,-4,minecraft:netherrack)
B(-8,36,-4,minecraft:netherrack)
B(-8,0,-3,minecraft:netherrack)
B(-8,1,-3,minecraft:netherrack)
B(-8,2,-3,minecraft:netherrack)
B(-8,3,-3,minecraft:netherrack)
B(-8,4,-3,minecraft:netherrack)
B(-8,5,-3,minecraft:netherrack)
B(-8,6,-3,minecraft:netherrack)
B(-8,7,-3,minecraft:netherrack)
B(-8,8,-3,minecraft:netherrack)
B(-8,9,-3,minecraft:netherrack)
B(-8,10,-3,minecraft:netherrack)
B(-8,11,-3,minecraft:netherrack)
B(-8,12,-3,minecraft:netherrack)
B(-8,13,-3,minecraft:netherrack)
B(-8,14,-3,minecraft:netherrack)
B(-8,15,-3,minecraft:netherrack)
B(-8,16,-3,minecraft:netherrack)
B(-8,17,-3,minecraft:netherrack)
B(-8,18,-3,minecraft:netherrack)
B(-8,19,-3,minecraft:netherrack)
B(-8,20,-3,minecraft:netherrack)
B(-8,21,-3,minecraft:netherrack)
B(-8,22,-3,minecraft:netherrack)
B(-8,23,-3,minecraft:netherrack)
B(-8,24,-3,minecraft:netherrack)
B(-8,25,-3,minecraft:netherrack)
B(-8,26,-3,minecraft:netherrack)
B(-8,27,-3,minecraft:netherrack)
B(-8,28,-3,minecraft:netherrack)
B(-8,29,-3,minecraft:netherrack)
B(-8,30,-3,minecraft:netherrack)
B(-8,31,-3,minecraft:netherrack)
B(-8,32,-3,minecraft:netherrack)
B(-8,33,-3,minecraft:netherrack)
B(-8,34,-3,minecraft:netherrack)
B(-8,35,-3,minecraft:netherrack)
B(-8,36,-3,minecraft:netherrack)
B(-8,0,-2,minecraft:netherrack)
B(-8,1,-2,minecraft:netherrack)
B(-8,2,-2,minecraft:netherrack)
B(-8,3,-2,minecraft:netherrack)
B(-8,4,-2,minecraft:netherrack)
B(-8,5,-2,minecraft:netherrack)
B(-8,6,-2,minecraft:netherrack)
B(-8,7,-2,minecraft:netherrack)
B(-8,8,-2,minecraft:netherrack)
B(-8,9,-2,minecraft:netherrack)
B(-8,10,-2,minecraft:netherrack)
B(-8,11,-2,minecraft:netherrack)
B(-8,12,-2,minecraft:netherrack)
B(-8,13,-2,minecraft:netherrack)
B(-8,14,-2,minecraft:netherrack)
B(-8,15,-2,minecraft:netherrack)
B(-8,16,-2,minecraft:netherrack)
B(-8,17,-2,minecraft:netherrack)
B(-8,18,-2,minecraft:netherrack)
B(-8,19,-2,minecraft:netherrack)
B(-8,20,-2,minecraft:netherrack)
B(-8,21,-2,minecraft:netherrack)
B(-8,22,-2,minecraft:netherrack)
B(-8,23,-2,minecraft:netherrack)
B(-8,24,-2,minecraft:netherrack)
B(-8,25,-2,minecraft:netherrack)
B(-8,26,-2,minecraft:netherrack)
B(-8,27,-2,minecraft:netherrack)
B(-8,28,-2,minecraft:netherrack)
B(-8,29,-2,minecraft:netherrack)
B(-8,30,-2,minecraft:netherrack)
B(-8,31,-2,minecraft:netherrack)
B(-8,32,-2,minecraft:netherrack)
B(-8,33,-2,minecraft:netherrack)
B(-8,34,-2,minecraft:netherrack)
B(-8,35,-2,minecraft:lava)
B(-8,0,-1,minecraft:netherrack)
B(-8,1,-1,minecraft:netherrack)
B(-8,2,-1,minecraft:netherrack)
B(-8,3,-1,minecraft:netherrack)
B(-8,4,-1,minecraft:netherrack)
B(-8,5,-1,minecraft:netherrack)
B(-8,6,-1,minecraft:netherrack)
B(-8,7,-1,minecraft:netherrack)
B(-8,8,-1,minecraft:netherrack)
B(-8,9,-1,minecraft:netherrack)
B(-8,10,-1,minecraft:netherrack)
B(-8,11,-1,minecraft:netherrack)
B(-8,12,-1,minecraft:netherrack)
B(-8,13,-1,minecraft:netherrack)
B(-8,14,-1,minecraft:netherrack)
B(-8,15,-1,minecraft:netherrack)
B(-8,16,-1,minecraft:netherrack)
B(-8,17,-1,minecraft:netherrack)
B(-8,18,-1,minecraft:netherrack)
B(-8,19,-1,minecraft:netherrack)
B(-8,20,-1,minecraft:netherrack)
B(-8,21,-1,minecraft:netherrack)
B(-8,22,-1,minecraft:netherrack)
B(-8,23,-1,minecraft:netherrack)
B(-8,24,-1,minecraft:netherrack)
B(-8,25,-1,minecraft:netherrack)
B(-8,26,-1,minecraft:netherrack)
B(-8,27,-1,minecraft:netherrack)
B(-8,28,-1,minecraft:netherrack)
B(-8,29,-1,minecraft:netherrack)
B(-8,30,-1,minecraft:netherrack)
B(-8,31,-1,minecraft:netherrack)
B(-8,32,-1,minecraft:netherrack)
B(-8,33,-1,minecraft:netherrack)
B(-8,34,-1,minecraft:lava)
B(-8,35,-1,minecraft:lava)
B(-8,0,0,minecraft:netherrack)
B(-8,1,0,minecraft:netherrack)
B(-8,2,0,minecraft:netherrack)
B(-8,3,0,minecraft:netherrack)
B(-8,4,0,minecraft:netherrack)
B(-8,5,0,minecraft:netherrack)
B(-8,6,0,minecraft:netherrack)
B(-8,7,0,minecraft:netherrack)
B(-8,8,0,minecraft:netherrack)
B(-8,9,0,minecraft:netherrack)
B(-8,10,0,minecraft:netherrack)
B(-8,11,0,minecraft:netherrack)
B(-8,12,0,minecraft:netherrack)
B(-8,13,0,minecraft:netherrack)
B(-8,14,0,minecraft:netherrack)
B(-8,15,0,minecraft:netherrack)
B(-8,16,0,minecraft:netherrack)
B(-8,17,0,minecraft:netherrack)
B(-8,18,0,minecraft:netherrack)
B(-8,19,0,minecraft:netherrack)
B(-8,20,0,minecraft:netherrack)
B(-8,21,0,minecraft:netherrack)
B(-8,22,0,minecraft:netherrack)
B(-8,23,0,minecraft:netherrack)
B(-8,24,0,minecraft:netherrack)
B(-8,25,0,minecraft:netherrack)
B(-8,26,0,minecraft:netherrack)
B(-8,27,0,minecraft:netherrack)
B(-8,28,0,minecraft:netherrack)
B(-8,29,0,minecraft:netherrack)
B(-8,30,0,minecraft:netherrack)
B(-8,31,0,minecraft:netherrack)
B(-8,32,0,minecraft:netherrack)
B(-8,33,0,minecraft:lava)
B(-8,34,0,minecraft:lava)
B(-8,35,0,minecraft:lava)
B(-8,0,1,minecraft:netherrack)
B(-8,1,1,minecraft:netherrack)
B(-8,2,1,minecraft:netherrack)
B(-8,3,1,minecraft:netherrack)
B(-8,4,1,minecraft:netherrack)
B(-8,5,1,minecraft:netherrack)
B(-8,6,1,minecraft:netherrack)
B(-8,7,1,minecraft:netherrack)
B(-8,8,1,minecraft:netherrack)
B(-8,9,1,minecraft:netherrack)
B(-8,10,1,minecraft:netherrack)
B(-8,11,1,minecraft:netherrack)
B(-8,12,1,minecraft:netherrack)
B(-8,13,1,minecraft:netherrack)
B(-8,14,1,minecraft:netherrack)
B(-8,15,1,minecraft:netherrack)
B(-8,16,1,minecraft:netherrack)
B(-8,17,1,minecraft:netherrack)
B(-8,18,1,minecraft:netherrack)
B(-8,19,1,minecraft:netherrack)
B(-8,20,1,minecraft:netherrack)
B(-8,21,1,minecraft:netherrack)
B(-8,22,1,minecraft:netherrack)
B(-8,23,1,minecraft:netherrack)
B(-8,24,1,minecraft:netherrack)
B(-8,25,1,minecraft:netherrack)
B(-8,26,1,minecraft:netherrack)
B(-8,27,1,minecraft:netherrack)
B(-8,28,1,minecraft:netherrack)
B(-8,29,1,minecraft:netherrack)
B(-8,30,1,minecraft:netherrack)
B(-8,31,1,minecraft:netherrack)
B(-8,32,1,minecraft:lava)
B(-8,33,1,minecraft:lava)
B(-8,34,1,minecraft:lava)
B(-8,35,1,minecraft:lava)
B(-8,0,2,minecraft:netherrack)
B(-8,1,2,minecraft:netherrack)
B(-8,2,2,minecraft:netherrack)
B(-8,3,2,minecraft:netherrack)
B(-8,4,2,minecraft:netherrack)
B(-8,5,2,minecraft:netherrack)
B(-8,6,2,minecraft:netherrack)
B(-8,7,2,minecraft:netherrack)
B(-8,8,2,minecraft:netherrack)
B(-8,9,2,minecraft:netherrack)
B(-8,10,2,minecraft:netherrack)
B(-8,11,2,minecraft:netherrack)
B(-8,12,2,minecraft:netherrack)
B(-8,13,2,minecraft:netherrack)
B(-8,14,2,minecraft:netherrack)
B(-8,15,2,minecraft:netherrack)
B(-8,16,2,minecraft:netherrack)
B(-8,17,2,minecraft:netherrack)
B(-8,18,2,minecraft:netherrack)
B(-8,19,2,minecraft:netherrack)
B(-8,20,2,minecraft:netherrack)
B(-8,21,2,minecraft:netherrack)
B(-8,22,2,minecraft:netherrack)
B(-8,23,2,minecraft:netherrack)
B(-8,24,2,minecraft:netherrack)
B(-8,25,2,minecraft:netherrack)
B(-8,26,2,minecraft:netherrack)
B(-8,27,2,minecraft:netherrack)
B(-8,28,2,minecraft:netherrack)
B(-8,29,2,minecraft:netherrack)
B(-8,30,2,minecraft:netherrack)
B(-8,31,2,minecraft:lava)
B(-8,32,2,minecraft:lava)
B(-8,33,2,minecraft:lava)
B(-8,34,2,minecraft:lava)
B(-8,35,2,minecraft:lava)
B(-8,0,3,minecraft:netherrack)
B(-8,1,3,minecraft:netherrack)
B(-8,2,3,minecraft:netherrack)
B(-8,3,3,minecraft:netherrack)
B(-8,4,3,minecraft:netherrack)
B(-8,5,3,minecraft:netherrack)
B(-8,6,3,minecraft:netherrack)
B(-8,7,3,minecraft:netherrack)
B(-8,8,3,minecraft:netherrack)
B(-8,9,3,minecraft:netherrack)
B(-8,10,3,minecraft:netherrack)
B(-8,11,3,minecraft:netherrack)
B(-8,12,3,minecraft:netherrack)
B(-8,13,3,minecraft:netherrack)
B(-8,14,3,minecraft:netherrack)
B(-8,15,3,minecraft:netherrack)
B(-8,16,3,minecraft:netherrack)
B(-8,17,3,minecraft:netherrack)
B(-8,18,3,minecraft:netherrack)
B(-8,19,3,minecraft:netherrack)
B(-8,20,3,minecraft:netherrack)
B(-8,21,3,minecraft:netherrack)
B(-8,22,3,minecraft:netherrack)
B(-8,23,3,minecraft:netherrack)
B(-8,24,3,minecraft:netherrack)
B(-8,25,3,minecraft:netherrack)
B(-8,26,3,minecraft:netherrack)
B(-8,27,3,minecraft:netherrack)
B(-8,28,3,minecraft:netherrack)
B(-8,29,3,minecraft:netherrack)
B(-8,30,3,minecraft:lava)
B(-8,31,3,minecraft:lava)
B(-8,32,3,minecraft:lava)
B(-8,33,3,minecraft:lava)
B(-8,34,3,minecraft:lava)
B(-8,35,3,minecraft:lava)
B(-8,0,4,minecraft:netherrack)
B(-8,1,4,minecraft:netherrack)
B(-8,2,4,minecraft:netherrack)
B(-8,3,4,minecraft:netherrack)
B(-8,4,4,minecraft:netherrack)
B(-8,5,4,minecraft:netherrack)
B(-8,6,4,minecraft:netherrack)
B(-8,7,4,minecraft:netherrack)
B(-8,8,4,minecraft:netherrack)
B(-8,9,4,minecraft:netherrack)
B(-8,10,4,minecraft:netherrack)
B(-8,11,4,minecraft:netherrack)
B(-8,12,4,minecraft:netherrack)
B(-8,13,4,minecraft:netherrack)
B(-8,14,4,minecraft:netherrack)
B(-8,15,4,minecraft:netherrack)
B(-8,16,4,minecraft:netherrack)
B(-8,17,4,minecraft:netherrack)
B(-8,18,4,minecraft:netherrack)
B(-8,19,4,minecraft:netherrack)
B(-8,20,4,minecraft:netherrack)
B(-8,21,4,minecraft:netherrack)
B(-8,22,4,minecraft:netherrack)
B(-8,23,4,minecraft:netherrack)
B(-8,24,4,minecraft:netherrack)
B(-8,25,4,minecraft:netherrack)
B(-8,26,4,minecraft:netherrack)
B(-8,27,4,minecraft:netherrack)
B(-8,28,4,minecraft:netherrack)
B(-8,29,4,minecraft:lava)
B(-8,30,4,minecraft:lava)
B(-8,31,4,minecraft:lava)
B(-8,32,4,minecraft:lava)
B(-8,33,4,minecraft:lava)
B(-8,34,4,minecraft:lava)
B(-8,35,4,minecraft:lava)
B(-8,0,5,minecraft:netherrack)
B(-8,1,5,minecraft:netherrack)
B(-8,2,5,minecraft:netherrack)
B(-8,3,5,minecraft:netherrack)
B(-8,4,5,minecraft:netherrack)
B(-8,5,5,minecraft:netherrack)
B(-8,6,5,minecraft:netherrack)
B(-8,7,5,minecraft:netherrack)
B(-8,8,5,minecraft:netherrack)
B(-8,9,5,minecraft:netherrack)
B(-8,10,5,minecraft:netherrack)
B(-8,11,5,minecraft:netherrack)
B(-8,12,5,minecraft:netherrack)
B(-8,13,5,minecraft:netherrack)
B(-8,14,5,minecraft:netherrack)
B(-8,15,5,minecraft:netherrack)
B(-8,16,5,minecraft:netherrack)
B(-8,17,5,minecraft:netherrack)
B(-8,18,5,minecraft:netherrack)
B(-8,19,5,minecraft:netherrack)
B(-8,20,5,minecraft:netherrack)
B(-8,21,5,minecraft:netherrack)
B(-8,22,5,minecraft:netherrack)
B(-8,23,5,minecraft:netherrack)
B(-8,24,5,minecraft:netherrack)
B(-8,25,5,minecraft:netherrack)
B(-8,26,5,minecraft:netherrack)
B(-8,27,5,minecraft:netherrack)
B(-8,28,5,minecraft:lava)
B(-8,29,5,minecraft:lava)
B(-8,30,5,minecraft:lava)
B(-8,31,5,minecraft:lava)
B(-8,32,5,minecraft:lava)
B(-8,33,5,minecraft:lava)
B(-8,34,5,minecraft:lava)
B(-8,35,5,minecraft:lava)
B(-8,0,6,minecraft:netherrack)
B(-8,1,6,minecraft:netherrack)
B(-8,2,6,minecraft:netherrack)
B(-8,3,6,minecraft:netherrack)
B(-8,4,6,minecraft:netherrack)
B(-8,5,6,minecraft:netherrack)
B(-8,6,6,minecraft:netherrack)
B(-8,7,6,minecraft:netherrack)
B(-8,8,6,minecraft:netherrack)
B(-8,9,6,minecraft:netherrack)
B(-8,10,6,minecraft:netherrack)
B(-8,11,6,minecraft:netherrack)
B(-8,12,6,minecraft:netherrack)
B(-8,13,6,minecraft:netherrack)
B(-8,14,6,minecraft:netherrack)
B(-8,15,6,minecraft:netherrack)
B(-8,16,6,minecraft:netherrack)
B(-8,17,6,minecraft:netherrack)
B(-8,18,6,minecraft:netherrack)
B(-8,19,6,minecraft:netherrack)
B(-8,20,6,minecraft:netherrack)
B(-8,21,6,minecraft:netherrack)
B(-8,22,6,minecraft:netherrack)
B(-8,23,6,minecraft:netherrack)
B(-8,24,6,minecraft:netherrack)
B(-8,25,6,minecraft:netherrack)
B(-8,26,6,minecraft:netherrack)
B(-8,27,6,minecraft:netherrack)
B(-8,28,6,minecraft:lava)
B(-8,29,6,minecraft:lava)
B(-8,30,6,minecraft:lava)
B(-8,31,6,minecraft:lava)
B(-8,32,6,minecraft:lava)
B(-8,33,6,minecraft:lava)
B(-8,34,6,minecraft:lava)
B(-8,35,6,minecraft:lava)
B(-8,0,7,minecraft:netherrack)
B(-8,1,7,minecraft:netherrack)
B(-8,2,7,minecraft:netherrack)
B(-8,3,7,minecraft:netherrack)
B(-8,4,7,minecraft:netherrack)
B(-8,5,7,minecraft:netherrack)
B(-8,6,7,minecraft:netherrack)
B(-8,7,7,minecraft:netherrack)
B(-8,8,7,minecraft:netherrack)
B(-8,9,7,minecraft:netherrack)
B(-8,10,7,minecraft:netherrack)
B(-8,11,7,minecraft:netherrack)
B(-8,12,7,minecraft:netherrack)
B(-8,13,7,minecraft:netherrack)
B(-8,14,7,minecraft:netherrack)
B(-8,15,7,minecraft:netherrack)
B(-8,16,7,minecraft:netherrack)
B(-8,17,7,minecraft:netherrack)
B(-8,18,7,minecraft:netherrack)
B(-8,19,7,minecraft:netherrack)
B(-8,20,7,minecraft:netherrack)
B(-8,21,7,minecraft:netherrack)
B(-8,22,7,minecraft:netherrack)
B(-8,23,7,minecraft:netherrack)
B(-8,24,7,minecraft:netherrack)
B(-8,25,7,minecraft:netherrack)
B(-8,26,7,minecraft:netherrack)
B(-8,27,7,minecraft:netherrack)
B(-8,28,7,minecraft:lava)
B(-8,29,7,minecraft:lava)
B(-8,30,7,minecraft:lava)
B(-8,31,7,minecraft:lava)
B(-8,32,7,minecraft:lava)
B(-8,33,7,minecraft:lava)
B(-8,34,7,minecraft:lava)
B(-8,35,7,minecraft:lava)
B(-8,0,8,minecraft:netherrack)
B(-8,1,8,minecraft:netherrack)
B(-8,2,8,minecraft:netherrack)
B(-8,3,8,minecraft:netherrack)
B(-8,4,8,minecraft:netherrack)
B(-8,5,8,minecraft:netherrack)
B(-8,6,8,minecraft:netherrack)
B(-8,7,8,minecraft:netherrack)
B(-8,8,8,minecraft:netherrack)
B(-8,9,8,minecraft:netherrack)
B(-8,10,8,minecraft:netherrack)
B(-8,11,8,minecraft:netherrack)
B(-8,12,8,minecraft:netherrack)
B(-8,13,8,minecraft:netherrack)
B(-8,14,8,minecraft:netherrack)
B(-8,15,8,minecraft:netherrack)
B(-8,16,8,minecraft:netherrack)
B(-8,17,8,minecraft:netherrack)
B(-8,18,8,minecraft:netherrack)
B(-8,19,8,minecraft:netherrack)
B(-8,20,8,minecraft:netherrack)
B(-8,21,8,minecraft:netherrack)
B(-8,22,8,minecraft:netherrack)
B(-8,23,8,minecraft:netherrack)
B(-8,24,8,minecraft:netherrack)
B(-8,25,8,minecraft:netherrack)
B(-8,26,8,minecraft:netherrack)
B(-8,27,8,minecraft:netherrack)
B(-8,28,8,minecraft:lava)
B(-8,29,8,minecraft:lava)
B(-8,30,8,minecraft:lava)
B(-8,31,8,minecraft:lava)
B(-8,32,8,minecraft:lava)
B(-8,33,8,minecraft:lava)
B(-8,34,8,minecraft:lava)
B(-8,35,8,minecraft:lava)
B(-7,0,-7,minecraft:netherrack)
B(-7,1,-7,minecraft:netherrack)
B(-7,2,-7,minecraft:netherrack)
B(-7,3,-7,minecraft:netherrack)
B(-7,4,-7,minecraft:netherrack)
B(-7,5,-7,minecraft:netherrack)
B(-7,6,-7,minecraft:netherrack)
B(-7,7,-7,minecraft:netherrack)
B(-7,8,-7,minecraft:netherrack)
B(-7,9,-7,minecraft:netherrack)
B(-7,10,-7,minecraft:netherrack)
B(-7,11,-7,minecraft:netherrack)
B(-7,12,-7,minecraft:netherrack)
B(-7,13,-7,minecraft:netherrack)
B(-7,14,-7,minecraft:netherrack)
B(-7,15,-7,minecraft:netherrack)
B(-7,16,-7,minecraft:netherrack)
B(-7,17,-7,minecraft:netherrack)
B(-7,18,-7,minecraft:netherrack)
B(-7,19,-7,minecraft:netherrack)
B(-7,20,-7,minecraft:netherrack)
B(-7,21,-7,minecraft:netherrack)
B(-7,22,-7,minecraft:netherrack)
B(-7,23,-7,minecraft:netherrack)
B(-7,24,-7,minecraft:netherrack)
B(-7,25,-7,minecraft:netherrack)
B(-7,26,-7,minecraft:netherrack)
B(-7,27,-7,minecraft:netherrack)
B(-7,28,-7,minecraft:netherrack)
B(-7,29,-7,minecraft:netherrack)
B(-7,30,-7,minecraft:netherrack)
B(-7,31,-7,minecraft:netherrack)
B(-7,32,-7,minecraft:netherrack)
B(-7,33,-7,minecraft:netherrack)
B(-7,0,-6,minecraft:netherrack)
B(-7,1,-6,minecraft:netherrack)
B(-7,2,-6,minecraft:netherrack)
B(-7,3,-6,minecraft:netherrack)
B(-7,4,-6,minecraft:netherrack)
B(-7,5,-6,minecraft:netherrack)
B(-7,6,-6,minecraft:netherrack)
B(-7,7,-6,minecraft:netherrack)
B(-7,8,-6,minecraft:netherrack)
B(-7,9,-6,minecraft:netherrack)
B(-7,10,-6,minecraft:netherrack)
B(-7,11,-6,minecraft:netherrack)
B(-7,12,-6,minecraft:netherrack)
B(-7,13,-6,minecraft:netherrack)
B(-7,14,-6,minecraft:netherrack)
B(-7,15,-6,minecraft:netherrack)
B(-7,16,-6,minecraft:netherrack)
B(-7,17,-6,minecraft:netherrack)
B(-7,18,-6,minecraft:netherrack)
B(-7,19,-6,minecraft:netherrack)
B(-7,20,-6,minecraft:netherrack)
B(-7,21,-6,minecraft:netherrack)
B(-7,22,-6,minecraft:netherrack)
B(-7,23,-6,minecraft:netherrack)
B(-7,24,-6,minecraft:netherrack)
B(-7,25,-6,minecraft:netherrack)
B(-7,26,-6,minecraft:netherrack)
B(-7,27,-6,minecraft:netherrack)
B(-7,28,-6,minecraft:netherrack)
B(-7,29,-6,minecraft:netherrack)
B(-7,30,-6,minecraft:netherrack)
B(-7,31,-6,minecraft:netherrack)
B(-7,32,-6,minecraft:netherrack)
B(-7,33,-6,minecraft:netherrack)
B(-7,0,-5,minecraft:netherrack)
B(-7,1,-5,minecraft:netherrack)
B(-7,2,-5,minecraft:netherrack)
B(-7,3,-5,minecraft:netherrack)
B(-7,4,-5,minecraft:netherrack)
B(-7,5,-5,minecraft:netherrack)
B(-7,6,-5,minecraft:netherrack)
B(-7,7,-5,minecraft:netherrack)
B(-7,8,-5,minecraft:netherrack)
B(-7,9,-5,minecraft:netherrack)
B(-7,10,-5,minecraft:netherrack)
B(-7,11,-5,minecraft:netherrack)
B(-7,12,-5,minecraft:netherrack)
B(-7,13,-5,minecraft:netherrack)
B(-7,14,-5,minecraft:netherrack)
B(-7,15,-5,minecraft:netherrack)
B(-7,16,-5,minecraft:netherrack)
B(-7,17,-5,minecraft:netherrack)
B(-7,18,-5,minecraft:netherrack)
B(-7,19,-5,minecraft:netherrack)
B(-7,20,-5,minecraft:netherrack)
B(-7,21,-5,minecraft:netherrack)
B(-7,22,-5,minecraft:netherrack)
B(-7,23,-5,minecraft:netherrack)
B(-7,24,-5,minecraft:netherrack)
B(-7,25,-5,minecraft:netherrack)
B(-7,26,-5,minecraft:netherrack)
B(-7,27,-5,minecraft:netherrack)
B(-7,28,-5,minecraft:netherrack)
B(-7,29,-5,minecraft:netherrack)
B(-7,30,-5,minecraft:netherrack)
B(-7,31,-5,minecraft:netherrack)
B(-7,32,-5,minecraft:netherrack)
B(-7,33,-5,minecraft:netherrack)
B(-7,34,-5,minecraft:netherrack)
B(-7,35,-5,minecraft:netherrack)
B(-7,0,-4,minecraft:netherrack)
B(-7,1,-4,minecraft:netherrack)
B(-7,2,-4,minecraft:netherrack)
B(-7,3,-4,minecraft:netherrack)
B(-7,4,-4,minecraft:netherrack)
B(-7,5,-4,minecraft:netherrack)
B(-7,6,-4,minecraft:netherrack)
B(-7,7,-4,minecraft:netherrack)
B(-7,8,-4,minecraft:netherrack)
B(-7,9,-4,minecraft:netherrack)
B(-7,10,-4,minecraft:netherrack)
B(-7,11,-4,minecraft:netherrack)
B(-7,12,-4,minecraft:netherrack)
B(-7,13,-4,minecraft:netherrack)
B(-7,14,-4,minecraft:netherrack)
B(-7,15,-4,minecraft:netherrack)
B(-7,16,-4,minecraft:netherrack)
B(-7,17,-4,minecraft:netherrack)
B(-7,18,-4,minecraft:netherrack)
B(-7,19,-4,minecraft:netherrack)
B(-7,20,-4,minecraft:netherrack)
B(-7,21,-4,minecraft:netherrack)
B(-7,22,-4,minecraft:netherrack)
B(-7,23,-4,minecraft:netherrack)
B(-7,24,-4,minecraft:netherrack)
B(-7,25,-4,minecraft:netherrack)
B(-7,26,-4,minecraft:netherrack)
B(-7,27,-4,minecraft:netherrack)
B(-7,28,-4,minecraft:netherrack)
B(-7,29,-4,minecraft:netherrack)
B(-7,30,-4,minecraft:netherrack)
B(-7,31,-4,minecraft:netherrack)
B(-7,32,-4,minecraft:netherrack)
B(-7,33,-4,minecraft:netherrack)
B(-7,34,-4,minecraft:netherrack)
B(-7,35,-4,minecraft:netherrack)
B(-7,36,-4,minecraft:netherrack)
B(-7,0,-3,minecraft:netherrack)
B(-7,1,-3,minecraft:netherrack)
B(-7,2,-3,minecraft:netherrack)
B(-7,3,-3,minecraft:netherrack)
B(-7,4,-3,minecraft:netherrack)
B(-7,5,-3,minecraft:netherrack)
B(-7,6,-3,minecraft:netherrack)
B(-7,7,-3,minecraft:netherrack)
B(-7,8,-3,minecraft:netherrack)
B(-7,9,-3,minecraft:netherrack)
B(-7,10,-3,minecraft:netherrack)
B(-7,11,-3,minecraft:netherrack)
B(-7,12,-3,minecraft:netherrack)
B(-7,13,-3,minecraft:netherrack)
B(-7,14,-3,minecraft:netherrack)
B(-7,15,-3,minecraft:netherrack)
B(-7,16,-3,minecraft:netherrack)
B(-7,17,-3,minecraft:netherrack)
B(-7,18,-3,minecraft:netherrack)
B(-7,19,-3,minecraft:netherrack)
B(-7,20,-3,minecraft:netherrack)
B(-7,21,-3,minecraft:netherrack)
B(-7,22,-3,minecraft:netherrack)
B(-7,23,-3,minecraft:netherrack)
B(-7,24,-3,minecraft:netherrack)
B(-7,25,-3,minecraft:netherrack)
B(-7,26,-3,minecraft:netherrack)
B(-7,27,-3,minecraft:netherrack)
B(-7,28,-3,minecraft:netherrack)
B(-7,29,-3,minecraft:netherrack)
B(-7,30,-3,minecraft:netherrack)
B(-7,31,-3,minecraft:netherrack)
B(-7,32,-3,minecraft:netherrack)
B(-7,33,-3,minecraft:netherrack)
B(-7,34,-3,minecraft:netherrack)
B(-7,35,-3,minecraft:netherrack)
B(-7,0,-2,minecraft:netherrack)
B(-7,1,-2,minecraft:netherrack)
B(-7,2,-2,minecraft:netherrack)
B(-7,3,-2,minecraft:netherrack)
B(-7,4,-2,minecraft:netherrack)
B(-7,5,-2,minecraft:netherrack)
B(-7,6,-2,minecraft:netherrack)
B(-7,7,-2,minecraft:netherrack)
B(-7,8,-2,minecraft:netherrack)
B(-7,9,-2,minecraft:netherrack)
B(-7,10,-2,minecraft:netherrack)
B(-7,11,-2,minecraft:netherrack)
B(-7,12,-2,minecraft:netherrack)
B(-7,13,-2,minecraft:netherrack)
B(-7,14,-2,minecraft:netherrack)
B(-7,15,-2,minecraft:netherrack)
B(-7,16,-2,minecraft:netherrack)
B(-7,17,-2,minecraft:netherrack)
B(-7,18,-2,minecraft:netherrack)
B(-7,19,-2,minecraft:netherrack)
B(-7,20,-2,minecraft:netherrack)
B(-7,21,-2,minecraft:netherrack)
B(-7,22,-2,minecraft:netherrack)
B(-7,23,-2,minecraft:netherrack)
B(-7,24,-2,minecraft:netherrack)
B(-7,25,-2,minecraft:netherrack)
B(-7,26,-2,minecraft:netherrack)
B(-7,27,-2,minecraft:netherrack)
B(-7,28,-2,minecraft:netherrack)
B(-7,29,-2,minecraft:netherrack)
B(-7,30,-2,minecraft:netherrack)
B(-7,31,-2,minecraft:netherrack)
B(-7,32,-2,minecraft:netherrack)
B(-7,33,-2,minecraft:netherrack)
B(-7,34,-2,minecraft:netherrack)
B(-7,35,-2,minecraft:lava)
B(-7,0,-1,minecraft:netherrack)
B(-7,1,-1,minecraft:netherrack)
B(-7,2,-1,minecraft:netherrack)
B(-7,3,-1,minecraft:netherrack)
B(-7,4,-1,minecraft:netherrack)
B(-7,5,-1,minecraft:netherrack)
B(-7,6,-1,minecraft:netherrack)
B(-7,7,-1,minecraft:netherrack)
B(-7,8,-1,minecraft:netherrack)
B(-7,9,-1,minecraft:netherrack)
B(-7,10,-1,minecraft:netherrack)
B(-7,11,-1,minecraft:netherrack)
B(-7,12,-1,minecraft:netherrack)
B(-7,13,-1,minecraft:netherrack)
B(-7,14,-1,minecraft:netherrack)
B(-7,15,-1,minecraft:netherrack)
B(-7,16,-1,minecraft:netherrack)
B(-7,17,-1,minecraft:netherrack)
B(-7,18,-1,minecraft:netherrack)
B(-7,19,-1,minecraft:netherrack)
B(-7,20,-1,minecraft:netherrack)
B(-7,21,-1,minecraft:netherrack)
B(-7,22,-1,minecraft:netherrack)
B(-7,23,-1,minecraft:netherrack)
B(-7,24,-1,minecraft:netherrack)
B(-7,25,-1,minecraft:netherrack)
B(-7,26,-1,minecraft:netherrack)
B(-7,27,-1,minecraft:netherrack)
B(-7,28,-1,minecraft:netherrack)
B(-7,29,-1,minecraft:netherrack)
B(-7,30,-1,minecraft:netherrack)
B(-7,31,-1,minecraft:netherrack)
B(-7,32,-1,minecraft:netherrack)
B(-7,33,-1,minecraft:netherrack)
B(-7,34,-1,minecraft:lava)
B(-7,35,-1,minecraft:lava)
B(-7,0,0,minecraft:netherrack)
B(-7,1,0,minecraft:netherrack)
B(-7,2,0,minecraft:netherrack)
B(-7,3,0,minecraft:netherrack)
B(-7,4,0,minecraft:netherrack)
B(-7,5,0,minecraft:netherrack)
B(-7,6,0,minecraft:netherrack)
B(-7,7,0,minecraft:netherrack)
B(-7,8,0,minecraft:netherrack)
B(-7,9,0,minecraft:netherrack)
B(-7,10,0,minecraft:netherrack)
B(-7,11,0,minecraft:netherrack)
B(-7,12,0,minecraft:netherrack)
B(-7,13,0,minecraft:netherrack)
B(-7,14,0,minecraft:netherrack)
B(-7,15,0,minecraft:netherrack)
B(-7,16,0,minecraft:netherrack)
B(-7,17,0,minecraft:netherrack)
B(-7,18,0,minecraft:netherrack)
B(-7,19,0,minecraft:netherrack)
B(-7,20,0,minecraft:netherrack)
B(-7,21,0,minecraft:netherrack)
B(-7,22,0,minecraft:netherrack)
B(-7,23,0,minecraft:netherrack)
B(-7,24,0,minecraft:netherrack)
B(-7,25,0,minecraft:netherrack)
B(-7,26,0,minecraft:netherrack)
B(-7,27,0,minecraft:netherrack)
B(-7,28,0,minecraft:netherrack)
B(-7,29,0,minecraft:netherrack)
B(-7,30,0,minecraft:netherrack)
B(-7,31,0,minecraft:netherrack)
B(-7,32,0,minecraft:netherrack)
B(-7,33,0,minecraft:lava)
B(-7,34,0,minecraft:lava)
B(-7,35,0,minecraft:lava)
B(-7,0,1,minecraft:netherrack)
B(-7,1,1,minecraft:netherrack)
B(-7,2,1,minecraft:netherrack)
B(-7,3,1,minecraft:netherrack)
B(-7,4,1,minecraft:netherrack)
B(-7,5,1,minecraft:netherrack)
B(-7,6,1,minecraft:netherrack)
B(-7,7,1,minecraft:netherrack)
B(-7,8,1,minecraft:netherrack)
B(-7,9,1,minecraft:netherrack)
B(-7,10,1,minecraft:netherrack)
B(-7,11,1,minecraft:netherrack)
B(-7,12,1,minecraft:netherrack)
B(-7,13,1,minecraft:netherrack)
B(-7,14,1,minecraft:netherrack)
B(-7,15,1,minecraft:netherrack)
B(-7,16,1,minecraft:netherrack)
B(-7,17,1,minecraft:netherrack)
B(-7,18,1,minecraft:netherrack)
B(-7,19,1,minecraft:netherrack)
B(-7,20,1,minecraft:netherrack)
B(-7,21,1,minecraft:netherrack)
B(-7,22,1,minecraft:netherrack)
B(-7,23,1,minecraft:netherrack)
B(-7,24,1,minecraft:netherrack)
B(-7,25,1,minecraft:netherrack)
B(-7,26,1,minecraft:netherrack)
B(-7,27,1,minecraft:netherrack)
B(-7,28,1,minecraft:netherrack)
B(-7,29,1,minecraft:netherrack)
B(-7,30,1,minecraft:netherrack)
B(-7,31,1,minecraft:lava)
B(-7,32,1,minecraft:lava)
B(-7,33,1,minecraft:lava)
B(-7,34,1,minecraft:lava)
B(-7,35,1,minecraft:lava)
B(-7,0,2,minecraft:netherrack)
B(-7,1,2,minecraft:netherrack)
B(-7,2,2,minecraft:netherrack)
B(-7,3,2,minecraft:netherrack)
B(-7,4,2,minecraft:netherrack)
B(-7,5,2,minecraft:netherrack)
B(-7,6,2,minecraft:netherrack)
B(-7,7,2,minecraft:netherrack)
B(-7,8,2,minecraft:netherrack)
B(-7,9,2,minecraft:netherrack)
B(-7,10,2,minecraft:netherrack)
B(-7,11,2,minecraft:netherrack)
B(-7,12,2,minecraft:netherrack)
B(-7,13,2,minecraft:netherrack)
B(-7,14,2,minecraft:netherrack)
B(-7,15,2,minecraft:netherrack)
B(-7,16,2,minecraft:netherrack)
B(-7,17,2,minecraft:netherrack)
B(-7,18,2,minecraft:netherrack)
B(-7,19,2,minecraft:netherrack)
B(-7,20,2,minecraft:netherrack)
B(-7,21,2,minecraft:netherrack)
B(-7,22,2,minecraft:netherrack)
B(-7,23,2,minecraft:netherrack)
B(-7,24,2,minecraft:netherrack)
B(-7,25,2,minecraft:netherrack)
B(-7,26,2,minecraft:netherrack)
B(-7,27,2,minecraft:netherrack)
B(-7,28,2,minecraft:netherrack)
B(-7,29,2,minecraft:netherrack)
B(-7,30,2,minecraft:lava)
B(-7,31,2,minecraft:lava)
B(-7,32,2,minecraft:lava)
B(-7,33,2,minecraft:lava)
B(-7,34,2,minecraft:lava)
B(-7,35,2,minecraft:lava)
B(-7,0,3,minecraft:netherrack)
B(-7,1,3,minecraft:netherrack)
B(-7,2,3,minecraft:netherrack)
B(-7,3,3,minecraft:netherrack)
B(-7,4,3,minecraft:netherrack)
B(-7,5,3,minecraft:netherrack)
B(-7,6,3,minecraft:netherrack)
B(-7,7,3,minecraft:netherrack)
B(-7,8,3,minecraft:netherrack)
B(-7,9,3,minecraft:netherrack)
B(-7,10,3,minecraft:netherrack)
B(-7,11,3,minecraft:netherrack)
B(-7,12,3,minecraft:netherrack)
B(-7,13,3,minecraft:netherrack)
B(-7,14,3,minecraft:netherrack)
B(-7,15,3,minecraft:netherrack)
B(-7,16,3,minecraft:netherrack)
B(-7,17,3,minecraft:netherrack)
B(-7,18,3,minecraft:netherrack)
B(-7,19,3,minecraft:netherrack)
B(-7,20,3,minecraft:netherrack)
B(-7,21,3,minecraft:netherrack)
B(-7,22,3,minecraft:netherrack)
B(-7,23,3,minecraft:netherrack)
B(-7,24,3,minecraft:netherrack)
B(-7,25,3,minecraft:netherrack)
B(-7,26,3,minecraft:netherrack)
B(-7,27,3,minecraft:netherrack)
B(-7,28,3,minecraft:netherrack)
B(-7,29,3,minecraft:lava)
B(-7,30,3,minecraft:lava)
B(-7,31,3,minecraft:lava)
B(-7,32,3,minecraft:lava)
B(-7,33,3,minecraft:lava)
B(-7,34,3,minecraft:lava)
B(-7,35,3,minecraft:lava)
B(-7,0,4,minecraft:netherrack)
B(-7,1,4,minecraft:netherrack)
B(-7,2,4,minecraft:netherrack)
B(-7,3,4,minecraft:netherrack)
B(-7,4,4,minecraft:netherrack)
B(-7,5,4,minecraft:netherrack)
B(-7,6,4,minecraft:netherrack)
B(-7,7,4,minecraft:netherrack)
B(-7,8,4,minecraft:netherrack)
B(-7,9,4,minecraft:netherrack)
B(-7,10,4,minecraft:netherrack)
B(-7,11,4,minecraft:netherrack)
B(-7,12,4,minecraft:netherrack)
B(-7,13,4,minecraft:netherrack)
B(-7,14,4,minecraft:netherrack)
B(-7,15,4,minecraft:netherrack)
B(-7,16,4,minecraft:netherrack)
B(-7,17,4,minecraft:netherrack)
B(-7,18,4,minecraft:netherrack)
B(-7,19,4,minecraft:netherrack)
B(-7,20,4,minecraft:netherrack)
B(-7,21,4,minecraft:netherrack)
B(-7,22,4,minecraft:netherrack)
B(-7,23,4,minecraft:netherrack)
B(-7,24,4,minecraft:netherrack)
B(-7,25,4,minecraft:netherrack)
B(-7,26,4,minecraft:netherrack)
B(-7,27,4,minecraft:netherrack)
B(-7,28,4,minecraft:netherrack)
B(-7,29,4,minecraft:lava)
B(-7,30,4,minecraft:lava)
B(-7,31,4,minecraft:lava)
B(-7,32,4,minecraft:lava)
B(-7,33,4,minecraft:lava)
B(-7,34,4,minecraft:lava)
B(-7,35,4,minecraft:lava)
B(-7,0,5,minecraft:netherrack)
B(-7,1,5,minecraft:netherrack)
B(-7,2,5,minecraft:netherrack)
B(-7,3,5,minecraft:netherrack)
B(-7,4,5,minecraft:netherrack)
B(-7,5,5,minecraft:netherrack)
B(-7,6,5,minecraft:netherrack)
B(-7,7,5,minecraft:netherrack)
B(-7,8,5,minecraft:netherrack)
B(-7,9,5,minecraft:netherrack)
B(-7,10,5,minecraft:netherrack)
B(-7,11,5,minecraft:netherrack)
B(-7,12,5,minecraft:netherrack)
B(-7,13,5,minecraft:netherrack)
B(-7,14,5,minecraft:netherrack)
B(-7,15,5,minecraft:netherrack)
B(-7,16,5,minecraft:netherrack)
B(-7,17,5,minecraft:netherrack)
B(-7,18,5,minecraft:netherrack)
B(-7,19,5,minecraft:netherrack)
B(-7,20,5,minecraft:netherrack)
B(-7,21,5,minecraft:netherrack)
B(-7,22,5,minecraft:netherrack)
B(-7,23,5,minecraft:netherrack)
B(-7,24,5,minecraft:netherrack)
B(-7,25,5,minecraft:netherrack)
B(-7,26,5,minecraft:netherrack)
B(-7,27,5,minecraft:netherrack)
B(-7,28,5,minecraft:lava)
B(-7,29,5,minecraft:lava)
B(-7,30,5,minecraft:lava)
B(-7,31,5,minecraft:lava)
B(-7,32,5,minecraft:lava)
B(-7,33,5,minecraft:lava)
B(-7,34,5,minecraft:lava)
B(-7,35,5,minecraft:lava)
B(-7,0,6,minecraft:netherrack)
B(-7,1,6,minecraft:netherrack)
B(-7,2,6,minecraft:netherrack)
B(-7,3,6,minecraft:netherrack)
B(-7,4,6,minecraft:netherrack)
B(-7,5,6,minecraft:netherrack)
B(-7,6,6,minecraft:netherrack)
B(-7,7,6,minecraft:netherrack)
B(-7,8,6,minecraft:netherrack)
B(-7,9,6,minecraft:netherrack)
B(-7,10,6,minecraft:netherrack)
B(-7,11,6,minecraft:netherrack)
B(-7,12,6,minecraft:netherrack)
B(-7,13,6,minecraft:netherrack)
B(-7,14,6,minecraft:netherrack)
B(-7,15,6,minecraft:netherrack)
B(-7,16,6,minecraft:netherrack)
B(-7,17,6,minecraft:netherrack)
B(-7,18,6,minecraft:netherrack)
B(-7,19,6,minecraft:netherrack)
B(-7,20,6,minecraft:netherrack)
B(-7,21,6,minecraft:netherrack)
B(-7,22,6,minecraft:netherrack)
B(-7,23,6,minecraft:netherrack)
B(-7,24,6,minecraft:netherrack)
B(-7,25,6,minecraft:netherrack)
B(-7,26,6,minecraft:netherrack)
B(-7,27,6,minecraft:netherrack)
B(-7,28,6,minecraft:lava)
B(-7,29,6,minecraft:lava)
B(-7,30,6,minecraft:lava)
B(-7,31,6,minecraft:lava)
B(-7,32,6,minecraft:lava)
B(-7,33,6,minecraft:lava)
B(-7,34,6,minecraft:lava)
B(-7,35,6,minecraft:lava)
B(-7,0,7,minecraft:netherrack)
B(-7,1,7,minecraft:netherrack)
B(-7,2,7,minecraft:netherrack)
B(-7,3,7,minecraft:netherrack)
B(-7,4,7,minecraft:netherrack)
B(-7,5,7,minecraft:netherrack)
B(-7,6,7,minecraft:netherrack)
B(-7,7,7,minecraft:netherrack)
B(-7,8,7,minecraft:netherrack)
B(-7,9,7,minecraft:netherrack)
B(-7,10,7,minecraft:netherrack)
B(-7,11,7,minecraft:netherrack)
B(-7,12,7,minecraft:netherrack)
B(-7,13,7,minecraft:netherrack)
B(-7,14,7,minecraft:netherrack)
B(-7,15,7,minecraft:netherrack)
B(-7,16,7,minecraft:netherrack)
B(-7,17,7,minecraft:netherrack)
B(-7,18,7,minecraft:netherrack)
B(-7,19,7,minecraft:netherrack)
B(-7,20,7,minecraft:netherrack)
B(-7,21,7,minecraft:netherrack)
B(-7,22,7,minecraft:netherrack)
B(-7,23,7,minecraft:netherrack)
B(-7,24,7,minecraft:netherrack)
B(-7,25,7,minecraft:netherrack)
B(-7,26,7,minecraft:netherrack)
B(-7,27,7,minecraft:lava)
B(-7,28,7,minecraft:lava)
B(-7,29,7,minecraft:lava)
B(-7,30,7,minecraft:lava)
B(-7,31,7,minecraft:lava)
B(-7,32,7,minecraft:lava)
B(-7,33,7,minecraft:lava)
B(-7,34,7,minecraft:lava)
B(-7,35,7,minecraft:lava)
B(-7,0,8,minecraft:netherrack)
B(-7,1,8,minecraft:netherrack)
B(-7,2,8,minecraft:netherrack)
B(-7,3,8,minecraft:netherrack)
B(-7,4,8,minecraft:netherrack)
B(-7,5,8,minecraft:netherrack)
B(-7,6,8,minecraft:netherrack)
B(-7,7,8,minecraft:netherrack)
B(-7,8,8,minecraft:netherrack)
B(-7,9,8,minecraft:netherrack)
B(-7,10,8,minecraft:netherrack)
B(-7,11,8,minecraft:netherrack)
B(-7,12,8,minecraft:netherrack)
B(-7,13,8,minecraft:netherrack)
B(-7,14,8,minecraft:netherrack)
B(-7,15,8,minecraft:netherrack)
B(-7,16,8,minecraft:netherrack)
B(-7,17,8,minecraft:netherrack)
B(-7,18,8,minecraft:netherrack)
B(-7,19,8,minecraft:netherrack)
B(-7,20,8,minecraft:netherrack)
B(-7,21,8,minecraft:netherrack)
B(-7,22,8,minecraft:netherrack)
B(-7,23,8,minecraft:netherrack)
B(-7,24,8,minecraft:netherrack)
B(-7,25,8,minecraft:netherrack)
B(-7,26,8,minecraft:netherrack)
B(-7,27,8,minecraft:netherrack)
B(-7,28,8,minecraft:lava)
B(-7,29,8,minecraft:lava)
B(-7,30,8,minecraft:lava)
B(-7,31,8,minecraft:lava)
B(-7,32,8,minecraft:lava)
B(-7,33,8,minecraft:lava)
B(-7,34,8,minecraft:lava)
B(-7,35,8,minecraft:lava)
B(-6,0,-7,minecraft:netherrack)
B(-6,1,-7,minecraft:netherrack)
B(-6,2,-7,minecraft:netherrack)
B(-6,3,-7,minecraft:netherrack)
B(-6,4,-7,minecraft:netherrack)
B(-6,5,-7,minecraft:netherrack)
B(-6,6,-7,minecraft:netherrack)
B(-6,7,-7,minecraft:netherrack)
B(-6,8,-7,minecraft:netherrack)
B(-6,9,-7,minecraft:netherrack)
B(-6,10,-7,minecraft:netherrack)
B(-6,11,-7,minecraft:netherrack)
B(-6,12,-7,minecraft:netherrack)
B(-6,13,-7,minecraft:netherrack)
B(-6,14,-7,minecraft:netherrack)
B(-6,15,-7,minecraft:netherrack)
B(-6,16,-7,minecraft:netherrack)
B(-6,17,-7,minecraft:netherrack)
B(-6,18,-7,minecraft:netherrack)
B(-6,19,-7,minecraft:netherrack)
B(-6,20,-7,minecraft:netherrack)
B(-6,21,-7,minecraft:netherrack)
B(-6,22,-7,minecraft:netherrack)
B(-6,23,-7,minecraft:netherrack)
B(-6,24,-7,minecraft:netherrack)
B(-6,25,-7,minecraft:netherrack)
B(-6,26,-7,minecraft:netherrack)
B(-6,27,-7,minecraft:netherrack)
B(-6,28,-7,minecraft:netherrack)
B(-6,29,-7,minecraft:netherrack)
B(-6,30,-7,minecraft:netherrack)
B(-6,31,-7,minecraft:netherrack)
B(-6,32,-7,minecraft:netherrack)
B(-6,33,-7,minecraft:netherrack)
B(-6,0,-6,minecraft:netherrack)
B(-6,1,-6,minecraft:netherrack)
B(-6,2,-6,minecraft:netherrack)
B(-6,3,-6,minecraft:netherrack)
B(-6,4,-6,minecraft:netherrack)
B(-6,5,-6,minecraft:netherrack)
B(-6,6,-6,minecraft:netherrack)
B(-6,7,-6,minecraft:netherrack)
B(-6,8,-6,minecraft:netherrack)
B(-6,9,-6,minecraft:netherrack)
B(-6,10,-6,minecraft:netherrack)
B(-6,11,-6,minecraft:netherrack)
B(-6,12,-6,minecraft:netherrack)
B(-6,13,-6,minecraft:netherrack)
B(-6,14,-6,minecraft:netherrack)
B(-6,15,-6,minecraft:netherrack)
B(-6,16,-6,minecraft:netherrack)
B(-6,17,-6,minecraft:netherrack)
B(-6,18,-6,minecraft:netherrack)
B(-6,19,-6,minecraft:netherrack)
B(-6,20,-6,minecraft:netherrack)
B(-6,21,-6,minecraft:netherrack)
B(-6,22,-6,minecraft:netherrack)
B(-6,23,-6,minecraft:netherrack)
B(-6,24,-6,minecraft:netherrack)
B(-6,25,-6,minecraft:netherrack)
B(-6,26,-6,minecraft:netherrack)
B(-6,27,-6,minecraft:netherrack)
B(-6,28,-6,minecraft:netherrack)
B(-6,29,-6,minecraft:netherrack)
B(-6,30,-6,minecraft:netherrack)
B(-6,31,-6,minecraft:netherrack)
B(-6,32,-6,minecraft:netherrack)
B(-6,33,-6,minecraft:netherrack)
B(-6,34,-6,minecraft:netherrack)
B(-6,0,-5,minecraft:netherrack)
B(-6,1,-5,minecraft:netherrack)
B(-6,2,-5,minecraft:netherrack)
B(-6,3,-5,minecraft:netherrack)
B(-6,4,-5,minecraft:netherrack)
B(-6,5,-5,minecraft:netherrack)
B(-6,6,-5,minecraft:netherrack)
B(-6,7,-5,minecraft:netherrack)
B(-6,8,-5,minecraft:netherrack)
B(-6,9,-5,minecraft:netherrack)
B(-6,10,-5,minecraft:netherrack)
B(-6,11,-5,minecraft:netherrack)
B(-6,12,-5,minecraft:netherrack)
B(-6,13,-5,minecraft:netherrack)
B(-6,14,-5,minecraft:netherrack)
B(-6,15,-5,minecraft:netherrack)
B(-6,16,-5,minecraft:netherrack)
B(-6,17,-5,minecraft:netherrack)
B(-6,18,-5,minecraft:netherrack)
B(-6,19,-5,minecraft:netherrack)
B(-6,20,-5,minecraft:netherrack)
B(-6,21,-5,minecraft:netherrack)
B(-6,22,-5,minecraft:netherrack)
B(-6,23,-5,minecraft:netherrack)
B(-6,24,-5,minecraft:netherrack)
B(-6,25,-5,minecraft:netherrack)
B(-6,26,-5,minecraft:netherrack)
B(-6,27,-5,minecraft:netherrack)
B(-6,28,-5,minecraft:netherrack)
B(-6,29,-5,minecraft:netherrack)
B(-6,30,-5,minecraft:netherrack)
B(-6,31,-5,minecraft:netherrack)
B(-6,32,-5,minecraft:netherrack)
B(-6,33,-5,minecraft:netherrack)
B(-6,34,-5,minecraft:netherrack)
B(-6,35,-5,minecraft:netherrack)
B(-6,0,-4,minecraft:netherrack)
B(-6,1,-4,minecraft:netherrack)
B(-6,2,-4,minecraft:netherrack)
B(-6,3,-4,minecraft:netherrack)
B(-6,4,-4,minecraft:netherrack)
B(-6,5,-4,minecraft:netherrack)
B(-6,6,-4,minecraft:netherrack)
B(-6,7,-4,minecraft:netherrack)
B(-6,8,-4,minecraft:netherrack)
B(-6,9,-4,minecraft:netherrack)
B(-6,10,-4,minecraft:netherrack)
B(-6,11,-4,minecraft:netherrack)
B(-6,12,-4,minecraft:netherrack)
B(-6,13,-4,minecraft:netherrack)
B(-6,14,-4,minecraft:netherrack)
B(-6,15,-4,minecraft:netherrack)
B(-6,16,-4,minecraft:netherrack)
B(-6,17,-4,minecraft:netherrack)
B(-6,18,-4,minecraft:netherrack)
B(-6,19,-4,minecraft:netherrack)
B(-6,20,-4,minecraft:netherrack)
B(-6,21,-4,minecraft:netherrack)
B(-6,22,-4,minecraft:netherrack)
B(-6,23,-4,minecraft:netherrack)
B(-6,24,-4,minecraft:netherrack)
B(-6,25,-4,minecraft:netherrack)
B(-6,26,-4,minecraft:netherrack)
B(-6,27,-4,minecraft:netherrack)
B(-6,28,-4,minecraft:netherrack)
B(-6,29,-4,minecraft:netherrack)
B(-6,30,-4,minecraft:netherrack)
B(-6,31,-4,minecraft:netherrack)
B(-6,32,-4,minecraft:netherrack)
B(-6,33,-4,minecraft:netherrack)
B(-6,34,-4,minecraft:netherrack)
B(-6,35,-4,minecraft:netherrack)
B(-6,36,-4,minecraft:netherrack)
B(-6,0,-3,minecraft:netherrack)
B(-6,1,-3,minecraft:netherrack)
B(-6,2,-3,minecraft:netherrack)
B(-6,3,-3,minecraft:netherrack)
B(-6,4,-3,minecraft:netherrack)
B(-6,5,-3,minecraft:netherrack)
B(-6,6,-3,minecraft:netherrack)
B(-6,7,-3,minecraft:netherrack)
B(-6,8,-3,minecraft:netherrack)
B(-6,9,-3,minecraft:netherrack)
B(-6,10,-3,minecraft:netherrack)
B(-6,11,-3,minecraft:netherrack)
B(-6,12,-3,minecraft:netherrack)
B(-6,13,-3,minecraft:netherrack)
B(-6,14,-3,minecraft:netherrack)
B(-6,15,-3,minecraft:netherrack)
B(-6,16,-3,minecraft:netherrack)
B(-6,17,-3,minecraft:netherrack)
B(-6,18,-3,minecraft:netherrack)
B(-6,19,-3,minecraft:netherrack)
B(-6,20,-3,minecraft:netherrack)
B(-6,21,-3,minecraft:netherrack)
B(-6,22,-3,minecraft:netherrack)
B(-6,23,-3,minecraft:netherrack)
B(-6,24,-3,minecraft:netherrack)
B(-6,25,-3,minecraft:netherrack)
B(-6,26,-3,minecraft:netherrack)
B(-6,27,-3,minecraft:netherrack)
B(-6,28,-3,minecraft:netherrack)
B(-6,29,-3,minecraft:netherrack)
B(-6,30,-3,minecraft:netherrack)
B(-6,31,-3,minecraft:netherrack)
B(-6,32,-3,minecraft:netherrack)
B(-6,33,-3,minecraft:netherrack)
B(-6,34,-3,minecraft:netherrack)
B(-6,35,-3,minecraft:netherrack)
B(-6,0,-2,minecraft:netherrack)
B(-6,1,-2,minecraft:netherrack)
B(-6,2,-2,minecraft:netherrack)
B(-6,3,-2,minecraft:netherrack)
B(-6,4,-2,minecraft:netherrack)
B(-6,5,-2,minecraft:netherrack)
B(-6,6,-2,minecraft:netherrack)
B(-6,7,-2,minecraft:netherrack)
B(-6,8,-2,minecraft:netherrack)
B(-6,9,-2,minecraft:netherrack)
B(-6,10,-2,minecraft:netherrack)
B(-6,11,-2,minecraft:netherrack)
B(-6,12,-2,minecraft:netherrack)
B(-6,13,-2,minecraft:netherrack)
B(-6,14,-2,minecraft:netherrack)
B(-6,15,-2,minecraft:netherrack)
B(-6,16,-2,minecraft:netherrack)
B(-6,17,-2,minecraft:netherrack)
B(-6,18,-2,minecraft:netherrack)
B(-6,19,-2,minecraft:netherrack)
B(-6,20,-2,minecraft:netherrack)
B(-6,21,-2,minecraft:netherrack)
B(-6,22,-2,minecraft:netherrack)
B(-6,23,-2,minecraft:netherrack)
B(-6,24,-2,minecraft:netherrack)
B(-6,25,-2,minecraft:netherrack)
B(-6,26,-2,minecraft:netherrack)
B(-6,27,-2,minecraft:netherrack)
B(-6,28,-2,minecraft:netherrack)
B(-6,29,-2,minecraft:netherrack)
B(-6,30,-2,minecraft:netherrack)
B(-6,31,-2,minecraft:netherrack)
B(-6,32,-2,minecraft:netherrack)
B(-6,33,-2,minecraft:netherrack)
B(-6,34,-2,minecraft:netherrack)
B(-6,35,-2,minecraft:netherrack)
B(-6,0,-1,minecraft:netherrack)
B(-6,1,-1,minecraft:netherrack)
B(-6,2,-1,minecraft:netherrack)
B(-6,3,-1,minecraft:netherrack)
B(-6,4,-1,minecraft:netherrack)
B(-6,5,-1,minecraft:netherrack)
B(-6,6,-1,minecraft:netherrack)
B(-6,7,-1,minecraft:netherrack)
B(-6,8,-1,minecraft:netherrack)
B(-6,9,-1,minecraft:netherrack)
B(-6,10,-1,minecraft:netherrack)
B(-6,11,-1,minecraft:netherrack)
B(-6,12,-1,minecraft:netherrack)
B(-6,13,-1,minecraft:netherrack)
B(-6,14,-1,minecraft:netherrack)
B(-6,15,-1,minecraft:netherrack)
B(-6,16,-1,minecraft:netherrack)
B(-6,17,-1,minecraft:netherrack)
B(-6,18,-1,minecraft:netherrack)
B(-6,19,-1,minecraft:netherrack)
B(-6,20,-1,minecraft:netherrack)
B(-6,21,-1,minecraft:netherrack)
B(-6,22,-1,minecraft:netherrack)
B(-6,23,-1,minecraft:netherrack)
B(-6,24,-1,minecraft:netherrack)
B(-6,25,-1,minecraft:netherrack)
B(-6,26,-1,minecraft:netherrack)
B(-6,27,-1,minecraft:netherrack)
B(-6,28,-1,minecraft:netherrack)
B(-6,29,-1,minecraft:netherrack)
B(-6,30,-1,minecraft:netherrack)
B(-6,31,-1,minecraft:netherrack)
B(-6,32,-1,minecraft:netherrack)
B(-6,33,-1,minecraft:netherrack)
B(-6,34,-1,minecraft:lava)
B(-6,35,-1,minecraft:lava)
B(-6,0,0,minecraft:netherrack)
B(-6,1,0,minecraft:netherrack)
B(-6,2,0,minecraft:netherrack)
B(-6,3,0,minecraft:netherrack)
B(-6,4,0,minecraft:netherrack)
B(-6,5,0,minecraft:netherrack)
B(-6,6,0,minecraft:netherrack)
B(-6,7,0,minecraft:netherrack)
B(-6,8,0,minecraft:netherrack)
B(-6,9,0,minecraft:netherrack)
B(-6,10,0,minecraft:netherrack)
B(-6,11,0,minecraft:netherrack)
B(-6,12,0,minecraft:netherrack)
B(-6,13,0,minecraft:netherrack)
B(-6,14,0,minecraft:netherrack)
B(-6,15,0,minecraft:netherrack)
B(-6,16,0,minecraft:netherrack)
B(-6,17,0,minecraft:netherrack)
B(-6,18,0,minecraft:netherrack)
B(-6,19,0,minecraft:netherrack)
B(-6,20,0,minecraft:netherrack)
B(-6,21,0,minecraft:netherrack)
B(-6,22,0,minecraft:netherrack)
B(-6,23,0,minecraft:netherrack)
B(-6,24,0,minecraft:netherrack)
B(-6,25,0,minecraft:netherrack)
B(-6,26,0,minecraft:netherrack)
B(-6,27,0,minecraft:netherrack)
B(-6,28,0,minecraft:netherrack)
B(-6,29,0,minecraft:netherrack)
B(-6,30,0,minecraft:netherrack)
B(-6,31,0,minecraft:netherrack)
B(-6,32,0,minecraft:netherrack)
B(-6,33,0,minecraft:lava)
B(-6,34,0,minecraft:lava)
B(-6,35,0,minecraft:lava)
B(-6,0,1,minecraft:netherrack)
B(-6,1,1,minecraft:netherrack)
B(-6,2,1,minecraft:netherrack)
B(-6,3,1,minecraft:netherrack)
B(-6,4,1,minecraft:netherrack)
B(-6,5,1,minecraft:netherrack)
B(-6,6,1,minecraft:netherrack)
B(-6,7,1,minecraft:netherrack)
B(-6,8,1,minecraft:netherrack)
B(-6,9,1,minecraft:netherrack)
B(-6,10,1,minecraft:netherrack)
B(-6,11,1,minecraft:netherrack)
B(-6,12,1,minecraft:netherrack)
B(-6,13,1,minecraft:netherrack)
B(-6,14,1,minecraft:netherrack)
B(-6,15,1,minecraft:netherrack)
B(-6,16,1,minecraft:netherrack)
B(-6,17,1,minecraft:netherrack)
B(-6,18,1,minecraft:netherrack)
B(-6,19,1,minecraft:netherrack)
B(-6,20,1,minecraft:netherrack)
B(-6,21,1,minecraft:netherrack)
B(-6,22,1,minecraft:netherrack)
B(-6,23,1,minecraft:netherrack)
B(-6,24,1,minecraft:netherrack)
B(-6,25,1,minecraft:netherrack)
B(-6,26,1,minecraft:netherrack)
B(-6,27,1,minecraft:netherrack)
B(-6,28,1,minecraft:netherrack)
B(-6,29,1,minecraft:netherrack)
B(-6,30,1,minecraft:netherrack)
B(-6,31,1,minecraft:netherrack)
B(-6,32,1,minecraft:lava)
B(-6,33,1,minecraft:lava)
B(-6,34,1,minecraft:lava)
B(-6,35,1,minecraft:lava)
B(-6,0,2,minecraft:netherrack)
B(-6,1,2,minecraft:netherrack)
B(-6,2,2,minecraft:netherrack)
B(-6,3,2,minecraft:netherrack)
B(-6,4,2,minecraft:netherrack)
B(-6,5,2,minecraft:netherrack)
B(-6,6,2,minecraft:netherrack)
B(-6,7,2,minecraft:netherrack)
B(-6,8,2,minecraft:netherrack)
B(-6,9,2,minecraft:netherrack)
B(-6,10,2,minecraft:netherrack)
B(-6,11,2,minecraft:netherrack)
B(-6,12,2,minecraft:netherrack)
B(-6,13,2,minecraft:netherrack)
B(-6,14,2,minecraft:netherrack)
B(-6,15,2,minecraft:netherrack)
B(-6,16,2,minecraft:netherrack)
B(-6,17,2,minecraft:netherrack)
B(-6,18,2,minecraft:netherrack)
B(-6,19,2,minecraft:netherrack)
B(-6,20,2,minecraft:netherrack)
B(-6,21,2,minecraft:netherrack)
B(-6,22,2,minecraft:netherrack)
B(-6,23,2,minecraft:netherrack)
B(-6,24,2,minecraft:netherrack)
B(-6,25,2,minecraft:netherrack)
B(-6,26,2,minecraft:netherrack)
B(-6,27,2,minecraft:netherrack)
B(-6,28,2,minecraft:netherrack)
B(-6,29,2,minecraft:netherrack)
B(-6,30,2,minecraft:netherrack)
B(-6,31,2,minecraft:lava)
B(-6,32,2,minecraft:lava)
B(-6,33,2,minecraft:lava)
B(-6,34,2,minecraft:lava)
B(-6,35,2,minecraft:lava)
B(-6,0,3,minecraft:netherrack)
B(-6,1,3,minecraft:netherrack)
B(-6,2,3,minecraft:netherrack)
B(-6,3,3,minecraft:netherrack)
B(-6,4,3,minecraft:netherrack)
B(-6,5,3,minecraft:netherrack)
B(-6,6,3,minecraft:netherrack)
B(-6,7,3,minecraft:netherrack)
B(-6,8,3,minecraft:netherrack)
B(-6,9,3,minecraft:netherrack)
B(-6,10,3,minecraft:netherrack)
B(-6,11,3,minecraft:netherrack)
B(-6,12,3,minecraft:netherrack)
B(-6,13,3,minecraft:netherrack)
B(-6,14,3,minecraft:netherrack)
B(-6,15,3,minecraft:netherrack)
B(-6,16,3,minecraft:netherrack)
B(-6,17,3,minecraft:netherrack)
B(-6,18,3,minecraft:netherrack)
B(-6,19,3,minecraft:netherrack)
B(-6,20,3,minecraft:netherrack)
B(-6,21,3,minecraft:netherrack)
B(-6,22,3,minecraft:netherrack)
B(-6,23,3,minecraft:netherrack)
B(-6,24,3,minecraft:netherrack)
B(-6,25,3,minecraft:netherrack)
B(-6,26,3,minecraft:netherrack)
B(-6,27,3,minecraft:netherrack)
B(-6,28,3,minecraft:netherrack)
B(-6,29,3,minecraft:netherrack)
B(-6,30,3,minecraft:lava)
B(-6,31,3,minecraft:lava)
B(-6,32,3,minecraft:lava)
B(-6,33,3,minecraft:lava)
B(-6,34,3,minecraft:lava)
B(-6,35,3,minecraft:lava)
B(-6,0,4,minecraft:netherrack)
B(-6,1,4,minecraft:netherrack)
B(-6,2,4,minecraft:netherrack)
B(-6,3,4,minecraft:netherrack)
B(-6,4,4,minecraft:netherrack)
B(-6,5,4,minecraft:netherrack)
B(-6,6,4,minecraft:netherrack)
B(-6,7,4,minecraft:netherrack)
B(-6,8,4,minecraft:netherrack)
B(-6,9,4,minecraft:netherrack)
B(-6,10,4,minecraft:netherrack)
B(-6,11,4,minecraft:netherrack)
B(-6,12,4,minecraft:netherrack)
B(-6,13,4,minecraft:netherrack)
B(-6,14,4,minecraft:netherrack)
B(-6,15,4,minecraft:netherrack)
B(-6,16,4,minecraft:netherrack)
B(-6,17,4,minecraft:netherrack)
B(-6,18,4,minecraft:netherrack)
B(-6,19,4,minecraft:netherrack)
B(-6,20,4,minecraft:netherrack)
B(-6,21,4,minecraft:netherrack)
B(-6,22,4,minecraft:netherrack)
B(-6,23,4,minecraft:netherrack)
B(-6,24,4,minecraft:netherrack)
B(-6,25,4,minecraft:netherrack)
B(-6,26,4,minecraft:netherrack)
B(-6,27,4,minecraft:netherrack)
B(-6,28,4,minecraft:netherrack)
B(-6,29,4,minecraft:lava)
B(-6,30,4,minecraft:lava)
B(-6,31,4,minecraft:lava)
B(-6,32,4,minecraft:lava)
B(-6,33,4,minecraft:lava)
B(-6,34,4,minecraft:lava)
B(-6,35,4,minecraft:lava)
B(-6,0,5,minecraft:netherrack)
B(-6,1,5,minecraft:netherrack)
B(-6,2,5,minecraft:netherrack)
B(-6,3,5,minecraft:netherrack)
B(-6,4,5,minecraft:netherrack)
B(-6,5,5,minecraft:netherrack)
B(-6,6,5,minecraft:netherrack)
B(-6,7,5,minecraft:netherrack)
B(-6,8,5,minecraft:netherrack)
B(-6,9,5,minecraft:netherrack)
B(-6,10,5,minecraft:netherrack)
B(-6,11,5,minecraft:netherrack)
B(-6,12,5,minecraft:netherrack)
B(-6,13,5,minecraft:netherrack)
B(-6,14,5,minecraft:netherrack)
B(-6,15,5,minecraft:netherrack)
B(-6,16,5,minecraft:netherrack)
B(-6,17,5,minecraft:netherrack)
B(-6,18,5,minecraft:netherrack)
B(-6,19,5,minecraft:netherrack)
B(-6,20,5,minecraft:netherrack)
B(-6,21,5,minecraft:netherrack)
B(-6,22,5,minecraft:netherrack)
B(-6,23,5,minecraft:netherrack)
B(-6,24,5,minecraft:netherrack)
B(-6,25,5,minecraft:netherrack)
B(-6,26,5,minecraft:netherrack)
B(-6,27,5,minecraft:netherrack)
B(-6,28,5,minecraft:lava)
B(-6,29,5,minecraft:lava)
B(-6,30,5,minecraft:lava)
B(-6,31,5,minecraft:lava)
B(-6,32,5,minecraft:lava)
B(-6,33,5,minecraft:lava)
B(-6,34,5,minecraft:lava)
B(-6,35,5,minecraft:lava)
B(-6,0,6,minecraft:netherrack)
B(-6,1,6,minecraft:netherrack)
B(-6,2,6,minecraft:netherrack)
B(-6,3,6,minecraft:netherrack)
B(-6,4,6,minecraft:netherrack)
B(-6,5,6,minecraft:netherrack)
B(-6,6,6,minecraft:netherrack)
B(-6,7,6,minecraft:netherrack)
B(-6,8,6,minecraft:netherrack)
B(-6,9,6,minecraft:netherrack)
B(-6,10,6,minecraft:netherrack)
B(-6,11,6,minecraft:netherrack)
B(-6,12,6,minecraft:netherrack)
B(-6,13,6,minecraft:netherrack)
B(-6,14,6,minecraft:netherrack)
B(-6,15,6,minecraft:netherrack)
B(-6,16,6,minecraft:netherrack)
B(-6,17,6,minecraft:netherrack)
B(-6,18,6,minecraft:netherrack)
B(-6,19,6,minecraft:netherrack)
B(-6,20,6,minecraft:netherrack)
B(-6,21,6,minecraft:netherrack)
B(-6,22,6,minecraft:netherrack)
B(-6,23,6,minecraft:netherrack)
B(-6,24,6,minecraft:netherrack)
B(-6,25,6,minecraft:netherrack)
B(-6,26,6,minecraft:netherrack)
B(-6,27,6,minecraft:netherrack)
B(-6,28,6,minecraft:lava)
B(-6,29,6,minecraft:lava)
B(-6,30,6,minecraft:lava)
B(-6,31,6,minecraft:lava)
B(-6,32,6,minecraft:lava)
B(-6,33,6,minecraft:lava)
B(-6,34,6,minecraft:lava)
B(-6,35,6,minecraft:lava)
B(-6,0,7,minecraft:netherrack)
B(-6,1,7,minecraft:netherrack)
B(-6,2,7,minecraft:netherrack)
B(-6,3,7,minecraft:netherrack)
B(-6,4,7,minecraft:netherrack)
B(-6,5,7,minecraft:netherrack)
B(-6,6,7,minecraft:netherrack)
B(-6,7,7,minecraft:netherrack)
B(-6,8,7,minecraft:netherrack)
B(-6,9,7,minecraft:netherrack)
B(-6,10,7,minecraft:netherrack)
B(-6,11,7,minecraft:netherrack)
B(-6,12,7,minecraft:netherrack)
B(-6,13,7,minecraft:netherrack)
B(-6,14,7,minecraft:netherrack)
B(-6,15,7,minecraft:netherrack)
B(-6,16,7,minecraft:netherrack)
B(-6,17,7,minecraft:netherrack)
B(-6,18,7,minecraft:netherrack)
B(-6,19,7,minecraft:netherrack)
B(-6,20,7,minecraft:netherrack)
B(-6,21,7,minecraft:netherrack)
B(-6,22,7,minecraft:netherrack)
B(-6,23,7,minecraft:netherrack)
B(-6,24,7,minecraft:netherrack)
B(-6,25,7,minecraft:netherrack)
B(-6,26,7,minecraft:netherrack)
B(-6,27,7,minecraft:netherrack)
B(-6,28,7,minecraft:lava)
B(-6,29,7,minecraft:lava)
B(-6,30,7,minecraft:lava)
B(-6,31,7,minecraft:lava)
B(-6,32,7,minecraft:lava)
B(-6,33,7,minecraft:lava)
B(-6,34,7,minecraft:lava)
B(-6,35,7,minecraft:lava)
B(-6,0,8,minecraft:netherrack)
B(-6,1,8,minecraft:netherrack)
B(-6,2,8,minecraft:netherrack)
B(-6,3,8,minecraft:netherrack)
B(-6,4,8,minecraft:netherrack)
B(-6,5,8,minecraft:netherrack)
B(-6,6,8,minecraft:netherrack)
B(-6,7,8,minecraft:netherrack)
B(-6,8,8,minecraft:netherrack)
B(-6,9,8,minecraft:netherrack)
B(-6,10,8,minecraft:netherrack)
B(-6,11,8,minecraft:netherrack)
B(-6,12,8,minecraft:netherrack)
B(-6,13,8,minecraft:netherrack)
B(-6,14,8,minecraft:netherrack)
B(-6,15,8,minecraft:netherrack)
B(-6,16,8,minecraft:netherrack)
B(-6,17,8,minecraft:netherrack)
B(-6,18,8,minecraft:netherrack)
B(-6,19,8,minecraft:netherrack)
B(-6,20,8,minecraft:netherrack)
B(-6,21,8,minecraft:netherrack)
B(-6,22,8,minecraft:netherrack)
B(-6,23,8,minecraft:netherrack)
B(-6,24,8,minecraft:netherrack)
B(-6,25,8,minecraft:netherrack)
B(-6,26,8,minecraft:netherrack)
B(-6,27,8,minecraft:netherrack)
B(-6,28,8,minecraft:lava)
B(-6,29,8,minecraft:lava)
B(-6,30,8,minecraft:lava)
B(-6,31,8,minecraft:lava)
B(-6,32,8,minecraft:lava)
B(-6,33,8,minecraft:lava)
B(-6,34,8,minecraft:lava)
B(-6,35,8,minecraft:lava)
B(-5,0,-7,minecraft:netherrack)
B(-5,1,-7,minecraft:netherrack)
B(-5,2,-7,minecraft:netherrack)
B(-5,3,-7,minecraft:netherrack)
B(-5,4,-7,minecraft:netherrack)
B(-5,5,-7,minecraft:netherrack)
B(-5,6,-7,minecraft:netherrack)
B(-5,7,-7,minecraft:netherrack)
B(-5,8,-7,minecraft:netherrack)
B(-5,9,-7,minecraft:netherrack)
B(-5,10,-7,minecraft:netherrack)
B(-5,11,-7,minecraft:netherrack)
B(-5,12,-7,minecraft:netherrack)
B(-5,13,-7,minecraft:netherrack)
B(-5,14,-7,minecraft:netherrack)
B(-5,15,-7,minecraft:netherrack)
B(-5,16,-7,minecraft:netherrack)
B(-5,17,-7,minecraft:netherrack)
B(-5,18,-7,minecraft:netherrack)
B(-5,19,-7,minecraft:netherrack)
B(-5,20,-7,minecraft:netherrack)
B(-5,21,-7,minecraft:netherrack)
B(-5,22,-7,minecraft:netherrack)
B(-5,23,-7,minecraft:netherrack)
B(-5,24,-7,minecraft:netherrack)
B(-5,25,-7,minecraft:netherrack)
B(-5,26,-7,minecraft:netherrack)
B(-5,27,-7,minecraft:netherrack)
B(-5,28,-7,minecraft:netherrack)
B(-5,29,-7,minecraft:netherrack)
B(-5,30,-7,minecraft:netherrack)
B(-5,31,-7,minecraft:netherrack)
B(-5,32,-7,minecraft:netherrack)
B(-5,33,-7,minecraft:netherrack)
B(-5,34,-7,minecraft:netherrack)
B(-5,0,-6,minecraft:netherrack)
B(-5,1,-6,minecraft:netherrack)
B(-5,2,-6,minecraft:netherrack)
B(-5,3,-6,minecraft:netherrack)
B(-5,4,-6,minecraft:netherrack)
B(-5,5,-6,minecraft:netherrack)
B(-5,6,-6,minecraft:netherrack)
B(-5,7,-6,minecraft:netherrack)
B(-5,8,-6,minecraft:netherrack)
B(-5,9,-6,minecraft:netherrack)
B(-5,10,-6,minecraft:netherrack)
B(-5,11,-6,minecraft:netherrack)
B(-5,12,-6,minecraft:netherrack)
B(-5,13,-6,minecraft:netherrack)
B(-5,14,-6,minecraft:netherrack)
B(-5,15,-6,minecraft:netherrack)
B(-5,16,-6,minecraft:netherrack)
B(-5,17,-6,minecraft:netherrack)
B(-5,18,-6,minecraft:netherrack)
B(-5,19,-6,minecraft:netherrack)
B(-5,20,-6,minecraft:netherrack)
B(-5,21,-6,minecraft:netherrack)
B(-5,22,-6,minecraft:netherrack)
B(-5,23,-6,minecraft:netherrack)
B(-5,24,-6,minecraft:netherrack)
B(-5,25,-6,minecraft:netherrack)
B(-5,26,-6,minecraft:netherrack)
B(-5,27,-6,minecraft:netherrack)
B(-5,28,-6,minecraft:netherrack)
B(-5,29,-6,minecraft:netherrack)
B(-5,30,-6,minecraft:netherrack)
B(-5,31,-6,minecraft:netherrack)
B(-5,32,-6,minecraft:netherrack)
B(-5,33,-6,minecraft:netherrack)
B(-5,34,-6,minecraft:netherrack)
B(-5,35,-6,minecraft:netherrack)
B(-5,0,-5,minecraft:netherrack)
B(-5,1,-5,minecraft:netherrack)
B(-5,2,-5,minecraft:netherrack)
B(-5,3,-5,minecraft:netherrack)
B(-5,4,-5,minecraft:netherrack)
B(-5,5,-5,minecraft:netherrack)
B(-5,6,-5,minecraft:netherrack)
B(-5,7,-5,minecraft:netherrack)
B(-5,8,-5,minecraft:netherrack)
B(-5,9,-5,minecraft:netherrack)
B(-5,10,-5,minecraft:netherrack)
B(-5,11,-5,minecraft:netherrack)
B(-5,12,-5,minecraft:netherrack)
B(-5,13,-5,minecraft:netherrack)
B(-5,14,-5,minecraft:netherrack)
B(-5,15,-5,minecraft:netherrack)
B(-5,16,-5,minecraft:netherrack)
B(-5,17,-5,minecraft:netherrack)
B(-5,18,-5,minecraft:netherrack)
B(-5,19,-5,minecraft:netherrack)
B(-5,20,-5,minecraft:netherrack)
B(-5,21,-5,minecraft:netherrack)
B(-5,22,-5,minecraft:netherrack)
B(-5,23,-5,minecraft:netherrack)
B(-5,24,-5,minecraft:netherrack)
B(-5,25,-5,minecraft:netherrack)
B(-5,26,-5,minecraft:netherrack)
B(-5,27,-5,minecraft:netherrack)
B(-5,28,-5,minecraft:netherrack)
B(-5,29,-5,minecraft:netherrack)
B(-5,30,-5,minecraft:netherrack)
B(-5,31,-5,minecraft:netherrack)
B(-5,32,-5,minecraft:netherrack)
B(-5,33,-5,minecraft:netherrack)
B(-5,34,-5,minecraft:netherrack)
B(-5,35,-5,minecraft:netherrack)
B(-5,36,-5,minecraft:netherrack)
B(-5,0,-4,minecraft:netherrack)
B(-5,1,-4,minecraft:netherrack)
B(-5,2,-4,minecraft:netherrack)
B(-5,3,-4,minecraft:netherrack)
B(-5,4,-4,minecraft:netherrack)
B(-5,5,-4,minecraft:netherrack)
B(-5,6,-4,minecraft:netherrack)
B(-5,7,-4,minecraft:netherrack)
B(-5,8,-4,minecraft:netherrack)
B(-5,9,-4,minecraft:netherrack)
B(-5,10,-4,minecraft:netherrack)
B(-5,11,-4,minecraft:netherrack)
B(-5,12,-4,minecraft:netherrack)
B(-5,13,-4,minecraft:netherrack)
B(-5,14,-4,minecraft:netherrack)
B(-5,15,-4,minecraft:netherrack)
B(-5,16,-4,minecraft:netherrack)
B(-5,17,-4,minecraft:netherrack)
B(-5,18,-4,minecraft:netherrack)
B(-5,19,-4,minecraft:netherrack)
B(-5,20,-4,minecraft:netherrack)
B(-5,21,-4,minecraft:netherrack)
B(-5,22,-4,minecraft:netherrack)
B(-5,23,-4,minecraft:netherrack)
B(-5,24,-4,minecraft:netherrack)
B(-5,25,-4,minecraft:netherrack)
B(-5,26,-4,minecraft:netherrack)
B(-5,27,-4,minecraft:netherrack)
B(-5,28,-4,minecraft:netherrack)
B(-5,29,-4,minecraft:netherrack)
B(-5,30,-4,minecraft:netherrack)
B(-5,31,-4,minecraft:netherrack)
B(-5,32,-4,minecraft:netherrack)
B(-5,33,-4,minecraft:netherrack)
B(-5,34,-4,minecraft:netherrack)
B(-5,35,-4,minecraft:netherrack)
B(-5,36,-4,minecraft:netherrack)
B(-5,0,-3,minecraft:netherrack)
B(-5,1,-3,minecraft:netherrack)
B(-5,2,-3,minecraft:netherrack)
B(-5,3,-3,minecraft:netherrack)
B(-5,4,-3,minecraft:netherrack)
B(-5,5,-3,minecraft:netherrack)
B(-5,6,-3,minecraft:netherrack)
B(-5,7,-3,minecraft:netherrack)
B(-5,8,-3,minecraft:netherrack)
B(-5,9,-3,minecraft:netherrack)
B(-5,10,-3,minecraft:netherrack)
B(-5,11,-3,minecraft:netherrack)
B(-5,12,-3,minecraft:netherrack)
B(-5,13,-3,minecraft:netherrack)
B(-5,14,-3,minecraft:netherrack)
B(-5,15,-3,minecraft:netherrack)
B(-5,16,-3,minecraft:netherrack)
B(-5,17,-3,minecraft:netherrack)
B(-5,18,-3,minecraft:netherrack)
B(-5,19,-3,minecraft:netherrack)
B(-5,20,-3,minecraft:netherrack)
B(-5,21,-3,minecraft:netherrack)
B(-5,22,-3,minecraft:netherrack)
B(-5,23,-3,minecraft:netherrack)
B(-5,24,-3,minecraft:netherrack)
B(-5,25,-3,minecraft:netherrack)
B(-5,26,-3,minecraft:netherrack)
B(-5,27,-3,minecraft:netherrack)
B(-5,28,-3,minecraft:netherrack)
B(-5,29,-3,minecraft:netherrack)
B(-5,30,-3,minecraft:netherrack)
B(-5,31,-3,minecraft:netherrack)
B(-5,32,-3,minecraft:netherrack)
B(-5,33,-3,minecraft:netherrack)
B(-5,34,-3,minecraft:netherrack)
B(-5,35,-3,minecraft:netherrack)
B(-5,0,-2,minecraft:netherrack)
B(-5,1,-2,minecraft:netherrack)
B(-5,2,-2,minecraft:netherrack)
B(-5,3,-2,minecraft:netherrack)
B(-5,4,-2,minecraft:netherrack)
B(-5,5,-2,minecraft:netherrack)
B(-5,6,-2,minecraft:netherrack)
B(-5,7,-2,minecraft:netherrack)
B(-5,8,-2,minecraft:netherrack)
B(-5,9,-2,minecraft:netherrack)
B(-5,10,-2,minecraft:netherrack)
B(-5,11,-2,minecraft:netherrack)
B(-5,12,-2,minecraft:netherrack)
B(-5,13,-2,minecraft:netherrack)
B(-5,14,-2,minecraft:netherrack)
B(-5,15,-2,minecraft:netherrack)
B(-5,16,-2,minecraft:netherrack)
B(-5,17,-2,minecraft:netherrack)
B(-5,18,-2,minecraft:netherrack)
B(-5,19,-2,minecraft:netherrack)
B(-5,20,-2,minecraft:netherrack)
B(-5,21,-2,minecraft:netherrack)
B(-5,22,-2,minecraft:netherrack)
B(-5,23,-2,minecraft:netherrack)
B(-5,24,-2,minecraft:netherrack)
B(-5,25,-2,minecraft:netherrack)
B(-5,26,-2,minecraft:netherrack)
B(-5,27,-2,minecraft:netherrack)
B(-5,28,-2,minecraft:netherrack)
B(-5,29,-2,minecraft:netherrack)
B(-5,30,-2,minecraft:netherrack)
B(-5,31,-2,minecraft:netherrack)
B(-5,32,-2,minecraft:netherrack)
B(-5,33,-2,minecraft:netherrack)
B(-5,34,-2,minecraft:netherrack)
B(-5,35,-2,minecraft:netherrack)
B(-5,0,-1,minecraft:netherrack)
B(-5,1,-1,minecraft:netherrack)
B(-5,2,-1,minecraft:netherrack)
B(-5,3,-1,minecraft:netherrack)
B(-5,4,-1,minecraft:netherrack)
B(-5,5,-1,minecraft:netherrack)
B(-5,6,-1,minecraft:netherrack)
B(-5,7,-1,minecraft:netherrack)
B(-5,8,-1,minecraft:netherrack)
B(-5,9,-1,minecraft:netherrack)
B(-5,10,-1,minecraft:netherrack)
B(-5,11,-1,minecraft:netherrack)
B(-5,12,-1,minecraft:netherrack)
B(-5,13,-1,minecraft:netherrack)
B(-5,14,-1,minecraft:netherrack)
B(-5,15,-1,minecraft:netherrack)
B(-5,16,-1,minecraft:netherrack)
B(-5,17,-1,minecraft:netherrack)
B(-5,18,-1,minecraft:netherrack)
B(-5,19,-1,minecraft:netherrack)
B(-5,20,-1,minecraft:netherrack)
B(-5,21,-1,minecraft:netherrack)
B(-5,22,-1,minecraft:netherrack)
B(-5,23,-1,minecraft:netherrack)
B(-5,24,-1,minecraft:netherrack)
B(-5,25,-1,minecraft:netherrack)
B(-5,26,-1,minecraft:netherrack)
B(-5,27,-1,minecraft:netherrack)
B(-5,28,-1,minecraft:netherrack)
B(-5,29,-1,minecraft:netherrack)
B(-5,30,-1,minecraft:netherrack)
B(-5,31,-1,minecraft:netherrack)
B(-5,32,-1,minecraft:netherrack)
B(-5,33,-1,minecraft:netherrack)
B(-5,34,-1,minecraft:netherrack)
B(-5,35,-1,minecraft:lava)
B(-5,0,0,minecraft:netherrack)
B(-5,1,0,minecraft:netherrack)
B(-5,2,0,minecraft:netherrack)
B(-5,3,0,minecraft:netherrack)
B(-5,4,0,minecraft:netherrack)
B(-5,5,0,minecraft:netherrack)
B(-5,6,0,minecraft:netherrack)
B(-5,7,0,minecraft:netherrack)
B(-5,8,0,minecraft:netherrack)
B(-5,9,0,minecraft:netherrack)
B(-5,10,0,minecraft:netherrack)
B(-5,11,0,minecraft:netherrack)
B(-5,12,0,minecraft:netherrack)
B(-5,13,0,minecraft:netherrack)
B(-5,14,0,minecraft:netherrack)
B(-5,15,0,minecraft:netherrack)
B(-5,16,0,minecraft:netherrack)
B(-5,17,0,minecraft:netherrack)
B(-5,18,0,minecraft:netherrack)
B(-5,19,0,minecraft:netherrack)
B(-5,20,0,minecraft:netherrack)
B(-5,21,0,minecraft:netherrack)
B(-5,22,0,minecraft:netherrack)
B(-5,23,0,minecraft:netherrack)
B(-5,24,0,minecraft:netherrack)
B(-5,25,0,minecraft:netherrack)
B(-5,26,0,minecraft:netherrack)
B(-5,27,0,minecraft:netherrack)
B(-5,28,0,minecraft:netherrack)
B(-5,29,0,minecraft:netherrack)
B(-5,30,0,minecraft:netherrack)
B(-5,31,0,minecraft:netherrack)
B(-5,32,0,minecraft:netherrack)
B(-5,33,0,minecraft:lava)
B(-5,34,0,minecraft:lava)
B(-5,35,0,minecraft:lava)
B(-5,0,1,minecraft:netherrack)
B(-5,1,1,minecraft:netherrack)
B(-5,2,1,minecraft:netherrack)
B(-5,3,1,minecraft:netherrack)
B(-5,4,1,minecraft:netherrack)
B(-5,5,1,minecraft:netherrack)
B(-5,6,1,minecraft:netherrack)
B(-5,7,1,minecraft:netherrack)
B(-5,8,1,minecraft:netherrack)
B(-5,9,1,minecraft:netherrack)
B(-5,10,1,minecraft:netherrack)
B(-5,11,1,minecraft:netherrack)
B(-5,12,1,minecraft:netherrack)
B(-5,13,1,minecraft:netherrack)
B(-5,14,1,minecraft:netherrack)
B(-5,15,1,minecraft:netherrack)
B(-5,16,1,minecraft:netherrack)
B(-5,17,1,minecraft:netherrack)
B(-5,18,1,minecraft:netherrack)
B(-5,19,1,minecraft:netherrack)
B(-5,20,1,minecraft:netherrack)
B(-5,21,1,minecraft:netherrack)
B(-5,22,1,minecraft:netherrack)
B(-5,23,1,minecraft:netherrack)
B(-5,24,1,minecraft:netherrack)
B(-5,25,1,minecraft:netherrack)
B(-5,26,1,minecraft:netherrack)
B(-5,27,1,minecraft:netherrack)
B(-5,28,1,minecraft:netherrack)
B(-5,29,1,minecraft:netherrack)
B(-5,30,1,minecraft:netherrack)
B(-5,31,1,minecraft:netherrack)
B(-5,32,1,minecraft:lava)
B(-5,33,1,minecraft:lava)
B(-5,34,1,minecraft:lava)
B(-5,35,1,minecraft:lava)
B(-5,0,2,minecraft:netherrack)
B(-5,1,2,minecraft:netherrack)
B(-5,2,2,minecraft:netherrack)
B(-5,3,2,minecraft:netherrack)
B(-5,4,2,minecraft:netherrack)
B(-5,5,2,minecraft:netherrack)
B(-5,6,2,minecraft:netherrack)
B(-5,7,2,minecraft:netherrack)
B(-5,8,2,minecraft:netherrack)
B(-5,9,2,minecraft:netherrack)
B(-5,10,2,minecraft:netherrack)
B(-5,11,2,minecraft:netherrack)
B(-5,12,2,minecraft:netherrack)
B(-5,13,2,minecraft:netherrack)
B(-5,14,2,minecraft:netherrack)
B(-5,15,2,minecraft:netherrack)
B(-5,16,2,minecraft:netherrack)
B(-5,17,2,minecraft:netherrack)
B(-5,18,2,minecraft:netherrack)
B(-5,19,2,minecraft:netherrack)
B(-5,20,2,minecraft:netherrack)
B(-5,21,2,minecraft:netherrack)
B(-5,22,2,minecraft:netherrack)
B(-5,23,2,minecraft:netherrack)
B(-5,24,2,minecraft:netherrack)
B(-5,25,2,minecraft:netherrack)
B(-5,26,2,minecraft:netherrack)
B(-5,27,2,minecraft:netherrack)
B(-5,28,2,minecraft:netherrack)
B(-5,29,2,minecraft:netherrack)
B(-5,30,2,minecraft:netherrack)
B(-5,31,2,minecraft:lava)
B(-5,32,2,minecraft:lava)
B(-5,33,2,minecraft:lava)
B(-5,34,2,minecraft:lava)
B(-5,35,2,minecraft:lava)
B(-5,0,3,minecraft:netherrack)
B(-5,1,3,minecraft:netherrack)
B(-5,2,3,minecraft:netherrack)
B(-5,3,3,minecraft:netherrack)
B(-5,4,3,minecraft:netherrack)
B(-5,5,3,minecraft:netherrack)
B(-5,6,3,minecraft:netherrack)
B(-5,7,3,minecraft:netherrack)
B(-5,8,3,minecraft:netherrack)
B(-5,9,3,minecraft:netherrack)
B(-5,10,3,minecraft:netherrack)
B(-5,11,3,minecraft:netherrack)
B(-5,12,3,minecraft:netherrack)
B(-5,13,3,minecraft:netherrack)
B(-5,14,3,minecraft:netherrack)
B(-5,15,3,minecraft:netherrack)
B(-5,16,3,minecraft:netherrack)
B(-5,17,3,minecraft:netherrack)
B(-5,18,3,minecraft:netherrack)
B(-5,19,3,minecraft:netherrack)
B(-5,20,3,minecraft:netherrack)
B(-5,21,3,minecraft:netherrack)
B(-5,22,3,minecraft:netherrack)
B(-5,23,3,minecraft:netherrack)
B(-5,24,3,minecraft:netherrack)
B(-5,25,3,minecraft:netherrack)
B(-5,26,3,minecraft:netherrack)
B(-5,27,3,minecraft:netherrack)
B(-5,28,3,minecraft:netherrack)
B(-5,29,3,minecraft:netherrack)
B(-5,30,3,minecraft:lava)
B(-5,31,3,minecraft:lava)
B(-5,32,3,minecraft:lava)
B(-5,33,3,minecraft:lava)
B(-5,34,3,minecraft:lava)
B(-5,35,3,minecraft:lava)
B(-5,0,4,minecraft:netherrack)
B(-5,1,4,minecraft:netherrack)
B(-5,2,4,minecraft:netherrack)
B(-5,3,4,minecraft:netherrack)
B(-5,4,4,minecraft:netherrack)
B(-5,5,4,minecraft:netherrack)
B(-5,6,4,minecraft:netherrack)
B(-5,7,4,minecraft:netherrack)
B(-5,8,4,minecraft:netherrack)
B(-5,9,4,minecraft:netherrack)
B(-5,10,4,minecraft:netherrack)
B(-5,11,4,minecraft:netherrack)
B(-5,12,4,minecraft:netherrack)
B(-5,13,4,minecraft:netherrack)
B(-5,14,4,minecraft:netherrack)
B(-5,15,4,minecraft:netherrack)
B(-5,16,4,minecraft:netherrack)
B(-5,17,4,minecraft:netherrack)
B(-5,18,4,minecraft:netherrack)
B(-5,19,4,minecraft:netherrack)
B(-5,20,4,minecraft:netherrack)
B(-5,21,4,minecraft:netherrack)
B(-5,22,4,minecraft:netherrack)
B(-5,23,4,minecraft:netherrack)
B(-5,24,4,minecraft:netherrack)
B(-5,25,4,minecraft:netherrack)
B(-5,26,4,minecraft:netherrack)
B(-5,27,4,minecraft:netherrack)
B(-5,28,4,minecraft:netherrack)
B(-5,29,4,minecraft:lava)
B(-5,30,4,minecraft:lava)
B(-5,31,4,minecraft:lava)
B(-5,32,4,minecraft:lava)
B(-5,33,4,minecraft:lava)
B(-5,34,4,minecraft:lava)
B(-5,35,4,minecraft:lava)
B(-5,0,5,minecraft:netherrack)
B(-5,1,5,minecraft:netherrack)
B(-5,2,5,minecraft:netherrack)
B(-5,3,5,minecraft:netherrack)
B(-5,4,5,minecraft:netherrack)
B(-5,5,5,minecraft:netherrack)
B(-5,6,5,minecraft:netherrack)
B(-5,7,5,minecraft:netherrack)
B(-5,8,5,minecraft:netherrack)
B(-5,9,5,minecraft:netherrack)
B(-5,10,5,minecraft:netherrack)
B(-5,11,5,minecraft:netherrack)
B(-5,12,5,minecraft:netherrack)
B(-5,13,5,minecraft:netherrack)
B(-5,14,5,minecraft:netherrack)
B(-5,15,5,minecraft:netherrack)
B(-5,16,5,minecraft:netherrack)
B(-5,17,5,minecraft:netherrack)
B(-5,18,5,minecraft:netherrack)
B(-5,19,5,minecraft:netherrack)
B(-5,20,5,minecraft:netherrack)
B(-5,21,5,minecraft:netherrack)
B(-5,22,5,minecraft:netherrack)
B(-5,23,5,minecraft:netherrack)
B(-5,24,5,minecraft:netherrack)
B(-5,25,5,minecraft:netherrack)
B(-5,26,5,minecraft:netherrack)
B(-5,27,5,minecraft:netherrack)
B(-5,28,5,minecraft:netherrack)
B(-5,29,5,minecraft:lava)
B(-5,30,5,minecraft:lava)
B(-5,31,5,minecraft:lava)
B(-5,32,5,minecraft:lava)
B(-5,33,5,minecraft:lava)
B(-5,34,5,minecraft:lava)
B(-5,35,5,minecraft:lava)
B(-5,0,6,minecraft:netherrack)
B(-5,1,6,minecraft:netherrack)
B(-5,2,6,minecraft:netherrack)
B(-5,3,6,minecraft:netherrack)
B(-5,4,6,minecraft:netherrack)
B(-5,5,6,minecraft:netherrack)
B(-5,6,6,minecraft:netherrack)
B(-5,7,6,minecraft:netherrack)
B(-5,8,6,minecraft:netherrack)
B(-5,9,6,minecraft:netherrack)
B(-5,10,6,minecraft:netherrack)
B(-5,11,6,minecraft:netherrack)
B(-5,12,6,minecraft:netherrack)
B(-5,13,6,minecraft:netherrack)
B(-5,14,6,minecraft:netherrack)
B(-5,15,6,minecraft:netherrack)
B(-5,16,6,minecraft:netherrack)
B(-5,17,6,minecraft:netherrack)
B(-5,18,6,minecraft:netherrack)
B(-5,19,6,minecraft:netherrack)
B(-5,20,6,minecraft:netherrack)
B(-5,21,6,minecraft:netherrack)
B(-5,22,6,minecraft:netherrack)
B(-5,23,6,minecraft:netherrack)
B(-5,24,6,minecraft:netherrack)
B(-5,25,6,minecraft:netherrack)
B(-5,26,6,minecraft:netherrack)
B(-5,27,6,minecraft:netherrack)
B(-5,28,6,minecraft:lava)
B(-5,29,6,minecraft:lava)
B(-5,30,6,minecraft:lava)
B(-5,31,6,minecraft:lava)
B(-5,32,6,minecraft:lava)
B(-5,33,6,minecraft:lava)
B(-5,34,6,minecraft:lava)
B(-5,35,6,minecraft:lava)
B(-5,0,7,minecraft:netherrack)
B(-5,1,7,minecraft:netherrack)
B(-5,2,7,minecraft:netherrack)
B(-5,3,7,minecraft:netherrack)
B(-5,4,7,minecraft:netherrack)
B(-5,5,7,minecraft:netherrack)
B(-5,6,7,minecraft:netherrack)
B(-5,7,7,minecraft:netherrack)
B(-5,8,7,minecraft:netherrack)
B(-5,9,7,minecraft:netherrack)
B(-5,10,7,minecraft:netherrack)
B(-5,11,7,minecraft:netherrack)
B(-5,12,7,minecraft:netherrack)
B(-5,13,7,minecraft:netherrack)
B(-5,14,7,minecraft:netherrack)
B(-5,15,7,minecraft:netherrack)
B(-5,16,7,minecraft:netherrack)
B(-5,17,7,minecraft:netherrack)
B(-5,18,7,minecraft:netherrack)
B(-5,19,7,minecraft:netherrack)
B(-5,20,7,minecraft:netherrack)
B(-5,21,7,minecraft:netherrack)
B(-5,22,7,minecraft:netherrack)
B(-5,23,7,minecraft:netherrack)
B(-5,24,7,minecraft:netherrack)
B(-5,25,7,minecraft:netherrack)
B(-5,26,7,minecraft:netherrack)
B(-5,27,7,minecraft:netherrack)
B(-5,28,7,minecraft:lava)
B(-5,29,7,minecraft:lava)
B(-5,30,7,minecraft:lava)
B(-5,31,7,minecraft:lava)
B(-5,32,7,minecraft:lava)
B(-5,33,7,minecraft:lava)
B(-5,34,7,minecraft:lava)
B(-5,35,7,minecraft:lava)
B(-5,0,8,minecraft:netherrack)
B(-5,1,8,minecraft:netherrack)
B(-5,2,8,minecraft:netherrack)
B(-5,3,8,minecraft:netherrack)
B(-5,4,8,minecraft:netherrack)
B(-5,5,8,minecraft:netherrack)
B(-5,6,8,minecraft:netherrack)
B(-5,7,8,minecraft:netherrack)
B(-5,8,8,minecraft:netherrack)
B(-5,9,8,minecraft:netherrack)
B(-5,10,8,minecraft:netherrack)
B(-5,11,8,minecraft:netherrack)
B(-5,12,8,minecraft:netherrack)
B(-5,13,8,minecraft:netherrack)
B(-5,14,8,minecraft:netherrack)
B(-5,15,8,minecraft:netherrack)
B(-5,16,8,minecraft:netherrack)
B(-5,17,8,minecraft:netherrack)
B(-5,18,8,minecraft:netherrack)
B(-5,19,8,minecraft:netherrack)
B(-5,20,8,minecraft:netherrack)
B(-5,21,8,minecraft:netherrack)
B(-5,22,8,minecraft:netherrack)
B(-5,23,8,minecraft:netherrack)
B(-5,24,8,minecraft:netherrack)
B(-5,25,8,minecraft:netherrack)
B(-5,26,8,minecraft:netherrack)
B(-5,27,8,minecraft:netherrack)
B(-5,28,8,minecraft:lava)
B(-5,29,8,minecraft:lava)
B(-5,30,8,minecraft:lava)
B(-5,31,8,minecraft:lava)
B(-5,32,8,minecraft:lava)
B(-5,33,8,minecraft:lava)
B(-5,34,8,minecraft:lava)
B(-5,35,8,minecraft:lava)
B(-4,0,-7,minecraft:netherrack)
B(-4,1,-7,minecraft:netherrack)
B(-4,2,-7,minecraft:netherrack)
B(-4,3,-7,minecraft:netherrack)
B(-4,4,-7,minecraft:netherrack)
B(-4,5,-7,minecraft:netherrack)
B(-4,6,-7,minecraft:netherrack)
B(-4,7,-7,minecraft:netherrack)
B(-4,8,-7,minecraft:netherrack)
B(-4,9,-7,minecraft:netherrack)
B(-4,10,-7,minecraft:netherrack)
B(-4,11,-7,minecraft:netherrack)
B(-4,12,-7,minecraft:netherrack)
B(-4,13,-7,minecraft:netherrack)
B(-4,14,-7,minecraft:netherrack)
B(-4,15,-7,minecraft:netherrack)
B(-4,16,-7,minecraft:netherrack)
B(-4,17,-7,minecraft:netherrack)
B(-4,18,-7,minecraft:netherrack)
B(-4,19,-7,minecraft:netherrack)
B(-4,20,-7,minecraft:netherrack)
B(-4,21,-7,minecraft:netherrack)
B(-4,22,-7,minecraft:netherrack)
B(-4,23,-7,minecraft:netherrack)
B(-4,24,-7,minecraft:netherrack)
B(-4,25,-7,minecraft:netherrack)
B(-4,26,-7,minecraft:netherrack)
B(-4,27,-7,minecraft:netherrack)
B(-4,28,-7,minecraft:netherrack)
B(-4,29,-7,minecraft:netherrack)
B(-4,30,-7,minecraft:netherrack)
B(-4,31,-7,minecraft:netherrack)
B(-4,32,-7,minecraft:netherrack)
B(-4,33,-7,minecraft:netherrack)
B(-4,34,-7,minecraft:netherrack)
B(-4,0,-6,minecraft:netherrack)
B(-4,1,-6,minecraft:netherrack)
B(-4,2,-6,minecraft:netherrack)
B(-4,3,-6,minecraft:netherrack)
B(-4,4,-6,minecraft:netherrack)
B(-4,5,-6,minecraft:netherrack)
B(-4,6,-6,minecraft:netherrack)
B(-4,7,-6,minecraft:netherrack)
B(-4,8,-6,minecraft:netherrack)
B(-4,9,-6,minecraft:netherrack)
B(-4,10,-6,minecraft:netherrack)
B(-4,11,-6,minecraft:netherrack)
B(-4,12,-6,minecraft:netherrack)
B(-4,13,-6,minecraft:netherrack)
B(-4,14,-6,minecraft:netherrack)
B(-4,15,-6,minecraft:netherrack)
B(-4,16,-6,minecraft:netherrack)
B(-4,17,-6,minecraft:netherrack)
B(-4,18,-6,minecraft:netherrack)
B(-4,19,-6,minecraft:netherrack)
B(-4,20,-6,minecraft:netherrack)
B(-4,21,-6,minecraft:netherrack)
B(-4,22,-6,minecraft:netherrack)
B(-4,23,-6,minecraft:netherrack)
B(-4,24,-6,minecraft:netherrack)
B(-4,25,-6,minecraft:netherrack)
B(-4,26,-6,minecraft:netherrack)
B(-4,27,-6,minecraft:netherrack)
B(-4,28,-6,minecraft:netherrack)
B(-4,29,-6,minecraft:netherrack)
B(-4,30,-6,minecraft:netherrack)
B(-4,31,-6,minecraft:netherrack)
B(-4,32,-6,minecraft:netherrack)
B(-4,33,-6,minecraft:netherrack)
B(-4,34,-6,minecraft:netherrack)
B(-4,35,-6,minecraft:netherrack)
B(-4,0,-5,minecraft:netherrack)
B(-4,1,-5,minecraft:netherrack)
B(-4,2,-5,minecraft:netherrack)
B(-4,3,-5,minecraft:netherrack)
B(-4,4,-5,minecraft:netherrack)
B(-4,5,-5,minecraft:netherrack)
B(-4,6,-5,minecraft:netherrack)
B(-4,7,-5,minecraft:netherrack)
B(-4,8,-5,minecraft:netherrack)
B(-4,9,-5,minecraft:netherrack)
B(-4,10,-5,minecraft:netherrack)
B(-4,11,-5,minecraft:netherrack)
B(-4,12,-5,minecraft:netherrack)
B(-4,13,-5,minecraft:netherrack)
B(-4,14,-5,minecraft:netherrack)
B(-4,15,-5,minecraft:netherrack)
B(-4,16,-5,minecraft:netherrack)
B(-4,17,-5,minecraft:netherrack)
B(-4,18,-5,minecraft:netherrack)
B(-4,19,-5,minecraft:netherrack)
B(-4,20,-5,minecraft:netherrack)
B(-4,21,-5,minecraft:netherrack)
B(-4,22,-5,minecraft:netherrack)
B(-4,23,-5,minecraft:netherrack)
B(-4,24,-5,minecraft:netherrack)
B(-4,25,-5,minecraft:netherrack)
B(-4,26,-5,minecraft:netherrack)
B(-4,27,-5,minecraft:netherrack)
B(-4,28,-5,minecraft:netherrack)
B(-4,29,-5,minecraft:netherrack)
B(-4,30,-5,minecraft:netherrack)
B(-4,31,-5,minecraft:netherrack)
B(-4,32,-5,minecraft:netherrack)
B(-4,33,-5,minecraft:netherrack)
B(-4,34,-5,minecraft:netherrack)
B(-4,35,-5,minecraft:netherrack)
B(-4,36,-5,minecraft:netherrack)
B(-4,0,-4,minecraft:netherrack)
B(-4,1,-4,minecraft:netherrack)
B(-4,2,-4,minecraft:netherrack)
B(-4,3,-4,minecraft:netherrack)
B(-4,4,-4,minecraft:netherrack)
B(-4,5,-4,minecraft:netherrack)
B(-4,6,-4,minecraft:netherrack)
B(-4,7,-4,minecraft:netherrack)
B(-4,8,-4,minecraft:netherrack)
B(-4,9,-4,minecraft:netherrack)
B(-4,10,-4,minecraft:netherrack)
B(-4,11,-4,minecraft:netherrack)
B(-4,12,-4,minecraft:netherrack)
B(-4,13,-4,minecraft:netherrack)
B(-4,14,-4,minecraft:netherrack)
B(-4,15,-4,minecraft:netherrack)
B(-4,16,-4,minecraft:netherrack)
B(-4,17,-4,minecraft:netherrack)
B(-4,18,-4,minecraft:netherrack)
B(-4,19,-4,minecraft:netherrack)
B(-4,20,-4,minecraft:netherrack)
B(-4,21,-4,minecraft:netherrack)
B(-4,22,-4,minecraft:netherrack)
B(-4,23,-4,minecraft:netherrack)
B(-4,24,-4,minecraft:netherrack)
B(-4,25,-4,minecraft:netherrack)
B(-4,26,-4,minecraft:netherrack)
B(-4,27,-4,minecraft:netherrack)
B(-4,28,-4,minecraft:netherrack)
B(-4,29,-4,minecraft:netherrack)
B(-4,30,-4,minecraft:netherrack)
B(-4,31,-4,minecraft:netherrack)
B(-4,32,-4,minecraft:netherrack)
B(-4,33,-4,minecraft:netherrack)
B(-4,34,-4,minecraft:netherrack)
B(-4,35,-4,minecraft:netherrack)
B(-4,36,-4,minecraft:netherrack)
B(-4,0,-3,minecraft:netherrack)
B(-4,1,-3,minecraft:netherrack)
B(-4,2,-3,minecraft:netherrack)
B(-4,3,-3,minecraft:netherrack)
B(-4,4,-3,minecraft:netherrack)
B(-4,5,-3,minecraft:netherrack)
B(-4,6,-3,minecraft:netherrack)
B(-4,7,-3,minecraft:netherrack)
B(-4,8,-3,minecraft:netherrack)
B(-4,9,-3,minecraft:netherrack)
B(-4,10,-3,minecraft:netherrack)
B(-4,11,-3,minecraft:netherrack)
B(-4,12,-3,minecraft:netherrack)
B(-4,13,-3,minecraft:netherrack)
B(-4,14,-3,minecraft:netherrack)
B(-4,15,-3,minecraft:netherrack)
B(-4,16,-3,minecraft:netherrack)
B(-4,17,-3,minecraft:netherrack)
B(-4,18,-3,minecraft:netherrack)
B(-4,19,-3,minecraft:netherrack)
B(-4,20,-3,minecraft:netherrack)
B(-4,21,-3,minecraft:netherrack)
B(-4,22,-3,minecraft:netherrack)
B(-4,23,-3,minecraft:netherrack)
B(-4,24,-3,minecraft:netherrack)
B(-4,25,-3,minecraft:netherrack)
B(-4,26,-3,minecraft:netherrack)
B(-4,27,-3,minecraft:netherrack)
B(-4,28,-3,minecraft:netherrack)
B(-4,29,-3,minecraft:netherrack)
B(-4,30,-3,minecraft:netherrack)
B(-4,31,-3,minecraft:netherrack)
B(-4,32,-3,minecraft:netherrack)
B(-4,33,-3,minecraft:netherrack)
B(-4,34,-3,minecraft:netherrack)
B(-4,35,-3,minecraft:netherrack)
B(-4,36,-3,minecraft:netherrack)
B(-4,0,-2,minecraft:netherrack)
B(-4,1,-2,minecraft:netherrack)
B(-4,2,-2,minecraft:netherrack)
B(-4,3,-2,minecraft:netherrack)
B(-4,4,-2,minecraft:netherrack)
B(-4,5,-2,minecraft:netherrack)
B(-4,6,-2,minecraft:netherrack)
B(-4,7,-2,minecraft:netherrack)
B(-4,8,-2,minecraft:netherrack)
B(-4,9,-2,minecraft:netherrack)
B(-4,10,-2,minecraft:netherrack)
B(-4,11,-2,minecraft:netherrack)
B(-4,12,-2,minecraft:netherrack)
B(-4,13,-2,minecraft:netherrack)
B(-4,14,-2,minecraft:netherrack)
B(-4,15,-2,minecraft:netherrack)
B(-4,16,-2,minecraft:netherrack)
B(-4,17,-2,minecraft:netherrack)
B(-4,18,-2,minecraft:netherrack)
B(-4,19,-2,minecraft:netherrack)
B(-4,20,-2,minecraft:netherrack)
B(-4,21,-2,minecraft:netherrack)
B(-4,22,-2,minecraft:netherrack)
B(-4,23,-2,minecraft:netherrack)
B(-4,24,-2,minecraft:netherrack)
B(-4,25,-2,minecraft:netherrack)
B(-4,26,-2,minecraft:netherrack)
B(-4,27,-2,minecraft:netherrack)
B(-4,28,-2,minecraft:netherrack)
B(-4,29,-2,minecraft:netherrack)
B(-4,30,-2,minecraft:netherrack)
B(-4,31,-2,minecraft:netherrack)
B(-4,32,-2,minecraft:netherrack)
B(-4,33,-2,minecraft:netherrack)
B(-4,34,-2,minecraft:netherrack)
B(-4,35,-2,minecraft:netherrack)
B(-4,0,-1,minecraft:netherrack)
B(-4,1,-1,minecraft:netherrack)
B(-4,2,-1,minecraft:netherrack)
B(-4,3,-1,minecraft:netherrack)
B(-4,4,-1,minecraft:netherrack)
B(-4,5,-1,minecraft:netherrack)
B(-4,6,-1,minecraft:netherrack)
B(-4,7,-1,minecraft:netherrack)
B(-4,8,-1,minecraft:netherrack)
B(-4,9,-1,minecraft:netherrack)
B(-4,10,-1,minecraft:netherrack)
B(-4,11,-1,minecraft:netherrack)
B(-4,12,-1,minecraft:netherrack)
B(-4,13,-1,minecraft:netherrack)
B(-4,14,-1,minecraft:netherrack)
B(-4,15,-1,minecraft:netherrack)
B(-4,16,-1,minecraft:netherrack)
B(-4,17,-1,minecraft:netherrack)
B(-4,18,-1,minecraft:netherrack)
B(-4,19,-1,minecraft:netherrack)
B(-4,20,-1,minecraft:netherrack)
B(-4,21,-1,minecraft:netherrack)
B(-4,22,-1,minecraft:netherrack)
B(-4,23,-1,minecraft:netherrack)
B(-4,24,-1,minecraft:netherrack)
B(-4,25,-1,minecraft:netherrack)
B(-4,26,-1,minecraft:netherrack)
B(-4,27,-1,minecraft:netherrack)
B(-4,28,-1,minecraft:netherrack)
B(-4,29,-1,minecraft:netherrack)
B(-4,30,-1,minecraft:netherrack)
B(-4,31,-1,minecraft:netherrack)
B(-4,32,-1,minecraft:netherrack)
B(-4,33,-1,minecraft:netherrack)
B(-4,34,-1,minecraft:netherrack)
B(-4,35,-1,minecraft:lava)
B(-4,0,0,minecraft:netherrack)
B(-4,1,0,minecraft:netherrack)
B(-4,2,0,minecraft:netherrack)
B(-4,3,0,minecraft:netherrack)
B(-4,4,0,minecraft:netherrack)
B(-4,5,0,minecraft:netherrack)
B(-4,6,0,minecraft:netherrack)
B(-4,7,0,minecraft:netherrack)
B(-4,8,0,minecraft:netherrack)
B(-4,9,0,minecraft:netherrack)
B(-4,10,0,minecraft:netherrack)
B(-4,11,0,minecraft:netherrack)
B(-4,12,0,minecraft:netherrack)
B(-4,13,0,minecraft:netherrack)
B(-4,14,0,minecraft:netherrack)
B(-4,15,0,minecraft:netherrack)
B(-4,16,0,minecraft:netherrack)
B(-4,17,0,minecraft:netherrack)
B(-4,18,0,minecraft:netherrack)
B(-4,19,0,minecraft:netherrack)
B(-4,20,0,minecraft:netherrack)
B(-4,21,0,minecraft:netherrack)
B(-4,22,0,minecraft:netherrack)
B(-4,23,0,minecraft:netherrack)
B(-4,24,0,minecraft:netherrack)
B(-4,25,0,minecraft:netherrack)
B(-4,26,0,minecraft:netherrack)
B(-4,27,0,minecraft:netherrack)
B(-4,28,0,minecraft:netherrack)
B(-4,29,0,minecraft:netherrack)
B(-4,30,0,minecraft:netherrack)
B(-4,31,0,minecraft:netherrack)
B(-4,32,0,minecraft:netherrack)
B(-4,33,0,minecraft:netherrack)
B(-4,34,0,minecraft:lava)
B(-4,35,0,minecraft:lava)
B(-4,0,1,minecraft:netherrack)
B(-4,1,1,minecraft:netherrack)
B(-4,2,1,minecraft:netherrack)
B(-4,3,1,minecraft:netherrack)
B(-4,4,1,minecraft:netherrack)
B(-4,5,1,minecraft:netherrack)
B(-4,6,1,minecraft:netherrack)
B(-4,7,1,minecraft:netherrack)
B(-4,8,1,minecraft:netherrack)
B(-4,9,1,minecraft:netherrack)
B(-4,10,1,minecraft:netherrack)
B(-4,11,1,minecraft:netherrack)
B(-4,12,1,minecraft:netherrack)
B(-4,13,1,minecraft:netherrack)
B(-4,14,1,minecraft:netherrack)
B(-4,15,1,minecraft:netherrack)
B(-4,16,1,minecraft:netherrack)
B(-4,17,1,minecraft:netherrack)
B(-4,18,1,minecraft:netherrack)
B(-4,19,1,minecraft:netherrack)
B(-4,20,1,minecraft:netherrack)
B(-4,21,1,minecraft:netherrack)
B(-4,22,1,minecraft:netherrack)
B(-4,23,1,minecraft:netherrack)
B(-4,24,1,minecraft:netherrack)
B(-4,25,1,minecraft:netherrack)
B(-4,26,1,minecraft:netherrack)
B(-4,27,1,minecraft:netherrack)
B(-4,28,1,minecraft:netherrack)
B(-4,29,1,minecraft:netherrack)
B(-4,30,1,minecraft:netherrack)
B(-4,31,1,minecraft:netherrack)
B(-4,32,1,minecraft:netherrack)
B(-4,33,1,minecraft:lava)
B(-4,34,1,minecraft:lava)
B(-4,35,1,minecraft:lava)
B(-4,0,2,minecraft:netherrack)
B(-4,1,2,minecraft:netherrack)
B(-4,2,2,minecraft:netherrack)
B(-4,3,2,minecraft:netherrack)
B(-4,4,2,minecraft:netherrack)
B(-4,5,2,minecraft:netherrack)
B(-4,6,2,minecraft:netherrack)
B(-4,7,2,minecraft:netherrack)
B(-4,8,2,minecraft:netherrack)
B(-4,9,2,minecraft:netherrack)
B(-4,10,2,minecraft:netherrack)
B(-4,11,2,minecraft:netherrack)
B(-4,12,2,minecraft:netherrack)
B(-4,13,2,minecraft:netherrack)
B(-4,14,2,minecraft:netherrack)
B(-4,15,2,minecraft:netherrack)
B(-4,16,2,minecraft:netherrack)
B(-4,17,2,minecraft:netherrack)
B(-4,18,2,minecraft:netherrack)
B(-4,19,2,minecraft:netherrack)
B(-4,20,2,minecraft:netherrack)
B(-4,21,2,minecraft:netherrack)
B(-4,22,2,minecraft:netherrack)
B(-4,23,2,minecraft:netherrack)
B(-4,24,2,minecraft:netherrack)
B(-4,25,2,minecraft:netherrack)
B(-4,26,2,minecraft:netherrack)
B(-4,27,2,minecraft:netherrack)
B(-4,28,2,minecraft:netherrack)
B(-4,29,2,minecraft:netherrack)
B(-4,30,2,minecraft:netherrack)
B(-4,31,2,minecraft:lava)
B(-4,32,2,minecraft:lava)
B(-4,33,2,minecraft:lava)
B(-4,34,2,minecraft:lava)
B(-4,35,2,minecraft:lava)
B(-4,0,3,minecraft:netherrack)
B(-4,1,3,minecraft:netherrack)
B(-4,2,3,minecraft:netherrack)
B(-4,3,3,minecraft:netherrack)
B(-4,4,3,minecraft:netherrack)
B(-4,5,3,minecraft:netherrack)
B(-4,6,3,minecraft:netherrack)
B(-4,7,3,minecraft:netherrack)
B(-4,8,3,minecraft:netherrack)
B(-4,9,3,minecraft:netherrack)
B(-4,10,3,minecraft:netherrack)
B(-4,11,3,minecraft:netherrack)
B(-4,12,3,minecraft:netherrack)
B(-4,13,3,minecraft:netherrack)
B(-4,14,3,minecraft:netherrack)
B(-4,15,3,minecraft:netherrack)
B(-4,16,3,minecraft:netherrack)
B(-4,17,3,minecraft:netherrack)
B(-4,18,3,minecraft:netherrack)
B(-4,19,3,minecraft:netherrack)
B(-4,20,3,minecraft:netherrack)
B(-4,21,3,minecraft:netherrack)
B(-4,22,3,minecraft:netherrack)
B(-4,23,3,minecraft:netherrack)
B(-4,24,3,minecraft:netherrack)
B(-4,25,3,minecraft:netherrack)
B(-4,26,3,minecraft:netherrack)
B(-4,27,3,minecraft:netherrack)
B(-4,28,3,minecraft:netherrack)
B(-4,29,3,minecraft:netherrack)
B(-4,30,3,minecraft:lava)
B(-4,31,3,minecraft:lava)
B(-4,32,3,minecraft:lava)
B(-4,33,3,minecraft:lava)
B(-4,34,3,minecraft:lava)
B(-4,35,3,minecraft:lava)
B(-4,0,4,minecraft:netherrack)
B(-4,1,4,minecraft:netherrack)
B(-4,2,4,minecraft:netherrack)
B(-4,3,4,minecraft:netherrack)
B(-4,4,4,minecraft:netherrack)
B(-4,5,4,minecraft:netherrack)
B(-4,6,4,minecraft:netherrack)
B(-4,7,4,minecraft:netherrack)
B(-4,8,4,minecraft:netherrack)
B(-4,9,4,minecraft:netherrack)
B(-4,10,4,minecraft:netherrack)
B(-4,11,4,minecraft:netherrack)
B(-4,12,4,minecraft:netherrack)
B(-4,13,4,minecraft:netherrack)
B(-4,14,4,minecraft:netherrack)
B(-4,15,4,minecraft:netherrack)
B(-4,16,4,minecraft:netherrack)
B(-4,17,4,minecraft:netherrack)
B(-4,18,4,minecraft:netherrack)
B(-4,19,4,minecraft:netherrack)
B(-4,20,4,minecraft:netherrack)
B(-4,21,4,minecraft:netherrack)
B(-4,22,4,minecraft:netherrack)
B(-4,23,4,minecraft:netherrack)
B(-4,24,4,minecraft:netherrack)
B(-4,25,4,minecraft:netherrack)
B(-4,26,4,minecraft:netherrack)
B(-4,27,4,minecraft:netherrack)
B(-4,28,4,minecraft:netherrack)
B(-4,29,4,minecraft:lava)
B(-4,30,4,minecraft:lava)
B(-4,31,4,minecraft:lava)
B(-4,32,4,minecraft:lava)
B(-4,33,4,minecraft:lava)
B(-4,34,4,minecraft:lava)
B(-4,35,4,minecraft:lava)
B(-4,0,5,minecraft:netherrack)
B(-4,1,5,minecraft:netherrack)
B(-4,2,5,minecraft:netherrack)
B(-4,3,5,minecraft:netherrack)
B(-4,4,5,minecraft:netherrack)
B(-4,5,5,minecraft:netherrack)
B(-4,6,5,minecraft:netherrack)
B(-4,7,5,minecraft:netherrack)
B(-4,8,5,minecraft:netherrack)
B(-4,9,5,minecraft:netherrack)
B(-4,10,5,minecraft:netherrack)
B(-4,11,5,minecraft:netherrack)
B(-4,12,5,minecraft:netherrack)
B(-4,13,5,minecraft:netherrack)
B(-4,14,5,minecraft:netherrack)
B(-4,15,5,minecraft:netherrack)
B(-4,16,5,minecraft:netherrack)
B(-4,17,5,minecraft:netherrack)
B(-4,18,5,minecraft:netherrack)
B(-4,19,5,minecraft:netherrack)
B(-4,20,5,minecraft:netherrack)
B(-4,21,5,minecraft:netherrack)
B(-4,22,5,minecraft:netherrack)
B(-4,23,5,minecraft:netherrack)
B(-4,24,5,minecraft:netherrack)
B(-4,25,5,minecraft:netherrack)
B(-4,26,5,minecraft:netherrack)
B(-4,27,5,minecraft:netherrack)
B(-4,28,5,minecraft:netherrack)
B(-4,29,5,minecraft:lava)
B(-4,30,5,minecraft:lava)
B(-4,31,5,minecraft:lava)
B(-4,32,5,minecraft:lava)
B(-4,33,5,minecraft:lava)
B(-4,34,5,minecraft:lava)
B(-4,35,5,minecraft:lava)
B(-4,0,6,minecraft:netherrack)
B(-4,1,6,minecraft:netherrack)
B(-4,2,6,minecraft:netherrack)
B(-4,3,6,minecraft:netherrack)
B(-4,4,6,minecraft:netherrack)
B(-4,5,6,minecraft:netherrack)
B(-4,6,6,minecraft:netherrack)
B(-4,7,6,minecraft:netherrack)
B(-4,8,6,minecraft:netherrack)
B(-4,9,6,minecraft:netherrack)
B(-4,10,6,minecraft:netherrack)
B(-4,11,6,minecraft:netherrack)
B(-4,12,6,minecraft:netherrack)
B(-4,13,6,minecraft:netherrack)
B(-4,14,6,minecraft:netherrack)
B(-4,15,6,minecraft:netherrack)
B(-4,16,6,minecraft:netherrack)
B(-4,17,6,minecraft:netherrack)
B(-4,18,6,minecraft:netherrack)
B(-4,19,6,minecraft:netherrack)
B(-4,20,6,minecraft:netherrack)
B(-4,21,6,minecraft:netherrack)
B(-4,22,6,minecraft:netherrack)
B(-4,23,6,minecraft:netherrack)
B(-4,24,6,minecraft:netherrack)
B(-4,25,6,minecraft:netherrack)
B(-4,26,6,minecraft:netherrack)
B(-4,27,6,minecraft:netherrack)
B(-4,28,6,minecraft:lava)
B(-4,29,6,minecraft:lava)
B(-4,30,6,minecraft:lava)
B(-4,31,6,minecraft:lava)
B(-4,32,6,minecraft:lava)
B(-4,33,6,minecraft:lava)
B(-4,34,6,minecraft:lava)
B(-4,35,6,minecraft:lava)
B(-4,0,7,minecraft:netherrack)
B(-4,1,7,minecraft:netherrack)
B(-4,2,7,minecraft:netherrack)
B(-4,3,7,minecraft:netherrack)
B(-4,4,7,minecraft:netherrack)
B(-4,5,7,minecraft:netherrack)
B(-4,6,7,minecraft:netherrack)
B(-4,7,7,minecraft:netherrack)
B(-4,8,7,minecraft:netherrack)
B(-4,9,7,minecraft:netherrack)
B(-4,10,7,minecraft:netherrack)
B(-4,11,7,minecraft:netherrack)
B(-4,12,7,minecraft:netherrack)
B(-4,13,7,minecraft:netherrack)
B(-4,14,7,minecraft:netherrack)
B(-4,15,7,minecraft:netherrack)
B(-4,16,7,minecraft:netherrack)
B(-4,17,7,minecraft:netherrack)
B(-4,18,7,minecraft:netherrack)
B(-4,19,7,minecraft:netherrack)
B(-4,20,7,minecraft:netherrack)
B(-4,21,7,minecraft:netherrack)
B(-4,22,7,minecraft:netherrack)
B(-4,23,7,minecraft:netherrack)
B(-4,24,7,minecraft:netherrack)
B(-4,25,7,minecraft:netherrack)
B(-4,26,7,minecraft:netherrack)
B(-4,27,7,minecraft:netherrack)
B(-4,28,7,minecraft:lava)
B(-4,29,7,minecraft:lava)
B(-4,30,7,minecraft:lava)
B(-4,31,7,minecraft:lava)
B(-4,32,7,minecraft:lava)
B(-4,33,7,minecraft:lava)
B(-4,34,7,minecraft:lava)
B(-4,35,7,minecraft:lava)
B(-4,0,8,minecraft:netherrack)
B(-4,1,8,minecraft:netherrack)
B(-4,2,8,minecraft:netherrack)
B(-4,3,8,minecraft:netherrack)
B(-4,4,8,minecraft:netherrack)
B(-4,5,8,minecraft:netherrack)
B(-4,6,8,minecraft:netherrack)
B(-4,7,8,minecraft:netherrack)
B(-4,8,8,minecraft:netherrack)
B(-4,9,8,minecraft:netherrack)
B(-4,10,8,minecraft:netherrack)
B(-4,11,8,minecraft:netherrack)
B(-4,12,8,minecraft:netherrack)
B(-4,13,8,minecraft:netherrack)
B(-4,14,8,minecraft:netherrack)
B(-4,15,8,minecraft:netherrack)
B(-4,16,8,minecraft:netherrack)
B(-4,17,8,minecraft:netherrack)
B(-4,18,8,minecraft:netherrack)
B(-4,19,8,minecraft:netherrack)
B(-4,20,8,minecraft:netherrack)
B(-4,21,8,minecraft:netherrack)
B(-4,22,8,minecraft:netherrack)
B(-4,23,8,minecraft:netherrack)
B(-4,24,8,minecraft:netherrack)
B(-4,25,8,minecraft:netherrack)
B(-4,26,8,minecraft:netherrack)
B(-4,27,8,minecraft:netherrack)
B(-4,28,8,minecraft:lava)
B(-4,29,8,minecraft:lava)
B(-4,30,8,minecraft:lava)
B(-4,31,8,minecraft:lava)
B(-4,32,8,minecraft:lava)
B(-4,33,8,minecraft:lava)
B(-4,34,8,minecraft:lava)
B(-4,35,8,minecraft:lava)
B(-3,0,-7,minecraft:netherrack)
B(-3,1,-7,minecraft:netherrack)
B(-3,2,-7,minecraft:netherrack)
B(-3,3,-7,minecraft:netherrack)
B(-3,4,-7,minecraft:netherrack)
B(-3,5,-7,minecraft:netherrack)
B(-3,6,-7,minecraft:netherrack)
B(-3,7,-7,minecraft:netherrack)
B(-3,8,-7,minecraft:netherrack)
B(-3,9,-7,minecraft:netherrack)
B(-3,10,-7,minecraft:netherrack)
B(-3,11,-7,minecraft:netherrack)
B(-3,12,-7,minecraft:netherrack)
B(-3,13,-7,minecraft:netherrack)
B(-3,14,-7,minecraft:netherrack)
B(-3,15,-7,minecraft:netherrack)
B(-3,16,-7,minecraft:netherrack)
B(-3,17,-7,minecraft:netherrack)
B(-3,18,-7,minecraft:netherrack)
B(-3,19,-7,minecraft:netherrack)
B(-3,20,-7,minecraft:netherrack)
B(-3,21,-7,minecraft:netherrack)
B(-3,22,-7,minecraft:netherrack)
B(-3,23,-7,minecraft:netherrack)
B(-3,24,-7,minecraft:netherrack)
B(-3,25,-7,minecraft:netherrack)
B(-3,26,-7,minecraft:netherrack)
B(-3,27,-7,minecraft:netherrack)
B(-3,28,-7,minecraft:netherrack)
B(-3,29,-7,minecraft:netherrack)
B(-3,30,-7,minecraft:netherrack)
B(-3,31,-7,minecraft:netherrack)
B(-3,32,-7,minecraft:netherrack)
B(-3,33,-7,minecraft:netherrack)
B(-3,0,-6,minecraft:netherrack)
B(-3,1,-6,minecraft:netherrack)
B(-3,2,-6,minecraft:netherrack)
B(-3,3,-6,minecraft:netherrack)
B(-3,4,-6,minecraft:netherrack)
B(-3,5,-6,minecraft:netherrack)
B(-3,6,-6,minecraft:netherrack)
B(-3,7,-6,minecraft:netherrack)
B(-3,8,-6,minecraft:netherrack)
B(-3,9,-6,minecraft:netherrack)
B(-3,10,-6,minecraft:netherrack)
B(-3,11,-6,minecraft:netherrack)
B(-3,12,-6,minecraft:netherrack)
B(-3,13,-6,minecraft:netherrack)
B(-3,14,-6,minecraft:netherrack)
B(-3,15,-6,minecraft:netherrack)
B(-3,16,-6,minecraft:netherrack)
B(-3,17,-6,minecraft:netherrack)
B(-3,18,-6,minecraft:netherrack)
B(-3,19,-6,minecraft:netherrack)
B(-3,20,-6,minecraft:netherrack)
B(-3,21,-6,minecraft:netherrack)
B(-3,22,-6,minecraft:netherrack)
B(-3,23,-6,minecraft:netherrack)
B(-3,24,-6,minecraft:netherrack)
B(-3,25,-6,minecraft:netherrack)
B(-3,26,-6,minecraft:netherrack)
B(-3,27,-6,minecraft:netherrack)
B(-3,28,-6,minecraft:netherrack)
B(-3,29,-6,minecraft:netherrack)
B(-3,30,-6,minecraft:netherrack)
B(-3,31,-6,minecraft:netherrack)
B(-3,32,-6,minecraft:netherrack)
B(-3,33,-6,minecraft:netherrack)
B(-3,34,-6,minecraft:netherrack)
B(-3,0,-5,minecraft:netherrack)
B(-3,1,-5,minecraft:netherrack)
B(-3,2,-5,minecraft:netherrack)
B(-3,3,-5,minecraft:netherrack)
B(-3,4,-5,minecraft:netherrack)
B(-3,5,-5,minecraft:netherrack)
B(-3,6,-5,minecraft:netherrack)
B(-3,7,-5,minecraft:netherrack)
B(-3,8,-5,minecraft:netherrack)
B(-3,9,-5,minecraft:netherrack)
B(-3,10,-5,minecraft:netherrack)
B(-3,11,-5,minecraft:netherrack)
B(-3,12,-5,minecraft:netherrack)
B(-3,13,-5,minecraft:netherrack)
B(-3,14,-5,minecraft:netherrack)
B(-3,15,-5,minecraft:netherrack)
B(-3,16,-5,minecraft:netherrack)
B(-3,17,-5,minecraft:netherrack)
B(-3,18,-5,minecraft:netherrack)
B(-3,19,-5,minecraft:netherrack)
B(-3,20,-5,minecraft:netherrack)
B(-3,21,-5,minecraft:netherrack)
B(-3,22,-5,minecraft:netherrack)
B(-3,23,-5,minecraft:netherrack)
B(-3,24,-5,minecraft:netherrack)
B(-3,25,-5,minecraft:netherrack)
B(-3,26,-5,minecraft:netherrack)
B(-3,27,-5,minecraft:netherrack)
B(-3,28,-5,minecraft:netherrack)
B(-3,29,-5,minecraft:netherrack)
B(-3,30,-5,minecraft:netherrack)
B(-3,31,-5,minecraft:netherrack)
B(-3,32,-5,minecraft:netherrack)
B(-3,33,-5,minecraft:netherrack)
B(-3,34,-5,minecraft:netherrack)
B(-3,35,-5,minecraft:netherrack)
B(-3,0,-4,minecraft:netherrack)
B(-3,1,-4,minecraft:netherrack)
B(-3,2,-4,minecraft:netherrack)
B(-3,3,-4,minecraft:netherrack)
B(-3,4,-4,minecraft:netherrack)
B(-3,5,-4,minecraft:netherrack)
B(-3,6,-4,minecraft:netherrack)
B(-3,7,-4,minecraft:netherrack)
B(-3,8,-4,minecraft:netherrack)
B(-3,9,-4,minecraft:netherrack)
B(-3,10,-4,minecraft:netherrack)
B(-3,11,-4,minecraft:netherrack)
B(-3,12,-4,minecraft:netherrack)
B(-3,13,-4,minecraft:netherrack)
B(-3,14,-4,minecraft:netherrack)
B(-3,15,-4,minecraft:netherrack)
B(-3,16,-4,minecraft:netherrack)
B(-3,17,-4,minecraft:netherrack)
B(-3,18,-4,minecraft:netherrack)
B(-3,19,-4,minecraft:netherrack)
B(-3,20,-4,minecraft:netherrack)
B(-3,21,-4,minecraft:netherrack)
B(-3,22,-4,minecraft:netherrack)
B(-3,23,-4,minecraft:netherrack)
B(-3,24,-4,minecraft:netherrack)
B(-3,25,-4,minecraft:netherrack)
B(-3,26,-4,minecraft:netherrack)
B(-3,27,-4,minecraft:netherrack)
B(-3,28,-4,minecraft:netherrack)
B(-3,29,-4,minecraft:netherrack)
B(-3,30,-4,minecraft:netherrack)
B(-3,31,-4,minecraft:netherrack)
B(-3,32,-4,minecraft:netherrack)
B(-3,33,-4,minecraft:netherrack)
B(-3,34,-4,minecraft:netherrack)
B(-3,35,-4,minecraft:netherrack)
B(-3,36,-4,minecraft:netherrack)
B(-3,0,-3,minecraft:netherrack)
B(-3,1,-3,minecraft:netherrack)
B(-3,2,-3,minecraft:netherrack)
B(-3,3,-3,minecraft:netherrack)
B(-3,4,-3,minecraft:netherrack)
B(-3,5,-3,minecraft:netherrack)
B(-3,6,-3,minecraft:netherrack)
B(-3,7,-3,minecraft:netherrack)
B(-3,8,-3,minecraft:netherrack)
B(-3,9,-3,minecraft:netherrack)
B(-3,10,-3,minecraft:netherrack)
B(-3,11,-3,minecraft:netherrack)
B(-3,12,-3,minecraft:netherrack)
B(-3,13,-3,minecraft:netherrack)
B(-3,14,-3,minecraft:netherrack)
B(-3,15,-3,minecraft:netherrack)
B(-3,16,-3,minecraft:netherrack)
B(-3,17,-3,minecraft:netherrack)
B(-3,18,-3,minecraft:netherrack)
B(-3,19,-3,minecraft:netherrack)
B(-3,20,-3,minecraft:netherrack)
B(-3,21,-3,minecraft:netherrack)
B(-3,22,-3,minecraft:netherrack)
B(-3,23,-3,minecraft:netherrack)
B(-3,24,-3,minecraft:netherrack)
B(-3,25,-3,minecraft:netherrack)
B(-3,26,-3,minecraft:netherrack)
B(-3,27,-3,minecraft:netherrack)
B(-3,28,-3,minecraft:netherrack)
B(-3,29,-3,minecraft:netherrack)
B(-3,30,-3,minecraft:netherrack)
B(-3,31,-3,minecraft:netherrack)
B(-3,32,-3,minecraft:netherrack)
B(-3,33,-3,minecraft:netherrack)
B(-3,34,-3,minecraft:netherrack)
B(-3,35,-3,minecraft:netherrack)
B(-3,36,-3,minecraft:netherrack)
B(-3,0,-2,minecraft:netherrack)
B(-3,1,-2,minecraft:netherrack)
B(-3,2,-2,minecraft:netherrack)
B(-3,3,-2,minecraft:netherrack)
B(-3,4,-2,minecraft:netherrack)
B(-3,5,-2,minecraft:netherrack)
B(-3,6,-2,minecraft:netherrack)
B(-3,7,-2,minecraft:netherrack)
B(-3,8,-2,minecraft:netherrack)
B(-3,9,-2,minecraft:netherrack)
B(-3,10,-2,minecraft:netherrack)
B(-3,11,-2,minecraft:netherrack)
B(-3,12,-2,minecraft:netherrack)
B(-3,13,-2,minecraft:netherrack)
B(-3,14,-2,minecraft:netherrack)
B(-3,15,-2,minecraft:netherrack)
B(-3,16,-2,minecraft:netherrack)
B(-3,17,-2,minecraft:netherrack)
B(-3,18,-2,minecraft:netherrack)
B(-3,19,-2,minecraft:netherrack)
B(-3,20,-2,minecraft:netherrack)
B(-3,21,-2,minecraft:netherrack)
B(-3,22,-2,minecraft:netherrack)
B(-3,23,-2,minecraft:netherrack)
B(-3,24,-2,minecraft:netherrack)
B(-3,25,-2,minecraft:netherrack)
B(-3,26,-2,minecraft:netherrack)
B(-3,27,-2,minecraft:netherrack)
B(-3,28,-2,minecraft:netherrack)
B(-3,29,-2,minecraft:netherrack)
B(-3,30,-2,minecraft:netherrack)
B(-3,31,-2,minecraft:netherrack)
B(-3,32,-2,minecraft:netherrack)
B(-3,33,-2,minecraft:netherrack)
B(-3,34,-2,minecraft:netherrack)
B(-3,35,-2,minecraft:netherrack)
B(-3,0,-1,minecraft:netherrack)
B(-3,1,-1,minecraft:netherrack)
B(-3,2,-1,minecraft:netherrack)
