Author: Bo3 BulkEdit

Description: Converted Schematic - Modified by Bo3BulkEdit

Version: 3

SettingsMode: WriteDisable

IsOTGPlus: true
Tree: false
Frequency: 10
Rarity: 100
RotateRandomly: true
SpawnHeight: randomY
SpawnHeightOffset: 0
SpawnHeightVariance: 0
MaxBranchDepth: 10
ExcludedBiomes: All

MinHeight: 50
MaxHeight: 65

SourceBlocks: AIR
MaxPercentageOutsideSourceBlock: 100
OutsideSourceBlock: placeAnyway

ReplaceBelow: NETHER_WART_BLOCK
ReplaceWithBiomeBlocks: false
ReplaceWithGroundBlock: NETHER_WART_BLOCK
ReplaceWithSurfaceBlock: NETHER_WART_BLOCK
ReplaceWithStoneBlock: NETHER_WART_BLOCK
SmoothRadius: 30
SmoothHeightOffset: 0
SmoothStartTop: false
SmoothStartWood: false
SmoothingSurfaceBlock: NETHER_WART_BLOCK
SmoothingGroundBlock: NETHER_WART_BLOCK

B(0,750,0,AIR)
B(15,750,15,AIR)
B(10,0,0,minecraft:nether_wart_block)
B(11,0,0,minecraft:nether_wart_block)
B(12,0,0,minecraft:nether_wart_block)
B(13,0,0,minecraft:nether_wart_block)
B(14,0,0,minecraft:nether_wart_block)
B(15,0,0,minecraft:nether_wart_block)
B(10,0,1,minecraft:nether_wart_block)
B(11,0,1,minecraft:nether_wart_block)
B(12,0,1,minecraft:nether_wart_block)
B(13,0,1,minecraft:nether_wart_block)
B(14,0,1,minecraft:nether_wart_block)
B(15,0,1,minecraft:nether_wart_block)
B(9,0,2,minecraft:nether_wart_block)
B(10,0,2,minecraft:nether_wart_block)
B(11,0,2,minecraft:nether_wart_block)
B(12,0,2,minecraft:nether_wart_block)
B(13,0,2,minecraft:nether_wart_block)
B(14,0,2,minecraft:nether_wart_block)
B(15,0,2,minecraft:nether_wart_block)
B(9,0,3,minecraft:nether_wart_block)
B(10,0,3,minecraft:nether_wart_block)
B(11,0,3,minecraft:nether_wart_block)
B(12,0,3,minecraft:nether_wart_block)
B(13,0,3,minecraft:nether_wart_block)
B(14,0,3,minecraft:nether_wart_block)
B(15,0,3,minecraft:nether_wart_block)
B(9,0,4,minecraft:nether_wart_block)
B(10,0,4,minecraft:nether_wart_block)
B(11,0,4,minecraft:nether_wart_block)
B(12,0,4,minecraft:nether_wart_block)
B(13,0,4,minecraft:nether_wart_block)
B(14,0,4,minecraft:nether_wart_block)
B(15,0,4,minecraft:nether_wart_block)
B(10,0,5,minecraft:nether_wart_block)
B(11,0,5,minecraft:nether_wart_block)
B(12,0,5,minecraft:nether_wart_block)
B(13,0,5,minecraft:nether_wart_block)
B(14,0,5,minecraft:nether_wart_block)
B(15,0,5,minecraft:nether_wart_block)
B(10,0,6,minecraft:nether_wart_block)
B(11,0,6,minecraft:nether_wart_block)
B(12,0,6,minecraft:nether_wart_block)
B(13,0,6,minecraft:nether_wart_block)
B(14,0,6,minecraft:nether_wart_block)
B(15,0,6,minecraft:nether_wart_block)
B(11,0,7,minecraft:nether_wart_block)
B(12,0,7,minecraft:nether_wart_block)
B(13,0,7,minecraft:nether_wart_block)
B(14,0,7,minecraft:nether_wart_block)
B(15,0,7,minecraft:nether_wart_block)
B(11,0,8,minecraft:nether_wart_block)
B(12,0,8,minecraft:nether_wart_block)
B(13,0,8,minecraft:nether_wart_block)
B(14,0,8,minecraft:nether_wart_block)
B(15,0,8,minecraft:nether_wart_block)
B(12,0,9,minecraft:nether_wart_block)
B(13,0,9,minecraft:nether_wart_block)
B(14,0,9,minecraft:nether_wart_block)
B(15,0,9,minecraft:nether_wart_block)
B(12,0,10,minecraft:nether_wart_block)
B(13,0,10,minecraft:nether_wart_block)
B(14,0,10,minecraft:nether_wart_block)
B(15,0,10,minecraft:nether_wart_block)
B(11,0,11,minecraft:nether_wart_block)
B(12,0,11,minecraft:nether_wart_block)
B(13,0,11,minecraft:nether_wart_block)
B(14,0,11,minecraft:nether_wart_block)
B(15,0,11,minecraft:nether_wart_block)
B(10,0,12,minecraft:nether_wart_block)
B(11,0,12,minecraft:nether_wart_block)
B(12,0,12,minecraft:nether_wart_block)
B(13,0,12,minecraft:nether_wart_block)
B(14,0,12,minecraft:nether_wart_block)
B(15,0,12,minecraft:nether_wart_block)
B(11,0,13,minecraft:nether_wart_block)
B(12,0,13,minecraft:nether_wart_block)
B(13,0,13,minecraft:nether_wart_block)
B(14,0,13,minecraft:nether_wart_block)
B(15,0,13,minecraft:nether_wart_block)
B(11,0,14,minecraft:nether_wart_block)
B(12,0,14,minecraft:nether_wart_block)
B(13,0,14,minecraft:nether_wart_block)
B(14,0,14,minecraft:nether_wart_block)
B(15,0,14,minecraft:nether_wart_block)
B(10,0,15,minecraft:nether_wart_block)
B(11,0,15,minecraft:nether_wart_block)
B(12,0,15,minecraft:nether_wart_block)
B(13,0,15,minecraft:nether_wart_block)
B(14,0,15,minecraft:nether_wart_block)
B(15,0,15,minecraft:nether_wart_block)
B(10,1,0,minecraft:nether_wart_block)
B(11,1,0,minecraft:nether_wart_block)
B(12,1,0,minecraft:nether_wart_block)
B(13,1,0,minecraft:nether_wart_block)
B(14,1,0,minecraft:nether_wart_block)
B(15,1,0,minecraft:nether_wart_block)
B(10,1,1,minecraft:nether_wart_block)
B(11,1,1,minecraft:nether_wart_block)
B(12,1,1,minecraft:nether_wart_block)
B(13,1,1,minecraft:nether_wart_block)
B(14,1,1,minecraft:nether_wart_block)
B(15,1,1,minecraft:nether_wart_block)
B(9,1,2,minecraft:nether_wart_block)
B(10,1,2,minecraft:nether_wart_block)
B(11,1,2,minecraft:nether_wart_block)
B(12,1,2,minecraft:nether_wart_block)
B(13,1,2,minecraft:nether_wart_block)
B(14,1,2,minecraft:nether_wart_block)
B(15,1,2,minecraft:nether_wart_block)
B(9,1,3,minecraft:nether_wart_block)
B(10,1,3,minecraft:nether_wart_block)
B(11,1,3,minecraft:nether_wart_block)
B(12,1,3,minecraft:nether_wart_block)
B(13,1,3,minecraft:nether_wart_block)
B(14,1,3,minecraft:nether_wart_block)
B(15,1,3,minecraft:nether_wart_block)
B(9,1,4,minecraft:nether_wart_block)
B(10,1,4,minecraft:nether_wart_block)
B(11,1,4,minecraft:nether_wart_block)
B(12,1,4,minecraft:nether_wart_block)
B(13,1,4,minecraft:nether_wart_block)
B(14,1,4,minecraft:nether_wart_block)
B(15,1,4,minecraft:nether_wart_block)
B(10,1,5,minecraft:nether_wart_block)
B(11,1,5,minecraft:nether_wart_block)
B(12,1,5,minecraft:nether_wart_block)
B(13,1,5,minecraft:nether_wart_block)
B(14,1,5,minecraft:nether_wart_block)
B(15,1,5,minecraft:nether_wart_block)
B(11,1,6,minecraft:nether_wart_block)
B(12,1,6,minecraft:nether_wart_block)
B(13,1,6,minecraft:nether_wart_block)
B(14,1,6,minecraft:nether_wart_block)
B(15,1,6,minecraft:nether_wart_block)
B(11,1,7,minecraft:nether_wart_block)
B(12,1,7,minecraft:nether_wart_block)
B(13,1,7,minecraft:nether_wart_block)
B(14,1,7,minecraft:nether_wart_block)
B(15,1,7,minecraft:nether_wart_block)
B(11,1,8,minecraft:nether_wart_block)
B(12,1,8,minecraft:nether_wart_block)
B(13,1,8,minecraft:nether_wart_block)
B(14,1,8,minecraft:nether_wart_block)
B(15,1,8,minecraft:nether_wart_block)
B(12,1,9,minecraft:nether_wart_block)
B(13,1,9,minecraft:nether_wart_block)
B(14,1,9,minecraft:nether_wart_block)
B(15,1,9,minecraft:nether_wart_block)
B(12,1,10,minecraft:nether_wart_block)
B(13,1,10,minecraft:nether_wart_block)
B(14,1,10,minecraft:nether_wart_block)
B(15,1,10,minecraft:nether_wart_block)
B(11,1,11,minecraft:nether_wart_block)
B(12,1,11,minecraft:nether_wart_block)
B(13,1,11,minecraft:nether_wart_block)
B(14,1,11,minecraft:nether_wart_block)
B(15,1,11,minecraft:nether_wart_block)
B(11,1,12,minecraft:nether_wart_block)
B(12,1,12,minecraft:nether_wart_block)
B(13,1,12,minecraft:nether_wart_block)
B(14,1,12,minecraft:nether_wart_block)
B(15,1,12,minecraft:nether_wart_block)
B(11,1,13,minecraft:nether_wart_block)
B(12,1,13,minecraft:nether_wart_block)
B(13,1,13,minecraft:nether_wart_block)
B(14,1,13,minecraft:nether_wart_block)
B(15,1,13,minecraft:nether_wart_block)
B(11,1,14,minecraft:nether_wart_block)
B(12,1,14,minecraft:nether_wart_block)
B(13,1,14,minecraft:nether_wart_block)
B(14,1,14,minecraft:nether_wart_block)
B(15,1,14,minecraft:nether_wart_block)
B(10,1,15,minecraft:nether_wart_block)
B(11,1,15,minecraft:nether_wart_block)
B(12,1,15,minecraft:nether_wart_block)
B(13,1,15,minecraft:nether_wart_block)
B(14,1,15,minecraft:nether_wart_block)
B(15,1,15,minecraft:nether_wart_block)
B(10,2,0,minecraft:nether_wart_block)
B(11,2,0,minecraft:nether_wart_block)
B(12,2,0,minecraft:nether_wart_block)
B(13,2,0,minecraft:nether_wart_block)
B(14,2,0,minecraft:nether_wart_block)
B(15,2,0,minecraft:nether_wart_block)
B(10,2,1,minecraft:nether_wart_block)
B(11,2,1,minecraft:nether_wart_block)
B(12,2,1,minecraft:nether_wart_block)
B(13,2,1,minecraft:nether_wart_block)
B(14,2,1,minecraft:nether_wart_block)
B(15,2,1,minecraft:nether_wart_block)
B(10,2,2,minecraft:nether_wart_block)
B(11,2,2,minecraft:nether_wart_block)
B(12,2,2,minecraft:nether_wart_block)
B(13,2,2,minecraft:nether_wart_block)
B(14,2,2,minecraft:nether_wart_block)
B(15,2,2,minecraft:nether_wart_block)
B(9,2,3,minecraft:nether_wart_block)
B(10,2,3,minecraft:nether_wart_block)
B(11,2,3,minecraft:nether_wart_block)
B(12,2,3,minecraft:nether_wart_block)
B(13,2,3,minecraft:nether_wart_block)
B(14,2,3,minecraft:nether_wart_block)
B(15,2,3,minecraft:nether_wart_block)
B(9,2,4,minecraft:nether_wart_block)
B(10,2,4,minecraft:nether_wart_block)
B(11,2,4,minecraft:nether_wart_block)
B(12,2,4,minecraft:nether_wart_block)
B(13,2,4,minecraft:nether_wart_block)
B(14,2,4,minecraft:nether_wart_block)
B(15,2,4,minecraft:nether_wart_block)
B(10,2,5,minecraft:nether_wart_block)
B(11,2,5,minecraft:nether_wart_block)
B(12,2,5,minecraft:nether_wart_block)
B(13,2,5,minecraft:nether_wart_block)
B(14,2,5,minecraft:nether_wart_block)
B(15,2,5,minecraft:nether_wart_block)
B(11,2,6,minecraft:nether_wart_block)
B(12,2,6,minecraft:nether_wart_block)
B(13,2,6,minecraft:nether_wart_block)
B(14,2,6,minecraft:nether_wart_block)
B(15,2,6,minecraft:nether_wart_block)
B(11,2,7,minecraft:nether_wart_block)
B(12,2,7,minecraft:nether_wart_block)
B(13,2,7,minecraft:nether_wart_block)
B(14,2,7,minecraft:nether_wart_block)
B(15,2,7,minecraft:nether_wart_block)
B(11,2,8,minecraft:nether_wart_block)
B(12,2,8,minecraft:nether_wart_block)
B(13,2,8,minecraft:nether_wart_block)
B(14,2,8,minecraft:nether_wart_block)
B(15,2,8,minecraft:nether_wart_block)
B(12,2,9,minecraft:nether_wart_block)
B(13,2,9,minecraft:nether_wart_block)
B(14,2,9,minecraft:nether_wart_block)
B(15,2,9,minecraft:nether_wart_block)
B(12,2,10,minecraft:nether_wart_block)
B(13,2,10,minecraft:nether_wart_block)
B(14,2,10,minecraft:nether_wart_block)
B(15,2,10,minecraft:nether_wart_block)
B(11,2,11,minecraft:nether_wart_block)
B(12,2,11,minecraft:nether_wart_block)
B(13,2,11,minecraft:nether_wart_block)
B(14,2,11,minecraft:nether_wart_block)
B(15,2,11,minecraft:nether_wart_block)
B(11,2,12,minecraft:nether_wart_block)
B(12,2,12,minecraft:nether_wart_block)
B(13,2,12,minecraft:nether_wart_block)
B(14,2,12,minecraft:nether_wart_block)
B(15,2,12,minecraft:nether_wart_block)
B(11,2,13,minecraft:nether_wart_block)
B(12,2,13,minecraft:nether_wart_block)
B(13,2,13,minecraft:nether_wart_block)
B(14,2,13,minecraft:nether_wart_block)
B(15,2,13,minecraft:nether_wart_block)
B(11,2,14,minecraft:nether_wart_block)
B(12,2,14,minecraft:nether_wart_block)
B(13,2,14,minecraft:nether_wart_block)
B(14,2,14,minecraft:nether_wart_block)
B(15,2,14,minecraft:nether_wart_block)
B(10,2,15,minecraft:nether_wart_block)
B(11,2,15,minecraft:nether_wart_block)
B(12,2,15,minecraft:nether_wart_block)
B(13,2,15,minecraft:nether_wart_block)
B(14,2,15,minecraft:nether_wart_block)
B(15,2,15,minecraft:nether_wart_block)
B(10,3,0,minecraft:nether_wart_block)
B(11,3,0,minecraft:nether_wart_block)
B(12,3,0,minecraft:nether_wart_block)
B(13,3,0,minecraft:nether_wart_block)
B(14,3,0,minecraft:nether_wart_block)
B(15,3,0,minecraft:nether_wart_block)
B(10,3,1,minecraft:nether_wart_block)
B(11,3,1,minecraft:nether_wart_block)
B(12,3,1,minecraft:nether_wart_block)
B(13,3,1,minecraft:nether_wart_block)
B(14,3,1,minecraft:nether_wart_block)
B(15,3,1,minecraft:nether_wart_block)
B(10,3,2,minecraft:nether_wart_block)
B(11,3,2,minecraft:nether_wart_block)
B(12,3,2,minecraft:nether_wart_block)
B(13,3,2,minecraft:nether_wart_block)
B(14,3,2,minecraft:nether_wart_block)
B(15,3,2,minecraft:nether_wart_block)
B(9,3,3,minecraft:nether_wart_block)
B(10,3,3,minecraft:nether_wart_block)
B(11,3,3,minecraft:nether_wart_block)
B(12,3,3,minecraft:nether_wart_block)
B(13,3,3,minecraft:nether_wart_block)
B(14,3,3,minecraft:nether_wart_block)
B(15,3,3,minecraft:nether_wart_block)
B(10,3,4,minecraft:nether_wart_block)
B(11,3,4,minecraft:nether_wart_block)
B(12,3,4,minecraft:nether_wart_block)
B(13,3,4,minecraft:nether_wart_block)
B(14,3,4,minecraft:nether_wart_block)
B(15,3,4,minecraft:nether_wart_block)
B(10,3,5,minecraft:nether_wart_block)
B(11,3,5,minecraft:nether_wart_block)
B(12,3,5,minecraft:nether_wart_block)
B(13,3,5,minecraft:nether_wart_block)
B(14,3,5,minecraft:nether_wart_block)
B(15,3,5,minecraft:nether_wart_block)
B(11,3,6,minecraft:nether_wart_block)
B(12,3,6,minecraft:nether_wart_block)
B(13,3,6,minecraft:nether_wart_block)
B(14,3,6,minecraft:nether_wart_block)
B(15,3,6,minecraft:nether_wart_block)
B(11,3,7,minecraft:nether_wart_block)
B(12,3,7,minecraft:nether_wart_block)
B(13,3,7,minecraft:nether_wart_block)
B(14,3,7,minecraft:nether_wart_block)
B(15,3,7,minecraft:nether_wart_block)
B(11,3,8,minecraft:nether_wart_block)
B(12,3,8,minecraft:nether_wart_block)
B(13,3,8,minecraft:nether_wart_block)
B(14,3,8,minecraft:nether_wart_block)
B(15,3,8,minecraft:nether_wart_block)
B(12,3,9,minecraft:nether_wart_block)
B(13,3,9,minecraft:nether_wart_block)
B(14,3,9,minecraft:nether_wart_block)
B(15,3,9,minecraft:nether_wart_block)
B(12,3,10,minecraft:nether_wart_block)
B(13,3,10,minecraft:nether_wart_block)
B(14,3,10,minecraft:nether_wart_block)
B(15,3,10,minecraft:nether_wart_block)
B(11,3,11,minecraft:nether_wart_block)
B(12,3,11,minecraft:nether_wart_block)
B(13,3,11,minecraft:nether_wart_block)
B(14,3,11,minecraft:nether_wart_block)
B(15,3,11,minecraft:nether_wart_block)
B(11,3,12,minecraft:nether_wart_block)
B(12,3,12,minecraft:nether_wart_block)
B(13,3,12,minecraft:nether_wart_block)
B(14,3,12,minecraft:nether_wart_block)
B(15,3,12,minecraft:nether_wart_block)
B(11,3,13,minecraft:nether_wart_block)
B(12,3,13,minecraft:nether_wart_block)
B(13,3,13,minecraft:nether_wart_block)
B(14,3,13,minecraft:nether_wart_block)
B(15,3,13,minecraft:nether_wart_block)
B(11,3,14,minecraft:nether_wart_block)
B(12,3,14,minecraft:nether_wart_block)
B(13,3,14,minecraft:nether_wart_block)
B(14,3,14,minecraft:nether_wart_block)
B(15,3,14,minecraft:nether_wart_block)
B(10,3,15,minecraft:nether_wart_block)
B(11,3,15,minecraft:nether_wart_block)
B(12,3,15,minecraft:nether_wart_block)
B(13,3,15,minecraft:nether_wart_block)
B(14,3,15,minecraft:nether_wart_block)
B(15,3,15,minecraft:nether_wart_block)
B(11,4,0,minecraft:nether_wart_block)
B(12,4,0,minecraft:nether_wart_block)
B(13,4,0,minecraft:nether_wart_block)
B(14,4,0,minecraft:nether_wart_block)
B(15,4,0,minecraft:nether_wart_block)
B(10,4,1,minecraft:nether_wart_block)
B(11,4,1,minecraft:nether_wart_block)
B(12,4,1,minecraft:nether_wart_block)
B(13,4,1,minecraft:nether_wart_block)
B(14,4,1,minecraft:nether_wart_block)
B(15,4,1,minecraft:nether_wart_block)
B(10,4,2,minecraft:nether_wart_block)
B(11,4,2,minecraft:nether_wart_block)
B(12,4,2,minecraft:nether_wart_block)
B(13,4,2,minecraft:nether_wart_block)
B(14,4,2,minecraft:nether_wart_block)
B(15,4,2,minecraft:nether_wart_block)
B(9,4,3,minecraft:nether_wart_block)
B(10,4,3,minecraft:nether_wart_block)
B(11,4,3,minecraft:nether_wart_block)
B(12,4,3,minecraft:nether_wart_block)
B(13,4,3,minecraft:nether_wart_block)
B(14,4,3,minecraft:nether_wart_block)
B(15,4,3,minecraft:nether_wart_block)
B(10,4,4,minecraft:nether_wart_block)
B(11,4,4,minecraft:nether_wart_block)
B(12,4,4,minecraft:nether_wart_block)
B(13,4,4,minecraft:nether_wart_block)
B(14,4,4,minecraft:nether_wart_block)
B(15,4,4,minecraft:nether_wart_block)
B(10,4,5,minecraft:nether_wart_block)
B(11,4,5,minecraft:nether_wart_block)
B(12,4,5,minecraft:nether_wart_block)
B(13,4,5,minecraft:nether_wart_block)
B(14,4,5,minecraft:nether_wart_block)
B(15,4,5,minecraft:nether_wart_block)
B(11,4,6,minecraft:nether_wart_block)
B(12,4,6,minecraft:nether_wart_block)
B(13,4,6,minecraft:nether_wart_block)
B(14,4,6,minecraft:nether_wart_block)
B(15,4,6,minecraft:nether_wart_block)
B(11,4,7,minecraft:nether_wart_block)
B(12,4,7,minecraft:nether_wart_block)
B(13,4,7,minecraft:nether_wart_block)
B(14,4,7,minecraft:nether_wart_block)
B(15,4,7,minecraft:nether_wart_block)
B(11,4,8,minecraft:nether_wart_block)
B(12,4,8,minecraft:nether_wart_block)
B(13,4,8,minecraft:nether_wart_block)
B(14,4,8,minecraft:nether_wart_block)
B(15,4,8,minecraft:nether_wart_block)
B(12,4,9,minecraft:nether_wart_block)
B(13,4,9,minecraft:nether_wart_block)
B(14,4,9,minecraft:nether_wart_block)
B(15,4,9,minecraft:nether_wart_block)
B(12,4,10,minecraft:nether_wart_block)
B(13,4,10,minecraft:nether_wart_block)
B(14,4,10,minecraft:nether_wart_block)
B(15,4,10,minecraft:nether_wart_block)
B(11,4,11,minecraft:nether_wart_block)
B(12,4,11,minecraft:nether_wart_block)
B(13,4,11,minecraft:nether_wart_block)
B(14,4,11,minecraft:nether_wart_block)
B(15,4,11,minecraft:nether_wart_block)
B(11,4,12,minecraft:nether_wart_block)
B(12,4,12,minecraft:nether_wart_block)
B(13,4,12,minecraft:nether_wart_block)
B(14,4,12,minecraft:nether_wart_block)
B(15,4,12,minecraft:nether_wart_block)
B(11,4,13,minecraft:nether_wart_block)
B(12,4,13,minecraft:nether_wart_block)
B(13,4,13,minecraft:nether_wart_block)
B(14,4,13,minecraft:nether_wart_block)
B(15,4,13,minecraft:nether_wart_block)
B(11,4,14,minecraft:nether_wart_block)
B(12,4,14,minecraft:nether_wart_block)
B(13,4,14,minecraft:nether_wart_block)
B(14,4,14,minecraft:nether_wart_block)
B(15,4,14,minecraft:nether_wart_block)
B(10,4,15,minecraft:nether_wart_block)
B(11,4,15,minecraft:nether_wart_block)
B(12,4,15,minecraft:nether_wart_block)
B(13,4,15,minecraft:nether_wart_block)
B(14,4,15,minecraft:nether_wart_block)
B(15,4,15,minecraft:nether_wart_block)
B(11,5,0,minecraft:nether_wart_block)
B(12,5,0,minecraft:nether_wart_block)
B(13,5,0,minecraft:nether_wart_block)
B(14,5,0,minecraft:nether_wart_block)
B(15,5,0,minecraft:nether_wart_block)
B(10,5,1,minecraft:nether_wart_block)
B(11,5,1,minecraft:nether_wart_block)
B(12,5,1,minecraft:nether_wart_block)
B(13,5,1,minecraft:nether_wart_block)
B(14,5,1,minecraft:nether_wart_block)
B(15,5,1,minecraft:nether_wart_block)
B(10,5,2,minecraft:nether_wart_block)
B(11,5,2,minecraft:nether_wart_block)
B(12,5,2,minecraft:nether_wart_block)
B(13,5,2,minecraft:nether_wart_block)
B(14,5,2,minecraft:nether_wart_block)
B(15,5,2,minecraft:nether_wart_block)
B(10,5,3,minecraft:nether_wart_block)
B(11,5,3,minecraft:nether_wart_block)
B(12,5,3,minecraft:nether_wart_block)
B(13,5,3,minecraft:nether_wart_block)
B(14,5,3,minecraft:nether_wart_block)
B(15,5,3,minecraft:nether_wart_block)
B(10,5,4,minecraft:nether_wart_block)
B(11,5,4,minecraft:nether_wart_block)
B(12,5,4,minecraft:nether_wart_block)
B(13,5,4,minecraft:nether_wart_block)
B(14,5,4,minecraft:nether_wart_block)
B(15,5,4,minecraft:nether_wart_block)
B(10,5,5,minecraft:nether_wart_block)
B(11,5,5,minecraft:nether_wart_block)
B(12,5,5,minecraft:nether_wart_block)
B(13,5,5,minecraft:nether_wart_block)
B(14,5,5,minecraft:nether_wart_block)
B(15,5,5,minecraft:nether_wart_block)
B(11,5,6,minecraft:nether_wart_block)
B(12,5,6,minecraft:nether_wart_block)
B(13,5,6,minecraft:nether_wart_block)
B(14,5,6,minecraft:nether_wart_block)
B(15,5,6,minecraft:nether_wart_block)
B(11,5,7,minecraft:nether_wart_block)
B(12,5,7,minecraft:nether_wart_block)
B(13,5,7,minecraft:nether_wart_block)
B(14,5,7,minecraft:nether_wart_block)
B(15,5,7,minecraft:nether_wart_block)
B(12,5,8,minecraft:nether_wart_block)
B(13,5,8,minecraft:nether_wart_block)
B(14,5,8,minecraft:nether_wart_block)
B(15,5,8,minecraft:nether_wart_block)
B(12,5,9,minecraft:nether_wart_block)
B(13,5,9,minecraft:nether_wart_block)
B(14,5,9,minecraft:nether_wart_block)
B(15,5,9,minecraft:nether_wart_block)
B(12,5,10,minecraft:nether_wart_block)
B(13,5,10,minecraft:nether_wart_block)
B(14,5,10,minecraft:nether_wart_block)
B(15,5,10,minecraft:nether_wart_block)
B(12,5,11,minecraft:nether_wart_block)
B(13,5,11,minecraft:nether_wart_block)
B(14,5,11,minecraft:nether_wart_block)
B(15,5,11,minecraft:nether_wart_block)
B(11,5,12,minecraft:nether_wart_block)
B(12,5,12,minecraft:nether_wart_block)
B(13,5,12,minecraft:nether_wart_block)
B(14,5,12,minecraft:nether_wart_block)
B(15,5,12,minecraft:nether_wart_block)
B(11,5,13,minecraft:nether_wart_block)
B(12,5,13,minecraft:nether_wart_block)
B(13,5,13,minecraft:nether_wart_block)
B(14,5,13,minecraft:nether_wart_block)
B(15,5,13,minecraft:nether_wart_block)
B(11,5,14,minecraft:nether_wart_block)
B(12,5,14,minecraft:nether_wart_block)
B(13,5,14,minecraft:nether_wart_block)
B(14,5,14,minecraft:nether_wart_block)
B(15,5,14,minecraft:nether_wart_block)
B(10,5,15,minecraft:nether_wart_block)
B(11,5,15,minecraft:nether_wart_block)
B(12,5,15,minecraft:nether_wart_block)
B(13,5,15,minecraft:nether_wart_block)
B(14,5,15,minecraft:nether_wart_block)
B(15,5,15,minecraft:nether_wart_block)
B(11,6,0,minecraft:nether_wart_block)
B(12,6,0,minecraft:nether_wart_block)
B(13,6,0,minecraft:nether_wart_block)
B(14,6,0,minecraft:nether_wart_block)
B(15,6,0,minecraft:nether_wart_block)
B(10,6,1,minecraft:nether_wart_block)
B(11,6,1,minecraft:nether_wart_block)
B(12,6,1,minecraft:nether_wart_block)
B(13,6,1,minecraft:nether_wart_block)
B(14,6,1,minecraft:nether_wart_block)
B(15,6,1,minecraft:nether_wart_block)
B(10,6,2,minecraft:nether_wart_block)
B(11,6,2,minecraft:nether_wart_block)
B(12,6,2,minecraft:nether_wart_block)
B(13,6,2,minecraft:nether_wart_block)
B(14,6,2,minecraft:nether_wart_block)
B(15,6,2,minecraft:nether_wart_block)
B(10,6,3,minecraft:nether_wart_block)
B(11,6,3,minecraft:nether_wart_block)
B(12,6,3,minecraft:nether_wart_block)
B(13,6,3,minecraft:nether_wart_block)
B(14,6,3,minecraft:nether_wart_block)
B(15,6,3,minecraft:nether_wart_block)
B(10,6,4,minecraft:nether_wart_block)
B(11,6,4,minecraft:nether_wart_block)
B(12,6,4,minecraft:nether_wart_block)
B(13,6,4,minecraft:nether_wart_block)
B(14,6,4,minecraft:nether_wart_block)
B(15,6,4,minecraft:nether_wart_block)
B(11,6,5,minecraft:nether_wart_block)
B(12,6,5,minecraft:nether_wart_block)
B(13,6,5,minecraft:nether_wart_block)
B(14,6,5,minecraft:nether_wart_block)
B(15,6,5,minecraft:nether_wart_block)
B(11,6,6,minecraft:nether_wart_block)
B(12,6,6,minecraft:nether_wart_block)
B(13,6,6,minecraft:nether_wart_block)
B(14,6,6,minecraft:nether_wart_block)
B(15,6,6,minecraft:nether_wart_block)
B(12,6,7,minecraft:nether_wart_block)
B(13,6,7,minecraft:nether_wart_block)
B(14,6,7,minecraft:nether_wart_block)
B(15,6,7,minecraft:nether_wart_block)
B(12,6,8,minecraft:nether_wart_block)
B(13,6,8,minecraft:nether_wart_block)
B(14,6,8,minecraft:nether_wart_block)
B(15,6,8,minecraft:nether_wart_block)
B(12,6,9,minecraft:nether_wart_block)
B(13,6,9,minecraft:nether_wart_block)
B(14,6,9,minecraft:nether_wart_block)
B(15,6,9,minecraft:nether_wart_block)
B(12,6,10,minecraft:nether_wart_block)
B(13,6,10,minecraft:nether_wart_block)
B(14,6,10,minecraft:nether_wart_block)
B(15,6,10,minecraft:nether_wart_block)
B(12,6,11,minecraft:nether_wart_block)
B(13,6,11,minecraft:nether_wart_block)
B(14,6,11,minecraft:nether_wart_block)
B(15,6,11,minecraft:nether_wart_block)
B(11,6,12,minecraft:nether_wart_block)
B(12,6,12,minecraft:nether_wart_block)
B(13,6,12,minecraft:nether_wart_block)
B(14,6,12,minecraft:nether_wart_block)
B(15,6,12,minecraft:nether_wart_block)
B(11,6,13,minecraft:nether_wart_block)
B(12,6,13,minecraft:nether_wart_block)
B(13,6,13,minecraft:nether_wart_block)
B(14,6,13,minecraft:nether_wart_block)
B(15,6,13,minecraft:nether_wart_block)
B(11,6,14,minecraft:nether_wart_block)
B(12,6,14,minecraft:nether_wart_block)
B(13,6,14,minecraft:nether_wart_block)
B(14,6,14,minecraft:nether_wart_block)
B(15,6,14,minecraft:nether_wart_block)
B(10,6,15,minecraft:nether_wart_block)
B(11,6,15,minecraft:nether_wart_block)
B(12,6,15,minecraft:nether_wart_block)
B(13,6,15,minecraft:nether_wart_block)
B(14,6,15,minecraft:nether_wart_block)
B(15,6,15,minecraft:nether_wart_block)
B(11,7,0,minecraft:nether_wart_block)
B(12,7,0,minecraft:nether_wart_block)
B(13,7,0,minecraft:nether_wart_block)
B(14,7,0,minecraft:nether_wart_block)
B(15,7,0,minecraft:nether_wart_block)
B(10,7,1,minecraft:nether_wart_block)
B(11,7,1,minecraft:nether_wart_block)
B(12,7,1,minecraft:nether_wart_block)
B(13,7,1,minecraft:nether_wart_block)
B(14,7,1,minecraft:nether_wart_block)
B(15,7,1,minecraft:nether_wart_block)
B(10,7,2,minecraft:nether_wart_block)
B(11,7,2,minecraft:nether_wart_block)
B(12,7,2,minecraft:nether_wart_block)
B(13,7,2,minecraft:nether_wart_block)
B(14,7,2,minecraft:nether_wart_block)
B(15,7,2,minecraft:nether_wart_block)
B(10,7,3,minecraft:nether_wart_block)
B(11,7,3,minecraft:nether_wart_block)
B(12,7,3,minecraft:nether_wart_block)
B(13,7,3,minecraft:nether_wart_block)
B(14,7,3,minecraft:nether_wart_block)
B(15,7,3,minecraft:nether_wart_block)
B(10,7,4,minecraft:nether_wart_block)
B(11,7,4,minecraft:nether_wart_block)
B(12,7,4,minecraft:nether_wart_block)
B(13,7,4,minecraft:nether_wart_block)
B(14,7,4,minecraft:nether_wart_block)
B(15,7,4,minecraft:nether_wart_block)
B(11,7,5,minecraft:nether_wart_block)
B(12,7,5,minecraft:nether_wart_block)
B(13,7,5,minecraft:nether_wart_block)
B(14,7,5,minecraft:nether_wart_block)
B(15,7,5,minecraft:nether_wart_block)
B(11,7,6,minecraft:nether_wart_block)
B(12,7,6,minecraft:nether_wart_block)
B(13,7,6,minecraft:nether_wart_block)
B(14,7,6,minecraft:nether_wart_block)
B(15,7,6,minecraft:nether_wart_block)
B(12,7,7,minecraft:nether_wart_block)
B(13,7,7,minecraft:nether_wart_block)
B(14,7,7,minecraft:nether_wart_block)
B(15,7,7,minecraft:nether_wart_block)
B(12,7,8,minecraft:nether_wart_block)
B(13,7,8,minecraft:nether_wart_block)
B(14,7,8,minecraft:nether_wart_block)
B(15,7,8,minecraft:nether_wart_block)
B(12,7,9,minecraft:nether_wart_block)
B(13,7,9,minecraft:nether_wart_block)
B(14,7,9,minecraft:nether_wart_block)
B(15,7,9,minecraft:nether_wart_block)
B(12,7,10,minecraft:nether_wart_block)
B(13,7,10,minecraft:nether_wart_block)
B(14,7,10,minecraft:nether_wart_block)
B(15,7,10,minecraft:nether_wart_block)
B(12,7,11,minecraft:nether_wart_block)
B(13,7,11,minecraft:nether_wart_block)
B(14,7,11,minecraft:nether_wart_block)
B(15,7,11,minecraft:nether_wart_block)
B(11,7,12,minecraft:nether_wart_block)
B(12,7,12,minecraft:nether_wart_block)
B(13,7,12,minecraft:nether_wart_block)
B(14,7,12,minecraft:nether_wart_block)
B(15,7,12,minecraft:nether_wart_block)
B(11,7,13,minecraft:nether_wart_block)
B(12,7,13,minecraft:nether_wart_block)
B(13,7,13,minecraft:nether_wart_block)
B(14,7,13,minecraft:nether_wart_block)
B(15,7,13,minecraft:nether_wart_block)
B(11,7,14,minecraft:nether_wart_block)
B(12,7,14,minecraft:nether_wart_block)
B(13,7,14,minecraft:nether_wart_block)
B(14,7,14,minecraft:nether_wart_block)
B(15,7,14,minecraft:nether_wart_block)
B(10,7,15,minecraft:nether_wart_block)
B(11,7,15,minecraft:nether_wart_block)
B(12,7,15,minecraft:nether_wart_block)
B(13,7,15,minecraft:nether_wart_block)
B(14,7,15,minecraft:nether_wart_block)
B(15,7,15,minecraft:nether_wart_block)
B(11,8,0,minecraft:nether_wart_block)
B(12,8,0,minecraft:nether_wart_block)
B(13,8,0,minecraft:nether_wart_block)
B(14,8,0,minecraft:nether_wart_block)
B(15,8,0,minecraft:nether_wart_block)
B(10,8,1,minecraft:nether_wart_block)
B(11,8,1,minecraft:nether_wart_block)
B(12,8,1,minecraft:nether_wart_block)
B(13,8,1,minecraft:nether_wart_block)
B(14,8,1,minecraft:nether_wart_block)
B(15,8,1,minecraft:nether_wart_block)
B(10,8,2,minecraft:nether_wart_block)
B(11,8,2,minecraft:nether_wart_block)
B(12,8,2,minecraft:nether_wart_block)
B(13,8,2,minecraft:nether_wart_block)
B(14,8,2,minecraft:nether_wart_block)
B(15,8,2,minecraft:nether_wart_block)
B(10,8,3,minecraft:nether_wart_block)
B(11,8,3,minecraft:nether_wart_block)
B(12,8,3,minecraft:nether_wart_block)
B(13,8,3,minecraft:nether_wart_block)
B(14,8,3,minecraft:nether_wart_block)
B(15,8,3,minecraft:nether_wart_block)
B(10,8,4,minecraft:nether_wart_block)
B(11,8,4,minecraft:nether_wart_block)
B(12,8,4,minecraft:nether_wart_block)
B(13,8,4,minecraft:nether_wart_block)
B(14,8,4,minecraft:nether_wart_block)
B(15,8,4,minecraft:nether_wart_block)
B(11,8,5,minecraft:nether_wart_block)
B(12,8,5,minecraft:nether_wart_block)
B(13,8,5,minecraft:nether_wart_block)
B(14,8,5,minecraft:nether_wart_block)
B(15,8,5,minecraft:nether_wart_block)
B(11,8,6,minecraft:nether_wart_block)
B(12,8,6,minecraft:nether_wart_block)
B(13,8,6,minecraft:nether_wart_block)
B(14,8,6,minecraft:nether_wart_block)
B(15,8,6,minecraft:nether_wart_block)
B(12,8,7,minecraft:nether_wart_block)
B(13,8,7,minecraft:nether_wart_block)
B(14,8,7,minecraft:nether_wart_block)
B(15,8,7,minecraft:nether_wart_block)
B(12,8,8,minecraft:nether_wart_block)
B(13,8,8,minecraft:nether_wart_block)
B(14,8,8,minecraft:nether_wart_block)
B(15,8,8,minecraft:nether_wart_block)
B(12,8,9,minecraft:nether_wart_block)
B(13,8,9,minecraft:nether_wart_block)
B(14,8,9,minecraft:nether_wart_block)
B(15,8,9,minecraft:nether_wart_block)
B(12,8,10,minecraft:nether_wart_block)
B(13,8,10,minecraft:nether_wart_block)
B(14,8,10,minecraft:nether_wart_block)
B(15,8,10,minecraft:nether_wart_block)
B(12,8,11,minecraft:nether_wart_block)
B(13,8,11,minecraft:nether_wart_block)
B(14,8,11,minecraft:nether_wart_block)
B(15,8,11,minecraft:nether_wart_block)
B(11,8,12,minecraft:nether_wart_block)
B(12,8,12,minecraft:nether_wart_block)
B(13,8,12,minecraft:nether_wart_block)
B(14,8,12,minecraft:nether_wart_block)
B(15,8,12,minecraft:nether_wart_block)
B(11,8,13,minecraft:nether_wart_block)
B(12,8,13,minecraft:nether_wart_block)
B(13,8,13,minecraft:nether_wart_block)
B(14,8,13,minecraft:nether_wart_block)
B(15,8,13,minecraft:nether_wart_block)
B(11,8,14,minecraft:nether_wart_block)
B(12,8,14,minecraft:nether_wart_block)
B(13,8,14,minecraft:nether_wart_block)
B(14,8,14,minecraft:nether_wart_block)
B(15,8,14,minecraft:nether_wart_block)
B(11,8,15,minecraft:nether_wart_block)
B(12,8,15,minecraft:nether_wart_block)
B(13,8,15,minecraft:nether_wart_block)
B(14,8,15,minecraft:nether_wart_block)
B(15,8,15,minecraft:nether_wart_block)
B(11,9,0,minecraft:nether_wart_block)
B(12,9,0,minecraft:nether_wart_block)
B(13,9,0,minecraft:nether_wart_block)
B(14,9,0,minecraft:nether_wart_block)
B(15,9,0,minecraft:nether_wart_block)
B(11,9,1,minecraft:nether_wart_block)
B(12,9,1,minecraft:nether_wart_block)
B(13,9,1,minecraft:nether_wart_block)
B(14,9,1,minecraft:nether_wart_block)
B(15,9,1,minecraft:nether_wart_block)
B(10,9,2,minecraft:nether_wart_block)
B(11,9,2,minecraft:nether_wart_block)
B(12,9,2,minecraft:nether_wart_block)
B(13,9,2,minecraft:nether_wart_block)
B(14,9,2,minecraft:nether_wart_block)
B(15,9,2,minecraft:nether_wart_block)
B(10,9,3,minecraft:nether_wart_block)
B(11,9,3,minecraft:nether_wart_block)
B(12,9,3,minecraft:nether_wart_block)
B(13,9,3,minecraft:nether_wart_block)
B(14,9,3,minecraft:nether_wart_block)
B(15,9,3,minecraft:nether_wart_block)
B(10,9,4,minecraft:nether_wart_block)
B(11,9,4,minecraft:nether_wart_block)
B(12,9,4,minecraft:nether_wart_block)
B(13,9,4,minecraft:nether_wart_block)
B(14,9,4,minecraft:nether_wart_block)
B(15,9,4,minecraft:nether_wart_block)
B(11,9,5,minecraft:nether_wart_block)
B(12,9,5,minecraft:nether_wart_block)
B(13,9,5,minecraft:nether_wart_block)
B(14,9,5,minecraft:nether_wart_block)
B(15,9,5,minecraft:nether_wart_block)
B(12,9,6,minecraft:nether_wart_block)
B(13,9,6,minecraft:nether_wart_block)
B(14,9,6,minecraft:nether_wart_block)
B(15,9,6,minecraft:nether_wart_block)
B(12,9,7,minecraft:nether_wart_block)
B(13,9,7,minecraft:nether_wart_block)
B(14,9,7,minecraft:nether_wart_block)
B(15,9,7,minecraft:nether_wart_block)
B(12,9,8,minecraft:nether_wart_block)
B(13,9,8,minecraft:nether_wart_block)
B(14,9,8,minecraft:nether_wart_block)
B(15,9,8,minecraft:nether_wart_block)
B(13,9,9,minecraft:nether_wart_block)
B(14,9,9,minecraft:nether_wart_block)
B(15,9,9,minecraft:nether_wart_block)
B(13,9,10,minecraft:nether_wart_block)
B(14,9,10,minecraft:nether_wart_block)
B(15,9,10,minecraft:nether_wart_block)
B(12,9,11,minecraft:nether_wart_block)
B(13,9,11,minecraft:nether_wart_block)
B(14,9,11,minecraft:nether_wart_block)
B(15,9,11,minecraft:nether_wart_block)
B(11,9,12,minecraft:nether_wart_block)
B(12,9,12,minecraft:nether_wart_block)
B(13,9,12,minecraft:nether_wart_block)
B(14,9,12,minecraft:nether_wart_block)
B(15,9,12,minecraft:nether_wart_block)
B(11,9,13,minecraft:nether_wart_block)
B(12,9,13,minecraft:nether_wart_block)
B(13,9,13,minecraft:nether_wart_block)
B(14,9,13,minecraft:nether_wart_block)
B(15,9,13,minecraft:nether_wart_block)
B(11,9,14,minecraft:nether_wart_block)
B(12,9,14,minecraft:nether_wart_block)
B(13,9,14,minecraft:nether_wart_block)
B(14,9,14,minecraft:nether_wart_block)
B(15,9,14,minecraft:nether_wart_block)
B(11,9,15,minecraft:nether_wart_block)
B(12,9,15,minecraft:nether_wart_block)
B(13,9,15,minecraft:nether_wart_block)
B(14,9,15,minecraft:nether_wart_block)
B(15,9,15,minecraft:nether_wart_block)
B(11,10,0,minecraft:nether_wart_block)
B(12,10,0,minecraft:nether_wart_block)
B(13,10,0,minecraft:nether_wart_block)
B(14,10,0,minecraft:nether_wart_block)
B(15,10,0,minecraft:nether_wart_block)
B(11,10,1,minecraft:nether_wart_block)
B(12,10,1,minecraft:nether_wart_block)
B(13,10,1,minecraft:nether_wart_block)
B(14,10,1,minecraft:nether_wart_block)
B(15,10,1,minecraft:nether_wart_block)
B(11,10,2,minecraft:nether_wart_block)
B(12,10,2,minecraft:nether_wart_block)
B(13,10,2,minecraft:nether_wart_block)
B(14,10,2,minecraft:nether_wart_block)
B(15,10,2,minecraft:nether_wart_block)
B(11,10,3,minecraft:nether_wart_block)
B(12,10,3,minecraft:nether_wart_block)
B(13,10,3,minecraft:nether_wart_block)
B(14,10,3,minecraft:nether_wart_block)
B(15,10,3,minecraft:nether_wart_block)
B(11,10,4,minecraft:nether_wart_block)
B(12,10,4,minecraft:nether_wart_block)
B(13,10,4,minecraft:nether_wart_block)
B(14,10,4,minecraft:nether_wart_block)
B(15,10,4,minecraft:nether_wart_block)
B(12,10,5,minecraft:nether_wart_block)
B(13,10,5,minecraft:nether_wart_block)
B(14,10,5,minecraft:nether_wart_block)
B(15,10,5,minecraft:nether_wart_block)
B(12,10,6,minecraft:nether_wart_block)
B(13,10,6,minecraft:nether_wart_block)
B(14,10,6,minecraft:nether_wart_block)
B(15,10,6,minecraft:nether_wart_block)
B(12,10,7,minecraft:nether_wart_block)
B(13,10,7,minecraft:nether_wart_block)
B(14,10,7,minecraft:nether_wart_block)
B(15,10,7,minecraft:nether_wart_block)
B(12,10,8,minecraft:nether_wart_block)
B(13,10,8,minecraft:nether_wart_block)
B(14,10,8,minecraft:nether_wart_block)
B(15,10,8,minecraft:nether_wart_block)
B(13,10,9,minecraft:nether_wart_block)
B(14,10,9,minecraft:nether_wart_block)
B(15,10,9,minecraft:nether_wart_block)
B(13,10,10,minecraft:nether_wart_block)
B(14,10,10,minecraft:nether_wart_block)
B(15,10,10,minecraft:nether_wart_block)
B(12,10,11,minecraft:nether_wart_block)
B(13,10,11,minecraft:nether_wart_block)
B(14,10,11,minecraft:nether_wart_block)
B(15,10,11,minecraft:nether_wart_block)
B(11,10,12,minecraft:nether_wart_block)
B(12,10,12,minecraft:nether_wart_block)
B(13,10,12,minecraft:nether_wart_block)
B(14,10,12,minecraft:nether_wart_block)
B(15,10,12,minecraft:nether_wart_block)
B(11,10,13,minecraft:nether_wart_block)
B(12,10,13,minecraft:nether_wart_block)
B(13,10,13,minecraft:nether_wart_block)
B(14,10,13,minecraft:nether_wart_block)
B(15,10,13,minecraft:nether_wart_block)
B(11,10,14,minecraft:nether_wart_block)
B(12,10,14,minecraft:nether_wart_block)
B(13,10,14,minecraft:nether_wart_block)
B(14,10,14,minecraft:nether_wart_block)
B(15,10,14,minecraft:nether_wart_block)
B(11,10,15,minecraft:nether_wart_block)
B(12,10,15,minecraft:nether_wart_block)
B(13,10,15,minecraft:nether_wart_block)
B(14,10,15,minecraft:nether_wart_block)
B(15,10,15,minecraft:nether_wart_block)
B(11,11,0,minecraft:nether_wart_block)
B(12,11,0,minecraft:nether_wart_block)
B(13,11,0,minecraft:nether_wart_block)
B(14,11,0,minecraft:nether_wart_block)
B(15,11,0,minecraft:nether_wart_block)
B(11,11,1,minecraft:nether_wart_block)
B(12,11,1,minecraft:nether_wart_block)
B(13,11,1,minecraft:nether_wart_block)
B(14,11,1,minecraft:nether_wart_block)
B(15,11,1,minecraft:nether_wart_block)
B(11,11,2,minecraft:nether_wart_block)
B(12,11,2,minecraft:nether_wart_block)
B(13,11,2,minecraft:nether_wart_block)
B(14,11,2,minecraft:nether_wart_block)
B(15,11,2,minecraft:nether_wart_block)
B(11,11,3,minecraft:nether_wart_block)
B(12,11,3,minecraft:nether_wart_block)
B(13,11,3,minecraft:nether_wart_block)
B(14,11,3,minecraft:nether_wart_block)
B(15,11,3,minecraft:nether_wart_block)
B(12,11,4,minecraft:nether_wart_block)
B(13,11,4,minecraft:nether_wart_block)
B(14,11,4,minecraft:nether_wart_block)
B(15,11,4,minecraft:nether_wart_block)
B(12,11,5,minecraft:nether_wart_block)
B(13,11,5,minecraft:nether_wart_block)
B(14,11,5,minecraft:nether_wart_block)
B(15,11,5,minecraft:nether_wart_block)
B(12,11,6,minecraft:nether_wart_block)
B(13,11,6,minecraft:nether_wart_block)
B(14,11,6,minecraft:nether_wart_block)
B(15,11,6,minecraft:nether_wart_block)
B(12,11,7,minecraft:nether_wart_block)
B(13,11,7,minecraft:nether_wart_block)
B(14,11,7,minecraft:nether_wart_block)
B(15,11,7,minecraft:nether_wart_block)
B(12,11,8,minecraft:nether_wart_block)
B(13,11,8,minecraft:nether_wart_block)
B(14,11,8,minecraft:nether_wart_block)
B(15,11,8,minecraft:nether_wart_block)
B(13,11,9,minecraft:nether_wart_block)
B(14,11,9,minecraft:nether_wart_block)
B(15,11,9,minecraft:nether_wart_block)
B(13,11,10,minecraft:nether_wart_block)
B(14,11,10,minecraft:nether_wart_block)
B(15,11,10,minecraft:nether_wart_block)
B(12,11,11,minecraft:nether_wart_block)
B(13,11,11,minecraft:nether_wart_block)
B(14,11,11,minecraft:nether_wart_block)
B(15,11,11,minecraft:nether_wart_block)
B(11,11,12,minecraft:nether_wart_block)
B(12,11,12,minecraft:nether_wart_block)
B(13,11,12,minecraft:nether_wart_block)
B(14,11,12,minecraft:nether_wart_block)
B(15,11,12,minecraft:nether_wart_block)
B(11,11,13,minecraft:nether_wart_block)
B(12,11,13,minecraft:nether_wart_block)
B(13,11,13,minecraft:nether_wart_block)
B(14,11,13,minecraft:nether_wart_block)
B(15,11,13,minecraft:nether_wart_block)
B(11,11,14,minecraft:nether_wart_block)
B(12,11,14,minecraft:nether_wart_block)
B(13,11,14,minecraft:nether_wart_block)
B(14,11,14,minecraft:nether_wart_block)
B(15,11,14,minecraft:nether_wart_block)
B(11,11,15,minecraft:nether_wart_block)
B(12,11,15,minecraft:nether_wart_block)
B(13,11,15,minecraft:nether_wart_block)
B(14,11,15,minecraft:nether_wart_block)
B(15,11,15,minecraft:nether_wart_block)
B(11,12,0,minecraft:nether_wart_block)
B(12,12,0,minecraft:nether_wart_block)
B(13,12,0,minecraft:nether_wart_block)
B(14,12,0,minecraft:nether_wart_block)
B(15,12,0,minecraft:nether_wart_block)
B(11,12,1,minecraft:nether_wart_block)
B(12,12,1,minecraft:nether_wart_block)
B(13,12,1,minecraft:nether_wart_block)
B(14,12,1,minecraft:nether_wart_block)
B(15,12,1,minecraft:nether_wart_block)
B(11,12,2,minecraft:nether_wart_block)
B(12,12,2,minecraft:nether_wart_block)
B(13,12,2,minecraft:nether_wart_block)
B(14,12,2,minecraft:nether_wart_block)
B(15,12,2,minecraft:nether_wart_block)
B(11,12,3,minecraft:nether_wart_block)
B(12,12,3,minecraft:nether_wart_block)
B(13,12,3,minecraft:nether_wart_block)
B(14,12,3,minecraft:nether_wart_block)
B(15,12,3,minecraft:nether_wart_block)
B(12,12,4,minecraft:nether_wart_block)
B(13,12,4,minecraft:nether_wart_block)
B(14,12,4,minecraft:nether_wart_block)
B(15,12,4,minecraft:nether_wart_block)
B(12,12,5,minecraft:nether_wart_block)
B(13,12,5,minecraft:nether_wart_block)
B(14,12,5,minecraft:nether_wart_block)
B(15,12,5,minecraft:nether_wart_block)
B(12,12,6,minecraft:nether_wart_block)
B(13,12,6,minecraft:nether_wart_block)
B(14,12,6,minecraft:nether_wart_block)
B(15,12,6,minecraft:nether_wart_block)
B(12,12,7,minecraft:nether_wart_block)
B(13,12,7,minecraft:nether_wart_block)
B(14,12,7,minecraft:nether_wart_block)
B(15,12,7,minecraft:nether_wart_block)
B(13,12,8,minecraft:nether_wart_block)
B(14,12,8,minecraft:nether_wart_block)
B(15,12,8,minecraft:nether_wart_block)
B(13,12,9,minecraft:nether_wart_block)
B(14,12,9,minecraft:nether_wart_block)
B(15,12,9,minecraft:nether_wart_block)
B(13,12,10,minecraft:nether_wart_block)
B(14,12,10,minecraft:nether_wart_block)
B(15,12,10,minecraft:nether_wart_block)
B(12,12,11,minecraft:nether_wart_block)
B(13,12,11,minecraft:nether_wart_block)
B(14,12,11,minecraft:nether_wart_block)
B(15,12,11,minecraft:nether_wart_block)
B(12,12,12,minecraft:nether_wart_block)
B(13,12,12,minecraft:nether_wart_block)
B(14,12,12,minecraft:nether_wart_block)
B(15,12,12,minecraft:nether_wart_block)
B(11,12,13,minecraft:nether_wart_block)
B(12,12,13,minecraft:nether_wart_block)
B(13,12,13,minecraft:nether_wart_block)
B(14,12,13,minecraft:nether_wart_block)
B(15,12,13,minecraft:nether_wart_block)
B(11,12,14,minecraft:nether_wart_block)
B(12,12,14,minecraft:nether_wart_block)
B(13,12,14,minecraft:nether_wart_block)
B(14,12,14,minecraft:nether_wart_block)
B(15,12,14,minecraft:nether_wart_block)
B(11,12,15,minecraft:nether_wart_block)
B(12,12,15,minecraft:nether_wart_block)
B(13,12,15,minecraft:nether_wart_block)
B(14,12,15,minecraft:nether_wart_block)
B(15,12,15,minecraft:nether_wart_block)
B(12,13,0,minecraft:nether_wart_block)
B(13,13,0,minecraft:nether_wart_block)
B(14,13,0,minecraft:nether_wart_block)
B(15,13,0,minecraft:nether_wart_block)
B(11,13,1,minecraft:nether_wart_block)
B(12,13,1,minecraft:nether_wart_block)
B(13,13,1,minecraft:nether_wart_block)
B(14,13,1,minecraft:nether_wart_block)
B(15,13,1,minecraft:nether_wart_block)
B(11,13,2,minecraft:nether_wart_block)
B(12,13,2,minecraft:nether_wart_block)
B(13,13,2,minecraft:nether_wart_block)
B(14,13,2,minecraft:nether_wart_block)
B(15,13,2,minecraft:nether_wart_block)
B(12,13,3,minecraft:nether_wart_block)
B(13,13,3,minecraft:nether_wart_block)
B(14,13,3,minecraft:nether_wart_block)
B(15,13,3,minecraft:nether_wart_block)
B(12,13,4,minecraft:nether_wart_block)
B(13,13,4,minecraft:nether_wart_block)
B(14,13,4,minecraft:nether_wart_block)
B(15,13,4,minecraft:nether_wart_block)
B(13,13,5,minecraft:nether_wart_block)
B(14,13,5,minecraft:nether_wart_block)
B(15,13,5,minecraft:nether_wart_block)
B(12,13,6,minecraft:nether_wart_block)
B(13,13,6,minecraft:nether_wart_block)
B(14,13,6,minecraft:nether_wart_block)
B(15,13,6,minecraft:nether_wart_block)
B(12,13,7,minecraft:nether_wart_block)
B(13,13,7,minecraft:nether_wart_block)
B(14,13,7,minecraft:nether_wart_block)
B(15,13,7,minecraft:nether_wart_block)
B(13,13,8,minecraft:nether_wart_block)
B(14,13,8,minecraft:nether_wart_block)
B(15,13,8,minecraft:nether_wart_block)
B(13,13,9,minecraft:nether_wart_block)
B(14,13,9,minecraft:nether_wart_block)
B(15,13,9,minecraft:nether_wart_block)
B(13,13,10,minecraft:nether_wart_block)
B(14,13,10,minecraft:nether_wart_block)
B(15,13,10,minecraft:nether_wart_block)
B(12,13,11,minecraft:nether_wart_block)
B(13,13,11,minecraft:nether_wart_block)
B(14,13,11,minecraft:nether_wart_block)
B(15,13,11,minecraft:nether_wart_block)
B(12,13,12,minecraft:nether_wart_block)
B(13,13,12,minecraft:nether_wart_block)
B(14,13,12,minecraft:nether_wart_block)
B(15,13,12,minecraft:nether_wart_block)
B(11,13,13,minecraft:nether_wart_block)
B(12,13,13,minecraft:nether_wart_block)
B(13,13,13,minecraft:nether_wart_block)
B(14,13,13,minecraft:nether_wart_block)
B(15,13,13,minecraft:nether_wart_block)
B(11,13,14,minecraft:nether_wart_block)
B(12,13,14,minecraft:nether_wart_block)
B(13,13,14,minecraft:nether_wart_block)
B(14,13,14,minecraft:nether_wart_block)
B(15,13,14,minecraft:nether_wart_block)
B(11,13,15,minecraft:nether_wart_block)
B(12,13,15,minecraft:nether_wart_block)
B(13,13,15,minecraft:nether_wart_block)
B(14,13,15,minecraft:nether_wart_block)
B(15,13,15,minecraft:nether_wart_block)
B(12,14,0,minecraft:nether_wart_block)
B(13,14,0,minecraft:nether_wart_block)
B(14,14,0,minecraft:nether_wart_block)
B(15,14,0,minecraft:nether_wart_block)
B(12,14,1,minecraft:nether_wart_block)
B(13,14,1,minecraft:nether_wart_block)
B(14,14,1,minecraft:nether_wart_block)
B(15,14,1,minecraft:nether_wart_block)
B(12,14,2,minecraft:nether_wart_block)
B(13,14,2,minecraft:nether_wart_block)
B(14,14,2,minecraft:nether_wart_block)
B(15,14,2,minecraft:nether_wart_block)
B(12,14,3,minecraft:nether_wart_block)
B(13,14,3,minecraft:nether_wart_block)
B(14,14,3,minecraft:nether_wart_block)
B(15,14,3,minecraft:nether_wart_block)
B(13,14,4,minecraft:nether_wart_block)
B(14,14,4,minecraft:nether_wart_block)
B(15,14,4,minecraft:nether_wart_block)
B(13,14,5,minecraft:nether_wart_block)
B(14,14,5,minecraft:nether_wart_block)
B(15,14,5,minecraft:nether_wart_block)
B(13,14,6,minecraft:nether_wart_block)
B(14,14,6,minecraft:nether_wart_block)
B(15,14,6,minecraft:nether_wart_block)
B(13,14,7,minecraft:nether_wart_block)
B(14,14,7,minecraft:nether_wart_block)
B(15,14,7,minecraft:nether_wart_block)
B(13,14,8,minecraft:nether_wart_block)
B(14,14,8,minecraft:nether_wart_block)
B(15,14,8,minecraft:nether_wart_block)
B(13,14,9,minecraft:nether_wart_block)
B(14,14,9,minecraft:nether_wart_block)
B(15,14,9,minecraft:nether_wart_block)
B(14,14,10,minecraft:nether_wart_block)
B(15,14,10,minecraft:nether_wart_block)
B(13,14,11,minecraft:nether_wart_block)
B(14,14,11,minecraft:nether_wart_block)
B(15,14,11,minecraft:nether_wart_block)
B(12,14,12,minecraft:nether_wart_block)
B(13,14,12,minecraft:nether_wart_block)
B(14,14,12,minecraft:nether_wart_block)
B(15,14,12,minecraft:nether_wart_block)
B(11,14,13,minecraft:nether_wart_block)
B(12,14,13,minecraft:nether_wart_block)
B(13,14,13,minecraft:nether_wart_block)
B(14,14,13,minecraft:nether_wart_block)
B(15,14,13,minecraft:nether_wart_block)
B(11,14,14,minecraft:nether_wart_block)
B(12,14,14,minecraft:nether_wart_block)
B(13,14,14,minecraft:nether_wart_block)
B(14,14,14,minecraft:nether_wart_block)
B(15,14,14,minecraft:nether_wart_block)
B(11,14,15,minecraft:nether_wart_block)
B(12,14,15,minecraft:nether_wart_block)
B(13,14,15,minecraft:nether_wart_block)
B(14,14,15,minecraft:nether_wart_block)
B(15,14,15,minecraft:nether_wart_block)
B(12,15,0,minecraft:nether_wart_block)
B(13,15,0,minecraft:nether_wart_block)
B(14,15,0,minecraft:nether_wart_block)
B(15,15,0,minecraft:nether_wart_block)
B(12,15,1,minecraft:nether_wart_block)
B(13,15,1,minecraft:nether_wart_block)
B(14,15,1,minecraft:nether_wart_block)
B(15,15,1,minecraft:nether_wart_block)
B(12,15,2,minecraft:nether_wart_block)
B(13,15,2,minecraft:nether_wart_block)
B(14,15,2,minecraft:nether_wart_block)
B(15,15,2,minecraft:nether_wart_block)
B(13,15,3,minecraft:nether_wart_block)
B(14,15,3,minecraft:nether_wart_block)
B(15,15,3,minecraft:nether_wart_block)
B(13,15,4,minecraft:nether_wart_block)
B(14,15,4,minecraft:nether_wart_block)
B(15,15,4,minecraft:nether_wart_block)
B(13,15,5,minecraft:nether_wart_block)
B(14,15,5,minecraft:nether_wart_block)
B(15,15,5,minecraft:nether_wart_block)
B(13,15,6,minecraft:nether_wart_block)
B(14,15,6,minecraft:nether_wart_block)
B(15,15,6,minecraft:nether_wart_block)
B(13,15,7,minecraft:nether_wart_block)
B(14,15,7,minecraft:nether_wart_block)
B(15,15,7,minecraft:nether_wart_block)
B(13,15,8,minecraft:nether_wart_block)
B(14,15,8,minecraft:nether_wart_block)
B(15,15,8,minecraft:nether_wart_block)
B(13,15,9,minecraft:nether_wart_block)
B(14,15,9,minecraft:nether_wart_block)
B(15,15,9,minecraft:nether_wart_block)
B(14,15,10,minecraft:nether_wart_block)
B(15,15,10,minecraft:nether_wart_block)
B(13,15,11,minecraft:nether_wart_block)
B(14,15,11,minecraft:nether_wart_block)
B(15,15,11,minecraft:nether_wart_block)
B(12,15,12,minecraft:nether_wart_block)
B(13,15,12,minecraft:nether_wart_block)
B(14,15,12,minecraft:nether_wart_block)
B(15,15,12,minecraft:nether_wart_block)
B(11,15,13,minecraft:nether_wart_block)
B(12,15,13,minecraft:nether_wart_block)
B(13,15,13,minecraft:nether_wart_block)
B(14,15,13,minecraft:nether_wart_block)
B(15,15,13,minecraft:nether_wart_block)
B(11,15,14,minecraft:nether_wart_block)
B(12,15,14,minecraft:nether_wart_block)
B(13,15,14,minecraft:nether_wart_block)
B(14,15,14,minecraft:nether_wart_block)
B(15,15,14,minecraft:nether_wart_block)
B(11,15,15,minecraft:nether_wart_block)
B(12,15,15,minecraft:nether_wart_block)
B(13,15,15,minecraft:nether_wart_block)
B(14,15,15,minecraft:nether_wart_block)
B(15,15,15,minecraft:nether_wart_block)
B(12,16,0,minecraft:nether_wart_block)
B(13,16,0,minecraft:nether_wart_block)
B(14,16,0,minecraft:nether_wart_block)
B(15,16,0,minecraft:nether_wart_block)
B(12,16,1,minecraft:nether_wart_block)
B(13,16,1,minecraft:nether_wart_block)
B(14,16,1,minecraft:nether_wart_block)
B(15,16,1,minecraft:nether_wart_block)
B(12,16,2,minecraft:nether_wart_block)
B(13,16,2,minecraft:nether_wart_block)
B(14,16,2,minecraft:nether_wart_block)
B(15,16,2,minecraft:nether_wart_block)
B(13,16,3,minecraft:nether_wart_block)
B(14,16,3,minecraft:nether_wart_block)
B(15,16,3,minecraft:nether_wart_block)
B(13,16,4,minecraft:nether_wart_block)
B(14,16,4,minecraft:nether_wart_block)
B(15,16,4,minecraft:nether_wart_block)
B(13,16,5,minecraft:nether_wart_block)
B(14,16,5,minecraft:nether_wart_block)
B(15,16,5,minecraft:nether_wart_block)
B(13,16,6,minecraft:nether_wart_block)
B(14,16,6,minecraft:nether_wart_block)
B(15,16,6,minecraft:nether_wart_block)
B(13,16,7,minecraft:nether_wart_block)
B(14,16,7,minecraft:nether_wart_block)
B(15,16,7,minecraft:nether_wart_block)
B(13,16,8,minecraft:nether_wart_block)
B(14,16,8,minecraft:nether_wart_block)
B(15,16,8,minecraft:nether_wart_block)
B(13,16,9,minecraft:nether_wart_block)
B(14,16,9,minecraft:nether_wart_block)
B(15,16,9,minecraft:nether_wart_block)
B(14,16,10,minecraft:nether_wart_block)
B(15,16,10,minecraft:nether_wart_block)
B(13,16,11,minecraft:nether_wart_block)
B(14,16,11,minecraft:nether_wart_block)
B(15,16,11,minecraft:nether_wart_block)
B(12,16,12,minecraft:nether_wart_block)
B(13,16,12,minecraft:nether_wart_block)
B(14,16,12,minecraft:nether_wart_block)
B(15,16,12,minecraft:nether_wart_block)
B(11,16,13,minecraft:nether_wart_block)
B(12,16,13,minecraft:nether_wart_block)
B(13,16,13,minecraft:nether_wart_block)
B(14,16,13,minecraft:nether_wart_block)
B(15,16,13,minecraft:nether_wart_block)
B(11,16,14,minecraft:nether_wart_block)
B(12,16,14,minecraft:nether_wart_block)
B(13,16,14,minecraft:nether_wart_block)
B(14,16,14,minecraft:nether_wart_block)
B(15,16,14,minecraft:nether_wart_block)
B(11,16,15,minecraft:nether_wart_block)
B(12,16,15,minecraft:nether_wart_block)
B(13,16,15,minecraft:nether_wart_block)
B(14,16,15,minecraft:nether_wart_block)
B(15,16,15,minecraft:nether_wart_block)
B(12,17,0,minecraft:nether_wart_block)
B(13,17,0,minecraft:nether_wart_block)
B(14,17,0,minecraft:nether_wart_block)
B(15,17,0,minecraft:nether_wart_block)
B(12,17,1,minecraft:nether_wart_block)
B(13,17,1,minecraft:nether_wart_block)
B(14,17,1,minecraft:nether_wart_block)
B(15,17,1,minecraft:nether_wart_block)
B(12,17,2,minecraft:nether_wart_block)
B(13,17,2,minecraft:nether_wart_block)
B(14,17,2,minecraft:nether_wart_block)
B(15,17,2,minecraft:nether_wart_block)
B(13,17,3,minecraft:nether_wart_block)
B(14,17,3,minecraft:nether_wart_block)
B(15,17,3,minecraft:nether_wart_block)
B(13,17,4,minecraft:nether_wart_block)
B(14,17,4,minecraft:nether_wart_block)
B(15,17,4,minecraft:nether_wart_block)
B(13,17,5,minecraft:nether_wart_block)
B(14,17,5,minecraft:nether_wart_block)
B(15,17,5,minecraft:nether_wart_block)
B(13,17,6,minecraft:nether_wart_block)
B(14,17,6,minecraft:nether_wart_block)
B(15,17,6,minecraft:nether_wart_block)
B(13,17,7,minecraft:nether_wart_block)
B(14,17,7,minecraft:nether_wart_block)
B(15,17,7,minecraft:nether_wart_block)
B(13,17,8,minecraft:nether_wart_block)
B(14,17,8,minecraft:nether_wart_block)
B(15,17,8,minecraft:nether_wart_block)
B(13,17,9,minecraft:nether_wart_block)
B(14,17,9,minecraft:nether_wart_block)
B(15,17,9,minecraft:nether_wart_block)
B(14,17,10,minecraft:nether_wart_block)
B(15,17,10,minecraft:nether_wart_block)
B(13,17,11,minecraft:nether_wart_block)
B(14,17,11,minecraft:nether_wart_block)
B(15,17,11,minecraft:nether_wart_block)
B(12,17,12,minecraft:nether_wart_block)
B(13,17,12,minecraft:nether_wart_block)
B(14,17,12,minecraft:nether_wart_block)
B(15,17,12,minecraft:nether_wart_block)
B(11,17,13,minecraft:nether_wart_block)
B(12,17,13,minecraft:nether_wart_block)
B(13,17,13,minecraft:nether_wart_block)
B(14,17,13,minecraft:nether_wart_block)
B(15,17,13,minecraft:nether_wart_block)
B(11,17,14,minecraft:nether_wart_block)
B(12,17,14,minecraft:nether_wart_block)
B(13,17,14,minecraft:nether_wart_block)
B(14,17,14,minecraft:nether_wart_block)
B(15,17,14,minecraft:nether_wart_block)
B(11,17,15,minecraft:nether_wart_block)
B(12,17,15,minecraft:nether_wart_block)
B(13,17,15,minecraft:nether_wart_block)
B(14,17,15,minecraft:nether_wart_block)
B(15,17,15,minecraft:nether_wart_block)
B(12,18,0,minecraft:nether_wart_block)
B(13,18,0,minecraft:nether_wart_block)
B(14,18,0,minecraft:nether_wart_block)
B(15,18,0,minecraft:nether_wart_block)
B(12,18,1,minecraft:nether_wart_block)
B(13,18,1,minecraft:nether_wart_block)
B(14,18,1,minecraft:nether_wart_block)
B(15,18,1,minecraft:nether_wart_block)
B(13,18,2,minecraft:nether_wart_block)
B(14,18,2,minecraft:nether_wart_block)
B(15,18,2,minecraft:nether_wart_block)
B(13,18,3,minecraft:nether_wart_block)
B(14,18,3,minecraft:nether_wart_block)
B(15,18,3,minecraft:nether_wart_block)
B(13,18,4,minecraft:nether_wart_block)
B(14,18,4,minecraft:nether_wart_block)
B(15,18,4,minecraft:nether_wart_block)
B(13,18,5,minecraft:nether_wart_block)
B(14,18,5,minecraft:nether_wart_block)
B(15,18,5,minecraft:nether_wart_block)
B(13,18,6,minecraft:nether_wart_block)
B(14,18,6,minecraft:nether_wart_block)
B(15,18,6,minecraft:nether_wart_block)
B(13,18,7,minecraft:nether_wart_block)
B(14,18,7,minecraft:nether_wart_block)
B(15,18,7,minecraft:nether_wart_block)
B(13,18,8,minecraft:nether_wart_block)
B(14,18,8,minecraft:nether_wart_block)
B(15,18,8,minecraft:nether_wart_block)
B(13,18,9,minecraft:nether_wart_block)
B(14,18,9,minecraft:nether_wart_block)
B(15,18,9,minecraft:nether_wart_block)
B(14,18,10,minecraft:nether_wart_block)
B(15,18,10,minecraft:nether_wart_block)
B(14,18,11,minecraft:nether_wart_block)
B(15,18,11,minecraft:nether_wart_block)
B(12,18,12,minecraft:nether_wart_block)
B(13,18,12,minecraft:nether_wart_block)
B(14,18,12,minecraft:nether_wart_block)
B(15,18,12,minecraft:nether_wart_block)
B(12,18,13,minecraft:nether_wart_block)
B(13,18,13,minecraft:nether_wart_block)
B(14,18,13,minecraft:nether_wart_block)
B(15,18,13,minecraft:nether_wart_block)
B(11,18,14,minecraft:nether_wart_block)
B(12,18,14,minecraft:nether_wart_block)
B(13,18,14,minecraft:nether_wart_block)
B(14,18,14,minecraft:nether_wart_block)
B(15,18,14,minecraft:nether_wart_block)
B(12,18,15,minecraft:nether_wart_block)
B(13,18,15,minecraft:nether_wart_block)
B(14,18,15,minecraft:nether_wart_block)
B(15,18,15,minecraft:nether_wart_block)
B(13,19,0,minecraft:nether_wart_block)
B(14,19,0,minecraft:nether_wart_block)
B(15,19,0,minecraft:nether_wart_block)
B(13,19,1,minecraft:nether_wart_block)
B(14,19,1,minecraft:nether_wart_block)
B(15,19,1,minecraft:nether_wart_block)
B(13,19,2,minecraft:nether_wart_block)
B(14,19,2,minecraft:nether_wart_block)
B(15,19,2,minecraft:nether_wart_block)
B(13,19,3,minecraft:nether_wart_block)
B(14,19,3,minecraft:nether_wart_block)
B(15,19,3,minecraft:nether_wart_block)
B(13,19,4,minecraft:nether_wart_block)
B(14,19,4,minecraft:nether_wart_block)
B(15,19,4,minecraft:nether_wart_block)
B(13,19,5,minecraft:nether_wart_block)
B(14,19,5,minecraft:nether_wart_block)
B(15,19,5,minecraft:nether_wart_block)
B(13,19,6,minecraft:nether_wart_block)
B(14,19,6,minecraft:nether_wart_block)
B(15,19,6,minecraft:nether_wart_block)
B(13,19,7,minecraft:nether_wart_block)
B(14,19,7,minecraft:nether_wart_block)
B(15,19,7,minecraft:nether_wart_block)
B(13,19,8,minecraft:nether_wart_block)
B(14,19,8,minecraft:nether_wart_block)
B(15,19,8,minecraft:nether_wart_block)
B(13,19,9,minecraft:nether_wart_block)
B(14,19,9,minecraft:nether_wart_block)
B(15,19,9,minecraft:nether_wart_block)
B(14,19,10,minecraft:nether_wart_block)
B(15,19,10,minecraft:nether_wart_block)
B(14,19,11,minecraft:nether_wart_block)
B(15,19,11,minecraft:nether_wart_block)
B(13,19,12,minecraft:nether_wart_block)
B(14,19,12,minecraft:nether_wart_block)
B(15,19,12,minecraft:nether_wart_block)
B(12,19,13,minecraft:nether_wart_block)
B(13,19,13,minecraft:nether_wart_block)
B(14,19,13,minecraft:nether_wart_block)
B(15,19,13,minecraft:nether_wart_block)
B(11,19,14,minecraft:nether_wart_block)
B(12,19,14,minecraft:nether_wart_block)
B(13,19,14,minecraft:nether_wart_block)
B(14,19,14,minecraft:nether_wart_block)
B(15,19,14,minecraft:nether_wart_block)
B(12,19,15,minecraft:nether_wart_block)
B(13,19,15,minecraft:nether_wart_block)
B(14,19,15,minecraft:nether_wart_block)
B(15,19,15,minecraft:nether_wart_block)
B(13,20,0,minecraft:nether_wart_block)
B(14,20,0,minecraft:nether_wart_block)
B(15,20,0,minecraft:nether_wart_block)
B(13,20,1,minecraft:nether_wart_block)
B(14,20,1,minecraft:nether_wart_block)
B(15,20,1,minecraft:nether_wart_block)
B(13,20,2,minecraft:nether_wart_block)
B(14,20,2,minecraft:nether_wart_block)
B(15,20,2,minecraft:nether_wart_block)
B(13,20,3,minecraft:nether_wart_block)
B(14,20,3,minecraft:nether_wart_block)
B(15,20,3,minecraft:nether_wart_block)
B(13,20,4,minecraft:nether_wart_block)
B(14,20,4,minecraft:nether_wart_block)
B(15,20,4,minecraft:nether_wart_block)
B(13,20,5,minecraft:nether_wart_block)
B(14,20,5,minecraft:nether_wart_block)
B(15,20,5,minecraft:nether_wart_block)
B(13,20,6,minecraft:nether_wart_block)
B(14,20,6,minecraft:nether_wart_block)
B(15,20,6,minecraft:nether_wart_block)
B(13,20,7,minecraft:nether_wart_block)
B(14,20,7,minecraft:nether_wart_block)
B(15,20,7,minecraft:nether_wart_block)
B(13,20,8,minecraft:nether_wart_block)
B(14,20,8,minecraft:nether_wart_block)
B(15,20,8,minecraft:nether_wart_block)
B(13,20,9,minecraft:nether_wart_block)
B(14,20,9,minecraft:nether_wart_block)
B(15,20,9,minecraft:nether_wart_block)
B(14,20,10,minecraft:nether_wart_block)
B(15,20,10,minecraft:nether_wart_block)
B(14,20,11,minecraft:nether_wart_block)
B(15,20,11,minecraft:nether_wart_block)
B(13,20,12,minecraft:nether_wart_block)
B(14,20,12,minecraft:nether_wart_block)
B(15,20,12,minecraft:nether_wart_block)
B(12,20,13,minecraft:nether_wart_block)
B(13,20,13,minecraft:nether_wart_block)
B(14,20,13,minecraft:nether_wart_block)
B(15,20,13,minecraft:nether_wart_block)
B(12,20,14,minecraft:nether_wart_block)
B(13,20,14,minecraft:nether_wart_block)
B(14,20,14,minecraft:nether_wart_block)
B(15,20,14,minecraft:nether_wart_block)
B(12,20,15,minecraft:nether_wart_block)
B(13,20,15,minecraft:nether_wart_block)
B(14,20,15,minecraft:nether_wart_block)
B(15,20,15,minecraft:nether_wart_block)
B(13,21,0,minecraft:nether_wart_block)
B(14,21,0,minecraft:nether_wart_block)
B(15,21,0,minecraft:nether_wart_block)
B(13,21,1,minecraft:nether_wart_block)
B(14,21,1,minecraft:nether_wart_block)
B(15,21,1,minecraft:nether_wart_block)
B(13,21,2,minecraft:nether_wart_block)
B(14,21,2,minecraft:nether_wart_block)
B(15,21,2,minecraft:nether_wart_block)
B(13,21,3,minecraft:nether_wart_block)
B(14,21,3,minecraft:nether_wart_block)
B(15,21,3,minecraft:nether_wart_block)
B(14,21,4,minecraft:nether_wart_block)
B(15,21,4,minecraft:nether_wart_block)
B(13,21,5,minecraft:nether_wart_block)
B(14,21,5,minecraft:nether_wart_block)
B(15,21,5,minecraft:nether_wart_block)
B(13,21,6,minecraft:nether_wart_block)
B(14,21,6,minecraft:nether_wart_block)
B(15,21,6,minecraft:nether_wart_block)
B(13,21,7,minecraft:nether_wart_block)
B(14,21,7,minecraft:nether_wart_block)
B(15,21,7,minecraft:nether_wart_block)
B(13,21,8,minecraft:nether_wart_block)
B(14,21,8,minecraft:nether_wart_block)
B(15,21,8,minecraft:nether_wart_block)
B(13,21,9,minecraft:nether_wart_block)
B(14,21,9,minecraft:nether_wart_block)
B(15,21,9,minecraft:nether_wart_block)
B(14,21,10,minecraft:nether_wart_block)
B(15,21,10,minecraft:nether_wart_block)
B(14,21,11,minecraft:nether_wart_block)
B(15,21,11,minecraft:nether_wart_block)
B(13,21,12,minecraft:nether_wart_block)
B(14,21,12,minecraft:nether_wart_block)
B(15,21,12,minecraft:nether_wart_block)
B(13,21,13,minecraft:nether_wart_block)
B(14,21,13,minecraft:nether_wart_block)
B(15,21,13,minecraft:nether_wart_block)
B(12,21,14,minecraft:nether_wart_block)
B(13,21,14,minecraft:nether_wart_block)
B(14,21,14,minecraft:nether_wart_block)
B(15,21,14,minecraft:nether_wart_block)
B(12,21,15,minecraft:nether_wart_block)
B(13,21,15,minecraft:nether_wart_block)
B(14,21,15,minecraft:nether_wart_block)
B(15,21,15,minecraft:nether_wart_block)
B(13,22,0,minecraft:nether_wart_block)
B(14,22,0,minecraft:nether_wart_block)
B(15,22,0,minecraft:nether_wart_block)
B(13,22,1,minecraft:nether_wart_block)
B(14,22,1,minecraft:nether_wart_block)
B(15,22,1,minecraft:nether_wart_block)
B(13,22,2,minecraft:nether_wart_block)
B(14,22,2,minecraft:nether_wart_block)
B(15,22,2,minecraft:nether_wart_block)
B(13,22,3,minecraft:nether_wart_block)
B(14,22,3,minecraft:nether_wart_block)
B(15,22,3,minecraft:nether_wart_block)
B(14,22,4,minecraft:nether_wart_block)
B(15,22,4,minecraft:nether_wart_block)
B(13,22,5,minecraft:nether_wart_block)
B(14,22,5,minecraft:nether_wart_block)
B(15,22,5,minecraft:nether_wart_block)
B(13,22,6,minecraft:nether_wart_block)
B(14,22,6,minecraft:nether_wart_block)
B(15,22,6,minecraft:nether_wart_block)
B(13,22,7,minecraft:nether_wart_block)
B(14,22,7,minecraft:nether_wart_block)
B(15,22,7,minecraft:nether_wart_block)
B(13,22,8,minecraft:nether_wart_block)
B(14,22,8,minecraft:nether_wart_block)
B(15,22,8,minecraft:nether_wart_block)
B(13,22,9,minecraft:nether_wart_block)
B(14,22,9,minecraft:nether_wart_block)
B(15,22,9,minecraft:nether_wart_block)
B(14,22,10,minecraft:nether_wart_block)
B(15,22,10,minecraft:nether_wart_block)
B(14,22,11,minecraft:nether_wart_block)
B(15,22,11,minecraft:nether_wart_block)
B(14,22,12,minecraft:nether_wart_block)
B(15,22,12,minecraft:nether_wart_block)
B(13,22,13,minecraft:nether_wart_block)
B(14,22,13,minecraft:nether_wart_block)
B(15,22,13,minecraft:nether_wart_block)
B(12,22,14,minecraft:nether_wart_block)
B(13,22,14,minecraft:nether_wart_block)
B(14,22,14,minecraft:nether_wart_block)
B(15,22,14,minecraft:nether_wart_block)
B(12,22,15,minecraft:nether_wart_block)
B(13,22,15,minecraft:nether_wart_block)
B(14,22,15,minecraft:nether_wart_block)
B(15,22,15,minecraft:nether_wart_block)
B(13,23,0,minecraft:nether_wart_block)
B(14,23,0,minecraft:nether_wart_block)
B(15,23,0,minecraft:nether_wart_block)
B(13,23,1,minecraft:nether_wart_block)
B(14,23,1,minecraft:nether_wart_block)
B(15,23,1,minecraft:nether_wart_block)
B(13,23,2,minecraft:nether_wart_block)
B(14,23,2,minecraft:nether_wart_block)
B(15,23,2,minecraft:nether_wart_block)
B(13,23,3,minecraft:nether_wart_block)
B(14,23,3,minecraft:nether_wart_block)
B(15,23,3,minecraft:nether_wart_block)
B(14,23,4,minecraft:nether_wart_block)
B(15,23,4,minecraft:nether_wart_block)
B(13,23,5,minecraft:nether_wart_block)
B(14,23,5,minecraft:nether_wart_block)
B(15,23,5,minecraft:nether_wart_block)
B(13,23,6,minecraft:nether_wart_block)
B(14,23,6,minecraft:nether_wart_block)
B(15,23,6,minecraft:nether_wart_block)
B(13,23,7,minecraft:nether_wart_block)
B(14,23,7,minecraft:nether_wart_block)
B(15,23,7,minecraft:nether_wart_block)
B(13,23,8,minecraft:nether_wart_block)
B(14,23,8,minecraft:nether_wart_block)
B(15,23,8,minecraft:nether_wart_block)
B(14,23,9,minecraft:nether_wart_block)
B(15,23,9,minecraft:nether_wart_block)
B(14,23,10,minecraft:nether_wart_block)
B(15,23,10,minecraft:nether_wart_block)
B(14,23,11,minecraft:nether_wart_block)
B(15,23,11,minecraft:nether_wart_block)
B(14,23,12,minecraft:nether_wart_block)
B(15,23,12,minecraft:nether_wart_block)
B(13,23,13,minecraft:nether_wart_block)
B(14,23,13,minecraft:nether_wart_block)
B(15,23,13,minecraft:nether_wart_block)
B(13,23,14,minecraft:nether_wart_block)
B(14,23,14,minecraft:nether_wart_block)
B(15,23,14,minecraft:nether_wart_block)
B(12,23,15,minecraft:nether_wart_block)
B(13,23,15,minecraft:nether_wart_block)
B(14,23,15,minecraft:nether_wart_block)
B(15,23,15,minecraft:nether_wart_block)
B(13,24,0,minecraft:nether_wart_block)
B(14,24,0,minecraft:nether_wart_block)
B(15,24,0,minecraft:nether_wart_block)
B(13,24,1,minecraft:nether_wart_block)
B(14,24,1,minecraft:nether_wart_block)
B(15,24,1,minecraft:nether_wart_block)
B(13,24,2,minecraft:nether_wart_block)
B(14,24,2,minecraft:nether_wart_block)
B(15,24,2,minecraft:nether_wart_block)
B(13,24,3,minecraft:nether_wart_block)
B(14,24,3,minecraft:nether_wart_block)
B(15,24,3,minecraft:nether_wart_block)
B(14,24,4,minecraft:nether_wart_block)
B(15,24,4,minecraft:nether_wart_block)
B(14,24,5,minecraft:nether_wart_block)
B(15,24,5,minecraft:nether_wart_block)
B(13,24,6,minecraft:nether_wart_block)
B(14,24,6,minecraft:nether_wart_block)
B(15,24,6,minecraft:nether_wart_block)
B(13,24,7,minecraft:nether_wart_block)
B(14,24,7,minecraft:nether_wart_block)
B(15,24,7,minecraft:nether_wart_block)
B(13,24,8,minecraft:nether_wart_block)
B(14,24,8,minecraft:nether_wart_block)
B(15,24,8,minecraft:nether_wart_block)
B(14,24,9,minecraft:nether_wart_block)
B(15,24,9,minecraft:nether_wart_block)
B(14,24,10,minecraft:nether_wart_block)
B(15,24,10,minecraft:nether_wart_block)
B(14,24,11,minecraft:nether_wart_block)
B(15,24,11,minecraft:nether_wart_block)
B(14,24,12,minecraft:nether_wart_block)
B(15,24,12,minecraft:nether_wart_block)
B(14,24,13,minecraft:nether_wart_block)
B(15,24,13,minecraft:nether_wart_block)
B(13,24,14,minecraft:nether_wart_block)
B(14,24,14,minecraft:nether_wart_block)
B(15,24,14,minecraft:nether_wart_block)
B(12,24,15,minecraft:nether_wart_block)
B(13,24,15,minecraft:nether_wart_block)
B(14,24,15,minecraft:nether_wart_block)
B(15,24,15,minecraft:nether_wart_block)
B(14,25,0,minecraft:nether_wart_block)
B(15,25,0,minecraft:nether_wart_block)
B(13,25,1,minecraft:nether_wart_block)
B(14,25,1,minecraft:nether_wart_block)
B(15,25,1,minecraft:nether_wart_block)
B(13,25,2,minecraft:nether_wart_block)
B(14,25,2,minecraft:nether_wart_block)
B(15,25,2,minecraft:nether_wart_block)
B(13,25,3,minecraft:nether_wart_block)
B(14,25,3,minecraft:nether_wart_block)
B(15,25,3,minecraft:nether_wart_block)
B(14,25,4,minecraft:nether_wart_block)
B(15,25,4,minecraft:nether_wart_block)
B(14,25,5,minecraft:nether_wart_block)
B(15,25,5,minecraft:nether_wart_block)
B(13,25,6,minecraft:nether_wart_block)
B(14,25,6,minecraft:nether_wart_block)
B(15,25,6,minecraft:nether_wart_block)
B(13,25,7,minecraft:nether_wart_block)
B(14,25,7,minecraft:nether_wart_block)
B(15,25,7,minecraft:nether_wart_block)
B(13,25,8,minecraft:nether_wart_block)
B(14,25,8,minecraft:nether_wart_block)
B(15,25,8,minecraft:nether_wart_block)
B(14,25,9,minecraft:nether_wart_block)
B(15,25,9,minecraft:nether_wart_block)
B(14,25,10,minecraft:nether_wart_block)
B(15,25,10,minecraft:nether_wart_block)
B(14,25,11,minecraft:nether_wart_block)
B(15,25,11,minecraft:nether_wart_block)
B(14,25,12,minecraft:nether_wart_block)
B(15,25,12,minecraft:nether_wart_block)
B(14,25,13,minecraft:nether_wart_block)
B(15,25,13,minecraft:nether_wart_block)
B(13,25,14,minecraft:nether_wart_block)
B(14,25,14,minecraft:nether_wart_block)
B(15,25,14,minecraft:nether_wart_block)
B(12,25,15,minecraft:nether_wart_block)
B(13,25,15,minecraft:nether_wart_block)
B(14,25,15,minecraft:nether_wart_block)
B(15,25,15,minecraft:nether_wart_block)
B(14,26,0,minecraft:nether_wart_block)
B(15,26,0,minecraft:nether_wart_block)
B(13,26,1,minecraft:nether_wart_block)
B(14,26,1,minecraft:nether_wart_block)
B(15,26,1,minecraft:nether_wart_block)
B(13,26,2,minecraft:nether_wart_block)
B(14,26,2,minecraft:nether_wart_block)
B(15,26,2,minecraft:nether_wart_block)
B(13,26,3,minecraft:nether_wart_block)
B(14,26,3,minecraft:nether_wart_block)
B(15,26,3,minecraft:nether_wart_block)
B(14,26,4,minecraft:nether_wart_block)
B(15,26,4,minecraft:nether_wart_block)
B(14,26,5,minecraft:nether_wart_block)
B(15,26,5,minecraft:nether_wart_block)
B(13,26,6,minecraft:nether_wart_block)
B(14,26,6,minecraft:nether_wart_block)
B(15,26,6,minecraft:nether_wart_block)
B(13,26,7,minecraft:nether_wart_block)
B(14,26,7,minecraft:nether_wart_block)
B(15,26,7,minecraft:nether_wart_block)
B(13,26,8,minecraft:nether_wart_block)
B(14,26,8,minecraft:nether_wart_block)
B(15,26,8,minecraft:nether_wart_block)
B(14,26,9,minecraft:nether_wart_block)
B(15,26,9,minecraft:nether_wart_block)
B(14,26,10,minecraft:nether_wart_block)
B(15,26,10,minecraft:nether_wart_block)
B(14,26,11,minecraft:nether_wart_block)
B(15,26,11,minecraft:nether_wart_block)
B(14,26,12,minecraft:nether_wart_block)
B(15,26,12,minecraft:nether_wart_block)
B(14,26,13,minecraft:nether_wart_block)
B(15,26,13,minecraft:nether_wart_block)
B(13,26,14,minecraft:nether_wart_block)
B(14,26,14,minecraft:nether_wart_block)
B(15,26,14,minecraft:nether_wart_block)
B(12,26,15,minecraft:nether_wart_block)
B(13,26,15,minecraft:nether_wart_block)
B(14,26,15,minecraft:nether_wart_block)
B(15,26,15,minecraft:nether_wart_block)
B(14,27,0,minecraft:nether_wart_block)
B(15,27,0,minecraft:nether_wart_block)
B(13,27,1,minecraft:nether_wart_block)
B(14,27,1,minecraft:nether_wart_block)
B(15,27,1,minecraft:nether_wart_block)
B(13,27,2,minecraft:nether_wart_block)
B(14,27,2,minecraft:nether_wart_block)
B(15,27,2,minecraft:nether_wart_block)
B(13,27,3,minecraft:nether_wart_block)
B(14,27,3,minecraft:nether_wart_block)
B(15,27,3,minecraft:nether_wart_block)
B(14,27,4,minecraft:nether_wart_block)
B(15,27,4,minecraft:nether_wart_block)
B(14,27,5,minecraft:nether_wart_block)
B(15,27,5,minecraft:nether_wart_block)
B(13,27,6,minecraft:nether_wart_block)
B(14,27,6,minecraft:nether_wart_block)
B(15,27,6,minecraft:nether_wart_block)
B(13,27,7,minecraft:nether_wart_block)
B(14,27,7,minecraft:nether_wart_block)
B(15,27,7,minecraft:nether_wart_block)
B(14,27,8,minecraft:nether_wart_block)
B(15,27,8,minecraft:nether_wart_block)
B(14,27,9,minecraft:nether_wart_block)
B(15,27,9,minecraft:nether_wart_block)
B(14,27,10,minecraft:nether_wart_block)
B(15,27,10,minecraft:nether_wart_block)
B(14,27,11,minecraft:nether_wart_block)
B(15,27,11,minecraft:nether_wart_block)
B(14,27,12,minecraft:nether_wart_block)
B(15,27,12,minecraft:nether_wart_block)
B(14,27,13,minecraft:nether_wart_block)
B(15,27,13,minecraft:nether_wart_block)
B(13,27,14,minecraft:nether_wart_block)
B(14,27,14,minecraft:nether_wart_block)
B(15,27,14,minecraft:nether_wart_block)
B(13,27,15,minecraft:nether_wart_block)
B(14,27,15,minecraft:nether_wart_block)
B(15,27,15,minecraft:nether_wart_block)
B(14,28,0,minecraft:nether_wart_block)
B(15,28,0,minecraft:nether_wart_block)
B(14,28,1,minecraft:nether_wart_block)
B(15,28,1,minecraft:nether_wart_block)
B(14,28,2,minecraft:nether_wart_block)
B(15,28,2,minecraft:nether_wart_block)
B(14,28,3,minecraft:nether_wart_block)
B(15,28,3,minecraft:nether_wart_block)
B(14,28,4,minecraft:nether_wart_block)
B(15,28,4,minecraft:nether_wart_block)
B(14,28,5,minecraft:nether_wart_block)
B(15,28,5,minecraft:nether_wart_block)
B(14,28,6,minecraft:nether_wart_block)
B(15,28,6,minecraft:nether_wart_block)
B(14,28,7,minecraft:nether_wart_block)
B(15,28,7,minecraft:nether_wart_block)
B(14,28,8,minecraft:nether_wart_block)
B(15,28,8,minecraft:nether_wart_block)
B(14,28,9,minecraft:nether_wart_block)
B(15,28,9,minecraft:nether_wart_block)
B(14,28,10,minecraft:nether_wart_block)
B(15,28,10,minecraft:nether_wart_block)
B(14,28,11,minecraft:nether_wart_block)
B(15,28,11,minecraft:nether_wart_block)
B(14,28,12,minecraft:nether_wart_block)
B(15,28,12,minecraft:nether_wart_block)
B(14,28,13,minecraft:nether_wart_block)
B(15,28,13,minecraft:nether_wart_block)
B(14,28,14,minecraft:nether_wart_block)
B(15,28,14,minecraft:nether_wart_block)
B(13,28,15,minecraft:nether_wart_block)
B(14,28,15,minecraft:nether_wart_block)
B(15,28,15,minecraft:nether_wart_block)
B(15,29,0,minecraft:nether_wart_block)
B(15,29,1,minecraft:nether_wart_block)
B(15,29,2,minecraft:nether_wart_block)
B(15,29,3,minecraft:nether_wart_block)
B(14,29,4,minecraft:nether_wart_block)
B(15,29,4,minecraft:nether_wart_block)
B(14,29,5,minecraft:nether_wart_block)
B(15,29,5,minecraft:nether_wart_block)
B(14,29,6,minecraft:nether_wart_block)
B(15,29,6,minecraft:nether_wart_block)
B(14,29,7,minecraft:nether_wart_block)
B(15,29,7,minecraft:nether_wart_block)
B(14,29,8,minecraft:nether_wart_block)
B(15,29,8,minecraft:nether_wart_block)
B(14,29,9,minecraft:nether_wart_block)
B(15,29,9,minecraft:nether_wart_block)
B(14,29,10,minecraft:nether_wart_block)
B(15,29,10,minecraft:nether_wart_block)
B(14,29,11,minecraft:nether_wart_block)
B(15,29,11,minecraft:nether_wart_block)
B(14,29,12,minecraft:nether_wart_block)
B(15,29,12,minecraft:nether_wart_block)
B(14,29,13,minecraft:nether_wart_block)
B(15,29,13,minecraft:nether_wart_block)
B(14,29,14,minecraft:nether_wart_block)
B(15,29,14,minecraft:nether_wart_block)
B(13,29,15,minecraft:nether_wart_block)
B(14,29,15,minecraft:nether_wart_block)
B(15,29,15,minecraft:nether_wart_block)
B(15,30,3,minecraft:nether_wart_block)
B(14,30,4,minecraft:nether_wart_block)
B(15,30,4,minecraft:nether_wart_block)
B(14,30,5,minecraft:nether_wart_block)
B(15,30,5,minecraft:nether_wart_block)
B(14,30,6,minecraft:nether_wart_block)
B(15,30,6,minecraft:nether_wart_block)
B(14,30,7,minecraft:nether_wart_block)
B(15,30,7,minecraft:nether_wart_block)
B(14,30,8,minecraft:nether_wart_block)
B(15,30,8,minecraft:nether_wart_block)
B(14,30,9,minecraft:nether_wart_block)
B(15,30,9,minecraft:nether_wart_block)
B(14,30,10,minecraft:nether_wart_block)
B(15,30,10,minecraft:nether_wart_block)
B(14,30,11,minecraft:nether_wart_block)
B(15,30,11,minecraft:nether_wart_block)
B(14,30,12,minecraft:nether_wart_block)
B(15,30,12,minecraft:nether_wart_block)
B(14,30,13,minecraft:nether_wart_block)
B(15,30,13,minecraft:nether_wart_block)
B(14,30,14,minecraft:nether_wart_block)
B(15,30,14,minecraft:nether_wart_block)
B(14,30,15,minecraft:nether_wart_block)
B(15,30,15,minecraft:nether_wart_block)
B(15,31,3,minecraft:nether_wart_block)
B(14,31,4,minecraft:nether_wart_block)
B(15,31,4,minecraft:nether_wart_block)
B(14,31,5,minecraft:nether_wart_block)
B(15,31,5,minecraft:nether_wart_block)
B(14,31,6,minecraft:nether_wart_block)
B(15,31,6,minecraft:nether_wart_block)
B(14,31,7,minecraft:nether_wart_block)
B(15,31,7,minecraft:nether_wart_block)
B(14,31,8,minecraft:nether_wart_block)
B(15,31,8,minecraft:nether_wart_block)
B(14,31,9,minecraft:nether_wart_block)
B(15,31,9,minecraft:nether_wart_block)
B(14,31,10,minecraft:nether_wart_block)
B(15,31,10,minecraft:nether_wart_block)
B(14,31,11,minecraft:nether_wart_block)
B(15,31,11,minecraft:nether_wart_block)
B(14,31,12,minecraft:nether_wart_block)
B(15,31,12,minecraft:nether_wart_block)
B(14,31,13,minecraft:nether_wart_block)
B(15,31,13,minecraft:nether_wart_block)
B(14,31,14,minecraft:nether_wart_block)
B(15,31,14,minecraft:nether_wart_block)
B(14,31,15,minecraft:nether_wart_block)
B(15,31,15,minecraft:nether_wart_block)
B(15,32,3,minecraft:nether_wart_block)
B(14,32,4,minecraft:nether_wart_block)
B(15,32,4,minecraft:nether_wart_block)
B(14,32,5,minecraft:nether_wart_block)
B(15,32,5,minecraft:nether_wart_block)
B(14,32,6,minecraft:nether_wart_block)
B(15,32,6,minecraft:nether_wart_block)
B(14,32,7,minecraft:nether_wart_block)
B(15,32,7,minecraft:nether_wart_block)
B(14,32,8,minecraft:nether_wart_block)
B(15,32,8,minecraft:nether_wart_block)
B(14,32,9,minecraft:nether_wart_block)
B(15,32,9,minecraft:nether_wart_block)
B(14,32,10,minecraft:nether_wart_block)
B(15,32,10,minecraft:nether_wart_block)
B(14,32,11,minecraft:nether_wart_block)
B(15,32,11,minecraft:nether_wart_block)
B(14,32,12,minecraft:nether_wart_block)
B(15,32,12,minecraft:nether_wart_block)
B(14,32,13,minecraft:nether_wart_block)
B(15,32,13,minecraft:nether_wart_block)
B(14,32,14,minecraft:nether_wart_block)
B(15,32,14,minecraft:nether_wart_block)
B(14,32,15,minecraft:nether_wart_block)
B(15,32,15,minecraft:nether_wart_block)
B(15,33,3,minecraft:nether_wart_block)
B(14,33,4,minecraft:nether_wart_block)
B(15,33,4,minecraft:nether_wart_block)
B(14,33,5,minecraft:nether_wart_block)
B(15,33,5,minecraft:nether_wart_block)
B(14,33,6,minecraft:nether_wart_block)
B(15,33,6,minecraft:nether_wart_block)
B(14,33,7,minecraft:nether_wart_block)
B(15,33,7,minecraft:nether_wart_block)
B(14,33,8,minecraft:nether_wart_block)
B(15,33,8,minecraft:nether_wart_block)
B(14,33,9,minecraft:nether_wart_block)
B(15,33,9,minecraft:nether_wart_block)
B(14,33,10,minecraft:nether_wart_block)
B(15,33,10,minecraft:nether_wart_block)
B(14,33,11,minecraft:nether_wart_block)
B(15,33,11,minecraft:nether_wart_block)
B(14,33,12,minecraft:nether_wart_block)
B(15,33,12,minecraft:nether_wart_block)
B(14,33,13,minecraft:nether_wart_block)
B(15,33,13,minecraft:nether_wart_block)
B(14,33,14,minecraft:nether_wart_block)
B(15,33,14,minecraft:nether_wart_block)
B(14,33,15,minecraft:nether_wart_block)
B(15,33,15,minecraft:nether_wart_block)
B(15,34,3,minecraft:nether_wart_block)
B(14,34,4,minecraft:nether_wart_block)
B(15,34,4,minecraft:nether_wart_block)
B(14,34,5,minecraft:nether_wart_block)
B(15,34,5,minecraft:nether_wart_block)
B(15,34,6,minecraft:nether_wart_block)
B(15,34,7,minecraft:nether_wart_block)
B(15,34,8,minecraft:nether_wart_block)
B(14,34,9,minecraft:nether_wart_block)
B(15,34,9,minecraft:nether_wart_block)
B(14,34,10,minecraft:nether_wart_block)
B(15,34,10,minecraft:nether_wart_block)
B(14,34,11,minecraft:nether_wart_block)
B(15,34,11,minecraft:nether_wart_block)
B(14,34,12,minecraft:nether_wart_block)
B(15,34,12,minecraft:nether_wart_block)
B(14,34,13,minecraft:nether_wart_block)
B(15,34,13,minecraft:nether_wart_block)
B(14,34,14,minecraft:nether_wart_block)
B(15,34,14,minecraft:nether_wart_block)
B(14,34,15,minecraft:nether_wart_block)
B(15,34,15,minecraft:nether_wart_block)
B(15,35,3,minecraft:nether_wart_block)
B(14,35,4,minecraft:nether_wart_block)
B(15,35,4,minecraft:nether_wart_block)
B(14,35,5,minecraft:nether_wart_block)
B(15,35,5,minecraft:nether_wart_block)
B(15,35,6,minecraft:nether_wart_block)
B(15,35,7,minecraft:nether_wart_block)
B(15,35,8,minecraft:nether_wart_block)
B(14,35,9,minecraft:nether_wart_block)
B(15,35,9,minecraft:nether_wart_block)
B(14,35,10,minecraft:nether_wart_block)
B(15,35,10,minecraft:nether_wart_block)
B(14,35,11,minecraft:nether_wart_block)
B(15,35,11,minecraft:nether_wart_block)
B(14,35,12,minecraft:nether_wart_block)
B(15,35,12,minecraft:nether_wart_block)
B(14,35,13,minecraft:nether_wart_block)
B(15,35,13,minecraft:nether_wart_block)
B(14,35,14,minecraft:nether_wart_block)
B(15,35,14,minecraft:nether_wart_block)
B(14,35,15,minecraft:nether_wart_block)
B(15,35,15,minecraft:nether_wart_block)
B(15,36,3,minecraft:nether_wart_block)
B(14,36,4,minecraft:nether_wart_block)
B(15,36,4,minecraft:nether_wart_block)
B(14,36,5,minecraft:nether_wart_block)
B(15,36,5,minecraft:nether_wart_block)
B(15,36,6,minecraft:nether_wart_block)
B(15,36,7,minecraft:nether_wart_block)
B(15,36,8,minecraft:nether_wart_block)
B(14,36,9,minecraft:nether_wart_block)
B(15,36,9,minecraft:nether_wart_block)
B(14,36,10,minecraft:nether_wart_block)
B(15,36,10,minecraft:nether_wart_block)
B(14,36,11,minecraft:nether_wart_block)
B(15,36,11,minecraft:nether_wart_block)
B(14,36,12,minecraft:nether_wart_block)
B(15,36,12,minecraft:nether_wart_block)
B(14,36,13,minecraft:nether_wart_block)
B(15,36,13,minecraft:nether_wart_block)
B(14,36,14,minecraft:nether_wart_block)
B(15,36,14,minecraft:nether_wart_block)
B(14,36,15,minecraft:nether_wart_block)
B(15,36,15,minecraft:nether_wart_block)
B(15,37,3,minecraft:nether_wart_block)
B(14,37,4,minecraft:nether_wart_block)
B(15,37,4,minecraft:nether_wart_block)
B(14,37,5,minecraft:nether_wart_block)
B(15,37,5,minecraft:nether_wart_block)
B(15,37,6,minecraft:nether_wart_block)
B(15,37,7,minecraft:nether_wart_block)
B(15,37,8,minecraft:nether_wart_block)
B(14,37,9,minecraft:nether_wart_block)
B(15,37,9,minecraft:nether_wart_block)
B(14,37,10,minecraft:nether_wart_block)
B(15,37,10,minecraft:nether_wart_block)
B(14,37,11,minecraft:nether_wart_block)
B(15,37,11,minecraft:nether_wart_block)
B(14,37,12,minecraft:nether_wart_block)
B(15,37,12,minecraft:nether_wart_block)
B(14,37,13,minecraft:nether_wart_block)
B(15,37,13,minecraft:nether_wart_block)
B(14,37,14,minecraft:nether_wart_block)
B(15,37,14,minecraft:nether_wart_block)
B(14,37,15,minecraft:nether_wart_block)
B(15,37,15,minecraft:nether_wart_block)
B(15,38,3,minecraft:nether_wart_block)
B(14,38,4,minecraft:nether_wart_block)
B(15,38,4,minecraft:nether_wart_block)
B(14,38,5,minecraft:nether_wart_block)
B(15,38,5,minecraft:nether_wart_block)
B(15,38,6,minecraft:nether_wart_block)
B(15,38,8,minecraft:nether_wart_block)
B(14,38,9,minecraft:nether_wart_block)
B(15,38,9,minecraft:nether_wart_block)
B(14,38,10,minecraft:nether_wart_block)
B(15,38,10,minecraft:nether_wart_block)
B(14,38,11,minecraft:nether_wart_block)
B(15,38,11,minecraft:nether_wart_block)
B(14,38,12,minecraft:nether_wart_block)
B(15,38,12,minecraft:nether_wart_block)
B(14,38,13,minecraft:nether_wart_block)
B(15,38,13,minecraft:nether_wart_block)
B(14,38,14,minecraft:nether_wart_block)
B(15,38,14,minecraft:nether_wart_block)
B(14,38,15,minecraft:nether_wart_block)
B(15,38,15,minecraft:nether_wart_block)
B(15,39,3,minecraft:nether_wart_block)
B(15,39,4,minecraft:nether_wart_block)
B(14,39,5,minecraft:nether_wart_block)
B(15,39,5,minecraft:nether_wart_block)
B(15,39,6,minecraft:nether_wart_block)
B(15,39,8,minecraft:nether_wart_block)
B(14,39,9,minecraft:nether_wart_block)
B(15,39,9,minecraft:nether_wart_block)
B(14,39,10,minecraft:nether_wart_block)
B(15,39,10,minecraft:nether_wart_block)
B(14,39,11,minecraft:nether_wart_block)
B(15,39,11,minecraft:nether_wart_block)
B(14,39,12,minecraft:nether_wart_block)
B(15,39,12,minecraft:nether_wart_block)
B(14,39,13,minecraft:nether_wart_block)
B(15,39,13,minecraft:nether_wart_block)
B(14,39,14,minecraft:nether_wart_block)
B(15,39,14,minecraft:nether_wart_block)
B(14,39,15,minecraft:nether_wart_block)
B(15,39,15,minecraft:nether_wart_block)
B(15,40,4,minecraft:nether_wart_block)
B(14,40,5,minecraft:nether_wart_block)
B(15,40,5,minecraft:nether_wart_block)
B(15,40,6,minecraft:nether_wart_block)
B(15,40,8,minecraft:nether_wart_block)
B(14,40,9,minecraft:nether_wart_block)
B(15,40,9,minecraft:nether_wart_block)
B(14,40,10,minecraft:nether_wart_block)
B(15,40,10,minecraft:nether_wart_block)
B(14,40,11,minecraft:nether_wart_block)
B(15,40,11,minecraft:nether_wart_block)
B(14,40,12,minecraft:nether_wart_block)
B(15,40,12,minecraft:nether_wart_block)
B(14,40,13,minecraft:nether_wart_block)
B(15,40,13,minecraft:nether_wart_block)
B(14,40,14,minecraft:nether_wart_block)
B(15,40,14,minecraft:nether_wart_block)
B(14,40,15,minecraft:nether_wart_block)
B(15,40,15,minecraft:nether_wart_block)
B(15,41,4,minecraft:nether_wart_block)
B(14,41,5,minecraft:nether_wart_block)
B(15,41,5,minecraft:nether_wart_block)
B(15,41,6,minecraft:nether_wart_block)
B(15,41,8,minecraft:nether_wart_block)
B(14,41,9,minecraft:nether_wart_block)
B(15,41,9,minecraft:nether_wart_block)
B(14,41,10,minecraft:nether_wart_block)
B(15,41,10,minecraft:nether_wart_block)
B(14,41,11,minecraft:nether_wart_block)
B(15,41,11,minecraft:nether_wart_block)
B(14,41,12,minecraft:nether_wart_block)
B(15,41,12,minecraft:nether_wart_block)
B(14,41,13,minecraft:nether_wart_block)
B(15,41,13,minecraft:nether_wart_block)
B(14,41,14,minecraft:nether_wart_block)
B(15,41,14,minecraft:nether_wart_block)
B(15,41,15,minecraft:nether_wart_block)
B(15,42,4,minecraft:nether_wart_block)
B(15,42,5,minecraft:nether_wart_block)
B(15,42,6,minecraft:nether_wart_block)
B(15,42,8,minecraft:nether_wart_block)
B(14,42,9,minecraft:nether_wart_block)
B(15,42,9,minecraft:nether_wart_block)
B(14,42,10,minecraft:nether_wart_block)
B(15,42,10,minecraft:nether_wart_block)
B(14,42,11,minecraft:nether_wart_block)
B(15,42,11,minecraft:nether_wart_block)
B(14,42,12,minecraft:nether_wart_block)
B(15,42,12,minecraft:nether_wart_block)
B(14,42,13,minecraft:nether_wart_block)
B(15,42,13,minecraft:nether_wart_block)
B(14,42,14,minecraft:nether_wart_block)
B(15,42,14,minecraft:nether_wart_block)
B(15,42,15,minecraft:nether_wart_block)
B(15,43,4,minecraft:nether_wart_block)
B(15,43,5,minecraft:nether_wart_block)
B(15,43,6,minecraft:nether_wart_block)
B(15,43,8,minecraft:nether_wart_block)
B(15,43,9,minecraft:nether_wart_block)
B(14,43,10,minecraft:nether_wart_block)
B(15,43,10,minecraft:nether_wart_block)
B(14,43,11,minecraft:nether_wart_block)
B(15,43,11,minecraft:nether_wart_block)
B(14,43,12,minecraft:nether_wart_block)
B(15,43,12,minecraft:nether_wart_block)
B(14,43,13,minecraft:nether_wart_block)
B(15,43,13,minecraft:nether_wart_block)
B(14,43,14,minecraft:nether_wart_block)
B(15,43,14,minecraft:nether_wart_block)
B(15,43,15,minecraft:nether_wart_block)
B(15,44,5,minecraft:nether_wart_block)
B(15,44,6,minecraft:nether_wart_block)
B(15,44,8,minecraft:nether_wart_block)
B(15,44,9,minecraft:nether_wart_block)
B(14,44,10,minecraft:nether_wart_block)
B(15,44,10,minecraft:nether_wart_block)
B(14,44,11,minecraft:nether_wart_block)
B(15,44,11,minecraft:nether_wart_block)
B(14,44,12,minecraft:nether_wart_block)
B(15,44,12,minecraft:nether_wart_block)
B(14,44,13,minecraft:nether_wart_block)
B(15,44,13,minecraft:nether_wart_block)
B(14,44,14,minecraft:nether_wart_block)
B(15,44,14,minecraft:nether_wart_block)
B(15,44,15,minecraft:nether_wart_block)
B(15,45,5,minecraft:nether_wart_block)
B(15,45,8,minecraft:nether_wart_block)
B(15,45,9,minecraft:nether_wart_block)
B(14,45,10,minecraft:nether_wart_block)
B(15,45,10,minecraft:nether_wart_block)
B(14,45,11,minecraft:nether_wart_block)
B(15,45,11,minecraft:nether_wart_block)
B(14,45,12,minecraft:nether_wart_block)
B(15,45,12,minecraft:nether_wart_block)
B(14,45,13,minecraft:nether_wart_block)
B(15,45,13,minecraft:nether_wart_block)
B(15,45,14,minecraft:nether_wart_block)
B(15,45,15,minecraft:nether_wart_block)
B(15,46,8,minecraft:nether_wart_block)
B(15,46,9,minecraft:nether_wart_block)
B(14,46,10,minecraft:nether_wart_block)
B(15,46,10,minecraft:nether_wart_block)
B(14,46,11,minecraft:nether_wart_block)
B(15,46,11,minecraft:nether_wart_block)
B(14,46,12,minecraft:nether_wart_block)
B(15,46,12,minecraft:nether_wart_block)
B(14,46,13,minecraft:nether_wart_block)
B(15,46,13,minecraft:nether_wart_block)
B(15,46,14,minecraft:nether_wart_block)
B(15,46,15,minecraft:nether_wart_block)
B(15,47,8,minecraft:nether_wart_block)
B(15,47,9,minecraft:nether_wart_block)
B(14,47,10,minecraft:nether_wart_block)
B(15,47,10,minecraft:nether_wart_block)
B(14,47,11,minecraft:nether_wart_block)
B(15,47,11,minecraft:nether_wart_block)
B(14,47,12,minecraft:nether_wart_block)
B(15,47,12,minecraft:nether_wart_block)
B(14,47,13,minecraft:nether_wart_block)
B(15,47,13,minecraft:nether_wart_block)
B(15,47,14,minecraft:nether_wart_block)
B(15,47,15,minecraft:nether_wart_block)
B(15,48,8,minecraft:nether_wart_block)
B(15,48,9,minecraft:nether_wart_block)
B(15,48,10,minecraft:nether_wart_block)
B(14,48,11,minecraft:nether_wart_block)
B(15,48,11,minecraft:nether_wart_block)
B(14,48,12,minecraft:nether_wart_block)
B(15,48,12,minecraft:nether_wart_block)
B(14,48,13,minecraft:nether_wart_block)
B(15,48,13,minecraft:nether_wart_block)
B(15,48,14,minecraft:nether_wart_block)
B(15,48,15,minecraft:nether_wart_block)
B(15,49,8,minecraft:nether_wart_block)
B(15,49,9,minecraft:nether_wart_block)
B(15,49,10,minecraft:nether_wart_block)
B(14,49,11,minecraft:nether_wart_block)
B(15,49,11,minecraft:nether_wart_block)
B(14,49,12,minecraft:nether_wart_block)
B(15,49,12,minecraft:nether_wart_block)
B(14,49,13,minecraft:nether_wart_block)
B(15,49,13,minecraft:nether_wart_block)
B(15,49,14,minecraft:nether_wart_block)
B(15,49,15,minecraft:nether_wart_block)
B(15,50,10,minecraft:nether_wart_block)
B(14,50,11,minecraft:nether_wart_block)
B(15,50,11,minecraft:nether_wart_block)
B(14,50,12,minecraft:nether_wart_block)
B(15,50,12,minecraft:nether_wart_block)
B(14,50,13,minecraft:nether_wart_block)
B(15,50,13,minecraft:nether_wart_block)
B(15,50,14,minecraft:nether_wart_block)
B(15,50,15,minecraft:nether_wart_block)
B(15,51,10,minecraft:nether_wart_block)
B(14,51,11,minecraft:nether_wart_block)
B(15,51,11,minecraft:nether_wart_block)
B(14,51,12,minecraft:nether_wart_block)
B(15,51,12,minecraft:nether_wart_block)
B(15,51,13,minecraft:nether_wart_block)
B(15,51,14,minecraft:nether_wart_block)
B(15,51,15,minecraft:nether_wart_block)
B(15,52,10,minecraft:nether_wart_block)
B(15,52,11,minecraft:nether_wart_block)
B(14,52,12,minecraft:nether_wart_block)
B(15,52,12,minecraft:nether_wart_block)
B(15,52,13,minecraft:nether_wart_block)
B(15,52,14,minecraft:nether_wart_block)
B(15,52,15,minecraft:nether_wart_block)
B(15,53,10,minecraft:nether_wart_block)
B(15,53,11,minecraft:nether_wart_block)
B(14,53,12,minecraft:nether_wart_block)
B(15,53,12,minecraft:nether_wart_block)
B(15,53,13,minecraft:nether_wart_block)
B(15,53,14,minecraft:nether_wart_block)
B(15,53,15,minecraft:nether_wart_block)
B(15,54,11,minecraft:nether_wart_block)
B(15,54,12,minecraft:nether_wart_block)
B(15,54,13,minecraft:nether_wart_block)
B(15,54,14,minecraft:nether_wart_block)
B(15,54,15,minecraft:nether_wart_block)
B(15,55,15,minecraft:nether_wart_block)
B(15,56,15,minecraft:nether_wart_block)
B(15,57,15,minecraft:nether_wart_block)

BR(0,0,-16,true,FleshWall1_0x0,NORTH,100,0)
BR(16,0,0,true,FleshWall1_1x1,NORTH,100,0)
