Author: Bo3 BulkEdit

Description: Converted Schematic - Modified by Bo3BulkEdit

Version: 3

SettingsMode: WriteDisable

IsOTGPlus: true
Tree: false
Frequency: 10
Rarity: 100
RotateRandomly: true
SpawnHeight: randomY
SpawnHeightOffset: 0
SpawnHeightVariance: 0
MaxBranchDepth: 10
ExcludedBiomes: All

MinHeight: 50
MaxHeight: 65

SourceBlocks: AIR
MaxPercentageOutsideSourceBlock: 100
OutsideSourceBlock: placeAnyway

ReplaceBelow: NETHER_WART_BLOCK
ReplaceWithBiomeBlocks: false
ReplaceWithGroundBlock: NETHER_WART_BLOCK
ReplaceWithSurfaceBlock: NETHER_WART_BLOCK
ReplaceWithStoneBlock: NETHER_WART_BLOCK
SmoothRadius: 30
SmoothHeightOffset: 0
SmoothStartTop: false
SmoothStartWood: false
SmoothingSurfaceBlock: NETHER_WART_BLOCK
SmoothingGroundBlock: NETHER_WART_BLOCK

B(0,750,0,AIR)
B(15,750,15,AIR)
B(9,0,0,minecraft:nether_wart_block)
B(10,0,0,minecraft:nether_wart_block)
B(11,0,0,minecraft:nether_wart_block)
B(12,0,0,minecraft:nether_wart_block)
B(13,0,0,minecraft:nether_wart_block)
B(14,0,0,minecraft:nether_wart_block)
B(15,0,0,minecraft:nether_wart_block)
B(8,0,1,minecraft:nether_wart_block)
B(9,0,1,minecraft:nether_wart_block)
B(10,0,1,minecraft:nether_wart_block)
B(11,0,1,minecraft:nether_wart_block)
B(12,0,1,minecraft:nether_wart_block)
B(13,0,1,minecraft:nether_wart_block)
B(14,0,1,minecraft:nether_wart_block)
B(15,0,1,minecraft:nether_wart_block)
B(8,0,2,minecraft:nether_wart_block)
B(9,0,2,minecraft:nether_wart_block)
B(10,0,2,minecraft:nether_wart_block)
B(11,0,2,minecraft:nether_wart_block)
B(12,0,2,minecraft:nether_wart_block)
B(13,0,2,minecraft:nether_wart_block)
B(14,0,2,minecraft:nether_wart_block)
B(15,0,2,minecraft:nether_wart_block)
B(8,0,3,minecraft:nether_wart_block)
B(9,0,3,minecraft:nether_wart_block)
B(10,0,3,minecraft:nether_wart_block)
B(11,0,3,minecraft:nether_wart_block)
B(12,0,3,minecraft:nether_wart_block)
B(13,0,3,minecraft:nether_wart_block)
B(14,0,3,minecraft:nether_wart_block)
B(15,0,3,minecraft:nether_wart_block)
B(8,0,4,minecraft:nether_wart_block)
B(9,0,4,minecraft:nether_wart_block)
B(10,0,4,minecraft:nether_wart_block)
B(11,0,4,minecraft:nether_wart_block)
B(12,0,4,minecraft:nether_wart_block)
B(13,0,4,minecraft:nether_wart_block)
B(14,0,4,minecraft:nether_wart_block)
B(15,0,4,minecraft:nether_wart_block)
B(8,0,5,minecraft:nether_wart_block)
B(9,0,5,minecraft:nether_wart_block)
B(10,0,5,minecraft:nether_wart_block)
B(11,0,5,minecraft:nether_wart_block)
B(12,0,5,minecraft:nether_wart_block)
B(13,0,5,minecraft:nether_wart_block)
B(14,0,5,minecraft:nether_wart_block)
B(15,0,5,minecraft:nether_wart_block)
B(9,0,6,minecraft:nether_wart_block)
B(10,0,6,minecraft:nether_wart_block)
B(11,0,6,minecraft:nether_wart_block)
B(12,0,6,minecraft:nether_wart_block)
B(13,0,6,minecraft:nether_wart_block)
B(14,0,6,minecraft:nether_wart_block)
B(15,0,6,minecraft:nether_wart_block)
B(9,0,7,minecraft:nether_wart_block)
B(10,0,7,minecraft:nether_wart_block)
B(11,0,7,minecraft:nether_wart_block)
B(12,0,7,minecraft:nether_wart_block)
B(13,0,7,minecraft:nether_wart_block)
B(14,0,7,minecraft:nether_wart_block)
B(15,0,7,minecraft:nether_wart_block)
B(10,0,8,minecraft:nether_wart_block)
B(11,0,8,minecraft:nether_wart_block)
B(12,0,8,minecraft:nether_wart_block)
B(13,0,8,minecraft:nether_wart_block)
B(14,0,8,minecraft:nether_wart_block)
B(15,0,8,minecraft:nether_wart_block)
B(11,0,9,minecraft:nether_wart_block)
B(12,0,9,minecraft:nether_wart_block)
B(13,0,9,minecraft:nether_wart_block)
B(14,0,9,minecraft:nether_wart_block)
B(15,0,9,minecraft:nether_wart_block)
B(11,0,10,minecraft:nether_wart_block)
B(12,0,10,minecraft:nether_wart_block)
B(13,0,10,minecraft:nether_wart_block)
B(14,0,10,minecraft:nether_wart_block)
B(15,0,10,minecraft:nether_wart_block)
B(10,0,11,minecraft:nether_wart_block)
B(11,0,11,minecraft:nether_wart_block)
B(12,0,11,minecraft:nether_wart_block)
B(13,0,11,minecraft:nether_wart_block)
B(14,0,11,minecraft:nether_wart_block)
B(15,0,11,minecraft:nether_wart_block)
B(11,0,12,minecraft:nether_wart_block)
B(12,0,12,minecraft:nether_wart_block)
B(13,0,12,minecraft:nether_wart_block)
B(14,0,12,minecraft:nether_wart_block)
B(15,0,12,minecraft:nether_wart_block)
B(10,0,13,minecraft:nether_wart_block)
B(11,0,13,minecraft:nether_wart_block)
B(12,0,13,minecraft:nether_wart_block)
B(13,0,13,minecraft:nether_wart_block)
B(14,0,13,minecraft:nether_wart_block)
B(15,0,13,minecraft:nether_wart_block)
B(10,0,14,minecraft:nether_wart_block)
B(11,0,14,minecraft:nether_wart_block)
B(12,0,14,minecraft:nether_wart_block)
B(13,0,14,minecraft:nether_wart_block)
B(14,0,14,minecraft:nether_wart_block)
B(15,0,14,minecraft:nether_wart_block)
B(10,0,15,minecraft:nether_wart_block)
B(11,0,15,minecraft:nether_wart_block)
B(12,0,15,minecraft:nether_wart_block)
B(13,0,15,minecraft:nether_wart_block)
B(14,0,15,minecraft:nether_wart_block)
B(15,0,15,minecraft:nether_wart_block)
B(9,1,0,minecraft:nether_wart_block)
B(10,1,0,minecraft:nether_wart_block)
B(11,1,0,minecraft:nether_wart_block)
B(12,1,0,minecraft:nether_wart_block)
B(13,1,0,minecraft:nether_wart_block)
B(14,1,0,minecraft:nether_wart_block)
B(15,1,0,minecraft:nether_wart_block)
B(8,1,1,minecraft:nether_wart_block)
B(9,1,1,minecraft:nether_wart_block)
B(10,1,1,minecraft:nether_wart_block)
B(11,1,1,minecraft:nether_wart_block)
B(12,1,1,minecraft:nether_wart_block)
B(13,1,1,minecraft:nether_wart_block)
B(14,1,1,minecraft:nether_wart_block)
B(15,1,1,minecraft:nether_wart_block)
B(8,1,2,minecraft:nether_wart_block)
B(9,1,2,minecraft:nether_wart_block)
B(10,1,2,minecraft:nether_wart_block)
B(11,1,2,minecraft:nether_wart_block)
B(12,1,2,minecraft:nether_wart_block)
B(13,1,2,minecraft:nether_wart_block)
B(14,1,2,minecraft:nether_wart_block)
B(15,1,2,minecraft:nether_wart_block)
B(8,1,3,minecraft:nether_wart_block)
B(9,1,3,minecraft:nether_wart_block)
B(10,1,3,minecraft:nether_wart_block)
B(11,1,3,minecraft:nether_wart_block)
B(12,1,3,minecraft:nether_wart_block)
B(13,1,3,minecraft:nether_wart_block)
B(14,1,3,minecraft:nether_wart_block)
B(15,1,3,minecraft:nether_wart_block)
B(8,1,4,minecraft:nether_wart_block)
B(9,1,4,minecraft:nether_wart_block)
B(10,1,4,minecraft:nether_wart_block)
B(11,1,4,minecraft:nether_wart_block)
B(12,1,4,minecraft:nether_wart_block)
B(13,1,4,minecraft:nether_wart_block)
B(14,1,4,minecraft:nether_wart_block)
B(15,1,4,minecraft:nether_wart_block)
B(9,1,5,minecraft:nether_wart_block)
B(10,1,5,minecraft:nether_wart_block)
B(11,1,5,minecraft:nether_wart_block)
B(12,1,5,minecraft:nether_wart_block)
B(13,1,5,minecraft:nether_wart_block)
B(14,1,5,minecraft:nether_wart_block)
B(15,1,5,minecraft:nether_wart_block)
B(9,1,6,minecraft:nether_wart_block)
B(10,1,6,minecraft:nether_wart_block)
B(11,1,6,minecraft:nether_wart_block)
B(12,1,6,minecraft:nether_wart_block)
B(13,1,6,minecraft:nether_wart_block)
B(14,1,6,minecraft:nether_wart_block)
B(15,1,6,minecraft:nether_wart_block)
B(9,1,7,minecraft:nether_wart_block)
B(10,1,7,minecraft:nether_wart_block)
B(11,1,7,minecraft:nether_wart_block)
B(12,1,7,minecraft:nether_wart_block)
B(13,1,7,minecraft:nether_wart_block)
B(14,1,7,minecraft:nether_wart_block)
B(15,1,7,minecraft:nether_wart_block)
B(10,1,8,minecraft:nether_wart_block)
B(11,1,8,minecraft:nether_wart_block)
B(12,1,8,minecraft:nether_wart_block)
B(13,1,8,minecraft:nether_wart_block)
B(14,1,8,minecraft:nether_wart_block)
B(15,1,8,minecraft:nether_wart_block)
B(11,1,9,minecraft:nether_wart_block)
B(12,1,9,minecraft:nether_wart_block)
B(13,1,9,minecraft:nether_wart_block)
B(14,1,9,minecraft:nether_wart_block)
B(15,1,9,minecraft:nether_wart_block)
B(11,1,10,minecraft:nether_wart_block)
B(12,1,10,minecraft:nether_wart_block)
B(13,1,10,minecraft:nether_wart_block)
B(14,1,10,minecraft:nether_wart_block)
B(15,1,10,minecraft:nether_wart_block)
B(10,1,11,minecraft:nether_wart_block)
B(11,1,11,minecraft:nether_wart_block)
B(12,1,11,minecraft:nether_wart_block)
B(13,1,11,minecraft:nether_wart_block)
B(14,1,11,minecraft:nether_wart_block)
B(15,1,11,minecraft:nether_wart_block)
B(11,1,12,minecraft:nether_wart_block)
B(12,1,12,minecraft:nether_wart_block)
B(13,1,12,minecraft:nether_wart_block)
B(14,1,12,minecraft:nether_wart_block)
B(15,1,12,minecraft:nether_wart_block)
B(10,1,13,minecraft:nether_wart_block)
B(11,1,13,minecraft:nether_wart_block)
B(12,1,13,minecraft:nether_wart_block)
B(13,1,13,minecraft:nether_wart_block)
B(14,1,13,minecraft:nether_wart_block)
B(15,1,13,minecraft:nether_wart_block)
B(10,1,14,minecraft:nether_wart_block)
B(11,1,14,minecraft:nether_wart_block)
B(12,1,14,minecraft:nether_wart_block)
B(13,1,14,minecraft:nether_wart_block)
B(14,1,14,minecraft:nether_wart_block)
B(15,1,14,minecraft:nether_wart_block)
B(10,1,15,minecraft:nether_wart_block)
B(11,1,15,minecraft:nether_wart_block)
B(12,1,15,minecraft:nether_wart_block)
B(13,1,15,minecraft:nether_wart_block)
B(14,1,15,minecraft:nether_wart_block)
B(15,1,15,minecraft:nether_wart_block)
B(9,2,0,minecraft:nether_wart_block)
B(10,2,0,minecraft:nether_wart_block)
B(11,2,0,minecraft:nether_wart_block)
B(12,2,0,minecraft:nether_wart_block)
B(13,2,0,minecraft:nether_wart_block)
B(14,2,0,minecraft:nether_wart_block)
B(15,2,0,minecraft:nether_wart_block)
B(9,2,1,minecraft:nether_wart_block)
B(10,2,1,minecraft:nether_wart_block)
B(11,2,1,minecraft:nether_wart_block)
B(12,2,1,minecraft:nether_wart_block)
B(13,2,1,minecraft:nether_wart_block)
B(14,2,1,minecraft:nether_wart_block)
B(15,2,1,minecraft:nether_wart_block)
B(8,2,2,minecraft:nether_wart_block)
B(9,2,2,minecraft:nether_wart_block)
B(10,2,2,minecraft:nether_wart_block)
B(11,2,2,minecraft:nether_wart_block)
B(12,2,2,minecraft:nether_wart_block)
B(13,2,2,minecraft:nether_wart_block)
B(14,2,2,minecraft:nether_wart_block)
B(15,2,2,minecraft:nether_wart_block)
B(8,2,3,minecraft:nether_wart_block)
B(9,2,3,minecraft:nether_wart_block)
B(10,2,3,minecraft:nether_wart_block)
B(11,2,3,minecraft:nether_wart_block)
B(12,2,3,minecraft:nether_wart_block)
B(13,2,3,minecraft:nether_wart_block)
B(14,2,3,minecraft:nether_wart_block)
B(15,2,3,minecraft:nether_wart_block)
B(8,2,4,minecraft:nether_wart_block)
B(9,2,4,minecraft:nether_wart_block)
B(10,2,4,minecraft:nether_wart_block)
B(11,2,4,minecraft:nether_wart_block)
B(12,2,4,minecraft:nether_wart_block)
B(13,2,4,minecraft:nether_wart_block)
B(14,2,4,minecraft:nether_wart_block)
B(15,2,4,minecraft:nether_wart_block)
B(9,2,5,minecraft:nether_wart_block)
B(10,2,5,minecraft:nether_wart_block)
B(11,2,5,minecraft:nether_wart_block)
B(12,2,5,minecraft:nether_wart_block)
B(13,2,5,minecraft:nether_wart_block)
B(14,2,5,minecraft:nether_wart_block)
B(15,2,5,minecraft:nether_wart_block)
B(9,2,6,minecraft:nether_wart_block)
B(10,2,6,minecraft:nether_wart_block)
B(11,2,6,minecraft:nether_wart_block)
B(12,2,6,minecraft:nether_wart_block)
B(13,2,6,minecraft:nether_wart_block)
B(14,2,6,minecraft:nether_wart_block)
B(15,2,6,minecraft:nether_wart_block)
B(9,2,7,minecraft:nether_wart_block)
B(10,2,7,minecraft:nether_wart_block)
B(11,2,7,minecraft:nether_wart_block)
B(12,2,7,minecraft:nether_wart_block)
B(13,2,7,minecraft:nether_wart_block)
B(14,2,7,minecraft:nether_wart_block)
B(15,2,7,minecraft:nether_wart_block)
B(10,2,8,minecraft:nether_wart_block)
B(11,2,8,minecraft:nether_wart_block)
B(12,2,8,minecraft:nether_wart_block)
B(13,2,8,minecraft:nether_wart_block)
B(14,2,8,minecraft:nether_wart_block)
B(15,2,8,minecraft:nether_wart_block)
B(11,2,9,minecraft:nether_wart_block)
B(12,2,9,minecraft:nether_wart_block)
B(13,2,9,minecraft:nether_wart_block)
B(14,2,9,minecraft:nether_wart_block)
B(15,2,9,minecraft:nether_wart_block)
B(11,2,10,minecraft:nether_wart_block)
B(12,2,10,minecraft:nether_wart_block)
B(13,2,10,minecraft:nether_wart_block)
B(14,2,10,minecraft:nether_wart_block)
B(15,2,10,minecraft:nether_wart_block)
B(10,2,11,minecraft:nether_wart_block)
B(11,2,11,minecraft:nether_wart_block)
B(12,2,11,minecraft:nether_wart_block)
B(13,2,11,minecraft:nether_wart_block)
B(14,2,11,minecraft:nether_wart_block)
B(15,2,11,minecraft:nether_wart_block)
B(11,2,12,minecraft:nether_wart_block)
B(12,2,12,minecraft:nether_wart_block)
B(13,2,12,minecraft:nether_wart_block)
B(14,2,12,minecraft:nether_wart_block)
B(15,2,12,minecraft:nether_wart_block)
B(10,2,13,minecraft:nether_wart_block)
B(11,2,13,minecraft:nether_wart_block)
B(12,2,13,minecraft:nether_wart_block)
B(13,2,13,minecraft:nether_wart_block)
B(14,2,13,minecraft:nether_wart_block)
B(15,2,13,minecraft:nether_wart_block)
B(10,2,14,minecraft:nether_wart_block)
B(11,2,14,minecraft:nether_wart_block)
B(12,2,14,minecraft:nether_wart_block)
B(13,2,14,minecraft:nether_wart_block)
B(14,2,14,minecraft:nether_wart_block)
B(15,2,14,minecraft:nether_wart_block)
B(10,2,15,minecraft:nether_wart_block)
B(11,2,15,minecraft:nether_wart_block)
B(12,2,15,minecraft:nether_wart_block)
B(13,2,15,minecraft:nether_wart_block)
B(14,2,15,minecraft:nether_wart_block)
B(15,2,15,minecraft:nether_wart_block)
B(9,3,0,minecraft:nether_wart_block)
B(10,3,0,minecraft:nether_wart_block)
B(11,3,0,minecraft:nether_wart_block)
B(12,3,0,minecraft:nether_wart_block)
B(13,3,0,minecraft:nether_wart_block)
B(14,3,0,minecraft:nether_wart_block)
B(15,3,0,minecraft:nether_wart_block)
B(9,3,1,minecraft:nether_wart_block)
B(10,3,1,minecraft:nether_wart_block)
B(11,3,1,minecraft:nether_wart_block)
B(12,3,1,minecraft:nether_wart_block)
B(13,3,1,minecraft:nether_wart_block)
B(14,3,1,minecraft:nether_wart_block)
B(15,3,1,minecraft:nether_wart_block)
B(9,3,2,minecraft:nether_wart_block)
B(10,3,2,minecraft:nether_wart_block)
B(11,3,2,minecraft:nether_wart_block)
B(12,3,2,minecraft:nether_wart_block)
B(13,3,2,minecraft:nether_wart_block)
B(14,3,2,minecraft:nether_wart_block)
B(15,3,2,minecraft:nether_wart_block)
B(9,3,3,minecraft:nether_wart_block)
B(10,3,3,minecraft:nether_wart_block)
B(11,3,3,minecraft:nether_wart_block)
B(12,3,3,minecraft:nether_wart_block)
B(13,3,3,minecraft:nether_wart_block)
B(14,3,3,minecraft:nether_wart_block)
B(15,3,3,minecraft:nether_wart_block)
B(9,3,4,minecraft:nether_wart_block)
B(10,3,4,minecraft:nether_wart_block)
B(11,3,4,minecraft:nether_wart_block)
B(12,3,4,minecraft:nether_wart_block)
B(13,3,4,minecraft:nether_wart_block)
B(14,3,4,minecraft:nether_wart_block)
B(15,3,4,minecraft:nether_wart_block)
B(9,3,5,minecraft:nether_wart_block)
B(10,3,5,minecraft:nether_wart_block)
B(11,3,5,minecraft:nether_wart_block)
B(12,3,5,minecraft:nether_wart_block)
B(13,3,5,minecraft:nether_wart_block)
B(14,3,5,minecraft:nether_wart_block)
B(15,3,5,minecraft:nether_wart_block)
B(9,3,6,minecraft:nether_wart_block)
B(10,3,6,minecraft:nether_wart_block)
B(11,3,6,minecraft:nether_wart_block)
B(12,3,6,minecraft:nether_wart_block)
B(13,3,6,minecraft:nether_wart_block)
B(14,3,6,minecraft:nether_wart_block)
B(15,3,6,minecraft:nether_wart_block)
B(9,3,7,minecraft:nether_wart_block)
B(10,3,7,minecraft:nether_wart_block)
B(11,3,7,minecraft:nether_wart_block)
B(12,3,7,minecraft:nether_wart_block)
B(13,3,7,minecraft:nether_wart_block)
B(14,3,7,minecraft:nether_wart_block)
B(15,3,7,minecraft:nether_wart_block)
B(10,3,8,minecraft:nether_wart_block)
B(11,3,8,minecraft:nether_wart_block)
B(12,3,8,minecraft:nether_wart_block)
B(13,3,8,minecraft:nether_wart_block)
B(14,3,8,minecraft:nether_wart_block)
B(15,3,8,minecraft:nether_wart_block)
B(11,3,9,minecraft:nether_wart_block)
B(12,3,9,minecraft:nether_wart_block)
B(13,3,9,minecraft:nether_wart_block)
B(14,3,9,minecraft:nether_wart_block)
B(15,3,9,minecraft:nether_wart_block)
B(11,3,10,minecraft:nether_wart_block)
B(12,3,10,minecraft:nether_wart_block)
B(13,3,10,minecraft:nether_wart_block)
B(14,3,10,minecraft:nether_wart_block)
B(15,3,10,minecraft:nether_wart_block)
B(10,3,11,minecraft:nether_wart_block)
B(11,3,11,minecraft:nether_wart_block)
B(12,3,11,minecraft:nether_wart_block)
B(13,3,11,minecraft:nether_wart_block)
B(14,3,11,minecraft:nether_wart_block)
B(15,3,11,minecraft:nether_wart_block)
B(11,3,12,minecraft:nether_wart_block)
B(12,3,12,minecraft:nether_wart_block)
B(13,3,12,minecraft:nether_wart_block)
B(14,3,12,minecraft:nether_wart_block)
B(15,3,12,minecraft:nether_wart_block)
B(10,3,13,minecraft:nether_wart_block)
B(11,3,13,minecraft:nether_wart_block)
B(12,3,13,minecraft:nether_wart_block)
B(13,3,13,minecraft:nether_wart_block)
B(14,3,13,minecraft:nether_wart_block)
B(15,3,13,minecraft:nether_wart_block)
B(10,3,14,minecraft:nether_wart_block)
B(11,3,14,minecraft:nether_wart_block)
B(12,3,14,minecraft:nether_wart_block)
B(13,3,14,minecraft:nether_wart_block)
B(14,3,14,minecraft:nether_wart_block)
B(15,3,14,minecraft:nether_wart_block)
B(10,3,15,minecraft:nether_wart_block)
B(11,3,15,minecraft:nether_wart_block)
B(12,3,15,minecraft:nether_wart_block)
B(13,3,15,minecraft:nether_wart_block)
B(14,3,15,minecraft:nether_wart_block)
B(15,3,15,minecraft:nether_wart_block)
B(9,4,0,minecraft:nether_wart_block)
B(10,4,0,minecraft:nether_wart_block)
B(11,4,0,minecraft:nether_wart_block)
B(12,4,0,minecraft:nether_wart_block)
B(13,4,0,minecraft:nether_wart_block)
B(14,4,0,minecraft:nether_wart_block)
B(15,4,0,minecraft:nether_wart_block)
B(9,4,1,minecraft:nether_wart_block)
B(10,4,1,minecraft:nether_wart_block)
B(11,4,1,minecraft:nether_wart_block)
B(12,4,1,minecraft:nether_wart_block)
B(13,4,1,minecraft:nether_wart_block)
B(14,4,1,minecraft:nether_wart_block)
B(15,4,1,minecraft:nether_wart_block)
B(9,4,2,minecraft:nether_wart_block)
B(10,4,2,minecraft:nether_wart_block)
B(11,4,2,minecraft:nether_wart_block)
B(12,4,2,minecraft:nether_wart_block)
B(13,4,2,minecraft:nether_wart_block)
B(14,4,2,minecraft:nether_wart_block)
B(15,4,2,minecraft:nether_wart_block)
B(9,4,3,minecraft:nether_wart_block)
B(10,4,3,minecraft:nether_wart_block)
B(11,4,3,minecraft:nether_wart_block)
B(12,4,3,minecraft:nether_wart_block)
B(13,4,3,minecraft:nether_wart_block)
B(14,4,3,minecraft:nether_wart_block)
B(15,4,3,minecraft:nether_wart_block)
B(9,4,4,minecraft:nether_wart_block)
B(10,4,4,minecraft:nether_wart_block)
B(11,4,4,minecraft:nether_wart_block)
B(12,4,4,minecraft:nether_wart_block)
B(13,4,4,minecraft:nether_wart_block)
B(14,4,4,minecraft:nether_wart_block)
B(15,4,4,minecraft:nether_wart_block)
B(9,4,5,minecraft:nether_wart_block)
B(10,4,5,minecraft:nether_wart_block)
B(11,4,5,minecraft:nether_wart_block)
B(12,4,5,minecraft:nether_wart_block)
B(13,4,5,minecraft:nether_wart_block)
B(14,4,5,minecraft:nether_wart_block)
B(15,4,5,minecraft:nether_wart_block)
B(9,4,6,minecraft:nether_wart_block)
B(10,4,6,minecraft:nether_wart_block)
B(11,4,6,minecraft:nether_wart_block)
B(12,4,6,minecraft:nether_wart_block)
B(13,4,6,minecraft:nether_wart_block)
B(14,4,6,minecraft:nether_wart_block)
B(15,4,6,minecraft:nether_wart_block)
B(9,4,7,minecraft:nether_wart_block)
B(10,4,7,minecraft:nether_wart_block)
B(11,4,7,minecraft:nether_wart_block)
B(12,4,7,minecraft:nether_wart_block)
B(13,4,7,minecraft:nether_wart_block)
B(14,4,7,minecraft:nether_wart_block)
B(15,4,7,minecraft:nether_wart_block)
B(10,4,8,minecraft:nether_wart_block)
B(11,4,8,minecraft:nether_wart_block)
B(12,4,8,minecraft:nether_wart_block)
B(13,4,8,minecraft:nether_wart_block)
B(14,4,8,minecraft:nether_wart_block)
B(15,4,8,minecraft:nether_wart_block)
B(11,4,9,minecraft:nether_wart_block)
B(12,4,9,minecraft:nether_wart_block)
B(13,4,9,minecraft:nether_wart_block)
B(14,4,9,minecraft:nether_wart_block)
B(15,4,9,minecraft:nether_wart_block)
B(11,4,10,minecraft:nether_wart_block)
B(12,4,10,minecraft:nether_wart_block)
B(13,4,10,minecraft:nether_wart_block)
B(14,4,10,minecraft:nether_wart_block)
B(15,4,10,minecraft:nether_wart_block)
B(10,4,11,minecraft:nether_wart_block)
B(11,4,11,minecraft:nether_wart_block)
B(12,4,11,minecraft:nether_wart_block)
B(13,4,11,minecraft:nether_wart_block)
B(14,4,11,minecraft:nether_wart_block)
B(15,4,11,minecraft:nether_wart_block)
B(11,4,12,minecraft:nether_wart_block)
B(12,4,12,minecraft:nether_wart_block)
B(13,4,12,minecraft:nether_wart_block)
B(14,4,12,minecraft:nether_wart_block)
B(15,4,12,minecraft:nether_wart_block)
B(10,4,13,minecraft:nether_wart_block)
B(11,4,13,minecraft:nether_wart_block)
B(12,4,13,minecraft:nether_wart_block)
B(13,4,13,minecraft:nether_wart_block)
B(14,4,13,minecraft:nether_wart_block)
B(15,4,13,minecraft:nether_wart_block)
B(10,4,14,minecraft:nether_wart_block)
B(11,4,14,minecraft:nether_wart_block)
B(12,4,14,minecraft:nether_wart_block)
B(13,4,14,minecraft:nether_wart_block)
B(14,4,14,minecraft:nether_wart_block)
B(15,4,14,minecraft:nether_wart_block)
B(10,4,15,minecraft:nether_wart_block)
B(11,4,15,minecraft:nether_wart_block)
B(12,4,15,minecraft:nether_wart_block)
B(13,4,15,minecraft:nether_wart_block)
B(14,4,15,minecraft:nether_wart_block)
B(15,4,15,minecraft:nether_wart_block)
B(9,5,0,minecraft:nether_wart_block)
B(10,5,0,minecraft:nether_wart_block)
B(11,5,0,minecraft:nether_wart_block)
B(12,5,0,minecraft:nether_wart_block)
B(13,5,0,minecraft:nether_wart_block)
B(14,5,0,minecraft:nether_wart_block)
B(15,5,0,minecraft:nether_wart_block)
B(9,5,1,minecraft:nether_wart_block)
B(10,5,1,minecraft:nether_wart_block)
B(11,5,1,minecraft:nether_wart_block)
B(12,5,1,minecraft:nether_wart_block)
B(13,5,1,minecraft:nether_wart_block)
B(14,5,1,minecraft:nether_wart_block)
B(15,5,1,minecraft:nether_wart_block)
B(9,5,2,minecraft:nether_wart_block)
B(10,5,2,minecraft:nether_wart_block)
B(11,5,2,minecraft:nether_wart_block)
B(12,5,2,minecraft:nether_wart_block)
B(13,5,2,minecraft:nether_wart_block)
B(14,5,2,minecraft:nether_wart_block)
B(15,5,2,minecraft:nether_wart_block)
B(9,5,3,minecraft:nether_wart_block)
B(10,5,3,minecraft:nether_wart_block)
B(11,5,3,minecraft:nether_wart_block)
B(12,5,3,minecraft:nether_wart_block)
B(13,5,3,minecraft:nether_wart_block)
B(14,5,3,minecraft:nether_wart_block)
B(15,5,3,minecraft:nether_wart_block)
B(9,5,4,minecraft:nether_wart_block)
B(10,5,4,minecraft:nether_wart_block)
B(11,5,4,minecraft:nether_wart_block)
B(12,5,4,minecraft:nether_wart_block)
B(13,5,4,minecraft:nether_wart_block)
B(14,5,4,minecraft:nether_wart_block)
B(15,5,4,minecraft:nether_wart_block)
B(9,5,5,minecraft:nether_wart_block)
B(10,5,5,minecraft:nether_wart_block)
B(11,5,5,minecraft:nether_wart_block)
B(12,5,5,minecraft:nether_wart_block)
B(13,5,5,minecraft:nether_wart_block)
B(14,5,5,minecraft:nether_wart_block)
B(15,5,5,minecraft:nether_wart_block)
B(9,5,6,minecraft:nether_wart_block)
B(10,5,6,minecraft:nether_wart_block)
B(11,5,6,minecraft:nether_wart_block)
B(12,5,6,minecraft:nether_wart_block)
B(13,5,6,minecraft:nether_wart_block)
B(14,5,6,minecraft:nether_wart_block)
B(15,5,6,minecraft:nether_wart_block)
B(9,5,7,minecraft:nether_wart_block)
B(10,5,7,minecraft:nether_wart_block)
B(11,5,7,minecraft:nether_wart_block)
B(12,5,7,minecraft:nether_wart_block)
B(13,5,7,minecraft:nether_wart_block)
B(14,5,7,minecraft:nether_wart_block)
B(15,5,7,minecraft:nether_wart_block)
B(10,5,8,minecraft:nether_wart_block)
B(11,5,8,minecraft:nether_wart_block)
B(12,5,8,minecraft:nether_wart_block)
B(13,5,8,minecraft:nether_wart_block)
B(14,5,8,minecraft:nether_wart_block)
B(15,5,8,minecraft:nether_wart_block)
B(11,5,9,minecraft:nether_wart_block)
B(12,5,9,minecraft:nether_wart_block)
B(13,5,9,minecraft:nether_wart_block)
B(14,5,9,minecraft:nether_wart_block)
B(15,5,9,minecraft:nether_wart_block)
B(11,5,10,minecraft:nether_wart_block)
B(12,5,10,minecraft:nether_wart_block)
B(13,5,10,minecraft:nether_wart_block)
B(14,5,10,minecraft:nether_wart_block)
B(15,5,10,minecraft:nether_wart_block)
B(10,5,11,minecraft:nether_wart_block)
B(11,5,11,minecraft:nether_wart_block)
B(12,5,11,minecraft:nether_wart_block)
B(13,5,11,minecraft:nether_wart_block)
B(14,5,11,minecraft:nether_wart_block)
B(15,5,11,minecraft:nether_wart_block)
B(11,5,12,minecraft:nether_wart_block)
B(12,5,12,minecraft:nether_wart_block)
B(13,5,12,minecraft:nether_wart_block)
B(14,5,12,minecraft:nether_wart_block)
B(15,5,12,minecraft:nether_wart_block)
B(10,5,13,minecraft:nether_wart_block)
B(11,5,13,minecraft:nether_wart_block)
B(12,5,13,minecraft:nether_wart_block)
B(13,5,13,minecraft:nether_wart_block)
B(14,5,13,minecraft:nether_wart_block)
B(15,5,13,minecraft:nether_wart_block)
B(10,5,14,minecraft:nether_wart_block)
B(11,5,14,minecraft:nether_wart_block)
B(12,5,14,minecraft:nether_wart_block)
B(13,5,14,minecraft:nether_wart_block)
B(14,5,14,minecraft:nether_wart_block)
B(15,5,14,minecraft:nether_wart_block)
B(10,5,15,minecraft:nether_wart_block)
B(11,5,15,minecraft:nether_wart_block)
B(12,5,15,minecraft:nether_wart_block)
B(13,5,15,minecraft:nether_wart_block)
B(14,5,15,minecraft:nether_wart_block)
B(15,5,15,minecraft:nether_wart_block)
B(9,6,0,minecraft:nether_wart_block)
B(10,6,0,minecraft:nether_wart_block)
B(11,6,0,minecraft:nether_wart_block)
B(12,6,0,minecraft:nether_wart_block)
B(13,6,0,minecraft:nether_wart_block)
B(14,6,0,minecraft:nether_wart_block)
B(15,6,0,minecraft:nether_wart_block)
B(9,6,1,minecraft:nether_wart_block)
B(10,6,1,minecraft:nether_wart_block)
B(11,6,1,minecraft:nether_wart_block)
B(12,6,1,minecraft:nether_wart_block)
B(13,6,1,minecraft:nether_wart_block)
B(14,6,1,minecraft:nether_wart_block)
B(15,6,1,minecraft:nether_wart_block)
B(9,6,2,minecraft:nether_wart_block)
B(10,6,2,minecraft:nether_wart_block)
B(11,6,2,minecraft:nether_wart_block)
B(12,6,2,minecraft:nether_wart_block)
B(13,6,2,minecraft:nether_wart_block)
B(14,6,2,minecraft:nether_wart_block)
B(15,6,2,minecraft:nether_wart_block)
B(9,6,3,minecraft:nether_wart_block)
B(10,6,3,minecraft:nether_wart_block)
B(11,6,3,minecraft:nether_wart_block)
B(12,6,3,minecraft:nether_wart_block)
B(13,6,3,minecraft:nether_wart_block)
B(14,6,3,minecraft:nether_wart_block)
B(15,6,3,minecraft:nether_wart_block)
B(9,6,4,minecraft:nether_wart_block)
B(10,6,4,minecraft:nether_wart_block)
B(11,6,4,minecraft:nether_wart_block)
B(12,6,4,minecraft:nether_wart_block)
B(13,6,4,minecraft:nether_wart_block)
B(14,6,4,minecraft:nether_wart_block)
B(15,6,4,minecraft:nether_wart_block)
B(9,6,5,minecraft:nether_wart_block)
B(10,6,5,minecraft:nether_wart_block)
B(11,6,5,minecraft:nether_wart_block)
B(12,6,5,minecraft:nether_wart_block)
B(13,6,5,minecraft:nether_wart_block)
B(14,6,5,minecraft:nether_wart_block)
B(15,6,5,minecraft:nether_wart_block)
B(9,6,6,minecraft:nether_wart_block)
B(10,6,6,minecraft:nether_wart_block)
B(11,6,6,minecraft:nether_wart_block)
B(12,6,6,minecraft:nether_wart_block)
B(13,6,6,minecraft:nether_wart_block)
B(14,6,6,minecraft:nether_wart_block)
B(15,6,6,minecraft:nether_wart_block)
B(9,6,7,minecraft:nether_wart_block)
B(10,6,7,minecraft:nether_wart_block)
B(11,6,7,minecraft:nether_wart_block)
B(12,6,7,minecraft:nether_wart_block)
B(13,6,7,minecraft:nether_wart_block)
B(14,6,7,minecraft:nether_wart_block)
B(15,6,7,minecraft:nether_wart_block)
B(10,6,8,minecraft:nether_wart_block)
B(11,6,8,minecraft:nether_wart_block)
B(12,6,8,minecraft:nether_wart_block)
B(13,6,8,minecraft:nether_wart_block)
B(14,6,8,minecraft:nether_wart_block)
B(15,6,8,minecraft:nether_wart_block)
B(11,6,9,minecraft:nether_wart_block)
B(12,6,9,minecraft:nether_wart_block)
B(13,6,9,minecraft:nether_wart_block)
B(14,6,9,minecraft:nether_wart_block)
B(15,6,9,minecraft:nether_wart_block)
B(11,6,10,minecraft:nether_wart_block)
B(12,6,10,minecraft:nether_wart_block)
B(13,6,10,minecraft:nether_wart_block)
B(14,6,10,minecraft:nether_wart_block)
B(15,6,10,minecraft:nether_wart_block)
B(10,6,11,minecraft:nether_wart_block)
B(11,6,11,minecraft:nether_wart_block)
B(12,6,11,minecraft:nether_wart_block)
B(13,6,11,minecraft:nether_wart_block)
B(14,6,11,minecraft:nether_wart_block)
B(15,6,11,minecraft:nether_wart_block)
B(11,6,12,minecraft:nether_wart_block)
B(12,6,12,minecraft:nether_wart_block)
B(13,6,12,minecraft:nether_wart_block)
B(14,6,12,minecraft:nether_wart_block)
B(15,6,12,minecraft:nether_wart_block)
B(10,6,13,minecraft:nether_wart_block)
B(11,6,13,minecraft:nether_wart_block)
B(12,6,13,minecraft:nether_wart_block)
B(13,6,13,minecraft:nether_wart_block)
B(14,6,13,minecraft:nether_wart_block)
B(15,6,13,minecraft:nether_wart_block)
B(10,6,14,minecraft:nether_wart_block)
B(11,6,14,minecraft:nether_wart_block)
B(12,6,14,minecraft:nether_wart_block)
B(13,6,14,minecraft:nether_wart_block)
B(14,6,14,minecraft:nether_wart_block)
B(15,6,14,minecraft:nether_wart_block)
B(10,6,15,minecraft:nether_wart_block)
B(11,6,15,minecraft:nether_wart_block)
B(12,6,15,minecraft:nether_wart_block)
B(13,6,15,minecraft:nether_wart_block)
B(14,6,15,minecraft:nether_wart_block)
B(15,6,15,minecraft:nether_wart_block)
B(9,7,0,minecraft:nether_wart_block)
B(10,7,0,minecraft:nether_wart_block)
B(11,7,0,minecraft:nether_wart_block)
B(12,7,0,minecraft:nether_wart_block)
B(13,7,0,minecraft:nether_wart_block)
B(14,7,0,minecraft:nether_wart_block)
B(15,7,0,minecraft:nether_wart_block)
B(9,7,1,minecraft:nether_wart_block)
B(10,7,1,minecraft:nether_wart_block)
B(11,7,1,minecraft:nether_wart_block)
B(12,7,1,minecraft:nether_wart_block)
B(13,7,1,minecraft:nether_wart_block)
B(14,7,1,minecraft:nether_wart_block)
B(15,7,1,minecraft:nether_wart_block)
B(9,7,2,minecraft:nether_wart_block)
B(10,7,2,minecraft:nether_wart_block)
B(11,7,2,minecraft:nether_wart_block)
B(12,7,2,minecraft:nether_wart_block)
B(13,7,2,minecraft:nether_wart_block)
B(14,7,2,minecraft:nether_wart_block)
B(15,7,2,minecraft:nether_wart_block)
B(9,7,3,minecraft:nether_wart_block)
B(10,7,3,minecraft:nether_wart_block)
B(11,7,3,minecraft:nether_wart_block)
B(12,7,3,minecraft:nether_wart_block)
B(13,7,3,minecraft:nether_wart_block)
B(14,7,3,minecraft:nether_wart_block)
B(15,7,3,minecraft:nether_wart_block)
B(9,7,4,minecraft:nether_wart_block)
B(10,7,4,minecraft:nether_wart_block)
B(11,7,4,minecraft:nether_wart_block)
B(12,7,4,minecraft:nether_wart_block)
B(13,7,4,minecraft:nether_wart_block)
B(14,7,4,minecraft:nether_wart_block)
B(15,7,4,minecraft:nether_wart_block)
B(9,7,5,minecraft:nether_wart_block)
B(10,7,5,minecraft:nether_wart_block)
B(11,7,5,minecraft:nether_wart_block)
B(12,7,5,minecraft:nether_wart_block)
B(13,7,5,minecraft:nether_wart_block)
B(14,7,5,minecraft:nether_wart_block)
B(15,7,5,minecraft:nether_wart_block)
B(9,7,6,minecraft:nether_wart_block)
B(10,7,6,minecraft:nether_wart_block)
B(11,7,6,minecraft:nether_wart_block)
B(12,7,6,minecraft:nether_wart_block)
B(13,7,6,minecraft:nether_wart_block)
B(14,7,6,minecraft:nether_wart_block)
B(15,7,6,minecraft:nether_wart_block)
B(9,7,7,minecraft:nether_wart_block)
B(10,7,7,minecraft:nether_wart_block)
B(11,7,7,minecraft:nether_wart_block)
B(12,7,7,minecraft:nether_wart_block)
B(13,7,7,minecraft:nether_wart_block)
B(14,7,7,minecraft:nether_wart_block)
B(15,7,7,minecraft:nether_wart_block)
B(10,7,8,minecraft:nether_wart_block)
B(11,7,8,minecraft:nether_wart_block)
B(12,7,8,minecraft:nether_wart_block)
B(13,7,8,minecraft:nether_wart_block)
B(14,7,8,minecraft:nether_wart_block)
B(15,7,8,minecraft:nether_wart_block)
B(11,7,9,minecraft:nether_wart_block)
B(12,7,9,minecraft:nether_wart_block)
B(13,7,9,minecraft:nether_wart_block)
B(14,7,9,minecraft:nether_wart_block)
B(15,7,9,minecraft:nether_wart_block)
B(11,7,10,minecraft:nether_wart_block)
B(12,7,10,minecraft:nether_wart_block)
B(13,7,10,minecraft:nether_wart_block)
B(14,7,10,minecraft:nether_wart_block)
B(15,7,10,minecraft:nether_wart_block)
B(10,7,11,minecraft:nether_wart_block)
B(11,7,11,minecraft:nether_wart_block)
B(12,7,11,minecraft:nether_wart_block)
B(13,7,11,minecraft:nether_wart_block)
B(14,7,11,minecraft:nether_wart_block)
B(15,7,11,minecraft:nether_wart_block)
B(11,7,12,minecraft:nether_wart_block)
B(12,7,12,minecraft:nether_wart_block)
B(13,7,12,minecraft:nether_wart_block)
B(14,7,12,minecraft:nether_wart_block)
B(15,7,12,minecraft:nether_wart_block)
B(10,7,13,minecraft:nether_wart_block)
B(11,7,13,minecraft:nether_wart_block)
B(12,7,13,minecraft:nether_wart_block)
B(13,7,13,minecraft:nether_wart_block)
B(14,7,13,minecraft:nether_wart_block)
B(15,7,13,minecraft:nether_wart_block)
B(10,7,14,minecraft:nether_wart_block)
B(11,7,14,minecraft:nether_wart_block)
B(12,7,14,minecraft:nether_wart_block)
B(13,7,14,minecraft:nether_wart_block)
B(14,7,14,minecraft:nether_wart_block)
B(15,7,14,minecraft:nether_wart_block)
B(10,7,15,minecraft:nether_wart_block)
B(11,7,15,minecraft:nether_wart_block)
B(12,7,15,minecraft:nether_wart_block)
B(13,7,15,minecraft:nether_wart_block)
B(14,7,15,minecraft:nether_wart_block)
B(15,7,15,minecraft:nether_wart_block)
B(9,8,0,minecraft:nether_wart_block)
B(10,8,0,minecraft:nether_wart_block)
B(11,8,0,minecraft:nether_wart_block)
B(12,8,0,minecraft:nether_wart_block)
B(13,8,0,minecraft:nether_wart_block)
B(14,8,0,minecraft:nether_wart_block)
B(15,8,0,minecraft:nether_wart_block)
B(9,8,1,minecraft:nether_wart_block)
B(10,8,1,minecraft:nether_wart_block)
B(11,8,1,minecraft:nether_wart_block)
B(12,8,1,minecraft:nether_wart_block)
B(13,8,1,minecraft:nether_wart_block)
B(14,8,1,minecraft:nether_wart_block)
B(15,8,1,minecraft:nether_wart_block)
B(9,8,2,minecraft:nether_wart_block)
B(10,8,2,minecraft:nether_wart_block)
B(11,8,2,minecraft:nether_wart_block)
B(12,8,2,minecraft:nether_wart_block)
B(13,8,2,minecraft:nether_wart_block)
B(14,8,2,minecraft:nether_wart_block)
B(15,8,2,minecraft:nether_wart_block)
B(9,8,3,minecraft:nether_wart_block)
B(10,8,3,minecraft:nether_wart_block)
B(11,8,3,minecraft:nether_wart_block)
B(12,8,3,minecraft:nether_wart_block)
B(13,8,3,minecraft:nether_wart_block)
B(14,8,3,minecraft:nether_wart_block)
B(15,8,3,minecraft:nether_wart_block)
B(9,8,4,minecraft:nether_wart_block)
B(10,8,4,minecraft:nether_wart_block)
B(11,8,4,minecraft:nether_wart_block)
B(12,8,4,minecraft:nether_wart_block)
B(13,8,4,minecraft:nether_wart_block)
B(14,8,4,minecraft:nether_wart_block)
B(15,8,4,minecraft:nether_wart_block)
B(9,8,5,minecraft:nether_wart_block)
B(10,8,5,minecraft:nether_wart_block)
B(11,8,5,minecraft:nether_wart_block)
B(12,8,5,minecraft:nether_wart_block)
B(13,8,5,minecraft:nether_wart_block)
B(14,8,5,minecraft:nether_wart_block)
B(15,8,5,minecraft:nether_wart_block)
B(9,8,6,minecraft:nether_wart_block)
B(10,8,6,minecraft:nether_wart_block)
B(11,8,6,minecraft:nether_wart_block)
B(12,8,6,minecraft:nether_wart_block)
B(13,8,6,minecraft:nether_wart_block)
B(14,8,6,minecraft:nether_wart_block)
B(15,8,6,minecraft:nether_wart_block)
B(9,8,7,minecraft:nether_wart_block)
B(10,8,7,minecraft:nether_wart_block)
B(11,8,7,minecraft:nether_wart_block)
B(12,8,7,minecraft:nether_wart_block)
B(13,8,7,minecraft:nether_wart_block)
B(14,8,7,minecraft:nether_wart_block)
B(15,8,7,minecraft:nether_wart_block)
B(10,8,8,minecraft:nether_wart_block)
B(11,8,8,minecraft:nether_wart_block)
B(12,8,8,minecraft:nether_wart_block)
B(13,8,8,minecraft:nether_wart_block)
B(14,8,8,minecraft:nether_wart_block)
B(15,8,8,minecraft:nether_wart_block)
B(11,8,9,minecraft:nether_wart_block)
B(12,8,9,minecraft:nether_wart_block)
B(13,8,9,minecraft:nether_wart_block)
B(14,8,9,minecraft:nether_wart_block)
B(15,8,9,minecraft:nether_wart_block)
B(11,8,10,minecraft:nether_wart_block)
B(12,8,10,minecraft:nether_wart_block)
B(13,8,10,minecraft:nether_wart_block)
B(14,8,10,minecraft:nether_wart_block)
B(15,8,10,minecraft:nether_wart_block)
B(11,8,11,minecraft:nether_wart_block)
B(12,8,11,minecraft:nether_wart_block)
B(13,8,11,minecraft:nether_wart_block)
B(14,8,11,minecraft:nether_wart_block)
B(15,8,11,minecraft:nether_wart_block)
B(11,8,12,minecraft:nether_wart_block)
B(12,8,12,minecraft:nether_wart_block)
B(13,8,12,minecraft:nether_wart_block)
B(14,8,12,minecraft:nether_wart_block)
B(15,8,12,minecraft:nether_wart_block)
B(10,8,13,minecraft:nether_wart_block)
B(11,8,13,minecraft:nether_wart_block)
B(12,8,13,minecraft:nether_wart_block)
B(13,8,13,minecraft:nether_wart_block)
B(14,8,13,minecraft:nether_wart_block)
B(15,8,13,minecraft:nether_wart_block)
B(10,8,14,minecraft:nether_wart_block)
B(11,8,14,minecraft:nether_wart_block)
B(12,8,14,minecraft:nether_wart_block)
B(13,8,14,minecraft:nether_wart_block)
B(14,8,14,minecraft:nether_wart_block)
B(15,8,14,minecraft:nether_wart_block)
B(10,8,15,minecraft:nether_wart_block)
B(11,8,15,minecraft:nether_wart_block)
B(12,8,15,minecraft:nether_wart_block)
B(13,8,15,minecraft:nether_wart_block)
B(14,8,15,minecraft:nether_wart_block)
B(15,8,15,minecraft:nether_wart_block)
B(9,9,0,minecraft:nether_wart_block)
B(10,9,0,minecraft:nether_wart_block)
B(11,9,0,minecraft:nether_wart_block)
B(12,9,0,minecraft:nether_wart_block)
B(13,9,0,minecraft:nether_wart_block)
B(14,9,0,minecraft:nether_wart_block)
B(15,9,0,minecraft:nether_wart_block)
B(9,9,1,minecraft:nether_wart_block)
B(10,9,1,minecraft:nether_wart_block)
B(11,9,1,minecraft:nether_wart_block)
B(12,9,1,minecraft:nether_wart_block)
B(13,9,1,minecraft:nether_wart_block)
B(14,9,1,minecraft:nether_wart_block)
B(15,9,1,minecraft:nether_wart_block)
B(9,9,2,minecraft:nether_wart_block)
B(10,9,2,minecraft:nether_wart_block)
B(11,9,2,minecraft:nether_wart_block)
B(12,9,2,minecraft:nether_wart_block)
B(13,9,2,minecraft:nether_wart_block)
B(14,9,2,minecraft:nether_wart_block)
B(15,9,2,minecraft:nether_wart_block)
B(9,9,3,minecraft:nether_wart_block)
B(10,9,3,minecraft:nether_wart_block)
B(11,9,3,minecraft:nether_wart_block)
B(12,9,3,minecraft:nether_wart_block)
B(13,9,3,minecraft:nether_wart_block)
B(14,9,3,minecraft:nether_wart_block)
B(15,9,3,minecraft:nether_wart_block)
B(9,9,4,minecraft:nether_wart_block)
B(10,9,4,minecraft:nether_wart_block)
B(11,9,4,minecraft:nether_wart_block)
B(12,9,4,minecraft:nether_wart_block)
B(13,9,4,minecraft:nether_wart_block)
B(14,9,4,minecraft:nether_wart_block)
B(15,9,4,minecraft:nether_wart_block)
B(9,9,5,minecraft:nether_wart_block)
B(10,9,5,minecraft:nether_wart_block)
B(11,9,5,minecraft:nether_wart_block)
B(12,9,5,minecraft:nether_wart_block)
B(13,9,5,minecraft:nether_wart_block)
B(14,9,5,minecraft:nether_wart_block)
B(15,9,5,minecraft:nether_wart_block)
B(9,9,6,minecraft:nether_wart_block)
B(10,9,6,minecraft:nether_wart_block)
B(11,9,6,minecraft:nether_wart_block)
B(12,9,6,minecraft:nether_wart_block)
B(13,9,6,minecraft:nether_wart_block)
B(14,9,6,minecraft:nether_wart_block)
B(15,9,6,minecraft:nether_wart_block)
B(9,9,7,minecraft:nether_wart_block)
B(10,9,7,minecraft:nether_wart_block)
B(11,9,7,minecraft:nether_wart_block)
B(12,9,7,minecraft:nether_wart_block)
B(13,9,7,minecraft:nether_wart_block)
B(14,9,7,minecraft:nether_wart_block)
B(15,9,7,minecraft:nether_wart_block)
B(10,9,8,minecraft:nether_wart_block)
B(11,9,8,minecraft:nether_wart_block)
B(12,9,8,minecraft:nether_wart_block)
B(13,9,8,minecraft:nether_wart_block)
B(14,9,8,minecraft:nether_wart_block)
B(15,9,8,minecraft:nether_wart_block)
B(11,9,9,minecraft:nether_wart_block)
B(12,9,9,minecraft:nether_wart_block)
B(13,9,9,minecraft:nether_wart_block)
B(14,9,9,minecraft:nether_wart_block)
B(15,9,9,minecraft:nether_wart_block)
B(11,9,10,minecraft:nether_wart_block)
B(12,9,10,minecraft:nether_wart_block)
B(13,9,10,minecraft:nether_wart_block)
B(14,9,10,minecraft:nether_wart_block)
B(15,9,10,minecraft:nether_wart_block)
B(11,9,11,minecraft:nether_wart_block)
B(12,9,11,minecraft:nether_wart_block)
B(13,9,11,minecraft:nether_wart_block)
B(14,9,11,minecraft:nether_wart_block)
B(15,9,11,minecraft:nether_wart_block)
B(11,9,12,minecraft:nether_wart_block)
B(12,9,12,minecraft:nether_wart_block)
B(13,9,12,minecraft:nether_wart_block)
B(14,9,12,minecraft:nether_wart_block)
B(15,9,12,minecraft:nether_wart_block)
B(10,9,13,minecraft:nether_wart_block)
B(11,9,13,minecraft:nether_wart_block)
B(12,9,13,minecraft:nether_wart_block)
B(13,9,13,minecraft:nether_wart_block)
B(14,9,13,minecraft:nether_wart_block)
B(15,9,13,minecraft:nether_wart_block)
B(10,9,14,minecraft:nether_wart_block)
B(11,9,14,minecraft:nether_wart_block)
B(12,9,14,minecraft:nether_wart_block)
B(13,9,14,minecraft:nether_wart_block)
B(14,9,14,minecraft:nether_wart_block)
B(15,9,14,minecraft:nether_wart_block)
B(10,9,15,minecraft:nether_wart_block)
B(11,9,15,minecraft:nether_wart_block)
B(12,9,15,minecraft:nether_wart_block)
B(13,9,15,minecraft:nether_wart_block)
B(14,9,15,minecraft:nether_wart_block)
B(15,9,15,minecraft:nether_wart_block)
B(9,10,0,minecraft:nether_wart_block)
B(10,10,0,minecraft:nether_wart_block)
B(11,10,0,minecraft:nether_wart_block)
B(12,10,0,minecraft:nether_wart_block)
B(13,10,0,minecraft:nether_wart_block)
B(14,10,0,minecraft:nether_wart_block)
B(15,10,0,minecraft:nether_wart_block)
B(9,10,1,minecraft:nether_wart_block)
B(10,10,1,minecraft:nether_wart_block)
B(11,10,1,minecraft:nether_wart_block)
B(12,10,1,minecraft:nether_wart_block)
B(13,10,1,minecraft:nether_wart_block)
B(14,10,1,minecraft:nether_wart_block)
B(15,10,1,minecraft:nether_wart_block)
B(9,10,2,minecraft:nether_wart_block)
B(10,10,2,minecraft:nether_wart_block)
B(11,10,2,minecraft:nether_wart_block)
B(12,10,2,minecraft:nether_wart_block)
B(13,10,2,minecraft:nether_wart_block)
B(14,10,2,minecraft:nether_wart_block)
B(15,10,2,minecraft:nether_wart_block)
B(9,10,3,minecraft:nether_wart_block)
B(10,10,3,minecraft:nether_wart_block)
B(11,10,3,minecraft:nether_wart_block)
B(12,10,3,minecraft:nether_wart_block)
B(13,10,3,minecraft:nether_wart_block)
B(14,10,3,minecraft:nether_wart_block)
B(15,10,3,minecraft:nether_wart_block)
B(9,10,4,minecraft:nether_wart_block)
B(10,10,4,minecraft:nether_wart_block)
B(11,10,4,minecraft:nether_wart_block)
B(12,10,4,minecraft:nether_wart_block)
B(13,10,4,minecraft:nether_wart_block)
B(14,10,4,minecraft:nether_wart_block)
B(15,10,4,minecraft:nether_wart_block)
B(9,10,5,minecraft:nether_wart_block)
B(10,10,5,minecraft:nether_wart_block)
B(11,10,5,minecraft:nether_wart_block)
B(12,10,5,minecraft:nether_wart_block)
B(13,10,5,minecraft:nether_wart_block)
B(14,10,5,minecraft:nether_wart_block)
B(15,10,5,minecraft:nether_wart_block)
B(9,10,6,minecraft:nether_wart_block)
B(10,10,6,minecraft:nether_wart_block)
B(11,10,6,minecraft:nether_wart_block)
B(12,10,6,minecraft:nether_wart_block)
B(13,10,6,minecraft:nether_wart_block)
B(14,10,6,minecraft:nether_wart_block)
B(15,10,6,minecraft:nether_wart_block)
B(9,10,7,minecraft:nether_wart_block)
B(10,10,7,minecraft:nether_wart_block)
B(11,10,7,minecraft:nether_wart_block)
B(12,10,7,minecraft:nether_wart_block)
B(13,10,7,minecraft:nether_wart_block)
B(14,10,7,minecraft:nether_wart_block)
B(15,10,7,minecraft:nether_wart_block)
B(10,10,8,minecraft:nether_wart_block)
B(11,10,8,minecraft:nether_wart_block)
B(12,10,8,minecraft:nether_wart_block)
B(13,10,8,minecraft:nether_wart_block)
B(14,10,8,minecraft:nether_wart_block)
B(15,10,8,minecraft:nether_wart_block)
B(11,10,9,minecraft:nether_wart_block)
B(12,10,9,minecraft:nether_wart_block)
B(13,10,9,minecraft:nether_wart_block)
B(14,10,9,minecraft:nether_wart_block)
B(15,10,9,minecraft:nether_wart_block)
B(11,10,10,minecraft:nether_wart_block)
B(12,10,10,minecraft:nether_wart_block)
B(13,10,10,minecraft:nether_wart_block)
B(14,10,10,minecraft:nether_wart_block)
B(15,10,10,minecraft:nether_wart_block)
B(11,10,11,minecraft:nether_wart_block)
B(12,10,11,minecraft:nether_wart_block)
B(13,10,11,minecraft:nether_wart_block)
B(14,10,11,minecraft:nether_wart_block)
B(15,10,11,minecraft:nether_wart_block)
B(11,10,12,minecraft:nether_wart_block)
B(12,10,12,minecraft:nether_wart_block)
B(13,10,12,minecraft:nether_wart_block)
B(14,10,12,minecraft:nether_wart_block)
B(15,10,12,minecraft:nether_wart_block)
B(10,10,13,minecraft:nether_wart_block)
B(11,10,13,minecraft:nether_wart_block)
B(12,10,13,minecraft:nether_wart_block)
B(13,10,13,minecraft:nether_wart_block)
B(14,10,13,minecraft:nether_wart_block)
B(15,10,13,minecraft:nether_wart_block)
B(10,10,14,minecraft:nether_wart_block)
B(11,10,14,minecraft:nether_wart_block)
B(12,10,14,minecraft:nether_wart_block)
B(13,10,14,minecraft:nether_wart_block)
B(14,10,14,minecraft:nether_wart_block)
B(15,10,14,minecraft:nether_wart_block)
B(10,10,15,minecraft:nether_wart_block)
B(11,10,15,minecraft:nether_wart_block)
B(12,10,15,minecraft:nether_wart_block)
B(13,10,15,minecraft:nether_wart_block)
B(14,10,15,minecraft:nether_wart_block)
B(15,10,15,minecraft:nether_wart_block)
B(9,11,0,minecraft:nether_wart_block)
B(10,11,0,minecraft:nether_wart_block)
B(11,11,0,minecraft:nether_wart_block)
B(12,11,0,minecraft:nether_wart_block)
B(13,11,0,minecraft:nether_wart_block)
B(14,11,0,minecraft:nether_wart_block)
B(15,11,0,minecraft:nether_wart_block)
B(9,11,1,minecraft:nether_wart_block)
B(10,11,1,minecraft:nether_wart_block)
B(11,11,1,minecraft:nether_wart_block)
B(12,11,1,minecraft:nether_wart_block)
B(13,11,1,minecraft:nether_wart_block)
B(14,11,1,minecraft:nether_wart_block)
B(15,11,1,minecraft:nether_wart_block)
B(9,11,2,minecraft:nether_wart_block)
B(10,11,2,minecraft:nether_wart_block)
B(11,11,2,minecraft:nether_wart_block)
B(12,11,2,minecraft:nether_wart_block)
B(13,11,2,minecraft:nether_wart_block)
B(14,11,2,minecraft:nether_wart_block)
B(15,11,2,minecraft:nether_wart_block)
B(9,11,3,minecraft:nether_wart_block)
B(10,11,3,minecraft:nether_wart_block)
B(11,11,3,minecraft:nether_wart_block)
B(12,11,3,minecraft:nether_wart_block)
B(13,11,3,minecraft:nether_wart_block)
B(14,11,3,minecraft:nether_wart_block)
B(15,11,3,minecraft:nether_wart_block)
B(9,11,4,minecraft:nether_wart_block)
B(10,11,4,minecraft:nether_wart_block)
B(11,11,4,minecraft:nether_wart_block)
B(12,11,4,minecraft:nether_wart_block)
B(13,11,4,minecraft:nether_wart_block)
B(14,11,4,minecraft:nether_wart_block)
B(15,11,4,minecraft:nether_wart_block)
B(9,11,5,minecraft:nether_wart_block)
B(10,11,5,minecraft:nether_wart_block)
B(11,11,5,minecraft:nether_wart_block)
B(12,11,5,minecraft:nether_wart_block)
B(13,11,5,minecraft:nether_wart_block)
B(14,11,5,minecraft:nether_wart_block)
B(15,11,5,minecraft:nether_wart_block)
B(9,11,6,minecraft:nether_wart_block)
B(10,11,6,minecraft:nether_wart_block)
B(11,11,6,minecraft:nether_wart_block)
B(12,11,6,minecraft:nether_wart_block)
B(13,11,6,minecraft:nether_wart_block)
B(14,11,6,minecraft:nether_wart_block)
B(15,11,6,minecraft:nether_wart_block)
B(9,11,7,minecraft:nether_wart_block)
B(10,11,7,minecraft:nether_wart_block)
B(11,11,7,minecraft:nether_wart_block)
B(12,11,7,minecraft:nether_wart_block)
B(13,11,7,minecraft:nether_wart_block)
B(14,11,7,minecraft:nether_wart_block)
B(15,11,7,minecraft:nether_wart_block)
B(10,11,8,minecraft:nether_wart_block)
B(11,11,8,minecraft:nether_wart_block)
B(12,11,8,minecraft:nether_wart_block)
B(13,11,8,minecraft:nether_wart_block)
B(14,11,8,minecraft:nether_wart_block)
B(15,11,8,minecraft:nether_wart_block)
B(11,11,9,minecraft:nether_wart_block)
B(12,11,9,minecraft:nether_wart_block)
B(13,11,9,minecraft:nether_wart_block)
B(14,11,9,minecraft:nether_wart_block)
B(15,11,9,minecraft:nether_wart_block)
B(11,11,10,minecraft:nether_wart_block)
B(12,11,10,minecraft:nether_wart_block)
B(13,11,10,minecraft:nether_wart_block)
B(14,11,10,minecraft:nether_wart_block)
B(15,11,10,minecraft:nether_wart_block)
B(11,11,11,minecraft:nether_wart_block)
B(12,11,11,minecraft:nether_wart_block)
B(13,11,11,minecraft:nether_wart_block)
B(14,11,11,minecraft:nether_wart_block)
B(15,11,11,minecraft:nether_wart_block)
B(11,11,12,minecraft:nether_wart_block)
B(12,11,12,minecraft:nether_wart_block)
B(13,11,12,minecraft:nether_wart_block)
B(14,11,12,minecraft:nether_wart_block)
B(15,11,12,minecraft:nether_wart_block)
B(10,11,13,minecraft:nether_wart_block)
B(11,11,13,minecraft:nether_wart_block)
B(12,11,13,minecraft:nether_wart_block)
B(13,11,13,minecraft:nether_wart_block)
B(14,11,13,minecraft:nether_wart_block)
B(15,11,13,minecraft:nether_wart_block)
B(10,11,14,minecraft:nether_wart_block)
B(11,11,14,minecraft:nether_wart_block)
B(12,11,14,minecraft:nether_wart_block)
B(13,11,14,minecraft:nether_wart_block)
B(14,11,14,minecraft:nether_wart_block)
B(15,11,14,minecraft:nether_wart_block)
B(10,11,15,minecraft:nether_wart_block)
B(11,11,15,minecraft:nether_wart_block)
B(12,11,15,minecraft:nether_wart_block)
B(13,11,15,minecraft:nether_wart_block)
B(14,11,15,minecraft:nether_wart_block)
B(15,11,15,minecraft:nether_wart_block)
B(9,12,0,minecraft:nether_wart_block)
B(10,12,0,minecraft:nether_wart_block)
B(11,12,0,minecraft:nether_wart_block)
B(12,12,0,minecraft:nether_wart_block)
B(13,12,0,minecraft:nether_wart_block)
B(14,12,0,minecraft:nether_wart_block)
B(15,12,0,minecraft:nether_wart_block)
B(9,12,1,minecraft:nether_wart_block)
B(10,12,1,minecraft:nether_wart_block)
B(11,12,1,minecraft:nether_wart_block)
B(12,12,1,minecraft:nether_wart_block)
B(13,12,1,minecraft:nether_wart_block)
B(14,12,1,minecraft:nether_wart_block)
B(15,12,1,minecraft:nether_wart_block)
B(9,12,2,minecraft:nether_wart_block)
B(10,12,2,minecraft:nether_wart_block)
B(11,12,2,minecraft:nether_wart_block)
B(12,12,2,minecraft:nether_wart_block)
B(13,12,2,minecraft:nether_wart_block)
B(14,12,2,minecraft:nether_wart_block)
B(15,12,2,minecraft:nether_wart_block)
B(9,12,3,minecraft:nether_wart_block)
B(10,12,3,minecraft:nether_wart_block)
B(11,12,3,minecraft:nether_wart_block)
B(12,12,3,minecraft:nether_wart_block)
B(13,12,3,minecraft:nether_wart_block)
B(14,12,3,minecraft:nether_wart_block)
B(15,12,3,minecraft:nether_wart_block)
B(9,12,4,minecraft:nether_wart_block)
B(10,12,4,minecraft:nether_wart_block)
B(11,12,4,minecraft:nether_wart_block)
B(12,12,4,minecraft:nether_wart_block)
B(13,12,4,minecraft:nether_wart_block)
B(14,12,4,minecraft:nether_wart_block)
B(15,12,4,minecraft:nether_wart_block)
B(9,12,5,minecraft:nether_wart_block)
B(10,12,5,minecraft:nether_wart_block)
B(11,12,5,minecraft:nether_wart_block)
B(12,12,5,minecraft:nether_wart_block)
B(13,12,5,minecraft:nether_wart_block)
B(14,12,5,minecraft:nether_wart_block)
B(15,12,5,minecraft:nether_wart_block)
B(9,12,6,minecraft:nether_wart_block)
B(10,12,6,minecraft:nether_wart_block)
B(11,12,6,minecraft:nether_wart_block)
B(12,12,6,minecraft:nether_wart_block)
B(13,12,6,minecraft:nether_wart_block)
B(14,12,6,minecraft:nether_wart_block)
B(15,12,6,minecraft:nether_wart_block)
B(9,12,7,minecraft:nether_wart_block)
B(10,12,7,minecraft:nether_wart_block)
B(11,12,7,minecraft:nether_wart_block)
B(12,12,7,minecraft:nether_wart_block)
B(13,12,7,minecraft:nether_wart_block)
B(14,12,7,minecraft:nether_wart_block)
B(15,12,7,minecraft:nether_wart_block)
B(10,12,8,minecraft:nether_wart_block)
B(11,12,8,minecraft:nether_wart_block)
B(12,12,8,minecraft:nether_wart_block)
B(13,12,8,minecraft:nether_wart_block)
B(14,12,8,minecraft:nether_wart_block)
B(15,12,8,minecraft:nether_wart_block)
B(11,12,9,minecraft:nether_wart_block)
B(12,12,9,minecraft:nether_wart_block)
B(13,12,9,minecraft:nether_wart_block)
B(14,12,9,minecraft:nether_wart_block)
B(15,12,9,minecraft:nether_wart_block)
B(11,12,10,minecraft:nether_wart_block)
B(12,12,10,minecraft:nether_wart_block)
B(13,12,10,minecraft:nether_wart_block)
B(14,12,10,minecraft:nether_wart_block)
B(15,12,10,minecraft:nether_wart_block)
B(11,12,11,minecraft:nether_wart_block)
B(12,12,11,minecraft:nether_wart_block)
B(13,12,11,minecraft:nether_wart_block)
B(14,12,11,minecraft:nether_wart_block)
B(15,12,11,minecraft:nether_wart_block)
B(11,12,12,minecraft:nether_wart_block)
B(12,12,12,minecraft:nether_wart_block)
B(13,12,12,minecraft:nether_wart_block)
B(14,12,12,minecraft:nether_wart_block)
B(15,12,12,minecraft:nether_wart_block)
B(10,12,13,minecraft:nether_wart_block)
B(11,12,13,minecraft:nether_wart_block)
B(12,12,13,minecraft:nether_wart_block)
B(13,12,13,minecraft:nether_wart_block)
B(14,12,13,minecraft:nether_wart_block)
B(15,12,13,minecraft:nether_wart_block)
B(10,12,14,minecraft:nether_wart_block)
B(11,12,14,minecraft:nether_wart_block)
B(12,12,14,minecraft:nether_wart_block)
B(13,12,14,minecraft:nether_wart_block)
B(14,12,14,minecraft:nether_wart_block)
B(15,12,14,minecraft:nether_wart_block)
B(10,12,15,minecraft:nether_wart_block)
B(11,12,15,minecraft:nether_wart_block)
B(12,12,15,minecraft:nether_wart_block)
B(13,12,15,minecraft:nether_wart_block)
B(14,12,15,minecraft:nether_wart_block)
B(15,12,15,minecraft:nether_wart_block)
B(9,13,0,minecraft:nether_wart_block)
B(10,13,0,minecraft:nether_wart_block)
B(11,13,0,minecraft:nether_wart_block)
B(12,13,0,minecraft:nether_wart_block)
B(13,13,0,minecraft:nether_wart_block)
B(14,13,0,minecraft:nether_wart_block)
B(15,13,0,minecraft:nether_wart_block)
B(9,13,1,minecraft:nether_wart_block)
B(10,13,1,minecraft:nether_wart_block)
B(11,13,1,minecraft:nether_wart_block)
B(12,13,1,minecraft:nether_wart_block)
B(13,13,1,minecraft:nether_wart_block)
B(14,13,1,minecraft:nether_wart_block)
B(15,13,1,minecraft:nether_wart_block)
B(9,13,2,minecraft:nether_wart_block)
B(10,13,2,minecraft:nether_wart_block)
B(11,13,2,minecraft:nether_wart_block)
B(12,13,2,minecraft:nether_wart_block)
B(13,13,2,minecraft:nether_wart_block)
B(14,13,2,minecraft:nether_wart_block)
B(15,13,2,minecraft:nether_wart_block)
B(9,13,3,minecraft:nether_wart_block)
B(10,13,3,minecraft:nether_wart_block)
B(11,13,3,minecraft:nether_wart_block)
B(12,13,3,minecraft:nether_wart_block)
B(13,13,3,minecraft:nether_wart_block)
B(14,13,3,minecraft:nether_wart_block)
B(15,13,3,minecraft:nether_wart_block)
B(9,13,4,minecraft:nether_wart_block)
B(10,13,4,minecraft:nether_wart_block)
B(11,13,4,minecraft:nether_wart_block)
B(12,13,4,minecraft:nether_wart_block)
B(13,13,4,minecraft:nether_wart_block)
B(14,13,4,minecraft:nether_wart_block)
B(15,13,4,minecraft:nether_wart_block)
B(9,13,5,minecraft:nether_wart_block)
B(10,13,5,minecraft:nether_wart_block)
B(11,13,5,minecraft:nether_wart_block)
B(12,13,5,minecraft:nether_wart_block)
B(13,13,5,minecraft:nether_wart_block)
B(14,13,5,minecraft:nether_wart_block)
B(15,13,5,minecraft:nether_wart_block)
B(9,13,6,minecraft:nether_wart_block)
B(10,13,6,minecraft:nether_wart_block)
B(11,13,6,minecraft:nether_wart_block)
B(12,13,6,minecraft:nether_wart_block)
B(13,13,6,minecraft:nether_wart_block)
B(14,13,6,minecraft:nether_wart_block)
B(15,13,6,minecraft:nether_wart_block)
B(9,13,7,minecraft:nether_wart_block)
B(10,13,7,minecraft:nether_wart_block)
B(11,13,7,minecraft:nether_wart_block)
B(12,13,7,minecraft:nether_wart_block)
B(13,13,7,minecraft:nether_wart_block)
B(14,13,7,minecraft:nether_wart_block)
B(15,13,7,minecraft:nether_wart_block)
B(10,13,8,minecraft:nether_wart_block)
B(11,13,8,minecraft:nether_wart_block)
B(12,13,8,minecraft:nether_wart_block)
B(13,13,8,minecraft:nether_wart_block)
B(14,13,8,minecraft:nether_wart_block)
B(15,13,8,minecraft:nether_wart_block)
B(12,13,9,minecraft:nether_wart_block)
B(13,13,9,minecraft:nether_wart_block)
B(14,13,9,minecraft:nether_wart_block)
B(15,13,9,minecraft:nether_wart_block)
B(11,13,10,minecraft:nether_wart_block)
B(12,13,10,minecraft:nether_wart_block)
B(13,13,10,minecraft:nether_wart_block)
B(14,13,10,minecraft:nether_wart_block)
B(15,13,10,minecraft:nether_wart_block)
B(11,13,11,minecraft:nether_wart_block)
B(12,13,11,minecraft:nether_wart_block)
B(13,13,11,minecraft:nether_wart_block)
B(14,13,11,minecraft:nether_wart_block)
B(15,13,11,minecraft:nether_wart_block)
B(11,13,12,minecraft:nether_wart_block)
B(12,13,12,minecraft:nether_wart_block)
B(13,13,12,minecraft:nether_wart_block)
B(14,13,12,minecraft:nether_wart_block)
B(15,13,12,minecraft:nether_wart_block)
B(10,13,13,minecraft:nether_wart_block)
B(11,13,13,minecraft:nether_wart_block)
B(12,13,13,minecraft:nether_wart_block)
B(13,13,13,minecraft:nether_wart_block)
B(14,13,13,minecraft:nether_wart_block)
B(15,13,13,minecraft:nether_wart_block)
B(10,13,14,minecraft:nether_wart_block)
B(11,13,14,minecraft:nether_wart_block)
B(12,13,14,minecraft:nether_wart_block)
B(13,13,14,minecraft:nether_wart_block)
B(14,13,14,minecraft:nether_wart_block)
B(15,13,14,minecraft:nether_wart_block)
B(10,13,15,minecraft:nether_wart_block)
B(11,13,15,minecraft:nether_wart_block)
B(12,13,15,minecraft:nether_wart_block)
B(13,13,15,minecraft:nether_wart_block)
B(14,13,15,minecraft:nether_wart_block)
B(15,13,15,minecraft:nether_wart_block)
B(9,14,0,minecraft:nether_wart_block)
B(10,14,0,minecraft:nether_wart_block)
B(11,14,0,minecraft:nether_wart_block)
B(12,14,0,minecraft:nether_wart_block)
B(13,14,0,minecraft:nether_wart_block)
B(14,14,0,minecraft:nether_wart_block)
B(15,14,0,minecraft:nether_wart_block)
B(9,14,1,minecraft:nether_wart_block)
B(10,14,1,minecraft:nether_wart_block)
B(11,14,1,minecraft:nether_wart_block)
B(12,14,1,minecraft:nether_wart_block)
B(13,14,1,minecraft:nether_wart_block)
B(14,14,1,minecraft:nether_wart_block)
B(15,14,1,minecraft:nether_wart_block)
B(9,14,2,minecraft:nether_wart_block)
B(10,14,2,minecraft:nether_wart_block)
B(11,14,2,minecraft:nether_wart_block)
B(12,14,2,minecraft:nether_wart_block)
B(13,14,2,minecraft:nether_wart_block)
B(14,14,2,minecraft:nether_wart_block)
B(15,14,2,minecraft:nether_wart_block)
B(9,14,3,minecraft:nether_wart_block)
B(10,14,3,minecraft:nether_wart_block)
B(11,14,3,minecraft:nether_wart_block)
B(12,14,3,minecraft:nether_wart_block)
B(13,14,3,minecraft:nether_wart_block)
B(14,14,3,minecraft:nether_wart_block)
B(15,14,3,minecraft:nether_wart_block)
B(9,14,4,minecraft:nether_wart_block)
B(10,14,4,minecraft:nether_wart_block)
B(11,14,4,minecraft:nether_wart_block)
B(12,14,4,minecraft:nether_wart_block)
B(13,14,4,minecraft:nether_wart_block)
B(14,14,4,minecraft:nether_wart_block)
B(15,14,4,minecraft:nether_wart_block)
B(9,14,5,minecraft:nether_wart_block)
B(10,14,5,minecraft:nether_wart_block)
B(11,14,5,minecraft:nether_wart_block)
B(12,14,5,minecraft:nether_wart_block)
B(13,14,5,minecraft:nether_wart_block)
B(14,14,5,minecraft:nether_wart_block)
B(15,14,5,minecraft:nether_wart_block)
B(9,14,6,minecraft:nether_wart_block)
B(10,14,6,minecraft:nether_wart_block)
B(11,14,6,minecraft:nether_wart_block)
B(12,14,6,minecraft:nether_wart_block)
B(13,14,6,minecraft:nether_wart_block)
B(14,14,6,minecraft:nether_wart_block)
B(15,14,6,minecraft:nether_wart_block)
B(9,14,7,minecraft:nether_wart_block)
B(10,14,7,minecraft:nether_wart_block)
B(11,14,7,minecraft:nether_wart_block)
B(12,14,7,minecraft:nether_wart_block)
B(13,14,7,minecraft:nether_wart_block)
B(14,14,7,minecraft:nether_wart_block)
B(15,14,7,minecraft:nether_wart_block)
B(10,14,8,minecraft:nether_wart_block)
B(11,14,8,minecraft:nether_wart_block)
B(12,14,8,minecraft:nether_wart_block)
B(13,14,8,minecraft:nether_wart_block)
B(14,14,8,minecraft:nether_wart_block)
B(15,14,8,minecraft:nether_wart_block)
B(12,14,9,minecraft:nether_wart_block)
B(13,14,9,minecraft:nether_wart_block)
B(14,14,9,minecraft:nether_wart_block)
B(15,14,9,minecraft:nether_wart_block)
B(11,14,10,minecraft:nether_wart_block)
B(12,14,10,minecraft:nether_wart_block)
B(13,14,10,minecraft:nether_wart_block)
B(14,14,10,minecraft:nether_wart_block)
B(15,14,10,minecraft:nether_wart_block)
B(11,14,11,minecraft:nether_wart_block)
B(12,14,11,minecraft:nether_wart_block)
B(13,14,11,minecraft:nether_wart_block)
B(14,14,11,minecraft:nether_wart_block)
B(15,14,11,minecraft:nether_wart_block)
B(11,14,12,minecraft:nether_wart_block)
B(12,14,12,minecraft:nether_wart_block)
B(13,14,12,minecraft:nether_wart_block)
B(14,14,12,minecraft:nether_wart_block)
B(15,14,12,minecraft:nether_wart_block)
B(10,14,13,minecraft:nether_wart_block)
B(11,14,13,minecraft:nether_wart_block)
B(12,14,13,minecraft:nether_wart_block)
B(13,14,13,minecraft:nether_wart_block)
B(14,14,13,minecraft:nether_wart_block)
B(15,14,13,minecraft:nether_wart_block)
B(10,14,14,minecraft:nether_wart_block)
B(11,14,14,minecraft:nether_wart_block)
B(12,14,14,minecraft:nether_wart_block)
B(13,14,14,minecraft:nether_wart_block)
B(14,14,14,minecraft:nether_wart_block)
B(15,14,14,minecraft:nether_wart_block)
B(10,14,15,minecraft:nether_wart_block)
B(11,14,15,minecraft:nether_wart_block)
B(12,14,15,minecraft:nether_wart_block)
B(13,14,15,minecraft:nether_wart_block)
B(14,14,15,minecraft:nether_wart_block)
B(15,14,15,minecraft:nether_wart_block)
B(9,15,0,minecraft:nether_wart_block)
B(10,15,0,minecraft:nether_wart_block)
B(11,15,0,minecraft:nether_wart_block)
B(12,15,0,minecraft:nether_wart_block)
B(13,15,0,minecraft:nether_wart_block)
B(14,15,0,minecraft:nether_wart_block)
B(15,15,0,minecraft:nether_wart_block)
B(10,15,1,minecraft:nether_wart_block)
B(11,15,1,minecraft:nether_wart_block)
B(12,15,1,minecraft:nether_wart_block)
B(13,15,1,minecraft:nether_wart_block)
B(14,15,1,minecraft:nether_wart_block)
B(15,15,1,minecraft:nether_wart_block)
B(9,15,2,minecraft:nether_wart_block)
B(10,15,2,minecraft:nether_wart_block)
B(11,15,2,minecraft:nether_wart_block)
B(12,15,2,minecraft:nether_wart_block)
B(13,15,2,minecraft:nether_wart_block)
B(14,15,2,minecraft:nether_wart_block)
B(15,15,2,minecraft:nether_wart_block)
B(10,15,3,minecraft:nether_wart_block)
B(11,15,3,minecraft:nether_wart_block)
B(12,15,3,minecraft:nether_wart_block)
B(13,15,3,minecraft:nether_wart_block)
B(14,15,3,minecraft:nether_wart_block)
B(15,15,3,minecraft:nether_wart_block)
B(9,15,4,minecraft:nether_wart_block)
B(10,15,4,minecraft:nether_wart_block)
B(11,15,4,minecraft:nether_wart_block)
B(12,15,4,minecraft:nether_wart_block)
B(13,15,4,minecraft:nether_wart_block)
B(14,15,4,minecraft:nether_wart_block)
B(15,15,4,minecraft:nether_wart_block)
B(10,15,5,minecraft:nether_wart_block)
B(11,15,5,minecraft:nether_wart_block)
B(12,15,5,minecraft:nether_wart_block)
B(13,15,5,minecraft:nether_wart_block)
B(14,15,5,minecraft:nether_wart_block)
B(15,15,5,minecraft:nether_wart_block)
B(9,15,6,minecraft:nether_wart_block)
B(10,15,6,minecraft:nether_wart_block)
B(11,15,6,minecraft:nether_wart_block)
B(12,15,6,minecraft:nether_wart_block)
B(13,15,6,minecraft:nether_wart_block)
B(14,15,6,minecraft:nether_wart_block)
B(15,15,6,minecraft:nether_wart_block)
B(10,15,7,minecraft:nether_wart_block)
B(11,15,7,minecraft:nether_wart_block)
B(12,15,7,minecraft:nether_wart_block)
B(13,15,7,minecraft:nether_wart_block)
B(14,15,7,minecraft:nether_wart_block)
B(15,15,7,minecraft:nether_wart_block)
B(10,15,8,minecraft:nether_wart_block)
B(11,15,8,minecraft:nether_wart_block)
B(12,15,8,minecraft:nether_wart_block)
B(13,15,8,minecraft:nether_wart_block)
B(14,15,8,minecraft:nether_wart_block)
B(15,15,8,minecraft:nether_wart_block)
B(12,15,9,minecraft:nether_wart_block)
B(13,15,9,minecraft:nether_wart_block)
B(14,15,9,minecraft:nether_wart_block)
B(15,15,9,minecraft:nether_wart_block)
B(11,15,10,minecraft:nether_wart_block)
B(12,15,10,minecraft:nether_wart_block)
B(13,15,10,minecraft:nether_wart_block)
B(14,15,10,minecraft:nether_wart_block)
B(15,15,10,minecraft:nether_wart_block)
B(11,15,11,minecraft:nether_wart_block)
B(12,15,11,minecraft:nether_wart_block)
B(13,15,11,minecraft:nether_wart_block)
B(14,15,11,minecraft:nether_wart_block)
B(15,15,11,minecraft:nether_wart_block)
B(11,15,12,minecraft:nether_wart_block)
B(12,15,12,minecraft:nether_wart_block)
B(13,15,12,minecraft:nether_wart_block)
B(14,15,12,minecraft:nether_wart_block)
B(15,15,12,minecraft:nether_wart_block)
B(10,15,13,minecraft:nether_wart_block)
B(11,15,13,minecraft:nether_wart_block)
B(12,15,13,minecraft:nether_wart_block)
B(13,15,13,minecraft:nether_wart_block)
B(14,15,13,minecraft:nether_wart_block)
B(15,15,13,minecraft:nether_wart_block)
B(10,15,14,minecraft:nether_wart_block)
B(11,15,14,minecraft:nether_wart_block)
B(12,15,14,minecraft:nether_wart_block)
B(13,15,14,minecraft:nether_wart_block)
B(14,15,14,minecraft:nether_wart_block)
B(15,15,14,minecraft:nether_wart_block)
B(10,15,15,minecraft:nether_wart_block)
B(11,15,15,minecraft:nether_wart_block)
B(12,15,15,minecraft:nether_wart_block)
B(13,15,15,minecraft:nether_wart_block)
B(14,15,15,minecraft:nether_wart_block)
B(15,15,15,minecraft:nether_wart_block)
B(9,16,0,minecraft:nether_wart_block)
B(10,16,0,minecraft:nether_wart_block)
B(11,16,0,minecraft:nether_wart_block)
B(12,16,0,minecraft:nether_wart_block)
B(13,16,0,minecraft:nether_wart_block)
B(14,16,0,minecraft:nether_wart_block)
B(15,16,0,minecraft:nether_wart_block)
B(10,16,1,minecraft:nether_wart_block)
B(11,16,1,minecraft:nether_wart_block)
B(12,16,1,minecraft:nether_wart_block)
B(13,16,1,minecraft:nether_wart_block)
B(14,16,1,minecraft:nether_wart_block)
B(15,16,1,minecraft:nether_wart_block)
B(10,16,2,minecraft:nether_wart_block)
B(11,16,2,minecraft:nether_wart_block)
B(12,16,2,minecraft:nether_wart_block)
B(13,16,2,minecraft:nether_wart_block)
B(14,16,2,minecraft:nether_wart_block)
B(15,16,2,minecraft:nether_wart_block)
B(10,16,3,minecraft:nether_wart_block)
B(11,16,3,minecraft:nether_wart_block)
B(12,16,3,minecraft:nether_wart_block)
B(13,16,3,minecraft:nether_wart_block)
B(14,16,3,minecraft:nether_wart_block)
B(15,16,3,minecraft:nether_wart_block)
B(9,16,4,minecraft:nether_wart_block)
B(10,16,4,minecraft:nether_wart_block)
B(11,16,4,minecraft:nether_wart_block)
B(12,16,4,minecraft:nether_wart_block)
B(13,16,4,minecraft:nether_wart_block)
B(14,16,4,minecraft:nether_wart_block)
B(15,16,4,minecraft:nether_wart_block)
B(10,16,5,minecraft:nether_wart_block)
B(11,16,5,minecraft:nether_wart_block)
B(12,16,5,minecraft:nether_wart_block)
B(13,16,5,minecraft:nether_wart_block)
B(14,16,5,minecraft:nether_wart_block)
B(15,16,5,minecraft:nether_wart_block)
B(9,16,6,minecraft:nether_wart_block)
B(10,16,6,minecraft:nether_wart_block)
B(11,16,6,minecraft:nether_wart_block)
B(12,16,6,minecraft:nether_wart_block)
B(13,16,6,minecraft:nether_wart_block)
B(14,16,6,minecraft:nether_wart_block)
B(15,16,6,minecraft:nether_wart_block)
B(10,16,7,minecraft:nether_wart_block)
B(11,16,7,minecraft:nether_wart_block)
B(12,16,7,minecraft:nether_wart_block)
B(13,16,7,minecraft:nether_wart_block)
B(14,16,7,minecraft:nether_wart_block)
B(15,16,7,minecraft:nether_wart_block)
B(10,16,8,minecraft:nether_wart_block)
B(11,16,8,minecraft:nether_wart_block)
B(12,16,8,minecraft:nether_wart_block)
B(13,16,8,minecraft:nether_wart_block)
B(14,16,8,minecraft:nether_wart_block)
B(15,16,8,minecraft:nether_wart_block)
B(12,16,9,minecraft:nether_wart_block)
B(13,16,9,minecraft:nether_wart_block)
B(14,16,9,minecraft:nether_wart_block)
B(15,16,9,minecraft:nether_wart_block)
B(11,16,10,minecraft:nether_wart_block)
B(12,16,10,minecraft:nether_wart_block)
B(13,16,10,minecraft:nether_wart_block)
B(14,16,10,minecraft:nether_wart_block)
B(15,16,10,minecraft:nether_wart_block)
B(11,16,11,minecraft:nether_wart_block)
B(12,16,11,minecraft:nether_wart_block)
B(13,16,11,minecraft:nether_wart_block)
B(14,16,11,minecraft:nether_wart_block)
B(15,16,11,minecraft:nether_wart_block)
B(11,16,12,minecraft:nether_wart_block)
B(12,16,12,minecraft:nether_wart_block)
B(13,16,12,minecraft:nether_wart_block)
B(14,16,12,minecraft:nether_wart_block)
B(15,16,12,minecraft:nether_wart_block)
B(10,16,13,minecraft:nether_wart_block)
B(11,16,13,minecraft:nether_wart_block)
B(12,16,13,minecraft:nether_wart_block)
B(13,16,13,minecraft:nether_wart_block)
B(14,16,13,minecraft:nether_wart_block)
B(15,16,13,minecraft:nether_wart_block)
B(10,16,14,minecraft:nether_wart_block)
B(11,16,14,minecraft:nether_wart_block)
B(12,16,14,minecraft:nether_wart_block)
B(13,16,14,minecraft:nether_wart_block)
B(14,16,14,minecraft:nether_wart_block)
B(15,16,14,minecraft:nether_wart_block)
B(10,16,15,minecraft:nether_wart_block)
B(11,16,15,minecraft:nether_wart_block)
B(12,16,15,minecraft:nether_wart_block)
B(13,16,15,minecraft:nether_wart_block)
B(14,16,15,minecraft:nether_wart_block)
B(15,16,15,minecraft:nether_wart_block)
B(9,17,0,minecraft:nether_wart_block)
B(10,17,0,minecraft:nether_wart_block)
B(11,17,0,minecraft:nether_wart_block)
B(12,17,0,minecraft:nether_wart_block)
B(13,17,0,minecraft:nether_wart_block)
B(14,17,0,minecraft:nether_wart_block)
B(15,17,0,minecraft:nether_wart_block)
B(10,17,1,minecraft:nether_wart_block)
B(11,17,1,minecraft:nether_wart_block)
B(12,17,1,minecraft:nether_wart_block)
B(13,17,1,minecraft:nether_wart_block)
B(14,17,1,minecraft:nether_wart_block)
B(15,17,1,minecraft:nether_wart_block)
B(10,17,2,minecraft:nether_wart_block)
B(11,17,2,minecraft:nether_wart_block)
B(12,17,2,minecraft:nether_wart_block)
B(13,17,2,minecraft:nether_wart_block)
B(14,17,2,minecraft:nether_wart_block)
B(15,17,2,minecraft:nether_wart_block)
B(10,17,3,minecraft:nether_wart_block)
B(11,17,3,minecraft:nether_wart_block)
B(12,17,3,minecraft:nether_wart_block)
B(13,17,3,minecraft:nether_wart_block)
B(14,17,3,minecraft:nether_wart_block)
B(15,17,3,minecraft:nether_wart_block)
B(9,17,4,minecraft:nether_wart_block)
B(10,17,4,minecraft:nether_wart_block)
B(11,17,4,minecraft:nether_wart_block)
B(12,17,4,minecraft:nether_wart_block)
B(13,17,4,minecraft:nether_wart_block)
B(14,17,4,minecraft:nether_wart_block)
B(15,17,4,minecraft:nether_wart_block)
B(10,17,5,minecraft:nether_wart_block)
B(11,17,5,minecraft:nether_wart_block)
B(12,17,5,minecraft:nether_wart_block)
B(13,17,5,minecraft:nether_wart_block)
B(14,17,5,minecraft:nether_wart_block)
B(15,17,5,minecraft:nether_wart_block)
B(9,17,6,minecraft:nether_wart_block)
B(10,17,6,minecraft:nether_wart_block)
B(11,17,6,minecraft:nether_wart_block)
B(12,17,6,minecraft:nether_wart_block)
B(13,17,6,minecraft:nether_wart_block)
B(14,17,6,minecraft:nether_wart_block)
B(15,17,6,minecraft:nether_wart_block)
B(10,17,7,minecraft:nether_wart_block)
B(11,17,7,minecraft:nether_wart_block)
B(12,17,7,minecraft:nether_wart_block)
B(13,17,7,minecraft:nether_wart_block)
B(14,17,7,minecraft:nether_wart_block)
B(15,17,7,minecraft:nether_wart_block)
B(10,17,8,minecraft:nether_wart_block)
B(11,17,8,minecraft:nether_wart_block)
B(12,17,8,minecraft:nether_wart_block)
B(13,17,8,minecraft:nether_wart_block)
B(14,17,8,minecraft:nether_wart_block)
B(15,17,8,minecraft:nether_wart_block)
B(12,17,9,minecraft:nether_wart_block)
B(13,17,9,minecraft:nether_wart_block)
B(14,17,9,minecraft:nether_wart_block)
B(15,17,9,minecraft:nether_wart_block)
B(11,17,10,minecraft:nether_wart_block)
B(12,17,10,minecraft:nether_wart_block)
B(13,17,10,minecraft:nether_wart_block)
B(14,17,10,minecraft:nether_wart_block)
B(15,17,10,minecraft:nether_wart_block)
B(11,17,11,minecraft:nether_wart_block)
B(12,17,11,minecraft:nether_wart_block)
B(13,17,11,minecraft:nether_wart_block)
B(14,17,11,minecraft:nether_wart_block)
B(15,17,11,minecraft:nether_wart_block)
B(11,17,12,minecraft:nether_wart_block)
B(12,17,12,minecraft:nether_wart_block)
B(13,17,12,minecraft:nether_wart_block)
B(14,17,12,minecraft:nether_wart_block)
B(15,17,12,minecraft:nether_wart_block)
B(11,17,13,minecraft:nether_wart_block)
B(12,17,13,minecraft:nether_wart_block)
B(13,17,13,minecraft:nether_wart_block)
B(14,17,13,minecraft:nether_wart_block)
B(15,17,13,minecraft:nether_wart_block)
B(10,17,14,minecraft:nether_wart_block)
B(11,17,14,minecraft:nether_wart_block)
B(12,17,14,minecraft:nether_wart_block)
B(13,17,14,minecraft:nether_wart_block)
B(14,17,14,minecraft:nether_wart_block)
B(15,17,14,minecraft:nether_wart_block)
B(10,17,15,minecraft:nether_wart_block)
B(11,17,15,minecraft:nether_wart_block)
B(12,17,15,minecraft:nether_wart_block)
B(13,17,15,minecraft:nether_wart_block)
B(14,17,15,minecraft:nether_wart_block)
B(15,17,15,minecraft:nether_wart_block)
B(10,18,0,minecraft:nether_wart_block)
B(11,18,0,minecraft:nether_wart_block)
B(12,18,0,minecraft:nether_wart_block)
B(13,18,0,minecraft:nether_wart_block)
B(14,18,0,minecraft:nether_wart_block)
B(15,18,0,minecraft:nether_wart_block)
B(10,18,1,minecraft:nether_wart_block)
B(11,18,1,minecraft:nether_wart_block)
B(12,18,1,minecraft:nether_wart_block)
B(13,18,1,minecraft:nether_wart_block)
B(14,18,1,minecraft:nether_wart_block)
B(15,18,1,minecraft:nether_wart_block)
B(10,18,2,minecraft:nether_wart_block)
B(11,18,2,minecraft:nether_wart_block)
B(12,18,2,minecraft:nether_wart_block)
B(13,18,2,minecraft:nether_wart_block)
B(14,18,2,minecraft:nether_wart_block)
B(15,18,2,minecraft:nether_wart_block)
B(10,18,3,minecraft:nether_wart_block)
B(11,18,3,minecraft:nether_wart_block)
B(12,18,3,minecraft:nether_wart_block)
B(13,18,3,minecraft:nether_wart_block)
B(14,18,3,minecraft:nether_wart_block)
B(15,18,3,minecraft:nether_wart_block)
B(10,18,4,minecraft:nether_wart_block)
B(11,18,4,minecraft:nether_wart_block)
B(12,18,4,minecraft:nether_wart_block)
B(13,18,4,minecraft:nether_wart_block)
B(14,18,4,minecraft:nether_wart_block)
B(15,18,4,minecraft:nether_wart_block)
B(10,18,5,minecraft:nether_wart_block)
B(11,18,5,minecraft:nether_wart_block)
B(12,18,5,minecraft:nether_wart_block)
B(13,18,5,minecraft:nether_wart_block)
B(14,18,5,minecraft:nether_wart_block)
B(15,18,5,minecraft:nether_wart_block)
B(9,18,6,minecraft:nether_wart_block)
B(10,18,6,minecraft:nether_wart_block)
B(11,18,6,minecraft:nether_wart_block)
B(12,18,6,minecraft:nether_wart_block)
B(13,18,6,minecraft:nether_wart_block)
B(14,18,6,minecraft:nether_wart_block)
B(15,18,6,minecraft:nether_wart_block)
B(10,18,7,minecraft:nether_wart_block)
B(11,18,7,minecraft:nether_wart_block)
B(12,18,7,minecraft:nether_wart_block)
B(13,18,7,minecraft:nether_wart_block)
B(14,18,7,minecraft:nether_wart_block)
B(15,18,7,minecraft:nether_wart_block)
B(10,18,8,minecraft:nether_wart_block)
B(11,18,8,minecraft:nether_wart_block)
B(12,18,8,minecraft:nether_wart_block)
B(13,18,8,minecraft:nether_wart_block)
B(14,18,8,minecraft:nether_wart_block)
B(15,18,8,minecraft:nether_wart_block)
B(12,18,9,minecraft:nether_wart_block)
B(13,18,9,minecraft:nether_wart_block)
B(14,18,9,minecraft:nether_wart_block)
B(15,18,9,minecraft:nether_wart_block)
B(11,18,10,minecraft:nether_wart_block)
B(12,18,10,minecraft:nether_wart_block)
B(13,18,10,minecraft:nether_wart_block)
B(14,18,10,minecraft:nether_wart_block)
B(15,18,10,minecraft:nether_wart_block)
B(11,18,11,minecraft:nether_wart_block)
B(12,18,11,minecraft:nether_wart_block)
B(13,18,11,minecraft:nether_wart_block)
B(14,18,11,minecraft:nether_wart_block)
B(15,18,11,minecraft:nether_wart_block)
B(11,18,12,minecraft:nether_wart_block)
B(12,18,12,minecraft:nether_wart_block)
B(13,18,12,minecraft:nether_wart_block)
B(14,18,12,minecraft:nether_wart_block)
B(15,18,12,minecraft:nether_wart_block)
B(11,18,13,minecraft:nether_wart_block)
B(12,18,13,minecraft:nether_wart_block)
B(13,18,13,minecraft:nether_wart_block)
B(14,18,13,minecraft:nether_wart_block)
B(15,18,13,minecraft:nether_wart_block)
B(10,18,14,minecraft:nether_wart_block)
B(11,18,14,minecraft:nether_wart_block)
B(12,18,14,minecraft:nether_wart_block)
B(13,18,14,minecraft:nether_wart_block)
B(14,18,14,minecraft:nether_wart_block)
B(15,18,14,minecraft:nether_wart_block)
B(10,18,15,minecraft:nether_wart_block)
B(11,18,15,minecraft:nether_wart_block)
B(12,18,15,minecraft:nether_wart_block)
B(13,18,15,minecraft:nether_wart_block)
B(14,18,15,minecraft:nether_wart_block)
B(15,18,15,minecraft:nether_wart_block)
B(10,19,0,minecraft:nether_wart_block)
B(11,19,0,minecraft:nether_wart_block)
B(12,19,0,minecraft:nether_wart_block)
B(13,19,0,minecraft:nether_wart_block)
B(14,19,0,minecraft:nether_wart_block)
B(15,19,0,minecraft:nether_wart_block)
B(10,19,1,minecraft:nether_wart_block)
B(11,19,1,minecraft:nether_wart_block)
B(12,19,1,minecraft:nether_wart_block)
B(13,19,1,minecraft:nether_wart_block)
B(14,19,1,minecraft:nether_wart_block)
B(15,19,1,minecraft:nether_wart_block)
B(10,19,2,minecraft:nether_wart_block)
B(11,19,2,minecraft:nether_wart_block)
B(12,19,2,minecraft:nether_wart_block)
B(13,19,2,minecraft:nether_wart_block)
B(14,19,2,minecraft:nether_wart_block)
B(15,19,2,minecraft:nether_wart_block)
B(10,19,3,minecraft:nether_wart_block)
B(11,19,3,minecraft:nether_wart_block)
B(12,19,3,minecraft:nether_wart_block)
B(13,19,3,minecraft:nether_wart_block)
B(14,19,3,minecraft:nether_wart_block)
B(15,19,3,minecraft:nether_wart_block)
B(10,19,4,minecraft:nether_wart_block)
B(11,19,4,minecraft:nether_wart_block)
B(12,19,4,minecraft:nether_wart_block)
B(13,19,4,minecraft:nether_wart_block)
B(14,19,4,minecraft:nether_wart_block)
B(15,19,4,minecraft:nether_wart_block)
B(10,19,5,minecraft:nether_wart_block)
B(11,19,5,minecraft:nether_wart_block)
B(12,19,5,minecraft:nether_wart_block)
B(13,19,5,minecraft:nether_wart_block)
B(14,19,5,minecraft:nether_wart_block)
B(15,19,5,minecraft:nether_wart_block)
B(10,19,6,minecraft:nether_wart_block)
B(11,19,6,minecraft:nether_wart_block)
B(12,19,6,minecraft:nether_wart_block)
B(13,19,6,minecraft:nether_wart_block)
B(14,19,6,minecraft:nether_wart_block)
B(15,19,6,minecraft:nether_wart_block)
B(10,19,7,minecraft:nether_wart_block)
B(11,19,7,minecraft:nether_wart_block)
B(12,19,7,minecraft:nether_wart_block)
B(13,19,7,minecraft:nether_wart_block)
B(14,19,7,minecraft:nether_wart_block)
B(15,19,7,minecraft:nether_wart_block)
B(10,19,8,minecraft:nether_wart_block)
B(11,19,8,minecraft:nether_wart_block)
B(12,19,8,minecraft:nether_wart_block)
B(13,19,8,minecraft:nether_wart_block)
B(14,19,8,minecraft:nether_wart_block)
B(15,19,8,minecraft:nether_wart_block)
B(12,19,9,minecraft:nether_wart_block)
B(13,19,9,minecraft:nether_wart_block)
B(14,19,9,minecraft:nether_wart_block)
B(15,19,9,minecraft:nether_wart_block)
B(11,19,10,minecraft:nether_wart_block)
B(12,19,10,minecraft:nether_wart_block)
B(13,19,10,minecraft:nether_wart_block)
B(14,19,10,minecraft:nether_wart_block)
B(15,19,10,minecraft:nether_wart_block)
B(11,19,11,minecraft:nether_wart_block)
B(12,19,11,minecraft:nether_wart_block)
B(13,19,11,minecraft:nether_wart_block)
B(14,19,11,minecraft:nether_wart_block)
B(15,19,11,minecraft:nether_wart_block)
B(11,19,12,minecraft:nether_wart_block)
B(12,19,12,minecraft:nether_wart_block)
B(13,19,12,minecraft:nether_wart_block)
B(14,19,12,minecraft:nether_wart_block)
B(15,19,12,minecraft:nether_wart_block)
B(11,19,13,minecraft:nether_wart_block)
B(12,19,13,minecraft:nether_wart_block)
B(13,19,13,minecraft:nether_wart_block)
B(14,19,13,minecraft:nether_wart_block)
B(15,19,13,minecraft:nether_wart_block)
B(10,19,14,minecraft:nether_wart_block)
B(11,19,14,minecraft:nether_wart_block)
B(12,19,14,minecraft:nether_wart_block)
B(13,19,14,minecraft:nether_wart_block)
B(14,19,14,minecraft:nether_wart_block)
B(15,19,14,minecraft:nether_wart_block)
B(10,19,15,minecraft:nether_wart_block)
B(11,19,15,minecraft:nether_wart_block)
B(12,19,15,minecraft:nether_wart_block)
B(13,19,15,minecraft:nether_wart_block)
B(14,19,15,minecraft:nether_wart_block)
B(15,19,15,minecraft:nether_wart_block)
B(10,20,0,minecraft:nether_wart_block)
B(11,20,0,minecraft:nether_wart_block)
B(12,20,0,minecraft:nether_wart_block)
B(13,20,0,minecraft:nether_wart_block)
B(14,20,0,minecraft:nether_wart_block)
B(15,20,0,minecraft:nether_wart_block)
B(10,20,1,minecraft:nether_wart_block)
B(11,20,1,minecraft:nether_wart_block)
B(12,20,1,minecraft:nether_wart_block)
B(13,20,1,minecraft:nether_wart_block)
B(14,20,1,minecraft:nether_wart_block)
B(15,20,1,minecraft:nether_wart_block)
B(10,20,2,minecraft:nether_wart_block)
B(11,20,2,minecraft:nether_wart_block)
B(12,20,2,minecraft:nether_wart_block)
B(13,20,2,minecraft:nether_wart_block)
B(14,20,2,minecraft:nether_wart_block)
B(15,20,2,minecraft:nether_wart_block)
B(10,20,3,minecraft:nether_wart_block)
B(11,20,3,minecraft:nether_wart_block)
B(12,20,3,minecraft:nether_wart_block)
B(13,20,3,minecraft:nether_wart_block)
B(14,20,3,minecraft:nether_wart_block)
B(15,20,3,minecraft:nether_wart_block)
B(10,20,4,minecraft:nether_wart_block)
B(11,20,4,minecraft:nether_wart_block)
B(12,20,4,minecraft:nether_wart_block)
B(13,20,4,minecraft:nether_wart_block)
B(14,20,4,minecraft:nether_wart_block)
B(15,20,4,minecraft:nether_wart_block)
B(10,20,5,minecraft:nether_wart_block)
B(11,20,5,minecraft:nether_wart_block)
B(12,20,5,minecraft:nether_wart_block)
B(13,20,5,minecraft:nether_wart_block)
B(14,20,5,minecraft:nether_wart_block)
B(15,20,5,minecraft:nether_wart_block)
B(10,20,6,minecraft:nether_wart_block)
B(11,20,6,minecraft:nether_wart_block)
B(12,20,6,minecraft:nether_wart_block)
B(13,20,6,minecraft:nether_wart_block)
B(14,20,6,minecraft:nether_wart_block)
B(15,20,6,minecraft:nether_wart_block)
B(10,20,7,minecraft:nether_wart_block)
B(11,20,7,minecraft:nether_wart_block)
B(12,20,7,minecraft:nether_wart_block)
B(13,20,7,minecraft:nether_wart_block)
B(14,20,7,minecraft:nether_wart_block)
B(15,20,7,minecraft:nether_wart_block)
B(10,20,8,minecraft:nether_wart_block)
B(11,20,8,minecraft:nether_wart_block)
B(12,20,8,minecraft:nether_wart_block)
B(13,20,8,minecraft:nether_wart_block)
B(14,20,8,minecraft:nether_wart_block)
B(15,20,8,minecraft:nether_wart_block)
B(12,20,9,minecraft:nether_wart_block)
B(13,20,9,minecraft:nether_wart_block)
B(14,20,9,minecraft:nether_wart_block)
B(15,20,9,minecraft:nether_wart_block)
B(11,20,10,minecraft:nether_wart_block)
B(12,20,10,minecraft:nether_wart_block)
B(13,20,10,minecraft:nether_wart_block)
B(14,20,10,minecraft:nether_wart_block)
B(15,20,10,minecraft:nether_wart_block)
B(11,20,11,minecraft:nether_wart_block)
B(12,20,11,minecraft:nether_wart_block)
B(13,20,11,minecraft:nether_wart_block)
B(14,20,11,minecraft:nether_wart_block)
B(15,20,11,minecraft:nether_wart_block)
B(11,20,12,minecraft:nether_wart_block)
B(12,20,12,minecraft:nether_wart_block)
B(13,20,12,minecraft:nether_wart_block)
B(14,20,12,minecraft:nether_wart_block)
B(15,20,12,minecraft:nether_wart_block)
B(11,20,13,minecraft:nether_wart_block)
B(12,20,13,minecraft:nether_wart_block)
B(13,20,13,minecraft:nether_wart_block)
B(14,20,13,minecraft:nether_wart_block)
B(15,20,13,minecraft:nether_wart_block)
B(10,20,14,minecraft:nether_wart_block)
B(11,20,14,minecraft:nether_wart_block)
B(12,20,14,minecraft:nether_wart_block)
B(13,20,14,minecraft:nether_wart_block)
B(14,20,14,minecraft:nether_wart_block)
B(15,20,14,minecraft:nether_wart_block)
B(10,20,15,minecraft:nether_wart_block)
B(11,20,15,minecraft:nether_wart_block)
B(12,20,15,minecraft:nether_wart_block)
B(13,20,15,minecraft:nether_wart_block)
B(14,20,15,minecraft:nether_wart_block)
B(15,20,15,minecraft:nether_wart_block)
B(10,21,0,minecraft:nether_wart_block)
B(11,21,0,minecraft:nether_wart_block)
B(12,21,0,minecraft:nether_wart_block)
B(13,21,0,minecraft:nether_wart_block)
B(14,21,0,minecraft:nether_wart_block)
B(15,21,0,minecraft:nether_wart_block)
B(10,21,1,minecraft:nether_wart_block)
B(11,21,1,minecraft:nether_wart_block)
B(12,21,1,minecraft:nether_wart_block)
B(13,21,1,minecraft:nether_wart_block)
B(14,21,1,minecraft:nether_wart_block)
B(15,21,1,minecraft:nether_wart_block)
B(10,21,2,minecraft:nether_wart_block)
B(11,21,2,minecraft:nether_wart_block)
B(12,21,2,minecraft:nether_wart_block)
B(13,21,2,minecraft:nether_wart_block)
B(14,21,2,minecraft:nether_wart_block)
B(15,21,2,minecraft:nether_wart_block)
B(10,21,3,minecraft:nether_wart_block)
B(11,21,3,minecraft:nether_wart_block)
B(12,21,3,minecraft:nether_wart_block)
B(13,21,3,minecraft:nether_wart_block)
B(14,21,3,minecraft:nether_wart_block)
B(15,21,3,minecraft:nether_wart_block)
B(10,21,4,minecraft:nether_wart_block)
B(11,21,4,minecraft:nether_wart_block)
B(12,21,4,minecraft:nether_wart_block)
B(13,21,4,minecraft:nether_wart_block)
B(14,21,4,minecraft:nether_wart_block)
B(15,21,4,minecraft:nether_wart_block)
B(10,21,5,minecraft:nether_wart_block)
B(11,21,5,minecraft:nether_wart_block)
B(12,21,5,minecraft:nether_wart_block)
B(13,21,5,minecraft:nether_wart_block)
B(14,21,5,minecraft:nether_wart_block)
B(15,21,5,minecraft:nether_wart_block)
B(10,21,6,minecraft:nether_wart_block)
B(11,21,6,minecraft:nether_wart_block)
B(12,21,6,minecraft:nether_wart_block)
B(13,21,6,minecraft:nether_wart_block)
B(14,21,6,minecraft:nether_wart_block)
B(15,21,6,minecraft:nether_wart_block)
B(10,21,7,minecraft:nether_wart_block)
B(11,21,7,minecraft:nether_wart_block)
B(12,21,7,minecraft:nether_wart_block)
B(13,21,7,minecraft:nether_wart_block)
B(14,21,7,minecraft:nether_wart_block)
B(15,21,7,minecraft:nether_wart_block)
B(10,21,8,minecraft:nether_wart_block)
B(11,21,8,minecraft:nether_wart_block)
B(12,21,8,minecraft:nether_wart_block)
B(13,21,8,minecraft:nether_wart_block)
B(14,21,8,minecraft:nether_wart_block)
B(15,21,8,minecraft:nether_wart_block)
B(12,21,9,minecraft:nether_wart_block)
B(13,21,9,minecraft:nether_wart_block)
B(14,21,9,minecraft:nether_wart_block)
B(15,21,9,minecraft:nether_wart_block)
B(11,21,10,minecraft:nether_wart_block)
B(12,21,10,minecraft:nether_wart_block)
B(13,21,10,minecraft:nether_wart_block)
B(14,21,10,minecraft:nether_wart_block)
B(15,21,10,minecraft:nether_wart_block)
B(11,21,11,minecraft:nether_wart_block)
B(12,21,11,minecraft:nether_wart_block)
B(13,21,11,minecraft:nether_wart_block)
B(14,21,11,minecraft:nether_wart_block)
B(15,21,11,minecraft:nether_wart_block)
B(11,21,12,minecraft:nether_wart_block)
B(12,21,12,minecraft:nether_wart_block)
B(13,21,12,minecraft:nether_wart_block)
B(14,21,12,minecraft:nether_wart_block)
B(15,21,12,minecraft:nether_wart_block)
B(11,21,13,minecraft:nether_wart_block)
B(12,21,13,minecraft:nether_wart_block)
B(13,21,13,minecraft:nether_wart_block)
B(14,21,13,minecraft:nether_wart_block)
B(15,21,13,minecraft:nether_wart_block)
B(10,21,14,minecraft:nether_wart_block)
B(11,21,14,minecraft:nether_wart_block)
B(12,21,14,minecraft:nether_wart_block)
B(13,21,14,minecraft:nether_wart_block)
B(14,21,14,minecraft:nether_wart_block)
B(15,21,14,minecraft:nether_wart_block)
B(10,21,15,minecraft:nether_wart_block)
B(11,21,15,minecraft:nether_wart_block)
B(12,21,15,minecraft:nether_wart_block)
B(13,21,15,minecraft:nether_wart_block)
B(14,21,15,minecraft:nether_wart_block)
B(15,21,15,minecraft:nether_wart_block)
B(10,22,0,minecraft:nether_wart_block)
B(11,22,0,minecraft:nether_wart_block)
B(12,22,0,minecraft:nether_wart_block)
B(13,22,0,minecraft:nether_wart_block)
B(14,22,0,minecraft:nether_wart_block)
B(15,22,0,minecraft:nether_wart_block)
B(10,22,1,minecraft:nether_wart_block)
B(11,22,1,minecraft:nether_wart_block)
B(12,22,1,minecraft:nether_wart_block)
B(13,22,1,minecraft:nether_wart_block)
B(14,22,1,minecraft:nether_wart_block)
B(15,22,1,minecraft:nether_wart_block)
B(10,22,2,minecraft:nether_wart_block)
B(11,22,2,minecraft:nether_wart_block)
B(12,22,2,minecraft:nether_wart_block)
B(13,22,2,minecraft:nether_wart_block)
B(14,22,2,minecraft:nether_wart_block)
B(15,22,2,minecraft:nether_wart_block)
B(10,22,3,minecraft:nether_wart_block)
B(11,22,3,minecraft:nether_wart_block)
B(12,22,3,minecraft:nether_wart_block)
B(13,22,3,minecraft:nether_wart_block)
B(14,22,3,minecraft:nether_wart_block)
B(15,22,3,minecraft:nether_wart_block)
B(10,22,4,minecraft:nether_wart_block)
B(11,22,4,minecraft:nether_wart_block)
B(12,22,4,minecraft:nether_wart_block)
B(13,22,4,minecraft:nether_wart_block)
B(14,22,4,minecraft:nether_wart_block)
B(15,22,4,minecraft:nether_wart_block)
B(10,22,5,minecraft:nether_wart_block)
B(11,22,5,minecraft:nether_wart_block)
B(12,22,5,minecraft:nether_wart_block)
B(13,22,5,minecraft:nether_wart_block)
B(14,22,5,minecraft:nether_wart_block)
B(15,22,5,minecraft:nether_wart_block)
B(10,22,6,minecraft:nether_wart_block)
B(11,22,6,minecraft:nether_wart_block)
B(12,22,6,minecraft:nether_wart_block)
B(13,22,6,minecraft:nether_wart_block)
B(14,22,6,minecraft:nether_wart_block)
B(15,22,6,minecraft:nether_wart_block)
B(10,22,7,minecraft:nether_wart_block)
B(11,22,7,minecraft:nether_wart_block)
B(12,22,7,minecraft:nether_wart_block)
B(13,22,7,minecraft:nether_wart_block)
B(14,22,7,minecraft:nether_wart_block)
B(15,22,7,minecraft:nether_wart_block)
B(10,22,8,minecraft:nether_wart_block)
B(11,22,8,minecraft:nether_wart_block)
B(12,22,8,minecraft:nether_wart_block)
B(13,22,8,minecraft:nether_wart_block)
B(14,22,8,minecraft:nether_wart_block)
B(15,22,8,minecraft:nether_wart_block)
B(12,22,9,minecraft:nether_wart_block)
B(13,22,9,minecraft:nether_wart_block)
B(14,22,9,minecraft:nether_wart_block)
B(15,22,9,minecraft:nether_wart_block)
B(11,22,10,minecraft:nether_wart_block)
B(12,22,10,minecraft:nether_wart_block)
B(13,22,10,minecraft:nether_wart_block)
B(14,22,10,minecraft:nether_wart_block)
B(15,22,10,minecraft:nether_wart_block)
B(11,22,11,minecraft:nether_wart_block)
B(12,22,11,minecraft:nether_wart_block)
B(13,22,11,minecraft:nether_wart_block)
B(14,22,11,minecraft:nether_wart_block)
B(15,22,11,minecraft:nether_wart_block)
B(11,22,12,minecraft:nether_wart_block)
B(12,22,12,minecraft:nether_wart_block)
B(13,22,12,minecraft:nether_wart_block)
B(14,22,12,minecraft:nether_wart_block)
B(15,22,12,minecraft:nether_wart_block)
B(11,22,13,minecraft:nether_wart_block)
B(12,22,13,minecraft:nether_wart_block)
B(13,22,13,minecraft:nether_wart_block)
B(14,22,13,minecraft:nether_wart_block)
B(15,22,13,minecraft:nether_wart_block)
B(10,22,14,minecraft:nether_wart_block)
B(11,22,14,minecraft:nether_wart_block)
B(12,22,14,minecraft:nether_wart_block)
B(13,22,14,minecraft:nether_wart_block)
B(14,22,14,minecraft:nether_wart_block)
B(15,22,14,minecraft:nether_wart_block)
B(10,22,15,minecraft:nether_wart_block)
B(11,22,15,minecraft:nether_wart_block)
B(12,22,15,minecraft:nether_wart_block)
B(13,22,15,minecraft:nether_wart_block)
B(14,22,15,minecraft:nether_wart_block)
B(15,22,15,minecraft:nether_wart_block)
B(10,23,0,minecraft:nether_wart_block)
B(11,23,0,minecraft:nether_wart_block)
B(12,23,0,minecraft:nether_wart_block)
B(13,23,0,minecraft:nether_wart_block)
B(14,23,0,minecraft:nether_wart_block)
B(15,23,0,minecraft:nether_wart_block)
B(10,23,1,minecraft:nether_wart_block)
B(11,23,1,minecraft:nether_wart_block)
B(12,23,1,minecraft:nether_wart_block)
B(13,23,1,minecraft:nether_wart_block)
B(14,23,1,minecraft:nether_wart_block)
B(15,23,1,minecraft:nether_wart_block)
B(10,23,2,minecraft:nether_wart_block)
B(11,23,2,minecraft:nether_wart_block)
B(12,23,2,minecraft:nether_wart_block)
B(13,23,2,minecraft:nether_wart_block)
B(14,23,2,minecraft:nether_wart_block)
B(15,23,2,minecraft:nether_wart_block)
B(10,23,3,minecraft:nether_wart_block)
B(11,23,3,minecraft:nether_wart_block)
B(12,23,3,minecraft:nether_wart_block)
B(13,23,3,minecraft:nether_wart_block)
B(14,23,3,minecraft:nether_wart_block)
B(15,23,3,minecraft:nether_wart_block)
B(10,23,4,minecraft:nether_wart_block)
B(11,23,4,minecraft:nether_wart_block)
B(12,23,4,minecraft:nether_wart_block)
B(13,23,4,minecraft:nether_wart_block)
B(14,23,4,minecraft:nether_wart_block)
B(15,23,4,minecraft:nether_wart_block)
B(10,23,5,minecraft:nether_wart_block)
B(11,23,5,minecraft:nether_wart_block)
B(12,23,5,minecraft:nether_wart_block)
B(13,23,5,minecraft:nether_wart_block)
B(14,23,5,minecraft:nether_wart_block)
B(15,23,5,minecraft:nether_wart_block)
B(10,23,6,minecraft:nether_wart_block)
B(11,23,6,minecraft:nether_wart_block)
B(12,23,6,minecraft:nether_wart_block)
B(13,23,6,minecraft:nether_wart_block)
B(14,23,6,minecraft:nether_wart_block)
B(15,23,6,minecraft:nether_wart_block)
B(10,23,7,minecraft:nether_wart_block)
B(11,23,7,minecraft:nether_wart_block)
B(12,23,7,minecraft:nether_wart_block)
B(13,23,7,minecraft:nether_wart_block)
B(14,23,7,minecraft:nether_wart_block)
B(15,23,7,minecraft:nether_wart_block)
B(10,23,8,minecraft:nether_wart_block)
B(11,23,8,minecraft:nether_wart_block)
B(12,23,8,minecraft:nether_wart_block)
B(13,23,8,minecraft:nether_wart_block)
B(14,23,8,minecraft:nether_wart_block)
B(15,23,8,minecraft:nether_wart_block)
B(12,23,9,minecraft:nether_wart_block)
B(13,23,9,minecraft:nether_wart_block)
B(14,23,9,minecraft:nether_wart_block)
B(15,23,9,minecraft:nether_wart_block)
B(11,23,10,minecraft:nether_wart_block)
B(12,23,10,minecraft:nether_wart_block)
B(13,23,10,minecraft:nether_wart_block)
B(14,23,10,minecraft:nether_wart_block)
B(15,23,10,minecraft:nether_wart_block)
B(11,23,11,minecraft:nether_wart_block)
B(12,23,11,minecraft:nether_wart_block)
B(13,23,11,minecraft:nether_wart_block)
B(14,23,11,minecraft:nether_wart_block)
B(15,23,11,minecraft:nether_wart_block)
B(11,23,12,minecraft:nether_wart_block)
B(12,23,12,minecraft:nether_wart_block)
B(13,23,12,minecraft:nether_wart_block)
B(14,23,12,minecraft:nether_wart_block)
B(15,23,12,minecraft:nether_wart_block)
B(11,23,13,minecraft:nether_wart_block)
B(12,23,13,minecraft:nether_wart_block)
B(13,23,13,minecraft:nether_wart_block)
B(14,23,13,minecraft:nether_wart_block)
B(15,23,13,minecraft:nether_wart_block)
B(10,23,14,minecraft:nether_wart_block)
B(11,23,14,minecraft:nether_wart_block)
B(12,23,14,minecraft:nether_wart_block)
B(13,23,14,minecraft:nether_wart_block)
B(14,23,14,minecraft:nether_wart_block)
B(15,23,14,minecraft:nether_wart_block)
B(10,23,15,minecraft:nether_wart_block)
B(11,23,15,minecraft:nether_wart_block)
B(12,23,15,minecraft:nether_wart_block)
B(13,23,15,minecraft:nether_wart_block)
B(14,23,15,minecraft:nether_wart_block)
B(15,23,15,minecraft:nether_wart_block)
B(10,24,0,minecraft:nether_wart_block)
B(11,24,0,minecraft:nether_wart_block)
B(12,24,0,minecraft:nether_wart_block)
B(13,24,0,minecraft:nether_wart_block)
B(14,24,0,minecraft:nether_wart_block)
B(15,24,0,minecraft:nether_wart_block)
B(10,24,1,minecraft:nether_wart_block)
B(11,24,1,minecraft:nether_wart_block)
B(12,24,1,minecraft:nether_wart_block)
B(13,24,1,minecraft:nether_wart_block)
B(14,24,1,minecraft:nether_wart_block)
B(15,24,1,minecraft:nether_wart_block)
B(10,24,2,minecraft:nether_wart_block)
B(11,24,2,minecraft:nether_wart_block)
B(12,24,2,minecraft:nether_wart_block)
B(13,24,2,minecraft:nether_wart_block)
B(14,24,2,minecraft:nether_wart_block)
B(15,24,2,minecraft:nether_wart_block)
B(10,24,3,minecraft:nether_wart_block)
B(11,24,3,minecraft:nether_wart_block)
B(12,24,3,minecraft:nether_wart_block)
B(13,24,3,minecraft:nether_wart_block)
B(14,24,3,minecraft:nether_wart_block)
B(15,24,3,minecraft:nether_wart_block)
B(10,24,4,minecraft:nether_wart_block)
B(11,24,4,minecraft:nether_wart_block)
B(12,24,4,minecraft:nether_wart_block)
B(13,24,4,minecraft:nether_wart_block)
B(14,24,4,minecraft:nether_wart_block)
B(15,24,4,minecraft:nether_wart_block)
B(10,24,5,minecraft:nether_wart_block)
B(11,24,5,minecraft:nether_wart_block)
B(12,24,5,minecraft:nether_wart_block)
B(13,24,5,minecraft:nether_wart_block)
B(14,24,5,minecraft:nether_wart_block)
B(15,24,5,minecraft:nether_wart_block)
B(10,24,6,minecraft:nether_wart_block)
B(11,24,6,minecraft:nether_wart_block)
B(12,24,6,minecraft:nether_wart_block)
B(13,24,6,minecraft:nether_wart_block)
B(14,24,6,minecraft:nether_wart_block)
B(15,24,6,minecraft:nether_wart_block)
B(10,24,7,minecraft:nether_wart_block)
B(11,24,7,minecraft:nether_wart_block)
B(12,24,7,minecraft:nether_wart_block)
B(13,24,7,minecraft:nether_wart_block)
B(14,24,7,minecraft:nether_wart_block)
B(15,24,7,minecraft:nether_wart_block)
B(10,24,8,minecraft:nether_wart_block)
B(11,24,8,minecraft:nether_wart_block)
B(12,24,8,minecraft:nether_wart_block)
B(13,24,8,minecraft:nether_wart_block)
B(14,24,8,minecraft:nether_wart_block)
B(15,24,8,minecraft:nether_wart_block)
B(12,24,9,minecraft:nether_wart_block)
B(13,24,9,minecraft:nether_wart_block)
B(14,24,9,minecraft:nether_wart_block)
B(15,24,9,minecraft:nether_wart_block)
B(11,24,10,minecraft:nether_wart_block)
B(12,24,10,minecraft:nether_wart_block)
B(13,24,10,minecraft:nether_wart_block)
B(14,24,10,minecraft:nether_wart_block)
B(15,24,10,minecraft:nether_wart_block)
B(11,24,11,minecraft:nether_wart_block)
B(12,24,11,minecraft:nether_wart_block)
B(13,24,11,minecraft:nether_wart_block)
B(14,24,11,minecraft:nether_wart_block)
B(15,24,11,minecraft:nether_wart_block)
B(11,24,12,minecraft:nether_wart_block)
B(12,24,12,minecraft:nether_wart_block)
B(13,24,12,minecraft:nether_wart_block)
B(14,24,12,minecraft:nether_wart_block)
B(15,24,12,minecraft:nether_wart_block)
B(11,24,13,minecraft:nether_wart_block)
B(12,24,13,minecraft:nether_wart_block)
B(13,24,13,minecraft:nether_wart_block)
B(14,24,13,minecraft:nether_wart_block)
B(15,24,13,minecraft:nether_wart_block)
B(10,24,14,minecraft:nether_wart_block)
B(11,24,14,minecraft:nether_wart_block)
B(12,24,14,minecraft:nether_wart_block)
B(13,24,14,minecraft:nether_wart_block)
B(14,24,14,minecraft:nether_wart_block)
B(15,24,14,minecraft:nether_wart_block)
B(10,24,15,minecraft:nether_wart_block)
B(11,24,15,minecraft:nether_wart_block)
B(12,24,15,minecraft:nether_wart_block)
B(13,24,15,minecraft:nether_wart_block)
B(14,24,15,minecraft:nether_wart_block)
B(15,24,15,minecraft:nether_wart_block)
B(10,25,0,minecraft:nether_wart_block)
B(11,25,0,minecraft:nether_wart_block)
B(12,25,0,minecraft:nether_wart_block)
B(13,25,0,minecraft:nether_wart_block)
B(14,25,0,minecraft:nether_wart_block)
B(15,25,0,minecraft:nether_wart_block)
B(10,25,1,minecraft:nether_wart_block)
B(11,25,1,minecraft:nether_wart_block)
B(12,25,1,minecraft:nether_wart_block)
B(13,25,1,minecraft:nether_wart_block)
B(14,25,1,minecraft:nether_wart_block)
B(15,25,1,minecraft:nether_wart_block)
B(10,25,2,minecraft:nether_wart_block)
B(11,25,2,minecraft:nether_wart_block)
B(12,25,2,minecraft:nether_wart_block)
B(13,25,2,minecraft:nether_wart_block)
B(14,25,2,minecraft:nether_wart_block)
B(15,25,2,minecraft:nether_wart_block)
B(10,25,3,minecraft:nether_wart_block)
B(11,25,3,minecraft:nether_wart_block)
B(12,25,3,minecraft:nether_wart_block)
B(13,25,3,minecraft:nether_wart_block)
B(14,25,3,minecraft:nether_wart_block)
B(15,25,3,minecraft:nether_wart_block)
B(10,25,4,minecraft:nether_wart_block)
B(11,25,4,minecraft:nether_wart_block)
B(12,25,4,minecraft:nether_wart_block)
B(13,25,4,minecraft:nether_wart_block)
B(14,25,4,minecraft:nether_wart_block)
B(15,25,4,minecraft:nether_wart_block)
B(10,25,5,minecraft:nether_wart_block)
B(11,25,5,minecraft:nether_wart_block)
B(12,25,5,minecraft:nether_wart_block)
B(13,25,5,minecraft:nether_wart_block)
B(14,25,5,minecraft:nether_wart_block)
B(15,25,5,minecraft:nether_wart_block)
B(10,25,6,minecraft:nether_wart_block)
B(11,25,6,minecraft:nether_wart_block)
B(12,25,6,minecraft:nether_wart_block)
B(13,25,6,minecraft:nether_wart_block)
B(14,25,6,minecraft:nether_wart_block)
B(15,25,6,minecraft:nether_wart_block)
B(10,25,7,minecraft:nether_wart_block)
B(11,25,7,minecraft:nether_wart_block)
B(12,25,7,minecraft:nether_wart_block)
B(13,25,7,minecraft:nether_wart_block)
B(14,25,7,minecraft:nether_wart_block)
B(15,25,7,minecraft:nether_wart_block)
B(10,25,8,minecraft:nether_wart_block)
B(11,25,8,minecraft:nether_wart_block)
B(12,25,8,minecraft:nether_wart_block)
B(13,25,8,minecraft:nether_wart_block)
B(14,25,8,minecraft:nether_wart_block)
B(15,25,8,minecraft:nether_wart_block)
B(12,25,9,minecraft:nether_wart_block)
B(13,25,9,minecraft:nether_wart_block)
B(14,25,9,minecraft:nether_wart_block)
B(15,25,9,minecraft:nether_wart_block)
B(11,25,10,minecraft:nether_wart_block)
B(12,25,10,minecraft:nether_wart_block)
B(13,25,10,minecraft:nether_wart_block)
B(14,25,10,minecraft:nether_wart_block)
B(15,25,10,minecraft:nether_wart_block)
B(11,25,11,minecraft:nether_wart_block)
B(12,25,11,minecraft:nether_wart_block)
B(13,25,11,minecraft:nether_wart_block)
B(14,25,11,minecraft:nether_wart_block)
B(15,25,11,minecraft:nether_wart_block)
B(11,25,12,minecraft:nether_wart_block)
B(12,25,12,minecraft:nether_wart_block)
B(13,25,12,minecraft:nether_wart_block)
B(14,25,12,minecraft:nether_wart_block)
B(15,25,12,minecraft:nether_wart_block)
B(11,25,13,minecraft:nether_wart_block)
B(12,25,13,minecraft:nether_wart_block)
B(13,25,13,minecraft:nether_wart_block)
B(14,25,13,minecraft:nether_wart_block)
B(15,25,13,minecraft:nether_wart_block)
B(11,25,14,minecraft:nether_wart_block)
B(12,25,14,minecraft:nether_wart_block)
B(13,25,14,minecraft:nether_wart_block)
B(14,25,14,minecraft:nether_wart_block)
B(15,25,14,minecraft:nether_wart_block)
B(11,25,15,minecraft:nether_wart_block)
B(12,25,15,minecraft:nether_wart_block)
B(13,25,15,minecraft:nether_wart_block)
B(14,25,15,minecraft:nether_wart_block)
B(15,25,15,minecraft:nether_wart_block)
B(10,26,0,minecraft:nether_wart_block)
B(11,26,0,minecraft:nether_wart_block)
B(12,26,0,minecraft:nether_wart_block)
B(13,26,0,minecraft:nether_wart_block)
B(14,26,0,minecraft:nether_wart_block)
B(15,26,0,minecraft:nether_wart_block)
B(10,26,1,minecraft:nether_wart_block)
B(11,26,1,minecraft:nether_wart_block)
B(12,26,1,minecraft:nether_wart_block)
B(13,26,1,minecraft:nether_wart_block)
B(14,26,1,minecraft:nether_wart_block)
B(15,26,1,minecraft:nether_wart_block)
B(10,26,2,minecraft:nether_wart_block)
B(11,26,2,minecraft:nether_wart_block)
B(12,26,2,minecraft:nether_wart_block)
B(13,26,2,minecraft:nether_wart_block)
B(14,26,2,minecraft:nether_wart_block)
B(15,26,2,minecraft:nether_wart_block)
B(10,26,3,minecraft:nether_wart_block)
B(11,26,3,minecraft:nether_wart_block)
B(12,26,3,minecraft:nether_wart_block)
B(13,26,3,minecraft:nether_wart_block)
B(14,26,3,minecraft:nether_wart_block)
B(15,26,3,minecraft:nether_wart_block)
B(10,26,4,minecraft:nether_wart_block)
B(11,26,4,minecraft:nether_wart_block)
B(12,26,4,minecraft:nether_wart_block)
B(13,26,4,minecraft:nether_wart_block)
B(14,26,4,minecraft:nether_wart_block)
B(15,26,4,minecraft:nether_wart_block)
B(10,26,5,minecraft:nether_wart_block)
B(11,26,5,minecraft:nether_wart_block)
