Author: Bo3 BulkEdit

Description: Converted Schematic - Modified by Bo3BulkEdit

Version: 3

SettingsMode: WriteDisable

IsOTGPlus: true
Tree: false
Frequency: 10
Rarity: 100
RotateRandomly: true
SpawnHeight: randomY
SpawnHeightOffset: 0
SpawnHeightVariance: 0
MaxBranchDepth: 10
ExcludedBiomes: All

MinHeight: 50
MaxHeight: 65

SourceBlocks: AIR
MaxPercentageOutsideSourceBlock: 100
OutsideSourceBlock: placeAnyway

ReplaceBelow: NETHER_WART_BLOCK
ReplaceWithBiomeBlocks: false
ReplaceWithGroundBlock: NETHER_WART_BLOCK
ReplaceWithSurfaceBlock: NETHER_WART_BLOCK
ReplaceWithStoneBlock: NETHER_WART_BLOCK
SmoothRadius: 30
SmoothHeightOffset: 0
SmoothStartTop: false
SmoothStartWood: false
SmoothingSurfaceBlock: NETHER_WART_BLOCK
SmoothingGroundBlock: NETHER_WART_BLOCK

B(0,750,0,AIR)
B(15,750,15,AIR)
B(0,0,0,minecraft:nether_wart_block)
B(1,0,0,minecraft:nether_wart_block)
B(2,0,0,minecraft:nether_wart_block)
B(3,0,0,minecraft:nether_wart_block)
B(4,0,0,minecraft:nether_wart_block)
B(5,0,0,minecraft:nether_wart_block)
B(6,0,0,minecraft:nether_wart_block)
B(7,0,0,minecraft:nether_wart_block)
B(0,0,1,minecraft:nether_wart_block)
B(1,0,1,minecraft:nether_wart_block)
B(2,0,1,minecraft:nether_wart_block)
B(3,0,1,minecraft:nether_wart_block)
B(4,0,1,minecraft:nether_wart_block)
B(5,0,1,minecraft:nether_wart_block)
B(0,0,2,minecraft:nether_wart_block)
B(1,0,2,minecraft:nether_wart_block)
B(2,0,2,minecraft:nether_wart_block)
B(3,0,2,minecraft:nether_wart_block)
B(0,0,3,minecraft:nether_wart_block)
B(1,0,3,minecraft:nether_wart_block)
B(2,0,3,minecraft:nether_wart_block)
B(3,0,3,minecraft:nether_wart_block)
B(0,0,4,minecraft:nether_wart_block)
B(1,0,4,minecraft:nether_wart_block)
B(2,0,4,minecraft:nether_wart_block)
B(3,0,4,minecraft:nether_wart_block)
B(0,0,5,minecraft:nether_wart_block)
B(1,0,5,minecraft:nether_wart_block)
B(2,0,5,minecraft:nether_wart_block)
B(3,0,5,minecraft:nether_wart_block)
B(4,0,5,minecraft:nether_wart_block)
B(0,0,6,minecraft:nether_wart_block)
B(1,0,6,minecraft:nether_wart_block)
B(2,0,6,minecraft:nether_wart_block)
B(3,0,6,minecraft:nether_wart_block)
B(4,0,6,minecraft:nether_wart_block)
B(0,0,7,minecraft:nether_wart_block)
B(1,0,7,minecraft:nether_wart_block)
B(2,0,7,minecraft:nether_wart_block)
B(3,0,7,minecraft:nether_wart_block)
B(4,0,7,minecraft:nether_wart_block)
B(5,0,7,minecraft:nether_wart_block)
B(0,0,8,minecraft:nether_wart_block)
B(1,0,8,minecraft:nether_wart_block)
B(2,0,8,minecraft:nether_wart_block)
B(3,0,8,minecraft:nether_wart_block)
B(4,0,8,minecraft:nether_wart_block)
B(5,0,8,minecraft:nether_wart_block)
B(6,0,8,minecraft:nether_wart_block)
B(0,0,9,minecraft:nether_wart_block)
B(1,0,9,minecraft:nether_wart_block)
B(2,0,9,minecraft:nether_wart_block)
B(3,0,9,minecraft:nether_wart_block)
B(4,0,9,minecraft:nether_wart_block)
B(5,0,9,minecraft:nether_wart_block)
B(6,0,9,minecraft:nether_wart_block)
B(0,0,10,minecraft:nether_wart_block)
B(1,0,10,minecraft:nether_wart_block)
B(2,0,10,minecraft:nether_wart_block)
B(3,0,10,minecraft:nether_wart_block)
B(4,0,10,minecraft:nether_wart_block)
B(5,0,10,minecraft:nether_wart_block)
B(6,0,10,minecraft:nether_wart_block)
B(0,0,11,minecraft:nether_wart_block)
B(1,0,11,minecraft:nether_wart_block)
B(2,0,11,minecraft:nether_wart_block)
B(3,0,11,minecraft:nether_wart_block)
B(4,0,11,minecraft:nether_wart_block)
B(5,0,11,minecraft:nether_wart_block)
B(6,0,11,minecraft:nether_wart_block)
B(0,0,12,minecraft:nether_wart_block)
B(1,0,12,minecraft:nether_wart_block)
B(2,0,12,minecraft:nether_wart_block)
B(3,0,12,minecraft:nether_wart_block)
B(4,0,12,minecraft:nether_wart_block)
B(5,0,12,minecraft:nether_wart_block)
B(6,0,12,minecraft:nether_wart_block)
B(0,0,13,minecraft:nether_wart_block)
B(1,0,13,minecraft:nether_wart_block)
B(2,0,13,minecraft:nether_wart_block)
B(3,0,13,minecraft:nether_wart_block)
B(4,0,13,minecraft:nether_wart_block)
B(5,0,13,minecraft:nether_wart_block)
B(6,0,13,minecraft:nether_wart_block)
B(0,0,14,minecraft:nether_wart_block)
B(1,0,14,minecraft:nether_wart_block)
B(2,0,14,minecraft:nether_wart_block)
B(3,0,14,minecraft:nether_wart_block)
B(4,0,14,minecraft:nether_wart_block)
B(5,0,14,minecraft:nether_wart_block)
B(0,0,15,minecraft:nether_wart_block)
B(1,0,15,minecraft:nether_wart_block)
B(2,0,15,minecraft:nether_wart_block)
B(3,0,15,minecraft:nether_wart_block)
B(4,0,15,minecraft:nether_wart_block)
B(0,1,0,minecraft:nether_wart_block)
B(1,1,0,minecraft:nether_wart_block)
B(2,1,0,minecraft:nether_wart_block)
B(3,1,0,minecraft:nether_wart_block)
B(4,1,0,minecraft:nether_wart_block)
B(5,1,0,minecraft:nether_wart_block)
B(6,1,0,minecraft:nether_wart_block)
B(0,1,1,minecraft:nether_wart_block)
B(1,1,1,minecraft:nether_wart_block)
B(2,1,1,minecraft:nether_wart_block)
B(3,1,1,minecraft:nether_wart_block)
B(4,1,1,minecraft:nether_wart_block)
B(5,1,1,minecraft:nether_wart_block)
B(0,1,2,minecraft:nether_wart_block)
B(1,1,2,minecraft:nether_wart_block)
B(2,1,2,minecraft:nether_wart_block)
B(3,1,2,minecraft:nether_wart_block)
B(0,1,3,minecraft:nether_wart_block)
B(1,1,3,minecraft:nether_wart_block)
B(2,1,3,minecraft:nether_wart_block)
B(3,1,3,minecraft:nether_wart_block)
B(0,1,4,minecraft:nether_wart_block)
B(1,1,4,minecraft:nether_wart_block)
B(2,1,4,minecraft:nether_wart_block)
B(3,1,4,minecraft:nether_wart_block)
B(0,1,5,minecraft:nether_wart_block)
B(1,1,5,minecraft:nether_wart_block)
B(2,1,5,minecraft:nether_wart_block)
B(3,1,5,minecraft:nether_wart_block)
B(4,1,5,minecraft:nether_wart_block)
B(0,1,6,minecraft:nether_wart_block)
B(1,1,6,minecraft:nether_wart_block)
B(2,1,6,minecraft:nether_wart_block)
B(3,1,6,minecraft:nether_wart_block)
B(4,1,6,minecraft:nether_wart_block)
B(0,1,7,minecraft:nether_wart_block)
B(1,1,7,minecraft:nether_wart_block)
B(2,1,7,minecraft:nether_wart_block)
B(3,1,7,minecraft:nether_wart_block)
B(4,1,7,minecraft:nether_wart_block)
B(5,1,7,minecraft:nether_wart_block)
B(0,1,8,minecraft:nether_wart_block)
B(1,1,8,minecraft:nether_wart_block)
B(2,1,8,minecraft:nether_wart_block)
B(3,1,8,minecraft:nether_wart_block)
B(4,1,8,minecraft:nether_wart_block)
B(5,1,8,minecraft:nether_wart_block)
B(6,1,8,minecraft:nether_wart_block)
B(0,1,9,minecraft:nether_wart_block)
B(1,1,9,minecraft:nether_wart_block)
B(2,1,9,minecraft:nether_wart_block)
B(3,1,9,minecraft:nether_wart_block)
B(4,1,9,minecraft:nether_wart_block)
B(5,1,9,minecraft:nether_wart_block)
B(6,1,9,minecraft:nether_wart_block)
B(0,1,10,minecraft:nether_wart_block)
B(1,1,10,minecraft:nether_wart_block)
B(2,1,10,minecraft:nether_wart_block)
B(3,1,10,minecraft:nether_wart_block)
B(4,1,10,minecraft:nether_wart_block)
B(5,1,10,minecraft:nether_wart_block)
B(6,1,10,minecraft:nether_wart_block)
B(0,1,11,minecraft:nether_wart_block)
B(1,1,11,minecraft:nether_wart_block)
B(2,1,11,minecraft:nether_wart_block)
B(3,1,11,minecraft:nether_wart_block)
B(4,1,11,minecraft:nether_wart_block)
B(5,1,11,minecraft:nether_wart_block)
B(6,1,11,minecraft:nether_wart_block)
B(0,1,12,minecraft:nether_wart_block)
B(1,1,12,minecraft:nether_wart_block)
B(2,1,12,minecraft:nether_wart_block)
B(3,1,12,minecraft:nether_wart_block)
B(4,1,12,minecraft:nether_wart_block)
B(5,1,12,minecraft:nether_wart_block)
B(6,1,12,minecraft:nether_wart_block)
B(0,1,13,minecraft:nether_wart_block)
B(1,1,13,minecraft:nether_wart_block)
B(2,1,13,minecraft:nether_wart_block)
B(3,1,13,minecraft:nether_wart_block)
B(4,1,13,minecraft:nether_wart_block)
B(5,1,13,minecraft:nether_wart_block)
B(6,1,13,minecraft:nether_wart_block)
B(0,1,14,minecraft:nether_wart_block)
B(1,1,14,minecraft:nether_wart_block)
B(2,1,14,minecraft:nether_wart_block)
B(3,1,14,minecraft:nether_wart_block)
B(4,1,14,minecraft:nether_wart_block)
B(5,1,14,minecraft:nether_wart_block)
B(0,1,15,minecraft:nether_wart_block)
B(1,1,15,minecraft:nether_wart_block)
B(2,1,15,minecraft:nether_wart_block)
B(3,1,15,minecraft:nether_wart_block)
B(4,1,15,minecraft:nether_wart_block)
B(0,2,0,minecraft:nether_wart_block)
B(1,2,0,minecraft:nether_wart_block)
B(2,2,0,minecraft:nether_wart_block)
B(3,2,0,minecraft:nether_wart_block)
B(4,2,0,minecraft:nether_wart_block)
B(5,2,0,minecraft:nether_wart_block)
B(6,2,0,minecraft:nether_wart_block)
B(0,2,1,minecraft:nether_wart_block)
B(1,2,1,minecraft:nether_wart_block)
B(2,2,1,minecraft:nether_wart_block)
B(3,2,1,minecraft:nether_wart_block)
B(4,2,1,minecraft:nether_wart_block)
B(5,2,1,minecraft:nether_wart_block)
B(0,2,2,minecraft:nether_wart_block)
B(1,2,2,minecraft:nether_wart_block)
B(2,2,2,minecraft:nether_wart_block)
B(3,2,2,minecraft:nether_wart_block)
B(0,2,3,minecraft:nether_wart_block)
B(1,2,3,minecraft:nether_wart_block)
B(2,2,3,minecraft:nether_wart_block)
B(3,2,3,minecraft:nether_wart_block)
B(0,2,4,minecraft:nether_wart_block)
B(1,2,4,minecraft:nether_wart_block)
B(2,2,4,minecraft:nether_wart_block)
B(3,2,4,minecraft:nether_wart_block)
B(0,2,5,minecraft:nether_wart_block)
B(1,2,5,minecraft:nether_wart_block)
B(2,2,5,minecraft:nether_wart_block)
B(3,2,5,minecraft:nether_wart_block)
B(0,2,6,minecraft:nether_wart_block)
B(1,2,6,minecraft:nether_wart_block)
B(2,2,6,minecraft:nether_wart_block)
B(3,2,6,minecraft:nether_wart_block)
B(4,2,6,minecraft:nether_wart_block)
B(0,2,7,minecraft:nether_wart_block)
B(1,2,7,minecraft:nether_wart_block)
B(2,2,7,minecraft:nether_wart_block)
B(3,2,7,minecraft:nether_wart_block)
B(4,2,7,minecraft:nether_wart_block)
B(5,2,7,minecraft:nether_wart_block)
B(0,2,8,minecraft:nether_wart_block)
B(1,2,8,minecraft:nether_wart_block)
B(2,2,8,minecraft:nether_wart_block)
B(3,2,8,minecraft:nether_wart_block)
B(4,2,8,minecraft:nether_wart_block)
B(5,2,8,minecraft:nether_wart_block)
B(0,2,9,minecraft:nether_wart_block)
B(1,2,9,minecraft:nether_wart_block)
B(2,2,9,minecraft:nether_wart_block)
B(3,2,9,minecraft:nether_wart_block)
B(4,2,9,minecraft:nether_wart_block)
B(5,2,9,minecraft:nether_wart_block)
B(6,2,9,minecraft:nether_wart_block)
B(0,2,10,minecraft:nether_wart_block)
B(1,2,10,minecraft:nether_wart_block)
B(2,2,10,minecraft:nether_wart_block)
B(3,2,10,minecraft:nether_wart_block)
B(4,2,10,minecraft:nether_wart_block)
B(5,2,10,minecraft:nether_wart_block)
B(6,2,10,minecraft:nether_wart_block)
B(0,2,11,minecraft:nether_wart_block)
B(1,2,11,minecraft:nether_wart_block)
B(2,2,11,minecraft:nether_wart_block)
B(3,2,11,minecraft:nether_wart_block)
B(4,2,11,minecraft:nether_wart_block)
B(5,2,11,minecraft:nether_wart_block)
B(6,2,11,minecraft:nether_wart_block)
B(0,2,12,minecraft:nether_wart_block)
B(1,2,12,minecraft:nether_wart_block)
B(2,2,12,minecraft:nether_wart_block)
B(3,2,12,minecraft:nether_wart_block)
B(4,2,12,minecraft:nether_wart_block)
B(5,2,12,minecraft:nether_wart_block)
B(6,2,12,minecraft:nether_wart_block)
B(0,2,13,minecraft:nether_wart_block)
B(1,2,13,minecraft:nether_wart_block)
B(2,2,13,minecraft:nether_wart_block)
B(3,2,13,minecraft:nether_wart_block)
B(4,2,13,minecraft:nether_wart_block)
B(5,2,13,minecraft:nether_wart_block)
B(0,2,14,minecraft:nether_wart_block)
B(1,2,14,minecraft:nether_wart_block)
B(2,2,14,minecraft:nether_wart_block)
B(3,2,14,minecraft:nether_wart_block)
B(4,2,14,minecraft:nether_wart_block)
B(0,2,15,minecraft:nether_wart_block)
B(1,2,15,minecraft:nether_wart_block)
B(2,2,15,minecraft:nether_wart_block)
B(3,2,15,minecraft:nether_wart_block)
B(4,2,15,minecraft:nether_wart_block)
B(0,3,0,minecraft:nether_wart_block)
B(1,3,0,minecraft:nether_wart_block)
B(2,3,0,minecraft:nether_wart_block)
B(3,3,0,minecraft:nether_wart_block)
B(4,3,0,minecraft:nether_wart_block)
B(5,3,0,minecraft:nether_wart_block)
B(6,3,0,minecraft:nether_wart_block)
B(0,3,1,minecraft:nether_wart_block)
B(1,3,1,minecraft:nether_wart_block)
B(2,3,1,minecraft:nether_wart_block)
B(3,3,1,minecraft:nether_wart_block)
B(4,3,1,minecraft:nether_wart_block)
B(0,3,2,minecraft:nether_wart_block)
B(1,3,2,minecraft:nether_wart_block)
B(2,3,2,minecraft:nether_wart_block)
B(3,3,2,minecraft:nether_wart_block)
B(0,3,3,minecraft:nether_wart_block)
B(1,3,3,minecraft:nether_wart_block)
B(2,3,3,minecraft:nether_wart_block)
B(3,3,3,minecraft:nether_wart_block)
B(0,3,4,minecraft:nether_wart_block)
B(1,3,4,minecraft:nether_wart_block)
B(2,3,4,minecraft:nether_wart_block)
B(3,3,4,minecraft:nether_wart_block)
B(0,3,5,minecraft:nether_wart_block)
B(1,3,5,minecraft:nether_wart_block)
B(2,3,5,minecraft:nether_wart_block)
B(3,3,5,minecraft:nether_wart_block)
B(0,3,6,minecraft:nether_wart_block)
B(1,3,6,minecraft:nether_wart_block)
B(2,3,6,minecraft:nether_wart_block)
B(3,3,6,minecraft:nether_wart_block)
B(4,3,6,minecraft:nether_wart_block)
B(0,3,7,minecraft:nether_wart_block)
B(1,3,7,minecraft:nether_wart_block)
B(2,3,7,minecraft:nether_wart_block)
B(3,3,7,minecraft:nether_wart_block)
B(4,3,7,minecraft:nether_wart_block)
B(0,3,8,minecraft:nether_wart_block)
B(1,3,8,minecraft:nether_wart_block)
B(2,3,8,minecraft:nether_wart_block)
B(3,3,8,minecraft:nether_wart_block)
B(4,3,8,minecraft:nether_wart_block)
B(5,3,8,minecraft:nether_wart_block)
B(0,3,9,minecraft:nether_wart_block)
B(1,3,9,minecraft:nether_wart_block)
B(2,3,9,minecraft:nether_wart_block)
B(3,3,9,minecraft:nether_wart_block)
B(4,3,9,minecraft:nether_wart_block)
B(5,3,9,minecraft:nether_wart_block)
B(6,3,9,minecraft:nether_wart_block)
B(0,3,10,minecraft:nether_wart_block)
B(1,3,10,minecraft:nether_wart_block)
B(2,3,10,minecraft:nether_wart_block)
B(3,3,10,minecraft:nether_wart_block)
B(4,3,10,minecraft:nether_wart_block)
B(5,3,10,minecraft:nether_wart_block)
B(6,3,10,minecraft:nether_wart_block)
B(0,3,11,minecraft:nether_wart_block)
B(1,3,11,minecraft:nether_wart_block)
B(2,3,11,minecraft:nether_wart_block)
B(3,3,11,minecraft:nether_wart_block)
B(4,3,11,minecraft:nether_wart_block)
B(5,3,11,minecraft:nether_wart_block)
B(6,3,11,minecraft:nether_wart_block)
B(0,3,12,minecraft:nether_wart_block)
B(1,3,12,minecraft:nether_wart_block)
B(2,3,12,minecraft:nether_wart_block)
B(3,3,12,minecraft:nether_wart_block)
B(4,3,12,minecraft:nether_wart_block)
B(5,3,12,minecraft:nether_wart_block)
B(6,3,12,minecraft:nether_wart_block)
B(0,3,13,minecraft:nether_wart_block)
B(1,3,13,minecraft:nether_wart_block)
B(2,3,13,minecraft:nether_wart_block)
B(3,3,13,minecraft:nether_wart_block)
B(4,3,13,minecraft:nether_wart_block)
B(5,3,13,minecraft:nether_wart_block)
B(0,3,14,minecraft:nether_wart_block)
B(1,3,14,minecraft:nether_wart_block)
B(2,3,14,minecraft:nether_wart_block)
B(3,3,14,minecraft:nether_wart_block)
B(4,3,14,minecraft:nether_wart_block)
B(0,3,15,minecraft:nether_wart_block)
B(1,3,15,minecraft:nether_wart_block)
B(2,3,15,minecraft:nether_wart_block)
B(3,3,15,minecraft:nether_wart_block)
B(4,3,15,minecraft:nether_wart_block)
B(0,4,0,minecraft:nether_wart_block)
B(1,4,0,minecraft:nether_wart_block)
B(2,4,0,minecraft:nether_wart_block)
B(3,4,0,minecraft:nether_wart_block)
B(4,4,0,minecraft:nether_wart_block)
B(5,4,0,minecraft:nether_wart_block)
B(6,4,0,minecraft:nether_wart_block)
B(0,4,1,minecraft:nether_wart_block)
B(1,4,1,minecraft:nether_wart_block)
B(2,4,1,minecraft:nether_wart_block)
B(3,4,1,minecraft:nether_wart_block)
B(4,4,1,minecraft:nether_wart_block)
B(0,4,2,minecraft:nether_wart_block)
B(1,4,2,minecraft:nether_wart_block)
B(2,4,2,minecraft:nether_wart_block)
B(3,4,2,minecraft:nether_wart_block)
B(0,4,3,minecraft:nether_wart_block)
B(1,4,3,minecraft:nether_wart_block)
B(2,4,3,minecraft:nether_wart_block)
B(3,4,3,minecraft:nether_wart_block)
B(0,4,4,minecraft:nether_wart_block)
B(1,4,4,minecraft:nether_wart_block)
B(2,4,4,minecraft:nether_wart_block)
B(3,4,4,minecraft:nether_wart_block)
B(0,4,5,minecraft:nether_wart_block)
B(1,4,5,minecraft:nether_wart_block)
B(2,4,5,minecraft:nether_wart_block)
B(3,4,5,minecraft:nether_wart_block)
B(0,4,6,minecraft:nether_wart_block)
B(1,4,6,minecraft:nether_wart_block)
B(2,4,6,minecraft:nether_wart_block)
B(3,4,6,minecraft:nether_wart_block)
B(4,4,6,minecraft:nether_wart_block)
B(0,4,7,minecraft:nether_wart_block)
B(1,4,7,minecraft:nether_wart_block)
B(2,4,7,minecraft:nether_wart_block)
B(3,4,7,minecraft:nether_wart_block)
B(4,4,7,minecraft:nether_wart_block)
B(0,4,8,minecraft:nether_wart_block)
B(1,4,8,minecraft:nether_wart_block)
B(2,4,8,minecraft:nether_wart_block)
B(3,4,8,minecraft:nether_wart_block)
B(4,4,8,minecraft:nether_wart_block)
B(5,4,8,minecraft:nether_wart_block)
B(0,4,9,minecraft:nether_wart_block)
B(1,4,9,minecraft:nether_wart_block)
B(2,4,9,minecraft:nether_wart_block)
B(3,4,9,minecraft:nether_wart_block)
B(4,4,9,minecraft:nether_wart_block)
B(5,4,9,minecraft:nether_wart_block)
B(6,4,9,minecraft:nether_wart_block)
B(0,4,10,minecraft:nether_wart_block)
B(1,4,10,minecraft:nether_wart_block)
B(2,4,10,minecraft:nether_wart_block)
B(3,4,10,minecraft:nether_wart_block)
B(4,4,10,minecraft:nether_wart_block)
B(5,4,10,minecraft:nether_wart_block)
B(6,4,10,minecraft:nether_wart_block)
B(0,4,11,minecraft:nether_wart_block)
B(1,4,11,minecraft:nether_wart_block)
B(2,4,11,minecraft:nether_wart_block)
B(3,4,11,minecraft:nether_wart_block)
B(4,4,11,minecraft:nether_wart_block)
B(5,4,11,minecraft:nether_wart_block)
B(6,4,11,minecraft:nether_wart_block)
B(0,4,12,minecraft:nether_wart_block)
B(1,4,12,minecraft:nether_wart_block)
B(2,4,12,minecraft:nether_wart_block)
B(3,4,12,minecraft:nether_wart_block)
B(4,4,12,minecraft:nether_wart_block)
B(5,4,12,minecraft:nether_wart_block)
B(6,4,12,minecraft:nether_wart_block)
B(0,4,13,minecraft:nether_wart_block)
B(1,4,13,minecraft:nether_wart_block)
B(2,4,13,minecraft:nether_wart_block)
B(3,4,13,minecraft:nether_wart_block)
B(4,4,13,minecraft:nether_wart_block)
B(5,4,13,minecraft:nether_wart_block)
B(0,4,14,minecraft:nether_wart_block)
B(1,4,14,minecraft:nether_wart_block)
B(2,4,14,minecraft:nether_wart_block)
B(3,4,14,minecraft:nether_wart_block)
B(4,4,14,minecraft:nether_wart_block)
B(0,4,15,minecraft:nether_wart_block)
B(1,4,15,minecraft:nether_wart_block)
B(2,4,15,minecraft:nether_wart_block)
B(3,4,15,minecraft:nether_wart_block)
B(4,4,15,minecraft:nether_wart_block)
B(0,5,0,minecraft:nether_wart_block)
B(1,5,0,minecraft:nether_wart_block)
B(2,5,0,minecraft:nether_wart_block)
B(3,5,0,minecraft:nether_wart_block)
B(4,5,0,minecraft:nether_wart_block)
B(5,5,0,minecraft:nether_wart_block)
B(6,5,0,minecraft:nether_wart_block)
B(0,5,1,minecraft:nether_wart_block)
B(1,5,1,minecraft:nether_wart_block)
B(2,5,1,minecraft:nether_wart_block)
B(3,5,1,minecraft:nether_wart_block)
B(0,5,2,minecraft:nether_wart_block)
B(1,5,2,minecraft:nether_wart_block)
B(2,5,2,minecraft:nether_wart_block)
B(3,5,2,minecraft:nether_wart_block)
B(0,5,3,minecraft:nether_wart_block)
B(1,5,3,minecraft:nether_wart_block)
B(2,5,3,minecraft:nether_wart_block)
B(3,5,3,minecraft:nether_wart_block)
B(0,5,4,minecraft:nether_wart_block)
B(1,5,4,minecraft:nether_wart_block)
B(2,5,4,minecraft:nether_wart_block)
B(3,5,4,minecraft:nether_wart_block)
B(0,5,5,minecraft:nether_wart_block)
B(1,5,5,minecraft:nether_wart_block)
B(2,5,5,minecraft:nether_wart_block)
B(3,5,5,minecraft:nether_wart_block)
B(0,5,6,minecraft:nether_wart_block)
B(1,5,6,minecraft:nether_wart_block)
B(2,5,6,minecraft:nether_wart_block)
B(3,5,6,minecraft:nether_wart_block)
B(4,5,6,minecraft:nether_wart_block)
B(0,5,7,minecraft:nether_wart_block)
B(1,5,7,minecraft:nether_wart_block)
B(2,5,7,minecraft:nether_wart_block)
B(3,5,7,minecraft:nether_wart_block)
B(4,5,7,minecraft:nether_wart_block)
B(0,5,8,minecraft:nether_wart_block)
B(1,5,8,minecraft:nether_wart_block)
B(2,5,8,minecraft:nether_wart_block)
B(3,5,8,minecraft:nether_wart_block)
B(4,5,8,minecraft:nether_wart_block)
B(5,5,8,minecraft:nether_wart_block)
B(0,5,9,minecraft:nether_wart_block)
B(1,5,9,minecraft:nether_wart_block)
B(2,5,9,minecraft:nether_wart_block)
B(3,5,9,minecraft:nether_wart_block)
B(4,5,9,minecraft:nether_wart_block)
B(5,5,9,minecraft:nether_wart_block)
B(6,5,9,minecraft:nether_wart_block)
B(0,5,10,minecraft:nether_wart_block)
B(1,5,10,minecraft:nether_wart_block)
B(2,5,10,minecraft:nether_wart_block)
B(3,5,10,minecraft:nether_wart_block)
B(4,5,10,minecraft:nether_wart_block)
B(5,5,10,minecraft:nether_wart_block)
B(6,5,10,minecraft:nether_wart_block)
B(0,5,11,minecraft:nether_wart_block)
B(1,5,11,minecraft:nether_wart_block)
B(2,5,11,minecraft:nether_wart_block)
B(3,5,11,minecraft:nether_wart_block)
B(4,5,11,minecraft:nether_wart_block)
B(5,5,11,minecraft:nether_wart_block)
B(6,5,11,minecraft:nether_wart_block)
B(0,5,12,minecraft:nether_wart_block)
B(1,5,12,minecraft:nether_wart_block)
B(2,5,12,minecraft:nether_wart_block)
B(3,5,12,minecraft:nether_wart_block)
B(4,5,12,minecraft:nether_wart_block)
B(5,5,12,minecraft:nether_wart_block)
B(0,5,13,minecraft:nether_wart_block)
B(1,5,13,minecraft:nether_wart_block)
B(2,5,13,minecraft:nether_wart_block)
B(3,5,13,minecraft:nether_wart_block)
B(4,5,13,minecraft:nether_wart_block)
B(5,5,13,minecraft:nether_wart_block)
B(0,5,14,minecraft:nether_wart_block)
B(1,5,14,minecraft:nether_wart_block)
B(2,5,14,minecraft:nether_wart_block)
B(3,5,14,minecraft:nether_wart_block)
B(4,5,14,minecraft:nether_wart_block)
B(0,5,15,minecraft:nether_wart_block)
B(1,5,15,minecraft:nether_wart_block)
B(2,5,15,minecraft:nether_wart_block)
B(3,5,15,minecraft:nether_wart_block)
B(4,5,15,minecraft:nether_wart_block)
B(0,6,0,minecraft:nether_wart_block)
B(1,6,0,minecraft:nether_wart_block)
B(2,6,0,minecraft:nether_wart_block)
B(3,6,0,minecraft:nether_wart_block)
B(0,6,1,minecraft:nether_wart_block)
B(1,6,1,minecraft:nether_wart_block)
B(2,6,1,minecraft:nether_wart_block)
B(3,6,1,minecraft:nether_wart_block)
B(0,6,2,minecraft:nether_wart_block)
B(1,6,2,minecraft:nether_wart_block)
B(2,6,2,minecraft:nether_wart_block)
B(0,6,3,minecraft:nether_wart_block)
B(1,6,3,minecraft:nether_wart_block)
B(2,6,3,minecraft:nether_wart_block)
B(3,6,3,minecraft:nether_wart_block)
B(0,6,4,minecraft:nether_wart_block)
B(1,6,4,minecraft:nether_wart_block)
B(2,6,4,minecraft:nether_wart_block)
B(3,6,4,minecraft:nether_wart_block)
B(0,6,5,minecraft:nether_wart_block)
B(1,6,5,minecraft:nether_wart_block)
B(2,6,5,minecraft:nether_wart_block)
B(3,6,5,minecraft:nether_wart_block)
B(0,6,6,minecraft:nether_wart_block)
B(1,6,6,minecraft:nether_wart_block)
B(2,6,6,minecraft:nether_wart_block)
B(3,6,6,minecraft:nether_wart_block)
B(4,6,6,minecraft:nether_wart_block)
B(0,6,7,minecraft:nether_wart_block)
B(1,6,7,minecraft:nether_wart_block)
B(2,6,7,minecraft:nether_wart_block)
B(3,6,7,minecraft:nether_wart_block)
B(4,6,7,minecraft:nether_wart_block)
B(0,6,8,minecraft:nether_wart_block)
B(1,6,8,minecraft:nether_wart_block)
B(2,6,8,minecraft:nether_wart_block)
B(3,6,8,minecraft:nether_wart_block)
B(4,6,8,minecraft:nether_wart_block)
B(0,6,9,minecraft:nether_wart_block)
B(1,6,9,minecraft:nether_wart_block)
B(2,6,9,minecraft:nether_wart_block)
B(3,6,9,minecraft:nether_wart_block)
B(4,6,9,minecraft:nether_wart_block)
B(5,6,9,minecraft:nether_wart_block)
B(0,6,10,minecraft:nether_wart_block)
B(1,6,10,minecraft:nether_wart_block)
B(2,6,10,minecraft:nether_wart_block)
B(3,6,10,minecraft:nether_wart_block)
B(4,6,10,minecraft:nether_wart_block)
B(5,6,10,minecraft:nether_wart_block)
B(0,6,11,minecraft:nether_wart_block)
B(1,6,11,minecraft:nether_wart_block)
B(2,6,11,minecraft:nether_wart_block)
B(3,6,11,minecraft:nether_wart_block)
B(4,6,11,minecraft:nether_wart_block)
B(5,6,11,minecraft:nether_wart_block)
B(0,6,12,minecraft:nether_wart_block)
B(1,6,12,minecraft:nether_wart_block)
B(2,6,12,minecraft:nether_wart_block)
B(3,6,12,minecraft:nether_wart_block)
B(4,6,12,minecraft:nether_wart_block)
B(5,6,12,minecraft:nether_wart_block)
B(0,6,13,minecraft:nether_wart_block)
B(1,6,13,minecraft:nether_wart_block)
B(2,6,13,minecraft:nether_wart_block)
B(3,6,13,minecraft:nether_wart_block)
B(4,6,13,minecraft:nether_wart_block)
B(5,6,13,minecraft:nether_wart_block)
B(0,6,14,minecraft:nether_wart_block)
B(1,6,14,minecraft:nether_wart_block)
B(2,6,14,minecraft:nether_wart_block)
B(3,6,14,minecraft:nether_wart_block)
B(4,6,14,minecraft:nether_wart_block)
B(0,6,15,minecraft:nether_wart_block)
B(1,6,15,minecraft:nether_wart_block)
B(2,6,15,minecraft:nether_wart_block)
B(3,6,15,minecraft:nether_wart_block)
B(4,6,15,minecraft:nether_wart_block)
B(0,7,0,minecraft:nether_wart_block)
B(1,7,0,minecraft:nether_wart_block)
B(2,7,0,minecraft:nether_wart_block)
B(3,7,0,minecraft:nether_wart_block)
B(0,7,1,minecraft:nether_wart_block)
B(1,7,1,minecraft:nether_wart_block)
B(2,7,1,minecraft:nether_wart_block)
B(3,7,1,minecraft:nether_wart_block)
B(0,7,2,minecraft:nether_wart_block)
B(1,7,2,minecraft:nether_wart_block)
B(2,7,2,minecraft:nether_wart_block)
B(0,7,3,minecraft:nether_wart_block)
B(1,7,3,minecraft:nether_wart_block)
B(2,7,3,minecraft:nether_wart_block)
B(3,7,3,minecraft:nether_wart_block)
B(0,7,4,minecraft:nether_wart_block)
B(1,7,4,minecraft:nether_wart_block)
B(2,7,4,minecraft:nether_wart_block)
B(3,7,4,minecraft:nether_wart_block)
B(0,7,5,minecraft:nether_wart_block)
B(1,7,5,minecraft:nether_wart_block)
B(2,7,5,minecraft:nether_wart_block)
B(3,7,5,minecraft:nether_wart_block)
B(0,7,6,minecraft:nether_wart_block)
B(1,7,6,minecraft:nether_wart_block)
B(2,7,6,minecraft:nether_wart_block)
B(3,7,6,minecraft:nether_wart_block)
B(4,7,6,minecraft:nether_wart_block)
B(0,7,7,minecraft:nether_wart_block)
B(1,7,7,minecraft:nether_wart_block)
B(2,7,7,minecraft:nether_wart_block)
B(3,7,7,minecraft:nether_wart_block)
B(4,7,7,minecraft:nether_wart_block)
B(0,7,8,minecraft:nether_wart_block)
B(1,7,8,minecraft:nether_wart_block)
B(2,7,8,minecraft:nether_wart_block)
B(3,7,8,minecraft:nether_wart_block)
B(4,7,8,minecraft:nether_wart_block)
B(0,7,9,minecraft:nether_wart_block)
B(1,7,9,minecraft:nether_wart_block)
B(2,7,9,minecraft:nether_wart_block)
B(3,7,9,minecraft:nether_wart_block)
B(4,7,9,minecraft:nether_wart_block)
B(0,7,10,minecraft:nether_wart_block)
B(1,7,10,minecraft:nether_wart_block)
B(2,7,10,minecraft:nether_wart_block)
B(3,7,10,minecraft:nether_wart_block)
B(4,7,10,minecraft:nether_wart_block)
B(5,7,10,minecraft:nether_wart_block)
B(0,7,11,minecraft:nether_wart_block)
B(1,7,11,minecraft:nether_wart_block)
B(2,7,11,minecraft:nether_wart_block)
B(3,7,11,minecraft:nether_wart_block)
B(4,7,11,minecraft:nether_wart_block)
B(5,7,11,minecraft:nether_wart_block)
B(0,7,12,minecraft:nether_wart_block)
B(1,7,12,minecraft:nether_wart_block)
B(2,7,12,minecraft:nether_wart_block)
B(3,7,12,minecraft:nether_wart_block)
B(4,7,12,minecraft:nether_wart_block)
B(5,7,12,minecraft:nether_wart_block)
B(0,7,13,minecraft:nether_wart_block)
B(1,7,13,minecraft:nether_wart_block)
B(2,7,13,minecraft:nether_wart_block)
B(3,7,13,minecraft:nether_wart_block)
B(4,7,13,minecraft:nether_wart_block)
B(0,7,14,minecraft:nether_wart_block)
B(1,7,14,minecraft:nether_wart_block)
B(2,7,14,minecraft:nether_wart_block)
B(3,7,14,minecraft:nether_wart_block)
B(4,7,14,minecraft:nether_wart_block)
B(0,7,15,minecraft:nether_wart_block)
B(1,7,15,minecraft:nether_wart_block)
B(2,7,15,minecraft:nether_wart_block)
B(3,7,15,minecraft:nether_wart_block)
B(4,7,15,minecraft:nether_wart_block)
B(0,8,0,minecraft:nether_wart_block)
B(1,8,0,minecraft:nether_wart_block)
B(2,8,0,minecraft:nether_wart_block)
B(3,8,0,minecraft:nether_wart_block)
B(0,8,1,minecraft:nether_wart_block)
B(1,8,1,minecraft:nether_wart_block)
B(2,8,1,minecraft:nether_wart_block)
B(0,8,2,minecraft:nether_wart_block)
B(1,8,2,minecraft:nether_wart_block)
B(2,8,2,minecraft:nether_wart_block)
B(0,8,3,minecraft:nether_wart_block)
B(1,8,3,minecraft:nether_wart_block)
B(2,8,3,minecraft:nether_wart_block)
B(3,8,3,minecraft:nether_wart_block)
B(0,8,4,minecraft:nether_wart_block)
B(1,8,4,minecraft:nether_wart_block)
B(2,8,4,minecraft:nether_wart_block)
B(3,8,4,minecraft:nether_wart_block)
B(0,8,5,minecraft:nether_wart_block)
B(1,8,5,minecraft:nether_wart_block)
B(2,8,5,minecraft:nether_wart_block)
B(3,8,5,minecraft:nether_wart_block)
B(0,8,6,minecraft:nether_wart_block)
B(1,8,6,minecraft:nether_wart_block)
B(2,8,6,minecraft:nether_wart_block)
B(3,8,6,minecraft:nether_wart_block)
B(0,8,7,minecraft:nether_wart_block)
B(1,8,7,minecraft:nether_wart_block)
B(2,8,7,minecraft:nether_wart_block)
B(3,8,7,minecraft:nether_wart_block)
B(4,8,7,minecraft:nether_wart_block)
B(0,8,8,minecraft:nether_wart_block)
B(1,8,8,minecraft:nether_wart_block)
B(2,8,8,minecraft:nether_wart_block)
B(3,8,8,minecraft:nether_wart_block)
B(4,8,8,minecraft:nether_wart_block)
B(0,8,9,minecraft:nether_wart_block)
B(1,8,9,minecraft:nether_wart_block)
B(2,8,9,minecraft:nether_wart_block)
B(3,8,9,minecraft:nether_wart_block)
B(0,8,10,minecraft:nether_wart_block)
B(1,8,10,minecraft:nether_wart_block)
B(2,8,10,minecraft:nether_wart_block)
B(3,8,10,minecraft:nether_wart_block)
B(4,8,10,minecraft:nether_wart_block)
B(0,8,11,minecraft:nether_wart_block)
B(1,8,11,minecraft:nether_wart_block)
B(2,8,11,minecraft:nether_wart_block)
B(3,8,11,minecraft:nether_wart_block)
B(4,8,11,minecraft:nether_wart_block)
B(0,8,12,minecraft:nether_wart_block)
B(1,8,12,minecraft:nether_wart_block)
B(2,8,12,minecraft:nether_wart_block)
B(3,8,12,minecraft:nether_wart_block)
B(4,8,12,minecraft:nether_wart_block)
B(0,8,13,minecraft:nether_wart_block)
B(1,8,13,minecraft:nether_wart_block)
B(2,8,13,minecraft:nether_wart_block)
B(3,8,13,minecraft:nether_wart_block)
B(4,8,13,minecraft:nether_wart_block)
B(0,8,14,minecraft:nether_wart_block)
B(1,8,14,minecraft:nether_wart_block)
B(2,8,14,minecraft:nether_wart_block)
B(3,8,14,minecraft:nether_wart_block)
B(4,8,14,minecraft:nether_wart_block)
B(0,8,15,minecraft:nether_wart_block)
B(1,8,15,minecraft:nether_wart_block)
B(2,8,15,minecraft:nether_wart_block)
B(3,8,15,minecraft:nether_wart_block)
B(4,8,15,minecraft:nether_wart_block)
B(0,9,0,minecraft:nether_wart_block)
B(1,9,0,minecraft:nether_wart_block)
B(2,9,0,minecraft:nether_wart_block)
B(3,9,0,minecraft:nether_wart_block)
B(0,9,1,minecraft:nether_wart_block)
B(1,9,1,minecraft:nether_wart_block)
B(2,9,1,minecraft:nether_wart_block)
B(0,9,2,minecraft:nether_wart_block)
B(1,9,2,minecraft:nether_wart_block)
B(2,9,2,minecraft:nether_wart_block)
B(0,9,3,minecraft:nether_wart_block)
B(1,9,3,minecraft:nether_wart_block)
B(2,9,3,minecraft:nether_wart_block)
B(3,9,3,minecraft:nether_wart_block)
B(0,9,4,minecraft:nether_wart_block)
B(1,9,4,minecraft:nether_wart_block)
B(2,9,4,minecraft:nether_wart_block)
B(3,9,4,minecraft:nether_wart_block)
B(0,9,5,minecraft:nether_wart_block)
B(1,9,5,minecraft:nether_wart_block)
B(2,9,5,minecraft:nether_wart_block)
B(3,9,5,minecraft:nether_wart_block)
B(0,9,6,minecraft:nether_wart_block)
B(1,9,6,minecraft:nether_wart_block)
B(2,9,6,minecraft:nether_wart_block)
B(3,9,6,minecraft:nether_wart_block)
B(0,9,7,minecraft:nether_wart_block)
B(1,9,7,minecraft:nether_wart_block)
B(2,9,7,minecraft:nether_wart_block)
B(3,9,7,minecraft:nether_wart_block)
B(4,9,7,minecraft:nether_wart_block)
B(0,9,8,minecraft:nether_wart_block)
B(1,9,8,minecraft:nether_wart_block)
B(2,9,8,minecraft:nether_wart_block)
B(3,9,8,minecraft:nether_wart_block)
B(4,9,8,minecraft:nether_wart_block)
B(0,9,9,minecraft:nether_wart_block)
B(1,9,9,minecraft:nether_wart_block)
B(2,9,9,minecraft:nether_wart_block)
B(3,9,9,minecraft:nether_wart_block)
B(0,9,10,minecraft:nether_wart_block)
B(1,9,10,minecraft:nether_wart_block)
B(2,9,10,minecraft:nether_wart_block)
B(3,9,10,minecraft:nether_wart_block)
B(4,9,10,minecraft:nether_wart_block)
B(0,9,11,minecraft:nether_wart_block)
B(1,9,11,minecraft:nether_wart_block)
B(2,9,11,minecraft:nether_wart_block)
B(3,9,11,minecraft:nether_wart_block)
B(4,9,11,minecraft:nether_wart_block)
B(0,9,12,minecraft:nether_wart_block)
B(1,9,12,minecraft:nether_wart_block)
B(2,9,12,minecraft:nether_wart_block)
B(3,9,12,minecraft:nether_wart_block)
B(4,9,12,minecraft:nether_wart_block)
B(0,9,13,minecraft:nether_wart_block)
B(1,9,13,minecraft:nether_wart_block)
B(2,9,13,minecraft:nether_wart_block)
B(3,9,13,minecraft:nether_wart_block)
B(4,9,13,minecraft:nether_wart_block)
B(0,9,14,minecraft:nether_wart_block)
B(1,9,14,minecraft:nether_wart_block)
B(2,9,14,minecraft:nether_wart_block)
B(3,9,14,minecraft:nether_wart_block)
B(4,9,14,minecraft:nether_wart_block)
B(0,9,15,minecraft:nether_wart_block)
B(1,9,15,minecraft:nether_wart_block)
B(2,9,15,minecraft:nether_wart_block)
B(3,9,15,minecraft:nether_wart_block)
B(4,9,15,minecraft:nether_wart_block)
B(0,10,0,minecraft:nether_wart_block)
B(1,10,0,minecraft:nether_wart_block)
B(2,10,0,minecraft:nether_wart_block)
B(3,10,0,minecraft:nether_wart_block)
B(0,10,1,minecraft:nether_wart_block)
B(1,10,1,minecraft:nether_wart_block)
B(2,10,1,minecraft:nether_wart_block)
B(0,10,2,minecraft:nether_wart_block)
B(1,10,2,minecraft:nether_wart_block)
B(2,10,2,minecraft:nether_wart_block)
B(0,10,3,minecraft:nether_wart_block)
B(1,10,3,minecraft:nether_wart_block)
B(2,10,3,minecraft:nether_wart_block)
B(3,10,3,minecraft:nether_wart_block)
B(0,10,4,minecraft:nether_wart_block)
B(1,10,4,minecraft:nether_wart_block)
B(2,10,4,minecraft:nether_wart_block)
B(3,10,4,minecraft:nether_wart_block)
B(0,10,5,minecraft:nether_wart_block)
B(1,10,5,minecraft:nether_wart_block)
B(2,10,5,minecraft:nether_wart_block)
B(3,10,5,minecraft:nether_wart_block)
B(0,10,6,minecraft:nether_wart_block)
B(1,10,6,minecraft:nether_wart_block)
B(2,10,6,minecraft:nether_wart_block)
B(3,10,6,minecraft:nether_wart_block)
B(0,10,7,minecraft:nether_wart_block)
B(1,10,7,minecraft:nether_wart_block)
B(2,10,7,minecraft:nether_wart_block)
B(3,10,7,minecraft:nether_wart_block)
B(4,10,7,minecraft:nether_wart_block)
B(0,10,8,minecraft:nether_wart_block)
B(1,10,8,minecraft:nether_wart_block)
B(2,10,8,minecraft:nether_wart_block)
B(3,10,8,minecraft:nether_wart_block)
B(4,10,8,minecraft:nether_wart_block)
B(0,10,9,minecraft:nether_wart_block)
B(1,10,9,minecraft:nether_wart_block)
B(2,10,9,minecraft:nether_wart_block)
B(3,10,9,minecraft:nether_wart_block)
B(0,10,10,minecraft:nether_wart_block)
B(1,10,10,minecraft:nether_wart_block)
B(2,10,10,minecraft:nether_wart_block)
B(3,10,10,minecraft:nether_wart_block)
B(0,10,11,minecraft:nether_wart_block)
B(1,10,11,minecraft:nether_wart_block)
B(2,10,11,minecraft:nether_wart_block)
B(3,10,11,minecraft:nether_wart_block)
B(0,10,12,minecraft:nether_wart_block)
B(1,10,12,minecraft:nether_wart_block)
B(2,10,12,minecraft:nether_wart_block)
B(3,10,12,minecraft:nether_wart_block)
B(4,10,12,minecraft:nether_wart_block)
B(0,10,13,minecraft:nether_wart_block)
B(1,10,13,minecraft:nether_wart_block)
B(2,10,13,minecraft:nether_wart_block)
B(3,10,13,minecraft:nether_wart_block)
B(4,10,13,minecraft:nether_wart_block)
B(0,10,14,minecraft:nether_wart_block)
B(1,10,14,minecraft:nether_wart_block)
B(2,10,14,minecraft:nether_wart_block)
B(3,10,14,minecraft:nether_wart_block)
B(4,10,14,minecraft:nether_wart_block)
B(0,10,15,minecraft:nether_wart_block)
B(1,10,15,minecraft:nether_wart_block)
B(2,10,15,minecraft:nether_wart_block)
B(3,10,15,minecraft:nether_wart_block)
B(4,10,15,minecraft:nether_wart_block)
B(0,11,0,minecraft:nether_wart_block)
B(1,11,0,minecraft:nether_wart_block)
B(2,11,0,minecraft:nether_wart_block)
B(3,11,0,minecraft:nether_wart_block)
B(0,11,1,minecraft:nether_wart_block)
B(1,11,1,minecraft:nether_wart_block)
B(2,11,1,minecraft:nether_wart_block)
B(0,11,2,minecraft:nether_wart_block)
B(1,11,2,minecraft:nether_wart_block)
B(2,11,2,minecraft:nether_wart_block)
B(0,11,3,minecraft:nether_wart_block)
B(1,11,3,minecraft:nether_wart_block)
B(2,11,3,minecraft:nether_wart_block)
B(3,11,3,minecraft:nether_wart_block)
B(0,11,4,minecraft:nether_wart_block)
B(1,11,4,minecraft:nether_wart_block)
B(2,11,4,minecraft:nether_wart_block)
B(0,11,5,minecraft:nether_wart_block)
B(1,11,5,minecraft:nether_wart_block)
B(2,11,5,minecraft:nether_wart_block)
B(3,11,5,minecraft:nether_wart_block)
B(0,11,6,minecraft:nether_wart_block)
B(1,11,6,minecraft:nether_wart_block)
B(2,11,6,minecraft:nether_wart_block)
B(3,11,6,minecraft:nether_wart_block)
B(0,11,7,minecraft:nether_wart_block)
B(1,11,7,minecraft:nether_wart_block)
B(2,11,7,minecraft:nether_wart_block)
B(3,11,7,minecraft:nether_wart_block)
B(4,11,7,minecraft:nether_wart_block)
B(0,11,8,minecraft:nether_wart_block)
B(1,11,8,minecraft:nether_wart_block)
B(2,11,8,minecraft:nether_wart_block)
B(3,11,8,minecraft:nether_wart_block)
B(0,11,9,minecraft:nether_wart_block)
B(1,11,9,minecraft:nether_wart_block)
B(2,11,9,minecraft:nether_wart_block)
B(3,11,9,minecraft:nether_wart_block)
B(0,11,10,minecraft:nether_wart_block)
B(1,11,10,minecraft:nether_wart_block)
B(2,11,10,minecraft:nether_wart_block)
B(3,11,10,minecraft:nether_wart_block)
B(0,11,11,minecraft:nether_wart_block)
B(1,11,11,minecraft:nether_wart_block)
B(2,11,11,minecraft:nether_wart_block)
B(3,11,11,minecraft:nether_wart_block)
B(0,11,12,minecraft:nether_wart_block)
B(1,11,12,minecraft:nether_wart_block)
B(2,11,12,minecraft:nether_wart_block)
B(3,11,12,minecraft:nether_wart_block)
B(0,11,13,minecraft:nether_wart_block)
B(1,11,13,minecraft:nether_wart_block)
B(2,11,13,minecraft:nether_wart_block)
B(3,11,13,minecraft:nether_wart_block)
B(4,11,13,minecraft:nether_wart_block)
B(0,11,14,minecraft:nether_wart_block)
B(1,11,14,minecraft:nether_wart_block)
B(2,11,14,minecraft:nether_wart_block)
B(3,11,14,minecraft:nether_wart_block)
B(4,11,14,minecraft:nether_wart_block)
B(0,11,15,minecraft:nether_wart_block)
B(1,11,15,minecraft:nether_wart_block)
B(2,11,15,minecraft:nether_wart_block)
B(3,11,15,minecraft:nether_wart_block)
B(4,11,15,minecraft:nether_wart_block)
B(0,12,0,minecraft:nether_wart_block)
B(1,12,0,minecraft:nether_wart_block)
B(2,12,0,minecraft:nether_wart_block)
B(3,12,0,minecraft:nether_wart_block)
B(0,12,1,minecraft:nether_wart_block)
B(1,12,1,minecraft:nether_wart_block)
B(2,12,1,minecraft:nether_wart_block)
B(0,12,2,minecraft:nether_wart_block)
B(1,12,2,minecraft:nether_wart_block)
B(2,12,2,minecraft:nether_wart_block)
B(0,12,3,minecraft:nether_wart_block)
B(1,12,3,minecraft:nether_wart_block)
B(2,12,3,minecraft:nether_wart_block)
B(3,12,3,minecraft:nether_wart_block)
B(0,12,4,minecraft:nether_wart_block)
B(1,12,4,minecraft:nether_wart_block)
B(2,12,4,minecraft:nether_wart_block)
B(0,12,5,minecraft:nether_wart_block)
B(1,12,5,minecraft:nether_wart_block)
B(2,12,5,minecraft:nether_wart_block)
B(3,12,5,minecraft:nether_wart_block)
B(0,12,6,minecraft:nether_wart_block)
B(1,12,6,minecraft:nether_wart_block)
B(2,12,6,minecraft:nether_wart_block)
B(3,12,6,minecraft:nether_wart_block)
B(0,12,7,minecraft:nether_wart_block)
B(1,12,7,minecraft:nether_wart_block)
B(2,12,7,minecraft:nether_wart_block)
B(3,12,7,minecraft:nether_wart_block)
B(4,12,7,minecraft:nether_wart_block)
B(0,12,8,minecraft:nether_wart_block)
B(1,12,8,minecraft:nether_wart_block)
B(2,12,8,minecraft:nether_wart_block)
B(3,12,8,minecraft:nether_wart_block)
B(0,12,9,minecraft:nether_wart_block)
B(1,12,9,minecraft:nether_wart_block)
B(2,12,9,minecraft:nether_wart_block)
B(3,12,9,minecraft:nether_wart_block)
B(0,12,10,minecraft:nether_wart_block)
B(1,12,10,minecraft:nether_wart_block)
B(2,12,10,minecraft:nether_wart_block)
B(3,12,10,minecraft:nether_wart_block)
B(0,12,11,minecraft:nether_wart_block)
B(1,12,11,minecraft:nether_wart_block)
B(2,12,11,minecraft:nether_wart_block)
B(3,12,11,minecraft:nether_wart_block)
B(0,12,12,minecraft:nether_wart_block)
B(1,12,12,minecraft:nether_wart_block)
B(2,12,12,minecraft:nether_wart_block)
B(3,12,12,minecraft:nether_wart_block)
B(0,12,13,minecraft:nether_wart_block)
B(1,12,13,minecraft:nether_wart_block)
B(2,12,13,minecraft:nether_wart_block)
B(3,12,13,minecraft:nether_wart_block)
B(0,12,14,minecraft:nether_wart_block)
B(1,12,14,minecraft:nether_wart_block)
B(2,12,14,minecraft:nether_wart_block)
B(3,12,14,minecraft:nether_wart_block)
B(4,12,14,minecraft:nether_wart_block)
B(0,12,15,minecraft:nether_wart_block)
B(1,12,15,minecraft:nether_wart_block)
B(2,12,15,minecraft:nether_wart_block)
B(3,12,15,minecraft:nether_wart_block)
B(0,13,0,minecraft:nether_wart_block)
B(1,13,0,minecraft:nether_wart_block)
B(2,13,0,minecraft:nether_wart_block)
B(3,13,0,minecraft:nether_wart_block)
B(0,13,1,minecraft:nether_wart_block)
B(1,13,1,minecraft:nether_wart_block)
B(2,13,1,minecraft:nether_wart_block)
B(0,13,2,minecraft:nether_wart_block)
B(1,13,2,minecraft:nether_wart_block)
B(2,13,2,minecraft:nether_wart_block)
B(0,13,3,minecraft:nether_wart_block)
B(1,13,3,minecraft:nether_wart_block)
B(2,13,3,minecraft:nether_wart_block)
B(0,13,4,minecraft:nether_wart_block)
B(1,13,4,minecraft:nether_wart_block)
B(2,13,4,minecraft:nether_wart_block)
B(0,13,5,minecraft:nether_wart_block)
B(1,13,5,minecraft:nether_wart_block)
B(2,13,5,minecraft:nether_wart_block)
B(3,13,5,minecraft:nether_wart_block)
B(0,13,6,minecraft:nether_wart_block)
B(1,13,6,minecraft:nether_wart_block)
B(2,13,6,minecraft:nether_wart_block)
B(3,13,6,minecraft:nether_wart_block)
B(0,13,7,minecraft:nether_wart_block)
B(1,13,7,minecraft:nether_wart_block)
B(2,13,7,minecraft:nether_wart_block)
B(3,13,7,minecraft:nether_wart_block)
B(0,13,8,minecraft:nether_wart_block)
B(1,13,8,minecraft:nether_wart_block)
B(2,13,8,minecraft:nether_wart_block)
B(3,13,8,minecraft:nether_wart_block)
B(0,13,9,minecraft:nether_wart_block)
B(1,13,9,minecraft:nether_wart_block)
B(2,13,9,minecraft:nether_wart_block)
B(3,13,9,minecraft:nether_wart_block)
B(0,13,10,minecraft:nether_wart_block)
B(1,13,10,minecraft:nether_wart_block)
B(2,13,10,minecraft:nether_wart_block)
B(3,13,10,minecraft:nether_wart_block)
B(0,13,11,minecraft:nether_wart_block)
B(1,13,11,minecraft:nether_wart_block)
B(2,13,11,minecraft:nether_wart_block)
B(3,13,11,minecraft:nether_wart_block)
B(0,13,12,minecraft:nether_wart_block)
B(1,13,12,minecraft:nether_wart_block)
B(2,13,12,minecraft:nether_wart_block)
B(3,13,12,minecraft:nether_wart_block)
B(0,13,13,minecraft:nether_wart_block)
B(1,13,13,minecraft:nether_wart_block)
B(2,13,13,minecraft:nether_wart_block)
B(3,13,13,minecraft:nether_wart_block)
B(0,13,14,minecraft:nether_wart_block)
B(1,13,14,minecraft:nether_wart_block)
B(2,13,14,minecraft:nether_wart_block)
B(3,13,14,minecraft:nether_wart_block)
B(4,13,14,minecraft:nether_wart_block)
B(0,13,15,minecraft:nether_wart_block)
B(1,13,15,minecraft:nether_wart_block)
B(2,13,15,minecraft:nether_wart_block)
B(3,13,15,minecraft:nether_wart_block)
B(0,14,0,minecraft:nether_wart_block)
B(1,14,0,minecraft:nether_wart_block)
B(2,14,0,minecraft:nether_wart_block)
B(3,14,0,minecraft:nether_wart_block)
B(0,14,1,minecraft:nether_wart_block)
B(1,14,1,minecraft:nether_wart_block)
B(2,14,1,minecraft:nether_wart_block)
B(0,14,2,minecraft:nether_wart_block)
B(1,14,2,minecraft:nether_wart_block)
B(2,14,2,minecraft:nether_wart_block)
B(0,14,3,minecraft:nether_wart_block)
B(1,14,3,minecraft:nether_wart_block)
B(2,14,3,minecraft:nether_wart_block)
B(0,14,4,minecraft:nether_wart_block)
B(1,14,4,minecraft:nether_wart_block)
B(2,14,4,minecraft:nether_wart_block)
B(0,14,5,minecraft:nether_wart_block)
B(1,14,5,minecraft:nether_wart_block)
B(2,14,5,minecraft:nether_wart_block)
B(0,14,6,minecraft:nether_wart_block)
B(1,14,6,minecraft:nether_wart_block)
B(2,14,6,minecraft:nether_wart_block)
B(3,14,6,minecraft:nether_wart_block)
B(0,14,7,minecraft:nether_wart_block)
B(1,14,7,minecraft:nether_wart_block)
B(2,14,7,minecraft:nether_wart_block)
B(3,14,7,minecraft:nether_wart_block)
B(0,14,8,minecraft:nether_wart_block)
B(1,14,8,minecraft:nether_wart_block)
B(2,14,8,minecraft:nether_wart_block)
B(3,14,8,minecraft:nether_wart_block)
B(0,14,9,minecraft:nether_wart_block)
B(1,14,9,minecraft:nether_wart_block)
B(2,14,9,minecraft:nether_wart_block)
B(3,14,9,minecraft:nether_wart_block)
B(0,14,10,minecraft:nether_wart_block)
B(1,14,10,minecraft:nether_wart_block)
B(2,14,10,minecraft:nether_wart_block)
B(3,14,10,minecraft:nether_wart_block)
B(0,14,11,minecraft:nether_wart_block)
B(1,14,11,minecraft:nether_wart_block)
B(2,14,11,minecraft:nether_wart_block)
B(3,14,11,minecraft:nether_wart_block)
B(0,14,12,minecraft:nether_wart_block)
B(1,14,12,minecraft:nether_wart_block)
B(2,14,12,minecraft:nether_wart_block)
B(3,14,12,minecraft:nether_wart_block)
B(0,14,13,minecraft:nether_wart_block)
B(1,14,13,minecraft:nether_wart_block)
B(2,14,13,minecraft:nether_wart_block)
B(3,14,13,minecraft:nether_wart_block)
B(0,14,14,minecraft:nether_wart_block)
B(1,14,14,minecraft:nether_wart_block)
B(2,14,14,minecraft:nether_wart_block)
B(3,14,14,minecraft:nether_wart_block)
B(4,14,14,minecraft:nether_wart_block)
B(0,14,15,minecraft:nether_wart_block)
B(1,14,15,minecraft:nether_wart_block)
B(2,14,15,minecraft:nether_wart_block)
B(3,14,15,minecraft:nether_wart_block)
B(0,15,0,minecraft:nether_wart_block)
B(1,15,0,minecraft:nether_wart_block)
B(2,15,0,minecraft:nether_wart_block)
B(3,15,0,minecraft:nether_wart_block)
B(0,15,1,minecraft:nether_wart_block)
B(1,15,1,minecraft:nether_wart_block)
B(2,15,1,minecraft:nether_wart_block)
B(0,15,2,minecraft:nether_wart_block)
B(1,15,2,minecraft:nether_wart_block)
B(2,15,2,minecraft:nether_wart_block)
B(0,15,3,minecraft:nether_wart_block)
B(1,15,3,minecraft:nether_wart_block)
B(2,15,3,minecraft:nether_wart_block)
B(0,15,4,minecraft:nether_wart_block)
B(1,15,4,minecraft:nether_wart_block)
B(0,15,5,minecraft:nether_wart_block)
B(1,15,5,minecraft:nether_wart_block)
B(2,15,5,minecraft:nether_wart_block)
B(0,15,6,minecraft:nether_wart_block)
B(1,15,6,minecraft:nether_wart_block)
B(2,15,6,minecraft:nether_wart_block)
B(3,15,6,minecraft:nether_wart_block)
B(0,15,7,minecraft:nether_wart_block)
B(1,15,7,minecraft:nether_wart_block)
B(2,15,7,minecraft:nether_wart_block)
B(3,15,7,minecraft:nether_wart_block)
B(0,15,8,minecraft:nether_wart_block)
B(1,15,8,minecraft:nether_wart_block)
B(2,15,8,minecraft:nether_wart_block)
B(3,15,8,minecraft:nether_wart_block)
B(0,15,9,minecraft:nether_wart_block)
B(1,15,9,minecraft:nether_wart_block)
B(2,15,9,minecraft:nether_wart_block)
B(3,15,9,minecraft:nether_wart_block)
B(0,15,10,minecraft:nether_wart_block)
B(1,15,10,minecraft:nether_wart_block)
B(2,15,10,minecraft:nether_wart_block)
B(3,15,10,minecraft:nether_wart_block)
B(0,15,11,minecraft:nether_wart_block)
B(1,15,11,minecraft:nether_wart_block)
B(2,15,11,minecraft:nether_wart_block)
B(3,15,11,minecraft:nether_wart_block)
B(0,15,12,minecraft:nether_wart_block)
B(1,15,12,minecraft:nether_wart_block)
B(2,15,12,minecraft:nether_wart_block)
B(3,15,12,minecraft:nether_wart_block)
B(0,15,13,minecraft:nether_wart_block)
B(1,15,13,minecraft:nether_wart_block)
B(2,15,13,minecraft:nether_wart_block)
B(3,15,13,minecraft:nether_wart_block)
B(0,15,14,minecraft:nether_wart_block)
B(1,15,14,minecraft:nether_wart_block)
B(2,15,14,minecraft:nether_wart_block)
B(3,15,14,minecraft:nether_wart_block)
B(4,15,14,minecraft:nether_wart_block)
B(0,15,15,minecraft:nether_wart_block)
B(1,15,15,minecraft:nether_wart_block)
B(2,15,15,minecraft:nether_wart_block)
B(3,15,15,minecraft:nether_wart_block)
B(0,16,0,minecraft:nether_wart_block)
B(1,16,0,minecraft:nether_wart_block)
B(2,16,0,minecraft:nether_wart_block)
B(0,16,1,minecraft:nether_wart_block)
B(1,16,1,minecraft:nether_wart_block)
B(2,16,1,minecraft:nether_wart_block)
B(0,16,2,minecraft:nether_wart_block)
B(1,16,2,minecraft:nether_wart_block)
B(2,16,2,minecraft:nether_wart_block)
B(0,16,3,minecraft:nether_wart_block)
B(1,16,3,minecraft:nether_wart_block)
B(2,16,3,minecraft:nether_wart_block)
B(0,16,4,minecraft:nether_wart_block)
B(1,16,4,minecraft:nether_wart_block)
B(0,16,5,minecraft:nether_wart_block)
B(1,16,5,minecraft:nether_wart_block)
B(2,16,5,minecraft:nether_wart_block)
B(0,16,6,minecraft:nether_wart_block)
B(1,16,6,minecraft:nether_wart_block)
B(2,16,6,minecraft:nether_wart_block)
B(3,16,6,minecraft:nether_wart_block)
B(0,16,7,minecraft:nether_wart_block)
B(1,16,7,minecraft:nether_wart_block)
B(2,16,7,minecraft:nether_wart_block)
B(3,16,7,minecraft:nether_wart_block)
B(0,16,8,minecraft:nether_wart_block)
B(1,16,8,minecraft:nether_wart_block)
B(2,16,8,minecraft:nether_wart_block)
B(3,16,8,minecraft:nether_wart_block)
B(0,16,9,minecraft:nether_wart_block)
B(1,16,9,minecraft:nether_wart_block)
B(2,16,9,minecraft:nether_wart_block)
B(3,16,9,minecraft:nether_wart_block)
B(0,16,10,minecraft:nether_wart_block)
B(1,16,10,minecraft:nether_wart_block)
B(2,16,10,minecraft:nether_wart_block)
B(3,16,10,minecraft:nether_wart_block)
B(0,16,11,minecraft:nether_wart_block)
B(1,16,11,minecraft:nether_wart_block)
B(2,16,11,minecraft:nether_wart_block)
B(3,16,11,minecraft:nether_wart_block)
B(0,16,12,minecraft:nether_wart_block)
B(1,16,12,minecraft:nether_wart_block)
B(2,16,12,minecraft:nether_wart_block)
B(3,16,12,minecraft:nether_wart_block)
B(0,16,13,minecraft:nether_wart_block)
B(1,16,13,minecraft:nether_wart_block)
B(2,16,13,minecraft:nether_wart_block)
B(3,16,13,minecraft:nether_wart_block)
B(0,16,14,minecraft:nether_wart_block)
B(1,16,14,minecraft:nether_wart_block)
B(2,16,14,minecraft:nether_wart_block)
B(3,16,14,minecraft:nether_wart_block)
B(0,16,15,minecraft:nether_wart_block)
B(1,16,15,minecraft:nether_wart_block)
B(2,16,15,minecraft:nether_wart_block)
B(3,16,15,minecraft:nether_wart_block)
B(0,17,0,minecraft:nether_wart_block)
B(1,17,0,minecraft:nether_wart_block)
B(2,17,0,minecraft:nether_wart_block)
B(0,17,1,minecraft:nether_wart_block)
B(1,17,1,minecraft:nether_wart_block)
B(2,17,1,minecraft:nether_wart_block)
B(0,17,2,minecraft:nether_wart_block)
B(1,17,2,minecraft:nether_wart_block)
B(2,17,2,minecraft:nether_wart_block)
B(0,17,3,minecraft:nether_wart_block)
B(1,17,3,minecraft:nether_wart_block)
B(2,17,3,minecraft:nether_wart_block)
B(0,17,4,minecraft:nether_wart_block)
B(1,17,4,minecraft:nether_wart_block)
B(0,17,5,minecraft:nether_wart_block)
B(1,17,5,minecraft:nether_wart_block)
B(0,17,6,minecraft:nether_wart_block)
B(1,17,6,minecraft:nether_wart_block)
B(2,17,6,minecraft:nether_wart_block)
B(3,17,6,minecraft:nether_wart_block)
B(0,17,7,minecraft:nether_wart_block)
B(1,17,7,minecraft:nether_wart_block)
B(2,17,7,minecraft:nether_wart_block)
B(3,17,7,minecraft:nether_wart_block)
B(0,17,8,minecraft:nether_wart_block)
B(1,17,8,minecraft:nether_wart_block)
B(2,17,8,minecraft:nether_wart_block)
B(3,17,8,minecraft:nether_wart_block)
B(0,17,9,minecraft:nether_wart_block)
B(1,17,9,minecraft:nether_wart_block)
B(2,17,9,minecraft:nether_wart_block)
B(3,17,9,minecraft:nether_wart_block)
B(0,17,10,minecraft:nether_wart_block)
B(1,17,10,minecraft:nether_wart_block)
B(2,17,10,minecraft:nether_wart_block)
B(3,17,10,minecraft:nether_wart_block)
B(0,17,11,minecraft:nether_wart_block)
B(1,17,11,minecraft:nether_wart_block)
B(2,17,11,minecraft:nether_wart_block)
B(3,17,11,minecraft:nether_wart_block)
B(0,17,12,minecraft:nether_wart_block)
B(1,17,12,minecraft:nether_wart_block)
B(2,17,12,minecraft:nether_wart_block)
B(3,17,12,minecraft:nether_wart_block)
B(0,17,13,minecraft:nether_wart_block)
B(1,17,13,minecraft:nether_wart_block)
B(2,17,13,minecraft:nether_wart_block)
B(3,17,13,minecraft:nether_wart_block)
B(0,17,14,minecraft:nether_wart_block)
B(1,17,14,minecraft:nether_wart_block)
B(2,17,14,minecraft:nether_wart_block)
B(3,17,14,minecraft:nether_wart_block)
B(0,17,15,minecraft:nether_wart_block)
B(1,17,15,minecraft:nether_wart_block)
B(2,17,15,minecraft:nether_wart_block)
B(3,17,15,minecraft:nether_wart_block)
B(0,18,0,minecraft:nether_wart_block)
B(1,18,0,minecraft:nether_wart_block)
B(2,18,0,minecraft:nether_wart_block)
B(0,18,1,minecraft:nether_wart_block)
B(1,18,1,minecraft:nether_wart_block)
B(2,18,1,minecraft:nether_wart_block)
B(0,18,2,minecraft:nether_wart_block)
B(1,18,2,minecraft:nether_wart_block)
B(2,18,2,minecraft:nether_wart_block)
B(0,18,3,minecraft:nether_wart_block)
B(1,18,3,minecraft:nether_wart_block)
B(2,18,3,minecraft:nether_wart_block)
B(0,18,4,minecraft:nether_wart_block)
B(1,18,4,minecraft:nether_wart_block)
B(0,18,5,minecraft:nether_wart_block)
B(0,18,6,minecraft:nether_wart_block)
B(1,18,6,minecraft:nether_wart_block)
B(2,18,6,minecraft:nether_wart_block)
B(3,18,6,minecraft:nether_wart_block)
B(0,18,7,minecraft:nether_wart_block)
B(1,18,7,minecraft:nether_wart_block)
B(2,18,7,minecraft:nether_wart_block)
B(3,18,7,minecraft:nether_wart_block)
B(0,18,8,minecraft:nether_wart_block)
B(1,18,8,minecraft:nether_wart_block)
B(2,18,8,minecraft:nether_wart_block)
B(3,18,8,minecraft:nether_wart_block)
B(0,18,9,minecraft:nether_wart_block)
B(1,18,9,minecraft:nether_wart_block)
B(2,18,9,minecraft:nether_wart_block)
B(3,18,9,minecraft:nether_wart_block)
B(0,18,10,minecraft:nether_wart_block)
B(1,18,10,minecraft:nether_wart_block)
B(2,18,10,minecraft:nether_wart_block)
B(3,18,10,minecraft:nether_wart_block)
B(0,18,11,minecraft:nether_wart_block)
B(1,18,11,minecraft:nether_wart_block)
B(2,18,11,minecraft:nether_wart_block)
B(3,18,11,minecraft:nether_wart_block)
B(0,18,12,minecraft:nether_wart_block)
B(1,18,12,minecraft:nether_wart_block)
B(2,18,12,minecraft:nether_wart_block)
B(3,18,12,minecraft:nether_wart_block)
B(0,18,13,minecraft:nether_wart_block)
B(1,18,13,minecraft:nether_wart_block)
B(2,18,13,minecraft:nether_wart_block)
B(3,18,13,minecraft:nether_wart_block)
B(0,18,14,minecraft:nether_wart_block)
B(1,18,14,minecraft:nether_wart_block)
B(2,18,14,minecraft:nether_wart_block)
B(3,18,14,minecraft:nether_wart_block)
B(0,18,15,minecraft:nether_wart_block)
B(1,18,15,minecraft:nether_wart_block)
B(2,18,15,minecraft:nether_wart_block)
B(3,18,15,minecraft:nether_wart_block)
B(0,19,0,minecraft:nether_wart_block)
B(1,19,0,minecraft:nether_wart_block)
B(2,19,0,minecraft:nether_wart_block)
B(0,19,1,minecraft:nether_wart_block)
B(1,19,1,minecraft:nether_wart_block)
B(2,19,1,minecraft:nether_wart_block)
B(0,19,2,minecraft:nether_wart_block)
B(1,19,2,minecraft:nether_wart_block)
B(2,19,2,minecraft:nether_wart_block)
B(0,19,3,minecraft:nether_wart_block)
B(1,19,3,minecraft:nether_wart_block)
B(2,19,3,minecraft:nether_wart_block)
B(0,19,4,minecraft:nether_wart_block)
B(1,19,4,minecraft:nether_wart_block)
B(0,19,5,minecraft:nether_wart_block)
B(0,19,6,minecraft:nether_wart_block)
B(1,19,6,minecraft:nether_wart_block)
B(2,19,6,minecraft:nether_wart_block)
B(3,19,6,minecraft:nether_wart_block)
B(0,19,7,minecraft:nether_wart_block)
B(1,19,7,minecraft:nether_wart_block)
B(2,19,7,minecraft:nether_wart_block)
B(3,19,7,minecraft:nether_wart_block)
B(0,19,8,minecraft:nether_wart_block)
B(1,19,8,minecraft:nether_wart_block)
B(2,19,8,minecraft:nether_wart_block)
B(3,19,8,minecraft:nether_wart_block)
B(0,19,9,minecraft:nether_wart_block)
B(1,19,9,minecraft:nether_wart_block)
B(2,19,9,minecraft:nether_wart_block)
B(3,19,9,minecraft:nether_wart_block)
B(0,19,10,minecraft:nether_wart_block)
B(1,19,10,minecraft:nether_wart_block)
B(2,19,10,minecraft:nether_wart_block)
B(3,19,10,minecraft:nether_wart_block)
B(0,19,11,minecraft:nether_wart_block)
B(1,19,11,minecraft:nether_wart_block)
B(2,19,11,minecraft:nether_wart_block)
B(3,19,11,minecraft:nether_wart_block)
B(0,19,12,minecraft:nether_wart_block)
B(1,19,12,minecraft:nether_wart_block)
B(2,19,12,minecraft:nether_wart_block)
B(3,19,12,minecraft:nether_wart_block)
B(0,19,13,minecraft:nether_wart_block)
B(1,19,13,minecraft:nether_wart_block)
B(2,19,13,minecraft:nether_wart_block)
B(3,19,13,minecraft:nether_wart_block)
B(0,19,14,minecraft:nether_wart_block)
B(1,19,14,minecraft:nether_wart_block)
B(2,19,14,minecraft:nether_wart_block)
B(3,19,14,minecraft:nether_wart_block)
B(0,19,15,minecraft:nether_wart_block)
B(1,19,15,minecraft:nether_wart_block)
B(2,19,15,minecraft:nether_wart_block)
B(3,19,15,minecraft:nether_wart_block)
B(0,20,0,minecraft:nether_wart_block)
B(1,20,0,minecraft:nether_wart_block)
B(2,20,0,minecraft:nether_wart_block)
B(0,20,1,minecraft:nether_wart_block)
B(1,20,1,minecraft:nether_wart_block)
B(2,20,1,minecraft:nether_wart_block)
B(0,20,2,minecraft:nether_wart_block)
B(1,20,2,minecraft:nether_wart_block)
B(2,20,2,minecraft:nether_wart_block)
B(0,20,3,minecraft:nether_wart_block)
B(1,20,3,minecraft:nether_wart_block)
B(2,20,3,minecraft:nether_wart_block)
B(0,20,4,minecraft:nether_wart_block)
B(1,20,4,minecraft:nether_wart_block)
B(0,20,5,minecraft:nether_wart_block)
B(0,20,6,minecraft:nether_wart_block)
B(1,20,6,minecraft:nether_wart_block)
B(2,20,6,minecraft:nether_wart_block)
B(3,20,6,minecraft:nether_wart_block)
B(0,20,7,minecraft:nether_wart_block)
B(1,20,7,minecraft:nether_wart_block)
B(2,20,7,minecraft:nether_wart_block)
B(0,20,8,minecraft:nether_wart_block)
B(1,20,8,minecraft:nether_wart_block)
B(2,20,8,minecraft:nether_wart_block)
B(3,20,8,minecraft:nether_wart_block)
B(0,20,9,minecraft:nether_wart_block)
B(1,20,9,minecraft:nether_wart_block)
B(2,20,9,minecraft:nether_wart_block)
B(3,20,9,minecraft:nether_wart_block)
B(0,20,10,minecraft:nether_wart_block)
B(1,20,10,minecraft:nether_wart_block)
B(2,20,10,minecraft:nether_wart_block)
B(3,20,10,minecraft:nether_wart_block)
B(0,20,11,minecraft:nether_wart_block)
B(1,20,11,minecraft:nether_wart_block)
B(2,20,11,minecraft:nether_wart_block)
B(3,20,11,minecraft:nether_wart_block)
B(0,20,12,minecraft:nether_wart_block)
B(1,20,12,minecraft:nether_wart_block)
B(2,20,12,minecraft:nether_wart_block)
B(3,20,12,minecraft:nether_wart_block)
B(0,20,13,minecraft:nether_wart_block)
B(1,20,13,minecraft:nether_wart_block)
B(2,20,13,minecraft:nether_wart_block)
B(3,20,13,minecraft:nether_wart_block)
B(0,20,14,minecraft:nether_wart_block)
B(1,20,14,minecraft:nether_wart_block)
B(2,20,14,minecraft:nether_wart_block)
B(3,20,14,minecraft:nether_wart_block)
B(0,20,15,minecraft:nether_wart_block)
B(1,20,15,minecraft:nether_wart_block)
B(2,20,15,minecraft:nether_wart_block)
B(3,20,15,minecraft:nether_wart_block)
B(0,21,0,minecraft:nether_wart_block)
B(1,21,0,minecraft:nether_wart_block)
B(2,21,0,minecraft:nether_wart_block)
B(0,21,1,minecraft:nether_wart_block)
B(1,21,1,minecraft:nether_wart_block)
B(2,21,1,minecraft:nether_wart_block)
B(0,21,2,minecraft:nether_wart_block)
B(1,21,2,minecraft:nether_wart_block)
B(2,21,2,minecraft:nether_wart_block)
B(0,21,3,minecraft:nether_wart_block)
B(1,21,3,minecraft:nether_wart_block)
B(2,21,3,minecraft:nether_wart_block)
B(0,21,4,minecraft:nether_wart_block)
B(1,21,4,minecraft:nether_wart_block)
B(0,21,5,minecraft:nether_wart_block)
B(0,21,6,minecraft:nether_wart_block)
B(1,21,6,minecraft:nether_wart_block)
B(2,21,6,minecraft:nether_wart_block)
B(0,21,7,minecraft:nether_wart_block)
B(1,21,7,minecraft:nether_wart_block)
B(2,21,7,minecraft:nether_wart_block)
B(0,21,8,minecraft:nether_wart_block)
B(1,21,8,minecraft:nether_wart_block)
B(2,21,8,minecraft:nether_wart_block)
B(3,21,8,minecraft:nether_wart_block)
B(0,21,9,minecraft:nether_wart_block)
B(1,21,9,minecraft:nether_wart_block)
B(2,21,9,minecraft:nether_wart_block)
B(3,21,9,minecraft:nether_wart_block)
B(0,21,10,minecraft:nether_wart_block)
B(1,21,10,minecraft:nether_wart_block)
B(2,21,10,minecraft:nether_wart_block)
B(0,21,11,minecraft:nether_wart_block)
B(1,21,11,minecraft:nether_wart_block)
B(2,21,11,minecraft:nether_wart_block)
B(3,21,11,minecraft:nether_wart_block)
B(0,21,12,minecraft:nether_wart_block)
B(1,21,12,minecraft:nether_wart_block)
B(2,21,12,minecraft:nether_wart_block)
B(3,21,12,minecraft:nether_wart_block)
B(0,21,13,minecraft:nether_wart_block)
B(1,21,13,minecraft:nether_wart_block)
B(2,21,13,minecraft:nether_wart_block)
B(3,21,13,minecraft:nether_wart_block)
B(0,21,14,minecraft:nether_wart_block)
B(1,21,14,minecraft:nether_wart_block)
B(2,21,14,minecraft:nether_wart_block)
B(3,21,14,minecraft:nether_wart_block)
B(0,21,15,minecraft:nether_wart_block)
B(1,21,15,minecraft:nether_wart_block)
B(2,21,15,minecraft:nether_wart_block)
B(3,21,15,minecraft:nether_wart_block)
B(0,22,0,minecraft:nether_wart_block)
B(1,22,0,minecraft:nether_wart_block)
B(2,22,0,minecraft:nether_wart_block)
B(0,22,1,minecraft:nether_wart_block)
B(1,22,1,minecraft:nether_wart_block)
B(2,22,1,minecraft:nether_wart_block)
B(0,22,2,minecraft:nether_wart_block)
B(1,22,2,minecraft:nether_wart_block)
B(2,22,2,minecraft:nether_wart_block)
B(0,22,3,minecraft:nether_wart_block)
B(1,22,3,minecraft:nether_wart_block)
B(2,22,3,minecraft:nether_wart_block)
B(0,22,4,minecraft:nether_wart_block)
B(1,22,4,minecraft:nether_wart_block)
B(0,22,5,minecraft:nether_wart_block)
B(0,22,6,minecraft:nether_wart_block)
B(1,22,6,minecraft:nether_wart_block)
B(2,22,6,minecraft:nether_wart_block)
B(0,22,7,minecraft:nether_wart_block)
B(1,22,7,minecraft:nether_wart_block)
B(2,22,7,minecraft:nether_wart_block)
B(0,22,8,minecraft:nether_wart_block)
B(1,22,8,minecraft:nether_wart_block)
B(2,22,8,minecraft:nether_wart_block)
B(3,22,8,minecraft:nether_wart_block)
B(0,22,9,minecraft:nether_wart_block)
B(1,22,9,minecraft:nether_wart_block)
B(2,22,9,minecraft:nether_wart_block)
B(3,22,9,minecraft:nether_wart_block)
B(0,22,10,minecraft:nether_wart_block)
B(1,22,10,minecraft:nether_wart_block)
B(2,22,10,minecraft:nether_wart_block)
B(0,22,11,minecraft:nether_wart_block)
B(1,22,11,minecraft:nether_wart_block)
B(2,22,11,minecraft:nether_wart_block)
B(0,22,12,minecraft:nether_wart_block)
B(1,22,12,minecraft:nether_wart_block)
B(2,22,12,minecraft:nether_wart_block)
B(3,22,12,minecraft:nether_wart_block)
B(0,22,13,minecraft:nether_wart_block)
B(1,22,13,minecraft:nether_wart_block)
B(2,22,13,minecraft:nether_wart_block)
B(3,22,13,minecraft:nether_wart_block)
B(0,22,14,minecraft:nether_wart_block)
B(1,22,14,minecraft:nether_wart_block)
B(2,22,14,minecraft:nether_wart_block)
B(3,22,14,minecraft:nether_wart_block)
B(0,22,15,minecraft:nether_wart_block)
B(1,22,15,minecraft:nether_wart_block)
B(2,22,15,minecraft:nether_wart_block)
B(3,22,15,minecraft:nether_wart_block)
B(0,23,0,minecraft:nether_wart_block)
B(1,23,0,minecraft:nether_wart_block)
B(2,23,0,minecraft:nether_wart_block)
B(0,23,1,minecraft:nether_wart_block)
B(1,23,1,minecraft:nether_wart_block)
B(2,23,1,minecraft:nether_wart_block)
B(0,23,2,minecraft:nether_wart_block)
B(1,23,2,minecraft:nether_wart_block)
B(2,23,2,minecraft:nether_wart_block)
B(0,23,3,minecraft:nether_wart_block)
B(1,23,3,minecraft:nether_wart_block)
B(2,23,3,minecraft:nether_wart_block)
B(0,23,4,minecraft:nether_wart_block)
B(1,23,4,minecraft:nether_wart_block)
B(0,23,5,minecraft:nether_wart_block)
B(0,23,6,minecraft:nether_wart_block)
B(1,23,6,minecraft:nether_wart_block)
B(0,23,7,minecraft:nether_wart_block)
B(1,23,7,minecraft:nether_wart_block)
B(2,23,7,minecraft:nether_wart_block)
B(0,23,8,minecraft:nether_wart_block)
B(1,23,8,minecraft:nether_wart_block)
B(2,23,8,minecraft:nether_wart_block)
B(0,23,9,minecraft:nether_wart_block)
B(1,23,9,minecraft:nether_wart_block)
B(2,23,9,minecraft:nether_wart_block)
B(3,23,9,minecraft:nether_wart_block)
B(0,23,10,minecraft:nether_wart_block)
B(1,23,10,minecraft:nether_wart_block)
B(2,23,10,minecraft:nether_wart_block)
B(0,23,11,minecraft:nether_wart_block)
B(1,23,11,minecraft:nether_wart_block)
B(2,23,11,minecraft:nether_wart_block)
B(0,23,12,minecraft:nether_wart_block)
B(1,23,12,minecraft:nether_wart_block)
B(2,23,12,minecraft:nether_wart_block)
B(3,23,12,minecraft:nether_wart_block)
B(0,23,13,minecraft:nether_wart_block)
B(1,23,13,minecraft:nether_wart_block)
B(2,23,13,minecraft:nether_wart_block)
B(3,23,13,minecraft:nether_wart_block)
B(0,23,14,minecraft:nether_wart_block)
B(1,23,14,minecraft:nether_wart_block)
B(2,23,14,minecraft:nether_wart_block)
B(3,23,14,minecraft:nether_wart_block)
B(0,23,15,minecraft:nether_wart_block)
B(1,23,15,minecraft:nether_wart_block)
B(2,23,15,minecraft:nether_wart_block)
B(3,23,15,minecraft:nether_wart_block)
B(0,24,0,minecraft:nether_wart_block)
B(1,24,0,minecraft:nether_wart_block)
B(2,24,0,minecraft:nether_wart_block)
B(0,24,1,minecraft:nether_wart_block)
B(1,24,1,minecraft:nether_wart_block)
B(2,24,1,minecraft:nether_wart_block)
B(0,24,2,minecraft:nether_wart_block)
B(1,24,2,minecraft:nether_wart_block)
B(2,24,2,minecraft:nether_wart_block)
B(0,24,3,minecraft:nether_wart_block)
B(1,24,3,minecraft:nether_wart_block)
B(2,24,3,minecraft:nether_wart_block)
B(0,24,4,minecraft:nether_wart_block)
B(1,24,4,minecraft:nether_wart_block)
B(0,24,5,minecraft:nether_wart_block)
B(0,24,6,minecraft:nether_wart_block)
B(1,24,6,minecraft:nether_wart_block)
B(0,24,7,minecraft:nether_wart_block)
B(1,24,7,minecraft:nether_wart_block)
B(2,24,7,minecraft:nether_wart_block)
B(0,24,8,minecraft:nether_wart_block)
B(1,24,8,minecraft:nether_wart_block)
B(2,24,8,minecraft:nether_wart_block)
B(0,24,9,minecraft:nether_wart_block)
B(1,24,9,minecraft:nether_wart_block)
B(2,24,9,minecraft:nether_wart_block)
B(0,24,10,minecraft:nether_wart_block)
B(1,24,10,minecraft:nether_wart_block)
B(2,24,10,minecraft:nether_wart_block)
B(0,24,11,minecraft:nether_wart_block)
B(1,24,11,minecraft:nether_wart_block)
B(2,24,11,minecraft:nether_wart_block)
B(0,24,12,minecraft:nether_wart_block)
B(1,24,12,minecraft:nether_wart_block)
B(2,24,12,minecraft:nether_wart_block)
B(3,24,12,minecraft:nether_wart_block)
B(0,24,13,minecraft:nether_wart_block)
B(1,24,13,minecraft:nether_wart_block)
B(2,24,13,minecraft:nether_wart_block)
B(3,24,13,minecraft:nether_wart_block)
B(0,24,14,minecraft:nether_wart_block)
B(1,24,14,minecraft:nether_wart_block)
B(2,24,14,minecraft:nether_wart_block)
B(3,24,14,minecraft:nether_wart_block)
B(0,24,15,minecraft:nether_wart_block)
B(1,24,15,minecraft:nether_wart_block)
B(2,24,15,minecraft:nether_wart_block)
B(3,24,15,minecraft:nether_wart_block)
B(0,25,0,minecraft:nether_wart_block)
B(1,25,0,minecraft:nether_wart_block)
B(2,25,0,minecraft:nether_wart_block)
B(0,25,1,minecraft:nether_wart_block)
B(1,25,1,minecraft:nether_wart_block)
B(2,25,1,minecraft:nether_wart_block)
B(0,25,2,minecraft:nether_wart_block)
B(1,25,2,minecraft:nether_wart_block)
B(2,25,2,minecraft:nether_wart_block)
B(0,25,3,minecraft:nether_wart_block)
B(1,25,3,minecraft:nether_wart_block)
B(2,25,3,minecraft:nether_wart_block)
B(0,25,4,minecraft:nether_wart_block)
B(1,25,4,minecraft:nether_wart_block)
B(0,25,5,minecraft:nether_wart_block)
B(0,25,6,minecraft:nether_wart_block)
B(1,25,6,minecraft:nether_wart_block)
B(0,25,7,minecraft:nether_wart_block)
B(1,25,7,minecraft:nether_wart_block)
B(2,25,7,minecraft:nether_wart_block)
B(0,25,8,minecraft:nether_wart_block)
B(1,25,8,minecraft:nether_wart_block)
B(2,25,8,minecraft:nether_wart_block)
B(0,25,9,minecraft:nether_wart_block)
B(1,25,9,minecraft:nether_wart_block)
B(2,25,9,minecraft:nether_wart_block)
B(0,25,10,minecraft:nether_wart_block)
B(1,25,10,minecraft:nether_wart_block)
B(2,25,10,minecraft:nether_wart_block)
B(0,25,11,minecraft:nether_wart_block)
B(1,25,11,minecraft:nether_wart_block)
B(2,25,11,minecraft:nether_wart_block)
B(0,25,12,minecraft:nether_wart_block)
B(1,25,12,minecraft:nether_wart_block)
B(2,25,12,minecraft:nether_wart_block)
B(0,25,13,minecraft:nether_wart_block)
B(1,25,13,minecraft:nether_wart_block)
B(2,25,13,minecraft:nether_wart_block)
B(3,25,13,minecraft:nether_wart_block)
B(0,25,14,minecraft:nether_wart_block)
B(1,25,14,minecraft:nether_wart_block)
B(2,25,14,minecraft:nether_wart_block)
B(3,25,14,minecraft:nether_wart_block)
B(0,25,15,minecraft:nether_wart_block)
B(1,25,15,minecraft:nether_wart_block)
B(2,25,15,minecraft:nether_wart_block)
B(3,25,15,minecraft:nether_wart_block)
B(0,26,0,minecraft:nether_wart_block)
B(1,26,0,minecraft:nether_wart_block)
B(2,26,0,minecraft:nether_wart_block)
B(0,26,1,minecraft:nether_wart_block)
B(1,26,1,minecraft:nether_wart_block)
B(2,26,1,minecraft:nether_wart_block)
B(0,26,2,minecraft:nether_wart_block)
B(1,26,2,minecraft:nether_wart_block)
B(2,26,2,minecraft:nether_wart_block)
B(0,26,3,minecraft:nether_wart_block)
B(1,26,3,minecraft:nether_wart_block)
B(2,26,3,minecraft:nether_wart_block)
B(0,26,4,minecraft:nether_wart_block)
B(1,26,4,minecraft:nether_wart_block)
B(0,26,5,minecraft:nether_wart_block)
B(0,26,6,minecraft:nether_wart_block)
B(1,26,6,minecraft:nether_wart_block)
B(0,26,7,minecraft:nether_wart_block)
B(1,26,7,minecraft:nether_wart_block)
B(2,26,7,minecraft:nether_wart_block)
B(0,26,8,minecraft:nether_wart_block)
B(1,26,8,minecraft:nether_wart_block)
B(2,26,8,minecraft:nether_wart_block)
B(0,26,9,minecraft:nether_wart_block)
B(1,26,9,minecraft:nether_wart_block)
B(2,26,9,minecraft:nether_wart_block)
B(0,26,10,minecraft:nether_wart_block)
B(1,26,10,minecraft:nether_wart_block)
B(2,26,10,minecraft:nether_wart_block)
B(0,26,11,minecraft:nether_wart_block)
B(1,26,11,minecraft:nether_wart_block)
B(2,26,11,minecraft:nether_wart_block)
B(0,26,12,minecraft:nether_wart_block)
B(1,26,12,minecraft:nether_wart_block)
B(2,26,12,minecraft:nether_wart_block)
B(0,26,13,minecraft:nether_wart_block)
B(1,26,13,minecraft:nether_wart_block)
B(2,26,13,minecraft:nether_wart_block)
B(3,26,13,minecraft:nether_wart_block)
B(0,26,14,minecraft:nether_wart_block)
B(1,26,14,minecraft:nether_wart_block)
B(2,26,14,minecraft:nether_wart_block)
B(0,26,15,minecraft:nether_wart_block)
B(1,26,15,minecraft:nether_wart_block)
B(2,26,15,minecraft:nether_wart_block)
B(3,26,15,minecraft:nether_wart_block)
B(0,27,0,minecraft:nether_wart_block)
B(1,27,0,minecraft:nether_wart_block)
B(2,27,0,minecraft:nether_wart_block)
B(0,27,1,minecraft:nether_wart_block)
B(1,27,1,minecraft:nether_wart_block)
B(2,27,1,minecraft:nether_wart_block)
B(0,27,2,minecraft:nether_wart_block)
B(1,27,2,minecraft:nether_wart_block)
B(2,27,2,minecraft:nether_wart_block)
B(0,27,3,minecraft:nether_wart_block)
B(1,27,3,minecraft:nether_wart_block)
B(0,27,4,minecraft:nether_wart_block)
B(1,27,4,minecraft:nether_wart_block)
B(0,27,5,minecraft:nether_wart_block)
B(0,27,6,minecraft:nether_wart_block)
B(1,27,6,minecraft:nether_wart_block)
B(0,27,7,minecraft:nether_wart_block)
B(1,27,7,minecraft:nether_wart_block)
B(2,27,7,minecraft:nether_wart_block)
B(0,27,8,minecraft:nether_wart_block)
B(1,27,8,minecraft:nether_wart_block)
B(2,27,8,minecraft:nether_wart_block)
B(0,27,9,minecraft:nether_wart_block)
B(1,27,9,minecraft:nether_wart_block)
B(2,27,9,minecraft:nether_wart_block)
B(0,27,10,minecraft:nether_wart_block)
B(1,27,10,minecraft:nether_wart_block)
B(2,27,10,minecraft:nether_wart_block)
B(0,27,11,minecraft:nether_wart_block)
B(1,27,11,minecraft:nether_wart_block)
B(2,27,11,minecraft:nether_wart_block)
B(0,27,12,minecraft:nether_wart_block)
B(1,27,12,minecraft:nether_wart_block)
B(2,27,12,minecraft:nether_wart_block)
B(0,27,13,minecraft:nether_wart_block)
B(1,27,13,minecraft:nether_wart_block)
B(2,27,13,minecraft:nether_wart_block)
B(0,27,14,minecraft:nether_wart_block)
B(1,27,14,minecraft:nether_wart_block)
B(2,27,14,minecraft:nether_wart_block)
B(0,27,15,minecraft:nether_wart_block)
B(1,27,15,minecraft:nether_wart_block)
B(2,27,15,minecraft:nether_wart_block)
B(3,27,15,minecraft:nether_wart_block)
B(0,28,0,minecraft:nether_wart_block)
B(1,28,0,minecraft:nether_wart_block)
B(2,28,0,minecraft:nether_wart_block)
B(0,28,1,minecraft:nether_wart_block)
B(1,28,1,minecraft:nether_wart_block)
B(2,28,1,minecraft:nether_wart_block)
B(0,28,2,minecraft:nether_wart_block)
B(1,28,2,minecraft:nether_wart_block)
B(2,28,2,minecraft:nether_wart_block)
B(0,28,3,minecraft:nether_wart_block)
B(1,28,3,minecraft:nether_wart_block)
B(0,28,4,minecraft:nether_wart_block)
B(1,28,4,minecraft:nether_wart_block)
B(0,28,5,minecraft:nether_wart_block)
B(0,28,6,minecraft:nether_wart_block)
B(1,28,6,minecraft:nether_wart_block)
B(0,28,7,minecraft:nether_wart_block)
B(1,28,7,minecraft:nether_wart_block)
B(2,28,7,minecraft:nether_wart_block)
B(0,28,8,minecraft:nether_wart_block)
B(1,28,8,minecraft:nether_wart_block)
B(2,28,8,minecraft:nether_wart_block)
B(0,28,9,minecraft:nether_wart_block)
B(1,28,9,minecraft:nether_wart_block)
B(2,28,9,minecraft:nether_wart_block)
B(0,28,10,minecraft:nether_wart_block)
B(1,28,10,minecraft:nether_wart_block)
B(2,28,10,minecraft:nether_wart_block)
B(0,28,11,minecraft:nether_wart_block)
B(1,28,11,minecraft:nether_wart_block)
B(2,28,11,minecraft:nether_wart_block)
B(0,28,12,minecraft:nether_wart_block)
B(1,28,12,minecraft:nether_wart_block)
B(2,28,12,minecraft:nether_wart_block)
B(0,28,13,minecraft:nether_wart_block)
B(1,28,13,minecraft:nether_wart_block)
B(2,28,13,minecraft:nether_wart_block)
B(0,28,14,minecraft:nether_wart_block)
B(1,28,14,minecraft:nether_wart_block)
B(2,28,14,minecraft:nether_wart_block)
B(0,28,15,minecraft:nether_wart_block)
B(1,28,15,minecraft:nether_wart_block)
B(2,28,15,minecraft:nether_wart_block)
B(3,28,15,minecraft:nether_wart_block)
B(0,29,0,minecraft:nether_wart_block)
B(1,29,0,minecraft:nether_wart_block)
B(2,29,0,minecraft:nether_wart_block)
B(0,29,1,minecraft:nether_wart_block)
B(1,29,1,minecraft:nether_wart_block)
B(2,29,1,minecraft:nether_wart_block)
B(0,29,2,minecraft:nether_wart_block)
B(1,29,2,minecraft:nether_wart_block)
B(2,29,2,minecraft:nether_wart_block)
B(0,29,3,minecraft:nether_wart_block)
B(1,29,3,minecraft:nether_wart_block)
B(0,29,4,minecraft:nether_wart_block)
B(1,29,4,minecraft:nether_wart_block)
B(0,29,5,minecraft:nether_wart_block)
B(0,29,6,minecraft:nether_wart_block)
B(1,29,6,minecraft:nether_wart_block)
B(0,29,7,minecraft:nether_wart_block)
B(1,29,7,minecraft:nether_wart_block)
B(2,29,7,minecraft:nether_wart_block)
B(0,29,8,minecraft:nether_wart_block)
B(1,29,8,minecraft:nether_wart_block)
B(2,29,8,minecraft:nether_wart_block)
B(0,29,9,minecraft:nether_wart_block)
B(1,29,9,minecraft:nether_wart_block)
B(2,29,9,minecraft:nether_wart_block)
B(0,29,10,minecraft:nether_wart_block)
B(1,29,10,minecraft:nether_wart_block)
B(2,29,10,minecraft:nether_wart_block)
B(0,29,11,minecraft:nether_wart_block)
B(1,29,11,minecraft:nether_wart_block)
B(2,29,11,minecraft:nether_wart_block)
B(0,29,12,minecraft:nether_wart_block)
B(1,29,12,minecraft:nether_wart_block)
B(2,29,12,minecraft:nether_wart_block)
B(0,29,13,minecraft:nether_wart_block)
B(1,29,13,minecraft:nether_wart_block)
B(2,29,13,minecraft:nether_wart_block)
B(0,29,14,minecraft:nether_wart_block)
B(1,29,14,minecraft:nether_wart_block)
B(2,29,14,minecraft:nether_wart_block)
B(0,29,15,minecraft:nether_wart_block)
B(1,29,15,minecraft:nether_wart_block)
B(2,29,15,minecraft:nether_wart_block)
B(3,29,15,minecraft:nether_wart_block)
B(0,30,0,minecraft:nether_wart_block)
B(1,30,0,minecraft:nether_wart_block)
B(2,30,0,minecraft:nether_wart_block)
B(0,30,1,minecraft:nether_wart_block)
B(1,30,1,minecraft:nether_wart_block)
B(2,30,1,minecraft:nether_wart_block)
B(0,30,2,minecraft:nether_wart_block)
B(1,30,2,minecraft:nether_wart_block)
B(2,30,2,minecraft:nether_wart_block)
B(0,30,3,minecraft:nether_wart_block)
B(1,30,3,minecraft:nether_wart_block)
B(0,30,4,minecraft:nether_wart_block)
B(1,30,4,minecraft:nether_wart_block)
B(0,30,5,minecraft:nether_wart_block)
B(0,30,6,minecraft:nether_wart_block)
B(1,30,6,minecraft:nether_wart_block)
B(0,30,7,minecraft:nether_wart_block)
B(1,30,7,minecraft:nether_wart_block)
B(2,30,7,minecraft:nether_wart_block)
B(0,30,8,minecraft:nether_wart_block)
B(1,30,8,minecraft:nether_wart_block)
B(2,30,8,minecraft:nether_wart_block)
B(0,30,9,minecraft:nether_wart_block)
B(1,30,9,minecraft:nether_wart_block)
B(2,30,9,minecraft:nether_wart_block)
B(0,30,10,minecraft:nether_wart_block)
B(1,30,10,minecraft:nether_wart_block)
B(2,30,10,minecraft:nether_wart_block)
B(0,30,11,minecraft:nether_wart_block)
B(1,30,11,minecraft:nether_wart_block)
B(2,30,11,minecraft:nether_wart_block)
B(0,30,12,minecraft:nether_wart_block)
B(1,30,12,minecraft:nether_wart_block)
B(2,30,12,minecraft:nether_wart_block)
B(0,30,13,minecraft:nether_wart_block)
B(1,30,13,minecraft:nether_wart_block)
B(2,30,13,minecraft:nether_wart_block)
B(0,30,14,minecraft:nether_wart_block)
B(1,30,14,minecraft:nether_wart_block)
B(2,30,14,minecraft:nether_wart_block)
B(0,30,15,minecraft:nether_wart_block)
B(1,30,15,minecraft:nether_wart_block)
B(2,30,15,minecraft:nether_wart_block)
B(3,30,15,minecraft:nether_wart_block)
B(0,31,0,minecraft:nether_wart_block)
B(1,31,0,minecraft:nether_wart_block)
B(2,31,0,minecraft:nether_wart_block)
B(0,31,1,minecraft:nether_wart_block)
B(1,31,1,minecraft:nether_wart_block)
B(2,31,1,minecraft:nether_wart_block)
B(0,31,2,minecraft:nether_wart_block)
B(1,31,2,minecraft:nether_wart_block)
B(2,31,2,minecraft:nether_wart_block)
B(0,31,3,minecraft:nether_wart_block)
B(1,31,3,minecraft:nether_wart_block)
B(0,31,4,minecraft:nether_wart_block)
B(1,31,4,minecraft:nether_wart_block)
B(0,31,5,minecraft:nether_wart_block)
B(0,31,6,minecraft:nether_wart_block)
B(1,31,6,minecraft:nether_wart_block)
B(0,31,7,minecraft:nether_wart_block)
B(1,31,7,minecraft:nether_wart_block)
B(2,31,7,minecraft:nether_wart_block)
B(0,31,8,minecraft:nether_wart_block)
B(1,31,8,minecraft:nether_wart_block)
B(2,31,8,minecraft:nether_wart_block)
B(0,31,9,minecraft:nether_wart_block)
B(1,31,9,minecraft:nether_wart_block)
B(2,31,9,minecraft:nether_wart_block)
B(0,31,10,minecraft:nether_wart_block)
B(1,31,10,minecraft:nether_wart_block)
B(2,31,10,minecraft:nether_wart_block)
B(0,31,11,minecraft:nether_wart_block)
B(1,31,11,minecraft:nether_wart_block)
B(2,31,11,minecraft:nether_wart_block)
B(0,31,12,minecraft:nether_wart_block)
B(1,31,12,minecraft:nether_wart_block)
B(2,31,12,minecraft:nether_wart_block)
B(0,31,13,minecraft:nether_wart_block)
B(1,31,13,minecraft:nether_wart_block)
B(2,31,13,minecraft:nether_wart_block)
B(0,31,14,minecraft:nether_wart_block)
B(1,31,14,minecraft:nether_wart_block)
B(2,31,14,minecraft:nether_wart_block)
B(0,31,15,minecraft:nether_wart_block)
B(1,31,15,minecraft:nether_wart_block)
B(2,31,15,minecraft:nether_wart_block)
B(3,31,15,minecraft:nether_wart_block)
B(0,32,0,minecraft:nether_wart_block)
B(1,32,0,minecraft:nether_wart_block)
B(2,32,0,minecraft:nether_wart_block)
B(0,32,1,minecraft:nether_wart_block)
B(1,32,1,minecraft:nether_wart_block)
B(2,32,1,minecraft:nether_wart_block)
B(0,32,2,minecraft:nether_wart_block)
B(1,32,2,minecraft:nether_wart_block)
B(2,32,2,minecraft:nether_wart_block)
B(0,32,3,minecraft:nether_wart_block)
B(1,32,3,minecraft:nether_wart_block)
B(0,32,4,minecraft:nether_wart_block)
B(1,32,4,minecraft:nether_wart_block)
B(0,32,5,minecraft:nether_wart_block)
B(0,32,6,minecraft:nether_wart_block)
B(1,32,6,minecraft:nether_wart_block)
B(0,32,7,minecraft:nether_wart_block)
B(1,32,7,minecraft:nether_wart_block)
B(2,32,7,minecraft:nether_wart_block)
B(0,32,8,minecraft:nether_wart_block)
B(1,32,8,minecraft:nether_wart_block)
B(2,32,8,minecraft:nether_wart_block)
B(0,32,9,minecraft:nether_wart_block)
B(1,32,9,minecraft:nether_wart_block)
B(2,32,9,minecraft:nether_wart_block)
B(0,32,10,minecraft:nether_wart_block)
B(1,32,10,minecraft:nether_wart_block)
B(2,32,10,minecraft:nether_wart_block)
B(0,32,11,minecraft:nether_wart_block)
B(1,32,11,minecraft:nether_wart_block)
B(2,32,11,minecraft:nether_wart_block)
B(0,32,12,minecraft:nether_wart_block)
B(1,32,12,minecraft:nether_wart_block)
B(2,32,12,minecraft:nether_wart_block)
B(0,32,13,minecraft:nether_wart_block)
B(1,32,13,minecraft:nether_wart_block)
B(2,32,13,minecraft:nether_wart_block)
B(0,32,14,minecraft:nether_wart_block)
B(1,32,14,minecraft:nether_wart_block)
B(2,32,14,minecraft:nether_wart_block)
B(0,32,15,minecraft:nether_wart_block)
B(1,32,15,minecraft:nether_wart_block)
B(2,32,15,minecraft:nether_wart_block)
B(3,32,15,minecraft:nether_wart_block)
B(0,33,0,minecraft:nether_wart_block)
B(1,33,0,minecraft:nether_wart_block)
B(2,33,0,minecraft:nether_wart_block)
B(0,33,1,minecraft:nether_wart_block)
B(1,33,1,minecraft:nether_wart_block)
B(2,33,1,minecraft:nether_wart_block)
B(0,33,2,minecraft:nether_wart_block)
B(1,33,2,minecraft:nether_wart_block)
B(2,33,2,minecraft:nether_wart_block)
B(0,33,3,minecraft:nether_wart_block)
B(1,33,3,minecraft:nether_wart_block)
B(0,33,4,minecraft:nether_wart_block)
B(1,33,4,minecraft:nether_wart_block)
B(0,33,5,minecraft:nether_wart_block)
B(0,33,6,minecraft:nether_wart_block)
B(1,33,6,minecraft:nether_wart_block)
B(0,33,7,minecraft:nether_wart_block)
B(1,33,7,minecraft:nether_wart_block)
B(2,33,7,minecraft:nether_wart_block)
B(0,33,8,minecraft:nether_wart_block)
B(1,33,8,minecraft:nether_wart_block)
B(2,33,8,minecraft:nether_wart_block)
B(0,33,9,minecraft:nether_wart_block)
B(1,33,9,minecraft:nether_wart_block)
B(2,33,9,minecraft:nether_wart_block)
B(0,33,10,minecraft:nether_wart_block)
B(1,33,10,minecraft:nether_wart_block)
B(2,33,10,minecraft:nether_wart_block)
B(0,33,11,minecraft:nether_wart_block)
B(1,33,11,minecraft:nether_wart_block)
B(2,33,11,minecraft:nether_wart_block)
B(0,33,12,minecraft:nether_wart_block)
B(1,33,12,minecraft:nether_wart_block)
B(2,33,12,minecraft:nether_wart_block)
B(0,33,13,minecraft:nether_wart_block)
B(1,33,13,minecraft:nether_wart_block)
B(2,33,13,minecraft:nether_wart_block)
B(0,33,14,minecraft:nether_wart_block)
B(1,33,14,minecraft:nether_wart_block)
B(2,33,14,minecraft:nether_wart_block)
B(0,33,15,minecraft:nether_wart_block)
B(1,33,15,minecraft:nether_wart_block)
B(2,33,15,minecraft:nether_wart_block)
B(0,34,0,minecraft:nether_wart_block)
B(1,34,0,minecraft:nether_wart_block)
B(2,34,0,minecraft:nether_wart_block)
B(0,34,1,minecraft:nether_wart_block)
B(1,34,1,minecraft:nether_wart_block)
B(2,34,1,minecraft:nether_wart_block)
B(0,34,2,minecraft:nether_wart_block)
B(1,34,2,minecraft:nether_wart_block)
B(2,34,2,minecraft:nether_wart_block)
B(0,34,3,minecraft:nether_wart_block)
B(1,34,3,minecraft:nether_wart_block)
B(0,34,4,minecraft:nether_wart_block)
B(1,34,4,minecraft:nether_wart_block)
B(0,34,5,minecraft:nether_wart_block)
B(0,34,6,minecraft:nether_wart_block)
B(1,34,6,minecraft:nether_wart_block)
B(0,34,7,minecraft:nether_wart_block)
B(1,34,7,minecraft:nether_wart_block)
B(0,34,8,minecraft:nether_wart_block)
B(1,34,8,minecraft:nether_wart_block)
B(2,34,8,minecraft:nether_wart_block)
B(0,34,9,minecraft:nether_wart_block)
B(1,34,9,minecraft:nether_wart_block)
B(2,34,9,minecraft:nether_wart_block)
B(0,34,10,minecraft:nether_wart_block)
B(1,34,10,minecraft:nether_wart_block)
B(2,34,10,minecraft:nether_wart_block)
B(0,34,11,minecraft:nether_wart_block)
B(1,34,11,minecraft:nether_wart_block)
B(2,34,11,minecraft:nether_wart_block)
B(0,34,12,minecraft:nether_wart_block)
B(1,34,12,minecraft:nether_wart_block)
B(2,34,12,minecraft:nether_wart_block)
B(0,34,13,minecraft:nether_wart_block)
B(1,34,13,minecraft:nether_wart_block)
B(2,34,13,minecraft:nether_wart_block)
B(0,34,14,minecraft:nether_wart_block)
B(1,34,14,minecraft:nether_wart_block)
B(2,34,14,minecraft:nether_wart_block)
B(0,34,15,minecraft:nether_wart_block)
B(1,34,15,minecraft:nether_wart_block)
B(2,34,15,minecraft:nether_wart_block)
B(0,35,0,minecraft:nether_wart_block)
B(1,35,0,minecraft:nether_wart_block)
B(2,35,0,minecraft:nether_wart_block)
B(0,35,1,minecraft:nether_wart_block)
B(1,35,1,minecraft:nether_wart_block)
B(2,35,1,minecraft:nether_wart_block)
B(0,35,2,minecraft:nether_wart_block)
B(1,35,2,minecraft:nether_wart_block)
B(2,35,2,minecraft:nether_wart_block)
B(0,35,3,minecraft:nether_wart_block)
B(1,35,3,minecraft:nether_wart_block)
B(0,35,4,minecraft:nether_wart_block)
B(0,35,5,minecraft:nether_wart_block)
B(0,35,6,minecraft:nether_wart_block)
B(1,35,6,minecraft:nether_wart_block)
B(0,35,7,minecraft:nether_wart_block)
B(1,35,7,minecraft:nether_wart_block)
B(0,35,8,minecraft:nether_wart_block)
B(1,35,8,minecraft:nether_wart_block)
B(2,35,8,minecraft:nether_wart_block)
B(0,35,9,minecraft:nether_wart_block)
B(1,35,9,minecraft:nether_wart_block)
B(2,35,9,minecraft:nether_wart_block)
B(0,35,10,minecraft:nether_wart_block)
B(1,35,10,minecraft:nether_wart_block)
B(2,35,10,minecraft:nether_wart_block)
B(0,35,11,minecraft:nether_wart_block)
B(1,35,11,minecraft:nether_wart_block)
B(2,35,11,minecraft:nether_wart_block)
B(0,35,12,minecraft:nether_wart_block)
B(1,35,12,minecraft:nether_wart_block)
B(2,35,12,minecraft:nether_wart_block)
B(0,35,13,minecraft:nether_wart_block)
B(1,35,13,minecraft:nether_wart_block)
B(2,35,13,minecraft:nether_wart_block)
B(0,35,14,minecraft:nether_wart_block)
B(1,35,14,minecraft:nether_wart_block)
B(2,35,14,minecraft:nether_wart_block)
B(0,35,15,minecraft:nether_wart_block)
B(1,35,15,minecraft:nether_wart_block)
B(2,35,15,minecraft:nether_wart_block)
B(0,36,0,minecraft:nether_wart_block)
B(1,36,0,minecraft:nether_wart_block)
B(2,36,0,minecraft:nether_wart_block)
B(0,36,1,minecraft:nether_wart_block)
B(1,36,1,minecraft:nether_wart_block)
B(2,36,1,minecraft:nether_wart_block)
B(0,36,2,minecraft:nether_wart_block)
B(1,36,2,minecraft:nether_wart_block)
B(2,36,2,minecraft:nether_wart_block)
B(0,36,3,minecraft:nether_wart_block)
B(1,36,3,minecraft:nether_wart_block)
B(0,36,4,minecraft:nether_wart_block)
B(0,36,5,minecraft:nether_wart_block)
B(0,36,6,minecraft:nether_wart_block)
B(0,36,7,minecraft:nether_wart_block)
B(1,36,7,minecraft:nether_wart_block)
B(0,36,8,minecraft:nether_wart_block)
B(1,36,8,minecraft:nether_wart_block)
B(2,36,8,minecraft:nether_wart_block)
B(0,36,9,minecraft:nether_wart_block)
B(1,36,9,minecraft:nether_wart_block)
B(2,36,9,minecraft:nether_wart_block)
B(0,36,10,minecraft:nether_wart_block)
B(1,36,10,minecraft:nether_wart_block)
B(0,36,11,minecraft:nether_wart_block)
B(1,36,11,minecraft:nether_wart_block)
B(2,36,11,minecraft:nether_wart_block)
B(0,36,12,minecraft:nether_wart_block)
B(1,36,12,minecraft:nether_wart_block)
B(2,36,12,minecraft:nether_wart_block)
B(0,36,13,minecraft:nether_wart_block)
B(1,36,13,minecraft:nether_wart_block)
B(2,36,13,minecraft:nether_wart_block)
B(0,36,14,minecraft:nether_wart_block)
B(1,36,14,minecraft:nether_wart_block)
B(2,36,14,minecraft:nether_wart_block)
B(0,36,15,minecraft:nether_wart_block)
B(1,36,15,minecraft:nether_wart_block)
B(2,36,15,minecraft:nether_wart_block)
B(0,37,0,minecraft:nether_wart_block)
B(1,37,0,minecraft:nether_wart_block)
B(2,37,0,minecraft:nether_wart_block)
B(0,37,1,minecraft:nether_wart_block)
B(1,37,1,minecraft:nether_wart_block)
B(2,37,1,minecraft:nether_wart_block)
B(0,37,2,minecraft:nether_wart_block)
B(1,37,2,minecraft:nether_wart_block)
B(2,37,2,minecraft:nether_wart_block)
B(0,37,3,minecraft:nether_wart_block)
B(1,37,3,minecraft:nether_wart_block)
B(0,37,4,minecraft:nether_wart_block)
B(0,37,5,minecraft:nether_wart_block)
B(0,37,6,minecraft:nether_wart_block)
B(0,37,7,minecraft:nether_wart_block)
B(1,37,7,minecraft:nether_wart_block)
B(0,37,8,minecraft:nether_wart_block)
B(1,37,8,minecraft:nether_wart_block)
B(2,37,8,minecraft:nether_wart_block)
B(0,37,9,minecraft:nether_wart_block)
B(1,37,9,minecraft:nether_wart_block)
B(0,37,10,minecraft:nether_wart_block)
B(1,37,10,minecraft:nether_wart_block)
B(0,37,11,minecraft:nether_wart_block)
B(1,37,11,minecraft:nether_wart_block)
B(2,37,11,minecraft:nether_wart_block)
B(0,37,12,minecraft:nether_wart_block)
B(1,37,12,minecraft:nether_wart_block)
B(2,37,12,minecraft:nether_wart_block)
B(0,37,13,minecraft:nether_wart_block)
B(1,37,13,minecraft:nether_wart_block)
B(2,37,13,minecraft:nether_wart_block)
B(0,37,14,minecraft:nether_wart_block)
B(1,37,14,minecraft:nether_wart_block)
B(0,37,15,minecraft:nether_wart_block)
B(1,37,15,minecraft:nether_wart_block)
B(2,37,15,minecraft:nether_wart_block)
B(0,38,0,minecraft:nether_wart_block)
B(1,38,0,minecraft:nether_wart_block)
B(2,38,0,minecraft:nether_wart_block)
B(0,38,1,minecraft:nether_wart_block)
B(1,38,1,minecraft:nether_wart_block)
B(2,38,1,minecraft:nether_wart_block)
B(0,38,2,minecraft:nether_wart_block)
B(1,38,2,minecraft:nether_wart_block)
B(0,38,3,minecraft:nether_wart_block)
B(1,38,3,minecraft:nether_wart_block)
B(0,38,4,minecraft:nether_wart_block)
B(0,38,5,minecraft:nether_wart_block)
B(0,38,6,minecraft:nether_wart_block)
B(0,38,7,minecraft:nether_wart_block)
B(1,38,7,minecraft:nether_wart_block)
B(0,38,8,minecraft:nether_wart_block)
B(1,38,8,minecraft:nether_wart_block)
B(2,38,8,minecraft:nether_wart_block)
B(0,38,9,minecraft:nether_wart_block)
B(1,38,9,minecraft:nether_wart_block)
B(0,38,10,minecraft:nether_wart_block)
B(1,38,10,minecraft:nether_wart_block)
B(0,38,11,minecraft:nether_wart_block)
B(1,38,11,minecraft:nether_wart_block)
B(2,38,11,minecraft:nether_wart_block)
B(0,38,12,minecraft:nether_wart_block)
B(1,38,12,minecraft:nether_wart_block)
B(2,38,12,minecraft:nether_wart_block)
B(0,38,13,minecraft:nether_wart_block)
B(1,38,13,minecraft:nether_wart_block)
B(0,38,14,minecraft:nether_wart_block)
B(1,38,14,minecraft:nether_wart_block)
B(0,38,15,minecraft:nether_wart_block)
B(1,38,15,minecraft:nether_wart_block)
B(2,38,15,minecraft:nether_wart_block)
B(0,39,0,minecraft:nether_wart_block)
B(1,39,0,minecraft:nether_wart_block)
B(2,39,0,minecraft:nether_wart_block)
B(0,39,1,minecraft:nether_wart_block)
B(1,39,1,minecraft:nether_wart_block)
B(2,39,1,minecraft:nether_wart_block)
B(0,39,2,minecraft:nether_wart_block)
B(1,39,2,minecraft:nether_wart_block)
B(0,39,3,minecraft:nether_wart_block)
B(1,39,3,minecraft:nether_wart_block)
B(0,39,4,minecraft:nether_wart_block)
B(0,39,5,minecraft:nether_wart_block)
B(0,39,6,minecraft:nether_wart_block)
B(0,39,7,minecraft:nether_wart_block)
B(1,39,7,minecraft:nether_wart_block)
B(0,39,8,minecraft:nether_wart_block)
B(1,39,8,minecraft:nether_wart_block)
B(2,39,8,minecraft:nether_wart_block)
B(0,39,9,minecraft:nether_wart_block)
B(1,39,9,minecraft:nether_wart_block)
B(0,39,10,minecraft:nether_wart_block)
B(1,39,10,minecraft:nether_wart_block)
B(0,39,11,minecraft:nether_wart_block)
B(1,39,11,minecraft:nether_wart_block)
B(2,39,11,minecraft:nether_wart_block)
B(0,39,12,minecraft:nether_wart_block)
B(1,39,12,minecraft:nether_wart_block)
B(2,39,12,minecraft:nether_wart_block)
B(0,39,13,minecraft:nether_wart_block)
B(1,39,13,minecraft:nether_wart_block)
B(0,39,14,minecraft:nether_wart_block)
B(1,39,14,minecraft:nether_wart_block)
B(0,39,15,minecraft:nether_wart_block)
B(1,39,15,minecraft:nether_wart_block)
B(2,39,15,minecraft:nether_wart_block)
B(0,40,0,minecraft:nether_wart_block)
B(1,40,0,minecraft:nether_wart_block)
B(2,40,0,minecraft:nether_wart_block)
B(0,40,1,minecraft:nether_wart_block)
B(1,40,1,minecraft:nether_wart_block)
B(0,40,2,minecraft:nether_wart_block)
B(1,40,2,minecraft:nether_wart_block)
B(0,40,3,minecraft:nether_wart_block)
B(1,40,3,minecraft:nether_wart_block)
B(0,40,4,minecraft:nether_wart_block)
B(0,40,6,minecraft:nether_wart_block)
B(0,40,7,minecraft:nether_wart_block)
B(1,40,7,minecraft:nether_wart_block)
B(0,40,8,minecraft:nether_wart_block)
B(1,40,8,minecraft:nether_wart_block)
B(2,40,8,minecraft:nether_wart_block)
B(0,40,9,minecraft:nether_wart_block)
B(1,40,9,minecraft:nether_wart_block)
B(0,40,10,minecraft:nether_wart_block)
B(1,40,10,minecraft:nether_wart_block)
B(0,40,11,minecraft:nether_wart_block)
B(1,40,11,minecraft:nether_wart_block)
B(2,40,11,minecraft:nether_wart_block)
B(0,40,12,minecraft:nether_wart_block)
B(1,40,12,minecraft:nether_wart_block)
B(2,40,12,minecraft:nether_wart_block)
B(0,40,13,minecraft:nether_wart_block)
B(1,40,13,minecraft:nether_wart_block)
B(0,40,14,minecraft:nether_wart_block)
B(1,40,14,minecraft:nether_wart_block)
B(0,40,15,minecraft:nether_wart_block)
B(1,40,15,minecraft:nether_wart_block)
B(2,40,15,minecraft:nether_wart_block)
B(0,41,0,minecraft:nether_wart_block)
B(1,41,0,minecraft:nether_wart_block)
B(2,41,0,minecraft:nether_wart_block)
B(0,41,1,minecraft:nether_wart_block)
B(1,41,1,minecraft:nether_wart_block)
B(0,41,2,minecraft:nether_wart_block)
B(1,41,2,minecraft:nether_wart_block)
B(0,41,3,minecraft:nether_wart_block)
B(1,41,3,minecraft:nether_wart_block)
B(0,41,4,minecraft:nether_wart_block)
B(0,41,6,minecraft:nether_wart_block)
B(0,41,7,minecraft:nether_wart_block)
B(1,41,7,minecraft:nether_wart_block)
B(0,41,8,minecraft:nether_wart_block)
B(1,41,8,minecraft:nether_wart_block)
B(2,41,8,minecraft:nether_wart_block)
B(0,41,9,minecraft:nether_wart_block)
B(1,41,9,minecraft:nether_wart_block)
B(0,41,10,minecraft:nether_wart_block)
B(1,41,10,minecraft:nether_wart_block)
B(0,41,11,minecraft:nether_wart_block)
B(1,41,11,minecraft:nether_wart_block)
B(2,41,11,minecraft:nether_wart_block)
B(0,41,12,minecraft:nether_wart_block)
B(1,41,12,minecraft:nether_wart_block)
B(2,41,12,minecraft:nether_wart_block)
B(0,41,13,minecraft:nether_wart_block)
B(1,41,13,minecraft:nether_wart_block)
B(0,41,14,minecraft:nether_wart_block)
B(1,41,14,minecraft:nether_wart_block)
B(0,41,15,minecraft:nether_wart_block)
B(1,41,15,minecraft:nether_wart_block)
B(2,41,15,minecraft:nether_wart_block)
B(0,42,0,minecraft:nether_wart_block)
B(1,42,0,minecraft:nether_wart_block)
B(2,42,0,minecraft:nether_wart_block)
B(0,42,1,minecraft:nether_wart_block)
B(1,42,1,minecraft:nether_wart_block)
B(0,42,2,minecraft:nether_wart_block)
B(1,42,2,minecraft:nether_wart_block)
B(0,42,3,minecraft:nether_wart_block)
B(1,42,3,minecraft:nether_wart_block)
B(0,42,4,minecraft:nether_wart_block)
B(0,42,6,minecraft:nether_wart_block)
B(0,42,7,minecraft:nether_wart_block)
B(1,42,7,minecraft:nether_wart_block)
B(0,42,8,minecraft:nether_wart_block)
B(1,42,8,minecraft:nether_wart_block)
B(0,42,9,minecraft:nether_wart_block)
B(1,42,9,minecraft:nether_wart_block)
B(0,42,10,minecraft:nether_wart_block)
B(1,42,10,minecraft:nether_wart_block)
B(0,42,11,minecraft:nether_wart_block)
B(1,42,11,minecraft:nether_wart_block)
B(2,42,11,minecraft:nether_wart_block)
B(0,42,12,minecraft:nether_wart_block)
B(1,42,12,minecraft:nether_wart_block)
B(2,42,12,minecraft:nether_wart_block)
B(0,42,13,minecraft:nether_wart_block)
B(1,42,13,minecraft:nether_wart_block)
B(0,42,14,minecraft:nether_wart_block)
B(1,42,14,minecraft:nether_wart_block)
B(0,42,15,minecraft:nether_wart_block)
B(1,42,15,minecraft:nether_wart_block)
B(2,42,15,minecraft:nether_wart_block)
B(0,43,0,minecraft:nether_wart_block)
B(1,43,0,minecraft:nether_wart_block)
B(2,43,0,minecraft:nether_wart_block)
B(0,43,1,minecraft:nether_wart_block)
B(1,43,1,minecraft:nether_wart_block)
B(0,43,2,minecraft:nether_wart_block)
B(1,43,2,minecraft:nether_wart_block)
B(0,43,3,minecraft:nether_wart_block)
B(1,43,3,minecraft:nether_wart_block)
B(0,43,4,minecraft:nether_wart_block)
B(0,43,6,minecraft:nether_wart_block)
B(0,43,7,minecraft:nether_wart_block)
B(1,43,7,minecraft:nether_wart_block)
B(0,43,8,minecraft:nether_wart_block)
B(1,43,8,minecraft:nether_wart_block)
B(0,43,9,minecraft:nether_wart_block)
B(1,43,9,minecraft:nether_wart_block)
B(0,43,10,minecraft:nether_wart_block)
B(1,43,10,minecraft:nether_wart_block)
B(0,43,11,minecraft:nether_wart_block)
B(1,43,11,minecraft:nether_wart_block)
B(2,43,11,minecraft:nether_wart_block)
B(0,43,12,minecraft:nether_wart_block)
B(1,43,12,minecraft:nether_wart_block)
B(2,43,12,minecraft:nether_wart_block)
B(0,43,13,minecraft:nether_wart_block)
B(1,43,13,minecraft:nether_wart_block)
B(0,43,14,minecraft:nether_wart_block)
B(1,43,14,minecraft:nether_wart_block)
B(0,43,15,minecraft:nether_wart_block)
B(1,43,15,minecraft:nether_wart_block)
B(2,43,15,minecraft:nether_wart_block)
B(0,44,0,minecraft:nether_wart_block)
B(1,44,0,minecraft:nether_wart_block)
B(2,44,0,minecraft:nether_wart_block)
B(0,44,1,minecraft:nether_wart_block)
B(1,44,1,minecraft:nether_wart_block)
B(0,44,2,minecraft:nether_wart_block)
B(1,44,2,minecraft:nether_wart_block)
B(0,44,3,minecraft:nether_wart_block)
B(0,44,4,minecraft:nether_wart_block)
B(0,44,6,minecraft:nether_wart_block)
B(0,44,7,minecraft:nether_wart_block)
B(1,44,7,minecraft:nether_wart_block)
B(0,44,8,minecraft:nether_wart_block)
B(1,44,8,minecraft:nether_wart_block)
B(0,44,9,minecraft:nether_wart_block)
B(1,44,9,minecraft:nether_wart_block)
B(0,44,10,minecraft:nether_wart_block)
B(1,44,10,minecraft:nether_wart_block)
B(0,44,11,minecraft:nether_wart_block)
B(1,44,11,minecraft:nether_wart_block)
B(2,44,11,minecraft:nether_wart_block)
B(0,44,12,minecraft:nether_wart_block)
B(1,44,12,minecraft:nether_wart_block)
B(0,44,13,minecraft:nether_wart_block)
B(1,44,13,minecraft:nether_wart_block)
B(0,44,14,minecraft:nether_wart_block)
B(1,44,14,minecraft:nether_wart_block)
B(0,44,15,minecraft:nether_wart_block)
B(1,44,15,minecraft:nether_wart_block)
B(2,44,15,minecraft:nether_wart_block)
B(0,45,0,minecraft:nether_wart_block)
B(1,45,0,minecraft:nether_wart_block)
B(0,45,1,minecraft:nether_wart_block)
B(0,45,2,minecraft:nether_wart_block)
B(0,45,3,minecraft:nether_wart_block)
B(0,45,6,minecraft:nether_wart_block)
B(0,45,7,minecraft:nether_wart_block)
B(1,45,7,minecraft:nether_wart_block)
B(0,45,8,minecraft:nether_wart_block)
B(1,45,8,minecraft:nether_wart_block)
B(0,45,9,minecraft:nether_wart_block)
B(1,45,9,minecraft:nether_wart_block)
B(0,45,10,minecraft:nether_wart_block)
B(1,45,10,minecraft:nether_wart_block)
B(0,45,11,minecraft:nether_wart_block)
B(1,45,11,minecraft:nether_wart_block)
B(0,45,12,minecraft:nether_wart_block)
B(1,45,12,minecraft:nether_wart_block)
B(0,45,13,minecraft:nether_wart_block)
B(0,45,14,minecraft:nether_wart_block)
B(0,45,15,minecraft:nether_wart_block)
B(1,45,15,minecraft:nether_wart_block)
B(0,46,0,minecraft:nether_wart_block)
B(0,46,1,minecraft:nether_wart_block)
B(0,46,2,minecraft:nether_wart_block)
B(0,46,3,minecraft:nether_wart_block)
B(0,46,6,minecraft:nether_wart_block)
B(0,46,7,minecraft:nether_wart_block)
B(1,46,7,minecraft:nether_wart_block)
B(0,46,8,minecraft:nether_wart_block)
B(1,46,8,minecraft:nether_wart_block)
B(0,46,9,minecraft:nether_wart_block)
B(1,46,9,minecraft:nether_wart_block)
B(0,46,10,minecraft:nether_wart_block)
B(1,46,10,minecraft:nether_wart_block)
B(0,46,11,minecraft:nether_wart_block)
B(1,46,11,minecraft:nether_wart_block)
B(0,46,12,minecraft:nether_wart_block)
B(1,46,12,minecraft:nether_wart_block)
B(0,46,13,minecraft:nether_wart_block)
B(0,46,14,minecraft:nether_wart_block)
B(0,46,15,minecraft:nether_wart_block)
B(1,46,15,minecraft:nether_wart_block)
B(0,47,0,minecraft:nether_wart_block)
B(0,47,1,minecraft:nether_wart_block)
B(0,47,2,minecraft:nether_wart_block)
B(0,47,3,minecraft:nether_wart_block)
B(0,47,6,minecraft:nether_wart_block)
B(0,47,7,minecraft:nether_wart_block)
B(1,47,7,minecraft:nether_wart_block)
B(0,47,8,minecraft:nether_wart_block)
B(1,47,8,minecraft:nether_wart_block)
B(0,47,9,minecraft:nether_wart_block)
B(1,47,9,minecraft:nether_wart_block)
B(0,47,10,minecraft:nether_wart_block)
B(1,47,10,minecraft:nether_wart_block)
B(0,47,11,minecraft:nether_wart_block)
B(1,47,11,minecraft:nether_wart_block)
B(0,47,12,minecraft:nether_wart_block)
B(1,47,12,minecraft:nether_wart_block)
B(0,47,13,minecraft:nether_wart_block)
B(0,47,14,minecraft:nether_wart_block)
B(0,47,15,minecraft:nether_wart_block)
B(1,47,15,minecraft:nether_wart_block)
B(0,48,0,minecraft:nether_wart_block)
B(0,48,1,minecraft:nether_wart_block)
B(0,48,2,minecraft:nether_wart_block)
B(0,48,3,minecraft:nether_wart_block)
B(0,48,6,minecraft:nether_wart_block)
B(0,48,7,minecraft:nether_wart_block)
B(1,48,7,minecraft:nether_wart_block)
B(0,48,8,minecraft:nether_wart_block)
B(1,48,8,minecraft:nether_wart_block)
B(0,48,9,minecraft:nether_wart_block)
B(1,48,9,minecraft:nether_wart_block)
B(0,48,10,minecraft:nether_wart_block)
B(1,48,10,minecraft:nether_wart_block)
B(0,48,11,minecraft:nether_wart_block)
B(1,48,11,minecraft:nether_wart_block)
B(0,48,12,minecraft:nether_wart_block)
B(1,48,12,minecraft:nether_wart_block)
B(0,48,13,minecraft:nether_wart_block)
B(0,48,14,minecraft:nether_wart_block)
B(0,48,15,minecraft:nether_wart_block)
B(1,48,15,minecraft:nether_wart_block)
B(0,49,0,minecraft:nether_wart_block)
B(0,49,1,minecraft:nether_wart_block)
B(0,49,2,minecraft:nether_wart_block)
B(0,49,3,minecraft:nether_wart_block)
B(0,49,6,minecraft:nether_wart_block)
B(0,49,7,minecraft:nether_wart_block)
B(1,49,7,minecraft:nether_wart_block)
B(0,49,8,minecraft:nether_wart_block)
B(1,49,8,minecraft:nether_wart_block)
B(0,49,9,minecraft:nether_wart_block)
B(1,49,9,minecraft:nether_wart_block)
B(0,49,10,minecraft:nether_wart_block)
B(1,49,10,minecraft:nether_wart_block)
B(0,49,11,minecraft:nether_wart_block)
B(1,49,11,minecraft:nether_wart_block)
B(0,49,12,minecraft:nether_wart_block)
B(1,49,12,minecraft:nether_wart_block)
B(0,49,13,minecraft:nether_wart_block)
B(0,49,14,minecraft:nether_wart_block)
B(0,49,15,minecraft:nether_wart_block)
B(1,49,15,minecraft:nether_wart_block)
B(0,50,0,minecraft:nether_wart_block)
B(0,50,1,minecraft:nether_wart_block)
B(0,50,2,minecraft:nether_wart_block)
B(0,50,3,minecraft:nether_wart_block)
B(0,50,6,minecraft:nether_wart_block)
B(0,50,7,minecraft:nether_wart_block)
B(1,50,7,minecraft:nether_wart_block)
B(0,50,8,minecraft:nether_wart_block)
B(1,50,8,minecraft:nether_wart_block)
B(0,50,9,minecraft:nether_wart_block)
B(1,50,9,minecraft:nether_wart_block)
B(0,50,10,minecraft:nether_wart_block)
B(1,50,10,minecraft:nether_wart_block)
B(0,50,11,minecraft:nether_wart_block)
B(1,50,11,minecraft:nether_wart_block)
B(0,50,12,minecraft:nether_wart_block)
B(0,50,13,minecraft:nether_wart_block)
B(0,50,15,minecraft:nether_wart_block)
B(0,51,0,minecraft:nether_wart_block)
