Author: Bo3 BulkEdit

Description: Converted Schematic - Modified by Bo3BulkEdit

Version: 3

SettingsMode: WriteDisable

IsOTGPlus: true
Tree: false
Frequency: 10
Rarity: 100
RotateRandomly: true
SpawnHeight: randomY
SpawnHeightOffset: 0
SpawnHeightVariance: 0
MaxBranchDepth: 10
ExcludedBiomes: All

MinHeight: 50
MaxHeight: 65

SourceBlocks: AIR
MaxPercentageOutsideSourceBlock: 100
OutsideSourceBlock: placeAnyway

ReplaceBelow: NETHER_WART_BLOCK
ReplaceWithBiomeBlocks: false
ReplaceWithGroundBlock: NETHER_WART_BLOCK
ReplaceWithSurfaceBlock: NETHER_WART_BLOCK
ReplaceWithStoneBlock: NETHER_WART_BLOCK
SmoothRadius: 30
SmoothHeightOffset: 0
SmoothStartTop: false
SmoothStartWood: false
SmoothingSurfaceBlock: NETHER_WART_BLOCK
SmoothingGroundBlock: NETHER_WART_BLOCK

B(0,750,0,AIR)
B(15,750,15,AIR)
B(0,0,0,minecraft:nether_wart_block)
B(1,0,0,minecraft:nether_wart_block)
B(2,0,0,minecraft:nether_wart_block)
B(3,0,0,minecraft:nether_wart_block)
B(4,0,0,minecraft:nether_wart_block)
B(0,0,1,minecraft:nether_wart_block)
B(1,0,1,minecraft:nether_wart_block)
B(2,0,1,minecraft:nether_wart_block)
B(3,0,1,minecraft:nether_wart_block)
B(4,0,1,minecraft:nether_wart_block)
B(0,0,2,minecraft:nether_wart_block)
B(1,0,2,minecraft:nether_wart_block)
B(2,0,2,minecraft:nether_wart_block)
B(3,0,2,minecraft:nether_wart_block)
B(0,0,3,minecraft:nether_wart_block)
B(1,0,3,minecraft:nether_wart_block)
B(2,0,3,minecraft:nether_wart_block)
B(3,0,3,minecraft:nether_wart_block)
B(0,0,4,minecraft:nether_wart_block)
B(1,0,4,minecraft:nether_wart_block)
B(2,0,4,minecraft:nether_wart_block)
B(3,0,4,minecraft:nether_wart_block)
B(0,0,5,minecraft:nether_wart_block)
B(1,0,5,minecraft:nether_wart_block)
B(2,0,5,minecraft:nether_wart_block)
B(3,0,5,minecraft:nether_wart_block)
B(4,0,5,minecraft:nether_wart_block)
B(0,0,6,minecraft:nether_wart_block)
B(1,0,6,minecraft:nether_wart_block)
B(2,0,6,minecraft:nether_wart_block)
B(3,0,6,minecraft:nether_wart_block)
B(4,0,6,minecraft:nether_wart_block)
B(5,0,6,minecraft:nether_wart_block)
B(0,0,7,minecraft:nether_wart_block)
B(1,0,7,minecraft:nether_wart_block)
B(2,0,7,minecraft:nether_wart_block)
B(3,0,7,minecraft:nether_wart_block)
B(4,0,7,minecraft:nether_wart_block)
B(5,0,7,minecraft:nether_wart_block)
B(0,0,8,minecraft:nether_wart_block)
B(1,0,8,minecraft:nether_wart_block)
B(2,0,8,minecraft:nether_wart_block)
B(3,0,8,minecraft:nether_wart_block)
B(4,0,8,minecraft:nether_wart_block)
B(5,0,8,minecraft:nether_wart_block)
B(0,0,9,minecraft:nether_wart_block)
B(1,0,9,minecraft:nether_wart_block)
B(2,0,9,minecraft:nether_wart_block)
B(3,0,9,minecraft:nether_wart_block)
B(4,0,9,minecraft:nether_wart_block)
B(5,0,9,minecraft:nether_wart_block)
B(6,0,9,minecraft:nether_wart_block)
B(0,0,10,minecraft:nether_wart_block)
B(1,0,10,minecraft:nether_wart_block)
B(2,0,10,minecraft:nether_wart_block)
B(3,0,10,minecraft:nether_wart_block)
B(4,0,10,minecraft:nether_wart_block)
B(5,0,10,minecraft:nether_wart_block)
B(6,0,10,minecraft:nether_wart_block)
B(7,0,10,minecraft:nether_wart_block)
B(0,0,11,minecraft:nether_wart_block)
B(1,0,11,minecraft:nether_wart_block)
B(2,0,11,minecraft:nether_wart_block)
B(3,0,11,minecraft:nether_wart_block)
B(4,0,11,minecraft:nether_wart_block)
B(5,0,11,minecraft:nether_wart_block)
B(6,0,11,minecraft:nether_wart_block)
B(7,0,11,minecraft:nether_wart_block)
B(8,0,11,minecraft:nether_wart_block)
B(0,0,12,minecraft:nether_wart_block)
B(1,0,12,minecraft:nether_wart_block)
B(2,0,12,minecraft:nether_wart_block)
B(3,0,12,minecraft:nether_wart_block)
B(4,0,12,minecraft:nether_wart_block)
B(5,0,12,minecraft:nether_wart_block)
B(6,0,12,minecraft:nether_wart_block)
B(7,0,12,minecraft:nether_wart_block)
B(8,0,12,minecraft:nether_wart_block)
B(9,0,12,minecraft:nether_wart_block)
B(0,0,13,minecraft:nether_wart_block)
B(1,0,13,minecraft:nether_wart_block)
B(2,0,13,minecraft:nether_wart_block)
B(3,0,13,minecraft:nether_wart_block)
B(4,0,13,minecraft:nether_wart_block)
B(5,0,13,minecraft:nether_wart_block)
B(6,0,13,minecraft:nether_wart_block)
B(7,0,13,minecraft:nether_wart_block)
B(8,0,13,minecraft:nether_wart_block)
B(9,0,13,minecraft:nether_wart_block)
B(10,0,13,minecraft:nether_wart_block)
B(0,0,14,minecraft:nether_wart_block)
B(1,0,14,minecraft:nether_wart_block)
B(2,0,14,minecraft:nether_wart_block)
B(3,0,14,minecraft:nether_wart_block)
B(4,0,14,minecraft:nether_wart_block)
B(5,0,14,minecraft:nether_wart_block)
B(6,0,14,minecraft:nether_wart_block)
B(7,0,14,minecraft:nether_wart_block)
B(8,0,14,minecraft:nether_wart_block)
B(9,0,14,minecraft:nether_wart_block)
B(10,0,14,minecraft:nether_wart_block)
B(0,0,15,minecraft:nether_wart_block)
B(1,0,15,minecraft:nether_wart_block)
B(2,0,15,minecraft:nether_wart_block)
B(3,0,15,minecraft:nether_wart_block)
B(4,0,15,minecraft:nether_wart_block)
B(5,0,15,minecraft:nether_wart_block)
B(6,0,15,minecraft:nether_wart_block)
B(7,0,15,minecraft:nether_wart_block)
B(8,0,15,minecraft:nether_wart_block)
B(9,0,15,minecraft:nether_wart_block)
B(10,0,15,minecraft:nether_wart_block)
B(11,0,15,minecraft:nether_wart_block)
B(0,1,0,minecraft:nether_wart_block)
B(1,1,0,minecraft:nether_wart_block)
B(2,1,0,minecraft:nether_wart_block)
B(3,1,0,minecraft:nether_wart_block)
B(4,1,0,minecraft:nether_wart_block)
B(0,1,1,minecraft:nether_wart_block)
B(1,1,1,minecraft:nether_wart_block)
B(2,1,1,minecraft:nether_wart_block)
B(3,1,1,minecraft:nether_wart_block)
B(4,1,1,minecraft:nether_wart_block)
B(0,1,2,minecraft:nether_wart_block)
B(1,1,2,minecraft:nether_wart_block)
B(2,1,2,minecraft:nether_wart_block)
B(3,1,2,minecraft:nether_wart_block)
B(0,1,3,minecraft:nether_wart_block)
B(1,1,3,minecraft:nether_wart_block)
B(2,1,3,minecraft:nether_wart_block)
B(3,1,3,minecraft:nether_wart_block)
B(0,1,4,minecraft:nether_wart_block)
B(1,1,4,minecraft:nether_wart_block)
B(2,1,4,minecraft:nether_wart_block)
B(3,1,4,minecraft:nether_wart_block)
B(0,1,5,minecraft:nether_wart_block)
B(1,1,5,minecraft:nether_wart_block)
B(2,1,5,minecraft:nether_wart_block)
B(3,1,5,minecraft:nether_wart_block)
B(4,1,5,minecraft:nether_wart_block)
B(0,1,6,minecraft:nether_wart_block)
B(1,1,6,minecraft:nether_wart_block)
B(2,1,6,minecraft:nether_wart_block)
B(3,1,6,minecraft:nether_wart_block)
B(4,1,6,minecraft:nether_wart_block)
B(5,1,6,minecraft:nether_wart_block)
B(0,1,7,minecraft:nether_wart_block)
B(1,1,7,minecraft:nether_wart_block)
B(2,1,7,minecraft:nether_wart_block)
B(3,1,7,minecraft:nether_wart_block)
B(4,1,7,minecraft:nether_wart_block)
B(5,1,7,minecraft:nether_wart_block)
B(0,1,8,minecraft:nether_wart_block)
B(1,1,8,minecraft:nether_wart_block)
B(2,1,8,minecraft:nether_wart_block)
B(3,1,8,minecraft:nether_wart_block)
B(4,1,8,minecraft:nether_wart_block)
B(5,1,8,minecraft:nether_wart_block)
B(0,1,9,minecraft:nether_wart_block)
B(1,1,9,minecraft:nether_wart_block)
B(2,1,9,minecraft:nether_wart_block)
B(3,1,9,minecraft:nether_wart_block)
B(4,1,9,minecraft:nether_wart_block)
B(5,1,9,minecraft:nether_wart_block)
B(6,1,9,minecraft:nether_wart_block)
B(0,1,10,minecraft:nether_wart_block)
B(1,1,10,minecraft:nether_wart_block)
B(2,1,10,minecraft:nether_wart_block)
B(3,1,10,minecraft:nether_wart_block)
B(4,1,10,minecraft:nether_wart_block)
B(5,1,10,minecraft:nether_wart_block)
B(6,1,10,minecraft:nether_wart_block)
B(7,1,10,minecraft:nether_wart_block)
B(0,1,11,minecraft:nether_wart_block)
B(1,1,11,minecraft:nether_wart_block)
B(2,1,11,minecraft:nether_wart_block)
B(3,1,11,minecraft:nether_wart_block)
B(4,1,11,minecraft:nether_wart_block)
B(5,1,11,minecraft:nether_wart_block)
B(6,1,11,minecraft:nether_wart_block)
B(7,1,11,minecraft:nether_wart_block)
B(8,1,11,minecraft:nether_wart_block)
B(0,1,12,minecraft:nether_wart_block)
B(1,1,12,minecraft:nether_wart_block)
B(2,1,12,minecraft:nether_wart_block)
B(3,1,12,minecraft:nether_wart_block)
B(4,1,12,minecraft:nether_wart_block)
B(5,1,12,minecraft:nether_wart_block)
B(6,1,12,minecraft:nether_wart_block)
B(7,1,12,minecraft:nether_wart_block)
B(8,1,12,minecraft:nether_wart_block)
B(0,1,13,minecraft:nether_wart_block)
B(1,1,13,minecraft:nether_wart_block)
B(2,1,13,minecraft:nether_wart_block)
B(3,1,13,minecraft:nether_wart_block)
B(4,1,13,minecraft:nether_wart_block)
B(5,1,13,minecraft:nether_wart_block)
B(6,1,13,minecraft:nether_wart_block)
B(7,1,13,minecraft:nether_wart_block)
B(8,1,13,minecraft:nether_wart_block)
B(9,1,13,minecraft:nether_wart_block)
B(10,1,13,minecraft:nether_wart_block)
B(0,1,14,minecraft:nether_wart_block)
B(1,1,14,minecraft:nether_wart_block)
B(2,1,14,minecraft:nether_wart_block)
B(3,1,14,minecraft:nether_wart_block)
B(4,1,14,minecraft:nether_wart_block)
B(5,1,14,minecraft:nether_wart_block)
B(6,1,14,minecraft:nether_wart_block)
B(7,1,14,minecraft:nether_wart_block)
B(8,1,14,minecraft:nether_wart_block)
B(9,1,14,minecraft:nether_wart_block)
B(10,1,14,minecraft:nether_wart_block)
B(0,1,15,minecraft:nether_wart_block)
B(1,1,15,minecraft:nether_wart_block)
B(2,1,15,minecraft:nether_wart_block)
B(3,1,15,minecraft:nether_wart_block)
B(4,1,15,minecraft:nether_wart_block)
B(5,1,15,minecraft:nether_wart_block)
B(6,1,15,minecraft:nether_wart_block)
B(7,1,15,minecraft:nether_wart_block)
B(8,1,15,minecraft:nether_wart_block)
B(9,1,15,minecraft:nether_wart_block)
B(10,1,15,minecraft:nether_wart_block)
B(11,1,15,minecraft:nether_wart_block)
B(0,2,0,minecraft:nether_wart_block)
B(1,2,0,minecraft:nether_wart_block)
B(2,2,0,minecraft:nether_wart_block)
B(3,2,0,minecraft:nether_wart_block)
B(4,2,0,minecraft:nether_wart_block)
B(0,2,1,minecraft:nether_wart_block)
B(1,2,1,minecraft:nether_wart_block)
B(2,2,1,minecraft:nether_wart_block)
B(3,2,1,minecraft:nether_wart_block)
B(4,2,1,minecraft:nether_wart_block)
B(0,2,2,minecraft:nether_wart_block)
B(1,2,2,minecraft:nether_wart_block)
B(2,2,2,minecraft:nether_wart_block)
B(3,2,2,minecraft:nether_wart_block)
B(0,2,3,minecraft:nether_wart_block)
B(1,2,3,minecraft:nether_wart_block)
B(2,2,3,minecraft:nether_wart_block)
B(3,2,3,minecraft:nether_wart_block)
B(0,2,4,minecraft:nether_wart_block)
B(1,2,4,minecraft:nether_wart_block)
B(2,2,4,minecraft:nether_wart_block)
B(3,2,4,minecraft:nether_wart_block)
B(0,2,5,minecraft:nether_wart_block)
B(1,2,5,minecraft:nether_wart_block)
B(2,2,5,minecraft:nether_wart_block)
B(3,2,5,minecraft:nether_wart_block)
B(4,2,5,minecraft:nether_wart_block)
B(0,2,6,minecraft:nether_wart_block)
B(1,2,6,minecraft:nether_wart_block)
B(2,2,6,minecraft:nether_wart_block)
B(3,2,6,minecraft:nether_wart_block)
B(4,2,6,minecraft:nether_wart_block)
B(5,2,6,minecraft:nether_wart_block)
B(0,2,7,minecraft:nether_wart_block)
B(1,2,7,minecraft:nether_wart_block)
B(2,2,7,minecraft:nether_wart_block)
B(3,2,7,minecraft:nether_wart_block)
B(4,2,7,minecraft:nether_wart_block)
B(5,2,7,minecraft:nether_wart_block)
B(0,2,8,minecraft:nether_wart_block)
B(1,2,8,minecraft:nether_wart_block)
B(2,2,8,minecraft:nether_wart_block)
B(3,2,8,minecraft:nether_wart_block)
B(4,2,8,minecraft:nether_wart_block)
B(5,2,8,minecraft:nether_wart_block)
B(0,2,9,minecraft:nether_wart_block)
B(1,2,9,minecraft:nether_wart_block)
B(2,2,9,minecraft:nether_wart_block)
B(3,2,9,minecraft:nether_wart_block)
B(4,2,9,minecraft:nether_wart_block)
B(5,2,9,minecraft:nether_wart_block)
B(6,2,9,minecraft:nether_wart_block)
B(0,2,10,minecraft:nether_wart_block)
B(1,2,10,minecraft:nether_wart_block)
B(2,2,10,minecraft:nether_wart_block)
B(3,2,10,minecraft:nether_wart_block)
B(4,2,10,minecraft:nether_wart_block)
B(5,2,10,minecraft:nether_wart_block)
B(6,2,10,minecraft:nether_wart_block)
B(7,2,10,minecraft:nether_wart_block)
B(0,2,11,minecraft:nether_wart_block)
B(1,2,11,minecraft:nether_wart_block)
B(2,2,11,minecraft:nether_wart_block)
B(3,2,11,minecraft:nether_wart_block)
B(4,2,11,minecraft:nether_wart_block)
B(5,2,11,minecraft:nether_wart_block)
B(6,2,11,minecraft:nether_wart_block)
B(7,2,11,minecraft:nether_wart_block)
B(8,2,11,minecraft:nether_wart_block)
B(0,2,12,minecraft:nether_wart_block)
B(1,2,12,minecraft:nether_wart_block)
B(2,2,12,minecraft:nether_wart_block)
B(3,2,12,minecraft:nether_wart_block)
B(4,2,12,minecraft:nether_wart_block)
B(5,2,12,minecraft:nether_wart_block)
B(6,2,12,minecraft:nether_wart_block)
B(7,2,12,minecraft:nether_wart_block)
B(8,2,12,minecraft:nether_wart_block)
B(0,2,13,minecraft:nether_wart_block)
B(1,2,13,minecraft:nether_wart_block)
B(2,2,13,minecraft:nether_wart_block)
B(3,2,13,minecraft:nether_wart_block)
B(4,2,13,minecraft:nether_wart_block)
B(5,2,13,minecraft:nether_wart_block)
B(6,2,13,minecraft:nether_wart_block)
B(7,2,13,minecraft:nether_wart_block)
B(8,2,13,minecraft:nether_wart_block)
B(9,2,13,minecraft:nether_wart_block)
B(0,2,14,minecraft:nether_wart_block)
B(1,2,14,minecraft:nether_wart_block)
B(2,2,14,minecraft:nether_wart_block)
B(3,2,14,minecraft:nether_wart_block)
B(4,2,14,minecraft:nether_wart_block)
B(5,2,14,minecraft:nether_wart_block)
B(6,2,14,minecraft:nether_wart_block)
B(7,2,14,minecraft:nether_wart_block)
B(8,2,14,minecraft:nether_wart_block)
B(9,2,14,minecraft:nether_wart_block)
B(10,2,14,minecraft:nether_wart_block)
B(0,2,15,minecraft:nether_wart_block)
B(1,2,15,minecraft:nether_wart_block)
B(2,2,15,minecraft:nether_wart_block)
B(3,2,15,minecraft:nether_wart_block)
B(4,2,15,minecraft:nether_wart_block)
B(5,2,15,minecraft:nether_wart_block)
B(6,2,15,minecraft:nether_wart_block)
B(7,2,15,minecraft:nether_wart_block)
B(8,2,15,minecraft:nether_wart_block)
B(9,2,15,minecraft:nether_wart_block)
B(10,2,15,minecraft:nether_wart_block)
B(11,2,15,minecraft:nether_wart_block)
B(0,3,0,minecraft:nether_wart_block)
B(1,3,0,minecraft:nether_wart_block)
B(2,3,0,minecraft:nether_wart_block)
B(3,3,0,minecraft:nether_wart_block)
B(4,3,0,minecraft:nether_wart_block)
B(0,3,1,minecraft:nether_wart_block)
B(1,3,1,minecraft:nether_wart_block)
B(2,3,1,minecraft:nether_wart_block)
B(3,3,1,minecraft:nether_wart_block)
B(4,3,1,minecraft:nether_wart_block)
B(0,3,2,minecraft:nether_wart_block)
B(1,3,2,minecraft:nether_wart_block)
B(2,3,2,minecraft:nether_wart_block)
B(3,3,2,minecraft:nether_wart_block)
B(0,3,3,minecraft:nether_wart_block)
B(1,3,3,minecraft:nether_wart_block)
B(2,3,3,minecraft:nether_wart_block)
B(3,3,3,minecraft:nether_wart_block)
B(0,3,4,minecraft:nether_wart_block)
B(1,3,4,minecraft:nether_wart_block)
B(2,3,4,minecraft:nether_wart_block)
B(3,3,4,minecraft:nether_wart_block)
B(0,3,5,minecraft:nether_wart_block)
B(1,3,5,minecraft:nether_wart_block)
B(2,3,5,minecraft:nether_wart_block)
B(3,3,5,minecraft:nether_wart_block)
B(4,3,5,minecraft:nether_wart_block)
B(0,3,6,minecraft:nether_wart_block)
B(1,3,6,minecraft:nether_wart_block)
B(2,3,6,minecraft:nether_wart_block)
B(3,3,6,minecraft:nether_wart_block)
B(4,3,6,minecraft:nether_wart_block)
B(5,3,6,minecraft:nether_wart_block)
B(0,3,7,minecraft:nether_wart_block)
B(1,3,7,minecraft:nether_wart_block)
B(2,3,7,minecraft:nether_wart_block)
B(3,3,7,minecraft:nether_wart_block)
B(4,3,7,minecraft:nether_wart_block)
B(5,3,7,minecraft:nether_wart_block)
B(0,3,8,minecraft:nether_wart_block)
B(1,3,8,minecraft:nether_wart_block)
B(2,3,8,minecraft:nether_wart_block)
B(3,3,8,minecraft:nether_wart_block)
B(4,3,8,minecraft:nether_wart_block)
B(5,3,8,minecraft:nether_wart_block)
B(0,3,9,minecraft:nether_wart_block)
B(1,3,9,minecraft:nether_wart_block)
B(2,3,9,minecraft:nether_wart_block)
B(3,3,9,minecraft:nether_wart_block)
B(4,3,9,minecraft:nether_wart_block)
B(5,3,9,minecraft:nether_wart_block)
B(6,3,9,minecraft:nether_wart_block)
B(0,3,10,minecraft:nether_wart_block)
B(1,3,10,minecraft:nether_wart_block)
B(2,3,10,minecraft:nether_wart_block)
B(3,3,10,minecraft:nether_wart_block)
B(4,3,10,minecraft:nether_wart_block)
B(5,3,10,minecraft:nether_wart_block)
B(6,3,10,minecraft:nether_wart_block)
B(7,3,10,minecraft:nether_wart_block)
B(0,3,11,minecraft:nether_wart_block)
B(1,3,11,minecraft:nether_wart_block)
B(2,3,11,minecraft:nether_wart_block)
B(3,3,11,minecraft:nether_wart_block)
B(4,3,11,minecraft:nether_wart_block)
B(5,3,11,minecraft:nether_wart_block)
B(6,3,11,minecraft:nether_wart_block)
B(7,3,11,minecraft:nether_wart_block)
B(0,3,12,minecraft:nether_wart_block)
B(1,3,12,minecraft:nether_wart_block)
B(2,3,12,minecraft:nether_wart_block)
B(3,3,12,minecraft:nether_wart_block)
B(4,3,12,minecraft:nether_wart_block)
B(5,3,12,minecraft:nether_wart_block)
B(6,3,12,minecraft:nether_wart_block)
B(7,3,12,minecraft:nether_wart_block)
B(8,3,12,minecraft:nether_wart_block)
B(0,3,13,minecraft:nether_wart_block)
B(1,3,13,minecraft:nether_wart_block)
B(2,3,13,minecraft:nether_wart_block)
B(3,3,13,minecraft:nether_wart_block)
B(4,3,13,minecraft:nether_wart_block)
B(5,3,13,minecraft:nether_wart_block)
B(6,3,13,minecraft:nether_wart_block)
B(7,3,13,minecraft:nether_wart_block)
B(8,3,13,minecraft:nether_wart_block)
B(9,3,13,minecraft:nether_wart_block)
B(0,3,14,minecraft:nether_wart_block)
B(1,3,14,minecraft:nether_wart_block)
B(2,3,14,minecraft:nether_wart_block)
B(3,3,14,minecraft:nether_wart_block)
B(4,3,14,minecraft:nether_wart_block)
B(5,3,14,minecraft:nether_wart_block)
B(6,3,14,minecraft:nether_wart_block)
B(7,3,14,minecraft:nether_wart_block)
B(8,3,14,minecraft:nether_wart_block)
B(9,3,14,minecraft:nether_wart_block)
B(10,3,14,minecraft:nether_wart_block)
B(0,3,15,minecraft:nether_wart_block)
B(1,3,15,minecraft:nether_wart_block)
B(2,3,15,minecraft:nether_wart_block)
B(3,3,15,minecraft:nether_wart_block)
B(4,3,15,minecraft:nether_wart_block)
B(5,3,15,minecraft:nether_wart_block)
B(6,3,15,minecraft:nether_wart_block)
B(7,3,15,minecraft:nether_wart_block)
B(8,3,15,minecraft:nether_wart_block)
B(9,3,15,minecraft:nether_wart_block)
B(10,3,15,minecraft:nether_wart_block)
B(11,3,15,minecraft:nether_wart_block)
B(0,4,0,minecraft:nether_wart_block)
B(1,4,0,minecraft:nether_wart_block)
B(2,4,0,minecraft:nether_wart_block)
B(3,4,0,minecraft:nether_wart_block)
B(4,4,0,minecraft:nether_wart_block)
B(0,4,1,minecraft:nether_wart_block)
B(1,4,1,minecraft:nether_wart_block)
B(2,4,1,minecraft:nether_wart_block)
B(3,4,1,minecraft:nether_wart_block)
B(4,4,1,minecraft:nether_wart_block)
B(0,4,2,minecraft:nether_wart_block)
B(1,4,2,minecraft:nether_wart_block)
B(2,4,2,minecraft:nether_wart_block)
B(3,4,2,minecraft:nether_wart_block)
B(0,4,3,minecraft:nether_wart_block)
B(1,4,3,minecraft:nether_wart_block)
B(2,4,3,minecraft:nether_wart_block)
B(3,4,3,minecraft:nether_wart_block)
B(0,4,4,minecraft:nether_wart_block)
B(1,4,4,minecraft:nether_wart_block)
B(2,4,4,minecraft:nether_wart_block)
B(3,4,4,minecraft:nether_wart_block)
B(0,4,5,minecraft:nether_wart_block)
B(1,4,5,minecraft:nether_wart_block)
B(2,4,5,minecraft:nether_wart_block)
B(3,4,5,minecraft:nether_wart_block)
B(4,4,5,minecraft:nether_wart_block)
B(0,4,6,minecraft:nether_wart_block)
B(1,4,6,minecraft:nether_wart_block)
B(2,4,6,minecraft:nether_wart_block)
B(3,4,6,minecraft:nether_wart_block)
B(4,4,6,minecraft:nether_wart_block)
B(5,4,6,minecraft:nether_wart_block)
B(0,4,7,minecraft:nether_wart_block)
B(1,4,7,minecraft:nether_wart_block)
B(2,4,7,minecraft:nether_wart_block)
B(3,4,7,minecraft:nether_wart_block)
B(4,4,7,minecraft:nether_wart_block)
B(5,4,7,minecraft:nether_wart_block)
B(0,4,8,minecraft:nether_wart_block)
B(1,4,8,minecraft:nether_wart_block)
B(2,4,8,minecraft:nether_wart_block)
B(3,4,8,minecraft:nether_wart_block)
B(4,4,8,minecraft:nether_wart_block)
B(5,4,8,minecraft:nether_wart_block)
B(0,4,9,minecraft:nether_wart_block)
B(1,4,9,minecraft:nether_wart_block)
B(2,4,9,minecraft:nether_wart_block)
B(3,4,9,minecraft:nether_wart_block)
B(4,4,9,minecraft:nether_wart_block)
B(5,4,9,minecraft:nether_wart_block)
B(6,4,9,minecraft:nether_wart_block)
B(0,4,10,minecraft:nether_wart_block)
B(1,4,10,minecraft:nether_wart_block)
B(2,4,10,minecraft:nether_wart_block)
B(3,4,10,minecraft:nether_wart_block)
B(4,4,10,minecraft:nether_wart_block)
B(5,4,10,minecraft:nether_wart_block)
B(6,4,10,minecraft:nether_wart_block)
B(7,4,10,minecraft:nether_wart_block)
B(0,4,11,minecraft:nether_wart_block)
B(1,4,11,minecraft:nether_wart_block)
B(2,4,11,minecraft:nether_wart_block)
B(3,4,11,minecraft:nether_wart_block)
B(4,4,11,minecraft:nether_wart_block)
B(5,4,11,minecraft:nether_wart_block)
B(6,4,11,minecraft:nether_wart_block)
B(7,4,11,minecraft:nether_wart_block)
B(0,4,12,minecraft:nether_wart_block)
B(1,4,12,minecraft:nether_wart_block)
B(2,4,12,minecraft:nether_wart_block)
B(3,4,12,minecraft:nether_wart_block)
B(4,4,12,minecraft:nether_wart_block)
B(5,4,12,minecraft:nether_wart_block)
B(6,4,12,minecraft:nether_wart_block)
B(7,4,12,minecraft:nether_wart_block)
B(8,4,12,minecraft:nether_wart_block)
B(0,4,13,minecraft:nether_wart_block)
B(1,4,13,minecraft:nether_wart_block)
B(2,4,13,minecraft:nether_wart_block)
B(3,4,13,minecraft:nether_wart_block)
B(4,4,13,minecraft:nether_wart_block)
B(5,4,13,minecraft:nether_wart_block)
B(6,4,13,minecraft:nether_wart_block)
B(7,4,13,minecraft:nether_wart_block)
B(8,4,13,minecraft:nether_wart_block)
B(9,4,13,minecraft:nether_wart_block)
B(0,4,14,minecraft:nether_wart_block)
B(1,4,14,minecraft:nether_wart_block)
B(2,4,14,minecraft:nether_wart_block)
B(3,4,14,minecraft:nether_wart_block)
B(4,4,14,minecraft:nether_wart_block)
B(5,4,14,minecraft:nether_wart_block)
B(6,4,14,minecraft:nether_wart_block)
B(7,4,14,minecraft:nether_wart_block)
B(8,4,14,minecraft:nether_wart_block)
B(9,4,14,minecraft:nether_wart_block)
B(10,4,14,minecraft:nether_wart_block)
B(0,4,15,minecraft:nether_wart_block)
B(1,4,15,minecraft:nether_wart_block)
B(2,4,15,minecraft:nether_wart_block)
B(3,4,15,minecraft:nether_wart_block)
B(4,4,15,minecraft:nether_wart_block)
B(5,4,15,minecraft:nether_wart_block)
B(6,4,15,minecraft:nether_wart_block)
B(7,4,15,minecraft:nether_wart_block)
B(8,4,15,minecraft:nether_wart_block)
B(9,4,15,minecraft:nether_wart_block)
B(10,4,15,minecraft:nether_wart_block)
B(11,4,15,minecraft:nether_wart_block)
B(0,5,0,minecraft:nether_wart_block)
B(1,5,0,minecraft:nether_wart_block)
B(2,5,0,minecraft:nether_wart_block)
B(3,5,0,minecraft:nether_wart_block)
B(4,5,0,minecraft:nether_wart_block)
B(0,5,1,minecraft:nether_wart_block)
B(1,5,1,minecraft:nether_wart_block)
B(2,5,1,minecraft:nether_wart_block)
B(3,5,1,minecraft:nether_wart_block)
B(4,5,1,minecraft:nether_wart_block)
B(0,5,2,minecraft:nether_wart_block)
B(1,5,2,minecraft:nether_wart_block)
B(2,5,2,minecraft:nether_wart_block)
B(3,5,2,minecraft:nether_wart_block)
B(0,5,3,minecraft:nether_wart_block)
B(1,5,3,minecraft:nether_wart_block)
B(2,5,3,minecraft:nether_wart_block)
B(3,5,3,minecraft:nether_wart_block)
B(0,5,4,minecraft:nether_wart_block)
B(1,5,4,minecraft:nether_wart_block)
B(2,5,4,minecraft:nether_wart_block)
B(3,5,4,minecraft:nether_wart_block)
B(0,5,5,minecraft:nether_wart_block)
B(1,5,5,minecraft:nether_wart_block)
B(2,5,5,minecraft:nether_wart_block)
B(3,5,5,minecraft:nether_wart_block)
B(4,5,5,minecraft:nether_wart_block)
B(0,5,6,minecraft:nether_wart_block)
B(1,5,6,minecraft:nether_wart_block)
B(2,5,6,minecraft:nether_wart_block)
B(3,5,6,minecraft:nether_wart_block)
B(4,5,6,minecraft:nether_wart_block)
B(5,5,6,minecraft:nether_wart_block)
B(0,5,7,minecraft:nether_wart_block)
B(1,5,7,minecraft:nether_wart_block)
B(2,5,7,minecraft:nether_wart_block)
B(3,5,7,minecraft:nether_wart_block)
B(4,5,7,minecraft:nether_wart_block)
B(5,5,7,minecraft:nether_wart_block)
B(0,5,8,minecraft:nether_wart_block)
B(1,5,8,minecraft:nether_wart_block)
B(2,5,8,minecraft:nether_wart_block)
B(3,5,8,minecraft:nether_wart_block)
B(4,5,8,minecraft:nether_wart_block)
B(5,5,8,minecraft:nether_wart_block)
B(0,5,9,minecraft:nether_wart_block)
B(1,5,9,minecraft:nether_wart_block)
B(2,5,9,minecraft:nether_wart_block)
B(3,5,9,minecraft:nether_wart_block)
B(4,5,9,minecraft:nether_wart_block)
B(5,5,9,minecraft:nether_wart_block)
B(6,5,9,minecraft:nether_wart_block)
B(0,5,10,minecraft:nether_wart_block)
B(1,5,10,minecraft:nether_wart_block)
B(2,5,10,minecraft:nether_wart_block)
B(3,5,10,minecraft:nether_wart_block)
B(4,5,10,minecraft:nether_wart_block)
B(5,5,10,minecraft:nether_wart_block)
B(6,5,10,minecraft:nether_wart_block)
B(7,5,10,minecraft:nether_wart_block)
B(0,5,11,minecraft:nether_wart_block)
B(1,5,11,minecraft:nether_wart_block)
B(2,5,11,minecraft:nether_wart_block)
B(3,5,11,minecraft:nether_wart_block)
B(4,5,11,minecraft:nether_wart_block)
B(5,5,11,minecraft:nether_wart_block)
B(6,5,11,minecraft:nether_wart_block)
B(7,5,11,minecraft:nether_wart_block)
B(0,5,12,minecraft:nether_wart_block)
B(1,5,12,minecraft:nether_wart_block)
B(2,5,12,minecraft:nether_wart_block)
B(3,5,12,minecraft:nether_wart_block)
B(4,5,12,minecraft:nether_wart_block)
B(5,5,12,minecraft:nether_wart_block)
B(6,5,12,minecraft:nether_wart_block)
B(7,5,12,minecraft:nether_wart_block)
B(0,5,13,minecraft:nether_wart_block)
B(1,5,13,minecraft:nether_wart_block)
B(2,5,13,minecraft:nether_wart_block)
B(3,5,13,minecraft:nether_wart_block)
B(4,5,13,minecraft:nether_wart_block)
B(5,5,13,minecraft:nether_wart_block)
B(6,5,13,minecraft:nether_wart_block)
B(7,5,13,minecraft:nether_wart_block)
B(8,5,13,minecraft:nether_wart_block)
B(9,5,13,minecraft:nether_wart_block)
B(0,5,14,minecraft:nether_wart_block)
B(1,5,14,minecraft:nether_wart_block)
B(2,5,14,minecraft:nether_wart_block)
B(3,5,14,minecraft:nether_wart_block)
B(4,5,14,minecraft:nether_wart_block)
B(5,5,14,minecraft:nether_wart_block)
B(6,5,14,minecraft:nether_wart_block)
B(7,5,14,minecraft:nether_wart_block)
B(8,5,14,minecraft:nether_wart_block)
B(9,5,14,minecraft:nether_wart_block)
B(10,5,14,minecraft:nether_wart_block)
B(0,5,15,minecraft:nether_wart_block)
B(1,5,15,minecraft:nether_wart_block)
B(2,5,15,minecraft:nether_wart_block)
B(3,5,15,minecraft:nether_wart_block)
B(4,5,15,minecraft:nether_wart_block)
B(5,5,15,minecraft:nether_wart_block)
B(6,5,15,minecraft:nether_wart_block)
B(7,5,15,minecraft:nether_wart_block)
B(8,5,15,minecraft:nether_wart_block)
B(9,5,15,minecraft:nether_wart_block)
B(10,5,15,minecraft:nether_wart_block)
B(0,6,0,minecraft:nether_wart_block)
B(1,6,0,minecraft:nether_wart_block)
B(2,6,0,minecraft:nether_wart_block)
B(3,6,0,minecraft:nether_wart_block)
B(4,6,0,minecraft:nether_wart_block)
B(0,6,1,minecraft:nether_wart_block)
B(1,6,1,minecraft:nether_wart_block)
B(2,6,1,minecraft:nether_wart_block)
B(3,6,1,minecraft:nether_wart_block)
B(4,6,1,minecraft:nether_wart_block)
B(0,6,2,minecraft:nether_wart_block)
B(1,6,2,minecraft:nether_wart_block)
B(2,6,2,minecraft:nether_wart_block)
B(3,6,2,minecraft:nether_wart_block)
B(0,6,3,minecraft:nether_wart_block)
B(1,6,3,minecraft:nether_wart_block)
B(2,6,3,minecraft:nether_wart_block)
B(3,6,3,minecraft:nether_wart_block)
B(0,6,4,minecraft:nether_wart_block)
B(1,6,4,minecraft:nether_wart_block)
B(2,6,4,minecraft:nether_wart_block)
B(3,6,4,minecraft:nether_wart_block)
B(0,6,5,minecraft:nether_wart_block)
B(1,6,5,minecraft:nether_wart_block)
B(2,6,5,minecraft:nether_wart_block)
B(3,6,5,minecraft:nether_wart_block)
B(4,6,5,minecraft:nether_wart_block)
B(0,6,6,minecraft:nether_wart_block)
B(1,6,6,minecraft:nether_wart_block)
B(2,6,6,minecraft:nether_wart_block)
B(3,6,6,minecraft:nether_wart_block)
B(4,6,6,minecraft:nether_wart_block)
B(5,6,6,minecraft:nether_wart_block)
B(0,6,7,minecraft:nether_wart_block)
B(1,6,7,minecraft:nether_wart_block)
B(2,6,7,minecraft:nether_wart_block)
B(3,6,7,minecraft:nether_wart_block)
B(4,6,7,minecraft:nether_wart_block)
B(5,6,7,minecraft:nether_wart_block)
B(0,6,8,minecraft:nether_wart_block)
B(1,6,8,minecraft:nether_wart_block)
B(2,6,8,minecraft:nether_wart_block)
B(3,6,8,minecraft:nether_wart_block)
B(4,6,8,minecraft:nether_wart_block)
B(5,6,8,minecraft:nether_wart_block)
B(0,6,9,minecraft:nether_wart_block)
B(1,6,9,minecraft:nether_wart_block)
B(2,6,9,minecraft:nether_wart_block)
B(3,6,9,minecraft:nether_wart_block)
B(4,6,9,minecraft:nether_wart_block)
B(5,6,9,minecraft:nether_wart_block)
B(6,6,9,minecraft:nether_wart_block)
B(0,6,10,minecraft:nether_wart_block)
B(1,6,10,minecraft:nether_wart_block)
B(2,6,10,minecraft:nether_wart_block)
B(3,6,10,minecraft:nether_wart_block)
B(4,6,10,minecraft:nether_wart_block)
B(5,6,10,minecraft:nether_wart_block)
B(6,6,10,minecraft:nether_wart_block)
B(7,6,10,minecraft:nether_wart_block)
B(0,6,11,minecraft:nether_wart_block)
B(1,6,11,minecraft:nether_wart_block)
B(2,6,11,minecraft:nether_wart_block)
B(3,6,11,minecraft:nether_wart_block)
B(4,6,11,minecraft:nether_wart_block)
B(5,6,11,minecraft:nether_wart_block)
B(6,6,11,minecraft:nether_wart_block)
B(7,6,11,minecraft:nether_wart_block)
B(0,6,12,minecraft:nether_wart_block)
B(1,6,12,minecraft:nether_wart_block)
B(2,6,12,minecraft:nether_wart_block)
B(3,6,12,minecraft:nether_wart_block)
B(4,6,12,minecraft:nether_wart_block)
B(5,6,12,minecraft:nether_wart_block)
B(6,6,12,minecraft:nether_wart_block)
B(7,6,12,minecraft:nether_wart_block)
B(0,6,13,minecraft:nether_wart_block)
B(1,6,13,minecraft:nether_wart_block)
B(2,6,13,minecraft:nether_wart_block)
B(3,6,13,minecraft:nether_wart_block)
B(4,6,13,minecraft:nether_wart_block)
B(5,6,13,minecraft:nether_wart_block)
B(6,6,13,minecraft:nether_wart_block)
B(7,6,13,minecraft:nether_wart_block)
B(8,6,13,minecraft:nether_wart_block)
B(9,6,13,minecraft:nether_wart_block)
B(0,6,14,minecraft:nether_wart_block)
B(1,6,14,minecraft:nether_wart_block)
B(2,6,14,minecraft:nether_wart_block)
B(3,6,14,minecraft:nether_wart_block)
B(4,6,14,minecraft:nether_wart_block)
B(5,6,14,minecraft:nether_wart_block)
B(6,6,14,minecraft:nether_wart_block)
B(7,6,14,minecraft:nether_wart_block)
B(8,6,14,minecraft:nether_wart_block)
B(9,6,14,minecraft:nether_wart_block)
B(10,6,14,minecraft:nether_wart_block)
B(0,6,15,minecraft:nether_wart_block)
B(1,6,15,minecraft:nether_wart_block)
B(2,6,15,minecraft:nether_wart_block)
B(3,6,15,minecraft:nether_wart_block)
B(4,6,15,minecraft:nether_wart_block)
B(5,6,15,minecraft:nether_wart_block)
B(6,6,15,minecraft:nether_wart_block)
B(7,6,15,minecraft:nether_wart_block)
B(8,6,15,minecraft:nether_wart_block)
B(9,6,15,minecraft:nether_wart_block)
B(10,6,15,minecraft:nether_wart_block)
B(0,7,0,minecraft:nether_wart_block)
B(1,7,0,minecraft:nether_wart_block)
B(2,7,0,minecraft:nether_wart_block)
B(3,7,0,minecraft:nether_wart_block)
B(4,7,0,minecraft:nether_wart_block)
B(0,7,1,minecraft:nether_wart_block)
B(1,7,1,minecraft:nether_wart_block)
B(2,7,1,minecraft:nether_wart_block)
B(3,7,1,minecraft:nether_wart_block)
B(4,7,1,minecraft:nether_wart_block)
B(0,7,2,minecraft:nether_wart_block)
B(1,7,2,minecraft:nether_wart_block)
B(2,7,2,minecraft:nether_wart_block)
B(3,7,2,minecraft:nether_wart_block)
B(0,7,3,minecraft:nether_wart_block)
B(1,7,3,minecraft:nether_wart_block)
B(2,7,3,minecraft:nether_wart_block)
B(3,7,3,minecraft:nether_wart_block)
B(0,7,4,minecraft:nether_wart_block)
B(1,7,4,minecraft:nether_wart_block)
B(2,7,4,minecraft:nether_wart_block)
B(3,7,4,minecraft:nether_wart_block)
B(0,7,5,minecraft:nether_wart_block)
B(1,7,5,minecraft:nether_wart_block)
B(2,7,5,minecraft:nether_wart_block)
B(3,7,5,minecraft:nether_wart_block)
B(4,7,5,minecraft:nether_wart_block)
B(0,7,6,minecraft:nether_wart_block)
B(1,7,6,minecraft:nether_wart_block)
B(2,7,6,minecraft:nether_wart_block)
B(3,7,6,minecraft:nether_wart_block)
B(4,7,6,minecraft:nether_wart_block)
B(5,7,6,minecraft:nether_wart_block)
B(0,7,7,minecraft:nether_wart_block)
B(1,7,7,minecraft:nether_wart_block)
B(2,7,7,minecraft:nether_wart_block)
B(3,7,7,minecraft:nether_wart_block)
B(4,7,7,minecraft:nether_wart_block)
B(5,7,7,minecraft:nether_wart_block)
B(0,7,8,minecraft:nether_wart_block)
B(1,7,8,minecraft:nether_wart_block)
B(2,7,8,minecraft:nether_wart_block)
B(3,7,8,minecraft:nether_wart_block)
B(4,7,8,minecraft:nether_wart_block)
B(5,7,8,minecraft:nether_wart_block)
B(0,7,9,minecraft:nether_wart_block)
B(1,7,9,minecraft:nether_wart_block)
B(2,7,9,minecraft:nether_wart_block)
B(3,7,9,minecraft:nether_wart_block)
B(4,7,9,minecraft:nether_wart_block)
B(5,7,9,minecraft:nether_wart_block)
B(6,7,9,minecraft:nether_wart_block)
B(0,7,10,minecraft:nether_wart_block)
B(1,7,10,minecraft:nether_wart_block)
B(2,7,10,minecraft:nether_wart_block)
B(3,7,10,minecraft:nether_wart_block)
B(4,7,10,minecraft:nether_wart_block)
B(5,7,10,minecraft:nether_wart_block)
B(6,7,10,minecraft:nether_wart_block)
B(7,7,10,minecraft:nether_wart_block)
B(0,7,11,minecraft:nether_wart_block)
B(1,7,11,minecraft:nether_wart_block)
B(2,7,11,minecraft:nether_wart_block)
B(3,7,11,minecraft:nether_wart_block)
B(4,7,11,minecraft:nether_wart_block)
B(5,7,11,minecraft:nether_wart_block)
B(6,7,11,minecraft:nether_wart_block)
B(7,7,11,minecraft:nether_wart_block)
B(0,7,12,minecraft:nether_wart_block)
B(1,7,12,minecraft:nether_wart_block)
B(2,7,12,minecraft:nether_wart_block)
B(3,7,12,minecraft:nether_wart_block)
B(4,7,12,minecraft:nether_wart_block)
B(5,7,12,minecraft:nether_wart_block)
B(6,7,12,minecraft:nether_wart_block)
B(7,7,12,minecraft:nether_wart_block)
B(0,7,13,minecraft:nether_wart_block)
B(1,7,13,minecraft:nether_wart_block)
B(2,7,13,minecraft:nether_wart_block)
B(3,7,13,minecraft:nether_wart_block)
B(4,7,13,minecraft:nether_wart_block)
B(5,7,13,minecraft:nether_wart_block)
B(6,7,13,minecraft:nether_wart_block)
B(7,7,13,minecraft:nether_wart_block)
B(8,7,13,minecraft:nether_wart_block)
B(9,7,13,minecraft:nether_wart_block)
B(0,7,14,minecraft:nether_wart_block)
B(1,7,14,minecraft:nether_wart_block)
B(2,7,14,minecraft:nether_wart_block)
B(3,7,14,minecraft:nether_wart_block)
B(4,7,14,minecraft:nether_wart_block)
B(5,7,14,minecraft:nether_wart_block)
B(6,7,14,minecraft:nether_wart_block)
B(7,7,14,minecraft:nether_wart_block)
B(8,7,14,minecraft:nether_wart_block)
B(9,7,14,minecraft:nether_wart_block)
B(10,7,14,minecraft:nether_wart_block)
B(0,7,15,minecraft:nether_wart_block)
B(1,7,15,minecraft:nether_wart_block)
B(2,7,15,minecraft:nether_wart_block)
B(3,7,15,minecraft:nether_wart_block)
B(4,7,15,minecraft:nether_wart_block)
B(5,7,15,minecraft:nether_wart_block)
B(6,7,15,minecraft:nether_wart_block)
B(7,7,15,minecraft:nether_wart_block)
B(8,7,15,minecraft:nether_wart_block)
B(9,7,15,minecraft:nether_wart_block)
B(10,7,15,minecraft:nether_wart_block)
B(0,8,0,minecraft:nether_wart_block)
B(1,8,0,minecraft:nether_wart_block)
B(2,8,0,minecraft:nether_wart_block)
B(3,8,0,minecraft:nether_wart_block)
B(4,8,0,minecraft:nether_wart_block)
B(0,8,1,minecraft:nether_wart_block)
B(1,8,1,minecraft:nether_wart_block)
B(2,8,1,minecraft:nether_wart_block)
B(3,8,1,minecraft:nether_wart_block)
B(4,8,1,minecraft:nether_wart_block)
B(0,8,2,minecraft:nether_wart_block)
B(1,8,2,minecraft:nether_wart_block)
B(2,8,2,minecraft:nether_wart_block)
B(3,8,2,minecraft:nether_wart_block)
B(0,8,3,minecraft:nether_wart_block)
B(1,8,3,minecraft:nether_wart_block)
B(2,8,3,minecraft:nether_wart_block)
B(3,8,3,minecraft:nether_wart_block)
B(0,8,4,minecraft:nether_wart_block)
B(1,8,4,minecraft:nether_wart_block)
B(2,8,4,minecraft:nether_wart_block)
B(3,8,4,minecraft:nether_wart_block)
B(0,8,5,minecraft:nether_wart_block)
B(1,8,5,minecraft:nether_wart_block)
B(2,8,5,minecraft:nether_wart_block)
B(3,8,5,minecraft:nether_wart_block)
B(4,8,5,minecraft:nether_wart_block)
B(0,8,6,minecraft:nether_wart_block)
B(1,8,6,minecraft:nether_wart_block)
B(2,8,6,minecraft:nether_wart_block)
B(3,8,6,minecraft:nether_wart_block)
B(4,8,6,minecraft:nether_wart_block)
B(5,8,6,minecraft:nether_wart_block)
B(0,8,7,minecraft:nether_wart_block)
B(1,8,7,minecraft:nether_wart_block)
B(2,8,7,minecraft:nether_wart_block)
B(3,8,7,minecraft:nether_wart_block)
B(4,8,7,minecraft:nether_wart_block)
B(5,8,7,minecraft:nether_wart_block)
B(0,8,8,minecraft:nether_wart_block)
B(1,8,8,minecraft:nether_wart_block)
B(2,8,8,minecraft:nether_wart_block)
B(3,8,8,minecraft:nether_wart_block)
B(4,8,8,minecraft:nether_wart_block)
B(5,8,8,minecraft:nether_wart_block)
B(0,8,9,minecraft:nether_wart_block)
B(1,8,9,minecraft:nether_wart_block)
B(2,8,9,minecraft:nether_wart_block)
B(3,8,9,minecraft:nether_wart_block)
B(4,8,9,minecraft:nether_wart_block)
B(5,8,9,minecraft:nether_wart_block)
B(6,8,9,minecraft:nether_wart_block)
B(0,8,10,minecraft:nether_wart_block)
B(1,8,10,minecraft:nether_wart_block)
B(2,8,10,minecraft:nether_wart_block)
B(3,8,10,minecraft:nether_wart_block)
B(4,8,10,minecraft:nether_wart_block)
B(5,8,10,minecraft:nether_wart_block)
B(6,8,10,minecraft:nether_wart_block)
B(7,8,10,minecraft:nether_wart_block)
B(0,8,11,minecraft:nether_wart_block)
B(1,8,11,minecraft:nether_wart_block)
B(2,8,11,minecraft:nether_wart_block)
B(3,8,11,minecraft:nether_wart_block)
B(4,8,11,minecraft:nether_wart_block)
B(5,8,11,minecraft:nether_wart_block)
B(6,8,11,minecraft:nether_wart_block)
B(7,8,11,minecraft:nether_wart_block)
B(0,8,12,minecraft:nether_wart_block)
B(1,8,12,minecraft:nether_wart_block)
B(2,8,12,minecraft:nether_wart_block)
B(3,8,12,minecraft:nether_wart_block)
B(4,8,12,minecraft:nether_wart_block)
B(5,8,12,minecraft:nether_wart_block)
B(6,8,12,minecraft:nether_wart_block)
B(7,8,12,minecraft:nether_wart_block)
B(0,8,13,minecraft:nether_wart_block)
B(1,8,13,minecraft:nether_wart_block)
B(2,8,13,minecraft:nether_wart_block)
B(3,8,13,minecraft:nether_wart_block)
B(4,8,13,minecraft:nether_wart_block)
B(5,8,13,minecraft:nether_wart_block)
B(6,8,13,minecraft:nether_wart_block)
B(7,8,13,minecraft:nether_wart_block)
B(8,8,13,minecraft:nether_wart_block)
B(9,8,13,minecraft:nether_wart_block)
B(0,8,14,minecraft:nether_wart_block)
B(1,8,14,minecraft:nether_wart_block)
B(2,8,14,minecraft:nether_wart_block)
B(3,8,14,minecraft:nether_wart_block)
B(4,8,14,minecraft:nether_wart_block)
B(5,8,14,minecraft:nether_wart_block)
B(6,8,14,minecraft:nether_wart_block)
B(7,8,14,minecraft:nether_wart_block)
B(8,8,14,minecraft:nether_wart_block)
B(9,8,14,minecraft:nether_wart_block)
B(10,8,14,minecraft:nether_wart_block)
B(0,8,15,minecraft:nether_wart_block)
B(1,8,15,minecraft:nether_wart_block)
B(2,8,15,minecraft:nether_wart_block)
B(3,8,15,minecraft:nether_wart_block)
B(4,8,15,minecraft:nether_wart_block)
B(5,8,15,minecraft:nether_wart_block)
B(6,8,15,minecraft:nether_wart_block)
B(7,8,15,minecraft:nether_wart_block)
B(8,8,15,minecraft:nether_wart_block)
B(9,8,15,minecraft:nether_wart_block)
B(10,8,15,minecraft:nether_wart_block)
B(0,9,0,minecraft:nether_wart_block)
B(1,9,0,minecraft:nether_wart_block)
B(2,9,0,minecraft:nether_wart_block)
B(3,9,0,minecraft:nether_wart_block)
B(4,9,0,minecraft:nether_wart_block)
B(0,9,1,minecraft:nether_wart_block)
B(1,9,1,minecraft:nether_wart_block)
B(2,9,1,minecraft:nether_wart_block)
B(3,9,1,minecraft:nether_wart_block)
B(4,9,1,minecraft:nether_wart_block)
B(0,9,2,minecraft:nether_wart_block)
B(1,9,2,minecraft:nether_wart_block)
B(2,9,2,minecraft:nether_wart_block)
B(3,9,2,minecraft:nether_wart_block)
B(0,9,3,minecraft:nether_wart_block)
B(1,9,3,minecraft:nether_wart_block)
B(2,9,3,minecraft:nether_wart_block)
B(3,9,3,minecraft:nether_wart_block)
B(0,9,4,minecraft:nether_wart_block)
B(1,9,4,minecraft:nether_wart_block)
B(2,9,4,minecraft:nether_wart_block)
B(3,9,4,minecraft:nether_wart_block)
B(0,9,5,minecraft:nether_wart_block)
B(1,9,5,minecraft:nether_wart_block)
B(2,9,5,minecraft:nether_wart_block)
B(3,9,5,minecraft:nether_wart_block)
B(4,9,5,minecraft:nether_wart_block)
B(0,9,6,minecraft:nether_wart_block)
B(1,9,6,minecraft:nether_wart_block)
B(2,9,6,minecraft:nether_wart_block)
B(3,9,6,minecraft:nether_wart_block)
B(4,9,6,minecraft:nether_wart_block)
B(0,9,7,minecraft:nether_wart_block)
B(1,9,7,minecraft:nether_wart_block)
B(2,9,7,minecraft:nether_wart_block)
B(3,9,7,minecraft:nether_wart_block)
B(4,9,7,minecraft:nether_wart_block)
B(5,9,7,minecraft:nether_wart_block)
B(0,9,8,minecraft:nether_wart_block)
B(1,9,8,minecraft:nether_wart_block)
B(2,9,8,minecraft:nether_wart_block)
B(3,9,8,minecraft:nether_wart_block)
B(4,9,8,minecraft:nether_wart_block)
B(5,9,8,minecraft:nether_wart_block)
B(0,9,9,minecraft:nether_wart_block)
B(1,9,9,minecraft:nether_wart_block)
B(2,9,9,minecraft:nether_wart_block)
B(3,9,9,minecraft:nether_wart_block)
B(4,9,9,minecraft:nether_wart_block)
B(5,9,9,minecraft:nether_wart_block)
B(6,9,9,minecraft:nether_wart_block)
B(0,9,10,minecraft:nether_wart_block)
B(1,9,10,minecraft:nether_wart_block)
B(2,9,10,minecraft:nether_wart_block)
B(3,9,10,minecraft:nether_wart_block)
B(4,9,10,minecraft:nether_wart_block)
B(5,9,10,minecraft:nether_wart_block)
B(6,9,10,minecraft:nether_wart_block)
B(0,9,11,minecraft:nether_wart_block)
B(1,9,11,minecraft:nether_wart_block)
B(2,9,11,minecraft:nether_wart_block)
B(3,9,11,minecraft:nether_wart_block)
B(4,9,11,minecraft:nether_wart_block)
B(5,9,11,minecraft:nether_wart_block)
B(6,9,11,minecraft:nether_wart_block)
B(7,9,11,minecraft:nether_wart_block)
B(0,9,12,minecraft:nether_wart_block)
B(1,9,12,minecraft:nether_wart_block)
B(2,9,12,minecraft:nether_wart_block)
B(3,9,12,minecraft:nether_wart_block)
B(4,9,12,minecraft:nether_wart_block)
B(5,9,12,minecraft:nether_wart_block)
B(6,9,12,minecraft:nether_wart_block)
B(7,9,12,minecraft:nether_wart_block)
B(0,9,13,minecraft:nether_wart_block)
B(1,9,13,minecraft:nether_wart_block)
B(2,9,13,minecraft:nether_wart_block)
B(3,9,13,minecraft:nether_wart_block)
B(4,9,13,minecraft:nether_wart_block)
B(5,9,13,minecraft:nether_wart_block)
B(6,9,13,minecraft:nether_wart_block)
B(7,9,13,minecraft:nether_wart_block)
B(8,9,13,minecraft:nether_wart_block)
B(9,9,13,minecraft:nether_wart_block)
B(0,9,14,minecraft:nether_wart_block)
B(1,9,14,minecraft:nether_wart_block)
B(2,9,14,minecraft:nether_wart_block)
B(3,9,14,minecraft:nether_wart_block)
B(4,9,14,minecraft:nether_wart_block)
B(5,9,14,minecraft:nether_wart_block)
B(6,9,14,minecraft:nether_wart_block)
B(7,9,14,minecraft:nether_wart_block)
B(8,9,14,minecraft:nether_wart_block)
B(9,9,14,minecraft:nether_wart_block)
B(0,9,15,minecraft:nether_wart_block)
B(1,9,15,minecraft:nether_wart_block)
B(2,9,15,minecraft:nether_wart_block)
B(3,9,15,minecraft:nether_wart_block)
B(4,9,15,minecraft:nether_wart_block)
B(5,9,15,minecraft:nether_wart_block)
B(6,9,15,minecraft:nether_wart_block)
B(7,9,15,minecraft:nether_wart_block)
B(8,9,15,minecraft:nether_wart_block)
B(9,9,15,minecraft:nether_wart_block)
B(10,9,15,minecraft:nether_wart_block)
B(0,10,0,minecraft:nether_wart_block)
B(1,10,0,minecraft:nether_wart_block)
B(2,10,0,minecraft:nether_wart_block)
B(3,10,0,minecraft:nether_wart_block)
B(4,10,0,minecraft:nether_wart_block)
B(0,10,1,minecraft:nether_wart_block)
B(1,10,1,minecraft:nether_wart_block)
B(2,10,1,minecraft:nether_wart_block)
B(3,10,1,minecraft:nether_wart_block)
B(4,10,1,minecraft:nether_wart_block)
B(0,10,2,minecraft:nether_wart_block)
B(1,10,2,minecraft:nether_wart_block)
B(2,10,2,minecraft:nether_wart_block)
B(3,10,2,minecraft:nether_wart_block)
B(0,10,3,minecraft:nether_wart_block)
B(1,10,3,minecraft:nether_wart_block)
B(2,10,3,minecraft:nether_wart_block)
B(3,10,3,minecraft:nether_wart_block)
B(0,10,4,minecraft:nether_wart_block)
B(1,10,4,minecraft:nether_wart_block)
B(2,10,4,minecraft:nether_wart_block)
B(3,10,4,minecraft:nether_wart_block)
B(0,10,5,minecraft:nether_wart_block)
B(1,10,5,minecraft:nether_wart_block)
B(2,10,5,minecraft:nether_wart_block)
B(3,10,5,minecraft:nether_wart_block)
B(4,10,5,minecraft:nether_wart_block)
B(0,10,6,minecraft:nether_wart_block)
B(1,10,6,minecraft:nether_wart_block)
B(2,10,6,minecraft:nether_wart_block)
B(3,10,6,minecraft:nether_wart_block)
B(4,10,6,minecraft:nether_wart_block)
B(0,10,7,minecraft:nether_wart_block)
B(1,10,7,minecraft:nether_wart_block)
B(2,10,7,minecraft:nether_wart_block)
B(3,10,7,minecraft:nether_wart_block)
B(4,10,7,minecraft:nether_wart_block)
B(5,10,7,minecraft:nether_wart_block)
B(0,10,8,minecraft:nether_wart_block)
B(1,10,8,minecraft:nether_wart_block)
B(2,10,8,minecraft:nether_wart_block)
B(3,10,8,minecraft:nether_wart_block)
B(4,10,8,minecraft:nether_wart_block)
B(5,10,8,minecraft:nether_wart_block)
B(0,10,9,minecraft:nether_wart_block)
B(1,10,9,minecraft:nether_wart_block)
B(2,10,9,minecraft:nether_wart_block)
B(3,10,9,minecraft:nether_wart_block)
B(4,10,9,minecraft:nether_wart_block)
B(5,10,9,minecraft:nether_wart_block)
B(6,10,9,minecraft:nether_wart_block)
B(0,10,10,minecraft:nether_wart_block)
B(1,10,10,minecraft:nether_wart_block)
B(2,10,10,minecraft:nether_wart_block)
B(3,10,10,minecraft:nether_wart_block)
B(4,10,10,minecraft:nether_wart_block)
B(5,10,10,minecraft:nether_wart_block)
B(6,10,10,minecraft:nether_wart_block)
B(0,10,11,minecraft:nether_wart_block)
B(1,10,11,minecraft:nether_wart_block)
B(2,10,11,minecraft:nether_wart_block)
B(3,10,11,minecraft:nether_wart_block)
B(4,10,11,minecraft:nether_wart_block)
B(5,10,11,minecraft:nether_wart_block)
B(6,10,11,minecraft:nether_wart_block)
B(7,10,11,minecraft:nether_wart_block)
B(0,10,12,minecraft:nether_wart_block)
B(1,10,12,minecraft:nether_wart_block)
B(2,10,12,minecraft:nether_wart_block)
B(3,10,12,minecraft:nether_wart_block)
B(4,10,12,minecraft:nether_wart_block)
B(5,10,12,minecraft:nether_wart_block)
B(6,10,12,minecraft:nether_wart_block)
B(7,10,12,minecraft:nether_wart_block)
B(0,10,13,minecraft:nether_wart_block)
B(1,10,13,minecraft:nether_wart_block)
B(2,10,13,minecraft:nether_wart_block)
B(3,10,13,minecraft:nether_wart_block)
B(4,10,13,minecraft:nether_wart_block)
B(5,10,13,minecraft:nether_wart_block)
B(6,10,13,minecraft:nether_wart_block)
B(7,10,13,minecraft:nether_wart_block)
B(8,10,13,minecraft:nether_wart_block)
B(9,10,13,minecraft:nether_wart_block)
B(0,10,14,minecraft:nether_wart_block)
B(1,10,14,minecraft:nether_wart_block)
B(2,10,14,minecraft:nether_wart_block)
B(3,10,14,minecraft:nether_wart_block)
B(4,10,14,minecraft:nether_wart_block)
B(5,10,14,minecraft:nether_wart_block)
B(6,10,14,minecraft:nether_wart_block)
B(7,10,14,minecraft:nether_wart_block)
B(8,10,14,minecraft:nether_wart_block)
B(9,10,14,minecraft:nether_wart_block)
B(0,10,15,minecraft:nether_wart_block)
B(1,10,15,minecraft:nether_wart_block)
B(2,10,15,minecraft:nether_wart_block)
B(3,10,15,minecraft:nether_wart_block)
B(4,10,15,minecraft:nether_wart_block)
B(5,10,15,minecraft:nether_wart_block)
B(6,10,15,minecraft:nether_wart_block)
B(7,10,15,minecraft:nether_wart_block)
B(8,10,15,minecraft:nether_wart_block)
B(9,10,15,minecraft:nether_wart_block)
B(10,10,15,minecraft:nether_wart_block)
B(0,11,0,minecraft:nether_wart_block)
B(1,11,0,minecraft:nether_wart_block)
B(2,11,0,minecraft:nether_wart_block)
B(3,11,0,minecraft:nether_wart_block)
B(4,11,0,minecraft:nether_wart_block)
B(0,11,1,minecraft:nether_wart_block)
B(1,11,1,minecraft:nether_wart_block)
B(2,11,1,minecraft:nether_wart_block)
B(3,11,1,minecraft:nether_wart_block)
B(0,11,2,minecraft:nether_wart_block)
B(1,11,2,minecraft:nether_wart_block)
B(2,11,2,minecraft:nether_wart_block)
B(3,11,2,minecraft:nether_wart_block)
B(0,11,3,minecraft:nether_wart_block)
B(1,11,3,minecraft:nether_wart_block)
B(2,11,3,minecraft:nether_wart_block)
B(3,11,3,minecraft:nether_wart_block)
B(0,11,4,minecraft:nether_wart_block)
B(1,11,4,minecraft:nether_wart_block)
B(2,11,4,minecraft:nether_wart_block)
B(3,11,4,minecraft:nether_wart_block)
B(0,11,5,minecraft:nether_wart_block)
B(1,11,5,minecraft:nether_wart_block)
B(2,11,5,minecraft:nether_wart_block)
B(3,11,5,minecraft:nether_wart_block)
B(4,11,5,minecraft:nether_wart_block)
B(0,11,6,minecraft:nether_wart_block)
B(1,11,6,minecraft:nether_wart_block)
B(2,11,6,minecraft:nether_wart_block)
B(3,11,6,minecraft:nether_wart_block)
B(4,11,6,minecraft:nether_wart_block)
B(0,11,7,minecraft:nether_wart_block)
B(1,11,7,minecraft:nether_wart_block)
B(2,11,7,minecraft:nether_wart_block)
B(3,11,7,minecraft:nether_wart_block)
B(4,11,7,minecraft:nether_wart_block)
B(5,11,7,minecraft:nether_wart_block)
B(0,11,8,minecraft:nether_wart_block)
B(1,11,8,minecraft:nether_wart_block)
B(2,11,8,minecraft:nether_wart_block)
B(3,11,8,minecraft:nether_wart_block)
B(4,11,8,minecraft:nether_wart_block)
B(5,11,8,minecraft:nether_wart_block)
B(0,11,9,minecraft:nether_wart_block)
B(1,11,9,minecraft:nether_wart_block)
B(2,11,9,minecraft:nether_wart_block)
B(3,11,9,minecraft:nether_wart_block)
B(4,11,9,minecraft:nether_wart_block)
B(5,11,9,minecraft:nether_wart_block)
B(0,11,10,minecraft:nether_wart_block)
B(1,11,10,minecraft:nether_wart_block)
B(2,11,10,minecraft:nether_wart_block)
B(3,11,10,minecraft:nether_wart_block)
B(4,11,10,minecraft:nether_wart_block)
B(5,11,10,minecraft:nether_wart_block)
B(6,11,10,minecraft:nether_wart_block)
B(0,11,11,minecraft:nether_wart_block)
B(1,11,11,minecraft:nether_wart_block)
B(2,11,11,minecraft:nether_wart_block)
B(3,11,11,minecraft:nether_wart_block)
B(4,11,11,minecraft:nether_wart_block)
B(5,11,11,minecraft:nether_wart_block)
B(6,11,11,minecraft:nether_wart_block)
B(0,11,12,minecraft:nether_wart_block)
B(1,11,12,minecraft:nether_wart_block)
B(2,11,12,minecraft:nether_wart_block)
B(3,11,12,minecraft:nether_wart_block)
B(4,11,12,minecraft:nether_wart_block)
B(5,11,12,minecraft:nether_wart_block)
B(6,11,12,minecraft:nether_wart_block)
B(7,11,12,minecraft:nether_wart_block)
B(0,11,13,minecraft:nether_wart_block)
B(1,11,13,minecraft:nether_wart_block)
B(2,11,13,minecraft:nether_wart_block)
B(3,11,13,minecraft:nether_wart_block)
B(4,11,13,minecraft:nether_wart_block)
B(5,11,13,minecraft:nether_wart_block)
B(6,11,13,minecraft:nether_wart_block)
B(7,11,13,minecraft:nether_wart_block)
B(8,11,13,minecraft:nether_wart_block)
B(0,11,14,minecraft:nether_wart_block)
B(1,11,14,minecraft:nether_wart_block)
B(2,11,14,minecraft:nether_wart_block)
B(3,11,14,minecraft:nether_wart_block)
B(4,11,14,minecraft:nether_wart_block)
B(5,11,14,minecraft:nether_wart_block)
B(6,11,14,minecraft:nether_wart_block)
B(7,11,14,minecraft:nether_wart_block)
B(8,11,14,minecraft:nether_wart_block)
B(9,11,14,minecraft:nether_wart_block)
B(0,11,15,minecraft:nether_wart_block)
B(1,11,15,minecraft:nether_wart_block)
B(2,11,15,minecraft:nether_wart_block)
B(3,11,15,minecraft:nether_wart_block)
B(4,11,15,minecraft:nether_wart_block)
B(5,11,15,minecraft:nether_wart_block)
B(6,11,15,minecraft:nether_wart_block)
B(7,11,15,minecraft:nether_wart_block)
B(8,11,15,minecraft:nether_wart_block)
B(9,11,15,minecraft:nether_wart_block)
B(10,11,15,minecraft:nether_wart_block)
B(0,12,0,minecraft:nether_wart_block)
B(1,12,0,minecraft:nether_wart_block)
B(2,12,0,minecraft:nether_wart_block)
B(3,12,0,minecraft:nether_wart_block)
B(4,12,0,minecraft:nether_wart_block)
B(0,12,1,minecraft:nether_wart_block)
B(1,12,1,minecraft:nether_wart_block)
B(2,12,1,minecraft:nether_wart_block)
B(3,12,1,minecraft:nether_wart_block)
B(0,12,2,minecraft:nether_wart_block)
B(1,12,2,minecraft:nether_wart_block)
B(2,12,2,minecraft:nether_wart_block)
B(3,12,2,minecraft:nether_wart_block)
B(0,12,3,minecraft:nether_wart_block)
B(1,12,3,minecraft:nether_wart_block)
B(2,12,3,minecraft:nether_wart_block)
B(3,12,3,minecraft:nether_wart_block)
B(0,12,4,minecraft:nether_wart_block)
B(1,12,4,minecraft:nether_wart_block)
B(2,12,4,minecraft:nether_wart_block)
B(3,12,4,minecraft:nether_wart_block)
B(0,12,5,minecraft:nether_wart_block)
B(1,12,5,minecraft:nether_wart_block)
B(2,12,5,minecraft:nether_wart_block)
B(3,12,5,minecraft:nether_wart_block)
B(4,12,5,minecraft:nether_wart_block)
B(0,12,6,minecraft:nether_wart_block)
B(1,12,6,minecraft:nether_wart_block)
B(2,12,6,minecraft:nether_wart_block)
B(3,12,6,minecraft:nether_wart_block)
B(4,12,6,minecraft:nether_wart_block)
B(0,12,7,minecraft:nether_wart_block)
B(1,12,7,minecraft:nether_wart_block)
B(2,12,7,minecraft:nether_wart_block)
B(3,12,7,minecraft:nether_wart_block)
B(4,12,7,minecraft:nether_wart_block)
B(5,12,7,minecraft:nether_wart_block)
B(0,12,8,minecraft:nether_wart_block)
B(1,12,8,minecraft:nether_wart_block)
B(2,12,8,minecraft:nether_wart_block)
B(3,12,8,minecraft:nether_wart_block)
B(4,12,8,minecraft:nether_wart_block)
B(5,12,8,minecraft:nether_wart_block)
B(0,12,9,minecraft:nether_wart_block)
B(1,12,9,minecraft:nether_wart_block)
B(2,12,9,minecraft:nether_wart_block)
B(3,12,9,minecraft:nether_wart_block)
B(4,12,9,minecraft:nether_wart_block)
B(5,12,9,minecraft:nether_wart_block)
B(0,12,10,minecraft:nether_wart_block)
B(1,12,10,minecraft:nether_wart_block)
B(2,12,10,minecraft:nether_wart_block)
B(3,12,10,minecraft:nether_wart_block)
B(4,12,10,minecraft:nether_wart_block)
B(5,12,10,minecraft:nether_wart_block)
B(6,12,10,minecraft:nether_wart_block)
B(0,12,11,minecraft:nether_wart_block)
B(1,12,11,minecraft:nether_wart_block)
B(2,12,11,minecraft:nether_wart_block)
B(3,12,11,minecraft:nether_wart_block)
B(4,12,11,minecraft:nether_wart_block)
B(5,12,11,minecraft:nether_wart_block)
B(6,12,11,minecraft:nether_wart_block)
B(0,12,12,minecraft:nether_wart_block)
B(1,12,12,minecraft:nether_wart_block)
B(2,12,12,minecraft:nether_wart_block)
B(3,12,12,minecraft:nether_wart_block)
B(4,12,12,minecraft:nether_wart_block)
B(5,12,12,minecraft:nether_wart_block)
B(6,12,12,minecraft:nether_wart_block)
B(7,12,12,minecraft:nether_wart_block)
B(0,12,13,minecraft:nether_wart_block)
B(1,12,13,minecraft:nether_wart_block)
B(2,12,13,minecraft:nether_wart_block)
B(3,12,13,minecraft:nether_wart_block)
B(4,12,13,minecraft:nether_wart_block)
B(5,12,13,minecraft:nether_wart_block)
B(6,12,13,minecraft:nether_wart_block)
B(7,12,13,minecraft:nether_wart_block)
B(8,12,13,minecraft:nether_wart_block)
B(0,12,14,minecraft:nether_wart_block)
B(1,12,14,minecraft:nether_wart_block)
B(2,12,14,minecraft:nether_wart_block)
B(3,12,14,minecraft:nether_wart_block)
B(4,12,14,minecraft:nether_wart_block)
B(5,12,14,minecraft:nether_wart_block)
B(6,12,14,minecraft:nether_wart_block)
B(7,12,14,minecraft:nether_wart_block)
B(8,12,14,minecraft:nether_wart_block)
B(9,12,14,minecraft:nether_wart_block)
B(0,12,15,minecraft:nether_wart_block)
B(1,12,15,minecraft:nether_wart_block)
B(2,12,15,minecraft:nether_wart_block)
B(3,12,15,minecraft:nether_wart_block)
B(4,12,15,minecraft:nether_wart_block)
B(5,12,15,minecraft:nether_wart_block)
B(6,12,15,minecraft:nether_wart_block)
B(7,12,15,minecraft:nether_wart_block)
B(8,12,15,minecraft:nether_wart_block)
B(9,12,15,minecraft:nether_wart_block)
B(10,12,15,minecraft:nether_wart_block)
B(0,13,0,minecraft:nether_wart_block)
B(1,13,0,minecraft:nether_wart_block)
B(2,13,0,minecraft:nether_wart_block)
B(3,13,0,minecraft:nether_wart_block)
B(4,13,0,minecraft:nether_wart_block)
B(0,13,1,minecraft:nether_wart_block)
B(1,13,1,minecraft:nether_wart_block)
B(2,13,1,minecraft:nether_wart_block)
B(3,13,1,minecraft:nether_wart_block)
B(0,13,2,minecraft:nether_wart_block)
B(1,13,2,minecraft:nether_wart_block)
B(2,13,2,minecraft:nether_wart_block)
B(3,13,2,minecraft:nether_wart_block)
B(0,13,3,minecraft:nether_wart_block)
B(1,13,3,minecraft:nether_wart_block)
B(2,13,3,minecraft:nether_wart_block)
B(3,13,3,minecraft:nether_wart_block)
B(0,13,4,minecraft:nether_wart_block)
B(1,13,4,minecraft:nether_wart_block)
B(2,13,4,minecraft:nether_wart_block)
B(3,13,4,minecraft:nether_wart_block)
B(0,13,5,minecraft:nether_wart_block)
B(1,13,5,minecraft:nether_wart_block)
B(2,13,5,minecraft:nether_wart_block)
B(3,13,5,minecraft:nether_wart_block)
B(4,13,5,minecraft:nether_wart_block)
B(0,13,6,minecraft:nether_wart_block)
B(1,13,6,minecraft:nether_wart_block)
B(2,13,6,minecraft:nether_wart_block)
B(3,13,6,minecraft:nether_wart_block)
B(4,13,6,minecraft:nether_wart_block)
B(0,13,7,minecraft:nether_wart_block)
B(1,13,7,minecraft:nether_wart_block)
B(2,13,7,minecraft:nether_wart_block)
B(3,13,7,minecraft:nether_wart_block)
B(4,13,7,minecraft:nether_wart_block)
B(5,13,7,minecraft:nether_wart_block)
B(0,13,8,minecraft:nether_wart_block)
B(1,13,8,minecraft:nether_wart_block)
B(2,13,8,minecraft:nether_wart_block)
B(3,13,8,minecraft:nether_wart_block)
B(4,13,8,minecraft:nether_wart_block)
B(5,13,8,minecraft:nether_wart_block)
B(0,13,9,minecraft:nether_wart_block)
B(1,13,9,minecraft:nether_wart_block)
B(2,13,9,minecraft:nether_wart_block)
B(3,13,9,minecraft:nether_wart_block)
B(4,13,9,minecraft:nether_wart_block)
B(5,13,9,minecraft:nether_wart_block)
B(0,13,10,minecraft:nether_wart_block)
B(1,13,10,minecraft:nether_wart_block)
B(2,13,10,minecraft:nether_wart_block)
B(3,13,10,minecraft:nether_wart_block)
B(4,13,10,minecraft:nether_wart_block)
B(5,13,10,minecraft:nether_wart_block)
B(6,13,10,minecraft:nether_wart_block)
B(0,13,11,minecraft:nether_wart_block)
B(1,13,11,minecraft:nether_wart_block)
B(2,13,11,minecraft:nether_wart_block)
B(3,13,11,minecraft:nether_wart_block)
B(4,13,11,minecraft:nether_wart_block)
B(5,13,11,minecraft:nether_wart_block)
B(6,13,11,minecraft:nether_wart_block)
B(0,13,12,minecraft:nether_wart_block)
B(1,13,12,minecraft:nether_wart_block)
B(2,13,12,minecraft:nether_wart_block)
B(3,13,12,minecraft:nether_wart_block)
B(4,13,12,minecraft:nether_wart_block)
B(5,13,12,minecraft:nether_wart_block)
B(6,13,12,minecraft:nether_wart_block)
B(7,13,12,minecraft:nether_wart_block)
B(0,13,13,minecraft:nether_wart_block)
B(1,13,13,minecraft:nether_wart_block)
B(2,13,13,minecraft:nether_wart_block)
B(3,13,13,minecraft:nether_wart_block)
B(4,13,13,minecraft:nether_wart_block)
B(5,13,13,minecraft:nether_wart_block)
B(6,13,13,minecraft:nether_wart_block)
B(7,13,13,minecraft:nether_wart_block)
B(0,13,14,minecraft:nether_wart_block)
B(1,13,14,minecraft:nether_wart_block)
B(2,13,14,minecraft:nether_wart_block)
B(3,13,14,minecraft:nether_wart_block)
B(4,13,14,minecraft:nether_wart_block)
B(5,13,14,minecraft:nether_wart_block)
B(6,13,14,minecraft:nether_wart_block)
B(7,13,14,minecraft:nether_wart_block)
B(8,13,14,minecraft:nether_wart_block)
B(9,13,14,minecraft:nether_wart_block)
B(0,13,15,minecraft:nether_wart_block)
B(1,13,15,minecraft:nether_wart_block)
B(2,13,15,minecraft:nether_wart_block)
B(3,13,15,minecraft:nether_wart_block)
B(4,13,15,minecraft:nether_wart_block)
B(5,13,15,minecraft:nether_wart_block)
B(6,13,15,minecraft:nether_wart_block)
B(7,13,15,minecraft:nether_wart_block)
B(8,13,15,minecraft:nether_wart_block)
B(9,13,15,minecraft:nether_wart_block)
B(10,13,15,minecraft:nether_wart_block)
B(0,14,0,minecraft:nether_wart_block)
B(1,14,0,minecraft:nether_wart_block)
B(2,14,0,minecraft:nether_wart_block)
B(3,14,0,minecraft:nether_wart_block)
B(4,14,0,minecraft:nether_wart_block)
B(0,14,1,minecraft:nether_wart_block)
B(1,14,1,minecraft:nether_wart_block)
B(2,14,1,minecraft:nether_wart_block)
B(3,14,1,minecraft:nether_wart_block)
B(0,14,2,minecraft:nether_wart_block)
B(1,14,2,minecraft:nether_wart_block)
B(2,14,2,minecraft:nether_wart_block)
B(3,14,2,minecraft:nether_wart_block)
B(0,14,3,minecraft:nether_wart_block)
B(1,14,3,minecraft:nether_wart_block)
B(2,14,3,minecraft:nether_wart_block)
B(3,14,3,minecraft:nether_wart_block)
B(0,14,4,minecraft:nether_wart_block)
B(1,14,4,minecraft:nether_wart_block)
B(2,14,4,minecraft:nether_wart_block)
B(3,14,4,minecraft:nether_wart_block)
B(0,14,5,minecraft:nether_wart_block)
B(1,14,5,minecraft:nether_wart_block)
B(2,14,5,minecraft:nether_wart_block)
B(3,14,5,minecraft:nether_wart_block)
B(4,14,5,minecraft:nether_wart_block)
B(0,14,6,minecraft:nether_wart_block)
B(1,14,6,minecraft:nether_wart_block)
B(2,14,6,minecraft:nether_wart_block)
B(3,14,6,minecraft:nether_wart_block)
B(4,14,6,minecraft:nether_wart_block)
B(0,14,7,minecraft:nether_wart_block)
B(1,14,7,minecraft:nether_wart_block)
B(2,14,7,minecraft:nether_wart_block)
B(3,14,7,minecraft:nether_wart_block)
B(4,14,7,minecraft:nether_wart_block)
B(5,14,7,minecraft:nether_wart_block)
B(0,14,8,minecraft:nether_wart_block)
B(1,14,8,minecraft:nether_wart_block)
B(2,14,8,minecraft:nether_wart_block)
B(3,14,8,minecraft:nether_wart_block)
B(4,14,8,minecraft:nether_wart_block)
B(5,14,8,minecraft:nether_wart_block)
B(0,14,9,minecraft:nether_wart_block)
B(1,14,9,minecraft:nether_wart_block)
B(2,14,9,minecraft:nether_wart_block)
B(3,14,9,minecraft:nether_wart_block)
B(4,14,9,minecraft:nether_wart_block)
B(5,14,9,minecraft:nether_wart_block)
B(0,14,10,minecraft:nether_wart_block)
B(1,14,10,minecraft:nether_wart_block)
B(2,14,10,minecraft:nether_wart_block)
B(3,14,10,minecraft:nether_wart_block)
B(4,14,10,minecraft:nether_wart_block)
B(5,14,10,minecraft:nether_wart_block)
B(6,14,10,minecraft:nether_wart_block)
B(0,14,11,minecraft:nether_wart_block)
B(1,14,11,minecraft:nether_wart_block)
B(2,14,11,minecraft:nether_wart_block)
B(3,14,11,minecraft:nether_wart_block)
B(4,14,11,minecraft:nether_wart_block)
B(5,14,11,minecraft:nether_wart_block)
B(6,14,11,minecraft:nether_wart_block)
B(0,14,12,minecraft:nether_wart_block)
B(1,14,12,minecraft:nether_wart_block)
B(2,14,12,minecraft:nether_wart_block)
B(3,14,12,minecraft:nether_wart_block)
B(4,14,12,minecraft:nether_wart_block)
B(5,14,12,minecraft:nether_wart_block)
B(6,14,12,minecraft:nether_wart_block)
B(7,14,12,minecraft:nether_wart_block)
B(0,14,13,minecraft:nether_wart_block)
B(1,14,13,minecraft:nether_wart_block)
B(2,14,13,minecraft:nether_wart_block)
B(3,14,13,minecraft:nether_wart_block)
B(4,14,13,minecraft:nether_wart_block)
B(5,14,13,minecraft:nether_wart_block)
B(6,14,13,minecraft:nether_wart_block)
B(7,14,13,minecraft:nether_wart_block)
B(0,14,14,minecraft:nether_wart_block)
B(1,14,14,minecraft:nether_wart_block)
B(2,14,14,minecraft:nether_wart_block)
B(3,14,14,minecraft:nether_wart_block)
B(4,14,14,minecraft:nether_wart_block)
B(5,14,14,minecraft:nether_wart_block)
B(6,14,14,minecraft:nether_wart_block)
B(7,14,14,minecraft:nether_wart_block)
B(8,14,14,minecraft:nether_wart_block)
B(9,14,14,minecraft:nether_wart_block)
B(0,14,15,minecraft:nether_wart_block)
B(1,14,15,minecraft:nether_wart_block)
B(2,14,15,minecraft:nether_wart_block)
B(3,14,15,minecraft:nether_wart_block)
B(4,14,15,minecraft:nether_wart_block)
B(5,14,15,minecraft:nether_wart_block)
B(6,14,15,minecraft:nether_wart_block)
B(7,14,15,minecraft:nether_wart_block)
B(8,14,15,minecraft:nether_wart_block)
B(9,14,15,minecraft:nether_wart_block)
B(10,14,15,minecraft:nether_wart_block)
B(0,15,0,minecraft:nether_wart_block)
B(1,15,0,minecraft:nether_wart_block)
B(2,15,0,minecraft:nether_wart_block)
B(3,15,0,minecraft:nether_wart_block)
B(4,15,0,minecraft:nether_wart_block)
B(0,15,1,minecraft:nether_wart_block)
B(1,15,1,minecraft:nether_wart_block)
B(2,15,1,minecraft:nether_wart_block)
B(3,15,1,minecraft:nether_wart_block)
B(0,15,2,minecraft:nether_wart_block)
B(1,15,2,minecraft:nether_wart_block)
B(2,15,2,minecraft:nether_wart_block)
B(3,15,2,minecraft:nether_wart_block)
B(0,15,3,minecraft:nether_wart_block)
B(1,15,3,minecraft:nether_wart_block)
B(2,15,3,minecraft:nether_wart_block)
B(3,15,3,minecraft:nether_wart_block)
B(0,15,4,minecraft:nether_wart_block)
B(1,15,4,minecraft:nether_wart_block)
B(2,15,4,minecraft:nether_wart_block)
B(3,15,4,minecraft:nether_wart_block)
B(0,15,5,minecraft:nether_wart_block)
B(1,15,5,minecraft:nether_wart_block)
B(2,15,5,minecraft:nether_wart_block)
B(3,15,5,minecraft:nether_wart_block)
B(4,15,5,minecraft:nether_wart_block)
B(0,15,6,minecraft:nether_wart_block)
B(1,15,6,minecraft:nether_wart_block)
B(2,15,6,minecraft:nether_wart_block)
B(3,15,6,minecraft:nether_wart_block)
B(4,15,6,minecraft:nether_wart_block)
B(0,15,7,minecraft:nether_wart_block)
B(1,15,7,minecraft:nether_wart_block)
B(2,15,7,minecraft:nether_wart_block)
B(3,15,7,minecraft:nether_wart_block)
B(4,15,7,minecraft:nether_wart_block)
B(5,15,7,minecraft:nether_wart_block)
B(0,15,8,minecraft:nether_wart_block)
B(1,15,8,minecraft:nether_wart_block)
B(2,15,8,minecraft:nether_wart_block)
B(3,15,8,minecraft:nether_wart_block)
B(4,15,8,minecraft:nether_wart_block)
B(5,15,8,minecraft:nether_wart_block)
B(0,15,9,minecraft:nether_wart_block)
B(1,15,9,minecraft:nether_wart_block)
B(2,15,9,minecraft:nether_wart_block)
B(3,15,9,minecraft:nether_wart_block)
B(4,15,9,minecraft:nether_wart_block)
B(5,15,9,minecraft:nether_wart_block)
B(0,15,10,minecraft:nether_wart_block)
B(1,15,10,minecraft:nether_wart_block)
B(2,15,10,minecraft:nether_wart_block)
B(3,15,10,minecraft:nether_wart_block)
B(4,15,10,minecraft:nether_wart_block)
B(5,15,10,minecraft:nether_wart_block)
B(6,15,10,minecraft:nether_wart_block)
B(0,15,11,minecraft:nether_wart_block)
B(1,15,11,minecraft:nether_wart_block)
B(2,15,11,minecraft:nether_wart_block)
B(3,15,11,minecraft:nether_wart_block)
B(4,15,11,minecraft:nether_wart_block)
B(5,15,11,minecraft:nether_wart_block)
B(6,15,11,minecraft:nether_wart_block)
B(0,15,12,minecraft:nether_wart_block)
B(1,15,12,minecraft:nether_wart_block)
B(2,15,12,minecraft:nether_wart_block)
B(3,15,12,minecraft:nether_wart_block)
B(4,15,12,minecraft:nether_wart_block)
B(5,15,12,minecraft:nether_wart_block)
B(6,15,12,minecraft:nether_wart_block)
B(0,15,13,minecraft:nether_wart_block)
B(1,15,13,minecraft:nether_wart_block)
B(2,15,13,minecraft:nether_wart_block)
B(3,15,13,minecraft:nether_wart_block)
B(4,15,13,minecraft:nether_wart_block)
B(5,15,13,minecraft:nether_wart_block)
B(6,15,13,minecraft:nether_wart_block)
B(7,15,13,minecraft:nether_wart_block)
B(0,15,14,minecraft:nether_wart_block)
B(1,15,14,minecraft:nether_wart_block)
B(2,15,14,minecraft:nether_wart_block)
B(3,15,14,minecraft:nether_wart_block)
B(4,15,14,minecraft:nether_wart_block)
B(5,15,14,minecraft:nether_wart_block)
B(6,15,14,minecraft:nether_wart_block)
B(7,15,14,minecraft:nether_wart_block)
B(8,15,14,minecraft:nether_wart_block)
B(9,15,14,minecraft:nether_wart_block)
B(0,15,15,minecraft:nether_wart_block)
B(1,15,15,minecraft:nether_wart_block)
B(2,15,15,minecraft:nether_wart_block)
B(3,15,15,minecraft:nether_wart_block)
B(4,15,15,minecraft:nether_wart_block)
B(5,15,15,minecraft:nether_wart_block)
B(6,15,15,minecraft:nether_wart_block)
B(7,15,15,minecraft:nether_wart_block)
B(8,15,15,minecraft:nether_wart_block)
B(9,15,15,minecraft:nether_wart_block)
B(10,15,15,minecraft:nether_wart_block)
B(0,16,0,minecraft:nether_wart_block)
B(1,16,0,minecraft:nether_wart_block)
B(2,16,0,minecraft:nether_wart_block)
B(3,16,0,minecraft:nether_wart_block)
B(4,16,0,minecraft:nether_wart_block)
B(0,16,1,minecraft:nether_wart_block)
B(1,16,1,minecraft:nether_wart_block)
B(2,16,1,minecraft:nether_wart_block)
B(3,16,1,minecraft:nether_wart_block)
B(0,16,2,minecraft:nether_wart_block)
B(1,16,2,minecraft:nether_wart_block)
B(2,16,2,minecraft:nether_wart_block)
B(3,16,2,minecraft:nether_wart_block)
B(0,16,3,minecraft:nether_wart_block)
B(1,16,3,minecraft:nether_wart_block)
B(2,16,3,minecraft:nether_wart_block)
B(3,16,3,minecraft:nether_wart_block)
B(0,16,4,minecraft:nether_wart_block)
B(1,16,4,minecraft:nether_wart_block)
B(2,16,4,minecraft:nether_wart_block)
B(3,16,4,minecraft:nether_wart_block)
B(0,16,5,minecraft:nether_wart_block)
B(1,16,5,minecraft:nether_wart_block)
B(2,16,5,minecraft:nether_wart_block)
B(3,16,5,minecraft:nether_wart_block)
B(4,16,5,minecraft:nether_wart_block)
B(0,16,6,minecraft:nether_wart_block)
B(1,16,6,minecraft:nether_wart_block)
B(2,16,6,minecraft:nether_wart_block)
B(3,16,6,minecraft:nether_wart_block)
B(4,16,6,minecraft:nether_wart_block)
B(0,16,7,minecraft:nether_wart_block)
B(1,16,7,minecraft:nether_wart_block)
B(2,16,7,minecraft:nether_wart_block)
B(3,16,7,minecraft:nether_wart_block)
B(4,16,7,minecraft:nether_wart_block)
B(0,16,8,minecraft:nether_wart_block)
B(1,16,8,minecraft:nether_wart_block)
B(2,16,8,minecraft:nether_wart_block)
B(3,16,8,minecraft:nether_wart_block)
B(4,16,8,minecraft:nether_wart_block)
B(5,16,8,minecraft:nether_wart_block)
B(0,16,9,minecraft:nether_wart_block)
B(1,16,9,minecraft:nether_wart_block)
B(2,16,9,minecraft:nether_wart_block)
B(3,16,9,minecraft:nether_wart_block)
B(4,16,9,minecraft:nether_wart_block)
B(5,16,9,minecraft:nether_wart_block)
B(0,16,10,minecraft:nether_wart_block)
B(1,16,10,minecraft:nether_wart_block)
B(2,16,10,minecraft:nether_wart_block)
B(3,16,10,minecraft:nether_wart_block)
B(4,16,10,minecraft:nether_wart_block)
B(5,16,10,minecraft:nether_wart_block)
B(0,16,11,minecraft:nether_wart_block)
B(1,16,11,minecraft:nether_wart_block)
B(2,16,11,minecraft:nether_wart_block)
B(3,16,11,minecraft:nether_wart_block)
B(4,16,11,minecraft:nether_wart_block)
B(5,16,11,minecraft:nether_wart_block)
B(6,16,11,minecraft:nether_wart_block)
B(0,16,12,minecraft:nether_wart_block)
B(1,16,12,minecraft:nether_wart_block)
B(2,16,12,minecraft:nether_wart_block)
B(3,16,12,minecraft:nether_wart_block)
B(4,16,12,minecraft:nether_wart_block)
B(5,16,12,minecraft:nether_wart_block)
B(6,16,12,minecraft:nether_wart_block)
B(0,16,13,minecraft:nether_wart_block)
B(1,16,13,minecraft:nether_wart_block)
B(2,16,13,minecraft:nether_wart_block)
B(3,16,13,minecraft:nether_wart_block)
B(4,16,13,minecraft:nether_wart_block)
B(5,16,13,minecraft:nether_wart_block)
B(6,16,13,minecraft:nether_wart_block)
B(7,16,13,minecraft:nether_wart_block)
B(0,16,14,minecraft:nether_wart_block)
B(1,16,14,minecraft:nether_wart_block)
B(2,16,14,minecraft:nether_wart_block)
B(3,16,14,minecraft:nether_wart_block)
B(4,16,14,minecraft:nether_wart_block)
B(5,16,14,minecraft:nether_wart_block)
B(6,16,14,minecraft:nether_wart_block)
B(7,16,14,minecraft:nether_wart_block)
B(8,16,14,minecraft:nether_wart_block)
B(0,16,15,minecraft:nether_wart_block)
B(1,16,15,minecraft:nether_wart_block)
B(2,16,15,minecraft:nether_wart_block)
B(3,16,15,minecraft:nether_wart_block)
B(4,16,15,minecraft:nether_wart_block)
B(5,16,15,minecraft:nether_wart_block)
B(6,16,15,minecraft:nether_wart_block)
B(7,16,15,minecraft:nether_wart_block)
B(8,16,15,minecraft:nether_wart_block)
B(9,16,15,minecraft:nether_wart_block)
B(10,16,15,minecraft:nether_wart_block)
B(0,17,0,minecraft:nether_wart_block)
B(1,17,0,minecraft:nether_wart_block)
B(2,17,0,minecraft:nether_wart_block)
B(3,17,0,minecraft:nether_wart_block)
B(4,17,0,minecraft:nether_wart_block)
B(0,17,1,minecraft:nether_wart_block)
B(1,17,1,minecraft:nether_wart_block)
B(2,17,1,minecraft:nether_wart_block)
B(3,17,1,minecraft:nether_wart_block)
B(0,17,2,minecraft:nether_wart_block)
B(1,17,2,minecraft:nether_wart_block)
B(2,17,2,minecraft:nether_wart_block)
B(3,17,2,minecraft:nether_wart_block)
B(0,17,3,minecraft:nether_wart_block)
B(1,17,3,minecraft:nether_wart_block)
B(2,17,3,minecraft:nether_wart_block)
B(3,17,3,minecraft:nether_wart_block)
B(0,17,4,minecraft:nether_wart_block)
B(1,17,4,minecraft:nether_wart_block)
B(2,17,4,minecraft:nether_wart_block)
B(3,17,4,minecraft:nether_wart_block)
B(0,17,5,minecraft:nether_wart_block)
B(1,17,5,minecraft:nether_wart_block)
B(2,17,5,minecraft:nether_wart_block)
B(3,17,5,minecraft:nether_wart_block)
B(4,17,5,minecraft:nether_wart_block)
B(0,17,6,minecraft:nether_wart_block)
B(1,17,6,minecraft:nether_wart_block)
B(2,17,6,minecraft:nether_wart_block)
B(3,17,6,minecraft:nether_wart_block)
B(4,17,6,minecraft:nether_wart_block)
B(0,17,7,minecraft:nether_wart_block)
B(1,17,7,minecraft:nether_wart_block)
B(2,17,7,minecraft:nether_wart_block)
B(3,17,7,minecraft:nether_wart_block)
B(4,17,7,minecraft:nether_wart_block)
B(0,17,8,minecraft:nether_wart_block)
B(1,17,8,minecraft:nether_wart_block)
B(2,17,8,minecraft:nether_wart_block)
B(3,17,8,minecraft:nether_wart_block)
B(4,17,8,minecraft:nether_wart_block)
B(5,17,8,minecraft:nether_wart_block)
B(0,17,9,minecraft:nether_wart_block)
B(1,17,9,minecraft:nether_wart_block)
B(2,17,9,minecraft:nether_wart_block)
B(3,17,9,minecraft:nether_wart_block)
B(4,17,9,minecraft:nether_wart_block)
B(5,17,9,minecraft:nether_wart_block)
B(0,17,10,minecraft:nether_wart_block)
B(1,17,10,minecraft:nether_wart_block)
B(2,17,10,minecraft:nether_wart_block)
B(3,17,10,minecraft:nether_wart_block)
B(4,17,10,minecraft:nether_wart_block)
B(5,17,10,minecraft:nether_wart_block)
B(0,17,11,minecraft:nether_wart_block)
B(1,17,11,minecraft:nether_wart_block)
B(2,17,11,minecraft:nether_wart_block)
B(3,17,11,minecraft:nether_wart_block)
B(4,17,11,minecraft:nether_wart_block)
B(5,17,11,minecraft:nether_wart_block)
B(6,17,11,minecraft:nether_wart_block)
B(0,17,12,minecraft:nether_wart_block)
B(1,17,12,minecraft:nether_wart_block)
B(2,17,12,minecraft:nether_wart_block)
B(3,17,12,minecraft:nether_wart_block)
B(4,17,12,minecraft:nether_wart_block)
B(5,17,12,minecraft:nether_wart_block)
B(6,17,12,minecraft:nether_wart_block)
B(0,17,13,minecraft:nether_wart_block)
B(1,17,13,minecraft:nether_wart_block)
B(2,17,13,minecraft:nether_wart_block)
B(3,17,13,minecraft:nether_wart_block)
B(4,17,13,minecraft:nether_wart_block)
B(5,17,13,minecraft:nether_wart_block)
B(6,17,13,minecraft:nether_wart_block)
B(7,17,13,minecraft:nether_wart_block)
B(0,17,14,minecraft:nether_wart_block)
B(1,17,14,minecraft:nether_wart_block)
B(2,17,14,minecraft:nether_wart_block)
B(3,17,14,minecraft:nether_wart_block)
B(4,17,14,minecraft:nether_wart_block)
B(5,17,14,minecraft:nether_wart_block)
B(6,17,14,minecraft:nether_wart_block)
B(7,17,14,minecraft:nether_wart_block)
B(8,17,14,minecraft:nether_wart_block)
B(0,17,15,minecraft:nether_wart_block)
B(1,17,15,minecraft:nether_wart_block)
B(2,17,15,minecraft:nether_wart_block)
B(3,17,15,minecraft:nether_wart_block)
B(4,17,15,minecraft:nether_wart_block)
B(5,17,15,minecraft:nether_wart_block)
B(6,17,15,minecraft:nether_wart_block)
B(7,17,15,minecraft:nether_wart_block)
B(8,17,15,minecraft:nether_wart_block)
B(9,17,15,minecraft:nether_wart_block)
B(0,18,0,minecraft:nether_wart_block)
B(1,18,0,minecraft:nether_wart_block)
B(2,18,0,minecraft:nether_wart_block)
B(3,18,0,minecraft:nether_wart_block)
B(4,18,0,minecraft:nether_wart_block)
B(0,18,1,minecraft:nether_wart_block)
B(1,18,1,minecraft:nether_wart_block)
B(2,18,1,minecraft:nether_wart_block)
B(3,18,1,minecraft:nether_wart_block)
B(0,18,2,minecraft:nether_wart_block)
B(1,18,2,minecraft:nether_wart_block)
B(2,18,2,minecraft:nether_wart_block)
B(3,18,2,minecraft:nether_wart_block)
B(0,18,3,minecraft:nether_wart_block)
B(1,18,3,minecraft:nether_wart_block)
B(2,18,3,minecraft:nether_wart_block)
B(3,18,3,minecraft:nether_wart_block)
B(0,18,4,minecraft:nether_wart_block)
B(1,18,4,minecraft:nether_wart_block)
B(2,18,4,minecraft:nether_wart_block)
B(3,18,4,minecraft:nether_wart_block)
B(0,18,5,minecraft:nether_wart_block)
B(1,18,5,minecraft:nether_wart_block)
B(2,18,5,minecraft:nether_wart_block)
B(3,18,5,minecraft:nether_wart_block)
B(4,18,5,minecraft:nether_wart_block)
B(0,18,6,minecraft:nether_wart_block)
B(1,18,6,minecraft:nether_wart_block)
B(2,18,6,minecraft:nether_wart_block)
B(3,18,6,minecraft:nether_wart_block)
B(4,18,6,minecraft:nether_wart_block)
B(0,18,7,minecraft:nether_wart_block)
B(1,18,7,minecraft:nether_wart_block)
B(2,18,7,minecraft:nether_wart_block)
B(3,18,7,minecraft:nether_wart_block)
B(4,18,7,minecraft:nether_wart_block)
B(0,18,8,minecraft:nether_wart_block)
B(1,18,8,minecraft:nether_wart_block)
B(2,18,8,minecraft:nether_wart_block)
B(3,18,8,minecraft:nether_wart_block)
B(4,18,8,minecraft:nether_wart_block)
B(5,18,8,minecraft:nether_wart_block)
B(0,18,9,minecraft:nether_wart_block)
B(1,18,9,minecraft:nether_wart_block)
B(2,18,9,minecraft:nether_wart_block)
B(3,18,9,minecraft:nether_wart_block)
B(4,18,9,minecraft:nether_wart_block)
B(5,18,9,minecraft:nether_wart_block)
B(0,18,10,minecraft:nether_wart_block)
B(1,18,10,minecraft:nether_wart_block)
B(2,18,10,minecraft:nether_wart_block)
B(3,18,10,minecraft:nether_wart_block)
B(4,18,10,minecraft:nether_wart_block)
B(5,18,10,minecraft:nether_wart_block)
B(0,18,11,minecraft:nether_wart_block)
B(1,18,11,minecraft:nether_wart_block)
B(2,18,11,minecraft:nether_wart_block)
B(3,18,11,minecraft:nether_wart_block)
B(4,18,11,minecraft:nether_wart_block)
B(5,18,11,minecraft:nether_wart_block)
B(6,18,11,minecraft:nether_wart_block)
B(0,18,12,minecraft:nether_wart_block)
B(1,18,12,minecraft:nether_wart_block)
B(2,18,12,minecraft:nether_wart_block)
B(3,18,12,minecraft:nether_wart_block)
B(4,18,12,minecraft:nether_wart_block)
B(5,18,12,minecraft:nether_wart_block)
B(6,18,12,minecraft:nether_wart_block)
B(0,18,13,minecraft:nether_wart_block)
B(1,18,13,minecraft:nether_wart_block)
B(2,18,13,minecraft:nether_wart_block)
B(3,18,13,minecraft:nether_wart_block)
B(4,18,13,minecraft:nether_wart_block)
B(5,18,13,minecraft:nether_wart_block)
B(6,18,13,minecraft:nether_wart_block)
B(7,18,13,minecraft:nether_wart_block)
B(0,18,14,minecraft:nether_wart_block)
B(1,18,14,minecraft:nether_wart_block)
B(2,18,14,minecraft:nether_wart_block)
B(3,18,14,minecraft:nether_wart_block)
B(4,18,14,minecraft:nether_wart_block)
B(5,18,14,minecraft:nether_wart_block)
B(6,18,14,minecraft:nether_wart_block)
B(7,18,14,minecraft:nether_wart_block)
B(8,18,14,minecraft:nether_wart_block)
B(0,18,15,minecraft:nether_wart_block)
B(1,18,15,minecraft:nether_wart_block)
B(2,18,15,minecraft:nether_wart_block)
B(3,18,15,minecraft:nether_wart_block)
B(4,18,15,minecraft:nether_wart_block)
B(5,18,15,minecraft:nether_wart_block)
B(6,18,15,minecraft:nether_wart_block)
B(7,18,15,minecraft:nether_wart_block)
B(8,18,15,minecraft:nether_wart_block)
B(9,18,15,minecraft:nether_wart_block)
B(0,19,0,minecraft:nether_wart_block)
B(1,19,0,minecraft:nether_wart_block)
B(2,19,0,minecraft:nether_wart_block)
B(3,19,0,minecraft:nether_wart_block)
B(4,19,0,minecraft:nether_wart_block)
B(0,19,1,minecraft:nether_wart_block)
B(1,19,1,minecraft:nether_wart_block)
B(2,19,1,minecraft:nether_wart_block)
B(3,19,1,minecraft:nether_wart_block)
B(0,19,2,minecraft:nether_wart_block)
B(1,19,2,minecraft:nether_wart_block)
B(2,19,2,minecraft:nether_wart_block)
B(3,19,2,minecraft:nether_wart_block)
B(0,19,3,minecraft:nether_wart_block)
B(1,19,3,minecraft:nether_wart_block)
B(2,19,3,minecraft:nether_wart_block)
B(3,19,3,minecraft:nether_wart_block)
B(0,19,4,minecraft:nether_wart_block)
B(1,19,4,minecraft:nether_wart_block)
B(2,19,4,minecraft:nether_wart_block)
B(3,19,4,minecraft:nether_wart_block)
B(0,19,5,minecraft:nether_wart_block)
B(1,19,5,minecraft:nether_wart_block)
B(2,19,5,minecraft:nether_wart_block)
B(3,19,5,minecraft:nether_wart_block)
B(4,19,5,minecraft:nether_wart_block)
B(0,19,6,minecraft:nether_wart_block)
B(1,19,6,minecraft:nether_wart_block)
B(2,19,6,minecraft:nether_wart_block)
B(3,19,6,minecraft:nether_wart_block)
B(4,19,6,minecraft:nether_wart_block)
B(0,19,7,minecraft:nether_wart_block)
B(1,19,7,minecraft:nether_wart_block)
B(2,19,7,minecraft:nether_wart_block)
B(3,19,7,minecraft:nether_wart_block)
B(4,19,7,minecraft:nether_wart_block)
B(0,19,8,minecraft:nether_wart_block)
B(1,19,8,minecraft:nether_wart_block)
B(2,19,8,minecraft:nether_wart_block)
B(3,19,8,minecraft:nether_wart_block)
B(4,19,8,minecraft:nether_wart_block)
B(5,19,8,minecraft:nether_wart_block)
B(0,19,9,minecraft:nether_wart_block)
B(1,19,9,minecraft:nether_wart_block)
B(2,19,9,minecraft:nether_wart_block)
B(3,19,9,minecraft:nether_wart_block)
B(4,19,9,minecraft:nether_wart_block)
B(5,19,9,minecraft:nether_wart_block)
B(0,19,10,minecraft:nether_wart_block)
B(1,19,10,minecraft:nether_wart_block)
B(2,19,10,minecraft:nether_wart_block)
B(3,19,10,minecraft:nether_wart_block)
B(4,19,10,minecraft:nether_wart_block)
B(5,19,10,minecraft:nether_wart_block)
B(0,19,11,minecraft:nether_wart_block)
B(1,19,11,minecraft:nether_wart_block)
B(2,19,11,minecraft:nether_wart_block)
B(3,19,11,minecraft:nether_wart_block)
B(4,19,11,minecraft:nether_wart_block)
B(5,19,11,minecraft:nether_wart_block)
B(6,19,11,minecraft:nether_wart_block)
B(0,19,12,minecraft:nether_wart_block)
B(1,19,12,minecraft:nether_wart_block)
B(2,19,12,minecraft:nether_wart_block)
B(3,19,12,minecraft:nether_wart_block)
B(4,19,12,minecraft:nether_wart_block)
B(5,19,12,minecraft:nether_wart_block)
B(6,19,12,minecraft:nether_wart_block)
B(0,19,13,minecraft:nether_wart_block)
B(1,19,13,minecraft:nether_wart_block)
B(2,19,13,minecraft:nether_wart_block)
B(3,19,13,minecraft:nether_wart_block)
B(4,19,13,minecraft:nether_wart_block)
B(5,19,13,minecraft:nether_wart_block)
B(6,19,13,minecraft:nether_wart_block)
B(7,19,13,minecraft:nether_wart_block)
B(0,19,14,minecraft:nether_wart_block)
B(1,19,14,minecraft:nether_wart_block)
B(2,19,14,minecraft:nether_wart_block)
B(3,19,14,minecraft:nether_wart_block)
B(4,19,14,minecraft:nether_wart_block)
B(5,19,14,minecraft:nether_wart_block)
B(6,19,14,minecraft:nether_wart_block)
B(7,19,14,minecraft:nether_wart_block)
B(8,19,14,minecraft:nether_wart_block)
B(0,19,15,minecraft:nether_wart_block)
B(1,19,15,minecraft:nether_wart_block)
B(2,19,15,minecraft:nether_wart_block)
B(3,19,15,minecraft:nether_wart_block)
B(4,19,15,minecraft:nether_wart_block)
B(5,19,15,minecraft:nether_wart_block)
B(6,19,15,minecraft:nether_wart_block)
B(7,19,15,minecraft:nether_wart_block)
B(8,19,15,minecraft:nether_wart_block)
B(9,19,15,minecraft:nether_wart_block)
B(0,20,0,minecraft:nether_wart_block)
B(1,20,0,minecraft:nether_wart_block)
B(2,20,0,minecraft:nether_wart_block)
B(3,20,0,minecraft:nether_wart_block)
B(4,20,0,minecraft:nether_wart_block)
B(0,20,1,minecraft:nether_wart_block)
B(1,20,1,minecraft:nether_wart_block)
B(2,20,1,minecraft:nether_wart_block)
B(3,20,1,minecraft:nether_wart_block)
B(0,20,2,minecraft:nether_wart_block)
B(1,20,2,minecraft:nether_wart_block)
B(2,20,2,minecraft:nether_wart_block)
B(3,20,2,minecraft:nether_wart_block)
B(0,20,3,minecraft:nether_wart_block)
B(1,20,3,minecraft:nether_wart_block)
B(2,20,3,minecraft:nether_wart_block)
B(3,20,3,minecraft:nether_wart_block)
B(0,20,4,minecraft:nether_wart_block)
B(1,20,4,minecraft:nether_wart_block)
B(2,20,4,minecraft:nether_wart_block)
B(3,20,4,minecraft:nether_wart_block)
B(0,20,5,minecraft:nether_wart_block)
B(1,20,5,minecraft:nether_wart_block)
B(2,20,5,minecraft:nether_wart_block)
B(3,20,5,minecraft:nether_wart_block)
B(4,20,5,minecraft:nether_wart_block)
B(0,20,6,minecraft:nether_wart_block)
B(1,20,6,minecraft:nether_wart_block)
B(2,20,6,minecraft:nether_wart_block)
B(3,20,6,minecraft:nether_wart_block)
B(4,20,6,minecraft:nether_wart_block)
B(0,20,7,minecraft:nether_wart_block)
B(1,20,7,minecraft:nether_wart_block)
B(2,20,7,minecraft:nether_wart_block)
B(3,20,7,minecraft:nether_wart_block)
B(4,20,7,minecraft:nether_wart_block)
B(0,20,8,minecraft:nether_wart_block)
B(1,20,8,minecraft:nether_wart_block)
B(2,20,8,minecraft:nether_wart_block)
B(3,20,8,minecraft:nether_wart_block)
B(4,20,8,minecraft:nether_wart_block)
B(5,20,8,minecraft:nether_wart_block)
B(0,20,9,minecraft:nether_wart_block)
B(1,20,9,minecraft:nether_wart_block)
B(2,20,9,minecraft:nether_wart_block)
B(3,20,9,minecraft:nether_wart_block)
B(4,20,9,minecraft:nether_wart_block)
B(5,20,9,minecraft:nether_wart_block)
B(0,20,10,minecraft:nether_wart_block)
B(1,20,10,minecraft:nether_wart_block)
B(2,20,10,minecraft:nether_wart_block)
B(3,20,10,minecraft:nether_wart_block)
B(4,20,10,minecraft:nether_wart_block)
B(5,20,10,minecraft:nether_wart_block)
B(0,20,11,minecraft:nether_wart_block)
B(1,20,11,minecraft:nether_wart_block)
B(2,20,11,minecraft:nether_wart_block)
B(3,20,11,minecraft:nether_wart_block)
B(4,20,11,minecraft:nether_wart_block)
B(5,20,11,minecraft:nether_wart_block)
B(6,20,11,minecraft:nether_wart_block)
B(0,20,12,minecraft:nether_wart_block)
B(1,20,12,minecraft:nether_wart_block)
B(2,20,12,minecraft:nether_wart_block)
B(3,20,12,minecraft:nether_wart_block)
B(4,20,12,minecraft:nether_wart_block)
B(5,20,12,minecraft:nether_wart_block)
B(6,20,12,minecraft:nether_wart_block)
B(0,20,13,minecraft:nether_wart_block)
B(1,20,13,minecraft:nether_wart_block)
B(2,20,13,minecraft:nether_wart_block)
B(3,20,13,minecraft:nether_wart_block)
B(4,20,13,minecraft:nether_wart_block)
B(5,20,13,minecraft:nether_wart_block)
B(6,20,13,minecraft:nether_wart_block)
B(0,20,14,minecraft:nether_wart_block)
B(1,20,14,minecraft:nether_wart_block)
B(2,20,14,minecraft:nether_wart_block)
B(3,20,14,minecraft:nether_wart_block)
B(4,20,14,minecraft:nether_wart_block)
B(5,20,14,minecraft:nether_wart_block)
B(6,20,14,minecraft:nether_wart_block)
B(7,20,14,minecraft:nether_wart_block)
B(0,20,15,minecraft:nether_wart_block)
B(1,20,15,minecraft:nether_wart_block)
B(2,20,15,minecraft:nether_wart_block)
B(3,20,15,minecraft:nether_wart_block)
B(4,20,15,minecraft:nether_wart_block)
B(5,20,15,minecraft:nether_wart_block)
B(6,20,15,minecraft:nether_wart_block)
B(7,20,15,minecraft:nether_wart_block)
B(8,20,15,minecraft:nether_wart_block)
B(9,20,15,minecraft:nether_wart_block)
B(0,21,0,minecraft:nether_wart_block)
B(1,21,0,minecraft:nether_wart_block)
B(2,21,0,minecraft:nether_wart_block)
B(3,21,0,minecraft:nether_wart_block)
B(4,21,0,minecraft:nether_wart_block)
B(0,21,1,minecraft:nether_wart_block)
B(1,21,1,minecraft:nether_wart_block)
B(2,21,1,minecraft:nether_wart_block)
B(3,21,1,minecraft:nether_wart_block)
B(0,21,2,minecraft:nether_wart_block)
B(1,21,2,minecraft:nether_wart_block)
B(2,21,2,minecraft:nether_wart_block)
B(3,21,2,minecraft:nether_wart_block)
B(0,21,3,minecraft:nether_wart_block)
B(1,21,3,minecraft:nether_wart_block)
B(2,21,3,minecraft:nether_wart_block)
B(3,21,3,minecraft:nether_wart_block)
B(0,21,4,minecraft:nether_wart_block)
B(1,21,4,minecraft:nether_wart_block)
B(2,21,4,minecraft:nether_wart_block)
B(3,21,4,minecraft:nether_wart_block)
B(0,21,5,minecraft:nether_wart_block)
B(1,21,5,minecraft:nether_wart_block)
B(2,21,5,minecraft:nether_wart_block)
B(3,21,5,minecraft:nether_wart_block)
B(4,21,5,minecraft:nether_wart_block)
B(0,21,6,minecraft:nether_wart_block)
B(1,21,6,minecraft:nether_wart_block)
B(2,21,6,minecraft:nether_wart_block)
B(3,21,6,minecraft:nether_wart_block)
B(4,21,6,minecraft:nether_wart_block)
B(0,21,7,minecraft:nether_wart_block)
B(1,21,7,minecraft:nether_wart_block)
B(2,21,7,minecraft:nether_wart_block)
B(3,21,7,minecraft:nether_wart_block)
B(4,21,7,minecraft:nether_wart_block)
B(0,21,8,minecraft:nether_wart_block)
B(1,21,8,minecraft:nether_wart_block)
B(2,21,8,minecraft:nether_wart_block)
B(3,21,8,minecraft:nether_wart_block)
B(4,21,8,minecraft:nether_wart_block)
B(5,21,8,minecraft:nether_wart_block)
B(0,21,9,minecraft:nether_wart_block)
B(1,21,9,minecraft:nether_wart_block)
B(2,21,9,minecraft:nether_wart_block)
B(3,21,9,minecraft:nether_wart_block)
B(4,21,9,minecraft:nether_wart_block)
B(5,21,9,minecraft:nether_wart_block)
B(0,21,10,minecraft:nether_wart_block)
B(1,21,10,minecraft:nether_wart_block)
B(2,21,10,minecraft:nether_wart_block)
B(3,21,10,minecraft:nether_wart_block)
B(4,21,10,minecraft:nether_wart_block)
B(5,21,10,minecraft:nether_wart_block)
B(0,21,11,minecraft:nether_wart_block)
B(1,21,11,minecraft:nether_wart_block)
B(2,21,11,minecraft:nether_wart_block)
B(3,21,11,minecraft:nether_wart_block)
B(4,21,11,minecraft:nether_wart_block)
B(5,21,11,minecraft:nether_wart_block)
B(6,21,11,minecraft:nether_wart_block)
B(0,21,12,minecraft:nether_wart_block)
B(1,21,12,minecraft:nether_wart_block)
B(2,21,12,minecraft:nether_wart_block)
B(3,21,12,minecraft:nether_wart_block)
B(4,21,12,minecraft:nether_wart_block)
B(5,21,12,minecraft:nether_wart_block)
B(6,21,12,minecraft:nether_wart_block)
B(0,21,13,minecraft:nether_wart_block)
B(1,21,13,minecraft:nether_wart_block)
B(2,21,13,minecraft:nether_wart_block)
B(3,21,13,minecraft:nether_wart_block)
B(4,21,13,minecraft:nether_wart_block)
B(5,21,13,minecraft:nether_wart_block)
B(6,21,13,minecraft:nether_wart_block)
B(0,21,14,minecraft:nether_wart_block)
B(1,21,14,minecraft:nether_wart_block)
B(2,21,14,minecraft:nether_wart_block)
B(3,21,14,minecraft:nether_wart_block)
B(4,21,14,minecraft:nether_wart_block)
B(5,21,14,minecraft:nether_wart_block)
B(6,21,14,minecraft:nether_wart_block)
B(7,21,14,minecraft:nether_wart_block)
B(0,21,15,minecraft:nether_wart_block)
B(1,21,15,minecraft:nether_wart_block)
B(2,21,15,minecraft:nether_wart_block)
B(3,21,15,minecraft:nether_wart_block)
B(4,21,15,minecraft:nether_wart_block)
B(5,21,15,minecraft:nether_wart_block)
B(6,21,15,minecraft:nether_wart_block)
B(7,21,15,minecraft:nether_wart_block)
B(8,21,15,minecraft:nether_wart_block)
B(0,22,0,minecraft:nether_wart_block)
B(1,22,0,minecraft:nether_wart_block)
B(2,22,0,minecraft:nether_wart_block)
B(3,22,0,minecraft:nether_wart_block)
B(4,22,0,minecraft:nether_wart_block)
B(0,22,1,minecraft:nether_wart_block)
B(1,22,1,minecraft:nether_wart_block)
B(2,22,1,minecraft:nether_wart_block)
B(3,22,1,minecraft:nether_wart_block)
B(0,22,2,minecraft:nether_wart_block)
B(1,22,2,minecraft:nether_wart_block)
B(2,22,2,minecraft:nether_wart_block)
B(3,22,2,minecraft:nether_wart_block)
B(0,22,3,minecraft:nether_wart_block)
B(1,22,3,minecraft:nether_wart_block)
B(2,22,3,minecraft:nether_wart_block)
B(3,22,3,minecraft:nether_wart_block)
B(0,22,4,minecraft:nether_wart_block)
B(1,22,4,minecraft:nether_wart_block)
B(2,22,4,minecraft:nether_wart_block)
B(3,22,4,minecraft:nether_wart_block)
B(0,22,5,minecraft:nether_wart_block)
B(1,22,5,minecraft:nether_wart_block)
B(2,22,5,minecraft:nether_wart_block)
B(3,22,5,minecraft:nether_wart_block)
B(4,22,5,minecraft:nether_wart_block)
B(0,22,6,minecraft:nether_wart_block)
B(1,22,6,minecraft:nether_wart_block)
B(2,22,6,minecraft:nether_wart_block)
B(3,22,6,minecraft:nether_wart_block)
B(4,22,6,minecraft:nether_wart_block)
B(0,22,7,minecraft:nether_wart_block)
B(1,22,7,minecraft:nether_wart_block)
B(2,22,7,minecraft:nether_wart_block)
B(3,22,7,minecraft:nether_wart_block)
B(4,22,7,minecraft:nether_wart_block)
B(0,22,8,minecraft:nether_wart_block)
B(1,22,8,minecraft:nether_wart_block)
B(2,22,8,minecraft:nether_wart_block)
B(3,22,8,minecraft:nether_wart_block)
B(4,22,8,minecraft:nether_wart_block)
B(5,22,8,minecraft:nether_wart_block)
B(0,22,9,minecraft:nether_wart_block)
B(1,22,9,minecraft:nether_wart_block)
B(2,22,9,minecraft:nether_wart_block)
B(3,22,9,minecraft:nether_wart_block)
B(4,22,9,minecraft:nether_wart_block)
B(5,22,9,minecraft:nether_wart_block)
B(0,22,10,minecraft:nether_wart_block)
B(1,22,10,minecraft:nether_wart_block)
B(2,22,10,minecraft:nether_wart_block)
B(3,22,10,minecraft:nether_wart_block)
B(4,22,10,minecraft:nether_wart_block)
B(5,22,10,minecraft:nether_wart_block)
B(0,22,11,minecraft:nether_wart_block)
B(1,22,11,minecraft:nether_wart_block)
B(2,22,11,minecraft:nether_wart_block)
B(3,22,11,minecraft:nether_wart_block)
B(4,22,11,minecraft:nether_wart_block)
B(5,22,11,minecraft:nether_wart_block)
B(6,22,11,minecraft:nether_wart_block)
B(0,22,12,minecraft:nether_wart_block)
B(1,22,12,minecraft:nether_wart_block)
B(2,22,12,minecraft:nether_wart_block)
B(3,22,12,minecraft:nether_wart_block)
B(4,22,12,minecraft:nether_wart_block)
B(5,22,12,minecraft:nether_wart_block)
B(6,22,12,minecraft:nether_wart_block)
B(0,22,13,minecraft:nether_wart_block)
B(1,22,13,minecraft:nether_wart_block)
B(2,22,13,minecraft:nether_wart_block)
B(3,22,13,minecraft:nether_wart_block)
B(4,22,13,minecraft:nether_wart_block)
B(5,22,13,minecraft:nether_wart_block)
B(6,22,13,minecraft:nether_wart_block)
B(0,22,14,minecraft:nether_wart_block)
B(1,22,14,minecraft:nether_wart_block)
B(2,22,14,minecraft:nether_wart_block)
B(3,22,14,minecraft:nether_wart_block)
B(4,22,14,minecraft:nether_wart_block)
B(5,22,14,minecraft:nether_wart_block)
B(6,22,14,minecraft:nether_wart_block)
B(7,22,14,minecraft:nether_wart_block)
B(0,22,15,minecraft:nether_wart_block)
B(1,22,15,minecraft:nether_wart_block)
B(2,22,15,minecraft:nether_wart_block)
B(3,22,15,minecraft:nether_wart_block)
B(4,22,15,minecraft:nether_wart_block)
B(5,22,15,minecraft:nether_wart_block)
B(6,22,15,minecraft:nether_wart_block)
B(7,22,15,minecraft:nether_wart_block)
B(8,22,15,minecraft:nether_wart_block)
B(0,23,0,minecraft:nether_wart_block)
B(1,23,0,minecraft:nether_wart_block)
B(2,23,0,minecraft:nether_wart_block)
B(3,23,0,minecraft:nether_wart_block)
B(0,23,1,minecraft:nether_wart_block)
B(1,23,1,minecraft:nether_wart_block)
B(2,23,1,minecraft:nether_wart_block)
B(3,23,1,minecraft:nether_wart_block)
B(0,23,2,minecraft:nether_wart_block)
B(1,23,2,minecraft:nether_wart_block)
B(2,23,2,minecraft:nether_wart_block)
B(3,23,2,minecraft:nether_wart_block)
B(0,23,3,minecraft:nether_wart_block)
B(1,23,3,minecraft:nether_wart_block)
B(2,23,3,minecraft:nether_wart_block)
B(3,23,3,minecraft:nether_wart_block)
B(0,23,4,minecraft:nether_wart_block)
B(1,23,4,minecraft:nether_wart_block)
B(2,23,4,minecraft:nether_wart_block)
B(3,23,4,minecraft:nether_wart_block)
B(0,23,5,minecraft:nether_wart_block)
B(1,23,5,minecraft:nether_wart_block)
B(2,23,5,minecraft:nether_wart_block)
B(3,23,5,minecraft:nether_wart_block)
B(4,23,5,minecraft:nether_wart_block)
B(0,23,6,minecraft:nether_wart_block)
B(1,23,6,minecraft:nether_wart_block)
B(2,23,6,minecraft:nether_wart_block)
B(3,23,6,minecraft:nether_wart_block)
B(4,23,6,minecraft:nether_wart_block)
B(0,23,7,minecraft:nether_wart_block)
B(1,23,7,minecraft:nether_wart_block)
B(2,23,7,minecraft:nether_wart_block)
B(3,23,7,minecraft:nether_wart_block)
B(4,23,7,minecraft:nether_wart_block)
B(0,23,8,minecraft:nether_wart_block)
B(1,23,8,minecraft:nether_wart_block)
B(2,23,8,minecraft:nether_wart_block)
B(3,23,8,minecraft:nether_wart_block)
B(4,23,8,minecraft:nether_wart_block)
B(5,23,8,minecraft:nether_wart_block)
B(0,23,9,minecraft:nether_wart_block)
B(1,23,9,minecraft:nether_wart_block)
B(2,23,9,minecraft:nether_wart_block)
B(3,23,9,minecraft:nether_wart_block)
B(4,23,9,minecraft:nether_wart_block)
B(5,23,9,minecraft:nether_wart_block)
B(0,23,10,minecraft:nether_wart_block)
B(1,23,10,minecraft:nether_wart_block)
B(2,23,10,minecraft:nether_wart_block)
B(3,23,10,minecraft:nether_wart_block)
B(4,23,10,minecraft:nether_wart_block)
B(5,23,10,minecraft:nether_wart_block)
B(0,23,11,minecraft:nether_wart_block)
B(1,23,11,minecraft:nether_wart_block)
B(2,23,11,minecraft:nether_wart_block)
B(3,23,11,minecraft:nether_wart_block)
B(4,23,11,minecraft:nether_wart_block)
B(5,23,11,minecraft:nether_wart_block)
B(0,23,12,minecraft:nether_wart_block)
B(1,23,12,minecraft:nether_wart_block)
B(2,23,12,minecraft:nether_wart_block)
B(3,23,12,minecraft:nether_wart_block)
B(4,23,12,minecraft:nether_wart_block)
B(5,23,12,minecraft:nether_wart_block)
B(6,23,12,minecraft:nether_wart_block)
B(0,23,13,minecraft:nether_wart_block)
B(1,23,13,minecraft:nether_wart_block)
B(2,23,13,minecraft:nether_wart_block)
B(3,23,13,minecraft:nether_wart_block)
B(4,23,13,minecraft:nether_wart_block)
B(5,23,13,minecraft:nether_wart_block)
B(6,23,13,minecraft:nether_wart_block)
B(0,23,14,minecraft:nether_wart_block)
B(1,23,14,minecraft:nether_wart_block)
B(2,23,14,minecraft:nether_wart_block)
B(3,23,14,minecraft:nether_wart_block)
B(4,23,14,minecraft:nether_wart_block)
B(5,23,14,minecraft:nether_wart_block)
B(6,23,14,minecraft:nether_wart_block)
B(7,23,14,minecraft:nether_wart_block)
B(0,23,15,minecraft:nether_wart_block)
B(1,23,15,minecraft:nether_wart_block)
B(2,23,15,minecraft:nether_wart_block)
B(3,23,15,minecraft:nether_wart_block)
B(4,23,15,minecraft:nether_wart_block)
B(5,23,15,minecraft:nether_wart_block)
B(6,23,15,minecraft:nether_wart_block)
B(7,23,15,minecraft:nether_wart_block)
B(8,23,15,minecraft:nether_wart_block)
B(0,24,0,minecraft:nether_wart_block)
B(1,24,0,minecraft:nether_wart_block)
B(2,24,0,minecraft:nether_wart_block)
B(3,24,0,minecraft:nether_wart_block)
B(0,24,1,minecraft:nether_wart_block)
B(1,24,1,minecraft:nether_wart_block)
B(2,24,1,minecraft:nether_wart_block)
B(3,24,1,minecraft:nether_wart_block)
B(0,24,2,minecraft:nether_wart_block)
B(1,24,2,minecraft:nether_wart_block)
B(2,24,2,minecraft:nether_wart_block)
B(3,24,2,minecraft:nether_wart_block)
B(0,24,3,minecraft:nether_wart_block)
B(1,24,3,minecraft:nether_wart_block)
B(2,24,3,minecraft:nether_wart_block)
B(3,24,3,minecraft:nether_wart_block)
B(0,24,4,minecraft:nether_wart_block)
B(1,24,4,minecraft:nether_wart_block)
B(2,24,4,minecraft:nether_wart_block)
B(3,24,4,minecraft:nether_wart_block)
B(0,24,5,minecraft:nether_wart_block)
B(1,24,5,minecraft:nether_wart_block)
B(2,24,5,minecraft:nether_wart_block)
B(3,24,5,minecraft:nether_wart_block)
B(4,24,5,minecraft:nether_wart_block)
B(0,24,6,minecraft:nether_wart_block)
B(1,24,6,minecraft:nether_wart_block)
B(2,24,6,minecraft:nether_wart_block)
B(3,24,6,minecraft:nether_wart_block)
B(4,24,6,minecraft:nether_wart_block)
B(0,24,7,minecraft:nether_wart_block)
B(1,24,7,minecraft:nether_wart_block)
B(2,24,7,minecraft:nether_wart_block)
B(3,24,7,minecraft:nether_wart_block)
B(4,24,7,minecraft:nether_wart_block)
B(0,24,8,minecraft:nether_wart_block)
B(1,24,8,minecraft:nether_wart_block)
B(2,24,8,minecraft:nether_wart_block)
B(3,24,8,minecraft:nether_wart_block)
B(4,24,8,minecraft:nether_wart_block)
B(5,24,8,minecraft:nether_wart_block)
B(0,24,9,minecraft:nether_wart_block)
B(1,24,9,minecraft:nether_wart_block)
B(2,24,9,minecraft:nether_wart_block)
B(3,24,9,minecraft:nether_wart_block)
B(4,24,9,minecraft:nether_wart_block)
B(5,24,9,minecraft:nether_wart_block)
B(0,24,10,minecraft:nether_wart_block)
B(1,24,10,minecraft:nether_wart_block)
B(2,24,10,minecraft:nether_wart_block)
B(3,24,10,minecraft:nether_wart_block)
B(4,24,10,minecraft:nether_wart_block)
B(5,24,10,minecraft:nether_wart_block)
B(0,24,11,minecraft:nether_wart_block)
B(1,24,11,minecraft:nether_wart_block)
B(2,24,11,minecraft:nether_wart_block)
B(3,24,11,minecraft:nether_wart_block)
B(4,24,11,minecraft:nether_wart_block)
B(5,24,11,minecraft:nether_wart_block)
B(0,24,12,minecraft:nether_wart_block)
B(1,24,12,minecraft:nether_wart_block)
B(2,24,12,minecraft:nether_wart_block)
B(3,24,12,minecraft:nether_wart_block)
B(4,24,12,minecraft:nether_wart_block)
B(5,24,12,minecraft:nether_wart_block)
B(6,24,12,minecraft:nether_wart_block)
B(0,24,13,minecraft:nether_wart_block)
B(1,24,13,minecraft:nether_wart_block)
B(2,24,13,minecraft:nether_wart_block)
B(3,24,13,minecraft:nether_wart_block)
B(4,24,13,minecraft:nether_wart_block)
B(5,24,13,minecraft:nether_wart_block)
B(6,24,13,minecraft:nether_wart_block)
B(0,24,14,minecraft:nether_wart_block)
B(1,24,14,minecraft:nether_wart_block)
B(2,24,14,minecraft:nether_wart_block)
B(3,24,14,minecraft:nether_wart_block)
B(4,24,14,minecraft:nether_wart_block)
B(5,24,14,minecraft:nether_wart_block)
B(6,24,14,minecraft:nether_wart_block)
B(7,24,14,minecraft:nether_wart_block)
B(0,24,15,minecraft:nether_wart_block)
B(1,24,15,minecraft:nether_wart_block)
B(2,24,15,minecraft:nether_wart_block)
B(3,24,15,minecraft:nether_wart_block)
B(4,24,15,minecraft:nether_wart_block)
B(5,24,15,minecraft:nether_wart_block)
B(6,24,15,minecraft:nether_wart_block)
B(7,24,15,minecraft:nether_wart_block)
B(8,24,15,minecraft:nether_wart_block)
B(0,25,0,minecraft:nether_wart_block)
B(1,25,0,minecraft:nether_wart_block)
B(2,25,0,minecraft:nether_wart_block)
B(3,25,0,minecraft:nether_wart_block)
B(0,25,1,minecraft:nether_wart_block)
B(1,25,1,minecraft:nether_wart_block)
B(2,25,1,minecraft:nether_wart_block)
B(3,25,1,minecraft:nether_wart_block)
B(0,25,2,minecraft:nether_wart_block)
B(1,25,2,minecraft:nether_wart_block)
B(2,25,2,minecraft:nether_wart_block)
B(3,25,2,minecraft:nether_wart_block)
B(0,25,3,minecraft:nether_wart_block)
B(1,25,3,minecraft:nether_wart_block)
B(2,25,3,minecraft:nether_wart_block)
B(3,25,3,minecraft:nether_wart_block)
B(0,25,4,minecraft:nether_wart_block)
B(1,25,4,minecraft:nether_wart_block)
B(2,25,4,minecraft:nether_wart_block)
B(3,25,4,minecraft:nether_wart_block)
B(0,25,5,minecraft:nether_wart_block)
B(1,25,5,minecraft:nether_wart_block)
B(2,25,5,minecraft:nether_wart_block)
B(3,25,5,minecraft:nether_wart_block)
B(4,25,5,minecraft:nether_wart_block)
B(0,25,6,minecraft:nether_wart_block)
B(1,25,6,minecraft:nether_wart_block)
B(2,25,6,minecraft:nether_wart_block)
B(3,25,6,minecraft:nether_wart_block)
B(4,25,6,minecraft:nether_wart_block)
B(0,25,7,minecraft:nether_wart_block)
B(1,25,7,minecraft:nether_wart_block)
B(2,25,7,minecraft:nether_wart_block)
B(3,25,7,minecraft:nether_wart_block)
B(4,25,7,minecraft:nether_wart_block)
B(0,25,8,minecraft:nether_wart_block)
B(1,25,8,minecraft:nether_wart_block)
B(2,25,8,minecraft:nether_wart_block)
B(3,25,8,minecraft:nether_wart_block)
B(4,25,8,minecraft:nether_wart_block)
B(5,25,8,minecraft:nether_wart_block)
B(0,25,9,minecraft:nether_wart_block)
B(1,25,9,minecraft:nether_wart_block)
B(2,25,9,minecraft:nether_wart_block)
B(3,25,9,minecraft:nether_wart_block)
B(4,25,9,minecraft:nether_wart_block)
B(5,25,9,minecraft:nether_wart_block)
B(0,25,10,minecraft:nether_wart_block)
B(1,25,10,minecraft:nether_wart_block)
B(2,25,10,minecraft:nether_wart_block)
B(3,25,10,minecraft:nether_wart_block)
B(4,25,10,minecraft:nether_wart_block)
B(5,25,10,minecraft:nether_wart_block)
B(0,25,11,minecraft:nether_wart_block)
B(1,25,11,minecraft:nether_wart_block)
B(2,25,11,minecraft:nether_wart_block)
B(3,25,11,minecraft:nether_wart_block)
B(4,25,11,minecraft:nether_wart_block)
B(5,25,11,minecraft:nether_wart_block)
B(0,25,12,minecraft:nether_wart_block)
B(1,25,12,minecraft:nether_wart_block)
B(2,25,12,minecraft:nether_wart_block)
B(3,25,12,minecraft:nether_wart_block)
B(4,25,12,minecraft:nether_wart_block)
B(5,25,12,minecraft:nether_wart_block)
B(6,25,12,minecraft:nether_wart_block)
