
#######################################################################
# +-----------------------------------------------------------------+ #
# |                            BO4 object                           | #
# +-----------------------------------------------------------------+ #
#######################################################################

Author: Unknown

Description: No description given

SettingsMode: WriteWithoutComments


#######################################################################
# +-----------------------------------------------------------------+ #
# |                          Main settings                          | #
# +-----------------------------------------------------------------+ #
#######################################################################

FixedRotation: 

Frequency: 0

SpawnHeight: highestBlock

UseCenterForHighestBlock: true

##############################
# Height Limits for the BO4. #
##############################

MinHeight: 0

MaxHeight: 255

InheritBO3: 

InheritBO3Rotation: NORTH

OverrideChildSettings: true

OverrideParentHeight: false

CanOverride: false

BranchFrequency: 0

BranchFrequencyGroup: 

MustBeBelowOther: false

MustBeInside: 

CannotBeInside: 

ReplacesBO3: 

MustBeInsideWorldBorders: false

CanSpawnOnWater: true

SpawnOnWaterOnly: false

SpawnUnderWater: false

SpawnAtWaterLevel: false

HeightOffset: 0

RemoveAir: true

ReplaceAbove: 

ReplaceBelow: 

ReplaceWithBiomeBlocks: true

ReplaceWithSurfaceBlock: GRASS

ReplaceWithGroundBlock: DIRT

ReplaceWithStoneBlock: STONE

SmoothRadius: 0

SmoothHeightOffset: 0

SmoothStartTop: false

SmoothStartWood: false

SmoothingSurfaceBlock: 

SmoothingGroundBlock: 

BO3Group: 

IsSpawnPoint: false

DoReplaceBlocks: true


#######################################################################
# +-----------------------------------------------------------------+ #
# |                              Blocks                             | #
# +-----------------------------------------------------------------+ #
#######################################################################

RandomBlock(-3,0,-6,minecraft:obsidian,80,minecraft:crying_obsidian,20)
RandomBlock(-3,0,-5,minecraft:obsidian,80,minecraft:crying_obsidian,20)
RandomBlock(-3,0,-4,minecraft:obsidian,80,minecraft:crying_obsidian,20)
RandomBlock(-2,0,-7,minecraft:obsidian,80,minecraft:crying_obsidian,20)
RandomBlock(-2,2,-6,minecraft:obsidian,80,minecraft:crying_obsidian,20)
RandomBlock(-2,0,-5,minecraft:obsidian,80,minecraft:crying_obsidian,20)
RandomBlock(-2,1,-5,minecraft:obsidian,80,minecraft:crying_obsidian,20)
RandomBlock(-2,2,-5,minecraft:obsidian,80,minecraft:crying_obsidian,20)
RandomBlock(-2,3,-5,minecraft:obsidian,80,minecraft:crying_obsidian,20)
RandomBlock(-2,0,-4,minecraft:obsidian,80,minecraft:crying_obsidian,20)
RandomBlock(-2,1,-4,minecraft:obsidian,80,minecraft:crying_obsidian,20)
RandomBlock(-2,2,-4,minecraft:obsidian,80,minecraft:crying_obsidian,20)
RandomBlock(-2,3,-4,minecraft:obsidian,80,minecraft:crying_obsidian,20)
RandomBlock(-2,0,-3,minecraft:obsidian,80,minecraft:crying_obsidian,20)
RandomBlock(-2,1,-3,minecraft:obsidian,80,minecraft:crying_obsidian,20)
RandomBlock(-2,2,-3,minecraft:obsidian,80,minecraft:crying_obsidian,20)
RandomBlock(-2,0,-2,minecraft:obsidian,80,minecraft:crying_obsidian,20)
RandomBlock(-2,1,-2,minecraft:obsidian,80,minecraft:crying_obsidian,20)
RandomBlock(-1,0,-7,minecraft:obsidian,80,minecraft:crying_obsidian,20)
RandomBlock(-1,1,-7,minecraft:obsidian,80,minecraft:crying_obsidian,20)
RandomBlock(-1,2,-7,minecraft:obsidian,80,minecraft:crying_obsidian,20)
RandomBlock(-1,3,-7,minecraft:obsidian,80,minecraft:crying_obsidian,20)
RandomBlock(-1,0,-6,minecraft:obsidian,80,minecraft:crying_obsidian,20)
RandomBlock(-1,1,-6,minecraft:obsidian,80,minecraft:crying_obsidian,20)
RandomBlock(-1,2,-6,minecraft:obsidian,80,minecraft:crying_obsidian,20)
RandomBlock(-1,3,-6,minecraft:obsidian,80,minecraft:crying_obsidian,20)
RandomBlock(-1,4,-6,minecraft:obsidian,80,minecraft:crying_obsidian,20)
RandomBlock(-1,5,-6,minecraft:obsidian,80,minecraft:crying_obsidian,20)
RandomBlock(-1,6,-6,minecraft:obsidian,80,minecraft:crying_obsidian,20)
RandomBlock(-1,7,-6,minecraft:obsidian,80,minecraft:crying_obsidian,20)
RandomBlock(-1,8,-6,minecraft:obsidian,80,minecraft:crying_obsidian,20)
RandomBlock(-1,9,-6,minecraft:obsidian,80,minecraft:crying_obsidian,20)
RandomBlock(-1,0,-5,minecraft:obsidian,80,minecraft:crying_obsidian,20)
RandomBlock(-1,1,-5,minecraft:obsidian,80,minecraft:crying_obsidian,20)
RandomBlock(-1,2,-5,minecraft:obsidian,80,minecraft:crying_obsidian,20)
RandomBlock(-1,3,-5,minecraft:obsidian,80,minecraft:crying_obsidian,20)
RandomBlock(-1,4,-5,minecraft:obsidian,80,minecraft:crying_obsidian,20)
RandomBlock(-1,5,-5,minecraft:obsidian,80,minecraft:crying_obsidian,20)
RandomBlock(-1,6,-5,minecraft:obsidian,80,minecraft:crying_obsidian,20)
RandomBlock(-1,7,-5,minecraft:obsidian,80,minecraft:crying_obsidian,20)
RandomBlock(-1,8,-5,minecraft:obsidian,80,minecraft:crying_obsidian,20)
RandomBlock(-1,9,-5,minecraft:obsidian,80,minecraft:crying_obsidian,20)
RandomBlock(-1,10,-5,minecraft:obsidian,80,minecraft:crying_obsidian,20)
RandomBlock(-1,0,-4,minecraft:obsidian,80,minecraft:crying_obsidian,20)
RandomBlock(-1,1,-4,minecraft:obsidian,80,minecraft:crying_obsidian,20)
RandomBlock(-1,2,-4,minecraft:obsidian,80,minecraft:crying_obsidian,20)
RandomBlock(-1,3,-4,minecraft:obsidian,80,minecraft:crying_obsidian,20)
RandomBlock(-1,4,-4,minecraft:obsidian,80,minecraft:crying_obsidian,20)
RandomBlock(-1,5,-4,minecraft:obsidian,80,minecraft:crying_obsidian,20)
RandomBlock(-1,6,-4,minecraft:obsidian,80,minecraft:crying_obsidian,20)
RandomBlock(-1,7,-4,minecraft:obsidian,80,minecraft:crying_obsidian,20)
RandomBlock(-1,8,-4,minecraft:obsidian,80,minecraft:crying_obsidian,20)
RandomBlock(-1,9,-4,minecraft:obsidian,80,minecraft:crying_obsidian,20)
RandomBlock(-1,0,-3,minecraft:obsidian,80,minecraft:crying_obsidian,20)
RandomBlock(-1,1,-3,minecraft:obsidian,80,minecraft:crying_obsidian,20)
RandomBlock(-1,2,-3,minecraft:obsidian,80,minecraft:crying_obsidian,20)
RandomBlock(-1,3,-3,minecraft:obsidian,80,minecraft:crying_obsidian,20)
RandomBlock(-1,4,-3,minecraft:obsidian,80,minecraft:crying_obsidian,20)
RandomBlock(-1,5,-3,minecraft:obsidian,80,minecraft:crying_obsidian,20)
RandomBlock(-1,0,-2,minecraft:obsidian,80,minecraft:crying_obsidian,20)
RandomBlock(-1,1,-2,minecraft:obsidian,80,minecraft:crying_obsidian,20)
RandomBlock(-1,2,-2,minecraft:obsidian,80,minecraft:crying_obsidian,20)
RandomBlock(-1,3,-2,minecraft:obsidian,80,minecraft:crying_obsidian,20)
RandomBlock(-1,4,-2,minecraft:obsidian,80,minecraft:crying_obsidian,20)
RandomBlock(-1,0,-1,minecraft:obsidian,80,minecraft:crying_obsidian,20)
RandomBlock(-1,1,-1,minecraft:obsidian,80,minecraft:crying_obsidian,20)
RandomBlock(-1,2,-1,minecraft:obsidian,80,minecraft:crying_obsidian,20)
RandomBlock(-1,3,-1,minecraft:obsidian,80,minecraft:crying_obsidian,20)
RandomBlock(-1,0,0,minecraft:obsidian,80,minecraft:crying_obsidian,20)
RandomBlock(0,0,-7,minecraft:obsidian,80,minecraft:crying_obsidian,20)
RandomBlock(0,1,-7,minecraft:obsidian,80,minecraft:crying_obsidian,20)
RandomBlock(0,2,-7,minecraft:obsidian,80,minecraft:crying_obsidian,20)
RandomBlock(0,3,-7,minecraft:obsidian,80,minecraft:crying_obsidian,20)
RandomBlock(0,4,-7,minecraft:obsidian,80,minecraft:crying_obsidian,20)
RandomBlock(0,5,-7,minecraft:obsidian,80,minecraft:crying_obsidian,20)
RandomBlock(0,6,-7,minecraft:obsidian,80,minecraft:crying_obsidian,20)
RandomBlock(0,7,-7,minecraft:obsidian,80,minecraft:crying_obsidian,20)
RandomBlock(0,8,-7,minecraft:obsidian,80,minecraft:crying_obsidian,20)
RandomBlock(0,9,-7,minecraft:obsidian,80,minecraft:crying_obsidian,20)
RandomBlock(0,10,-7,minecraft:obsidian,80,minecraft:crying_obsidian,20)
RandomBlock(0,11,-7,minecraft:obsidian,80,minecraft:crying_obsidian,20)
RandomBlock(0,12,-7,minecraft:obsidian,80,minecraft:crying_obsidian,20)
RandomBlock(0,0,-6,minecraft:obsidian,80,minecraft:crying_obsidian,20)
RandomBlock(0,1,-6,minecraft:obsidian,80,minecraft:crying_obsidian,20)
RandomBlock(0,2,-6,minecraft:obsidian,80,minecraft:crying_obsidian,20)
RandomBlock(0,3,-6,minecraft:obsidian,80,minecraft:crying_obsidian,20)
RandomBlock(0,4,-6,minecraft:obsidian,80,minecraft:crying_obsidian,20)
RandomBlock(0,5,-6,minecraft:obsidian,80,minecraft:crying_obsidian,20)
RandomBlock(0,6,-6,minecraft:obsidian,80,minecraft:crying_obsidian,20)
RandomBlock(0,7,-6,minecraft:obsidian,80,minecraft:crying_obsidian,20)
RandomBlock(0,8,-6,minecraft:obsidian,80,minecraft:crying_obsidian,20)
RandomBlock(0,9,-6,minecraft:obsidian,80,minecraft:crying_obsidian,20)
RandomBlock(0,10,-6,minecraft:obsidian,80,minecraft:crying_obsidian,20)
RandomBlock(0,11,-6,minecraft:obsidian,80,minecraft:crying_obsidian,20)
RandomBlock(0,12,-6,minecraft:obsidian,80,minecraft:crying_obsidian,20)
RandomBlock(0,13,-6,minecraft:obsidian,80,minecraft:crying_obsidian,20)
RandomBlock(0,14,-6,minecraft:obsidian,80,minecraft:crying_obsidian,20)
RandomBlock(0,15,-6,minecraft:obsidian,80,minecraft:crying_obsidian,20)
RandomBlock(0,16,-6,minecraft:obsidian,80,minecraft:crying_obsidian,20)
RandomBlock(0,17,-6,minecraft:obsidian,80,minecraft:crying_obsidian,20)
RandomBlock(0,0,-5,minecraft:obsidian,80,minecraft:crying_obsidian,20)
RandomBlock(0,1,-5,minecraft:obsidian,80,minecraft:crying_obsidian,20)
RandomBlock(0,2,-5,minecraft:obsidian,80,minecraft:crying_obsidian,20)
RandomBlock(0,3,-5,minecraft:obsidian,80,minecraft:crying_obsidian,20)
RandomBlock(0,4,-5,minecraft:obsidian,80,minecraft:crying_obsidian,20)
RandomBlock(0,5,-5,minecraft:obsidian,80,minecraft:crying_obsidian,20)
RandomBlock(0,6,-5,minecraft:obsidian,80,minecraft:crying_obsidian,20)
RandomBlock(0,7,-5,minecraft:obsidian,80,minecraft:crying_obsidian,20)
RandomBlock(0,8,-5,minecraft:obsidian,80,minecraft:crying_obsidian,20)
RandomBlock(0,9,-5,minecraft:obsidian,80,minecraft:crying_obsidian,20)
RandomBlock(0,10,-5,minecraft:obsidian,80,minecraft:crying_obsidian,20)
RandomBlock(0,11,-5,minecraft:obsidian,80,minecraft:crying_obsidian,20)
RandomBlock(0,12,-5,minecraft:obsidian,80,minecraft:crying_obsidian,20)
RandomBlock(0,13,-5,minecraft:obsidian,80,minecraft:crying_obsidian,20)
RandomBlock(0,14,-5,minecraft:obsidian,80,minecraft:crying_obsidian,20)
RandomBlock(0,15,-5,minecraft:obsidian,80,minecraft:crying_obsidian,20)
RandomBlock(0,16,-5,minecraft:obsidian,80,minecraft:crying_obsidian,20)
RandomBlock(0,17,-5,minecraft:obsidian,80,minecraft:crying_obsidian,20)
RandomBlock(0,0,-4,minecraft:obsidian,80,minecraft:crying_obsidian,20)
RandomBlock(0,1,-4,minecraft:obsidian,80,minecraft:crying_obsidian,20)
RandomBlock(0,2,-4,minecraft:obsidian,80,minecraft:crying_obsidian,20)
RandomBlock(0,3,-4,minecraft:obsidian,80,minecraft:crying_obsidian,20)
RandomBlock(0,4,-4,minecraft:obsidian,80,minecraft:crying_obsidian,20)
RandomBlock(0,5,-4,minecraft:obsidian,80,minecraft:crying_obsidian,20)
RandomBlock(0,6,-4,minecraft:obsidian,80,minecraft:crying_obsidian,20)
RandomBlock(0,7,-4,minecraft:obsidian,80,minecraft:crying_obsidian,20)
RandomBlock(0,8,-4,minecraft:obsidian,80,minecraft:crying_obsidian,20)
RandomBlock(0,9,-4,minecraft:obsidian,80,minecraft:crying_obsidian,20)
RandomBlock(0,10,-4,minecraft:obsidian,80,minecraft:crying_obsidian,20)
RandomBlock(0,11,-4,minecraft:obsidian,80,minecraft:crying_obsidian,20)
RandomBlock(0,12,-4,minecraft:obsidian,80,minecraft:crying_obsidian,20)
RandomBlock(0,13,-4,minecraft:obsidian,80,minecraft:crying_obsidian,20)
RandomBlock(0,14,-4,minecraft:obsidian,80,minecraft:crying_obsidian,20)
RandomBlock(0,15,-4,minecraft:obsidian,80,minecraft:crying_obsidian,20)
RandomBlock(0,16,-4,minecraft:obsidian,80,minecraft:crying_obsidian,20)
RandomBlock(0,17,-4,minecraft:obsidian,80,minecraft:crying_obsidian,20)
RandomBlock(0,0,-3,minecraft:obsidian,80,minecraft:crying_obsidian,20)
RandomBlock(0,1,-3,minecraft:obsidian,80,minecraft:crying_obsidian,20)
RandomBlock(0,2,-3,minecraft:obsidian,80,minecraft:crying_obsidian,20)
RandomBlock(0,3,-3,minecraft:obsidian,80,minecraft:crying_obsidian,20)
RandomBlock(0,4,-3,minecraft:obsidian,80,minecraft:crying_obsidian,20)
RandomBlock(0,5,-3,minecraft:obsidian,80,minecraft:crying_obsidian,20)
RandomBlock(0,6,-3,minecraft:obsidian,80,minecraft:crying_obsidian,20)
RandomBlock(0,7,-3,minecraft:obsidian,80,minecraft:crying_obsidian,20)
RandomBlock(0,8,-3,minecraft:obsidian,80,minecraft:crying_obsidian,20)
RandomBlock(0,9,-3,minecraft:obsidian,80,minecraft:crying_obsidian,20)
RandomBlock(0,10,-3,minecraft:obsidian,80,minecraft:crying_obsidian,20)
RandomBlock(0,11,-3,minecraft:obsidian,80,minecraft:crying_obsidian,20)
RandomBlock(0,12,-3,minecraft:obsidian,80,minecraft:crying_obsidian,20)
RandomBlock(0,13,-3,minecraft:obsidian,80,minecraft:crying_obsidian,20)
RandomBlock(0,0,-2,minecraft:obsidian,80,minecraft:crying_obsidian,20)
RandomBlock(0,1,-2,minecraft:obsidian,80,minecraft:crying_obsidian,20)
RandomBlock(0,2,-2,minecraft:obsidian,80,minecraft:crying_obsidian,20)
RandomBlock(0,3,-2,minecraft:obsidian,80,minecraft:crying_obsidian,20)
RandomBlock(0,4,-2,minecraft:obsidian,80,minecraft:crying_obsidian,20)
RandomBlock(0,5,-2,minecraft:obsidian,80,minecraft:crying_obsidian,20)
RandomBlock(0,6,-2,minecraft:obsidian,80,minecraft:crying_obsidian,20)
RandomBlock(0,0,-1,minecraft:obsidian,80,minecraft:crying_obsidian,20)
RandomBlock(0,1,-1,minecraft:obsidian,80,minecraft:crying_obsidian,20)
RandomBlock(0,2,-1,minecraft:obsidian,80,minecraft:crying_obsidian,20)
RandomBlock(0,3,-1,minecraft:obsidian,80,minecraft:crying_obsidian,20)
RandomBlock(0,4,-1,minecraft:obsidian,80,minecraft:crying_obsidian,20)
RandomBlock(0,0,0,minecraft:obsidian,80,minecraft:crying_obsidian,20)
RandomBlock(0,1,0,minecraft:obsidian,80,minecraft:crying_obsidian,20)
RandomBlock(0,2,0,minecraft:obsidian,80,minecraft:crying_obsidian,20)
RandomBlock(0,3,0,minecraft:obsidian,80,minecraft:crying_obsidian,20)
RandomBlock(0,4,0,minecraft:obsidian,80,minecraft:crying_obsidian,20)
RandomBlock(0,0,1,minecraft:obsidian,80,minecraft:crying_obsidian,20)
RandomBlock(0,1,1,minecraft:obsidian,80,minecraft:crying_obsidian,20)
RandomBlock(0,0,2,minecraft:obsidian,80,minecraft:crying_obsidian,20)
RandomBlock(1,0,-7,minecraft:obsidian,80,minecraft:crying_obsidian,20)
RandomBlock(1,1,-7,minecraft:obsidian,80,minecraft:crying_obsidian,20)
RandomBlock(1,2,-7,minecraft:obsidian,80,minecraft:crying_obsidian,20)
RandomBlock(1,3,-7,minecraft:obsidian,80,minecraft:crying_obsidian,20)
RandomBlock(1,4,-7,minecraft:obsidian,80,minecraft:crying_obsidian,20)
RandomBlock(1,5,-7,minecraft:obsidian,80,minecraft:crying_obsidian,20)
RandomBlock(1,6,-7,minecraft:obsidian,80,minecraft:crying_obsidian,20)
RandomBlock(1,7,-7,minecraft:obsidian,80,minecraft:crying_obsidian,20)
RandomBlock(1,8,-7,minecraft:obsidian,80,minecraft:crying_obsidian,20)
RandomBlock(1,9,-7,minecraft:obsidian,80,minecraft:crying_obsidian,20)
RandomBlock(1,10,-7,minecraft:obsidian,80,minecraft:crying_obsidian,20)
RandomBlock(1,11,-7,minecraft:obsidian,80,minecraft:crying_obsidian,20)
RandomBlock(1,12,-7,minecraft:obsidian,80,minecraft:crying_obsidian,20)
RandomBlock(1,13,-7,minecraft:obsidian,80,minecraft:crying_obsidian,20)
RandomBlock(1,14,-7,minecraft:obsidian,80,minecraft:crying_obsidian,20)
RandomBlock(1,15,-7,minecraft:obsidian,80,minecraft:crying_obsidian,20)
RandomBlock(1,16,-7,minecraft:obsidian,80,minecraft:crying_obsidian,20)
RandomBlock(1,17,-7,minecraft:obsidian,80,minecraft:crying_obsidian,20)
RandomBlock(1,18,-7,minecraft:obsidian,80,minecraft:crying_obsidian,20)
RandomBlock(1,19,-7,minecraft:obsidian,80,minecraft:crying_obsidian,20)
RandomBlock(1,20,-7,minecraft:obsidian,80,minecraft:crying_obsidian,20)
RandomBlock(1,21,-7,minecraft:obsidian,80,minecraft:crying_obsidian,20)
RandomBlock(1,22,-7,minecraft:obsidian,80,minecraft:crying_obsidian,20)
RandomBlock(1,0,-6,minecraft:obsidian,80,minecraft:crying_obsidian,20)
RandomBlock(1,1,-6,minecraft:obsidian,80,minecraft:crying_obsidian,20)
RandomBlock(1,2,-6,minecraft:obsidian,80,minecraft:crying_obsidian,20)
RandomBlock(1,3,-6,minecraft:obsidian,80,minecraft:crying_obsidian,20)
RandomBlock(1,4,-6,minecraft:obsidian,80,minecraft:crying_obsidian,20)
RandomBlock(1,5,-6,minecraft:obsidian,80,minecraft:crying_obsidian,20)
RandomBlock(1,6,-6,minecraft:obsidian,80,minecraft:crying_obsidian,20)
RandomBlock(1,7,-6,minecraft:obsidian,80,minecraft:crying_obsidian,20)
RandomBlock(1,8,-6,minecraft:obsidian,80,minecraft:crying_obsidian,20)
RandomBlock(1,9,-6,minecraft:obsidian,80,minecraft:crying_obsidian,20)
RandomBlock(1,10,-6,minecraft:obsidian,80,minecraft:crying_obsidian,20)
RandomBlock(1,11,-6,minecraft:obsidian,80,minecraft:crying_obsidian,20)
RandomBlock(1,12,-6,minecraft:obsidian,80,minecraft:crying_obsidian,20)
RandomBlock(1,13,-6,minecraft:obsidian,80,minecraft:crying_obsidian,20)
RandomBlock(1,14,-6,minecraft:obsidian,80,minecraft:crying_obsidian,20)
RandomBlock(1,15,-6,minecraft:obsidian,80,minecraft:crying_obsidian,20)
RandomBlock(1,16,-6,minecraft:obsidian,80,minecraft:crying_obsidian,20)
RandomBlock(1,17,-6,minecraft:obsidian,80,minecraft:crying_obsidian,20)
RandomBlock(1,18,-6,minecraft:obsidian,80,minecraft:crying_obsidian,20)
RandomBlock(1,19,-6,minecraft:obsidian,80,minecraft:crying_obsidian,20)
RandomBlock(1,20,-6,minecraft:obsidian,80,minecraft:crying_obsidian,20)
RandomBlock(1,21,-6,minecraft:obsidian,80,minecraft:crying_obsidian,20)
RandomBlock(1,22,-6,minecraft:obsidian,80,minecraft:crying_obsidian,20)
RandomBlock(1,23,-6,minecraft:obsidian,80,minecraft:crying_obsidian,20)
RandomBlock(1,0,-5,minecraft:obsidian,80,minecraft:crying_obsidian,20)
RandomBlock(1,1,-5,minecraft:obsidian,80,minecraft:crying_obsidian,20)
RandomBlock(1,2,-5,minecraft:obsidian,80,minecraft:crying_obsidian,20)
RandomBlock(1,3,-5,minecraft:obsidian,80,minecraft:crying_obsidian,20)
RandomBlock(1,4,-5,minecraft:obsidian,80,minecraft:crying_obsidian,20)
RandomBlock(1,5,-5,minecraft:obsidian,80,minecraft:crying_obsidian,20)
RandomBlock(1,6,-5,minecraft:obsidian,80,minecraft:crying_obsidian,20)
RandomBlock(1,7,-5,minecraft:obsidian,80,minecraft:crying_obsidian,20)
RandomBlock(1,8,-5,minecraft:obsidian,80,minecraft:crying_obsidian,20)
RandomBlock(1,9,-5,minecraft:obsidian,80,minecraft:crying_obsidian,20)
RandomBlock(1,10,-5,minecraft:obsidian,80,minecraft:crying_obsidian,20)
RandomBlock(1,11,-5,minecraft:obsidian,80,minecraft:crying_obsidian,20)
RandomBlock(1,12,-5,minecraft:obsidian,80,minecraft:crying_obsidian,20)
RandomBlock(1,13,-5,minecraft:obsidian,80,minecraft:crying_obsidian,20)
RandomBlock(1,14,-5,minecraft:obsidian,80,minecraft:crying_obsidian,20)
RandomBlock(1,15,-5,minecraft:obsidian,80,minecraft:crying_obsidian,20)
RandomBlock(1,16,-5,minecraft:obsidian,80,minecraft:crying_obsidian,20)
RandomBlock(1,17,-5,minecraft:obsidian,80,minecraft:crying_obsidian,20)
RandomBlock(1,18,-5,minecraft:obsidian,80,minecraft:crying_obsidian,20)
RandomBlock(1,19,-5,minecraft:obsidian,80,minecraft:crying_obsidian,20)
RandomBlock(1,20,-5,minecraft:obsidian,80,minecraft:crying_obsidian,20)
RandomBlock(1,0,-4,minecraft:obsidian,80,minecraft:crying_obsidian,20)
RandomBlock(1,1,-4,minecraft:obsidian,80,minecraft:crying_obsidian,20)
RandomBlock(1,2,-4,minecraft:obsidian,80,minecraft:crying_obsidian,20)
RandomBlock(1,3,-4,minecraft:obsidian,80,minecraft:crying_obsidian,20)
RandomBlock(1,4,-4,minecraft:obsidian,80,minecraft:crying_obsidian,20)
RandomBlock(1,5,-4,minecraft:obsidian,80,minecraft:crying_obsidian,20)
RandomBlock(1,6,-4,minecraft:obsidian,80,minecraft:crying_obsidian,20)
RandomBlock(1,7,-4,minecraft:obsidian,80,minecraft:crying_obsidian,20)
RandomBlock(1,8,-4,minecraft:obsidian,80,minecraft:crying_obsidian,20)
RandomBlock(1,9,-4,minecraft:obsidian,80,minecraft:crying_obsidian,20)
RandomBlock(1,10,-4,minecraft:obsidian,80,minecraft:crying_obsidian,20)
RandomBlock(1,11,-4,minecraft:obsidian,80,minecraft:crying_obsidian,20)
RandomBlock(1,12,-4,minecraft:obsidian,80,minecraft:crying_obsidian,20)
RandomBlock(1,13,-4,minecraft:obsidian,80,minecraft:crying_obsidian,20)
RandomBlock(1,14,-4,minecraft:obsidian,80,minecraft:crying_obsidian,20)
RandomBlock(1,15,-4,minecraft:obsidian,80,minecraft:crying_obsidian,20)
RandomBlock(1,16,-4,minecraft:obsidian,80,minecraft:crying_obsidian,20)
RandomBlock(1,17,-4,minecraft:obsidian,80,minecraft:crying_obsidian,20)
RandomBlock(1,18,-4,minecraft:obsidian,80,minecraft:crying_obsidian,20)
RandomBlock(1,19,-4,minecraft:obsidian,80,minecraft:crying_obsidian,20)
RandomBlock(1,20,-4,minecraft:obsidian,80,minecraft:crying_obsidian,20)
RandomBlock(1,0,-3,minecraft:obsidian,80,minecraft:crying_obsidian,20)
RandomBlock(1,1,-3,minecraft:obsidian,80,minecraft:crying_obsidian,20)
RandomBlock(1,2,-3,minecraft:obsidian,80,minecraft:crying_obsidian,20)
RandomBlock(1,3,-3,minecraft:obsidian,80,minecraft:crying_obsidian,20)
RandomBlock(1,4,-3,minecraft:obsidian,80,minecraft:crying_obsidian,20)
RandomBlock(1,5,-3,minecraft:obsidian,80,minecraft:crying_obsidian,20)
RandomBlock(1,6,-3,minecraft:obsidian,80,minecraft:crying_obsidian,20)
RandomBlock(1,7,-3,minecraft:obsidian,80,minecraft:crying_obsidian,20)
RandomBlock(1,8,-3,minecraft:obsidian,80,minecraft:crying_obsidian,20)
RandomBlock(1,9,-3,minecraft:obsidian,80,minecraft:crying_obsidian,20)
RandomBlock(1,10,-3,minecraft:obsidian,80,minecraft:crying_obsidian,20)
RandomBlock(1,11,-3,minecraft:obsidian,80,minecraft:crying_obsidian,20)
RandomBlock(1,12,-3,minecraft:obsidian,80,minecraft:crying_obsidian,20)
RandomBlock(1,13,-3,minecraft:obsidian,80,minecraft:crying_obsidian,20)
RandomBlock(1,14,-3,minecraft:obsidian,80,minecraft:crying_obsidian,20)
RandomBlock(1,15,-3,minecraft:obsidian,80,minecraft:crying_obsidian,20)
RandomBlock(1,16,-3,minecraft:obsidian,80,minecraft:crying_obsidian,20)
RandomBlock(1,17,-3,minecraft:obsidian,80,minecraft:crying_obsidian,20)
RandomBlock(1,18,-3,minecraft:obsidian,80,minecraft:crying_obsidian,20)
RandomBlock(1,19,-3,minecraft:obsidian,80,minecraft:crying_obsidian,20)
RandomBlock(1,20,-3,minecraft:obsidian,80,minecraft:crying_obsidian,20)
RandomBlock(1,0,-2,minecraft:obsidian,80,minecraft:crying_obsidian,20)
RandomBlock(1,1,-2,minecraft:obsidian,80,minecraft:crying_obsidian,20)
RandomBlock(1,2,-2,minecraft:obsidian,80,minecraft:crying_obsidian,20)
RandomBlock(1,3,-2,minecraft:obsidian,80,minecraft:crying_obsidian,20)
RandomBlock(1,4,-2,minecraft:obsidian,80,minecraft:crying_obsidian,20)
RandomBlock(1,5,-2,minecraft:obsidian,80,minecraft:crying_obsidian,20)
RandomBlock(1,6,-2,minecraft:obsidian,80,minecraft:crying_obsidian,20)
RandomBlock(1,7,-2,minecraft:obsidian,80,minecraft:crying_obsidian,20)
RandomBlock(1,8,-2,minecraft:obsidian,80,minecraft:crying_obsidian,20)
RandomBlock(1,9,-2,minecraft:obsidian,80,minecraft:crying_obsidian,20)
RandomBlock(1,10,-2,minecraft:obsidian,80,minecraft:crying_obsidian,20)
RandomBlock(1,11,-2,minecraft:obsidian,80,minecraft:crying_obsidian,20)
RandomBlock(1,12,-2,minecraft:obsidian,80,minecraft:crying_obsidian,20)
RandomBlock(1,13,-2,minecraft:obsidian,80,minecraft:crying_obsidian,20)
RandomBlock(1,0,-1,minecraft:obsidian,80,minecraft:crying_obsidian,20)
RandomBlock(1,1,-1,minecraft:obsidian,80,minecraft:crying_obsidian,20)
RandomBlock(1,2,-1,minecraft:obsidian,80,minecraft:crying_obsidian,20)
RandomBlock(1,3,-1,minecraft:obsidian,80,minecraft:crying_obsidian,20)
RandomBlock(1,4,-1,minecraft:obsidian,80,minecraft:crying_obsidian,20)
RandomBlock(1,5,-1,minecraft:obsidian,80,minecraft:crying_obsidian,20)
RandomBlock(1,6,-1,minecraft:obsidian,80,minecraft:crying_obsidian,20)
RandomBlock(1,7,-1,minecraft:obsidian,80,minecraft:crying_obsidian,20)
RandomBlock(1,0,0,minecraft:obsidian,80,minecraft:crying_obsidian,20)
RandomBlock(1,1,0,minecraft:obsidian,80,minecraft:crying_obsidian,20)
RandomBlock(1,2,0,minecraft:obsidian,80,minecraft:crying_obsidian,20)
RandomBlock(1,3,0,minecraft:obsidian,80,minecraft:crying_obsidian,20)
RandomBlock(1,0,1,minecraft:obsidian,80,minecraft:crying_obsidian,20)
RandomBlock(1,1,1,minecraft:obsidian,80,minecraft:crying_obsidian,20)
RandomBlock(1,2,1,minecraft:obsidian,80,minecraft:crying_obsidian,20)
RandomBlock(1,3,1,minecraft:obsidian,80,minecraft:crying_obsidian,20)
RandomBlock(1,4,1,minecraft:obsidian,80,minecraft:crying_obsidian,20)
RandomBlock(1,5,1,minecraft:obsidian,80,minecraft:crying_obsidian,20)
RandomBlock(1,6,1,minecraft:obsidian,80,minecraft:crying_obsidian,20)
RandomBlock(1,0,2,minecraft:obsidian,80,minecraft:crying_obsidian,20)
RandomBlock(1,1,2,minecraft:obsidian,80,minecraft:crying_obsidian,20)
RandomBlock(1,2,2,minecraft:obsidian,80,minecraft:crying_obsidian,20)
RandomBlock(1,3,2,minecraft:obsidian,80,minecraft:crying_obsidian,20)
RandomBlock(1,4,2,minecraft:obsidian,80,minecraft:crying_obsidian,20)
RandomBlock(1,5,2,minecraft:obsidian,80,minecraft:crying_obsidian,20)
RandomBlock(1,0,3,minecraft:obsidian,80,minecraft:crying_obsidian,20)
RandomBlock(2,0,-7,minecraft:obsidian,80,minecraft:crying_obsidian,20)
RandomBlock(2,1,-7,minecraft:obsidian,80,minecraft:crying_obsidian,20)
RandomBlock(2,2,-7,minecraft:obsidian,80,minecraft:crying_obsidian,20)
RandomBlock(2,3,-7,minecraft:obsidian,80,minecraft:crying_obsidian,20)
RandomBlock(2,4,-7,minecraft:obsidian,80,minecraft:crying_obsidian,20)
RandomBlock(2,5,-7,minecraft:obsidian,80,minecraft:crying_obsidian,20)
RandomBlock(2,6,-7,minecraft:obsidian,80,minecraft:crying_obsidian,20)
RandomBlock(2,7,-7,minecraft:obsidian,80,minecraft:crying_obsidian,20)
RandomBlock(2,8,-7,minecraft:obsidian,80,minecraft:crying_obsidian,20)
RandomBlock(2,9,-7,minecraft:obsidian,80,minecraft:crying_obsidian,20)
RandomBlock(2,10,-7,minecraft:obsidian,80,minecraft:crying_obsidian,20)
RandomBlock(2,11,-7,minecraft:obsidian,80,minecraft:crying_obsidian,20)
RandomBlock(2,12,-7,minecraft:obsidian,80,minecraft:crying_obsidian,20)
RandomBlock(2,13,-7,minecraft:obsidian,80,minecraft:crying_obsidian,20)
RandomBlock(2,14,-7,minecraft:obsidian,80,minecraft:crying_obsidian,20)
RandomBlock(2,15,-7,minecraft:obsidian,80,minecraft:crying_obsidian,20)
RandomBlock(2,16,-7,minecraft:obsidian,80,minecraft:crying_obsidian,20)
RandomBlock(2,17,-7,minecraft:obsidian,80,minecraft:crying_obsidian,20)
RandomBlock(2,18,-7,minecraft:obsidian,80,minecraft:crying_obsidian,20)
RandomBlock(2,19,-7,minecraft:obsidian,80,minecraft:crying_obsidian,20)
RandomBlock(2,20,-7,minecraft:obsidian,80,minecraft:crying_obsidian,20)
RandomBlock(2,21,-7,minecraft:obsidian,80,minecraft:crying_obsidian,20)
RandomBlock(2,22,-7,minecraft:obsidian,80,minecraft:crying_obsidian,20)
RandomBlock(2,23,-7,minecraft:obsidian,80,minecraft:crying_obsidian,20)
RandomBlock(2,24,-7,minecraft:obsidian,80,minecraft:crying_obsidian,20)
RandomBlock(2,0,-6,minecraft:obsidian,80,minecraft:crying_obsidian,20)
RandomBlock(2,1,-6,minecraft:obsidian,80,minecraft:crying_obsidian,20)
RandomBlock(2,3,-6,minecraft:obsidian,80,minecraft:crying_obsidian,20)
RandomBlock(2,4,-6,minecraft:obsidian,80,minecraft:crying_obsidian,20)
RandomBlock(2,5,-6,minecraft:obsidian,80,minecraft:crying_obsidian,20)
RandomBlock(2,6,-6,minecraft:obsidian,80,minecraft:crying_obsidian,20)
RandomBlock(2,7,-6,minecraft:obsidian,80,minecraft:crying_obsidian,20)
RandomBlock(2,8,-6,minecraft:obsidian,80,minecraft:crying_obsidian,20)
RandomBlock(2,9,-6,minecraft:obsidian,80,minecraft:crying_obsidian,20)
RandomBlock(2,10,-6,minecraft:obsidian,80,minecraft:crying_obsidian,20)
RandomBlock(2,11,-6,minecraft:obsidian,80,minecraft:crying_obsidian,20)
RandomBlock(2,12,-6,minecraft:obsidian,80,minecraft:crying_obsidian,20)
RandomBlock(2,13,-6,minecraft:obsidian,80,minecraft:crying_obsidian,20)
RandomBlock(2,14,-6,minecraft:obsidian,80,minecraft:crying_obsidian,20)
RandomBlock(2,15,-6,minecraft:obsidian,80,minecraft:crying_obsidian,20)
RandomBlock(2,16,-6,minecraft:obsidian,80,minecraft:crying_obsidian,20)
RandomBlock(2,17,-6,minecraft:obsidian,80,minecraft:crying_obsidian,20)
RandomBlock(2,18,-6,minecraft:obsidian,80,minecraft:crying_obsidian,20)
RandomBlock(2,19,-6,minecraft:obsidian,80,minecraft:crying_obsidian,20)
RandomBlock(2,20,-6,minecraft:obsidian,80,minecraft:crying_obsidian,20)
RandomBlock(2,21,-6,minecraft:obsidian,80,minecraft:crying_obsidian,20)
RandomBlock(2,22,-6,minecraft:obsidian,80,minecraft:crying_obsidian,20)
RandomBlock(2,23,-6,minecraft:obsidian,80,minecraft:crying_obsidian,20)
RandomBlock(2,24,-6,minecraft:obsidian,80,minecraft:crying_obsidian,20)
RandomBlock(2,25,-6,minecraft:obsidian,80,minecraft:crying_obsidian,20)
RandomBlock(2,0,-5,minecraft:obsidian,80,minecraft:crying_obsidian,20)
RandomBlock(2,1,-5,minecraft:obsidian,80,minecraft:crying_obsidian,20)
RandomBlock(2,3,-5,minecraft:obsidian,80,minecraft:crying_obsidian,20)
RandomBlock(2,4,-5,minecraft:obsidian,80,minecraft:crying_obsidian,20)
RandomBlock(2,5,-5,minecraft:obsidian,80,minecraft:crying_obsidian,20)
RandomBlock(2,6,-5,minecraft:obsidian,80,minecraft:crying_obsidian,20)
RandomBlock(2,7,-5,minecraft:obsidian,80,minecraft:crying_obsidian,20)
RandomBlock(2,8,-5,minecraft:obsidian,80,minecraft:crying_obsidian,20)
RandomBlock(2,9,-5,minecraft:obsidian,80,minecraft:crying_obsidian,20)
RandomBlock(2,10,-5,minecraft:obsidian,80,minecraft:crying_obsidian,20)
RandomBlock(2,11,-5,minecraft:obsidian,80,minecraft:crying_obsidian,20)
RandomBlock(2,12,-5,minecraft:obsidian,80,minecraft:crying_obsidian,20)
RandomBlock(2,13,-5,minecraft:obsidian,80,minecraft:crying_obsidian,20)
RandomBlock(2,14,-5,minecraft:obsidian,80,minecraft:crying_obsidian,20)
RandomBlock(2,15,-5,minecraft:obsidian,80,minecraft:crying_obsidian,20)
RandomBlock(2,16,-5,minecraft:obsidian,80,minecraft:crying_obsidian,20)
RandomBlock(2,17,-5,minecraft:obsidian,80,minecraft:crying_obsidian,20)
RandomBlock(2,18,-5,minecraft:obsidian,80,minecraft:crying_obsidian,20)
RandomBlock(2,19,-5,minecraft:obsidian,80,minecraft:crying_obsidian,20)
RandomBlock(2,20,-5,minecraft:obsidian,80,minecraft:crying_obsidian,20)
RandomBlock(2,21,-5,minecraft:obsidian,80,minecraft:crying_obsidian,20)
RandomBlock(2,22,-5,minecraft:obsidian,80,minecraft:crying_obsidian,20)
RandomBlock(2,23,-5,minecraft:obsidian,80,minecraft:crying_obsidian,20)
RandomBlock(2,24,-5,minecraft:obsidian,80,minecraft:crying_obsidian,20)
RandomBlock(2,25,-5,minecraft:obsidian,80,minecraft:crying_obsidian,20)
RandomBlock(2,26,-5,minecraft:obsidian,80,minecraft:crying_obsidian,20)
RandomBlock(2,27,-5,minecraft:obsidian,80,minecraft:crying_obsidian,20)
RandomBlock(2,28,-5,minecraft:obsidian,80,minecraft:crying_obsidian,20)
RandomBlock(2,29,-5,minecraft:obsidian,80,minecraft:crying_obsidian,20)
RandomBlock(2,1,-4,minecraft:obsidian,80,minecraft:crying_obsidian,20)
RandomBlock(2,2,-4,minecraft:obsidian,80,minecraft:crying_obsidian,20)
RandomBlock(2,3,-4,minecraft:obsidian,80,minecraft:crying_obsidian,20)
RandomBlock(2,4,-4,minecraft:obsidian,80,minecraft:crying_obsidian,20)
RandomBlock(2,5,-4,minecraft:obsidian,80,minecraft:crying_obsidian,20)
RandomBlock(2,6,-4,minecraft:obsidian,80,minecraft:crying_obsidian,20)
RandomBlock(2,7,-4,minecraft:obsidian,80,minecraft:crying_obsidian,20)
RandomBlock(2,8,-4,minecraft:obsidian,80,minecraft:crying_obsidian,20)
RandomBlock(2,9,-4,minecraft:obsidian,80,minecraft:crying_obsidian,20)
RandomBlock(2,10,-4,minecraft:obsidian,80,minecraft:crying_obsidian,20)
RandomBlock(2,11,-4,minecraft:obsidian,80,minecraft:crying_obsidian,20)
RandomBlock(2,12,-4,minecraft:obsidian,80,minecraft:crying_obsidian,20)
RandomBlock(2,13,-4,minecraft:obsidian,80,minecraft:crying_obsidian,20)
RandomBlock(2,14,-4,minecraft:obsidian,80,minecraft:crying_obsidian,20)
RandomBlock(2,15,-4,minecraft:obsidian,80,minecraft:crying_obsidian,20)
RandomBlock(2,16,-4,minecraft:obsidian,80,minecraft:crying_obsidian,20)
RandomBlock(2,17,-4,minecraft:obsidian,80,minecraft:crying_obsidian,20)
RandomBlock(2,18,-4,minecraft:obsidian,80,minecraft:crying_obsidian,20)
RandomBlock(2,19,-4,minecraft:obsidian,80,minecraft:crying_obsidian,20)
RandomBlock(2,20,-4,minecraft:obsidian,80,minecraft:crying_obsidian,20)
RandomBlock(2,21,-4,minecraft:obsidian,80,minecraft:crying_obsidian,20)
RandomBlock(2,22,-4,minecraft:obsidian,80,minecraft:crying_obsidian,20)
RandomBlock(2,23,-4,minecraft:obsidian,80,minecraft:crying_obsidian,20)
RandomBlock(2,24,-4,minecraft:obsidian,80,minecraft:crying_obsidian,20)
RandomBlock(2,25,-4,minecraft:obsidian,80,minecraft:crying_obsidian,20)
RandomBlock(2,26,-4,minecraft:obsidian,80,minecraft:crying_obsidian,20)
RandomBlock(2,27,-4,minecraft:obsidian,80,minecraft:crying_obsidian,20)
RandomBlock(2,28,-4,minecraft:obsidian,80,minecraft:crying_obsidian,20)
RandomBlock(2,1,-3,minecraft:obsidian,80,minecraft:crying_obsidian,20)
RandomBlock(2,2,-3,minecraft:obsidian,80,minecraft:crying_obsidian,20)
RandomBlock(2,3,-3,minecraft:obsidian,80,minecraft:crying_obsidian,20)
RandomBlock(2,4,-3,minecraft:obsidian,80,minecraft:crying_obsidian,20)
RandomBlock(2,5,-3,minecraft:obsidian,80,minecraft:crying_obsidian,20)
RandomBlock(2,6,-3,minecraft:obsidian,80,minecraft:crying_obsidian,20)
RandomBlock(2,7,-3,minecraft:obsidian,80,minecraft:crying_obsidian,20)
RandomBlock(2,8,-3,minecraft:obsidian,80,minecraft:crying_obsidian,20)
RandomBlock(2,9,-3,minecraft:obsidian,80,minecraft:crying_obsidian,20)
RandomBlock(2,10,-3,minecraft:obsidian,80,minecraft:crying_obsidian,20)
RandomBlock(2,11,-3,minecraft:obsidian,80,minecraft:crying_obsidian,20)
RandomBlock(2,12,-3,minecraft:obsidian,80,minecraft:crying_obsidian,20)
RandomBlock(2,13,-3,minecraft:obsidian,80,minecraft:crying_obsidian,20)
RandomBlock(2,14,-3,minecraft:obsidian,80,minecraft:crying_obsidian,20)
RandomBlock(2,15,-3,minecraft:obsidian,80,minecraft:crying_obsidian,20)
RandomBlock(2,16,-3,minecraft:obsidian,80,minecraft:crying_obsidian,20)
RandomBlock(2,17,-3,minecraft:obsidian,80,minecraft:crying_obsidian,20)
RandomBlock(2,18,-3,minecraft:obsidian,80,minecraft:crying_obsidian,20)
RandomBlock(2,19,-3,minecraft:obsidian,80,minecraft:crying_obsidian,20)
RandomBlock(2,20,-3,minecraft:obsidian,80,minecraft:crying_obsidian,20)
RandomBlock(2,21,-3,minecraft:obsidian,80,minecraft:crying_obsidian,20)
RandomBlock(2,22,-3,minecraft:obsidian,80,minecraft:crying_obsidian,20)
RandomBlock(2,23,-3,minecraft:obsidian,80,minecraft:crying_obsidian,20)
RandomBlock(2,24,-3,minecraft:obsidian,80,minecraft:crying_obsidian,20)
RandomBlock(2,25,-3,minecraft:obsidian,80,minecraft:crying_obsidian,20)
RandomBlock(2,26,-3,minecraft:obsidian,80,minecraft:crying_obsidian,20)
RandomBlock(2,0,-2,minecraft:obsidian,80,minecraft:crying_obsidian,20)
RandomBlock(2,1,-2,minecraft:obsidian,80,minecraft:crying_obsidian,20)
RandomBlock(2,2,-2,minecraft:obsidian,80,minecraft:crying_obsidian,20)
RandomBlock(2,3,-2,minecraft:obsidian,80,minecraft:crying_obsidian,20)
RandomBlock(2,4,-2,minecraft:obsidian,80,minecraft:crying_obsidian,20)
RandomBlock(2,5,-2,minecraft:obsidian,80,minecraft:crying_obsidian,20)
RandomBlock(2,6,-2,minecraft:obsidian,80,minecraft:crying_obsidian,20)
RandomBlock(2,7,-2,minecraft:obsidian,80,minecraft:crying_obsidian,20)
RandomBlock(2,8,-2,minecraft:obsidian,80,minecraft:crying_obsidian,20)
RandomBlock(2,9,-2,minecraft:obsidian,80,minecraft:crying_obsidian,20)
RandomBlock(2,10,-2,minecraft:obsidian,80,minecraft:crying_obsidian,20)
RandomBlock(2,11,-2,minecraft:obsidian,80,minecraft:crying_obsidian,20)
RandomBlock(2,12,-2,minecraft:obsidian,80,minecraft:crying_obsidian,20)
RandomBlock(2,13,-2,minecraft:obsidian,80,minecraft:crying_obsidian,20)
RandomBlock(2,14,-2,minecraft:obsidian,80,minecraft:crying_obsidian,20)
RandomBlock(2,15,-2,minecraft:obsidian,80,minecraft:crying_obsidian,20)
RandomBlock(2,16,-2,minecraft:obsidian,80,minecraft:crying_obsidian,20)
RandomBlock(2,17,-2,minecraft:obsidian,80,minecraft:crying_obsidian,20)
RandomBlock(2,18,-2,minecraft:obsidian,80,minecraft:crying_obsidian,20)
RandomBlock(2,19,-2,minecraft:obsidian,80,minecraft:crying_obsidian,20)
RandomBlock(2,20,-2,minecraft:obsidian,80,minecraft:crying_obsidian,20)
RandomBlock(2,0,-1,minecraft:obsidian,80,minecraft:crying_obsidian,20)
RandomBlock(2,1,-1,minecraft:obsidian,80,minecraft:crying_obsidian,20)
RandomBlock(2,2,-1,minecraft:obsidian,80,minecraft:crying_obsidian,20)
RandomBlock(2,3,-1,minecraft:obsidian,80,minecraft:crying_obsidian,20)
RandomBlock(2,4,-1,minecraft:obsidian,80,minecraft:crying_obsidian,20)
RandomBlock(2,5,-1,minecraft:obsidian,80,minecraft:crying_obsidian,20)
RandomBlock(2,6,-1,minecraft:obsidian,80,minecraft:crying_obsidian,20)
RandomBlock(2,7,-1,minecraft:obsidian,80,minecraft:crying_obsidian,20)
RandomBlock(2,8,-1,minecraft:obsidian,80,minecraft:crying_obsidian,20)
RandomBlock(2,9,-1,minecraft:obsidian,80,minecraft:crying_obsidian,20)
RandomBlock(2,10,-1,minecraft:obsidian,80,minecraft:crying_obsidian,20)
RandomBlock(2,11,-1,minecraft:obsidian,80,minecraft:crying_obsidian,20)
RandomBlock(2,12,-1,minecraft:obsidian,80,minecraft:crying_obsidian,20)
RandomBlock(2,13,-1,minecraft:obsidian,80,minecraft:crying_obsidian,20)
RandomBlock(2,14,-1,minecraft:obsidian,80,minecraft:crying_obsidian,20)
RandomBlock(2,0,0,minecraft:obsidian,80,minecraft:crying_obsidian,20)
RandomBlock(2,1,0,minecraft:obsidian,80,minecraft:crying_obsidian,20)
RandomBlock(2,2,0,minecraft:obsidian,80,minecraft:crying_obsidian,20)
RandomBlock(2,3,0,minecraft:obsidian,80,minecraft:crying_obsidian,20)
RandomBlock(2,4,0,minecraft:obsidian,80,minecraft:crying_obsidian,20)
RandomBlock(2,5,0,minecraft:obsidian,80,minecraft:crying_obsidian,20)
RandomBlock(2,6,0,minecraft:obsidian,80,minecraft:crying_obsidian,20)
RandomBlock(2,7,0,minecraft:obsidian,80,minecraft:crying_obsidian,20)
RandomBlock(2,0,1,minecraft:obsidian,80,minecraft:crying_obsidian,20)
RandomBlock(2,1,1,minecraft:obsidian,80,minecraft:crying_obsidian,20)
RandomBlock(2,2,1,minecraft:obsidian,80,minecraft:crying_obsidian,20)
RandomBlock(2,3,1,minecraft:obsidian,80,minecraft:crying_obsidian,20)
RandomBlock(2,4,1,minecraft:obsidian,80,minecraft:crying_obsidian,20)
RandomBlock(2,5,1,minecraft:obsidian,80,minecraft:crying_obsidian,20)
RandomBlock(2,6,1,minecraft:obsidian,80,minecraft:crying_obsidian,20)
RandomBlock(2,7,1,minecraft:obsidian,80,minecraft:crying_obsidian,20)
RandomBlock(2,0,2,minecraft:obsidian,80,minecraft:crying_obsidian,20)
RandomBlock(2,1,2,minecraft:obsidian,80,minecraft:crying_obsidian,20)
RandomBlock(2,2,2,minecraft:obsidian,80,minecraft:crying_obsidian,20)
RandomBlock(2,3,2,minecraft:obsidian,80,minecraft:crying_obsidian,20)
RandomBlock(2,4,2,minecraft:obsidian,80,minecraft:crying_obsidian,20)
RandomBlock(2,5,2,minecraft:obsidian,80,minecraft:crying_obsidian,20)
RandomBlock(2,6,2,minecraft:obsidian,80,minecraft:crying_obsidian,20)
RandomBlock(2,0,3,minecraft:obsidian,80,minecraft:crying_obsidian,20)
RandomBlock(2,1,3,minecraft:obsidian,80,minecraft:crying_obsidian,20)
RandomBlock(2,2,3,minecraft:obsidian,80,minecraft:crying_obsidian,20)
RandomBlock(2,3,3,minecraft:obsidian,80,minecraft:crying_obsidian,20)
RandomBlock(2,4,3,minecraft:obsidian,80,minecraft:crying_obsidian,20)
RandomBlock(2,5,3,minecraft:obsidian,80,minecraft:crying_obsidian,20)
RandomBlock(2,6,3,minecraft:obsidian,80,minecraft:crying_obsidian,20)
RandomBlock(2,0,4,minecraft:obsidian,80,minecraft:crying_obsidian,20)
RandomBlock(3,0,-7,minecraft:obsidian,80,minecraft:crying_obsidian,20)
RandomBlock(3,1,-7,minecraft:obsidian,80,minecraft:crying_obsidian,20)
RandomBlock(3,2,-7,minecraft:obsidian,80,minecraft:crying_obsidian,20)
RandomBlock(3,3,-7,minecraft:obsidian,80,minecraft:crying_obsidian,20)
RandomBlock(3,4,-7,minecraft:obsidian,80,minecraft:crying_obsidian,20)
RandomBlock(3,5,-7,minecraft:obsidian,80,minecraft:crying_obsidian,20)
RandomBlock(3,6,-7,minecraft:obsidian,80,minecraft:crying_obsidian,20)
RandomBlock(3,7,-7,minecraft:obsidian,80,minecraft:crying_obsidian,20)
RandomBlock(3,8,-7,minecraft:obsidian,80,minecraft:crying_obsidian,20)
RandomBlock(3,9,-7,minecraft:obsidian,80,minecraft:crying_obsidian,20)
RandomBlock(3,10,-7,minecraft:obsidian,80,minecraft:crying_obsidian,20)
RandomBlock(3,11,-7,minecraft:obsidian,80,minecraft:crying_obsidian,20)
RandomBlock(3,12,-7,minecraft:obsidian,80,minecraft:crying_obsidian,20)
RandomBlock(3,13,-7,minecraft:obsidian,80,minecraft:crying_obsidian,20)
RandomBlock(3,14,-7,minecraft:obsidian,80,minecraft:crying_obsidian,20)
RandomBlock(3,15,-7,minecraft:obsidian,80,minecraft:crying_obsidian,20)
RandomBlock(3,16,-7,minecraft:obsidian,80,minecraft:crying_obsidian,20)
RandomBlock(3,17,-7,minecraft:obsidian,80,minecraft:crying_obsidian,20)
RandomBlock(3,18,-7,minecraft:obsidian,80,minecraft:crying_obsidian,20)
RandomBlock(3,19,-7,minecraft:obsidian,80,minecraft:crying_obsidian,20)
RandomBlock(3,20,-7,minecraft:obsidian,80,minecraft:crying_obsidian,20)
RandomBlock(3,21,-7,minecraft:obsidian,80,minecraft:crying_obsidian,20)
RandomBlock(3,22,-7,minecraft:obsidian,80,minecraft:crying_obsidian,20)
RandomBlock(3,23,-7,minecraft:obsidian,80,minecraft:crying_obsidian,20)
RandomBlock(3,24,-7,minecraft:obsidian,80,minecraft:crying_obsidian,20)
RandomBlock(3,25,-7,minecraft:obsidian,80,minecraft:crying_obsidian,20)
RandomBlock(3,26,-7,minecraft:obsidian,80,minecraft:crying_obsidian,20)
RandomBlock(3,0,-6,minecraft:obsidian,80,minecraft:crying_obsidian,20)
RandomBlock(3,1,-6,minecraft:obsidian,80,minecraft:crying_obsidian,20)
RandomBlock(3,2,-6,minecraft:obsidian,80,minecraft:crying_obsidian,20)
RandomBlock(3,3,-6,minecraft:obsidian,80,minecraft:crying_obsidian,20)
RandomBlock(3,4,-6,minecraft:obsidian,80,minecraft:crying_obsidian,20)
RandomBlock(3,5,-6,minecraft:obsidian,80,minecraft:crying_obsidian,20)
RandomBlock(3,6,-6,minecraft:obsidian,80,minecraft:crying_obsidian,20)
RandomBlock(3,7,-6,minecraft:obsidian,80,minecraft:crying_obsidian,20)
RandomBlock(3,8,-6,minecraft:obsidian,80,minecraft:crying_obsidian,20)
RandomBlock(3,9,-6,minecraft:obsidian,80,minecraft:crying_obsidian,20)
RandomBlock(3,10,-6,minecraft:obsidian,80,minecraft:crying_obsidian,20)
RandomBlock(3,11,-6,minecraft:obsidian,80,minecraft:crying_obsidian,20)
RandomBlock(3,12,-6,minecraft:obsidian,80,minecraft:crying_obsidian,20)
RandomBlock(3,13,-6,minecraft:obsidian,80,minecraft:crying_obsidian,20)
RandomBlock(3,14,-6,minecraft:obsidian,80,minecraft:crying_obsidian,20)
RandomBlock(3,15,-6,minecraft:obsidian,80,minecraft:crying_obsidian,20)
RandomBlock(3,16,-6,minecraft:obsidian,80,minecraft:crying_obsidian,20)
RandomBlock(3,17,-6,minecraft:obsidian,80,minecraft:crying_obsidian,20)
RandomBlock(3,18,-6,minecraft:obsidian,80,minecraft:crying_obsidian,20)
RandomBlock(3,19,-6,minecraft:obsidian,80,minecraft:crying_obsidian,20)
RandomBlock(3,20,-6,minecraft:obsidian,80,minecraft:crying_obsidian,20)
RandomBlock(3,21,-6,minecraft:obsidian,80,minecraft:crying_obsidian,20)
RandomBlock(3,22,-6,minecraft:obsidian,80,minecraft:crying_obsidian,20)
RandomBlock(3,23,-6,minecraft:obsidian,80,minecraft:crying_obsidian,20)
RandomBlock(3,24,-6,minecraft:obsidian,80,minecraft:crying_obsidian,20)
RandomBlock(3,25,-6,minecraft:obsidian,80,minecraft:crying_obsidian,20)
RandomBlock(3,26,-6,minecraft:obsidian,80,minecraft:crying_obsidian,20)
RandomBlock(3,27,-6,minecraft:obsidian,80,minecraft:crying_obsidian,20)
RandomBlock(3,28,-6,minecraft:obsidian,80,minecraft:crying_obsidian,20)
RandomBlock(3,29,-6,minecraft:obsidian,80,minecraft:crying_obsidian,20)
RandomBlock(3,30,-6,minecraft:obsidian,80,minecraft:crying_obsidian,20)
RandomBlock(3,0,-5,minecraft:obsidian,80,minecraft:crying_obsidian,20)
RandomBlock(3,1,-5,minecraft:obsidian,80,minecraft:crying_obsidian,20)
RandomBlock(3,3,-5,minecraft:obsidian,80,minecraft:crying_obsidian,20)
RandomBlock(3,4,-5,minecraft:obsidian,80,minecraft:crying_obsidian,20)
RandomBlock(3,5,-5,minecraft:obsidian,80,minecraft:crying_obsidian,20)
RandomBlock(3,6,-5,minecraft:obsidian,80,minecraft:crying_obsidian,20)
RandomBlock(3,7,-5,minecraft:obsidian,80,minecraft:crying_obsidian,20)
RandomBlock(3,8,-5,minecraft:obsidian,80,minecraft:crying_obsidian,20)
RandomBlock(3,9,-5,minecraft:obsidian,80,minecraft:crying_obsidian,20)
RandomBlock(3,10,-5,minecraft:obsidian,80,minecraft:crying_obsidian,20)
RandomBlock(3,11,-5,minecraft:obsidian,80,minecraft:crying_obsidian,20)
RandomBlock(3,12,-5,minecraft:obsidian,80,minecraft:crying_obsidian,20)
RandomBlock(3,13,-5,minecraft:obsidian,80,minecraft:crying_obsidian,20)
RandomBlock(3,14,-5,minecraft:obsidian,80,minecraft:crying_obsidian,20)
RandomBlock(3,15,-5,minecraft:obsidian,80,minecraft:crying_obsidian,20)
RandomBlock(3,16,-5,minecraft:obsidian,80,minecraft:crying_obsidian,20)
RandomBlock(3,17,-5,minecraft:obsidian,80,minecraft:crying_obsidian,20)
RandomBlock(3,18,-5,minecraft:obsidian,80,minecraft:crying_obsidian,20)
RandomBlock(3,19,-5,minecraft:obsidian,80,minecraft:crying_obsidian,20)
RandomBlock(3,20,-5,minecraft:obsidian,80,minecraft:crying_obsidian,20)
RandomBlock(3,21,-5,minecraft:obsidian,80,minecraft:crying_obsidian,20)
RandomBlock(3,22,-5,minecraft:obsidian,80,minecraft:crying_obsidian,20)
RandomBlock(3,23,-5,minecraft:obsidian,80,minecraft:crying_obsidian,20)
RandomBlock(3,24,-5,minecraft:obsidian,80,minecraft:crying_obsidian,20)
RandomBlock(3,25,-5,minecraft:obsidian,80,minecraft:crying_obsidian,20)
RandomBlock(3,26,-5,minecraft:obsidian,80,minecraft:crying_obsidian,20)
RandomBlock(3,27,-5,minecraft:obsidian,80,minecraft:crying_obsidian,20)
RandomBlock(3,28,-5,minecraft:obsidian,80,minecraft:crying_obsidian,20)
RandomBlock(3,29,-5,minecraft:obsidian,80,minecraft:crying_obsidian,20)
RandomBlock(3,30,-5,minecraft:obsidian,80,minecraft:crying_obsidian,20)
RandomBlock(3,31,-5,minecraft:obsidian,80,minecraft:crying_obsidian,20)
RandomBlock(3,32,-5,minecraft:obsidian,80,minecraft:crying_obsidian,20)
RandomBlock(3,33,-5,minecraft:obsidian,80,minecraft:crying_obsidian,20)
RandomBlock(3,34,-5,minecraft:obsidian,80,minecraft:crying_obsidian,20)
RandomBlock(3,5,-4,minecraft:obsidian,80,minecraft:crying_obsidian,20)
RandomBlock(3,6,-4,minecraft:obsidian,80,minecraft:crying_obsidian,20)
RandomBlock(3,7,-4,minecraft:obsidian,80,minecraft:crying_obsidian,20)
RandomBlock(3,8,-4,minecraft:obsidian,80,minecraft:crying_obsidian,20)
RandomBlock(3,9,-4,minecraft:obsidian,80,minecraft:crying_obsidian,20)
RandomBlock(3,10,-4,minecraft:obsidian,80,minecraft:crying_obsidian,20)
RandomBlock(3,11,-4,minecraft:obsidian,80,minecraft:crying_obsidian,20)
RandomBlock(3,12,-4,minecraft:obsidian,80,minecraft:crying_obsidian,20)
RandomBlock(3,13,-4,minecraft:obsidian,80,minecraft:crying_obsidian,20)
RandomBlock(3,14,-4,minecraft:obsidian,80,minecraft:crying_obsidian,20)
RandomBlock(3,15,-4,minecraft:obsidian,80,minecraft:crying_obsidian,20)
RandomBlock(3,16,-4,minecraft:obsidian,80,minecraft:crying_obsidian,20)
RandomBlock(3,17,-4,minecraft:obsidian,80,minecraft:crying_obsidian,20)
RandomBlock(3,18,-4,minecraft:obsidian,80,minecraft:crying_obsidian,20)
RandomBlock(3,19,-4,minecraft:obsidian,80,minecraft:crying_obsidian,20)
RandomBlock(3,20,-4,minecraft:obsidian,80,minecraft:crying_obsidian,20)
RandomBlock(3,21,-4,minecraft:obsidian,80,minecraft:crying_obsidian,20)
RandomBlock(3,22,-4,minecraft:obsidian,80,minecraft:crying_obsidian,20)
RandomBlock(3,23,-4,minecraft:obsidian,80,minecraft:crying_obsidian,20)
RandomBlock(3,24,-4,minecraft:obsidian,80,minecraft:crying_obsidian,20)
RandomBlock(3,25,-4,minecraft:obsidian,80,minecraft:crying_obsidian,20)
RandomBlock(3,26,-4,minecraft:obsidian,80,minecraft:crying_obsidian,20)
RandomBlock(3,27,-4,minecraft:obsidian,80,minecraft:crying_obsidian,20)
RandomBlock(3,28,-4,minecraft:obsidian,80,minecraft:crying_obsidian,20)
RandomBlock(3,29,-4,minecraft:obsidian,80,minecraft:crying_obsidian,20)
RandomBlock(3,30,-4,minecraft:obsidian,80,minecraft:crying_obsidian,20)
RandomBlock(3,31,-4,minecraft:obsidian,80,minecraft:crying_obsidian,20)
RandomBlock(3,32,-4,minecraft:obsidian,80,minecraft:crying_obsidian,20)
RandomBlock(3,33,-4,minecraft:obsidian,80,minecraft:crying_obsidian,20)
RandomBlock(3,34,-4,minecraft:obsidian,80,minecraft:crying_obsidian,20)
RandomBlock(3,0,-3,minecraft:obsidian,80,minecraft:crying_obsidian,20)
RandomBlock(3,1,-3,minecraft:obsidian,80,minecraft:crying_obsidian,20)
RandomBlock(3,2,-3,minecraft:obsidian,80,minecraft:crying_obsidian,20)
RandomBlock(3,3,-3,minecraft:obsidian,80,minecraft:crying_obsidian,20)
RandomBlock(3,4,-3,minecraft:obsidian,80,minecraft:crying_obsidian,20)
RandomBlock(3,5,-3,minecraft:obsidian,80,minecraft:crying_obsidian,20)
RandomBlock(3,6,-3,minecraft:obsidian,80,minecraft:crying_obsidian,20)
RandomBlock(3,7,-3,minecraft:obsidian,80,minecraft:crying_obsidian,20)
RandomBlock(3,8,-3,minecraft:obsidian,80,minecraft:crying_obsidian,20)
RandomBlock(3,9,-3,minecraft:obsidian,80,minecraft:crying_obsidian,20)
RandomBlock(3,10,-3,minecraft:obsidian,80,minecraft:crying_obsidian,20)
RandomBlock(3,11,-3,minecraft:obsidian,80,minecraft:crying_obsidian,20)
RandomBlock(3,12,-3,minecraft:obsidian,80,minecraft:crying_obsidian,20)
RandomBlock(3,13,-3,minecraft:obsidian,80,minecraft:crying_obsidian,20)
RandomBlock(3,14,-3,minecraft:obsidian,80,minecraft:crying_obsidian,20)
RandomBlock(3,15,-3,minecraft:obsidian,80,minecraft:crying_obsidian,20)
RandomBlock(3,16,-3,minecraft:obsidian,80,minecraft:crying_obsidian,20)
RandomBlock(3,17,-3,minecraft:obsidian,80,minecraft:crying_obsidian,20)
RandomBlock(3,18,-3,minecraft:obsidian,80,minecraft:crying_obsidian,20)
RandomBlock(3,19,-3,minecraft:obsidian,80,minecraft:crying_obsidian,20)
RandomBlock(3,20,-3,minecraft:obsidian,80,minecraft:crying_obsidian,20)
RandomBlock(3,21,-3,minecraft:obsidian,80,minecraft:crying_obsidian,20)
RandomBlock(3,22,-3,minecraft:obsidian,80,minecraft:crying_obsidian,20)
RandomBlock(3,23,-3,minecraft:obsidian,80,minecraft:crying_obsidian,20)
RandomBlock(3,24,-3,minecraft:obsidian,80,minecraft:crying_obsidian,20)
RandomBlock(3,25,-3,minecraft:obsidian,80,minecraft:crying_obsidian,20)
RandomBlock(3,26,-3,minecraft:obsidian,80,minecraft:crying_obsidian,20)
RandomBlock(3,27,-3,minecraft:obsidian,80,minecraft:crying_obsidian,20)
RandomBlock(3,28,-3,minecraft:obsidian,80,minecraft:crying_obsidian,20)
RandomBlock(3,29,-3,minecraft:obsidian,80,minecraft:crying_obsidian,20)
RandomBlock(3,30,-3,minecraft:obsidian,80,minecraft:crying_obsidian,20)
RandomBlock(3,31,-3,minecraft:obsidian,80,minecraft:crying_obsidian,20)
RandomBlock(3,0,-2,minecraft:obsidian,80,minecraft:crying_obsidian,20)
RandomBlock(3,1,-2,minecraft:obsidian,80,minecraft:crying_obsidian,20)
RandomBlock(3,2,-2,minecraft:obsidian,80,minecraft:crying_obsidian,20)
RandomBlock(3,3,-2,minecraft:obsidian,80,minecraft:crying_obsidian,20)
RandomBlock(3,4,-2,minecraft:obsidian,80,minecraft:crying_obsidian,20)
RandomBlock(3,5,-2,minecraft:obsidian,80,minecraft:crying_obsidian,20)
RandomBlock(3,6,-2,minecraft:obsidian,80,minecraft:crying_obsidian,20)
RandomBlock(3,7,-2,minecraft:obsidian,80,minecraft:crying_obsidian,20)
RandomBlock(3,8,-2,minecraft:obsidian,80,minecraft:crying_obsidian,20)
RandomBlock(3,9,-2,minecraft:obsidian,80,minecraft:crying_obsidian,20)
RandomBlock(3,10,-2,minecraft:obsidian,80,minecraft:crying_obsidian,20)
RandomBlock(3,11,-2,minecraft:obsidian,80,minecraft:crying_obsidian,20)
RandomBlock(3,12,-2,minecraft:obsidian,80,minecraft:crying_obsidian,20)
RandomBlock(3,13,-2,minecraft:obsidian,80,minecraft:crying_obsidian,20)
RandomBlock(3,14,-2,minecraft:obsidian,80,minecraft:crying_obsidian,20)
RandomBlock(3,15,-2,minecraft:obsidian,80,minecraft:crying_obsidian,20)
RandomBlock(3,16,-2,minecraft:obsidian,80,minecraft:crying_obsidian,20)
RandomBlock(3,17,-2,minecraft:obsidian,80,minecraft:crying_obsidian,20)
RandomBlock(3,18,-2,minecraft:obsidian,80,minecraft:crying_obsidian,20)
RandomBlock(3,19,-2,minecraft:obsidian,80,minecraft:crying_obsidian,20)
RandomBlock(3,20,-2,minecraft:obsidian,80,minecraft:crying_obsidian,20)
RandomBlock(3,21,-2,minecraft:obsidian,80,minecraft:crying_obsidian,20)
RandomBlock(3,22,-2,minecraft:obsidian,80,minecraft:crying_obsidian,20)
RandomBlock(3,23,-2,minecraft:obsidian,80,minecraft:crying_obsidian,20)
RandomBlock(3,24,-2,minecraft:obsidian,80,minecraft:crying_obsidian,20)
RandomBlock(3,25,-2,minecraft:obsidian,80,minecraft:crying_obsidian,20)
RandomBlock(3,26,-2,minecraft:obsidian,80,minecraft:crying_obsidian,20)
RandomBlock(3,27,-2,minecraft:obsidian,80,minecraft:crying_obsidian,20)
RandomBlock(3,28,-2,minecraft:obsidian,80,minecraft:crying_obsidian,20)
RandomBlock(3,0,-1,minecraft:obsidian,80,minecraft:crying_obsidian,20)
RandomBlock(3,1,-1,minecraft:obsidian,80,minecraft:crying_obsidian,20)
RandomBlock(3,2,-1,minecraft:obsidian,80,minecraft:crying_obsidian,20)
RandomBlock(3,3,-1,minecraft:obsidian,80,minecraft:crying_obsidian,20)
RandomBlock(3,4,-1,minecraft:obsidian,80,minecraft:crying_obsidian,20)
RandomBlock(3,5,-1,minecraft:obsidian,80,minecraft:crying_obsidian,20)
RandomBlock(3,6,-1,minecraft:obsidian,80,minecraft:crying_obsidian,20)
RandomBlock(3,7,-1,minecraft:obsidian,80,minecraft:crying_obsidian,20)
RandomBlock(3,8,-1,minecraft:obsidian,80,minecraft:crying_obsidian,20)
RandomBlock(3,9,-1,minecraft:obsidian,80,minecraft:crying_obsidian,20)
RandomBlock(3,10,-1,minecraft:obsidian,80,minecraft:crying_obsidian,20)
RandomBlock(3,11,-1,minecraft:obsidian,80,minecraft:crying_obsidian,20)
RandomBlock(3,12,-1,minecraft:obsidian,80,minecraft:crying_obsidian,20)
RandomBlock(3,13,-1,minecraft:obsidian,80,minecraft:crying_obsidian,20)
RandomBlock(3,14,-1,minecraft:obsidian,80,minecraft:crying_obsidian,20)
RandomBlock(3,15,-1,minecraft:obsidian,80,minecraft:crying_obsidian,20)
RandomBlock(3,16,-1,minecraft:obsidian,80,minecraft:crying_obsidian,20)
RandomBlock(3,17,-1,minecraft:obsidian,80,minecraft:crying_obsidian,20)
RandomBlock(3,18,-1,minecraft:obsidian,80,minecraft:crying_obsidian,20)
RandomBlock(3,19,-1,minecraft:obsidian,80,minecraft:crying_obsidian,20)
RandomBlock(3,20,-1,minecraft:obsidian,80,minecraft:crying_obsidian,20)
RandomBlock(3,21,-1,minecraft:obsidian,80,minecraft:crying_obsidian,20)
RandomBlock(3,0,0,minecraft:obsidian,80,minecraft:crying_obsidian,20)
RandomBlock(3,1,0,minecraft:obsidian,80,minecraft:crying_obsidian,20)
RandomBlock(3,2,0,minecraft:obsidian,80,minecraft:crying_obsidian,20)
RandomBlock(3,3,0,minecraft:obsidian,80,minecraft:crying_obsidian,20)
RandomBlock(3,4,0,minecraft:obsidian,80,minecraft:crying_obsidian,20)
RandomBlock(3,5,0,minecraft:obsidian,80,minecraft:crying_obsidian,20)
RandomBlock(3,6,0,minecraft:obsidian,80,minecraft:crying_obsidian,20)
RandomBlock(3,7,0,minecraft:obsidian,80,minecraft:crying_obsidian,20)
RandomBlock(3,8,0,minecraft:obsidian,80,minecraft:crying_obsidian,20)
RandomBlock(3,9,0,minecraft:obsidian,80,minecraft:crying_obsidian,20)
RandomBlock(3,10,0,minecraft:obsidian,80,minecraft:crying_obsidian,20)
RandomBlock(3,11,0,minecraft:obsidian,80,minecraft:crying_obsidian,20)
RandomBlock(3,12,0,minecraft:obsidian,80,minecraft:crying_obsidian,20)
RandomBlock(3,13,0,minecraft:obsidian,80,minecraft:crying_obsidian,20)
RandomBlock(3,14,0,minecraft:obsidian,80,minecraft:crying_obsidian,20)
RandomBlock(3,15,0,minecraft:obsidian,80,minecraft:crying_obsidian,20)
RandomBlock(3,16,0,minecraft:obsidian,80,minecraft:crying_obsidian,20)
RandomBlock(3,17,0,minecraft:obsidian,80,minecraft:crying_obsidian,20)
RandomBlock(3,0,1,minecraft:obsidian,80,minecraft:crying_obsidian,20)
RandomBlock(3,1,1,minecraft:obsidian,80,minecraft:crying_obsidian,20)
RandomBlock(3,2,1,minecraft:obsidian,80,minecraft:crying_obsidian,20)
RandomBlock(3,3,1,minecraft:obsidian,80,minecraft:crying_obsidian,20)
RandomBlock(3,4,1,minecraft:obsidian,80,minecraft:crying_obsidian,20)
RandomBlock(3,5,1,minecraft:obsidian,80,minecraft:crying_obsidian,20)
RandomBlock(3,6,1,minecraft:obsidian,80,minecraft:crying_obsidian,20)
RandomBlock(3,7,1,minecraft:obsidian,80,minecraft:crying_obsidian,20)
RandomBlock(3,8,1,minecraft:obsidian,80,minecraft:crying_obsidian,20)
RandomBlock(3,9,1,minecraft:obsidian,80,minecraft:crying_obsidian,20)
RandomBlock(3,0,2,minecraft:obsidian,80,minecraft:crying_obsidian,20)
RandomBlock(3,1,2,minecraft:obsidian,80,minecraft:crying_obsidian,20)
RandomBlock(3,2,2,minecraft:obsidian,80,minecraft:crying_obsidian,20)
RandomBlock(3,3,2,minecraft:obsidian,80,minecraft:crying_obsidian,20)
RandomBlock(3,4,2,minecraft:obsidian,80,minecraft:crying_obsidian,20)
RandomBlock(3,5,2,minecraft:obsidian,80,minecraft:crying_obsidian,20)
RandomBlock(3,6,2,minecraft:obsidian,80,minecraft:crying_obsidian,20)
RandomBlock(3,7,2,minecraft:obsidian,80,minecraft:crying_obsidian,20)
RandomBlock(3,8,2,minecraft:obsidian,80,minecraft:crying_obsidian,20)
RandomBlock(3,0,3,minecraft:obsidian,80,minecraft:crying_obsidian,20)
RandomBlock(3,1,3,minecraft:obsidian,80,minecraft:crying_obsidian,20)
RandomBlock(3,2,3,minecraft:obsidian,80,minecraft:crying_obsidian,20)
RandomBlock(3,3,3,minecraft:obsidian,80,minecraft:crying_obsidian,20)
RandomBlock(3,4,3,minecraft:obsidian,80,minecraft:crying_obsidian,20)
RandomBlock(3,5,3,minecraft:obsidian,80,minecraft:crying_obsidian,20)
RandomBlock(3,6,3,minecraft:obsidian,80,minecraft:crying_obsidian,20)
RandomBlock(3,7,3,minecraft:obsidian,80,minecraft:crying_obsidian,20)
RandomBlock(3,0,4,minecraft:obsidian,80,minecraft:crying_obsidian,20)
RandomBlock(3,1,4,minecraft:obsidian,80,minecraft:crying_obsidian,20)
RandomBlock(3,2,4,minecraft:obsidian,80,minecraft:crying_obsidian,20)
RandomBlock(3,0,5,minecraft:obsidian,80,minecraft:crying_obsidian,20)
RandomBlock(3,1,5,minecraft:obsidian,80,minecraft:crying_obsidian,20)
RandomBlock(3,0,6,minecraft:obsidian,80,minecraft:crying_obsidian,20)
RandomBlock(4,0,-7,minecraft:obsidian,80,minecraft:crying_obsidian,20)
RandomBlock(4,1,-7,minecraft:obsidian,80,minecraft:crying_obsidian,20)
RandomBlock(4,2,-7,minecraft:obsidian,80,minecraft:crying_obsidian,20)
RandomBlock(4,3,-7,minecraft:obsidian,80,minecraft:crying_obsidian,20)
RandomBlock(4,4,-7,minecraft:obsidian,80,minecraft:crying_obsidian,20)
RandomBlock(4,5,-7,minecraft:obsidian,80,minecraft:crying_obsidian,20)
RandomBlock(4,6,-7,minecraft:obsidian,80,minecraft:crying_obsidian,20)
RandomBlock(4,7,-7,minecraft:obsidian,80,minecraft:crying_obsidian,20)
RandomBlock(4,8,-7,minecraft:obsidian,80,minecraft:crying_obsidian,20)
RandomBlock(4,9,-7,minecraft:obsidian,80,minecraft:crying_obsidian,20)
RandomBlock(4,10,-7,minecraft:obsidian,80,minecraft:crying_obsidian,20)
RandomBlock(4,11,-7,minecraft:obsidian,80,minecraft:crying_obsidian,20)
RandomBlock(4,12,-7,minecraft:obsidian,80,minecraft:crying_obsidian,20)
RandomBlock(4,13,-7,minecraft:obsidian,80,minecraft:crying_obsidian,20)
RandomBlock(4,14,-7,minecraft:obsidian,80,minecraft:crying_obsidian,20)
RandomBlock(4,15,-7,minecraft:obsidian,80,minecraft:crying_obsidian,20)
RandomBlock(4,16,-7,minecraft:obsidian,80,minecraft:crying_obsidian,20)
RandomBlock(4,17,-7,minecraft:obsidian,80,minecraft:crying_obsidian,20)
RandomBlock(4,18,-7,minecraft:obsidian,80,minecraft:crying_obsidian,20)
RandomBlock(4,19,-7,minecraft:obsidian,80,minecraft:crying_obsidian,20)
RandomBlock(4,20,-7,minecraft:obsidian,80,minecraft:crying_obsidian,20)
RandomBlock(4,21,-7,minecraft:obsidian,80,minecraft:crying_obsidian,20)
RandomBlock(4,22,-7,minecraft:obsidian,80,minecraft:crying_obsidian,20)
RandomBlock(4,23,-7,minecraft:obsidian,80,minecraft:crying_obsidian,20)
RandomBlock(4,24,-7,minecraft:obsidian,80,minecraft:crying_obsidian,20)
RandomBlock(4,25,-7,minecraft:obsidian,80,minecraft:crying_obsidian,20)
RandomBlock(4,26,-7,minecraft:obsidian,80,minecraft:crying_obsidian,20)
RandomBlock(4,27,-7,minecraft:obsidian,80,minecraft:crying_obsidian,20)
RandomBlock(4,28,-7,minecraft:obsidian,80,minecraft:crying_obsidian,20)
RandomBlock(4,29,-7,minecraft:obsidian,80,minecraft:crying_obsidian,20)
RandomBlock(4,0,-6,minecraft:obsidian,80,minecraft:crying_obsidian,20)
RandomBlock(4,1,-6,minecraft:obsidian,80,minecraft:crying_obsidian,20)
RandomBlock(4,4,-6,minecraft:obsidian,80,minecraft:crying_obsidian,20)
RandomBlock(4,5,-6,minecraft:obsidian,80,minecraft:crying_obsidian,20)
RandomBlock(4,6,-6,minecraft:obsidian,80,minecraft:crying_obsidian,20)
RandomBlock(4,7,-6,minecraft:obsidian,80,minecraft:crying_obsidian,20)
RandomBlock(4,8,-6,minecraft:obsidian,80,minecraft:crying_obsidian,20)
RandomBlock(4,9,-6,minecraft:obsidian,80,minecraft:crying_obsidian,20)
RandomBlock(4,10,-6,minecraft:obsidian,80,minecraft:crying_obsidian,20)
RandomBlock(4,11,-6,minecraft:obsidian,80,minecraft:crying_obsidian,20)
RandomBlock(4,12,-6,minecraft:obsidian,80,minecraft:crying_obsidian,20)
RandomBlock(4,13,-6,minecraft:obsidian,80,minecraft:crying_obsidian,20)
RandomBlock(4,14,-6,minecraft:obsidian,80,minecraft:crying_obsidian,20)
RandomBlock(4,15,-6,minecraft:obsidian,80,minecraft:crying_obsidian,20)
RandomBlock(4,16,-6,minecraft:obsidian,80,minecraft:crying_obsidian,20)
RandomBlock(4,17,-6,minecraft:obsidian,80,minecraft:crying_obsidian,20)
RandomBlock(4,18,-6,minecraft:obsidian,80,minecraft:crying_obsidian,20)
RandomBlock(4,19,-6,minecraft:obsidian,80,minecraft:crying_obsidian,20)
RandomBlock(4,20,-6,minecraft:obsidian,80,minecraft:crying_obsidian,20)
RandomBlock(4,21,-6,minecraft:obsidian,80,minecraft:crying_obsidian,20)
RandomBlock(4,22,-6,minecraft:obsidian,80,minecraft:crying_obsidian,20)
RandomBlock(4,23,-6,minecraft:obsidian,80,minecraft:crying_obsidian,20)
RandomBlock(4,24,-6,minecraft:obsidian,80,minecraft:crying_obsidian,20)
RandomBlock(4,25,-6,minecraft:obsidian,80,minecraft:crying_obsidian,20)
RandomBlock(4,26,-6,minecraft:obsidian,80,minecraft:crying_obsidian,20)
RandomBlock(4,27,-6,minecraft:obsidian,80,minecraft:crying_obsidian,20)
RandomBlock(4,28,-6,minecraft:obsidian,80,minecraft:crying_obsidian,20)
RandomBlock(4,29,-6,minecraft:obsidian,80,minecraft:crying_obsidian,20)
RandomBlock(4,30,-6,minecraft:obsidian,80,minecraft:crying_obsidian,20)
RandomBlock(4,31,-6,minecraft:obsidian,80,minecraft:crying_obsidian,20)
RandomBlock(4,32,-6,minecraft:obsidian,80,minecraft:crying_obsidian,20)
RandomBlock(4,33,-6,minecraft:obsidian,80,minecraft:crying_obsidian,20)
RandomBlock(4,34,-6,minecraft:obsidian,80,minecraft:crying_obsidian,20)
RandomBlock(4,35,-6,minecraft:obsidian,80,minecraft:crying_obsidian,20)
RandomBlock(4,0,-5,minecraft:obsidian,80,minecraft:crying_obsidian,20)
RandomBlock(4,1,-5,minecraft:obsidian,80,minecraft:crying_obsidian,20)
RandomBlock(4,3,-5,minecraft:obsidian,80,minecraft:crying_obsidian,20)
RandomBlock(4,4,-5,minecraft:obsidian,80,minecraft:crying_obsidian,20)
RandomBlock(4,5,-5,minecraft:obsidian,80,minecraft:crying_obsidian,20)
RandomBlock(4,6,-5,minecraft:obsidian,80,minecraft:crying_obsidian,20)
RandomBlock(4,7,-5,minecraft:obsidian,80,minecraft:crying_obsidian,20)
RandomBlock(4,8,-5,minecraft:obsidian,80,minecraft:crying_obsidian,20)
RandomBlock(4,9,-5,minecraft:obsidian,80,minecraft:crying_obsidian,20)
RandomBlock(4,10,-5,minecraft:obsidian,80,minecraft:crying_obsidian,20)
RandomBlock(4,11,-5,minecraft:obsidian,80,minecraft:crying_obsidian,20)
RandomBlock(4,12,-5,minecraft:obsidian,80,minecraft:crying_obsidian,20)
RandomBlock(4,13,-5,minecraft:obsidian,80,minecraft:crying_obsidian,20)
RandomBlock(4,14,-5,minecraft:obsidian,80,minecraft:crying_obsidian,20)
RandomBlock(4,15,-5,minecraft:obsidian,80,minecraft:crying_obsidian,20)
RandomBlock(4,16,-5,minecraft:obsidian,80,minecraft:crying_obsidian,20)
RandomBlock(4,17,-5,minecraft:obsidian,80,minecraft:crying_obsidian,20)
RandomBlock(4,18,-5,minecraft:obsidian,80,minecraft:crying_obsidian,20)
RandomBlock(4,19,-5,minecraft:obsidian,80,minecraft:crying_obsidian,20)
RandomBlock(4,20,-5,minecraft:obsidian,80,minecraft:crying_obsidian,20)
RandomBlock(4,21,-5,minecraft:obsidian,80,minecraft:crying_obsidian,20)
RandomBlock(4,22,-5,minecraft:obsidian,80,minecraft:crying_obsidian,20)
RandomBlock(4,23,-5,minecraft:obsidian,80,minecraft:crying_obsidian,20)
RandomBlock(4,24,-5,minecraft:obsidian,80,minecraft:crying_obsidian,20)
RandomBlock(4,25,-5,minecraft:obsidian,80,minecraft:crying_obsidian,20)
RandomBlock(4,26,-5,minecraft:obsidian,80,minecraft:crying_obsidian,20)
RandomBlock(4,27,-5,minecraft:obsidian,80,minecraft:crying_obsidian,20)
RandomBlock(4,28,-5,minecraft:obsidian,80,minecraft:crying_obsidian,20)
RandomBlock(4,29,-5,minecraft:obsidian,80,minecraft:crying_obsidian,20)
RandomBlock(4,30,-5,minecraft:obsidian,80,minecraft:crying_obsidian,20)
RandomBlock(4,31,-5,minecraft:obsidian,80,minecraft:crying_obsidian,20)
RandomBlock(4,32,-5,minecraft:obsidian,80,minecraft:crying_obsidian,20)
RandomBlock(4,33,-5,minecraft:obsidian,80,minecraft:crying_obsidian,20)
RandomBlock(4,34,-5,minecraft:obsidian,80,minecraft:crying_obsidian,20)
RandomBlock(4,35,-5,minecraft:obsidian,80,minecraft:crying_obsidian,20)
RandomBlock(4,36,-5,minecraft:obsidian,80,minecraft:crying_obsidian,20)
RandomBlock(4,37,-5,minecraft:obsidian,80,minecraft:crying_obsidian,20)
RandomBlock(4,0,-4,minecraft:obsidian,80,minecraft:crying_obsidian,20)
RandomBlock(4,1,-4,minecraft:obsidian,80,minecraft:crying_obsidian,20)
RandomBlock(4,2,-4,minecraft:obsidian,80,minecraft:crying_obsidian,20)
RandomBlock(4,3,-4,minecraft:obsidian,80,minecraft:crying_obsidian,20)
RandomBlock(4,4,-4,minecraft:obsidian,80,minecraft:crying_obsidian,20)
RandomBlock(4,5,-4,minecraft:obsidian,80,minecraft:crying_obsidian,20)
RandomBlock(4,6,-4,minecraft:obsidian,80,minecraft:crying_obsidian,20)
RandomBlock(4,7,-4,minecraft:obsidian,80,minecraft:crying_obsidian,20)
RandomBlock(4,8,-4,minecraft:obsidian,80,minecraft:crying_obsidian,20)
RandomBlock(4,9,-4,minecraft:obsidian,80,minecraft:crying_obsidian,20)
RandomBlock(4,10,-4,minecraft:obsidian,80,minecraft:crying_obsidian,20)
RandomBlock(4,11,-4,minecraft:obsidian,80,minecraft:crying_obsidian,20)
RandomBlock(4,12,-4,minecraft:obsidian,80,minecraft:crying_obsidian,20)
RandomBlock(4,13,-4,minecraft:obsidian,80,minecraft:crying_obsidian,20)
RandomBlock(4,14,-4,minecraft:obsidian,80,minecraft:crying_obsidian,20)
RandomBlock(4,15,-4,minecraft:obsidian,80,minecraft:crying_obsidian,20)
RandomBlock(4,16,-4,minecraft:obsidian,80,minecraft:crying_obsidian,20)
RandomBlock(4,17,-4,minecraft:obsidian,80,minecraft:crying_obsidian,20)
RandomBlock(4,18,-4,minecraft:obsidian,80,minecraft:crying_obsidian,20)
RandomBlock(4,19,-4,minecraft:obsidian,80,minecraft:crying_obsidian,20)
RandomBlock(4,20,-4,minecraft:obsidian,80,minecraft:crying_obsidian,20)
RandomBlock(4,21,-4,minecraft:obsidian,80,minecraft:crying_obsidian,20)
RandomBlock(4,22,-4,minecraft:obsidian,80,minecraft:crying_obsidian,20)
RandomBlock(4,23,-4,minecraft:obsidian,80,minecraft:crying_obsidian,20)
RandomBlock(4,24,-4,minecraft:obsidian,80,minecraft:crying_obsidian,20)
RandomBlock(4,25,-4,minecraft:obsidian,80,minecraft:crying_obsidian,20)
RandomBlock(4,26,-4,minecraft:obsidian,80,minecraft:crying_obsidian,20)
RandomBlock(4,27,-4,minecraft:obsidian,80,minecraft:crying_obsidian,20)
RandomBlock(4,28,-4,minecraft:obsidian,80,minecraft:crying_obsidian,20)
RandomBlock(4,29,-4,minecraft:obsidian,80,minecraft:crying_obsidian,20)
RandomBlock(4,30,-4,minecraft:obsidian,80,minecraft:crying_obsidian,20)
RandomBlock(4,31,-4,minecraft:obsidian,80,minecraft:crying_obsidian,20)
RandomBlock(4,32,-4,minecraft:obsidian,80,minecraft:crying_obsidian,20)
RandomBlock(4,33,-4,minecraft:obsidian,80,minecraft:crying_obsidian,20)
RandomBlock(4,34,-4,minecraft:obsidian,80,minecraft:crying_obsidian,20)
RandomBlock(4,35,-4,minecraft:obsidian,80,minecraft:crying_obsidian,20)
RandomBlock(4,36,-4,minecraft:obsidian,80,minecraft:crying_obsidian,20)
RandomBlock(4,37,-4,minecraft:obsidian,80,minecraft:crying_obsidian,20)
RandomBlock(4,0,-3,minecraft:obsidian,80,minecraft:crying_obsidian,20)
RandomBlock(4,1,-3,minecraft:obsidian,80,minecraft:crying_obsidian,20)
RandomBlock(4,2,-3,minecraft:obsidian,80,minecraft:crying_obsidian,20)
RandomBlock(4,3,-3,minecraft:obsidian,80,minecraft:crying_obsidian,20)
RandomBlock(4,4,-3,minecraft:obsidian,80,minecraft:crying_obsidian,20)
RandomBlock(4,5,-3,minecraft:obsidian,80,minecraft:crying_obsidian,20)
RandomBlock(4,6,-3,minecraft:obsidian,80,minecraft:crying_obsidian,20)
RandomBlock(4,7,-3,minecraft:obsidian,80,minecraft:crying_obsidian,20)
RandomBlock(4,8,-3,minecraft:obsidian,80,minecraft:crying_obsidian,20)
RandomBlock(4,9,-3,minecraft:obsidian,80,minecraft:crying_obsidian,20)
RandomBlock(4,10,-3,minecraft:obsidian,80,minecraft:crying_obsidian,20)
RandomBlock(4,11,-3,minecraft:obsidian,80,minecraft:crying_obsidian,20)
RandomBlock(4,12,-3,minecraft:obsidian,80,minecraft:crying_obsidian,20)
RandomBlock(4,13,-3,minecraft:obsidian,80,minecraft:crying_obsidian,20)
RandomBlock(4,14,-3,minecraft:obsidian,80,minecraft:crying_obsidian,20)
RandomBlock(4,15,-3,minecraft:obsidian,80,minecraft:crying_obsidian,20)
RandomBlock(4,16,-3,minecraft:obsidian,80,minecraft:crying_obsidian,20)
RandomBlock(4,17,-3,minecraft:obsidian,80,minecraft:crying_obsidian,20)
RandomBlock(4,18,-3,minecraft:obsidian,80,minecraft:crying_obsidian,20)
RandomBlock(4,19,-3,minecraft:obsidian,80,minecraft:crying_obsidian,20)
RandomBlock(4,20,-3,minecraft:obsidian,80,minecraft:crying_obsidian,20)
RandomBlock(4,21,-3,minecraft:obsidian,80,minecraft:crying_obsidian,20)
RandomBlock(4,22,-3,minecraft:obsidian,80,minecraft:crying_obsidian,20)
RandomBlock(4,23,-3,minecraft:obsidian,80,minecraft:crying_obsidian,20)
RandomBlock(4,24,-3,minecraft:obsidian,80,minecraft:crying_obsidian,20)
RandomBlock(4,25,-3,minecraft:obsidian,80,minecraft:crying_obsidian,20)
RandomBlock(4,26,-3,minecraft:obsidian,80,minecraft:crying_obsidian,20)
RandomBlock(4,27,-3,minecraft:obsidian,80,minecraft:crying_obsidian,20)
RandomBlock(4,28,-3,minecraft:obsidian,80,minecraft:crying_obsidian,20)
RandomBlock(4,29,-3,minecraft:obsidian,80,minecraft:crying_obsidian,20)
RandomBlock(4,30,-3,minecraft:obsidian,80,minecraft:crying_obsidian,20)
RandomBlock(4,31,-3,minecraft:obsidian,80,minecraft:crying_obsidian,20)
RandomBlock(4,32,-3,minecraft:obsidian,80,minecraft:crying_obsidian,20)
RandomBlock(4,33,-3,minecraft:obsidian,80,minecraft:crying_obsidian,20)
RandomBlock(4,34,-3,minecraft:obsidian,80,minecraft:crying_obsidian,20)
RandomBlock(4,35,-3,minecraft:obsidian,80,minecraft:crying_obsidian,20)
RandomBlock(4,36,-3,minecraft:obsidian,80,minecraft:crying_obsidian,20)
RandomBlock(4,37,-3,minecraft:obsidian,80,minecraft:crying_obsidian,20)
RandomBlock(4,0,-2,minecraft:obsidian,80,minecraft:crying_obsidian,20)
RandomBlock(4,1,-2,minecraft:obsidian,80,minecraft:crying_obsidian,20)
RandomBlock(4,2,-2,minecraft:obsidian,80,minecraft:crying_obsidian,20)
RandomBlock(4,3,-2,minecraft:obsidian,80,minecraft:crying_obsidian,20)
RandomBlock(4,4,-2,minecraft:obsidian,80,minecraft:crying_obsidian,20)
RandomBlock(4,5,-2,minecraft:obsidian,80,minecraft:crying_obsidian,20)
RandomBlock(4,6,-2,minecraft:obsidian,80,minecraft:crying_obsidian,20)
RandomBlock(4,7,-2,minecraft:obsidian,80,minecraft:crying_obsidian,20)
RandomBlock(4,8,-2,minecraft:obsidian,80,minecraft:crying_obsidian,20)
RandomBlock(4,9,-2,minecraft:obsidian,80,minecraft:crying_obsidian,20)
RandomBlock(4,10,-2,minecraft:obsidian,80,minecraft:crying_obsidian,20)
RandomBlock(4,11,-2,minecraft:obsidian,80,minecraft:crying_obsidian,20)
RandomBlock(4,12,-2,minecraft:obsidian,80,minecraft:crying_obsidian,20)
RandomBlock(4,13,-2,minecraft:obsidian,80,minecraft:crying_obsidian,20)
RandomBlock(4,14,-2,minecraft:obsidian,80,minecraft:crying_obsidian,20)
RandomBlock(4,15,-2,minecraft:obsidian,80,minecraft:crying_obsidian,20)
RandomBlock(4,16,-2,minecraft:obsidian,80,minecraft:crying_obsidian,20)
RandomBlock(4,17,-2,minecraft:obsidian,80,minecraft:crying_obsidian,20)
RandomBlock(4,18,-2,minecraft:obsidian,80,minecraft:crying_obsidian,20)
RandomBlock(4,19,-2,minecraft:obsidian,80,minecraft:crying_obsidian,20)
RandomBlock(4,20,-2,minecraft:obsidian,80,minecraft:crying_obsidian,20)
RandomBlock(4,21,-2,minecraft:obsidian,80,minecraft:crying_obsidian,20)
RandomBlock(4,22,-2,minecraft:obsidian,80,minecraft:crying_obsidian,20)
RandomBlock(4,23,-2,minecraft:obsidian,80,minecraft:crying_obsidian,20)
RandomBlock(4,24,-2,minecraft:obsidian,80,minecraft:crying_obsidian,20)
RandomBlock(4,25,-2,minecraft:obsidian,80,minecraft:crying_obsidian,20)
RandomBlock(4,26,-2,minecraft:obsidian,80,minecraft:crying_obsidian,20)
RandomBlock(4,27,-2,minecraft:obsidian,80,minecraft:crying_obsidian,20)
RandomBlock(4,28,-2,minecraft:obsidian,80,minecraft:crying_obsidian,20)
RandomBlock(4,29,-2,minecraft:obsidian,80,minecraft:crying_obsidian,20)
RandomBlock(4,30,-2,minecraft:obsidian,80,minecraft:crying_obsidian,20)
RandomBlock(4,31,-2,minecraft:obsidian,80,minecraft:crying_obsidian,20)
RandomBlock(4,0,-1,minecraft:obsidian,80,minecraft:crying_obsidian,20)
RandomBlock(4,1,-1,minecraft:obsidian,80,minecraft:crying_obsidian,20)
RandomBlock(4,2,-1,minecraft:obsidian,80,minecraft:crying_obsidian,20)
RandomBlock(4,3,-1,minecraft:obsidian,80,minecraft:crying_obsidian,20)
RandomBlock(4,4,-1,minecraft:obsidian,80,minecraft:crying_obsidian,20)
RandomBlock(4,5,-1,minecraft:obsidian,80,minecraft:crying_obsidian,20)
RandomBlock(4,6,-1,minecraft:obsidian,80,minecraft:crying_obsidian,20)
RandomBlock(4,7,-1,minecraft:obsidian,80,minecraft:crying_obsidian,20)
RandomBlock(4,8,-1,minecraft:obsidian,80,minecraft:crying_obsidian,20)
RandomBlock(4,9,-1,minecraft:obsidian,80,minecraft:crying_obsidian,20)
RandomBlock(4,10,-1,minecraft:obsidian,80,minecraft:crying_obsidian,20)
RandomBlock(4,11,-1,minecraft:obsidian,80,minecraft:crying_obsidian,20)
RandomBlock(4,12,-1,minecraft:obsidian,80,minecraft:crying_obsidian,20)
RandomBlock(4,13,-1,minecraft:obsidian,80,minecraft:crying_obsidian,20)
RandomBlock(4,14,-1,minecraft:obsidian,80,minecraft:crying_obsidian,20)
RandomBlock(4,15,-1,minecraft:obsidian,80,minecraft:crying_obsidian,20)
RandomBlock(4,16,-1,minecraft:obsidian,80,minecraft:crying_obsidian,20)
RandomBlock(4,17,-1,minecraft:obsidian,80,minecraft:crying_obsidian,20)
RandomBlock(4,18,-1,minecraft:obsidian,80,minecraft:crying_obsidian,20)
RandomBlock(4,19,-1,minecraft:obsidian,80,minecraft:crying_obsidian,20)
RandomBlock(4,20,-1,minecraft:obsidian,80,minecraft:crying_obsidian,20)
RandomBlock(4,21,-1,minecraft:obsidian,80,minecraft:crying_obsidian,20)
RandomBlock(4,22,-1,minecraft:obsidian,80,minecraft:crying_obsidian,20)
RandomBlock(4,23,-1,minecraft:obsidian,80,minecraft:crying_obsidian,20)
RandomBlock(4,24,-1,minecraft:obsidian,80,minecraft:crying_obsidian,20)
RandomBlock(4,25,-1,minecraft:obsidian,80,minecraft:crying_obsidian,20)
RandomBlock(4,26,-1,minecraft:obsidian,80,minecraft:crying_obsidian,20)
RandomBlock(4,27,-1,minecraft:obsidian,80,minecraft:crying_obsidian,20)
RandomBlock(4,0,0,minecraft:obsidian,80,minecraft:crying_obsidian,20)
RandomBlock(4,1,0,minecraft:obsidian,80,minecraft:crying_obsidian,20)
RandomBlock(4,2,0,minecraft:obsidian,80,minecraft:crying_obsidian,20)
RandomBlock(4,3,0,minecraft:obsidian,80,minecraft:crying_obsidian,20)
RandomBlock(4,4,0,minecraft:obsidian,80,minecraft:crying_obsidian,20)
RandomBlock(4,5,0,minecraft:obsidian,80,minecraft:crying_obsidian,20)
RandomBlock(4,6,0,minecraft:obsidian,80,minecraft:crying_obsidian,20)
RandomBlock(4,7,0,minecraft:obsidian,80,minecraft:crying_obsidian,20)
RandomBlock(4,8,0,minecraft:obsidian,80,minecraft:crying_obsidian,20)
RandomBlock(4,9,0,minecraft:obsidian,80,minecraft:crying_obsidian,20)
RandomBlock(4,10,0,minecraft:obsidian,80,minecraft:crying_obsidian,20)
RandomBlock(4,11,0,minecraft:obsidian,80,minecraft:crying_obsidian,20)
RandomBlock(4,12,0,minecraft:obsidian,80,minecraft:crying_obsidian,20)
RandomBlock(4,13,0,minecraft:obsidian,80,minecraft:crying_obsidian,20)
RandomBlock(4,14,0,minecraft:obsidian,80,minecraft:crying_obsidian,20)
RandomBlock(4,15,0,minecraft:obsidian,80,minecraft:crying_obsidian,20)
RandomBlock(4,16,0,minecraft:obsidian,80,minecraft:crying_obsidian,20)
RandomBlock(4,17,0,minecraft:obsidian,80,minecraft:crying_obsidian,20)
RandomBlock(4,18,0,minecraft:obsidian,80,minecraft:crying_obsidian,20)
RandomBlock(4,19,0,minecraft:obsidian,80,minecraft:crying_obsidian,20)
RandomBlock(4,20,0,minecraft:obsidian,80,minecraft:crying_obsidian,20)
RandomBlock(4,0,1,minecraft:obsidian,80,minecraft:crying_obsidian,20)
RandomBlock(4,1,1,minecraft:obsidian,80,minecraft:crying_obsidian,20)
RandomBlock(4,2,1,minecraft:obsidian,80,minecraft:crying_obsidian,20)
RandomBlock(4,3,1,minecraft:obsidian,80,minecraft:crying_obsidian,20)
RandomBlock(4,4,1,minecraft:obsidian,80,minecraft:crying_obsidian,20)
RandomBlock(4,5,1,minecraft:obsidian,80,minecraft:crying_obsidian,20)
RandomBlock(4,6,1,minecraft:obsidian,80,minecraft:crying_obsidian,20)
RandomBlock(4,7,1,minecraft:obsidian,80,minecraft:crying_obsidian,20)
RandomBlock(4,8,1,minecraft:obsidian,80,minecraft:crying_obsidian,20)
RandomBlock(4,9,1,minecraft:obsidian,80,minecraft:crying_obsidian,20)
RandomBlock(4,10,1,minecraft:obsidian,80,minecraft:crying_obsidian,20)
RandomBlock(4,0,2,minecraft:obsidian,80,minecraft:crying_obsidian,20)
RandomBlock(4,1,2,minecraft:obsidian,80,minecraft:crying_obsidian,20)
RandomBlock(4,2,2,minecraft:obsidian,80,minecraft:crying_obsidian,20)
RandomBlock(4,3,2,minecraft:obsidian,80,minecraft:crying_obsidian,20)
RandomBlock(4,4,2,minecraft:obsidian,80,minecraft:crying_obsidian,20)
RandomBlock(4,5,2,minecraft:obsidian,80,minecraft:crying_obsidian,20)
RandomBlock(4,6,2,minecraft:obsidian,80,minecraft:crying_obsidian,20)
RandomBlock(4,7,2,minecraft:obsidian,80,minecraft:crying_obsidian,20)
RandomBlock(4,8,2,minecraft:obsidian,80,minecraft:crying_obsidian,20)
RandomBlock(4,9,2,minecraft:obsidian,80,minecraft:crying_obsidian,20)
RandomBlock(4,10,2,minecraft:obsidian,80,minecraft:crying_obsidian,20)
RandomBlock(4,0,3,minecraft:obsidian,80,minecraft:crying_obsidian,20)
RandomBlock(4,1,3,minecraft:obsidian,80,minecraft:crying_obsidian,20)
RandomBlock(4,2,3,minecraft:obsidian,80,minecraft:crying_obsidian,20)
RandomBlock(4,3,3,minecraft:obsidian,80,minecraft:crying_obsidian,20)
RandomBlock(4,4,3,minecraft:obsidian,80,minecraft:crying_obsidian,20)
RandomBlock(4,5,3,minecraft:obsidian,80,minecraft:crying_obsidian,20)
RandomBlock(4,6,3,minecraft:obsidian,80,minecraft:crying_obsidian,20)
RandomBlock(4,7,3,minecraft:obsidian,80,minecraft:crying_obsidian,20)
RandomBlock(4,8,3,minecraft:obsidian,80,minecraft:crying_obsidian,20)
RandomBlock(4,9,3,minecraft:obsidian,80,minecraft:crying_obsidian,20)
RandomBlock(4,0,4,minecraft:obsidian,80,minecraft:crying_obsidian,20)
RandomBlock(4,1,4,minecraft:obsidian,80,minecraft:crying_obsidian,20)
RandomBlock(4,2,4,minecraft:obsidian,80,minecraft:crying_obsidian,20)
RandomBlock(4,3,4,minecraft:obsidian,80,minecraft:crying_obsidian,20)
RandomBlock(4,4,4,minecraft:obsidian,80,minecraft:crying_obsidian,20)
RandomBlock(4,0,5,minecraft:obsidian,80,minecraft:crying_obsidian,20)
RandomBlock(4,1,5,minecraft:obsidian,80,minecraft:crying_obsidian,20)
RandomBlock(4,2,5,minecraft:obsidian,80,minecraft:crying_obsidian,20)
RandomBlock(4,3,5,minecraft:obsidian,80,minecraft:crying_obsidian,20)
RandomBlock(4,4,5,minecraft:obsidian,80,minecraft:crying_obsidian,20)
RandomBlock(4,0,6,minecraft:obsidian,80,minecraft:crying_obsidian,20)
RandomBlock(4,1,6,minecraft:obsidian,80,minecraft:crying_obsidian,20)
RandomBlock(4,2,6,minecraft:obsidian,80,minecraft:crying_obsidian,20)
RandomBlock(4,0,7,minecraft:obsidian,80,minecraft:crying_obsidian,20)
RandomBlock(5,0,-7,minecraft:obsidian,80,minecraft:crying_obsidian,20)
RandomBlock(5,1,-7,minecraft:obsidian,80,minecraft:crying_obsidian,20)
RandomBlock(5,2,-7,minecraft:obsidian,80,minecraft:crying_obsidian,20)
RandomBlock(5,3,-7,minecraft:obsidian,80,minecraft:crying_obsidian,20)
RandomBlock(5,4,-7,minecraft:obsidian,80,minecraft:crying_obsidian,20)
RandomBlock(5,5,-7,minecraft:obsidian,80,minecraft:crying_obsidian,20)
RandomBlock(5,6,-7,minecraft:obsidian,80,minecraft:crying_obsidian,20)
RandomBlock(5,7,-7,minecraft:obsidian,80,minecraft:crying_obsidian,20)
RandomBlock(5,8,-7,minecraft:obsidian,80,minecraft:crying_obsidian,20)
RandomBlock(5,9,-7,minecraft:obsidian,80,minecraft:crying_obsidian,20)
RandomBlock(5,10,-7,minecraft:obsidian,80,minecraft:crying_obsidian,20)
RandomBlock(5,11,-7,minecraft:obsidian,80,minecraft:crying_obsidian,20)
RandomBlock(5,12,-7,minecraft:obsidian,80,minecraft:crying_obsidian,20)
RandomBlock(5,13,-7,minecraft:obsidian,80,minecraft:crying_obsidian,20)
RandomBlock(5,14,-7,minecraft:obsidian,80,minecraft:crying_obsidian,20)
RandomBlock(5,15,-7,minecraft:obsidian,80,minecraft:crying_obsidian,20)
RandomBlock(5,16,-7,minecraft:obsidian,80,minecraft:crying_obsidian,20)
RandomBlock(5,17,-7,minecraft:obsidian,80,minecraft:crying_obsidian,20)
RandomBlock(5,18,-7,minecraft:obsidian,80,minecraft:crying_obsidian,20)
RandomBlock(5,19,-7,minecraft:obsidian,80,minecraft:crying_obsidian,20)
RandomBlock(5,20,-7,minecraft:obsidian,80,minecraft:crying_obsidian,20)
RandomBlock(5,21,-7,minecraft:obsidian,80,minecraft:crying_obsidian,20)
RandomBlock(5,22,-7,minecraft:obsidian,80,minecraft:crying_obsidian,20)
RandomBlock(5,23,-7,minecraft:obsidian,80,minecraft:crying_obsidian,20)
RandomBlock(5,24,-7,minecraft:obsidian,80,minecraft:crying_obsidian,20)
RandomBlock(5,25,-7,minecraft:obsidian,80,minecraft:crying_obsidian,20)
RandomBlock(5,26,-7,minecraft:obsidian,80,minecraft:crying_obsidian,20)
RandomBlock(5,27,-7,minecraft:obsidian,80,minecraft:crying_obsidian,20)
RandomBlock(5,28,-7,minecraft:obsidian,80,minecraft:crying_obsidian,20)
RandomBlock(5,29,-7,minecraft:obsidian,80,minecraft:crying_obsidian,20)
RandomBlock(5,30,-7,minecraft:obsidian,80,minecraft:crying_obsidian,20)
RandomBlock(5,31,-7,minecraft:obsidian,80,minecraft:crying_obsidian,20)
RandomBlock(5,32,-7,minecraft:obsidian,80,minecraft:crying_obsidian,20)
RandomBlock(5,33,-7,minecraft:obsidian,80,minecraft:crying_obsidian,20)
RandomBlock(5,34,-7,minecraft:obsidian,80,minecraft:crying_obsidian,20)
RandomBlock(5,35,-7,minecraft:obsidian,80,minecraft:crying_obsidian,20)
RandomBlock(5,0,-6,minecraft:obsidian,80,minecraft:crying_obsidian,20)
RandomBlock(5,1,-6,minecraft:obsidian,80,minecraft:crying_obsidian,20)
RandomBlock(5,2,-6,minecraft:obsidian,80,minecraft:crying_obsidian,20)
RandomBlock(5,3,-6,minecraft:obsidian,80,minecraft:crying_obsidian,20)
RandomBlock(5,4,-6,minecraft:obsidian,80,minecraft:crying_obsidian,20)
RandomBlock(5,5,-6,minecraft:obsidian,80,minecraft:crying_obsidian,20)
RandomBlock(5,6,-6,minecraft:obsidian,80,minecraft:crying_obsidian,20)
RandomBlock(5,7,-6,minecraft:obsidian,80,minecraft:crying_obsidian,20)
RandomBlock(5,8,-6,minecraft:obsidian,80,minecraft:crying_obsidian,20)
RandomBlock(5,9,-6,minecraft:obsidian,80,minecraft:crying_obsidian,20)
RandomBlock(5,10,-6,minecraft:obsidian,80,minecraft:crying_obsidian,20)
RandomBlock(5,11,-6,minecraft:obsidian,80,minecraft:crying_obsidian,20)
RandomBlock(5,12,-6,minecraft:obsidian,80,minecraft:crying_obsidian,20)
RandomBlock(5,13,-6,minecraft:obsidian,80,minecraft:crying_obsidian,20)
RandomBlock(5,14,-6,minecraft:obsidian,80,minecraft:crying_obsidian,20)
RandomBlock(5,15,-6,minecraft:obsidian,80,minecraft:crying_obsidian,20)
RandomBlock(5,16,-6,minecraft:obsidian,80,minecraft:crying_obsidian,20)
RandomBlock(5,17,-6,minecraft:obsidian,80,minecraft:crying_obsidian,20)
RandomBlock(5,18,-6,minecraft:obsidian,80,minecraft:crying_obsidian,20)
RandomBlock(5,19,-6,minecraft:obsidian,80,minecraft:crying_obsidian,20)
RandomBlock(5,20,-6,minecraft:obsidian,80,minecraft:crying_obsidian,20)
RandomBlock(5,21,-6,minecraft:obsidian,80,minecraft:crying_obsidian,20)
RandomBlock(5,22,-6,minecraft:obsidian,80,minecraft:crying_obsidian,20)
RandomBlock(5,23,-6,minecraft:obsidian,80,minecraft:crying_obsidian,20)
RandomBlock(5,24,-6,minecraft:obsidian,80,minecraft:crying_obsidian,20)
RandomBlock(5,25,-6,minecraft:obsidian,80,minecraft:crying_obsidian,20)
RandomBlock(5,26,-6,minecraft:obsidian,80,minecraft:crying_obsidian,20)
RandomBlock(5,27,-6,minecraft:obsidian,80,minecraft:crying_obsidian,20)
RandomBlock(5,28,-6,minecraft:obsidian,80,minecraft:crying_obsidian,20)
RandomBlock(5,29,-6,minecraft:obsidian,80,minecraft:crying_obsidian,20)
RandomBlock(5,30,-6,minecraft:obsidian,80,minecraft:crying_obsidian,20)
RandomBlock(5,31,-6,minecraft:obsidian,80,minecraft:crying_obsidian,20)
RandomBlock(5,32,-6,minecraft:obsidian,80,minecraft:crying_obsidian,20)
RandomBlock(5,33,-6,minecraft:obsidian,80,minecraft:crying_obsidian,20)
RandomBlock(5,34,-6,minecraft:obsidian,80,minecraft:crying_obsidian,20)
RandomBlock(5,35,-6,minecraft:obsidian,80,minecraft:crying_obsidian,20)
RandomBlock(5,36,-6,minecraft:obsidian,80,minecraft:crying_obsidian,20)
RandomBlock(5,0,-5,minecraft:obsidian,80,minecraft:crying_obsidian,20)
RandomBlock(5,1,-5,minecraft:obsidian,80,minecraft:crying_obsidian,20)
RandomBlock(5,3,-5,minecraft:obsidian,80,minecraft:crying_obsidian,20)
RandomBlock(5,4,-5,minecraft:obsidian,80,minecraft:crying_obsidian,20)
RandomBlock(5,5,-5,minecraft:obsidian,80,minecraft:crying_obsidian,20)
RandomBlock(5,6,-5,minecraft:obsidian,80,minecraft:crying_obsidian,20)
RandomBlock(5,7,-5,minecraft:obsidian,80,minecraft:crying_obsidian,20)
RandomBlock(5,8,-5,minecraft:obsidian,80,minecraft:crying_obsidian,20)
RandomBlock(5,9,-5,minecraft:obsidian,80,minecraft:crying_obsidian,20)
RandomBlock(5,10,-5,minecraft:obsidian,80,minecraft:crying_obsidian,20)
RandomBlock(5,11,-5,minecraft:obsidian,80,minecraft:crying_obsidian,20)
RandomBlock(5,12,-5,minecraft:obsidian,80,minecraft:crying_obsidian,20)
RandomBlock(5,13,-5,minecraft:obsidian,80,minecraft:crying_obsidian,20)
RandomBlock(5,14,-5,minecraft:obsidian,80,minecraft:crying_obsidian,20)
RandomBlock(5,15,-5,minecraft:obsidian,80,minecraft:crying_obsidian,20)
RandomBlock(5,16,-5,minecraft:obsidian,80,minecraft:crying_obsidian,20)
RandomBlock(5,17,-5,minecraft:obsidian,80,minecraft:crying_obsidian,20)
RandomBlock(5,18,-5,minecraft:obsidian,80,minecraft:crying_obsidian,20)
RandomBlock(5,19,-5,minecraft:obsidian,80,minecraft:crying_obsidian,20)
RandomBlock(5,20,-5,minecraft:obsidian,80,minecraft:crying_obsidian,20)
RandomBlock(5,21,-5,minecraft:obsidian,80,minecraft:crying_obsidian,20)
RandomBlock(5,22,-5,minecraft:obsidian,80,minecraft:crying_obsidian,20)
RandomBlock(5,23,-5,minecraft:obsidian,80,minecraft:crying_obsidian,20)
RandomBlock(5,24,-5,minecraft:obsidian,80,minecraft:crying_obsidian,20)
RandomBlock(5,25,-5,minecraft:obsidian,80,minecraft:crying_obsidian,20)
RandomBlock(5,26,-5,minecraft:obsidian,80,minecraft:crying_obsidian,20)
RandomBlock(5,27,-5,minecraft:obsidian,80,minecraft:crying_obsidian,20)
RandomBlock(5,28,-5,minecraft:obsidian,80,minecraft:crying_obsidian,20)
RandomBlock(5,29,-5,minecraft:obsidian,80,minecraft:crying_obsidian,20)
RandomBlock(5,30,-5,minecraft:obsidian,80,minecraft:crying_obsidian,20)
RandomBlock(5,31,-5,minecraft:obsidian,80,minecraft:crying_obsidian,20)
RandomBlock(5,32,-5,minecraft:obsidian,80,minecraft:crying_obsidian,20)
RandomBlock(5,33,-5,minecraft:obsidian,80,minecraft:crying_obsidian,20)
RandomBlock(5,34,-5,minecraft:obsidian,80,minecraft:crying_obsidian,20)
RandomBlock(5,35,-5,minecraft:obsidian,80,minecraft:crying_obsidian,20)
RandomBlock(5,36,-5,minecraft:obsidian,80,minecraft:crying_obsidian,20)
RandomBlock(5,37,-5,minecraft:obsidian,80,minecraft:crying_obsidian,20)
RandomBlock(5,0,-4,minecraft:obsidian,80,minecraft:crying_obsidian,20)
RandomBlock(5,1,-4,minecraft:obsidian,80,minecraft:crying_obsidian,20)
RandomBlock(5,2,-4,minecraft:obsidian,80,minecraft:crying_obsidian,20)
RandomBlock(5,3,-4,minecraft:obsidian,80,minecraft:crying_obsidian,20)
RandomBlock(5,4,-4,minecraft:obsidian,80,minecraft:crying_obsidian,20)
RandomBlock(5,5,-4,minecraft:obsidian,80,minecraft:crying_obsidian,20)
RandomBlock(5,6,-4,minecraft:obsidian,80,minecraft:crying_obsidian,20)
RandomBlock(5,7,-4,minecraft:obsidian,80,minecraft:crying_obsidian,20)
RandomBlock(5,8,-4,minecraft:obsidian,80,minecraft:crying_obsidian,20)
RandomBlock(5,9,-4,minecraft:obsidian,80,minecraft:crying_obsidian,20)
RandomBlock(5,10,-4,minecraft:obsidian,80,minecraft:crying_obsidian,20)
RandomBlock(5,11,-4,minecraft:obsidian,80,minecraft:crying_obsidian,20)
RandomBlock(5,12,-4,minecraft:obsidian,80,minecraft:crying_obsidian,20)
RandomBlock(5,13,-4,minecraft:obsidian,80,minecraft:crying_obsidian,20)
RandomBlock(5,14,-4,minecraft:obsidian,80,minecraft:crying_obsidian,20)
RandomBlock(5,15,-4,minecraft:obsidian,80,minecraft:crying_obsidian,20)
RandomBlock(5,16,-4,minecraft:obsidian,80,minecraft:crying_obsidian,20)
RandomBlock(5,17,-4,minecraft:obsidian,80,minecraft:crying_obsidian,20)
RandomBlock(5,18,-4,minecraft:obsidian,80,minecraft:crying_obsidian,20)
RandomBlock(5,19,-4,minecraft:obsidian,80,minecraft:crying_obsidian,20)
RandomBlock(5,20,-4,minecraft:obsidian,80,minecraft:crying_obsidian,20)
RandomBlock(5,21,-4,minecraft:obsidian,80,minecraft:crying_obsidian,20)
RandomBlock(5,22,-4,minecraft:obsidian,80,minecraft:crying_obsidian,20)
RandomBlock(5,23,-4,minecraft:obsidian,80,minecraft:crying_obsidian,20)
RandomBlock(5,24,-4,minecraft:obsidian,80,minecraft:crying_obsidian,20)
RandomBlock(5,25,-4,minecraft:obsidian,80,minecraft:crying_obsidian,20)
RandomBlock(5,26,-4,minecraft:obsidian,80,minecraft:crying_obsidian,20)
RandomBlock(5,27,-4,minecraft:obsidian,80,minecraft:crying_obsidian,20)
RandomBlock(5,28,-4,minecraft:obsidian,80,minecraft:crying_obsidian,20)
RandomBlock(5,29,-4,minecraft:obsidian,80,minecraft:crying_obsidian,20)
RandomBlock(5,30,-4,minecraft:obsidian,80,minecraft:crying_obsidian,20)
RandomBlock(5,31,-4,minecraft:obsidian,80,minecraft:crying_obsidian,20)
RandomBlock(5,32,-4,minecraft:obsidian,80,minecraft:crying_obsidian,20)
RandomBlock(5,33,-4,minecraft:obsidian,80,minecraft:crying_obsidian,20)
RandomBlock(5,34,-4,minecraft:obsidian,80,minecraft:crying_obsidian,20)
RandomBlock(5,35,-4,minecraft:obsidian,80,minecraft:crying_obsidian,20)
RandomBlock(5,36,-4,minecraft:obsidian,80,minecraft:crying_obsidian,20)
RandomBlock(5,37,-4,minecraft:obsidian,80,minecraft:crying_obsidian,20)
RandomBlock(5,0,-3,minecraft:obsidian,80,minecraft:crying_obsidian,20)
RandomBlock(5,1,-3,minecraft:obsidian,80,minecraft:crying_obsidian,20)
RandomBlock(5,2,-3,minecraft:obsidian,80,minecraft:crying_obsidian,20)
RandomBlock(5,3,-3,minecraft:obsidian,80,minecraft:crying_obsidian,20)
RandomBlock(5,4,-3,minecraft:obsidian,80,minecraft:crying_obsidian,20)
RandomBlock(5,5,-3,minecraft:obsidian,80,minecraft:crying_obsidian,20)
RandomBlock(5,6,-3,minecraft:obsidian,80,minecraft:crying_obsidian,20)
RandomBlock(5,7,-3,minecraft:obsidian,80,minecraft:crying_obsidian,20)
RandomBlock(5,8,-3,minecraft:obsidian,80,minecraft:crying_obsidian,20)
RandomBlock(5,9,-3,minecraft:obsidian,80,minecraft:crying_obsidian,20)
RandomBlock(5,10,-3,minecraft:obsidian,80,minecraft:crying_obsidian,20)
RandomBlock(5,11,-3,minecraft:obsidian,80,minecraft:crying_obsidian,20)
RandomBlock(5,12,-3,minecraft:obsidian,80,minecraft:crying_obsidian,20)
RandomBlock(5,13,-3,minecraft:obsidian,80,minecraft:crying_obsidian,20)
RandomBlock(5,14,-3,minecraft:obsidian,80,minecraft:crying_obsidian,20)
RandomBlock(5,15,-3,minecraft:obsidian,80,minecraft:crying_obsidian,20)
RandomBlock(5,16,-3,minecraft:obsidian,80,minecraft:crying_obsidian,20)
RandomBlock(5,17,-3,minecraft:obsidian,80,minecraft:crying_obsidian,20)
RandomBlock(5,18,-3,minecraft:obsidian,80,minecraft:crying_obsidian,20)
RandomBlock(5,19,-3,minecraft:obsidian,80,minecraft:crying_obsidian,20)
RandomBlock(5,20,-3,minecraft:obsidian,80,minecraft:crying_obsidian,20)
RandomBlock(5,21,-3,minecraft:obsidian,80,minecraft:crying_obsidian,20)
RandomBlock(5,22,-3,minecraft:obsidian,80,minecraft:crying_obsidian,20)
RandomBlock(5,23,-3,minecraft:obsidian,80,minecraft:crying_obsidian,20)
RandomBlock(5,24,-3,minecraft:obsidian,80,minecraft:crying_obsidian,20)
RandomBlock(5,25,-3,minecraft:obsidian,80,minecraft:crying_obsidian,20)
RandomBlock(5,26,-3,minecraft:obsidian,80,minecraft:crying_obsidian,20)
RandomBlock(5,27,-3,minecraft:obsidian,80,minecraft:crying_obsidian,20)
RandomBlock(5,28,-3,minecraft:obsidian,80,minecraft:crying_obsidian,20)
RandomBlock(5,29,-3,minecraft:obsidian,80,minecraft:crying_obsidian,20)
RandomBlock(5,30,-3,minecraft:obsidian,80,minecraft:crying_obsidian,20)
RandomBlock(5,31,-3,minecraft:obsidian,80,minecraft:crying_obsidian,20)
RandomBlock(5,32,-3,minecraft:obsidian,80,minecraft:crying_obsidian,20)
RandomBlock(5,33,-3,minecraft:obsidian,80,minecraft:crying_obsidian,20)
RandomBlock(5,34,-3,minecraft:obsidian,80,minecraft:crying_obsidian,20)
RandomBlock(5,35,-3,minecraft:obsidian,80,minecraft:crying_obsidian,20)
RandomBlock(5,36,-3,minecraft:obsidian,80,minecraft:crying_obsidian,20)
RandomBlock(5,37,-3,minecraft:obsidian,80,minecraft:crying_obsidian,20)
RandomBlock(5,0,-2,minecraft:obsidian,80,minecraft:crying_obsidian,20)
RandomBlock(5,1,-2,minecraft:obsidian,80,minecraft:crying_obsidian,20)
RandomBlock(5,2,-2,minecraft:obsidian,80,minecraft:crying_obsidian,20)
RandomBlock(5,3,-2,minecraft:obsidian,80,minecraft:crying_obsidian,20)
RandomBlock(5,4,-2,minecraft:obsidian,80,minecraft:crying_obsidian,20)
RandomBlock(5,5,-2,minecraft:obsidian,80,minecraft:crying_obsidian,20)
RandomBlock(5,6,-2,minecraft:obsidian,80,minecraft:crying_obsidian,20)
RandomBlock(5,7,-2,minecraft:obsidian,80,minecraft:crying_obsidian,20)
RandomBlock(5,8,-2,minecraft:obsidian,80,minecraft:crying_obsidian,20)
RandomBlock(5,9,-2,minecraft:obsidian,80,minecraft:crying_obsidian,20)
RandomBlock(5,10,-2,minecraft:obsidian,80,minecraft:crying_obsidian,20)
RandomBlock(5,11,-2,minecraft:obsidian,80,minecraft:crying_obsidian,20)
RandomBlock(5,12,-2,minecraft:obsidian,80,minecraft:crying_obsidian,20)
RandomBlock(5,13,-2,minecraft:obsidian,80,minecraft:crying_obsidian,20)
RandomBlock(5,14,-2,minecraft:obsidian,80,minecraft:crying_obsidian,20)
RandomBlock(5,15,-2,minecraft:obsidian,80,minecraft:crying_obsidian,20)
RandomBlock(5,16,-2,minecraft:obsidian,80,minecraft:crying_obsidian,20)
RandomBlock(5,17,-2,minecraft:obsidian,80,minecraft:crying_obsidian,20)
RandomBlock(5,18,-2,minecraft:obsidian,80,minecraft:crying_obsidian,20)
RandomBlock(5,19,-2,minecraft:obsidian,80,minecraft:crying_obsidian,20)
RandomBlock(5,20,-2,minecraft:obsidian,80,minecraft:crying_obsidian,20)
RandomBlock(5,21,-2,minecraft:obsidian,80,minecraft:crying_obsidian,20)
RandomBlock(5,22,-2,minecraft:obsidian,80,minecraft:crying_obsidian,20)
RandomBlock(5,23,-2,minecraft:obsidian,80,minecraft:crying_obsidian,20)
RandomBlock(5,24,-2,minecraft:obsidian,80,minecraft:crying_obsidian,20)
RandomBlock(5,25,-2,minecraft:obsidian,80,minecraft:crying_obsidian,20)
RandomBlock(5,26,-2,minecraft:obsidian,80,minecraft:crying_obsidian,20)
RandomBlock(5,27,-2,minecraft:obsidian,80,minecraft:crying_obsidian,20)
RandomBlock(5,28,-2,minecraft:obsidian,80,minecraft:crying_obsidian,20)
RandomBlock(5,29,-2,minecraft:obsidian,80,minecraft:crying_obsidian,20)
RandomBlock(5,30,-2,minecraft:obsidian,80,minecraft:crying_obsidian,20)
RandomBlock(5,31,-2,minecraft:obsidian,80,minecraft:crying_obsidian,20)
RandomBlock(5,32,-2,minecraft:obsidian,80,minecraft:crying_obsidian,20)
RandomBlock(5,33,-2,minecraft:obsidian,80,minecraft:crying_obsidian,20)
RandomBlock(5,34,-2,minecraft:obsidian,80,minecraft:crying_obsidian,20)
RandomBlock(5,35,-2,minecraft:obsidian,80,minecraft:crying_obsidian,20)
RandomBlock(5,36,-2,minecraft:obsidian,80,minecraft:crying_obsidian,20)
RandomBlock(5,0,-1,minecraft:obsidian,80,minecraft:crying_obsidian,20)
RandomBlock(5,1,-1,minecraft:obsidian,80,minecraft:crying_obsidian,20)
RandomBlock(5,2,-1,minecraft:obsidian,80,minecraft:crying_obsidian,20)
RandomBlock(5,3,-1,minecraft:obsidian,80,minecraft:crying_obsidian,20)
RandomBlock(5,4,-1,minecraft:obsidian,80,minecraft:crying_obsidian,20)
RandomBlock(5,5,-1,minecraft:obsidian,80,minecraft:crying_obsidian,20)
RandomBlock(5,6,-1,minecraft:obsidian,80,minecraft:crying_obsidian,20)
RandomBlock(5,7,-1,minecraft:obsidian,80,minecraft:crying_obsidian,20)
RandomBlock(5,8,-1,minecraft:obsidian,80,minecraft:crying_obsidian,20)
RandomBlock(5,9,-1,minecraft:obsidian,80,minecraft:crying_obsidian,20)
RandomBlock(5,10,-1,minecraft:obsidian,80,minecraft:crying_obsidian,20)
RandomBlock(5,11,-1,minecraft:obsidian,80,minecraft:crying_obsidian,20)
RandomBlock(5,12,-1,minecraft:obsidian,80,minecraft:crying_obsidian,20)
RandomBlock(5,13,-1,minecraft:obsidian,80,minecraft:crying_obsidian,20)
RandomBlock(5,14,-1,minecraft:obsidian,80,minecraft:crying_obsidian,20)
RandomBlock(5,15,-1,minecraft:obsidian,80,minecraft:crying_obsidian,20)
RandomBlock(5,20,-1,minecraft:obsidian,80,minecraft:crying_obsidian,20)
RandomBlock(5,21,-1,minecraft:obsidian,80,minecraft:crying_obsidian,20)
RandomBlock(5,22,-1,minecraft:obsidian,80,minecraft:crying_obsidian,20)
RandomBlock(5,23,-1,minecraft:obsidian,80,minecraft:crying_obsidian,20)
RandomBlock(5,24,-1,minecraft:obsidian,80,minecraft:crying_obsidian,20)
RandomBlock(5,25,-1,minecraft:obsidian,80,minecraft:crying_obsidian,20)
RandomBlock(5,26,-1,minecraft:obsidian,80,minecraft:crying_obsidian,20)
RandomBlock(5,27,-1,minecraft:obsidian,80,minecraft:crying_obsidian,20)
RandomBlock(5,28,-1,minecraft:obsidian,80,minecraft:crying_obsidian,20)
RandomBlock(5,29,-1,minecraft:obsidian,80,minecraft:crying_obsidian,20)
RandomBlock(5,30,-1,minecraft:obsidian,80,minecraft:crying_obsidian,20)
RandomBlock(5,0,0,minecraft:obsidian,80,minecraft:crying_obsidian,20)
RandomBlock(5,1,0,minecraft:obsidian,80,minecraft:crying_obsidian,20)
RandomBlock(5,2,0,minecraft:obsidian,80,minecraft:crying_obsidian,20)
RandomBlock(5,3,0,minecraft:obsidian,80,minecraft:crying_obsidian,20)
RandomBlock(5,4,0,minecraft:obsidian,80,minecraft:crying_obsidian,20)
RandomBlock(5,5,0,minecraft:obsidian,80,minecraft:crying_obsidian,20)
RandomBlock(5,6,0,minecraft:obsidian,80,minecraft:crying_obsidian,20)
RandomBlock(5,7,0,minecraft:obsidian,80,minecraft:crying_obsidian,20)
RandomBlock(5,8,0,minecraft:obsidian,80,minecraft:crying_obsidian,20)
RandomBlock(5,9,0,minecraft:obsidian,80,minecraft:crying_obsidian,20)
RandomBlock(5,10,0,minecraft:obsidian,80,minecraft:crying_obsidian,20)
RandomBlock(5,11,0,minecraft:obsidian,80,minecraft:crying_obsidian,20)
RandomBlock(5,12,0,minecraft:obsidian,80,minecraft:crying_obsidian,20)
RandomBlock(5,20,0,minecraft:obsidian,80,minecraft:crying_obsidian,20)
RandomBlock(5,21,0,minecraft:obsidian,80,minecraft:crying_obsidian,20)
RandomBlock(5,22,0,minecraft:obsidian,80,minecraft:crying_obsidian,20)
RandomBlock(5,23,0,minecraft:obsidian,80,minecraft:crying_obsidian,20)
RandomBlock(5,0,1,minecraft:obsidian,80,minecraft:crying_obsidian,20)
RandomBlock(5,1,1,minecraft:obsidian,80,minecraft:crying_obsidian,20)
RandomBlock(5,2,1,minecraft:obsidian,80,minecraft:crying_obsidian,20)
RandomBlock(5,3,1,minecraft:obsidian,80,minecraft:crying_obsidian,20)
RandomBlock(5,4,1,minecraft:obsidian,80,minecraft:crying_obsidian,20)
RandomBlock(5,5,1,minecraft:obsidian,80,minecraft:crying_obsidian,20)
RandomBlock(5,6,1,minecraft:obsidian,80,minecraft:crying_obsidian,20)
RandomBlock(5,7,1,minecraft:obsidian,80,minecraft:crying_obsidian,20)
RandomBlock(5,8,1,minecraft:obsidian,80,minecraft:crying_obsidian,20)
RandomBlock(5,9,1,minecraft:obsidian,80,minecraft:crying_obsidian,20)
RandomBlock(5,10,1,minecraft:obsidian,80,minecraft:crying_obsidian,20)
RandomBlock(5,11,1,minecraft:obsidian,80,minecraft:crying_obsidian,20)
RandomBlock(5,0,2,minecraft:obsidian,80,minecraft:crying_obsidian,20)
RandomBlock(5,1,2,minecraft:obsidian,80,minecraft:crying_obsidian,20)
RandomBlock(5,2,2,minecraft:obsidian,80,minecraft:crying_obsidian,20)
RandomBlock(5,3,2,minecraft:obsidian,80,minecraft:crying_obsidian,20)
RandomBlock(5,4,2,minecraft:obsidian,80,minecraft:crying_obsidian,20)
RandomBlock(5,5,2,minecraft:obsidian,80,minecraft:crying_obsidian,20)
RandomBlock(5,6,2,minecraft:obsidian,80,minecraft:crying_obsidian,20)
RandomBlock(5,7,2,minecraft:obsidian,80,minecraft:crying_obsidian,20)
RandomBlock(5,8,2,minecraft:obsidian,80,minecraft:crying_obsidian,20)
RandomBlock(5,0,3,minecraft:obsidian,80,minecraft:crying_obsidian,20)
RandomBlock(5,1,3,minecraft:obsidian,80,minecraft:crying_obsidian,20)
