Author: Bo3 BulkEdit

Description: Converted Schematic - Modified by Bo3BulkEdit

Version: 3

SettingsMode: WriteDisable

IsOTGPlus: true
Tree: false
Frequency: 10
Rarity: 100
RotateRandomly: true
SpawnHeight: randomY
SpawnHeightOffset: 0
SpawnHeightVariance: 0
MaxBranchDepth: 10
ExcludedBiomes: All

MinHeight: 50
MaxHeight: 65

SourceBlocks: AIR
MaxPercentageOutsideSourceBlock: 100
OutsideSourceBlock: placeAnyway

ReplaceBelow: NETHER_WART_BLOCK
ReplaceWithBiomeBlocks: false
ReplaceWithGroundBlock: NETHER_WART_BLOCK
ReplaceWithSurfaceBlock: NETHER_WART_BLOCK
ReplaceWithStoneBlock: NETHER_WART_BLOCK
SmoothRadius: 30
SmoothHeightOffset: 0
SmoothStartTop: false
SmoothStartWood: false
SmoothingSurfaceBlock: NETHER_WART_BLOCK
SmoothingGroundBlock: NETHER_WART_BLOCK

B(0,750,0,AIR)
B(15,750,15,AIR)
B(0,0,12,minecraft:nether_wart_block)
B(1,0,12,minecraft:nether_wart_block)
B(0,0,13,minecraft:nether_wart_block)
B(1,0,13,minecraft:nether_wart_block)
B(0,0,14,minecraft:nether_wart_block)
B(1,0,14,minecraft:nether_wart_block)
B(2,0,14,minecraft:nether_wart_block)
B(3,0,14,minecraft:nether_wart_block)
B(4,0,14,minecraft:nether_wart_block)
B(0,0,15,minecraft:nether_wart_block)
B(1,0,15,minecraft:nether_wart_block)
B(2,0,15,minecraft:nether_wart_block)
B(0,1,12,minecraft:nether_wart_block)
B(1,1,12,minecraft:nether_wart_block)
B(0,1,13,minecraft:nether_wart_block)
B(1,1,13,minecraft:nether_wart_block)
B(0,1,14,minecraft:nether_wart_block)
B(1,1,14,minecraft:nether_wart_block)
B(2,1,14,minecraft:nether_wart_block)
B(3,1,14,minecraft:nether_wart_block)
B(4,1,14,minecraft:nether_wart_block)
B(0,1,15,minecraft:nether_wart_block)
B(1,1,15,minecraft:nether_wart_block)
B(2,1,15,minecraft:nether_wart_block)
B(0,2,12,minecraft:nether_wart_block)
B(1,2,12,minecraft:nether_wart_block)
B(0,2,13,minecraft:nether_wart_block)
B(1,2,13,minecraft:nether_wart_block)
B(0,2,14,minecraft:nether_wart_block)
B(1,2,14,minecraft:nether_wart_block)
B(2,2,14,minecraft:nether_wart_block)
B(3,2,14,minecraft:nether_wart_block)
B(4,2,14,minecraft:nether_wart_block)
B(0,2,15,minecraft:nether_wart_block)
B(1,2,15,minecraft:nether_wart_block)
B(2,2,15,minecraft:nether_wart_block)
B(0,3,12,minecraft:nether_wart_block)
B(1,3,12,minecraft:nether_wart_block)
B(0,3,13,minecraft:nether_wart_block)
B(1,3,13,minecraft:nether_wart_block)
B(0,3,14,minecraft:nether_wart_block)
B(1,3,14,minecraft:nether_wart_block)
B(2,3,14,minecraft:nether_wart_block)
B(3,3,14,minecraft:nether_wart_block)
B(4,3,14,minecraft:nether_wart_block)
B(0,3,15,minecraft:nether_wart_block)
B(1,3,15,minecraft:nether_wart_block)
B(2,3,15,minecraft:nether_wart_block)
B(0,4,12,minecraft:nether_wart_block)
B(1,4,12,minecraft:nether_wart_block)
B(0,4,13,minecraft:nether_wart_block)
B(1,4,13,minecraft:nether_wart_block)
B(0,4,14,minecraft:nether_wart_block)
B(1,4,14,minecraft:nether_wart_block)
B(2,4,14,minecraft:nether_wart_block)
B(3,4,14,minecraft:nether_wart_block)
B(4,4,14,minecraft:nether_wart_block)
B(0,4,15,minecraft:nether_wart_block)
B(1,4,15,minecraft:nether_wart_block)
B(2,4,15,minecraft:nether_wart_block)
B(0,5,12,minecraft:nether_wart_block)
B(1,5,12,minecraft:nether_wart_block)
B(0,5,13,minecraft:nether_wart_block)
B(1,5,13,minecraft:nether_wart_block)
B(0,5,14,minecraft:nether_wart_block)
B(1,5,14,minecraft:nether_wart_block)
B(2,5,14,minecraft:nether_wart_block)
B(3,5,14,minecraft:nether_wart_block)
B(4,5,14,minecraft:nether_wart_block)
B(0,5,15,minecraft:nether_wart_block)
B(1,5,15,minecraft:nether_wart_block)
B(2,5,15,minecraft:nether_wart_block)
B(0,6,12,minecraft:nether_wart_block)
B(1,6,12,minecraft:nether_wart_block)
B(0,6,13,minecraft:nether_wart_block)
B(1,6,13,minecraft:nether_wart_block)
B(0,6,14,minecraft:nether_wart_block)
B(1,6,14,minecraft:nether_wart_block)
B(2,6,14,minecraft:nether_wart_block)
B(3,6,14,minecraft:nether_wart_block)
B(4,6,14,minecraft:nether_wart_block)
B(0,6,15,minecraft:nether_wart_block)
B(1,6,15,minecraft:nether_wart_block)
B(2,6,15,minecraft:nether_wart_block)
B(0,7,12,minecraft:nether_wart_block)
B(1,7,12,minecraft:nether_wart_block)
B(0,7,13,minecraft:nether_wart_block)
B(1,7,13,minecraft:nether_wart_block)
B(0,7,14,minecraft:nether_wart_block)
B(1,7,14,minecraft:nether_wart_block)
B(2,7,14,minecraft:nether_wart_block)
B(3,7,14,minecraft:nether_wart_block)
B(4,7,14,minecraft:nether_wart_block)
B(0,7,15,minecraft:nether_wart_block)
B(1,7,15,minecraft:nether_wart_block)
B(2,7,15,minecraft:nether_wart_block)
B(0,8,12,minecraft:nether_wart_block)
B(1,8,12,minecraft:nether_wart_block)
B(0,8,13,minecraft:nether_wart_block)
B(1,8,13,minecraft:nether_wart_block)
B(0,8,14,minecraft:nether_wart_block)
B(1,8,14,minecraft:nether_wart_block)
B(2,8,14,minecraft:nether_wart_block)
B(3,8,14,minecraft:nether_wart_block)
B(4,8,14,minecraft:nether_wart_block)
B(0,8,15,minecraft:nether_wart_block)
B(1,8,15,minecraft:nether_wart_block)
B(2,8,15,minecraft:nether_wart_block)
B(0,9,12,minecraft:nether_wart_block)
B(1,9,12,minecraft:nether_wart_block)
B(0,9,13,minecraft:nether_wart_block)
B(1,9,13,minecraft:nether_wart_block)
B(0,9,14,minecraft:nether_wart_block)
B(1,9,14,minecraft:nether_wart_block)
B(2,9,14,minecraft:nether_wart_block)
B(3,9,14,minecraft:nether_wart_block)
B(4,9,14,minecraft:nether_wart_block)
B(0,9,15,minecraft:nether_wart_block)
B(1,9,15,minecraft:nether_wart_block)
B(2,9,15,minecraft:nether_wart_block)
B(0,10,12,minecraft:nether_wart_block)
B(1,10,12,minecraft:nether_wart_block)
B(0,10,13,minecraft:nether_wart_block)
B(1,10,13,minecraft:nether_wart_block)
B(0,10,14,minecraft:nether_wart_block)
B(1,10,14,minecraft:nether_wart_block)
B(2,10,14,minecraft:nether_wart_block)
B(3,10,14,minecraft:nether_wart_block)
B(4,10,14,minecraft:nether_wart_block)
B(0,10,15,minecraft:nether_wart_block)
B(1,10,15,minecraft:nether_wart_block)
B(2,10,15,minecraft:nether_wart_block)
B(0,11,12,minecraft:nether_wart_block)
B(1,11,12,minecraft:nether_wart_block)
B(0,11,13,minecraft:nether_wart_block)
B(1,11,13,minecraft:nether_wart_block)
B(0,11,14,minecraft:nether_wart_block)
B(1,11,14,minecraft:nether_wart_block)
B(2,11,14,minecraft:nether_wart_block)
B(3,11,14,minecraft:nether_wart_block)
B(4,11,14,minecraft:nether_wart_block)
B(0,11,15,minecraft:nether_wart_block)
B(1,11,15,minecraft:nether_wart_block)
B(2,11,15,minecraft:nether_wart_block)
B(0,12,12,minecraft:nether_wart_block)
B(1,12,12,minecraft:nether_wart_block)
B(0,12,13,minecraft:nether_wart_block)
B(1,12,13,minecraft:nether_wart_block)
B(0,12,14,minecraft:nether_wart_block)
B(1,12,14,minecraft:nether_wart_block)
B(2,12,14,minecraft:nether_wart_block)
B(3,12,14,minecraft:nether_wart_block)
B(4,12,14,minecraft:nether_wart_block)
B(0,12,15,minecraft:nether_wart_block)
B(1,12,15,minecraft:nether_wart_block)
B(2,12,15,minecraft:nether_wart_block)
B(0,13,12,minecraft:nether_wart_block)
B(1,13,12,minecraft:nether_wart_block)
B(0,13,13,minecraft:nether_wart_block)
B(1,13,13,minecraft:nether_wart_block)
B(0,13,14,minecraft:nether_wart_block)
B(1,13,14,minecraft:nether_wart_block)
B(2,13,14,minecraft:nether_wart_block)
B(3,13,14,minecraft:nether_wart_block)
B(4,13,14,minecraft:nether_wart_block)
B(0,13,15,minecraft:nether_wart_block)
B(1,13,15,minecraft:nether_wart_block)
B(2,13,15,minecraft:nether_wart_block)
B(0,14,12,minecraft:nether_wart_block)
B(1,14,12,minecraft:nether_wart_block)
B(0,14,13,minecraft:nether_wart_block)
B(1,14,13,minecraft:nether_wart_block)
B(0,14,14,minecraft:nether_wart_block)
B(1,14,14,minecraft:nether_wart_block)
B(2,14,14,minecraft:nether_wart_block)
B(3,14,14,minecraft:nether_wart_block)
B(4,14,14,minecraft:nether_wart_block)
B(0,14,15,minecraft:nether_wart_block)
B(1,14,15,minecraft:nether_wart_block)
B(2,14,15,minecraft:nether_wart_block)
B(0,15,12,minecraft:nether_wart_block)
B(1,15,12,minecraft:nether_wart_block)
B(0,15,13,minecraft:nether_wart_block)
B(1,15,13,minecraft:nether_wart_block)
B(0,15,14,minecraft:nether_wart_block)
B(1,15,14,minecraft:nether_wart_block)
B(2,15,14,minecraft:nether_wart_block)
B(3,15,14,minecraft:nether_wart_block)
B(4,15,14,minecraft:nether_wart_block)
B(0,15,15,minecraft:nether_wart_block)
B(1,15,15,minecraft:nether_wart_block)
B(2,15,15,minecraft:nether_wart_block)
B(0,16,12,minecraft:nether_wart_block)
B(1,16,12,minecraft:nether_wart_block)
B(0,16,13,minecraft:nether_wart_block)
B(1,16,13,minecraft:nether_wart_block)
B(0,16,14,minecraft:nether_wart_block)
B(1,16,14,minecraft:nether_wart_block)
B(2,16,14,minecraft:nether_wart_block)
B(3,16,14,minecraft:nether_wart_block)
B(4,16,14,minecraft:nether_wart_block)
B(0,16,15,minecraft:nether_wart_block)
B(1,16,15,minecraft:nether_wart_block)
B(2,16,15,minecraft:nether_wart_block)
B(0,17,12,minecraft:nether_wart_block)
B(1,17,12,minecraft:nether_wart_block)
B(0,17,13,minecraft:nether_wart_block)
B(1,17,13,minecraft:nether_wart_block)
B(0,17,14,minecraft:nether_wart_block)
B(1,17,14,minecraft:nether_wart_block)
B(2,17,14,minecraft:nether_wart_block)
B(3,17,14,minecraft:nether_wart_block)
B(4,17,14,minecraft:nether_wart_block)
B(0,17,15,minecraft:nether_wart_block)
B(1,17,15,minecraft:nether_wart_block)
B(2,17,15,minecraft:nether_wart_block)
B(0,18,12,minecraft:nether_wart_block)
B(1,18,12,minecraft:nether_wart_block)
B(0,18,13,minecraft:nether_wart_block)
B(1,18,13,minecraft:nether_wart_block)
B(0,18,14,minecraft:nether_wart_block)
B(1,18,14,minecraft:nether_wart_block)
B(2,18,14,minecraft:nether_wart_block)
B(3,18,14,minecraft:nether_wart_block)
B(0,18,15,minecraft:nether_wart_block)
B(1,18,15,minecraft:nether_wart_block)
B(2,18,15,minecraft:nether_wart_block)
B(0,19,12,minecraft:nether_wart_block)
B(1,19,12,minecraft:nether_wart_block)
B(0,19,13,minecraft:nether_wart_block)
B(1,19,13,minecraft:nether_wart_block)
B(0,19,14,minecraft:nether_wart_block)
B(1,19,14,minecraft:nether_wart_block)
B(2,19,14,minecraft:nether_wart_block)
B(3,19,14,minecraft:nether_wart_block)
B(0,19,15,minecraft:nether_wart_block)
B(1,19,15,minecraft:nether_wart_block)
B(2,19,15,minecraft:nether_wart_block)
B(0,20,12,minecraft:nether_wart_block)
B(1,20,12,minecraft:nether_wart_block)
B(0,20,13,minecraft:nether_wart_block)
B(1,20,13,minecraft:nether_wart_block)
B(0,20,14,minecraft:nether_wart_block)
B(1,20,14,minecraft:nether_wart_block)
B(2,20,14,minecraft:nether_wart_block)
B(3,20,14,minecraft:nether_wart_block)
B(0,20,15,minecraft:nether_wart_block)
B(1,20,15,minecraft:nether_wart_block)
B(2,20,15,minecraft:nether_wart_block)
B(0,21,12,minecraft:nether_wart_block)
B(1,21,12,minecraft:nether_wart_block)
B(0,21,13,minecraft:nether_wart_block)
B(1,21,13,minecraft:nether_wart_block)
B(0,21,14,minecraft:nether_wart_block)
B(1,21,14,minecraft:nether_wart_block)
B(2,21,14,minecraft:nether_wart_block)
B(3,21,14,minecraft:nether_wart_block)
B(0,21,15,minecraft:nether_wart_block)
B(1,21,15,minecraft:nether_wart_block)
B(2,21,15,minecraft:nether_wart_block)
B(0,22,12,minecraft:nether_wart_block)
B(1,22,12,minecraft:nether_wart_block)
B(0,22,13,minecraft:nether_wart_block)
B(1,22,13,minecraft:nether_wart_block)
B(0,22,14,minecraft:nether_wart_block)
B(1,22,14,minecraft:nether_wart_block)
B(2,22,14,minecraft:nether_wart_block)
B(3,22,14,minecraft:nether_wart_block)
B(0,22,15,minecraft:nether_wart_block)
B(1,22,15,minecraft:nether_wart_block)
B(2,22,15,minecraft:nether_wart_block)
B(0,23,12,minecraft:nether_wart_block)
B(1,23,12,minecraft:nether_wart_block)
B(0,23,13,minecraft:nether_wart_block)
B(1,23,13,minecraft:nether_wart_block)
B(0,23,14,minecraft:nether_wart_block)
B(1,23,14,minecraft:nether_wart_block)
B(2,23,14,minecraft:nether_wart_block)
B(3,23,14,minecraft:nether_wart_block)
B(0,23,15,minecraft:nether_wart_block)
B(1,23,15,minecraft:nether_wart_block)
B(2,23,15,minecraft:nether_wart_block)
B(0,24,12,minecraft:nether_wart_block)
B(1,24,12,minecraft:nether_wart_block)
B(0,24,13,minecraft:nether_wart_block)
B(1,24,13,minecraft:nether_wart_block)
B(0,24,14,minecraft:nether_wart_block)
B(1,24,14,minecraft:nether_wart_block)
B(2,24,14,minecraft:nether_wart_block)
B(3,24,14,minecraft:nether_wart_block)
B(0,24,15,minecraft:nether_wart_block)
B(1,24,15,minecraft:nether_wart_block)
B(2,24,15,minecraft:nether_wart_block)
B(0,25,12,minecraft:nether_wart_block)
B(1,25,12,minecraft:nether_wart_block)
B(0,25,13,minecraft:nether_wart_block)
B(1,25,13,minecraft:nether_wart_block)
B(0,25,14,minecraft:nether_wart_block)
B(1,25,14,minecraft:nether_wart_block)
B(2,25,14,minecraft:nether_wart_block)
B(3,25,14,minecraft:nether_wart_block)
B(0,25,15,minecraft:nether_wart_block)
B(1,25,15,minecraft:nether_wart_block)
B(2,25,15,minecraft:nether_wart_block)
B(0,26,12,minecraft:nether_wart_block)
B(0,26,13,minecraft:nether_wart_block)
B(1,26,13,minecraft:nether_wart_block)
B(0,26,14,minecraft:nether_wart_block)
B(1,26,14,minecraft:nether_wart_block)
B(2,26,14,minecraft:nether_wart_block)
B(3,26,14,minecraft:nether_wart_block)
B(0,26,15,minecraft:nether_wart_block)
B(1,26,15,minecraft:nether_wart_block)
B(2,26,15,minecraft:nether_wart_block)
B(0,27,12,minecraft:nether_wart_block)
B(0,27,13,minecraft:nether_wart_block)
B(1,27,13,minecraft:nether_wart_block)
B(0,27,14,minecraft:nether_wart_block)
B(1,27,14,minecraft:nether_wart_block)
B(2,27,14,minecraft:nether_wart_block)
B(3,27,14,minecraft:nether_wart_block)
B(0,27,15,minecraft:nether_wart_block)
B(1,27,15,minecraft:nether_wart_block)
B(2,27,15,minecraft:nether_wart_block)
B(0,28,12,minecraft:nether_wart_block)
B(0,28,13,minecraft:nether_wart_block)
B(1,28,13,minecraft:nether_wart_block)
B(0,28,14,minecraft:nether_wart_block)
B(1,28,14,minecraft:nether_wart_block)
B(2,28,14,minecraft:nether_wart_block)
B(3,28,14,minecraft:nether_wart_block)
B(0,28,15,minecraft:nether_wart_block)
B(1,28,15,minecraft:nether_wart_block)
B(2,28,15,minecraft:nether_wart_block)
B(0,29,12,minecraft:nether_wart_block)
B(0,29,13,minecraft:nether_wart_block)
B(1,29,13,minecraft:nether_wart_block)
B(0,29,14,minecraft:nether_wart_block)
B(1,29,14,minecraft:nether_wart_block)
B(2,29,14,minecraft:nether_wart_block)
B(3,29,14,minecraft:nether_wart_block)
B(0,29,15,minecraft:nether_wart_block)
B(1,29,15,minecraft:nether_wart_block)
B(2,29,15,minecraft:nether_wart_block)
B(0,30,12,minecraft:nether_wart_block)
B(0,30,13,minecraft:nether_wart_block)
B(1,30,13,minecraft:nether_wart_block)
B(0,30,14,minecraft:nether_wart_block)
B(1,30,14,minecraft:nether_wart_block)
B(2,30,14,minecraft:nether_wart_block)
B(0,30,15,minecraft:nether_wart_block)
B(1,30,15,minecraft:nether_wart_block)
B(2,30,15,minecraft:nether_wart_block)
B(0,31,12,minecraft:nether_wart_block)
B(0,31,13,minecraft:nether_wart_block)
B(1,31,13,minecraft:nether_wart_block)
B(0,31,14,minecraft:nether_wart_block)
B(1,31,14,minecraft:nether_wart_block)
B(2,31,14,minecraft:nether_wart_block)
B(0,31,15,minecraft:nether_wart_block)
B(1,31,15,minecraft:nether_wart_block)
B(2,31,15,minecraft:nether_wart_block)
B(0,32,12,minecraft:nether_wart_block)
B(0,32,13,minecraft:nether_wart_block)
B(1,32,13,minecraft:nether_wart_block)
B(0,32,14,minecraft:nether_wart_block)
B(1,32,14,minecraft:nether_wart_block)
B(2,32,14,minecraft:nether_wart_block)
B(0,32,15,minecraft:nether_wart_block)
B(1,32,15,minecraft:nether_wart_block)
B(2,32,15,minecraft:nether_wart_block)
B(0,33,12,minecraft:nether_wart_block)
B(0,33,13,minecraft:nether_wart_block)
B(1,33,13,minecraft:nether_wart_block)
B(0,33,14,minecraft:nether_wart_block)
B(1,33,14,minecraft:nether_wart_block)
B(2,33,14,minecraft:nether_wart_block)
B(0,33,15,minecraft:nether_wart_block)
B(1,33,15,minecraft:nether_wart_block)
B(2,33,15,minecraft:nether_wart_block)
B(0,34,12,minecraft:nether_wart_block)
B(0,34,13,minecraft:nether_wart_block)
B(1,34,13,minecraft:nether_wart_block)
B(0,34,14,minecraft:nether_wart_block)
B(1,34,14,minecraft:nether_wart_block)
B(2,34,14,minecraft:nether_wart_block)
B(0,34,15,minecraft:nether_wart_block)
B(1,34,15,minecraft:nether_wart_block)
B(2,34,15,minecraft:nether_wart_block)
B(0,35,12,minecraft:nether_wart_block)
B(0,35,13,minecraft:nether_wart_block)
B(1,35,13,minecraft:nether_wart_block)
B(0,35,14,minecraft:nether_wart_block)
B(1,35,14,minecraft:nether_wart_block)
B(2,35,14,minecraft:nether_wart_block)
B(0,35,15,minecraft:nether_wart_block)
B(1,35,15,minecraft:nether_wart_block)
B(2,35,15,minecraft:nether_wart_block)
B(0,36,12,minecraft:nether_wart_block)
B(0,36,13,minecraft:nether_wart_block)
B(1,36,13,minecraft:nether_wart_block)
B(0,36,14,minecraft:nether_wart_block)
B(1,36,14,minecraft:nether_wart_block)
B(2,36,14,minecraft:nether_wart_block)
B(0,36,15,minecraft:nether_wart_block)
B(1,36,15,minecraft:nether_wart_block)
B(2,36,15,minecraft:nether_wart_block)
B(0,37,12,minecraft:nether_wart_block)
B(0,37,13,minecraft:nether_wart_block)
B(1,37,13,minecraft:nether_wart_block)
B(0,37,14,minecraft:nether_wart_block)
B(1,37,14,minecraft:nether_wart_block)
B(2,37,14,minecraft:nether_wart_block)
B(0,37,15,minecraft:nether_wart_block)
B(1,37,15,minecraft:nether_wart_block)
B(2,37,15,minecraft:nether_wart_block)
B(0,38,12,minecraft:nether_wart_block)
B(0,38,13,minecraft:nether_wart_block)
B(1,38,13,minecraft:nether_wart_block)
B(0,38,14,minecraft:nether_wart_block)
B(1,38,14,minecraft:nether_wart_block)
B(2,38,14,minecraft:nether_wart_block)
B(0,38,15,minecraft:nether_wart_block)
B(1,38,15,minecraft:nether_wart_block)
B(2,38,15,minecraft:nether_wart_block)
B(0,39,12,minecraft:nether_wart_block)
B(0,39,13,minecraft:nether_wart_block)
B(1,39,13,minecraft:nether_wart_block)
B(0,39,14,minecraft:nether_wart_block)
B(1,39,14,minecraft:nether_wart_block)
B(2,39,14,minecraft:nether_wart_block)
B(0,39,15,minecraft:nether_wart_block)
B(1,39,15,minecraft:nether_wart_block)
B(2,39,15,minecraft:nether_wart_block)
B(0,40,12,minecraft:nether_wart_block)
B(0,40,13,minecraft:nether_wart_block)
B(1,40,13,minecraft:nether_wart_block)
B(0,40,14,minecraft:nether_wart_block)
B(1,40,14,minecraft:nether_wart_block)
B(2,40,14,minecraft:nether_wart_block)
B(0,40,15,minecraft:nether_wart_block)
B(1,40,15,minecraft:nether_wart_block)
B(2,40,15,minecraft:nether_wart_block)
B(0,41,12,minecraft:nether_wart_block)
B(0,41,13,minecraft:nether_wart_block)
B(1,41,13,minecraft:nether_wart_block)
B(0,41,14,minecraft:nether_wart_block)
B(1,41,14,minecraft:nether_wart_block)
B(2,41,14,minecraft:nether_wart_block)
B(0,41,15,minecraft:nether_wart_block)
B(1,41,15,minecraft:nether_wart_block)
B(2,41,15,minecraft:nether_wart_block)
B(0,42,12,minecraft:nether_wart_block)
B(0,42,13,minecraft:nether_wart_block)
B(1,42,13,minecraft:nether_wart_block)
B(0,42,14,minecraft:nether_wart_block)
B(1,42,14,minecraft:nether_wart_block)
B(2,42,14,minecraft:nether_wart_block)
B(0,42,15,minecraft:nether_wart_block)
B(1,42,15,minecraft:nether_wart_block)
B(2,42,15,minecraft:nether_wart_block)
B(0,43,12,minecraft:nether_wart_block)
B(0,43,13,minecraft:nether_wart_block)
B(1,43,13,minecraft:nether_wart_block)
B(0,43,14,minecraft:nether_wart_block)
B(1,43,14,minecraft:nether_wart_block)
B(2,43,14,minecraft:nether_wart_block)
B(0,43,15,minecraft:nether_wart_block)
B(1,43,15,minecraft:nether_wart_block)
B(2,43,15,minecraft:nether_wart_block)
B(0,44,12,minecraft:nether_wart_block)
B(0,44,13,minecraft:nether_wart_block)
B(1,44,13,minecraft:nether_wart_block)
B(0,44,14,minecraft:nether_wart_block)
B(1,44,14,minecraft:nether_wart_block)
B(2,44,14,minecraft:nether_wart_block)
B(0,44,15,minecraft:nether_wart_block)
B(1,44,15,minecraft:nether_wart_block)
B(2,44,15,minecraft:nether_wart_block)
B(0,45,12,minecraft:nether_wart_block)
B(0,45,13,minecraft:nether_wart_block)
B(1,45,13,minecraft:nether_wart_block)
B(0,45,14,minecraft:nether_wart_block)
B(1,45,14,minecraft:nether_wart_block)
B(2,45,14,minecraft:nether_wart_block)
B(0,45,15,minecraft:nether_wart_block)
B(1,45,15,minecraft:nether_wart_block)
B(2,45,15,minecraft:nether_wart_block)
B(0,46,12,minecraft:nether_wart_block)
B(0,46,13,minecraft:nether_wart_block)
B(1,46,13,minecraft:nether_wart_block)
B(0,46,14,minecraft:nether_wart_block)
B(1,46,14,minecraft:nether_wart_block)
B(2,46,14,minecraft:nether_wart_block)
B(0,46,15,minecraft:nether_wart_block)
B(1,46,15,minecraft:nether_wart_block)
B(2,46,15,minecraft:nether_wart_block)
B(0,47,12,minecraft:nether_wart_block)
B(0,47,13,minecraft:nether_wart_block)
B(1,47,13,minecraft:nether_wart_block)
B(0,47,14,minecraft:nether_wart_block)
B(1,47,14,minecraft:nether_wart_block)
B(2,47,14,minecraft:nether_wart_block)
B(0,47,15,minecraft:nether_wart_block)
B(1,47,15,minecraft:nether_wart_block)
B(2,47,15,minecraft:nether_wart_block)
B(0,48,12,minecraft:nether_wart_block)
B(0,48,13,minecraft:nether_wart_block)
B(1,48,13,minecraft:nether_wart_block)
B(0,48,14,minecraft:nether_wart_block)
B(1,48,14,minecraft:nether_wart_block)
B(2,48,14,minecraft:nether_wart_block)
B(0,48,15,minecraft:nether_wart_block)
B(1,48,15,minecraft:nether_wart_block)
B(2,48,15,minecraft:nether_wart_block)
B(0,49,12,minecraft:nether_wart_block)
B(0,49,13,minecraft:nether_wart_block)
B(1,49,13,minecraft:nether_wart_block)
B(0,49,14,minecraft:nether_wart_block)
B(1,49,14,minecraft:nether_wart_block)
B(2,49,14,minecraft:nether_wart_block)
B(0,49,15,minecraft:nether_wart_block)
B(1,49,15,minecraft:nether_wart_block)
B(2,49,15,minecraft:nether_wart_block)
B(0,50,13,minecraft:nether_wart_block)
B(1,50,13,minecraft:nether_wart_block)
B(0,50,14,minecraft:nether_wart_block)
B(1,50,14,minecraft:nether_wart_block)
B(2,50,14,minecraft:nether_wart_block)
B(0,50,15,minecraft:nether_wart_block)
B(1,50,15,minecraft:nether_wart_block)
B(2,50,15,minecraft:nether_wart_block)
B(0,51,13,minecraft:nether_wart_block)
B(1,51,13,minecraft:nether_wart_block)
B(0,51,14,minecraft:nether_wart_block)
B(1,51,14,minecraft:nether_wart_block)
B(2,51,14,minecraft:nether_wart_block)
B(0,51,15,minecraft:nether_wart_block)
B(1,51,15,minecraft:nether_wart_block)
B(2,51,15,minecraft:nether_wart_block)
B(0,52,14,minecraft:nether_wart_block)
B(1,52,14,minecraft:nether_wart_block)
B(2,52,14,minecraft:nether_wart_block)
B(0,52,15,minecraft:nether_wart_block)
B(1,52,15,minecraft:nether_wart_block)
B(2,52,15,minecraft:nether_wart_block)
B(1,53,14,minecraft:nether_wart_block)
B(2,53,14,minecraft:nether_wart_block)
B(0,53,15,minecraft:nether_wart_block)
B(1,53,15,minecraft:nether_wart_block)
B(2,53,15,minecraft:nether_wart_block)
B(0,54,15,minecraft:nether_wart_block)
B(1,54,15,minecraft:nether_wart_block)
B(2,54,15,minecraft:nether_wart_block)

