Author: Bo3 BulkEdit

Description: Converted Schematic - Modified by Bo3BulkEdit

Version: 3

SettingsMode: WriteDisable

IsOTGPlus: true
Tree: false
Frequency: 10
Rarity: 100
RotateRandomly: true
SpawnHeight: randomY
SpawnHeightOffset: 0
SpawnHeightVariance: 0
MaxBranchDepth: 10
ExcludedBiomes: All

MinHeight: 50
MaxHeight: 65

SourceBlocks: AIR
MaxPercentageOutsideSourceBlock: 100
OutsideSourceBlock: placeAnyway

ReplaceBelow: NETHER_WART_BLOCK
ReplaceWithBiomeBlocks: false
ReplaceWithGroundBlock: NETHER_WART_BLOCK
ReplaceWithSurfaceBlock: NETHER_WART_BLOCK
ReplaceWithStoneBlock: NETHER_WART_BLOCK
SmoothRadius: 30
SmoothHeightOffset: 0
SmoothStartTop: false
SmoothStartWood: false
SmoothingSurfaceBlock: NETHER_WART_BLOCK
SmoothingGroundBlock: NETHER_WART_BLOCK

B(0,750,0,AIR)
B(15,750,15,AIR)
B(0,0,0,minecraft:nether_wart_block)
B(1,0,0,minecraft:nether_wart_block)
B(2,0,0,minecraft:nether_wart_block)
B(3,0,0,minecraft:nether_wart_block)
B(7,0,0,minecraft:nether_wart_block)
B(8,0,0,minecraft:nether_wart_block)
B(9,0,0,minecraft:nether_wart_block)
B(10,0,0,minecraft:nether_wart_block)
B(11,0,0,minecraft:nether_wart_block)
B(12,0,0,minecraft:nether_wart_block)
B(13,0,0,minecraft:nether_wart_block)
B(14,0,0,minecraft:nether_wart_block)
B(15,0,0,minecraft:nether_wart_block)
B(0,0,1,minecraft:nether_wart_block)
B(1,0,1,minecraft:nether_wart_block)
B(2,0,1,minecraft:nether_wart_block)
B(3,0,1,minecraft:nether_wart_block)
B(4,0,1,minecraft:nether_wart_block)
B(7,0,1,minecraft:nether_wart_block)
B(8,0,1,minecraft:nether_wart_block)
B(9,0,1,minecraft:nether_wart_block)
B(10,0,1,minecraft:nether_wart_block)
B(11,0,1,minecraft:nether_wart_block)
B(12,0,1,minecraft:nether_wart_block)
B(13,0,1,minecraft:nether_wart_block)
B(14,0,1,minecraft:nether_wart_block)
B(15,0,1,minecraft:nether_wart_block)
B(0,0,2,minecraft:nether_wart_block)
B(1,0,2,minecraft:nether_wart_block)
B(2,0,2,minecraft:nether_wart_block)
B(3,0,2,minecraft:nether_wart_block)
B(4,0,2,minecraft:nether_wart_block)
B(5,0,2,minecraft:nether_wart_block)
B(6,0,2,minecraft:nether_wart_block)
B(7,0,2,minecraft:nether_wart_block)
B(8,0,2,minecraft:nether_wart_block)
B(9,0,2,minecraft:nether_wart_block)
B(10,0,2,minecraft:nether_wart_block)
B(11,0,2,minecraft:nether_wart_block)
B(12,0,2,minecraft:nether_wart_block)
B(13,0,2,minecraft:nether_wart_block)
B(14,0,2,minecraft:nether_wart_block)
B(15,0,2,minecraft:nether_wart_block)
B(0,0,3,minecraft:nether_wart_block)
B(1,0,3,minecraft:nether_wart_block)
B(2,0,3,minecraft:nether_wart_block)
B(3,0,3,minecraft:nether_wart_block)
B(4,0,3,minecraft:nether_wart_block)
B(5,0,3,minecraft:nether_wart_block)
B(6,0,3,minecraft:nether_wart_block)
B(7,0,3,minecraft:nether_wart_block)
B(8,0,3,minecraft:nether_wart_block)
B(9,0,3,minecraft:nether_wart_block)
B(10,0,3,minecraft:nether_wart_block)
B(11,0,3,minecraft:nether_wart_block)
B(12,0,3,minecraft:nether_wart_block)
B(13,0,3,minecraft:nether_wart_block)
B(14,0,3,minecraft:nether_wart_block)
B(15,0,3,minecraft:nether_wart_block)
B(0,0,4,minecraft:nether_wart_block)
B(1,0,4,minecraft:nether_wart_block)
B(2,0,4,minecraft:nether_wart_block)
B(3,0,4,minecraft:nether_wart_block)
B(4,0,4,minecraft:nether_wart_block)
B(5,0,4,minecraft:nether_wart_block)
B(6,0,4,minecraft:nether_wart_block)
B(7,0,4,minecraft:nether_wart_block)
B(8,0,4,minecraft:nether_wart_block)
B(9,0,4,minecraft:nether_wart_block)
B(10,0,4,minecraft:nether_wart_block)
B(11,0,4,minecraft:nether_wart_block)
B(12,0,4,minecraft:nether_wart_block)
B(13,0,4,minecraft:nether_wart_block)
B(14,0,4,minecraft:nether_wart_block)
B(15,0,4,minecraft:nether_wart_block)
B(0,0,5,minecraft:nether_wart_block)
B(1,0,5,minecraft:nether_wart_block)
B(2,0,5,minecraft:nether_wart_block)
B(3,0,5,minecraft:nether_wart_block)
B(4,0,5,minecraft:nether_wart_block)
B(5,0,5,minecraft:nether_wart_block)
B(6,0,5,minecraft:nether_wart_block)
B(7,0,5,minecraft:nether_wart_block)
B(8,0,5,minecraft:nether_wart_block)
B(9,0,5,minecraft:nether_wart_block)
B(10,0,5,minecraft:nether_wart_block)
B(11,0,5,minecraft:nether_wart_block)
B(12,0,5,minecraft:nether_wart_block)
B(13,0,5,minecraft:nether_wart_block)
B(14,0,5,minecraft:nether_wart_block)
B(15,0,5,minecraft:nether_wart_block)
B(0,0,6,minecraft:nether_wart_block)
B(1,0,6,minecraft:nether_wart_block)
B(2,0,6,minecraft:nether_wart_block)
B(3,0,6,minecraft:nether_wart_block)
B(4,0,6,minecraft:nether_wart_block)
B(5,0,6,minecraft:nether_wart_block)
B(6,0,6,minecraft:nether_wart_block)
B(7,0,6,minecraft:nether_wart_block)
B(8,0,6,minecraft:nether_wart_block)
B(9,0,6,minecraft:nether_wart_block)
B(10,0,6,minecraft:nether_wart_block)
B(11,0,6,minecraft:nether_wart_block)
B(12,0,6,minecraft:nether_wart_block)
B(13,0,6,minecraft:nether_wart_block)
B(14,0,6,minecraft:nether_wart_block)
B(15,0,6,minecraft:nether_wart_block)
B(0,0,7,minecraft:nether_wart_block)
B(1,0,7,minecraft:nether_wart_block)
B(2,0,7,minecraft:nether_wart_block)
B(3,0,7,minecraft:nether_wart_block)
B(4,0,7,minecraft:nether_wart_block)
B(5,0,7,minecraft:nether_wart_block)
B(6,0,7,minecraft:nether_wart_block)
B(7,0,7,minecraft:nether_wart_block)
B(8,0,7,minecraft:nether_wart_block)
B(9,0,7,minecraft:nether_wart_block)
B(10,0,7,minecraft:nether_wart_block)
B(11,0,7,minecraft:nether_wart_block)
B(12,0,7,minecraft:nether_wart_block)
B(13,0,7,minecraft:nether_wart_block)
B(14,0,7,minecraft:nether_wart_block)
B(15,0,7,minecraft:nether_wart_block)
B(0,0,8,minecraft:nether_wart_block)
B(1,0,8,minecraft:nether_wart_block)
B(2,0,8,minecraft:nether_wart_block)
B(3,0,8,minecraft:nether_wart_block)
B(4,0,8,minecraft:nether_wart_block)
B(5,0,8,minecraft:nether_wart_block)
B(6,0,8,minecraft:nether_wart_block)
B(7,0,8,minecraft:nether_wart_block)
B(8,0,8,minecraft:nether_wart_block)
B(9,0,8,minecraft:nether_wart_block)
B(10,0,8,minecraft:nether_wart_block)
B(11,0,8,minecraft:nether_wart_block)
B(12,0,8,minecraft:nether_wart_block)
B(13,0,8,minecraft:nether_wart_block)
B(14,0,8,minecraft:nether_wart_block)
B(15,0,8,minecraft:nether_wart_block)
B(0,0,9,minecraft:nether_wart_block)
B(1,0,9,minecraft:nether_wart_block)
B(2,0,9,minecraft:nether_wart_block)
B(3,0,9,minecraft:nether_wart_block)
B(4,0,9,minecraft:nether_wart_block)
B(5,0,9,minecraft:nether_wart_block)
B(6,0,9,minecraft:nether_wart_block)
B(7,0,9,minecraft:nether_wart_block)
B(8,0,9,minecraft:nether_wart_block)
B(9,0,9,minecraft:nether_wart_block)
B(10,0,9,minecraft:nether_wart_block)
B(11,0,9,minecraft:nether_wart_block)
B(12,0,9,minecraft:nether_wart_block)
B(13,0,9,minecraft:nether_wart_block)
B(14,0,9,minecraft:nether_wart_block)
B(15,0,9,minecraft:nether_wart_block)
B(2,0,10,minecraft:nether_wart_block)
B(3,0,10,minecraft:nether_wart_block)
B(4,0,10,minecraft:nether_wart_block)
B(5,0,10,minecraft:nether_wart_block)
B(6,0,10,minecraft:nether_wart_block)
B(7,0,10,minecraft:nether_wart_block)
B(8,0,10,minecraft:nether_wart_block)
B(9,0,10,minecraft:nether_wart_block)
B(10,0,10,minecraft:nether_wart_block)
B(11,0,10,minecraft:nether_wart_block)
B(12,0,10,minecraft:nether_wart_block)
B(13,0,10,minecraft:nether_wart_block)
B(14,0,10,minecraft:nether_wart_block)
B(15,0,10,minecraft:nether_wart_block)
B(3,0,11,minecraft:nether_wart_block)
B(4,0,11,minecraft:nether_wart_block)
B(5,0,11,minecraft:nether_wart_block)
B(13,0,11,minecraft:nether_wart_block)
B(14,0,11,minecraft:nether_wart_block)
B(15,0,11,minecraft:nether_wart_block)
B(0,1,0,minecraft:nether_wart_block)
B(1,1,0,minecraft:nether_wart_block)
B(2,1,0,minecraft:nether_wart_block)
B(3,1,0,minecraft:nether_wart_block)
B(7,1,0,minecraft:nether_wart_block)
B(8,1,0,minecraft:nether_wart_block)
B(9,1,0,minecraft:nether_wart_block)
B(10,1,0,minecraft:nether_wart_block)
B(11,1,0,minecraft:nether_wart_block)
B(12,1,0,minecraft:nether_wart_block)
B(13,1,0,minecraft:nether_wart_block)
B(14,1,0,minecraft:nether_wart_block)
B(15,1,0,minecraft:nether_wart_block)
B(0,1,1,minecraft:nether_wart_block)
B(1,1,1,minecraft:nether_wart_block)
B(2,1,1,minecraft:nether_wart_block)
B(3,1,1,minecraft:nether_wart_block)
B(4,1,1,minecraft:nether_wart_block)
B(7,1,1,minecraft:nether_wart_block)
B(8,1,1,minecraft:nether_wart_block)
B(9,1,1,minecraft:nether_wart_block)
B(10,1,1,minecraft:nether_wart_block)
B(11,1,1,minecraft:nether_wart_block)
B(12,1,1,minecraft:nether_wart_block)
B(13,1,1,minecraft:nether_wart_block)
B(14,1,1,minecraft:nether_wart_block)
B(15,1,1,minecraft:nether_wart_block)
B(0,1,2,minecraft:nether_wart_block)
B(1,1,2,minecraft:nether_wart_block)
B(2,1,2,minecraft:nether_wart_block)
B(3,1,2,minecraft:nether_wart_block)
B(4,1,2,minecraft:nether_wart_block)
B(5,1,2,minecraft:nether_wart_block)
B(6,1,2,minecraft:nether_wart_block)
B(7,1,2,minecraft:nether_wart_block)
B(8,1,2,minecraft:nether_wart_block)
B(9,1,2,minecraft:nether_wart_block)
B(10,1,2,minecraft:nether_wart_block)
B(11,1,2,minecraft:nether_wart_block)
B(12,1,2,minecraft:nether_wart_block)
B(13,1,2,minecraft:nether_wart_block)
B(14,1,2,minecraft:nether_wart_block)
B(15,1,2,minecraft:nether_wart_block)
B(0,1,3,minecraft:nether_wart_block)
B(1,1,3,minecraft:nether_wart_block)
B(2,1,3,minecraft:nether_wart_block)
B(3,1,3,minecraft:nether_wart_block)
B(4,1,3,minecraft:nether_wart_block)
B(5,1,3,minecraft:nether_wart_block)
B(6,1,3,minecraft:nether_wart_block)
B(7,1,3,minecraft:nether_wart_block)
B(8,1,3,minecraft:nether_wart_block)
B(9,1,3,minecraft:nether_wart_block)
B(10,1,3,minecraft:nether_wart_block)
B(11,1,3,minecraft:nether_wart_block)
B(12,1,3,minecraft:nether_wart_block)
B(13,1,3,minecraft:nether_wart_block)
B(14,1,3,minecraft:nether_wart_block)
B(15,1,3,minecraft:nether_wart_block)
B(0,1,4,minecraft:nether_wart_block)
B(1,1,4,minecraft:nether_wart_block)
B(2,1,4,minecraft:nether_wart_block)
B(3,1,4,minecraft:nether_wart_block)
B(4,1,4,minecraft:nether_wart_block)
B(5,1,4,minecraft:nether_wart_block)
B(6,1,4,minecraft:nether_wart_block)
B(7,1,4,minecraft:nether_wart_block)
B(8,1,4,minecraft:nether_wart_block)
B(9,1,4,minecraft:nether_wart_block)
B(10,1,4,minecraft:nether_wart_block)
B(11,1,4,minecraft:nether_wart_block)
B(12,1,4,minecraft:nether_wart_block)
B(13,1,4,minecraft:nether_wart_block)
B(14,1,4,minecraft:nether_wart_block)
B(15,1,4,minecraft:nether_wart_block)
B(0,1,5,minecraft:nether_wart_block)
B(1,1,5,minecraft:nether_wart_block)
B(2,1,5,minecraft:nether_wart_block)
B(3,1,5,minecraft:nether_wart_block)
B(4,1,5,minecraft:nether_wart_block)
B(5,1,5,minecraft:nether_wart_block)
B(6,1,5,minecraft:nether_wart_block)
B(7,1,5,minecraft:nether_wart_block)
B(8,1,5,minecraft:nether_wart_block)
B(9,1,5,minecraft:nether_wart_block)
B(10,1,5,minecraft:nether_wart_block)
B(11,1,5,minecraft:nether_wart_block)
B(12,1,5,minecraft:nether_wart_block)
B(13,1,5,minecraft:nether_wart_block)
B(14,1,5,minecraft:nether_wart_block)
B(15,1,5,minecraft:nether_wart_block)
B(0,1,6,minecraft:nether_wart_block)
B(1,1,6,minecraft:nether_wart_block)
B(2,1,6,minecraft:nether_wart_block)
B(3,1,6,minecraft:nether_wart_block)
B(4,1,6,minecraft:nether_wart_block)
B(5,1,6,minecraft:nether_wart_block)
B(6,1,6,minecraft:nether_wart_block)
B(7,1,6,minecraft:nether_wart_block)
B(8,1,6,minecraft:nether_wart_block)
B(9,1,6,minecraft:nether_wart_block)
B(10,1,6,minecraft:nether_wart_block)
B(11,1,6,minecraft:nether_wart_block)
B(12,1,6,minecraft:nether_wart_block)
B(13,1,6,minecraft:nether_wart_block)
B(14,1,6,minecraft:nether_wart_block)
B(15,1,6,minecraft:nether_wart_block)
B(0,1,7,minecraft:nether_wart_block)
B(1,1,7,minecraft:nether_wart_block)
B(2,1,7,minecraft:nether_wart_block)
B(3,1,7,minecraft:nether_wart_block)
B(4,1,7,minecraft:nether_wart_block)
B(5,1,7,minecraft:nether_wart_block)
B(6,1,7,minecraft:nether_wart_block)
B(7,1,7,minecraft:nether_wart_block)
B(8,1,7,minecraft:nether_wart_block)
B(9,1,7,minecraft:nether_wart_block)
B(10,1,7,minecraft:nether_wart_block)
B(11,1,7,minecraft:nether_wart_block)
B(12,1,7,minecraft:nether_wart_block)
B(13,1,7,minecraft:nether_wart_block)
B(14,1,7,minecraft:nether_wart_block)
B(15,1,7,minecraft:nether_wart_block)
B(0,1,8,minecraft:nether_wart_block)
B(1,1,8,minecraft:nether_wart_block)
B(2,1,8,minecraft:nether_wart_block)
B(3,1,8,minecraft:nether_wart_block)
B(4,1,8,minecraft:nether_wart_block)
B(5,1,8,minecraft:nether_wart_block)
B(6,1,8,minecraft:nether_wart_block)
B(7,1,8,minecraft:nether_wart_block)
B(8,1,8,minecraft:nether_wart_block)
B(9,1,8,minecraft:nether_wart_block)
B(10,1,8,minecraft:nether_wart_block)
B(11,1,8,minecraft:nether_wart_block)
B(12,1,8,minecraft:nether_wart_block)
B(13,1,8,minecraft:nether_wart_block)
B(14,1,8,minecraft:nether_wart_block)
B(15,1,8,minecraft:nether_wart_block)
B(0,1,9,minecraft:nether_wart_block)
B(1,1,9,minecraft:nether_wart_block)
B(2,1,9,minecraft:nether_wart_block)
B(3,1,9,minecraft:nether_wart_block)
B(4,1,9,minecraft:nether_wart_block)
B(5,1,9,minecraft:nether_wart_block)
B(6,1,9,minecraft:nether_wart_block)
B(7,1,9,minecraft:nether_wart_block)
B(8,1,9,minecraft:nether_wart_block)
B(9,1,9,minecraft:nether_wart_block)
B(10,1,9,minecraft:nether_wart_block)
B(11,1,9,minecraft:nether_wart_block)
B(12,1,9,minecraft:nether_wart_block)
B(13,1,9,minecraft:nether_wart_block)
B(14,1,9,minecraft:nether_wart_block)
B(15,1,9,minecraft:nether_wart_block)
B(2,1,10,minecraft:nether_wart_block)
B(3,1,10,minecraft:nether_wart_block)
B(4,1,10,minecraft:nether_wart_block)
B(5,1,10,minecraft:nether_wart_block)
B(6,1,10,minecraft:nether_wart_block)
B(7,1,10,minecraft:nether_wart_block)
B(8,1,10,minecraft:nether_wart_block)
B(9,1,10,minecraft:nether_wart_block)
B(10,1,10,minecraft:nether_wart_block)
B(11,1,10,minecraft:nether_wart_block)
B(12,1,10,minecraft:nether_wart_block)
B(13,1,10,minecraft:nether_wart_block)
B(14,1,10,minecraft:nether_wart_block)
B(15,1,10,minecraft:nether_wart_block)
B(3,1,11,minecraft:nether_wart_block)
B(4,1,11,minecraft:nether_wart_block)
B(5,1,11,minecraft:nether_wart_block)
B(13,1,11,minecraft:nether_wart_block)
B(14,1,11,minecraft:nether_wart_block)
B(15,1,11,minecraft:nether_wart_block)
B(0,2,0,minecraft:nether_wart_block)
B(1,2,0,minecraft:nether_wart_block)
B(2,2,0,minecraft:nether_wart_block)
B(3,2,0,minecraft:nether_wart_block)
B(7,2,0,minecraft:nether_wart_block)
B(8,2,0,minecraft:nether_wart_block)
B(9,2,0,minecraft:nether_wart_block)
B(10,2,0,minecraft:nether_wart_block)
B(11,2,0,minecraft:nether_wart_block)
B(12,2,0,minecraft:nether_wart_block)
B(13,2,0,minecraft:nether_wart_block)
B(14,2,0,minecraft:nether_wart_block)
B(15,2,0,minecraft:nether_wart_block)
B(0,2,1,minecraft:nether_wart_block)
B(1,2,1,minecraft:nether_wart_block)
B(2,2,1,minecraft:nether_wart_block)
B(3,2,1,minecraft:nether_wart_block)
B(4,2,1,minecraft:nether_wart_block)
B(7,2,1,minecraft:nether_wart_block)
B(8,2,1,minecraft:nether_wart_block)
B(9,2,1,minecraft:nether_wart_block)
B(10,2,1,minecraft:nether_wart_block)
B(11,2,1,minecraft:nether_wart_block)
B(12,2,1,minecraft:nether_wart_block)
B(13,2,1,minecraft:nether_wart_block)
B(14,2,1,minecraft:nether_wart_block)
B(15,2,1,minecraft:nether_wart_block)
B(0,2,2,minecraft:nether_wart_block)
B(1,2,2,minecraft:nether_wart_block)
B(2,2,2,minecraft:nether_wart_block)
B(3,2,2,minecraft:nether_wart_block)
B(4,2,2,minecraft:nether_wart_block)
B(5,2,2,minecraft:nether_wart_block)
B(6,2,2,minecraft:nether_wart_block)
B(7,2,2,minecraft:nether_wart_block)
B(8,2,2,minecraft:nether_wart_block)
B(9,2,2,minecraft:nether_wart_block)
B(10,2,2,minecraft:nether_wart_block)
B(11,2,2,minecraft:nether_wart_block)
B(12,2,2,minecraft:nether_wart_block)
B(13,2,2,minecraft:nether_wart_block)
B(14,2,2,minecraft:nether_wart_block)
B(15,2,2,minecraft:nether_wart_block)
B(0,2,3,minecraft:nether_wart_block)
B(1,2,3,minecraft:nether_wart_block)
B(2,2,3,minecraft:nether_wart_block)
B(3,2,3,minecraft:nether_wart_block)
B(4,2,3,minecraft:nether_wart_block)
B(5,2,3,minecraft:nether_wart_block)
B(6,2,3,minecraft:nether_wart_block)
B(7,2,3,minecraft:nether_wart_block)
B(8,2,3,minecraft:nether_wart_block)
B(9,2,3,minecraft:nether_wart_block)
B(10,2,3,minecraft:nether_wart_block)
B(11,2,3,minecraft:nether_wart_block)
B(12,2,3,minecraft:nether_wart_block)
B(13,2,3,minecraft:nether_wart_block)
B(14,2,3,minecraft:nether_wart_block)
B(15,2,3,minecraft:nether_wart_block)
B(0,2,4,minecraft:nether_wart_block)
B(1,2,4,minecraft:nether_wart_block)
B(2,2,4,minecraft:nether_wart_block)
B(3,2,4,minecraft:nether_wart_block)
B(4,2,4,minecraft:nether_wart_block)
B(5,2,4,minecraft:nether_wart_block)
B(6,2,4,minecraft:nether_wart_block)
B(7,2,4,minecraft:nether_wart_block)
B(8,2,4,minecraft:nether_wart_block)
B(9,2,4,minecraft:nether_wart_block)
B(10,2,4,minecraft:nether_wart_block)
B(11,2,4,minecraft:nether_wart_block)
B(12,2,4,minecraft:nether_wart_block)
B(13,2,4,minecraft:nether_wart_block)
B(14,2,4,minecraft:nether_wart_block)
B(15,2,4,minecraft:nether_wart_block)
B(0,2,5,minecraft:nether_wart_block)
B(1,2,5,minecraft:nether_wart_block)
B(2,2,5,minecraft:nether_wart_block)
B(3,2,5,minecraft:nether_wart_block)
B(4,2,5,minecraft:nether_wart_block)
B(5,2,5,minecraft:nether_wart_block)
B(6,2,5,minecraft:nether_wart_block)
B(7,2,5,minecraft:nether_wart_block)
B(8,2,5,minecraft:nether_wart_block)
B(9,2,5,minecraft:nether_wart_block)
B(10,2,5,minecraft:nether_wart_block)
B(11,2,5,minecraft:nether_wart_block)
B(12,2,5,minecraft:nether_wart_block)
B(13,2,5,minecraft:nether_wart_block)
B(14,2,5,minecraft:nether_wart_block)
B(15,2,5,minecraft:nether_wart_block)
B(0,2,6,minecraft:nether_wart_block)
B(1,2,6,minecraft:nether_wart_block)
B(2,2,6,minecraft:nether_wart_block)
B(3,2,6,minecraft:nether_wart_block)
B(4,2,6,minecraft:nether_wart_block)
B(5,2,6,minecraft:nether_wart_block)
B(6,2,6,minecraft:nether_wart_block)
B(7,2,6,minecraft:nether_wart_block)
B(8,2,6,minecraft:nether_wart_block)
B(9,2,6,minecraft:nether_wart_block)
B(10,2,6,minecraft:nether_wart_block)
B(11,2,6,minecraft:nether_wart_block)
B(12,2,6,minecraft:nether_wart_block)
B(13,2,6,minecraft:nether_wart_block)
B(14,2,6,minecraft:nether_wart_block)
B(15,2,6,minecraft:nether_wart_block)
B(0,2,7,minecraft:nether_wart_block)
B(1,2,7,minecraft:nether_wart_block)
B(2,2,7,minecraft:nether_wart_block)
B(3,2,7,minecraft:nether_wart_block)
B(4,2,7,minecraft:nether_wart_block)
B(5,2,7,minecraft:nether_wart_block)
B(6,2,7,minecraft:nether_wart_block)
B(7,2,7,minecraft:nether_wart_block)
B(8,2,7,minecraft:nether_wart_block)
B(9,2,7,minecraft:nether_wart_block)
B(10,2,7,minecraft:nether_wart_block)
B(11,2,7,minecraft:nether_wart_block)
B(12,2,7,minecraft:nether_wart_block)
B(13,2,7,minecraft:nether_wart_block)
B(14,2,7,minecraft:nether_wart_block)
B(15,2,7,minecraft:nether_wart_block)
B(0,2,8,minecraft:nether_wart_block)
B(1,2,8,minecraft:nether_wart_block)
B(2,2,8,minecraft:nether_wart_block)
B(3,2,8,minecraft:nether_wart_block)
B(4,2,8,minecraft:nether_wart_block)
B(5,2,8,minecraft:nether_wart_block)
B(6,2,8,minecraft:nether_wart_block)
B(7,2,8,minecraft:nether_wart_block)
B(8,2,8,minecraft:nether_wart_block)
B(9,2,8,minecraft:nether_wart_block)
B(10,2,8,minecraft:nether_wart_block)
B(11,2,8,minecraft:nether_wart_block)
B(12,2,8,minecraft:nether_wart_block)
B(13,2,8,minecraft:nether_wart_block)
B(14,2,8,minecraft:nether_wart_block)
B(15,2,8,minecraft:nether_wart_block)
B(0,2,9,minecraft:nether_wart_block)
B(1,2,9,minecraft:nether_wart_block)
B(2,2,9,minecraft:nether_wart_block)
B(3,2,9,minecraft:nether_wart_block)
B(4,2,9,minecraft:nether_wart_block)
B(5,2,9,minecraft:nether_wart_block)
B(6,2,9,minecraft:nether_wart_block)
B(7,2,9,minecraft:nether_wart_block)
B(8,2,9,minecraft:nether_wart_block)
B(9,2,9,minecraft:nether_wart_block)
B(10,2,9,minecraft:nether_wart_block)
B(11,2,9,minecraft:nether_wart_block)
B(12,2,9,minecraft:nether_wart_block)
B(13,2,9,minecraft:nether_wart_block)
B(14,2,9,minecraft:nether_wart_block)
B(15,2,9,minecraft:nether_wart_block)
B(2,2,10,minecraft:nether_wart_block)
B(3,2,10,minecraft:nether_wart_block)
B(4,2,10,minecraft:nether_wart_block)
B(5,2,10,minecraft:nether_wart_block)
B(6,2,10,minecraft:nether_wart_block)
B(7,2,10,minecraft:nether_wart_block)
B(8,2,10,minecraft:nether_wart_block)
B(9,2,10,minecraft:nether_wart_block)
B(10,2,10,minecraft:nether_wart_block)
B(11,2,10,minecraft:nether_wart_block)
B(12,2,10,minecraft:nether_wart_block)
B(13,2,10,minecraft:nether_wart_block)
B(14,2,10,minecraft:nether_wart_block)
B(15,2,10,minecraft:nether_wart_block)
B(3,2,11,minecraft:nether_wart_block)
B(4,2,11,minecraft:nether_wart_block)
B(5,2,11,minecraft:nether_wart_block)
B(13,2,11,minecraft:nether_wart_block)
B(14,2,11,minecraft:nether_wart_block)
B(15,2,11,minecraft:nether_wart_block)
B(0,3,0,minecraft:nether_wart_block)
B(1,3,0,minecraft:nether_wart_block)
B(2,3,0,minecraft:nether_wart_block)
B(3,3,0,minecraft:nether_wart_block)
B(7,3,0,minecraft:nether_wart_block)
B(8,3,0,minecraft:nether_wart_block)
B(9,3,0,minecraft:nether_wart_block)
B(10,3,0,minecraft:nether_wart_block)
B(11,3,0,minecraft:nether_wart_block)
B(12,3,0,minecraft:nether_wart_block)
B(13,3,0,minecraft:nether_wart_block)
B(14,3,0,minecraft:nether_wart_block)
B(15,3,0,minecraft:nether_wart_block)
B(0,3,1,minecraft:nether_wart_block)
B(1,3,1,minecraft:nether_wart_block)
B(2,3,1,minecraft:nether_wart_block)
B(3,3,1,minecraft:nether_wart_block)
B(4,3,1,minecraft:nether_wart_block)
B(7,3,1,minecraft:nether_wart_block)
B(8,3,1,minecraft:nether_wart_block)
B(9,3,1,minecraft:nether_wart_block)
B(10,3,1,minecraft:nether_wart_block)
B(11,3,1,minecraft:nether_wart_block)
B(12,3,1,minecraft:nether_wart_block)
B(13,3,1,minecraft:nether_wart_block)
B(14,3,1,minecraft:nether_wart_block)
B(15,3,1,minecraft:nether_wart_block)
B(0,3,2,minecraft:nether_wart_block)
B(1,3,2,minecraft:nether_wart_block)
B(2,3,2,minecraft:nether_wart_block)
B(3,3,2,minecraft:nether_wart_block)
B(4,3,2,minecraft:nether_wart_block)
B(5,3,2,minecraft:nether_wart_block)
B(6,3,2,minecraft:nether_wart_block)
B(7,3,2,minecraft:nether_wart_block)
B(8,3,2,minecraft:nether_wart_block)
B(9,3,2,minecraft:nether_wart_block)
B(10,3,2,minecraft:nether_wart_block)
B(11,3,2,minecraft:nether_wart_block)
B(12,3,2,minecraft:nether_wart_block)
B(13,3,2,minecraft:nether_wart_block)
B(14,3,2,minecraft:nether_wart_block)
B(15,3,2,minecraft:nether_wart_block)
B(0,3,3,minecraft:nether_wart_block)
B(1,3,3,minecraft:nether_wart_block)
B(2,3,3,minecraft:nether_wart_block)
B(3,3,3,minecraft:nether_wart_block)
B(4,3,3,minecraft:nether_wart_block)
B(5,3,3,minecraft:nether_wart_block)
B(6,3,3,minecraft:nether_wart_block)
B(7,3,3,minecraft:nether_wart_block)
B(8,3,3,minecraft:nether_wart_block)
B(9,3,3,minecraft:nether_wart_block)
B(10,3,3,minecraft:nether_wart_block)
B(11,3,3,minecraft:nether_wart_block)
B(12,3,3,minecraft:nether_wart_block)
B(13,3,3,minecraft:nether_wart_block)
B(14,3,3,minecraft:nether_wart_block)
B(15,3,3,minecraft:nether_wart_block)
B(0,3,4,minecraft:nether_wart_block)
B(1,3,4,minecraft:nether_wart_block)
B(2,3,4,minecraft:nether_wart_block)
B(3,3,4,minecraft:nether_wart_block)
B(4,3,4,minecraft:nether_wart_block)
B(5,3,4,minecraft:nether_wart_block)
B(6,3,4,minecraft:nether_wart_block)
B(7,3,4,minecraft:nether_wart_block)
B(8,3,4,minecraft:nether_wart_block)
B(9,3,4,minecraft:nether_wart_block)
B(10,3,4,minecraft:nether_wart_block)
B(11,3,4,minecraft:nether_wart_block)
B(12,3,4,minecraft:nether_wart_block)
B(13,3,4,minecraft:nether_wart_block)
B(14,3,4,minecraft:nether_wart_block)
B(15,3,4,minecraft:nether_wart_block)
B(0,3,5,minecraft:nether_wart_block)
B(1,3,5,minecraft:nether_wart_block)
B(2,3,5,minecraft:nether_wart_block)
B(3,3,5,minecraft:nether_wart_block)
B(4,3,5,minecraft:nether_wart_block)
B(5,3,5,minecraft:nether_wart_block)
B(6,3,5,minecraft:nether_wart_block)
B(7,3,5,minecraft:nether_wart_block)
B(8,3,5,minecraft:nether_wart_block)
B(9,3,5,minecraft:nether_wart_block)
B(10,3,5,minecraft:nether_wart_block)
B(11,3,5,minecraft:nether_wart_block)
B(12,3,5,minecraft:nether_wart_block)
B(13,3,5,minecraft:nether_wart_block)
B(14,3,5,minecraft:nether_wart_block)
B(15,3,5,minecraft:nether_wart_block)
B(0,3,6,minecraft:nether_wart_block)
B(1,3,6,minecraft:nether_wart_block)
B(2,3,6,minecraft:nether_wart_block)
B(3,3,6,minecraft:nether_wart_block)
B(4,3,6,minecraft:nether_wart_block)
B(5,3,6,minecraft:nether_wart_block)
B(6,3,6,minecraft:nether_wart_block)
B(7,3,6,minecraft:nether_wart_block)
B(8,3,6,minecraft:nether_wart_block)
B(9,3,6,minecraft:nether_wart_block)
B(10,3,6,minecraft:nether_wart_block)
B(11,3,6,minecraft:nether_wart_block)
B(12,3,6,minecraft:nether_wart_block)
B(13,3,6,minecraft:nether_wart_block)
B(14,3,6,minecraft:nether_wart_block)
B(15,3,6,minecraft:nether_wart_block)
B(0,3,7,minecraft:nether_wart_block)
B(1,3,7,minecraft:nether_wart_block)
B(2,3,7,minecraft:nether_wart_block)
B(3,3,7,minecraft:nether_wart_block)
B(4,3,7,minecraft:nether_wart_block)
B(5,3,7,minecraft:nether_wart_block)
B(6,3,7,minecraft:nether_wart_block)
B(7,3,7,minecraft:nether_wart_block)
B(8,3,7,minecraft:nether_wart_block)
B(9,3,7,minecraft:nether_wart_block)
B(10,3,7,minecraft:nether_wart_block)
B(11,3,7,minecraft:nether_wart_block)
B(12,3,7,minecraft:nether_wart_block)
B(13,3,7,minecraft:nether_wart_block)
B(14,3,7,minecraft:nether_wart_block)
B(15,3,7,minecraft:nether_wart_block)
B(0,3,8,minecraft:nether_wart_block)
B(1,3,8,minecraft:nether_wart_block)
B(2,3,8,minecraft:nether_wart_block)
B(3,3,8,minecraft:nether_wart_block)
B(4,3,8,minecraft:nether_wart_block)
B(5,3,8,minecraft:nether_wart_block)
B(6,3,8,minecraft:nether_wart_block)
B(7,3,8,minecraft:nether_wart_block)
B(8,3,8,minecraft:nether_wart_block)
B(9,3,8,minecraft:nether_wart_block)
B(10,3,8,minecraft:nether_wart_block)
B(11,3,8,minecraft:nether_wart_block)
B(12,3,8,minecraft:nether_wart_block)
B(13,3,8,minecraft:nether_wart_block)
B(14,3,8,minecraft:nether_wart_block)
B(15,3,8,minecraft:nether_wart_block)
B(0,3,9,minecraft:nether_wart_block)
B(1,3,9,minecraft:nether_wart_block)
B(2,3,9,minecraft:nether_wart_block)
B(3,3,9,minecraft:nether_wart_block)
B(4,3,9,minecraft:nether_wart_block)
B(5,3,9,minecraft:nether_wart_block)
B(6,3,9,minecraft:nether_wart_block)
B(7,3,9,minecraft:nether_wart_block)
B(8,3,9,minecraft:nether_wart_block)
B(9,3,9,minecraft:nether_wart_block)
B(10,3,9,minecraft:nether_wart_block)
B(11,3,9,minecraft:nether_wart_block)
B(12,3,9,minecraft:nether_wart_block)
B(13,3,9,minecraft:nether_wart_block)
B(14,3,9,minecraft:nether_wart_block)
B(15,3,9,minecraft:nether_wart_block)
B(2,3,10,minecraft:nether_wart_block)
B(3,3,10,minecraft:nether_wart_block)
B(4,3,10,minecraft:nether_wart_block)
B(5,3,10,minecraft:nether_wart_block)
B(6,3,10,minecraft:nether_wart_block)
B(7,3,10,minecraft:nether_wart_block)
B(8,3,10,minecraft:nether_wart_block)
B(9,3,10,minecraft:nether_wart_block)
B(10,3,10,minecraft:nether_wart_block)
B(11,3,10,minecraft:nether_wart_block)
B(12,3,10,minecraft:nether_wart_block)
B(13,3,10,minecraft:nether_wart_block)
B(14,3,10,minecraft:nether_wart_block)
B(15,3,10,minecraft:nether_wart_block)
B(3,3,11,minecraft:nether_wart_block)
B(4,3,11,minecraft:nether_wart_block)
B(13,3,11,minecraft:nether_wart_block)
B(14,3,11,minecraft:nether_wart_block)
B(15,3,11,minecraft:nether_wart_block)
B(0,4,0,minecraft:nether_wart_block)
B(1,4,0,minecraft:nether_wart_block)
B(2,4,0,minecraft:nether_wart_block)
B(3,4,0,minecraft:nether_wart_block)
B(7,4,0,minecraft:nether_wart_block)
B(8,4,0,minecraft:nether_wart_block)
B(9,4,0,minecraft:nether_wart_block)
B(10,4,0,minecraft:nether_wart_block)
B(11,4,0,minecraft:nether_wart_block)
B(12,4,0,minecraft:nether_wart_block)
B(13,4,0,minecraft:nether_wart_block)
B(14,4,0,minecraft:nether_wart_block)
B(15,4,0,minecraft:nether_wart_block)
B(0,4,1,minecraft:nether_wart_block)
B(1,4,1,minecraft:nether_wart_block)
B(2,4,1,minecraft:nether_wart_block)
B(3,4,1,minecraft:nether_wart_block)
B(4,4,1,minecraft:nether_wart_block)
B(7,4,1,minecraft:nether_wart_block)
B(8,4,1,minecraft:nether_wart_block)
B(9,4,1,minecraft:nether_wart_block)
B(10,4,1,minecraft:nether_wart_block)
B(11,4,1,minecraft:nether_wart_block)
B(12,4,1,minecraft:nether_wart_block)
B(13,4,1,minecraft:nether_wart_block)
B(14,4,1,minecraft:nether_wart_block)
B(15,4,1,minecraft:nether_wart_block)
B(0,4,2,minecraft:nether_wart_block)
B(1,4,2,minecraft:nether_wart_block)
B(2,4,2,minecraft:nether_wart_block)
B(3,4,2,minecraft:nether_wart_block)
B(4,4,2,minecraft:nether_wart_block)
B(5,4,2,minecraft:nether_wart_block)
B(6,4,2,minecraft:nether_wart_block)
B(7,4,2,minecraft:nether_wart_block)
B(8,4,2,minecraft:nether_wart_block)
B(9,4,2,minecraft:nether_wart_block)
B(10,4,2,minecraft:nether_wart_block)
B(11,4,2,minecraft:nether_wart_block)
B(12,4,2,minecraft:nether_wart_block)
B(13,4,2,minecraft:nether_wart_block)
B(14,4,2,minecraft:nether_wart_block)
B(15,4,2,minecraft:nether_wart_block)
B(0,4,3,minecraft:nether_wart_block)
B(1,4,3,minecraft:nether_wart_block)
B(2,4,3,minecraft:nether_wart_block)
B(3,4,3,minecraft:nether_wart_block)
B(4,4,3,minecraft:nether_wart_block)
B(5,4,3,minecraft:nether_wart_block)
B(6,4,3,minecraft:nether_wart_block)
B(7,4,3,minecraft:nether_wart_block)
B(8,4,3,minecraft:nether_wart_block)
B(9,4,3,minecraft:nether_wart_block)
B(10,4,3,minecraft:nether_wart_block)
B(11,4,3,minecraft:nether_wart_block)
B(12,4,3,minecraft:nether_wart_block)
B(13,4,3,minecraft:nether_wart_block)
B(14,4,3,minecraft:nether_wart_block)
B(15,4,3,minecraft:nether_wart_block)
B(0,4,4,minecraft:nether_wart_block)
B(1,4,4,minecraft:nether_wart_block)
B(2,4,4,minecraft:nether_wart_block)
B(3,4,4,minecraft:nether_wart_block)
B(4,4,4,minecraft:nether_wart_block)
B(5,4,4,minecraft:nether_wart_block)
B(6,4,4,minecraft:nether_wart_block)
B(7,4,4,minecraft:nether_wart_block)
B(8,4,4,minecraft:nether_wart_block)
B(9,4,4,minecraft:nether_wart_block)
B(10,4,4,minecraft:nether_wart_block)
B(11,4,4,minecraft:nether_wart_block)
B(12,4,4,minecraft:nether_wart_block)
B(13,4,4,minecraft:nether_wart_block)
B(14,4,4,minecraft:nether_wart_block)
B(15,4,4,minecraft:nether_wart_block)
B(0,4,5,minecraft:nether_wart_block)
B(1,4,5,minecraft:nether_wart_block)
B(2,4,5,minecraft:nether_wart_block)
B(3,4,5,minecraft:nether_wart_block)
B(4,4,5,minecraft:nether_wart_block)
B(5,4,5,minecraft:nether_wart_block)
B(6,4,5,minecraft:nether_wart_block)
B(7,4,5,minecraft:nether_wart_block)
B(8,4,5,minecraft:nether_wart_block)
B(9,4,5,minecraft:nether_wart_block)
B(10,4,5,minecraft:nether_wart_block)
B(11,4,5,minecraft:nether_wart_block)
B(12,4,5,minecraft:nether_wart_block)
B(13,4,5,minecraft:nether_wart_block)
B(14,4,5,minecraft:nether_wart_block)
B(15,4,5,minecraft:nether_wart_block)
B(0,4,6,minecraft:nether_wart_block)
B(1,4,6,minecraft:nether_wart_block)
B(2,4,6,minecraft:nether_wart_block)
B(3,4,6,minecraft:nether_wart_block)
B(4,4,6,minecraft:nether_wart_block)
B(5,4,6,minecraft:nether_wart_block)
B(6,4,6,minecraft:nether_wart_block)
B(7,4,6,minecraft:nether_wart_block)
B(8,4,6,minecraft:nether_wart_block)
B(9,4,6,minecraft:nether_wart_block)
B(10,4,6,minecraft:nether_wart_block)
B(11,4,6,minecraft:nether_wart_block)
B(12,4,6,minecraft:nether_wart_block)
B(13,4,6,minecraft:nether_wart_block)
B(14,4,6,minecraft:nether_wart_block)
B(15,4,6,minecraft:nether_wart_block)
B(0,4,7,minecraft:nether_wart_block)
B(1,4,7,minecraft:nether_wart_block)
B(2,4,7,minecraft:nether_wart_block)
B(3,4,7,minecraft:nether_wart_block)
B(4,4,7,minecraft:nether_wart_block)
B(5,4,7,minecraft:nether_wart_block)
B(6,4,7,minecraft:nether_wart_block)
B(7,4,7,minecraft:nether_wart_block)
B(8,4,7,minecraft:nether_wart_block)
B(9,4,7,minecraft:nether_wart_block)
B(10,4,7,minecraft:nether_wart_block)
B(11,4,7,minecraft:nether_wart_block)
B(12,4,7,minecraft:nether_wart_block)
B(13,4,7,minecraft:nether_wart_block)
B(14,4,7,minecraft:nether_wart_block)
B(15,4,7,minecraft:nether_wart_block)
B(0,4,8,minecraft:nether_wart_block)
B(1,4,8,minecraft:nether_wart_block)
B(2,4,8,minecraft:nether_wart_block)
B(3,4,8,minecraft:nether_wart_block)
B(4,4,8,minecraft:nether_wart_block)
B(5,4,8,minecraft:nether_wart_block)
B(6,4,8,minecraft:nether_wart_block)
B(7,4,8,minecraft:nether_wart_block)
B(8,4,8,minecraft:nether_wart_block)
B(9,4,8,minecraft:nether_wart_block)
B(10,4,8,minecraft:nether_wart_block)
B(11,4,8,minecraft:nether_wart_block)
B(12,4,8,minecraft:nether_wart_block)
B(13,4,8,minecraft:nether_wart_block)
B(14,4,8,minecraft:nether_wart_block)
B(15,4,8,minecraft:nether_wart_block)
B(0,4,9,minecraft:nether_wart_block)
B(1,4,9,minecraft:nether_wart_block)
B(2,4,9,minecraft:nether_wart_block)
B(3,4,9,minecraft:nether_wart_block)
B(4,4,9,minecraft:nether_wart_block)
B(5,4,9,minecraft:nether_wart_block)
B(6,4,9,minecraft:nether_wart_block)
B(7,4,9,minecraft:nether_wart_block)
B(8,4,9,minecraft:nether_wart_block)
B(9,4,9,minecraft:nether_wart_block)
B(10,4,9,minecraft:nether_wart_block)
B(11,4,9,minecraft:nether_wart_block)
B(12,4,9,minecraft:nether_wart_block)
B(13,4,9,minecraft:nether_wart_block)
B(14,4,9,minecraft:nether_wart_block)
B(15,4,9,minecraft:nether_wart_block)
B(2,4,10,minecraft:nether_wart_block)
B(3,4,10,minecraft:nether_wart_block)
B(4,4,10,minecraft:nether_wart_block)
B(5,4,10,minecraft:nether_wart_block)
B(6,4,10,minecraft:nether_wart_block)
B(7,4,10,minecraft:nether_wart_block)
B(8,4,10,minecraft:nether_wart_block)
B(9,4,10,minecraft:nether_wart_block)
B(10,4,10,minecraft:nether_wart_block)
B(11,4,10,minecraft:nether_wart_block)
B(12,4,10,minecraft:nether_wart_block)
B(13,4,10,minecraft:nether_wart_block)
B(14,4,10,minecraft:nether_wart_block)
B(15,4,10,minecraft:nether_wart_block)
B(3,4,11,minecraft:nether_wart_block)
B(4,4,11,minecraft:nether_wart_block)
B(13,4,11,minecraft:nether_wart_block)
B(14,4,11,minecraft:nether_wart_block)
B(15,4,11,minecraft:nether_wart_block)
B(0,5,0,minecraft:nether_wart_block)
B(1,5,0,minecraft:nether_wart_block)
B(2,5,0,minecraft:nether_wart_block)
B(3,5,0,minecraft:nether_wart_block)
B(7,5,0,minecraft:nether_wart_block)
B(8,5,0,minecraft:nether_wart_block)
B(9,5,0,minecraft:nether_wart_block)
B(10,5,0,minecraft:nether_wart_block)
B(11,5,0,minecraft:nether_wart_block)
B(12,5,0,minecraft:nether_wart_block)
B(13,5,0,minecraft:nether_wart_block)
B(14,5,0,minecraft:nether_wart_block)
B(15,5,0,minecraft:nether_wart_block)
B(0,5,1,minecraft:nether_wart_block)
B(1,5,1,minecraft:nether_wart_block)
B(2,5,1,minecraft:nether_wart_block)
B(3,5,1,minecraft:nether_wart_block)
B(4,5,1,minecraft:nether_wart_block)
B(7,5,1,minecraft:nether_wart_block)
B(8,5,1,minecraft:nether_wart_block)
B(9,5,1,minecraft:nether_wart_block)
B(10,5,1,minecraft:nether_wart_block)
B(11,5,1,minecraft:nether_wart_block)
B(12,5,1,minecraft:nether_wart_block)
B(13,5,1,minecraft:nether_wart_block)
B(14,5,1,minecraft:nether_wart_block)
B(15,5,1,minecraft:nether_wart_block)
B(0,5,2,minecraft:nether_wart_block)
B(1,5,2,minecraft:nether_wart_block)
B(2,5,2,minecraft:nether_wart_block)
B(3,5,2,minecraft:nether_wart_block)
B(4,5,2,minecraft:nether_wart_block)
B(5,5,2,minecraft:nether_wart_block)
B(6,5,2,minecraft:nether_wart_block)
B(7,5,2,minecraft:nether_wart_block)
B(8,5,2,minecraft:nether_wart_block)
B(9,5,2,minecraft:nether_wart_block)
B(10,5,2,minecraft:nether_wart_block)
B(11,5,2,minecraft:nether_wart_block)
B(12,5,2,minecraft:nether_wart_block)
B(13,5,2,minecraft:nether_wart_block)
B(14,5,2,minecraft:nether_wart_block)
B(15,5,2,minecraft:nether_wart_block)
B(0,5,3,minecraft:nether_wart_block)
B(1,5,3,minecraft:nether_wart_block)
B(2,5,3,minecraft:nether_wart_block)
B(3,5,3,minecraft:nether_wart_block)
B(4,5,3,minecraft:nether_wart_block)
B(5,5,3,minecraft:nether_wart_block)
B(6,5,3,minecraft:nether_wart_block)
B(7,5,3,minecraft:nether_wart_block)
B(8,5,3,minecraft:nether_wart_block)
B(9,5,3,minecraft:nether_wart_block)
B(10,5,3,minecraft:nether_wart_block)
B(11,5,3,minecraft:nether_wart_block)
B(12,5,3,minecraft:nether_wart_block)
B(13,5,3,minecraft:nether_wart_block)
B(14,5,3,minecraft:nether_wart_block)
B(15,5,3,minecraft:nether_wart_block)
B(0,5,4,minecraft:nether_wart_block)
B(1,5,4,minecraft:nether_wart_block)
B(2,5,4,minecraft:nether_wart_block)
B(3,5,4,minecraft:nether_wart_block)
B(4,5,4,minecraft:nether_wart_block)
B(5,5,4,minecraft:nether_wart_block)
B(6,5,4,minecraft:nether_wart_block)
B(7,5,4,minecraft:nether_wart_block)
B(8,5,4,minecraft:nether_wart_block)
B(9,5,4,minecraft:nether_wart_block)
B(10,5,4,minecraft:nether_wart_block)
B(11,5,4,minecraft:nether_wart_block)
B(12,5,4,minecraft:nether_wart_block)
B(13,5,4,minecraft:nether_wart_block)
B(14,5,4,minecraft:nether_wart_block)
B(15,5,4,minecraft:nether_wart_block)
B(0,5,5,minecraft:nether_wart_block)
B(1,5,5,minecraft:nether_wart_block)
B(2,5,5,minecraft:nether_wart_block)
B(3,5,5,minecraft:nether_wart_block)
B(4,5,5,minecraft:nether_wart_block)
B(5,5,5,minecraft:nether_wart_block)
B(6,5,5,minecraft:nether_wart_block)
B(7,5,5,minecraft:nether_wart_block)
B(8,5,5,minecraft:nether_wart_block)
B(9,5,5,minecraft:nether_wart_block)
B(10,5,5,minecraft:nether_wart_block)
B(11,5,5,minecraft:nether_wart_block)
B(12,5,5,minecraft:nether_wart_block)
B(13,5,5,minecraft:nether_wart_block)
B(14,5,5,minecraft:nether_wart_block)
B(15,5,5,minecraft:nether_wart_block)
B(0,5,6,minecraft:nether_wart_block)
B(1,5,6,minecraft:nether_wart_block)
B(2,5,6,minecraft:nether_wart_block)
B(3,5,6,minecraft:nether_wart_block)
B(4,5,6,minecraft:nether_wart_block)
B(5,5,6,minecraft:nether_wart_block)
B(6,5,6,minecraft:nether_wart_block)
B(7,5,6,minecraft:nether_wart_block)
B(8,5,6,minecraft:nether_wart_block)
B(9,5,6,minecraft:nether_wart_block)
B(10,5,6,minecraft:nether_wart_block)
B(11,5,6,minecraft:nether_wart_block)
B(12,5,6,minecraft:nether_wart_block)
B(13,5,6,minecraft:nether_wart_block)
B(14,5,6,minecraft:nether_wart_block)
B(15,5,6,minecraft:nether_wart_block)
B(0,5,7,minecraft:nether_wart_block)
B(1,5,7,minecraft:nether_wart_block)
B(2,5,7,minecraft:nether_wart_block)
B(3,5,7,minecraft:nether_wart_block)
B(4,5,7,minecraft:nether_wart_block)
B(5,5,7,minecraft:nether_wart_block)
B(6,5,7,minecraft:nether_wart_block)
B(7,5,7,minecraft:nether_wart_block)
B(8,5,7,minecraft:nether_wart_block)
B(9,5,7,minecraft:nether_wart_block)
B(10,5,7,minecraft:nether_wart_block)
B(11,5,7,minecraft:nether_wart_block)
B(12,5,7,minecraft:nether_wart_block)
B(13,5,7,minecraft:nether_wart_block)
B(14,5,7,minecraft:nether_wart_block)
B(15,5,7,minecraft:nether_wart_block)
B(0,5,8,minecraft:nether_wart_block)
B(1,5,8,minecraft:nether_wart_block)
B(2,5,8,minecraft:nether_wart_block)
B(3,5,8,minecraft:nether_wart_block)
B(4,5,8,minecraft:nether_wart_block)
B(5,5,8,minecraft:nether_wart_block)
B(6,5,8,minecraft:nether_wart_block)
B(7,5,8,minecraft:nether_wart_block)
B(8,5,8,minecraft:nether_wart_block)
B(9,5,8,minecraft:nether_wart_block)
B(10,5,8,minecraft:nether_wart_block)
B(11,5,8,minecraft:nether_wart_block)
B(12,5,8,minecraft:nether_wart_block)
B(13,5,8,minecraft:nether_wart_block)
B(14,5,8,minecraft:nether_wart_block)
B(15,5,8,minecraft:nether_wart_block)
B(0,5,9,minecraft:nether_wart_block)
B(1,5,9,minecraft:nether_wart_block)
B(2,5,9,minecraft:nether_wart_block)
B(3,5,9,minecraft:nether_wart_block)
B(4,5,9,minecraft:nether_wart_block)
B(5,5,9,minecraft:nether_wart_block)
B(6,5,9,minecraft:nether_wart_block)
B(7,5,9,minecraft:nether_wart_block)
B(8,5,9,minecraft:nether_wart_block)
B(9,5,9,minecraft:nether_wart_block)
B(10,5,9,minecraft:nether_wart_block)
B(11,5,9,minecraft:nether_wart_block)
B(12,5,9,minecraft:nether_wart_block)
B(13,5,9,minecraft:nether_wart_block)
B(14,5,9,minecraft:nether_wart_block)
B(15,5,9,minecraft:nether_wart_block)
B(2,5,10,minecraft:nether_wart_block)
B(3,5,10,minecraft:nether_wart_block)
B(4,5,10,minecraft:nether_wart_block)
B(5,5,10,minecraft:nether_wart_block)
B(6,5,10,minecraft:nether_wart_block)
B(7,5,10,minecraft:nether_wart_block)
B(8,5,10,minecraft:nether_wart_block)
B(9,5,10,minecraft:nether_wart_block)
B(10,5,10,minecraft:nether_wart_block)
B(11,5,10,minecraft:nether_wart_block)
B(12,5,10,minecraft:nether_wart_block)
B(13,5,10,minecraft:nether_wart_block)
B(14,5,10,minecraft:nether_wart_block)
B(15,5,10,minecraft:nether_wart_block)
B(3,5,11,minecraft:nether_wart_block)
B(4,5,11,minecraft:nether_wart_block)
B(14,5,11,minecraft:nether_wart_block)
B(15,5,11,minecraft:nether_wart_block)
B(0,6,0,minecraft:nether_wart_block)
B(1,6,0,minecraft:nether_wart_block)
B(2,6,0,minecraft:nether_wart_block)
B(3,6,0,minecraft:nether_wart_block)
B(7,6,0,minecraft:nether_wart_block)
B(8,6,0,minecraft:nether_wart_block)
B(9,6,0,minecraft:nether_wart_block)
B(10,6,0,minecraft:nether_wart_block)
B(11,6,0,minecraft:nether_wart_block)
B(12,6,0,minecraft:nether_wart_block)
B(13,6,0,minecraft:nether_wart_block)
B(14,6,0,minecraft:nether_wart_block)
B(15,6,0,minecraft:nether_wart_block)
B(0,6,1,minecraft:nether_wart_block)
B(1,6,1,minecraft:nether_wart_block)
B(2,6,1,minecraft:nether_wart_block)
B(3,6,1,minecraft:nether_wart_block)
B(4,6,1,minecraft:nether_wart_block)
B(7,6,1,minecraft:nether_wart_block)
B(8,6,1,minecraft:nether_wart_block)
B(9,6,1,minecraft:nether_wart_block)
B(10,6,1,minecraft:nether_wart_block)
B(11,6,1,minecraft:nether_wart_block)
B(12,6,1,minecraft:nether_wart_block)
B(13,6,1,minecraft:nether_wart_block)
B(14,6,1,minecraft:nether_wart_block)
B(15,6,1,minecraft:nether_wart_block)
B(0,6,2,minecraft:nether_wart_block)
B(1,6,2,minecraft:nether_wart_block)
B(2,6,2,minecraft:nether_wart_block)
B(3,6,2,minecraft:nether_wart_block)
B(4,6,2,minecraft:nether_wart_block)
B(5,6,2,minecraft:nether_wart_block)
B(6,6,2,minecraft:nether_wart_block)
B(7,6,2,minecraft:nether_wart_block)
B(8,6,2,minecraft:nether_wart_block)
B(9,6,2,minecraft:nether_wart_block)
B(10,6,2,minecraft:nether_wart_block)
B(11,6,2,minecraft:nether_wart_block)
B(12,6,2,minecraft:nether_wart_block)
B(13,6,2,minecraft:nether_wart_block)
B(14,6,2,minecraft:nether_wart_block)
B(15,6,2,minecraft:nether_wart_block)
B(0,6,3,minecraft:nether_wart_block)
B(1,6,3,minecraft:nether_wart_block)
B(2,6,3,minecraft:nether_wart_block)
B(3,6,3,minecraft:nether_wart_block)
B(4,6,3,minecraft:nether_wart_block)
B(5,6,3,minecraft:nether_wart_block)
B(6,6,3,minecraft:nether_wart_block)
B(7,6,3,minecraft:nether_wart_block)
B(8,6,3,minecraft:nether_wart_block)
B(9,6,3,minecraft:nether_wart_block)
B(10,6,3,minecraft:nether_wart_block)
B(11,6,3,minecraft:nether_wart_block)
B(12,6,3,minecraft:nether_wart_block)
B(13,6,3,minecraft:nether_wart_block)
B(14,6,3,minecraft:nether_wart_block)
B(15,6,3,minecraft:nether_wart_block)
B(0,6,4,minecraft:nether_wart_block)
B(1,6,4,minecraft:nether_wart_block)
B(2,6,4,minecraft:nether_wart_block)
B(3,6,4,minecraft:nether_wart_block)
B(4,6,4,minecraft:nether_wart_block)
B(5,6,4,minecraft:nether_wart_block)
B(6,6,4,minecraft:nether_wart_block)
B(7,6,4,minecraft:nether_wart_block)
B(8,6,4,minecraft:nether_wart_block)
B(9,6,4,minecraft:nether_wart_block)
B(10,6,4,minecraft:nether_wart_block)
B(11,6,4,minecraft:nether_wart_block)
B(12,6,4,minecraft:nether_wart_block)
B(13,6,4,minecraft:nether_wart_block)
B(14,6,4,minecraft:nether_wart_block)
B(15,6,4,minecraft:nether_wart_block)
B(0,6,5,minecraft:nether_wart_block)
B(1,6,5,minecraft:nether_wart_block)
B(2,6,5,minecraft:nether_wart_block)
B(3,6,5,minecraft:nether_wart_block)
B(4,6,5,minecraft:nether_wart_block)
B(5,6,5,minecraft:nether_wart_block)
B(6,6,5,minecraft:nether_wart_block)
B(7,6,5,minecraft:nether_wart_block)
B(8,6,5,minecraft:nether_wart_block)
B(9,6,5,minecraft:nether_wart_block)
B(10,6,5,minecraft:nether_wart_block)
B(11,6,5,minecraft:nether_wart_block)
B(12,6,5,minecraft:nether_wart_block)
B(13,6,5,minecraft:nether_wart_block)
B(14,6,5,minecraft:nether_wart_block)
B(15,6,5,minecraft:nether_wart_block)
B(0,6,6,minecraft:nether_wart_block)
B(1,6,6,minecraft:nether_wart_block)
B(2,6,6,minecraft:nether_wart_block)
B(3,6,6,minecraft:nether_wart_block)
B(4,6,6,minecraft:nether_wart_block)
B(5,6,6,minecraft:nether_wart_block)
B(6,6,6,minecraft:nether_wart_block)
B(7,6,6,minecraft:nether_wart_block)
B(8,6,6,minecraft:nether_wart_block)
B(9,6,6,minecraft:nether_wart_block)
B(10,6,6,minecraft:nether_wart_block)
B(11,6,6,minecraft:nether_wart_block)
B(12,6,6,minecraft:nether_wart_block)
B(13,6,6,minecraft:nether_wart_block)
B(14,6,6,minecraft:nether_wart_block)
B(15,6,6,minecraft:nether_wart_block)
B(0,6,7,minecraft:nether_wart_block)
B(1,6,7,minecraft:nether_wart_block)
B(2,6,7,minecraft:nether_wart_block)
B(3,6,7,minecraft:nether_wart_block)
B(4,6,7,minecraft:nether_wart_block)
B(5,6,7,minecraft:nether_wart_block)
B(6,6,7,minecraft:nether_wart_block)
B(7,6,7,minecraft:nether_wart_block)
B(8,6,7,minecraft:nether_wart_block)
B(9,6,7,minecraft:nether_wart_block)
B(10,6,7,minecraft:nether_wart_block)
B(11,6,7,minecraft:nether_wart_block)
B(12,6,7,minecraft:nether_wart_block)
B(13,6,7,minecraft:nether_wart_block)
B(14,6,7,minecraft:nether_wart_block)
B(15,6,7,minecraft:nether_wart_block)
B(0,6,8,minecraft:nether_wart_block)
B(1,6,8,minecraft:nether_wart_block)
B(2,6,8,minecraft:nether_wart_block)
B(3,6,8,minecraft:nether_wart_block)
B(4,6,8,minecraft:nether_wart_block)
B(5,6,8,minecraft:nether_wart_block)
B(6,6,8,minecraft:nether_wart_block)
B(7,6,8,minecraft:nether_wart_block)
B(8,6,8,minecraft:nether_wart_block)
B(9,6,8,minecraft:nether_wart_block)
B(10,6,8,minecraft:nether_wart_block)
B(11,6,8,minecraft:nether_wart_block)
B(12,6,8,minecraft:nether_wart_block)
B(13,6,8,minecraft:nether_wart_block)
B(14,6,8,minecraft:nether_wart_block)
B(15,6,8,minecraft:nether_wart_block)
B(0,6,9,minecraft:nether_wart_block)
B(1,6,9,minecraft:nether_wart_block)
B(2,6,9,minecraft:nether_wart_block)
B(3,6,9,minecraft:nether_wart_block)
B(4,6,9,minecraft:nether_wart_block)
B(5,6,9,minecraft:nether_wart_block)
B(6,6,9,minecraft:nether_wart_block)
B(7,6,9,minecraft:nether_wart_block)
B(8,6,9,minecraft:nether_wart_block)
B(9,6,9,minecraft:nether_wart_block)
B(10,6,9,minecraft:nether_wart_block)
B(11,6,9,minecraft:nether_wart_block)
B(12,6,9,minecraft:nether_wart_block)
B(13,6,9,minecraft:nether_wart_block)
B(14,6,9,minecraft:nether_wart_block)
B(15,6,9,minecraft:nether_wart_block)
B(2,6,10,minecraft:nether_wart_block)
B(3,6,10,minecraft:nether_wart_block)
B(4,6,10,minecraft:nether_wart_block)
B(5,6,10,minecraft:nether_wart_block)
B(6,6,10,minecraft:nether_wart_block)
B(7,6,10,minecraft:nether_wart_block)
B(8,6,10,minecraft:nether_wart_block)
B(9,6,10,minecraft:nether_wart_block)
B(10,6,10,minecraft:nether_wart_block)
B(11,6,10,minecraft:nether_wart_block)
B(12,6,10,minecraft:nether_wart_block)
B(13,6,10,minecraft:nether_wart_block)
B(14,6,10,minecraft:nether_wart_block)
B(15,6,10,minecraft:nether_wart_block)
B(3,6,11,minecraft:nether_wart_block)
B(4,6,11,minecraft:nether_wart_block)
B(14,6,11,minecraft:nether_wart_block)
B(15,6,11,minecraft:nether_wart_block)
B(0,7,0,minecraft:nether_wart_block)
B(1,7,0,minecraft:nether_wart_block)
B(2,7,0,minecraft:nether_wart_block)
B(3,7,0,minecraft:nether_wart_block)
B(7,7,0,minecraft:nether_wart_block)
B(8,7,0,minecraft:nether_wart_block)
B(9,7,0,minecraft:nether_wart_block)
B(10,7,0,minecraft:nether_wart_block)
B(11,7,0,minecraft:nether_wart_block)
B(12,7,0,minecraft:nether_wart_block)
B(13,7,0,minecraft:nether_wart_block)
B(14,7,0,minecraft:nether_wart_block)
B(15,7,0,minecraft:nether_wart_block)
B(0,7,1,minecraft:nether_wart_block)
B(1,7,1,minecraft:nether_wart_block)
B(2,7,1,minecraft:nether_wart_block)
B(3,7,1,minecraft:nether_wart_block)
B(4,7,1,minecraft:nether_wart_block)
B(7,7,1,minecraft:nether_wart_block)
B(8,7,1,minecraft:nether_wart_block)
B(9,7,1,minecraft:nether_wart_block)
B(10,7,1,minecraft:nether_wart_block)
B(11,7,1,minecraft:nether_wart_block)
B(12,7,1,minecraft:nether_wart_block)
B(13,7,1,minecraft:nether_wart_block)
B(14,7,1,minecraft:nether_wart_block)
B(15,7,1,minecraft:nether_wart_block)
B(0,7,2,minecraft:nether_wart_block)
B(1,7,2,minecraft:nether_wart_block)
B(2,7,2,minecraft:nether_wart_block)
B(3,7,2,minecraft:nether_wart_block)
B(4,7,2,minecraft:nether_wart_block)
B(5,7,2,minecraft:nether_wart_block)
B(6,7,2,minecraft:nether_wart_block)
B(7,7,2,minecraft:nether_wart_block)
B(8,7,2,minecraft:nether_wart_block)
B(9,7,2,minecraft:nether_wart_block)
B(10,7,2,minecraft:nether_wart_block)
B(11,7,2,minecraft:nether_wart_block)
B(12,7,2,minecraft:nether_wart_block)
B(13,7,2,minecraft:nether_wart_block)
B(14,7,2,minecraft:nether_wart_block)
B(15,7,2,minecraft:nether_wart_block)
B(0,7,3,minecraft:nether_wart_block)
B(1,7,3,minecraft:nether_wart_block)
B(2,7,3,minecraft:nether_wart_block)
B(3,7,3,minecraft:nether_wart_block)
B(4,7,3,minecraft:nether_wart_block)
B(5,7,3,minecraft:nether_wart_block)
B(6,7,3,minecraft:nether_wart_block)
B(7,7,3,minecraft:nether_wart_block)
B(8,7,3,minecraft:nether_wart_block)
B(9,7,3,minecraft:nether_wart_block)
B(10,7,3,minecraft:nether_wart_block)
B(11,7,3,minecraft:nether_wart_block)
B(12,7,3,minecraft:nether_wart_block)
B(13,7,3,minecraft:nether_wart_block)
B(14,7,3,minecraft:nether_wart_block)
B(15,7,3,minecraft:nether_wart_block)
B(0,7,4,minecraft:nether_wart_block)
B(1,7,4,minecraft:nether_wart_block)
B(2,7,4,minecraft:nether_wart_block)
B(3,7,4,minecraft:nether_wart_block)
B(4,7,4,minecraft:nether_wart_block)
B(5,7,4,minecraft:nether_wart_block)
B(6,7,4,minecraft:nether_wart_block)
B(7,7,4,minecraft:nether_wart_block)
B(8,7,4,minecraft:nether_wart_block)
B(9,7,4,minecraft:nether_wart_block)
B(10,7,4,minecraft:nether_wart_block)
B(11,7,4,minecraft:nether_wart_block)
B(12,7,4,minecraft:nether_wart_block)
B(13,7,4,minecraft:nether_wart_block)
B(14,7,4,minecraft:nether_wart_block)
B(15,7,4,minecraft:nether_wart_block)
B(0,7,5,minecraft:nether_wart_block)
B(1,7,5,minecraft:nether_wart_block)
B(2,7,5,minecraft:nether_wart_block)
B(3,7,5,minecraft:nether_wart_block)
B(4,7,5,minecraft:nether_wart_block)
B(5,7,5,minecraft:nether_wart_block)
B(6,7,5,minecraft:nether_wart_block)
B(7,7,5,minecraft:nether_wart_block)
B(8,7,5,minecraft:nether_wart_block)
B(9,7,5,minecraft:nether_wart_block)
B(10,7,5,minecraft:nether_wart_block)
B(11,7,5,minecraft:nether_wart_block)
B(12,7,5,minecraft:nether_wart_block)
B(13,7,5,minecraft:nether_wart_block)
B(14,7,5,minecraft:nether_wart_block)
B(15,7,5,minecraft:nether_wart_block)
B(0,7,6,minecraft:nether_wart_block)
B(1,7,6,minecraft:nether_wart_block)
B(2,7,6,minecraft:nether_wart_block)
B(3,7,6,minecraft:nether_wart_block)
B(4,7,6,minecraft:nether_wart_block)
B(5,7,6,minecraft:nether_wart_block)
B(6,7,6,minecraft:nether_wart_block)
B(7,7,6,minecraft:nether_wart_block)
B(8,7,6,minecraft:nether_wart_block)
B(9,7,6,minecraft:nether_wart_block)
B(10,7,6,minecraft:nether_wart_block)
B(11,7,6,minecraft:nether_wart_block)
B(12,7,6,minecraft:nether_wart_block)
B(13,7,6,minecraft:nether_wart_block)
B(14,7,6,minecraft:nether_wart_block)
B(15,7,6,minecraft:nether_wart_block)
B(0,7,7,minecraft:nether_wart_block)
B(1,7,7,minecraft:nether_wart_block)
B(2,7,7,minecraft:nether_wart_block)
B(3,7,7,minecraft:nether_wart_block)
B(4,7,7,minecraft:nether_wart_block)
B(5,7,7,minecraft:nether_wart_block)
B(6,7,7,minecraft:nether_wart_block)
B(7,7,7,minecraft:nether_wart_block)
B(8,7,7,minecraft:nether_wart_block)
B(9,7,7,minecraft:nether_wart_block)
B(10,7,7,minecraft:nether_wart_block)
B(11,7,7,minecraft:nether_wart_block)
B(12,7,7,minecraft:nether_wart_block)
B(13,7,7,minecraft:nether_wart_block)
B(14,7,7,minecraft:nether_wart_block)
B(15,7,7,minecraft:nether_wart_block)
B(0,7,8,minecraft:nether_wart_block)
B(1,7,8,minecraft:nether_wart_block)
B(2,7,8,minecraft:nether_wart_block)
B(3,7,8,minecraft:nether_wart_block)
B(4,7,8,minecraft:nether_wart_block)
B(5,7,8,minecraft:nether_wart_block)
B(6,7,8,minecraft:nether_wart_block)
B(7,7,8,minecraft:nether_wart_block)
B(8,7,8,minecraft:nether_wart_block)
B(9,7,8,minecraft:nether_wart_block)
B(10,7,8,minecraft:nether_wart_block)
B(11,7,8,minecraft:nether_wart_block)
B(12,7,8,minecraft:nether_wart_block)
B(13,7,8,minecraft:nether_wart_block)
B(14,7,8,minecraft:nether_wart_block)
B(15,7,8,minecraft:nether_wart_block)
B(0,7,9,minecraft:nether_wart_block)
B(1,7,9,minecraft:nether_wart_block)
B(2,7,9,minecraft:nether_wart_block)
B(3,7,9,minecraft:nether_wart_block)
B(4,7,9,minecraft:nether_wart_block)
B(5,7,9,minecraft:nether_wart_block)
B(6,7,9,minecraft:nether_wart_block)
B(7,7,9,minecraft:nether_wart_block)
B(8,7,9,minecraft:nether_wart_block)
B(9,7,9,minecraft:nether_wart_block)
B(10,7,9,minecraft:nether_wart_block)
B(11,7,9,minecraft:nether_wart_block)
B(12,7,9,minecraft:nether_wart_block)
B(13,7,9,minecraft:nether_wart_block)
B(14,7,9,minecraft:nether_wart_block)
B(15,7,9,minecraft:nether_wart_block)
B(2,7,10,minecraft:nether_wart_block)
B(3,7,10,minecraft:nether_wart_block)
B(4,7,10,minecraft:nether_wart_block)
B(5,7,10,minecraft:nether_wart_block)
B(6,7,10,minecraft:nether_wart_block)
B(7,7,10,minecraft:nether_wart_block)
B(8,7,10,minecraft:nether_wart_block)
B(9,7,10,minecraft:nether_wart_block)
B(10,7,10,minecraft:nether_wart_block)
B(11,7,10,minecraft:nether_wart_block)
B(12,7,10,minecraft:nether_wart_block)
B(13,7,10,minecraft:nether_wart_block)
B(14,7,10,minecraft:nether_wart_block)
B(15,7,10,minecraft:nether_wart_block)
B(3,7,11,minecraft:nether_wart_block)
B(4,7,11,minecraft:nether_wart_block)
B(14,7,11,minecraft:nether_wart_block)
B(15,7,11,minecraft:nether_wart_block)
B(0,8,0,minecraft:nether_wart_block)
B(1,8,0,minecraft:nether_wart_block)
B(2,8,0,minecraft:nether_wart_block)
B(7,8,0,minecraft:nether_wart_block)
B(8,8,0,minecraft:nether_wart_block)
B(9,8,0,minecraft:nether_wart_block)
B(10,8,0,minecraft:nether_wart_block)
B(11,8,0,minecraft:nether_wart_block)
B(12,8,0,minecraft:nether_wart_block)
B(13,8,0,minecraft:nether_wart_block)
B(14,8,0,minecraft:nether_wart_block)
B(15,8,0,minecraft:nether_wart_block)
B(0,8,1,minecraft:nether_wart_block)
B(1,8,1,minecraft:nether_wart_block)
B(2,8,1,minecraft:nether_wart_block)
B(3,8,1,minecraft:nether_wart_block)
B(4,8,1,minecraft:nether_wart_block)
B(7,8,1,minecraft:nether_wart_block)
B(8,8,1,minecraft:nether_wart_block)
B(9,8,1,minecraft:nether_wart_block)
B(10,8,1,minecraft:nether_wart_block)
B(11,8,1,minecraft:nether_wart_block)
B(12,8,1,minecraft:nether_wart_block)
B(13,8,1,minecraft:nether_wart_block)
B(14,8,1,minecraft:nether_wart_block)
B(15,8,1,minecraft:nether_wart_block)
B(0,8,2,minecraft:nether_wart_block)
B(1,8,2,minecraft:nether_wart_block)
B(2,8,2,minecraft:nether_wart_block)
B(3,8,2,minecraft:nether_wart_block)
B(4,8,2,minecraft:nether_wart_block)
B(5,8,2,minecraft:nether_wart_block)
B(6,8,2,minecraft:nether_wart_block)
B(7,8,2,minecraft:nether_wart_block)
B(8,8,2,minecraft:nether_wart_block)
B(9,8,2,minecraft:nether_wart_block)
B(10,8,2,minecraft:nether_wart_block)
B(11,8,2,minecraft:nether_wart_block)
B(12,8,2,minecraft:nether_wart_block)
B(13,8,2,minecraft:nether_wart_block)
B(14,8,2,minecraft:nether_wart_block)
B(15,8,2,minecraft:nether_wart_block)
B(0,8,3,minecraft:nether_wart_block)
B(1,8,3,minecraft:nether_wart_block)
B(2,8,3,minecraft:nether_wart_block)
B(3,8,3,minecraft:nether_wart_block)
B(4,8,3,minecraft:nether_wart_block)
B(5,8,3,minecraft:nether_wart_block)
B(6,8,3,minecraft:nether_wart_block)
B(7,8,3,minecraft:nether_wart_block)
B(8,8,3,minecraft:nether_wart_block)
B(9,8,3,minecraft:nether_wart_block)
B(10,8,3,minecraft:nether_wart_block)
B(11,8,3,minecraft:nether_wart_block)
B(12,8,3,minecraft:nether_wart_block)
B(13,8,3,minecraft:nether_wart_block)
B(14,8,3,minecraft:nether_wart_block)
B(15,8,3,minecraft:nether_wart_block)
B(0,8,4,minecraft:nether_wart_block)
B(1,8,4,minecraft:nether_wart_block)
B(2,8,4,minecraft:nether_wart_block)
B(3,8,4,minecraft:nether_wart_block)
B(4,8,4,minecraft:nether_wart_block)
B(5,8,4,minecraft:nether_wart_block)
B(6,8,4,minecraft:nether_wart_block)
B(7,8,4,minecraft:nether_wart_block)
B(8,8,4,minecraft:nether_wart_block)
B(9,8,4,minecraft:nether_wart_block)
B(10,8,4,minecraft:nether_wart_block)
B(11,8,4,minecraft:nether_wart_block)
B(12,8,4,minecraft:nether_wart_block)
B(13,8,4,minecraft:nether_wart_block)
B(14,8,4,minecraft:nether_wart_block)
B(15,8,4,minecraft:nether_wart_block)
B(0,8,5,minecraft:nether_wart_block)
B(1,8,5,minecraft:nether_wart_block)
B(2,8,5,minecraft:nether_wart_block)
B(3,8,5,minecraft:nether_wart_block)
B(4,8,5,minecraft:nether_wart_block)
B(5,8,5,minecraft:nether_wart_block)
B(6,8,5,minecraft:nether_wart_block)
B(7,8,5,minecraft:nether_wart_block)
B(8,8,5,minecraft:nether_wart_block)
B(9,8,5,minecraft:nether_wart_block)
B(10,8,5,minecraft:nether_wart_block)
B(11,8,5,minecraft:nether_wart_block)
B(12,8,5,minecraft:nether_wart_block)
B(13,8,5,minecraft:nether_wart_block)
B(14,8,5,minecraft:nether_wart_block)
B(15,8,5,minecraft:nether_wart_block)
B(0,8,6,minecraft:nether_wart_block)
B(1,8,6,minecraft:nether_wart_block)
B(2,8,6,minecraft:nether_wart_block)
B(3,8,6,minecraft:nether_wart_block)
B(4,8,6,minecraft:nether_wart_block)
B(5,8,6,minecraft:nether_wart_block)
B(6,8,6,minecraft:nether_wart_block)
B(7,8,6,minecraft:nether_wart_block)
B(8,8,6,minecraft:nether_wart_block)
B(9,8,6,minecraft:nether_wart_block)
B(10,8,6,minecraft:nether_wart_block)
B(11,8,6,minecraft:nether_wart_block)
B(12,8,6,minecraft:nether_wart_block)
B(13,8,6,minecraft:nether_wart_block)
B(14,8,6,minecraft:nether_wart_block)
B(15,8,6,minecraft:nether_wart_block)
B(0,8,7,minecraft:nether_wart_block)
B(1,8,7,minecraft:nether_wart_block)
B(2,8,7,minecraft:nether_wart_block)
B(3,8,7,minecraft:nether_wart_block)
B(4,8,7,minecraft:nether_wart_block)
B(5,8,7,minecraft:nether_wart_block)
B(6,8,7,minecraft:nether_wart_block)
B(7,8,7,minecraft:nether_wart_block)
B(8,8,7,minecraft:nether_wart_block)
B(9,8,7,minecraft:nether_wart_block)
B(10,8,7,minecraft:nether_wart_block)
B(11,8,7,minecraft:nether_wart_block)
B(12,8,7,minecraft:nether_wart_block)
B(13,8,7,minecraft:nether_wart_block)
B(14,8,7,minecraft:nether_wart_block)
B(15,8,7,minecraft:nether_wart_block)
B(0,8,8,minecraft:nether_wart_block)
B(1,8,8,minecraft:nether_wart_block)
B(2,8,8,minecraft:nether_wart_block)
B(3,8,8,minecraft:nether_wart_block)
B(4,8,8,minecraft:nether_wart_block)
B(5,8,8,minecraft:nether_wart_block)
B(6,8,8,minecraft:nether_wart_block)
B(7,8,8,minecraft:nether_wart_block)
B(8,8,8,minecraft:nether_wart_block)
B(9,8,8,minecraft:nether_wart_block)
B(10,8,8,minecraft:nether_wart_block)
B(11,8,8,minecraft:nether_wart_block)
B(12,8,8,minecraft:nether_wart_block)
B(13,8,8,minecraft:nether_wart_block)
B(14,8,8,minecraft:nether_wart_block)
B(15,8,8,minecraft:nether_wart_block)
B(0,8,9,minecraft:nether_wart_block)
B(1,8,9,minecraft:nether_wart_block)
B(2,8,9,minecraft:nether_wart_block)
B(3,8,9,minecraft:nether_wart_block)
B(4,8,9,minecraft:nether_wart_block)
B(5,8,9,minecraft:nether_wart_block)
B(6,8,9,minecraft:nether_wart_block)
B(7,8,9,minecraft:nether_wart_block)
B(8,8,9,minecraft:nether_wart_block)
B(9,8,9,minecraft:nether_wart_block)
B(10,8,9,minecraft:nether_wart_block)
B(11,8,9,minecraft:nether_wart_block)
B(12,8,9,minecraft:nether_wart_block)
B(13,8,9,minecraft:nether_wart_block)
B(14,8,9,minecraft:nether_wart_block)
B(15,8,9,minecraft:nether_wart_block)
B(2,8,10,minecraft:nether_wart_block)
B(3,8,10,minecraft:nether_wart_block)
B(4,8,10,minecraft:nether_wart_block)
B(5,8,10,minecraft:nether_wart_block)
B(6,8,10,minecraft:nether_wart_block)
B(7,8,10,minecraft:nether_wart_block)
B(8,8,10,minecraft:nether_wart_block)
B(9,8,10,minecraft:nether_wart_block)
B(10,8,10,minecraft:nether_wart_block)
B(11,8,10,minecraft:nether_wart_block)
B(12,8,10,minecraft:nether_wart_block)
B(13,8,10,minecraft:nether_wart_block)
B(14,8,10,minecraft:nether_wart_block)
B(15,8,10,minecraft:nether_wart_block)
B(3,8,11,minecraft:nether_wart_block)
B(4,8,11,minecraft:nether_wart_block)
B(14,8,11,minecraft:nether_wart_block)
B(15,8,11,minecraft:nether_wart_block)
B(0,9,0,minecraft:nether_wart_block)
B(1,9,0,minecraft:nether_wart_block)
B(2,9,0,minecraft:nether_wart_block)
B(7,9,0,minecraft:nether_wart_block)
B(8,9,0,minecraft:nether_wart_block)
B(9,9,0,minecraft:nether_wart_block)
B(10,9,0,minecraft:nether_wart_block)
B(11,9,0,minecraft:nether_wart_block)
B(12,9,0,minecraft:nether_wart_block)
B(13,9,0,minecraft:nether_wart_block)
B(14,9,0,minecraft:nether_wart_block)
B(15,9,0,minecraft:nether_wart_block)
B(0,9,1,minecraft:nether_wart_block)
B(1,9,1,minecraft:nether_wart_block)
B(2,9,1,minecraft:nether_wart_block)
B(3,9,1,minecraft:nether_wart_block)
B(4,9,1,minecraft:nether_wart_block)
B(7,9,1,minecraft:nether_wart_block)
B(8,9,1,minecraft:nether_wart_block)
B(9,9,1,minecraft:nether_wart_block)
B(10,9,1,minecraft:nether_wart_block)
B(11,9,1,minecraft:nether_wart_block)
B(12,9,1,minecraft:nether_wart_block)
B(13,9,1,minecraft:nether_wart_block)
B(14,9,1,minecraft:nether_wart_block)
B(15,9,1,minecraft:nether_wart_block)
B(0,9,2,minecraft:nether_wart_block)
B(1,9,2,minecraft:nether_wart_block)
B(2,9,2,minecraft:nether_wart_block)
B(3,9,2,minecraft:nether_wart_block)
B(4,9,2,minecraft:nether_wart_block)
B(5,9,2,minecraft:nether_wart_block)
B(6,9,2,minecraft:nether_wart_block)
B(7,9,2,minecraft:nether_wart_block)
B(8,9,2,minecraft:nether_wart_block)
B(9,9,2,minecraft:nether_wart_block)
B(10,9,2,minecraft:nether_wart_block)
B(11,9,2,minecraft:nether_wart_block)
B(12,9,2,minecraft:nether_wart_block)
B(13,9,2,minecraft:nether_wart_block)
B(14,9,2,minecraft:nether_wart_block)
B(15,9,2,minecraft:nether_wart_block)
B(0,9,3,minecraft:nether_wart_block)
B(1,9,3,minecraft:nether_wart_block)
B(2,9,3,minecraft:nether_wart_block)
B(3,9,3,minecraft:nether_wart_block)
B(4,9,3,minecraft:nether_wart_block)
B(5,9,3,minecraft:nether_wart_block)
B(6,9,3,minecraft:nether_wart_block)
B(7,9,3,minecraft:nether_wart_block)
B(8,9,3,minecraft:nether_wart_block)
B(9,9,3,minecraft:nether_wart_block)
B(10,9,3,minecraft:nether_wart_block)
B(11,9,3,minecraft:nether_wart_block)
B(12,9,3,minecraft:nether_wart_block)
B(13,9,3,minecraft:nether_wart_block)
B(14,9,3,minecraft:nether_wart_block)
B(15,9,3,minecraft:nether_wart_block)
B(0,9,4,minecraft:nether_wart_block)
B(1,9,4,minecraft:nether_wart_block)
B(2,9,4,minecraft:nether_wart_block)
B(3,9,4,minecraft:nether_wart_block)
B(4,9,4,minecraft:nether_wart_block)
B(5,9,4,minecraft:nether_wart_block)
B(6,9,4,minecraft:nether_wart_block)
B(7,9,4,minecraft:nether_wart_block)
B(8,9,4,minecraft:nether_wart_block)
B(9,9,4,minecraft:nether_wart_block)
B(10,9,4,minecraft:nether_wart_block)
B(11,9,4,minecraft:nether_wart_block)
B(12,9,4,minecraft:nether_wart_block)
B(13,9,4,minecraft:nether_wart_block)
B(14,9,4,minecraft:nether_wart_block)
B(15,9,4,minecraft:nether_wart_block)
B(0,9,5,minecraft:nether_wart_block)
B(1,9,5,minecraft:nether_wart_block)
B(2,9,5,minecraft:nether_wart_block)
B(3,9,5,minecraft:nether_wart_block)
B(4,9,5,minecraft:nether_wart_block)
B(5,9,5,minecraft:nether_wart_block)
B(6,9,5,minecraft:nether_wart_block)
B(7,9,5,minecraft:nether_wart_block)
B(8,9,5,minecraft:nether_wart_block)
B(9,9,5,minecraft:nether_wart_block)
B(10,9,5,minecraft:nether_wart_block)
B(11,9,5,minecraft:nether_wart_block)
B(12,9,5,minecraft:nether_wart_block)
B(13,9,5,minecraft:nether_wart_block)
B(14,9,5,minecraft:nether_wart_block)
B(15,9,5,minecraft:nether_wart_block)
B(0,9,6,minecraft:nether_wart_block)
B(1,9,6,minecraft:nether_wart_block)
B(2,9,6,minecraft:nether_wart_block)
B(3,9,6,minecraft:nether_wart_block)
B(4,9,6,minecraft:nether_wart_block)
B(5,9,6,minecraft:nether_wart_block)
B(6,9,6,minecraft:nether_wart_block)
B(7,9,6,minecraft:nether_wart_block)
B(8,9,6,minecraft:nether_wart_block)
B(9,9,6,minecraft:nether_wart_block)
B(10,9,6,minecraft:nether_wart_block)
B(11,9,6,minecraft:nether_wart_block)
B(12,9,6,minecraft:nether_wart_block)
B(13,9,6,minecraft:nether_wart_block)
B(14,9,6,minecraft:nether_wart_block)
B(15,9,6,minecraft:nether_wart_block)
B(0,9,7,minecraft:nether_wart_block)
B(1,9,7,minecraft:nether_wart_block)
B(2,9,7,minecraft:nether_wart_block)
B(3,9,7,minecraft:nether_wart_block)
B(4,9,7,minecraft:nether_wart_block)
B(5,9,7,minecraft:nether_wart_block)
B(6,9,7,minecraft:nether_wart_block)
B(7,9,7,minecraft:nether_wart_block)
B(8,9,7,minecraft:nether_wart_block)
B(9,9,7,minecraft:nether_wart_block)
B(10,9,7,minecraft:nether_wart_block)
B(11,9,7,minecraft:nether_wart_block)
B(12,9,7,minecraft:nether_wart_block)
B(13,9,7,minecraft:nether_wart_block)
B(14,9,7,minecraft:nether_wart_block)
B(15,9,7,minecraft:nether_wart_block)
B(0,9,8,minecraft:nether_wart_block)
B(1,9,8,minecraft:nether_wart_block)
B(2,9,8,minecraft:nether_wart_block)
B(3,9,8,minecraft:nether_wart_block)
B(4,9,8,minecraft:nether_wart_block)
B(5,9,8,minecraft:nether_wart_block)
B(6,9,8,minecraft:nether_wart_block)
B(7,9,8,minecraft:nether_wart_block)
B(8,9,8,minecraft:nether_wart_block)
B(9,9,8,minecraft:nether_wart_block)
B(10,9,8,minecraft:nether_wart_block)
B(11,9,8,minecraft:nether_wart_block)
B(12,9,8,minecraft:nether_wart_block)
B(13,9,8,minecraft:nether_wart_block)
B(14,9,8,minecraft:nether_wart_block)
B(15,9,8,minecraft:nether_wart_block)
B(0,9,9,minecraft:nether_wart_block)
B(1,9,9,minecraft:nether_wart_block)
B(2,9,9,minecraft:nether_wart_block)
B(3,9,9,minecraft:nether_wart_block)
B(4,9,9,minecraft:nether_wart_block)
B(5,9,9,minecraft:nether_wart_block)
B(6,9,9,minecraft:nether_wart_block)
B(7,9,9,minecraft:nether_wart_block)
B(8,9,9,minecraft:nether_wart_block)
B(9,9,9,minecraft:nether_wart_block)
B(10,9,9,minecraft:nether_wart_block)
B(11,9,9,minecraft:nether_wart_block)
B(12,9,9,minecraft:nether_wart_block)
B(13,9,9,minecraft:nether_wart_block)
B(14,9,9,minecraft:nether_wart_block)
B(15,9,9,minecraft:nether_wart_block)
B(2,9,10,minecraft:nether_wart_block)
B(3,9,10,minecraft:nether_wart_block)
B(4,9,10,minecraft:nether_wart_block)
B(5,9,10,minecraft:nether_wart_block)
B(6,9,10,minecraft:nether_wart_block)
B(7,9,10,minecraft:nether_wart_block)
B(8,9,10,minecraft:nether_wart_block)
B(9,9,10,minecraft:nether_wart_block)
B(10,9,10,minecraft:nether_wart_block)
B(11,9,10,minecraft:nether_wart_block)
B(13,9,10,minecraft:nether_wart_block)
B(14,9,10,minecraft:nether_wart_block)
B(15,9,10,minecraft:nether_wart_block)
B(3,9,11,minecraft:nether_wart_block)
B(14,9,11,minecraft:nether_wart_block)
B(15,9,11,minecraft:nether_wart_block)
B(0,10,0,minecraft:nether_wart_block)
B(1,10,0,minecraft:nether_wart_block)
B(2,10,0,minecraft:nether_wart_block)
B(7,10,0,minecraft:nether_wart_block)
B(8,10,0,minecraft:nether_wart_block)
B(9,10,0,minecraft:nether_wart_block)
B(10,10,0,minecraft:nether_wart_block)
B(11,10,0,minecraft:nether_wart_block)
B(12,10,0,minecraft:nether_wart_block)
B(13,10,0,minecraft:nether_wart_block)
B(14,10,0,minecraft:nether_wart_block)
B(15,10,0,minecraft:nether_wart_block)
B(0,10,1,minecraft:nether_wart_block)
B(1,10,1,minecraft:nether_wart_block)
B(2,10,1,minecraft:nether_wart_block)
B(3,10,1,minecraft:nether_wart_block)
B(4,10,1,minecraft:nether_wart_block)
B(7,10,1,minecraft:nether_wart_block)
B(8,10,1,minecraft:nether_wart_block)
B(9,10,1,minecraft:nether_wart_block)
B(10,10,1,minecraft:nether_wart_block)
B(11,10,1,minecraft:nether_wart_block)
B(12,10,1,minecraft:nether_wart_block)
B(13,10,1,minecraft:nether_wart_block)
B(14,10,1,minecraft:nether_wart_block)
B(15,10,1,minecraft:nether_wart_block)
B(0,10,2,minecraft:nether_wart_block)
B(1,10,2,minecraft:nether_wart_block)
B(2,10,2,minecraft:nether_wart_block)
B(3,10,2,minecraft:nether_wart_block)
B(4,10,2,minecraft:nether_wart_block)
B(5,10,2,minecraft:nether_wart_block)
B(6,10,2,minecraft:nether_wart_block)
B(7,10,2,minecraft:nether_wart_block)
B(8,10,2,minecraft:nether_wart_block)
B(9,10,2,minecraft:nether_wart_block)
B(10,10,2,minecraft:nether_wart_block)
B(11,10,2,minecraft:nether_wart_block)
B(12,10,2,minecraft:nether_wart_block)
B(13,10,2,minecraft:nether_wart_block)
B(14,10,2,minecraft:nether_wart_block)
B(15,10,2,minecraft:nether_wart_block)
B(0,10,3,minecraft:nether_wart_block)
B(1,10,3,minecraft:nether_wart_block)
B(2,10,3,minecraft:nether_wart_block)
B(3,10,3,minecraft:nether_wart_block)
B(4,10,3,minecraft:nether_wart_block)
B(5,10,3,minecraft:nether_wart_block)
B(6,10,3,minecraft:nether_wart_block)
B(7,10,3,minecraft:nether_wart_block)
B(8,10,3,minecraft:nether_wart_block)
B(9,10,3,minecraft:nether_wart_block)
B(10,10,3,minecraft:nether_wart_block)
B(11,10,3,minecraft:nether_wart_block)
B(12,10,3,minecraft:nether_wart_block)
B(13,10,3,minecraft:nether_wart_block)
B(14,10,3,minecraft:nether_wart_block)
B(15,10,3,minecraft:nether_wart_block)
B(0,10,4,minecraft:nether_wart_block)
B(1,10,4,minecraft:nether_wart_block)
B(2,10,4,minecraft:nether_wart_block)
B(3,10,4,minecraft:nether_wart_block)
B(4,10,4,minecraft:nether_wart_block)
B(5,10,4,minecraft:nether_wart_block)
B(6,10,4,minecraft:nether_wart_block)
B(7,10,4,minecraft:nether_wart_block)
B(8,10,4,minecraft:nether_wart_block)
B(9,10,4,minecraft:nether_wart_block)
B(10,10,4,minecraft:nether_wart_block)
B(11,10,4,minecraft:nether_wart_block)
B(12,10,4,minecraft:nether_wart_block)
B(13,10,4,minecraft:nether_wart_block)
B(14,10,4,minecraft:nether_wart_block)
B(15,10,4,minecraft:nether_wart_block)
B(0,10,5,minecraft:nether_wart_block)
B(1,10,5,minecraft:nether_wart_block)
B(2,10,5,minecraft:nether_wart_block)
B(3,10,5,minecraft:nether_wart_block)
B(4,10,5,minecraft:nether_wart_block)
B(5,10,5,minecraft:nether_wart_block)
B(6,10,5,minecraft:nether_wart_block)
B(7,10,5,minecraft:nether_wart_block)
B(8,10,5,minecraft:nether_wart_block)
B(9,10,5,minecraft:nether_wart_block)
B(10,10,5,minecraft:nether_wart_block)
B(11,10,5,minecraft:nether_wart_block)
B(12,10,5,minecraft:nether_wart_block)
B(13,10,5,minecraft:nether_wart_block)
B(14,10,5,minecraft:nether_wart_block)
B(15,10,5,minecraft:nether_wart_block)
B(0,10,6,minecraft:nether_wart_block)
B(1,10,6,minecraft:nether_wart_block)
B(2,10,6,minecraft:nether_wart_block)
B(3,10,6,minecraft:nether_wart_block)
B(4,10,6,minecraft:nether_wart_block)
B(5,10,6,minecraft:nether_wart_block)
B(6,10,6,minecraft:nether_wart_block)
B(7,10,6,minecraft:nether_wart_block)
B(8,10,6,minecraft:nether_wart_block)
B(9,10,6,minecraft:nether_wart_block)
B(10,10,6,minecraft:nether_wart_block)
B(11,10,6,minecraft:nether_wart_block)
B(12,10,6,minecraft:nether_wart_block)
B(13,10,6,minecraft:nether_wart_block)
B(14,10,6,minecraft:nether_wart_block)
B(15,10,6,minecraft:nether_wart_block)
B(0,10,7,minecraft:nether_wart_block)
B(1,10,7,minecraft:nether_wart_block)
B(2,10,7,minecraft:nether_wart_block)
B(3,10,7,minecraft:nether_wart_block)
B(4,10,7,minecraft:nether_wart_block)
B(5,10,7,minecraft:nether_wart_block)
B(6,10,7,minecraft:nether_wart_block)
B(7,10,7,minecraft:nether_wart_block)
B(8,10,7,minecraft:nether_wart_block)
B(9,10,7,minecraft:nether_wart_block)
B(10,10,7,minecraft:nether_wart_block)
B(11,10,7,minecraft:nether_wart_block)
B(12,10,7,minecraft:nether_wart_block)
B(13,10,7,minecraft:nether_wart_block)
B(14,10,7,minecraft:nether_wart_block)
B(15,10,7,minecraft:nether_wart_block)
B(0,10,8,minecraft:nether_wart_block)
B(1,10,8,minecraft:nether_wart_block)
B(2,10,8,minecraft:nether_wart_block)
B(3,10,8,minecraft:nether_wart_block)
B(4,10,8,minecraft:nether_wart_block)
B(5,10,8,minecraft:nether_wart_block)
B(6,10,8,minecraft:nether_wart_block)
B(7,10,8,minecraft:nether_wart_block)
B(8,10,8,minecraft:nether_wart_block)
B(9,10,8,minecraft:nether_wart_block)
B(10,10,8,minecraft:nether_wart_block)
B(11,10,8,minecraft:nether_wart_block)
B(12,10,8,minecraft:nether_wart_block)
B(13,10,8,minecraft:nether_wart_block)
B(14,10,8,minecraft:nether_wart_block)
B(15,10,8,minecraft:nether_wart_block)
B(0,10,9,minecraft:nether_wart_block)
B(1,10,9,minecraft:nether_wart_block)
B(2,10,9,minecraft:nether_wart_block)
B(3,10,9,minecraft:nether_wart_block)
B(4,10,9,minecraft:nether_wart_block)
B(5,10,9,minecraft:nether_wart_block)
B(6,10,9,minecraft:nether_wart_block)
B(7,10,9,minecraft:nether_wart_block)
B(8,10,9,minecraft:nether_wart_block)
B(9,10,9,minecraft:nether_wart_block)
B(10,10,9,minecraft:nether_wart_block)
B(11,10,9,minecraft:nether_wart_block)
B(12,10,9,minecraft:nether_wart_block)
B(13,10,9,minecraft:nether_wart_block)
B(14,10,9,minecraft:nether_wart_block)
B(15,10,9,minecraft:nether_wart_block)
B(2,10,10,minecraft:nether_wart_block)
B(3,10,10,minecraft:nether_wart_block)
B(4,10,10,minecraft:nether_wart_block)
B(5,10,10,minecraft:nether_wart_block)
B(6,10,10,minecraft:nether_wart_block)
B(7,10,10,minecraft:nether_wart_block)
B(8,10,10,minecraft:nether_wart_block)
B(9,10,10,minecraft:nether_wart_block)
B(10,10,10,minecraft:nether_wart_block)
B(11,10,10,minecraft:nether_wart_block)
B(13,10,10,minecraft:nether_wart_block)
B(14,10,10,minecraft:nether_wart_block)
B(15,10,10,minecraft:nether_wart_block)
B(3,10,11,minecraft:nether_wart_block)
B(15,10,11,minecraft:nether_wart_block)
B(0,11,0,minecraft:nether_wart_block)
B(1,11,0,minecraft:nether_wart_block)
B(2,11,0,minecraft:nether_wart_block)
B(7,11,0,minecraft:nether_wart_block)
B(8,11,0,minecraft:nether_wart_block)
B(9,11,0,minecraft:nether_wart_block)
B(10,11,0,minecraft:nether_wart_block)
B(11,11,0,minecraft:nether_wart_block)
B(12,11,0,minecraft:nether_wart_block)
B(13,11,0,minecraft:nether_wart_block)
B(14,11,0,minecraft:nether_wart_block)
B(15,11,0,minecraft:nether_wart_block)
B(0,11,1,minecraft:nether_wart_block)
B(1,11,1,minecraft:nether_wart_block)
B(2,11,1,minecraft:nether_wart_block)
B(3,11,1,minecraft:nether_wart_block)
B(4,11,1,minecraft:nether_wart_block)
B(7,11,1,minecraft:nether_wart_block)
B(8,11,1,minecraft:nether_wart_block)
B(9,11,1,minecraft:nether_wart_block)
B(10,11,1,minecraft:nether_wart_block)
B(11,11,1,minecraft:nether_wart_block)
B(12,11,1,minecraft:nether_wart_block)
B(13,11,1,minecraft:nether_wart_block)
B(14,11,1,minecraft:nether_wart_block)
B(15,11,1,minecraft:nether_wart_block)
B(0,11,2,minecraft:nether_wart_block)
B(1,11,2,minecraft:nether_wart_block)
B(2,11,2,minecraft:nether_wart_block)
B(3,11,2,minecraft:nether_wart_block)
B(4,11,2,minecraft:nether_wart_block)
B(5,11,2,minecraft:nether_wart_block)
B(6,11,2,minecraft:nether_wart_block)
B(7,11,2,minecraft:nether_wart_block)
B(8,11,2,minecraft:nether_wart_block)
B(9,11,2,minecraft:nether_wart_block)
B(10,11,2,minecraft:nether_wart_block)
B(11,11,2,minecraft:nether_wart_block)
B(12,11,2,minecraft:nether_wart_block)
B(13,11,2,minecraft:nether_wart_block)
B(14,11,2,minecraft:nether_wart_block)
B(15,11,2,minecraft:nether_wart_block)
B(0,11,3,minecraft:nether_wart_block)
B(1,11,3,minecraft:nether_wart_block)
B(2,11,3,minecraft:nether_wart_block)
B(3,11,3,minecraft:nether_wart_block)
B(4,11,3,minecraft:nether_wart_block)
B(5,11,3,minecraft:nether_wart_block)
B(6,11,3,minecraft:nether_wart_block)
B(7,11,3,minecraft:nether_wart_block)
B(8,11,3,minecraft:nether_wart_block)
B(9,11,3,minecraft:nether_wart_block)
B(10,11,3,minecraft:nether_wart_block)
B(11,11,3,minecraft:nether_wart_block)
B(12,11,3,minecraft:nether_wart_block)
B(13,11,3,minecraft:nether_wart_block)
B(14,11,3,minecraft:nether_wart_block)
B(15,11,3,minecraft:nether_wart_block)
B(0,11,4,minecraft:nether_wart_block)
B(1,11,4,minecraft:nether_wart_block)
B(2,11,4,minecraft:nether_wart_block)
B(3,11,4,minecraft:nether_wart_block)
B(4,11,4,minecraft:nether_wart_block)
B(5,11,4,minecraft:nether_wart_block)
B(6,11,4,minecraft:nether_wart_block)
B(7,11,4,minecraft:nether_wart_block)
B(8,11,4,minecraft:nether_wart_block)
B(9,11,4,minecraft:nether_wart_block)
B(10,11,4,minecraft:nether_wart_block)
B(11,11,4,minecraft:nether_wart_block)
B(12,11,4,minecraft:nether_wart_block)
B(13,11,4,minecraft:nether_wart_block)
B(14,11,4,minecraft:nether_wart_block)
B(15,11,4,minecraft:nether_wart_block)
B(0,11,5,minecraft:nether_wart_block)
B(1,11,5,minecraft:nether_wart_block)
B(2,11,5,minecraft:nether_wart_block)
B(3,11,5,minecraft:nether_wart_block)
B(4,11,5,minecraft:nether_wart_block)
B(5,11,5,minecraft:nether_wart_block)
B(6,11,5,minecraft:nether_wart_block)
B(7,11,5,minecraft:nether_wart_block)
B(8,11,5,minecraft:nether_wart_block)
B(9,11,5,minecraft:nether_wart_block)
B(10,11,5,minecraft:nether_wart_block)
B(11,11,5,minecraft:nether_wart_block)
B(12,11,5,minecraft:nether_wart_block)
B(13,11,5,minecraft:nether_wart_block)
B(14,11,5,minecraft:nether_wart_block)
B(15,11,5,minecraft:nether_wart_block)
B(0,11,6,minecraft:nether_wart_block)
B(1,11,6,minecraft:nether_wart_block)
B(2,11,6,minecraft:nether_wart_block)
B(3,11,6,minecraft:nether_wart_block)
B(4,11,6,minecraft:nether_wart_block)
B(5,11,6,minecraft:nether_wart_block)
B(6,11,6,minecraft:nether_wart_block)
B(7,11,6,minecraft:nether_wart_block)
B(8,11,6,minecraft:nether_wart_block)
B(9,11,6,minecraft:nether_wart_block)
B(10,11,6,minecraft:nether_wart_block)
B(11,11,6,minecraft:nether_wart_block)
B(12,11,6,minecraft:nether_wart_block)
B(13,11,6,minecraft:nether_wart_block)
B(14,11,6,minecraft:nether_wart_block)
B(15,11,6,minecraft:nether_wart_block)
B(0,11,7,minecraft:nether_wart_block)
B(1,11,7,minecraft:nether_wart_block)
B(2,11,7,minecraft:nether_wart_block)
B(3,11,7,minecraft:nether_wart_block)
B(4,11,7,minecraft:nether_wart_block)
B(5,11,7,minecraft:nether_wart_block)
B(6,11,7,minecraft:nether_wart_block)
B(7,11,7,minecraft:nether_wart_block)
B(8,11,7,minecraft:nether_wart_block)
B(9,11,7,minecraft:nether_wart_block)
B(10,11,7,minecraft:nether_wart_block)
B(11,11,7,minecraft:nether_wart_block)
B(12,11,7,minecraft:nether_wart_block)
B(13,11,7,minecraft:nether_wart_block)
B(14,11,7,minecraft:nether_wart_block)
B(15,11,7,minecraft:nether_wart_block)
B(0,11,8,minecraft:nether_wart_block)
B(1,11,8,minecraft:nether_wart_block)
B(2,11,8,minecraft:nether_wart_block)
B(3,11,8,minecraft:nether_wart_block)
B(4,11,8,minecraft:nether_wart_block)
B(5,11,8,minecraft:nether_wart_block)
B(6,11,8,minecraft:nether_wart_block)
B(7,11,8,minecraft:nether_wart_block)
B(8,11,8,minecraft:nether_wart_block)
B(9,11,8,minecraft:nether_wart_block)
B(10,11,8,minecraft:nether_wart_block)
B(11,11,8,minecraft:nether_wart_block)
B(12,11,8,minecraft:nether_wart_block)
B(13,11,8,minecraft:nether_wart_block)
B(14,11,8,minecraft:nether_wart_block)
B(15,11,8,minecraft:nether_wart_block)
B(0,11,9,minecraft:nether_wart_block)
B(1,11,9,minecraft:nether_wart_block)
B(2,11,9,minecraft:nether_wart_block)
B(3,11,9,minecraft:nether_wart_block)
B(4,11,9,minecraft:nether_wart_block)
B(5,11,9,minecraft:nether_wart_block)
B(6,11,9,minecraft:nether_wart_block)
B(7,11,9,minecraft:nether_wart_block)
B(8,11,9,minecraft:nether_wart_block)
B(9,11,9,minecraft:nether_wart_block)
B(10,11,9,minecraft:nether_wart_block)
B(11,11,9,minecraft:nether_wart_block)
B(12,11,9,minecraft:nether_wart_block)
B(13,11,9,minecraft:nether_wart_block)
B(14,11,9,minecraft:nether_wart_block)
B(15,11,9,minecraft:nether_wart_block)
B(2,11,10,minecraft:nether_wart_block)
B(3,11,10,minecraft:nether_wart_block)
B(4,11,10,minecraft:nether_wart_block)
B(5,11,10,minecraft:nether_wart_block)
B(6,11,10,minecraft:nether_wart_block)
B(8,11,10,minecraft:nether_wart_block)
B(9,11,10,minecraft:nether_wart_block)
B(11,11,10,minecraft:nether_wart_block)
B(13,11,10,minecraft:nether_wart_block)
B(14,11,10,minecraft:nether_wart_block)
B(15,11,10,minecraft:nether_wart_block)
B(3,11,11,minecraft:nether_wart_block)
B(15,11,11,minecraft:nether_wart_block)
B(0,12,0,minecraft:nether_wart_block)
B(1,12,0,minecraft:nether_wart_block)
B(2,12,0,minecraft:nether_wart_block)
B(7,12,0,minecraft:nether_wart_block)
B(8,12,0,minecraft:nether_wart_block)
B(9,12,0,minecraft:nether_wart_block)
B(10,12,0,minecraft:nether_wart_block)
B(11,12,0,minecraft:nether_wart_block)
B(12,12,0,minecraft:nether_wart_block)
B(13,12,0,minecraft:nether_wart_block)
B(14,12,0,minecraft:nether_wart_block)
B(15,12,0,minecraft:nether_wart_block)
B(0,12,1,minecraft:nether_wart_block)
B(1,12,1,minecraft:nether_wart_block)
B(2,12,1,minecraft:nether_wart_block)
B(3,12,1,minecraft:nether_wart_block)
B(4,12,1,minecraft:nether_wart_block)
B(7,12,1,minecraft:nether_wart_block)
B(8,12,1,minecraft:nether_wart_block)
B(9,12,1,minecraft:nether_wart_block)
B(10,12,1,minecraft:nether_wart_block)
B(11,12,1,minecraft:nether_wart_block)
B(12,12,1,minecraft:nether_wart_block)
B(13,12,1,minecraft:nether_wart_block)
B(14,12,1,minecraft:nether_wart_block)
B(15,12,1,minecraft:nether_wart_block)
B(0,12,2,minecraft:nether_wart_block)
B(1,12,2,minecraft:nether_wart_block)
B(2,12,2,minecraft:nether_wart_block)
B(3,12,2,minecraft:nether_wart_block)
B(4,12,2,minecraft:nether_wart_block)
B(5,12,2,minecraft:nether_wart_block)
B(6,12,2,minecraft:nether_wart_block)
B(7,12,2,minecraft:nether_wart_block)
B(8,12,2,minecraft:nether_wart_block)
B(9,12,2,minecraft:nether_wart_block)
B(10,12,2,minecraft:nether_wart_block)
B(11,12,2,minecraft:nether_wart_block)
B(12,12,2,minecraft:nether_wart_block)
B(13,12,2,minecraft:nether_wart_block)
B(14,12,2,minecraft:nether_wart_block)
B(15,12,2,minecraft:nether_wart_block)
B(0,12,3,minecraft:nether_wart_block)
B(1,12,3,minecraft:nether_wart_block)
B(2,12,3,minecraft:nether_wart_block)
B(3,12,3,minecraft:nether_wart_block)
B(4,12,3,minecraft:nether_wart_block)
B(5,12,3,minecraft:nether_wart_block)
B(6,12,3,minecraft:nether_wart_block)
B(7,12,3,minecraft:nether_wart_block)
B(8,12,3,minecraft:nether_wart_block)
B(9,12,3,minecraft:nether_wart_block)
B(10,12,3,minecraft:nether_wart_block)
B(11,12,3,minecraft:nether_wart_block)
B(12,12,3,minecraft:nether_wart_block)
B(13,12,3,minecraft:nether_wart_block)
B(14,12,3,minecraft:nether_wart_block)
B(15,12,3,minecraft:nether_wart_block)
B(0,12,4,minecraft:nether_wart_block)
B(1,12,4,minecraft:nether_wart_block)
B(2,12,4,minecraft:nether_wart_block)
B(3,12,4,minecraft:nether_wart_block)
B(4,12,4,minecraft:nether_wart_block)
B(5,12,4,minecraft:nether_wart_block)
B(6,12,4,minecraft:nether_wart_block)
B(7,12,4,minecraft:nether_wart_block)
B(8,12,4,minecraft:nether_wart_block)
B(9,12,4,minecraft:nether_wart_block)
B(10,12,4,minecraft:nether_wart_block)
B(11,12,4,minecraft:nether_wart_block)
B(12,12,4,minecraft:nether_wart_block)
B(13,12,4,minecraft:nether_wart_block)
B(14,12,4,minecraft:nether_wart_block)
B(15,12,4,minecraft:nether_wart_block)
B(0,12,5,minecraft:nether_wart_block)
B(1,12,5,minecraft:nether_wart_block)
B(2,12,5,minecraft:nether_wart_block)
B(3,12,5,minecraft:nether_wart_block)
B(4,12,5,minecraft:nether_wart_block)
B(5,12,5,minecraft:nether_wart_block)
B(6,12,5,minecraft:nether_wart_block)
B(7,12,5,minecraft:nether_wart_block)
B(8,12,5,minecraft:nether_wart_block)
B(9,12,5,minecraft:nether_wart_block)
B(10,12,5,minecraft:nether_wart_block)
B(11,12,5,minecraft:nether_wart_block)
B(12,12,5,minecraft:nether_wart_block)
B(13,12,5,minecraft:nether_wart_block)
B(14,12,5,minecraft:nether_wart_block)
B(15,12,5,minecraft:nether_wart_block)
B(0,12,6,minecraft:nether_wart_block)
B(1,12,6,minecraft:nether_wart_block)
B(2,12,6,minecraft:nether_wart_block)
B(3,12,6,minecraft:nether_wart_block)
B(4,12,6,minecraft:nether_wart_block)
B(5,12,6,minecraft:nether_wart_block)
B(6,12,6,minecraft:nether_wart_block)
B(7,12,6,minecraft:nether_wart_block)
B(8,12,6,minecraft:nether_wart_block)
B(9,12,6,minecraft:nether_wart_block)
B(10,12,6,minecraft:nether_wart_block)
B(11,12,6,minecraft:nether_wart_block)
B(12,12,6,minecraft:nether_wart_block)
B(13,12,6,minecraft:nether_wart_block)
B(14,12,6,minecraft:nether_wart_block)
B(15,12,6,minecraft:nether_wart_block)
B(0,12,7,minecraft:nether_wart_block)
B(1,12,7,minecraft:nether_wart_block)
B(2,12,7,minecraft:nether_wart_block)
B(3,12,7,minecraft:nether_wart_block)
B(4,12,7,minecraft:nether_wart_block)
B(5,12,7,minecraft:nether_wart_block)
B(6,12,7,minecraft:nether_wart_block)
B(7,12,7,minecraft:nether_wart_block)
B(8,12,7,minecraft:nether_wart_block)
B(9,12,7,minecraft:nether_wart_block)
B(10,12,7,minecraft:nether_wart_block)
B(11,12,7,minecraft:nether_wart_block)
B(12,12,7,minecraft:nether_wart_block)
B(13,12,7,minecraft:nether_wart_block)
B(14,12,7,minecraft:nether_wart_block)
B(15,12,7,minecraft:nether_wart_block)
B(0,12,8,minecraft:nether_wart_block)
B(1,12,8,minecraft:nether_wart_block)
B(2,12,8,minecraft:nether_wart_block)
B(3,12,8,minecraft:nether_wart_block)
B(4,12,8,minecraft:nether_wart_block)
B(5,12,8,minecraft:nether_wart_block)
B(6,12,8,minecraft:nether_wart_block)
B(7,12,8,minecraft:nether_wart_block)
B(8,12,8,minecraft:nether_wart_block)
B(9,12,8,minecraft:nether_wart_block)
B(10,12,8,minecraft:nether_wart_block)
B(11,12,8,minecraft:nether_wart_block)
B(12,12,8,minecraft:nether_wart_block)
B(13,12,8,minecraft:nether_wart_block)
B(14,12,8,minecraft:nether_wart_block)
B(15,12,8,minecraft:nether_wart_block)
B(0,12,9,minecraft:nether_wart_block)
B(1,12,9,minecraft:nether_wart_block)
B(2,12,9,minecraft:nether_wart_block)
B(3,12,9,minecraft:nether_wart_block)
B(4,12,9,minecraft:nether_wart_block)
B(5,12,9,minecraft:nether_wart_block)
B(6,12,9,minecraft:nether_wart_block)
B(7,12,9,minecraft:nether_wart_block)
B(8,12,9,minecraft:nether_wart_block)
B(9,12,9,minecraft:nether_wart_block)
B(10,12,9,minecraft:nether_wart_block)
B(11,12,9,minecraft:nether_wart_block)
B(12,12,9,minecraft:nether_wart_block)
B(13,12,9,minecraft:nether_wart_block)
B(14,12,9,minecraft:nether_wart_block)
B(15,12,9,minecraft:nether_wart_block)
B(2,12,10,minecraft:nether_wart_block)
B(3,12,10,minecraft:nether_wart_block)
B(4,12,10,minecraft:nether_wart_block)
B(5,12,10,minecraft:nether_wart_block)
B(6,12,10,minecraft:nether_wart_block)
B(8,12,10,minecraft:nether_wart_block)
B(9,12,10,minecraft:nether_wart_block)
B(11,12,10,minecraft:nether_wart_block)
B(13,12,10,minecraft:nether_wart_block)
B(14,12,10,minecraft:nether_wart_block)
B(15,12,10,minecraft:nether_wart_block)
B(3,12,11,minecraft:nether_wart_block)
B(0,13,0,minecraft:nether_wart_block)
B(1,13,0,minecraft:nether_wart_block)
B(2,13,0,minecraft:nether_wart_block)
B(7,13,0,minecraft:nether_wart_block)
B(8,13,0,minecraft:nether_wart_block)
B(9,13,0,minecraft:nether_wart_block)
B(10,13,0,minecraft:nether_wart_block)
B(11,13,0,minecraft:nether_wart_block)
B(12,13,0,minecraft:nether_wart_block)
B(13,13,0,minecraft:nether_wart_block)
B(14,13,0,minecraft:nether_wart_block)
B(15,13,0,minecraft:nether_wart_block)
B(0,13,1,minecraft:nether_wart_block)
B(1,13,1,minecraft:nether_wart_block)
B(2,13,1,minecraft:nether_wart_block)
B(3,13,1,minecraft:nether_wart_block)
B(4,13,1,minecraft:nether_wart_block)
B(7,13,1,minecraft:nether_wart_block)
B(8,13,1,minecraft:nether_wart_block)
B(9,13,1,minecraft:nether_wart_block)
B(10,13,1,minecraft:nether_wart_block)
B(11,13,1,minecraft:nether_wart_block)
B(12,13,1,minecraft:nether_wart_block)
B(13,13,1,minecraft:nether_wart_block)
B(14,13,1,minecraft:nether_wart_block)
B(15,13,1,minecraft:nether_wart_block)
B(0,13,2,minecraft:nether_wart_block)
B(1,13,2,minecraft:nether_wart_block)
B(2,13,2,minecraft:nether_wart_block)
B(3,13,2,minecraft:nether_wart_block)
B(4,13,2,minecraft:nether_wart_block)
B(5,13,2,minecraft:nether_wart_block)
B(6,13,2,minecraft:nether_wart_block)
B(7,13,2,minecraft:nether_wart_block)
B(8,13,2,minecraft:nether_wart_block)
B(9,13,2,minecraft:nether_wart_block)
B(10,13,2,minecraft:nether_wart_block)
B(11,13,2,minecraft:nether_wart_block)
B(12,13,2,minecraft:nether_wart_block)
B(13,13,2,minecraft:nether_wart_block)
B(14,13,2,minecraft:nether_wart_block)
B(15,13,2,minecraft:nether_wart_block)
B(0,13,3,minecraft:nether_wart_block)
B(1,13,3,minecraft:nether_wart_block)
B(2,13,3,minecraft:nether_wart_block)
B(3,13,3,minecraft:nether_wart_block)
B(4,13,3,minecraft:nether_wart_block)
B(5,13,3,minecraft:nether_wart_block)
B(6,13,3,minecraft:nether_wart_block)
B(7,13,3,minecraft:nether_wart_block)
B(8,13,3,minecraft:nether_wart_block)
B(9,13,3,minecraft:nether_wart_block)
B(10,13,3,minecraft:nether_wart_block)
B(11,13,3,minecraft:nether_wart_block)
B(12,13,3,minecraft:nether_wart_block)
B(13,13,3,minecraft:nether_wart_block)
B(14,13,3,minecraft:nether_wart_block)
B(15,13,3,minecraft:nether_wart_block)
B(0,13,4,minecraft:nether_wart_block)
B(1,13,4,minecraft:nether_wart_block)
B(2,13,4,minecraft:nether_wart_block)
B(3,13,4,minecraft:nether_wart_block)
B(4,13,4,minecraft:nether_wart_block)
B(5,13,4,minecraft:nether_wart_block)
B(6,13,4,minecraft:nether_wart_block)
B(7,13,4,minecraft:nether_wart_block)
B(8,13,4,minecraft:nether_wart_block)
B(9,13,4,minecraft:nether_wart_block)
B(10,13,4,minecraft:nether_wart_block)
B(11,13,4,minecraft:nether_wart_block)
B(12,13,4,minecraft:nether_wart_block)
B(13,13,4,minecraft:nether_wart_block)
B(14,13,4,minecraft:nether_wart_block)
B(15,13,4,minecraft:nether_wart_block)
B(0,13,5,minecraft:nether_wart_block)
B(1,13,5,minecraft:nether_wart_block)
B(2,13,5,minecraft:nether_wart_block)
B(3,13,5,minecraft:nether_wart_block)
B(4,13,5,minecraft:nether_wart_block)
B(5,13,5,minecraft:nether_wart_block)
B(6,13,5,minecraft:nether_wart_block)
B(7,13,5,minecraft:nether_wart_block)
B(8,13,5,minecraft:nether_wart_block)
B(9,13,5,minecraft:nether_wart_block)
B(10,13,5,minecraft:nether_wart_block)
B(11,13,5,minecraft:nether_wart_block)
B(12,13,5,minecraft:nether_wart_block)
B(13,13,5,minecraft:nether_wart_block)
B(14,13,5,minecraft:nether_wart_block)
B(15,13,5,minecraft:nether_wart_block)
B(0,13,6,minecraft:nether_wart_block)
B(1,13,6,minecraft:nether_wart_block)
B(2,13,6,minecraft:nether_wart_block)
B(3,13,6,minecraft:nether_wart_block)
B(4,13,6,minecraft:nether_wart_block)
B(5,13,6,minecraft:nether_wart_block)
B(6,13,6,minecraft:nether_wart_block)
B(7,13,6,minecraft:nether_wart_block)
B(8,13,6,minecraft:nether_wart_block)
B(9,13,6,minecraft:nether_wart_block)
B(10,13,6,minecraft:nether_wart_block)
B(11,13,6,minecraft:nether_wart_block)
B(12,13,6,minecraft:nether_wart_block)
B(13,13,6,minecraft:nether_wart_block)
B(14,13,6,minecraft:nether_wart_block)
B(15,13,6,minecraft:nether_wart_block)
B(0,13,7,minecraft:nether_wart_block)
B(1,13,7,minecraft:nether_wart_block)
B(2,13,7,minecraft:nether_wart_block)
B(3,13,7,minecraft:nether_wart_block)
B(4,13,7,minecraft:nether_wart_block)
B(5,13,7,minecraft:nether_wart_block)
B(6,13,7,minecraft:nether_wart_block)
B(7,13,7,minecraft:nether_wart_block)
B(8,13,7,minecraft:nether_wart_block)
B(9,13,7,minecraft:nether_wart_block)
B(10,13,7,minecraft:nether_wart_block)
B(11,13,7,minecraft:nether_wart_block)
B(12,13,7,minecraft:nether_wart_block)
B(13,13,7,minecraft:nether_wart_block)
B(14,13,7,minecraft:nether_wart_block)
B(15,13,7,minecraft:nether_wart_block)
B(0,13,8,minecraft:nether_wart_block)
B(1,13,8,minecraft:nether_wart_block)
B(2,13,8,minecraft:nether_wart_block)
B(3,13,8,minecraft:nether_wart_block)
B(4,13,8,minecraft:nether_wart_block)
B(5,13,8,minecraft:nether_wart_block)
B(6,13,8,minecraft:nether_wart_block)
B(7,13,8,minecraft:nether_wart_block)
B(8,13,8,minecraft:nether_wart_block)
B(9,13,8,minecraft:nether_wart_block)
B(10,13,8,minecraft:nether_wart_block)
B(11,13,8,minecraft:nether_wart_block)
B(12,13,8,minecraft:nether_wart_block)
B(13,13,8,minecraft:nether_wart_block)
B(14,13,8,minecraft:nether_wart_block)
B(15,13,8,minecraft:nether_wart_block)
B(0,13,9,minecraft:nether_wart_block)
B(1,13,9,minecraft:nether_wart_block)
B(2,13,9,minecraft:nether_wart_block)
B(3,13,9,minecraft:nether_wart_block)
B(4,13,9,minecraft:nether_wart_block)
B(5,13,9,minecraft:nether_wart_block)
B(6,13,9,minecraft:nether_wart_block)
B(7,13,9,minecraft:nether_wart_block)
B(8,13,9,minecraft:nether_wart_block)
B(9,13,9,minecraft:nether_wart_block)
B(10,13,9,minecraft:nether_wart_block)
B(11,13,9,minecraft:nether_wart_block)
B(12,13,9,minecraft:nether_wart_block)
B(13,13,9,minecraft:nether_wart_block)
B(14,13,9,minecraft:nether_wart_block)
B(15,13,9,minecraft:nether_wart_block)
B(2,13,10,minecraft:nether_wart_block)
B(3,13,10,minecraft:nether_wart_block)
B(4,13,10,minecraft:nether_wart_block)
B(5,13,10,minecraft:nether_wart_block)
B(6,13,10,minecraft:nether_wart_block)
B(9,13,10,minecraft:nether_wart_block)
B(11,13,10,minecraft:nether_wart_block)
B(13,13,10,minecraft:nether_wart_block)
B(14,13,10,minecraft:nether_wart_block)
B(15,13,10,minecraft:nether_wart_block)
B(3,13,11,minecraft:nether_wart_block)
B(1,14,0,minecraft:nether_wart_block)
B(2,14,0,minecraft:nether_wart_block)
B(7,14,0,minecraft:nether_wart_block)
B(8,14,0,minecraft:nether_wart_block)
B(9,14,0,minecraft:nether_wart_block)
B(10,14,0,minecraft:nether_wart_block)
B(11,14,0,minecraft:nether_wart_block)
B(12,14,0,minecraft:nether_wart_block)
B(13,14,0,minecraft:nether_wart_block)
B(14,14,0,minecraft:nether_wart_block)
B(15,14,0,minecraft:nether_wart_block)
B(0,14,1,minecraft:nether_wart_block)
B(1,14,1,minecraft:nether_wart_block)
B(2,14,1,minecraft:nether_wart_block)
B(3,14,1,minecraft:nether_wart_block)
B(4,14,1,minecraft:nether_wart_block)
B(7,14,1,minecraft:nether_wart_block)
B(8,14,1,minecraft:nether_wart_block)
B(9,14,1,minecraft:nether_wart_block)
B(10,14,1,minecraft:nether_wart_block)
B(11,14,1,minecraft:nether_wart_block)
B(12,14,1,minecraft:nether_wart_block)
B(13,14,1,minecraft:nether_wart_block)
B(14,14,1,minecraft:nether_wart_block)
B(15,14,1,minecraft:nether_wart_block)
B(0,14,2,minecraft:nether_wart_block)
B(1,14,2,minecraft:nether_wart_block)
B(2,14,2,minecraft:nether_wart_block)
B(3,14,2,minecraft:nether_wart_block)
B(4,14,2,minecraft:nether_wart_block)
B(5,14,2,minecraft:nether_wart_block)
B(6,14,2,minecraft:nether_wart_block)
B(7,14,2,minecraft:nether_wart_block)
B(8,14,2,minecraft:nether_wart_block)
B(9,14,2,minecraft:nether_wart_block)
B(10,14,2,minecraft:nether_wart_block)
B(11,14,2,minecraft:nether_wart_block)
B(12,14,2,minecraft:nether_wart_block)
B(13,14,2,minecraft:nether_wart_block)
B(14,14,2,minecraft:nether_wart_block)
B(15,14,2,minecraft:nether_wart_block)
B(0,14,3,minecraft:nether_wart_block)
B(1,14,3,minecraft:nether_wart_block)
B(2,14,3,minecraft:nether_wart_block)
B(3,14,3,minecraft:nether_wart_block)
B(4,14,3,minecraft:nether_wart_block)
B(5,14,3,minecraft:nether_wart_block)
B(6,14,3,minecraft:nether_wart_block)
B(7,14,3,minecraft:nether_wart_block)
B(8,14,3,minecraft:nether_wart_block)
B(9,14,3,minecraft:nether_wart_block)
B(10,14,3,minecraft:nether_wart_block)
B(11,14,3,minecraft:nether_wart_block)
B(12,14,3,minecraft:nether_wart_block)
B(13,14,3,minecraft:nether_wart_block)
B(14,14,3,minecraft:nether_wart_block)
B(15,14,3,minecraft:nether_wart_block)
B(0,14,4,minecraft:nether_wart_block)
B(1,14,4,minecraft:nether_wart_block)
B(2,14,4,minecraft:nether_wart_block)
B(3,14,4,minecraft:nether_wart_block)
B(4,14,4,minecraft:nether_wart_block)
B(5,14,4,minecraft:nether_wart_block)
B(6,14,4,minecraft:nether_wart_block)
B(7,14,4,minecraft:nether_wart_block)
B(8,14,4,minecraft:nether_wart_block)
B(9,14,4,minecraft:nether_wart_block)
B(10,14,4,minecraft:nether_wart_block)
B(11,14,4,minecraft:nether_wart_block)
B(12,14,4,minecraft:nether_wart_block)
B(13,14,4,minecraft:nether_wart_block)
B(14,14,4,minecraft:nether_wart_block)
B(15,14,4,minecraft:nether_wart_block)
B(0,14,5,minecraft:nether_wart_block)
B(1,14,5,minecraft:nether_wart_block)
B(2,14,5,minecraft:nether_wart_block)
B(3,14,5,minecraft:nether_wart_block)
B(4,14,5,minecraft:nether_wart_block)
B(5,14,5,minecraft:nether_wart_block)
B(6,14,5,minecraft:nether_wart_block)
B(7,14,5,minecraft:nether_wart_block)
B(8,14,5,minecraft:nether_wart_block)
B(9,14,5,minecraft:nether_wart_block)
B(10,14,5,minecraft:nether_wart_block)
B(11,14,5,minecraft:nether_wart_block)
B(12,14,5,minecraft:nether_wart_block)
B(13,14,5,minecraft:nether_wart_block)
B(14,14,5,minecraft:nether_wart_block)
B(15,14,5,minecraft:nether_wart_block)
B(0,14,6,minecraft:nether_wart_block)
B(1,14,6,minecraft:nether_wart_block)
B(2,14,6,minecraft:nether_wart_block)
B(3,14,6,minecraft:nether_wart_block)
B(4,14,6,minecraft:nether_wart_block)
B(5,14,6,minecraft:nether_wart_block)
B(6,14,6,minecraft:nether_wart_block)
B(7,14,6,minecraft:nether_wart_block)
B(8,14,6,minecraft:nether_wart_block)
B(9,14,6,minecraft:nether_wart_block)
B(10,14,6,minecraft:nether_wart_block)
B(11,14,6,minecraft:nether_wart_block)
B(12,14,6,minecraft:nether_wart_block)
B(13,14,6,minecraft:nether_wart_block)
B(14,14,6,minecraft:nether_wart_block)
B(15,14,6,minecraft:nether_wart_block)
B(0,14,7,minecraft:nether_wart_block)
B(1,14,7,minecraft:nether_wart_block)
B(2,14,7,minecraft:nether_wart_block)
B(3,14,7,minecraft:nether_wart_block)
B(4,14,7,minecraft:nether_wart_block)
B(5,14,7,minecraft:nether_wart_block)
B(6,14,7,minecraft:nether_wart_block)
B(7,14,7,minecraft:nether_wart_block)
B(8,14,7,minecraft:nether_wart_block)
B(9,14,7,minecraft:nether_wart_block)
B(10,14,7,minecraft:nether_wart_block)
B(11,14,7,minecraft:nether_wart_block)
B(12,14,7,minecraft:nether_wart_block)
B(13,14,7,minecraft:nether_wart_block)
B(14,14,7,minecraft:nether_wart_block)
B(15,14,7,minecraft:nether_wart_block)
B(0,14,8,minecraft:nether_wart_block)
B(1,14,8,minecraft:nether_wart_block)
B(2,14,8,minecraft:nether_wart_block)
B(3,14,8,minecraft:nether_wart_block)
B(4,14,8,minecraft:nether_wart_block)
B(5,14,8,minecraft:nether_wart_block)
B(6,14,8,minecraft:nether_wart_block)
B(7,14,8,minecraft:nether_wart_block)
B(8,14,8,minecraft:nether_wart_block)
B(9,14,8,minecraft:nether_wart_block)
B(10,14,8,minecraft:nether_wart_block)
B(11,14,8,minecraft:nether_wart_block)
B(12,14,8,minecraft:nether_wart_block)
B(13,14,8,minecraft:nether_wart_block)
B(14,14,8,minecraft:nether_wart_block)
B(15,14,8,minecraft:nether_wart_block)
B(0,14,9,minecraft:nether_wart_block)
B(1,14,9,minecraft:nether_wart_block)
B(2,14,9,minecraft:nether_wart_block)
B(3,14,9,minecraft:nether_wart_block)
B(4,14,9,minecraft:nether_wart_block)
B(5,14,9,minecraft:nether_wart_block)
B(6,14,9,minecraft:nether_wart_block)
B(7,14,9,minecraft:nether_wart_block)
B(8,14,9,minecraft:nether_wart_block)
B(9,14,9,minecraft:nether_wart_block)
B(10,14,9,minecraft:nether_wart_block)
B(11,14,9,minecraft:nether_wart_block)
B(12,14,9,minecraft:nether_wart_block)
B(13,14,9,minecraft:nether_wart_block)
B(14,14,9,minecraft:nether_wart_block)
B(15,14,9,minecraft:nether_wart_block)
B(2,14,10,minecraft:nether_wart_block)
B(3,14,10,minecraft:nether_wart_block)
B(4,14,10,minecraft:nether_wart_block)
B(5,14,10,minecraft:nether_wart_block)
B(6,14,10,minecraft:nether_wart_block)
B(11,14,10,minecraft:nether_wart_block)
B(13,14,10,minecraft:nether_wart_block)
B(14,14,10,minecraft:nether_wart_block)
B(15,14,10,minecraft:nether_wart_block)
B(1,15,0,minecraft:nether_wart_block)
B(7,15,0,minecraft:nether_wart_block)
B(8,15,0,minecraft:nether_wart_block)
B(9,15,0,minecraft:nether_wart_block)
B(10,15,0,minecraft:nether_wart_block)
B(11,15,0,minecraft:nether_wart_block)
B(12,15,0,minecraft:nether_wart_block)
B(13,15,0,minecraft:nether_wart_block)
B(14,15,0,minecraft:nether_wart_block)
B(15,15,0,minecraft:nether_wart_block)
B(0,15,1,minecraft:nether_wart_block)
B(1,15,1,minecraft:nether_wart_block)
B(2,15,1,minecraft:nether_wart_block)
B(3,15,1,minecraft:nether_wart_block)
B(4,15,1,minecraft:nether_wart_block)
B(7,15,1,minecraft:nether_wart_block)
B(8,15,1,minecraft:nether_wart_block)
B(9,15,1,minecraft:nether_wart_block)
B(10,15,1,minecraft:nether_wart_block)
B(11,15,1,minecraft:nether_wart_block)
B(12,15,1,minecraft:nether_wart_block)
B(13,15,1,minecraft:nether_wart_block)
B(14,15,1,minecraft:nether_wart_block)
B(15,15,1,minecraft:nether_wart_block)
B(0,15,2,minecraft:nether_wart_block)
B(1,15,2,minecraft:nether_wart_block)
B(2,15,2,minecraft:nether_wart_block)
B(3,15,2,minecraft:nether_wart_block)
B(4,15,2,minecraft:nether_wart_block)
B(5,15,2,minecraft:nether_wart_block)
B(6,15,2,minecraft:nether_wart_block)
B(7,15,2,minecraft:nether_wart_block)
B(8,15,2,minecraft:nether_wart_block)
B(9,15,2,minecraft:nether_wart_block)
B(10,15,2,minecraft:nether_wart_block)
B(11,15,2,minecraft:nether_wart_block)
B(12,15,2,minecraft:nether_wart_block)
B(13,15,2,minecraft:nether_wart_block)
B(14,15,2,minecraft:nether_wart_block)
B(15,15,2,minecraft:nether_wart_block)
B(0,15,3,minecraft:nether_wart_block)
B(1,15,3,minecraft:nether_wart_block)
B(2,15,3,minecraft:nether_wart_block)
B(3,15,3,minecraft:nether_wart_block)
B(4,15,3,minecraft:nether_wart_block)
B(5,15,3,minecraft:nether_wart_block)
B(6,15,3,minecraft:nether_wart_block)
B(7,15,3,minecraft:nether_wart_block)
B(8,15,3,minecraft:nether_wart_block)
B(9,15,3,minecraft:nether_wart_block)
B(10,15,3,minecraft:nether_wart_block)
B(11,15,3,minecraft:nether_wart_block)
B(12,15,3,minecraft:nether_wart_block)
B(13,15,3,minecraft:nether_wart_block)
B(14,15,3,minecraft:nether_wart_block)
B(15,15,3,minecraft:nether_wart_block)
B(0,15,4,minecraft:nether_wart_block)
B(1,15,4,minecraft:nether_wart_block)
B(2,15,4,minecraft:nether_wart_block)
